File: datasets/am_bench_2022/raw_data/90-X.08-4/specimen.dat
MTS793|MPT|ENU|1|2|.|/|:|1|0|0|A

Operator Information						Time:	11.672852	Sec	11/2/2021 11:28:15 AM
Operator	Nick Derimow
Project	AM Bench 2022 mini-tensile challenge
Specimen ID	90-X.08-4
Material	PBF-L Inconel 625
Specimen Width	2.54	mm
Specimen Thickness	1.5	mm
Notes
Operator Information End

Data Acquisition						Time:	1012.6672	Sec	11/2/2021 11:44:56 AM
Time	Axial Displacement	Axial Extensometer	Axial Force
Sec	mm	mm	N
11.787109	-0.00054386177	-1.954146e-06	32.838818
12.687988	0.0042919237	0.00010066652	43.497242
13.588867	0.0057799956	0.00015772866	53.873962
14.489746	0.0088119721	0.00025430095	63.088863
15.390625	0.014199529	0.00036142408	76.499214
16.291504	0.014144003	0.00039813644	85.386078
17.192383	0.016686033	0.00050772342	97.671333
18.093262	0.018192392	0.00050878065	105.8666
18.994141	0.023477299	0.00071814435	119.38333
19.89502	0.02243215	0.00076659187	131.74536
20.795898	0.027606005	0.00081726856	137.23943
21.696777	0.033546716	0.00079092063	149.52296
22.597656	0.032413464	0.00091361545	161.34396
23.498535	0.034333497	0.0010742438	177.35658
24.399414	0.036068719	0.0011434796	191.82437
25.300293	0.041798852	0.0012076474	200.40916
26.201172	0.041457914	0.0013368628	219.27809
27.102051	0.047249261	0.0013807536	241.56656
28.00293	0.050162606	0.0015506184	259.04803
28.903809	0.053193096	0.0015824297	273.19781
29.804688	0.055475172	0.0016649875	287.19241
30.705566	0.057002582	0.0017750908	305.47388
31.606445	0.060411304	0.0019599199	322.67664
32.507324	0.062826969	0.0021383625	347.99954
33.408203	0.06359572	0.0022410599	367.03293
34.309082	0.070415206	0.0022945858	385.02512
35.209961	0.070678905	0.0024900855	412.09433
36.11084	0.073573753	0.0025208683	427.7066
37.011719	0.074173883	0.0026324058	443.94168
37.912598	0.079027288	0.0026495552	467.1019
38.813477	0.080402106	0.0028366391	482.12613
39.714355	0.0851629	0.0028888034	504.22263
40.615234	0.088127419	0.0030802556	520.34326
41.516113	0.08865194	0.0030390765	538.87994
42.416992	0.093014836	0.0033193806	566.37109
43.317871	0.096169695	0.0034215506	584.46637
44.21875	0.098739028	0.0035389028	605.94629
45.119629	0.099993519	0.003724196	631.38513
46.020508	0.10194757	0.0038384616	649.96069
46.921387	0.10865155	0.0039364612	677.70502
47.822266	0.1065172	0.0040682899	701.117
48.723145	0.11000235	0.0041800407	721.69556
49.624023	0.11027403	0.0043424596	743.14136
50.524902	0.11609554	0.0045564296	778.80078
51.425781	0.1172497	0.0045537003	795.84393
52.32666	0.11958847	0.0048059672	824.58057
53.227539	0.12495575	0.0049914569	853.07086
54.128418	0.12408947	0.0049889656	868.12225
55.029297	0.12813315	0.0052046264	896.75055
55.930176	0.12896603	0.0053085666	918.30835
56.831055	0.13465662	0.0054527177	942.45612
57.731934	0.13562739	0.0056139044	971.54218
58.632813	0.13957758	0.0058005541	1001.2146
59.533691	0.14207685	0.0058729942	1016.6296
60.43457	0.1441233	0.0060138218	1048.4346
61.335449	0.14967328	0.006172881	1063.1821
62.236328	0.1506377	0.0063179345	1101.1573
63.137207	0.15541551	0.006540746	1120.4669
64.038086	0.15539317	0.0066406224	1149.1161
64.938965	0.15942439	0.0066439691	1167.5844
65.839844	0.16321971	0.0069428692	1194.8337
66.740723	0.1653688	0.0071224007	1216.6658
67.641602	0.16594209	0.0071656737	1237.9918
68.54248	0.16912666	0.0073433565	1259.0052
69.443359	0.17179823	0.0074764155	1289.0436
70.344238	0.17696936	0.0076720803	1317.606
71.245117	0.17838107	0.0077770571	1345.8085
72.145996	0.18003243	0.0078696581	1360.8342
73.046875	0.18435748	0.0081153121	1395.7345
73.947754	0.18573168	0.0082561849	1414.5563
74.848633	0.19282696	0.0084235091	1442.9629
75.749512	0.19183159	0.0085016619	1457.9948
76.650391	0.19288002	0.00860277	1483.6969
77.55127	0.19660796	0.0088320943	1517.8607
78.452148	0.19738205	0.0089534698	1534.8083
79.353027	0.20285934	0.0091272397	1564.6738
80.253906	0.20737052	0.009284935	1591.8583
81.154785	0.20759529	0.0094155381	1612.5764
82.055664	0.21045271	0.0094861919	1627.6338
82.956543	0.2134582	0.0096590659	1658.2715
83.857422	0.21451686	0.0097888624	1680.0948
84.758301	0.21803378	0.0099374875	1701.418
85.65918	0.21938051	0.010082644	1728.5168
86.560059	0.22336847	0.010334739	1754.1925
87.460938	0.22965242	0.010360514	1778.1075
88.361816	0.22758773	0.010585555	1803.0181
89.262695	0.22977208	0.010681976	1822.5205
90.163574	0.23615658	0.010877817	1848.5717
91.064453	0.23845546	0.010944729	1872.4902
91.965332	0.24000055	0.01110432	1897.1433
92.866211	0.2425563	0.011231594	1916.192
93.76709	0.24741416	0.01149356	1955.0353
94.667969	0.24670365	0.011582871	1961.1812
95.568848	0.25293741	0.011601389	1981.6016
96.469727	0.25546122	0.011773184	2004.1714
97.370605	0.2535443	0.011891478	2017.5073
98.271484	0.2623907	0.012055902	2039.6068
99.172363	0.26188731	0.012132702	2052.0029
100.07324	0.26182213	0.01223309	2071.1973
100.97412	0.26767194	0.012319852	2089.1179
101.875	0.27281404	0.012530895	2116.05
102.77588	0.27068439	0.012593403	2123.9197
103.67676	0.27540156	0.012754777	2148.7783
104.57764	0.27771497	0.012851857	2159.7959
105.47852	0.28224587	0.012987074	2183.9456
106.37939	0.28161359	0.013069753	2195.9756
107.28027	0.28737357	0.013212711	2217.2651
108.18115	0.28839004	0.013287655	2233.4863
109.08203	0.290692	0.013476882	2247.2798
109.98291	0.29397491	0.013524165	2264.6465
110.88379	0.29971838	0.013744028	2283.4512
111.78467	0.30102634	0.013769196	2299.6189
112.68555	0.30155557	0.013925584	2309.3875
113.58643	0.30600211	0.014071924	2329.1565
114.4873	0.30959934	0.014183015	2342.0466
115.38818	0.31306255	0.014282779	2351.7502
116.28906	0.31219834	0.014417891	2364.46
117.18994	0.31713676	0.01450782	2377.2344
118.09082	0.32085651	0.01469833	2390.3757
118.9917	0.32259828	0.014814288	2403.0186
119.89258	0.3263334	0.014913065	2409.0427
120.79346	0.32849106	0.015060409	2428.084
121.69434	0.33048627	0.015172163	2432.0886
122.59521	0.33027464	0.015279193	2443.3398
123.49609	0.33491167	0.015453373	2460.5012
124.39697	0.33808744	0.015538991	2466.1592
125.29785	0.34415808	0.015750736	2477.2798
126.19873	0.3440659	0.015825398	2484.3855
127.09961	0.34522209	0.016054742	2499.4248
128.00049	0.35148099	0.016136143	2504.626
128.90137	0.35486984	0.016280971	2514.3267
129.80225	0.3543072	0.016400417	2519.6843
130.70313	0.35729247	0.016560899	2530.1365
131.604	0.35885414	0.016821377	2534.7361
132.50488	0.36299473	0.016948642	2547.135
133.40576	0.36694068	0.017239526	2556.6062
134.30664	0.36858591	0.017416451	2567.3665
135.20752	0.37173304	0.017660219	2573.4658
136.1084	0.37414482	0.017824488	2578.3872
137.00928	0.37984723	0.018093642	2582.7986
137.91016	0.3802484	0.018330423	2589.0859
138.81104	0.3814857	0.018694818	2606.8057
139.71191	0.38627583	0.019003715	2617.813
140.61279	0.38676101	0.01939618	2621.2461
141.51367	0.38652682	0.019701742	2620.3875
142.41455	0.39107844	0.020142576	2635.1216
143.31543	0.39602172	0.020571422	2635.4963
144.21631	0.3965815	0.020902297	2648.4939
145.11719	0.40001813	0.02138832	2651.9663
146.01807	0.40530995	0.021821082	2664.4871
146.91895	0.40453714	0.022308458	2662.5791
147.81982	0.40814784	0.022917433	2672.7837
148.7207	0.41345739	0.023253709	2672.2185
149.62158	0.41249543	0.023751309	2679.9651
150.52246	0.41651699	0.0242422	2689.063
151.42334	0.41976321	0.024699209	2690.0625
152.32422	0.42300966	0.025297554	2694.5474
153.2251	0.42425683	0.025799146	2697.5657
154.12598	0.42641699	0.0264777	2714.1875
155.02686	0.43097803	0.027354795	2721.137
155.92773	0.43090817	0.028094441	2719.5693
156.82861	0.43713981	0.028740047	2722.4312
157.72949	0.44162032	0.029434988	2737.1094
158.63037	0.44287837	0.030068349	2727.0854
159.53125	0.44451666	0.030578457	2729.8083
160.43213	0.45025331	0.031252526	2746.5007
161.33301	0.44905549	0.032000534	2744.2058
162.23389	0.45257452	0.032617822	2750.8977
163.13477	0.45491579	0.033455849	2758.4592
164.03564	0.45847404	0.034284573	2762.6826
164.93652	0.45942739	0.035094198	2763.3445
165.8374	0.46524954	0.035991538	2770.7756
166.73828	0.46748057	0.036774028	2774.6948
167.63916	0.46763447	0.03748044	2770.7297
168.54004	0.47490922	0.038112607	2781.7656
169.44092	0.47453693	0.038844414	2779.812
170.3418	0.47658414	0.03953293	2783.9817
171.24268	0.48122063	0.040397525	2796.4063
172.14355	0.48183531	0.041493464	2797.0522
173.04443	0.48587996	0.042306222	2800.3806
173.94531	0.48494202	0.042977598	2796.1489
174.84619	0.48845175	0.043864291	2801.4036
175.74707	0.48983184	0.04456035	2797.6421
176.64795	0.49943107	0.045251478	2809.4783
177.54883	0.49957758	0.045991309	2809.2827
178.44971	0.50365835	0.046847042	2824.9453
179.35059	0.50396812	0.04770102	2823.9595
180.25146	0.50528949	0.048628338	2821.9343
181.15234	0.51196414	0.049399033	2822.0945
182.05322	0.51701152	0.050306968	2835.1936
182.9541	0.51375216	0.051248066	2831.3091
183.85498	0.51793951	0.052163299	2842.6943
184.75586	0.51936674	0.053079348	2840.6799
185.65674	0.52169865	0.053901337	2839.8254
186.55762	0.52605492	0.054791857	2845.7776
187.4585	0.52875888	0.055701625	2847.5706
188.35938	0.53059667	0.056684621	2858.8003
189.26025	0.5337612	0.057593942	2857.5461
190.16113	0.53772211	0.058529336	2860.0413
191.06201	0.53878778	0.059666883	2867.3821
191.96289	0.54136813	0.060604021	2863.176
192.86377	0.54437542	0.061501686	2869.8225
193.76465	0.54681695	0.062488187	2872.9202
194.66553	0.55122429	0.063549794	2878.0684
195.56641	0.55173773	0.064305037	2876.4541
196.46729	0.55551976	0.065088272	2878.0977
197.36816	0.55848634	0.066067979	2878.6787
198.26904	0.56012422	0.067099042	2889.845
199.16992	0.56551158	0.06829647	2895.8408
200.0708	0.56765616	0.069266975	2895.1631
200.97168	0.56790447	0.070253357	2896.1741
201.87256	0.57294285	0.071281463	2909.2185
202.77344	0.57479674	0.072244927	2907.071
203.67432	0.57506329	0.073124312	2905.5627
204.5752	0.5806129	0.074174166	2911.4663
205.47607	0.58163303	0.075053208	2917.4443
206.37695	0.58215857	0.076127097	2911.814
207.27783	0.59134722	0.077011116	2914.5649
208.17871	0.5917781	0.077834383	2920.1941
209.07959	0.59184676	0.07881584	2921.0823
209.98047	0.59281236	0.0797299	2921.5991
210.88135	0.60007668	0.080596551	2925.8926
211.78223	0.60300022	0.081586167	2925.4998
212.68311	0.60468668	0.082498305	2924.5181
213.58398	0.60824394	0.083144821	2927.4365
214.48486	0.61071569	0.08401747	2939.4937
215.38574	0.6095683	0.085076876	2937.8162
216.28662	0.61312789	0.086298585	2939.6719
217.1875	0.61992568	0.087265514	2944.8904
218.08838	0.62127203	0.088232726	2946.3806
218.98926	0.62358534	0.089265704	2950.259
219.89014	0.62590021	0.090386644	2955.0928
220.79102	0.62856686	0.091346465	2957.3699
221.69189	0.62921411	0.092396386	2960.7295
222.59277	0.63386178	0.093502879	2958.5864
223.49365	0.63607293	0.094641089	2962.3157
224.39453	0.63606435	0.095471382	2961.1343
225.29541	0.64111674	0.096331097	2962.3091
226.19629	0.6471144	0.097462274	2975.8162
227.09717	0.64561015	0.098665252	2973.1033
227.99805	0.65046489	0.099534161	2973.9453
228.89893	0.6527853	0.10053786	2977.3069
229.7998	0.65664476	0.10143311	2979.3926
230.70068	0.66122776	0.10241599	2984.2166
231.60156	0.66383636	0.10370363	2995.8647
232.50244	0.66385871	0.10481837	2993.6631
233.40332	0.66557443	0.10574701	2986.811
234.3042	0.67073703	0.10665498	2989.572
235.20508	0.67125273	0.1075312	2993.4001
236.10596	0.67467088	0.10852412	2992.1077
237.00684	0.67704862	0.10942225	2997.2214
237.90771	0.68090773	0.11050255	3009.5354
238.80859	0.68137199	0.11159203	2997.2813
239.70947	0.68758523	0.11257902	3011.2017
240.61035	0.68971854	0.1134927	3010.6921
241.51123	0.69277078	0.11447121	3008.4248
242.41211	0.69208252	0.1152747	3002.4631
243.31299	0.69303077	0.11636861	3021.3108
244.21387	0.69898379	0.11745667	3015.5276
245.11475	0.70262551	0.11867265	3022.6326
246.01563	0.702061	0.1195425	3018.1038
246.9165	0.70925981	0.12080198	3034.9277
247.81738	0.70959586	0.12211622	3030.8958
248.71826	0.71241158	0.1230069	3027.1204
249.61914	0.71400768	0.12393584	3026.3457
250.52002	0.71850395	0.12505087	3034.3945
251.4209	0.71983635	0.12611224	3029.2341
252.32178	0.72243559	0.12701689	3034.356
253.22266	0.72761613	0.12777308	3038.6033
254.12354	0.73050016	0.12876998	3043.8904
255.02441	0.73227572	0.12966666	3045.0527
255.92529	0.73583466	0.13072023	3049.9353
256.82617	0.7371484	0.13182466	3045.5608
257.72705	0.74055606	0.13285014	3044.8923
258.62793	0.74170184	0.13383484	3049.031
259.52881	0.74497265	0.13460763	3051.6885
260.42969	0.74570578	0.13564278	3055.6477
261.33057	0.7514689	0.13672104	3061.2461
262.23145	0.75505769	0.13805802	3068.5422
263.13232	0.75713468	0.1393705	3068.7112
264.0332	0.76019365	0.14044012	3067.7251
264.93408	0.76236939	0.14139818	3072.7952
265.83496	0.76110643	0.14241156	3063.4602
266.73584	0.7685076	0.14361881	3079.9709
267.63672	0.76871538	0.14456628	3072.1189
268.5376	0.77131808	0.14566752	3076.4668
269.43848	0.77515095	0.14665857	3072.7126
270.33936	0.77650142	0.147678	3084.1697
271.24023	0.7796874	0.14875616	3087.9304
272.14111	0.78382611	0.14984943	3093.8772
273.04199	0.78718448	0.15101378	3087.5273
273.94287	0.79268062	0.1518984	3089.6003
274.84375	0.79091424	0.15304875	3095.9761
275.74463	0.79436457	0.1541933	3097.978
276.64551	0.79766184	0.15523338	3099.1294
277.54639	0.80140924	0.15624888	3097.4749
278.44727	0.80321336	0.15709913	3097.5715
279.34814	0.80519539	0.15799987	3098.2131
280.24902	0.81023484	0.15885814	3101.8147
281.1499	0.80889648	0.15967834	3106.5193
282.05078	0.81205279	0.16075994	3110.5603
282.95166	0.81592399	0.16180369	3111.7971
283.85254	0.81634605	0.16267122	3103.6501
284.75342	0.81983346	0.16375753	3112.927
285.6543	0.82278675	0.16481604	3114.7678
286.55518	0.82391751	0.16592669	3118.8296
287.45605	0.83036518	0.16703214	3116.7842
288.35693	0.82970297	0.16795932	3113.7429
289.25781	0.83495075	0.16903795	3122.771
290.15869	0.83364892	0.16993085	3115.939
291.05957	0.84080034	0.17081277	3121.241
291.96045	0.84164327	0.17176948	3126.1089
292.86133	0.84576029	0.17278421	3126.2495
293.76221	0.84671956	0.17388563	3132.7793
294.66309	0.85112035	0.17493285	3133.186
295.56396	0.85179585	0.17589979	3127.9011
296.46484	0.8556447	0.17678681	3139.584
297.36572	0.85754037	0.17810255	3141.9924
298.2666	0.85963511	0.17905819	3137.988
299.16748	0.86646366	0.18012565	3144.4543
300.06836	0.86892253	0.18114972	3145.5361
300.96924	0.87053603	0.18219286	3149.3672
301.87012	0.87152338	0.18326722	3148.9724
302.771	0.87607044	0.18436922	3150.3528
303.67188	0.8774541	0.18540339	3151.0044
304.57275	0.87882352	0.1863305	3147.4465
305.47363	0.88263309	0.18740413	3155.8823
306.37451	0.885499	0.18848154	3156.4907
307.27539	0.88883996	0.18963182	3162.5134
308.17627	0.89381504	0.19075058	3160.9763
309.07715	0.89403635	0.19173723	3160.0083
309.97803	0.89993548	0.19268394	3167.1804
310.87891	0.89839429	0.19352959	3164.8628
311.77979	0.90099025	0.1946336	3170.8508
312.68066	0.90334976	0.19568424	3177.9211
313.58154	0.90840578	0.19679525	3184.2456
314.48242	0.9073807	0.19775569	3170.312
315.3833	0.91378456	0.19893667	3182.5549
316.28418	0.91645235	0.19985104	3179.6355
317.18506	0.9194597	0.20072833	3176.5457
318.08594	0.92426991	0.20166719	3184.6104
318.98682	0.92597991	0.20244883	3179.5833
319.8877	0.92645794	0.20342967	3185.2969
320.78857	0.9289481	0.20431271	3182.0872
321.68945	0.93325955	0.20552737	3188.2568
322.59033	0.933972	0.2065648	3194.5313
323.49121	0.93589711	0.20786631	3196.4165
324.39209	0.93868977	0.20899415	3189.8752
325.29297	0.94320548	0.21021083	3200.6245
326.19385	0.94521421	0.21113814	3197.3833
327.09473	0.94766921	0.2120173	3195.105
327.99561	0.94625092	0.21320765	3201.2161
328.89648	0.95208865	0.21421999	3199.4246
329.79736	0.95502245	0.21517196	3200.0977
330.69824	0.95897985	0.21606989	3203.426
331.59912	0.96228778	0.21701597	3208.76
332.5	0.96187472	0.21801029	3204.6902
333.40088	0.96683204	0.21898906	3210.3037
334.30176	0.97051221	0.21998268	3212.7683
335.20264	0.97162539	0.22121024	3222.1812
336.10352	0.97546089	0.22237793	3218.7759
337.00439	0.97586292	0.22357549	3217.4001
337.90527	0.9781509	0.22445048	3212.6804
338.80615	0.98311287	0.22548677	3223.3284
339.70703	0.98423856	0.22632307	3220.6196
340.60791	0.98837811	0.22712934	3217.6611
341.50879	0.99158919	0.22798242	3220.1025
342.40967	0.992019	0.22895803	3223.9604
343.31055	0.99745202	0.23017168	3234.1965
344.21143	1.0003235	0.23121911	3231.8572
345.1123	1.003669	0.23232584	3233.6704
346.01318	1.0041773	0.233372	3230.2334
346.91406	1.0097986	0.23455265	3239.7971
347.81494	1.0111527	0.23558374	3237.3311
348.71582	1.0140101	0.2363864	3229.2839
349.6167	1.0138131	0.23724666	3234.5254
350.51758	1.0188246	0.23830631	3243.3218
351.41846	1.0198539	0.2392077	3242.5698
352.31934	1.0246561	0.2401412	3244.7993
353.22021	1.0270615	0.24134706	3253.1396
354.12109	1.0291855	0.2424711	3243.3652
355.02197	1.0311781	0.24346657	3254.2639
355.92285	1.0364007	0.24451952	3253.6243
356.82373	1.0372291	0.24536233	3255.1848
357.72461	1.0392704	0.24648097	3257.8154
358.62549	1.0423155	0.24749617	3261.2458
359.52637	1.0431494	0.2485085	3261.835
360.42725	1.0486279	0.24950424	3256.2278
361.32813	1.0527483	0.2504172	3257.8708
362.229	1.052582	0.25143418	3261.1499
363.12988	1.0575665	0.2519533	3256.0437
364.03076	1.0610446	0.25285637	3263.4595
364.93164	1.0615549	0.25386262	3266.2515
365.83252	1.0633577	0.25493184	3265.4673
366.7334	1.0673006	0.25604272	3272.428
367.63428	1.069587	0.25698721	3269.3315
368.53516	1.072513	0.25819889	3276.2219
369.43604	1.074098	0.25926214	3275.7136
370.33691	1.0759472	0.26019949	3275.4514
371.23779	1.0788473	0.26102948	3275.0508
372.13867	1.0816917	0.26207548	3279.6357
373.03955	1.0847305	0.26324305	3282.8572
373.94043	1.0892348	0.26445457	3286.1326
374.84131	1.0919212	0.26564375	3290.2583
375.74219	1.0951208	0.26668763	3288.8857
376.64307	1.09659	0.26764268	3286.9648
377.54395	1.0996108	0.26872447	3286.4873
378.44482	1.1003301	0.26997101	3295.1472
379.3457	1.104127	0.27093509	3289.3484
380.24658	1.1053288	0.27178338	3286.4983
381.14746	1.1092843	0.27287725	3296.0361
382.04834	1.1151202	0.27389252	3301.0059
382.94922	1.114615	0.2746672	3296.4915
383.8501	1.1190126	0.27556348	3298.3035
384.75098	1.1177278	0.27645108	3294.8179
385.65186	1.1217198	0.27758878	3303.6223
386.55273	1.1253179	0.2783896	3300.3909
387.45361	1.1276786	0.27943361	3303.5479
388.35449	1.1312463	0.28033176	3307.6252
389.25537	1.1351931	0.28124511	3307.3423
390.15625	1.1378798	0.28223005	3309.2444
391.05713	1.1411915	0.28330523	3312.8853
391.95801	1.1404339	0.28411588	3310.0659
392.85889	1.1426839	0.28523833	3315.252
393.75977	1.1489286	0.28647721	3316.4175
394.66064	1.1489215	0.28730071	3307.9995
395.56152	1.1510367	0.28822279	3317.1428
396.4624	1.1565303	0.28921679	3321.4998
397.36328	1.1588416	0.29017866	3314.4648
398.26416	1.1632817	0.29109511	3323.6023
399.16504	1.1639761	0.29213303	3317.2317
400.06592	1.1668998	0.2930972	3328.5232
400.9668	1.1679913	0.29418197	3326.3167
401.86768	1.1731294	0.29519531	3325.6055
402.76855	1.1746428	0.29601011	3319.8674
403.66943	1.1753914	0.29717493	3329.5486
404.57031	1.1790061	0.29817054	3329.2031
405.47119	1.1825185	0.29900971	3332.3479
406.37207	1.1846962	0.3002333	3345.3867
407.27295	1.1899474	0.30137351	3335.9851
408.17383	1.1906165	0.3023265	3336.5366
409.07471	1.1925036	0.30344534	3339.905
409.97559	1.1975591	0.30463082	3343.5146
410.87646	1.1986203	0.305711	3344.9666
411.77734	1.1997101	0.30657476	3343.7017
412.67822	1.203813	0.30757269	3344.2068
413.5791	1.2053101	0.30846494	3344.5354
414.47998	1.2111646	0.30936664	3348.155
415.38086	1.2134819	0.31036529	3352.7466
416.28174	1.2170088	0.31138909	3348.3113
417.18262	1.2181063	0.31229994	3347.9338
418.0835	1.2231952	0.3131856	3351.95
418.98438	1.2246399	0.31425291	3353.6975
419.88525	1.2269461	0.31526163	3363.2642
420.78613	1.2289211	0.31623757	3356.3721
421.68701	1.2326734	0.31717286	3354.7336
422.58789	1.235137	0.31798798	3356.1191
423.48877	1.2353623	0.31888998	3358.1797
424.38965	1.2383156	0.31991816	3359.7021
425.29053	1.2413111	0.32072026	3358.0188
426.19141	1.2447208	0.3217172	3363.2839
427.09229	1.2483412	0.32263607	3361.9548
427.99316	1.2487803	0.32364416	3368.7964
428.89404	1.2541302	0.32468218	3367.7927
429.79492	1.255903	0.32583788	3373.3599
430.6958	1.2585365	0.32690111	3369.7092
431.59668	1.2608737	0.32792786	3371.6196
432.49756	1.2631574	0.32898587	3377.1111
433.39844	1.2679546	0.33008349	3376.8232
434.29932	1.2682468	0.33105004	3376.2976
435.2002	1.2718151	0.33197698	3379.3389
436.10107	1.2732797	0.33304289	3379.9646
437.00195	1.27704	0.33390293	3380.0508
437.90283	1.2803776	0.33493629	3382.8298
438.80371	1.282451	0.33586699	3380.2427
439.70459	1.2825725	0.3369019	3382.0728
440.60547	1.288792	0.33798423	3391.0229
441.50635	1.2924986	0.33920336	3392.2295
442.40723	1.2919618	0.34022862	3388.6958
443.30811	1.295718	0.34121451	3388.6831
444.20898	1.3000242	0.34230012	3393.5227
445.10986	1.3015074	0.34312043	3392.842
446.01074	1.3067284	0.34408313	3396.5667
446.91162	1.3072472	0.34499395	3393.041
447.8125	1.3081601	0.34591827	3393.668
448.71338	1.3118577	0.34711543	3403.4915
449.61426	1.3121827	0.34814212	3393.7383
450.51514	1.3172543	0.34916383	3394.2292
451.41602	1.3218825	0.35006309	3403.4207
452.31689	1.3243065	0.35088328	3398.6904
453.21777	1.3263675	0.35190338	3404.8845
454.11865	1.3316073	0.35279706	3402.231
455.01953	1.3323249	0.35389444	3411.4775
455.92041	1.3345543	0.35499263	3410.9478
456.82129	1.3349165	0.35620615	3411.7388
457.72217	1.3368185	0.3570683	3403.3774
458.62305	1.3436519	0.35811642	3416.2903
459.52393	1.3462737	0.35909626	3409.855
460.4248	1.3483348	0.35994613	3414.0728
461.32568	1.3496706	0.36092106	3414.3601
462.22656	1.354666	0.36170009	3412.5728
463.12744	1.3549789	0.36280879	3423.4531
464.02832	1.3592675	0.36387783	3414.9673
464.9292	1.363767	0.3648721	3416.8848
465.83008	1.3648816	0.36581373	3422.4656
466.73096	1.3678643	0.36672539	3417.4102
467.63184	1.3682301	0.36764792	3421.8613
468.53271	1.3727065	0.36859289	3424.1021
469.43359	1.3727938	0.36973649	3425.1255
470.33447	1.3761077	0.37062806	3420.4666
471.23535	1.3792195	0.37167501	3425.9622
472.13623	1.3804866	0.37259889	3425.4155
473.03711	1.3864517	0.37356779	3430.0393
473.93799	1.391467	0.37469214	3437.989
474.83887	1.3929812	0.3757627	3436.8623
475.73975	1.3945225	0.37692115	3435.9136
476.64063	1.3972082	0.37803504	3437.6409
477.5415	1.4001145	0.3790656	3434.333
478.44238	1.4034915	0.37996131	3438.4519
479.34326	1.4056453	0.38082433	3438.1006
480.24414	1.4069388	0.38174701	3437.271
481.14502	1.4131976	0.3829532	3450.104
482.0459	1.4121298	0.38388038	3434.5969
482.94678	1.4154139	0.3847388	3441.7424
483.84766	1.4167072	0.38595816	3446.5173
484.74854	1.4221328	0.38700768	3449.793
485.64941	1.421558	0.38796777	3442.5842
486.55029	1.4261068	0.38898611	3444.1372
487.45117	1.4295655	0.38984016	3445.7979
488.35205	1.4331038	0.39087877	3446.4287
489.25293	1.4364296	0.39188316	3450.9309
490.15381	1.4401844	0.3928763	3454.7944
491.05469	1.4383707	0.39367953	3444.7891
491.95557	1.4405133	0.39477205	3453.4348
492.85645	1.4414181	0.39572933	3453.3804
493.75732	1.448053	0.396833	3457.272
494.6582	1.4513721	0.39782894	3462.5679
495.55908	1.453102	0.39871001	3453.5623
496.45996	1.4576432	0.39956865	3461.8838
497.36084	1.459361	0.4006339	3456.7991
498.26172	1.4604688	0.40173611	3462.2534
499.1626	1.4657182	0.40291157	3468.2747
500.06348	1.4661509	0.40400138	3465.6746
500.96436	1.4716464	0.40513331	3463.2852
501.86523	1.4716002	0.40608212	3461.2417
502.76611	1.4772159	0.40717974	3467.3743
503.66699	1.4749192	0.40807176	3465.6831
504.56787	1.4814297	0.40914425	3470.3188
505.46875	1.4838967	0.41003466	3465.8413
506.36963	1.4867548	0.41089463	3471.9878
507.27051	1.488389	0.41178027	3473.6548
508.17139	1.4902329	0.41260058	3467.3003
509.07227	1.4938477	0.4135755	3473.4692
509.97314	1.4950011	0.41459727	3478.2903
510.87402	1.4993019	0.41565317	3477.1528
511.7749	1.5000627	0.41685048	3478.5454
512.67578	1.5064452	0.41792098	3478.1699
513.57666	1.5079284	0.41903287	3486.7144
514.47754	1.5109109	0.42016378	3483.0862
515.37842	1.5133111	0.42124066	3484.5974
516.2793	1.5151775	0.42223248	3483.4841
517.18018	1.5182197	0.42318815	3480.5571
518.08105	1.5205784	0.42404753	3484.1453
518.98193	1.5221685	0.42516512	3485.5459
519.88281	1.5261145	0.42608181	3485.7727
520.78369	1.5290979	0.42717689	3489.5156
521.68457	1.5334952	0.42833018	3490.6433
522.58545	1.5337951	0.42905778	3485.5996
523.48633	1.5377622	0.43021053	3486.3149
524.38721	1.5374222	0.43125543	3490.9758
525.28809	1.542804	0.43246284	3495.0776
526.18896	1.5462097	0.43370864	3495.084
527.08984	1.5465096	0.43449599	3490.7317
527.99072	1.5510176	0.43571249	3504.4746
528.8916	1.555831	0.43653166	3501.1516
529.79248	1.5575982	0.43775806	3499.562
530.69336	1.5588895	0.43857902	3500.054
531.59424	1.5627875	0.43956035	3505.5239
532.49512	1.5644225	0.44049025	3503.0845
533.396	1.5681549	0.44154227	3501.5964
534.29688	1.5718651	0.44250864	3506.6389
535.19775	1.5714303	0.44360316	3509.2053
536.09863	1.5748646	0.4444727	3501.5271
536.99951	1.5773191	0.44544747	3501.9324
537.90039	1.5794629	0.44643298	3506.6289
538.80127	1.5831083	0.44764104	3510.7722
539.70215	1.5844141	0.44865951	3506.2991
540.60303	1.5894049	0.44970906	3505.3657
541.50391	1.5919788	0.45071176	3510.3616
542.40479	1.5918374	0.45167264	3509.7104
543.30566	1.5967346	0.45281205	3511.5212
544.20654	1.5989926	0.45398107	3516.729
545.10742	1.6018044	0.4550955	3515.8738
546.0083	1.6049775	0.45600113	3511.8718
546.90918	1.6076107	0.45730087	3518.9016
547.81006	1.6085382	0.45835769	3522.2747
548.71094	1.610261	0.45967552	3523.1208
549.61182	1.6138371	0.46075287	3520.261
550.5127	1.6172717	0.46175045	3516.5356
551.41357	1.6210198	0.46280959	3518.5913
552.31445	1.6237588	0.46385947	3520.2869
553.21533	1.6269587	0.46479699	3520.8184
554.11621	1.6301247	0.46596661	3527.5488
555.01709	1.6340361	0.46709841	3525.4675
555.91797	1.6344174	0.46818745	3524.2666
556.81885	1.6363987	0.46926787	3529.1311
557.71973	1.637522	0.47019801	3528.1838
558.62061	1.6420466	0.47120169	3525.2883
559.52148	1.6426646	0.4722428	3530.9956
560.42236	1.6477143	0.47342548	3529.8726
561.32324	1.649875	0.47465488	3531.1653
562.22412	1.6548536	0.47579306	3536.7419
563.125	1.6547031	0.47657189	3527.0894
564.02588	1.6579392	0.47762716	3534.8503
564.92676	1.6613184	0.47859704	3530.9194
565.82764	1.6664921	0.479761	3539.1448
566.72852	1.6671559	0.48081595	3534.4761
567.62939	1.6686978	0.48193881	3532.6079
568.53027	1.6715363	0.48288429	3535.1104
569.43115	1.6703144	0.48375383	3535.2808
570.33203	1.6770107	0.48480862	3541.0466
571.23291	1.6776017	0.48576057	3537.7769
572.13379	1.683885	0.4868587	3545.4746
573.03467	1.6864041	0.48796296	3548.4839
573.93555	1.6878343	0.4889926	3540.7876
574.83643	1.6930245	0.49013627	3543.739
575.7373	1.6901139	0.49123022	3545.1343
576.63818	1.6952254	0.49238864	3546.6848
577.53906	1.7015219	0.49343356	3544.2764
578.43994	1.7021101	0.49436042	3544.9268
579.34082	1.7058877	0.49549276	3553.708
580.2417	1.7077222	0.49666798	3551.0166
581.14258	1.7117639	0.49775267	3554.0459
582.04346	1.7111635	0.4987722	3545.8972
582.94434	1.7173641	0.50005621	3559.4988
583.84521	1.7179135	0.50131786	3554.7554
584.74609	1.7230989	0.50269222	3557.5627
585.64697	1.7255778	0.50388706	3551.7908
586.54785	1.7276273	0.50489634	3553.478
587.44873	1.7306163	0.506006	3559.144
588.34961	1.7318989	0.50682998	3552.9546
589.25049	1.7312961	0.50799024	3558.4365
590.15137	1.7359607	0.50903416	3561.6865
591.05225	1.7394471	0.51036006	3562.1094
591.95313	1.7402701	0.51125968	3555.3135
592.854	1.7482235	0.5124743	3560.6169
593.75488	1.74965	0.51369041	3563.0608
594.65576	1.7504718	0.5147922	3561.5737
595.55664	1.7545493	0.51592839	3567.0217
596.45752	1.7562479	0.51723093	3564.2578
597.3584	1.7570807	0.51835358	3561.9338
598.25928	1.7633556	0.51951456	3563.9485
599.16016	1.7624754	0.52045631	3561.7144
600.06104	1.76639	0.52161849	3571.0369
600.96191	1.7707884	0.52273542	3567.5916
601.86279	1.7711965	0.52357626	3567.9644
602.76367	1.7738445	0.5245738	3565.4072
603.66455	1.7733233	0.52543116	3567.5901
604.56543	1.7806398	0.52658367	3576.6333
605.46631	1.7844579	0.52762544	3573.8596
606.36719	1.7867193	0.52894974	3576.6987
607.26807	1.7901223	0.53000814	3573.8108
608.16895	1.7923578	0.53122681	3575.5649
609.06982	1.7949332	0.53236389	3580.3228
609.9707	1.7948884	0.53358293	3576.3777
610.87158	1.7989275	0.53487182	3577.5837
611.77246	1.8007514	0.53588104	3574.1582
612.67334	1.8053352	0.53697258	3572.4778
613.57422	1.8091935	0.53794783	3576.936
614.4751	1.810023	0.53900868	3573.2241
615.37598	1.8147926	0.54005313	3582.334
616.27686	1.8131868	0.54122317	3588.9509
617.17773	1.8189846	0.54243958	3582.7891
618.07861	1.821436	0.54378933	3589.0305
618.97949	1.8229885	0.54503554	3582.6873
619.88037	1.8263023	0.54627019	3589.6526
620.78125	1.8313837	0.54765648	3588.3618
621.68213	1.8295307	0.54871148	3588.4602
622.58301	1.8332708	0.54997009	3589.8389
623.48389	1.8362997	0.5511958	3585.5029
624.38477	1.8393266	0.55245954	3583.3452
625.28564	1.8428911	0.55328828	3588.0779
626.18652	1.8431208	0.55440289	3586.7644
627.0874	1.8468484	0.55563277	3591.5403
627.98828	1.8499889	0.55697882	3597.2449
628.88916	1.8550359	0.55827492	3596.6677
629.79004	1.8571438	0.5594368	3592.5649
630.69092	1.8563353	0.56073463	3594.6951
631.5918	1.8624545	0.56195527	3592.4744
632.49268	1.8666512	0.56318831	3592.8518
633.39355	1.8671706	0.56420374	3590.5164
634.29443	1.8695565	0.56531423	3598.6741
635.19531	1.8750727	0.56640059	3592.1025
636.09619	1.8752012	0.56742913	3594.0703
636.99707	1.8765202	0.56866968	3601.8528
637.89795	1.8799061	0.56982017	3597.6572
638.79883	1.8816696	0.57101053	3596.1301
639.69971	1.8848109	0.57233739	3600.7964
640.60059	1.8896323	0.57372063	3602.2671
641.50146	1.891185	0.57468635	3600.4473
642.40234	1.894233	0.57586616	3602.6033
643.30322	1.8932447	0.5769974	3607.3062
644.2041	1.9022886	0.57833779	3606.219
645.10498	1.8998604	0.5793817	3604.175
646.00586	1.9070237	0.58073652	3608.0359
646.90674	1.9104363	0.58199239	3606.8433
647.80762	1.9106557	0.58316487	3606.4868
648.7085	1.9140364	0.5842644	3608.2649
649.60938	1.9150664	0.58553129	3610.5227
650.51025	1.9170209	0.58661216	3598.8865
651.41113	1.922503	0.58774769	3612.9656
652.31201	1.9225985	0.58908647	3612.5491
653.21289	1.9266877	0.59065616	3613.6191
654.11377	1.9278463	0.59209192	3612.9641
655.01465	1.9317309	0.59343588	3607.6313
655.91553	1.9310807	0.59449536	3606.5981
656.81641	1.9359939	0.595851	3610.0242
657.71729	1.9410117	0.59694546	3610.1516
658.61816	1.9426057	0.59840697	3619.1848
659.51904	1.9445989	0.59962225	3617.3
660.41992	1.948885	0.60078979	3608.6157
661.3208	1.9538033	0.60195804	3610.3733
662.22168	1.9543786	0.60310352	3615.4634
663.12256	1.9535975	0.60414505	3611.8225
664.02344	1.9576169	0.60543001	3617.905
664.92432	1.9609283	0.60651898	3615.5581
665.8252	1.9644583	0.60772753	3621.3806
666.72607	1.9676707	0.60906047	3624.9143
667.62695	1.970546	0.61037934	3621.2473
668.52783	1.9733851	0.6115374	3619.9084
669.42871	1.9727161	0.61295879	3621.3157
670.32959	1.9782073	0.61426091	3619.9426
671.23047	1.9817038	0.61555004	3624.144
672.13135	1.9824989	0.61695129	3624.5022
673.03223	1.9874145	0.61829054	3621.2134
673.93311	1.9897453	0.61950058	3622.9656
674.83398	1.9930524	0.62063742	3619.4043
675.73486	1.9947075	0.62177736	3618.7251
676.63574	1.99463	0.622823	3617.1494
677.53662	1.9970067	0.62419838	3619.3706
678.4375	2.0032797	0.62574029	3626.4248
679.33838	2.0041506	0.62679386	3627.5278
680.23926	2.0097201	0.62836289	3629.9617
681.14014	2.0105457	0.62977737	3630.0996
682.04102	2.0110288	0.63117284	3623.5747
682.94189	2.0154402	0.6325084	3629.3616
683.84277	2.019891	0.6338492	3624.0781
684.74365	2.0225966	0.63494378	3628.8782
685.64453	2.0223968	0.63611597	3623.1914
686.54541	2.0239422	0.63745975	3628.6416
687.44629	2.0277145	0.63876349	3628.1042
688.34717	2.0352559	0.64005733	3628.8286
689.24805	2.0315361	0.64122248	3629.8228
690.14893	2.0395081	0.64248002	3637.8501
691.0498	2.0400095	0.64388996	3640.9761
691.95068	2.0431294	0.64559907	3637.2214
692.85156	2.0455272	0.64711815	3637.2097
693.75244	2.0469465	0.64847231	3633.5693
694.65332	2.0518818	0.64963627	3629.3176
695.5542	2.0541408	0.65092051	3631.238
696.45508	2.0540433	0.65217435	3631.2502
697.35596	2.0590947	0.65342379	3635.5837
698.25684	2.0633061	0.65464276	3632.7769
699.15771	2.0622072	0.65597343	3636.3271
700.05859	2.0686481	0.65750206	3643.6628
700.95947	2.0687928	0.65905344	3638.9338
701.86035	2.0722077	0.66043568	3640.6067
702.76123	2.0737655	0.6616466	3633.0981
703.66211	2.0794656	0.66279191	3636.8596
704.56299	2.0800261	0.66410816	3639.03
705.46387	2.0815909	0.66512233	3633.1479
706.36475	2.084976	0.66669589	3645.574
707.26563	2.086746	0.66790897	3637.6831
708.1665	2.0886297	0.66922861	3633.7542
709.06738	2.0955284	0.67064625	3645.2671
709.96826	2.0966663	0.67185336	3643.4148
710.86914	2.0999513	0.67327458	3638.0662
711.77002	2.1039813	0.67451608	3639.5552
712.6709	2.1037841	0.67586827	3642.2852
713.57178	2.1062374	0.67735678	3644.3306
714.47266	2.1082497	0.67885804	3642.2981
715.37354	2.1115506	0.68036693	3645.4023
716.27441	2.1146131	0.68176121	3634.7422
717.17529	2.1139581	0.68323714	3642.9224
718.07617	2.1202338	0.68454629	3635.4275
718.97705	2.1243677	0.68586731	3645.8213
719.87793	2.1258574	0.68746638	3651.1331
720.77881	2.1301019	0.68874812	3639.8706
721.67969	2.1307919	0.68999553	3648.9817
722.58057	2.1351216	0.69165868	3652.6768
723.48145	2.1376829	0.69318241	3648.3574
724.38232	2.1439455	0.6945138	3651.7065
725.2832	2.1410568	0.69599998	3650.887
726.18408	2.1469877	0.6975224	3648.4556
727.08496	2.1491559	0.69871187	3646.5093
727.98584	2.1518569	0.7002337	3649.842
728.88672	2.1541417	0.70176584	3656.7368
729.7876	2.1562414	0.70317996	3653.2107
730.68848	2.1612625	0.70464325	3649.4575
731.58936	2.1620109	0.70620579	3654.8743
732.49023	2.164283	0.70749223	3650.7734
733.39111	2.1632743	0.70911723	3652.9265
734.29199	2.1681666	0.71066976	3646.3359
735.19287	2.1738112	0.71216667	3652.9302
736.09375	2.173455	0.71365136	3648.3301
736.99463	2.1768966	0.71513093	3649.0225
737.89551	2.178565	0.71649599	3648.3901
738.79639	2.1838043	0.71783781	3650.8003
739.69727	2.1834843	0.71954715	3654.4092
740.59814	2.1877863	0.72115093	3651.9521
741.49902	2.195554	0.72283429	3659.5532
742.3999	2.1975193	0.72442245	3659.832
743.30078	2.1979878	0.72591871	3655.2156
744.20166	2.2008049	0.72725481	3651.5076
745.10254	2.2009017	0.72869247	3650.7666
746.00342	2.2047055	0.73016685	3651.3918
746.9043	2.2040932	0.73169428	3652.6353
747.80518	2.210005	0.73310268	3649.6316
748.70605	2.2118821	0.73461628	3654.8821
749.60693	2.2156901	0.73612279	3648.0239
750.50781	2.2168245	0.73765111	3652.0452
751.40869	2.2228127	0.7391274	3661.1123
752.30957	2.223711	0.7406379	3657.2776
753.21045	2.2256079	0.74215508	3654.2163
754.11133	2.2287936	0.7438482	3655.7952
755.01221	2.2331781	0.74559009	3659.0254
755.91309	2.237802	0.74694133	3654.7659
756.81396	2.2369189	0.74850172	3656.6863
757.71484	2.2430654	0.74999195	3662.0317
758.61572	2.2438972	0.75140929	3652.8584
759.5166	2.243412	0.75305176	3656.1313
760.41748	2.248467	0.75468105	3660.8428
761.31836	2.2496307	0.75604081	3651.4546
762.21924	2.255748	0.75752401	3657.979
763.12012	2.2564678	0.75912619	3659.5
764.021	2.260843	0.76104468	3663.8984
764.92188	2.2581584	0.76266682	3657.1855
765.82275	2.2639804	0.76440513	3661.8677
766.72363	2.2689273	0.76637083	3666.3755
767.62451	2.269043	0.76802015	3657.7456
768.52539	2.2732511	0.76981264	3664.54
769.42627	2.2751544	0.7713722	3655.0549
770.32715	2.2767959	0.77289337	3657.1804
771.22803	2.2817595	0.77439338	3663.0005
772.12891	2.2841554	0.77604663	3661.5776
773.02979	2.2883086	0.7777403	3659.1543
773.93066	2.2880659	0.77938247	3655.5127
774.83154	2.2925525	0.78084278	3659.8323
775.73242	2.2948103	0.78258044	3661.4724
776.6333	2.2967412	0.78416032	3662.3596
777.53418	2.30004	0.78586411	3665.5791
778.43506	2.3058059	0.78761816	3663.9055
779.33594	2.3066416	0.78926915	3663.2585
780.23682	2.3037486	0.79100966	3657.6079
781.1377	2.3124499	0.79282689	3662.7217
782.03857	2.3125648	0.7945286	3661.853
782.93945	2.3154235	0.79604518	3655.2241
783.84033	2.3167028	0.79763293	3659.5398
784.74121	2.3222191	0.79934329	3663.5674
785.64209	2.3202453	0.8009125	3659.5515
786.54297	2.3268929	0.80272186	3667.2827
787.44385	2.3272905	0.80419576	3661.3801
788.34473	2.3314722	0.8056736	3657.5127
789.24561	2.3364487	0.80716401	3664.6541
790.14648	2.3371363	0.80893147	3667.0889
791.04736	2.3402381	0.810579	3666.4756
791.94824	2.3434854	0.81230575	3668.1975
792.84912	2.3461049	0.81427747	3659.9578
793.75	2.3473399	0.81599212	3663.1809
794.65088	2.3509684	0.81774539	3661.9875
795.55176	2.3544502	0.8196016	3666.4219
796.45264	2.3569992	0.82165956	3665.2449
797.35352	2.3579826	0.82354558	3666.3662
798.25439	2.361577	0.8255198	3666.7803
799.15527	2.3628206	0.82749164	3663.0798
800.05615	2.3674223	0.8294611	3669.0808
800.95703	2.3693526	0.83115411	3661.6047
801.85791	2.3708844	0.83312649	3660.8296
802.75879	2.3756576	0.83497024	3664.2793
803.65967	2.3774226	0.83678842	3661.1311
804.56055	2.3800545	0.83859611	3663.0161
805.46143	2.3860095	0.84016818	3662.8481
806.3623	2.3841069	0.84181815	3662.3162
807.26318	2.3877244	0.8436048	3658.7424
808.16406	2.3924985	0.84533095	3663.2729
809.06494	2.3964262	0.84726238	3663.9702
809.96582	2.3981285	0.84894377	3663.562
810.8667	2.4005442	0.85069126	3659.4824
811.76758	2.40029	0.85249484	3660.6809
812.66846	2.4042985	0.85425681	3663.5007
813.56934	2.4054589	0.85627174	3663.5505
814.47021	2.4115679	0.85827911	3664.4143
815.37109	2.4134629	0.86046094	3660.2664
816.27197	2.4150753	0.86244673	3662.8005
817.17285	2.4192286	0.86448652	3656.8435
818.07373	2.4246318	0.86596179	3658.3796
818.97461	2.4248562	0.86780697	3665.8955
819.87549	2.4253509	0.86957449	3654.6504
820.77637	2.4300671	0.87138808	3665.5598
821.67725	2.4341383	0.87328833	3664.9583
822.57813	2.4365907	0.87552541	3667.9219
823.479	2.4381592	0.87773037	3665.7615
824.37988	2.4404266	0.87967336	3662.4314
825.28076	2.4418492	0.88150066	3660.0676
826.18164	2.444927	0.88335592	3660.7598
827.08252	2.4493253	0.88517255	3663.9272
827.9834	2.4527657	0.88713723	3663.2087
828.88428	2.4538438	0.88905907	3657.9844
829.78516	2.4570363	0.89104879	3663.4631
830.68604	2.4568706	0.89337355	3668.2283
831.58691	2.4629219	0.89575034	3655.5439
832.48779	2.4646816	0.89761782	3658.5938
833.38867	2.4660237	0.89971942	3662.2139
834.28955	2.4688234	0.90214938	3665.8149
835.19043	2.4732745	0.90470666	3667.0588
836.09131	2.4749229	0.90692109	3656.1123
836.99219	2.4771242	0.90935558	3660.2642
837.89307	2.4810786	0.91152543	3656.6423
838.79395	2.4816644	0.91353983	3655.9302
839.69482	2.4853663	0.91534543	3658.0759
840.5957	2.4886189	0.91732424	3653.8423
841.49658	2.4926517	0.91940093	3659.7595
842.39746	2.4949329	0.92175943	3658.4006
843.29834	2.4964819	0.92408848	3662.4993
844.19922	2.4992568	0.92648005	3656.9583
845.1001	2.502105	0.92852181	3653.4854
846.00098	2.5033283	0.93043387	3652.6287
846.90186	2.510232	0.93215078	3656.0488
847.80273	2.5097475	0.93407613	3658.3064
848.70361	2.5123866	0.93630236	3656.1423
849.60449	2.5173342	0.93859172	3664.3574
850.50537	2.5160587	0.94080746	3654.8843
851.40625	2.5213072	0.94293839	3652.0652
852.30713	2.5238533	0.94495285	3647.4531
853.20801	2.5282664	0.94700027	3649.7021
854.10889	2.5282536	0.94897491	3652.939
855.00977	2.5332532	0.95083588	3648.97
855.91064	2.5348451	0.9528414	3651.1321
856.81152	2.539609	0.95512444	3655.8508
857.7124	2.5410714	0.95720536	3649.8955
858.61328	2.5429196	0.95931298	3652.6125
859.51416	2.5443151	0.96162939	3651.8311
860.41504	2.5496273	0.96402675	3649.999
861.31592	2.5507145	0.96623635	3650.1819
862.2168	2.5516346	0.96822107	3644.8079
863.11768	2.5577834	0.97062504	3651.4155
864.01855	2.5577023	0.97297633	3648.4006
864.91943	2.5601299	0.97528756	3647.1304
865.82031	2.5636065	0.97769845	3648.2783
866.72119	2.5666246	0.97991198	3648.1484
867.62207	2.5712166	0.98198146	3646.3054
868.52295	2.5730741	0.98429066	3650.8425
869.42383	2.5745614	0.98715621	3647.7124
870.32471	2.5786252	0.98999649	3645.3379
871.22559	2.5794179	0.99238044	3642.2847
872.12646	2.5828137	0.99482548	3646.6399
873.02734	2.5875289	0.99739325	3644.1936
873.92822	2.5917265	0.99948269	3640.5918
874.8291	2.5926409	1.001536	3647.562
875.72998	2.5924888	1.0039595	3645.5164
876.63086	2.5978103	1.0069921	3640.1438
877.53174	2.5984726	1.0093961	3642.9597
878.43262	2.6034946	1.0116192	3637.728
879.3335	2.6032345	1.0136219	3631.978
880.23438	2.6082618	1.0157424	3637.1082
881.13525	2.6106584	1.0184019	3643.5308
882.03613	2.613802	1.0212951	3634.8481
882.93701	2.6168864	1.0239128	3641.4521
883.83789	2.6176739	1.0264682	3635.8342
884.73877	2.6185153	1.0291059	3635.7607
885.63965	2.6233644	1.0313795	3628.4961
886.54053	2.6254666	1.0338039	3634.2957
887.44141	2.6317019	1.0360153	3631.3264
888.34229	2.6314018	1.0382385	3632.1038
889.24316	2.63357	1.040714	3632.3613
890.14404	2.6381311	1.0429801	3631.9551
891.04492	2.6412344	1.0452547	3626.0315
891.9458	2.6447489	1.0476197	3629.4856
892.84668	2.6437483	1.0502614	3631.2295
893.74756	2.6495342	1.0527377	3627.9629
894.64844	2.6510384	1.0548788	3627.363
895.54932	2.6551085	1.0574051	3628.4961
896.4502	2.6547048	1.0602136	3622.9714
897.35107	2.6621785	1.0628998	3623.2515
898.25195	2.6605265	1.0658864	3625.5452
899.15283	2.6648426	1.0690916	3633.3408
900.05371	2.6668274	1.0719072	3617.241
900.95459	2.6706398	1.0749911	3623.5708
901.85547	2.6747487	1.077828	3621.6372
902.75635	2.6750062	1.0800924	3614.3171
903.65723	2.6786356	1.082413	3613.8035
904.55811	2.6784685	1.0847356	3616.7158
905.45898	2.6836329	1.0873603	3616.1902
906.35986	2.6857743	1.0900481	3620.0176
907.26074	2.6888742	1.0931813	3613.8369
908.16162	2.6881199	1.0956534	3605.5991
909.0625	2.6942255	1.0980769	3613.6316
909.96338	2.6974227	1.1005179	3609.2356
910.86426	2.697989	1.1031398	3608.3799
911.76514	2.7039185	1.10574	3608.5071
912.66602	2.7055459	1.1084812	3610.4436
913.56689	2.709703	1.1115247	3607.7407
914.46777	2.709564	1.1144346	3605.1128
915.36865	2.7130771	1.1172361	3606.8645
916.26953	2.7158618	1.1195396	3597.9604
917.17041	2.7213759	1.1220189	3599.0876
918.07129	2.7214203	1.1247289	3599.8999
918.97217	2.7213497	1.1274557	3601.2261
919.87305	2.7276626	1.12983	3601.3577
920.77393	2.7314019	1.1324012	3599.9978
921.6748	2.7305882	1.1348439	3597.186
922.57568	2.7350438	1.1378886	3602.0544
923.47656	2.7354293	1.1410333	3588.2905
924.37744	2.7355971	1.1436985	3588.0039
925.27832	2.7428272	1.146893	3591.3677
926.1792	2.7455707	1.1497564	3589.9937
927.08008	2.7457654	1.1521901	3581.8645
927.98096	2.7518647	1.1544429	3583.4573
928.88184	2.7543163	1.1570799	3584.2578
929.78271	2.756711	1.1597564	3584.1711
930.68359	2.7575457	1.16276	3588.0325
931.58447	2.7646041	1.1656501	3579.332
932.48535	2.763099	1.1683388	3579.8513
933.38623	2.7691145	1.1711521	3581.9233
934.28711	2.7693398	1.1739364	3578.6704
935.18799	2.7730758	1.1765125	3576.9209
936.08887	2.7732804	1.1791496	3571.8198
936.98975	2.7777948	1.1819859	3564.4155
937.89063	2.7830696	1.1848724	3572.2957
938.7915	2.7842796	1.1877283	3569.7969
939.69238	2.7840066	1.1901753	3566.6353
940.59326	2.7897398	1.1933801	3568.8977
941.49414	2.7897587	1.1969634	3563.2065
942.39502	2.7921636	1.2001396	3563.7595
943.2959	2.7973373	1.2029957	3561.9128
944.19678	2.7980175	1.2060006	3554.5339
945.09766	2.8003573	1.2085748	3555.5676
945.99854	2.8055327	1.2109897	3552.4045
946.89941	2.8067946	1.2136306	3552.5713
947.80029	2.8094893	1.2162229	3547.8804
948.70117	2.8137009	1.2186947	3547.9146
949.60205	2.8143246	1.2211388	3547.6782
950.50293	2.8195105	1.2240489	3546.2324
951.40381	2.8207164	1.227146	3547.0342
952.30469	2.8265562	1.2301404	3546.9961
953.20557	2.8272824	1.2325846	3536.4014
954.10645	2.8298538	1.235206	3543.0706
955.00732	2.8298035	1.2378459	3539.8547
955.9082	2.8325856	1.2405508	3536.6973
956.80908	2.8371794	1.2435967	3527.3772
957.70996	2.8400602	1.2468426	3538.3657
958.61084	2.8435369	1.2501373	3531.8801
959.51172	2.8431573	1.2528051	3524.6365
960.4126	2.8486001	1.2552588	3522.406
961.31348	2.8501966	1.2577887	3523.2285
962.21436	2.8567462	1.2604482	3524.3323
963.11523	2.8575263	1.2637265	3523.7129
964.01611	2.8593614	1.2666631	3520.0405
964.91699	2.8623955	1.2692826	3514.7053
965.81787	2.8659761	1.2717535	3516.7976
966.71875	2.8681753	1.2742186	3508.5154
967.61963	2.8715839	1.2769806	3515.5339
968.52051	2.8711596	1.2801352	3510.8811
969.42139	2.8774161	1.2832444	3509.1162
970.32227	2.8770237	1.2861612	3502.5813
971.22314	2.8814692	1.2892501	3507.2917
972.12402	2.8833373	1.2924292	3497.6594
973.0249	2.8857183	1.2948756	3494.2146
973.92578	2.8874893	1.2977235	3493.1921
974.82666	2.8900101	1.3010356	3498.325
975.72754	2.8949783	1.3044969	3492.907
976.62842	2.8985546	1.3076347	3489.0076
977.5293	2.8998146	1.310632	3487.2073
978.43018	2.9014904	1.3137687	3480.7585
979.33105	2.9042103	1.3162502	3474.324
980.23193	2.9107847	1.3189092	3477.3931
981.13281	2.9129241	1.3218119	3479.3542
982.03369	2.9114459	1.3243184	3470.9543
982.93457	2.9167626	1.3271493	3472.5361
983.83545	2.9182312	1.3300012	3464.1816
984.73633	2.9205053	1.3329042	3467.9316
985.63721	2.9249876	1.3360689	3464.9839
986.53809	2.9256189	1.3391386	3461.905
987.43896	2.9267974	1.342364	3452.6162
988.33984	2.9306202	1.3451581	3454.6196
989.24072	2.935353	1.3478506	3454.4075
990.1416	2.9358695	1.3508598	3448.9509
991.04248	2.9401627	1.3541899	3448.8594
991.94336	2.9426112	1.357937	3448.5229
992.84424	2.945308	1.3609375	3435.9172
993.74512	2.9458761	1.3635201	3428.7207
994.646	2.9502921	1.3661242	3436.3394
995.54688	2.955163	1.3685859	3433.5701
996.44775	2.9584489	1.3711549	3434.2063
997.34863	2.9579344	1.3732567	3420.1248
998.24951	2.9616559	1.3754604	3427.2998
999.15039	2.9655404	1.3778639	3423.6011
1000.0513	2.9674284	1.38118	3427.5376
1000.9521	2.9688406	1.3846992	3419.6736
1001.853	2.971489	1.3871865	3405.5671
1002.7539	2.9745388	1.3901035	3417.9221
1003.6548	2.9780226	1.3934708	3413.4634
1004.5557	2.9804144	1.3966523	3401.9368
1005.4565	2.9825227	1.3993306	3394.1716
1006.3574	2.9806678	1.4019749	3398.325
1007.2583	2.9872584	1.4041599	3389.5647
1008.1592	2.9919314	1.4062608	3387.6157
1009.0601	2.9943635	1.4084724	3394.5962
1009.9609	2.9977295	1.4106778	3388.1563
1010.8618	3.0004554	1.4131556	3389.0254
1011.7627	3.0018251	1.4160277	3384.4604
1012.6636	3.0018339	1.4189276	3381.2468
1013.5645	3.0070581	1.4225153	3382.7544
1014.4653	3.0109701	1.4259614	3378.7847
1015.3662	3.0136342	1.429358	3375.0527
1016.2671	3.0190382	1.4327645	3369.3628
1017.168	3.0195014	1.435879	3359.7732
1018.0688	3.0211537	1.4387711	3360.127
1018.9697	3.0232067	1.4414178	3359.2273
1019.8706	3.0246778	1.4442837	3353.5225
1020.7715	3.0302939	1.4473596	3346.9795
1021.6724	3.0332761	1.4505627	3345.3315
1022.5732	3.0360427	1.4535396	3340.5295
1023.4741	3.0378361	1.4565299	3339.3352
1024.375	3.0431721	1.4598598	3341.2166
1025.2759	3.0430431	1.46339	3333.5564
1026.1768	3.0444119	1.4660094	3319.1284
1027.0776	3.051898	1.4682151	3327.2566
1027.9785	3.0519469	1.4714513	3328.8904
1028.8794	3.0541217	1.4752303	3322.7969
1029.7803	3.0583575	1.4783435	3314.5632
1030.6812	3.0573711	1.4806805	3299.1499
1031.582	3.0634038	1.4831415	3307.9319
1032.4829	3.0654531	1.4861379	3308.5715
1033.3838	3.0665059	1.4891903	3298.5791
1034.2847	3.0700583	1.4924412	3295.8743
1035.1855	3.0711675	1.4952453	3289.6064
1036.0864	3.0726357	1.4980378	3288.7156
1036.9873	3.0788877	1.5007457	3283.3318
1037.8882	3.0795882	1.5039319	3281.6272
1038.7891	3.0844896	1.5071288	3271.241
1039.6899	3.0855074	1.510289	3272.7639
1040.5908	3.0878253	1.5135748	3265.7485
1041.4917	3.0918124	1.517036	3261.9321
1042.3926	3.0960135	1.5202202	3253.1633
1043.2935	3.0959392	1.52333	3250.5645
1044.1943	3.0997767	1.5265219	3247.4934
1045.0952	3.1034105	1.5300297	3244.7932
1045.9961	3.1058328	1.5332518	3237.5002
1046.897	3.1047666	1.536025	3222.0442
1047.7979	3.1104283	1.5384288	3222.696
1048.6987	3.113209	1.5410495	3220.4648
1049.5996	3.1170671	1.5445186	3219.9482
1050.5005	3.1174181	1.5480173	3207.6021
1051.4014	3.1206968	1.5517426	3207.5576
1052.3022	3.1214471	1.5551025	3193.7615
1053.2031	3.1301999	1.5586301	3190.3875
1054.104	3.1280491	1.5615498	3183.0881
1055.0049	3.1326113	1.5644755	3176.2268
1055.9058	3.1358068	1.5674983	3168.8857
1056.8066	3.1372967	1.5706773	3169.1042
1057.7075	3.1422622	1.5744102	3164.0027
1058.6084	3.1441045	1.5783011	3154.436
1059.5093	3.1466522	1.5817647	3139.905
1060.4102	3.1486294	1.5848402	3138.9836
1061.311	3.1521754	1.5884017	3137.2932
1062.2119	3.1554115	1.5912291	3121.9856
1063.1128	3.157943	1.5946106	3123.5039
1064.0137	3.1605637	1.5981451	3115.2644
1064.9146	3.1596105	1.6015234	3103.8699
1065.8154	3.1642258	1.6047609	3094.6204
1066.7163	3.166024	1.6071811	3087.9639
1067.6172	3.1698022	1.6100112	3082.7676
1068.5181	3.1748843	1.6131525	3076.3982
1069.4189	3.1772542	1.6164665	3070.1262
1070.3198	3.1792231	1.6201758	3058.9473
1071.2207	3.1811123	1.6236728	3047.9468
1072.1216	3.182785	1.6271216	3038.5791
1073.0225	3.1888795	1.6309371	3022.4307
1073.9233	3.1896756	1.6342869	3009.5083
1074.8242	3.1948061	1.6379983	3004.0427
1075.7251	3.1949911	1.641439	2991.061
1076.626	3.1986558	1.6450959	2981.7166
1077.5269	3.2020748	1.6498107	2964.2378
1078.4277	3.2044759	1.6540242	2948.3508
1079.3286	3.2081525	1.6587594	2929.8984
1080.2295	3.2112787	1.6646574	2893.8479
1081.1304	3.210988	1.6766366	2787.217
1081.2305	3.212898	1.6785151	2779.4536