File: datasets/am_bench_2022/raw_data/0-XY.05-1/specimen.dat
MTS793|MPT|ENU|1|2|.|/|:|1|0|0|A

Operator Information						Time:	36.144775	Sec	10/13/2021 12:01:35 PM
Operator	Nick Derimow
Project	AM Bench 2022 mini-tensile challenge
Specimen ID	O-XY.05-1
Material	PBF-L Inconel 625
Specimen Width	2.56	mm
Specimen Thickness	1.54	mm
Notes
Operator Information End

Data Acquisition						Time:	1037.1382	Sec	10/13/2021 12:18:16 PM
Time	Axial Displacement	Axial Extensometer	Axial Force
Sec	mm	mm	N
36.258057	0.00087337557	-7.9734755e-06	65.010124
37.158936	0.0026686301	0.00012058127	80.030685
38.059814	0.0075539993	0.00022959043	93.559547
38.960693	0.0081809144	0.00039645567	103.82375
39.861572	0.012041419	0.0004465761	116.03806
40.762451	0.010356652	0.0004308323	124.88886
41.66333	0.016311755	0.00049991638	136.84045
42.564209	0.014324314	0.00062293088	149.85405
43.465088	0.021970741	0.00089894462	167.21631
44.365967	0.026494274	0.0008632004	181.6761
45.266846	0.0259005	0.0010009926	196.93382
46.167725	0.028634565	0.001065692	210.51163
47.068604	0.033019796	0.0011979348	228.73328
47.969482	0.034170054	0.001311759	245.72098
48.870361	0.039233215	0.0014007257	274.9079
49.77124	0.040096626	0.0015789501	285.66788
50.672119	0.044074584	0.0017152743	309.16379
51.572998	0.043125734	0.0017881745	322.91498
52.473877	0.047264274	0.0018636963	341.74948
53.374756	0.051359124	0.0019945991	356.93738
54.275635	0.050453763	0.001926437	368.8692
55.176514	0.057401564	0.0021170287	390.56665
56.077393	0.058308974	0.0021649885	404.08609
56.978271	0.060300104	0.0023754053	427.97244
57.87915	0.063201308	0.002442043	445.89493
58.780029	0.064198107	0.0026722893	466.54269
59.680908	0.067853101	0.002722634	490.686
60.581787	0.07282985	0.0027621451	513.06628
61.482666	0.078417741	0.0030125189	527.85358
62.383545	0.079466581	0.0030850002	554.18073
63.284424	0.080212794	0.0031855146	570.38367
64.185303	0.084731661	0.0033520437	598.0943
65.086182	0.085829414	0.0033639029	613.23676
65.987061	0.086529531	0.0036080109	633.23816
66.887939	0.090600662	0.0036244269	658.5437
67.788818	0.092732295	0.0037608217	678.30176
68.689697	0.098462023	0.0038356469	700.39227
69.590576	0.098218665	0.0039739921	720.26654
70.491455	0.10075762	0.0041513592	744.65552
71.392334	0.10496557	0.0042731618	777.06262
72.293213	0.10902446	0.0043230066	802.46045
73.194092	0.10861591	0.0045263343	825.97607
74.094971	0.11048512	0.0046480498	854.6745
74.99585	0.1153477	0.0049901861	884.72144
75.896729	0.11657336	0.0050159856	899.90375
76.797607	0.11950816	0.0051085134	920.97217
77.698486	0.12255551	0.0051876199	941.42932
78.599365	0.12476137	0.0052731493	965.31744
79.500244	0.12866443	0.0054033678	983.55438
80.401123	0.13138068	0.0056120311	1022.7354
81.302002	0.13728496	0.0058557005	1060.0525
82.202881	0.13819981	0.0059828018	1083.6925
83.10376	0.1378396	0.0060799434	1105.0951
84.004639	0.14309578	0.0062878351	1129.3414
84.905518	0.14722306	0.0063886745	1157.5809
85.806396	0.1452858	0.0064494768	1186.4922
86.707275	0.14841777	0.0066230297	1199.8267
87.608154	0.15201847	0.0066813896	1227.9465
88.509033	0.15555382	0.0068906471	1254.7538
89.409912	0.16094075	0.006993542	1289.0798
90.310791	0.1606119	0.0072405557	1308.7256
91.21167	0.16335233	0.0072670183	1328.689
92.112549	0.16364756	0.0073368768	1351.5392
93.013428	0.16799736	0.0074740709	1371.4727
93.914307	0.16934855	0.007622119	1394.3812
94.815186	0.17425154	0.0078346953	1429.3386
95.716064	0.17412247	0.0079877805	1451.0159
96.616943	0.17660657	0.0080255941	1479.9888
97.517822	0.17852107	0.0081893494	1495.7285
98.418701	0.18719538	0.0082680648	1526.1133
99.31958	0.18865031	0.0086210947	1557.913
100.22046	0.190229	0.0086248852	1576.6556
101.12134	0.19106556	0.0087581249	1602.764
102.02222	0.19649631	0.0090289628	1632.0973
102.9231	0.19546677	0.0090580815	1646.5685
103.82397	0.20183121	0.0091710035	1675.0049
104.72485	0.20492649	0.0093285926	1704.0481
105.62573	0.20790002	0.0094509637	1723.7186
106.52661	0.20949197	0.009833388	1755.2867
107.42749	0.21116184	0.0098153828	1780.6411
108.32837	0.21414602	0.009992714	1798.9908
109.22925	0.21817581	0.010118892	1812.448
110.13013	0.21888638	0.010196041	1846.2538
111.03101	0.22311339	0.010510414	1869.6451
111.93188	0.22623137	0.010569048	1888.5182
112.83276	0.22639486	0.010730916	1911.3975
113.73364	0.23261981	0.011037515	1940.3683
114.63452	0.23305848	0.011162636	1962.6154
115.5354	0.23589781	0.011432741	1984.1571
116.43628	0.23792583	0.011424381	1999.934
117.33716	0.24277042	0.011576544	2019.0842
118.23804	0.24349307	0.011879008	2044.7618
119.13892	0.2474931	0.011770819	2050.1992
120.03979	0.2493801	0.012125108	2074.7593
120.94067	0.25360921	0.0122193	2097.1912
121.84155	0.25457567	0.012380117	2108.3813
122.74243	0.25766993	0.012572093	2133.5811
123.64331	0.26140976	0.012841042	2148.6462
124.54419	0.26365182	0.013028396	2166.9558
125.44507	0.26680547	0.013242083	2187.501
126.34595	0.26895559	0.013348196	2203.1331
127.24683	0.27265775	0.013666822	2218.6506
128.14771	0.27338058	0.013709852	2234.9082
129.04858	0.27312076	0.013936196	2240.1648
129.94946	0.279695	0.014052036	2268.4019
130.85034	0.2850402	0.01435396	2282.9324
131.75122	0.28748962	0.0145702	2302.011
132.6521	0.28937399	0.014707136	2314.7322
133.55298	0.29294923	0.015078775	2329.9839
134.45386	0.29301807	0.015135053	2338.8203
135.35474	0.29561386	0.015347797	2348.6311
136.25562	0.2982592	0.015680987	2371.5872
137.15649	0.3009547	0.015832892	2381.8096
138.05737	0.30290279	0.016235789	2396.78
138.95825	0.30735332	0.016337175	2405.1631
139.85913	0.31194288	0.016752202	2427.0894
140.76001	0.31241456	0.017004305	2433.4746
141.66089	0.31927112	0.017164443	2446.3762
142.56177	0.3210983	0.017512528	2460.5774
143.46265	0.3230302	0.017580273	2469.001
144.36353	0.32252762	0.0179612	2478.2742
145.2644	0.32477915	0.018299874	2485.9836
146.16528	0.32802889	0.018535241	2501.4939
147.06616	0.33242434	0.018855602	2511.6577
147.96704	0.33264932	0.019127812	2518.4114
148.86792	0.33802786	0.01945458	2532.4905
149.7688	0.34022549	0.019843172	2543.4121
150.66968	0.34352437	0.020090437	2547.8188
151.57056	0.34921208	0.020682249	2564.7568
152.47144	0.34422204	0.020841772	2567.3796
153.37231	0.35143414	0.021318894	2575.5518
154.27319	0.35557207	0.021647131	2588.0889
155.17407	0.35790142	0.022167433	2593.8689
156.07495	0.35874003	0.022553697	2604.4951
156.97583	0.36379629	0.022964085	2609.488
157.87671	0.36564767	0.023443365	2621.6255
158.77759	0.36749473	0.0239265	2629.8481
159.67847	0.36867508	0.024240078	2623.0972
160.57935	0.37228441	0.024822764	2637.2231
161.48022	0.37663233	0.025338694	2645.9077
162.3811	0.37724641	0.025877904	2645.3252
163.28198	0.3818191	0.026246348	2651.9063
164.18286	0.38459739	0.026798626	2661.5571
165.08374	0.38807085	0.027506188	2670.4167
165.98462	0.39288229	0.028101835	2682.1575
166.8855	0.39153185	0.028798474	2688.136
167.78638	0.39602119	0.029567469	2688.6343
168.68726	0.39597446	0.030183151	2694.5168
169.58813	0.40220386	0.03095765	2697.6245
170.48901	0.40357047	0.03160182	2704.8237
171.38989	0.40726399	0.03227051	2704.4629
172.29077	0.40924877	0.032953043	2708.6106
173.19165	0.40905577	0.03350234	2713.4756
174.09253	0.41651309	0.034167521	2714.0974
174.99341	0.41762975	0.034757882	2726.0996
175.89429	0.42164883	0.035834618	2734.8521
176.79517	0.4212999	0.036799263	2736.2041
177.69604	0.42362356	0.037553251	2736.0745
178.59692	0.42591995	0.038555257	2743.6514
179.4978	0.42951021	0.039448101	2744.9187
180.39868	0.43111756	0.040271178	2747.6494
181.29956	0.43339247	0.041212946	2751.0825
182.20044	0.43776309	0.04200913	2757.4924
183.10132	0.43889144	0.043269314	2761.3342
184.0022	0.44429907	0.04408624	2765.7429
184.90308	0.44649079	0.045116685	2771.5691
185.80396	0.44907749	0.046048649	2771.1897
186.70483	0.44876891	0.046928823	2772.2903
187.60571	0.45506144	0.047829401	2778.2278
188.50659	0.45583591	0.048872527	2781.5828
189.40747	0.46237025	0.050011862	2787.1531
190.30835	0.46340311	0.051306289	2796.8826
191.20923	0.4671874	0.052384607	2793.093
192.11011	0.46873078	0.053322643	2797.9771
193.01099	0.47223154	0.054485496	2802.3789
193.91187	0.4732683	0.055775695	2802.0837
194.81274	0.47657683	0.056992162	2801.9092
195.71362	0.48064736	0.057852361	2804.0864
196.6145	0.48033467	0.059129648	2809.0786
197.51538	0.48382822	0.060108047	2800.4343
198.41626	0.48709869	0.061398361	2816.8972
199.31714	0.4906199	0.062658422	2817.4514
200.21802	0.49087459	0.06357035	2818.0657
201.1189	0.49463382	0.064605482	2817.3108
202.01978	0.49947765	0.065933034	2832.5715
202.92065	0.49998537	0.066832885	2822.8911
203.82153	0.50164962	0.067898601	2832.1348
204.72241	0.50737488	0.068922572	2830.5613
205.62329	0.51014227	0.070173278	2833.031
206.52417	0.5105744	0.071073033	2833.6289
207.42505	0.51380265	0.07208626	2828.2209
208.32593	0.51654381	0.07326331	2841.2966
209.22681	0.52085406	0.074554704	2843.957
210.12769	0.52066785	0.075796224	2847.8391
211.02856	0.52605969	0.077003025	2845.761
211.92944	0.52793974	0.078191951	2839.3044
212.83032	0.52747774	0.079405457	2845.2207
213.7312	0.53296357	0.080455117	2850.8054
214.63208	0.53658497	0.081724405	2848.4229
215.53296	0.53773075	0.082777977	2854.7009
216.43384	0.539635	0.084168546	2856.0632
217.33472	0.54654485	0.085455239	2858.71
218.2356	0.54688907	0.086865239	2861.6938
219.13647	0.55099171	0.088277899	2867.9099
220.03735	0.551799	0.089334182	2866.0742
220.93823	0.55335271	0.09067452	2867.9175
221.83911	0.56219643	0.092404656	2879.9714
222.73999	0.56224114	0.093526855	2869.688
223.64087	0.56185287	0.095005944	2868.6201
224.54175	0.5673669	0.096267022	2879.4478
225.44263	0.56928706	0.097576886	2880.3933
226.34351	0.57033569	0.098697506	2873.0713
227.24438	0.57235855	0.099802025	2873.9739
228.14526	0.57551485	0.10099043	2878.8206
229.04614	0.58096474	0.1020709	2882.7275
229.94702	0.57914633	0.10327261	2882.8672
230.8479	0.58521813	0.10473625	2887.9912
231.74878	0.58650649	0.1061627	2888.9155
232.64966	0.58860618	0.10738486	2881.053
233.55054	0.59187973	0.10864666	2890.6443
234.45142	0.59374177	0.10995566	2890.3074
235.35229	0.5994702	0.11135216	2897.761
236.25317	0.600214	0.11244182	2896.4277
237.15405	0.60189199	0.11367615	2900.7932
238.05493	0.60781908	0.11483517	2898.8323
238.95581	0.60822088	0.11614164	2901.2715
239.85669	0.61097127	0.11744523	2904.2393
240.75757	0.61519259	0.11873985	2901.9331
241.65845	0.61520857	0.12010691	2902.8352
242.55933	0.61839849	0.1214967	2906.6733
243.46021	0.6238786	0.12275822	2907.9834
244.36108	0.62567753	0.12397574	2907.1897
245.26196	0.62808108	0.12513092	2902.8762
246.16284	0.63095343	0.12661923	2910.7212
247.06372	0.63389707	0.12791756	2914.7996
247.9646	0.63708657	0.12926891	2915.2737
248.86548	0.63763547	0.13035563	2915.2329
249.76636	0.6384151	0.13153793	2907.5378
250.66724	0.6451239	0.13295402	2913.8105
251.56812	0.64276052	0.13430171	2913.55
252.46899	0.65191501	0.1356599	2921.8706
253.36987	0.65063995	0.13706419	2915.9114
254.27075	0.65576255	0.13824055	2923.7671
255.17163	0.65980297	0.13958715	2928.248
256.07251	0.66079426	0.14084274	2925.2825
256.97339	0.66137367	0.14230385	2929.3657
257.87427	0.66683024	0.14386797	2934.3254
258.77515	0.66552246	0.14522818	2927.4348
259.67603	0.67067003	0.14640683	2929.0388
260.5769	0.67255235	0.14761642	2933.2556
261.47778	0.67898202	0.14900151	2940.2764
262.37866	0.68023181	0.15018688	2936.6614
263.27954	0.68276745	0.15158546	2937.1682
264.18042	0.68459529	0.15315568	2941.157
265.0813	0.68845892	0.15478511	2947.7161
265.98218	0.68919748	0.15612085	2938.9089
266.88306	0.69341534	0.15763693	2941.5671
267.78394	0.69430375	0.15853651	2939.0349
268.68481	0.69681424	0.1601283	2943.9373
269.58569	0.6983974	0.16156138	2944.1653
270.48657	0.70293814	0.16289297	2944.7732
271.38745	0.70587873	0.16417053	2948.927
272.28833	0.70843613	0.16552413	2947.1028
273.18921	0.71137893	0.1665832	2946.9146
274.09009	0.71527743	0.16808392	2958.9912
274.99097	0.71792167	0.16928707	2950.5249
275.89185	0.72162646	0.17053397	2958.5378
276.79272	0.72080857	0.17176634	2954.8481
277.6936	0.72365934	0.17307003	2955.061
278.59448	0.72807169	0.17433012	2955.1658
279.49536	0.73119521	0.17578304	2960.6138
280.39624	0.73172665	0.17705114	2958.7529
281.29712	0.73788989	0.1781088	2950.6758
282.198	0.73804295	0.17950808	2966.686
283.09888	0.7419064	0.18100253	2967.6716
283.99976	0.74396199	0.18251695	2967.7109
284.90063	0.74819809	0.1840778	2969.0811
285.80151	0.75165433	0.18507928	2955.7913
286.70239	0.75144839	0.18599099	2958.5308
287.60327	0.75446564	0.18704581	2963.2224
288.50415	0.75535876	0.18876104	2973.907
289.40503	0.75867319	0.19047953	2974.4299
290.30591	0.76385379	0.19199978	2975.8569
291.20679	0.76557058	0.19327554	2968.4209
292.10767	0.76600206	0.19450572	2972.7473
293.00854	0.76895088	0.19594727	2975.3962
293.90942	0.77376056	0.19736315	2977.0884
294.8103	0.77750099	0.19876757	2982.5115
295.71118	0.78106159	0.20027487	2984.3921
296.61206	0.78130049	0.20156191	2978.8225
297.51294	0.78420705	0.20293121	2981.3337
298.41382	0.78738976	0.20416968	2979.7854
299.3147	0.79017395	0.2052463	2982.022
300.21558	0.79441398	0.20671706	2988.6445
301.11646	0.79418266	0.20792717	2983.7354
302.01733	0.79903895	0.20933326	2991.5989
302.91821	0.8020553	0.21063901	2987.4163
303.81909	0.80192703	0.21212032	2993.439
304.71997	0.80904979	0.21341829	2988.5857
305.62085	0.80709863	0.21471809	2992.5688
306.52173	0.80789036	0.21591984	2980.019
307.42261	0.81211573	0.21703391	2994.6743
308.32349	0.81542367	0.21844919	2993.0017
309.22437	0.82155764	0.21984917	3000.2405
310.12524	0.82278472	0.22132759	3002.875
311.02612	0.82348049	0.22276177	2997.5867
311.927	0.82465494	0.22390516	2995.9646
312.82788	0.83107919	0.22548547	3009.449
313.72876	0.83338666	0.22679542	2999.3701
314.62964	0.83660281	0.22802141	3000.9448
315.53052	0.83690292	0.22932872	3006.1028
316.4314	0.84135455	0.23046798	3001.8582
317.33228	0.84526402	0.23157232	3003.1943
318.23315	0.84678209	0.23294832	3008.2537
319.13403	0.85107595	0.23433933	3017.5667
320.03491	0.85448319	0.23580445	3013.927
320.93579	0.8544789	0.23739664	3010.2961
321.83667	0.85712296	0.23863716	3009.9927
322.73755	0.86238641	0.24010827	3020.4165
323.63843	0.8629964	0.24160966	3014.7239
324.53931	0.86653215	0.24322914	3017.2444
325.44019	0.87023139	0.24449697	3016.6914
326.34106	0.87288731	0.24592721	3012.8953
327.24194	0.87089151	0.2469036	3013.3699
328.14282	0.87607175	0.24837358	3014.7856
329.0437	0.87783498	0.2495482	3019.751
329.94458	0.88347417	0.25093323	3021.0696
330.84546	0.88573056	0.25208765	3018.0713
331.74634	0.88703471	0.25389951	3026.6301
332.64722	0.89168441	0.25527021	3030.7234
333.5481	0.89121997	0.25690392	3025.7563
334.44897	0.8952294	0.25812113	3023.9282
335.34985	0.89845294	0.25934279	3026.4399
336.25073	0.90172684	0.26093912	3031.2393
337.15161	0.901263	0.26213577	3025.7368
338.05249	0.90730602	0.26336992	3027.7556
338.95337	0.90932679	0.26479587	3030.4299
339.85425	0.9114607	0.2660054	3026.7563
340.75513	0.91536897	0.26748696	3034.6704
341.65601	0.92054957	0.26848504	3031.6125
342.55688	0.91954154	0.26959309	3031.9099
343.45776	0.92060369	0.27110377	3035.8225
344.35864	0.92799419	0.27244329	3038.103
345.25952	0.92984784	0.27371103	3044.6311
346.1604	0.9309628	0.27508047	3043.1658
347.06128	0.93162644	0.2763952	3044.6238
347.96216	0.9358502	0.27782413	3046.2693
348.86304	0.93854469	0.27929246	3040.894
349.76392	0.94075441	0.28060973	3039.1438
350.66479	0.94469178	0.28192544	3047.7051
351.56567	0.94661552	0.28333548	3045.0464
352.46655	0.95138526	0.28466108	3053.0986
353.36743	0.9510507	0.28608441	3043.22
354.26831	0.95286906	0.28726637	3043.6863
355.16919	0.95585006	0.28850332	3043.2522
356.07007	0.96102923	0.28998595	3053.4543
356.97095	0.96389621	0.29122341	3044.9414
357.87183	0.96689844	0.29238284	3047.9478
358.77271	0.96915245	0.29397929	3061.4849
359.67358	0.97038156	0.29535937	3050.9097
360.57446	0.97219992	0.29667059	3054.3748
361.47534	0.97403902	0.29817197	3054.3113
362.37622	0.98111159	0.29945335	3053.3535
363.2771	0.98069358	0.30073979	3054.4543
364.17798	0.98248553	0.30199838	3059.2002
365.07886	0.98736066	0.30345917	3060.884
365.97974	0.98992342	0.30467165	3056.9385
366.88062	0.9918471	0.30592105	3063.2441
367.78149	0.99620819	0.30722237	3066.2766
368.68237	0.9993813	0.30871481	3066.2759
369.58325	1.0007432	0.31009117	3062.709
370.48413	1.0053183	0.31131878	3059.4761
371.38501	1.0036902	0.31250337	3057.7546
372.28589	1.0088334	0.31374952	3063.2188
373.18677	1.0116365	0.31506398	3066.6741
374.08765	1.0141474	0.31632179	3068.6116
374.98853	1.0194669	0.3178733	3071.4045
375.8894	1.0196851	0.319251	3073.6069
376.79028	1.0246936	0.32088476	3076.2681
377.69116	1.0261942	0.32214856	3074.6709
378.59204	1.0265985	0.32350269	3073.6047
379.49292	1.0292823	0.3248722	3073.1965
380.3938	1.0326126	0.32608971	3076.0271
381.29468	1.0344245	0.32745707	3073.0229
382.19556	1.0392205	0.32889301	3083.1091
383.09644	1.0431744	0.33024937	3077.3691
383.99731	1.0449288	0.3317169	3081.7673
384.89819	1.0504926	0.33329564	3086.9338
385.79907	1.0458233	0.3346377	3078.5906
386.69995	1.0495006	0.33591244	3079.8059
387.60083	1.0544561	0.33712929	3079.1045
388.50171	1.0598511	0.3385219	3092.0845
389.40259	1.0587276	0.33985591	3080.7949
390.30347	1.0607692	0.34134316	3085.6985
391.20435	1.0653708	0.34277278	3082.8745
392.10522	1.0685201	0.34405756	3089.6716
393.0061	1.0716298	0.34537128	3087.7109
393.90698	1.0739461	0.34643856	3088.8701
394.80786	1.0762639	0.34792563	3090.99
395.70874	1.07751	0.34928069	3092.4636
396.60962	1.0809923	0.35081679	3094.3862
397.5105	1.0833539	0.35236698	3093.6858
398.41138	1.0868925	0.35363442	3092.0251
399.31226	1.0886135	0.3548381	3096.2051
400.21313	1.0894526	0.35618305	3098.4893
401.11401	1.0972244	0.35747942	3095.4993
402.01489	1.1007411	0.35880435	3100.1909
402.91577	1.1023941	0.35993081	3091.3003
403.81665	1.1042632	0.36138326	3105.2063
404.71753	1.1059021	0.3625977	3098.6736
405.61841	1.1083748	0.36403996	3100.6826
406.51929	1.1141379	0.36534336	3097.5542
407.42017	1.1163895	0.36654216	3101.3391
408.32104	1.1169702	0.3678638	3108.624
409.22192	1.1201205	0.36919329	3106.241
410.1228	1.1230096	0.37059864	3111.3542
411.02368	1.124048	0.37226495	3108.6042
411.92456	1.1281933	0.37363663	3108.2554
412.82544	1.1280122	0.37478715	3100.853
413.72632	1.1348536	0.3758007	3109.8433
414.6272	1.1353612	0.37693301	3110.6648
415.52808	1.1392177	0.37838224	3112.342
416.42896	1.1429797	0.37984082	3115.0591
417.32983	1.1447635	0.38111863	3117.0833
418.23071	1.1466372	0.38220635	3108.2268
419.13159	1.150755	0.38335678	3109.4343
420.03247	1.1540148	0.38446221	3115.7952
420.93335	1.1519483	0.3856025	3111.3477
421.83423	1.1567657	0.38692641	3117.6411
422.73511	1.1596937	0.38845935	3116.1223
423.63599	1.1622679	0.38973403	3116.2227
424.53687	1.1669343	0.3912344	3118.2666
425.43774	1.1719311	0.39254335	3123.3174
426.33862	1.1739358	0.39410055	3125.48
427.2395	1.172052	0.39532602	3117.9436
428.14038	1.1776997	0.39658561	3121.2183
429.04126	1.1773587	0.39800504	3116.854
429.94214	1.1844292	0.39927757	3124.4666
430.84302	1.1848768	0.40053463	3126.5767
431.7439	1.1873281	0.40194309	3129.4561
432.64478	1.1916811	0.40313292	3121.4177
433.54565	1.192582	0.40451264	3130.9971
434.44653	1.1931918	0.40572235	3126.3152
435.34741	1.1984595	0.40723225	3123.1125
436.24829	1.1978112	0.40826026	3124.2793
437.14917	1.2040424	0.40952247	3131.9434
438.05005	1.2073387	0.41083255	3127.3933
438.95093	1.2065923	0.41220024	3131.0518
439.85181	1.2115134	0.41359216	3133.3843
440.75269	1.2147268	0.41497955	3137.7063
441.65356	1.2160307	0.41655168	3135.967
442.55444	1.2201186	0.41797441	3129.9922
443.45532	1.2227203	0.41924316	3135.7402
444.3562	1.2218053	0.42080343	3135.1167
445.25708	1.2274418	0.42223036	3137.4905
446.15796	1.22991	0.42355344	3138.6995
447.05884	1.2322595	0.42490628	3139.9382
447.95972	1.2359127	0.42616504	3147.8164
448.8606	1.2376243	0.42753583	3134.1221
449.76147	1.2421807	0.42860317	3134.2163
450.66235	1.2457699	0.42976514	3141.0193
451.56323	1.2475319	0.43106374	3154.1538
452.46411	1.2488055	0.43229049	3142.3333
453.36499	1.2555711	0.43373129	3151.354
454.26587	1.2526304	0.43510473	3141.293
455.16675	1.2550991	0.43633074	3142.0493
456.06763	1.2607996	0.43758696	3147.8599
456.96851	1.261156	0.43873659	3142.9072
457.86938	1.2634416	0.43991625	3143.5408
458.77026	1.2669746	0.4411068	3148.3821
459.67114	1.2683086	0.44255108	3147.9712
460.57202	1.2732246	0.44386864	3144.7507
461.4729	1.2749442	0.44521764	3152.3535
462.37378	1.278686	0.44658872	3149.9724
463.27466	1.2811191	0.4480387	3158.5728
464.17554	1.2881134	0.44911158	3151.1777
465.07642	1.2872565	0.45029843	3148.5977
465.97729	1.2905344	0.45151815	3151.7144
466.87817	1.2905167	0.45299023	3153.5696
467.77905	1.2968187	0.45442334	3156.4524
468.67993	1.2976552	0.45575485	3152.584
469.58081	1.3008833	0.45718521	3166.1155
470.48169	1.3039321	0.45860493	3160.4609
471.38257	1.3034897	0.45990384	3156.3032
472.28345	1.3088695	0.46124166	3160.1226
473.18433	1.3108144	0.46271899	3161.259
474.08521	1.313484	0.46399319	3159.321
474.98608	1.3195829	0.46531141	3159.0022
475.88696	1.3175374	0.46664378	3162.9099
476.78784	1.3198165	0.46768096	3160.179
477.68872	1.3243877	0.46902156	3165.3389
478.5896	1.329969	0.47050062	3171.5264
479.49048	1.3335968	0.47168368	3170.5378
480.39136	1.333568	0.47307068	3164.115
481.29224	1.3372293	0.47431841	3172.0808
482.19312	1.3398951	0.47575417	3167.4221
483.09399	1.342629	0.47684646	3162.4805
483.99487	1.3411994	0.47791386	3165.1816
484.89575	1.3432741	0.47932884	3171.5229
485.79663	1.3507575	0.4808071	3172.6157
486.69751	1.3512039	0.48203942	3170.9739
487.59839	1.355159	0.48358721	3176.1309
488.49927	1.3593247	0.48506144	3177.2063
489.40015	1.3645524	0.48669294	3174.4836
490.30103	1.3639611	0.48768553	3169.8564
491.2019	1.3647875	0.48880231	3170.4675
492.10278	1.367358	0.49006104	3176.1111
493.00366	1.3722095	0.49130011	3179.114
493.90454	1.3752404	0.49254593	3177.9011
494.80542	1.3783617	0.49373946	3182.5684
495.7063	1.3791434	0.49502605	3180.1509
496.60718	1.383617	0.49634206	3180.0784
497.50806	1.3865161	0.497253	3172.2937
498.40894	1.3877685	0.4986414	3180.5835
499.30981	1.3921751	0.49980047	3184.3301
500.21069	1.393798	0.50129616	3182.1516
501.11157	1.3933479	0.50276351	3180.8296
502.01245	1.400236	0.5041368	3189.9387
502.91333	1.4000065	0.50543815	3186.5496
503.81421	1.4043633	0.50684994	3185.4219
504.71509	1.4031192	0.50837576	3187.3052
505.61597	1.4056098	0.50989062	3185.1497
506.51685	1.4154353	0.51122218	3193.0222
507.41772	1.4139934	0.51246417	3187.2734
508.3186	1.4190532	0.51388144	3191.895
509.21948	1.4185799	0.515342	3187.4702
510.12036	1.4199688	0.51696819	3189.7961
511.02124	1.4247216	0.51830453	3188.1365
511.92212	1.4278494	0.51970726	3187.2683
512.823	1.431046	0.5209192	3193.9084
513.72388	1.4316514	0.5222978	3190.166
514.62476	1.4388396	0.52354068	3197.0481
515.52563	1.4380696	0.52503031	3191.9719
516.42651	1.4454234	0.52621084	3200.6367
517.32739	1.444384	0.52761358	3199.3857
518.22827	1.4480934	0.52906179	3203.6597
519.12915	1.4484416	0.53035283	3187.5569
520.03003	1.4504341	0.53151935	3194.3572
520.93091	1.4507097	0.53295201	3200.04
521.83179	1.4558327	0.53405315	3198.0376
522.73267	1.4591144	0.53523397	3194.7009
523.63354	1.4612191	0.53655457	3199.5515
524.53442	1.4679139	0.5378657	3200.8337
525.4353	1.4675413	0.53931206	3198.2498
526.33618	1.4691674	0.5405978	3197.0862
527.23706	1.473214	0.54159838	3196.8408
528.13794	1.4735943	0.5428701	3202.5464
529.03882	1.4791734	0.54451233	3213.011
529.9397	1.4821671	0.54608309	3211.1257
530.84058	1.4852754	0.54723185	3201.7979
531.74146	1.4854008	0.54875666	3204.9263
532.64233	1.4896686	0.54988873	3208.6628
533.54321	1.4893894	0.55106801	3204.2732
534.44409	1.4983838	0.55219597	3208.3567
535.34497	1.4988911	0.55340743	3208.8555
536.24585	1.499927	0.55470139	3211.4885
537.14673	1.5024505	0.55633599	3211.844
538.04761	1.507241	0.55780387	3215.064
538.94849	1.5097709	0.55937636	3212.0588
539.84937	1.5098625	0.56058812	3207.825
540.75024	1.5116023	0.56189358	3213.0962
541.65112	1.5160398	0.56335282	3211.062
542.552	1.5213854	0.56483287	3220.843
543.45288	1.5196966	0.56605655	3206.0137
544.35376	1.5268273	0.56720072	3210.7551
545.25464	1.5273942	0.56865132	3214.7144
546.15552	1.5315913	0.56976151	3216.6304
547.0564	1.5355184	0.57104468	3219.3577
547.95728	1.5371914	0.57231575	3217.5718
548.85815	1.5382245	0.57382774	3222.0435
549.75903	1.5396391	0.57527298	3222.9209
550.65991	1.5442393	0.57675457	3218.073
551.56079	1.5468197	0.57788849	3214.7642
552.46167	1.5501008	0.57933563	3219.2651
553.36255	1.553234	0.58062291	3224.1638
554.26343	1.557174	0.58225	3223.8823
555.16431	1.5578763	0.58360046	3220.1521
556.06519	1.5606498	0.58511925	3221.4946
556.96606	1.5631678	0.58640397	3226.3599
557.86694	1.5696943	0.58765572	3223.2944
558.76782	1.5698206	0.58889616	3226.5166
559.6687	1.5703468	0.59021318	3219.9954
560.56958	1.5747511	0.59119707	3221.6309
561.47046	1.5754373	0.5927586	3229.9724
562.37134	1.576756	0.59438819	3231.3975
563.27222	1.5827123	0.59583396	3227.5801
564.1731	1.5853503	0.59717214	3227.3728
565.07397	1.5871825	0.59839261	3220.3245
565.97485	1.5865448	0.59962851	3227.2283
566.87573	1.5904924	0.60078633	3223.2109
567.77661	1.5954326	0.60196358	3222.5149
568.67749	1.5979439	0.60331136	3221.8843
569.57837	1.6013418	0.60473216	3238.196
570.47925	1.6041861	0.60616028	3234.2295
571.38013	1.606016	0.60754979	3236.8892
572.28101	1.6102017	0.60886759	3243.4431
573.18188	1.6110414	0.61029649	3235.2878
574.08276	1.6122773	0.61155379	3233.9871
574.98364	1.6180488	0.61305493	3239.9548
575.88452	1.6193724	0.61435628	3232.6248
576.7854	1.6206822	0.61580557	3235.04
577.68628	1.6269732	0.61719328	3239.7129
578.58716	1.6270707	0.61865401	3238.4585
579.48804	1.6312686	0.62014645	3244.3296
580.38892	1.6331803	0.62167352	3241.3865
581.28979	1.6351328	0.62296909	3235.6982
582.19067	1.639096	0.62413698	3236.3003
583.09155	1.6385131	0.62547064	3241.1348
583.99243	1.6412392	0.62686253	3239.5842
584.89331	1.6479101	0.6281473	3248.4685
585.79419	1.6506681	0.62972677	3244.2056
586.69507	1.6509873	0.63093925	3237.502
587.59595	1.65391	0.632276	3243.1785
588.49683	1.6586791	0.63374984	3244.5747
589.39771	1.6619624	0.63514829	3242.1206
590.29858	1.6622275	0.63639778	3243.7891
591.19946	1.6668154	0.63779807	3243.7373
592.10034	1.6673468	0.6389032	3240.6494
593.00122	1.6701205	0.64037079	3245.074
593.9021	1.6745872	0.64154476	3243.5605
594.80298	1.6737843	0.64279819	3244.949
595.70386	1.678551	0.64409667	3247.7673
596.60474	1.6831473	0.64520049	3248.8892
597.50562	1.6878109	0.64663094	3251.5415
598.40649	1.689899	0.64818531	3252.1543
599.30737	1.6932034	0.64984697	3253.1614
600.20825	1.6910744	0.65117234	3256.8403
601.10913	1.6945374	0.65269309	3252.2312
602.01001	1.6986266	0.65400577	3249.7678
602.91089	1.6998864	0.65510237	3247.5994
603.81177	1.7065369	0.65618151	3251.76
604.71265	1.7083151	0.65772265	3262.76
605.61353	1.7109076	0.65910846	3254.2505
606.5144	1.71155	0.66081947	3258.6516
607.41528	1.713632	0.66216505	3258.7949
608.31616	1.7197516	0.66386551	3262.9656
609.21704	1.7202461	0.66510338	3256.5515
610.11792	1.7260507	0.66646504	3257.6357
611.0188	1.7253674	0.66794169	3264.5288
611.91968	1.7295717	0.66943049	3261.095
612.82056	1.7319745	0.67087597	3256.0781
613.72144	1.733623	0.67230177	3259.4551
614.62231	1.7342944	0.67355973	3257.5352
615.52319	1.7392579	0.67499727	3262.564
616.42407	1.7399317	0.67647403	3258.3445
617.32495	1.7462767	0.67805576	3264.3713
618.22583	1.746533	0.67933625	3256.0728
619.12671	1.7500452	0.68076593	3259.9043
620.02759	1.7518419	0.68243343	3266.0774
620.92847	1.7554219	0.68396127	3260.4277
621.82935	1.7583914	0.68512011	3262.9426
622.73022	1.7593714	0.68644148	3253.4321
623.6311	1.7625209	0.68779773	3267.5942
624.53198	1.769843	0.68917531	3267.2751
625.43286	1.7667248	0.69060326	3261.8391
626.33374	1.771798	0.69193619	3264.7585
627.23462	1.7754242	0.69311219	3261.5952
628.1355	1.7744553	0.69435346	3271.1013
629.03638	1.7795074	0.69591457	3273.5725
629.93726	1.7811987	0.69714159	3263.5854
630.83813	1.7833678	0.69843566	3263.2593
631.73901	1.7859979	0.69987506	3269.1951
632.63989	1.7930744	0.70128566	3272.6277
633.54077	1.7939916	0.70289153	3277.4656
634.44165	1.7949448	0.70434612	3269.6177
635.34253	1.7952365	0.70589358	3264.6963
636.24341	1.8009113	0.70745403	3266.8816
637.14429	1.8035935	0.70875621	3268.9238
638.04517	1.8034083	0.71036136	3265.7046
638.94604	1.8080496	0.71149457	3269.5566
639.84692	1.810599	0.71282572	3267.293
640.7478	1.8138801	0.7143563	3275.4712
641.64868	1.8168586	0.71572703	3267.5215
642.54956	1.8212742	0.71699572	3276.8733
643.45044	1.82031	0.71863699	3273.0544
644.35132	1.8227075	0.72005618	3270.7639
645.2522	1.8270619	0.72139555	3269.5923
646.15308	1.8298057	0.72262502	3271.8853
647.05396	1.8318917	0.72420597	3279.2412
647.95483	1.8344097	0.72579747	3281.1367
648.85571	1.8376464	0.72721761	3265.8142
649.75659	1.843647	0.72887123	3277.4285
650.65747	1.8390061	0.73061943	3277.9524
651.55835	1.8466742	0.73207289	3278.4163
652.45923	1.8490771	0.73332036	3275.8279
653.36011	1.854965	0.73466355	3282.0237
654.26099	1.8575765	0.73594904	3277.1333
655.16187	1.8574601	0.73720562	3278.8809
656.06274	1.8601807	0.73891199	3281.1206
656.96362	1.866004	0.74038851	3284.2559
657.8645	1.8646644	0.74179173	3276.1196
658.76538	1.8668073	0.74328262	3280.4543
659.66626	1.86948	0.74491286	3284.9185
660.56714	1.8764797	0.74639475	3279.3279
661.46802	1.8768363	0.74769789	3284.3879
662.3689	1.8808304	0.74920046	3284.7744
663.26978	1.8823793	0.7506007	3282.6877
664.17065	1.8839502	0.75199276	3284.1353
665.07153	1.8866916	0.75348431	3282.8623
665.97241	1.8875912	0.7548216	3281.9292
666.87329	1.8904413	0.7562297	3281.4351
667.77417	1.8968633	0.75779009	3281.9438
668.67505	1.8981012	0.75911665	3282.5452
669.57593	1.9005744	0.76057041	3290.3313
670.47681	1.8998024	0.76190728	3282.9187
671.37769	1.9079512	0.7634663	3288.0459
672.27856	1.9101454	0.7648983	3287.8572
673.17944	1.9100088	0.76619548	3285.0864
674.08032	1.913229	0.76778388	3285.7739
674.9812	1.91426	0.7692681	3282.7971
675.88208	1.9202886	0.77042931	3282.4272
676.78296	1.9212315	0.7722159	3291.1501
677.68384	1.9227532	0.77361524	3287.6047
678.58472	1.9256879	0.77523488	3284.9846
679.4856	1.9308933	0.77645886	3282.1741
680.38647	1.9328983	0.77789468	3288.5376
681.28735	1.9350688	0.77929509	3288.3787
682.18823	1.937822	0.78097606	3297.0007
683.08911	1.9425185	0.78248745	3293.6587
683.98999	1.9454998	0.78396356	3290.1375
684.89087	1.9456626	0.78518593	3292.1956
685.79175	1.9488946	0.78712201	3293.2529
686.69263	1.9507716	0.78861243	3291.314
687.59351	1.9535152	0.79030991	3291.5928
688.49438	1.9552287	0.79190964	3294.1414
689.39526	1.9629332	0.79349315	3295.7561
690.29614	1.9614489	0.7951349	3293.1226
691.19702	1.9669049	0.79639298	3297.593
692.0979	1.9678741	0.79817432	3292.8875
692.99878	1.9690344	0.79976869	3298.3323
693.89966	1.9715928	0.80122286	3291.1448
694.80054	1.9774499	0.80254215	3299.5029
695.70142	1.9755356	0.80390769	3287.7683
696.60229	1.9790751	0.80522543	3287.6584
697.50317	1.985041	0.80667436	3302.2932
698.40405	1.9867007	0.8082605	3296.2036
699.30493	1.9874946	0.8100397	3297.4849
700.20581	1.993798	0.81164873	3302.8806
701.10669	1.9954354	0.8132813	3299.7139
702.00757	1.9981197	0.81464452	3294.3174
702.90845	2.0029049	0.81616747	3298.5518
703.80933	2.0024436	0.81735522	3290.4863
704.71021	2.0041361	0.81895608	3304.4658
705.61108	2.0076554	0.82051015	3303.3586
706.51196	2.0133247	0.82197326	3301.085
707.41284	2.0139298	0.82337314	3298.2271
708.31372	2.0166512	0.82501197	3296.2734
709.2146	2.0187409	0.82667953	3298.0229
710.11548	2.0216651	0.82842171	3303.1345
711.01636	2.0261414	0.82992339	3301.9883
711.91724	2.0282383	0.83156091	3304.1023
712.81812	2.0311425	0.8332274	3305.5273
713.71899	2.031461	0.83495581	3296.5703
714.61987	2.036442	0.83638519	3299.616
715.52075	2.0371368	0.8377642	3301.3044
716.42163	2.0416553	0.83921778	3298.1213
717.32251	2.04496	0.84048676	3302.4863
718.22339	2.0475748	0.84203225	3301.103
719.12427	2.0479012	0.84363782	3301.8425
720.02515	2.0533347	0.8454178	3306.3926
720.92603	2.0549598	0.84726429	3310.2107
721.8269	2.0580165	0.84898257	3306.606
722.72778	2.0599043	0.85044348	3305.2344
723.62866	2.0610001	0.85207921	3304.6233
724.52954	2.0641775	0.85330367	3299.9521
725.43042	2.0701902	0.85499644	3308.9509
726.3313	2.0721893	0.85653752	3305.8655
727.23218	2.07284	0.85790688	3302.6746
728.13306	2.0753942	0.85952806	3303.9233
729.03394	2.0799301	0.86109906	3304.1382
729.93481	2.0825102	0.86268198	3306.6494
730.83569	2.0855911	0.86425823	3305.7422
731.73657	2.0871794	0.8657856	3304.5237
732.63745	2.0892534	0.86765563	3312.7922
733.53833	2.0941706	0.86948836	3313.3513
734.43921	2.0931511	0.87105089	3301.04
735.34009	2.0948191	0.87260664	3302.3367
736.24097	2.0993786	0.87399417	3303.376
737.14185	2.1012602	0.87514943	3297.4646
738.04272	2.1033063	0.87664396	3304.1145
738.9436	2.108583	0.87798327	3311.4844
739.84448	2.1113491	0.87934941	3305.9431
740.74536	2.1123145	0.88077629	3308.1365
741.64624	2.1198485	0.88251615	3315.2522
742.54712	2.1178024	0.88411283	3307.5522
743.448	2.1217978	0.88561374	3303.592
744.34888	2.1217005	0.88720906	3307.5466
745.24976	2.1268466	0.88879788	3310.5559
746.15063	2.1297181	0.89056307	3311.1785
747.05151	2.1335166	0.8925457	3310.6042
747.95239	2.1372006	0.89438164	3309.9878
748.85327	2.1361556	0.89585996	3305.0837
749.75415	2.1416798	0.89743781	3310.6704
750.65503	2.1458561	0.89893353	3311.1501
751.55591	2.145494	0.90048438	3317.2004
752.45679	2.1464262	0.9023748	3316.1685
753.35767	2.1512449	0.90429533	3313.4883
754.25854	2.1562338	0.90593326	3314.2405
755.15942	2.1562381	0.90777427	3310.4482
756.0603	2.1598327	0.90912855	3309.1257
756.96118	2.1613989	0.91081166	3306.7576
757.86206	2.1677823	0.9127866	3313.9429
758.76294	2.1674156	0.91440809	3308.7297
759.66382	2.1726325	0.91587704	3303.5715
760.5647	2.171536	0.91743731	3310.8796
761.46558	2.1770711	0.91927183	3313.54
762.36646	2.1771865	0.92082095	3304.7795
763.26733	2.1837707	0.92245615	3320.0056
764.16821	2.1838677	0.92437041	3314.6301
765.06909	2.1864405	0.92627025	3314.3032
765.96997	2.1903541	0.92770261	3310.9424
766.87085	2.1927016	0.92925894	3309.5715
767.77173	2.1954033	0.93107718	3315.9844
768.67261	2.1998391	0.93308526	3318.2856
769.57349	2.2002428	0.93481082	3311.6653
770.47437	2.2032607	0.93647581	3310.585
771.37524	2.2049036	0.93791008	3304.9885
772.27612	2.2092626	0.93950063	3312.6521
773.177	2.2114584	0.94090027	3310.8052
774.07788	2.2150383	0.94232088	3315.4817
774.97876	2.2162023	0.94393891	3321.9387
775.87964	2.2195089	0.94580156	3319.5652
776.78052	2.2231963	0.94792008	3322.4287
777.6814	2.2274344	0.94972241	3315.761
778.58228	2.2280934	0.9514634	3315.8645
779.48315	2.2323956	0.95340377	3322.8062
780.38403	2.2375207	0.95486504	3319.8293
781.28491	2.2362039	0.95672119	3320.1875
782.18579	2.2406721	0.95865786	3319.043
783.08667	2.2399163	0.96054739	3319.3257
783.98755	2.2430439	0.96261835	3314.2664
784.88843	2.244292	0.96418917	3317.6699
785.78931	2.2484004	0.96597815	3320.1199
786.69019	2.2532868	0.96783161	3313.5469
787.59106	2.2528641	0.96941471	3308.2725
788.49194	2.2562556	0.97130603	3321.0259
789.39282	2.2598929	0.97327816	3318.7668
790.2937	2.2614572	0.97496724	3315.4255
791.19458	2.2643843	0.9768675	3315.8281
792.09546	2.2670095	0.9782564	3309.6646
792.99634	2.2705331	0.9799493	3317.4131
793.89722	2.2744746	0.98179138	3319.4602
794.7981	2.2765393	0.98367161	3322.0112
795.69897	2.2814329	0.98572463	3322.2312
796.59985	2.2821434	0.98735911	3314.5276
797.50073	2.2848356	0.98929143	3315.8945
798.40161	2.2846336	0.99107164	3314.6304
799.30249	2.2891567	0.99309403	3316.116
800.20337	2.2918537	0.99518555	3319.7424
801.10425	2.294925	0.99698466	3315.1575
802.00513	2.2972255	0.99887997	3317.0042
802.90601	2.3003285	1.0006019	3317.7876
803.80688	2.3015869	1.0023534	3317.2715
804.70776	2.3066747	1.0041184	3315.6658
805.60864	2.3108528	1.0057582	3320.1807
806.50952	2.3091218	1.0074258	3312.4866
807.4104	2.3150909	1.0090023	3315.9543
808.31128	2.3180351	1.0107675	3320.9619
809.21216	2.3181612	1.0125557	3316.4148
810.11304	2.3226292	1.0143285	3318.2766
811.01392	2.3263299	1.0160657	3321.762
811.91479	2.3269227	1.0179063	3318.2617
812.81567	2.3307011	1.0195999	3321.1648
813.71655	2.3376582	1.0212787	3320.6228
814.61743	2.3358326	1.0233221	3314.6172
815.51831	2.3400521	1.0253531	3322.3833
816.41919	2.3420558	1.0273664	3320.9746
817.32007	2.3438909	1.0291411	3317.8691
818.22095	2.3427651	1.0309625	3315.02
819.12183	2.3494375	1.032513	3313.8643
820.02271	2.3519666	1.034587	3317.9463
820.92358	2.3550956	1.0365255	3317.7954
821.82446	2.3563943	1.0385271	3321.8433
822.72534	2.3592429	1.0405598	3319.4858
823.62622	2.3619187	1.0427219	3320.4043
824.5271	2.3643095	1.0450109	3318.4736
825.42798	2.3678253	1.047195	3315.4583
826.32886	2.3701174	1.048875	3311.3298
827.22974	2.3728142	1.0508397	3314.2869
828.13062	2.3747673	1.0524974	3314.521
829.03149	2.3790941	1.0541812	3311.946
829.93237	2.3836789	1.0561028	3320.1714
830.83325	2.3858669	1.0578082	3316.0447
831.73413	2.3858106	1.059548	3313.9124
832.63501	2.3877556	1.0613695	3319.3774
833.53589	2.3918967	1.0636181	3320.3467
834.43677	2.3944857	1.0658213	3320.4468
835.33765	2.3958583	1.06806	3315.9756
836.23853	2.4021838	1.0701642	3313.8855
837.1394	2.403991	1.071569	3311.4268
838.04028	2.403753	1.0733336	3315.1165
838.94116	2.4100156	1.0750208	3310.344
839.84204	2.4127126	1.0770122	3321.8962
840.74292	2.4125977	1.0791967	3318.7537
841.6438	2.4163737	1.0816027	3320.8035
842.54468	2.4183667	1.0839761	3311.3264
843.44556	2.4225931	1.0857993	3313.968
844.34644	2.4249091	1.0876168	3317.219
845.24731	2.4274428	1.0898288	3324.2493
846.14819	2.428823	1.0923445	3318.0212
847.04907	2.432385	1.0949042	3315.5764
847.94995	2.4343936	1.0970213	3312.8049
848.85083	2.4383368	1.0990709	3315.7693
849.75171	2.4410691	1.1008511	3308.4697
850.65259	2.4442482	1.1026731	3314.1252
851.55347	2.4476354	1.1045212	3312.2136
852.45435	2.4509034	1.1067481	3324.062
853.35522	2.4510939	1.1090741	3314.2969
854.2561	2.4565609	1.111441	3315.5173
855.15698	2.4585152	1.11358	3319.366
856.05786	2.4608734	1.1151721	3313.4424
856.95874	2.461715	1.1171087	3310.905
857.85962	2.4641476	1.1187546	3309.7842
858.7605	2.4676805	1.1210939	3318.3647
859.66138	2.468154	1.1231009	3309.4988
860.56226	2.4725022	1.1253116	3315.5737
861.46313	2.4774058	1.1274791	3317.1531
862.36401	2.4789069	1.1296085	3309.1233
863.26489	2.4842141	1.1314607	3309.8574
864.16577	2.4866998	1.1335435	3322.0696
865.06665	2.4884741	1.1360922	3315.2627
865.96753	2.4905784	1.1382854	3311.7969
866.86841	2.4945133	1.1403288	3307.9116
867.76929	2.4929025	1.1427257	3311.5486
868.67017	2.4991558	1.1455669	3316.0166
869.57104	2.5030317	1.1477363	3317.8921
870.47192	2.5041769	1.1499211	3304.782
871.3728	2.5082536	1.1519125	3313.1746
872.27368	2.5083654	1.1538945	3307.0989
873.17456	2.5119057	1.1558751	3312.6443
874.07544	2.5150282	1.1579238	3312.7678
874.97632	2.5174811	1.1601436	3311.3186
875.8772	2.5175848	1.1621431	3310.4719
876.77808	2.5182538	1.1645528	3316.5225
877.67896	2.5235648	1.1666702	3305.5371
878.57983	2.5297902	1.1686453	3302.8818
879.48071	2.5301142	1.1703569	3306.3484
880.38159	2.534919	1.1725547	3318.1533
881.28247	2.5347087	1.1749309	3309.292
882.18335	2.5401571	1.1768421	3306.4204
883.08423	2.5420647	1.1787591	3307.2822
883.98511	2.5439076	1.1809201	3313.9282
884.88599	2.5469596	1.1833558	3308.8789
885.78687	2.5507517	1.185541	3308.6531
886.68774	2.5540822	1.1876374	3312.5688
887.58862	2.554522	1.1902162	3307.5864
888.4895	2.5589032	1.1929331	3310.7927
889.39038	2.561672	1.1951585	3304.1289
890.29126	2.5639231	1.197565	3304.6279
891.19214	2.5643954	1.1996903	3300.5178
892.09302	2.5689068	1.2017304	3295.2371
892.9939	2.5710375	1.2037717	3309.0261
893.89478	2.5730727	1.2061281	3305.6902
894.79565	2.5754228	1.2085887	3305.4031
895.69653	2.5816727	1.2112546	3309.2883
896.59741	2.5816083	1.2136555	3300.7087
897.49829	2.5817647	1.2163706	3303.2717
898.39917	2.5875585	1.2191912	3309.0708
899.30005	2.5899284	1.2217426	3301.3357
900.20093	2.5917897	1.2242557	3297.8774
901.10181	2.5958893	1.2265581	3301.5618
902.00269	2.5983646	1.2290205	3300.9009
902.90356	2.6024079	1.23124	3296.8059
903.80444	2.6021609	1.2332413	3292.5381
904.70532	2.6050987	1.2356017	3302.4626
905.6062	2.6100309	1.2378528	3299.2253
906.50708	2.610476	1.2401696	3294.1714
907.40796	2.6094158	1.2425345	3297.2371
908.30884	2.6193781	1.245595	3301.4644
909.20972	2.618613	1.2482375	3294.8665
910.1106	2.6241	1.250988	3293.7039
911.01147	2.6234334	1.2536156	3297.6079
911.91235	2.6308959	1.2558976	3295.356
912.81323	2.6317248	1.2584054	3296.5767
913.71411	2.6336036	1.2605888	3294.5195
914.61499	2.6370163	1.2626374	3285.7556
915.51587	2.638675	1.2646041	3289.8979
916.41675	2.6396241	1.2666731	3286.5139
917.31763	2.6454344	1.2687879	3291.6575
918.21851	2.6447489	1.2711986	3299.666
919.11938	2.6509295	1.2738699	3295.1196
920.02026	2.6507187	1.2765454	3290.0515
920.92114	2.6569192	1.2794628	3294.1377
921.82202	2.6559978	1.28256	3288.907
922.7229	2.6603928	1.2857065	3286.8928
923.62378	2.6625581	1.2880453	3277.2429
924.52466	2.6664686	1.2902255	3282.0566
925.42554	2.6719415	1.2923502	3288.0261
926.32642	2.6702394	1.2944299	3279.7043
927.22729	2.6765006	1.2970273	3289.5828
928.12817	2.6748674	1.3000712	3285.7581
929.02905	2.6799872	1.303522	3283.8594
929.92993	2.6806307	1.3060271	3277.6619
930.83081	2.6827953	1.3086122	3281.0093
931.73169	2.6851559	1.3109361	3276.7151
932.63257	2.6885986	1.3130815	3280.6287
933.53345	2.6907706	1.3156329	3272.6079
934.43433	2.6966326	1.3182917	3278.7808
935.33521	2.6988354	1.3211631	3282.1189
936.23608	2.7006385	1.3236663	3277.7659
937.13696	2.7031069	1.3262575	3273.3896
938.03784	2.7075543	1.3284087	3274.4285
938.93872	2.708828	1.3309439	3270.1143
939.8396	2.7118154	1.3335513	3274.325
940.74048	2.7135274	1.3356438	3267.1838
941.64136	2.7133534	1.3381414	3268.48
942.54224	2.7174172	1.3404688	3264.1985
943.44312	2.7196195	1.34276	3269.637
944.34399	2.7249379	1.3457161	3275.708
945.24487	2.7267935	1.3487267	3267.731
946.14575	2.7278247	1.3514925	3260.1431
947.04663	2.7344651	1.3539817	3261.2004
947.94751	2.7364218	1.356745	3268.7102
948.84839	2.7378683	1.3595562	3260.6797
949.74927	2.7415493	1.3621023	3263.4199
950.65015	2.7440982	1.3644664	3259.8796
951.55103	2.7444911	1.3671066	3258.6072
952.4519	2.7465234	1.3699973	3260.4961
953.35278	2.7544143	1.3730648	3259.7385
954.25366	2.7569041	1.3758167	3257.0669
955.15454	2.7575788	1.3783083	3251.2332
956.05542	2.758208	1.3807014	3251.1477
956.9563	2.7645533	1.3829709	3251.7109
957.85718	2.7637634	1.3856108	3252.9045
958.75806	2.7662876	1.3878996	3248.4495
959.65894	2.7706707	1.390605	3252.9429
960.55981	2.7721238	1.3937179	3251.5813
961.46069	2.7796636	1.3960382	3250.5959
962.36157	2.7801507	1.3989718	3252.0044
963.26245	2.7823107	1.4019564	3245.6106
964.16333	2.7858071	1.4049546	3245.0676
965.06421	2.7888563	1.4078288	3247.2588
965.96509	2.790174	1.4106175	3242.3315
966.86597	2.7930894	1.4135029	3242.1492
967.76685	2.7926295	1.4160763	3236.5859
968.66772	2.8004434	1.4188743	3238.7422
969.5686	2.8021474	1.4218912	3240.105
970.46948	2.7990539	1.4246683	3229.5728
971.37036	2.8075504	1.4271314	3232.4624
972.27124	2.811043	1.4296412	3234.8003
973.17212	2.8141816	1.4321463	3234.1511
974.073	2.8176835	1.4351122	3239.4351
974.97388	2.8165495	1.4381323	3229.3772
975.87476	2.8199501	1.44139	3226.8889
976.77563	2.8218198	1.444454	3225.7742
977.67651	2.8251669	1.4470917	3221.8838
978.57739	2.8306456	1.4495702	3225.8142
979.47827	2.8315306	1.451993	3215.3811
980.37915	2.8344841	1.4541136	3215.9985
981.28003	2.8359706	1.4564153	3216.4846
982.18091	2.8401861	1.45927	3224.9563
983.08179	2.8395996	1.4624715	3214.8579
983.98267	2.8478162	1.4655412	3219.6975
984.88354	2.8465419	1.4682208	3210.137
985.78442	2.8517258	1.4705775	3211.2742
986.6853	2.8548534	1.473224	3208.1729
987.58618	2.8527546	1.4755641	3207.8228
988.48706	2.8560691	1.4784212	3208.4082
989.38794	2.8589752	1.4814008	3207.6902
990.28882	2.8598526	1.4844182	3203.4832
991.1897	2.8681483	1.4872487	3206.5396
992.09058	2.8666928	1.4899734	3197.3745
992.99146	2.8735881	1.4924543	3193.9956
993.89233	2.8737795	1.4947966	3195.4304
994.79321	2.8758016	1.4971704	3198.5845
995.69409	2.8785958	1.5000007	3198.2629
996.59497	2.8828831	1.5032538	3196.1575
997.49585	2.8837576	1.5059909	3192.2363
998.39673	2.890888	1.5094562	3190.8372
999.29761	2.8877466	1.5118542	3182.7561
1000.1985	2.8949125	1.514742	3187.1021
1001.0994	2.8963335	1.5172104	3179.6555
1002.0002	2.8969269	1.5198956	3173.4658
1002.9011	2.9010086	1.5224407	3175.2588
1003.802	2.9053824	1.5255972	3183.6177
1004.7029	2.9065392	1.5286682	3179.4146
1005.6038	2.9111156	1.5319527	3181.8945
1006.5046	2.9109139	1.5349464	3171.2261
1007.4055	2.9164875	1.5379574	3168.3992
1008.3064	2.9213109	1.5406077	3171.5354
1009.2073	2.9218907	1.5431453	3167.989
1010.1082	2.9230602	1.5459552	3175.2124
1011.009	2.9239244	1.5494891	3161.6411
1011.9099	2.9287765	1.552372	3156.8262
1012.8108	2.9313602	1.5549526	3160.2197
1013.7117	2.9323344	1.5574019	3153.9553
1014.6125	2.9381802	1.5598744	3154.4924
1015.5134	2.9394717	1.5623661	3157.7588
1016.4143	2.940665	1.565171	3153.8042
1017.3152	2.9434674	1.5683281	3151.79
1018.2161	2.9460795	1.5709728	3147.302
1019.1169	2.9473846	1.5740907	3145.3315
1020.0178	2.9528024	1.5770218	3141.2756
1020.9187	2.9538655	1.5798329	3140.7068
1021.8196	2.9575498	1.5821425	3134.96
1022.7205	2.9578276	1.584775	3134.6384
1023.6213	2.9638467	1.5873501	3138.543
1024.5222	2.9666543	1.5901818	3137.3125
1025.4231	2.9710267	1.5929997	3131.478
1026.324	2.9695776	1.5960866	3126.2078
1027.2249	2.9746253	1.5992717	3130.3242
1028.1257	2.9791658	1.6021633	3121.6079
1029.0266	2.9792485	1.6048287	3115.9043
1029.9275	2.9821317	1.6078795	3122.4595
1030.8284	2.9853177	1.6107099	3115.1467
1031.7292	2.9881108	1.6141138	3119.4031
1032.6301	2.9909515	1.616793	3113.1384
1033.531	2.9967973	1.6191436	3110.3572
1034.4319	3.0011308	1.6211082	3109.2976
1035.3328	3.0007272	1.6228482	3104.6438
1036.2336	2.9991415	1.6251295	3103.4343
1037.1345	3.0037837	1.6277738	3106.9036
1038.0354	3.0088899	1.6303008	3101.2764
1038.9363	3.0071151	1.6329392	3097.7236
1039.8372	3.011312	1.635712	3096.1262
1040.738	3.0158484	1.6392957	3096.1436
1041.6389	3.0163791	1.6424047	3086.1462
1042.5398	3.0196686	1.6454893	3089.8325
1043.4407	3.0213213	1.6488607	3085.4297
1044.3416	3.0230238	1.6519302	3083.4143
1045.2424	3.0298615	1.6553535	3082.5103
1046.1433	3.028487	1.6585159	3068.9998
1047.0442	3.0342345	1.6613086	3073.6262
1047.9451	3.0333929	1.6639768	3064.8096
1048.8459	3.0388963	1.6663666	3070.2283
1049.7468	3.0410438	1.6692342	3069.5742
1050.6477	3.0432718	1.6720622	3061.0034
1051.5486	3.0482736	1.674832	3062.1804
1052.4495	3.049876	1.6773583	3056.8289
1053.3503	3.0540907	1.6798283	3057.1184
1054.2512	3.0554621	1.6826831	3059.3977
1055.1521	3.0580411	1.6856558	3050.373
1056.053	3.0633361	1.6890953	3045.4514
1056.9539	3.0634544	1.6924328	3041.4802
1057.8547	3.0679877	1.6953071	3037.1946
1058.7556	3.0693052	1.6978003	3032.8667
1059.6565	3.0730667	1.7006756	3035.5317
1060.5574	3.0763276	1.7040296	3035.7664
1061.4583	3.0802505	1.7069194	3027.0403
1062.3591	3.0797045	1.7094679	3024.5938
1063.26	3.0788178	1.7124361	3016.3562
1064.1609	3.0861962	1.7152221	3025.1714
1065.0618	3.0881741	1.7177497	3015.75
1065.9626	3.0893512	1.7207762	3017.7673
1066.8635	3.0920866	1.7244058	3011.3147
1067.7644	3.098192	1.7277673	3013.0198
1068.6653	3.1014719	1.730212	3001.1633
1069.5662	3.0993066	1.7328528	3004.3103
1070.467	3.1053572	1.7360488	3001.1416
1071.3679	3.1053839	1.7389293	3000.2698
1072.2688	3.1107831	1.7423421	2993.4727
1073.1697	3.1101117	1.7451278	2984.7429
1074.0706	3.1128983	1.7480017	2986.2112
1074.9714	3.1180434	1.751352	2980.6265
1075.8723	3.1193433	1.7546011	2979.4783
1076.7732	3.1238019	1.7578022	2980.4465
1077.6741	3.1241016	1.7604703	2974.3989
1078.575	3.1290035	1.763683	2969.3921
1079.4758	3.1315079	1.7667491	2966.4363
1080.3767	3.1318495	1.7693335	2964.155
1081.2776	3.1359549	1.7729293	2958.2297
1082.1785	3.1356297	1.7762786	2952.3303
1083.0793	3.1418555	1.7792642	2949.4546
1083.9802	3.1462638	1.7828315	2952.376
1084.8811	3.1473677	1.7861943	2945.8325
1085.782	3.1488326	1.7894641	2938.3091
1086.6829	3.1543336	1.7927903	2939.9402
1087.5837	3.1539338	1.7965637	2927.2458
1088.4846	3.1563435	1.7992235	2917.6648
1089.3855	3.1602097	1.801448	2917.9063
1090.2864	3.1657569	1.8038574	2919.4368
1091.1873	3.1662474	1.8064282	2916.2532
1092.0881	3.171623	1.8091984	2919.3469
1092.989	3.1723857	1.812606	2912.8618
1093.8899	3.1725881	1.8156176	2900.9712
1094.7908	3.1771655	1.8191656	2893.9604
1095.6917	3.1828253	1.8217175	2896.085
1096.5925	3.1843107	1.8244042	2897.0159
1097.4934	3.1828296	1.8273207	2892.3257
1098.3943	3.1879935	1.8306648	2889.5559
1099.2952	3.1890185	1.8336998	2875.6765
1100.196	3.1933117	1.8360627	2873.0984
1101.0969	3.195852	1.8386109	2874.053
1101.9978	3.1974382	1.8415409	2874.7307
1102.8987	3.2013967	1.8446386	2867.3606
1103.7996	3.2039745	1.8476026	2859.175
1104.7004	3.2054791	1.8503524	2857.2856
1105.6013	3.2092247	1.8536114	2855.3376
1106.5022	3.2127149	1.8572531	2848.4045
1107.4031	3.2135088	1.860603	2843.9653
1108.304	3.2198167	1.8640459	2839.3157
1109.2048	3.2175872	1.8672444	2831.0261
1110.1057	3.2236729	1.8708688	2826.8909
1111.0066	3.2262115	1.8745023	2824.4844
1111.9075	3.2288263	1.8776923	2812.4934
1112.8083	3.2304165	1.880829	2813.5732
1113.7092	3.2362056	1.8841645	2805.7371
1114.6101	3.238718	1.8872184	2800.345
1115.511	3.2412095	1.8902111	2795.439
1116.4119	3.2442527	1.8933238	2791.2405
1117.3127	3.2463131	1.8961728	2787.9934
1118.2136	3.2468786	1.8997496	2783.5439
1119.1145	3.251677	1.9033792	2776.8186
1120.0154	3.2515047	1.9072191	2766.4807
1120.9163	3.2554917	1.9104362	2756.6262
1121.8171	3.2573524	1.9133023	2752.5107
1122.718	3.2584538	1.9162564	2746.4331
1123.6189	3.2631774	1.9193844	2739.021
1124.5198	3.2670932	1.9224229	2740.5801
1125.4207	3.2696321	1.9250289	2732.2119
1126.3215	3.2697806	1.9277028	2717.2031
1127.2224	3.2764926	1.9311572	2725.6738
1128.1233	3.2779632	1.9345182	2717.3755
1129.0242	3.2798293	1.9378072	2712.0542
1129.925	3.2808323	1.9415132	2702.3386
1130.8259	3.2862511	1.9451985	2692.5444
1131.7268	3.288636	1.9490691	2679.9231
1132.6277	3.2918591	1.9522289	2670.8198
1133.5286	3.2930043	1.9557334	2655.415
1134.4294	3.2961812	1.9592705	2646.2161
1135.3303	3.2987857	1.9638921	2631.4419
1136.2312	3.3055117	1.974058	2569.4336
1137.1321	3.3069682	1.9841424	2482.9229