File: datasets/am_bench_2022/raw_data/90-X.08-1/specimen.dat
MTS793|MPT|ENU|1|2|.|/|:|1|0|0|A

Operator Information						Time:	13.703369	Sec	10/15/2021 12:41:00 PM
Operator	Jake Benzing
Project	AM Bench 2022 mini-tensile challenge
Specimen ID	90-X.08-1
Material	PBF-L Inconel 625
Specimen Width	2.55	mm
Specimen Thickness	1.51	mm
Notes
Operator Information End

Data Acquisition						Time:	1014.6973	Sec	10/15/2021 12:57:41 PM
Time	Axial Displacement	Axial Extensometer	Axial Force
Sec	mm	mm	N
13.817139	0.0012365411	-4.1533309e-05	63.669308
14.718018	0.0039058605	-4.453701e-05	74.809769
15.618896	0.004018141	3.0899744e-05	83.651169
16.519775	0.0080490634	0.00010202047	99.386215
17.420654	0.011790116	0.00012623449	111.19521
18.321533	0.01357738	0.00022365809	120.22425
19.222412	0.017643236	0.00020783232	129.83746
20.123291	0.020397125	0.00037934142	146.25835
21.02417	0.02065959	0.0003978021	153.09044
21.925049	0.022329194	0.000507597	167.60164
22.825928	0.029511392	0.00058695127	186.8047
23.726807	0.028911881	0.00075160677	200.49005
24.627686	0.030196752	0.00077857455	210.09085
25.528564	0.034433026	0.00092277169	229.55728
26.429443	0.037085697	0.0010171629	249.43556
27.330322	0.040285431	0.0010284975	268.746
28.231201	0.043379489	0.0012240228	280.28363
29.13208	0.045295373	0.0011814435	301.92242
30.032959	0.048409048	0.0013963843	315.83292
30.933838	0.053773247	0.0014874605	333.13931
31.834717	0.051717166	0.0016066362	349.73792
32.735596	0.057172183	0.0016947547	370.41443
33.636475	0.06031844	0.0018205885	393.1637
34.537354	0.056447893	0.0018977299	409.3895
35.438232	0.063031755	0.002072627	432.86652
36.339111	0.065815561	0.0021084491	448.11713
37.23999	0.070316605	0.0022837354	475.62769
38.140869	0.072352558	0.0023211075	494.74557
39.041748	0.072617069	0.0024807113	518.17255
39.942627	0.078488529	0.0026163636	541.24799
40.843506	0.082651503	0.0026800642	562.0188
41.744385	0.082218565	0.002804186	580.15796
42.645264	0.085775428	0.0030039158	603.62378
43.546143	0.089629576	0.0030608622	624.07605
44.447021	0.089670554	0.0031593184	639.12469
45.3479	0.092493288	0.0034002559	671.1687
46.248779	0.097424395	0.0033976415	689.49622
47.149658	0.099172063	0.0036545061	719.92627
48.050537	0.10328172	0.0037224551	739.22723
48.951416	0.10400908	0.003757217	759.92902
49.852295	0.10650071	0.0038992658	780.5835
50.753174	0.10894158	0.0040612477	796.77368
51.654053	0.11104806	0.0042247442	829.98932
52.554932	0.11673798	0.0043440717	852.75818
53.455811	0.11744506	0.0044579399	876.54919
54.356689	0.11808596	0.0045849797	894.52216
55.257568	0.12411667	0.0046774745	922.73956
56.158447	0.12762067	0.004806058	948.3689
57.059326	0.13034689	0.004936011	967.52844
57.960205	0.13211034	0.0050489898	996.13184
58.861084	0.13626982	0.005171407	1010.4335
59.761963	0.13915239	0.0052943244	1045.0244
60.662842	0.1421085	0.0054869484	1075.8883
61.563721	0.14090113	0.0055489969	1093.2653
62.4646	0.14452785	0.0058011818	1123.9712
63.365479	0.1522378	0.0059308847	1153.6082
64.266357	0.14894156	0.0060279323	1175.7511
65.167236	0.15456311	0.0062076403	1199.8754
66.068115	0.15660173	0.0062489286	1221.8708
66.968994	0.15850291	0.0064296611	1239.2084
67.869873	0.16266009	0.0065381457	1267.3217
68.770752	0.16480079	0.0067353719	1292.606
69.671631	0.17028624	0.006794461	1315.3447
70.57251	0.17166987	0.0069485456	1344.2626
71.473389	0.17444056	0.0071134521	1373.6177
72.374268	0.17478888	0.0072088563	1390.541
73.275146	0.1787869	0.0072681229	1414.4783
74.176025	0.17855825	0.007512358	1441.7516
75.076904	0.18270595	0.0076818625	1467.7815
75.977783	0.1853216	0.0077127232	1491.6929
76.878662	0.18990721	0.0078591937	1522.0928
77.779541	0.19092982	0.0079908669	1536.0359
78.68042	0.19585632	0.0081628552	1569.8723
79.581299	0.19988094	0.0081639783	1586.2527
80.482178	0.1986414	0.008314698	1602.533
81.383057	0.2027822	0.0084212236	1617.8251
82.283936	0.2059596	0.0086017679	1649.2729
83.184814	0.21151026	0.0087884339	1681.9022
84.085693	0.21086116	0.0088286111	1699.3851
84.986572	0.21415329	0.0089295646	1719.876
85.887451	0.21153586	0.0090137124	1741.3931
86.78833	0.21711335	0.0092563462	1769.7372
87.689209	0.21963079	0.0093653742	1791.7036
88.590088	0.22193992	0.0094208959	1820.2917
89.490967	0.22688793	0.0096869683	1840.2832
90.391846	0.23119166	0.0097708534	1862.0226
91.292725	0.233696	0.0098782191	1884.7627
92.193604	0.23244047	0.0099636419	1899.2683
93.094482	0.239381	0.010101752	1925.3352
93.995361	0.2374475	0.010228174	1945.3237
94.89624	0.24140389	0.010258879	1971.2372
95.797119	0.24417669	0.010453166	1997.8248
96.697998	0.24994959	0.010674084	2023.9191
97.598877	0.25013626	0.01072972	2042.5155
98.499756	0.25351053	0.010868918	2066.292
99.400635	0.25759831	0.010957322	2075.208
100.30151	0.25674209	0.011101593	2094.8235
101.20239	0.26031575	0.011229128	2119.6362
102.10327	0.26369044	0.011317731	2137.5854
103.00415	0.26509047	0.011389331	2158.208
103.90503	0.26913249	0.011551704	2174.771
104.80591	0.272203	0.011665742	2190.4189
105.70679	0.27455306	0.011786687	2208.9619
106.60767	0.27927226	0.011908928	2223.7961
107.50854	0.28001431	0.011976533	2239.1589
108.40942	0.28370562	0.012158003	2260.9094
109.3103	0.28573343	0.012182511	2273.9526
110.21118	0.28987458	0.012329896	2287.668
111.11206	0.29206979	0.012504994	2303.6499
112.01294	0.29279244	0.012600898	2314.2087
112.91382	0.29548097	0.01257536	2322.6809
113.8147	0.30137441	0.012729589	2344.543
114.71558	0.302975	0.012824386	2357.5952
115.61646	0.30383879	0.012973443	2367.5544
116.51733	0.30730057	0.013029918	2375.0867
117.41821	0.30922961	0.013122818	2391.4319
118.31909	0.31221056	0.013277937	2400.5813
119.21997	0.31555292	0.013379663	2422.4932
120.12085	0.3196812	0.013540358	2431.1985
121.02173	0.32003582	0.013621199	2433.8926
121.92261	0.32347491	0.013678051	2445.5183
122.82349	0.32386932	0.013860697	2460.781
123.72437	0.3278335	0.013822035	2467.6492
124.62524	0.33338392	0.014008258	2478.7673
125.52612	0.3339113	0.014174983	2486.1899
126.427	0.33931017	0.014296905	2501.2019
127.32788	0.33932021	0.014349492	2506.4778
128.22876	0.3451767	0.014548357	2529.0703
129.12964	0.34674388	0.014659422	2527.103
130.03052	0.34943512	0.014875014	2542.4817
130.9314	0.34982255	0.014999717	2546.6111
131.83228	0.35305327	0.015171664	2552.6016
132.73315	0.35766712	0.015317815	2566.6846
133.63403	0.36037961	0.015549139	2581.8499
134.53491	0.36221913	0.015729638	2581.3191
135.43579	0.36638498	0.015791906	2590.3955
136.33667	0.36726063	0.016015876	2593.4338
137.23755	0.3685545	0.016261056	2605.2637
138.13843	0.37012991	0.01644953	2616.019
139.03931	0.37893727	0.016688099	2622.1638
139.94019	0.37845433	0.01682237	2626.9006
140.84106	0.38107771	0.017206062	2643.7876
141.74194	0.38183725	0.017382847	2642.751
142.64282	0.3850261	0.017683418	2654.7678
143.5437	0.38876963	0.017935464	2659.9341
144.44458	0.39168522	0.018165566	2659.6353
145.34546	0.39482921	0.018426012	2671.0957
146.24634	0.39707237	0.018864024	2683.3718
147.14722	0.40633622	0.019075248	2692.073
148.0481	0.40259019	0.019407142	2690.7664
148.94897	0.40662038	0.019777913	2691.499
149.84985	0.40870857	0.020121867	2702.2515
150.75073	0.40971768	0.020401012	2704.1301
151.65161	0.41475275	0.020887438	2717.094
152.55249	0.41622901	0.021441678	2718.5657
153.45337	0.41791424	0.021852316	2718.9883
154.35425	0.42192432	0.022302998	2726.2136
155.25513	0.42218146	0.022996671	2740.5071
156.15601	0.43029094	0.023730973	2747.0093
157.05688	0.43095559	0.024340402	2747.3386
157.95776	0.43268609	0.024722872	2746.7397
158.85864	0.43683797	0.025331067	2757.8931
159.75952	0.43872905	0.025976425	2754.8093
160.6604	0.43921486	0.026549978	2763.0117
161.56128	0.44307557	0.027152507	2763.3352
162.46216	0.44830024	0.027716976	2773.0977
163.36304	0.44571701	0.028339265	2779.9094
164.26392	0.45232219	0.029166544	2787.2979
165.16479	0.45247996	0.029870544	2782.6045
166.06567	0.45505989	0.030463802	2789.6917
166.96655	0.4596642	0.031291518	2810.0757
167.86743	0.46076345	0.032253698	2799.2744
168.76831	0.46446612	0.03304781	2810.4717
169.66919	0.47073552	0.033755351	2810.2444
170.57007	0.46912715	0.034277011	2812.4417
171.47095	0.47508267	0.035172734	2818.5681
172.37183	0.47411132	0.035803091	2818.2688
173.27271	0.474594	0.036573097	2826.0212
174.17358	0.48054788	0.037449788	2827.51
175.07446	0.48531049	0.038263217	2835.5139
175.97534	0.48599854	0.039097156	2837.1331
176.87622	0.48862559	0.040030818	2846.1479
177.7771	0.49477386	0.040808946	2849.4783
178.67798	0.49458945	0.041459039	2843.0725
179.57886	0.49714854	0.042294528	2849.9055
180.47974	0.50196999	0.04313606	2862.5645
181.38062	0.50508857	0.043910384	2854.6951
182.28149	0.5063259	0.044721432	2855.3547
183.18237	0.50945824	0.045493528	2868.1621
184.08325	0.51222241	0.046286613	2872.2537
184.98413	0.51591963	0.047272909	2878.3081
185.88501	0.51316965	0.048048694	2870.0012
186.78589	0.52027392	0.048825122	2877.7253
187.68677	0.5227254	0.049801074	2883.8347
188.58765	0.52465463	0.050637782	2875.9551
189.48853	0.52709776	0.051378235	2884.7581
190.3894	0.5316751	0.052393921	2889.9817
191.29028	0.53164113	0.053215768	2895.7805
192.19116	0.53534204	0.05406202	2887.1619
193.09204	0.53766054	0.055037189	2896.3254
193.99292	0.54221421	0.055964936	2898.7881
194.8938	0.54359579	0.056975778	2909.4971
195.79468	0.54589564	0.05810954	2908.6638
196.69556	0.55053759	0.05894687	2917.2305
197.59644	0.54838008	0.059701256	2914.2549
198.49731	0.55417728	0.0606388	2920.7847
199.39819	0.55469686	0.061671544	2920.1445
200.29907	0.56009978	0.062579192	2927.3118
201.19995	0.56137788	0.063450657	2926.4934
202.10083	0.56313109	0.06433671	2923.9468
203.00171	0.56758171	0.065442495	2935.3103
203.90259	0.57030714	0.066656165	2942.104
204.80347	0.57461143	0.067519739	2934.0559
205.70435	0.57302409	0.068408541	2940.5413
206.60522	0.57781398	0.069412068	2941.3389
207.5061	0.58178824	0.070357472	2949.1218
208.40698	0.58482635	0.0710219	2943.3513
209.30786	0.58520311	0.072006918	2953.0125
210.20874	0.58692908	0.072898872	2952.0881
211.10962	0.59167618	0.073971093	2955.0598
212.0105	0.59567249	0.074949704	2960.2849
212.91138	0.59601814	0.075788438	2958.8987
213.81226	0.59922528	0.076691009	2966.9565
214.71313	0.60310978	0.077739857	2978.2766
215.61401	0.6050927	0.078883462	2974.3655
216.51489	0.6113658	0.079792015	2976.814
217.41577	0.61229163	0.080683723	2974.9165
218.31665	0.61501092	0.081655286	2974.397
219.21753	0.61561346	0.082399823	2982.645
220.11841	0.6209802	0.08344733	2985.0718
221.01929	0.62180567	0.084329575	2987.4521
221.92017	0.62497818	0.08534833	2999.897
222.82104	0.6280607	0.0862583	2991.9155
223.72192	0.6298883	0.087230094	2993.3647
224.6228	0.63199496	0.087998539	2993.406
225.52368	0.6347487	0.088980034	3001.5498
226.42456	0.638668	0.090113327	3005.6707
227.32544	0.63923532	0.091129877	3012.6104
228.22632	0.64352447	0.092110716	3005.9004
229.1272	0.64688528	0.093042322	3005.9509
230.02808	0.65054846	0.093812674	3004.1855
230.92896	0.65033823	0.094701499	3008.3679
231.82983	0.65784025	0.095692798	3018.6394
232.73071	0.65605134	0.096634284	3018.1824
233.63159	0.66172659	0.097697377	3022.9026
234.53247	0.66403323	0.098774701	3033.0046
235.43335	0.66480112	0.10002111	3022.9805
236.33423	0.66869175	0.10100962	3033.9495
237.23511	0.67041177	0.10226782	3032.7986
238.13599	0.67314422	0.10330158	3035.5569
239.03687	0.67388773	0.10465575	3040.2107
239.93774	0.67854118	0.10557041	3040.3557
240.83862	0.68396145	0.10647873	3049.3345
241.7395	0.68442249	0.1074033	3042.7473
242.64038	0.68616813	0.108411	3042.4646
243.54126	0.69131595	0.10925844	3046.2087
244.44214	0.69325274	0.11030053	3053.5793
245.34302	0.69545496	0.11118845	3051.7629
246.2439	0.70073676	0.11233056	3063.9851
247.14478	0.70021451	0.11339842	3059.5049
248.04565	0.70395839	0.11430929	3064.7456
248.94653	0.7023648	0.1153207	3061.4268
249.84741	0.70739251	0.11647256	3062.2009
250.74829	0.71258914	0.11749903	3072.4463
251.64917	0.71578747	0.11850557	3078.0891
252.55005	0.71343082	0.1197055	3072.5635
253.45093	0.71870774	0.1207002	3072.0117
254.35181	0.72046626	0.12182506	3081.3818
255.25269	0.72095227	0.12282475	3074.2112
256.15356	0.72813141	0.12368283	3074.2151
257.05444	0.72580075	0.12460154	3079.22
257.95532	0.73104817	0.12552077	3083.4092
258.8562	0.73740196	0.12637579	3093.3518
259.75708	0.73815411	0.12743922	3092.8789
260.65796	0.74068183	0.12844913	3092.6492
261.55884	0.7475335	0.12950246	3100.3108
262.45972	0.74420613	0.13050847	3097.675
263.3606	0.74912471	0.13146582	3100.0688
264.26147	0.75065106	0.13248384	3098.9729
265.16235	0.75197244	0.1333901	3100.1177
266.06323	0.75802118	0.1342925	3108.9143
266.96411	0.76273644	0.13547419	3111.3538
267.86499	0.76506293	0.13657863	3109.0408
268.76587	0.76793861	0.13756426	3113.803
269.66675	0.76746547	0.138712	3114.0259
270.56763	0.7708537	0.13989751	3117.749
271.46851	0.77098262	0.1407738	3115.0132
272.36938	0.77697003	0.14188111	3122.2493
273.27026	0.77787977	0.14272574	3115.3838
274.17114	0.77994955	0.14373162	3126.4912
275.07202	0.78481054	0.14473987	3129.6257
275.9729	0.78614253	0.14596733	3133.1777
276.87378	0.79140729	0.14715117	3133.6265
277.77466	0.79009396	0.14814393	3122.512
278.67554	0.79319561	0.14905713	3127.7839
279.57642	0.79814595	0.15015334	3140.5774
280.47729	0.80324435	0.15129994	3142.3042
281.37817	0.80323821	0.15235543	3135.4441
282.27905	0.80391455	0.15311734	3134.6882
283.17993	0.81106335	0.1541111	3147.9404
284.08081	0.81039822	0.15527384	3146.333
284.98169	0.81278563	0.15647727	3154.1831
285.88257	0.81596303	0.15774031	3154.1248
286.78345	0.81931072	0.15870659	3157.4268
287.68433	0.82270247	0.15978052	3152.3381
288.58521	0.82782239	0.16090403	3155.6453
289.48608	0.82758963	0.16182053	3157.334
290.38696	0.83127332	0.16286911	3158.4758
291.28784	0.83422744	0.16374418	3160.8162
292.18872	0.83444911	0.16490914	3173.9299
293.0896	0.83714092	0.16573139	3162.5828
293.99048	0.84095263	0.16677645	3173.9167
294.89136	0.84552395	0.16780651	3172.689
295.79224	0.84551245	0.16874598	3168.7744
296.69312	0.84924394	0.1699485	3176.3118
297.59399	0.84837705	0.17107834	3177.4724
298.49487	0.85582864	0.17207365	3178.3252
299.39575	0.85979772	0.17315006	3186.5579
300.29663	0.8587333	0.17405953	3179.4585
301.19751	0.86456919	0.17510967	3191.1938
302.09839	0.86786026	0.17616329	3192.332
302.99927	0.8695125	0.17708191	3188.8687
303.90015	0.87062216	0.17795555	3184.2703
304.80103	0.87225819	0.17913416	3195.335
305.7019	0.87720895	0.18019538	3197.3027
306.60278	0.87874031	0.18112563	3195.5994
307.50366	0.88300097	0.18214178	3190.6584
308.40454	0.8820312	0.1830319	3193.175
309.30542	0.88959247	0.1840263	3204.949
310.2063	0.8874827	0.18509968	3204.8699
311.10718	0.89384842	0.18653554	3217.4478
312.00806	0.89564747	0.18765582	3203.6245
312.90894	0.89809322	0.18864749	3204.2041
313.80981	0.89999646	0.18973982	3212.8955
314.71069	0.90549713	0.19072352	3219.0745
315.61157	0.90554279	0.19168724	3218.5635
316.51245	0.90993297	0.1928343	3221.4976
317.41333	0.91220737	0.19379002	3220.6406
318.31421	0.91388834	0.19504192	3222.8533
319.21509	0.91572046	0.19607507	3222.426
320.11597	0.92253852	0.1972238	3231.0681
321.01685	0.92233813	0.19831797	3232.4778
321.91772	0.92669159	0.19934574	3228.2043
322.8186	0.9265281	0.20039079	3230.7583
323.71948	0.92997497	0.20132582	3230.2549
324.62036	0.9321894	0.20244409	3237.5906
325.52124	0.93312228	0.20341632	3233.5964
326.42212	0.9360466	0.20437548	3227.9612
327.323	0.94172615	0.20508705	3231.7422
328.22388	0.9462806	0.20599382	3240.2192
329.12476	0.94754004	0.2070017	3242.0696
330.02563	0.94917732	0.20796452	3240.6106
330.92651	0.95314884	0.20906775	3247.5322
331.82739	0.95525557	0.2100589	3249.3945
332.72827	0.95654207	0.21105145	3247.3315
333.62915	0.95947176	0.21197909	3248.416
334.53003	0.9657653	0.21308063	3254.1206
335.43091	0.96760911	0.21400324	3253.6772
336.33179	0.96723127	0.21495247	3257.3289
337.23267	0.96914208	0.21592335	3257.4377
338.13354	0.97543907	0.21693054	3259.2566
339.03442	0.97746795	0.21793835	3263.9858
339.9353	0.97795451	0.21921691	3266.7285
340.83618	0.98070884	0.22034286	3267.3489
341.73706	0.98462671	0.22137921	3266.7949
342.63794	0.98556411	0.22237314	3266.6633
343.53882	0.9897061	0.22351111	3273.1228
344.4397	0.9891392	0.22445926	3266.1479
345.34058	0.99480498	0.22573853	3276.9988
346.24146	0.99909371	0.22670883	3273.9058
347.14233	1.0001364	0.22776647	3284.5669
348.04321	1.003186	0.22896889	3281.8494
348.94409	1.0074136	0.2299967	3284.9126
349.84497	1.0096722	0.23097493	3284.302
350.74585	1.0138807	0.23191679	3281.158
351.64673	1.0139987	0.23290633	3283.0645
352.54761	1.0172676	0.23391055	3285.8179
353.44849	1.0216737	0.23478042	3291.7468
354.34937	1.0217161	0.23587662	3293.1831
355.25024	1.0253729	0.23675931	3291.8176
356.15112	1.0249985	0.23772359	3290.4558
357.052	1.02899	0.23870477	3296.1716
357.95288	1.0323952	0.23977658	3295.6563
358.85376	1.0367442	0.24073358	3305.1609
359.75464	1.0385892	0.24189965	3301.8682
360.65552	1.0409225	0.24289417	3298.4766
361.5564	1.0438921	0.24391931	3302.0564
362.45728	1.0479344	0.2450397	3301.8137
363.35815	1.0460788	0.24593727	3301.6589
364.25903	1.0535295	0.24699722	3308.9995
365.15991	1.0565988	0.24789615	3307.2734
366.06079	1.0561613	0.24870171	3301.8191
366.96167	1.0599276	0.24974655	3315.7676
367.86255	1.0616794	0.25063819	3310.0852
368.76343	1.064728	0.25160703	3310.9819
369.66431	1.0661503	0.25282067	3316.0894
370.56519	1.0687428	0.25371003	3319.4155
371.46606	1.0757461	0.25484541	3319.6243
372.36694	1.0769744	0.2558347	3315.1077
373.26782	1.0792742	0.25675455	3322.72
374.1687	1.0814033	0.25777602	3319.5759
375.06958	1.0857704	0.25890329	3330.4766
375.97046	1.0876569	0.25995839	3331.1633
376.87134	1.0915743	0.26103479	3330.2859
377.77222	1.0918163	0.26220793	3337.8621
378.6731	1.0949777	0.26315776	3331.0608
379.57397	1.0992311	0.26406771	3333.6619
380.47485	1.1006213	0.26501864	3332.5239
381.37573	1.1027198	0.26577154	3331.3853
382.27661	1.1069365	0.26695275	3344.3838
383.17749	1.1102662	0.26809111	3346.2451
384.07837	1.1106473	0.26913854	3342.3071
384.97925	1.11501	0.27023607	3347.0259
385.88013	1.1164136	0.27141306	3347.4189
386.78101	1.1191365	0.27258334	3351.7529
387.68188	1.125216	0.27360085	3350.1711
388.58276	1.1247084	0.27457383	3344.303
389.48364	1.1267198	0.27546632	3353.1411
390.38452	1.1291876	0.27652988	3354.1086
391.2854	1.1336533	0.27758184	3355.8164
392.18628	1.1363603	0.27844453	3353.0193
393.08716	1.1378597	0.27914578	3352.4561
393.98804	1.1417353	0.28026038	3363.77
394.88892	1.1453129	0.2812314	3362.4517
395.78979	1.1489081	0.28224838	3362.7271
396.69067	1.1489997	0.28313985	3358.9368
397.59155	1.154196	0.28407469	3364.4297
398.49243	1.1527075	0.28518337	3364.3765
399.39331	1.1581023	0.28632247	3370.3154
400.29419	1.1603831	0.28738716	3371.0674
401.19507	1.1606041	0.28843865	3376.8679
402.09595	1.1654127	0.28968215	3377.9216
402.99683	1.170173	0.29076746	3375.9368
403.89771	1.17189	0.29178762	3377.4897
404.79858	1.1719798	0.29282603	3381.9707
405.69946	1.1757301	0.29375809	3373.7209
406.60034	1.177868	0.29462326	3374.2407
407.50122	1.1816107	0.2954582	3372.7795
408.4021	1.1857268	0.29655981	3384.0044
409.30298	1.184505	0.2974225	3382.8591
410.20386	1.1900196	0.2984902	3380.4749
411.10474	1.1923578	0.29951668	3387.9961
412.00562	1.1984203	0.30065635	3390.344
412.90649	1.1942729	0.30166587	3384.2439
413.80737	1.2012215	0.30260074	3393.5242
414.70825	1.2037178	0.30355042	3389.3877
415.60913	1.2050529	0.30453569	3386.6846
416.51001	1.2077048	0.30527154	3387.5376
417.41089	1.2122953	0.30632544	3401.6365
418.31177	1.2130103	0.30721754	3395.3389
419.21265	1.2175851	0.30850643	3407.6201
420.11353	1.2168969	0.30961049	3398.5886
421.0144	1.2221434	0.31061953	3394.8223
421.91528	1.2219495	0.31167555	3397.7461
422.81616	1.2274311	0.31275812	3408.0295
423.71704	1.2322488	0.31368762	3409.707
424.61792	1.2341388	0.3147305	3409.1421
425.5188	1.2364659	0.31575483	3409.9607
426.41968	1.2379742	0.31671602	3413.0281
427.32056	1.2397527	0.31768605	3406.7915
428.22144	1.2417886	0.31862003	3412.6113
429.12231	1.2449996	0.31956315	3413.5691
430.02319	1.2505324	0.32055837	3414.3655
430.92407	1.2521646	0.32149357	3413.5317
431.82495	1.255536	0.32253966	3423.5127
432.72583	1.2602981	0.32391071	3428.8489
433.62671	1.2603619	0.32487884	3418.5061
434.52759	1.2623118	0.32592589	3420.9341
435.42847	1.2654059	0.32701677	3424.0393
436.32935	1.2649093	0.32776204	3424.6863
437.23022	1.2707604	0.32885936	3428.542
438.1311	1.2729452	0.32972637	3423.4458
439.03198	1.2771306	0.33085644	3433.6028
439.93286	1.2788366	0.33180767	3432.2358
440.83374	1.2809907	0.33278596	3425.9294
441.73462	1.2854617	0.33367136	3429.4363
442.6355	1.2885888	0.33489254	3438.4629
443.53638	1.2902206	0.33591005	3434.8635
444.43726	1.2915788	0.33687139	3435.1658
445.33813	1.2958392	0.33781177	3433.8848
446.23901	1.2947875	0.33884287	3438.908
447.13989	1.2991127	0.33973828	3438.2249
448.04077	1.3017213	0.34071156	3442.9055
448.94165	1.3057823	0.34172302	3442.5015
449.84253	1.3102411	0.34265032	3441.6448
450.74341	1.3100206	0.34351769	3441.2546
451.64429	1.3143545	0.34462956	3450.2859
452.54517	1.3166033	0.34573579	3447.7754
453.44604	1.3203714	0.34683949	3451.8384
454.34692	1.3229533	0.34791833	3458.0803
455.2478	1.3242658	0.34906822	3453.8547
456.14868	1.3271042	0.35020792	3453.0918
457.04956	1.3297415	0.35126019	3458.0256
457.95044	1.3317157	0.35220793	3456.2422
458.85132	1.3367316	0.353239	3462.1541
459.7522	1.3390937	0.35433775	3461.6729
460.65308	1.3420012	0.35538521	3461.7341
461.55396	1.3447067	0.35638189	3458.3701
462.45483	1.3472482	0.35748813	3465.2361
463.35571	1.3490525	0.3584758	3465.3047
464.25659	1.3516785	0.35934046	3462.6418
465.15747	1.3554707	0.36059821	3470.4006
466.05835	1.3583245	0.36165839	3465.5669
466.95923	1.3579506	0.3625429	3461.8691
467.86011	1.3619832	0.36349452	3471.3511
468.76099	1.365738	0.36464864	3479.522
469.66187	1.3677692	0.36588261	3473.7236
470.56274	1.3724455	0.36684474	3473.7847
471.46362	1.3739004	0.36773691	3472.6528
472.3645	1.3735822	0.36863258	3474.0449
473.26538	1.3794277	0.36963445	3471.3936
474.16626	1.3803442	0.37052023	3477.2966
475.06714	1.3823982	0.37143067	3476.7771
475.96802	1.3853911	0.37254289	3477.8572
476.8689	1.3908131	0.3735719	3484.7295
477.76978	1.3878906	0.37435818	3474.7617
478.67065	1.394187	0.3754006	3485.7544
479.57153	1.3965026	0.37654558	3489.9412
480.47241	1.3989003	0.37767869	3488.873
481.37329	1.4033856	0.37879464	3485.8228
482.27417	1.4068027	0.37981397	3494.4841
483.17505	1.4097798	0.38102347	3487.5466
484.07593	1.4105668	0.38198647	3490.8284
484.97681	1.4127632	0.38302168	3495.1248
485.87769	1.4153831	0.3842226	3498.075
486.77856	1.4199128	0.38531926	3491.1787
487.67944	1.4213034	0.38622883	3497.4819
488.58032	1.424287	0.38728455	3498.8901
489.4812	1.4249129	0.38826814	3498.7839
490.38208	1.4328531	0.38936314	3501.0559
491.28296	1.4338319	0.39027908	3502.8308
492.18384	1.4372017	0.39128554	3499.0242
493.08472	1.4390798	0.39219093	3499.5146
493.9856	1.4386727	0.39297068	3498.6938
494.88647	1.4432387	0.39391851	3502.7024
495.78735	1.4451805	0.39508483	3508.5774
496.68823	1.4500858	0.39620224	3508.5583
497.58911	1.4510731	0.39713547	3506.1292
498.48999	1.458095	0.39823291	3507.5701
499.39087	1.4577039	0.39920208	3518.2983
500.29175	1.4603156	0.40032923	3510.5156
501.19263	1.4621981	0.40162078	3518.844
502.09351	1.4678895	0.40265718	3514.3584
502.99438	1.4689167	0.40348673	3508.6909
503.89526	1.4709877	0.40432906	3516.2561
504.79614	1.4716148	0.40528286	3511.6223
505.69702	1.4725927	0.40627873	3515.6582
506.5979	1.4773548	0.40722561	3518.6077
507.49878	1.4806314	0.40849277	3517.9353
508.39966	1.4862903	0.40961838	3519.1321
509.30054	1.4880913	0.41057757	3519.9626
510.20142	1.4880221	0.41148457	3525.6921
511.10229	1.4940964	0.41260639	3528.7336
512.00317	1.4936463	0.4137575	3530.8445
512.90405	1.4997482	0.41486526	3528.2053
513.80493	1.5009415	0.41575968	3527.3586
514.70581	1.5053903	0.41699824	3535.1616
515.60669	1.5065197	0.41795114	3526.3464
516.50757	1.5081041	0.41888946	3531.481
517.40845	1.5138086	0.42008018	3538.386
518.30933	1.5141802	0.42111623	3533.6404
519.21021	1.5173196	0.42205691	3531.6997
520.11108	1.5191334	0.42312071	3535.5935
521.01196	1.5179286	0.42429346	3534.9138
521.91284	1.5244592	0.42541152	3539.219
522.81372	1.526426	0.42638904	3534.8259
523.7146	1.5292493	0.42758086	3539.8672
524.61548	1.5322185	0.42867449	3543.3882
525.51636	1.5377883	0.42977041	3548.2542
526.41724	1.5367481	0.43089864	3548.8232
527.31812	1.5392789	0.43217725	3543.291
528.21899	1.5442958	0.43324438	3546.1619
529.11987	1.5424771	0.43413681	3545.7302
530.02075	1.5488433	0.43502063	3546.0176
530.92163	1.5520931	0.43596658	3545.7117
531.82251	1.5542917	0.43692788	3544.9556
532.72339	1.5568349	0.43797734	3545.3286
533.62427	1.5575209	0.43903109	3549.2668
534.52515	1.5623137	0.44008264	3560.0012
535.42603	1.5657017	0.44126013	3556.2493
536.3269	1.5672123	0.44227308	3555.6604
537.22778	1.5694926	0.44335926	3552.6626
538.12866	1.5717584	0.44434869	3553.625
539.02954	1.5758232	0.44541425	3559.7634
539.93042	1.5800231	0.44658557	3562.2361
540.8313	1.5822684	0.44773683	3568.6206
541.73218	1.5837076	0.44883049	3565.2522
542.63306	1.5873691	0.44993752	3561.0376
543.53394	1.5912925	0.45085651	3566.2097
544.43481	1.5947168	0.45189574	3564.4121
545.33569	1.5928915	0.45270532	3560.771
546.23657	1.5989984	0.45370111	3569.2173
547.13745	1.600266	0.45478642	3568.3423
548.03833	1.6036582	0.45590425	3569.0322
548.93921	1.6078182	0.45689577	3569.6394
549.84009	1.6092291	0.45799896	3579.6572
550.74097	1.6116736	0.45912603	3571.9114
551.64185	1.613139	0.4602797	3574.2253
552.54272	1.6176695	0.46152428	3576.0842
553.4436	1.6199144	0.46275654	3578.6157
554.34448	1.6239145	0.46389225	3572.7649
555.24536	1.6260047	0.46470305	3571.9712
556.14624	1.6282022	0.46561453	3573.3923
557.04712	1.6295675	0.46671301	3579.9644
557.948	1.6335356	0.46766061	3577.6453
558.84888	1.6368634	0.46863818	3579.0605
559.74976	1.6369705	0.46972841	3581.7844
560.65063	1.6434572	0.47089791	3589.8767
561.55151	1.6429095	0.47213063	3585.4919
562.45239	1.6449746	0.47319332	3579.7563
563.35327	1.6505247	0.47425124	3584.4719
564.25415	1.6518506	0.47534153	3584.9944
565.15503	1.6504897	0.47656676	3591.7041
566.05591	1.6563245	0.47757685	3587.0459
566.95679	1.6602008	0.47888261	3591.8511
567.85767	1.6624024	0.48020414	3592.812
568.75854	1.6656231	0.48124415	3585.6497
569.65942	1.6643167	0.48222351	3582.2947
570.5603	1.6693319	0.48328725	3591.7646
571.46118	1.6735409	0.48456529	3593.2476
572.36206	1.6748523	0.48565236	3592.2864
573.26294	1.6788328	0.48659191	3592.8159
574.16382	1.680774	0.48777097	3598.1624
575.0647	1.6834559	0.48900741	3599.4402
575.96558	1.6841002	0.49009648	3594.0254
576.86646	1.6887263	0.49116173	3591.9048
577.76733	1.6933688	0.49228707	3600.3423
578.66821	1.6940253	0.49351951	3604.6206
579.56909	1.6955122	0.49454924	3600.374
580.46997	1.701112	0.49530762	3596.4463
581.37085	1.7064358	0.49618706	3594.9189
582.27173	1.7051319	0.49705362	3602.2402
583.17261	1.7089851	0.49818683	3611.3186
584.07349	1.7112601	0.49940401	3605.2126
584.97437	1.7136056	0.50079191	3607.2388
585.87524	1.7154976	0.50183052	3604.353
586.77612	1.7178483	0.50291884	3608.8062
587.677	1.7230408	0.50392437	3608.498
588.57788	1.7255263	0.50519687	3613.3027
589.47876	1.7305354	0.50640726	3611.0867
590.37964	1.7321757	0.50756681	3619.6914
591.28052	1.7335024	0.50862175	3602.9641
592.1814	1.7380868	0.50981128	3618.9829
593.08228	1.7394813	0.51099789	3613.7688
593.98315	1.7396156	0.51215971	3611.4861
594.88403	1.7451739	0.51324797	3612.7927
595.78491	1.7454129	0.5145312	3618.3669
596.68579	1.7478088	0.51588875	3619.3391
597.58667	1.7523766	0.51715177	3622.4573
598.48755	1.7534667	0.51828754	3616.4436
599.38843	1.7577987	0.51947951	3617.907
600.28931	1.7568727	0.52044517	3610.614
601.19019	1.7594974	0.52146691	3620.8508
602.09106	1.7650126	0.52231318	3614.1035
602.99194	1.7684892	0.52342874	3621.8408
603.89282	1.7713865	0.52451116	3621.4863
604.7937	1.7737657	0.52569145	3618.9304
605.69458	1.7748551	0.52676821	3621.5842
606.59546	1.7802941	0.52811676	3626.0347
607.49634	1.7831304	0.52909976	3625.575
608.39722	1.78257	0.53012174	3631.2175
609.2981	1.7876577	0.53128958	3633.0835
610.19897	1.7905233	0.532417	3629.8074
611.09985	1.7925084	0.53360963	3630.4883
612.00073	1.7921529	0.53514844	3631.0107
612.90161	1.795612	0.53620058	3629.3718
613.80249	1.8021652	0.5375706	3638.1301
614.70337	1.804781	0.53864002	3637.115
615.60425	1.8082441	0.53979713	3629.2786
616.50513	1.8124558	0.540833	3632.0781
617.40601	1.8094071	0.54160935	3624.1687
618.30688	1.8114266	0.54266006	3629.4263
619.20776	1.8184974	0.54389238	3642.4683
620.10864	1.8189193	0.54508311	3640.7588
621.00952	1.8210591	0.54653907	3638.6533
621.9104	1.824894	0.54792643	3637.1599
622.81128	1.8299803	0.54902184	3636.0479
623.71216	1.830847	0.55031383	3638.5813
624.61304	1.8315302	0.55159527	3642.8792
625.51392	1.8351661	0.55294657	3642.9106
626.41479	1.8399664	0.55396563	3638.1914
627.31567	1.8422825	0.55506015	3640.5613
628.21655	1.8413937	0.55619991	3637.9529
629.11743	1.8460885	0.55742979	3644.8413
630.01831	1.8486449	0.55856925	3650.4514
630.91919	1.8507104	0.55973947	3640.1321
631.82007	1.854467	0.56109977	3652.4502
632.72095	1.8589053	0.56228244	3648.8406
633.62183	1.8587748	0.56347066	3640.9646
634.52271	1.8639277	0.56467021	3651.0242
635.42358	1.8665786	0.56586564	3653.7222
636.32446	1.8690832	0.56693262	3644.9131
637.22534	1.8693737	0.56816697	3650.3223
638.12622	1.8726348	0.56944764	3651.6499
639.0271	1.8770517	0.57062346	3653.1201
639.92798	1.8794216	0.57187551	3653.3105
640.82886	1.8839743	0.57292837	3652.7131
641.72974	1.8860781	0.57414043	3654.6123
642.63062	1.8857576	0.57546747	3655.1003
643.53149	1.8897206	0.57658464	3656.8298
644.43237	1.8945303	0.57789546	3656.833
645.33325	1.8970836	0.57916456	3658.9851
646.23413	1.8980423	0.58044553	3659.3555
647.13501	1.8994536	0.58172262	3658.6228
648.03589	1.9033811	0.58316106	3663.2991
648.93677	1.9066441	0.58444583	3656.2083
649.83765	1.9067155	0.58558685	3654.2815
650.73853	1.9151782	0.5867784	3658.2966
651.6394	1.9130033	0.58781105	3659.439
652.54028	1.9157968	0.58893502	3655.6113
653.44116	1.9190423	0.5899967	3658.3137
654.34204	1.9207995	0.59111118	3660.0393
655.24292	1.9257365	0.59221995	3660.4678
656.1438	1.9257576	0.59353817	3669.4509
657.04468	1.9299412	0.59478736	3667.3572
657.94556	1.9337844	0.59610581	3667.165
658.84644	1.9358623	0.59746623	3664.7744
659.74731	1.9384587	0.59865284	3665.4712
660.64819	1.9410406	0.59989107	3669.1738
661.54907	1.9477072	0.60114372	3672.3848
662.44995	1.9497783	0.60231501	3673.9644
663.35083	1.9529841	0.60347277	3671.5469
664.25171	1.951075	0.60494238	3669.0137
665.15259	1.9521239	0.6065833	3674.8904
666.05347	1.958811	0.60799891	3672.72
666.95435	1.9596004	0.60940778	3668.3479
667.85522	1.9628781	0.61066329	3673.7239
668.7561	1.9666106	0.61195904	3676.5659
669.65698	1.9676957	0.61320567	3671.5974
670.55786	1.9714847	0.61448973	3671.0291
671.45874	1.9766293	0.6158399	3674.395
672.35962	1.9799771	0.61702305	3676.6414
673.2605	1.9779295	0.61841381	3676.0818
674.16138	1.981979	0.61974496	3675.5549
675.06226	1.984058	0.6209811	3670.4382
675.96313	1.9892528	0.62223691	3675.583
676.86401	1.9920713	0.62352556	3677.1577
677.76489	1.9927666	0.62478656	3674.9519
678.66577	1.9939214	0.62618083	3679.5945
679.56665	1.9976114	0.62757415	3677.7585
680.46753	2.0009265	0.62896425	3684.8037
681.36841	2.0000646	0.63010865	3675.4521
682.26929	2.0035486	0.63127381	3673.3384
683.17017	2.0085995	0.63261235	3685.8259
684.07104	2.0106046	0.63382655	3675.1941
684.97192	2.0134833	0.63502735	3677.3672
685.8728	2.0156808	0.63634223	3678.1345
686.77368	2.0176935	0.6376434	3677.0535
687.67456	2.0214961	0.63875467	3675.8359
688.57544	2.0249324	0.64017028	3686.9177
689.47632	2.0263641	0.64145213	3690.1372
690.3772	2.031688	0.64309782	3683.6807
691.27808	2.0336878	0.64438033	3680.2092
692.17896	2.0361788	0.64557385	3678.9832
693.07983	2.0399408	0.64669228	3686.6433
693.98071	2.0429671	0.64812028	3695.3601
694.88159	2.0420177	0.64947927	3683.5254
695.78247	2.0449483	0.65091795	3688.5347
696.68335	2.0467813	0.65209556	3687.0151
697.58423	2.0527563	0.65373588	3691.2039
698.48511	2.055474	0.65522557	3692.4897
699.38599	2.0593257	0.65659451	3695.7769
700.28687	2.0572352	0.65793246	3688.4382
701.18774	2.0629866	0.6595208	3693.749
702.08862	2.0654211	0.66081476	3686.6418
702.9895	2.0678768	0.66218388	3692.8232
703.89038	2.07109	0.66370237	3697.2522
704.79126	2.0738358	0.66559535	3698.7832
705.69214	2.0765295	0.66718209	3695.4031
706.59302	2.0799625	0.66850168	3690.4514
707.4939	2.0797369	0.66987741	3690.0459
708.39478	2.0861263	0.67108905	3694.0293
709.29565	2.084655	0.67238009	3695.9263
710.19653	2.0894117	0.67366111	3699.3052
711.09741	2.0936172	0.67529315	3698.6299
711.99829	2.0967498	0.67668676	3698.0396
712.89917	2.0980787	0.67818403	3701.1055
713.80005	2.0988038	0.67948222	3694.2468
714.70093	2.1041243	0.68069643	3692.4448
715.60181	2.1055825	0.68188852	3699.3586
716.50269	2.1072814	0.68319041	3693.7517
717.40356	2.1114271	0.68470782	3698.7483
718.30444	2.1166754	0.68609631	3698.5654
719.20532	2.1135843	0.68746519	3697.594
720.1062	2.1224477	0.68909693	3701.1484
721.00708	2.1241021	0.69055176	3698.29
721.90796	2.1248386	0.69207788	3698.9497
722.80884	2.1275225	0.69327581	3699.6619
723.70972	2.1280801	0.69478631	3701.6113
724.6106	2.1334193	0.69649053	3699.6082
725.51147	2.1345222	0.69773597	3701.4233
726.41235	2.1369989	0.69896752	3697.387
727.31323	2.1450124	0.70030409	3702.5833
728.21411	2.1447613	0.70178616	3707.7729
729.11499	2.14784	0.70333123	3702.8396
730.01587	2.1501012	0.70472699	3704.314
730.91675	2.1514018	0.70633304	3700.458
731.81763	2.1569612	0.70781952	3708.8643
732.71851	2.1575077	0.70925516	3705.4573
733.61938	2.1605515	0.71080512	3701.7329
734.52026	2.1635475	0.71232575	3706.9399
735.42114	2.1659439	0.71401584	3708.0115
736.32202	2.1695902	0.71580446	3710.384
737.2229	2.1714959	0.71741921	3707.6389
738.12378	2.1749663	0.71859854	3701.7139
739.02466	2.1754088	0.72027135	3706.2908
739.92554	2.1809547	0.72196269	3711.3157
740.82642	2.1809275	0.72360557	3712.0784
741.72729	2.1849899	0.72519326	3701.031
742.62817	2.1836402	0.72651434	3702.0093
743.52905	2.1866932	0.72786456	3699.968
744.42993	2.1920006	0.72948676	3706.2087
745.33081	2.1982682	0.73112255	3708.2146
746.23169	2.1987314	0.73229671	3705.3401
747.13257	2.2041872	0.73380876	3711.9639
748.03345	2.2033513	0.73543113	3710.7886
748.93433	2.2059202	0.73714077	3713.1304
749.83521	2.2096612	0.73899877	3715.6785
750.73608	2.2123888	0.74096727	3713.6233
751.63696	2.2155449	0.74260628	3713.4031
752.53784	2.216897	0.74429011	3714.4426
753.43872	2.2212236	0.74581933	3706.3921
754.3396	2.2240484	0.74767685	3711.2114
755.24048	2.2257469	0.74912077	3709.6509
756.14136	2.2277441	0.75059563	3709.5645
757.04224	2.2311018	0.75228626	3713.4412
757.94312	2.2325664	0.75380236	3706.4636
758.84399	2.2361956	0.75533009	3712.4456
759.74487	2.2382758	0.7568323	3716.0879
760.64575	2.2401609	0.75828183	3702.6184
761.54663	2.2454114	0.76001281	3714.8535
762.44751	2.2422879	0.76177227	3707.6589
763.34839	2.2500448	0.7635901	3714.6011
764.24927	2.252064	0.76508468	3707.1628
765.15015	2.2557044	0.76633835	3705.9575
766.05103	2.258729	0.76791859	3714.7578
766.9519	2.2613616	0.76935929	3713.3962
767.85278	2.2624106	0.77115124	3717.7073
768.75366	2.2648072	0.77299136	3714.6672
769.65454	2.269875	0.77471262	3715.8384
770.55542	2.2722647	0.77647722	3713.0015
771.4563	2.2737238	0.7780804	3710.0986
772.35718	2.2764852	0.77951676	3715.4846
773.25806	2.2802312	0.7810635	3710.3777
774.15894	2.2819915	0.78252864	3712.9807
775.05981	2.2826326	0.78401285	3708.9077
775.96069	2.286109	0.78586853	3715.4978
776.86157	2.2909377	0.78788292	3718.4468
777.76245	2.2941816	0.79005396	3717.9617
778.66333	2.2963777	0.79194695	3712.1135
779.56421	2.3002927	0.79369628	3717.1956
780.46509	2.2997038	0.79528981	3710.269
781.36597	2.3040524	0.79703569	3713.3044
782.26685	2.3076162	0.79862863	3715.6143
783.16772	2.3058672	0.80055135	3718.3862
784.0686	2.3103545	0.80276209	3718.5957
784.96948	2.3144486	0.80467969	3713.6223
785.87036	2.3159339	0.80629283	3707.6165
786.77124	2.3206115	0.80791014	3713.501
787.67212	2.3223102	0.8093726	3712.5293
788.573	2.3279521	0.81100613	3719.3618
789.47388	2.3268855	0.81272012	3715.8044
790.37476	2.3316607	0.81470776	3722.9229
791.27563	2.3310268	0.81650162	3715.9646
792.17651	2.3352208	0.81846482	3717.0149
793.07739	2.3378787	0.82031482	3716.0161
793.97827	2.3399153	0.82195866	3709.6064
794.87915	2.3470795	0.82374537	3721.3708
795.78003	2.3471117	0.82528794	3713.752
796.68091	2.350301	0.82699865	3713.9958
797.58179	2.3507447	0.82860476	3709.4321
798.48267	2.353292	0.83052349	3717.0854
799.38354	2.3557272	0.8323909	3713.2134
800.28442	2.360265	0.83437854	3716.3564
801.1853	2.3621924	0.83626187	3712.6248
802.08618	2.3670025	0.83815211	3717.1023
802.98706	2.3690743	0.84006512	3712.9636
803.88794	2.3695121	0.84193128	3714.1667
804.78882	2.372932	0.84382999	3712.7114
805.6897	2.3769126	0.84569651	3720.0869
806.59058	2.3789556	0.84780204	3711.7788
807.49146	2.3806493	0.8497591	3715.9624
808.39233	2.3813846	0.85183489	3711.6326
809.29321	2.3852506	0.85393095	3715.9233
810.19409	2.3905227	0.8559975	3715.6255
811.09497	2.3932924	0.85786855	3715.2656
811.99585	2.3964012	0.85993266	3717.2312
812.89673	2.3989308	0.86191308	3715.3633
813.79761	2.4021101	0.86384165	3714.3613
814.69849	2.4038272	0.8657788	3718.2937
815.59937	2.4065914	0.86748576	3709.6355
816.50024	2.4102581	0.86954927	3714.7964
817.40112	2.4106753	0.87175643	3719.8408
818.302	2.4143703	0.87389147	3714.2771
819.20288	2.4167254	0.87570238	3708.8953
820.10376	2.4203603	0.87775618	3719.8298
821.00464	2.4231491	0.87997717	3715.4026
821.90552	2.4247594	0.88203615	3711.4414
822.8064	2.4281039	0.88402224	3713.9326
823.70728	2.4301691	0.88592434	3707.7175
824.60815	2.4315369	0.8879171	3714.4263
825.50903	2.4373207	0.890329	3714.1372
826.40991	2.4364493	0.89226651	3713.5049
827.31079	2.4420614	0.89487678	3717.5964
828.21167	2.4411721	0.89713287	3704.9651
829.11255	2.4456184	0.89914846	3703.3936
830.01343	2.4500489	0.90110523	3710.292
830.91431	2.4490042	0.90275133	3701.6648
831.81519	2.4556353	0.904814	3713.3274
832.71606	2.455436	0.90659881	3705.8203
833.61694	2.4596241	0.9083851	3707.5098
834.51782	2.461431	0.91105419	3712.844
835.4187	2.4659634	0.91327381	3711.2278
836.31958	2.4688749	0.9153685	3707.823
837.22046	2.4727905	0.91739184	3707.3838
838.12134	2.4763305	0.91965848	3715.853
839.02222	2.4761312	0.92183328	3707.811
839.9231	2.4799576	0.92429924	3711.3098
840.82397	2.4809356	0.92651683	3705.4885
841.72485	2.4817801	0.92872369	3707.1052
842.62573	2.4854465	0.93109858	3707.0461
843.52661	2.4904203	0.93362159	3706.4509
844.42749	2.4929106	0.93611288	3705.2368
845.32837	2.4954553	0.93870008	3709.0068
846.22925	2.5009184	0.9409036	3709.0479
847.13013	2.4999087	0.94313145	3704.666
848.03101	2.501914	0.94551724	3703.4705
848.93188	2.5047536	0.9476124	3698.7151
849.83276	2.5091517	0.9498018	3704.9575
850.73364	2.5120091	0.95218515	3701.686
851.63452	2.5150149	0.95435458	3700.3977
852.5354	2.514868	0.95638353	3699.5857
853.43628	2.5181961	0.95870417	3702.324
854.33716	2.5227866	0.9612323	3702.7578
855.23804	2.5237129	0.96400779	3707.2092
856.13892	2.5288599	0.96686506	3704.4272
857.03979	2.5295959	0.96937197	3697.9771
857.94067	2.5360105	0.97194141	3700.3557
858.84155	2.5336874	0.97411001	3698.5212
859.74243	2.5395043	0.97633767	3699.8257
860.64331	2.5422039	0.97862744	3693.1008
861.54419	2.5426431	0.98092258	3693.4573
862.44507	2.5455968	0.98336476	3698.0747
863.34595	2.5491672	0.9854036	3689.8047
864.24683	2.5497556	0.98731911	3693.1731
865.14771	2.5579302	0.98950589	3692.2649
866.04858	2.5561931	0.9918592	3691.49
866.94946	2.561656	0.99393219	3692.1208
867.85034	2.5640583	0.9964813	3696.52
868.75122	2.5685837	0.99898243	3691.5996
869.6521	2.5678949	1.0014043	3687.7334
870.55298	2.5697634	1.0042723	3693.4392
871.45386	2.5726612	1.0070018	3690.4607
872.35474	2.5756578	1.0090513	3682.6455
873.25562	2.5781338	1.0114492	3690.625
874.15649	2.5794222	1.0139503	3682.6218
875.05737	2.5844631	1.0164334	3686.3118
875.95825	2.5870361	1.0185815	3682.3376
876.85913	2.5849881	1.0206254	3677.3281
877.76001	2.5952492	1.022948	3681.5034
878.66089	2.5950305	1.0252427	3685.9761
879.56177	2.6012106	1.0281159	3687.8823
880.46265	2.6000714	1.0307127	3683.1877
881.36353	2.6060522	1.0336576	3686.759
882.2644	2.6061404	1.0363462	3678.9907
883.16528	2.6083724	1.0391296	3678.3005
884.06616	2.6094871	1.0419341	3677.344
884.96704	2.614902	1.0445766	3676.4272
885.86792	2.6168334	1.047398	3679.0571
886.7688	2.6182618	1.0500262	3675.4153
887.66968	2.621588	1.052161	3672.5059
888.57056	2.6258609	1.0546471	3674.4587
889.47144	2.6277776	1.0571226	3672.4392
890.37231	2.6337368	1.0597037	3672.0471
891.27319	2.6342454	1.0619495	3668.854
892.17407	2.6331904	1.064549	3671.3289
893.07495	2.639905	1.0674207	3671.7881
893.97583	2.6406145	1.0703148	3669.4136
894.87671	2.642144	1.0731591	3667.1873
895.77759	2.6482475	1.0761342	3667.1357
896.67847	2.6474187	1.0785737	3659.4653
897.57935	2.6501296	1.0812004	3661.6606
898.48022	2.6524258	1.0837141	3659.2439
899.3811	2.6569791	1.0862403	3658.4233
900.28198	2.6599333	1.0888449	3661.8726
901.18286	2.6626546	1.0914418	3659.9519
902.08374	2.6671813	1.0939515	3657.2236
902.98462	2.6668646	1.0964582	3656.7891
903.8855	2.6708977	1.0990105	3654.5635
904.78638	2.6764741	1.1016121	3657.0486
905.68726	2.6780865	1.1040907	3650.0718
906.58813	2.6787531	1.1070114	3654.8726
907.48901	2.6781816	1.1102262	3650.7856
908.38989	2.68367	1.113076	3645.6091
909.29077	2.6866665	1.1155779	3641.5444
910.19165	2.6885114	1.1181322	3644.8308
911.09253	2.6931167	1.1207796	3652.2466
911.99341	2.6971803	1.1241733	3644.811
912.89429	2.6990559	1.1268485	3639.7905
913.79517	2.7042532	1.1296664	3641.4243
914.69604	2.7044592	1.1319424	3636.2358
915.59692	2.7066386	1.134442	3634.2742
916.4978	2.7086787	1.1371089	3636.4177
917.39868	2.7141993	1.1400576	3634.4895
918.29956	2.7144446	1.1432301	3639.0081
919.20044	2.715487	1.1462892	3638.2219
920.10132	2.7194061	1.1500957	3632.8918
921.0022	2.7237139	1.152968	3626.354
921.90308	2.724694	1.1554071	3627.3381
922.80396	2.7264371	1.1580112	3629.0784
923.70483	2.7286327	1.1610373	3623.6365
924.60571	2.7333786	1.1637056	3618.2297
925.50659	2.7363424	1.1665456	3621.0945
926.40747	2.7380557	1.1692405	3616.8713
927.30835	2.7380548	1.1720628	3616.3748
928.20923	2.7454312	1.174762	3620.96
929.11011	2.7459259	1.1782216	3613.2808
930.01099	2.7517824	1.1807753	3607.5867
930.91187	2.7532821	1.1829997	3604.6465
931.81274	2.7575338	1.185873	3614.6685
932.71362	2.7546163	1.1884605	3606.45
933.6145	2.7593675	1.1919193	3604.5674
934.51538	2.7646141	1.1949354	3600.8599
935.41626	2.7661545	1.1974723	3600.4424
936.31714	2.7673097	1.2004462	3593.417
937.21802	2.7728791	1.2032195	3599.8301
938.1189	2.7733805	1.205765	3592.3696
939.01978	2.7767253	1.208429	3593.5769
939.92065	2.7782719	1.2111567	3592.416
940.82153	2.7803063	1.2143697	3588.3503
941.72241	2.7848926	1.2174386	3588.626
942.62329	2.7871912	1.2202005	3589.8162
943.52417	2.7905812	1.2231117	3585.4312
944.42505	2.7930436	1.2262863	3583.7109
945.32593	2.7951694	1.2295091	3582.8855
946.22681	2.7979124	1.2318195	3568.2981
947.12769	2.8008647	1.2340449	3573.9949
948.02856	2.805583	1.2365417	3573.6836
948.92944	2.8070331	1.2394328	3581.1416
949.83032	2.8103073	1.2428032	3570.6353
950.7312	2.8162031	1.2453671	3573.6724
951.63208	2.8157189	1.2485002	3574.1135
952.53296	2.8181968	1.2514082	3561.5986
953.43384	2.8155968	1.2539662	3558.5254
954.33472	2.8232229	1.2573704	3561.979
955.2356	2.8263764	1.2607591	3562.8296
956.13647	2.8281868	1.2634519	3551.5588
957.03735	2.830483	1.2664206	3552.1516
957.93823	2.8344781	1.2696563	3551.4871
958.83911	2.8382361	1.2727263	3549.4116
959.73999	2.8409874	1.2760662	3545.9473
960.64087	2.8420315	1.2785537	3533.3567
961.54175	2.8446314	1.280921	3540.5393
962.44263	2.8478742	1.2834563	3538.4514
963.34351	2.8512373	1.2862948	3538.3533
964.24438	2.8526292	1.2891115	3533.9326
965.14526	2.8552351	1.292713	3532.0225
966.04614	2.855881	1.2959387	3526.9883
966.94702	2.8622708	1.2988615	3523.2598
967.8479	2.86325	1.3023742	3526.9036
968.74878	2.8648772	1.3053268	3513.6155
969.64966	2.8696826	1.3082693	3517.72
970.55054	2.8706977	1.3109533	3513.8938
971.45142	2.8738565	1.3139156	3514.1213
972.35229	2.8763402	1.3170934	3510.4839
973.25317	2.8818254	1.3194094	3507.2761
974.15405	2.8811808	1.321378	3501.113
975.05493	2.8854597	1.3237427	3499.1802
975.95581	2.8853934	1.3265127	3500.7563
976.85669	2.8905346	1.3293848	3497.01
977.75757	2.8924148	1.3322285	3492.9155
978.65845	2.8963914	1.3355796	3500.9009
979.55933	2.8948503	1.3393651	3493.9875
980.46021	2.9011245	1.3426478	3480.0803
981.36108	2.9026191	1.3450977	3478.5371
982.26196	2.9065623	1.3479519	3479.7271
983.16284	2.9078977	1.3508946	3471.6711
984.06372	2.9116263	1.3534086	3469.3157
984.9646	2.915415	1.3563612	3475.0962
985.86548	2.9142828	1.3593142	3464.0281
986.76636	2.9188533	1.3623443	3463.6187
987.66724	2.9231994	1.3656446	3455.2534
988.56812	2.9233503	1.3681309	3453.1199
989.46899	2.9278312	1.3709456	3451.2922
990.36987	2.9319112	1.3741263	3452.1846
991.27075	2.9309609	1.376945	3442.9373
992.17163	2.9373977	1.3799489	3448.7856
993.07251	2.9402039	1.3832456	3444.4392
993.97339	2.9443307	1.3862865	3436.7573
994.87427	2.9445038	1.3898951	3443.2085
995.77515	2.9469695	1.3934083	3427.3008
996.67603	2.9476998	1.3964906	3425.8438
997.5769	2.9528291	1.399455	3422.925
998.47778	2.9554081	1.4022743	3421.0449
999.37866	2.9569917	1.4052292	3422.6653
1000.2795	2.9613922	1.4080172	3411.426
1001.1804	2.9625928	1.4103248	3401.5437
1002.0813	2.9709506	1.4129068	3410.3264
1002.9822	2.9711688	1.4163938	3412.1929
1003.8831	2.9701662	1.4200795	3400.1462
1004.7839	2.9722588	1.4231446	3394.9585
1005.6848	2.9777727	1.4263549	3393.9482
1006.5857	2.9792902	1.4296322	3388.3521
1007.4866	2.9815295	1.4328116	3376.1016
1008.3875	2.9813261	1.4353603	3371.7322
1009.2883	2.9893405	1.4377834	3373.3845
1010.1892	2.9926777	1.4404873	3376.5278
1011.0901	2.992034	1.4429334	3367.1628
1011.991	2.9974723	1.4456707	3368.5239
1012.8918	3.0000978	1.4487118	3366.7439
1013.7927	3.0016415	1.4517494	3362.4592
1014.6936	3.0025628	1.4550335	3357.0303
1015.5945	3.0069828	1.4581255	3356.3279
1016.4954	3.0111952	1.4619451	3354.4509
1017.3962	3.0113742	1.465976	3344.908
1018.2971	3.0180793	1.469287	3335.3262
1019.198	3.0191178	1.4717215	3321.7361
1020.0989	3.0231237	1.4739375	3327.2996
1020.9998	3.0215733	1.4757837	3317.5015
1021.9006	3.0228703	1.4782718	3323.0205
1022.8015	3.0275674	1.4808038	3317.1819
1023.7024	3.0318463	1.4833925	3320.4802
1024.6033	3.0340569	1.4864622	3313.8564
1025.5042	3.0363064	1.4890794	3309.7087
1026.405	3.03935	1.4920762	3302.7346
1027.3059	3.0412791	1.4944952	3296.7649
1028.2068	3.0415957	1.4972315	3297.4873
1029.1077	3.0462024	1.5010446	3294.574
1030.0085	3.0468941	1.5044836	3285.6062
1030.9094	3.0537794	1.5076594	3279.0071
1031.8103	3.0515947	1.5110599	3274.0933
1032.7112	3.0598991	1.5142094	3276.3303
1033.6121	3.0613532	1.5175344	3270.0498
1034.5129	3.0641127	1.5210764	3260.0859
1035.4138	3.0657372	1.5239083	3249.7122
1036.3147	3.0659797	1.5266581	3250.4395
1037.2156	3.0701892	1.5291485	3247.9238
1038.1165	3.0734503	1.5321413	3239.7764
1039.0173	3.0763032	1.5351382	3230.9778
1039.9182	3.081002	1.5385004	3235.1895
1040.8191	3.08587	1.5421987	3226.2803
1041.72	3.0851634	1.54526	3219.4016
1042.6208	3.084234	1.5485766	3215.5042
1043.5217	3.091383	1.5521059	3214.1367
1044.4226	3.0925031	1.555645	3207.6536
1045.3235	3.0974782	1.5586411	3192.5857
1046.2244	3.0992386	1.5616809	3194.8184
1047.1252	3.0992076	1.5648514	3183.4355
1048.0261	3.1031044	1.5675143	3176.2163
1048.927	3.1043541	1.5702147	3174.4851
1049.8279	3.1079102	1.5731163	3168.3887
1050.7288	3.113714	1.5761646	3166.7153
1051.6296	3.1130757	1.5792822	3157.7583
1052.5305	3.1151538	1.5828146	3150.7178
1053.4314	3.1183674	1.5860603	3150.5452
1054.3323	3.1247208	1.589336	3135.6003
1055.2332	3.1260076	1.5920016	3130.1189
1056.134	3.1262743	1.5950154	3128.8467
1057.0349	3.1308408	1.5977889	3121.7456
1057.9358	3.1371453	1.6012893	3124.7998
1058.8367	3.1363797	1.6051023	3107.4834
1059.7375	3.1388724	1.6087555	3101.4744
1060.6384	3.1420226	1.6120594	3088.9158
1061.5393	3.1460567	1.6150614	3083.8462
1062.4402	3.1478746	1.6180353	3073.5217
1063.3411	3.1521556	1.6214409	3078.1353
1064.2419	3.1540709	1.6251409	3065.9739
1065.1428	3.1554875	1.6285383	3055.0801
1066.0437	3.1596134	1.6317338	3053.4458
1066.9446	3.161437	1.6354481	3044.0923
1067.8455	3.1638849	1.6389916	3030.1421
1068.7463	3.1690519	1.6426744	3027.5496
1069.6472	3.170953	1.6464463	3017.998
1070.5481	3.1689305	1.6496695	2998.8064
1071.449	3.1768196	1.6532352	2998.7864
1072.3499	3.1768181	1.6570668	2991.5435
1073.2507	3.1811965	1.6605779	2979.4097
1074.1516	3.1801341	1.6636666	2962.4832
1075.0525	3.185915	1.6673629	2962.9548
1075.9534	3.1886823	1.6708094	2947.978
1076.8542	3.189626	1.674628	2943.0989
1077.7551	3.1943979	1.6781548	2927.1133
1078.656	3.1988411	1.6811422	2912.7004
1079.5569	3.2011209	1.6837325	2910.1045
1080.4578	3.2012484	1.6866937	2902.7087
1081.3586	3.2039969	1.6906193	2898.4082
1082.2595	3.2076423	1.6945331	2880.1353
1083.1604	3.2102816	1.698733	2867.0918
1084.0613	3.2103753	1.7032994	2841.498
1084.9622	3.2189097	1.7134216	2763.2041
1085.1624	3.2179937	1.7177712	2720.1443