File: datasets/am_bench_2022/raw_data/30-XY.18-2/specimen.dat
MTS793|MPT|ENU|1|2|.|/|:|1|0|0|A

Operator Information						Time:	17.33667	Sec	10/18/2021 2:57:33 PM
Operator	Nick Derimow
Project	AM Bench 2022 mini-tensile challenge
Specimen ID	30-XY.18-2
Material	PBF-L Inconel 625
Specimen Width	2.54	mm
Specimen Thickness	1.5	mm
Notes
Operator Information End

Data Acquisition						Time:	1018.3303	Sec	10/18/2021 3:14:14 PM
Time	Axial Displacement	Axial Extensometer	Axial Force
Sec	mm	mm	N
17.450195	0.0018246769	-2.8042174e-05	64.849831
18.451172	0.0029898405	0.00010730675	76.284393
19.452148	0.0049199136	0.00017749317	87.365791
20.453125	0.0099619729	0.00015854588	100.78223
21.454102	0.011746368	0.00019309357	113.00192
22.455078	0.017977666	0.00027302562	125.94086
23.456055	0.016327884	0.00029473589	135.96733
24.457031	0.019537654	0.00040072802	149.89252
25.458008	0.02248501	0.00049884111	161.82074
26.458984	0.026670473	0.00051162217	175.85205
27.459961	0.031038696	0.0005905329	192.52214
28.460938	0.032782268	0.00063474837	205.61917
29.461914	0.034407668	0.00077501056	228.5379
30.462891	0.039728019	0.00082061108	249.19211
31.463867	0.038547438	0.00090099289	264.40079
32.464844	0.041045878	0.00093380309	284.82101
33.46582	0.046564925	0.00099635939	302.09525
34.466797	0.047352117	0.0011826811	322.23392
35.467773	0.054411173	0.0012677795	340.9783
36.46875	0.053559646	0.0012932065	361.15826
37.469727	0.060012583	0.0014378994	386.19159
38.470703	0.059718359	0.0014481153	399.18069
39.47168	0.061315484	0.0014716563	422.98126
40.472656	0.066922888	0.0016058302	451.78397
41.473633	0.069222175	0.0017310329	467.54868
42.474609	0.071284555	0.0019003373	498.86624
43.475586	0.07733345	0.0018702921	518.87109
44.476563	0.077256411	0.002008907	536.04828
45.477539	0.082713068	0.002110577	568.07928
46.478516	0.085754827	0.0023032585	594.76202
47.479492	0.088545188	0.00236511	615.91791
48.480469	0.089630291	0.0024228317	641.39221
49.481445	0.093607582	0.002559955	667.26221
50.482422	0.094641052	0.00269476	695.89813
51.483398	0.097407028	0.002775986	720.63275
52.484375	0.10321005	0.0029184446	753.37854
53.485352	0.10780699	0.0030287651	775.18268
54.486328	0.10834421	0.0031467353	802.93713
55.487305	0.1110352	0.0033018407	833.57446
56.488281	0.11387309	0.0034041407	858.95349
57.489258	0.11804544	0.0035145811	889.05878
58.490234	0.11966326	0.0036198315	913.646
59.491211	0.12648156	0.0037362331	936.88202
60.492188	0.12792088	0.0038450414	965.10284
61.493164	0.12991509	0.0039635114	990.56696
62.494141	0.13112552	0.004151796	1024.042
63.495117	0.13931578	0.0042174258	1055.3271
64.496094	0.13919142	0.0043062787	1081.369
65.49707	0.14235447	0.0044529662	1110.1664
66.498047	0.14198916	0.0046503642	1136.869
67.499023	0.14759226	0.0047385236	1164.6722
68.5	0.15017736	0.0047433581	1185.9891
69.500977	0.15285996	0.0050372919	1215.7488
70.501953	0.15811181	0.0050428649	1243.8605
71.50293	0.15625924	0.005237747	1267.8198
72.503906	0.16072008	0.0053592012	1300.2915
73.504883	0.16444167	0.0054802485	1328.9841
74.505859	0.16971633	0.0056080013	1363.2316
75.506836	0.17030703	0.0057211942	1389.8994
76.507813	0.17383049	0.0057935114	1418.6138
77.508789	0.17627648	0.005937438	1446.369
78.509766	0.18224382	0.0061006593	1470.134
79.510742	0.18400584	0.006255093	1501.8317
80.511719	0.18732814	0.0063426215	1527.8969
81.512695	0.18805367	0.0063701412	1544.5696
82.513672	0.19145398	0.0065658018	1580.3752
83.514648	0.19354674	0.0067367456	1613.1119
84.515625	0.19863325	0.0068165045	1633.8591
85.516602	0.20126754	0.0069795134	1668.4484
86.517578	0.20296465	0.0070178653	1693.2679
87.518555	0.20881623	0.007174694	1725.9305
88.519531	0.21087001	0.0072899326	1745.6456
89.520508	0.21132344	0.0074739587	1781.0558
90.521484	0.21758506	0.0076117264	1795.0906
91.522461	0.22052197	0.0076748603	1819.7649
92.523438	0.21966799	0.0077295979	1847.6464
93.524414	0.22569823	0.0078628706	1873.256
94.525391	0.22745004	0.0079417322	1886.2306
95.526367	0.23010175	0.0080661979	1913.024
96.527344	0.23497498	0.0082116239	1937.4518
97.52832	0.23684378	0.0082201306	1952.405
98.529297	0.24262145	0.0084050959	1978.5535
99.530273	0.24321277	0.0085157435	2002.0635
100.53125	0.24727304	0.0085678548	2023.119
101.53223	0.24828495	0.0087542674	2037.4746
102.5332	0.25339529	0.0088033294	2063.8772
103.53418	0.25568289	0.0089637004	2080.1689
104.53516	0.26187235	0.009070877	2099.7537
105.53613	0.26117387	0.0091103185	2115.6863
106.53711	0.26630655	0.009204952	2140.2222
107.53809	0.2699241	0.009380931	2153.2026
108.53906	0.2699618	0.0093671586	2164.2944
109.54004	0.27512515	0.00951494	2181.2463
110.54102	0.27825153	0.0095841391	2199.8374
111.54199	0.28158471	0.0097061638	2212.407
112.54297	0.28601438	0.0098026693	2228.9949
113.54395	0.28900144	0.0098200645	2247.0542
114.54492	0.28913769	0.0099732894	2263.3513
115.5459	0.29309183	0.010143522	2285.626
116.54688	0.29454675	0.010268382	2296.4497
117.54785	0.29716077	0.010250536	2302.2534
118.54883	0.30209833	0.010407131	2323.5505
119.5498	0.3059527	0.010477438	2333.4722
120.55078	0.30845153	0.010603652	2346.1345
121.55176	0.31354529	0.010673946	2359.3467
122.55273	0.3137008	0.010752141	2371.3027
123.55371	0.32089749	0.010960716	2388.3667
124.55469	0.32057193	0.011119865	2399.1836
125.55566	0.32307097	0.011177936	2415.189
126.55664	0.32382762	0.011239312	2419.2168
127.55762	0.33065471	0.011375833	2437.8203
128.55859	0.33232984	0.011524676	2448.5835
129.55957	0.33256957	0.011697266	2459.9304
130.56055	0.3408719	0.011808808	2474.2468
131.56152	0.34015787	0.011842796	2473.5093
132.5625	0.34516466	0.011962417	2482.8086
133.56348	0.3449319	0.012045601	2500.7173
134.56445	0.35142469	0.01222547	2507.6055
135.56543	0.35299677	0.012365782	2520.5388
136.56641	0.35495943	0.012461641	2527.7207
137.56738	0.35645407	0.012564285	2529.0549
138.56836	0.36043423	0.012883437	2549.7832
139.56934	0.36771497	0.012936289	2557.5022
140.57031	0.36713451	0.012984324	2566.3923
141.57129	0.37314633	0.013258883	2577.2585
142.57227	0.37461621	0.013289197	2586.6633
143.57324	0.37743941	0.013491874	2588.5867
144.57422	0.3802644	0.01355257	2598.5989
145.5752	0.38282546	0.013777607	2607.9661
146.57617	0.38571152	0.013959844	2614.866
147.57715	0.38827881	0.014163313	2617.5466
148.57813	0.3952958	0.014224974	2628.96
149.5791	0.39665094	0.014461644	2637.9138
150.58008	0.39508605	0.014617847	2648.4851
151.58105	0.40338033	0.014890553	2663.8406
152.58203	0.40414274	0.015102265	2671.1003
153.58301	0.40511885	0.015319747	2671.0103
154.58398	0.41079444	0.015570621	2684.6016
155.58496	0.41246465	0.015794626	2688.1272
156.58594	0.41515896	0.016119136	2698.2031
157.58691	0.42105752	0.016316291	2709.5635
158.58789	0.42472234	0.016716653	2721.1162
159.58887	0.4241927	0.016847281	2719.1094
160.58984	0.43021336	0.017242929	2735.6477
161.59082	0.42915922	0.017513555	2738.7334
162.5918	0.43482336	0.017825175	2740.6819
163.59277	0.43992588	0.018229498	2754.7024
164.59375	0.44175288	0.018618463	2762.3457
165.59473	0.44217497	0.018879756	2765.6018
166.5957	0.44500205	0.019341948	2774.3987
167.59668	0.45102736	0.019644663	2779.241
168.59766	0.45245767	0.020115718	2784.4294
169.59863	0.45630655	0.020515854	2788.7695
170.59961	0.45476678	0.020971324	2796.5215
171.60059	0.46014205	0.021537637	2803.0957
172.60156	0.46300659	0.021962494	2802.3503
173.60254	0.46607438	0.022484357	2818.5918
174.60352	0.4690299	0.023048026	2823.2483
175.60449	0.47402796	0.023720976	2834.9524
176.60547	0.47762826	0.024192486	2832.7778
177.60645	0.47972548	0.024782438	2837.5596
178.60742	0.48283428	0.0255036	2844.7822
179.6084	0.48676488	0.026169151	2851.176
180.60938	0.48673269	0.026782999	2858.3552
181.61035	0.49148244	0.027511397	2860.5127
182.61133	0.49314055	0.028214425	2862.8916
183.6123	0.49625921	0.02884404	2863.4526
184.61328	0.50014699	0.029439252	2872.0081
185.61426	0.50716686	0.030278422	2884.4089
186.61523	0.50756532	0.030894285	2884.167
187.61621	0.50891006	0.031762529	2885.6958
188.61719	0.5145871	0.032599468	2898.7959
189.61816	0.51427341	0.033611428	2891.4983
190.61914	0.51868224	0.034547988	2899.3887
191.62012	0.52401263	0.035513341	2903.9875
192.62109	0.52444434	0.036492612	2913.3408
193.62207	0.52745557	0.037322283	2913.1047
194.62305	0.53253043	0.038217098	2911.9023
195.62402	0.53611064	0.038921807	2913.5398
196.625	0.5335499	0.039758954	2916.8457
197.62598	0.54066575	0.040700078	2929.957
198.62695	0.54419577	0.041794576	2935.1221
199.62793	0.54434448	0.04301466	2932.5918
200.62891	0.54685152	0.04400108	2934.8066
201.62988	0.5536055	0.0452815	2942.8467
202.63086	0.55417776	0.046336453	2940.865
203.63184	0.55786979	0.047425419	2940.9741
204.63281	0.56231982	0.048699014	2948.2485
205.63379	0.56504649	0.049650166	2946.4419
206.63477	0.56695664	0.050543159	2950.8977
207.63574	0.56765038	0.051588781	2958.8652
208.63672	0.57236183	0.052945819	2962.1631
209.6377	0.57645321	0.054178115	2967.1553
210.63867	0.57933623	0.055190127	2966.2061
211.63965	0.58107287	0.05644419	2974.7312
212.64063	0.58813965	0.057601105	2982.0674
213.6416	0.58816302	0.058891382	2977.9897
214.64258	0.59038013	0.060025319	2981.0679
215.64355	0.59134477	0.060998328	2970.6426
216.64453	0.59628379	0.061927579	2977.5264
217.64551	0.5984261	0.063181646	2985.4456
218.64648	0.60274762	0.064344697	2988.9856
219.64746	0.60550708	0.065507203	2989.5435
220.64844	0.60808927	0.066432022	2988.5959
221.64941	0.61187905	0.067566	2991.0913
222.65039	0.61415964	0.069130227	2998.9575
223.65137	0.61828864	0.070390575	2993.8723
224.65234	0.62101078	0.071473368	2997.2898
225.65332	0.62471926	0.072612204	3006.0728
226.6543	0.62498808	0.073748678	3004.5015
227.65527	0.62854534	0.075001366	3009.3669
228.65625	0.63357824	0.076239765	3010.3804
229.65723	0.63361454	0.077576987	3013.2607
230.6582	0.63646203	0.078945287	3016.0593
231.65918	0.6407364	0.080392495	3017.7664
232.66016	0.64320695	0.081615925	3025.3162
233.66113	0.64874798	0.08297199	3022.9832
234.66211	0.65324384	0.084125556	3021.0676
235.66309	0.6537534	0.085560858	3026.1472
236.66406	0.65766209	0.086901158	3030.4995
237.66504	0.66203809	0.088134371	3028.8284
238.66602	0.66302055	0.089368999	3026.5295
239.66699	0.66519582	0.090610348	3033.3242
240.66797	0.66833532	0.091705285	3037.1709
241.66895	0.67115605	0.092821062	3036.8359
242.66992	0.67790055	0.094251588	3047.0864
243.6709	0.67579287	0.095596567	3043.6726
244.67188	0.68124801	0.09708593	3048.7092
245.67285	0.6846422	0.098386332	3045.5176
246.67383	0.68590271	0.099464789	3041.1997
247.6748	0.68744344	0.10067207	3042.2495
248.67578	0.6920014	0.10208211	3052.2129
249.67676	0.69539905	0.10334527	3055.3352
250.67773	0.70051867	0.10466294	3061.8271
251.67871	0.70216101	0.10600056	3062.7859
252.67969	0.70433462	0.10714481	3056.439
253.68066	0.70813614	0.10819902	3064.8098
254.68164	0.70850515	0.10941975	3060.7341
255.68262	0.71561688	0.11072979	3072.6877
256.68359	0.71521342	0.11213262	3065.5518
257.68457	0.72116786	0.11339431	3071.4907
258.68555	0.72335386	0.11480767	3069.1799
259.68652	0.72630101	0.11617509	3077.8291
260.6875	0.73095322	0.11745775	3073.1455
261.68848	0.73093617	0.11848629	3067.8994
262.68945	0.73435658	0.11970273	3073.1204
263.69043	0.7396462	0.12101362	3080.6384
264.69141	0.74007136	0.12228967	3079.4875
265.69238	0.74332255	0.12370654	3079.3875
266.69336	0.74755204	0.12511693	3090.7488
267.69434	0.75165331	0.12636247	3081.2764
268.69531	0.75122303	0.12773663	3090.5879
269.69629	0.75823593	0.12913291	3094.6472
270.69727	0.75875473	0.13053229	3084.8733
271.69824	0.7630465	0.13186204	3089.917
272.69922	0.76432669	0.13318118	3093.99
273.7002	0.76986808	0.13450569	3097.5625
274.70117	0.77036923	0.13565113	3102.3723
275.70215	0.77303648	0.1369344	3095.3062
276.70313	0.77511752	0.13831884	3103.031
277.7041	0.77996379	0.13974637	3103.4944
278.70508	0.78253776	0.14111574	3100.4395
279.70605	0.78528613	0.14226408	3103.5269
280.70703	0.79187393	0.14358728	3107.9988
281.70801	0.79327661	0.14472009	3107.9856
282.70898	0.79412466	0.14598285	3114.3198
283.70996	0.79707241	0.14734824	3115.5427
284.71094	0.80015081	0.14861923	3112.5903
285.71191	0.80454487	0.15006615	3114.8459
286.71289	0.80920959	0.15118495	3118.0986
287.71387	0.80936056	0.15241767	3111.2205
288.71484	0.81486779	0.15343873	3111.8818
289.71582	0.81790709	0.15449516	3117.3447
290.7168	0.81972551	0.15571678	3122.9846
291.71777	0.82107037	0.15710814	3129.9045
292.71875	0.82390136	0.15840736	3126.0315
293.71973	0.82501328	0.1596377	3120.2139
294.7207	0.82989287	0.16085979	3130.1086
295.72168	0.83406544	0.16214141	3129.6863
296.72266	0.83927816	0.16340108	3124.8616
297.72363	0.83691788	0.16472448	3129.4438
298.72461	0.84012276	0.16603151	3129.5767
299.72559	0.84792864	0.16733949	3140.3188
300.72656	0.84806222	0.16856149	3135.0327
301.72754	0.85399681	0.16979544	3136.2134
302.72852	0.85343027	0.17117681	3139.946
303.72949	0.86109704	0.17236961	3144.9456
304.73047	0.85890162	0.17371137	3144.0076
305.73145	0.86531991	0.17509723	3145.7527
306.73242	0.86773741	0.17626195	3145.5696
307.7334	0.87056655	0.17747563	3146.678
308.73438	0.87447381	0.17879543	3147.6868
309.73535	0.87506247	0.18003897	3150.0122
310.73633	0.88103348	0.18124588	3151.0664
311.7373	0.88358432	0.18250743	3156.1489
312.73828	0.88593173	0.18384826	3154.2771
313.73926	0.88898498	0.18509826	3155.5952
314.74023	0.89203501	0.18636966	3159.8596
315.74121	0.89506775	0.18756902	3155.0125
316.74219	0.89825356	0.18876395	3164.5967
317.74316	0.89804006	0.18997426	3158.7588
318.74414	0.90144634	0.19098836	3154.8806
319.74512	0.90783662	0.19244945	3168.1226
320.74609	0.90899563	0.19382596	3165.8545
321.74707	0.91262013	0.19506243	3169.6353
322.74805	0.91578341	0.1963274	3166.5122
323.74902	0.91784871	0.19747968	3163.4734
324.75	0.92119002	0.19855961	3164.3735
325.75098	0.92530376	0.19974209	3171.2717
326.75195	0.92737335	0.20091757	3174.9622
327.75293	0.93173832	0.20211868	3173.5015
328.75391	0.9304108	0.20337988	3167.8811
329.75488	0.93964493	0.20452265	3179.262
330.75586	0.93717128	0.20583279	3175.2878
331.75684	0.94616097	0.20699582	3183.3801
332.75781	0.94577217	0.20825545	3182.8894
333.75879	0.94856006	0.20952091	3185.009
334.75977	0.95213127	0.21103512	3184.844
335.76074	0.95656157	0.212285	3187.3843
336.76172	0.95624155	0.21376763	3189.8831
337.7627	0.96219194	0.21483657	3187.9836
338.76367	0.96486878	0.21610278	3190.8982
339.76465	0.96472657	0.21735132	3189.4861
340.76563	0.97076446	0.21867298	3191.3374
341.7666	0.97406191	0.21983349	3190.0955
342.76758	0.97738111	0.22091959	3191.9392
343.76855	0.97662503	0.22223303	3194.6372
344.76953	0.98087633	0.22361216	3194.8618
345.77051	0.98478335	0.22500224	3200.8752
346.77148	0.98682117	0.2261592	3200.4246
347.77246	0.99000674	0.22738987	3197.7271
348.77344	0.99158174	0.22858453	3201.0024
349.77441	0.99715596	0.22977403	3204.5291
350.77539	1.0000459	0.23109609	3204.866
351.77637	1.0050817	0.23226745	3207.0134
352.77734	1.0056838	0.23356828	3212.0059
353.77832	1.0075181	0.23472109	3208.9905
354.7793	1.0116041	0.23602737	3210.6394
355.78027	1.0151871	0.23742628	3216.4822
356.78125	1.0194894	0.23882769	3212.2961
357.78223	1.0215158	0.24012876	3213.5928
358.7832	1.0235618	0.24119343	3209.9114
359.78418	1.0267103	0.24249241	3215.1597
360.78516	1.026352	0.24370307	3217.9736
361.78613	1.0310428	0.24479045	3216.3943
362.78711	1.0358324	0.2460894	3221.2388
363.78809	1.0398568	0.24727771	3223.887
364.78906	1.0423899	0.24870783	3228.416
365.79004	1.0453783	0.24997579	3224.2166
366.79102	1.0485058	0.25114602	3219.3799
367.79199	1.0513408	0.25216734	3229.6062
368.79297	1.0540437	0.25338167	3229.2786
369.79395	1.0572561	0.25475466	3223.2068
370.79492	1.0610486	0.2557525	3234.509
371.7959	1.0617014	0.25699651	3229.0967
372.79688	1.0638566	0.25820521	3236.6338
373.79785	1.0688907	0.25959295	3229.4199
374.79883	1.0711538	0.26066342	3236.6428
375.7998	1.0747342	0.26183984	3238.6343
376.80078	1.0778333	0.26320058	3239.541
377.80176	1.0815049	0.26440802	3231.6853
378.80273	1.0843065	0.26575911	3246.7893
379.80371	1.0862266	0.26699245	3239.7939
380.80469	1.091584	0.26841903	3245.9338
381.80566	1.0905759	0.26960501	3248.3562
382.80664	1.0956861	0.27094388	3244.1284
383.80762	1.0993339	0.27199438	3239.5593
384.80859	1.1010674	0.27331612	3250.0903
385.80957	1.1038486	0.27466837	3246.5916
386.81055	1.107721	0.27589956	3247.9199
387.81152	1.1105314	0.27697277	3246.9734
388.8125	1.1120517	0.27820095	3249.9568
389.81348	1.1196702	0.27934098	3249.3032
390.81445	1.1180823	0.28060627	3252.5693
391.81543	1.1188102	0.28161296	3247.3071
392.81641	1.1252574	0.28289548	3255.0208
393.81738	1.1269742	0.28413555	3257.0371
394.81836	1.1343185	0.28532287	3262.4324
395.81934	1.133957	0.28646812	3257.6885
396.82031	1.1405735	0.28754655	3259.3477
397.82129	1.1397842	0.28873926	3262.0154
398.82227	1.1398233	0.29001108	3261.9912
399.82324	1.146682	0.29133058	3264.4268
400.82422	1.1471874	0.2927227	3266.2102
401.8252	1.151032	0.29389605	3262.1975
402.82617	1.1547128	0.29503497	3262.6777
403.82715	1.1593999	0.29633176	3267.7173
404.82813	1.1612213	0.2976191	3276.9141
405.8291	1.1650783	0.29887295	3269.0095
406.83008	1.1665996	0.30020514	3269.7666
407.83105	1.1684539	0.30139211	3271.707
408.83203	1.1726781	0.30261388	3277.6094
409.83301	1.1788203	0.30402341	3281.1631
410.83398	1.1790233	0.30542254	3275.0774
411.83496	1.1815207	0.3066372	3277.7473
412.83594	1.1830703	0.30787876	3270.8499
413.83691	1.1884485	0.3090238	3276.916
414.83789	1.1916534	0.31020206	3279.5293
415.83887	1.1922759	0.31127307	3277.4966
416.83984	1.2026736	0.31248617	3286.0327
417.84082	1.1990329	0.31395093	3286.8137
418.8418	1.2042294	0.3151536	3281.304
419.84277	1.2068603	0.31615338	3284.5659
420.84375	1.2089944	0.3173236	3288.8076
421.84473	1.2146314	0.31860715	3287.4221
422.8457	1.2164712	0.31974697	3292.8503
423.84668	1.2211615	0.32090595	3287.3447
424.84766	1.2188665	0.32224202	3288.9141
425.84863	1.2268592	0.32332522	3293.3008
426.84961	1.2275844	0.32442304	3291.1228
427.85059	1.2326396	0.32554665	3292.7322
428.85156	1.2350752	0.32675645	3296.5552
429.85254	1.2332659	0.32801142	3291.1914
430.85352	1.2398826	0.3291752	3302.47
431.85449	1.2424383	0.3303895	3299.9021
432.85547	1.2458876	0.33153626	3300.0142
433.85645	1.2505016	0.33286524	3296.3137
434.85742	1.2522247	0.33414367	3308.7324
435.8584	1.2528026	0.33542347	3302.6531
436.85938	1.2571758	0.33625433	3300.0034
437.86035	1.2592734	0.33750594	3307.9309
438.86133	1.2649431	0.33871391	3311.6584
439.8623	1.2660195	0.33986494	3305.4888
440.86328	1.2702428	0.34096548	3306.916
441.86426	1.2722017	0.34227461	3312.1921
442.86523	1.2756962	0.34356287	3312.8455
443.86621	1.2789024	0.34472612	3315.939
444.86719	1.2792048	0.34610951	3313.552
445.86816	1.2839305	0.34746668	3311.1406
446.86914	1.2896045	0.34842816	3316.6392
447.87012	1.2905858	0.34968048	3315.0015
448.87109	1.2932038	0.35089549	3320.4485
449.87207	1.29583	0.35215294	3318.8809
450.87305	1.3015798	0.35352489	3324.116
451.87402	1.3036052	0.35481587	3319.3604
452.875	1.305154	0.35605592	3320.5408
453.87598	1.3086957	0.35731676	3324.4048
454.87695	1.3133398	0.35858047	3327.533
455.87793	1.3159943	0.3598536	3323.2644
456.87891	1.3182672	0.36102253	3326.1755
457.87988	1.3220196	0.3621603	3330.6411
458.88086	1.3248036	0.36348486	3327.4045
459.88184	1.3258629	0.36465898	3326.6494
460.88281	1.3299069	0.36606804	3328.8032
461.88379	1.333088	0.36719194	3331.1284
462.88477	1.3380251	0.36847588	3332.1543
463.88574	1.3420267	0.36975154	3341.8994
464.88672	1.3390226	0.37125319	3336.0117
465.8877	1.3469042	0.37252876	3333.6697
466.88867	1.3486391	0.37358811	3335.1389
467.88965	1.3543719	0.37463087	3338.7451
468.89063	1.3523631	0.37592825	3334.929
469.8916	1.3548163	0.37723467	3335.6721
470.89258	1.359715	0.3784613	3341.2976
471.89355	1.364738	0.37971386	3343.4282
472.89453	1.3638192	0.38092488	3339.3855
473.89551	1.3696498	0.38195312	3338.5693
474.89648	1.3720248	0.38292861	3340.4426
475.89746	1.377643	0.38404566	3348.7441
476.89844	1.3796471	0.38521343	3350.2444
477.89941	1.3830473	0.38640109	3349.582
478.90039	1.3847446	0.38745135	3347.2219
479.90137	1.3862747	0.38863394	3346.1284
480.90234	1.3921347	0.38975993	3352.9998
481.90332	1.3927892	0.39092475	3356.8218
482.9043	1.4001719	0.39223167	3356.9009
483.90527	1.3996953	0.39369303	3356.4021
484.90625	1.4018745	0.39500463	3354.0662
485.90723	1.4039146	0.3964026	3355.0278
486.9082	1.4057438	0.39762548	3358.6458
487.90918	1.4125674	0.39899975	3361.1497
488.91016	1.4132433	0.40024251	3360.0828
489.91113	1.4182268	0.40140367	3359.176
490.91211	1.4229088	0.40251943	3360.126
491.91309	1.4238595	0.40362313	3355.292
492.91406	1.42585	0.40485483	3359.3259
493.91504	1.4299293	0.40608042	3367.1521
494.91602	1.4304626	0.40732598	3362.6235
495.91699	1.4340217	0.40873748	3365.5251
496.91797	1.4362917	0.40996709	3359.8132
497.91895	1.4421179	0.41113782	3367.3909
498.91992	1.4424039	0.4122318	3363.5042
499.9209	1.4446545	0.41343173	3365.6594
500.92188	1.4488409	0.41459912	3367.6116
501.92285	1.4510732	0.4158183	3366.8687
502.92383	1.4591566	0.41699362	3370.9592
503.9248	1.4612229	0.41833061	3373.4136
504.92578	1.4630911	0.41958791	3372.9104
505.92676	1.4655946	0.4207705	3376.5212
506.92773	1.4660678	0.42195395	3371.0076
507.92871	1.4706933	0.42320213	3375.8071
508.92969	1.4734584	0.4244141	3370.8088
509.93066	1.4739755	0.42557752	3372.0935
510.93164	1.4810033	0.42676294	3376.3271
511.93262	1.4819605	0.42791572	3374.9141
512.93359	1.4856881	0.42913961	3380.5649
513.93457	1.4884419	0.43040869	3382.229
514.93555	1.4915149	0.43183559	3383.6731
515.93652	1.4954292	0.43296751	3379.4768
516.9375	1.4996271	0.43430182	3388.4221
517.93848	1.5012164	0.43536323	3374.9326
518.93945	1.5036991	0.43649486	3384.1711
519.94043	1.5077451	0.43754947	3390.5039
520.94141	1.5109849	0.43890205	3394.8564
521.94238	1.5143932	0.44021249	3386.9333
522.94336	1.5163075	0.44134009	3387.8271
523.94434	1.5208281	0.44258904	3395.3718
524.94531	1.5232595	0.44384748	3391.3936
525.94629	1.5239711	0.44497561	3385.8323
526.94727	1.5274687	0.44605008	3391.0542
527.94824	1.5269715	0.44722411	3389.762
528.94922	1.5345939	0.44851771	3400.238
529.9502	1.5370635	0.45010093	3408.7078
530.95117	1.5422947	0.45151398	3400.5906
531.95215	1.5421542	0.45270833	3397.2805
532.95313	1.5444502	0.45380658	3393.5173
533.9541	1.5497342	0.45489281	3400.2964
534.95508	1.5530955	0.45594934	3393.3899
535.95605	1.5512258	0.45714381	3400.2637
536.95703	1.5586278	0.45842099	3406.6873
537.95801	1.5601213	0.45986548	3398.323
538.95898	1.5631442	0.46106738	3404.0664
539.95996	1.5631958	0.46229038	3401.532
540.96094	1.5667036	0.46347967	3406.1555
541.96191	1.5739781	0.46477005	3412.3713
542.96289	1.575443	0.46580264	3402.1365
543.96387	1.5814302	0.4668918	3409.0603
544.96484	1.581787	0.46800005	3410.4861
545.96582	1.5872923	0.46928442	3414.5786
546.9668	1.589968	0.47075292	3412.6599
547.96777	1.5916001	0.47183824	3411.9539
548.96875	1.5951369	0.47301614	3416.7659
549.96973	1.5987849	0.47425136	3412.772
550.9707	1.6012264	0.47546279	3421.1885
551.97168	1.6033323	0.47664243	3413.0713
552.97266	1.6082436	0.47774112	3419.7031
553.97363	1.6097594	0.47923654	3422.4587
554.97461	1.6135906	0.48062465	3419.6819
555.97559	1.6167885	0.48185003	3415.123
556.97656	1.6183493	0.48306367	3419.3589
557.97754	1.6207319	0.48430967	3426.0747
558.97852	1.625779	0.48565775	3427.4612
559.97949	1.6255442	0.48685902	3416.9082
560.98047	1.6324141	0.48809835	3425.9109
561.98145	1.6323494	0.48913679	3418.4878
562.98242	1.6374339	0.49019858	3424.2776
563.9834	1.6355156	0.49127156	3423.3755
564.98438	1.6426309	0.49269134	3432.9316
565.98535	1.6445239	0.49365053	3425.1829
566.98633	1.6488667	0.49464017	3425.24
567.9873	1.6499624	0.49570575	3425.9316
568.98828	1.6546679	0.49679649	3430.7251
569.98926	1.6565892	0.49796933	3429.9868
570.99023	1.6575376	0.4991309	3430.4065
571.99121	1.6633136	0.50025427	3435.5583
572.99219	1.6656868	0.50125974	3428.4177
573.99316	1.6689003	0.50227511	3436.8452
574.99414	1.6725469	0.50313485	3426.6111
575.99512	1.674203	0.50399899	3426.2563
576.99609	1.6793609	0.50485885	3432.4407
577.99707	1.6804993	0.50582153	3433.9136
578.99805	1.6855549	0.50705135	3441.4746
579.99902	1.6856768	0.50812006	3437.9417
581	1.6900059	0.509422	3443.4866
582.00098	1.6909196	0.51075596	3434.4302
583.00195	1.6971872	0.51194167	3440.5234
584.00293	1.6970874	0.51325709	3437.7627
585.00391	1.7031206	0.51441121	3439.3608
586.00488	1.7079902	0.51551044	3445.0496
587.00586	1.7069396	0.51702434	3442.5713
588.00684	1.7097903	0.51839834	3447.9409
589.00781	1.7121371	0.51986521	3443.7773
590.00879	1.7188128	0.52105016	3440.2839
591.00977	1.7198297	0.52233338	3445.6619
592.01074	1.724394	0.52363306	3443.5852
593.01172	1.7250953	0.52504611	3451.5205
594.0127	1.7279652	0.52632225	3444.0593
595.01367	1.7348959	0.52800006	3460.9768
596.01465	1.7383813	0.52931154	3452.2976
597.01563	1.7373341	0.53061908	3452.9878
598.0166	1.741052	0.53182697	3451.6028
599.01758	1.7431626	0.53317279	3445.4355
600.01855	1.7481456	0.53432196	3451.1167
601.01953	1.7489439	0.53574175	3450.0862
602.02051	1.7559673	0.53703284	3458.2871
603.02148	1.7538126	0.53826189	3452.4688
604.02246	1.7592267	0.53949308	3453.5012
605.02344	1.7630942	0.54090285	3458.626
606.02441	1.7631946	0.54217237	3460.792
607.02539	1.7694336	0.54372716	3465.5972
608.02637	1.7716378	0.54494089	3452.7085
609.02734	1.7728918	0.54591161	3449.7688
610.02832	1.7767664	0.5470587	3459.8083
611.0293	1.7819539	0.5482707	3464.8369
612.03027	1.7831236	0.54977375	3467.0027
613.03125	1.7834765	0.55106759	3457.3633
614.03223	1.7894735	0.55219972	3457.4639
615.0332	1.7940546	0.55341226	3466.7292
616.03418	1.7963328	0.55443287	3465.4656
617.03516	1.7983024	0.55581623	3470.3518
618.03613	1.8000641	0.55725157	3471.6643
619.03711	1.8046521	0.5585888	3466.4661
620.03809	1.810575	0.55959326	3461.3621
621.03906	1.8094435	0.56073302	3464.8992
622.04004	1.8150955	0.56196237	3474.7092
623.04102	1.8159925	0.56321502	3469.9973
624.04199	1.81982	0.56445277	3475.2891
625.04297	1.8239274	0.56588489	3470.2915
626.04395	1.8267572	0.5672617	3478.043
627.04492	1.8240536	0.56863099	3476.7708
628.0459	1.8322666	0.57026505	3477.8821
629.04688	1.8320539	0.5717541	3471.5571
630.04785	1.8392159	0.57305586	3476.1453
631.04883	1.8405033	0.57438534	3477.1111
632.0498	1.8437324	0.57563454	3472.6287
633.05078	1.8466129	0.5769847	3481.573
634.05176	1.8492602	0.57840788	3478.8152
635.05273	1.8513817	0.57980919	3476.9985
636.05371	1.8533149	0.58096582	3474.8342
637.05469	1.8570143	0.58230782	3477.6072
638.05566	1.8620304	0.58360177	3479.3274
639.05664	1.8666129	0.5846017	3480.4075
640.05762	1.8665721	0.58581322	3480.3235
641.05859	1.8689598	0.5871886	3481.0813
642.05957	1.8734207	0.58840144	3481.0063
643.06055	1.8747303	0.58970743	3476.842
644.06152	1.8832319	0.59062868	3480.6479
645.0625	1.8829434	0.59184635	3484.4934
646.06348	1.889055	0.59293139	3488.6458
647.06445	1.887081	0.59398669	3488.3411
648.06543	1.8929913	0.59506369	3488.9705
649.06641	1.8934238	0.59621656	3491.1797
650.06738	1.8959817	0.59743106	3489.0664
651.06836	1.8987988	0.5987711	3495.3821
652.06934	1.9037213	0.60027474	3487.2969
653.07031	1.9047396	0.60159451	3486.9167
654.07129	1.9087006	0.60298049	3498.7778
655.07227	1.9138556	0.60424161	3487.4685
656.07324	1.916978	0.60558856	3497.3862
657.07422	1.9188578	0.60695827	3489.6467
658.0752	1.9212699	0.60819471	3493.9507
659.07617	1.9262987	0.60931557	3493.084
660.07715	1.9283848	0.61048287	3492.6445
661.07813	1.9319214	0.61194134	3504.9441
662.0791	1.9338934	0.61360466	3496.7593
663.08008	1.9359907	0.61518031	3500.8711
664.08105	1.9369543	0.61676902	3502.2593
665.08203	1.9395669	0.61817956	3499.2417
666.08301	1.9451909	0.61936647	3498.1777
667.08398	1.9473983	0.62067163	3494.9141
668.08496	1.9506701	0.62187141	3495.3215
669.08594	1.9552755	0.62328774	3506.4016
670.08691	1.9591998	0.62483239	3504.5659
671.08789	1.9607148	0.62608266	3507.4858
672.08887	1.9617189	0.6272639	3497.7163
673.08984	1.965394	0.6285283	3503.9983
674.09082	1.9704387	0.62973851	3504.7222
675.0918	1.9736559	0.63098013	3504.5562
676.09277	1.9747113	0.63249499	3506.5649
677.09375	1.9776193	0.63382071	3501.0457
678.09473	1.9811858	0.63510782	3504.5366
679.0957	1.986699	0.63664919	3509.6233
680.09668	1.9905937	0.63811964	3510.6614
681.09766	1.992738	0.63964957	3509.0032
682.09863	1.993657	0.64110529	3507.2671
683.09961	1.9964225	0.64248437	3508.4421
684.10059	2.0010726	0.64397132	3517.3086
685.10156	2.0011151	0.64520872	3509.3188
686.10254	2.0047789	0.64650959	3502.7727
687.10352	2.0094631	0.64764988	3510.4219
688.10449	2.0117366	0.6489318	3517.739
689.10547	2.0136919	0.65042114	3510.2256
690.10645	2.01771	0.65186661	3511.9128
691.10742	2.020896	0.6533823	3517.1648
692.1084	2.0244987	0.6548211	3513.958
693.10938	2.0291646	0.6563164	3514.7971
694.11035	2.0303395	0.65761721	3516.6533
695.11133	2.033325	0.65887505	3521.2061
696.1123	2.033524	0.66047263	3514.2539
697.11328	2.0388808	0.6617949	3511.3408
698.11426	2.04022	0.66326541	3518.1931
699.11523	2.0468912	0.66500038	3525.0554
700.11621	2.0480535	0.66668659	3521.6079
701.11719	2.0513473	0.66824132	3518.8306
702.11816	2.054461	0.66978973	3525.9053
703.11914	2.0589657	0.67125803	3520.7546
704.12012	2.0600898	0.67267549	3520.4736
705.12109	2.0639338	0.67415559	3525.6301
706.12207	2.0642047	0.67558342	3521.5398
707.12305	2.0685081	0.67690408	3522.7554
708.12402	2.071636	0.67848122	3526.0259
709.125	2.0719278	0.68020093	3518.7979
710.12598	2.0758905	0.68148798	3521.3896
711.12695	2.0809803	0.68292272	3520.1775
712.12793	2.082902	0.68418944	3517.7664
713.12891	2.0871944	0.68533754	3526.8528
714.12988	2.0872581	0.68653107	3519.2231
715.13086	2.0945735	0.68754554	3529.5051
716.13184	2.0957394	0.68891609	3523.6787
717.13281	2.0980802	0.69043177	3530.656
718.13379	2.100678	0.69191134	3529.6021
719.13477	2.1052434	0.69341278	3531.5947
720.13574	2.1051512	0.69481939	3528.0613
721.13672	2.1090596	0.69626582	3526.0249
722.1377	2.1124816	0.69782287	3538.0627
723.13867	2.116055	0.69927955	3523.825
724.13965	2.1178479	0.70064378	3531.842
725.14063	2.1226902	0.70235413	3532.5488
726.1416	2.1274433	0.7037639	3533.0132
727.14258	2.1304305	0.70526046	3533.3137
728.14355	2.1333799	0.70679843	3538.072
729.14453	2.1366866	0.70801353	3527.3857
730.14551	2.13534	0.70930326	3535.376
731.14648	2.1391838	0.71083146	3533.8247
732.14746	2.1438174	0.71201915	3538.04
733.14844	2.1450472	0.71345347	3537.6636
734.14941	2.1501045	0.71508205	3539.634
735.15039	2.1497524	0.71640664	3531.7891
736.15137	2.1563096	0.71778733	3531.3079
737.15234	2.1618915	0.71879655	3540.2375
738.15332	2.1623695	0.72021443	3545.0444
739.1543	2.1632993	0.72182488	3537.8425
740.15527	2.1672838	0.72310954	3531.2214
741.15625	2.1698692	0.72417945	3534.9033
742.15723	2.1738384	0.72564721	3538.8828
743.1582	2.1773803	0.72709119	3542.575
744.15918	2.1822827	0.72860211	3544.468
745.16016	2.1819744	0.73020697	3536.9695
746.16113	2.187032	0.73159397	3546.8357
747.16211	2.1889145	0.73301029	3547.3223
748.16309	2.1937399	0.73457336	3545.3594
749.16406	2.1959083	0.73601007	3540.8074
750.16504	2.1972349	0.73740911	3540.1926
751.16602	2.2022526	0.73887783	3542.0056
752.16699	2.2029865	0.74015164	3542.7488
753.16797	2.2088189	0.74180585	3543.9478
754.16895	2.2091942	0.74320239	3540.4956
755.16992	2.2131231	0.74444211	3540.1094
756.1709	2.2171283	0.74575621	3550.116
757.17188	2.218328	0.74736392	3549.7634
758.17285	2.2251022	0.74890411	3548.3125
759.17383	2.2225993	0.75032485	3550.6179
760.1748	2.229059	0.75178802	3552.2734
761.17578	2.2271385	0.75335485	3548.6057
762.17676	2.2342632	0.75488639	3550.1355
763.17773	2.2363985	0.75660604	3547.8855
764.17871	2.2389944	0.75790483	3542.4792
765.17969	2.2439418	0.75928628	3546.7163
766.18066	2.246433	0.76070499	3550.2107
767.18164	2.2519579	0.76219958	3555.9221
768.18262	2.2553585	0.76375431	3559.2512
769.18359	2.2547379	0.76543015	3552.9834
770.18457	2.259532	0.76701576	3555.0339
771.18555	2.2601268	0.76857179	3553.1953
772.18652	2.2636516	0.77013731	3552.5791
773.1875	2.2677977	0.77166301	3556.5049
774.18848	2.2678423	0.77312803	3552.9609
775.18945	2.2742929	0.77456445	3554.3953
776.19043	2.2744963	0.77604371	3550.8042
777.19141	2.2792723	0.77790803	3560.6084
778.19238	2.2817905	0.77998561	3562.1216
779.19336	2.2866964	0.78176838	3560.1204
780.19434	2.2858968	0.78329039	3554.4497
781.19531	2.2904019	0.7847681	3556.2876
782.19629	2.2940314	0.78600448	3551.2908
783.19727	2.3000612	0.78740746	3558.551
784.19824	2.299397	0.78929424	3554.5259
785.19922	2.3055856	0.79076564	3561.1509
786.2002	2.3076909	0.79225326	3556.1746
787.20117	2.3058336	0.79354775	3552.7524
788.20215	2.3126459	0.79493684	3555.2798
789.20313	2.3169115	0.79636383	3563.0222
790.2041	2.3188596	0.7980026	3560.2688
791.20508	2.3221991	0.79985011	3569.6685
792.20605	2.324646	0.80173439	3562.8884
793.20703	2.3283045	0.80317038	3556.3506
794.20801	2.328182	0.80452561	3554.9104
795.20898	2.3316743	0.8060928	3556.9502
796.20996	2.3346214	0.8076452	3564.7883
797.21094	2.3425329	0.80930609	3567.5291
798.21191	2.3401294	0.81081635	3555.6599
799.21289	2.3461468	0.81205344	3560.2888
800.21387	2.3462391	0.81358987	3559.9998
801.21484	2.352984	0.8151474	3559.634
802.21582	2.3544118	0.81671721	3561.8618
803.2168	2.3577659	0.81832063	3567.0225
804.21777	2.3578544	0.81983435	3559.7834
805.21875	2.3624403	0.82161689	3568.0413
806.21973	2.364193	0.82331842	3560.1511
807.2207	2.3687332	0.8245638	3562.5605
808.22168	2.3731239	0.82611442	3568.7878
809.22266	2.3748212	0.82781088	3566.4248
810.22363	2.3786061	0.8295607	3571.8198
811.22461	2.3806775	0.83137149	3567.1746
812.22559	2.3825336	0.83299637	3565.0618
813.22656	2.3878639	0.83484983	3569.8953
814.22754	2.3913016	0.83658165	3565.929
815.22852	2.3945472	0.83824867	3575.3401
816.22949	2.3978548	0.83997142	3560.0339
817.23047	2.3993161	0.84133601	3557.2368
818.23145	2.4018655	0.84279805	3568.5701
819.23242	2.4051087	0.84405553	3566.6726
820.2334	2.4065197	0.84565061	3568.8411
821.23438	2.411994	0.84728616	3566.5916
822.23535	2.4138355	0.84887075	3570.8921
823.23633	2.4170177	0.85022175	3568.9519
824.2373	2.4210649	0.8517043	3569.697
825.23828	2.4233797	0.85327333	3576.064
826.23926	2.4277723	0.85499233	3576.6599
827.24023	2.4298587	0.85647601	3570.0149
828.24121	2.4311476	0.85817975	3575.5164
829.24219	2.4363539	0.86000293	3571.1511
830.24316	2.4377935	0.86137003	3570.2891
831.24414	2.443783	0.86295259	3580.9856
832.24512	2.4452021	0.86481506	3576.2292
833.24609	2.4498041	0.86651921	3577.4641
834.24707	2.4505537	0.86844677	3569.083
835.24805	2.4528809	0.87009972	3573.4033
836.24902	2.4581161	0.87163395	3572.0981
837.25	2.4596515	0.87342721	3570.6807
838.25098	2.4634304	0.87485629	3572.0786
839.25195	2.4634655	0.87637925	3575.4907
840.25293	2.4693842	0.87771237	3579.4548
841.25391	2.4681945	0.87930971	3570.365
842.25488	2.4723682	0.88091063	3574.1626
843.25586	2.4763751	0.8828181	3576.3682
844.25684	2.4837511	0.88468373	3573.7905
845.25781	2.4817688	0.88599831	3570.9377
846.25879	2.4825647	0.88756132	3570.0994
847.25977	2.4882815	0.88933653	3576.804
848.26074	2.4899104	0.89112854	3575.4155
849.26172	2.494509	0.89259726	3582.7527
850.2627	2.5007484	0.89463532	3585.0544
851.26367	2.4987624	0.89686811	3573.6035
852.26465	2.5026834	0.89879513	3576.9375
853.26563	2.506752	0.90058708	3580.1873
854.2666	2.5099859	0.90224546	3572.1465
855.26758	2.5154467	0.90408123	3583.6106
856.26855	2.5171411	0.90581131	3577.0022
857.26953	2.5225031	0.90730679	3579.5618
858.27051	2.5243406	0.90880966	3583.1797
859.27148	2.5253637	0.91041744	3580.2341
860.27246	2.524611	0.91243851	3577.8799
861.27344	2.5308993	0.91398931	3573.6377
862.27441	2.5333014	0.91539401	3575.9844
863.27539	2.538604	0.91686404	3575.3074
864.27637	2.5394707	0.91834223	3581.2014
865.27734	2.542583	0.92018729	3587.0598
866.27832	2.5448072	0.92185777	3581.3362
867.2793	2.5482237	0.92341006	3574.0828
868.28027	2.5520272	0.92469519	3578.4202
869.28125	2.5562704	0.92621386	3580.8481
870.28223	2.5594006	0.92775935	3578.2314
871.2832	2.5610998	0.92921501	3576.0261
872.28418	2.563112	0.93054873	3577.1091
873.28516	2.5675058	0.93190521	3583.1501
874.28613	2.5704679	0.93344146	3574.5146
875.28711	2.5756657	0.93490142	3585.9971
876.28809	2.5743768	0.9365716	3579.5596
877.28906	2.5784955	0.93831867	3582.2336
878.29004	2.5803792	0.94014412	3581.5344
879.29102	2.5877044	0.94228733	3585.9214
880.29199	2.5899577	0.9443928	3586.6438
881.29297	2.5914044	0.94623262	3581.9307
882.29395	2.5940874	0.94787073	3583.3728
883.29492	2.5990872	0.94980246	3584.8853
884.2959	2.5995023	0.95145422	3579.6743
885.29688	2.6050344	0.95308799	3587.833
886.29785	2.604743	0.95518416	3583.8704
887.29883	2.6096134	0.95701957	3579.7607
888.2998	2.613764	0.95873213	3584.5044
889.30078	2.6140096	0.9604153	3585.1511
890.30176	2.6190033	0.96228868	3584.5542
891.30273	2.620044	0.96370769	3577.0422
892.30371	2.6241858	0.96572387	3580.2615
893.30469	2.627295	0.96742165	3585.4231
894.30566	2.632364	0.96976417	3586.9001
895.30664	2.6325505	0.97202986	3587.3186
896.30762	2.6352086	0.97404104	3581.4153
897.30859	2.642935	0.97577047	3585.9502
898.30957	2.6419823	0.97759771	3581.4744
899.31055	2.6439161	0.97929353	3577.9817
900.31152	2.6497819	0.9808836	3586.281
901.3125	2.6501157	0.98251772	3577.1453
902.31348	2.657485	0.98407954	3585.6772
903.31445	2.6602802	0.98589319	3591.0842
904.31543	2.6615083	0.98769379	3584.9402
905.31641	2.6628513	0.98965991	3582.8154
906.31738	2.6656299	0.99157268	3578.8557
907.31836	2.6681337	0.99396509	3584.3945
908.31934	2.6702192	0.99595481	3588.3755
909.32031	2.6770568	0.99815267	3584.1333
910.32129	2.6771686	1.0001732	3582.584
911.32227	2.6828313	1.0018556	3584.2913
912.32324	2.685096	1.0036101	3585.9817
913.32422	2.6857986	1.005716	3587.821
914.3252	2.6898975	1.0075595	3581.4426
915.32617	2.6956303	1.009325	3589.7217
916.32715	2.6978292	1.0112857	3579.926
917.32813	2.6975956	1.0129217	3583.7207
918.3291	2.7037838	1.0148321	3592.0845
919.33008	2.7069576	1.0168782	3583.1858
920.33105	2.7083278	1.0184937	3582.4216
921.33203	2.7111111	1.0202755	3584.6794
922.33301	2.7152483	1.022415	3585.5801
923.33398	2.7186122	1.0240686	3583.5457
924.33496	2.7184246	1.0260583	3581.9651
925.33594	2.7229726	1.0281523	3586.3901
926.33691	2.7249451	1.0300379	3588.9651
927.33789	2.7296994	1.031925	3584.115
928.33887	2.7324524	1.0338699	3587.3499
929.33984	2.7369349	1.035864	3588.3359
930.34082	2.7380214	1.0377518	3584.3857
931.3418	2.7419791	1.0395321	3580.6057
932.34277	2.7435799	1.0415342	3583.9111
933.34375	2.746222	1.0436412	3585.8569
934.34473	2.7503977	1.0457631	3584.0532
935.3457	2.7528336	1.0479323	3586.0403
936.34668	2.7549803	1.0501814	3581.1353
937.34766	2.7609735	1.0521456	3585.2017
938.34863	2.7642746	1.0541058	3574.4524
939.34961	2.7657173	1.0559459	3587.4773
940.35059	2.7701185	1.057953	3581.6218
941.35156	2.7705944	1.0598575	3579.7017
942.35254	2.7733779	1.0620046	3586.9058
943.35352	2.778043	1.0640876	3582.6958
944.35449	2.7785542	1.0661603	3582.5298
945.35547	2.7868671	1.0680081	3586.8457
946.35645	2.7844779	1.0701189	3580.7192
947.35742	2.789664	1.0721364	3579.5737
948.3584	2.7922406	1.0740565	3583.3723
949.35938	2.7955117	1.0764517	3589.874
950.36035	2.7983341	1.079116	3582.1648
951.36133	2.8032436	1.0812278	3584.5627
952.3623	2.8053563	1.083515	3582.6965
953.36328	2.8078675	1.0858798	3577.5049
954.36426	2.8099303	1.0882162	3583.8679
955.36523	2.8115227	1.0900187	3580.4854
956.36621	2.8142676	1.0921413	3578.1133
957.36719	2.8209634	1.0939362	3580.8462
958.36816	2.8242877	1.0961074	3582.739
959.36914	2.8258584	1.0979835	3578.4431
960.37012	2.8272202	1.1001084	3582.3291
961.37109	2.832181	1.1022688	3589.1296
962.37207	2.8368587	1.1047668	3581.2791
963.37305	2.8395855	1.1066561	3575.6951
964.37402	2.8411229	1.1085924	3578.6875
965.375	2.8438499	1.1105344	3580.1897
966.37598	2.8469172	1.1126492	3576.5908
967.37695	2.8479655	1.1146489	3578.1755
968.37793	2.8541188	1.1166438	3574.4233
969.37891	2.8546576	1.1183847	3575.7244
970.37988	2.8589363	1.1204571	3577.0212
971.38086	2.8594248	1.122494	3582.1321
972.38184	2.8651011	1.1250902	3582.9829
973.38281	2.8679261	1.1271596	3572.9624
974.38379	2.8704939	1.1293546	3580.9146
975.38477	2.8736115	1.131665	3581.0669
976.38574	2.8777721	1.13411	3577.3643
977.38672	2.8791556	1.1359366	3572.3887
978.3877	2.882498	1.1378998	3577.354
979.38867	2.8858335	1.1401757	3579.6106
980.38965	2.8907797	1.1425613	3571.8496
981.39063	2.8894198	1.1448665	3576.4817
982.3916	2.8961649	1.1471629	3579.6563
983.39258	2.8976195	1.1491355	3566.2893
984.39355	2.9008498	1.1507803	3569.2661
985.39453	2.9023712	1.1531254	3584.7153
986.39551	2.9060402	1.1562688	3577.2437
987.39648	2.9090784	1.1584642	3569.9463
988.39746	2.9135678	1.160714	3572.7168
989.39844	2.9184999	1.1629082	3572.9475
990.39941	2.9156437	1.1648848	3566.7324
991.40039	2.9233644	1.1667705	3570.3711
992.40137	2.9242196	1.1684891	3568.123
993.40234	2.9272764	1.1704538	3572.0945
994.40332	2.9333384	1.1722591	3571.9954
995.4043	2.9328623	1.1745241	3574.1147
996.40527	2.9371574	1.1764894	3565.3745
997.40625	2.9415865	1.1785014	3573.4624
998.40723	2.9423687	1.1809767	3575.7297
999.4082	2.9431334	1.1834091	3567.6138
1000.4092	2.9480267	1.1856327	3565.5793
1001.4102	2.9492249	1.1879332	3565.9336
1002.4111	2.9559655	1.1902348	3566.1057
1003.4121	2.9574323	1.1924533	3561.2131
1004.4131	2.9616647	1.1944699	3566.4153
1005.4141	2.9650495	1.1962653	3562.0715
1006.415	2.9678903	1.1983776	3565.7925
1007.416	2.967695	1.2012511	3572.4656
1008.417	2.9714022	1.2036721	3564.1169
1009.418	2.9758036	1.2058035	3561.0928
1010.4189	2.9796352	1.2078366	3559.9512
1011.4199	2.9820912	1.209844	3560.0078
1012.4209	2.9838088	1.2119781	3553.1702
1013.4219	2.9883256	1.2140582	3561.6926
1014.4229	2.986239	1.2161214	3555.6882
1015.4238	2.9927366	1.2179745	3551.2507
1016.4248	3.0002196	1.2197596	3555.0579
1017.4258	3.0000181	1.2214627	3557.467
1018.4268	3.0049515	1.22323	3555.4641
1019.4277	3.0034153	1.2253757	3560.2893
1020.4287	3.0083489	1.2275046	3551.4834
1021.4297	3.0125432	1.2297642	3560.5042
1022.4307	3.0126696	1.2323809	3555.8672
1023.4316	3.0150576	1.2349757	3552.4028
1024.4326	3.0212681	1.2376808	3551.6448
1025.4336	3.0223198	1.239792	3551.2546
1026.4346	3.0268042	1.2420812	3552.5044
1027.4355	3.0306048	1.2444092	3552.9624
1028.4365	3.0352516	1.2464741	3556.9456
1029.4375	3.0361624	1.2487364	3543.6963
1030.4385	3.0391409	1.2509344	3545.8662
1031.4395	3.040683	1.2531224	3549.1704
1032.4404	3.0472834	1.2553651	3544.989
1033.4414	3.0492134	1.2578369	3545.2629
1034.4424	3.0496402	1.2601415	3542.2632
1035.4434	3.0537796	1.26248	3545.2505
1036.4443	3.0572085	1.2650152	3542.2119
1037.4453	3.0621796	1.2677146	3541.2004
1038.4463	3.0614071	1.2699133	3530.2627
1039.4473	3.0659866	1.2718898	3542.2915
1040.4482	3.0718403	1.2739735	3541.6785
1041.4492	3.0757115	1.2761211	3537.521
1042.4502	3.0766921	1.2782826	3537.9497
1043.4512	3.0801659	1.2808102	3541.2913
1044.4521	3.082128	1.2835119	3535.6548
1045.4531	3.08372	1.2857544	3528.9651
1046.4541	3.0841343	1.2878686	3526.7292
1047.4551	3.0904176	1.2901235	3533.6455
1048.4561	3.090204	1.2924837	3529.2971
1049.457	3.0955751	1.2949512	3525.9429
1050.458	3.0969656	1.297297	3521.9143
1051.459	3.1041412	1.2996686	3528.0618
1052.46	3.1060312	1.3020277	3521.7461
1053.4609	3.1085038	1.304266	3519.9998
1054.4619	3.1146357	1.3065567	3522.4431
1055.4629	3.1151829	1.3090423	3526.7241
1056.4639	3.1173894	1.3115438	3522.6677
1057.4648	3.1212983	1.3139629	3519.2507
1058.4658	3.1249206	1.3165379	3516.9014
1059.4668	3.1255174	1.3189014	3508.9663
1060.4678	3.1270192	1.3211049	3506.9758
1061.4688	3.130682	1.3232828	3511.3208
1062.4697	3.1381698	1.3259362	3511.3665
1063.4707	3.1366432	1.32841	3499.8054
1064.4717	3.139246	1.3305708	3501.6887
1065.4727	3.144711	1.3330933	3502.9309
1066.4736	3.1481602	1.3353659	3500.2356
1067.4746	3.1499588	1.3377143	3496.6177
1068.4756	3.1550934	1.3394212	3498.2227
1069.4766	3.1566339	1.3417391	3496.4722
1070.4775	3.1578255	1.344088	3501.1689
1071.4785	3.1632802	1.3464577	3495.1365
1072.4795	3.1677475	1.3487828	3500.3811
1073.4805	3.167752	1.35121	3490.6152
1074.4814	3.1723325	1.3537155	3490.4868
1075.4824	3.1732309	1.3560935	3486.7122
1076.4834	3.1742976	1.3583068	3478.9351
1077.4844	3.1780128	1.3603066	3479.8064
1078.4854	3.1821628	1.3626601	3481.0229
1079.4863	3.1850801	1.365154	3478.8767
1080.4873	3.1897919	1.3678138	3484.1426
1081.4883	3.1932602	1.3707994	3475.6108
1082.4893	3.1948459	1.3733661	3474.8579
1083.4902	3.1994383	1.3757045	3472.9463
1084.4912	3.1998198	1.3780428	3467.7664
1085.4922	3.2022653	1.3803368	3466.2319
1086.4932	3.2103095	1.3826314	3465.9312
1087.4941	3.2109373	1.3850164	3462.8206
1088.4951	3.2149937	1.3876009	3462.9749
1089.4961	3.2154651	1.3899122	3455.3574
1090.4971	3.2199759	1.3924661	3462.2627
1091.498	3.2220688	1.3950498	3456.2947
1092.499	3.2258544	1.3970397	3447.0977
1093.5	3.229815	1.39928	3453.5674
1094.501	3.232599	1.4020658	3452.5344
1095.502	3.2331886	1.4046369	3447.4744
1096.5029	3.2365012	1.4072033	3442.2466
1097.5039	3.2395122	1.4096698	3439.3455
1098.5049	3.2446263	1.4120321	3436.7698
1099.5059	3.2474544	1.4144132	3434.8413
1100.5068	3.2498741	1.4163291	3427.3069
1101.5078	3.2518582	1.4184315	3430.5635
1102.5088	3.2554407	1.420862	3433.5098
1103.5098	3.2582726	1.423335	3433.0676
1104.5107	3.2621052	1.4261783	3428.5002
1105.5117	3.2634022	1.4291242	3420.7683
1106.5127	3.2680225	1.4318781	3415.23
1107.5137	3.2716913	1.4343486	3416.5984
1108.5146	3.2741807	1.4368471	3410.5364
1109.5156	3.2765718	1.4386554	3403.3064
1110.5166	3.2787068	1.4407921	3407.553
1111.5176	3.2834666	1.4433901	3409.2571
1112.5186	3.2859433	1.445822	3406.5847
1113.5195	3.287564	1.4483775	3401.6619
1114.5205	3.2923603	1.4504714	3391.8352
1115.5215	3.2937295	1.4531035	3389.6907
1116.5225	3.2968531	1.4556466	3393.6394
1117.5234	3.3015175	1.458267	3388.7603
1118.5244	3.3057959	1.4607188	3387.9551
1119.5254	3.3046315	1.4632579	3385.9893
1120.5264	3.305398	1.4659491	3374.9832
1121.5273	3.3119338	1.4682753	3367.0681
1122.5283	3.313261	1.4708302	3373.5647
1123.5293	3.3170223	1.4734052	3367.6504
1124.5303	3.3199201	1.4762373	3364.95
1125.5313	3.3239634	1.4786543	3355.3987
1126.5322	3.3276863	1.481203	3359.7969
1127.5332	3.3314362	1.4837042	3353.2195
1128.5342	3.3344479	1.4865935	3356.2686
1129.5352	3.3388958	1.4895141	3352.5088
1130.5361	3.3415453	1.4924164	3345.6907
1131.5371	3.3437853	1.4948545	3335.7468
1132.5381	3.346297	1.4972607	3341.1384
1133.5391	3.3476605	1.4998132	3328.6228
1134.54	3.3500016	1.5023534	3330.6853
1135.541	3.3548772	1.5048249	3324.0684
1136.542	3.3590429	1.5076411	3326.2617
1137.543	3.3609037	1.5102464	3314.9082
1138.5439	3.362417	1.5130177	3314.7637
1139.5449	3.3679671	1.515862	3313.6396
1140.5459	3.3720269	1.5190389	3308.0435
1141.5469	3.3725271	1.5217253	3301.5952
1142.5479	3.3748965	1.5243732	3293.9822
1143.5488	3.3788946	1.5266523	3290.4287
1144.5498	3.3846188	1.5288497	3291.2698
1145.5508	3.3867171	1.5313512	3287.4023
1146.5518	3.3895669	1.5344232	3281.7568
1147.5527	3.3904519	1.5366966	3274.1816
1148.5537	3.3934059	1.5389638	3271.3335
1149.5547	3.3949268	1.5413288	3269.3767
1150.5557	3.4013987	1.5437105	3262.7207
1151.5566	3.4043608	1.5461267	3264.7542
1152.5576	3.4076219	1.5494511	3259.6599
1153.5586	3.4081447	1.5522921	3246.8716
1154.5596	3.4118049	1.5547142	3242.988
1155.5605	3.4135594	1.5568565	3246.9675
1156.5615	3.417846	1.5592685	3234.6897
1157.5625	3.4197855	1.5620822	3234.6152
1158.5635	3.4231997	1.5652134	3232.4104
1159.5645	3.4277079	1.5682139	3222.104
1160.5654	3.4289062	1.5712152	3220.1082
1161.5664	3.4338405	1.5743332	3212.4429
1162.5674	3.4365168	1.5773089	3204.8918
1163.5684	3.4372418	1.5801927	3204.5137
1164.5693	3.4418998	1.5830716	3196.9463
1165.5703	3.4457681	1.586344	3192.3706
1166.5713	3.4498656	1.589307	3181.7417
1167.5723	3.4498909	1.5923471	3172.6538
1168.5732	3.4518549	1.5946213	3172.6865
1169.5742	3.45627	1.5971309	3166.5203
1170.5752	3.459043	1.5998718	3160.5886
1171.5762	3.4627717	1.6031332	3160.313
1172.5771	3.462929	1.6061119	3147.6912
1173.5781	3.4707019	1.609257	3141.1951
1174.5791	3.472461	1.6123599	3136.8835
1175.5801	3.476388	1.6151096	3128.4839
1176.5811	3.4763246	1.6180863	3117.647
1177.582	3.4808316	1.62137	3114.4915
1178.583	3.4849536	1.6249002	3106.8665
1179.584	3.4851186	1.6280752	3100.4961
1180.585	3.4892724	1.6315782	3087.8245
1181.5859	3.4942832	1.6355001	3082.947
1182.5869	3.4974093	1.6396205	3059.6628
1183.5879	3.4994307	1.642679	3049.6379
1184.5889	3.5011933	1.6462419	3029.5864
1185.3896	3.5071514	1.6527793	2983.8489