File: datasets/am_bench_2022/raw_data/60-X.12-1/specimen.dat
MTS793|MPT|ENU|1|2|.|/|:|1|0|0|A

Operator Information						Time:	21.935303	Sec	11/1/2021 9:14:52 AM
Operator	Nick Derimow
Project	AM Bench 2022 mini-tensile challenge
Specimen ID	60-X.12-1
Material	PBF-L Inconel 625
Specimen Width	2.54	mm
Specimen Thickness	1.52	mm
Notes
Operator Information End

Data Acquisition						Time:	1022.9285	Sec	11/1/2021 9:31:33 AM
Time	Axial Displacement	Axial Extensometer	Axial Force
Sec	mm	mm	N
22.04834	-0.0016525277	8.4442137e-05	52.910648
22.949219	-0.00091307622	0.00012487429	66.881386
23.850098	0.0039149234	0.00011260952	77.517677
24.750977	0.0076588448	0.00026028571	95.609413
25.651855	0.0077793207	0.0002434027	106.00297
26.552734	0.010035119	0.00037680924	116.66681
27.453613	0.009158032	0.00035292408	127.94654
28.354492	0.014738186	0.00069249398	141.88287
29.255371	0.015583566	0.00048143067	149.09471
30.15625	0.021864805	0.00082834385	168.23058
31.057129	0.023977591	0.00064489373	183.73978
31.958008	0.024837108	0.00092781638	194.90363
32.858887	0.029665312	0.00074931432	213.61217
33.759766	0.028875304	0.0011728792	229.25507
34.660645	0.034044601	0.00092188682	243.61835
35.561523	0.035186253	0.0012329615	254.6368
36.462402	0.03818683	0.0011080611	275.98657
37.363281	0.041557696	0.0014674151	295.55804
38.26416	0.043733176	0.0014078708	319.95688
39.165039	0.047112599	0.0016536713	329.84531
40.065918	0.050155383	0.001667231	348.52911
40.966797	0.052141391	0.0018781847	368.91751
41.867676	0.055201437	0.0018769512	388.16666
42.768555	0.055921424	0.0020092637	405.92688
43.669434	0.058158372	0.0021750398	424.46777
44.570313	0.0628829	0.0022092639	445.02399
45.471191	0.064829722	0.0023932212	471.74002
46.37207	0.070462123	0.0025405767	494.18015
47.272949	0.071270831	0.0026362527	510.06735
48.173828	0.072595246	0.0026967148	526.52863
49.074707	0.075025611	0.0028254867	549.44836
49.975586	0.078553371	0.0030025269	576.94855
50.876465	0.0826305	0.0030590636	599.2312
51.777344	0.083388336	0.0031348772	623.41492
52.678223	0.089375816	0.0033034391	651.14349
53.579102	0.091329604	0.0033680687	662.14935
54.47998	0.093528084	0.0035357249	687.51978
55.380859	0.096688531	0.0035860902	716.22516
56.281738	0.098939002	0.0036908714	738.97235
57.182617	0.1025397	0.0037235997	762.67456
58.083496	0.10433081	0.0040146811	792.23438
58.984375	0.10587507	0.0039736833	822.37372
59.885254	0.10959036	0.0042248233	852.22595
60.786133	0.11016503	0.0043737856	870.82306
61.687012	0.11308268	0.0044629653	886.70917
62.587891	0.11737053	0.0044778651	913.02057
63.48877	0.11861237	0.0046249991	945.07489
64.389648	0.12459616	0.0047900011	969.83301
65.290527	0.12444802	0.0048923213	989.1283
66.191406	0.12739266	0.0050983783	1020.8066
67.092285	0.12793481	0.0051000747	1044.6361
67.993164	0.13478221	0.0052453894	1071.8798
68.894043	0.13251776	0.0053116758	1088.8746
69.794922	0.13991898	0.0055308733	1119.9066
70.695801	0.13638979	0.0056247409	1141.2206
71.59668	0.1430552	0.0057221288	1165.9889
72.497559	0.14829873	0.005877262	1194.1091
73.398438	0.14813173	0.0059025949	1215.4741
74.299316	0.15348835	0.0060198884	1246.8326
75.200195	0.1548623	0.0061836159	1278.0726
76.101074	0.15831916	0.0063128304	1297.1067
77.001953	0.16246451	0.0064253267	1323.4036
77.902832	0.16034123	0.0065611308	1343.4617
78.803711	0.16684628	0.006669776	1372.2091
79.70459	0.168144	0.0067529883	1391.6759
80.605469	0.16877034	0.0067610857	1413.567
81.506348	0.17456338	0.0070529664	1446.9165
82.407227	0.17572081	0.0071653603	1471.3884
83.308105	0.17866319	0.0071520917	1496.1748
84.208984	0.17946903	0.0074402634	1523.4834
85.109863	0.1857052	0.0074525857	1549.7888
86.010742	0.18490694	0.0075905244	1570.4329
86.911621	0.18938914	0.0076040924	1591.7339
87.8125	0.19158265	0.0077129784	1619.0948
88.713379	0.19395775	0.0078484258	1638.6573
89.614258	0.20060615	0.008076787	1666.6871
90.515137	0.20237231	0.008082184	1689.9005
91.416016	0.20490983	0.0082065137	1712.6335
92.316895	0.2060224	0.0081682485	1730.6296
93.217773	0.20788562	0.0084129758	1762.4946
94.118652	0.20904039	0.0085855089	1772.2799
95.019531	0.21476744	0.0085770879	1804.1152
95.92041	0.21805036	0.0087504601	1829.4496
96.821289	0.21917276	0.0088252686	1840.7899
97.722168	0.22327361	0.0089189028	1864.9182
98.623047	0.2255673	0.0089913392	1883.606
99.523926	0.22777377	0.0091465879	1910.1147
100.4248	0.22726892	0.0092073129	1927.2952
101.32568	0.23109582	0.0093417037	1946.6344
102.22656	0.23522413	0.0093977079	1958.6279
103.12744	0.23664053	0.0094594816	1978.302
104.02832	0.23992755	0.0095561929	1999.0649
104.9292	0.24281938	0.0096925264	2010.9165
105.83008	0.24675733	0.0096588666	2022.5856
106.73096	0.25034636	0.0098419804	2048.0164
107.63184	0.25426731	0.0098709883	2065.2539
108.53271	0.25549132	0.0099645285	2077.6079
109.43359	0.25934795	0.0099329464	2085.8132
110.33447	0.25867507	0.010098848	2095.8403
111.23535	0.26302323	0.010061616	2113.2917
112.13623	0.26254296	0.01008976	2123.9207
113.03711	0.26560539	0.010267562	2138.2869
113.93799	0.26793584	0.010316874	2146.198
114.83887	0.27520341	0.01034424	2166.7124
115.73975	0.27878097	0.010475541	2174.5928
116.64063	0.27800116	0.010533401	2184.3362
117.5415	0.28033137	0.010479623	2189.8669
118.44238	0.28471005	0.010520071	2205.6233
119.34326	0.287305	0.010777505	2217.1531
120.24414	0.28862792	0.01073291	2219.6028
121.14502	0.29291829	0.010851314	2235.8857
122.0459	0.29296663	0.010831387	2239.8899
122.94678	0.30080819	0.010964918	2252.377
123.84766	0.30094609	0.011075569	2262.7942
124.74854	0.30421773	0.011119074	2275.874
125.64941	0.30685544	0.011237473	2285.375
126.55029	0.31147203	0.011243348	2297.0166
127.45117	0.31276035	0.011311088	2303.2043
128.35205	0.31353524	0.011391236	2312.4602
129.25293	0.31789875	0.011526254	2323.0313
130.15381	0.32255813	0.011603538	2336.0784
131.05469	0.32507351	0.011661169	2333.998
131.95557	0.32650447	0.011708581	2353.603
132.85645	0.3296454	0.011867443	2363.718
133.75732	0.33144864	0.01192802	2367.0354
134.6582	0.33553597	0.011937539	2369.2561
135.55908	0.33646351	0.012132413	2385.5842
136.45996	0.33982286	0.012176162	2391.9514
137.36084	0.33972225	0.012278668	2397.7473
138.26172	0.34586826	0.012307307	2407.8271
139.1626	0.34552938	0.012499577	2415.2192
140.06348	0.35177198	0.012512822	2418.5417
140.96436	0.35256714	0.012603112	2431.7183
141.86523	0.3584874	0.012787684	2444.7371
142.76611	0.3584995	0.01283898	2442.3071
143.66699	0.35994965	0.01294433	2449.8674
144.56787	0.36467198	0.013158197	2462.4968
145.46875	0.36628935	0.013200817	2473.3867
146.36963	0.36906064	0.013258882	2476.3774
147.27051	0.37114131	0.013532028	2484.2847
148.17139	0.37244377	0.013498111	2494.2593
149.07227	0.37673867	0.013697078	2493.2302
149.97314	0.37927744	0.013757237	2498.1982
150.87402	0.38109994	0.013794469	2505.5852
151.7749	0.38670912	0.014158106	2526.3894
152.67578	0.3877266	0.014191254	2527.488
153.57666	0.39036602	0.014423224	2528.5842
154.47754	0.39287466	0.014524685	2540.0264
155.37842	0.39728877	0.014642668	2551.7378
156.2793	0.40042275	0.014828641	2556.0928
157.18018	0.4003793	0.01501302	2557.3979
158.08105	0.40565601	0.015165834	2566.9668
158.98193	0.40910837	0.015335028	2578.6196
159.88281	0.4086636	0.015546964	2583.0601
160.78369	0.4134174	0.015691876	2586.9392
161.68457	0.41483769	0.015983135	2592.8599
162.58545	0.41641882	0.016201939	2599.26
163.48633	0.42153472	0.016369514	2601.4487
164.38721	0.42567345	0.016639706	2619.459
165.28809	0.42191559	0.016854424	2614.5618
166.18896	0.42718282	0.017020047	2625.6904
167.08984	0.43260112	0.01724676	2636.0918
167.99072	0.43540588	0.017661087	2641.2961
168.8916	0.43460351	0.017844686	2642.6533
169.79248	0.44093311	0.018302687	2654.4084
170.69336	0.44093966	0.018525073	2650.2795
171.59424	0.44677553	0.018846687	2668.9878
172.49512	0.44849253	0.019160064	2667.7976
173.396	0.44976401	0.01936744	2669.4814
174.29688	0.4544068	0.019673508	2678.4333
175.19775	0.45438385	0.020086624	2680.5527
176.09863	0.4595907	0.020568293	2682.5791
176.99951	0.46419924	0.020852929	2690.2998
177.90039	0.46299919	0.021340063	2697.0681
178.80127	0.46600372	0.021714088	2701.6191
179.70215	0.46963415	0.022178095	2710.6863
180.60303	0.47437036	0.022607615	2708.1128
181.50391	0.47615531	0.023041165	2717.7319
182.40479	0.47662431	0.023433385	2716.4243
183.30566	0.48378026	0.023865508	2728.4041
184.20654	0.4810296	0.024343492	2725.9119
185.10742	0.48524854	0.024794506	2735.885
186.0083	0.48736152	0.025430456	2738.167
186.90918	0.49236614	0.025894765	2746.9041
187.81006	0.49197766	0.02639791	2752.1851
188.71094	0.49609715	0.027043158	2745.688
189.61182	0.49997118	0.027511735	2758.3433
190.5127	0.50323665	0.028208442	2762.9333
191.41357	0.50466865	0.028839355	2765.2847
192.31445	0.50768769	0.029480632	2775.5117
193.21533	0.50920999	0.030134931	2769.5076
194.11621	0.51164758	0.030900547	2776.2017
195.01709	0.51507968	0.031560477	2777.929
195.91797	0.51746905	0.032222383	2785.3511
196.81885	0.51932371	0.032641351	2785.9155
197.71973	0.52368522	0.033485815	2794.5833
198.62061	0.52549809	0.034190781	2798.3694
199.52148	0.52932066	0.034769651	2798.8135
200.42236	0.53092551	0.035570238	2807.0413
201.32324	0.53477907	0.036251374	2805.5867
202.22412	0.53692901	0.036793582	2807.8696
203.125	0.54016173	0.037438374	2812.0166
204.02588	0.54342437	0.038261063	2819.9827
204.92676	0.54335386	0.039162111	2821.9114
205.82764	0.54906678	0.039944217	2825.9663
206.72852	0.55022997	0.040763672	2831.4204
207.62939	0.55339283	0.041556269	2837.7085
208.53027	0.5546965	0.042338535	2832.7424
209.43115	0.56073248	0.043161292	2841.9084
210.33203	0.56455988	0.04395726	2842.812
211.23291	0.56212699	0.044840779	2845.1294
212.13379	0.56867462	0.045594808	2850.6555
213.03467	0.56931084	0.046254113	2848.521
213.93555	0.57314306	0.046881508	2844.8567
214.83643	0.5732525	0.047648545	2848.2417
215.7373	0.57671857	0.048566055	2858.9404
216.63818	0.58023053	0.049414381	2864.4258
217.53906	0.58355463	0.050398294	2864.6724
218.43994	0.58525747	0.051313151	2872.4326
219.34082	0.58755118	0.05239588	2867.4026
220.2417	0.58916593	0.05314073	2873.7305
221.14258	0.59534788	0.053972494	2878.04
222.04346	0.59758604	0.054862402	2872.741
222.94434	0.59812754	0.055540524	2873.8403
223.84521	0.60273552	0.056338925	2882.7095
224.74609	0.60172498	0.057263456	2878.3577
225.64697	0.60769057	0.058012195	2882.9006
226.54785	0.60913789	0.059065301	2886.5264
227.44873	0.61435717	0.059890505	2886.9343
228.34961	0.61403161	0.060609631	2891.7056
229.25049	0.61946857	0.061552383	2894.585
230.15137	0.61991441	0.062737681	2896.4067
231.05225	0.62531281	0.063717291	2899.0671
231.95313	0.62894118	0.064565144	2903.5652
232.854	0.62948084	0.065557465	2905.0024
233.75488	0.63299614	0.066615328	2908.2595
234.65576	0.63790935	0.067472816	2914.5791
235.55664	0.63582957	0.068314977	2913.3899
236.45752	0.64097303	0.069201216	2911.4531
237.3584	0.64460659	0.070224904	2917.6699
238.25928	0.64221388	0.071103431	2919.877
239.16016	0.64712179	0.072179228	2922.8167
240.06104	0.6533764	0.073431641	2931.2178
240.96191	0.65130824	0.07455425	2923.7756
241.86279	0.65609729	0.075271152	2926.1563
242.76367	0.65969008	0.076241843	2931.5735
243.66455	0.66241264	0.077110581	2933.54
244.56543	0.66812444	0.078068234	2938.0486
245.46631	0.66469175	0.079128578	2938.104
246.36719	0.67180389	0.080185547	2940.3877
247.26807	0.67000145	0.081018202	2937.7158
248.16895	0.67354423	0.08194977	2943.8501
249.06982	0.67963737	0.082915418	2942.9321
249.9707	0.68404311	0.08402656	2953.1731
250.87158	0.68615985	0.085062109	2955.6941
251.77246	0.68424392	0.086003318	2948.0027
252.67334	0.69080079	0.086728424	2954.2942
253.57422	0.69279844	0.087887816	2955.7563
254.4751	0.69062132	0.088857718	2948.7864
255.37598	0.69958085	0.089891672	2961.3169
256.27686	0.70289147	0.090977937	2962.8518
257.17773	0.70091861	0.091923818	2964.5906
258.07861	0.70630097	0.09278442	2963.3828
258.97949	0.70769137	0.093911737	2966.5449
259.88037	0.7101084	0.094849952	2974.2898
260.78125	0.71062207	0.095896818	2963.2483
261.68213	0.71584243	0.096992418	2974.46
262.58301	0.71861905	0.09808436	2974.4358
263.48389	0.71981233	0.099282786	2974.5835
264.38477	0.72401464	0.10042265	2973.4001
265.28564	0.72606516	0.10135221	2973.6873
266.18652	0.73063093	0.10224002	2987.0632
267.0874	0.73265785	0.1032346	2978.1416
267.98828	0.73641449	0.10417295	2984.8809
268.88916	0.73737723	0.10513112	2981.9277
269.79004	0.73863262	0.10614868	2986.9968
270.69092	0.74158424	0.10724667	2990.408
271.5918	0.74610287	0.10856544	2995.4375
272.49268	0.747684	0.10963421	2986.3066
273.39355	0.7519924	0.11048754	2994.6748
274.29443	0.75383371	0.11152617	2995.2861
275.19531	0.75757354	0.11247541	3000.6138
276.09619	0.75877559	0.11368532	3010.5195
276.99707	0.76314342	0.11502504	3004.113
277.89795	0.76475942	0.11614402	2999.7959
278.79883	0.76680297	0.11715095	3003.2136
279.69971	0.77231097	0.11812549	3012.3784
280.60059	0.77367288	0.11923563	3002.6318
281.50146	0.77669227	0.12012741	3004.6846
282.40234	0.78022605	0.12105753	3005.6558
283.30322	0.78127164	0.12219737	3014.6091
284.2041	0.78275597	0.12316512	3013.2432
285.10498	0.78232104	0.12452218	3023.936
286.00586	0.78900403	0.12563638	3021.5474
286.90674	0.78981334	0.12676996	3013.1067
287.80762	0.79582685	0.12781987	3022.9841
288.7085	0.79764938	0.12890765	3022.7837
289.60938	0.80015695	0.12972817	3023.5588
290.51025	0.80463439	0.13071845	3026.6973
291.41113	0.80305284	0.13165341	3021.7278
292.31201	0.80610222	0.13282576	3026.6736
293.21289	0.8123132	0.1336333	3024.6541
294.11377	0.81268406	0.13464317	3034.167
295.01465	0.81392938	0.13567092	3034.907
295.91553	0.81742376	0.13688533	3035.6355
296.81641	0.82283038	0.13789113	3038.9443
297.71729	0.82420868	0.13855751	3034.2192
298.61816	0.82820129	0.13961536	3036.0601
299.51904	0.829346	0.14067392	3046.7332
300.41992	0.83076507	0.14202248	3046.2979
301.3208	0.83619052	0.1430375	3036.8521
302.22168	0.83765733	0.14396991	3041.8223
303.12256	0.84345156	0.14510283	3050.2065
304.02344	0.84299976	0.14607882	3044.4795
304.92432	0.84634912	0.14716099	3045.6626
305.8252	0.84961772	0.14824459	3052.0505
306.72607	0.85146785	0.14919806	3052.3889
307.62695	0.85114229	0.15033527	3050.3135
308.52783	0.85351014	0.15162052	3056.2749
309.42871	0.85971195	0.15268961	3055.8611
310.32959	0.86453545	0.15368843	3058.2937
311.23047	0.86130929	0.15491754	3058.2285
312.13135	0.87053865	0.15601927	3066.9453
313.03223	0.86994141	0.15705176	3062.6892
313.93311	0.87321538	0.15820944	3062.3401
314.83398	0.87259614	0.15932554	3067.1233
315.73486	0.88031614	0.16033232	3067.9265
316.63574	0.88322061	0.16148943	3067.7383
317.53662	0.88527858	0.16246888	3073.2444
318.4375	0.88997418	0.16337699	3078.3853
319.33838	0.89018649	0.1644814	3072.7683
320.23926	0.89141399	0.16558389	3074.7156
321.14014	0.8945787	0.16659865	3077.2473
322.04102	0.89686662	0.16783972	3081.7
322.94189	0.90032399	0.16893029	3082.5569
323.84277	0.90452522	0.17002003	3082.332
324.74365	0.90829003	0.17102273	3086.1201
325.64453	0.90764606	0.17224358	3086.2925
326.54541	0.91145349	0.17339136	3088.9319
327.44629	0.91462785	0.17425871	3085.6362
328.34717	0.91356164	0.17516485	3079.126
329.24805	0.91992623	0.17597339	3083.6582
330.14893	0.92112792	0.17704576	3093.3931
331.0498	0.92262155	0.17818205	3096.4744
331.95068	0.92657757	0.17927925	3091.9775
332.85156	0.93086791	0.18036352	3094.2776
333.75244	0.93302006	0.18154323	3097.8811
334.65332	0.93263185	0.18261799	3093.8252
335.5542	0.93745136	0.18349944	3098.3745
336.45508	0.93896079	0.18472198	3101.6604
337.35596	0.94104826	0.18587649	3096.7439
338.25684	0.94612515	0.18681979	3100.1355
339.15771	0.95040303	0.18798962	3106.2031
340.05859	0.95445287	0.18917036	3114.8945
340.95947	0.95113897	0.19023389	3101.707
341.86035	0.95447278	0.19118489	3099.9709
342.76123	0.96110803	0.19228919	3111.7302
343.66211	0.96281868	0.193334	3111.9053
344.56299	0.96779627	0.19430248	3114.4512
345.46387	0.96903747	0.1951718	3108.5095
346.36475	0.96920097	0.19624287	3116.1057
347.26563	0.97317618	0.19751483	3116.0178
348.1665	0.97478414	0.19855167	3114.0964
349.06738	0.97952998	0.19979197	3125.0081
349.96826	0.9810636	0.200826	3117.021
350.86914	0.98343617	0.20189182	3121.1792
351.77002	0.9878993	0.20294975	3118.3176
352.6709	0.98794436	0.20417979	3133.4319
353.57178	0.98976475	0.20516612	3124.5195
354.47266	0.99312663	0.20620821	3127.4878
355.37354	0.99724078	0.20725358	3133.1025
356.27441	0.99989998	0.20850697	3126.9409
357.17529	1.0006298	0.2094986	3128.9749
358.07617	1.0035284	0.21073094	3127.3433
358.97705	1.0113951	0.21177755	3130.8896
359.87793	1.0085409	0.21273164	3128.9541
360.77881	1.0131805	0.21389183	3138.1724
361.67969	1.0152284	0.21473804	3128.0405
362.58057	1.0206701	0.21580262	3132.8691
363.48145	1.0199678	0.21679068	3136.1941
364.38232	1.0223557	0.2177901	3130.7031
365.2832	1.0266846	0.21884789	3138.9509
366.18408	1.0326035	0.21988387	3143.5605
367.08496	1.0285734	0.22096844	3139.7959
367.98584	1.0363179	0.22196136	3142.9465
368.88672	1.0383462	0.22314836	3150.0266
369.7876	1.0382619	0.22405985	3143.8794
370.68848	1.0412195	0.22502008	3141.9834
371.58936	1.0480366	0.22610271	3156.0339
372.49023	1.0494626	0.22720212	3154.5586
373.39111	1.0541953	0.22825463	3158.5134
374.29199	1.0532223	0.22926271	3156.1292
375.19287	1.0549464	0.23040721	3157.4592
376.09375	1.0581168	0.23148116	3154.1326
376.99463	1.0622821	0.23260672	3158.2104
377.89551	1.0612458	0.2337244	3149.5408
378.79639	1.0641015	0.23457541	3155.7261
379.69727	1.0689875	0.23567337	3155.741
380.59814	1.0738238	0.23662828	3157.4268
381.49902	1.0772424	0.23776239	3170.3726
382.3999	1.0783758	0.23892155	3159.8093
383.30078	1.0813172	0.24002482	3171.1179
384.20166	1.0842657	0.24109498	3168.0955
385.10254	1.0862819	0.24207984	3171.6216
386.00342	1.0911646	0.24306606	3172.8921
386.9043	1.0906096	0.24426202	3172.0957
387.80518	1.0936462	0.2450942	3165.1904
388.70605	1.0957613	0.24623448	3173.5686
389.60693	1.1006716	0.24712165	3177.7344
390.50781	1.1006497	0.24827923	3173.6096
391.40869	1.1060398	0.24935782	3171.7646
392.30957	1.1050359	0.25022861	3176.9158
393.21045	1.1123832	0.25123093	3179.8745
394.11133	1.1139127	0.25227907	3184.4238
395.01221	1.1140978	0.25332555	3183.0281
395.91309	1.1170923	0.25423113	3179.0623
396.81396	1.1216469	0.25528786	3188.7266
397.71484	1.1238005	0.25640985	3190.3433
398.61572	1.1282798	0.25746596	3186.7346
399.5166	1.1298962	0.25861681	3189.2898
400.41748	1.1322161	0.2596266	3190.4888
401.31836	1.1337937	0.26077563	3185.3132
402.21924	1.1371797	0.26189345	3185.6038
403.12012	1.1390766	0.26272234	3182.8611
404.021	1.1443624	0.26376683	3192.6309
404.92188	1.145012	0.26478648	3199.2332
405.82275	1.1479902	0.26580989	3195.9941
406.72363	1.1537898	0.26695928	3203.3347
407.62451	1.1550394	0.26796746	3200.5515
408.52539	1.1569517	0.26885098	3195.6406
409.42627	1.1601117	0.26984698	3202.6953
410.32715	1.160661	0.27096486	3200.6252
411.22803	1.1664662	0.27225846	3201.3823
412.12891	1.1659334	0.27322295	3197.7405
413.02979	1.1716801	0.2740294	3203.1365
413.93066	1.1731317	0.27496362	3197.2231
414.83154	1.1743525	0.27594218	3203.613
415.73242	1.1796484	0.27686849	3204.0098
416.6333	1.1820737	0.27791837	3207.6711
417.53418	1.1856984	0.2791999	3220.2412
418.43506	1.1854208	0.2803947	3212.7732
419.33594	1.1867908	0.28160018	3209.7676
420.23682	1.1923594	0.28249833	3214.1995
421.1377	1.195888	0.2834686	3218.9998
422.03857	1.1961291	0.28450492	3218.1045
422.93945	1.2018603	0.28554139	3218.1116
423.84033	1.2033477	0.28649387	3221.3123
424.74121	1.2050035	0.28753892	3217.4998
425.64209	1.2094345	0.28860137	3219.8911
426.54297	1.2103573	0.28959966	3217.7996
427.44385	1.2122662	0.29080912	3223.9629
428.34473	1.2172292	0.29196224	3227.2295
429.24561	1.2204502	0.29328209	3229.4255
430.14648	1.2190386	0.29427382	3227.4827
431.04736	1.2226968	0.29551625	3225.6545
431.94824	1.2284621	0.29660997	3233.1069
432.84912	1.2291851	0.29753426	3222.8982
433.75	1.2310798	0.29826289	3222.3135
434.65088	1.2341238	0.29899055	3220.0642
435.55176	1.2402008	0.29992783	3236.844
436.45264	1.2409958	0.30087665	3227.4761
437.35352	1.2417789	0.30177006	3230.9827
438.25439	1.24358	0.30262342	3231.3828
439.15527	1.2462839	0.30347231	3224.0347
440.05615	1.2498132	0.3044692	3240.8796
440.95703	1.254382	0.30558726	3244.7551
441.85791	1.2541802	0.30682665	3237.928
442.75879	1.2575239	0.30791092	3235.9968
443.65967	1.2601132	0.30882698	3246.0078
444.56055	1.2636708	0.31004867	3243.9351
445.46143	1.2653594	0.31121287	3242.0808
446.3623	1.272577	0.31230453	3249.6575
447.26318	1.2733977	0.31345707	3251.0618
448.16406	1.2750175	0.31442684	3238.947
449.06494	1.2772267	0.31537044	3246.7495
449.96582	1.2809236	0.31637418	3247.3774
450.8667	1.2842627	0.31755945	3251.8638
451.76758	1.2887977	0.31856269	3250.0986
452.66846	1.2891986	0.3197076	3254.0027
453.56934	1.2918642	0.3207736	3256.1167
454.47021	1.2942227	0.32189921	3249.2554
455.37109	1.2979187	0.32287672	3254.842
456.27197	1.2997879	0.32400882	3252.6404
457.17285	1.301496	0.32496494	3257.5313
458.07373	1.3052423	0.32614362	3254.4714
458.97461	1.3098508	0.32700849	3259.8958
459.87549	1.3075409	0.32790911	3252.4463
460.77637	1.3136625	0.32913867	3269.7493
461.67725	1.3182474	0.33037245	3267.532
462.57813	1.3170584	0.33131576	3260.291
463.479	1.3208396	0.33230734	3267.4883
464.37988	1.3261343	0.33359581	3274.3118
465.28076	1.3250242	0.33475465	3265.9749
466.18164	1.3291383	0.33566135	3263.074
467.08252	1.3311788	0.33679566	3267.1145
467.9834	1.3378783	0.33781672	3267.5103
468.88428	1.3388718	0.33887771	3272.594
469.78516	1.3426319	0.33984143	3271.8108
470.68604	1.3436307	0.34073675	3273.1882
471.58691	1.3500844	0.34192476	3274.2732
472.48779	1.3477759	0.34287933	3276.0542
473.38867	1.3530768	0.34390137	3279.4312
474.28955	1.3559555	0.34479529	3271.8721
475.19043	1.3543192	0.34581867	3278.6621
476.09131	1.3577805	0.34688488	3278.6826
476.99219	1.3631405	0.34786507	3278.9136
477.89307	1.3625458	0.34881839	3278.1016
478.79395	1.366711	0.34977552	3283.7544
479.69482	1.371484	0.35099572	3290.8186
480.5957	1.3707329	0.35206687	3283.4768
481.49658	1.3760376	0.35331258	3289.2676
482.39746	1.3784469	0.35432148	3284.8855
483.29834	1.3807943	0.35536715	3282.3938
484.19922	1.3841316	0.35645604	3291.2278
485.1001	1.3840625	0.35757396	3287.5913
486.00098	1.3896979	0.35868922	3292.9426
486.90186	1.3921235	0.35967749	3292.0486
487.80273	1.3938676	0.36063147	3290.0747
488.70361	1.397324	0.36163306	3292.8828
489.60449	1.4012762	0.36276856	3292.3779
490.50537	1.4013475	0.36363369	3291.2449
491.40625	1.4024738	0.36478883	3294.8672
492.30713	1.411635	0.36590591	3299.5972
493.20801	1.413215	0.36688587	3299.9773
494.10889	1.4123888	0.36803335	3298.8284
495.00977	1.4154357	0.36912155	3297.9072
495.91064	1.4181629	0.37011543	3301.1499
496.81152	1.4191898	0.37133452	3308.4058
497.7124	1.4251329	0.37252837	3309.3015
498.61328	1.4273188	0.37343228	3302.323
499.51416	1.4278353	0.37445307	3302.012
500.41504	1.4309185	0.37546173	3304.4521
501.31592	1.4330211	0.37650478	3305.4048
502.2168	1.4359773	0.37748632	3303.8752
503.11768	1.4383399	0.37840581	3308.551
504.01855	1.4413342	0.37942424	3305.0923
504.91943	1.444151	0.38054445	3314.0842
505.82031	1.4498502	0.38156271	3313.8003
506.72119	1.4511564	0.38240391	3311.0425
507.62207	1.4536872	0.38337007	3305.1895
508.52295	1.4548608	0.3845425	3312.498
509.42383	1.4613854	0.38553545	3314.7969
510.32471	1.4615724	0.38648841	3315.2673
511.22559	1.4641525	0.38759264	3314.9441
512.12646	1.4679681	0.38855845	3316.5427
513.02734	1.4680392	0.38963023	3313.8806
513.92822	1.4769418	0.39060661	3323.7764
514.8291	1.4751738	0.3917335	3324.8357
515.72998	1.4787551	0.39293346	3322.8657
516.63086	1.4824725	0.39423868	3326.9299
517.53174	1.4838519	0.39530262	3327.5942
518.43262	1.4869928	0.39646786	3319.9133
519.3335	1.488065	0.39740029	3319.5994
520.23438	1.4919274	0.39826274	3320.228
521.13525	1.495712	0.39926621	3327.2349
522.03613	1.4983498	0.40031719	3334.7349
522.93701	1.5006204	0.40153745	3332.3486
523.83789	1.503544	0.40270123	3330.9397
524.73877	1.5050808	0.40371409	3334.3606
525.63965	1.5076063	0.40486881	3333.4121
526.54053	1.5103722	0.40601039	3332.2546
527.44141	1.5153189	0.40708014	3334.9761
528.34229	1.5168953	0.40803725	3333.5469
529.24316	1.5190119	0.40897545	3333.7036
530.14404	1.5231118	0.4101066	3342.3149
531.04492	1.5228362	0.41112342	3337.9617
531.9458	1.5269897	0.41238388	3338.5903
532.84668	1.5291693	0.4134827	3345.3591
533.74756	1.5315119	0.4146587	3335.2949
534.64844	1.5352937	0.41582912	3339.9988
535.54932	1.5375915	0.41681916	3345.0876
536.4502	1.5451286	0.41772905	3342.6428
537.35107	1.5411118	0.41868615	3337.6624
538.25195	1.5431126	0.41989872	3340.6116
539.15283	1.5503583	0.42097342	3347.9446
540.05371	1.5506194	0.42212385	3344.1196
540.95459	1.5530964	0.42322013	3345.4792
541.85547	1.5555651	0.42409465	3344.8394
542.75635	1.5594879	0.42510226	3349.8157
543.65723	1.5633446	0.42628357	3352.8887
544.55811	1.5645865	0.4271903	3345.4302
545.45898	1.5673816	0.4284032	3361.9746
546.35986	1.5710951	0.4295795	3360.105
547.26074	1.5738993	0.43062103	3351.1484
548.16162	1.5774497	0.43155017	3351.3621
549.0625	1.5804056	0.43256772	3355.6858
549.96338	1.583311	0.4338392	3363.8491
550.86426	1.5820773	0.43513182	3356.9844
551.76514	1.5845213	0.43616787	3352.98
552.66602	1.5859752	0.43716717	3353.4099
553.56689	1.5943524	0.43807369	3357.1997
554.46777	1.5923326	0.43922123	3359.0625
555.36865	1.599571	0.44026062	3358.0757
556.26953	1.6034746	0.44129947	3364.8994
557.17041	1.605065	0.44235018	3362.1187
558.07129	1.6045564	0.44335541	3359.731
558.97217	1.6069971	0.44426697	3358.6292
559.87305	1.613204	0.44534394	3365.687
560.77393	1.6132644	0.44650084	3364.8523
561.6748	1.6161634	0.44768748	3363.2683
562.57568	1.6177064	0.44889671	3366.126
563.47656	1.6191586	0.44990221	3365.3826
564.37744	1.6242126	0.45129439	3376.2102
565.27832	1.624512	0.45255473	3362.6213
566.1792	1.6263412	0.45363972	3369.1528
567.08008	1.635661	0.45476922	3376.1333
567.98096	1.6382449	0.45567051	3368.7485
568.88184	1.6376691	0.45655605	3369.2815
569.78271	1.6389898	0.45744869	3371.5613
570.68359	1.6438193	0.45859703	3373.9341
571.58447	1.6440176	0.45997259	3377.7952
572.48535	1.6488341	0.46114078	3374.4402
573.38623	1.6507962	0.46213043	3373.5959
574.28711	1.6546079	0.4631111	3373.2239
575.18799	1.6567308	0.46418214	3374.4539
576.08887	1.6574786	0.46524665	3381.489
576.98975	1.6582545	0.46618614	3370.9524
577.89063	1.6657171	0.46727481	3383.8201
578.7915	1.667836	0.46819937	3378.1038
579.69238	1.6732501	0.46928006	3379.3088
580.59326	1.6759514	0.47028309	3389.6145
581.49414	1.6726385	0.47129205	3377.845
582.39502	1.678928	0.47237968	3386.1157
583.2959	1.6828356	0.47332647	3377.7529
584.19678	1.6831706	0.47441122	3384.8904
585.09766	1.6855491	0.47550744	3386.6792
585.99854	1.6870649	0.47668815	3389.0557
586.89941	1.6908506	0.47799373	3391.5911
587.80029	1.6950551	0.47891492	3385.5818
588.70117	1.6981252	0.47995511	3388.1116
589.60205	1.6999811	0.48112601	3393.4128
590.50293	1.7008697	0.48229462	3387.0313
591.40381	1.7057694	0.48344782	3392.4221
592.30469	1.7089107	0.4844358	3390.2974
593.20557	1.7099842	0.4856039	3393.4395
594.10645	1.7116342	0.48666289	3385.5076
595.00732	1.7167387	0.48787314	3392.4199
595.9082	1.716718	0.48890105	3396.3899
596.80908	1.7194375	0.49015969	3395.5378
597.70996	1.7233323	0.49144262	3395.2634
598.61084	1.7293586	0.49271423	3400.3967
599.51172	1.7302849	0.49393052	3397.9973
600.4126	1.7329874	0.49494708	3401.7546
601.31348	1.7350373	0.49616465	3402.7507
602.21436	1.7377052	0.49733901	3400.1184
603.11523	1.7388829	0.4982546	3395.8503
604.01611	1.7457123	0.49937218	3404.7507
604.91699	1.7472483	0.50060868	3412.2939
605.81787	1.7493501	0.50171423	3403.2542
606.71875	1.7496272	0.50308204	3407.5798
607.61963	1.7531837	0.50411159	3400.9668
608.52051	1.757282	0.50503153	3409.969
609.42139	1.7569467	0.50623053	3401.6572
610.32227	1.7610887	0.50729442	3405.0698
611.22314	1.76369	0.50855458	3410.4595
612.12402	1.7702193	0.50967896	3414.3481
613.0249	1.7726728	0.51074636	3411.7415
613.92578	1.7704268	0.51197475	3409.6641
614.82666	1.7768799	0.51307553	3406.5613
615.72754	1.7781687	0.51419622	3408.7896
616.62842	1.7793093	0.51504856	3404.8591
617.5293	1.7817296	0.51611567	3408.5664
618.43018	1.7883363	0.51727015	3413.926
619.33105	1.7868955	0.51820862	3409.9885
620.23193	1.7930232	0.51919633	3410.5029
621.13281	1.79505	0.52032369	3424.1414
622.03369	1.7991619	0.52131724	3419.479
622.93457	1.8013566	0.52262205	3427.1296
623.83545	1.8034154	0.52413368	3426.6726
624.73633	1.8052597	0.52544355	3421.8025
625.63721	1.8067846	0.52660859	3414.6313
626.53809	1.8112997	0.52769047	3426.1724
627.43896	1.8141965	0.52901363	3418.1382
628.33984	1.8170836	0.53014082	3417.9751
629.24072	1.8191129	0.53123981	3426.0918
630.1416	1.8184745	0.53227812	3413.7625
631.04248	1.8230357	0.53336632	3418.8235
631.94336	1.8281662	0.53458935	3426.3145
632.84424	1.8277519	0.53574377	3422.5762
633.74512	1.8314018	0.53720111	3428.5837
634.646	1.8361976	0.53848523	3429.6687
635.54688	1.8398868	0.53960729	3426.1919
636.44775	1.8379006	0.54083711	3428.697
637.34863	1.842041	0.54192793	3421.6919
638.24951	1.845317	0.54301977	3422.4297
639.15039	1.8491515	0.54410118	3431.7336
640.05127	1.8503273	0.54518104	3426.1414
640.95215	1.8553343	0.5461942	3429.3875
641.85303	1.8542422	0.54740268	3430.9253
642.75391	1.8564465	0.54880458	3430.3186
643.65479	1.8639692	0.55004758	3431.0591
644.55566	1.8633029	0.55119437	3433.2083
645.45654	1.8678111	0.55236483	3432.6309
646.35742	1.8673923	0.55357069	3427.9182
647.2583	1.8715048	0.5546875	3437.625
648.15918	1.8739797	0.55570209	3428.7854
649.06006	1.8780309	0.55681187	3432.0208
649.96094	1.8810782	0.55811155	3438.3867
650.86182	1.8819888	0.55907887	3425.5752
651.7627	1.886488	0.55998707	3434.0867
652.66357	1.8887346	0.5610972	3433.8938
653.56445	1.8953129	0.56229609	3445.8562
654.46533	1.8916053	0.56354159	3441.156
655.36621	1.8987603	0.56477225	3443.9631
656.26709	1.8967198	0.5660708	3441.0552
657.16797	1.9002233	0.56734067	3435.8672
658.06885	1.9048666	0.56863028	3444.1133
658.96973	1.9100292	0.56987989	3450.1206
659.87061	1.9111509	0.57107031	3439.3801
660.77148	1.9167269	0.57226837	3444.511
661.67236	1.9148206	0.57335037	3435.7383
662.57324	1.918026	0.57444572	3438.9871
663.47412	1.9206768	0.57557976	3448.4536
664.375	1.9240252	0.57700962	3444.7786
665.27588	1.9250383	0.57825375	3437.8948
666.17676	1.9289521	0.57946223	3442.0142
667.07764	1.9303561	0.58066809	3445.3064
667.97852	1.9339385	0.5816893	3443.6167
668.87939	1.9365293	0.58306676	3451.3782
669.78027	1.9415226	0.58418071	3450.5002
670.68115	1.9434901	0.58561355	3451.126
671.58203	1.9433281	0.58697861	3448.7021
672.48291	1.9488254	0.58820993	3446.5996
673.38379	1.951514	0.58940524	3452.0764
674.28467	1.9519556	0.59072787	3444.9243
675.18555	1.9561532	0.59174615	3454.0552
676.08643	1.9600837	0.59308106	3456.8379
676.9873	1.962106	0.59425694	3449.9365
677.88818	1.9640337	0.59571105	3453.9756
678.78906	1.9672816	0.59704369	3455.7144
679.68994	1.9695611	0.59822071	3455.7578
680.59082	1.9720724	0.59932065	3453.9814
681.4917	1.9732519	0.60057604	3455.5386
682.39258	1.9766691	0.60189533	3458.1658
683.29346	1.9842227	0.6031673	3460.823
684.19434	1.9830427	0.60432249	3454.4536
685.09521	1.9889265	0.60542923	3456.6733
685.99609	1.98801	0.60652691	3458.616
686.89697	1.992592	0.60790867	3462.4209
687.79785	1.9933659	0.60917348	3455.4158
688.69873	1.9983071	0.61028308	3463.5151
689.59961	1.9979613	0.61137891	3457.8601
690.50049	2.0045149	0.61263126	3458.1829
691.40137	2.0066321	0.61365175	3460.6343
692.30225	2.0068164	0.61475617	3454.6611
693.20313	2.0115306	0.61599946	3465.6379
694.104	2.0128636	0.61731195	3461.3794
695.00488	2.0157127	0.61827815	3459.3501
695.90576	2.0191407	0.61950994	3465.7341
696.80664	2.0186751	0.62087494	3464.4182
697.70752	2.022356	0.62187827	3460.489
698.6084	2.0297256	0.62332547	3472.511
699.50928	2.0298982	0.62490261	3469.0244
700.41016	2.0320635	0.62645018	3474.6396
701.31104	2.0359154	0.62763268	3459.3594
702.21191	2.0361001	0.62881023	3465.0591
703.11279	2.0416386	0.63003033	3469.698
704.01367	2.0424538	0.63160348	3472.7629
704.91455	2.046093	0.63294601	3472.0017
705.81543	2.0498962	0.63412911	3466.1946
706.71631	2.0476007	0.63505447	3460.2637
707.61719	2.0510156	0.63649613	3469.6365
708.51807	2.0541685	0.63808781	3477.7781
709.41895	2.0600307	0.63966042	3472.5586
710.31982	2.0587831	0.64082444	3462.5127
711.2207	2.0659521	0.64180893	3467.2847
712.12158	2.0665023	0.6430949	3473.0701
713.02246	2.0711379	0.64420587	3474.7183
713.92334	2.0757537	0.64561272	3474.271
714.82422	2.0740817	0.64661402	3464.2292
715.7251	2.0766308	0.6478278	3470.5452
716.62598	2.0811045	0.64914554	3477.4192
717.52686	2.084244	0.65045398	3476.6311
718.42773	2.0850062	0.65174407	3480.1167
719.32861	2.0895765	0.65332294	3485.0962
720.22949	2.091522	0.6546787	3477.0437
721.13037	2.0950131	0.65606666	3478.7515
722.03125	2.0991449	0.65716934	3481.8191
722.93213	2.0995231	0.65820909	3473.9683
723.83301	2.1029286	0.65926802	3473.3682
724.73389	2.1053765	0.66037887	3473.6853
725.63477	2.1087167	0.66146857	3483.1243
726.53564	2.1072805	0.66280514	3477.0764
727.43652	2.1147602	0.66379368	3473.5415
728.3374	2.1172018	0.66515577	3481.1077
729.23828	2.1200297	0.66645688	3483.7844
730.13916	2.1225045	0.66816264	3486.3059
731.04004	2.124038	0.6695354	3484.46
731.94092	2.1242764	0.6708377	3481.6077
732.8418	2.1273782	0.672185	3478.4934
733.74268	2.1312807	0.67356884	3483.2246
734.64355	2.1359751	0.67467505	3478.5508
735.54443	2.1367981	0.67593729	3480.5242
736.44531	2.1395798	0.67748201	3481.1096
737.34619	2.142894	0.67883015	3490.9797
738.24707	2.1455104	0.6801334	3487.864
739.14795	2.148037	0.68143147	3490.8142
740.04883	2.1497743	0.68290091	3481.5149
740.94971	2.1521776	0.68416804	3483.8269
741.85059	2.1554043	0.68557441	3487.5664
742.75146	2.1602764	0.68686908	3484.8901
743.65234	2.1613939	0.68830562	3488.7502
744.55322	2.1624417	0.68986231	3488.6067
745.4541	2.1710212	0.69148332	3496.1035
746.35498	2.1709924	0.69288737	3488.5725
747.25586	2.1711214	0.6940347	3483.7991
748.15674	2.1755097	0.69530725	3491.5151
749.05762	2.1795864	0.6968413	3491.8975
749.9585	2.1846452	0.69782656	3489.1394
750.85938	2.1825056	0.69927174	3490.1243
751.76025	2.1861517	0.70043772	3487.3103
752.66113	2.1899257	0.70167732	3494.1243
753.56201	2.1876686	0.70301181	3491.9753
754.46289	2.1927836	0.70456707	3491.1831
755.36377	2.1982245	0.70607239	3492.4019
756.26465	2.1997604	0.70772225	3489.457
757.16553	2.2024457	0.70905036	3489.8699
758.06641	2.2072611	0.71031493	3497.0142
758.96729	2.208252	0.71151578	3490.9231
759.86816	2.2101822	0.71295816	3495.1897
760.76904	2.2149742	0.71435988	3490.5303
761.66992	2.2165427	0.71571612	3490.363
762.5708	2.2175617	0.71704018	3497.8145
763.47168	2.2186499	0.71853232	3495.4138
764.37256	2.2252905	0.71993446	3493.6284
765.27344	2.2280037	0.7214306	3499.5535
766.17432	2.2304881	0.72259629	3496.6426
767.0752	2.2319198	0.72422987	3493.4646
767.97607	2.2347932	0.72541976	3498.5969
768.87695	2.2404103	0.7268514	3499.2751
769.77783	2.2394433	0.72820777	3497.6931
770.67871	2.2410724	0.7296657	3496.8977
771.57959	2.2473993	0.73103994	3503.3569
772.48047	2.2471471	0.73269576	3494.0266
773.38135	2.2539613	0.73399395	3494.0056
774.28223	2.2518253	0.73538542	3495.9082
775.18311	2.2551436	0.7367326	3495.3652
776.08398	2.2575891	0.73845696	3502.6963
776.98486	2.2624724	0.7400189	3502.1267
777.88574	2.2633817	0.74144077	3489.3704
778.78662	2.2691185	0.74271441	3498.02
779.6875	2.268358	0.7443018	3501.8064
780.58838	2.2759855	0.74581724	3502.3279
781.48926	2.2719684	0.74746114	3502.0803
782.39014	2.2782109	0.74902761	3499.4023
783.29102	2.2804403	0.75035995	3501.2388
784.19189	2.2845244	0.75205082	3507.5313
785.09277	2.2844849	0.75372368	3504.5496
785.99365	2.2920942	0.75579214	3508.9229
786.89453	2.2911482	0.75693786	3497.5776
787.79541	2.2920079	0.75851566	3500.8022
788.69629	2.2961464	0.75998449	3503.5063
789.59717	2.2976923	0.76170307	3504.4636
790.49805	2.299521	0.76301122	3499.0247
791.39893	2.3041928	0.76458377	3504.481
792.2998	2.3120828	0.76577431	3508.0076
793.20068	2.3105314	0.76732618	3502.9788
794.10156	2.3161218	0.76848763	3506.9587
795.00244	2.3159232	0.77007306	3502.3091
795.90332	2.3169124	0.77110511	3502.124
796.8042	2.3220451	0.77243376	3503.2905
797.70508	2.3219163	0.77370888	3503.7056
798.60596	2.3293462	0.77481329	3507.3169
799.50684	2.3300307	0.77617693	3497.6187
800.40771	2.3331981	0.77756459	3511.4338
801.30859	2.3337491	0.77886057	3508.3181
802.20947	2.3382063	0.78030777	3507.6992
803.11035	2.3428395	0.78149509	3503.2117
804.01123	2.3449612	0.78285128	3512.8025
804.91211	2.3455081	0.78448743	3511.9304
805.81299	2.3478835	0.78593266	3508.3328
806.71387	2.3538971	0.78739053	3513.9746
807.61475	2.3527045	0.7891615	3505.4255
808.51563	2.3581047	0.7907443	3511.0867
809.4165	2.3623061	0.79214692	3510.9004
810.31738	2.364264	0.79334939	3505.9824
811.21826	2.366091	0.79486585	3511.896
812.11914	2.3649282	0.79623568	3506.085
813.02002	2.3697367	0.7980029	3505.8689
813.9209	2.3723514	0.79934549	3505.3499
814.82178	2.3743136	0.8007831	3507.3267
815.72266	2.378619	0.80216444	3504.6826
816.62354	2.3796389	0.80351424	3507.8911
817.52441	2.3849318	0.80512267	3517.9768
818.42529	2.3871851	0.80681258	3513.5435
819.32617	2.391943	0.80830485	3508.7852
820.22705	2.3939624	0.80973804	3513.7505
821.12793	2.3953507	0.81109768	3509.7117
822.02881	2.3932786	0.81245226	3509.5676
822.92969	2.3972166	0.81407219	3509.875
823.83057	2.4008205	0.81543005	3505.3484
824.73145	2.404547	0.81681067	3509.0439
825.63232	2.4090943	0.81828582	3506.3723
826.5332	2.4111984	0.81944799	3510.2715
827.43408	2.4126301	0.82095432	3512.9644
828.33496	2.4162793	0.82239658	3516.2048
829.23584	2.4169724	0.8235538	3509.4929
830.13672	2.4217062	0.82509148	3512.532
831.0376	2.4233463	0.82669234	3512.4446
831.93848	2.4260781	0.828174	3513.7715
832.83936	2.4289019	0.82978231	3509.7034
833.74023	2.432272	0.83117074	3507.6702
834.64111	2.4362836	0.83276254	3511.688
835.54199	2.4383938	0.8339929	3510.6965
836.44287	2.4418683	0.83523828	3516.4766
837.34375	2.4453444	0.83645135	3517.3845
838.24463	2.4434659	0.83821088	3512.7981
839.14551	2.4499333	0.83962363	3507.9648
840.04639	2.4495738	0.84131545	3512.5557
840.94727	2.4547944	0.8426668	3508.3511
841.84814	2.4542861	0.84406626	3508.9929
842.74902	2.4590123	0.84537846	3511.0115
843.6499	2.4628792	0.84692758	3520.834
844.55078	2.4684894	0.84861594	3518.7314
845.45166	2.4672489	0.85018909	3518.9058
846.35254	2.4707358	0.8519429	3517.0989
847.25342	2.4719098	0.85354507	3518.2979
848.1543	2.4740002	0.85552019	3516.2012
849.05518	2.4773319	0.85717618	3514.1345
849.95605	2.4793739	0.85880405	3519.2424
850.85693	2.4847631	0.8604129	3516.7327
851.75781	2.4887848	0.86166894	3509.4934
852.65869	2.4853504	0.86318094	3513.0127
853.55957	2.4909015	0.86475295	3515.2649
854.46045	2.491847	0.86674088	3514.0601
855.36133	2.4960277	0.86824018	3515.1375
856.26221	2.4988449	0.86974007	3507.8379
857.16309	2.5021505	0.87134743	3513.5974
858.06396	2.5045903	0.87289107	3515.1926
858.96484	2.5085642	0.87461734	3518.2197
859.86572	2.5136871	0.87613553	3517.6609
860.7666	2.5118148	0.87767726	3516.0481
861.66748	2.5149074	0.87916279	3515.6621
862.56836	2.5198493	0.88096589	3518.8667
863.46924	2.5186133	0.88285911	3506.9268
864.37012	2.5251527	0.88462359	3516.9434
865.271	2.5310745	0.88596374	3516.9849
866.17188	2.5311375	0.88763565	3521.2737
867.07275	2.5314727	0.88917905	3514.5115
867.97363	2.5348637	0.89075214	3514.7124
868.87451	2.536123	0.89227235	3512.0398
869.77539	2.5388675	0.89396358	3514.5439
870.67627	2.54369	0.8953765	3515.2078
871.57715	2.5460224	0.8970989	3512.2864
872.47803	2.5478017	0.89852917	3511.0034
873.37891	2.5528295	0.90019852	3515.1973
874.27979	2.5522568	0.90175658	3513.5515
875.18066	2.5557704	0.90401506	3524.865
876.08154	2.560708	0.90606165	3522.8892
876.98242	2.5622301	0.90834564	3519.0818
877.8833	2.5612073	0.91039681	3515.9287
878.78418	2.5688477	0.91281343	3519.4856
879.68506	2.5697918	0.91477793	3513.2454
880.58594	2.573936	0.91648632	3511.1877
881.48682	2.5740602	0.91830134	3517.6619
882.3877	2.5785604	0.92020059	3514.2227
883.28857	2.5819459	0.92240846	3519.4346
884.18945	2.5815575	0.92441809	3514.9026
885.09033	2.5849257	0.92684811	3519.4993
885.99121	2.5883002	0.92897457	3514.8145
886.89209	2.590075	0.93138927	3511.9949
887.79297	2.5948799	0.93335176	3513.3511
888.69385	2.5979774	0.93519813	3515.6663
889.59473	2.597285	0.93717557	3515.01
890.49561	2.6005821	0.93939793	3514.4871
891.39648	2.604569	0.94107246	3514.8445
892.29736	2.6086152	0.94299889	3510.9893
893.19824	2.6103981	0.94513965	3508.8477
894.09912	2.6167891	0.94679618	3514.4468
895	2.6125093	0.94894034	3509.3076
895.90088	2.6183467	0.95071208	3516.0537
896.80176	2.6219308	0.95299697	3512.4514
897.70264	2.6234183	0.95515585	3517.8586
898.60352	2.6255004	0.95727426	3516.335
899.50439	2.6278341	0.95931256	3514.6038
900.40527	2.6329448	0.96109718	3511.6592
901.30615	2.6334696	0.96307027	3514.5635
902.20703	2.6366603	0.96496391	3517.3047
903.10791	2.6411531	0.96676809	3514.5681
904.00879	2.6406639	0.96857202	3515.123
904.90967	2.6494892	0.97011018	3515.4595
905.81055	2.6481886	0.97202432	3512.0239
906.71143	2.6530213	0.97355318	3516.1025
907.6123	2.6529098	0.97555262	3507.3254
908.51318	2.6571286	0.97706288	3512.2749
909.41406	2.6607676	0.97933519	3517.0779
910.31494	2.6609454	0.9811216	3507.9187
911.21582	2.6619179	0.98330289	3506.655
912.1167	2.6676109	0.98492426	3511.3311
913.01758	2.672174	0.9868629	3515.2463
913.91846	2.6742058	0.98847127	3510.5273
914.81934	2.6747522	0.99067509	3515.0684
915.72021	2.6788819	0.99270707	3514.8032
916.62109	2.6814795	0.9949097	3510.7744
917.52197	2.6819878	0.99675101	3506.5869
918.42285	2.6843078	0.99878627	3509.564
919.32373	2.6883478	1.0008897	3514.2036
920.22461	2.6886961	1.0032161	3507.0212
921.12549	2.6931486	1.0052274	3511.8879
922.02637	2.6979897	1.007216	3508.9617
922.92725	2.7014387	1.0092455	3509.4932
923.82813	2.7017465	1.0110873	3507.051
924.729	2.7072752	1.0130166	3509.6511
925.62988	2.7091985	1.0145643	3503.2095
926.53076	2.7109864	1.0162014	3504.7974
927.43164	2.7139981	1.017683	3509.6584
928.33252	2.715065	1.0197302	3507.0034
929.2334	2.7173743	1.0214857	3506.7219
930.13428	2.7244473	1.0234575	3507.2742
931.03516	2.7254636	1.0252709	3505.9297
931.93604	2.7266886	1.027342	3505.1836
932.83691	2.7290699	1.0291396	3508.0686
933.73779	2.7337277	1.0313377	3512.5134
934.63867	2.7350204	1.0329962	3507.3677
935.53955	2.738682	1.0352135	3504.364
936.44043	2.7400999	1.0369934	3501.9565
937.34131	2.7408326	1.0388643	3499.5674
938.24219	2.7466464	1.0409777	3508.0029
939.14307	2.7474968	1.043188	3503.0962
940.04395	2.749507	1.0448666	3499.592
940.94482	2.7520249	1.0470583	3498.0835
941.8457	2.7562759	1.0489609	3498.8838
942.74658	2.7587609	1.0507103	3501.9902
943.64746	2.7596941	1.0529678	3505.8445
944.54834	2.7643628	1.0554929	3494.3992
945.44922	2.7686641	1.0573884	3497.8894
946.3501	2.7693858	1.0595571	3500
947.25098	2.7705095	1.0617614	3496.0342
948.15186	2.775979	1.063954	3501.0515
949.05273	2.7787867	1.0667366	3499.5588
949.95361	2.7800274	1.0692664	3493.6509
950.85449	2.7814274	1.0718923	3495.6509
951.75537	2.7855372	1.074121	3498.3821
952.65625	2.7905269	1.076779	3498.8958
953.55713	2.7903278	1.0789788	3491.5115
954.45801	2.7942476	1.0814346	3499.2102
955.35889	2.7983131	1.0840605	3495.4939
956.25977	2.8016112	1.0869853	3499.0632
957.16064	2.8031378	1.0893584	3492.3862
958.06152	2.8040383	1.0917425	3493.9412
958.9624	2.8082943	1.0943705	3498.6362
959.86328	2.8095162	1.0967392	3493.9956
960.76416	2.8141797	1.0991263	3495.9192
961.66504	2.817071	1.1013384	3489.1428
962.56592	2.8189299	1.1034688	3489.2114
963.4668	2.8235817	1.1054143	3494.3315
964.36768	2.8225234	1.1078413	3491.6758
965.26855	2.8267756	1.1101393	3491.803
966.16943	2.8310254	1.1127059	3490.0098
967.07031	2.8348534	1.1148249	3491.7544
967.97119	2.8360083	1.1173178	3494.9729
968.87207	2.8388367	1.1196172	3489.2993
969.77295	2.839499	1.1217984	3480.1904
970.67383	2.8454645	1.1236211	3481.8015
971.57471	2.8469727	1.1258014	3485.5728
972.47559	2.8480043	1.1281898	3484.0938
973.37646	2.8540022	1.1304775	3488.3196
974.27734	2.8543978	1.1328895	3477.7808
975.17822	2.857548	1.1349596	3484.1567
976.0791	2.858433	1.1374336	3482.5244
976.97998	2.861975	1.1394163	3478.6301
977.88086	2.8651392	1.1415803	3480.0229
978.78174	2.8677688	1.1435891	3477.5891
979.68262	2.8701484	1.14557	3475.7695
980.5835	2.8745723	1.1478082	3479.9614
981.48438	2.8757899	1.1505634	3481.6252
982.38525	2.881938	1.1533041	3482.3569
983.28613	2.8795421	1.1561838	3477.7415
984.18701	2.8845396	1.1587373	3481.1211
985.08789	2.8868279	1.1612453	3467.876
985.98877	2.8893311	1.1638589	3470.9795
986.88965	2.8928659	1.1662713	3466.6213
987.79053	2.8934734	1.1688439	3471.584
988.69141	2.8960724	1.1716106	3467.7339
989.59229	2.9002571	1.1740708	3469.2502
990.49316	2.9026084	1.1769997	3468.491
991.39404	2.9072685	1.1791745	3465.4319
992.29492	2.9062526	1.1817641	3465.2588
993.1958	2.9099612	1.184172	3464.6196
994.09668	2.9118807	1.1868366	3462.6836
994.99756	2.9187143	1.1891803	3465.6484
995.89844	2.9192271	1.1921617	3464.9934
996.79932	2.9224617	1.1949388	3462.3088
997.7002	2.9233196	1.1972741	3455.7292
998.60107	2.9260654	1.1995658	3461.3027
999.50195	2.9312172	1.2022887	3463.3333
1000.4028	2.9311697	1.2052896	3458.6702
1001.3037	2.9329095	1.2081606	3455.217
1002.2046	2.9382033	1.2106501	3453.1194
1003.1055	2.939147	1.2131965	3450.2732
1004.0063	2.9420891	1.2161808	3452.6599
1004.9072	2.9475307	1.2185755	3456.7273
1005.8081	2.9486587	1.2214774	3453.5933
1006.709	2.9532661	1.2243489	3447.655
1007.6099	2.9533675	1.2272701	3450.8535
1008.5107	2.9542396	1.2293764	3440.5022
1009.4116	2.9593594	1.2322233	3447.3618
1010.3125	2.9608512	1.2343905	3441.1409
1011.2134	2.9640496	1.2371377	3443.6797
1012.1143	2.9692917	1.2398504	3442.7573
1013.0151	2.9699986	1.2427728	3438.6865
1013.916	2.9719121	1.2452729	3434.7954
1014.8169	2.9769025	1.2478465	3441.8845
1015.7178	2.9808328	1.2508813	3441.1843
1016.6187	2.9827063	1.2531818	3433.8599
1017.5195	2.9846313	1.2554889	3432.4202
1018.4204	2.9846432	1.258364	3432.9077
1019.3213	2.9901376	1.2611752	3434.4246
1020.2222	2.9924932	1.2632452	3426.0012
1021.123	2.9951038	1.2655441	3430.6936
1022.0239	3.0005631	1.2675747	3425.97
1022.9248	3.001025	1.2698008	3428.637
1023.8257	3.0038037	1.2719555	3431.7253
1024.7266	3.0058813	1.2748898	3423.4067
1025.6274	3.0078778	1.2774309	3423.061
1026.5283	3.0105283	1.2804325	3424.0681
1027.4292	3.0131586	1.2837715	3418.6814
1028.3301	3.0186074	1.2861415	3425.2603
1029.231	3.0172577	1.2894487	3417.644
1030.1318	3.0225403	1.2922956	3412.3875
1031.0327	3.0250041	1.2950485	3411.3716
1031.9336	3.0268877	1.2978452	3411.9553
1032.8345	3.0299513	1.3006711	3412.8418
1033.7354	3.0356631	1.3040712	3410.6985
1034.6362	3.0330958	1.3066578	3403.8657
1035.5371	3.0383074	1.3096565	3412.4482
1036.438	3.0428224	1.3129953	3402.6865
1037.3389	3.0431116	1.3163885	3406.5737
1038.2397	3.046361	1.3194451	3407.2883
1039.1406	3.047436	1.3222692	3393.8457
1040.0415	3.0526056	1.3251712	3395.4275
1040.9424	3.0555954	1.3280591	3391.3049
1041.8433	3.057555	1.3304608	3385.7507
1042.7441	3.0616767	1.3326061	3388.3245
1043.645	3.0609994	1.3349053	3385.666
1044.5459	3.0629616	1.3374068	3387.0503
1045.4468	3.0697796	1.3405924	3389.4885
1046.3477	3.0673211	1.3429667	3378.0337
1047.2485	3.0738459	1.3450741	3381.2175
1048.1494	3.0735755	1.3477358	3384.7542
1049.0503	3.0758829	1.3508409	3380.6758
1049.9512	3.0824502	1.353623	3376.8684
1050.8521	3.0840883	1.356464	3375.4102
1051.7529	3.0877721	1.3592514	3376.8623
1052.6538	3.0910649	1.3619701	3377.6118
1053.5547	3.092345	1.3647105	3367.0979
1054.4556	3.0921729	1.3676949	3372.7964
1055.3564	3.097698	1.3708889	3374.6714
1056.2573	3.1005454	1.3739928	3365.2996
1057.1582	3.1018651	1.3769702	3359.4016
1058.0591	3.1094928	1.3795999	3360.8992
1058.96	3.1077015	1.3825774	3359.2446
1059.8608	3.1135662	1.3852437	3354.6638
1060.7617	3.1118839	1.3883982	3359.1321
1061.6626	3.1148748	1.3914355	3348.2903
1062.5635	3.1201954	1.3943695	3344.8091
1063.4644	3.122858	1.3975139	3347.1062
1064.3652	3.1237049	1.4006089	3342.926
1065.2661	3.1281581	1.4031715	3341.7214
1066.167	3.1281762	1.4060099	3336.4207
1067.0679	3.1308904	1.4089097	3329.7888
1067.9688	3.1355379	1.4119426	3332.9619
1068.8696	3.1361794	1.4147674	3332.3977
1069.7705	3.1407795	1.4179132	3333.2241
1070.6714	3.1442595	1.4207554	3326.8711
1071.5723	3.1484783	1.4235259	3324.4038
1072.4731	3.1487877	1.4266834	3324.1555
1073.374	3.1503148	1.429582	3317.3669
1074.2749	3.1511304	1.4323584	3306.2979
1075.1758	3.1557183	1.4346759	3313.5662
1076.0767	3.1592808	1.4376171	3314.1057
1076.9775	3.1627963	1.4405868	3302.4719
1077.8784	3.1650915	1.443575	3307.9946
1078.7793	3.1691189	1.446295	3303.5261
1079.6802	3.1687815	1.4496485	3303.4473
1080.5811	3.1744995	1.4525615	3291.3994
1081.4819	3.1758423	1.4555564	3290.8213
1082.3828	3.1798995	1.4579767	3287.3408
1083.2837	3.1786294	1.4607549	3286.1416
1084.1846	3.184551	1.4634944	3290.4895
1085.0854	3.1866271	1.4666216	3284.21
1085.9863	3.1905613	1.4697491	3284.1157
1086.8872	3.193059	1.4726884	3278.1213
1087.7881	3.1961296	1.4765359	3275.3223
1088.689	3.1983008	1.4796505	3271.6143
1089.5898	3.2022874	1.4827909	3269.4231
1090.4907	3.2041276	1.4861032	3266.8315
1091.3916	3.2078965	1.4894263	3263.8542
1092.2925	3.2100952	1.4925135	3261.5166
1093.1934	3.2094526	1.495736	3249.0215
1094.0942	3.2137609	1.4985254	3253.1819
1094.9951	3.2185702	1.5014107	3244.0876
1095.896	3.2204823	1.504102	3237.9329
1096.7969	3.2221203	1.5066974	3246.686
1097.6978	3.2253966	1.5098752	3233.4536
1098.5986	3.2259414	1.5126553	3232.4204
1099.4995	3.2294376	1.5161297	3231.8818
1100.4004	3.2316315	1.5198023	3223.3389
1101.3013	3.2344067	1.523682	3216.446
1102.2021	3.2376716	1.5267889	3203.8047
1103.103	3.2393594	1.5298738	3207.3528
1104.0039	3.243171	1.5330062	3197.9102
1104.9048	3.2471902	1.5361114	3193.614
1105.8057	3.2473536	1.5391589	3187.6599
1106.7065	3.2516878	1.5427773	3178.8313
1107.6074	3.2551217	1.5459806	3162.3333
1108.5083	3.257195	1.5494652	3165.2864
1109.4092	3.2592752	1.5553175	3127.5938
1110.3101	3.2651401	1.5651963	3052.4807
1110.6104	3.2673731	1.5707015	2998.6218