File: datasets/am_bench_2022/raw_data/0-XY.05-2/specimen.dat
MTS793|MPT|ENU|1|2|.|/|:|1|0|0|A

Operator Information						Time:	34.961426	Sec	10/13/2021 12:28:04 PM
Operator	Nick Derimow
Project	AM Bench 2022 mini-tensile challenge
Specimen ID	O-XY.05-2
Material	PBF-L Inconel 625
Specimen Width	2.56	mm
Specimen Thickness	1.52	mm
Notes
Operator Information End

Data Acquisition						Time:	1035.9556	Sec	10/13/2021 12:44:45 PM
Time	Axial Displacement	Axial Extensometer	Axial Force
Sec	mm	mm	N
35.075195	-0.0046951305	5.0066177e-05	61.329613
36.076172	0.00066205102	0.00011115954	72.836533
37.077148	0.0049536973	0.00023325715	86.612885
38.078125	0.0086207846	0.00028056133	102.19901
39.079102	0.0080364356	0.00033444253	116.27041
40.080078	0.01244113	0.00067517214	130.52774
41.081055	0.014077953	0.00040020741	143.3019
42.082031	0.019059056	0.00054633466	152.97836
43.083008	0.023260091	0.00061566464	176.67276
44.083984	0.022969555	0.00067763904	189.19543
45.084961	0.029063115	0.0009173922	208.96596
46.085938	0.03325969	0.00072946004	218.94759
47.086914	0.033360291	0.00068311777	235.84804
48.087891	0.035698868	0.0011208059	261.63144
49.088867	0.0424155	0.0011626108	278.58994
50.089844	0.044850629	0.001218672	303.09842
51.09082	0.044904515	0.0013975491	314.90524
52.091797	0.048777312	0.0014861582	345.31683
53.092773	0.052518982	0.0016078214	358.76758
54.09375	0.050923087	0.0017009065	377.12692
55.094727	0.0557517	0.0018530493	401.28195
56.095703	0.056629248	0.0018890927	423.8212
57.09668	0.064611904	0.001929239	444.46591
58.097656	0.065932631	0.0021290425	461.60599
59.098633	0.070363343	0.0022261424	480.88705
60.099609	0.071645141	0.0023957009	510.38043
61.100586	0.074413784	0.0024046588	532.07294
62.101563	0.077404119	0.0025530912	554.06134
63.102539	0.079204701	0.0027572874	582.50104
64.103516	0.085415713	0.0027921353	615.01263
65.104492	0.088530205	0.0030197497	637.73474
66.105469	0.092985921	0.0031241488	667.23584
67.106445	0.093824334	0.0032180739	691.27954
68.107422	0.094077326	0.0034942967	712.6994
69.108398	0.099632122	0.0035843535	743.98962
70.109375	0.10308756	0.0037905003	771.78949
71.110352	0.10297343	0.0038363826	793.70648
72.111328	0.10761186	0.0039589228	825.37378
73.112305	0.11269233	0.0040606214	850.98932
74.113281	0.11454736	0.0041631102	874.42267
75.114258	0.11465535	0.0043332833	904.21564
76.115234	0.11873815	0.0045769243	933.883
77.116211	0.12251076	0.0047481824	958.39465
78.117188	0.12768278	0.0046750493	981.91565
79.118164	0.13050453	0.0048591336	1019.0995
80.119141	0.13213767	0.0050906381	1045.6785
81.120117	0.13426602	0.0052045593	1073.2301
82.121094	0.13811244	0.005406674	1097.5355
83.12207	0.13992572	0.0055840584	1129.7878
84.123047	0.14368132	0.0055872137	1143.9036
85.124023	0.14791201	0.0057722558	1180.8027
86.125	0.14584759	0.0058992025	1202.7653
87.125977	0.1523643	0.0061115031	1233.2042
88.126953	0.15495427	0.0061415937	1260.101
89.12793	0.16290312	0.0063410476	1288.6521
90.128906	0.15974458	0.0065068351	1317.9519
91.129883	0.16571771	0.0066546714	1348.2635
92.130859	0.16696098	0.0066847494	1368.5487
93.131836	0.17096552	0.0069355532	1398.9292
94.132813	0.17250359	0.0070039202	1420.4154
95.133789	0.17895392	0.0071909591	1457.2091
96.134766	0.17758667	0.007452569	1490.4159
97.135742	0.18240833	0.007708081	1519.4119
98.136719	0.18766209	0.0077959704	1548.7277
99.137695	0.1876078	0.0077691181	1568.9189
100.13867	0.19001296	0.0080181435	1593.426
101.13965	0.19555603	0.0080999807	1620.865
102.14063	0.19848017	0.0083258403	1654.1327
103.1416	0.20205364	0.0085454322	1674.6595
104.14258	0.20442995	0.0086775729	1700.3823
105.14355	0.20908093	0.0088451114	1727.4702
106.14453	0.21014616	0.0088455621	1748.2017
107.14551	0.21261054	0.0090738116	1767.9437
108.14648	0.21715005	0.0093060201	1798.0975
109.14746	0.21673331	0.0094091194	1822.1787
110.14844	0.22222371	0.0097172847	1846.2242
111.14941	0.22341454	0.0098089678	1877.3073
112.15039	0.23032378	0.010190136	1909.722
113.15137	0.23247615	0.010143211	1929.5216
114.15234	0.23610288	0.01033159	1948.952
115.15332	0.23670627	0.01059472	1969.6743
116.1543	0.23827794	0.010759561	1990.7281
117.15527	0.24110934	0.01102115	2015.6896
118.15625	0.24811409	0.011194081	2044.8942
119.15723	0.25081143	0.011342469	2058.1697
120.1582	0.25257671	0.011612299	2082.1121
121.15918	0.25526586	0.011763192	2105.0515
122.16016	0.25578055	0.012021843	2121.241
123.16113	0.26167035	0.012124607	2146.1396
124.16211	0.26370424	0.012445893	2161.519
125.16309	0.26684681	0.012630005	2182.905
126.16406	0.27140701	0.012845349	2193.6343
127.16504	0.2736131	0.012996121	2218.449
128.16602	0.27469429	0.013216197	2223.2554
129.16699	0.28307807	0.013516522	2249.4883
130.16797	0.2794534	0.01358216	2258.6079
131.16895	0.28517431	0.013913326	2275.718
132.16992	0.2903451	0.0141614	2292.7087
133.1709	0.29042909	0.014366453	2303.8818
134.17188	0.29449019	0.014545366	2326.1245
135.17285	0.29618624	0.014830452	2329.2405
136.17383	0.30065224	0.015113424	2347.5259
137.1748	0.30405194	0.015264329	2364.3352
138.17578	0.30427158	0.015700262	2379.8711
139.17676	0.30810013	0.015869128	2389.6245
140.17773	0.31359199	0.016204227	2406.9011
141.17871	0.31560457	0.016525937	2418.9243
142.17969	0.31755963	0.016923754	2430.0688
143.18066	0.32050735	0.017139802	2443.7898
144.18164	0.3252247	0.017336322	2452.9155
145.18262	0.32645589	0.017757602	2468.1174
146.18359	0.3282989	0.018005403	2471.9573
147.18457	0.33392119	0.018451752	2488.7698
148.18555	0.33586681	0.018658014	2504.2061
149.18652	0.33905387	0.019211052	2510.4277
150.1875	0.34118906	0.019592527	2521.2761
151.18848	0.34301415	0.01982256	2524.0696
152.18945	0.35080954	0.020395314	2541.6631
153.19043	0.35106608	0.020775849	2550.7729
154.19141	0.35183173	0.021226628	2554.8611
155.19238	0.35847673	0.021626135	2566.1003
156.19336	0.36277318	0.022162043	2576.3706
157.19434	0.36118308	0.022550983	2576.7827
158.19531	0.36944541	0.023056529	2588.7993
159.19629	0.37181559	0.023656381	2604.5789
160.19727	0.37443608	0.024257923	2604.9417
161.19824	0.37544191	0.024862422	2606.2153
162.19922	0.38109151	0.02534589	2616.8923
163.2002	0.38267303	0.025862573	2620.4443
164.20117	0.38618562	0.026548602	2629.8801
165.20215	0.38455677	0.027240327	2640.5757
166.20313	0.39062062	0.028069511	2647.0149
167.2041	0.39248922	0.028700966	2649.7097
168.20508	0.39625776	0.029422525	2660.2712
169.20605	0.40154326	0.030106382	2661.1118
170.20703	0.40679559	0.031017341	2676.1353
171.20801	0.40649256	0.031931967	2677.1614
172.20898	0.40962058	0.032717623	2680.3728
173.20996	0.41411316	0.033480294	2684.1033
174.21094	0.41696867	0.034404047	2697.1128
175.21191	0.41653001	0.035161715	2691.8481
176.21289	0.42053503	0.035990335	2698.5496
177.21387	0.42791367	0.037064549	2712.8608
178.21484	0.42963204	0.038096067	2707.6758
179.21582	0.430971	0.038925655	2705.9353
180.2168	0.43465391	0.039983079	2717.8577
181.21777	0.43502536	0.040932473	2725.8823
182.21875	0.43762988	0.042160071	2728.7092
183.21973	0.44274494	0.043293599	2733.7039
184.2207	0.44343865	0.044493102	2730.3567
185.22168	0.44983795	0.045573689	2741.125
186.22266	0.45057803	0.04671979	2741.6743
187.22363	0.45235854	0.048241857	2745.4761
188.22461	0.45585454	0.049409624	2746.853
189.22559	0.45832178	0.05051152	2749.5237
190.22656	0.46453524	0.051632937	2761.3975
191.22754	0.46818268	0.053016767	2765.4707
192.22852	0.46818084	0.054187618	2754.9297
193.22949	0.47174361	0.055014484	2763.0498
194.23047	0.47493562	0.0562062	2770.384
195.23145	0.47964355	0.057561647	2782.3184
196.23242	0.48513636	0.058883924	2775.2036
197.2334	0.48266503	0.059931364	2766.7612
198.23438	0.48868653	0.06101273	2780.5466
199.23535	0.49089786	0.062237594	2778.7966
200.23633	0.49297935	0.063613139	2786.7727
201.2373	0.49756613	0.065219976	2795.1321
202.23828	0.49641901	0.066729181	2793.8208
203.23926	0.50445718	0.068284795	2795.8855
204.24023	0.50727582	0.069236808	2797.3718
205.24121	0.50782269	0.070616931	2794.1682
206.24219	0.5103305	0.071853556	2796.8547
207.24316	0.51510894	0.072939247	2805.0476
208.24414	0.51796794	0.074226879	2802.76
209.24512	0.52090114	0.075641043	2807.7322
210.24609	0.52440774	0.077141963	2811.729
211.24707	0.52669966	0.078199372	2816.7078
212.24805	0.53030658	0.079645097	2814.1335
213.24902	0.53368354	0.080957234	2814.8137
214.25	0.53734773	0.082376041	2828.2529
215.25098	0.54128611	0.083566882	2818.3621
216.25195	0.54438037	0.08486411	2820.8062
217.25293	0.54466963	0.086369693	2827.5637
218.25391	0.55011517	0.088242076	2831.3135
219.25488	0.55162966	0.089756362	2831.3286
220.25586	0.55162704	0.091151357	2831.21
221.25684	0.55983591	0.092318512	2831.3098
222.25781	0.55877888	0.093713418	2833.8101
223.25879	0.56197149	0.094872095	2832.9099
224.25977	0.56692159	0.096419133	2844.385
225.26074	0.56916434	0.09785036	2839.2788
226.26172	0.57034671	0.099354148	2845.6401
227.2627	0.57420945	0.10106791	2846.5461
228.26367	0.57578814	0.10239632	2841.8892
229.26465	0.58317953	0.10372578	2845.2
230.26563	0.58275598	0.10513463	2853.1018
231.2666	0.58541852	0.1066276	2853.042
232.26758	0.5902338	0.10811843	2849.595
233.26855	0.59170979	0.10938115	2858.7537
234.26953	0.59481657	0.11073546	2848.6992
235.27051	0.59967774	0.11194026	2855.0083
236.27148	0.60403305	0.11313854	2863.4109
237.27246	0.60317087	0.11455195	2856.9526
238.27344	0.6110009	0.11624018	2870.2346
239.27441	0.6084609	0.11761094	2862.4558
240.27539	0.6134901	0.11919895	2868.7166
241.27637	0.61879319	0.12068492	2874.9719
242.27734	0.62214154	0.12202661	2865.9155
243.27832	0.62532097	0.12355222	2870.5488
244.2793	0.62533611	0.12499502	2874.1541
245.28027	0.6289649	0.12628528	2872.7253
246.28125	0.63226891	0.12776925	2878.8298
247.28223	0.63871515	0.12912345	2881.2778
248.2832	0.63999021	0.13078739	2885.0781
249.28418	0.64202023	0.13218941	2886.5825
250.28516	0.64504886	0.13382189	2884.5383
251.28613	0.64945465	0.13526107	2888.252
252.28711	0.65002072	0.13679524	2884.4714
253.28809	0.65090442	0.13801263	2881.3965
254.28906	0.65411133	0.1397756	2889.9343
255.29004	0.65882599	0.14148715	2896.8145
256.29102	0.66221321	0.14303082	2890.1399
257.29199	0.66685295	0.14461616	2898.302
258.29297	0.67125887	0.14612274	2897.1892
259.29395	0.67054009	0.14753529	2896.6953
260.29492	0.67472744	0.14898849	2901.5574
261.2959	0.67734963	0.15046744	2907.5291
262.29688	0.67989939	0.1517182	2895.8518
263.29785	0.68398041	0.15325209	2901.6199
264.29883	0.68446493	0.15484031	2902.7444
265.2998	0.69055301	0.15600811	2905.53
266.30078	0.69254476	0.1572814	2905.8132
267.30176	0.69670928	0.15875417	2914.6465
268.30273	0.69911367	0.16042531	2910.7371
269.30371	0.69923598	0.16214684	2906.7834
270.30469	0.70776838	0.16337888	2920.3184
271.30566	0.70577174	0.16489589	2911.1121
272.30664	0.71068823	0.16615643	2912.7742
273.30762	0.71143138	0.16760299	2916.9482
274.30859	0.71650791	0.16906117	2919.1624
275.30957	0.71783292	0.17027315	2910.6206
276.31055	0.72187597	0.17170998	2920.0693
277.31152	0.7276364	0.17312269	2924.9861
278.3125	0.73190564	0.17447634	2921.6821
279.31348	0.72990948	0.17602862	2929.49
280.31445	0.73284203	0.17762512	2923.5774
281.31543	0.73774934	0.17918985	2929.9944
282.31641	0.74125743	0.18080793	2922.1707
283.31738	0.7450487	0.18225713	2931.5237
284.31836	0.7488637	0.1836312	2931.0754
285.31934	0.75047517	0.1853085	2940.7485
286.32031	0.75282133	0.18696441	2936.449
287.32129	0.7563231	0.18851249	2938.1443
288.32227	0.75984371	0.18998758	2938.957
289.32324	0.76027352	0.19153404	2936.5261
290.32422	0.76238614	0.19307172	2933.7534
291.3252	0.76787388	0.19450475	2940.1094
292.32617	0.76963121	0.19636284	2945.1001
293.32715	0.77025902	0.19768789	2942.3523
294.32813	0.78063905	0.19922777	2949.5874
295.3291	0.77791816	0.20024826	2936.6396
296.33008	0.78418243	0.20178494	2953.7822
297.33105	0.7870785	0.20318545	2955.0093
298.33203	0.78579426	0.20453987	2950.2126
299.33301	0.79176635	0.20627135	2954.876
300.33398	0.79696542	0.20780066	2957.2932
301.33496	0.79713565	0.20935966	2950.5583
302.33594	0.80141479	0.21071665	2953.9902
303.33691	0.80280244	0.21209683	2957.7205
304.33789	0.80885118	0.21349885	2955.4446
305.33887	0.81205362	0.21493347	2965.4736
306.33984	0.81402236	0.21655984	2957.3721
307.34082	0.81749874	0.21786024	2960.8882
308.3418	0.81980532	0.21907525	2963.5681
309.34277	0.82010406	0.22040127	2965.0854
310.34375	0.825885	0.22207542	2963.8564
311.34473	0.82604873	0.22379793	2965.918
312.3457	0.83064806	0.22526038	2970.2517
313.34668	0.83403957	0.22661337	2966.0229
314.34766	0.83313477	0.22804144	2965.7573
315.34863	0.83770221	0.22963908	2972.2031
316.34961	0.8403483	0.23099422	2968.0249
317.35059	0.84535027	0.23251399	2973.3865
318.35156	0.84903806	0.23385347	2967.1201
319.35254	0.85122585	0.23531134	2971.99
320.35352	0.85580289	0.23689972	2975.7727
321.35449	0.85644621	0.23857015	2976.5059
322.35547	0.86127788	0.23991735	2975.1257
323.35645	0.86399102	0.24145924	2981.8623
324.35742	0.86699778	0.24302883	2988.0315
325.3584	0.86838239	0.24451424	2980.1287
326.35938	0.87016863	0.2457726	2973.7424
327.36035	0.87361377	0.24730726	2986.3989
328.36133	0.88125086	0.24885653	2993.1023
329.3623	0.88217878	0.25041938	2987.6553
330.36328	0.88352096	0.25176072	2989.7034
331.36426	0.8860631	0.25336006	2983.1643
332.36523	0.88971293	0.25461286	2991.4788
333.36621	0.89058846	0.25599006	2990.6865
334.36719	0.89473867	0.25751755	2986.2837
335.36816	0.89856762	0.25862294	2985.1921
336.36914	0.90463847	0.25988531	2994.6384
337.37012	0.90527076	0.26127294	2995.9329
338.37109	0.90830946	0.2629182	2995.3804
339.37207	0.91378403	0.26432443	3000.1365
340.37305	0.91580594	0.26558653	2998.1199
341.37402	0.9167636	0.26724449	3000.3784
342.375	0.92187291	0.26872656	2998.1528
343.37598	0.92471057	0.27010369	3006.4331
344.37695	0.92771035	0.27146605	3002.4175
345.37793	0.92756057	0.27298382	3000.8069
346.37891	0.93530172	0.27429488	3011.6543
347.37988	0.93600798	0.27571666	3008.9314
348.38086	0.93589878	0.2772947	3004.198
349.38184	0.94204766	0.2788527	3014.7051
350.38281	0.94160467	0.2803961	3005.5151
351.38379	0.94669408	0.28199962	3010.574
352.38477	0.9532786	0.28350621	3013.4941
353.38574	0.95286375	0.28487584	3012.2
354.38672	0.95635396	0.28624728	3011.6575
355.3877	0.9594124	0.28757566	3013.1812
356.38867	0.96176738	0.28918532	3017.9309
357.38965	0.96468455	0.29067209	3014.7368
358.39063	0.96741796	0.29228204	3020.3416
359.3916	0.9702518	0.29383206	3020.9685
360.39258	0.97497797	0.29538366	3020.1204
361.39355	0.97633064	0.29664081	3016.9082
362.39453	0.98222816	0.29794171	3026.4094
363.39551	0.9850505	0.299229	3025.1216
364.39648	0.98460877	0.30058596	3028.3345
365.39746	0.98960167	0.30208963	3024.0029
366.39844	0.99156326	0.30347285	3021.98
367.39941	0.99570143	0.30482176	3028.3674
368.40039	0.99867231	0.30621406	3034.9995
369.40137	1.0033522	0.30777729	3035.8428
370.40234	1.0057701	0.30932233	3035.873
371.40332	1.0069124	0.31079525	3036.5859
372.4043	1.0102469	0.31235459	3034.0178
373.40527	1.017565	0.31390509	3038.4966
374.40625	1.0149665	0.31554443	3036.7412
375.40723	1.0196152	0.31715688	3034.8684
376.4082	1.0224146	0.31882393	3036.7222
377.40918	1.0257486	0.32009286	3035.5461
378.41016	1.0277271	0.32114726	3034.812
379.41113	1.0323794	0.32264569	3043.8291
380.41211	1.0346874	0.32406777	3032.9875
381.41309	1.0374395	0.32543349	3040.3164
382.41406	1.0416631	0.32673174	3040.0151
383.41504	1.0413717	0.3281264	3046.0393
384.41602	1.0448632	0.32971701	3046.8306
385.41699	1.0496576	0.33105704	3046.0281
386.41797	1.05577	0.33256891	3051.5637
387.41895	1.0556512	0.33419803	3054.1333
388.41992	1.0593978	0.33577946	3055.7039
389.4209	1.0634652	0.33682147	3041.0488
390.42188	1.0643076	0.33794752	3044.5723
391.42285	1.0663395	0.33917204	3050.4976
392.42383	1.071931	0.34092578	3065.209
393.4248	1.0739402	0.34254324	3058.9041
394.42578	1.0778743	0.34410509	3060.9929
395.42676	1.0810115	0.3453328	3056.1924
396.42773	1.0842414	0.34700772	3066.7561
397.42871	1.0860852	0.34847981	3055.8413
398.42969	1.0871395	0.34987155	3058.9546
399.43066	1.092773	0.35150495	3066.2891
400.43164	1.0965267	0.35254979	3052.6931
401.43262	1.098559	0.35412192	3070.4998
402.43359	1.1019868	0.35557726	3067.4192
403.43457	1.1058565	0.35685459	3066.0938
404.43555	1.1055666	0.35822684	3063.5583
405.43652	1.1103157	0.35962123	3072.6555
406.4375	1.1133177	0.36114722	3069.1262
407.43848	1.1167272	0.36249787	3068.7542
408.43945	1.1170709	0.36404058	3071.8716
409.44043	1.1237187	0.36550903	3068.7446
410.44141	1.1256102	0.36690372	3070.0579
411.44238	1.126574	0.36852947	3074.489
412.44336	1.1289692	0.37011573	3075.9177
413.44434	1.1311457	0.37130263	3067.9844
414.44531	1.1375346	0.3727715	3074.7129
415.44629	1.1425805	0.37381688	3069.4724
416.44727	1.1448605	0.37521839	3077.22
417.44824	1.1461118	0.37666506	3077.1191
418.44922	1.1503243	0.37790945	3081.6558
419.4502	1.1525258	0.37937015	3079.6494
420.45117	1.1515243	0.38088575	3083.0786
421.45215	1.1579181	0.38260034	3092.9143
422.45313	1.1614535	0.38453531	3084.822
423.4541	1.1665548	0.38598803	3086.8328
424.45508	1.1683022	0.38743418	3086.8674
425.45605	1.1715658	0.38888735	3089.8711
426.45703	1.1721981	0.39011872	3089.5605
427.45801	1.177117	0.39128035	3094.2095
428.45898	1.1808717	0.39273363	3093.3008
429.45996	1.1830131	0.39431012	3091.0396
430.46094	1.1866964	0.39585975	3097.4292
431.46191	1.1870576	0.39720818	3091.1663
432.46289	1.1898985	0.39884502	3095.189
433.46387	1.1944549	0.40028122	3091.178
434.46484	1.1991554	0.40147296	3095.3218
435.46582	1.2021459	0.40334949	3099.7151
436.4668	1.2006743	0.40438783	3095.1838
437.46777	1.202459	0.40560567	3092.7737
438.46875	1.2092302	0.4067933	3097.6682
439.46973	1.213594	0.40820688	3098.6917
440.4707	1.2124771	0.40970233	3098.1423
441.47168	1.2200931	0.41128209	3108.1731
442.47266	1.2224975	0.4127146	3107.5095
443.47363	1.2215632	0.41409704	3103.4072
444.47461	1.2266107	0.4155367	3105.4187
445.47559	1.2290571	0.41711318	3104.0088
446.47656	1.2334791	0.41860512	3105.5188
447.47754	1.2363814	0.42008373	3107.9587
448.47852	1.2394433	0.42156306	3105.2358
449.47949	1.2416817	0.42288738	3105.415
450.48047	1.2447155	0.42417976	3106.748
451.48145	1.24878	0.42538017	3107.3564
452.48242	1.2527798	0.42655855	3113.6379
453.4834	1.2555144	0.42795935	3108.9502
454.48438	1.2579427	0.42918104	3117.4084
455.48535	1.2606519	0.43059137	3113.752
456.48633	1.2666265	0.43214613	3124.4543
457.4873	1.2641162	0.43355367	3111.3535
458.48828	1.2682728	0.43500939	3124.1865
459.48926	1.2741755	0.43656027	3120.6511
460.49023	1.2750978	0.43825018	3123.1978
461.49121	1.2769486	0.44004551	3119.9041
462.49219	1.2798697	0.44132575	3118.1628
463.49316	1.2836015	0.4427419	3121.1228
464.49414	1.2838482	0.44398704	3114.5347
465.49512	1.2891539	0.44530052	3115.1995
466.49609	1.2961698	0.44659212	3125.2891
467.49707	1.2956965	0.44787249	3122.7136
468.49805	1.2996405	0.44938806	3125.084
469.49902	1.301561	0.45094448	3133.7705
470.5	1.3036731	0.45238072	3126.2156
471.50098	1.3051466	0.4537262	3126.0256
472.50195	1.3110818	0.45545912	3131.3411
473.50293	1.3143073	0.45707011	3138.8972
474.50391	1.3177941	0.45839304	3126.2156
475.50488	1.3187875	0.45971522	3123.0857
476.50586	1.3219546	0.46090156	3130.3621
477.50684	1.327213	0.46253464	3133.8684
478.50781	1.3295187	0.46399188	3133.6467
479.50879	1.3318632	0.46530575	3128.0786
480.50977	1.3357072	0.46663341	3139.1206
481.51074	1.3390646	0.46831983	3144.5901
482.51172	1.341194	0.4696551	3135.9888
483.5127	1.3457563	0.47088766	3137.679
484.51367	1.3467578	0.47220871	3134.9194
485.51465	1.3502803	0.47343591	3138.5835
486.51563	1.351787	0.47489333	3134.9224
487.5166	1.3549685	0.47628024	3140.8599
488.51758	1.3561311	0.47764525	3141.7107
489.51855	1.3615301	0.47894338	3143.8372
490.51953	1.364635	0.48031306	3142.6907
491.52051	1.3696355	0.48192301	3144.2908
492.52148	1.3698131	0.48327914	3143.2388
493.52246	1.3720839	0.48470008	3143.4771
494.52344	1.3773637	0.48607022	3150.5198
495.52441	1.3810877	0.4876368	3146.4668
496.52539	1.3825717	0.48907602	3147.3472
497.52637	1.3848976	0.4901959	3142.3059
498.52734	1.390445	0.49156216	3147.613
499.52832	1.392568	0.49295086	3150.6277
500.5293	1.3933291	0.49419177	3150.1228
501.53027	1.400372	0.49565026	3160.4204
502.53125	1.4012027	0.49713466	3155.8557
503.53223	1.4037937	0.49868307	3154.4153
504.5332	1.4057639	0.49996245	3150.4612
505.53418	1.4101919	0.5012688	3154.1272
506.53516	1.4159058	0.50304163	3160.9653
507.53613	1.4160366	0.50450581	3159.9045
508.53711	1.4173315	0.50599456	3156.1455
509.53809	1.4228102	0.50764865	3160.7725
510.53906	1.4243466	0.5091877	3161.0217
511.54004	1.4270669	0.51062644	3156.4492
512.54102	1.4311502	0.51218796	3162.6763
513.54199	1.4358411	0.51340151	3160.1851
514.54297	1.4367442	0.51496977	3165.342
515.54395	1.4400753	0.51634598	3165.5093
516.54492	1.4458448	0.51796299	3162.9612
517.5459	1.4468726	0.51922381	3165.7839
518.54688	1.4467216	0.52037579	3159.1621
519.54785	1.4538758	0.5219146	3172.4504
520.54883	1.4540012	0.52338392	3167.1365
521.5498	1.4567746	0.52519089	3167.9744
522.55078	1.4597681	0.52631152	3167.0503
523.55176	1.4650373	0.5275932	3171.3711
524.55273	1.4714901	0.5290181	3173.0869
525.55371	1.4697903	0.53011221	3170.4575
526.55469	1.4762019	0.53164804	3175.5208
527.55566	1.4763343	0.53286451	3171.7415
528.55664	1.4777771	0.5343411	3170.1943
529.55762	1.4828326	0.53567135	3168.4756
530.55859	1.4861118	0.53730941	3180.7534
531.55957	1.4912881	0.53870851	3174.9011
532.56055	1.4941105	0.53997064	3180.5527
533.56152	1.4921596	0.54141307	3177.688
534.5625	1.4995041	0.54302424	3185.145
535.56348	1.5022006	0.54448777	3177.4958
536.56445	1.5047189	0.54592597	3181.292
537.56543	1.5076693	0.54740757	3180.4861
538.56641	1.5079806	0.54891729	3179.7886
539.56738	1.5130719	0.55031592	3183.5178
540.56836	1.518108	0.55198574	3185.8923
541.56934	1.5191853	0.55348629	3177.9875
542.57031	1.5194887	0.5548529	3182.6758
543.57129	1.5270236	0.55631369	3191.9692
544.57227	1.5238621	0.5579353	3185.2671
545.57324	1.5324037	0.55937368	3191.9404
546.57422	1.535082	0.56078917	3187.6538
547.5752	1.5352793	0.56220549	3188.5549
548.57617	1.5365648	0.56349438	3182.769
549.57715	1.5432835	0.56471461	3186.0188
550.57813	1.5458446	0.56597644	3196.3171
551.5791	1.5470088	0.56769204	3194.2346
552.58008	1.5515804	0.56921232	3187.981
553.58105	1.5544922	0.5706085	3191.6563
554.58203	1.5571601	0.57211858	3194.5579
555.58301	1.5595804	0.5737589	3195.4414
556.58398	1.5622101	0.57506907	3187.9324
557.58496	1.5668091	0.57621813	3185.5278
558.58594	1.5695416	0.57761222	3189.6995
559.58691	1.573337	0.57889771	3196.6904
560.58789	1.5747113	0.58021408	3198.2922
561.58887	1.575308	0.58179295	3196.4629
562.58984	1.5808762	0.58321178	3194.2856
563.59082	1.583805	0.58458793	3196.9675
564.5918	1.5895267	0.58597183	3198.5874
565.59277	1.5935165	0.5874728	3198.5481
566.59375	1.5915068	0.58873916	3202.3906
567.59473	1.599781	0.59022087	3206.3376
568.5957	1.5986581	0.59166032	3204.793
569.59668	1.5994999	0.59332925	3201.7163
570.59766	1.6067946	0.59494346	3212.9775
571.59863	1.6071548	0.59622335	3199.0076
572.59961	1.6084698	0.59759295	3197.3
573.60059	1.6165923	0.59889334	3207.0691
574.60156	1.6177819	0.60004967	3204.5425
575.60254	1.6188226	0.60192293	3208.4438
576.60352	1.6251662	0.60345972	3210.9309
577.60449	1.626353	0.60500783	3205.5217
578.60547	1.628274	0.60650551	3208.2307
579.60645	1.6321023	0.60812116	3214.8835
580.60742	1.6366158	0.60983372	3211.9016
581.6084	1.6378267	0.6111396	3212.4795
582.60938	1.6428778	0.61269951	3212.521
583.61035	1.6444415	0.61417723	3211.3799
584.61133	1.6478109	0.61545074	3207.1323
585.6123	1.650558	0.61680549	3214.0461
586.61328	1.6544075	0.61835784	3210.6238
587.61426	1.6579754	0.61976594	3212.5713
588.61523	1.658462	0.62088704	3206.886
589.61621	1.662964	0.62226599	3217.8262
590.61719	1.6656747	0.62390631	3224.5049
591.61816	1.6688498	0.62525743	3211.9333
592.61914	1.669634	0.6266734	3217.0552
593.62012	1.6747918	0.62816417	3213.4309
594.62109	1.6784008	0.629403	3216.3557
595.62207	1.6811112	0.63069177	3222.3252
596.62305	1.6823213	0.63203442	3215.0273
597.62402	1.686759	0.63365108	3225.1748
598.625	1.6911799	0.63516259	3222.6672
599.62598	1.6934134	0.63662297	3223.1646
600.62695	1.6931347	0.63821089	3223.1565
601.62793	1.6969393	0.63976699	3217.926
602.62891	1.7008029	0.64118516	3220.5977
603.62988	1.7060074	0.64251363	3224.5964
604.63086	1.7072103	0.64395481	3222.8367
605.63184	1.7103645	0.64528495	3222.7324
606.63281	1.7135172	0.64676088	3227.9763
607.63379	1.7146357	0.64870948	3228.2986
608.63477	1.7210549	0.65010595	3226.9768
609.63574	1.7206842	0.65133661	3223.3054
610.63672	1.723835	0.65321547	3230.6228
611.6377	1.7318155	0.65483487	3228.3396
612.63867	1.7320285	0.65605015	3229.4041
613.63965	1.7336445	0.65728748	3224.1438
614.64063	1.7378445	0.65866983	3230.5857
615.6416	1.7395672	0.66010112	3226.959
616.64258	1.7436043	0.66176897	3231.9614
617.64355	1.7481266	0.66347218	3233.9265
618.64453	1.7477087	0.6652301	3236.0454
619.64551	1.7544738	0.66686213	3230.3879
620.64648	1.7554843	0.66826117	3232.0537
621.64746	1.7586024	0.66991341	3233.0754
622.64844	1.7639908	0.67117244	3232.2307
623.64941	1.7650843	0.67231733	3227.8823
624.65039	1.764629	0.67386496	3233.4844
625.65137	1.7697439	0.67539042	3232.9785
626.65234	1.7738218	0.67701072	3236.498
627.65332	1.7764068	0.67857736	3240.7888
628.6543	1.7778417	0.68008107	3232.2368
629.65527	1.7852262	0.68149799	3236.9478
630.65625	1.7844085	0.68279815	3237.3391
631.65723	1.7889951	0.6843155	3235.6941
632.6582	1.7903148	0.68575251	3242.5386
633.65918	1.7941878	0.68750036	3238.4209
634.66016	1.798394	0.68889546	3239.136
635.66113	1.8003017	0.69014442	3237.6365
636.66211	1.8009901	0.69171745	3239.0955
637.66309	1.8063424	0.69325399	3245.7729
638.66406	1.8062447	0.69491214	3238.8779
639.66504	1.8128288	0.69648033	3243.7063
640.66602	1.8180056	0.69832331	3249.4216
641.66699	1.8182149	0.69986117	3239.0703
642.66797	1.8238755	0.7014814	3246.2476
643.66895	1.8265681	0.70275527	3247.105
644.66992	1.8282086	0.70397359	3243.5127
645.6709	1.8304205	0.70564389	3245.1238
646.67188	1.8341665	0.70710272	3250.5088
647.67285	1.8365848	0.70907241	3258.009
648.67383	1.838354	0.71061337	3243.0542
649.6748	1.8450918	0.71227252	3243.9082
650.67578	1.8485354	0.71373069	3249.7478
651.67676	1.8498492	0.71511745	3246.1533
652.67773	1.8504589	0.71685809	3253.8303
653.67871	1.8535525	0.71849847	3247.9121
654.67969	1.8572372	0.72008932	3244.293
655.68066	1.860878	0.72153699	3249.9133
656.68164	1.8666683	0.72315788	3252.2471
657.68262	1.867089	0.72445995	3247.8096
658.68359	1.870248	0.72573715	3249.0598
659.68457	1.8727342	0.72727102	3253.3909
660.68555	1.8760582	0.72886181	3257.1187
661.68652	1.8780284	0.73043579	3252.1785
662.6875	1.8812616	0.73185158	3248.8777
663.68848	1.8831627	0.7331636	3248.3457
664.68945	1.8865174	0.73463631	3258.7415
665.69043	1.8895731	0.73617417	3254.0037
666.69141	1.895354	0.73753572	3253.8062
667.69238	1.8972718	0.73904097	3259.3379
668.69336	1.9001851	0.74093688	3262.0613
669.69434	1.9026062	0.74277115	3262.6216
670.69531	1.9044843	0.74437732	3251.7546
671.69629	1.9082592	0.74562854	3254.6484
672.69727	1.9111866	0.74708974	3260.5381
673.69824	1.9175143	0.74861425	3259.8574
674.69922	1.9213116	0.7503646	3259.7412
675.7002	1.917555	0.75194967	3256.9854
676.70117	1.9234768	0.75346613	3256.1125
677.70215	1.9270909	0.75512469	3260.3877
678.70313	1.9320098	0.75682336	3263.9656
679.7041	1.9312344	0.75836533	3266.1438
680.70508	1.9341146	0.75984663	3258.4136
681.70605	1.9406953	0.76156265	3265.6421
682.70703	1.9444289	0.76334286	3269.8264
683.70801	1.9437373	0.76495063	3261.3928
684.70898	1.9449553	0.76671606	3259.2585
685.70996	1.9497215	0.76827532	3266.2471
686.71094	1.9515585	0.76987404	3265.4797
687.71191	1.9562231	0.77158284	3258.8706
688.71289	1.958554	0.77312845	3260.5391
689.71387	1.96665	0.7746231	3261.9727
690.71484	1.9665135	0.77604222	3273.3406
691.71582	1.9699528	0.77759546	3262.6438
692.7168	1.9730638	0.77907556	3267.2603
693.71777	1.975682	0.78068537	3263.1536
694.71875	1.977562	0.78200388	3263.1267
695.71973	1.9795377	0.7835834	3270.5308
696.7207	1.9816502	0.78544289	3267.8013
697.72168	1.9871572	0.78704453	3272.249
698.72266	1.9889125	0.78883833	3267.0645
699.72363	1.9917001	0.79047549	3266.7808
700.72461	1.9974028	0.79216743	3264.9751
701.72559	1.9988869	0.79379046	3265.0891
702.72656	2.0045037	0.79513705	3271.4919
703.72754	2.0070574	0.7967149	3274.1536
704.72852	2.0072122	0.79840422	3277.1421
705.72949	2.0069838	0.80010235	3271.2698
706.73047	2.0131998	0.8015793	3271.6235
707.73145	2.0174148	0.80304599	3276.7515
708.73242	2.0216827	0.80489433	3272.2605
709.7334	2.0231869	0.80638802	3270.187
710.73438	2.0272844	0.80826491	3279.009
711.73535	2.0271292	0.81000119	3275.0532
712.73633	2.0354009	0.81192118	3279.2083
713.7373	2.0350494	0.81375223	3281.5061
714.73828	2.0323691	0.8151632	3262.7727
715.73926	2.0404556	0.81673926	3273.1528
716.74023	2.0425057	0.81819254	3275.1406
717.74121	2.047106	0.81995517	3281.5288
718.74219	2.0507183	0.82140207	3271.698
719.74316	2.0506272	0.8228628	3275.8545
720.74414	2.0573268	0.82472616	3279.2581
721.74512	2.0606833	0.82637542	3279.2446
722.74609	2.0609059	0.82813102	3272.6008
723.74707	2.0649793	0.82962179	3274.9792
724.74805	2.0678806	0.83120787	3277.283
725.74902	2.0698833	0.83283997	3276.948
726.75	2.0758557	0.83483398	3285.2371
727.75098	2.0769205	0.83662856	3277.9006
728.75195	2.0816901	0.83841687	3280.3955
729.75293	2.0824425	0.84030944	3275.3083
730.75391	2.0847776	0.84182876	3280.2676
731.75488	2.0900149	0.84369671	3283.2024
732.75586	2.0918849	0.84564275	3284.2778
733.75684	2.095046	0.84753853	3279.6631
734.75781	2.0994315	0.84916747	3277.6785
735.75879	2.1013241	0.85064077	3276.5313
736.75977	2.1036215	0.85222429	3277.2209
737.76074	2.1052988	0.8538475	3279.3975
738.76172	2.1120913	0.85528278	3281.3418
739.7627	2.1119788	0.85688144	3278.9995
740.76367	2.1175041	0.85880035	3277.5261
741.76465	2.116498	0.86033362	3285.2297
742.76563	2.1234834	0.86222047	3291.9553
743.7666	2.1257827	0.86368459	3278.8035
744.76758	2.1262665	0.86511689	3280.7434
745.76855	2.1283777	0.86646527	3282.2395
746.76953	2.1363235	0.86825609	3285.6001
747.77051	2.1366308	0.87023914	3286.0588
748.77148	2.1386411	0.87179911	3279.4692
749.77246	2.1433184	0.87346506	3283.0513
750.77344	2.145601	0.87523723	3285.7212
751.77441	2.1506214	0.87700301	3288.041
752.77539	2.1516368	0.87885374	3288.2141
753.77637	2.1541195	0.88057995	3284.4988
754.77734	2.1581378	0.8823871	3282.709
755.77832	2.1600599	0.8841626	3283.3057
756.7793	2.1641033	0.88610047	3288.1948
757.78027	2.1640666	0.88810301	3284.6128
758.78125	2.1694937	0.88980478	3284.4492
759.78223	2.1739271	0.89128143	3286.1633
760.7832	2.1729898	0.89273852	3279.9224
761.78418	2.1794202	0.89459705	3293.9553
762.78516	2.182421	0.89649886	3287.4497
763.78613	2.1830807	0.89817935	3285.9099
764.78711	2.1891227	0.89993775	3288.4324
765.78809	2.1905854	0.90193355	3295.9473
766.78906	2.1943309	0.90378124	3289.6851
767.79004	2.1995485	0.90551561	3289.4814
768.79102	2.1995952	0.90713638	3286.1858
769.79199	2.2022796	0.90868235	3281.2944
770.79297	2.2059245	0.91031736	3290.2195
771.79395	2.2092326	0.91221261	3292.3071
772.79492	2.2110908	0.91408461	3288.6824
773.7959	2.2135894	0.91599089	3290.4063
774.79688	2.2163439	0.91812998	3292.3755
775.79785	2.2202027	0.92015696	3283.4761
776.79883	2.2243202	0.92199206	3289.6687
777.7998	2.2271237	0.92374307	3290.0781
778.80078	2.231622	0.92544204	3284.9277
779.80176	2.234694	0.92692834	3285.8979
780.80273	2.2378376	0.92860705	3290.9524
781.80371	2.2405398	0.93063658	3296.8872
782.80469	2.2427666	0.93234241	3292.0742
783.80566	2.244951	0.93394196	3293.3809
784.80664	2.2465384	0.93564963	3289.5315
785.80762	2.2522223	0.93738812	3294.1396
786.80859	2.256331	0.93921548	3295.3032
787.80957	2.2566659	0.94136184	3293.5229
788.81055	2.2601798	0.94335574	3295.2979
789.81152	2.2628977	0.94549507	3292.5493
790.8125	2.2663543	0.94739562	3294.2427
791.81348	2.2691605	0.949449	3292.4507
792.81445	2.2724969	0.9514606	3290.1267
793.81543	2.2775347	0.95296228	3288.9717
794.81641	2.278373	0.95463485	3295.0745
795.81738	2.2803853	0.95650446	3297.9929
796.81836	2.2866886	0.9584235	3294.6904
797.81934	2.2858403	0.96018809	3290.4727
798.82031	2.290679	0.96189129	3294.134
799.82129	2.2938044	0.96405536	3297.2773
800.82227	2.2980549	0.96614802	3296.8335
801.82324	2.2990587	0.96846253	3291.4141
802.82422	2.3038278	0.97028029	3290.9495
803.8252	2.3067751	0.97199976	3287.9414
804.82617	2.3095169	0.9737817	3292.7263
805.82715	2.3133957	0.97561413	3295.9043
806.82813	2.3144801	0.97756356	3289.6416
807.8291	2.316726	0.9792245	3291.8076
808.83008	2.3202758	0.98097193	3296.8967
809.83105	2.3252687	0.98253638	3293.8904
810.83203	2.327075	0.98443484	3291.6436
811.83301	2.3268936	0.98628569	3295.2393
812.83398	2.3338799	0.98826879	3294.7925
813.83496	2.3371432	0.99011517	3289.7144
814.83594	2.3378026	0.99183804	3295.7607
815.83691	2.342566	0.99406022	3293.7029
816.83789	2.3440657	0.99635613	3297.8167
817.83887	2.3476355	0.99843025	3293.2864
818.83984	2.3511322	1.000509	3296.1462
819.84082	2.3520019	1.0027802	3300.9507
820.8418	2.3597362	1.0049528	3295.2351
821.84277	2.3594954	1.0066968	3289.9763
822.84375	2.3618817	1.0082464	3287.8159
823.84473	2.3655722	1.0098052	3291.2578
824.8457	2.370476	1.0119821	3303.3994
825.84668	2.3704829	1.0143178	3296.7407
826.84766	2.37661	1.0165211	3294.5754
827.84863	2.3783307	1.0184139	3289.6863
828.84961	2.3811567	1.0202292	3295.9431
829.85059	2.3845339	1.0223488	3294.0007
830.85156	2.3847306	1.0241293	3287.0835
831.85254	2.3889809	1.0260754	3291.9858
832.85352	2.3933992	1.0284271	3299.2815
833.85449	2.3960388	1.0304226	3293.7866
834.85547	2.3994577	1.0325958	3290.2029
835.85645	2.4014277	1.0345725	3298.4551
836.85742	2.4028838	1.0366752	3296.2498
837.8584	2.4081736	1.0390255	3294.3577
838.85938	2.4117053	1.0407928	3297.0481
839.86035	2.4134672	1.0427134	3295.1973
840.86133	2.4168611	1.0446244	3294.7651
841.8623	2.4179912	1.0466317	3289.6245
842.86328	2.4227073	1.0486521	3292.3796
843.86426	2.4257233	1.0508178	3297.4685
844.86523	2.4275403	1.0530785	3292.802
845.86621	2.4326069	1.0554646	3292.5881
846.86719	2.4371207	1.0574526	3296.8711
847.86816	2.4378479	1.0593872	3298.2744
848.86914	2.4424875	1.0618006	3299.5891
849.87012	2.443285	1.0639601	3296.0999
850.87109	2.4491782	1.0661514	3294.7588
851.87207	2.4493539	1.0684814	3298.2117
852.87305	2.4563539	1.0709496	3294.9717
853.87402	2.4577687	1.0731019	3296.8132
854.875	2.4566894	1.0751855	3290.9409
855.87598	2.4603148	1.07696	3283.9895
856.87695	2.4646246	1.0788156	3293.5093
857.87793	2.4687688	1.0808276	3291.2976
858.87891	2.4701955	1.0827383	3288.606
859.87988	2.4719033	1.0850097	3291.0708
860.88086	2.4775608	1.0875455	3291.9478
861.88184	2.4809718	1.0900877	3298.8662
862.88281	2.4808345	1.0923071	3290.0078
863.88379	2.4885106	1.0947262	3295.4592
864.88477	2.4882679	1.0966823	3288.0715
865.88574	2.4910672	1.0988555	3288.1787
866.88672	2.4945631	1.1009816	3296.74
867.8877	2.4981716	1.1032995	3297.0549
868.88867	2.5017166	1.1057026	3300.6938
869.88965	2.5024197	1.1077132	3286.5813
870.89063	2.5048149	1.110073	3290.3999
871.8916	2.5099511	1.1126325	3291.583
872.89258	2.5141525	1.1151339	3290.9131
873.89355	2.5158103	1.1175194	3287.6838
874.89453	2.5177114	1.1198936	3289.509
875.89551	2.5209036	1.1221626	3285.2632
876.89648	2.5259013	1.1242607	3283.3311
877.89746	2.5280225	1.1262778	3291.4753
878.89844	2.5303335	1.1284543	3289.6458
879.89941	2.5341368	1.1306992	3285.0151
880.90039	2.5348382	1.1325734	3279.1331
881.90137	2.5399632	1.1343105	3284.1021
882.90234	2.5442069	1.1364731	3292.0132
883.90332	2.5470788	1.1392721	3295.052
884.9043	2.5467474	1.1415064	3284.9785
885.90527	2.5514848	1.143922	3285.0762
886.90625	2.5549524	1.1461627	3284.3081
887.90723	2.5549383	1.1481465	3283.605
888.9082	2.5624974	1.1503638	3287.6685
889.90918	2.5622907	1.1529489	3287.4277
890.91016	2.5656896	1.1556641	3282.6279
891.91113	2.5705996	1.1578904	3282.6335
892.91211	2.5718193	1.1605136	3287.6047
893.91309	2.5770741	1.1630301	3285.6938
894.91406	2.5780358	1.165089	3278.0581
895.91504	2.5822356	1.1671418	3275.1204
896.91602	2.5843506	1.1693476	3287.7554
897.91699	2.5886724	1.1718889	3277.6489
898.91797	2.5902023	1.1742455	3281.9011
899.91895	2.5933142	1.1766846	3285.3772
900.91992	2.5987656	1.1796148	3287.2803
901.9209	2.5996306	1.1823655	3279.1082
902.92188	2.601697	1.1847049	3276.3523
903.92285	2.6083114	1.1871024	3278.678
904.92383	2.6076944	1.1897775	3279.4868
905.9248	2.6110637	1.1922491	3277.2124
906.92578	2.6137054	1.1947563	3277.4836
907.92676	2.6183753	1.1972219	3277.5464
908.92773	2.6212449	1.1995797	3274.8064
909.92871	2.6250596	1.2019506	3278.4177
910.92969	2.6247797	1.2041478	3270.8367
911.93066	2.6312118	1.2065444	3281.3223
912.93164	2.6322207	1.2089274	3276.196
913.93262	2.637538	1.2116131	3277.7607
914.93359	2.6399248	1.2144305	3281.1135
915.93457	2.6397202	1.2169263	3270.3159
916.93555	2.6453106	1.2198536	3266.554
917.93652	2.647367	1.2222388	3267.8179
918.9375	2.6504943	1.2247694	3266.429
919.93848	2.6538107	1.2272696	3272.5835
920.93945	2.6576395	1.2296748	3268.3015
921.94043	2.6596575	1.2324311	3268.8801
922.94141	2.6637199	1.2350693	3267.0901
923.94238	2.66728	1.237422	3263.8958
924.94336	2.6668062	1.2394332	3263.5493
925.94434	2.6710887	1.2422291	3266.5862
926.94531	2.6747098	1.2453288	3270.8716
927.94629	2.6789832	1.2478765	3265.5857
928.94727	2.681494	1.2503229	3259.1704
929.94824	2.685643	1.2530516	3260.5745
930.94922	2.6870334	1.2556645	3267.4639
931.9502	2.6895995	1.2585523	3262.5581
932.95117	2.692631	1.261201	3265.7004
933.95215	2.695076	1.2641305	3258.3738
934.95313	2.6972697	1.2665691	3254.4731
935.9541	2.7038949	1.2695076	3261.0659
936.95508	2.7050738	1.2719994	3257.5364
937.95605	2.7085788	1.2745527	3252.2651
938.95703	2.7120922	1.2767168	3253.4136
939.95801	2.7134285	1.2790146	3253.0576
940.95898	2.7150698	1.2812005	3248.647
941.95996	2.7206738	1.2840815	3257.2925
942.96094	2.7205544	1.2869588	3254.7742
943.96191	2.7273431	1.2898124	3251.98
944.96289	2.7289388	1.2926039	3243.7114
945.96387	2.7307496	1.2952719	3241.6987
946.96484	2.7365031	1.2977594	3250.5227
947.96582	2.7377057	1.3002063	3247.0586
948.9668	2.7402451	1.303014	3245.3931
949.96777	2.742924	1.3061789	3245.6133
950.96875	2.7478588	1.3086193	3238.0085
951.96973	2.7491064	1.3117054	3246.0522
952.9707	2.7541294	1.3149556	3244.9089
953.97168	2.758985	1.3175212	3239.8472
954.97266	2.7576399	1.3199127	3230.7285
955.97363	2.7591646	1.322234	3235.302
956.97461	2.7654314	1.325158	3242.5225
957.97559	2.7691412	1.328271	3237.6746
958.97656	2.7716279	1.3313527	3235.1089
959.97754	2.7717297	1.3344127	3232.5586
960.97852	2.7746441	1.3372954	3229.991
961.97949	2.7800386	1.3401963	3227.1572
962.98047	2.7806156	1.3422992	3219.8972
963.98145	2.7837238	1.3445445	3222.259
964.98242	2.7879581	1.3469539	3225.6394
965.9834	2.7899981	1.3497216	3227.3169
966.98438	2.7976749	1.3527802	3225.9585
967.98535	2.7978351	1.355749	3224.5188
968.98633	2.7981701	1.3585198	3222.7554
969.9873	2.8030553	1.3616447	3220.0127
970.98828	2.8081055	1.3648361	3216.907
971.98926	2.8115518	1.3676499	3215.7212
972.99023	2.8119953	1.370227	3214.7109
973.99121	2.8164535	1.3729756	3212.1819
974.99219	2.8174767	1.3757837	3210.9468
975.99316	2.8226731	1.3787652	3216.5918
976.99414	2.8243639	1.3820475	3211.8867
977.99512	2.827832	1.3851527	3209.5286
978.99609	2.8298805	1.3877358	3200.3081
979.99707	2.8340392	1.3902854	3206.3538
980.99805	2.8379443	1.3929437	3204.4712
981.99902	2.8403649	1.3958991	3199.9927
983	2.8436007	1.3990504	3206.1484
984.00098	2.8457968	1.4023219	3198.2312
985.00195	2.8507729	1.4055625	3198.8601
986.00293	2.8491614	1.4086887	3194.5564
987.00391	2.8556688	1.4114627	3190.1199
988.00488	2.8607361	1.4137888	3185.9348
989.00586	2.8594427	1.4158784	3187.1877
990.00684	2.8648272	1.4187086	3194.4976
991.00781	2.8669641	1.4214922	3185.1804
992.00879	2.8696308	1.4242133	3182.6638
993.00977	2.8740046	1.4272039	3189.9023
994.01074	2.8777342	1.4306058	3189.0337
995.01172	2.8774605	1.4342508	3182.7415
996.0127	2.8828793	1.4377826	3179.7249
997.01367	2.8833756	1.4407877	3168.0173
998.01465	2.8865864	1.4437462	3175.4731
999.01563	2.8923583	1.4466929	3172.5205
1000.0166	2.8932312	1.4491237	3162.8772
1001.0176	2.8963614	1.4516308	3166.0862
1002.0186	2.9017045	1.4539328	3167.4529
1003.0195	2.9028141	1.4564058	3162.0032
1004.0205	2.9061468	1.4590858	3164.9441
1005.0215	2.9118032	1.462379	3166.1489
1006.0225	2.9115486	1.465628	3157.6475
1007.0234	2.9131923	1.4685664	3155.2847
1008.0244	2.9181621	1.4717518	3155.4629
1009.0254	2.9204412	1.4746997	3152.0015
1010.0264	2.9216251	1.477614	3151.5181
1011.0273	2.9267538	1.4809649	3153.3936
1012.0283	2.9313617	1.4839671	3146.9946
1013.0293	2.9319851	1.4865454	3142.8369
1014.0303	2.9345994	1.489462	3138.9858
1015.0313	2.9347649	1.4923253	3141.0762
1016.0322	2.9423051	1.4951202	3137.8896
1017.0332	2.9453161	1.498114	3134.6169
1018.0342	2.9483368	1.5010357	3137.0303
1019.0352	2.9483464	1.5044961	3126.2676
1020.0361	2.9527638	1.5078417	3130.3252
1021.0371	2.9573936	1.5111542	3129.2241
1022.0381	2.9622102	1.5144839	3128.5977
1023.0391	2.9665999	1.5174998	3119.7422
1024.04	2.9673097	1.520394	3120.4719
1025.041	2.9711916	1.5234226	3125.3787
1026.042	2.9715672	1.5266452	3113.2378
1027.043	2.9748106	1.5290837	3106.814
1028.0439	2.9744813	1.5320972	3117.051
1029.0449	2.9797087	1.535025	3105.875
1030.0459	2.9809253	1.5380489	3106.5984
1031.0469	2.9869883	1.541036	3101.2839
1032.0479	2.9889829	1.5438447	3097.3943
1033.0488	2.9944336	1.5467142	3093.2996
1034.0498	2.9943435	1.5492204	3092.3457
1035.0508	3.0007083	1.5510509	3091.5913
1036.0518	3.0014858	1.5530696	3083.5178
1037.0527	3.0065444	1.5553696	3092.8323
1038.0537	3.0095766	1.5583167	3089.9539
1039.0547	3.0118055	1.5620182	3091.6624
1040.0557	3.0135133	1.5654576	3082.1296
1041.0566	3.0179751	1.5687429	3083.0364
1042.0576	3.0218828	1.5721153	3078.6904
1043.0586	3.0223722	1.5755342	3075.7969
1044.0596	3.0270121	1.5788598	3070.7449
1045.0605	3.0274405	1.5821449	3066.489
1046.0615	3.0329552	1.5858178	3067.6887
1047.0625	3.0341434	1.5891044	3062.085
1048.0635	3.0382195	1.5921948	3060.6704
1049.0645	3.0404572	1.5950046	3059.7634
1050.0654	3.0451646	1.598043	3058.2058
1051.0664	3.0451589	1.6011795	3052.5344
1052.0674	3.0491648	1.6042356	3049.3125
1053.0684	3.0539465	1.6074129	3043.9966
1054.0693	3.0540385	1.6107186	3042.6436
1055.0703	3.0588584	1.6139978	3036.0366
1056.0713	3.0618451	1.6170801	3034.0579
1057.0723	3.0668108	1.6205579	3033.9407
1058.0732	3.0683606	1.6240101	3029.7937
1059.0742	3.0726991	1.6269031	3025.0869
1060.0752	3.0763543	1.6298811	3026.8589
1061.0762	3.0770998	1.6331331	3018.7686
1062.0771	3.0803056	1.6364553	3022.3687
1063.0781	3.0813329	1.6398417	3016.365
1064.0791	3.0864449	1.643674	3009.3386
1065.0801	3.0910048	1.6469649	3009.3931
1066.0811	3.0921121	1.649701	3005.0952
1067.082	3.0953031	1.6524038	3000.7571
1068.083	3.0976253	1.6553986	3000.3435
1069.084	3.0999622	1.6588578	2997.7595
1070.085	3.103282	1.6618878	2993.5005
1071.0859	3.1074989	1.6650835	2990.6475
1072.0869	3.1115294	1.6686206	2988.6294
1073.0879	3.1142895	1.6715876	2975
1074.0889	3.1162829	1.6740444	2975.0742
1075.0898	3.1199317	1.6771889	2977.0867
1076.0908	3.1221607	1.6810329	2973.6177
1077.0918	3.1254923	1.6849133	2965.2383
1078.0928	3.1294882	1.6884283	2966.8303
1079.0938	3.1304455	1.6916654	2959.9666
1080.0947	3.1332991	1.6949635	2955.8843
1081.0957	3.1380951	1.6989738	2947.7878
1082.0967	3.1385856	1.7019323	2947.8716
1083.0977	3.1455784	1.7054213	2945.8816
1084.0986	3.1464016	1.7087338	2941.3792
1085.0996	3.1451135	1.7121912	2938.1389
1086.1006	3.1513364	1.7158281	2929.6267
1087.1016	3.1556761	1.7194378	2924.823
1088.1025	3.1556928	1.7225502	2917.7847
1089.1035	3.1614506	1.7261451	2916.6208
1090.1045	3.1620922	1.7294084	2916.7097
1091.1055	3.1678438	1.7325336	2911.5737
1092.1064	3.17102	1.7359335	2906.5872
1093.1074	3.1736038	1.7387326	2901.7561
1094.1084	3.1768084	1.7415316	2896.5349
1095.1094	3.1788573	1.7442167	2896.9546
1096.1104	3.1806049	1.7475005	2892.0125
1097.1113	3.1872618	1.7510763	2889.8674
1098.1123	3.1902916	1.754403	2878.7573
1099.1133	3.1911011	1.7578652	2876.3206
1100.1143	3.1939454	1.7614491	2870.1519
1101.1152	3.1986308	1.7647675	2867.4543
1102.1162	3.2033341	1.7684722	2871.1401
1103.1172	3.2050729	1.7718703	2854.7273
1104.1182	3.2085354	1.7750485	2858.7534
1105.1191	3.2104652	1.7781856	2854.3301
1106.1201	3.2127347	1.7817447	2851.5469
1107.1211	3.218725	1.785507	2843.0024
1108.1221	3.2184372	1.7888728	2838.2244
1109.123	3.2206893	1.7916812	2827.8877
1110.124	3.2235227	1.795218	2823.7749
1111.125	3.2272999	1.7989221	2821.4336
1112.126	3.2320557	1.8020166	2816.991
1113.127	3.2350168	1.8054341	2813.6294
1114.1279	3.2378011	1.8093122	2815.1328
1115.1289	3.2432778	1.8133714	2802.8438
1116.1299	3.2464299	1.8166581	2796.1885
1117.1309	3.2445254	1.8203701	2791.6809
1118.1318	3.2488661	1.8239501	2787.0247
1119.1328	3.249717	1.8271122	2777.1887
1120.1338	3.2549415	1.8305397	2781.436
1121.1348	3.2582815	1.8343549	2767.2722
1122.1357	3.2597058	1.8381684	2766.1897
1123.1367	3.261657	1.8417435	2750.2097
1124.1377	3.2662528	1.844997	2746.1619
1125.1387	3.2691514	1.8484596	2744.5413
1126.1396	3.2738569	1.8517457	2743.127
1127.1406	3.2742915	1.855341	2729.7214
1128.1416	3.2800858	1.8586357	2727.2766
1129.1426	3.2838955	1.8622036	2724.1038
1130.1436	3.2837782	1.8658712	2712.2747
1131.1445	3.2859583	1.8692402	2702.606
1132.1455	3.2877233	1.8724741	2698.2756
1133.1465	3.2949009	1.875399	2698.7639
1134.1475	3.2978344	1.8783389	2693.7712
1135.1484	3.3026881	1.8819923	2690.7292
1136.1494	3.3021545	1.8864044	2676.0984
1137.1504	3.308676	1.8903584	2670.7671
1138.1514	3.3091254	1.8938215	2664.4512
1139.1523	3.3132255	1.8976657	2663.437
1140.1533	3.3128657	1.9020212	2656.1162
1141.1543	3.31777	1.906487	2638.6057
1142.1553	3.3224733	1.9097253	2632.385
1143.1563	3.3213041	1.9129858	2626.1211
1144.1572	3.3267972	1.9169598	2621.3867
1145.1582	3.3289709	1.9205418	2610.9802
1146.1592	3.3332279	1.9240305	2603.5593
1147.1602	3.3365898	1.927533	2596.4607
1148.1611	3.3387113	1.9313529	2591.1438
1149.1621	3.3444896	1.9344965	2585.3997
1150.1631	3.344986	1.9383336	2574.2361
1151.1641	3.3470016	1.9420688	2562.1016
1152.165	3.353209	1.9473968	2538.9175
1152.3652	3.3527095	1.9505637	2511.9202