File: datasets/am_bench_2022/raw_data/45-XY.08-3/specimen.dat
MTS793|MPT|ENU|1|2|.|/|:|1|0|0|A

Operator Information						Time:	35.255371	Sec	10/19/2021 1:25:29 PM
Operator	Newell Moser
Project	AM Bench 2022 mini-tensile challenge
Specimen ID	45-XY.08-3
Material	PBF-L Inconel 625
Specimen Width	2.55	mm
Specimen Thickness	1.52	mm
Notes
Operator Information End

Data Acquisition						Time:	1036.2502	Sec	10/19/2021 1:42:10 PM
Time	Axial Displacement	Axial Extensometer	Axial Force
Sec	mm	mm	N
35.369629	0.0014434549	8.6363172e-05	44.736378
36.370605	0.00056180905	0.00022209728	53.553226
37.371582	0.0039231991	0.00014682137	65.673424
38.372559	0.010568786	0.00020367451	76.786392
39.373535	0.011358846	0.00038380851	92.349243
40.374512	0.013929152	0.00037953857	102.19149
41.375488	0.01599732	0.00039936791	111.76138
42.376465	0.020919723	0.00045117564	127.31248
43.377441	0.023063703	0.00049283716	138.35783
44.378418	0.026270451	0.00053229503	152.53281
45.379395	0.031597309	0.00052838575	167.28014
46.380371	0.033554632	0.00063961593	181.01358
47.381348	0.036301553	0.00065856834	199.75879
48.382324	0.040625729	0.00065064721	220.43172
49.383301	0.041646291	0.00072076399	231.97078
50.384277	0.043754976	0.00071796519	252.82454
51.385254	0.046419378	0.00082880096	274.23276
52.38623	0.050555665	0.00093124236	296.63373
53.387207	0.053498924	0.0009029592	317.35233
54.388184	0.05311086	0.00096337229	340.56122
55.38916	0.057847224	0.0011331839	371.13391
56.390137	0.062458243	0.0010828227	386.75162
57.391113	0.063119628	0.0010451351	406.3429
58.39209	0.069716662	0.0012784301	438.27832
59.393066	0.071014591	0.0011829683	454.90982
60.394043	0.07276088	0.0014095008	480.0498
61.39502	0.075297579	0.0013487312	494.7142
62.395996	0.082549438	0.001453827	525.36316
63.396973	0.082547188	0.0016015349	547.96295
64.397949	0.085547149	0.0015122895	570.34753
65.398926	0.087686978	0.0016779009	601.66241
66.399902	0.091641173	0.0016109763	620.23193
67.400879	0.092804544	0.0016927719	643.48303
68.401855	0.095993616	0.0017563526	665.19836
69.402832	0.097828776	0.0017949417	688.94373
70.403809	0.10310446	0.0019165016	717.8385
71.404785	0.10563425	0.0019608522	741.73199
72.405762	0.10980844	0.0020744305	776.50891
73.406738	0.11552623	0.0020625715	802.37256
74.407715	0.11319011	0.0020064691	818.80725
75.408691	0.1178958	0.0022391279	854.92566
76.409668	0.11936712	0.0022385912	883.45258
77.410645	0.12469582	0.0025243987	917.8382
78.411621	0.12791891	0.0024322593	938.90668
79.412598	0.13059765	0.0025113267	963.02417
80.413574	0.13198887	0.0026113412	993.23914
81.414551	0.13499497	0.0027760386	1019.5495
82.415527	0.14040199	0.0028058216	1053.5686
83.416504	0.14285612	0.0028084686	1074.9799
84.41748	0.14418608	0.0030008091	1111.0837
85.418457	0.15039361	0.0030960382	1141.799
86.419434	0.15273464	0.0031518906	1172.9614
87.42041	0.15476424	0.0032227982	1196.5048
88.421387	0.15488574	0.0032392377	1222.0551
89.422363	0.15835249	0.0033633525	1252.7616
90.42334	0.16163971	0.0034426432	1281.2628
91.424316	0.16352779	0.0034864037	1311.3896
92.425293	0.16698055	0.003589971	1346.0045
93.42627	0.17360032	0.0037160383	1373.9481
94.427246	0.17734179	0.0038874778	1402.1764
95.428223	0.18036306	0.0038406972	1429.8578
96.429199	0.18132783	0.0040380745	1459.0012
97.430176	0.18255514	0.0039818487	1484.7129
98.431152	0.18533407	0.0040711146	1516.2615
99.432129	0.18972586	0.0041773943	1538.366
100.43311	0.19377854	0.0041981866	1562.6235
101.43408	0.19467331	0.0043469234	1594.2697
102.43506	0.19993895	0.0044319653	1622.4727
103.43604	0.19851825	0.0045368755	1647.486
104.43701	0.20433524	0.0045545865	1674.849
105.43799	0.20643	0.0045930557	1695.2341
106.43896	0.21011062	0.0047869296	1728.1061
107.43994	0.21327414	0.0048200195	1761.4603
108.44092	0.2170912	0.0050135534	1790.9634
109.44189	0.21975493	0.005057219	1805.4677
110.44287	0.22435981	0.0051775952	1833.2087
111.44385	0.223446	0.0052207741	1849.7632
112.44482	0.22948429	0.0053386213	1879.8096
113.4458	0.23431085	0.0054808883	1907.7065
114.44678	0.23354395	0.005502156	1929.2931
115.44775	0.23696618	0.0056593288	1959.7478
116.44873	0.23918331	0.0056540016	1970.9313
117.44971	0.24511684	0.0058146431	1995.2976
118.45068	0.24824964	0.0059708008	2017.499
119.45166	0.24930517	0.0061361869	2045.6915
120.45264	0.25322741	0.0061538117	2069.0867
121.45361	0.25608906	0.0062287841	2087.5449
122.45459	0.25834227	0.0063693877	2104.8945
123.45557	0.26319501	0.0064612585	2132.457
124.45654	0.26609215	0.0065424284	2152.0076
125.45752	0.26940274	0.0066121761	2166.2983
126.4585	0.26968342	0.0066446885	2179.9939
127.45947	0.27664202	0.00677671	2204.1206
128.46045	0.27798119	0.0068869772	2215.4692
129.46143	0.28241193	0.0069351909	2239.7603
130.4624	0.28077367	0.0070411963	2244.2195
131.46338	0.28644842	0.0071262019	2260.5222
132.46436	0.28799289	0.0071618147	2282.4802
133.46533	0.2923435	0.0071896063	2299.1372
134.46631	0.29620114	0.0073158499	2313.3672
135.46729	0.29829451	0.0074201589	2323.8225
136.46826	0.299784	0.007604952	2346.8274
137.46924	0.30565244	0.0075704157	2355.9768
138.47021	0.31054643	0.0077016964	2374.9263
139.47119	0.3113578	0.0077991895	2386.2588
140.47217	0.31289423	0.0078140236	2399.9434
141.47314	0.31704527	0.0079589831	2415.1165
142.47412	0.31949636	0.008123463	2431.0537
143.4751	0.32282314	0.0081269713	2434.8748
144.47607	0.3277089	0.008150829	2448.5874
145.47705	0.33059925	0.0083022369	2459.7795
146.47803	0.33205256	0.0083487416	2474.6628
147.479	0.33490402	0.0084903371	2487.6409
148.47998	0.33570063	0.0085185422	2493.135
149.48096	0.34087402	0.0085666254	2500.2698
150.48193	0.34095782	0.0086517688	2508.4465
151.48291	0.34603703	0.0088125039	2521.5901
152.48389	0.35209006	0.008909801	2539.4548
153.48486	0.3526842	0.0090059647	2542.9312
154.48584	0.35972011	0.009154737	2563.2888
155.48682	0.35927427	0.0091959443	2563.2668
156.48779	0.36374781	0.0093142111	2578.4766
157.48877	0.36808857	0.0095349168	2590.6016
158.48975	0.36646685	0.0095386747	2589.5347
159.49072	0.37162986	0.0096840421	2601.1978
160.4917	0.37589997	0.0097591961	2610.4902
161.49268	0.37716246	0.0098932628	2619.6655
162.49365	0.37967232	0.01000916	2629.2837
163.49463	0.38361007	0.010125094	2633.2346
164.49561	0.38709322	0.010229332	2640.4255
165.49658	0.38981515	0.010368723	2649.9651
166.49756	0.39362648	0.010498081	2667.5684
167.49854	0.3939203	0.010595806	2665.105
168.49951	0.3983092	0.010710133	2672.146
169.50049	0.40157232	0.010964502	2679.1785
170.50146	0.4044143	0.011179304	2696.6807
171.50244	0.40732801	0.011311694	2702.4656
172.50342	0.4110041	0.011491431	2703.6411
173.50439	0.4169971	0.011612463	2709.8171
174.50537	0.41778985	0.011823748	2721.6289
175.50635	0.41915953	0.012151922	2737.5867
176.50732	0.42230231	0.012349992	2739.3167
177.5083	0.42680678	0.012594141	2748.844
178.50928	0.42888704	0.012900553	2756.2517
179.51025	0.43306082	0.013159671	2755.8027
180.51123	0.43414894	0.013521361	2764.8335
181.51221	0.43934986	0.013705548	2763.5981
182.51318	0.43832704	0.014088296	2781.459
183.51416	0.44373754	0.014514697	2788.5493
184.51514	0.44850019	0.014739661	2792.2246
185.51611	0.44899786	0.015133535	2796.0603
186.51709	0.45342365	0.015512715	2810.3547
187.51807	0.45705488	0.015994841	2813.9998
188.51904	0.45790172	0.016437585	2818.7559
189.52002	0.46121493	0.016795415	2821.5779
190.521	0.46493694	0.017173562	2825.8699
191.52197	0.46714628	0.017686263	2830.5078
192.52295	0.47009686	0.018235236	2840.4795
193.52393	0.47347197	0.018789683	2845.2166
194.5249	0.47440812	0.019254243	2847.3721
195.52588	0.47878784	0.019842437	2852.657
196.52686	0.4810738	0.020364899	2856.2456
197.52783	0.48917425	0.021016449	2867.4771
198.52881	0.49197221	0.021702191	2872.3479
199.52979	0.4919433	0.022306407	2869.5256
200.53076	0.49649906	0.022984629	2878.4004
201.53174	0.4999674	0.023559215	2883.032
202.53271	0.50075209	0.024183292	2888.4233
203.53369	0.50288785	0.024868248	2889.3665
204.53467	0.50577515	0.025767328	2894.4255
205.53564	0.5096525	0.026305018	2893.5088
206.53662	0.51463127	0.027101841	2901.012
207.5376	0.51595932	0.027660832	2899.2185
208.53857	0.51893818	0.028389493	2906.1309
209.53955	0.52209765	0.02911929	2907.5813
210.54053	0.52326655	0.030042535	2912.4836
211.5415	0.52544242	0.030833613	2916.1489
212.54248	0.53354168	0.031653728	2914.469
213.54346	0.5368486	0.032447834	2921.979
214.54443	0.53616261	0.033443883	2929.187
215.54541	0.53915644	0.034352966	2927.7925
216.54639	0.54331565	0.035319045	2925.738
217.54736	0.54695553	0.036185846	2934.167
218.54834	0.54745054	0.037037864	2939.6638
219.54932	0.5539099	0.037997752	2941.6995
220.55029	0.55319196	0.038983434	2944.4102
221.55127	0.55634147	0.040018488	2945.0784
222.55225	0.56330031	0.041026182	2952.1438
223.55322	0.56133831	0.04206606	2958.4148
224.5542	0.56842393	0.043179248	2958.3853
225.55518	0.56987172	0.044251349	2954.3411
226.55615	0.57079345	0.045175381	2953.6514
227.55713	0.57759494	0.046086423	2961.2759
228.55811	0.57845056	0.047186065	2969.1226
229.55908	0.58166629	0.048221465	2964.6372
230.56006	0.58848399	0.04919083	2967.678
231.56104	0.5872981	0.049949951	2970.3289
232.56201	0.5902282	0.051081043	2974.6799
233.56299	0.59204984	0.052209135	2977.3103
234.56396	0.59598517	0.053188387	2979.0386
235.56494	0.59732741	0.05429104	2976.7402
236.56592	0.6040144	0.055209734	2977.6716
237.56689	0.60374045	0.056126639	2980.3345
238.56787	0.60938632	0.057087753	2987.0654
239.56885	0.61046606	0.057991385	2987.5134
240.56982	0.61582148	0.059305456	2991.8784
241.5708	0.61733234	0.060364638	2992.0745
242.57178	0.62221867	0.061523754	3000.708
243.57275	0.62156981	0.062555544	2993.8125
244.57373	0.62777156	0.06362772	3003.3818
245.57471	0.63197958	0.064851508	3002.6433
246.57568	0.63104904	0.0658997	3004.3906
247.57666	0.63573515	0.06693837	3006.5776
248.57764	0.64090675	0.068168066	3009.6326
249.57861	0.6431573	0.069238223	3014.1704
250.57959	0.64428663	0.070334867	3014.4707
251.58057	0.64675289	0.071417607	3014.9104
252.58154	0.65102416	0.072520077	3015.7588
253.58252	0.65363997	0.073506601	3012.1423
254.5835	0.65780401	0.074900731	3023.6121
255.58447	0.65934449	0.076114394	3021.6875
256.58545	0.66374898	0.077400081	3026.3455
257.58643	0.66825759	0.078614928	3024.4973
258.5874	0.66706246	0.079652563	3022.7693
259.58838	0.67469394	0.080859832	3032.9019
260.58936	0.67559624	0.081955314	3031.5671
261.59033	0.67830217	0.082924895	3031.3655
262.59131	0.68210888	0.084123254	3039.0425
263.59229	0.68800271	0.085396126	3037.001
264.59326	0.6891802	0.086805873	3040.3835
265.59424	0.69037449	0.087930001	3039.7173
266.59521	0.69445419	0.088926755	3034.2031
267.59619	0.69520432	0.089992791	3038.7732
268.59717	0.69930905	0.091164678	3044.5078
269.59814	0.70249486	0.092337653	3050.8047
270.59912	0.70560998	0.093727767	3045.4319
271.6001	0.70640635	0.094622336	3043.978
272.60107	0.7100051	0.095483206	3043.0874
273.60205	0.71162701	0.096649006	3054.9021
274.60303	0.72031564	0.097882435	3056.7246
275.604	0.72274405	0.098999791	3057.2751
276.60498	0.72492671	0.10023142	3056.1289
277.60596	0.72613162	0.10128146	3056.3933
278.60693	0.72715157	0.10230393	3056.0173
279.60791	0.73450011	0.1033826	3064.5325
280.60889	0.73578149	0.1048401	3066.1763
281.60986	0.73757184	0.10595776	3065.2126
282.61084	0.74021548	0.10699586	3069.2495
283.61182	0.74479431	0.10830431	3075.5259
284.61279	0.74685055	0.10975684	3077.2659
285.61377	0.75074655	0.1110894	3069.4368
286.61475	0.7556169	0.11239083	3072.2668
287.61572	0.75781029	0.11349601	3075.9568
288.6167	0.75979459	0.11455373	3075.2119
289.61768	0.76143742	0.11575833	3084.1533
290.61865	0.76438516	0.1168208	3079.947
291.61963	0.76855695	0.11797855	3080.0437
292.62061	0.77304924	0.11913488	3079.9858
293.62158	0.77194452	0.12020236	3084.875
294.62256	0.7770049	0.12133019	3086.9126
295.62354	0.78025132	0.12235902	3087.6963
296.62451	0.78231579	0.12355391	3087.7087
297.62549	0.78455174	0.12473487	3091.1497
298.62646	0.7871331	0.1259881	3090.1755
299.62744	0.79063857	0.12712403	3095.833
300.62842	0.79406577	0.12833627	3094.7607
301.62939	0.79960734	0.1295431	3097.7673
302.63037	0.80296427	0.13061513	3101.0686
303.63135	0.80787873	0.13183923	3097.5071
304.63232	0.80811763	0.13301903	3103.1643
305.6333	0.80990565	0.13426308	3107.2124
306.63428	0.81495023	0.13556829	3103.8259
307.63525	0.81674302	0.13677375	3100.7017
308.63623	0.81961286	0.13796502	3113.9038
309.63721	0.82229882	0.13913977	3110.1541
310.63818	0.82674628	0.14033082	3108.7886
311.63916	0.82645983	0.1413604	3105.5781
312.64014	0.83465093	0.14231947	3111.2649
313.64111	0.83454394	0.1434136	3116.0342
314.64209	0.83707678	0.14451098	3118.7273
315.64307	0.83973986	0.14563814	3120.9302
316.64404	0.84500539	0.14686933	3114.5625
317.64502	0.84776765	0.14812976	3123.8591
318.646	0.84974217	0.14930068	3116.7109
319.64697	0.85132927	0.15038536	3119.7041
320.64795	0.8569985	0.15169007	3122.6304
321.64893	0.86135179	0.15300404	3128.5222
322.6499	0.86050332	0.15433615	3131.5442
323.65088	0.8631134	0.15561083	3131.0232
324.65186	0.86843598	0.15677163	3133.0044
325.65283	0.86996591	0.15795329	3133.3674
326.65381	0.87446076	0.15915103	3139.8315
327.65479	0.87717938	0.16034991	3130.6086
328.65576	0.87781376	0.16152869	3135.7974
329.65674	0.88319063	0.1626256	3135.8025
330.65771	0.88651371	0.16371322	3145.9705
331.65869	0.88977802	0.16504064	3142.7378
332.65967	0.89346683	0.16618153	3142.9148
333.66064	0.89544219	0.1673529	3147.3582
334.66162	0.89967132	0.16845895	3142.332
335.6626	0.90170544	0.16977204	3151.5422
336.66357	0.90698308	0.17101592	3158.2114
337.66455	0.90737033	0.17235552	3149.0269
338.66553	0.90929592	0.17344567	3151.7854
339.6665	0.91223097	0.17460369	3152.9121
340.66748	0.91739804	0.17583574	3150.7683
341.66846	0.91769511	0.17705421	3155.386
342.66943	0.92428315	0.17796072	3154.9084
343.67041	0.92418456	0.17910913	3158.9045
344.67139	0.93137407	0.18038893	3164.2664
345.67236	0.93450087	0.18150246	3161.7729
346.67334	0.93499732	0.18263629	3163.4514
347.67432	0.93825692	0.18376794	3168.5671
348.67529	0.94083649	0.18498877	3167.2239
349.67627	0.94226867	0.18608859	3158.3721
350.67725	0.94440806	0.18731523	3167.3164
351.67822	0.94968128	0.18861809	3172.7329
352.6792	0.95305401	0.18978404	3177.7739
353.68018	0.95773196	0.19102083	3171.4648
354.68115	0.9555577	0.19222848	3170.4429
355.68213	0.96136385	0.19328284	3174.0244
356.68311	0.9636963	0.19447421	3172.4751
357.68408	0.96733248	0.19562112	3176.6494
358.68506	0.97118598	0.19677545	3180.0256
359.68604	0.97301263	0.19794251	3184.2864
360.68701	0.9761408	0.19927454	3186.5525
361.68799	0.97800493	0.2006153	3184.6702
362.68896	0.98440784	0.201819	3186.3069
363.68994	0.98677415	0.20293212	3182.2813
364.69092	0.98966062	0.20409527	3189.3269
365.69189	0.99199659	0.20532811	3189.7236
366.69287	0.99319333	0.20680051	3189.2351
367.69385	0.9958784	0.20806025	3189.3401
368.69482	1.001858	0.20924927	3194.2256
369.6958	1.0031564	0.21046577	3194.78
370.69678	1.0054172	0.21155936	3189.4854
371.69775	1.0102518	0.2125096	3194.8376
372.69873	1.0118423	0.21372488	3191.2104
373.69971	1.0138981	0.21491489	3193.0471
374.70068	1.0171976	0.21594578	3195.7686
375.70166	1.0197808	0.21714057	3197.3264
376.70264	1.023381	0.21834418	3201.3999
377.70361	1.0251459	0.21953301	3201.4954
378.70459	1.0292658	0.22070096	3204.4377
379.70557	1.028932	0.22209318	3205.2327
380.70654	1.03479	0.22322725	3202.2974
381.70752	1.0387386	0.2244155	3204.0796
382.7085	1.0415771	0.22553582	3207.4739
383.70947	1.0448248	0.22672597	3207.7832
384.71045	1.048439	0.22805475	3210.6948
385.71143	1.0514888	0.22924499	3218.01
386.7124	1.0563434	0.23028642	3217.8015
387.71338	1.05533	0.23143125	3209.3428
388.71436	1.0630616	0.23268054	3219.177
389.71533	1.062368	0.2338319	3219.7639
390.71631	1.064774	0.23499763	3219.5784
391.71729	1.0713718	0.23631413	3227.312
392.71826	1.0715351	0.23760626	3227.1267
393.71924	1.075451	0.23882143	3225.9031
394.72021	1.0800091	0.24008797	3225.7273
395.72119	1.0796075	0.24127674	3226.3691
396.72217	1.0818213	0.24244919	3225.8779
397.72314	1.088769	0.24372737	3232.0989
398.72412	1.0899397	0.24483152	3227.8958
399.7251	1.0942962	0.24616258	3228.2942
400.72607	1.0996162	0.24730849	3235.1008
401.72705	1.100623	0.24854937	3236.2922
402.72803	1.1021637	0.24967027	3232.1729
403.729	1.1056404	0.25078589	3230.6287
404.72998	1.108686	0.25199535	3237.0645
405.73096	1.1120238	0.25320157	3235.0461
406.73193	1.1154855	0.25439942	3236.0586
407.73291	1.1177002	0.25558093	3235.0261
408.73389	1.1207514	0.25676221	3247.2458
409.73486	1.1227194	0.25797808	3242.0227
410.73584	1.1271261	0.25919399	3241.7141
411.73682	1.1292529	0.26025456	3243.0356
412.73779	1.1322061	0.26140156	3245.4072
413.73877	1.1392926	0.26239488	3247.5916
414.73975	1.1379194	0.26373187	3249.2898
415.74072	1.1413869	0.26502645	3249.4688
416.7417	1.144037	0.26628986	3253.2373
417.74268	1.1464521	0.26746681	3251.3779
418.74365	1.1492045	0.26848602	3247.0447
419.74463	1.1540375	0.26955855	3245.1013
420.74561	1.1542374	0.27062815	3249.5601
421.74658	1.1590813	0.27171654	3256.3547
422.74756	1.1585796	0.27309939	3256.7402
423.74854	1.1640855	0.27435124	3263.2283
424.74951	1.170758	0.27557203	3256.6392
425.75049	1.1699023	0.27663654	3254.3435
426.75146	1.1739326	0.2778545	3260.1758
427.75244	1.1788614	0.27901193	3262.5789
428.75342	1.1802346	0.28021631	3259.4419
429.75439	1.1802295	0.28158787	3267.9014
430.75537	1.1858286	0.28274497	3268.792
431.75635	1.1891309	0.28384516	3267.1226
432.75732	1.1942726	0.28491339	3269.4373
433.7583	1.1961524	0.2859011	3271.228
434.75928	1.1982068	0.28715509	3273.3594
435.76025	1.2030181	0.28827426	3270.8552
436.76123	1.2033981	0.2896575	3277.5156
437.76221	1.2083554	0.29088137	3273.7803
438.76318	1.2129593	0.29209051	3278.5303
439.76416	1.2125149	0.29324093	3275.5964
440.76514	1.2148587	0.29444319	3275.4902
441.76611	1.2182618	0.29559544	3281.2219
442.76709	1.2209412	0.29680458	3284.5073
443.76807	1.2242237	0.2980895	3279.999
444.76904	1.2262646	0.29908738	3280.8601
445.77002	1.2321584	0.30028814	3285.5659
446.771	1.236239	0.30145696	3284.9314
447.77197	1.2381899	0.30267608	3285.2336
448.77295	1.240533	0.30411512	3292.7285
449.77393	1.2455872	0.30535781	3287.2681
450.7749	1.246509	0.30654907	3294.4602
451.77588	1.2485058	0.30770224	3285.7805
452.77686	1.2518587	0.3087627	3285.2742
453.77783	1.2555112	0.30968881	3286.8315
454.77881	1.2600092	0.31052953	3288.198
455.77979	1.2619665	0.31171519	3295.4856
456.78076	1.2630832	0.31293538	3299.4404
457.78174	1.2656693	0.31406608	3288.4766
458.78271	1.2701752	0.31514248	3296.4771
459.78369	1.2747933	0.31612197	3295.5342
460.78467	1.2736106	0.3172425	3292.9998
461.78564	1.2792011	0.31840786	3303.1516
462.78662	1.2798702	0.31977633	3301.0247
463.7876	1.2856616	0.32094267	3302.9949
464.78857	1.2896444	0.3220996	3302.6841
465.78955	1.2920707	0.32333642	3307.2642
466.79053	1.2925414	0.32463911	3304.0371
467.7915	1.2980562	0.32593566	3309.7544
468.79248	1.3006115	0.32723635	3305.4832
469.79346	1.3026129	0.32886097	3316.7144
470.79443	1.3077664	0.33029765	3310.8479
471.79541	1.310065	0.33146641	3315.8491
472.79639	1.3113359	0.33263648	3312.4202
473.79736	1.3177688	0.33376807	3315.5652
474.79834	1.3169076	0.33471483	3307.9219
475.79932	1.3192003	0.33574831	3308.7515
476.80029	1.3235546	0.33674726	3315.9033
477.80127	1.3253186	0.33792156	3318.3997
478.80225	1.3309928	0.33919954	3320.1382
479.80322	1.3337309	0.34023973	3318.1794
480.8042	1.3348572	0.3413434	3314.3306
481.80518	1.3410823	0.342509	3324.7439
482.80615	1.3434527	0.34357134	3320.9626
483.80713	1.3456683	0.34480578	3326.3665
484.80811	1.3494939	0.34595171	3321.8528
485.80908	1.34962	0.34713387	3331.2461
486.81006	1.3539869	0.34837571	3327.0977
487.81104	1.3550557	0.3495158	3322.9253
488.81201	1.3610002	0.35087353	3334.2529
489.81299	1.3604647	0.35223532	3327.3879
490.81396	1.3651981	0.35324776	3327.3594
491.81494	1.3674245	0.3544006	3326.9966
492.81592	1.3739249	0.3555319	3335.2461
493.81689	1.3761432	0.35654876	3327.5884
494.81787	1.3794061	0.35743204	3329.6909
495.81885	1.3825258	0.35867864	3334.4365
496.81982	1.3850695	0.36007249	3337.7595
497.8208	1.38662	0.36125022	3337.4058
498.82178	1.391113	0.36245754	3338.2209
499.82275	1.3923999	0.36371619	3340.5371
500.82373	1.3977457	0.36510307	3344.8145
501.82471	1.3972318	0.36601567	3336.1311
502.82568	1.4070582	0.36731303	3344.3909
503.82666	1.4052891	0.36865777	3343.3008
504.82764	1.4126421	0.36998054	3349.0374
505.82861	1.4111534	0.37135312	3349.5579
506.82959	1.4137368	0.37262797	3343.0518
507.83057	1.4182888	0.37371111	3343.9138
508.83154	1.4247965	0.3749159	3355.7871
509.83252	1.4243608	0.37597671	3347.2341
510.8335	1.4291506	0.37724924	3353.2903
511.83447	1.4317399	0.37869012	3361.7595
512.83545	1.4338123	0.38000253	3354.9705
513.83643	1.4359161	0.38118187	3347.7122
514.8374	1.4372175	0.38210383	3349.4192
515.83838	1.4396688	0.38339698	3359.4878
516.83936	1.4472668	0.38455454	3360.6389
517.84033	1.4478939	0.38556787	3354.6082
518.84131	1.4507209	0.38645995	3349.2664
519.84229	1.4552206	0.38764465	3362.5413
520.84326	1.4584666	0.38891628	3367.3267
521.84424	1.4619945	0.39031264	3362.3301
522.84521	1.462536	0.39139929	3362.8196
523.84619	1.4687349	0.3925409	3363.9255
524.84717	1.468071	0.39365608	3365.3096
525.84814	1.4722778	0.39474809	3364.5913
526.84912	1.4759748	0.39588261	3363.5591
527.8501	1.4782925	0.39689735	3367.29
528.85107	1.4785949	0.39820951	3368.8682
529.85205	1.4828526	0.3994754	3368.2163
530.85303	1.4877739	0.40068004	3369.2151
531.854	1.4919457	0.40196404	3373.5667
532.85498	1.493984	0.40322131	3375.5708
533.85596	1.4953876	0.40428233	3365.6802
534.85693	1.4993604	0.40540379	3370.4502
535.85791	1.5031226	0.40666509	3372.9561
536.85889	1.5054268	0.4079608	3381.5674
537.85986	1.5092348	0.40924391	3384.9233
538.86084	1.5110613	0.41045639	3372.3303
539.86182	1.51199	0.41164768	3373.0891
540.86279	1.5191481	0.41297725	3384.5032
541.86377	1.5183562	0.41449672	3380.6194
542.86475	1.5209688	0.41585898	3376.7949
543.86572	1.5251217	0.41691735	3372.5884
544.8667	1.5275898	0.41809228	3381.042
545.86768	1.530593	0.41930026	3382.6675
546.86865	1.5332018	0.42045215	3387.2637
547.86963	1.541001	0.42162058	3392.8044
548.87061	1.5403682	0.42267033	3381.8906
549.87158	1.5411059	0.42378762	3387.5269
550.87256	1.5452352	0.42492679	3383.8926
551.87354	1.5490257	0.4262009	3387.9968
552.87451	1.556007	0.42741793	3391.7615
553.87549	1.5565157	0.4286522	3393.4143
554.87646	1.559177	0.42996258	3394.3496
555.87744	1.5616949	0.431023	3389.2886
556.87842	1.5655144	0.43231013	3391.762
557.87939	1.5676467	0.43350044	3395.8052
558.88037	1.5699991	0.43451375	3389.322
559.88135	1.5741843	0.43555453	3391.3875
560.88232	1.5760236	0.43671632	3395.8481
561.8833	1.5810691	0.43802416	3402.896
562.88428	1.5815585	0.43915915	3397.1392
563.88525	1.583567	0.44037995	3397.1624
564.88623	1.5882434	0.44173717	3400.5447
565.88721	1.5903834	0.44288942	3399.7676
566.88818	1.5925958	0.44414535	3403.6619
567.88916	1.595395	0.44531509	3401.5293
568.89014	1.6023395	0.44669858	3409.3096
569.89111	1.6037638	0.4482159	3411.146
570.89209	1.6057326	0.44952667	3399.6826
571.89307	1.611522	0.45083511	3412.7705
572.89404	1.6142216	0.45185828	3405.6677
573.89502	1.6163014	0.45300502	3404.0854
574.896	1.6166011	0.45416304	3406.8997
575.89697	1.6230938	0.45516679	3412.6292
576.89795	1.6268687	0.45634478	3413.585
577.89893	1.6270916	0.45760486	3411.6953
578.8999	1.6305176	0.45918724	3417.793
579.90088	1.630982	0.46061897	3416.2295
580.90186	1.6365052	0.46198058	3420.96
581.90283	1.6407471	0.4635233	3417.3403
582.90381	1.6430398	0.46466964	3414.0474
583.90479	1.6452966	0.46584049	3417.7563
584.90576	1.6491455	0.46692166	3414.3054
585.90674	1.6496809	0.4680706	3418.3198
586.90771	1.6526861	0.46925482	3415.5686
587.90869	1.6599118	0.47055146	3420.2119
588.90967	1.6595825	0.47157612	3421.6489
589.91064	1.6637942	0.47278503	3423.3367
590.91162	1.6654136	0.47413498	3426.2375
591.9126	1.6704305	0.47530439	3415.8191
592.91357	1.6740769	0.47641984	3424.2378
593.91455	1.6797097	0.47755083	3425.396
594.91553	1.6779623	0.47858185	3421.3022
595.9165	1.6803555	0.47988236	3429.6831
596.91748	1.6816816	0.4809505	3422.9231
597.91846	1.6884961	0.48211879	3432.541
598.91943	1.6920258	0.48319119	3428.9768
599.92041	1.691692	0.48435414	3424.4507
600.92139	1.6973	0.48551512	3433.405
601.92236	1.7023342	0.48689687	3431.8655
602.92334	1.7002552	0.48828149	3434.6108
603.92432	1.7066759	0.48936024	3436.0271
604.92529	1.7073258	0.49066982	3426.4834
605.92627	1.7109733	0.49185428	3430.4329
606.92725	1.7157431	0.49310043	3437.1733
607.92822	1.7171713	0.49431968	3433.9192
608.9292	1.7215849	0.49540079	3434.3833
609.93018	1.7232682	0.49661574	3439.6887
610.93115	1.727082	0.4979775	3441.3188
611.93213	1.7310787	0.49917546	3443.344
612.93311	1.7322668	0.50046742	3444.0459
613.93408	1.7373475	0.50208616	3446.3262
614.93506	1.7374634	0.5034619	3438.6033
615.93604	1.7411761	0.50458074	3438.155
616.93701	1.7432697	0.50597268	3441.4797
617.93799	1.749281	0.50719553	3448.2063
618.93896	1.7522782	0.50850475	3446.228
619.93994	1.7564895	0.50989568	3450.3838
620.94092	1.7559685	0.51134169	3442.8999
621.94189	1.7603424	0.51249683	3444.7632
622.94287	1.7611052	0.51369232	3439.1672
623.94385	1.7641207	0.51494324	3445.6924
624.94482	1.7703018	0.51607078	3448.3247
625.9458	1.7742273	0.517299	3456.4534
626.94678	1.7738644	0.51867819	3456.5522
627.94775	1.7765675	0.51993924	3449.4609
628.94873	1.7801164	0.52127665	3455.1475
629.94971	1.7856385	0.52242345	3452.5186
630.95068	1.786186	0.52364111	3453.7393
631.95166	1.7877626	0.5248149	3448.1731
632.95264	1.7933739	0.52607405	3453.9541
633.95361	1.7961571	0.52710956	3451.2092
634.95459	1.7964284	0.52830398	3454.7729
635.95557	1.803839	0.52961624	3460.2212
636.95654	1.8034987	0.53087151	3461.3027
637.95752	1.8068472	0.53226084	3457.4641
638.9585	1.8090123	0.53347856	3456.3694
639.95947	1.8142084	0.53481042	3466.2268
640.96045	1.8196458	0.53610021	3458.7822
641.96143	1.8215637	0.53707689	3457.1963
642.9624	1.823836	0.53826177	3463.5164
643.96338	1.8244514	0.53960222	3471.7356
644.96436	1.8279958	0.54082561	3466.5088
645.96533	1.8326515	0.54197556	3465.4114
646.96631	1.8342402	0.54324424	3465.0515
647.96729	1.8356279	0.54457265	3468.8413
648.96826	1.8405352	0.54617566	3472.7778
649.96924	1.8445977	0.54779726	3467.0378
650.97021	1.847451	0.54902261	3461.2651
651.97119	1.850616	0.55025321	3467.4622
652.97217	1.8507618	0.55132276	3465.2815
653.97314	1.8579534	0.55261636	3471.8872
654.97412	1.8595787	0.55395895	3470.8281
655.9751	1.8616971	0.55520916	3470.3191
656.97607	1.862692	0.55648494	3470.5688
657.97705	1.8698382	0.55779445	3478.7322
658.97803	1.8708116	0.55893338	3471.8174
659.979	1.8723825	0.56013155	3472.3206
660.97998	1.8764836	0.56140834	3480.1873
661.98096	1.8804777	0.56274283	3478.9619
662.98193	1.8841882	0.56412089	3476.9841
663.98291	1.8875304	0.56537586	3475.7666
664.98389	1.8890067	0.56643647	3473.5173
665.98486	1.8900863	0.56743461	3477.2769
666.98584	1.8946694	0.56899959	3487.3635
667.98682	1.8997211	0.57039422	3489.3369
668.98779	1.8996407	0.5717079	3481.7256
669.98877	1.9024926	0.57320565	3486.6108
670.98975	1.9065661	0.57443959	3478.3096
671.99072	1.9084939	0.5758605	3480.7959
672.9917	1.9133369	0.57702953	3485.2478
673.99268	1.9146032	0.5782901	3482.8628
674.99365	1.9165896	0.57955402	3484.0095
675.99463	1.9217898	0.58086771	3485.7617
676.99561	1.9260824	0.58233356	3488.6938
677.99658	1.9302099	0.58359975	3486.5298
678.99756	1.9300697	0.58484036	3485.4165
679.99854	1.9347363	0.58617783	3492.6597
680.99951	1.9381714	0.58738971	3489.9763
682.00049	1.938125	0.58867693	3489.9424
683.00146	1.9428967	0.59001052	3488.0015
684.00244	1.9467927	0.59138638	3494.1177
685.00342	1.9499944	0.59269315	3495.0105
686.00439	1.9506032	0.59406191	3500.4629
687.00537	1.9575809	0.59537405	3493.03
688.00635	1.9580622	0.59690338	3500.0706
689.00732	1.9608818	0.59825188	3488.6887
690.0083	1.9612749	0.59943205	3487.5654
691.00928	1.9655771	0.60053301	3490.7214
692.01025	1.9731563	0.60208774	3503.4148
693.01123	1.9745036	0.60343099	3499.208
694.01221	1.9772428	0.60471618	3498.1355
695.01318	1.9813496	0.6059826	3500.5356
696.01416	1.9829924	0.60736674	3503.9441
697.01514	1.9852943	0.60874462	3499.9355
698.01611	1.9877685	0.60982203	3493.6609
699.01709	1.9924273	0.61102694	3500.0142
700.01807	1.9906231	0.6121341	3495.4822
701.01904	1.9976639	0.61342853	3500.6394
702.02002	1.9976048	0.61480701	3506.6875
703.021	2.0022829	0.61600381	3497.9351
704.02197	2.006896	0.61725318	3505.7324
705.02295	2.0080788	0.61849451	3506.0798
706.02393	2.0106635	0.62014085	3513.0627
707.0249	2.0161066	0.62174016	3509.6138
708.02588	2.0189903	0.62311077	3508.1169
709.02686	2.0208039	0.62458056	3504.5728
710.02783	2.0250525	0.62569982	3505.8794
711.02881	2.0264492	0.62688959	3502.5588
712.02979	2.0305498	0.62805855	3505.488
713.03076	2.0342715	0.629462	3511.4302
714.03174	2.0366423	0.63088042	3513.7346
715.03271	2.0404577	0.6323272	3516.2939
716.03369	2.0398643	0.6335358	3507.6206
717.03467	2.0447659	0.63502192	3506.3457
718.03564	2.0484424	0.63639653	3508.2927
719.03662	2.0522285	0.63774914	3516.4844
720.0376	2.0527852	0.6392985	3516.6682
721.03857	2.0585425	0.64071894	3514.3188
722.03955	2.0576065	0.6421724	3510.8835
723.04053	2.0613739	0.64354581	3517.1978
724.0415	2.0688014	0.64471519	3518.0173
725.04248	2.0687678	0.64594907	3510.634
726.04346	2.070415	0.64718074	3512.4949
727.04443	2.0739703	0.6483655	3517.7239
728.04541	2.0789247	0.64972419	3514.6328
729.04639	2.084085	0.65114403	3521.0105
730.04736	2.0837176	0.65260124	3514.124
731.04834	2.0866311	0.65375733	3523.0728
732.04932	2.0912659	0.65511334	3523.2239
733.05029	2.0941522	0.65657312	3524.8494
734.05127	2.0974383	0.65820313	3529.6313
735.05225	2.0986607	0.65980119	3519.3826
736.05322	2.0998735	0.66108274	3515.8896
737.0542	2.1044345	0.66242605	3520.9343
738.05518	2.1040292	0.66341114	3512.2068
739.05615	2.1109295	0.66449982	3517.3281
740.05713	2.1125798	0.66583508	3529.5801
741.05811	2.1170495	0.66713321	3523.0513
742.05908	2.1213405	0.66869068	3526.8596
743.06006	2.1225088	0.67000622	3528.7104
744.06104	2.1282477	0.67133045	3528.5747
745.06201	2.1291199	0.67273867	3532.0515
746.06299	2.1344829	0.67408454	3525.137
747.06396	2.1369152	0.67554742	3532.5906
748.06494	2.1387823	0.67695308	3533.063
749.06592	2.143584	0.67824942	3533.9521
750.06689	2.1416547	0.67947674	3525.8823
751.06787	2.1466439	0.68091565	3532.8921
752.06885	2.1496286	0.68222272	3528.6658
753.06982	2.1547277	0.68362606	3530.7261
754.0708	2.1575539	0.68479627	3531.4207
755.07178	2.1591923	0.68606329	3528.2646
756.07275	2.1635189	0.68781263	3535.0022
757.07373	2.1638088	0.68961	3536.6169
758.07471	2.1700015	0.69131321	3535.8579
759.07568	2.1708584	0.6926896	3529.929
760.07666	2.17291	0.69395608	3527.6636
761.07764	2.1790514	0.69551337	3539.2717
762.07861	2.1823645	0.69698626	3535.6765
763.07959	2.1819854	0.69819099	3536.0022
764.08057	2.1847758	0.69964987	3532.7876
765.08154	2.1892252	0.70096016	3538.054
766.08252	2.1936326	0.70217311	3536.6174
767.0835	2.1975596	0.70369357	3544.3652
768.08447	2.1978688	0.70505464	3541.2444
769.08545	2.2010152	0.706397	3536.908
770.08643	2.2035172	0.70786345	3534.7039
771.0874	2.207015	0.70927984	3536.2292
772.08838	2.2095771	0.71060741	3541.6775
773.08936	2.2156458	0.71224523	3543.0261
774.09033	2.2144828	0.71371299	3537.6304
775.09131	2.2203929	0.71541035	3549.4587
776.09229	2.2216132	0.71679753	3535.4482
777.09326	2.2286882	0.71840799	3546.6448
778.09424	2.2275319	0.71977472	3544.2266
779.09521	2.2301753	0.72104907	3532.0889
780.09619	2.2367353	0.72214413	3541.3877
781.09717	2.2342422	0.72335321	3542.6335
782.09814	2.2406814	0.72504711	3546.8972
783.09912	2.2432327	0.72635472	3546.1721
784.1001	2.2455602	0.72782356	3545.583
785.10107	2.2487156	0.72935677	3546.2363
786.10205	2.2535541	0.73083764	3549.2537
787.10303	2.2537887	0.73234558	3545.9795
788.104	2.2563746	0.73385251	3550.9028
789.10498	2.2609437	0.73530924	3545.1516
790.10596	2.2640886	0.73678476	3543.2722
791.10693	2.2656934	0.73815024	3546.8599
792.10791	2.2717361	0.7396934	3552.1792
793.10889	2.2719576	0.74134159	3549.6418
794.10986	2.2780926	0.74279034	3546.6106
795.11084	2.2800858	0.7441988	3545.803
796.11182	2.2822626	0.74556077	3545.8855
797.11279	2.2846446	0.74708718	3549.5649
798.11377	2.2897112	0.74871832	3559.489
799.11475	2.2926631	0.74999464	3549.1833
800.11572	2.2937999	0.75138009	3554.1343
801.1167	2.2982619	0.75296021	3557.5605
802.11768	2.3033431	0.75441682	3561.9187
803.11865	2.3056753	0.75576091	3555.0647
804.11963	2.3079009	0.7572915	3557.0564
805.12061	2.3104038	0.75891322	3553.5413
806.12158	2.3095398	0.76045364	3553.9321
807.12256	2.3152437	0.76204962	3559.5811
808.12354	2.3207107	0.76373374	3559.0769
809.12451	2.3220527	0.76510966	3552.158
810.12549	2.328104	0.76647383	3555.8152
811.12646	2.3272104	0.76752084	3551.281
812.12744	2.3305779	0.76884103	3558.8362
813.12842	2.3329456	0.77049005	3556.8418
814.12939	2.3363667	0.77181125	3557.7805
815.13037	2.3379741	0.77341223	3559.3433
816.13135	2.3412497	0.7752279	3562.8235
817.13232	2.3477604	0.77669585	3556.0137
818.1333	2.3476877	0.77822524	3562.0457
819.13428	2.3517668	0.77956039	3554.8762
820.13525	2.3558586	0.78093725	3556.0269
821.13623	2.3561022	0.78232294	3557.2925
822.13721	2.3591475	0.78368413	3559.3796
823.13818	2.3643417	0.78533459	3562.8491
824.13916	2.3692422	0.78691393	3557.6331
825.14014	2.3689873	0.78839499	3563.177
826.14111	2.3729873	0.79001629	3565.5085
827.14209	2.3761866	0.79165429	3565.5608
828.14307	2.3782372	0.79345232	3561.1394
829.14404	2.382858	0.79512382	3567.5286
830.14502	2.3841779	0.79639757	3558.655
831.146	2.3877795	0.79791868	3569.9993
832.14697	2.3897552	0.79967684	3563.3901
833.14795	2.3939829	0.80129236	3562.3423
834.14893	2.3969491	0.80274326	3562.7056
835.1499	2.4004385	0.80417949	3563.72
836.15088	2.4017186	0.80554819	3564.3088
837.15186	2.4061058	0.80727369	3567.9426
838.15283	2.4070442	0.80887997	3566.9924
839.15381	2.4143298	0.81072491	3569.0679
840.15479	2.4151363	0.81222194	3566.5454
841.15576	2.4171085	0.81395882	3571.5132
842.15674	2.419524	0.81540203	3561.23
843.15771	2.4256816	0.8170386	3570.6716
844.15869	2.4252894	0.8186456	3570.6143
845.15967	2.4290538	0.82011563	3569.1616
846.16064	2.4317348	0.82156956	3568.0608
847.16162	2.4333904	0.82315964	3563.1711
848.1626	2.4388318	0.82479048	3569.4946
849.16357	2.4419134	0.82630169	3572.2129
850.16455	2.4437401	0.82811475	3571.2056
851.16553	2.4500756	0.82958293	3568.4734
852.1665	2.4507704	0.83116418	3569.2329
853.16748	2.4528515	0.83267123	3569.2578
854.16846	2.4546969	0.83405018	3570.3657
855.16943	2.4602139	0.83555937	3564.4187
856.17041	2.4608111	0.83683693	3565.436
857.17139	2.4626839	0.8383919	3571.2361
858.17236	2.4664915	0.84001857	3575.7686
859.17334	2.4728959	0.84148741	3568.5107
860.17432	2.4729781	0.84292567	3572.5728
861.17529	2.4769931	0.84462553	3575.0217
862.17627	2.4795413	0.84644955	3572.7515
863.17725	2.4824347	0.84841156	3573.3977
864.17822	2.4861248	0.85004771	3572.6909
865.1792	2.4900212	0.85191596	3575.9597
866.18018	2.4923337	0.85369903	3573.8772
867.18115	2.4974074	0.85533446	3577.438
868.18213	2.5000165	0.85701394	3577.0046
869.18311	2.50137	0.8586064	3572.6372
870.18408	2.5034506	0.86016327	3576.5195
871.18506	2.5063972	0.86168635	3574.9734
872.18604	2.5093119	0.86323321	3576.6104
873.18701	2.5122385	0.86500263	3574.9258
874.18799	2.5162122	0.86696839	3581.5205
875.18896	2.5209999	0.86859083	3579.2361
876.18994	2.5206311	0.87004083	3575.4417
877.19092	2.5269678	0.87174028	3579.1189
878.19189	2.5258861	0.87324917	3572.124
879.19287	2.5341132	0.8749581	3580.4182
880.19385	2.5352418	0.87657154	3575.3381
881.19482	2.5353882	0.87815881	3577.7153
882.1958	2.5426953	0.87987429	3579.8254
883.19678	2.5444729	0.88158685	3575.9353
884.19775	2.5447166	0.88311666	3571.2324
885.19873	2.5505524	0.8845486	3578.7913
886.19971	2.5501885	0.8860997	3577.5439
887.20068	2.5552104	0.88782597	3582.7515
888.20166	2.5594478	0.88973176	3578.5105
889.20264	2.5627644	0.89133495	3581.1167
890.20361	2.5640922	0.89291704	3573.9448
891.20459	2.5675578	0.89463723	3578.3567
892.20557	2.5721064	0.89620119	3577.1501
893.20654	2.5753379	0.89781916	3580.8462
894.20752	2.5770009	0.89962792	3581.4851
895.2085	2.5797462	0.90135223	3582.6934
896.20947	2.5824745	0.90301299	3574.3511
897.21045	2.5863364	0.90457237	3577.9336
898.21143	2.5879791	0.90607601	3576.1758
899.2124	2.594883	0.90780216	3583.6147
900.21338	2.5960665	0.90956742	3590.678
901.21436	2.5970492	0.91141194	3579.8821
902.21533	2.600915	0.91330314	3583.5007
903.21631	2.6022933	0.91515952	3580.1851
904.21729	2.6089709	0.91724998	3588.4512
905.21826	2.6097445	0.91908842	3580.8496
906.21924	2.6137671	0.92101508	3585.1577
907.22021	2.6165104	0.92292768	3582.7388
908.22119	2.6191387	0.92454243	3578.6084
909.22217	2.6223719	0.92629099	3585.9189
910.22314	2.6263678	0.92825168	3589.283
911.22412	2.6282725	0.93029875	3581.7144
912.2251	2.6330435	0.93213052	3585.9404
913.22607	2.634624	0.93394256	3582.4678
914.22705	2.637059	0.93585968	3580.0759
915.22803	2.6423774	0.93725157	3581.9197
916.229	2.6413114	0.93895483	3578.2983
917.22998	2.6466162	0.94064385	3583.3811
918.23096	2.6486132	0.94231981	3580.7043
919.23193	2.651021	0.9441222	3582.4246
920.23291	2.656307	0.9457292	3590.5505
921.23389	2.6575356	0.94774944	3585.6382
922.23486	2.6601863	0.94958842	3578.7793
923.23584	2.6660736	0.95137602	3581.5862
924.23682	2.6687863	0.95305717	3584.0662
925.23779	2.6701376	0.95462805	3587.7158
926.23877	2.6690497	0.95647317	3586.5073
927.23975	2.6766112	0.95852649	3587.575
928.24072	2.678051	0.9606294	3583.5037
929.2417	2.6827359	0.96249419	3587.2229
930.24268	2.6846776	0.96443784	3585.697
931.24365	2.6872034	0.96633977	3582.3552
932.24463	2.691875	0.96815902	3590.2129
933.24561	2.6953659	0.97001767	3586.4199
934.24658	2.6989427	0.97190458	3587.4834
935.24756	2.6989522	0.97390491	3589.3354
936.24854	2.7037616	0.97581995	3585.7339
937.24951	2.7058265	0.9775188	3584.741
938.25049	2.7127953	0.97924489	3585.3806
939.25146	2.7125218	0.98112702	3587.6567
940.25244	2.7141492	0.98292136	3587.748
941.25342	2.7174468	0.98460275	3581.5757
942.25439	2.7188492	0.98646826	3585.554
943.25537	2.7259457	0.98848492	3591.5283
944.25635	2.7267339	0.99054098	3585.8191
945.25732	2.7283845	0.9925583	3586.9915
946.2583	2.7313685	0.99459356	3580.0647
947.25928	2.7358742	0.99639934	3588.2222
948.26025	2.7371371	0.99841481	3585.5244
949.26123	2.7400193	1.000491	3587.5254
950.26221	2.7463627	1.0025767	3586.1665
951.26318	2.7473724	1.0044278	3587.4976
952.26416	2.7495582	1.0063252	3581.0969
953.26514	2.7530127	1.0081079	3583.7795
954.26611	2.758966	1.0099565	3593.4373
955.26709	2.7594268	1.0119718	3584.7405
956.26807	2.76261	1.013968	3586.3162
957.26904	2.7662315	1.0158943	3582.7522
958.27002	2.7720599	1.0179425	3587.4705
959.271	2.7717369	1.0198402	3585.1699
960.27197	2.773442	1.0217239	3587.9241
961.27295	2.7741785	1.0237293	3584.4683
962.27393	2.7812986	1.0256341	3590.3606
963.2749	2.7830951	1.0274829	3583.3066
964.27588	2.7860415	1.0294906	3586.8608
965.27686	2.7909715	1.0314244	3589.4146
966.27783	2.7955983	1.0335206	3585.0803
967.27881	2.7972198	1.0355433	3590.8059
968.27979	2.8012357	1.0375911	3591.3569
969.28076	2.802681	1.0398017	3588.0076
970.28174	2.80582	1.0419656	3590.6592
971.28271	2.8076346	1.0440226	3592.6023
972.28369	2.8102813	1.0464846	3589.1868
973.28467	2.8156474	1.049013	3595.2173
974.28564	2.8144999	1.0514108	3587.3921
975.28662	2.819628	1.0532688	3581.6714
976.2876	2.8219507	1.0552187	3581.1069
977.28857	2.827415	1.0570216	3579.7639
978.28955	2.8308213	1.0587029	3588.2112
979.29053	2.8318508	1.0602484	3577.4724
980.2915	2.835429	1.062312	3595.3596
981.29248	2.8373744	1.0645874	3588.1702
982.29346	2.8428135	1.0665938	3582.5718
983.29443	2.8451636	1.0686257	3585.5513
984.29541	2.847682	1.0706819	3586.9167
985.29639	2.8491488	1.0725511	3590.8279
986.29736	2.8523266	1.075075	3586.073
987.29834	2.8579655	1.0774711	3585.5103
988.29932	2.8615639	1.0797683	3593.2864
989.30029	2.8601673	1.0818995	3585.2856
990.30127	2.8653538	1.0841143	3586.8337
991.30225	2.8701582	1.0860314	3587.2654
992.30322	2.8697293	1.0884421	3583.7603
993.3042	2.8707151	1.0906717	3578.7771
994.30518	2.8786812	1.0930177	3586.9902
995.30615	2.8812957	1.0951333	3578.7383
996.30713	2.8824439	1.0970442	3583.3481
997.30811	2.8885667	1.0988265	3578.8428
998.30908	2.8904998	1.1006887	3580.8474
999.31006	2.8926191	1.1026263	3585.9492
1000.311	2.895458	1.1050954	3589.137
1001.312	2.8999596	1.1073046	3584.9949
1002.313	2.9039495	1.1095016	3584.8149
1003.314	2.9051714	1.1118503	3586.7065
1004.3149	2.9060519	1.1143342	3584.7112
1005.3159	2.9097571	1.1170058	3588.2502
1006.3169	2.9112883	1.1194829	3582.6558
1007.3179	2.9164081	1.1219306	3583.4023
1008.3188	2.9172976	1.1242141	3579.7329
1009.3198	2.9213262	1.1269106	3588.5146
1010.3208	2.924943	1.1293592	3580.196
1011.3218	2.9305794	1.1313001	3579.9175
1012.3228	2.9306741	1.1331804	3579.3076
1013.3237	2.9336486	1.1354625	3583.0569
1014.3247	2.9364142	1.1380649	3588.4146
1015.3257	2.9393268	1.140633	3581.5579
1016.3267	2.9427149	1.1431139	3584.7336
1017.3276	2.9442794	1.1452914	3576.4429
1018.3286	2.9505782	1.1477696	3582.114
1019.3296	2.9536364	1.1501206	3580.4153
1020.3306	2.9539385	1.1522774	3574.6841
1021.3315	2.9561503	1.1543856	3572.2307
1022.3325	2.9604907	1.1564335	3578.3599
1023.3335	2.964956	1.1586921	3579.1775
1024.3345	2.9680593	1.1608105	3579.8528
1025.3354	2.973201	1.1633356	3581.1848
1026.3364	2.9741311	1.1656059	3575.9509
1027.3374	2.9768305	1.168043	3586.5903
1028.3384	2.9780278	1.1703105	3576.9036
1029.3394	2.9820421	1.1725786	3580.7222
1030.3403	2.9855218	1.1752279	3576.3933
1031.3413	2.9863811	1.1777596	3578.0085
1032.3423	2.9897768	1.1804304	3577.249
1033.3433	2.9949629	1.1832681	3582.8408
1034.3442	2.9962428	1.185926	3573.4446
1035.3452	2.9994972	1.1881621	3566.2322
1036.3462	3.0062742	1.1898472	3572.4436
1037.3472	3.0073249	1.1913122	3568.0059
1038.3481	3.0118256	1.1931032	3579.2983
1039.3491	3.0124841	1.1948912	3569.5938
1040.3501	3.0146451	1.1970124	3579.6423
1041.3511	3.0184066	1.1995288	3580.7771
1042.3521	3.0190525	1.2021863	3576.9465
1043.353	3.0247195	1.2046515	3572.5696
1044.354	3.0296838	1.2071915	3572.7168
1045.355	3.0286984	1.2100285	3579.4568
1046.356	3.0356796	1.2132434	3577.0706
1047.3569	3.0363753	1.2157614	3570.9993
1048.3579	3.0393448	1.2183524	3571.3701
1049.3589	3.0437346	1.2209283	3575.325
1050.3599	3.0464926	1.2237467	3574.175
1051.3608	3.049814	1.2262639	3571.7219
1052.3618	3.0525439	1.2287235	3565.7705
1053.3628	3.0536935	1.2314667	3573.1462
1054.3638	3.0557287	1.2340027	3567.3115
1055.3647	3.0601683	1.2362186	3568.334
1056.3657	3.0650921	1.2385342	3566.2104
1057.3667	3.0674741	1.2413096	3574.4004
1058.3677	3.0701189	1.2449573	3576.5645
1059.3687	3.0730186	1.2474544	3562.5266
1060.3696	3.0738289	1.2494681	3558.4575
1061.3706	3.0797603	1.2517326	3563.7244
1062.3716	3.0822163	1.2542871	3574.8359
1063.3726	3.0829284	1.2573783	3569.5779
1064.3735	3.0877826	1.2597768	3557.1912
1065.3745	3.0877063	1.2623217	3558.9502
1066.3755	3.0941601	1.2649038	3566.3032
1067.3765	3.0965023	1.2678641	3567.917
1068.3774	3.1004057	1.2707033	3560.4502
1069.3784	3.1042533	1.2732441	3560.7432
1070.3794	3.1067865	1.2760929	3566.8352
1071.3804	3.1090539	1.2789896	3558.9717
1072.3813	3.1092348	1.2816998	3552.3257
1073.3823	3.1152496	1.2839524	3557.4651
1074.3833	3.118356	1.2866007	3554.886
1075.3843	3.1186635	1.2891644	3559.8501
1076.3853	3.124789	1.2918274	3561.1123
1077.3862	3.1271033	1.2944026	3557.3489
1078.3872	3.1278598	1.2972478	3558.1597
1079.3882	3.1320789	1.3004221	3565.4592
1080.3892	3.1335871	1.3038197	3556.5923
1081.3901	3.1389844	1.3071351	3553.6821
1082.3911	3.1426897	1.3100443	3557.0964
1083.3921	3.1430967	1.3129238	3548.1558
1084.3931	3.1462259	1.3155512	3551.5762
1085.394	3.1504598	1.3178819	3545.6309
1086.395	3.1551175	1.3203837	3547.4978
1087.396	3.1551995	1.3230784	3555.5178
1088.397	3.1587393	1.3263054	3548.7876
1089.3979	3.1629682	1.3296487	3547.0999
1090.3989	3.1654968	1.3324919	3541.1399
1091.3999	3.1687882	1.3350734	3542.842
1092.4009	3.1707935	1.3380286	3549.7034
1093.4019	3.1741512	1.3413738	3545.7026
1094.4028	3.1776171	1.3445591	3545.416
1095.4038	3.1777446	1.3476166	3545.3308
1096.4048	3.1841793	1.3507485	3539.5459
1097.4058	3.187722	1.353495	3540.5337
1098.4067	3.1900134	1.3561141	3535.8186
1099.4077	3.1913292	1.358884	3538.3289
1100.4087	3.1950192	1.3618286	3542.8972
1101.4097	3.1974485	1.3651503	3537.801
1102.4106	3.2043204	1.367933	3533.1675
1103.4116	3.2050111	1.3708909	3535.9146
1104.4126	3.2062774	1.3739398	3533.8713
1105.4136	3.2117918	1.3770261	3535.8022
1106.4146	3.2139783	1.3801829	3534.8645
1107.4155	3.2168329	1.383221	3529.8806
1108.4165	3.2195132	1.3858492	3532.8066
1109.4175	3.2207751	1.3884152	3530.0359
1110.4185	3.2246199	1.3912904	3531.4023
1111.4194	3.2289464	1.3943019	3529.5166
1112.4204	3.2308233	1.3974301	3523.9231
1113.4214	3.2350507	1.400552	3520.4951
1114.4224	3.2394133	1.4034457	3522.6021
1115.4233	3.2397497	1.4062856	3519.9214
1116.4243	3.2444201	1.4094646	3526.8777
1117.4253	3.2472613	1.4125217	3523.9045
1118.4263	3.2512515	1.4156163	3518.2246
1119.4272	3.2523735	1.4189516	3522.064
1120.4282	3.2567053	1.4221076	3513.5061
1121.4292	3.2575667	1.425063	3513.55
1122.4302	3.2616737	1.4278859	3515.0198
1123.4312	3.264261	1.4307442	3511.9846
1124.4321	3.2680771	1.4339489	3508.2654
1125.4331	3.2720962	1.4370831	3511.0027
1126.4341	3.2716074	1.4402205	3510.8677
1127.4351	3.2760677	1.4437892	3508.094
1128.436	3.2777925	1.4470409	3503.0005
1129.437	3.2828774	1.4503354	3505.6213
1130.438	3.2849739	1.4535758	3498.5266
1131.439	3.2845595	1.4567264	3497.1719
1132.4399	3.2948241	1.4597783	3501.5474
1133.4409	3.2951009	1.4628549	3497.2798
1134.4419	3.2989607	1.4652536	3495.7537
1135.4429	3.3009458	1.4681876	3494.0671
1136.4438	3.3040268	1.4711794	3493.4233
1137.4448	3.3036001	1.4743141	3491.4138
1138.4458	3.3124695	1.4780252	3493.9412
1139.4468	3.3136284	1.4809535	3482.4177
1140.4478	3.3147206	1.4837528	3488.5105
1141.4487	3.3202724	1.4866616	3486.5613
1142.4497	3.3204138	1.4893496	3474.7966
1143.4507	3.3244822	1.4921331	3484.0999
1144.4517	3.3275659	1.4956195	3484.5042
1145.4526	3.3312731	1.499033	3477.1353
1146.4536	3.3372173	1.5020012	3473.1453
1147.4546	3.3400002	1.5051055	3480.1895
1148.4556	3.3394513	1.5087222	3473.9468
1149.4565	3.3429842	1.5120322	3467.323
1150.4575	3.3459957	1.5151502	3467.0198
1151.4585	3.3480234	1.5184008	3471.4158
1152.4595	3.3517525	1.5223626	3471.5212
1153.4604	3.3555858	1.525715	3456.8679
1154.4614	3.3598685	1.5283287	3456.4951
1155.4624	3.3625247	1.5312451	3461.2981
1156.4634	3.3651812	1.534669	3457.3877
1157.4644	3.3679159	1.5382161	3449.4556
1158.4653	3.3710825	1.5415462	3460.3782
1159.4663	3.374933	1.5447493	3446.8027
1160.4673	3.3788712	1.5476729	3450.0876
1161.4683	3.3795178	1.5511096	3449.3425
1162.4692	3.382303	1.5547535	3444.3684
1163.4702	3.3823688	1.5584739	3438.9163
1164.4712	3.3883493	1.561401	3432.9316
1165.4722	3.3907044	1.5640793	3429.9314
1166.4731	3.3933389	1.5667803	3432.6257
1167.4741	3.3959553	1.5702959	3437.2905
1168.4751	3.4014409	1.5734904	3425.488
1169.4761	3.4014962	1.5760665	3421.9163
1170.4771	3.4051261	1.578892	3423.1069
1171.478	3.4074526	1.582023	3422.0076
1172.479	3.4111254	1.58521	3418.1826
1173.48	3.4139111	1.5889578	3416.0215
1174.481	3.4171987	1.5923257	3409.8853
1175.4819	3.4217441	1.5950401	3406.6475
1176.4829	3.4257133	1.5982252	3412.7231
1177.4839	3.4279768	1.6013739	3406.8628
1178.4849	3.4309974	1.6045908	3402.9155
1179.4858	3.4317901	1.607995	3399.1943
1180.4868	3.4361506	1.6113751	3389.5742
1181.4878	3.4399323	1.6145915	3395.0557
1182.4888	3.4418671	1.6176081	3387.4553
1183.4897	3.443629	1.6206123	3384.7415
1184.4907	3.4484408	1.6239212	3388.9458
1185.4917	3.4499578	1.6272898	3377.2681
1186.4927	3.4527879	1.6307573	3382.4004
1187.4937	3.4552827	1.6346822	3372.8005
1188.4946	3.4611814	1.6381726	3369.2883
1189.4956	3.4628916	1.6410885	3366.9875
1190.4966	3.4677415	1.6440603	3365.4397
1191.4976	3.4685495	1.6475815	3365.4302
1192.4985	3.4717119	1.6510028	3361.6643
1193.4995	3.477561	1.6547444	3357.0933
1194.5005	3.4773831	1.658103	3354.3735
1195.5015	3.4840136	1.6610428	3345.7603
1196.5024	3.484715	1.6639072	3342.8459
1197.5034	3.488028	1.6673744	3339.0068
1198.5044	3.4906497	1.6706573	3339.0884
1199.5054	3.4924307	1.6739537	3331.7444
1200.5063	3.4998479	1.6772208	3336.4094
1201.5073	3.4984591	1.6799809	3325.3333
1202.5083	3.4998808	1.6834362	3326.5356
1203.5093	3.5027342	1.6870295	3317.572
1204.5103	3.5077333	1.6907134	3320.6563
1205.5112	3.5117207	1.6946669	3310.8347
1206.5122	3.5136294	1.6984158	3303.3213
1207.5132	3.5180781	1.7015609	3299.1389
1208.5142	3.5202913	1.7042906	3291.7661
1209.5151	3.5245512	1.7068425	3292.9302
1210.5161	3.5275118	1.710016	3289.5049
1211.5171	3.5259478	1.7135934	3284.8149
1212.5181	3.5350778	1.7173662	3276.936
1213.519	3.5358362	1.7207786	3270.9622
1214.52	3.5393889	1.7240735	3268.0723
1215.521	3.5428669	1.7279377	3265.054
1216.522	3.5479293	1.7317303	3257.4517
1217.5229	3.5482385	1.7353836	3252.854
1218.5239	3.5527198	1.7394532	3245.5186
1219.5249	3.5535328	1.7428527	3234.3174
1220.5259	3.5565808	1.7464143	3225.7222
1221.5269	3.558634	1.749384	3214.0173
1222.5278	3.5616887	1.7530675	3213.5706
1223.5288	3.5638297	1.7596141	3178.4773
1224.5298	3.5677011	1.7648998	3155.6448
1225.5308	3.5727303	1.7708077	3116.8433
1226.5317	3.5742667	1.7768928	3078.1597
1227.5327	3.5822937	1.7842122	3032.9775
1227.6328	3.5824456	1.7880425	2989.6909