File: datasets/am_bench_2022/raw_data/45-XY.13-1/specimen.dat
MTS793|MPT|ENU|1|2|.|/|:|1|0|0|A

Operator Information						Time:	30.886963	Sec	10/19/2021 2:55:47 PM
Operator	Newell Moser
Project	AM Bench 2022 mini-tensile challenge
Specimen ID	45-XY.13-1
Material	PBF-L Inconel 625
Specimen Width	2.55	mm
Specimen Thickness	1.51	mm
Notes
Operator Information End

Data Acquisition						Time:	1031.8816	Sec	10/19/2021 3:12:28 PM
Time	Axial Displacement	Axial Extensometer	Axial Force
Sec	mm	mm	N
31.001465	-0.00098774314	0.00023000095	70.475166
32.002441	0.003607705	0.00022027273	84.538795
33.003418	0.0016294828	0.00014237933	91.154694
34.004395	0.00477082	0.00028064181	102.34769
35.005371	0.0069324197	0.00034688716	117.59308
36.006348	0.014211274	0.00045258424	134.44643
37.007324	0.01209726	0.00054329255	146.15201
38.008301	0.017117856	0.00062149839	163.54654
39.009277	0.02134281	0.0007600559	178.42624
40.010254	0.021115381	0.00082258863	197.18526
41.01123	0.026649896	0.00088369125	224.18246
42.012207	0.030259	0.00098874909	240.93333
43.013184	0.032699816	0.0010716305	269.45566
44.01416	0.035399407	0.0012384139	288.85867
45.015137	0.038739335	0.001293258	314.10968
46.016113	0.038862679	0.0013930933	339.80072
47.01709	0.042455595	0.0014666112	356.07062
48.018066	0.047954768	0.001620638	382.95267
49.019043	0.050967485	0.001798428	411.72055
50.02002	0.051248595	0.0018810595	432.7406
51.020996	0.056874439	0.002132646	472.41043
52.021973	0.060548902	0.0021824387	492.84036
53.022949	0.061521262	0.0023457308	521.51947
54.023926	0.066233344	0.0023228894	554.336
55.024902	0.063998602	0.0025378794	580.70355
56.025879	0.07008791	0.0026998601	606.89441
57.026855	0.07669124	0.0027633721	638.3866
58.027832	0.075355142	0.0028052838	656.90985
59.028809	0.07699243	0.0028977827	680.77991
60.029785	0.08332146	0.0031184515	710.99823
61.030762	0.085148625	0.0032418522	732.43243
62.031738	0.086998582	0.0034228056	759.61029
63.032715	0.093563445	0.0034396835	790.05341
64.033691	0.095668443	0.0034729659	815.53485
65.034668	0.095725812	0.0036499694	839.31586
66.035645	0.098557763	0.0038162619	873.54712
67.036621	0.10447025	0.0040235552	908.29614
68.037598	0.10268483	0.0040926319	932.68225
69.038574	0.1087518	0.0041978704	957.01471
70.039551	0.11423238	0.0043591019	988.33203
71.040527	0.11264223	0.0045184097	1008.4809
72.041504	0.11974165	0.0046825553	1047.0566
73.04248	0.12177063	0.0047523319	1077.6122
74.043457	0.12456637	0.0048390445	1105.2937
75.044434	0.12769398	0.0049704197	1130.2202
76.04541	0.12981434	0.0052161957	1159.2825
77.046387	0.13411951	0.0053438242	1200.2698
78.047363	0.13687627	0.0053828685	1221.9191
79.04834	0.13899991	0.0055384277	1251.1849
80.049316	0.14606942	0.0056797033	1289.7288
81.050293	0.14890896	0.0057927314	1313.0781
82.05127	0.1459682	0.0059275567	1336.4913
83.052246	0.15213224	0.006058529	1366.2242
84.053223	0.15444095	0.0061448324	1392.0457
85.054199	0.15793307	0.0062867347	1426.342
86.055176	0.15865982	0.0064074583	1457.2598
87.056152	0.16360767	0.006505671	1480.6293
88.057129	0.16576943	0.00658275	1501.3771
89.058105	0.17256439	0.0067720548	1533.1232
90.059082	0.17152272	0.0069428775	1558.6273
91.060059	0.17280656	0.0069917724	1583.9791
92.061035	0.17631076	0.0070964051	1610.2321
93.062012	0.18195684	0.0072607379	1637.1666
94.062988	0.18385495	0.0073919208	1666.2611
95.063965	0.18710452	0.0074447528	1693.9054
96.064941	0.18724406	0.0075924289	1715.9465
97.065918	0.19314255	0.0077469749	1744.9174
98.066895	0.1923023	0.0078696832	1770.1133
99.067871	0.19601426	0.0079855602	1798.1294
100.06885	0.20233263	0.0080802357	1822.8608
101.06982	0.20293398	0.0082146134	1851.4768
102.0708	0.20699877	0.0083465986	1879.6379
103.07178	0.21097524	0.0083877575	1901.5759
104.07275	0.21523635	0.0085319821	1926.2571
105.07373	0.21799475	0.0086674057	1953.8903
106.07471	0.21997887	0.0087502785	1974.0972
107.07568	0.22320728	0.0088347327	1999.4298
108.07666	0.22601634	0.0090248045	2021.714
109.07764	0.23033641	0.0091830362	2045.3419
110.07861	0.23104452	0.0092000216	2062.6772
111.07959	0.23365088	0.0093665663	2084.8225
112.08057	0.23660229	0.0094868857	2105.3416
113.08154	0.24142398	0.0096462639	2121.3174
114.08252	0.24671786	0.0097926697	2142.7473
115.0835	0.24888375	0.0098389788	2157.5049
116.08447	0.25201833	0.0099356044	2177.458
117.08545	0.25247011	0.010019891	2196.8
118.08643	0.258625	0.010000362	2212.2385
119.0874	0.25952873	0.010173004	2227.9475
120.08838	0.26286963	0.010317906	2245.7798
121.08936	0.26576596	0.010381991	2263.0471
122.09033	0.26772818	0.010527438	2280.6267
123.09131	0.27501667	0.010671437	2296.2263
124.09229	0.27585223	0.010714713	2307.8896
125.09326	0.27936298	0.010882805	2332.8909
126.09424	0.28135082	0.010901359	2333.021
127.09521	0.28407255	0.011057149	2352.27
128.09619	0.28767142	0.011147168	2364.6895
129.09717	0.29205337	0.011271305	2379.907
130.09814	0.2947776	0.011458647	2390.4324
131.09912	0.29692787	0.011577033	2402.2944
132.1001	0.29844633	0.011696424	2420.5249
133.10107	0.3031919	0.011682108	2429.7207
134.10205	0.30487755	0.011942587	2444.7747
135.10303	0.30718708	0.011943886	2454.2209
136.104	0.31343532	0.012046829	2465.4634
137.10498	0.31455547	0.012255517	2478.5889
138.10596	0.31631503	0.012337469	2485.843
139.10693	0.32283401	0.012470134	2501.5691
140.10791	0.32664981	0.012636766	2511.3562
141.10889	0.32563648	0.012783309	2522.5066
142.10986	0.32637343	0.012755151	2523.7202
143.11084	0.33128336	0.013023752	2542.7793
144.11182	0.33736488	0.013100105	2556.9678
145.11279	0.33817217	0.013174651	2559.979
146.11377	0.34228468	0.013421071	2574.0688
147.11475	0.34419361	0.013605483	2580.1086
148.11572	0.34758374	0.013679205	2587.259
149.1167	0.34955397	0.013774361	2600.1492
150.11768	0.3523857	0.014108677	2614.5896
151.11865	0.35969284	0.014266663	2615.7888
152.11963	0.35875198	0.014424033	2624.2375
153.12061	0.36315426	0.014451095	2631.959
154.12158	0.36291108	0.014693556	2640.1594
155.12256	0.37015912	0.014785613	2648.7209
156.12354	0.37198451	0.01504973	2660.6272
157.12451	0.37354127	0.015284914	2673.0129
158.12549	0.3752189	0.015431701	2673.7112
159.12646	0.38109016	0.015733398	2682.3042
160.12744	0.38470542	0.015949979	2691.4031
161.12842	0.38850963	0.01616188	2702.7043
162.12939	0.38746265	0.016370339	2700.7314
163.13037	0.39464703	0.01681626	2718.2373
164.13135	0.39622673	0.016978716	2723.1411
165.13232	0.39977479	0.017274342	2736.3445
166.1333	0.40268978	0.017623832	2744.0496
167.13428	0.40466651	0.017937295	2746.2197
168.13525	0.40788797	0.018172331	2746.3965
169.13623	0.40849197	0.018576447	2756.4858
170.13721	0.41259548	0.018943336	2767.321
171.13818	0.41573626	0.019327931	2773.0361
172.13916	0.42160198	0.01971123	2779.7061
173.14014	0.42582431	0.020057103	2788.8997
174.14111	0.42796808	0.02048411	2787.449
175.14209	0.43131924	0.020897517	2798.6438
176.14307	0.43249634	0.021410437	2808.981
177.14404	0.43719396	0.021918327	2811.9336
178.14502	0.43970615	0.022310434	2815.6968
179.146	0.43896094	0.022834679	2817.0237
180.14697	0.44482508	0.02345698	2825.4226
181.14795	0.44641197	0.024035987	2831.2686
182.14893	0.45138806	0.024585944	2844.343
183.1499	0.45465505	0.025181843	2842.1157
184.15088	0.4574585	0.02578944	2843.6316
185.15186	0.45877656	0.026340872	2847.989
186.15283	0.46212915	0.026872562	2860.9336
187.15381	0.46502054	0.027585579	2862.0649
188.15479	0.46797177	0.02831996	2871.9944
189.15576	0.46968937	0.029180489	2871.8125
190.15674	0.47379041	0.029710626	2869.2747
191.15771	0.47925395	0.030438755	2876.1816
192.15869	0.48193944	0.031210084	2885.7356
193.15967	0.4836888	0.031904697	2883.3291
194.16064	0.48477346	0.032607298	2891.4619
195.16162	0.48839709	0.033362508	2890.8118
196.1626	0.4908914	0.034266997	2893.8054
197.16357	0.49636996	0.035036165	2898.1738
198.16455	0.49845365	0.035915714	2907.2024
199.16553	0.50336301	0.036738344	2909.0066
200.1665	0.50468308	0.037597939	2915.0645
201.16748	0.50913781	0.038507737	2916.2266
202.16846	0.51050484	0.039472729	2919.3057
203.16943	0.51449353	0.040764578	2929.4558
204.17041	0.51545	0.041690372	2930.0085
205.17139	0.51953936	0.042590886	2929.2275
206.17236	0.52131021	0.043567397	2938.8413
207.17334	0.52643472	0.044596154	2944.3489
208.17432	0.52894515	0.045755446	2942.8149
209.17529	0.53218627	0.046864454	2945.8909
210.17627	0.53474766	0.047804166	2953.7986
211.17725	0.5366357	0.048764668	2954.2439
212.17822	0.53963917	0.049826212	2954.3123
213.1792	0.54536349	0.051061772	2963.5217
214.18018	0.54834914	0.052123353	2962.8674
215.18115	0.55088776	0.053172503	2962.0972
216.18213	0.55290711	0.054166175	2964.5063
217.18311	0.5586921	0.055218216	2973.498
218.18408	0.55635005	0.056226473	2966.854
219.18506	0.5625037	0.057232805	2974.0889
220.18604	0.56330216	0.058400542	2970.3682
221.18701	0.56685859	0.059498966	2981.3091
222.18799	0.56949896	0.060493909	2973.8574
223.18896	0.57084882	0.061668586	2989.1707
224.18994	0.5756098	0.062753774	2988.5635
225.19092	0.57927138	0.063899137	2988.5347
226.19189	0.58352953	0.065027781	2992.7581
227.19287	0.58703619	0.066130102	2991.1846
228.19385	0.58954901	0.06723085	2999.7134
229.19482	0.58974403	0.06838382	2999.7537
230.1958	0.59477162	0.069597565	3002.7786
231.19678	0.59935963	0.070708774	3002.8447
232.19775	0.60222197	0.071737416	3002.9661
233.19873	0.60403484	0.07284686	3009.0059
234.19971	0.60852081	0.074166954	3012.9729
235.20068	0.60761178	0.075382233	3012.6355
236.20166	0.60982722	0.076439366	3005.9729
237.20264	0.61621159	0.077424504	3018.8384
238.20361	0.61970037	0.078535795	3017.0083
239.20459	0.62434542	0.079838939	3023.6738
240.20557	0.62399548	0.081192695	3023.4553
241.20654	0.62900257	0.082358561	3025.375
242.20752	0.63004482	0.083569311	3026.0132
243.2085	0.6333884	0.08492142	3038.6672
244.20947	0.63781929	0.086207196	3033.4033
245.21045	0.63877034	0.087599076	3042.9919
246.21143	0.64016283	0.08900746	3032.5134
247.2124	0.64485687	0.090220056	3035.0444
248.21338	0.65001875	0.091482356	3044.7263
249.21436	0.64989275	0.092580602	3040.6514
250.21533	0.65464395	0.093805842	3045.7456
251.21631	0.65832418	0.095048584	3049.2568
252.21729	0.66060048	0.096164592	3046.5571
253.21826	0.6621865	0.097473815	3051.7322
254.21924	0.66731834	0.098696254	3052.6172
255.22021	0.6682471	0.09976998	3043.2742
256.22119	0.67247498	0.10095499	3055.3462
257.22217	0.67808259	0.10212865	3057.2944
258.22314	0.67845654	0.10323245	3055.3923
259.22412	0.68269569	0.10454179	3062.4438
260.2251	0.6845786	0.10573369	3059.592
261.22607	0.68606853	0.10698809	3059.9922
262.22705	0.69390118	0.1082538	3069.1821
263.22803	0.6919046	0.10941572	3070.311
264.229	0.69385344	0.11055882	3062.8784
265.22998	0.69879216	0.11172149	3066.3625
266.23096	0.70265079	0.11275987	3073.1287
267.23193	0.70527667	0.11421391	3078.6665
268.23291	0.70985097	0.11522437	3073.2305
269.23389	0.71411592	0.11646666	3078.9438
270.23486	0.71586055	0.11792467	3084.0303
271.23584	0.72124398	0.11911977	3087.4138
272.23682	0.71875423	0.12023175	3077.5291
273.23779	0.7246331	0.12142929	3086.6355
274.23877	0.7263279	0.12278423	3093.7217
275.23975	0.7309078	0.12417731	3091.5244
276.24072	0.73434973	0.12562285	3097.8372
277.2417	0.73675448	0.12684619	3090.6663
278.24268	0.73893476	0.12785366	3089.8462
279.24365	0.7417618	0.12920411	3096.1108
280.24463	0.74608654	0.13056439	3106.3206
281.24561	0.74896747	0.13210544	3100.7114
282.24658	0.7518177	0.13325305	3104.0474
283.24756	0.75483817	0.13463372	3100.9507
284.24854	0.76028633	0.13596904	3104.0176
285.24951	0.7605539	0.13717689	3103.1509
286.25049	0.7618255	0.1385618	3104.908
287.25146	0.77003169	0.13973957	3110.9556
288.25244	0.76921505	0.14098194	3111.0339
289.25342	0.77420443	0.14226468	3116.335
290.25439	0.77820837	0.14364862	3118.4749
291.25537	0.77653998	0.14478971	3116.3237
292.25635	0.78338587	0.14626211	3121.9934
293.25732	0.78422469	0.14730062	3117.3438
294.2583	0.78633833	0.14857866	3120.5125
295.25928	0.7895838	0.14998946	3124.7476
296.26025	0.79244286	0.15118521	3121.9177
297.26123	0.79750127	0.15212367	3121.1814
298.26221	0.79748344	0.15317591	3122.4014
299.26318	0.80239135	0.15449044	3133.9946
300.26416	0.8027665	0.15584248	3128.2727
301.26514	0.80800045	0.15712009	3129.0552
302.26611	0.80982512	0.15817405	3122.8958
303.26709	0.81520224	0.15915687	3140.7776
304.26807	0.81849092	0.16043089	3131.6917
305.26904	0.82008636	0.16161613	3136.324
306.27002	0.82519382	0.16299327	3139.2695
307.271	0.82889289	0.16432039	3143.8264
308.27197	0.8312518	0.16572686	3149.6982
309.27295	0.83400977	0.16690469	3145.8096
310.27393	0.83395982	0.16821861	3144.9863
311.2749	0.83878368	0.16965905	3151.2637
312.27588	0.84333795	0.17111038	3150.1045
313.27686	0.84509861	0.17249434	3153.0425
314.27783	0.84769839	0.1738193	3149.8542
315.27881	0.85118151	0.17502308	3154.6038
316.27979	0.85397941	0.17630973	3152.5549
317.28076	0.85497439	0.17763899	3153.3416
318.28174	0.85508299	0.17885484	3154.2402
319.28271	0.85989892	0.17995018	3157.2935
320.28369	0.86776233	0.18122938	3160.071
321.28467	0.87093645	0.18257099	3162.1707
322.28564	0.86845076	0.18381351	3158.6506
323.28662	0.87567371	0.18524313	3171.3008
324.2876	0.87611812	0.18667516	3165.7832
325.28857	0.88045698	0.18812294	3162.8911
326.28955	0.88364512	0.18935469	3166.5515
327.29053	0.88473082	0.19053483	3170.1519
328.2915	0.88704461	0.19188225	3177.7705
329.29248	0.89288455	0.19327565	3175.3459
330.29346	0.89470309	0.19458041	3172.1992
331.29443	0.89966863	0.19588476	3176.5444
332.29541	0.89912814	0.19696838	3169.9829
333.29639	0.90348858	0.19801113	3171.1318
334.29736	0.90839028	0.19903466	3177.5974
335.29834	0.9113608	0.20000018	3177.1978
336.29932	0.91423661	0.20117371	3179.6826
337.30029	0.91801924	0.202446	3185.97
338.30127	0.9195981	0.20386986	3187.4885
339.30225	0.92104828	0.20524599	3188.0588
340.30322	0.92365801	0.20661807	3187.1104
341.3042	0.93181252	0.20816027	3195.2488
342.30518	0.93044329	0.20926808	3190.7458
343.30615	0.93426609	0.21040064	3190.8062
344.30713	0.93775415	0.21153432	3193.3489
345.30811	0.93954325	0.21294235	3197.7488
346.30908	0.94229424	0.21441695	3203.3286
347.31006	0.94450313	0.21570414	3197.885
348.31104	0.95008039	0.21697886	3199.1604
349.31201	0.95207912	0.21826799	3201.6228
350.31299	0.95487463	0.21963961	3201.2361
351.31396	0.95803314	0.2209143	3204.8494
352.31494	0.96041912	0.22242972	3204.7429
353.31592	0.96525347	0.2235776	3202.7429
354.31689	0.96898592	0.22473548	3207.896
355.31787	0.97071558	0.2261672	3212.3394
356.31885	0.97335434	0.22748475	3210.7126
357.31982	0.97606808	0.22863254	3203.8025
358.3208	0.97993785	0.22989295	3209.6638
359.32178	0.9827016	0.23123376	3218.0527
360.32275	0.98416531	0.23252004	3214.1309
361.32373	0.98390222	0.23377241	3213.384
362.32471	0.99032444	0.23505408	3212.8208
363.32568	0.99702656	0.23618047	3221.6438
364.32666	0.99697864	0.23750333	3220.9368
365.32764	1.0012647	0.23873103	3221.936
366.32861	1.0054173	0.24002936	3228.54
367.32959	1.0050162	0.24122223	3219.8801
368.33057	1.0079299	0.24246663	3221.1089
369.33154	1.0114884	0.24355167	3225.6541
370.33252	1.0158153	0.24456322	3223.7954
371.3335	1.0204459	0.24584341	3228.0432
372.33447	1.0185192	0.24705778	3227.343
373.33545	1.0244435	0.24813145	3229.3354
374.33643	1.0230019	0.24973856	3233.4175
375.3374	1.0326216	0.25104502	3234.3821
376.33838	1.0350637	0.25227475	3238.9202
377.33936	1.0363805	0.25370729	3234.0437
378.34033	1.040928	0.25514838	3238.9565
379.34131	1.0408752	0.25660494	3241.7612
380.34229	1.0445592	0.25779465	3230.563
381.34326	1.0480764	0.25894454	3241.9922
382.34424	1.0527894	0.26012239	3240.5369
383.34521	1.053582	0.26129708	3244.7764
384.34619	1.0591252	0.26252434	3249.5444
385.34717	1.0622756	0.26380879	3249.7773
386.34814	1.0661844	0.26523682	3256.7388
387.34912	1.0655999	0.26652852	3245.7349
388.3501	1.070201	0.26761493	3249.3428
389.35107	1.0722626	0.26882082	3250.033
390.35205	1.0745419	0.27013099	3255.4385
391.35303	1.0795094	0.2714431	3254.3069
392.354	1.0795105	0.27263519	3246.3633
393.35498	1.0851825	0.27369648	3254.4556
394.35596	1.0876515	0.27499881	3255.7031
395.35693	1.0917172	0.27635768	3257.4597
396.35791	1.0952213	0.27796164	3272.3879
397.35889	1.094699	0.27931538	3256.6887
398.35986	1.0978117	0.28031376	3256.9805
399.36084	1.1003346	0.28151429	3264.8225
400.36182	1.1060195	0.28284988	3266.6997
401.36279	1.1083134	0.28423861	3266.4126
402.36377	1.113602	0.28556645	3270.814
403.36475	1.1131833	0.28688806	3271.1099
404.36572	1.1164601	0.28815323	3264.4475
405.3667	1.1226428	0.28935227	3269.5151
406.36768	1.1236526	0.29041687	3273.584
407.36865	1.1266799	0.29161894	3272.4939
408.36963	1.1294919	0.29295132	3277.7903
409.37061	1.1349449	0.29420552	3276.2
410.37158	1.1372013	0.29537758	3278.4673
411.37256	1.1402941	0.29645839	3273.625
412.37354	1.1437126	0.2977621	3285.3794
413.37451	1.1461004	0.29902005	3284.8059
414.37549	1.1474921	0.30043119	3281.6472
415.37646	1.1507133	0.30168146	3286.2192
416.37744	1.1536783	0.30290785	3286.9097
417.37842	1.155683	0.30438089	3289.989
418.37939	1.1603361	0.30577484	3289.9214
419.38037	1.1620437	0.30688292	3282.2991
420.38135	1.1656787	0.30795521	3286.5347
421.38232	1.1700878	0.30917358	3289.4351
422.3833	1.170611	0.31042564	3289.0276
423.38428	1.1741644	0.31192189	3295.3599
424.38525	1.1785907	0.31333891	3295.6831
425.38623	1.1764807	0.31441125	3288.3022
426.38721	1.1846412	0.31568697	3294.27
427.38818	1.1904739	0.31692135	3301.1699
428.38916	1.1876209	0.31826562	3293.999
429.39014	1.1917925	0.31958163	3304.0173
430.39111	1.1955223	0.32099697	3299.0999
431.39209	1.2016599	0.32226393	3302.9451
432.39307	1.202036	0.32361132	3303.5303
433.39404	1.2061213	0.32491228	3305.6597
434.39502	1.2077419	0.32610354	3305.3008
435.396	1.2090219	0.32738885	3308.7981
436.39697	1.2176646	0.32863954	3307.5569
437.39795	1.2157247	0.32990709	3308.7437
438.39893	1.2203414	0.33106515	3308.907
439.3999	1.2226162	0.33234537	3307.4624
440.40088	1.2305565	0.33343196	3310.3994
441.40186	1.2292713	0.33458024	3311.8298
442.40283	1.2319735	0.33589375	3308.2781
443.40381	1.2346052	0.3369993	3312.8896
444.40479	1.2356499	0.33799204	3310.1797
445.40576	1.2435619	0.33898878	3312.918
446.40674	1.2436174	0.34003326	3318.8323
447.40771	1.2461979	0.34131739	3317.3667
448.40869	1.2474838	0.34256729	3318.3923
449.40967	1.2513255	0.34403181	3321.7847
450.41064	1.2560654	0.3453232	3320.0264
451.41162	1.2581776	0.34642959	3319.9104
452.4126	1.2617548	0.34763306	3325.8745
453.41357	1.2638979	0.3491247	3324.0781
454.41455	1.2650185	0.35030964	3319.2588
455.41553	1.2699736	0.3515071	3326.2563
456.4165	1.2725185	0.35281685	3329.9519
457.41748	1.2771677	0.35419405	3329.3423
458.41846	1.278886	0.35559836	3324.5642
459.41943	1.2842346	0.35698923	3333.0183
460.42041	1.2837799	0.35848388	3332.1125
461.42139	1.289785	0.35969147	3327.1101
462.42236	1.2887579	0.36088747	3328.4233
463.42334	1.2943956	0.3621124	3332.1748
464.42432	1.2998145	0.36329949	3338.5562
465.42529	1.2989988	0.36450356	3331.6367
466.42627	1.3036416	0.36578485	3340.6445
467.42725	1.3055161	0.36718667	3338.0022
468.42822	1.3110805	0.36865968	3342.3611
469.4292	1.3116146	0.37001306	3340.5271
470.43018	1.3154757	0.3712686	3342.4058
471.43115	1.3203638	0.37244487	3345.7107
472.43213	1.3223448	0.3737165	3347.123
473.43311	1.3255694	0.37505963	3343.5923
474.43408	1.3238255	0.37605789	3338.5186
475.43506	1.3308975	0.37712291	3340.521
476.43604	1.3310727	0.37822729	3344.2561
477.43701	1.3383229	0.37963697	3351.6328
478.43799	1.3379555	0.38090923	3350.6062
479.43896	1.3416294	0.38208869	3353.0991
480.43994	1.3465301	0.38337857	3354.7961
481.44092	1.348828	0.38449049	3353.2332
482.44189	1.3531486	0.38556468	3349.1055
483.44287	1.3557729	0.38672504	3351.8364
484.44385	1.3587976	0.38791311	3351.5044
485.44482	1.3590723	0.38932887	3355.8679
486.4458	1.3638417	0.3906686	3364.2942
487.44678	1.364117	0.39192277	3358.3657
488.44775	1.3692322	0.39321578	3358.5491
489.44873	1.3718846	0.39443576	3360.6069
490.44971	1.3776205	0.39575687	3360.668
491.45068	1.3788834	0.39709255	3364.6863
492.45166	1.3810368	0.39851338	3367.1926
493.45264	1.3844051	0.39969966	3362.1719
494.45361	1.3871092	0.40076303	3361.5693
495.45459	1.3886173	0.40195227	3363.3662
496.45557	1.3927548	0.40338185	3368.4177
497.45654	1.3959795	0.40472934	3370.0269
498.45752	1.3965424	0.40615901	3366.7444
499.4585	1.400093	0.40733263	3359.3599
500.45947	1.4069175	0.40840721	3365.4978
501.46045	1.4086434	0.40981349	3376.6162
502.46143	1.4120567	0.41112009	3375.1506
503.4624	1.4176198	0.41243005	3377.0444
504.46338	1.4189316	0.41386488	3377.9849
505.46436	1.423032	0.41513026	3381.5847
506.46533	1.4264889	0.41654772	3378.408
507.46631	1.4284554	0.41786724	3381.946
508.46729	1.4309872	0.41896874	3374.6826
509.46826	1.4310025	0.42015845	3377.8862
510.46924	1.435304	0.42150107	3380.1255
511.47021	1.4382294	0.42302883	3380.6914
512.47119	1.4422278	0.42415914	3375.1531
513.47217	1.4442368	0.42528254	3383.5598
514.47314	1.4486804	0.42653573	3388.7498
515.47412	1.4516344	0.42790383	3393.2258
516.4751	1.4533733	0.42923865	3387.6799
517.47607	1.4573423	0.43036494	3385.1792
518.47705	1.4609519	0.43174642	3388.6775
519.47803	1.4619638	0.43304005	3392.3086
520.479	1.4647467	0.43448797	3399.3125
521.47998	1.4698149	0.43585429	3390.2168
522.48096	1.4706271	0.43698871	3387.822
523.48193	1.4738075	0.43830702	3386.6487
524.48291	1.4777385	0.43947378	3392.5173
525.48389	1.4799142	0.44054148	3393.5266
526.48486	1.4807063	0.44176939	3390.4163
527.48584	1.4858308	0.44298103	3395.2146
528.48682	1.4889213	0.44424674	3394.21
529.48779	1.4941018	0.44560593	3402.9529
530.48877	1.4971875	0.44709918	3402.3225
531.48975	1.5001296	0.44847527	3401.2993
532.49072	1.4984369	0.44969091	3395.1123
533.4917	1.5047899	0.45110679	3402.4646
534.49268	1.5072185	0.45238978	3402.7505
535.49365	1.5105013	0.45385799	3406.2397
536.49463	1.5138789	0.45534804	3409.9907
537.49561	1.5179565	0.45668086	3409.0259
538.49658	1.5183864	0.45814708	3405.9534
539.49756	1.5241218	0.45951542	3409.678
540.49854	1.5276994	0.46082023	3412.7524
541.49951	1.5282276	0.46209532	3403.1597
542.50049	1.5307707	0.46325651	3403.9922
543.50146	1.5349002	0.46455544	3412.3374
544.50244	1.5379938	0.46580392	3412.8813
545.50342	1.5414113	0.46704498	3407.1865
546.50439	1.544484	0.46854427	3413.4971
547.50537	1.5471711	0.4697144	3410.7988
548.50635	1.549813	0.47081491	3412.5413
549.50732	1.553653	0.47198474	3415.2017
550.5083	1.5554556	0.473434	3417.3828
551.50928	1.556325	0.47472316	3412.0762
552.51025	1.5643111	0.4761574	3414.3308
553.51123	1.566581	0.47730935	3416.5867
554.51221	1.5663983	0.47849032	3417.5068
555.51318	1.5706432	0.47960228	3418.6362
556.51416	1.5725093	0.48093259	3423.3062
557.51514	1.5773876	0.48210615	3419.8198
558.51611	1.5806139	0.4834305	3420.6675
559.51709	1.5815172	0.48475415	3424.3696
560.51807	1.5853417	0.48591146	3418.8733
561.51904	1.5889912	0.48700854	3422.5718
562.52002	1.5908606	0.48833054	3427.3125
563.521	1.5928419	0.48988697	3430.834
564.52197	1.5970412	0.4915475	3429.1865
565.52295	1.6001664	0.493036	3426.8875
566.52393	1.6050102	0.49439135	3433.4736
567.5249	1.6081117	0.49563235	3425.0447
568.52588	1.6113392	0.49690193	3433.8906
569.52686	1.6133518	0.49833876	3434.0701
570.52783	1.6153154	0.49977583	3435.3716
571.52881	1.6201713	0.50110751	3432.1487
572.52979	1.6217443	0.50248349	3434.626
573.53076	1.62464	0.50380117	3433.6665
574.53174	1.6287422	0.50508004	3435.5947
575.53271	1.6281419	0.5063253	3432.8748
576.53369	1.6336997	0.50753403	3435.7646
577.53467	1.6377963	0.50896138	3441.5464
578.53564	1.6399025	0.51038867	3439.9543
579.53662	1.6440916	0.51157844	3446.709
580.5376	1.6471606	0.51293546	3443.0603
581.53857	1.6492217	0.51439661	3442.7168
582.53955	1.6519922	0.51572812	3437.1709
583.54053	1.6547582	0.51683706	3440.2197
584.5415	1.6588451	0.51823324	3443.5417
585.54248	1.6609759	0.5193826	3442.2849
586.54346	1.6659946	0.52069896	3441.4033
587.54443	1.6675314	0.52184713	3440.9006
588.54541	1.6704602	0.5231927	3449.4307
589.54639	1.6736835	0.52458984	3447.6711
590.54736	1.6771995	0.52581078	3449.7625
591.54834	1.6787447	0.52722651	3441.2266
592.54932	1.6837785	0.52836114	3451.2075
593.55029	1.6872625	0.52962518	3451.686
594.55127	1.6901271	0.53096426	3452.7024
595.55225	1.6915853	0.53233331	3452.3633
596.55322	1.6942236	0.53380591	3453.7854
597.5542	1.695807	0.53522068	3454.6848
598.55518	1.6983649	0.53680193	3452.5649
599.55615	1.7021768	0.53829861	3456.626
600.55713	1.7072412	0.53977269	3452.759
601.55811	1.7104133	0.54119551	3456.7324
602.55908	1.710979	0.54264611	3454.0491
603.56006	1.7144055	0.54404587	3459.9509
604.56104	1.7188551	0.54510331	3455.5513
605.56201	1.7224259	0.54640973	3456.5876
606.56299	1.7248291	0.54749441	3457.0413
607.56396	1.7274975	0.54881537	3463.2415
608.56494	1.7291497	0.55027062	3465.1086
609.56592	1.7345073	0.55158865	3461.3218
610.56689	1.7369511	0.55287278	3464.3499
611.56787	1.7402049	0.55436641	3467.4412
612.56885	1.7403293	0.55577952	3460.9744
613.56982	1.7449582	0.55720413	3464.7646
614.5708	1.7491992	0.55890149	3473.7156
615.57178	1.7535691	0.560534	3470.6555
616.57275	1.755074	0.56188214	3465.7749
617.57373	1.7566894	0.56319273	3462.7979
618.57471	1.7603685	0.56427771	3464.7146
619.57568	1.7622405	0.56550598	3467.0701
620.57666	1.7660707	0.56686592	3468.9949
621.57764	1.7707844	0.56835109	3467.5215
622.57861	1.7726117	0.569583	3467.937
623.57959	1.7733489	0.57084882	3468.9739
624.58057	1.7797282	0.57232481	3475.4343
625.58154	1.7818696	0.57381254	3472.5347
626.58252	1.7859048	0.57505995	3466.7893
627.5835	1.7858691	0.5761984	3473.3333
628.58447	1.7911531	0.57766002	3474.3379
629.58545	1.7922742	0.57871759	3473.2615
630.58643	1.7963972	0.58016896	3476.3254
631.5874	1.7978204	0.5816319	3481.5103
632.58838	1.8023272	0.58307546	3479.0037
633.58936	1.8051077	0.58459252	3469.9468
634.59033	1.8077255	0.58602864	3479.7461
635.59131	1.8106987	0.58745813	3479.948
636.59229	1.8151331	0.58904713	3481.1223
637.59326	1.8168876	0.59061426	3479.1729
638.59424	1.8194796	0.59204274	3478.9155
639.59521	1.8245851	0.59337544	3483.9734
640.59619	1.8274838	0.59467411	3477.7786
641.59717	1.8284752	0.59596592	3480.6484
642.59814	1.8310899	0.59729213	3476.0742
643.59912	1.8339962	0.59869355	3479.113
644.6001	1.8378084	0.600021	3481.4392
645.60107	1.8381437	0.6013025	3483.4246
646.60205	1.8451647	0.60277843	3488.5879
647.60303	1.8486933	0.60446876	3487.2424
648.604	1.8525417	0.60621428	3492.5139
649.60498	1.855765	0.60759676	3484.4631
650.60596	1.8571444	0.60895509	3489.0007
651.60693	1.8605844	0.61030567	3491.2615
652.60791	1.8607337	0.61177093	3485.3523
653.60889	1.8641583	0.61302572	3483.8521
654.60986	1.865917	0.61436182	3484.5632
655.61084	1.8733596	0.61567432	3490.0884
656.61182	1.8739699	0.61702889	3494.9348
657.61279	1.8755475	0.6184209	3492.8801
658.61377	1.8787254	0.61967391	3485.6187
659.61475	1.8845038	0.62103069	3487.2588
660.61572	1.8873709	0.62258953	3497.8198
661.6167	1.8877366	0.6240654	3494.1704
662.61768	1.8929589	0.62553561	3497.0833
663.61865	1.896961	0.62698716	3494.4788
664.61963	1.8994796	0.62827957	3491.7107
665.62061	1.9021349	0.62972826	3492.7102
666.62158	1.9040377	0.6311065	3494.1946
667.62256	1.9077311	0.63250285	3499.1228
668.62354	1.9094843	0.6338535	3495.3926
669.62451	1.9155451	0.63536572	3501.1445
670.62549	1.9174445	0.63666463	3499.6606
671.62646	1.9186885	0.63812155	3501.6277
672.62744	1.9232358	0.63959754	3504.6624
673.62842	1.9255348	0.64120561	3500.2993
674.62939	1.9254333	0.64278227	3496.8821
675.63037	1.9301755	0.64417231	3504.3438
676.63135	1.9348173	0.64568448	3501.1665
677.63232	1.938184	0.6470812	3507.4124
678.6333	1.9402778	0.64839745	3499.7834
679.63428	1.9435825	0.64991695	3509.9856
680.63525	1.9477526	0.65153515	3509.0405
681.63623	1.9483824	0.65325534	3503.644
682.63721	1.955254	0.65451807	3499.8774
683.63818	1.9551544	0.65596521	3504.4404
684.63916	1.9569348	0.6574862	3501.2415
685.64014	1.9605114	0.65897262	3507.293
686.64111	1.9651159	0.66038078	3505.157
687.64209	1.9682041	0.66167605	3508.6008
688.64307	1.9691157	0.66332304	3516.447
689.64404	1.9755926	0.66500688	3506.6863
690.64502	1.9772127	0.66662848	3508.6819
691.646	1.9791311	0.66789448	3507.6323
692.64697	1.9828	0.66922915	3510.6782
693.64795	1.9854076	0.67055601	3505.8862
694.64893	1.9863189	0.67199141	3509.8069
695.6499	1.9920585	0.6732046	3508.3186
696.65088	1.9949902	0.67479259	3518.8398
697.65186	1.9978774	0.6762349	3515.2954
698.65283	1.999272	0.67787844	3517.156
699.65381	2.0023813	0.67959589	3515.3262
700.65479	2.0045404	0.68145853	3514.0881
701.65576	2.009305	0.68281716	3512.6558
702.65674	2.0142031	0.68421417	3518.1426
703.65771	2.0167103	0.68575466	3519.251
704.65869	2.0177791	0.68715239	3515.0557
705.65967	2.022182	0.68862242	3515.5396
706.66064	2.0266461	0.68999249	3519.2351
707.66162	2.0263209	0.6917451	3523.6765
708.6626	2.0316372	0.69326985	3519.5693
709.66357	2.0335784	0.6948086	3514.2622
710.66455	2.0386016	0.69635141	3517.238
711.66553	2.0408139	0.69795841	3521.1099
712.6665	2.0419371	0.69955713	3519.937
713.66748	2.0481317	0.70110977	3524.8667
714.66846	2.0462015	0.70245534	3514.9458
715.66943	2.051456	0.70422029	3524.8438
716.67041	2.0535991	0.70561123	3521.0959
717.67139	2.0560684	0.70720041	3521.8403
718.67236	2.0645936	0.70872074	3525.1931
719.67334	2.0618067	0.71017289	3516.8843
720.67432	2.0670977	0.71167648	3522.5513
721.67529	2.0707259	0.7131955	3523.2905
722.67627	2.0729954	0.71490186	3530.1902
723.67725	2.0746031	0.71664685	3526.7849
724.67822	2.0802321	0.71835721	3530.7864
725.6792	2.0804651	0.71988839	3523.1042
726.68018	2.085906	0.7211743	3523.0513
727.68115	2.0876377	0.72243083	3528.552
728.68213	2.0906029	0.72385836	3532.2483
729.68311	2.0951197	0.72552401	3531.2061
730.68408	2.0966535	0.72724956	3531.3967
731.68506	2.0985632	0.72897059	3528.9653
732.68604	2.1034553	0.7304762	3523.7681
733.68701	2.1051865	0.73183119	3528.5168
734.68799	2.108264	0.73328763	3529.752
735.68896	2.113209	0.73476273	3529.6265
736.68994	2.115478	0.7363103	3529.9011
737.69092	2.1169665	0.73775995	3533.906
738.69189	2.1224694	0.73934901	3529.6909
739.69287	2.1225893	0.74074852	3526.3955
740.69385	2.1248271	0.74230427	3530.457
741.69482	2.1305592	0.74396145	3532.4355
742.6958	2.1320331	0.74568653	3538.2222
743.69678	2.1375926	0.74753392	3537.3975
744.69775	2.1403134	0.74938959	3533.3027
745.69873	2.1411762	0.75080168	3536.2361
746.69971	2.1474612	0.75246495	3535.905
747.70068	2.1464324	0.75398874	3527.4031
748.70166	2.1484716	0.75579637	3537.0388
749.70264	2.1532619	0.75762177	3537.6567
750.70361	2.1569092	0.75936157	3536.844
751.70459	2.1583757	0.76088721	3533.9756
752.70557	2.1618476	0.76235533	3532.426
753.70654	2.1656487	0.76388425	3533.9702
754.70752	2.1667559	0.76564658	3543.53
755.7085	2.170013	0.76705235	3534.8359
756.70947	2.1733234	0.76842266	3535.2156
757.71045	2.1772058	0.77027237	3539.7729
758.71143	2.18222	0.77181542	3540.2571
759.7124	2.1854277	0.77370393	3544.9429
760.71338	2.1864922	0.7755596	3539.8867
761.71436	2.1922979	0.77731961	3542.4016
762.71533	2.1941829	0.77887845	3540.9539
763.71631	2.1979074	0.78020406	3532.4126
764.71729	2.1983042	0.78128684	3530.1731
765.71826	2.2020948	0.78274685	3545.2788
766.71924	2.2057898	0.78427422	3548.7278
767.72021	2.2084305	0.78605688	3546.4946
768.72119	2.2101212	0.78782248	3542.4509
769.72217	2.2151198	0.78944522	3544.0698
770.72314	2.2172558	0.79089481	3541.0962
771.72412	2.2208829	0.79265034	3550.7854
772.7251	2.2235796	0.79441476	3545.0298
773.72607	2.2258477	0.79606378	3540.9453
774.72705	2.2314889	0.79773062	3547.8123
775.72803	2.235182	0.79932749	3547.2295
776.729	2.2341413	0.80085224	3542.2871
777.72998	2.2386281	0.80272418	3549.7896
778.73096	2.2409081	0.80443907	3548.2
779.73193	2.245394	0.80642098	3547.6819
780.73291	2.2457156	0.80809498	3544.7698
781.73389	2.2513282	0.80999249	3558.0073
782.73486	2.2514813	0.81170982	3544.4009
783.73584	2.2543235	0.81340057	3544.0557
784.73682	2.2590766	0.81502527	3551.8845
785.73779	2.2640307	0.81664628	3549.9346
786.73877	2.2657862	0.81858224	3550.4905
787.73975	2.2695405	0.82027853	3550.1963
788.74072	2.2723625	0.82197005	3548.8306
789.7417	2.2735052	0.82358468	3546.0374
790.74268	2.2752008	0.82503819	3545.4536
791.74365	2.2777424	0.82704383	3552.4199
792.74463	2.2822628	0.82892877	3548.4409
793.74561	2.2851851	0.83081925	3547.167
794.74658	2.2894225	0.83235288	3548.1533
795.74756	2.292186	0.83397263	3544.4226
796.74854	2.2943525	0.83557421	3550.2009
797.74951	2.2977283	0.83713341	3542.177
798.75049	2.300565	0.83856672	3549.106
799.75146	2.3039935	0.84027731	3552.2361
800.75244	2.3076141	0.84189796	3550.6274
801.75342	2.3134873	0.84358352	3555.7781
802.75439	2.313719	0.8451553	3552.7483
803.75537	2.315469	0.84702343	3552.2056
804.75635	2.3202269	0.84899306	3552.2935
805.75732	2.3221309	0.85092545	3554.8025
806.7583	2.3233304	0.85299718	3555.0413
807.75928	2.3257134	0.85448062	3544.0857
808.76025	2.3293865	0.8560847	3546.0493
809.76123	2.3357849	0.85810637	3555.5688
810.76221	2.3375454	0.8597278	3550.3162
811.76318	2.3367658	0.86142141	3552.0632
812.76416	2.3411853	0.86333036	3555.2261
813.76514	2.3484435	0.86495781	3551.2441
814.76611	2.3487685	0.86651772	3548.95
815.76709	2.3516994	0.86838514	3560.6599
816.76807	2.351938	0.870408	3552.9702
817.76904	2.3599632	0.87228978	3552.6829
818.77002	2.3633878	0.87409896	3555.6023
819.771	2.364187	0.8758263	3549.0032
820.77197	2.3642132	0.87731558	3548.3489
821.77295	2.3704047	0.87898022	3553.2241
822.77393	2.3732297	0.88082308	3562.8367
823.7749	2.3783169	0.88278085	3559.373
824.77588	2.3787498	0.88451499	3554.0698
825.77686	2.3808258	0.88651198	3556.3674
826.77783	2.3840313	0.88842022	3552.8076
827.77881	2.3886061	0.89013571	3558.6338
828.77979	2.3899508	0.89201307	3559.1873
829.78076	2.3948441	0.89407277	3557.4983
830.78174	2.3988044	0.89580613	3551.8831
831.78271	2.4007883	0.89744389	3555.2813
832.78369	2.4036334	0.89938706	3555.781
833.78467	2.4086883	0.90118378	3562.6956
834.78564	2.4106379	0.90345371	3560.8774
835.78662	2.412765	0.90522981	3554.9543
836.7876	2.4145706	0.90690029	3552.8281
837.78857	2.4158316	0.9085325	3557.4729
838.78955	2.4244113	0.91035008	3554.3765
839.79053	2.4254546	0.91222453	3559.7605
840.7915	2.4264367	0.9141224	3556.1746
841.79248	2.4301951	0.91615433	3554.8645
842.79346	2.4333103	0.91786295	3555.7554
843.79443	2.4366825	0.91949874	3557.8577
844.79541	2.438123	0.92155105	3562.1909
845.79639	2.4439936	0.92341906	3562.0408
846.79736	2.445338	0.9254939	3560.1663
847.79834	2.4472933	0.92767054	3557.5461
848.79932	2.4506145	0.92974043	3553.5925
849.80029	2.4537954	0.9313572	3548.7202
850.80127	2.4552813	0.93314409	3557.6277
851.80225	2.4614768	0.93508083	3564.3208
852.80322	2.4611506	0.93733799	3564.2507
853.8042	2.4660838	0.93959337	3558.2415
854.80518	2.4686275	0.94148099	3558.0168
855.80615	2.4724154	0.94357514	3557.916
856.80713	2.4760983	0.9457109	3566.9788
857.80811	2.4788258	0.94778806	3559.7334
858.80908	2.4802527	0.94978136	3558.9421
859.81006	2.4856312	0.95160538	3559.6965
860.81104	2.485321	0.95349473	3554.4858
861.81201	2.4902608	0.955329	3563.7727
862.81299	2.4905317	0.95731837	3559.509
863.81396	2.4967473	0.95925826	3557.9189
864.81494	2.4979768	0.96135557	3562.739
865.81592	2.5003097	0.96325994	3555.7488
866.81689	2.5068622	0.96544099	3563.6335
867.81787	2.5093598	0.96743172	3562.9932
868.81885	2.5117607	0.96934307	3558.5601
869.81982	2.5163057	0.97109723	3559.6663
870.8208	2.5180454	0.97279084	3556.759
871.82178	2.5178535	0.97469527	3558.5603
872.82275	2.5237083	0.97653687	3558.0459
873.82373	2.5258906	0.97865433	3566.7861
874.82471	2.5294147	0.98100066	3565.8418
875.82568	2.531075	0.9831484	3559.6331
876.82666	2.5352488	0.98511082	3561.1702
877.82764	2.5386975	0.98703009	3559.5298
878.82861	2.5404775	0.98916596	3555.7188
879.82959	2.5454016	0.99118578	3557.9368
880.83057	2.5474489	0.9932251	3563.5737
881.83154	2.5530126	0.99563885	3565.5864
882.83252	2.5545719	0.99773192	3561.0854
883.8335	2.5565951	0.99976444	3560.2488
884.83447	2.5601113	1.0017229	3555.9109
885.83545	2.5631039	1.0038061	3559.7815
886.83643	2.5657279	1.0058222	3560.6167
887.8374	2.5680337	1.0080563	3564.7712
888.83838	2.5709465	1.0105841	3560.8184
889.83936	2.5737531	1.0129448	3560.3147
890.84033	2.5772314	1.0152212	3555.7158
891.84131	2.5801866	1.0174226	3562.2065
892.84229	2.5841088	1.0194136	3562.8535
893.84326	2.585753	1.0216711	3553.7107
894.84424	2.586647	1.0232947	3551.6165
895.84521	2.58921	1.0251769	3556.2969
896.84619	2.5962946	1.0274067	3556.9241
897.84717	2.5964353	1.0293958	3560.1235
898.84814	2.5985203	1.0316757	3568.0029
899.84912	2.6054325	1.0341917	3564.6221
900.8501	2.6063294	1.0364066	3559.9143
901.85107	2.6094396	1.0383557	3548.9336
902.85205	2.6135437	1.0402882	3555.8623
903.85303	2.6167176	1.0426216	3559.5923
904.854	2.619705	1.0450602	3560.4263
905.85498	2.6228812	1.0470454	3550.7178
906.85596	2.6249835	1.0490153	3559.5203
907.85693	2.6311092	1.0515369	3562.5732
908.85791	2.6302357	1.0536177	3556.7161
909.85889	2.6363654	1.0560018	3560.2559
910.85986	2.6346719	1.058239	3555.6797
911.86084	2.6396251	1.0603282	3556.7395
912.86182	2.6439743	1.0626705	3557.4915
913.86279	2.647507	1.0652202	3562.4841
914.86377	2.6497338	1.0674943	3554.2502
915.86475	2.650244	1.0698974	3551.1277
916.86572	2.6585367	1.0717529	3552.4946
917.8667	2.6611903	1.0737733	3556.7168
918.86768	2.6611404	1.0757658	3558.4219
919.86865	2.6657646	1.0780219	3558.0459
920.86963	2.6665618	1.0807121	3558.4919
921.87061	2.6709692	1.0832636	3551.4714
922.87158	2.6752694	1.0860038	3559.9812
923.87256	2.6758835	1.0886154	3559.2273
924.87354	2.6772799	1.0913119	3555.5071
925.87451	2.68361	1.0939372	3550.489
926.87549	2.685503	1.0959882	3549.6951
927.87646	2.6889615	1.0983062	3554.7649
928.87744	2.6897783	1.1004725	3555.3154
929.87842	2.6942976	1.1027323	3549.9133
930.87939	2.6970825	1.1048704	3553.5667
931.88037	2.6982355	1.1074722	3552.4248
932.88135	2.7044144	1.109936	3553.146
933.88232	2.7058182	1.1123173	3552.5974
934.8833	2.7096636	1.1148243	3550.4392
935.88428	2.7133148	1.1170478	3556.1482
936.88525	2.7167323	1.1194068	3549.6216
937.88623	2.7185228	1.1218253	3550.0442
938.88721	2.7227364	1.1243544	3556.1072
939.88818	2.7257288	1.1270643	3554.7834
940.88916	2.7263422	1.1295804	3549.9131
941.89014	2.7307658	1.1320766	3550.8455
942.89111	2.7331054	1.1344756	3544.0903
943.89209	2.7342803	1.1368195	3545.8918
944.89307	2.740761	1.1390911	3553.2529
945.89404	2.7436924	1.1417822	3553.5522
946.89502	2.7444682	1.1444417	3549.5688
947.896	2.7486372	1.1471344	3548.9849
948.89697	2.7503717	1.1494596	3550.3672
949.89795	2.7539859	1.1518817	3544.1768
950.89893	2.7553101	1.1543317	3546.0481
951.8999	2.759727	1.1567651	3545.0227
952.90088	2.7640753	1.1595702	3554.6375
953.90186	2.7651813	1.1618242	3544.938
954.90283	2.7696536	1.1640182	3543.6069
955.90381	2.7717764	1.1664855	3553.4343
956.90479	2.7750359	1.1693882	3550.7476
957.90576	2.7787054	1.1724367	3551.45
958.90674	2.7810726	1.1753069	3547.9526
959.90771	2.7840416	1.1780691	3549.6184
960.90869	2.7882919	1.1812587	3551.4739
961.90967	2.7882774	1.1841508	3546.4429
962.91064	2.7908206	1.1867936	3538.3257
963.91162	2.7967546	1.1892574	3537.2686
964.9126	2.8000515	1.1914377	3536.886
965.91357	2.801352	1.1936243	3540.9707
966.91455	2.8063874	1.1958612	3545.7449
967.91553	2.8063643	1.1983258	3537.0957
968.9165	2.8116872	1.2013949	3545.0564
969.91748	2.8112204	1.2044326	3538.146
970.91846	2.8149822	1.2070022	3535.301
971.91943	2.8195555	1.2097517	3539.8127
972.92041	2.8253946	1.2128347	3544.6318
973.92139	2.824301	1.2157359	3540.2729
974.92236	2.8294728	1.218596	3541.8142
975.92334	2.8331833	1.2213222	3532.9929
976.92432	2.8337841	1.2241454	3537.7773
977.92529	2.8393688	1.22666	3528.5637
978.92627	2.8429377	1.2290421	3531.7017
979.92725	2.8445523	1.2317758	3535.5227
980.92822	2.8480108	1.2344216	3531.0381
981.9292	2.848974	1.2371072	3530.9729
982.93018	2.853354	1.239671	3528.8977
983.93115	2.854532	1.2421453	3527.3262
984.93213	2.8562584	1.2447591	3526.8193
985.93311	2.863508	1.2474909	3535.4497
986.93408	2.8648546	1.250329	3531.05
987.93506	2.8677673	1.2534263	3525.0884
988.93604	2.8723869	1.2562683	3530.2537
989.93701	2.8758819	1.2591537	3525.4155
990.93799	2.876641	1.2617753	3524.0535
991.93896	2.88096	1.2645756	3524.8953
992.93994	2.8835168	1.2674658	3524.7446
993.94092	2.8861549	1.2704155	3525.9858
994.94189	2.8905501	1.2732816	3520.625
995.94287	2.8936448	1.2759838	3520.3638
996.94385	2.896621	1.2790946	3525.1855
997.94482	2.8971963	1.281903	3518.3394
998.9458	2.9017611	1.2851039	3527.5522
999.94678	2.9063377	1.2887757	3521.7239
1000.9478	2.9061277	1.2913065	3511.8142
1001.9487	2.9101725	1.2941178	3516.2302
1002.9497	2.9150171	1.2969481	3513.5525
1003.9507	2.9186912	1.3001462	3519.9185
1004.9517	2.9198689	1.3028146	3514.0103
1005.9526	2.9203572	1.3056734	3520.4807
1006.9536	2.9269814	1.3092053	3511.9473
1007.9546	2.9267044	1.3120028	3509.5793
1008.9556	2.9326279	1.3148835	3511.241
1009.9565	2.9349904	1.3173901	3506.3989
1010.9575	2.9375842	1.3197935	3505.3379
1011.9585	2.9395518	1.3224654	3509.5571
1012.9595	2.9466169	1.3249059	3508.3799
1013.9604	2.9470115	1.3278781	3508.0205
1014.9614	2.951458	1.3304096	3502.1221
1015.9624	2.9544537	1.3333346	3506.668
1016.9634	2.9547675	1.3365207	3501.5273
1017.9644	2.9587414	1.339656	3504.5957
1018.9653	2.9609973	1.3427337	3500.6946
1019.9663	2.9647202	1.3455393	3495.0535
1020.9673	2.9684107	1.3482738	3501.9124
1021.9683	2.9711416	1.350872	3496.0215
1022.9692	2.9736662	1.3533829	3494.9714
1023.9702	2.9777772	1.3558435	3494.5093
1024.9712	2.9780025	1.3583313	3490.761
1025.9722	2.9840138	1.3606212	3487.6411
1026.9731	2.9841597	1.3628072	3487.4475
1027.9741	2.9884491	1.3654639	3492.5415
1028.9751	2.9927793	1.3681577	3492.7249
1029.9761	2.995239	1.3714684	3493.7585
1030.9771	2.9946523	1.3746852	3488.7629
1031.978	3.0025437	1.3783303	3491.7422
1032.979	3.0037246	1.3820988	3492.2214
1033.98	3.0068748	1.385366	3484.3992
1034.981	3.0092652	1.3883265	3482.1472
1035.9819	3.0121398	1.3911754	3481.8127
1036.9829	3.0175161	1.3946764	3488.3132
1037.9839	3.0187566	1.398311	3475.7583
1038.9849	3.0216181	1.4010475	3476.6724
1039.9858	3.024708	1.404163	3477.1143
1040.9868	3.0280523	1.4070395	3474.1816
1041.9878	3.0307634	1.4100735	3476.3079
1042.9888	3.0352068	1.4130014	3474.054
1043.9897	3.0369277	1.4156691	3469.3286
1044.9907	3.0403414	1.4185512	3467.9084
1045.9917	3.0415218	1.4213661	3469.613
1046.9927	3.0422163	1.424436	3467.7588
1047.9937	3.0468266	1.4280139	3468.7249
1048.9946	3.0529971	1.4312254	3470.2478
1049.9956	3.0548694	1.4340624	3461.0625
1050.9966	3.0551748	1.4367516	3456.176
1051.9976	3.0595152	1.4400215	3462.9604
1052.9985	3.0628307	1.4430674	3452.4395
1053.9995	3.0674295	1.4460343	3454.0879
1055.0005	3.0685108	1.4486512	3451.1448
1056.0015	3.0711403	1.4519498	3452.1594
1057.0024	3.0777278	1.455474	3455.0103
1058.0034	3.0820246	1.4586428	3450.8813
1059.0044	3.0842791	1.4616811	3443.9587
1060.0054	3.0853271	1.4648182	3445.4707
1061.0063	3.0897372	1.4676473	3440.998
1062.0073	3.0912526	1.4709123	3444.7659
1063.0083	3.0931666	1.4742336	3440.2034
1064.0093	3.0984473	1.4773597	3438.9609
1065.0103	3.0977275	1.4805223	3430.2905
1066.0112	3.104753	1.4835106	3436.7634
1067.0122	3.1084447	1.4869714	3437.2239
1068.0132	3.110136	1.4905576	3434.5762
1069.0142	3.1132715	1.4938002	3429.6465
1070.0151	3.114531	1.4970214	3432.4263
1071.0161	3.1186137	1.5002612	3425.179
1072.0171	3.1205726	1.5033447	3416.5752
1073.0181	3.1232433	1.5060555	3420.5615
1074.019	3.1255252	1.5089883	3417.6938
1075.02	3.1296339	1.5123519	3420.5896
1076.021	3.1344845	1.5161424	3421.7068
1077.022	3.1351266	1.5197986	3408.1936
1078.0229	3.1401007	1.5235176	3413.7461
1079.0239	3.1405602	1.5266389	3403.1497
1080.0249	3.1441143	1.5292791	3402.1584
1081.0259	3.1477473	1.5320715	3404.0154
1082.0269	3.1499891	1.5359753	3403.9063
1083.0278	3.1520209	1.5393938	3397.0681
1084.0288	3.1564505	1.5424794	3396.6294
1085.0298	3.159884	1.5452931	3391.7439
1086.0308	3.1644728	1.5478413	3392.5342
1087.0317	3.1651671	1.5507423	3385.5686
1088.0327	3.1687446	1.5536591	3393.0571
1089.0337	3.1714342	1.5567093	3387.2163
1090.0347	3.1774569	1.5596653	3384.7495
1091.0356	3.1793759	1.5629818	3384.0383
1092.0366	3.1810238	1.56591	3383.3833
1093.0376	3.1824985	1.5690364	3380.4868
1094.0386	3.1872973	1.572475	3379.4021
1095.0396	3.1924238	1.5762185	3375.187
1096.0405	3.1927495	1.5795093	3369.5518
1097.0415	3.1963191	1.5824343	3371.6787
1098.0425	3.2024124	1.5864431	3368.6816
1099.0435	3.2017176	1.5898429	3359.8379
1100.0444	3.2062042	1.5928724	3357.7019
1101.0454	3.2069318	1.5957853	3359.0383
1102.0464	3.2110574	1.5990528	3353.4897
1103.0474	3.2141545	1.6034603	3364.075
1104.0483	3.2181346	1.6072634	3343.7148
1105.0493	3.2201774	1.6102124	3341.8984
1106.0503	3.2238677	1.6127769	3337.4331
1107.0513	3.2272999	1.6157575	3339.5693
1108.0522	3.2294796	1.6191852	3337.6587
1109.0532	3.2322879	1.6225299	3333.8528
1110.0542	3.2342381	1.6255058	3330.627
1111.0552	3.2387567	1.628665	3326.2217
1112.0562	3.240272	1.6316077	3321.2832
1113.0571	3.2452874	1.6348124	3323.2163
1114.0581	3.2475917	1.6387757	3323.4856
1115.0591	3.2538278	1.642585	3318.8181
1116.0601	3.2515106	1.6457709	3310.5618
1117.061	3.2561178	1.648824	3306.1599
1118.062	3.26037	1.6520847	3299.3037
1119.063	3.2641826	1.6545511	3299.8689
1120.064	3.26226	1.6578085	3300.9114
1121.0649	3.2690468	1.660753	3298.8157
1122.0659	3.2722921	1.6640295	3292.2515
1123.0669	3.2754133	1.6671593	3290.876
1124.0679	3.2765441	1.6703222	3282.4951
1125.0688	3.2790813	1.6738092	3284.2522
1126.0698	3.2834406	1.676805	3271.033
1127.0708	3.2870235	1.6797849	3276.2371
1128.0718	3.291496	1.6832285	3279.6638
1129.0728	3.2920685	1.687158	3271.6138
1130.0737	3.2966008	1.6906015	3264.5142
1131.0747	3.2963345	1.6934968	3255.9265
1132.0757	3.3017111	1.6971054	3260.6514
1133.0767	3.3048904	1.7004684	3250.5671
1134.0776	3.3082697	1.7040905	3248.908
1135.0786	3.3111496	1.7071507	3241.5435
1136.0796	3.3138318	1.7102896	3237.3284
1137.0806	3.3151853	1.7141249	3235.6658
1138.0815	3.3195629	1.7174298	3227.2473
1139.0825	3.3218992	1.7206265	3224.762
1140.0835	3.3268595	1.7240857	3222.5837
1141.0845	3.3286493	1.7272478	3216.3765
1142.0854	3.3347554	1.7305573	3212.5183
1143.0864	3.3343661	1.7341758	3207.7817
1144.0874	3.3377666	1.7377112	3202.623
1145.0884	3.340934	1.7408924	3196.9343
1146.0894	3.3434086	1.7441024	3189.1851
1147.0903	3.3457665	1.7471994	3193.5776
1148.0913	3.347451	1.7507358	3183.4551
1149.0923	3.3507662	1.7537738	3176.2988
1150.0933	3.3545883	1.7573043	3181.3896
1151.0942	3.3566074	1.7615014	3168.1104
1152.0952	3.3608806	1.7648968	3162.7502
1153.0962	3.3646162	1.7683557	3157.7014
1154.0972	3.3672433	1.7717896	3153.0637
1155.0981	3.3725383	1.7757981	3149.8052
1156.0991	3.376349	1.7785839	3133.9956
1157.1001	3.3760753	1.7818723	3135.3782
1158.1011	3.3787591	1.7859635	3129.2871
1159.1021	3.3850093	1.7892812	3118.8269
1160.103	3.3883171	1.7924223	3113.0486
1161.104	3.3898528	1.7958392	3103.4001
1162.105	3.3902161	1.799335	3096.0615
1163.106	3.3929899	1.8034031	3086.7642
1164.1069	3.3993008	1.8070383	3083.5991
1165.1079	3.3985879	1.8104254	3074.2493
1166.1089	3.4085402	1.814484	3070.2622
1167.1099	3.407115	1.8185002	3056.5618
1168.1108	3.4102836	1.8223461	3048.9329
1169.1118	3.4111638	1.8260125	3038.186
1170.1128	3.4164217	1.8297477	3029.6475
1171.1138	3.41593	1.8337508	3015.6997
1172.1147	3.4222662	1.8381245	3013.7527
1173.1157	3.4269571	1.8423865	2993.3584
1174.1167	3.4263222	1.8464018	2986.6477
1175.1177	3.433007	1.8516027	2968.6973
1176.1187	3.4336479	1.8568946	2934.0347
1176.7192	3.4452019	1.873316	-34.709984