File: datasets/am_bench_2022/raw_data/60-XY.04-4/specimen.dat
MTS793|MPT|ENU|1|2|.|/|:|1|0|0|A

Operator Information						Time:	18.508789	Sec	11/1/2021 1:50:57 PM
Operator	Nick Derimow
Project	AM Bench 2022 mini-tensile challenge
Specimen ID	60-XY.04-4
Material	PBF-L Inconel 625
Specimen Width	2.54	mm
Specimen Thickness	1.51	mm
Notes
Operator Information End

Data Acquisition						Time:	1019.5034	Sec	11/1/2021 2:07:38 PM
Time	Axial Displacement	Axial Extensometer	Axial Force
Sec	mm	mm	N
18.623291	-0.0010127622	0.00012896066	33.273605
19.52417	0.001861602	0.00021487963	41.727673
20.425049	0.00272952	0.00034072163	54.410217
21.325928	0.0086856494	0.00030285367	67.423286
22.226807	0.0074479543	0.00038333383	80.127563
23.127686	0.010294248	0.00042940149	90.94091
24.028564	0.013629002	0.00055734569	100.45844
24.929443	0.016059367	0.00051699136	114.15121
25.830322	0.016207913	0.00060935109	123.53102
26.731201	0.020996829	0.00058216206	131.40549
27.63208	0.023460388	0.00078984571	143.11931
28.532959	0.026363641	0.00071500003	155.58931
29.433838	0.029253168	0.0007751591	169.22675
30.334717	0.033902347	0.00085678254	181.24573
31.235596	0.03548754	0.0010560328	198.65099
32.136475	0.037545465	0.0010209566	217.5276
33.037354	0.041595902	0.0012152065	234.3923
33.938232	0.042123649	0.001201487	243.67017
34.839111	0.043813385	0.0013749334	263.3537
35.73999	0.051979419	0.0014302775	288.22223
36.640869	0.053987555	0.0016313513	305.65744
37.541748	0.054406557	0.0016740096	316.00665
38.442627	0.058232844	0.0017619437	332.38354
39.343506	0.059083756	0.0018596429	349.43781
40.244385	0.063687198	0.0019848088	368.35162
41.145264	0.06475652	0.0019561579	380.89969
42.046143	0.06704469	0.0020462186	407.88779
42.947021	0.07322415	0.0021288665	418.8844
43.8479	0.071122788	0.0023610962	449.2244
44.748779	0.076232716	0.0022616338	464.32587
45.649658	0.079284318	0.0025551084	483.56439
46.550537	0.08179751	0.002644534	505.48047
47.451416	0.083777726	0.0028328432	529.20062
48.352295	0.083481044	0.002822693	546.9314
49.253174	0.088483252	0.0029835016	574.79565
50.154053	0.093726307	0.0030801559	598.66925
51.054932	0.094407983	0.0032254143	621.61761
51.955811	0.095969409	0.0032974202	635.2699
52.856689	0.10306862	0.0034437799	661.27081
53.757568	0.10027724	0.0035650088	683.85443
54.658447	0.10292704	0.0037839112	712.3894
55.559326	0.10772369	0.0037056899	738.8623
56.460205	0.10712685	0.0040963995	756.30084
57.361084	0.11381648	0.0039929594	788.55756
58.261963	0.11410435	0.004201307	806.48346
59.162842	0.11915912	0.0043366561	839.0191
60.063721	0.11928226	0.0044934335	859.27179
60.9646	0.12258464	0.004616112	884.2417
61.865479	0.12653658	0.0047334437	908.43152
62.766357	0.12734835	0.0048519466	930.02124
63.667236	0.13329501	0.0050456617	964.49829
64.568115	0.13442887	0.0051216497	982.83691
65.468994	0.13501137	0.0052188691	1005.9152
66.369873	0.13852684	0.0053009484	1026.1976
67.270752	0.14015758	0.0054763528	1051.8778
68.171631	0.14448769	0.0055806176	1077.7107
69.07251	0.14946213	0.0056800903	1112.9788
69.973389	0.15014422	0.0057895663	1136.1946
70.874268	0.15219088	0.0059672785	1168.4741
71.775146	0.15308236	0.0061308327	1192.625
72.676025	0.15865554	0.0061803181	1212.6108
73.576904	0.16059294	0.0063488674	1247.0662
74.477783	0.16182576	0.0065892506	1265.6908
75.378662	0.16476734	0.0067362334	1296.8511
76.279541	0.16418032	0.0067233262	1318.0648
77.18042	0.17294689	0.0069616935	1342.6713
78.081299	0.17463212	0.0070172669	1368.2631
78.982178	0.17790602	0.0071596159	1390.7411
79.883057	0.17986518	0.007258446	1417.3829
80.783936	0.1819139	0.0073947827	1437.8729
81.684814	0.18396153	0.0074620484	1462.3452
82.585693	0.18485914	0.0076605435	1485.7
83.486572	0.19076441	0.0076572038	1515.9988
84.387451	0.19795337	0.0078538191	1541.8856
85.28833	0.19540212	0.0080072684	1567.6288
86.189209	0.19850145	0.0081349555	1594.3035
87.090088	0.2004993	0.0082405144	1616.7515
87.990967	0.20549592	0.0083930045	1637.8876
88.891846	0.20667528	0.0084784022	1657.5057
89.792725	0.21058168	0.0086129438	1688.0863
90.693604	0.21445304	0.0087001482	1708.7191
91.594482	0.21629578	0.0088085886	1725.4681
92.495361	0.21932386	0.0089657288	1760.9432
93.39624	0.21994181	0.009040813	1779.062
94.297119	0.22266051	0.0091876602	1800.4358
95.197998	0.22574714	0.0091980612	1824.4712
96.098877	0.22891593	0.0093444875	1847.58
96.999756	0.23357469	0.0095042745	1875.9307
97.900635	0.23395845	0.0095639965	1890.9052
98.801514	0.24087526	0.0097060166	1917.1456
99.702393	0.23996104	0.0098295724	1939.5763
100.60327	0.24189112	0.0098075839	1955.3132
101.50415	0.24326321	0.0099869147	1974.9548
102.40503	0.25030485	0.010130382	2003.0355
103.30591	0.25109839	0.010281581	2031.8408
104.20679	0.25276539	0.010355181	2046.8572
105.10767	0.25514945	0.010502316	2060.0264
106.00854	0.25939414	0.010490511	2084.8428
106.90942	0.26178563	0.010647955	2102.313
107.8103	0.26515192	0.01074824	2123.9778
108.71118	0.26655659	0.010794287	2139.9998
109.61206	0.26902348	0.010869513	2150.1104
110.51294	0.27032059	0.010966081	2170.5264
111.41382	0.27890548	0.011135516	2196.2051
112.3147	0.27999362	0.011097759	2198.6477
113.21558	0.27986336	0.011134467	2208.2202
114.11646	0.28443766	0.011220189	2228.498
115.01733	0.28538015	0.01137103	2246.1641
115.91821	0.28776446	0.011504685	2261.0212
116.81909	0.29000863	0.01153927	2273.1047
117.71997	0.29056218	0.011661309	2285.4666
118.62085	0.2950052	0.011642926	2295.4138
119.52173	0.30118281	0.011884609	2317.989
120.42261	0.30194727	0.011849266	2330.3501
121.32349	0.30320162	0.011795524	2331.2358
122.22437	0.3083998	0.012080155	2343.3953
123.12524	0.31232178	0.012009322	2359.6511
124.02612	0.31229287	0.012106192	2369.0156
124.927	0.31584385	0.012251746	2386.0095
125.82788	0.32005349	0.012304652	2392.522
126.72876	0.32074451	0.012388487	2412.9695
127.62964	0.32307905	0.012493862	2411.5046
128.53052	0.32873687	0.012648491	2423.5139
129.4314	0.33271581	0.012632044	2437.8853
130.33228	0.33165917	0.012683224	2441.9707
131.23315	0.3349044	0.012826127	2460.7942
132.13403	0.33721489	0.012902677	2469.647
133.03491	0.34116417	0.013025765	2483.7375
133.93579	0.34347266	0.013035813	2488.7991
134.83667	0.3482787	0.013186664	2494.7585
135.73755	0.34960988	0.013218865	2504.6118
136.63843	0.35166508	0.013374105	2515.365
137.53931	0.35367876	0.013531139	2526.9282
138.44019	0.35898086	0.013570683	2528.9297
139.34106	0.36118874	0.013729759	2546.1968
140.24194	0.36363083	0.01372017	2549.2461
141.14282	0.36797938	0.013869452	2563.6504
142.0437	0.36832175	0.013925645	2572.145
142.94458	0.36993343	0.014179006	2585.4939
143.84546	0.37235355	0.01421655	2585.6067
144.74634	0.37691048	0.014392946	2599.2563
145.64722	0.37827846	0.014474492	2599.0725
146.5481	0.38063699	0.014555124	2607.4783
147.44897	0.38376075	0.014712323	2619.0779
148.34985	0.38931689	0.014784559	2622.1938
149.25073	0.39034665	0.014960234	2635.0933
150.15161	0.39323086	0.015154074	2647.3398
151.05249	0.39557666	0.015307561	2651.8682
151.95337	0.39701745	0.015462154	2662.958
152.85425	0.39883867	0.015683481	2664.9397
153.75513	0.40132353	0.015817504	2671.5891
154.65601	0.40952915	0.016049381	2684.3203
155.55688	0.40710571	0.0161967	2690.0435
156.45776	0.41155753	0.016424555	2699.4731
157.35864	0.41407052	0.016526738	2696.5637
158.25952	0.42005938	0.016858514	2716.4602
159.1604	0.41816741	0.017058542	2717.2747
160.06128	0.42088386	0.01721273	2721.6074
160.96216	0.42625031	0.017485453	2730.8379
161.86304	0.42829609	0.017826661	2739.4888
162.76392	0.42919433	0.017980091	2744.2466
163.66479	0.43185583	0.018242607	2752.926
164.56567	0.43611777	0.018664014	2759.9648
165.46655	0.43555063	0.018897241	2761.5388
166.36743	0.44123605	0.019230908	2771.6558
167.26831	0.44557539	0.01971839	2780.896
168.16919	0.44950375	0.019951772	2783.4099
169.07007	0.44808468	0.020338392	2788.738
169.97095	0.45298663	0.020645045	2796.4941
170.87183	0.45416415	0.021087997	2805.0649
171.77271	0.45842087	0.021517145	2803.6963
172.67358	0.46086583	0.02196281	2809.5947
173.57446	0.46457723	0.02228006	2820.0012
174.47534	0.4647083	0.022699192	2823.4746
175.37622	0.47032246	0.023155991	2831.5002
176.2771	0.47087997	0.023665644	2833.3955
177.17798	0.47424197	0.024157394	2836.0398
178.07886	0.47329703	0.024628256	2841.2351
178.97974	0.48221704	0.025202407	2858.5864
179.88062	0.48077694	0.025728267	2851.2256
180.78149	0.48212874	0.026202206	2856.5095
181.68237	0.48601118	0.026823966	2857.1438
182.58325	0.48921075	0.027322952	2868.7991
183.48413	0.4928844	0.027895918	2870.9712
184.38501	0.49336466	0.028371051	2866.3489
185.28589	0.49867472	0.029135682	2879.7327
186.18677	0.49948424	0.029778823	2882.4033
187.08765	0.50091171	0.030580515	2889.9907
187.98853	0.50663447	0.031229882	2893.033
188.8894	0.50950432	0.031928644	2890.5354
189.79028	0.5127055	0.032786272	2903.6504
190.69116	0.51759112	0.033508278	2910.1541
191.59204	0.51631159	0.034146614	2903.2097
192.49292	0.5218972	0.034818202	2911.9082
193.3938	0.52309704	0.035428673	2910.061
194.29468	0.52240348	0.036104608	2917.4014
195.19556	0.52925169	0.036952846	2919.8765
196.09644	0.52980822	0.0375655	2918.5151
196.99731	0.53460509	0.038332	2921.2639
197.89819	0.53599435	0.039119583	2924.8652
198.79907	0.53721982	0.03985491	2930.0811
199.69995	0.54196239	0.04066344	2938.8152
200.60083	0.54385394	0.041541245	2940.7498
201.50171	0.54999894	0.042321626	2944.1887
202.40259	0.55081725	0.043282628	2954.0225
203.30347	0.55376863	0.044308025	2957.8906
204.20435	0.55669552	0.04511195	2956.7017
205.10522	0.5568918	0.046081752	2962.4902
206.0061	0.56272376	0.046976425	2962.2544
206.90698	0.56522852	0.04778355	2964.1096
207.80786	0.56530476	0.04879104	2970.7869
208.70874	0.56908906	0.049857274	2972.6206
209.60962	0.56964368	0.050635148	2967.4587
210.5105	0.57617712	0.051457401	2973.1089
211.41138	0.57636911	0.052115798	2971.9087
212.31226	0.57685757	0.052906595	2971.1636
213.21313	0.58154994	0.053669196	2980.0793
214.11401	0.58434016	0.054624327	2983.4155
215.01489	0.58733499	0.05552623	2985.2227
215.91577	0.5880599	0.056533955	2989.8889
216.81665	0.59469885	0.057552099	2988.2686
217.71753	0.59475869	0.05835456	2989.1038
218.61841	0.59778577	0.059276406	2998.4165
219.51929	0.60044026	0.06002678	2990.9998
220.42017	0.60304523	0.060674336	2996.5313
221.32104	0.60545206	0.061426491	3000.5554
222.22192	0.60832232	0.062316831	3003.9719
223.1228	0.61107177	0.06342376	3011.5811
224.02368	0.61569816	0.064272687	3007.1316
224.92456	0.61564177	0.065223493	3008.4617
225.82544	0.62309378	0.066142991	3016.5156
226.72632	0.62484479	0.067048632	3019.9927
227.6272	0.62421435	0.068023928	3020.0383
228.52808	0.62886548	0.069039203	3020.8677
229.42896	0.62964427	0.070168152	3026.8271
230.32983	0.63458228	0.071140014	3034.8997
231.23071	0.63741672	0.072051384	3028.1118
232.13159	0.63690329	0.072873838	3024.4688
233.03247	0.6396631	0.073780775	3026.1694
233.93335	0.64632076	0.074750394	3037.1521
234.83423	0.6490013	0.075718097	3041.5759
235.73511	0.65120512	0.076806046	3048.311
236.63599	0.65110105	0.077921808	3044.8469
237.53687	0.65633285	0.078828953	3050.2791
238.43774	0.65629208	0.079878874	3042.1494
239.33862	0.66093588	0.080760241	3048.5767
240.2395	0.66123211	0.081600934	3045.4084
241.14038	0.66457963	0.082630292	3050.3936
242.04126	0.66931808	0.083504476	3054.9153
242.94214	0.67133129	0.084600314	3056.4026
243.84302	0.67320848	0.085477866	3057.9197
244.7439	0.67936033	0.086387172	3055.8926
245.64478	0.68145669	0.087211758	3061.2263
246.54565	0.68181896	0.08820717	3065.1282
247.44653	0.6870026	0.088987581	3067.7349
248.34741	0.68679279	0.090149932	3071.4995
249.24829	0.68971986	0.091078475	3066.6885
250.14917	0.69050252	0.09203738	3074.0281
251.05005	0.69659203	0.093093388	3074.8025
251.95093	0.7001214	0.094082378	3080.002
252.85181	0.69694626	0.095054202	3072.4272
253.75269	0.70565063	0.096055232	3078.9121
254.65356	0.70559961	0.096937992	3078.8562
255.55444	0.71065313	0.097847849	3080.1089
256.45532	0.70984566	0.098787628	3083.7856
257.3562	0.71472669	0.099795878	3085.2007
258.25708	0.71900505	0.10077112	3088.094
259.15796	0.7193982	0.10158154	3082.0767
260.05884	0.72022676	0.10267728	3087.2261
260.95972	0.72514755	0.10364067	3094.6858
261.8606	0.72611237	0.10461564	3091.6458
262.76147	0.72998357	0.10568365	3096.9871
263.66235	0.73589396	0.10673594	3107.9077
264.56323	0.73684216	0.10796299	3105.271
265.46411	0.73762506	0.10886544	3101.9868
266.36499	0.74274731	0.10979148	3100.7334
267.26587	0.74500233	0.11065347	3096.3213
268.16675	0.74637568	0.11148434	3110.6179
269.06763	0.74949449	0.11257724	3111.3792
269.96851	0.75384712	0.11355639	3113.2776
270.86938	0.75633675	0.11453468	3113.5894
271.77026	0.76033247	0.11538588	3118.4678
272.67114	0.76137763	0.11632031	3119.1458
273.57202	0.76387948	0.11740708	3119.199
274.4729	0.76708639	0.11839026	3120.7871
275.37378	0.76670516	0.11916079	3117.479
276.27466	0.77205151	0.12027826	3129.0044
277.17554	0.77646029	0.12143844	3131.3984
278.07642	0.77454561	0.12238424	3122.6746
278.97729	0.77758592	0.12347563	3127.4282
279.87817	0.78461689	0.12436291	3136.6787
280.77905	0.78969735	0.12536681	3135.1743
281.67993	0.78839993	0.12633562	3139.281
282.58081	0.78863293	0.12751557	3133.5591
283.48169	0.79393071	0.12847869	3140.7878
284.38257	0.79448736	0.12956631	3141.5723
285.28345	0.79965311	0.13062683	3137.7739
286.18433	0.79946625	0.13168883	3139.0562
287.08521	0.80243015	0.13247199	3142.0283
287.98608	0.80677807	0.13335042	3138.1768
288.88696	0.80653238	0.13414404	3144.1252
289.78784	0.81240332	0.13510352	3147.1821
290.68872	0.81523341	0.13606767	3151.7131
291.5896	0.81706554	0.1370528	3149.7112
292.49048	0.82355434	0.13796066	3151.0117
293.39136	0.82404238	0.13888426	3154.8882
294.29224	0.82777911	0.14003314	3159.0139
295.19312	0.82705939	0.14097089	3159.3325
296.09399	0.83018333	0.14212833	3162.0283
296.99487	0.83506435	0.14320908	3166.7893
297.89575	0.83831143	0.14406124	3156.186
298.79663	0.84291732	0.14497724	3169.4177
299.69751	0.84258622	0.14593728	3169.9602
300.59839	0.84869212	0.1470525	3173.7734
301.49927	0.84661108	0.14787385	3166.8582
302.40015	0.84936845	0.14891911	3167.1589
303.30103	0.85184169	0.14986588	3172.0933
304.2019	0.85581362	0.15094134	3174.9663
305.10278	0.8580547	0.15193322	3178.085
306.00366	0.86151421	0.15297323	3172.2356
306.90454	0.86414075	0.15383451	3178.9529
307.80542	0.86763465	0.15494896	3185.6418
308.7063	0.86790657	0.15584269	3173.3843
309.60718	0.87196398	0.15668605	3178.9663
310.50806	0.87582082	0.15768747	3190.8816
311.40894	0.87759209	0.15865672	3183.6965
312.30981	0.87759799	0.15980306	3191.2393
313.21069	0.88131815	0.16084428	3194.4707
314.11157	0.8835234	0.16193655	3190.6165
315.01245	0.88839644	0.16293247	3196.4846
315.91333	0.89019066	0.16390733	3195.04
316.81421	0.89518404	0.16476671	3190.8452
317.71509	0.8964113	0.16567327	3194.3779
318.61597	0.89933753	0.16642129	3195.5007
319.51685	0.90069491	0.16745457	3202.5063
320.41772	0.90370202	0.16838585	3198.1853
321.3186	0.90573335	0.16959544	3213.3022
322.21948	0.90828562	0.17061986	3200.7356
323.12036	0.91297632	0.17166109	3204.3176
324.02124	0.91654408	0.17269169	3210.5488
324.92212	0.91869211	0.1737112	3209.1614
325.823	0.91933489	0.1745768	3209.5176
326.72388	0.92316651	0.17555355	3215.8032
327.62476	0.92623591	0.17671767	3218.6563
328.52563	0.92854106	0.17779709	3220.3621
329.42651	0.93050575	0.17870289	3218.6304
330.32739	0.93353981	0.17971711	3219.7192
331.22827	0.93755007	0.18065055	3227.0923
332.12915	0.93773717	0.181667	3222.4031
333.03003	0.94344962	0.18257336	3221.2354
333.93091	0.94379401	0.18337783	3224.5815
334.83179	0.946181	0.18435757	3219.8796
335.73267	0.94847083	0.18533739	3227.8831
336.63354	0.95374447	0.18615432	3229.2783
337.53442	0.9560011	0.18699014	3234.2852
338.4353	0.95840669	0.18813734	3237.9111
339.33618	0.96191031	0.18940637	3239.4485
340.23706	0.96462101	0.19034018	3238.5459
341.13794	0.9667967	0.19133289	3236.4329
342.03882	0.9696393	0.19242667	3241.7102
342.9397	0.97360355	0.19339789	3239.2144
343.84058	0.97477096	0.19445258	3241.8789
344.74146	0.97679055	0.19554421	3244.9358
345.64233	0.98148662	0.19675952	3244.9526
346.54321	0.98233294	0.19766517	3245.0835
347.44409	0.98786807	0.19860274	3245.1746
348.34497	0.98789573	0.19954735	3245.0342
349.24585	0.99084902	0.20054531	3252.1711
350.14673	0.99483734	0.20160922	3251.7817
351.04761	0.99657559	0.20255999	3250.2422
351.94849	0.99836141	0.20350704	3252.1631
352.84937	1.003172	0.20446509	3256.5315
353.75024	1.002183	0.20539115	3253.79
354.65112	1.005262	0.20638241	3253.8435
355.552	1.0097983	0.20748386	3258.7375
356.45288	1.010583	0.20843133	3261.3833
357.35376	1.0163783	0.20940149	3263.6621
358.25464	1.018437	0.21036264	3263.7236
359.15552	1.022175	0.21131699	3262.0581
360.0564	1.0214485	0.21211822	3258.2534
360.95728	1.0242525	0.2130411	3267.4514
361.85815	1.0286907	0.21419074	3270.1206
362.75903	1.03026	0.21517408	3265.2573
363.65991	1.0331532	0.21616854	3270.6387
364.56079	1.0361457	0.21709423	3269.2744
365.46167	1.0397551	0.21809328	3274.7017
366.36255	1.0424445	0.21900848	3275.6206
367.26343	1.0442461	0.21989302	3273.3909
368.16431	1.0469116	0.22092158	3283.6375
369.06519	1.0487063	0.22192463	3280.2856
369.96606	1.0518644	0.22294617	3278.668
370.86694	1.0538977	0.22387193	3276.887
371.76782	1.0592991	0.22486626	3285.7742
372.6687	1.0603578	0.22595201	3286.3767
373.56958	1.0637327	0.22680664	3279.8904
374.47046	1.0663508	0.22771086	3288.3174
375.37134	1.0701091	0.22892345	3296.9592
376.27222	1.0726058	0.22986922	3292.3474
377.1731	1.0730839	0.23101735	3287.938
378.07397	1.0775886	0.2320381	3293.9329
378.97485	1.0795598	0.23295365	3293.3091
379.87573	1.0842868	0.23382868	3287.9224
380.77661	1.0848724	0.23492549	3300.1692
381.67749	1.0883708	0.23596093	3297.6694
382.57837	1.0919734	0.23676737	3294.2039
383.47925	1.0951654	0.23777102	3305.9114
384.38013	1.0963835	0.23871313	3299.0527
385.28101	1.0985622	0.23961079	3310.8784
386.18188	1.0998999	0.24071765	3301.9216
387.08276	1.1038185	0.24184568	3305.5256
387.98364	1.1097354	0.24266379	3309.1428
388.88452	1.1109072	0.24372359	3308.1472
389.7854	1.1155539	0.24452223	3306.7231
390.68628	1.1177549	0.24546009	3308.7974
391.58716	1.1160361	0.24655092	3311.3633
392.48804	1.120851	0.24768406	3311.4033
393.38892	1.1248631	0.2486788	3314.3433
394.28979	1.128111	0.24971896	3317.165
395.19067	1.1266412	0.25060958	3314.1423
396.09155	1.1300255	0.25169253	3322.1409
396.99243	1.1352721	0.25265458	3317.8088
397.89331	1.1365414	0.25347635	3317.4521
398.79419	1.1371626	0.25441974	3317.4446
399.69507	1.1425602	0.25558168	3324.8237
400.59595	1.1475698	0.25659081	3323.6218
401.49683	1.147482	0.25738931	3322.7878
402.39771	1.1514283	0.25838155	3332.813
403.29858	1.1542399	0.25947654	3328.7263
404.19946	1.154824	0.26029804	3332.3289
405.10034	1.1563874	0.26117748	3321.7622
406.00122	1.1642554	0.26208866	3329.0457
406.9021	1.1648579	0.2628825	3329.9021
407.80298	1.1629572	0.26384106	3329.7881
408.70386	1.1692629	0.26495913	3333.5664
409.60474	1.1702342	0.2659826	3338.5647
410.50562	1.1761972	0.26702315	3346.6831
411.40649	1.1779113	0.26823297	3344.6416
412.30737	1.1794209	0.26941934	3341.9214
413.20825	1.182696	0.27051345	3338.6135
414.10913	1.1837801	0.27133921	3338.5249
415.01001	1.1885997	0.27226335	3342.5342
415.91089	1.1879321	0.27346659	3344.543
416.81177	1.1948158	0.27452523	3348.5017
417.71265	1.1981918	0.27551195	3343.1055
418.61353	1.1988702	0.27650711	3344.3772
419.5144	1.201278	0.27735925	3347.4521
420.41528	1.205526	0.27826691	3354.2603
421.31616	1.2087146	0.27924621	3350.2397
422.21704	1.2068392	0.28039795	3357.699
423.11792	1.2118247	0.28144589	3355.4973
424.0188	1.2138944	0.28256187	3355.4739
424.91968	1.2169024	0.28346726	3356.082
425.82056	1.2197032	0.28455129	3357.8901
426.72144	1.2211001	0.28541952	3363.2412
427.62231	1.224678	0.28643692	3361.0439
428.52319	1.2265879	0.28752217	3363.625
429.42407	1.2302259	0.28859565	3363.7615
430.32495	1.2340271	0.28971675	3359.5146
431.22583	1.2380018	0.29052114	3364.3508
432.12671	1.2388833	0.29124737	3361.5901
433.02759	1.241302	0.29227677	3367.4216
433.92847	1.2441679	0.29318443	3367.0054
434.82935	1.2451942	0.29415345	3369.7363
435.73022	1.2509651	0.29516912	3377.2266
436.6311	1.2536012	0.2961224	3371.9995
437.53198	1.2555374	0.29697642	3370.657
438.43286	1.2587162	0.29788423	3365.9077
439.33374	1.262094	0.29880714	3372.5605
440.23462	1.2632707	0.29975924	3375.5181
441.1355	1.2667041	0.30073106	3377.0894
442.03638	1.2686157	0.301761	3376.2078
442.93726	1.2739593	0.30273384	3381.3396
443.83813	1.272413	0.30371097	3375.9731
444.73901	1.2773014	0.30446219	3378.1687
445.63989	1.2775306	0.30542174	3381.8323
446.54077	1.2821623	0.306467	3385.4194
447.44165	1.2841835	0.30755448	3384.7568
448.34253	1.2903105	0.30855638	3390.5474
449.24341	1.2905948	0.30966628	3388.7524
450.14429	1.2932262	0.31066963	3389.4949
451.04517	1.2934633	0.31183398	3391.9922
451.94604	1.2958537	0.31300837	3388.4551
452.84692	1.3039145	0.31402871	3393.9243
453.7478	1.302883	0.31521207	3387.502
454.64868	1.3065162	0.31634378	3395.7151
455.54956	1.3084352	0.31740889	3401.3118
456.45044	1.3140129	0.31849587	3397.9387
457.35132	1.3162142	0.31932056	3395.5896
458.2522	1.3162869	0.3200593	3391.9231
459.15308	1.3201768	0.32108802	3396.5989
460.05396	1.3224163	0.3218849	3396.4568
460.95483	1.3254639	0.32273802	3400.7065
461.85571	1.3275712	0.32363731	3402.4382
462.75659	1.3317432	0.32460222	3409.1196
463.65747	1.3343958	0.32567641	3402.9951
464.55835	1.3379647	0.32663414	3410.5359
465.45923	1.3406672	0.32770869	3414.6543
466.36011	1.3423592	0.32893103	3410.2888
467.26099	1.3446467	0.32992229	3409.9692
468.16187	1.347232	0.33087254	3404.7607
469.06274	1.34806	0.3317847	3409.897
469.96362	1.3537352	0.33281431	3414.7896
470.8645	1.3564622	0.3340441	3416.9875
471.76538	1.3564788	0.33488652	3415.4089
472.66626	1.3625464	0.33598542	3417.2083
473.56714	1.365242	0.33684868	3419.7966
474.46802	1.3679249	0.3379986	3421.6436
475.3689	1.3666512	0.33892211	3414.9182
476.26978	1.3721842	0.33993617	3417.7046
477.17065	1.3725088	0.34075078	3415.1121
478.07153	1.3766502	0.34159929	3419.5344
478.97241	1.3760799	0.34259668	3422.2361
479.87329	1.3828882	0.34366629	3422.6919
480.77417	1.3851748	0.3447516	3427.2305
481.67505	1.3883501	0.34577703	3425.8743
482.57593	1.3915042	0.34681746	3432.3364
483.47681	1.3956734	0.34782577	3430.6934
484.37769	1.3951362	0.34879771	3428.5027
485.27856	1.3991174	0.34962776	3425.3613
486.17944	1.400229	0.35062358	3424.6128
487.08032	1.4045857	0.35155672	3430.5164
487.9812	1.4081566	0.35260475	3436.2932
488.88208	1.4114994	0.35355636	3437.499
489.78296	1.4140884	0.35468	3434.7581
490.68384	1.4132031	0.35571042	3436.3513
491.58472	1.4195693	0.35692343	3442.0581
492.4856	1.4233104	0.35789797	3443.1116
493.38647	1.4210483	0.35896435	3441.2781
494.28735	1.4265883	0.36001617	3444.2197
495.18823	1.4291955	0.36118034	3442.4011
496.08911	1.4286726	0.36207184	3445.1243
496.98999	1.4350153	0.36318532	3438.9651
497.89087	1.4366219	0.36412954	3441.0486
498.79175	1.4419149	0.36511803	3443.1865
499.69263	1.4433051	0.36600256	3444.2058
500.59351	1.4478713	0.3668693	3446.1848
501.49438	1.4488364	0.36777145	3455.6873
502.39526	1.4520004	0.36876947	3454.8789
503.29614	1.4537692	0.36976877	3452.4587
504.19702	1.453475	0.37076983	3446.9326
505.0979	1.4584681	0.37188733	3457.1572
505.99878	1.4633567	0.37305048	3452.7166
506.89966	1.462261	0.37401575	3460.032
507.80054	1.4659557	0.37492937	3449.585
508.70142	1.471679	0.37563473	3449.9609
509.60229	1.4729211	0.37650406	3453.7859
510.50317	1.4748086	0.37733689	3455.9536
511.40405	1.4758625	0.37845707	3460.5505
512.30493	1.4799803	0.3796148	3464.886
513.20581	1.4811257	0.38064447	3462.1855
514.10669	1.4831506	0.38181213	3464.2156
515.00757	1.4881461	0.382898	3463.0693
515.90845	1.4909811	0.38390824	3463.7244
516.80933	1.4911405	0.38482663	3461.5217
517.71021	1.4969884	0.38592923	3461.6096
518.61108	1.4990859	0.38690728	3462.5061
519.51196	1.5014418	0.38793695	3463.6265
520.41284	1.5028453	0.3888832	3471.6462
521.31372	1.5052631	0.38992482	3471.1855
522.2146	1.5106064	0.39096102	3470.6553
523.11548	1.5106968	0.39219412	3472.0369
524.01636	1.5153643	0.39331001	3479.5991
524.91724	1.517935	0.39441091	3477.5977
525.81812	1.5187589	0.39542869	3475.5322
526.71899	1.5220922	0.39632979	3475.5769
527.61987	1.5260682	0.39731041	3472.1951
528.52075	1.5260653	0.39819685	3474.449
529.42163	1.5302351	0.39921251	3477.0215
530.32251	1.5332637	0.40020522	3476.1465
531.22339	1.5373378	0.40136898	3481.5557
532.12427	1.539404	0.4025431	3480.116
533.02515	1.5417281	0.40346199	3478.687
533.92603	1.5472834	0.40442654	3483.7549
534.8269	1.5462121	0.40527993	3480.415
535.72778	1.5492079	0.40630406	3482.2524
536.62866	1.5525734	0.40738285	3490.1711
537.52954	1.5547704	0.4085609	3486.3079
538.43042	1.5585234	0.40946692	3485.6802
539.3313	1.5613165	0.41045266	3491.6519
540.23218	1.5612085	0.41152331	3492.2925
541.13306	1.5652391	0.412521	3486.3022
542.03394	1.5671273	0.41352403	3488.1292
542.93481	1.5723094	0.41465241	3492.3396
543.83569	1.5733489	0.41573542	3495.8
544.73657	1.5780262	0.41668826	3488.155
545.63745	1.580516	0.4174403	3485.9661
546.53833	1.5793777	0.41855189	3496.219
547.43921	1.5849634	0.4196085	3498.7322
548.34009	1.5868367	0.42089111	3506.1865
549.24097	1.5890197	0.42197195	3497.3069
550.14185	1.5903389	0.42278382	3489.8225
551.04272	1.5943334	0.42404661	3505.9202
551.9436	1.5949448	0.42489973	3495.2776
552.84448	1.602632	0.42599824	3503.1101
553.74536	1.6032189	0.42715657	3501.6104
554.64624	1.6058339	0.4282994	3511.342
555.54712	1.6097267	0.42929024	3501.97
556.448	1.6119273	0.43017825	3501.4888
557.34888	1.6138014	0.43106562	3499.8113
558.24976	1.616991	0.43201137	3503.644
559.15063	1.6190695	0.43304548	3509.0764
560.05151	1.6219031	0.43403751	3505.5593
560.95239	1.6261984	0.43514305	3516.2202
561.85327	1.6287011	0.43624657	3509.8928
562.75415	1.6307545	0.43736202	3511.3591
563.65503	1.6330447	0.43850794	3516.1758
564.55591	1.6352848	0.43943444	3511.2556
565.45679	1.6412771	0.44053522	3519.2236
566.35767	1.642267	0.44154492	3513.1643
567.25854	1.6453239	0.44242498	3516.6782
568.15942	1.6478738	0.44366395	3517.5942
569.0603	1.6511724	0.4447642	3515.345
569.96118	1.6532397	0.44575831	3515.5896
570.86206	1.6560236	0.44667396	3515.7129
571.76294	1.6569058	0.44773504	3525.2515
572.66382	1.6621917	0.44874498	3523.6895
573.5647	1.6643307	0.44983566	3525.2949
574.46558	1.6662714	0.45075721	3522.8354
575.36646	1.667341	0.45188841	3522.7378
576.26733	1.6703461	0.45299265	3523.1917
577.16821	1.6730156	0.45401585	3524.7883
578.06909	1.6790115	0.4550072	3525.5342
578.96997	1.6800301	0.45609033	3531.9036
579.87085	1.6846125	0.45691466	3526.5188
580.77173	1.6866237	0.45795968	3526.3127
581.67261	1.687909	0.459016	3531.6133
582.57349	1.6877563	0.46011212	3532.2158
583.47437	1.6908169	0.46099555	3525.365
584.37524	1.6971437	0.46206698	3532.0693
585.27612	1.7012271	0.46310055	3535.1797
586.177	1.7023323	0.46407792	3533.2705
587.07788	1.7049719	0.46519583	3535.7334
587.97876	1.7059352	0.46618038	3534.8706
588.87964	1.7114599	0.46725386	3534.1311
589.78052	1.7110097	0.4681721	3535.4116
590.6814	1.7126443	0.46925774	3541.9126
591.58228	1.7167981	0.4702796	3537.4558
592.48315	1.7193623	0.47136608	3538.8357
593.38403	1.7232924	0.47243065	3543.5842
594.28491	1.725359	0.47362185	3548.0793
595.18579	1.7284458	0.47480115	3547.3655
596.08667	1.7319533	0.47616467	3544.7686
596.98755	1.7337613	0.47724089	3538.1538
597.88843	1.7374882	0.47841185	3542.5618
598.78931	1.7390472	0.47937694	3543.5288
599.69019	1.7417197	0.48046488	3544.418
600.59106	1.7454935	0.48146415	3547.5166
601.49194	1.7478811	0.48235402	3541.9409
602.39282	1.7521883	0.48337764	3546.7097
603.2937	1.7531605	0.48446915	3553.5977
604.19458	1.7572502	0.48555672	3548.2795
605.09546	1.7592016	0.48655501	3548.3513
605.99634	1.7609183	0.48752767	3549.8657
606.89722	1.7626181	0.48869228	3551.5188
607.7981	1.7641314	0.48960924	3545.1841
608.69897	1.7704451	0.49059498	3550.9065
609.59985	1.7736372	0.49172074	3555.7661
610.50073	1.7719735	0.49270537	3548.9104
611.40161	1.7757641	0.49378341	3558.8767
612.30249	1.7782279	0.49481145	3556.5105
613.20337	1.7825292	0.49594575	3557.0703
614.10425	1.7864417	0.49699575	3554.4585
615.00513	1.7891618	0.49796909	3555.134
615.90601	1.79296	0.49899486	3558.1929
616.80688	1.7933129	0.50012195	3560.2454
617.70776	1.7961953	0.50109071	3557.8699
618.60864	1.7997113	0.50232744	3566.5652
619.50952	1.8025726	0.50340527	3560.8342
620.4104	1.8055587	0.50461531	3565.6006
621.31128	1.8062998	0.50544906	3560.0879
622.21216	1.807514	0.50659108	3562.6064
623.11304	1.8108622	0.50760281	3562.7078
624.01392	1.8135481	0.50858682	3559.5198
624.91479	1.8189998	0.50966865	3563.8425
625.81567	1.8196337	0.51068109	3565.8467
626.71655	1.8187971	0.51177597	3566.3892
627.61743	1.8275898	0.51281196	3572.4749
628.51831	1.8245535	0.51408488	3566.946
629.41919	1.8305579	0.51517111	3567.6697
630.32007	1.8357543	0.51633787	3574.0061
631.22095	1.8369038	0.51747257	3571.2483
632.12183	1.8392375	0.51880413	3576.1826
633.02271	1.8454714	0.51989627	3574.6316
633.92358	1.8472668	0.52093947	3575.0063
634.82446	1.8485222	0.52205688	3573.8997
635.72534	1.8517807	0.52315944	3574.5549
636.62622	1.8547579	0.524073	3577.5798
637.5271	1.8564466	0.52521938	3581.2539
638.42798	1.8574404	0.52635449	3574.1833
639.32886	1.8600285	0.52743119	3576.116
640.22974	1.8674526	0.52833009	3577.844
641.13062	1.8656336	0.52929217	3576.5867
642.03149	1.8709646	0.530442	3586.3381
642.93237	1.8722882	0.53149641	3582.9937
643.83325	1.8746877	0.53262651	3577.9448
644.73413	1.877139	0.53371865	3581.1938
645.63501	1.8798603	0.53466982	3582.8306
646.53589	1.8844262	0.53570598	3587.3042
647.43677	1.8833804	0.53679502	3579.1848
648.33765	1.8865782	0.53804743	3589.6968
649.23853	1.8917109	0.53918839	3587.6648
650.1394	1.8943971	0.54010427	3587.0413
651.04028	1.8949312	0.54116499	3588.7544
651.94116	1.899393	0.54235125	3590.4761
652.84204	1.902185	0.54356557	3587.6733
653.74292	1.9047625	0.54468453	3589.0337
654.6438	1.9055622	0.54566592	3590.8257
655.54468	1.9102206	0.5469259	3595.5183
656.44556	1.9146025	0.54815996	3595.1848
657.34644	1.9152427	0.54913074	3590.9375
658.24731	1.9167216	0.55029684	3591.5522
659.14819	1.9204762	0.55133218	3590.1643
660.04907	1.9221687	0.55221218	3587.6873
660.94995	1.9263598	0.55326217	3594.5452
661.85083	1.9310888	0.5544619	3607.8105
662.75171	1.9280741	0.55567056	3595.0869
663.65259	1.9353226	0.55704457	3602.9951
664.55347	1.9377178	0.5582388	3602.5645
665.45435	1.9394329	0.5593574	3607.7957
666.35522	1.9420156	0.56062359	3596.6042
667.2561	1.9471548	0.5618037	3600.2056
668.15698	1.9445449	0.5629338	3601.991
669.05786	1.9523761	0.56421685	3601.8389
669.95874	1.9501436	0.56501937	3596.782
670.85962	1.9558568	0.56602389	3596.3845
671.7605	1.958129	0.56695569	3600.9221
672.66138	1.9606748	0.56792122	3599.2571
673.56226	1.9655746	0.569157	3611.322
674.46313	1.9648112	0.57044011	3611.2241
675.36401	1.9691465	0.57167935	3604.644
676.26489	1.9744446	0.57256508	3601.6599
677.16577	1.9771078	0.5735417	3600.8293
678.06665	1.9757383	0.57452011	3604.5923
678.96753	1.9803141	0.57559997	3613.3049
679.86841	1.9816126	0.57677025	3609.3599
680.76929	1.9846042	0.57778257	3607.0674
681.67017	1.9872286	0.57896411	3612.3506
682.57104	1.9884826	0.5801419	3610.4163
683.47192	1.9941121	0.58141595	3614.5769
684.3728	1.9968121	0.58270055	3616.7783
685.27368	1.9985033	0.58390081	3614.1553
686.17456	2.0027919	0.5850603	3616.0703
687.07544	2.0023289	0.58622533	3610.7908
687.97632	2.0069575	0.5874241	3614.0671
688.8772	2.0112619	0.58850902	3612.7834
689.77808	2.013165	0.58964503	3614.4219
690.67896	2.0131798	0.59083223	3610.6633
691.57983	2.0177717	0.59195167	3611.7454
692.48071	2.0221283	0.59303474	3616.917
693.38159	2.0222144	0.59409761	3611.4651
694.28247	2.0273125	0.59511739	3618.9355
695.18335	2.0290394	0.59628224	3622.3401
696.08423	2.0290432	0.59733158	3617.6272
696.98511	2.0344288	0.59846908	3621.7639
697.88599	2.0381601	0.59966379	3623.8413
698.78687	2.0402226	0.60080624	3624.49
699.68774	2.0425899	0.60196918	3622.2375
700.58862	2.0450118	0.60295105	3622.2844
701.4895	2.0496032	0.60408682	3625.8982
702.39038	2.0517743	0.6051811	3626.5952
703.29126	2.0552051	0.60633415	3625.1765
704.19214	2.0521574	0.60732746	3621.3967
705.09302	2.0602162	0.60855365	3630.7703
705.9939	2.0643506	0.60975629	3629.5557
706.89478	2.0617261	0.61091042	3623.2727
707.79565	2.0665741	0.61220866	3624.2173
708.69653	2.0704126	0.61326295	3625.3311
709.59741	2.0702705	0.61446643	3628.7344
710.49829	2.0736377	0.61552602	3620.647
711.39917	2.0779126	0.61686498	3633.0073
712.30005	2.0807207	0.6180172	3629.7075
713.20093	2.0822473	0.61921883	3629.6853
714.10181	2.0839992	0.62022948	3626.0208
715.00269	2.0879488	0.62128407	3628.2478
715.90356	2.0911341	0.62250727	3634.0325
716.80444	2.0906954	0.62364483	3632.2327
717.70532	2.0971048	0.62475175	3629.5925
718.6062	2.1029532	0.62607789	3634.7583
719.50708	2.0997632	0.62722546	3630.9026
720.40796	2.1037982	0.62818611	3628.6155
721.30884	2.1046371	0.62918538	3631.696
722.20972	2.1104548	0.63025415	3636.2124
723.1106	2.1147943	0.63118476	3634.8015
724.01147	2.1169538	0.63213873	3635.7432
724.91235	2.1183653	0.63353604	3644.5295
725.81323	2.1238229	0.63497466	3639.7656
726.71411	2.1231947	0.63614815	3630.9492
727.61499	2.1258242	0.63729805	3637.5313
728.51587	2.1280577	0.63864857	3638.2832
729.41675	2.1312399	0.63990998	3639.1499
730.31763	2.1330059	0.64107174	3634.4221
731.21851	2.1375723	0.64214236	3637.9075
732.11938	2.1396282	0.64327538	3638.4421
733.02026	2.1412354	0.64443386	3644.5874
733.92114	2.1427066	0.64565879	3634.2114
734.82202	2.1483393	0.64669812	3641.9973
735.7229	2.1534328	0.64792705	3645.5713
736.62378	2.1517317	0.6490187	3642.5322
737.52466	2.1553707	0.65019369	3641.2432
738.42554	2.1578805	0.65148807	3645.3726
739.32642	2.1611423	0.65270525	3643.0227
740.22729	2.1624877	0.65407336	3644.5161
741.12817	2.1660392	0.65522224	3640.7048
742.02905	2.1679068	0.65645909	3645.2927
742.92993	2.1722002	0.6576066	3648.9109
743.83081	2.174325	0.65903032	3651.3853
744.73169	2.177002	0.6602847	3645.7888
745.63257	2.1786997	0.66128135	3639.481
746.53345	2.180748	0.66248775	3647.5039
747.43433	2.185828	0.66358739	3648.2847
748.33521	2.1880357	0.66473138	3647.3833
749.23608	2.1900094	0.66587478	3645.3267
750.13696	2.192476	0.66719615	3652.7473
751.03784	2.1988165	0.66854131	3656.1899
751.93872	2.199038	0.66987807	3651.355
752.8396	2.20327	0.67115903	3654.0759
753.74048	2.2037101	0.6722725	3648.4534
754.64136	2.2070694	0.67343402	3649.0098
755.54224	2.2070282	0.67462009	3645.7705
756.44312	2.211024	0.67558211	3645.4927
757.34399	2.2184012	0.67656136	3655.6851
758.24487	2.220773	0.6777128	3657.1924
759.14575	2.2181506	0.67913294	3658.686
760.04663	2.2275097	0.68066829	3661.2778
760.94751	2.2267022	0.68176025	3651.4023
761.84839	2.2304041	0.68284637	3655.3877
762.74927	2.2335947	0.68388498	3652.676
763.65015	2.2344573	0.68491942	3654.3237
764.55103	2.2381096	0.68644512	3661.6504
765.4519	2.2396939	0.68775868	3663.5947
766.35278	2.2431381	0.68901372	3658.5806
767.25366	2.2465856	0.69015145	3658.958
768.15454	2.2487192	0.69139594	3661.6797
769.05542	2.2511456	0.69258511	3656.3386
769.9563	2.2538028	0.69360173	3658.3142
770.85718	2.2559235	0.69474554	3660.4556
771.75806	2.2565784	0.6958344	3654.8997
772.65894	2.2625699	0.6969952	3664.3293
773.55981	2.2615366	0.69832301	3665.0562
774.46069	2.268466	0.69996047	3669.946
775.36157	2.2664607	0.70113868	3662.4604
776.26245	2.2747822	0.70253116	3663.6733
777.16333	2.273406	0.70376235	3662.0535
778.06421	2.2776549	0.705221	3661.8909
778.96509	2.2815459	0.70642197	3661.2544
779.86597	2.2801509	0.7076382	3664.8501
780.76685	2.2870696	0.70876932	3666.853
781.66772	2.2877254	0.70989895	3665.4819
782.5686	2.2929938	0.71117228	3669.425
783.46948	2.2926855	0.71241158	3665.3704
784.37036	2.2945943	0.71361482	3667.1199
785.27124	2.3013182	0.71489304	3668.5896
786.17212	2.3020933	0.71607631	3669.1311
787.073	2.302779	0.71759307	3668.21
787.97388	2.3075161	0.71906596	3671.7112
788.87476	2.3084047	0.7202456	3661.3787
789.77563	2.3119459	0.72149652	3664.1521
790.67651	2.3150542	0.72253013	3664.97
791.57739	2.3164129	0.72375774	3665.0754
792.47827	2.323416	0.72471613	3667.52
793.37915	2.3226061	0.72597921	3669.4114
794.28003	2.3239605	0.72713655	3663.9822
795.18091	2.3299553	0.72840351	3673.4917
796.08179	2.3307252	0.72965884	3667.4563
796.98267	2.3326139	0.73097324	3673.5552
797.88354	2.3385623	0.73209983	3670.7258
798.78442	2.338917	0.73323572	3668.1743
799.6853	2.3412297	0.73456591	3672.2969
800.58618	2.3442609	0.73559922	3668.8262
801.48706	2.3485572	0.73696017	3677.1504
802.38794	2.34986	0.73828036	3671.5137
803.28882	2.3520138	0.73953444	3671.5679
804.1897	2.3549047	0.74085414	3674.7744
805.09058	2.3573363	0.74222922	3680.6301
805.99146	2.3602045	0.74353182	3669.2327
806.89233	2.365798	0.74475688	3672.4006
807.79321	2.364248	0.74611443	3671.9187
808.69409	2.3705595	0.7474516	3675.1702
809.59497	2.372817	0.7490449	3678.6646
810.49585	2.3761115	0.75050426	3679.4746
811.39673	2.3768532	0.75189161	3674.3838
812.29761	2.3792052	0.75313771	3675.2849
813.19849	2.3829734	0.75442553	3677.4443
814.09937	2.3823042	0.75563651	3672.2869
815.00024	2.3867788	0.75680786	3674.1274
815.90112	2.3894725	0.75789529	3675.0417
816.802	2.3938925	0.75902599	3671.4612
817.70288	2.3961508	0.76016134	3675.7734
818.60376	2.3989451	0.76137757	3677.9841
819.50464	2.3982043	0.76280832	3681.1257
820.40552	2.4008877	0.76431882	3681.9612
821.3064	2.4055648	0.76598781	3685.0476
822.20728	2.40768	0.76745027	3675.842
823.10815	2.4134669	0.7686286	3676.0957
824.00903	2.4138925	0.76976842	3672.9487
824.90991	2.4189212	0.77103651	3679.7415
825.81079	2.4187448	0.77230448	3680.7107
826.71167	2.4225833	0.77361751	3679.2654
827.61255	2.4245977	0.77494889	3678.4646
828.51343	2.4328885	0.77622771	3685.2251
829.41431	2.4288142	0.77760881	3678.9055
830.31519	2.4339628	0.77891654	3683.7236
831.21606	2.4359136	0.7803095	3676.5598
832.11694	2.4426582	0.78180051	3685.2061
833.01782	2.4420247	0.78318405	3681.1233
833.9187	2.4463019	0.78440011	3682.6426
834.81958	2.4457951	0.78575945	3679.8264
835.72046	2.4508905	0.78705084	3679.9827
836.62134	2.4514887	0.78813654	3678.9143
837.52222	2.4585185	0.7897172	3691.793
838.4231	2.4607768	0.79101181	3682.5896
839.32397	2.463491	0.79244459	3688.426
840.22485	2.4648731	0.79386872	3686.9646
841.12573	2.4687138	0.79529315	3686.5479
842.02661	2.4724164	0.7967118	3682.7798
842.92749	2.4714253	0.79799634	3684.8296
843.82837	2.4764676	0.79930526	3686.9875
844.72925	2.4765463	0.80068308	3685.5964
845.63013	2.4797258	0.80217445	3683.0046
846.53101	2.4822998	0.80363482	3687.6958
847.43188	2.485589	0.80505526	3686.9548
848.33276	2.48667	0.806306	3680.4263
849.23364	2.4880581	0.80778402	3686.467
850.13452	2.4903471	0.80929846	3684.3638
851.0354	2.496295	0.81069148	3686.6182
851.93628	2.4979081	0.81211329	3687.501
852.83716	2.5028684	0.81337517	3685.958
853.73804	2.5042493	0.81509471	3692.3755
854.63892	2.505424	0.81657785	3689.1697
855.53979	2.5112247	0.81781304	3684.0564
856.44067	2.5110362	0.81909198	3688.3035
857.34155	2.5119491	0.82049674	3686.2107
858.24243	2.5167596	0.82170093	3686.4128
859.14331	2.5191004	0.82307035	3688.8647
860.04419	2.5237083	0.82452327	3692.5354
860.94507	2.5247078	0.82599699	3690.2629
861.84595	2.5281646	0.82748014	3695.4968
862.74683	2.5314822	0.82906622	3689.7998
863.64771	2.5371406	0.83055484	3692.156
864.54858	2.5388293	0.83180577	3683.6475
865.44946	2.5420039	0.83285028	3687.1882
866.35034	2.5446324	0.83399147	3685.198
867.25122	2.5469704	0.8349002	3684.0879
868.1521	2.5486395	0.83600879	3693.4189
869.05298	2.5497684	0.8374806	3694.0535
869.95386	2.5543091	0.83906108	3690.9492
870.85474	2.5535522	0.84042376	3686.0181
871.75562	2.5565112	0.84207422	3689.3948
872.65649	2.5625422	0.84361321	3690.2539
873.55737	2.5652113	0.84504557	3687.4746
874.45825	2.5654366	0.84631079	3691.334
875.35913	2.567318	0.84785426	3692.77
876.26001	2.5711181	0.8492434	3688.9341
877.16089	2.5732186	0.85084581	3690.9055
878.06177	2.5757964	0.85225379	3689.9185
878.96265	2.5796032	0.8537426	3682.5503
879.86353	2.5807664	0.85498786	3689.3206
880.7644	2.5838392	0.85633308	3690.6155
881.66528	2.5901163	0.85796672	3697.8125
882.56616	2.5888817	0.85940772	3689.8757
883.46704	2.5902641	0.86105478	3690.0244
884.36792	2.5953972	0.8625589	3693.26
885.2688	2.6006358	0.86409831	3693.4897
886.16968	2.5991685	0.86554027	3694.0581
887.07056	2.6036325	0.86718053	3692.4065
887.97144	2.6061254	0.86881566	3695.9641
888.87231	2.6113572	0.87038797	3694.1138
889.77319	2.6127849	0.87173873	3687.2085
890.67407	2.6150703	0.87311673	3693.1331
891.57495	2.6206317	0.87466627	3695.5515
892.47583	2.6213989	0.87604725	3690.4041
893.37671	2.6260784	0.87759978	3696.6833
894.27759	2.6240399	0.87883437	3681.5393
895.17847	2.6277499	0.88012266	3685.1299
896.07935	2.6282301	0.88155514	3685.0254
896.98022	2.6349106	0.88299435	3692.2805
897.8811	2.638701	0.88450485	3688.9314
898.78198	2.6389372	0.88597131	3694.4944
899.68286	2.6405053	0.8875612	3692.52
900.58374	2.6463439	0.88925064	3695.6882
901.48462	2.6469357	0.89076751	3690.5544
902.3855	2.6507769	0.89206988	3687.1904
903.28638	2.6507537	0.89351982	3690.4934
904.18726	2.6555214	0.89497846	3691.6887
905.08813	2.6591117	0.8965416	3689.2954
905.98901	2.6623993	0.89820486	3694.3235
906.88989	2.6643877	0.89983159	3695.3445
907.79077	2.6662843	0.90129161	3691.4614
908.69165	2.6713274	0.90278864	3690.3467
909.59253	2.6717455	0.90415013	3688.8772
910.49341	2.6761682	0.90574926	3693.9878
911.39429	2.6775599	0.90727139	3693.3948
912.29517	2.679091	0.90870905	3693.304
913.19604	2.6814039	0.91015106	3684.6709
914.09692	2.6862442	0.91149402	3694.5337
914.9978	2.6857023	0.91319299	3698.5959
915.89868	2.6878262	0.91473061	3689.9878
916.79956	2.6930916	0.91648608	3690.9016
917.70044	2.6935449	0.91809636	3689.1328
918.60132	2.6974401	0.91954154	3687.0229
919.5022	2.6989148	0.92107022	3686.2795
920.40308	2.7047672	0.92254376	3684.542
921.30396	2.7097013	0.92394358	3688.9519
922.20483	2.7112174	0.92553747	3689.2593
923.10571	2.7118835	0.92699581	3687.9092
924.00659	2.7176278	0.92854595	3690.6553
924.90747	2.7185559	0.92996371	3690.1704
925.80835	2.7196798	0.93163049	3691.7856
926.70923	2.7239406	0.93326622	3691.584
927.61011	2.7266617	0.93504453	3686.915
928.51099	2.7278175	0.93672997	3688.3237
929.41187	2.7306428	0.9384504	3685.6182
930.31274	2.7338274	0.94018435	3687.7944
931.21362	2.7382848	0.94184774	3684.4387
932.1145	2.7387187	0.94339955	3689.8403
933.01538	2.7417195	0.94483435	3689.5886
933.91626	2.7448163	0.94657737	3686.7595
934.81714	2.7483294	0.94822758	3681.6265
935.71802	2.7517993	0.94954526	3682.4656
936.6189	2.7545617	0.95110691	3685.3909
937.51978	2.7552426	0.95262802	3683.3428
938.42065	2.7584901	0.95426232	3690.9495
939.32153	2.7609549	0.9560203	3687.8015
940.22241	2.765902	0.95754313	3684.5261
941.12329	2.7688515	0.95918024	3691.3206
942.02417	2.7701962	0.96083283	3684.1455
942.92505	2.7728827	0.96228659	3684.1069
943.82593	2.7759247	0.9637993	3682.9182
944.72681	2.7779906	0.9652766	3680.5776
945.62769	2.780462	0.96686202	3681.665
946.52856	2.7819614	0.96841085	3680.4556
947.42944	2.7837698	0.9700498	3681.1536
948.33032	2.7886407	0.97182053	3684.8962
949.2312	2.7933705	0.97368878	3686.0293
950.13208	2.7941673	0.97557205	3679.4509
951.03296	2.796231	0.97736454	3676.9539
951.93384	2.8020546	0.97877818	3679.3813
952.83472	2.8018558	0.98042822	3680.666
953.7356	2.8065405	0.98218685	3681.3379
954.63647	2.8065112	0.98369265	3674.905
955.53735	2.8088739	0.98516935	3675.2122
956.43823	2.8135736	0.98668742	3673.3638
957.33911	2.8151462	0.98845887	3676.8203
958.23999	2.8171833	0.99011391	3680.4023
959.14087	2.8212793	0.99164772	3667.7715
960.04175	2.8230321	0.99274588	3664.9905
960.94263	2.8257365	0.99405861	3671.1555
961.84351	2.8285713	0.99562556	3677.5579
962.74438	2.830934	0.99755943	3678.4248
963.64526	2.8361273	0.99961174	3675.3713
964.54614	2.836462	1.0013413	3665.4397
965.44702	2.8405559	1.0029263	3670.095
966.3479	2.8416965	1.0045397	3668.4424
967.24878	2.8450384	1.0061269	3669.7874
968.14966	2.8481517	1.0077559	3664.8567
969.05054	2.8486564	1.0093944	3666.1824
969.95142	2.8530428	1.0111833	3669.8599
970.85229	2.8533766	1.0128235	3661.8813
971.75317	2.8600447	1.0142391	3663.8896
972.65405	2.8609741	1.01588	3668.03
973.55493	2.8618915	1.0174844	3665.4021
974.45581	2.8671923	1.0190663	3663.5522
975.35669	2.8700802	1.0209386	3664.8713
976.25757	2.8716285	1.0223767	3659.6187
977.15845	2.8744793	1.0240418	3655.3203
978.05933	2.8755376	1.0259162	3658.7312
978.96021	2.8811507	1.0274299	3654.1926
979.86108	2.8847446	1.0290362	3660.282
980.76196	2.8870339	1.0307441	3661.9031
981.66284	2.8867834	1.0323986	3652.8875
982.56372	2.892077	1.0337812	3650.7993
983.4646	2.8941245	1.0353978	3652.2817
984.36548	2.8971958	1.0369581	3648.6956
985.26636	2.8988984	1.0386072	3651.8406
986.16724	2.89925	1.0401376	3652.3464
987.06812	2.905941	1.041906	3652.5291
987.96899	2.9072478	1.0437002	3643.5896
988.86987	2.9104466	1.0454502	3645.4155
989.77075	2.9133358	1.0471379	3649.9482
990.67163	2.9175482	1.0490844	3641.2166
991.57251	2.9154677	1.0507368	3635.564
992.47339	2.9250314	1.052683	3647.45
993.37427	2.9249871	1.0539982	3629.8455
994.27515	2.9248497	1.0554881	3635.45
995.17603	2.930563	1.0573488	3637.7627
996.0769	2.9323206	1.0589617	3634.0942
996.97778	2.9330378	1.0606027	3628.9709
997.87866	2.9355085	1.0620654	3630.7993
998.77954	2.9381416	1.0638744	3630.2078
999.68042	2.9440565	1.065485	3628.29
1000.5813	2.9431593	1.0670946	3626.8413
1001.4822	2.9495924	1.0688535	3626.729
1002.3831	2.9509957	1.0703806	3624.2473
1003.2839	2.9530618	1.0720465	3624.6267
1004.1848	2.9535472	1.0738229	3621.6951
1005.0857	2.9570942	1.0753406	3620.2791
1005.9866	2.9646971	1.0769583	3617.5532
1006.8875	2.9641981	1.07856	3619.0869
1007.7883	2.9674225	1.080106	3613.157
1008.6892	2.9693744	1.081481	3604.2288
1009.5901	2.9728022	1.0830204	3616.9443
1010.491	2.9729726	1.0851289	3609.7085
1011.3918	2.979259	1.0869906	3610.2612
1012.2927	2.9824452	1.0888997	3613.8088
1013.1936	2.9829211	1.0905125	3597.834
1014.0945	2.9869115	1.0921743	3602.6418
1014.9954	2.9885426	1.0935652	3596.6013
1015.8962	2.9922278	1.0952299	3595.6311
1016.7971	2.9933522	1.0968206	3594.8091
1017.698	2.9990413	1.0984967	3595.7996
1018.5989	2.9987788	1.0996828	3582.4089
1019.4998	2.9994175	1.1006852	3579.9849
1020.4006	3.0059569	1.1019329	3587.8372
1021.3015	3.0101805	1.1032226	3594.4939
1022.2024	3.0093365	1.1047752	3586.9026
1023.1033	3.0114875	1.1061488	3585.9817
1024.0042	3.0153596	1.1079884	3589.8167
1024.905	3.0176213	1.1097528	3583.8052
1025.8059	3.0218437	1.1119268	3580.781
1026.7068	3.0223758	1.1139538	3574.7151
1027.6077	3.0231345	1.1155664	3569.0459
1028.5085	3.0292575	1.1172779	3575.2476
1029.4094	3.0327163	1.1188418	3568.2354
1030.3103	3.0361853	1.1206297	3573.134
1031.2112	3.0354903	1.1225269	3565.7009
1032.1121	3.040642	1.1242946	3562.6511
1033.0129	3.0435827	1.125821	3558.2954
1033.9138	3.0478921	1.1271977	3553.7227
1034.8147	3.0457404	1.1287924	3558.2756
1035.7156	3.0479865	1.1308063	3554.9136
1036.6165	3.0525773	1.1326674	3548.1711
1037.5173	3.0565236	1.1347344	3551.8884
1038.4182	3.059602	1.1369123	3544.6643
1039.3191	3.0626166	1.1383021	3538.7075
1040.22	3.0655878	1.1399467	3542.8511
1041.1208	3.0663688	1.1415347	3539.9241
1042.0217	3.0723984	1.143477	3544.2546
1042.9226	3.0716217	1.1453228	3532.1804
1043.8235	3.0726225	1.147104	3522.9773
1044.7244	3.0778191	1.148641	3524.8687
1045.6252	3.0837934	1.1502825	3530.4966
1046.5261	3.0819201	1.1519086	3522.3608
1047.427	3.0856125	1.1537397	3520.7766
1048.3279	3.0889151	1.1555135	3515.708
1049.2288	3.0922382	1.1573191	3513.0625
1050.1296	3.0935962	1.1590633	3512.6396
1051.0305	3.0937223	1.1606833	3502.4714
1051.9314	3.0988092	1.1626046	3509.936
1052.8323	3.1035473	1.1647704	3510.26
1053.7332	3.1061268	1.1669335	3496.667
1054.634	3.1056023	1.168925	3494.1965
1055.5349	3.1129885	1.1709082	3495.5286
1056.4358	3.1150341	1.1728826	3489.825
1057.3367	3.1151621	1.1746676	3483.7896
1058.2375	3.1188269	1.1764429	3484.7202
1059.1384	3.1176918	1.1780746	3474.418
1060.0393	3.1238809	1.1800661	3480.4751
1060.9402	3.1280589	1.1820892	3474.1892
1061.8411	3.1296859	1.1839762	3470.8779
1062.7419	3.1290605	1.1857758	3459.2356
1063.6428	3.1334188	1.1874764	3466.0232
1064.5437	3.1368916	1.1893429	3463.5728
1065.4446	3.1390905	1.1911232	3460.322
1066.3455	3.141129	1.1931616	3457.9617
1067.2463	3.1454885	1.1953523	3452.8423
1068.1472	3.149416	1.1971961	3445.6953
1069.0481	3.1529725	1.199016	3445.0376
1069.949	3.1523423	1.2010071	3439.1631
1070.8499	3.1568179	1.2030797	3438.4395
1071.7507	3.1563575	1.2055392	3432.707
1072.6516	3.1611431	1.2074564	3423.0684
1073.5525	3.1635573	1.2094568	3423.1252
1074.4534	3.1671805	1.2115051	3418.9805
1075.3542	3.1676977	1.2133228	3414.8491
1076.2551	3.1710992	1.2154936	3405.8389
1077.156	3.1757841	1.2173634	3409.3503
1078.0569	3.1772766	1.219187	3398.1665
1078.9578	3.1799707	1.2209142	3393.1064
1079.8586	3.1849957	1.2227459	3393.6094
1080.7595	3.1873603	1.2248101	3395.7742
1081.6604	3.1876976	1.2275728	3391.4727
1082.5613	3.1930623	1.2296323	3372.3945
1083.4622	3.1940136	1.2316837	3371.1733
1084.363	3.1976531	1.2334443	3368.7498
1085.2639	3.1993427	1.2358638	3365.2849
1086.1648	3.2046576	1.2383696	3362.363
1087.0657	3.204071	1.2407582	3355.4026
1087.9666	3.2089231	1.2437857	3349.0488
1088.8674	3.2111514	1.2470089	3337.8748
1089.7683	3.2146633	1.2509187	3327.2517
1090.6692	3.2152123	1.2570332	3296.9421
1091.5701	3.2183831	1.2660966	3243.9856
1092.4709	3.2245202	1.2708358	3215.0767
1093.3718	3.2250094	1.2746381	3200.324
1094.2727	3.2307403	1.2790762	3186.7507
1095.1736	3.2305779	1.2829602	3166.1602
1096.0745	3.2336738	1.2879325	3142.0674
1096.9753	3.2376385	1.294188	3116.4688
1097.4758	3.2425027	1.3055437	3020.9788