File: datasets/am_bench_2022/raw_data/0-XY.05-3/specimen.dat
MTS793|MPT|ENU|1|2|.|/|:|1|0|0|A

Operator Information						Time:	29.114258	Sec	10/13/2021 12:51:11 PM
Operator	Nick Derimow
Project	AM Bench 2022 mini-tensile challenge
Specimen ID	0-XY.05-3
Material	PBF-L Inconel 625
Specimen Width	2.56	mm
Specimen Thickness	1.53	mm
Notes
Operator Information End

Data Acquisition						Time:	1030.1082	Sec	10/13/2021 1:07:52 PM
Time	Axial Displacement	Axial Extensometer	Axial Force
Sec	mm	mm	N
29.228027	-0.0017396073	3.8438146e-05	23.760975
30.229004	-0.00026772186	8.3378931e-05	33.629116
31.22998	0.0039624572	0.00025354189	48.543896
32.230957	0.0065456713	0.0002561686	58.67701
33.231934	0.0089860763	0.00028802504	71.122353
34.23291	0.011069408	0.00040850812	86.324532
35.233887	0.01376941	0.00057579542	102.16055
36.234863	0.0174597	0.00059538713	115.31184
37.23584	0.020090859	0.0006282762	126.09802
38.236816	0.027575424	0.00082200166	143.92397
39.237793	0.025390722	0.00079510355	150.34834
40.23877	0.030629324	0.00095637632	169.0741
41.239746	0.034996729	0.0010468705	192.92368
42.240723	0.035138924	0.0011821057	208.94427
43.241699	0.036472917	0.00123641	226.14496
44.242676	0.041786712	0.0013868635	247.24593
45.243652	0.042744577	0.0015458404	264.03427
46.244629	0.049301807	0.0016181865	285.24536
47.245605	0.050797306	0.001768645	301.11258
48.246582	0.053295489	0.0019039284	326.50208
49.247559	0.056122985	0.002104613	344.08041
50.248535	0.056941524	0.0020854885	365.88406
51.249512	0.0619529	0.0022668641	393.41861
52.250488	0.066775523	0.0023873912	406.74973
53.251465	0.065687396	0.0023625183	427.9176
54.252441	0.068584301	0.0024545996	448.97412
55.253418	0.073438726	0.0026972897	480.66037
56.254395	0.077207237	0.0028241039	496.35345
57.255371	0.081246205	0.0029462415	526.43823
58.256348	0.083086535	0.003077178	546.7879
59.257324	0.086741738	0.0032903773	566.06543
60.258301	0.086689897	0.0033798851	594.47919
61.259277	0.090664729	0.0035645021	623.27472
62.260254	0.094557203	0.0036029099	657.57959
63.26123	0.097024292	0.0039832611	677.94684
64.262207	0.098800495	0.0039638048	703.21771
65.263184	0.10518008	0.0041909041	730.66083
66.26416	0.10839149	0.0042335284	754.40021
67.265137	0.11072192	0.0043792459	776.2699
68.266113	0.1115132	0.0044873157	802.27985
69.26709	0.11566917	0.0046818615	837.86084
70.268066	0.11595643	0.0049867979	865.07471
71.269043	0.12277018	0.004948176	897.44269
72.27002	0.12189426	0.005226017	923.27136
73.270996	0.12896971	0.0054048728	945.79431
74.271973	0.12912379	0.0054661925	970.08289
75.272949	0.1311204	0.0055703693	1004.6278
76.273926	0.13735908	0.0058200299	1033.1167
77.274902	0.13791475	0.0060369461	1057.9259
78.275879	0.14256161	0.0060923062	1085.5753
79.276855	0.1460066	0.0062004672	1110.8938
80.277832	0.14705417	0.0064764484	1144.9515
81.278809	0.15284008	0.0065167174	1164.9265
82.279785	0.15377146	0.0067380294	1200.447
83.280762	0.15864269	0.0069968076	1236.0039
84.281738	0.16124536	0.0071972013	1255.4628
85.282715	0.16232391	0.0072549265	1287.1152
86.283691	0.16705152	0.0074195839	1306.0721
87.284668	0.16692428	0.0076098437	1332.9583
88.285645	0.17336902	0.0077359518	1362.8876
89.286621	0.17598486	0.0079363249	1396.7026
90.287598	0.17882998	0.008035589	1421.407
91.288574	0.17976633	0.0082863932	1449.3929
92.289551	0.18111221	0.0083406679	1464.9872
93.290527	0.18858141	0.0085800225	1505.3624
94.291504	0.19039592	0.0087877028	1526.3177
95.29248	0.19235632	0.0087334281	1546.7534
96.293457	0.19604778	0.0090471981	1584.1819
97.294434	0.19706421	0.0090823779	1608.3055
98.29541	0.2022022	0.0094394982	1637.1118
99.296387	0.20253024	0.0096459435	1671.4592
100.29736	0.20979275	0.0097931447	1697.0038
101.29834	0.21195818	0.0099335294	1716.7654
102.29932	0.21163855	0.010044497	1738.433
103.30029	0.21684293	0.010330842	1761.8177
104.30127	0.21786146	0.010337247	1790.8815
105.30225	0.22338261	0.010703436	1817.5056
106.30322	0.22782105	0.010901404	1848.0704
107.3042	0.23050185	0.011047354	1875.9198
108.30518	0.23050021	0.011336226	1897.1189
109.30615	0.23596336	0.011451054	1923.1243
110.30713	0.23903033	0.011667318	1953.6174
111.30811	0.24078128	0.011836047	1975.4763
112.30908	0.24549131	0.012029946	1986.1862
113.31006	0.24573308	0.012212425	2009.5475
114.31104	0.25152278	0.0123727	2036.2719
115.31201	0.25575352	0.012805617	2063.2981
116.31299	0.25789505	0.012872591	2085.4226
117.31396	0.25994641	0.01306785	2104.9758
118.31494	0.26363337	0.01329985	2126.9202
119.31592	0.26624385	0.013668571	2151.3459
120.31689	0.26764873	0.013879607	2168.0034
121.31787	0.27554581	0.01403034	2183.8052
122.31885	0.27474856	0.014305805	2203.1929
123.31982	0.27954379	0.014463228	2226.1895
124.3208	0.28121337	0.014712909	2231.5139
125.32178	0.2835817	0.014943058	2250.7439
126.32275	0.29005581	0.015220431	2274.2976
127.32373	0.28704438	0.015420136	2290.3235
128.32471	0.29428959	0.015758481	2306.7288
129.32568	0.29624382	0.016094534	2326.2205
130.32666	0.3004863	0.016300431	2343.2976
131.32764	0.30358726	0.016635105	2353.2229
132.32861	0.30355018	0.016762849	2363.929
133.32959	0.30720559	0.017115183	2375.2058
134.33057	0.3133246	0.017356236	2405.6831
135.33154	0.31603834	0.017802831	2416.9788
136.33252	0.31744164	0.01816543	2423.8157
137.3335	0.32418779	0.018393213	2437.1294
138.33447	0.32585928	0.01879763	2457.4502
139.33545	0.32628012	0.019063223	2469.7952
140.33643	0.32780159	0.019575065	2474.2368
141.3374	0.33253103	0.019909795	2488.968
142.33838	0.33181208	0.020341486	2500.0171
143.33936	0.33794072	0.020746781	2514.7114
144.34033	0.33987224	0.02108332	2522.8042
145.34131	0.34591991	0.021460293	2532.1868
146.34229	0.34833428	0.021819295	2537.8577
147.34326	0.35295251	0.022465678	2553.3772
148.34424	0.35694867	0.022830194	2561.6782
149.34521	0.36034447	0.023384534	2578.4524
150.34619	0.35875842	0.02394703	2580.6265
151.34717	0.36395666	0.024349157	2591.6924
152.34814	0.36370811	0.025078693	2599.3938
153.34912	0.37021542	0.025594007	2605.8936
154.3501	0.37783375	0.026144454	2615.1602
155.35107	0.37526834	0.026754431	2622.7026
156.35205	0.37877032	0.027440717	2626.813
157.35303	0.3836022	0.028116021	2642.3347
158.354	0.38319552	0.028746804	2641.6282
159.35498	0.38614938	0.029357579	2645.7458
160.35596	0.39114559	0.030074315	2654.3528
161.35693	0.39224482	0.030894455	2665.9321
162.35791	0.39351946	0.031513721	2665.592
163.35889	0.39933765	0.032311145	2673.561
164.35986	0.40526119	0.033249073	2684.1055
165.36084	0.4068161	0.034073323	2691.6711
166.36182	0.40860885	0.034925718	2696.5444
167.36279	0.41216099	0.035849594	2701.2688
168.36377	0.41441295	0.036923386	2710.4768
169.36475	0.41959643	0.037904076	2709.8379
170.36572	0.42159596	0.038812526	2713.0757
171.3667	0.42359546	0.039689332	2716.6204
172.36768	0.42929459	0.040575657	2723.1489
173.36865	0.42917821	0.04166083	2721.5271
174.36963	0.4341841	0.042685714	2736.7856
175.37061	0.43356922	0.043620113	2732.0039
176.37158	0.4380731	0.04457511	2743.366
177.37256	0.44042274	0.045676555	2743.0098
178.37354	0.44383985	0.046732042	2751.2068
179.37451	0.4497675	0.047908012	2760.8201
180.37549	0.4517107	0.049101595	2762.9045
181.37646	0.45634869	0.050287683	2759.9578
182.37744	0.45512411	0.051484786	2760.6941
183.37842	0.45855129	0.052469868	2768.0225
184.37939	0.46218106	0.053478245	2769.8425
185.38037	0.46469405	0.054670326	2778.3457
186.38135	0.4676303	0.055690039	2772.894
187.38232	0.47064316	0.056655951	2777.5574
188.3833	0.47677243	0.057877365	2789.4978
189.38428	0.48178607	0.059185207	2786.6931
190.38525	0.48334134	0.060363747	2792.9944
191.38623	0.481163	0.061904322	2789.0674
192.38721	0.48716542	0.063286133	2796.4263
193.38818	0.49074769	0.064677007	2801.5818
194.38916	0.4916113	0.066118471	2804.3391
195.39014	0.49515915	0.067316428	2797.0974
196.39111	0.50005168	0.068405025	2802.5259
197.39209	0.5018996	0.069555871	2815.2341
198.39307	0.50737172	0.071049899	2815.906
199.39404	0.50743484	0.072353207	2811.3762
200.39502	0.51005125	0.073368728	2809.105
201.396	0.51303649	0.074504897	2815.6951
202.39697	0.51488584	0.075650342	2817.9016
203.39795	0.51835501	0.077276364	2822.418
204.39893	0.5258103	0.078643411	2827.8003
205.3999	0.52501446	0.07993415	2827.2083
206.40088	0.5245297	0.081509784	2833.5012
207.40186	0.53103369	0.083015256	2835.6924
208.40283	0.53592831	0.084430441	2834.8574
209.40381	0.53688818	0.086082563	2833.2917
210.40479	0.54151827	0.087389745	2842.7227
211.40576	0.54628295	0.088731244	2843.3845
212.40674	0.54696971	0.090092532	2840.2236
213.40771	0.55043662	0.091373622	2850.0303
214.40869	0.55564392	0.093027696	2851.0835
215.40967	0.55828285	0.094388746	2853.3533
216.41064	0.55811489	0.095308803	2847.3777
217.41162	0.56168133	0.096990906	2850.5571
218.4126	0.56602889	0.098476931	2861.5156
219.41357	0.56695211	0.099899881	2856.5854
220.41455	0.56899655	0.10126404	2858.1973
221.41553	0.57404655	0.10257316	2860.062
222.4165	0.57698673	0.10391696	2854.9563
223.41748	0.58183217	0.10528321	2871.6116
224.41846	0.58289862	0.10683656	2872.4485
225.41943	0.58299571	0.10833074	2868.4775
226.42041	0.58877683	0.10982305	2873.0959
227.42139	0.59260231	0.11113889	2872.4812
228.42236	0.59531075	0.11224775	2875.3779
229.42334	0.5985527	0.1135556	2877.8191
230.42432	0.60347039	0.11483066	2879.4954
231.42529	0.60206062	0.11616233	2882.772
232.42627	0.60278368	0.1178359	2887.8298
233.42725	0.60974354	0.11943646	2882.3674
234.42822	0.6116125	0.12104221	2882.2366
235.4292	0.61740941	0.12243521	2886.1968
236.43018	0.61616349	0.12365236	2885.967
237.43115	0.62365013	0.12506045	2893.335
238.43213	0.62667465	0.12625033	2889.938
239.43311	0.6307677	0.12758124	2892.3999
240.43408	0.63109922	0.12883982	2891.4141
241.43506	0.63305533	0.13050228	2895.4675
242.43604	0.637375	0.13183294	2899.2913
243.43701	0.63824105	0.13321213	2896.467
244.43799	0.6452843	0.13483715	2907.4702
245.43896	0.64448482	0.13638425	2902.9473
246.43994	0.65158713	0.13777603	2907.9238
247.44092	0.6527257	0.1392401	2907.8735
248.44189	0.65692663	0.14068124	2904.7051
249.44287	0.65768927	0.14199772	2904.4937
250.44385	0.66301399	0.14349261	2915.9155
251.44482	0.66323769	0.14493179	2907.3303
252.4458	0.6646086	0.14665815	2911.002
253.44678	0.67038518	0.1482392	2912.3025
254.44775	0.67240542	0.14958665	2912.8376
255.44873	0.6723935	0.15141307	2918.5073
256.44971	0.67760241	0.15292718	2918.8259
257.45068	0.67959601	0.15462375	2918.1838
258.45166	0.68623865	0.15617315	2925.5313
259.45264	0.68813086	0.15767373	2924.5132
260.45361	0.69365692	0.15928046	2924.4873
261.45459	0.69488192	0.1609228	2930.5972
262.45557	0.69735199	0.16238037	2927.1753
263.45654	0.69847828	0.16355604	2919.7886
264.45752	0.70280516	0.1649165	2930.0581
265.4585	0.7060203	0.16616978	2925.0842
266.45947	0.70912266	0.1674839	2936.5864
267.46045	0.71420968	0.16893518	2935.4314
268.46143	0.71506649	0.17059712	2938.4255
269.4624	0.717426	0.17195667	2932.99
270.46338	0.72239578	0.17329778	2944.5317
271.46436	0.72627187	0.17516278	2944.6677
272.46533	0.72457719	0.17698678	2942.5474
273.46631	0.73034817	0.17842636	2940.3022
274.46729	0.73385155	0.17970614	2942.448
275.46826	0.73462087	0.18099938	2945.4917
276.46924	0.73961133	0.18227375	2939.6309
277.47021	0.74268001	0.18342504	2947.2915
278.47119	0.74337804	0.18495104	2950.6257
279.47217	0.74776322	0.18639043	2948.4346
280.47314	0.74976808	0.18789837	2950.0896
281.47412	0.75503063	0.18905988	2953.5652
282.4751	0.75844657	0.19076826	2960.6504
283.47607	0.75895363	0.19249348	2955.8286
284.47705	0.76397383	0.1939794	2961.8787
285.47803	0.76521581	0.19561146	2964.3005
286.479	0.76876026	0.19713855	2954.2495
287.47998	0.77078825	0.1986151	2960.4536
288.48096	0.775213	0.19998945	2957.3008
289.48193	0.77845246	0.2015404	2961.6133
290.48291	0.78062677	0.20303628	2963.7781
291.48389	0.78052163	0.20458657	2960.4912
292.48486	0.78871435	0.20657526	2975.2078
293.48584	0.79191244	0.20817521	2964.4502
294.48682	0.79421234	0.2096049	2968.4275
295.48779	0.79759669	0.21103157	2970.1355
296.48877	0.79942858	0.21247633	2974.4302
297.48975	0.80008155	0.21407141	2967.8638
298.49072	0.80384743	0.2151148	2964.0139
299.4917	0.80505049	0.21670577	2978.5042
300.49268	0.81210852	0.21819958	2972.9902
301.49365	0.81304735	0.21941593	2977.05
302.49463	0.81896794	0.22076304	2980.2751
303.49561	0.8212707	0.22207294	2982.5491
304.49658	0.8243916	0.22355163	2986.3638
305.49756	0.82671624	0.22509295	2984.3232
306.49854	0.83010244	0.22643487	2990.3967
307.49951	0.83277845	0.22817639	2993.7903
308.50049	0.83340073	0.22964051	2986.061
309.50146	0.83886778	0.23111662	2988.0627
310.50244	0.8390907	0.2327629	2989.5613
311.50342	0.84020001	0.23470965	2992.6487
312.50439	0.84525555	0.23631836	2993.8657
313.50537	0.8520124	0.23788881	2994.6667
314.50635	0.85185671	0.23947851	2990.4453
315.50732	0.85767412	0.24092983	2994.2976
316.5083	0.8594234	0.24209836	3000.9893
317.50928	0.8631385	0.24341117	2995.512
318.51025	0.86391997	0.24516413	3002.0652
319.51123	0.86899561	0.24674267	3006.7773
320.51221	0.86972749	0.24823707	3000.9844
321.51318	0.87474912	0.24967645	3000.6458
322.51416	0.87444055	0.25104296	2998.5996
323.51514	0.88012499	0.25240254	2998.8098
324.51611	0.88432765	0.25374579	3008.8777
325.51709	0.88647568	0.25528532	3004.5295
326.51807	0.88748419	0.25655091	2999.6064
327.51904	0.89164793	0.2580623	3011.0168
328.52002	0.89784497	0.25988021	3013.1453
329.521	0.90019256	0.26129222	3013.8982
330.52197	0.9012453	0.26272538	3012.0063
331.52295	0.90301883	0.26389351	3006.1877
332.52393	0.90721333	0.26547551	3018.5762
333.5249	0.91243774	0.26705188	3023.9163
334.52588	0.91669965	0.26847744	3021.4104
335.52686	0.91320628	0.27001819	3015.8354
336.52783	0.92081857	0.27160889	3020.2446
337.52881	0.92230701	0.27301759	3022.323
338.52979	0.92804474	0.27449679	3024.8796
339.53076	0.92927551	0.27599493	3021.0635
340.53174	0.93414223	0.27717572	3027.0369
341.53271	0.93488169	0.27860713	3026.1541
342.53369	0.93973219	0.28008723	3025.6052
343.53467	0.94066364	0.28167397	3029.3303
344.53564	0.94323272	0.28320321	3020.0569
345.53662	0.94615054	0.28464371	3034.7615
346.5376	0.952012	0.28645194	3034.7957
347.53857	0.95249122	0.28771549	3028.0842
348.53955	0.95509291	0.28946912	3039.4407
349.54053	0.95850885	0.29103518	3033.6526
350.5415	0.96550167	0.29247186	3038.1499
351.54248	0.96565348	0.29405218	3042.2502
352.54346	0.96705508	0.29549086	3035.2104
353.54443	0.97212183	0.2970694	3038.6565
354.54541	0.97244716	0.29852459	3040.3008
355.54639	0.97307944	0.2999202	3035.1323
356.54736	0.979532	0.3017475	3047.7161
357.54834	0.9812668	0.30340254	3046.0688
358.54932	0.985834	0.30490944	3040.3279
359.55029	0.99006164	0.30620611	3045.9963
360.55127	0.99199992	0.3076928	3050.3306
361.55225	0.99633843	0.30891937	3046.4875
362.55322	0.99821889	0.31012744	3046.7844
363.5542	1.0019293	0.31146711	3044.8594
364.55518	1.0056301	0.31308684	3060.0369
365.55615	1.0062944	0.31481564	3050.6401
366.55713	1.0100223	0.31616426	3055.6392
367.55811	1.0124453	0.31755677	3052.2751
368.55908	1.0173782	0.31894079	3056.0315
369.56006	1.0141503	0.32040027	3050.0605
370.56104	1.0185435	0.32192472	3056.3684
371.56201	1.0258238	0.32315367	3055.189
372.56299	1.0271889	0.32459563	3061.8425
373.56396	1.0307347	0.32607672	3060.4604
374.56494	1.0339082	0.32767123	3062.1147
375.56592	1.0369674	0.32910159	3065.7131
376.56689	1.0397514	0.33070365	3061.0876
377.56787	1.0427121	0.33196759	3062.4629
378.56885	1.0475675	0.33316842	3069.5552
379.56982	1.0464824	0.334732	3064.6436
380.5708	1.0508132	0.33616862	3066.1575
381.57178	1.0557019	0.33782205	3067.7419
382.57275	1.056674	0.33909547	3067.1211
383.57373	1.0597762	0.3404029	3074.7363
384.57471	1.061016	0.34206939	3070.0647
385.57568	1.0660176	0.34324548	3068.8052
386.57666	1.0703297	0.34453481	3072.3772
387.57764	1.0707427	0.34594783	3074.9348
388.57861	1.072976	0.34756607	3077.5981
389.57959	1.0784042	0.34922311	3079.093
390.58057	1.0813437	0.35086671	3078.3638
391.58154	1.0855131	0.35245848	3083.0537
392.58252	1.0870348	0.35399544	3081.0051
393.5835	1.0931319	0.35561413	3090.6401
394.58447	1.0910308	0.35715565	3078.7612
395.58545	1.0942069	0.35861048	3079.5032
396.58643	1.0987059	0.36013719	3081.7102
397.5874	1.1028301	0.36167383	3087.6768
398.58838	1.104609	0.36314189	3085.0349
399.58936	1.1069552	0.36464763	3083.7097
400.59033	1.1124339	0.36616695	3087.3884
401.59131	1.1128035	0.36783147	3093.5281
402.59229	1.1197402	0.36948431	3091.0908
403.59326	1.1175097	0.37050754	3087.1934
404.59424	1.1272032	0.37204885	3092.5974
405.59521	1.1269521	0.37327895	3088.8601
406.59619	1.1283928	0.37449589	3087.8713
407.59717	1.1312729	0.37587193	3090.3438
408.59814	1.1342164	0.37728482	3089.0144
409.59912	1.1412446	0.37863705	3089.687
410.6001	1.1410141	0.37962195	3094.2666
411.60107	1.1430138	0.38106287	3099.458
412.60205	1.1454488	0.38289157	3098.8311
413.60303	1.1490262	0.38458049	3101.0442
414.604	1.1527791	0.38598487	3096.5901
415.60498	1.158658	0.38744101	3105.9011
416.60596	1.1609486	0.38908485	3103.9509
417.60693	1.1631824	0.39021531	3099.4783
418.60791	1.1638068	0.39151588	3104.9856
419.60889	1.1680076	0.39329785	3106.7407
420.60986	1.1725558	0.39463237	3109.9729
421.61084	1.1743575	0.39599416	3110.1243
422.61182	1.1773946	0.39725396	3108.2761
423.61279	1.181447	0.39879367	3109.0002
424.61377	1.186341	0.40027174	3113.9309
425.61475	1.1879351	0.40180004	3116.51
426.61572	1.1884477	0.40345526	3116.6868
427.6167	1.1939158	0.40526348	3120.4187
428.61768	1.195487	0.40664551	3111.8926
429.61865	1.1966558	0.40803197	3113.3962
430.61963	1.2020843	0.40945429	3118.2056
431.62061	1.2079936	0.41067135	3117.7261
432.62158	1.2062666	0.41214818	3117.8916
433.62256	1.2096195	0.41361079	3118.4878
434.62354	1.212741	0.41496745	3116.7932
435.62451	1.2184274	0.41650823	3126.6123
436.62549	1.2184727	0.41796383	3124.334
437.62646	1.2226019	0.41948381	3128.3496
438.62744	1.2275995	0.42087314	3132.9968
439.62842	1.2273991	0.42234573	3126.9124
440.62939	1.2316618	0.42395413	3123.3491
441.63037	1.2341877	0.42528757	3126.439
442.63135	1.2386721	0.42687762	3126.2964
443.63232	1.2382648	0.42817506	3123.7004
444.6333	1.2446812	0.42952988	3126.6121
445.63428	1.2440072	0.43077877	3126.4326
446.63525	1.2510664	0.43198505	3132.292
447.63623	1.253881	0.43336838	3130.6514
448.63721	1.2544115	0.43466014	3135.1436
449.63818	1.258718	0.43621278	3132.605
450.63916	1.2624506	0.43751755	3134.0432
451.64014	1.2639112	0.43909174	3138.0752
452.64111	1.2672536	0.44062796	3133.8782
453.64209	1.26975	0.44200197	3137.9497
454.64307	1.2764096	0.44392776	3147.3508
455.64404	1.276759	0.44521272	3132.9316
456.64502	1.279411	0.4466083	3143.8914
457.646	1.2801892	0.44812849	3137.7888
458.64697	1.2845258	0.44971323	3134.5479
459.64795	1.286088	0.45103958	3141.616
460.64893	1.2895473	0.45245236	3141.1799
461.6499	1.2946121	0.45412692	3143.8843
462.65088	1.2983446	0.45563152	3151.0547
463.65186	1.3003354	0.45710239	3147.5115
464.65283	1.3055131	0.4586395	3151.3843
465.65381	1.3091296	0.46004686	3144.3687
466.65479	1.3110321	0.46142834	3150.9321
467.65576	1.3136734	0.46289691	3145.7827
468.65674	1.3175532	0.46419933	3150.5686
469.65771	1.3174007	0.46542352	3144.0076
470.65869	1.3213063	0.46666431	3151.728
471.65967	1.3245775	0.46804944	3154.5771
472.66064	1.3277626	0.46953171	3157.6672
473.66162	1.3289411	0.47088307	3149.3354
474.6626	1.3317809	0.47225368	3149.9834
475.66357	1.338743	0.47387072	3158.6431
476.66455	1.3375831	0.47516358	3158.2922
477.66553	1.3436269	0.47698167	3158.5103
478.6665	1.3482964	0.47842911	3157.9773
479.66748	1.3498744	0.47976187	3155.519
480.66846	1.3510662	0.48095688	3156.6108
481.66943	1.3532619	0.48230046	3157.4097
482.67041	1.3540207	0.48368528	3160.3711
483.67139	1.3582678	0.48496523	3162.5208
484.67236	1.3655571	0.48644423	3167.6021
485.67334	1.3672827	0.487863	3165.4487
486.67432	1.3682976	0.48945779	3168.7292
487.67529	1.3692859	0.49093163	3161.9319
488.67627	1.3760622	0.49266899	3172.1396
489.67725	1.3774942	0.49439627	3164.3638
490.67822	1.383751	0.49569133	3170.5613
491.6792	1.3849384	0.49710953	3165.6975
492.68018	1.3909231	0.49845058	3170.6106
493.68115	1.3896556	0.50003046	3165.3398
494.68213	1.3927778	0.50114638	3169.1113
495.68311	1.3955145	0.50287724	3175.2717
496.68408	1.3989958	0.50455177	3174.0557
497.68506	1.4041436	0.50598007	3176.0393
498.68604	1.4052472	0.50751728	3180.2339
499.68701	1.4102942	0.50894839	3175.6575
500.68799	1.4150323	0.51027972	3178.4421
501.68896	1.4140137	0.51142067	3175.5369
502.68994	1.4173272	0.51312721	3185.9082
503.69092	1.4220093	0.51469666	3180.0366
504.69189	1.4222435	0.51596767	3175.9985
505.69287	1.4286586	0.5173254	3189.1121
506.69385	1.4325371	0.51904488	3187.8044
507.69482	1.4339149	0.52051324	3176.854
508.6958	1.4330425	0.52198344	3182.4302
509.69678	1.4404571	0.52367848	3183.8726
510.69775	1.4418874	0.52498341	3180.7881
511.69873	1.446538	0.52619737	3185.6497
512.69971	1.4471427	0.52796251	3190.0054
513.70068	1.4490689	0.52977073	3190.7522
514.70166	1.4520931	0.53132808	3183.6636
515.70264	1.4543424	0.53250325	3181.02
516.70361	1.4600313	0.53370482	3186.8086
517.70459	1.4610045	0.53528208	3191.5623
518.70557	1.4660021	0.53636515	3185.4602
519.70654	1.4720507	0.53791845	3198.7727
520.70752	1.468534	0.53963071	3194.8979
521.7085	1.4779009	0.54130501	3195.5332
522.70947	1.4798368	0.54267383	3194.4678
523.71045	1.4847882	0.54403311	3191.9639
524.71143	1.4854252	0.54526895	3195.7407
525.7124	1.4867172	0.54674906	3195.8289
526.71338	1.4891273	0.54805684	3195.9905
527.71436	1.4916284	0.549146	3191.1477
528.71533	1.4946216	0.55044734	3195.8647
529.71631	1.5001495	0.5519436	3202.6069
530.71729	1.5028831	0.55365527	3207.1152
531.71826	1.5055584	0.55515063	3199.8545
532.71924	1.506305	0.55674994	3204.8223
533.72021	1.5110674	0.55843914	3203.0117
534.72119	1.5128105	0.56003165	3199.6724
535.72217	1.51671	0.5615893	3200.0225
536.72314	1.5187368	0.56270367	3199.8552
537.72412	1.52277	0.56406146	3206.1118
538.7251	1.5259813	0.56553262	3202.8733
539.72607	1.529669	0.5668382	3200.802
540.72705	1.5317894	0.56822407	3204.7747
541.72803	1.5357903	0.56966078	3205.3037
542.729	1.5340209	0.57110065	3206.5779
543.72998	1.5439719	0.57260394	3214.1626
544.73096	1.545769	0.57408166	3210.9871
545.73193	1.5501468	0.57556432	3206.2791
546.73291	1.5477784	0.57703698	3210.302
547.73389	1.5531722	0.57874054	3212.0979
548.73486	1.556215	0.58000237	3209.2217
549.73584	1.5612372	0.5815922	3217.9438
550.73682	1.5617583	0.58290309	3216.3513
551.73779	1.5680258	0.58446181	3218.1902
552.73877	1.5678492	0.58630949	3218.0227
553.73975	1.5719116	0.58776242	3217.9226
554.74072	1.5737365	0.58925623	3211.9788
555.7417	1.5753504	0.59060717	3209.8677
556.74268	1.5797487	0.59199429	3214.0457
557.74365	1.5843792	0.59340197	3222.9604
558.74463	1.5833708	0.59500951	3217.7617
559.74561	1.5875138	0.59673625	3224.5994
560.74658	1.5941836	0.59826982	3217.2773
561.74756	1.5936898	0.59987342	3218.7354
562.74854	1.5967969	0.60122389	3225.582
563.74951	1.60144	0.60270315	3224.3079
564.75049	1.6028168	0.60396552	3221.8469
565.75146	1.606333	0.60535222	3228.8818
566.75244	1.6103697	0.60705662	3222.0188
567.75342	1.6128865	0.60821819	3216.5159
568.75439	1.6150416	0.60972893	3221.6836
569.75537	1.619282	0.61127478	3229.1624
570.75635	1.6212809	0.61312473	3227.6121
571.75732	1.6263777	0.61442912	3231.6765
572.7583	1.6291009	0.6158188	3221.2317
573.75928	1.6320757	0.61726463	3226.8184
574.76025	1.6351137	0.6187641	3236.2031
575.76123	1.6360589	0.62031674	3226.8462
576.76221	1.6392543	0.62188643	3234.438
577.76318	1.6442329	0.62357205	3230.1924
578.76416	1.6439078	0.62497228	3225.1006
579.76514	1.6472987	0.62637532	3228.6133
580.76611	1.6533879	0.62786651	3227.9077
581.76709	1.656978	0.62932891	3235.4207
582.76807	1.6594633	0.63096488	3237.7195
583.76904	1.6628234	0.63255209	3239.0396
584.77002	1.6628718	0.63412976	3237.322
585.771	1.6683317	0.63570064	3239.2219
586.77197	1.6703466	0.63714248	3235.3557
587.77295	1.6771321	0.63854808	3236.0391
588.77393	1.6783739	0.63973886	3236.8337
589.7749	1.6791893	0.64118731	3239.3196
590.77588	1.6840461	0.64261222	3244.2117
591.77686	1.6857265	0.64420056	3243.9187
592.77783	1.6871395	0.64541012	3238.6265
593.77881	1.6944017	0.64678591	3240.9578
594.77979	1.6936289	0.64801657	3235.2354
595.78076	1.7004774	0.64943433	3243.4678
596.78174	1.6995369	0.65079969	3242.1133
597.78271	1.7020326	0.65233064	3247.5276
598.78369	1.7090224	0.65415859	3244.4775
599.78467	1.7127723	0.65551686	3249.3489
600.78564	1.7128735	0.65729433	3245.4258
601.78662	1.7148049	0.6588009	3245.7944
602.7876	1.7203226	0.6605584	3249.2957
603.78857	1.7198987	0.6622076	3243.6167
604.78955	1.725174	0.66397452	3242.9331
605.79053	1.7266443	0.66536331	3246.0938
606.7915	1.7297266	0.66706961	3248.5698
607.79248	1.7325236	0.6687429	3250.1116
608.79346	1.7351426	0.67035079	3247.3618
609.79443	1.7418865	0.67200047	3253.2236
610.79541	1.7433083	0.67343313	3248.7544
611.79639	1.7444891	0.67445165	3242.7505
612.79736	1.750488	0.67582422	3252.283
613.79834	1.7473191	0.67713624	3255.4009
614.79932	1.7559615	0.6786024	3255.7778
615.80029	1.7559059	0.6802054	3252.4119
616.80127	1.7591728	0.6816268	3258.4775
617.80225	1.7637174	0.68352604	3264.6382
618.80322	1.7646487	0.68510878	3255.7908
619.8042	1.7666724	0.68678713	3252.7485
620.80518	1.770943	0.68840528	3256.7739
621.80615	1.7744064	0.68976319	3252.1445
622.80713	1.7793975	0.6912505	3259.3894
623.80811	1.7830306	0.6925205	3259.8289
624.80908	1.7835695	0.69393945	3257.0349
625.81006	1.7873032	0.69564474	3261.0571
626.81104	1.7900479	0.69734383	3260.9597
627.81201	1.795488	0.69868308	3258.3879
628.81299	1.7968551	0.70030743	3259.8027
629.81396	1.800524	0.70202041	3265.2258
630.81494	1.8027093	0.7032966	3257.6365
631.81592	1.8056188	0.70494008	3261.6167
632.81689	1.8106183	0.70676196	3263.1948
633.81787	1.8094658	0.7081241	3258.5117
634.81885	1.8129442	0.70960283	3262.0549
635.81982	1.8169001	0.71122986	3264.9417
636.8208	1.8212069	0.71281052	3264.2332
637.82178	1.8207554	0.71467584	3266.7415
638.82275	1.8258425	0.71629697	3265.2825
639.82373	1.8274771	0.71789306	3261.0181
640.82471	1.8330214	0.71930766	3265.7017
641.82568	1.8356768	0.72086173	3264.572
642.82666	1.8364365	0.72239554	3271.1882
643.82764	1.8420419	0.72414953	3277.2124
644.82861	1.8462447	0.7257123	3265.4834
645.82959	1.8489115	0.72760999	3272.6006
646.83057	1.8510026	0.7291733	3271.3638
647.83154	1.8555821	0.73073691	3268.575
648.83252	1.856198	0.73220098	3268.3611
649.8335	1.8593616	0.73372865	3272.4124
650.83447	1.8644288	0.73537898	3276.3989
651.83545	1.8659855	0.73693025	3277.1436
652.83643	1.8693419	0.73861605	3272.3071
653.8374	1.8723102	0.74032706	3273.113
654.83838	1.8739053	0.74173522	3267.459
655.83936	1.8788429	0.74318147	3273.3394
656.84033	1.8812641	0.74449539	3271.7402
657.84131	1.8837154	0.7459414	3267.3962
658.84229	1.8864464	0.74745995	3274.0972
659.84326	1.8911792	0.74897373	3275.3862
660.84424	1.893683	0.7504608	3278.4836
661.84521	1.8930011	0.75219709	3277.8103
662.84619	1.9001788	0.75369912	3282.2012
663.84717	1.9011286	0.75536513	3279.8811
664.84814	1.9029375	0.75730461	3283.5649
665.84912	1.9087214	0.75885612	3276.8691
666.8501	1.910681	0.76049262	3280.2012
667.85107	1.913834	0.76202321	3277.7136
668.85205	1.9151943	0.76350635	3279.3113
669.85303	1.9204667	0.76511806	3276.2729
670.854	1.9241962	0.76687109	3283.6326
671.85498	1.9291872	0.76855493	3283.7014
672.85596	1.9294612	0.76988447	3281.6023
673.85693	1.9310129	0.77141893	3284.3496
674.85791	1.9344982	0.77306914	3280.0764
675.85889	1.9381806	0.7749421	3287.3003
676.85986	1.9403415	0.77654958	3277.9807
677.86084	1.9406981	0.77831692	3278.1287
678.86182	1.9475037	0.77975863	3284.0493
679.86279	1.951067	0.78148681	3284.2695
680.86377	1.9527587	0.78323436	3279.2305
681.86475	1.957446	0.78483278	3284.9519
682.86572	1.9544473	0.78607315	3283.7747
683.8667	1.9581256	0.78740394	3277.8206
684.86768	1.9660474	0.78903425	3285.9417
685.86865	1.9687345	0.79059923	3285.8489
686.86963	1.9690897	0.79223788	3287.6741
687.87061	1.9737837	0.7940076	3284.916
688.87158	1.9749197	0.79580975	3290.2581
689.87256	1.9793062	0.79783887	3288.7234
690.87354	1.9855269	0.7994256	3287.8892
691.87451	1.9824139	0.80095237	3284.1204
692.87549	1.9871945	0.80256224	3291.5117
693.87646	1.9898001	0.80394369	3285.9631
694.87744	1.9922781	0.80552822	3282.7407
695.87842	1.9995387	0.80708647	3290.3181
696.87939	2.0015988	0.80890769	3291.0588
697.88037	2.0049081	0.81064594	3292.0049
698.88135	2.0045471	0.81219429	3284.967
699.88232	2.0104749	0.81385177	3290.1462
700.8833	2.0102549	0.81546772	3287.7917
701.88428	2.0141516	0.81750834	3293.0469
702.88525	2.018018	0.81920624	3296.7473
703.88623	2.0221167	0.82128441	3295.9255
704.88721	2.0231028	0.82299167	3290.3989
705.88818	2.026269	0.82445532	3287.8911
706.88916	2.0303242	0.82621658	3291.0847
707.89014	2.0348969	0.82788104	3292.5908
708.89111	2.0328803	0.82941675	3287.53
709.89209	2.0391753	0.83036393	3282.0063
710.89307	2.043371	0.83207655	3298.439
711.89404	2.0449073	0.83389896	3296.5144
712.89502	2.0501471	0.83593524	3302.46
713.896	2.0526588	0.83785814	3298.9331
714.89697	2.0542076	0.83941668	3291.9336
715.89795	2.0563293	0.84132254	3301.866
716.89893	2.0629706	0.84307647	3301.6741
717.8999	2.0651987	0.8446269	3300.2891
718.90088	2.0663598	0.84652662	3291.6145
719.90186	2.0736089	0.84806192	3296.9705
720.90283	2.0740335	0.84987217	3303.6331
721.90381	2.0771666	0.85139638	3297.6975
722.90479	2.0782418	0.85308427	3296.4099
723.90576	2.0815458	0.85484517	3300.0173
724.90674	2.0836029	0.85643423	3303.9424
725.90771	2.0869792	0.85855669	3305.2253
726.90869	2.0892622	0.86029971	3301.2749
727.90967	2.0949757	0.8619417	3296.8123
728.91064	2.0987663	0.86357629	3299.1116
729.91162	2.1031086	0.86526525	3306.2881
730.9126	2.102515	0.86703944	3302.5479
731.91357	2.105047	0.86879712	3298.4277
732.91455	2.1073663	0.87050581	3299.3716
733.91553	2.1117525	0.87207049	3299.5508
734.9165	2.1163423	0.87373829	3298.8184
735.91748	2.1200926	0.87528998	3302.6968
736.91846	2.119828	0.87698215	3298.377
737.91943	2.1226451	0.87857991	3300.4624
738.92041	2.1247921	0.88041389	3303.7466
739.92139	2.1327283	0.88235754	3313.0544
740.92236	2.1327808	0.88411158	3303.3838
741.92334	2.1373303	0.88610435	3309.1772
742.92432	2.1399968	0.88788027	3302.5442
743.92529	2.141892	0.88970321	3301.5791
744.92627	2.1456215	0.89129752	3301.4883
745.92725	2.1469486	0.89282113	3297.9143
746.92822	2.1501148	0.89467204	3304.6123
747.9292	2.1538482	0.89667392	3312.0483
748.93018	2.1578553	0.89873743	3305.5464
749.93115	2.1573756	0.90067893	3307.1387
750.93213	2.1618972	0.9025656	3303.4167
751.93311	2.1644049	0.90431821	3303.3425
752.93408	2.1650021	0.90588433	3300.5281
753.93506	2.1725354	0.90756279	3306.2485
754.93604	2.1728523	0.90920877	3306.3562
755.93701	2.1785336	0.91108686	3308.8188
756.93799	2.1797693	0.91287458	3305.5076
757.93896	2.1841779	0.91488463	3302.4729
758.93994	2.1866219	0.91654402	3301.9729
759.94092	2.1891906	0.91814721	3302.8684
760.94189	2.1929483	0.91999441	3309.7095
761.94287	2.1950023	0.9220444	3309.5022
762.94385	2.2002439	0.92377859	3304.6038
763.94482	2.2007179	0.92540634	3305.1311
764.9458	2.2061319	0.92713118	3309.1033
765.94678	2.2062862	0.92902225	3307.2798
766.94775	2.2117043	0.93080884	3306.406
767.94873	2.2138143	0.93250048	3306.761
768.94971	2.2171679	0.93426001	3313.7288
769.95068	2.2222767	0.93612856	3308.7542
770.95166	2.2214563	0.93801123	3309.28
771.95264	2.2264647	0.94009203	3311.0959
772.95361	2.2265003	0.94200301	3305.3215
773.95459	2.2330527	0.94400853	3310.8855
774.95557	2.2352009	0.94587463	3303.7783
775.95654	2.2359855	0.94768894	3311.8625
776.95752	2.2381871	0.94971079	3308.7144
777.9585	2.2414348	0.95145589	3311.1689
778.95947	2.249635	0.95370007	3320.5525
779.96045	2.2521057	0.95558983	3311.4792
780.96143	2.2507386	0.95730758	3305.1262
781.9624	2.2539124	0.95895481	3307.3101
782.96338	2.2602546	0.96095014	3311.1182
783.96436	2.2611086	0.96299756	3313.7607
784.96533	2.2644806	0.96490628	3315.6909
785.96631	2.2699368	0.96709633	3317.7588
786.96729	2.2695997	0.96909153	3311.2256
787.96826	2.2714856	0.97080112	3309.6543
788.96924	2.274019	0.9725166	3308.0461
789.97021	2.2790906	0.97427547	3307.2261
790.97119	2.2824035	0.97643167	3307.2126
791.97217	2.2863038	0.97845632	3314.3625
792.97314	2.2877796	0.98059744	3313.6665
793.97412	2.2890685	0.98282301	3312.6272
794.9751	2.294276	0.9845193	3307.2976
795.97607	2.2983172	0.98655999	3313.6377
796.97705	2.3017139	0.98880583	3317.8188
797.97803	2.3022161	0.99092668	3311.7739
798.979	2.3106265	0.99289721	3310.7893
799.97998	2.3111241	0.99506545	3313.4065
800.98096	2.3111401	0.99664944	3307.2666
801.98193	2.3165066	0.99847066	3309.4666
802.98291	2.3173769	0.99999887	3306.2061
803.98389	2.3196285	1.0015587	3308.4048
804.98486	2.324265	1.0031432	3307.8438
805.98584	2.3239479	1.0050671	3313.6531
806.98682	2.3315654	1.0072227	3311.8938
807.98779	2.3345678	1.0091939	3312.2825
808.98877	2.3378851	1.0113899	3312.1765
809.98975	2.3376398	1.0131997	3306.8164
810.99072	2.3440487	1.0152709	3315.0618
811.9917	2.3449166	1.0173117	3311.6157
812.99268	2.3478038	1.0194994	3309.3772
813.99365	2.3501523	1.0214586	3309.1333
814.99463	2.3558903	1.0234222	3309.585
815.99561	2.3567019	1.0254564	3312.5945
816.99658	2.3622739	1.0274276	3309.1982
817.99756	2.3653219	1.0293754	3311.8276
818.99854	2.3688905	1.031783	3319.8103
819.99951	2.3703034	1.0338551	3315.0376
821.00049	2.3730478	1.0362482	3318.1716
822.00146	2.3743603	1.0384127	3310.5283
823.00244	2.3804924	1.0407802	3317.397
824.00342	2.3823233	1.0433106	3315.9041
825.00439	2.3834198	1.0452223	3306.1062
826.00537	2.3892107	1.0471298	3311.074
827.00635	2.3922553	1.0495023	3314.8445
828.00732	2.3955297	1.0517462	3316.1292
829.0083	2.3990333	1.0541021	3317.1602
830.00928	2.4008083	1.0561396	3308.5313
831.01025	2.4033213	1.0580423	3305.7959
832.01123	2.4049981	1.0600505	3310.1804
833.01221	2.4076366	1.0620648	3310.9265
834.01318	2.4126019	1.0639449	3314.7622
835.01416	2.4148946	1.0661457	3313.1157
836.01514	2.4169383	1.0681758	3317.0667
837.01611	2.4173341	1.0703454	3307.7529
838.01709	2.4212911	1.0726767	3309.3167
839.01807	2.4259193	1.0747052	3307.9976
840.01904	2.4306123	1.0767676	3310.5232
841.02002	2.4349389	1.0784593	3304.9719
842.021	2.4321673	1.080521	3310.4258
843.02197	2.4416075	1.0828953	3314.686
844.02295	2.4414706	1.0850198	3310.5735
845.02393	2.4455445	1.0871247	3309.7502
846.0249	2.4456835	1.0893962	3318.4143
847.02588	2.4509702	1.0916855	3306.9612
848.02686	2.4548416	1.0939791	3311.9619
849.02783	2.4587643	1.0966071	3313.6343
850.02881	2.459383	1.0988986	3309.8545
851.02979	2.4633551	1.1008174	3304.3062
852.03076	2.4644082	1.1028682	3308.7273
853.03174	2.467356	1.1053275	3309.8645
854.03271	2.4708169	1.1076256	3309.9639
855.03369	2.4753311	1.1102979	3311.1045
856.03467	2.4784682	1.1130024	3313.4346
857.03564	2.4801433	1.1151226	3303.9233
858.03662	2.4861023	1.1173288	3310.0959
859.0376	2.4880793	1.1197475	3315.2371
860.03857	2.4905281	1.1222583	3306.5527
861.03955	2.493129	1.1244309	3303.116
862.04053	2.495517	1.1265683	3305.0835
863.0415	2.4992285	1.1288522	3310.1455
864.04248	2.4998844	1.1309294	3304.9287
865.04346	2.5058169	1.1330168	3309.2798
866.04443	2.5067108	1.1356252	3309.2385
867.04541	2.5137296	1.1377889	3298.0681
868.04639	2.5152783	1.1398907	3305.6963
869.04736	2.5171375	1.1419561	3306.4827
870.04834	2.5181355	1.1443253	3303.241
871.04932	2.5231006	1.1464473	3303.1709
872.05029	2.5230026	1.1486205	3300.605
873.05127	2.5306597	1.1508924	3306.1897
874.05225	2.5332007	1.1532698	3315.1628
875.05322	2.5359802	1.1556606	3306.0603
876.0542	2.5379004	1.1578746	3306.4333
877.05518	2.5401487	1.1606004	3303.3018
878.05615	2.5450335	1.1632645	3305.0952
879.05713	2.5474784	1.1656035	3307.8906
880.05811	2.5500495	1.1678146	3301.5627
881.05908	2.5527115	1.1702092	3303.699
882.06006	2.5580254	1.1727781	3307.2214
883.06104	2.5606608	1.1752347	3303.4077
884.06201	2.5622275	1.1779119	3301.4402
885.06299	2.5653541	1.180411	3297.8708
886.06396	2.5681381	1.1827503	3298.8557
887.06494	2.5729795	1.1853553	3302.5391
888.06592	2.5729182	1.1880209	3295.228
889.06689	2.5770268	1.1904386	3291.0134
890.06787	2.5797865	1.1928152	3299.4912
891.06885	2.582294	1.1952276	3303.3723
892.06982	2.5864964	1.1979183	3303.5405
893.0708	2.5893323	1.2007196	3305.156
894.07178	2.5917809	1.203493	3300.8936
895.07275	2.5952387	1.2061801	3295.22
896.07373	2.5968955	1.2086369	3291.272
897.07471	2.6017959	1.2113051	3296.761
898.07568	2.6040263	1.2137363	3291.022
899.07666	2.6078181	1.2163577	3296.1326
900.07764	2.6095805	1.2188157	3296.0315
901.07861	2.6128986	1.2211998	3292.0337
902.07959	2.6127846	1.2238808	3293.23
903.08057	2.6203809	1.2267251	3293.9282
904.08154	2.6223867	1.2292968	3294.4795
905.08252	2.6239038	1.2319263	3288.5439
906.0835	2.6308858	1.2348393	3292.7041
907.08447	2.628783	1.2376846	3291.7834
908.08545	2.6339371	1.2401764	3285.9424
909.08643	2.6363311	1.2424557	3287.7249
910.0874	2.641192	1.2449785	3290.5161
911.08838	2.6435168	1.2473135	3281.8318
912.08936	2.6439598	1.2498655	3288.2979
913.09033	2.6516922	1.2522289	3290.9341
914.09131	2.6520863	1.2546005	3286.9778
915.09229	2.6576402	1.2575538	3286.0667
916.09326	2.6585228	1.2602938	3280.7178
917.09424	2.66452	1.2630641	3281.2915
918.09521	2.6627872	1.2658466	3282.9636
919.09619	2.6686652	1.2687303	3281.8357
920.09717	2.6694555	1.2714096	3279.5925
921.09814	2.6752028	1.2739502	3280.1565
922.09912	2.6740189	1.2765225	3276.9463
923.1001	2.6771719	1.2791917	3278.5767
924.10107	2.682652	1.2819923	3282.8093
925.10205	2.6857283	1.2847682	3278.5852
926.10303	2.6883502	1.2877016	3275.9248
927.104	2.6920416	1.2902203	3273.7205
928.10498	2.6934993	1.2930957	3276.3743
929.10596	2.6969783	1.2959579	3272.7827
930.10693	2.6989875	1.2985951	3272.0405
931.10791	2.7012057	1.3016181	3272.9932
932.10889	2.7034657	1.3043783	3266.2737
933.10986	2.709657	1.3069595	3268.4885
934.11084	2.7125404	1.3101519	3271.7976
935.11182	2.7151203	1.3127626	3267.574
936.11279	2.7179351	1.315763	3266.3564
937.11377	2.7212813	1.3188901	3266.1956
938.11475	2.7263458	1.321455	3262.8105
939.11572	2.7248979	1.3240839	3266.5771
940.1167	2.7317674	1.3271986	3270.9482
941.11768	2.732408	1.3302553	3259.8201
942.11865	2.7354004	1.3330132	3256.373
943.11963	2.7388906	1.3355466	3257.2017
944.12061	2.7430255	1.3379481	3258.1663
945.12158	2.7450993	1.3404766	3255.4011
946.12256	2.7498026	1.343269	3260.2617
947.12354	2.7508302	1.3459907	3259.6631
948.12451	2.7538383	1.3491812	3256.8911
949.12549	2.75741	1.3523295	3250.8735
950.12646	2.763217	1.3554499	3251.2092
951.12744	2.7653844	1.3586311	3253.6345
952.12842	2.7669082	1.361963	3252.9739
953.12939	2.7670476	1.3645936	3241.5339
954.13037	2.7717185	1.3671246	3241.6165
955.13135	2.7740574	1.3697344	3245.7998
956.13232	2.7769163	1.3729835	3251.1677
957.1333	2.7807703	1.3763642	3240.9016
958.13428	2.7859197	1.3793273	3240.4993
959.13525	2.7876334	1.382444	3246.6714
960.13623	2.7899888	1.3850955	3229.364
961.13721	2.7931511	1.387796	3234.1663
962.13818	2.7982686	1.3903023	3236.1528
963.13916	2.7986536	1.3936111	3242.165
964.14014	2.8041537	1.3975083	3240.3931
965.14111	2.8030756	1.400545	3225.7742
966.14209	2.8078694	1.4031918	3225.5879
967.14307	2.8110261	1.4063977	3233.1384
968.14404	2.8160982	1.4091814	3223.761
969.14502	2.8198831	1.4114423	3220.7239
970.146	2.8185956	1.4144647	3221.4255
971.14697	2.8224761	1.4173294	3220.6946
972.14795	2.8268237	1.4202999	3218.0571
973.14893	2.8306811	1.4228097	3218.7554
974.1499	2.8339784	1.4258463	3224.0696
975.15088	2.8372309	1.4288865	3217.196
976.15186	2.8388469	1.4318638	3209.8064
977.15283	2.8416853	1.4346294	3210.019
978.15381	2.846483	1.4379677	3214.0635
979.15479	2.8478637	1.4410831	3208.0337
980.15576	2.8495436	1.4439586	3205.4124
981.15674	2.8537025	1.446617	3203.2915
982.15771	2.8554707	1.4494674	3205.4529
983.15869	2.8625758	1.4526002	3207.0073
984.15967	2.8635504	1.4556135	3201.0879
985.16064	2.8664997	1.4589955	3202.8486
986.16162	2.8661757	1.4619256	3194.5669
987.1626	2.8744636	1.4648348	3199.5789
988.16357	2.8754926	1.4677374	3194.3459
989.16455	2.8765182	1.4710716	3187.6946
990.16553	2.8816209	1.4737829	3185.5049
991.1665	2.8821943	1.4765168	3187.1057
992.16748	2.8887432	1.4791574	3187.7573
993.16846	2.8908055	1.4819629	3192.9133
994.16943	2.8956809	1.4850951	3185.1768
995.17041	2.8991437	1.4882683	3179.7195
996.17139	2.9005964	1.4912827	3180.4971
997.17236	2.9003644	1.4945331	3179.095
998.17334	2.9051025	1.4976008	3176.6978
999.17432	2.9066956	1.5009663	3172.689
1000.1753	2.9141943	1.5044624	3171.8896
1001.1763	2.9135273	1.5077361	3169.012
1002.1772	2.917794	1.5111066	3166.5452
1003.1782	2.9179924	1.5142782	3160.6301
1004.1792	2.9229062	1.5171647	3161.8337
1005.1802	2.9266336	1.5206276	3166.4451
1006.1812	2.9295297	1.524097	3160.2532
1007.1821	2.9317117	1.5268228	3149.2781
1008.1831	2.933023	1.5300219	3154.1072
1009.1841	2.9335825	1.5332807	3148.0547
1010.1851	2.9407902	1.5360774	3147.9592
1011.186	2.9434657	1.5389982	3149.7449
1012.187	2.9509823	1.5417554	3148.5957
1013.188	2.9499638	1.5449245	3146.562
1014.189	2.9500461	1.5480936	3142.9302
1015.1899	2.9556699	1.5516776	3136.2336
1016.1909	2.9618084	1.5543065	3128.4497
1017.1919	2.9620736	1.5570532	3131.3923
1018.1929	2.96122	1.5595386	3131.3223
1019.1938	2.9684336	1.5623642	3130.958
1020.1948	2.969594	1.5651034	3124.7214
1021.1958	2.9737027	1.5677128	3126.521
1022.1968	2.9784346	1.5711423	3127.552
1023.1978	2.9831944	1.5742909	3127.019
1024.1987	2.9839504	1.5777062	3114.9409
1025.1997	2.9891448	1.5804445	3115.2097
1026.2007	2.9871564	1.5838017	3118.5547
1027.2017	2.9955308	1.5872427	3110.0378
1028.2026	2.9954417	1.5899093	3098.8967
1029.2036	2.9970539	1.59194	3098.2954
1030.2046	3.0030386	1.5935079	3097.1772
1031.2056	3.0049117	1.5958287	3104.1672
1032.2065	3.0052421	1.598843	3102.7014
1033.2075	3.008877	1.6025592	3104.2444
1034.2085	3.0128882	1.6062195	3098.2141
1035.2095	3.0161941	1.6095388	3095.1646
1036.2104	3.016145	1.6127883	3086.8298
1037.2114	3.0237591	1.61602	3088.3459
1038.2124	3.0259178	1.6192162	3086.7061
1039.2134	3.0274272	1.6225162	3086.6243
1040.2144	3.0307159	1.6264402	3081.3594
1041.2153	3.0361381	1.630071	3076.9641
1042.2163	3.0378134	1.6331824	3071.4585
1043.2173	3.0394068	1.6361942	3067.2332
1044.2183	3.0439751	1.6389666	3066.9443
1045.2192	3.0467045	1.6425848	3061.9016
1046.2202	3.0488839	1.6459705	3060.4561
1047.2212	3.0517294	1.6494625	3052.5522
1048.2222	3.0553074	1.6529818	3060.0034
1049.2231	3.0610807	1.6561526	3047.7615
1050.2241	3.0603635	1.6589839	3042.5671
1051.2251	3.0651026	1.6618425	3043.3428
1052.2261	3.0682359	1.6651955	3041.1436
1053.2271	3.0675206	1.6683106	3035.4792
1054.228	3.0708468	1.6711605	3032.0374
1055.229	3.0720181	1.6742868	3024.7483
1056.23	3.0819104	1.677592	3029.499
1057.231	3.0802751	1.6807069	3026.5076
1058.2319	3.0850196	1.6842233	3023.9316
1059.2329	3.0872798	1.6874815	3015.3884
1060.2339	3.0913589	1.6910323	3015.7632
1061.2349	3.095293	1.6944799	3011.116
1062.2358	3.0952713	1.6980813	3007.2339
1063.2368	3.1006768	1.7012587	3002.5466
1064.2378	3.1043551	1.7043849	3003.5149
1065.2388	3.1034589	1.7074223	2990.6897
1066.2397	3.108891	1.7105595	2994.075
1067.2407	3.1143324	1.7136558	2992.3394
1068.2417	3.1140904	1.7166535	2985.6965
1069.2427	3.1181335	1.7202876	2985.5103
1070.2437	3.1171498	1.7239256	2977.5337
1071.2446	3.1235309	1.7275915	2975.9297
1072.2456	3.125916	1.7310374	2968.6033
1073.2466	3.1296384	1.7338961	2968.2371
1074.2476	3.1331716	1.7375263	2966.4443
1075.2485	3.1334455	1.7407682	2961.4875
1076.2495	3.1367495	1.7445599	2956.7244
1077.2505	3.141691	1.748111	2952.2341
1078.2515	3.1436625	1.751442	2952.8723
1079.2524	3.1476269	1.7547466	2948.647
1080.2534	3.1501997	1.7584026	2941.9148
1081.2544	3.1556826	1.7616798	2931.6177
1082.2554	3.1581023	1.7650658	2934.261
1083.2563	3.1580896	1.7681808	2918.561
1084.2573	3.1615605	1.7709948	2923.7578
1085.2583	3.166997	1.7747296	2924.5542
1086.2593	3.1692162	1.7783846	2920.135
1087.2603	3.1716769	1.7818685	2912.0762
1088.2612	3.1788507	1.7853708	2908.3706
1089.2622	3.1763027	1.7887558	2899.7468
1090.2632	3.1846526	1.7921031	2899.0889
1091.2642	3.1839089	1.7951256	2896.939
1092.2651	3.1880496	1.7983564	2885.1545
1093.2661	3.1929202	1.8015543	2883.5405
1094.2671	3.1928029	1.8050263	2886.7639
1095.2681	3.1963007	1.8087662	2871.1125
1096.269	3.2005177	1.8119094	2873.7817
1097.27	3.2028692	1.8154629	2875.9487
1098.271	3.204432	1.8191186	2860.7256
1099.272	3.2087185	1.8221381	2852.5803
1100.2729	3.211863	1.8252022	2851.4705
1101.2739	3.2169044	1.8281798	2850.2087
1102.2749	3.2199261	1.8314873	2845.0728
1103.2759	3.2204983	1.8349353	2841.283
1104.2769	3.2216847	1.8387983	2828.6917
1105.2778	3.2210784	1.8421378	2830.4148
1106.2788	3.2294748	1.845338	2823.5935
1107.2798	3.2326658	1.848231	2816.092
1108.2808	3.2351766	1.8519943	2815.1453
1109.2817	3.238862	1.8558056	2813.9329
1110.2827	3.2409749	1.8600768	2799.4773
1111.2837	3.2438178	1.8637218	2793.5591
1112.2847	3.2474217	1.8666449	2787.4224
1113.2856	3.2524538	1.8705813	2787.4106
1114.2866	3.2562904	1.8736633	2774.0281
1115.2876	3.2551179	1.8766215	2767.2861
1116.2886	3.2575679	1.8805017	2766.304
1117.2896	3.26402	1.8839716	2767.7188
1118.2905	3.2660234	1.8868947	2747.4043
1119.2915	3.266449	1.8904556	2757.5122
1120.2925	3.2735291	1.8945813	2753.2874
1121.2935	3.2749035	1.8980279	2734.3228
1122.2944	3.2796905	1.9020419	2731.0798
1123.2954	3.2799599	1.9055433	2723.656
1124.2964	3.2839682	1.9092669	2721.9958
1125.2974	3.2886622	1.912984	2712.3867
1126.2983	3.2865055	1.9156471	2694.3872
1127.2993	3.2933619	1.9187653	2693.385
1128.3003	3.2939951	1.9226278	2687.0872
1129.3013	3.2996156	1.927179	2681.8245
1130.3022	3.3033762	1.9318838	2660.9333
1131.3032	3.3066819	1.9355633	2649.5085
1132.3042	3.3099349	1.9387083	2641.2437
1133.3052	3.3084846	1.942144	2633.9927
1134.3062	3.3155391	1.9463975	2624.9272
1135.3071	3.3170741	1.9517115	2600.8662
1136.3081	3.3228164	1.9621969	2528.543
1136.4082	3.3241994	1.9676018	2481.5928