File: datasets/am_bench_2022/raw_data/90-X.19-4/specimen.dat
MTS793|MPT|ENU|1|2|.|/|:|1|0|0|A

Operator Information						Time:	11.447998	Sec	11/2/2021 2:20:02 PM
Operator	Nick Derimow
Project	AM Bench 2022 mini-tensile challenge
Specimen ID	90-X.19-4
Material	PBF-L Inconel 625
Specimen Width	2.54	mm
Specimen Thickness	1.51	mm
Notes
Operator Information End

Data Acquisition						Time:	1012.4412	Sec	11/2/2021 2:36:43 PM
Time	Axial Displacement	Axial Extensometer	Axial Force
Sec	mm	mm	N
11.561035	0.00088672049	6.7308218e-05	31.687283
12.562012	0.0022562116	5.5109012e-05	42.058941
13.562988	0.0056315344	0.00020400225	58.330727
14.563965	0.0065895533	0.00030107037	71.986259
15.564941	0.010731629	0.00028533884	81.577545
16.565918	0.011510215	0.00034896057	90.370789
17.566895	0.017024137	0.00038202485	101.09229
18.567871	0.018663675	0.00045446199	109.72372
19.568848	0.024006771	0.00062574062	130.55869
20.569824	0.022396533	0.00054455973	138.47302
21.570801	0.029223857	0.0005837871	153.33839
22.571777	0.032016266	0.00071895676	167.39629
23.572754	0.034864608	0.00082333537	178.93341
24.57373	0.034815434	0.00085864117	192.28055
25.574707	0.040409315	0.0010589282	215.02608
26.575684	0.041030955	0.0010699022	230.34349
27.57666	0.047223069	0.0012110454	251.33527
28.577637	0.046269353	0.0013632907	268.65515
29.578613	0.053901847	0.001396523	287.39481
30.57959	0.054672237	0.0015732322	306.56708
31.580566	0.056790758	0.0016869201	324.01135
32.581543	0.057551928	0.0017781407	341.57666
33.58252	0.065732561	0.00199876	366.75723
34.583496	0.069033094	0.0021234762	391.65903
35.584473	0.067363441	0.0022354398	409.87381
36.585449	0.071203664	0.002459944	434.48193
37.586426	0.073133327	0.0025680189	459.02856
38.587402	0.077254042	0.0027343882	475.05365
39.588379	0.083915353	0.002863534	500.65613
40.589355	0.08608187	0.0029798865	524.8327
41.590332	0.086773939	0.0030544535	541.97754
42.591309	0.089199647	0.0032193314	565.70532
43.592285	0.092941567	0.003419643	591.27399
44.593262	0.094287448	0.0035454687	616.9201
45.594238	0.096138224	0.0037034713	644.51776
46.595215	0.10328799	0.0039688512	672.854
47.596191	0.10593191	0.0041166288	694.10828
48.597168	0.10592638	0.0041571469	717.14746
49.598145	0.11408232	0.0044164951	740.26074
50.599121	0.11491151	0.0045745634	773.81104
51.600098	0.11763308	0.0047788704	800.72736
52.601074	0.1188069	0.0048660585	822.90997
53.602051	0.12472733	0.0051689735	854.6004
54.603027	0.12256844	0.0052958657	883.52509
55.604004	0.13164686	0.0055142352	912.45538
56.60498	0.13165833	0.0056704022	934.96796
57.605957	0.13449724	0.0057853768	960.05817
58.606934	0.13830693	0.0059369416	991.47504
59.60791	0.141931	0.0061122156	1014.0009
60.608887	0.1416714	0.0062851324	1041.646
61.609863	0.15027882	0.0064385207	1066.2261
62.61084	0.14970799	0.0066991556	1098.2731
63.611816	0.15328	0.0068076896	1122.7657
64.612793	0.15579705	0.0070499699	1150.8864
65.61377	0.15762857	0.0071662855	1171.9772
66.614746	0.16448186	0.0072964095	1198.7229
67.615723	0.16702764	0.0074698692	1225.5629
68.616699	0.16865565	0.0076451381	1250.36
69.617676	0.17264426	0.0079126935	1286.4789
70.618652	0.17324848	0.0081024664	1309.9073
71.619629	0.17719832	0.0082447128	1342.5316
72.620605	0.17837967	0.008437397	1368.7595
73.621582	0.18317223	0.0085435351	1389.9269
74.622559	0.18348959	0.0086414013	1419.131
75.623535	0.18940495	0.0089950506	1445.4385
76.624512	0.19157326	0.0091947271	1487.6501
77.625488	0.19207381	0.0093066376	1508.3531
78.626465	0.19743596	0.0094368821	1530.6008
79.627441	0.20106043	0.0095284376	1549.4352
80.628418	0.20472178	0.0096931281	1575.9244
81.629395	0.20870255	0.0097950874	1598.22
82.630371	0.20968255	0.010085026	1629.7642
83.631348	0.21253361	0.010253911	1661.2834
84.632324	0.21259405	0.010435759	1683.4221
85.633301	0.21935391	0.010664582	1716.1149
86.634277	0.22179329	0.010840549	1744.3254
87.635254	0.22353384	0.010973874	1770.1232
88.63623	0.22586058	0.011180733	1798.0096
89.637207	0.22951804	0.011295442	1825.7809
90.638184	0.23178491	0.011429287	1844.4059
91.63916	0.23780537	0.011721524	1876.3024
92.640137	0.24055603	0.011826281	1896.0149
93.641113	0.24174537	0.011999461	1920.5824
94.64209	0.24564931	0.012138514	1942.3674
95.643066	0.24854663	0.012258731	1969.4935
96.644043	0.25418258	0.01245962	1991.8899
97.64502	0.25320646	0.012694487	2017.3247
98.645996	0.25807786	0.012697832	2035.2358
99.646973	0.26068282	0.012924197	2054.9097
100.64795	0.26698932	0.013019108	2083.1218
101.64893	0.26689219	0.013219117	2098.7117
102.6499	0.27185744	0.013307375	2127.3301
103.65088	0.27617073	0.0134524	2144.6812
104.65186	0.27425957	0.013748668	2167.0093
105.65283	0.27941254	0.013878908	2191.5742
106.65381	0.28215167	0.014090517	2205.1492
107.65479	0.28634205	0.014133736	2222.6245
108.65576	0.28781584	0.014376414	2241.6272
109.65674	0.29062441	0.014648437	2265.3643
110.65771	0.29526761	0.014734737	2276.5562
111.65869	0.29594007	0.014800747	2295.759
112.65967	0.30019927	0.014959925	2307.147
113.66064	0.30412146	0.015201299	2327.5615
114.66162	0.30467507	0.015327544	2343.0723
115.6626	0.30888286	0.015548226	2365.061
116.66357	0.31173366	0.015756417	2381.2439
117.66455	0.3146593	0.015989544	2393.3071
118.66553	0.31846121	0.016052276	2404.4395
119.6665	0.3229534	0.016413635	2425.874
120.66748	0.32781848	0.016638216	2436.7307
121.66846	0.32735276	0.016616926	2441.2766
122.66943	0.33130711	0.016810626	2453.2595
123.67041	0.33270571	0.017080404	2465.4976
124.67139	0.33593595	0.017202541	2478.937
125.67236	0.33995074	0.017397091	2491.9138
126.67334	0.34167632	0.017564235	2497.6428
127.67432	0.34579581	0.017763978	2512.3684
128.67529	0.34958768	0.018085787	2530.2803
129.67627	0.35120058	0.018435819	2537.0078
130.67725	0.35514694	0.018568572	2547.8928
131.67822	0.35947725	0.018886706	2563.4758
132.6792	0.36196524	0.019096971	2570.8621
133.68018	0.36219835	0.019364113	2580.1987
134.68115	0.36753243	0.019615227	2587.8479
135.68213	0.37044102	0.019938391	2600.1597
136.68311	0.37518281	0.020203799	2602.9971
137.68408	0.37720239	0.020405225	2605.7808
138.68506	0.37509942	0.020779589	2618.094
139.68604	0.37903652	0.021181209	2630.1528
140.68701	0.38622978	0.021568505	2636.5474
141.68799	0.38839957	0.021959966	2646.3647
142.68896	0.39147165	0.022405105	2653.2358
143.68994	0.39341828	0.022765715	2661.9641
144.69092	0.39924574	0.023292074	2673.71
145.69189	0.39974526	0.023745995	2678.728
146.69287	0.40560099	0.024112746	2678.4236
147.69385	0.4087995	0.024817411	2691.2639
148.69482	0.40963683	0.025301382	2696.9229
149.6958	0.41405836	0.026017724	2705.4976
150.69678	0.4149099	0.026607385	2707.6797
151.69775	0.41768101	0.027392825	2718.8291
152.69873	0.42387393	0.02801517	2723.5769
153.69971	0.42671517	0.028700458	2726.2146
154.70068	0.42796069	0.029435182	2738.5205
155.70166	0.43297508	0.030412333	2741.387
156.70264	0.43425503	0.031154174	2745.4973
157.70361	0.43853986	0.031941101	2755.1382
158.70459	0.43823683	0.032562613	2752.1816
159.70557	0.44234386	0.033345461	2765.2058
160.70654	0.44690198	0.034037624	2773.4019
161.70752	0.44913018	0.034837589	2771.1191
162.7085	0.45006114	0.035771526	2777.7791
163.70947	0.4518019	0.036713015	2779.1548
164.71045	0.45879498	0.037592985	2781.3345
165.71143	0.46109053	0.03851242	2791.0847
166.7124	0.46532783	0.039459739	2797.3635
167.71338	0.46756789	0.0403837	2801.5862
168.71436	0.47274154	0.04126735	2806.8877
169.71533	0.47149581	0.042134583	2805.8921
170.71631	0.47638932	0.043217421	2813.1218
171.71729	0.476928	0.044312749	2813.71
172.71826	0.48482075	0.045229949	2818.7029
173.71924	0.48565218	0.046121541	2818.9524
174.72021	0.48871034	0.046899837	2829.3538
175.72119	0.49094975	0.047886133	2826.5999
176.72217	0.49496397	0.048930164	2837.2947
177.72314	0.49624392	0.049912497	2832.9602
178.72412	0.49846613	0.050822735	2845.177
179.7251	0.50443268	0.05178839	2847.1755
180.72607	0.50743204	0.05268681	2850.7354
181.72705	0.51002735	0.053788383	2856.2866
182.72803	0.51326829	0.05468506	2856.8687
183.729	0.51356024	0.055661112	2860.1987
184.72998	0.52074999	0.056649506	2865.2715
185.73096	0.52247804	0.057475239	2867.155
186.73193	0.52643853	0.058508705	2870.03
187.73291	0.52656925	0.059623305	2872.6345
188.73389	0.53211576	0.060821638	2884.0659
189.73486	0.53389037	0.061988223	2882.042
190.73584	0.5363847	0.063124619	2885.9128
191.73682	0.53898185	0.064145118	2887.6992
192.73779	0.54205823	0.06523186	2888.6897
193.73877	0.54589206	0.066364057	2893.5454
194.73975	0.54890746	0.067445882	2897.0471
195.74072	0.55267638	0.068589427	2898.0798
196.7417	0.55502456	0.069633268	2900.0229
197.74268	0.55750251	0.07059893	2900.1157
198.74365	0.56132388	0.07161653	2909.3022
199.74463	0.56654429	0.072700679	2913.0408
200.74561	0.56705379	0.073771283	2913.0093
201.74658	0.56816286	0.074740998	2912.9934
202.74756	0.57201415	0.075895861	2922.2341
203.74854	0.57424253	0.077170819	2923.3052
204.74951	0.57905376	0.078301147	2921.0254
205.75049	0.5803988	0.079161569	2921.321
206.75146	0.58617932	0.080099411	2929.417
207.75244	0.58787233	0.08082927	2928.7546
208.75342	0.58965981	0.081933513	2933.7014
209.75439	0.59401488	0.082825772	2938.9041
210.75537	0.59524071	0.083896726	2936.1353
211.75635	0.59978372	0.085065179	2945.938
212.75732	0.60460681	0.086136125	2948.7581
213.7583	0.60618347	0.087200984	2952.1743
214.75928	0.60834336	0.088311084	2950.4111
215.76025	0.61271077	0.089428209	2956.4458
216.76123	0.61203194	0.090633169	2953.874
217.76221	0.61736929	0.091646686	2953.3567
218.76318	0.62008351	0.092817977	2967.166
219.76416	0.62347156	0.093679011	2955.6687
220.76514	0.62499851	0.094818532	2966.1147
221.76611	0.62879986	0.095793359	2963.4531
222.76709	0.63327873	0.097038247	2975.3135
223.76807	0.63522577	0.097983263	2969.9329
224.76904	0.63882935	0.099085018	2977.0864
225.77002	0.64068711	0.10009967	2975.6035
226.771	0.64365393	0.10132462	2982.4441
227.77197	0.64676535	0.10234472	2982.4492
228.77295	0.64906275	0.10346559	2980.4753
229.77393	0.65406322	0.10452425	2985.9155
230.7749	0.65571219	0.10577603	2987.4944
231.77588	0.66095138	0.10665751	2986.7271
232.77686	0.66141278	0.10776789	2992.7261
233.77783	0.6655876	0.10877655	2993.3689
234.77881	0.66983765	0.10978461	2998.3584
235.77979	0.67277038	0.11085301	2997.9094
236.78076	0.67383891	0.11177222	3000.425
237.78174	0.67861789	0.11280875	2997.9897
238.78271	0.68118417	0.11387615	3008.3098
239.78369	0.68245757	0.11491502	3011.9084
240.78467	0.68510777	0.1160278	3012.7683
241.78564	0.68953067	0.11718037	3010.6094
242.78662	0.69387394	0.11832794	3018.1147
243.7876	0.69617236	0.11916533	3012.7488
244.78857	0.69559419	0.12004595	3013.553
245.78955	0.70179796	0.12116856	3021.6316
246.79053	0.70106345	0.12224092	3025.5295
247.7915	0.7054202	0.12353008	3029.7573
248.79248	0.71027714	0.12463684	3026.0349
249.79346	0.71036524	0.12546405	3017.9844
250.79443	0.7159183	0.12660855	3034.7117
251.79541	0.71844763	0.12751105	3033.3455
252.79639	0.71943355	0.12867501	3036.0164
253.79736	0.72752196	0.12989458	3040.8562
254.79834	0.72906637	0.13101202	3044.0742
255.79932	0.73310065	0.13208018	3042.8022
256.80029	0.7347039	0.1330415	3044.5747
257.80127	0.73808169	0.13386381	3040.6343
258.80225	0.73833227	0.13504055	3049.4087
259.80322	0.74444515	0.13615231	3054.5442
260.8042	0.7451489	0.13724343	3052.5308
261.80518	0.75009561	0.13834836	3058.825
262.80615	0.75224465	0.13953356	3057.6836
263.80713	0.75437778	0.14058727	3054.9409
264.80811	0.75926125	0.14161724	3056.928
265.80908	0.76271015	0.14260386	3062.4419
266.81006	0.76814467	0.14377375	3069.2268
267.81104	0.76548165	0.14500788	3068.979
268.81201	0.76935077	0.14619444	3063.6807
269.81299	0.773929	0.14709795	3064.0171
270.81396	0.77749389	0.14812335	3073.8789
271.81494	0.77785659	0.14914912	3069.0815
272.81592	0.779854	0.15032567	3078.9375
273.81689	0.78619915	0.15129825	3073.0806
274.81787	0.78828764	0.15207309	3079.1638
275.81885	0.79091865	0.15321721	3082.439
276.81982	0.79261631	0.1542922	3081.1169
277.8208	0.79759693	0.15534534	3087.0957
278.82178	0.8008467	0.15637854	3086.9475
279.82275	0.80307341	0.1573377	3088.2732
280.82373	0.80583942	0.15824232	3091.8647
281.82471	0.8096292	0.15918015	3091.3909
282.82568	0.81432503	0.16009718	3094.6306
283.82666	0.81586075	0.16105777	3093.1426
284.82764	0.81793666	0.16193248	3090.5193
285.82861	0.82246858	0.16283002	3097.4602
286.82959	0.82479572	0.16390243	3102.1335
287.83057	0.82914078	0.1649472	3102.9768
288.83154	0.83123392	0.16582017	3098.8291
289.83252	0.83672184	0.16710657	3115.7776
290.8335	0.83615839	0.1680555	3109.5034
291.83447	0.84068477	0.16909201	3103.6636
292.83545	0.8388871	0.16992138	3110.6755
293.83643	0.8439678	0.17077766	3110.0251
294.8374	0.85038567	0.17181157	3113.0579
295.83838	0.84799075	0.17292224	3114.8933
296.83936	0.85843313	0.17409679	3125.2876
297.84033	0.85907787	0.17503223	3116.3381
298.84131	0.85885799	0.17602482	3125.4214
299.84229	0.86473221	0.17732006	3129.1731
300.84326	0.86479878	0.17839503	3123.8149
301.84424	0.87016851	0.17932221	3121.4219
302.84521	0.87697017	0.18020052	3128.6189
303.84619	0.87435579	0.18129979	3132.1768
304.84717	0.87674028	0.18222784	3128.6667
305.84814	0.88271672	0.18319197	3133.6118
306.84912	0.88516557	0.18416625	3132.2534
307.8501	0.89021415	0.18531711	3142.2837
308.85107	0.89156443	0.18657315	3135.9521
309.85205	0.89505202	0.18771273	3143.4531
310.85303	0.89790308	0.18867232	3143.6038
311.854	0.90097004	0.18967178	3143.9158
312.85498	0.90663618	0.19055104	3144.8125
313.85596	0.90723199	0.19153342	3147.6819
314.85693	0.90664804	0.19259988	3144.3633
315.85791	0.91093481	0.19358338	3143.5188
316.85889	0.91695154	0.19448179	3148.5403
317.85986	0.91816407	0.195421	3150.5254
318.86084	0.9231478	0.19662997	3156.1572
319.86182	0.92574209	0.19764228	3157.123
320.86279	0.92503172	0.19863671	3160.615
321.86377	0.92988938	0.19968621	3157.9336
322.86475	0.93383229	0.20050013	3155.8877
323.86572	0.93933362	0.20149602	3160.1792
324.8667	0.93864024	0.20229679	3156.1089
325.86768	0.94129086	0.20324105	3168.1118
326.86865	0.94480103	0.20425077	3168.969
327.86963	0.94769937	0.20548888	3167.8079
328.87061	0.94918013	0.20666544	3171.8972
329.87158	0.957407	0.20771225	3177.3176
330.87256	0.95657265	0.20858555	3168.1089
331.87354	0.96163076	0.20962112	3176.3457
332.87451	0.96483749	0.21058497	3172.4893
333.87549	0.96602279	0.21164459	3177.8245
334.87646	0.96715581	0.21276012	3178.4705
335.87744	0.97256649	0.2139301	3184.6047
336.87842	0.97724718	0.21483219	3180.2068
337.87939	0.97891092	0.21576118	3180.8704
338.88037	0.98400623	0.21673015	3184.7244
339.88135	0.98171091	0.21775106	3185.011
340.88232	0.98704469	0.21874189	3192.7063
341.8833	0.98786819	0.2198053	3188.3877
342.88428	0.99314797	0.22081667	3191.1836
343.88525	0.99779916	0.22184424	3192.6099
344.88623	0.99912357	0.22285609	3193.1306
345.88721	1.0036291	0.2237127	3195.3445
346.88818	1.0034508	0.22476469	3194.5461
347.88916	1.0080132	0.22560123	3193.3464
348.89014	1.0106405	0.22659604	3199.4448
349.89111	1.0130793	0.22793922	3204.5349
350.89209	1.0149747	0.22885513	3201.7524
351.89307	1.0184414	0.2297557	3201.5544
352.89404	1.0250055	0.23084293	3205.9287
353.89502	1.0275553	0.23162793	3205.5308
354.896	1.0310206	0.2326179	3209.7327
355.89697	1.032639	0.23362009	3213.1951
356.89795	1.0352358	0.23474094	3215.2214
357.89893	1.0367286	0.23561157	3217.8411
358.8999	1.0452446	0.23669708	3219.9656
359.90088	1.0455279	0.2376729	3216.5042
360.90186	1.0468976	0.23855859	3217.4539
361.90283	1.0492002	0.23984705	3219.5554
362.90381	1.0526835	0.24088642	3219.0688
363.90479	1.0560274	0.24205613	3233.2893
364.90576	1.0586995	0.24307108	3225.05
365.90674	1.0612183	0.24406554	3220.2842
366.90771	1.0663594	0.24499483	3229.0762
367.90869	1.0696853	0.24610382	3234.5693
368.90967	1.0703039	0.24699852	3231.4312
369.91064	1.0725716	0.24799149	3229.5422
370.91162	1.0750281	0.24912153	3231.2878
371.9126	1.0807483	0.25014845	3234.8003
372.91357	1.0852208	0.25107285	3235.8823
373.91455	1.0850785	0.25190043	3230.0525
374.91553	1.089478	0.25285357	3238.3164
375.9165	1.0940628	0.25380439	3247.1174
376.91748	1.0966702	0.25501761	3248.6514
377.91846	1.1001348	0.25607708	3240.3696
378.91943	1.1025881	0.25717771	3245.0322
379.92041	1.1046712	0.25808552	3240.6909
380.92139	1.1054833	0.25900745	3246.9258
381.92236	1.1112317	0.26006478	3249.3279
382.92334	1.111339	0.26096296	3244.9731
383.92432	1.1177627	0.26184243	3251.1853
384.92529	1.1226841	0.26284379	3257.7214
385.92627	1.1243954	0.26370573	3252.1023
386.92725	1.1244855	0.26476768	3250.6685
387.92822	1.1259617	0.26574296	3254.1992
388.9292	1.1332141	0.2668528	3263.1138
389.93018	1.1318729	0.26798862	3264.2017
390.93115	1.1371888	0.26918653	3265.2671
391.93213	1.1408112	0.27003911	3258.957
392.93311	1.1422	0.27092683	3259.6389
393.93408	1.1441747	0.27186644	3262.4314
394.93506	1.148554	0.27293044	3266.8186
395.93604	1.1516457	0.27386457	3267.4578
396.93701	1.1544187	0.27489606	3274.5254
397.93799	1.1591442	0.27584979	3268.6101
398.93896	1.1604352	0.27672163	3264.2021
399.93994	1.1638364	0.27763996	3269.8706
400.94092	1.1663954	0.27874088	3275.2415
401.94189	1.1700331	0.27976039	3278.4761
402.94287	1.1769533	0.28058904	3277.7231
403.94385	1.1772451	0.28152427	3275.6846
404.94482	1.1789479	0.28254452	3282.9917
405.9458	1.1830255	0.28383395	3282.8105
406.94678	1.1818473	0.28475285	3281.1902
407.94775	1.1889277	0.28583476	3278.1362
408.94873	1.1920004	0.28692892	3283.3394
409.94971	1.1968673	0.28774214	3280.6921
410.95068	1.1974771	0.28869078	3282.5015
411.95166	1.1984698	0.28979322	3287.6384
412.95264	1.2066017	0.29072285	3292.0964
413.95361	1.2068979	0.29176056	3294.0828
414.95459	1.2113003	0.29274568	3292.4946
415.95557	1.2109094	0.29366052	3298.3315
416.95654	1.2191137	0.29477608	3296.1963
417.95752	1.2175014	0.29575753	3293.0774
418.9585	1.2230141	0.29693308	3303.3508
419.95947	1.2268066	0.29782256	3302.2175
420.96045	1.2256373	0.29885399	3294.3936
421.96143	1.2292728	0.2998493	3300.2339
422.9624	1.232378	0.30076614	3298.1177
423.96338	1.2407614	0.30165467	3302.4331
424.96436	1.2424906	0.30254203	3302.0232
425.96533	1.245509	0.30350938	3307.8523
426.96631	1.2448547	0.30407003	3295.7749
427.96729	1.2477561	0.3050999	3303.7336
428.96826	1.2501158	0.30624527	3315.0793
429.96924	1.2546936	0.30735675	3309.1418
430.97021	1.2548237	0.30853024	3308.4846
431.97119	1.260164	0.30967665	3311.8726
432.97217	1.2643595	0.31059012	3310.1152
433.97314	1.2642258	0.3115505	3314.2881
434.97412	1.2697924	0.31253555	3317.3313
435.9751	1.2706903	0.31352189	3317.9153
436.97607	1.2738329	0.31446692	3318.0962
437.97705	1.2790452	0.31548217	3324.741
438.97803	1.2822937	0.31679723	3327.8071
439.979	1.2860869	0.31763041	3323.4771
440.97998	1.2887832	0.3186821	3325.0967
441.98096	1.289279	0.31974068	3328.2805
442.98193	1.2955064	0.32075945	3326.0566
443.98291	1.2928314	0.32179838	3326.2844
444.98389	1.2993833	0.32294121	3325.6809
445.98486	1.3020101	0.32400882	3331.6218
446.98584	1.308182	0.32494634	3325.4573
447.98682	1.3089825	0.32591715	3328.334
448.98779	1.3143651	0.32683665	3332.4216
449.98877	1.3152059	0.32788974	3332.7627
450.98975	1.3196031	0.32874149	3334.7078
451.99072	1.3217553	0.32969275	3338.6243
452.9917	1.3251188	0.33078331	3347.1033
453.99268	1.3266809	0.33195713	3338.9148
454.99365	1.3296142	0.33304107	3340.7285
455.99463	1.3309581	0.33401635	3340.3091
456.99561	1.3339206	0.33500153	3341.7932
457.99658	1.3406131	0.33619794	3346.792
458.99756	1.3409904	0.33711135	3343.1665
459.99854	1.3455626	0.33808169	3344.6707
460.99951	1.350175	0.33894295	3347.925
462.00049	1.3493775	0.33989969	3345.927
463.00146	1.3532383	0.34076807	3351.4792
464.00244	1.3572513	0.34196252	3349.3416
465.00342	1.3586093	0.34325898	3353.9392
466.00439	1.3621911	0.3443391	3354.2612
467.00537	1.3641328	0.34540132	3354.0806
468.00635	1.370133	0.34631839	3351.9456
469.00732	1.3718364	0.34733826	3361.2439
470.0083	1.3744752	0.34828249	3359.6511
471.00928	1.3781755	0.34931296	3356.8293
472.01025	1.3806303	0.35036054	3363.0981
473.01123	1.3856683	0.35142258	3364.2649
474.01221	1.3874381	0.35235292	3363.2419
475.01318	1.387062	0.35327733	3359.5881
476.01416	1.3935111	0.35415879	3365.8945
477.01514	1.3963561	0.35529339	3369.5952
478.01611	1.3974146	0.35649738	3366.7336
479.01709	1.4020578	0.35749698	3367.9214
480.01807	1.4050907	0.35858527	3366.2822
481.01904	1.409211	0.35952082	3369.9551
482.02002	1.4130459	0.36036441	3367.2502
483.021	1.4144127	0.36140063	3372.0811
484.02197	1.4182968	0.36247867	3376.1396
485.02295	1.4180802	0.36339289	3371.5435
486.02393	1.422228	0.36457124	3376.2288
487.0249	1.4262393	0.36559272	3380.3083
488.02588	1.426662	0.36671239	3377.5901
489.02686	1.4291977	0.36770549	3377.5256
490.02783	1.43462	0.36865717	3381.9163
491.02881	1.436429	0.36979395	3380.5701
492.02979	1.4412011	0.37076429	3381.1069
493.03076	1.4448743	0.37162432	3386.6587
494.03174	1.4463762	0.3725712	3384.4299
495.03271	1.4471892	0.37350547	3388.5791
496.03369	1.4533372	0.37453222	3383.1802
497.03467	1.4533129	0.37569258	3389.145
498.03564	1.4593487	0.37678337	3394.752
499.03662	1.4637421	0.37789091	3389.5103
500.0376	1.4635688	0.37890989	3390.4358
501.03857	1.4658961	0.37980804	3389.8408
502.03955	1.4723206	0.38072768	3393.5386
503.04053	1.4747243	0.38167116	3392.0352
504.0415	1.4767814	0.38250369	3393.7397
505.04248	1.480486	0.38354558	3396.688
506.04346	1.4834347	0.38463241	3400.3574
507.04443	1.4853523	0.38567835	3399.0315
508.04541	1.4881496	0.38678035	3395.24
509.04639	1.4904718	0.38781843	3398.363
510.04736	1.4938554	0.38880765	3396.8013
511.04834	1.4994184	0.38985392	3403.3318
512.04932	1.4988018	0.39100263	3403.6753
513.05029	1.5042963	0.3920705	3402.9797
514.05127	1.5089647	0.39320064	3407.2285
515.05225	1.5088494	0.39438385	3412.3674
516.05322	1.5142429	0.3954705	3406.7451
517.0542	1.5146654	0.39654297	3408.8599
518.05518	1.5171392	0.39763913	3413.4429
519.05615	1.523597	0.39877516	3412.2974
520.05713	1.522833	0.39970678	3409.5769
521.05811	1.5256008	0.40073693	3416.2275
522.05908	1.5282812	0.40204865	3417.0381
523.06006	1.5321823	0.40309301	3411.2705
524.06104	1.537214	0.40403295	3407.698
525.06201	1.5402031	0.40497091	3412.8003
526.06299	1.5410818	0.40598401	3418.8564
527.06396	1.5457238	0.40697688	3416.5728
528.06494	1.5471711	0.40808693	3417.6536
529.06592	1.5498186	0.40919349	3422.0725
530.06689	1.5543096	0.41031885	3425.176
531.06787	1.55573	0.41126421	3416.8447
532.06885	1.5579255	0.41214061	3415.7617
533.06982	1.5616006	0.41297239	3421.6343
534.0708	1.5671967	0.41410351	3432.7356
535.07178	1.570893	0.41517317	3424.4265
536.07275	1.5704342	0.41623545	3423.2402
537.07373	1.5734575	0.41738203	3430.0056
538.07471	1.5812492	0.41851994	3433.1213
539.07568	1.5827109	0.41958553	3428.6433
540.07666	1.5836878	0.42064586	3430.7542
541.07764	1.5893962	0.42164302	3433.3955
542.07861	1.5884448	0.42252025	3430.9954
543.07959	1.5951382	0.42383945	3436.1089
544.08057	1.5946786	0.4248282	3429.4739
545.08154	1.6000445	0.42588305	3436.1155
546.08252	1.6012686	0.42696863	3441.54
547.0835	1.6048536	0.42820722	3436.7322
548.08447	1.6084607	0.42942843	3445.6643
549.08545	1.613865	0.43062371	3441.3206
550.08643	1.6125591	0.43156701	3438.9326
551.0874	1.6181363	0.43258214	3439.1746
552.08838	1.621071	0.43371019	3449.8823
553.08936	1.6234288	0.43476257	3443.3145
554.09033	1.6284924	0.4358522	3440.9041
555.09131	1.6317749	0.43692058	3445.4641
556.09229	1.6324685	0.43816042	3438.4819
557.09326	1.6365184	0.43919811	3447.1924
558.09424	1.6384168	0.44013929	3447.0254
559.09521	1.6419781	0.44136313	3452.8472
560.09619	1.6441973	0.44251609	3448.7273
561.09717	1.6481721	0.44338167	3440.8474
562.09814	1.64886	0.44445708	3449.9531
563.09912	1.6529843	0.44558072	3451.9375
564.1001	1.6574343	0.44666421	3452.6753
565.10107	1.6599973	0.44781116	3454.605
566.10205	1.6635422	0.44868177	3452.5291
567.10303	1.6666133	0.44967464	3457.0542
568.104	1.6671132	0.45078519	3459.2168
569.10498	1.6723402	0.45172656	3457.0449
570.10596	1.674284	0.45260459	3454.0835
571.10693	1.6777335	0.45364675	3462.5298
572.10791	1.6814518	0.45467052	3458.0728
573.10889	1.6847415	0.45586827	3466.8533
574.10986	1.6866062	0.45726845	3466.8345
575.11084	1.6908798	0.45861012	3468.1399
576.11182	1.6908154	0.45965174	3463.8623
577.11279	1.6931635	0.46048754	3459.0977
578.11377	1.6994739	0.46151331	3466.7412
579.11475	1.700402	0.46241435	3464.8489
580.11572	1.7045473	0.4635002	3465.9656
581.1167	1.708975	0.4645083	3457.0508
582.11768	1.7097824	0.46561506	3468.0159
583.11865	1.7133044	0.46679035	3474.3472
584.11963	1.7158297	0.4678157	3470.4255
585.12061	1.719225	0.46922305	3474.9451
586.12158	1.724643	0.47041649	3473.1665
587.12256	1.7276462	0.47163382	3473.3501
588.12354	1.7309169	0.47288072	3472.0977
589.12451	1.7312315	0.47405502	3471.644
590.12549	1.7344089	0.47519678	3471.4595
591.12646	1.7374113	0.47630727	3471.9248
592.12744	1.7414246	0.4774262	3474.9778
593.12842	1.7425998	0.47843191	3474.7771
594.12939	1.748333	0.47973505	3484.1682
595.13037	1.7511206	0.48092687	3479.2029
596.13135	1.7513806	0.48192674	3470.7412
597.13232	1.7571014	0.48289376	3477.1614
598.1333	1.7606537	0.48393539	3481.7136
599.13428	1.764119	0.48505631	3482.8037
600.13525	1.7653762	0.486132	3483.2573
601.13623	1.764172	0.48719111	3484.5176
602.13721	1.7714239	0.48836517	3483.2058
603.13818	1.7728581	0.48933664	3484.0342
604.13916	1.7754112	0.49041614	3484.6284
605.14014	1.7775161	0.49156114	3486.5779
606.14111	1.7817349	0.49276939	3494.1606
607.14209	1.7846457	0.49406594	3490.4338
608.14307	1.7893076	0.49526125	3492.0828
609.14404	1.7900811	0.496407	3486.2773
610.14502	1.7970961	0.49754891	3487.3042
611.146	1.7974308	0.49872971	3493.2976
612.14697	1.7994722	0.49988085	3494.98
613.14795	1.802189	0.50094408	3490.6433
614.14893	1.8084797	0.50201982	3494.312
615.1499	1.8134173	0.50316584	3500.4526
616.15088	1.8140023	0.50414145	3496.3025
617.15186	1.8169482	0.50526351	3498.4758
618.15283	1.8190886	0.50652498	3501.0908
619.15381	1.8201145	0.50750923	3500.2737
620.15479	1.8254244	0.50900859	3502.165
621.15576	1.8277624	0.51028091	3500.6104
622.15674	1.8366208	0.51157504	3499.825
623.15771	1.8339783	0.51249653	3494.6331
624.15869	1.8381146	0.51355624	3501.4963
625.15967	1.8380054	0.51466203	3500.3955
626.16064	1.8408909	0.51581967	3498.3965
627.16162	1.8463857	0.51677853	3501.0149
628.1626	1.8499864	0.51781505	3497.374
629.16357	1.8505349	0.51913589	3508.9084
630.16455	1.8556767	0.52026045	3506.9063
631.16553	1.8612995	0.52149069	3508.2219
632.1665	1.8630589	0.52271986	3513.3557
633.16748	1.8673469	0.52401733	3514.8669
634.16846	1.8693409	0.52519208	3505.405
635.16943	1.8693911	0.52621299	3508.1416
636.17041	1.8745543	0.52739567	3510.3186
637.17139	1.8766593	0.52850181	3512.7009
638.17236	1.8784449	0.52971125	3507.564
639.17334	1.8813293	0.53073746	3508.2119
640.17432	1.8850962	0.53169346	3505.3079
641.17529	1.8898233	0.53264236	3505.1543
642.17627	1.8905003	0.53386241	3522.9368
643.17725	1.8959246	0.53516972	3522.4751
644.17822	1.8951577	0.53651774	3512.4744
645.1792	1.9015816	0.53762609	3513.2148
646.18018	1.9035853	0.5387367	3515.4731
647.18115	1.9063208	0.53976291	3515.8472
648.18213	1.9074085	0.54110092	3519.2371
649.18311	1.9141697	0.54228175	3521.1296
650.18408	1.9146925	0.5434733	3511.4043
651.18506	1.9168756	0.54469794	3520.7002
652.18604	1.9237603	0.54597455	3528.1719
653.18701	1.9223791	0.54701263	3517.6138
654.18799	1.9264787	0.54828429	3525.2371
655.18896	1.9302565	0.5495013	3527.658
656.18994	1.9354185	0.5505591	3519.7227
657.19092	1.9340234	0.55175555	3520.2729
658.19189	1.9398648	0.55319375	3529.1538
659.19287	1.9409683	0.55465341	3529.3313
660.19385	1.9458401	0.55596882	3525.9395
661.19482	1.9491509	0.55710983	3520.5054
662.1958	1.9521759	0.558011	3519.2002
663.19678	1.9558612	0.55925339	3529.6689
664.19775	1.9591446	0.56043559	3528.4255
665.19873	1.9605267	0.5616017	3526.9822
666.19971	1.9629614	0.56283218	3529.396
667.20068	1.9663882	0.56413931	3528.3765
668.20166	1.9672778	0.56532896	3527.0059
669.20264	1.9723189	0.56641597	3525.416
670.20361	1.9776253	0.56770748	3530.646
671.20459	1.9801776	0.56889367	3535.0657
672.20557	1.9814378	0.57019895	3533.6501
673.20654	1.9807664	0.57154655	3535.7642
674.20752	1.9900109	0.57272828	3530.7686
675.2085	1.992637	0.57378894	3528.927
676.20947	1.9924369	0.57494938	3535.7576
677.21045	1.9955055	0.57596618	3530.9624
678.21143	2.001868	0.5772469	3536.6526
679.2124	2.0025923	0.57859641	3537.2844
680.21338	2.0016284	0.57985818	3537.4495
681.21436	2.0078223	0.581222	3537.7634
682.21533	2.0105155	0.5824188	3537.0688
683.21631	2.0162363	0.58345258	3534.6936
684.21729	2.0184503	0.58445024	3534.2256
685.21826	2.0213752	0.58561522	3541.3435
686.21924	2.0235679	0.58706474	3543.4148
687.22021	2.0255175	0.58865982	3543.7549
688.22119	2.0314283	0.59013009	3539.4824
689.22217	2.0360675	0.59127486	3540.2161
690.22314	2.0392201	0.59262705	3544.1011
691.22412	2.0383244	0.5937506	3537.6116
692.2251	2.0399084	0.59500575	3541.8508
693.22607	2.0433404	0.59626794	3545.9746
694.22705	2.0463839	0.59762031	3546.2617
695.22803	2.0515788	0.59923035	3547.8396
696.229	2.0535231	0.60031724	3544.9316
697.22998	2.0564723	0.60145086	3535.5891
698.23096	2.0585725	0.60277867	3547.9893
699.23193	2.0603476	0.60387135	3544.8982
700.23291	2.0664961	0.60502815	3546.2153
701.23389	2.0667865	0.60631001	3546.5029
702.23486	2.0709414	0.60756934	3548.4639
703.23584	2.0746515	0.60890549	3552.4585
704.23682	2.0784152	0.61019528	3550.4524
705.23779	2.080507	0.61162084	3548.1667
706.23877	2.0831027	0.61281496	3548.9773
707.23975	2.0878663	0.61408252	3548.4868
708.24072	2.0898595	0.61523485	3550.2966
709.2417	2.0906289	0.61635375	3543.3562
710.24268	2.0962627	0.61748123	3543.7583
711.24365	2.0969882	0.61863083	3550.1362
712.24463	2.1014099	0.61975783	3547.8887
713.24561	2.1059175	0.62098414	3557.2539
714.24658	2.1081376	0.62244111	3560.0107
715.24756	2.1091354	0.6239987	3554.3416
716.24854	2.1123867	0.62551486	3551.0632
717.24951	2.1172485	0.62683463	3550.7549
718.25049	2.118345	0.62792939	3548.3274
719.25146	2.1225901	0.62928528	3558.0459
720.25244	2.1246865	0.63053834	3551.5254
721.25342	2.1266987	0.6317991	3556.0591
722.25439	2.1334145	0.63332987	3558.9038
723.25537	2.1347475	0.63462085	3557.7847
724.25635	2.1364899	0.63607419	3558.3145
725.25732	2.1399715	0.63736516	3557.2522
726.2583	2.1427093	0.63866234	3556.3101
727.25928	2.1456318	0.64010906	3563.7407
728.26025	2.152787	0.64181674	3559.0681
729.26123	2.1504962	0.64290488	3550.5955
730.26221	2.1560876	0.64429337	3555.3452
731.26318	2.159188	0.64545846	3559.6885
732.26416	2.160805	0.64675212	3559.9995
733.26514	2.1641977	0.64835042	3563.2649
734.26611	2.1676373	0.64965159	3560.6362
735.26709	2.1731062	0.65113598	3565.916
736.26807	2.1720312	0.65260655	3558.8508
737.26904	2.1753724	0.65406096	3557.5415
738.27002	2.1811612	0.65539044	3562.3047
739.271	2.183537	0.65652776	3559.0054
740.27197	2.1854141	0.65788376	3560.7874
741.27295	2.1894374	0.65911627	3556.8899
742.27393	2.1896558	0.66040772	3564.3369
743.2749	2.1952801	0.66216844	3568.6277
744.27588	2.1957078	0.66356075	3567.0403
745.27686	2.2000453	0.66496795	3562.1602
746.27783	2.2041211	0.6661278	3560.8901
747.27881	2.2079132	0.66726875	3565.4771
748.27979	2.2083514	0.6687218	3562.1665
749.28076	2.2131314	0.6701479	3565.7563
750.28174	2.216588	0.67142951	3561.615
751.28271	2.2189033	0.67268944	3566.1448
752.28369	2.2206843	0.67412269	3569.886
753.28467	2.2250466	0.6755178	3567.9534
754.28564	2.2281184	0.67708778	3570.2356
755.28662	2.2331076	0.67855597	3567.553
756.2876	2.2338099	0.67997479	3570.614
757.28857	2.2357531	0.68130738	3563.4604
758.28955	2.239105	0.6826809	3569.5625
759.29053	2.2430117	0.68418008	3568.3691
760.2915	2.2476375	0.68560141	3570.0442
761.29248	2.2492208	0.68691897	3567.3535
762.29346	2.2514737	0.68864757	3572.5967
763.29443	2.2559154	0.69045317	3578.1848
764.29541	2.2572575	0.6920864	3566.4119
765.29639	2.2589476	0.69354361	3559.5359
766.29736	2.2634804	0.69508404	3573.249
767.29834	2.2659936	0.6963141	3563.3555
768.29932	2.2708783	0.69756925	3570.5
769.30029	2.2744105	0.69897079	3575.6045
770.30127	2.2772465	0.70035827	3570.769
771.30225	2.2801149	0.70167065	3574.2202
772.30322	2.2848032	0.70295078	3569.9329
773.3042	2.2844892	0.7043308	3572.1831
774.30518	2.2886384	0.70585287	3570.9785
775.30615	2.2905931	0.70748121	3575.2959
776.30713	2.296617	0.70900238	3575.8481
777.30811	2.2983444	0.71043676	3578.064
778.30908	2.3007209	0.71218848	3573.3459
779.31006	2.3025446	0.71393573	3572.8923
780.31104	2.3040197	0.71537977	3568.261
781.31201	2.3083577	0.71665144	3574.2087
782.31299	2.3156016	0.71817577	3575.8591
783.31396	2.3127091	0.71976274	3575.5967
784.31494	2.3166211	0.72107351	3567.3367
785.31592	2.3195403	0.72248864	3569.1531
786.31689	2.324327	0.72385657	3578.4846
787.31787	2.3266034	0.72513509	3571.1213
788.31885	2.3280733	0.7266686	3576.1641
789.31982	2.3317306	0.72832978	3578.3367
790.3208	2.334722	0.73010719	3577.1785
791.32178	2.33792	0.731516	3577.9521
792.32275	2.3425765	0.73289424	3575.2698
793.32373	2.3428895	0.73450536	3573.6372
794.32471	2.3457716	0.73620832	3577.4595
795.32568	2.3533399	0.73756778	3572.3513
796.32666	2.3514435	0.73906285	3573.3367
797.32764	2.3556385	0.74061871	3574.48
798.32861	2.3608532	0.742163	3575.8
799.32959	2.3652945	0.74389392	3581.8965
800.33057	2.3655107	0.74563342	3577.166
801.33154	2.3695519	0.74734634	3574.761
802.33252	2.3730996	0.74893224	3577.9163
803.3335	2.3731844	0.75031018	3576.6274
804.33447	2.378423	0.75171363	3575.6467
805.33545	2.3801775	0.7536568	3581.8516
806.33643	2.3857427	0.75550956	3579.7781
807.3374	2.3862853	0.75722826	3577.7939
808.33838	2.3880515	0.75861621	3571.916
809.33936	2.391989	0.76010197	3574.0625
810.34033	2.3946757	0.76163667	3577.7644
811.34131	2.3995225	0.76314044	3579.1904
812.34229	2.4001672	0.76478404	3577.0229
813.34326	2.4046109	0.76664394	3583.4622
814.34424	2.4068687	0.76846904	3580.2656
815.34521	2.4114664	0.77058953	3579.3701
816.34619	2.4167461	0.77242678	3574.3271
817.34717	2.4172828	0.77394015	3577.6838
818.34814	2.4218419	0.77539086	3578.0393
819.34912	2.4198971	0.7769053	3570.4192
820.3501	2.4251401	0.77852219	3581.2346
821.35107	2.4301612	0.78042662	3581.29
822.35205	2.4320757	0.78203636	3576.0413
823.35303	2.4352105	0.78358781	3578.5566
824.354	2.4362476	0.78516477	3578.2266
825.35498	2.4438677	0.78695935	3581.0806
826.35596	2.444787	0.78879261	3578.6919
827.35693	2.4469824	0.79045099	3582.2676
828.35791	2.4482179	0.79207373	3573.0869
829.35889	2.4521806	0.79371297	3579.668
830.35986	2.4566786	0.79540533	3573.8911
831.36084	2.4574337	0.79698896	3576.5754
832.36182	2.4612381	0.79858524	3577.687
833.36279	2.464855	0.80046326	3579.5825
834.36377	2.4688466	0.80232948	3583.0896
835.36475	2.4673476	0.80408907	3575.0225
836.36572	2.4702001	0.80580747	3578.2458
837.3667	2.478008	0.80784291	3577.2009
838.36768	2.4786096	0.809825	3579.0571
839.36865	2.4814248	0.81172734	3578.5393
840.36963	2.4850993	0.81353223	3576.6589
841.37061	2.489826	0.81543922	3576.6824
842.37158	2.4913037	0.81715393	3577.2571
843.37256	2.4940121	0.81889421	3574.4507
844.37354	2.4964283	0.82058007	3575.7341
845.37451	2.5009191	0.82240248	3577.3157
846.37549	2.500818	0.82430136	3576.2466
847.37646	2.5058115	0.82643545	3582.5364
848.37744	2.5100312	0.828592	3578.7271
849.37842	2.5139105	0.83086812	3582.9019
850.37939	2.5175848	0.83258617	3574.6155
851.38037	2.5203981	0.83444256	3577.0876
852.38135	2.5213554	0.83621728	3575.865
853.38232	2.524904	0.83778495	3578.6289
854.3833	2.5285888	0.83949924	3575.4653
855.38428	2.5291669	0.84138101	3581.3191
856.38525	2.5369921	0.84329301	3573.5364
857.38623	2.5363648	0.84508842	3573.9622
858.38721	2.5386083	0.8468973	3575.2493
859.38818	2.5434144	0.84854335	3571.7097
860.38916	2.5461442	0.85033613	3577.3132
861.39014	2.551121	0.85234457	3582.3936
862.39111	2.5495903	0.85456616	3576.4363
863.39209	2.5536845	0.8565743	3574.8752
864.39307	2.5583851	0.85891503	3576.6704
865.39404	2.5594683	0.86092776	3575.3396
866.39502	2.5632393	0.86295974	3571.9829
867.396	2.564198	0.86498207	3571.5295
868.39697	2.5696487	0.86685818	3572.6062
869.39795	2.5719802	0.86888772	3574.4387
870.39893	2.5767188	0.87101918	3575.469
871.3999	2.5796392	0.87300593	3578.561
872.40088	2.5834944	0.87522888	3576.5659
873.40186	2.5823963	0.87729633	3571.5259
874.40283	2.5853837	0.87931955	3570.0771
875.40381	2.5929959	0.88151562	3577.916
876.40479	2.5928197	0.8838374	3573.7219
877.40576	2.5975049	0.885961	3571.0532
878.40674	2.597209	0.88784367	3565.7705
879.40771	2.6021292	0.88985723	3572.1973
880.40869	2.6051896	0.89215666	3576.1445
881.40967	2.6081541	0.89444172	3568.6267
882.41064	2.6136558	0.89682359	3574.5452
883.41162	2.6150568	0.89882791	3573.5195
884.4126	2.6183178	0.90102249	3568.687
885.41357	2.6204636	0.90323848	3571.3328
886.41455	2.626966	0.90533501	3570.1541
887.41553	2.6292558	0.90736341	3568.144
888.4165	2.6305954	0.90958357	3565.9902
889.41748	2.6335306	0.91160995	3568.217
890.41846	2.6363797	0.91398573	3567.5093
891.41943	2.6377671	0.91638696	3569.625
892.42041	2.6435232	0.91897589	3570.3379
893.42139	2.6450603	0.92116404	3565.0046
894.42236	2.6507559	0.92350256	3571.843
895.42334	2.650588	0.92576903	3566.9956
896.42432	2.6541879	0.92841882	3566.0315
897.42529	2.6546876	0.93060869	3565.3269
898.42627	2.6578057	0.93311781	3562.4531
899.42725	2.6657245	0.93569767	3565.6592
900.42822	2.6676524	0.93799371	3565.8928
901.4292	2.6673608	0.94058794	3562.5776
902.43018	2.6704266	0.94324732	3560.9253
903.43115	2.675035	0.94566095	3560.2646
904.43213	2.6781447	0.94812965	3561.4226
905.43311	2.6800339	0.95071512	3558.5935
906.43408	2.684242	0.95294631	3558.2129
907.43506	2.6874363	0.95506501	3558.1169
908.43604	2.6926041	0.95762479	3568.0288
909.43701	2.690434	0.96072084	3553.9814
910.43799	2.6987519	0.96314681	3552.3149
911.43896	2.6987467	0.96528733	3557.8713
912.43994	2.7032762	0.96754462	3554.0537
913.44092	2.7050405	0.97003794	3559.5449
914.44189	2.7081175	0.97274357	3558.5588
915.44287	2.7111068	0.97548401	3557.3718
916.44385	2.7150259	0.9781751	3559.2859
917.44482	2.718935	0.98074967	3556.7859
918.4458	2.7191246	0.98297	3551.0198
919.44678	2.7241783	0.9853999	3547.5464
920.44775	2.7259007	0.98807365	3552.3542
921.44873	2.7299609	0.99085587	3548.2283
922.44971	2.7322409	0.99392402	3553.522
923.45068	2.7335238	0.996562	3547.5742
924.45166	2.7360559	0.99945289	3551.7405
925.45264	2.7436397	1.0026221	3553.7576
926.45361	2.7413857	1.0053645	3547.114
927.45459	2.7475677	1.0077741	3542.8591
928.45557	2.7492476	1.0103985	3549.1777
929.45654	2.751637	1.0129893	3545.105
930.45752	2.7557364	1.0155944	3545.0571
931.4585	2.7608433	1.018495	3540.7822
932.45947	2.7634368	1.0210632	3534.1826
933.46045	2.7639043	1.0237157	3542.7195
934.46143	2.7673342	1.0266305	3540.1201
935.4624	2.76964	1.0297129	3537.9666
936.46338	2.7749009	1.0327824	3533.6213
937.46436	2.7782536	1.0355448	3532.2114
938.46533	2.7781107	1.0380439	3532.9395
939.46631	2.7823851	1.0401868	3527.0337
940.46729	2.7848043	1.0428303	3530.968
941.46826	2.7886765	1.0456667	3528.2324
942.46924	2.7940969	1.0486355	3532.7471
943.47021	2.7956612	1.0520898	3534.2207
944.47119	2.7976253	1.0551455	3532.073
945.47217	2.8005893	1.05778	3522.5662
946.47314	2.8048387	1.0606656	3527.3018
947.47412	2.8067284	1.06382	3527.3865
948.4751	2.8102453	1.0668131	3521.1382
949.47607	2.8117979	1.069651	3520.7336
950.47705	2.8182416	1.0723273	3516.9565
951.47803	2.8205347	1.0754626	3527.3184
952.479	2.8244131	1.0788195	3521.5254
953.47998	2.8249214	1.0818	3513.6624
954.48096	2.8299797	1.0851547	3516.407
955.48193	2.8293672	1.0881792	3514.6665
956.48291	2.8355808	1.091197	3512.1296
957.48389	2.8394353	1.0939946	3507.5667
958.48486	2.8391023	1.096601	3505.7478
959.48584	2.8437927	1.0990362	3505.6875
960.48682	2.8449724	1.1019976	3506.1648
961.48779	2.8487139	1.1049004	3505.5146
962.48877	2.8516021	1.1077514	3501.9692
963.48975	2.8540266	1.1106075	3501.8936
964.49072	2.8594046	1.1133633	3496.0393
965.4917	2.8615141	1.1164219	3496.561
966.49268	2.8657293	1.1196398	3502.0388
967.49365	2.8650632	1.1224338	3489.1201
968.49463	2.8713558	1.1255559	3498.365
969.49561	2.8747633	1.1295166	3495.136
970.49658	2.8738098	1.1332892	3483.2378
971.49756	2.87868	1.1359371	3482.6956
972.49854	2.8830292	1.1387087	3484.9944
973.49951	2.8863456	1.1417271	3480.1951
974.50049	2.8880424	1.1447611	3482.7224
975.50146	2.8907163	1.1475855	3480.2024
976.50244	2.8960366	1.150509	3480.8789
977.50342	2.8985569	1.1534845	3475.168
978.50439	2.9007378	1.1565727	3476.6228
979.50537	2.90504	1.1599516	3476.385
980.50635	2.9059033	1.1633954	3466.2817
981.50732	2.9091368	1.1664979	3462.7388
982.5083	2.9120967	1.1700475	3467.7532
983.50928	2.9153848	1.1734358	3460.667
984.51025	2.9182065	1.1766752	3453.781
985.51123	2.9199929	1.1797681	3458.4988
986.51221	2.9212289	1.1828576	3454.9946
987.51318	2.9263079	1.1859815	3454.8765
988.51416	2.9310522	1.1895807	3453.3162
989.51514	2.9318819	1.1932865	3445.2161
990.51611	2.9362528	1.1962848	3444.54
991.51709	2.940361	1.1991496	3445.7678
992.51807	2.9406013	1.2022177	3436.918
993.51904	2.9458578	1.205317	3440.2568
994.52002	2.9470868	1.2083874	3435.7449
995.521	2.9519899	1.2117146	3433.4438
996.52197	2.9535432	1.2148998	3432.0115
997.52295	2.9566851	1.2176774	3422.6357
998.52393	2.9609282	1.2207764	3428.2036
999.5249	2.9642038	1.2238147	3421.0229
1000.5259	2.9669347	1.2267146	3420.5408
1001.5269	2.9696071	1.2293389	3419.6858
1002.5278	2.9717274	1.2328393	3424.1863
1003.5288	2.9763341	1.2361206	3413.4666
1004.5298	2.9779353	1.2397177	3412.5166
1005.5308	2.9802537	1.2433271	3407.0105
1006.5317	2.9831369	1.2465571	3396.989
1007.5327	2.9896019	1.2494262	3400.1738
1008.5337	2.9876108	1.2513912	3391.7954
1009.5347	2.9927509	1.253508	3395.5737
1010.5356	2.9981868	1.2556528	3391.5547
1011.5366	2.996505	1.2585666	3400.6162
1012.5376	3.0036025	1.2619469	3395.8306
1013.5386	3.0060792	1.2650837	3389.1643
1014.5396	3.0097282	1.2682532	3386.9856
1015.5405	3.0098526	1.2724366	3387.9561
1016.5415	3.0162439	1.2767302	3377.3127
1017.5425	3.0172975	1.2797177	3373.8525
1018.5435	3.020561	1.2828734	3372.1416
1019.5444	3.02476	1.2858193	3369.7688
1020.5454	3.0247364	1.288991	3367.5347
1021.5464	3.0303376	1.2923254	3364.5073
1022.5474	3.0353842	1.295683	3365.1179
1023.5483	3.0388188	1.2987181	3359.8865
1024.5493	3.0393829	1.3022683	3355.7351
1025.5503	3.0453732	1.3056885	3349.3879
1026.5513	3.0456119	1.3084873	3347.7344
1027.5522	3.0509267	1.311623	3347.1045
1028.5532	3.0533037	1.3150228	3347.3755
1029.5542	3.0556662	1.3185539	3334.8735
1030.5552	3.0569484	1.3221188	3328.7561
1031.5562	3.0608759	1.324959	3322.7993
1032.5571	3.0623224	1.3277674	3326.1367
1033.5581	3.0682321	1.3311789	3321.8701
1034.5591	3.068526	1.3344982	3315.3442
1035.5601	3.069176	1.3380274	3309.73
1036.561	3.0759244	1.3411838	3309.2043
1037.562	3.0758786	1.3436021	3304.0452
1038.563	3.0794842	1.3466384	3307.1179
1039.564	3.084276	1.3502802	3305.6194
1040.5649	3.0877459	1.3537436	3300.6997
1041.5659	3.0921168	1.3570393	3292.6282
1042.5669	3.0942204	1.3609594	3292.2583
1043.5679	3.0945983	1.3645848	3285.4036
1044.5688	3.0980079	1.3682323	3277.6594
1045.5698	3.1012659	1.3710417	3275.1191
1046.5708	3.1019552	1.3741822	3272.5562
1047.5718	3.108923	1.3778238	3269.7014
1048.5728	3.1135161	1.3811893	3265.1265
1049.5737	3.1131573	1.3845685	3264.2239
1050.5747	3.1194143	1.3884646	3263.6213
1051.5757	3.1219926	1.3923337	3252.3042
1052.5767	3.1238158	1.3959643	3244.7966
1053.5776	3.1243014	1.3987445	3233.6992
1054.5786	3.1294117	1.4019768	3243.4309
1055.5796	3.1307738	1.4056282	3232.5757
1056.5806	3.1351938	1.4090565	3222.1667
1057.5815	3.1397066	1.412763	3226.1809
1058.5825	3.1419585	1.4164203	3223.5583
1059.5835	3.1436806	1.4197973	3213.2332
1060.5845	3.1445317	1.4229764	3210.9741
1061.5854	3.1494234	1.4265699	3204.5359
1062.5864	3.152705	1.4300494	3196.5667
1063.5874	3.1551781	1.4334764	3198.8472
1064.5884	3.1567833	1.43708	3188.0244
1065.5894	3.1604652	1.4405371	3183.2322
1066.5903	3.1640551	1.4434595	3177.2808
1067.5913	3.1671429	1.4464614	3165.6016
1068.5923	3.1696901	1.4489243	3168.7373
1069.5933	3.1741734	1.4518361	3167.7798
1070.5942	3.1771245	1.4557804	3168.5647
1071.5952	3.1806989	1.4598442	3152.9275
1072.5962	3.182806	1.4632717	3147.2476
1073.5972	3.1877747	1.4665926	3139.0647
1074.5981	3.1886694	1.4696392	3141.384
1075.5991	3.1908662	1.4727925	3135.5828
1076.6001	3.1956093	1.4761335	3126.9324
1077.6011	3.1978517	1.4802152	3123.0786
1078.6021	3.2006738	1.4840639	3113.3809
1079.603	3.206377	1.4874798	3114.6208
1080.604	3.2061765	1.4909298	3108.3276
1081.605	3.2109764	1.4948268	3098.9922
1082.606	3.2139425	1.4982334	3093.9919
1083.6069	3.2181885	1.5019041	3089.1277
1084.6079	3.218312	1.5057945	3082.311
1085.6089	3.2225866	1.5099063	3075.0664
1086.6099	3.2236691	1.5135366	3065.1472
1087.6108	3.2281361	1.5166645	3058.8225
1088.6118	3.2320576	1.5196159	3059.5081
1089.6128	3.2339909	1.5226684	3048.7449
1090.6138	3.2378047	1.5259857	3045.7944
1091.6147	3.2407968	1.5298866	3038.0269
1092.6157	3.2457004	1.5332037	3032.4946
1093.6167	3.2483742	1.5369409	3031.9951
1094.6177	3.2511518	1.5403571	3018.2161
1095.6187	3.251478	1.5437348	3010.7786
1096.6196	3.2578096	1.5471168	3007.333
1097.6206	3.2556636	1.5503999	3000.3066
1098.6216	3.2600846	1.5544786	2990.0686
1099.6226	3.2624254	1.5579418	2982.9063
1100.6235	3.2665691	1.5614631	2980.8052
1101.6245	3.2712002	1.5648983	2974.7939
1102.6255	3.2731731	1.5686314	2959.8767
1103.6265	3.2766094	1.5717727	2957.5034
1104.6274	3.2774305	1.575101	2954.8716
1105.6284	3.2819614	1.5788289	2943.6643
1106.6294	3.2852502	1.582661	2935.2043
1107.6304	3.2875726	1.5870608	2927.7419
1108.6313	3.2930317	1.5909547	2919.9812
1109.6323	3.2951016	1.5943235	2911.1997
1110.6333	3.3000183	1.5979954	2901.2004
1111.6343	3.3012598	1.6015139	2895.9731
1112.6353	3.3025029	1.6054235	2883.104
1113.6362	3.3054092	1.608788	2880.8574
1114.6372	3.3106129	1.6129963	2871.4084
1115.6382	3.314285	1.6166296	2859.8425
1116.6392	3.3169842	1.6198553	2851.7483
1117.6401	3.3163328	1.6229886	2846.9187
1118.6411	3.3237534	1.6271338	2839.2183
1119.6421	3.3250422	1.6310264	2829.645
1120.6431	3.326319	1.6346606	2819.4651
1121.644	3.3311291	1.638768	2809.6973
1122.645	3.3330088	1.6431292	2799.8584
1123.646	3.3384554	1.6478218	2788.188
1124.647	3.3397677	1.6516256	2777.0449
1125.6479	3.3445659	1.6554831	2773.2454
1126.6489	3.3455775	1.6600289	2752.5142
1127.6499	3.3469396	1.6648607	2738.2312
1128.6509	3.3539174	1.6697292	2711.6011
1129.6519	3.3537948	1.6742415	2695.7886
1130.6528	3.3584931	1.6792115	2679.7241
1131.6538	3.360491	1.6828882	2664.2598
1132.6548	3.3642073	1.6862503	2656.2903
1133.6558	3.3652942	1.6905874	2641.4814
1134.6567	3.3722448	1.6954393	2623.1243
1135.6577	3.3730013	1.700817	2592.2788
1136.6587	3.3783782	1.7071358	2554.4761
1137.6597	3.3810737	1.7134268	2518.2273
1138.6606	3.3856077	1.7189506	2490.6484
1139.1611	3.3910224	1.7335504	2268.5608