File: datasets/am_bench_2022/raw_data/90-XY.16-1/specimen.dat
MTS793|MPT|ENU|1|2|.|/|:|1|0|0|A

Operator Information						Time:	14.304932	Sec	11/3/2021 7:16:44 AM
Operator	Nick Derimow
Project	AM Bench 2022 mini-tensile challenge
Specimen ID	90-XY.16-1
Material	PBF-L Inconel 625
Specimen Width	2.54	mm
Specimen Thickness	1.5	mm
Notes
Operator Information End

Data Acquisition						Time:	955.51001	Sec	11/3/2021 7:32:25 AM
Time	Axial Displacement	Axial Extensometer	Axial Force
Sec	mm	mm	N
14.418945	0.00041368307	7.9226913e-05	57.306374
15.219727	0.0027850911	5.6402059e-05	65.983376
16.020508	0.0066962037	0.00016740276	85.734016
16.821289	0.004502641	0.00020956932	91.199303
17.62207	0.011791381	0.00030356817	102.07939
18.422852	0.011637713	0.00024184785	108.66271
19.223633	0.013834298	0.00030363785	116.48416
20.024414	0.018644676	0.0003604285	124.53561
20.825195	0.018174861	0.0004097693	137.37849
21.625977	0.0219719	0.00037422584	148.94492
22.426758	0.025338618	0.00041326476	157.55788
23.227539	0.028468685	0.00047391249	171.68959
24.02832	0.03116459	0.00050699007	178.10471
24.829102	0.032412786	0.00058760855	188.9073
25.629883	0.035141524	0.00067362894	207.26575
26.430664	0.036964592	0.00073856296	219.09926
27.231445	0.038712107	0.00079019449	232.94238
28.032227	0.043054514	0.00084447011	249.58911
28.833008	0.045558643	0.0008758133	264.30435
29.633789	0.04642779	0.0010283986	283.16141
30.43457	0.049913958	0.0010179246	295.59351
31.235352	0.050319437	0.0011712507	310.36685
32.036133	0.053839616	0.0011940909	328.67664
32.836914	0.056072313	0.001310469	347.35849
33.637695	0.061074879	0.0013666614	368.07669
34.438477	0.062669754	0.0013596541	375.94687
35.239258	0.063110471	0.0015337069	398.65524
36.040039	0.065888949	0.0015173033	418.92831
36.84082	0.071349397	0.0016251241	433.8121
37.641602	0.069740437	0.0016893974	444.07187
38.442383	0.072688974	0.0018747848	471.86258
39.243164	0.074313961	0.0019840768	488.37796
40.043945	0.077605277	0.0019210164	507.69238
40.844727	0.081480533	0.0021357718	533.4848
41.645508	0.08345563	0.0021278916	544.76825
42.446289	0.086623654	0.0022620687	566.98431
43.24707	0.08734405	0.0024193747	588.4693
44.047852	0.090032838	0.0023859048	612.83124
44.848633	0.093461588	0.0025520355	634.89069
45.649414	0.096622847	0.0026764402	653.35693
46.450195	0.097080521	0.0028165795	681.20251
47.250977	0.099463813	0.0029961478	700.69366
48.051758	0.10318976	0.0030464814	731.0835
48.852539	0.10570454	0.0031154712	746.289
49.65332	0.10628602	0.0032775092	769.34869
50.454102	0.10889915	0.0032713176	787.0849
51.254883	0.11112319	0.0033471261	802.73785
52.055664	0.11511201	0.0035169674	830.06012
52.856445	0.11514704	0.0035268432	846.94287
53.657227	0.11813102	0.0036355481	871.48706
54.458008	0.12148544	0.0038599058	896.50732
55.258789	0.122757	0.003890286	909.56586
56.05957	0.12727255	0.0040091462	934.93207
56.860352	0.12615199	0.0040971707	957.67798
57.661133	0.13176595	0.004197652	979.97888
58.461914	0.13538304	0.0042437729	1005.2354
59.262695	0.13720386	0.0044402401	1026.4821
60.063477	0.14000656	0.0045101405	1045.3284
60.864258	0.1401674	0.004668884	1070.0142
61.665039	0.14329609	0.0046507469	1081.322
62.46582	0.14723685	0.0047745942	1102.9651
63.266602	0.15003444	0.0049460931	1122.7047
64.067383	0.15352204	0.0050504031	1153.1307
64.868164	0.15443525	0.0051359031	1177.2338
65.668945	0.15420802	0.0053040185	1200.1892
66.469727	0.15832505	0.0052648676	1223.4113
67.270508	0.15869898	0.0054438133	1243.7676
68.071289	0.16300921	0.005567628	1263.9189
68.87207	0.1664208	0.0056772642	1285.5793
69.672852	0.16694225	0.0056831967	1299.8268
70.473633	0.1679204	0.0058973916	1326.4745
71.274414	0.17015514	0.0060067289	1355.976
72.075195	0.17669332	0.0061625913	1376.802
72.875977	0.17525314	0.0062064747	1397.2301
73.676758	0.18056305	0.0063582645	1419.1133
74.477539	0.18176308	0.0064959489	1446.5128
75.27832	0.18354031	0.0066514849	1465.0104
76.079102	0.18680008	0.0067279735	1493.6979
76.879883	0.19031718	0.0069439183	1522.5454
77.680664	0.18782304	0.0069366898	1533.9698
78.481445	0.19176653	0.0070612617	1560.4739
79.282227	0.19715577	0.0071816258	1578.4941
80.083008	0.19530869	0.0072561479	1604.2738
80.883789	0.20029896	0.0074801859	1630.0662
81.68457	0.20431779	0.0075171636	1649.8032
82.485352	0.20641792	0.0077233557	1674.7106
83.286133	0.2089344	0.0077842604	1705.6794
84.086914	0.21141332	0.007922912	1721.4312
84.887695	0.21029426	0.0080220383	1736.3785
85.688477	0.21733133	0.0080459071	1756.188
86.489258	0.21540004	0.0081517324	1777.2374
87.290039	0.21978855	0.0083142659	1803.1772
88.09082	0.22076711	0.0084455004	1820.3074
88.891602	0.22360054	0.0085578961	1840.2888
89.692383	0.22506505	0.0086268159	1861.6595
90.493164	0.22862785	0.0088219559	1886.8842
91.293945	0.23142312	0.0088503854	1907.7968
92.094727	0.2331481	0.0090227257	1930.1898
92.895508	0.23682487	0.0091386316	1944.389
93.696289	0.24010533	0.0092085311	1966.675
94.49707	0.24290614	0.0093628252	1986.2012
95.297852	0.24515948	0.0093809608	2003.451
96.098633	0.24459028	0.0095498711	2032.0197
96.899414	0.24621384	0.0096637942	2040.462
97.700195	0.24964188	0.0097070336	2061.5486
98.500977	0.2549167	0.0099117467	2079.2188
99.301758	0.25496504	0.0099528832	2096.0657
100.10254	0.25907284	0.010044953	2113.396
100.90332	0.26133811	0.010109025	2131.7803
101.7041	0.26276088	0.010264358	2146.4644
102.50488	0.26628804	0.010346724	2162.7251
103.30566	0.26485032	0.010451074	2183.8752
104.10645	0.27242154	0.010613059	2206.7146
104.90723	0.27333146	0.010614227	2209.2485
105.70801	0.27600223	0.010783621	2233.4187
106.50879	0.27728668	0.010938894	2250.6702
107.30957	0.2788645	0.01107026	2259.4026
108.11035	0.28159544	0.011018333	2267.9265
108.91113	0.28512055	0.011168525	2284.9946
109.71191	0.28684449	0.011273649	2299.8005
110.5127	0.29176673	0.011421192	2323.7561
111.31348	0.29183191	0.011498936	2330.5593
112.11426	0.29390663	0.011508042	2344.7952
112.91504	0.29682523	0.011679053	2348.5854
113.71582	0.29702297	0.011751568	2361.8215
114.5166	0.30131149	0.011808559	2379.0632
115.31738	0.30750632	0.012044559	2402.2014
116.11816	0.30614316	0.012121855	2408.9934
116.91895	0.30567214	0.012191898	2417.6785
117.71973	0.31211871	0.012334852	2435.3398
118.52051	0.31320935	0.012337709	2440.1067
119.32129	0.31391603	0.012478361	2452.3452
120.12207	0.31820458	0.012621066	2462.4385
120.92285	0.32337123	0.01272072	2481.8447
121.72363	0.32487839	0.012852886	2483.4829
122.52441	0.3271012	0.012875001	2495.7063
123.3252	0.3298234	0.013034642	2508.0063
124.12598	0.3293165	0.013098088	2514.4109
124.92676	0.33159098	0.01328461	2529.6824
125.72754	0.33674943	0.013392685	2540.2747
126.52832	0.33651504	0.013515843	2549.9653
127.3291	0.33995017	0.013603081	2551.5632
128.12988	0.34433568	0.013712902	2572.4668
128.93066	0.34656954	0.013794619	2577.7996
129.73145	0.34703383	0.013880324	2580.1941
130.53223	0.35114941	0.01403058	2589.3499
131.33301	0.35045648	0.014184982	2604.1875
132.13379	0.35443664	0.014281893	2612.0376
132.93457	0.35716087	0.014358792	2616.8257
133.73535	0.35898885	0.014568414	2627.051
134.53613	0.36204639	0.014643021	2634.3354
135.33691	0.36366257	0.014844398	2646.9758
136.1377	0.36570427	0.015015792	2654.0278
136.93848	0.37104148	0.015029901	2661.7932
137.73926	0.3706663	0.015211018	2667.1953
138.54004	0.37579113	0.015356246	2676.6621
139.34082	0.37860534	0.015504919	2685.2666
140.1416	0.37500504	0.0156572	2688.1528
140.94238	0.38143626	0.015906492	2703.0703
141.74316	0.38388121	0.015979497	2709.9011
142.54395	0.3874563	0.016158726	2716.1487
143.34473	0.38890627	0.016354347	2726.6479
144.14551	0.39163584	0.016615333	2732.4954
144.94629	0.39579403	0.016684938	2735.6716
145.74707	0.39465567	0.016933825	2746.0276
146.54785	0.39750057	0.017088003	2754.1558
147.34863	0.40080747	0.01734983	2762.8345
148.14941	0.40260574	0.01751386	2763.9888
148.9502	0.40514126	0.01775657	2770.2832
149.75098	0.40716657	0.017853003	2774.7114
150.55176	0.41186205	0.018244874	2790.667
151.35254	0.41258135	0.018526107	2792.2183
152.15332	0.41808918	0.018658468	2802.9065
152.9541	0.41731614	0.018966045	2807.7498
153.75488	0.41868317	0.019195823	2807.7236
154.55566	0.42181796	0.019459132	2815.2375
155.35645	0.42636588	0.01978907	2824.8625
156.15723	0.42844284	0.020130517	2836.0889
156.95801	0.42754215	0.020471759	2831.9771
157.75879	0.43332672	0.020757291	2839.1394
158.55957	0.43461633	0.0211556	2852.8284
159.36035	0.43492037	0.021419788	2854.3416
160.16113	0.44226158	0.021748867	2858.459
160.96191	0.44009218	0.022117572	2866.572
161.7627	0.44253448	0.022591397	2870.5422
162.56348	0.44569322	0.022964176	2876.0015
163.36426	0.44830883	0.02342717	2875.947
164.16504	0.45055628	0.023758724	2885.5625
164.96582	0.45106748	0.024368519	2896.6694
165.7666	0.45579651	0.024879962	2898.9141
166.56738	0.45893723	0.025423117	2904.4746
167.36816	0.4589442	0.025830112	2907.8413
168.16895	0.46136022	0.026286498	2901.1267
168.96973	0.46676746	0.026685465	2910.2983
169.77051	0.46809062	0.027099665	2913.8225
170.57129	0.46917349	0.027470099	2920.2949
171.37207	0.4712584	0.027898656	2923.3147
172.17285	0.47545534	0.028326413	2930.1453
172.97363	0.47852787	0.028909756	2935.7295
173.77441	0.48000613	0.029525906	2938.9937
174.5752	0.48282972	0.030100275	2946.2588
175.37598	0.48354289	0.030689845	2948.0728
176.17676	0.48695058	0.031297106	2952.7188
176.97754	0.48621795	0.031899024	2946.71
177.77832	0.49147868	0.032567471	2957.5608
178.5791	0.49192965	0.033388	2963.562
179.37988	0.49278301	0.034013726	2964.5044
180.18066	0.50040662	0.034713183	2965.8337
180.98145	0.50277621	0.035446621	2972.6003
181.78223	0.50821543	0.036142137	2976.2361
182.58301	0.50546807	0.036658667	2972.9453
183.38379	0.51019132	0.037417844	2990.0315
184.18457	0.5107525	0.03829604	2992.7607
184.98535	0.516312	0.038920339	2995.2847
185.78613	0.51682502	0.039710261	2999.5249
186.58691	0.5205366	0.040643957	3008.5366
187.3877	0.52055299	0.041171532	2996.9966
188.18848	0.52391106	0.042011626	3003.9939
188.98926	0.52476954	0.042657927	3004.0955
189.79004	0.52610672	0.043517541	3011.7373
190.59082	0.53349125	0.044317085	3012.9136
191.3916	0.53262568	0.044935502	3009.5205
192.19238	0.53807074	0.045873497	3024.0693
192.99316	0.53967994	0.04657834	3016.9407
193.79395	0.54060209	0.047353424	3028.9492
194.59473	0.54164851	0.048141483	3027.2588
195.39551	0.54276431	0.048929207	3029.0891
196.19629	0.54819	0.049826123	3032.3098
196.99707	0.55075228	0.050814234	3039.3457
197.79785	0.55358118	0.051624797	3042.3833
198.59863	0.55694652	0.052345373	3041.2144
199.39941	0.55760342	0.053155437	3052.8181
200.2002	0.56048125	0.054069124	3053.5525
201.00098	0.55967277	0.054885324	3046.2629
201.80176	0.56413704	0.055677887	3054.8408
202.60254	0.5654496	0.056461632	3058.1919
203.40332	0.57082689	0.057464506	3061.7319
204.2041	0.5700317	0.058390982	3057.9026
205.00488	0.57264531	0.059209175	3061.873
205.80566	0.57618022	0.059868883	3067.5256
206.60645	0.57729745	0.060827296	3074.1316
207.40723	0.57895648	0.061841305	3075.9177
208.20801	0.58180827	0.062716432	3075.1899
209.00879	0.5853371	0.063655704	3072.3389
209.80957	0.58750117	0.064412862	3070.5974
210.61035	0.59124547	0.065169953	3076.043
211.41113	0.59243035	0.065807983	3072.3022
212.21191	0.59502876	0.066794641	3088.752
213.0127	0.59562248	0.067709401	3088.7937
213.81348	0.60181201	0.068696506	3095.1021
214.61426	0.60052818	0.069560371	3088.2903
215.41504	0.60608846	0.070554174	3094.2571
216.21582	0.6051656	0.071306266	3097.1055
217.0166	0.60876137	0.072402216	3100.4473
217.81738	0.61274815	0.073383041	3102.6504
218.61816	0.61325425	0.07423906	3105.4634
219.41895	0.6162321	0.075268127	3102.2332
220.21973	0.61957872	0.076212034	3104.7251
221.02051	0.62230533	0.07689324	3104.5886
221.82129	0.62292188	0.077877007	3112.8174
222.62207	0.6245358	0.078723453	3114.0366
223.42285	0.63003564	0.07987465	3119.9338
224.22363	0.63269323	0.080738991	3115.0581
225.02441	0.63512278	0.081776753	3121.4009
225.8252	0.63430834	0.082643785	3116.9641
226.62598	0.63768882	0.08344344	3118.0552
227.42676	0.64270061	0.084215604	3121.228
228.22754	0.64159542	0.085091248	3120.8936
229.02832	0.64578271	0.085947886	3123.4543
229.8291	0.65143847	0.086795479	3131.0754
230.62988	0.65094084	0.087846383	3132.3162
231.43066	0.65261376	0.088815987	3135.5779
232.23145	0.65871632	0.08999671	3147.8481
233.03223	0.6569283	0.09090443	3133.8188
233.83301	0.65866554	0.091928512	3141.7864
234.63379	0.66248935	0.092900828	3135.8044
235.43457	0.66454667	0.093911834	3150.3679
236.23535	0.66691685	0.094782114	3145.323
237.03613	0.66894031	0.095780306	3151.2727
237.83691	0.67258316	0.096590385	3148.3125
238.6377	0.67692971	0.097630143	3155.6975
239.43848	0.67569482	0.098473057	3151.7292
240.23926	0.67813587	0.09931802	3148.8748
241.04004	0.68177205	0.10028439	3159.3362
241.84082	0.68403447	0.10112727	3158.1199
242.6416	0.6857444	0.10200895	3160.2458
243.44238	0.69111806	0.10299984	3167.4531
244.24316	0.69215727	0.10387232	3162.1365
245.04395	0.69037038	0.10460157	3162.5767
245.84473	0.69666809	0.10575482	3174.1538
246.64551	0.69925088	0.10691968	3174.9612
247.44629	0.70043635	0.10789067	3166.4331
248.24707	0.70369673	0.10885513	3175.7395
249.04785	0.7073217	0.10981913	3174.2993
249.84863	0.7087667	0.11076024	3179.8887
250.64941	0.71028149	0.1116169	3178.5625
251.4502	0.71323127	0.11279088	3187.3303
252.25098	0.71642178	0.11395948	3192.0671
253.05176	0.71950537	0.11510225	3190.2517
253.85254	0.72017968	0.11577911	3179.262
254.65332	0.72143418	0.11672135	3179.4722
255.4541	0.72568661	0.11772691	3186.3601
256.25488	0.72833502	0.11855067	3188.688
257.05566	0.73273093	0.11953347	3196.1926
257.85645	0.73338103	0.12026559	3197.0737
258.65723	0.73752022	0.12129985	3196.7417
259.45801	0.73496032	0.122232	3199.8262
260.25879	0.73759377	0.12326124	3201.5696
261.05957	0.7425344	0.12421857	3203.562
261.86035	0.74259073	0.12518203	3198.4058
262.66113	0.74867946	0.12620984	3213.979
263.46191	0.75101316	0.12714943	3212.884
264.2627	0.75103241	0.12829043	3209.6125
265.06348	0.75355089	0.12909849	3207.2715
265.86426	0.75554317	0.13007283	3209.022
266.66504	0.7600553	0.13106401	3208.6091
267.46582	0.75851923	0.13197091	3214.1106
268.2666	0.76461858	0.13302286	3213.0779
269.06738	0.76513362	0.13385436	3216.6279
269.86816	0.77083319	0.13482103	3223.7644
270.66895	0.77222055	0.1356831	3222.5107
271.46973	0.77111512	0.13657622	3219.199
272.27051	0.77685469	0.1375386	3222.2668
273.07129	0.77683014	0.13865359	3225.6213
273.87207	0.77874911	0.13952424	3223.9126
274.67285	0.78427595	0.1404883	3228.8335
275.47363	0.7839039	0.14146742	3222.1018
276.27441	0.78510863	0.14239778	3226.521
277.0752	0.78923142	0.14318301	3230.8743
277.87598	0.79196668	0.14420295	3240.0457
278.67676	0.79701346	0.14520206	3232.9333
279.47754	0.79455382	0.1461046	3234.1555
280.27832	0.8000598	0.14700855	3237.543
281.0791	0.80060685	0.14799237	3235.0547
281.87988	0.80550772	0.14899136	3239.5166
282.68066	0.80519098	0.14988969	3245.5281
283.48145	0.80947214	0.15101181	3242.4321
284.28223	0.81096888	0.15195756	3236.6724
285.08301	0.81284666	0.1530394	3241.502
285.88379	0.81432128	0.15402362	3246.293
286.68457	0.81736284	0.15502882	3256.7349
287.48535	0.82157552	0.15608619	3258.2524
288.28613	0.82435095	0.15712954	3254.8203
289.08691	0.82591301	0.15820564	3257.1416
289.8877	0.83162779	0.1592752	3256.677
290.68848	0.83201361	0.16022415	3254.1904
291.48926	0.83363324	0.1611242	3261.5249
292.29004	0.83626646	0.1619795	3255.3523
293.09082	0.83933282	0.16292068	3263.7363
293.8916	0.84049189	0.16381055	3269.6887
294.69238	0.8425293	0.16480583	3260.1919
295.49316	0.84341377	0.16577543	3261.3748
296.29395	0.84707248	0.1669313	3272.2839
297.09473	0.84999251	0.16791022	3265.6077
297.89551	0.85041177	0.1689253	3272.0046
298.69629	0.85690653	0.16984943	3271.718
299.49707	0.86079121	0.17067249	3272.9768
300.29785	0.86032015	0.17161484	3271.9277
301.09863	0.8646183	0.17263556	3278.7258
301.89941	0.86555696	0.17373438	3284.334
302.7002	0.86497217	0.17476618	3275.2429
303.50098	0.87066114	0.17585546	3278.7844
304.30176	0.87222731	0.17692783	3283.6545
305.10254	0.87448353	0.17796518	3283.1213
305.90332	0.87742078	0.17887725	3289.9133
306.7041	0.88022059	0.17983972	3280.3665
307.50488	0.88100719	0.18077299	3284.554
308.30566	0.88251084	0.18172812	3288.6277
309.10645	0.88576895	0.1827047	3281.7881
309.90723	0.88848644	0.18345514	3291.7217
310.70801	0.89385229	0.18426664	3293.3816
311.50879	0.89525843	0.18533899	3291.9631
312.30957	0.8960802	0.18622686	3285.406
313.11035	0.89900827	0.18680388	3285.6294
313.91113	0.89889026	0.18763849	3291.4656
314.71191	0.90320069	0.18863009	3302.592
315.5127	0.90656561	0.18962477	3300.7314
316.31348	0.90792507	0.1906203	3303.0981
317.11426	0.91236562	0.19173816	3301.9519
317.91504	0.91542047	0.19255845	3294.8284
318.71582	0.91689074	0.19347416	3305.2131
319.5166	0.92147923	0.1943554	3306.7473
320.31738	0.91971165	0.19539426	3317.1057
321.11816	0.92038614	0.19644907	3305.6145
321.91895	0.92383051	0.19766615	3311.3037
322.71973	0.92677885	0.19863626	3310.7292
323.52051	0.93062174	0.1995966	3315.6045
324.32129	0.93012363	0.20073722	3314.3879
325.12207	0.93463045	0.20170119	3314.0249
325.92285	0.93416083	0.20273332	3315.3877
326.72363	0.94104362	0.20372854	3318.7671
327.52441	0.94037324	0.20461094	3312.8843
328.3252	0.94586366	0.20535815	3313.4858
329.12598	0.94456625	0.20626448	3316.5581
329.92676	0.95014066	0.20718145	3318.6584
330.72754	0.95197076	0.20816791	3325.8472
331.52832	0.95081705	0.20931403	3328.5225
332.3291	0.95559752	0.21049297	3327.7856
333.12988	0.95517707	0.21139291	3319.3872
333.93066	0.96176118	0.21212642	3320.8533
334.73145	0.96320826	0.21304882	3328.5088
335.53223	0.96618044	0.21412814	3339.2739
336.33301	0.96649587	0.21504909	3335.5518
337.13379	0.96948546	0.21614477	3336.1501
337.93457	0.97389263	0.21739519	3344.1426
338.73535	0.97720891	0.21848725	3338.6499
339.53613	0.97964162	0.21955921	3338.262
340.33691	0.97966927	0.2204071	3328.3699
341.1377	0.98170626	0.22141969	3343.342
341.93848	0.98564011	0.22245006	3336.95
342.73926	0.98915213	0.22336271	3344.9875
343.54004	0.98683912	0.2244668	3349.7886
344.34082	0.99290669	0.22561233	3344.1858
345.1416	0.99336189	0.22657453	3341.6021
345.94238	0.9992193	0.2274891	3347.9031
346.74316	1.0005443	0.22819446	3345.3706
347.54395	1.0020046	0.22914092	3348.48
348.34473	1.005035	0.22983822	3351.0249
349.14551	1.008672	0.23090596	3358.3689
349.94629	1.008932	0.23180376	3349.4951
350.74707	1.0083883	0.23268098	3354.7222
351.54785	1.0151938	0.23373738	3359.1196
352.34863	1.0152889	0.23475757	3359.7229
353.14941	1.0183233	0.23574762	3357.0115
353.9502	1.0203667	0.23684521	3362.8596
354.75098	1.0255792	0.23779055	3360.9773
355.55176	1.026468	0.23891962	3361.3442
356.35254	1.0264903	0.23982821	3358.4504
357.15332	1.0328119	0.24080643	3373.3633
357.9541	1.0319417	0.24189821	3363.5845
358.75488	1.0347562	0.24272177	3358.9521
359.55566	1.0377614	0.24349527	3362.4854
360.35645	1.0418435	0.24447012	3369.1348
361.15723	1.0417552	0.24548544	3368.686
361.95801	1.0457718	0.2467071	3379.187
362.75879	1.050469	0.24775815	3376.6565
363.55957	1.0497146	0.24864897	3367.6016
364.36035	1.051977	0.24963075	3374.918
365.16113	1.052345	0.25054991	3375.4324
365.96191	1.0582266	0.25163898	3379.0562
366.7627	1.0576071	0.2527073	3377.5549
367.56348	1.0601448	0.25374371	3375.5129
368.36426	1.0636252	0.25472921	3385.0464
369.16504	1.0674149	0.25567618	3382.4194
369.96582	1.0719091	0.25649467	3374.6187
370.7666	1.0691065	0.25749913	3382.7751
371.56738	1.0705746	0.25847745	3382.4241
372.36816	1.0756872	0.25947192	3388.1802
373.16895	1.0767453	0.26037216	3379.0291
373.96973	1.0807608	0.26139885	3392.991
374.77051	1.0831456	0.26238909	3392.8125
375.57129	1.0841089	0.26343018	3386.9551
376.37207	1.0903931	0.26460218	3394.729
377.17285	1.0899013	0.26553339	3390.7522
377.97363	1.0939649	0.26646242	3398.8757
378.77441	1.0956094	0.26737985	3395.2617
379.5752	1.0960793	0.26850939	3393.0627
380.37598	1.0979728	0.26934105	3391.7693
381.17676	1.1027575	0.27032283	3396.7908
381.97754	1.1064262	0.27116242	3399.7351
382.77832	1.1060745	0.27214423	3400.978
383.5791	1.1100705	0.27310738	3398.8767
384.37988	1.1110725	0.27404684	3394.1162
385.18066	1.1142839	0.27481881	3398.9695
385.98145	1.1126188	0.27561688	3398.7981
386.78223	1.1167823	0.27672604	3407.5955
387.58301	1.1232837	0.27798113	3406.0383
388.38379	1.123696	0.27915385	3408.2581
389.18457	1.1252141	0.28024951	3406.3093
389.98535	1.1312371	0.28137869	3411.0688
390.78613	1.1319826	0.28215212	3401.9827
391.58691	1.1330438	0.28313878	3409.9844
392.3877	1.1357257	0.2840161	3414.2458
393.18848	1.1393826	0.28501084	3415.6094
393.98926	1.139944	0.28602025	3416.572
394.79004	1.1462723	0.28707218	3422.3992
395.59082	1.1486468	0.28801766	3411.8171
396.3916	1.1463603	0.28892356	3415.0186
397.19238	1.1487933	0.29008508	3419.269
397.99316	1.1544849	0.29112306	3428.8179
398.79395	1.1576558	0.29211715	3424.5818
399.59473	1.1566693	0.29310912	3418.6084
400.39551	1.1607823	0.29420859	3420.0352
401.19629	1.1610326	0.29505381	3419.1863
401.99707	1.1656729	0.29632118	3436.6365
402.79785	1.1689023	0.29769015	3431.9075
403.59863	1.170982	0.29874781	3430.531
404.39941	1.1713986	0.299822	3426.8689
405.2002	1.1747533	0.30076617	3426.3433
406.00098	1.1748142	0.30152127	3426.1853
406.80176	1.1793529	0.30251211	3427.1553
407.60254	1.1818786	0.30332747	3425.0007
408.40332	1.1847055	0.30432555	3436.1147
409.2041	1.187052	0.30530927	3440.9492
410.00488	1.191025	0.3062129	3438.9731
410.80566	1.1926044	0.30708066	3436.9966
411.60645	1.1940329	0.30827543	3443.9846
412.40723	1.1942974	0.30900875	3434.5349
413.20801	1.1979791	0.31022057	3439.5857
414.00879	1.1989031	0.31124803	3440.7029
414.80957	1.2050742	0.31208995	3437.2317
415.61035	1.2051409	0.31314483	3444.8672
416.41113	1.207103	0.31425759	3448.2773
417.21191	1.2111778	0.31532365	3442.1382
418.0127	1.2143472	0.31628519	3445.1401
418.81348	1.2133242	0.31703347	3440.533
419.61426	1.21806	0.31788835	3440.4846
420.41504	1.2190646	0.31889114	3446.7664
421.21582	1.2223895	0.31965154	3450.0837
422.0166	1.2260748	0.32072192	3455.7485
422.81738	1.2275494	0.32173014	3448.3376
423.61816	1.2295223	0.32257593	3452.2603
424.41895	1.2319221	0.32362354	3451.8691
425.21973	1.2363248	0.32460797	3449.8357
426.02051	1.235811	0.32547879	3459.8162
426.82129	1.2393825	0.32646015	3455.3943
427.62207	1.2392944	0.32740727	3458.3774
428.42285	1.2415839	0.32854447	3463.6909
429.22363	1.246568	0.32962427	3459.8135
430.02441	1.2494246	0.33070791	3462.3799
430.8252	1.2493565	0.33188456	3460.1252
431.62598	1.2519473	0.33275801	3457.6699
432.42676	1.256494	0.33384803	3466.2937
433.22754	1.2577771	0.33467305	3463.9465
434.02832	1.2600566	0.33570805	3462.6047
434.8291	1.2630852	0.33683652	3466.4297
435.62988	1.2671791	0.33783934	3470.7598
436.43066	1.2700502	0.33902693	3474.0845
437.23145	1.2679631	0.33996058	3468.3354
438.03223	1.2717862	0.34092668	3466.5432
438.83301	1.2744395	0.34212136	3469.3801
439.63379	1.2788929	0.34305149	3471.3076
440.43457	1.2798481	0.34411812	3472.0981
441.23535	1.2775325	0.34508532	3470.2581
442.03613	1.2851064	0.34613198	3471.478
442.83691	1.2855239	0.34715068	3473.5886
443.6377	1.2887249	0.34808463	3475.6785
444.43848	1.2919388	0.34912157	3485.2444
445.23926	1.2953469	0.35009551	3478.5051
446.04004	1.2989054	0.35125193	3482.5098
446.84082	1.2992619	0.3522048	3480.1628
447.6416	1.3007504	0.35315895	3475.7598
448.44238	1.3036851	0.35425812	3486.2217
449.24316	1.3070409	0.35520551	3482.9395
450.04395	1.3095952	0.35629669	3482.115
450.84473	1.3094085	0.35716012	3483.1841
451.64551	1.3153516	0.35823467	3494.7148
452.44629	1.3154255	0.35939017	3490.303
453.24707	1.3181393	0.360625	3489.7629
454.04785	1.3230335	0.36162108	3491.3262
454.84863	1.3227317	0.36255151	3493.6597
455.64941	1.3268015	0.36345136	3494.4944
456.4502	1.3251007	0.36443701	3488.7063
457.25098	1.3293239	0.36523905	3488.2366
458.05176	1.3348439	0.36607125	3490.3372
458.85254	1.3374662	0.36699536	3494.1008
459.65332	1.3378856	0.36777407	3488.3435
460.4541	1.3426884	0.36890188	3503.073
461.25488	1.3421593	0.36969191	3495.7356
462.05566	1.3454787	0.3706643	3497.7949
462.85645	1.3476652	0.37182894	3498.4141
463.65723	1.348984	0.37308872	3500.9036
464.45801	1.3524227	0.37426302	3510.4661
465.25879	1.3581817	0.37538189	3503.9705
466.05957	1.3595256	0.37632188	3506.3416
466.86035	1.3564008	0.37739643	3497.7759
467.66113	1.3644235	0.37844279	3510.5125
468.46191	1.3639737	0.37951204	3504.0049
469.2627	1.368363	0.38050938	3507.2998
470.06348	1.3694791	0.38156378	3506.0903
470.86426	1.3719871	0.38271812	3511.3154
471.66504	1.375138	0.38376784	3506.2148
472.46582	1.377237	0.38479874	3511.3569
473.2666	1.3801179	0.38598439	3515.2639
474.06738	1.3837805	0.38712278	3517.3672
474.86816	1.3860496	0.38822666	3516.2102
475.66895	1.3836493	0.38917619	3505.8293
476.46973	1.3890483	0.39012092	3513.1018
477.27051	1.3905004	0.39115724	3509.4656
478.07129	1.3938007	0.39205417	3507.6401
478.87207	1.397046	0.39306557	3519.175
479.67285	1.4008206	0.39400548	3516.1636
480.47363	1.3986677	0.39472243	3510.9248
481.27441	1.4027642	0.39584449	3516.7502
482.0752	1.4050367	0.39683762	3513.8511
482.87598	1.4073857	0.39788947	3523.2595
483.67676	1.4092349	0.39913687	3528.9504
484.47754	1.4110991	0.39992663	3515.0503
485.27832	1.4138873	0.40086803	3522.4856
486.0791	1.4179039	0.40184921	3523.9805
486.87988	1.4201589	0.40289867	3520.6836
487.68066	1.4196903	0.40403357	3526.835
488.48145	1.4235727	0.40538597	3532.2947
489.28223	1.4276918	0.40650326	3526.4558
490.08301	1.4304504	0.40759066	3528.5916
490.88379	1.4324892	0.40850177	3533.2158
491.68457	1.4316554	0.40960509	3530.1797
492.48535	1.4347818	0.41073817	3531.5723
493.28613	1.4381459	0.41172826	3533.511
494.08691	1.4422749	0.4127652	3530.7219
494.8877	1.4424012	0.4139193	3533.4619
495.68848	1.4472419	0.41495261	3533.8921
496.48926	1.4481553	0.41584629	3532.2524
497.29004	1.4512649	0.41718578	3534.0923
498.09082	1.4520534	0.41828522	3535.4321
498.8916	1.4560994	0.41940951	3536.7983
499.69238	1.4593621	0.42019796	3530.3743
500.49316	1.4607705	0.4210602	3534.4573
501.29395	1.4616325	0.42208418	3540.1682
502.09473	1.4640061	0.42300633	3539.6123
502.89551	1.4660273	0.42391929	3538.6575
503.69629	1.4696491	0.42510122	3544.3162
504.49707	1.4748222	0.42624301	3548.2253
505.29785	1.4744349	0.4273009	3549.0176
506.09863	1.4765409	0.42835933	3540.6389
506.89941	1.4795119	0.42955965	3546.5076
507.7002	1.4795784	0.43074557	3546.0811
508.50098	1.482825	0.43194112	3546.4749
509.30176	1.4872966	0.43313691	3546.2507
510.10254	1.489777	0.43428364	3551.1904
510.90332	1.4921571	0.43565542	3547.6243
511.7041	1.4942138	0.43686917	3556.9739
512.50488	1.4952344	0.43798402	3547.134
513.30566	1.4988818	0.4391309	3547.3486
514.10645	1.4993491	0.44009572	3548.9844
514.90723	1.5043093	0.44117987	3556.7422
515.70801	1.5060402	0.4418982	3549.3557
516.50879	1.5095067	0.4429093	3550.8191
517.30957	1.5107262	0.44384998	3556.7168
518.11035	1.5138366	0.44509932	3555.3381
518.91113	1.5147691	0.44640604	3560.5674
519.71191	1.5170019	0.44760323	3555.9998
520.5127	1.5221411	0.4486686	3559.6504
521.31348	1.5229846	0.44948131	3553.7324
522.11426	1.5281603	0.45048448	3555.8982
522.91504	1.5297549	0.45156729	3563.2727
523.71582	1.5323058	0.45274082	3555.8147
524.5166	1.5318928	0.45381996	3560.7578
525.31738	1.5357177	0.45486906	3563.1943
526.11816	1.5380656	0.45599091	3561.8398
526.91895	1.5376613	0.45695114	3563.0586
527.71973	1.5411178	0.4578945	3556.6375
528.52051	1.5431418	0.45898479	3561.6201
529.32129	1.5447112	0.45986527	3559.0112
530.12207	1.5475394	0.46090817	3565.3916
530.92285	1.5548877	0.46202239	3570.5261
531.72363	1.5526571	0.46315014	3570.4351
532.52441	1.5564039	0.46404421	3564.7615
533.3252	1.5586607	0.46508008	3568.4829
534.12598	1.5634686	0.46596366	3566.8579
534.92676	1.563031	0.4670735	3571.8589
535.72754	1.5651815	0.46837738	3571.1235
536.52832	1.5678467	0.46953091	3573.3367
537.3291	1.5728713	0.4706313	3579.4412
538.12988	1.5749817	0.47162035	3565.7388
538.93066	1.5746903	0.47248736	3571.0935
539.73145	1.5743418	0.473526	3574.4719
540.53223	1.5769638	0.474787	3575.7983
541.33301	1.5847424	0.47575662	3577.2349
542.13379	1.5851017	0.47693563	3576.7319
542.93457	1.5917708	0.47796717	3578.5947
543.73535	1.5905901	0.47907341	3579.6523
544.53613	1.5912697	0.48024419	3579.6653
545.33691	1.5942863	0.48141724	3579.4568
546.1377	1.5936285	0.48275506	3583.3564
546.93848	1.6006637	0.48402795	3579.304
547.73926	1.5974069	0.48518798	3577.72
548.54004	1.6008233	0.48633024	3579.7261
549.34082	1.6096454	0.48741323	3582.9736
550.1416	1.6082983	0.48855099	3579.9058
550.94238	1.6138778	0.48966518	3589.6323
551.74316	1.6121306	0.49047804	3577.7454
552.54395	1.6187103	0.4915024	3583.2048
553.34473	1.6214914	0.49241361	3582.0908
554.14551	1.6223546	0.49344879	3581.4246
554.94629	1.6236802	0.49432537	3582.6921
555.74707	1.6288722	0.49545485	3591.0288
556.54785	1.6287972	0.49647212	3585.8069
557.34863	1.6304207	0.49742696	3591.0957
558.14941	1.6321334	0.49862447	3592.6362
558.9502	1.6361258	0.49984321	3591.1863
559.75098	1.6377094	0.50083965	3592.5657
560.55176	1.640901	0.50217354	3595.2126
561.35254	1.6451451	0.50317526	3595.8562
562.15332	1.6430695	0.50414336	3589.9128
562.9541	1.6494431	0.50545561	3598.3325
563.75488	1.6519743	0.50670695	3593.9199
564.55566	1.6527101	0.50791532	3597.9915
565.35645	1.6560733	0.50887173	3595.5264
566.15723	1.6557285	0.50989163	3592.2085
566.95801	1.6570112	0.51102179	3595.6597
567.75879	1.6640309	0.51209086	3599.2959
568.55957	1.6610138	0.51331234	3593.5969
569.36035	1.6652288	0.51447308	3597.2251
570.16113	1.6700491	0.51580226	3609.5901
570.96191	1.6699382	0.51700944	3598.6589
571.7627	1.6752471	0.51813769	3594.4929
572.56348	1.6768026	0.51911467	3596.3477
573.36426	1.6778566	0.52003407	3595.3333
574.16504	1.6770271	0.52127981	3602.0708
574.96582	1.6836727	0.52247351	3608.0952
575.7666	1.6847878	0.52374929	3605.7312
576.56738	1.6894448	0.52502155	3604.644
577.36816	1.6880141	0.52613401	3601.7258
578.16895	1.6966702	0.52719605	3599.5122
578.96973	1.6936104	0.52797234	3595.0745
579.77051	1.6977817	0.52903461	3602.8276
580.57129	1.7015984	0.53024226	3610.4961
581.37207	1.7037635	0.5314796	3612.0281
582.17285	1.7039591	0.53274232	3609.302
582.97363	1.7117033	0.53415889	3611.4939
583.77441	1.7117383	0.53519517	3609.9253
584.5752	1.7124678	0.53647387	3610.7754
585.37598	1.7148188	0.53756976	3608.1375
586.17676	1.7140667	0.53853565	3602.6587
586.97754	1.7221937	0.53983003	3613.6118
587.77832	1.7204552	0.5408203	3605.7051
588.5791	1.7263665	0.54203671	3615.1641
589.37988	1.7288666	0.54315978	3613.2673
590.18066	1.7296153	0.5443961	3620.6904
590.98145	1.7325864	0.54554957	3615.3193
591.78223	1.7326562	0.5467338	3611.5005
592.58301	1.7362188	0.54764462	3612.2063
593.38379	1.7402123	0.54894799	3611.9536
594.18457	1.7428629	0.55048847	3617.7144
594.98535	1.7446851	0.5515275	3613.0935
595.78613	1.7472373	0.55269229	3619.1509
596.58691	1.7525219	0.55390221	3617.1436
597.3877	1.7522528	0.55513102	3623.7432
598.18848	1.7504296	0.55643004	3619.8547
598.98926	1.7586199	0.55764824	3619.7849
599.79004	1.7556615	0.55862111	3609.675
600.59082	1.7603856	0.55967861	3609.5344
601.3916	1.7647982	0.56054413	3615.1914
602.19238	1.7662489	0.56173605	3624.7515
602.99316	1.7674718	0.56284994	3619.5374
603.79395	1.7715988	0.56390488	3619.7551
604.59473	1.7743068	0.56481612	3620.4937
605.39551	1.7757859	0.56627953	3625.9224
606.19629	1.7775314	0.56725085	3620.7249
606.99707	1.7789063	0.56824118	3617.8193
607.79785	1.7828476	0.56963539	3628.5869
608.59863	1.7877313	0.57100117	3634.5708
609.39941	1.7876836	0.57221627	3630.4233
610.2002	1.787573	0.57343894	3624.7698
611.00098	1.7936627	0.57460088	3621.2727
611.80176	1.7920235	0.57558709	3622.6956
612.60254	1.7972388	0.57666874	3626.4763
613.40332	1.7992692	0.57772464	3625.7092
614.2041	1.8008796	0.57887459	3632.3657
615.00488	1.802688	0.58029366	3633.8728
615.80566	1.8046725	0.58155525	3632.0935
616.60645	1.8071527	0.5831098	3635.8435
617.40723	1.8119268	0.58442342	3635.0352
618.20801	1.8145607	0.58587945	3632.813
619.00879	1.8151079	0.58709878	3626.7751
619.80957	1.819554	0.58840734	3635.5032
620.61035	1.8218975	0.5893898	3628.1396
621.41113	1.8224705	0.59078532	3631.114
622.21191	1.828029	0.59197831	3636.074
623.0127	1.8267651	0.59323132	3632.6829
623.81348	1.8301619	0.5945124	3633.032
624.61426	1.8331443	0.59571725	3636.0195
625.41504	1.8348182	0.596838	3631.2444
626.21582	1.8364618	0.59791607	3634.3691
627.0166	1.8376046	0.59929657	3632.8176
627.81738	1.8400197	0.60051447	3634.8279
628.61816	1.8442744	0.60179657	3639.1091
629.41895	1.848487	0.60303813	3640.6653
630.21973	1.8510085	0.60418415	3640.8103
631.02051	1.8537641	0.60540825	3641.8066
631.82129	1.8532321	0.60662496	3633.7473
632.62207	1.8588024	0.60795265	3640.9441
633.42285	1.8608931	0.60918248	3642.0828
634.22363	1.8595233	0.61041528	3642.3545
635.02441	1.8638686	0.61160231	3643.7529
635.8252	1.8648754	0.61285186	3643.6243
636.62598	1.8708583	0.61405843	3642.3154
637.42676	1.8724778	0.61530977	3645.2065
638.22754	1.8733078	0.61663413	3643.3818
639.02832	1.8793471	0.61789411	3651.6089
639.8291	1.8785564	0.61916679	3642.7346
640.62988	1.8797611	0.62025064	3648.3069
641.43066	1.8849781	0.62164271	3642.0366
642.23145	1.8863199	0.62262499	3639.0996
643.03223	1.888877	0.62368298	3638.9463
643.83301	1.8898751	0.62498707	3649.2947
644.63379	1.8920658	0.62621832	3643.6494
645.43457	1.8943127	0.62725085	3636.9512
646.23535	1.898239	0.62835318	3644.4822
647.03613	1.8976321	0.62926632	3639.7539
647.83691	1.9024181	0.63050342	3649.6987
648.6377	1.9039234	0.6319133	3656.8704
649.43848	1.9080822	0.63335186	3650.5327
650.23926	1.909233	0.63453084	3646.395
651.04004	1.9123294	0.63593227	3651.6101
651.84082	1.9139204	0.63708848	3653.6204
652.6416	1.9176109	0.63871431	3655.4304
653.44238	1.9199463	0.63996303	3653.416
654.24316	1.9226613	0.64119279	3652.2959
655.04395	1.9249401	0.64244145	3650.2834
655.84473	1.9235351	0.64386559	3647.8953
656.64551	1.930763	0.64517272	3659.198
657.44629	1.9314191	0.64647609	3654.9224
658.24707	1.9317678	0.64768893	3641.1816
659.04785	1.934894	0.64876282	3645.1125
659.84863	1.9364098	0.650029	3647.5107
660.64941	1.9402695	0.65119308	3647.7883
661.4502	1.9429859	0.65254915	3655.9448
662.25098	1.9454429	0.6537953	3653.6958
663.05176	1.9492608	0.65523863	3655.9331
663.85254	1.9472367	0.65657645	3655.5591
664.65332	1.9517512	0.65796512	3655.4832
665.4541	1.9543097	0.65919232	3650.2261
666.25488	1.956098	0.66067696	3654.6174
667.05566	1.9587001	0.66201949	3652.8083
667.85645	1.9638568	0.66343224	3667.2212
668.65723	1.9664583	0.66506594	3663.575
669.45801	1.9686425	0.66623968	3660.0544
670.25879	1.972396	0.66742599	3657.2407
671.05957	1.9713007	0.66872102	3653.1418
671.86035	1.9748077	0.67011571	3660.3967
672.66113	1.9760625	0.67131776	3650.0818
673.46191	1.9813148	0.6725862	3651.1533
674.2627	1.9811347	0.67372322	3657.9478
675.06348	1.9874403	0.67500335	3664.001
675.86426	1.9870005	0.67635304	3662.0571
676.66504	1.9893047	0.67778087	3660.25
677.46582	1.9925323	0.67908537	3660.197
678.2666	1.9942589	0.68047315	3661.6077
679.06738	1.9943639	0.68171799	3654.6323
679.86816	1.9971598	0.68292671	3658.8779
680.66895	1.9999722	0.6841706	3655.4028
681.46973	2.0051594	0.68530113	3659.9495
682.27051	2.0061805	0.68682796	3663.5891
683.07129	2.007066	0.68816763	3663.8176
683.87207	2.0108278	0.68949425	3654.7231
684.67285	2.0118504	0.69083935	3659.2759
685.47363	2.017271	0.69210893	3664.998
686.27441	2.0163121	0.69351512	3665.0522
687.0752	2.0203471	0.69489628	3664.0964
687.87598	2.0219867	0.69645107	3664.6926
688.67676	2.0256443	0.69764161	3661.3647
689.47754	2.0277867	0.69935209	3672.4832
690.27832	2.0283113	0.70101142	3667.9236
691.0791	2.0324178	0.70230854	3660.9709
691.87988	2.0388131	0.70376903	3663.73
692.68066	2.0360308	0.70491576	3658.7905
693.48145	2.0376966	0.70615339	3661.3252
694.28223	2.0417571	0.70772773	3665.8384
695.08301	2.0446234	0.7091186	3670.7014
695.88379	2.0445924	0.71072143	3665.2019
696.68457	2.0503385	0.71230072	3669.4387
697.48535	2.0508311	0.71383488	3663.9597
698.28613	2.0511031	0.71537846	3665.5781
699.08691	2.0576186	0.71664655	3664.8611
699.8877	2.0577967	0.71793491	3656.751
700.68848	2.0620778	0.71937513	3666.6792
701.48926	2.0646582	0.72082371	3668.3413
702.29004	2.0653453	0.72223836	3668.9888
703.09082	2.0680282	0.72369409	3665.2266
703.8916	2.0704353	0.72496885	3667.7207
704.69238	2.0707881	0.72631109	3666.5242
705.49316	2.0741858	0.72762078	3672.1155
706.29395	2.0773487	0.72918957	3672.1533
707.09473	2.0791669	0.73043978	3670.6699
707.89551	2.0835474	0.7319513	3668.24
708.69629	2.0833426	0.73331523	3668.9971
709.49707	2.0837355	0.73471487	3671.8357
710.29785	2.0900788	0.73625875	3671.2844
711.09863	2.0931153	0.73805845	3672.8792
711.89941	2.095423	0.7394309	3665.2083
712.7002	2.0967846	0.74059892	3664.5647
713.50098	2.0996823	0.74209625	3670.3748
714.30176	2.1036963	0.74349624	3673.8281
715.10254	2.103775	0.74492103	3676.6946
715.90332	2.1057012	0.74650788	3669.4141
716.7041	2.1063406	0.74804562	3670.2224
717.50488	2.109704	0.74966097	3668.4014
718.30566	2.1131642	0.75096864	3666.8691
719.10645	2.1134531	0.75255966	3680.7114
719.90723	2.1171958	0.75413775	3671.1584
720.70801	2.1226413	0.7555182	3673.6238
721.50879	2.1229732	0.7571581	3677.2319
722.30957	2.1269817	0.75859839	3668.5454
723.11035	2.1264622	0.75999677	3671.7354
723.91113	2.1313322	0.76136035	3671.4006
724.71191	2.1323433	0.76293927	3673.4495
725.5127	2.1359866	0.76445979	3673.3828
726.31348	2.1379709	0.76582807	3669.1079
727.11426	2.1385779	0.76740122	3675.3086
727.91504	2.1424541	0.76880997	3674.469
728.71582	2.1455305	0.77016491	3673.155
729.5166	2.1498702	0.77169424	3680.7336
730.31738	2.1501784	0.77322268	3676.2549
731.11816	2.1548882	0.77481127	3680.6274
731.91895	2.1521897	0.77678537	3673.5737
732.71973	2.1567166	0.77848285	3678.1111
733.52051	2.158181	0.78006124	3669.9971
734.32129	2.1601737	0.78149873	3667.6995
735.12207	2.1667523	0.78316468	3679.8601
735.92285	2.1662414	0.78469586	3676.1902
736.72363	2.168936	0.78625315	3676.0928
737.52441	2.1713045	0.78773201	3667.5686
738.3252	2.1755228	0.78924394	3675.2676
739.12598	2.1782134	0.79076636	3676.9844
739.92676	2.1793048	0.79227746	3677.8943
740.72754	2.1799498	0.79389179	3672.0554
741.52832	2.1833742	0.79520553	3666.6692
742.3291	2.183742	0.79650599	3673.3274
743.12988	2.1901884	0.79793984	3672.3718
743.93066	2.1902204	0.79913741	3667.5964
744.73145	2.1942885	0.80071074	3682.0994
745.53223	2.193979	0.80227405	3677.4587
746.33301	2.1969554	0.80397886	3677.0732
747.13379	2.1981881	0.80530047	3674.1401
747.93457	2.200187	0.80699807	3677.905
748.73535	2.2032521	0.80879456	3673.2654
749.53613	2.2085106	0.81073278	3679.4226
750.33691	2.2098157	0.81243259	3678.303
751.1377	2.2136424	0.81409216	3672.5288
751.93848	2.2153287	0.81556135	3668.4644
752.73926	2.2181292	0.81701022	3674.4028
753.54004	2.2178667	0.81832445	3672.7251
754.34082	2.2200794	0.81992239	3674.0691
755.1416	2.224947	0.82154894	3677.5598
755.94238	2.2280633	0.82332247	3673.8479
756.74316	2.2273774	0.82493883	3673.8647
757.54395	2.2314994	0.82668614	3678.783
758.34473	2.2329357	0.82820725	3678.0154
759.14551	2.2346044	0.83002108	3676.2488
759.94629	2.2416914	0.83208543	3682.144
760.74707	2.2419894	0.83400828	3677.1528
761.54785	2.2443347	0.83586657	3682.2834
762.34863	2.2460625	0.83741671	3677.3186
763.14941	2.2475386	0.83908981	3673.8792
763.9502	2.2498696	0.84098291	3680.0107
764.75098	2.2571249	0.84289074	3682.8733
765.55176	2.2577386	0.84463567	3675.9121
766.35254	2.2580853	0.84620953	3673.5491
767.15332	2.2632926	0.84790915	3683.5603
767.9541	2.2610884	0.84978509	3681.4126
768.75488	2.2653759	0.85166353	3671.0769
769.55566	2.2665815	0.8534683	3675.2175
770.35645	2.2716806	0.85506618	3671.2695
771.15723	2.2755997	0.85659808	3682.4734
771.95801	2.2740443	0.8581534	3674.2361
772.75879	2.276063	0.85947406	3662.718
773.55957	2.277992	0.86091572	3673.7876
774.36035	2.2804313	0.86284542	3679.1938
775.16113	2.2861836	0.86456341	3678.2026
775.96191	2.2867637	0.8663258	3679.8152
776.7627	2.2899179	0.86782074	3672.3591
777.56348	2.2904637	0.86934054	3673.3792
778.36426	2.2914045	0.87080526	3671.1787
779.16504	2.298439	0.87296116	3687.3579
779.96582	2.2994919	0.87524122	3675.5374
780.7666	2.301528	0.87704486	3672.6277
781.56738	2.3036203	0.87896883	3678.9377
782.36816	2.3071148	0.8808471	3678.1831
783.16895	2.3105843	0.88252312	3671.991
783.96973	2.3100376	0.88410652	3670.9089
784.77051	2.312856	0.88610297	3676.3911
785.57129	2.3168702	0.88805532	3669.3518
786.37207	2.3191175	0.88941509	3670.0867
787.17285	2.3191133	0.89117754	3670.0698
787.97363	2.3223057	0.89327025	3674.0566
788.77441	2.3241005	0.89476097	3669.6499
789.5752	2.3283119	0.89636302	3671.4622
790.37598	2.3256826	0.89825404	3674.6155
791.17676	2.3346999	0.90018326	3676.394
791.97754	2.3317664	0.90220958	3680.6396
792.77832	2.3367698	0.90443903	3679.114
793.5791	2.3379884	0.90633518	3671.71
794.37988	2.341084	0.90800852	3668.7412
795.18066	2.3420241	0.90996116	3671.3787
795.98145	2.3502262	0.91215348	3673.679
796.78223	2.3471375	0.91420007	3667.4475
797.58301	2.355299	0.91595304	3666.0454
798.38379	2.3553741	0.9176662	3665.6831
799.18457	2.356353	0.91951293	3670.2341
799.98535	2.3607664	0.92152667	3667.408
800.78613	2.3620021	0.92338675	3668.324
801.58691	2.3634188	0.92551911	3667.6064
802.3877	2.3681378	0.92755312	3669.9934
803.18848	2.3684545	0.92986315	3678.9758
803.98926	2.3695877	0.93228304	3670.3174
804.79004	2.3765972	0.93443286	3666.9504
805.59082	2.3760285	0.9363535	3666.7559
806.3916	2.3790874	0.93826145	3662.7319
807.19238	2.380132	0.94007069	3666.1218
807.99316	2.3817816	0.94186348	3665.6516
808.79395	2.3874056	0.94353461	3664.0925
809.59473	2.3861756	0.94540799	3664.2747
810.39551	2.3906727	0.94758409	3669.6892
811.19629	2.3918355	0.94950479	3661.7649
811.99707	2.3946855	0.9517495	3675.7141
812.79785	2.3952777	0.95407879	3664.8042
813.59863	2.3961976	0.95616132	3662.9063
814.39941	2.4033659	0.95824283	3667.4927
815.2002	2.4039466	0.96010846	3664.4619
816.00098	2.4050393	0.96177226	3654.5259
816.80176	2.4100423	0.96352422	3664.0637
817.60254	2.4116218	0.96514469	3658.8896
818.40332	2.4157276	0.96697646	3660.5308
819.2041	2.4148309	0.96906024	3662.4221
820.00488	2.4203782	0.97079426	3654.822
820.80566	2.4214566	0.97253531	3659.6174
821.60645	2.4246418	0.97447604	3660.5352
822.40723	2.4256268	0.97655576	3664.2837
823.20801	2.4290664	0.97942311	3664.4922
824.00879	2.4299262	0.98165822	3658.8777
824.80957	2.4328539	0.98389465	3660.7603
825.61035	2.437603	0.98609853	3655.9023
826.41113	2.4398372	0.98790884	3656.0229
827.21191	2.4411018	0.98984003	3651.9875
828.0127	2.444061	0.992006	3661.0552
828.81348	2.4462316	0.99436033	3658.01
829.61426	2.4477723	0.99655426	3656.8054
830.41504	2.4488118	0.9991582	3655.6697
831.21582	2.4511659	1.0017544	3656.8904
832.0166	2.4536514	1.0039141	3651.6472
832.81738	2.4570014	1.0058481	3655.4534
833.61816	2.4595857	1.0080507	3653.804
834.41895	2.4661105	1.0102818	3655.5891
835.21973	2.4622879	1.0124363	3646.7178
836.02051	2.4676099	1.014643	3651.4387
836.82129	2.4686403	1.0171617	3653.5505
837.62207	2.4725478	1.0196607	3651.856
838.42285	2.4743822	1.0215576	3642.9729
839.22363	2.4781239	1.0236055	3651.8682
840.02441	2.4786665	1.0257503	3648.9265
840.8252	2.4825921	1.0281781	3654.9238
841.62598	2.4846785	1.03061	3649.9197
842.42676	2.4849591	1.0329517	3642.2261
843.22754	2.4875491	1.0352881	3639.1921
844.02832	2.4933743	1.0378597	3649.2727
844.8291	2.493763	1.0402391	3641.428
845.62988	2.494462	1.0424482	3635.6091
846.43066	2.4991858	1.0447671	3642.4204
847.23145	2.5049393	1.0470256	3639.8162
848.03223	2.5060861	1.0491254	3644.7942
848.83301	2.5074627	1.0512886	3644.2598
849.63379	2.505918	1.0530781	3636.907
850.43457	2.5103414	1.0554253	3638.3777
851.23535	2.5113883	1.057969	3639.843
852.03613	2.5144904	1.0606194	3639.4246
852.83691	2.5185049	1.0632969	3636.4495
853.6377	2.5207162	1.0654348	3628.0186
854.43848	2.5230463	1.067813	3644.6885
855.23926	2.5253766	1.0701683	3638.0989
856.04004	2.5258412	1.0723749	3627.6028
856.84082	2.5285807	1.0747892	3629.1785
857.6416	2.5291016	1.0770353	3632.6257
858.44238	2.5342252	1.0795105	3629.3723
859.24316	2.5381448	1.0816851	3624.7886
860.04395	2.5389395	1.083369	3621.0566
860.84473	2.5410502	1.085295	3623.3694
861.64551	2.5430768	1.0873719	3625.2976
862.44629	2.5454938	1.0900239	3625.3772
863.24707	2.5494473	1.092504	3620.3911
864.04785	2.5514646	1.0953016	3624.3745
864.84863	2.5529203	1.0981888	3620.9692
865.64941	2.5577621	1.1006651	3615.9026
866.4502	2.5589178	1.1029176	3614.1575
867.25098	2.5599041	1.1054776	3615.0725
868.05176	2.5658326	1.1080981	3616.0735
868.85254	2.5654132	1.1107627	3620.4004
869.65332	2.5680726	1.1133479	3607.0647
870.4541	2.5696349	1.1157005	3608.0691
871.25488	2.5720072	1.1181465	3607.1458
872.05566	2.576432	1.1206484	3610.7988
872.85645	2.5777164	1.1231759	3610.2839
873.65723	2.5792637	1.1259522	3602.4346
874.45801	2.5820906	1.1283789	3607.4036
875.25879	2.5844579	1.1304857	3600.9502
876.05957	2.5883505	1.1331071	3608.0012
876.86035	2.5890272	1.1358354	3602.6443
877.66113	2.5915062	1.1385722	3594.7007
878.46191	2.595639	1.1412827	3595.8962
879.2627	2.5974715	1.1437435	3595.051
880.06348	2.5986483	1.1460959	3596.801
880.86426	2.6034665	1.1485685	3595.7136
881.66504	2.6030345	1.151316	3596.2446
882.46582	2.6053476	1.1538225	3589.3196
883.2666	2.6087265	1.1562581	3578.1257
884.06738	2.6124048	1.1580935	3581.2561
884.86816	2.6108754	1.1603278	3583.7095
885.66895	2.6160691	1.1629211	3589.2183
886.46973	2.618129	1.1654162	3581.083
887.27051	2.6188982	1.1673194	3577.3264
888.07129	2.6261272	1.1695457	3577.4668
888.87207	2.6232255	1.1715908	3575.6643
889.67285	2.6296599	1.1737502	3572.1313
890.47363	2.6316979	1.1758353	3572.4805
891.27441	2.6343219	1.1786463	3578.8232
892.0752	2.6373689	1.181481	3577.3616
892.87598	2.6364882	1.1841142	3568.4617
893.67676	2.6384296	1.1868837	3565.8594
894.47754	2.6426024	1.1896889	3562.3896
895.27832	2.6472044	1.1920896	3551.293
896.0791	2.6452186	1.1942122	3562.7788
896.87988	2.6504321	1.196412	3556.8032
897.68066	2.6497409	1.1990583	3556.9553
898.48145	2.6508989	1.2020696	3553.9243
899.28223	2.657063	1.2049475	3553.5339
900.08301	2.6611886	1.2073658	3545.4131
900.88379	2.6624269	1.2096025	3545.3025
901.68457	2.6638944	1.2118608	3550.3245
902.48535	2.6681423	1.2146964	3548.1328
903.28613	2.6679475	1.2174195	3540.3428
904.08691	2.6708319	1.2198578	3532.8191
904.8877	2.6736612	1.2221507	3534.8467
905.68848	2.6760662	1.2247852	3538.9556
906.48926	2.6793561	1.2272975	3537.0186
907.29004	2.684263	1.2298752	3538.2896
908.09082	2.6851017	1.2324426	3528.6191
908.8916	2.6887801	1.235211	3525.043
909.69238	2.6863875	1.2379525	3525.7827
910.49316	2.6930516	1.2410207	3518.863
911.29395	2.695462	1.2437025	3524.5757
912.09473	2.6947868	1.2466811	3507.8096
912.89551	2.6975563	1.2491503	3508.1355
913.69629	2.7004397	1.2520181	3510.0925
914.49707	2.7020843	1.2544841	3502.9912
915.29785	2.7031322	1.2570217	3499.5879
916.09863	2.7098658	1.2592734	3506.3909
916.89941	2.7112491	1.2614536	3502.7742
917.7002	2.7119131	1.2640362	3504.0808
918.50098	2.7154908	1.2664539	3490.6763
919.30176	2.7174242	1.2688658	3489.7349
920.10254	2.7234371	1.2716291	3497.5498
920.90332	2.7197471	1.274202	3489.7236
921.7041	2.7254753	1.2770098	3488.209
922.50488	2.726475	1.2794585	3486.2542
923.30566	2.7289531	1.282214	3472.0327
924.10645	2.7306147	1.2847193	3470.7954
924.90723	2.7320559	1.2870566	3472.0391
925.70801	2.737484	1.2900168	3474.2002
926.50879	2.7395308	1.2928426	3467.9937
927.30957	2.7411239	1.2960787	3465.7778
928.11035	2.7437694	1.2986827	3454.7478
928.91113	2.7452261	1.3006817	3446.7061
929.71191	2.7480798	1.302722	3449.595
930.5127	2.7496932	1.3052363	3451.1655
931.31348	2.7527564	1.307933	3445.666
932.11426	2.7571268	1.3106711	3442.5913
932.91504	2.7577729	1.3140249	3441.8975
933.71582	2.7613795	1.3164785	3436.2466
934.5166	2.7612658	1.3193369	3427.4238
935.31738	2.7654023	1.3225151	3425.8447
936.11816	2.7682905	1.325374	3427.8918
936.91895	2.7697883	1.3282034	3422.4021
937.71973	2.7745068	1.330927	3418.7549
938.52051	2.7753112	1.333621	3414.1572
939.32129	2.7749946	1.3361599	3406.1353
940.12207	2.7817686	1.3393679	3413.4956
940.92285	2.7846589	1.3428069	3402.8486
941.72363	2.786443	1.3455919	3393.1973
942.52441	2.7828639	1.3482203	3388.5754
943.3252	2.79059	1.3507241	3385.5083
944.12598	2.7900035	1.3534253	3383.0625
944.92676	2.7926421	1.3560433	3379.6846
945.72754	2.7962036	1.3583014	3368.7117
946.52832	2.7986271	1.3605366	3368.4744
947.3291	2.8020418	1.3636488	3369.3899
948.12988	2.8049564	1.3671758	3359.2766
948.93066	2.8062134	1.3707314	3350.5757
949.73145	2.8063698	1.3736577	3332.356
950.53223	2.811089	1.3767577	3327.6892
951.33301	2.8157482	1.3804401	3314.7666
952.13379	2.8159094	1.3843663	3296.4434
952.93457	2.8209856	1.3899018	3265.457
953.73535	2.8223071	1.3954391	3214.4707
954.53613	2.8218703	1.3994817	3198.178
955.33691	2.8261917	1.404284	3172.0684
955.43701	2.8256986	1.4049795	3167.3044