File: datasets/am_bench_2022/raw_data/0-XY.20-1/specimen.dat
MTS793|MPT|ENU|1|2|.|/|:|1|0|0|A

Operator Information						Time:	14.06543	Sec	10/13/2021 3:48:36 PM
Operator	Jake Benzing
Project	AM Bench 2022 mini-tensile challenge
Specimen ID	0-XY.20-1
Material	PBF-L Inconel 625
Specimen Width	2.54	mm
Specimen Thickness	1.52	mm
Notes
Operator Information End

Data Acquisition						Time:	1015.0596	Sec	10/13/2021 4:05:17 PM
Time	Axial Displacement	Axial Extensometer	Axial Force
Sec	mm	mm	N
14.179443	-0.00076800224	-0.00012553553	59.993649
15.18042	0.0014995261	-5.0874285e-05	71.036278
16.181396	0.00075433764	3.7649879e-05	86.034225
17.182373	0.0066260519	0.0002275162	100.80402
18.18335	0.012475433	0.0001480564	112.47057
19.184326	0.013477913	0.00027394755	121.22557
20.185303	0.016463378	0.00038258074	136.67401
21.186279	0.019515999	0.00041517787	150.62273
22.187256	0.024473079	0.00051683147	168.2142
23.188232	0.025853429	0.00069710886	191.32692
24.189209	0.028621046	0.00086794898	203.09714
25.190186	0.031874098	0.00096202572	221.08209
26.191162	0.034089331	0.0010014549	242.62868
27.192139	0.036202934	0.0011084224	262.55237
28.193115	0.040685281	0.0012464686	283.15042
29.194092	0.040750232	0.0013183393	298.08115
30.195068	0.045489769	0.001440146	315.30908
31.196045	0.046995666	0.0015998523	337.07498
32.197021	0.051337462	0.0016975802	364.98456
33.197998	0.056405593	0.0017653899	387.31351
34.198975	0.059599996	0.0019505806	404.4415
35.199951	0.059125315	0.00206865	427.51944
36.200928	0.062460069	0.00209349	449.96027
37.201904	0.065268256	0.0022321017	475.01273
38.202881	0.069491416	0.002403151	495.46414
39.203857	0.073985644	0.0024332565	520.60583
40.204834	0.07327918	0.0027092129	542.99231
41.205811	0.075851381	0.0028140433	570.20618
42.206787	0.081926912	0.0030417356	596.20819
43.207764	0.085467838	0.0030107929	614.68134
44.20874	0.085878648	0.0031432335	640.60303
45.209717	0.092173815	0.003253143	659.84656
46.210693	0.091968924	0.0033618531	681.95001
47.21167	0.096249662	0.0036138466	715.66095
48.212646	0.10320315	0.0037193263	743.87372
49.213623	0.10360514	0.0038775259	763.82104
50.2146	0.10507093	0.0038086826	782.25934
51.215576	0.11035133	0.0040989607	816.8584
52.216553	0.11009174	0.0042564133	846.45941
53.217529	0.11441346	0.0043978323	868.16577
54.218506	0.11550327	0.0045979461	898.09088
55.219482	0.12109546	0.004714733	930.02216
56.220459	0.12359574	0.0048583555	953.31897
57.221436	0.12568051	0.0049175522	979.38513
58.222412	0.12784308	0.0051689507	1012.165
59.223389	0.13172059	0.0052634371	1040.3328
60.224365	0.13260756	0.0052908226	1061.3025
61.225342	0.13858992	0.0054547456	1104.0082
62.226318	0.14284934	0.0056943912	1132.7584
63.227295	0.14487956	0.0058533805	1159.7516
64.228271	0.14896299	0.005960464	1187.8774
65.229248	0.15041013	0.006040744	1213.2112
66.230225	0.15171529	0.0062365266	1241.7517
67.231201	0.15810451	0.006321195	1274.7576
68.232178	0.1587915	0.0065134545	1300.4689
69.233154	0.15948834	0.0066560972	1320.641
70.234131	0.16587822	0.0067827147	1350.1504
71.235107	0.16745727	0.0069064186	1379.9915
72.236084	0.17089795	0.0070345718	1400.7251
73.237061	0.17485003	0.0071481541	1427.7623
74.238037	0.1780445	0.0073494124	1461.6886
75.239014	0.17834076	0.0074921702	1487.9423
76.23999	0.18066519	0.0076927566	1511.5024
77.240967	0.18796721	0.0077846325	1547.6257
78.241943	0.18787767	0.0079852678	1575.7225
79.24292	0.19373797	0.0081277471	1608.4323
80.243896	0.19607961	0.0083205923	1637.6262
81.244873	0.19808769	0.0083819199	1657.0238
82.24585	0.20084916	0.0085674254	1684.47
83.246826	0.20594972	0.0087537151	1718.1965
84.247803	0.20566431	0.0090278229	1742.05
85.248779	0.20947789	0.0090056574	1775.5734
86.249756	0.21272802	0.0091126794	1792.6449
87.250732	0.21564808	0.0094103292	1818.1381
88.251709	0.22026448	0.0094671575	1846.2571
89.252686	0.22139399	0.0096582239	1869.8103
90.253662	0.22646847	0.0099578323	1902.4027
91.254639	0.22416079	0.010057655	1920.5785
92.255615	0.23159131	0.010230227	1950.8298
93.256592	0.23562905	0.010413685	1974.6798
94.257568	0.23573682	0.010565713	1988.0231
95.258545	0.23849973	0.010603409	2006.921
96.259521	0.24232683	0.010846763	2029.8094
97.260498	0.2450693	0.011091347	2048.4717
98.261475	0.2471893	0.011211383	2073.9023
99.262451	0.2542522	0.011371282	2100.865
100.26343	0.25619555	0.011571974	2114.915
101.2644	0.26143169	0.011801802	2142.9333
102.26538	0.25995776	0.011993434	2165.509
103.26636	0.26463592	0.012159763	2176.7522
104.26733	0.26703438	0.012354461	2193.094
105.26831	0.26890621	0.012585787	2215.0269
106.26929	0.27144173	0.01268438	2231.6179
107.27026	0.27567679	0.012985915	2246.1541
108.27124	0.28046012	0.01322872	2268.4045
109.27222	0.28415221	0.013346056	2285.9888
110.27319	0.28976575	0.013467665	2297.5027
111.27417	0.28636891	0.01378335	2312.1079
112.27515	0.29542351	0.01411131	2332.9478
113.27612	0.28960511	0.014245102	2339.0752
114.2771	0.29709786	0.014416541	2362.4521
115.27808	0.30284706	0.014759984	2379.3325
116.27905	0.30590931	0.01495555	2398.6003
117.28003	0.30543375	0.015329602	2415.1409
118.28101	0.31000033	0.01557367	2425.9534
119.28198	0.31382215	0.015841426	2435.2803
120.28296	0.31364676	0.016006047	2444.3982
121.28394	0.32298985	0.016321296	2467.0208
122.28491	0.32170007	0.016531143	2470.7622
123.28589	0.32363319	0.0167746	2487.1748
124.28687	0.32801479	0.017179858	2499.6614
125.28784	0.33280587	0.017653041	2515.0063
126.28882	0.33442265	0.017921222	2522.2383
127.28979	0.33613652	0.018262554	2538.9084
128.29077	0.33778712	0.018609578	2545.1685
129.29175	0.34355476	0.018990254	2555.5833
130.29272	0.34595191	0.019236984	2570.0715
131.2937	0.34661147	0.019729234	2572.5283
132.29468	0.35177407	0.020223785	2589.907
133.29565	0.35247108	0.020495431	2589.3606
134.29663	0.35770497	0.021012701	2602.7722
135.29761	0.36168474	0.021571007	2613.0537
136.29858	0.36106083	0.022046383	2621.0305
137.29956	0.36896932	0.022529347	2629.3477
138.30054	0.37274438	0.023040021	2640.5181
139.30151	0.3695969	0.02363657	2636.5127
140.30249	0.3754991	0.024103668	2641.6624
141.30347	0.37853539	0.024496939	2650.6013
142.30444	0.38266531	0.025053486	2663.8748
143.30542	0.38298556	0.02571637	2664.8794
144.3064	0.3925721	0.026534962	2682.9919
145.30737	0.3930575	0.027265791	2682.772
146.30835	0.39313656	0.028031087	2683.2837
147.30933	0.39693826	0.028657157	2693.1494
148.3103	0.40242597	0.029487545	2703.5508
149.31128	0.40111759	0.030334391	2703.061
150.31226	0.40682599	0.03115011	2712.9978
151.31323	0.40890211	0.031926118	2711.6492
152.31421	0.4126116	0.03287195	2727.3623
153.31519	0.41437	0.033850703	2732.6653
154.31616	0.4235445	0.034890112	2735.3857
155.31714	0.42179233	0.035962265	2747.2549
156.31812	0.42432308	0.037150748	2746.5898
157.31909	0.42846775	0.038058367	2746.4465
158.32007	0.4304443	0.039003339	2749.9956
159.32104	0.43278906	0.039973095	2754.2981
160.32202	0.4362396	0.041033462	2755.6899
161.323	0.43670613	0.041986126	2763.96
162.32397	0.44396898	0.043096546	2773.3596
163.32495	0.44448572	0.044093516	2763.375
164.32593	0.45242107	0.045227721	2775.0576
165.3269	0.45116901	0.046055887	2774.7979
166.32788	0.45594391	0.047370721	2789.2207
167.32886	0.45725602	0.048447281	2783.6675
168.32983	0.45859745	0.049690761	2787.3704
169.33081	0.46403173	0.051016331	2794.6467
170.33179	0.4687413	0.052313782	2792.7014
171.33276	0.4703984	0.053673878	2799.3369
172.33374	0.46991956	0.054729559	2798.1934
173.33472	0.47874334	0.05588321	2806.1609
174.33569	0.47934955	0.056922432	2807.8008
175.33667	0.48374197	0.058116719	2812.6453
176.33765	0.48540711	0.059251405	2810.0742
177.33862	0.48968211	0.060549177	2818.5994
178.3396	0.48942047	0.061756957	2818.8118
179.34058	0.49621415	0.063030943	2823.9097
180.34155	0.49892116	0.064147681	2816.9534
181.34253	0.49814442	0.065493695	2831.2227
182.34351	0.50318569	0.066744529	2830.7942
183.34448	0.50635797	0.06816522	2834.9539
184.34546	0.50880092	0.069541961	2834.8013
185.34644	0.51080179	0.070937373	2835.0764
186.34741	0.51218194	0.072364129	2838.917
187.34839	0.52034003	0.073728904	2837.52
188.34937	0.51886958	0.075106889	2842.9478
189.35034	0.52435374	0.07610447	2841.395
190.35132	0.52784145	0.077490672	2853.2766
191.35229	0.53117102	0.078986391	2853.9011
192.35327	0.53322029	0.080271125	2851.5415
193.35425	0.53375959	0.081276871	2848.063
194.35522	0.54115385	0.082658194	2857.1946
195.3562	0.54119545	0.084206596	2864.1587
196.35718	0.54517889	0.085911572	2865.814
197.35815	0.54586631	0.087239847	2856.7551
198.35913	0.54929715	0.088836886	2865.9907
199.36011	0.55240077	0.090542905	2868.6675
200.36108	0.55980402	0.092188336	2875.5405
201.36206	0.55766743	0.093485154	2866.4211
202.36304	0.56482625	0.094873875	2873.5845
203.36401	0.56305212	0.096382163	2874.6238
204.36499	0.56973481	0.097674437	2877.8005
205.36597	0.57636911	0.099135749	2877.5063
206.36694	0.57427388	0.10015325	2881.3325
207.36792	0.5790959	0.10156016	2884.1353
208.3689	0.58104402	0.10303369	2884.6372
209.36987	0.58334243	0.10438082	2883.5615
210.37085	0.58514118	0.10573177	2883.7007
211.37183	0.58827472	0.10735748	2889.8611
212.3728	0.59139293	0.10902164	2886.9607
213.37378	0.59607035	0.11048609	2893.3171
214.37476	0.59816718	0.11187686	2895.1414
215.37573	0.60329634	0.113369	2895.3926
216.37671	0.60717344	0.11464892	2895.2795
217.37769	0.60841799	0.11574689	2896.8052
218.37866	0.61587322	0.11731645	2908.7783
219.37964	0.61627239	0.11866215	2903.5823
220.38062	0.61527395	0.12004397	2899.9077
221.38159	0.61967188	0.12131876	2898.0024
222.38257	0.6228739	0.12267788	2907.0833
223.38354	0.62896973	0.12423991	2915.8176
224.38452	0.63021994	0.12588227	2910.7566
225.3855	0.63237023	0.12776433	2911.6335
226.38647	0.63577509	0.12901743	2913.8989
227.38745	0.63908035	0.13047415	2915.7808
228.38843	0.63701463	0.13221724	2910.1096
229.3894	0.64253294	0.13376541	2915.1614
230.39038	0.64846158	0.13529348	2922.5122
231.39136	0.65026647	0.1367494	2921.8342
232.39233	0.65569067	0.13805558	2923.0237
233.39331	0.653072	0.13943087	2920.2964
234.39429	0.65877569	0.14082325	2921.8667
235.39526	0.66095859	0.14232664	2927.8311
236.39624	0.66377091	0.14390178	2928.447
237.39722	0.66714317	0.14562219	2925.6929
238.39819	0.67279416	0.14700356	2935.9587
239.39917	0.67613733	0.14872694	2935.5374
240.40015	0.67530733	0.15015586	2928.6414
241.40112	0.68090135	0.15166789	2938.074
242.4021	0.68433529	0.1534247	2940.3706
243.40308	0.68631518	0.15482862	2934.1902
244.40405	0.69083315	0.1563203	2937.8948
245.40503	0.69411874	0.15764704	2937.0183
246.40601	0.69118762	0.15923651	2947.3027
247.40698	0.69733143	0.16081123	2940.9463
248.40796	0.70274991	0.16209495	2946.5747
249.40894	0.70501065	0.16348223	2947.3828
250.40991	0.71022773	0.16492157	2950.249
251.41089	0.71132648	0.16645913	2956.4912
252.41187	0.71055496	0.16767848	2944.5515
253.41284	0.71696776	0.16920738	2951.5286
254.41382	0.71901947	0.17027918	2947.6597
255.41479	0.72433162	0.17181014	2955.4395
256.41577	0.72640204	0.17317703	2955.6958
257.41675	0.72800344	0.17467228	2955.4004
258.41772	0.73057586	0.17631896	2961.6953
259.4187	0.73350286	0.1777707	2963.3169
260.41968	0.73643422	0.17952234	2962.7744
261.42065	0.74258232	0.18083121	2961.5535
262.42163	0.74503583	0.18254869	2969.501
263.42261	0.74803764	0.18382168	2962.5515
264.42358	0.75073624	0.18534318	2964.5627
265.42456	0.75325269	0.18692666	2971.3477
266.42554	0.75977105	0.18827146	2971.293
267.42651	0.7578488	0.1899395	2971.6169
268.42749	0.76295251	0.19205491	2982.0498
269.42847	0.76836836	0.19376625	2978.2161
270.42944	0.76762378	0.1952204	2969.3865
271.43042	0.77125263	0.19655205	2973.9153
272.4314	0.77359939	0.19788258	2976.6025
273.43237	0.77796084	0.19939396	2983.2598
274.43335	0.77871644	0.20103589	2981.7825
275.43433	0.78181374	0.20256297	2978.5947
276.4353	0.7839694	0.20397331	2980.0669
277.43628	0.78906125	0.20550212	2985.1282
278.43726	0.79454184	0.20690767	2983.2087
279.43823	0.79438245	0.20838764	2983.7551
280.43921	0.79743493	0.209874	2985.1714
281.44019	0.80027646	0.21137254	2985.635
282.44116	0.80128825	0.21264344	2981.0405
283.44214	0.80823392	0.21420182	2995.7395
284.44312	0.81185597	0.21588618	2996.0164
285.44409	0.81447244	0.21729407	2990.6223
286.44507	0.81720436	0.2184817	2991.0723
287.44604	0.82175636	0.2197701	3002.0786
288.44702	0.82171232	0.22124864	2992.231
289.448	0.82501286	0.22265284	2997.6899
290.44897	0.82898116	0.22406785	3000.7498
291.44995	0.83221877	0.2254369	2995.6257
292.45093	0.83604389	0.22698385	3004.7444
293.4519	0.83913505	0.22859091	3006.906
294.45288	0.84145296	0.23030093	3004.9229
295.45386	0.84176314	0.23212291	3007.781
296.45483	0.84689003	0.23366909	3008.4097
297.45581	0.85233968	0.2351664	3006.0999
298.45679	0.85164231	0.23657006	3012.804
299.45776	0.85350102	0.23815852	3002.8552
300.45874	0.86146975	0.23962432	3009.4946
301.45972	0.86387432	0.24090992	3013.3108
302.46069	0.8624956	0.24240658	3011.657
303.46167	0.86677104	0.2440922	3016.9668
304.46265	0.87021887	0.24583456	3014.761
305.46362	0.87117493	0.24739946	3017.0698
306.4646	0.8761375	0.24885879	3022.5305
307.46558	0.88111079	0.25043568	3017.9771
308.46655	0.88404948	0.25180838	3028.0479
309.46753	0.88525611	0.25334826	3025.0803
310.46851	0.88778728	0.25469166	3023.7859
311.46948	0.89217657	0.25626603	3027.4451
312.47046	0.89109153	0.25777152	3026.8838
313.47144	0.89496475	0.25945729	3028.3696
314.47241	0.90364754	0.26084548	3032.1384
315.47339	0.90539217	0.26251587	3035.3994
316.47437	0.90466911	0.26415336	3027.0701
317.47534	0.91034901	0.2655156	3030.8862
318.47632	0.90656018	0.2668885	3023.1938
319.47729	0.91260338	0.26817447	3029.4963
320.47827	0.91523826	0.26987344	3038.6421
321.47925	0.92178118	0.27133328	3036.8689
322.48022	0.92514014	0.27289402	3033.8411
323.4812	0.92970461	0.27437523	3036.2456
324.48218	0.92772704	0.27538902	3031.73
325.48315	0.92834723	0.27679259	3036.8525
326.48413	0.93460065	0.27815533	3037.2065
327.48511	0.93807638	0.27955547	3041.1284
328.48608	0.94445413	0.28130996	3049.0845
329.48706	0.94300866	0.283014	3046.0979
330.48804	0.9470374	0.2847603	3042.1729
331.48901	0.95373273	0.28600475	3046.3699
332.48999	0.95471722	0.28758034	3048.2744
333.49097	0.95647883	0.2890301	3043.6404
334.49194	0.96263802	0.29079306	3052.5986
335.49292	0.96483153	0.29242206	3051.3198
336.4939	0.96437645	0.29367331	3044.8777
337.49487	0.96611637	0.2951178	3050.51
338.49585	0.97067499	0.29704177	3051.3298
339.49683	0.97100383	0.29843068	3054.4395
340.4978	0.9809677	0.29999772	3056.3386
341.49878	0.98050427	0.30131626	3057.1104
342.49976	0.98205674	0.3027162	3055.3965
343.50073	0.98652804	0.30429739	3059.9749
344.50171	0.9893254	0.30597451	3057.2515
345.50269	0.99387038	0.3072007	3058.1875
346.50366	0.99698472	0.30877283	3061.2283
347.50464	0.99991214	0.31032807	3061.2144
348.50562	1.0032957	0.31178623	3060.4607
349.50659	1.0050106	0.31330791	3063.4265
350.50757	1.0101144	0.31479582	3070.1597
351.50854	1.0087435	0.31636885	3062.9614
352.50952	1.011972	0.31788597	3064.8215
353.5105	1.0204725	0.31937966	3068.8042
354.51147	1.0198258	0.32067871	3068.084
355.51245	1.0238532	0.32176664	3068.0452
356.51343	1.025484	0.3233386	3074.2852
357.5144	1.0300273	0.32471895	3074.9084
358.51538	1.0336403	0.3262729	3080.3416
359.51636	1.0355316	0.32783413	3076.4695
360.51733	1.036737	0.32928038	3074.5842
361.51831	1.0429218	0.33067161	3079.2297
362.51929	1.0417391	0.33229643	3076.9639
363.52026	1.0479174	0.33379254	3078.6016
364.52124	1.0514013	0.3351894	3089.6555
365.52222	1.0535741	0.33660567	3075.2935
366.52319	1.0547352	0.33799073	3081.4741
367.52417	1.0575103	0.33921367	3074.7222
368.52515	1.0625483	0.340763	3090.3916
369.52612	1.0652995	0.34243423	3088.4326
370.5271	1.0690858	0.34401518	3085.4956
371.52808	1.0700006	0.34568784	3090.7336
372.52905	1.0778306	0.34737647	3092.3743
373.53003	1.0757009	0.34863526	3084.7419
374.53101	1.0766561	0.35016492	3090.7698
375.53198	1.0835027	0.35182124	3094.9009
376.53296	1.0850649	0.35345367	3090.501
377.53394	1.0937045	0.35498184	3098.3975
378.53491	1.0907991	0.35621682	3087.1196
379.53589	1.0932242	0.35775268	3089.7676
380.53687	1.0951258	0.359245	3093.6245
381.53784	1.1039422	0.36042532	3095.3948
382.53882	1.1028707	0.36180809	3099.7576
383.53979	1.1070244	0.36359963	3104.458
384.54077	1.1097468	0.36530215	3102.1948
385.54175	1.1135895	0.36679354	3098.229
386.54272	1.1154565	0.36820886	3100.3555
387.5437	1.1182884	0.36957902	3101.2351
388.54468	1.1210773	0.37099674	3105.1931
389.54565	1.1228806	0.37240812	3103.7944
390.54663	1.1311197	0.37389177	3111.042
391.54761	1.130913	0.37544951	3104.9255
392.54858	1.1358042	0.37684128	3109.7261
393.54956	1.1333373	0.37831676	3106.3596
394.55054	1.1397197	0.37998125	3106.8242
395.55151	1.1435694	0.38154453	3113.5881
396.55249	1.1446648	0.38309079	3111.5403
397.55347	1.14868	0.38464758	3107.9001
398.55444	1.1522596	0.38610387	3110.5464
399.55542	1.1532027	0.38749731	3112.3018
400.5564	1.1572492	0.38909018	3107.1523
401.55737	1.162769	0.39045975	3119.7095
402.55835	1.1639942	0.39197323	3118.4436
403.55933	1.1651018	0.39345843	3115.6628
404.5603	1.1683017	0.39514828	3116.9648
405.56128	1.1711812	0.39661011	3118.2981
406.56226	1.1764057	0.39792374	3116.8799
407.56323	1.1785644	0.39948604	3119.7571
408.56421	1.1814041	0.40085697	3126.3264
409.56519	1.1864002	0.40242502	3119.4851
410.56616	1.188146	0.40365249	3119.7485
411.56714	1.1914269	0.40539989	3134.2769
412.56812	1.1960213	0.4068383	3125.3499
413.56909	1.1964687	0.40841219	3126.8474
414.57007	1.201072	0.4099803	3129.7388
415.57104	1.2016789	0.41142985	3129.3757
416.57202	1.2056826	0.41270286	3125.0977
417.573	1.2097206	0.41422376	3130.9666
418.57397	1.2127048	0.41577435	3135.4824
419.57495	1.2136868	0.41718018	3129.8862
420.57593	1.2169783	0.41849849	3126.3137
421.5769	1.2251543	0.42004645	3137.5681
422.57788	1.2239194	0.42125842	3130.177
423.57886	1.2303897	0.42292142	3137.9568
424.57983	1.2306733	0.424254	3133.5349
425.58081	1.2341286	0.42547241	3135.4458
426.58179	1.2356006	0.42697579	3140.759
427.58276	1.2404473	0.42839774	3135.7886
428.58374	1.2392884	0.42976138	3132.8379
429.58472	1.2444915	0.43110409	3136.3044
430.58569	1.2473459	0.43259889	3143.2771
431.58667	1.2541326	0.43414029	3149.1567
432.58765	1.2526115	0.43585339	3141.4092
433.58862	1.254843	0.43749586	3143.0723
434.5896	1.2576312	0.43899843	3148.6301
435.59058	1.2655314	0.44083235	3153.3867
436.59155	1.265515	0.44229236	3146.6602
437.59253	1.2694517	0.44358438	3146.1221
438.59351	1.2722229	0.44488701	3148.7283
439.59448	1.2783253	0.44640687	3151.7275
440.59546	1.2780689	0.44802013	3149.8022
441.59644	1.2797747	0.44929031	3147.4746
442.59741	1.2852423	0.45085844	3155.387
443.59839	1.2881122	0.45217839	3153.99
444.59937	1.2920835	0.45348531	3158.8479
445.60034	1.2933754	0.45481348	3155.1331
446.60132	1.2966944	0.45647451	3159.3069
447.60229	1.3003453	0.45819557	3154.5964
448.60327	1.3005563	0.45958638	3153.9006
449.60425	1.3043848	0.46113178	3161.4548
450.60522	1.3087158	0.46258289	3157.29
451.6062	1.3112929	0.46422729	3160.2546
452.60718	1.3162503	0.46593457	3165.1267
453.60815	1.3183461	0.46766204	3158.6204
454.60913	1.3198601	0.46930474	3166.0342
455.61011	1.3219619	0.47080499	3159.8557
456.61108	1.3269954	0.47230691	3167.3098
457.61206	1.3288542	0.47363332	3163.0083
458.61304	1.33219	0.4750694	3163.135
459.61401	1.3368214	0.47656786	3165.8188
460.61499	1.3402256	0.47799712	3160.624
461.61597	1.3421772	0.47929367	3165.187
462.61694	1.3466341	0.48058778	3178.6499
463.61792	1.3479389	0.4820691	3162.2236
464.6189	1.3501825	0.48322767	3163.8113
465.61987	1.355346	0.48456553	3170.9995
466.62085	1.3580601	0.48568153	3166.6443
467.62183	1.3591131	0.48718068	3176.9609
468.6228	1.3618383	0.48884293	3170.6868
469.62378	1.3652483	0.49029738	3178.7305
470.62476	1.3699908	0.49195784	3178.4543
471.62573	1.3727398	0.49367601	3178.3269
472.62671	1.3740318	0.49514207	3179.4167
473.62769	1.3762139	0.49684066	3180.5388
474.62866	1.3802717	0.49833325	3173.3218
475.62964	1.3826789	0.49983194	3175.1047
476.63062	1.3846333	0.50127667	3171.8752
477.63159	1.3876647	0.50259966	3175.0237
478.63257	1.3924019	0.50426644	3185.061
479.63354	1.3963556	0.50559616	3180.5205
480.63452	1.3963577	0.50696826	3186.4578
481.6355	1.4008825	0.50859356	3184.1282
482.63647	1.4040257	0.5102489	3187.26
483.63745	1.4063667	0.51162267	3185.783
484.63843	1.4109854	0.51318562	3182.353
485.6394	1.4140222	0.51479673	3188.4307
486.64038	1.4179618	0.5164153	3191.5369
487.64136	1.4190412	0.51786304	3180.4695
488.64233	1.4225612	0.51949716	3183.8372
489.64331	1.4272105	0.52123928	3195.3745
490.64429	1.4322321	0.5223726	3188.8796
491.64526	1.4296788	0.5239799	3185.0229
492.64624	1.4344946	0.52550191	3188.9429
493.64722	1.4376346	0.5269599	3189.4316
494.64819	1.441188	0.52831995	3191.9155
495.64917	1.4451249	0.52975553	3192.5518
496.65015	1.4480354	0.53135401	3197.5068
497.65112	1.4511076	0.53289062	3192.2363
498.6521	1.4529328	0.53436476	3189.9502
499.65308	1.4554876	0.53553599	3189.0688
500.65405	1.4560395	0.53669471	3192.0264
501.65503	1.4620087	0.53804094	3203.4807
502.65601	1.462021	0.53940797	3193.6797
503.65698	1.4702305	0.54079026	3196.9114
504.65796	1.4721409	0.54225862	3209.718
505.65894	1.4711483	0.54420549	3199.3062
506.65991	1.4762242	0.5456745	3199.8748
507.66089	1.481451	0.54750103	3203.821
508.66187	1.4810451	0.54897177	3202.8972
509.66284	1.4871833	0.55041224	3206.6509
510.66382	1.4894165	0.55175424	3204.489
511.66479	1.4943017	0.55319935	3199.9153
512.66577	1.4923714	0.55460644	3201.3333
513.66675	1.4982034	0.55621564	3203.5903
514.66772	1.4990145	0.5579071	3207.6848
515.6687	1.5020138	0.55950177	3204.6882
516.66968	1.5069603	0.56105006	3210.4817
517.67065	1.5090424	0.56240505	3208.9182
518.67163	1.5151515	0.56405801	3212.291
519.67261	1.513644	0.56576234	3207.9739
520.67358	1.5170295	0.56733817	3209.4819
521.67456	1.5208027	0.56886506	3205.9724
522.67554	1.5268018	0.57033533	3212.6616
523.67651	1.5282234	0.5720064	3215.2073
524.67749	1.5282638	0.57349855	3212.6917
525.67847	1.5335317	0.57492203	3211.345
526.67944	1.5370084	0.57644802	3218.9265
527.68042	1.5418022	0.57810414	3216.6875
528.6814	1.5433278	0.57934374	3209.2927
529.68237	1.5464226	0.58074623	3220.8013
530.68335	1.5505165	0.58236188	3223.7524
531.68433	1.551671	0.5839051	3215.9854
532.6853	1.5560117	0.58547521	3222.6924
533.68628	1.5590786	0.58688927	3223.0706
534.68726	1.5619286	0.58855927	3222.1946
535.68823	1.5641842	0.59014648	3220.8105
536.68921	1.5661342	0.59127361	3215.4639
537.69019	1.5668803	0.59267443	3219.9807
538.69116	1.5749848	0.59406716	3221.4346
539.69214	1.5751088	0.59550077	3221.7737
540.69312	1.5780733	0.59705514	3227.3594
541.69409	1.5821476	0.59846991	3217.821
542.69507	1.5833622	0.59984708	3221.9141
543.69604	1.5879849	0.60133624	3223.2437
544.69702	1.5894399	0.60283273	3220.6787
545.698	1.5924529	0.60433286	3225.5332
546.69897	1.5985641	0.60588229	3228.9343
547.69995	1.5994779	0.60745084	3226.8987
548.70093	1.6037972	0.60907865	3234.3647
549.7019	1.608006	0.61050856	3230.792
550.70288	1.6090434	0.61194962	3229.7512
551.70386	1.6112013	0.6135692	3231.2771
552.70483	1.6147274	0.6151213	3236.9902
553.70581	1.6175952	0.6167497	3235.1277
554.70679	1.6175596	0.61871243	3232.1152
555.70776	1.6249812	0.62029964	3233.6255
556.70874	1.6267773	0.62180585	3230.9641
557.70972	1.6300094	0.62315559	3231.0959
558.71069	1.6338687	0.62487322	3232.573
559.71167	1.6317139	0.62618339	3232.8623
560.71265	1.6409358	0.62770993	3238.2852
561.71362	1.6418971	0.62918591	3236.3665
562.7146	1.6426593	0.63081479	3239.7292
563.71558	1.6491702	0.63254553	3243.6685
564.71655	1.6522398	0.63392848	3239.9255
565.71753	1.6546289	0.6354546	3238.4685
566.71851	1.6574029	0.63703251	3237.9739
567.71948	1.6570585	0.63866961	3234.8328
568.72046	1.6631633	0.64022195	3236.769
569.72144	1.6639909	0.64178121	3246.75
570.72241	1.6678488	0.6430704	3234.093
571.72339	1.6699009	0.64456391	3240.4878
572.72437	1.6752495	0.64596432	3241.3738
573.72534	1.6758527	0.64727473	3240.4397
574.72632	1.6812547	0.64881331	3244.9058
575.72729	1.685055	0.65032077	3244.0645
576.72827	1.6853234	0.651779	3239.6946
577.72925	1.6915818	0.65325516	3249.5173
578.73022	1.6924903	0.65453881	3243.0432
579.7312	1.6961875	0.65631515	3246.3291
580.73218	1.6971354	0.65780365	3243.5862
581.73315	1.7034202	0.65943849	3249.8083
582.73413	1.7050431	0.66113222	3251.5557
583.73511	1.7064413	0.66288882	3245.4268
584.73608	1.7112763	0.66420764	3247.8894
585.73706	1.7135273	0.66584486	3255.5496
586.73804	1.7155592	0.66737896	3249.2429
587.73901	1.7198149	0.6690551	3245.3665
588.73999	1.7219335	0.67041081	3246.5068
589.74097	1.7261862	0.67214018	3255.1096
590.74194	1.7301528	0.67369556	3255.8677
591.74292	1.733224	0.67542189	3262.0039
592.7439	1.7353754	0.67721391	3254.1426
593.74487	1.740355	0.6786052	3253.1057
594.74585	1.737842	0.6799078	3251.5378
595.74683	1.7439132	0.68125772	3254.9028
596.7478	1.7481015	0.68265194	3254.6853
597.74878	1.7497486	0.68426245	3256.1975
598.74976	1.7534405	0.68580419	3260.9417
599.75073	1.7560455	0.68750006	3261.0933
600.75171	1.7568309	0.68926072	3256.0693
601.75269	1.7618059	0.69086814	3258.0544
602.75366	1.7650543	0.69234848	3260.7292
603.75464	1.76719	0.69415897	3263.7866
604.75562	1.7728944	0.69580531	3258.7622
605.75659	1.769866	0.6974473	3258.5391
606.75757	1.7766079	0.69895583	3266.1919
607.75854	1.7768923	0.70067865	3260.1575
608.75952	1.7797314	0.70210469	3257.126
609.7605	1.7858382	0.70350134	3261.4412
610.76147	1.7860403	0.70513016	3260.9912
611.76245	1.7927284	0.70665675	3266.4094
612.76343	1.7952998	0.70826989	3265.426
613.7644	1.7981429	0.70987982	3274.2212
614.76538	1.8027211	0.71160948	3269.4897
615.76636	1.8082097	0.71306974	3269.3606
616.76733	1.8031975	0.71473831	3262.6057
617.76831	1.8092719	0.71636581	3268.3127
618.76929	1.8123925	0.71807879	3266.9817
619.77026	1.8164974	0.71973383	3268.4058
620.77124	1.8175131	0.72108048	3264.9146
621.77222	1.8232495	0.72300619	3271.6829
622.77319	1.8258307	0.72476166	3266.6707
623.77417	1.8301595	0.7263813	3278.5063
624.77515	1.8332428	0.72809291	3274.542
625.77612	1.8327887	0.7296989	3268.7554
626.7771	1.839591	0.73142928	3280.1816
627.77808	1.8392031	0.73329961	3269.9194
628.77905	1.8443457	0.73443568	3274.1152
629.78003	1.8451794	0.73591405	3269.5349
630.78101	1.8477771	0.73743695	3269.9631
631.78198	1.8509601	0.73935038	3273.5862
632.78296	1.8537656	0.74061167	3264.9229
633.78394	1.8552243	0.74222898	3274.1379
634.78491	1.8607067	0.74401021	3277.5337
635.78589	1.8647913	0.74626899	3282.2402
636.78687	1.8670764	0.7480126	3274.5811
637.78784	1.869512	0.74951237	3274.4976
638.78882	1.8721104	0.75113678	3267.2397
639.78979	1.8764153	0.75253624	3270.062
640.79077	1.8758882	0.75385016	3275.8115
641.79175	1.881873	0.7553705	3277.8936
642.79272	1.881495	0.75720292	3280.6377
643.7937	1.8858622	0.75880659	3277.2021
644.79468	1.8895543	0.76054031	3276.5513
645.79565	1.8943591	0.76216805	3280.8992
646.79663	1.8956194	0.76362085	3277.627
647.79761	1.9033716	0.76489705	3281.9626
648.79858	1.9028	0.76646012	3274.8872
649.79956	1.9082242	0.76778632	3280.9504
650.80054	1.9096471	0.76969296	3286.9456
651.80151	1.9130335	0.77144003	3290.2664
652.80249	1.9139832	0.77351856	3281.675
653.80347	1.92038	0.77514094	3284.7314
654.80444	1.9213418	0.77698231	3280.6113
655.80542	1.9255455	0.77875561	3279.676
656.8064	1.9246619	0.78017712	3277.5928
657.80737	1.9312395	0.78166503	3286.9282
658.80835	1.9310772	0.78344351	3283.1958
659.80933	1.9362692	0.78535968	3285.157
660.8103	1.9391819	0.78689837	3281.4126
661.81128	1.9439747	0.78855437	3286.3503
662.81226	1.9458872	0.79030722	3290.4333
663.81323	1.948851	0.79216206	3291.5
664.81421	1.9505347	0.79383683	3283.2061
665.81519	1.9503274	0.79532427	3283.5605
666.81616	1.9582033	0.79705465	3292.5171
667.81714	1.9599887	0.798917	3290.7424
668.81812	1.9625458	0.80068493	3288.3379
669.81909	1.9648683	0.80242354	3286.1663
670.82007	1.971877	0.80417031	3291.5024
671.82104	1.9731143	0.80576515	3286.6465
672.82202	1.9765285	0.80718821	3290.6482
673.823	1.9781178	0.80887514	3289.3096
674.82397	1.9803479	0.81038171	3292.5254
675.82495	1.9834791	0.81199372	3290.144
676.82593	1.9873059	0.81372279	3285.2891
677.8269	1.9901112	0.81504005	3283.6768
678.82788	1.9935406	0.81665385	3291.4512
679.82886	1.9955894	0.8180303	3285.9927
680.82983	1.9994467	0.81966144	3291.6125
681.83081	2.0031133	0.82117701	3294.5808
682.83179	2.0046849	0.82276523	3294.8811
683.83276	2.0043125	0.8246612	3291.7061
684.83374	2.0114796	0.82644278	3292.3191
685.83472	2.013932	0.82825279	3296.6592
686.83569	2.017719	0.83019012	3296.8406
687.83667	2.0178537	0.83216041	3289.5808
688.83765	2.021488	0.83364701	3286.8315
689.83862	2.0266602	0.83544946	3293.6152
690.8396	2.0279229	0.83737344	3295.3337
691.84058	2.031039	0.83899385	3290.5
692.84155	2.0333347	0.8410871	3298.2253
693.84253	2.0373595	0.84293246	3292.7634
694.84351	2.0436792	0.84471053	3293.7424
695.84448	2.0455778	0.84644789	3294.3267
696.84546	2.0460417	0.84815967	3292.6711
697.84644	2.0499465	0.84985405	3295.3271
698.84741	2.0540791	0.85183674	3304.9829
699.84839	2.0564563	0.8536734	3301.8035
700.84937	2.0596099	0.8555283	3301.979
701.85034	2.0629206	0.85765535	3298.9658
702.85132	2.0645111	0.8594439	3293.2769
703.85229	2.0705004	0.86106652	3300.1936
704.85327	2.0672476	0.86310232	3300.3616
705.85425	2.0742943	0.86505395	3298.3901
706.85522	2.0813301	0.86663204	3301.1846
707.8562	2.0785556	0.86828279	3295.7195
708.85718	2.0820591	0.87006986	3299.8882
709.85815	2.0869725	0.87187082	3299.9995
710.85913	2.0886927	0.87366414	3301.3123
711.86011	2.0886176	0.87560189	3301.3611
712.86108	2.0958121	0.87741208	3298.7725
713.86206	2.1015866	0.87905091	3298.2043
714.86304	2.0992303	0.88068289	3296.7551
715.86401	2.108217	0.88243538	3303.0686
716.86499	2.107538	0.88388032	3296.9983
717.86597	2.1086123	0.8853634	3298.4319
718.86694	2.1112287	0.88724965	3301.6531
719.86792	2.1178155	0.88889891	3299.8521
720.8689	2.1211567	0.89071488	3307.7256
721.86987	2.1235354	0.89264202	3309.324
722.87085	2.1270514	0.89457822	3302.1841
723.87183	2.1313751	0.89657855	3305.7607
724.8728	2.1313403	0.89831227	3306.4714
725.87378	2.1323345	0.90001667	3302.1428
726.87476	2.1387646	0.90165192	3302.6226
727.87573	2.1411166	0.90392143	3312.1008
728.87671	2.1416781	0.90567142	3297.5745
729.87769	2.148762	0.9074254	3302.7351
730.87866	2.1476543	0.90895349	3299.7375
731.87964	2.1534755	0.91063011	3300.8142
732.88062	2.1512747	0.91262984	3301.1072
733.88159	2.1551092	0.91515666	3310.3911
734.88257	2.1637707	0.9167493	3304.1147
735.88354	2.1671576	0.91856313	3305.9983
736.88452	2.1664834	0.92032349	3307.3264
737.8855	2.1699941	0.92209238	3303.291
738.88647	2.1724496	0.92384982	3304.6365
739.88745	2.1753914	0.92602772	3303.437
740.88843	2.1800656	0.92818338	3307.1824
741.8894	2.1830039	0.93043053	3314.6208
742.89038	2.1840115	0.9324919	3304.0967
743.89136	2.1887455	0.9343766	3304.489
744.89233	2.1909969	0.93609828	3302.415
745.89331	2.1932497	0.93757743	3303.6262
746.89429	2.1973975	0.93977237	3307.0261
747.89526	2.2003255	0.94145906	3300.3069
748.89624	2.2040932	0.94345897	3308.345
749.89722	2.2065129	0.9453885	3306.8862
750.89819	2.2102611	0.94733667	3305.5796
751.89917	2.2099843	0.9491182	3302.8599
752.90015	2.2146204	0.95109826	3304.4663
753.90112	2.2206788	0.95315158	3302.5796
754.9021	2.2228377	0.95486045	3303.3943
755.90308	2.2234795	0.95662874	3299.8936
756.90405	2.2277455	0.95840794	3307.4502
757.90503	2.2327273	0.96019685	3309.0532
758.90601	2.2340837	0.96214503	3305.2092
759.90698	2.2359529	0.96411359	3308.293
760.90796	2.2388608	0.96628863	3305.2615
761.90894	2.2435944	0.96820211	3307.3042
762.90991	2.2437828	0.97011989	3304.2761
763.91089	2.2473388	0.97194862	3308.2517
764.91187	2.2504766	0.97445893	3307.5911
765.91284	2.2535918	0.97656375	3305.8074
766.91382	2.2586548	0.97829998	3309.3223
767.91479	2.2585888	0.98020339	3301.533
768.91577	2.2637041	0.98210829	3308.0994
769.91675	2.2671962	0.98431724	3310.5115
770.91772	2.2700465	0.98644334	3308.2756
771.9187	2.2697332	0.9889096	3308.4597
772.91968	2.2742484	0.99108326	3306.3127
773.92065	2.2790544	0.9932912	3310.5461
774.92163	2.2805212	0.9952035	3304.6228
775.92261	2.2866752	0.99705726	3306.8613
776.92358	2.2893224	0.9989177	3300.0498
777.92456	2.2928731	1.0007827	3312.2065
778.92554	2.2945349	1.0032411	3310.894
779.92651	2.2957125	1.0054134	3309.7859
780.92749	2.3017862	1.0076126	3307.3667
781.92847	2.3012123	1.0097781	3302.9749
782.92944	2.3050108	1.0116128	3306.45
783.93042	2.3107314	1.0135512	3308.4832
784.9314	2.3134346	1.0151986	3309.4131
785.93237	2.3139887	1.0172789	3309.6799
786.93335	2.3193321	1.0192747	3307.9741
787.93433	2.3205643	1.0209038	3307.0742
788.9353	2.32163	1.0227299	3305.4529
789.93628	2.3244178	1.0247065	3311.2507
790.93726	2.3294296	1.0268778	3306.9802
791.93823	2.3321607	1.0289075	3308.9082
792.93921	2.3350129	1.0307007	3303.9695
793.94019	2.3386915	1.0327076	3306.1833
794.94116	2.3409951	1.0349971	3309.3215
795.94214	2.3441339	1.0373244	3308.2715
796.94312	2.3462243	1.0393391	3311.1641
797.94409	2.347352	1.041507	3306.1421
798.94507	2.3540757	1.0435493	3309.9702
799.94604	2.3585539	1.0457348	3313.2725
800.94702	2.3567135	1.0484172	3306.0557
801.948	2.3646879	1.0503485	3303.5938
802.94897	2.3624172	1.0523683	3306.5588
803.94995	2.3668323	1.0546395	3309.6873
804.95093	2.3709424	1.057271	3309.1833
805.9519	2.3765328	1.0595397	3312.7478
806.95288	2.3751655	1.0615617	3305.5256
807.95386	2.38252	1.0636835	3307.7537
808.95483	2.3801386	1.0654508	3295.9727
809.95581	2.3864148	1.0678641	3306.6602
810.95679	2.3892715	1.0702403	3309.9077
811.95776	2.3921492	1.0726849	3307.7458
812.95874	2.3946681	1.0748447	3301.4836
813.95972	2.4024105	1.0770447	3306.7996
814.96069	2.4013865	1.0792336	3301.0083
815.96167	2.4057703	1.0813614	3304.8271
816.96265	2.4069126	1.0838643	3304.323
817.96362	2.4099019	1.0859579	3298.2139
818.9646	2.4124546	1.0878563	3300.7224
819.96558	2.4192536	1.0898653	3306.4094
820.96655	2.4192064	1.0921069	3307.5991
821.96753	2.424037	1.0944338	3307.0305
822.96851	2.425596	1.0965889	3303.6221
823.96948	2.4277942	1.0985637	3292.7114
824.97046	2.4310553	1.1006519	3303.27
825.97144	2.434351	1.1028148	3305.4656
826.97241	2.436336	1.1051593	3302.7922
827.97339	2.4403393	1.1080157	3302.0735
828.97437	2.4444699	1.1102037	3300.8748
829.97534	2.445564	1.112262	3298.8247
830.97632	2.4493566	1.1145465	3300.5955
831.97729	2.4487963	1.1165794	3298.8831
832.97827	2.456425	1.1185595	3300.8052
833.97925	2.4562583	1.1206074	3298.6519
834.98022	2.461633	1.1228139	3302.8413
835.9812	2.4641566	1.125165	3302.9636
836.98218	2.4680743	1.1275164	3304.0203
837.98315	2.4696252	1.1299847	3298.2175
838.98413	2.4753942	1.1325134	3305.0554
839.98511	2.4767597	1.1352187	3304.1086
840.98608	2.4767761	1.1379552	3301.1135
841.98706	2.482058	1.1408082	3305.5535
842.98804	2.4833999	1.1434159	3297.2009
843.98901	2.4894252	1.1454376	3296.5215
844.98999	2.4917798	1.1480939	3299.6436
845.99097	2.493057	1.150318	3296.7808
846.99194	2.4992659	1.152819	3295.7612
847.99292	2.499711	1.1549708	3297.136
848.9939	2.5016663	1.1571285	3291.7534
849.99487	2.5057619	1.1593655	3296.8884
850.99585	2.5100503	1.1614504	3296.8398
851.99683	2.5120265	1.1640426	3298.9729
852.9978	2.5139985	1.1667634	3302.324
853.99878	2.5201743	1.1697215	3298.4556
854.99976	2.5206037	1.1721311	3295.7385
856.00073	2.5253832	1.1745198	3294.3528
857.00171	2.5291409	1.1768777	3299.1714
858.00269	2.5337627	1.1792762	3305.8926
859.00366	2.5351875	1.1822211	3293.8123
860.00464	2.5364347	1.1843302	3288.6838
861.00562	2.541533	1.1864678	3289.0969
862.00659	2.5424907	1.1881266	3285.3809
863.00757	2.5463455	1.1897253	3288.7893
864.00854	2.5483873	1.1919404	3293.5903
865.00952	2.5501854	1.1944655	3296.585
866.0105	2.5570939	1.1976606	3295.1746
867.01147	2.555099	1.1999424	3286.2864
868.01245	2.5585489	1.2028224	3287.2656
869.01343	2.5609796	1.2049348	3287.2671
870.0144	2.5679736	1.2076025	3293.5554
871.01538	2.5675397	1.2101295	3293.2124
872.01636	2.5737464	1.2126173	3290.8015
873.01733	2.5750308	1.2152503	3291.9729
874.01831	2.5764856	1.2173967	3278.894
875.01929	2.5821743	1.219854	3289.614
876.02026	2.5835927	1.2222875	3288.832
877.02124	2.5883868	1.2248605	3284.6499
878.02222	2.5887358	1.2272197	3281.9912
879.02319	2.5940526	1.230049	3289.5298
880.02417	2.5989561	1.2332112	3285.0537
881.02515	2.5998602	1.2360098	3280.4023
882.02612	2.6019096	1.2385355	3280.4526
883.0271	2.6064346	1.2408198	3276.6541
884.02808	2.6076431	1.2430906	3280.5039
885.02905	2.6109874	1.2455878	3282.7917
886.03003	2.6192522	1.2483521	3287.7773
887.03101	2.6163568	1.2515434	3283.967
888.03198	2.6207511	1.2542304	3275.3691
889.03296	2.6241975	1.2568835	3277.0535
890.03394	2.63044	1.259506	3282.9368
891.03491	2.6275938	1.2623149	3277.0522
892.03589	2.6327789	1.2649577	3276.1775
893.03687	2.6350646	1.267619	3278.1592
894.03784	2.6376562	1.2707542	3272.4302
895.03882	2.6430659	1.2734805	3274.7063
896.03979	2.6478276	1.2757207	3268.2898
897.04077	2.6505163	1.2778046	3270.0884
898.04175	2.6516337	1.2800503	3275.5303
899.04272	2.6554227	1.2827618	3270.4343
900.0437	2.6552775	1.2853122	3265.0981
901.04468	2.6605251	1.2881992	3275.7891
902.04565	2.6637695	1.2905284	3262.1538
903.04663	2.6666193	1.2931632	3269.4124
904.04761	2.6688848	1.2953824	3264.7615
905.04858	2.6735897	1.2980919	3271.5037
906.04956	2.6704133	1.3008778	3269.0032
907.05054	2.6764994	1.3039995	3264.241
908.05151	2.6789021	1.3068404	3258.6108
909.05249	2.6837699	1.3095007	3263.1406
910.05347	2.6874852	1.3119873	3264.4524
911.05444	2.6919413	1.3142697	3260.8374
912.05542	2.6933169	1.3172811	3267.2578
913.0564	2.695225	1.3205006	3269.2639
914.05737	2.6971166	1.3234001	3257.5474
915.05835	2.7007296	1.3265448	3260.7649
916.05933	2.7047086	1.3291931	3253.6719
917.0603	2.711046	1.3318945	3256.3521
918.06128	2.7114003	1.3339688	3254.6235
919.06226	2.7179551	1.3369732	3260.0562
920.06323	2.7170868	1.3398632	3254.5449
921.06421	2.7204173	1.3425672	3255.6157
922.06519	2.7231531	1.3453628	3251.0662
923.06616	2.7272458	1.3483018	3254.1021
924.06714	2.7294011	1.350861	3247.5022
925.06812	2.7302403	1.3536837	3245.8215
926.06909	2.7366722	1.3565587	3253.6011
927.07007	2.7378955	1.3590126	3247.0635
928.07104	2.7395759	1.3615299	3246.3069
929.07202	2.7435153	1.3644611	3243.7666
930.073	2.7447598	1.3670095	3242.7312
931.07397	2.7491477	1.3693483	3236.7151
932.07495	2.7535851	1.3722036	3240.2783
933.07593	2.7569163	1.3758419	3246.1931
934.0769	2.7618284	1.3790917	3244.6626
935.07788	2.759553	1.3819551	3232.6145
936.07886	2.7662413	1.3850963	3240.6406
937.07983	2.7675478	1.3880762	3229.8877
938.08081	2.7702243	1.390561	3233.1084
939.08179	2.7736337	1.3930659	3229.1033
940.08276	2.7763374	1.395972	3234.9829
941.08374	2.7811079	1.3991896	3232.8296
942.08472	2.7818489	1.4016292	3223.6733
943.08569	2.7857583	1.4042928	3230.9651
944.08667	2.789305	1.4072076	3230.7109
945.08765	2.7911916	1.4099956	3226.8601
946.08862	2.7959828	1.4128244	3225.0435
947.0896	2.7985854	1.4155018	3225.6514
948.09058	2.7991674	1.418528	3224.53
949.09155	2.8044918	1.4221641	3221.1692
950.09253	2.809314	1.4256328	3225.4063
951.09351	2.8084095	1.4287218	3214.0073
952.09448	2.8120773	1.4313859	3206.304
953.09546	2.8154418	1.4339697	3212.8333
954.09644	2.8202	1.436727	3215.8313
955.09741	2.8202002	1.4396693	3211.8167
956.09839	2.8254664	1.442636	3211.0461
957.09937	2.8284411	1.4456735	3209.123
958.10034	2.8309512	1.4487002	3213.8726
959.10132	2.8377776	1.4515715	3204.8472
960.10229	2.8402154	1.4541934	3205.9558
961.10327	2.8412116	1.4571946	3208.1816
962.10425	2.8450167	1.4600691	3201.8208
963.10522	2.8476567	1.4630406	3200.384
964.1062	2.8504629	1.4661385	3197.2102
965.10718	2.849638	1.4688576	3189.2749
966.10815	2.8568561	1.4712437	3194.4236
967.10913	2.8572972	1.4738595	3190.2905
968.11011	2.8591971	1.4768577	3195.24
969.11108	2.8618097	1.4797031	3186.9333
970.11206	2.8647938	1.4824278	3185.1143
971.11304	2.8722656	1.4858952	3196.3804
972.11401	2.8763139	1.4898481	3191.3206
973.11499	2.8782895	1.4927826	3179.3491
974.11597	2.8785098	1.4954108	3180.0715
975.11694	2.8811722	1.4985524	3181.3699
976.11792	2.8859992	1.5026351	3177.5825
977.1189	2.8873916	1.5054092	3171.5071
978.11987	2.8920381	1.5081847	3174.8884
979.12085	2.8955019	1.5109975	3172.1062
980.12183	2.8952498	1.5138295	3174.9929
981.1228	2.9004276	1.5171344	3166.3945
982.12378	2.9014597	1.519793	3162.5588
983.12476	2.9025533	1.5226274	3169.0239
984.12573	2.9091146	1.5267961	3165.9661
985.12671	2.9143369	1.5307595	3165.208
986.12769	2.9173455	1.5342332	3160.2715
987.12866	2.9181826	1.5371308	3154.9551
988.12964	2.9215488	1.5395671	3148.6768
989.13062	2.9274895	1.5424461	3163.6687
990.13159	2.9284406	1.5452838	3150.9968
991.13257	2.9310572	1.5481719	3147.2415
992.13354	2.9342346	1.5515506	3147.2488
993.13452	2.9364576	1.554142	3143.3308
994.1355	2.938745	1.5571111	3138.7944
995.13647	2.9402509	1.5596912	3136.8354
996.13745	2.9447243	1.5626861	3134.0889
997.13843	2.9496756	1.5659631	3140.9504
998.1394	2.9528711	1.5688419	3137.1147
999.14038	2.9528668	1.5722499	3130.061
1000.1414	2.9587021	1.5752224	3123.5691
1001.1423	2.9622345	1.5777881	3128.6045
1002.1433	2.9609101	1.5807097	3125.7097
1003.1443	2.9651418	1.5840799	3122.8931
1004.1453	2.9693687	1.5874604	3119.73
1005.1462	2.9738257	1.590561	3120.814
1006.1472	2.9766781	1.5936803	3117.769
1007.1482	2.9807825	1.5967343	3121.8884
1008.1492	2.9817724	1.5998396	3113.3538
1009.1501	2.9838319	1.6026617	3109.2146
1010.1511	2.9858711	1.6060451	3110.4534
1011.1521	2.9887395	1.6092827	3109.0276
1012.1531	2.993866	1.6119841	3091.3372
1013.1541	2.9939792	1.6143125	3091.7251
1014.155	2.9987965	1.6166065	3095.9878
1015.156	3.0017529	1.6188966	3092.5759
1016.157	3.0061231	1.6213692	3094.2964
1017.158	3.0096712	1.6243087	3095.0413
1018.1589	3.0103855	1.627002	3090.5476
1019.1599	3.0147192	1.6302831	3092.1021
1020.1609	3.0170972	1.6337534	3089.271
1021.1619	3.0211773	1.6375479	3086.4124
1022.1628	3.0210907	1.640528	3072.7112
1023.1638	3.0242248	1.6440314	3075.1296
1024.1648	3.0310977	1.6467681	3071.4978
1025.1658	3.0322356	1.6497304	3071.98
1026.1667	3.0386281	1.6528728	3067.6548
1027.1677	3.0378528	1.6560435	3063.3982
1028.1687	3.042243	1.6589911	3065.9692
1029.1697	3.0447524	1.6619391	3059.8333
1030.1707	3.0486674	1.6650233	3060.2229
1031.1716	3.0535281	1.668259	3059.8318
1032.1726	3.0544214	1.6715137	3058.9473
1033.1736	3.0575993	1.6753103	3052.5818
1034.1746	3.0595508	1.6786398	3040.6836
1035.1755	3.0657983	1.6816704	3046.2959
1036.1765	3.0669911	1.6849483	3045.842
1037.1775	3.0674419	1.6884853	3036.4258
1038.1785	3.0712445	1.6919112	3038.1077
1039.1794	3.0713937	1.6948659	3029.0781
1040.1804	3.0748177	1.6977645	3025.9043
1041.1814	3.0804312	1.701449	3024.2666
1042.1824	3.0861008	1.704793	3022.8164
1043.1833	3.0871298	1.7080357	3025.0432
1044.1843	3.0886457	1.7109278	3011.2864
1045.1853	3.0944746	1.7138916	3021.26
1046.1863	3.0960524	1.7168577	3016.5627
1047.1873	3.0992036	1.7199367	3011.0588
1048.1882	3.1013668	1.7231662	3004.4243
1049.1892	3.1014161	1.7261127	3000.5669
1050.1902	3.1064284	1.7294338	2995.3774
1051.1912	3.1078362	1.7329931	2994.1147
1052.1921	3.1143925	1.7364639	2996.4077
1053.1931	3.1152089	1.7399743	2989.7012
1054.1941	3.1197846	1.7429615	2978.3618
1055.1951	3.1250625	1.7460823	2984.1563
1056.196	3.1266651	1.749669	2985.3875
1057.197	3.1274338	1.753311	2976.4941
1058.198	3.1308944	1.7571324	2968.2944
1059.199	3.1316407	1.7603388	2964.3533
1060.2	3.1370406	1.7635726	2960.7856
1061.2009	3.1425891	1.766018	2959.7778
1062.2019	3.1432328	1.7690537	2964.0266
1063.2029	3.1480985	1.77256	2953.7952
1064.2039	3.1498778	1.7756943	2952.4355
1065.2048	3.1516733	1.7793318	2947.2551
1066.2058	3.1554344	1.782552	2942.604
1067.2068	3.1609929	1.7859634	2945.4514
1068.2078	3.1606741	1.7894642	2934.6323
1069.2087	3.1624744	1.7930002	2926.0435
1070.2097	3.1666355	1.7961929	2928.2583
1071.2107	3.1717927	1.7993785	2923.7476
1072.2117	3.1771014	1.8032737	2925.8018
1073.2126	3.1771057	1.8066922	2915.6235
1074.2136	3.1811864	1.8099282	2907.2183
1075.2146	3.1825781	1.8123853	2905.2473
1076.2156	3.187916	1.8153284	2911.0657
1077.2166	3.1879277	1.8186672	2902.6282
1078.2175	3.1919985	1.8221151	2895.4287
1079.2185	3.1947961	1.8255972	2885.4548
1080.2195	3.1976035	1.8287795	2884.7493
1081.2205	3.2007413	1.8319597	2883.7227
1082.2214	3.2047956	1.8353605	2878.5774
1083.2224	3.2036722	1.8393401	2878.2808
1084.2234	3.2105582	1.8431643	2870.4509
1085.2244	3.2137344	1.8467886	2866.9854
1086.2253	3.2172089	1.8502383	2864.0349
1087.2263	3.2164288	1.8536441	2852.2627
1088.2273	3.2201259	1.8567328	2845.3213
1089.2283	3.2232106	1.859597	2845.2534
1090.2292	3.2281671	1.8628178	2843.0493
1091.2302	3.230999	1.8663437	2837.6895
1092.2312	3.2307706	1.8696744	2835.2532
1093.2322	3.235419	1.8742172	2831.9578
1094.2332	3.2397981	1.877532	2818.2627
1095.2341	3.2444513	1.8809006	2823.905
1096.2351	3.2475526	1.8843716	2808.4333
1097.2361	3.2486155	1.8875247	2808.0691
1098.2371	3.2523751	1.8907046	2810.1672
1099.238	3.256506	1.894514	2797.6829
1100.239	3.2592099	1.8980803	2794.1282
1101.24	3.2622132	1.9015065	2787.2659
1102.241	3.2663064	1.9055265	2791.4109
1103.2419	3.2703252	1.9089839	2779.4302
1104.2429	3.2706449	1.9119991	2766.292
1105.2439	3.2742712	1.9145281	2766.3081
1106.2449	3.2729919	1.917356	2761.4846
1107.2458	3.2771726	1.9209189	2760.9434
1108.2468	3.2832019	1.9240355	2752.6824
1109.2478	3.2875032	1.9271735	2747.0354
1110.2488	3.2877581	1.9303069	2745.0298
1111.2498	3.2882988	1.9343247	2745.0942
1112.2507	3.2962494	1.9385083	2735.1433
1113.2517	3.2953889	1.9425935	2717.8635
1114.2527	3.2961669	1.9456786	2717.6772
1115.2537	3.3047869	1.9496254	2718.1128
1116.2546	3.3074396	1.9536268	2703.1824
1117.2556	3.3070273	1.9573017	2696.2673
1118.2566	3.3152323	1.9608986	2693.7832
1119.2576	3.3161428	1.9637485	2681.9636
1120.2585	3.318234	1.9669819	2686.2151
1121.2595	3.3220787	1.9717426	2676.658
1122.2605	3.3234959	1.9751424	2663.6917
1123.2615	3.3300984	1.9784482	2656.7019
1124.2625	3.3295732	1.9814039	2649.9482
1125.2634	3.3334939	1.9843941	2648.7244
1126.2644	3.3354576	1.9881109	2646.5557
1127.2654	3.3384666	1.9924393	2636.5664
1128.2664	3.3434031	1.996374	2631.3665
1129.2673	3.3469737	2.0000031	2617.6609
1130.2683	3.3469758	2.0031199	2608.2273
1131.2693	3.3511183	2.006799	2606.3042
1132.2703	3.351728	2.0107725	2593.3892
1133.2712	3.3548615	2.0150833	2585.3655
1134.2722	3.3590431	2.0190706	2573.6599
1135.2732	3.3644385	2.0228655	2569.9114
1136.2742	3.36781	2.0271504	2557.2808
1137.2751	3.3707416	2.0322075	2549.2454
1138.2761	3.3752592	2.036587	2536.7129
1139.2771	3.3745437	2.0407078	2517.4907
1140.2781	3.3779223	2.0438929	2505.6458
1141.2791	3.3812387	2.0460443	2489.6658
1142.28	3.3831792	2.0501854	2452.3579