File: datasets/am_bench_2022/raw_data/60-XY.04-3/specimen.dat
MTS793|MPT|ENU|1|2|.|/|:|1|0|0|A

Operator Information						Time:	16.700195	Sec	11/1/2021 1:29:54 PM
Operator	Nick Derimow
Project	AM Bench 2022 mini-tensile challenge
Specimen ID	60-XY.04-3
Material	PBF-L Inconel 625
Specimen Width	2.55	mm
Specimen Thickness	1.52	mm
Notes
Operator Information End

Data Acquisition						Time:	1017.6948	Sec	11/1/2021 1:46:35 PM
Time	Axial Displacement	Axial Extensometer	Axial Force
Sec	mm	mm	N
16.814697	0.00090088032	-0.00012255223	57.019249
17.715576	0.0020046278	8.9744572e-06	65.59597
18.616455	0.0034455748	2.2099772e-05	76.176903
19.517334	0.010379854	0.00013477956	91.098328
20.418213	0.0096483929	0.00018819873	103.4905
21.319092	0.011320098	0.00027038768	110.91449
22.219971	0.017211225	0.00031304598	122.94034
23.12085	0.01712722	0.00037145527	130.97394
24.021729	0.02011366	0.00046768639	141.24437
24.922607	0.02280142	0.00043253633	148.15527
25.823486	0.028441401	0.00059066195	167.02821
26.724365	0.028735215	0.00058698619	177.63425
27.625244	0.032287307	0.00078085915	193.32477
28.526123	0.033167928	0.00077612209	205.88519
29.427002	0.034810539	0.00086195912	219.1461
30.327881	0.040691268	0.00093934848	235.34007
31.22876	0.04267149	0.00097078283	250.40248
32.129639	0.04168253	0.0010630852	266.51254
33.030518	0.045338761	0.0011851664	281.65894
33.931396	0.049929291	0.0012219884	300.1528
34.832275	0.054520436	0.0013228101	326.05591
35.733154	0.051459417	0.0014524437	340.50363
36.634033	0.056201924	0.0015046038	354.21866
37.534912	0.0618583	0.0015640702	375.67493
38.435791	0.062011968	0.0016124696	390.6554
39.33667	0.06783963	0.0016949659	420.31268
40.237549	0.067664854	0.0017494331	435.06427
41.138428	0.074724481	0.0019264619	463.57025
42.039307	0.074265935	0.0020450221	479.89777
42.940186	0.078494065	0.0020654046	504.36627
43.841064	0.078721695	0.0022522057	521.8924
44.741943	0.082336128	0.0023022515	552.01257
45.642822	0.085916542	0.0023448842	564.05963
46.543701	0.087287627	0.0024045852	585.33142
47.44458	0.088304296	0.0024596313	604.26276
48.345459	0.090226784	0.0026620727	625.77228
49.246338	0.097665861	0.0027249251	659.5578
50.147217	0.0964275	0.0028322614	672.83215
51.048096	0.10244735	0.0030050653	706.02332
51.948975	0.10470996	0.0029479705	726.93835
52.849854	0.10485359	0.0031761504	750.17963
53.750732	0.10718787	0.0032616882	772.75812
54.651611	0.11251744	0.0032663762	800.13885
55.55249	0.11240598	0.003470801	826.89917
56.453369	0.11641154	0.003552069	855.16718
57.354248	0.12225764	0.0036399527	880.24945
58.255127	0.12330725	0.0037134625	901.2179
59.156006	0.1238666	0.0038453538	923.45074
60.056885	0.1267885	0.0039986758	951.25165
60.957764	0.12693213	0.0040804725	970.30322
61.858643	0.1313756	0.0041730688	993.81641
62.759521	0.13665554	0.0043620951	1029.5225
63.6604	0.13695304	0.0043985411	1046.2816
64.561279	0.14083752	0.0045917309	1079.1354
65.462158	0.14462985	0.0046057701	1098.6202
66.363037	0.14533529	0.0046731574	1120.3931
67.263916	0.15064022	0.0048189065	1148.7335
68.164795	0.15322588	0.0049421107	1173.0579
69.065674	0.15252624	0.0051168478	1193.307
69.966553	0.1529561	0.0051183272	1214.6063
70.867432	0.15986758	0.0052564912	1245.0201
71.768311	0.16201341	0.0053495024	1270.9426
72.669189	0.16315301	0.0054486403	1293.7859
73.570068	0.16480377	0.0055071642	1319.9298
74.470947	0.17150386	0.0057528224	1348.8357
75.371826	0.17099716	0.0058452343	1375.5237
76.272705	0.17461856	0.0059649111	1401.0461
77.173584	0.17793302	0.0061093559	1426.6641
78.074463	0.18358427	0.0062400675	1451.9271
78.975342	0.18363672	0.006262097	1476.2578
79.876221	0.18678913	0.0063921353	1504.6986
80.7771	0.18943222	0.0064904462	1528.5068
81.677979	0.19423579	0.006623283	1557.8483
82.578857	0.19650783	0.0066711856	1576.6976
83.479736	0.19773369	0.0067785433	1602.3945
84.380615	0.20002928	0.0069070705	1618.6105
85.281494	0.20126104	0.0070000612	1643.4653
86.182373	0.20617899	0.0071703112	1676.4564
87.083252	0.20752957	0.0071723522	1695.0543
87.984131	0.20918469	0.0074292165	1723.7858
88.88501	0.21111107	0.0074540772	1745.3243
89.785889	0.21359737	0.0075966474	1774.9637
90.686768	0.21763921	0.0077743758	1802.7665
91.587646	0.2249845	0.0078288605	1832.5227
92.488525	0.22404568	0.0080039781	1852.7109
93.389404	0.2255168	0.0080712596	1878.7931
94.290283	0.2278523	0.0082037691	1893.1064
95.191162	0.23309992	0.0082644075	1916.7228
96.092041	0.23516148	0.0083645293	1939.0237
96.99292	0.23805925	0.0085826619	1968.1
97.893799	0.23970658	0.0087057389	1996.4193
98.794678	0.24283849	0.008791225	2011.1704
99.695557	0.24554874	0.0088625848	2033.0015
100.59644	0.25082543	0.0089075789	2044.2283
101.49731	0.25356096	0.0089843255	2071.1733
102.39819	0.25539631	0.0092182299	2093.6687
103.29907	0.25846675	0.009216452	2112.0854
104.19995	0.26117516	0.0093506286	2125.0278
105.10083	0.26335129	0.0093809934	2146.105
106.00171	0.26690349	0.0094621377	2165.1941
106.90259	0.27084428	0.0095898248	2189.4387
107.80347	0.26985019	0.0097352546	2202.304
108.70435	0.27024132	0.0097718686	2215.158
109.60522	0.27575114	0.0098398989	2230.2141
110.5061	0.28020158	0.0099595711	2253.2778
111.40698	0.28366315	0.0099447118	2267.6687
112.30786	0.28398874	0.010030622	2280.8362
113.20874	0.2839832	0.010193213	2295.2209
114.10962	0.29056337	0.010197676	2308.752
115.0105	0.29201198	0.010288867	2315.832
115.91138	0.2957145	0.010471706	2334.5469
116.81226	0.29661867	0.01051802	2353.8237
117.71313	0.30275199	0.010517561	2374.5942
118.61401	0.29994443	0.010538626	2375.635
119.51489	0.30888206	0.010635387	2386.8867
120.41577	0.30737638	0.010821266	2403.2151
121.31665	0.3102946	0.010884158	2420.2517
122.21753	0.31245244	0.01090759	2428.6006
123.11841	0.31584436	0.011020312	2444.7883
124.01929	0.32183862	0.01116502	2460.5796
124.92017	0.32420409	0.011218688	2474.9536
125.82104	0.32596362	0.01125329	2476.1719
126.72192	0.32879987	0.011382411	2491.0974
127.6228	0.33223876	0.011514138	2504.8936
128.52368	0.33215803	0.011568066	2514.6606
129.42456	0.33667544	0.011634281	2524.6343
130.32544	0.34032243	0.011753722	2532.5503
131.22632	0.34217891	0.011821029	2545.2991
132.1272	0.34557191	0.011928481	2555.8276
133.02808	0.34270138	0.012008674	2558.4287
133.92896	0.34844667	0.012094649	2576.6389
134.82983	0.3528651	0.01221344	2583.6123
135.73071	0.35326257	0.012199036	2583.2986
136.63159	0.35824385	0.012257437	2593.5388
137.53247	0.36214224	0.012523173	2603.876
138.43335	0.36375496	0.012507774	2616.374
139.33423	0.3660343	0.012598203	2622.106
140.23511	0.36832616	0.01283292	2629.7019
141.13599	0.37314826	0.012956632	2640.1421
142.03687	0.37536925	0.013015149	2648.4329
142.93774	0.37742674	0.013121375	2656.4778
143.83862	0.37813789	0.013326046	2666.8403
144.7395	0.38099119	0.013421127	2679.1421
145.64038	0.38420731	0.013532202	2675.5701
146.54126	0.38882816	0.013763286	2688.0347
147.44214	0.39032182	0.013866154	2697.9106
148.34302	0.39348346	0.014026991	2701.3699
149.2439	0.39614084	0.014173756	2711.3513
150.14478	0.39709973	0.01443857	2715.8547
151.04565	0.39787319	0.014582395	2724.0801
151.94653	0.40559563	0.014887843	2737.8525
152.84741	0.40441898	0.015082126	2737.2676
153.74829	0.40751547	0.01530943	2741.5283
154.64917	0.41216519	0.01560054	2756.209
155.55005	0.41326833	0.015816594	2759.0974
156.45093	0.41672623	0.016034814	2770.3359
157.35181	0.42344922	0.016478758	2775.6904
158.25269	0.42081621	0.016770741	2783.5715
159.15356	0.42558828	0.01716393	2786.4861
160.05444	0.42920864	0.017493665	2796.7422
160.95532	0.43174765	0.017801031	2799.001
161.8562	0.43329638	0.018331774	2808.7246
162.75708	0.43671164	0.018708495	2814.9529
163.65796	0.43889967	0.019166011	2818.4519
164.55884	0.44387725	0.019585237	2823.6077
165.45972	0.44667867	0.02003721	2830.5825
166.3606	0.44825634	0.020633738	2836.7759
167.26147	0.45113829	0.021311933	2848.0088
168.16235	0.44965425	0.021800559	2846.0452
169.06323	0.45536634	0.022287596	2848.6826
169.96411	0.45619452	0.022817064	2854.8433
170.86499	0.45976287	0.023506293	2859.9229
171.76587	0.4640106	0.024122229	2863.6094
172.66675	0.47016075	0.024744952	2871.5002
173.56763	0.47091621	0.02538077	2873.1245
174.46851	0.47271407	0.025982229	2876.0757
175.36938	0.47267225	0.026618861	2881.8894
176.27026	0.4768438	0.027371457	2882.5747
177.17114	0.47727981	0.028084181	2888.8054
178.07202	0.48591197	0.028805934	2899.0354
178.9729	0.4881883	0.029607963	2907.1035
179.87378	0.4885737	0.030415094	2908.6694
180.77466	0.49002817	0.03106527	2903.4949
181.67554	0.49343857	0.031851869	2907.6768
182.57642	0.49798363	0.032680489	2917.6489
183.47729	0.49857536	0.033510584	2915.0938
184.37817	0.50345492	0.03421383	2919.6655
185.27905	0.50743103	0.035004694	2923.5151
186.17993	0.50574583	0.035804588	2927.8455
187.08081	0.51103443	0.036667839	2931.5293
187.98169	0.51494616	0.037460636	2934.4143
188.88257	0.51652884	0.038250949	2933.498
189.78345	0.51829666	0.038891528	2932.8457
190.68433	0.52275115	0.039719701	2943.1997
191.58521	0.52405775	0.040423196	2948.4304
192.48608	0.52964258	0.041459333	2956.478
193.38696	0.53050292	0.042558163	2954.4307
194.28784	0.53137183	0.043498248	2954.4226
195.18872	0.53289723	0.044522882	2963.5933
196.0896	0.5364207	0.045416731	2959.5027
196.99048	0.54071027	0.046274241	2964.0938
197.89136	0.54050803	0.047165137	2967.7908
198.79224	0.54742962	0.048144069	2970.0574
199.69312	0.54519528	0.04905073	2966.8223
200.59399	0.55070698	0.049845524	2970.2725
201.49487	0.5539698	0.050599277	2978.3977
202.39575	0.5562709	0.051677871	2986.1431
203.29663	0.5572089	0.052647922	2983.603
204.19751	0.56220537	0.053586014	2986.1094
205.09839	0.56306607	0.054412972	2985.1682
205.99927	0.5695653	0.055391349	2990.7573
206.90015	0.56949461	0.056235727	2989.6106
207.80103	0.56915742	0.057304043	2998.2678
208.7019	0.57668275	0.058325373	3001.6101
209.60278	0.57915211	0.059381202	3004.4241
210.50366	0.57952166	0.060389973	3006.9407
211.40454	0.58222604	0.061378989	3007.8035
212.30542	0.58375549	0.062456653	3007.2664
213.2063	0.58740914	0.063236721	3002.0557
214.10718	0.59045476	0.0640449	3010.7705
215.00806	0.59493405	0.06488657	3006.8503
215.90894	0.5962109	0.065782174	3016.7639
216.80981	0.59965509	0.066741936	3023.3953
217.71069	0.5999862	0.067878127	3026.4434
218.61157	0.60295445	0.068873055	3020.0447
219.51245	0.60511619	0.069667861	3016.9934
220.41333	0.60933238	0.070414625	3025.1077
221.31421	0.61533195	0.071397647	3040.1345
222.21509	0.61464411	0.072427057	3036.7473
223.11597	0.62032342	0.073495366	3038.9067
224.01685	0.621831	0.074450657	3036.1323
224.91772	0.62326741	0.075484611	3029.3203
225.8186	0.62664872	0.0763506	3040.4373
226.71948	0.63005704	0.077392347	3047.5596
227.62036	0.63173223	0.078603826	3049.4126
228.52124	0.63529855	0.079464808	3039.4346
229.42212	0.63580954	0.080530383	3046.5735
230.323	0.63821077	0.081662275	3056.0417
231.22388	0.64302593	0.082611315	3055.3406
232.12476	0.64683682	0.083685786	3058.1848
233.02563	0.6488269	0.08485534	3064.0342
233.92651	0.64867407	0.08589378	3065.1174
234.82739	0.65336132	0.086998269	3059.4451
235.72827	0.6566025	0.087712854	3057.2642
236.62915	0.65987802	0.088655755	3068.5669
237.53003	0.66004437	0.089751981	3073.1919
238.43091	0.66400772	0.091022179	3071.4954
239.33179	0.66747445	0.092091732	3075.5916
240.23267	0.67138416	0.093029819	3071.2192
241.13354	0.67156464	0.094108313	3074.1272
242.03442	0.67495471	0.095107928	3074.5181
242.9353	0.67749798	0.096116647	3073.5647
243.83618	0.68134969	0.097039193	3082.8398
244.73706	0.68442672	0.098092377	3082.9514
245.63794	0.68399888	0.098964036	3082.0862
246.53882	0.6895141	0.099884436	3086.0886
247.4397	0.69110894	0.1010446	3087.5625
248.34058	0.69633347	0.10196488	3087.8635
249.24146	0.69645947	0.10310207	3090.2937
250.14233	0.69689405	0.10397092	3091.9849
251.04321	0.70595413	0.1049128	3103.9011
251.94409	0.70439351	0.10584647	3097.9951
252.84497	0.70817906	0.10678926	3103.96
253.74585	0.71214819	0.10783532	3104.3406
254.64673	0.71366334	0.10891327	3107.2576
255.54761	0.71321934	0.11006898	3105.9519
256.44849	0.719024	0.11115332	3106.5767
257.34937	0.72309643	0.11203428	3110.908
258.25024	0.72155339	0.11301771	3106.1216
259.15112	0.7261402	0.11400492	3113.6992
260.052	0.73177975	0.11528058	3125.8679
260.95288	0.73450357	0.1164485	3119.366
261.85376	0.7352125	0.11759757	3127.5081
262.75464	0.74079198	0.11870378	3122.5859
263.65552	0.73990625	0.11965786	3123.6162
264.5564	0.74634856	0.12069083	3121.9646
265.45728	0.74766845	0.12161867	3125.3381
266.35815	0.74683827	0.12261834	3125.9727
267.25903	0.751086	0.12361348	3126.2051
268.15991	0.75318962	0.12462962	3131.5828
269.06079	0.75493544	0.1255919	3130.0735
269.96167	0.75864697	0.12659138	3137.4048
270.86255	0.76349515	0.1277767	3145.1306
271.76343	0.76637089	0.12884119	3138.5244
272.66431	0.76917642	0.12986025	3138.407
273.56519	0.76744926	0.13104177	3144.1213
274.46606	0.77113247	0.13192394	3136.7615
275.36694	0.7748	0.13291296	3148.7034
276.26782	0.77654797	0.13385381	3143.271
277.1687	0.781003	0.13487791	3148.1799
278.06958	0.7860654	0.13587363	3149.5115
278.97046	0.78774345	0.13685933	3154.49
279.87134	0.78537595	0.13784671	3149.9888
280.77222	0.79156649	0.13899197	3162.8386
281.6731	0.79441625	0.14010984	3158.1909
282.57397	0.79314661	0.14117078	3156.3833
283.47485	0.79931533	0.14224343	3160.0723
284.37573	0.80110466	0.14321944	3159.6777
285.27661	0.80377072	0.14428283	3166.387
286.17749	0.80819809	0.14512299	3163.8132
287.07837	0.8097288	0.14585055	3156.8735
287.97925	0.81120276	0.146743	3163.1924
288.88013	0.81611276	0.1478792	3171.8662
289.78101	0.81828064	0.14902547	3175.425
290.68188	0.82083768	0.15006955	3173.0295
291.58276	0.82614958	0.15114963	3180.6082
292.48364	0.82564068	0.15227388	3176.8635
293.38452	0.83172154	0.15322183	3177.8667
294.2854	0.83153713	0.15404563	3174.4365
295.18628	0.83566487	0.15519516	3180.7825
296.08716	0.8392629	0.15616395	3174.9292
296.98804	0.84075856	0.15694436	3186.0808
297.88892	0.84251821	0.15820344	3190.2173
298.78979	0.84623832	0.15923604	3189.1687
299.69067	0.8449676	0.16025127	3182.4812
300.59155	0.85027158	0.16126946	3182.2275
301.49243	0.85582733	0.16235565	3191.1726
302.39331	0.8565799	0.16344492	3195.072
303.29419	0.85789818	0.16466141	3201.0481
304.19507	0.86320001	0.16588783	3200.2197
305.09595	0.86486536	0.1670831	3201.4209
305.99683	0.86956966	0.16807897	3198.4446
306.89771	0.86863714	0.16903074	3195.8394
307.79858	0.87263864	0.17000085	3198.7432
308.69946	0.87309557	0.17084675	3199.2112
309.60034	0.87923646	0.17183858	3207.314
310.50122	0.88092434	0.17308295	3210.0889
311.4021	0.88469619	0.17426687	3205.7981
312.30298	0.88725913	0.17533256	3213.8196
313.20386	0.88696736	0.17626511	3203.5562
314.10474	0.89014351	0.17715846	3205.7886
315.00562	0.89564395	0.17804216	3213.6323
315.90649	0.89577425	0.17918193	3216.2405
316.80737	0.89960873	0.18024264	3217.9075
317.70825	0.90533024	0.18124738	3222.3645
318.60913	0.90289229	0.18207894	3215.2517
319.51001	0.90797538	0.1831141	3227.9661
320.41089	0.91080368	0.18420975	3227.4189
321.31177	0.91488832	0.18545678	3232.0535
322.21265	0.9180215	0.18635668	3221.0874
323.11353	0.91872299	0.1873603	3223.2693
324.0144	0.92240834	0.18839677	3230.8679
324.91528	0.92637724	0.18946271	3235.1096
325.81616	0.92652845	0.19043736	3231.3438
326.71704	0.93136138	0.19141984	3233.1631
327.61792	0.93260831	0.19241084	3240.5554
328.5188	0.93491983	0.19356832	3235.168
329.41968	0.93750519	0.19457237	3242.3906
330.32056	0.93999273	0.19576532	3236.1538
331.22144	0.94529873	0.19679308	3243.7349
332.12231	0.94524688	0.1977053	3242.3916
333.02319	0.94673252	0.19870917	3236.6426
333.92407	0.94982779	0.19985057	3246.1267
334.82495	0.95412326	0.2009556	3249.6648
335.72583	0.95523232	0.20194612	3245.5593
336.62671	0.96009612	0.20276994	3238.2229
337.52759	0.96122098	0.20376691	3252.678
338.42847	0.96548539	0.20496912	3255.0369
339.32935	0.96707326	0.20614925	3251.5981
340.23022	0.9706381	0.2072161	3248.0483
341.1311	0.97321826	0.20827648	3252.127
342.03198	0.97503334	0.20945564	3254.5352
342.93286	0.97728431	0.21061717	3264.5034
343.83374	0.97815961	0.21158244	3254.2012
344.73462	0.98236388	0.21247286	3259.4189
345.6355	0.98575842	0.21342346	3264.2625
346.53638	0.98858839	0.21438253	3259.6042
347.43726	0.98925757	0.21550477	3266.312
348.33813	0.99366039	0.21658887	3268.7605
349.23901	0.9972316	0.21754618	3270.8115
350.13989	0.99777478	0.21843022	3266.3137
351.04077	1.0022856	0.21957067	3272.676
351.94165	1.0048001	0.22088575	3275.4702
352.84253	1.0083855	0.2219637	3275.8435
353.74341	1.0099121	0.2229926	3279.3975
354.64429	1.0114648	0.22393335	3276.3313
355.54517	1.0127466	0.22494912	3272.4011
356.44604	1.0193861	0.22604859	3279.8818
357.34692	1.0225974	0.22702487	3278.6602
358.2478	1.0232725	0.22806624	3280.561
359.14868	1.0242343	0.22902732	3277.2644
360.04956	1.0279796	0.23001207	3281.6787
360.95044	1.0319448	0.23101996	3286.5664
361.85132	1.0348215	0.23221257	3289.8928
362.7522	1.0386542	0.23304985	3283.4832
363.65308	1.0416244	0.2339316	3285.0112
364.55396	1.0441544	0.23487283	3287.5625
365.45483	1.0465878	0.23601969	3297.3601
366.35571	1.0496798	0.23710182	3292.9092
367.25659	1.0535272	0.23815526	3301.0259
368.15747	1.0509335	0.23918535	3297.2878
369.05835	1.0574697	0.24035461	3298.959
369.95923	1.0592349	0.24155368	3302.835
370.86011	1.0630393	0.24274693	3305.0144
371.76099	1.0633708	0.24374653	3292.6462
372.66187	1.0693914	0.24473745	3302.6953
373.56274	1.0704336	0.2460174	3309.8306
374.46362	1.0717033	0.24700992	3300.9565
375.3645	1.0738442	0.24788322	3304.8489
376.26538	1.0773656	0.24901375	3311.0679
377.16626	1.0812322	0.24993198	3310.1636
378.06714	1.0859925	0.25091177	3309.4451
378.96802	1.0877738	0.25178957	3310.7874
379.8689	1.0884335	0.25281495	3315.6965
380.76978	1.0924227	0.25393334	3320.8081
381.67065	1.0924892	0.25492916	3313.5261
382.57153	1.0949295	0.25611016	3316.0227
383.47241	1.0989195	0.25731108	3324.0222
384.37329	1.1026006	0.25854155	3318.1145
385.27417	1.1055623	0.25955948	3322.2532
386.17505	1.1085781	0.26048493	3319.6243
387.07593	1.1094856	0.26145029	3319.6899
387.97681	1.112578	0.26252031	3322.4731
388.87769	1.1159701	0.26373774	3328.0066
389.77856	1.1170677	0.2647298	3330.9556
390.67944	1.1221051	0.26579237	3326.8027
391.58032	1.1215478	0.26669928	3328.4084
392.4812	1.1285112	0.26763824	3330.8098
393.38208	1.1288558	0.26861864	3328.9392
394.28296	1.1321055	0.26954836	3327.571
395.18384	1.1361848	0.27057379	3332.29
396.08472	1.1374348	0.27141398	3330.5325
396.9856	1.1419939	0.27242827	3332.5156
397.88647	1.1411686	0.27341238	3335.5837
398.78735	1.1465881	0.27455398	3339.0947
399.68823	1.1463016	0.2757197	3338.3015
400.58911	1.1515198	0.27676675	3340.5232
401.48999	1.1545103	0.27775592	3341.7683
402.39087	1.1601449	0.2788668	3349.6714
403.29175	1.159294	0.28003275	3347.8962
404.19263	1.1607796	0.28118527	3347.8755
405.09351	1.1656353	0.28227061	3347.5869
405.99438	1.1664668	0.2832264	3350.6741
406.89526	1.1718898	0.28433955	3356.5947
407.79614	1.1705159	0.28544173	3349.4768
408.69702	1.1746739	0.28663152	3353.3818
409.5979	1.1774482	0.28783098	3356.7107
410.49878	1.1834286	0.28892797	3356.28
411.39966	1.1822957	0.29004064	3352.395
412.30054	1.1879693	0.29085991	3350.9541
413.20142	1.188296	0.29187781	3356.6577
414.10229	1.1889784	0.29294741	3357.4319
415.00317	1.1931771	0.29384607	3351.8599
415.90405	1.1959449	0.29489028	3363.1501
416.80493	1.2012525	0.29593563	3368.2786
417.70581	1.2020243	0.29696336	3366.292
418.60669	1.2057896	0.29821011	3369.5015
419.50757	1.2078223	0.29918611	3361.8799
420.40845	1.2104071	0.300136	3360.9143
421.30933	1.2129374	0.30100927	3365.5112
422.21021	1.2174395	0.30213282	3371.7537
423.11108	1.2187021	0.30319282	3371.7512
424.01196	1.2193158	0.30414587	3371.032
424.91284	1.2208661	0.30524501	3380.002
425.81372	1.2277411	0.30639619	3380.9919
426.7146	1.2306125	0.30751288	3377.4263
427.61548	1.231612	0.30865929	3371.3137
428.51636	1.2354254	0.30953804	3369.4243
429.41724	1.2373312	0.31048027	3376.2292
430.31812	1.2410009	0.31148496	3380.2969
431.21899	1.2428207	0.31242949	3379.322
432.11987	1.2486908	0.3134633	3385.2056
433.02075	1.2491846	0.31465968	3386.3965
433.92163	1.2491738	0.31580123	3390.3545
434.82251	1.2526573	0.31697369	3393.1394
435.72339	1.2582673	0.31803054	3385.4014
436.62427	1.258749	0.31926411	3386.1672
437.52515	1.2619537	0.32027677	3387.2092
438.42603	1.2646525	0.3212086	3385.3037
439.3269	1.2670996	0.32210803	3388.1963
440.22778	1.2729694	0.32307521	3391.3696
441.12866	1.2730356	0.32406053	3385.22
442.02954	1.2765169	0.32511094	3396.0845
442.93042	1.2761205	0.32606789	3388.6047
443.8313	1.2809368	0.32713437	3402.519
444.73218	1.2827588	0.32824358	3403.0376
445.63306	1.2826228	0.32940173	3399.5361
446.53394	1.2897308	0.33070889	3405.1943
447.43481	1.2896343	0.33180183	3399.8081
448.33569	1.2952996	0.33277294	3398.1655
449.23657	1.2948484	0.33400697	3404.6074
450.13745	1.3020104	0.3351585	3408.6394
451.03833	1.2996776	0.33637801	3407.554
451.93921	1.3022305	0.33748394	3408.6863
452.84009	1.3098325	0.33862287	3413.4868
453.74097	1.3118002	0.33964792	3410.6687
454.64185	1.3132783	0.34077424	3410.1155
455.54272	1.3185078	0.34194681	3415.0374
456.4436	1.321527	0.34319079	3417.4551
457.34448	1.3229688	0.344116	3411.3933
458.24536	1.3251307	0.34503612	3408.4768
459.14624	1.3266578	0.34578758	3411.2695
460.04712	1.3284433	0.346623	3414.6414
460.948	1.3318913	0.34787941	3425.0774
461.84888	1.3340173	0.34903008	3420.688
462.74976	1.336141	0.3502166	3419.2163
463.65063	1.3407691	0.35128579	3421.334
464.55151	1.3424904	0.35219961	3415.8892
465.45239	1.3469629	0.35315305	3420.8674
466.35327	1.351155	0.35414305	3426.6831
467.25415	1.3514932	0.35519615	3431.1187
468.15503	1.3535463	0.35638365	3428.8408
469.05591	1.3569138	0.35745132	3426.1411
469.95679	1.3571721	0.35838872	3430.2896
470.85767	1.3630497	0.35928795	3426.3838
471.75854	1.3648367	0.36045226	3437.1528
472.65942	1.3681235	0.36152282	3431.7612
473.5603	1.3701494	0.36266616	3430.0359
474.46118	1.3714124	0.36375329	3434.8342
475.36206	1.3771414	0.36485735	3435.7646
476.26294	1.377627	0.36581314	3430.5085
477.16382	1.3809762	0.36679074	3437.4978
478.0647	1.3822726	0.36782306	3440.7588
478.96558	1.383594	0.36908108	3444.5486
479.86646	1.3888001	0.37028745	3441.8169
480.76733	1.3925188	0.37148556	3445.5371
481.66821	1.3925263	0.37262216	3442.7576
482.56909	1.3949049	0.37380147	3443.7224
483.46997	1.3988446	0.37487561	3438.429
484.37085	1.404959	0.37596166	3447.4143
485.27173	1.4033797	0.3769486	3438.6355
486.17261	1.4048837	0.37792858	3442.2107
487.07349	1.4060243	0.37911892	3448.1123
487.97437	1.4117738	0.3802003	3445.5305
488.87524	1.4159719	0.38125539	3444.1406
489.77612	1.4174963	0.38232961	3451.1304
490.677	1.4219961	0.38349155	3454.5928
491.57788	1.4254048	0.3846685	3459.8296
492.47876	1.4286956	0.385674	3457.0532
493.37964	1.4298824	0.38676867	3451.9995
494.28052	1.4331279	0.38781279	3451.4653
495.1814	1.4357605	0.38884309	3463.3635
496.08228	1.4365981	0.39007199	3458.9612
496.98315	1.4428337	0.39120683	3462.5352
497.88403	1.4453048	0.39240879	3463.605
498.78491	1.4451165	0.39338633	3462.2878
499.68579	1.4511529	0.3944678	3465.593
500.58667	1.4507954	0.39535871	3457.4761
501.48755	1.4515494	0.39628127	3462.4041
502.38843	1.4560977	0.39735752	3466.782
503.28931	1.4570476	0.39835793	3466.3477
504.19019	1.4608696	0.39949912	3466.0332
505.09106	1.4632344	0.40040481	3463.2
505.99194	1.4699579	0.40141428	3466.9231
506.89282	1.4717538	0.40247598	3473.2544
507.7937	1.4728607	0.40361333	3465.0962
508.69458	1.476925	0.40475765	3475.4214
509.59546	1.4753829	0.40576753	3465.9658
510.49634	1.4790456	0.40684614	3467.5989
511.39722	1.4839576	0.40790007	3475.7681
512.2981	1.4862987	0.40902728	3471.5449
513.19897	1.4874904	0.40999874	3477.6318
514.09985	1.4944984	0.41113645	3477.1304
515.00073	1.4960508	0.41223335	3476.9832
515.90161	1.4985191	0.41317043	3475.9263
516.80249	1.5014269	0.41437185	3485.7134
517.70337	1.5009292	0.41552374	3476.8621
518.60425	1.5069224	0.41661128	3479.5581
519.50513	1.5059433	0.41782823	3482.7786
520.40601	1.5108423	0.41885474	3480.2512
521.30688	1.5117465	0.41996261	3482.9749
522.20776	1.5151095	0.42105219	3486.4214
523.10864	1.5185045	0.42216727	3486.6306
524.00952	1.521175	0.42343259	3488.9697
524.9104	1.5249379	0.42449421	3485.8547
525.81128	1.5257552	0.42557845	3482.488
526.71216	1.5309464	0.42671734	3485.1711
527.61304	1.5291651	0.42770681	3486.9287
528.51392	1.5356359	0.42902771	3492.3264
529.41479	1.5391903	0.43014577	3491.4756
530.31567	1.5404588	0.43115693	3490.6768
531.21655	1.5411521	0.43220738	3494.2334
532.11743	1.5444912	0.43321532	3494.8435
533.01831	1.5512513	0.43430868	3498.8423
533.91919	1.5530424	0.43546113	3500.5112
534.82007	1.552559	0.43653575	3491.4106
535.72095	1.5580374	0.43748116	3496.6243
536.62183	1.5619643	0.43862757	3500.8354
537.52271	1.5628693	0.43973508	3500.7769
538.42358	1.5647911	0.44103903	3507.1833
539.32446	1.5680163	0.44209743	3506.4265
540.22534	1.5699562	0.44318822	3506.5923
541.12622	1.5738232	0.44411457	3498.6865
542.0271	1.5761809	0.44526789	3510.231
542.92798	1.5770322	0.4464218	3505.5479
543.82886	1.5808858	0.44745913	3506.1123
544.72974	1.5851277	0.44852877	3510.9617
545.63062	1.5870068	0.4497295	3516.5256
546.53149	1.5872158	0.45090234	3506.9883
547.43237	1.5914862	0.45180917	3508.1543
548.33325	1.5965272	0.45295575	3515.1294
549.23413	1.597091	0.45402089	3516.9817
550.13501	1.6032461	0.45534593	3520.1099
551.03589	1.600922	0.45646048	3513.5603
551.93677	1.6054125	0.45745841	3510.6252
552.83765	1.6094366	0.45869833	3513.4817
553.73853	1.6108931	0.4597984	3519.7949
554.6394	1.6136868	0.46100536	3513.0361
555.54028	1.6184646	0.46193501	3512.3401
556.44116	1.6180866	0.46299165	3519.2412
557.34204	1.6206735	0.46399027	3514.7651
558.24292	1.6259533	0.46506992	3515.6233
559.1438	1.6288429	0.46612197	3520.2981
560.04468	1.629527	0.46734527	3522.8311
560.94556	1.6338707	0.46883035	3531.0706
561.84644	1.6380407	0.47003821	3527.7002
562.74731	1.6380062	0.47130737	3527.5203
563.64819	1.6421713	0.47238198	3525.9299
564.54907	1.6463124	0.47342262	3528.603
565.44995	1.6420561	0.47446287	3523.7646
566.35083	1.6496664	0.47555518	3534.4868
567.25171	1.6506587	0.47678044	3531.6482
568.15259	1.6539199	0.47799671	3530.1328
569.05347	1.6564108	0.47922647	3530.05
569.95435	1.6612639	0.48025823	3531.2053
570.85522	1.6620339	0.48145831	3533.6516
571.7561	1.6681128	0.48246855	3536.46
572.65698	1.6644176	0.48362112	3528.9922
573.55786	1.6715176	0.48464018	3536.2874
574.45874	1.6763852	0.4857063	3536.5271
575.35962	1.6780962	0.48664862	3537.1597
576.2605	1.682525	0.4876458	3537.0879
577.16138	1.678038	0.48876569	3535.6729
578.06226	1.6853373	0.49016315	3547.8589
578.96313	1.6843041	0.49125883	3539.0303
579.86401	1.6886219	0.49255827	3544.7742
580.76489	1.6910322	0.49372056	3542.6738
581.66577	1.6922727	0.49488649	3539.4656
582.56665	1.6966257	0.4959082	3538.5605
583.46753	1.6988468	0.49695253	3535.2456
584.36841	1.7019916	0.49804831	3544.1665
585.26929	1.7032981	0.4990615	3543.5359
586.17017	1.7077307	0.5001381	3547.6223
587.07104	1.7122327	0.50135636	3550.1445
587.97192	1.7134331	0.50238055	3546.9419
588.8728	1.7173389	0.5036636	3558.4636
589.77368	1.7186257	0.50517488	3556.655
590.67456	1.7214634	0.50641865	3551.7178
591.57544	1.7238464	0.50762314	3550.6333
592.47632	1.7267189	0.50895381	3554.8633
593.3772	1.7284318	0.51008916	3547.2129
594.27808	1.7339602	0.51109654	3551.594
595.17896	1.7344241	0.51235008	3552.2332
596.07983	1.7394837	0.51341462	3553.0593
596.98071	1.7415254	0.51444912	3557.8228
597.88159	1.740748	0.51563388	3554.1545
598.78247	1.7441484	0.51681989	3563.0828
599.68335	1.7479504	0.51814431	3555.2246
600.58423	1.7498384	0.51921368	3552.4924
601.48511	1.7528758	0.52021009	3555.5596
602.38599	1.7561678	0.52142066	3562.876
603.28687	1.7607605	0.52260303	3565.384
604.18774	1.7615016	0.52366477	3563.6348
605.08862	1.7625705	0.52478445	3554.8083
605.9895	1.7658985	0.52581257	3562.5696
606.89038	1.7710638	0.52698779	3559.6086
607.79126	1.7747102	0.52793193	3563.2732
608.69214	1.7747002	0.52921396	3562.6621
609.59302	1.77784	0.5303027	3563.8079
610.4939	1.7815301	0.53138369	3565.3545
611.39478	1.7822288	0.53253788	3568.5349
612.29565	1.7856545	0.53375053	3570.8635
613.19653	1.7872136	0.53490782	3562.668
614.09741	1.7886713	0.53595859	3565.0225
614.99829	1.7940511	0.53707796	3567.8079
615.89917	1.798004	0.53803194	3569.3079
616.80005	1.7991781	0.5391891	3565.584
617.70093	1.8046993	0.54019725	3574.9385
618.60181	1.8067603	0.54143679	3572.4058
619.50269	1.8102336	0.54280144	3580.9006
620.40356	1.8103542	0.54389822	3573.8984
621.30444	1.813805	0.54527122	3579.5439
622.20532	1.8162173	0.54654121	3579.7437
623.1062	1.8199494	0.5477463	3579.7593
624.00708	1.8236963	0.54891896	3575.178
624.90796	1.8257715	0.55019403	3575.1135
625.80884	1.8277774	0.55158681	3587.929
626.70972	1.8294021	0.55276495	3581.3567
627.6106	1.8321505	0.55379957	3576.5188
628.51147	1.8337374	0.55500007	3576.9348
629.41235	1.8369538	0.55634403	3587.0422
630.31323	1.8432647	0.55773926	3585.155
631.21411	1.8415834	0.55906415	3592.0974
632.11499	1.8452842	0.56030387	3584.376
633.01587	1.8466736	0.56149411	3582.8745
633.91675	1.8507004	0.56255996	3581.8438
634.81763	1.8515643	0.56360358	3582.23
635.71851	1.8576428	0.56444812	3580.9099
636.61938	1.8597453	0.56549644	3582.9116
637.52026	1.8628582	0.56657702	3586.3235
638.42114	1.8609544	0.56770086	3580.1248
639.32202	1.8680068	0.56881332	3594.5198
640.2229	1.8685246	0.57000035	3587.5549
641.12378	1.8698758	0.57116443	3586.5415
642.02466	1.8772883	0.57248741	3594.4148
642.92554	1.8798181	0.57361346	3591.8408
643.82642	1.881477	0.57479441	3598.6057
644.72729	1.8797572	0.57605463	3596.6248
645.62817	1.8865436	0.57730627	3591.5149
646.52905	1.8891823	0.57835507	3584.3208
647.42993	1.8894196	0.57933718	3586.3936
648.33081	1.8942273	0.58055615	3596.3152
649.23169	1.8960948	0.58186412	3598.8999
650.13257	1.901711	0.58300298	3594.4551
651.03345	1.9014986	0.5840711	3595.6729
651.93433	1.905201	0.5853098	3600.814
652.83521	1.9079757	0.58654851	3606.2112
653.73608	1.9099844	0.5877949	3602.5894
654.63696	1.9119666	0.58908957	3596.2898
655.53784	1.9155586	0.59032899	3601.7317
656.43872	1.9195029	0.59168369	3602.2002
657.3396	1.9234546	0.59283864	3604.4963
658.24048	1.922114	0.59402132	3598.8455
659.14136	1.9247218	0.59514958	3597.6143
660.04224	1.9296728	0.5963605	3607.2893
660.94312	1.9321527	0.59757602	3601.293
661.84399	1.9342291	0.59895885	3604.877
662.74487	1.9371188	0.60034007	3604.8086
663.64575	1.9407625	0.60156012	3608.4307
664.54663	1.9454904	0.60294873	3610.7388
665.44751	1.9451132	0.60426837	3609.8875
666.34839	1.9494148	0.60546398	3603.4211
667.24927	1.9509314	0.60660398	3604.3203
668.15015	1.9525795	0.60754073	3602.116
669.05103	1.9562643	0.6087743	3608.5444
669.9519	1.9585195	0.60982537	3609.3315
670.85278	1.9614269	0.61127657	3614.2974
671.75366	1.9636873	0.61229622	3607.2817
672.65454	1.9668957	0.61355919	3614.6023
673.55542	1.9709085	0.61465114	3610.8694
674.4563	1.9735948	0.61582261	3608.4622
675.35718	1.9775046	0.6170339	3616.1299
676.25806	1.975438	0.61817545	3607.7893
677.15894	1.9808072	0.61935079	3615.384
678.05981	1.9859152	0.6207245	3621.4695
678.96069	1.9856578	0.62192577	3615.1208
679.86157	1.9878286	0.62307435	3616.3228
680.76245	1.9926742	0.62438351	3612.4861
681.66333	1.9932456	0.62545091	3613.6917
682.56421	1.9993052	0.62645012	3619.6069
683.46509	2.0019414	0.62753689	3624.4834
684.36597	2.0028164	0.62886095	3623.7815
685.26685	2.0048633	0.63019723	3626.3936
686.16772	2.0096262	0.63149768	3625.2344
687.0686	2.007086	0.63290298	3617.3562
687.96948	2.0121875	0.63407969	3616.5266
688.87036	2.0148859	0.63544548	3620.7153
689.77124	2.0203657	0.63656795	3619.1387
690.67212	2.020251	0.63770896	3619.3635
691.573	2.0267787	0.63904423	3628.7793
692.47388	2.0267494	0.64025676	3626.4846
693.37476	2.0277669	0.64139342	3622.0774
694.27563	2.0322137	0.64255804	3623.7793
695.17651	2.0363066	0.6438095	3623.6907
696.07739	2.0378726	0.64524353	3629.4009
696.97827	2.0395808	0.64664948	3632.1318
697.87915	2.0420156	0.64800018	3624.7476
698.78003	2.0462654	0.64921266	3621.877
699.68091	2.0462158	0.65028912	3621.8325
700.58179	2.0528896	0.65160733	3634.512
701.48267	2.0544825	0.65289509	3627.3972
702.38354	2.0572033	0.65436947	3629.3931
703.28442	2.0546746	0.65576255	3629.4878
704.1853	2.0617974	0.65706319	3629.1626
705.08618	2.0666513	0.65830028	3630.5823
705.98706	2.065155	0.65967834	3631.4578
706.88794	2.0719638	0.66083843	3632.5479
707.78882	2.075166	0.66217101	3633.8699
708.6897	2.0747771	0.66337878	3629.7947
709.59058	2.0769982	0.66468418	3633.1411
710.49146	2.0821915	0.66617268	3641.2412
711.39233	2.0847762	0.66782808	3641.9944
712.29321	2.0832846	0.66897446	3633.2505
713.19409	2.0897975	0.67033964	3631.6313
714.09497	2.092654	0.67121935	3629.3887
714.99585	2.0938683	0.67226207	3636.2043
715.89673	2.0963318	0.67347533	3634.2678
716.79761	2.1014724	0.67444313	3638.449
717.69849	2.1023898	0.67575097	3642.1472
718.59937	2.1051409	0.67715061	3650.8086
719.50024	2.1076047	0.6785751	3644.1392
720.40112	2.11024	0.68003321	3647.8564
721.302	2.1137352	0.68139052	3640.6318
722.20288	2.1155486	0.68271339	3640.2595
723.10376	2.1194141	0.683945	3643.6726
724.00464	2.1198282	0.6852845	3638.5649
724.90552	2.125855	0.68655783	3646.2715
725.8064	2.1263278	0.68794805	3641.3479
726.70728	2.1265397	0.68915212	3640.6479
727.60815	2.1322179	0.69040442	3642.0063
728.50903	2.1344519	0.69185752	3645.6113
729.40991	2.1363122	0.6930657	3644.0967
730.31079	2.1419659	0.69459701	3652.8137
731.21167	2.1411815	0.69594318	3642.0239
732.11255	2.1436589	0.6973539	3643.8457
733.01343	2.1473868	0.69869971	3639.5386
733.91431	2.1531103	0.70008254	3648.9072
734.81519	2.1554363	0.70136964	3647.4563
735.71606	2.1555765	0.70243597	3644.5371
736.61694	2.1629677	0.70377743	3647.8528
737.51782	2.1605575	0.70501751	3650.4399
738.4187	2.1649928	0.70624924	3647.4473
739.31958	2.1689522	0.7075488	3654.2744
740.22046	2.1702106	0.70898503	3651.7415
741.12134	2.1725962	0.7101348	3650.5706
742.02222	2.1751111	0.71145833	3648.4819
742.9231	2.1753683	0.71272308	3643.7034
743.82397	2.1807928	0.71403271	3654.1108
744.72485	2.1843634	0.71534097	3651.2549
745.62573	2.1887889	0.7165786	3649.46
746.52661	2.1855857	0.71794635	3649.7063
747.42749	2.1902988	0.71913034	3651.99
748.32837	2.193013	0.72049344	3648.2695
749.22925	2.1987963	0.72168589	3655.2034
750.13013	2.1991701	0.72310174	3654.24
751.03101	2.2018397	0.7244963	3659.0535
751.93188	2.2063341	0.72590864	3655.6436
752.83276	2.2070401	0.72732294	3658.1104
753.73364	2.2089	0.72892475	3653.3708
754.63452	2.2120357	0.73041064	3654.7466
755.5354	2.2157154	0.73187852	3654.6858
756.43628	2.2180521	0.73333728	3659.8286
757.33716	2.2214105	0.73464066	3659.9077
758.23804	2.2236528	0.73606783	3653.0808
759.13892	2.2256904	0.73735166	3653.9268
760.03979	2.230901	0.7387749	3661.2065
760.94067	2.2312503	0.7402513	3660.1702
761.84155	2.2341163	0.74143529	3653.8269
762.74243	2.2364078	0.74267447	3661.0579
763.64331	2.2392247	0.74403238	3656.7595
764.54419	2.2420857	0.74526089	3656.2441
765.44507	2.245574	0.74651688	3657.5327
766.34595	2.248435	0.74795872	3665.8176
767.24683	2.2509766	0.7493977	3667.0051
768.14771	2.2530379	0.75093639	3666.2427
769.04858	2.2584774	0.75267583	3667.5737
769.94946	2.2567053	0.75418234	3661.2014
770.85034	2.2641246	0.75576901	3663.4846
771.75122	2.2636499	0.75716472	3661.9116
772.6521	2.2674935	0.75872487	3664.3481
773.55298	2.2728913	0.7601676	3667.4832
774.45386	2.2736936	0.76154101	3662.7915
775.35474	2.2748737	0.76289517	3661.5723
776.25562	2.2780585	0.76419556	3665.3845
777.15649	2.2838445	0.76555914	3669.2629
778.05737	2.2837925	0.7668525	3672.4946
778.95825	2.285315	0.76849574	3665.4998
779.85913	2.2906849	0.76993352	3668.261
780.76001	2.2911096	0.7713781	3662.9661
781.66089	2.2968616	0.77260619	3663.0583
782.56177	2.2981009	0.77382362	3664.9639
783.46265	2.29983	0.7752313	3666.9363
784.36353	2.3022943	0.77645576	3666.822
785.2644	2.3067396	0.77792037	3672.6887
786.16528	2.3073907	0.77933717	3666.8416
787.06616	2.3108554	0.78074902	3669.7532
787.96704	2.3110054	0.7821371	3664.3699
788.86792	2.3164454	0.78338599	3666.8328
789.7688	2.3190446	0.78472394	3671.7129
790.66968	2.3183167	0.78605306	3660.7197
791.57056	2.322866	0.78734875	3668.3364
792.47144	2.3290954	0.78901452	3676.6792
793.37231	2.3296072	0.79040366	3670.7141
794.27319	2.3323951	0.79175705	3667.282
795.17407	2.3356559	0.79320031	3671.9429
796.07495	2.3383145	0.79471576	3671.7065
796.97583	2.3390391	0.79605544	3669.7615
797.87671	2.3415625	0.79761976	3673.8015
798.77759	2.3450773	0.79898089	3675.0083
799.67847	2.3460178	0.8007015	3674.575
800.57935	2.3501453	0.80236495	3673.123
801.48022	2.3540311	0.80392897	3672.9319
802.3811	2.3543038	0.80549586	3672.4714
803.28198	2.3601699	0.80699635	3673.1902
804.18286	2.3585021	0.80859756	3675.6741
805.08374	2.3605239	0.81020045	3672.541
805.98462	2.3661797	0.81165373	3671.9448
806.8855	2.3698201	0.81300271	3672.2253
807.78638	2.3723524	0.81476521	3675.3621
808.68726	2.3779299	0.81633472	3675.1614
809.58813	2.3779564	0.81769806	3674.3882
810.48901	2.3802738	0.81919283	3678.4724
811.38989	2.3843935	0.82073003	3674.5354
812.29077	2.3843606	0.82209039	3675.2383
813.19165	2.3882687	0.82350606	3679.1265
814.09253	2.3907144	0.82510954	3678.2166
814.99341	2.3948424	0.82682681	3682.3928
815.89429	2.3979118	0.82835275	3677.4941
816.79517	2.3995545	0.82972419	3676.5803
817.69604	2.4043527	0.83128363	3676.0039
818.59692	2.4065223	0.83282351	3678.3618
819.4978	2.4057293	0.83421105	3675.0264
820.39868	2.4092443	0.83570999	3678.3828
821.29956	2.4118922	0.83731157	3680.4119
822.20044	2.4139926	0.83898604	3680.6597
823.10132	2.4205844	0.84049577	3679.9321
824.0022	2.4221852	0.84171903	3675.4248
824.90308	2.4237692	0.84300655	3667.679
825.80396	2.4270449	0.84436369	3680.7214
826.70483	2.4297233	0.84599173	3680.1199
827.60571	2.4327221	0.84766829	3680.6626
828.50659	2.4348888	0.84925288	3678.8293
829.40747	2.4348652	0.85078663	3681.0779
830.30835	2.4422517	0.85229743	3677.8198
831.20923	2.4447639	0.85381651	3679.2417
832.11011	2.4456997	0.85572958	3680.7954
833.01099	2.4435575	0.85737592	3678.4041
833.91187	2.4501517	0.85876191	3671.6929
834.81274	2.4518676	0.86014456	3678.2583
835.71362	2.4567404	0.86157125	3676.1343
836.6145	2.4601955	0.86335254	3684.3923
837.51538	2.4616294	0.86497325	3680.7354
838.41626	2.4637091	0.86662424	3683.8625
839.31714	2.4669895	0.86820221	3679.6187
840.21802	2.4691055	0.87012368	3692.6641
841.1189	2.4732029	0.87185657	3682.2397
842.01978	2.4749098	0.87367725	3684.3899
842.92065	2.4786155	0.87533277	3679.8538
843.82153	2.4819155	0.87692231	3680.8359
844.72241	2.4832885	0.87827402	3680.8218
845.62329	2.4853618	0.87978595	3676.3188
846.52417	2.4893823	0.88113916	3676.1106
847.42505	2.4921181	0.88272899	3680.0989
848.32593	2.4938335	0.88455945	3692.625
849.22681	2.4990478	0.88620925	3684.8511
850.12769	2.5019004	0.8878656	3688.0034
851.02856	2.5023479	0.88938218	3682.5754
851.92944	2.5063021	0.8910023	3681.4666
852.83032	2.5096517	0.89257675	3688.1523
853.7312	2.5118034	0.89451689	3684.332
854.63208	2.5129681	0.89630908	3686.3284
855.53296	2.5151479	0.89807683	3685.4609
856.43384	2.5181279	0.89961368	3685.6233
857.33472	2.5219657	0.90117198	3680.178
858.2356	2.5234089	0.90261513	3676.8674
859.13647	2.5293019	0.90394551	3679.1431
860.03735	2.529078	0.90542126	3681.2048
860.93823	2.5341337	0.90673614	3682.9714
861.83911	2.5356634	0.90828699	3685.4216
862.73999	2.5378077	0.90986389	3685.1853
863.64087	2.5432189	0.91145164	3686.77
864.54175	2.5425017	0.91325009	3684.0203
865.44263	2.5440397	0.9151237	3684.3696
866.34351	2.5506094	0.91727823	3689.282
867.24438	2.5489151	0.91899645	3683.522
868.14526	2.5529957	0.92081982	3685.854
869.04614	2.5564528	0.92258328	3682.531
869.94702	2.560514	0.92426091	3685.4431
870.8479	2.5628614	0.92605048	3685.7522
871.74878	2.5663934	0.92795324	3688.1714
872.64966	2.5671668	0.92973548	3685.7673
873.55054	2.572753	0.93159378	3685.304
874.45142	2.5718839	0.93337405	3682.8726
875.35229	2.5758631	0.93506593	3686.947
876.25317	2.5800512	0.93687522	3684.8342
877.15405	2.5799487	0.93855959	3684.0813
878.05493	2.5829825	0.9404183	3685.6445
878.95581	2.5882449	0.9422785	3686.5613
879.85669	2.5880291	0.94423646	3681.2705
880.75757	2.5936882	0.94582713	3676.3906
881.65845	2.5937181	0.94743448	3683.4233
882.55933	2.5977561	0.94907522	3687.2622
883.46021	2.5994134	0.95088297	3690.0576
884.36108	2.6021161	0.9526878	3683.811
885.26196	2.6033931	0.95462447	3683.0281
886.16284	2.6051538	0.95656759	3685.2297
887.06372	2.6088922	0.95851725	3682.5518
887.9646	2.6132598	0.96022826	3682.5681
888.86548	2.6144223	0.96202624	3681.5735
889.76636	2.6194599	0.96384007	3678.8687
890.66724	2.6233058	0.96541321	3676.2971
891.56812	2.6231675	0.96702743	3679.8933
892.46899	2.6257961	0.96846813	3680.4121
893.36987	2.6274283	0.97040594	3687.4524
894.27075	2.6311247	0.97231442	3681.0386
895.17163	2.6341863	0.97396123	3675.0718
896.07251	2.638809	0.97582817	3682.0742
896.97339	2.6389084	0.97759807	3682.0691
897.87427	2.644136	0.97954929	3681.8616
898.77515	2.6459126	0.98160481	3689.3315
899.67603	2.6489942	0.98344702	3679.1753
900.5769	2.6497519	0.98534036	3681.3
901.47778	2.6514618	0.98740315	3680.6938
902.37866	2.6574273	0.98933411	3682.7847
903.27954	2.659354	0.99146628	3681.9063
904.18042	2.661072	0.99312842	3672.8853
905.0813	2.662889	0.99504203	3685.5676
905.98218	2.665307	0.99744195	3680.8132
906.88306	2.6689484	0.9996177	3679.8643
907.78394	2.6728508	1.0015203	3674.4026
908.68481	2.6747119	1.0033323	3676.8521
909.58569	2.6782854	1.0051416	3681.5715
910.48657	2.6811011	1.0072343	3681.3862
911.38745	2.6826706	1.0091664	3678.2092
912.28833	2.6862481	1.0109189	3675.8557
913.18921	2.6894433	1.012954	3685.2073
914.09009	2.6915746	1.0151824	3681.0757
914.99097	2.6966789	1.0171642	3680.7129
915.89185	2.6959674	1.0191691	3676.915
916.79272	2.6999633	1.0208731	3671.0886
917.6936	2.702585	1.0228106	3672.7625
918.59448	2.705199	1.024583	3677.2781
919.49536	2.7078457	1.0266591	3675.9402
920.39624	2.7120862	1.0284232	3677.2109
921.29712	2.7148845	1.0303791	3677.6675
922.198	2.7174227	1.0321959	3671.9946
923.09888	2.7179561	1.0341238	3671.7998
923.99976	2.7223372	1.0364071	3674.9387
924.90063	2.7264304	1.0384104	3676.7603
925.80151	2.7249558	1.0405022	3673.0044
926.70239	2.7290151	1.0423205	3675.8672
927.60327	2.7309299	1.0443989	3673.7769
928.50415	2.7326431	1.0462323	3668.981
929.40503	2.7392242	1.0482781	3672.5212
930.30591	2.7395606	1.0502472	3669.7642
931.20679	2.7436392	1.0521547	3672.9185
932.10767	2.7473681	1.0541704	3677.3408
933.00854	2.7476728	1.0565202	3670.0461
933.90942	2.7501459	1.0587527	3679.1377
934.8103	2.7540078	1.061307	3676.2136
935.71118	2.7569768	1.0635697	3667.9839
936.61206	2.7606978	1.0654804	3666.3022
937.51294	2.7588401	1.0674126	3665.6663
938.41382	2.7653577	1.0695502	3668.2747
939.3147	2.7662642	1.0714701	3671.8303
940.21558	2.7687616	1.0736195	3664.5049
941.11646	2.7758126	1.075247	3659.5779
942.01733	2.7746067	1.0769514	3666.3499
942.91821	2.7781475	1.0789002	3668.8086
943.81909	2.7840366	1.0811028	3665.7979
944.71997	2.7827151	1.0832659	3665.3418
945.62085	2.7880523	1.0855429	3665.8169
946.52173	2.788552	1.0879384	3663.876
947.42261	2.7927816	1.0904852	3668.4177
948.32349	2.7947359	1.0928092	3662.7561
949.22437	2.798027	1.0953529	3661.0283
950.12524	2.8017297	1.0974176	3657.2332
951.02612	2.80111	1.0997136	3658.8579
951.927	2.8030407	1.1019199	3651.1611
952.82788	2.8084791	1.1037132	3654.7795
953.72876	2.8113403	1.1058062	3658.0603
954.62964	2.8139129	1.1080139	3662.2798
955.53052	2.8172166	1.1100149	3654.178
956.4314	2.8175423	1.1120807	3649.4866
957.33228	2.8220725	1.1142129	3655.1267
958.23315	2.8224769	1.1160483	3650.5022
959.13403	2.8284407	1.1180463	3649.5366
960.03491	2.8300107	1.1200894	3652.2017
960.93579	2.8311529	1.1223916	3650.6423
961.83667	2.8349247	1.1244597	3643.7952
962.73755	2.8360589	1.1263375	3643.6482
963.63843	2.8412073	1.128702	3657.0068
964.53931	2.8427148	1.1316063	3649.9763
965.44019	2.8483896	1.1342386	3647.9924
966.34106	2.8503683	1.1363733	3641.583
967.24194	2.8502648	1.1384079	3639.7036
968.14282	2.8529663	1.140117	3633.7141
969.0437	2.8595893	1.1419744	3640.7981
969.94458	2.8590753	1.1439016	3640.4517
970.84546	2.8628631	1.1462572	3640.7227
971.74634	2.8632629	1.1482463	3635.6328
972.64722	2.866262	1.1504339	3638.2109
973.5481	2.8723505	1.1527029	3639.2158
974.44897	2.8705716	1.1549858	3633.8081
975.34985	2.8786876	1.1575757	3633.6736
976.25073	2.8774147	1.1599042	3628.3999
977.15161	2.8819876	1.162201	3631.686
978.05249	2.8821044	1.1645638	3628.6931
978.95337	2.8855662	1.1669567	3628.2695
979.85425	2.8892376	1.1691728	3623.3621
980.75513	2.8888175	1.1712978	3619.6841
981.65601	2.897243	1.173187	3624.5645
982.55688	2.8977425	1.1755785	3622.8152
983.45776	2.9012282	1.1780274	3623.5952
984.35864	2.902853	1.1806113	3624.1433
985.25952	2.906019	1.1832957	3622.6667
986.1604	2.9055202	1.1857599	3611.262
987.06128	2.9088211	1.1881927	3621.5942
987.96216	2.913681	1.1906879	3614.5151
988.86304	2.9147925	1.1928719	3608.4392
989.76392	2.9198859	1.1950126	3612.2488
990.66479	2.9173543	1.1971786	3608.4875
991.56567	2.9247048	1.1995178	3616.522
992.46655	2.9253902	1.2017628	3604.1125
993.36743	2.9286215	1.2041024	3603.5347
994.26831	2.9327109	1.206525	3605.6372
995.16919	2.9350731	1.2089776	3604.3953
996.07007	2.9382091	1.2115477	3604.2139
996.97095	2.9393904	1.213894	3598.8926
997.87183	2.9436176	1.2167745	3606.0774
998.77271	2.9455175	1.2194818	3594.4841
999.67358	2.9503953	1.221365	3587.8337
1000.5745	2.9545562	1.2233522	3597.7441
1001.4753	2.9525189	1.2254844	3588.3748
1002.3762	2.9577234	1.2275705	3586.6487
1003.2771	2.9623134	1.2296063	3590.968
1004.178	2.9626367	1.2319014	3589.8757
1005.0789	2.9615936	1.2342741	3583.1536
1005.9797	2.966815	1.2364995	3579.0293
1006.8806	2.9696646	1.2390951	3582.8513
1007.7815	2.9748232	1.2417206	3580.9617
1008.6824	2.9747999	1.2439303	3574.7742
1009.5833	2.9767764	1.2462265	3572.343
1010.4841	2.9830141	1.2485293	3575.3975
1011.385	2.9838579	1.2508096	3572.6987
1012.2859	2.9853289	1.2531545	3568.6216
1013.1868	2.989429	1.2556542	3569.4993
1014.0876	2.992888	1.2577643	3562.5232
1014.9885	2.9979382	1.2595305	3558.6304
1015.8894	2.9963493	1.2613239	3560.0251
1016.7903	3.0009747	1.2631377	3556.6409
1017.6912	3.002152	1.2650127	3559.1016
1018.592	3.0034256	1.2675681	3559.375
1019.4929	3.0070891	1.2707136	3560.198
1020.3938	3.0116868	1.2735035	3552.5339
1021.2947	3.0139406	1.275939	3548.1094
1022.1956	3.0166461	1.2782649	3548.1631
1023.0964	3.019563	1.2808254	3546.7656
1023.9973	3.0213044	1.2834067	3543.2073
1024.8982	3.0239565	1.2856841	3540.0095
1025.7991	3.0284617	1.2881426	3544.9006
1026.7	3.0294988	1.2910283	3540.4133
1027.6008	3.0316067	1.2938923	3537.5049
1028.5017	3.0375526	1.2968117	3532.1677
1029.4026	3.03617	1.2992815	3524.926
1030.3035	3.0436516	1.3017211	3528.8608
1031.2043	3.0460236	1.3039539	3523.9546
1032.1052	3.046381	1.306525	3524.8691
1033.0061	3.0489542	1.3092476	3515.4265
1033.907	3.052655	1.3116939	3518.5874
1034.8079	3.0521824	1.3143513	3513.115
1035.7087	3.057183	1.3169425	3511.0139
1036.6096	3.0590231	1.3194424	3506.8342
1037.5105	3.0625112	1.3216299	3502.9912
1038.4114	3.0625772	1.3241303	3501.1746
1039.3123	3.0687709	1.3264372	3500.5422
1040.2131	3.0673964	1.3287829	3492.3018
1041.114	3.0733984	1.3312497	3494.5068
1042.0149	3.0770094	1.3337257	3495.4441
1042.9158	3.0805616	1.3363461	3490.552
1043.8167	3.0835009	1.3393034	3493.2402
1044.7175	3.0827551	1.342008	3477.2849
1045.6184	3.0865707	1.3446299	3476.3264
1046.5193	3.0908036	1.3467705	3473.0115
1047.4202	3.0931516	1.3494439	3477.4316
1048.321	3.0954251	1.3524094	3477.3728
1049.2219	3.0956039	1.3555459	3467.439
1050.1228	3.102107	1.3581377	3464.0139
1051.0237	3.1014836	1.3606379	3456.3899
1051.9246	3.1051295	1.3632351	3459.5022
1052.8254	3.1098046	1.3660878	3455.8313
1053.7263	3.1103311	1.3689879	3454.6616
1054.6272	3.1154115	1.3722767	3450.6008
1055.5281	3.1157408	1.3749171	3443.7788
1056.429	3.1205752	1.3774219	3439.9016
1057.3298	3.1186452	1.3799182	3435.2698
1058.2307	3.1243446	1.3823276	3431.8677
1059.1316	3.1270535	1.3851988	3431.2373
1060.0325	3.1307926	1.3881869	3426.1121
1060.9333	3.1311853	1.3908786	3417.1035
1061.8342	3.1355493	1.3932753	3416.8892
1062.7351	3.1378739	1.3956219	3411.9165
1063.636	3.1397319	1.3985062	3413.8374
1064.5369	3.1430786	1.4016101	3409.7852
1065.4377	3.145911	1.4042996	3395.7041
1066.3386	3.1457553	1.406865	3398.49
1067.2395	3.1538033	1.4096053	3396.8245
1068.1404	3.1555419	1.4125285	3391.053
1069.0413	3.1589739	1.415206	3385.4075
1069.9421	3.161365	1.4179929	3380.2112
1070.843	3.1604202	1.4207686	3376.7844
1071.7439	3.1644549	1.4238198	3363.5203
1072.6448	3.1651578	1.4264967	3366.6777
1073.5457	3.1699631	1.4295144	3361.3875
1074.4465	3.1741107	1.4328891	3362.5645
1075.3474	3.1744244	1.435709	3344.5181
1076.2483	3.1793845	1.4381747	3339.1067
1077.1492	3.1795933	1.4405998	3342.3591
1078.05	3.184938	1.4436781	3340.7175
1078.9509	3.1912935	1.4468867	3333.2856
1079.8518	3.1893303	1.4497339	3325.6123
1080.7527	3.1911438	1.4520571	3315.6025
1081.6536	3.1949377	1.4552197	3320.3569
1082.5544	3.1970577	1.4579879	3312.8679
1083.4553	3.2010677	1.4610803	3304.0818
1084.3562	3.205956	1.4638926	3304.4023
1085.2571	3.2052813	1.4673462	3295.8425
1086.158	3.2083299	1.4703163	3284.9885
1087.0588	3.211632	1.4734379	3279.856
1087.9597	3.2161617	1.476904	3267.4482
1088.8606	3.216435	1.4805706	3253.6831
1089.7615	3.2224376	1.4841698	3240.5652
1090.6624	3.2235904	1.4874488	3230.3604
1091.5632	3.2238271	1.4910495	3230.8801
1092.4641	3.2260382	1.4944608	3215.5513
1093.365	3.2300112	1.4981749	3207.4517
1094.2659	3.2346945	1.5074618	3150.4634
1095.1667	3.2404346	1.5153933	3090.7625
1095.9675	3.2421081	1.5259055	3001.4707