File: datasets/am_bench_2022/raw_data/0-X.01-3/specimen.dat
MTS793|MPT|ENU|1|2|.|/|:|1|0|0|A

Operator Information						Time:	54.737549	Sec	10/12/2021 3:43:37 PM
Operator	Nick Derimow
Project	AM Bench 2022 mini-tensile challenge
Specimen ID	0-X.01-3
Material	PBF-L Inconel 625
Specimen Width	2.56	mm
Specimen Thickness	1.52	mm
Notes
Operator Information End

Data Acquisition						Time:	1055.7314	Sec	10/12/2021 4:00:18 PM
Time	Axial Displacement	Axial Extensometer	Axial Force
Sec	mm	mm	N
54.851318	-0.00029304172	-4.6460009e-05	79.889832
55.952393	0.002055777	4.9571365e-05	96.417946
57.053467	0.0065784892	6.3863532e-05	110.02777
58.154541	0.0085769445	0.00023887218	120.38327
59.255615	0.0088537522	0.00028060743	137.16675
60.356689	0.01499121	0.00031070181	151.04103
61.457764	0.017391302	0.00031152138	171.68114
62.558838	0.019089798	0.0004275665	190.29987
63.659912	0.024045648	0.00056688214	205.45198
64.760986	0.027171055	0.00047921849	225.12547
65.862061	0.034996968	0.00057840929	247.55919
66.963135	0.034710325	0.00073806237	263.04886
68.064209	0.035191562	0.00067880482	284.94427
69.165283	0.040219791	0.00085065712	309.64255
70.266357	0.042608567	0.00095770345	332.8812
71.367432	0.048031978	0.0010973919	358.26358
72.468506	0.049658965	0.0011573174	386.39896
73.56958	0.056575008	0.0013104273	407.00702
74.670654	0.057691459	0.0014671136	428.27533
75.771729	0.060785674	0.0013438809	448.6344
76.872803	0.063537918	0.0014615611	467.96481
77.973877	0.067576528	0.0016484524	496.2652
79.074951	0.068922199	0.0017240479	522.63507
80.176025	0.073998936	0.0019333174	552.01086
81.2771	0.078028679	0.0019666317	582.26245
82.378174	0.08105123	0.0021497775	605.4433
83.479248	0.08166898	0.0022206728	631.09631
84.580322	0.082939662	0.0022580777	657.96204
85.681396	0.090163603	0.0024597254	687.75629
86.782471	0.095950082	0.0025142909	717.08276
87.883545	0.099683143	0.002665573	747.39734
88.984619	0.099722892	0.002767283	767.30365
90.085693	0.10544893	0.0028435558	805.74634
91.186768	0.10622547	0.0030332899	828.41626
92.287842	0.11168966	0.0030594708	854.8443
93.388916	0.1115366	0.0032677527	886.52002
94.48999	0.11707511	0.0034654993	925.69531
95.591064	0.12043819	0.0036369336	963.5481
96.692139	0.12234506	0.0037194625	985.94012
97.793213	0.12566327	0.0038644702	1024.4427
98.894287	0.12994416	0.0040408997	1059.8965
99.995361	0.13589066	0.0042196698	1091.6047
101.09644	0.13598286	0.004326527	1114.1724
102.19751	0.14084877	0.0043995283	1150.1772
103.29858	0.14448041	0.0046168296	1184.293
104.39966	0.14588144	0.0048363837	1217.0085
105.50073	0.14939508	0.0049679843	1252.1573
106.60181	0.15172365	0.0051234737	1274.7764
107.70288	0.1551832	0.0053147376	1303.7151
108.80396	0.15855072	0.005418702	1333.4917
109.90503	0.16368319	0.0056570773	1362.4393
111.0061	0.1655141	0.0056266277	1388.767
112.10718	0.16971529	0.0057771467	1425.3167
113.20825	0.17294048	0.0061424426	1460.1766
114.30933	0.17609657	0.0061033578	1488.9583
115.4104	0.1796651	0.0063113077	1515.4978
116.51147	0.1798282	0.0065596243	1547.1149
117.61255	0.18713209	0.0067175808	1580.4114
118.71362	0.18751135	0.00694275	1603.2462
119.8147	0.19053303	0.0069738645	1639.5188
120.91577	0.1927813	0.0072896876	1669.1522
122.01685	0.19902627	0.007523072	1696.7831
123.11792	0.19826019	0.0074540409	1707.5319
124.21899	0.20557658	0.0078165792	1746.6769
125.32007	0.20830958	0.0079560149	1778.6053
126.42114	0.21092804	0.0080662845	1803.5269
127.52222	0.21536987	0.0082857618	1835.0914
128.62329	0.21870154	0.0083749788	1852.1609
129.72437	0.22505572	0.0086286515	1885.0444
130.82544	0.22442651	0.0087898001	1908.7046
131.92651	0.22775823	0.0089555876	1933.7706
133.02759	0.22970408	0.009246394	1960.4421
134.12866	0.23385917	0.0093777329	1983.1331
135.22974	0.23794076	0.009664936	2015.2531
136.33081	0.24085492	0.0098944819	2039.6398
137.43188	0.24514733	0.010103227	2062.709
138.53296	0.24849807	0.010266493	2078.8396
139.63403	0.24752627	0.010520638	2101.6934
140.73511	0.25522971	0.010743314	2124.0356
141.83618	0.26040453	0.010965111	2149.5916
142.93726	0.25977373	0.011260639	2165.0664
144.03833	0.26423657	0.011421783	2186.8733
145.1394	0.26568943	0.011717306	2200.1182
146.24048	0.27172875	0.01200488	2223.8821
147.34155	0.27235594	0.012098845	2231.6538
148.44263	0.28192076	0.012552133	2255.3435
149.5437	0.27993372	0.012682377	2268.3975
150.64478	0.28490105	0.013032745	2288.6497
151.74585	0.28741091	0.013468727	2296.0249
152.84692	0.29453349	0.013701972	2323.3669
153.948	0.29305273	0.014030982	2320.7422
155.04907	0.29831162	0.014259167	2343.1333
156.15015	0.30326235	0.014641665	2356.8765
157.25122	0.30582055	0.015010211	2366.9431
158.35229	0.31077784	0.015320338	2379.6584
159.45337	0.31183079	0.015763558	2389.0239
160.55444	0.31462014	0.01611919	2400.4868
161.65552	0.31806204	0.016298961	2408.5364
162.75659	0.32004601	0.016898789	2423.3694
163.85767	0.32451442	0.017329723	2437.2095
164.95874	0.32616809	0.017881595	2443.6086
166.05981	0.33059323	0.018298423	2451.6873
167.16089	0.33671701	0.01893313	2473.0999
168.26196	0.33695692	0.019487314	2472.2449
169.36304	0.34399498	0.020077024	2489.7786
170.46411	0.34519953	0.020749526	2496.3206
171.56519	0.34666142	0.021490969	2499.1282
172.66626	0.35066107	0.021930313	2507.1528
173.76733	0.35721281	0.022780336	2520.5415
174.86841	0.35791123	0.023431964	2526.1772
175.96948	0.36098194	0.024334954	2530.2554
177.07056	0.36760411	0.025361679	2545.9099
178.17163	0.36811101	0.02627434	2544.4241
179.27271	0.37238702	0.027348246	2548.4607
180.37378	0.37482545	0.028162204	2554.7935
181.47485	0.38153264	0.029045241	2560.9124
182.57593	0.3807115	0.030069914	2566.1394
183.677	0.38446438	0.031031391	2565.0854
184.77808	0.3909395	0.032276418	2576.248
185.87915	0.39185515	0.03328893	2576.8608
186.98022	0.39420301	0.034525629	2578.0164
188.0813	0.39706507	0.035475407	2580.2456
189.18237	0.40360391	0.036373455	2589.6514
190.28345	0.40571076	0.037691418	2594.4043
191.38452	0.40746176	0.038907405	2601.1621
192.4856	0.40952393	0.040370952	2606.3494
193.58667	0.41493279	0.042001337	2609.9048
194.68774	0.41816837	0.043353666	2608.0613
195.78882	0.42352274	0.044795088	2611.0942
196.88989	0.42450452	0.045914263	2610.2354
197.99097	0.42895517	0.047309745	2613.0095
199.09204	0.43149495	0.048651498	2620.1794
200.19312	0.43499258	0.050123863	2621.0212
201.29419	0.43891662	0.05188008	2620.8469
202.39526	0.43870169	0.053405289	2627.8423
203.49634	0.44351047	0.055046041	2630.0762
204.59741	0.44404504	0.056809455	2629.3452
205.69849	0.45223582	0.058518458	2638.7214
206.79956	0.45592529	0.060239024	2642.4692
207.90063	0.45410892	0.061756901	2634.1597
209.00171	0.45974952	0.063543595	2638.342
210.10278	0.4663842	0.065298744	2640.6902
211.20386	0.46974543	0.066606879	2644.0923
212.30493	0.47165129	0.068327338	2650.2908
213.40601	0.4748801	0.070142351	2646.8357
214.50708	0.48109233	0.071743704	2649.7932
215.60815	0.48151892	0.073471576	2655.0715
216.70923	0.48466933	0.07529331	2658.574
217.8103	0.48900309	0.077155448	2658.8516
218.91138	0.49086493	0.078502037	2648.9797
220.01245	0.49324304	0.080139287	2656.3113
221.11353	0.50101286	0.082018159	2661.6631
222.2146	0.5020926	0.083311833	2655.7629
223.31567	0.50656325	0.084947698	2667.3179
224.41675	0.50978494	0.086577758	2664.5486
225.51782	0.51116347	0.088667057	2663.019
226.6189	0.51580495	0.090112776	2662.95
227.71997	0.51642561	0.09170837	2666.0911
228.82104	0.52502155	0.093566477	2675.0105
229.92212	0.52335906	0.095091388	2666.5393
231.02319	0.52446115	0.096781023	2671.4563
232.12427	0.52968699	0.098596916	2670.7805
233.22534	0.53431952	0.10036656	2678.3396
234.32642	0.53805774	0.10233071	2682.6797
235.42749	0.54233086	0.10429911	2684.6465
236.52856	0.54482788	0.10619618	2679.0166
237.62964	0.54449576	0.10782278	2672.8398
238.73071	0.5507834	0.1095734	2684.6064
239.83179	0.55122167	0.11193976	2686.2175
240.93286	0.55853736	0.11392967	2680.0754
242.03394	0.56066144	0.11553143	2683.7532
243.13501	0.56481558	0.11737994	2690.0256
244.23608	0.56928194	0.11896908	2690.009
245.33716	0.57043362	0.12095861	2690.2131
246.43823	0.57463503	0.12334444	2699.3577
247.53931	0.58031911	0.1249045	2698.5103
248.64038	0.58439779	0.12703574	2702.1746
249.74146	0.58372045	0.12885569	2696.2598
250.84253	0.58763444	0.13059242	2699.2544
251.9436	0.58874941	0.13246165	2703.9648
253.04468	0.59567451	0.13433979	2701.2605
254.14575	0.59610862	0.13618276	2702.0471
255.24683	0.60017848	0.13810091	2701.3582
256.3479	0.60341907	0.14010388	2699.3975
257.44897	0.60641819	0.14139278	2701.2529
258.55005	0.61110055	0.14286463	2701.1096
259.65112	0.6144318	0.14453883	2711.7742
260.7522	0.6158402	0.14647886	2708.7205
261.85327	0.62195778	0.14868213	2720.406
262.95435	0.62432176	0.1506066	2710.8135
264.05542	0.6248408	0.15253331	2711.3977
265.15649	0.63065678	0.15434396	2712.1702
266.25757	0.63572222	0.15603106	2717.2461
267.35864	0.63957798	0.15787543	2712.8513
268.45972	0.64126217	0.15938969	2712.4856
269.56079	0.64334244	0.16116835	2717.0627
270.66187	0.64737403	0.16293946	2717.3125
271.76294	0.65092409	0.16462168	2717.7185
272.86401	0.65159184	0.16648462	2724.9429
273.96509	0.65419185	0.16850965	2730.1106
275.06616	0.66034532	0.17116281	2724.1216
276.16724	0.6633057	0.1732025	2724.4175
277.26831	0.66564947	0.17485034	2725.2004
278.36938	0.66903502	0.17674918	2730.8809
279.47046	0.67317867	0.17880732	2731.3403
280.57153	0.67808741	0.18081929	2723.4976
281.67261	0.6790629	0.18276046	2731.4817
282.77368	0.6851176	0.18457715	2730.3999
283.87476	0.68745083	0.18641457	2734.3127
284.97583	0.68695253	0.18784839	2725.2156
286.0769	0.69391036	0.18951963	2733.7095
287.17798	0.69534415	0.19170262	2739.5229
288.27905	0.70016968	0.19337364	2727.8601
289.38013	0.70363557	0.195188	2740.3713
290.4812	0.70335138	0.19660109	2733.1223
291.58228	0.70919424	0.1984719	2734.4309
292.68335	0.71342909	0.20048587	2742.0579
293.78442	0.71539068	0.20276207	2749.1184
294.8855	0.72033972	0.20473927	2745.8047
295.98657	0.7265625	0.20657201	2749.4807
297.08765	0.72477788	0.20824233	2742.8943
298.18872	0.73027807	0.2102389	2747.2251
299.28979	0.73404944	0.21181561	2743.4255
300.39087	0.73519069	0.21415889	2753.345
301.49194	0.73917663	0.21603796	2746.7881
302.59302	0.74165905	0.21786694	2750.9976
303.69409	0.74689984	0.21970254	2752.9458
304.79517	0.74888074	0.2215735	2750.1597
305.89624	0.75251532	0.22366865	2753.603
306.99731	0.75387102	0.22570522	2757.7224
308.09839	0.75910676	0.22809336	2756.8157
309.19946	0.76016849	0.22982845	2750.1956
310.30054	0.76758093	0.23179127	2760.856
311.40161	0.77053481	0.23401278	2763.3818
312.50269	0.76987737	0.23552562	2754.032
313.60376	0.77841997	0.2372656	2755.9717
314.70483	0.7796284	0.23899788	2762.9954
315.80591	0.78409553	0.24055673	2761.3481
316.90698	0.78695458	0.24268626	2764.8623
318.00806	0.78532839	0.24460632	2764.3071
319.10913	0.79095626	0.24647491	2758.2859
320.21021	0.79508048	0.24848533	2769.4631
321.31128	0.79830194	0.25029415	2776.3096
322.41235	0.80353886	0.25223276	2771.2344
323.51343	0.80682367	0.25410283	2772.4082
324.6145	0.80945975	0.25603029	2773.7075
325.71558	0.81161946	0.25795153	2769.0137
326.81665	0.81705457	0.25976524	2778.2507
327.91772	0.81968904	0.26146072	2773.7881
329.0188	0.82216555	0.26310182	2773.4409
330.11987	0.82406336	0.26451874	2770.9971
331.22095	0.83055794	0.26608083	2778.823
332.32202	0.83340573	0.2679705	2778.1299
333.4231	0.83709228	0.26989174	2785.4971
334.52417	0.83936101	0.27182055	2786.1802
335.62524	0.83977777	0.2737183	2779.7766
336.72632	0.84425664	0.27556956	2784.0857
337.82739	0.84565133	0.27758288	2788.438
338.92847	0.8495028	0.27981582	2784.1885
340.02954	0.85548121	0.28156736	2787.4216
341.13062	0.86106998	0.28360295	2794.77
342.23169	0.86275274	0.28535143	2788.0371
343.33276	0.86562258	0.28726155	2793.7622
344.43384	0.86717135	0.28936294	2788.0776
345.53491	0.873501	0.29102442	2792.0925
346.63599	0.87466288	0.29310581	2792.5269
347.73706	0.87629628	0.29501691	2787.5132
348.83813	0.88147521	0.29692274	2796.5291
349.93921	0.88341248	0.29924753	2800.3462
351.04028	0.88610494	0.30082279	2789.4312
352.14136	0.89256728	0.30285648	2802.1497
353.24243	0.8945598	0.30480075	2798.311
354.34351	0.89873546	0.30651033	2801.9834
355.44458	0.9009192	0.30841219	2799.9648
356.54565	0.90729594	0.31011519	2799.5029
357.64673	0.90758872	0.31166029	2799.1221
358.7478	0.91350406	0.31365791	2806.9731
359.84888	0.91192454	0.31522688	2798.8589
360.94995	0.91784054	0.31740537	2805.5776
362.05103	0.92096096	0.31909394	2809.6262
363.1521	0.92255414	0.32114875	2809.8828
364.25317	0.92533165	0.32279336	2806.8279
365.35425	0.92905366	0.32435533	2802.4182
366.45532	0.93525356	0.32596219	2809.071
367.5564	0.93681604	0.32772031	2809.8716
368.65747	0.93933886	0.32939863	2811.8767
369.75854	0.945364	0.33156371	2822.5889
370.85962	0.94577438	0.33359838	2820.1313
371.96069	0.95186883	0.33584517	2823.9441
373.06177	0.95471805	0.33778176	2820.3755
374.16284	0.95507473	0.33974251	2816.4934
375.26392	0.96010351	0.34148961	2816.9094
376.36499	0.9626013	0.3433111	2817.3992
377.46606	0.96728444	0.3451128	2819.5811
378.56714	0.97027236	0.34702876	2826.4351
379.66821	0.97294509	0.34920964	2825.5581
380.76929	0.9769851	0.3508462	2819.9744
381.87036	0.98084992	0.35272104	2827.418
382.97144	0.98371798	0.35483444	2831.4968
384.07251	0.98844659	0.35703495	2835.4919
385.17358	0.98894054	0.35898456	2826.0657
386.27466	0.99433881	0.36061937	2826.1428
387.37573	0.99585164	0.36218193	2824.1792
388.47681	0.99714285	0.36408418	2828.6719
389.57788	1.0045277	0.36582941	2837.1484
390.67896	1.0064423	0.36781237	2834.2124
391.78003	1.0112531	0.36978424	2832.856
392.8811	1.0164417	0.37160426	2837.925
393.98218	1.0169272	0.37326229	2834.9146
395.08325	1.0208728	0.3752161	2844.1321
396.18433	1.0239818	0.37725812	2840.6331
397.2854	1.0250672	0.37920365	2839.6257
398.38647	1.0283359	0.38106152	2842.3711
399.48755	1.0318614	0.38289815	2836.2366
400.58862	1.0353065	0.38453972	2839.9004
401.6897	1.037733	0.38619488	2840.4412
402.79077	1.0420464	0.38793078	2835.4568
403.89185	1.0490327	0.38973451	2851.0979
404.99292	1.0482258	0.39129332	2842.0439
406.09399	1.0536497	0.39330474	2849.1255
407.19507	1.0584143	0.39525688	2850.1326
408.29614	1.0595369	0.39690733	2848.8489
409.39722	1.0629258	0.39909267	2855.4995
410.49829	1.0664017	0.40120882	2856.4219
411.59937	1.0713893	0.40310895	2856.6782
412.70044	1.0705882	0.40490153	2851.7502
413.80151	1.0728781	0.40650707	2844.9543
414.90259	1.0785872	0.40818423	2855.5818
416.00366	1.0819446	0.40994602	2848.5276
417.10474	1.0861653	0.4117839	2858.9329
418.20581	1.0879524	0.41407746	2857.3669
419.30688	1.0928787	0.41636083	2858.2092
420.40796	1.0965974	0.41826513	2864.4092
421.50903	1.0975738	0.42022419	2858.4163
422.61011	1.1015528	0.42198071	2857.231
423.71118	1.1057137	0.42379168	2861.0901
424.81226	1.1112139	0.42566907	2867.5405
425.91333	1.1104528	0.42755571	2864.0032
427.0144	1.1162665	0.42928603	2863.427
428.11548	1.1172215	0.43099207	2866.7654
429.21655	1.1221802	0.43275449	2873.2234
430.31763	1.1278416	0.43469173	2869.2358
431.4187	1.1297953	0.43652445	2874.5728
432.51978	1.1335531	0.43846601	2868.6355
433.62085	1.1344221	0.44014451	2866.5044
434.72192	1.1415598	0.44199663	2879.509
435.823	1.1433375	0.44405508	2875.7229
436.92407	1.1459018	0.44572082	2873.3364
438.02515	1.1473348	0.44725624	2875.158
439.12622	1.1519532	0.44886953	2875.8994
440.22729	1.1537557	0.45086211	2881.7324
441.32837	1.1601561	0.45275879	2883.01
442.42944	1.1613545	0.45449167	2880.8433
443.53052	1.1659775	0.45642638	2882.3579
444.63159	1.1713361	0.45832279	2887.5454
445.73267	1.1724874	0.46029496	2888.7051
446.83374	1.1736562	0.46218327	2883.2664
447.93481	1.1801888	0.46400979	2886.4937
449.03589	1.1788555	0.46601987	2885.6973
450.13696	1.1847649	0.46740913	2883.7009
451.23804	1.1858116	0.46914345	2890.3657
452.33911	1.1907097	0.47109759	2890.2593
453.44019	1.1962268	0.47335097	2895.429
454.54126	1.1965827	0.47542137	2891.821
455.64233	1.203445	0.47729298	2891.5779
456.74341	1.2063808	0.47940451	2897.9612
457.84448	1.2089267	0.48100781	2894.1301
458.94556	1.2096905	0.48287556	2890.5962
460.04663	1.2134551	0.48479721	2897.4998
461.14771	1.2205684	0.48629269	2896.574
462.24878	1.2229306	0.48803747	2899.2615
463.34985	1.2256472	0.48973364	2904.1353
464.45093	1.227646	0.49151039	2896.7861
465.552	1.229982	0.49359331	2901.5281
466.65308	1.2361559	0.49548709	2904.5527
467.75415	1.238061	0.49728283	2905.0803
468.85522	1.2414941	0.49911025	2904.6653
469.9563	1.2435706	0.5010277	2905.4775
471.05737	1.2474791	0.50289369	2906.6624
472.15845	1.2523031	0.50437695	2901.4653
473.25952	1.2540429	0.50623304	2910.9763
474.3606	1.257086	0.50790989	2904.5894
475.46167	1.2621696	0.50976557	2917.6553
476.56274	1.2631629	0.51153946	2912.3484
477.66382	1.2702332	0.51339972	2912.8186
478.76489	1.2710856	0.51513535	2912.3118
479.86597	1.2732908	0.51689994	2913.2004
480.96704	1.2771158	0.51885325	2918.2627
482.06812	1.2779711	0.52056134	2912.9238
483.16919	1.2843838	0.52235776	2917.3975
484.27026	1.2878106	0.52444899	2918.9041
485.37134	1.2914361	0.52617162	2928.7036
486.47241	1.2957549	0.5281769	2919.1138
487.57349	1.2974819	0.52976203	2917.5217
488.67456	1.3006616	0.5315851	2922.7849
489.77563	1.3068161	0.53335959	2927.3784
490.87671	1.307552	0.53536695	2922.7505
491.97778	1.3132508	0.53733033	2923.7876
493.07886	1.3138366	0.539271	2929.0649
494.17993	1.3170228	0.54101831	2929.126
495.28101	1.3231217	0.54339981	2935.6204
496.38208	1.3221576	0.54542542	2923.6182
497.48315	1.3250775	0.54715449	2923.7776
498.58423	1.3288854	0.54905462	2928.4768
499.6853	1.3311695	0.55072987	2932.2134
500.78638	1.3342938	0.55249256	2932.2048
501.88745	1.3407505	0.55425847	2940.9189
502.98853	1.3445886	0.55609441	2941.321
504.0896	1.3454218	0.55838722	2935.6606
505.19067	1.3500643	0.56007719	2938.5095
506.29175	1.3545384	0.56189597	2941.1365
507.39282	1.3560055	0.56361562	2931.1296
508.4939	1.3604856	0.56521803	2943.3118
509.59497	1.361637	0.56698376	2934.7854
510.69604	1.3662574	0.56908828	2938.0808
511.79712	1.3675567	0.57078379	2938.7405
512.89819	1.3715072	0.5725069	2941.686
513.99927	1.3776815	0.57422292	2945.071
515.10034	1.3826214	0.57583076	2945.1846
516.20142	1.3864018	0.57755101	2946.3125
517.30249	1.3875039	0.57917106	2946.8635
518.40356	1.3899312	0.58101529	2953.1189
519.50464	1.3943037	0.58308327	2954.2319
520.60571	1.3953927	0.58498722	2950.4939
521.70679	1.3993435	0.58693987	2949.561
522.80786	1.4014891	0.58866221	2946.2178
523.90894	1.4078792	0.59047216	2956.637
525.01001	1.4093634	0.59209698	2951.3997
526.11108	1.4116074	0.59431446	2955.0925
527.21216	1.4161079	0.59609985	2949.2119
528.31323	1.4171823	0.59816593	2955.8564
529.41431	1.4235442	0.60011077	2954.2341
530.51538	1.4233985	0.60208404	2955.1458
531.61646	1.4291552	0.60416001	2966.3516
532.71753	1.432037	0.60598266	2957.4497
533.8186	1.4374561	0.60812253	2960.9207
534.91968	1.4396482	0.61011654	2962.0911
536.02075	1.4405987	0.61148345	2955.8242
537.12183	1.4461911	0.61353862	2965.9839
538.2229	1.4496198	0.61532032	2958.2688
539.32397	1.450048	0.61676437	2960.7383
540.42505	1.4556762	0.61847031	2964.0083
541.52612	1.457463	0.62018383	2967.1597
542.6272	1.4644662	0.62198913	2965.125
543.72827	1.4679475	0.62359411	2962.021
544.82935	1.4659946	0.62531418	2964.863
545.93042	1.4711977	0.62668806	2960.7107
547.03149	1.4772117	0.62829196	2979.5566
548.13257	1.4784693	0.63025832	2971.7683
549.23364	1.4813174	0.63201553	2968.489
550.33472	1.4832664	0.63392675	2971.0825
551.43579	1.488896	0.6357848	2972.0076
552.53687	1.4913336	0.63759184	2976.49
553.63794	1.4965421	0.63933736	2975.6511
554.73901	1.4999645	0.64128089	2973.4375
555.84009	1.5009816	0.64282024	2969.9529
556.94116	1.504599	0.64456046	2975.5239
558.04224	1.5123428	0.64655894	2985.9512
559.14331	1.5123316	0.64832902	2976.9941
560.24438	1.5164198	0.65039074	2989.8555
561.34546	1.5181037	0.65243691	2980.8076
562.44653	1.519315	0.65413332	2980.7991
563.54761	1.5257802	0.65575927	2981.9722
564.64868	1.5301182	0.65778708	2995.6489
565.74976	1.5295051	0.65966475	2982.1519
566.85083	1.5353677	0.66167563	2988.0164
567.9519	1.5412822	0.66336405	2987.2664
569.05298	1.5419812	0.66530436	2988.6511
570.15405	1.5465848	0.66747648	2996.6013
571.25513	1.5492765	0.66951978	2990.5757
572.3562	1.5536269	0.67141193	2990.689
573.45728	1.5576952	0.67325109	2992.0674
574.55835	1.5583981	0.67487252	2992.3147
575.65942	1.5581048	0.67647219	2983.5505
576.7605	1.5654793	0.67812741	2990.0103
577.86157	1.5662923	0.67957669	2991.4761
578.96265	1.574392	0.68147004	3000.3813
580.06372	1.5738868	0.68289113	2990.3828
581.16479	1.5785586	0.68501192	2997.718
582.26587	1.5821859	0.68670428	3000.9412
583.36694	1.5837448	0.68851686	3004.4404
584.46802	1.5901775	0.69046837	3000.3142
585.56909	1.5905517	0.69215399	2998.8142
586.67017	1.5940049	0.6940394	3002.8711
587.77124	1.5981513	0.69590646	3004.3438
588.87231	1.6022228	0.6975702	3005.042
589.97339	1.6081574	0.69929099	3006.5972
591.07446	1.6102946	0.70105433	3013.9067
592.17554	1.6114348	0.70276856	3004.2578
593.27661	1.6116304	0.70473593	3001.947
594.37769	1.6163535	0.70677453	3008.6357
595.47876	1.6221207	0.70850992	3006.3821
596.57983	1.6250278	0.71039706	3011.3784
597.68091	1.6271715	0.71225423	3011.1704
598.78198	1.6313596	0.71441364	3017.238
599.88306	1.6334326	0.71632135	3007.7639
600.98413	1.6397465	0.71808738	3015.9177
602.08521	1.6450173	0.719823	3017.8206
603.18628	1.6459095	0.72179365	3016.5171
604.28735	1.6467432	0.72338855	3020.3406
605.38843	1.651033	0.72516561	3009.5171
606.4895	1.6535263	0.72687507	3019.2686
607.59058	1.6579244	0.72875929	3017.0098
608.69165	1.6596154	0.73080683	3020.9751
609.79272	1.6634108	0.73237419	3021.7495
610.8938	1.6677063	0.73435622	3021.3232
611.99487	1.6723496	0.73633349	3023.0083
613.09595	1.6735724	0.73825318	3021.3503
614.19702	1.6780746	0.7399407	3020.8511
615.2981	1.6831682	0.74135071	3028.3706
616.39917	1.683877	0.74281836	3017.0437
617.50024	1.6877624	0.74431247	3025.0984
618.60132	1.6884602	0.74575198	3019.2622
619.70239	1.6911213	0.74771065	3023.1816
620.80347	1.6970452	0.7493965	3026.458
621.90454	1.7032374	0.75144994	3038.7424
623.00562	1.7061254	0.75353199	3035.3401
624.10669	1.7101778	0.75506151	3026.1702
625.20776	1.7134126	0.75679547	3034.0205
626.30884	1.7095839	0.75885516	3025.9373
627.40991	1.7183535	0.76056182	3028.0161
628.51099	1.7207857	0.76222348	3030.4929
629.61206	1.7215751	0.76407081	3032.1013
630.71313	1.7260327	0.76613677	3037.0701
631.81421	1.7300401	0.76785761	3029.6252
632.91528	1.7339891	0.76979107	3041.7876
634.01636	1.7361741	0.77190661	3042.4241
635.11743	1.7386807	0.77400106	3036.7832
636.21851	1.7446518	0.7757526	3037.7136
637.31958	1.7462226	0.77733439	3038.4604
638.42065	1.7503538	0.77922279	3040.6118
639.52173	1.7515677	0.780747	3033.2639
640.6228	1.7569764	0.78239113	3037.115
641.72388	1.7582235	0.78424042	3039.0793
642.82495	1.7638187	0.78588414	3044.6016
643.92603	1.7663902	0.78818971	3047.3276
645.0271	1.7692126	0.78986514	3038.1946
646.12817	1.7728184	0.79181844	3051.676
647.22925	1.7757102	0.79382229	3043.7402
648.33032	1.7821779	0.79545671	3046.5916
649.4314	1.7828313	0.79730755	3045.6541
650.53247	1.7850804	0.79911107	3045.1125
651.63354	1.7878724	0.80070722	3049.4053
652.73462	1.794757	0.80279601	3043.2563
653.83569	1.7950135	0.80448794	3042.4832
654.93677	1.7993332	0.80641359	3050.0466
656.03784	1.8009537	0.80804521	3044.7876
657.13892	1.8033948	0.80983388	3050.9893
658.23999	1.8088782	0.81195509	3055.0356
659.34106	1.8141412	0.81369531	3055.4648
660.44214	1.8178477	0.81542134	3054.8101
661.54321	1.81936	0.81723744	3057.321
662.64429	1.8200324	0.81878185	3049.2319
663.74536	1.8246611	0.82020164	3054.2419
664.84644	1.8283088	0.82195085	3057.9712
665.94751	1.8325775	0.82372737	3060.0005
667.04858	1.8376361	0.82579303	3064.6052
668.14966	1.8379296	0.82745284	3057.6997
669.25073	1.8428823	0.82912439	3058.8132
670.35181	1.8452816	0.83091712	3062.0071
671.45288	1.8510721	0.83317626	3064.1765
672.55396	1.8524609	0.83496737	3061.2751
673.65503	1.8561403	0.83688909	3059.4521
674.7561	1.8607872	0.83864164	3066.0386
675.85718	1.8652928	0.84055585	3068.7239
676.95825	1.8638209	0.84262472	3068.3333
678.05933	1.8687885	0.84466815	3070.5063
679.1604	1.8735837	0.84636259	3056.8293
680.26147	1.876961	0.84812427	3064.3008
681.36255	1.8786747	0.84998959	3071.9556
682.46362	1.8792968	0.85164446	3062.8389
683.5647	1.8840551	0.85346782	3070.1121
684.66577	1.8887025	0.85537511	3070.5413
685.76685	1.8959038	0.85725969	3070.6948
686.86792	1.8933659	0.85888195	3068.874
687.96899	1.8982043	0.86055952	3065.9451
689.07007	1.9028331	0.86218774	3074.3955
690.17114	1.9068063	0.86382055	3077.7517
691.27222	1.9078468	0.86578876	3070.9761
692.37329	1.9131964	0.86775613	3082.1719
693.47437	1.9142684	0.86967331	3074.3738
694.57544	1.9167411	0.8715232	3072.927
695.67651	1.9217793	0.87343389	3076.7612
696.77759	1.9246173	0.87509048	3078.2153
697.87866	1.9283614	0.87670797	3075.0024
698.97974	1.932831	0.87811321	3077.3064
700.08081	1.9342049	0.8799246	3083.6812
701.18188	1.9370807	0.88183296	3075.3438
702.28296	1.9426392	0.88377303	3077.9094
703.38403	1.9450496	0.88540775	3078.2935
704.48511	1.9487561	0.88742095	3086.5203
705.58618	1.9495416	0.88930476	3082.3086
706.68726	1.9540387	0.89106566	3078.2488
707.78833	1.9544319	0.89332789	3084.7957
708.8894	1.9608804	0.89529741	3090.3765
709.99048	1.9703804	0.89722884	3087.8274
711.09155	1.9649429	0.89882684	3079.8416
712.19263	1.9706672	0.90066624	3087.7202
713.2937	1.9757948	0.90235972	3086.6782
714.39478	1.9747778	0.90406251	3085.4224
715.49585	1.9812012	0.90599763	3090.6055
716.59692	1.9846933	0.90783602	3083.7991
717.698	1.9903276	0.90990651	3093.9673
718.79907	1.9934908	0.91158462	3093.6414
719.90015	1.9931587	0.91351819	3095.1216
721.00122	1.9969057	0.91539824	3090.8816
722.10229	1.9992549	0.91721982	3085.2983
723.20337	2.0011799	0.91872126	3086.5784
724.30444	2.0069151	0.92074102	3101.1465
725.40552	2.012073	0.92270994	3096.8459
726.50659	2.0152025	0.9245429	3094.3655
727.60767	2.0172203	0.92618293	3088.7314
728.70874	2.0206935	0.9277032	3094.8726
729.80981	2.0264034	0.92976803	3102.6309
730.91089	2.0278862	0.93181092	3106.6897
732.01196	2.0328624	0.93349087	3097.45
733.11304	2.0329618	0.93533063	3093.3203
734.21411	2.0364528	0.93706107	3099.7556
735.31519	2.041136	0.93902886	3101.731
736.41626	2.0446618	0.94067448	3099.03
737.51733	2.0484593	0.94235271	3096.7986
738.61841	2.0532734	0.94420731	3103.696
739.71948	2.0531044	0.94636685	3105.7461
740.82056	2.0577738	0.94862729	3108.6804
741.92163	2.0580232	0.95078379	3103.7026
743.02271	2.0646603	0.95271742	3107.5911
744.12378	2.0661433	0.95450574	3100.9578
745.22485	2.0702271	0.95589662	3094.1543
746.32593	2.0719702	0.95754129	3100.4851
747.427	2.0770798	0.9592483	3102.6619
748.52808	2.0803468	0.96100193	3111.2869
749.62915	2.0872061	0.963112	3108.4167
750.73022	2.0887871	0.96475869	3111.4412
751.8313	2.0909736	0.96670508	3115.8938
752.93237	2.0949216	0.96832222	3103.2908
754.03345	2.0958264	0.97021824	3111.99
755.13452	2.1019111	0.97215497	3107.593
756.2356	2.1038947	0.97393239	3115.5649
757.33667	2.1058581	0.97555029	3104.3862
758.43774	2.1090734	0.97717619	3103.2344
759.53882	2.1153364	0.97855937	3105.1875
760.63989	2.1170139	0.98038518	3118.2478
761.74097	2.1168144	0.98249018	3117.8245
762.84204	2.1215	0.98444301	3116.4128
763.94312	2.1246274	0.98634541	3114.4319
765.04419	2.1297867	0.98842347	3118.1985
766.14526	2.1347089	0.99043512	3116.4209
767.24634	2.1383109	0.99240226	3118.7896
768.34741	2.1421888	0.99421245	3114.9609
769.44849	2.1423013	0.99595463	3114.8762
770.54956	2.1496317	0.99761164	3119.2839
771.65063	2.1501248	0.99959129	3117.8708
772.75171	2.1557188	1.0011158	3121.8813
773.85278	2.1585307	1.0030652	3125.8516
774.95386	2.1597526	1.0052388	3122.688
776.05493	2.1628773	1.0068748	3116.5613
777.15601	2.165669	1.0089927	3121.6189
778.25708	2.1709085	1.0110884	3125.2683
779.35815	2.1749136	1.0131081	3128.6025
780.45923	2.1749854	1.0150021	3123.5076
781.5603	2.1809075	1.0167712	3133.7788
782.66138	2.1802924	1.0189743	3122.2158
783.76245	2.1866093	1.0208616	3119.9277
784.86353	2.1903636	1.0227324	3128.9082
785.9646	2.1941037	1.0245656	3126.2832
787.06567	2.1953907	1.0262547	3120.0178
788.16675	2.1972318	1.0281959	3125.8508
789.26782	2.2020698	1.0301584	3132.5591
790.3689	2.2012658	1.0319388	3125.2026
791.46997	2.210813	1.0337629	3126.4695
792.57104	2.2115705	1.0354263	3123.8164
793.67212	2.2146966	1.0369784	3128.0105
794.77319	2.2213545	1.0386058	3125.3828
795.87427	2.2218235	1.0405542	3132.137
796.97534	2.2273662	1.0424683	3134.1602
798.07642	2.2305031	1.0443323	3131.5935
799.17749	2.2316208	1.0460246	3129.4958
800.27856	2.2373772	1.04774	3135.3423
801.37964	2.2423675	1.0497917	3135.2378
802.48071	2.2418678	1.0514914	3135.928
803.58179	2.2459521	1.0533087	3129.5076
804.68286	2.2466598	1.0557112	3141.9131
805.78394	2.2519405	1.0578039	3139.8123
806.88501	2.2582235	1.0602441	3143.3972
807.98608	2.2600451	1.062327	3133.9409
809.08716	2.2609432	1.0643992	3137.8818
810.18823	2.2636657	1.0664823	3137.7163
811.28931	2.271585	1.0683542	3140.4585
812.39038	2.2694802	1.0702224	3140.0935
813.49146	2.2738318	1.0722234	3136.8579
814.59253	2.2812188	1.0741469	3138.1968
815.6936	2.281764	1.0762827	3135.9053
816.79468	2.2849569	1.0779028	3140.3435
817.89575	2.2909892	1.0794947	3141.1489
818.99683	2.2913437	1.0814999	3140.7043
820.0979	2.295331	1.0835075	3147.3169
821.19897	2.2982345	1.0854251	3147.7021
822.30005	2.3001065	1.0874226	3142.054
823.40112	2.3070428	1.0896081	3147.959
824.5022	2.3073478	1.0913562	3142.9443
825.60327	2.3093696	1.0931098	3134.6392
826.70435	2.3150561	1.0948635	3141.8157
827.80542	2.3186252	1.0968108	3144.967
828.90649	2.321872	1.0988752	3154.8528
830.00757	2.3268614	1.1006622	3147.2026
831.10864	2.3278656	1.1024125	3144.22
832.20972	2.3315756	1.1041391	3144.9963
833.31079	2.3343356	1.1055236	3141.3979
834.41187	2.3392613	1.1074002	3152.1538
835.51294	2.3424933	1.1093621	3151.8303
836.61401	2.3448565	1.1114048	3150.4316
837.71509	2.3491731	1.1135899	3150.4441
838.81616	2.3514528	1.1154076	3150.5242
839.91724	2.3552327	1.1175978	3153.6672
841.01831	2.3572714	1.1191375	3143.3386
842.11938	2.3610952	1.1208446	3144.6238
843.22046	2.3650386	1.1227921	3148.5774
844.32153	2.3692522	1.1244733	3149.3599
845.42261	2.3720226	1.1266558	3150.5422
846.52368	2.3723476	1.1288757	3152.2727
847.62476	2.378264	1.1310166	3157.1907
848.72583	2.3802218	1.1333531	3154.6609
849.8269	2.3838544	1.1355267	3151.7559
850.92798	2.3851097	1.1374633	3149.4749
852.02905	2.3923514	1.1393821	3152.3823
853.13013	2.3968801	1.1414242	3158.8755
854.2312	2.3989837	1.1433631	3152.5557
855.33228	2.4030416	1.145026	3154.7529
856.43335	2.4044976	1.1468912	3155.7825
857.53442	2.4088547	1.148867	3155.6426
858.6355	2.4119756	1.1510108	3159.4087
859.73657	2.4149964	1.1530896	3160.6016
860.83765	2.4164944	1.15537	3159.47
861.93872	2.4205008	1.1575428	3156.5122
863.03979	2.42539	1.1596382	3158.866
864.14087	2.4298825	1.1615709	3160.1318
865.24194	2.427937	1.1633428	3153.522
866.34302	2.4349644	1.1649975	3152.9099
867.44409	2.4355202	1.1665975	3155.4036
868.54517	2.4393203	1.1688125	3169.6807
869.64624	2.4443684	1.1706524	3153.1079
870.74731	2.4479442	1.172742	3161.738
871.84839	2.4522355	1.1746963	3160.686
872.94946	2.4537377	1.1769512	3162.1409
874.05054	2.4571447	1.1789647	3165.1052
875.15161	2.4621902	1.1807221	3162.4648
876.25269	2.464761	1.1826861	3165.8735
877.35376	2.4675572	1.1844753	3169.0964
878.45483	2.4694316	1.1867046	3167.5454
879.55591	2.4734697	1.1885967	3161.6228
880.65698	2.4791746	1.1903186	3161.9619
881.75806	2.4807801	1.1923752	3167.7173
882.85913	2.4820156	1.1940221	3164.2764
883.96021	2.4873002	1.1961986	3170.5042
885.06128	2.4906363	1.1985742	3165.0813
886.16235	2.4900451	1.2004644	3159.6384
887.26343	2.4992523	1.202507	3169.3196
888.3645	2.4959693	1.2043365	3161.9109
889.46558	2.5048947	1.2064942	3168.3733
890.56665	2.5080447	1.2084056	3168.0295
891.66772	2.5097432	1.2103915	3167.5605
892.7688	2.5145342	1.2126212	3173.5818
893.86987	2.518466	1.2144831	3163.0393
894.97095	2.5194814	1.2164789	3170.3552
896.07202	2.5235155	1.2189656	3168.0615
897.1731	2.5242381	1.2209524	3172.0662
898.27417	2.532414	1.2228976	3174.0398
899.37524	2.5370734	1.2249995	3173.2502
900.47632	2.5370214	1.2271489	3169.4526
901.57739	2.5388186	1.2288454	3170.4775
902.67847	2.5428295	1.2303571	3166.614
903.77954	2.5458519	1.2321186	3167.718
904.88062	2.5485237	1.2340406	3172.7566
905.98169	2.5560331	1.2362045	3172.9294
907.08276	2.5567846	1.2382179	3173.3484
908.18384	2.5601194	1.2404786	3170.0471
909.28491	2.5608582	1.242402	3174.1277
910.38599	2.5647287	1.24456	3178.1965
911.48706	2.5660639	1.2471005	3172.0823
912.58813	2.5729818	1.2492685	3172.2795
913.68921	2.5745647	1.2510792	3173.533
914.79028	2.5800636	1.253199	3176.0933
915.89136	2.5823846	1.2554415	3179.2114
916.99243	2.5869284	1.2578617	3177.0107
918.09351	2.5894928	1.2598058	3179.4727
919.19458	2.5940113	1.2619607	3176.156
920.29565	2.5957041	1.2641582	3178.8826
921.39673	2.598614	1.2662871	3176.0698
922.4978	2.6036937	1.2684593	3177.9868
923.59888	2.605896	1.2703053	3168.9683
924.69995	2.6072855	1.2720113	3170.5037
925.80103	2.613724	1.2739272	3178.9592
926.9021	2.6136031	1.2760805	3183.3452
928.00317	2.6210179	1.2785132	3186.9084
929.10425	2.6228168	1.2809335	3182.8967
930.20532	2.6256294	1.2827291	3182.2456
931.3064	2.6246989	1.2850837	3178.6194
932.40747	2.6319776	1.2870878	3181.5159
933.50854	2.6356735	1.2891823	3185.4084
934.60962	2.6399715	1.2915348	3191.4155
935.71069	2.6437988	1.2937024	3187.5073
936.81177	2.6432528	1.2956278	3179.5515
937.91284	2.6492817	1.2975528	3179.134
939.01392	2.650748	1.2998248	3182.7983
940.11499	2.6567285	1.3019208	3186.5151
941.21606	2.6577959	1.3038895	3182.3718
942.31714	2.6602082	1.3062197	3182.6111
943.41821	2.6667242	1.3084215	3182.6226
944.51929	2.66659	1.3104981	3181.2681
945.62036	2.6730273	1.3122308	3184.6172
946.72144	2.6751037	1.3145075	3187.9143
947.82251	2.675266	1.3167605	3183.8098
948.92358	2.6819892	1.3186488	3183.3164
950.02466	2.6845725	1.320742	3188.9182
951.12573	2.6874273	1.3228527	3182.1694
952.22681	2.6922765	1.3249661	3183.0144
953.32788	2.6959882	1.3270916	3179.5574
954.42896	2.6967652	1.3291928	3186.9849
955.53003	2.7005854	1.3314643	3185.76
956.6311	2.7065206	1.3339229	3192.2546
957.73218	2.7069123	1.3362187	3181.1794
958.83325	2.7094667	1.338339	3183.7258
959.93433	2.7155812	1.3401934	3186.1885
961.0354	2.7194414	1.3424004	3191.6057
962.13647	2.720479	1.3446482	3191.2485
963.23755	2.7233293	1.3469043	3188.4258
964.33862	2.7307425	1.3495919	3193.6748
965.4397	2.7296321	1.3517693	3185.6021
966.54077	2.7329121	1.3536016	3181.0491
967.64185	2.7390897	1.3559179	3192.0269
968.74292	2.7388265	1.3579853	3191.3911
969.84399	2.7434554	1.3604218	3184.1528
970.94507	2.750494	1.3625674	3191.0867
972.04614	2.7514882	1.3645805	3185.1711
973.14722	2.7528646	1.3665065	3184.3984
974.24829	2.7582529	1.3683443	3191.5107
975.34937	2.7624254	1.3708141	3196.9248
976.45044	2.76406	1.373367	3191.9719
977.55151	2.7666242	1.375515	3184.824
978.65259	2.7704818	1.3775166	3185.5129
979.75366	2.7765739	1.3796527	3194.7351
980.85474	2.7732689	1.3818601	3189.5215
981.95581	2.7812512	1.3839998	3190.5569
983.05688	2.7851913	1.3862286	3195.7803
984.15796	2.7869663	1.3883364	3195.1763
985.25903	2.7890413	1.3906434	3194.3794
986.36011	2.7917979	1.3929054	3190.0159
987.46118	2.7973032	1.3951679	3193.6238
988.56226	2.7992125	1.3976209	3191.6475
989.66333	2.8054395	1.3998863	3194.875
990.7644	2.8090053	1.4019989	3189.7307
991.86548	2.8097308	1.4039977	3188.7644
992.96655	2.8159533	1.4065751	3201.4104
994.06763	2.8194892	1.4092824	3197.1416
995.1687	2.8212781	1.4114072	3200.7654
996.26978	2.8212359	1.4136313	3187.5698
997.37085	2.825819	1.4160215	3188.7026
998.47192	2.8272302	1.4183373	3195.623
999.573	2.8320544	1.4210306	3196.6489
1000.6741	2.837172	1.4235903	3196.6958
1001.7751	2.8387663	1.4260174	3195.7202
1002.8762	2.8445849	1.4283774	3195.9919
1003.9773	2.8473902	1.4305731	3191.334
1005.0784	2.8507669	1.4331198	3200.0239
1006.1794	2.8546655	1.4355339	3197.8445
1007.2805	2.8550119	1.4375769	3191.6201
1008.3816	2.8600569	1.4398861	3195.7454
1009.4827	2.861352	1.441959	3191.178
1010.5837	2.8656232	1.443898	3190.1064
1011.6848	2.8713391	1.4461819	3190.656
1012.7859	2.8747633	1.4485291	3196.6018
1013.887	2.8739719	1.4511383	3196.8198
1014.988	2.880281	1.4538434	3202.4514
1016.0891	2.8828843	1.4564215	3193.8418
1017.1902	2.8877964	1.4585122	3193.6392
1018.2913	2.8910639	1.4608052	3194.5325
1019.3923	2.8964083	1.4636894	3205.1868
1020.4934	2.8971868	1.4661192	3202.4871
1021.5945	2.8981981	1.4691234	3200.0044
1022.6956	2.9019539	1.4715497	3195.0635
1023.7966	2.9047089	1.4736185	3188.0525
1024.8977	2.9104083	1.4756668	3194.7837
1025.9988	2.9106507	1.4777205	3198.9587
1027.0999	2.9183893	1.4800663	3198.5947
1028.2009	2.9209697	1.4825641	3199.4944
1029.302	2.9233403	1.4853133	3200.6836
1030.4031	2.9253914	1.4871576	3189.9019
1031.5042	2.9321954	1.4893181	3197.865
1032.6052	2.9325414	1.4918066	3202.7412
1033.7063	2.9363143	1.4940535	3198.2041
1034.8074	2.9403927	1.4965364	3201.5916
1035.9084	2.9415145	1.499084	3194.8928
1037.0095	2.944016	1.5015786	3199.697
1038.1106	2.9504554	1.5040988	3195.3909
1039.2117	2.9530802	1.5065877	3193.2732
1040.3127	2.9569879	1.509068	3194.6074
1041.4138	2.9616888	1.5112828	3195.6025
1042.5149	2.9602029	1.5136796	3194.7761
1043.616	2.9673979	1.5164406	3202.6072
1044.717	2.9688485	1.5186616	3197.4707
1045.8181	2.9725254	1.5210061	3203.4104
1046.9192	2.9744136	1.5231491	3195.3723
1048.0203	2.9813323	1.5255984	3198.8882
1049.1213	2.9826453	1.5278327	3197.1292
1050.2224	2.9827225	1.5300224	3192.5134
1051.3235	2.988517	1.532366	3200.2688
1052.4246	2.9941065	1.5348265	3201.6304
1053.5256	2.995177	1.5374391	3201.2278
1054.6267	2.9982862	1.5401695	3199.4058
1055.7278	3.0012276	1.5425719	3191.9734
1056.8289	3.0036361	1.5444164	3181.158
1057.9299	3.0081227	1.5462165	3189.019
1059.031	3.0088291	1.5482901	3196.1172
1060.1321	3.0156949	1.5507122	3202.9836
1061.2332	3.0190866	1.5528687	3194.2278
1062.3342	3.0213597	1.5556109	3203.5981
1063.4353	3.0223315	1.5582789	3198.595
1064.5364	3.0288415	1.5604753	3198.8684
1065.6375	3.0311773	1.5633038	3202.5999
1066.7385	3.0352108	1.5660107	3201.9094
1067.8396	3.0388646	1.5686029	3195.8838
1068.9407	3.0441692	1.5709889	3196.1929
1070.0417	3.0449607	1.5731229	3191.4116
1071.1428	3.0474167	1.5757524	3197.8364
1072.2439	3.0506804	1.5783447	3203.7446
1073.345	3.0561094	1.5808411	3197.5393
1074.446	3.0577953	1.5839161	3201.4866
1075.5471	3.0613675	1.5864182	3201.6733
1076.6482	3.0618434	1.5889628	3195.949
1077.7493	3.0677185	1.5911708	3195.9675
1078.8503	3.07214	1.5935764	3196.7275
1079.9514	3.0769403	1.5964012	3201.2917
1081.0525	3.0793653	1.5987123	3196.3589
1082.1536	3.080327	1.6010935	3195.1526
1083.2546	3.085973	1.6035471	3198.5801
1084.3557	3.0906336	1.6064807	3207.4292
1085.4568	3.0893331	1.6092657	3193.0376
1086.5579	3.0947034	1.6120404	3196.6052
1087.6589	3.099643	1.6145464	3190.7844
1088.76	3.1010203	1.6169248	3196.1699
1089.8611	3.1075861	1.6193236	3200.437
1090.9622	3.1100497	1.6217736	3197.5354
1092.0632	3.1105211	1.6241752	3202.7188
1093.1643	3.1154795	1.6270796	3199.8506
1094.2654	3.1162183	1.6298958	3203.9753
1095.3665	3.1201456	1.6330609	3201.1633
1096.4675	3.1247067	1.6362739	3199.1411
1097.5686	3.1293769	1.6393067	3201.103
1098.6697	3.1323116	1.6419257	3195.4727
1099.7708	3.1361673	1.6446069	3198.467
1100.8718	3.1369565	1.6475729	3197.5239
1101.9729	3.1442835	1.6505823	3195.6956
1103.074	3.1474748	1.6532335	3201.6035
1104.175	3.1491983	1.6558733	3197.7854
1105.2761	3.1490228	1.6586034	3194.6023
1106.3772	3.1562767	1.6613586	3200.2339
1107.4783	3.1567602	1.664077	3195.7759
1108.5793	3.1582582	1.6666344	3189.97
1109.6804	3.1650438	1.6691167	3191.7283
1110.7815	3.1679478	1.6714954	3193.2996
1111.8826	3.1713624	1.6742821	3198.4993
1112.9836	3.1730928	1.6772702	3196.3975
1114.0847	3.1789317	1.680009	3197.9927
1115.1858	3.1797321	1.6828045	3197.1636
1116.2869	3.1853077	1.6856074	3195.3127
1117.3879	3.1894026	1.6884809	3199.531
1118.489	3.1915822	1.6915797	3196.7861
1119.5901	3.1910796	1.6941348	3194.4304
1120.6912	3.198009	1.6967721	3193.8142
1121.7922	3.1990016	1.6995575	3193.9033
1122.8933	3.2002554	1.7024562	3194.5999
1123.9944	3.208642	1.7053213	3189.8943
1125.0955	3.2101345	1.7080528	3194.6775
1126.1965	3.2118545	1.7108424	3193.5593
1127.2976	3.2171888	1.7138908	3192.1504
1128.3987	3.2180362	1.7171996	3193.3352
1129.4998	3.2264991	1.7203019	3196.2974
1130.6008	3.2249298	1.7233003	3195.022
1131.7019	3.2324078	1.7264961	3195.063
1132.803	3.2345521	1.7294542	3192.9089
1133.9041	3.2358253	1.731981	3189.7341
1135.0051	3.2386966	1.7346777	3192.2366
1136.1062	3.2449148	1.7381946	3196.5669
1137.2073	3.2447827	1.7413143	3190.8833
1138.3083	3.2502828	1.7441062	3185.7324
1139.4094	3.2538316	1.7467332	3186.8269
1140.5105	3.2545483	1.7497846	3187.855
1141.6116	3.2582412	1.7528193	3190.364
1142.7126	3.2634475	1.7559536	3185.3987
1143.8137	3.2663574	1.7587641	3188.0508
1144.9148	3.2686412	1.7615358	3187.72
1146.0159	3.2742994	1.7642093	3188.9229
1147.1169	3.2743776	1.7669638	3192.0508
1148.218	3.2787216	1.7707089	3193.5908
1149.3191	3.2846589	1.774073	3188.5005
1150.4202	3.2854071	1.7771478	3182.9702
1151.5212	3.2884364	1.780183	3182.6963
1152.6223	3.2920656	1.7830716	3185.0117
1153.7234	3.2948782	1.785877	3181.5676
1154.8245	3.3017898	1.7887189	3186.5327
1155.9255	3.3034906	1.7912629	3185.2688
1157.0266	3.3060129	1.7941755	3188.252
1158.1277	3.3070314	1.7974234	3188.0137
1159.2288	3.3144906	1.8008933	3186.2703
1160.3298	3.3181276	1.8040742	3181.8713
1161.4309	3.3176019	1.806802	3177.231
1162.532	3.3251765	1.8094865	3182.78
1163.6331	3.3234465	1.8126448	3182.6147
1164.7341	3.3273845	1.8160843	3185.5601
1165.8352	3.3315661	1.8192747	3188.4988
1166.9363	3.3366621	1.823097	3192.0789
1168.0374	3.3365705	1.8269501	3179.7156
1169.1384	3.3439493	1.8297493	3176.2192
1170.2395	3.3473525	1.832551	3180.6775
1171.3406	3.3494289	1.8353179	3178.9927
1172.4417	3.3489807	1.8385437	3177.4124
1173.5427	3.3565285	1.8416996	3180.3804
1174.6438	3.3619242	1.8444586	3174.8433
1175.7449	3.364321	1.8474412	3176.0415
1176.8459	3.3691099	1.8500729	3178.2434
1177.947	3.367871	1.8531121	3184.1877
1179.0481	3.374239	1.8568627	3177.6655
1180.1492	3.3770037	1.8598685	3181.0278
1181.2502	3.3805912	1.8633516	3173.4614
1182.3513	3.3777678	1.8663087	3171.908
1183.4524	3.3865054	1.869958	3177.1079
1184.5535	3.3893824	1.8731167	3168.1279
1185.6545	3.3951356	1.8761762	3179.4194
1186.7556	3.3951738	1.8796412	3176.3347
1187.8567	3.397481	1.8830056	3169.1035
1188.9578	3.4026456	1.8859227	3169.5215
1190.0588	3.402566	1.888641	3163.2693
1191.1599	3.4063475	1.8912436	3161.6567
1192.261	3.4100418	1.8945342	3172.5552
1193.3621	3.4178717	1.8975672	3172.9634
1194.4631	3.4176571	1.9009842	3167.3525
1195.5642	3.419677	1.9050871	3169.4492
1196.6653	3.4271784	1.9080768	3163.2095
1197.7664	3.4279647	1.9109583	3162.7893
1198.8674	3.428618	1.9138479	3162.6633
1199.9685	3.4351513	1.916772	3158.9619
1201.0696	3.4388132	1.9200566	3164.3757
1202.1707	3.4423487	1.9234703	3165.2476
1203.2717	3.442266	1.9268548	3162.7927
1204.3728	3.4494381	1.9301143	3159.4424
1205.4739	3.4500377	1.9332892	3155.4617
1206.575	3.4541366	1.9365025	3163.9688
1207.676	3.4560912	1.9400346	3153.2048
1208.7771	3.4617908	1.9438645	3156.8838
1209.8782	3.4659288	1.9471191	3155.1133
1210.9792	3.4675062	1.9506465	3154.1367
1212.0803	3.4711714	1.9543045	3157.2522
1213.1814	3.4775479	1.9578801	3164.4063
1214.2825	3.4759471	1.9614654	3151.022
1215.3835	3.481313	1.9650112	3149.188
1216.4846	3.4844081	1.9681301	3151.4146
1217.5857	3.4865749	1.9717228	3148.6272
1218.6868	3.4888592	1.9750718	3145.2949
1219.7878	3.4957926	1.9785372	3148.354
1220.8889	3.4980993	1.9819427	3142.625
1221.99	3.5018644	1.9849138	3143.916
1223.0911	3.5063174	1.9886172	3153.9756
1224.1921	3.5057135	1.9917474	3140.0432
1225.2932	3.5126674	1.9949461	3148.3503
1226.3943	3.5164402	1.9979459	3138.8137
1227.4954	3.517349	2.0009634	3137.9202
1228.5964	3.5197952	2.0039134	3135.6785
1229.6975	3.5225573	2.0070467	3140.9509
1230.7986	3.5270774	2.011148	3145.4675
1231.8997	3.5312746	2.014545	3134.2466
1233.0007	3.5325153	2.0176742	3131.9185
1234.1018	3.5371034	2.0206475	3132.5459
1235.2029	3.5421126	2.0239196	3137.1782
1236.304	3.5453141	2.0274332	3137.8977
1237.405	3.5464897	2.0313351	3134.1226
1238.5061	3.5487497	2.0352099	3128.1926
1239.6072	3.5520566	2.0382264	3121.4993
1240.7083	3.5595329	2.0416076	3125.9595
1241.8093	3.5611639	2.0446827	3127.6074
1242.9104	3.564029	2.048156	3130.6335
1244.0115	3.566196	2.050947	3121.7063
1245.1125	3.5717926	2.0523183	3116.8496
1246.2136	3.5743287	2.0527129	3116.1353
1247.3147	3.5805225	2.0532148	3125.3711
1248.4158	3.5805931	2.0536654	3120.2717
1249.5168	3.5826457	2.0539854	3118.8096
1250.6179	3.5857587	2.0540559	3115.5837
1251.719	3.589551	2.0541601	3112.9978
1252.8201	3.5958555	2.0545847	3115.8533
1253.9211	3.5987158	2.0544131	3113.311
1255.0222	3.6018965	2.0544357	3115.5186
1256.1233	3.6021924	2.0545065	3113.575
1257.2244	3.6076245	2.054817	3106.5486
1258.3254	3.6086447	2.0551467	3100.2571
1259.4265	3.6125584	2.0551865	3108.7397
1260.5276	3.6162732	2.0554371	3105.1255
1261.6287	3.6202774	2.0556152	3093.3784
1262.7297	3.6209114	2.0554359	3095.8669
1263.8308	3.6264927	2.0556157	3094.6089
1264.9319	3.6297333	2.0555785	3096.6077
1266.033	3.6356192	2.0556948	3094.0437
1267.134	3.6352656	2.0558221	3088.2048
1268.2351	3.6405931	2.055464	3086.0989
1269.3362	3.6437879	2.055758	3087.9346
1270.4373	3.6475496	2.0555725	3084.3391
1271.5383	3.6488562	2.0555024	3082.0632
1272.6394	3.6532328	2.0553071	3086.6262
1273.7405	3.6573646	2.0552289	3074.3352
1274.8416	3.6586225	2.0550284	3078.491
1275.9426	3.6643164	2.0550311	3078.4133
1277.0437	3.665704	2.0549719	3070.582
1278.1448	3.6686227	2.055032	3076.0862
1279.2458	3.6726725	2.0551336	3075.8218
1280.3469	3.6795509	2.0549002	3073.9412
1281.448	3.6794555	2.0545943	3071.1853
1282.5491	3.6841114	2.0545812	3066.3484
1283.6501	3.6854403	2.0544584	3059.5405
1284.7512	3.6885848	2.0540986	3063.2727
1285.8523	3.6904442	2.0543787	3060.0005
1286.9534	3.6975734	2.0541387	3054.2964
1288.0544	3.7019901	2.053978	3058.5159
1289.1555	3.7026124	2.0538828	3053.4465
1290.2566	3.7065868	2.0535605	3054.5872
1291.3577	3.7066965	2.0537918	3038.7988
1292.4587	3.7118971	2.0537298	3042.7864
1293.5598	3.7179863	2.0541482	3044.885
1294.6609	3.7164598	2.0543346	3038.606
1295.762	3.7208152	2.0541306	3039.2991
1296.863	3.7259469	2.0539505	3036.3411
1297.9641	3.7288811	2.0540578	3041.1311
1299.0652	3.7309601	2.0543499	3028.9758
1300.1663	3.7336452	2.05424	3025.3005
1301.2673	3.7384515	2.0543833	3020.6655
1302.3684	3.7426324	2.0546408	3021.6072
1303.4695	3.7446315	2.0547011	3014.5298
1304.5706	3.7457888	2.0548189	3015.6118
1305.6716	3.7517951	2.054728	3016.5225
1306.7727	3.7552359	2.0548699	3013.8064
1307.8738	3.7616796	2.0547278	3011.8457
1308.9749	3.7605667	2.0550566	3011.6323
1310.0759	3.7646759	2.0549722	3005.3953
1311.177	3.7709529	2.0549679	3004.2869
1312.2781	3.7732744	2.054956	3000.1792
1313.3792	3.7766461	2.054925	2990.8999
1314.4802	3.7793965	2.0551956	2994.8911
1315.5813	3.7798932	2.0550618	2986.7129
1316.6824	3.7809906	2.0552752	2976.8542
1317.7834	3.7885191	2.0551095	2976.9067
1318.8845	3.7888875	2.0552654	2981.5923
1319.9856	3.7976398	2.0551515	2974.6072
1321.0867	3.7974617	2.0553854	2978.1929
1322.1877	3.8012455	2.0554025	2975.3657
1323.2888	3.8053024	2.05513	2963.0461
1324.3899	3.8077731	2.0552971	2966.8054
1325.491	3.8111014	2.055099	2956.9805
1326.592	3.8164387	2.05509	2951.9932
1327.6931	3.8203802	2.0549626	2957.6411
1328.7942	3.8231671	2.0548491	2953.9722
1329.8953	3.8258724	2.0551674	2943.8257
1330.9963	3.8294201	2.0551534	2938.7705
1332.0974	3.8336124	2.055126	2934.6912
1333.1985	3.8351648	2.0551364	2933.9888
1334.2996	3.837301	2.055258	2930.3071
1335.4006	3.8428435	2.0554326	2931.1675
1336.5017	3.8429129	2.0553994	2926.7322
1337.6028	3.849503	2.0556531	2929.1006
1338.7039	3.8478348	2.0556095	2911.9067
1339.8049	3.8523691	2.0554874	2909.2605
1340.906	3.8603022	2.05562	2908.2678
1342.0071	3.859868	2.0558016	2902.645
1343.1082	3.8655982	2.0557401	2901.7393
1344.2092	3.8655457	2.0558982	2893.7729
1345.3103	3.8701348	2.0556512	2889.8994
1346.4114	3.8743272	2.0557685	2886.7507
1347.5125	3.8784094	2.0558553	2883.5444
1348.6135	3.8803985	2.0556233	2877.4683
1349.7146	3.8815689	2.0557387	2874.5332
1350.8157	3.8878284	2.0553303	2876.2627
1351.9167	3.8917685	2.0552502	2863.3352
1353.0178	3.897285	2.0548685	2863.0459
1354.1189	3.8969481	2.0547464	2855.3333
1355.22	3.9015291	2.0547879	2851.2971
1356.321	3.9044566	2.0549331	2845.9946
1357.4221	3.9084806	2.0549455	2839.3513
1358.5232	3.9109318	2.0545521	2836.6143
1359.6243	3.9161484	2.0545592	2832.7253
1360.7253	3.9163253	2.0546625	2830.022
1361.8264	3.9182181	2.0546467	2816.9575
1362.9275	3.9240291	2.0546346	2810.3152
1364.0286	3.9250669	2.0547712	2805.2764
1365.1296	3.9316654	2.0546436	2800.8267
1366.2307	3.9350734	2.0545528	2804.7559
1367.3318	3.9371526	2.0547965	2798.0208
1368.4329	3.9400821	2.0547171	2782.2227
1369.5339	3.9442594	2.0547113	2783.502
1370.635	3.9472489	2.0549831	2779.9495
1371.7361	3.948292	2.055124	2768.2048
1372.8372	3.9535308	2.0549223	2774.1882
1373.9382	3.9585154	2.0549128	2767.094
1375.0393	3.9589846	2.0551651	2756.8176
1376.1404	3.9645174	2.0548546	2746.9041
1377.2415	3.9685183	2.0549054	2743.1641
1378.3425	3.970655	2.0544746	2732.6865
1379.4436	3.9736335	2.0545053	2727.5659
1380.5447	3.9764805	2.0546601	2719.8984
1381.6458	3.9824505	2.0543227	2712.2532
1382.7468	3.9811637	2.0543938	2700.4409
1383.8479	3.9861627	2.0543065	2693.7729
1384.949	3.9899538	2.0543442	2680.4534
1386.05	3.9934134	2.0544627	2675.6924
1387.1511	3.9978509	2.0546086	2664.6711
1388.2522	4.000989	2.0546005	2646.8269
1389.3533	4.0023775	2.0545168	2637.0542
1390.4543	4.0068474	2.0543818	2634.5049
1391.5554	4.0082569	2.0543027	2612.2109
1392.6565	4.0141339	2.0543122	2596.9561
1393.7576	4.0162759	2.0543473	2589.7166
1394.8586	4.0212536	2.0545833	2570.6631
1395.9597	4.0248699	2.0546973	2560.377
1397.0608	4.0276623	2.0545907	2554.2703
1398.1619	4.0307012	2.0546203	2515.9585
1398.6624	4.0337667	2.0544639	2488.9946