File: datasets/am_bench_2022/raw_data/90-XY.16-3/specimen.dat
MTS793|MPT|ENU|1|2|.|/|:|1|0|0|A

Operator Information						Time:	12.07373	Sec	11/3/2021 7:53:24 AM
Operator	Nick Derimow
Project	AM Bench 2022 mini-tensile challenge
Specimen ID	90-XY.16-3
Material	PBF-L Inconel 625
Specimen Width	2.54	mm
Specimen Thickness	1.5	mm
Notes
Operator Information End

Data Acquisition						Time:	992.07886	Sec	11/3/2021 8:09:44 AM
Time	Axial Displacement	Axial Extensometer	Axial Force
Sec	mm	mm	N
12.1875	0.0036102382	0.0001727534	60.875656
13.088379	0.0034789031	0.00020222492	70.646355
13.989258	0.011618965	0.00025593914	86.395836
14.890137	0.009951409	0.00031141029	97.19445
15.791016	0.01298231	0.00028659491	104.90881
16.691895	0.015438696	0.00036868552	113.50071
17.592773	0.01570362	0.00032079429	122.89307
18.493652	0.022436285	0.00049677311	136.76538
19.394531	0.022919623	0.00051741384	144.35544
20.29541	0.025438502	0.00047144038	156.82671
21.196289	0.032816317	0.00057464803	171.20145
22.097168	0.0331298	0.00068860227	190.48268
22.998047	0.034065537	0.00081054826	203.57153
23.898926	0.038635582	0.00083178724	221.98415
24.799805	0.038038325	0.00099134096	229.86043
25.700684	0.041616488	0.00099666812	246.67128
26.601563	0.046853449	0.001152372	270.28821
27.502441	0.048080951	0.0011337884	284.3822
28.40332	0.051396444	0.0013507945	304.3515
29.304199	0.055719595	0.0014003157	317.97668
30.205078	0.059084263	0.0014369214	332.03253
31.105957	0.057940356	0.0015933947	352.65326
32.006836	0.062169716	0.0016534636	375.39957
32.907715	0.065504678	0.0018731497	396.12866
33.808594	0.065924495	0.0018331222	417.39856
34.709473	0.071048103	0.0020631913	438.70053
35.610352	0.071819514	0.0021311247	457.60498
36.51123	0.074146666	0.0022292419	473.79364
37.412109	0.076424643	0.0024377001	506.6355
38.312988	0.080105461	0.0024702807	525.51917
39.213867	0.08111921	0.0025338246	538.66278
40.114746	0.086469889	0.0025569282	564.45032
41.015625	0.087058127	0.0028104039	586.99274
41.916504	0.094428979	0.0029067837	613.79144
42.817383	0.092421919	0.003095146	631.92957
43.718262	0.093208291	0.0030483869	650.14734
44.619141	0.098153234	0.0033107754	672.79504
45.52002	0.099107206	0.0033444706	697.16437
46.420898	0.10400143	0.0035204096	715.25165
47.321777	0.10824893	0.0036139279	741.93713
48.222656	0.11063406	0.0036407562	761.56598
49.123535	0.11467159	0.0038369538	794.96033
50.024414	0.11390264	0.0039375122	813.44562
50.925293	0.11600666	0.0041675782	845.27612
51.826172	0.11927667	0.004265687	862.37677
52.727051	0.11974178	0.0043758685	888.13898
53.62793	0.12403685	0.0044597946	907.57703
54.528809	0.12680733	0.0046295365	935.70703
55.429688	0.13237314	0.0047375746	960.36261
56.330566	0.13493957	0.0048779803	986.75708
57.231445	0.13700752	0.0050842911	1009.6377
58.132324	0.13955344	0.0051184343	1037.8567
59.033203	0.14277454	0.0051932102	1051.9918
59.934082	0.14108808	0.0053195846	1081.9773
60.834961	0.14763758	0.0055060582	1109.8912
61.73584	0.14572881	0.0055380007	1129.1832
62.636719	0.15268537	0.0055973032	1149.4167
63.537598	0.15509489	0.0058281384	1175.1519
64.438477	0.15778531	0.0059216181	1204.484
65.339355	0.16109774	0.0061149788	1239.1202
66.240234	0.16461951	0.0061234119	1257.4366
67.141113	0.16344696	0.0062480709	1275.8126
68.041992	0.16877797	0.0064323721	1304.5403
68.942871	0.16944592	0.0065139546	1324.1302
69.84375	0.17256778	0.0066955108	1356.0496
70.744629	0.17687947	0.0067880382	1382.9406
71.645508	0.18042833	0.0069865594	1416.7247
72.546387	0.18189207	0.007129563	1434.3987
73.447266	0.18535794	0.0072319829	1466.7977
74.348145	0.18935512	0.0073089264	1481.0149
75.249023	0.19028369	0.007435461	1515.1014
76.149902	0.19345576	0.0076210173	1540.7805
77.050781	0.1930386	0.0077088233	1560.2493
77.95166	0.19870746	0.0077676764	1579.6927
78.852539	0.20007859	0.0079874843	1607.1245
79.753418	0.2035365	0.0080255121	1636.9547
80.654297	0.20412248	0.0081374142	1654.7572
81.555176	0.20960593	0.0084473696	1687.8782
82.456055	0.21295318	0.008478906	1708.0242
83.356934	0.21507497	0.0085172402	1725.7517
84.257813	0.21559417	0.0086688297	1751.4194
85.158691	0.22012077	0.0088041956	1774.0162
86.05957	0.22278415	0.0089493264	1804.325
86.960449	0.22803484	0.0090220617	1821.2683
87.861328	0.22762077	0.0091150897	1838.0029
88.762207	0.22882321	0.0092907567	1866.585
89.663086	0.2345515	0.0093517844	1891.9358
90.563965	0.23768798	0.0095303413	1915.8672
91.464844	0.2404941	0.0097121876	1937.7412
92.365723	0.2434869	0.0097189369	1959.3727
93.266602	0.24350677	0.0098967636	1980.8219
94.16748	0.24616969	0.0099810138	1999.9357
95.068359	0.24876997	0.01005386	2014.4849
95.969238	0.25257596	0.010210088	2044.0173
96.870117	0.25496191	0.01035208	2069.6499
97.770996	0.25947824	0.010468883	2082.4609
98.671875	0.26317671	0.010585878	2108.4661
99.572754	0.26349327	0.010727018	2126.4106
100.47363	0.26702124	0.010754289	2146.8159
101.37451	0.26840714	0.010925678	2168.9583
102.27539	0.26941758	0.010950289	2185.0354
103.17627	0.27529606	0.011071727	2197.8398
104.07715	0.27822989	0.011205707	2218.4265
104.97803	0.27882344	0.011320535	2245.656
105.87891	0.280222	0.011474094	2255.0706
106.77979	0.28540632	0.011642358	2279.8762
107.68066	0.28775677	0.011636691	2294.4412
108.58154	0.29260117	0.011840645	2310.9792
109.48242	0.29213366	0.011894539	2326.3538
110.3833	0.29874456	0.012055884	2341.9678
111.28418	0.29752547	0.012055073	2352.3623
112.18506	0.30155173	0.012222389	2368.4001
113.08594	0.30334145	0.012235756	2383.1414
113.98682	0.30680385	0.01235703	2400.7239
114.8877	0.3088038	0.012478963	2410.9714
115.78857	0.31328976	0.012529759	2428.4194
116.68945	0.31515142	0.012560165	2441.3708
117.59033	0.31766808	0.012812058	2449.2939
118.49121	0.31981468	0.012858335	2465.8513
119.39209	0.3225784	0.012867522	2473.6985
120.29297	0.32513174	0.013014402	2482.0596
121.19385	0.33245897	0.013175285	2498.1738
122.09473	0.33142328	0.013320297	2515.9734
122.99561	0.33562267	0.013404593	2522.8962
123.89648	0.33783934	0.013479712	2528.584
124.79736	0.33962902	0.013484339	2534.7896
125.69824	0.34521291	0.01364007	2547.4155
126.59912	0.34294599	0.013771102	2555.6074
127.5	0.35043466	0.013897247	2576.3875
128.40088	0.35013962	0.013945425	2578.6184
129.30176	0.35240775	0.014145125	2596.8218
130.20264	0.35736668	0.014120474	2602.2495
131.10352	0.35694626	0.014384087	2608.2275
132.00439	0.36404788	0.014529358	2618.9021
132.90527	0.36492726	0.014511365	2631.6802
133.80615	0.36801001	0.014769762	2641.9138
134.70703	0.37033674	0.014822249	2655.2727
135.60791	0.37055025	0.014971186	2656.9709
136.50879	0.37515941	0.015188267	2666.1133
137.40967	0.3766354	0.015335689	2679.2856
138.31055	0.3829214	0.015472382	2682.7798
139.21143	0.38310498	0.015553599	2695.1787
140.1123	0.38513464	0.015826635	2708.8948
141.01318	0.38992324	0.015948044	2715.3474
141.91406	0.39142242	0.016123945	2722.9392
142.81494	0.39344054	0.016188856	2729.0413
143.71582	0.3951098	0.016450532	2738.978
144.6167	0.40008739	0.016652931	2752.1172
145.51758	0.40080798	0.016818788	2757.8674
146.41846	0.40465721	0.017003154	2767.9392
147.31934	0.40783009	0.017210072	2770.8313
148.22021	0.40760943	0.017313022	2771.0193
149.12109	0.41225308	0.01766164	2782.7158
150.02197	0.41881481	0.017862141	2795.0911
150.92285	0.41880313	0.018179316	2810.7915
151.82373	0.42174265	0.018293371	2807.2539
152.72461	0.4240059	0.018614419	2823.2346
153.62549	0.42763814	0.018883154	2825.4807
154.52637	0.42870745	0.01911179	2836.0923
155.42725	0.43446827	0.019484306	2838.0061
156.32813	0.43622214	0.019651052	2843.6187
157.229	0.43638524	0.019961849	2850.769
158.12988	0.44095528	0.02026014	2863.4146
159.03076	0.44223809	0.020560721	2859.7266
159.93164	0.4462617	0.020836845	2869.7996
160.83252	0.44863081	0.021286018	2874.5271
161.7334	0.44868368	0.021667905	2879.946
162.63428	0.45097598	0.022081224	2893.1921
163.53516	0.45469204	0.022571724	2894.741
164.43604	0.46034425	0.02296279	2907.0107
165.33691	0.45979419	0.023340002	2911.4192
166.23779	0.46711382	0.023860604	2913.0706
167.13867	0.46696773	0.024327734	2919.9778
168.03955	0.47124273	0.024854552	2925.334
168.94043	0.47390932	0.025292963	2928.2588
169.84131	0.47652456	0.02587329	2942.7644
170.74219	0.48056886	0.026338195	2940.908
171.64307	0.48487458	0.026763212	2946.864
172.54395	0.48396569	0.027231809	2939.5972
173.44482	0.48810792	0.02774453	2956.4084
174.3457	0.48725271	0.028336076	2960.178
175.24658	0.49231842	0.028908519	2962.8342
176.14746	0.49576095	0.029646	2964.3589
177.04834	0.49887872	0.030381696	2974.8669
177.94922	0.4994016	0.031129234	2980.7688
178.8501	0.50143898	0.031773929	2973.1057
179.75098	0.50206065	0.032379538	2980.5852
180.65186	0.50869226	0.033176411	2991.2781
181.55273	0.50857979	0.033916563	2992.7852
182.45361	0.51536506	0.034485362	2994.3025
183.35449	0.51510137	0.03537624	3002.9165
184.25537	0.51708347	0.036102973	3003.9539
185.15625	0.52071184	0.036889866	3003.7878
186.05713	0.52391362	0.037577424	3011.113
186.95801	0.52888978	0.038269758	3013.3645
187.85889	0.52708107	0.039155282	3014.0859
188.75977	0.53204364	0.039911654	3022.0449
189.66064	0.535101	0.040733475	3026.8879
190.56152	0.53318918	0.041664775	3030.2605
191.4624	0.54023939	0.042531248	3031.1729
192.36328	0.542997	0.043474369	3035.0464
193.26416	0.5472241	0.044387527	3038.968
194.16504	0.54771948	0.045235567	3036.5605
195.06592	0.55284417	0.045949034	3040.606
195.9668	0.55325228	0.046768628	3047.614
196.86768	0.55721503	0.047482971	3045.8081
197.76855	0.56089175	0.048205633	3055.2019
198.66943	0.56183076	0.049061224	3053.4954
199.57031	0.5634799	0.050028265	3064.7083
200.47119	0.56863117	0.051009584	3065.9648
201.37207	0.56920159	0.051893152	3062.8201
202.27295	0.57095444	0.05248332	3066.3552
203.17383	0.57305866	0.053312652	3068.5588
204.07471	0.57901847	0.054063551	3068.0818
204.97559	0.58164734	0.054883532	3072.8137
205.87646	0.58387637	0.05557958	3079.2144
206.77734	0.58654445	0.056372322	3085.7771
207.67822	0.58890063	0.057557356	3092.0059
208.5791	0.59173197	0.058391932	3083.6201
209.47998	0.59205675	0.059454996	3094.3225
210.38086	0.59679765	0.060215529	3092.2686
211.28174	0.5998866	0.061206918	3097.9539
212.18262	0.60015213	0.062166762	3101.7874
213.0835	0.60653621	0.063298285	3107.2236
213.98438	0.60677165	0.064435244	3105.2354
214.88525	0.60996276	0.065261148	3108.4248
215.78613	0.61378646	0.066230953	3103.7581
216.68701	0.61886561	0.067159399	3118.8062
217.58789	0.61512578	0.068166181	3116.8787
218.48877	0.62351102	0.069177568	3119.3489
219.38965	0.62350142	0.07016018	3121.5186
220.29053	0.62688804	0.071096487	3119.0073
221.19141	0.63044488	0.071978964	3127.1123
222.09229	0.63405895	0.072947346	3129.5811
222.99316	0.63414496	0.073773444	3129.7048
223.89404	0.63976735	0.074701108	3136.7136
224.79492	0.63866746	0.075579152	3134.8274
225.6958	0.64265561	0.076479822	3130.283
226.59668	0.64683187	0.077289313	3133.4878
227.49756	0.647659	0.078060962	3137.6663
228.39844	0.65169388	0.079149596	3146.7109
229.29932	0.65235341	0.08014933	3146.0159
230.2002	0.65415239	0.081066288	3143.4172
231.10107	0.65928072	0.082014032	3147.6594
232.00195	0.66149676	0.082925156	3152.6624
232.90283	0.66440719	0.08398959	3153.7017
233.80371	0.66713351	0.08509443	3162.1462
234.70459	0.66994804	0.086033151	3151.02
235.60547	0.67529517	0.086963363	3162.625
236.50635	0.67352003	0.087822512	3160.8274
237.40723	0.67958969	0.088804707	3164.9009
238.30811	0.68257123	0.08982937	3171.252
239.20898	0.68508273	0.090813987	3168.6572
240.10986	0.68699884	0.091621049	3164.1868
241.01074	0.68859673	0.092646532	3173.0837
241.91162	0.69334346	0.093702503	3176.3003
242.8125	0.69573408	0.094678864	3173.9929
243.71338	0.6967243	0.095688909	3176.2998
244.61426	0.70175385	0.096571319	3185.7563
245.51514	0.70543784	0.097680598	3183.7874
246.41602	0.70310003	0.098518781	3184.4399
247.31689	0.70805037	0.09961506	3181.1001
248.21777	0.7123487	0.10078733	3196.1533
249.11865	0.71439761	0.1020866	3194.4563
250.01953	0.71465391	0.1030423	3191.4802
250.92041	0.71953046	0.10386615	3185.2156
251.82129	0.7201525	0.10472826	3192.3794
252.72217	0.72818929	0.10564133	3203.0828
253.62305	0.72593647	0.10657949	3199.7019
254.52393	0.72941977	0.10769973	3202.4094
255.4248	0.73467153	0.10870559	3203.6235
256.32568	0.73786372	0.10990382	3208.1516
257.22656	0.74001133	0.11086724	3210.2554
258.12744	0.74050426	0.11200647	3211.6555
259.02832	0.74205893	0.11303335	3213.5544
259.9292	0.74774343	0.11423193	3216.1521
260.83008	0.74829912	0.11513132	3213.2673
261.73096	0.75092208	0.1160318	3211.6548
262.63184	0.75510877	0.11699525	3218.9456
263.53271	0.7550512	0.11795462	3216.2917
264.43359	0.75975418	0.11904258	3220.4258
265.33447	0.76342517	0.11984129	3222.4519
266.23535	0.76219994	0.12097607	3223.6609
267.13623	0.76797146	0.12193537	3225.5681
268.03711	0.77142692	0.12295147	3231.281
268.93799	0.77344304	0.12393884	3231.5193
269.83887	0.77491617	0.12481757	3228.679
270.73975	0.77994168	0.12582494	3232.1245
271.64063	0.78211409	0.12681699	3237.1465
272.5415	0.78597111	0.12769507	3241.5371
273.44238	0.78687757	0.12869318	3234.9353
274.34326	0.79114026	0.12977134	3243.4116
275.24414	0.79332167	0.13073689	3245.1018
276.14502	0.79460758	0.1317144	3244.4314
277.0459	0.79684943	0.13275555	3249.1418
277.94678	0.79740512	0.13391519	3252.3308
278.84766	0.80163097	0.13502367	3248.0447
279.74854	0.80636221	0.13580655	3256.3381
280.64941	0.80800998	0.13686933	3251.4463
281.55029	0.80915552	0.13782455	3250.28
282.45117	0.81442136	0.13893487	3258.7998
283.35205	0.81564742	0.14007299	3261.1736
284.25293	0.81791902	0.14134499	3267.1531
285.15381	0.82294118	0.14248216	3262.3862
286.05469	0.8244791	0.14332889	3262.9907
286.95557	0.82682407	0.14444953	3261.5906
287.85645	0.82832021	0.14541447	3263.6345
288.75732	0.8334403	0.14626923	3267.5291
289.6582	0.83626777	0.14739853	3275.718
290.55908	0.83868426	0.14850242	3278.418
291.45996	0.84097248	0.14965101	3269.5386
292.36084	0.84557307	0.15064594	3279.999
293.26172	0.84804231	0.15170906	3281.8169
294.1626	0.84636098	0.15264484	3277.1909
295.06348	0.8515951	0.15379301	3278.2449
295.96436	0.85257077	0.15480307	3281.678
296.86523	0.85808927	0.15575215	3282.5808
297.76611	0.85797578	0.15671769	3281.1536
298.66699	0.86297047	0.15773627	3288.5806
299.56787	0.86520505	0.15867873	3292.012
300.46875	0.86826754	0.15962106	3283.709
301.36963	0.86968493	0.16068967	3290.741
302.27051	0.87406504	0.16148701	3291.0198
303.17139	0.87584305	0.16251566	3291.6907
304.07227	0.87797469	0.16340306	3291.2446
304.97314	0.87949067	0.16435735	3295.877
305.87402	0.8834129	0.16540128	3296.082
306.7749	0.8861658	0.16647747	3298.8037
307.67578	0.88773376	0.16730179	3298.2986
308.57666	0.89167297	0.1685109	3310.0063
309.47754	0.89523679	0.16958699	3309.3794
310.37842	0.89657223	0.17069748	3308.1643
311.2793	0.90021741	0.1717948	3310.856
312.18018	0.90204829	0.17295255	3308.9163
313.08105	0.90300226	0.17393292	3306.6853
313.98193	0.90770471	0.17497747	3313.2153
314.88281	0.91267306	0.17599717	3318.7446
315.78369	0.91404575	0.17696933	3311.4304
316.68457	0.91450942	0.17779972	3310.2366
317.58545	0.91828144	0.17885751	3317.2566
318.48633	0.92182297	0.18005969	3322.5146
319.38721	0.92546731	0.18122163	3320.3926
320.28809	0.92598033	0.18229082	3322.5105
321.18896	0.92774892	0.18314002	3314.925
322.08984	0.9315871	0.18421157	3319.262
322.99072	0.93806857	0.18528603	3335.8174
323.8916	0.93652517	0.18630441	3327.9885
324.79248	0.94098413	0.18733154	3331.6855
325.69336	0.94300783	0.18845801	3331.2791
326.59424	0.94435412	0.18949945	3333.1982
327.49512	0.95011544	0.19045413	3333.9824
328.396	0.95200306	0.1914942	3332.553
329.29688	0.95593995	0.1926678	3337.3428
330.19775	0.9558863	0.19381262	3342.3027
331.09863	0.95836151	0.19484282	3342.2168
331.99951	0.96141255	0.19588894	3334.6184
332.90039	0.96233946	0.19685519	3342.7571
333.80127	0.96878076	0.19794147	3345.0088
334.70215	0.9700529	0.19913436	3351.8848
335.60303	0.97215706	0.20001583	3349.4363
336.50391	0.97622049	0.20098235	3345.8162
337.40479	0.97836542	0.20181926	3346.8911
338.30566	0.98050773	0.20277157	3347.9583
339.20654	0.98336285	0.20388123	3356.6392
340.10742	0.99036068	0.20483772	3348.9934
341.0083	0.98448747	0.20592894	3353.2256
341.90918	0.98961467	0.2069612	3355.6445
342.81006	0.99418628	0.20798299	3354.959
343.71094	0.99925339	0.20901549	3367.834
344.61182	0.99891186	0.21004061	3360.2566
345.5127	1.0007161	0.21096233	3362.2827
346.41357	1.0044399	0.21198358	3359.6003
347.31445	1.0086789	0.2129548	3359.4929
348.21533	1.0137085	0.21387585	3364.2937
349.11621	1.0134493	0.2150463	3371.1763
350.01709	1.015062	0.21622923	3371.2065
350.91797	1.0199751	0.21735892	3372.5178
351.81885	1.0207936	0.21852124	3369.6931
352.71973	1.0260961	0.21962166	3377.0662
353.62061	1.0284544	0.22061597	3374.2585
354.52148	1.0273582	0.22162119	3372.1206
355.42236	1.0341365	0.22271048	3373.6904
356.32324	1.034758	0.22367041	3378.5999
357.22412	1.0365517	0.22469102	3379.6062
358.125	1.042653	0.22581284	3384.4209
359.02588	1.0442779	0.2268804	3380.293
359.92676	1.0467734	0.22793543	3381.6416
360.82764	1.0496994	0.22889322	3387.3503
361.72852	1.0527439	0.22981806	3387.9951
362.62939	1.0565217	0.23077396	3387.2261
363.53027	1.056411	0.23182233	3387.5798
364.43115	1.0613109	0.23303826	3395.0415
365.33203	1.0644828	0.23424396	3393.3223
366.23291	1.0640293	0.23542169	3394.6179
367.13379	1.0676194	0.23637134	3390.1768
368.03467	1.06776	0.23739363	3392.0164
368.93555	1.0754329	0.2382406	3392.0073
369.83643	1.0769402	0.23925179	3395.6113
370.7373	1.0764829	0.24022873	3400.6721
371.63818	1.0813193	0.24113803	3400.3442
372.53906	1.0828208	0.24231029	3403.9172
373.43994	1.0875176	0.24348907	3405.2593
374.34082	1.0919825	0.24445808	3401.8572
375.2417	1.0917633	0.2456018	3406.2517
376.14258	1.0940615	0.24674939	3415.7219
377.04346	1.0955781	0.2479132	3404.0505
377.94434	1.102657	0.24885654	3411.5244
378.84521	1.1016028	0.24995744	3412.1455
379.74609	1.1058737	0.25089639	3411.0754
380.64697	1.10745	0.25186986	3406.7246
381.54785	1.107123	0.25291577	3411.2095
382.44873	1.1147627	0.25395772	3417.1057
383.34961	1.11646	0.25486651	3415.1731
384.25049	1.120173	0.25592533	3422.1213
385.15137	1.1221474	0.25699076	3416.9604
386.05225	1.127076	0.25802264	3421.6936
386.95313	1.1281515	0.25893837	3419.5393
387.854	1.1268337	0.26004237	3430.199
388.75488	1.130559	0.2611264	3424.947
389.65576	1.1343981	0.26241544	3430.1609
390.55664	1.1380967	0.2636964	3428.3682
391.45752	1.1439476	0.26495469	3431.458
392.3584	1.1418098	0.265865	3427.7268
393.25928	1.1466657	0.26681072	3428.6851
394.16016	1.1509078	0.26791826	3433.5911
395.06104	1.1503031	0.26895776	3438.8696
395.96191	1.1559228	0.26994729	3436.9175
396.86279	1.1585184	0.27103746	3436.123
397.76367	1.1573091	0.27192426	3432.542
398.66455	1.1620034	0.27293941	3441.9309
399.56543	1.1642426	0.27412763	3441.2678
400.46631	1.1647477	0.27512041	3439.8965
401.36719	1.1675436	0.27594286	3437.8564
402.26807	1.1726594	0.2769908	3442.4758
403.16895	1.1737009	0.27789629	3441.2244
404.06982	1.1801512	0.27893081	3444.9468
404.9707	1.1809251	0.28023779	3445.2722
405.87158	1.1845219	0.2813299	3452.3792
406.77246	1.1880345	0.28220364	3450.6084
407.67334	1.1900429	0.2832157	3449.6753
408.57422	1.192681	0.28422755	3448.5422
409.4751	1.1946063	0.28539395	3457.5664
410.37598	1.1988319	0.28639674	3453.5107
411.27686	1.1991091	0.28745538	3455.271
412.17773	1.2035993	0.28863123	3461.1284
413.07861	1.2065296	0.2897841	3451.5037
413.97949	1.2046806	0.29076388	3451.5786
414.88037	1.209394	0.291861	3453.4678
415.78125	1.2138929	0.29280624	3463.7498
416.68213	1.2143537	0.29393762	3467.6008
417.58301	1.2218404	0.29498258	3468.2527
418.48389	1.2194399	0.29610401	3463.0537
419.38477	1.2244844	0.2971805	3462.9377
420.28564	1.2263501	0.29816496	3464.1284
421.18652	1.2337948	0.29911768	3468.031
422.0874	1.2315938	0.30019391	3463.9097
422.98828	1.2345862	0.30118266	3468.4158
423.88916	1.2377961	0.30213279	3468.4932
424.79004	1.2415223	0.30316979	3473.1919
425.69092	1.2443248	0.30426845	3476.6096
426.5918	1.2459247	0.30538335	3470.4119
427.49268	1.2508759	0.30642378	3480.2937
428.39355	1.2498287	0.30772498	3478.8401
429.29443	1.2528849	0.30892581	3476.1438
430.19531	1.2586943	0.30981684	3468.5322
431.09619	1.2599466	0.31089783	3482.1304
431.99707	1.2621856	0.31183124	3479.1567
432.89795	1.2677308	0.31301039	3483.5764
433.79883	1.2678587	0.31401676	3486.5972
434.69971	1.2703358	0.31516367	3490.5154
435.60059	1.2708927	0.31626835	3485.6746
436.50146	1.2747506	0.31722885	3483.1509
437.40234	1.2792017	0.3183724	3485.6377
438.30322	1.2818413	0.31949759	3492.3376
439.2041	1.2851537	0.32058907	3489.7251
440.10498	1.2839983	0.32179505	3488.7429
441.00586	1.2882988	0.32267755	3493.3018
441.90674	1.2899868	0.32391813	3490.2598
442.80762	1.2953911	0.32490626	3485.3535
443.7085	1.3003861	0.32586405	3494.1394
444.60938	1.3016502	0.32676962	3486.3188
445.51025	1.3025802	0.3277804	3491.3235
446.41113	1.3080118	0.32851663	3490.8257
447.31201	1.3096265	0.32962093	3502.2444
448.21289	1.312682	0.33071783	3506.6147
449.11377	1.3158832	0.33180717	3505.5615
450.01465	1.3159809	0.33283943	3503.4397
450.91553	1.3202153	0.33400324	3507.2383
451.81641	1.3202672	0.33522192	3503.4421
452.71729	1.3236599	0.33645761	3504.0071
453.61816	1.3267089	0.33740771	3507.5835
454.51904	1.3284857	0.33861101	3511.502
455.41992	1.3279073	0.33970979	3505.4358
456.3208	1.3339453	0.3408998	3502.8604
457.22168	1.3375993	0.3420178	3504.6606
458.12256	1.3390613	0.34300816	3510.947
459.02344	1.3447562	0.34394571	3511.4844
459.92432	1.3443758	0.34495863	3510.9417
460.8252	1.3505896	0.34604186	3516.0396
461.72607	1.3542017	0.34696409	3513.3557
462.62695	1.353236	0.34814319	3516.7993
463.52783	1.3564347	0.34925413	3517.9185
464.42871	1.3581711	0.3504512	3515.082
465.32959	1.3647217	0.35126898	3516.1431
466.23047	1.3684338	0.352456	3526.3418
467.13135	1.3669367	0.35371426	3529.3889
468.03223	1.3688836	0.35492903	3517.9958
468.93311	1.3740247	0.35593179	3519.7998
469.83398	1.3775979	0.35713348	3528.7012
470.73486	1.3781043	0.35834768	3523.0679
471.63574	1.3849089	0.35939494	3533.1382
472.53662	1.3830023	0.36035708	3523.0969
473.4375	1.3901573	0.36141869	3537.0305
474.33838	1.3883127	0.36279595	3532.8208
475.23926	1.3896617	0.3639307	3531.8284
476.14014	1.3944846	0.36490336	3531.207
477.04102	1.395967	0.36608601	3530.6274
477.94189	1.3994597	0.36717126	3532.9851
478.84277	1.4056702	0.36846247	3539.929
479.74365	1.406414	0.36948577	3531.8342
480.64453	1.4096667	0.37043437	3531.7632
481.54541	1.4115068	0.37136355	3532.0166
482.44629	1.4138553	0.37244341	3535.8892
483.34717	1.4150833	0.37352943	3534.344
484.24805	1.4176139	0.37461418	3536.0037
485.14893	1.4182328	0.37563801	3540.6206
486.0498	1.4239231	0.37674835	3542.4111
486.95068	1.4262004	0.37768659	3534.3845
487.85156	1.4308845	0.3788783	3545.1091
488.75244	1.4331849	0.37995496	3542.5732
489.65332	1.4336151	0.38117784	3543.4131
490.5542	1.43927	0.38229561	3547.9434
491.45508	1.4398068	0.38356271	3549.1321
492.35596	1.4431276	0.38453704	3548.6514
493.25684	1.4439902	0.38560835	3544.9219
494.15771	1.446254	0.38644534	3541.979
495.05859	1.4507072	0.38751745	3549.4202
495.95947	1.4547443	0.38867438	3553.1689
496.86035	1.4580296	0.38986492	3551.3181
497.76123	1.4596816	0.3909367	3553.0955
498.66211	1.460706	0.3920756	3552.7366
499.56299	1.4652101	0.39328358	3559.5322
500.46387	1.4660475	0.3945044	3564.2405
501.36475	1.470639	0.39567804	3560.2058
502.26563	1.4729263	0.39681518	3551.6086
503.1665	1.4749569	0.39778277	3554.2161
504.06738	1.4767665	0.39873224	3557.8953
504.96826	1.4815354	0.39984116	3561.5581
505.86914	1.4825766	0.40098122	3563.3708
506.77002	1.487443	0.40208778	3563.2646
507.6709	1.4868472	0.40308088	3557.7236
508.57178	1.4906542	0.40417358	3561.9778
509.47266	1.493705	0.40530589	3564.0205
510.37354	1.4975541	0.40627718	3567.4546
511.27441	1.5006058	0.40725356	3565.2578
512.17529	1.5029367	0.40849072	3568.3406
513.07617	1.506119	0.40971518	3577.4973
513.97705	1.5068513	0.41075251	3563.4951
514.87793	1.5134493	0.41191927	3577.9629
515.77881	1.5119886	0.41320044	3567.4636
516.67969	1.5172361	0.41411659	3570.9023
517.58057	1.5206114	0.41518059	3570.0623
518.48145	1.5231063	0.41604561	3565.3723
519.38232	1.5280343	0.41710734	3576.3232
520.2832	1.5264645	0.4182705	3572.9382
521.18408	1.530636	0.41951224	3582.3054
522.08496	1.5311676	0.42074445	3576.2163
522.98584	1.5334872	0.42199698	3578.47
523.88672	1.5398211	0.42304745	3581.9163
524.7876	1.5406864	0.42419165	3578.4067
525.68848	1.5436552	0.42539901	3581.2219
526.58936	1.5465083	0.42645583	3578.5625
527.49023	1.5516893	0.42748553	3583.3462
528.39111	1.5540152	0.42863169	3586.373
529.29199	1.5554922	0.42985883	3582.2678
530.19287	1.5552572	0.43089586	3583.8074
531.09375	1.5615395	0.43210456	3589.6096
531.99463	1.560141	0.43335006	3586.9983
532.89551	1.5655017	0.43440977	3583.2244
533.79639	1.5662392	0.43558371	3589.2678
534.69727	1.5695652	0.4368479	3590.1941
535.59814	1.5721554	0.43805918	3589.5845
536.49902	1.5747406	0.43912098	3578.1755
537.3999	1.5774782	0.44020149	3587.3801
538.30078	1.5818431	0.44116846	3592.6672
539.20166	1.5819128	0.44240639	3589.0566
540.10254	1.5839515	0.44354603	3592.2986
541.00342	1.590211	0.44471422	3596.4585
541.9043	1.5899918	0.44596922	3594.5671
542.80518	1.5956354	0.44714049	3597.7053
543.70605	1.5975978	0.44823241	3595.8708
544.60693	1.5991745	0.44947591	3594.8318
545.50781	1.6050766	0.45051742	3601.5266
546.40869	1.6038908	0.45180047	3600.7095
547.30957	1.6091925	0.45297706	3598.0581
548.21045	1.6115133	0.45420918	3597.5547
549.11133	1.6142582	0.45522377	3599.2883
550.01221	1.6161876	0.45640963	3604.6152
550.91309	1.6197256	0.45746091	3597.7515
551.81396	1.6216203	0.45842904	3595.9241
552.71484	1.625048	0.45955366	3605.2974
553.61572	1.6268836	0.46057481	3604.9119
554.5166	1.6277736	0.46190283	3603.8115
555.41748	1.6335856	0.46294051	3601.3594
556.31836	1.6321052	0.46410021	3604.6531
557.21924	1.638332	0.46518245	3605.6885
558.12012	1.6436919	0.46631289	3610.4038
559.021	1.6435677	0.46741804	3604.7881
559.92188	1.6454848	0.46868277	3607.0349
560.82275	1.6469525	0.46976078	3606.5796
561.72363	1.6508962	0.47099465	3614.9805
562.62451	1.6543753	0.47227091	3614.3538
563.52539	1.6545036	0.47352421	3608.4463
564.42627	1.6595176	0.47471625	3617.0977
565.32715	1.6609954	0.47582626	3610.5339
566.22803	1.6674907	0.47684008	3611.9194
567.12891	1.6685421	0.47802129	3619.4822
568.02979	1.6701229	0.47926837	3618.6235
568.93066	1.6720052	0.48057261	3619.2307
569.83154	1.6756967	0.48191559	3620.9321
570.73242	1.6754506	0.48311168	3615.9868
571.6333	1.6821115	0.48429897	3615.7161
572.53418	1.6850177	0.4854987	3622.0894
573.43506	1.6876749	0.48662096	3623.1589
574.33594	1.6880383	0.48783046	3616.6802
575.23682	1.6909449	0.48914132	3624.6418
576.1377	1.6949037	0.49032024	3624.0308
577.03857	1.696565	0.49168304	3627.1165
577.93945	1.7018028	0.49274004	3618.8813
578.84033	1.7022492	0.49374586	3617.4006
579.74121	1.7079961	0.49489388	3627.6326
580.64209	1.7093824	0.49613196	3629.6082
581.54297	1.7126955	0.49749756	3628.2681
582.44385	1.7148226	0.49845761	3625.2905
583.34473	1.7176996	0.49975064	3633.9353
584.24561	1.7215799	0.50111914	3629.699
585.14648	1.7189875	0.50231647	3630.2085
586.04736	1.7245425	0.50346327	3625.5686
586.94824	1.726998	0.50448829	3632.3411
587.84912	1.7323142	0.50551921	3629.6553
588.75	1.7305757	0.50670922	3636.1587
589.65088	1.733245	0.50783592	3636.9119
590.55176	1.7391987	0.50899297	3628.9451
591.45264	1.7408743	0.51013136	3628.0313
592.35352	1.7440016	0.51100439	3630.1599
593.25439	1.7463039	0.51201922	3633.9177
594.15527	1.7483954	0.5129832	3627.1638
595.05615	1.749938	0.5141201	3633.0259
595.95703	1.753203	0.51535964	3642.4775
596.85791	1.7566949	0.51677388	3638.7532
597.75879	1.7600876	0.51808572	3644.8865
598.65967	1.7616634	0.51951581	3640.5957
599.56055	1.7643497	0.52073777	3641.4226
600.46143	1.7669121	0.52209753	3633.4941
601.3623	1.7702112	0.52314389	3639.1824
602.26318	1.770748	0.52430683	3643.9407
603.16406	1.7789167	0.52560204	3642.7871
604.06494	1.7777691	0.52688974	3641.5061
604.96582	1.7806234	0.52811795	3637.6719
605.8667	1.7839295	0.5293622	3645.7383
606.76758	1.7870121	0.53061867	3642.1675
607.66846	1.7918167	0.53204077	3649.8931
608.56934	1.7922076	0.53328121	3644.7422
609.47021	1.796172	0.53465158	3651.9033
610.37109	1.7953709	0.53587538	3646.5854
611.27197	1.8010662	0.53720814	3648.9512
612.17285	1.8028446	0.53844994	3648.5212
613.07373	1.8079228	0.53970999	3652.2122
613.97461	1.8089229	0.54095811	3654.084
614.87549	1.8142354	0.5423249	3660.1536
615.77637	1.8113551	0.54359448	3649.1189
616.67725	1.8157668	0.54476595	3649.5461
617.57813	1.8205329	0.54585361	3654.1724
618.479	1.819483	0.54713345	3648.5803
619.37988	1.8242606	0.54818618	3653.4541
620.28076	1.8254676	0.54929131	3651.594
621.18164	1.8322762	0.55034715	3651.8545
622.08252	1.832574	0.55137265	3651.323
622.9834	1.8347452	0.5525676	3654.4561
623.88428	1.8361294	0.55358297	3654.2417
624.78516	1.8426	0.55501598	3658.2961
625.68604	1.8447694	0.55615175	3656.5281
626.58691	1.8475329	0.55734831	3661.8875
627.48779	1.849748	0.55870503	3659.4885
628.38867	1.8489423	0.56006992	3657.0747
629.28955	1.8537947	0.5614869	3657.0793
630.19043	1.8579152	0.56288946	3661.4377
631.09131	1.859355	0.56413686	3657.615
631.99219	1.8623593	0.56561917	3664.0232
632.89307	1.8660907	0.56687069	3660.8286
633.79395	1.8680933	0.56809443	3660.6526
634.69482	1.8718058	0.56900984	3652.9568
635.5957	1.8705746	0.57031059	3664.7009
636.49658	1.8788366	0.57143849	3662.1206
637.39746	1.8782346	0.5729295	3660.9531
638.29834	1.8816464	0.57420301	3660.9592
639.19922	1.8824422	0.57545024	3663.3428
640.1001	1.8887311	0.57677501	3673.0176
641.00098	1.8918042	0.57819903	3675.2947
641.90186	1.8895822	0.57966924	3666.3926
642.80273	1.894797	0.58077931	3663.8152
643.70361	1.8967168	0.58197528	3670.1609
644.60449	1.8989228	0.58323526	3659.9529
645.50537	1.8997942	0.58476222	3673.511
646.40625	1.9056774	0.58611441	3671.5798
647.30713	1.9069132	0.58759409	3671.5952
648.20801	1.9110209	0.58893269	3670.6606
649.10889	1.9160335	0.59043854	3680.5398
650.00977	1.9181334	0.59177852	3665.9646
650.91064	1.9173839	0.59295017	3668.0918
651.81152	1.9210711	0.59429741	3678.9629
652.7124	1.9241188	0.59547782	3668.0232
653.61328	1.9275734	0.59672219	3675.9104
654.51416	1.9295238	0.59793711	3673.178
655.41504	1.9351979	0.59920681	3675.1572
656.31592	1.9362642	0.60036516	3672.5845
657.2168	1.9372902	0.60172856	3679.8225
658.11768	1.9405507	0.60308242	3677.2722
659.01855	1.9440588	0.60452163	3679.1777
659.91943	1.9428586	0.60584617	3672.9497
660.82031	1.9482245	0.60715729	3678.5935
661.72119	1.9545794	0.60840023	3672.5957
662.62207	1.9539834	0.6094197	3676.5286
663.52295	1.9578531	0.61116612	3688.6531
664.42383	1.9579121	0.61243808	3678.1648
665.32471	1.9622389	0.61367923	3672.4004
666.22559	1.9633187	0.61476773	3673.9385
667.12646	1.9707367	0.6161707	3683.7043
668.02734	1.9707952	0.61754739	3681.1174
668.92822	1.9755198	0.61889434	3682.3782
669.8291	1.9772118	0.62023437	3683.7813
670.72998	1.9774384	0.62174451	3683.0337
671.63086	1.9805521	0.62282783	3669.5552
672.53174	1.9847389	0.62429285	3686.4434
673.43262	1.9885294	0.62558687	3686.4478
674.3335	1.9897912	0.62683809	3680.8845
675.23438	1.9955405	0.62789512	3687.574
676.13525	1.9948845	0.62906188	3683.4148
677.03613	1.9978131	0.63038784	3687.2249
677.93701	1.9970082	0.63191462	3686.072
678.83789	2.0056205	0.63367993	3686.7727
679.73877	2.0030231	0.63506508	3680.0642
680.63965	2.0098798	0.63655216	3695.4795
681.54053	2.0129666	0.63771111	3685.7656
682.44141	2.0155556	0.63905793	3685.145
683.34229	2.0161717	0.64029258	3688.0715
684.24316	2.018316	0.64156961	3688.2532
685.14404	2.0247946	0.64290863	3686.3054
686.04492	2.0258787	0.64420027	3690.9094
686.9458	2.0273542	0.6455943	3688.6487
687.84668	2.0298722	0.64685452	3685.4805
688.74756	2.0355632	0.64837718	3693.2954
689.64844	2.0351329	0.65016556	3697.2844
690.54932	2.0366938	0.65182132	3689.3711
691.4502	2.0419934	0.65316498	3691.8479
692.35107	2.0444536	0.65474898	3691.3279
693.25195	2.0448325	0.65603101	3687.1519
694.15283	2.0485992	0.65737587	3681.7507
695.05371	2.0519352	0.65855652	3687.2124
695.95459	2.056077	0.6600343	3690.741
696.85547	2.0537741	0.66116846	3688.1895
697.75635	2.0574658	0.66247404	3688.9749
698.65723	2.0612323	0.66391355	3693.9614
699.55811	2.0663044	0.66521764	3689.9641
700.45898	2.0648005	0.66661453	3694.8123
701.35986	2.0693049	0.66798759	3693.3748
702.26074	2.072278	0.66941786	3693.3718
703.16162	2.0743635	0.67083836	3691.9031
704.0625	2.0791743	0.67222768	3695.6038
704.96338	2.0830858	0.67349106	3696.4055
705.86426	2.0845826	0.67485458	3696.6541
706.76514	2.0860701	0.67617875	3691.7068
707.66602	2.0901859	0.67763984	3697.9868
708.56689	2.091996	0.67930013	3702.9673
709.46777	2.0957286	0.6807549	3697.0774
710.36865	2.0988977	0.68223131	3696.0676
711.26953	2.0994444	0.68370473	3695.8647
712.17041	2.1042752	0.68529755	3695.1511
713.07129	2.1063249	0.68700475	3703.4016
713.97217	2.1086292	0.68870914	3698.8872
714.87305	2.1111114	0.69024229	3695.5195
715.77393	2.11116	0.6917038	3692.4795
716.6748	2.1158431	0.69290555	3693.1729
717.57568	2.1165938	0.69408071	3688.7468
718.47656	2.1216328	0.69556957	3695.7888
719.37744	2.1239216	0.69698137	3703.4324
720.27832	2.1253278	0.69838506	3694.3303
721.1792	2.1293371	0.69992274	3702.844
722.08008	2.1323593	0.70159006	3703.0879
722.98096	2.1376674	0.70298809	3702.9468
723.88184	2.139756	0.70450628	3704.2759
724.78271	2.1415358	0.70598835	3701.9009
725.68359	2.1473043	0.70732188	3707.0977
726.58447	2.1428783	0.70890749	3702.0579
727.48535	2.1453826	0.71030301	3701.5002
728.38623	2.1509409	0.7116769	3699.6824
729.28711	2.156045	0.71295464	3702.2854
730.18799	2.1591384	0.71442074	3703.104
731.08887	2.160552	0.71581781	3700.8728
731.98975	2.161622	0.71707839	3699.6143
732.89063	2.1660182	0.71846598	3701.2776
733.7915	2.1681478	0.71973175	3694.4966
734.69238	2.172308	0.72094631	3703.5647
735.59326	2.1723301	0.72219658	3699.6711
736.49414	2.1743481	0.72374088	3709.6096
737.39502	2.1785917	0.72537869	3704.3325
738.2959	2.1817377	0.72709805	3712.364
739.19678	2.183135	0.72883081	3702.415
740.09766	2.185781	0.73045242	3700.0007
740.99854	2.1901035	0.73214424	3706.7441
741.89941	2.1913834	0.73377502	3706.417
742.80029	2.1957724	0.73531991	3700.6082
743.70117	2.2009199	0.73668456	3706.2017
744.60205	2.2002299	0.73851329	3707.738
745.50293	2.2043097	0.74000037	3704.3022
746.40381	2.2068062	0.74165654	3709.2551
747.30469	2.2080891	0.74322504	3702.2583
748.20557	2.2074847	0.7450422	3707.5322
749.10645	2.2129481	0.74667418	3708.2109
750.00732	2.2190027	0.74807483	3698.5857
750.9082	2.2183821	0.74956107	3703.072
751.80908	2.2224584	0.75105542	3708.0059
752.70996	2.2234862	0.75235528	3705.9148
753.61084	2.227447	0.75385493	3706.0566
754.51172	2.2295015	0.75537789	3706.9146
755.4126	2.2333403	0.75698858	3708.5527
756.31348	2.2346828	0.75858533	3704.6299
757.21436	2.2388029	0.76025379	3711.8901
758.11523	2.2380502	0.7617175	3697.2578
759.01611	2.2413137	0.76358068	3710.9934
759.91699	2.2480066	0.76533091	3708.3816
760.81787	2.2496285	0.76704842	3709.2615
761.71875	2.2489116	0.76850086	3702.9136
762.61963	2.2551191	0.77008283	3709.645
763.52051	2.254308	0.77175939	3705.9102
764.42139	2.2585006	0.77330756	3703.2097
765.32227	2.2638533	0.77480394	3706.6721
766.22314	2.2623506	0.77643549	3710.978
767.12402	2.2687457	0.77805257	3712.2539
768.0249	2.2706227	0.779764	3697.415
768.92578	2.2736228	0.78129286	3705.7524
769.82666	2.2742724	0.78285736	3702.2244
770.72754	2.2800198	0.78443193	3710.2141
771.62842	2.2812641	0.78601533	3704.7649
772.5293	2.285598	0.78791952	3711.1287
773.43018	2.2871759	0.79005027	3711.647
774.33105	2.2883904	0.79134917	3699.8848
775.23193	2.2919264	0.79258907	3699.3164
776.13281	2.2931879	0.79389602	3707.0762
777.03369	2.2990484	0.79511148	3707.8416
777.93457	2.3012948	0.79672843	3717.3835
778.83545	2.303087	0.79887831	3713.2085
779.73633	2.3084373	0.80097967	3711.4419
780.63721	2.3081837	0.80285913	3707.4875
781.53809	2.309299	0.80476624	3710.5142
782.43896	2.3126698	0.80659014	3708.686
783.33984	2.3185797	0.80808353	3707.4438
784.24072	2.3187625	0.80965704	3707.5278
785.1416	2.3203506	0.81132931	3706.3496
786.04248	2.3256776	0.81307036	3710.3708
786.94336	2.3268504	0.81506294	3713.2046
787.84424	2.3290823	0.81692398	3708.8511
788.74512	2.3317177	0.81867868	3713.7783
789.646	2.3347669	0.82088029	3710.8618
790.54688	2.3408864	0.82271808	3707.4607
791.44775	2.3404245	0.82401168	3701.3433
792.34863	2.3438323	0.82530248	3705.8821
793.24951	2.3469269	0.82672745	3704.2397
794.15039	2.3503098	0.8283428	3706.3191
795.05127	2.353245	0.83024657	3711.752
795.95215	2.3533294	0.8320455	3705.8201
796.85303	2.3572104	0.83380193	3702.762
797.75391	2.3603458	0.83569223	3712.8789
798.65479	2.3618336	0.83736378	3705.1646
799.55566	2.3644197	0.83892345	3706.4124
800.45654	2.3658354	0.84091789	3711.8755
801.35742	2.3705971	0.84289336	3704.2314
802.2583	2.3738031	0.84487969	3711.7825
803.15918	2.3750796	0.84646505	3699.8804
804.06006	2.3760848	0.8481977	3703.5684
804.96094	2.3822851	0.84970355	3704.9241
805.86182	2.3835654	0.8517012	3708.0708
806.7627	2.3858712	0.85363889	3707.208
807.66357	2.3877842	0.85535055	3708.366
808.56445	2.391789	0.85711938	3699.4531
809.46533	2.3944147	0.85887182	3707.7327
810.36621	2.397583	0.86110437	3709.1628
811.26709	2.4001055	0.86317223	3711.6582
812.16797	2.3996069	0.86505294	3698.4878
813.06885	2.4035163	0.86686438	3704.8408
813.96973	2.4106345	0.86858481	3702.4949
814.87061	2.4104154	0.87034583	3701.2559
815.77148	2.4150681	0.87222338	3713.77
816.67236	2.4156103	0.87383968	3708.531
817.57324	2.419153	0.87569541	3705.1646
818.47412	2.4204996	0.87748897	3705.7144
819.375	2.4263675	0.87921625	3705.146
820.27588	2.4262533	0.88110751	3709.2573
821.17676	2.4320595	0.88329667	3708.8804
822.07764	2.4332285	0.88548154	3705.1292
822.97852	2.4336498	0.88746917	3700.2007
823.87939	2.4376338	0.88971031	3698.9861
824.78027	2.440721	0.89153403	3700.9536
825.68115	2.444922	0.89356822	3705.0198
826.58203	2.4464993	0.89547634	3701.7126
827.48291	2.4511499	0.89728588	3705.2222
828.38379	2.4502234	0.89916974	3701.8047
829.28467	2.4560738	0.9013254	3705.8743
830.18555	2.4554846	0.90355122	3700.8743
831.08643	2.4602749	0.90541416	3699.9482
831.9873	2.4626191	0.90710586	3696.8945
832.88818	2.4672096	0.90902174	3704.2849
833.78906	2.4667895	0.91122961	3705.907
834.68994	2.4688194	0.91344959	3696.4441
835.59082	2.4732389	0.91525418	3697.6785
836.4917	2.4757071	0.91699487	3702.594
837.39258	2.478646	0.91880858	3696.0249
838.29346	2.4821429	0.92080498	3703.8232
839.19434	2.4823985	0.92338043	3699.3799
840.09521	2.4854038	0.92581242	3698.3945
840.99609	2.488539	0.9277122	3693.0364
841.89697	2.49365	0.92986232	3696.4678
842.79785	2.4949558	0.93190229	3697.1279
843.69873	2.4988313	0.93409586	3702.0098
844.59961	2.5020204	0.93600911	3695.009
845.50049	2.504705	0.93782973	3692.7832
846.40137	2.5074124	0.9397586	3696.1892
847.30225	2.5078716	0.94170642	3694.1848
848.20313	2.5121899	0.94419748	3698.2776
849.104	2.5151119	0.94599438	3691.1736
850.00488	2.517853	0.94821411	3701.5984
850.90576	2.5182381	0.95038682	3684.5557
851.80664	2.5237427	0.9525125	3696.3342
852.70752	2.523844	0.95498008	3697.2383
853.6084	2.526881	0.95732051	3694.7983
854.50928	2.5296602	0.95954221	3689.0332
855.41016	2.5332842	0.9617148	3689.8708
856.31104	2.5335114	0.96367133	3682.8799
857.21191	2.5386374	0.96548325	3691.137
858.11279	2.5398703	0.96776134	3686.7202
859.01367	2.5440176	0.96974397	3690.5635
859.91455	2.5494606	0.97179025	3689.9233
860.81543	2.5462837	0.97387028	3688.9509
861.71631	2.5519836	0.97619128	3690.1272
862.61719	2.5531371	0.97843277	3685.4448
863.51807	2.5534716	0.98089635	3694.4583
864.41895	2.5596101	0.98336923	3687.5986
865.31982	2.5592136	0.98579639	3680.3325
866.2207	2.5687208	0.98805112	3683.7629
867.12158	2.5672424	0.99021327	3678.5652
868.02246	2.5704918	0.99230325	3676.8064
868.92334	2.5756056	0.99455702	3681.9241
869.82422	2.5761933	0.99685693	3681.7651
870.7251	2.5778689	0.99916118	3684.968
871.62598	2.5797613	1.0015128	3680.4688
872.52686	2.5824444	1.0041323	3675.53
873.42773	2.5891659	1.0065244	3676.6353
874.32861	2.5888309	1.0086968	3672.3896
875.22949	2.5924995	1.0105183	3673.6953
876.13037	2.5933905	1.0127399	3674.814
877.03125	2.5972228	1.0149817	3677.8181
877.93213	2.5993767	1.0173621	3677.3655
878.83301	2.602886	1.0198743	3673.4436
879.73389	2.6036091	1.02262	3667.9934
880.63477	2.6073592	1.0248773	3671.3169
881.53564	2.6094215	1.0273409	3672.2551
882.43652	2.6142163	1.0296015	3667.5117
883.3374	2.6172149	1.0320314	3668.1616
884.23828	2.6178226	1.0344241	3666.1877
885.13916	2.6226878	1.0368211	3668.488
886.04004	2.6242268	1.039227	3663.6965
886.94092	2.6290271	1.0414683	3664.8591
887.8418	2.6301851	1.0438162	3662.8215
888.74268	2.6336136	1.0461087	3666.7314
889.64355	2.6381955	1.0487529	3662.3389
890.54443	2.6398699	1.0514075	3659.0046
891.44531	2.6428499	1.0537964	3658.7739
892.34619	2.6455314	1.0565947	3657.7974
893.24707	2.6451216	1.0592	3652.7729
894.14795	2.6470916	1.0618647	3651.7263
895.04883	2.6501403	1.0644118	3653.3213
895.94971	2.6530731	1.0670263	3652.0864
896.85059	2.6594057	1.0697184	3651.7402
897.75146	2.6622357	1.0723978	3648.7402
898.65234	2.663904	1.0748709	3648.3298
899.55322	2.6638703	1.0772762	3642.4336
900.4541	2.6691353	1.079733	3647.2573
901.35498	2.6694655	1.0825307	3645.2773
902.25586	2.6729915	1.0849065	3642.8401
903.15674	2.6731386	1.0873041	3639.1438
904.05762	2.6783047	1.0893124	3635.9031
904.9585	2.6823001	1.0915539	3646.2078
905.85938	2.6837354	1.0944268	3637.863
906.76025	2.6847558	1.0972049	3630.53
907.66113	2.6908975	1.0995926	3630.1182
908.56201	2.6917531	1.1020439	3626.5596
909.46289	2.6942718	1.1045177	3630.1223
910.36377	2.6993194	1.1070883	3628.8384
911.26465	2.6989946	1.1095244	3623.4119
912.16553	2.7034557	1.112072	3627.1387
913.06641	2.7049267	1.1148573	3618.5046
913.96729	2.7099893	1.1177638	3622.8611
914.86816	2.7121906	1.1207856	3615.1584
915.76904	2.7147403	1.1232527	3612.4023
916.66992	2.7145257	1.1256112	3604.7493
917.5708	2.7187166	1.1281545	3611.4619
918.47168	2.7218626	1.1308366	3613.1516
919.37256	2.7239625	1.1338078	3607.7322
920.27344	2.728821	1.1367797	3609.4043
921.17432	2.7290885	1.1393081	3599.2158
922.0752	2.7318649	1.1416996	3597.4294
922.97607	2.7364359	1.1444734	3603.9414
923.87695	2.7405999	1.147393	3598.1516
924.77783	2.7436814	1.1499466	3597.6851
925.67871	2.7456465	1.1526036	3597.4119
926.57959	2.7457559	1.1553935	3588.0759
927.48047	2.7492559	1.1583866	3590.3115
928.38135	2.7494278	1.161038	3584.5308
929.28223	2.75703	1.1639823	3590.5942
930.18311	2.7540715	1.1673335	3574.769
931.08398	2.7601619	1.1701692	3578.0259
931.98486	2.7608321	1.1726421	3573.7764
932.88574	2.7652702	1.1750724	3580.0032
933.78662	2.7680185	1.1780518	3573.0811
934.6875	2.7732372	1.1806744	3568.6252
935.58838	2.7750325	1.183646	3572.7283
936.48926	2.7765203	1.1866853	3565.7305
937.39014	2.7807419	1.1894723	3559.991
938.29102	2.7787638	1.1919302	3552.0476
939.19189	2.7843909	1.1944139	3553.4775
940.09277	2.7875586	1.1977797	3555.6106
940.99365	2.7923324	1.2009381	3551.5833
941.89453	2.7940283	1.2036916	3540.3411
942.79541	2.7951379	1.2065003	3545.1331
943.69629	2.7950935	1.2092514	3540.0388
944.59717	2.7985053	1.2120237	3533.6123
945.49805	2.8045413	1.2148889	3539.2412
946.39893	2.8057141	1.2175533	3531.8638
947.2998	2.8093572	1.2202832	3525.5913
948.20068	2.8105435	1.2225713	3525.5046
949.10156	2.8152454	1.2252051	3526.6853
950.00244	2.8163342	1.2277324	3517.2869
950.90332	2.8194757	1.2305847	3521.6462
951.8042	2.8208306	1.2338569	3511.8809
952.70508	2.8223011	1.2364582	3511.9316
953.60596	2.8259439	1.2395802	3507.0784
954.50684	2.8282909	1.2423617	3503.6331
955.40771	2.8309443	1.2446593	3495.4783
956.30859	2.8358824	1.2472413	3502.3054
957.20947	2.8381798	1.2506042	3497.0454
958.11035	2.841284	1.2541934	3492.3599
959.01123	2.8439205	1.2573074	3484.8677
959.91211	2.8474712	1.2603896	3486.5559
960.81299	2.8481667	1.2632104	3477.1592
961.71387	2.8510954	1.266395	3479.3147
962.61475	2.8516798	1.2696593	3465.4189
963.51563	2.8563607	1.2725639	3462.3533
964.4165	2.8605931	1.2756603	3465.0779
965.31738	2.8606832	1.2788248	3459.5115
966.21826	2.865433	1.2815295	3454.0437
967.11914	2.8687577	1.2841259	3452.8635
968.02002	2.8711593	1.2875712	3451.1917
968.9209	2.8741789	1.2913765	3447.2437
969.82178	2.8775847	1.2948918	3435.0193
970.72266	2.8788218	1.297974	3427.1257
971.62354	2.8821683	1.3009924	3429.7266
972.52441	2.8843224	1.3039424	3423.3206
973.42529	2.8867207	1.3070703	3415.3689
974.32617	2.8908174	1.3100545	3405.4841
975.22705	2.8924191	1.3128589	3403.988
976.12793	2.8947246	1.315518	3392.6919
977.02881	2.8958011	1.3188598	3396.5854
977.92969	2.9019432	1.3222529	3386.0444
978.83057	2.8998547	1.3246746	3377.3228
979.73145	2.9071109	1.3275001	3376.4539
980.63232	2.9085898	1.3306673	3370.1326
981.5332	2.9099498	1.3338565	3357.7739
982.43408	2.9138598	1.3372216	3354.1179
983.33496	2.9182224	1.3408735	3342.8545
984.23584	2.92261	1.3447289	3331.1133
985.13672	2.9247451	1.3489628	3317.8213
986.0376	2.9253221	1.3527025	3300.1182
986.93848	2.9300835	1.3564463	3292.7527
987.83936	2.9300799	1.3628341	3248.4592
988.74023	2.9367018	1.3687239	3212.5574
989.64111	2.939889	1.3736968	3197.864
990.54199	2.9425378	1.378673	3169.6167
991.44287	2.9435122	1.3833822	3139.7795
992.04346	2.947032	1.3925109	3067.6833