File: datasets/am_bench_2022/raw_data/45-XY.02-4/specimen.dat
MTS793|MPT|ENU|1|2|.|/|:|1|0|0|A

Operator Information						Time:	33.914795	Sec	10/19/2021 11:40:20 AM
Operator	Newell Moser
Project	AM Bench 2022 mini-tensile challenge
Specimen ID	45-XY.02-4
Material	PBF-L Inconel 625
Specimen Width	2.55	mm
Specimen Thickness	1.49	mm
Notes
Operator Information End

Data Acquisition						Time:	1034.9087	Sec	10/19/2021 11:57:01 AM
Time	Axial Displacement	Axial Extensometer	Axial Force
Sec	mm	mm	N
34.028564	-0.0007690714	7.5343953e-05	25.957409
35.129639	-0.0028415436	0.00012597149	37.8894
36.230713	0.0060914466	0.00017857007	52.468937
37.331787	0.0081228893	0.00018310636	68.301682
38.432861	0.011196203	0.00021414734	82.616074
39.533936	0.012642528	0.00022887798	93.400024
40.63501	0.014390811	0.00035629555	106.7135
41.736084	0.020197369	0.00033383543	123.96953
42.837158	0.027236091	0.00045849723	137.02861
43.938232	0.027292641	0.00055998692	149.17087
45.039307	0.033939663	0.00060660369	167.04129
46.140381	0.035280265	0.00067202025	182.13744
47.241455	0.036072168	0.00080022257	202.30562
48.342529	0.040726982	0.00073592883	228.04077
49.443604	0.042466506	0.00094170694	250.37181
50.544678	0.045398496	0.00099258858	268.73203
51.645752	0.048948593	0.0010741055	295.75546
52.746826	0.055309124	0.0011605202	317.84506
53.8479	0.057117492	0.0012932548	338.79944
54.948975	0.060657956	0.0013652443	366.03879
56.050049	0.061378557	0.0014081115	390.26328
57.151123	0.066503651	0.0016084426	417.64215
58.252197	0.069771811	0.001742051	442.51898
59.353271	0.072152853	0.0018905581	461.6553
60.454346	0.076917492	0.0019389779	484.4454
61.55542	0.078169577	0.0020374709	510.077
62.656494	0.083075024	0.0020798589	529.89563
63.757568	0.087828651	0.0022095374	561.84216
64.858643	0.092980586	0.0023719349	594.21472
65.959717	0.094986208	0.002559778	623.03271
67.060791	0.091457218	0.0025334824	645.74396
68.161865	0.10033238	0.0027127722	683.97815
69.262939	0.10015064	0.0027856387	710.28271
70.364014	0.10483337	0.0029385672	741.78119
71.465088	0.10751801	0.0029918223	770.06256
72.566162	0.11152547	0.0032362214	798.89099
73.667236	0.11644936	0.0033159149	826.02045
74.768311	0.11716007	0.0034674748	847.64624
75.869385	0.12281378	0.003594961	883.77869
76.970459	0.12303097	0.0036749698	910.16833
78.071533	0.12941778	0.0037715298	950.66602
79.172607	0.13216081	0.0039581629	973.27869
80.273682	0.13445041	0.0039935345	1001.7131
81.374756	0.13866769	0.0042598853	1043.2521
82.47583	0.14075527	0.0043340684	1066.887
83.576904	0.14635099	0.0045176242	1101.5085
84.677979	0.14753684	0.0046096393	1129.5767
85.779053	0.1514142	0.0047829016	1163.7581
86.880127	0.15711996	0.0048642503	1197.8951
87.981201	0.15858631	0.0049346499	1222.2084
89.082275	0.16092181	0.0050937044	1253.7638
90.18335	0.16347496	0.0052774572	1289.0142
91.284424	0.16651882	0.0053796433	1323.2356
92.385498	0.16918501	0.0055781314	1353.2258
93.486572	0.17584325	0.0057658055	1388.9315
94.587646	0.17868201	0.0057696369	1419.9551
95.688721	0.17981732	0.0058906884	1450.8987
96.789795	0.18279372	0.0061438363	1481.1267
97.890869	0.18718305	0.0062350621	1511.6652
98.991943	0.18969947	0.0063770209	1539.7415
100.09302	0.19323999	0.0062937746	1557.8252
101.19409	0.19813964	0.0065664938	1585.9523
102.29517	0.20262404	0.0067204139	1616.25
103.39624	0.2048678	0.0067477012	1641.85
104.49731	0.20970051	0.0068469862	1680.5731
105.59839	0.21109946	0.0070865089	1703.1045
106.69946	0.21536134	0.0072073392	1732.063
107.80054	0.21799338	0.0073250532	1758.6873
108.90161	0.21906392	0.0073286309	1781.3939
110.00269	0.22350346	0.0075154146	1809.4446
111.10376	0.22752438	0.0075789634	1835.4645
112.20483	0.22881658	0.0076195677	1862.8164
113.30591	0.23211184	0.0078134909	1889.8514
114.40698	0.24025841	0.0079667801	1920.5946
115.50806	0.24073663	0.0080378102	1941.2742
116.60913	0.24459714	0.0082090162	1962.3101
117.71021	0.24812612	0.0083047105	1993.5505
118.81128	0.25091654	0.008351217	2008.4567
119.91235	0.25294837	0.0084963674	2031.8931
121.01343	0.25604117	0.008564624	2050.3213
122.1145	0.26095977	0.0087080225	2077.491
123.21558	0.26482555	0.0087876832	2093.9976
124.31665	0.26730841	0.0088715767	2114.2017
125.41772	0.27121153	0.0090061724	2129.7668
126.5188	0.27513209	0.0090672243	2153.6494
127.61987	0.27751252	0.009232684	2168.3896
128.72095	0.28307131	0.0092264926	2190.354
129.82202	0.28344667	0.0093634604	2202.0164
130.9231	0.28764591	0.0094065443	2217.03
132.02417	0.29118001	0.0094835553	2246.9136
133.12524	0.29954848	0.0095892521	2257.0535
134.22632	0.29659742	0.009693237	2266.3
135.32739	0.3025009	0.0097004538	2275.8926
136.42847	0.30302277	0.0098629789	2290.1807
137.52954	0.30639032	0.010028496	2318.4536
138.63062	0.31161579	0.010104428	2325.5959
139.73169	0.3134172	0.010127597	2334.1895
140.83276	0.31646365	0.010194444	2351.2234
141.93384	0.32146624	0.010314595	2361.8206
143.03491	0.32441682	0.010467811	2375.1882
144.13599	0.32839888	0.010589785	2391.9258
145.23706	0.33071205	0.010690742	2396.5815
146.33813	0.33207205	0.010706976	2409.3538
147.43921	0.33728424	0.010808513	2421.2605
148.54028	0.34046659	0.01095515	2434.4768
149.64136	0.34636489	0.011134855	2449.3533
150.74243	0.34630096	0.011205639	2457.8982
151.84351	0.35071611	0.011273014	2466.0969
152.94458	0.3543652	0.011478559	2479.1204
154.04565	0.35709655	0.011602734	2485.9006
155.14673	0.35825768	0.011760256	2503.2815
156.2478	0.36396071	0.011836287	2512.6494
157.34888	0.36742255	0.012114099	2520.665
158.44995	0.37397569	0.012369263	2538.9236
159.55103	0.37571189	0.012495163	2530.9238
160.6521	0.37871948	0.012620538	2544.9558
161.75317	0.37859982	0.012866257	2554.801
162.85425	0.38502455	0.013000516	2571.3777
163.95532	0.38609749	0.013295753	2581.342
165.0564	0.3912068	0.013471662	2591.8093
166.15747	0.39290392	0.013699039	2595.386
167.25854	0.39700088	0.013951966	2595.2244
168.35962	0.39954886	0.014124859	2606.103
169.46069	0.40577585	0.014394017	2616.4421
170.56177	0.40875515	0.014648215	2632.8665
171.66284	0.40830666	0.015026754	2637.9985
172.76392	0.41175082	0.01532513	2647.3667
173.86499	0.41729507	0.015596869	2654.5867
174.96606	0.42162645	0.016092429	2663.3772
176.06714	0.42181456	0.0162687	2661.3799
177.16821	0.42931196	0.016642068	2675.9055
178.26929	0.42931792	0.017053017	2680.8503
179.37036	0.4320825	0.017448762	2686.8997
180.47144	0.43830007	0.017845862	2698.1084
181.57251	0.43980166	0.01838308	2702.3806
182.67358	0.44258738	0.018865084	2709.4128
183.77466	0.44761023	0.019400967	2720.761
184.87573	0.44865352	0.019910045	2719.4373
185.97681	0.45516589	0.020461209	2726.4346
187.07788	0.45581865	0.021168733	2729.5515
188.17896	0.45751861	0.021709103	2735.002
189.28003	0.46256259	0.022307897	2741.4263
190.3811	0.4656558	0.023024578	2750.7056
191.48218	0.47331983	0.02387573	2765.2168
192.58325	0.47284776	0.024642956	2755.6138
193.68433	0.47876415	0.025297899	2771.4595
194.7854	0.48112404	0.026078492	2771.2603
195.88647	0.48393857	0.026919646	2781.1416
196.98755	0.48746762	0.027896956	2784.51
198.08862	0.4905645	0.028844984	2786.5442
199.1897	0.49253902	0.02976577	2790.0879
200.29077	0.49577808	0.030752858	2792.106
201.39185	0.49979371	0.031762447	2800.5732
202.49292	0.50510275	0.032805264	2801.1331
203.59399	0.50754869	0.033809949	2806.8362
204.69507	0.50989878	0.034814298	2799.5886
205.79614	0.51421338	0.035895657	2809.9951
206.89722	0.51674944	0.036781915	2806.3276
207.99829	0.51987129	0.037727132	2815.7351
209.09937	0.52358162	0.038615301	2816.8601
210.20044	0.52427888	0.039799202	2826.2913
211.30151	0.52869183	0.040851615	2823.8293
212.40259	0.53488946	0.041917745	2828.6331
213.50366	0.536394	0.043134142	2835.4353
214.60474	0.53796607	0.044403836	2832.1638
215.70581	0.54435331	0.045493681	2834.4839
216.80688	0.54799002	0.046559099	2839.7058
217.90796	0.54894567	0.047689367	2837.9512
219.00903	0.55053186	0.048921835	2844.1545
220.11011	0.55801588	0.050149526	2849.2183
221.21118	0.56054318	0.051497635	2854.5955
222.31226	0.56440282	0.052838277	2855.8582
223.41333	0.56594753	0.054068472	2855.2007
224.5144	0.56896186	0.055340517	2860.5806
225.61548	0.57414466	0.056624398	2861.574
226.71655	0.57903069	0.058058452	2866.8494
227.81763	0.57973796	0.059491642	2875.3423
228.9187	0.58194852	0.06071011	2866.1809
230.01978	0.58529943	0.061937477	2867.0535
231.12085	0.58998668	0.063433394	2876.592
232.22192	0.59403098	0.064773433	2878.124
233.323	0.59773678	0.065986983	2873.6624
234.42407	0.59950089	0.06711711	2876.3899
235.52515	0.60223514	0.068157993	2878.9978
236.62622	0.60427642	0.069320224	2879.8296
237.72729	0.60757023	0.070494287	2887.4185
238.82837	0.6135366	0.071890093	2882.4102
239.92944	0.61199766	0.072760977	2882.8743
241.03052	0.61880857	0.073904432	2890.4775
242.13159	0.62118942	0.075235561	2893.7068
243.23267	0.62440777	0.076592341	2900.1804
244.33374	0.63041657	0.077721983	2891.4377
245.43481	0.63426352	0.078946501	2904.5657
246.53589	0.63612968	0.080327764	2905.6892
247.63696	0.63820356	0.081750207	2902.5105
248.73804	0.6402545	0.082983337	2903.3674
249.83911	0.64488167	0.08408159	2912.821
250.94019	0.65165305	0.085757256	2917.7004
252.04126	0.65217817	0.087162651	2911.2583
253.14233	0.65534145	0.088363878	2911.728
254.24341	0.6600129	0.089749865	2918.0122
255.34448	0.66363376	0.091186948	2923.2837
256.44556	0.66436249	0.092615947	2917.2234
257.54663	0.66701335	0.094038904	2924.3748
258.64771	0.67167085	0.0954521	2926.2808
259.74878	0.67085212	0.096913286	2927.4912
260.84985	0.67740756	0.098267831	2929.5195
261.95093	0.68431556	0.099712759	2930.771
263.052	0.68375498	0.10093305	2930.3025
264.15308	0.68930668	0.10237309	2936.3286
265.25415	0.68948388	0.10352974	2936.0586
266.35522	0.69763333	0.10467785	2937.4097
267.4563	0.69613111	0.10581849	2933.7983
268.55737	0.70015794	0.10712048	2936.8616
269.65845	0.70465893	0.10866696	2941.5054
270.75952	0.70771939	0.10978348	2947.6636
271.8606	0.71271944	0.11103963	2939.053
272.96167	0.7151376	0.11214418	2946.175
274.06274	0.71899134	0.11350162	2950.9888
275.16382	0.7212832	0.11494134	2954.0945
276.26489	0.7255742	0.11610092	2949.104
277.36597	0.72992361	0.11753304	2953.645
278.46704	0.73451126	0.11866695	2953.873
279.56812	0.73394799	0.11995739	2960.0137
280.66919	0.73882926	0.12134416	2959.3364
281.77026	0.7420122	0.12242686	2960.8076
282.87134	0.7428211	0.12388879	2963.6919
283.97241	0.75082242	0.12527306	2970.627
285.07349	0.75115967	0.12658693	2963.0325
286.17456	0.75345176	0.12794803	2961.9204
287.27563	0.7595945	0.12910523	2967.0308
288.37671	0.76319379	0.13046882	2971.2881
289.47778	0.76392651	0.13190547	2982.3342
290.57886	0.76684225	0.13337474	2975.6826
291.67993	0.77097958	0.13467267	2976.863
292.78101	0.77375871	0.13585	2980.7817
293.88208	0.77851391	0.13722537	2981.9619
294.98315	0.78028107	0.13842112	2978.5928
296.08423	0.7873227	0.13981818	2980.6538
297.1853	0.78974634	0.1411801	2983.5022
298.28638	0.78961068	0.14231829	2988.4683
299.38745	0.79545677	0.14371145	2992.3953
300.48853	0.79654294	0.14509347	2996.2212
301.5896	0.80367714	0.14657749	2996.762
302.69067	0.80542153	0.14809348	2997.9282
303.79175	0.80708933	0.14960128	2996.2676
304.89282	0.81376153	0.15065321	2998.7576
305.9939	0.81685966	0.15186204	2996.1746
307.09497	0.81703711	0.15303513	2998.1064
308.19604	0.82016861	0.15429537	3004.4229
309.29712	0.82467002	0.15573521	3002.4709
310.39819	0.82995141	0.15696184	3003.0918
311.49927	0.82811075	0.15803133	2995.7539
312.60034	0.83348757	0.15926829	3009.2375
313.70142	0.83808571	0.16036566	3014.9858
314.80249	0.84298664	0.16175926	3016.1821
315.90356	0.84684527	0.16299899	3015.3086
317.00464	0.84453171	0.16434772	3012.3074
318.10571	0.85204911	0.16568638	3018.1638
319.20679	0.8553105	0.16710959	3014.0244
320.30786	0.85661888	0.16840547	3010.1323
321.40894	0.85773021	0.16956688	3018.9565
322.51001	0.86662793	0.17070392	3027.4846
323.61108	0.86586964	0.17203513	3026.9421
324.71216	0.8727358	0.17327574	3022.3879
325.81323	0.87369454	0.17443261	3027.874
326.91431	0.87616593	0.17610432	3029.5254
328.01538	0.88059741	0.17745791	3034.3154
329.11646	0.88267928	0.17879617	3032.3748
330.21753	0.89105356	0.18000281	3042.7317
331.3186	0.88880754	0.18141267	3032.6499
332.41968	0.89387155	0.18270253	3038.9209
333.52075	0.89653409	0.18417794	3038.886
334.62183	0.89743781	0.18538041	3038.1516
335.7229	0.90216583	0.18671708	3038.6233
336.82397	0.90895814	0.18810502	3050.0061
337.92505	0.90742761	0.189503	3042.7654
339.02612	0.91275424	0.19092213	3045.0618
340.1272	0.91686743	0.19228086	3045.5798
341.22827	0.92088389	0.19362997	3052.3999
342.32935	0.92307085	0.19492	3049.2405
343.43042	0.92921913	0.19620825	3057.9946
344.53149	0.92934293	0.19760989	3060.8525
345.63257	0.93228924	0.19881417	3049.1384
346.73364	0.93603581	0.20003496	3057.5513
347.83472	0.94295609	0.20122388	3059.3882
348.93579	0.94572544	0.20241992	3058.6885
350.03687	0.94642466	0.20349772	3064.3953
351.13794	0.948484	0.20476583	3064.4814
352.23901	0.95185506	0.20631178	3066.9839
353.34009	0.95577514	0.20753565	3062.6433
354.44116	0.96002883	0.20870532	3069.5383
355.54224	0.96243757	0.21015732	3067.6321
356.64331	0.96920419	0.21135581	3071.1733
357.74438	0.96806049	0.21257068	3069.9431
358.84546	0.97165531	0.21398753	3075.6506
359.94653	0.9760983	0.21545912	3072.5071
361.04761	0.9788059	0.21655446	3071.2236
362.14868	0.98357445	0.21792634	3077.4827
363.24976	0.98374206	0.21919605	3071.2993
364.35083	0.99194068	0.22045353	3079.9189
365.4519	0.99238956	0.22177379	3081.7607
366.55298	0.99776834	0.2232127	3087.0674
367.65405	1.0003048	0.22447912	3089.2903
368.75513	1.0032767	0.22562909	3082.9692
369.8562	1.0076665	0.22668597	3085.3064
370.95728	1.0124214	0.22810076	3091.749
372.05835	1.0081973	0.22929735	3085.7153
373.15942	1.0209234	0.23057446	3091.9492
374.2605	1.0167688	0.23170091	3090.7034
375.36157	1.0227872	0.23305397	3094.48
376.46265	1.0285746	0.23449993	3103.3218
377.56372	1.0296311	0.23585878	3097.0459
378.66479	1.0330426	0.23715641	3094.2795
379.76587	1.0375208	0.23850006	3099.8772
380.86694	1.0366654	0.23968637	3094.6726
381.96802	1.0449078	0.24086028	3101.7988
383.06909	1.0441196	0.24203807	3097.8306
384.17017	1.0503186	0.24317512	3105.3855
385.27124	1.0529826	0.24482735	3115.1833
386.37231	1.0582114	0.24624626	3115.7302
387.47339	1.0597303	0.24766296	3108.4939
388.57446	1.0626409	0.24892545	3113.4624
389.67554	1.0649376	0.25006437	3108.4641
390.77661	1.0680474	0.25127918	3111.5349
391.87769	1.0757409	0.25245488	3119.5754
392.97876	1.0771629	0.25383258	3118.5427
394.07983	1.0787332	0.25535595	3122.4734
395.18091	1.0811236	0.25656965	3112.6738
396.28198	1.0870942	0.25765583	3116.2234
397.38306	1.0882834	0.25870666	3118.5842
398.48413	1.0902803	0.25997183	3124.1797
399.58521	1.0946231	0.26144972	3127.593
400.68628	1.0992872	0.26284453	3127.7329
401.78735	1.1037775	0.26402315	3128.2583
402.88843	1.1062669	0.26526061	3130.2646
403.9895	1.1103978	0.26644674	3135.5437
405.09058	1.110201	0.26758435	3133.542
406.19165	1.1137953	0.26885027	3136.1809
407.29272	1.1193439	0.27026868	3139.6741
408.3938	1.1246085	0.27151102	3138.9607
409.49487	1.1242805	0.2726787	3130.4778
410.59595	1.1291622	0.27395883	3142.4072
411.69702	1.1278312	0.27525499	3135.2954
412.7981	1.1373106	0.2765035	3141.4656
413.89917	1.1393965	0.2780048	3146.8022
415.00024	1.1407552	0.27941579	3147.4326
416.10132	1.1450132	0.28050283	3143.0542
417.20239	1.1484209	0.28170723	3149.6841
418.30347	1.1516814	0.28287989	3145.8923
419.40454	1.1560832	0.28426966	3152.5063
420.50562	1.1587118	0.28539959	3148.4351
421.60669	1.1629053	0.2866585	3151.6143
422.70776	1.1617156	0.28783858	3144.3594
423.80884	1.1683301	0.28880394	3149.5979
424.90991	1.16945	0.29022151	3156.634
426.01099	1.1726832	0.29162031	3155.9824
427.11206	1.181831	0.29285514	3160.7566
428.21313	1.179451	0.29400775	3154.9949
429.31421	1.1838527	0.29531974	3157.8855
430.41528	1.1867267	0.29640993	3155.6929
431.51636	1.1912225	0.29777548	3166.4524
432.61743	1.1956731	0.29918835	3164.3972
433.71851	1.1969395	0.30051777	3163.415
434.81958	1.1991934	0.30188575	3165.7737
435.92065	1.2020735	0.30295956	3162.3323
437.02173	1.2099705	0.30421388	3173.675
438.1228	1.2092826	0.30544004	3173.7522
439.22388	1.2139797	0.30695924	3172.4453
440.32495	1.2156944	0.30840138	3172.946
441.42603	1.2183162	0.30965874	3170.3962
442.5271	1.2256999	0.31110337	3180.7563
443.62817	1.2283586	0.31239569	3177.4504
444.72925	1.2292949	0.31379816	3181.1431
445.83032	1.2328204	0.31509867	3177.9414
446.9314	1.2378407	0.31634259	3179.9651
448.03247	1.2420344	0.31774068	3183.3091
449.13354	1.2444307	0.31912258	3179.8296
450.23462	1.2486726	0.32017213	3182.8652
451.33569	1.2526193	0.32129282	3178.9707
452.43677	1.2540908	0.32243964	3180.738
453.53784	1.2549802	0.32366163	3187.9485
454.63892	1.2582066	0.32486022	3191.7996
455.73999	1.2655778	0.32621422	3191.9636
456.84106	1.2659007	0.32744122	3188.9851
457.94214	1.2695123	0.3286007	3192.8459
459.04321	1.2738973	0.32989919	3193.3184
460.14429	1.2766821	0.33109379	3191.8572
461.24536	1.2802312	0.33224636	3198.8352
462.34644	1.2836418	0.33354235	3200.0981
463.44751	1.2864956	0.33475763	3211.5938
464.54858	1.2882981	0.33618551	3200.5464
465.64966	1.2959774	0.33741853	3200.2983
466.75073	1.2966424	0.33862266	3201.9856
467.85181	1.3002696	0.33986098	3199.5742
468.95288	1.3015511	0.34114549	3210.7646
470.05396	1.3063326	0.3424722	3205.7183
471.15503	1.3100569	0.34388152	3206.1975
472.2561	1.313957	0.34501925	3206.1169
473.35718	1.3158749	0.34651315	3213.2136
474.45825	1.3191094	0.34788108	3208.4209
475.55933	1.3263034	0.34916961	3212.2427
476.6604	1.32664	0.35055646	3214.6396
477.76147	1.3343498	0.35194096	3218.572
478.86255	1.3329509	0.35319364	3215.9417
479.96362	1.3369234	0.35432041	3215.0674
481.0647	1.3396438	0.35568959	3214.4663
482.16577	1.3440194	0.3569563	3219.5999
483.26685	1.3460698	0.358197	3225.2263
484.36792	1.3494557	0.35964113	3225.3726
485.46899	1.3536353	0.36090615	3218.2825
486.57007	1.3566742	0.36194205	3223.813
487.67114	1.3591671	0.36292157	3218.8679
488.77222	1.3638846	0.36416954	3225.4355
489.87329	1.3642673	0.36541688	3226.2258
490.97437	1.3678293	0.3667005	3232.73
492.07544	1.3732362	0.36815745	3234.6443
493.17651	1.3757377	0.36935186	3232.8845
494.27759	1.3800862	0.37065062	3234.1035
495.37866	1.3839889	0.3719013	3234.8979
496.47974	1.3858933	0.37344489	3239.9048
497.58081	1.3890427	0.37454617	3228.2468
498.68188	1.3944854	0.37562975	3229.9067
499.78296	1.3961394	0.37702557	3242.8645
500.88403	1.3988829	0.37835684	3239.6035
501.98511	1.4049839	0.37964982	3245.0916
503.08618	1.4048306	0.38101822	3245.0652
504.18726	1.409332	0.38239959	3245.2551
505.28833	1.41427	0.38366127	3245.9119
506.3894	1.4150922	0.38485727	3241.9761
507.49048	1.4188497	0.38616297	3250.4998
508.59155	1.4217167	0.38761967	3256.4963
509.69263	1.4248011	0.38892475	3248.5735
510.7937	1.4295359	0.39029655	3252.22
511.89478	1.4309182	0.39147025	3246.2178
512.99585	1.4363756	0.3926011	3252.6531
514.09692	1.4378707	0.39397699	3260.2747
515.198	1.4411303	0.39535576	3258.689
516.29907	1.4476022	0.39661357	3254.8652
517.40015	1.4493783	0.39791194	3257.6821
518.50122	1.4507765	0.39928904	3257.3938
519.60229	1.4558866	0.40068936	3258.9897
520.70337	1.4588225	0.40191889	3261.5291
521.80444	1.4604654	0.40323156	3259.7485
522.90552	1.465971	0.40456828	3258.4524
524.00659	1.4707798	0.4056969	3258.8105
525.10767	1.4688547	0.4069058	3264.7849
526.20874	1.47473	0.40803403	3260.1826
527.30981	1.4786483	0.40893924	3257.7727
528.41089	1.4809146	0.41020048	3271.2937
529.51196	1.4848423	0.41163489	3269.1123
530.61304	1.4891849	0.41290444	3270.7053
531.71411	1.4918408	0.41409868	3270.9536
532.81519	1.4925743	0.41521898	3271.0913
533.91626	1.4970778	0.41658354	3272.2366
535.01733	1.4981101	0.4176718	3271.5388
536.11841	1.5040786	0.41892537	3275.9373
537.21948	1.5072501	0.42003819	3276.5474
538.32056	1.5107952	0.42134929	3283.0708
539.42163	1.5160912	0.42280862	3278.4343
540.52271	1.5196555	0.4241043	3283.2473
541.62378	1.5206583	0.42557183	3285.6191
542.72485	1.5233935	0.42700508	3281.4153
543.82593	1.527463	0.42845827	3283.8279
544.927	1.5293033	0.42958799	3279.085
546.02808	1.5368924	0.430868	3286.5173
547.12915	1.5389119	0.43218827	3288.3123
548.23022	1.5404345	0.43351975	3289.1479
549.3313	1.5433855	0.43460763	3286.4382
550.43237	1.5457882	0.43592051	3288.6563
551.53345	1.5488706	0.43717226	3292.436
552.63452	1.5539973	0.43858802	3295.2729
553.7356	1.5585257	0.44008413	3300.1724
554.83667	1.5608777	0.44142222	3291.344
555.93774	1.5658634	0.44271263	3292.9429
557.03882	1.5669414	0.44408074	3299.738
558.13989	1.5700299	0.44535956	3301.1394
559.24097	1.5712806	0.44663632	3298.2288
560.34204	1.57885	0.44786856	3300.3574
561.44312	1.5814775	0.44903779	3300.3354
562.54419	1.582551	0.45001727	3298.6367
563.64526	1.5883679	0.45115659	3306.5491
564.74634	1.5900085	0.45256516	3299.491
565.84741	1.5953934	0.45389235	3305.2114
566.94849	1.5963314	0.45536736	3309.8689
568.04956	1.5997444	0.45673731	3306.3259
569.15063	1.6064638	0.45794606	3310.7471
570.25171	1.6036049	0.45925602	3311.6563
571.35278	1.6128694	0.46057326	3312.5908
572.45386	1.6160263	0.46203294	3307.3728
573.55493	1.6187458	0.46320081	3314.2705
574.65601	1.6188753	0.46437925	3308.1992
575.75708	1.6202276	0.4657189	3314.2039
576.85815	1.6256428	0.46726954	3316.2488
577.95923	1.6315982	0.46885756	3318.6216
579.0603	1.6360394	0.47032961	3324.4641
580.16138	1.6359372	0.47149819	3312.7241
581.26245	1.6392381	0.47285071	3321.0916
582.36353	1.6445353	0.47403136	3313.46
583.4646	1.6486098	0.47529575	3327.7456
584.56567	1.6476527	0.47658509	3320.4182
585.66675	1.6574392	0.47800845	3331.5037
586.76782	1.6557479	0.47949713	3322.0242
587.8689	1.6621413	0.48068392	3329.0796
588.96997	1.66168	0.48191547	3327.3569
590.07104	1.6655686	0.48330504	3324.554
591.17212	1.6696519	0.4844532	3324.8276
592.27319	1.6745548	0.48556149	3326.9241
593.37427	1.6765549	0.48671821	3326.3193
594.47534	1.6804525	0.48795581	3335.9802
595.57642	1.6852539	0.48939541	3337.2646
596.67749	1.6909703	0.49066851	3334.2661
597.77856	1.6896126	0.49160597	3326.8569
598.87964	1.6969965	0.49258938	3335.4902
599.98071	1.6946168	0.49392229	3338.9321
601.08179	1.7004079	0.4951928	3340.8787
602.18286	1.7027997	0.49652672	3338.9019
603.28394	1.7066813	0.49783498	3345.0022
604.38501	1.7092451	0.49925271	3342.874
605.48608	1.7146357	0.50077754	3346.2546
606.58716	1.7169007	0.502195	3345.248
607.68823	1.7198728	0.50353736	3339.2542
608.78931	1.7238526	0.50479794	3349.2578
609.89038	1.7257236	0.50609565	3349.2446
610.99146	1.7327195	0.50745213	3348.187
612.09253	1.7312092	0.5086205	3342.7932
613.1936	1.7398117	0.5099594	3352.9736
614.29468	1.7389078	0.51150429	3354.7346
615.39575	1.7397687	0.51282024	3345.7632
616.49683	1.7432432	0.51428002	3352.0403
617.5979	1.7505258	0.5155921	3355.5276
618.69897	1.7524879	0.51701307	3351.0745
619.80005	1.7547388	0.51827276	3351.7876
620.90112	1.7585326	0.51967001	3351.3301
622.0022	1.7615019	0.52100015	3351.7178
623.10327	1.7645992	0.52238637	3356.8965
624.20435	1.7709938	0.52354425	3353.5081
625.30542	1.7694379	0.52467805	3357.8066
626.40649	1.7747525	0.52608913	3356.9246
627.50757	1.7777187	0.52751261	3361.5813
628.60864	1.7821219	0.52879816	3354.3027
629.70972	1.7856725	0.52992821	3354.1868
630.81079	1.7873474	0.53090709	3357.6541
631.91187	1.7906193	0.53239125	3363.4302
633.01294	1.7950246	0.53394318	3367.7947
634.11401	1.7987304	0.53555155	3367.2671
635.21509	1.8017726	0.53683263	3362.5488
636.31616	1.8041806	0.53793544	3365.7749
637.41724	1.8101161	0.53934515	3370.7285
638.51831	1.8123288	0.54068357	3378.2749
639.61938	1.8153747	0.5419699	3369.7722
640.72046	1.8178133	0.54332185	3371.6248
641.82153	1.8195103	0.54466546	3371.0989
642.92261	1.8278072	0.54592681	3372.0173
644.02368	1.8271217	0.54715526	3366.3289
645.12476	1.8329548	0.54850209	3376.8665
646.22583	1.8336828	0.54976642	3374.0366
647.3269	1.8408692	0.55099314	3379.9111
648.42798	1.8387027	0.55219704	3376.3003
649.52905	1.8426582	0.55341697	3373.2083
650.63013	1.8469245	0.55484253	3385.6379
651.7312	1.8502842	0.55601615	3373.8657
652.83228	1.8533915	0.55741179	3380.313
653.93335	1.8581413	0.55882788	3378.9241
655.03442	1.8596755	0.56008524	3379.7368
656.1355	1.8640511	0.56157261	3380.356
657.23657	1.8692274	0.56288242	3385.5408
658.33765	1.8716408	0.564309	3385.874
659.43872	1.8761908	0.56575745	3388.3118
660.53979	1.8768083	0.56721568	3387.252
661.64087	1.8769861	0.56869072	3386.657
662.74194	1.8837223	0.57009101	3387.3535
663.84302	1.8862087	0.57152539	3386.7524
664.94409	1.8877633	0.57280201	3387.8176
666.04517	1.8946949	0.57431483	3392.9844
667.14624	1.8983864	0.57560456	3391.2773
668.24731	1.9003282	0.57698596	3390.1719
669.34839	1.9046687	0.57806826	3385.8013
670.44946	1.9047842	0.57934618	3392.1694
671.55054	1.9111444	0.58069891	3395.7078
672.65161	1.9162083	0.58210272	3404.8018
673.75269	1.9168081	0.58347517	3400.2634
674.85376	1.9197663	0.58489984	3396.9976
675.95483	1.922713	0.58651108	3395.1338
677.05591	1.9250047	0.58790278	3398.2957
678.15698	1.9327478	0.58932084	3400.906
679.25806	1.9362819	0.59070057	3403.1697
680.35913	1.9345553	0.59202152	3396.0605
681.46021	1.9414784	0.59332567	3406.4243
682.56128	1.9460663	0.59474999	3406.5142
683.66235	1.9483426	0.59594345	3400.9521
684.76343	1.9517474	0.59720892	3400.3999
685.8645	1.9519219	0.59851646	3407.9478
686.96558	1.95733	0.60016537	3407.5706
688.06665	1.960495	0.60176891	3410.3318
689.16772	1.9612845	0.6031068	3404.1611
690.2688	1.967627	0.60441262	3408.0027
691.36987	1.9693751	0.60572964	3409.8835
692.47095	1.9723854	0.60690802	3407.4978
693.57202	1.976688	0.60839087	3412.8772
694.6731	1.9803531	0.60984522	3415.0923
695.77417	1.9828247	0.61110067	3408.2378
696.87524	1.9869634	0.61232603	3411.5872
697.97632	1.9894209	0.61355472	3410.2551
699.07739	1.9925586	0.61471951	3409.9104
700.17847	1.9960725	0.61601776	3412.6125
701.27954	1.9983778	0.61740482	3419.7463
702.38062	2.004797	0.61880487	3420.1653
703.48169	2.0064073	0.62041277	3418.2871
704.58276	2.0109322	0.62181216	3426.0703
705.68384	2.0146451	0.62339187	3422.8828
706.78491	2.0160241	0.62462515	3415.0193
707.88599	2.0222859	0.62592	3422.0728
708.98706	2.0245652	0.6274243	3425.9417
710.08813	2.0285647	0.62883735	3427.7588
711.18921	2.0318794	0.63020349	3423.5137
712.29028	2.0339844	0.63156319	3423.8584
713.39136	2.0369227	0.63283485	3430.6609
714.49243	2.0375712	0.634076	3420.8716
715.59351	2.0417957	0.63556087	3429.6743
716.69458	2.0484519	0.6369645	3430.2109
717.79565	2.0506601	0.6383872	3434.7532
718.89673	2.05305	0.63980293	3431.4458
719.9978	2.0547931	0.64126897	3431.3948
721.09888	2.060261	0.64290756	3428.3318
722.19995	2.0610192	0.64455891	3432.8291
723.30103	2.0666091	0.6459887	3433.1287
724.4021	2.0695372	0.64731717	3427.5671
725.50317	2.0748465	0.64864683	3438.0776
726.60425	2.078037	0.64988965	3435.6262
727.70532	2.0777724	0.65137184	3436.0542
728.8064	2.0812809	0.65291667	3433.6082
729.90747	2.0867684	0.65435606	3435.0522
731.00854	2.0915263	0.65573508	3438.5911
732.10962	2.09425	0.6570102	3440.8721
733.21069	2.0980701	0.65864521	3442.2092
734.31177	2.1009085	0.65993363	3441.4038
735.41284	2.101706	0.66120344	3434.3174
736.51392	2.1050804	0.66271973	3445.4966
737.61499	2.1071346	0.66418624	3436.4453
738.71606	2.1133494	0.6654948	3445.49
739.81714	2.1161537	0.66678363	3445.186
740.91821	2.1210752	0.66804904	3444.9556
742.01929	2.1228981	0.66954261	3451.7197
743.12036	2.1245909	0.67087269	3435.293
744.22144	2.1297185	0.67214257	3447.4246
745.32251	2.1316261	0.67387021	3450.9419
746.42358	2.1338077	0.67529392	3443.5911
747.52466	2.1398861	0.67688805	3450.9063
748.62573	2.1421986	0.6783129	3445.8203
749.72681	2.1430821	0.67980665	3448.3877
750.82788	2.1494839	0.68115526	3446.8621
751.92896	2.151583	0.6824156	3451.3789
753.03003	2.1556833	0.68391031	3453.436
754.1311	2.1553478	0.68540883	3448.8752
755.23218	2.163785	0.68686277	3452.7642
756.33325	2.1635823	0.6881032	3451.1794
757.43433	2.1696835	0.68966031	3466.3271
758.5354	2.1724648	0.69116259	3455.6106
759.63647	2.1747184	0.69274789	3457.6514
760.73755	2.1794703	0.69410545	3453.4771
761.83862	2.1829329	0.69534171	3451.9578
762.9397	2.1845975	0.69671047	3451.6519
764.04077	2.1897998	0.69807458	3457.3071
765.14185	2.192405	0.69960314	3458.5659
766.24292	2.194593	0.70111519	3461.0598
767.34399	2.1983252	0.70268244	3456.322
768.44507	2.2010601	0.7042464	3457.1426
769.54614	2.2039006	0.70568472	3457.1204
770.64722	2.2112248	0.70694816	3460.8872
771.74829	2.2109785	0.70826757	3462.575
772.84937	2.213557	0.70995826	3462.0498
773.95044	2.220083	0.71126568	3463.7942
775.05151	2.221437	0.71273816	3459.8926
776.15259	2.2254562	0.71398026	3461.3298
777.25366	2.228194	0.71540469	3466.6211
778.35474	2.2301297	0.71698916	3467.3242
779.45581	2.2348547	0.71870053	3467.2236
780.55688	2.2384493	0.72016853	3465.3374
781.65796	2.2384	0.72150469	3461.4656
782.75903	2.2418802	0.72312433	3471.2017
783.86011	2.2481256	0.72483861	3469.7656
784.96118	2.2518914	0.72631526	3470.6777
786.06226	2.2560205	0.7276904	3464.5195
787.16333	2.2597625	0.72914106	3473.1121
788.2644	2.2634325	0.73057783	3469.0552
789.36548	2.2617664	0.7319591	3470.4065
790.46655	2.2682817	0.73333722	3465.4063
791.56763	2.2707427	0.73474783	3469.0947
792.6687	2.2701969	0.73637688	3477.9351
793.76978	2.2785959	0.73818326	3474.4492
794.87085	2.281059	0.73969799	3476.4492
795.97192	2.285455	0.74095851	3476.5515
797.073	2.2901373	0.74255401	3478.3857
798.17407	2.2914541	0.74398762	3475.2266
799.27515	2.2943702	0.74552345	3476.8989
800.37622	2.2978396	0.74714142	3479.6677
801.47729	2.2990499	0.74888933	3477.2646
802.57837	2.3044195	0.75045311	3480.3203
803.67944	2.3065977	0.75187576	3475.7471
804.78052	2.3097839	0.75327766	3472.1768
805.88159	2.3139589	0.7547375	3477.8604
806.98267	2.3160279	0.75627631	3479.7686
808.08374	2.3188982	0.75807047	3477.5137
809.18481	2.3251529	0.75944358	3482.3083
810.28589	2.3261912	0.76096076	3482.5693
811.38696	2.3299577	0.76237828	3484.396
812.48804	2.3361731	0.76364625	3480.5842
813.58911	2.3389406	0.76518154	3484.9385
814.69019	2.3406899	0.76664555	3484.4885
815.79126	2.3449254	0.76801658	3487.0403
816.89233	2.3426819	0.76953554	3479.1887
817.99341	2.3511927	0.77126497	3488.7625
819.09448	2.3523095	0.77258271	3478.428
820.19556	2.355866	0.77407682	3484.0444
821.29663	2.3625679	0.77587885	3492.7053
822.39771	2.3659139	0.77727365	3487.2639
823.49878	2.3665881	0.77872294	3490.8284
824.59985	2.3690636	0.78034949	3487.168
825.70093	2.3728735	0.7818433	3486.3577
826.802	2.3777533	0.78351361	3494.6816
827.90308	2.3774009	0.78523493	3487.8147
829.00415	2.3847857	0.78670412	3492.0298
830.10522	2.3894818	0.7883569	3495.092
831.2063	2.3883779	0.78990477	3487.7751
832.30737	2.3929853	0.79150808	3492.1685
833.40845	2.3972547	0.79318517	3492.6052
834.50952	2.399559	0.79481179	3497.1372
835.6106	2.40573	0.79649448	3499.2153
836.71167	2.4064627	0.79800111	3494.4932
837.81274	2.4104466	0.79952222	3493.2891
838.91382	2.4128523	0.80104429	3493.5662
840.01489	2.4191391	0.80256265	3497.6921
841.11597	2.4207335	0.80408055	3493.3047
842.21704	2.4240689	0.80581033	3498.6013
843.31812	2.4241576	0.80734187	3494.1892
844.41919	2.4281328	0.80869663	3490.9045
845.52026	2.4327679	0.81050336	3502.342
846.62134	2.4373174	0.81221968	3501.4216
847.72241	2.4410787	0.8139205	3494.9741
848.82349	2.446382	0.81535912	3497.0461
849.92456	2.4478655	0.81675148	3497.7358
851.02563	2.4472144	0.81819141	3496.4055
852.12671	2.4523797	0.81972259	3502.5322
853.22778	2.4547412	0.82125473	3500.1602
854.32886	2.4583323	0.82285023	3499.9644
855.42993	2.4627457	0.82476521	3504.5029
856.53101	2.4646728	0.82641417	3499.449
857.63208	2.4686909	0.82795227	3500.6948
858.73315	2.4749806	0.82960606	3498.344
859.83423	2.4773622	0.83097225	3503.0229
860.9353	2.4808543	0.83251208	3506.8948
862.03638	2.4842641	0.83404934	3507.4434
863.13745	2.4845984	0.8356272	3505.1611
864.23853	2.4866831	0.83742738	3513.4143
865.3396	2.4934072	0.83925182	3506.1929
866.44067	2.4978781	0.84099329	3505.2278
867.54175	2.4984159	0.84232485	3498.7563
868.64282	2.5029876	0.8441087	3506.8323
869.7439	2.5084469	0.84574342	3515.49
870.84497	2.5096252	0.84742832	3508.8213
871.94604	2.5120366	0.84893841	3507.8391
873.04712	2.5184925	0.85077661	3510.0703
874.14819	2.5192487	0.85261434	3507.8416
875.24927	2.5212901	0.85433036	3512.064
876.35034	2.5271513	0.85587692	3508.127
877.45142	2.5313852	0.85759455	3515.9338
878.55249	2.530993	0.85915595	3505.4246
879.65356	2.534261	0.86082315	3506.3997
880.75464	2.538759	0.86247098	3510.3596
881.85571	2.5420837	0.86392623	3504.7568
882.95679	2.5454028	0.86524534	3507.2742
884.05786	2.5479403	0.86677092	3508.0781
885.15894	2.550709	0.86832315	3513.8542
886.26001	2.5558503	0.87029713	3521.3193
887.36108	2.5563319	0.87210965	3515.2964
888.46216	2.5623219	0.87379313	3509.9958
889.56323	2.5652075	0.87539065	3512.0916
890.66431	2.5696855	0.87699932	3514.3462
891.76538	2.5730376	0.87855697	3516.4041
892.86646	2.5763683	0.88018841	3514.2261
893.96753	2.5785062	0.88188642	3517.0847
895.0686	2.5815995	0.88363367	3513.5713
896.16968	2.5862486	0.88533044	3519.2744
897.27075	2.5917683	0.88712925	3519.1428
898.37183	2.5925317	0.88878435	3515.3862
899.4729	2.5976045	0.89059609	3519.3069
900.57397	2.5978589	0.8925125	3525.0051
901.67505	2.6031194	0.89439607	3520.3257
902.77612	2.6051638	0.89633727	3523.3821
903.8772	2.6082518	0.89824504	3513.0366
904.97827	2.6130371	0.89998442	3520.8623
906.07935	2.6159241	0.9014852	3512.3916
907.18042	2.6206219	0.90316832	3522.8203
908.28149	2.6192765	0.90507859	3519.5559
909.38257	2.626169	0.90699613	3518.5405
910.48364	2.6263759	0.90872848	3516.5474
911.58472	2.6315031	0.91037756	3517.0454
912.68579	2.6346703	0.91210955	3516.2278
913.78687	2.6362269	0.91374105	3519.0144
914.88794	2.6419511	0.9152984	3517.1748
915.98901	2.6452563	0.91682047	3519.241
917.09009	2.6508474	0.9184975	3523.2371
918.19116	2.6542683	0.92033958	3526.468
919.29224	2.6525929	0.92203057	3517.2256
920.39331	2.6561744	0.92377931	3520.9333
921.49438	2.6608546	0.92578918	3524.5862
922.59546	2.6651149	0.92764044	3524.6511
923.69653	2.6652875	0.9294734	3519.293
924.79761	2.6703808	0.93135113	3522.0544
925.89868	2.6742065	0.93315417	3523.739
926.99976	2.6762307	0.93477553	3516.5198
928.10083	2.6807783	0.93657207	3526.957
929.2019	2.6836891	0.93847001	3526.0999
930.30298	2.6880991	0.94029146	3526.6663
931.40405	2.6917975	0.94201595	3526.5703
932.50513	2.696698	0.94356716	3524.2512
933.6062	2.6974146	0.94512975	3524.6338
934.70728	2.6992517	0.94667214	3528.7825
935.80835	2.7048466	0.94866645	3534.7075
936.90942	2.7092328	0.95062238	3525.2483
938.0105	2.7105191	0.9525333	3528.8032
939.11157	2.7160423	0.95424759	3530.5239
940.21265	2.7183628	0.95624149	3526.6223
941.31372	2.7185934	0.95793247	3527.9004
942.41479	2.7246366	0.95980138	3527.4055
943.51587	2.7243042	0.9615283	3525.8547
944.61694	2.7297428	0.96324545	3530.2324
945.71802	2.7331121	0.96522969	3535.3076
946.81909	2.7382421	0.96713424	3525.554
947.92017	2.7402623	0.9688949	3525.343
949.02124	2.7442195	0.97088248	3536.4216
950.12231	2.7428007	0.97273886	3525.9463
951.22339	2.7494829	0.97454673	3532.5989
952.32446	2.7525742	0.97651011	3528.3525
953.42554	2.7566209	0.97844523	3528.5002
954.52661	2.7615249	0.98050439	3534.4744
955.62769	2.7627175	0.98273408	3534.6194
956.72876	2.7675657	0.98460478	3530.9739
957.82983	2.7707176	0.98643357	3529.283
958.93091	2.7737513	0.98824489	3529.3872
960.03198	2.7760401	0.99018544	3527.7668
961.13306	2.7807801	0.99196726	3529.6875
962.23413	2.7811825	0.99373257	3529.6072
963.33521	2.7888582	0.99551594	3532.2986
964.43628	2.7889426	0.99758101	3532.4668
965.53735	2.7936459	0.99952501	3533.9395
966.63843	2.7948463	1.0017327	3532.176
967.7395	2.8010557	1.0037227	3532.845
968.84058	2.8039832	1.0055183	3528.5251
969.94165	2.8062871	1.0072502	3528.9429
971.04272	2.8081393	1.0090637	3529.7385
972.1438	2.8132098	1.0110343	3532.5369
973.24487	2.8171556	1.0132396	3533.7261
974.34595	2.8209496	1.0152335	3537.9001
975.44702	2.8229144	1.0171185	3526.5625
976.5481	2.8231535	1.0191135	3530.8137
977.64917	2.8311067	1.0207667	3526.561
978.75024	2.8344281	1.0226872	3533.1487
979.85132	2.837683	1.0246202	3537.334
980.95239	2.842453	1.026777	3537.9709
982.05347	2.84022	1.0290457	3532.4578
983.15454	2.8469055	1.0310807	3530.3613
984.25562	2.8466043	1.033003	3530.9028
985.35669	2.849961	1.0348513	3529.2466
986.45776	2.8559453	1.0368123	3533.5649
987.55884	2.860189	1.0387921	3538.0249
988.65991	2.8610508	1.0408421	3538.6458
989.76099	2.8650868	1.0426971	3534.9553
990.86206	2.866334	1.0445911	3531.2419
991.96313	2.8710225	1.0467831	3537.3127
993.06421	2.8764236	1.0485003	3526.7361
994.16528	2.879194	1.0502986	3531.9729
995.26636	2.8810091	1.0522596	3528.842
996.36743	2.8868361	1.0541425	3537.4465
997.46851	2.8908656	1.0560906	3533.7576
998.56958	2.8906043	1.0583351	3537.4856
999.67065	2.8972526	1.0605952	3537.324
1000.7717	2.8971977	1.0625805	3534.2886
1001.8728	2.9026015	1.0646914	3532.7366
1002.9739	2.9049702	1.0668924	3539.7559
1004.075	2.9070141	1.0688908	3531.4248
1005.176	2.9122872	1.0711652	3534.3154
1006.2771	2.9171093	1.0730429	3530.678
1007.3782	2.9189143	1.0752208	3533.9165
1008.4792	2.9208553	1.0774465	3540.2913
1009.5803	2.9225004	1.0797273	3530.0059
1010.6814	2.9284115	1.0820872	3535.9143
1011.7825	2.9291694	1.0841792	3534.9817
1012.8835	2.9362648	1.0862645	3530.8303
1013.9846	2.9383886	1.0883874	3534.6917
1015.0857	2.9395275	1.0900834	3529.811
1016.1868	2.9469104	1.0921959	3539.4185
1017.2878	2.9477727	1.0947438	3541.28
1018.3889	2.9539878	1.0972883	3542.9834
1019.49	2.9546595	1.099957	3541.9531
1020.5911	2.96187	1.1022115	3533.9207
1021.6921	2.9621639	1.1041975	3528.658
1022.7932	2.9677594	1.1060036	3532.2671
1023.8943	2.9662359	1.1077344	3528.3574
1024.9954	2.9723673	1.1096419	3531.446
1026.0964	2.9750519	1.1113437	3530.6172
1027.1975	2.9788766	1.1134094	3536.5681
1028.2986	2.9810083	1.1155636	3530.8538
1029.3997	2.9818022	1.117424	3529.9888
1030.5007	2.9867439	1.1196289	3537.1387
1031.6018	2.9916806	1.1219398	3538.6116
1032.7029	2.9957242	1.1239625	3530.1467
1033.804	2.9981408	1.1261659	3534.2849
1034.905	3.0032675	1.1284586	3538.8818
1036.0061	3.0040758	1.1305122	3531.5151
1037.1072	3.0046523	1.1323733	3531.1399
1038.2083	3.0103362	1.1340457	3524.3159
1039.3093	3.015619	1.1357278	3532.5427
1040.4104	3.0189478	1.1374108	3533.75
1041.5115	3.0207262	1.1394862	3539.2512
1042.6125	3.0238149	1.1417698	3538.1858
1043.7136	3.0283101	1.1441367	3535.2271
1044.8147	3.032234	1.1466048	3531.314
1045.9158	3.0347955	1.1488154	3537.3223
1047.0168	3.0391188	1.1509234	3537.3557
1048.1179	3.0413511	1.1530945	3527.873
1049.219	3.0431068	1.15571	3539.9036
1050.3201	3.046484	1.1582955	3535.1694
1051.4211	3.0514343	1.1608461	3538.894
1052.5222	3.0559042	1.1635005	3538.4231
1053.6233	3.056716	1.1661097	3531.1746
1054.7244	3.0620444	1.1685842	3534.0972
1055.8254	3.0625138	1.1709789	3532.6311
1056.9265	3.0675588	1.173316	3535.9663
1058.0276	3.0712478	1.1757058	3533.6084
1059.1287	3.0725667	1.1781723	3533.4636
1060.2297	3.0768855	1.1803622	3529.4968
1061.3308	3.0780957	1.1827812	3534.1326
1062.4319	3.0826392	1.1849637	3528.8181
1063.533	3.0871856	1.1872554	3530.7178
1064.634	3.0909321	1.1894453	3529.1626
1065.7351	3.0942421	1.1917551	3533.563
1066.8362	3.0987391	1.1943783	3536.4094
1067.9373	3.1018369	1.1967758	3535.1714
1069.0383	3.1026435	1.199122	3530.5935
1070.1394	3.109746	1.2019385	3537.6455
1071.2405	3.1083751	1.204345	3527.429
1072.3416	3.1142554	1.2070597	3533.1028
1073.4426	3.115736	1.2094722	3527.1733
1074.5437	3.1218903	1.2118461	3531.0193
1075.6448	3.1217554	1.2141368	3532.7231
1076.7458	3.127703	1.2163298	3530.8909
1077.8469	3.1285207	1.2184949	3523.1851
1078.948	3.1347868	1.220845	3524.8972
1080.0491	3.1369534	1.2233698	3532.6436
1081.1501	3.1384683	1.2262177	3534.3965
1082.2512	3.1423442	1.2289619	3523.4346
1083.3523	3.1439667	1.2313619	3524.8403
1084.4534	3.148896	1.2344062	3530.4919
1085.5544	3.1539254	1.2374541	3532.2893
1086.6555	3.1562908	1.2400726	3527.5852
1087.7566	3.1577501	1.2425036	3522.3157
1088.8577	3.164464	1.2448696	3529.4163
1089.9587	3.1660075	1.2472417	3530.7305
1091.0598	3.1705346	1.249794	3529.2075
1092.1609	3.1724141	1.2523898	3526.927
1093.262	3.1762586	1.2549754	3526.0718
1094.363	3.1801586	1.2571596	3519.1328
1095.4641	3.1847756	1.2596397	3528.1484
1096.5652	3.1828001	1.2623796	3525.7495
1097.6663	3.1907692	1.2656478	3529.4351
1098.7673	3.1941273	1.268314	3529.4326
1099.8684	3.1987314	1.2707518	3521.8701
1100.9695	3.2003713	1.2730308	3525.3997
1102.0706	3.2011974	1.2753851	3520.5278
1103.1716	3.2054288	1.2781247	3522.2847
1104.2727	3.2123435	1.2811363	3530.5105
1105.3738	3.2115633	1.2839262	3521.2651
1106.4749	3.2174823	1.2866659	3522.3679
1107.5759	3.2196527	1.2893788	3519.1443
1108.677	3.2222934	1.2919612	3521.4941
1109.7781	3.2257786	1.2946808	3520.0452
1110.8792	3.2286429	1.2975755	3519.1267
1111.9802	3.2304444	1.3006314	3518.936
1113.0813	3.2373672	1.303817	3521.3069
1114.1824	3.2374883	1.3068656	3519.4705
1115.2834	3.2456617	1.309731	3517.6912
1116.3845	3.2449989	1.3124845	3522.4595
1117.4856	3.2472086	1.3151836	3511.5774
1118.5867	3.2547681	1.3175547	3513.7935
1119.6877	3.2544634	1.3199478	3512.5369
1120.7888	3.2577677	1.3227179	3522.0134
1121.8899	3.2582657	1.3256409	3516.3228
1122.991	3.2648604	1.3287492	3515.0525
1124.092	3.2698109	1.3315991	3519.6875
1125.1931	3.2742519	1.3342848	3516.6897
1126.2942	3.2774363	1.3367165	3504.5227
1127.3953	3.2767167	1.3394473	3512.5054
1128.4963	3.2809503	1.3419851	3511.303
1129.5974	3.2848616	1.3450018	3513.907
1130.6985	3.2881496	1.3480114	3510.6953
1131.7996	3.2935114	1.3511087	3515.3171
1132.9006	3.2942972	1.3542348	3508.3645
1134.0017	3.2977774	1.3571074	3506.7327
1135.1028	3.3000529	1.3595437	3503.9331
1136.2039	3.3054173	1.3623177	3505.7031
1137.3049	3.3096402	1.3651657	3506.0532
1138.406	3.3129182	1.368089	3506.2402
1139.5071	3.3147807	1.3709298	3508.7729
1140.6082	3.3169794	1.3743575	3510.2598
1141.7092	3.3201683	1.3775885	3505.2839
1142.8103	3.3258471	1.3805753	3504.6484
1143.9114	3.3297644	1.3838133	3503.0879
1145.0125	3.3329878	1.3870789	3507.3513
1146.1135	3.3343587	1.3899875	3501.7859
1147.2146	3.3386893	1.3933448	3505.0417
1148.3157	3.3434386	1.396094	3495.4353
1149.4167	3.3455551	1.3990959	3501.3484
1150.5178	3.3510551	1.4018323	3500.833
1151.6189	3.3522301	1.4043717	3496.4717
1152.72	3.3578227	1.4077353	3499.9299
1153.821	3.3561344	1.4111897	3495.2698
1154.9221	3.358644	1.4146672	3497.845
1156.0232	3.3651245	1.4182094	3490.1494
1157.1243	3.3668261	1.4211831	3492.583
1158.2253	3.3704143	1.4240437	3489.2166
1159.3264	3.3758192	1.4270587	3489.7324
1160.4275	3.3769257	1.4298801	3494.4939
1161.5286	3.3821084	1.4332563	3492.1243
1162.6296	3.3841066	1.4366275	3485.2363
1163.7307	3.3847425	1.4400309	3479.8357
1164.8318	3.39082	1.4431558	3477.7983
1165.9329	3.3954144	1.446166	3485.1404
1167.0339	3.3974445	1.4494981	3481.271
1168.135	3.3991399	1.4524583	3479.5295
1169.2361	3.4064865	1.4555551	3479.5029
1170.3372	3.4069881	1.4580046	3475.6831
1171.4382	3.4125154	1.4607966	3480.7261
1172.5393	3.4149292	1.4636611	3484.1763
1173.6404	3.4183333	1.4667326	3477.1169
1174.7415	3.421551	1.4695035	3478.0452
1175.8425	3.4247489	1.4725946	3470.3367
1176.9436	3.4255893	1.4756793	3474.761
1178.0447	3.4287462	1.4795226	3473.8994
1179.1458	3.4357431	1.4826213	3470.031
1180.2468	3.436486	1.4858128	3466.2236
1181.3479	3.4434898	1.4889609	3467.3035
1182.449	3.444308	1.4921578	3465.8
1183.55	3.4466593	1.4951026	3456.1345
1184.6511	3.4495432	1.4981723	3464.1255
1185.7522	3.4557235	1.5014158	3461.9226
1186.8533	3.45998	1.5048138	3460.3628
1187.9543	3.4611788	1.5082123	3463.0242
1189.0554	3.4632287	1.5120395	3462.3972
1190.1565	3.4650571	1.5163125	3455.0569
1191.2576	3.4702525	1.5193326	3449.803
1192.3586	3.4755142	1.5221115	3449.2371
1193.4597	3.4746199	1.5255914	3450.4963
1194.5608	3.4789276	1.5290879	3444.2317
1195.6619	3.4833558	1.5319835	3446.3877
1196.7629	3.4894338	1.5353321	3451.2996
1197.864	3.4879916	1.5383853	3438.8501
1198.9651	3.4961615	1.5415342	3445.947
1200.0662	3.4935558	1.5446869	3437.0095
1201.1672	3.5004649	1.5483221	3447.4392
1202.2683	3.5053165	1.5519814	3436.7861
1203.3694	3.5059741	1.5552514	3431.041
1204.4705	3.5105491	1.5582089	3430.5493
1205.5715	3.5109787	1.5611688	3428.449
1206.6726	3.5181465	1.5645592	3431.6243
1207.7737	3.5186696	1.5677769	3424.8708
1208.8748	3.5227268	1.5715801	3426.3208
1209.9758	3.5268843	1.5751476	3426.8535
1211.0769	3.5287511	1.5794833	3422.1724
1212.178	3.531965	1.5825154	3411.6421
1213.2791	3.5378156	1.5856154	3419.0432
1214.3801	3.5395241	1.5886017	3415.4077
1215.4812	3.5424101	1.5917161	3409.4814
1216.5823	3.5486948	1.5946081	3412.9802
1217.6833	3.5533712	1.598555	3417.7207
1218.7844	3.5516655	1.6023538	3402.7021
1219.8855	3.5545766	1.6058942	3401.593
1220.9866	3.5581634	1.6093974	3398.1533
1222.0876	3.5606833	1.6124067	3396.9324
1223.1887	3.5679331	1.6157129	3401.552
1224.2898	3.5676005	1.6197758	3403.2827
1225.3909	3.5726719	1.6239452	3385.5242
1226.4919	3.578645	1.62716	3387.2329
1227.593	3.5781653	1.6302631	3381.1697
1228.6941	3.5842485	1.633472	3386.4175
1229.7952	3.5870547	1.6364912	3384.2888
1230.8962	3.5894811	1.6398546	3381.9424
1231.9973	3.5924673	1.6440439	3381.0769
1233.0984	3.5961492	1.6476471	3371.772
1234.1995	3.5981953	1.6511066	3370.5906
1235.3005	3.6021771	1.6542147	3366.9717
1236.4016	3.6035872	1.6573275	3366.2122
1237.5027	3.6098855	1.6603377	3363.4548
1238.6038	3.6113834	1.6632626	3362.0105
1239.7048	3.61378	1.6671655	3366.989
1240.8059	3.6195521	1.6710534	3356.3057
1241.907	3.6232464	1.6747279	3359.4536
1243.0081	3.6287611	1.6779261	3354.5261
1244.1091	3.6300619	1.6814973	3354.0381
1245.2102	3.6326158	1.6852362	3351.7944
1246.3113	3.6356437	1.6885018	3341.499
1247.4124	3.6408188	1.6916673	3341.8535
1248.5134	3.6414747	1.6952806	3336.2104
1249.6145	3.6442106	1.6988554	3331.6646
1250.7156	3.6503155	1.7022791	3330.8618
1251.8167	3.6533806	1.7055293	3329.2947
1252.9177	3.6539237	1.7096859	3321.8403
1254.0188	3.6589231	1.7141205	3314.4561
1255.1199	3.664778	1.7176586	3312.9429
1256.2209	3.6675785	1.7210802	3309.8943
1257.322	3.6681292	1.724488	3303.126
1258.4231	3.6710954	1.7277192	3302.3086
1259.5242	3.6742373	1.7312849	3297.8887
1260.6252	3.6793969	1.7357575	3297.8892
1261.7263	3.6809204	1.7396371	3295.0203
1262.8274	3.689023	1.7437966	3287.6873
1263.9285	3.6902769	1.7468793	3282.6865
1265.0295	3.6942465	1.7505897	3274.4714
1266.1306	3.694345	1.7541435	3272.387
1267.2317	3.7012494	1.7577984	3265.2395
1268.3328	3.7023296	1.7616178	3260.9529
1269.4338	3.7050173	1.7653381	3260.8108
1270.5349	3.7068	1.7692193	3251.8831
1271.636	3.7131364	1.7729235	3251.6187
1272.7371	3.7138453	1.7765672	3240.6165
1273.8381	3.7211442	1.7801166	3238.1665
1274.9392	3.720943	1.7838191	3226.084
1276.0403	3.724426	1.7875063	3226.1301
1277.1414	3.7270913	1.7908015	3211.7905
1278.2424	3.7327132	1.7945213	3220.3132
1279.3435	3.7371631	1.7983266	3209.9705
1280.4446	3.7390983	1.8026198	3201.3479
1281.5457	3.7434471	1.8063365	3205.7002
1282.6467	3.7436783	1.8099333	3195.3245
1283.7478	3.7482128	1.8136861	3186.5874
1284.8489	3.7527843	1.8175911	3180.1123
1285.95	3.7561448	1.8215562	3174.5657
1287.051	3.7599854	1.8263482	3162.7568
1288.1521	3.7636757	1.8302222	3153.1729
1289.2532	3.7636445	1.8339293	3139.0083
1290.3542	3.7688401	1.8372756	3133.8711
1291.4553	3.7727113	1.8415008	3126.9683
1292.5564	3.7750432	1.8468111	3104.4307
1293.6575	3.7796907	1.8527949	3080.8694
1294.7585	3.7831345	1.859599	3049.438
1295.1589	3.7843614	1.8684143	2977.0369