File: datasets/am_bench_2022/raw_data/90-X.13-4/specimen.dat
MTS793|MPT|ENU|1|2|.|/|:|1|0|0|A

Operator Information						Time:	19.498291	Sec	11/2/2021 12:55:24 PM
Operator	Nick Derimow
Project	AM Bench 2022 mini-tensile challenge
Specimen ID	90-X.13-4
Material	PBF-L Inconel 625
Specimen Width	2.54	mm
Specimen Thickness	1.52	mm
Notes
Operator Information End

Data Acquisition						Time:	1020.4919	Sec	11/2/2021 1:12:05 PM
Time	Axial Displacement	Axial Extensometer	Axial Force
Sec	mm	mm	N
19.611816	-0.001637051	-9.8835189e-06	39.085243
20.612793	0.0021626006	0.00014852076	55.945141
21.61377	0.0040641939	0.00014818474	65.548401
22.614746	0.0073295413	0.00042517786	79.504616
23.615723	0.0097398274	0.00049236469	87.982216
24.616699	0.013354667	0.00048179639	100.68768
25.617676	0.015881946	0.0007484589	112.7168
26.618652	0.017663063	0.00072322454	123.86774
27.619629	0.021184729	0.00087607629	136.38071
28.620605	0.023690494	0.0010922332	152.65724
29.621582	0.029423445	0.0009607895	161.80577
30.622559	0.030811787	0.0011712473	176.55136
31.623535	0.033002686	0.0013932395	194.13097
32.624512	0.034249447	0.0013435043	210.19991
33.625488	0.042388178	0.0016382122	230.65691
34.626465	0.042988099	0.0018121258	246.11076
35.627441	0.047789924	0.0018125274	264.41016
36.628418	0.050299581	0.0019491026	281.21979
37.629395	0.049799237	0.0023027444	301.06564
38.630371	0.055169124	0.0022955977	315.45474
39.631348	0.056365278	0.0023921034	335.68793
40.632324	0.060384624	0.0025834164	358.39743
41.633301	0.062929109	0.002599492	374.50928
42.634277	0.065193929	0.002767981	396.7818
43.635254	0.069832198	0.0030273742	421.06522
44.63623	0.070662826	0.0031899642	442.36462
45.637207	0.077053934	0.0033353663	466.23172
46.638184	0.078940518	0.0034622981	488.2182
47.63916	0.079787947	0.003557171	510.12939
48.640137	0.084576614	0.0039284448	540.70178
49.641113	0.084882721	0.0038998551	555.83142
50.64209	0.092352733	0.0041299653	582.80762
51.643066	0.093594372	0.004358015	612.67456
52.644043	0.095528699	0.0044889096	637.83405
53.64502	0.10229251	0.0047358945	665.58728
54.645996	0.099615246	0.0048397486	687.96686
55.646973	0.10250457	0.0050686207	713.99982
56.647949	0.10749485	0.0051640347	740.31549
57.648926	0.11056693	0.0053329119	764.58826
58.649902	0.11154795	0.0054704938	784.29907
59.650879	0.11796241	0.0057007363	814.51575
60.651855	0.11800462	0.0058660936	839.62708
61.652832	0.12293727	0.0060572876	870.08051
62.653809	0.12587295	0.0063414271	893.70599
63.654785	0.1264991	0.0064017335	920.22223
64.655762	0.1317465	0.0066608437	952.2489
65.656738	0.136438	0.0068495343	979.92792
66.657715	0.14049116	0.0070660077	1014.5845
67.658691	0.13754441	0.007173737	1038.7521
68.659668	0.14344583	0.0072851721	1058.3115
69.660645	0.14749299	0.0076181404	1093.2694
70.661621	0.15084618	0.007748106	1121.6854
71.662598	0.15294878	0.0078347167	1137.7367
72.663574	0.15377961	0.0080741206	1166.0543
73.664551	0.15930808	0.0081635583	1190.1986
74.665527	0.16026329	0.0084306141	1216.8965
75.666504	0.16277315	0.008443932	1242.3718
76.66748	0.16707094	0.0086920271	1279.715
77.668457	0.17109945	0.0090181492	1313.5894
78.669434	0.17099516	0.0090630567	1332.1115
79.67041	0.17202741	0.0091385413	1354.375
80.671387	0.17776486	0.0094026057	1379.6318
81.672363	0.18182376	0.0096215913	1411.9086
82.67334	0.18588357	0.0097973896	1440.7762
83.674316	0.18818408	0.0099916197	1466.4561
84.675293	0.19106746	0.010102849	1495.752
85.67627	0.19233738	0.010298941	1518.5078
86.677246	0.1983062	0.010480139	1541.6364
87.678223	0.20241627	0.010718007	1571.4646
88.679199	0.20338474	0.010824583	1593.5769
89.680176	0.20415533	0.010962239	1622.5442
90.681152	0.21043293	0.011209375	1653.0348
91.682129	0.21065299	0.011409158	1685.121
92.683105	0.21404941	0.011490671	1703.3615
93.684082	0.21799721	0.011751437	1732.2863
94.685059	0.22081096	0.011943889	1761.7987
95.686035	0.22555149	0.012036256	1781.2877
96.687012	0.22655314	0.012374548	1808.5177
97.687988	0.23097177	0.012410027	1834.3159
98.688965	0.23410292	0.012600983	1864.6521
99.689941	0.23833652	0.012883646	1890.2385
100.69092	0.23810479	0.012943126	1906.179
101.69189	0.24406886	0.013117294	1934.9854
102.69287	0.24738809	0.013301239	1958.0275
103.69385	0.24555473	0.013491228	1981.0059
104.69482	0.25443643	0.013700518	2018.2009
105.6958	0.25252917	0.013852656	2029.1423
106.69678	0.25768617	0.014035036	2050.9692
107.69775	0.26368022	0.014105431	2072.4333
108.69873	0.2662811	0.014256597	2090.1858
109.69971	0.26578957	0.014428663	2111.1631
110.70068	0.2685416	0.014495149	2135.5349
111.70166	0.27396849	0.014787234	2153.6313
112.70264	0.27505851	0.015007596	2181.2339
113.70361	0.27821562	0.015041571	2189.7715
114.70459	0.27929357	0.015208993	2204.137
115.70557	0.28563565	0.015351973	2233.4836
116.70654	0.28795522	0.015611457	2253.019
117.70752	0.29276192	0.015691642	2267.4082
118.7085	0.29554632	0.015937177	2287.127
119.70947	0.3004604	0.016049962	2296.8545
120.71045	0.30024567	0.01630046	2321.7007
121.71143	0.30270967	0.016465023	2338.0569
122.7124	0.30608439	0.016739979	2356.7507
123.71338	0.30908495	0.016802179	2373.8979
124.71436	0.31345728	0.017076591	2389.2957
125.71533	0.31527877	0.017187579	2396.0605
126.71631	0.31825414	0.017335238	2412.1509
127.71729	0.3205829	0.017668825	2428.4487
128.71826	0.32720676	0.017856892	2451.9868
129.71924	0.32736391	0.018002724	2452.4067
130.72021	0.32953471	0.018063039	2462.9246
131.72119	0.33531028	0.018457441	2478.3345
132.72217	0.33738539	0.01857079	2486.9294
133.72314	0.34341511	0.018861158	2508.6882
134.72412	0.33939987	0.019001367	2507.9553
135.7251	0.34489048	0.019237546	2520.626
136.72607	0.34811828	0.019553259	2537.7178
137.72705	0.35321695	0.01962883	2542.084
138.72803	0.35467678	0.020036211	2561.0522
139.729	0.36091685	0.020349113	2567.7515
140.72998	0.3612541	0.020545797	2573.5481
141.73096	0.36309218	0.020865031	2585.1592
142.73193	0.36424217	0.021115055	2594.9355
143.73291	0.37025103	0.021280315	2594.7756
144.73389	0.37309545	0.021672575	2612.6982
145.73486	0.37653798	0.02191967	2616.8601
146.73584	0.37801602	0.022177247	2622.1218
147.73682	0.38021696	0.022604773	2641.0747
148.73779	0.38492778	0.023089785	2647.824
149.73877	0.38562807	0.023433981	2653.5439
150.73975	0.39067915	0.023757992	2662.6946
151.74072	0.39183924	0.024160447	2664.8145
152.7417	0.39812854	0.024573432	2674.9729
153.74268	0.40183046	0.025012001	2680.9768
154.74365	0.40323028	0.025493177	2687.3879
155.74463	0.40829819	0.025931446	2694.4177
156.74561	0.40992871	0.026482241	2708.8896
157.74658	0.4104977	0.02707123	2711.4167
158.74756	0.41486114	0.027705576	2717.5442
159.74854	0.41954654	0.02825143	2727.4395
160.74951	0.42404658	0.028853526	2730.3069
161.75049	0.42545411	0.029576272	2741.4285
162.75146	0.42862475	0.030310789	2748.0435
163.75244	0.43547645	0.030927159	2749.9758
164.75342	0.43408793	0.031411387	2753.0098
165.75439	0.43600878	0.032058027	2755.7571
166.75537	0.44040549	0.032669064	2759.0271
167.75635	0.44213328	0.03345542	2775.2883
168.75732	0.44522625	0.034182429	2773.5908
169.7583	0.44996127	0.035162106	2788.9111
170.75928	0.45284507	0.036018327	2783.6589
171.76025	0.45496607	0.036894124	2788.4507
172.76123	0.45815617	0.037746903	2792.783
173.76221	0.46037185	0.03856964	2797.5872
174.76318	0.46528837	0.039412417	2805.5994
175.76416	0.46560922	0.040286575	2802.5288
176.76514	0.46997538	0.041047037	2810.8252
177.76611	0.47399265	0.04208073	2822.8047
178.76709	0.47565532	0.043045301	2819.7444
179.76807	0.48070133	0.04370147	2825.4463
180.76904	0.48184171	0.044614106	2835.5173
181.77002	0.48427212	0.045519788	2827.1584
182.771	0.48674572	0.046469208	2834.8809
183.77197	0.48858994	0.047329225	2839.4946
184.77295	0.49370131	0.0484154	2850.4363
185.77393	0.49846575	0.049195401	2849.6443
186.7749	0.49704507	0.049861029	2844.2244
187.77588	0.50051177	0.05092435	2852.2351
188.77686	0.5011875	0.051975835	2862.1489
189.77783	0.50758415	0.053022295	2862.7708
190.77881	0.51053947	0.053959005	2870.3447
191.77979	0.51388854	0.055193234	2873.949
192.78076	0.51798737	0.056150861	2874.844
193.78174	0.52054644	0.057320002	2885.3657
194.78271	0.52276736	0.058135163	2881.9585
195.78369	0.52966088	0.059228454	2893.0728
196.78467	0.52864259	0.060155567	2888.0447
197.78564	0.53364456	0.061204784	2889.6663
198.78662	0.53627819	0.06216469	2894.865
199.7876	0.53928387	0.063167199	2895.928
200.78857	0.54177368	0.064240634	2902.2432
201.78955	0.54325503	0.065275878	2907.5146
202.79053	0.54835427	0.066277169	2913.4202
203.7915	0.55109018	0.067478679	2918.5825
204.79248	0.5538398	0.068514511	2918.4348
205.79346	0.55705327	0.069706485	2925.0364
206.79443	0.56036097	0.070790455	2925.8096
207.79541	0.56650108	0.071775869	2926.1072
208.79639	0.56717658	0.073001429	2931.0059
209.79736	0.56790948	0.073941708	2930.8269
210.79834	0.57205397	0.074952573	2933.7368
211.79932	0.57483006	0.075928316	2931.2605
212.80029	0.57688278	0.077072807	2944.8333
213.80127	0.58159196	0.078241684	2944.939
214.80225	0.58656299	0.078970134	2945.2881
215.80322	0.5886454	0.079961099	2947.646
216.8042	0.59140676	0.080869161	2951.3398
217.80518	0.59412414	0.081638291	2949.9963
218.80615	0.59586591	0.082638696	2956.8547
219.80713	0.59800214	0.083849214	2961.2952
220.80811	0.60296673	0.085005112	2970.1008
221.80908	0.60277027	0.086288758	2967.0554
222.81006	0.60597098	0.087583311	2966.7988
223.81104	0.61080009	0.088597819	2971.5974
224.81201	0.61665434	0.089698076	2980.2192
225.81299	0.61704689	0.090783775	2976.0701
226.81396	0.62047327	0.091828503	2980.4893
227.81494	0.62408197	0.092783913	2977.5034
228.81592	0.62323457	0.093895547	2983.8977
229.81689	0.62889087	0.094912432	2986.3625
230.81787	0.62900728	0.096165046	2989.2473
231.81885	0.63589072	0.097121924	2991.8931
232.81982	0.63701129	0.098179989	2998.3979
233.8208	0.64213514	0.099427819	3002.2683
234.82178	0.64230353	0.10049634	3002.2954
235.82275	0.64572555	0.10157869	3003.312
236.82373	0.65091872	0.10267451	3003.4441
237.82471	0.65047836	0.10379768	3008.7029
238.82568	0.65816808	0.10486235	3014.3945
239.82666	0.65699691	0.10607415	3012.616
240.82764	0.66240883	0.10717384	3015.676
241.82861	0.66330647	0.10823336	3018.1948
242.82959	0.6705097	0.10941401	3020.8123
243.83057	0.67323226	0.11055899	3028.2925
244.83154	0.67474598	0.11163324	3028.136
245.83252	0.67843014	0.11270244	3022.1667
246.8335	0.68220949	0.11386693	3036.7961
247.83447	0.68253279	0.1149297	3039.4131
248.83545	0.68662047	0.11595537	3034.6277
249.83643	0.68755293	0.11712852	3037.4292
250.8374	0.69123811	0.11816724	3036.8958
251.83838	0.6955781	0.11920431	3038.1938
252.83936	0.69661617	0.12031887	3043.8718
253.84033	0.699247	0.12142292	3049.7107
254.84131	0.70635623	0.12241301	3047.4529
255.84229	0.70831269	0.12346029	3053.8982
256.84326	0.71020216	0.12452312	3046.7944
257.84424	0.71274465	0.12537748	3051.3967
258.84521	0.71697271	0.12640752	3055.8494
259.84619	0.717713	0.12750165	3060.1411
260.84717	0.7213223	0.12859306	3062.76
261.84814	0.72535449	0.12950328	3057.9417
262.84912	0.72566634	0.13047163	3064.3826
263.8501	0.73098344	0.13154052	3068.3337
264.85107	0.73137844	0.13274291	3076.7063
265.85205	0.73719072	0.13406113	3068.8936
266.85303	0.73993045	0.13518476	3078.9377
267.854	0.74106783	0.13641782	3080.6104
268.85498	0.74806476	0.13759485	3078.5496
269.85596	0.75048226	0.13883215	3092.0989
270.85693	0.75151426	0.14004518	3088.0913
271.85791	0.75545573	0.14127684	3085.781
272.85889	0.75736982	0.14236587	3084.3584
273.85986	0.76209617	0.14332305	3088.0334
274.86084	0.76090103	0.14429311	3085.0659
275.86182	0.7692976	0.14532037	3097.8823
276.86279	0.77242237	0.14647	3098.3882
277.86377	0.77448928	0.14779624	3099.198
278.86475	0.77595812	0.1489861	3099.6755
279.86572	0.77912408	0.14984529	3097.5139
280.8667	0.78322428	0.15097576	3107.2874
281.86768	0.78574282	0.15195623	3105.2236
282.86865	0.79083139	0.15281105	3111.5955
283.86963	0.7926684	0.15398687	3115.9395
284.87061	0.79468411	0.15523185	3117.1709
285.87158	0.79730117	0.15635985	3114.7031
286.87256	0.80094779	0.15719347	3113.6387
287.87354	0.80229491	0.15825206	3121.4297
288.87451	0.80411857	0.15912539	3116.6023
289.87549	0.8079443	0.16014944	3119.1719
290.87646	0.8150019	0.16122007	3127.491
291.87744	0.81572372	0.16210441	3121.9321
292.87842	0.81462282	0.16319466	3125.7629
293.87939	0.82195765	0.16437298	3134.896
294.88037	0.82311362	0.16579363	3134.9949
295.88135	0.82601672	0.16688716	3134.5049
296.88232	0.83072954	0.16757205	3127.4128
297.8833	0.83478159	0.16848922	3128.7771
298.88428	0.83516699	0.16952382	3141.854
299.88525	0.84014708	0.17076974	3149.3643
300.88623	0.84342879	0.17187934	3149.8479
301.88721	0.84446037	0.17309946	3149.438
302.88818	0.84766257	0.17428286	3147.8977
303.88916	0.85130715	0.17541011	3147.8862
304.89014	0.85560322	0.17649932	3151.6797
305.89111	0.85922116	0.17772962	3160.5334
306.89209	0.85923815	0.17890295	3156.8896
307.89307	0.86316955	0.18007576	3158.1558
308.89404	0.86566883	0.181044	3158.7112
309.89502	0.86997598	0.1820204	3156.9897
310.896	0.87323946	0.18304856	3165.3113
311.89697	0.8764019	0.18431471	3167.844
312.89795	0.87733579	0.18533595	3164.7344
313.89893	0.88135731	0.18640384	3164.2261
314.8999	0.88633305	0.18731691	3177.636
315.90088	0.88607734	0.18829705	3168.2532
316.90186	0.89068776	0.18928887	3175.2505
317.90283	0.89317513	0.19038361	3174.7283
318.90381	0.89751953	0.19163422	3176.6399
319.90479	0.9007597	0.19281082	3183.002
320.90576	0.9048388	0.19398865	3180.6589
321.90674	0.90711921	0.19519311	3182.7517
322.90771	0.90855855	0.19601576	3177.2751
323.90869	0.91209775	0.19682397	3180.8013
324.90967	0.91580254	0.19786766	3188.6702
325.91064	0.91769844	0.19888043	3191.5122
326.91162	0.92135954	0.19999023	3188.262
327.9126	0.92232215	0.20100546	3192.7729
328.91357	0.92360681	0.20189384	3186.8984
329.91455	0.92711323	0.20303911	3191.6831
330.91553	0.93103766	0.20415495	3202.3472
331.9165	0.93692726	0.20531555	3202.2092
332.91748	0.93637359	0.20630537	3194.6165
333.91846	0.94207704	0.20733468	3203.3574
334.91943	0.94671476	0.20842606	3205.8223
335.92041	0.94740033	0.20945133	3204.1921
336.92139	0.95207095	0.21065241	3216.0396
337.92236	0.95228523	0.21172814	3206.0994
338.92334	0.95733005	0.21265949	3213.3267
339.92432	0.95822459	0.21371406	3214.5442
340.92529	0.96316463	0.21468094	3212.3306
341.92627	0.968656	0.2158459	3222.2556
342.92725	0.96876585	0.21694806	3216.0439
343.92822	0.97301835	0.21780849	3220.4519
344.9292	0.97468919	0.21888006	3221.8298
345.93018	0.97686189	0.22013451	3231.8337
346.93115	0.97806185	0.2211199	3221.5212
347.93213	0.98366988	0.22229674	3226.8928
348.93311	0.98746014	0.22321913	3224.562
349.93408	0.98884517	0.22425793	3229.7834
350.93506	0.99311239	0.22535396	3234.6597
351.93604	0.99581605	0.22650217	3233.2625
352.93701	0.996876	0.22761436	3233.6816
353.93799	1.0035589	0.22867319	3237.5437
354.93896	1.0058886	0.2296498	3236.407
355.93994	1.0069499	0.23068921	3241.8132
356.94092	1.0118976	0.23178822	3245.1313
357.94189	1.0130415	0.23289497	3246.2209
358.94287	1.0161525	0.23383391	3241.0281
359.94385	1.0188134	0.23488857	3241.5356
360.94482	1.0235332	0.23581554	3249.4348
361.9458	1.0218521	0.23705135	3252.3225
362.94678	1.0270033	0.23792256	3245.0508
363.94775	1.0316831	0.238961	3253.2334
364.94873	1.0333263	0.24000214	3250.6853
365.94971	1.0353668	0.24088681	3251.23
366.95068	1.0415516	0.24196488	3259.7207
367.95166	1.0439793	0.24300799	3263.1646
368.95264	1.0476034	0.24403806	3259.2371
369.95361	1.0497483	0.24506631	3257.0002
370.95459	1.050853	0.2460857	3261.916
371.95557	1.0546136	0.24696589	3266.0991
372.95654	1.0560142	0.248071	3262.9287
373.95752	1.0620277	0.24923217	3269.2415
374.9585	1.0634054	0.25048473	3272.5293
375.95947	1.0669641	0.25150308	3270.6497
376.96045	1.0687439	0.25254408	3275.1335
377.96143	1.07184	0.25378078	3275.8215
378.9624	1.0794166	0.25487441	3274.3164
379.96338	1.0766225	0.25589961	3278.3997
380.96436	1.0849242	0.25711945	3282.8579
381.96533	1.0858946	0.25797603	3275.0215
382.96631	1.0872433	0.25884175	3277.0676
383.96729	1.0924598	0.25992548	3285.5032
384.96826	1.0947075	0.26088646	3284.9583
385.96924	1.0972894	0.26209354	3292.1309
386.97021	1.1005187	0.26309985	3283.95
387.97119	1.1053438	0.26411489	3292.0459
388.97217	1.1077111	0.26518714	3291.759
389.97314	1.1110129	0.26642719	3293.437
390.97412	1.1115353	0.26740903	3294.7981
391.9751	1.1129851	0.2685993	3296.0752
392.97607	1.1204046	0.26965341	3302.6633
393.97705	1.1225601	0.27061972	3291.3757
394.97803	1.1238204	0.27162817	3300.8328
395.979	1.1282825	0.27258718	3301.9399
396.97998	1.1280687	0.27351347	3300.6775
397.98096	1.1329018	0.274508	3299.0183
398.98193	1.1366297	0.2754727	3307.0955
399.98291	1.1401962	0.27657783	3307.2986
400.98389	1.1438959	0.27755904	3307.6235
401.98486	1.1458081	0.27870831	3310.2732
402.98584	1.1477329	0.27962205	3314.7222
403.98682	1.1538032	0.28050828	3309.8257
404.98779	1.1551076	0.28133914	3311.8416
405.98877	1.1565804	0.28237718	3309.5088
406.98975	1.1612748	0.28331104	3318.2329
407.99072	1.1642735	0.28462905	3325.1765
408.9917	1.1684755	0.28568709	3327.8694
409.99268	1.1678672	0.28702497	3326.145
410.99365	1.1715791	0.28787917	3317.5627
411.99463	1.1729349	0.288914	3319.3401
412.99561	1.1813341	0.29012218	3327.0342
413.99658	1.1807629	0.29109684	3326.5823
414.99756	1.1868553	0.29217523	3331.3848
415.99854	1.1891738	0.29324841	3328.9336
416.99951	1.1902113	0.29439694	3332.2974
418.00049	1.1925411	0.29533944	3333.7996
419.00146	1.1927092	0.29637632	3331.0027
420.00244	1.1989446	0.29729652	3333.1743
421.00342	1.2023115	0.29828236	3335.5283
422.00439	1.2014407	0.29934651	3341.0979
423.00537	1.2074238	0.30056286	3337.926
424.00635	1.2100579	0.30158949	3340.1313
425.00732	1.2155277	0.30262008	3341.6897
426.0083	1.2161021	0.30361402	3339.6409
427.00928	1.2199702	0.30461818	3339.9451
428.01025	1.2246443	0.30549613	3346.9387
429.01123	1.2300843	0.30659035	3348.7949
430.01221	1.2326653	0.30752704	3346.3633
431.01318	1.2324092	0.30823782	3344.6885
432.01416	1.2364742	0.30930492	3355.0977
433.01514	1.2397211	0.31034359	3355.7019
434.01611	1.2410837	0.31155631	3358.5
435.01709	1.2475156	0.31255388	3355.657
436.01807	1.2451636	0.3136628	3351.9729
437.01904	1.2519763	0.3146897	3360.3706
438.02002	1.2557118	0.3157784	3365.8972
439.021	1.2587774	0.31676444	3360.2419
440.02197	1.2612958	0.3177864	3362.6084
441.02295	1.2623385	0.31872261	3361.1797
442.02393	1.2660159	0.31989214	3369.4666
443.0249	1.2702407	0.32089922	3368.8232
444.02588	1.2716235	0.32189265	3367.9731
445.02686	1.2781204	0.32308137	3371.0757
446.02783	1.2784591	0.32406303	3370.2078
447.02881	1.2802774	0.32510611	3371.3843
448.02979	1.2805052	0.32624018	3371.6379
449.03076	1.2859811	0.32732511	3372.5308
450.03174	1.2900208	0.3281967	3369.0278
451.03271	1.2888073	0.32916364	3368.0076
452.03369	1.2955897	0.33010614	3372.9795
453.03467	1.3009394	0.33139843	3387.5566
454.03564	1.2999641	0.33235368	3381.9307
455.03662	1.3026726	0.33347061	3378.2913
456.0376	1.3076719	0.3344692	3385.4443
457.03857	1.3099446	0.3354691	3381.7319
458.03955	1.3141618	0.33645239	3381.6243
459.04053	1.3161991	0.33749068	3385.0471
460.0415	1.316306	0.33845446	3384.7942
461.04248	1.3222398	0.33958289	3387.0598
462.04346	1.3258538	0.34060341	3392.2654
463.04443	1.3274603	0.3415311	3388.9473
464.04541	1.3308004	0.34259292	3396.2805
465.04639	1.3350961	0.34355754	3395.196
466.04736	1.3392633	0.34476098	3393.2634
467.04834	1.33971	0.3457633	3394.3513
468.04932	1.3439608	0.34679273	3396.9028
469.05029	1.3463693	0.34776789	3394.0796
470.05127	1.3457518	0.34873825	3396.4868
471.05225	1.3529407	0.34981135	3401.1682
472.05322	1.3566021	0.35089439	3403.5923
473.0542	1.3579696	0.3518512	3404.0027
474.05518	1.3623047	0.35300174	3405.2461
475.05615	1.3663279	0.35415018	3409.7092
476.05713	1.3665037	0.35536885	3409.5845
477.05811	1.3697358	0.3563959	3405.5962
478.05908	1.3726143	0.35739911	3411.3303
479.06006	1.3753209	0.35836524	3413.5996
480.06104	1.3796362	0.3594805	3421.2622
481.06201	1.3811855	0.36068049	3410.658
482.06299	1.3850576	0.36179262	3410.761
483.06396	1.3895084	0.36298907	3422.0645
484.06494	1.3938184	0.36422908	3419.7844
485.06592	1.3958226	0.36538705	3418.5896
486.06689	1.3989049	0.36655986	3420.7629
487.06787	1.4026903	0.36749682	3422.3423
488.06885	1.4022875	0.36847886	3419.6951
489.06982	1.4063301	0.36952382	3426.8982
490.0708	1.4089767	0.37073743	3422.6465
491.07178	1.4142499	0.37183648	3425.321
492.07275	1.4142509	0.3728427	3422.6567
493.07373	1.4155048	0.37388715	3423.0801
494.07471	1.4233732	0.37476066	3429.3943
495.07568	1.4254409	0.37579378	3424.1775
496.07666	1.4272579	0.37671304	3432.8411
497.07764	1.4300468	0.37795937	3435.8232
498.07861	1.4352051	0.37914836	3433.522
499.07959	1.4361641	0.38002005	3430.4536
500.08057	1.4395442	0.3809346	3434.1392
501.08154	1.4418473	0.38189605	3436.3843
502.08252	1.4467776	0.3831594	3446.7358
503.0835	1.4500487	0.38415939	3435.6572
504.08447	1.4509476	0.38507116	3443.1189
505.08545	1.4550338	0.38613167	3439.5181
506.08643	1.4571903	0.38725498	3445.3228
507.0874	1.4618838	0.38832751	3442.2441
508.08838	1.4652265	0.38934857	3445.1375
509.08936	1.4688628	0.3906903	3446.7424
510.09033	1.4716243	0.39196351	3451.0664
511.09131	1.4716871	0.3929438	3447.8408
512.09229	1.4768376	0.39393035	3444.4541
513.09326	1.4794977	0.3948777	3451.2605
514.09424	1.4824885	0.39601493	3451.968
515.09521	1.4851509	0.39697134	3448.1257
516.09619	1.4888191	0.39801231	3457.5117
517.09717	1.493089	0.39890394	3454.751
518.09814	1.4936539	0.39979553	3451.3962
519.09912	1.4969624	0.40090019	3455.428
520.1001	1.4970274	0.40203261	3459.3093
521.10107	1.5023631	0.40343514	3461.2354
522.10205	1.5049062	0.40469393	3464.4661
523.10303	1.5079453	0.40568393	3456.4924
524.104	1.511228	0.40663072	3458.1047
525.10498	1.5136265	0.40771994	3461.1909
526.10596	1.5196794	0.40863159	3458.8794
527.10693	1.5236676	0.40960884	3469.2129
528.10791	1.5267434	0.41060916	3468.9011
529.10889	1.5259997	0.41183645	3470.3643
530.10986	1.5293345	0.41307524	3472.041
531.11084	1.5319767	0.41420576	3470.2466
532.11182	1.535238	0.41541013	3469.0713
533.11279	1.5372092	0.41641957	3471.0344
534.11377	1.5431592	0.41750392	3468.928
535.11475	1.5475799	0.41848248	3477.533
536.11572	1.5493652	0.41933405	3474.645
537.1167	1.5510368	0.42034593	3473.8765
538.11768	1.5533217	0.4214159	3477.051
539.11865	1.5561957	0.42237538	3479.7739
540.11963	1.5576514	0.42379579	3480.7644
541.12061	1.5621829	0.42482358	3477.4661
542.12158	1.5644716	0.42609268	3481.3003
543.12256	1.5663357	0.42728284	3482.0864
544.12354	1.5695802	0.42837182	3475.5593
545.12451	1.5735523	0.42927441	3478.2786
546.12549	1.579227	0.43030381	3484.7141
547.12646	1.5794485	0.43137392	3486.9922
548.12744	1.5845964	0.43265513	3487.4646
549.12842	1.5897948	0.43368572	3483.7148
550.12939	1.5901382	0.43472591	3486.6514
551.13037	1.5929505	0.43590242	3490.7153
552.13135	1.5961291	0.43703774	3485.8875
553.13232	1.5973275	0.43813658	3488.1633
554.1333	1.6018635	0.43933186	3493.2078
555.13428	1.6033045	0.44033065	3491.1438
556.13525	1.6063108	0.44153956	3493.2175
557.13623	1.6103954	0.44268897	3492.8066
558.13721	1.613093	0.44365972	3493.2283
559.13818	1.6162111	0.4448427	3503.2021
560.13916	1.6218512	0.4460665	3498.072
561.14014	1.6234077	0.44719079	3505.1445
562.14111	1.6280464	0.44816428	3498.5762
563.14209	1.6297759	0.44928813	3506.3462
564.14307	1.630054	0.45053977	3505.0796
565.14404	1.6327847	0.45148385	3497.1021
566.14502	1.6385572	0.45248541	3500.9536
567.146	1.6422262	0.45385927	3509.4729
568.14697	1.6439999	0.45516255	3501.5837
569.14795	1.6481594	0.45630908	3510.9978
570.14893	1.6483692	0.45734498	3508.7197
571.1499	1.6524274	0.45844632	3510.8958
572.15088	1.6559852	0.45932496	3505.7397
573.15186	1.6608539	0.46038002	3504.4426
574.15283	1.6642884	0.46138129	3513.085
575.15381	1.6647115	0.46252704	3511.1121
576.15479	1.6671257	0.46373585	3510.6943
577.15576	1.6728042	0.46494639	3520.4326
578.15674	1.6747642	0.46600112	3511.0544
579.15771	1.6790012	0.46699893	3511.9961
580.15869	1.6808325	0.46796516	3518.5344
581.15967	1.6816601	0.46919647	3517.0845
582.16064	1.6848084	0.47022519	3516.55
583.16162	1.6901127	0.47137803	3518.5867
584.1626	1.6892706	0.47260991	3519.6448
585.16357	1.6974547	0.47399583	3527.7024
586.16455	1.6992756	0.47509021	3527.9634
587.16553	1.7004379	0.47631639	3522.5146
588.1665	1.7064631	0.47742543	3523.6084
589.16748	1.7075179	0.47844052	3523.3794
590.16846	1.7091542	0.47960326	3523.4417
591.16943	1.7137284	0.48088723	3530.7554
592.17041	1.7181276	0.48178092	3521.8174
593.17139	1.7189786	0.4828133	3524.8398
594.17236	1.7210602	0.48404816	3529.1614
595.17334	1.7257868	0.4856005	3534.4094
596.17432	1.7293007	0.48683199	3531.1416
597.17529	1.7314698	0.4881928	3534.4951
598.17627	1.7365085	0.48936656	3532.5796
599.17725	1.735881	0.49044907	3531.979
600.17822	1.7396538	0.49134728	3530.3203
601.1792	1.7440856	0.49230802	3526.7224
602.18018	1.7459353	0.49336421	3534.1069
603.18115	1.7492893	0.49438435	3538.1228
604.18213	1.7502748	0.49564457	3544.6748
605.18311	1.7557452	0.49702618	3535.7434
606.18408	1.7567079	0.49806091	3531.614
607.18506	1.7639199	0.49913898	3539.2759
608.18604	1.765178	0.50010431	3538.2451
609.18701	1.768465	0.50144887	3545.3193
610.18799	1.7708172	0.50291514	3547.0513
611.18896	1.7739136	0.50383115	3534.3679
612.18994	1.7760363	0.50480449	3539.6494
613.19092	1.7811546	0.50603807	3544.5039
614.19189	1.7832958	0.50717175	3546.3706
615.19287	1.7838085	0.50827265	3542.5103
616.19385	1.7877045	0.5096606	3551.1543
617.19482	1.7927071	0.51086164	3546.2122
618.1958	1.7931464	0.51208502	3551.0447
619.19678	1.7949176	0.51348186	3549.3486
620.19775	1.7960826	0.51485687	3552.2036
621.19873	1.8030617	0.51607311	3547.1658
622.19971	1.8082572	0.51730001	3553.5671
623.20068	1.809284	0.51851958	3545.1118
624.20166	1.8136812	0.51958841	3556.9048
625.20264	1.8167144	0.52071279	3547.2783
626.20361	1.8174567	0.52183557	3545.9263
627.20459	1.8222932	0.52303576	3555.8108
628.20557	1.820416	0.52419102	3552.0867
629.20654	1.8257565	0.52547342	3556.9673
630.20752	1.8293604	0.52665305	3559.3635
631.2085	1.8324969	0.52792948	3556.7666
632.20947	1.8369272	0.52917731	3559.9507
633.21045	1.8402474	0.53067839	3565.5757
634.21143	1.8416976	0.53201777	3563.1831
635.2124	1.8459476	0.53330898	3556.6226
636.21338	1.8487331	0.53447175	3557.1528
637.21436	1.8516147	0.53545105	3555.9629
638.21533	1.852121	0.53648335	3559.3394
639.21631	1.8578269	0.53785044	3564.9961
640.21729	1.8612009	0.53905815	3572.626
641.21826	1.8599634	0.54027879	3563.8914
642.21924	1.8646934	0.54150164	3564.2441
643.22021	1.8720508	0.54291922	3569.5791
644.22119	1.8707471	0.54411918	3563.2322
645.22217	1.8753037	0.54542607	3569.292
646.22314	1.8789603	0.54687542	3571.459
647.22412	1.8798976	0.54784727	3561.5291
648.2251	1.8853103	0.54903173	3567.512
649.22607	1.8922569	0.55025607	3575.0273
650.22705	1.8919991	0.55138642	3568.6265
651.22803	1.8924991	0.55272186	3572.8774
652.229	1.8961916	0.5540657	3572.2544
653.22998	1.9022232	0.55535191	3576.3567
654.23096	1.9031314	0.5564605	3575.8948
655.23193	1.9054217	0.55762851	3569.2983
656.23291	1.910513	0.5589785	3577.5396
657.23389	1.9095601	0.56006354	3573.6611
658.23486	1.9151725	0.5612148	3575.2205
659.23584	1.9181312	0.56248432	3576.7642
660.23682	1.9195099	0.56397313	3580.0117
661.23779	1.9231534	0.5654065	3580.5151
662.23877	1.9275262	0.56685174	3581.2817
663.23975	1.9285445	0.56812966	3580.2637
664.24072	1.9308954	0.56941789	3583.019
665.2417	1.9358244	0.5708124	3579.8857
666.24268	1.9399239	0.57215428	3582.2104
667.24365	1.9417994	0.57346833	3585.3572
668.24463	1.9425013	0.57496154	3586.8481
669.24561	1.9458072	0.5760504	3575.0405
670.24658	1.9503287	0.57700926	3582.6492
671.24756	1.9545896	0.57812834	3579.146
672.24854	1.9564809	0.57942522	3586.3362
673.24951	1.9594169	0.58090806	3587.2549
674.25049	1.9624492	0.58218193	3582.5093
675.25146	1.9619089	0.58349782	3584.0718
676.25244	1.9671961	0.58462584	3581.666
677.25342	1.9713439	0.58592963	3587.0083
678.25439	1.9757656	0.58725518	3588.4534
679.25537	1.9790893	0.58868366	3599.7759
680.25635	1.9787685	0.58994764	3584.6858
681.25732	1.9844506	0.59119034	3589.8259
682.2583	1.9874486	0.59245288	3593.4353
683.25928	1.9879751	0.59376186	3589.4163
684.26025	1.990778	0.59509051	3587.7744
685.26123	1.9958848	0.59641832	3592.8904
686.26221	1.9980514	0.59772629	3589.5474
687.26318	2.0017784	0.59903878	3594.5234
688.26416	2.0019448	0.60043299	3594.6897
689.26514	2.0050066	0.60164034	3588.7739
690.26611	2.0128779	0.60294008	3595.2407
691.26709	2.0134766	0.60427296	3593.1267
692.26807	2.0173116	0.60568738	3599.6958
693.26904	2.0202823	0.60733259	3599.9414
694.27002	2.0250013	0.60880911	3599.05
695.271	2.0241928	0.61004615	3596.7563
696.27197	2.027348	0.61154914	3597.0742
697.27295	2.0332892	0.61296278	3602.6001
698.27393	2.0334508	0.61410183	3593.4033
699.2749	2.0376279	0.6154319	3594.7117
700.27588	2.0390544	0.61692148	3602.4438
701.27686	2.0453615	0.6183238	3606.7305
702.27783	2.047864	0.61976904	3597.8352
703.27881	2.0490284	0.62116522	3596.269
704.27979	2.0532951	0.62224096	3599.4402
705.28076	2.0556509	0.62359899	3604.1189
706.28174	2.059793	0.62508452	3607.9312
707.28271	2.062448	0.6266492	3608.2019
708.28369	2.0649173	0.62824774	3603.0476
709.28467	2.0684056	0.62954736	3605.0947
710.28564	2.0714746	0.63077432	3602.2864
711.28662	2.0736523	0.63207722	3607.4773
712.2876	2.0730886	0.63326442	3598.7773
713.28857	2.0793171	0.6345048	3604.8899
714.28955	2.0834358	0.63592291	3602.1365
715.29053	2.0859549	0.6371268	3604.2629
716.2915	2.0888658	0.63853371	3603.2839
717.29248	2.0919974	0.64012784	3608.6067
718.29346	2.0978873	0.64142305	3606.1707
719.29443	2.0984311	0.64269829	3606.0388
720.29541	2.0996139	0.6442728	3613.9927
721.29639	2.1028562	0.64560342	3605.1765
722.29736	2.1022599	0.64690197	3606.0398
723.29834	2.1088274	0.64848298	3606.8821
724.29932	2.1135714	0.65006274	3615.1511
725.30029	2.1158304	0.65169966	3614.3577
726.30127	2.1206486	0.65325195	3607.8225
727.30225	2.1215096	0.6548087	3609.1702
728.30322	2.1260579	0.65630537	3607.7034
729.3042	2.1265371	0.65782875	3612.7991
730.30518	2.1310792	0.65919161	3611.0007
731.30615	2.133606	0.66052139	3613.4814
732.30713	2.1355548	0.66181558	3609.6531
733.30811	2.1398449	0.66338968	3614.2263
734.30908	2.1416566	0.66487998	3608.8682
735.31006	2.1423364	0.66652614	3614.4526
736.31104	2.1472914	0.66807467	3611.1895
737.31201	2.1501791	0.66957831	3614.2615
738.31299	2.153811	0.67092311	3613.1108
739.31396	2.159404	0.67265934	3610.8918
740.31494	2.1591041	0.67415452	3614.3474
741.31592	2.1641769	0.67566228	3618.5925
742.31689	2.1674125	0.67734712	3619.0461
743.31787	2.1696391	0.67882979	3618.8313
744.31885	2.1712294	0.68036491	3615.7773
745.31982	2.1754258	0.68184108	3617.2703
746.3208	2.1782882	0.6831212	3617.4475
747.32178	2.1824136	0.6845783	3618.0671
748.32275	2.184335	0.68621987	3616.6812
749.32373	2.1867185	0.68749952	3613.3457
750.32471	2.1914942	0.68896556	3621.2324
751.32568	2.1938937	0.6903761	3620.4031
752.32666	2.1981211	0.69184512	3614.7981
753.32764	2.2009764	0.69334263	3620.5107
754.32861	2.2015142	0.69471735	3617.1284
755.32959	2.2061195	0.69650388	3623.979
756.33057	2.2070718	0.69799757	3621.2249
757.33154	2.2094817	0.69958025	3617.186
758.33252	2.213454	0.70133185	3618.3816
759.3335	2.2195203	0.70282787	3619.1243
760.33447	2.2214739	0.70447326	3622.6584
761.33545	2.2257407	0.70613337	3622.5559
762.33643	2.2263339	0.70786977	3619.0947
763.3374	2.2308083	0.7096557	3623.4348
764.33838	2.2328365	0.71119261	3620.478
765.33936	2.235888	0.71272075	3622.9058
766.34033	2.239778	0.71441758	3622.2139
767.34131	2.2420671	0.71600658	3621.6707
768.34229	2.2473462	0.71772379	3624.5515
769.34326	2.2502704	0.71981776	3626.8738
770.34424	2.2503474	0.72137916	3622.7322
771.34521	2.2534726	0.72299933	3624.0894
772.34619	2.2567694	0.72472954	3628.6577
773.34717	2.2611001	0.72627074	3618.2161
774.34814	2.2619936	0.7274704	3623.4082
775.34912	2.2669339	0.72912616	3624.2141
776.3501	2.2713561	0.7308926	3627.7361
777.35107	2.2695961	0.73259443	3626.063
778.35205	2.2758262	0.73442757	3627.4861
779.35303	2.2794874	0.73603684	3624.7837
780.354	2.2824616	0.73785686	3626.2949
781.35498	2.2864385	0.73951316	3623.8206
782.35596	2.2855849	0.74128842	3625.217
783.35693	2.2888415	0.74298137	3623.1919
784.35791	2.2937775	0.7446512	3628.0095
785.35889	2.2959654	0.74658537	3627.6931
786.35986	2.2978499	0.74824196	3622.8767
787.36084	2.3010631	0.74952745	3618.3435
788.36182	2.3069806	0.75112349	3627.1323
789.36279	2.3099613	0.75257009	3619.3271
790.36377	2.3106883	0.75446832	3625.7275
791.36475	2.3140147	0.75640476	3630.3813
792.36572	2.3171759	0.7582171	3622.6208
793.3667	2.3222928	0.75972855	3626.3982
794.36768	2.3234389	0.76139951	3622.7834
795.36865	2.3265917	0.76285487	3627.105
796.36963	2.3274062	0.76489037	3626.541
797.37061	2.3298025	0.76664186	3627.8586
798.37158	2.3365119	0.76839483	3627.6772
799.37256	2.3388681	0.77015108	3628.0491
800.37354	2.3435268	0.77192819	3633.2534
801.37451	2.3411391	0.77370554	3623.3948
802.37549	2.3476508	0.77542526	3625.6482
803.37646	2.3482265	0.7772876	3622.0645
804.37744	2.3516321	0.77905279	3625.7134
805.37842	2.3567662	0.7808404	3628.0522
806.37939	2.3588176	0.78295857	3633.1719
807.38037	2.3645654	0.78512812	3629.6545
808.38135	2.3628874	0.78696662	3622.6257
809.38232	2.3688538	0.78889698	3626.4927
810.3833	2.3722615	0.79094791	3628.7119
811.38428	2.3713357	0.79277444	3617.7412
812.38525	2.3765607	0.79432654	3619.7156
813.38623	2.3784964	0.79595584	3623.092
814.38721	2.3835888	0.79792142	3630.5867
815.38818	2.3859591	0.79973024	3621.6414
816.38916	2.3880591	0.80190045	3625.5864
817.39014	2.3907442	0.80388242	3623.2034
818.39111	2.3939481	0.80584931	3622.0398
819.39209	2.3964074	0.80797905	3625.7429
820.39307	2.4012265	0.80974215	3620.6101
821.39404	2.403734	0.81160641	3624.6416
822.39502	2.4025793	0.8136636	3628.9773
823.396	2.4086947	0.81566507	3621.8804
824.39697	2.4126797	0.81730473	3623.7219
825.39795	2.4142489	0.81938344	3619.542
826.39893	2.4215534	0.82124221	3625.918
827.3999	2.4227657	0.82276452	3620.0205
828.40088	2.4233251	0.8244397	3624.8872
829.40186	2.4286551	0.82652181	3628.7292
830.40283	2.429703	0.82877183	3622.1045
831.40381	2.4342284	0.83111262	3627.9448
832.40479	2.4361765	0.8335008	3624.1853
833.40576	2.4378376	0.83567071	3620.075
834.40674	2.4419937	0.83774972	3615.8315
835.40771	2.4449179	0.83934242	3619.634
836.40869	2.4466648	0.84124923	3617.9268
837.40967	2.4535482	0.84296948	3620.0461
838.41064	2.4539094	0.84514964	3619.991
839.41162	2.4593446	0.84725958	3621.7063
840.4126	2.4635768	0.8490541	3616.2185
841.41357	2.4644949	0.85101628	3621.0713
842.41455	2.4685409	0.85334885	3626.1753
843.41553	2.4700973	0.85597777	3623.8767
844.4165	2.4738483	0.8582322	3615.7927
845.41748	2.4767051	0.86040014	3617.6306
846.41846	2.4793239	0.86249572	3621.6255
847.41943	2.4823959	0.86465412	3618.2524
848.42041	2.4849975	0.8666532	3618.2585
849.42139	2.4885626	0.86874968	3614.0935
850.42236	2.4914691	0.87057465	3619.5242
851.42334	2.494828	0.87278664	3620.3293
852.42432	2.4965506	0.8756327	3626.0842
853.42529	2.4977334	0.87829518	3617.1631
854.42627	2.5026164	0.88069522	3615.8308
855.42725	2.5048985	0.88315052	3617.9126
856.42822	2.5098858	0.88553733	3615.8152
857.4292	2.5130899	0.88754296	3614.4463
858.43018	2.5173123	0.88932872	3615.4187
859.43115	2.5209582	0.89131343	3612.9072
860.43213	2.5248947	0.89333582	3614.4846
861.43311	2.52548	0.8952111	3610.1528
862.43408	2.5278795	0.89727575	3614.8572
863.43506	2.5281067	0.89958292	3612.4812
864.43604	2.5322864	0.90167731	3609.2634
865.43701	2.537576	0.9041959	3612.8447
866.43799	2.5386851	0.90657556	3609.9204
867.43896	2.5442154	0.90909636	3613.4678
868.43994	2.547323	0.91165173	3614.0466
869.44092	2.5479555	0.91381311	3606.2314
870.44189	2.5498693	0.91617513	3610.2537
871.44287	2.5541415	0.91851437	3605.8992
872.44385	2.5566225	0.92077166	3607.5942
873.44482	2.5607409	0.92305315	3607.4617
874.4458	2.5634439	0.92582744	3612.1653
875.44678	2.5663831	0.92834425	3606.4739
876.44775	2.5668051	0.93085229	3601.1069
877.44873	2.5735068	0.9333086	3604.9568
878.44971	2.5722075	0.93534499	3597.0002
879.45068	2.5791495	0.93785226	3602.8743
880.45166	2.584053	0.93985188	3599.0234
881.45264	2.5831604	0.94217771	3599.2849
882.45361	2.5879261	0.94447011	3600.1477
883.45459	2.5906899	0.94700241	3599.7581
884.45557	2.5904806	0.94947392	3599.8938
885.45654	2.5955358	0.95201188	3597.2798
886.45752	2.6023529	0.95498544	3598.8242
887.4585	2.6002297	0.95777005	3592.3496
888.45947	2.603457	0.96058625	3594.0627
889.46045	2.6077819	0.96300572	3588.7212
890.46143	2.6108711	0.96546638	3591.3831
891.4624	2.6132405	0.96803278	3591.3708
892.46338	2.6178417	0.97071618	3586.0259
893.46436	2.6197853	0.97297788	3589.8528
894.46533	2.6213388	0.97498691	3580.1357
895.46631	2.6274943	0.97767407	3595.0808
896.46729	2.6279941	0.98055315	3589.4453
897.46826	2.6341741	0.98331988	3591.6462
898.46924	2.6354718	0.98618221	3585.7876
899.47021	2.6372426	0.988805	3579.0044
900.47119	2.6408973	0.9910208	3578.9238
901.47217	2.643163	0.99335128	3585.0447
902.47314	2.6494217	0.99585146	3580.8386
903.47412	2.6530232	0.99858779	3581.8811
904.4751	2.6545129	1.0013927	3581.6792
905.47607	2.6591315	1.0040333	3578.7722
906.47705	2.6596839	1.006876	3575.728
907.47803	2.6603115	1.009192	3572.3782
908.479	2.6656954	1.0118998	3576.8486
909.47998	2.6682951	1.0149782	3575.1191
910.48096	2.6720324	1.0177989	3570.5974
911.48193	2.6772873	1.0203071	3570.374
912.48291	2.6747544	1.0226712	3566.6328
913.48389	2.6791179	1.0255849	3567.3281
914.48486	2.6852911	1.0284818	3562.877
915.48584	2.6866186	1.0308912	3563.6348
916.48682	2.6897283	1.0333637	3565.7666
917.48779	2.693553	1.0367643	3566.6501
918.48877	2.6938987	1.03969	3560.6038
919.48975	2.6971202	1.0426874	3562.6475
920.49072	2.7016912	1.0455407	3557.4561
921.4917	2.7009857	1.0482897	3553.3254
922.49268	2.7061498	1.0512198	3554.3523
923.49365	2.7102473	1.0544488	3550.6108
924.49463	2.713526	1.0570811	3550.8125
925.49561	2.7168067	1.059629	3552.0408
926.49658	2.7189472	1.0624127	3548.6096
927.49756	2.724853	1.0652666	3551.2397
928.49854	2.7267396	1.0682701	3547.1853
929.49951	2.7309141	1.0711761	3541.3154
930.50049	2.7320888	1.0739647	3541.113
931.50146	2.7361345	1.077078	3535.9302
932.50244	2.73967	1.0797123	3536.9285
933.50342	2.7428722	1.0827188	3537.6357
934.50439	2.7424698	1.0857347	3534.1919
935.50537	2.7435956	1.0887522	3531.1023
936.50635	2.7501638	1.0915693	3527.678
937.50732	2.7552807	1.0943887	3528.386
938.5083	2.7574666	1.0967523	3532.1941
939.50928	2.7620866	1.0994318	3527.363
940.51025	2.7636414	1.1023188	3530.355
941.51123	2.7633092	1.105376	3519.1262
942.51221	2.7673872	1.108072	3516.2581
943.51318	2.7702506	1.1108049	3513.8928
944.51416	2.7775531	1.1138455	3521.2605
945.51514	2.7752204	1.1166455	3509.3198
946.51611	2.7799885	1.1195428	3511.4287
947.51709	2.7830534	1.1220833	3512.145
948.51807	2.7859032	1.1249115	3508.5732
949.51904	2.7888937	1.1282539	3505.4976
950.52002	2.7919834	1.1317953	3505.781
951.521	2.7945254	1.134522	3492.8652
952.52197	2.796411	1.1373684	3500.2075
953.52295	2.8030465	1.140457	3497.8887
954.52393	2.8017688	1.1435537	3495.4402
955.5249	2.8047965	1.1460538	3487.2695
956.52588	2.8086951	1.1489043	3491.2236
957.52686	2.8116786	1.1524493	3488.2168
958.52783	2.8128257	1.1557584	3487.2317
959.52881	2.8182442	1.159036	3485.9878
960.52979	2.8221264	1.162093	3475.5525
961.53076	2.8255954	1.1652462	3479.7573
962.53174	2.8283322	1.1683129	3479.012
963.53271	2.8311458	1.1709075	3469.1689
964.53369	2.832315	1.1732337	3463.759
965.53467	2.8383319	1.1756897	3470.113
966.53564	2.8386636	1.1785352	3469.5732
967.53662	2.8426743	1.1817231	3465.625
968.5376	2.8440917	1.1843888	3461.2317
969.53857	2.8494568	1.1872355	3457.8955
970.53955	2.8526053	1.1906956	3465.6697
971.54053	2.8555751	1.1951884	3463.3035
972.5415	2.8580325	1.1986393	3446.4172
973.54248	2.8618691	1.2016572	3449.6848
974.54346	2.8634636	1.2046214	3446.3264
975.54443	2.8655715	1.2073573	3440.0623
976.54541	2.8696327	1.2102535	3440.75
977.54639	2.872282	1.213055	3439.7065
978.54736	2.8775856	1.2162765	3434.127
979.54834	2.8782763	1.2197109	3438.1404
980.54932	2.8824797	1.2228618	3428.082
981.55029	2.8846021	1.2254723	3420.2727
982.55127	2.8872311	1.2283552	3423.6807
983.55225	2.8901067	1.2315049	3417.3064
984.55322	2.8956785	1.2344438	3417.6025
985.5542	2.8965018	1.2376792	3421.4041
986.55518	2.9005249	1.241449	3410.3152
987.55615	2.899076	1.2447766	3405.0613
988.55713	2.907208	1.2479815	3404.1323
989.55811	2.9083354	1.2508568	3402.9658
990.55908	2.9095511	1.2543048	3392.6147
991.56006	2.9150507	1.2576838	3398.261
992.56104	2.9160631	1.2608985	3393.6555
993.56201	2.9229994	1.2639922	3388.2908
994.56299	2.9257264	1.2675682	3389.0125
995.56396	2.9291615	1.2710649	3387.2717
996.56494	2.9306645	1.2747446	3376.4148
997.56592	2.9343476	1.2776784	3374.4661
998.56689	2.9353397	1.2802455	3372.593
999.56787	2.940304	1.2835084	3372.8384
1000.5688	2.9430099	1.286276	3360.5073
1001.5698	2.9452419	1.2892042	3364.0198
1002.5708	2.9499433	1.2924471	3360.7468
1003.5718	2.9529951	1.2952645	3349.1741
1004.5728	2.9531436	1.2984896	3354.5566
1005.5737	2.9588532	1.3019857	3352.0254
1006.5747	2.9607689	1.3050292	3344.324
1007.5757	2.9616013	1.3076454	3334.9597
1008.5767	2.9661365	1.3102542	3331.3694
1009.5776	2.9668963	1.313329	3338.0449
1010.5786	2.9713659	1.3169169	3334.6531
1011.5796	2.9755855	1.3208755	3325.7803
1012.5806	2.9816303	1.3238634	3323.104
1013.5815	2.9837008	1.3270659	3317.6228
1014.5825	2.9823792	1.3298049	3307.8245
1015.5835	2.9855998	1.331807	3298.5583
1016.5845	2.9884143	1.3340424	3305.6477
1017.5854	2.9953442	1.3362432	3304.6072
1018.5864	2.9944229	1.339115	3309.1296
1019.5874	2.9969916	1.3429902	3300.7253
1020.5884	3.0003822	1.3465238	3299.0522
1021.5894	3.0065274	1.3499069	3290.9143
1022.5903	3.0083218	1.3533746	3291.1243
1023.5913	3.0104933	1.3570794	3283.4277
1024.5923	3.0148983	1.3601948	3275.3196
1025.5933	3.0164669	1.3637482	3274.3621
1026.5942	3.0199287	1.3672205	3272.6047
1027.5952	3.0236042	1.370538	3267.5173
1028.5962	3.024291	1.3737301	3261.3438
1029.5972	3.0324419	1.3770099	3256.4749
1030.5981	3.0353353	1.3798772	3252.937
1031.5991	3.0327435	1.3831791	3250.9236
1032.6001	3.0373981	1.3868895	3239.6511
1033.6011	3.0407131	1.389997	3239.0386
1034.6021	3.044611	1.3930106	3239.0933
1035.603	3.0465329	1.3967159	3235.7751
1036.604	3.0484984	1.4003152	3223.2253
1037.605	3.0508158	1.4038528	3218.1572
1038.606	3.0597105	1.4074321	3214.6069
1039.6069	3.0618725	1.4104528	3212.2698
1040.6079	3.0625982	1.4133618	3211.1902
1041.6089	3.0654941	1.41662	3203.9167
1042.6099	3.067152	1.4196025	3194.1089
1043.6108	3.0696163	1.4230866	3193.4873
1044.6118	3.0739748	1.426699	3188.0076
1045.6128	3.0795338	1.4296271	3178.136
1046.6138	3.0795815	1.4325713	3182.4319
1047.6147	3.082648	1.4365375	3179.7451
1048.6157	3.0830641	1.4406221	3164.9883
1049.6167	3.0879347	1.4437574	3161.2737
1050.6177	3.0910556	1.4469267	3154.0522
1051.6187	3.0925453	1.4497997	3146.071
1052.6196	3.0996838	1.4530481	3150.4343
1053.6206	3.1017423	1.456689	3145.4944
1054.6216	3.1060059	1.4602934	3139.3188
1055.6226	3.1057272	1.4636151	3129.9807
1056.6235	3.1108944	1.4672947	3134.2397
1057.6245	3.1115174	1.4714621	3117.2202
1058.6255	3.1160128	1.4752024	3116.6316
1059.6265	3.1213305	1.4796876	3110.6101
1060.6274	3.1222038	1.4832484	3102.1172
1061.6284	3.1282015	1.4869417	3098.363
1062.6294	3.1285231	1.4904289	3088.3718
1063.6304	3.1313534	1.4931722	3082.0122
1064.6313	3.1353574	1.496551	3085.8433
1065.6323	3.1379044	1.4998789	3072.0444
1066.6333	3.1435478	1.5035766	3073.7148
1067.6343	3.1425705	1.5068884	3060.6719
1068.6353	3.1453133	1.5099962	3055.6008
1069.6362	3.1511338	1.513345	3050.3267
1070.6372	3.153693	1.5174696	3049.8506
1071.6382	3.1568234	1.521318	3039.4822
1072.6392	3.1620233	1.524613	3033.3694
1073.6401	3.1610119	1.5283237	3028.2732
1074.6411	3.1634388	1.5318652	3021.2344
1075.6421	3.1677516	1.5355821	3009.5154
1076.6431	3.1705413	1.5385076	3004.488
1077.644	3.1726711	1.5416105	3000.9031
1078.645	3.1791291	1.5446556	2994.9692
1079.646	3.1806064	1.5479256	2994.2542
1080.647	3.1793106	1.5513971	2979.2825
1081.6479	3.1884861	1.5551671	2975.884
1082.6489	3.1887619	1.5589755	2973.0796
1083.6499	3.1905499	1.5631036	2969.0981
1084.6509	3.1938317	1.5669515	2948.1479
1085.6519	3.1977594	1.5702314	2935.5549
1086.6528	3.1996863	1.5735559	2938.8118
1087.6538	3.2040107	1.5763493	2927.9424
1088.6548	3.2066793	1.5799361	2926.1228
1089.6558	3.2098539	1.5836827	2919.5732
1090.6567	3.2139206	1.58759	2909.2822
1091.6577	3.2144821	1.5912957	2898.7974
1092.6587	3.2201076	1.5949749	2899.0879
1093.6597	3.2229354	1.5988972	2890.7341
1094.6606	3.224694	1.6026607	2880.6296
1095.6616	3.228642	1.6065849	2870.4519
1096.6626	3.2317376	1.6108328	2858.0488
1097.6636	3.2321606	1.6152682	2855.3013
1098.6646	3.2375972	1.619554	2841.6575
1099.6655	3.2413008	1.6231298	2823.9204
1100.6665	3.2429721	1.6261226	2822.2974
1101.6675	3.2448814	1.6292567	2820.9187
1102.6685	3.2467828	1.6337774	2810.6428
1103.6694	3.2493169	1.6376882	2794.8672
1104.6704	3.2547185	1.641493	2785.2854
1105.6714	3.2597933	1.646157	2778.9131
1106.6724	3.2604811	1.6501123	2757.001
1107.6733	3.265826	1.6535193	2752.592
1108.6743	3.2671366	1.6568127	2741.0859
1109.6753	3.2699027	1.6601988	2733.8306
1110.6763	3.2708364	1.6641076	2720.6094
1111.6772	3.2782373	1.6680329	2709.447
1112.6782	3.2774122	1.671719	2695.1641
1113.6792	3.2841771	1.6753401	2685.3867
1114.6802	3.2829137	1.6795566	2674.8198
1115.6812	3.2889037	1.6845384	2661.0505
1116.6821	3.2950122	1.6887648	2651.854
1117.6831	3.2945004	1.6931204	2632.6841
1118.6841	3.299623	1.698393	2612.3005
1119.4849	3.3037052	1.7077491	2547.8008