File: datasets/am_bench_2022/raw_data/60-XY.15-4/specimen.dat
MTS793|MPT|ENU|1|2|.|/|:|1|0|0|A

Operator Information						Time:	10.552734	Sec	11/2/2021 10:19:51 AM
Operator	Nick Derimow
Project	AM Bench 2022 mini-tensile challenge
Specimen ID	60-XY.15-4
Material	PBF-L Inconel 625
Specimen Width	2.54	mm
Specimen Thickness	1.5	mm
Notes
Operator Information End

Data Acquisition						Time:	1011.5471	Sec	11/2/2021 10:36:32 AM
Time	Axial Displacement	Axial Extensometer	Axial Force
Sec	mm	mm	N
10.666992	0.0027227995	3.4170367e-05	71.873688
11.667969	0.0016036852	5.0102688e-05	83.467972
12.668945	0.0061829984	0.00023086775	99.784195
13.669922	0.012789195	0.00024141964	110.47974
14.670898	0.012121661	0.00035740636	120.51272
15.671875	0.015833618	0.00035162433	133.81044
16.672852	0.019424332	0.00039733551	144.90996
17.673828	0.021517653	0.00039782314	153.22137
18.674805	0.023485631	0.00062207732	172.84557
19.675781	0.027067482	0.00065358134	186.7641
20.676758	0.030470056	0.0007077576	205.70885
21.677734	0.030880658	0.00069178431	220.3927
22.678711	0.037388302	0.00082858489	237.96526
23.679688	0.038011376	0.00095000124	258.47482
24.680664	0.043344431	0.0010143369	280.93924
25.681641	0.045229837	0.0011001894	293.87772
26.682617	0.049274743	0.0011661099	316.89444
27.683594	0.052730795	0.0012863021	336.08148
28.68457	0.052039493	0.0013781947	348.65439
29.685547	0.056376573	0.0014348993	371.33429
30.686523	0.059900492	0.0015380158	392.09344
31.6875	0.064487696	0.0016985581	419.3399
32.688477	0.066796407	0.001790676	448.01358
33.689453	0.067484632	0.0018728127	468.65323
34.69043	0.07152237	0.0019938315	487.90057
35.691406	0.072658487	0.0021044717	517.758
36.692383	0.077118091	0.002223708	538.36194
37.693359	0.079636976	0.0023292955	561.96777
38.694336	0.083855629	0.0024351205	589.86169
39.695313	0.086366564	0.0025076019	612.15845
40.696289	0.089531876	0.0025735183	630.40118
41.697266	0.090624355	0.0026656005	656.2757
42.698242	0.095001541	0.0028125052	683.30884
43.699219	0.098527715	0.0029230674	711.41193
44.700195	0.10026724	0.0029255918	732.50244
45.701172	0.1044566	0.0031309878	761.04095
46.702148	0.10674579	0.0032516469	786.73047
47.703125	0.1105397	0.0033286277	826.64545
48.704102	0.11098555	0.003583017	857.51422
49.705078	0.11664602	0.0036678656	886.06714
50.706055	0.11786532	0.0037178467	917.03687
51.707031	0.12418304	0.00390068	939.7807
52.708008	0.126385	0.0040152962	968.67926
53.708984	0.12660997	0.0041398513	996.19812
54.709961	0.12954436	0.0042264252	1019.9977
55.710938	0.13347986	0.004324235	1047.043
56.711914	0.13763253	0.0044911248	1077.9824
57.712891	0.13964908	0.0046584122	1101.8354
58.713867	0.14215341	0.0046408651	1131.8248
59.714844	0.14504355	0.0049017211	1157.1564
60.71582	0.14838056	0.0049813366	1183.0426
61.716797	0.15022314	0.0050794301	1220.4789
62.717773	0.15645035	0.0052487981	1255.449
63.71875	0.15796039	0.0054224832	1281.9454
64.719727	0.16055426	0.0055110105	1307.2609
65.720703	0.16216588	0.005610018	1331.2344
66.72168	0.16819663	0.0057393718	1369.8878
67.722656	0.1733311	0.0058788359	1394.2773
68.723633	0.17425311	0.0060363947	1424.5782
69.724609	0.17530988	0.0061739781	1447.5072
70.725586	0.17929113	0.0062365877	1478.0354
71.726563	0.18065652	0.0064207376	1496.554
72.727539	0.18798189	0.006455109	1532.1853
73.728516	0.18576497	0.006627609	1556.9651
74.729492	0.19073802	0.0066527817	1582.4614
75.730469	0.19399722	0.0068168892	1610.8442
76.731445	0.19620262	0.0069046305	1636.1272
77.732422	0.19738115	0.0071762064	1658.3821
78.733398	0.20354787	0.0072306707	1687.3479
79.734375	0.20614854	0.0073656878	1718.4149
80.735352	0.20771554	0.0074233185	1742.1971
81.736328	0.21272688	0.0076030591	1771.7286
82.737305	0.21534348	0.0077621597	1798.6907
83.738281	0.21900919	0.0077777067	1823.2013
84.739258	0.22020923	0.0079601062	1847.7299
85.740234	0.22402999	0.0080399113	1875.6028
86.741211	0.22717871	0.0081703672	1899.1512
87.742188	0.23089352	0.0082760369	1926.9207
88.743164	0.23204543	0.0083731124	1948.5774
89.744141	0.23650625	0.008496861	1965.9435
90.745117	0.23938493	0.0085888198	1989.6689
91.746094	0.24334562	0.0087877903	2017.9181
92.74707	0.24578916	0.008772268	2037.1022
93.748047	0.2470607	0.0089426655	2066.0374
94.749023	0.25147688	0.0090909237	2082.8894
95.75	0.25478622	0.0091487803	2096.8977
96.750977	0.25877786	0.0093346136	2130.8557
97.751953	0.25990927	0.0093833618	2138.4658
98.75293	0.26312909	0.009510044	2165.061
99.753906	0.26815522	0.0095570851	2177.8569
100.75488	0.27136865	0.009732414	2198.7859
101.75586	0.27343109	0.009727193	2214.5134
102.75684	0.27461413	0.0098102912	2226.5293
103.75781	0.27792513	0.0099964002	2241.4021
104.75879	0.2821317	0.010053282	2260.4072
105.75977	0.287274	0.010212303	2279.7568
106.76074	0.28692546	0.010316272	2296.7476
107.76172	0.29281989	0.010341792	2309.658
108.7627	0.29157707	0.010475975	2326.1396
109.76367	0.29812834	0.010567425	2339.5828
110.76465	0.2969656	0.010624178	2348.0386
111.76563	0.30260968	0.010657554	2367.0547
112.7666	0.30476779	0.010850232	2380.6699
113.76758	0.31096196	0.011008284	2397.6052
114.76855	0.31371713	0.011071525	2403.2542
115.76953	0.31510442	0.011120866	2414.1401
116.77051	0.31945232	0.011245738	2422.7566
117.77148	0.31888381	0.011421641	2440.7854
118.77246	0.3233282	0.011544453	2450.021
119.77344	0.32581249	0.011601514	2466.1909
120.77441	0.33031881	0.011858945	2479.0837
121.77539	0.33444282	0.011930832	2488.1577
122.77637	0.33560926	0.012110515	2503.9443
123.77734	0.33964965	0.012242622	2520.1492
124.77832	0.34216839	0.012384185	2525.1328
125.7793	0.3458375	0.012519459	2541.2019
126.78027	0.34973136	0.01265256	2548.0242
127.78125	0.35141453	0.012767026	2553.6199
128.78223	0.35532427	0.013061841	2567.7451
129.7832	0.35671952	0.013176706	2573.7515
130.78418	0.36283034	0.013286321	2584.4985
131.78516	0.36447251	0.013565022	2596.7661
132.78613	0.36649927	0.013709641	2605.429
133.78711	0.36862954	0.013815688	2609.147
134.78809	0.37185958	0.014080523	2613.0127
135.78906	0.37517551	0.01431728	2621.21
136.79004	0.37813756	0.014477212	2634.7637
137.79102	0.37914276	0.014753976	2638.0198
138.79199	0.38385335	0.015052719	2655.6035
139.79297	0.3863897	0.015262063	2661.5408
140.79395	0.39100516	0.015630154	2667.832
141.79492	0.39361343	0.015764162	2671.8757
142.7959	0.3971912	0.016082056	2676.0706
143.79688	0.39981583	0.016338777	2688.1919
144.79785	0.40214396	0.016702425	2698.554
145.79883	0.40599382	0.017095024	2708.1101
146.7998	0.41276643	0.017458504	2713.4043
147.80078	0.41364968	0.017914226	2725.4546
148.80176	0.41608602	0.018419031	2734.0569
149.80273	0.41775686	0.01885042	2733.5647
150.80371	0.42078331	0.019191273	2746.5774
151.80469	0.42352203	0.019682353	2739.2156
152.80566	0.42501137	0.020118006	2752.9431
153.80664	0.43081501	0.020722598	2765.738
154.80762	0.43244329	0.021400779	2774.6653
155.80859	0.43648824	0.021916525	2773.5366
156.80957	0.43931773	0.022435319	2783.9998
157.81055	0.44340894	0.023157114	2786.1038
158.81152	0.44454154	0.023614377	2791.3589
159.8125	0.4478243	0.024252091	2797.6646
160.81348	0.45228779	0.024961343	2805.6758
161.81445	0.45405164	0.025713263	2809.8247
162.81543	0.45824879	0.026387002	2807.8428
163.81641	0.46015918	0.027109902	2820.5974
164.81738	0.46241155	0.027763767	2820.6631
165.81836	0.46667898	0.028514354	2822.7253
166.81934	0.46745321	0.029251715	2823.7405
167.82031	0.47492287	0.029914303	2835.1621
168.82129	0.47480527	0.030827234	2840.5737
169.82227	0.47974902	0.031657357	2846.9761
170.82324	0.47875983	0.032643221	2846.5823
171.82422	0.48533303	0.033474401	2854.5029
172.8252	0.48858383	0.03435633	2857.7554
173.82617	0.48917699	0.035054784	2861.4451
174.82715	0.49309793	0.035980254	2861.1074
175.82813	0.4960649	0.037018828	2870.6074
176.8291	0.49968815	0.037960134	2876.0647
177.83008	0.50407028	0.038826212	2873.6262
178.83105	0.50443769	0.039541695	2877.7288
179.83203	0.50638884	0.040460177	2882.2957
180.83301	0.5123058	0.041418321	2888.6089
181.83398	0.51581478	0.042417176	2891.5828
182.83496	0.51563239	0.04336394	2895.0625
183.83594	0.52179933	0.044325527	2903.6003
184.83691	0.52165878	0.045466028	2899.9058
185.83789	0.52705449	0.04654156	2903.9053
186.83887	0.52855593	0.047573529	2909.2341
187.83984	0.53424549	0.048627641	2915.6841
188.84082	0.53208655	0.049584027	2907.8831
189.8418	0.539096	0.050723914	2916.6467
190.84277	0.54224783	0.051790819	2924.6147
191.84375	0.54437619	0.053080916	2925.7205
192.84473	0.54616266	0.054396011	2927.7869
193.8457	0.55426538	0.055519838	2935.0125
194.84668	0.55391175	0.056543812	2933.3335
195.84766	0.55651832	0.057765633	2939.1155
196.84863	0.55884075	0.058797069	2941.666
197.84961	0.56058908	0.059874259	2944.1631
198.85059	0.56489497	0.060996529	2941.3972
199.85156	0.56507403	0.062354717	2941.8574
200.85254	0.5710519	0.063324198	2948.6223
201.85352	0.57442582	0.064422011	2953.238
202.85449	0.5776819	0.065596938	2959.7183
203.85547	0.58315963	0.066823363	2958.572
204.85645	0.58373004	0.067789562	2958.7197
205.85742	0.58717316	0.068950608	2954.7598
206.8584	0.58852643	0.070248239	2966.811
207.85938	0.5955832	0.071500324	2972.6885
208.86035	0.59219414	0.072460569	2963.3401
209.86133	0.59916383	0.073603034	2962.3206
210.8623	0.60162431	0.074522987	2965.4294
211.86328	0.60448176	0.075420424	2973.5146
212.86426	0.60866082	0.076417461	2973.8049
213.86523	0.60969412	0.077537306	2974.1267
214.86621	0.61349803	0.078862846	2982.9719
215.86719	0.61491317	0.079958834	2980.2827
216.86816	0.61678672	0.081169084	2981.4192
217.86914	0.6187458	0.082308874	2988.928
218.87012	0.62743396	0.083434872	2985.197
219.87109	0.62814945	0.084403716	2988.3091
220.87207	0.63253772	0.08550474	2996
221.87305	0.63383037	0.087023579	3005.1494
222.87402	0.63678676	0.088305265	2999.8315
223.875	0.6429131	0.089515761	2995.8367
224.87598	0.64100355	0.090482593	2990.2158
225.87695	0.64436352	0.091540761	3006.4019
226.87793	0.65150738	0.092911623	3012.4629
227.87891	0.65216708	0.094359517	3011.7151
228.87988	0.65768307	0.095610142	3016.2449
229.88086	0.66054291	0.096853577	3012.7844
230.88184	0.66013253	0.098074019	3017.3528
231.88281	0.66562051	0.099348344	3021.6519
232.88379	0.66836911	0.1006721	3021.512
233.88477	0.66945863	0.10175142	3020.1077
234.88574	0.67296016	0.10293142	3026.7576
235.88672	0.67569321	0.10418793	3022.7805
236.8877	0.68199742	0.10551909	3034.7642
237.88867	0.68428624	0.10678765	3032.2688
238.88965	0.68675536	0.10802834	3028.8853
239.89063	0.69048822	0.1094437	3041.2678
240.8916	0.69403464	0.1103498	3029.8362
241.89258	0.69387853	0.11148582	3038.8596
242.89355	0.69751734	0.11252929	3035.1414
243.89453	0.69961476	0.11359324	3034.051
244.89551	0.70414329	0.11472574	3046.0725
245.89648	0.70869446	0.11610416	3046.5574
246.89746	0.70852399	0.11721288	3042.5679
247.89844	0.71373528	0.11819841	3043.2209
248.89941	0.71802813	0.11958617	3052.2336
249.90039	0.71931136	0.121096	3050.3792
250.90137	0.72182536	0.1223053	3047.9739
251.90234	0.72528529	0.12342159	3056.8718
252.90332	0.72664714	0.12453119	3054.0608
253.9043	0.72833216	0.12558876	3050.0256
254.90527	0.73121476	0.1266918	3055.8992
255.90625	0.73605627	0.12805288	3065.2358
256.90723	0.73919779	0.12930684	3070.4927
257.9082	0.74464542	0.13058998	3060.7148
258.90918	0.74668527	0.13174659	3067.8345
259.91016	0.74969405	0.1330054	3070.4951
260.91113	0.75228447	0.13422398	3068.7612
261.91211	0.753883	0.13537842	3077.125
262.91309	0.75675762	0.13652739	3070.4934
263.91406	0.75803554	0.13792311	3077.0911
264.91504	0.76339209	0.13931505	3073.7761
265.91602	0.76527542	0.14046702	3080.3247
266.91699	0.76879114	0.14160588	3075.7896
267.91797	0.77323681	0.14279121	3079.261
268.91895	0.77595139	0.14396894	3083.0608
269.91992	0.77970779	0.14499907	3085.4336
270.9209	0.78247339	0.14594838	3084.0779
271.92188	0.78121084	0.14718728	3091.2935
272.92285	0.79009235	0.1487204	3100.2844
273.92383	0.79179233	0.15023008	3092.5964
274.9248	0.79748988	0.15157875	3097.7905
275.92578	0.7953248	0.15267651	3097.0327
276.92676	0.79865265	0.15404031	3102.209
277.92773	0.80261499	0.15527149	3101.5269
278.92871	0.80502915	0.15659322	3098.0645
279.92969	0.80654389	0.15778299	3099.4453
280.93066	0.80944717	0.15891005	3096.5725
281.93164	0.81292534	0.15981568	3098.71
282.93262	0.81823504	0.16100588	3105.2778
283.93359	0.82431823	0.16211936	3108.0676
284.93457	0.8253693	0.1631704	3107.1902
285.93555	0.82493716	0.16435717	3103.9224
286.93652	0.83050418	0.16568591	3113.801
287.9375	0.83094859	0.16681217	3113.4976
288.93848	0.83637345	0.16796935	3107.3401
289.93945	0.83925664	0.16903856	3115.6362
290.94043	0.84140527	0.17025596	3111.9807
291.94141	0.84424829	0.17138873	3116.8767
292.94238	0.84647787	0.17248583	3120.2163
293.94336	0.85236418	0.17360649	3121.7329
294.94434	0.85472715	0.17498092	3125.7168
295.94531	0.85678649	0.17633657	3127.644
296.94629	0.85828871	0.17790636	3127.7686
297.94727	0.86078608	0.17897633	3124.1873
298.94824	0.86255205	0.18009371	3125.4395
299.94922	0.86932629	0.1814854	3139.1765
300.9502	0.87301737	0.18282561	3134.8691
301.95117	0.87457794	0.1840906	3134.2451
302.95215	0.87686455	0.18540983	3137.7261
303.95313	0.88004935	0.18672679	3140.2119
304.9541	0.88470376	0.18804035	3136.7087
305.95508	0.88610852	0.18908213	3134.0901
306.95605	0.89247197	0.19025294	3151.7053
307.95703	0.89101356	0.19129455	3141.7354
308.95801	0.89725298	0.1924683	3146.8567
309.95898	0.89916646	0.19367394	3136.9919
310.95996	0.90067834	0.19469599	3144.9111
311.96094	0.90391397	0.19587912	3150.4966
312.96191	0.91087729	0.19707982	3159.0513
313.96289	0.9110955	0.19837767	3155.5818
314.96387	0.91462916	0.19976448	3160.0225
315.96484	0.91445297	0.20116872	3153.8042
316.96582	0.92023867	0.20216365	3155.7776
317.9668	0.92147267	0.20345479	3159.5317
318.96777	0.92366976	0.20465554	3158.823
319.96875	0.93028969	0.20600228	3163.9097
320.96973	0.93213266	0.20697907	3160.9949
321.9707	0.93675369	0.2082182	3169.5894
322.97168	0.93253487	0.20944454	3163.2341
323.97266	0.94061685	0.21065375	3166.3701
324.97363	0.94335437	0.21183498	3165.2197
325.97461	0.94744515	0.21296772	3169.3708
326.97559	0.94812375	0.21418646	3170.3
327.97656	0.95340562	0.21547589	3171.0103
328.97754	0.95435685	0.21682709	3175.8245
329.97852	0.95350456	0.21800032	3174.9277
330.97949	0.96144831	0.2194425	3177.9084
331.98047	0.96366113	0.22053851	3175.3386
332.98145	0.96934164	0.22184896	3183.6458
333.98242	0.97050416	0.22300588	3180.5393
334.9834	0.97360456	0.22404143	3177.4839
335.98438	0.97473943	0.22552676	3190.0916
336.98535	0.97947484	0.22686936	3189.2588
337.98633	0.98563397	0.22807783	3189.9343
338.9873	0.98610318	0.22916088	3188.5679
339.98828	0.98691171	0.23036718	3187.603
340.98926	0.99334699	0.23156017	3195.2898
341.99023	0.99463737	0.23264804	3185.6038
342.99121	0.99714112	0.23369764	3191.6282
343.99219	1.0013738	0.23460709	3192.5583
344.99316	1.0014807	0.23603258	3195.3586
345.99414	1.0085245	0.23736803	3203.377
346.99512	1.0086477	0.2386099	3197.1238
347.99609	1.0149224	0.23989682	3202.0483
348.99707	1.016994	0.24133497	3206.0825
349.99805	1.0195369	0.24263844	3204.6692
350.99902	1.0219382	0.24389455	3205.6919
352	1.0269437	0.24509253	3211.0088
353.00098	1.028289	0.24614082	3201.4536
354.00195	1.0335603	0.24713857	3205.8708
355.00293	1.034042	0.24825764	3207.9058
356.00391	1.0385361	0.24940906	3216.1628
357.00488	1.0398176	0.25064883	3217.1294
358.00586	1.0422002	0.25219864	3215.1187
359.00684	1.0479213	0.25326875	3210.6694
360.00781	1.047823	0.2544187	3216.4285
361.00879	1.0524197	0.25563061	3212.5972
362.00977	1.0541859	0.25680462	3216.6531
363.01074	1.0594218	0.25809482	3233.198
364.01172	1.0607892	0.25952682	3225.7524
365.0127	1.0629032	0.26074618	3221.5117
366.01367	1.0677382	0.26180175	3222.3245
367.01465	1.0702702	0.26280198	3218.0156
368.01563	1.0756829	0.26391381	3225.5872
369.0166	1.0745859	0.26503995	3227.9585
370.01758	1.0777823	0.26622266	3222.5676
371.01855	1.0820613	0.26760471	3229.1204
372.01953	1.0876244	0.26887313	3238.2585
373.02051	1.0855463	0.27022883	3234.3159
374.02148	1.0897561	0.27165079	3237.5378
375.02246	1.095627	0.27267736	3233.2141
376.02344	1.097028	0.27388266	3236.2092
377.02441	1.0991635	0.27508363	3242.532
378.02539	1.1037924	0.27613473	3237.543
379.02637	1.1041847	0.27730587	3234.8315
380.02734	1.1083807	0.2785275	3241.9512
381.02832	1.1091036	0.27983519	3242.2334
382.0293	1.1146436	0.28114343	3239.3889
383.03027	1.1171118	0.28234172	3242.0044
384.03125	1.1217552	0.28340751	3242.9419
385.03223	1.1224802	0.28478375	3247.7927
386.0332	1.1274034	0.28595012	3247.46
387.03418	1.1308707	0.28710639	3246.5042
388.03516	1.1343114	0.28844625	3251.001
389.03613	1.1392922	0.28945205	3251.7266
390.03711	1.1397815	0.2905058	3251.0444
391.03809	1.1410052	0.2918162	3257.7109
392.03906	1.1454344	0.29289663	3255.5513
393.04004	1.146397	0.29434022	3257.5398
394.04102	1.1485887	0.29558349	3258.8452
395.04199	1.153715	0.29692689	3253.9202
396.04297	1.1549768	0.29805079	3263.6064
397.04395	1.1588179	0.29931572	3254.0767
398.04492	1.1621979	0.30046919	3262.9976
399.0459	1.1655368	0.30169138	3259.5232
400.04688	1.1692694	0.30283645	3258.0513
401.04785	1.1747433	0.30394569	3269.9961
402.04883	1.1752977	0.30486411	3265.5745
403.0498	1.1785202	0.30622575	3268.3638
404.05078	1.1812334	0.3075617	3266.2246
405.05176	1.1848251	0.30860248	3271.6064
406.05273	1.1863279	0.30975714	3274.9741
407.05371	1.189271	0.31106851	3270.228
408.05469	1.1966237	0.31265607	3284.0791
409.05566	1.196977	0.31395677	3273.2595
410.05664	1.1968606	0.31527019	3275.3877
411.05762	1.2033997	0.31645608	3274.9207
412.05859	1.2030034	0.31752449	3275.9678
413.05957	1.2075739	0.31885222	3281.4761
414.06055	1.2127397	0.32016659	3285.802
415.06152	1.2131305	0.32125911	3277.2927
416.0625	1.2173505	0.32237509	3280.6216
417.06348	1.2198132	0.32360077	3285.4836
418.06445	1.2242848	0.32493436	3282.989
419.06543	1.2258956	0.32611996	3285.8623
420.06641	1.2303945	0.32708168	3284.24
421.06738	1.2333783	0.32821286	3291.8745
422.06836	1.2328033	0.32934737	3289.9331
423.06934	1.2427536	0.33036268	3292.0278
424.07031	1.2395434	0.33149454	3287.6033
425.07129	1.2412288	0.3326337	3289.8608
426.07227	1.2477828	0.33372864	3291.3235
427.07324	1.251054	0.33492076	3293.0586
428.07422	1.251574	0.33617809	3296.7976
429.0752	1.2553619	0.33734307	3297.8335
430.07617	1.261369	0.33854857	3301.2129
431.07715	1.2625982	0.33989149	3302.8174
432.07813	1.2664255	0.34103447	3302.427
433.0791	1.2679043	0.34237421	3304.2734
434.08008	1.2731394	0.34349859	3302.3662
435.08105	1.2749846	0.34471557	3302.1836
436.08203	1.2784379	0.34574685	3301.9153
437.08301	1.2777643	0.34688517	3309.7734
438.08398	1.2840352	0.3483012	3297.782
439.08496	1.2874353	0.34949225	3309.8801
440.08594	1.2900308	0.3506439	3310.6333
441.08691	1.2895049	0.35197935	3314.9565
442.08789	1.296434	0.35314965	3306.7241
443.08887	1.3001719	0.35426372	3313.6958
444.08984	1.303448	0.35542011	3311.0864
445.09082	1.3049856	0.35684931	3314.3379
446.0918	1.3051361	0.35824779	3318.7346
447.09277	1.3093269	0.35944846	3313.5295
448.09375	1.3130171	0.36076221	3314.2478
449.09473	1.3157901	0.36195797	3317.0789
450.0957	1.3186632	0.36339855	3326.1816
451.09668	1.3217136	0.36455315	3325.2488
452.09766	1.3239967	0.36570284	3322.2161
453.09863	1.3289244	0.36690593	3325.1211
454.09961	1.3315585	0.36802295	3318.427
455.10059	1.3355801	0.3692461	3325.2053
456.10156	1.3385733	0.37037787	3324.8845
457.10254	1.3389441	0.37169254	3325.0945
458.10352	1.3435731	0.37307969	3327.7268
459.10449	1.3465586	0.37426671	3327.2739
460.10547	1.3497045	0.3755275	3331.9597
461.10645	1.3517087	0.37673092	3331.4089
462.10742	1.3551227	0.37807238	3326.5039
463.1084	1.3585004	0.37919563	3329.676
464.10938	1.3620687	0.38054943	3336.2014
465.11035	1.3675956	0.3819086	3336.8889
466.11133	1.3671811	0.38305056	3331.7458
467.1123	1.3682803	0.38421807	3328.7227
468.11328	1.3745772	0.38561845	3344.8943
469.11426	1.3766987	0.38664401	3335.9458
470.11523	1.3780617	0.38805479	3341.5718
471.11621	1.3803599	0.38915849	3334.1165
472.11719	1.3844535	0.39046016	3338.9766
473.11816	1.3858832	0.39159799	3340.3872
474.11914	1.3914905	0.39278036	3344.1519
475.12012	1.3938196	0.39393669	3335.2148
476.12109	1.3966465	0.39509124	3347.9001
477.12207	1.4007145	0.39614421	3341.9451
478.12305	1.4035769	0.39748332	3352.156
479.12402	1.4061259	0.39894977	3347.2202
480.125	1.4085382	0.40022272	3348.2351
481.12598	1.4114856	0.40132907	3346.6763
482.12695	1.4154959	0.4024843	3349.249
483.12793	1.4171143	0.40380538	3351.1052
484.12891	1.4208508	0.40521872	3353.3235
485.12988	1.4264082	0.40670541	3354.7937
486.13086	1.428455	0.40810946	3359.7656
487.13184	1.4305769	0.40937901	3361.6367
488.13281	1.4351342	0.4107911	3357.4451
489.13379	1.43557	0.41197732	3356.5969
490.13477	1.4376516	0.41316706	3357.3931
491.13574	1.4439633	0.414368	3359.9912
492.13672	1.4454858	0.41562909	3360.4924
493.1377	1.4501188	0.41660962	3355.1587
494.13867	1.4488623	0.41774279	3362.2014
495.13965	1.4513382	0.4190436	3363.0779
496.14063	1.4562755	0.42023942	3364.553
497.1416	1.4637666	0.42139444	3361.0833
498.14258	1.4634068	0.42243153	3360.137
499.14355	1.4666831	0.42364004	3366.979
500.14453	1.4683325	0.42507395	3376.3655
501.14551	1.4722161	0.42618525	3366.7456
502.14648	1.4751625	0.42764178	3365.5391
503.14746	1.4789773	0.42893198	3375.4951
504.14844	1.4810395	0.4302884	3379.2881
505.14941	1.4858074	0.43170106	3377.8547
506.15039	1.4875841	0.43302584	3368.3889
507.15137	1.4908574	0.43421724	3372.1062
508.15234	1.4945759	0.43528563	3362.3167
509.15332	1.4968846	0.43629584	3377.074
510.1543	1.4988445	0.43739155	3372.7368
511.15527	1.5033851	0.43877664	3380.1377
512.15625	1.5053552	0.43992281	3381.011
513.15723	1.5104499	0.44124687	3382.3206
514.1582	1.5104724	0.44261497	3379.9854
515.15918	1.5129538	0.44406423	3383.8398
516.16016	1.5142684	0.44547769	3381.2832
517.16113	1.522737	0.44678229	3383.6091
518.16211	1.5202265	0.4480828	3382.2061
519.16309	1.5288119	0.4494344	3388.9895
520.16406	1.5286192	0.4507319	3386.6404
521.16504	1.5332152	0.45179665	3383.8142
522.16602	1.5364609	0.45328802	3387.9844
523.16699	1.5361587	0.45445046	3387.9563
524.16797	1.5432662	0.45557627	3383.9355
525.16895	1.5435443	0.45675728	3391.1416
526.16992	1.5490559	0.45790246	3393.458
527.1709	1.5516133	0.45924827	3388.2263
528.17188	1.5535617	0.46057853	3393.563
529.17285	1.5561287	0.46192807	3389.4375
530.17383	1.5592911	0.46306092	3392.7678
531.1748	1.5655509	0.46438035	3395.2781
532.17578	1.5671402	0.46574458	3394.8367
533.17676	1.5677645	0.46683571	3389.6064
534.17773	1.5716897	0.46787593	3394.1997
535.17871	1.5734805	0.46916428	3397.0061
536.17969	1.5760769	0.47050402	3398.9185
537.18066	1.5801376	0.47181025	3400.6069
538.18164	1.5826267	0.47296232	3396.1453
539.18262	1.5911069	0.47420749	3399.7275
540.18359	1.591431	0.47569594	3404.2878
541.18457	1.5934871	0.47693992	3397.2639
542.18555	1.5942487	0.47834212	3405.2046
543.18652	1.5984403	0.47961167	3405.3025
544.1875	1.6023449	0.48092625	3406.8572
545.18848	1.6042019	0.48210135	3403.1245
546.18945	1.6054225	0.48321769	3406.1838
547.19043	1.6129636	0.4843843	3413.1973
548.19141	1.6141046	0.48575094	3413.4236
549.19238	1.6189768	0.48738295	3417.7571
550.19336	1.6222218	0.4886772	3414.5879
551.19434	1.6240094	0.49002033	3410.5549
552.19531	1.6223782	0.49130988	3411.8611
553.19629	1.6307325	0.49256667	3409.7375
554.19727	1.6320791	0.49374866	3414.0022
555.19824	1.6343163	0.49500066	3415.6208
556.19922	1.6388166	0.49636668	3419.5132
557.2002	1.6426417	0.49785832	3416.907
558.20117	1.6434908	0.49901432	3416.0608
559.20215	1.6482079	0.50034821	3416.8999
560.20313	1.6456511	0.50165588	3420.5759
561.2041	1.6540858	0.5030517	3422.134
562.20508	1.6565986	0.50455934	3421.8577
563.20605	1.6586311	0.50571269	3425.2065
564.20703	1.6637955	0.50711197	3423.1555
565.20801	1.663692	0.50822222	3423.2637
566.20898	1.6680256	0.50946444	3417.2231
567.20996	1.6707079	0.51082224	3425.1941
568.21094	1.6730498	0.51183569	3418.2856
569.21191	1.676837	0.51294261	3424.6809
570.21289	1.6818268	0.51424098	3430.5427
571.21387	1.6828545	0.51551127	3424.4932
572.21484	1.6846025	0.51695478	3432.7512
573.21582	1.6874933	0.51827174	3425.7153
574.2168	1.6907501	0.51946396	3426.3064
575.21777	1.6928638	0.52055407	3432.9094
576.21875	1.6975125	0.5217725	3433.2126
577.21973	1.6989454	0.52311283	3426.6096
578.2207	1.7033342	0.52446783	3432.7356
579.22168	1.705178	0.52589172	3435.3198
580.22266	1.7126235	0.52715302	3433.2717
581.22363	1.7133325	0.52857178	3436.3513
582.22461	1.7137231	0.52983624	3430.5779
583.22559	1.7188228	0.53139591	3434.9146
584.22656	1.7217922	0.53249335	3438.606
585.22754	1.7243712	0.53392714	3443.2009
586.22852	1.7270316	0.53540748	3441.4949
587.22949	1.7301941	0.53681743	3436.4531
588.23047	1.7351167	0.53826678	3436.3108
589.23145	1.7359915	0.53970069	3438.4546
590.23242	1.7407653	0.54088575	3436.2058
591.2334	1.7431394	0.54222041	3442.4712
592.23438	1.7484885	0.54367834	3451.0313
593.23535	1.7467626	0.54518229	3439.2668
594.23633	1.7525104	0.54662901	3445.5056
595.2373	1.7561232	0.54803455	3443.8435
596.23828	1.759105	0.54927683	3443.3254
597.23926	1.7610983	0.55048418	3449.7603
598.24023	1.7645781	0.55181205	3447.2144
599.24121	1.7673556	0.5529682	3447.2437
600.24219	1.7700663	0.55438882	3446.3533
601.24316	1.7724723	0.55583239	3450.3953
602.24414	1.7755907	0.55729008	3446.9312
603.24512	1.7810602	0.55847782	3453.636
604.24609	1.7804211	0.55967855	3445.7493
605.24707	1.7863241	0.56101501	3452.696
606.24805	1.7869402	0.56229508	3449.9058
607.24902	1.790863	0.56348985	3445.8271
608.25	1.7931205	0.56471896	3451.5327
609.25098	1.7983572	0.56609148	3459.637
610.25195	1.8003391	0.56742591	3457.7847
611.25293	1.8016748	0.56890041	3459.7671
612.25391	1.8033017	0.57041621	3456.1699
613.25488	1.8076169	0.57198894	3460.1567
614.25586	1.8173908	0.57332891	3452.5742
615.25684	1.816426	0.57460517	3460.0254
616.25781	1.8205825	0.57593364	3458.4731
617.25879	1.81785	0.57732153	3464.7983
618.25977	1.8245307	0.57883406	3460.2178
619.26074	1.826847	0.5802061	3459.3909
620.26172	1.8308908	0.58156002	3462.4939
621.2627	1.8348105	0.58313733	3468.5486
622.26367	1.8354836	0.58463144	3459.1887
623.26465	1.838002	0.58625007	3468.4507
624.26563	1.840021	0.58743113	3455.6218
625.2666	1.8454437	0.5888555	3463.3894
626.26758	1.8481915	0.59007138	3464.4871
627.26855	1.8530197	0.59148937	3466.104
628.26953	1.8537587	0.59279513	3463.7341
629.27051	1.8551855	0.59396511	3463.6262
630.27148	1.8593078	0.59526932	3465.9397
631.27246	1.8634727	0.59677607	3464.9326
632.27344	1.8663852	0.59804893	3465.593
633.27441	1.8694552	0.59943742	3465.2778
634.27539	1.8742017	0.60071015	3469.6001
635.27637	1.8736111	0.60196751	3469.0879
636.27734	1.8781766	0.60355604	3477.7502
637.27832	1.8790649	0.604922	3469.4231
638.2793	1.8836374	0.60620248	3473.7996
639.28027	1.886591	0.60766548	3471.0405
640.28125	1.8878102	0.6091063	3471.6973
641.28223	1.8935877	0.61058152	3471.3071
642.2832	1.8948616	0.61204088	3469.9043
643.28418	1.8973508	0.61331153	3474.0789
644.28516	1.9027691	0.61464137	3476.145
645.28613	1.9044065	0.61612231	3475.2031
646.28711	1.910566	0.61740565	3473.9868
647.28809	1.9115199	0.61876512	3476.8828
648.28906	1.9129277	0.62005907	3471.9792
649.29004	1.9165119	0.62155366	3480.2126
650.29102	1.9167786	0.62291187	3479.8752
651.29199	1.922913	0.62464529	3484.1902
652.29297	1.9255339	0.626122	3483.7773
653.29395	1.9288749	0.62760997	3479.8896
654.29492	1.9315138	0.62885082	3474.6909
655.2959	1.9354517	0.62999725	3475.0859
656.29688	1.939546	0.63125533	3484.4329
657.29785	1.9414732	0.63265204	3482.9565
658.29883	1.9401195	0.63406497	3484.3455
659.2998	1.9448662	0.63568735	3484.8354
660.30078	1.9522692	0.63725007	3486.0991
661.30176	1.9545817	0.63861132	3481.9912
662.30273	1.9553559	0.64008182	3484.6484
663.30371	1.9594883	0.64189595	3494.3318
664.30469	1.9622622	0.64340949	3486.2717
665.30566	1.9657182	0.64514416	3496.8948
666.30664	1.9668477	0.64660299	3481.5662
667.30762	1.9708987	0.64785999	3479.7434
668.30859	1.9739081	0.64899331	3490.0747
669.30957	1.9768603	0.65026516	3485.0481
670.31055	1.981335	0.65148628	3489.9036
671.31152	1.9811772	0.65296578	3489.3945
672.3125	1.9889854	0.65447444	3492.2874
673.31348	1.9876515	0.65576339	3484.7693
674.31445	1.9922791	0.65717322	3489.7891
675.31543	1.9954605	0.65835232	3494.6233
676.31641	1.9967453	0.65972227	3490.5403
677.31738	1.9997331	0.66115606	3493.7434
678.31836	2.0042427	0.66241658	3487.6375
679.31934	2.0048215	0.66380268	3493.5195
680.32031	2.011987	0.66528326	3502.7373
681.32129	2.016753	0.66696233	3496.3862
682.32227	2.0150301	0.66829157	3493.6489
683.32324	2.0204372	0.66982466	3500.8545
684.32422	2.0232835	0.67153871	3498.8557
685.3252	2.0264068	0.67325062	3502.2012
686.32617	2.0282025	0.67468834	3501.8706
687.32715	2.0325904	0.67606562	3499.8408
688.32813	2.03302	0.67748761	3493.0898
689.3291	2.0375676	0.67892325	3496.9055
690.33008	2.0413213	0.68020582	3498.0808
691.33105	2.042716	0.68177128	3502.1279
692.33203	2.0454025	0.68309951	3498.0313
693.33301	2.0505579	0.6844058	3496.9412
694.33398	2.0539637	0.68587238	3506.1326
695.33496	2.0518119	0.68740183	3509.2449
696.33594	2.0568893	0.68925637	3509.8286
697.33691	2.0614126	0.691028	3502.6204
698.33789	2.0636485	0.69264609	3505.29
699.33887	2.0648456	0.69402605	3503.0996
700.33984	2.068573	0.69558179	3500.085
701.34082	2.0741591	0.69703698	3503.1257
702.3418	2.0753481	0.69835472	3501.1443
703.34277	2.076216	0.6998319	3506.2498
704.34375	2.0845101	0.70133895	3507.1362
705.34473	2.0832722	0.70290816	3506.7771
706.3457	2.0851352	0.70441312	3511.7759
707.34668	2.0905674	0.70579278	3507.5005
708.34766	2.0928411	0.70753294	3514.3137
709.34863	2.0987866	0.70913643	3508.324
710.34961	2.1013217	0.71065325	3508.4402
711.35059	2.1028619	0.71194893	3503.4309
712.35156	2.1051931	0.71319103	3503.2632
713.35254	2.1119747	0.71453452	3509.1716
714.35352	2.1114922	0.71615219	3513.6382
715.35449	2.1128306	0.7179538	3512.2219
716.35547	2.1194015	0.71945077	3509.5703
717.35645	2.1198912	0.72106647	3512.6216
718.35742	2.1250541	0.72243643	3510.0557
719.3584	2.1281707	0.72402096	3513.5039
720.35938	2.1305671	0.72536498	3513.0906
721.36035	2.1317031	0.72724348	3515.6604
722.36133	2.1374555	0.7287432	3513.4727
723.3623	2.1391227	0.73016727	3513.5859
724.36328	2.1423392	0.73151535	3507.3591
725.36426	2.1437471	0.73284632	3513.9619
726.36523	2.1481283	0.73447376	3518.6531
727.36621	2.1529062	0.73592055	3513.3113
728.36719	2.1553531	0.73745668	3518.5901
729.36816	2.1582999	0.73915797	3521.313
730.36914	2.1631792	0.74084032	3520.0083
731.37012	2.1627629	0.74246198	3513.6394
732.37109	2.166126	0.7442944	3519.3755
733.37207	2.169101	0.74592263	3512.2109
734.37305	2.1717553	0.74748009	3515.1514
735.37402	2.1761599	0.7489208	3518.7432
736.375	2.1792095	0.75064468	3520.0754
737.37598	2.1800113	0.75229234	3516.6228
738.37695	2.1834359	0.75352025	3514.1135
739.37793	2.1885586	0.75493157	3521.771
740.37891	2.1921275	0.75620359	3517.2939
741.37988	2.1941893	0.75779539	3516.4465
742.38086	2.1960015	0.75943607	3521.7158
743.38184	2.198734	0.76115501	3524.3506
744.38281	2.2023497	0.7629227	3527.6936
745.38379	2.2056572	0.76448667	3518.1677
746.38477	2.2084916	0.76617235	3519.7681
747.38574	2.2088487	0.76768285	3523.0339
748.38672	2.2130966	0.76914155	3516.6313
749.3877	2.2197094	0.77069461	3523.9819
750.38867	2.2199745	0.77225769	3523.0923
751.38965	2.2216136	0.77419573	3529.9246
752.39063	2.2257586	0.77610058	3520.3088
753.3916	2.227983	0.77744263	3518.8804
754.39258	2.2338417	0.77907169	3523.8394
755.39355	2.2361639	0.7804811	3522.9407
756.39453	2.2369652	0.78190184	3519.0945
757.39551	2.2411685	0.78357971	3523.4509
758.39648	2.2437959	0.78498989	3522.824
759.39746	2.2469938	0.78655362	3524.3425
760.39844	2.250922	0.78835052	3521.8193
761.39941	2.2511399	0.78998834	3524.2224
762.40039	2.2570672	0.79157984	3528.9487
763.40137	2.2585778	0.79328424	3521.6987
764.40234	2.2616167	0.79493666	3526.729
765.40332	2.2648699	0.79658663	3527.5801
766.4043	2.2660065	0.79840231	3524.2935
767.40527	2.2708399	0.8000592	3528.2456
768.40625	2.2727804	0.80154473	3526.5315
769.40723	2.2756853	0.80337554	3527.2312
770.4082	2.2807815	0.80510974	3533.1711
771.40918	2.2852798	0.80667537	3530.1895
772.41016	2.2861819	0.80848873	3528.2981
773.41113	2.2915411	0.8102147	3528.0613
774.41211	2.2926779	0.8116349	3527.1475
775.41309	2.294095	0.81335282	3527.8809
776.41406	2.3011255	0.81486279	3531.7192
777.41504	2.2994738	0.81659949	3537.1084
778.41602	2.3064098	0.81855732	3532.8816
779.41699	2.3075798	0.81996638	3527.0962
780.41797	2.3121688	0.82148302	3529.4736
781.41895	2.3130655	0.82308036	3529.1628
782.41992	2.3131175	0.82435381	3530.6245
783.4209	2.3203986	0.82600462	3531.6399
784.42188	2.3225069	0.82755774	3532.9983
785.42285	2.325388	0.82931405	3535.8755
786.42383	2.3266771	0.83119702	3533.385
787.4248	2.3297617	0.8330273	3534.231
788.42578	2.3349209	0.83482558	3529.5266
789.42676	2.3369651	0.83642799	3528.4434
790.42773	2.3433104	0.83803284	3532.9175
791.42871	2.3443534	0.83981842	3539.9155
792.42969	2.3472912	0.84158564	3542.3528
793.43066	2.3511765	0.84337974	3531.7551
794.43164	2.3520758	0.84516698	3529.176
795.43262	2.3546212	0.8466844	3535.6729
796.43359	2.3608248	0.84850949	3535.1421
797.43457	2.3608794	0.8500995	3528.928
798.43555	2.3647594	0.85151982	3535.4824
799.43652	2.3677571	0.85302752	3538.4248
800.4375	2.3688989	0.85479635	3532.7573
801.43848	2.3753841	0.85667264	3536.3782
802.43945	2.3758597	0.85860008	3536.8699
803.44043	2.38079	0.86069655	3539.6851
804.44141	2.3824451	0.8624962	3534.4998
805.44238	2.3861313	0.86413145	3536.1848
806.44336	2.3886464	0.86597759	3538.2017
807.44434	2.3898587	0.86774099	3536.5242
808.44531	2.3944013	0.86956203	3539.3176
809.44629	2.3954856	0.87128884	3531.9478
810.44727	2.4002328	0.87296981	3534.6238
811.44824	2.4045057	0.87493378	3537.5688
812.44922	2.4080167	0.87636137	3538.2874
813.4502	2.410639	0.878142	3537.3105
814.45117	2.4133322	0.87975395	3535.332
815.45215	2.4172947	0.88145304	3543.0349
816.45313	2.4161012	0.88331133	3537.4453
817.4541	2.4231904	0.8850686	3534.79
818.45508	2.4233794	0.886783	3534.0776
819.45605	2.4263606	0.88852924	3541.7705
820.45703	2.4297602	0.89038146	3542.5142
821.45801	2.4324288	0.89182413	3534.6179
822.45898	2.4362278	0.89368397	3538.3184
823.45996	2.440007	0.89544898	3536.0569
824.46094	2.4411469	0.89732498	3535.2551
825.46191	2.4452901	0.89909518	3539.0542
826.46289	2.4477539	0.90106153	3538.574
827.46387	2.4545619	0.90302444	3541.7146
828.46484	2.4548538	0.90465122	3536.4944
829.46582	2.4548657	0.90610039	3534.8103
830.4668	2.4601007	0.90786946	3534.7732
831.46777	2.464278	0.90974522	3541.6755
832.46875	2.4694822	0.91158074	3546.7939
833.46973	2.4712343	0.91346395	3540.738
834.4707	2.472142	0.91514176	3536.1047
835.47168	2.4753201	0.91678101	3543.814
836.47266	2.4796498	0.91883832	3540.9919
837.47363	2.4823971	0.92074716	3540.9478
838.47461	2.485723	0.92285633	3542.3599
839.47559	2.4871967	0.92476714	3542.8101
840.47656	2.4902842	0.9271127	3540.6545
841.47754	2.4935551	0.92909616	3532.9463
842.47852	2.4957125	0.93065512	3533.752
843.47949	2.4985955	0.93267387	3540.262
844.48047	2.5042303	0.9342773	3540.4604
845.48145	2.5039785	0.93616962	3541.5352
846.48242	2.5085213	0.93821824	3536.2239
847.4834	2.5089881	0.94003797	3540.2561
848.48438	2.5166574	0.94217592	3541.593
849.48535	2.5178924	0.94417131	3543.9714
850.48633	2.5208776	0.9461205	3540.7493
851.4873	2.5233397	0.94809598	3533.8403
852.48828	2.5262671	0.94988561	3539.585
853.48926	2.5296934	0.95158702	3540.0359
854.49023	2.5347149	0.95344347	3538.7625
855.49121	2.5365002	0.95514399	3537.2419
856.49219	2.5382659	0.95678902	3540.5513
857.49316	2.5418468	0.95839036	3537.5251
858.49414	2.5456519	0.96024621	3540.9048
859.49512	2.5484941	0.96216416	3542.5608
860.49609	2.5486093	0.96385807	3535.3394
861.49707	2.5554206	0.96588618	3549.7825
862.49805	2.5566797	0.96813083	3546.106
863.49902	2.5611558	0.97040749	3545.5051
864.5	2.5609744	0.9725492	3537.3154
865.50098	2.5667424	0.9744339	3534.5549
866.50195	2.5696111	0.97649133	3542.5715
867.50293	2.5680697	0.97855735	3543.3442
868.50391	2.5739226	0.98056775	3539.5703
869.50488	2.5769975	0.9827683	3542.0042
870.50586	2.5794542	0.98464197	3532.9355
871.50684	2.5838561	0.98645324	3538.2041
872.50781	2.5840335	0.98852098	3541.116
873.50879	2.5902755	0.99099654	3546.2012
874.50977	2.5919106	0.99332869	3542.5813
875.51074	2.5945225	0.99542832	3532.2898
876.51172	2.6005096	0.99733299	3539.5251
877.5127	2.6018724	0.99912006	3540.0266
878.51367	2.6056752	1.0009223	3536.3088
879.51465	2.6076021	1.0027263	3539.9768
880.51563	2.6094043	1.004532	3538.9883
881.5166	2.6148455	1.0066167	3541.9807
882.51758	2.6163723	1.0089505	3541.5833
883.51855	2.6179976	1.0113254	3540.0188
884.51953	2.6237321	1.0134759	3539.3193
885.52051	2.6241305	1.0151997	3530.6245
886.52148	2.6276305	1.0167854	3536.7966
887.52246	2.6302624	1.0188006	3538.3477
888.52344	2.635684	1.0209785	3540.3252
889.52441	2.6393359	1.0231904	3538.7319
890.52539	2.6381476	1.0249604	3537.3904
891.52637	2.6449118	1.0270039	3539.9468
892.52734	2.6462801	1.0291189	3537.292
893.52832	2.6514716	1.0311203	3544.2471
894.5293	2.6533124	1.0332838	3538.1162
895.53027	2.6566632	1.0356882	3539.5054
896.53125	2.6589019	1.0380387	3537.894
897.53223	2.661212	1.0400414	3535.1223
898.5332	2.6640034	1.0419154	3534.1953
899.53418	2.6668377	1.0439647	3532.2649
900.53516	2.6702092	1.0459253	3535.0193
901.53613	2.6723416	1.0477413	3533.2759
902.53711	2.6746657	1.0500523	3537.988
903.53809	2.67957	1.0521483	3531.4163
904.53906	2.681514	1.0539001	3530.3955
905.54004	2.6837602	1.0558265	3537.8635
906.54102	2.6883826	1.0582983	3544.8542
907.54199	2.691433	1.0606458	3535.5244
908.54297	2.6932924	1.0630467	3538.9907
909.54395	2.6977696	1.0654721	3533.3733
910.54492	2.700217	1.0674919	3528.7227
911.5459	2.7032113	1.0697722	3530.5122
912.54688	2.7080863	1.0719283	3529.9902
913.54785	2.7092235	1.0742576	3538.6836
914.54883	2.7110102	1.0766218	3531.6433
915.5498	2.7149463	1.0786871	3532.5017
916.55078	2.7185938	1.0810403	3534.4971
917.55176	2.7239513	1.0833148	3536.5559
918.55273	2.72352	1.0852176	3527.7727
919.55371	2.7271173	1.0873426	3540.3167
920.55469	2.7318451	1.0895343	3532.5828
921.55566	2.7330513	1.0918679	3530.8545
922.55664	2.7383018	1.0942012	3534.2974
923.55762	2.7388299	1.0965465	3528.7024
924.55859	2.7428865	1.0989653	3533.7883
925.55957	2.7460179	1.1014385	3537.0149
926.56055	2.7451735	1.1038114	3528.3335
927.56152	2.7543118	1.1058084	3529.8274
928.5625	2.7527504	1.1080104	3528.7688
929.56348	2.7594502	1.1103179	3530.3755
930.56445	2.7608643	1.112728	3532.4006
931.56543	2.765306	1.1150818	3528.7229
932.56641	2.7636762	1.1169717	3520.699
933.56738	2.769022	1.1191834	3534.4275
934.56836	2.7729759	1.1216339	3530.2534
935.56934	2.7746491	1.1237657	3529.1682
936.57031	2.7794311	1.1261464	3531.3206
937.57129	2.7799883	1.1287038	3527.3208
938.57227	2.7867429	1.1310827	3527.7371
939.57324	2.7845638	1.1333946	3531.2969
940.57422	2.7931759	1.1358569	3526.323
941.5752	2.7938285	1.1379377	3523.9973
942.57617	2.799283	1.1403823	3534.0461
943.57715	2.7996626	1.1432855	3522.7371
944.57813	2.801826	1.145833	3528.1714
945.5791	2.8063259	1.1482292	3525.355
946.58008	2.8080819	1.1505857	3521.9116
947.58105	2.8116777	1.1529373	3526.7932
948.58203	2.816788	1.1555167	3526.2312
949.58301	2.8209078	1.1580042	3518.4329
950.58398	2.8208311	1.1605327	3522.7349
951.58496	2.8258359	1.162968	3523.053
952.58594	2.8268211	1.165411	3519.7329
953.58691	2.8317189	1.1678997	3519.6746
954.58789	2.83465	1.1708304	3520.0393
955.58887	2.8350916	1.1729158	3515.1221
956.58984	2.8413408	1.1751139	3525.2095
957.59082	2.841414	1.1775614	3518.7756
958.5918	2.8473585	1.1799132	3516.8052
959.59277	2.8464835	1.1821131	3513.4592
960.59375	2.8515024	1.1843013	3516.9248
961.59473	2.8551848	1.1868219	3518.9678
962.5957	2.8584144	1.1890411	3511.793
963.59668	2.8584042	1.1915841	3511.627
964.59766	2.8605614	1.1944115	3515.7698
965.59863	2.8682799	1.1974373	3517.0042
966.59961	2.8700373	1.200037	3510.6287
967.60059	2.8714244	1.2024225	3503.4531
968.60156	2.875134	1.2045988	3506.6909
969.60254	2.8772113	1.2066326	3504.6782
970.60352	2.880774	1.2089268	3511.0771
971.60449	2.8840563	1.2113951	3503.5745
972.60547	2.8882473	1.2135482	3506.7344
973.60645	2.8911514	1.2161065	3506.9707
974.60742	2.8895407	1.2189293	3509.1284
975.6084	2.8965528	1.2219796	3514.3855
976.60938	2.8990543	1.2250621	3508.2244
977.61035	2.9013424	1.2279264	3501.6677
978.61133	2.904043	1.230731	3503.7292
979.6123	2.9085531	1.2335408	3502.7458
980.61328	2.913265	1.2360021	3497.4912
981.61426	2.9130301	1.2384877	3497.3301
982.61523	2.9176598	1.2413465	3505.3591
983.61621	2.9183795	1.2436804	3493.3899
984.61719	2.9234266	1.2462807	3497.6365
985.61816	2.9246447	1.248928	3495.0884
986.61914	2.9289098	1.2514975	3498.5349
987.62012	2.9326665	1.2541057	3490.647
988.62109	2.936156	1.2564294	3496.4929
989.62207	2.9375019	1.2590103	3491.8474
990.62305	2.9414003	1.2615356	3498.2559
991.62402	2.9437342	1.2645999	3494.7241
992.625	2.9455111	1.2673844	3488.1807
993.62598	2.9516761	1.2702075	3490.8184
994.62695	2.9537387	1.2728633	3489.0112
995.62793	2.9579079	1.2759571	3494.6323
996.62891	2.9622829	1.2789932	3487.9756
997.62988	2.9607477	1.2813008	3475.5425
998.63086	2.9661748	1.2834302	3478.9927
999.63184	2.9684834	1.2856905	3482.4502
1000.6328	2.9734981	1.2885809	3483.4448
1001.6338	2.9717565	1.2913055	3478.989
1002.6348	2.9783151	1.2940812	3475.0149
1003.6357	2.9774218	1.2965549	3473.4629
1004.6367	2.9828248	1.2992301	3477.9709
1005.6377	2.9864607	1.3020978	3470.9309
1006.6387	2.989193	1.3049675	3473.2485
1007.6396	2.9943864	1.3075809	3470.3047
1008.6406	2.9981065	1.3098609	3464.668
1009.6416	3.0035362	1.3119099	3470.4919
1010.6426	2.9967542	1.3139186	3463.4656
1011.6436	3.0019057	1.315799	3461.9883
1012.6445	3.0070009	1.3182672	3471.9639
1013.6455	3.0095482	1.321093	3468.8674
1014.6465	3.0130274	1.324039	3465.8701
1015.6475	3.0169842	1.3270084	3467.1038
1016.6484	3.0209358	1.3300507	3468.4756
1017.6494	3.022887	1.3329729	3455.7144
1018.6504	3.0270629	1.3361491	3456.8291
1019.6514	3.026772	1.338851	3451.4761
1020.6523	3.0314233	1.3415041	3452.0488
1021.6533	3.0374029	1.3441796	3453.74
1022.6543	3.0372217	1.3469446	3453.4133
1023.6553	3.0387635	1.349589	3450.2095
1024.6563	3.0454741	1.3524266	3450.8936
1025.6572	3.0468416	1.3557286	3444.916
1026.6582	3.0500264	1.358726	3445.3486
1027.6592	3.0516872	1.3619748	3445.0303
1028.6602	3.0559416	1.3648889	3437.2725
1029.6611	3.0588601	1.3672583	3434.1594
1030.6621	3.0591736	1.3698839	3437.0405
1031.6631	3.0625095	1.3725626	3437.8872
1032.6641	3.0642593	1.3755296	3436.5288
1033.665	3.0675762	1.3787253	3429.1506
1034.666	3.073822	1.3818032	3435.1321
1035.667	3.0782609	1.3846273	3430.6545
1036.668	3.0813043	1.387284	3438.3813
1037.6689	3.0803394	1.3905537	3425.7549
1038.6699	3.0839705	1.393207	3416.6055
1039.6709	3.0883353	1.3961927	3424.3047
1040.6719	3.0921538	1.3992091	3421.6479
1041.6729	3.0961416	1.4022386	3419.3657
1042.6738	3.0988252	1.4052601	3415.1396
1043.6748	3.1026015	1.4077753	3409.4253
1044.6758	3.1014831	1.410524	3412.2273
1045.6768	3.1083515	1.4132907	3417.4802
1046.6777	3.1077194	1.4161553	3407.689
1047.6787	3.1125851	1.4192232	3405.9153
1048.6797	3.1129549	1.4224783	3406.3281
1049.6807	3.1199689	1.4256052	3401.9839
1050.6816	3.1206484	1.4288703	3403.1501
1051.6826	3.1230886	1.431928	3395.6069
1052.6836	3.1282392	1.4345753	3397.9512
1053.6846	3.1307993	1.4380245	3397.5823
1054.6855	3.1348941	1.4412148	3388.0657
1055.6865	3.1347446	1.4440467	3382.137
1056.6875	3.1417022	1.446787	3382.6555
1057.6885	3.1414244	1.4493196	3384.363
1058.6895	3.1467981	1.4523895	3386.3005
1059.6904	3.1496179	1.45597	3383.5547
1060.6914	3.1527271	1.4591331	3372.1606
1061.6924	3.1577721	1.461886	3373.8792
1062.6934	3.1581948	1.464609	3370.1223
1063.6943	3.1611099	1.4676018	3369.1689
1064.6953	3.1632459	1.4706719	3369.3657
1065.6963	3.1671278	1.4739431	3364.7351
1066.6973	3.1703448	1.4774084	3359.3191
1067.6982	3.1724298	1.4801955	3352.7656
1068.6992	3.1775696	1.4830304	3350.7817
1069.7002	3.1755345	1.4857663	3350.936
1070.7012	3.1832857	1.4889582	3352.3809
1071.7021	3.1814828	1.4919336	3342.0183
1072.7031	3.1854792	1.4951211	3343.949
1073.7041	3.1916203	1.498157	3337.0488
1074.7051	3.1942358	1.5015694	3346.3508
1075.7061	3.1974533	1.5055804	3332.7244
1076.707	3.2005777	1.508701	3332.1521
1077.708	3.2029486	1.5115865	3323.5713
1078.709	3.2049658	1.5149699	3327.8142
1079.71	3.209466	1.5181962	3325.3374
1080.7109	3.2110178	1.5217403	3312.7092
1081.7119	3.2161803	1.5248426	3310.0056
1082.7129	3.2174711	1.527858	3315.1724
1083.7139	3.2217565	1.5305942	3302.241
1084.7148	3.2232053	1.5336663	3303.3042
1085.7158	3.2290287	1.5364367	3305.7002
1086.7168	3.2313495	1.5395931	3303.5781
1087.7178	3.2335443	1.5432426	3297.4446
1088.7188	3.2360117	1.546952	3290.5491
1089.7197	3.237576	1.5508684	3284.8391
1090.7207	3.2415795	1.5549008	3283.1392
1091.7217	3.2453265	1.5581112	3269.5649
1092.7227	3.2480624	1.5611469	3273.9766
1093.7236	3.2519238	1.5639824	3270.2988
1094.7246	3.2556365	1.5668608	3266.5872
1095.7256	3.253732	1.5696839	3263.3184
1096.7266	3.2597663	1.5729616	3266.9966
1097.7275	3.2621791	1.5765576	3253.9851
1098.7285	3.2647486	1.5803214	3247.1997
1099.7295	3.2699714	1.5840367	3245.5693
1100.7305	3.2729728	1.5870908	3241.6069
1101.7314	3.2778111	1.5903596	3239.9338
1102.7324	3.2792966	1.5941024	3239.3928
1103.7334	3.2803936	1.5979526	3227.3928
1104.7344	3.284595	1.6021839	3217.6545
1105.7354	3.2869589	1.6059752	3206.4492
1106.7363	3.2922077	1.6096081	3203.7798
1107.7373	3.2923965	1.6130632	3200.4521
1108.7383	3.2942874	1.6159869	3183.679
1109.7393	3.3005848	1.6189866	3186.0256
1110.7402	3.2991419	1.6237715	3164.8123
1111.7412	3.3072352	1.631019	3127.252
1112.7422	3.3096216	1.6372865	3095.8335
1113.7432	3.3134556	1.6421638	3088.5786
1114.7441	3.3185148	1.6463686	3070.7505
1115.7451	3.3196282	1.6500516	3062.5676
1116.7461	3.3228869	1.6547602	3046.5378
1117.7471	3.325568	1.6592035	3029.1182
1118.748	3.3278015	1.6631399	3014.5818
1119.749	3.329406	1.6670753	3006.3286
1120.75	3.3341534	1.6711046	3001.2588
1121.751	3.3356147	1.6761719	2981.4814
1122.752	3.3395407	1.6802348	2961.0784
1123.7529	3.3430028	1.6881627	2914.6863
1124.3535	3.3474672	1.703272	2801.3086