File: datasets/am_bench_2022/raw_data/45-XY.13-4/specimen.dat
MTS793|MPT|ENU|1|2|.|/|:|1|0|0|A

Operator Information						Time:	31.791748	Sec	10/20/2021 10:41:13 AM
Operator	Newell Moser
Project	AM Bench 2022 mini-tensile challenge
Specimen ID	45-XY.13-4
Material	PBF-L Inconel 625
Specimen Width	2.54	mm
Specimen Thickness	1.5	mm
Notes
Operator Information End

Data Acquisition						Time:	1032.7849	Sec	10/20/2021 10:57:54 AM
Time	Axial Displacement	Axial Extensometer	Axial Force
Sec	mm	mm	N
31.904785	0.0025055266	0.00021377591	72.60627
32.805664	0.0037819974	0.00033151344	87.183472
33.706543	0.0092974063	0.00029484718	99.533562
34.607422	0.011663692	0.00047628733	112.29003
35.508301	0.012332815	0.00047964754	120.38061
36.40918	0.016127754	0.00053916429	133.56253
37.310059	0.020912163	0.00057546992	149.17735
38.210938	0.021652639	0.00061857078	159.24486
39.111816	0.02483147	0.00076818833	178.71417
40.012695	0.026563568	0.00087076804	182.00636
40.913574	0.032268502	0.0009477773	205.69276
41.814453	0.031532329	0.00095673924	221.45786
42.715332	0.031353254	0.0011395491	237.70012
43.616211	0.038734194	0.0012283068	257.33652
44.51709	0.038752019	0.001390267	276.40588
45.417969	0.044728585	0.0013023698	292.35205
46.318848	0.047099583	0.001515855	311.28821
47.219727	0.049229376	0.0014486066	330.72726
48.120605	0.049865358	0.0016797011	347.96323
49.021484	0.057388645	0.001687909	380.45288
49.922363	0.054306932	0.0017045257	386.06973
50.823242	0.055077322	0.0019252639	408.47247
51.724121	0.059184104	0.0020202217	430.41968
52.625	0.062971875	0.0021255675	441.68176
53.525879	0.068732537	0.002147462	467.97589
54.426758	0.069429725	0.0022429321	496.17041
55.327637	0.072249025	0.002506345	513.65906
56.228516	0.075033292	0.0024332451	540.93164
57.129395	0.075682797	0.0026823771	561.85681
58.030273	0.07910499	0.0027998309	581.66437
58.931152	0.081909128	0.0029087907	602.31189
59.832031	0.086758226	0.0029583129	621.55005
60.73291	0.088230163	0.0031102621	649.92877
61.633789	0.092945218	0.0032692964	677.06824
62.534668	0.096400656	0.0033138643	704.65411
63.435547	0.098754853	0.0034342029	726.61041
64.336426	0.097779572	0.0036158941	748.41309
65.237305	0.10243531	0.0037309024	779.07611
66.138184	0.10395063	0.0037915942	792.67139
67.039063	0.10294789	0.0039098561	819.71149
67.939941	0.11034805	0.0039916397	846.01068
68.84082	0.11307985	0.0040964526	869.71503
69.741699	0.113815	0.0041462439	885.76105
70.642578	0.11931422	0.0044110874	924.11115
71.543457	0.12235168	0.0044960994	939.43927
72.444336	0.12326319	0.0046017035	964.97943
73.345215	0.1259653	0.0046723448	993.4375
74.246094	0.1255424	0.0048574382	1018.9783
75.146973	0.13245885	0.00499509	1042.2909
76.047852	0.13404773	0.0051024356	1062.5024
76.94873	0.13921073	0.0051695444	1094.5414
77.849609	0.14022617	0.0052971281	1113.1643
78.750488	0.14386764	0.0054529342	1137.6012
79.651367	0.14367647	0.0055295257	1162.3361
80.552246	0.14744355	0.0055928277	1192.9275
81.453125	0.15153804	0.0058051981	1215.9579
82.354004	0.15120305	0.0058847247	1236.8441
83.254883	0.15459481	0.0060634366	1261.4468
84.155762	0.15815474	0.0062112221	1296.3658
85.056641	0.16156591	0.006308184	1325.9751
85.95752	0.16512913	0.0064618676	1348.6381
86.858398	0.16419831	0.0065810094	1369.5929
87.759277	0.16741714	0.0067358776	1403.5864
88.660156	0.17296533	0.0068875551	1429.1366
89.561035	0.17563091	0.0070005362	1448.4222
90.461914	0.17764618	0.007174334	1476.36
91.362793	0.18106498	0.0072768531	1502.3196
92.263672	0.18184131	0.0073437979	1530.0632
93.164551	0.18470134	0.0074677304	1550.9257
94.06543	0.18777628	0.0075826324	1582.9578
94.966309	0.1930071	0.0075871646	1598.2429
95.867188	0.19312757	0.007813788	1625.4299
96.768066	0.19620894	0.0080132997	1652.4318
97.668945	0.20155895	0.0081235878	1677.4604
98.569824	0.20044455	0.0082159676	1697.6322
99.470703	0.20349081	0.0082881823	1720.5845
100.37158	0.20454416	0.00854374	1747.193
101.27246	0.21010382	0.0085358759	1771.6333
102.17334	0.2141057	0.0086323787	1795.6594
103.07422	0.21455236	0.0087870164	1819.4116
103.9751	0.21806864	0.0088795619	1835.1338
104.87598	0.22041568	0.0090147099	1853.8513
105.77686	0.22300714	0.0090458272	1875.5763
106.67773	0.22898452	0.0092087146	1902.1481
107.57861	0.22796007	0.0093384823	1924.2003
108.47949	0.23341319	0.0094501916	1941.2166
109.38037	0.23371315	0.0094944481	1961.598
110.28125	0.2394316	0.0096579744	1986.6534
111.18213	0.24023902	0.0098147914	2002.5217
112.08301	0.24275243	0.0098977629	2028.0667
112.98389	0.2487061	0.0099295871	2041.7748
113.88477	0.24869072	0.010042787	2059.4956
114.78564	0.24864012	0.010129955	2079.1821
115.68652	0.25075331	0.010231396	2088.3826
116.5874	0.25709972	0.0103377	2111.0203
117.48828	0.25577596	0.010476848	2128.0532
118.38916	0.26181158	0.010521674	2142.2158
119.29004	0.26513529	0.010642319	2152.3452
120.19092	0.26770702	0.010676266	2172.5593
121.0918	0.2674593	0.010793413	2186.3269
121.99268	0.27154684	0.010798192	2198.5808
122.89355	0.2742731	0.011012784	2217.2729
123.79443	0.27521437	0.011086633	2230.5374
124.69531	0.27887061	0.011029581	2247.1338
125.59619	0.28288335	0.011238316	2260.0928
126.49707	0.2846972	0.011303144	2268.7908
127.39795	0.28673586	0.011387041	2280.4827
128.29883	0.29079655	0.01150693	2296.9595
129.19971	0.29562965	0.011545699	2312.1289
130.10059	0.29726696	0.011660092	2313.9802
131.00146	0.29938731	0.011623516	2328.7417
131.90234	0.30012941	0.011850118	2342.1257
132.80322	0.30385065	0.01202465	2358.3081
133.7041	0.3061167	0.012068038	2370.5193
134.60498	0.3084895	0.012103148	2378.3169
135.50586	0.31304416	0.012193228	2392.3154
136.40674	0.31553727	0.01228333	2404.3853
137.30762	0.31986862	0.012479548	2418.9448
138.2085	0.32090718	0.012591098	2424.8965
139.10938	0.32011327	0.012621032	2439.8979
140.01025	0.32630885	0.012705774	2449.2544
140.91113	0.32837641	0.012759979	2463.8896
141.81201	0.3311637	0.012955517	2473.5867
142.71289	0.33296633	0.012994511	2475.4736
143.61377	0.33796558	0.013143363	2485.6545
144.51465	0.34075701	0.013234719	2496.1448
145.41553	0.34094283	0.013284658	2499.4114
146.31641	0.34443945	0.013439345	2510.6272
147.21729	0.34859377	0.013600076	2521.9465
148.11816	0.34893408	0.013661318	2522.9033
149.01904	0.3511354	0.013767515	2538.7629
149.91992	0.35464415	0.013876577	2546.481
150.8208	0.36091518	0.013960984	2554.1147
151.72168	0.36074635	0.014127402	2571.9106
152.62256	0.36620927	0.014272884	2579.5818
153.52344	0.36728722	0.014393224	2580.5649
154.42432	0.37203673	0.014614738	2593.282
155.3252	0.37396619	0.014727053	2597.0376
156.22607	0.37547168	0.014902508	2610.8789
157.12695	0.37766236	0.014978734	2610.854
158.02783	0.38046339	0.015144772	2620.8579
158.92871	0.38401455	0.015386557	2632.1199
159.82959	0.38599047	0.015491758	2637.1626
160.73047	0.38895437	0.015630268	2641.1355
161.63135	0.39159805	0.015750499	2647.1545
162.53223	0.39712846	0.016022924	2655.7786
163.43311	0.3966361	0.016270431	2669.999
164.33398	0.39924166	0.01643244	2671.6875
165.23486	0.40145135	0.016744269	2682.9487
166.13574	0.40258273	0.016909925	2685.9351
167.03662	0.40949306	0.017259538	2697.0549
167.9375	0.40988275	0.01751524	2706.3884
168.83838	0.41583329	0.017761348	2719.2334
169.73926	0.41733086	0.017935893	2711.9709
170.64014	0.41915372	0.018231375	2725.4976
171.54102	0.4227891	0.018600654	2737.1414
172.44189	0.42400083	0.018927647	2741.5889
173.34277	0.42602879	0.019232497	2734.9275
174.24365	0.42903119	0.019429825	2741.7275
175.14453	0.43405181	0.019715337	2747.7195
176.04541	0.43520144	0.020055879	2754.5369
176.94629	0.43697745	0.020362761	2762.9802
177.84717	0.43991572	0.020686038	2767.0576
178.74805	0.44013864	0.021105167	2769.6978
179.64893	0.44846448	0.021566257	2784.3147
180.5498	0.44747835	0.021972455	2780.1567
181.45068	0.45293272	0.022287276	2790.3096
182.35156	0.45255673	0.022736177	2788.4854
183.25244	0.45732325	0.023139985	2789.6848
184.15332	0.45999581	0.023615504	2812.0503
185.0542	0.46039003	0.024049839	2800.8621
185.95508	0.46243092	0.024475371	2811.0098
186.85596	0.46796048	0.025143808	2819.479
187.75684	0.47070166	0.025557429	2829.0806
188.65771	0.4726989	0.026222866	2826.5342
189.55859	0.47553623	0.026820682	2831.9524
190.45947	0.48245448	0.027360769	2837.5945
191.36035	0.48079243	0.02798236	2838.0056
192.26123	0.48418704	0.028508805	2838.012
193.16211	0.48881096	0.029190898	2852.4714
194.06299	0.48597997	0.02958186	2843.6912
194.96387	0.49348754	0.030403057	2855.4839
195.86475	0.49405345	0.03091407	2856.0713
196.76563	0.49447021	0.031619698	2859.0586
197.6665	0.49948993	0.032289494	2863.5105
198.56738	0.50096452	0.032849107	2866.4116
199.46826	0.50572366	0.033558629	2874.4771
200.36914	0.50925881	0.034520268	2883.4526
201.27002	0.51218462	0.035330802	2887.9424
202.1709	0.51511478	0.036092382	2888.1238
203.07178	0.51594925	0.036720064	2892.0464
203.97266	0.52092683	0.037593052	2892.3633
204.87354	0.52170563	0.038318854	2894.0317
205.77441	0.5240342	0.03894414	2896.2178
206.67529	0.52767444	0.039901014	2900.7019
207.57617	0.52979749	0.04078725	2906.2915
208.47705	0.53002965	0.041719094	2906.7417
209.37793	0.53433537	0.042667776	2909.3721
210.27881	0.53868127	0.043219905	2903.5569
211.17969	0.54199225	0.04386675	2917.8904
212.08057	0.54154843	0.044561852	2911.1729
212.98145	0.5433597	0.045373026	2916.9419
213.88232	0.54821515	0.046280555	2916.6392
214.7832	0.55194122	0.047104072	2921.6189
215.68408	0.55279762	0.047919821	2928.5737
216.58496	0.5569346	0.0487381	2929.26
217.48584	0.55796129	0.049547616	2934.1201
218.38672	0.56195211	0.050469141	2939.7534
219.2876	0.56129813	0.051435605	2935.4683
220.18848	0.56854522	0.052461866	2941.7788
221.08936	0.57168454	0.053271461	2941.2451
221.99023	0.57161301	0.053995922	2937.9182
222.89111	0.57677394	0.054899432	2945.4927
223.79199	0.58072871	0.055841848	2947.9104
224.69287	0.5816679	0.056840207	2962.3335
225.59375	0.58200926	0.057834961	2952.5981
226.49463	0.5874964	0.058955155	2957.5974
227.39551	0.58801252	0.059947588	2965.4248
228.29639	0.59391469	0.06076353	2955.6599
229.19727	0.59210312	0.061540846	2960.8679
230.09814	0.59509099	0.062445149	2958.8521
230.99902	0.60146368	0.063130811	2960.4412
231.8999	0.60129052	0.064120911	2968.8701
232.80078	0.60578966	0.065230481	2979.5781
233.70166	0.60819954	0.066266097	2970.5283
234.60254	0.61259896	0.06729643	2978.988
235.50342	0.61413968	0.068202913	2980.8477
236.4043	0.61664832	0.069057286	2979.3459
237.30518	0.61519921	0.0699846	2977.0601
238.20605	0.62029469	0.07114955	2984.6467
239.10693	0.62296218	0.072147347	2981.8254
240.00781	0.62445259	0.073039688	2986.0066
240.90869	0.63024002	0.074154958	2992.1108
241.80957	0.6317144	0.075221613	2995.4775
242.71045	0.63888556	0.076421447	3001.6465
243.61133	0.63877082	0.077538021	3000.6943
244.51221	0.64062828	0.078717723	2999.4714
245.41309	0.64150256	0.079737931	3005.1072
246.31396	0.64346248	0.080631666	2995.8616
247.21484	0.65039963	0.081443816	3003.6414
248.11572	0.6515882	0.082478262	3009.5505
249.0166	0.65288049	0.083362341	3005.0271
249.91748	0.6535297	0.084413171	3015.3582
250.81836	0.66086572	0.085570991	3015.4189
251.71924	0.66002387	0.086515538	3014.5815
252.62012	0.66512787	0.08733809	3014.3679
253.521	0.6643284	0.088184409	3008.1797
254.42188	0.66829258	0.088836208	3016.4512
255.32275	0.67483896	0.08988148	3019.9009
256.22363	0.67575049	0.0909077	3023.8806
257.12451	0.67721301	0.09201549	3023.4939
258.02539	0.68200493	0.09307681	3025.0911
258.92627	0.68605542	0.093850784	3030.5164
259.82715	0.68692613	0.094647199	3021.3364
260.72803	0.68797028	0.095599167	3031.6331
261.62891	0.69222134	0.096815214	3038.2952
262.52979	0.69535202	0.09788195	3039.0686
263.43066	0.69516617	0.098946981	3035.8479
264.33154	0.69869232	0.099947236	3036.2681
265.23242	0.70186538	0.10097671	3040.1191
266.1333	0.70433414	0.10181298	3034.2834
267.03418	0.70981574	0.10285027	3041.2671
267.93506	0.70886952	0.1038465	3045.3184
268.83594	0.71194714	0.10489803	3047.0208
269.73682	0.71695793	0.10594776	3050.7163
270.6377	0.71887368	0.10706143	3051.8704
271.53857	0.72384238	0.10817206	3055.0908
272.43945	0.72387248	0.10928376	3055.4326
273.34033	0.72708201	0.11037202	3061.8093
274.24121	0.72756743	0.11145493	3057.5945
275.14209	0.73069406	0.11245244	3064.3918
276.04297	0.73682064	0.11361376	3058.0063
276.94385	0.73515326	0.11463591	3056.2805
277.84473	0.73987371	0.11557674	3060.5068
278.74561	0.74184	0.11648966	3058.9246
279.64648	0.74687004	0.11757644	3066.918
280.54736	0.74950427	0.11835001	3062.0173
281.44824	0.75267285	0.1192816	3068.731
282.34912	0.75398207	0.12020438	3068.385
283.25	0.75525135	0.12133986	3073.7449
284.15088	0.75839955	0.1224373	3074.7761
285.05176	0.76606047	0.12366797	3073.6226
285.95264	0.76523787	0.12475688	3077.4182
286.85352	0.7656216	0.1258906	3078.2942
287.75439	0.77107108	0.12683754	3077.3391
288.65527	0.77534831	0.12769607	3080.7527
289.55615	0.77382439	0.12875634	3080.9622
290.45703	0.77930266	0.12970799	3078.8772
291.35791	0.7783069	0.1309018	3088.7375
292.25879	0.7854026	0.13190955	3086.7654
293.15967	0.78691655	0.13279268	3083.3706
294.06055	0.78879863	0.133791	3087.4949
294.96143	0.7921924	0.13460858	3083.8889
295.8623	0.79630512	0.13549392	3091.3767
296.76318	0.79608631	0.13654442	3095.8232
297.66406	0.80291897	0.137584	3099.3247
298.56494	0.80176151	0.13877733	3096.8816
299.46582	0.80674565	0.13966587	3100.5876
300.3667	0.80855888	0.14090452	3106.5923
301.26758	0.81137717	0.14172208	3103.4221
302.16846	0.81324619	0.1430707	3108.4172
303.06934	0.81622112	0.1441551	3099.4004
303.97021	0.81972963	0.14525834	3102.4773
304.87109	0.82154411	0.14628057	3110.7664
305.77197	0.82461214	0.14729427	3106.8965
306.67285	0.82480043	0.14840519	3110.1731
307.57373	0.83168936	0.149663	3117.6758
308.47461	0.83389705	0.15073246	3112.1724
309.37549	0.83710337	0.15177655	3112.2549
310.27637	0.83920389	0.15273556	3113.9326
311.17725	0.83960307	0.15383679	3125.0881
312.07813	0.84443474	0.15489833	3116.2495
312.979	0.84514791	0.15600474	3121.8813
313.87988	0.8481319	0.15699911	3119.6526
314.78076	0.84808743	0.15791747	3119.3982
315.68164	0.85562634	0.15887094	3120.1765
316.58252	0.85870171	0.15989821	3128.1709
317.4834	0.86218333	0.16105993	3133.8562
318.38428	0.86250627	0.16203359	3127.8015
319.28516	0.86889142	0.16294913	3130.7642
320.18604	0.86649835	0.16411392	3131.9036
321.08691	0.87033385	0.16511013	3129.439
321.98779	0.87493479	0.16616191	3137.9751
322.88867	0.8753913	0.16714641	3133.6182
323.78955	0.87959588	0.16814095	3134.4299
324.69043	0.88165104	0.16906431	3138.6641
325.59131	0.88268965	0.16994327	3138.4932
326.49219	0.88773239	0.17082204	3135.5811
327.39307	0.8926872	0.17177799	3145.2834
328.29395	0.89157653	0.17277057	3149.8223
329.19482	0.89473778	0.17403801	3155.3103
330.0957	0.89671367	0.1750879	3145.7881
330.99658	0.89970952	0.17621918	3146.9768
331.89746	0.90217328	0.17725153	3148.7981
332.79834	0.90572673	0.17810416	3147.6614
333.69922	0.90944278	0.1792357	3154.9954
334.6001	0.91356558	0.18022875	3153.3093
335.50098	0.91034555	0.18143757	3160.0327
336.40186	0.91492581	0.18234593	3151.1013
337.30273	0.91812491	0.1832958	3148.3267
338.20361	0.92447525	0.18434481	3154.759
339.10449	0.92414892	0.18538578	3158.3647
340.00537	0.92745847	0.18641011	3158.4343
340.90625	0.93095118	0.18740514	3159.7126
341.80713	0.93416017	0.188513	3162.7314
342.70801	0.93420178	0.18977925	3168.3647
343.60889	0.93745005	0.19101737	3166.7625
344.50977	0.93908793	0.1921107	3166.252
345.41064	0.94089788	0.19320914	3163.6697
346.31152	0.94662762	0.19409108	3167.0498
347.2124	0.94924712	0.19495013	3163.9014
348.11328	0.9494229	0.19605146	3172.5771
349.01416	0.95330596	0.19708999	3167.7483
349.91504	0.9550246	0.19799979	3166.8728
350.81592	0.95900637	0.19895558	3173.7078
351.7168	0.96114892	0.20004994	3175.0942
352.61768	0.96278739	0.20106855	3176.2563
353.51855	0.9679299	0.20204076	3177.1572
354.41943	0.96993303	0.20305681	3181.2002
355.32031	0.97673064	0.20419626	3182.2878
356.22119	0.97501105	0.20519921	3180.1519
357.12207	0.97927618	0.20649703	3183.0906
358.02295	0.98095119	0.20740379	3181.9006
358.92383	0.98283285	0.20836148	3185.7
359.82471	0.98504096	0.20948592	3183.7261
360.72559	0.98805326	0.21068163	3195.9739
361.62646	0.99272346	0.21188182	3185.8591
362.52734	0.99207276	0.2128666	3186.4275
363.42822	0.99690646	0.2138046	3187.082
364.3291	0.99817306	0.21479952	3191.355
365.22998	1.0029562	0.2158124	3194.0569
366.13086	1.0061488	0.2167339	3196.5688
367.03174	1.0108759	0.21779105	3194.7329
367.93262	1.0103475	0.21890411	3197.1487
368.8335	1.0151557	0.22018118	3204.2314
369.73438	1.0161498	0.22163314	3212.9651
370.63525	1.0190189	0.2226478	3203.4192
371.53613	1.021521	0.22358955	3199.2925
372.43701	1.0256654	0.22442141	3199.6855
373.33789	1.0282327	0.22542387	3199.0166
374.23877	1.0313206	0.2265916	3207.0027
375.13965	1.0318838	0.22755994	3202.9634
376.04053	1.0372779	0.22838107	3208.3088
376.94141	1.0373182	0.22925153	3211.6606
377.84229	1.0413409	0.23029962	3208.614
378.74316	1.0439018	0.23143378	3221.2065
379.64404	1.0481409	0.23285377	3216.9888
380.54492	1.0466294	0.23406602	3204.4297
381.4458	1.0518351	0.23524603	3215.7864
382.34668	1.0566329	0.23632477	3221.3167
383.24756	1.0560699	0.23747776	3219.3999
384.14844	1.0580397	0.2383395	3211.5403
385.04932	1.0613852	0.23932266	3218.3127
385.9502	1.0641849	0.24036075	3217.6404
386.85107	1.0672642	0.24141249	3221.4128
387.75195	1.0686859	0.24228321	3218.8445
388.65283	1.0727695	0.2434554	3225.4465
389.55371	1.0752448	0.24466623	3225.3479
390.45459	1.080415	0.24588309	3236.6677
391.35547	1.0820878	0.2470731	3229.8167
392.25635	1.0865366	0.24834774	3230.5994
393.15723	1.0862402	0.24925639	3223.3398
394.05811	1.0883981	0.25014779	3228.5847
394.95898	1.092101	0.25111231	3231.9802
395.85986	1.0928015	0.25216535	3231.0129
396.76074	1.1004244	0.25310177	3235.2837
397.66162	1.1016068	0.25397065	3227.8484
398.5625	1.1000519	0.25494313	3231.2588
399.46338	1.1058	0.25587761	3240.5251
400.36426	1.1087451	0.25707281	3245.6094
401.26514	1.1110116	0.25806826	3238.8848
402.16602	1.1116933	0.2588667	3241.3503
403.06689	1.1154163	0.2599391	3241.0693
403.96777	1.1193286	0.26103529	3249.5098
404.86865	1.1210569	0.26208273	3244.5107
405.76953	1.1235337	0.26313531	3245.6304
406.67041	1.1272904	0.26436192	3250.8718
407.57129	1.1313709	0.26545903	3251.0017
408.47217	1.133291	0.26646996	3255.9043
409.37305	1.1344011	0.26759851	3251.1887
410.27393	1.139635	0.26874951	3255.3191
411.1748	1.1399741	0.26967478	3248.918
412.07568	1.1430663	0.27058855	3250.9324
412.97656	1.1448848	0.27165917	3252.4033
413.87744	1.1494832	0.27269515	3251.7629
414.77832	1.1501859	0.27384099	3255.4065
415.6792	1.1525503	0.27502638	3257.7288
416.58008	1.1558011	0.27601802	3260.437
417.48096	1.1567683	0.27685323	3250.6177
418.38184	1.1634705	0.27785614	3262.0549
419.28271	1.1630212	0.2789185	3261.0872
420.18359	1.1686546	0.28018048	3265.4187
421.08447	1.1730219	0.28104973	3266.3318
421.98535	1.1735537	0.28209534	3264.0786
422.88623	1.1751729	0.28319174	3268.1262
423.78711	1.1787269	0.28421062	3265.4451
424.68799	1.1827759	0.28532174	3270.8044
425.58887	1.1839206	0.28644779	3269.3228
426.48975	1.1826082	0.28735715	3262.9761
427.39063	1.1888347	0.2882987	3270.4661
428.2915	1.1938194	0.28949744	3278.7112
429.19238	1.1939116	0.29069969	3278.8394
430.09326	1.199213	0.29184258	3274.4341
430.99414	1.2018678	0.29293612	3275.6504
431.89502	1.2036021	0.29405785	3279.3462
432.7959	1.2046777	0.29519027	3281.8059
433.69678	1.2075684	0.29604077	3270.1523
434.59766	1.2111104	0.29701442	3281.8486
435.49854	1.2169845	0.29802397	3287.5137
436.39941	1.2143099	0.29898438	3276.1885
437.30029	1.2191877	0.30015525	3285.26
438.20117	1.2208906	0.30131513	3290.2913
439.10205	1.2234111	0.30229032	3286.4929
440.00293	1.2276809	0.30325267	3284.8647
440.90381	1.2292787	0.30428159	3283.4199
441.80469	1.2301769	0.30526051	3285.0698
442.70557	1.2345859	0.30622348	3283.9526
443.60645	1.2352011	0.30745426	3294.792
444.50732	1.2394575	0.3085646	3291.2954
445.4082	1.2428476	0.30946141	3296.2043
446.30908	1.2457339	0.31064162	3295.7712
447.20996	1.2512039	0.31158489	3297.1699
448.11084	1.2491652	0.31261873	3293.4304
449.01172	1.2543339	0.31380135	3295.6125
449.9126	1.2568467	0.31495106	3302.0596
450.81348	1.2582321	0.31586206	3295.0471
451.71436	1.259958	0.31688425	3295.4155
452.61523	1.267603	0.31794593	3308.5005
453.51611	1.2714164	0.31902829	3306.9211
454.41699	1.2732229	0.32007909	3306.5637
455.31787	1.2729963	0.32102659	3294.7668
456.21875	1.2774849	0.32212609	3308.6799
457.11963	1.281114	0.3233462	3308.2688
458.02051	1.2824692	0.3243559	3307.6895
458.92139	1.2833024	0.32544693	3314.7424
459.82227	1.2871222	0.32661134	3309.3201
460.72314	1.2919022	0.32778341	3315.8469
461.62402	1.293577	0.32888597	3314.7173
462.5249	1.2923945	0.32995623	3313.5085
463.42578	1.2991771	0.33085483	3312.0786
464.32666	1.3021308	0.33191395	3310.9036
465.22754	1.3026838	0.33299968	3315.1675
466.12842	1.3056768	0.33390704	3314.9851
467.0293	1.3098925	0.33500281	3316.0181
467.93018	1.3123602	0.33580822	3310.575
468.83105	1.3150926	0.33667737	3310.6069
469.73193	1.317207	0.33739346	3309.134
470.63281	1.3186576	0.33830124	3320.5466
471.53369	1.3225958	0.33934936	3319.8274
472.43457	1.327173	0.34042686	3325.1428
473.33545	1.327844	0.34175691	3323.156
474.23633	1.3310835	0.34280634	3319.918
475.13721	1.3326656	0.3438971	3327.6563
476.03809	1.3331383	0.34486684	3324.3838
476.93896	1.338616	0.34581307	3321.052
477.83984	1.3412648	0.34680283	3330.8477
478.74072	1.3409606	0.34793797	3332.2825
479.6416	1.3460333	0.34916157	3328.2964
480.54248	1.3482115	0.35034388	3322.5049
481.44336	1.3522973	0.35133198	3329.2336
482.34424	1.3537019	0.35235643	3336.1968
483.24512	1.3600827	0.35337165	3329.8984
484.146	1.3606505	0.35448214	3333.8198
485.04688	1.3630017	0.35542238	3332.9128
485.94775	1.3665272	0.35653186	3336.4106
486.84863	1.3701385	0.35763487	3335.999
487.74951	1.36835	0.35870418	3335.9807
488.65039	1.3736712	0.35967901	3333.5916
489.55127	1.3776859	0.36073369	3341.4844
490.45215	1.3808885	0.36186582	3341.1682
491.35303	1.3812989	0.36297742	3340.9573
492.25391	1.3837198	0.36405689	3340.2883
493.15479	1.3845695	0.36532661	3346.1829
494.05566	1.388975	0.36646277	3342.803
494.95654	1.3912189	0.36755818	3340.3137
495.85742	1.3943677	0.36859179	3341.1516
496.7583	1.3977664	0.36956859	3346.7253
497.65918	1.4011005	0.37060887	3347.3557
498.56006	1.4015998	0.37165785	3347.3591
499.46094	1.4041249	0.37287292	3354.1687
500.36182	1.4103819	0.37404403	3349.697
501.2627	1.411492	0.37507012	3352.8645
502.16357	1.4148457	0.376185	3351.8052
503.06445	1.4188644	0.37720886	3354.031
503.96533	1.419603	0.37808353	3352.2227
504.86621	1.4221219	0.37922478	3353.8777
505.76709	1.4253597	0.38025945	3355.4563
506.66797	1.4279919	0.38130498	3355.3027
507.56885	1.4294003	0.38233379	3353.9438
508.46973	1.4359328	0.38372421	3363.5652
509.37061	1.434708	0.38485706	3353.0845
510.27148	1.4373589	0.3856878	3356.0984
511.17236	1.4444836	0.38669041	3363.6179
512.07324	1.4412978	0.38750678	3359.8284
512.97412	1.4479883	0.38851199	3360.2917
513.875	1.4490178	0.38936335	3359.917
514.77588	1.44965	0.39035666	3366.4463
515.67676	1.453795	0.39155322	3368.5386
516.57764	1.4561553	0.39256376	3365.0405
517.47852	1.4625654	0.3938821	3374.0554
518.37939	1.4661671	0.39508462	3368.3276
519.28027	1.4656553	0.39618111	3363.6711
520.18115	1.469547	0.39740756	3372.053
521.08203	1.4712728	0.39870694	3371.311
521.98291	1.4697886	0.39984423	3366.874
522.88379	1.4763449	0.40115151	3377.8682
523.78467	1.4803057	0.40230486	3375.6777
524.68555	1.4801203	0.40340102	3372.8059
525.58643	1.4822989	0.40446052	3373.7041
526.4873	1.4850688	0.40556425	3369.3242
527.38818	1.4884224	0.4063808	3372.3838
528.28906	1.4911784	0.40746078	3371.665
529.18994	1.4965389	0.40849903	3382.0674
530.09082	1.4987406	0.40964913	3382.3892
530.9917	1.4999256	0.41065162	3381.28
531.89258	1.5000238	0.41184902	3379.8276
532.79346	1.5048963	0.41307288	3380.103
533.69434	1.5105096	0.41431651	3390.6348
534.59521	1.5100373	0.41524956	3376.2869
535.49609	1.5121319	0.41623399	3381.1125
536.39697	1.5169289	0.41731951	3386.8694
537.29785	1.5214463	0.41836458	3385.9436
538.19873	1.5239536	0.41931248	3387.2673
539.09961	1.5257263	0.42040011	3387.6252
540.00049	1.5274215	0.4214392	3384.2637
540.90137	1.5320684	0.42255232	3383.9768
541.80225	1.5298676	0.42335337	3382.1194
542.70313	1.5355397	0.4244068	3393.8398
543.604	1.5374838	0.42551145	3385.9321
544.50488	1.5401781	0.42659307	3388.8633
545.40576	1.5433778	0.42790005	3401.3208
546.30664	1.5459672	0.42901343	3394.8438
547.20752	1.5487435	0.42999762	3390.2053
548.1084	1.5495303	0.43108302	3393.8792
549.00928	1.5519117	0.43224445	3393.5747
549.91016	1.558257	0.43325129	3397.3052
550.81104	1.5579474	0.43443289	3398.6067
551.71191	1.5615854	0.43576643	3395.239
552.61279	1.5631692	0.43676314	3397.6743
553.51367	1.5686578	0.43787831	3400.0239
554.41455	1.570861	0.43896368	3397.9119
555.31543	1.5707031	0.44016168	3396.9912
556.21631	1.5769855	0.44137347	3401.542
557.11719	1.57803	0.44248056	3402.1602
558.01807	1.579861	0.44351205	3405.2437
558.91895	1.5842152	0.44468778	3403.5452
559.81982	1.5860113	0.44567841	3395.9009
560.7207	1.5922198	0.446789	3408.9202
561.62158	1.5937148	0.44814333	3406.9714
562.52246	1.5954531	0.44920078	3401.7683
563.42334	1.5986037	0.45017958	3406.1592
564.32422	1.5996857	0.45133981	3409.5579
565.2251	1.6031675	0.45270535	3415.4946
566.12598	1.6042371	0.45382509	3411.2573
567.02686	1.6076818	0.45507988	3406.7776
567.92773	1.6147106	0.45606971	3406.1294
568.82861	1.6119919	0.45706138	3405.4104
569.72949	1.6186552	0.45810637	3414.2253
570.63037	1.618062	0.4591195	3409.9319
571.53125	1.6234082	0.46018511	3414.2957
572.43213	1.6232766	0.46129349	3421.1741
573.33301	1.6260637	0.46228626	3411.4507
574.23389	1.6301955	0.46334988	3415.8901
575.13477	1.6326035	0.46426609	3416.5222
576.03564	1.6354306	0.46536559	3418.5278
576.93652	1.6364157	0.46640646	3413.9536
577.8374	1.6417756	0.46738663	3417.4702
578.73828	1.6444424	0.46837357	3417.3972
579.63916	1.6456075	0.469327	3416.7576
580.54004	1.6485037	0.47040993	3422.9866
581.44092	1.652203	0.47156715	3426.2239
582.3418	1.6549571	0.47275737	3422.3289
583.24268	1.6573519	0.47383898	3419.6758
584.14355	1.6599855	0.47510836	3431.2505
585.04443	1.6610447	0.47631431	3426.6306
585.94531	1.6657159	0.4775027	3419.457
586.84619	1.6698648	0.47848439	3423.3367
587.74707	1.6702447	0.47982654	3429.1499
588.64795	1.6741203	0.48104149	3432.1392
589.54883	1.6755902	0.48222721	3428.4934
590.44971	1.6750212	0.48328376	3425.291
591.35059	1.6823249	0.48433226	3427.917
592.25146	1.6829101	0.48558003	3433.6016
593.15234	1.6859988	0.48684332	3437.9583
594.05322	1.6866677	0.48806283	3428.647
594.9541	1.6933711	0.48937407	3431.7417
595.85498	1.694988	0.49048656	3440.4141
596.75586	1.6953613	0.49170679	3429.3813
597.65674	1.6988307	0.49278116	3432.2822
598.55762	1.703401	0.4938637	3440.4128
599.4585	1.7080127	0.49510723	3439.0298
600.35938	1.7090218	0.49620664	3437.0842
601.26025	1.7108237	0.49728501	3436.842
602.16113	1.7123319	0.49824917	3434.5447
603.06201	1.716571	0.49944875	3435.8452
603.96289	1.7204351	0.50072753	3442.3301
604.86377	1.7221005	0.50196362	3444.7712
605.76465	1.7237453	0.50318599	3440.1685
606.66553	1.7259451	0.5039897	3430.1035
607.56641	1.7285484	0.50498372	3434.3711
608.46729	1.7318569	0.50630063	3449.3555
609.36816	1.7325785	0.50752258	3440.7756
610.26904	1.736277	0.50877738	3440.6052
611.16992	1.7384703	0.51008403	3442.3032
612.0708	1.7419095	0.51101023	3440.8708
612.97168	1.7479695	0.51201087	3444.3821
613.87256	1.7496634	0.51304555	3451.7451
614.77344	1.7521566	0.51416224	3453.2705
615.67432	1.7548063	0.51513457	3441.5471
616.5752	1.7586832	0.5162769	3449.0757
617.47607	1.7592309	0.51745629	3450.4512
618.37695	1.762042	0.51855636	3448.0977
619.27783	1.7601371	0.51965719	3451.532
620.17871	1.7683052	0.52087677	3448.9302
621.07959	1.7706932	0.52204013	3452.0125
621.98047	1.7718068	0.52329075	3453.8523
622.88135	1.7770697	0.52425981	3454.7366
623.78223	1.7798263	0.52551979	3457.7234
624.68311	1.7799076	0.52690524	3456.4507
625.58398	1.7855315	0.52811545	3457.1584
626.48486	1.785475	0.52936184	3450.5935
627.38574	1.7890024	0.53035623	3443.9514
628.28662	1.790275	0.53139734	3452.999
629.1875	1.7954715	0.53255385	3457.9097
630.08838	1.7972432	0.53392673	3461.5491
630.98926	1.8003815	0.53521526	3455.8174
631.89014	1.803797	0.5364759	3463.2581
632.79102	1.8091139	0.53776067	3464.2415
633.69189	1.8096917	0.5387398	3459.1816
634.59277	1.8108356	0.53992838	3459.8979
635.49365	1.814695	0.54131263	3464.2383
636.39453	1.8159876	0.5425396	3460.0254
637.29541	1.8175833	0.54370707	3459.8484
638.19629	1.821521	0.54474425	3461.8633
639.09717	1.8230405	0.54591435	3457.824
639.99805	1.8269382	0.54692376	3463.7114
640.89893	1.831534	0.54811323	3466.7954
641.7998	1.8316137	0.5490517	3454.49
642.70068	1.8379709	0.55031562	3470.7297
643.60156	1.8379333	0.55150479	3469.3894
644.50244	1.8430974	0.55258709	3465.8342
645.40332	1.8417071	0.55366379	3468.7529
646.3042	1.8488721	0.5547629	3469.4419
647.20508	1.847952	0.55599731	3467.7561
648.10596	1.8515582	0.55712306	3464.303
649.00684	1.8545061	0.55826944	3469.5383
649.90771	1.8573124	0.55951738	3472.6741
650.80859	1.8602813	0.56062198	3468.7095
651.70947	1.8617297	0.56188118	3474.3938
652.61035	1.8652605	0.56318647	3474.1807
653.51123	1.8677864	0.56421471	3470.8711
654.41211	1.8716793	0.56541163	3475.8477
655.31299	1.8720081	0.56666785	3477.9431
656.21387	1.8731483	0.56802201	3475.6404
657.11475	1.8767306	0.56940138	3474.6545
658.01563	1.8806491	0.57076317	3478.5681
658.9165	1.8820266	0.5719859	3475.8538
659.81738	1.8836634	0.57308501	3472.1086
660.71826	1.8877553	0.57409358	3472.8516
661.61914	1.8929018	0.57530755	3482.3303
662.52002	1.8937615	0.57638347	3475.4739
663.4209	1.8991073	0.57750022	3483.2817
664.32178	1.9016756	0.57868683	3482.7219
665.22266	1.9033031	0.5800367	3485.2917
666.12354	1.9071959	0.58145815	3489.2363
667.02441	1.9054457	0.58273119	3478.3228
667.92529	1.9118491	0.58405268	3478.9365
668.82617	1.9141623	0.58516431	3486.0679
669.72705	1.9178736	0.58625048	3480.9614
670.62793	1.9206941	0.58720416	3479.4319
671.52881	1.9211125	0.58828783	3486.8074
672.42969	1.9264028	0.58962888	3489.6055
673.33057	1.9265617	0.59082234	3489.6675
674.23145	1.9298135	0.59226859	3490.709
675.13232	1.9318625	0.59360361	3490.6714
676.0332	1.9334934	0.59493351	3479.2297
676.93408	1.9380562	0.5961802	3491.5032
677.83496	1.9398103	0.5972684	3488.0825
678.73584	1.942373	0.59847885	3486.6086
679.63672	1.944484	0.59962493	3489.5408
680.5376	1.9459715	0.6007182	3490.1387
681.43848	1.9523982	0.60186553	3490.1421
682.33936	1.9531264	0.60304898	3492.4065
683.24023	1.9575907	0.6043548	3498.543
684.14111	1.9597738	0.60563505	3495.3789
685.04199	1.9643406	0.60690182	3496.4543
685.94287	1.9654498	0.60814404	3496.439
686.84375	1.9669912	0.6095072	3493.4148
687.74463	1.9689178	0.61055446	3488.6123
688.64551	1.9743258	0.61184156	3497.2319
689.54639	1.9758295	0.6127947	3490.7463
690.44727	1.9755028	0.61408883	3494.2988
691.34814	1.9804043	0.61547023	3495.3076
692.24902	1.9818424	0.6165607	3487.0396
693.1499	1.9879897	0.61771739	3498.2732
694.05078	1.9882498	0.6191808	3503.2705
694.95166	1.9927957	0.62034637	3497.6069
695.85254	1.9944389	0.62165582	3493.3359
696.75342	1.9983549	0.62273413	3493.0093
697.6543	1.9982893	0.62378967	3496.0557
698.55518	2.0028524	0.62497079	3501.9846
699.45605	2.006577	0.62660933	3509.8928
700.35693	2.0081055	0.62803066	3495.646
701.25781	2.0132124	0.62924767	3498.1792
702.15869	2.0149977	0.63054013	3498.9431
703.05957	2.0155346	0.63203818	3503.0178
703.96045	2.0185437	0.63326091	3496.4709
704.86133	2.0212734	0.63442564	3500.8521
705.76221	2.025337	0.63579679	3507.074
706.66309	2.0278978	0.63706243	3506.9597
707.56396	2.030673	0.63838112	3505.8467
708.46484	2.0305014	0.63964683	3500.9829
709.36572	2.0357478	0.64085841	3506.6685
710.2666	2.0365047	0.64190698	3502.2988
711.16748	2.0385437	0.6430226	3503.5881
712.06836	2.0424178	0.6442647	3511.9041
712.96924	2.0445714	0.64560676	3502.7432
713.87012	2.0484755	0.64665616	3504.1206
714.771	2.0534062	0.64800417	3506.8342
715.67188	2.0524154	0.64943147	3507.6396
716.57275	2.0568278	0.65060574	3508.155
717.47363	2.0581429	0.65194082	3509.4788
718.37451	2.0611827	0.65315449	3508.394
719.27539	2.0634069	0.65442747	3506.6633
720.17627	2.0655224	0.65579444	3512.4001
721.07715	2.0725362	0.65704393	3509.9309
721.97803	2.0733891	0.65837228	3509.0024
722.87891	2.0765214	0.65968305	3521.2361
723.77979	2.0767629	0.66122973	3515.344
724.68066	2.0833888	0.66235334	3510.2961
725.58154	2.0829437	0.66359377	3507.3203
726.48242	2.0873656	0.66483468	3514.3811
727.3833	2.088464	0.6659252	3505.1245
728.28418	2.089994	0.6670928	3511.9727
729.18506	2.0949221	0.66829014	3517.4375
730.08594	2.096669	0.66954345	3509.4414
730.98682	2.09992	0.6708588	3514.6111
731.8877	2.1022825	0.67223585	3515.3652
732.78857	2.1071398	0.6734913	3515.8918
733.68945	2.1073887	0.67491746	3518.3003
734.59033	2.1131241	0.67628175	3519.4304
735.49121	2.1127329	0.67755753	3517.7153
736.39209	2.1134698	0.67884767	3515.9358
737.29297	2.1191819	0.68030733	3520.5271
738.19385	2.1215947	0.68190193	3520.4368
739.09473	2.1244147	0.68326455	3517.9482
739.99561	2.1247547	0.68475771	3520.3223
740.89648	2.1300247	0.68599838	3518.9102
741.79736	2.1327081	0.68745065	3521.7336
742.69824	2.136611	0.68866551	3514.5432
743.59912	2.1390073	0.68998492	3519.3901
744.5	2.1387246	0.69131327	3519.2371
745.40088	2.1445336	0.69270498	3522.8633
746.30176	2.1463952	0.69377619	3514.4695
747.20264	2.1465983	0.69507259	3521.9495
748.10352	2.1499262	0.69635224	3524.4087
749.00439	2.1526589	0.69767863	3523.0142
749.90527	2.1554134	0.69892067	3521.6804
750.80615	2.1573827	0.70011628	3520.7029
751.70703	2.1641109	0.70143336	3521.8022
752.60791	2.1654441	0.7028873	3526.9033
753.50879	2.1665277	0.70415241	3516.4536
754.40967	2.168879	0.70543659	3520.4194
755.31055	2.1695452	0.70653057	3516.6252
756.21143	2.1774137	0.70755512	3525.5527
757.1123	2.1801896	0.70877659	3523.5823
758.01318	2.1828177	0.70980859	3523.2893
758.91406	2.1811216	0.71105707	3521.7856
759.81494	2.1868303	0.71272373	3533.071
760.71582	2.1875587	0.71413261	3526.2163
761.6167	2.1922028	0.71556485	3526.6155
762.51758	2.1933267	0.71691453	3525.6523
763.41846	2.1992271	0.71871758	3542.4319
764.31934	2.2015615	0.72015125	3520.3555
765.22021	2.2033582	0.72160196	3532.7754
766.12109	2.204278	0.72270101	3528.1636
767.02197	2.2078543	0.72413045	3526.6096
767.92285	2.2098229	0.72537684	3523.134
768.82373	2.2120705	0.72679889	3531.3689
769.72461	2.2146664	0.72825444	3530.687
770.62549	2.2201562	0.72975063	3530.9377
771.52637	2.2237198	0.73081213	3527.4578
772.42725	2.2240722	0.73220229	3532.6111
773.32813	2.2283635	0.73338425	3529.3491
774.229	2.2264824	0.73477429	3525.2842
775.12988	2.2317214	0.73627192	3533.9224
776.03076	2.2369843	0.73774683	3527.9819
776.93164	2.2372701	0.73920095	3534.4033
777.83252	2.2412379	0.74053556	3534.1865
778.7334	2.2434528	0.74175847	3530.3232
779.63428	2.245409	0.74315345	3538.1826
780.53516	2.249505	0.74479234	3539.6831
781.43604	2.2498629	0.74614531	3527.0088
782.33691	2.2563553	0.74743593	3529.4558
783.23779	2.2590046	0.74890393	3533.9292
784.13867	2.2573359	0.75043476	3533.0688
785.03955	2.2632437	0.75189334	3535.104
785.94043	2.2632072	0.75314993	3533.9104
786.84131	2.2688818	0.75466746	3537.54
787.74219	2.2714634	0.7559455	3532.0833
788.64307	2.2727561	0.75724548	3537.6638
789.54395	2.2778711	0.7585488	3533.0933
790.44482	2.2776446	0.75955153	3527.7725
791.3457	2.280865	0.76096541	3542.6074
792.24658	2.2858088	0.76244718	3539.1006
793.14746	2.2868536	0.76398587	3543.5107
794.04834	2.2884464	0.76546043	3539.6392
794.94922	2.2917824	0.7667793	3535.8367
795.8501	2.2944427	0.7681002	3534.4519
796.75098	2.2957492	0.7694909	3535.7087
797.65186	2.2990098	0.77070218	3532.3159
798.55273	2.3041432	0.77217054	3541.1301
799.45361	2.3055942	0.77358043	3540.9705
800.35449	2.309263	0.77506638	3536.3191
801.25537	2.3127196	0.77681839	3542.9158
802.15625	2.313045	0.77848142	3539.4485
803.05713	2.318161	0.77975893	3538.8176
803.95801	2.3196993	0.78119183	3538.5581
804.85889	2.322629	0.78267372	3539.5559
805.75977	2.3259649	0.78392661	3536.3889
806.66064	2.3283865	0.78544295	3545.4409
807.56152	2.3292675	0.78698307	3546.8484
808.4624	2.3298118	0.78863472	3546.1069
809.36328	2.3350224	0.79041016	3543.4287
810.26416	2.33863	0.79173785	3534.5991
811.16504	2.3398709	0.79299343	3539.2209
812.06592	2.3443956	0.79452461	3545.6755
812.9668	2.3457148	0.79585993	3542.7715
813.86768	2.3475566	0.79720974	3536.3188
814.76855	2.3514194	0.79847693	3537.3518
815.66943	2.3537536	0.79983264	3541.7227
816.57031	2.3581841	0.80140424	3543.9841
817.47119	2.3577495	0.80287021	3543.1113
818.37207	2.3627777	0.80456722	3548.6519
819.27295	2.3671556	0.80602652	3538.5725
820.17383	2.3672636	0.80750483	3539.8716
821.07471	2.3723705	0.8088091	3535.3318
821.97559	2.3737757	0.81005096	3545.6384
822.87646	2.3770716	0.81138694	3540.887
823.77734	2.3762596	0.81289232	3543.3667
824.67822	2.3803964	0.81439859	3551.3433
825.5791	2.3831234	0.81591374	3544.9507
826.47998	2.3872783	0.81731832	3544.9658
827.38086	2.3906238	0.81864685	3544.7441
828.28174	2.3912523	0.82012361	3545.6824
829.18262	2.3934619	0.82167786	3550.1948
830.0835	2.3980038	0.82336974	3550.8433
830.98438	2.3999326	0.82512927	3550.2876
831.88525	2.4044945	0.82620603	3536.8782
832.78613	2.4055459	0.82756442	3541.3564
833.68701	2.4071524	0.82880592	3545.5293
834.58789	2.4120731	0.83030742	3545.792
835.48877	2.4139524	0.83183146	3545.272
836.38965	2.4143562	0.83325344	3541.3713
837.29053	2.4189343	0.83477068	3546.3755
838.19141	2.4217801	0.83635461	3550.2659
839.09229	2.426156	0.83793694	3550.2986
839.99316	2.4254012	0.83952087	3541.1799
840.89404	2.4284081	0.84092802	3544.384
841.79492	2.4311297	0.84245718	3544.116
842.6958	2.4375668	0.84397775	3547.4192
843.59668	2.4389005	0.84567773	3552.7468
844.49756	2.440202	0.847417	3547.2454
845.39844	2.4429824	0.84912986	3553.1274
846.29932	2.4454997	0.8505432	3544.2354
847.2002	2.4490869	0.85212189	3543.6333
848.10107	2.4545298	0.85373694	3550.5894
849.00195	2.4544318	0.85527986	3549.8511
849.90283	2.4571235	0.8565442	3550.0757
850.80371	2.4609876	0.85815769	3555.104
851.70459	2.4610505	0.85994947	3549.5508
852.60547	2.464807	0.86158019	3551.0439
853.50635	2.4682283	0.862966	3548.5959
854.40723	2.4713597	0.86434323	3548.9229
855.30811	2.4719086	0.86587703	3549.4595
856.20898	2.4754372	0.86733359	3549.2551
857.10986	2.4777348	0.8689329	3550.3137
858.01074	2.4823515	0.8706426	3549.9893
858.91162	2.4850545	0.87226081	3550.9558
859.8125	2.4861586	0.87385839	3551.1804
860.71338	2.493567	0.87545574	3552.9214
861.61426	2.4929223	0.87713754	3553.6196
862.51514	2.4916463	0.87850106	3540.8071
863.41602	2.4980049	0.87993395	3546.2163
864.31689	2.4980648	0.88119364	3544.7788
865.21777	2.5020752	0.8830089	3555.6106
866.11865	2.5045054	0.88455611	3546.4031
867.01953	2.5075841	0.88617754	3554.1328
867.92041	2.5103605	0.88770103	3547.6721
868.82129	2.5140553	0.88920832	3547.5117
869.72217	2.5160306	0.89078259	3554.8647
870.62305	2.5182598	0.89234483	3546.4731
871.52393	2.5212431	0.89415181	3552.2842
872.4248	2.5282032	0.89575243	3557.3867
873.32568	2.5279279	0.89715672	3548.1375
874.22656	2.5289173	0.89911526	3551.9026
875.12744	2.5358002	0.90097445	3559.2087
876.02832	2.5342758	0.90257174	3547.5229
876.9292	2.5353422	0.90399146	3544.2524
877.83008	2.5424042	0.90557605	3547.9639
878.73096	2.5426531	0.90699649	3547.0525
879.63184	2.5467396	0.90846908	3547.863
880.53271	2.54778	0.91034299	3550.3416
881.43359	2.5503783	0.91230643	3550.9585
882.33447	2.5518532	0.91400647	3546.1418
883.23535	2.5574701	0.91563863	3551.2366
884.13623	2.5610304	0.91709703	3546.4763
885.03711	2.5631428	0.91869283	3551.2012
885.93799	2.568399	0.92045099	3553.1292
886.83887	2.5678215	0.92211777	3551.7124
887.73975	2.5703337	0.92407668	3554.3718
888.64063	2.5719349	0.92581969	3546.9153
889.5415	2.5753586	0.92752516	3548.4277
890.44238	2.5760617	0.9290058	3554.3145
891.34326	2.5793011	0.93028188	3543.8958
892.24414	2.581908	0.93191981	3554.1248
893.14502	2.5874233	0.93363106	3553.0815
894.0459	2.5899837	0.93560266	3554.2595
894.94678	2.5924244	0.93743479	3550.1267
895.84766	2.5965464	0.93894082	3546.3882
896.74854	2.598042	0.9404009	3542.5457
897.64941	2.6008611	0.94184935	3547.9932
898.55029	2.6015236	0.94355208	3552.6021
899.45117	2.6074672	0.94518828	3544.563
900.35205	2.6080594	0.94656754	3545.5068
901.25293	2.6102023	0.94827521	3554.6648
902.15381	2.613771	0.94998974	3551.051
903.05469	2.6161785	0.95186037	3551.4404
903.95557	2.6176667	0.95358449	3546.512
904.85645	2.6212451	0.95540667	3547.6733
905.75732	2.6232831	0.95688206	3544.3569
906.6582	2.6253743	0.95843214	3541.4094
907.55908	2.6286066	0.96010804	3548.9233
908.45996	2.634079	0.9619506	3552.6182
909.36084	2.6358893	0.96370369	3547.2004
910.26172	2.6388412	0.96528989	3547.812
911.1626	2.6434817	0.96695423	3547.6262
912.06348	2.6426558	0.96880406	3548.1418
912.96436	2.647311	0.97045231	3547.918
913.86523	2.6496656	0.97219229	3552.2583
914.76611	2.6520598	0.9739719	3550.501
915.66699	2.6532938	0.976156	3555.8447
916.56787	2.6585689	0.97817963	3551.8596
917.46875	2.6585112	0.98018867	3550.0999
918.36963	2.6611345	0.98200923	3541.8904
919.27051	2.6661391	0.98369056	3541.3169
920.17139	2.667264	0.98559326	3549.2454
921.07227	2.6725724	0.9871788	3542.9846
921.97314	2.6745911	0.98865592	3543.1506
922.87402	2.6750703	0.99033433	3545.4736
923.7749	2.6780827	0.99189985	3544.4851
924.67578	2.68347	0.99393135	3552.4739
925.57666	2.683352	0.99552304	3544.9641
926.47754	2.6879175	0.99731368	3548.9485
927.37842	2.6866941	0.99901325	3544.051
928.2793	2.691679	1.000911	3547.3262
929.18018	2.6964645	1.0029932	3547.6731
930.08105	2.6958959	1.0048491	3550.9587
930.98193	2.7	1.0068622	3542.5762
931.88281	2.7024632	1.0084554	3543.4026
932.78369	2.7046196	1.0099707	3543.0554
933.68457	2.7080007	1.0118238	3547.2998
934.58545	2.7107744	1.013552	3544.3618
935.48633	2.7138338	1.0153092	3545.8872
936.38721	2.7160544	1.0172532	3545.1797
937.28809	2.716933	1.019379	3546.4526
938.18896	2.7238653	1.0213284	3550.8572
939.08984	2.7242873	1.0230277	3542.5359
939.99072	2.7275288	1.0247551	3541.0588
940.8916	2.7286472	1.0265421	3541.8345
941.79248	2.7325785	1.0285354	3544.6777
942.69336	2.7337558	1.0307603	3544.3005
943.59424	2.7369306	1.032632	3544.0693
944.49512	2.7416625	1.0344315	3537.6692
945.396	2.7440472	1.0362651	3541.9465
946.29688	2.746623	1.0382452	3544.7227
947.19775	2.7496212	1.0399604	3543.5667
948.09863	2.7498662	1.0419869	3539.158
948.99951	2.7562675	1.04362	3535.2771
949.90039	2.7564931	1.0455666	3539.97
950.80127	2.7579079	1.0473034	3534.9187
951.70215	2.7618837	1.0490488	3536.9277
952.60303	2.7637661	1.0512513	3543.4519
953.50391	2.7681031	1.0534652	3534.3088
954.40479	2.7699246	1.0554382	3539.0154
955.30566	2.773067	1.0573996	3538.3623
956.20654	2.7758119	1.0594817	3533.6414
957.10742	2.7796116	1.0614573	3540.4863
958.0083	2.7813084	1.0635347	3534.1853
958.90918	2.7849805	1.0652617	3536.6685
959.81006	2.786871	1.0672448	3539.325
960.71094	2.7897277	1.0692704	3536.0305
961.61182	2.7905579	1.0710038	3530.614
962.5127	2.7941771	1.0726931	3531.8367
963.41357	2.7974977	1.0744537	3533.3792
964.31445	2.7991636	1.0762787	3530.0671
965.21533	2.8017924	1.0778919	3526.8633
966.11621	2.8078344	1.0799047	3536.7991
967.01709	2.8080695	1.0818069	3528.782
967.91797	2.8120983	1.0839183	3534.2644
968.81885	2.8162942	1.0859555	3535.9583
969.71973	2.8171229	1.0878742	3523.1506
970.62061	2.8159254	1.0894884	3521.4209
971.52148	2.8221741	1.0916692	3535.8528
972.42236	2.8234348	1.0940354	3530.292
973.32324	2.8280096	1.0963999	3532.4133
974.22412	2.830044	1.0986391	3528.5142
975.125	2.8349729	1.1008207	3529.8857
976.02588	2.83689	1.1030958	3528.9731
976.92676	2.837327	1.1054308	3529.269
977.82764	2.8364131	1.1076978	3517.9641
978.72852	2.8426092	1.1100547	3525.0806
979.62939	2.8456922	1.1121533	3523.6687
980.53027	2.8493414	1.1138841	3518.187
981.43115	2.8495507	1.1159462	3525.5806
982.33203	2.8542795	1.1180464	3516.8369
983.23291	2.8572907	1.1196529	3514.3833
984.13379	2.8617177	1.1211601	3520.5627
985.03467	2.8635244	1.1230323	3517.7024
985.93555	2.865711	1.1251296	3520.3293
986.83643	2.8655386	1.1272095	3519.2756
987.7373	2.8722694	1.1297524	3521.8555
988.63818	2.8712256	1.1317782	3510.1792
989.53906	2.8766904	1.133849	3511.1328
990.43994	2.8798244	1.1362743	3524.0598
991.34082	2.8816602	1.1386219	3515.5872
992.2417	2.8854527	1.1406332	3507.3215
993.14258	2.8837688	1.1425107	3506.8928
994.04346	2.8898213	1.1445117	3510.5806
994.94434	2.8908837	1.1464846	3510.1841
995.84521	2.8947814	1.1486099	3510.198
996.74609	2.8970177	1.1506798	3503.9285
997.64697	2.9020379	1.1525581	3502.7136
998.54785	2.9018278	1.1546413	3503.3323
999.44873	2.9029639	1.1566502	3500.1331
1000.3496	2.9035859	1.1588675	3505.7659
1001.2505	2.9099381	1.1614555	3501.634
1002.1514	2.9158382	1.1638094	3503.9438
1003.0522	2.9163749	1.1659838	3495.1926
1003.9531	2.9212544	1.1682739	3497.9612
1004.854	2.9235847	1.1703587	3495.3533
1005.7549	2.9237807	1.1723307	3491.7031
1006.6558	2.9302616	1.1742194	3490.6516
1007.5566	2.9258163	1.1761301	3493.105
1008.4575	2.9333663	1.1781321	3489.0679
1009.3584	2.9372373	1.1801287	3491.6729
1010.2593	2.9373372	1.1822704	3488.7244
1011.1602	2.9424791	1.184286	3489.4856
1012.061	2.9432831	1.1863612	3483.5347
1012.9619	2.9471152	1.1885554	3487.0388
1013.8628	2.9513161	1.1907481	3494.2002
1014.7637	2.9508345	1.1934654	3486.5469
1015.6646	2.9562213	1.1957039	3481.1809
1016.5654	2.9574685	1.1979446	3480.6453
1017.4663	2.9616339	1.2004452	3489.0696
1018.3672	2.9611936	1.2029673	3477.3521
1019.2681	2.9678915	1.2049532	3477.5081
1020.1689	2.9676635	1.2070506	3482.5469
1021.0698	2.9687133	1.2093005	3480.9761
1021.9707	2.9730587	1.2116427	3475.1375
1022.8716	2.977345	1.2140521	3473.1147
1023.7725	2.9787612	1.216666	3472.1333
1024.6733	2.9783044	1.2187675	3464.8784
1025.5742	2.9829147	1.2209759	3465.8259
1026.4751	2.9844332	1.2233002	3465.0791
1027.376	2.9892282	1.2252752	3459.8364
1028.2769	2.9917233	1.2273469	3463.0168
1029.1777	2.9957206	1.2296367	3463.1365
1030.0786	2.9966266	1.2318716	3458.1519
1030.9795	2.9990211	1.2342215	3459.5127
1031.8804	3.0037198	1.2368237	3461.2246
1032.7813	3.0075052	1.2391584	3450.9082
1033.6821	3.0090744	1.2416182	3455.0417
1034.583	3.0107484	1.2437965	3456.3955
1035.4839	3.0146315	1.2459641	3455.0459
1036.3848	3.0174251	1.2481686	3446.8918
1037.2856	3.0183377	1.2503828	3444.8804
1038.1865	3.0208242	1.2528626	3440.4028
1039.0874	3.0242119	1.2549399	3441.1472
1039.9883	3.0262368	1.257345	3444.0564
1040.8892	3.0315721	1.2597992	3439.3201
1041.79	3.0324924	1.2617956	3434.6482
1042.6909	3.0336452	1.26373	3430.6597
1043.5918	3.0369301	1.2654598	3427.3716
1044.4927	3.0414073	1.2675959	3433.5015
1045.3936	3.0442059	1.2697179	3434.5427
1046.2944	3.0457382	1.2720697	3432.3071
1047.1953	3.0482483	1.2748989	3426.4709
1048.0962	3.0512595	1.2774307	3418.0654
1048.9971	3.0521626	1.2797325	3425.9541
1049.8979	3.0554445	1.282186	3420.5374
1050.7988	3.059293	1.2845014	3418.6423
1051.6997	3.06599	1.2864826	3410.8311
1052.6006	3.0621665	1.2881243	3405.3335
1053.5015	3.0706732	1.2897122	3408.5208
1054.4023	3.0699055	1.2912495	3401.5061
1055.3032	3.0718472	1.2929497	3410.7273
1056.2041	3.0753529	1.2947118	3407.3501
1057.105	3.0809305	1.2965931	3412.0703
1058.0059	3.0799823	1.2988209	3406.1145
1058.9067	3.0847876	1.3013384	3410.8591
1059.8076	3.0863595	1.3042049	3405.8257
1060.7085	3.0887434	1.307007	3396.1431
1061.6094	3.095232	1.309487	3392.5017
1062.5103	3.0957468	1.3118669	3392.8535
1063.4111	3.0980284	1.3141133	3395.959
1064.312	3.1006401	1.3162652	3386.1921
1065.2129	3.1007371	1.3187572	3385.4915
1066.1138	3.1073432	1.3215587	3386.1248
1067.0146	3.113229	1.3244984	3384.2065
1067.9155	3.1120739	1.3269632	3375.2363
1068.8164	3.114795	1.3293521	3378.1089
1069.7173	3.1175196	1.3319659	3371.0469
1070.6182	3.1192033	1.3346354	3373.6594
1071.519	3.1218419	1.3371292	3364.0698
1072.4199	3.1249418	1.3395594	3372.7744
1073.3208	3.125272	1.3419745	3361.1353
1074.2217	3.1317194	1.3443409	3359.2542
1075.1226	3.1336777	1.346861	3357.2798
1076.0234	3.1361632	1.3493148	3354.5667
1076.9243	3.1379211	1.3515649	3348.3264
1077.8252	3.141068	1.3541563	3349.2842
1078.7261	3.1434739	1.3566449	3343.4365
1079.627	3.1487467	1.3590635	3345.7517
1080.5278	3.1473644	1.3616308	3333.5767
1081.4287	3.1509027	1.3639666	3335.4377
1082.3296	3.153429	1.3665729	3334.1267
1083.2305	3.15679	1.3694074	3323.0454
1084.1313	3.159121	1.3716645	3317.2239
1085.0322	3.1638143	1.3737255	3320.2993
1085.9331	3.1643019	1.3757455	3321.3259
1086.834	3.1674752	1.3782337	3316.019
1087.7349	3.172148	1.3806816	3316.177
1088.6357	3.1729186	1.3831959	3311.5042
1089.5366	3.1763339	1.3862523	3308.8271
1090.4375	3.1772935	1.388579	3293.4365
1091.3384	3.1830761	1.3911225	3303.8672
1092.2393	3.1835089	1.3932725	3291.1123
1093.1401	3.186233	1.395772	3294.3284
1094.041	3.1892207	1.3986889	3291.0208
1094.9419	3.1930985	1.4012939	3278.5718
1095.8428	3.1949408	1.4042548	3286.4753
1096.7437	3.1965506	1.407503	3278.0566
1097.6445	3.2036614	1.4107019	3271.5405
1098.5454	3.2036741	1.4132371	3261.4363
1099.4463	3.2053237	1.4157547	3252.2749
1100.3472	3.2072694	1.4180264	3250.344
1101.248	3.2099326	1.4206448	3248.5889
1102.1489	3.2118986	1.4232695	3248.2505
1103.0498	3.2147911	1.4258261	3233.9958
1103.9507	3.2213616	1.4283508	3236.4275
1104.8516	3.2234166	1.4310347	3237.0635
1105.7524	3.2261641	1.434224	3231.8586
1106.6533	3.2288749	1.437065	3224.8313
1107.5542	3.2310512	1.4395044	3218.5664
1108.4551	3.2321272	1.4419429	3214.6072
1109.356	3.2358749	1.4445571	3214.7244
1110.2568	3.2387114	1.446838	3203.3049
1111.1577	3.2398241	1.4498255	3200.675
1112.0586	3.2427647	1.4530052	3186.179
1112.9595	3.2466576	1.4556506	3178.3682
1113.8604	3.2511754	1.4581872	3181.5278
1114.7612	3.2541707	1.4608688	3172.5781
1115.6621	3.2504101	1.4636075	3161.1013
1116.563	3.2587202	1.4666479	3153.6199
1117.4639	3.2593563	1.4695917	3141.4678
1118.3647	3.2653661	1.4728087	3140.686
1119.2656	3.2667069	1.4760844	3124.7366
1120.1665	3.2645802	1.4789215	3119.1438
1121.0674	3.272733	1.482509	3114.616
1121.9683	3.2751615	1.4853128	3098.9705
1122.8691	3.2774677	1.4885854	3094.801
1123.77	3.2800341	1.4922082	3082.376
1124.6709	3.2785192	1.4965178	3053.7219
1125.5718	3.2848752	1.5012205	3024.8542
1125.8721	3.2888973	1.5094389	2927.7268