File: datasets/am_bench_2022/raw_data/45-XY.02-1/specimen.dat
MTS793|MPT|ENU|1|2|.|/|:|1|0|0|A

Operator Information						Time:	27.083984	Sec	10/14/2021 4:18:24 PM
Operator	Nick Derimow
Project	AM Bench 2022 mini-tensile challenge
Specimen ID	45-XY.02-1
Material	PBF-L Inconel 625
Specimen Width	2.56	mm
Specimen Thickness	1.53	mm
Notes
Operator Information End

Data Acquisition						Time:	1028.0774	Sec	10/14/2021 4:35:05 PM
Time	Axial Displacement	Axial Extensometer	Axial Force
Sec	mm	mm	N
27.197266	0.00027806763	0.00016547139	58.79966
28.198242	0.0049368273	0.00028689695	74.312035
29.199219	0.004858559	0.00025334809	81.546173
30.200195	0.0097638024	0.0002798159	99.747505
31.201172	0.012927729	0.00027742278	112.32716
32.202148	0.014307003	0.00036776639	125.75024
33.203125	0.019112259	0.00036731563	141.62576
34.204102	0.021077318	0.0005644433	159.74326
35.205078	0.022844708	0.00059469749	174.21217
36.206055	0.027753023	0.00067398517	189.41675
37.207031	0.030532934	0.00082005805	208.60193
38.208008	0.029181318	0.00074882258	230.56764
39.208984	0.033577561	0.00081255904	252.98643
40.209961	0.03855006	0.0010750336	267.61737
41.210938	0.038094383	0.0011956887	285.71161
42.211914	0.041407213	0.0010433821	307.47577
43.212891	0.047559783	0.0011003828	332.38477
44.213867	0.048312552	0.0012784145	352.51208
45.214844	0.055568919	0.0014189114	372.49475
46.21582	0.05682116	0.0014667236	397.36356
47.216797	0.057416163	0.001657807	421.02338
48.217773	0.061798323	0.0015627212	437.87442
49.21875	0.064606145	0.0018049536	461.50171
50.219727	0.064043105	0.0020399974	482.96826
51.220703	0.069179669	0.0021846658	503.67325
52.22168	0.071078554	0.0020030893	531.05524
53.222656	0.076958254	0.0021190597	557.05975
54.223633	0.078546159	0.0020949889	572.16028
55.224609	0.082097076	0.0024379285	596.96631
56.225586	0.08392895	0.002566393	630.88055
57.226563	0.088875793	0.002663662	657.45526
58.227539	0.08961504	0.0027342346	680.06512
59.228516	0.094001293	0.002790058	704.6438
60.229492	0.095395371	0.0027943198	726.62396
61.230469	0.10034195	0.0032178285	762.3844
62.231445	0.10402138	0.00331295	787.63617
63.232422	0.10835457	0.0033982533	814.32513
64.233398	0.10822324	0.0034611865	842.88812
65.234375	0.11381911	0.0035728759	868.29114
66.235352	0.11438359	0.0036835158	898.61554
67.236328	0.11787821	0.0039025217	921.00012
68.237305	0.11825951	0.0040055718	943.93768
69.238281	0.12286049	0.0039890781	975.65924
70.239258	0.12827913	0.0042110588	1003.783
71.240234	0.13042393	0.0043963683	1028.692
72.241211	0.13294901	0.0044610719	1059.0304
73.242188	0.13450265	0.0044509382	1089.0459
74.243164	0.13563734	0.0047729295	1123.2616
75.244141	0.13837668	0.0050945426	1154.0189
76.245117	0.14285657	0.0049957572	1183.0488
77.246094	0.15086852	0.0050529293	1212.733
78.24707	0.15085705	0.0052395756	1244.1479
79.248047	0.15436493	0.0053012921	1270.3236
80.249023	0.15526789	0.0055383355	1295.1519
81.25	0.16052498	0.0055715316	1322.4534
82.250977	0.16445817	0.0057896064	1348.3654
83.251953	0.16504231	0.0058922926	1372.9423
84.25293	0.16752534	0.0059544402	1403.5496
85.253906	0.17227204	0.0062028263	1432.2363
86.254883	0.17261298	0.0063145403	1469.5105
87.255859	0.17374808	0.0065043899	1484.9686
88.256836	0.17963429	0.0064796354	1513.8728
89.257813	0.18568406	0.0068024532	1542.297
90.258789	0.18704085	0.0068389564	1571.4321
91.259766	0.19159321	0.0069527016	1597.3542
92.260742	0.18994738	0.0070146197	1614.1742
93.261719	0.1959262	0.0071587218	1647.8911
94.262695	0.19778006	0.0072509013	1675.3076
95.263672	0.20174301	0.0073671183	1699.1823
96.264648	0.20310163	0.0076054856	1719.5242
97.265625	0.20498596	0.0076242615	1745.1698
98.266602	0.20944823	0.0076458817	1775.4098
99.267578	0.21305165	0.0079245754	1803.3002
100.26855	0.21599711	0.0079649789	1836.1042
101.26953	0.2191698	0.0080503318	1843.9741
102.27051	0.22159074	0.0081290342	1872.2
103.27148	0.22936712	0.0083532184	1899.5375
104.27246	0.22927901	0.0083531775	1911.0388
105.27344	0.23101424	0.0084649241	1939.9614
106.27441	0.23671216	0.0086545609	1969.5088
107.27539	0.23635092	0.0087341396	1982.8093
108.27637	0.24075219	0.0087384051	1997.2537
109.27734	0.24264452	0.0088709472	2026.4463
110.27832	0.245985	0.0090374025	2055.842
111.2793	0.24957423	0.0090614203	2073.3779
112.28027	0.24993443	0.0091354176	2095.5212
113.28125	0.25355464	0.0092820395	2102.7039
114.28223	0.26059192	0.0093191452	2125.5286
115.2832	0.26480383	0.0093983309	2145.3835
116.28418	0.2635245	0.009391061	2152.7024
117.28516	0.26967445	0.0096178558	2176.4187
118.28613	0.27100441	0.0096626328	2188.427
119.28711	0.27496034	0.009671947	2205.4729
120.28809	0.27774972	0.0097544231	2218.271
121.28906	0.27920014	0.0098362304	2243.0527
122.29004	0.28280246	0.0099744815	2257.834
123.29102	0.28838873	0.010019	2272.7693
124.29199	0.28814128	0.0101766	2285.8528
125.29297	0.29358703	0.010310958	2299.9004
126.29395	0.29419369	0.010290083	2314.3008
127.29492	0.29854855	0.010454712	2326.5056
128.2959	0.30294219	0.010483425	2335.5508
129.29688	0.30280614	0.010517867	2345.0813
130.29785	0.30825481	0.010598278	2359.7856
131.29883	0.31033358	0.010746228	2373.1643
132.2998	0.3115375	0.010789209	2380.0784
133.30078	0.31559178	0.010791389	2398.0349
134.30176	0.31922513	0.010901021	2401.1013
135.30273	0.32301372	0.01107094	2420.4238
136.30371	0.32497227	0.011167515	2429.479
137.30469	0.32927549	0.011265321	2441.7053
138.30566	0.32839471	0.011392332	2447.8904
139.30664	0.33771491	0.011542645	2474.2329
140.30762	0.33798516	0.011554713	2486.8875
141.30859	0.34274119	0.011697968	2486.0242
142.30957	0.34164813	0.011784188	2501.0239
143.31055	0.34676811	0.011822728	2507.6758
144.31152	0.35071772	0.012061591	2520.7708
145.3125	0.3536132	0.012198159	2527.8838
146.31348	0.35436741	0.012258739	2534.8376
147.31445	0.35987809	0.012411407	2551.7065
148.31543	0.36272931	0.012630855	2559.1091
149.31641	0.36568666	0.012670849	2568.3906
150.31738	0.36826479	0.012820569	2580.647
151.31836	0.3718313	0.012868951	2584.6023
152.31934	0.37402895	0.013152074	2596.0525
153.32031	0.37697503	0.013108564	2598.1052
154.32129	0.37765896	0.013253031	2602.7695
155.32227	0.38127053	0.013490276	2613.3354
156.32324	0.38775179	0.013562745	2621.521
157.32422	0.38722929	0.013815045	2631.8574
158.3252	0.39295918	0.013946862	2640.7595
159.32617	0.39673772	0.014178948	2649.8611
160.32715	0.3969875	0.014432813	2656.7473
161.32813	0.40333906	0.01459976	2669.761
162.3291	0.40500546	0.014986439	2674.4565
163.33008	0.40625504	0.015153587	2683.3633
164.33105	0.4094314	0.015399317	2686.7087
165.33203	0.41382855	0.015676703	2698.468
166.33301	0.41711456	0.01607356	2702.8247
167.33398	0.41990039	0.016314395	2713.2832
168.33496	0.42163235	0.016621035	2714.7559
169.33594	0.42552727	0.017098509	2722.4697
170.33691	0.42764011	0.017331202	2729.707
171.33789	0.43175119	0.017850237	2744.105
172.33887	0.43250477	0.018209336	2743.6721
173.33984	0.43364269	0.018791007	2747.7607
174.34082	0.44054502	0.019153329	2755.9805
175.3418	0.44292456	0.0196594	2767.9751
176.34277	0.44754276	0.020240078	2774.2852
177.34375	0.45371792	0.020743772	2780.8623
178.34473	0.45610386	0.021377545	2783.4258
179.3457	0.45610327	0.022022298	2788.6563
180.34668	0.4601725	0.02270497	2795.8711
181.34766	0.46228471	0.023223309	2792.1689
182.34863	0.46467328	0.023861274	2801.6545
183.34961	0.46768805	0.024534298	2802.2964
184.35059	0.47176594	0.025195066	2813.4922
185.35156	0.47606573	0.025898082	2817.9338
186.35254	0.47784618	0.026577864	2821.4536
187.35352	0.48253962	0.027250458	2824.6941
188.35449	0.48250642	0.027982106	2833.543
189.35547	0.48660168	0.028897982	2836.48
190.35645	0.48857519	0.029733457	2826.835
191.35742	0.49110207	0.030377155	2840.0867
192.3584	0.49599874	0.031344894	2843.1282
193.35938	0.49593952	0.03214984	2843.8103
194.36035	0.49930483	0.033127852	2850.5994
195.36133	0.5043276	0.033971533	2849.7051
196.3623	0.50432986	0.034912258	2859.6458
197.36328	0.50764972	0.03607481	2861.3088
198.36426	0.51409817	0.037117291	2867.8625
199.36523	0.51647019	0.038001467	2866.1431
200.36621	0.51785725	0.03895998	2869.8926
201.36719	0.52253878	0.040057857	2873.7659
202.36816	0.52601653	0.041006133	2879.272
203.36914	0.5292595	0.042075664	2885.3201
204.37012	0.53201753	0.043111872	2875.5989
205.37109	0.53146636	0.043925848	2883.5867
206.37207	0.5382359	0.045044094	2889.5969
207.37305	0.53807402	0.046394255	2901.01
208.37402	0.54310203	0.047347426	2892.4358
209.375	0.54423851	0.048484661	2895.3186
210.37598	0.55270374	0.049587362	2904.5574
211.37695	0.54938823	0.050826475	2900.374
212.37793	0.55415815	0.051850393	2903.1172
213.37891	0.55837476	0.052956574	2903.8018
214.37988	0.5625574	0.054091498	2904.4141
215.38086	0.5641377	0.055276506	2912.5498
216.38184	0.56727678	0.056466058	2914.0564
217.38281	0.57068449	0.057553932	2909.7915
218.38379	0.57460791	0.058604162	2915.4971
219.38477	0.57579058	0.059592657	2916.4744
220.38574	0.58129793	0.060720481	2924.0972
221.38672	0.58394796	0.062110633	2929.0029
222.3877	0.58537972	0.063171573	2927.2419
223.38867	0.58632386	0.064161286	2922.8098
224.38965	0.58806443	0.065278597	2924.8269
225.39063	0.59405982	0.066487513	2932.6863
226.3916	0.59929782	0.067534238	2934.2764
227.39258	0.60032475	0.068569243	2937.4404
228.39355	0.60263938	0.069760211	2939.6963
229.39453	0.60552418	0.071228437	2948.532
230.39551	0.60767716	0.072539948	2944.1626
231.39648	0.61403877	0.07375294	2942.4563
232.39746	0.61412257	0.074868515	2945.5547
233.39844	0.62105101	0.075937577	2947.3054
234.39941	0.62157696	0.077308349	2957.335
235.40039	0.62351054	0.078471474	2958.4626
236.40137	0.62749052	0.07965301	2959.5176
237.40234	0.63318437	0.080671646	2958.9573
238.40332	0.63237667	0.08201123	2963.7954
239.4043	0.63638777	0.083377071	2963.4915
240.40527	0.63914084	0.084485613	2960.2224
241.40625	0.64145303	0.085714191	2961.5161
242.40723	0.64506114	0.086884238	2962.1646
243.4082	0.6486932	0.088073403	2965.6086
244.40918	0.65056568	0.089064032	2964.9507
245.41016	0.6563499	0.090283521	2969.5698
246.41113	0.65631098	0.091763124	2978.5957
247.41211	0.66035241	0.092799872	2975.9451
248.41309	0.66089249	0.094079576	2977.2065
249.41406	0.66484374	0.095317341	2975.9224
250.41504	0.67091793	0.096771896	2984.3645
251.41602	0.67166919	0.097902097	2978.4888
252.41699	0.67579114	0.098985717	2983.636
253.41797	0.67565507	0.1001836	2983.2498
254.41895	0.68162435	0.10138977	2986.6042
255.41992	0.6845274	0.10255294	2991.5232
256.4209	0.68583769	0.10381797	2988.9163
257.42188	0.69287902	0.10518306	2999.1128
258.42285	0.69443911	0.10631061	2993.9807
259.42383	0.69557315	0.10755016	2994.5408
260.4248	0.69845569	0.10875861	2997.2241
261.42578	0.70433724	0.10975285	3002.3809
262.42676	0.70491868	0.11094654	3002.1853
263.42773	0.70824385	0.11217118	3002.0762
264.42871	0.70990616	0.11340221	3006.7634
265.42969	0.71345049	0.11461383	3009.9985
266.43066	0.71707106	0.11589631	3013.5063
267.43164	0.72059476	0.11725327	3005.8481
268.43262	0.72626299	0.11842207	3015.03
269.43359	0.72616792	0.11943871	3012.1772
270.43457	0.73017025	0.1206466	3016.3762
271.43555	0.73248214	0.12182721	3011.2205
272.43652	0.73590672	0.12296107	3017.2019
273.4375	0.73836964	0.12428402	3018.8408
274.43848	0.74053329	0.12540285	3014.8904
275.43945	0.74526453	0.12658378	3021.3384
276.44043	0.74868172	0.12784269	3025.0063
277.44141	0.75202978	0.12920815	3025.1667
278.44238	0.75360477	0.13063894	3027.9983
279.44336	0.75460935	0.13180086	3031.3816
280.44434	0.76137125	0.13318822	3027.9109
281.44531	0.76193881	0.13438086	3024.7485
282.44629	0.76669163	0.13554573	3038.9429
283.44727	0.76732618	0.13679853	3034.3291
284.44824	0.76892143	0.13807274	3032.2654
285.44922	0.7734648	0.13935749	3040.9753
286.4502	0.77570528	0.14044851	3038.6587
287.45117	0.77996904	0.14151716	3042.7771
288.45215	0.78185111	0.14269799	3040.2273
289.45313	0.7846837	0.14399345	3043.9539
290.4541	0.78865874	0.14526607	3041.5903
291.45508	0.79389799	0.14644335	3045.7881
292.45605	0.79333657	0.14770696	3047.8628
293.45703	0.80337572	0.14878924	3051.7749
294.45801	0.79951704	0.14977138	3051.0432
295.45898	0.80468518	0.15102041	3051.8096
296.45996	0.81026363	0.15195325	3052.8098
297.46094	0.81071335	0.15276925	3050.3564
298.46191	0.81205666	0.15413083	3060.6265
299.46289	0.81500292	0.15538436	3058.4377
300.46387	0.81891936	0.15644026	3063.0947
301.46484	0.82152247	0.15780219	3064.1213
302.46582	0.8260591	0.15907064	3061.0593
303.4668	0.82728535	0.16022103	3070.0505
304.46777	0.83129817	0.16154715	3065.1926
305.46875	0.83559602	0.16286911	3070.5386
306.46973	0.83862227	0.16380246	3068.3682
307.4707	0.84129566	0.16536628	3072.5112
308.47168	0.84338516	0.16662656	3073.4436
309.47266	0.845779	0.16766243	3070.5728
310.47363	0.84912974	0.16865799	3078.0208
311.47461	0.85368139	0.16988492	3078.947
312.47559	0.85713851	0.17110063	3080.1582
313.47656	0.85681802	0.17223498	3082.5137
314.47754	0.86276364	0.17369477	3083.0549
315.47852	0.86483717	0.17478672	3082.7869
316.47949	0.86443579	0.17618237	3089.9175
317.48047	0.87216645	0.17727552	3089.8584
318.48145	0.87367296	0.17857826	3091.5303
319.48242	0.87497979	0.17996529	3081.2808
320.4834	0.87954587	0.18070406	3086.905
321.48438	0.87981552	0.18188165	3088.4749
322.48535	0.88443744	0.18314371	3096.2412
323.48633	0.88771707	0.18453236	3097.2095
324.4873	0.89035726	0.18592927	3095.8254
325.48828	0.89261597	0.18703459	3096.676
326.48926	0.8973434	0.18813927	3100.6914
327.49023	0.90074223	0.18930937	3103.6287
328.49121	0.90529162	0.19066814	3105.4382
329.49219	0.90821147	0.19186373	3109.3652
330.49316	0.91144896	0.19310021	3105.241
331.49414	0.9119634	0.19418715	3100.4333
332.49512	0.91675246	0.19522281	3104.959
333.49609	0.9181996	0.1963971	3104.1423
334.49707	0.91888249	0.19736759	3107.4004
335.49805	0.92377931	0.19884695	3117.7075
336.49902	0.9279654	0.19999376	3112.3364
337.5	0.93052381	0.20109966	3115.4666
338.50098	0.93249917	0.20230094	3114.9939
339.50195	0.93514138	0.20343938	3120.7739
340.50293	0.94230556	0.20474221	3127.1772
341.50391	0.94021034	0.20588887	3120.7039
342.50488	0.94522953	0.20715746	3122.3491
343.50586	0.94881219	0.20842212	3125.3193
344.50684	0.9485653	0.20965526	3121.4434
345.50781	0.95615155	0.21078253	3131.4565
346.50879	0.95846736	0.21192265	3128.7249
347.50977	0.96073586	0.21303877	3127.5554
348.51074	0.96351177	0.2144534	3131.7061
349.51172	0.96769148	0.21569742	3132.7578
350.5127	0.97118211	0.21687113	3128.4539
351.51367	0.97371227	0.2180876	3135.9546
352.51465	0.97543007	0.21906799	3130.4846
353.51563	0.97805291	0.2200699	3131.395
354.5166	0.97935951	0.22113925	3138.4324
355.51758	0.98280102	0.22239056	3137.2891
356.51855	0.98791397	0.22355342	3143.1455
357.51953	0.98989153	0.22471641	3141.7102
358.52051	0.99015135	0.22601967	3148.1121
359.52148	0.99660087	0.22731605	3141.6399
360.52246	0.99990511	0.22849135	3148.2949
361.52344	1.0013052	0.2295979	3144.9756
362.52441	1.0052274	0.23056743	3141.8953
363.52539	1.0122732	0.23157419	3149.7542
364.52637	1.0135909	0.2328703	3155.2917
365.52734	1.0165887	0.23421158	3156.2017
366.52832	1.0147419	0.23509715	3146.8779
367.5293	1.0204613	0.23626548	3155.3621
368.53027	1.0256578	0.23781437	3160.6301
369.53125	1.0246116	0.23884441	3153.916
370.53223	1.0323154	0.24004863	3158.0132
371.5332	1.0328635	0.24130093	3155.6287
372.53418	1.0349959	0.24248795	3159.1826
373.53516	1.0381126	0.24355815	3161.8369
374.53613	1.042926	0.24469401	3161.2251
375.53711	1.0436625	0.2458978	3165.9512
376.53809	1.0480421	0.24703379	3164.9165
377.53906	1.0501479	0.24830231	3164.9004
378.54004	1.0541412	0.24948972	3170.4375
379.54102	1.0571233	0.25079218	3178.438
380.54199	1.0617896	0.25209126	3178.8984
381.54297	1.0613352	0.25339374	3174.0037
382.54395	1.0641059	0.25469828	3175.5286
383.54492	1.0678358	0.25571075	3172.9299
384.5459	1.0735931	0.25671321	3172.7751
385.54688	1.074906	0.25798801	3188.3645
386.54785	1.0769176	0.25935918	3180.4888
387.54883	1.0806644	0.2605961	3181.2998
388.5498	1.0832392	0.26179343	3177.1074
389.55078	1.085501	0.26282793	3180.9131
390.55176	1.0882545	0.26381752	3184.5022
391.55273	1.0929874	0.26494983	3185.0686
392.55371	1.0943917	0.26616457	3185.2993
393.55469	1.0994667	0.26737449	3191.1597
394.55566	1.1016139	0.26886824	3193.4065
395.55664	1.1050382	0.27005017	3190.0388
396.55762	1.1086469	0.27109665	3188.9141
397.55859	1.1098337	0.27203968	3196.0415
398.55957	1.1157027	0.27332187	3197.5513
399.56055	1.1145298	0.27462208	3195.5569
400.56152	1.1166691	0.27581468	3196.6309
401.5625	1.1233535	0.27687898	3197.2639
402.56348	1.1258825	0.27781081	3199.3613
403.56445	1.1291811	0.27898616	3205.3831
404.56543	1.1322513	0.28008661	3202.7881
405.56641	1.1339021	0.28140011	3201.7842
406.56738	1.1386583	0.28254312	3211.0576
407.56836	1.1407831	0.2836619	3205.2949
408.56934	1.142343	0.28483075	3204.3528
409.57031	1.1481954	0.28585064	3213.1807
410.57129	1.1490499	0.28700989	3205.8528
411.57227	1.1528393	0.2879687	3214.0518
412.57324	1.1572423	0.28900179	3212.7329
413.57422	1.1612558	0.29047281	3220.4556
414.5752	1.1629195	0.29175398	3219.4211
415.57617	1.1634775	0.29276639	3215.5806
416.57715	1.1666113	0.29389948	3219.3416
417.57813	1.1704372	0.29514238	3222.958
418.5791	1.1703591	0.29636851	3219.8076
419.58008	1.1790897	0.29761308	3223.2417
420.58105	1.1772394	0.29868761	3219.7061
421.58203	1.1843311	0.30006513	3230.4766
422.58301	1.1895348	0.30144507	3233.489
423.58398	1.1886429	0.30271199	3226.1526
424.58496	1.1902142	0.30384544	3222.9131
425.58594	1.1932642	0.30494606	3223.6462
426.58691	1.1978574	0.30611113	3230.1719
427.58789	1.2007318	0.30741704	3233.8547
428.58887	1.2060274	0.30886376	3231.0371
429.58984	1.2088468	0.30967131	3232.512
430.59082	1.2093434	0.31079087	3232.5679
431.5918	1.2111938	0.31203693	3235.7424
432.59277	1.2157167	0.31304729	3232.2302
433.59375	1.216808	0.31421623	3237.2603
434.59473	1.2198781	0.31545153	3244.5315
435.5957	1.2246982	0.31653738	3237.0068
436.59668	1.2294703	0.31772619	3246.1074
437.59766	1.2354819	0.31885615	3245.5537
438.59863	1.2326075	0.32009119	3241.8904
439.59961	1.2367908	0.32098192	3240.1987
440.60059	1.2386535	0.32190603	3235.7034
441.60156	1.2412938	0.32286856	3247.9622
442.60254	1.2450234	0.32408506	3246.8892
443.60352	1.2486651	0.32541251	3247.1323
444.60449	1.249275	0.32652181	3248.4695
445.60547	1.2540518	0.32778117	3253.0896
446.60645	1.2558273	0.32879767	3245.8203
447.60742	1.2585204	0.33004048	3250.6172
448.6084	1.2658601	0.33124343	3252.3208
449.60938	1.2672257	0.3326267	3252.9458
450.61035	1.2696888	0.33357346	3254.0166
451.61133	1.2730281	0.33469042	3262.387
452.6123	1.2768691	0.33605525	3259.3247
453.61328	1.2799374	0.33719543	3260.2019
454.61426	1.2839426	0.33840245	3263.0615
455.61523	1.2848465	0.33953339	3257.9631
456.61621	1.2868186	0.34065685	3262.8513
457.61719	1.2886382	0.34187105	3264.9512
458.61816	1.2931641	0.34304318	3259.0974
459.61914	1.2951486	0.34419939	3261.4368
460.62012	1.2991557	0.34520993	3267.9492
461.62109	1.303634	0.34621263	3260.0547
462.62207	1.3047618	0.34740776	3269.0466
463.62305	1.3073528	0.34865165	3270.7405
464.62402	1.3122233	0.34964341	3272.2207
465.625	1.3164482	0.35104892	3282.7883
466.62598	1.3165452	0.3524749	3273.3496
467.62695	1.3217477	0.3534095	3271.9272
468.62793	1.3227692	0.35456014	3273.2107
469.62891	1.3287256	0.35565743	3277.9375
470.62988	1.328167	0.35688412	3281.4807
471.63086	1.3330144	0.35807338	3279.8599
472.63184	1.3382767	0.3591561	3283.5469
473.63281	1.3365588	0.36020625	3278.0752
474.63379	1.3429587	0.36124715	3278.9915
475.63477	1.3422918	0.36247224	3277.7109
476.63574	1.3465233	0.36347151	3278.6484
477.63672	1.3517745	0.36459136	3284.178
478.6377	1.3548402	0.36583465	3291.3535
479.63867	1.3545262	0.36717346	3289.7534
480.63965	1.3618076	0.36841449	3288.6963
481.64063	1.3624631	0.36940476	3289.8943
482.6416	1.3662814	0.37045431	3290.2769
483.64258	1.3699995	0.37162539	3296.7922
484.64355	1.3720167	0.37262824	3293.5857
485.64453	1.3736106	0.37395304	3302.3706
486.64551	1.3778946	0.37518704	3297.7156
487.64648	1.3810426	0.37660521	3300.8372
488.64746	1.3829068	0.3777543	3292.3789
489.64844	1.3875465	0.37887499	3302.3135
490.64941	1.3905426	0.38009924	3302.3865
491.65039	1.3928958	0.38145158	3306.7485
492.65137	1.3981934	0.38253114	3302.9978
493.65234	1.3985291	0.38369378	3302.5962
494.65332	1.4025512	0.38498285	3309.6704
495.6543	1.4042187	0.38585994	3304.6536
496.65527	1.4086833	0.38716677	3307.8333
497.65625	1.4115109	0.38821313	3311.1428
498.65723	1.4141103	0.38938504	3310.5847
499.6582	1.4202105	0.39058745	3311.5291
500.65918	1.4184468	0.39186946	3315.2273
501.66016	1.4217511	0.39306423	3310.4658
502.66113	1.4275742	0.39421505	3315.8418
503.66211	1.4279428	0.39540181	3309.7285
504.66309	1.4320039	0.3965207	3318.7722
505.66406	1.4343491	0.39772785	3310.6753
506.66504	1.4376281	0.39877856	3321.4521
507.66602	1.4406569	0.39997542	3320.9067
508.66699	1.4436167	0.40121236	3322.187
509.66797	1.4496367	0.4024474	3325.6387
510.66895	1.4495959	0.40363169	3325.4006
511.66992	1.4539961	0.40488684	3323.4587
512.6709	1.4560984	0.40590411	3318.7178
513.67188	1.4596477	0.40676668	3327.7373
514.67285	1.4617515	0.40792191	3329.8284
515.67383	1.4651064	0.40924224	3328.7949
516.6748	1.4679819	0.41035655	3329.5352
517.67578	1.4687855	0.41161361	3329.1697
518.67676	1.4749926	0.41286993	3330.7852
519.67773	1.4788593	0.41415387	3333.248
520.67871	1.4803934	0.4153828	3335.9131
521.67969	1.4834219	0.41645655	3327.2683
522.68066	1.4840968	0.41765493	3330.4543
523.68164	1.4879816	0.41869989	3331.6294
524.68262	1.4958339	0.4198578	3342.5388
525.68359	1.4962406	0.42103288	3340.2966
526.68457	1.497334	0.42220208	3339.5667
527.68555	1.4996498	0.42322391	3338.5313
528.68652	1.5037161	0.42446619	3341.1189
529.6875	1.5055926	0.42581436	3340.6335
530.68848	1.5116806	0.42673269	3342.7544
531.68945	1.5104634	0.42788321	3345.2454
532.69043	1.5178376	0.42904353	3345.2522
533.69141	1.5185673	0.43042591	3347.9343
534.69238	1.5213915	0.43159452	3351.4846
535.69336	1.5243472	0.43287152	3345.0383
536.69434	1.5260996	0.43423367	3349.0959
537.69531	1.5302986	0.43528169	3347.4368
538.69629	1.5347303	0.43638378	3345.6052
539.69727	1.5385534	0.43737873	3346.9773
540.69824	1.5411928	0.43855643	3357.9104
541.69922	1.5437316	0.43958756	3356.6584
542.7002	1.5432763	0.44090465	3360.5354
543.70117	1.5497208	0.44215468	3356.5664
544.70215	1.553532	0.44325969	3363.6235
545.70313	1.5550588	0.44457287	3366.5969
546.7041	1.5571005	0.44578111	3357.0913
547.70508	1.5611113	0.44696966	3360.167
548.70605	1.5633756	0.44824171	3367.6023
549.70703	1.5679094	0.44946149	3362.7778
550.70801	1.5664195	0.45064718	3356.634
551.70898	1.5729177	0.45189783	3365.9802
552.70996	1.5768141	0.45320004	3370.1931
553.71094	1.5780034	0.45453352	3368.3376
554.71191	1.5802933	0.45577174	3368.926
555.71289	1.5861466	0.45694831	3370.5813
556.71387	1.5885161	0.45817119	3367.418
557.71484	1.5892745	0.45920551	3363.6265
558.71582	1.5965195	0.46029288	3369.8389
559.7168	1.5990607	0.46119571	3366.9075
560.71777	1.6015263	0.4623608	3380.2393
561.71875	1.6005683	0.46357411	3371.3838
562.71973	1.6109574	0.46472672	3375.1968
563.7207	1.6072459	0.46575439	3375.5359
564.72168	1.6131992	0.4670262	3371.9377
565.72266	1.6134623	0.46813634	3376.1851
566.72363	1.6184441	0.46935725	3372.6816
567.72461	1.6210678	0.47043309	3372.9348
568.72559	1.6275885	0.4714292	3383.511
569.72656	1.6261964	0.47263384	3379.9678
570.72754	1.6287855	0.4739354	3383.6692
571.72852	1.6333289	0.4751986	3386.7036
572.72949	1.6363895	0.47624263	3388.3618
573.73047	1.6379747	0.47738472	3380.4377
574.73145	1.6419934	0.47874916	3396.0415
575.73242	1.6450323	0.48008767	3389.0923
576.7334	1.6495901	0.48104137	3383.7236
577.73438	1.6525497	0.48229942	3390.3914
578.73535	1.6550465	0.48371321	3391.3989
579.73633	1.6572917	0.48496783	3387.7043
580.7373	1.6622713	0.4861083	3388.1843
581.73828	1.6621315	0.48709679	3391.022
582.73926	1.6634483	0.48824161	3384.5112
583.74023	1.6669085	0.48908228	3390.5657
584.74121	1.6712456	0.49032396	3397.53
585.74219	1.6740091	0.49152493	3395.0674
586.74316	1.6782014	0.49273723	3387.8591
587.74414	1.6802845	0.49392518	3398.1204
588.74512	1.6832581	0.49528828	3397.3076
589.74609	1.6841366	0.49643505	3395.5137
590.74707	1.6893706	0.49759209	3401.0132
591.74805	1.6912075	0.49878535	3401.3064
592.74902	1.6949617	0.50007743	3398.665
593.75	1.7018836	0.50127107	3398.7756
594.75098	1.7027614	0.50232852	3401.521
595.75195	1.7040352	0.50348139	3399.5212
596.75293	1.7098247	0.50467157	3408.3628
597.75391	1.708674	0.50580114	3402.1694
598.75488	1.7141056	0.50722122	3411.3677
599.75586	1.7173719	0.50870091	3409.021
600.75684	1.7208483	0.50988245	3409.4946
601.75781	1.7208246	0.5111115	3411.0647
602.75879	1.7291119	0.5124104	3410.0847
603.75977	1.7282917	0.51367301	3410.5959
604.76074	1.7332189	0.51494682	3414.9583
605.76172	1.732008	0.51611465	3409.0159
606.7627	1.7415822	0.51722813	3415.1025
607.76367	1.7421799	0.51833785	3415.4478
608.76465	1.7438461	0.51963496	3416.0254
609.76563	1.7492212	0.520778	3417.7441
610.7666	1.7495962	0.52192783	3412.5713
611.76758	1.7541406	0.52291709	3418.238
612.76855	1.7562289	0.5240953	3420.4312
613.76953	1.759791	0.52540439	3420.2395
614.77051	1.7621379	0.52654886	3422.1208
615.77148	1.7629892	0.52775353	3419.0637
616.77246	1.7692164	0.5288983	3418.4866
617.77344	1.7717593	0.53012252	3421.5669
618.77441	1.7747234	0.53137177	3425.4746
619.77539	1.7778054	0.53266603	3426.9409
620.77637	1.7821817	0.53403312	3428.3708
621.77734	1.7836659	0.53509951	3426.2778
622.77832	1.7870888	0.53626722	3426.5313
623.7793	1.790938	0.53735894	3425.3408
624.78027	1.7934213	0.53872383	3429.6414
625.78125	1.7957768	0.53988838	3430.8506
626.78223	1.7994467	0.54114157	3438.4768
627.7832	1.8011552	0.54258192	3437.2207
628.78418	1.8039843	0.54388767	3430.7903
629.78516	1.8068783	0.54486424	3425.134
630.78613	1.8112524	0.54598588	3432.9243
631.78711	1.8136442	0.54729861	3434.9597
632.78809	1.8167251	0.5483827	3438.6919
633.78906	1.8209921	0.54976022	3441.126
634.79004	1.8220965	0.55108762	3438.7861
635.79102	1.8246851	0.55232996	3437.6343
636.79199	1.8312279	0.55351615	3444.3159
637.79297	1.8312534	0.55481035	3439.2207
638.79395	1.8316349	0.55607593	3440.9797
639.79492	1.837458	0.55718225	3444.5977
640.7959	1.8417015	0.55871695	3448.5879
641.79688	1.8433784	0.56009114	3443.78
642.79785	1.8442703	0.56126761	3442.7239
643.79883	1.8486884	0.5624252	3436.4958
644.7998	1.8531027	0.56360954	3448.0325
645.80078	1.854761	0.56491852	3451.3499
646.80176	1.8603926	0.5660491	3443.876
647.80273	1.860256	0.56711853	3444.0642
648.80371	1.8622469	0.5683828	3451.032
649.80469	1.8682926	0.56947953	3447.1267
650.80566	1.8694471	0.57081246	3445.3599
651.80664	1.8730865	0.57200998	3454.1777
652.80762	1.8762653	0.57335544	3450.9695
653.80859	1.8800167	0.57442576	3451.7515
654.80957	1.8817654	0.57567358	3448.1902
655.81055	1.8848296	0.57688099	3448.6404
656.81152	1.8897978	0.57789958	3456.0972
657.8125	1.8879777	0.57912886	3451.1489
658.81348	1.8941402	0.58020562	3458.4243
659.81445	1.9000221	0.58142656	3461.1038
660.81543	1.9004602	0.58271742	3456.2207
661.81641	1.9035934	0.58409089	3460.7703
662.81738	1.90813	0.58545393	3462.7126
663.81836	1.9104004	0.58650202	3458.3213
664.81934	1.9122194	0.5876438	3464.4478
665.82031	1.9163846	0.58891976	3462.8196
666.82129	1.9169632	0.59027481	3459.9512
667.82227	1.9242177	0.59149885	3461.6035
668.82324	1.9269687	0.5927279	3465.8911
669.82422	1.9311454	0.59401321	3463.866
670.8252	1.9310765	0.59500647	3461.4316
671.82617	1.9343976	0.59628826	3471.3376
672.82715	1.9359962	0.59781474	3466.7195
673.82813	1.9402205	0.59925169	3466.1731
674.8291	1.9410177	0.60062528	3468.2307
675.83008	1.9487287	0.60206002	3475.895
676.83105	1.9481822	0.60338306	3465.7158
677.83203	1.9535363	0.60434902	3464.5105
678.83301	1.9518217	0.60566986	3468.2671
679.83398	1.9574392	0.60689652	3470.7852
680.83496	1.9592659	0.60820681	3472.3069
681.83594	1.9642781	0.60953671	3472.2141
682.83691	1.966279	0.61110675	3477.9409
683.83789	1.9708145	0.61247665	3473.1025
684.83887	1.972604	0.6137383	3475.1035
685.83984	1.9742863	0.61481869	3474.0288
686.84082	1.978825	0.6160022	3470.8792
687.8418	1.983345	0.61721462	3475.2708
688.84277	1.9846272	0.61826181	3476.8215
689.84375	1.9870354	0.61980927	3487.6328
690.84473	1.990348	0.62108386	3478.7039
691.8457	1.9946618	0.62208521	3472.0266
692.84668	1.9975373	0.62350929	3488.606
693.84766	2.0012443	0.62469518	3479.6206
694.84863	2.0027361	0.62587768	3477.5632
695.84961	2.004117	0.62688476	3480.2297
696.85059	2.0075364	0.62813926	3487.064
697.85156	2.0101016	0.62922007	3487.8706
698.85254	2.013464	0.63037777	3480.7832
699.85352	2.0195704	0.63186985	3492.8381
700.85449	2.0208642	0.63342839	3493.3179
701.85547	2.0212581	0.63483644	3489.7263
702.85645	2.0275333	0.63608903	3492.3735
703.85742	2.0311151	0.63732523	3484.4275
704.8584	2.0332654	0.63874084	3490.1865
705.85938	2.0350699	0.64002514	3493.6079
706.86035	2.0397611	0.64143008	3496.3213
707.86133	2.0401244	0.64272803	3491.1504
708.8623	2.0459683	0.64413083	3495.1697
709.86328	2.0489371	0.64548481	3488.897
710.86426	2.0517161	0.64668876	3489.1636
711.86523	2.0505037	0.64808619	3491.5959
712.86621	2.0559926	0.64932489	3499.7744
713.86719	2.0595248	0.65056884	3494.7468
714.86816	2.0587192	0.65182883	3494.3303
715.86914	2.0656712	0.6530174	3487.2778
716.87012	2.0684531	0.65424037	3499.271
717.87109	2.071718	0.65548819	3495.3003
718.87207	2.0735335	0.65711153	3503.7678
719.87305	2.0776148	0.65826112	3501.4465
720.87402	2.0807447	0.65941393	3497.5986
721.875	2.0815518	0.66081899	3502.3398
722.87598	2.0877185	0.66211015	3502.7322
723.87695	2.0900037	0.66342902	3496.5803
724.87793	2.0938296	0.66465282	3503.0742
725.87891	2.0926075	0.66574156	3493.0654
726.87988	2.1005244	0.66689497	3497.854
727.88086	2.1009951	0.66806537	3499.3835
728.88184	2.1061251	0.66934937	3505.8882
729.88281	2.1052094	0.67055911	3504.2148
730.88379	2.1120236	0.6718713	3506.1692
731.88477	2.1145227	0.67301613	3497.228
732.88574	2.1194386	0.67434895	3508.4395
733.88672	2.1200156	0.67554533	3508.9304
734.8877	2.1229441	0.67701817	3513.6929
735.88867	2.1279697	0.6784119	3512.1416
736.88965	2.1263328	0.67975712	3506.0129
737.89063	2.1307888	0.68132794	3505.5195
738.8916	2.1362357	0.6825496	3510.5972
739.89258	2.1376338	0.68406266	3512.7336
740.89355	2.1401701	0.68541592	3513.5901
741.89453	2.1418428	0.6866762	3507.1687
742.89551	2.146667	0.68785793	3510.4473
743.89648	2.1501372	0.6889568	3510.7747
744.89746	2.1545775	0.6902777	3516.3101
745.89844	2.1554065	0.69158489	3517.6541
746.89941	2.1597483	0.69295925	3515.1709
747.90039	2.1611481	0.69431257	3516.2214
748.90137	2.1649845	0.6958282	3521.9006
749.90234	2.1664751	0.69717646	3511.5227
750.90332	2.1718214	0.69845861	3524.9438
751.9043	2.1725457	0.69983584	3509.5083
752.90527	2.1761332	0.70121914	3521.5713
753.90625	2.1787443	0.70267594	3521.6792
754.90723	2.1821554	0.70398146	3522.3081
755.9082	2.1840448	0.70553595	3519.7253
756.90918	2.1913798	0.70704001	3521.751
757.91016	2.1925373	0.70828152	3518.7991
758.91113	2.1930504	0.70953834	3521.4773
759.91211	2.1999464	0.71079129	3525.3613
760.91309	2.2000008	0.71240097	3520.7473
761.91406	2.2052817	0.71355921	3520.4705
762.91504	2.2081051	0.71469426	3519.6035
763.91602	2.212554	0.71614963	3524.4602
764.91699	2.2096775	0.71708786	3521.6555
765.91797	2.2148585	0.71858722	3526.5625
766.91895	2.2171178	0.71971929	3523.8079
767.91992	2.2221088	0.72104001	3525.054
768.9209	2.2269821	0.72239631	3528.7957
769.92188	2.2255473	0.72406924	3529.5017
770.92285	2.2309904	0.72548473	3533.4412
771.92383	2.2356663	0.72654021	3527.3196
772.9248	2.2387137	0.72808415	3528.145
773.92578	2.2406158	0.7295174	3531.2095
774.92676	2.2443366	0.7309562	3532.5283
775.92773	2.2463396	0.73229104	3536.7266
776.92871	2.2485659	0.73364872	3533.1023
777.92969	2.2514384	0.73510551	3534.2764
778.93066	2.2583809	0.73650229	3534.1448
779.93164	2.2580762	0.73795885	3535.856
780.93262	2.2630458	0.73929822	3535.4421
781.93359	2.2650032	0.74051368	3530.4456
782.93457	2.2660308	0.74182934	3531.2915
783.93555	2.2668602	0.74317139	3527.5239
784.93652	2.2732856	0.74463457	3542.7922
785.9375	2.2746191	0.74611974	3544.6028
786.93848	2.2764947	0.74774468	3540.8718
787.93945	2.2813423	0.74913371	3530.3271
788.94043	2.2831371	0.75058967	3534.7896
789.94141	2.2871573	0.75163418	3528.8848
790.94238	2.2899168	0.75295782	3538.6042
791.94336	2.2908139	0.75429785	3534.033
792.94434	2.294524	0.75566089	3542.332
793.94531	2.3001304	0.75713927	3546.6384
794.94629	2.3031209	0.75855041	3538.7478
795.94727	2.3059483	0.75995886	3544.6235
796.94824	2.308516	0.76140207	3541.2605
797.94922	2.3145237	0.76264381	3546.8904
798.9502	2.3147357	0.76401287	3536.9258
799.95117	2.3204732	0.76523823	3546.5942
800.95215	2.3202012	0.76679707	3551.3335
801.95313	2.3236291	0.76818818	3544.1152
802.9541	2.3288517	0.76964051	3551.6792
803.95508	2.3331461	0.77080977	3541.3066
804.95605	2.3366461	0.77216786	3546.249
805.95703	2.338903	0.77359843	3550.3916
806.95801	2.3402786	0.77511466	3550.0413
807.95898	2.3431292	0.77659315	3551.2629
808.95996	2.3450649	0.77781975	3542.8025
809.96094	2.347831	0.7793951	3553.6968
810.96191	2.3501909	0.78074294	3547.4895
811.96289	2.3550472	0.7820912	3551.7444
812.96387	2.3558855	0.78340292	3542.3318
813.96484	2.3581336	0.78457844	3552.8481
814.96582	2.3643484	0.78611845	3560.0759
815.9668	2.3647931	0.78782672	3551.3535
816.96777	2.3716135	0.789469	3554.188
817.96875	2.3727689	0.79073286	3554.3052
818.96973	2.376123	0.79221827	3553.3154
819.9707	2.3784807	0.79370785	3550.8364
820.97168	2.3812048	0.79500335	3550.2307
821.97266	2.3838608	0.79640502	3554.2463
822.97363	2.385926	0.79776645	3555.2671
823.97461	2.3925352	0.79918396	3555.335
824.97559	2.3893979	0.80040151	3551.5088
825.97656	2.3950467	0.80191737	3556.0251
826.97754	2.3988199	0.80354434	3560.6565
827.97852	2.4014585	0.80484021	3559.0938
828.97949	2.4039686	0.80636412	3556.5959
829.98047	2.409636	0.80774218	3552.7712
830.98145	2.4124608	0.80903405	3552.0459
831.98242	2.4153135	0.81038237	3559.4563
832.9834	2.4161124	0.81178266	3562.6458
833.98438	2.4180844	0.8134945	3558.8696
834.98535	2.4222481	0.81509578	3561.8411
835.98633	2.4271133	0.81665432	3565.1301
836.9873	2.4288924	0.81810302	3562.7017
837.98828	2.4308565	0.819776	3556.1475
838.98926	2.4326677	0.82094902	3556.2854
839.99023	2.4380627	0.82242209	3565.0127
840.99121	2.4422646	0.82374954	3551.8037
841.99219	2.4443939	0.82497054	3563.6067
842.99316	2.4474032	0.82654214	3566.7998
843.99414	2.4515786	0.82840395	3568.104
844.99512	2.4547694	0.82994211	3562.2761
845.99609	2.4576349	0.83140564	3563.9675
846.99707	2.4620647	0.83279622	3563.0894
847.99805	2.4609067	0.83428645	3562.6404
848.99902	2.4670529	0.8355639	3563.3879
850	2.4678636	0.83700669	3562.5374
851.00098	2.4731729	0.83856225	3570.4824
852.00195	2.4726341	0.84027672	3563.9419
853.00293	2.477608	0.841524	3561.4978
854.00391	2.4818766	0.84297323	3567.7432
855.00488	2.4811916	0.84460956	3569.1238
856.00586	2.4868264	0.84619516	3570.519
857.00684	2.4891362	0.84795904	3564.2947
858.00781	2.4945354	0.84933072	3572.7954
859.00879	2.494549	0.8507306	3562.884
860.00977	2.4991088	0.85197163	3563.0264
861.01074	2.5026407	0.85342813	3569.0625
862.01172	2.5022488	0.85505921	3567.8066
863.0127	2.5053411	0.85643506	3570.4841
864.01367	2.51282	0.85800308	3569.6138
865.01465	2.5128703	0.85944146	3569.8164
866.01563	2.5148637	0.86102307	3569.2395
867.0166	2.5169051	0.86247569	3574.4409
868.01758	2.5227144	0.86392039	3566.3542
869.01855	2.5247893	0.86530191	3562.4092
870.01953	2.5293052	0.86665279	3572.6609
871.02051	2.5321395	0.86840928	3576.813
872.02148	2.5347502	0.87003672	3576.9958
873.02246	2.5360327	0.8717531	3567.1023
874.02344	2.5393119	0.87301135	3568.4089
875.02441	2.5426757	0.87455547	3571.6118
876.02539	2.546896	0.87644553	3581.8101
877.02637	2.547936	0.8778398	3570.0938
878.02734	2.5498319	0.87936842	3572.6819
879.02832	2.5582292	0.88082916	3575.2751
880.0293	2.5580859	0.88220578	3573.7095
881.03027	2.5611444	0.88362664	3576.1943
882.03125	2.561445	0.88516086	3579.2986
883.03223	2.5672057	0.8866508	3576.3745
884.0332	2.5709994	0.88824379	3577.0276
885.03418	2.5747995	0.88991845	3575.1809
886.03516	2.5748496	0.89145964	3574.3716
887.03613	2.581512	0.8932364	3578.7039
888.03711	2.5822735	0.89448613	3572.8667
889.03809	2.5827439	0.89624238	3572.4141
890.03906	2.5882797	0.89791149	3578.5449
891.04004	2.5925045	0.8996352	3582.011
892.04102	2.5948625	0.90131962	3574.0764
893.04199	2.5956745	0.9027701	3577.7539
894.04297	2.6003387	0.90435243	3578.4141
895.04395	2.6033382	0.90582478	3581.0735
896.04492	2.6082885	0.9074114	3577.6646
897.0459	2.6108346	0.90882415	3575.0176
898.04688	2.6131463	0.91030043	3580.6609
899.04785	2.615355	0.91222727	3582.564
900.04883	2.6188705	0.91399133	3577.6243
901.0498	2.6236842	0.91540587	3584.4111
902.05078	2.6241276	0.91680348	3579.3123
903.05176	2.6257684	0.91851276	3577.9905
904.05273	2.6314099	0.92010427	3579.8215
905.05371	2.6322157	0.92155033	3578.5857
906.05469	2.6385064	0.92311049	3587.1885
907.05566	2.6381633	0.9246797	3582.1409
908.05664	2.6426413	0.92650104	3582.2134
909.05762	2.6480429	0.92813259	3587.2124
910.05859	2.6488433	0.92990237	3581.5718
911.05957	2.6540928	0.9317655	3588.3306
912.06055	2.6539495	0.93339348	3585.2471
913.06152	2.6586454	0.93482757	3574.5327
914.0625	2.6616027	0.93623304	3578.1633
915.06348	2.6662898	0.9377768	3584.3213
916.06445	2.6648619	0.9392094	3582.3789
917.06543	2.6681132	0.94090295	3585.825
918.06641	2.6736522	0.9426719	3585.6372
919.06738	2.6741056	0.94443327	3586.2715
920.06836	2.6771324	0.94619149	3583.4204
921.06934	2.6802943	0.9479031	3584.3618
922.07031	2.6853511	0.9498207	3588.8533
923.07129	2.6878321	0.95145792	3592.8645
924.07227	2.6907518	0.95332986	3590.2881
925.07324	2.6923585	0.95494062	3582.3374
926.07422	2.6999097	0.95650721	3586.4739
927.0752	2.6991527	0.95812511	3584.7759
928.07617	2.7014353	0.9596566	3581.7444
929.07715	2.7057672	0.96137142	3586.4976
930.07813	2.7091649	0.96315145	3589.5076
931.0791	2.7127235	0.96501738	3590.3591
932.08008	2.7171257	0.96676302	3582.7751
933.08105	2.7193573	0.96830201	3589.5417
934.08203	2.7216275	0.96995884	3591.6174
935.08301	2.7246199	0.97188556	3589.4504
936.08398	2.7246656	0.97365099	3586.4231
937.08496	2.7294784	0.97559553	3593.6946
938.08594	2.7341335	0.97736377	3588.9949
939.08691	2.7371237	0.97906929	3583.9063
940.08789	2.7409704	0.98055279	3586.8923
941.08887	2.7421806	0.98201454	3582.9624
942.08984	2.7443123	0.98359007	3586.4282
943.09082	2.7496698	0.98534495	3591.2166
944.0918	2.7512574	0.98697591	3594.2917
945.09277	2.7543762	0.9885214	3584.3689
946.09375	2.7554762	0.99022126	3587.4031
947.09473	2.7571847	0.99192321	3591.6628
948.0957	2.7640719	0.99401474	3598.0334
949.09668	2.7646682	0.99604219	3593.4158
950.09766	2.7716122	0.99810898	3591.8608
951.09863	2.7714043	0.99983758	3590.1543
952.09961	2.7746079	1.0014611	3582.8225
953.10059	2.7792099	1.0031444	3596.8992
954.10156	2.7808542	1.0047828	3592.9053
955.10254	2.7840099	1.0066254	3596.3337
956.10352	2.7852149	1.0082201	3585.9221
957.10449	2.7896209	1.0096574	3583.8435
958.10547	2.7904627	1.0115454	3598.4119
959.10645	2.7939169	1.013835	3592.8955
960.10742	2.7996595	1.0161035	3597.9419
961.1084	2.8025331	1.0182234	3591.7878
962.10938	2.8026907	1.0198598	3587.7637
963.11035	2.8053291	1.0215641	3589.9956
964.11133	2.8075631	1.0233601	3584.6506
965.1123	2.815403	1.025144	3592.7273
966.11328	2.8133266	1.0268744	3585.7798
967.11426	2.8202398	1.0285897	3588.7544
968.11523	2.8211529	1.0300808	3591.4165
969.11621	2.8276784	1.0318102	3589.7759
970.11719	2.8294349	1.0335987	3598.0513
971.11816	2.8302603	1.0355204	3588.6289
972.11914	2.8358397	1.0372655	3595.3599
973.12012	2.8377893	1.0391772	3596.6018
974.12109	2.8413889	1.0408692	3588.8
975.12207	2.8435681	1.0426009	3590.3013
976.12305	2.8449802	1.0445743	3596.3018
977.12402	2.8495431	1.0462888	3590.9775
978.125	2.8528943	1.0484328	3597.061
979.12598	2.8544629	1.0503082	3590.6599
980.12695	2.8613491	1.0522141	3594.9802
981.12793	2.863764	1.0541003	3598.2634
982.12891	2.8636396	1.0558307	3587.7729
983.12988	2.8671043	1.0578352	3593.8206
984.13086	2.8726425	1.0597311	3595.0991
985.13184	2.8739319	1.0619957	3597.0447
986.13281	2.8748634	1.0638524	3592.7288
987.13379	2.8802614	1.0660193	3599.6584
988.13477	2.8822343	1.0678966	3587.1204
989.13574	2.8858411	1.0696714	3588.2717
990.13672	2.8890646	1.0717512	3592.3977
991.1377	2.8930557	1.0735857	3587.9817
992.13867	2.8939123	1.0753638	3595.2512
993.13965	2.8998306	1.0771194	3595.3101
994.14063	2.9005322	1.079007	3593.5212
995.1416	2.9033189	1.0811551	3597.5024
996.14258	2.9064426	1.0833312	3597.9104
997.14355	2.9093499	1.0855061	3595.7568
998.14453	2.9117904	1.0876669	3595.0876
999.14551	2.9152181	1.0901285	3597.5725
1000.1465	2.9189134	1.0923433	3588.5615
1001.1475	2.9213181	1.0944232	3589.0847
1002.1484	2.9232767	1.0961179	3588.2134
1003.1494	2.9249856	1.0976915	3587.9421
1004.1504	2.9329617	1.0995126	3591.9919
1005.1514	2.9327371	1.1013712	3589.2473
1006.1523	2.9375882	1.103395	3595.615
1007.1533	2.9420831	1.1054562	3598.2417
1008.1543	2.9434228	1.1075091	3588.1575
1009.1553	2.9466906	1.109269	3588.2053
1010.1563	2.9465935	1.1109785	3592.6592
1011.1572	2.9536455	1.1130587	3598.8562
1012.1582	2.9526327	1.1150994	3590.1584
1013.1592	2.9583423	1.1171155	3593.5142
1014.1602	2.9591467	1.1191356	3587.2214
1015.1611	2.9613388	1.1213584	3590.106
1016.1621	2.9674985	1.1234373	3593.1899
1017.1631	2.9665878	1.1254538	3587.9099
1018.1641	2.9731135	1.127593	3587.397
1019.165	2.9768372	1.1297451	3589.8357
1020.166	2.977253	1.1316489	3585.2913
1021.167	2.9839933	1.133389	3591.9685
1022.168	2.9870317	1.13548	3586.9976
1023.1689	2.9889987	1.1373426	3586.6179
1024.1699	2.9882987	1.1390159	3586.6665
1025.1709	2.9898782	1.1405202	3580.7695
1026.1719	2.9967985	1.1421921	3585.96
1027.1729	2.9980571	1.1440256	3591.239
1028.1738	3.0048358	1.1456174	3593.374
1029.1748	3.0033324	1.1474961	3592.2397
1030.1758	3.007983	1.1497864	3597.4541
1031.1768	3.0110166	1.1522105	3595.5337
1032.1777	3.0156024	1.1547922	3594.2627
1033.1787	3.0178745	1.1571969	3594.7375
1034.1797	3.0188546	1.1597735	3590.3689
1035.1807	3.0205917	1.1621032	3592.4495
1036.1816	3.0252843	1.1647757	3587.0234
1037.1826	3.0297639	1.1669214	3590.7832
1038.1836	3.0331905	1.1692073	3591.228
1039.1846	3.0346067	1.1714048	3582.2781
1040.1855	3.0404449	1.1732159	3585.968
1041.1865	3.0428784	1.175468	3589.2656
1042.1875	3.0449598	1.17781	3591.771
1043.1885	3.0497942	1.1801045	3590.1235
1044.1895	3.0518017	1.1825079	3590.7769
1045.1904	3.0532832	1.1845642	3588.5913
1046.1914	3.0553145	1.1865702	3578.5864
1047.1924	3.0589185	1.1883427	3584.8955
1048.1934	3.0634966	1.1902719	3585.3479
1049.1943	3.066576	1.1924021	3594.0789
1050.1953	3.0676365	1.1946093	3585.9863
1051.1963	3.0728548	1.1967779	3584.5488
1052.1973	3.0742917	1.1992987	3590.8145
1053.1982	3.0762875	1.2020569	3589.7185
1054.1992	3.0815408	1.2049116	3586.6868
1055.2002	3.0823939	1.2073437	3578.8533
1056.2012	3.0884826	1.2095102	3580.0935
1057.2021	3.0902948	1.2113245	3579.8401
1058.2031	3.0906112	1.2134924	3582.5769
1059.2041	3.0970635	1.2156444	3586.1946
1060.2051	3.0965965	1.2178481	3582.0249
1061.2061	3.1012068	1.2199546	3582.7017
1062.207	3.1039491	1.2225238	3586.1252
1063.208	3.109776	1.2249227	3583.2993
1064.209	3.1106594	1.2268015	3574.646
1065.21	3.1138756	1.2289934	3579.2944
1066.2109	3.1159604	1.2313344	3587.8586
1067.2119	3.1193264	1.2344611	3582.4829
1068.2129	3.1225133	1.2372694	3581.7688
1069.2139	3.1263878	1.2398587	3578.9517
1070.2148	3.1281073	1.2421178	3578.7231
1071.2158	3.1319664	1.2448174	3579.9941
1072.2168	3.1342103	1.2473332	3576.7175
1073.2178	3.1382973	1.2497369	3583.6448
1074.2188	3.1442494	1.2523026	3581.0259
1075.2197	3.1430585	1.2546935	3575.2617
1076.2207	3.1468503	1.2570752	3576.771
1077.2217	3.1500111	1.2591853	3580.6689
1078.2227	3.1505313	1.2618151	3574.0549
1079.2236	3.1542637	1.2646493	3578.2195
1080.2246	3.1609762	1.2673984	3580.9272
1081.2256	3.1613553	1.2699014	3572.7605
1082.2266	3.165031	1.2719114	3565.8223
1083.2275	3.166853	1.274441	3576.6797
1084.2285	3.1682444	1.2769382	3566.9963
1085.2295	3.176095	1.2793959	3569.1318
1086.2305	3.1785374	1.2815284	3566.821
1087.2314	3.1776006	1.2836759	3569.8291
1088.2324	3.1848993	1.2860707	3570.4031
1089.2334	3.1833558	1.2883016	3568.5952
1090.2344	3.1902089	1.2912129	3572.3047
1091.2354	3.1907063	1.2940639	3570.0618
1092.2363	3.1951256	1.2962704	3560.3125
1093.2373	3.1976163	1.2987424	3569.2034
1094.2383	3.20033	1.301506	3570.5461
1095.2393	3.2047992	1.3045087	3566.561
1096.2402	3.2097411	1.3073466	3563.9031
1097.2412	3.2097409	1.3093884	3558.1545
1098.2422	3.2119398	1.3115673	3563.5537
1099.2432	3.2145545	1.3139639	3563.8418
1100.2441	3.2186699	1.3165767	3563.5833
1101.2451	3.2233565	1.3192164	3562.5498
1102.2461	3.2250407	1.321905	3561.2375
1103.2471	3.2304387	1.3247403	3564.7957
1104.248	3.232646	1.3278061	3560.3499
1105.249	3.2333362	1.3311625	3556.4978
1106.25	3.238869	1.3337492	3556.99
1107.251	3.2400129	1.3366721	3560.1599
1108.252	3.2425351	1.3392385	3551.8899
1109.2529	3.2474215	1.3417871	3549.8198
1110.2539	3.2486436	1.3441848	3552.5444
1111.2549	3.2527478	1.346611	3551.054
1112.2559	3.2535594	1.3490025	3552.1289
1113.2568	3.2584164	1.3515871	3549.2666
1114.2578	3.261714	1.3540757	3548.1223
1115.2588	3.2651448	1.3568263	3552.3286
1116.2598	3.262841	1.3599702	3550.2993
1117.2607	3.2708399	1.3634585	3545.7488
1118.2617	3.2725768	1.3662428	3543.2998
1119.2627	3.2754114	1.3691423	3544.8914
1120.2637	3.2778106	1.3723184	3543.4734
1121.2646	3.2841351	1.3755456	3538.8284
1122.2656	3.2865298	1.3778845	3539.291
1123.2666	3.288655	1.3803493	3530.7813
1124.2676	3.2896695	1.38272	3535.6201
1125.2686	3.2916803	1.3849059	3533.144
1126.2695	3.2973676	1.387463	3537.4873
1127.2705	3.3004384	1.3898535	3531.8364
1128.2715	3.303899	1.3927183	3541.855
1129.2725	3.3078113	1.3958076	3536.9172
1130.2734	3.308815	1.3987627	3526.4878
1131.2744	3.3153389	1.4018503	3542.6211
1132.2754	3.3156929	1.4045784	3530.5938
1133.2764	3.3179276	1.4072841	3525.8655
1134.2773	3.3224165	1.4100504	3530.52
1135.2783	3.3250065	1.4132758	3530.5232
1136.2793	3.3259983	1.4167162	3520.8154
1137.2803	3.3307047	1.4192671	3516.6147
1138.2813	3.33656	1.4217223	3521.5459
1139.2822	3.335211	1.424256	3519.5977
1140.2832	3.3404074	1.4271499	3516.3223
1141.2842	3.3421161	1.4302576	3520.6436
1142.2852	3.346705	1.4333947	3516.7388
1143.2861	3.3463478	1.436519	3510.1565
1144.2871	3.3507566	1.4398474	3510.9167
1145.2881	3.3532424	1.4427392	3507.0454
1146.2891	3.3574004	1.4454309	3505.7483
1147.29	3.360631	1.4486144	3509.7292
1148.291	3.3652976	1.4514151	3504.8979
1149.292	3.3671756	1.454073	3500.5713
1150.293	3.3696079	1.4569063	3494.8696
1151.2939	3.373688	1.4597265	3504.0154
1152.2949	3.3737662	1.4624407	3496.979
1153.2959	3.3782783	1.4649071	3491.4802
1154.2969	3.3821425	1.4671935	3490.3037
1155.2979	3.3865218	1.469644	3493.8442
1156.2988	3.3855908	1.4724075	3489.9749
1157.2998	3.3900075	1.475018	3484.2053
1158.3008	3.3923757	1.4778568	3484.4604
1159.3018	3.3976743	1.4812342	3488.0532
1160.3027	3.3984902	1.4841745	3481.5652
1161.3037	3.3998191	1.4870937	3482.54
1162.3047	3.4058778	1.4900566	3474.9463
1163.3057	3.4103801	1.4929745	3481.4285
1164.3066	3.4131362	1.496009	3477.5339
1165.3076	3.4130657	1.4993471	3472.9038
1166.3086	3.4178183	1.5028044	3470.8206
1167.3096	3.426415	1.5054787	3465.3149
1168.3105	3.4232464	1.5084755	3468.1858
1169.3115	3.4254456	1.5114473	3461.3438
1170.3125	3.4300199	1.5145578	3460.3394
1171.3135	3.4327333	1.517755	3463.418
1172.3145	3.4375031	1.5207884	3455.8235
1173.3154	3.4374707	1.5239916	3462.4243
1174.3164	3.4401042	1.5275757	3451.5515
1175.3174	3.4433737	1.5312009	3451.8357
1176.3184	3.4482481	1.5354072	3460.1313
1177.3193	3.4496703	1.5385852	3441.1206
1178.3203	3.4525194	1.5416478	3438.2568
1179.3213	3.4564302	1.5446293	3439.1145
1180.3223	3.4586911	1.5476539	3431.7275
1181.3232	3.4627538	1.5501379	3430.4922
1182.3242	3.4619255	1.5527407	3425.8101
1183.3252	3.4667192	1.5553875	3428.1462
1184.3262	3.4724383	1.5584165	3428.8218
1185.3271	3.4764142	1.5620525	3427.5215
1186.3281	3.48015	1.5651352	3421.4087
1187.3291	3.4820254	1.5681248	3416.0591
1188.3301	3.4839866	1.5706489	3416.1196
1189.3311	3.4838569	1.5735759	3415.9077
1190.332	3.4911671	1.5765887	3415.3562
1191.333	3.4931774	1.5800314	3403.5164
1192.334	3.4931614	1.5829433	3401.0657
1193.335	3.4991012	1.5857112	3404.4304
1194.3359	3.4995518	1.5890325	3399.6624
1195.3369	3.5047653	1.5926213	3397.1792
1196.3379	3.508425	1.5957491	3390.8506
1197.3389	3.5130799	1.598703	3389.9106
1198.3398	3.5147913	1.6021479	3391.5527
1199.3408	3.5158746	1.6055702	3381.1775
1200.3418	3.521687	1.6082474	3376.3188
1201.3428	3.5215781	1.6114283	3381.5107
1202.3438	3.5265045	1.6145965	3371.6301
1203.3447	3.5272071	1.6176838	3368.2031
1204.3457	3.5343294	1.6206003	3365.8174
1205.3467	3.5339503	1.6234607	3357.7556
1206.3477	3.5372248	1.6263562	3360.1963
1207.3486	3.541585	1.6300119	3358.7749
1208.3496	3.5465486	1.6333045	3353.8718
1209.3506	3.5458694	1.6363846	3344.8606
1210.3516	3.5495088	1.639693	3346.3882
1211.3525	3.5529449	1.6431311	3331.8103
1212.3535	3.5578072	1.6463232	3336.4934
1213.3545	3.5568612	1.6494842	3336.958
1214.3555	3.5620599	1.6527299	3327.2039
1215.3564	3.5662982	1.6557899	3322.5632
1216.3574	3.5675466	1.659276	3326.0718
1217.3584	3.5699501	1.6631093	3314.6326
1218.3594	3.5735571	1.6661817	3312.4063
1219.3604	3.5784712	1.669613	3308.2871
1220.3613	3.5789886	1.6729442	3303.6516
1221.3623	3.582984	1.6765593	3300.426
1222.3633	3.5865977	1.6799747	3293.3416
1223.3643	3.5853207	1.683211	3289.4565
1224.3652	3.5896595	1.6869781	3288.488
1225.3662	3.5969644	1.6910586	3283.4463
1226.3672	3.5959685	1.695085	3271.4524
1227.3682	3.6017096	1.6981477	3265.8914
1228.3691	3.6020298	1.7011828	3255.4397
1229.3701	3.6072147	1.7038331	3251.4897
1230.3711	3.6086285	1.7069843	3254.4153
1231.3721	3.6144848	1.7108274	3252.1975
1232.373	3.6156881	1.7144138	3236.7644
1233.374	3.618171	1.7183167	3236.4043
1234.375	3.6197395	1.7224336	3226.6345
1235.376	3.622906	1.7260964	3220.4404
1236.377	3.627131	1.7295413	3207.4927
1237.3779	3.6302991	1.732432	3200.4004
1238.3789	3.6324859	1.7361519	3197.207
1239.3799	3.6356144	1.7402711	3192.4324
1240.3809	3.6402595	1.7453239	3171.873
1241.3818	3.6422005	1.7502903	3152.1111
1242.3828	3.6482179	1.7591141	3081.377
1243.3838	3.6520269	1.7657356	3034.6172
1244.0845	3.6542535	1.7759776	2957.4885