File: datasets/am_bench_2022/raw_data/45-XY.08-4/specimen.dat
MTS793|MPT|ENU|1|2|.|/|:|1|0|0|A

Operator Information						Time:	30.061035	Sec	10/19/2021 2:21:04 PM
Operator	Newell Moser
Project	AM Bench 2022 mini-tensile challenge
Specimen ID	45-XY.08-4
Material	PBF-L Inconel 625
Specimen Width	2.55	mm
Specimen Thickness	1.52	mm
Notes
Operator Information End

Data Acquisition						Time:	1031.0552	Sec	10/19/2021 2:37:45 PM
Time	Axial Displacement	Axial Extensometer	Axial Force
Sec	mm	mm	N
30.175049	-0.0019170159	0.00011898013	52.845676
31.176025	0.0019412859	0.00012341398	66.665245
32.177002	0.0022441146	0.00021450747	80.228111
33.177979	0.0054374943	0.00029319688	98.043404
34.178955	0.0075074565	0.00039461689	110.23798
35.179932	0.013853903	0.00040702918	127.29479
36.180908	0.012115403	0.00048222722	136.07484
37.181885	0.01759598	0.00054206664	150.10938
38.182861	0.022357799	0.00064517499	170.07529
39.183838	0.024075555	0.00063574588	184.40718
40.184814	0.02816272	0.00075251632	204.53577
41.185791	0.030018622	0.00082822249	218.95567
42.186768	0.034316108	0.00077294704	235.05406
43.187744	0.036600437	0.00089781883	259.09753
44.188721	0.038279876	0.00096099492	274.39664
45.189697	0.042862672	0.0011075228	296.9133
46.190674	0.044294193	0.0011128909	311.20758
47.19165	0.049870867	0.0011846222	340.6937
48.192627	0.051389467	0.0012583286	361.25732
49.193604	0.055335667	0.0013074072	381.16949
50.19458	0.054661985	0.0013614574	397.93658
51.195557	0.060003236	0.0014594435	415.70108
52.196533	0.062728852	0.0016099461	439.34552
53.19751	0.064498648	0.001721459	465.26709
54.198486	0.068041213	0.0019187055	493.71814
55.199463	0.071929172	0.0018498786	510.30118
56.200439	0.075406529	0.0020363119	534.58765
57.201416	0.076030836	0.0020655366	549.43085
58.202393	0.079033665	0.0021391856	578.11133
59.203369	0.083169185	0.0022080985	598.28143
60.204346	0.08567474	0.0023408865	625.69495
61.205322	0.088164113	0.0024556243	647.13452
62.206299	0.090116523	0.0024745357	677.77808
63.207275	0.094335794	0.0026805014	703.435
64.208252	0.097958624	0.0029034945	742.58649
65.209229	0.103305	0.0028696505	764.19012
66.210205	0.10464513	0.0030437373	797.75964
67.211182	0.10511987	0.0031284289	824.94635
68.212158	0.1120519	0.0033097973	857.35693
69.213135	0.11071421	0.0033073428	878.45642
70.214111	0.11392603	0.0034925817	911.70581
71.215088	0.11850688	0.0035754601	932.26563
72.216064	0.12197199	0.0037582032	970.43274
73.217041	0.12205129	0.0038645407	994.17102
74.218018	0.1276464	0.004019096	1028.0587
75.218994	0.12940533	0.0039773937	1051.5254
76.219971	0.13499717	0.004248736	1089.9076
77.220947	0.13277574	0.0043627154	1118.249
78.221924	0.13844113	0.0045040473	1148.6949
79.2229	0.1448115	0.0044983514	1173.6633
80.223877	0.14873742	0.0046983846	1198.2803
81.224854	0.14910765	0.0047590802	1221.9259
82.22583	0.14898308	0.0048833294	1250.9629
83.226807	0.15475415	0.0050444249	1285.6791
84.227783	0.15964606	0.0051737754	1309.9025
85.22876	0.1615956	0.005301564	1339.5944
86.229736	0.16423255	0.0054595992	1373.0599
87.230713	0.16809551	0.005519697	1400.6749
88.231689	0.17150889	0.0057129646	1421.7915
89.232666	0.17518771	0.0057317847	1442.5349
90.233643	0.17492954	0.0058689611	1469.6124
91.234619	0.177772	0.0059940638	1498.3878
92.235596	0.1831089	0.0060586976	1524.712
93.236572	0.18246575	0.0062065204	1558.6714
94.237549	0.18837598	0.0063072229	1577.4459
95.238525	0.18971904	0.0063652145	1609.9491
96.239502	0.19510388	0.0066943881	1640.9958
97.240479	0.19891481	0.0066892821	1670.5457
98.241455	0.1997485	0.0068886145	1696.2042
99.242432	0.20168759	0.0069959559	1719.9106
100.24341	0.20699176	0.007126655	1750.1921
101.24438	0.20975794	0.0072239432	1778.563
102.24536	0.21300602	0.0073692878	1808.2046
103.24634	0.21421406	0.0074796318	1831.3574
104.24731	0.21945758	0.0075127091	1850.1459
105.24829	0.21999255	0.0077253925	1877.3948
106.24927	0.22679831	0.0077426359	1901.8937
107.25024	0.22511047	0.0078694867	1932.2279
108.25122	0.23068796	0.008036253	1949.7599
109.2522	0.23484023	0.0081447512	1981.7535
110.25317	0.23573515	0.0081980787	2001.9656
111.25415	0.2386511	0.008337169	2034.6649
112.25513	0.24023122	0.0084141344	2046.7164
113.2561	0.24384058	0.0085188728	2065.2207
114.25708	0.25024045	0.0086390851	2092.1079
115.25806	0.2529712	0.0086427694	2107.7107
116.25903	0.2509084	0.0086941421	2127.8608
117.26001	0.25648344	0.0088348147	2148.4429
118.26099	0.25923219	0.0088406457	2160.043
119.26196	0.26199228	0.0089637591	2179.7197
120.26294	0.2650494	0.0090502473	2209.343
121.26392	0.27272063	0.0090989117	2223.0735
122.26489	0.27221763	0.0092227431	2231.7334
123.26587	0.27370799	0.0093142912	2254.6265
124.26685	0.27909529	0.0094905989	2266.5215
125.26782	0.28144887	0.0095157176	2282.5405
126.2688	0.28527173	0.0095504709	2295.427
127.26978	0.29239112	0.0097211674	2309.3184
128.27075	0.28992841	0.0098325033	2327.5432
129.27173	0.29567021	0.0098712519	2344.1721
130.27271	0.29642051	0.010057173	2353.9377
131.27368	0.30029577	0.010041171	2367.8374
132.27466	0.3036418	0.010120704	2377.3994
133.27563	0.30769572	0.010237725	2395.5542
134.27661	0.31067669	0.010303239	2410.1335
135.27759	0.31324393	0.010327597	2419.1199
136.27856	0.31399053	0.010433638	2422.9456
137.27954	0.31926903	0.010517455	2438.2498
138.28052	0.32170889	0.010674137	2461.0994
139.28149	0.32416409	0.010832976	2469.6064
140.28247	0.32479209	0.010759449	2469.7942
141.28345	0.33107722	0.010952454	2486.5044
142.28442	0.33302343	0.010986875	2500.812
143.2854	0.34005523	0.011211195	2518.1274
144.28638	0.33918408	0.011266728	2521.8767
145.28735	0.34413087	0.011247648	2530.0476
146.28833	0.34522375	0.011443595	2540.8279
147.28931	0.34768751	0.011570811	2554.239
148.29028	0.35285789	0.011619125	2565.9016
149.29126	0.35435197	0.011784354	2576.8884
150.29224	0.35677618	0.011905559	2584.2039
151.29321	0.36059549	0.011982793	2588.2715
152.29419	0.36329123	0.012198832	2606.4177
153.29517	0.36662129	0.012241933	2602.5178
154.29614	0.36928016	0.012459529	2623.7007
155.29712	0.37303755	0.012634786	2633.5574
156.2981	0.37646803	0.012696803	2636.1809
157.29907	0.37984583	0.012776135	2642.575
158.30005	0.38028142	0.01298964	2650.9653
159.30103	0.38706568	0.013135259	2664.5996
160.302	0.39094403	0.013338062	2665.8572
161.30298	0.39223936	0.013439064	2681.8333
162.30396	0.3931599	0.013678263	2684.2742
163.30493	0.39519468	0.013831852	2687.9658
164.30591	0.39882281	0.013989567	2693.5029
165.30688	0.40345454	0.014170267	2711.425
166.30786	0.40741235	0.014447231	2711.373
167.30884	0.40769061	0.014600565	2718.3567
168.30981	0.41308594	0.014854074	2727.4436
169.31079	0.41587058	0.015108149	2735.7192
170.31177	0.41655654	0.015391657	2742.1492
171.31274	0.42173469	0.015668809	2755.9395
172.31372	0.42587367	0.016086334	2768.4863
173.3147	0.42515817	0.016260656	2772.4976
174.31567	0.43247089	0.01675996	2786.5327
175.31665	0.4330999	0.017123096	2795.4678
176.31763	0.43611339	0.017477393	2797.1987
177.3186	0.43662563	0.017727071	2800.2688
178.31958	0.44205636	0.018273026	2805.6316
179.32056	0.4463937	0.018674005	2813.8225
180.32153	0.4477115	0.01908854	2824.8323
181.32251	0.45133904	0.019478485	2827.5339
182.32349	0.45487151	0.019905647	2829.8296
183.32446	0.45349097	0.020418493	2832.467
184.32544	0.45951208	0.020970933	2837.0125
185.32642	0.46383581	0.021515798	2849.0403
186.32739	0.46521062	0.022013484	2849.5967
187.32837	0.46840563	0.022588098	2855.6277
188.32935	0.47168082	0.023091318	2857.4055
189.33032	0.47389686	0.023713263	2866.6042
190.3313	0.47666311	0.02436078	2873.8496
191.33228	0.48028326	0.025092989	2876.0801
192.33325	0.48340413	0.025637636	2878.2773
193.33423	0.48724556	0.026280491	2884.0398
194.33521	0.48853517	0.026985152	2887.9097
195.33618	0.49639302	0.027791429	2899.5769
196.33716	0.49415296	0.02846653	2891.9153
197.33813	0.50009006	0.029157504	2902.8337
198.33911	0.50331008	0.029851228	2904.9602
199.34009	0.50196087	0.030588442	2905.3142
200.34106	0.50706547	0.031258363	2910.387
201.34204	0.51188344	0.032199923	2919.4324
202.34302	0.51565874	0.032935902	2919.3208
203.34399	0.5168221	0.033713527	2923.6877
204.34497	0.51908749	0.034515925	2923.1462
205.34595	0.52058893	0.035182379	2925.6343
206.34692	0.52469224	0.036090385	2939.6306
207.3479	0.52968293	0.037046973	2934.9504
208.34888	0.53320187	0.037989825	2945.1123
209.34985	0.53671962	0.038991041	2947.3987
210.35083	0.53819585	0.039960835	2950.5605
211.35181	0.54455149	0.040893286	2954.1577
212.35278	0.54343855	0.041943684	2953.3157
213.35376	0.54484814	0.042671241	2948.8123
214.35474	0.55210882	0.043594819	2955.9434
215.35571	0.55314887	0.044483483	2958.7351
216.35669	0.55566835	0.045530036	2967.7673
217.35767	0.55950999	0.046457887	2962.7773
218.35864	0.56226307	0.047404122	2965.7646
219.35962	0.5648492	0.048312798	2974.1509
220.3606	0.5688318	0.04953514	2980.9927
221.36157	0.57161808	0.050460741	2971.8794
222.36255	0.57379997	0.051358297	2979.1685
223.36353	0.57293183	0.052272454	2979.2932
224.3645	0.57999092	0.053234592	2983.125
225.36548	0.58425564	0.054168299	2986.6599
226.36646	0.58709025	0.05547424	2994.5657
227.36743	0.59024429	0.056679223	2993.0234
228.36841	0.59214282	0.057796873	2993.1287
229.36938	0.59717774	0.058944903	2997.3169
230.37036	0.5970698	0.059908364	2992.8127
231.37134	0.59996605	0.060653236	2993.6255
232.37231	0.60278654	0.061746866	2999.4033
233.37329	0.61090142	0.062898837	3007.2649
234.37427	0.61135274	0.063903943	3004.1846
235.37524	0.61165452	0.065014943	3009.9497
236.37622	0.6179772	0.066233762	3014.0513
237.3772	0.61809957	0.067243166	3008.457
238.37817	0.62488848	0.068342164	3016.4319
239.37915	0.62757874	0.069580391	3017.7932
240.38013	0.62888318	0.070687018	3020.3472
241.3811	0.6325264	0.071858563	3020.407
242.38208	0.63676447	0.073037557	3025.0676
243.38306	0.6372577	0.0742139	3022.5847
244.38403	0.63981628	0.075273141	3030.0913
245.38501	0.64511698	0.076524615	3029.9429
246.38599	0.64621252	0.07782571	3027.9802
247.38696	0.6499663	0.078950055	3036.8494
248.38794	0.65205061	0.080294326	3040.7805
249.38892	0.65713942	0.081581175	3038.3015
250.38989	0.65919387	0.082653768	3034.9424
251.39087	0.66369939	0.083864741	3046.4937
252.39185	0.66453123	0.084903896	3043.9971
253.39282	0.66705459	0.086080849	3046.6509
254.3938	0.67062908	0.087137513	3048.0879
255.39478	0.67269498	0.08823695	3046.6465
256.39575	0.67657048	0.089382589	3050.6677
257.39673	0.68009245	0.090527102	3063.7959
258.39771	0.68408942	0.091531761	3059.0623
259.39868	0.68396568	0.092963599	3054.353
260.39966	0.68927437	0.093954809	3057.5957
261.40063	0.69101387	0.095160492	3061.2053
262.40161	0.6934551	0.096499309	3063.4971
263.40259	0.69725454	0.097899348	3065.1741
264.40356	0.69960159	0.098993376	3063.4912
265.40454	0.70232844	0.10028955	3067.4907
266.40552	0.70993549	0.10139643	3067.2146
267.40649	0.71236491	0.10240094	3072.7859
268.40747	0.71361166	0.10359737	3072.8699
269.40845	0.71587545	0.10467026	3073.5442
270.40942	0.71738589	0.10592171	3076.9958
271.4104	0.71943969	0.1070108	3071.1267
272.41138	0.724841	0.10812156	3083.2681
273.41235	0.72665673	0.10930832	3082.5327
274.41333	0.73062009	0.11056484	3082.8733
275.41431	0.73564762	0.11160858	3089.522
276.41528	0.73578548	0.11259287	3087.303
277.41626	0.74073362	0.11378694	3089.5002
278.41724	0.7443769	0.11494417	3094.209
279.41821	0.74848741	0.11612195	3085.5378
280.41919	0.74579817	0.11729521	3088.9009
281.42017	0.75322199	0.11868869	3096.4338
282.42114	0.75540096	0.11996192	3097.4265
283.42212	0.75722343	0.12112405	3097.2537
284.4231	0.76083457	0.1223447	3098.1697
285.42407	0.76325387	0.1234903	3101.9827
286.42505	0.76650059	0.12482238	3104.2346
287.42603	0.7701658	0.12600772	3107.3547
288.427	0.77172118	0.12724838	3110.042
289.42798	0.77675194	0.12831596	3106.74
290.42896	0.77875376	0.1293311	3108.4363
291.42993	0.77976465	0.13042828	3108.5613
292.43091	0.7843945	0.13165846	3117.7888
293.43188	0.78630793	0.13291393	3106.8835
294.43286	0.78990823	0.13410012	3109.6401
295.43384	0.79302794	0.13507956	3118.4448
296.43481	0.7951293	0.13637957	3114.2058
297.43579	0.80095482	0.13758999	3124.6858
298.43677	0.80175328	0.13891296	3121.582
299.43774	0.80526978	0.14005196	3121.2219
300.43872	0.81010664	0.14095455	3124.6162
301.4397	0.81226021	0.14198339	3128.5054
302.44067	0.81624871	0.14328285	3130.3201
303.44165	0.81660748	0.14439388	3126.1543
304.44263	0.82357025	0.14548828	3133.1624
305.4436	0.82416159	0.1466189	3135.2139
306.44458	0.82658786	0.14773785	3136.5103
307.44556	0.82970619	0.14891638	3133.9844
308.44653	0.8330369	0.15012877	3133.5254
309.44751	0.83811307	0.15118913	3131.3867
310.44849	0.83802372	0.15239231	3140.1636
311.44946	0.84020025	0.15357368	3138.4001
312.45044	0.84525031	0.15474752	3144.0461
313.45142	0.84840667	0.15591069	3142.7056
314.45239	0.85252798	0.15699035	3143.9517
315.45337	0.85398495	0.15821742	3147.5947
316.45435	0.85641164	0.15936324	3146.9297
317.45532	0.86117309	0.16045009	3149.3589
318.4563	0.86143428	0.16168456	3159.0947
319.45728	0.86319798	0.1629546	3153.7463
320.45825	0.86959708	0.16425492	3149.5
321.45923	0.86988777	0.16562428	3159.4797
322.46021	0.87434149	0.16694881	3157.8208
323.46118	0.87686402	0.16808209	3156.8914
324.46216	0.87981796	0.16911927	3157.4563
325.46313	0.88260996	0.17039317	3157.3035
326.46411	0.88483155	0.17160685	3161.5913
327.46509	0.88997322	0.17276791	3156.1379
328.46606	0.89345324	0.17372018	3166.2749
329.46704	0.89579064	0.17498878	3167.8333
330.46802	0.89852095	0.17611997	3169.866
331.46899	0.89826834	0.17739835	3172.3789
332.46997	0.90396506	0.17867294	3163.2112
333.47095	0.90661818	0.17983949	3172.2505
334.47192	0.91197968	0.18099271	3171.9055
335.4729	0.91451687	0.18206853	3175.1001
336.47388	0.91690069	0.18299957	3173.3115
337.47485	0.91956121	0.18425883	3174.512
338.47583	0.9234938	0.18546404	3181.1838
339.47681	0.92531753	0.18681136	3180.887
340.47778	0.92911065	0.18799503	3183.3081
341.47876	0.93264234	0.18912904	3182.4768
342.47974	0.93542671	0.19032985	3183.9956
343.48071	0.93824452	0.19166391	3188.8286
344.48169	0.93861192	0.19288833	3190.9331
345.48267	0.94287753	0.19424631	3190.2742
346.48364	0.94528723	0.19542417	3186.6301
347.48462	0.95136726	0.19666001	3192.1633
348.4856	0.95305145	0.19777054	3193.6187
349.48657	0.9566381	0.19901741	3194.5737
350.48755	0.95847791	0.20019391	3197.4004
351.48853	0.96070385	0.20124036	3190.2048
352.4895	0.9668749	0.20239897	3199.2051
353.49048	0.96636921	0.20348948	3202.5381
354.49146	0.97060674	0.2046807	3202.6045
355.49243	0.97209257	0.20598423	3201.3308
356.49341	0.97732377	0.20723301	3203.6455
357.49438	0.97953922	0.2084837	3205.5334
358.49536	0.98374522	0.20967738	3210.1077
359.49634	0.98345429	0.21074797	3205.1702
360.49731	0.98489565	0.21187101	3207.4587
361.49829	0.99351555	0.21290463	3209.2263
362.49927	0.99581236	0.21405318	3210.7209
363.50024	0.99784172	0.21533483	3215.0276
364.50122	1.000505	0.21684758	3221.9529
365.5022	1.0032605	0.21814841	3219.3987
366.50317	1.0050893	0.21933711	3214.7085
367.50415	1.0094391	0.22043629	3221.0557
368.50513	1.0134455	0.22179344	3218.8823
369.5061	1.0155275	0.22290021	3225.3818
370.50708	1.01922	0.2241378	3225.6365
371.50806	1.0214831	0.22541435	3222.9583
372.50903	1.0218343	0.22648403	3228.0244
373.51001	1.0275046	0.2274521	3225.9067
374.51099	1.0320313	0.22866598	3227.4963
375.51196	1.0342302	0.22973976	3227.0967
376.51294	1.0383757	0.23087651	3231.7229
377.51392	1.0430478	0.23188959	3235.8025
378.51489	1.0436068	0.23297232	3229.3938
379.51587	1.0419443	0.23386021	3227.645
380.51685	1.0499792	0.23514436	3236.4185
381.51782	1.0528172	0.23630922	3234.9617
382.5188	1.0562135	0.23750578	3239.4773
383.51978	1.0558957	0.23886225	3241.1101
384.52075	1.0601269	0.24012673	3241.021
385.52173	1.0655148	0.24123022	3242.9468
386.52271	1.0683906	0.24258667	3244.8694
387.52368	1.0697222	0.24390116	3249.022
388.52466	1.0732869	0.24509962	3244.5413
389.52563	1.0752276	0.24608557	3244.2671
390.52661	1.077951	0.2473682	3246.6511
391.52759	1.0825951	0.24856563	3248.5574
392.52856	1.0847204	0.24982668	3255.0674
393.52954	1.088641	0.25096303	3252.7056
394.53052	1.0894972	0.2520093	3254.0903
395.53149	1.0969156	0.25315714	3260.9578
396.53247	1.0975332	0.2544114	3262.1938
397.53345	1.1018977	0.25574449	3262.6875
398.53442	1.1051425	0.25704911	3265.2583
399.5354	1.1032568	0.25817302	3254.2283
400.53638	1.1083052	0.25919992	3256.2073
401.53735	1.1132282	0.26040819	3266.8328
402.53833	1.1151212	0.26156473	3262.9414
403.53931	1.1157726	0.26287982	3266.396
404.54028	1.119428	0.26416293	3269.6499
405.54126	1.1253821	0.26547861	3266.6599
406.54224	1.1287756	0.26661086	3270.4395
407.54321	1.1304809	0.26775011	3265.1482
408.54419	1.1328198	0.26855436	3264.0181
409.54517	1.1352943	0.2698164	3278.1177
410.54614	1.1361982	0.27099311	3269.2307
411.54712	1.1391827	0.2720747	3270.0073
412.5481	1.1471148	0.2731739	3271.4136
413.54907	1.1482661	0.27430266	3279.3079
414.55005	1.1501547	0.27534717	3281.1277
415.55103	1.1540471	0.27669662	3283.9788
416.552	1.1568863	0.27786317	3280.7407
417.55298	1.1622144	0.27910224	3282.1843
418.55396	1.1658396	0.28022453	3280.4551
419.55493	1.1673236	0.28133002	3282.5471
420.55591	1.1687324	0.28243905	3284.8738
421.55688	1.1723976	0.28372732	3283.3003
422.55786	1.1745598	0.28487915	3286.5693
423.55884	1.1787645	0.28596357	3286.5691
424.55981	1.1826599	0.28715289	3293.1086
425.56079	1.1844774	0.28852844	3291.3513
426.56177	1.187869	0.28971511	3290.8972
427.56274	1.1910435	0.29107803	3294.0862
428.56372	1.1956898	0.29224187	3294.7642
429.5647	1.1924075	0.29358038	3297.0068
430.56567	1.1996115	0.29478928	3297.9307
431.56665	1.2026925	0.29576182	3293.4983
432.56763	1.2058643	0.29688412	3296.2766
433.5686	1.210216	0.29823914	3303.6646
434.56958	1.2128043	0.29944533	3309.0364
435.57056	1.2129258	0.30072182	3297.873
436.57153	1.2190194	0.30190143	3298.2053
437.57251	1.2193145	0.30292583	3303.6382
438.57349	1.2240623	0.30400485	3300.5781
439.57446	1.2290008	0.30513623	3305.7314
440.57544	1.2308509	0.30629557	3302.4211
441.57642	1.2335911	0.30747086	3307.5205
442.57739	1.2356142	0.30840069	3301.2439
443.57837	1.2372787	0.30950058	3309.3035
444.57935	1.2423472	0.3106204	3315.9839
445.58032	1.2472014	0.31181532	3316.3782
446.5813	1.2452995	0.3130424	3314.8662
447.58228	1.2519799	0.31438676	3315.4146
448.58325	1.252673	0.31542662	3316.0447
449.58423	1.2586017	0.31680667	3323.5864
450.58521	1.2579448	0.31788111	3315.593
451.58618	1.2621807	0.31887001	3312.636
452.58716	1.2660997	0.32001901	3322.5796
453.58813	1.2673593	0.32123733	3327.6047
454.58911	1.2715427	0.3224498	3327.03
455.59009	1.2734493	0.32361725	3328.4216
456.59106	1.2767837	0.32469127	3319.8289
457.59204	1.2795173	0.32584068	3323.6445
458.59302	1.2816362	0.32714039	3324.7163
459.59399	1.2880703	0.3282319	3330.6162
460.59497	1.2918643	0.32939559	3337.564
461.59595	1.2908887	0.33064732	3327.9946
462.59692	1.2945354	0.33210647	3336.5254
463.5979	1.298893	0.33371446	3339.979
464.59888	1.3013248	0.3350766	3333.2664
465.59985	1.3035301	0.3361825	3335.4822
466.60083	1.3079927	0.33745152	3337.9263
467.60181	1.3105128	0.33870092	3338.6182
468.60278	1.3129455	0.33986881	3330.4436
469.60376	1.3172598	0.34088758	3337.8496
470.60474	1.3192149	0.34193709	3339.1296
471.60571	1.3215158	0.34308606	3342.0349
472.60669	1.3272264	0.34402215	3346.0376
473.60767	1.3285482	0.34505501	3345.8823
474.60864	1.3326964	0.34629917	3346.366
475.60962	1.3351673	0.34772462	3347.2808
476.6106	1.3366513	0.34901574	3348.1355
477.61157	1.3390008	0.35012338	3344.1587
478.61255	1.3413701	0.35112515	3343.9995
479.61353	1.3476921	0.35219193	3348.9121
480.6145	1.3494997	0.35339954	3355.2764
481.61548	1.352331	0.35471374	3351.6082
482.61646	1.3549891	0.35591397	3354.9026
483.61743	1.3581479	0.3571482	3357.5774
484.61841	1.3616793	0.35825327	3358.4736
485.61938	1.3668474	0.35959387	3361.4163
486.62036	1.3667109	0.36084327	3354.3457
487.62134	1.3706653	0.36199814	3355.3862
488.62231	1.3748907	0.36319169	3355.4612
489.62329	1.3772262	0.36430252	3362.76
490.62427	1.3773969	0.36532211	3356.4998
491.62524	1.3819832	0.3664799	3359.55
492.62622	1.3870175	0.36768425	3364.2446
493.6272	1.3887203	0.36875477	3366.0359
494.62817	1.391351	0.37015429	3369.7749
495.62915	1.3935572	0.37147385	3369.6523
496.63013	1.3955098	0.37283757	3367.2363
497.6311	1.4041839	0.37404716	3367.1423
498.63208	1.4040896	0.37521064	3374.3904
499.63306	1.4075415	0.37647873	3373.6792
500.63403	1.409623	0.37788466	3366.8909
501.63501	1.411826	0.37898242	3371.0076
502.63599	1.4163239	0.38001758	3375.6797
503.63696	1.4199525	0.38119021	3373.5837
504.63794	1.4228756	0.38256505	3377.6042
505.63892	1.4221522	0.38374239	3374.4094
506.63989	1.4291278	0.38491106	3375.042
507.64087	1.4267173	0.38614163	3375.4778
508.64185	1.4347823	0.38726294	3384.4592
509.64282	1.437048	0.38847753	3380.7178
510.6438	1.4385437	0.38970843	3380.6697
511.64478	1.4440367	0.39083102	3381.3794
512.64575	1.4455564	0.39183483	3386.8662
513.64673	1.4472543	0.39294478	3382.3845
514.64771	1.4531428	0.39402604	3382.4353
515.64868	1.4535434	0.39517194	3389.5247
516.64966	1.4591352	0.39641216	3393.3098
517.65063	1.4585614	0.39748791	3383.1794
518.65161	1.4631717	0.39893162	3398.8352
519.65259	1.4644786	0.4000259	3391.2083
520.65356	1.468967	0.40119544	3387.7896
521.65454	1.4716446	0.4021337	3387.1343
522.65552	1.4757912	0.40329152	3389.7664
523.65649	1.4774315	0.40449229	3397.9395
524.65747	1.4818102	0.40558526	3392.2991
525.65845	1.4833872	0.40700021	3396.6875
526.65942	1.4860783	0.40819126	3400.1616
527.6604	1.4889889	0.40943182	3388.5908
528.66138	1.4940691	0.41053259	3396.5562
529.66235	1.4942528	0.41165167	3400.3103
530.66333	1.5012158	0.41287902	3404.4348
531.66431	1.5006143	0.41396061	3397.0137
532.66528	1.502869	0.41520372	3406.4111
533.66626	1.5082591	0.41668436	3408.0125
534.66724	1.5126965	0.41799664	3407.3474
535.66821	1.5139447	0.41942239	3412.3577
536.66919	1.5173585	0.42083362	3409.0745
537.67017	1.5204164	0.42203537	3407.1101
538.67114	1.5234997	0.42321098	3407.1853
539.67212	1.5273864	0.42446542	3413.2573
540.6731	1.5277702	0.42573601	3407.1831
541.67407	1.5321232	0.4269087	3409.4275
542.67505	1.5360569	0.42819306	3419.3047
543.67603	1.5396519	0.42955136	3414.0254
544.677	1.5428045	0.43065399	3415.5276
545.67798	1.5432377	0.43165278	3404.2104
546.67896	1.5455328	0.43275875	3419.0789
547.67993	1.5515797	0.4338589	3415.3066
548.68091	1.5530461	0.43510151	3418.0034
549.68188	1.5571877	0.43627149	3424.7046
550.68286	1.5596167	0.43741071	3414.0466
551.68384	1.5650223	0.43873498	3416.9973
552.68481	1.5638472	0.44010124	3428.3389
553.68579	1.5729475	0.44160977	3423.3271
554.68677	1.5721706	0.44280159	3424.7061
555.68774	1.5752081	0.44394112	3419.7847
556.68872	1.5762503	0.44520432	3425.6953
557.6897	1.5791347	0.4464052	3430.0759
558.69067	1.5830368	0.4477348	3427.8386
559.69165	1.5870562	0.44884461	3425.8372
560.69263	1.5897683	0.45005766	3426.822
561.6936	1.5924803	0.45097244	3425.4221
562.69458	1.5945383	0.45222211	3425.6064
563.69556	1.5977101	0.45344344	3433.9988
564.69653	1.6011566	0.45474657	3435.3193
565.69751	1.6040016	0.45586598	3427.0913
566.69849	1.6084163	0.45698488	3428.4604
567.69946	1.6096576	0.45804355	3432.2019
568.70044	1.6136948	0.45942751	3438.4004
569.70142	1.6146905	0.46073857	3440.0059
570.70239	1.6200225	0.46192884	3439.2295
571.70337	1.6229444	0.46324605	3434.8918
572.70435	1.6268625	0.46435207	3441.5781
573.70532	1.6282818	0.46541956	3436.541
574.7063	1.6322204	0.46676841	3444.2415
575.70728	1.6323581	0.46803182	3446.2671
576.70825	1.6389965	0.46924055	3444.4504
577.70923	1.6408163	0.47059062	3442.9448
578.71021	1.6428262	0.47181454	3443.5388
579.71118	1.6455113	0.47316447	3448.386
580.71216	1.6504709	0.47447476	3448.0515
581.71313	1.6534789	0.4756757	3446.0732
582.71411	1.6564921	0.47694874	3450.6418
583.71509	1.6588042	0.47822273	3448.1062
584.71606	1.6632624	0.47936419	3454.571
585.71704	1.6647692	0.48055351	3447.3228
586.71802	1.6671668	0.48169306	3447.4187
587.71899	1.6715127	0.4830251	3455.7275
588.71997	1.6757849	0.48419228	3450.9641
589.72095	1.6782328	0.48531654	3455.4578
590.72192	1.6806712	0.4866907	3463.4551
591.7229	1.6828067	0.48780435	3455.333
592.72388	1.6844592	0.48886481	3456.2026
593.72485	1.6905122	0.49012575	3457.0996
594.72583	1.6904089	0.49129528	3453.8501
595.72681	1.6944746	0.49247256	3454.6479
596.72778	1.7005292	0.49361441	3462.5178
597.72876	1.7001404	0.49485052	3466.7695
598.72974	1.7052039	0.49617016	3467.6887
599.73071	1.7034926	0.49742866	3458.7756
600.73169	1.7107481	0.49880081	3467.5837
601.73267	1.7116346	0.5001114	3465.0874
602.73364	1.7149444	0.50154531	3468.2202
603.73462	1.7210109	0.50285244	3469.8145
604.7356	1.7234973	0.50400442	3467.3352
605.73657	1.7277292	0.50510448	3469.4934
606.73755	1.7277317	0.50630933	3469.7385
607.73853	1.7344358	0.50757515	3468.1147
608.7395	1.7332022	0.50867623	3464.418
609.74048	1.7373207	0.50977677	3472.5376
610.74146	1.7373216	0.51123357	3474.9512
611.74243	1.7427233	0.51255745	3469.1406
612.74341	1.7456143	0.51371789	3476.5037
613.74438	1.7487465	0.51510704	3470.8728
614.74536	1.7535167	0.51637524	3477.8506
615.74634	1.7526891	0.5176779	3475.1843
616.74731	1.7589225	0.51899898	3478.6221
617.74829	1.7636045	0.52025002	3478.9966
618.74927	1.7621036	0.52143335	3474.0649
619.75024	1.76762	0.52261233	3478.3059
620.75122	1.7677925	0.52395821	3483.1558
621.7522	1.773246	0.52538413	3481.6438
622.75317	1.774851	0.52672142	3482.9568
623.75415	1.7750908	0.52798957	3482.1785
624.75513	1.7833742	0.52921802	3476.6567
625.7561	1.7839127	0.53036326	3478.5896
626.75708	1.7883568	0.53168768	3487.5405
627.75806	1.7910396	0.53281045	3481.3176
628.75903	1.794489	0.53408456	3485.4307
629.76001	1.7963365	0.5351302	3485.4248
630.76099	1.8017809	0.53648216	3488.3311
631.76196	1.8042079	0.5378018	3490.6892
632.76294	1.8045282	0.53880364	3486.241
633.76392	1.8094035	0.53980005	3487.4199
634.76489	1.8101759	0.54102081	3492.22
635.76587	1.8157641	0.54227072	3491.1155
636.76685	1.8177989	0.54368693	3494.802
637.76782	1.8211186	0.54496098	3493.1921
638.7688	1.8237683	0.54627562	3491.877
639.76978	1.8265929	0.54768848	3496.8674
640.77075	1.8283846	0.54903442	3496.1372
641.77173	1.835026	0.55067658	3495.9419
642.77271	1.8370013	0.5520674	3500.1719
643.77368	1.8392872	0.55329448	3492.5225
644.77466	1.8411994	0.55427229	3491.426
645.77563	1.8467298	0.55548406	3497.2625
646.77661	1.8479792	0.55669147	3497.2717
647.77759	1.8514763	0.55796534	3505.4749
648.77856	1.8538731	0.55918074	3496.5166
649.77954	1.8576756	0.56050104	3504.7844
650.78052	1.8587575	0.56168884	3497.5706
651.78149	1.8631752	0.56295323	3501.1316
652.78247	1.8636156	0.56428009	3497.8264
653.78345	1.8666185	0.56549507	3503.7859
654.78442	1.8707453	0.56678182	3501.8411
655.7854	1.8741461	0.5681265	3502.2024
656.78638	1.8765105	0.56954795	3510.9956
657.78735	1.8803991	0.57103741	3509.5925
658.78833	1.884515	0.57230479	3504.281
659.78931	1.8860798	0.57351905	3506.0808
660.79028	1.8920095	0.57464492	3501.5554
661.79126	1.8937935	0.57572955	3502.907
662.79224	1.8971184	0.57692009	3508.3518
663.79321	1.8995402	0.57802737	3509.9495
664.79419	1.9014575	0.57910329	3505.1023
665.79517	1.9047363	0.58032215	3512.6135
666.79614	1.9072901	0.58170533	3516.3992
667.79712	1.9122722	0.58303845	3516.4138
668.7981	1.9137752	0.58440107	3511.3108
669.79907	1.9176216	0.58578765	3514.8313
670.80005	1.9187874	0.58712989	3515.7183
671.80103	1.9225957	0.58852333	3517.7324
672.802	1.9282938	0.58986157	3516.804
673.80298	1.9302604	0.59113085	3521.0986
674.80396	1.9302667	0.59247321	3517.5186
675.80493	1.9340647	0.59377062	3510.8779
676.80591	1.9387065	0.59504724	3521.7319
677.80688	1.939446	0.59628052	3521.8047
678.80786	1.9437052	0.59766525	3518.1284
679.80884	1.9450845	0.59928602	3524.7217
680.80981	1.9524218	0.60054433	3517.9888
681.81079	1.9548205	0.60170394	3519.0464
682.81177	1.9588941	0.603064	3529.2793
683.81274	1.960058	0.60452884	3526.7705
684.81372	1.9634098	0.60573184	3519.6968
685.8147	1.9643121	0.60696936	3524.7847
686.81567	1.9670006	0.60834801	3523.0132
687.81665	1.9699485	0.6095593	3524.397
688.81763	1.9718394	0.61082393	3522.7551
689.8186	1.9761454	0.61199206	3519.0073
690.81958	1.9821903	0.61312336	3524.3191
691.82056	1.9823266	0.61449403	3527.3777
692.82153	1.9883535	0.61589825	3529.7937
693.82251	1.9881392	0.61722463	3527.9421
694.82349	1.9941424	0.61873788	3535.1643
695.82446	1.9934802	0.61995679	3525.6978
696.82544	1.9998434	0.62111181	3532.8159
697.82642	2.0021157	0.62230456	3527.3127
698.82739	2.0013435	0.62348682	3532.7322
699.82837	2.008786	0.62483221	3539.3955
700.82935	2.0094564	0.62621367	3535.1023
701.83032	2.014842	0.62734652	3533.1504
702.8313	2.0158694	0.628811	3534.2537
703.83228	2.0198281	0.63023359	3536.1941
704.83325	2.0216062	0.63163871	3532.3035
705.83423	2.0229638	0.63283384	3527.4077
706.83521	2.0281343	0.63403541	3539.363
707.83618	2.03233	0.63544667	3538.7852
708.83716	2.0368738	0.63678592	3541.3184
709.83813	2.0355389	0.63821262	3539.4895
710.83911	2.0394368	0.63956589	3542.3701
711.84009	2.0437274	0.64092463	3535.9932
712.84106	2.0449734	0.64213723	3538.6396
713.84204	2.0492136	0.64350444	3543.0068
714.84302	2.0487227	0.64495713	3540.9504
715.84399	2.0551579	0.64632946	3543.51
716.84497	2.0559771	0.64755023	3540.9248
717.84595	2.0611734	0.64887631	3539.1641
718.84692	2.0636592	0.65013552	3543.592
719.8479	2.0666049	0.6516251	3546.5171
720.84888	2.0695446	0.65300101	3545.5774
721.84985	2.0753675	0.65434957	3546.0896
722.85083	2.0757458	0.65571296	3549.9692
723.85181	2.0766397	0.65731597	3547.1343
724.85278	2.0835061	0.65887803	3554.7549
725.85376	2.0860827	0.66019815	3543.0581
726.85474	2.0883174	0.6615051	3549.1992
727.85571	2.0932386	0.66292506	3552.1953
728.85669	2.0958056	0.66440618	3546.897
729.85767	2.0994098	0.66546029	3548.2402
730.85864	2.1008084	0.66671044	3549.2666
731.85962	2.1036904	0.6678775	3544.6821
732.8606	2.1049578	0.66929644	3552.4956
733.86157	2.1077411	0.67091519	3556.3975
734.86255	2.1125927	0.67240971	3555.5417
735.86353	2.1158533	0.67362601	3548.1475
736.8645	2.1180604	0.67511731	3556.9065
737.86548	2.1221411	0.67637414	3553.4307
738.86646	2.1246674	0.67766714	3553.1118
739.86743	2.1284924	0.67876071	3551.6968
740.86841	2.1300709	0.68008155	3557.7722
741.86938	2.1357484	0.68168515	3564.6753
742.87036	2.1388638	0.68311691	3557.4475
743.87134	2.1396282	0.6844154	3551.7236
744.87231	2.1426938	0.68566996	3558.292
745.87329	2.1464691	0.6869936	3557.6274
746.87427	2.146584	0.68824226	3555.5217
747.87524	2.15203	0.68950438	3559.1157
748.87622	2.1525686	0.69115943	3559.0713
749.8772	2.1554103	0.69252038	3559.9607
750.87817	2.1611443	0.69399953	3557.6104
751.87915	2.1629455	0.69546306	3558.6018
752.88013	2.1651828	0.69700468	3564.1133
753.8811	2.1672485	0.69830734	3556.5334
754.88208	2.1710827	0.6994282	3557.2742
755.88306	2.1745901	0.70052606	3556.3574
756.88403	2.1772974	0.7021392	3571.2024
757.88501	2.1814828	0.70381755	3568.7388
758.88599	2.1853631	0.70544642	3567.4221
759.88696	2.1853788	0.70656115	3562.313
760.88794	2.187469	0.70809108	3565.4001
761.88892	2.1956587	0.7095291	3567.1279
762.88989	2.1980727	0.71099907	3571.3892
763.89087	2.1999698	0.71231288	3571.0752
764.89185	2.201354	0.71387732	3571.3967
765.89282	2.2026312	0.71518362	3568.2371
766.8938	2.2079711	0.71683639	3568.1758
767.89478	2.2106495	0.71823114	3568.4812
768.89575	2.215312	0.71944106	3564.0205
769.89673	2.2162211	0.72065794	3568.8457
770.89771	2.2195585	0.72202265	3565.9404
771.89868	2.2217193	0.72340626	3574.179
772.89966	2.2248588	0.72480643	3568.927
773.90063	2.2263584	0.72612977	3564.9919
774.90161	2.230315	0.72753519	3575.2996
775.90259	2.2366199	0.72910136	3576.8455
776.90356	2.2375088	0.73050427	3573.9026
777.90454	2.2417879	0.73175853	3569.1018
778.90552	2.2452428	0.73292023	3571.6694
779.90649	2.2478499	0.73425049	3583.4299
780.90747	2.2507138	0.73578453	3575.5017
781.90845	2.2517657	0.73750985	3576.3462
782.90942	2.2570908	0.73913127	3582.0095
783.9104	2.2586107	0.74081272	3579.0347
784.91138	2.2630203	0.74242699	3583.7646
785.91235	2.2681563	0.74381912	3569.3325
786.91333	2.2707794	0.74509102	3576.5708
787.91431	2.2702978	0.74648184	3577.8921
788.91528	2.2745416	0.74801373	3577.4666
789.91626	2.2772212	0.74948686	3580.7817
790.91724	2.2811952	0.75105667	3580.4463
791.91821	2.2839994	0.75249112	3583.8938
792.91919	2.2865775	0.75386107	3581.9148
793.92017	2.2894166	0.75558794	3582.9436
794.92114	2.2923982	0.75704682	3583.2954
795.92212	2.2951348	0.75849479	3577.1865
796.9231	2.2991219	0.7599653	3580.4163
797.92407	2.2984381	0.76136214	3577.552
798.92505	2.3061864	0.76294076	3585.9397
799.92603	2.3057442	0.76418453	3580.002
800.927	2.310159	0.76554221	3582.1279
801.92798	2.3147388	0.76685101	3583.1052
802.92896	2.3144236	0.76825249	3579.6807
803.92993	2.3180733	0.76959175	3583.8335
804.93091	2.3219314	0.77099729	3582.8726
805.93188	2.3254178	0.77244031	3579.5437
806.93286	2.3272259	0.77374208	3584.0801
807.93384	2.331377	0.77526075	3588.821
808.93481	2.3360364	0.77679658	3589.8618
809.93579	2.3387043	0.77829838	3584.9001
810.93677	2.3392837	0.77993202	3586.3105
811.93774	2.3473949	0.78149867	3585.5925
812.93872	2.3446529	0.78293127	3587.2439
813.9397	2.3487675	0.78472787	3585.645
814.94067	2.3515573	0.78625578	3583.3047
815.94165	2.3540168	0.7877208	3588.3843
816.94263	2.3561075	0.78923345	3586.7749
817.9436	2.3615038	0.79052228	3584.1047
818.94458	2.3626859	0.79211789	3590.7664
819.94556	2.3652189	0.79366195	3588.604
820.94653	2.3712125	0.79522413	3593.4063
821.94751	2.3752165	0.79682279	3594.7432
822.94849	2.376586	0.79840136	3588.9207
823.94946	2.37936	0.79981977	3590.5432
824.95044	2.3789608	0.80119246	3589.3811
825.95142	2.3813384	0.80297625	3593.4241
826.95239	2.3890507	0.80442458	3591.2932
827.95337	2.3914793	0.80569303	3591.0308
828.95435	2.3932569	0.80705172	3586.6404
829.95532	2.3960547	0.80871367	3594.946
830.9563	2.403661	0.81031632	3600.8477
831.95728	2.4012141	0.81197554	3591.6245
832.95825	2.4053774	0.8132773	3587.5051
833.95923	2.4103255	0.81464756	3590.728
834.96021	2.4118681	0.81628805	3595.3584
835.96118	2.4153299	0.81772172	3593.3909
836.96216	2.4188874	0.8193112	3597.9795
837.96313	2.4219115	0.82084084	3597.521
838.96411	2.425447	0.82227355	3599.4312
839.96509	2.4258077	0.82387578	3595.5845
840.96606	2.4282622	0.82554209	3598.1572
841.96704	2.4324586	0.82698578	3590.9287
842.96802	2.4370437	0.82842106	3595.708
843.96899	2.4393728	0.82988071	3594.8398
844.96997	2.4419236	0.83145118	3594.7227
845.97095	2.4453833	0.83311361	3602.0615
846.97192	2.4501426	0.83494431	3600.2358
847.9729	2.4484749	0.83638728	3596.7798
848.97388	2.4502516	0.83798915	3598.8357
849.97485	2.4571884	0.8395983	3592.2217
850.97583	2.4591565	0.8410086	3598.5054
851.97681	2.4655447	0.84262228	3602.3394
852.97778	2.4680021	0.84438628	3605.583
853.97876	2.4695106	0.8462469	3598.4973
854.97974	2.4720097	0.84798121	3601.0798
855.98071	2.4775019	0.84969753	3601.7703
856.98169	2.4793544	0.85112596	3595.1882
857.98267	2.4827352	0.85255778	3601.0459
858.98364	2.4837635	0.8541615	3599.3325
859.98462	2.4917674	0.85553288	3604.8047
860.9856	2.4919424	0.85711706	3600.8699
861.98657	2.4932392	0.85885233	3606.467
862.98755	2.4967196	0.86034316	3601.2358
863.98853	2.5016372	0.8616032	3599.4824
864.9895	2.5032971	0.86315548	3605.7471
865.99048	2.5049863	0.86480141	3606.4746
866.99146	2.5078673	0.86646706	3603.8503
867.99243	2.5088868	0.8681342	3609.0337
868.99341	2.5119028	0.86985868	3606.0737
869.99438	2.5180213	0.87159365	3600.01
870.99536	2.5198853	0.87341011	3603.7822
871.99634	2.5257344	0.87507749	3605.7241
872.99731	2.525085	0.87671912	3607.3882
873.99829	2.5287154	0.8782329	3601.2349
874.99927	2.5347292	0.87981093	3604.6702
876.00024	2.53548	0.88162088	3602.1243
877.00122	2.5390363	0.88309765	3598.2166
878.0022	2.5410814	0.88451695	3597.0952
879.00317	2.5458381	0.88625866	3603.0403
880.00415	2.5509572	0.88760155	3603.6887
881.00513	2.5510206	0.88920689	3605.1584
882.0061	2.5516057	0.89057136	3600.6409
883.00708	2.5539384	0.89226609	3604.165
884.00806	2.5595295	0.8940798	3608.073
885.00903	2.5625279	0.89583302	3613.2583
886.01001	2.5659535	0.89780903	3609.625
887.01099	2.5693517	0.89951694	3606.6445
888.01196	2.5714777	0.90126693	3604.5515
889.01294	2.5748165	0.90277153	3606.8132
890.01392	2.5784109	0.90437311	3605.6116
891.01489	2.5815456	0.90602386	3608.9263
892.01587	2.5827546	0.907664	3606.208
893.01685	2.5859892	0.90937364	3612.2295
894.01782	2.5892007	0.91116607	3610.3057
895.0188	2.5913815	0.91293257	3608.2048
896.01978	2.5946584	0.91468948	3603.9175
897.02075	2.6002283	0.91630512	3612.1794
898.02173	2.6018069	0.91813654	3612.0269
899.02271	2.6061747	0.91982883	3611.4985
900.02368	2.6075397	0.92171806	3607.6731
901.02466	2.6090426	0.92337805	3605.7441
902.02563	2.6134999	0.92519575	3613.8433
903.02661	2.617857	0.92682803	3606.7861
904.02759	2.6192269	0.92834502	3603.9666
905.02856	2.6225243	0.93013692	3604.8208
906.02954	2.6278415	0.93174577	3613.6968
907.03052	2.6283004	0.93370622	3612.3945
908.03149	2.6323273	0.93545419	3607.4673
909.03247	2.6323972	0.93732536	3609.4668
910.03345	2.636338	0.93873775	3599.179
911.03442	2.6407051	0.94018275	3601.9805
912.0354	2.6439824	0.94168788	3604.5376
913.03638	2.6489038	0.94330758	3618.0918
914.03735	2.6506281	0.94532967	3617.7979
915.03833	2.6523576	0.94742763	3610.2019
916.03931	2.6559403	0.94928718	3616.2434
917.04028	2.6583648	0.95109749	3605.5012
918.04126	2.6628435	0.95272994	3614.334
919.04224	2.6669357	0.95457369	3608.8809
920.04321	2.668088	0.95647269	3611.6599
921.04419	2.6724167	0.95836788	3610.0217
922.04517	2.6729205	0.96016312	3610.7009
923.04614	2.6779599	0.9622196	3615.999
924.04712	2.6813295	0.96392912	3614.3618
925.0481	2.6825709	0.96587372	3612.9814
926.04907	2.6861007	0.96759397	3616.7522
927.05005	2.6893969	0.96969432	3618.833
928.05103	2.6939321	0.97174174	3618.5847
929.052	2.6937509	0.97341532	3608.3862
930.05298	2.6967244	0.97509611	3608.7327
931.05396	2.7008955	0.97690099	3611.6914
932.05493	2.7046278	0.97871155	3607.1799
933.05591	2.7059977	0.98055106	3613.426
934.05688	2.7119145	0.98224866	3614.7441
935.05786	2.7107296	0.98413569	3609.4648
936.05884	2.715754	0.9859426	3610.8411
937.05981	2.7179503	0.98763144	3609.5237
938.06079	2.7208416	0.98942709	3610.698
939.06177	2.7265091	0.9914934	3616.4399
940.06274	2.7283418	0.99342126	3613.8542
941.06372	2.7316334	0.99540544	3614.0889
942.0647	2.7342477	0.9976415	3616.8638
943.06567	2.7360232	0.99956751	3602.9648
944.06665	2.7387111	1.0013605	3605.3184
945.06763	2.7414761	1.0031782	3610.6973
946.0686	2.7429368	1.0049049	3601.6797
947.06958	2.7496812	1.0066409	3609.2988
948.07056	2.7511101	1.0085461	3610.1733
949.07153	2.7567589	1.0104356	3614.9497
950.07251	2.7569828	1.0123043	3609.4937
951.07349	2.7620027	1.0143641	3610.1545
952.07446	2.7641344	1.0164664	3614.1606
953.07544	2.7651193	1.0186012	3607.8066
954.07642	2.7714458	1.0205899	3612.9399
955.07739	2.7740848	1.0225438	3608.4866
956.07837	2.7743003	1.0245894	3607.3586
957.07935	2.7788577	1.0265082	3613.3169
958.08032	2.7822974	1.0285103	3617.3926
959.0813	2.7836008	1.030413	3609.3547
960.08228	2.7868953	1.032565	3606.241
961.08325	2.7921648	1.0346754	3608.551
962.08423	2.7931931	1.0365404	3603.5647
963.08521	2.7943945	1.0386524	3611.8984
964.08618	2.7976048	1.0407232	3603.1797
965.08716	2.8029299	1.0427271	3600.9648
966.08813	2.8071251	1.044332	3606.3706
967.08911	2.8081849	1.0462542	3603.0659
968.09009	2.8104732	1.0483247	3605.7952
969.09106	2.8169875	1.050365	3608.6624
970.09204	2.8182456	1.052523	3608.0601
971.09302	2.8207388	1.0544977	3608.5349
972.09399	2.8238249	1.0570323	3613.7256
973.09497	2.8266902	1.0593473	3604.4153
974.09595	2.8290122	1.0613111	3597.9739
975.09692	2.8315599	1.0633074	3605.6541
976.0979	2.8362374	1.0652326	3603.51
977.09888	2.8377361	1.0670128	3601.519
978.09985	2.8428493	1.0690085	3601.9863
979.10083	2.8421564	1.0710723	3599.2803
980.10181	2.8454926	1.0728927	3605.759
981.10278	2.8518779	1.075227	3603.4927
982.10376	2.8530512	1.0771819	3603.7356
983.10474	2.8561544	1.0792499	3605.0603
984.10571	2.8612888	1.0817505	3608.606
985.10669	2.8620427	1.0841027	3605.8745
986.10767	2.8669178	1.0864862	3598.4517
987.10864	2.8682108	1.0885519	3597.7087
988.10962	2.8686864	1.0905366	3595.7651
989.1106	2.8769567	1.092423	3597.1802
990.11157	2.8786967	1.0943331	3597.6951
991.11255	2.8796861	1.0964221	3602.9937
992.11353	2.8832953	1.0987804	3600.8403
993.1145	2.8870227	1.1009779	3597.9302
994.11548	2.8919547	1.1032749	3596.9336
995.11646	2.8917856	1.1055844	3598.5337
996.11743	2.8946998	1.1079698	3601.7058
997.11841	2.8983254	1.1105562	3601.0034
998.11938	2.9021788	1.1133065	3596.4983
999.12036	2.9041834	1.1156962	3591.2625
1000.1213	2.9106362	1.1176492	3595.9124
1001.1223	2.9119458	1.1197174	3586.2786
1002.1233	2.9133568	1.1216053	3593.113
1003.1243	2.9172015	1.1241703	3596.1687
1004.1252	2.9215283	1.1265551	3599.2246
1005.1262	2.9246581	1.1289238	3597.7598
1006.1272	2.9280233	1.1315525	3592.6609
1007.1282	2.9304307	1.1341859	3595.5029
1008.1292	2.9306042	1.1364862	3589.0317
1009.1301	2.9352262	1.1387943	3585.2742
1010.1311	2.9361668	1.1408559	3579.9099
1011.1321	2.9400907	1.1427649	3584.5237
1012.1331	2.9437122	1.1449738	3583.5132
1013.134	2.9477501	1.1472902	3587.2808
1014.135	2.952493	1.1487738	3577.2102
1015.136	2.9505491	1.1507421	3585.8821
1016.137	2.9581742	1.1525153	3582.8022
1017.1379	2.9588442	1.1546724	3584.3867
1018.1389	2.9602072	1.1566931	3582.2566
1019.1399	2.9647994	1.1588956	3577.9595
1020.1409	2.966629	1.1614308	3585.249
1021.1418	2.9728801	1.1639576	3583.7219
1022.1428	2.9743805	1.1668806	3579.7078
1023.1438	2.976438	1.1697849	3577.0527
1024.1448	2.9820437	1.1722504	3579.4453
1025.1458	2.9824908	1.1745012	3571.1785
1026.1467	2.9868557	1.1766664	3572.3208
1027.1477	2.9888442	1.1789896	3573.5508
1028.1487	2.9918945	1.1812332	3567.8665
1029.1497	2.9969721	1.1830233	3566.3164
1030.1506	2.998873	1.1848373	3566.6758
1031.1516	3.0008476	1.1865516	3570.051
1032.1526	3.0052443	1.1886623	3566.8484
1033.1536	3.007205	1.1913414	3571.4265
1034.1545	3.0107391	1.1940023	3572.0352
1035.1555	3.0135388	1.1964989	3564.2463
1036.1565	3.0150871	1.1990602	3566.1699
1037.1575	3.0189736	1.2015836	3565.3684
1038.1584	3.0211565	1.2040533	3559.7639
1039.1594	3.0234466	1.2062546	3553.2256
1040.1604	3.0298061	1.2086319	3558.0603
1041.1614	3.0299983	1.2106136	3550.6506
1042.1624	3.0348647	1.2130829	3559.4587
1043.1633	3.0386474	1.2154907	3557.4712
1044.1643	3.0398371	1.2178572	3555.4485
1045.1653	3.0410588	1.220618	3555.8792
1046.1663	3.0457015	1.223809	3551.0425
1047.1672	3.0498979	1.2263484	3550.5632
1048.1682	3.0534301	1.2286725	3550.1257
1049.1692	3.0571828	1.2310617	3548.0876
1050.1702	3.058872	1.2336774	3551.7615
1051.1711	3.0631466	1.2361341	3545.3735
1052.1721	3.0643678	1.2385083	3544.0229
1053.1731	3.0674093	1.2414757	3543.3704
1054.1741	3.0697591	1.2441088	3536.6973
1055.175	3.0719442	1.2468162	3535.0088
1056.176	3.0735893	1.249594	3537.9209
1057.177	3.0780826	1.2525899	3534.4116
1058.178	3.0807736	1.2554524	3532.5681
1059.179	3.0852697	1.2579896	3529.8362
1060.1799	3.0889943	1.2601004	3529.8945
1061.1809	3.090426	1.2622414	3521.9734
1062.1819	3.0949321	1.2641991	3522.4099
1063.1829	3.097209	1.2667533	3528.3003
1064.1838	3.10221	1.269964	3529.9355
1065.1848	3.104141	1.2731183	3522.3538
1066.1858	3.1064765	1.2764028	3523.0046
1067.1868	3.1070538	1.2792082	3513.0427
1068.1877	3.1166666	1.2815063	3509.562
1069.1887	3.1153009	1.2836478	3512.5823
1070.1897	3.1160798	1.2863071	3512.7529
1071.1907	3.122086	1.2893933	3511.4954
1072.1917	3.1249974	1.292226	3505.5879
1073.1926	3.128073	1.294687	3504.6912
1074.1936	3.1295226	1.2976449	3507.8918
1075.1946	3.1343646	1.3005644	3506.6968
1076.1956	3.1382132	1.3032728	3499.5547
1077.1965	3.1372409	1.3058971	3495.1616
1078.1975	3.145226	1.3085102	3496.0178
1079.1985	3.1457994	1.3109717	3491.4451
1080.1995	3.1491561	1.3134549	3489.6367
1081.2004	3.1492336	1.315854	3488.8496
1082.2014	3.1519973	1.3185707	3485.1042
1083.2024	3.1572545	1.3214386	3488.5513
1084.2034	3.1634338	1.3245047	3482.6216
1085.2043	3.1657484	1.3273631	3479.2051
1086.2053	3.165797	1.3302258	3479.009
1087.2063	3.1694312	1.3330517	3476.2214
1088.2073	3.1716588	1.3358992	3477.4395
1089.2083	3.1754735	1.3384974	3462.625
1090.2092	3.177479	1.3409399	3464.156
1091.2102	3.1828809	1.3432062	3469.5315
1092.2112	3.1816096	1.3460724	3462.3469
1093.2122	3.1863782	1.3491098	3464.3242
1094.2131	3.1933985	1.3522393	3461.4727
1095.2141	3.1943243	1.3552403	3455.9084
1096.2151	3.1972315	1.3582962	3454.1714
1097.2161	3.2002981	1.3611516	3449.7615
1098.217	3.2013185	1.3638148	3442.3464
1099.218	3.2091656	1.3668884	3448.4951
1100.219	3.2093809	1.3701688	3440.3284
1101.22	3.2112765	1.3730611	3438.479
1102.2209	3.2144711	1.3755372	3435.6821
1103.2219	3.2181544	1.3783419	3431.4578
1104.2229	3.2206533	1.3809869	3429.282
1105.2239	3.2225358	1.3835049	3429.5278
1106.2249	3.2253678	1.386175	3428.1929
1107.2258	3.2324727	1.3894776	3431.4658
1108.2268	3.2309678	1.3928517	3423.8335
1109.2278	3.234901	1.3963013	3414.8018
1110.2288	3.2409163	1.3992404	3409.3027
1111.2297	3.2408113	1.4020422	3406.115
1112.2307	3.2449884	1.4050469	3409.4209
1113.2317	3.2494895	1.4080812	3399.5
1114.2327	3.2515643	1.4112097	3400.7012
1115.2336	3.2546144	1.4146012	3399.24
1116.2346	3.2559681	1.4179814	3389.3088
1117.2356	3.2607903	1.4211179	3388.947
1118.2366	3.2644725	1.4242514	3390.7729
1119.2375	3.266778	1.4271028	3384.0747
1120.2385	3.2714694	1.430365	3378.897
1121.2395	3.270911	1.4331802	3373.1062
1122.2405	3.2739344	1.4358571	3366.8035
1123.2415	3.277405	1.4392362	3369.8867
1124.2424	3.2821581	1.4426036	3366.6545
1125.2434	3.2844813	1.4457191	3354.5613
1126.2444	3.2900236	1.448342	3353.6025
1127.2454	3.2884042	1.4508048	3352.5813
1128.2463	3.2937586	1.4534448	3348.1174
1129.2473	3.2962854	1.4565076	3346.897
1130.2483	3.2978318	1.4596514	3341.6189
1131.2493	3.2996957	1.4631348	3335.5217
1132.2502	3.3056593	1.4663711	3332.9319
1133.2512	3.3072534	1.4696028	3329.7537
1134.2522	3.3088434	1.4725063	3320.7053
1135.2532	3.3128824	1.4754183	3321.7905
1136.2542	3.3161848	1.4788952	3316.2935
1137.2551	3.3226273	1.4823679	3318.1611
1138.2561	3.3234384	1.4858104	3306.0757
1139.2571	3.3256881	1.4889297	3298.7178
1140.2581	3.3285084	1.4917648	3299.0808
1141.259	3.3312237	1.4947598	3292.7568
1142.26	3.3354259	1.4978737	3289.9758
1143.261	3.3397377	1.5011125	3283.0193
1144.262	3.3427124	1.5046226	3283.8933
1145.2629	3.3408897	1.508431	3272.6938
1146.2639	3.3468323	1.5119812	3265.9688
1147.2649	3.3520424	1.5154704	3264.6333
1148.2659	3.3537669	1.5192057	3257.7422
1149.2668	3.3554265	1.5226256	3249.177
1150.2678	3.3622291	1.5260845	3243.8201
1151.2688	3.360642	1.5290606	3237.6028
1152.2698	3.3634074	1.5320216	3233.9185
1153.2708	3.366482	1.5356791	3227.665
1154.2717	3.3730199	1.539291	3221.1582
1155.2727	3.3761744	1.5422744	3214.4863
1156.2737	3.376816	1.5453448	3205.1138
1157.2747	3.377914	1.5485848	3207.0349
1158.2756	3.3851578	1.5521121	3194.1926
1159.2766	3.3888242	1.5560261	3195.4705
1160.2776	3.3854885	1.5608158	3174.4436
1161.2786	3.395112	1.5661175	3153.4302
1162.2795	3.3958232	1.5715384	3125.1741
1162.8801	3.4012406	1.5789431	3064.9182