File: datasets/am_bench_2022/raw_data/60-XY.09-3/specimen.dat
MTS793|MPT|ENU|1|2|.|/|:|1|0|0|A

Operator Information						Time:	13.244873	Sec	11/1/2021 2:54:15 PM
Operator	Nick Derimow
Project	AM Bench 2022 mini-tensile challenge
Specimen ID	60-XY.09-3
Material	PBF-L Inconel 625
Specimen Width	2.54	mm
Specimen Thickness	1.51	mm
Notes
Operator Information End

Data Acquisition						Time:	1014.2383	Sec	11/1/2021 3:10:56 PM
Time	Axial Displacement	Axial Extensometer	Axial Force
Sec	mm	mm	N
13.358154	-0.0027084735	9.9278288e-05	77.921516
14.359131	0.0057392837	0.00014373552	92.425827
15.360107	0.0021308463	0.00020128838	104.96352
16.361084	0.0054768696	0.00017843484	118.05264
17.362061	0.0099300724	0.00028811296	127.8265
18.363037	0.015163397	0.0002968731	139.47168
19.364014	0.01354271	0.00037957425	147.6938
20.36499	0.017455051	0.00035624229	163.79625
21.365967	0.021847658	0.00052364846	183.37128
22.366943	0.02119467	0.00046261554	196.99057
23.36792	0.027185425	0.00066371809	217.26309
24.368896	0.029721515	0.00085613324	234.57443
25.369873	0.031050233	0.00096649362	253.42256
26.37085	0.037272464	0.00095815561	273.81314
27.371826	0.038141407	0.00091483758	293.38257
28.372803	0.042583596	0.0010278134	313.17435
29.373779	0.044370655	0.0010589077	326.87695
30.374756	0.047700901	0.0012130369	348.04352
31.375732	0.048014589	0.0013892124	364.96741
32.376709	0.054237898	0.0015181974	391.90891
33.377686	0.055366848	0.0015560039	409.58594
34.378662	0.060142342	0.0016418932	432.60245
35.379639	0.062427491	0.0017428788	462.77505
36.380615	0.066909023	0.0019243077	486.95483
37.381592	0.067042612	0.0020938979	516.21289
38.382568	0.068146974	0.0021070684	536.09558
39.383545	0.074358545	0.0022493098	560.9549
40.384521	0.075515769	0.0023166975	582.49469
41.385498	0.0792097	0.0025083227	604.56427
42.386475	0.079231218	0.0026475606	626.87946
43.387451	0.087356471	0.0026250225	653.97943
44.388428	0.086418889	0.0027977189	678.72974
45.389404	0.090583451	0.0029126371	710.9325
46.390381	0.096425459	0.0030729459	739.08002
47.391357	0.09522792	0.0031420013	761.75897
48.392334	0.099904045	0.0032451148	793.3866
49.393311	0.10290427	0.0033867324	814.65094
50.394287	0.10458022	0.0034605176	842.50293
51.395264	0.11158723	0.0036535014	879.86835
52.39624	0.11153171	0.0038298378	903.48248
53.397217	0.11587576	0.0039388211	934.25928
54.398193	0.1187866	0.0040848213	960.54138
55.39917	0.1201819	0.0041420874	987.15582
56.400146	0.12272173	0.0043002213	1013.3475
57.401123	0.12480337	0.0043880283	1040.041
58.4021	0.12945823	0.0045663472	1066.8208
59.403076	0.13153148	0.0045832423	1097.2795
60.404053	0.13608722	0.004889796	1125.3615
61.405029	0.13798857	0.0049026553	1146.5214
62.406006	0.14380224	0.0050159618	1183.4529
63.406982	0.14553562	0.0052279318	1215.8228
64.407959	0.14834857	0.0053603724	1254.6024
65.408936	0.15316182	0.0055506392	1275.5516
66.409912	0.15401144	0.0055669486	1301.1512
67.410889	0.15880297	0.0056826328	1331.1456
68.411865	0.16061933	0.0058957133	1353.5634
69.412842	0.15960759	0.0059845736	1389.9719
70.413818	0.16767015	0.0061163288	1413.8436
71.414795	0.16916442	0.0062647345	1444.7948
72.415771	0.17259896	0.0063671861	1475.6307
73.416748	0.17558564	0.0064336034	1505.4442
74.417725	0.17781849	0.006660345	1525.2876
75.418701	0.18175071	0.0067451526	1552.7559
76.419678	0.18606895	0.0068702702	1583.8063
77.420654	0.18373647	0.0069955271	1606.8904
78.421631	0.19118297	0.00716099	1644.2405
79.422607	0.19394997	0.0072840299	1668.6003
80.423584	0.19437513	0.0073576914	1697.7245
81.424561	0.19791026	0.0075415266	1725.2507
82.425537	0.20069329	0.0075903963	1749.0981
83.426514	0.20687911	0.0076764985	1778.2228
84.42749	0.21158433	0.0078592552	1809.5571
85.428467	0.21296877	0.0079578795	1824.2284
86.429443	0.21390963	0.008160986	1857.9376
87.43042	0.21654904	0.0082007144	1874.2742
88.431396	0.22104548	0.0082609719	1896.2789
89.432373	0.22219245	0.0083689895	1918.302
90.43335	0.22634985	0.008537448	1946.7413
91.434326	0.23206933	0.0087016663	1975.9496
92.435303	0.23047307	0.0087875761	1995.1234
93.436279	0.23657872	0.0089509925	2024.3718
94.437256	0.23906891	0.0089668622	2040.647
95.438232	0.24288377	0.009065045	2064.1733
96.439209	0.24513055	0.009206648	2080.9866
97.440186	0.24575651	0.009253731	2099.6829
98.441162	0.25088564	0.0093392311	2126.7908
99.442139	0.25620872	0.0095053622	2141.3127
100.44312	0.25911975	0.0095479796	2164.6199
101.44409	0.26196009	0.0097403787	2185.1204
102.44507	0.26235533	0.0097375959	2198.6121
103.44604	0.26540694	0.0099355923	2214.6475
104.44702	0.26768962	0.0099694235	2231.9048
105.448	0.27189925	0.010079592	2245.1787
106.44897	0.27499962	0.010236311	2268.3293
107.44995	0.27981308	0.010254387	2280.5205
108.45093	0.28180769	0.010404676	2299.5217
109.4519	0.2814694	0.010444012	2311.105
110.45288	0.28394428	0.010511432	2324.229
111.45386	0.29105365	0.010645715	2341.3579
112.45483	0.28995323	0.010782577	2364.4968
113.45581	0.29652834	0.010886825	2369.3398
114.45679	0.29900891	0.010947234	2384.458
115.45776	0.30070519	0.011126331	2406.6934
116.45874	0.30790824	0.011202029	2417.1072
117.45972	0.30899355	0.011335395	2433.6638
118.46069	0.30842456	0.011411397	2431.8372
119.46167	0.31272188	0.011434947	2443.3909
120.46265	0.31854561	0.01169888	2460.4084
121.46362	0.31892404	0.011758101	2469.7178
122.4646	0.32342958	0.01190079	2486.9551
123.46558	0.32738003	0.012007873	2498.4668
124.46655	0.32972682	0.012073294	2505.2949
125.46753	0.33227664	0.012272404	2515.7336
126.46851	0.33416778	0.012440536	2533.5798
127.46948	0.3381846	0.012522683	2536.5676
128.47046	0.3399229	0.012700032	2549.1799
129.47144	0.34141549	0.012831353	2551.7729
130.47241	0.34779391	0.012878534	2568.3044
131.47339	0.34975347	0.013079309	2577.7363
132.47437	0.35268992	0.01334105	2586.1812
133.47534	0.3601675	0.013546446	2607.3293
134.47632	0.36037916	0.013619465	2607.2231
135.47729	0.36316261	0.013866998	2619.3721
136.47827	0.36566877	0.014050117	2620.2505
137.47925	0.37082297	0.014193366	2632.4395
138.48022	0.3721287	0.014485259	2640.8132
139.4812	0.3732222	0.014684562	2645.3118
140.48218	0.37769783	0.014913562	2660.5471
141.48315	0.38146266	0.015078276	2666.9446
142.48413	0.38191417	0.015425009	2676.8284
143.48511	0.38796353	0.015662422	2678.8337
144.48608	0.38855463	0.016027618	2686.9456
145.48706	0.39506558	0.016293159	2703.0779
146.48804	0.39498839	0.01650944	2701.5461
147.48901	0.40197158	0.016770242	2717.7546
148.48999	0.40156692	0.017205369	2719.8838
149.49097	0.40200332	0.017677637	2726.1167
150.49194	0.40793076	0.017937284	2736.7422
151.49292	0.41047382	0.018492093	2745.7468
152.4939	0.41378215	0.018890569	2748.876
153.49487	0.41819754	0.019317942	2752.3657
154.49585	0.41968399	0.019849936	2761.1404
155.49683	0.42411205	0.020402549	2772.1143
156.4978	0.4283942	0.020995356	2779.7095
157.49878	0.43111843	0.021602146	2788.5225
158.49976	0.43461177	0.022289814	2795.8154
159.50073	0.43667293	0.022799041	2790.5786
160.50171	0.43706736	0.023294298	2793.2729
161.50269	0.44131386	0.024034122	2808.8643
162.50366	0.44321239	0.024697948	2815.6775
163.50464	0.44781584	0.025288401	2815.1616
164.50562	0.44969299	0.025944985	2816.9312
165.50659	0.4534623	0.026694199	2831.0454
166.50757	0.45333773	0.027494969	2835.4021
167.50854	0.45928299	0.028493285	2837.0867
168.50952	0.46493652	0.02922863	2850.3716
169.5105	0.46317506	0.030061839	2846.9167
170.51147	0.467632	0.030920871	2850.8311
171.51245	0.47012061	0.031646371	2853.3999
172.51343	0.47314024	0.032581247	2862.0894
173.5144	0.47505701	0.03319874	2860.7056
174.51538	0.47812682	0.034172602	2869.438
175.51636	0.48303351	0.035080951	2875.4907
176.51733	0.4879787	0.035840113	2873.2346
177.51831	0.49021667	0.03659305	2875.3789
178.51929	0.49503157	0.037418582	2882.2156
179.52026	0.4955858	0.038340218	2893.7363
180.52124	0.501167	0.039540697	2895.4172
181.52222	0.50487894	0.040616322	2895.4756
182.52319	0.50440812	0.041637938	2897.8374
183.52417	0.50918794	0.04248083	2898.0317
184.52515	0.50979257	0.043239594	2902.0076
185.52612	0.51205295	0.044399388	2913.6426
186.5271	0.51737648	0.0456554	2917.3611
187.52808	0.51917833	0.046668611	2915.5676
188.52905	0.52399057	0.047496404	2915.1528
189.53003	0.52557045	0.048491649	2923.0901
190.53101	0.53101778	0.049547337	2928.0281
191.53198	0.5311991	0.050613202	2930.5159
192.53296	0.53424132	0.051582899	2929.0835
193.53394	0.53723353	0.052741583	2934.2834
194.53491	0.53681839	0.053975951	2940.8828
195.53589	0.54862243	0.055041954	2943.4197
196.53687	0.54746807	0.056067649	2939.3696
197.53784	0.5475691	0.057125621	2947.3367
198.53882	0.5551883	0.058310766	2950.2917
199.53979	0.55382377	0.059168302	2945.6431
200.54077	0.55892938	0.060217787	2952.3042
201.54175	0.56185186	0.06129035	2953.9053
202.54272	0.5657407	0.06241126	2961.0764
203.5437	0.56822211	0.063602194	2961.718
204.54468	0.57334691	0.06447348	2963.4768
205.54565	0.57423943	0.06540852	2961.9568
206.54663	0.5754661	0.0664744	2969.2571
207.54761	0.58038753	0.067613162	2972.9146
208.54858	0.58420193	0.068913244	2974.2817
209.54956	0.58768976	0.070216507	2978.9263
210.55054	0.5906437	0.071066841	2972.6177
211.55151	0.59385794	0.072161041	2982.5959
212.55249	0.59778118	0.073316038	2981.283
213.55347	0.59569603	0.074299373	2985.6323
214.55444	0.60070449	0.075471178	2990.9028
215.55542	0.60437304	0.076609477	2990.0156
216.5564	0.6084075	0.077701978	2992.387
217.55737	0.61094487	0.078847401	2999.363
218.55835	0.61182487	0.080082066	2996.3704
219.55933	0.61641908	0.08130645	3002.6091
220.5603	0.61857945	0.082587525	2995.7266
221.56128	0.62244749	0.083476737	2995.5649
222.56226	0.62439454	0.08474452	3007.8289
223.56323	0.6310311	0.085869268	3011.9111
224.56421	0.63041604	0.087157808	3011.1042
225.56519	0.6334672	0.088363722	3009.7158
226.56616	0.6364941	0.089382462	3011.8726
227.56714	0.63872629	0.090529263	3018.9424
228.56812	0.64375246	0.091767959	3021.4941
229.56909	0.64538991	0.093010068	3014.2712
230.57007	0.6495375	0.094086565	3015.1411
231.57104	0.65368927	0.095213115	3027.905
232.57202	0.65551567	0.096273907	3028.3911
233.573	0.65469861	0.097288609	3023.676
234.57397	0.66001344	0.098439671	3031.5532
235.57495	0.66069221	0.099904537	3031.1248
236.57593	0.66689503	0.10111559	3034.5757
237.5769	0.66923916	0.1021809	3034.2478
238.57788	0.67457545	0.10332437	3040.1643
239.57886	0.67436194	0.10432626	3033.9385
240.57983	0.67821389	0.10543257	3047.2517
241.58081	0.6808899	0.10681693	3046.4431
242.58179	0.68457156	0.10790287	3046.8435
243.58276	0.68786514	0.10888559	3043.9587
244.58374	0.69030088	0.11017397	3046.3523
245.58472	0.6933074	0.11124468	3050.4695
246.58569	0.69827414	0.11236574	3056.7693
247.58667	0.70002085	0.11352304	3052.9724
248.58765	0.70562124	0.11487898	3059.9177
249.58862	0.70653808	0.11606058	3055.2092
250.5896	0.7065801	0.11709844	3062.7317
251.59058	0.7132712	0.11828214	3065.3064
252.59155	0.71474326	0.11953403	3062.3013
253.59253	0.72030234	0.1207947	3067.5762
254.59351	0.72127491	0.12177999	3061.4758
255.59448	0.724949	0.12280688	3070.469
256.59546	0.72553128	0.12403379	3069.8501
257.59644	0.73331088	0.12537941	3077.2859
258.59741	0.73321766	0.12666763	3072.7966
259.59839	0.73733574	0.12801348	3084.8674
260.59937	0.73703641	0.12907313	3069.2378
261.60034	0.74077582	0.13011056	3074.7947
262.60132	0.74354815	0.13116013	3077.0444
263.60229	0.7470274	0.13251787	3087.781
264.60327	0.75320214	0.13377784	3086.7664
265.60425	0.75631601	0.13497004	3091.4668
266.60522	0.75548106	0.13601023	3083.6484
267.6062	0.75996774	0.13705769	3085.0801
268.60718	0.76370794	0.13815977	3094.0554
269.60815	0.76589805	0.13932213	3089.2637
270.60913	0.7703591	0.14063543	3102.0959
271.61011	0.77311504	0.14185512	3100.1924
272.61108	0.77589536	0.14314786	3103.7373
273.61206	0.78027302	0.14445895	3110.0837
274.61304	0.78248864	0.14557056	3101.4988
275.61401	0.78321952	0.14652777	3092.9504
276.61499	0.78663152	0.14746611	3096.4272
277.61597	0.78935117	0.14850886	3110.5969
278.61694	0.79412681	0.14960659	3108.4507
279.61792	0.79484403	0.150621	3109.9934
280.6189	0.79977041	0.15183055	3108.5933
281.61987	0.80133122	0.15301321	3113.834
282.62085	0.80916375	0.15427643	3121.2275
283.62183	0.80820733	0.15539499	3113.1218
284.6228	0.81395876	0.1565787	3119.7617
285.62378	0.81684458	0.15779632	3113.5093
286.62476	0.8189261	0.15888157	3124.9614
287.62573	0.82207787	0.16012113	3122.3513
288.62671	0.8231976	0.16111583	3120.7417
289.62769	0.82836771	0.16233589	3126.249
290.62866	0.83105057	0.16362216	3131.209
291.62964	0.83198792	0.16486791	3132.6682
292.63062	0.8364498	0.16624729	3130.1685
293.63159	0.83882421	0.16760355	3133.4783
294.63257	0.84170043	0.16886498	3132.4617
295.63354	0.84250563	0.17006125	3131.6841
296.63452	0.84637892	0.17122714	3134.3318
297.6355	0.85082644	0.17234837	3133.2629
298.63647	0.85247141	0.17368148	3137.0352
299.63745	0.85884023	0.17498355	3149.426
300.63843	0.86000955	0.17606467	3144.1624
301.6394	0.86017054	0.17698711	3142.6387
302.64038	0.86703902	0.17837551	3148.2056
303.64136	0.86878711	0.17944041	3151.0181
304.64233	0.86879981	0.18051063	3145.7473
305.64331	0.87584168	0.181739	3144.4092
306.64429	0.87664872	0.18290092	3152.0354
307.64526	0.87797827	0.18398933	3144.147
308.64624	0.88104665	0.18508996	3148.876
309.64722	0.88611215	0.18628761	3161.5122
310.64819	0.89204895	0.18751748	3156.3171
311.64917	0.89227021	0.18866363	3158.2332
312.65015	0.89701277	0.18973888	3161.2983
313.65112	0.90157533	0.1909072	3167.197
314.6521	0.90195763	0.19205011	3166.3191
315.65308	0.90296417	0.19312756	3160.2751
316.65405	0.90741497	0.19431444	3162.2349
317.65503	0.91058111	0.19534479	3166.8364
318.65601	0.91540813	0.19657867	3175.7717
319.65698	0.91682655	0.19796507	3173.522
320.65796	0.91686404	0.19927175	3168.3962
321.65894	0.9240585	0.20030448	3176.3762
322.65991	0.92361903	0.20154324	3173.3679
323.66089	0.92817742	0.20274897	3178.3804
324.66187	0.92977899	0.20389059	3165.9502
325.66284	0.93179864	0.20493394	3176.3252
326.66382	0.93856728	0.20611894	3180.9551
327.66479	0.94002509	0.20736741	3182.3687
328.66577	0.94497645	0.20843643	3182.5127
329.66675	0.94825912	0.20960855	3186.7375
330.66772	0.95118719	0.21074283	3188.6213
331.6687	0.95109558	0.21196003	3188.9448
332.66968	0.95703226	0.213035	3188.9604
333.67065	0.95745641	0.21409963	3188.9441
334.67163	0.96088725	0.21536359	3189.6404
335.67261	0.96560276	0.21652462	3189.5581
336.67358	0.96487844	0.21779625	3191.6338
337.67456	0.97132164	0.21913663	3196.1619
338.67554	0.97249258	0.22017208	3195.1682
339.67651	0.97798395	0.22148865	3201.2246
340.67749	0.97640771	0.22276832	3203.7673
341.67847	0.98344958	0.22410582	3203.8672
342.67944	0.98496598	0.22526301	3199.4758
343.68042	0.98831075	0.22628927	3195.5088
344.6814	0.99427223	0.22723812	3207.5225
345.68237	0.99490535	0.22869608	3206.8955
346.68335	0.9965741	0.22975481	3212.1531
347.68433	0.99638253	0.2309466	3202.6973
348.6853	1.0019203	0.23214887	3202.7893
349.68628	1.0077131	0.23334293	3214.5437
350.68726	1.0091474	0.23431636	3207.5732
351.68823	1.0113348	0.23544461	3213.5334
352.68921	1.0171494	0.23657246	3217.6167
353.69019	1.0212722	0.23787391	3215.8552
354.69116	1.0222214	0.23896211	3218.2771
355.69214	1.0254185	0.24032132	3230.4338
356.69312	1.0266044	0.24158649	3220.6038
357.69409	1.0295722	0.24270999	3219.8081
358.69507	1.0336334	0.24393252	3218.7937
359.69604	1.0376197	0.2449939	3222.4819
360.69702	1.0390146	0.24610025	3223.2842
361.698	1.0438069	0.24723034	3231.8884
362.69897	1.0440685	0.24848954	3232.0522
363.69995	1.0478233	0.24988173	3235.0176
364.70093	1.0523388	0.25115204	3230.4265
365.7019	1.0538688	0.25244337	3235.1938
366.70288	1.0536938	0.25359958	3230.7715
367.70386	1.0625095	0.25474268	3235.5913
368.70483	1.062107	0.25609282	3237.3235
369.70581	1.0662291	0.25717801	3239.3774
370.70679	1.0728679	0.25821328	3238.4573
371.70776	1.0723532	0.25940374	3240.8464
372.70874	1.0762573	0.26074076	3245.4309
373.70972	1.0774301	0.26189005	3241.5645
374.71069	1.082999	0.26302022	3247.3105
375.71167	1.0852518	0.26404834	3241.917
376.71265	1.0882454	0.26515946	3247.0601
377.71362	1.0919709	0.26627919	3253.7324
378.7146	1.0931437	0.2674683	3253.4177
379.71558	1.0989949	0.26865309	3251.7759
380.71655	1.0981582	0.26982638	3249.7952
381.71753	1.1008688	0.27113253	3247.127
382.71851	1.105841	0.2723572	3255.9231
383.71948	1.1110339	0.27372727	3253.1455
384.72046	1.1121095	0.27512822	3262.9089
385.72144	1.1146374	0.27626184	3257.0317
386.72241	1.1180239	0.27733031	3253.1672
387.72339	1.1192764	0.27840143	3255.8091
388.72437	1.1238185	0.27948484	3262.135
389.72534	1.1256161	0.28047186	3257.6162
390.72632	1.1292619	0.28157085	3262.7661
391.72729	1.1316801	0.28274572	3269.3088
392.72827	1.1347909	0.28400835	3262.603
393.72925	1.1360693	0.28523785	3271.0542
394.73022	1.1433346	0.28668386	3275.5178
395.7312	1.1464381	0.28789738	3278.3606
396.73218	1.1479354	0.2891736	3270.9961
397.73315	1.1488873	0.29041123	3275.2979
398.73413	1.1535003	0.29159307	3272.6689
399.73511	1.1562614	0.29270321	3273.3916
400.73608	1.1602248	0.29389888	3271.2327
401.73706	1.1629009	0.29506397	3279.4729
402.73804	1.165012	0.29621041	3282.8262
403.73901	1.1697001	0.29741624	3282.2527
404.73999	1.17097	0.29872996	3285.4641
405.74097	1.1728833	0.3000688	3281.9502
406.74194	1.1755089	0.3011733	3285.2852
407.74292	1.1759287	0.3024742	3284.0012
408.7439	1.1842443	0.30378118	3288.5784
409.74487	1.18712	0.3050265	3285.7078
410.74585	1.185069	0.30618745	3289.7163
411.74683	1.1907094	0.30722871	3285.501
412.7478	1.1974468	0.30839232	3296.0051
413.74878	1.1987455	0.30940291	3289.3708
414.74976	1.1994989	0.31047744	3296.251
415.75073	1.2086838	0.31180009	3300.0098
416.75171	1.2086625	0.31310353	3297.2688
417.75269	1.2096388	0.31452987	3304.8101
418.75366	1.2145127	0.31602812	3300.793
419.75464	1.2188207	0.31720272	3292.7905
420.75562	1.216987	0.31817824	3290.2996
421.75659	1.2231582	0.31923306	3298.625
422.75757	1.2256398	0.32004115	3295.6636
423.75854	1.2303166	0.32113761	3301.0789
424.75952	1.2294573	0.32242662	3305.4517
425.7605	1.2335711	0.32359585	3309.2104
426.76147	1.2352163	0.32465047	3303.2898
427.76245	1.2409239	0.32571644	3307.3618
428.76343	1.2455766	0.32699791	3309.7075
429.7644	1.2500677	0.32839337	3318.5422
430.76538	1.2498115	0.3296195	3311.2566
431.76636	1.2512429	0.33094519	3310.3376
432.76733	1.253768	0.33225307	3312.0334
433.76831	1.2590518	0.33327693	3308.0107
434.76929	1.2636315	0.33439469	3317.5178
435.77026	1.2664547	0.33571166	3315.2351
436.77124	1.2683924	0.33700392	3323.3008
437.77222	1.2700264	0.33809716	3308.8352
438.77319	1.2743324	0.33915606	3317.2747
439.77417	1.2772183	0.34035325	3325.3813
440.77515	1.2826679	0.34151652	3329.5505
441.77612	1.2837925	0.34296221	3326.0513
442.7771	1.2844054	0.34451094	3327.1206
443.77808	1.2884181	0.34580103	3325.3994
444.77905	1.2934383	0.34696743	3323.1633
445.78003	1.2939728	0.34820881	3327.9529
446.78101	1.2973664	0.34942997	3328.5759
447.78198	1.3029027	0.35058689	3331.5564
448.78296	1.304598	0.3516039	3331.4966
449.78394	1.3051186	0.35285559	3336.7283
450.78491	1.3070849	0.3541092	3335.175
451.78589	1.3137813	0.35528055	3333.7209
452.78687	1.3178625	0.35655707	3340.6648
453.78784	1.3208743	0.35781991	3335.7468
454.78882	1.3229285	0.35894838	3339.136
455.78979	1.3230691	0.36007616	3339.3022
456.79077	1.3298792	0.36123979	3339.3076
457.79175	1.3290972	0.36248511	3336.5176
458.79272	1.3346486	0.36378533	3355.3601
459.7937	1.3394947	0.36481467	3339.2959
460.79468	1.3404336	0.36588466	3342.4058
461.79565	1.3424861	0.36734086	3350.7583
462.79663	1.3471707	0.36879939	3358.6389
463.79761	1.3515025	0.36996505	3351.8665
464.79858	1.3517877	0.37120351	3345.4573
465.79956	1.3543205	0.37244487	3344.4951
466.80054	1.3583497	0.37358046	3350.8716
467.80151	1.3620362	0.37477252	3349.886
468.80249	1.3646303	0.37603685	3349.2927
469.80347	1.3671385	0.37714282	3355.5022
470.80444	1.3689618	0.37843367	3360.644
471.80542	1.3725502	0.37953299	3350.5852
472.8064	1.3751223	0.38079938	3359.3845
473.80737	1.3779078	0.38191018	3356.2566
474.80835	1.3823113	0.38320827	3360.5906
475.80933	1.3819985	0.38449854	3358.2883
476.8103	1.3891807	0.38592979	3367.9087
477.81128	1.3922805	0.38729551	3362.1113
478.81226	1.3930149	0.38839749	3354.6616
479.81323	1.3977706	0.38937989	3360.3525
480.81421	1.4022987	0.39062145	3370.6685
481.81519	1.402514	0.39191213	3371.1914
482.81616	1.40413	0.39307341	3366.3896
483.81714	1.4081218	0.39451545	3366.1765
484.81812	1.4130547	0.39564687	3363.2307
485.81909	1.4168168	0.3970719	3371.667
486.82007	1.4189739	0.39816365	3367.4541
487.82104	1.4213455	0.39946586	3373.5115
488.82202	1.4241308	0.4005602	3372.7573
489.823	1.4256341	0.40194565	3371.7166
490.82397	1.4306227	0.40314645	3373.9824
491.82495	1.4320216	0.40430936	3372.2493
492.82593	1.4352114	0.4055301	3373.5598
493.8269	1.4346499	0.40666163	3374.176
494.82788	1.4407225	0.40780121	3376.5129
495.82886	1.4437733	0.4088853	3382.4658
496.82983	1.4484752	0.41005448	3382.8577
497.83081	1.4484818	0.41128331	3380.8877
498.83179	1.4546332	0.41251215	3386.4443
499.83276	1.454736	0.41384056	3383.0686
500.83374	1.4606771	0.41505581	3381.3818
501.83472	1.4655483	0.41618514	3385.8562
502.83569	1.4650483	0.41729617	3385.9541
503.83667	1.4674894	0.41854036	3387.6155
504.83765	1.4725651	0.42024693	3395.6367
505.83862	1.474828	0.42176983	3391.1116
506.8396	1.4809909	0.42298508	3391.3591
507.84058	1.4826593	0.42420357	3387.2214
508.84155	1.4849793	0.42540085	3393.8291
509.84253	1.4880941	0.42681441	3397.3076
510.84351	1.487151	0.42791048	3388.2439
511.84448	1.4931926	0.42908877	3395.0232
512.84546	1.4981605	0.43034133	3403.7971
513.84644	1.4977751	0.43174246	3404.3103
514.84741	1.5015094	0.4331688	3399.8508
515.84839	1.5048147	0.43442598	3391.5588
516.84937	1.5073141	0.43577012	3396.5525
517.85034	1.5110872	0.43678951	3401.519
518.85132	1.5163798	0.43798521	3401.8228
519.85229	1.5187006	0.43912908	3405.071
520.85327	1.52314	0.44054994	3412.0181
521.85425	1.5203913	0.44207594	3404.5168
522.85522	1.528283	0.44322512	3398.7351
523.8562	1.5291669	0.44438228	3400.8386
524.85718	1.5330385	0.44550157	3413.8906
525.85815	1.5344259	0.44653416	3401.4692
526.85913	1.5393807	0.44796267	3416.03
527.86011	1.5415587	0.44921303	3410.1782
528.86108	1.5459017	0.45043075	3411.2903
529.86206	1.5463028	0.45188373	3415.3623
530.86304	1.5521833	0.45296276	3408.6499
531.86401	1.5524212	0.45398757	3414.3635
532.86499	1.556311	0.45518807	3420.0664
533.86597	1.5610335	0.45637003	3414.689
534.86694	1.5597591	0.45764858	3416.2527
535.86792	1.5661112	0.45881492	3414.5835
536.8689	1.5653694	0.46023193	3421.2058
537.86987	1.5709326	0.46167725	3419.4001
538.87085	1.5729853	0.4628261	3411.8452
539.87183	1.5749347	0.46402186	3416.9824
540.8728	1.5814819	0.46517774	3418.3672
541.87378	1.5836778	0.46628293	3423.1467
542.87476	1.5873506	0.46787629	3430.5623
543.87573	1.5907462	0.46936852	3429.0994
544.87671	1.5939686	0.47070539	3431.6833
545.87769	1.5948495	0.472047	3430.0808
546.87866	1.5992104	0.47340277	3429.2871
547.87964	1.6023057	0.47473767	3430.5945
548.88062	1.6035116	0.47602329	3424.908
549.88159	1.606438	0.47716454	3429.0664
550.88257	1.6088725	0.4782384	3426.7012
551.88354	1.6140045	0.47929746	3427.5281
552.88452	1.6176633	0.48040766	3431.5339
553.8855	1.6187479	0.48148179	3430.136
554.88647	1.6212335	0.48290598	3438.1887
555.88745	1.624615	0.48420146	3431.0635
556.88843	1.6264061	0.48533523	3432.1675
557.8894	1.6298326	0.48663276	3439.5093
558.89038	1.6324224	0.48799488	3434.9229
559.89136	1.636422	0.48920351	3440.0381
560.89233	1.6414407	0.49062893	3437.3188
561.89331	1.6415832	0.4923116	3444.7222
562.89429	1.6463538	0.4935315	3438.865
563.89526	1.6474983	0.49485207	3431.2957
564.89624	1.6523666	0.49596635	3441.0696
565.89722	1.6547805	0.49708891	3437.9524
566.89819	1.659229	0.49834931	3440.6616
567.89917	1.660768	0.49973488	3451.0991
568.90015	1.6660129	0.50118762	3449.6941
569.90112	1.6661477	0.50261098	3442.3394
570.9021	1.6705734	0.50385225	3446.9563
571.90308	1.6723127	0.50500435	3444.3887
572.90405	1.678265	0.50606728	3445.4768
573.90503	1.6797932	0.50717199	3451.3445
574.90601	1.6827927	0.50851941	3452.8025
575.90698	1.6883627	0.50978506	3447.3054
576.90796	1.6861012	0.51106316	3449.7866
577.90894	1.6934104	0.51264495	3459.9548
578.90991	1.6932803	0.51432794	3455.0256
579.91089	1.6958426	0.51570857	3452.8416
580.91187	1.6969793	0.51682693	3447.4102
581.91284	1.7023237	0.51817334	3455.8662
582.91382	1.7079641	0.51939428	3448.583
583.91479	1.7107784	0.52072865	3460.6428
584.91577	1.7143143	0.5219909	3457.032
585.91675	1.7156157	0.52329594	3460.509
586.91772	1.7158868	0.52479839	3459.2109
587.9187	1.7190665	0.52592182	3452.8984
588.91968	1.7237341	0.52717894	3464.731
589.92065	1.7254877	0.52847958	3458.8589
590.92163	1.731806	0.52966744	3457.8647
591.92261	1.7315141	0.5310055	3460.7039
592.92358	1.7391964	0.53253198	3468.6855
593.92456	1.739781	0.5340572	3470.8274
594.92554	1.7426709	0.5356304	3465.145
595.92651	1.7438616	0.53680128	3463.5959
596.92749	1.7493315	0.53807873	3472.217
597.92847	1.7500572	0.53943509	3465.0898
598.92944	1.7543944	0.54059482	3466.345
599.93042	1.7564406	0.5418964	3466.4121
600.9314	1.7587374	0.54319584	3477.8711
601.93237	1.7631723	0.54445463	3469.1599
602.93335	1.7686813	0.54566622	3466.522
603.93433	1.7676415	0.54683226	3465.498
604.9353	1.7712224	0.54812455	3470.4553
605.93628	1.773703	0.54926258	3465.1968
606.93726	1.7758402	0.5506171	3474.9094
607.93823	1.7780646	0.55216765	3467.6541
608.93921	1.7871168	0.55332923	3470.939
609.94019	1.7857418	0.55467325	3478.147
610.94116	1.7888043	0.55620217	3480.8904
611.94214	1.7913363	0.55781245	3474.7014
612.94312	1.7942123	0.5591892	3473.6575
613.94409	1.7997314	0.5605303	3475.2593
614.94507	1.802196	0.56194609	3479.9487
615.94604	1.8062593	0.56301099	3477.6616
616.94702	1.8090681	0.56435364	3481.2073
617.948	1.8110234	0.56547856	3476.1104
618.94897	1.8132801	0.5666284	3485.7339
619.94995	1.8157809	0.56822115	3485.6504
620.95093	1.8217964	0.56973773	3488.0588
621.9519	1.8227805	0.57100898	3483.969
622.95288	1.8282081	0.57249904	3485.1658
623.95386	1.8306841	0.57382321	3489.843
624.95483	1.8318183	0.57516164	3485.5388
625.95581	1.8349726	0.57666612	3493.9353
626.95679	1.8388063	0.57821691	3491.6238
627.95776	1.8398558	0.57963771	3483.9714
628.95874	1.845853	0.58108354	3491.3154
629.95972	1.8481935	0.58249134	3490.2976
630.96069	1.850652	0.58371997	3483.7952
631.96167	1.8508894	0.58478367	3487.8452
632.96265	1.8544286	0.5861094	3489.988
633.96362	1.8569946	0.58749443	3499.1555
634.9646	1.8631353	0.58879304	3502.0837
635.96558	1.8660686	0.59037274	3495.7646
636.96655	1.8668158	0.59168726	3490.865
637.96753	1.8710296	0.59301198	3496.0149
638.96851	1.8746448	0.59422439	3493.2083
639.96948	1.8770362	0.59560138	3490.5813
640.97046	1.8816037	0.59659076	3492.6453
641.97144	1.8837322	0.59765929	3500.1873
642.97241	1.8862003	0.59904939	3495.7009
643.97339	1.8889184	0.60060644	3500.1814
644.97437	1.8945659	0.60187477	3497.7214
645.97534	1.8946589	0.60301769	3501.564
646.97632	1.8989782	0.604756	3503.9714
647.97729	1.8989458	0.60623068	3498.7424
648.97827	1.9041609	0.60766912	3500.28
649.97925	1.9077584	0.60915631	3505.7361
650.98022	1.913236	0.61048383	3505.7163
651.9812	1.9164158	0.61171573	3503.5676
652.98218	1.9171715	0.61305398	3504.2104
653.98315	1.9191293	0.61432737	3506.4209
654.98413	1.9227087	0.61583549	3509.1316
655.98511	1.9252558	0.6173768	3508.8186
656.98608	1.9297061	0.61894393	3509.1458
657.98706	1.9314172	0.62028217	3503.6804
658.98804	1.9316317	0.62166929	3504.6697
659.98901	1.9351865	0.62306255	3509.6584
660.98999	1.9368929	0.62448376	3506.7434
661.99097	1.9429877	0.62604129	3511.6882
662.99194	1.9461067	0.62748379	3507.6714
663.99292	1.9474176	0.62889302	3509.9138
664.9939	1.949185	0.63028562	3510.3027
665.99487	1.9541459	0.63151842	3508.0784
666.99585	1.9586082	0.63290751	3513.9988
667.99683	1.9617106	0.63439173	3514.9597
668.9978	1.9654424	0.63617063	3523.9893
669.99878	1.9665943	0.63771135	3517.0847
670.99976	1.9706255	0.63931847	3514.5452
672.00073	1.9721422	0.64049739	3512.8218
673.00171	1.9756086	0.64173353	3509.9639
674.00269	1.978483	0.64301568	3513.821
675.00366	1.9807433	0.64429921	3513.9795
676.00464	1.985159	0.64554268	3515.4575
677.00562	1.9886225	0.64674383	3513.1987
678.00659	1.992455	0.64789635	3519.3174
679.00757	1.9932932	0.64921373	3518.7952
680.00854	1.9982193	0.65091413	3520.572
681.00952	1.9998507	0.65258312	3523.7041
682.0105	2.0015266	0.6538049	3515.2344
683.01147	2.008863	0.65508765	3523.438
684.01245	2.0093515	0.6564424	3522.4084
685.01343	2.0122185	0.65792221	3530.1235
686.0144	2.0147171	0.65951908	3531.1169
687.01538	2.0202482	0.66125119	3526.0986
688.01636	2.0206747	0.66287977	3525.3523
689.01733	2.0248437	0.66441292	3535.6897
690.01831	2.026644	0.66594237	3520.6211
691.01929	2.0316176	0.66723853	3525.968
692.02026	2.0315578	0.6687296	3521.1704
693.02124	2.0377111	0.6703167	3532.3328
694.02222	2.0393748	0.67179483	3528.25
695.02319	2.0441325	0.67338562	3527.8398
696.02417	2.0445302	0.67456377	3525.0723
697.02515	2.0502312	0.6759854	3529.6992
698.02612	2.0526006	0.67737287	3529.8262
699.0271	2.0554876	0.67890978	3531.4082
700.02808	2.0563276	0.68034363	3537.9167
701.02905	2.0630772	0.68204063	3532.0864
702.03003	2.0664537	0.68354249	3537.7378
703.03101	2.0683374	0.68480486	3531.061
704.03198	2.0679991	0.68602669	3530.2834
705.03296	2.0717101	0.68756741	3538.1692
706.03394	2.0736659	0.68909997	3533.4382
707.03491	2.0795267	0.69055313	3537.1885
708.03589	2.0811403	0.69204128	3536.353
709.03687	2.0857072	0.69351649	3533.6855
710.03784	2.0880244	0.69478542	3533.1499
711.03882	2.088284	0.69611847	3536.0242
712.03979	2.0943847	0.69735181	3535.7192
713.04077	2.0975573	0.69880188	3530.5476
714.04175	2.0986621	0.700001	3535.9402
715.04272	2.1032321	0.70166785	3542.8279
716.0437	2.1055579	0.70320958	3541.1067
717.04468	2.1083333	0.7048012	3538.0151
718.04565	2.1116765	0.70643473	3541.0857
719.04663	2.1106448	0.70803005	3545.895
720.04761	2.1182532	0.70947218	3542.2634
721.04858	2.1215184	0.71085232	3539.9507
722.04956	2.1244864	0.71236646	3545.6702
723.05054	2.123219	0.71380728	3541.3257
724.05151	2.1324248	0.71522111	3538.5854
725.05249	2.1334651	0.71649617	3536.7483
726.05347	2.1353626	0.71787024	3544.1401
727.05444	2.1394706	0.71948111	3545.1992
728.05542	2.1426287	0.72118443	3547.2839
729.0564	2.1449325	0.72290033	3541.9614
730.05737	2.1466346	0.72443485	3542.6106
731.05835	2.1510699	0.72601664	3543.6594
732.05933	2.1541855	0.72754759	3551.2468
733.0603	2.1533566	0.72901076	3544.8618
734.06128	2.1576211	0.73028326	3546.6426
735.06226	2.1660414	0.73189819	3552.8042
736.06323	2.1675432	0.73340887	3552.5569
737.06421	2.1688082	0.73519182	3551.0642
738.06519	2.1716664	0.73693174	3547.8579
739.06616	2.1721494	0.73837173	3538.7239
740.06714	2.1764057	0.73966318	3542.8052
741.06812	2.1815603	0.74096334	3551.0857
742.06909	2.1825433	0.74237496	3548.5605
743.07007	2.1843474	0.74396747	3552.9163
744.07104	2.1910141	0.74564439	3546.2217
745.07202	2.1934395	0.74707752	3552.6191
746.073	2.1954536	0.74847096	3547.9788
747.07397	2.1998026	0.75011563	3555.0771
748.07495	2.202189	0.75169975	3548.3293
749.07593	2.2061324	0.75294608	3548.7754
750.0769	2.2076347	0.75455046	3556.9177
751.07788	2.2107697	0.75652164	3558.3757
752.07886	2.2115195	0.75815731	3549.0195
753.07983	2.217783	0.75981188	3553.1858
754.08081	2.2190211	0.76123178	3551.9629
755.08179	2.225718	0.76269132	3556.2339
756.08276	2.2261758	0.76433378	3561.7112
757.08374	2.2267745	0.76597619	3553.5095
758.08472	2.2309318	0.7674979	3558.6311
759.08569	2.2358057	0.76906693	3555.2932
760.08667	2.2372732	0.77050704	3554.5635
761.08765	2.2416286	0.77210855	3554.0088
762.08862	2.2437563	0.77370048	3564.7239
763.0896	2.2472341	0.77539736	3563.4502
764.09058	2.2505729	0.77726579	3559.2839
765.09155	2.2517378	0.77886504	3555.3406
766.09253	2.254499	0.78056544	3558.5518
767.09351	2.2594175	0.78202862	3555.7693
768.09448	2.2629943	0.78356576	3558.8557
769.09546	2.2649696	0.78489393	3557.1125
770.09644	2.2713928	0.78627747	3559.2207
771.09741	2.2689273	0.78783673	3558.4189
772.09839	2.2744131	0.78941113	3564.9856
773.09937	2.2750723	0.79091072	3562.0647
774.10034	2.2799747	0.7927016	3563.3518
775.10132	2.2833316	0.79427207	3557.0984
776.10229	2.2868469	0.79601562	3564.4893
777.10327	2.2876501	0.7975933	3561.6709
778.10425	2.2890801	0.79908788	3560.3184
779.10522	2.2970841	0.80086696	3568.6602
780.1062	2.2984982	0.80262083	3563.3049
781.10718	2.3025942	0.80387121	3557.8474
782.10815	2.3033483	0.80546367	3561.8044
783.10913	2.3084912	0.80684054	3558.8748
784.11011	2.3116698	0.80838722	3564.9631
785.11108	2.311193	0.80993658	3560.4097
786.11206	2.3162115	0.8114242	3561.7454
787.11304	2.3192661	0.81315798	3570.4539
788.11401	2.321326	0.81484103	3569.8369
789.11499	2.3265188	0.81640065	3563.3369
790.11597	2.333086	0.81798494	3570.9565
791.11694	2.3276215	0.81947345	3561.4854
792.11792	2.3328886	0.82133174	3568.8608
793.1189	2.3363018	0.8230052	3565.7903
794.11987	2.3416014	0.82486546	3573.6804
795.12085	2.3448882	0.82662064	3569.1665
796.12183	2.3476627	0.82834446	3565.8738
797.1228	2.3487093	0.83038616	3565.1565
798.12378	2.3526304	0.83198053	3563.9509
799.12476	2.3562813	0.83365065	3564.7913
800.12573	2.3574061	0.83558589	3567.9968
801.12671	2.3625729	0.83733267	3573.6748
802.12769	2.3638909	0.83906353	3567.3591
803.12866	2.3646538	0.84083974	3568.2393
804.12964	2.3685818	0.84235531	3566.5923
805.13062	2.3718333	0.84395725	3563.8425
806.13159	2.3761985	0.84558415	3568.3494
807.13257	2.3755167	0.84726948	3568.6514
808.13354	2.3848164	0.8489359	3573.3838
809.13452	2.3827052	0.85075015	3568.0796
810.1355	2.3880618	0.85228455	3566.9434
811.13647	2.3904312	0.85404807	3569.5989
812.13745	2.3945353	0.85574526	3568.3242
813.13843	2.3981781	0.85743314	3572.2473
814.1394	2.3994749	0.85939819	3569.2244
815.14038	2.4017596	0.86104888	3571.2588
816.14136	2.4038763	0.86256665	3564.0732
817.14233	2.4106486	0.86411023	3570.376
818.14331	2.4118214	0.86560321	3573.3809
819.14429	2.4165335	0.86753553	3576.2708
820.14526	2.4178627	0.86915582	3574.4792
821.14624	2.4206724	0.87084198	3567.5303
822.14722	2.4212484	0.87235737	3567.5405
823.14819	2.4271522	0.87410676	3571.1799
824.14917	2.4309876	0.87578088	3575.1914
825.15015	2.4307842	0.87771118	3572.2507
826.15112	2.4329021	0.87952101	3571.3584
827.1521	2.4370279	0.88110238	3563.9075
828.15308	2.4407585	0.8828243	3574.0259
829.15405	2.4467752	0.88460547	3575.1965
830.15503	2.4468191	0.88622189	3571.9937
831.15601	2.4511535	0.88796109	3575.77
832.15698	2.454777	0.88975555	3576.9514
833.15796	2.4586217	0.89193034	3580.6328
834.15894	2.4609089	0.89374816	3579.3818
835.15991	2.4630947	0.89578938	3576.0103
836.16089	2.4656775	0.89797693	3581.7371
837.16187	2.4686043	0.89978826	3570.6228
838.16284	2.4715853	0.90128237	3571.9695
839.16382	2.4746065	0.90297395	3570.5786
840.16479	2.4805882	0.9046374	3574.1655
841.16577	2.4805789	0.90653253	3573.8
842.16675	2.4849465	0.90816402	3574.0415
843.16772	2.485857	0.91009355	3576.7424
844.1687	2.4872978	0.91156334	3570.0583
845.16968	2.4931309	0.91354781	3578.3337
846.17065	2.4968009	0.91531819	3574.8625
847.17163	2.4986482	0.91671431	3573.7954
848.17261	2.5008667	0.91853583	3576.6216
849.17358	2.5043824	0.92035967	3581.0493
850.17456	2.5073166	0.92236149	3576.1777
851.17554	2.5094333	0.92431146	3578.6956
852.17651	2.5102348	0.92611814	3578.1729
853.17749	2.5157101	0.92789531	3576.823
854.17847	2.5198953	0.92964065	3575.7295
855.17944	2.5228834	0.93113631	3569.6182
856.18042	2.5276732	0.93289709	3582.1401
857.1814	2.5290449	0.9348613	3578.7813
858.18237	2.531955	0.93668592	3579.6528
859.18335	2.5358937	0.93866301	3575.4714
860.18433	2.5374868	0.94050241	3578.1738
861.1853	2.5401666	0.94253212	3578.1533
862.18628	2.5479465	0.94440669	3573.6587
863.18726	2.5497768	0.94615626	3578.5337
864.18823	2.5506914	0.94801241	3576.3152
865.18921	2.5551963	0.94975734	3578.8542
866.19019	2.5543144	0.95173603	3577.2043
867.19116	2.5600083	0.9538089	3579.3376
868.19214	2.5632761	0.95576143	3578.0864
869.19312	2.5669384	0.95766956	3576.6042
870.19409	2.5675571	0.95924205	3576.2261
871.19507	2.5681686	0.96128792	3578.1912
872.19604	2.5725429	0.96340191	3579.8418
873.19702	2.5775161	0.96536422	3577.3613
874.198	2.5805581	0.96750087	3581.4905
875.19897	2.5832219	0.96971315	3580.5195
876.19995	2.5853209	0.97151941	3574.7407
877.20093	2.5882983	0.97385383	3584.1704
878.2019	2.5912097	0.97584951	3575.4268
879.20288	2.5955906	0.97775686	3573.7007
880.20386	2.5992119	0.97944003	3576.9292
881.20483	2.6013029	0.98127115	3576.7515
882.20581	2.604918	0.98309088	3578.5925
883.20679	2.6048148	0.98496568	3577.269
884.20776	2.6096351	0.98670131	3576.5061
885.20874	2.6138031	0.98879868	3577.1501
886.20972	2.6151578	0.99103934	3585.168
887.21069	2.6189008	0.99302125	3572.7
888.21167	2.6234858	0.99497229	3582.1584
889.21265	2.628145	0.99686587	3573.4402
890.21362	2.6273301	0.99848491	3568.8528
891.2146	2.6321104	1.0002091	3575.5054
892.21558	2.6316671	1.0017169	3572.8489
893.21655	2.6380601	1.0038279	3583.8005
894.21753	2.6389575	1.005814	3579.2991
895.21851	2.6432841	1.0079001	3573.8008
896.21948	2.6470654	1.0103872	3575.1401
897.22046	2.6495392	1.0126567	3578.4529
898.22144	2.6517148	1.0147088	3575.8118
899.22241	2.6541054	1.0165648	3568.459
900.22339	2.6606963	1.0183319	3571.8435
901.22437	2.6604965	1.0200642	3570.9395
902.22534	2.6636834	1.0220231	3575.9417
903.22632	2.6665022	1.0242956	3580.7437
904.22729	2.6673627	1.0263501	3571.4482
905.22827	2.6749802	1.0285099	3578.2732
906.22925	2.6753535	1.030863	3579.0593
907.23022	2.6810677	1.0331681	3578.4231
908.2312	2.6836162	1.0353705	3577.2756
909.23218	2.6849413	1.0373482	3573.6094
910.23315	2.6900694	1.0395347	3570.9336
911.23413	2.6900644	1.0416378	3576.7693
912.23511	2.6952095	1.0437835	3575.5527
913.23608	2.6975532	1.0461978	3575.8967
914.23706	2.6994495	1.0486475	3575.2849
915.23804	2.7046709	1.0509133	3569.894
916.23901	2.7061739	1.0529175	3578.4094
917.23999	2.7057247	1.0550784	3567.4795
918.24097	2.7109482	1.0572386	3574.2888
919.24194	2.714143	1.059474	3570.0957
920.24292	2.7166855	1.0615791	3564.9263
921.2439	2.7228611	1.0634764	3573.085
922.24487	2.7262967	1.0654043	3572.6421
923.24585	2.7253165	1.0675359	3575.4109
924.24683	2.7306309	1.0698045	3571.832
925.2478	2.7320831	1.0719435	3574.8325
926.24878	2.7361782	1.0743856	3575.3018
927.24976	2.7381542	1.0764959	3569.3689
928.25073	2.7422552	1.0786991	3571.4216
929.25171	2.7444041	1.0810826	3573.1682
930.25269	2.7498868	1.0830942	3569.4473
931.25366	2.7482743	1.0853827	3567.4094
932.25464	2.7524993	1.0874519	3564.8345
933.25562	2.7595916	1.0890857	3569.0874
934.25659	2.7589169	1.0913078	3568.729
935.25757	2.7634587	1.0933348	3565.1692
936.25854	2.7657804	1.0952712	3568.8464
937.25952	2.7702312	1.0973891	3571.1782
938.2605	2.7708063	1.1000661	3572.4629
939.26147	2.7776356	1.1022596	3562.0117
940.26245	2.7755418	1.1045091	3570.8374
941.26343	2.7808614	1.1069206	3570.095
942.2644	2.7845829	1.1092777	3570.1064
943.26538	2.7861226	1.1117259	3567.7061
944.26636	2.789783	1.1140963	3566.6467
945.26733	2.7930419	1.1163036	3561.1519
946.26831	2.7966924	1.118476	3563.5083
947.26929	2.8010418	1.1204667	3566.7834
948.27026	2.8020904	1.1232328	3570.521
949.27124	2.8061876	1.1255933	3565.4448
950.27222	2.8062963	1.1279272	3562.293
951.27319	2.8103306	1.1304317	3563.4922
952.27417	2.8192716	1.1329572	3564.3982
953.27515	2.8182447	1.1351056	3557.8879
954.27612	2.821202	1.1374621	3558.5576
955.2771	2.8225658	1.1395459	3556.0396
956.27808	2.8269637	1.141832	3559.2559
957.27905	2.8322017	1.1439365	3557.0627
958.28003	2.8344369	1.1462855	3559.3293
959.28101	2.8348472	1.1488235	3559.8865
960.28198	2.8373249	1.1511919	3549.8821
961.28296	2.8433685	1.153246	3556.5618
962.28394	2.8447576	1.1555568	3554.1831
963.28491	2.8460443	1.1578394	3550.8394
964.28589	2.8478627	1.1603287	3563.1587
965.28687	2.8519816	1.1630563	3553.2207
966.28784	2.858577	1.165506	3558.7156
967.28882	2.8568287	1.1678953	3550.8618
968.28979	2.8631172	1.170323	3553.877
969.29077	2.8691211	1.1729689	3554.8643
970.29175	2.8689167	1.1753644	3552.4448
971.29272	2.8698709	1.1775305	3543.8562
972.2937	2.8777866	1.1799531	3553.9678
973.29468	2.877804	1.1822617	3545.6609
974.29565	2.8802788	1.1845728	3547.1658
975.29663	2.883743	1.1868447	3547.4951
976.29761	2.8859062	1.1890943	3550.146
977.29858	2.8890009	1.192094	3548.9861
978.29956	2.8939421	1.1948823	3549.3694
979.30054	2.8964133	1.1980728	3543.2537
980.30151	2.9012899	1.2004654	3543.9041
981.30249	2.9005134	1.2029938	3539.0972
982.30347	2.9042757	1.2053326	3538.3921
983.30444	2.9095306	1.2080655	3540.5281
984.30542	2.9110138	1.210422	3537.5261
985.3064	2.9136767	1.212553	3537.207
986.30737	2.9157572	1.215107	3536.6528
987.30835	2.9184384	1.2180178	3533.4536
988.30933	2.9212928	1.2205302	3532.6218
989.3103	2.9287195	1.2227423	3528.415
990.31128	2.9287806	1.2248677	3532.9238
991.31226	2.928195	1.2275388	3528.8848
992.31323	2.9333282	1.2300136	3524.6936
993.31421	2.9371972	1.2322807	3528.2168
994.31519	2.9413548	1.2347662	3526.825
995.31616	2.9445398	1.2371655	3526.6199
996.31714	2.9450724	1.2392479	3523.8103
997.31812	2.9501574	1.2413518	3522.0859
998.31909	2.9521303	1.2432332	3518.729
999.32007	2.9551828	1.2453722	3522.155
1000.321	2.9595554	1.2478251	3522.4404
1001.322	2.9622371	1.250904	3527.4258
1002.323	2.9624605	1.2537119	3514.7683
1003.324	2.966583	1.2561438	3513.229
1004.325	2.9704742	1.2586172	3516.6868
1005.3259	2.9742224	1.2615192	3516.2954
1006.3269	2.9751928	1.2642543	3515.634
1007.3279	2.9804132	1.2664562	3501.1143
1008.3289	2.984787	1.2680626	3503.8735
1009.3298	2.9860566	1.2699424	3509.1108
1010.3308	2.991231	1.2722747	3505.7981
1011.3318	2.9909308	1.2746159	3505.7676
1012.3328	2.9938066	1.2769029	3503.0881
1013.3337	2.9992714	1.2793231	3503.8604
1014.3347	3.0010853	1.2821741	3501.978
1015.3357	3.0051203	1.2853467	3506.5127
1016.3367	3.0068736	1.288488	3494.2805
1017.3376	3.0081015	1.2908144	3490.6614
1018.3386	3.0167263	1.2936347	3496.9634
1019.3396	3.0187998	1.2959569	3492.832
1020.3406	3.0165093	1.2984596	3485.5647
1021.3416	3.0211291	1.3010565	3485.2664
1022.3425	3.0244651	1.3039726	3489.5505
1023.3435	3.0277164	1.3065345	3481.9189
1024.3445	3.0315819	1.3088158	3483.9143
1025.3455	3.0346344	1.3112069	3479.3442
1026.3464	3.0379179	1.3140823	3479.4409
1027.3474	3.0405114	1.3169538	3471.8811
1028.3484	3.0447977	1.3196994	3480.3643
1029.3494	3.0454848	1.3223722	3472.3259
1030.3503	3.0497103	1.324762	3471.4097
1031.3513	3.0519361	1.3275235	3470.5437
1032.3523	3.0532465	1.3301293	3464.6409
1033.3533	3.0578845	1.332746	3462.4744
1034.3542	3.0632961	1.3356904	3464.8137
1035.3552	3.0640242	1.3388175	3457.4067
1036.3562	3.068171	1.3418283	3459.3479
1037.3572	3.0691202	1.3443689	3450.7769
1038.3582	3.0732577	1.3469274	3458.0352
1039.3591	3.0780873	1.3500887	3453.2329
1040.3601	3.0812788	1.3531337	3452.6787
1041.3611	3.0813413	1.3561108	3443.9749
1042.3621	3.0858872	1.3587847	3443.0085
1043.363	3.0893464	1.361269	3436.5801
1044.364	3.0948341	1.3642305	3444.8022
1045.365	3.0952401	1.3674787	3437.8818
1046.366	3.0969419	1.3700492	3437.7854
1047.3669	3.1013944	1.3729244	3433.2031
1048.3679	3.1041658	1.3757458	3429.8154
1049.3689	3.1045923	1.3788371	3424.9751
1050.3699	3.1086812	1.3814919	3420.7322
1051.3708	3.1119266	1.3844507	3422.4814
1052.3718	3.1137164	1.3872449	3419.1865
1053.3728	3.1163807	1.3902555	3419.8245
1054.3738	3.1214755	1.3936341	3412.697
1055.3748	3.1238976	1.3962661	3406.6875
1056.3757	3.1266611	1.3989003	3409.8137
1057.3767	3.1293619	1.4022344	3403.7244
1058.3777	3.1328826	1.4052926	3408.6975
1059.3787	3.1384494	1.4085417	3397.4045
1060.3796	3.1404898	1.4114764	3396.0413
1061.3806	3.1417303	1.4144059	3382.9929
1062.3816	3.1449568	1.4166942	3382.7903
1063.3826	3.1464105	1.4186831	3385.6423
1064.3835	3.1500914	1.421363	3382.5981
1065.3845	3.1520531	1.4240878	3379.1587
1066.3855	3.1589692	1.4270194	3383.8394
1067.3865	3.1589789	1.4296656	3372.5469
1068.3875	3.1637936	1.4322205	3368.6575
1069.3884	3.1684344	1.4350331	3369.9165
1070.3894	3.1685052	1.4383135	3365.2058
1071.3904	3.1739459	1.4415979	3362.4255
1072.3914	3.1753368	1.4443748	3352.0186
1073.3923	3.177371	1.4469751	3356.3491
1074.3933	3.1849105	1.4501638	3358.9399
1075.3943	3.1802511	1.4528456	3345.3372
1076.3953	3.187396	1.455748	3338.8599
1077.3962	3.1906123	1.4584897	3340.3169
1078.3972	3.1904788	1.4611465	3340.4438
1079.3982	3.1986825	1.4640174	3337.5703
1080.3992	3.1999309	1.4671572	3339.9187
1081.4001	3.2021666	1.4713205	3330.5635
1082.4011	3.2052178	1.4750024	3316.5273
1083.4021	3.2103691	1.4777973	3320.2522
1084.4031	3.2126093	1.4803989	3313.1729
1085.4041	3.216599	1.4831176	3312.2979
1086.405	3.2163651	1.4864691	3314.3787
1087.406	3.2224178	1.4901419	3303.5618
1088.407	3.2222447	1.4934448	3299.1792
1089.408	3.225245	1.4966042	3298.0068
1090.4089	3.2296026	1.4998351	3290.4165
1091.4099	3.2316704	1.5022353	3283.5388
1092.4109	3.233444	1.5051376	3279.9092
1093.4119	3.2382174	1.5084245	3280.3674
1094.4128	3.2375555	1.5118163	3271.2737
1095.4138	3.2437081	1.5153942	3270.0911
1096.4148	3.2475643	1.5186396	3264.5542
1097.4158	3.251476	1.5214441	3256.2734
1098.4167	3.2538662	1.5239806	3254.1448
1099.4177	3.2565238	1.5267473	3260.4673
1100.4187	3.2577784	1.5297636	3248.8284
1101.4197	3.2630086	1.532917	3244.7354
1102.4207	3.267669	1.5369956	3244.0212
1103.4216	3.2697506	1.5405496	3231.0168
1104.4226	3.2720656	1.543708	3230.9912
1105.4236	3.2751601	1.5470775	3221.7751
1106.4246	3.2763045	1.5505798	3217.1406
1107.4255	3.2801766	1.5537915	3208.8369
1108.4265	3.2824309	1.5566843	3200.2952
1109.4275	3.2871068	1.5592312	3198.1597
1110.4285	3.2898169	1.5626229	3204.6038
1111.4294	3.2911801	1.5667962	3193.9487
1112.4304	3.2970545	1.5702125	3179.3994
1113.4314	3.2965722	1.5727181	3175.5117
1114.4324	3.3023264	1.5759164	3179.0647
1115.4333	3.3062937	1.5797821	3171.7847
1116.4343	3.3090131	1.5837752	3158.073
1117.4353	3.3091085	1.5872484	3153.5261
1118.4363	3.3115349	1.5914204	3139.5784
1119.4373	3.3172011	1.5947187	3136.2766
1120.4382	3.3199718	1.5985513	3129.5779
1121.4392	3.3216069	1.6026578	3112.8911
1122.4402	3.3300099	1.6070222	3105.627
1123.4412	3.325352	1.6110903	3089.9412
1124.4421	3.3329282	1.6145176	3081.396
1125.4431	3.3313861	1.6180308	3068.5986
1126.4441	3.3404322	1.62242	3060.0845
1127.4451	3.3409169	1.6262879	3040.9453
1128.446	3.3467069	1.6299491	3029.7495
1129.447	3.3450968	1.6341878	3017.3252
1130.448	3.348491	1.6395707	2991.4109
1130.7483	3.352191	1.6451871	2947.3091