File: datasets/am_bench_2022/raw_data/60-X.14-4/specimen.dat
MTS793|MPT|ENU|1|2|.|/|:|1|0|0|A

Operator Information						Time:	13.635254	Sec	11/1/2021 12:48:08 PM
Operator	Nick Derimow
Project	AM Bench 2022 mini-tensile challenge
Specimen ID	60-X.14-4
Material	PBF-L Inconel 625
Specimen Width	2.55	mm
Specimen Thickness	1.52	mm
Notes
Operator Information End

Data Acquisition						Time:	1014.6296	Sec	11/1/2021 1:04:49 PM
Time	Axial Displacement	Axial Extensometer	Axial Force
Sec	mm	mm	N
13.749512	0.0026345297	7.7775239e-06	32.515633
14.650391	0.0046786759	3.1306179e-05	49.438702
15.55127	0.0079374155	0.00019204621	61.160225
16.452148	0.0090053072	0.00028525727	72.705414
17.353027	0.012169848	0.0002514144	82.489418
18.253906	0.013077105	0.00045464779	94.234726
19.154785	0.017712045	0.00041801328	103.23962
20.055664	0.021062782	0.00036096346	114.06417
20.956543	0.020392019	0.00058183796	125.01756
21.857422	0.022177389	0.00065093028	135.50601
22.758301	0.026707938	0.00061377638	147.96506
23.65918	0.029403022	0.0008650024	161.74571
24.560059	0.032609925	0.00081054342	172.14136
25.460938	0.034594651	0.00092422304	185.28825
26.361816	0.037172385	0.0010345435	202.53947
27.262695	0.040511083	0.0010199348	221.51796
28.163574	0.046301816	0.0012390923	236.51598
29.064453	0.045591664	0.0011367421	249.49583
29.965332	0.049062874	0.0014337848	271.16122
30.866211	0.054714739	0.001537054	289.85928
31.76709	0.051937904	0.0014814138	301.49734
32.667969	0.058216479	0.0017561368	322.0885
33.568848	0.059822414	0.0017038363	338.96054
34.469727	0.06289757	0.0020185907	359.10416
35.370605	0.065181285	0.0019129787	378.43298
36.271484	0.068645529	0.0020063014	396.2981
37.172363	0.070660427	0.0021882425	421.15063
38.073242	0.072234765	0.0022078301	434.68573
38.974121	0.079207152	0.0023247029	458.79013
39.875	0.08159408	0.0025377127	472.11188
40.775879	0.080688305	0.002389214	491.69156
41.676758	0.082606852	0.0028197707	522.33997
42.577637	0.086974874	0.0027920613	545.57751
43.478516	0.088940546	0.0027941144	569.12897
44.379395	0.090145513	0.0031302636	583.46039
45.280273	0.09488602	0.0030860687	610.66876
46.181152	0.10074749	0.0033416958	628.76215
47.082031	0.1004838	0.003536504	653.75446
47.98291	0.10339238	0.0034309092	681.36774
48.883789	0.10367492	0.0036834262	697.47467
49.784668	0.10770267	0.0037257147	717.66272
50.685547	0.10806061	0.0039452245	750.90143
51.586426	0.11600121	0.0040502581	785.23181
52.487305	0.11300965	0.0041164123	801.97491
53.388184	0.11483769	0.0042478731	828.53204
54.289063	0.11858857	0.0044046249	856.65198
55.189941	0.12460822	0.0045394711	881.37799
56.09082	0.1255732	0.0047295215	909.98535
56.991699	0.13018075	0.0047968724	932.51514
57.892578	0.12990968	0.0047936104	949.94916
58.793457	0.13457565	0.0049341433	976.16901
59.694336	0.13729368	0.0051219482	1009.2255
60.595215	0.14015085	0.0051996335	1032.9739
61.496094	0.14314015	0.005281033	1056.0679
62.396973	0.14363538	0.0054578013	1078.4469
63.297852	0.15011048	0.0055750073	1107.8495
64.19873	0.14970358	0.0056749061	1125.5309
65.099609	0.1511831	0.0056858226	1139.2462
66.000488	0.15419351	0.0058632316	1176.0938
66.901367	0.15909711	0.0059282426	1199.2126
67.802246	0.16140357	0.0060836021	1229.274
68.703125	0.16310084	0.0061825467	1245.7529
69.604004	0.16725557	0.006292481	1282.521
70.504883	0.16846585	0.0064329165	1302.2528
71.405762	0.17055877	0.0065577175	1324.6099
72.306641	0.17520015	0.0065896683	1360.5234
73.20752	0.17790242	0.0067494814	1380.1558
74.108398	0.17888154	0.0068006744	1400.2878
75.009277	0.18188094	0.0069585172	1435.3286
75.910156	0.18544537	0.0071240589	1461.6392
76.811035	0.186234	0.0071390443	1477.6802
77.711914	0.19187316	0.0073913564	1506.8625
78.612793	0.19362512	0.0074371086	1534.6393
79.513672	0.19146645	0.0074629821	1557.9895
80.414551	0.20015578	0.0076902113	1586.7695
81.31543	0.2004756	0.0077242027	1599.4091
82.216309	0.20452379	0.0079690078	1631.0225
83.117188	0.20694289	0.0079553416	1652.2003
84.018066	0.20924397	0.0081579629	1676.054
84.918945	0.21378005	0.0081901802	1693.6936
85.819824	0.21491493	0.0083454447	1722.094
86.720703	0.21946096	0.0084081767	1744.9056
87.621582	0.21817553	0.0083920984	1763.4915
88.522461	0.22761536	0.008644931	1781.2805
89.42334	0.22451925	0.0086234864	1798.1177
90.324219	0.23142874	0.0087980367	1832.7195
91.225098	0.22951218	0.0088724187	1847.4045
92.125977	0.23485284	0.0089036021	1867.0817
93.026855	0.24052395	0.0091281608	1893.9069
93.927734	0.23854287	0.009142343	1907.2959
94.828613	0.24222967	0.0092277601	1938.2015
95.729492	0.24436806	0.0093194693	1948.4799
96.630371	0.25082797	0.0094042113	1970.7847
97.53125	0.25107363	0.009502545	1989.3881
98.432129	0.25184342	0.0094968444	2005.4659
99.333008	0.2580829	0.0095985774	2021.4811
100.23389	0.26115787	0.0097696828	2035.7194
101.13477	0.26094559	0.0097679244	2049.8757
102.03564	0.26329809	0.0098114759	2064.5159
102.93652	0.2645674	0.0098165246	2074.0823
103.8374	0.27061102	0.010003916	2090.7988
104.73828	0.27198705	0.010085847	2105.2998
105.63916	0.27523699	0.010049991	2111.5098
106.54004	0.27995762	0.010220179	2136.4761
107.44092	0.28148365	0.010242046	2138.5396
108.3418	0.28416276	0.010265395	2155.0925
109.24268	0.28655624	0.010383043	2165.4045
110.14355	0.29045016	0.010510675	2181.5627
111.04443	0.29133058	0.010444316	2185.0344
111.94531	0.29607788	0.010598015	2199.1367
112.84619	0.2973496	0.010781333	2217.1284
113.74707	0.30111113	0.010768654	2221.8276
114.64795	0.30506119	0.010789299	2233.655
115.54883	0.30455306	0.010878213	2245.5027
116.44971	0.30566233	0.01096652	2252.0671
117.35059	0.31045344	0.010998056	2263.74
118.25146	0.31543449	0.011118817	2274.7168
119.15234	0.31519866	0.011133729	2278.4348
120.05322	0.31737968	0.011283298	2290.5425
120.9541	0.32197723	0.011447037	2303.8506
121.85498	0.32183769	0.011458687	2307.7012
122.75586	0.32910243	0.011555259	2318.8528
123.65674	0.32810131	0.011671598	2331.0093
124.55762	0.33174565	0.011714499	2339.2922
125.4585	0.33733997	0.011870673	2344.99
126.35938	0.33842814	0.012009841	2358.854
127.26025	0.3394241	0.012029929	2362.5481
128.16113	0.34575021	0.012227962	2372.0139
129.06201	0.34630978	0.012224351	2380.1321
129.96289	0.3492102	0.012351243	2388.5334
130.86377	0.3526347	0.012383443	2393.7783
131.76465	0.35526732	0.012523079	2405.0496
132.66553	0.35756469	0.012655068	2414.8916
133.56641	0.35929048	0.012714829	2420.1958
134.46729	0.36327091	0.01287559	2429.502
135.36816	0.36932635	0.013000875	2439.7041
136.26904	0.37087426	0.013143486	2448.9121
137.16992	0.37427339	0.01327663	2451.3059
138.0708	0.37462765	0.013280405	2461.0364
138.97168	0.37520403	0.013430125	2465.6777
139.87256	0.37917435	0.013608698	2475.074
140.77344	0.38082427	0.013788413	2480.7493
141.67432	0.3807587	0.013857129	2480.9304
142.5752	0.38696051	0.013990769	2494.8623
143.47607	0.39108184	0.014084354	2498.1389
144.37695	0.39180756	0.014244673	2513.072
145.27783	0.39414594	0.014452572	2517.0054
146.17871	0.40074357	0.014660276	2528.1438
147.07959	0.39983591	0.014757418	2531.4604
147.98047	0.40148404	0.014969036	2527.0515
148.88135	0.40869814	0.015197445	2542.8416
149.78223	0.41004369	0.015392478	2551.4966
150.68311	0.40990373	0.015587582	2559.6404
151.58398	0.41162908	0.015680023	2560.1389
152.48486	0.41663313	0.015945932	2569.3311
153.38574	0.42057225	0.016099885	2575.3604
154.28662	0.42038196	0.016380817	2580.4221
155.1875	0.42503187	0.016665336	2589.1145
156.08838	0.43108982	0.017029375	2605.813
156.98926	0.43059829	0.0172182	2602.927
157.89014	0.43403897	0.017528713	2617.7146
158.79102	0.4335106	0.017898606	2618.7075
159.69189	0.43605098	0.018197581	2626.7449
160.59277	0.43926138	0.018594114	2627.1938
161.49365	0.44117936	0.018774906	2632.1157
162.39453	0.44671115	0.01918781	2643.3308
163.29541	0.44891596	0.019460676	2646.5618
164.19629	0.4514254	0.019809218	2651.4319
165.09717	0.45469156	0.020107957	2652.7632
165.99805	0.45785052	0.020518091	2658.9253
166.89893	0.46179217	0.021046424	2668.1128
167.7998	0.46063808	0.021310935	2673.7097
168.70068	0.4641875	0.021789052	2672.4084
169.60156	0.46899444	0.022308445	2682.6289
170.50244	0.46974966	0.022691607	2679.8733
171.40332	0.4729121	0.023183454	2692.7573
172.3042	0.47785294	0.023632534	2696.9067
173.20508	0.48049521	0.024207344	2708.4563
174.10596	0.48458973	0.02460303	2705.9507
175.00684	0.48253247	0.025031095	2708.8354
175.90771	0.48676872	0.025438713	2711.0222
176.80859	0.48766673	0.026104912	2717.7192
177.70947	0.49215868	0.026563784	2721.2847
178.61035	0.49463254	0.027111288	2727.3071
179.51123	0.49963164	0.02760678	2728.1604
180.41211	0.49858341	0.028252337	2737.4111
181.31299	0.50443769	0.028904425	2737.6902
182.21387	0.50671458	0.02942512	2742.8938
183.11475	0.51089436	0.029972091	2740.4409
184.01563	0.5127486	0.030590646	2746.9292
184.9165	0.51362616	0.031148614	2752.064
185.81738	0.51738566	0.03180594	2757.5681
186.71826	0.51863319	0.032441087	2758.0461
187.61914	0.52199072	0.033071876	2764.8677
188.52002	0.5265218	0.033723373	2764.0991
189.4209	0.52786529	0.034248516	2768.6313
190.32178	0.53330958	0.0351763	2780.0171
191.22266	0.53408796	0.035879582	2773.6575
192.12354	0.53827238	0.036472205	2782.9553
193.02441	0.53675073	0.037275679	2786.3779
193.92529	0.54435575	0.038169939	2796.5522
194.82617	0.54298729	0.038937896	2794.033
195.72705	0.54958862	0.039695632	2794.8167
196.62793	0.55138838	0.040387407	2796.604
197.52881	0.5502246	0.041207511	2801.5227
198.42969	0.55802447	0.042162377	2811.2095
199.33057	0.55978954	0.042911869	2808.7107
200.23145	0.56198621	0.043756731	2814.6167
201.13232	0.56386548	0.044524651	2813.429
202.0332	0.5670203	0.045217942	2818.8066
202.93408	0.5705741	0.045926813	2820.7156
203.83496	0.56925684	0.046626847	2822.4058
204.73584	0.57309198	0.047317572	2822.3706
205.63672	0.57518494	0.048016537	2821.5327
206.5376	0.58069235	0.048788369	2829.9834
207.43848	0.58346957	0.04965638	2838.6157
208.33936	0.58668387	0.050468203	2835.7302
209.24023	0.5853492	0.051251147	2834.9409
210.14111	0.59214377	0.052165773	2841.3818
211.04199	0.59347367	0.052963685	2840.8206
211.94287	0.59543955	0.053561326	2845.259
212.84375	0.59987909	0.054444846	2845.2759
213.74463	0.60363352	0.055310797	2847.7983
214.64551	0.60294753	0.055998236	2850.2053
215.54639	0.60630608	0.056931179	2856.4983
216.44727	0.60786939	0.057970021	2858.7175
217.34814	0.6156525	0.058818791	2860.6406
218.24902	0.61835742	0.059656654	2864.7815
219.1499	0.6174258	0.060612902	2873.4131
220.05078	0.61984426	0.061633263	2861.3521
220.95166	0.62350935	0.062618874	2867.2688
221.85254	0.62587023	0.063308373	2869.231
222.75342	0.62706375	0.064098075	2871.1294
223.6543	0.63053358	0.064969838	2872.2134
224.55518	0.6356979	0.066029415	2877.6304
225.45605	0.6363585	0.066920117	2882.7717
226.35693	0.63512534	0.067878038	2881.1392
227.25781	0.64132315	0.06885644	2882.9841
228.15869	0.64382327	0.069861896	2886.1345
229.05957	0.64651179	0.070806682	2886.9768
229.96045	0.6493544	0.071743488	2890.7881
230.86133	0.65123546	0.072626866	2889.2253
231.76221	0.65515149	0.073418505	2893.5898
232.66309	0.65618539	0.0742485	2895.2314
233.56396	0.66214687	0.075210288	2905.137
234.46484	0.66375601	0.07618583	2899.0515
235.36572	0.66743803	0.077074379	2906.2173
236.2666	0.6695177	0.078164756	2906.3042
237.16748	0.67395926	0.079211317	2911.386
238.06836	0.67403346	0.079923667	2902.457
238.96924	0.6753189	0.080945887	2908.2805
239.87012	0.68043453	0.081948683	2910.012
240.771	0.68033928	0.083023161	2912.3428
241.67188	0.687343	0.083969444	2919.3611
242.57275	0.6866613	0.085062809	2921.7666
243.47363	0.69032967	0.086028002	2917.7048
244.37451	0.69022393	0.086992398	2917.7708
245.27539	0.69351542	0.087801062	2919.5432
246.17627	0.70151764	0.08878424	2928.074
247.07715	0.70494539	0.089618035	2928.9927
247.97803	0.70489168	0.090417385	2929.2051
248.87891	0.70591611	0.091359071	2928.0205
249.77979	0.70824391	0.092299327	2932.5483
250.68066	0.71301943	0.093334727	2935.1755
251.58154	0.71489972	0.094367303	2938.2288
252.48242	0.71865755	0.095213048	2937.0798
253.3833	0.71851617	0.09609589	2941.1853
254.28418	0.72158724	0.097145274	2940.863
255.18506	0.72603559	0.09814705	2942.4824
256.08594	0.72697973	0.099283896	2943.9856
256.98682	0.72948325	0.10018562	2945.7485
257.8877	0.73285282	0.1012565	2951.7861
258.78857	0.7366693	0.10228024	2947.9561
259.68945	0.74063373	0.10334599	2955.6758
260.59033	0.74075747	0.10422219	2954.4468
261.49121	0.74359041	0.10527928	2958.363
262.39209	0.74688977	0.10651553	2962.7119
263.29297	0.75124472	0.10748249	2960.2505
264.19385	0.75234991	0.10862626	2966.5264
265.09473	0.75510991	0.10950758	2959.2017
265.99561	0.75623494	0.11058836	2962.5686
266.89648	0.76154709	0.11169022	2964.5051
267.79736	0.76086539	0.11258147	2962.7454
268.69824	0.76587129	0.11368094	2968.2834
269.59912	0.76918703	0.11467095	2970.2202
270.5	0.77360719	0.11582523	2975.335
271.40088	0.77464789	0.11688828	2976.2314
272.30176	0.77782041	0.11785071	2976.9226
273.20264	0.78025526	0.11891834	2976.7612
274.10352	0.78597534	0.11999445	2978.4189
275.00439	0.7849499	0.12100457	2982.0413
275.90527	0.78850943	0.12196641	2984.1553
276.80615	0.7900297	0.12317775	2982.24
277.70703	0.79745382	0.12427855	2991.7991
278.60791	0.7972092	0.12532574	2997.8525
279.50879	0.79838872	0.12630758	2986.6191
280.40967	0.80280632	0.12703821	2990.147
281.31055	0.80356896	0.1278993	2985.0964
282.21143	0.80897963	0.128766	2995.1228
283.1123	0.81088936	0.12957369	2994.5757
284.01318	0.81445098	0.13071395	2994.6218
284.91406	0.81527853	0.13175938	3000.4031
285.81494	0.81758434	0.13280928	2999.0781
286.71582	0.82159954	0.13393575	3001.2595
287.6167	0.82326758	0.13484707	3003.7695
288.51758	0.82514066	0.13590503	3005.9871
289.41846	0.82845265	0.13661784	2999.5515
290.31934	0.83152413	0.13749664	3010.0828
291.22021	0.83313686	0.13847254	3007.6375
292.12109	0.83574098	0.13938804	3007.4302
293.02197	0.83813632	0.14030603	3007.8782
293.92285	0.84440672	0.14148727	3014.3271
294.82373	0.84560084	0.14275818	3025.8796
295.72461	0.8468222	0.14386584	3011.4932
296.62549	0.85025358	0.14499028	3016.3564
297.52637	0.84958285	0.14598249	3015.4094
298.42725	0.85611916	0.14701465	3018.1917
299.32813	0.85637081	0.148138	3024.3945
300.229	0.86142111	0.14944939	3022.439
301.12988	0.86215991	0.15049607	3022.2898
302.03076	0.86909515	0.15159532	3020.6604
302.93164	0.86764312	0.15243402	3020.7163
303.83252	0.87408829	0.15333991	3024.2515
304.7334	0.87497121	0.1544057	3031.312
305.63428	0.878259	0.15542857	3039.6328
306.53516	0.88052464	0.15657453	3040.7458
307.43604	0.88437766	0.15756096	3039.1304
308.33691	0.88845432	0.15854646	3034.9468
309.23779	0.88741589	0.15971039	3043.1768
310.13867	0.88901591	0.1608863	3039.9617
311.03955	0.89418846	0.16193479	3037.0952
311.94043	0.89566612	0.1628688	3038.5696
312.84131	0.89839303	0.16373065	3039.6582
313.74219	0.90420777	0.16489746	3041.7827
314.64307	0.9043448	0.1658916	3040.1145
315.54395	0.90798938	0.16698843	3047.7209
316.44482	0.90949082	0.16786337	3039.0933
317.3457	0.91303438	0.16885343	3047.801
318.24658	0.914729	0.16973582	3047.3965
319.14746	0.91817093	0.17067967	3052.0166
320.04834	0.92003214	0.17177494	3053.874
320.94922	0.92243749	0.17266522	3050.5793
321.8501	0.92692155	0.17380871	3057.4331
322.75098	0.92865056	0.17491065	3056.1833
323.65186	0.93204188	0.17578012	3053.0466
324.55273	0.93284363	0.17657034	3051.8096
325.45361	0.93644142	0.17760536	3063.7383
326.35449	0.93969512	0.17866187	3062.7107
327.25537	0.94291675	0.17980236	3066.6499
328.15625	0.94282746	0.18090557	3062.3215
329.05713	0.94563788	0.18194993	3066.0889
329.95801	0.95016676	0.18282972	3063.3098
330.85889	0.95172983	0.18385001	3062.9922
331.75977	0.95587558	0.18477991	3071.1284
332.66064	0.95771217	0.18581761	3061.4927
333.56152	0.9594937	0.18688634	3073.0317
334.4624	0.96228755	0.18796803	3073.4668
335.36328	0.96519923	0.18899393	3072.2566
336.26416	0.96836227	0.1899955	3079.1082
337.16504	0.97285736	0.19120437	3074.7324
338.06592	0.97339171	0.19229676	3076.4482
338.9668	0.97549176	0.19324243	3073.3999
339.86768	0.98058534	0.19427958	3086.282
340.76855	0.98118055	0.19534189	3080.6521
341.66943	0.98517013	0.19641413	3083.1184
342.57031	0.98932523	0.19738968	3086.1711
343.47119	0.99042857	0.19838016	3084.2744
344.37207	0.99410743	0.19949208	3089.9932
345.27295	0.99728703	0.20063895	3092.0408
346.17383	0.99982071	0.20176154	3091.8162
347.07471	1.0015079	0.20266925	3092.1675
347.97559	1.0048132	0.20372102	3090.375
348.87646	1.0074155	0.20475975	3090.9761
349.77734	1.0094678	0.205695	3094.2927
350.67822	1.010807	0.20669489	3091.969
351.5791	1.0138915	0.20747946	3093.7239
352.47998	1.0165122	0.20848487	3096.9202
353.38086	1.0206753	0.20949069	3100.4644
354.28174	1.0245349	0.21032852	3097.7949
355.18262	1.0260212	0.21145184	3104.1445
356.0835	1.0319792	0.21265221	3109.6448
356.98438	1.0307019	0.21349192	3107.9565
357.88525	1.0329643	0.21452305	3112.1458
358.78613	1.0357581	0.21576343	3104.3096
359.68701	1.0402335	0.21670441	3109.656
360.58789	1.0408338	0.21770783	3101.1011
361.48877	1.0443989	0.21873596	3113.1648
362.38965	1.0483129	0.21970695	3113.3748
363.29053	1.05457	0.22063351	3113.7371
364.19141	1.0501993	0.22142485	3110.5217
365.09229	1.056465	0.22246405	3116.9539
365.99316	1.0568694	0.2234166	3114.6526
366.89404	1.0575404	0.22447254	3110.3433
367.79492	1.0634593	0.22536086	3117.5398
368.6958	1.0650927	0.2263443	3120.502
369.59668	1.067873	0.22736947	3118.8284
370.49756	1.0714215	0.22842042	3123.6382
371.39844	1.0752531	0.22959663	3127.2778
372.29932	1.076851	0.23056056	3123.8242
373.2002	1.0814683	0.23171721	3130.5774
374.10107	1.082163	0.23265207	3123.6011
375.00195	1.0836644	0.23364574	3123.7893
375.90283	1.0897588	0.23488358	3138.6123
376.80371	1.0918108	0.23579904	3129.2109
377.70459	1.0930995	0.23679605	3136.9744
378.60547	1.0935844	0.23776415	3130.1543
379.50635	1.0971217	0.23894338	3135.0049
380.40723	1.0995734	0.23990035	3138.0376
381.30811	1.1035872	0.24105078	3143.8445
382.20898	1.1060503	0.24196747	3134.0781
383.10986	1.1094422	0.24317183	3140.7607
384.01074	1.1138127	0.24410529	3146.4285
384.91162	1.1137865	0.24496119	3134.2043
385.8125	1.1204778	0.24600691	3148.46
386.71338	1.1210831	0.24699046	3145.4573
387.61426	1.1245708	0.24781264	3141.9814
388.51514	1.1256438	0.2486877	3144.1028
389.41602	1.1297705	0.249623	3146.1746
390.31689	1.1310023	0.25060046	3148.5461
391.21777	1.134828	0.25139332	3138.9631
392.11865	1.1367751	0.2521154	3147.5989
393.01953	1.1413789	0.25307927	3155.521
393.92041	1.1400143	0.25410664	3149.554
394.82129	1.1438049	0.25509676	3156.5654
395.72217	1.1479576	0.25623932	3164.0005
396.62305	1.1496948	0.25727698	3157.1936
397.52393	1.1510687	0.25838289	3157.2937
398.4248	1.154881	0.25942409	3159.429
399.32568	1.1562037	0.2605193	3158.2856
400.22656	1.158779	0.26160905	3159.4319
401.12744	1.1671653	0.26263112	3169.9636
402.02832	1.1661845	0.26379797	3169.2869
402.9292	1.1682189	0.26493648	3159.4773
403.83008	1.1705804	0.26594988	3163.5801
404.73096	1.1755452	0.26684919	3162.4128
405.63184	1.1766447	0.26768726	3163.8599
406.53271	1.1813908	0.26862332	3168.6567
407.43359	1.1827494	0.26976678	3174.6653
408.33447	1.1869756	0.2709527	3177.158
409.23535	1.1867528	0.27198586	3168.8433
410.13623	1.1928632	0.27280125	3174.4092
411.03711	1.1931288	0.27370363	3172.4604
411.93799	1.1945852	0.27462631	3172.1865
412.83887	1.1992521	0.27568567	3180.1494
413.73975	1.2018849	0.27647838	3173.1045
414.64063	1.2048125	0.27748305	3176.2544
415.5415	1.2071295	0.27839679	3177.1638
416.44238	1.2114223	0.27947217	3189.6953
417.34326	1.2109674	0.28044119	3182.2898
418.24414	1.2145604	0.28155383	3182.8752
419.14502	1.2192283	0.28267571	3186.6167
420.0459	1.2177937	0.28372067	3178.354
420.94678	1.2256356	0.28466395	3192.0276
421.84766	1.2253748	0.28562286	3189.5771
422.74854	1.2283211	0.28663948	3191.3755
423.64941	1.23306	0.28766784	3191.7219
424.55029	1.2344463	0.28881171	3191.5845
425.45117	1.2365739	0.28970578	3195.0623
426.35205	1.238559	0.29059982	3188.0625
427.25293	1.2434881	0.29138944	3195.7209
428.15381	1.245659	0.29235688	3203.4614
429.05469	1.2463226	0.29326028	3193.0923
429.95557	1.247618	0.29431316	3195.9514
430.85645	1.2530963	0.29539654	3196.5862
431.75732	1.2555448	0.29622066	3193.719
432.6582	1.260762	0.29716292	3204.4397
433.55908	1.2622068	0.29823634	3204.7627
434.45996	1.2683045	0.29929626	3201.9993
435.36084	1.2667494	0.3003163	3200.8315
436.26172	1.2695531	0.30122393	3202.7656
437.1626	1.269483	0.30190793	3202.0969
438.06348	1.2710116	0.30304167	3204.8916
438.96436	1.2786815	0.3043052	3212.2905
439.86523	1.2789372	0.30537465	3211.4993
440.76611	1.2844121	0.30638716	3211.7917
441.66699	1.2858294	0.30724499	3206.6516
442.56787	1.2905214	0.30811051	3207.5857
443.46875	1.2895128	0.30905679	3212.1345
444.36963	1.2925397	0.31015137	3211.031
445.27051	1.2972981	0.31142327	3219.0349
446.17139	1.2981858	0.31270048	3220.7
447.07227	1.3032047	0.31382224	3214.0935
447.97314	1.3053541	0.31474099	3213.9595
448.87402	1.3061472	0.31575489	3221.3638
449.7749	1.3058016	0.31669086	3216.5149
450.67578	1.312801	0.31756905	3220.5049
451.57666	1.3142281	0.31853005	3216.4666
452.47754	1.3180954	0.31933096	3224.0642
453.37842	1.3195869	0.32037106	3219.8472
454.2793	1.325473	0.3214255	3226.3735
455.18018	1.3262703	0.32225901	3229.8354
456.08105	1.3318136	0.32329521	3225.8672
456.98193	1.3350623	0.32434526	3233.7615
457.88281	1.3330958	0.32536569	3227.7756
458.78369	1.3368191	0.32631439	3231.947
459.68457	1.340525	0.32720965	3226.438
460.58545	1.3415835	0.32819629	3230.4731
461.48633	1.3444985	0.32921976	3237.05
462.38721	1.3496734	0.33013248	3238.4097
463.28809	1.348371	0.33096284	3224.2512
464.18896	1.355547	0.33177355	3235.5747
465.08984	1.3543229	0.33278525	3237.8882
465.99072	1.3585312	0.33380744	3235.387
466.8916	1.3617579	0.3348197	3243.8137
467.79248	1.3621633	0.33590412	3240.4841
468.69336	1.3640776	0.33700171	3237.9846
469.59424	1.3693492	0.33792505	3238.5781
470.49512	1.3701997	0.33888882	3243.3013
471.396	1.3754535	0.33990994	3245.8364
472.29688	1.3753315	0.34097028	3241.1843
473.19775	1.3819947	0.34202284	3244.1748
474.09863	1.3828573	0.34304032	3250.5134
474.99951	1.3873016	0.34420666	3249.3555
475.90039	1.3877865	0.34533599	3250.7424
476.80127	1.391789	0.34634522	3245.4309
477.70215	1.3962736	0.34730825	3251.5857
478.60303	1.3973335	0.34841007	3256.5137
479.50391	1.4001552	0.34942728	3255.4922
480.40479	1.4012425	0.35052994	3254.696
481.30566	1.4051681	0.35148922	3252.6348
482.20654	1.4054503	0.35233873	3256.9236
483.10742	1.412052	0.35348544	3263.334
484.0083	1.4109453	0.35449865	3259.0383
484.90918	1.412365	0.35552457	3258.0305
485.81006	1.4178509	0.35665765	3258.2639
486.71094	1.4222277	0.35746235	3256.2168
487.61182	1.4248291	0.35837704	3255.7781
488.5127	1.4269047	0.35948879	3264.1223
489.41357	1.4292947	0.36047283	3264.4946
490.31445	1.4294914	0.36147124	3259.688
491.21533	1.4329123	0.36259183	3267.0195
492.11621	1.433466	0.36353618	3263.4063
493.01709	1.4355645	0.36451179	3261.7825
493.91797	1.4408488	0.36543474	3265.4297
494.81885	1.4450295	0.3663955	3271.4863
495.71973	1.4469386	0.36751646	3267.8035
496.62061	1.4521229	0.36839131	3271.218
497.52148	1.451811	0.36923841	3263.5254
498.42236	1.4574165	0.37020227	3276.0583
499.32324	1.4584296	0.37105697	3268.0603
500.22412	1.4598626	0.37205842	3275.2449
501.125	1.4613435	0.37278807	3274.6035
502.02588	1.4655066	0.37379107	3276.1616
502.92676	1.4692658	0.37493247	3285.467
503.82764	1.4690146	0.37601382	3276.7844
504.72852	1.4735525	0.37709031	3274.8857
505.62939	1.4772732	0.37778249	3272.0835
506.53027	1.4802536	0.37867588	3278.394
507.43115	1.4793332	0.37961864	3279.2146
508.33203	1.4849516	0.38047183	3284.604
509.23291	1.489465	0.38155475	3285.6169
510.13379	1.4923729	0.3825224	3287.2422
511.03467	1.4928925	0.3836267	3285.6599
511.93555	1.4938685	0.38459471	3284.6919
512.83643	1.4990156	0.38543436	3281.9202
513.7373	1.501694	0.38628796	3283.7915
514.63818	1.5040455	0.38717771	3296.9946
515.53906	1.5063053	0.38828442	3284.2561
516.43994	1.5100995	0.38915044	3286.845
517.34082	1.5132328	0.39015532	3296.103
518.2417	1.5152614	0.39109516	3297.6646
519.14258	1.515269	0.39189556	3289.8464
520.04346	1.5187759	0.39269873	3289.7671
520.94434	1.5206685	0.39366168	3289.9287
521.84521	1.5247796	0.39439163	3294.7241
522.74609	1.5290202	0.39531642	3301.8787
523.64697	1.5303547	0.3962374	3298.2146
524.54785	1.5364527	0.39739957	3311.4905
525.44873	1.5366194	0.39847136	3298.614
526.34961	1.5397768	0.39952922	3302.8997
527.25049	1.5436963	0.40052623	3303.4956
528.15137	1.5450402	0.40154883	3307.6721
529.05225	1.5460681	0.40230766	3298.0264
529.95313	1.5494856	0.40329313	3294.8037
530.854	1.5512471	0.4041639	3312.5203
531.75488	1.5548522	0.40538463	3309.5635
532.65576	1.5572231	0.40644068	3308.0054
533.55664	1.5583184	0.40741432	3305.5447
534.45752	1.5613811	0.40815997	3301.9358
535.3584	1.5634896	0.40917847	3303.5154
536.25928	1.5700448	0.41019344	3313.1001
537.16016	1.5726954	0.41113114	3310.9785
538.06104	1.5732654	0.41206697	3313.7065
538.96191	1.5771741	0.41297475	3310.0183
539.86279	1.5794221	0.41386679	3314.2786
540.76367	1.5833073	0.41477707	3314.1172
541.66455	1.5859594	0.41589242	3319.2461
542.56543	1.5854813	0.41695485	3315.0725
543.46631	1.5908098	0.4179486	3318.8052
544.36719	1.5918118	0.41879982	3312.3726
545.26807	1.5986692	0.41974458	3322.4155
546.16895	1.5999677	0.42078927	3318.5923
547.06982	1.5979201	0.42187765	3322.1711
547.9707	1.6030989	0.42290062	3325.7029
548.87158	1.605197	0.42392004	3321.0408
549.77246	1.6112782	0.42472139	3321.7935
550.67334	1.614246	0.42585585	3326.6592
551.57422	1.6142939	0.42662615	3323.0156
552.4751	1.6194813	0.42785111	3326.833
553.37598	1.6202041	0.42867661	3322.0295
554.27686	1.6218945	0.42978507	3330.0354
555.17773	1.6285866	0.43078279	3328.4521
556.07861	1.6272575	0.4317593	3327.002
556.97949	1.6326808	0.43280113	3329.1919
557.88037	1.6379361	0.43367699	3333.0957
558.78125	1.6333549	0.43472546	3329.167
559.68213	1.6432871	0.43554336	3334.3435
560.58301	1.6412262	0.43661657	3334.0056
561.48389	1.645085	0.43779069	3338.2585
562.38477	1.6488445	0.43909159	3336.011
563.28564	1.6503961	0.43994898	3339.9573
564.18652	1.6534919	0.44096082	3339.5747
565.0874	1.655308	0.44176614	3337.4639
565.98828	1.659224	0.44293541	3341.9038
566.88916	1.6618828	0.44371229	3329.5547
567.79004	1.6639571	0.44477373	3339.8032
568.69092	1.6662529	0.44553229	3333.4695
569.5918	1.6699675	0.44634616	3335.2708
570.49268	1.6716688	0.44717565	3339.906
571.39355	1.6745849	0.44813198	3344.3767
572.29443	1.6772192	0.44934255	3342.9141
573.19531	1.6795077	0.45036554	3345.9016
574.09619	1.6816093	0.45118266	3338.9287
574.99707	1.68448	0.45204544	3340.9609
575.89795	1.6893378	0.45299557	3342.738
576.79883	1.6910342	0.45409966	3343.3069
577.69971	1.6944163	0.45507357	3350.6594
578.60059	1.6963867	0.45611569	3346.4126
579.50146	1.6988757	0.45720825	3348.1797
580.40234	1.7032722	0.45814866	3354.2532
581.30322	1.7046039	0.45922998	3348.1453
582.2041	1.7067804	0.46021897	3355.9932
583.10498	1.7094392	0.46108365	3345.8311
584.00586	1.7113233	0.46218318	3352.3989
584.90674	1.7153311	0.46327794	3352.9031
585.80762	1.7177984	0.46403605	3353.3091
586.7085	1.7190105	0.46511942	3356.9092
587.60938	1.7222	0.46643725	3354.3618
588.51025	1.7261258	0.46748599	3352.7197
589.41113	1.7254596	0.46844453	3353.396
590.31201	1.7327514	0.46959293	3362.0176
591.21289	1.735664	0.47074443	3360.9194
592.11377	1.73729	0.47174892	3362.6609
593.01465	1.7373865	0.47286138	3351.5464
593.91553	1.740677	0.47398973	3358.74
594.81641	1.7439407	0.47508162	3355.8767
595.71729	1.7503098	0.47620198	3365.5161
596.61816	1.7506071	0.47719541	3361.8484
597.51904	1.7525915	0.47811192	3360.2295
598.41992	1.7548515	0.47924155	3363.8015
599.3208	1.7611901	0.48082274	3367.6277
600.22168	1.759298	0.4816846	3363.8413
601.12256	1.7647206	0.48290879	3366.3374
602.02344	1.768485	0.48395765	3371.6526
602.92432	1.7687736	0.48494843	3362.5618
603.8252	1.771261	0.48579651	3365.6501
604.72607	1.7765558	0.48708078	3370.9541
605.62695	1.7772179	0.48820993	3372.0891
606.52783	1.7796223	0.48910373	3365.8679
607.42871	1.7814863	0.48997703	3363.3376
608.32959	1.7834934	0.49105826	3374.4854
609.23047	1.7865512	0.49191788	3374.8125
610.13135	1.7934	0.49285612	3379.4397
611.03223	1.7956376	0.49388143	3370.342
611.93311	1.7958126	0.49513039	3379.78
612.83398	1.8001174	0.49596187	3380.5176
613.73486	1.8012347	0.49727979	3374.0574
614.63574	1.8036178	0.49847883	3377.3706
615.53662	1.8093758	0.49925494	3381.1187
616.4375	1.8080941	0.50043821	3372.324
617.33838	1.8105439	0.5012542	3376.9294
618.23926	1.8131526	0.50214982	3379.4119
619.14014	1.8165436	0.50300777	3380.1797
620.04102	1.8193461	0.50375605	3376.3494
620.94189	1.8216717	0.50485539	3386.8276
621.84277	1.8267729	0.50564456	3383.7925
622.74365	1.8267082	0.50671875	3384.071
623.64453	1.8311223	0.50758308	3390.1663
624.54541	1.8322988	0.50860041	3384.5325
625.44629	1.8330274	0.5097276	3377.959
626.34717	1.8384278	0.51045471	3382.2793
627.24805	1.845288	0.51157963	3391.2581
628.14893	1.8441415	0.51248509	3390.4673
629.0498	1.8486185	0.51327097	3385.999
629.95068	1.8508161	0.51443249	3393.6208
630.85156	1.854158	0.5155198	3389.2888
631.75244	1.8564527	0.51623833	3380.9675
632.65332	1.8587636	0.51732111	3391.9922
633.5542	1.8629203	0.51823837	3393.3237
634.45508	1.8632053	0.51921731	3385.1858
635.35596	1.8658677	0.5200302	3387.0132
636.25684	1.8701906	0.52090526	3393.4341
637.15771	1.8720129	0.5219878	3392.9329
638.05859	1.8726727	0.52361667	3398.0911
638.95947	1.8783134	0.52487475	3401.4063
639.86035	1.8799999	0.52617002	3395.7043
640.76123	1.8814831	0.52711284	3395.0542
641.66211	1.8843863	0.52821118	3400.9563
642.56299	1.888329	0.52918917	3392.7598
643.46387	1.8903408	0.53035426	3393.3733
644.36475	1.8928779	0.53170133	3398.9399
645.26563	1.8975505	0.53295559	3399.5701
646.1665	1.8975071	0.53415334	3393.0474
647.06738	1.8997339	0.53568959	3400.1807
647.96826	1.9033123	0.53673255	3392.4895
648.86914	1.9051178	0.53791845	3391.6924
649.77002	1.9071773	0.53895807	3395.4739
650.6709	1.9131238	0.54046583	3408.1501
651.57178	1.9126171	0.54193783	3397.6785
652.47266	1.918026	0.54318541	3398.3369
653.37354	1.9209878	0.54479849	3406.4529
654.27441	1.9226607	0.54683059	3404.5476
655.17529	1.9248717	0.54860687	3401.9475
656.07617	1.928453	0.55020195	3404.2102
656.97705	1.9304975	0.55182862	3404.5322
657.87793	1.9333704	0.55356199	3407.1833
658.77881	1.938024	0.55511189	3406.322
659.67969	1.9397761	0.55705553	3412.9299
660.58057	1.9450598	0.55865556	3412.6274
661.48145	1.9458243	0.56026947	3405.8293
662.38232	1.9447914	0.56185108	3406.9673
663.2832	1.948706	0.56350702	3409.7412
664.18408	1.9540714	0.56532532	3414.8765
665.08496	1.9552007	0.5670048	3413.5322
665.98584	1.9568511	0.56883043	3410.0698
666.88672	1.960602	0.57062912	3411.7251
667.7876	1.9661903	0.57233042	3415.1707
668.68848	1.9658328	0.57362258	3410.5684
669.58936	1.9695792	0.57531881	3411.5942
670.49023	1.9706215	0.5766902	3416.6482
671.39111	1.9751173	0.57816035	3417.8259
672.29199	1.977322	0.57977492	3417.895
673.19287	1.9805672	0.5811767	3410.9482
674.09375	1.9828629	0.58245188	3416.8535
674.99463	1.987524	0.58396459	3414.1082
675.89551	1.9892838	0.58563602	3421.7378
676.79639	1.9915789	0.58735043	3426.9971
677.69727	1.9957137	0.58900857	3421.875
678.59814	1.9957305	0.59038383	3414.6267
679.49902	1.9993125	0.59182137	3422.1501
680.3999	2.0003293	0.59312695	3414.6309
681.30078	2.0020268	0.59476775	3419.1104
682.20166	2.0076358	0.59649551	3426.8132
683.10254	2.0081635	0.59808868	3414.3823
684.00342	2.0126748	0.59947717	3419.9224
684.9043	2.0140729	0.60083431	3420.094
685.80518	2.0179462	0.60259336	3429.0759
686.70605	2.0191412	0.60419565	3430.0603
687.60693	2.0248981	0.6055758	3417.1396
688.50781	2.0245955	0.60693783	3424.4167
689.40869	2.0262206	0.60831982	3422.1484
690.30957	2.0308659	0.60980225	3422.0144
691.21045	2.0336392	0.61142659	3426.7205
692.11133	2.0370171	0.61284822	3423.3931
693.01221	2.0381482	0.61424887	3423.856
693.91309	2.0418956	0.6156835	3432.0667
694.81396	2.0451415	0.61741918	3434.2419
695.71484	2.047688	0.61919791	3426.3071
696.61572	2.0469806	0.6207487	3421.7686
697.5166	2.0525517	0.62222725	3425.2546
698.41748	2.0553439	0.62412715	3432.3879
699.31836	2.0602427	0.62567145	3434.1936
700.21924	2.0609493	0.62730843	3434.5706
701.12012	2.0643184	0.6290831	3435.1067
702.021	2.067044	0.63060147	3432.3137
702.92188	2.0701737	0.63216352	3435.2803
703.82275	2.0719101	0.63401639	3432.647
704.72363	2.0727181	0.63567495	3436.1172
705.62451	2.0780578	0.63742703	3436.0022
706.52539	2.0811794	0.63899004	3429.0925
707.42627	2.0834508	0.64040875	3434.3987
708.32715	2.0858498	0.64217758	3433.7278
709.22803	2.0878022	0.64358813	3434.7788
710.12891	2.092422	0.64521247	3441.7234
711.02979	2.0936861	0.64676917	3434.5317
711.93066	2.0938883	0.64846075	3437.6631
712.83154	2.0983379	0.64986175	3428.4421
713.73242	2.0993533	0.65114278	3430.209
714.6333	2.1057312	0.65239894	3436.5259
715.53418	2.1042032	0.65386331	3434.0566
716.43506	2.1101041	0.65551108	3443.375
717.33594	2.1099339	0.6575461	3440.6685
718.23682	2.113441	0.65924215	3440.4031
719.1377	2.1164644	0.6608609	3440.874
720.03857	2.1209052	0.66277647	3440.3845
720.93945	2.1224604	0.66462499	3439.9363
721.84033	2.1264331	0.66635674	3442.5308
722.74121	2.1275537	0.66803145	3440.4543
723.64209	2.1296861	0.66945392	3436.3181
724.54297	2.1346655	0.67101693	3442.9758
725.44385	2.1353195	0.67271626	3441.3384
726.34473	2.141928	0.67412359	3445.9175
727.24561	2.1444438	0.67544258	3446.4551
728.14648	2.1459911	0.67701823	3440.1909
729.04736	2.1456447	0.67829794	3442.156
729.94824	2.1473403	0.67964339	3442.7083
730.84912	2.1531899	0.68123597	3449.9368
731.75	2.1580188	0.68299747	3451.063
732.65088	2.1612473	0.68445897	3453.8755
733.55176	2.1578615	0.68603444	3443.3303
734.45264	2.1653008	0.68764877	3448.2871
735.35352	2.168689	0.68919444	3449.177
736.25439	2.1684573	0.69070399	3449.7385
737.15527	2.1705668	0.6921581	3444.45
738.05615	2.1724167	0.69374508	3449.0305
738.95703	2.1774144	0.69544613	3449.3118
739.85791	2.1788793	0.69687897	3446.8206
740.75879	2.1836123	0.69859535	3457.0669
741.65967	2.1838512	0.70023161	3450.7476
742.56055	2.1859815	0.70199418	3447.8271
743.46143	2.1907961	0.70376855	3448.825
744.3623	2.1897373	0.70506185	3446.521
745.26318	2.1952548	0.70623612	3445.1648
746.16406	2.1959243	0.7077955	3453.0833
747.06494	2.2008998	0.70931667	3456.1309
747.96582	2.208286	0.71105576	3460.0596
748.8667	2.2078943	0.7127862	3447.2219
749.76758	2.2119589	0.71406049	3451.0212
750.66846	2.2139986	0.71566528	3453.3523
751.56934	2.2165985	0.71687758	3452.2258
752.47021	2.2187512	0.71819186	3447.9309
753.37109	2.2184002	0.71970695	3453.2205
754.27197	2.2235212	0.72132164	3454.6575
755.17285	2.2264986	0.72313184	3460.2866
756.07373	2.2278616	0.72508949	3454.9988
756.97461	2.2309272	0.72699195	3454.1829
757.87549	2.2312858	0.72881138	3460.6758
758.77637	2.2376804	0.73091161	3461.8879
759.67725	2.2414439	0.73264879	3460.167
760.57813	2.2426722	0.73446053	3458.3328
761.479	2.2424371	0.73582929	3449.9912
762.37988	2.2476349	0.73741621	3458.8784
763.28076	2.2509577	0.73881334	3453.8501
764.18164	2.2538657	0.7405417	3460.9377
765.08252	2.2563236	0.74230111	3462.4587
765.9834	2.2592752	0.74414766	3466.9482
766.88428	2.2635136	0.74617529	3460.4495
767.78516	2.2641032	0.74802256	3462.262
768.68604	2.2677498	0.74989635	3464.8799
769.58691	2.2701085	0.75154513	3459.4888
770.48779	2.272608	0.75341451	3464.8872
771.38867	2.274245	0.75541782	3464.4907
772.28955	2.2785819	0.75737542	3466.9934
773.19043	2.2825294	0.75934064	3459.0837
774.09131	2.2844224	0.76078391	3461.395
774.99219	2.2878945	0.76257604	3465.2893
775.89307	2.2865961	0.76414973	3461.5818
776.79395	2.291477	0.76600838	3465.0134
777.69482	2.2932692	0.76782715	3463.3323
778.5957	2.29881	0.76950121	3465.5161
779.49658	2.2988465	0.77133095	3464.3687
780.39746	2.3027537	0.77306777	3468.7061
781.29834	2.3032777	0.77497381	3465.9902
782.19922	2.3065002	0.77670699	3465.4226
783.1001	2.3110075	0.77876246	3465.6707
784.00098	2.3142126	0.7805571	3462.9111
784.90186	2.3179731	0.78173482	3457.0872
785.80273	2.3153839	0.7833904	3464.1067
786.70361	2.3199298	0.78521568	3470.4106
787.60449	2.3212512	0.78735	3466.8269
788.50537	2.3251081	0.78953075	3469.3376
789.40625	2.3289568	0.79160208	3468.8411
790.30713	2.3312249	0.79351664	3464.8611
791.20801	2.3365917	0.79510808	3465.3962
792.10889	2.3374083	0.79652387	3465.1375
793.00977	2.3388793	0.7980063	3467.2051
793.91064	2.3443892	0.79952037	3469.7578
794.81152	2.3466108	0.800677	3466.1316
795.7124	2.3461306	0.80238724	3468.532
796.61328	2.3523083	0.80393839	3475.9783
797.51416	2.3513067	0.80571949	3466.4844
798.41504	2.3577137	0.80706906	3473.282
799.31592	2.3580027	0.80869949	3472.3154
800.2168	2.3599622	0.81027734	3470.3091
801.11768	2.3660567	0.81186086	3468.7493
802.01855	2.3648632	0.81412035	3468.1692
802.91943	2.3676474	0.81609166	3470.7026
803.82031	2.3684168	0.81830591	3467.7061
804.72119	2.3753207	0.82017672	3465.0059
805.62207	2.3772085	0.8215456	3465.2717
806.52295	2.382452	0.82346326	3477.3386
807.42383	2.3844087	0.82522929	3467.7058
808.32471	2.3859363	0.82704002	3467.5168
809.22559	2.3905354	0.82919389	3476.5698
810.12646	2.3903937	0.83118486	3469.9771
811.02734	2.3932717	0.83299762	3474.1887
811.92822	2.3951414	0.83506274	3471.0896
812.8291	2.401346	0.83697695	3474.824
813.72998	2.4003632	0.83877695	3468.1804
814.63086	2.4044826	0.84031278	3474.7673
815.53174	2.405813	0.84197408	3471.6565
816.43262	2.4074476	0.84353936	3480.3599
817.3335	2.4126883	0.84575057	3474.248
818.23438	2.4147322	0.84796077	3471.9409
819.13525	2.4179552	0.84966063	3470.4512
820.03613	2.4192588	0.85109413	3467.8838
820.93701	2.4240062	0.85252708	3474.0105
821.83789	2.422101	0.85439014	3468.97
822.73877	2.4290535	0.85646093	3477.011
823.63965	2.4318509	0.8583951	3475.6616
824.54053	2.4358342	0.86034477	3473.3965
825.44141	2.4357851	0.86217284	3471.4368
826.34229	2.4380698	0.8643645	3473.5925
827.24316	2.4423423	0.86634851	3473.5876
828.14404	2.4447033	0.86823946	3474.5151
829.04492	2.4485412	0.87016886	3473.6787
829.9458	2.4512789	0.87203163	3474.6885
830.84668	2.4539471	0.8745864	3474.0066
831.74756	2.4553471	0.87688774	3477.147
832.64844	2.4556844	0.87919867	3475.4258
833.54932	2.4648697	0.8815468	3478.9724
834.4502	2.4638603	0.88375866	3470.6792
835.35107	2.4671643	0.88596344	3477.0735
836.25195	2.4692297	0.88805276	3478.842
837.15283	2.4726572	0.89061481	3480.842
838.05371	2.4757783	0.89323545	3484.9602
838.95459	2.4778545	0.89585006	3477.8059
839.85547	2.4790981	0.89802361	3472.7539
840.75635	2.4842846	0.89972359	3474.4067
841.65723	2.4863214	0.90179056	3475.9983
842.55811	2.4863441	0.90360862	3476.6982
843.45898	2.4920008	0.90539819	3478.3376
844.35986	2.4954264	0.90739936	3486.259
845.26074	2.4994588	0.90931988	3477.6899
846.16162	2.4988585	0.91154224	3482.9507
847.0625	2.501739	0.91368556	3473.2515
847.96338	2.5054593	0.91538197	3472.8853
848.86426	2.5063426	0.91736692	3475.5151
849.76514	2.5084219	0.91915148	3477.4951
850.66602	2.5131886	0.92110723	3477.4919
851.56689	2.516221	0.92297697	3477.9736
852.46777	2.5181355	0.92521507	3479.2646
853.36865	2.5211847	0.92739826	3481.272
854.26953	2.5226171	0.92940569	3476.125
855.17041	2.5269778	0.93133491	3477.6152
856.07129	2.5289688	0.93302178	3468.6707
856.97217	2.5319171	0.93522185	3482.5598
857.87305	2.5344234	0.93734092	3476.531
858.77393	2.5370874	0.93911165	3480.9419
859.6748	2.540514	0.94153321	3479.6743
860.57568	2.5440893	0.94386923	3476.3464
861.47656	2.5429621	0.94609016	3478.2053
862.37744	2.5498025	0.94801748	3479.5674
863.27832	2.5492771	0.94994009	3471.7644
864.1792	2.5539246	0.95170808	3479.6643
865.08008	2.5548778	0.95336765	3476.9551
865.98096	2.5617499	0.95513272	3477.8965
866.88184	2.5596471	0.95696491	3479.2925
867.78271	2.5656164	0.95943022	3480.2283
868.68359	2.5652764	0.96209216	3476.8943
869.58447	2.5710351	0.96399593	3477.1099
870.48535	2.5714843	0.96572351	3471.7612
871.38623	2.5740469	0.96739918	3470.2041
872.28711	2.576056	0.96932101	3475.8445
873.18799	2.5807116	0.97169167	3485.1306
874.08887	2.5814896	0.97415859	3483.7012
874.98975	2.5851133	0.97671229	3484.2563
875.89063	2.5872777	0.97884244	3479.0029
876.7915	2.5921407	0.98063189	3481.345
877.69238	2.59161	0.98282439	3470.7434
878.59326	2.5941603	0.98484808	3473.8657
879.49414	2.6022172	0.98665136	3471.5896
880.39502	2.6044545	0.98873359	3479.3706
881.2959	2.6044102	0.99091542	3476.6067
882.19678	2.605731	0.99324417	3484.5198
883.09766	2.609494	0.9965443	3482.0828
883.99854	2.6113024	0.99903411	3474.6396
884.89941	2.6134863	1.0016112	3476.0132
885.80029	2.6172779	1.0038407	3474.9092
886.70117	2.6213787	1.0056826	3472.229
887.60205	2.623625	1.0077808	3480.9419
888.50293	2.624428	1.0097876	3476.395
889.40381	2.6275785	1.0119127	3470.0288
890.30469	2.6280746	1.0134604	3466.5269
891.20557	2.63484	1.015136	3478.22
892.10645	2.6386685	1.0175213	3483.4072
893.00732	2.6397686	1.0200454	3479.4707
893.9082	2.6448867	1.0224288	3484.7761
894.80908	2.6455905	1.0248506	3473.2974
895.70996	2.6473715	1.0272807	3476.9065
896.61084	2.6509409	1.0294452	3475.0442
897.51172	2.6521111	1.0315418	3475.9592
898.4126	2.6546116	1.0336126	3475.9897
899.31348	2.6595664	1.0360605	3479.2747
900.21436	2.663795	1.0379913	3477.3225
901.11523	2.6646013	1.0401078	3474.4741
902.01611	2.6672018	1.0421622	3475.6687
902.91699	2.6718366	1.0443469	3479.2366
903.81787	2.6707451	1.0467384	3472.2854
904.71875	2.6773882	1.0487665	3481.6753
905.61963	2.6795285	1.051281	3479.3186
906.52051	2.6812811	1.0536802	3471.8816
907.42139	2.6831803	1.0557585	3475.2083
908.32227	2.6831353	1.058107	3475.8413
909.22314	2.689832	1.0605338	3477.5208
910.12402	2.6917491	1.0631781	3475.5181
911.0249	2.6931221	1.0656981	3469.2358
911.92578	2.6980917	1.0675997	3477.6731
912.82666	2.7013421	1.0699918	3481.6599
913.72754	2.701565	1.0726869	3471.5176
914.62842	2.7063088	1.0751231	3476.8013
915.5293	2.7044954	1.0775499	3474.428
916.43018	2.7146883	1.0800046	3478.2417
917.33105	2.7092841	1.0819708	3463.5039
918.23193	2.7123618	1.0837373	3466.2891
919.13281	2.7178123	1.0859768	3469.3494
920.03369	2.7232869	1.0884717	3478.635
920.93457	2.7220626	1.09091	3472.9944
921.83545	2.7271771	1.093321	3473.9885
922.73633	2.7258101	1.0954949	3469.8848
923.63721	2.7358463	1.0975558	3471.6689
924.53809	2.7343326	1.0997908	3473.0852
925.43896	2.7398176	1.1015238	3470.2622
926.33984	2.7420511	1.1032759	3471.5564
927.24072	2.7428839	1.1049901	3466.1433
928.1416	2.744802	1.1068506	3469.0229
929.04248	2.7469966	1.1089555	3468.5923
929.94336	2.7495999	1.1108375	3469.0452
930.84424	2.7554071	1.1131119	3476.0659
931.74512	2.7542922	1.1153913	3461.3953
932.646	2.7576654	1.1172371	3463.887
933.54688	2.7624307	1.1189768	3472.436
934.44775	2.7599418	1.1213115	3465.0779
935.34863	2.7676067	1.1233567	3471.9116
936.24951	2.7670336	1.1256216	3465.9353
937.15039	2.7719347	1.1277953	3466.3762
938.05127	2.7771833	1.1303545	3468.9751
938.95215	2.7760582	1.1328585	3463.1497
939.85303	2.7801628	1.1346329	3462.3489
940.75391	2.7845645	1.1366628	3462.6548
941.65479	2.785059	1.1387175	3465.7065
942.55566	2.7862391	1.1404539	3456.9517
943.45654	2.7914135	1.1424723	3465.2351
944.35742	2.7934291	1.1448509	3466.8347
945.2583	2.7936466	1.1474453	3461.3479
946.15918	2.8001657	1.1494153	3458.6201
947.06006	2.8002744	1.1514364	3456.5742
947.96094	2.8058834	1.1533731	3465.1489
948.86182	2.8066592	1.1558334	3459.2068
949.7627	2.8121307	1.1582202	3458.9858
950.66357	2.8150728	1.1603519	3462.4451
951.56445	2.8145611	1.1629109	3462.7451
952.46533	2.8181925	1.1654524	3463.3149
953.36621	2.8185718	1.1682498	3457.7598
954.26709	2.8250446	1.1707565	3449.8792
955.16797	2.826823	1.173406	3459.9307
956.06885	2.8291752	1.1760805	3458.6523
956.96973	2.8336413	1.1778412	3448.4441
957.87061	2.8312001	1.1797858	3450.123
958.77148	2.8381009	1.1820648	3460.376
959.67236	2.836617	1.1844838	3454.6829
960.57324	2.8418133	1.1873624	3457.6499
961.47412	2.846086	1.1902055	3454.1411
962.375	2.8490455	1.1925045	3450.0535
963.27588	2.8486867	1.1950761	3456.375
964.17676	2.8528619	1.1983128	3453.2678
965.07764	2.8550961	1.2010556	3450.5547
965.97852	2.858532	1.2036269	3444.6079
966.87939	2.8598645	1.2060454	3445.3354
967.78027	2.8627229	1.2087946	3448.3274
968.68115	2.8638725	1.2114927	3448.5188
969.58203	2.8673062	1.2144811	3444.8076
970.48291	2.8701823	1.2169701	3443.262
971.38379	2.8747942	1.219329	3443.5063
972.28467	2.874661	1.2211924	3442.3826
973.18555	2.8806839	1.2239683	3446.9124
974.08643	2.8845656	1.2261828	3442.2512
974.9873	2.8887792	1.2284305	3443.8396
975.88818	2.888324	1.2305124	3441.6812
976.78906	2.8917625	1.2329581	3445.3608
977.68994	2.8920469	1.2354113	3441.7603
978.59082	2.8976536	1.2378581	3433.4609
979.4917	2.8976388	1.2395033	3437.0825
980.39258	2.9043775	1.2417892	3446.9341
981.29346	2.9043424	1.2449478	3446.0459
982.19434	2.9085996	1.247412	3433.573
983.09521	2.9094579	1.2497826	3430.4324
983.99609	2.9124401	1.2522272	3438.0784
984.89697	2.9147227	1.2548726	3439.4441
985.79785	2.9194515	1.2574693	3432.8354
986.69873	2.9208972	1.2597519	3429.6643
987.59961	2.9234102	1.2623298	3426.1892
988.50049	2.9265401	1.2642903	3417.5564
989.40137	2.9273667	1.2662582	3425.99
990.30225	2.9348688	1.2691331	3429.5886
991.20313	2.9364204	1.27188	3425.0107
992.104	2.9354172	1.2742095	3419.2822
993.00488	2.9389353	1.2768606	3425.9502
993.90576	2.9423268	1.27889	3413.7583
994.80664	2.9442222	1.2812581	3422.1311
995.70752	2.9458122	1.2839881	3415.8071
996.6084	2.9505401	1.2865635	3419.0496
997.50928	2.9497495	1.2892175	3405.2351
998.41016	2.9544423	1.2913653	3408.4622
999.31104	2.9598804	1.2935518	3416.1848
1000.2119	2.9582131	1.2963945	3409.3501
1001.1128	2.9619973	1.2988936	3400.9707
1002.0137	2.9673471	1.3014874	3406.8093
1002.9146	2.9708288	1.3041483	3409.4158
1003.8154	2.9729924	1.3068666	3409.2048
1004.7163	2.975934	1.3096991	3404.5383
1005.6172	2.9756935	1.3123677	3402.7192
1006.5181	2.9799452	1.3155986	3410.8433
1007.4189	2.9815583	1.3186183	3394.7024
1008.3198	2.9828675	1.3212931	3389.845
1009.2207	2.9869883	1.3234929	3391.7935
1010.1216	2.9923096	1.3252755	3388.3433
1011.0225	2.9932704	1.3268745	3383.0581
1011.9233	2.999917	1.3284763	3395.0747
1012.8242	3.000946	1.3305203	3384.2393
1013.7251	3.0026503	1.3323054	3385.3833
1014.626	3.003608	1.3344423	3388.7971
1015.5269	3.0067945	1.3369839	3384.9355
1016.4277	3.0084867	1.339756	3393.4353
1017.3286	3.0123837	1.3431232	3386.4973
1018.2295	3.0146213	1.3461986	3384.5706
1019.1304	3.0152774	1.3484256	3377.9683
1020.0313	3.020107	1.350515	3376.1248
1020.9321	3.0240848	1.3531367	3383.0259
1021.833	3.0273378	1.3562263	3373.3123
1022.7339	3.030057	1.3593686	3380.6633
1023.6348	3.0316176	1.3624381	3362.9492
1024.5356	3.0341237	1.3647798	3365.6702
1025.4365	3.0390799	1.3672258	3369.2832
1026.3374	3.0369916	1.3699822	3364.1521
1027.2383	3.0435135	1.3726609	3358.344
1028.1392	3.0449977	1.3747389	3359.8872
1029.04	3.048188	1.3767197	3357.1213
1029.9409	3.0518773	1.3792012	3361.2729
1030.8418	3.0552149	1.3820423	3359.6409
1031.7427	3.0565526	1.3844681	3349.9756
1032.6436	3.0587258	1.3866465	3348.7961
1033.5444	3.0602987	1.3893056	3354.5115
1034.4453	3.063535	1.3921357	3348.2166
1035.3462	3.0664783	1.3947445	3346.0852
1036.2471	3.0704801	1.3975495	3345.48
1037.1479	3.0755932	1.4001658	3342.4282
1038.0488	3.0769496	1.4030082	3340.8843
1038.9497	3.0785038	1.4057859	3341.9321
1039.8506	3.0804706	1.4089036	3340.6641
1040.7515	3.0831325	1.411844	3329.093
1041.6523	3.0860612	1.4147441	3329.0667
1042.5532	3.0916672	1.416852	3331.1492
1043.4541	3.0920572	1.4194634	3333.6753
1044.355	3.0944448	1.4224226	3325.0276
1045.2559	3.0924923	1.4251086	3317.5876
1046.1567	3.0962358	1.4277869	3314.9822
1047.0576	3.1019678	1.4303166	3315.9824
1047.9585	3.1038656	1.432717	3313.4368
1048.8594	3.1052794	1.4354666	3310.4055
1049.7603	3.1119895	1.4382672	3309.4004
1050.6611	3.1120915	1.4410005	3304.8855
1051.562	3.114254	1.4436576	3303.7461
1052.4629	3.1185298	1.44678	3297.5298
1053.3638	3.1205058	1.4502126	3295.5303
1054.2646	3.1235986	1.4532784	3297.9011
1055.1655	3.1282611	1.4564711	3284.7559
1056.0664	3.1273184	1.4588481	3284.2959
1056.9673	3.1327946	1.4617058	3286.9346
1057.8682	3.1336532	1.4651878	3281.5317
1058.769	3.1367757	1.4683406	3274.8218
1059.6699	3.1413736	1.4713448	3270.0137
1060.5708	3.1422727	1.4737045	3268.5764
1061.4717	3.1445627	1.4763134	3265.6155
1062.3726	3.147742	1.4794486	3263.9526
1063.2734	3.1496472	1.4829401	3257.8638
1064.1743	3.154012	1.4865575	3253.3713
1065.0752	3.159066	1.4893754	3245.2974
1065.9761	3.158354	1.4927372	3242.4519
1066.877	3.1648145	1.4960681	3231.4893
1067.7778	3.1642027	1.4999988	3219.2739
1068.6787	3.1666152	1.5038742	3200.5452
1069.5796	3.1700044	1.5070902	3201.4319
1070.4805	3.1692593	1.5104128	3191.7534
1071.3813	3.1750653	1.5138946	3184.2322
1072.2822	3.1782887	1.516587	3174.6672
1073.1831	3.1800883	1.5195765	3167.1833
1074.084	3.1827514	1.5239784	3158.0481
1074.9849	3.1889319	1.5328312	3099.1978
1075.8857	3.1926606	1.5390553	3066.7476
1076.7866	3.1912951	1.5445071	3025.7815
1077.0869	3.1956761	1.5492879	2977.9775