File: datasets/am_bench_2022/raw_data/90-XY.17-3/specimen.dat
MTS793|MPT|ENU|1|2|.|/|:|1|0|0|A

Operator Information						Time:	11.553711	Sec	11/3/2021 10:14:43 AM
Operator	Nick Derimow
Project	AM Bench 2022 mini-tensile challenge
Specimen ID	90-XY.17-3
Material	PBF-L Inconel 625
Specimen Width	2.54	mm
Specimen Thickness	1.51	mm
Notes
Operator Information End

Data Acquisition						Time:	978.91211	Sec	11/3/2021 10:30:50 AM
Time	Axial Displacement	Axial Extensometer	Axial Force
Sec	mm	mm	N
11.668701	0.002666652	1.9831818e-05	54.71603
12.469482	0.0091425385	0.00010712152	62.380253
13.270264	0.011484442	2.8613444e-05	73.523323
14.071045	0.012703697	6.3827742e-06	78.214798
14.871826	0.016348502	5.9059217e-05	85.704094
15.672607	0.015772963	5.9128881e-05	94.793236
16.473389	0.016963584	0.00014278894	99.281342
17.27417	0.020016205	0.00015408662	107.00288
18.074951	0.023979768	0.00020518643	116.56246
18.875732	0.025562501	0.00028786302	127.22288
19.676514	0.027719183	0.00027174628	132.19385
20.477295	0.028402904	0.00029400975	144.42209
21.278076	0.034089398	0.00035550469	155.81117
22.078857	0.034631949	0.00036411421	170.69164
22.879639	0.040242784	0.00052053819	181.9493
23.68042	0.043216981	0.00051789102	190.96758
24.481201	0.044128131	0.00050619995	205.95352
25.281982	0.044940524	0.00058184878	219.09276
26.082764	0.048614781	0.00068081415	234.30484
26.883545	0.05213983	0.0007551937	255.2197
27.684326	0.052971892	0.00081566419	267.67935
28.485107	0.056872196	0.00083863654	278.68457
29.285889	0.059376527	0.0010361986	295.29492
30.08667	0.057003532	0.00095302105	307.13107
30.887451	0.062319119	0.0011048196	319.59253
31.688232	0.063055702	0.0012303748	334.11252
32.489014	0.067925498	0.0012201712	352.60416
33.289795	0.067725733	0.0013072375	371.23315
34.090576	0.072227545	0.0014415743	381.36243
34.891357	0.073876508	0.0014884687	395.93777
35.692139	0.077425987	0.001541974	418.49219
36.49292	0.079926632	0.0016550021	437.19897
37.293701	0.081126474	0.0018132998	457.51254
38.094482	0.080979362	0.0018097921	475.86914
38.895264	0.085095413	0.0018239091	494.08575
39.696045	0.087558359	0.0019666136	511.64215
40.496826	0.090706043	0.0020279856	523.14844
41.297607	0.092714541	0.0021097043	544.92511
42.098389	0.095827654	0.0021607294	567.18182
42.89917	0.099255838	0.0023133464	591.7063
43.699951	0.10172805	0.0024620378	617.98914
44.500732	0.0999832	0.0024663939	628.05389
45.301514	0.1052761	0.0026049113	645.89612
46.102295	0.1064304	0.0028245884	669.4942
46.903076	0.111231	0.0028679925	689.55573
47.703857	0.11016905	0.002883306	706.73096
48.504639	0.11397833	0.0030364885	724.27399
49.30542	0.11864467	0.0031548203	750.25922
50.106201	0.11696436	0.0031982807	768.3949
50.906982	0.11990961	0.0032988116	794.35901
51.707764	0.12316164	0.0034674676	810.54529
52.508545	0.12849778	0.0035861435	838.91229
53.309326	0.12573732	0.0036650295	854.44568
54.110107	0.1306667	0.0038654837	883.39819
54.910889	0.13760488	0.0038275388	897.43945
55.71167	0.13355623	0.0040082959	917.67529
56.512451	0.13992275	0.0041203494	939.20239
57.313232	0.14197452	0.0042843134	969.94214
58.114014	0.14380927	0.0043737148	990.36078
58.914795	0.14462125	0.0045063025	1003.8802
59.715576	0.14727947	0.0046378775	1028.1611
60.516357	0.15060218	0.0047404775	1055.8403
61.317139	0.14957835	0.0047781039	1072.8535
62.11792	0.15551153	0.0050236587	1098.2183
62.918701	0.15691374	0.0049768207	1124.3185
63.719482	0.16041794	0.0051178951	1145.0496
64.520264	0.16311471	0.0053661666	1163.2092
65.321045	0.16730367	0.0054226541	1188.6208
66.121826	0.16674472	0.0053778985	1203.5784
66.922607	0.16952135	0.005737212	1228.9867
67.723389	0.17267729	0.0057486724	1249.601
68.52417	0.17245232	0.0059443954	1270.2391
69.324951	0.1751308	0.0061329096	1300.0055
70.125732	0.17904115	0.0060203546	1318.9692
70.926514	0.179387	0.0063083954	1343.7399
71.727295	0.18306655	0.0063321181	1368.037
72.528076	0.18703339	0.0064813718	1393.8149
73.328857	0.18865263	0.0067993174	1407.6637
74.129639	0.19178726	0.0068144752	1432.576
74.93042	0.1909468	0.0068801786	1450.9623
75.731201	0.19460569	0.0071583274	1473.0566
76.531982	0.19846784	0.0072633373	1499.6525
77.332764	0.19870755	0.0073383632	1524.3832
78.133545	0.20320487	0.0074825315	1544.1373
78.934326	0.20402217	0.0075554512	1560.2872
79.735107	0.20566581	0.0076991883	1585.5164
80.535889	0.209371	0.0077536809	1603.4438
81.33667	0.21312231	0.0079483818	1632.4325
82.137451	0.21203761	0.0080849854	1648.9286
82.938232	0.2166179	0.0081922682	1676.8043
83.739014	0.22103919	0.0082765194	1702.6182
84.539795	0.22219478	0.0084337462	1715.0077
85.340576	0.22193804	0.0084684175	1725.2925
86.141357	0.2276208	0.0085852621	1760.0776
86.942139	0.22710344	0.0087312646	1778.2318
87.74292	0.22806296	0.0087727429	1793.1826
88.543701	0.23308852	0.0089758113	1822.4651
89.344482	0.23810537	0.0089921951	1846.183
90.145264	0.23882331	0.009087367	1864.7781
90.946045	0.24195728	0.0092911804	1884.9761
91.746826	0.24425472	0.0093469443	1909.8384
92.547607	0.2436464	0.00947404	1923.1661
93.348389	0.24759746	0.0094988272	1941.6604
94.14917	0.24929334	0.0097321663	1966.4193
94.949951	0.25142416	0.0098319845	1985.2944
95.750732	0.25560921	0.0098904027	2012.46
96.551514	0.25823081	0.010019531	2025.7983
97.352295	0.25807774	0.010039394	2039.8992
98.153076	0.26259944	0.010176345	2061.9224
98.953857	0.26653472	0.010201862	2080.144
99.754639	0.26596758	0.010354979	2089.9666
100.55542	0.27215707	0.010447019	2111.5398
101.3562	0.27309179	0.01053145	2133.3123
102.15698	0.27237159	0.010639966	2141.4412
102.95776	0.27784863	0.010735011	2165.5891
103.75854	0.27947733	0.010966273	2182.9119
104.55933	0.28478703	0.010964921	2193.3662
105.36011	0.28775439	0.011095233	2217.2886
106.16089	0.28774047	0.011188552	2230.5757
106.96167	0.28826869	0.011185089	2240.7969
107.76245	0.2926324	0.011279195	2260.7698
108.56323	0.2941635	0.011418384	2276.563
109.36401	0.29913825	0.011497377	2287.8123
110.16479	0.30095905	0.011522758	2302.98
110.96558	0.30258527	0.011615302	2321.531
111.76636	0.30419055	0.011800596	2331.0176
112.56714	0.30668324	0.011812491	2349.1628
113.36792	0.30840632	0.011828657	2356.6526
114.1687	0.30966845	0.01193839	2366.3455
114.96948	0.31436062	0.01192992	2378.6367
115.77026	0.31409878	0.012165838	2391.082
116.57104	0.31893536	0.01219723	2406.4275
117.37183	0.32045853	0.012332059	2423.394
118.17261	0.32462084	0.012480325	2430.1191
118.97339	0.33003423	0.012590691	2444.9875
119.77417	0.3307476	0.012621859	2465.5405
120.57495	0.329238	0.012713923	2466.2842
121.37573	0.3336716	0.012795555	2476.1677
122.17651	0.33737844	0.012894123	2483.3647
122.97729	0.3391239	0.012997837	2495.5569
123.77808	0.34178457	0.013035938	2505.4595
124.57886	0.34410122	0.013103954	2517.4514
125.37964	0.34367037	0.013230726	2526.5691
126.18042	0.34903044	0.01337439	2533.4932
126.9812	0.35133976	0.013357638	2545.103
127.78198	0.35177904	0.013463156	2549.592
128.58276	0.3553158	0.013616761	2560.0603
129.38354	0.35653019	0.013818465	2573.9238
130.18433	0.36133868	0.013901221	2588.3381
130.98511	0.36357692	0.013844019	2588.9692
131.78589	0.36355847	0.014096458	2601.2542
132.58667	0.36760911	0.014163122	2612.4351
133.38745	0.3705155	0.014254289	2619.4644
134.18823	0.37414038	0.01435649	2627.4924
134.98901	0.37037247	0.014465615	2634.666
135.78979	0.37583312	0.014584704	2638.5596
136.59058	0.37912491	0.014722377	2655.0364
137.39136	0.38046348	0.014752082	2660.5046
138.19214	0.38403118	0.014884001	2667.96
138.99292	0.38734052	0.015102674	2679.0476
139.7937	0.38932586	0.015191764	2684.3552
140.59448	0.39319196	0.015276458	2691.1025
141.39526	0.39565799	0.015487538	2697.7454
142.19604	0.39789554	0.015505847	2708.1384
142.99683	0.39914969	0.015800005	2714.0161
143.79761	0.40059233	0.015840635	2720.0828
144.59839	0.40445158	0.016021624	2728.6514
145.39917	0.403907	0.016097676	2732.2529
146.19995	0.40870816	0.016351599	2745.5879
147.00073	0.40996331	0.01644285	2751.0996
147.80151	0.41111234	0.016607361	2746.5691
148.60229	0.41682091	0.016782887	2764.2063
149.40308	0.41462222	0.016941788	2763.0984
150.20386	0.4188059	0.017136449	2769.8081
151.00464	0.42179602	0.01736233	2782.3376
151.80542	0.42403364	0.017566551	2786.8511
152.6062	0.42790869	0.017645244	2794.4758
153.40698	0.42612612	0.017867381	2796.5337
154.20776	0.42944041	0.018077137	2804.6494
155.00854	0.43537563	0.018322609	2811.135
155.80933	0.43609869	0.01853703	2820.0161
156.61011	0.43943837	0.018794231	2832.7771
157.41089	0.44467184	0.018960871	2830.8091
158.21167	0.44569403	0.019243401	2842.2336
159.01245	0.4446995	0.019377111	2845.0928
159.81323	0.44844219	0.019784478	2857.0305
160.61401	0.45141003	0.020113848	2858.2986
161.41479	0.4540709	0.020327482	2860.3916
162.21558	0.45709032	0.020627202	2864.0188
163.01636	0.4571985	0.020907605	2875.4324
163.81714	0.45840409	0.021213064	2879.2585
164.61792	0.46522748	0.021557141	2890.4009
165.4187	0.46619067	0.022009151	2889.187
166.21948	0.46706596	0.022239765	2888.7568
167.02026	0.47072384	0.022564026	2897.9502
167.82104	0.47450817	0.022996558	2912.02
168.62183	0.47682482	0.023291884	2911.6414
169.42261	0.47906524	0.02365369	2915.7654
170.22339	0.4804042	0.024157956	2919.6799
171.02417	0.48115534	0.024511259	2925.772
171.82495	0.48422906	0.024975	2932.3435
172.62573	0.48715061	0.025366681	2931.5525
173.42651	0.49190173	0.025731063	2940.4517
174.22729	0.49056855	0.026240118	2947.2668
175.02808	0.49767876	0.026697472	2957.7969
175.82886	0.49649614	0.027266325	2956.7083
176.62964	0.4999676	0.027747089	2956.4839
177.43042	0.50241417	0.028209481	2961.4255
178.2312	0.50257933	0.028686089	2966.0259
179.03198	0.50854284	0.029334828	2974.5388
179.83276	0.50766629	0.029831028	2977.9641
180.63354	0.51043409	0.03042715	2977.8345
181.43433	0.51109529	0.031040989	2982.8477
182.23511	0.51641768	0.031656519	2988.074
183.03589	0.51913655	0.032229137	2989.8499
183.83667	0.51985818	0.032886907	2992.5962
184.63745	0.52387971	0.03355604	3000.552
185.43823	0.52540022	0.034317106	3011.1724
186.23901	0.52654594	0.035020418	3009.6077
187.03979	0.53331077	0.035723869	3014.9495
187.84058	0.5308941	0.03627789	3004.6362
188.64136	0.53315419	0.036829773	3013.5786
189.44214	0.53773385	0.037419297	3018.4546
190.24292	0.54265243	0.038080595	3023.7454
191.0437	0.54238528	0.038753901	3023.2021
191.84448	0.54529798	0.039393168	3029.9392
192.64526	0.54473513	0.039942209	3027.7859
193.44604	0.55120963	0.040742654	3043.4185
194.24683	0.54974031	0.041562766	3036.1533
195.04761	0.55491054	0.042278308	3042.0603
195.84839	0.55440223	0.04294477	3040.2617
196.64917	0.56013376	0.043557968	3052.8582
197.44995	0.56038225	0.044260554	3046.4661
198.25073	0.56542236	0.044964809	3049.7612
199.05151	0.56372893	0.045784205	3060.7847
199.85229	0.5709064	0.046722848	3061.8037
200.65308	0.57135922	0.047400739	3059.5674
201.45386	0.57443744	0.048108771	3065.8228
202.25464	0.57673341	0.04882732	3068.76
203.05542	0.57837951	0.049572363	3071.0593
203.8562	0.58231258	0.050307479	3071.3711
204.65698	0.58294111	0.051102765	3073.1191
205.45776	0.58857739	0.051849034	3083.1724
206.25854	0.5866006	0.052685	3079.4116
207.05933	0.59080309	0.053431951	3082.1892
207.86011	0.59266472	0.054198723	3080.2488
208.66089	0.59542769	0.054886214	3090.4465
209.46167	0.59821332	0.055861317	3094.8833
210.26245	0.598324	0.056765728	3093.8379
211.06323	0.60215783	0.057498313	3091.9812
211.86401	0.60618943	0.058274187	3097.9546
212.66479	0.6063388	0.059215777	3102.5522
213.46558	0.61132127	0.059914105	3102.8342
214.26636	0.61128992	0.060674522	3104.9502
215.06714	0.61254656	0.061376166	3107.6946
215.86792	0.61782116	0.062219452	3113.6348
216.6687	0.62263465	0.063033082	3116.9927
217.46948	0.61989403	0.063762322	3112.6897
218.27026	0.6242907	0.064542316	3117.0383
219.07104	0.62798715	0.065443859	3121.7
219.87183	0.62814736	0.066257201	3122.6067
220.67261	0.63043141	0.067133576	3124.9773
221.47339	0.63675839	0.067960031	3128.3032
222.27417	0.63868272	0.068920664	3134.6292
223.07495	0.63922119	0.069788441	3132.8943
223.87573	0.63898498	0.07067696	3133.6023
224.67651	0.64709258	0.071430147	3132.2961
225.47729	0.64808631	0.072119467	3140.1565
226.27808	0.6505667	0.072789699	3131.0178
227.07886	0.65032756	0.073321238	3127.5002
227.87964	0.65481383	0.074053116	3139.2371
228.68042	0.65612346	0.074714281	3141.8391
229.4812	0.65993255	0.075689144	3153.1914
230.28198	0.66072094	0.076564826	3152.2397
231.08276	0.66331851	0.077467069	3149.7229
231.88354	0.66473413	0.078279868	3152.5
232.68433	0.66795087	0.079257093	3163.0791
233.48511	0.67110509	0.080243811	3162.5649
234.28589	0.67347074	0.081310444	3168.0239
235.08667	0.67220414	0.082114771	3165.8616
235.88745	0.67686617	0.083014637	3170.2698
236.68823	0.67797542	0.08393842	3164.8245
237.48901	0.68013966	0.084737837	3168.6807
238.28979	0.68379468	0.085659958	3165.9988
239.09058	0.69048083	0.086448707	3172.8037
239.89136	0.6887325	0.087264106	3175.05
240.69214	0.69299728	0.088299073	3188.5137
241.49292	0.69316322	0.088951752	3174.9177
242.2937	0.69815856	0.089650899	3180.1489
243.09448	0.69886422	0.090421207	3180.2581
243.89526	0.70146883	0.091347188	3189.7002
244.69604	0.70391965	0.092107832	3184.1228
245.49683	0.70595115	0.093003117	3188.146
246.29761	0.70866901	0.093779504	3192.3467
247.09839	0.71034741	0.094845526	3203.4768
247.89917	0.71377379	0.095779285	3192.5977
248.69995	0.71502507	0.096649721	3199.3892
249.50073	0.71771234	0.097515434	3198.4897
250.30151	0.72063875	0.098246716	3199.7314
251.10229	0.72438145	0.099087037	3201.7466
251.90308	0.72583026	0.099984556	3201.8289
252.70386	0.73174191	0.10103548	3215.3323
253.50464	0.72999406	0.1018782	3206.5952
254.30542	0.73377907	0.10264179	3203.5249
255.1062	0.73400593	0.10352727	3213.6768
255.90698	0.73942214	0.10458843	3214.6245
256.70776	0.73843557	0.10541429	3217.8804
257.50854	0.7426883	0.10630771	3218.8228
258.30933	0.74578762	0.10713138	3219.2061
259.11011	0.74484843	0.10789885	3216.4885
259.91089	0.74899596	0.10880682	3216.7324
260.71167	0.75092685	0.1097394	3224.5496
261.51245	0.75521398	0.11065789	3226.0178
262.31323	0.75497139	0.11160234	3228.823
263.11401	0.76045191	0.11245809	3231.4148
263.91479	0.76269543	0.11325108	3231.0542
264.71558	0.76665062	0.11415426	3229.5413
265.51636	0.76626319	0.11490413	3225.1953
266.31714	0.76707882	0.11564833	3228.4973
267.11792	0.77104878	0.11647272	3233.6206
267.9187	0.77423269	0.11724574	3233.5994
268.71948	0.7768836	0.11799704	3242.7734
269.52026	0.78111553	0.11894502	3244.7319
270.32104	0.77986634	0.11987683	3243.8108
271.12183	0.78545082	0.12078368	3251.2961
271.92261	0.78801125	0.12159554	3249.0288
272.72339	0.7882629	0.12238211	3241.7373
273.52417	0.79092211	0.12309523	3248.3779
274.32495	0.79116225	0.12383637	3249.9087
275.12573	0.79478818	0.12476483	3258.2908
275.92651	0.79732573	0.12578963	3254.4631
276.72729	0.79826432	0.12669204	3255.3501
277.52808	0.80021757	0.12754597	3254.5076
278.32886	0.80529344	0.12842028	3260.6877
279.12964	0.803581	0.12930542	3260.4998
279.93042	0.81022269	0.13020442	3262.9797
280.7312	0.81005448	0.13116439	3263.6758
281.53198	0.81525469	0.13226017	3268.7671
282.33276	0.81505984	0.13330816	3264.8149
283.13354	0.81879354	0.13420512	3273.0017
283.93433	0.82026464	0.13513759	3270.5452
284.73511	0.82187921	0.13599949	3268.9949
285.53589	0.82378423	0.13702576	3277.0364
286.33667	0.82881999	0.137758	3268.1738
287.13745	0.83346868	0.13844532	3276.8645
287.93823	0.83360946	0.13937268	3278.7947
288.73901	0.83574033	0.14005733	3280.0815
289.53979	0.83814853	0.14088304	3279.2319
290.34058	0.84089571	0.14170258	3278.8765
291.14136	0.84180683	0.14268418	3287.0969
291.94214	0.84773815	0.14361347	3290.4182
292.74292	0.84968382	0.14447995	3284.7251
293.5437	0.85094082	0.14537086	3290.8682
294.34448	0.85123336	0.14629917	3290.0901
295.14526	0.85661519	0.14725013	3297.3848
295.94604	0.85781127	0.14828594	3294.7397
296.74683	0.85841936	0.14913556	3298.5212
297.54761	0.86627877	0.14984551	3292.2007
298.34839	0.86601424	0.15059064	3292.4419
299.14917	0.86650759	0.15137467	3296.0103
299.94995	0.8710596	0.15214737	3308.3262
300.75073	0.87367499	0.15292701	3298.1042
301.55151	0.87410671	0.15371646	3302.1372
302.35229	0.87727845	0.15463281	3304.4258
303.15308	0.87963587	0.15573123	3309.2393
303.95386	0.88199002	0.15670416	3318.2627
304.75464	0.88270426	0.15777627	3312.8667
305.55542	0.88507581	0.15885232	3312.6729
306.3562	0.88847905	0.15970065	3305.896
307.15698	0.89214182	0.16049425	3308.9014
307.95776	0.89475864	0.1613604	3315.9817
308.75854	0.89540219	0.16218944	3316.6963
309.55933	0.89857876	0.16325472	3325.5669
310.36011	0.90186685	0.16416341	3311.2366
311.16089	0.90409034	0.16488792	3319.8279
311.96167	0.90611833	0.16581444	3318.9358
312.76245	0.90848744	0.16651069	3317.6946
313.56323	0.91267759	0.16724735	3328.3474
314.36401	0.91347808	0.16812897	3330.7102
315.16479	0.91572654	0.16890249	3325.8264
315.96558	0.91859066	0.16985889	3333.1707
316.76636	0.91998619	0.17103031	3333.9282
317.56714	0.92170537	0.17206898	3335.6848
318.36792	0.92693007	0.1730613	3337.3879
319.1687	0.92921072	0.17400241	3337.9834
319.96948	0.92921543	0.17476535	3331.4468
320.77026	0.93280774	0.17568663	3343.3911
321.57104	0.9350121	0.17665286	3340.8433
322.37183	0.93648565	0.17744756	3335.1968
323.17261	0.94082415	0.17827074	3341.217
323.97339	0.93950099	0.1792445	3350.1328
324.77417	0.94275361	0.18031871	3350.3853
325.57495	0.94849253	0.18111932	3350.6245
326.37573	0.9488169	0.1821411	3347.157
327.17651	0.95303923	0.18294972	3348.7061
327.97729	0.9553768	0.18372084	3347.8945
328.77808	0.9546892	0.1846325	3348.8823
329.57886	0.95940346	0.18539678	3353.9688
330.37964	0.96274745	0.18630412	3351.709
331.18042	0.96441483	0.18712741	3356.7068
331.9812	0.96645677	0.18817504	3359.1047
332.78198	0.96775782	0.18892092	3356.772
333.58276	0.97346354	0.18975793	3359.6589
334.38354	0.9716323	0.1906198	3360.668
335.18433	0.97811681	0.19138215	3354.7429
335.98511	0.98042893	0.1922781	3365.1365
336.78589	0.97948933	0.19316547	3367.0115
337.58667	0.98360926	0.19415464	3368.2815
338.38745	0.98409116	0.19499826	3365.5291
339.18823	0.98592877	0.19589904	3367.8035
339.98901	0.99201459	0.19683273	3370.3364
340.78979	0.98995727	0.197807	3367.9558
341.59058	0.9933207	0.19884074	3376.1223
342.39136	0.99942499	0.19993621	3377.6899
343.19214	1.0017257	0.20087989	3377.6729
343.99292	1.0033978	0.20166758	3378.0227
344.7937	1.0053293	0.20264252	3381.8433
345.59448	1.0073279	0.20355628	3385.3975
346.39526	1.0064025	0.20426518	3378.1206
347.19604	1.011627	0.20524062	3377.9089
347.99683	1.015448	0.20610078	3384.345
348.79761	1.0166821	0.20682769	3386.6084
349.59839	1.0198284	0.20780906	3391.7085
350.39917	1.0226535	0.20897432	3391.928
351.19995	1.0239944	0.2099807	3388.2959
352.00073	1.0251924	0.21098232	3395.4111
352.80151	1.0279393	0.21194096	3388.7148
353.60229	1.0311965	0.21286386	3391.1191
354.40308	1.0347588	0.21373987	3400.1602
355.20386	1.0359173	0.21482	3399.979
356.00464	1.0382029	0.21566071	3395.5229
356.80542	1.0411617	0.21632835	3391.9539
357.6062	1.0446208	0.21715008	3402.3855
358.40698	1.0455503	0.21792352	3392.353
359.20776	1.0477705	0.21855006	3399.0767
360.00854	1.0504969	0.21934359	3403.8792
360.80933	1.0514784	0.22057062	3417.6333
361.61011	1.0547798	0.22162357	3412.3713
362.41089	1.0604941	0.2226719	3410.9585
363.21167	1.0591288	0.22345018	3405.0161
364.01245	1.0601349	0.22441243	3407.8806
364.81323	1.0617665	0.22537369	3403.1733
365.61401	1.0649157	0.22613703	3406.3218
366.41479	1.0705531	0.2270721	3416.4441
367.21558	1.073741	0.22789586	3415.1006
368.01636	1.0731708	0.22860564	3408.5293
368.81714	1.0762736	0.229638	3419.7258
369.61792	1.0798554	0.23054297	3421.1128
370.4187	1.0828128	0.23131451	3419.3733
371.21948	1.0843804	0.23237093	3427.9812
372.02026	1.0854901	0.23321161	3419.9377
372.82104	1.0876654	0.23430905	3429.4431
373.62183	1.0926311	0.23528634	3420.9968
374.42261	1.0932046	0.23626992	3424.5815
375.22339	1.0946232	0.23711301	3425.5134
376.02417	1.0989759	0.23817445	3431.0879
376.82495	1.0999366	0.23911579	3424.2522
377.62573	1.1050544	0.23999219	3427.3433
378.42651	1.1062076	0.24079046	3429.1819
379.22729	1.108511	0.24181859	3434.0332
380.02808	1.10879	0.24271362	3432.302
380.82886	1.1108494	0.24358812	3429.198
381.62964	1.1166846	0.24437381	3440.3276
382.43042	1.1159792	0.24516936	3434.0991
383.2312	1.1182327	0.24609914	3435.0408
384.03198	1.120253	0.24694808	3437.0647
384.83276	1.1242623	0.24772942	3437.5774
385.63354	1.1253372	0.24859412	3443.5881
386.43433	1.1271089	0.24958529	3447.1091
387.23511	1.1328166	0.25070217	3447.7214
388.03589	1.1338502	0.25150806	3442.9509
388.83667	1.1368362	0.25243562	3444.6536
389.63745	1.1355228	0.2533094	3443.6091
390.43823	1.1414529	0.25420755	3447.7646
391.23901	1.1419417	0.25490531	3443.196
392.03979	1.1458759	0.25584331	3453.2649
392.84058	1.1486616	0.25690609	3458.8193
393.64136	1.1527278	0.2578418	3461.301
394.44214	1.1533723	0.25891128	3454.1028
395.24292	1.1534594	0.25994268	3453.8782
396.0437	1.1578002	0.26096135	3460.4268
396.84448	1.1580014	0.26200253	3455.7761
397.64526	1.1633373	0.2630991	3456.2253
398.44604	1.164379	0.26391479	3458.321
399.24683	1.1655768	0.26493469	3459.2747
400.04761	1.1694624	0.26576838	3461.8901
400.84839	1.1713301	0.26652926	3459.1306
401.64917	1.1751983	0.26726037	3462.2813
402.44995	1.1786859	0.26808521	3468.127
403.25073	1.1818496	0.26895109	3466.6333
404.05151	1.1823082	0.26988006	3465.5803
404.85229	1.1841702	0.27075154	3467.5129
405.65308	1.1885784	0.27161014	3470.8567
406.45386	1.1898726	0.27258191	3473.1169
407.25464	1.1906588	0.2734561	3469.6658
408.05542	1.1961955	0.27440384	3472.031
408.8562	1.1990321	0.27538496	3482.7063
409.65698	1.2001251	0.27637604	3475.3037
410.45776	1.2046664	0.27724445	3474.667
411.25854	1.2030587	0.27822626	3473.5083
412.05933	1.2062972	0.27918941	3478.1636
412.86011	1.2105207	0.28009462	3479.3411
413.66089	1.2076975	0.28095174	3477.5535
414.46167	1.2163048	0.28186616	3481.4409
415.26245	1.2171943	0.28268361	3484.2605
416.06323	1.2190695	0.28369626	3485.6851
416.86401	1.2207192	0.28481433	3489.9482
417.66479	1.2221586	0.285705	3485.1313
418.46558	1.2244365	0.2865549	3477.1172
419.26636	1.2274927	0.28730461	3481.2004
420.06714	1.2296036	0.2882767	3486.2371
420.86792	1.2360637	0.288941	3489.8508
421.6687	1.2363799	0.28994653	3491.1301
422.46948	1.2375556	0.29087448	3489.5981
423.27026	1.2431873	0.29182592	3494.8669
424.07104	1.2434238	0.29288554	3502.2395
424.87183	1.2463002	0.29399067	3499.6941
425.67261	1.246173	0.29479143	3486.6895
426.47339	1.2484862	0.29573706	3497.012
427.27417	1.2545687	0.29658562	3495.8525
428.07495	1.2536887	0.29750773	3504.0027
428.87573	1.2567166	0.29843861	3506.0525
429.67651	1.2595274	0.29947555	3505.4192
430.47729	1.2615945	0.30040556	3502.4666
431.27808	1.2621676	0.3012372	3502.1904
432.07886	1.2667834	0.30227271	3504.5696
432.87964	1.269266	0.30320725	3505.0334
433.68042	1.272586	0.3040944	3503.7515
434.4812	1.275732	0.30503029	3506.9543
435.28198	1.2763791	0.30599177	3512.6812
436.08276	1.277741	0.30698884	3512.4138
436.88354	1.2831692	0.30796352	3515.3062
437.68433	1.2855533	0.30889061	3509.9165
438.48511	1.2853487	0.30988121	3509.855
439.28589	1.2852343	0.31084096	3511.4167
440.08667	1.2918144	0.31189921	3518.7209
440.88745	1.2927005	0.3128697	3507.5298
441.68823	1.2968237	0.31356969	3515.1414
442.48901	1.298967	0.31443495	3521.301
443.28979	1.300809	0.31524044	3513.4875
444.09058	1.3000964	0.31609359	3517.0269
444.89136	1.3048947	0.31699178	3520.6472
445.69214	1.3067117	0.31779152	3517.4368
446.49292	1.3097178	0.31871733	3523.6318
447.2937	1.309101	0.31955105	3525.094
448.09448	1.3132461	0.32061893	3522.4424
448.89526	1.3173277	0.32155386	3526.6692
449.69604	1.3189242	0.32259744	3524.5044
450.49683	1.3226296	0.32367316	3529.0593
451.29761	1.3234799	0.32446414	3526.865
452.09839	1.3270048	0.32541078	3527.0137
452.89917	1.3274736	0.32642061	3537.1138
453.69995	1.3306112	0.32746875	3528.4099
454.50073	1.3334537	0.32842389	3528.4785
455.30151	1.3347615	0.3294563	3533.5027
456.10229	1.3362025	0.33048511	3531.9844
456.90308	1.3399419	0.33149713	3534.7383
457.70386	1.3419833	0.33242214	3531.3586
458.50464	1.3437635	0.33316311	3525.2908
459.30542	1.3461654	0.33391941	3531.9978
460.1062	1.3484777	0.33481857	3536.752
460.90698	1.3536944	0.33584204	3543.4824
461.70776	1.3562219	0.33685932	3541.5417
462.50854	1.3570726	0.33779502	3543.7781
463.30933	1.3567983	0.33890557	3544.8291
464.11011	1.3602858	0.33994338	3547.5476
464.91089	1.3658234	0.34097001	3543.6025
465.71167	1.3654845	0.3420001	3544.4768
466.51245	1.3710657	0.34297499	3548.7004
467.31323	1.3725578	0.34376568	3541.585
468.11401	1.3742583	0.34465227	3545.1475
468.91479	1.3761295	0.34549063	3546.772
469.71558	1.3791256	0.34646568	3548.856
470.51636	1.3825769	0.34732834	3550.1943
471.31714	1.3833637	0.34836647	3552.1338
472.11792	1.3849375	0.34937039	3555.2036
472.9187	1.3892682	0.35039967	3553.2925
473.71948	1.391657	0.35132274	3550.9048
474.52026	1.3920504	0.35249582	3561.1926
475.32104	1.3992764	0.35351759	3561.6084
476.12183	1.3975775	0.3545056	3552.6321
476.92261	1.4011791	0.3553519	3555.0498
477.72339	1.4057671	0.35624236	3563.7249
478.52417	1.4051249	0.35719511	3559.7463
479.32495	1.4087	0.3582963	3560.249
480.12573	1.4111995	0.35930189	3561.324
480.92651	1.4132484	0.36012754	3560.3079
481.72729	1.4140911	0.3609626	3557.6946
482.52808	1.4193006	0.36181483	3562.8796
483.32886	1.4214607	0.36278608	3567.8613
484.12964	1.4250524	0.36365664	3564.3879
484.93042	1.4258753	0.36463082	3572.3699
485.7312	1.4288957	0.36560065	3575.3281
486.53198	1.4292885	0.3667402	3568.4724
487.33276	1.4337401	0.36783528	3572.251
488.13354	1.435473	0.3688525	3577.9834
488.93433	1.4347812	0.36974332	3564.8416
489.73511	1.440197	0.37072384	3575.1785
490.53589	1.4433719	0.37161949	3571.9585
491.33667	1.4453255	0.37258372	3576.6357
492.13745	1.444152	0.37357479	3579.5454
492.93823	1.4504211	0.37476218	3584.6685
493.73901	1.4511822	0.37580919	3580.5022
494.53979	1.4527293	0.37675542	3575.1614
495.34058	1.456525	0.37769774	3583.5474
496.14136	1.4602914	0.37882128	3581.2888
496.94214	1.4598304	0.37982017	3579.877
497.74292	1.4631189	0.38093373	3579.2756
498.5437	1.4643879	0.38176361	3576.679
499.34448	1.4690239	0.38277829	3581.2209
500.14526	1.4714851	0.38352624	3582.0715
500.94604	1.4727024	0.38448602	3586.9453
501.74683	1.4743173	0.38548401	3586.5867
502.54761	1.4775383	0.38631967	3585.4121
503.34839	1.4798831	0.38725331	3586.6077
504.14917	1.4833655	0.38822371	3586.7532
504.94995	1.4864619	0.38912097	3584.406
505.75073	1.4897765	0.39003631	3585.5967
506.55151	1.4910409	0.39109635	3595.5764
507.35229	1.4935017	0.39211723	3595.6687
508.15308	1.494841	0.3931241	3596.6042
508.95386	1.4961313	0.39409068	3590.7126
509.75464	1.4984577	0.39495939	3587.1006
510.55542	1.5033849	0.3959505	3593.8601
511.3562	1.5041776	0.39695576	3597.4915
512.15698	1.5068763	0.39803484	3598.2078
512.95776	1.5102237	0.39896911	3592.9058
513.75854	1.5121256	0.39975548	3592.3718
514.55933	1.5133846	0.40055409	3597.137
515.36011	1.5175338	0.40160447	3607.4053
516.16089	1.5182046	0.40256009	3603.8979
516.96167	1.5208651	0.40358877	3601.4829
517.76245	1.5230008	0.40482411	3603.0669
518.56323	1.5244017	0.40589884	3601.6768
519.36401	1.529084	0.4069041	3599.8164
520.16479	1.5295161	0.40780494	3597.998
520.96558	1.5357804	0.40875098	3602.4812
521.76636	1.5362295	0.40970492	3606.6282
522.56714	1.5372359	0.41061753	3607.6067
523.36792	1.5399853	0.41174382	3609.5671
524.1687	1.544224	0.41276687	3610.189
524.96948	1.5453421	0.41384944	3612.8787
525.77026	1.547204	0.41495892	3611.3354
526.57104	1.5487084	0.41593549	3611.417
527.37183	1.549619	0.41686815	3609.7202
528.17261	1.5565659	0.41811603	3619.5994
528.97339	1.5581194	0.41902521	3609.387
529.77417	1.5590049	0.4198288	3605.6658
530.57495	1.5608538	0.42081302	3614.5208
531.37573	1.5656247	0.42191771	3623.9146
532.17651	1.5652376	0.42304337	3618.78
532.97729	1.5749754	0.42401448	3617.7595
533.77808	1.5712906	0.42481512	3614.0776
534.57886	1.5720346	0.42572007	3614.1716
535.37964	1.5746484	0.42672211	3617.3835
536.18042	1.5785519	0.42773756	3619.6753
536.9812	1.582739	0.4288719	3625.8242
537.78198	1.581566	0.42983359	3621.6086
538.58276	1.5825822	0.43097743	3622.6631
539.38354	1.5890778	0.43196619	3622.7056
540.18433	1.5891136	0.43300435	3622.0632
540.98511	1.5906674	0.43396679	3625.053
541.78589	1.5949457	0.43494684	3621.7725
542.58667	1.593182	0.43590483	3625.3484
543.38745	1.601531	0.43709326	3630.2712
544.18823	1.6040978	0.43821058	3629.0195
544.98901	1.6046828	0.43916973	3621.5769
545.78979	1.6055442	0.44020775	3628.7903
546.59058	1.6121745	0.44134393	3634.4993
547.39136	1.6102918	0.44235772	3629.6077
548.19214	1.6165289	0.4431988	3629.0881
548.99292	1.6161426	0.44407526	3628.5032
549.7937	1.6168108	0.44523066	3629.4031
550.59448	1.6213269	0.44630355	3634.5498
551.39526	1.6241351	0.44760329	3637.3694
552.19604	1.6261295	0.44854921	3631.9932
552.99683	1.630301	0.44950759	3629.1167
553.79761	1.6315632	0.45053643	3638.4438
554.59839	1.6329843	0.4514775	3632.1848
555.39917	1.6363	0.45249376	3643.2502
556.19995	1.6358339	0.45355016	3635.9097
557.00073	1.6427243	0.45458332	3640.3923
557.80151	1.6434752	0.45548981	3642.3423
558.60229	1.6460485	0.45653045	3641.3054
559.40308	1.6476305	0.45752507	3643.1245
560.20386	1.6497065	0.45857617	3639.1267
561.00464	1.6523993	0.45970592	3644.312
561.80542	1.6564105	0.46081164	3647.0232
562.6062	1.6601552	0.46179721	3640.7327
563.40698	1.6592159	0.46276259	3638.7871
564.20776	1.6629198	0.46367714	3640.3191
565.00854	1.6654339	0.46466485	3642.9858
565.80933	1.6677588	0.46572882	3645.9905
566.61011	1.6692914	0.46698278	3651.8503
567.41089	1.669646	0.46801296	3646.0291
568.21167	1.674711	0.46913108	3651.519
569.01245	1.6767763	0.47019318	3652.4019
569.81323	1.6787494	0.47137076	3647.5735
570.61401	1.681525	0.47231373	3643.7058
571.41479	1.683503	0.47326851	3648.219
572.21558	1.6874681	0.47429362	3646.4983
573.01636	1.6885428	0.47529897	3649.0283
573.81714	1.6927861	0.47635454	3657.7456
574.61792	1.6913992	0.47718558	3648.1331
575.4187	1.6981668	0.47827032	3657.0508
576.21948	1.698408	0.47939795	3657.969
577.02026	1.7011429	0.48055285	3658.2268
577.82104	1.7036837	0.48156381	3652.9563
578.62183	1.7035335	0.48269328	3656.0798
579.42261	1.7092608	0.48384765	3662.8215
580.22339	1.7096794	0.48503593	3663.9226
581.02417	1.712556	0.48620644	3655.8716
581.82495	1.716574	0.48732948	3660.5728
582.62573	1.7175578	0.48841399	3661.5378
583.42651	1.7186331	0.489528	3656.5427
584.22729	1.7252051	0.49047756	3657.3403
585.02808	1.7254537	0.49125445	3655.146
585.82886	1.7269669	0.49222836	3660.5898
586.62964	1.7296132	0.49331227	3663.3633
587.43042	1.7333381	0.49434337	3659.1555
588.2312	1.7332498	0.4952516	3656.0249
589.03198	1.7358896	0.49622065	3667.9141
589.83276	1.7379179	0.49716836	3663.3191
590.63354	1.7410771	0.4981837	3667.9727
591.43433	1.7452433	0.4992801	3669.1313
592.23511	1.7448331	0.50014484	3665.1653
593.03589	1.7489526	0.50109565	3669.5667
593.83667	1.7513846	0.50212204	3674.519
594.63745	1.7529969	0.50330162	3673.7563
595.43823	1.7559738	0.50441748	3670.3872
596.23901	1.7577233	0.50554961	3669.1614
597.03979	1.7618731	0.50662398	3675.6074
597.84058	1.7645425	0.50791532	3674.1313
598.64136	1.7658408	0.50914925	3668.5149
599.44214	1.7701293	0.51024514	3668.3325
600.24292	1.7695878	0.51134199	3671.2029
601.0437	1.7708907	0.51245546	3677.0764
601.84448	1.7754341	0.51363915	3673.8459
602.64526	1.7793489	0.5146668	3677.9175
603.44604	1.7819406	0.51580179	3676.8889
604.24683	1.7826	0.51695114	3683.6814
605.04761	1.7867829	0.51809996	3677.7668
605.84839	1.7861036	0.51930153	3682.8167
606.64917	1.7896113	0.52042913	3678.0298
607.44995	1.7916325	0.52145457	3669.8689
608.25073	1.7969607	0.52247649	3679.1099
609.05151	1.7964864	0.52353358	3678.7751
609.85229	1.7994009	0.52474755	3688.908
610.65308	1.8019167	0.52595681	3678.7842
611.45386	1.8074086	0.52729082	3690.3311
612.25464	1.8067791	0.52853107	3685.645
613.05542	1.8120325	0.52956384	3687.0764
613.8562	1.8115538	0.53072751	3680.9087
614.65698	1.814712	0.53169888	3682.2668
615.45776	1.8156142	0.53271323	3678.9402
616.25854	1.8226173	0.5337984	3687.7273
617.05933	1.8201123	0.53502589	3690.8738
617.86011	1.8262905	0.53636986	3692.2065
618.66089	1.825529	0.53745288	3682.3914
619.46167	1.8264042	0.53838986	3678.2478
620.26245	1.8319004	0.53934187	3688.218
621.06323	1.8357403	0.54021901	3684.1968
621.86401	1.8356011	0.5412876	3687.1467
622.66479	1.8401977	0.54244208	3691.4348
623.46558	1.8392922	0.54342389	3687.6328
624.26636	1.8433912	0.54459053	3692.1458
625.06714	1.8466139	0.54561263	3690.6868
625.86792	1.8479282	0.54679954	3689.3652
626.6687	1.8488743	0.54789525	3688.2537
627.46948	1.8536524	0.54906237	3694.0059
628.27026	1.8531045	0.55011833	3687.4905
629.07104	1.8576814	0.55117208	3692.5044
629.87183	1.8591768	0.55241978	3693.7356
630.67261	1.8601491	0.55364233	3693.1614
631.47339	1.8623265	0.55475867	3691.4441
632.27417	1.8663751	0.55582947	3694.4285
633.07495	1.8719171	0.55704302	3698.4482
633.87573	1.8714401	0.55808359	3698.1272
634.67651	1.8760219	0.55906165	3693.0391
635.47729	1.8747276	0.55985552	3690.3606
636.27808	1.8805373	0.56092703	3695.6887
637.07886	1.883543	0.56205267	3697.3784
637.87964	1.8865147	0.56331462	3698.1685
638.68042	1.8864737	0.56454712	3703.6052
639.4812	1.887623	0.565687	3696.6531
640.28198	1.8914124	0.56678933	3700.1099
641.08276	1.8911384	0.56803483	3697.1182
641.88354	1.8959656	0.56925696	3704.0547
642.68433	1.9005122	0.57066005	3709.3176
643.48511	1.9016086	0.57182747	3702.9211
644.28589	1.9041318	0.57308555	3706.0366
645.08667	1.9053282	0.57439601	3701.1831
645.88745	1.9076647	0.5756045	3709.5852
646.68823	1.9120796	0.57693011	3710.9609
647.48901	1.9105532	0.57814318	3705.5315
648.28979	1.9153767	0.5793612	3706.384
649.09058	1.9206858	0.58060932	3704.5725
649.89136	1.9204549	0.58180606	3705.1372
650.69214	1.9239763	0.58283067	3703.6953
651.49292	1.9257617	0.58400899	3705.3809
652.2937	1.9278821	0.58506441	3707.0857
653.09448	1.9309671	0.58600324	3705.6995
653.89526	1.9327403	0.58702147	3704.957
654.69604	1.9358922	0.58828843	3712.1035
655.49683	1.9384946	0.58941185	3711.9036
656.29761	1.9422704	0.59055603	3707.4763
657.09839	1.9408513	0.59162652	3706.782
657.89917	1.943653	0.59280878	3704.8904
658.69995	1.943423	0.59388548	3709.4263
659.50073	1.9503442	0.59517986	3711.4822
660.30151	1.9506936	0.59653211	3713.489
661.10229	1.9547955	0.5980128	3711.8596
661.90308	1.9538023	0.5990864	3710.771
662.70386	1.9588472	0.60009557	3710.3276
663.50464	1.9627097	0.60132456	3721.5051
664.30542	1.9615451	0.60271901	3718.198
665.1062	1.9654063	0.60407555	3714.9421
665.90698	1.9676918	0.60531569	3708.9658
666.70776	1.9724703	0.60645592	3713.7444
667.50854	1.9744825	0.60763103	3714.9968
668.30933	1.9767873	0.60867739	3713.7314
669.11011	1.9795254	0.60998887	3721.478
669.91089	1.9806013	0.61129838	3722.3853
670.71167	1.9866304	0.61244589	3714.76
671.51245	1.9845538	0.61369556	3717.3303
672.31323	1.9859643	0.61486053	3722.9712
673.11401	1.9902418	0.61605477	3717.9688
673.91479	1.9953539	0.61740434	3719.7637
674.71558	1.9939203	0.61873549	3718.2773
675.51636	1.9968765	0.62001801	3720.1326
676.31714	1.9988317	0.6210115	3716.3416
677.11792	1.9994562	0.62199676	3710.8923
677.9187	2.0064211	0.62317866	3718.7339
678.71948	2.0070484	0.62429047	3720.3706
679.52026	2.0081	0.62552595	3723.6233
680.32104	2.0124631	0.62685567	3723.0544
681.12183	2.0132647	0.62820762	3722.2222
681.92261	2.0167172	0.62954158	3723.6355
682.72339	2.0168095	0.63087416	3723.1956
683.52417	2.0201967	0.63211185	3714.9231
684.32495	2.0195167	0.63329184	3721.2688
685.12573	2.0230978	0.63459069	3719.8923
685.92651	2.0261984	0.63593632	3724.146
686.72729	2.0311139	0.63749921	3726.7092
687.52808	2.0342932	0.63889354	3727.0615
688.32886	2.0332336	0.640136	3722.0217
689.12964	2.0372	0.64126986	3718.1106
689.93042	2.0384464	0.64248836	3724.9744
690.7312	2.0458169	0.64360631	3719.1958
691.53198	2.045692	0.64475507	3725.9458
692.33276	2.0473816	0.64618272	3733.9329
693.13354	2.0489655	0.64754295	3721.1523
693.93433	2.0525601	0.64869338	3727.8311
694.73511	2.0551534	0.64991611	3726.417
695.53589	2.0546074	0.65113521	3729.0906
696.33667	2.0569365	0.65262383	3730.6313
697.13745	2.064692	0.65381396	3729.7886
697.93823	2.061321	0.6550945	3718.8533
698.73901	2.0654485	0.65618104	3719.0095
699.53979	2.0687773	0.65768933	3732.8857
700.34058	2.0724292	0.6592164	3733.4944
701.14136	2.0735459	0.66067892	3729.1855
701.94214	2.0774891	0.66163665	3720.5098
702.74292	2.0751634	0.66269225	3725.8997
703.5437	2.0789809	0.66385108	3730.5764
704.34448	2.0812371	0.66529453	3729.2773
705.14526	2.083164	0.66645849	3726.3132
705.94604	2.0869009	0.66779172	3731.126
706.74683	2.0919642	0.66917169	3733.3027
707.54761	2.0917766	0.67042381	3731.8425
708.34839	2.0971959	0.67161494	3727.2734
709.14917	2.0980737	0.67281079	3729.7732
709.94995	2.098943	0.67416984	3732.6423
710.75073	2.1031952	0.67565382	3737.6062
711.55151	2.1030145	0.67705822	3733.1685
712.35229	2.1057386	0.67848247	3727.7229
713.15308	2.1117818	0.6797387	3738.7087
713.95386	2.1118364	0.68131077	3736.5796
714.75464	2.1126122	0.68267649	3732.0779
715.55542	2.1191351	0.68397743	3734.3745
716.3562	2.1191256	0.68541622	3738.7466
717.15698	2.1220226	0.6867131	3733.6191
717.95776	2.1262505	0.68790889	3731.9834
718.75854	2.1259427	0.68921793	3733.2432
719.55933	2.1295888	0.690575	3731.8916
720.36011	2.1298273	0.69195163	3730.5854
721.16089	2.1350772	0.6932767	3733.793
721.96167	2.1348078	0.69452465	3732.7034
722.76245	2.1388159	0.69588387	3739.1077
723.56323	2.1455305	0.69737983	3739.8428
724.36401	2.1409113	0.69890702	3739.8706
725.16479	2.1422105	0.70043319	3736.627
725.96558	2.149915	0.70181143	3737.5684
726.76636	2.1505327	0.70307648	3736.2837
727.56714	2.1522195	0.70420116	3730.0581
728.36792	2.1585228	0.70537597	3737.1599
729.1687	2.1572106	0.70666611	3734.511
729.96948	2.1601717	0.70796674	3740.4666
730.77026	2.160259	0.70931035	3739.3313
731.57104	2.1637137	0.71072167	3740.8284
732.37183	2.1650703	0.71194774	3734.5518
733.17261	2.1686771	0.713067	3732.446
733.97339	2.1734185	0.71461481	3742.8826
734.77417	2.1770327	0.71615398	3741.2219
735.57495	2.1748879	0.71746796	3739.6633
736.37573	2.1764426	0.71906668	3740.0918
737.17651	2.1812384	0.72069889	3735.3557
737.97729	2.1816962	0.72210324	3739.0864
738.77808	2.1871572	0.72350091	3734.4663
739.57886	2.1909325	0.72470343	3733.1824
740.37964	2.193857	0.72592241	3740.2861
741.18042	2.1930611	0.72724032	3737.4431
741.9812	2.1957202	0.72846746	3739.5354
742.78198	2.2004864	0.72978616	3741.1548
743.58276	2.2025759	0.73125988	3743.0898
744.38354	2.2021778	0.73272204	3742.8933
745.18433	2.2045317	0.73420566	3743.8101
745.98511	2.2095227	0.73609912	3743.3574
746.78589	2.2121005	0.73761606	3742.5537
747.58667	2.2139893	0.73912847	3739.533
748.38745	2.2135859	0.74063522	3740.1404
749.18823	2.2168064	0.74217147	3742.4973
749.98901	2.2182558	0.7436012	3737.8108
750.78979	2.2227693	0.74507195	3741.9448
751.59058	2.2255144	0.74656743	3746.1201
752.39136	2.2282939	0.748227	3747.6733
753.19214	2.2287426	0.74992186	3737.6726
753.99292	2.2320416	0.7513451	3740.4617
754.7937	2.2358193	0.75257248	3732.7356
755.59448	2.2372992	0.75381362	3741.0098
756.39526	2.2406757	0.75527704	3741.2026
757.19604	2.2399089	0.75668103	3742.7847
757.99683	2.2456288	0.75824988	3741.1343
758.79761	2.2473392	0.75974649	3738.2568
759.59839	2.2499161	0.76120108	3742.0474
760.39917	2.2536521	0.76256382	3743.9253
761.19995	2.2527337	0.76397735	3740.0984
762.00073	2.2580256	0.7656523	3748.1021
762.80151	2.2598011	0.76699632	3741.5
763.60229	2.2591729	0.76845986	3742.3923
764.40308	2.2620046	0.77011114	3745.4077
765.20386	2.2675591	0.77154362	3742.2866
766.00464	2.2701814	0.77296537	3742.0908
766.80542	2.2706356	0.77438527	3741.6809
767.6062	2.2746203	0.77597708	3746.3572
768.40698	2.2759154	0.77753985	3739.2964
769.20776	2.2775881	0.77915466	3744.5085
770.00854	2.2776628	0.78054309	3739.8157
770.80933	2.2842281	0.78184909	3735.6831
771.61011	2.2839353	0.78316331	3742.7629
772.41089	2.2880836	0.78494346	3751.0044
773.21167	2.2921743	0.78668064	3744.9038
774.01245	2.2946143	0.78835201	3743.5698
774.81323	2.2918401	0.78975874	3738.0239
775.61401	2.2985091	0.79143065	3749.4023
776.41479	2.2994618	0.79304165	3743.4229
777.21558	2.3030903	0.79463655	3741.0122
778.01636	2.3044987	0.79584056	3736.5815
778.81714	2.3065536	0.7973513	3741.9902
779.61792	2.3068781	0.79890049	3745.0022
780.4187	2.3078077	0.80069119	3743.0547
781.21948	2.3161261	0.80268669	3748.3181
782.02026	2.3193128	0.80476362	3749.0784
782.82104	2.3216	0.80639219	3745.4084
783.62183	2.3223789	0.80775297	3738.5725
784.42261	2.3233004	0.80920529	3745.2126
785.22339	2.3257296	0.81093848	3745.1582
786.02417	2.3295958	0.81273979	3743.3579
786.82495	2.3323534	0.81449229	3749.7061
787.62573	2.3355041	0.81640428	3752.5959
788.42651	2.334775	0.81819522	3742.3574
789.22729	2.3388124	0.81996763	3744.509
790.02808	2.3395307	0.82138866	3740.5325
790.82886	2.3425157	0.82276094	3737.6458
791.62964	2.3436096	0.82437193	3745.4055
792.43042	2.3457203	0.8258965	3742.7961
793.2312	2.3504806	0.82777435	3747.1646
794.03198	2.3514035	0.82942933	3743.1072
794.83276	2.3537707	0.83143437	3739.8147
795.63354	2.3575611	0.83295476	3736.1753
796.43433	2.3571904	0.83444405	3739.2786
797.23511	2.3617859	0.8361088	3742.1089
798.03589	2.3644247	0.83760631	3742.5754
798.83667	2.3678176	0.83896393	3733.2554
799.63745	2.3701513	0.84027857	3740.1191
800.43823	2.3703284	0.84183776	3745.0938
801.23901	2.3714857	0.84355545	3739.6804
802.03979	2.3748212	0.84527558	3740.1235
802.84058	2.3781526	0.84691858	3736.9497
803.64136	2.3819757	0.84850699	3740.1362
804.44214	2.3835044	0.85013103	3741.8101
805.24292	2.3897491	0.85188323	3745.1819
806.0437	2.3890474	0.85353291	3743.8511
806.84448	2.3891063	0.85519904	3738.2773
807.64526	2.3902488	0.85687661	3738.3572
808.44604	2.3957109	0.85883439	3737.949
809.24683	2.3989134	0.86056566	3737.2595
810.04761	2.4007409	0.86253774	3739.375
810.84839	2.4025211	0.86422825	3738.6069
811.64917	2.4038808	0.86612093	3737.8728
812.44995	2.4091895	0.86787939	3735.9854
813.25073	2.4106603	0.86955863	3739.0657
814.05151	2.41208	0.87137556	3742.1194
814.85229	2.4151618	0.87324721	3744.2876
815.65308	2.4186859	0.87507498	3736.2493
816.45386	2.4204342	0.87667882	3735.2173
817.25464	2.4215696	0.8783676	3735.3115
818.05542	2.4250553	0.88030678	3736.9478
818.8562	2.4261203	0.88228309	3738.0542
819.65698	2.4317541	0.88439268	3743.5393
820.45776	2.4309607	0.88649076	3740.7847
821.25854	2.4344449	0.88859046	3738.9556
822.05933	2.4385071	0.89042222	3734.8364
822.86011	2.4395757	0.89202029	3732.6934
823.66089	2.4419422	0.89357299	3727.8525
824.46167	2.4450793	0.89512479	3731.4275
825.26245	2.4465463	0.8967123	3732.7078
826.06323	2.4492011	0.89849162	3739.1365
826.86401	2.4513538	0.90052474	3739.5479
827.66479	2.4535501	0.90240079	3736.5854
828.46558	2.4545047	0.90420681	3735.8042
829.26636	2.458708	0.90654808	3741.1006
830.06714	2.4614117	0.90863603	3733.658
830.86792	2.4611819	0.91037136	3722.5803
831.6687	2.4641128	0.91219985	3731.4714
832.46948	2.4687207	0.91421896	3736.4949
833.27026	2.4710758	0.91599107	3729.5283
834.07104	2.4722455	0.91769457	3727.3098
834.87183	2.4754524	0.91961485	3726.2722
835.67261	2.4759407	0.92140371	3733.4504
836.47339	2.4814134	0.92356414	3731.4485
837.27417	2.4823787	0.92586786	3728.7275
838.07495	2.4834907	0.92802483	3723.1421
838.87573	2.4859576	0.93011218	3732.9429
839.67651	2.4882405	0.93223971	3727.1045
840.47729	2.491225	0.93411434	3726.7705
841.27808	2.4919546	0.9358356	3721.5374
842.07886	2.498656	0.93750739	3725.0542
842.87964	2.4975998	0.93942684	3725.6421
843.68042	2.5015602	0.94128591	3725.5313
844.4812	2.5032747	0.9433431	3722.5261
845.28198	2.5050027	0.94517487	3723.3003
846.08276	2.5078547	0.94709444	3726.1372
846.88354	2.5094047	0.94918561	3726.2515
847.68433	2.5138872	0.95136285	3725.4587
848.48511	2.5185697	0.95363915	3724.0518
849.28589	2.5173779	0.95549494	3722.0786
850.08667	2.5170314	0.95752299	3719.771
850.88745	2.5224636	0.95966303	3720.592
851.68823	2.5243263	0.96177471	3717.8394
852.48901	2.5289843	0.9637807	3722.397
853.28979	2.5319684	0.96628261	3724.3552
854.09058	2.532769	0.96838683	3716.8831
854.89136	2.5362868	0.9700743	3709.9939
855.69214	2.5388877	0.97179186	3718.8823
856.49292	2.5416348	0.97413945	3725.8064
857.2937	2.5419667	0.97630322	3718.4839
858.09448	2.5443189	0.97868007	3714.9063
858.89526	2.5479801	0.98087525	3717.7068
859.69604	2.5494573	0.98321581	3716.877
860.49683	2.5549579	0.9853633	3711.5315
861.29761	2.5559032	0.98735708	3711.9216
862.09839	2.5550475	0.98955745	3711.3752
862.89917	2.5579338	0.99165803	3704.8928
863.69995	2.5616193	0.99385697	3709.1565
864.50073	2.5660865	0.99619794	3711.4456
865.30151	2.5668504	0.99865866	3713.8494
866.10229	2.5681381	1.0009794	3708.9089
866.90308	2.5729537	1.0032457	3711.385
867.70386	2.5736609	1.0055023	3707.0508
868.50464	2.5780449	1.0073888	3706.7734
869.30542	2.5783081	1.00934	3702.6252
870.1062	2.582855	1.0113934	3705.6973
870.90698	2.5804956	1.013472	3699.7043
871.70776	2.582078	1.0154775	3697.4565
872.50854	2.58564	1.0173196	3694.4976
873.30933	2.590235	1.0192429	3699.2837
874.11011	2.5931449	1.0211297	3698.5232
874.91089	2.5985291	1.0234407	3706.5498
875.71167	2.5962439	1.0257604	3690.4502
876.51245	2.5999904	1.028132	3702.7053
877.31323	2.6065307	1.0305048	3693.9502
878.11401	2.6063514	1.0326595	3694.3894
878.91479	2.6080358	1.0349809	3694.7864
879.71558	2.6125696	1.0372127	3697.5178
880.51636	2.613409	1.039484	3687.0842
881.31714	2.6156089	1.0415945	3684.0195
882.11792	2.6193666	1.0440625	3696.5022
882.9187	2.6197379	1.0464263	3683.6155
883.71948	2.6205761	1.0487646	3685.7412
884.52026	2.6256888	1.0512286	3688.3723
885.32104	2.6254213	1.0537161	3685.2405
886.12183	2.6297107	1.0557128	3682.8228
886.92261	2.631268	1.0575805	3675.9651
887.72339	2.6330163	1.059534	3680.9751
888.52417	2.6352515	1.0619012	3678.7837
889.32495	2.6406693	1.0644643	3680.6299
890.12573	2.6397638	1.0669308	3673.3845
890.92651	2.6421566	1.0693942	3674.6877
891.72729	2.6428525	1.0719106	3671.1184
892.52808	2.6490757	1.0745916	3672.5854
893.32886	2.6475954	1.0769531	3671.3196
894.12964	2.652827	1.0793372	3669.4255
894.93042	2.6554544	1.0816209	3672.4409
895.7312	2.6558888	1.083918	3664.4673
896.53198	2.6607013	1.0861205	3666.5708
897.33276	2.6625874	1.0882108	3666.8652
898.13354	2.6677206	1.090271	3660.4143
898.93433	2.6676631	1.0923424	3664.4595
899.73511	2.669266	1.0948576	3660.6646
900.53589	2.6701231	1.0973221	3658.0042
901.33667	2.6729968	1.0995944	3653.0327
902.13745	2.6762385	1.1019964	3659.124
902.93823	2.6779413	1.1044755	3655.9658
903.73901	2.6810887	1.1067375	3650.3511
904.53979	2.6850085	1.1091238	3649.6804
905.34058	2.686748	1.1118803	3653.2744
906.14136	2.6898923	1.1149095	3650.3608
906.94214	2.6912165	1.1179901	3642.9558
907.74292	2.6938872	1.1200064	3635.3162
908.5437	2.697561	1.1220356	3636.5706
909.34448	2.6978571	1.1239548	3632.4622
910.14526	2.6993697	1.1261426	3639.1257
910.94604	2.7010846	1.1285714	3638.8577
911.74683	2.7045681	1.1308722	3635.1306
912.54761	2.710984	1.1332967	3634.866
913.34839	2.7107842	1.1356872	3635.3889
914.14917	2.7113187	1.1380699	3631.4067
914.94995	2.713891	1.1407095	3626.7673
915.75073	2.7190678	1.1430682	3627.6296
916.55151	2.7211077	1.1453745	3619.1804
917.35229	2.7197392	1.1478213	3621.7185
918.15308	2.7245817	1.150723	3619.1716
918.95386	2.7300329	1.1530789	3615.7649
919.75464	2.7317967	1.1551057	3606.2273
920.55542	2.7326791	1.157179	3612.8589
921.3562	2.735029	1.1599703	3612.761
922.15698	2.7353656	1.1625315	3611.0393
922.95776	2.7354872	1.1649421	3604.3821
923.75854	2.7428589	1.1677328	3605.1484
924.55933	2.7437701	1.1707296	3602.396
925.36011	2.7458189	1.1736864	3597.1106
926.16089	2.7479846	1.1763395	3593.3159
926.96167	2.7549155	1.1790515	3589.7122
927.76245	2.755353	1.1814426	3583.3225
928.56323	2.7573786	1.1839821	3587.9614
929.36401	2.7561617	1.1868123	3581.3687
930.16479	2.762948	1.189328	3579.0247
930.96558	2.7670553	1.1916542	3582.5852
931.76636	2.7686775	1.1942685	3575.7671
932.56714	2.7677045	1.1970907	3568.9443
933.36792	2.7711551	1.199801	3558.4946
934.1687	2.7751336	1.2022786	3565.5315
934.96948	2.7787056	1.2048569	3559.3708
935.77026	2.7780111	1.207655	3555.9189
936.57104	2.7806849	1.2102907	3550.4451
937.37183	2.7828286	1.2130345	3548.1946
938.17261	2.7839158	1.2154438	3539.9832
938.97339	2.7879939	1.2187326	3540.2002
939.77417	2.7898247	1.2214179	3532.6716
940.57495	2.7910335	1.2239635	3523.9814
941.37573	2.7983539	1.2264807	3521.8508
942.17651	2.7968068	1.2288949	3513.6565
942.97729	2.8019016	1.2315	3515.8206
943.77808	2.8025565	1.2342186	3510.9368
944.57886	2.8040519	1.2373054	3508.7349
945.37964	2.8084242	1.2407324	3497.5432
946.18042	2.8126087	1.2430956	3493.8594
946.9812	2.8126938	1.2455869	3488.8577
947.78198	2.816644	1.2483752	3490.9346
948.58276	2.8153243	1.2513114	3488.5488
949.38354	2.8187859	1.2544067	3482.6042
950.18433	2.8237462	1.25763	3478.0959
950.98511	2.8242764	1.2602786	3461.1914
951.78589	2.8271542	1.2631537	3462.9922
952.58667	2.8272066	1.2659688	3456.4636
953.38745	2.8312418	1.2684941	3451.8813
954.18823	2.8327761	1.270949	3446.8616
954.98901	2.8336236	1.2733469	3442.2917
955.78979	2.8397563	1.2758324	3446.4246
956.59058	2.8418498	1.2786762	3441.4194
957.39136	2.8428664	1.2816664	3433.3264
958.19214	2.8445375	1.2847006	3417.5618
958.99292	2.8475173	1.286986	3412.0842
959.7937	2.8507135	1.2893056	3415.8857
960.59448	2.8536167	1.2923803	3412.0884
961.39526	2.8554842	1.2953366	3403.7578
962.19604	2.8579607	1.2982725	3399.5322
962.99683	2.8599164	1.3014913	3388.5774
963.79761	2.8590248	1.304491	3382.8535
964.59839	2.8632214	1.3074254	3377.509
965.39917	2.8677714	1.3107989	3373.4668
966.19995	2.8696434	1.3144362	3363.1663
967.00073	2.871758	1.3176795	3353.6938
967.80151	2.877167	1.3205298	3348.6838
968.60229	2.8765421	1.3234618	3339.3174
969.40308	2.8797328	1.3268528	3336.7302
970.20386	2.8823164	1.3301244	3315.6165
971.00464	2.8848391	1.3335717	3295.6538
971.80542	2.8891795	1.3373733	3276.8633
972.6062	2.891988	1.3404882	3272.8892
973.40698	2.8912556	1.3435158	3266.1145
974.20776	2.8962986	1.3478005	3249.4644
975.00854	2.8969095	1.3539228	3204.7981
975.80933	2.9028001	1.3622037	3145.3325
976.61011	2.9043658	1.3707999	3084.0679
977.41089	2.905602	1.3765948	3041.106
978.21167	2.9113953	1.3811351	3021.4658
978.81226	2.9105203	1.3945169	2904.9768