File: datasets/am_bench_2022/raw_data/TH1-F/specimen.dat
MTS793|MPT|ENU|1|2|.|/|:|1|0|0|A

Operator Information						Time:	10.448242	Sec	11/3/2021 11:16:35 AM
Operator	Nick Derimow
Project	AM Bench 2022 mini-tensile challenge
Specimen ID	TH1-F
Material	PBF-L Inconel 625
Specimen Width	2.56	mm
Specimen Thickness	1.51	mm
Notes
Operator Information End

Data Acquisition						Time:	1011.4431	Sec	11/3/2021 11:33:16 AM
Time	Axial Displacement	Axial Extensometer	Axial Force
Sec	mm	mm	N
10.562988	0.002137997	6.0152752e-06	43.384819
11.463867	0.0058958512	4.9288246e-05	51.16383
12.364746	0.0046032453	0.00015180954	66.687141
13.265625	0.010614029	0.00018407167	77.762817
14.166504	0.0098583912	0.00023612934	88.56424
15.067383	0.015352491	0.00036440644	103.37905
15.968262	0.018666551	0.00050268124	116.43598
16.869141	0.017723694	0.00053918461	120.80399
17.77002	0.024479257	0.00048718328	129.37323
18.670898	0.024100414	0.00062966341	139.08133
19.571777	0.028474169	0.00073994597	151.93135
20.472656	0.031498566	0.00077289657	163.97794
21.373535	0.03687562	0.00088697881	181.56099
22.274414	0.035998277	0.00096690987	193.0797
23.175293	0.039915383	0.0011376486	207.19518
24.076172	0.042547565	0.0012677768	226.18599
24.977051	0.042972304	0.0013206049	237.1412
25.87793	0.047414497	0.0014327531	255.89764
26.778809	0.049262561	0.001534296	274.38498
27.679688	0.050416917	0.0017567226	299.17639
28.580566	0.056048088	0.0018675266	315.44125
29.481445	0.056078821	0.0019232281	329.17972
30.382324	0.060194414	0.0020333058	347.87164
31.283203	0.064450361	0.0022007253	373.26331
32.184082	0.06672731	0.0022981653	387.09113
33.084961	0.067182787	0.0024536806	408.7623
33.98584	0.070381492	0.0025805265	427.75391
34.886719	0.073421821	0.0027057878	443.64178
35.787598	0.078105167	0.0028482054	468.91183
36.688477	0.078805894	0.0030187967	486.30484
37.589355	0.083950035	0.0031165604	503.53311
38.490234	0.087136038	0.003223791	533.56433
39.391113	0.086232059	0.0033945164	553.75415
40.291992	0.090809278	0.0034561139	573.03601
41.192871	0.090424284	0.0036581834	586.87207
42.09375	0.09944164	0.0037617178	612.11743
42.994629	0.098720886	0.0038455296	632.21826
43.895508	0.10016818	0.0039750556	651.995
44.796387	0.099510275	0.0041223057	674.99384
45.697266	0.10581247	0.0044061788	706.58545
46.598145	0.10799927	0.0044712145	718.01874
47.499023	0.11378488	0.0047383113	751.46326
48.399902	0.11522035	0.0047105076	770.05646
49.300781	0.11729625	0.0049733836	800.68439
50.20166	0.11660597	0.0051441304	822.27991
51.102539	0.12183868	0.0052125058	852.33411
52.003418	0.12464174	0.005509946	868.47192
52.904297	0.12395208	0.005536844	893.86328
53.805176	0.12893723	0.0057697827	912.86963
54.706055	0.13433155	0.0059520886	943.70508
55.606934	0.1357199	0.0061134081	966.63501
56.507813	0.13843383	0.0062403628	994.1723
57.408691	0.14336033	0.0063780067	1019.0552
58.30957	0.14236952	0.0066179307	1038.6998
59.210449	0.14468433	0.0067275381	1068.9176
60.111328	0.1493476	0.0069673806	1094.3773
61.012207	0.15032881	0.0071002925	1115.431
61.913086	0.15392952	0.0071720933	1144.1558
62.813965	0.15679179	0.0074204383	1163.8745
63.714844	0.15687273	0.0075602676	1192.8654
64.615723	0.164276	0.0077567222	1217.7997
65.516602	0.16305874	0.0078717098	1232.1069
66.41748	0.16432333	0.0080407513	1261.3793
67.318359	0.17021589	0.0082713524	1291.5625
68.219238	0.17206258	0.0084370961	1317.0087
69.120117	0.1751343	0.0085536279	1338.9546
70.020996	0.17777796	0.0087671876	1361.1648
70.921875	0.1795119	0.0089169331	1386.8984
71.822754	0.18249573	0.0091024628	1416.8777
72.723633	0.18417722	0.0092967469	1437.1879
73.624512	0.18915956	0.0093064383	1458.6606
74.525391	0.19207899	0.0095440019	1483.1503
75.42627	0.19728599	0.0098194666	1513.2429
76.327148	0.19955249	0.010021098	1542.1251
77.228027	0.20090805	0.010094821	1561.7482
78.128906	0.20341688	0.010380034	1591.3628
79.029785	0.20627061	0.010403761	1606.3501
79.930664	0.20679754	0.010561766	1626.9329
80.831543	0.21035193	0.010754136	1648.9213
81.732422	0.21253976	0.010889465	1671.1866
82.633301	0.21773021	0.011037858	1698.4579
83.53418	0.21763249	0.011189152	1723.5061
84.435059	0.22062466	0.011406264	1745.7745
85.335938	0.22484741	0.011490116	1772.6434
86.236816	0.22531927	0.011698307	1794.075
87.137695	0.22497936	0.011873841	1811.2795
88.038574	0.23306532	0.01199917	1839.5704
88.939453	0.23392971	0.012150334	1862.7489
89.840332	0.23896731	0.012336626	1888.1749
90.741211	0.24004422	0.012612087	1909.3491
91.64209	0.24519841	0.012671038	1931.2742
92.542969	0.24493185	0.012817565	1950.2754
93.443848	0.24951254	0.013005166	1975.1086
94.344727	0.24819058	0.013119714	1993.7524
95.245605	0.25492263	0.013291392	2017.5519
96.146484	0.25384349	0.013518415	2038.9111
97.047363	0.25971705	0.013596941	2057.3533
97.948242	0.26044905	0.013841627	2077.8916
98.849121	0.26574135	0.013912084	2102.5996
99.75	0.26902944	0.014066932	2126.6675
100.65088	0.2696898	0.014276382	2139.5247
101.55176	0.27226871	0.014378034	2162.5164
102.45264	0.27531272	0.014665976	2187.2383
103.35352	0.27910152	0.014740424	2202.4768
104.25439	0.28184336	0.014883753	2218.1006
105.15527	0.28176099	0.015017061	2236.7114
106.05615	0.28643921	0.015209161	2257.6589
106.95703	0.28825244	0.015412751	2274.0461
107.85791	0.29179332	0.01550268	2290.0002
108.75879	0.29575285	0.015645931	2307.4653
109.65967	0.2993474	0.015857646	2318.9927
110.56055	0.30007046	0.015968699	2331.3567
111.46143	0.30213633	0.016207119	2350.0249
112.3623	0.30608615	0.01633315	2362.4978
113.26318	0.31047466	0.016534708	2381.3904
114.16406	0.3104341	0.016615639	2392.2512
115.06494	0.31464189	0.01679985	2403.1528
115.96582	0.31643286	0.017001595	2416.8315
116.8667	0.31745726	0.0170896	2422.1152
117.76758	0.32109162	0.017235562	2434.0715
118.66846	0.32688177	0.017524337	2456.5325
119.56934	0.32673344	0.01768971	2468.7524
120.47021	0.32979813	0.017909372	2484.2214
121.37109	0.33382133	0.018123994	2496.9126
122.27197	0.33158863	0.018383091	2510.0173
123.17285	0.33705452	0.018511843	2518.5642
124.07373	0.33919907	0.018811684	2529.0378
124.97461	0.34242523	0.018952299	2544.981
125.87549	0.34487525	0.019165967	2549.0298
126.77637	0.34983811	0.019426854	2562.5811
127.67725	0.3520636	0.019556658	2569.9194
128.57813	0.35272846	0.019855071	2582.9412
129.479	0.35601363	0.020016065	2583.7297
130.37988	0.36003295	0.020273836	2595.9258
131.28076	0.3652918	0.020620199	2608.1123
132.18164	0.36398876	0.020875352	2618.9255
133.08252	0.3701905	0.021098549	2630.1829
133.9834	0.37393075	0.021286214	2633.3728
134.88428	0.37554795	0.021441462	2638.584
135.78516	0.37806517	0.02178302	2652.3643
136.68604	0.38009259	0.021983413	2655.2883
137.58691	0.38140321	0.022298316	2660.728
138.48779	0.38111779	0.022512197	2666.7036
139.38867	0.38731018	0.022833198	2686.344
140.28955	0.39116269	0.023113482	2690.4995
141.19043	0.39223221	0.023524586	2699.542
142.09131	0.39523852	0.024059853	2712.6079
142.99219	0.40185583	0.024319611	2716.6672
143.89307	0.40062013	0.024752205	2725.4956
144.79395	0.40496275	0.025134755	2732.0623
145.69482	0.40464744	0.025417859	2736.9536
146.5957	0.41044846	0.025978729	2753.4128
147.49658	0.41106251	0.026426559	2757.2378
148.39746	0.41434216	0.026810082	2758.5945
149.29834	0.41789082	0.027074248	2760.9961
150.19922	0.41815984	0.027495226	2768.5708
151.1001	0.42224857	0.028057428	2780.1858
152.00098	0.42371622	0.028566042	2780.8018
152.90186	0.42709461	0.02902651	2789.8921
153.80273	0.43052921	0.029474912	2795.9729
154.70361	0.43492463	0.030055467	2802.4121
155.60449	0.43840978	0.030472836	2810.3984
156.50537	0.43974996	0.031092474	2814.6526
157.40625	0.44500476	0.031655829	2821.7717
158.30713	0.44279957	0.032306377	2827.1472
159.20801	0.44784516	0.03289292	2835.0227
160.10889	0.44977662	0.033286858	2836.731
161.00977	0.45109797	0.033847667	2836.3406
161.91064	0.45512277	0.034563191	2854.3447
162.81152	0.45828193	0.035248958	2850.1526
163.7124	0.4598549	0.035857506	2852.718
164.61328	0.46660513	0.036806401	2868.928
165.51416	0.46499693	0.037446417	2871.3667
166.41504	0.46902713	0.038127743	2867.7644
167.31592	0.473355	0.038670212	2874.7148
168.2168	0.47367546	0.03947401	2882.1128
169.11768	0.48026896	0.040225357	2886.426
170.01855	0.48045233	0.040889852	2896.3572
170.91943	0.48257357	0.041826062	2896.6589
171.82031	0.48606893	0.042560339	2904.5925
172.72119	0.49009112	0.043275535	2906.9146
173.62207	0.49051133	0.043843966	2900.3052
174.52295	0.49020442	0.044557892	2906.8362
175.42383	0.49602491	0.04528128	2914.3271
176.32471	0.5008412	0.046117764	2908.9983
177.22559	0.50237828	0.046815801	2916.8621
178.12646	0.50520635	0.047560602	2914.4106
179.02734	0.50866777	0.048352852	2925.8943
179.92822	0.50892222	0.049069986	2926.853
180.8291	0.51320028	0.049884003	2930.136
181.72998	0.51702046	0.05074662	2943.2529
182.63086	0.51920187	0.05166135	2946.7129
183.53174	0.52209556	0.052543897	2943.6189
184.43262	0.52033162	0.053507239	2948.7715
185.3335	0.52727556	0.054247003	2948.7847
186.23438	0.53010279	0.05517922	2950.25
187.13525	0.53153723	0.055903625	2958.7493
188.03613	0.53247929	0.056661941	2953.1941
188.93701	0.53697968	0.057513364	2959.1162
189.83789	0.54052877	0.058299296	2969.344
190.73877	0.54316318	0.059353277	2969.4497
191.63965	0.54501933	0.06024874	2975.0259
192.54053	0.54796475	0.061276603	2972.0466
193.44141	0.54880625	0.062090777	2970.457
194.34229	0.5530538	0.06289123	2979.0898
195.24316	0.55591422	0.063935377	2986.7981
196.14404	0.55928338	0.064885102	2985.8601
197.04492	0.56229407	0.065909266	2990.5852
197.9458	0.56445318	0.066690877	2987.6106
198.84668	0.56706411	0.067560084	2995.2231
199.74756	0.56725997	0.068383254	2997.2026
200.64844	0.57188493	0.069384702	2997.5959
201.54932	0.57633245	0.070262909	3004.6443
202.4502	0.57965142	0.071318246	3007.8352
203.35107	0.58223921	0.072242193	3010.6709
204.25195	0.58390838	0.073068537	3006.5642
205.15283	0.58626926	0.073968597	3009.8313
206.05371	0.58880275	0.074688703	3011.9961
206.95459	0.59268767	0.075826474	3024.9866
207.85547	0.59352732	0.076740585	3017.2632
208.75635	0.5963521	0.07772398	3017.4702
209.65723	0.59866816	0.078526184	3019.5542
210.55811	0.6011346	0.079341628	3023.1716
211.45898	0.60627443	0.080263533	3037.186
212.35986	0.60872781	0.081264459	3032.72
213.26074	0.6083678	0.082157806	3033.4995
214.16162	0.6109916	0.083067775	3038.9556
215.0625	0.61671722	0.083957106	3035.5168
215.96338	0.61858255	0.084847353	3039.186
216.86426	0.61971533	0.085714936	3051.3635
217.76514	0.62252253	0.086641572	3046.2021
218.66602	0.62826633	0.087627061	3047.6355
219.56689	0.62632072	0.08847709	3048.8335
220.46777	0.63240272	0.089550622	3064.7268
221.36865	0.63266087	0.090573102	3055.2004
222.26953	0.63966262	0.091828257	3065.9338
223.17041	0.64004928	0.09281069	3056.1714
224.07129	0.64110345	0.093776405	3059.5825
224.97217	0.64291918	0.094931647	3063.9817
225.87305	0.64545369	0.095936604	3066.1108
226.77393	0.65307462	0.097074926	3072.3169
227.6748	0.65501148	0.098005347	3066.2593
228.57568	0.65709031	0.099022359	3072.8564
229.47656	0.65799081	0.099946178	3075.7153
230.37744	0.66304088	0.10063377	3073.2756
231.27832	0.6650148	0.10135457	3074.085
232.1792	0.66458493	0.10229008	3083.8801
233.08008	0.66877609	0.1033802	3085.7405
233.98096	0.67518282	0.10432303	3089.0857
234.88184	0.67424297	0.10521797	3091.6514
235.78271	0.67816615	0.10641149	3094.9033
236.68359	0.68171501	0.10730014	3090.7512
237.58447	0.68433845	0.10822321	3091.9226
238.48535	0.68452448	0.10916397	3095.1631
239.38623	0.68624926	0.11021945	3096.6968
240.28711	0.69428861	0.11125807	3109.0977
241.18799	0.69605255	0.1121797	3103.3584
242.08887	0.69489247	0.11310332	3100.8523
242.98975	0.69912243	0.1140153	3100.792
243.89063	0.70026791	0.11479811	3104.5896
244.7915	0.70228589	0.11567102	3103.3127
245.69238	0.70861447	0.11651886	3105.6648
246.59326	0.71086866	0.11760928	3125.2971
247.49414	0.71238482	0.11867043	3112.1848
248.39502	0.71567577	0.11980197	3118.1155
249.2959	0.71625209	0.1205566	3115.625
250.19678	0.72140521	0.12158272	3122.3425
251.09766	0.72150683	0.12247885	3119.3674
251.99854	0.7278617	0.12342949	3125.8433
252.89941	0.72741443	0.12432695	3123.9944
253.80029	0.73120117	0.12534505	3129.5603
254.70117	0.73635924	0.126368	3134.739
255.60205	0.73666763	0.1273434	3132.2937
256.50293	0.74198222	0.12820806	3133.4548
257.40381	0.74170703	0.12909746	3133.5674
258.30469	0.74588597	0.13014278	3140.2529
259.20557	0.74744081	0.13099013	3130.0093
260.10645	0.7505849	0.13213974	3141.9453
261.00732	0.75290877	0.1332128	3143.6821
261.9082	0.75698698	0.13448289	3145.2849
262.80908	0.75978315	0.13543023	3145.6345
263.70996	0.76084751	0.13640274	3149.0649
264.61084	0.76513422	0.13759619	3145.9575
265.51172	0.76892346	0.13855286	3150.8337
266.4126	0.77009851	0.13943784	3154.7578
267.31348	0.7700786	0.14044936	3155.8296
268.21436	0.77534872	0.14133589	3156.2817
269.11523	0.77559006	0.14234416	3157.6667
270.01611	0.77789634	0.14320557	3160.0654
270.91699	0.78193611	0.14414443	3156.9314
271.81787	0.78585827	0.14483377	3162.7524
272.71875	0.79001832	0.14575422	3157.9277
273.61963	0.79517621	0.14672399	3167.4028
274.52051	0.79287964	0.14778869	3167.8533
275.42139	0.79556036	0.14881821	3170.8872
276.32227	0.79994684	0.14978456	3172.1433
277.22314	0.80160582	0.15062954	3172.3545
278.12402	0.80448657	0.15153715	3170.5452
279.0249	0.80672646	0.15215819	3161.636
279.92578	0.8113575	0.1529609	3170.8994
280.82666	0.81485718	0.15408634	3180.6917
281.72754	0.81461066	0.15484992	3175.0867
282.62842	0.81747794	0.15583435	3177.0847
283.5293	0.82011896	0.15678853	3180.5056
284.43018	0.82305646	0.1577839	3182.6191
285.33105	0.82606769	0.15859537	3178.6108
286.23193	0.82981551	0.15941611	3190.312
287.13281	0.8336615	0.16036017	3195.2903
288.03369	0.83400059	0.16145259	3195.782
288.93457	0.83669299	0.16242014	3187.9126
289.83545	0.84144413	0.16343684	3194.7695
290.73633	0.84168285	0.16428922	3191.373
291.63721	0.8447994	0.16535668	3196.9539
292.53809	0.84818727	0.16646868	3199.4751
293.43896	0.8506431	0.16746119	3199.387
294.33984	0.85318738	0.16838388	3196.6338
295.24072	0.85545135	0.16935115	3195.5527
296.1416	0.8570776	0.17019132	3199.5632
297.04248	0.86420995	0.17114782	3209.6377
297.94336	0.86342871	0.17225055	3209.0652
298.84424	0.86615396	0.17326416	3209.3252
299.74512	0.86977863	0.17412414	3211.9019
300.646	0.8717773	0.17495349	3212.304
301.54688	0.87409484	0.17583649	3208.0403
302.44775	0.87716383	0.17680666	3214.1509
303.34863	0.88154495	0.17775512	3212.385
304.24951	0.88201743	0.17880067	3218.4377
305.15039	0.8861593	0.17974621	3221.1736
306.05127	0.88571918	0.18089086	3222.5198
306.95215	0.89309698	0.18195786	3227.7061
307.85303	0.89127451	0.18286309	3220.8262
308.75391	0.89553368	0.18392251	3226.865
309.65479	0.89980692	0.18493058	3225.769
310.55566	0.90240794	0.18607993	3231.8279
311.45654	0.90461117	0.18703157	3228.0833
312.35742	0.90728348	0.18783188	3227.5759
313.2583	0.90744394	0.18878524	3233.4722
314.15918	0.91300237	0.18975942	3234.3943
315.06006	0.91535223	0.19064322	3229.5542
315.96094	0.91756278	0.19155546	3231.0415
316.86182	0.9216162	0.19236127	3235.3418
317.7627	0.92644405	0.19328888	3238.8267
318.66357	0.92647523	0.19414951	3243.0969
319.56445	0.92906624	0.19523396	3246.5549
320.46533	0.93481153	0.1963309	3251.0161
321.36621	0.93426877	0.19729979	3239.4902
322.26709	0.93948871	0.19816248	3240.9805
323.16797	0.93928671	0.19902901	3246.9963
324.06885	0.94134438	0.19987917	3241.6431
324.96973	0.94539195	0.20071375	3251.572
325.87061	0.9474892	0.20177321	3253.3167
326.77148	0.94889081	0.20291053	3251.4607
327.67236	0.95170844	0.20369703	3248.4756
328.57324	0.95621967	0.20473076	3257.2334
329.47412	0.95819956	0.20561506	3254.4673
330.375	0.9606877	0.20650798	3257.2546
331.27588	0.96423864	0.20744444	3263.8435
332.17676	0.96680999	0.20848852	3259.3684
333.07764	0.97157407	0.20967488	3261.7239
333.97852	0.97466028	0.21063632	3265.4688
334.87939	0.97601026	0.21156621	3270.2668
335.78027	0.97521448	0.21265253	3266.8267
336.68115	0.97970545	0.21338578	3261.3467
337.58203	0.98467505	0.21424015	3267.4507
338.48291	0.98591518	0.21502598	3269.8337
339.38379	0.98862505	0.2161559	3276.4814
340.28467	0.99433291	0.21729426	3279.5686
341.18555	0.99429661	0.21837018	3275.7026
342.08643	0.99753588	0.21945338	3277.8215
342.9873	1.0003878	0.22044237	3276.937
343.88818	1.0027782	0.22122435	3280.7249
344.78906	1.0046345	0.22214195	3276.6619
345.68994	1.0084707	0.22296567	3277.064
346.59082	1.0101933	0.22396807	3288.5815
347.4917	1.0107909	0.22503753	3283.5566
348.39258	1.0152377	0.226054	3289.5234
349.29346	1.019174	0.22692047	3285.8931
350.19434	1.0225528	0.22776575	3287.0876
351.09521	1.0245627	0.22863285	3290.7834
351.99609	1.0263035	0.2296204	3292.6658
352.89697	1.0301771	0.23064874	3289.1877
353.79785	1.0291352	0.23161323	3298.8198
354.69873	1.0357636	0.23236641	3287.8164
355.59961	1.0367645	0.23318782	3295.7173
356.50049	1.040483	0.23421128	3296.9302
357.40137	1.0409075	0.23499203	3291.2197
358.30225	1.0443423	0.23591955	3299.0149
359.20313	1.0503663	0.23685642	3301.7754
360.104	1.0496596	0.23782365	3303.2261
361.00488	1.0512352	0.23899084	3303.9924
361.90576	1.0560588	0.24021509	3303.8655
362.80664	1.0602677	0.24108079	3302.2803
363.70752	1.06204	0.24185798	3306.769
364.6084	1.0646147	0.24282317	3308.4819
365.50928	1.0686619	0.24388084	3310.198
366.41016	1.0663215	0.24472634	3308.8442
367.31104	1.0716482	0.24561401	3304.4751
368.21191	1.074461	0.24647458	3310.9258
369.11279	1.0797167	0.24742806	3317.7361
370.01367	1.0776299	0.24834119	3314.8281
370.91455	1.0827233	0.2495015	3322.3704
371.81543	1.0830771	0.25041166	3312.4531
372.71631	1.0889249	0.25149217	3322.2361
373.61719	1.0914612	0.25235868	3320.4253
374.51807	1.0946984	0.25329071	3321.9783
375.41895	1.0974038	0.25424349	3319.8677
376.31982	1.1002582	0.25518408	3325.9165
377.2207	1.0996606	0.25614882	3320.8076
378.12158	1.1020632	0.25714004	3331.2258
379.02246	1.1118164	0.25813001	3330.1907
379.92334	1.1136788	0.25893286	3329.4712
380.82422	1.1122403	0.25982526	3327.2566
381.7251	1.1167552	0.26072738	3335.4641
382.62598	1.1177955	0.26179579	3333.0859
383.52686	1.1199629	0.26275012	3334.3367
384.42773	1.1241044	0.26363215	3335.8892
385.32861	1.1260195	0.26463178	3334.7671
386.22949	1.1302294	0.26549473	3334.5894
387.13037	1.1310985	0.26658329	3348.8398
388.03125	1.1345775	0.26747495	3338.6519
388.93213	1.136209	0.26839501	3341.178
389.83301	1.1402678	0.26947385	3347.3308
390.73389	1.1429944	0.27034348	3341.3132
391.63477	1.1477287	0.27119833	3344.5691
392.53564	1.1479008	0.27213478	3345.2661
393.43652	1.1522282	0.27324414	3350.8477
394.3374	1.1556518	0.27420264	3346.3855
395.23828	1.154363	0.27534127	3352.7598
396.13916	1.159022	0.27620772	3346.7285
397.04004	1.1632998	0.27710119	3353.1758
397.94092	1.16278	0.27779081	3345.9805
398.8418	1.1680111	0.2789019	3354.5237
399.74268	1.1671129	0.27989039	3353.302
400.64355	1.1750122	0.28080326	3358.9209
401.54443	1.1760763	0.28161511	3355.5654
402.44531	1.1766665	0.2826519	3356.8452
403.34619	1.1826862	0.28348362	3353.2559
404.24707	1.1852293	0.28439438	3365.0354
405.14795	1.1867552	0.28559029	3366.9434
406.04883	1.1878946	0.28646004	3360.1968
406.94971	1.191021	0.28753901	3360.0715
407.85059	1.1943833	0.28843585	3357.8164
408.75146	1.1968077	0.28943521	3365.4412
409.65234	1.2002226	0.29015973	3360.2856
410.55322	1.2015351	0.2910338	3368.3879
411.4541	1.2038581	0.29191673	3372.9961
412.35498	1.205933	0.29309162	3374.8203
413.25586	1.2120695	0.29428637	3382.4172
414.15674	1.2159494	0.29539415	3378.2551
415.05762	1.2166324	0.29641423	3374.4734
415.9585	1.2198876	0.29737985	3376.6958
416.85938	1.2233999	0.29826313	3373.2986
417.76025	1.2221963	0.29920894	3377.3562
418.66113	1.226387	0.30018136	3378.9075
419.56201	1.2297989	0.30126065	3383.4641
420.46289	1.2329742	0.30220467	3379.2432
421.36377	1.2339525	0.30303124	3377.7642
422.26465	1.239754	0.30372882	3377.6006
423.16553	1.2389001	0.30472603	3382.4956
424.06641	1.2429044	0.30562246	3387.2346
424.96729	1.2463616	0.30648535	3389.1838
425.86816	1.2466778	0.30744794	3388.9512
426.76904	1.2501202	0.30859303	3389.3164
427.66992	1.2548672	0.30945328	3390.2688
428.5708	1.2571931	0.31048679	3387.1414
429.47168	1.2579018	0.31140229	3393.7651
430.37256	1.2607613	0.31225911	3389.4236
431.27344	1.2642651	0.3131783	3392.5483
432.17432	1.2652159	0.31403556	3385.2329
433.0752	1.2707819	0.31494027	3393.7839
433.97607	1.2734209	0.31585309	3397.7061
434.87695	1.275766	0.31680879	3397.0002
435.77783	1.2774023	0.31768236	3394.9084
436.67871	1.2799892	0.31852591	3397.0317
437.57959	1.2839891	0.31957176	3404.3337
438.48047	1.2863399	0.32050514	3400.4561
439.38135	1.2868187	0.32166135	3405.8076
440.28223	1.2922221	0.32271275	3408.3882
441.18311	1.2933352	0.32378584	3408.6611
442.08398	1.2975366	0.32498997	3408.1274
442.98486	1.3010708	0.32591003	3407.7351
443.88574	1.3035455	0.32686105	3412.7395
444.78662	1.30193	0.32782465	3405.9133
445.6875	1.3061188	0.32887688	3408.6292
446.58838	1.3114628	0.32992727	3414.825
447.48926	1.3161801	0.33073026	3411.4561
448.39014	1.3155327	0.33161679	3406.4565
449.29102	1.3191133	0.33245546	3409.3281
450.19189	1.320331	0.33341902	3416.3726
451.09277	1.3258566	0.33431336	3414.4492
451.99365	1.327283	0.33523735	3416.7356
452.89453	1.3289742	0.33629546	3423.1931
453.79541	1.332798	0.33748084	3424.1963
454.69629	1.3374492	0.33847547	3419.3997
455.59717	1.3371077	0.33947954	3416.0554
456.49805	1.3393366	0.34041807	3421.2466
457.39893	1.3443431	0.34142515	3426.7463
458.2998	1.3446262	0.34224638	3419.304
459.20068	1.3468493	0.34324548	3425.0627
460.10156	1.3525485	0.34416378	3431.3806
461.00244	1.3523831	0.34507665	3421.8967
461.90332	1.3590455	0.3461538	3438.2522
462.8042	1.358382	0.34722781	3425.4795
463.70508	1.3608145	0.34816721	3432.0325
464.60596	1.3647829	0.34903112	3425.4941
465.50684	1.3711827	0.35007221	3436.5156
466.40771	1.3663579	0.35094136	3427.4102
467.30859	1.3738546	0.35188258	3432.3232
468.20947	1.3763781	0.35270482	3434.2754
469.11035	1.3758115	0.35374668	3442.2405
470.01123	1.378415	0.35496357	3436.5801
470.91211	1.3834242	0.35586807	3437.0383
471.81299	1.3862166	0.35690001	3440.5586
472.71387	1.3885304	0.35782862	3438.9268
473.61475	1.391362	0.35871807	3440.9238
474.51563	1.3910577	0.35964343	3444.2517
475.4165	1.396309	0.36073294	3443.3806
476.31738	1.4005326	0.36166018	3444.2102
477.21826	1.4016362	0.36254346	3442.9094
478.11914	1.4069209	0.36358687	3447.4226
479.02002	1.4071871	0.36476627	3451.0496
479.9209	1.4106241	0.36565042	3445.7534
480.82178	1.4142702	0.36669293	3447.4763
481.72266	1.4155564	0.36766648	3447.8298
482.62354	1.4182317	0.36856928	3446.8943
483.52441	1.4218928	0.36963037	3446.6365
484.42529	1.4242802	0.37074602	3457.7917
485.32617	1.4272859	0.37182143	3448.9329
486.22705	1.4295138	0.37270746	3451.8594
487.12793	1.430024	0.37366828	3454.7551
488.02881	1.4318885	0.37441868	3448.3879
488.92969	1.4396614	0.37546226	3457.2476
489.83057	1.440483	0.37640914	3456.168
490.73145	1.4418337	0.3772549	3457.8435
491.63232	1.4471339	0.37817246	3460.3577
492.5332	1.4483173	0.37920064	3462.4861
493.43408	1.4520583	0.38013136	3459.5662
494.33496	1.4546174	0.3810873	3461.6831
495.23584	1.4578176	0.3820917	3468.3411
496.13672	1.4593549	0.38322094	3464.7598
497.0376	1.458943	0.38414294	3461.3411
497.93848	1.464733	0.38502851	3462.7732
498.83936	1.4671786	0.38604304	3467.8083
499.74023	1.4705781	0.38701954	3472.3518
500.64111	1.4718567	0.38794848	3467.8196
501.54199	1.4760822	0.38883495	3465.863
502.44287	1.4749225	0.38968483	3465.0562
503.34375	1.4783472	0.39059517	3468.8796
504.24463	1.4834508	0.39154455	3470.9922
505.14551	1.4854335	0.39252925	3475.3298
506.04639	1.4873244	0.39339969	3469.5283
506.94727	1.4917243	0.39445534	3474.8105
507.84814	1.4928291	0.39540336	3480.9753
508.74902	1.4976037	0.39668277	3485.1472
509.6499	1.5001112	0.39778468	3476.043
510.55078	1.5050963	0.3988367	3483.5552
511.45166	1.5050453	0.39997301	3475.2192
512.35254	1.5094957	0.40100172	3480.5195
513.25342	1.5109199	0.40219596	3486.781
514.1543	1.5154023	0.40321177	3480.1382
515.05518	1.5160736	0.40418625	3484.0518
515.95605	1.5180488	0.40511781	3478.5076
516.85693	1.5212195	0.40602449	3477.853
517.75781	1.5259057	0.40698004	3487.6985
518.65869	1.5241349	0.40780875	3485.49
519.55957	1.5269251	0.40890211	3484.4763
520.46045	1.5303793	0.40999028	3490.6909
521.36133	1.5328765	0.41113269	3491.8464
522.26221	1.5348108	0.41229868	3490.3811
523.16309	1.5422	0.41356906	3492.0769
524.06396	1.5440402	0.41452566	3492.8945
524.96484	1.5475668	0.41560736	3496.332
525.86572	1.5500933	0.41650429	3493.5815
526.7666	1.5507452	0.41734084	3487.0017
527.66748	1.5539743	0.41821069	3491.7512
528.56836	1.558705	0.41929999	3493.5627
529.46924	1.5580206	0.42029634	3497.6914
530.37012	1.5618713	0.42163774	3501.7407
531.271	1.564568	0.42248711	3494.0042
532.17188	1.5682091	0.42339388	3495.5291
533.07275	1.5707293	0.42433864	3499.3374
533.97363	1.5722114	0.42528516	3495.834
534.87451	1.5741222	0.42620689	3500.8459
535.77539	1.5784181	0.42729759	3507.7141
536.67627	1.5814129	0.42825842	3501.5422
537.57715	1.5820751	0.42922232	3505.0261
538.47803	1.5843114	0.43034297	3512.1995
539.37891	1.588819	0.43150628	3506.251
540.27979	1.5922774	0.43253782	3501.8274
541.18066	1.5955843	0.43357342	3505.4087
542.08154	1.5976185	0.43456009	3511.1846
542.98242	1.5995727	0.43553278	3504.0344
543.8833	1.6007618	0.43655699	3509.176
544.78418	1.6049927	0.437666	3509.4587
545.68506	1.607299	0.43857026	3504.4485
546.58594	1.6103141	0.43960154	3516.6992
547.48682	1.6120821	0.44059759	3513.8787
548.3877	1.6160976	0.44176507	3511.751
549.28857	1.6180884	0.4427661	3513.8552
550.18945	1.6198463	0.44391987	3513.8511
551.09033	1.6254822	0.44507813	3528.8137
551.99121	1.6249387	0.44612288	3514.0239
552.89209	1.6286356	0.44724265	3518.4512
553.79297	1.6327431	0.44830191	3516.897
554.69385	1.636586	0.4493289	3515.116
555.59473	1.6385306	0.45039004	3520.2107
556.49561	1.6375247	0.45138693	3521.8455
557.39648	1.6420565	0.45241335	3520.364
558.29736	1.6458023	0.45346299	3521.4077
559.19824	1.6486801	0.45440754	3524.0085
560.09912	1.6497273	0.45522323	3519.657
561	1.6558611	0.45608962	3520.7302
561.90088	1.6559248	0.45707682	3525.8833
562.80176	1.660921	0.45805749	3523.5027
563.70264	1.6629775	0.45909891	3530.3149
564.60352	1.6659724	0.46018219	3524.0769
565.50439	1.666039	0.46118245	3526.1824
566.40527	1.6684799	0.46218064	3527.0283
567.30615	1.6709076	0.46294636	3524.6108
568.20703	1.6718348	0.46396273	3526.0405
569.10791	1.6797962	0.46502963	3538.7068
570.00879	1.6813078	0.46602395	3533.5955
570.90967	1.679504	0.46707311	3532.7715
571.81055	1.6863075	0.46823934	3535.1707
572.71143	1.6917256	0.4693422	3534.1926
573.6123	1.6896293	0.47020996	3531.3042
574.51318	1.6921172	0.4712629	3533.7124
575.41406	1.6974955	0.47214383	3532.9463
576.31494	1.7019948	0.47320515	3543.168
577.21582	1.7026955	0.47423163	3537.291
578.1167	1.7042733	0.47509795	3535.2427
579.01758	1.7055919	0.47648814	3541.208
579.91846	1.7096679	0.47747749	3538.7947
580.81934	1.7117082	0.47852099	3537.6245
581.72021	1.7177129	0.47963893	3542.333
582.62109	1.7175536	0.48061925	3541.8464
583.52197	1.7202691	0.48181438	3545.1992
584.42285	1.7223952	0.48295861	3543.4563
585.32373	1.7249583	0.48395145	3544.1348
586.22461	1.7285285	0.48515764	3545.5815
587.12549	1.73076	0.48617351	3540.9658
588.02637	1.7348092	0.48729151	3549.8953
588.92725	1.7354351	0.48833987	3545.1475
589.82813	1.741012	0.48938882	3544.7625
590.729	1.7426107	0.49047354	3549.5254
591.62988	1.7449981	0.49147898	3546.2664
592.53076	1.7479249	0.49268839	3551.8643
593.43164	1.7508613	0.49363548	3551.054
594.33252	1.7522292	0.49478024	3554.5542
595.2334	1.7559586	0.49589124	3547.53
596.13428	1.7566308	0.49715316	3553.2883
597.03516	1.7596436	0.49814123	3550.1826
597.93604	1.764827	0.49915221	3554.062
598.83691	1.7675509	0.50009149	3549.8645
599.73779	1.7719573	0.50091201	3549.1321
600.63867	1.7731928	0.50197816	3555.7617
601.53955	1.7769687	0.50317186	3558.6177
602.44043	1.7750577	0.50431418	3556.1172
603.34131	1.7812504	0.50556183	3557.7493
604.24219	1.7834949	0.50672412	3555.0544
605.14307	1.7833735	0.50755757	3552.906
606.04395	1.7902299	0.50856751	3559.6782
606.94482	1.7914811	0.50986731	3563.2495
607.8457	1.7945606	0.51088321	3559.344
608.74658	1.7967241	0.51183569	3555.6721
609.64746	1.798198	0.51278704	3556.3291
610.54834	1.8011404	0.51412898	3565.4126
611.44922	1.8057852	0.51503015	3559.7068
612.3501	1.8073915	0.51600128	3566.7219
613.25098	1.8148201	0.5171591	3563.8594
614.15186	1.812797	0.51811105	3564.8042
615.05273	1.8163441	0.51914054	3562.917
615.95361	1.8168681	0.5202083	3567.719
616.85449	1.8213277	0.52132148	3564.229
617.75537	1.8239568	0.5224219	3567.6538
618.65625	1.8255291	0.52339655	3569.8066
619.55713	1.8291665	0.52463549	3570.0527
620.45801	1.8315233	0.52569652	3565.7874
621.35889	1.8334851	0.52688807	3574.2053
622.25977	1.8347063	0.52820915	3572.2507
623.16064	1.8398074	0.52942204	3571.5073
624.06152	1.8406916	0.53060472	3570.0791
624.9624	1.8453374	0.53156722	3569.3206
625.86328	1.8480685	0.53262895	3572.2351
626.76416	1.8494835	0.53386933	3579.781
627.66504	1.8524165	0.53517389	3576.6748
628.56592	1.856141	0.53638178	3574.9937
629.4668	1.8581924	0.53755832	3572.6453
630.36768	1.861396	0.5386306	3573.374
631.26855	1.8648343	0.53967983	3570.6184
632.16943	1.8680315	0.54067445	3573.127
633.07031	1.8696773	0.54165727	3572.8755
633.97119	1.8702985	0.54269284	3578.2883
634.87207	1.8747914	0.54384929	3580.3157
635.77295	1.8788292	0.544981	3577.9587
636.67383	1.8808172	0.54594332	3583.4099
637.57471	1.882123	0.54725003	3585.8813
638.47559	1.8866441	0.54824662	3582.2844
639.37646	1.887747	0.54936773	3581.3337
640.27734	1.8930519	0.55053216	3585.2502
641.17822	1.8946801	0.55153596	3577.0972
642.0791	1.8971822	0.55259043	3583.2195
642.97998	1.8977954	0.55373609	3581.7524
643.88086	1.9012902	0.55491078	3584.1733
644.78174	1.907125	0.55603784	3585.7185
645.68262	1.9054796	0.55697393	3578.0906
646.5835	1.9075736	0.55798841	3584.312
647.48438	1.9163439	0.55910301	3588.699
648.38525	1.9177059	0.56019986	3585.2837
649.28613	1.9170973	0.56137431	3589.9153
650.18701	1.9219601	0.56269324	3592.1777
651.08789	1.9221513	0.56397265	3588.189
651.98877	1.9255748	0.56515276	3584.7166
652.88965	1.9288292	0.56632179	3591.1782
653.79053	1.9298228	0.56750506	3590.676
654.69141	1.9348184	0.5687682	3593.3918
655.59229	1.9362751	0.56981999	3585.5742
656.49316	1.9400903	0.57096398	3590.2993
657.39404	1.9427103	0.57196003	3592.5483
658.29492	1.9441651	0.57316226	3589.1609
659.1958	1.9490622	0.57439148	3598.311
660.09668	1.9499272	0.5755949	3593.7544
660.99756	1.9533508	0.57659572	3590.0168
661.89844	1.9547559	0.57783729	3594.97
662.79932	1.9575442	0.57891721	3593.3201
663.7002	1.9602239	0.5801571	3592.5916
664.60107	1.9662745	0.58138967	3598.5261
665.50195	1.9666392	0.58252203	3593.1326
666.40283	1.9725113	0.58359069	3601.4131
667.30371	1.9718442	0.58467835	3595.0447
668.20459	1.9757018	0.58579797	3593.4263
669.10547	1.9787774	0.58722377	3602.4316
670.00635	1.9820049	0.58845174	3600.9268
670.90723	1.9844184	0.58953005	3601.675
671.80811	1.9869015	0.59082448	3602.8206
672.70898	1.9906626	0.59181082	3594.0293
673.60986	1.989539	0.59298164	3600.4993
674.51074	1.9901984	0.59427965	3601.793
675.41162	1.9955999	0.59528542	3597.9709
676.3125	1.9988686	0.59650427	3599.9768
677.21338	2.0025566	0.59774995	3602.9412
678.11426	2.0063894	0.59893501	3602.0769
679.01514	2.0060692	0.60011232	3602.8169
679.91602	2.0090718	0.60128009	3601.7429
680.81689	2.0130553	0.60223466	3602.0671
681.71777	2.0146089	0.60332894	3601.0251
682.61865	2.0178831	0.6045509	3607.887
683.51953	2.0223563	0.60573196	3607.1196
684.42041	2.0222681	0.60705858	3606.5562
685.32129	2.0262494	0.60837829	3612.0576
686.22217	2.0272117	0.60964489	3607.865
687.12305	2.0308197	0.61081094	3605.9866
688.02393	2.0339241	0.6119023	3603.1091
688.9248	2.0386255	0.61286259	3607.1824
689.82568	2.0417368	0.61403453	3613.6912
690.72656	2.0425475	0.6154328	3615.3342
691.62744	2.0441396	0.61676329	3613.7793
692.52832	2.0514698	0.61818844	3618.2944
693.4292	2.0508997	0.61924839	3604.437
694.33008	2.0529373	0.6205309	3612.2961
695.23096	2.0570605	0.62204319	3616.4583
696.13184	2.0591044	0.62333304	3614.553
697.03271	2.0627332	0.6245814	3619.2185
697.93359	2.0635579	0.62584251	3607.5002
698.83447	2.0671794	0.62692839	3607.2
699.73535	2.0694301	0.62789929	3606.0432
700.63623	2.074152	0.62922317	3620.8015
701.53711	2.0753314	0.63056266	3617.0168
702.43799	2.0779979	0.63191003	3620.4683
703.33887	2.0799119	0.63313156	3612.9746
704.23975	2.0831246	0.63444018	3617.0234
705.14063	2.0860653	0.63604015	3621.0437
706.0415	2.0888162	0.63712776	3614.8496
706.94238	2.0896912	0.63819969	3608.324
707.84326	2.0938892	0.63920629	3611.3484
708.74414	2.0972826	0.64018905	3614.8357
709.64502	2.0975595	0.64127737	3615.321
710.5459	2.0993531	0.6425038	3614.0391
711.44678	2.1042778	0.64374274	3620.5398
712.34766	2.1075013	0.64481384	3617.0688
713.24854	2.1094856	0.64598894	3617.8049
714.14941	2.1138487	0.64716095	3616.6565
715.05029	2.118413	0.64850837	3618.3535
715.95117	2.1174531	0.64967602	3617.2361
716.85205	2.1213009	0.65091568	3623.7456
717.75293	2.1224103	0.65225011	3624.0378
718.65381	2.1290195	0.65360618	3619.2437
719.55469	2.1298673	0.65484214	3615.8286
720.45557	2.1315756	0.65605003	3620.7498
721.35645	2.1341059	0.65745574	3624.0869
722.25732	2.1390131	0.65887183	3624.9524
723.1582	2.1368892	0.66013688	3616.5693
724.05908	2.1412032	0.66117519	3615.6909
724.95996	2.1463606	0.66234905	3622.4409
725.86084	2.1465156	0.66369861	3622.616
726.76172	2.1519318	0.66510075	3624.918
727.6626	2.1549726	0.66648465	3630.3254
728.56348	2.1567407	0.66808003	3630.0945
729.46436	2.1580927	0.66919708	3618.0857
730.36523	2.1599336	0.67045051	3618.2271
731.26611	2.1619399	0.67160362	3619.6472
732.16699	2.1694241	0.6727109	3621.6392
733.06787	2.1720018	0.67404741	3625.4495
733.96875	2.1743124	0.67550749	3631.418
734.86963	2.1731527	0.67673784	3621.3528
735.77051	2.1784155	0.67818844	3630.8286
736.67139	2.1819916	0.67942762	3626.2166
737.57227	2.1843667	0.68066454	3626.2166
738.47314	2.1847641	0.68190688	3622.4607
739.37402	2.18998	0.68334275	3630.6387
740.2749	2.1901243	0.68496335	3630.1267
741.17578	2.1948223	0.6865145	3626.8386
742.07666	2.1995485	0.68792951	3628.6785
742.97754	2.1991107	0.68932086	3631.5588
743.87842	2.2009852	0.69062352	3626.0115
744.7793	2.2068536	0.6918509	3626.6719
745.68018	2.2092557	0.69318247	3630.4531
746.58105	2.2108874	0.69426489	3625.97
747.48193	2.2155645	0.69548327	3627.6807
748.38281	2.2145562	0.69673288	3630.4243
749.28369	2.2170825	0.69804376	3632.0823
750.18457	2.2220757	0.69941407	3628.7273
751.08545	2.2239251	0.70079726	3630.9429
751.98633	2.2243519	0.7023651	3629.7256
752.88721	2.228786	0.70372438	3630.1902
753.78809	2.2318928	0.70512509	3629.4253
754.68896	2.2312868	0.70668888	3632.4768
755.58984	2.2369633	0.7080164	3628.6475
756.49072	2.2402723	0.70932049	3626.6216
757.3916	2.2412498	0.71054298	3631.3184
758.29248	2.2426012	0.71198601	3631.8271
759.19336	2.2475622	0.71335089	3635.6973
760.09424	2.2507491	0.71471202	3631.022
760.99512	2.2541354	0.71616751	3634.3394
761.896	2.2563825	0.71751624	3627.8511
762.79688	2.2601156	0.71908253	3641.0264
763.69775	2.2619865	0.72065783	3634.3696
764.59863	2.2649891	0.72222912	3639.1091
765.49951	2.2667153	0.72378176	3629.7461
766.40039	2.2681451	0.72497702	3629.5151
767.30127	2.2734823	0.72619182	3629.5369
768.20215	2.2757485	0.72734559	3628.2825
769.10303	2.2775109	0.72875643	3634.6587
770.00391	2.2792127	0.73022944	3636.0957
770.90479	2.2832234	0.73152816	3629.416
771.80566	2.2873216	0.7329523	3632.0693
772.70654	2.2910166	0.73440456	3639.0486
773.60742	2.2907658	0.73575389	3628.8267
774.5083	2.2906256	0.73717278	3633.1135
775.40918	2.2966664	0.73863876	3637.1589
776.31006	2.2986126	0.74018717	3639.6667
777.21094	2.3016338	0.74164641	3635.311
778.11182	2.303715	0.74311185	3631.3538
779.0127	2.307945	0.74461061	3633.8591
779.91357	2.3099544	0.7462557	3638.9656
780.81445	2.3120823	0.74770743	3632.1135
781.71533	2.3147278	0.74878591	3625.6621
782.61621	2.3208337	0.74991751	3634.0183
783.51709	2.3204014	0.75125885	3635.7578
784.41797	2.3240736	0.7526083	3634.627
785.31885	2.3243449	0.75405359	3638.0757
786.21973	2.3265162	0.75562876	3638.3044
787.12061	2.3304615	0.75731587	3639.207
788.02148	2.3343053	0.75890303	3633.3879
788.92236	2.3360417	0.76025581	3637.2161
789.82324	2.3395596	0.76196247	3636.4766
790.72412	2.3453031	0.76327306	3635.9138
791.625	2.3450027	0.76465821	3632.5967
792.52588	2.3477573	0.76634151	3641.1162
793.42676	2.3525133	0.76766521	3635.6782
794.32764	2.3519938	0.76906198	3634.2295
795.22852	2.3548386	0.77056319	3639.6929
796.12939	2.3597834	0.77221441	3648.1052
797.03027	2.3605833	0.77387935	3637.6968
797.93115	2.3640101	0.77552557	3644.0881
798.83203	2.3669662	0.77714831	3635.8191
799.73291	2.3706861	0.77865916	3637.5261
800.63379	2.3732698	0.78023231	3636.3101
801.53467	2.373584	0.7818234	3636.335
802.43555	2.3770568	0.7834211	3641.1555
803.33643	2.380265	0.78493881	3636.1982
804.2373	2.3827348	0.78652495	3635.6765
805.13818	2.3866417	0.78809893	3639.7942
806.03906	2.3898959	0.78984612	3645.9973
806.93994	2.3905971	0.79123664	3630.6396
807.84082	2.3940933	0.79287928	3635.6956
808.7417	2.3946645	0.79436034	3632.8818
809.64258	2.3999157	0.79594326	3637.6587
810.54346	2.4032798	0.79742289	3636.2751
811.44434	2.4031935	0.79897779	3634.8311
812.34521	2.4059477	0.80075967	3636.5371
813.24609	2.4127269	0.80247164	3640.8896
814.14697	2.4109359	0.80423212	3638.9854
815.04785	2.41693	0.80581808	3635.6257
815.94873	2.4187901	0.80720639	3634.1084
816.84961	2.4206643	0.80857217	3632.8855
817.75049	2.4226639	0.80996364	3637.3225
818.65137	2.427213	0.81155294	3641.8979
819.55225	2.4286335	0.81345123	3647.2327
820.45313	2.4329166	0.81534016	3643.2654
821.354	2.4321835	0.81715113	3639.3911
822.25488	2.4353414	0.8189944	3634.9468
823.15576	2.441577	0.82069689	3636.2278
824.05664	2.4464405	0.82233161	3637.9902
824.95752	2.443795	0.82363611	3635.0818
825.8584	2.4468946	0.82536596	3641.2485
826.75928	2.4533548	0.82737237	3639.4792
827.66016	2.4555619	0.82909638	3638.0076
828.56104	2.4574327	0.83074152	3636.4226
829.46191	2.4565134	0.83230275	3635.1201
830.36279	2.4616101	0.83386588	3635.5635
831.26367	2.4646039	0.83561873	3639.001
832.16455	2.4660914	0.8370527	3630.5916
833.06543	2.4699695	0.83877558	3636.3989
833.96631	2.4715517	0.84071368	3641.8274
834.86719	2.4727132	0.84272152	3640.1499
835.76807	2.4778142	0.84464937	3637.6406
836.66895	2.4816232	0.84629518	3631.7971
837.56982	2.4842176	0.84807587	3636.9592
838.4707	2.4858279	0.84970194	3637.0481
839.37158	2.4885223	0.85137278	3633.2029
840.27246	2.4916806	0.85293072	3636.0662
841.17334	2.4935	0.85478497	3635.4509
842.07422	2.4974868	0.85657012	3638.3105
842.9751	2.4984319	0.85833585	3634.5198
843.87598	2.5020285	0.86022371	3636.7083
844.77686	2.5052326	0.86206532	3634.7317
845.67773	2.5064604	0.86389774	3632.7246
846.57861	2.5092876	0.86566144	3631.3062
847.47949	2.5126512	0.8678329	3642.0757
848.38037	2.5146186	0.87000859	3635.075
849.28125	2.5170479	0.87199056	3638.3457
850.18213	2.5232275	0.87439644	3639.9465
851.08301	2.5219393	0.87629241	3630.2236
851.98389	2.528748	0.87807018	3631.6616
852.88477	2.5288029	0.87964481	3624.6609
853.78564	2.5295167	0.88087028	3618.8677
854.68652	2.5347087	0.88238984	3634.7151
855.5874	2.5364718	0.88411331	3632.0608
856.48828	2.5402048	0.88603836	3636.4934
857.38916	2.542417	0.8884418	3637.3721
858.29004	2.5438306	0.8901931	3628.9253
859.19092	2.548749	0.89188272	3630.4893
860.0918	2.5502155	0.89367771	3625.646
860.99268	2.5535061	0.89547312	3631.9949
861.89355	2.5563872	0.89739192	3636.011
862.79443	2.5585518	0.89954376	3634.5078
863.69531	2.5613425	0.9016428	3634.2397
864.59619	2.5636287	0.90385437	3633.709
865.49707	2.5674894	0.90638566	3632.3381
866.39795	2.5686755	0.90819412	3626.4707
867.29883	2.5705278	0.91010416	3624.6509
868.19971	2.5778327	0.91210949	3627.1836
869.10059	2.5771852	0.91386449	3624.6494
870.00146	2.578356	0.91581178	3627.377
870.90234	2.5864882	0.91792494	3630.7324
871.80322	2.5870028	0.92024404	3632.9255
872.7041	2.5877993	0.92255133	3625.1289
873.60498	2.591265	0.92443305	3630.9978
874.50586	2.5945222	0.92653185	3630.9731
875.40674	2.5977232	0.92868477	3629.8933
876.30762	2.6002252	0.93108904	3628.3926
877.2085	2.5987055	0.93328476	3625.5601
878.10938	2.6044548	0.93574351	3630.2339
879.01025	2.6059744	0.93800896	3618.7896
879.91113	2.6068652	0.93995357	3616.5959
880.81201	2.6137428	0.94175583	3617.886
881.71289	2.6153417	0.94403899	3625.0198
882.61377	2.6177905	0.94584769	3619.0337
883.51465	2.6209769	0.94788718	3622.2126
884.41553	2.6233778	0.94991791	3623.6953
885.31641	2.6283221	0.95206767	3625.46
886.21729	2.6303709	0.95391178	3621.5259
887.11816	2.633642	0.95612919	3626.5823
888.01904	2.634254	0.95840061	3624.094
888.91992	2.6353106	0.96059942	3614.7241
889.8208	2.6402602	0.96243703	3614.8979
890.72168	2.6438067	0.96482903	3621.6389
891.62256	2.6460962	0.96734428	3622.1091
892.52344	2.6473057	0.96974808	3616.5823
893.42432	2.6502008	0.97216415	3618.7278
894.3252	2.6537931	0.97453803	3619.8967
895.22607	2.6565504	0.97680193	3612.1978
896.12695	2.6585317	0.97888058	3611.939
897.02783	2.6618805	0.98107779	3618.0906
897.92871	2.66414	0.98314112	3610.3262
898.82959	2.6657979	0.98556823	3615.8787
899.73047	2.6700938	0.98836249	3619.2949
900.63135	2.6734226	0.99117404	3613.4773
901.53223	2.6763978	0.99325413	3608.3298
902.43311	2.6784449	0.99546075	3609.4934
903.33398	2.6808243	0.99795634	3613.7302
904.23486	2.6835246	1.0004252	3605.5193
905.13574	2.686357	1.0027566	3611.3267
906.03662	2.6884713	1.0056571	3613.9041
906.9375	2.6921952	1.0083923	3605.7219
907.83838	2.6923501	1.010542	3599.0793
908.73926	2.6992471	1.0127199	3604.2834
909.64014	2.6999404	1.0150019	3609.8704
910.54102	2.7018676	1.0175976	3605.6265
911.44189	2.7031643	1.0201786	3600.7231
912.34277	2.7059658	1.0226241	3600.0388
913.24365	2.7111566	1.024951	3600.5762
914.14453	2.7134824	1.0274343	3599.8711
915.04541	2.7156618	1.0302618	3602.0483
915.94629	2.7175066	1.0328091	3597.635
916.84717	2.7210467	1.0356547	3597.8901
917.74805	2.7249322	1.0384897	3597.6206
918.64893	2.7270215	1.0409724	3587.9717
919.5498	2.7304428	1.0432775	3593.9792
920.45068	2.7323565	1.0457823	3594.0715
921.35156	2.731961	1.0483813	3586.4536
922.25244	2.7385578	1.0509752	3585.8013
923.15332	2.7405903	1.0533671	3588.8889
924.0542	2.7422523	1.0558484	3589.0374
924.95508	2.7445784	1.0586311	3590.8755
925.85596	2.7493641	1.0612781	3586.1958
926.75684	2.7497673	1.0642587	3585.4922
927.65771	2.7533202	1.066931	3579.4954
928.55859	2.7561326	1.0695397	3584.5186
929.45947	2.7591679	1.0723529	3580.9373
930.36035	2.7636631	1.0752233	3583.1223
931.26123	2.7636707	1.078293	3576.3599
932.16211	2.7691655	1.0811895	3572.7251
933.06299	2.7681894	1.083984	3576.2722
933.96387	2.7712562	1.0865378	3571.8994
934.86475	2.7751346	1.0887308	3568.0574
935.76563	2.779495	1.0911294	3576.4346
936.6665	2.7806962	1.0937977	3568.9734
937.56738	2.782069	1.096271	3565.6614
938.46826	2.7845991	1.0990567	3570.8535
939.36914	2.786953	1.1017048	3565.2178
940.27002	2.793335	1.1047379	3566.6072
941.1709	2.7938373	1.107796	3568.0383
942.07178	2.7959707	1.110772	3558.3994
942.97266	2.7991331	1.1137658	3557.6477
943.87354	2.8038118	1.1164079	3564.031
944.77441	2.8037601	1.1190486	3554.0784
945.67529	2.8087862	1.1215696	3558.2781
946.57617	2.810034	1.1243032	3554.1223
947.47705	2.8128245	1.1269115	3555.2925
948.37793	2.8181539	1.1297907	3551.1943
949.27881	2.8202064	1.1326615	3550.9021
950.17969	2.823143	1.1354829	3548.0122
951.08057	2.8253169	1.1381121	3545.1545
951.98145	2.8257008	1.1409189	3547.2942
952.88232	2.83006	1.1437384	3534.1064
953.7832	2.8323178	1.146459	3539.4985
954.68408	2.8338099	1.1490667	3536.7974
955.58496	2.8386805	1.1521266	3538.7991
956.48584	2.8397181	1.1550246	3534.8086
957.38672	2.8421528	1.1577837	3534.2371
958.2876	2.8443661	1.1607945	3530.3835
959.18848	2.8484716	1.1638855	3527.5112
960.08936	2.8495662	1.1668277	3520.3892
960.99023	2.8542204	1.1694044	3522.1296
961.89111	2.8583381	1.1721762	3519.4463
962.79199	2.85974	1.1746794	3517.6541
963.69287	2.8602743	1.1773731	3516.4028
964.59375	2.8627024	1.1803244	3516.1758
965.49463	2.8655193	1.183171	3514.0959
966.39551	2.8692286	1.1862503	3513.2097
967.29639	2.875881	1.1891392	3513.0171
968.19727	2.8759727	1.1918091	3510.5776
969.09814	2.8775213	1.1950666	3508.835
969.99902	2.8794556	1.198217	3501.6489
970.8999	2.8826318	1.201331	3499.2463
971.80078	2.8851652	1.2042025	3497.0906
972.70166	2.8912306	1.2068106	3493.9197
973.60254	2.8907776	1.2097094	3495.7583
974.50342	2.8949423	1.2127635	3484.9272
975.4043	2.8940117	1.2154077	3482.8228
976.30518	2.8983157	1.2182521	3486.1995
977.20605	2.9034226	1.2216179	3486.2097
978.10693	2.9065707	1.2250552	3481.6406
979.00781	2.9076538	1.2281621	3473.678
979.90869	2.9138751	1.2311474	3480.332
980.80957	2.9136868	1.2339299	3463.9329
981.71045	2.9157548	1.2365335	3466.561
982.61133	2.9211054	1.2396907	3466.8728
983.51221	2.9233308	1.2424848	3462.8386
984.41309	2.92349	1.24546	3461.0222
985.31396	2.926333	1.2485837	3458.4355
986.21484	2.9297538	1.2514154	3449.2061
987.11572	2.9325078	1.2540736	3451.2668
988.0166	2.9358563	1.2569489	3454.0186
988.91748	2.9365096	1.260402	3449.8591
989.81836	2.9416075	1.2639813	3442.8147
990.71924	2.9431195	1.2666279	3436.699
991.62012	2.944577	1.2691746	3435.5847
992.521	2.9510891	1.2717007	3436.2437
993.42188	2.9533162	1.2744809	3428.5811
994.32275	2.9542875	1.2768531	3423.3376
995.22363	2.9563086	1.2791903	3422.3735
996.12451	2.9591606	1.2815374	3420.0186
997.02539	2.9613597	1.2839319	3421.0828
997.92627	2.9632354	1.2873731	3422.6011
998.82715	2.9678941	1.2907941	3413.2288
999.72803	2.9705298	1.2942528	3408.7366
1000.6289	2.9716213	1.2969205	3404.8743
1001.5298	2.9759779	1.2995464	3404.4861
1002.4307	2.9781001	1.3027629	3403.2551
1003.3315	2.9837787	1.3055933	3393.1794
1004.2324	2.9858618	1.3085464	3395.3403
1005.1333	2.9852762	1.3116091	3389.3022
1006.0342	2.9907389	1.3141161	3383.5825
1006.9351	2.988205	1.3162056	3380.5217
1007.8359	2.9949305	1.318635	3380.2778
1008.7368	2.9980102	1.3207777	3376.0139
1009.6377	3.001447	1.3234969	3380.533
1010.5386	3.0028107	1.3264678	3375.7273
1011.4395	3.0055401	1.3295783	3370.1055
1012.3403	3.0078907	1.3326215	3363.2
1013.2412	3.0105653	1.3354076	3358.8577
1014.1421	3.0135443	1.3381917	3358.6218
1015.043	3.0124171	1.3416172	3356.2332
1015.9438	3.0196686	1.3448977	3350.7495
1016.8447	3.019356	1.3480954	3341.7383
1017.7456	3.025099	1.3508774	3337.6838
1018.6465	3.0261357	1.3534503	3340.5178
1019.5474	3.0302646	1.356495	3342.9771
1020.4482	3.034301	1.3596063	3333.4326
1021.3491	3.0335743	1.3627342	3329.9673
1022.25	3.037945	1.3660659	3325.1729
1023.1509	3.0396132	1.3693886	3313.9326
1024.0518	3.0437183	1.3724324	3312.6672
1024.9526	3.0466096	1.3754702	3312.4958
1025.8535	3.0484152	1.3781201	3303.4358
1026.7544	3.0518603	1.3810542	3302.2449
1027.6553	3.0529025	1.3838603	3298.614
1028.5562	3.0564184	1.3874891	3303.8025
1029.457	3.0589592	1.3908967	3286.2703
1030.3579	3.0621812	1.3943028	3284.9336
1031.2588	3.0641057	1.3971893	3276.9419
1032.1597	3.0674503	1.4001285	3277.9382
1033.0605	3.0716588	1.4029777	3268.0896
1033.9614	3.0722756	1.4057384	3270.8442
1034.8623	3.0735745	1.4093648	3263.9717
1035.7632	3.0752273	1.4128109	3260.9438
1036.6641	3.0806856	1.4160427	3249.1377
1037.5649	3.0836554	1.4189632	3242.4438
1038.4658	3.0875852	1.4212612	3241.9543
1039.3667	3.091361	1.4236952	3242.1724
1040.2676	3.0931339	1.4269446	3242.3191
1041.1685	3.0957816	1.4301777	3229.2461
1042.0693	3.0981588	1.4329667	3224.6143
1042.9702	3.1029108	1.4355092	3223.6802
1043.8711	3.1040421	1.4389969	3226.2979
1044.772	3.1074319	1.443	3216.0669
1045.6729	3.1088269	1.4469346	3204.2878
1046.5737	3.1114168	1.4502304	3199.291
1047.4746	3.1141598	1.4528676	3190.397
1048.3755	3.1151795	1.4556978	3192.521
1049.2764	3.1157496	1.4589785	3186.6868
1050.1772	3.1195543	1.4628114	3182.7761
1051.0781	3.1215696	1.4660504	3166.9602
1051.979	3.1255088	1.4687644	3162.8406
1052.8799	3.1318493	1.4715539	3163.9275
1053.7808	3.1318188	1.4746594	3163.6794
1054.6816	3.135257	1.477847	3154.5767
1055.5825	3.1389225	1.4812524	3150.6431
1056.4834	3.1420972	1.4845339	3143.0586
1057.3843	3.1432455	1.4874717	3137.0374
1058.2852	3.1459708	1.4906857	3132.4109
1059.186	3.1462741	1.4938641	3124.0708
1060.0869	3.149111	1.4972824	3118.7437
1060.9878	3.1547229	1.5009733	3112.7229
1061.8887	3.1568744	1.504248	3103.1765
1062.7896	3.1599398	1.5072347	3097.6621
1063.6904	3.1661792	1.510102	3099.6755
1064.5913	3.1653085	1.5128286	3085.2305
1065.4922	3.1682632	1.515733	3086.2361
1066.3931	3.1715539	1.5193615	3084.655
1067.2939	3.1713362	1.5227368	3072.9167
1068.1948	3.1745822	1.5254267	3058.4546
1069.0957	3.1783493	1.5284449	3057.2212
1069.9966	3.1777964	1.53153	3052.1936
1070.8975	3.1849923	1.5351344	3051.4712
1071.7983	3.1861403	1.5386531	3044.2717
1072.6992	3.1863036	1.5422794	3032.5674
1073.6001	3.1929345	1.5456533	3028.6394
1074.501	3.1953239	1.5488055	3017.3228
1075.4019	3.1938634	1.5518067	3013.9954
1076.3027	3.2034829	1.5551203	3007.3701
1077.2036	3.204772	1.558422	3007.7981
1078.1045	3.2072027	1.5622482	2996.3142
1079.0054	3.2096384	1.5656803	2985.0769
1079.9063	3.2108719	1.568475	2976.2451
1080.8071	3.2170281	1.5720165	2978.2639
1081.708	3.2176352	1.5755521	2967.6414
1082.6089	3.2220771	1.5785857	2959.1467
1083.5098	3.2214899	1.5812081	2950.1021
1084.4106	3.2242272	1.5842341	2943.4048
1085.3115	3.226378	1.5876484	2941.1877
1086.2124	3.2314548	1.5916473	2933.3066
1087.1133	3.232228	1.595201	2918.4849
1088.0142	3.2362304	1.5989935	2914.1636
1088.915	3.2385507	1.6026294	2906.2229
1089.8159	3.2388573	1.6056715	2889.6541
1090.7168	3.2429447	1.6086575	2883.7683
1091.6177	3.245924	1.6117266	2888.2312
1092.5186	3.2514002	1.615658	2879.5898
1093.4194	3.2509665	1.6193544	2863.4851
1094.3203	3.2559204	1.622708	2858.0688
1095.2212	3.2561538	1.6259331	2848.0728
1096.1221	3.2605808	1.6291139	2837.8291
1097.0229	3.262172	1.6326548	2835.6514
1097.9238	3.2652388	1.6359698	2823.6624
1098.8247	3.2682645	1.6394545	2811.7742
1099.7256	3.2714894	1.6431173	2805.2871
1100.6265	3.2752423	1.6472092	2797.865
1101.5273	3.2743881	1.6511301	2782.4294
1102.4282	3.2797623	1.6543911	2772.8647
1103.3291	3.2790647	1.6574349	2758.1995
1104.23	3.2867634	1.6613909	2752.6577
1105.1309	3.2859468	1.6644531	2742.8335
1106.0317	3.2905378	1.6679605	2740.8071
1106.9326	3.2906437	1.6720165	2718.0015
1107.8335	3.2936065	1.6757556	2705.8154
1108.7344	3.2987411	1.6805471	2685.8076
1109.335	3.3019896	1.6893376	2619.6218