File: datasets/am_bench_2022/raw_data/90-X.19-3/specimen.dat
MTS793|MPT|ENU|1|2|.|/|:|1|0|0|A

Operator Information						Time:	13.352539	Sec	11/2/2021 1:59:34 PM
Operator	Nick Derimow
Project	AM Bench 2022 mini-tensile challenge
Specimen ID	90-X.19-3
Material	PBF-L Inconel 625
Specimen Width	2.54	mm
Specimen Thickness	1.51	mm
Notes
Operator Information End

Data Acquisition						Time:	1014.3469	Sec	11/2/2021 2:16:15 PM
Time	Axial Displacement	Axial Extensometer	Axial Force
Sec	mm	mm	N
13.466797	0.0029377367	5.9039099e-05	64.754318
14.367676	0.00099455088	0.00022745742	78.627167
15.268555	0.0060100257	0.00021643429	90.699707
16.169434	0.0056592524	0.00028199941	97.366295
17.070313	0.0094851302	0.00036378572	108.00284
17.971191	0.013129679	0.00045564142	115.28041
18.87207	0.015912099	0.00054457231	123.97919
19.772949	0.017976938	0.00063220621	138.07249
20.673828	0.023485944	0.00063151366	147.582
21.574707	0.02411291	0.00078190264	157.12505
22.475586	0.025360081	0.00079235615	168.67438
23.376465	0.032135773	0.00099037611	182.67453
24.277344	0.032392912	0.0010819705	196.97005
25.178223	0.032825846	0.0012440158	217.89333
26.079102	0.03876492	0.0012624683	228.27118
26.97998	0.040497888	0.0013991705	244.25798
27.880859	0.040212065	0.0014498226	255.93608
28.781738	0.046309773	0.0016514045	280.00998
29.682617	0.046036448	0.0017793241	298.53528
30.583496	0.050593533	0.0018864207	314.33109
31.484375	0.052976005	0.0020012436	332.26648
32.385254	0.057398934	0.0021371262	350.97769
33.286133	0.057270057	0.0022711474	364.68677
34.187012	0.061087329	0.0023645316	390.82864
35.087891	0.063948378	0.0024869244	405.94046
35.98877	0.066311792	0.0025445919	421.15295
36.889648	0.068198636	0.0027062704	446.36649
37.790527	0.071516179	0.0028759458	465.60818
38.691406	0.075355574	0.0029961336	487.69119
39.592285	0.078609198	0.0031301344	508.62558
40.493164	0.078343041	0.0032296253	523.39935
41.394043	0.082954727	0.0034888873	539.703
42.294922	0.083175808	0.003494075	560.70642
43.195801	0.085402101	0.0036898248	583.81323
44.09668	0.089847155	0.0038124921	609.24988
44.997559	0.093954556	0.004101627	642.49725
45.898438	0.0977915	0.0041668634	659.28955
46.799316	0.096725702	0.0041967151	677.81372
47.700195	0.098614134	0.0043566478	700.38123
48.601074	0.1034616	0.0046478645	731.37939
49.501953	0.10371013	0.0048290556	755.65509
50.402832	0.11045017	0.0048937388	781.14514
51.303711	0.1101246	0.0050644884	795.85297
52.20459	0.1143303	0.005150964	818.99072
53.105469	0.1190958	0.0053282906	839.09406
54.006348	0.11982993	0.0054159625	862.17108
54.907227	0.1238794	0.0056448691	884.95764
55.808105	0.12657775	0.0057822708	910.27399
56.708984	0.12621632	0.0059697032	939.3233
57.609863	0.13171612	0.0061361706	964.06171
58.510742	0.13052903	0.006329176	992.28461
59.411621	0.13693571	0.006398215	1011.0685
60.3125	0.13970743	0.0066405199	1041.2408
61.213379	0.14180587	0.0067507094	1066.4419
62.114258	0.1444907	0.0068877139	1087.3011
63.015137	0.14531048	0.0070308005	1109.3986
63.916016	0.1507366	0.0072730863	1133.6445
64.816895	0.15006681	0.0073414603	1160.2159
65.717773	0.15631016	0.0074632918	1181.073
66.618652	0.15740161	0.0077073793	1206.338
67.519531	0.16218351	0.0079255123	1229.2809
68.42041	0.16226996	0.0079032527	1251.3462
69.321289	0.16596143	0.0080957254	1282.6458
70.222168	0.17014013	0.0083007663	1312.1982
71.123047	0.16920072	0.0084761754	1339.2781
72.023926	0.17167513	0.0086525269	1364.8088
72.924805	0.17573811	0.0087985629	1387.2711
73.825684	0.1830561	0.0089104734	1415.2991
74.726563	0.17927305	0.0091500785	1441.8818
75.627441	0.18398426	0.0092815515	1460.4781
76.52832	0.18765812	0.0093241967	1481.1991
77.429199	0.19066407	0.0094839977	1507.551
78.330078	0.19172023	0.0097182058	1532.8723
79.230957	0.19552274	0.0099651655	1558.0015
80.131836	0.19626199	0.009873868	1580.0197
81.032715	0.20372838	0.010211106	1607.8652
81.933594	0.20028785	0.010206628	1628.4758
82.834473	0.20512445	0.010413536	1649.531
83.735352	0.20992766	0.010651395	1677.4225
84.63623	0.20822234	0.010796035	1699.6086
85.537109	0.21478516	0.01099204	1729.5137
86.437988	0.21703465	0.011052358	1748.0375
87.338867	0.21903844	0.011208864	1771.3585
88.239746	0.21961254	0.01133931	1791.3665
89.140625	0.22746898	0.011517365	1818.7842
90.041504	0.22842604	0.011633825	1840.3295
90.942383	0.22753353	0.011761839	1866.2732
91.843262	0.2332778	0.011928475	1879.4631
92.744141	0.23282233	0.012096087	1908.8202
93.64502	0.23854196	0.012263996	1924.7141
94.545898	0.24138154	0.01237886	1948.6594
95.446777	0.24422461	0.012493762	1967.689
96.347656	0.24713258	0.012659386	1990.1116
97.248535	0.249515	0.012803008	2014.7087
98.149414	0.25145409	0.013004726	2034.0156
99.050293	0.25583234	0.01316749	2059.1892
99.951172	0.25833264	0.013267918	2073.7307
100.85205	0.25857517	0.013461644	2092.8044
101.75293	0.26566797	0.013610113	2117.8691
102.65381	0.27015901	0.013749488	2135.4995
103.55469	0.27123794	0.013906199	2152.5793
104.45557	0.26900813	0.014018691	2166.1677
105.35645	0.27569258	0.01433217	2198.9573
106.25732	0.27758864	0.014387802	2213.0322
107.1582	0.28159136	0.014617604	2224.7705
108.05908	0.28240374	0.014761765	2250.5752
108.95996	0.28690186	0.015075949	2267.2439
109.86084	0.2884832	0.015135674	2284.2786
110.76172	0.29012394	0.015264262	2301.4536
111.6626	0.29512402	0.015511021	2322.7659
112.56348	0.29460463	0.015726745	2336.2354
113.46436	0.29901713	0.015890168	2353.2151
114.36523	0.3023113	0.015967816	2361.8396
115.26611	0.30404428	0.016062872	2377.3848
116.16699	0.3067418	0.016291454	2390.7058
117.06787	0.30689529	0.016437519	2405.9561
117.96875	0.31360069	0.016688079	2428.0479
118.86963	0.31456369	0.016895328	2435.5051
119.77051	0.31530151	0.017022403	2449.8745
120.67139	0.32210603	0.017277867	2470.603
121.57227	0.32013127	0.01735419	2473.9114
122.47314	0.32287458	0.017533539	2482.9785
123.37402	0.32611918	0.017720811	2496.3792
124.2749	0.33065438	0.017987818	2517.656
125.17578	0.33233362	0.018231021	2528.0481
126.07666	0.33601859	0.018572258	2539.7551
126.97754	0.34234822	0.018622754	2548.4211
127.87842	0.33989957	0.01885963	2559.7209
128.7793	0.34168315	0.019075917	2564.0154
129.68018	0.34796193	0.019243063	2567.5637
130.58105	0.3491458	0.019568095	2582.9587
131.48193	0.35233164	0.019756241	2594.9756
132.38281	0.35454687	0.019951815	2606.7466
133.28369	0.35902902	0.020253988	2612.1101
134.18457	0.36419508	0.020586813	2627.7817
135.08545	0.36500788	0.020725958	2629.6223
135.98633	0.36915341	0.020992115	2637.1516
136.88721	0.37173539	0.021267613	2640.2908
137.78809	0.37158376	0.021500671	2646.5442
138.68896	0.37519184	0.021726334	2656.6963
139.58984	0.37729585	0.02215663	2668.3555
140.49072	0.38182431	0.02254203	2676.8818
141.3916	0.38211629	0.02295908	2685.1165
142.29248	0.38547379	0.023285639	2687.0002
143.19336	0.38969263	0.023539832	2696.5159
144.09424	0.39317656	0.02417377	2708.2544
144.99512	0.39607412	0.024586448	2714.4248
145.896	0.39709669	0.025019629	2713.5776
146.79688	0.40189189	0.025633888	2723.1433
147.69775	0.40122724	0.026077542	2732.2407
148.59863	0.40548304	0.026691757	2740.874
149.49951	0.40692747	0.027152749	2741.1746
150.40039	0.4113133	0.02761553	2741.3042
151.30127	0.41396475	0.028352441	2752.6262
152.20215	0.4160538	0.029000102	2756.3008
153.10303	0.42173499	0.029679103	2765.2668
154.00391	0.41956401	0.030368697	2768.6528
154.90479	0.42469192	0.030909222	2773.9883
155.80566	0.42506728	0.031634502	2781.3225
156.70654	0.42957032	0.032396201	2784.7207
157.60742	0.43301925	0.033238653	2789.5549
158.5083	0.43847805	0.033893269	2790.1484
159.40918	0.43619296	0.034576215	2794.2476
160.31006	0.44115305	0.035439402	2800.9033
161.21094	0.44389018	0.03633666	2807.7241
162.11182	0.44659102	0.037168104	2809.2566
163.0127	0.44912204	0.03789245	2811.657
163.91357	0.45084512	0.038712051	2816.4329
164.81445	0.45366991	0.039465051	2812.0164
165.71533	0.45822564	0.04025064	2826.7175
166.61621	0.4606179	0.041122828	2827.6787
167.51709	0.46176529	0.04210858	2838.8833
168.41797	0.46578234	0.042978246	2838.7649
169.31885	0.46871242	0.044011489	2847.9685
170.21973	0.4700022	0.044694915	2841.23
171.12061	0.47321472	0.045571018	2848.4001
172.02148	0.47568071	0.046532929	2853.4729
172.92236	0.4787614	0.047309797	2857.7573
173.82324	0.48076621	0.048246246	2855.6921
174.72412	0.48446327	0.049205262	2862.4551
175.625	0.48608333	0.04991458	2866.969
176.52588	0.48862416	0.050856307	2866.6311
177.42676	0.49271473	0.051782347	2870.2644
178.32764	0.49276063	0.052745402	2873.5488
179.22852	0.49956727	0.053638149	2882.0264
180.12939	0.5026418	0.05457814	2882.7761
181.03027	0.50479662	0.055509642	2888.6816
181.93115	0.50576878	0.056412399	2887.7971
182.83203	0.50718802	0.05737805	2883.7764
183.73291	0.51025343	0.058281865	2890.5742
184.63379	0.51245087	0.059288077	2897.7849
185.53467	0.51521152	0.060274553	2898.0627
186.43555	0.5239498	0.06128899	2908.5791
187.33643	0.52166241	0.062077351	2908.1064
188.2373	0.52761483	0.062994748	2912.1047
189.13818	0.52803361	0.064244173	2917.7893
190.03906	0.52930558	0.065286607	2914.6863
190.93994	0.53236455	0.066429593	2924.22
191.84082	0.53610069	0.067307025	2920.1243
192.7417	0.53900152	0.068195194	2919.8733
193.64258	0.53957194	0.06917502	2929.468
194.54346	0.54327595	0.07014031	2927.0151
195.44434	0.54618102	0.071044624	2922.5681
196.34521	0.55072159	0.07184989	2933.5903
197.24609	0.54808646	0.072937794	2935.0681
198.14697	0.55673468	0.073894769	2941.1836
199.04785	0.56028783	0.075047478	2947.4727
199.94873	0.5600059	0.075929441	2940.7605
200.84961	0.56095964	0.076771438	2944.6563
201.75049	0.56607306	0.077612564	2947.1816
202.65137	0.56629336	0.078709945	2954.1431
203.55225	0.57054746	0.079760388	2955.6353
204.45313	0.57198572	0.080892801	2957.6697
205.354	0.57430953	0.081859939	2962.3821
206.25488	0.57914662	0.082641043	2955.0247
207.15576	0.58011597	0.08361084	2962.9243
208.05664	0.583924	0.084510565	2966.9131
208.95752	0.58631605	0.085475683	2965.9849
209.8584	0.58908081	0.086383402	2974.0786
210.75928	0.59339213	0.087676406	2988.0554
211.66016	0.59379101	0.088655733	2976.4126
212.56104	0.59849668	0.08949139	2975.7622
213.46191	0.59902507	0.090444617	2978.4636
214.36279	0.60617632	0.091300748	2988.8254
215.26367	0.60586303	0.092466645	2989.0354
216.16455	0.60792625	0.093383707	2984.8274
217.06543	0.61014444	0.094118476	2981.9709
217.96631	0.61337548	0.095019802	2992.7983
218.86719	0.6175257	0.096232161	2996.3132
219.76807	0.6175884	0.097129211	2994.9705
220.66895	0.61908942	0.098133691	2993.7344
221.56982	0.62589496	0.09947037	3009.8398
222.4707	0.6284278	0.10041047	3005.0142
223.37158	0.6274243	0.10133755	3003.8062
224.27246	0.63357878	0.10245051	3008.0176
225.17334	0.63567555	0.10344864	3011.7747
226.07422	0.64032221	0.10437381	3012.1938
226.9751	0.64065808	0.10540317	3014.4766
227.87598	0.6410234	0.10645106	3018.9734
228.77686	0.6454342	0.10728651	3014.5266
229.67773	0.64861161	0.1083771	3021.7761
230.57861	0.65094084	0.10927048	3017.7292
231.47949	0.65419626	0.11045406	3027.1711
232.38037	0.65730524	0.1115023	3025.9055
233.28125	0.65698272	0.11261031	3030.1492
234.18213	0.66212237	0.11386558	3034.7522
235.08301	0.6662693	0.1149032	3037.6753
235.98389	0.66596979	0.11584853	3028.5867
236.88477	0.67020464	0.11667032	3035.2649
237.78564	0.67425692	0.11766644	3038.4993
238.68652	0.6766367	0.11849078	3040.2566
239.5874	0.6794039	0.11955664	3043.7529
240.48828	0.68380982	0.12050876	3047.3359
241.38916	0.68729031	0.12155005	3045.7163
242.29004	0.68646175	0.1225351	3051.1558
243.19092	0.69048983	0.12336458	3051.4895
244.0918	0.69125819	0.12436717	3049.2168
244.99268	0.69518566	0.12522006	3051.8711
245.89355	0.69783056	0.12627152	3054.8535
246.79443	0.70099264	0.12739554	3060.4075
247.69531	0.7041055	0.1281855	3059.1394
248.59619	0.70472407	0.12927957	3063.9197
249.49707	0.70753121	0.13035069	3064.1343
250.39795	0.7099067	0.13130605	3066.1257
251.29883	0.71474171	0.13239785	3074.2336
252.19971	0.71689713	0.13333575	3066.9087
253.10059	0.71973908	0.13411056	3070.7688
254.00146	0.72016996	0.13511729	3073.7227
254.90234	0.72285485	0.13607037	3076.3538
255.80322	0.72607738	0.13702226	3073.4675
256.7041	0.73183203	0.13809662	3085.4343
257.60498	0.73102295	0.13919386	3081.2686
258.50586	0.73544359	0.14018646	3081.4243
259.40674	0.73850137	0.14122485	3084.2871
260.30762	0.74040627	0.14230473	3090.2065
261.2085	0.74403214	0.14326398	3090.2053
262.10938	0.74761951	0.14426163	3088.4712
263.01025	0.75152427	0.14525126	3098.4392
263.91113	0.75289935	0.1464033	3096.7617
264.81201	0.75514168	0.14745505	3101.0142
265.71289	0.7561208	0.14839274	3094.0435
266.61377	0.75859851	0.14923353	3095.1497
267.51465	0.76179641	0.15007259	3097.1958
268.41553	0.76368237	0.15111013	3105.1086
269.31641	0.76721305	0.15237142	3101.4119
270.21729	0.77245981	0.15347275	3108.5876
271.11816	0.77116352	0.15455213	3109.6934
272.01904	0.77378482	0.15532814	3103.9348
272.91992	0.7794742	0.15617621	3109.4419
273.8208	0.77969426	0.15689442	3106.187
274.72168	0.78451097	0.15788691	3116.4377
275.62256	0.78776151	0.15876576	3117.8677
276.52344	0.78962517	0.15983362	3122.9807
277.42432	0.79212648	0.16086684	3121.1125
278.3252	0.79558033	0.16183001	3126.688
279.22607	0.801135	0.16277489	3120.7947
280.12695	0.80133557	0.16376528	3124.0266
281.02783	0.79972476	0.16460867	3129.8682
281.92871	0.80561799	0.16581947	3126.8816
282.82959	0.80976796	0.16680588	3127.8997
283.73047	0.80817437	0.16762485	3128.8345
284.63135	0.81440258	0.16838671	3126.7029
285.53223	0.81465256	0.16946758	3135.1406
286.43311	0.82241255	0.17030258	3135.9167
287.33398	0.8224842	0.17122118	3136.6934
288.23486	0.82554382	0.17219204	3140.8086
289.13574	0.82739538	0.1733387	3145.4592
290.03662	0.82976693	0.1743589	3140.8191
290.9375	0.83485478	0.17530592	3140.6504
291.83838	0.83606791	0.17607345	3140.53
292.73926	0.83765274	0.17711402	3154.0056
293.64014	0.84057277	0.17805953	3145.7527
294.54102	0.84316581	0.17888209	3148.6804
295.44189	0.8466953	0.17995214	3155.8479
296.34277	0.84764576	0.18093914	3156.2515
297.24365	0.84988105	0.18195556	3158.6133
298.14453	0.85649812	0.18299598	3162.4106
299.04541	0.85482466	0.18387006	3155.6392
299.94629	0.86164683	0.18475528	3156.719
300.84717	0.86359102	0.18560214	3157.6157
301.74805	0.86379284	0.18647861	3158.2813
302.64893	0.86803871	0.1873741	3157.3398
303.5498	0.87028199	0.18855806	3173.4312
304.45068	0.87387067	0.18978608	3171.2041
305.35156	0.87666553	0.19086109	3171.7275
306.25244	0.87977225	0.19184212	3172.7461
307.15332	0.88468528	0.19289547	3174.583
308.0542	0.88500142	0.19383739	3176.2083
308.95508	0.88914108	0.19471832	3173.9241
309.85596	0.88778901	0.19561166	3173.5828
310.75684	0.89226252	0.19659439	3173.8494
311.65771	0.89599824	0.19754834	3181.3601
312.55859	0.89634997	0.19850837	3183.6221
313.45947	0.89907074	0.19949616	3184.4819
314.36035	0.89928913	0.20042866	3182.1853
315.26123	0.90561795	0.20141698	3189.9268
316.16211	0.91046089	0.2022104	3190.7351
317.06299	0.91227645	0.20312361	3189.1152
317.96387	0.91230285	0.20388214	3189.2358
318.86475	0.91818523	0.20462786	3187.6392
319.76563	0.91986734	0.20549247	3188.5222
320.6665	0.92189002	0.20634617	3199.3264
321.56738	0.92333442	0.20724568	3192.3159
322.46826	0.92647541	0.20823495	3201.2224
323.36914	0.92812026	0.20922862	3199.7888
324.27002	0.93439412	0.21037161	3203.4832
325.1709	0.93629104	0.21141568	3207.8916
326.07178	0.93603349	0.21242465	3204.4519
326.97266	0.94359487	0.21316563	3204.4824
327.87354	0.94467139	0.21410362	3212.8154
328.77441	0.94660598	0.21511655	3208.2949
329.67529	0.94998044	0.21626823	3211.2568
330.57617	0.95441526	0.21734875	3216.0271
331.47705	0.95452672	0.2180609	3210.1501
332.37793	0.95662993	0.21894044	3210.0725
333.27881	0.9609676	0.22001114	3223.5186
334.17969	0.9608897	0.221172	3217.197
335.08057	0.96650678	0.22218108	3217.5437
335.98145	0.96773529	0.22315475	3215.551
336.88232	0.96864724	0.22397596	3219.4731
337.7832	0.97447979	0.2250202	3227.0015
338.68408	0.97380161	0.22579232	3224.6135
339.58496	0.97893304	0.22670567	3223.0833
340.48584	0.98277432	0.22757387	3220.9646
341.38672	0.98552579	0.22850455	3225.1177
342.2876	0.98663896	0.22951901	3229.7524
343.18848	0.98841202	0.23048559	3236.8955
344.08936	0.99385875	0.23141694	3233.0103
344.99023	0.99284357	0.23243271	3232.0715
345.89111	0.99831063	0.23339245	3237.3174
346.79199	0.99972659	0.23424701	3233.9382
347.69287	0.99936783	0.23522995	3236.8835
348.59375	1.0044765	0.2361996	3239.1055
349.49463	1.0105518	0.23722142	3242.1462
350.39551	1.0118793	0.23800066	3232.1443
351.29639	1.0129042	0.23906547	3245.2437
352.19727	1.0198854	0.24000359	3245.5017
353.09814	1.0160385	0.24093431	3245.5264
353.99902	1.018573	0.2418623	3246.2178
354.8999	1.0278922	0.24300943	3249.791
355.80078	1.0303435	0.24399167	3245.3064
356.70166	1.0314776	0.24482416	3250.926
357.60254	1.030717	0.24554271	3245.1755
358.50342	1.0362183	0.24635962	3256.5068
359.4043	1.0367941	0.24728554	3255.1646
360.30518	1.0405217	0.24842162	3258.3066
361.20605	1.0414253	0.24940413	3261.8853
362.10693	1.0456175	0.25021574	3253.998
363.00781	1.0499057	0.25118053	3255.5847
363.90869	1.0528774	0.25192788	3256.936
364.80957	1.05629	0.25278014	3261.5549
365.71045	1.059116	0.2536467	3268.8447
366.61133	1.0595758	0.25465503	3271.3054
367.51221	1.0631397	0.25557902	3268.0283
368.41309	1.0639236	0.25653845	3266.3796
369.31396	1.0673189	0.25758681	3275.9351
370.21484	1.069217	0.25872689	3276.4277
371.11572	1.0749984	0.25970513	3275.1978
372.0166	1.0768534	0.26066926	3270.9163
372.91748	1.0770059	0.26161778	3270.7837
373.81836	1.0824128	0.26253828	3276.6465
374.71924	1.0834744	0.26367927	3281.5542
375.62012	1.0871931	0.26454636	3274.9709
376.521	1.0901997	0.26551384	3280.4773
377.42188	1.0906107	0.26628309	3279.2903
378.32275	1.0953538	0.26706603	3280.0688
379.22363	1.0989919	0.26803744	3282.6814
380.12451	1.1006525	0.26904768	3287.8059
381.02539	1.1023153	0.26992226	3288.4104
381.92627	1.1062205	0.27095792	3286.7717
382.82715	1.1091906	0.27195281	3292.1365
383.72803	1.1133437	0.27288958	3295.5356
384.62891	1.1172931	0.27393237	3295.0964
385.52979	1.1196829	0.27493447	3291.6228
386.43066	1.122291	0.27577564	3295.7454
387.33154	1.1237941	0.27664769	3299.6243
388.23242	1.1253418	0.27766585	3296.3005
389.1333	1.1268162	0.27854306	3293.1448
390.03418	1.1319087	0.27925301	3295.1794
390.93506	1.1320817	0.28010485	3294.7354
391.83594	1.1332959	0.28111514	3297.9348
392.73682	1.1426347	0.2817935	3304.78
393.6377	1.1401861	0.28270671	3305.2451
394.53857	1.1444374	0.28358218	3305.4148
395.43945	1.1451827	0.28450081	3305.2844
396.34033	1.1478386	0.28567797	3316.0066
397.24121	1.1534386	0.28678864	3314.9541
398.14209	1.1559476	0.28786525	3311.2922
399.04297	1.1575626	0.28882867	3309.1921
399.94385	1.1620854	0.28971493	3311.4121
400.84473	1.1638436	0.29042885	3312.7861
401.74561	1.1664381	0.29126254	3312.155
402.64648	1.1650418	0.29217967	3316.3892
403.54736	1.1702126	0.29312921	3318.8691
404.44824	1.1728938	0.29418722	3324.6504
405.34912	1.177496	0.2951372	3315.9246
406.25	1.1762232	0.29597855	3320.2537
407.15088	1.1811523	0.29701209	3325.8906
408.05176	1.1825235	0.29791415	3321.9426
408.95264	1.1861861	0.29877296	3324.8572
409.85352	1.1889693	0.29968399	3322.2029
410.75439	1.1934762	0.30053613	3327.2407
411.65527	1.1930016	0.30152661	3323.5232
412.55615	1.1950845	0.30273449	3330.47
413.45703	1.1991442	0.3036826	3330.2632
414.35791	1.2066427	0.30457377	3333.6985
415.25879	1.207076	0.30549991	3337.8291
416.15967	1.2067482	0.30648759	3335.7124
417.06055	1.2111803	0.30735269	3331.8179
417.96143	1.2127868	0.30833602	3338.3784
418.8623	1.2176412	0.3091681	3338.7449
419.76318	1.2168642	0.31003878	3336.6934
420.66406	1.2218708	0.31070104	3331.9116
421.56494	1.2214831	0.31145674	3332.9385
422.46582	1.2297904	0.31254742	3350.093
423.3667	1.2313509	0.31355953	3344.6697
424.26758	1.2334659	0.3144426	3339.6235
425.16846	1.2369001	0.31536534	3344.3806
426.06934	1.2383097	0.31619939	3340.7007
426.97021	1.2427548	0.3169134	3344.6309
427.87109	1.2452632	0.31789142	3350.5459
428.77197	1.245841	0.31886262	3349.3157
429.67285	1.2482008	0.3197729	3348.762
430.57373	1.2509758	0.32079694	3348.7468
431.47461	1.2546533	0.32188892	3352.2383
432.37549	1.2581956	0.32278815	3356.8335
433.27637	1.2613317	0.32358119	3355.522
434.17725	1.2629133	0.32457802	3358.0698
435.07813	1.2651827	0.32567266	3358.5708
435.979	1.2687595	0.32671404	3363.7771
436.87988	1.272308	0.32770547	3360.6711
437.78076	1.2731693	0.32851553	3356.5168
438.68164	1.2742295	0.32948616	3358.0618
439.58252	1.279905	0.33023235	3360.3403
440.4834	1.2788159	0.33135971	3367.5679
441.38428	1.2843525	0.33235162	3366.2144
442.28516	1.290768	0.33330241	3371.4487
443.18604	1.291294	0.33422133	3364.6907
444.08691	1.2924608	0.33490977	3364.7188
444.98779	1.2946945	0.33582512	3369.4797
445.88867	1.2997435	0.33679727	3371.8953
446.78955	1.3006078	0.3376126	3367.543
447.69043	1.3028641	0.33840194	3368.5913
448.59131	1.3091644	0.33929983	3373.3577
449.49219	1.3085591	0.34019294	3372.3171
450.39307	1.3101511	0.34126425	3377.2632
451.29395	1.3119414	0.34243751	3377.0076
452.19482	1.3188281	0.34355688	3383.9744
453.0957	1.3186692	0.3444528	3379.0415
453.99658	1.3227912	0.34556496	3382.5549
454.89746	1.3250911	0.3464343	3382.145
455.79834	1.3255655	0.3474597	3379.3672
456.69922	1.3287121	0.34836999	3378.6177
457.6001	1.3330551	0.34945273	3379.8669
458.50098	1.336376	0.35029048	3378.1746
459.40186	1.3397083	0.35106048	3384.5747
460.30273	1.3431529	0.35197735	3393.1404
461.20361	1.3433	0.3529093	3388.2375
462.10449	1.3474429	0.35397035	3392.0388
463.00537	1.3499603	0.3548874	3393.45
463.90625	1.349486	0.3559612	3390.958
464.80713	1.3540827	0.35678503	3390.8816
465.70801	1.3559716	0.35780019	3392.2358
466.60889	1.3606037	0.35873479	3396.7341
467.50977	1.3610928	0.35957056	3390.9429
468.41064	1.367113	0.36034161	3394.4316
469.31152	1.3669485	0.36134094	3394.9241
470.2124	1.3706744	0.36241651	3397.2463
471.11328	1.373022	0.36329812	3396.2534
472.01416	1.3743649	0.36440155	3403.2708
472.91504	1.3772488	0.36523682	3401.6587
473.81592	1.3819067	0.366182	3397.9988
474.7168	1.3811444	0.36689377	3399.479
475.61768	1.3893256	0.36783087	3409.9956
476.51855	1.3893416	0.36877111	3405.8296
477.41943	1.3921887	0.36974192	3404.022
478.32031	1.3949877	0.37076536	3409.1929
479.22119	1.3995992	0.3718403	3413.1736
480.12207	1.3986351	0.3729108	3408.7942
481.02295	1.4051608	0.37369522	3409.688
481.92383	1.4077387	0.3745206	3413.6658
482.82471	1.4088123	0.3755261	3414.656
483.72559	1.4118171	0.37660271	3409.7896
484.62646	1.4130771	0.37743783	3415.5598
485.52734	1.4177321	0.37841278	3420.0417
486.42822	1.4219383	0.37935662	3414.5212
487.3291	1.4230832	0.38027453	3421.6599
488.22998	1.425378	0.38124296	3415.5393
489.13086	1.4237741	0.38229039	3420.3928
490.03174	1.4307296	0.38326502	3420.2583
490.93262	1.4314927	0.38420704	3418.4561
491.8335	1.4365476	0.3851648	3426.7842
492.73438	1.4392908	0.38603583	3426.0251
493.63525	1.4414297	0.38682586	3418.0022
494.53613	1.4463518	0.38778254	3430.0056
495.43701	1.4468282	0.38851947	3422.4883
496.33789	1.4478456	0.38956797	3428.7153
497.23877	1.4514304	0.39052781	3426.2988
498.13965	1.4523444	0.39163202	3428.8093
499.04053	1.4553496	0.39268869	3428.2651
499.94141	1.4585245	0.39367533	3431.5476
500.84229	1.4619653	0.39475316	3432.2153
501.74316	1.4675912	0.39571306	3435.0916
502.64404	1.4676527	0.39656994	3430.5293
503.54492	1.4712118	0.39762348	3438.5706
504.4458	1.4725097	0.39859265	3440.0281
505.34668	1.4730619	0.3997806	3440.5515
506.24756	1.4787291	0.40055388	3434.7639
507.14844	1.4824618	0.40131	3432.3831
508.04932	1.4825445	0.40222123	3442.6985
508.9502	1.4884849	0.40319571	3449.9231
509.85107	1.4897741	0.40426812	3440.2483
510.75195	1.4904144	0.40531182	3443.3247
511.65283	1.49438	0.40634003	3446.2354
512.55371	1.4994055	0.4075706	3449.6023
513.45459	1.5011339	0.40832874	3444.1958
514.35547	1.5024461	0.40937009	3445.6838
515.25635	1.5059536	0.41034421	3442.9038
516.15723	1.5078528	0.41133747	3445.8333
517.05811	1.511549	0.41208899	3449.209
517.95898	1.5145049	0.41306236	3449.5867
518.85986	1.5184243	0.4140045	3448.1792
519.76074	1.5187384	0.41501862	3453.6519
520.66162	1.5226347	0.41599622	3451.3142
521.5625	1.5254296	0.41697177	3453.707
522.46338	1.525807	0.41794148	3451.0676
523.36426	1.5294073	0.41883469	3452.0278
524.26514	1.5333941	0.41985232	3460.781
525.16602	1.5355726	0.42089295	3456.6338
526.06689	1.5372198	0.42209011	3460.8511
526.96777	1.5427499	0.42325896	3459.5322
527.86865	1.5458592	0.42422748	3456.813
528.76953	1.5448831	0.42509279	3455.8203
529.67041	1.5477101	0.42589378	3453.6323
530.57129	1.5499852	0.42677918	3456.386
531.47217	1.5552466	0.42780387	3467.0244
532.37305	1.5581143	0.42880008	3467.446
533.27393	1.5604545	0.4296855	3461.3506
534.1748	1.5614529	0.43058363	3458.6638
535.07568	1.5665026	0.43154854	3469.9272
535.97656	1.5706389	0.43261093	3468.6692
536.87744	1.571865	0.43365338	3473.8792
537.77832	1.5687994	0.43465731	3466.4685
538.6792	1.5772665	0.43590772	3476.2065
539.58008	1.578685	0.43683407	3464.3955
540.48096	1.5809149	0.43771052	3467.6094
541.38184	1.5853032	0.43890971	3480.6772
542.28271	1.5852761	0.43994218	3474.8606
543.18359	1.5926011	0.44083261	3473.7373
544.08447	1.5908196	0.4417184	3469.4119
544.98535	1.5978153	0.44271207	3474.9104
545.88623	1.5998069	0.44358432	3475.8247
546.78711	1.5996186	0.44464689	3481.0596
547.68799	1.6015193	0.44575375	3478.1941
548.58887	1.6044379	0.4466458	3474.7852
549.48975	1.6086885	0.44779888	3485.0405
550.39063	1.6101747	0.4490172	3484.2446
551.2915	1.6129478	0.45016345	3485.5999
552.19238	1.6191051	0.45123672	3489.0129
553.09326	1.6196468	0.45230624	3485.8293
553.99414	1.621129	0.45340428	3484.9092
554.89502	1.6246887	0.45426378	3483.3101
555.7959	1.6304705	0.45515999	3483.8188
556.69678	1.6307932	0.45602918	3486.5403
557.59766	1.633871	0.45686406	3485.4163
558.49854	1.6341593	0.4577418	3480.416
559.39941	1.6373878	0.45862228	3487.5349
560.30029	1.6421108	0.45961612	3491.0825
561.20117	1.6434486	0.46071023	3488.3765
562.10205	1.6458385	0.46178082	3492.8347
563.00293	1.6509792	0.46268722	3493.3459
563.90381	1.6523708	0.46380007	3499.6997
564.80469	1.6578529	0.4647502	3490.6963
565.70557	1.6578526	0.4657183	3490.5007
566.60645	1.6599607	0.46681535	3495.9001
567.50732	1.6617182	0.46767071	3493.9485
568.4082	1.6664587	0.46881446	3498.4783
569.30908	1.6676226	0.4698236	3493.0818
570.20996	1.6722257	0.47086576	3496.541
571.11084	1.6727608	0.47157872	3497.4109
572.01172	1.6765468	0.47272202	3498.4644
572.9126	1.6802402	0.47368613	3498.9207
573.81348	1.6834283	0.47471794	3501.9451
574.71436	1.6865008	0.47583288	3504.7397
575.61523	1.6896607	0.47675744	3500.4722
576.51611	1.6872629	0.47767055	3499.2629
577.41699	1.6939006	0.47864181	3500.8018
578.31787	1.6955324	0.47958401	3505.9668
579.21875	1.6976856	0.48064998	3507.7607
580.11963	1.7021221	0.48187792	3513.9165
581.02051	1.7059814	0.48289928	3507.446
581.92139	1.7056134	0.48408115	3515.9377
582.82227	1.7076106	0.48526168	3508.5076
583.72314	1.7091924	0.48637232	3511.6023
584.62402	1.7131504	0.48746288	3515.1526
585.5249	1.7154107	0.48844239	3511.2295
586.42578	1.7189215	0.48955816	3515.406
587.32666	1.7210585	0.49050498	3508.2593
588.22754	1.7253256	0.4915415	3510.0442
589.12842	1.7281536	0.49244291	3511.0535
590.0293	1.7339767	0.49346825	3518.4468
590.93018	1.7314984	0.49459743	3515.8711
591.83105	1.7370615	0.4956871	3521.5024
592.73193	1.7417338	0.49702957	3521.3931
593.63281	1.7406708	0.49795613	3508.3005
594.53369	1.7419755	0.49882847	3511.9324
595.43457	1.7444539	0.49995053	3518.3171
596.33545	1.7501904	0.50101221	3523.5283
597.23633	1.7534177	0.50199252	3519.6206
598.13721	1.7551303	0.50320053	3521.9678
599.03809	1.7574799	0.50409937	3521.4692
599.93896	1.7598767	0.50517607	3518.7336
600.83984	1.763648	0.5060429	3521.0786
601.74072	1.7672188	0.50712818	3523.8538
602.6416	1.7675643	0.50799608	3523.6152
603.54248	1.7696507	0.50910056	3528.3831
604.44336	1.7736682	0.51025122	3527.6577
605.34424	1.7756562	0.51140749	3527.145
606.24512	1.7796187	0.51245165	3525.9924
607.146	1.7821485	0.51348329	3526.7078
608.04688	1.7847922	0.51444346	3526.4976
608.94775	1.7880448	0.5155462	3530.1851
609.84863	1.7870886	0.51679695	3534.5935
610.74951	1.7916318	0.51792723	3532.5588
611.65039	1.7948916	0.51892972	3530.4233
612.55127	1.7953544	0.5200305	3537.6194
613.45215	1.7983851	0.5210765	3530.7964
614.35303	1.8042374	0.52208418	3535.5291
615.25391	1.8075014	0.52310681	3533.5701
616.15479	1.8075004	0.52416408	3532.4648
617.05566	1.812356	0.52541274	3538.4995
617.95654	1.8137856	0.52669263	3531.9956
618.85742	1.8158787	0.52768224	3534.9514
619.7583	1.8211495	0.52865136	3532.8184
620.65918	1.8237092	0.52967632	3535.8542
621.56006	1.8258387	0.53071719	3540.5168
622.46094	1.8250335	0.53179318	3542.5728
623.36182	1.8275251	0.53315854	3540.2405
624.2627	1.8322198	0.53434455	3541.082
625.16357	1.8362322	0.53538513	3539.6248
626.06445	1.8362657	0.53637087	3529.6777
626.96533	1.8431182	0.53745764	3544.2056
627.86621	1.8414117	0.53868401	3532.6521
628.76709	1.8476604	0.5395627	3540.978
629.66797	1.8485402	0.54059058	3541.7788
630.56885	1.8515525	0.5416342	3542.1284
631.46973	1.8550739	0.54282677	3546.5317
632.37061	1.8567013	0.5439952	3545.7014
633.27148	1.8594102	0.54510438	3546.7419
634.17236	1.8610742	0.54627824	3540.8977
635.07324	1.8671629	0.54734135	3547.104
635.97412	1.86596	0.5482561	3542.6248
636.875	1.8720037	0.54929489	3547.0269
637.77588	1.8707218	0.55038953	3545.5593
638.67676	1.8757484	0.55124485	3543.865
639.57764	1.8820266	0.55239922	3554.5327
640.47852	1.8831711	0.55376214	3555.198
641.37939	1.8857789	0.55474365	3550.738
642.28027	1.8875252	0.55592573	3552.1235
643.18115	1.8890481	0.55710834	3555.5195
644.08203	1.8927099	0.55822891	3554.8936
644.98291	1.8957205	0.55936688	3556.1753
645.88379	1.8972635	0.56060916	3548.6709
646.78467	1.9004186	0.5616793	3555.5369
647.68555	1.9039896	0.56291443	3557.0508
648.58643	1.9041908	0.5639261	3551.5686
649.4873	1.9103178	0.56506079	3555.1824
650.38818	1.9111921	0.56612629	3554.2629
651.28906	1.9153259	0.56723261	3553.5483
652.18994	1.9204147	0.5683251	3562.7043
653.09082	1.9193165	0.5694586	3556.031
653.9917	1.924024	0.57078731	3564.0391
654.89258	1.9237859	0.57185012	3556.8918
655.79346	1.928424	0.57308656	3562.9832
656.69434	1.9311465	0.57404768	3558.8264
657.59521	1.9336017	0.57529199	3564.1711
658.49609	1.9374362	0.5766778	3564.3467
659.39697	1.9361758	0.57791108	3558.9194
660.29785	1.9421233	0.579189	3564.9958
661.19873	1.9450167	0.58026832	3562.1064
662.09961	1.947345	0.5814178	3565.0208
663.00049	1.9476936	0.58266103	3569.2153
663.90137	1.9526296	0.58386242	3564.4265
664.80225	1.954456	0.58511859	3563.3645
665.70313	1.9576007	0.58623475	3566.6912
666.604	1.9602002	0.58710021	3563.3459
667.50488	1.9636899	0.58808833	3563.687
668.40576	1.9662428	0.58917034	3568.7957
669.30664	1.9678735	0.59018213	3568.1182
670.20752	1.9707634	0.59120381	3568.9985
671.1084	1.9766237	0.59224129	3568.9363
672.00928	1.9733149	0.59338224	3569.7622
672.91016	1.9820913	0.59479725	3575.4629
673.81104	1.9833176	0.59624159	3574.2537
674.71191	1.9850994	0.59757978	3573.8342
675.61279	1.9866436	0.59865451	3565.9905
676.51367	1.9875396	0.59992254	3576.8301
677.41455	1.9946942	0.6011489	3569.5706
678.31543	1.9960608	0.60236669	3576.3818
679.21631	2.0003161	0.60328662	3565.8213
680.11719	1.9983566	0.60435253	3569.7275
681.01807	2.0036943	0.60575378	3578.644
681.91895	2.0070603	0.60712862	3578.2114
682.81982	2.0077116	0.60838783	3575.4944
683.7207	2.0108378	0.6096223	3573.0459
684.62158	2.0150933	0.61077857	3573.1399
685.52246	2.0142889	0.6119976	3574.6304
686.42334	2.0174589	0.61313289	3575.968
687.32422	2.0225208	0.61440569	3574.3286
688.2251	2.0232267	0.61564153	3582.1492
689.12598	2.0271528	0.61679459	3576.8689
690.02686	2.0299945	0.61797142	3577.7681
690.92773	2.0331609	0.61938059	3580.3379
691.82861	2.0357046	0.62050641	3579.6838
692.72949	2.0398135	0.62182063	3580.9734
693.63037	2.0411744	0.62302417	3575.0093
694.53125	2.0437818	0.62430555	3580.1016
695.43213	2.0473261	0.62590933	3581.1245
696.33301	2.0486884	0.62728071	3581.9734
697.23389	2.0512016	0.62856072	3574.0974
698.13477	2.0544603	0.62984663	3585.4773
699.03564	2.0587537	0.63118482	3586.3462
699.93652	2.0605788	0.63223928	3579.7119
700.8374	2.063519	0.63363087	3581.8589
701.73828	2.0657113	0.63463795	3581.2917
702.63916	2.0684586	0.63579798	3582.2168
703.54004	2.0734379	0.6367991	3585.9373
704.44092	2.0742598	0.63798803	3586.5034
705.3418	2.0762982	0.6392653	3587.3638
706.24268	2.0818191	0.64049155	3584.2134
707.14355	2.0808616	0.64153594	3580.3237
708.04443	2.0827186	0.6426906	3580.7383
708.94531	2.0871189	0.64391863	3585.1721
709.84619	2.092099	0.64514047	3589.8589
710.74707	2.0921748	0.64625001	3585.8596
711.64795	2.0956502	0.64771986	3585.0464
712.54883	2.099066	0.64899278	3587.1838
713.44971	2.1007037	0.6504702	3589.0178
714.35059	2.1063943	0.65181613	3586.5559
715.25146	2.1089466	0.65312266	3591.4041
716.15234	2.1106827	0.65425277	3587.5193
717.05322	2.110779	0.65553069	3590.353
717.9541	2.1130342	0.65702534	3590.9683
718.85498	2.1152148	0.65840465	3596.2385
719.75586	2.1208105	0.65969867	3586.2542
720.65674	2.1207559	0.66109937	3583.6667
721.55762	2.1230409	0.66239154	3593.6882
722.4585	2.1270702	0.66363609	3587.9919
723.35938	2.1321859	0.665079	3592.9575
724.26025	2.1313291	0.66627592	3592.4858
725.16113	2.1356022	0.66750056	3587.4614
726.06201	2.1395111	0.66889483	3592.7549
726.96289	2.1403322	0.6701259	3591.0781
727.86377	2.1433218	0.67158687	3592.7329
728.76465	2.1490488	0.67283964	3593.0608
729.66553	2.1505785	0.67423844	3592.3618
730.56641	2.1514492	0.67564636	3593.0378
731.46729	2.1514838	0.67698175	3599.7952
732.36816	2.1607077	0.67839468	3596.0703
733.26904	2.162704	0.67947578	3593.3425
734.16992	2.1654029	0.68095112	3597.6323
735.0708	2.1643953	0.68230367	3596.9319
735.97168	2.1694016	0.68371487	3593.2556
736.87256	2.1683228	0.68497229	3590.1443
737.77344	2.1740842	0.68646652	3595.7449
738.67432	2.1765802	0.68779457	3596.9309
739.5752	2.1799405	0.68935126	3597.3213
740.47607	2.1818244	0.69079614	3597.4126
741.37695	2.1833482	0.69230103	3599.0305
742.27783	2.1884205	0.69367933	3594.8918
743.17871	2.1892095	0.69500685	3596.2341
744.07959	2.1921933	0.6964491	3598.2734
744.98047	2.1974192	0.69763273	3600.3857
745.88135	2.1991682	0.69912177	3598.4946
746.78223	2.2026346	0.70069492	3602.7671
747.68311	2.2041905	0.7019707	3592.2671
748.58398	2.2081673	0.7032094	3595.6809
749.48486	2.2078216	0.70462859	3595.3599
750.38574	2.2117767	0.70605946	3599.6299
751.28662	2.2142756	0.70729035	3595.9253
752.1875	2.2184303	0.70860499	3598.3123
753.08838	2.2195458	0.70994937	3603.6208
753.98926	2.2227645	0.7115556	3603.5801
754.89014	2.2257421	0.71296704	3601.2832
755.79102	2.2278981	0.71464878	3604.4521
756.69189	2.2284672	0.71628511	3598.2366
757.59277	2.2330244	0.71788603	3598.6262
758.49365	2.2353327	0.71909505	3597.606
759.39453	2.2369792	0.72044051	3596.0967
760.29541	2.2392962	0.72179753	3597.4124
761.19629	2.2460051	0.72314972	3600.311
762.09717	2.2481453	0.72464049	3603.9331
762.99805	2.2492685	0.72625005	3607.2922
763.89893	2.2508609	0.72780967	3600.3162
764.7998	2.2540889	0.72932732	3599.9551
765.70068	2.2544971	0.73069173	3600.304
766.60156	2.257978	0.73245621	3604.1812
767.50244	2.261744	0.73417324	3599.0825
768.40332	2.2639253	0.73539406	3596.9202
769.3042	2.2681937	0.73693764	3595.8115
770.20508	2.2737598	0.73829734	3606.5
771.10596	2.2758851	0.739932	3603.1113
772.00684	2.2787836	0.74126339	3599.0342
772.90771	2.2804966	0.74283516	3604.9187
773.80859	2.2838106	0.74457699	3602.8674
774.70947	2.2861314	0.74603271	3602.8462
775.61035	2.2861462	0.74759412	3599.0054
776.51123	2.2923696	0.74920064	3604.4629
777.41211	2.2916884	0.7506566	3604.9487
778.31299	2.2933099	0.75252479	3605.8809
779.21387	2.2982008	0.75403965	3594.7429
780.11475	2.2986002	0.75554377	3601.9578
781.01563	2.3040164	0.75678295	3599.73
781.9165	2.3064754	0.75827718	3601.9163
782.81738	2.3091173	0.75979221	3602.8975
783.71826	2.3103611	0.76142389	3606.8481
784.61914	2.3160007	0.76303607	3600.5771
785.52002	2.3177466	0.76442599	3601.6484
786.4209	2.3207908	0.76607251	3605.5178
787.32178	2.3241086	0.76755846	3606.9553
788.22266	2.327013	0.76939112	3606.6077
789.12354	2.3299119	0.77138823	3609.9578
790.02441	2.329525	0.77347761	3608.7844
790.92529	2.3341854	0.77504808	3601.0027
791.82617	2.3353636	0.77665114	3605.2786
792.72705	2.3380396	0.7782532	3597.6863
793.62793	2.3411908	0.77969813	3601.302
794.52881	2.3445244	0.78124738	3602.4893
795.42969	2.3477247	0.78292245	3608.0859
796.33057	2.3486896	0.78513664	3610.0479
797.23145	2.3547833	0.78684759	3601.0215
798.13232	2.3548069	0.78831911	3602.6963
799.0332	2.3590257	0.78995132	3601.3101
799.93408	2.3604465	0.79164416	3602.5269
800.83496	2.364192	0.79296112	3599.3821
801.73584	2.3665013	0.79449886	3602.8435
802.63672	2.36625	0.79625273	3602.4475
803.5376	2.3714783	0.79823041	3607.2817
804.43848	2.3742163	0.79988891	3603.2668
805.33936	2.3751469	0.80148476	3601.0894
806.24023	2.3794677	0.80324638	3602.6836
807.14111	2.3793893	0.80496079	3601.1853
808.04199	2.3831174	0.80654806	3601.8901
808.94287	2.3850248	0.80835712	3607.2522
809.84375	2.3880298	0.81026149	3602.6067
810.74463	2.3916593	0.812078	3602.5706
811.64551	2.3945405	0.8137818	3598.5044
812.54639	2.3987327	0.81561702	3604.9668
813.44727	2.4003417	0.81761593	3602.1743
814.34814	2.4020176	0.81954014	3600.032
815.24902	2.409375	0.82108033	3597.6326
816.1499	2.4096432	0.82257575	3602.1807
817.05078	2.4130254	0.82436085	3601.834
817.95166	2.4139616	0.82624537	3603.3831
818.85254	2.4161277	0.82791454	3601.2112
819.75342	2.4223309	0.82987905	3603.9268
820.6543	2.4232423	0.83165562	3602.8904
821.55518	2.4267933	0.83338434	3598.4331
822.45605	2.4280407	0.83527362	3607.6377
823.35693	2.4299462	0.83726722	3611.1558
824.25781	2.4349675	0.83956403	3605.9607
825.15869	2.4355462	0.8414976	3601.6536
826.05957	2.4383652	0.84326541	3599.7593
826.96045	2.4421029	0.84505916	3609.3416
827.86133	2.4468529	0.84731507	3602.9463
828.76221	2.4462569	0.8494252	3601.7734
829.66309	2.449775	0.8511222	3596.8921
830.56396	2.4538589	0.85301363	3604.2878
831.46484	2.4561939	0.85521388	3604.6033
832.36572	2.4561989	0.8573693	3602.4802
833.2666	2.4590144	0.85959542	3600.3152
834.16748	2.464155	0.8617515	3600.6208
835.06836	2.46421	0.86371887	3595.071
835.96924	2.4679284	0.86562836	3594.9299
836.87012	2.4729171	0.86783177	3600.7019
837.771	2.4735813	0.86981463	3599.1362
838.67188	2.47733	0.8715412	3595.5032
839.57275	2.4800875	0.87328714	3594.866
840.47363	2.4816418	0.87523592	3594.8459
841.37451	2.4850047	0.87723577	3594.4905
842.27539	2.4865735	0.87942797	3598.1294
843.17627	2.48859	0.88149142	3595.3728
844.07715	2.4935155	0.88329786	3589.7766
844.97803	2.4946277	0.88532388	3596.7764
845.87891	2.4961691	0.88733774	3592.8501
846.77979	2.5006776	0.8897081	3592.6453
847.68066	2.5042341	0.89221275	3593.3074
848.58154	2.5054722	0.8944329	3590.7979
849.48242	2.5094175	0.89670128	3592.8628
850.3833	2.5139227	0.89879525	3595.7676
851.28418	2.5130281	0.90070009	3586.137
852.18506	2.5176718	0.90264887	3589.4187
853.08594	2.5173759	0.90420389	3583.5854
853.98682	2.520895	0.90583652	3586.241
854.8877	2.5230103	0.90786433	3592.7932
855.78857	2.526644	0.90992641	3596.3625
856.68945	2.5302689	0.9129101	3597.3792
857.59033	2.5331652	0.91570342	3587.3809
858.49121	2.53634	0.91792613	3585.3088
859.39209	2.5348597	0.92028499	3582.5881
860.29297	2.5409915	0.92223746	3581.8701
861.19385	2.542551	0.92429686	3588.5156
862.09473	2.5495169	0.92647982	3590.4297
862.99561	2.5500393	0.92852885	3586.8213
863.89648	2.5515478	0.93115193	3587.4844
864.79736	2.5547726	0.93403107	3591.6699
865.69824	2.5580206	0.93644983	3582.6418
866.59912	2.5597737	0.93833756	3582.811
867.5	2.5617151	0.9405157	3584.2546
868.40088	2.5637755	0.94273245	3581.7864
869.30176	2.570704	0.94542015	3589.7659
870.20264	2.5700257	0.94800901	3585.4585
871.10352	2.5755434	0.95054507	3581.8271
872.00439	2.5780308	0.95279837	3581.532
872.90527	2.5784216	0.95474052	3575.2058
873.80615	2.5829201	0.95669746	3575.4541
874.70703	2.5855155	0.95894033	3583.0432
875.60791	2.5879128	0.96147233	3578.7302
876.50879	2.5884826	0.96395022	3578.6438
877.40967	2.5935686	0.96616602	3576.2446
878.31055	2.5964241	0.96879452	3579.7612
879.21143	2.5973096	0.97151375	3574.8398
880.1123	2.6014969	0.97385794	3566.9678
881.01318	2.6018441	0.97627735	3573.2925
881.91406	2.606735	0.97889256	3572.1033
882.81494	2.6089919	0.98180562	3574.1685
883.71582	2.6126387	0.98442447	3574.1785
884.6167	2.6172698	0.98710597	3572.7815
885.51758	2.6181939	0.98990858	3568.7627
886.41846	2.6198182	0.99219769	3564.5906
887.31934	2.6225803	0.99449641	3562.0557
888.22021	2.6249557	0.99700689	3560.9001
889.12109	2.6288214	0.99966639	3561.2388
890.02197	2.6313777	1.0021203	3560.6248
890.92285	2.6294878	1.0044535	3562.4187
891.82373	2.636358	1.0068936	3565.3196
892.72461	2.6374011	1.0092062	3557.5127
893.62549	2.6429977	1.0118837	3558.6936
894.52637	2.6425047	1.0139631	3559.332
895.42725	2.6475098	1.0165609	3558.6091
896.32813	2.6495764	1.0194756	3557.0042
897.229	2.6513417	1.0222617	3553.2271
898.12988	2.6558094	1.0249903	3558.8181
899.03076	2.6605027	1.0279442	3562.4026
899.93164	2.6597462	1.0307939	3551.2593
900.83252	2.6654162	1.0330796	3544.7341
901.7334	2.6649377	1.0355027	3546.6553
902.63428	2.6698389	1.0379859	3542.9983
903.53516	2.6722536	1.0402378	3543.0791
904.43604	2.6732764	1.0429208	3546.9722
905.33691	2.6776979	1.0463235	3548.6936
906.23779	2.6785882	1.0489746	3545.6978
907.13867	2.6843479	1.0516936	3540.8784
908.03955	2.682862	1.0544733	3539.9878
908.94043	2.6874571	1.0573012	3535.9382
909.84131	2.6896923	1.059994	3543.7598
910.74219	2.6936309	1.0630558	3537.3281
911.64307	2.6952715	1.0660292	3532.0354
912.54395	2.7000701	1.0686044	3529.4021
913.44482	2.7007964	1.0711817	3529.7988
914.3457	2.7035296	1.073851	3527.9714
915.24658	2.7059968	1.0766034	3525.5164
916.14746	2.7098019	1.0791336	3527.397
917.04834	2.7114553	1.0815641	3523.2688
917.94922	2.7144308	1.084476	3524.4158
918.8501	2.7152762	1.08724	3518.8306
919.75098	2.720217	1.090149	3514.7634
920.65186	2.7219312	1.0927249	3518.7529
921.55273	2.7256641	1.0952362	3515.1514
922.45361	2.7294655	1.0977763	3515.333
923.35449	2.7296672	1.1003169	3512.814
924.25537	2.7332342	1.1033708	3513.01
925.15625	2.7368243	1.1066796	3505.5032
926.05713	2.73946	1.1095035	3508.1472
926.95801	2.7392931	1.1124139	3507.697
927.85889	2.746464	1.1151962	3506.2473
928.75977	2.7491131	1.1181034	3505.1367
929.66064	2.749624	1.1212165	3499.6113
930.56152	2.7525563	1.1238295	3496.7725
931.4624	2.7565227	1.1264304	3499.8992
932.36328	2.7601855	1.1287796	3496.0298
933.26416	2.7626143	1.1317439	3492.3997
934.16504	2.7621768	1.1343269	3488.9221
935.06592	2.7657993	1.1371982	3487.1277
935.9668	2.7695742	1.1401749	3489.3804
936.86768	2.7714369	1.1429843	3483.7642
937.76855	2.7750614	1.1457839	3483.5601
938.66943	2.7754383	1.1484351	3482.0605
939.57031	2.7817543	1.1510741	3477.4092
940.47119	2.782505	1.1538665	3473.7852
941.37207	2.7853048	1.1564604	3473.8594
942.27295	2.7875352	1.1595547	3478.5938
943.17383	2.7905257	1.1633848	3474.5701
944.07471	2.7942357	1.1665401	3471.1836
944.97559	2.7981691	1.169448	3464.5728
945.87646	2.8000443	1.1718458	3464.3264
946.77734	2.8029957	1.1749192	3464.3999
947.67822	2.80301	1.1772006	3456.4409
948.5791	2.8071284	1.1800817	3461.0776
949.47998	2.8084352	1.1831751	3458.7031
950.38086	2.8117762	1.1868458	3459.3704
951.28174	2.8140886	1.1904421	3445.6411
952.18262	2.8176589	1.193481	3445.3418
953.0835	2.818728	1.1963263	3441.8315
953.98438	2.8237576	1.1988164	3442.9795
954.88525	2.8266191	1.2013369	3437.9358
955.78613	2.8286386	1.2039087	3436.3245
956.68701	2.8299766	1.2066671	3436.6697
957.58789	2.8341024	1.2091436	3424.9553
958.48877	2.8365724	1.2122053	3433.3928
959.38965	2.8389246	1.2154622	3425.2852
960.29053	2.8417532	1.2183821	3426.0408
961.19141	2.8446214	1.2209567	3423.4731
962.09229	2.8473432	1.2238826	3420.5586
962.99316	2.8517177	1.2268314	3416.1895
963.89404	2.8508763	1.2292666	3417.3433
964.79492	2.8532853	1.2316184	3409.6077
965.6958	2.8582385	1.2342507	3409.6414
966.59668	2.8621421	1.2374592	3410.1106
967.49756	2.8649814	1.2409805	3411.9978
968.39844	2.8655977	1.2439778	3398.5964
969.29932	2.867521	1.2467093	3396.9663
970.2002	2.8702502	1.2490525	3392.0249
971.10107	2.8759465	1.2522171	3399.5195
972.00195	2.8770313	1.2555095	3386.272
972.90283	2.8786085	1.2585957	3391.4624
973.80371	2.883563	1.2614857	3381.5103
974.70459	2.8834569	1.2646035	3389.1926
975.60547	2.887846	1.2677144	3378.741
976.50635	2.891197	1.2705404	3377.1682
977.40723	2.8921547	1.2735243	3374.4204
978.30811	2.8976181	1.2764541	3372.8591
979.20898	2.8986571	1.2797427	3373.1995
980.10986	2.9043012	1.282789	3361.9583
981.01074	2.904851	1.2859058	3361.624
981.91162	2.9071438	1.2887381	3357.6445
982.8125	2.9100955	1.2917247	3356.8896
983.71338	2.9110057	1.2945861	3347.0723
984.61426	2.9140553	1.2975061	3349.908
985.51514	2.9172497	1.3002958	3345.8896
986.41602	2.9192076	1.3031833	3339.9207
987.31689	2.9242139	1.3062575	3337.9678
988.21777	2.9263391	1.309189	3338.1245
989.11865	2.9254322	1.312066	3330.0396
990.01953	2.9308631	1.3152057	3329.168
990.92041	2.9361992	1.3186786	3329.9768
991.82129	2.9346368	1.3220925	3321.5911
992.72217	2.939343	1.3252228	3315.4963
993.62305	2.9435949	1.3280802	3312.7913
994.52393	2.945919	1.3312169	3315.7026
995.4248	2.9484508	1.3337988	3307.3582
996.32568	2.948143	1.3364869	3298.8667
997.22656	2.9523468	1.3391653	3298.4924
998.12744	2.9534087	1.3416452	3295.3416
999.02832	2.9567988	1.3439894	3288.7554
999.9292	2.9608047	1.346788	3294.2136
1000.8301	2.9623313	1.3497564	3293.5444
1001.731	2.9665463	1.3529406	3289.4265
1002.6318	2.9677896	1.3555304	3278.7168
1003.5327	2.9717178	1.3583838	3281.0706
1004.4336	2.9714239	1.3614193	3272.8059
1005.3345	2.9819598	1.3647342	3269.5596
1006.2354	2.9804132	1.3672453	3260.605
1007.1362	2.9809513	1.3697224	3260.5366
1008.0371	2.9867141	1.37194	3257.9739
1008.938	2.9842505	1.3743151	3253.3469
1009.8389	2.9913208	1.3771436	3258.0884
1010.7397	2.9954515	1.3798039	3250.4995
1011.6406	2.9951005	1.3826778	3249.1243
1012.5415	2.9976044	1.385831	3244.3926
1013.4424	3.0023751	1.3892349	3237.7561
1014.3433	3.0041482	1.3928159	3239.7024
1015.2441	3.0075686	1.3957127	3215.208
1016.145	3.0072291	1.3984375	3226.1614
1017.0459	3.0155027	1.4014231	3227.5732
1017.9468	3.0144684	1.4044768	3219.9534
1018.8477	3.016793	1.4076953	3219.9099
1019.7485	3.0199139	1.4109446	3213.426
1020.6494	3.0236721	1.4138211	3205.333
1021.5503	3.0288386	1.4169194	3202.1704
1022.4512	3.0271156	1.4195887	3191.9497
1023.3521	3.0305946	1.4225917	3196.3765
1024.2529	3.0329254	1.4259185	3188.6516
1025.1538	3.0331621	1.4291782	3179.1379
1026.0547	3.0391624	1.4318519	3180.9221
1026.9556	3.0409207	1.4345851	3174.6138
1027.8564	3.0438817	1.4376109	3172.8538
1028.7573	3.0462403	1.4410344	3166.9673
1029.6582	3.0505559	1.4443257	3160.946
1030.5591	3.0522001	1.4476801	3156.2732
1031.46	3.0564046	1.4506661	3150.0869
1032.3608	3.0582337	1.4533454	3146.8596
1033.2617	3.0602689	1.4561609	3140.7986
1034.1626	3.0648928	1.4594905	3148.502
1035.0635	3.0673137	1.4633609	3134.5684
1035.9644	3.0688033	1.4664629	3128.5146
1036.8652	3.0721669	1.468959	3118.5759
1037.7661	3.0732067	1.4714719	3119.9697
1038.667	3.078258	1.4743159	3120.9182
1039.5679	3.0807052	1.4775567	3112.0793
1040.4688	3.0806451	1.4810125	3105.6428
1041.3696	3.0857255	1.4844029	3103.3853
1042.2705	3.0880523	1.4874181	3088.2275
1043.1714	3.0907207	1.4910237	3090.0054
1044.0723	3.0956197	1.4943945	3085.4961
1044.9731	3.0954132	1.4973674	3078.8721
1045.874	3.0973189	1.5003942	3075.4397
1046.7749	3.1026473	1.5041552	3072.5845
1047.6758	3.1056454	1.5072391	3058.7483
1048.5767	3.1068373	1.5108802	3056.6858
1049.4775	3.1094916	1.5144606	3046.5002
1050.3784	3.1146181	1.5182164	3041.8491
1051.2793	3.1142871	1.520822	3033.9329
1052.1802	3.1169758	1.5233469	3030.8938
1053.0811	3.1232276	1.5261096	3030.0239
1053.9819	3.1257448	1.5294323	3024.7354
1054.8828	3.1257129	1.5327834	3018.0959
1055.7837	3.1281466	1.5359703	3012.3865
1056.6846	3.1319094	1.5391221	3000.9153
1057.5854	3.1360631	1.5422288	3001.9346
1058.4863	3.1370869	1.5458548	2993.637
1059.3872	3.1382587	1.5497074	2984.7786
1060.2881	3.1417072	1.5528698	2978.6418
1061.189	3.1441658	1.5559181	2968.9768
1062.0898	3.1464608	1.5592399	2964.8892
1062.9907	3.1507537	1.5629154	2965.8916
1063.8916	3.1575255	1.5661081	2957.9045
1064.7925	3.1558814	1.5690004	2945.4404
1065.6934	3.1599119	1.5722923	2941.0615
1066.5942	3.1611254	1.5753782	2926.0352
1067.4951	3.1641865	1.5782173	2926.303
1068.396	3.1649504	1.5814537	2919.0732
1069.2969	3.1700029	1.5853918	2916.1812
1070.1978	3.1717479	1.5887414	2900.4668
1071.0986	3.1764848	1.592191	2897.9753
1071.9995	3.1779122	1.5952386	2888.6929
1072.9004	3.1792521	1.5985886	2876.9641
1073.8013	3.1842785	1.6015381	2876.7581
1074.7021	3.1858344	1.6042097	2862.6365
1075.603	3.1865013	1.6078583	2861.0278
1076.5039	3.192431	1.6114712	2855.4172
1077.4048	3.1929543	1.6153226	2837.7097
1078.3057	3.1982896	1.6196629	2833.292
1079.2065	3.1981249	1.623511	2816.4004
1080.1074	3.2029405	1.6273676	2799.9111
1081.0083	3.2052209	1.6303855	2793.989
1081.9092	3.2058511	1.6334133	2785.0708
1082.8101	3.2112629	1.6375041	2778.688
1083.7109	3.2145374	1.6419353	2761.5186
1084.6118	3.2169256	1.6456952	2743.0469
1085.5127	3.220417	1.6491103	2736.0054
1086.4136	3.2182355	1.6530713	2720.0178
1087.3145	3.225112	1.6576657	2703.4849
1088.2153	3.2248058	1.6627476	2675.5281
1089.1162	3.2300522	1.668242	2650.9419
1090.0171	3.2308171	1.6731946	2622.0596
1090.918	3.2373097	1.6806333	2573.3613
1091.2183	3.2377295	1.6853627	2536.2803