File: datasets/am_bench_2022/raw_data/30-XY.01-4/specimen.dat
MTS793|MPT|ENU|1|2|.|/|:|1|0|0|A

Operator Information						Time:	27.096191	Sec	10/18/2021 11:35:57 AM
Operator	Nick Derimow
Project	AM Bench 2022 mini-tensile challenge
Specimen ID	30-XY.01-4
Material	PBF-L Inconel 625
Specimen Width	2.54	mm
Specimen Thickness	1.5	mm
Notes
Operator Information End

Data Acquisition						Time:	1028.0901	Sec	10/18/2021 11:52:38 AM
Time	Axial Displacement	Axial Extensometer	Axial Force
Sec	mm	mm	N
27.209961	0.0013162763	2.5260957e-05	80.674759
28.210938	0.0028154633	7.6922166e-05	93.629715
29.211914	0.0061244015	0.00018246048	109.60582
30.212891	0.010546512	0.00033275413	124.082
31.213867	0.010289169	0.00031745699	135.04678
32.214844	0.014805734	0.0003488053	143.7646
33.21582	0.016112529	0.00042010224	160.33046
34.216797	0.02094565	0.00050468429	176.75859
35.217773	0.024180418	0.00058646756	195.43983
36.21875	0.0252856	0.00068094995	211.4819
37.219727	0.030821497	0.00073355366	229.50424
38.220703	0.032013554	0.00086623081	254.40376
39.22168	0.033918578	0.0010197618	271.36285
40.222656	0.038930774	0.0010781679	289.93872
41.223633	0.039316326	0.0011169282	312.16858
42.224609	0.04492788	0.001274263	329.45062
43.225586	0.048097085	0.0013463672	353.3042
44.226563	0.048998401	0.0014654078	368.88647
45.227539	0.052169446	0.0015424212	389.66321
46.228516	0.056773704	0.0016977675	413.21585
47.229492	0.058572236	0.0017364058	436.78314
48.230469	0.061336983	0.0019206407	464.55099
49.231445	0.061817452	0.0020057238	481.59781
50.232422	0.06921453	0.0021211205	506.16736
51.233398	0.070668437	0.0022355304	525.18225
52.234375	0.073039383	0.0023489776	547.22656
53.235352	0.076057427	0.0024027808	576.11212
54.236328	0.081366047	0.0026102227	609.18591
55.237305	0.081876844	0.0026507778	621.45148
56.238281	0.085976504	0.0028233852	656.36029
57.239258	0.085746415	0.0028809381	680.67316
58.240234	0.091168344	0.0030032764	704.54681
59.241211	0.092109203	0.0031739937	727.23535
60.242188	0.095768504	0.0033202642	756.2724
61.243164	0.10155068	0.0034928417	785.04224
62.244141	0.1023936	0.0036095344	805.8421
63.245117	0.10902459	0.0036693902	834.9281
64.246094	0.10782885	0.0038130577	854.64404
65.24707	0.1121877	0.0039513498	881.35718
66.248047	0.11658455	0.0040819412	911.64252
67.249023	0.11811898	0.0041505508	937.81744
68.25	0.11882298	0.0042744959	965.86218
69.250977	0.12341536	0.0044642352	988.93616
70.251953	0.12478362	0.0046059969	1015.3366
71.25293	0.12957023	0.0046701482	1048.3063
72.253906	0.13478665	0.0049059582	1084.5892
73.254883	0.13655077	0.0049996008	1103.5414
74.255859	0.13859516	0.0050910302	1134.8781
75.256836	0.14024675	0.0052530887	1163.6055
76.257813	0.14490919	0.0053797257	1199.705
77.258789	0.14782454	0.0054969355	1223.2644
78.259766	0.14964049	0.0056231995	1261.5244
79.260742	0.15660898	0.0058787735	1293.1676
80.261719	0.15704985	0.0059532095	1313.3434
81.262695	0.15985215	0.0060858382	1345.7089
82.263672	0.16488053	0.0062373122	1362.8337
83.264648	0.16649057	0.0062678289	1390.6874
84.265625	0.17056328	0.0064723152	1421.2675
85.266602	0.17388165	0.0066212984	1445.5057
86.267578	0.17687899	0.0067440793	1474.2887
87.268555	0.17924671	0.0069285203	1499.6847
88.269531	0.18001546	0.0070277355	1521.9342
89.270508	0.18439983	0.0070453067	1536.8838
90.271484	0.18813166	0.0072492654	1566.3193
91.272461	0.19132365	0.0073288567	1596.2837
92.273438	0.19107102	0.0073804851	1608.6074
93.274414	0.19551198	0.0076586418	1647.7308
94.275391	0.19837877	0.007715371	1675.0293
95.276367	0.20258759	0.0077360477	1688.1991
96.277344	0.2064254	0.0079748668	1721.3057
97.27832	0.20900083	0.0081454078	1750.7278
98.279297	0.21125868	0.0081970114	1770.7808
99.280273	0.2100845	0.0083359322	1791.7136
100.28125	0.21892728	0.0084025217	1817.1157
101.28223	0.22083928	0.008566523	1846.7479
102.2832	0.22188073	0.0086178845	1866.7234
103.28418	0.2257902	0.0088563794	1891.8431
104.28516	0.22786038	0.008855748	1916.2864
105.28613	0.23101692	0.009034534	1939.0605
106.28711	0.23597278	0.0092065707	1960.136
107.28809	0.23612235	0.0092272069	1973.629
108.28906	0.24068727	0.0093859918	1998.7555
109.29004	0.24568164	0.0094453432	2018.72
110.29102	0.2459773	0.0096131964	2033.3342
111.29199	0.25174776	0.009654494	2052.2
112.29297	0.25556338	0.0097958921	2073.2092
113.29395	0.25868818	0.0099102398	2086.8298
114.29492	0.26007035	0.009992687	2107.5381
115.2959	0.26144165	0.01011013	2124.3323
116.29688	0.26483685	0.010249662	2141.1191
117.29785	0.26673412	0.010338733	2160.6318
118.29883	0.27326131	0.010409976	2171.7
119.2998	0.27344775	0.01053263	2186.7441
120.30078	0.28037336	0.010672516	2209.3892
121.30176	0.28243554	0.010763527	2220.1521
122.30273	0.28343868	0.010908511	2235.0269
123.30371	0.28719312	0.010978898	2244.3445
124.30469	0.29328051	0.011117637	2264.8933
125.30566	0.29359975	0.011243999	2278.7104
126.30664	0.2950657	0.011238185	2290.8999
127.30762	0.29855028	0.011424121	2299.4856
128.30859	0.29908586	0.011612864	2323.8367
129.30957	0.30562833	0.01174199	2329.1187
130.31055	0.30948392	0.011806619	2337.6589
131.31152	0.31134576	0.011944486	2354.8398
132.3125	0.31213418	0.012022499	2361.011
133.31348	0.31759879	0.012151348	2372.175
134.31445	0.3227185	0.012262014	2386.1436
135.31543	0.32119232	0.012366584	2394.7305
136.31641	0.32531261	0.012494333	2402.7915
137.31738	0.32842773	0.012708846	2422.5356
138.31836	0.33343458	0.012918082	2434.0608
139.31934	0.33461231	0.01302188	2443.0298
140.32031	0.33844945	0.013299783	2456.3101
141.32129	0.34061271	0.013250318	2460.3188
142.32227	0.34391713	0.013510261	2471.113
143.32324	0.34713897	0.01359835	2475.4092
144.32422	0.35164735	0.0137401	2493.1335
145.3252	0.35360366	0.014124204	2500.1284
146.32617	0.35631555	0.01426563	2512.7212
147.32715	0.35675052	0.014325943	2514.9932
148.32813	0.36527306	0.014660009	2534.4722
149.3291	0.36547652	0.014799931	2540.1199
150.33008	0.36617786	0.014993887	2544.103
151.33105	0.37172744	0.01525221	2554.7708
152.33203	0.37549329	0.015433763	2565.5259
153.33301	0.37892172	0.015621022	2568.1223
154.33398	0.37842792	0.01599814	2581.8184
155.33496	0.38256976	0.016349507	2591.2056
156.33594	0.38699228	0.016534183	2596.5137
157.33691	0.38599774	0.016807415	2602.999
158.33789	0.39235935	0.017115308	2608.2883
159.33887	0.39381242	0.01731603	2614.7556
160.33984	0.39756107	0.017540857	2621.5867
161.34082	0.40207779	0.017932143	2634.9309
162.3418	0.40463215	0.018178288	2638.9941
163.34277	0.40795529	0.018590301	2649.5315
164.34375	0.40939602	0.019008413	2653.6284
165.34473	0.41165268	0.019377029	2661.2109
166.3457	0.41540334	0.019766506	2667.2437
167.34668	0.42074054	0.02016923	2669.2925
168.34766	0.42426911	0.020577857	2682.5847
169.34863	0.42730454	0.021068389	2693.7832
170.34961	0.42860824	0.021579798	2698.0364
171.35059	0.43223906	0.021992104	2696.7432
172.35156	0.43744078	0.02260554	2706.0449
173.35254	0.44052169	0.023172664	2710.1902
174.35352	0.44178483	0.023697391	2719.8254
175.35449	0.44642618	0.024249095	2725.3728
176.35547	0.44407731	0.024929781	2726.9368
177.35645	0.45007604	0.025544852	2735.209
178.35742	0.45223704	0.026268909	2746.1648
179.3584	0.4560141	0.027024198	2741.2517
180.35938	0.45936221	0.027656423	2746.082
181.36035	0.46198237	0.028382188	2751.594
182.36133	0.46447176	0.029079456	2759.9983
183.3623	0.46723855	0.029771635	2764.0112
184.36328	0.47156805	0.030598545	2768.7739
185.36426	0.47213539	0.031458348	2770.0466
186.36523	0.47610345	0.032275669	2771.9705
187.36621	0.48269981	0.032996088	2777.0293
188.36719	0.48518085	0.033880305	2791.8987
189.36816	0.48680276	0.034938622	2787.6145
190.36914	0.48884839	0.035986759	2797.2241
191.37012	0.49124843	0.036768667	2791.4758
192.37109	0.49523351	0.037485253	2795.667
193.37207	0.49985826	0.038456682	2801.334
194.37305	0.50141358	0.039316952	2803.0706
195.37402	0.50630057	0.040094018	2806.6062
196.375	0.50491655	0.040956203	2805.8257
197.37598	0.51404107	0.042057812	2821.9529
198.37695	0.51552242	0.0430324	2817.4377
199.37793	0.51657426	0.044207841	2825.7136
200.37891	0.51864696	0.045154072	2823.406
201.37988	0.52385086	0.046099234	2827.3582
202.38086	0.52636695	0.047201838	2834.2375
203.38184	0.52700782	0.048176687	2827.2371
204.38281	0.53239745	0.049309473	2840.2793
205.38379	0.53594732	0.050476857	2838.3828
206.38477	0.53931838	0.051605284	2846.043
207.38574	0.53695577	0.052721504	2839.4355
208.38672	0.54206473	0.053703614	2840.6353
209.3877	0.54594123	0.054926615	2853.7954
210.38867	0.55078286	0.056050144	2849.3137
211.38965	0.55231708	0.057338655	2862.4475
212.39063	0.55695617	0.058480345	2855.5576
213.3916	0.55935913	0.059597153	2861.1497
214.39258	0.56279308	0.060478292	2858.814
215.39355	0.56522405	0.061661232	2865.6536
216.39453	0.56679106	0.062877767	2867.115
217.39551	0.57160574	0.063993953	2873.4385
218.39648	0.57320386	0.065111443	2874.8193
219.39746	0.57647717	0.066056423	2877.4683
220.39844	0.57842398	0.067304678	2880.4287
221.39941	0.58145577	0.068560041	2878.637
222.40039	0.58636284	0.069821388	2884.542
223.40137	0.5902217	0.071036696	2883.8472
224.40234	0.58932555	0.0722166	2880.3137
225.40332	0.59684861	0.073316731	2892.1614
226.4043	0.59580493	0.074442215	2890.7717
227.40527	0.60295552	0.075778566	2899.1643
228.40625	0.60360891	0.076960951	2890.866
229.40723	0.60612947	0.078281395	2896.5195
230.4082	0.61135149	0.079385422	2899.3318
231.40918	0.61278015	0.080519475	2903.1174
232.41016	0.61582112	0.08176899	2900.8235
233.41113	0.61913598	0.082935162	2904.8623
234.41211	0.62094927	0.084027655	2907.8472
235.41309	0.62426132	0.085374825	2915.1545
236.41406	0.62921387	0.086617544	2908.8748
237.41504	0.632155	0.087770574	2911.8599
238.41602	0.63260311	0.088757738	2912.0024
239.41699	0.63488704	0.089960001	2913.8875
240.41797	0.6401754	0.091094606	2920.2727
241.41895	0.64160675	0.092185251	2913.8748
242.41992	0.6456576	0.093472555	2926.8982
243.4209	0.64738852	0.094822377	2926.6558
244.42188	0.64991832	0.096045732	2924.7041
245.42285	0.65560967	0.097207434	2930.2664
246.42383	0.65385193	0.098329343	2925.0859
247.4248	0.65880573	0.099571057	2930.0598
248.42578	0.66066426	0.10069526	2930.3621
249.42676	0.66640669	0.10182102	2933.1919
250.42773	0.66992664	0.10341389	2941.1714
251.42871	0.67357922	0.10487367	2943.8718
252.42969	0.67766738	0.10608041	2941.4966
253.43066	0.68357819	0.10723633	2944.4426
254.43164	0.68078184	0.10851539	2940.3608
255.43262	0.68371284	0.10966623	2945.9688
256.43359	0.68955112	0.11114007	2948.9868
257.43457	0.69138956	0.1123711	2952.5195
258.43555	0.694058	0.11360701	2945.0466
259.43652	0.69846392	0.11478068	2956.4622
260.4375	0.69769377	0.1158611	2954.4077
261.43848	0.70320636	0.11709693	2961.3372
262.43945	0.70474583	0.1184273	2957.708
263.44043	0.70722401	0.1195589	2953.1975
264.44141	0.71287334	0.12052231	2956.5579
265.44238	0.71495116	0.12161964	2962.6372
266.44336	0.71882373	0.12291935	2965.9822
267.44434	0.71923602	0.12383804	2964.2966
268.44531	0.7231254	0.12526314	2972.509
269.44629	0.72754031	0.12656762	2966.7769
270.44727	0.73164016	0.12785295	2974.9387
271.44824	0.73540968	0.12889858	2971.7588
272.44922	0.73625708	0.1301374	2970.9937
273.4502	0.73870569	0.13139312	2980.1348
274.45117	0.74032801	0.13275281	2972.9424
275.45215	0.74279571	0.13390382	2981.4973
276.45313	0.74595529	0.13519691	2981.1147
277.4541	0.74893993	0.13671272	2981.6836
278.45508	0.7556898	0.13839212	2986.8667
279.45605	0.7565403	0.13973418	2984.7549
280.45703	0.76000535	0.14106034	2985.0681
281.45801	0.76253408	0.14221276	2982.9006
282.45898	0.76629066	0.14317276	2983.2683
283.45996	0.76528567	0.14416037	2990.0525
284.46094	0.77393633	0.1455072	2996.4409
285.46191	0.77507633	0.14685129	2993.0034
286.46289	0.77874726	0.14796931	2990.5869
287.46387	0.78024483	0.14911857	3001.9727
288.46484	0.78583705	0.15027028	2995.7407
289.46582	0.78681707	0.15135776	3000.1177
290.4668	0.79107714	0.15261538	3002.0557
291.46777	0.79119945	0.15383856	3001.2664
292.46875	0.79589158	0.1552548	3002.4021
293.46973	0.79899997	0.15656671	3004.9124
294.4707	0.80236441	0.15784186	3015.0657
295.47168	0.80477494	0.15900204	3009.6785
296.47266	0.80609339	0.16035308	3009.4402
297.47363	0.81228161	0.16157162	3018.3228
298.47461	0.8160764	0.16281305	3012.0259
299.47559	0.81736654	0.1639763	3016.1978
300.47656	0.82281148	0.1652966	3015.0405
301.47754	0.82569939	0.16641094	3018.2542
302.47852	0.82735735	0.16753264	3014.0313
303.47949	0.82841718	0.16855271	3018.8201
304.48047	0.83529967	0.169649	3022.1963
305.48145	0.83499414	0.17083876	3024.6494
306.48242	0.8391313	0.17199874	3021.3406
307.4834	0.84036267	0.17309597	3020.6887
308.48438	0.84438521	0.17420129	3028.5662
309.48535	0.84647095	0.17560542	3024.906
310.48633	0.85158855	0.17701441	3030.4893
311.4873	0.85436392	0.17833588	3036.3682
312.48828	0.85632795	0.1796014	3032.8669
313.48926	0.85760689	0.18099138	3039.8357
314.49023	0.86327946	0.18229233	3033.0886
315.49121	0.86604583	0.18348122	3035.165
316.49219	0.86880547	0.18425691	3037.3972
317.49316	0.87066936	0.18550511	3041.5513
318.49414	0.87133896	0.18677171	3036.261
319.49512	0.87506872	0.18801843	3041.1035
320.49609	0.88014221	0.18946798	3044.522
321.49707	0.88238531	0.19075191	3043.1018
322.49805	0.88810802	0.19182375	3049.8225
323.49902	0.89025652	0.19294043	3045.1831
324.5	0.89193952	0.19407658	3049.5378
325.50098	0.89683586	0.19557846	3055.1531
326.50195	0.89694655	0.19692402	3050.4502
327.50293	0.904342	0.19813323	3049.394
328.50391	0.90453768	0.19916156	3056.428
329.50488	0.90794253	0.20069657	3063.3325
330.50586	0.9115268	0.20203148	3060.8401
331.50684	0.91463804	0.20314211	3062.9189
332.50781	0.91563588	0.20432951	3055.7751
333.50879	0.91965127	0.20546953	3055.2761
334.50977	0.92078042	0.20643727	3061.7283
335.51074	0.92132545	0.20757623	3063.0071
336.51172	0.92830783	0.20871001	3069.2822
337.5127	0.92927712	0.21020943	3070.8726
338.51367	0.93245208	0.21133754	3060.4324
339.51465	0.9353441	0.21233799	3061.6135
340.51563	0.93959999	0.21349892	3069.4517
341.5166	0.9415524	0.21471114	3068.3591
342.51758	0.94643676	0.21579154	3071.6604
343.51855	0.94626099	0.21709718	3076.3813
344.51953	0.95111889	0.21857345	3079.2449
345.52051	0.95337409	0.21975501	3072.1023
346.52148	0.96019894	0.22107357	3083.6538
347.52246	0.96199745	0.22239795	3082.6321
348.52344	0.96221381	0.22341727	3072.425
349.52441	0.96755892	0.22467715	3083.5015
350.52539	0.97100562	0.22580557	3080.6213
351.52637	0.97567791	0.22716279	3083.7927
352.52734	0.97811747	0.22821945	3090.9009
353.52832	0.9813301	0.22937763	3084.5676
354.5293	0.98366731	0.23059358	3087.3806
355.53027	0.9880355	0.23205656	3099.8281
356.53125	0.98807013	0.23350431	3095.3699
357.53223	0.99287415	0.23488137	3097.5581
358.5332	0.99379367	0.23595655	3092.1907
359.53418	0.99764031	0.23723094	3096.4417
360.53516	1.0019279	0.23841509	3096.9907
361.53613	1.0032955	0.23959278	3093.4197
362.53711	1.0053462	0.24076173	3097.5896
363.53809	1.0108269	0.24166684	3099.1855
364.53906	1.0123657	0.24290933	3099.7544
365.54004	1.0144839	0.24444464	3111.4707
366.54102	1.0192181	0.2456997	3098.0298
367.54199	1.0225275	0.24702407	3107.6748
368.54297	1.0253664	0.24821191	3109.8276
369.54395	1.0267807	0.24933697	3100.6106
370.54492	1.0293958	0.25044763	3106.3494
371.5459	1.0323831	0.25141954	3101.3984
372.54688	1.034869	0.2524527	3106.0942
373.54785	1.0395067	0.25356033	3111.875
374.54883	1.0379708	0.25486889	3111.7085
375.5498	1.0457164	0.25617245	3119.5706
376.55078	1.0473194	0.25769731	3116.8645
377.55176	1.0518833	0.25887099	3117.7566
378.55273	1.0549695	0.26011664	3123.3169
379.55371	1.0570626	0.261417	3117.9299
380.55469	1.0611981	0.26252246	3113.509
381.55566	1.063272	0.26363829	3122.9707
382.55664	1.0654881	0.26489797	3118.2454
383.55762	1.0698172	0.26630381	3125.3208
384.55859	1.0731288	0.26755819	3125.7625
385.55957	1.0745006	0.26875934	3124.6709
386.56055	1.0785125	0.26983052	3128.2939
387.56152	1.0828699	0.2708877	3128.6465
388.5625	1.084553	0.27202451	3127.4094
389.56348	1.085835	0.27325693	3129.335
390.56445	1.0913076	0.27442405	3130.1938
391.56543	1.0936559	0.27559742	3133.0754
392.56641	1.0946329	0.27681211	3137.0752
393.56738	1.1008015	0.27820867	3136.9839
394.56836	1.1048288	0.27971211	3141.0566
395.56934	1.1063005	0.2812449	3142.2446
396.57031	1.1091058	0.28249061	3139.0957
397.57129	1.1105146	0.28351787	3137.1936
398.57227	1.1152627	0.28465804	3144.3215
399.57324	1.1185596	0.28592116	3142.5281
400.57422	1.118274	0.28704995	3145.5791
401.5752	1.1229895	0.28824937	3143.6013
402.57617	1.1268942	0.289473	3144.9631
403.57715	1.1319464	0.2904233	3146.2307
404.57813	1.132965	0.29155514	3149.2573
405.5791	1.1370572	0.29288179	3151.4736
406.58008	1.1356772	0.29402164	3145.6653
407.58105	1.1413202	0.29521182	3148.7964
408.58203	1.1453021	0.29628575	3147.8206
409.58301	1.1467533	0.29742774	3149.5691
410.58398	1.1524388	0.2988188	3162.0854
411.58496	1.1513618	0.30003685	3147.5427
412.58594	1.1559055	0.30106604	3152.2273
413.58691	1.1594213	0.30234262	3158.0796
414.58789	1.1622024	0.30358678	3160.4788
415.58887	1.1643157	0.30488294	3162.3433
416.58984	1.1690204	0.30615953	3161.5337
417.59082	1.1715142	0.30734545	3161.75
418.5918	1.1763881	0.30866629	3168.8708
419.59277	1.1763524	0.30985606	3165.7898
420.59375	1.1808361	0.31091022	3159.1077
421.59473	1.1811029	0.31215078	3164.6736
422.5957	1.1841338	0.31335449	3166.7153
423.59668	1.1888272	0.31466323	3165.6587
424.59766	1.1935431	0.31561342	3172.4138
425.59863	1.1947583	0.31664225	3169.3623
426.59961	1.1985067	0.31801409	3175.248
427.60059	1.199717	0.31927684	3176.6406
428.60156	1.2026365	0.32064369	3176.574
429.60254	1.2079109	0.32197338	3168.3423
430.60352	1.207532	0.32314786	3172.6472
431.60449	1.21373	0.32421562	3173.3782
432.60547	1.2173895	0.32546625	3180.5107
433.60645	1.2222217	0.32663783	3183.7302
434.60742	1.2232755	0.32790822	3180.9636
435.6084	1.2257576	0.32921046	3182.3486
436.60938	1.2285938	0.33054936	3189.7097
437.61035	1.2302811	0.33174071	3181.0764
438.61133	1.2342213	0.33290246	3181.5679
439.6123	1.2387282	0.33422345	3191.2473
440.61328	1.2422596	0.33562452	3189.29
441.61426	1.2447445	0.33674613	3193.2251
442.61523	1.2479162	0.33803681	3190.782
443.61621	1.2491118	0.33911708	3185.6914
444.61719	1.2498063	0.34018907	3181.6038
445.61816	1.2544998	0.34099203	3188.1001
446.61914	1.257134	0.34200552	3187.748
447.62012	1.2627513	0.34311172	3190.9238
448.62109	1.2669811	0.34421775	3194.5515
449.62207	1.2675298	0.34522653	3193.8018
450.62305	1.2704051	0.34646457	3198.7136
451.62402	1.2715747	0.34778947	3196.8645
452.625	1.2748537	0.34936115	3205.5325
453.62598	1.2778956	0.35059947	3198.0964
454.62695	1.2819159	0.3518092	3198.3794
455.62793	1.2856389	0.35308611	3209.5046
456.62891	1.2913421	0.35434976	3207.6375
457.62988	1.2907332	0.35561964	3199.9932
458.63086	1.2934103	0.3568784	3200.0281
459.63184	1.2994289	0.35808656	3205.3271
460.63281	1.2992668	0.35901916	3203.4844
461.63379	1.3054949	0.36014891	3205.7368
462.63477	1.3053515	0.36143279	3206.8293
463.63574	1.306993	0.36275899	3211.6321
464.63672	1.3119889	0.36408803	3210.0183
465.6377	1.3135779	0.36525232	3213.2659
466.63867	1.3196076	0.36653778	3214.0166
467.63965	1.3191139	0.36756876	3206.3853
468.64063	1.3253609	0.36893636	3221.2642
469.6416	1.329368	0.37013105	3220.8306
470.64258	1.3296262	0.37134722	3218.043
471.64355	1.3326046	0.37248361	3213.2734
472.64453	1.3383881	0.3738099	3226.0728
473.64551	1.3404968	0.37510714	3216.4771
474.64648	1.3439746	0.37623641	3223.9124
475.64746	1.3466711	0.37761089	3222.7354
476.64844	1.3477315	0.37883782	3221.1335
477.64941	1.350086	0.37993753	3220.842
478.65039	1.3553329	0.38116178	3227.373
479.65137	1.3592148	0.38245595	3228.7253
480.65234	1.3590773	0.38369146	3223.5696
481.65332	1.3640333	0.38490894	3234.1343
482.6543	1.3680156	0.38602811	3227.2354
483.65527	1.368283	0.38733333	3230.28
484.65625	1.3723699	0.38847744	3230.3035
485.65723	1.3749415	0.38963246	3234.1821
486.6582	1.3794391	0.391058	3243.772
487.65918	1.3842319	0.39234343	3235.3735
488.66016	1.3849603	0.393498	3228.6858
489.66113	1.3890288	0.39459935	3235.5757
490.66211	1.3902985	0.39592394	3241.9995
491.66309	1.3938596	0.39692429	3231.6912
492.66406	1.395804	0.39810181	3235.8821
493.66504	1.398486	0.39921901	3237.8892
494.66602	1.402233	0.4004584	3243.7419
495.66699	1.4056982	0.40169051	3248.0964
496.66797	1.4078461	0.4030211	3240.6956
497.66895	1.4116822	0.40436009	3246.3601
498.66992	1.4147031	0.40553135	3243.6155
499.6709	1.4154121	0.40673649	3244.2927
500.67188	1.4191399	0.40811899	3248.3789
501.67285	1.4237715	0.4092764	3251.6509
502.67383	1.4291824	0.41047281	3251.1167
503.6748	1.4288231	0.41160151	3253.1392
504.67578	1.43177	0.41288304	3249.7393
505.67676	1.4314709	0.41424337	3250.7859
506.67773	1.4383868	0.41543862	3251.8542
507.67871	1.4420552	0.41683024	3254.7947
508.67969	1.4441522	0.41817439	3251.6912
509.68066	1.4466164	0.41934714	3246.376
510.68164	1.4515365	0.42046037	3252.8931
511.68262	1.454425	0.42163721	3256.9543
512.68359	1.4579021	0.42292833	3260.6387
513.68457	1.463313	0.42415822	3262.7893
514.68555	1.4615991	0.42538759	3257.4597
515.68652	1.4635243	0.4264906	3257.5046
516.6875	1.4667553	0.42749867	3256.5129
517.68848	1.4740766	0.42853874	3260.7732
518.68945	1.4739522	0.42948103	3258.4639
519.69043	1.4759548	0.43041044	3256.2898
520.69141	1.4826297	0.43152708	3261.9812
521.69238	1.4844526	0.43281469	3276.4556
522.69336	1.4870653	0.43407062	3265.7808
523.69434	1.4898376	0.43541589	3270.2642
524.69531	1.4928032	0.43672445	3269.8225
525.69629	1.4972669	0.43785605	3265.2805
526.69727	1.497792	0.43917724	3272.0176
527.69824	1.5008243	0.44053334	3277.918
528.69922	1.5046771	0.44180137	3272.249
529.7002	1.5072286	0.44310966	3277.2007
530.70117	1.5113598	0.44433388	3271.4795
531.70215	1.5135144	0.44556305	3275.106
532.70313	1.5164394	0.44674054	3272.2976
533.7041	1.5211586	0.44791782	3277.7219
534.70508	1.5222386	0.44927174	3278.6616
535.70605	1.5261304	0.45038179	3278.7019
536.70703	1.5254719	0.45184821	3280.407
537.70801	1.5321953	0.45301801	3283.0378
538.70898	1.5319185	0.45420459	3279.5049
539.70996	1.5369557	0.45543414	3291.8711
540.71094	1.5386802	0.45691988	3284.9668
541.71191	1.5427135	0.4583697	3283.4167
542.71289	1.5489353	0.45953932	3283.4639
543.71387	1.5475261	0.46066076	3281.2312
544.71484	1.5518866	0.4620122	3286.373
545.71582	1.5541127	0.46315825	3286.1282
546.7168	1.5575618	0.46420151	3283.0894
547.71777	1.5601999	0.46521515	3288.6687
548.71875	1.5655514	0.46661794	3296.5251
549.71973	1.5661632	0.46787229	3292.9639
550.7207	1.5722882	0.4691467	3294.0901
551.72168	1.5722868	0.47029805	3291.5703
552.72266	1.5787379	0.47146189	3293.0276
553.72363	1.5776547	0.47270131	3294.665
554.72461	1.5828587	0.47400892	3297.6943
555.72559	1.5870649	0.4750953	3298.312
556.72656	1.5892003	0.476293	3293.1951
557.72754	1.5902706	0.47751051	3298.6577
558.72852	1.5936861	0.47853732	3293.9607
559.72949	1.5975914	0.47970355	3297.0156
560.73047	1.6021807	0.48094288	3300.6438
561.73145	1.604965	0.48227909	3302.7917
562.73242	1.6066785	0.48363215	3301.981
563.7334	1.6092541	0.48488426	3299.4026
564.73438	1.6132146	0.48619011	3302.7546
565.73535	1.6156416	0.48760641	3302.2126
566.73633	1.6178242	0.48876002	3301.01
567.7373	1.6199744	0.49012876	3305.3982
568.73828	1.6254367	0.49168575	3310.2849
569.73926	1.6287247	0.49294668	3305.3594
570.74023	1.6293552	0.49410316	3301.9067
571.74121	1.6317759	0.4954327	3302.5483
572.74219	1.6366949	0.49667975	3307.3159
573.74316	1.6396223	0.49804267	3311.3826
574.74414	1.6402224	0.49944091	3308.7715
575.74512	1.6474288	0.50056016	3310.2603
576.74609	1.6514224	0.50193906	3321.4773
577.74707	1.6508704	0.50330299	3315.9438
578.74805	1.6542692	0.5044027	3313.7959
579.74902	1.6590385	0.50550705	3307.7622
580.75	1.6599746	0.50657761	3308.8616
581.75098	1.6604304	0.50768626	3316.9363
582.75195	1.6679857	0.508843	3322.1277
583.75293	1.6700495	0.51006138	3317.8862
584.75391	1.6735685	0.51158428	3325.0298
585.75488	1.678063	0.51284808	3324.4333
586.75586	1.6823817	0.51402873	3320.2671
587.75684	1.6809633	0.51512909	3317.7119
588.75781	1.6852373	0.51637602	3321.7605
589.75879	1.6848109	0.51739585	3316.1526
590.75977	1.6909931	0.5184657	3322.9197
591.76074	1.6948529	0.51972026	3327.042
592.76172	1.6978537	0.5210005	3326.2051
593.7627	1.6998488	0.52222431	3323.4404
594.76367	1.706349	0.52351165	3330.4827
595.76465	1.7041372	0.52459592	3318.8552
596.76563	1.7085971	0.52581203	3333.1138
597.7666	1.7129815	0.52695084	3329.6094
598.76758	1.716064	0.52813119	3332.4612
599.76855	1.7178966	0.52930492	3327.0293
600.76953	1.7216163	0.53048366	3332.1147
601.77051	1.7251481	0.53173983	3333.2766
602.77148	1.7270696	0.53295988	3334.2466
603.77246	1.7347709	0.5342679	3338.3284
604.77344	1.7358952	0.53561628	3339.9075
605.77441	1.7345618	0.53682643	3334.231
606.77539	1.7393502	0.53821647	3337.3069
607.77637	1.7419082	0.53961188	3336.1599
608.77734	1.7414411	0.54105574	3335.9556
609.77832	1.7460688	0.54242957	3339.4258
610.7793	1.7525868	0.5437758	3337.6848
611.78027	1.7577803	0.54493648	3338.3601
612.78125	1.7569176	0.54614222	3336.2754
613.78223	1.7582104	0.54744899	3343.2891
614.7832	1.7651434	0.54877859	3344.4199
615.78418	1.7645104	0.54987586	3335.9541
616.78516	1.7658751	0.55114591	3338.99
617.78613	1.7720162	0.55242836	3347.6252
618.78711	1.7735022	0.55361772	3337.8601
619.78809	1.7785858	0.5551241	3347.783
620.78906	1.7822738	0.55637354	3344.96
621.79004	1.7821894	0.55760974	3343.2708
622.79102	1.7867372	0.55910236	3352.7395
623.79199	1.7886574	0.56030244	3344.8801
624.79297	1.7937105	0.56172109	3352.9185
625.79395	1.7980188	0.5630613	3350.7791
626.79492	1.7981373	0.56429803	3346.2539
627.7959	1.8009832	0.56551236	3353.9014
628.79688	1.8064957	0.56687129	3353.054
629.79785	1.8075734	0.5682041	3350.5325
630.79883	1.8112361	0.56922543	3355.2083
631.7998	1.8149565	0.57067049	3359.6973
632.80078	1.8141164	0.57194048	3357.0005
633.80176	1.8213631	0.57310933	3357.4224
634.80273	1.8228054	0.57423556	3356.7979
635.80371	1.8244671	0.57547832	3357.366
636.80469	1.8268282	0.57672334	3361.6631
637.80566	1.8336169	0.57812411	3357.5161
638.80664	1.8349324	0.57950926	3359.748
639.80762	1.8375273	0.58065695	3358.3364
640.80859	1.8408028	0.58188725	3362.8738
641.80957	1.8456511	0.58317226	3366.9333
642.81055	1.8450416	0.58462679	3364.3079
643.81152	1.8480403	0.58602542	3359.6802
644.8125	1.8513595	0.58756149	3363.4136
645.81348	1.8570329	0.5890578	3370.446
646.81445	1.8584018	0.59050667	3357.5906
647.81543	1.8646265	0.59171152	3365.7932
648.81641	1.8664702	0.59290582	3367.4451
649.81738	1.8663399	0.59405333	3365.7729
650.81836	1.8716958	0.59531116	3365.1401
651.81934	1.8741118	0.59649301	3372.1453
652.82031	1.8765845	0.59783393	3369.5879
653.82129	1.8802758	0.59919173	3368.9846
654.82227	1.8816757	0.60044616	3368.5676
655.82324	1.8863757	0.60169899	3365.1941
656.82422	1.8874433	0.60289717	3365.1372
657.8252	1.8906732	0.60419738	3371.9861
658.82617	1.894793	0.60538268	3374.6404
659.82715	1.8972799	0.6066801	3376.4089
660.82813	1.9023719	0.60798466	3372.5271
661.8291	1.902764	0.60916781	3372.2686
662.83008	1.9070357	0.61053669	3372.3086
663.83105	1.9085377	0.61166793	3381.3792
664.83203	1.9113892	0.6130529	3378.1812
665.83301	1.9189162	0.6145972	3382.1511
666.83398	1.9167876	0.61588728	3370.9045
667.83496	1.9208097	0.61707103	3370.0051
668.83594	1.9238956	0.61828375	3380.4031
669.83691	1.9269706	0.61961931	3378.9863
670.83789	1.9314978	0.62083024	3379.5286
671.83887	1.933427	0.62219274	3379.418
672.83984	1.9362867	0.62364477	3384.0249
673.84082	1.9417566	0.62517035	3383.5254
674.8418	1.9421109	0.62630826	3379.0132
675.84277	1.9450979	0.62755466	3382.5071
676.84375	1.9515474	0.62889242	3384.6238
677.84473	1.9515921	0.63025194	3384.364
678.8457	1.9570698	0.63147718	3385.863
679.84668	1.9570712	0.6329267	3387.6008
680.84766	1.960152	0.63430274	3390.7444
681.84863	1.9628726	0.63603336	3393.2175
682.84961	1.9671689	0.63738167	3388.0554
683.85059	1.9708084	0.63847184	3379.6636
684.85156	1.9731777	0.63968068	3385.5491
685.85254	1.9747578	0.64088821	3386.3228
686.85352	1.9793447	0.64224237	3392.9236
687.85449	1.9839909	0.64378154	3397.863
688.85547	1.9870052	0.64519429	3399.3372
689.85645	1.9870101	0.64649141	3386.479
690.85742	1.9923592	0.647596	3388.7839
691.8584	1.9920332	0.64897925	3390.7419
692.85938	1.9975876	0.65020895	3392.1851
693.86035	2.000103	0.65149528	3396.5957
694.86133	2.0016418	0.65283626	3397.8157
695.8623	2.0082138	0.65436542	3399.2449
696.86328	2.0097654	0.65578544	3395.9675
697.86426	2.0113199	0.65704679	3393.0889
698.86523	2.0153422	0.65845329	3394.6995
699.86621	2.0200584	0.65979409	3397.1313
700.86719	2.0209615	0.66094548	3401.2417
701.86816	2.0272012	0.66233993	3401.072
702.86914	2.0251789	0.66358322	3394.6223
703.87012	2.0307634	0.66489458	3401.0825
704.87109	2.0339854	0.66611993	3399.282
705.87207	2.0331645	0.66739678	3395.0818
706.87305	2.039875	0.66872436	3405.8962
707.87402	2.0408952	0.67011029	3398.3511
708.875	2.044194	0.6715169	3398.197
709.87598	2.0495374	0.67267913	3400.5745
710.87695	2.0509424	0.67425257	3405.4888
711.87793	2.057724	0.6756404	3408.5105
712.87891	2.0574501	0.67703688	3404.8298
713.87988	2.0617239	0.67864966	3410.04
714.88086	2.0630341	0.68025047	3405.6904
715.88184	2.0667243	0.68170357	3407.2664
716.88281	2.0705729	0.68318003	3405.6633
717.88379	2.0733719	0.68437368	3405.9536
718.88477	2.0746725	0.68578637	3409.3643
719.88574	2.0781486	0.68745863	3413.6497
720.88672	2.0840724	0.68866819	3403.8198
721.8877	2.0838966	0.6898855	3403.9795
722.88867	2.0866771	0.69130898	3408.1501
723.88965	2.0879793	0.69252115	3406.9006
724.89063	2.0927205	0.69386435	3410.4207
725.8916	2.0968246	0.69527119	3415.9771
726.89258	2.0987623	0.69666404	3413.4255
727.89355	2.0979114	0.69800192	3414.2144
728.89453	2.1076984	0.69933736	3411.3115
729.89551	2.1047373	0.70053995	3408.6719
730.89648	2.1119666	0.7018491	3412.6128
731.89746	2.1160679	0.70339632	3417.5471
732.89844	2.1201856	0.70444578	3410.8083
733.89941	2.1221642	0.7056064	3415.9602
734.90039	2.1227028	0.70698643	3412.9187
735.90137	2.127244	0.70815998	3411.6567
736.90234	2.1294789	0.70948857	3417.8167
737.90332	2.1357963	0.71107036	3430.427
738.9043	2.1326389	0.71261364	3427.3
739.90527	2.1402588	0.71433347	3422.9651
740.90625	2.1409421	0.71598411	3420.8535
741.90723	2.1426256	0.71731788	3416.481
742.9082	2.1481156	0.71860069	3408.9429
743.90918	2.1507502	0.71980494	3415.9128
744.91016	2.1535068	0.7212519	3427.0212
745.91113	2.1554608	0.72250539	3416.3555
746.91211	2.1580324	0.72376364	3422.8591
747.91309	2.1611214	0.72488427	3421.6667
748.91406	2.1624551	0.72634256	3424.999
749.91504	2.1670356	0.72797793	3431.106
750.91602	2.1683688	0.72996289	3426.5688
751.91699	2.1768298	0.731435	3426.4575
752.91797	2.1802633	0.7329542	3424.1689
753.91895	2.1811836	0.73421288	3423.7346
754.91992	2.184042	0.73557562	3425.4604
755.9209	2.1872742	0.73695147	3426.3269
756.92188	2.1915309	0.73847014	3426.4441
757.92285	2.1934211	0.73972279	3423.9343
758.92383	2.1942475	0.7414552	3429.9551
759.9248	2.1970367	0.74281073	3425.2197
760.92578	2.1989202	0.74414617	3420.9607
761.92676	2.2039948	0.74572802	3431.1765
762.92773	2.2036245	0.74707824	3428.3071
763.92871	2.2109523	0.74859434	3428.3474
764.92969	2.2117078	0.75012225	3428.5667
765.93066	2.215349	0.75165856	3426.7036
766.93164	2.2186351	0.75306457	3430.8408
767.93262	2.2203679	0.75436223	3425.0647
768.93359	2.2262938	0.75582278	3430.6799
769.93457	2.2297683	0.75711548	3431.0693
770.93555	2.2309427	0.75844753	3432.3965
771.93652	2.2335851	0.75982523	3432.8022
772.9375	2.2361462	0.7611841	3433.4392
773.93848	2.2395687	0.76270598	3434.063
774.93945	2.2446256	0.76419008	3429.4263
775.94043	2.24596	0.76568544	3436.3408
776.94141	2.2490299	0.76708949	3429.8096
777.94238	2.2534919	0.76846683	3436.4043
778.94336	2.2552996	0.76964307	3432.657
779.94434	2.2587848	0.77103025	3438.0007
780.94531	2.2593179	0.77249277	3440.1914
781.94629	2.2635939	0.77417469	3438.8665
782.94727	2.2696512	0.77570933	3440.0205
783.94824	2.2731574	0.77733499	3438.8601
784.94922	2.2726536	0.77896541	3439.7356
785.9502	2.2735732	0.78050816	3436.1238
786.95117	2.2785428	0.78210282	3438.9524
787.95215	2.2851937	0.78355306	3440.8838
788.95313	2.2827663	0.78488719	3437.072
789.9541	2.2905943	0.78627056	3444.2302
790.95508	2.289748	0.78781074	3433.1899
791.95605	2.2946947	0.78925556	3440.7678
792.95703	2.2967885	0.79063773	3440.5791
793.95801	2.2968273	0.79210842	3436.7493
794.95898	2.3028224	0.7936216	3446.4753
795.95996	2.3097374	0.79509139	3439.6216
796.96094	2.3103261	0.79653209	3444.7063
797.96191	2.309011	0.7979663	3444.2185
798.96289	2.3150399	0.79961908	3443.4705
799.96387	2.3180757	0.80127329	3446.2534
800.96484	2.3226163	0.80294585	3449.2815
801.96582	2.3246796	0.80454022	3443.3057
802.9668	2.3272591	0.80601782	3445.2056
803.96777	2.328886	0.80745655	3434.8867
804.96875	2.3332968	0.80894852	3442.739
805.96973	2.3363271	0.81030279	3438.4187
806.9707	2.3407824	0.81171048	3442.167
807.97168	2.3413436	0.81311786	3446.0952
808.97266	2.3474686	0.81448764	3445.0938
809.97363	2.3476267	0.81590676	3445.9419
810.97461	2.3528922	0.81756413	3449.0884
811.97559	2.3547845	0.81906295	3446.7166
812.97656	2.3599176	0.82078266	3446.4785
813.97754	2.360353	0.82225507	3447.4841
814.97852	2.3609612	0.82370996	3445.0623
815.97949	2.3656077	0.82527721	3446.4297
816.98047	2.3709321	0.82666177	3449.5588
817.98145	2.3696406	0.8280108	3444.1575
818.98242	2.3742528	0.82940751	3445.363
819.9834	2.3786337	0.83085972	3450.8555
820.98438	2.38012	0.83243966	3446.677
821.98535	2.3822756	0.83426934	3448.4661
822.98633	2.3871186	0.83574796	3450.0188
823.9873	2.3917608	0.8373155	3449.585
824.98828	2.39342	0.83876699	3453.354
825.98926	2.396065	0.84071791	3460.5334
826.99023	2.3991818	0.84249842	3454.2305
827.99121	2.4023674	0.84429133	3450.3149
828.99219	2.4052908	0.84601057	3459.0981
829.99316	2.4080579	0.8477726	3455.5918
830.99414	2.4117677	0.84933633	3452.98
831.99512	2.4097767	0.8510254	3449.1812
832.99609	2.4173324	0.85234046	3455.5618
833.99707	2.4217961	0.85402709	3456.1384
834.99805	2.4247055	0.85551172	3461.1406
835.99902	2.4264724	0.85697043	3455.6863
837	2.4306655	0.85859174	3455.0454
838.00098	2.435662	0.86008942	3463.6917
839.00195	2.4360297	0.86166871	3457.3667
840.00293	2.4371679	0.86309844	3454.9348
841.00391	2.4428208	0.86460972	3451.7827
842.00488	2.4444506	0.86620176	3454.4744
843.00586	2.446713	0.86783594	3457.7585
844.00684	2.4498446	0.86934692	3455.1863
845.00781	2.4548542	0.87106359	3463.1663
846.00879	2.4600883	0.87258255	3455.8149
847.00977	2.4588087	0.87431467	3458.3494
848.01074	2.4629257	0.87609392	3461.2444
849.01172	2.467556	0.8779766	3464.0522
850.0127	2.4692819	0.87962985	3459.2463
851.01367	2.4724128	0.88115603	3455.3921
852.01465	2.476599	0.88277167	3461.9031
853.01563	2.4772677	0.88428652	3458.5776
854.0166	2.480438	0.88573986	3456.3491
855.01758	2.4827437	0.88730514	3459.5972
856.01855	2.486877	0.88897544	3461.1055
857.01953	2.4913805	0.8907119	3459.0027
858.02051	2.4905181	0.89235348	3457.261
859.02148	2.4939649	0.89410585	3464.1787
860.02246	2.4993722	0.89605612	3461.7539
861.02344	2.5027919	0.89783943	3468.0098
862.02441	2.5028157	0.89973062	3460.8921
863.02539	2.5051205	0.90141582	3456.4258
864.02637	2.5083306	0.90313005	3454.5137
865.02734	2.5139976	0.90462333	3454.0613
866.02832	2.5187836	0.90622139	3465.7542
867.0293	2.517906	0.9077518	3459.2915
868.03027	2.5212924	0.90949619	3460.4961
869.03125	2.5256853	0.91140699	3466.0867
870.03223	2.5282645	0.91319019	3463.9211
871.0332	2.5329649	0.91467655	3460.9463
872.03418	2.5359106	0.91643333	3464.4163
873.03516	2.5378194	0.9181447	3464.5015
874.03613	2.5420647	0.9196558	3458.5508
875.03711	2.5402622	0.92113322	3461.6511
876.03809	2.5446389	0.92265612	3459.251
877.03906	2.549684	0.92433965	3464.7078
878.04004	2.5535853	0.92594182	3458.4788
879.04102	2.5531955	0.9274556	3459.3176
880.04199	2.5561931	0.92912978	3466.3208
881.04297	2.5610869	0.93088186	3466.448
882.04395	2.5645859	0.93277365	3466.3154
883.04492	2.565356	0.93442357	3461.9468
884.0459	2.5726075	0.93628603	3465.8916
885.04688	2.573549	0.93827075	3464.0537
886.04785	2.5776722	0.94000864	3461.062
887.04883	2.5772443	0.94148457	3457.3953
888.0498	2.5807419	0.94318324	3461.1514
889.05078	2.587672	0.94482726	3470.8203
890.05176	2.5918119	0.94632429	3463.4307
891.05273	2.5916028	0.94767368	3459.1062
892.05371	2.5951498	0.94953489	3470.0398
893.05469	2.5970368	0.95172274	3471.6321
894.05566	2.6003916	0.95353305	3457.8777
895.05664	2.6078107	0.95529288	3470.8223
896.05762	2.6058083	0.9571352	3463.6243
897.05859	2.608835	0.95904863	3465.4153
898.05957	2.6117401	0.96116662	3470.281
899.06055	2.615478	0.96329486	3464.3823
900.06152	2.6183512	0.96541381	3466.8665
901.0625	2.6200268	0.96717238	3457.1616
902.06348	2.6229777	0.96886754	3461.7239
903.06445	2.6301939	0.97068834	3464.6414
904.06543	2.6317985	0.97240794	3459.9473
905.06641	2.6351502	0.97393698	3460.1245
906.06738	2.6366904	0.9754321	3459.6658
907.06836	2.6401465	0.97704393	3468.1382
908.06934	2.6422889	0.97877884	3466.3955
909.07031	2.6437967	0.98054069	3459.4426
910.07129	2.646805	0.98206216	3460.8154
911.07227	2.6497478	0.98387206	3466.2766
912.07324	2.6510985	0.98580337	3466.1255
913.07422	2.6578991	0.9878397	3469.2639
914.0752	2.660727	0.98981732	3461.3831
915.07617	2.6634457	0.99160933	3460.4243
916.07715	2.6699383	0.99326354	3467.1172
917.07813	2.6715662	0.99493676	3465.0901
918.0791	2.6715877	0.99651784	3462.6709
919.08008	2.6780276	0.99808997	3465.1641
920.08105	2.6812332	0.99995703	3472.9656
921.08203	2.6816845	1.0019399	3464.2258
922.08301	2.6853776	1.003837	3469.9375
923.08398	2.6857357	1.0059	3469.2485
924.08496	2.688205	1.0078937	3467.262
925.08594	2.6923358	1.0099943	3465.6506
926.08691	2.6976988	1.0119845	3468.0193
927.08789	2.6986718	1.0139831	3465.5405
928.08887	2.704216	1.0160145	3468.2136
929.08984	2.7095861	1.0180467	3470.1768
930.09082	2.7097707	1.0201497	3463.5742
931.0918	2.7129157	1.0219193	3461.1362
932.09277	2.7148895	1.0237217	3464.7739
933.09375	2.7172775	1.0254787	3466.9922
934.09473	2.7186592	1.0275364	3466.4016
935.0957	2.7246461	1.0295764	3469.6897
936.09668	2.7257676	1.0312701	3456.9836
937.09766	2.7288129	1.0329735	3461.5908
938.09863	2.7317266	1.0350933	3466.2251
939.09961	2.7332046	1.0370537	3466.1814
940.10059	2.7408555	1.0389659	3470.6699
941.10156	2.7395544	1.0409948	3466.4519
942.10254	2.7430854	1.0431594	3459.8027
943.10352	2.7482829	1.0452033	3461.5242
944.10449	2.7519181	1.0468919	3459.5808
945.10547	2.7570956	1.0488474	3463.5774
946.10645	2.7547905	1.050545	3457.0437
947.10742	2.7597106	1.0524095	3465.7881
948.1084	2.7614403	1.0544617	3463.4116
949.10938	2.7651756	1.0566179	3456.9941
950.11035	2.7699137	1.0583189	3455.1899
951.11133	2.772718	1.0602	3461.3665
952.1123	2.7762916	1.0624005	3467.0139
953.11328	2.7777386	1.0646243	3458.5059
954.11426	2.7812417	1.0663543	3453.4993
955.11523	2.7843502	1.0682698	3463.8774
956.11621	2.7866001	1.0701865	3460.6233
957.11719	2.7914796	1.0721701	3458.0581
958.11816	2.7919433	1.073994	3449.1675
959.11914	2.79597	1.0759203	3456.7588
960.12012	2.7995377	1.0778161	3458.9895
961.12109	2.8026123	1.0798233	3459.1807
962.12207	2.8066263	1.0819685	3457.8442
963.12305	2.806288	1.0841553	3458.9497
964.12402	2.8113122	1.0862981	3459.541
965.125	2.8124595	1.0887067	3458.8694
966.12598	2.818238	1.0911938	3459.8394
967.12695	2.8209844	1.0929556	3455.7791
968.12793	2.8223352	1.0951747	3454.2844
969.12891	2.8257546	1.0972793	3460.4119
970.12988	2.826088	1.0996375	3453.7603
971.13086	2.8316877	1.101818	3453.1646
972.13184	2.8328292	1.1037501	3454.2251
973.13281	2.8380697	1.1059302	3457.533
974.13379	2.8429701	1.1081685	3452.5713
975.13477	2.8449001	1.1101828	3451.9519
976.13574	2.8473301	1.1120813	3452.1099
977.13672	2.8514321	1.1140742	3455.604
978.1377	2.8525262	1.1163388	3452.3972
979.13867	2.8550205	1.1186278	3449.9534
980.13965	2.8554759	1.1206272	3443.7131
981.14063	2.8608446	1.1225786	3449.8179
982.1416	2.8637602	1.1244308	3443.0125
983.14258	2.8659782	1.1260707	3446.7573
984.14355	2.8761911	1.1279567	3449.6494
985.14453	2.8726406	1.1297508	3446.0645
986.14551	2.877645	1.131914	3449.5867
987.14648	2.8803151	1.1345069	3448.3635
988.14746	2.883642	1.1367458	3445.1726
989.14844	2.8866169	1.1387435	3443.5769
990.14941	2.8869936	1.1408484	3444.3333
991.15039	2.8931241	1.1430773	3446.9453
992.15137	2.894908	1.1451869	3443.7043
993.15234	2.9000523	1.1474384	3442.7971
994.15332	2.9015155	1.1492984	3438.7466
995.1543	2.9035134	1.1514071	3441.9138
996.15527	2.905808	1.1538739	3444.3745
997.15625	2.9104514	1.1558783	3436.1042
998.15723	2.9146123	1.158039	3438.6348
999.1582	2.9147632	1.1603446	3437.8965
1000.1592	2.9177771	1.1626709	3438.5269
1001.1602	2.9208701	1.1649054	3436.5198
1002.1611	2.9215348	1.167347	3429.261
1003.1621	2.9287474	1.1696057	3436.4268
1004.1631	2.9301748	1.1719124	3429.9724
1005.1641	2.9345143	1.1738616	3431.3313
1006.165	2.9364953	1.1758111	3430.8943
1007.166	2.9397144	1.1779177	3427.5129
1008.167	2.9446144	1.1800327	3428.7502
1009.168	2.9452555	1.1821339	3428.303
1010.1689	2.9509404	1.1839966	3423.3071
1011.1699	2.9524567	1.186082	3427.0576
1012.1709	2.9548314	1.1882818	3429.1711
1013.1719	2.9588408	1.1902659	3418.9165
1014.1729	2.9611728	1.1924658	3421.5869
1015.1738	2.9647336	1.1946193	3425.3372
1016.1748	2.9696829	1.1970189	3422.7979
1017.1758	2.9737005	1.1991993	3426.7646
1018.1768	2.9745576	1.2015275	3424.3743
1019.1777	2.9755974	1.2037158	3418.8394
1020.1787	2.9795256	1.2058775	3416.3777
1021.1797	2.9825034	1.2077947	3418.1257
1022.1807	2.9848776	1.2101912	3418.0029
1023.1816	2.9880354	1.2126575	3407.9131
1024.1826	2.9937234	1.2145746	3406.0989
1025.1836	2.9939954	1.2164969	3412.7266
1026.1846	2.9966843	1.2185305	3414.4937
1027.1855	2.9997711	1.2208414	3409.7654
1028.1865	3.0015438	1.222735	3396.4067
1029.1875	3.005415	1.2246779	3408.415
1030.1885	3.0113347	1.226428	3399.3088
1031.1895	3.0084271	1.2279569	3398.218
1032.1904	3.0139837	1.2296443	3397.6995
1033.1914	3.0178754	1.2312765	3400.0237
1034.1924	3.0205576	1.2333914	3404.356
1035.1934	3.0272141	1.2355851	3404.2539
1036.1943	3.0276923	1.2377967	3400.3909
1037.1953	3.0305433	1.2401854	3399.8186
1038.1963	3.0348315	1.242743	3397.623
1039.1973	3.0362802	1.2451775	3395.4045
1040.1982	3.0388823	1.247633	3395.9443
1041.1992	3.0432909	1.2501025	3384.2178
1042.2002	3.0454168	1.2522407	3388.0056
1043.2012	3.0463498	1.2544081	3384.73
1044.2021	3.0504816	1.2564759	3385.4763
1045.2031	3.056478	1.2586249	3388.3594
1046.2041	3.061002	1.2613068	3386.699
1047.2051	3.0575502	1.2640041	3375.5117
1048.2061	3.0633297	1.2660767	3372.3003
1049.207	3.0685716	1.2681127	3373.9875
1050.208	3.067167	1.2699831	3375.0762
1051.209	3.0751932	1.2723194	3376.2239
1052.21	3.075202	1.2746055	3371.2942
1053.2109	3.0784073	1.2767069	3372.1213
1054.2119	3.0824671	1.2787133	3368.2139
1055.2129	3.0847604	1.2809272	3364.4294
1056.2139	3.0870407	1.2829766	3365.2747
1057.2148	3.088526	1.2849696	3360.1021
1058.2158	3.0903435	1.2873005	3360.6494
1059.2168	3.0925541	1.2897813	3363.5088
1060.2178	3.0998397	1.2920953	3352.2417
1061.2188	3.1038358	1.2942228	3355.2053
1062.2197	3.105056	1.2964119	3354.2632
1063.2207	3.1069689	1.2986989	3360.1008
1064.2217	3.1113515	1.3010752	3350.0815
1065.2227	3.1148121	1.3034579	3351.6707
1066.2236	3.1175244	1.3058288	3343.0942
1067.2246	3.1227212	1.3080549	3345.8118
1068.2256	3.1246371	1.3102133	3337.176
1069.2266	3.1268587	1.3126405	3340.3342
1070.2275	3.1299267	1.3148768	3338.5566
1071.2285	3.1317699	1.3172808	3337.9832
1072.2295	3.1358821	1.3199019	3341.2239
1073.2305	3.1407743	1.3225201	3332.5217
1074.2314	3.1410313	1.3250886	3322.8416
1075.2324	3.1460528	1.3275046	3330.0042
1076.2334	3.1483653	1.3298018	3324.9011
1077.2344	3.1499846	1.3322668	3323.5015
1078.2354	3.1552022	1.3347455	3318.9087
1079.2363	3.1602573	1.3370589	3319.896
1080.2373	3.161216	1.3394762	3315.2339
1081.2383	3.1625359	1.3417627	3305.6519
1082.2393	3.1646712	1.3440921	3305.6985
1083.2402	3.16835	1.346599	3307.9341
1084.2412	3.1723588	1.3491113	3303.9292
1085.2422	3.1755371	1.3515865	3298.5391
1086.2432	3.1769695	1.3537999	3292.2725
1087.2441	3.1821148	1.3560656	3301.4631
1088.2451	3.182848	1.3584502	3288.3679
1089.2461	3.1864135	1.3607073	3289.5193
1090.2471	3.1896677	1.3630035	3285.0974
1091.248	3.1945899	1.3652992	3286.6963
1092.249	3.1956615	1.3676877	3284.3804
1093.25	3.1974111	1.3699867	3279.9619
1094.251	3.2020347	1.3720082	3275.1538
1095.252	3.2044997	1.3745356	3277.8381
1096.2529	3.2083523	1.3776126	3278.3975
1097.2539	3.2088268	1.3803188	3266.4429
1098.2549	3.2163246	1.3826038	3262.4189
1099.2559	3.2203441	1.3848823	3264.7744
1100.2568	3.2197821	1.3873031	3261.0239
1101.2578	3.223042	1.3900496	3260.7405
1102.2588	3.2251966	1.3926964	3249.0969
1103.2598	3.2261045	1.3951008	3250.3401
1104.2607	3.2319822	1.3976544	3250.4612
1105.2617	3.2336745	1.4000686	3247.502
1106.2627	3.2359142	1.4030137	3241.0715
1107.2637	3.2428904	1.405633	3236.8276
1108.2646	3.242569	1.4078907	3232.0107
1109.2656	3.2475469	1.4107372	3230.1929
1110.2666	3.2483945	1.4139405	3231.5798
1111.2676	3.2530305	1.4171389	3225.2322
1112.2686	3.2535264	1.419433	3220.647
1113.2695	3.2562826	1.4218566	3217.6243
1114.2705	3.2622466	1.4248488	3215.3293
1115.2715	3.2642705	1.4275508	3208.3782
1116.2725	3.2676027	1.4302226	3200.0403
1117.2734	3.2715752	1.4325112	3202.1255
1118.2744	3.2747879	1.4353265	3198.6931
1119.2754	3.2769575	1.4381185	3196.3145
1120.2764	3.2789774	1.4404194	3188.9893
1121.2773	3.2853734	1.4428757	3184.1897
1122.2783	3.2858434	1.4454173	3188.385
1123.2793	3.2899022	1.4480238	3178.2026
1124.2803	3.2901735	1.4508246	3176.5718
1125.2813	3.2938621	1.4536597	3173.2551
1126.2822	3.2994578	1.4565684	3172.8225
1127.2832	3.3005395	1.4588295	3163.0989
1128.2842	3.3042595	1.4612644	3161.4475
1129.2852	3.3091922	1.4637003	3158.5432
1130.2861	3.3092368	1.4664153	3156.8865
1131.2871	3.3123527	1.4690409	3149.271
1132.2881	3.3144698	1.4722939	3148.3704
1133.2891	3.3196237	1.4753683	3142.7703
1134.29	3.3227718	1.47795	3136.249
1135.291	3.3251433	1.4808791	3135.2019
1136.292	3.329541	1.4842145	3131.7507
1137.293	3.3327472	1.4872408	3120.6877
1138.2939	3.3333867	1.4899846	3113.7939
1139.2949	3.3365991	1.492643	3106.8472
1140.2959	3.3418381	1.4953971	3109.6853
1141.2969	3.3450754	1.4982357	3102.1348
1142.2979	3.3449981	1.5008372	3091.7439
1143.2988	3.348094	1.5035746	3095.4954
1144.2998	3.3519778	1.5070455	3093.9392
1145.3008	3.3537223	1.5109922	3080.7065
1146.3018	3.3573101	1.5139563	3069.0142
1147.3027	3.360862	1.5165938	3064.5222
1148.3037	3.3617685	1.5193974	3064.3604
1149.3047	3.3695822	1.5227517	3066.3232
1150.3057	3.3712387	1.526103	3053.3098
1151.3066	3.3739066	1.5292875	3043.4631
1152.3076	3.3745756	1.5322592	3039.0356
1153.3086	3.3770845	1.5356526	3042.2776
1154.3096	3.3800867	1.5391243	3027.1555
1155.3105	3.3856649	1.542582	3024.3582
1156.3115	3.3892968	1.5453523	3009.1284
1157.3125	3.3900442	1.547712	3002.355
1158.3135	3.3940179	1.551414	3014.3953
1159.3145	3.3973994	1.5554414	2998.262
1160.3154	3.4023435	1.5585124	2987.4985
1161.3164	3.4032109	1.5618925	2982.9661
1162.3174	3.4081702	1.5649632	2970.478
1163.3184	3.4125102	1.5676907	2968.5042
1164.3193	3.4106874	1.5700986	2956.7249
1165.3203	3.415843	1.5728334	2958.7761
1166.3213	3.415633	1.5759244	2945.3928
1167.3223	3.4193556	1.5791497	2943.552
1168.3232	3.422724	1.5834992	2934.3074
1169.3242	3.4259541	1.5880865	2917.5156
1170.3252	3.4318371	1.5916082	2901.6157
1171.3262	3.4346564	1.5959163	2883.9341
1172.3271	3.4381437	1.6006131	2864.8245
1173.3281	3.4412045	1.6082907	2816.9104
1174.0288	3.4467483	1.6205852	2714.8647