File: datasets/am_bench_2022/raw_data/60-X.05-1/specimen.dat
MTS793|MPT|ENU|1|2|.|/|:|1|0|0|A

Operator Information						Time:	20.254639	Sec	10/15/2021 11:27:02 AM
Operator	Orion Kafka
Project	AM Bench 2022 mini-tensile challenge
Specimen ID	60-X.05-1
Material	PBF-L Inconel 625
Specimen Width	2.56	mm
Specimen Thickness	1.53	mm
Notes
Operator Information End

Data Acquisition						Time:	1021.249	Sec	10/15/2021 11:43:43 AM
Time	Axial Displacement	Axial Extensometer	Axial Force
Sec	mm	mm	N
20.368652	0.0024270571	-1.0935174e-05	103.06807
21.469727	0.00017079788	0.00019574039	116.52634
22.570801	0.0077652354	0.0002054932	146.44286
23.671875	0.012320679	0.0002663612	162.79489
24.772949	0.013222199	0.00045458018	180.55516
25.874023	0.017011657	0.0002424627	204.10236
26.975098	0.01896688	0.0006341323	214.73029
28.076172	0.024309156	0.00063850876	251.37157
29.177246	0.027221834	0.00064928603	268.88428
30.27832	0.030205866	0.00074541161	298.94846
31.379395	0.034162465	0.00090828561	315.76004
32.480469	0.034770992	0.00088145409	340.2691
33.581543	0.039512269	0.00097261625	364.13406
34.682617	0.0440672	0.0010957425	396.00278
35.783691	0.046387337	0.0012623618	422.33078
36.884766	0.050263412	0.0013942942	454.14917
37.98584	0.052177247	0.001486785	477.58289
39.086914	0.054696996	0.0016759997	502.33984
40.187988	0.064012669	0.0017340771	536.53113
41.289063	0.065689445	0.0017683011	565.05292
42.390137	0.064068809	0.0020786668	591.82336
43.491211	0.070797175	0.0021844264	626.93341
44.592285	0.071716517	0.002125463	648.65613
45.693359	0.078010261	0.0023221644	684.7428
46.794434	0.079368226	0.0026227611	718.45856
47.895508	0.084208161	0.0026567227	748.29285
48.996582	0.086763509	0.0027992849	774.37744
50.097656	0.088311046	0.0029650764	813.12939
51.19873	0.092208385	0.0031244017	843.90607
52.299805	0.097985491	0.0032037713	878.17816
53.400879	0.0993203	0.0032057588	909.69324
54.501953	0.10287695	0.003549034	940.89349
55.603027	0.10573042	0.003562938	980.73358
56.704102	0.10928446	0.003682625	1004.8612
57.805176	0.1111211	0.0037917653	1033.8042
58.90625	0.11321032	0.0040193633	1060.5516
60.007324	0.11838889	0.0041284463	1092.5509
61.108398	0.12033981	0.0040965131	1116.6838
62.209473	0.12545101	0.0043316674	1150.5768
63.310547	0.12765396	0.0045493939	1187.5243
64.411621	0.13484594	0.0045697475	1216.4525
65.512695	0.13547146	0.0048177037	1251.4728
66.61377	0.13856307	0.0049349819	1285.3964
67.714844	0.14200293	0.0050975117	1310.4868
68.815918	0.14541964	0.0050950493	1348.6947
69.916992	0.14769286	0.0053392309	1382.4025
71.018066	0.15409483	0.0056086145	1414.7891
72.119141	0.15369509	0.005608594	1446.5724
73.220215	0.1596823	0.0057641054	1487.1031
74.321289	0.16011421	0.0060743839	1511.2214
75.422363	0.16551249	0.0060066069	1544.5481
76.523438	0.16913551	0.0062245065	1573.1619
77.624512	0.17201664	0.0063574375	1611.403
78.725586	0.1757706	0.0066116345	1635.6343
79.82666	0.17920028	0.0066996668	1672.0388
80.927734	0.18140648	0.0068885088	1694.521
82.028809	0.18495454	0.0069618016	1725.0708
83.129883	0.18850853	0.0070136716	1754.8561
84.230957	0.1914946	0.0071860077	1784.686
85.332031	0.19409379	0.0072849402	1804.9313
86.433105	0.1968735	0.0075115832	1834.5702
87.53418	0.20068012	0.0075629987	1860.8214
88.635254	0.20648402	0.0075251637	1881.7018
89.736328	0.2093406	0.0079740211	1893.2471
90.837402	0.21148309	0.0079098828	1922.3904
91.938477	0.21315742	0.0078115654	1939.8307
93.039551	0.21806496	0.0082463063	1966.7867
94.140625	0.21959278	0.008246785	1991.6816
95.241699	0.2266649	0.0082919383	2021.3278
96.342773	0.22512273	0.0084330169	2026.9203
97.443848	0.23227912	0.0085704066	2051.3086
98.544922	0.23200642	0.0086751748	2060.6575
99.645996	0.23485762	0.0086116344	2066.1113
100.74707	0.24232744	0.0089372937	2087.6042
101.84814	0.24592881	0.008895779	2104.5466
102.94922	0.24533236	0.0089164153	2118.8196
104.05029	0.25257435	0.0091239056	2134.6199
105.15137	0.25678602	0.0090326685	2152.0654
106.25244	0.25914064	0.0091931662	2157.842
107.35352	0.26120403	0.0091960551	2175.3311
108.45459	0.26597038	0.0093810121	2190.062
109.55566	0.26973292	0.009510342	2201.3206
110.65674	0.27180091	0.0094761876	2205.6279
111.75781	0.27452099	0.0094667543	2218.6101
112.85889	0.2798489	0.0096156951	2232.3096
113.95996	0.28033057	0.0096356263	2248.6736
115.06104	0.28489101	0.0097177792	2259.3184
116.16211	0.28871423	0.0099183321	2274.3806
117.26318	0.28745702	0.009986815	2281.9983
118.36426	0.29487193	0.0099494429	2292.7451
119.46533	0.29645818	0.010264193	2310.3047
120.56641	0.3015376	0.010377631	2315.7
121.66748	0.30623138	0.010263124	2326.4951
122.76855	0.30737442	0.010358527	2335.3806
123.86963	0.30903649	0.010624087	2351.937
124.9707	0.31651783	0.010555658	2358.5232
126.07178	0.32052419	0.010490406	2373.0017
127.17285	0.31935677	0.011051437	2382.9905
128.27393	0.32466584	0.010822232	2392.5457
129.375	0.32612959	0.01091244	2401.0383
130.47607	0.33112964	0.011132449	2407.9763
131.57715	0.33178264	0.011261012	2413.4087
132.67822	0.33773467	0.011041418	2420.855
133.7793	0.3394756	0.011266167	2432.2678
134.88037	0.34337279	0.011342834	2447.4241
135.98145	0.34759876	0.011390211	2450.2927
137.08252	0.34954095	0.011540181	2459.3125
138.18359	0.35171771	0.011587507	2470.4656
139.28467	0.35946533	0.011774479	2488.8101
140.38574	0.36187175	0.011879802	2491.1167
141.48682	0.36331889	0.011859861	2504.8047
142.58789	0.36625457	0.011948357	2504.2664
143.68896	0.37201703	0.012014769	2508.0552
144.79004	0.37383583	0.012221186	2528.3577
145.89111	0.37900046	0.01219517	2530.8525
146.99219	0.38223073	0.012364325	2547.4849
148.09326	0.38364631	0.012408906	2551.437
149.19434	0.38956264	0.012524106	2560.3191
150.29541	0.39136159	0.012666451	2568.9353
151.39648	0.39330089	0.012798173	2575.644
152.49756	0.39600787	0.013003956	2584.625
153.59863	0.40104601	0.01306016	2591.1902
154.69971	0.40049961	0.013104973	2595.6418
155.80078	0.40989399	0.013324098	2605.728
156.90186	0.40953338	0.013413044	2613.6951
158.00293	0.41397393	0.013558224	2626.9539
159.104	0.41499934	0.013856722	2631.8149
160.20508	0.42066294	0.013835734	2638.8638
161.30615	0.42444184	0.01409366	2643.5959
162.40723	0.42486557	0.014242281	2649.0366
163.5083	0.42982715	0.014343341	2657.4766
164.60938	0.43391207	0.014584367	2665.0146
165.71045	0.43501619	0.014753093	2678.0645
166.81152	0.44378725	0.015181147	2688.5239
167.9126	0.44194958	0.01525296	2687.0718
169.01367	0.44664446	0.015516083	2692.9912
170.11475	0.4491576	0.015876764	2705.9529
171.21582	0.45389238	0.016048424	2701.7642
172.31689	0.45799178	0.016298141	2714.8157
173.41797	0.45929673	0.016690357	2719.2168
174.51904	0.46404338	0.016971329	2719.0352
175.62012	0.46613282	0.017368177	2741.9175
176.72119	0.47250098	0.017745804	2742.5046
177.82227	0.47281221	0.018093135	2749.8677
178.92334	0.47689605	0.018495481	2746.4609
180.02441	0.48044553	0.018874371	2757.8147
181.12549	0.48500267	0.01940972	2762.3037
182.22656	0.48903507	0.019844456	2769.2148
183.32764	0.48914221	0.020247051	2774.9521
184.42871	0.49357498	0.020743001	2775.9758
185.52979	0.49461195	0.021310559	2783.6292
186.63086	0.49658212	0.021896368	2790.8433
187.73193	0.50298941	0.022495663	2795.2505
188.83301	0.50770658	0.023183662	2801.26
189.93408	0.50935733	0.023739668	2797.8005
191.03516	0.51356989	0.024347212	2809.6143
192.13623	0.51515567	0.025090912	2812.676
193.2373	0.51821923	0.025721101	2813.6567
194.33838	0.52270335	0.02656902	2823.6086
195.43945	0.52714539	0.027320765	2831.0386
196.54053	0.53098828	0.028076636	2832.5085
197.6416	0.53259885	0.028796664	2840.7622
198.74268	0.53903693	0.029604429	2842.8091
199.84375	0.5401718	0.030430064	2841.6067
200.94482	0.54337829	0.031194689	2850.2686
202.0459	0.54315412	0.031986758	2852.7295
203.14697	0.54775655	0.03287952	2851.9963
204.24805	0.55286115	0.03346286	2851.6362
205.34912	0.56080425	0.034539279	2873.1343
206.4502	0.55874676	0.03523789	2861.5132
207.55127	0.56245154	0.036047954	2870.5757
208.65234	0.566818	0.03740219	2874.5342
209.75342	0.5687865	0.038272444	2875.7993
210.85449	0.57297856	0.039091229	2873.6233
211.95557	0.57252145	0.040031638	2879.2319
213.05664	0.5738405	0.040904313	2876.6316
214.15771	0.58100426	0.041976526	2891.0361
215.25879	0.58746374	0.043081596	2900.4363
216.35986	0.59000415	0.044077955	2897.2751
217.46094	0.59297895	0.045083601	2894.957
218.56201	0.59319121	0.045896683	2898.781
219.66309	0.60109234	0.046978567	2908.3359
220.76416	0.60367227	0.048138782	2911.9229
221.86523	0.60755473	0.049177282	2914.6223
222.96631	0.60585618	0.050156131	2912.7786
224.06738	0.61084485	0.051058456	2916.6782
225.16846	0.61418593	0.052202746	2924.6155
226.26953	0.6219939	0.053230975	2925.6982
227.37061	0.6243372	0.054351121	2930.8164
228.47168	0.62401527	0.055356026	2930.4053
229.57275	0.62905061	0.056498952	2934.5684
230.67383	0.63170618	0.057554938	2934.5735
231.7749	0.63569456	0.05858608	2942.375
232.87598	0.63828373	0.059840348	2946.8269
233.97705	0.64106286	0.060896203	2938.0842
235.07813	0.64341778	0.061987754	2947.5542
236.1792	0.64801288	0.06299369	2946.863
237.28027	0.64866912	0.064210534	2955.657
238.38135	0.65676689	0.065507762	2957.0405
239.48242	0.65769875	0.066639788	2958.1594
240.5835	0.6638577	0.067796193	2955.6533
241.68457	0.66671115	0.069119029	2961.9177
242.78564	0.67092657	0.069971256	2960.2417
243.88672	0.67049015	0.0712073	2964.1536
244.98779	0.67504853	0.071885124	2959.6736
246.08887	0.67813027	0.073196329	2975.2944
247.18994	0.68287998	0.074594803	2974.425
248.29102	0.68599468	0.075735003	2971.7219
249.39209	0.68399638	0.077104285	2979.6948
250.49316	0.69171333	0.078433484	2983.0205
251.59424	0.6973998	0.079903938	2986.7927
252.69531	0.69797003	0.081041887	2981.4648
253.79639	0.70284867	0.082040146	2978.9678
254.89746	0.70190227	0.083452627	2986.6487
255.99854	0.70805198	0.084902532	2987.4407
257.09961	0.7117908	0.085866652	2989.575
258.20068	0.7127136	0.086957268	2997.8611
259.30176	0.71761781	0.088428676	2995.4238
260.40283	0.72005802	0.089791313	3006.5369
261.50391	0.7246713	0.091032192	2998.9487
262.60498	0.72817349	0.09222015	2999.2883
263.70605	0.73177218	0.093669064	3007.8711
264.80713	0.73220199	0.09491235	3008.0083
265.9082	0.73655897	0.096290812	3005.938
267.00928	0.7433545	0.09756162	3022.7856
268.11035	0.74594206	0.098919578	3018.4604
269.21143	0.74688268	0.10020076	3015.1499
270.3125	0.74987674	0.10156449	3023.1997
271.41357	0.75349671	0.10292239	3014.6763
272.51465	0.75901538	0.10392024	3020.4524
273.61572	0.75989336	0.10489056	3011.8013
274.7168	0.76243865	0.10598931	3022.7659
275.81787	0.76586622	0.10687966	3018.7703
276.91895	0.76584816	0.10819633	3024.2693
278.02002	0.77216142	0.10969722	3025.5405
279.12109	0.77594757	0.11087416	3032.9434
280.22217	0.78213769	0.11239465	3035.5906
281.32324	0.7872082	0.11351826	3039.1226
282.42432	0.7903111	0.11498628	3039.0959
283.52539	0.78742748	0.11613896	3032.8879
284.62646	0.79457402	0.11715646	3041.8845
285.72754	0.7939741	0.11849181	3041.499
286.82861	0.80034488	0.11995923	3054.2903
287.92969	0.8047049	0.12138285	3055.2524
289.03076	0.80659974	0.1227603	3050.8767
290.13184	0.80984581	0.12407637	3049.2402
291.23291	0.81325984	0.12542559	3055.9585
292.33398	0.81562793	0.12664559	3050.9133
293.43506	0.81979638	0.12797154	3054.9265
294.53613	0.82627559	0.12935376	3065.4949
295.63721	0.82660264	0.13083906	3062.4377
296.73828	0.82777721	0.1321653	3068.8899
297.83936	0.83148974	0.13348225	3060.2686
298.94043	0.83855027	0.13489853	3066.8884
300.0415	0.84019208	0.13613498	3073.1785
301.14258	0.84457231	0.13757677	3074.074
302.24365	0.84699965	0.13871577	3072.2983
303.34473	0.84786206	0.13988085	3071.4094
304.4458	0.85107261	0.14105929	3070.0237
305.54688	0.85755712	0.14208506	3077.7375
306.64795	0.86076677	0.1433389	3082.6528
307.74902	0.86247736	0.1448002	3081.7717
308.8501	0.86975908	0.14637122	3088.9592
309.95117	0.87179196	0.1477728	3088.021
311.05225	0.87323767	0.14904752	3088.5298
312.15332	0.87753958	0.15032218	3082.7561
313.25439	0.88048464	0.15139467	3087.6196
314.35547	0.88282728	0.15225385	3088.0371
315.45654	0.88546872	0.15341116	3083.3418
316.55762	0.89235258	0.15462226	3100.8743
317.65869	0.89339691	0.15584628	3098.2419
318.75977	0.8940208	0.15706487	3097.9158
319.86084	0.90433633	0.1583827	3107.1436
320.96191	0.90430236	0.15969121	3099.9172
322.06299	0.90439433	0.1610792	3100.9382
323.16406	0.90967488	0.16243804	3108.9353
324.26514	0.91218638	0.16402633	3110.1516
325.36621	0.91484421	0.16538051	3102.7446
326.46729	0.91926777	0.16672388	3104.1018
327.56836	0.92289346	0.16791081	3104.9519
328.66943	0.92617452	0.169098	3119.03
329.77051	0.92953581	0.17066939	3110.5183
330.87158	0.93141973	0.17163868	3106.5139
331.97266	0.93338048	0.1728974	3106.7148
333.07373	0.93954432	0.17434232	3119.2817
334.1748	0.94110173	0.17571141	3118.0957
335.27588	0.94533515	0.17697565	3115.4348
336.37695	0.95035857	0.17836516	3124.6191
337.47803	0.95040923	0.17978306	3118.4487
338.5791	0.95639485	0.18100736	3127.5376
339.68018	0.95952636	0.18223397	3128.1565
340.78125	0.96050513	0.1836766	3127.9829
341.88232	0.96631569	0.18469101	3134.302
342.9834	0.96489668	0.18606347	3124.0251
344.08447	0.97331923	0.18734437	3132.6716
345.18555	0.97664189	0.18864721	3135.8184
346.28662	0.97840697	0.18983263	3138.8735
347.3877	0.98043376	0.19094533	3135.3804
348.48877	0.98523659	0.19214934	3132.3633
349.58984	0.99035263	0.19329689	3140.3547
350.69092	0.99116009	0.19459637	3138.6836
351.79199	0.99503273	0.19585927	3145.3855
352.89307	0.99734122	0.19676922	3141.5193
353.99414	1.004187	0.19817783	3158.1985
355.09521	1.0030004	0.19947819	3146.4824
356.19629	1.006627	0.20075557	3145.5117
357.29736	1.0147252	0.20207773	3151.0859
358.39844	1.0153869	0.20329012	3157.2021
359.49951	1.0189039	0.20463783	3149.8953
360.60059	1.0193443	0.20583893	3148.1267
361.70166	1.0238178	0.20679237	3156.9773
362.80273	1.0309951	0.20825247	3160.3376
363.90381	1.0299343	0.20954831	3158.188
365.00488	1.0340519	0.21083044	3166.417
366.10596	1.0395403	0.21229598	3169.8379
367.20703	1.0404403	0.21378522	3171.666
368.30811	1.0471729	0.21515065	3169.248
369.40918	1.0492016	0.21636696	3168.0415
370.51025	1.0498396	0.21754666	3168.6016
371.61133	1.0543163	0.21890545	3167.8318
372.7124	1.0589612	0.22011088	3173.0056
373.81348	1.061666	0.22165449	3172.2029
374.91455	1.0649139	0.22284076	3171.7673
376.01563	1.0658973	0.2240819	3172.1011
377.1167	1.0695751	0.2255546	3175.7324
378.21777	1.0737448	0.22684011	3174.5701
379.31885	1.0765344	0.22790381	3175.696
380.41992	1.0815753	0.22884502	3178.5713
381.521	1.0845683	0.2302382	3186.7637
382.62207	1.0887303	0.23154889	3188.1133
383.72314	1.093436	0.23274541	3183.6016
384.82422	1.0932399	0.23384951	3187.6372
385.92529	1.0968215	0.23486477	3181.1128
387.02637	1.0981573	0.23632205	3186.1306
388.12744	1.1030976	0.23770218	3195.4617
389.22852	1.1069039	0.23892099	3194.6553
390.32959	1.1101525	0.24045955	3194.2822
391.43066	1.1117723	0.24164228	3195.6565
392.53174	1.1214271	0.24308202	3203.2446
393.63281	1.1231774	0.2444075	3202.1328
394.73389	1.1259359	0.24547866	3197.208
395.83496	1.1271057	0.24686834	3198.635
396.93604	1.1319574	0.2478037	3207.5764
398.03711	1.1353521	0.24917553	3207.5625
399.13818	1.1357228	0.25020653	3201.2119
400.23926	1.1416563	0.25136569	3218.7722
401.34033	1.1437784	0.25268793	3214.9065
402.44141	1.1496841	0.25413206	3219.7908
403.54248	1.1481279	0.25538892	3214.5688
404.64355	1.154074	0.25669289	3213.5171
405.74463	1.1562649	0.25776666	3208.4915
406.8457	1.1613767	0.25902605	3220.4397
407.94678	1.1639547	0.26012504	3217.9031
409.04785	1.1692774	0.26174152	3223.5894
410.14893	1.1700095	0.26281422	3220.1675
411.25	1.1720239	0.26390049	3226.2161
412.35107	1.175403	0.26533988	3228.3306
413.45215	1.1820395	0.26641771	3223.6677
414.55322	1.1840974	0.26771474	3228.7009
415.6543	1.1852452	0.26905999	3229.7041
416.75537	1.1900029	0.27029699	3231.0874
417.85645	1.1924583	0.27156147	3228.7932
418.95752	1.1985784	0.27255723	3230.4055
420.05859	1.2004029	0.2736434	3233.501
421.15967	1.2035216	0.27480501	3226.2781
422.26074	1.206578	0.27600631	3238.7366
423.36182	1.2089548	0.27728903	3235.0239
424.46289	1.2100699	0.27844059	3238.0229
425.56396	1.216953	0.27993754	3240.6587
426.66504	1.2178105	0.28109324	3237.6914
427.76611	1.2236347	0.28214222	3238.156
428.86719	1.2276491	0.2834259	3246.158
429.96826	1.2315979	0.28459117	3249.5061
431.06934	1.2333528	0.28607318	3241.8701
432.17041	1.2358469	0.28722018	3247.2192
433.27148	1.2381357	0.28827369	3244.6331
434.37256	1.2441801	0.28947383	3250.7883
435.47363	1.2449331	0.29053441	3245.2024
436.57471	1.249481	0.29201531	3255.3672
437.67578	1.2532563	0.2933687	3255.8323
438.77686	1.255505	0.29459515	3253.3513
439.87793	1.260545	0.2960352	3256.2065
440.979	1.2635124	0.29689389	3251.0791
442.08008	1.2653505	0.29805765	3260.1467
443.18115	1.2714598	0.29956877	3265.4705
444.28223	1.2721714	0.30073291	3260.0671
445.3833	1.2749802	0.30201924	3254.8904
446.48438	1.2779235	0.30315015	3269.0332
447.58545	1.2835679	0.30469888	3274.0654
448.68652	1.2884252	0.30612379	3273.8516
449.7876	1.287887	0.30725962	3266.9102
450.88867	1.2930986	0.30847362	3271.373
451.98975	1.2929226	0.30966911	3266.437
453.09082	1.2983078	0.31100053	3269.9648
454.19189	1.3003873	0.31197429	3265.8137
455.29297	1.307114	0.31313869	3276.9412
456.39404	1.3124287	0.31436065	3276.8091
457.49512	1.3102639	0.31516555	3271.314
458.59619	1.3139982	0.31622705	3278.24
459.69727	1.3187056	0.31742674	3279.98
460.79834	1.3214009	0.31858647	3277.5049
461.89941	1.3254232	0.31981769	3287.021
463.00049	1.327867	0.3211225	3277.6147
464.10156	1.3318858	0.3226141	3286.8149
465.20264	1.3374641	0.32388088	3283.4556
466.30371	1.3400927	0.32496923	3280.5264
467.40479	1.3425717	0.32617465	3286.9917
468.50586	1.3454212	0.32713756	3287.3088
469.60693	1.347384	0.32839489	3296.7732
470.70801	1.3514996	0.32978401	3290.6023
471.80908	1.3532784	0.33096215	3291.7197
472.91016	1.3599384	0.3323493	3292.8335
474.01123	1.361347	0.33343473	3300.7461
475.1123	1.3653095	0.3352446	3303.5591
476.21338	1.3663334	0.33656463	3300.8186
477.31445	1.3704493	0.3375819	3292.7908
478.41553	1.3727641	0.33887821	3297.2456
479.5166	1.377021	0.34010372	3299.9885
480.61768	1.3839777	0.34117886	3303.5671
481.71875	1.3854799	0.34236386	3306.4019
482.81982	1.3924595	0.34358367	3309.7043
483.9209	1.3916936	0.34475115	3298.0601
485.02197	1.3960141	0.34577566	3303.1716
486.12305	1.3962343	0.34679121	3306.4685
487.22412	1.4026861	0.34856904	3313.4485
488.3252	1.4044886	0.3497881	3310.4121
489.42627	1.4088471	0.35088974	3313.9404
490.52734	1.4111879	0.35217595	3312.968
491.62842	1.4144338	0.35335276	3315.6836
492.72949	1.4191723	0.35438704	3318.7566
493.83057	1.4225703	0.35569528	3317.5908
494.93164	1.42449	0.35667565	3314.8274
496.03271	1.4271746	0.35781828	3321.5981
497.13379	1.4320183	0.35917357	3316.1096
498.23486	1.4342502	0.36022675	3319.4629
499.33594	1.4385431	0.36148468	3327.907
500.43701	1.4416624	0.36272171	3324.4973
501.53809	1.4465303	0.36378518	3333.0122
502.63916	1.4467084	0.36518773	3331.5366
503.74023	1.4526398	0.36634988	3333.7009
504.84131	1.4544306	0.36760724	3323.7769
505.94238	1.4605612	0.36890125	3330.5298
507.04346	1.4625179	0.37021273	3333.7583
508.14453	1.4657807	0.37136707	3328.2339
509.24561	1.4678274	0.37261206	3331.0054
510.34668	1.4749651	0.37391451	3344.1753
511.44775	1.4739084	0.37534469	3339.3098
512.54883	1.4768503	0.37639415	3332.1262
513.6499	1.4796537	0.37771657	3334.7598
514.75098	1.4837683	0.37875631	3337.7083
515.85205	1.484938	0.37993845	3343.2305
516.95313	1.4910665	0.38113293	3338.4978
518.0542	1.4945098	0.38233927	3339.9141
519.15527	1.4961909	0.38352334	3346.512
520.25635	1.4982761	0.38487396	3344.4561
521.35742	1.5034888	0.38620591	3358.1675
522.4585	1.5059772	0.38746953	3340.283
523.55957	1.5085732	0.38866743	3346.0254
524.66064	1.5143961	0.38975593	3345.0605
525.76172	1.5138031	0.39093789	3347.4548
526.86279	1.5206182	0.39202949	3353.322
527.96387	1.5201949	0.39322779	3342.2004
529.06494	1.5265584	0.39436471	3348.2378
530.16602	1.5282362	0.39549887	3344.0156
531.26709	1.5362327	0.39674172	3360.5012
532.36816	1.5401317	0.39790148	3359.0188
533.46924	1.5422369	0.39893219	3360.1018
534.57031	1.5432638	0.40010351	3359.9817
535.67139	1.5462669	0.40144622	3362.9041
536.77246	1.5520198	0.40279889	3365.3208
537.87354	1.5525672	0.40393493	3355.5444
538.97461	1.555138	0.40515316	3367.3955
540.07568	1.5604922	0.40627158	3369.5876
541.17676	1.5645533	0.40778181	3367.2876
542.27783	1.5679836	0.40914065	3375.3804
543.37891	1.5706884	0.41015741	3366.9866
544.47998	1.5751247	0.41150236	3369.2649
545.58105	1.5781199	0.41267565	3368.4729
546.68213	1.5802761	0.41403982	3374.7004
547.7832	1.5854222	0.41530576	3374.9548
548.88428	1.5847143	0.41669059	3369.3794
549.98535	1.5891705	0.4178308	3379.4626
551.08643	1.5935575	0.41900274	3371.4382
552.1875	1.5949204	0.42043716	3374.7185
553.28857	1.598506	0.42147446	3378.0569
554.38965	1.6056502	0.42262799	3380.321
555.49072	1.6059244	0.42390534	3378.0447
556.5918	1.6112777	0.42505276	3380.0806
557.69287	1.6124132	0.42643887	3382.7998
558.79395	1.6158457	0.42761225	3379.1829
559.89502	1.6201264	0.42876789	3379.9167
560.99609	1.6265308	0.42977929	3387.2363
562.09717	1.6269262	0.43102404	3387.2781
563.19824	1.6306916	0.43234128	3389.1697
564.29932	1.63161	0.43363652	3382.7517
565.40039	1.6355561	0.43445677	3391.5627
566.50146	1.6403552	0.43584239	3391.4031
567.60254	1.6394781	0.43687692	3390.6765
568.70361	1.6453726	0.43820074	3389.9265
569.80469	1.6490752	0.43936282	3394.5754
570.90576	1.6528053	0.44070128	3393.0378
572.00684	1.6572934	0.44185358	3393.5183
573.10791	1.6603198	0.44294247	3400.085
574.20898	1.6610775	0.44423726	3402.9009
575.31006	1.6657469	0.44563919	3397.666
576.41113	1.6694907	0.44678593	3396.5461
577.51221	1.6745756	0.44817036	3399.7266
578.61328	1.674847	0.44929379	3398.2673
579.71436	1.6802305	0.45087111	3406.1377
580.81543	1.6842203	0.4519946	3404.0691
581.9165	1.6854869	0.45336163	3407.5911
583.01758	1.6883748	0.45472661	3403.719
584.11865	1.6908871	0.45588303	3411.0735
585.21973	1.6972731	0.45729533	3405.9397
586.3208	1.6984811	0.45858389	3404.5969
587.42188	1.7026314	0.45964038	3404.4775
588.52295	1.7041597	0.46072903	3407.4556
589.62402	1.7079946	0.46189302	3415.407
590.7251	1.7139252	0.46338642	3414.7576
591.82617	1.7153732	0.46459883	3409.2791
592.92725	1.7152252	0.46568727	3414.4236
594.02832	1.7242827	0.46717674	3418.3267
595.12939	1.7264345	0.46824753	3417.1177
596.23047	1.7265203	0.46962625	3412.5557
597.33154	1.7330689	0.47089657	3422.8418
598.43262	1.7376114	0.471901	3419.9065
599.53369	1.7388241	0.47315535	3414.2056
600.63477	1.7420636	0.47422048	3422.8203
601.73584	1.7442765	0.47519726	3410.0671
602.83691	1.7460772	0.47624803	3422.9277
603.93799	1.752266	0.47732404	3422.1929
605.03906	1.7547808	0.47852874	3428.7185
606.14014	1.7570248	0.47981477	3426.4885
607.24121	1.7616705	0.48108906	3432.2297
608.34229	1.7627906	0.48242614	3424.9978
609.44336	1.7693031	0.48364848	3427.1023
610.54443	1.772121	0.48496881	3430.1873
611.64551	1.7716863	0.48598734	3419.5227
612.74658	1.7766421	0.48718742	3430.4517
613.84766	1.7864032	0.48827699	3439.0891
614.94873	1.784402	0.48952633	3434.2917
616.0498	1.7897947	0.49073148	3433.8235
617.15088	1.7925088	0.491833	3437.2383
618.25195	1.7954973	0.49340251	3434.793
619.35303	1.7972485	0.49474517	3432.3196
620.4541	1.801307	0.49604702	3441.877
621.55518	1.8043969	0.49714458	3432.23
622.65625	1.8066372	0.49811104	3441.4316
623.75732	1.8116372	0.49918208	3444.0142
624.8584	1.8147372	0.50040931	3446.1968
625.95947	1.8213611	0.50171798	3451.7544
627.06055	1.8195379	0.50304025	3444.2798
628.16162	1.8274112	0.50399089	3440.1897
629.2627	1.8298377	0.5049938	3451.5339
630.36377	1.8312278	0.5061515	3452.7876
631.46484	1.8337753	0.5069623	3447.6138
632.56592	1.837689	0.50822002	3451.0447
633.66699	1.8409255	0.50940222	3446.9771
634.76807	1.846029	0.51034606	3449.3345
635.86914	1.8477622	0.51152623	3451.5051
636.97021	1.852066	0.51248479	3451.0181
638.07129	1.8526893	0.51364577	3450.1777
639.17236	1.8591534	0.51465982	3455.6426
640.27344	1.8613306	0.51585442	3454.8416
641.37451	1.8664924	0.51716506	3458.0535
642.47559	1.86804	0.51812255	3457.0894
643.57666	1.8692933	0.51928252	3460.8682
644.67773	1.8734699	0.52022851	3453.5669
645.77881	1.8743397	0.52147162	3452.4666
646.87988	1.8773196	0.52247328	3459.179
647.98096	1.8828459	0.52367467	3465.4019
649.08203	1.8877999	0.52508008	3455.7061
650.18311	1.890195	0.5261367	3463.6992
651.28418	1.891765	0.5273807	3454.3208
652.38525	1.8985276	0.52835566	3467.5559
653.48633	1.900167	0.52958757	3463.1289
654.5874	1.9031417	0.53083509	3458.4636
655.68848	1.9083153	0.5318194	3462.8215
656.78955	1.9087436	0.53310406	3469.6113
657.89063	1.9110693	0.5343262	3462.4648
658.9917	1.9187472	0.53514743	3468.8862
660.09277	1.9206337	0.53657281	3470.9468
661.19385	1.9219509	0.53760576	3469.3569
662.29492	1.9264847	0.53880829	3467.7612
663.396	1.9346468	0.53987163	3472.3811
664.49707	1.9335879	0.5408234	3468.1165
665.59814	1.9396236	0.54211658	3472.2439
666.69922	1.9396943	0.54297906	3474.25
667.80029	1.9418033	0.5442692	3472.1577
668.90137	1.9470407	0.54540741	3466.9602
670.00244	1.9526753	0.54640383	3473.0547
671.10352	1.9522041	0.54755396	3472.9573
672.20459	1.9590445	0.54861683	3474.4543
673.30566	1.9568545	0.54982316	3475.6233
674.40674	1.9621691	0.55104047	3477.436
675.50781	1.9658082	0.55205423	3481.2515
676.60889	1.9678553	0.55342042	3479.1387
677.70996	1.9716909	0.55444932	3487.8411
678.81104	1.9758128	0.55560267	3476.2319
679.91211	1.9804063	0.55673754	3478.8472
681.01318	1.9834894	0.55759698	3482.2688
682.11426	1.9860277	0.55863661	3478.9988
683.21533	1.9885426	0.55959004	3480.3816
684.31641	1.9940484	0.5605858	3492.4336
685.41748	1.9952701	0.56188619	3487.7351
686.51855	2.0022454	0.5632481	3495.1885
687.61963	2.0010374	0.56463057	3491.1223
688.7207	2.0064321	0.56575882	3494.4956
689.82178	2.0092907	0.56701416	3495.6726
690.92285	2.013499	0.56813222	3492.5703
692.02393	2.0160484	0.56932896	3494.3567
693.125	2.018353	0.57073647	3489.1206
694.22607	2.0233781	0.57156491	3491.2314
695.32715	2.026299	0.57279211	3488.7061
696.42822	2.0286102	0.57406902	3495.1694
697.5293	2.0326436	0.57514143	3495.1289
698.63037	2.0357497	0.57654005	3497.2751
699.73145	2.0417602	0.57751018	3504.4072
700.83252	2.0427141	0.57852632	3499.7085
701.93359	2.0477467	0.57962763	3501.4709
703.03467	2.0505848	0.58074081	3505.7986
704.13574	2.0542896	0.58199072	3502.9941
705.23682	2.0589037	0.58279008	3498.7292
706.33789	2.0606985	0.58411431	3505.8108
707.43896	2.063035	0.58551294	3504.1714
708.54004	2.0662608	0.58658969	3497.2385
709.64111	2.0687551	0.588045	3502.4875
710.74219	2.0752265	0.5890097	3504.3682
711.84326	2.0743024	0.59022933	3499.8306
712.94434	2.0799305	0.59129268	3508.3093
714.04541	2.0789366	0.5923453	3503.1018
715.14648	2.0863543	0.59352022	3513.5015
716.24756	2.0868597	0.594733	3506.7183
717.34863	2.090486	0.59572786	3503.6333
718.44971	2.0940917	0.59685308	3510.7715
719.55078	2.0982676	0.59783989	3513.0898
720.65186	2.0993702	0.59885448	3508.7461
721.75293	2.1052189	0.5996328	3508.321
722.854	2.1095619	0.60089767	3515.4678
723.95508	2.1099019	0.60176206	3509.5347
725.05615	2.1173387	0.60261834	3514.05
726.15723	2.1176677	0.60367996	3521.3103
727.2583	2.1212327	0.6046434	3516.7849
728.35938	2.1249106	0.60558945	3517.811
729.46045	2.125886	0.60653001	3513.48
730.56152	2.1341937	0.60745054	3513.0383
731.6626	2.1349189	0.60858631	3514.5356
732.76367	2.1383214	0.60927749	3515.0969
733.86475	2.1415417	0.61055505	3524.2051
734.96582	2.1460223	0.61158878	3521.9021
736.06689	2.1464617	0.61223984	3516.4631
737.16797	2.1476872	0.61313379	3512.3525
738.26904	2.1519578	0.61409724	3523.7212
739.37012	2.1559308	0.61540347	3521.012
740.47119	2.1615617	0.61644328	3516.7966
741.57227	2.1642394	0.61746782	3516.4534
742.67334	2.1703169	0.61864924	3526.8069
743.77441	2.1722972	0.61942512	3523.6743
744.87549	2.1779549	0.6206646	3529.2808
745.97656	2.1791551	0.62223393	3527.4719
747.07764	2.1793602	0.62351382	3522.1069
748.17871	2.1833794	0.62502962	3526.2505
749.27979	2.1896427	0.62640351	3525.4888
750.38086	2.1917636	0.62828225	3532.3232
751.48193	2.1923285	0.62985712	3519.1118
752.58301	2.1966631	0.6312893	3531.4355
753.68408	2.200326	0.63308537	3533.1821
754.78516	2.202168	0.63475513	3530.4932
755.88623	2.2088947	0.63612527	3529.0669
756.9873	2.2099781	0.63712531	3526.8062
758.08838	2.2148736	0.63891679	3538.8101
759.18945	2.2139623	0.64062369	3528.5325
760.29053	2.2207901	0.64212435	3539.21
761.3916	2.2232373	0.64368582	3534.3279
762.49268	2.2298427	0.64503694	3534.5864
763.59375	2.2323079	0.64625776	3529.6841
764.69482	2.2332869	0.6476022	3533.4944
765.7959	2.2377796	0.64899415	3529.915
766.89697	2.2404416	0.65037501	3541.6011
767.99805	2.2438803	0.6518842	3537.3223
769.09912	2.2473979	0.65312397	3531.4077
770.2002	2.2484927	0.65462852	3538.9985
771.30127	2.2555885	0.65570986	3543.8435
772.40234	2.2558589	0.65715218	3534.6909
773.50342	2.2579575	0.65855736	3540.3992
774.60449	2.2608011	0.65972662	3531.7043
775.70557	2.26946	0.66101795	3543.3662
776.80664	2.2691777	0.66217655	3543.5466
777.90771	2.2773416	0.66345257	3542.958
779.00879	2.2768016	0.66422206	3538.5996
780.10986	2.2798252	0.66518289	3541.0703
781.21094	2.2851405	0.6664151	3539.6331
782.31201	2.2884781	0.66726464	3551.8145
783.41309	2.2890794	0.66852719	3543.3293
784.51416	2.2914352	0.66972798	3545.5068
785.61523	2.2954788	0.67084903	3547.3982
786.71631	2.2981391	0.6722303	3552.2324
787.81738	2.3047776	0.6735	3550.2407
788.91846	2.3087587	0.67460465	3546.3171
790.01953	2.3115351	0.67574972	3548.397
791.12061	2.3117824	0.67715317	3553.1655
792.22168	2.3136044	0.67849571	3547.1052
793.32275	2.3178811	0.67965984	3547.6897
794.42383	2.3219345	0.68067384	3542.9778
795.5249	2.3247621	0.68166006	3542.8918
796.62598	2.3291087	0.68300033	3552.9653
797.72705	2.3337324	0.68418819	3553.061
798.82813	2.335844	0.68555194	3555.3396
799.9292	2.3419561	0.68665677	3550.5579
801.03027	2.3432629	0.68775076	3553.0854
802.13135	2.3468001	0.68911135	3558.9595
803.23242	2.3494773	0.69062084	3552.1804
804.3335	2.3517196	0.69204438	3554.7249
805.43457	2.357733	0.6934908	3558.5999
806.53564	2.3607132	0.69491941	3557.4751
807.63672	2.3646641	0.69620544	3556.5237
808.73779	2.3649642	0.69800961	3557.9902
809.83887	2.3696268	0.69958717	3558.3369
810.93994	2.3731103	0.70163888	3559.4275
812.04102	2.3762815	0.70317829	3552.5283
813.14209	2.3788638	0.70433015	3546.6106
814.24316	2.3798428	0.70593548	3549.6162
815.34424	2.3867514	0.70729548	3555.8252
816.44531	2.3917768	0.70892787	3561.344
817.54639	2.3945088	0.71064115	3568.752
818.64746	2.3965454	0.71251631	3560.0996
819.74854	2.4009988	0.71409756	3561.2107
820.84961	2.4033391	0.71587187	3561.3965
821.95068	2.4054053	0.71744061	3563.5613
823.05176	2.4106143	0.7191301	3562.4182
824.15283	2.4120183	0.72080559	3562.9612
825.25391	2.4154189	0.72261548	3563.2783
826.35498	2.418716	0.72451359	3565.4082
827.45605	2.4239039	0.72611213	3566.3418
828.55713	2.42555	0.72777998	3565.4504
829.6582	2.4292641	0.7292105	3561.1018
830.75928	2.4311814	0.73087293	3559.4773
831.86035	2.4354544	0.73263651	3570.1931
832.96143	2.4413633	0.73405898	3565.301
834.0625	2.4409769	0.73551846	3560.2122
835.16357	2.4428473	0.73740059	3567.6182
836.26465	2.44766	0.73915428	3571.4595
837.36572	2.4536514	0.74078208	3571.6538
838.4668	2.4564395	0.74237609	3564.4783
839.56787	2.458164	0.74388063	3568.7065
840.66895	2.4623642	0.74544984	3564.4519
841.77002	2.4626257	0.74711013	3563.7742
842.87109	2.4701805	0.74832493	3565.8684
843.97217	2.4706774	0.74984193	3567.853
845.07324	2.473803	0.75131428	3560.7654
846.17432	2.4792511	0.75271535	3566.8909
847.27539	2.483372	0.75416285	3568.052
848.37646	2.4840951	0.75566375	3568.376
849.47754	2.4905398	0.75774962	3579.385
850.57861	2.4926732	0.75958699	3578.0796
851.67969	2.4955378	0.76109403	3575.1541
852.78076	2.4974077	0.76291835	3566.9458
853.88184	2.5026994	0.76421458	3566.165
854.98291	2.5043445	0.76602662	3568.8594
856.08398	2.5094528	0.76786286	3580.0791
857.18506	2.5130115	0.76962262	3573.1089
858.28613	2.5147221	0.77100521	3575.6328
859.38721	2.5194252	0.77253908	3573.644
860.48828	2.5201693	0.77425957	3568.2021
861.58936	2.5238857	0.77595526	3572.8557
862.69043	2.5310476	0.77775532	3576.6362
863.7915	2.5314307	0.77979571	3574.0273
864.89258	2.5344954	0.78150839	3576.4944
865.99365	2.537091	0.78318328	3577.2332
867.09473	2.5443869	0.78503519	3580.0579
868.1958	2.5421591	0.78707159	3576.3367
869.29688	2.5477448	0.78895158	3568.1917
870.39795	2.5494878	0.79027587	3572.075
871.49902	2.5524156	0.7917152	3573.8748
872.6001	2.5559115	0.7934835	3579.3572
873.70117	2.5604382	0.79488015	3573.4519
874.80225	2.5645506	0.79634458	3577.4631
875.90332	2.5662086	0.79760462	3580.8506
877.00439	2.5714002	0.79919177	3579.7646
878.10547	2.5747912	0.80067378	3581.1953
879.20654	2.5809765	0.8021965	3584.6472
880.30762	2.5830722	0.80386269	3582.2358
881.40869	2.5848706	0.80561429	3579.8845
882.50977	2.5891182	0.80788267	3585.6523
883.61084	2.5889139	0.80963343	3574.6108
884.71191	2.5961554	0.81097227	3576.9241
885.81299	2.5941846	0.81250846	3575.3164
886.91406	2.6045206	0.81405097	3587.6013
888.01514	2.6037843	0.81600934	3583.5613
889.11621	2.6079876	0.81805754	3578.2117
890.21729	2.6137676	0.82015216	3590.7993
891.31836	2.6138206	0.82287496	3584.5544
892.41943	2.6178119	0.82531708	3582.668
893.52051	2.6175413	0.82753706	3581.8611
894.62158	2.6228271	0.82994395	3587.6729
895.72266	2.6267729	0.83231837	3581.3972
896.82373	2.6286428	0.83469987	3579.1929
897.9248	2.6329813	0.8364262	3582.5667
899.02588	2.6360617	0.83840424	3589.9697
900.12695	2.6417909	0.84050953	3586.3391
901.22803	2.6450412	0.84214026	3591.3545
902.3291	2.6483696	0.84369946	3580.8752
903.43018	2.648068	0.84565693	3591.311
904.53125	2.6549358	0.84772778	3588.9397
905.63232	2.6567066	0.84996653	3590.7595
906.7334	2.6600866	0.85188949	3583.8188
907.83447	2.6601515	0.85336256	3573.3577
908.93555	2.6662982	0.85461503	3584.458
910.03662	2.6687405	0.8565079	3592.4529
911.1377	2.672332	0.85822296	3585.4133
912.23877	2.6783578	0.85973215	3590.3269
913.33984	2.6817112	0.8614949	3588.3713
914.44092	2.6824296	0.86307782	3598.8416
915.54199	2.685312	0.86486143	3582.8833
916.64307	2.6900172	0.86630988	3584.5181
917.74414	2.692816	0.86781603	3592.0198
918.84521	2.6980076	0.86974847	3587.7693
919.94629	2.6991789	0.87163687	3591.9309
921.04736	2.7019839	0.87333763	3587.5835
922.14844	2.7070262	0.87521499	3588.0444
923.24951	2.7090349	0.8770054	3588.4558
924.35059	2.712209	0.87932295	3589.0559
925.45166	2.7161171	0.88130218	3592.3608
926.55273	2.7180338	0.88352019	3589.2642
927.65381	2.7229483	0.88621074	3589.1995
928.75488	2.7255096	0.88864356	3591.0483
929.85596	2.7290399	0.89130884	3581.8479
930.95703	2.7329259	0.8936606	3588.0449
932.05811	2.735419	0.89595866	3585.3074
933.15918	2.7381492	0.89832246	3588.2019
934.26025	2.743892	0.90054798	3588.8738
935.36133	2.7450733	0.90328783	3598.7917
936.4624	2.7495248	0.90595949	3593.2344
937.56348	2.7531505	0.90848249	3591.0979
938.66455	2.7571416	0.91097611	3591.3452
939.76563	2.7587707	0.91336632	3591.741
940.8667	2.7623997	0.91527438	3583.9299
941.96777	2.7662246	0.91710865	3581.7405
943.06885	2.7681708	0.91924483	3592.9924
944.16992	2.7718914	0.92138487	3592.3496
945.271	2.7737784	0.92339402	3581.0706
946.37207	2.7786889	0.92561156	3590.093
947.47314	2.7844634	0.92752421	3595.0134
948.57422	2.783927	0.92968416	3586.8135
949.67529	2.7888525	0.93199986	3590.9106
950.77637	2.7911537	0.93410689	3588.8855
951.87744	2.7984498	0.93591422	3589.9106
952.97852	2.8000388	0.9377737	3599.9055
954.07959	2.8012841	0.94025797	3596.2368
955.18066	2.8064537	0.94212711	3593.4243
956.28174	2.8082824	0.94391882	3587.8799
957.38281	2.8092978	0.94629502	3591.1338
958.48389	2.8149822	0.94819838	3594.0728
959.58496	2.8175554	0.94996613	3590.0334
960.68604	2.8226187	0.95156598	3588.092
961.78711	2.8245382	0.95378232	3594.3257
962.88818	2.8266251	0.95564324	3587.6089
963.98926	2.8315396	0.9572733	3597.7451
965.09033	2.8368373	0.95941305	3597.5737
966.19141	2.8412261	0.96132714	3600.7332
967.29248	2.8421993	0.96332961	3601.3455
968.39355	2.842838	0.96535325	3589.2227
969.49463	2.8483596	0.96717489	3589.0703
970.5957	2.8523376	0.96872926	3589.6675
971.69678	2.8542957	0.97042608	3589.9534
972.79785	2.8603847	0.97208303	3589.8506
973.89893	2.8616941	0.97432965	3595.782
975	2.8651838	0.97624964	3590.4453
976.10107	2.8683467	0.97813886	3598.4988
977.20215	2.8707495	0.98021978	3592.0144
978.30322	2.8754535	0.98187894	3591.9358
979.4043	2.8801708	0.98373312	3597.5027
980.50537	2.8821492	0.98541695	3593.6116
981.60645	2.8836668	0.9873122	3590.4075
982.70752	2.8885186	0.98911095	3594.0828
983.80859	2.8920324	0.99087554	3588.7129
984.90967	2.8941777	0.99298596	3593.8162
986.01074	2.9000049	0.99490756	3595.7756
987.11182	2.9007258	0.99670064	3587.915
988.21289	2.9025993	0.99851036	3583.5422
989.31396	2.9068217	1.0001774	3592.8438
990.41504	2.9120045	1.0021589	3592.6643
991.51611	2.9129808	1.0038358	3581.1411
992.61719	2.9179873	1.0053923	3588.5498
993.71826	2.9208324	1.0069325	3590.7441
994.81934	2.9267387	1.0083731	3590.1553
995.92041	2.9270983	1.0100754	3592.0715
997.02148	2.9292812	1.0113412	3590.5142
998.12256	2.933181	1.0134349	3596.7256
999.22363	2.9351528	1.0151607	3591.6365
1000.3247	2.9440732	1.017045	3595.0205
1001.4258	2.9424241	1.0188572	3588.656
1002.5269	2.9476125	1.0204006	3592.4839
1003.6279	2.9487216	1.0220087	3583.4324
1004.729	2.9558523	1.0236506	3586.123
1005.8301	2.9590271	1.0254136	3597.2021
1006.9312	2.9625161	1.0269186	3585.1072
1008.0322	2.9637437	1.0286884	3593.5156
1009.1333	2.967078	1.0305333	3594.0671
1010.2344	2.9692008	1.0326287	3590.6106
1011.3354	2.9724483	1.0346559	3587.9666
1012.4365	2.9798687	1.0366119	3590.0891
1013.5376	2.9828544	1.0383949	3590.0522
1014.6387	2.9825397	1.0401624	3586.3818
1015.7397	2.9862366	1.0424014	3589.7642
1016.8408	2.9916487	1.0443083	3581.3486
1017.9419	2.9909313	1.0461117	3582.3201
1019.043	2.9974096	1.0480608	3592.1658
1020.144	3.0005958	1.0500771	3587.1306
1021.2451	3.0017476	1.0519143	3580.353
1022.3462	3.007272	1.0537922	3582.5679
1023.4473	3.0097299	1.056002	3587.2295
1024.5483	3.0142961	1.0582736	3589.4014
1025.6494	3.0141661	1.0603626	3581.7891
1026.7505	3.0195153	1.0624802	3583.259
1027.8516	3.0248814	1.0644398	3588.9451
1028.9526	3.0262065	1.0665103	3583.0525
1030.0537	3.0307252	1.0684217	3582.5322
1031.1548	3.0333118	1.0707231	3586.2876
1032.2559	3.0392759	1.0726731	3590.9463
1033.3569	3.0398989	1.074852	3585.1973
1034.458	3.0446784	1.0771639	3583.3311
1035.5591	3.0489707	1.0790826	3587.7803
1036.6602	3.0490081	1.0812546	3586.4854
1037.7612	3.0564494	1.0835835	3585.4331
1038.8623	3.0563126	1.0856287	3580.3821
1039.9634	3.0597074	1.0878817	3577.2356
1041.0645	3.0665147	1.0897499	3582.8662
1042.1655	3.068434	1.0910733	3572.4866
1043.2666	3.0702505	1.0930275	3581.6624
1044.3677	3.070837	1.0951842	3583.8069
1045.4688	3.0759461	1.097577	3582.2283
1046.5698	3.0790472	1.0998214	3583.7644
1047.6709	3.0828836	1.1023934	3585.0391
1048.772	3.0878706	1.1050122	3583.3298
1049.873	3.0912354	1.1072837	3579.8245
1050.9741	3.0935495	1.1097542	3584.4822
1052.0752	3.0959589	1.1118575	3573.6543
1053.1763	3.0995426	1.1139628	3588.6123
1054.2773	3.1025875	1.1168332	3582.7844
1055.3784	3.1070025	1.1192664	3581.739
1056.4795	3.1091959	1.1218048	3576.8677
1057.5806	3.1122634	1.1239214	3576.9238
1058.6816	3.1139741	1.125823	3567.7021
1059.7827	3.1174593	1.1278172	3576.562
1060.8838	3.1230497	1.1301636	3583.144
1061.9849	3.1227987	1.1328912	3577.7937
1063.0859	3.1299336	1.1350412	3577.2695
1064.187	3.133019	1.1371876	3578.7969
1065.2881	3.132813	1.1396182	3575.2019
1066.3892	3.1369779	1.1417309	3570.1536
1067.4902	3.1437957	1.1439068	3579.9177
1068.5913	3.1436298	1.1459796	3569.5867
1069.6924	3.1498125	1.1484405	3574.6965
1070.7935	3.1515687	1.1509026	3569.5244
1071.8945	3.1556559	1.1531416	3575.1838
1072.9956	3.1575885	1.1556071	3572.5247
1074.0967	3.1625516	1.1576971	3576.5278
1075.1978	3.1666877	1.1601053	3568.605
1076.2988	3.1680899	1.1623616	3570.3232
1077.3999	3.1705422	1.1645961	3570.4436
1078.501	3.1759341	1.1678035	3576.5435
1079.6021	3.1821122	1.1701097	3569.6194
1080.7031	3.1822567	1.1725549	3572.0942
1081.8042	3.1851628	1.1750072	3566.7891
1082.9053	3.18731	1.1770822	3569.3726
1084.0063	3.1919384	1.1797019	3569.2334
1085.1074	3.1958861	1.1820762	3574.6812
1086.2085	3.1996803	1.184842	3570.0107
1087.3096	3.2023227	1.1875658	3572.5105
1088.4106	3.204138	1.1905569	3571.47
1089.5117	3.2069676	1.193113	3562.8352
1090.6128	3.2135966	1.1953999	3566.3806
1091.7139	3.215265	1.1978443	3567.406
1092.8149	3.2173784	1.2007098	3565.3315
1093.916	3.2214103	1.2033068	3562.8818
1095.0171	3.2252383	1.2055961	3562.3311
1096.1182	3.2293611	1.2082748	3565.4919
1097.2192	3.2306643	1.2109833	3563.3928
1098.3203	3.2352135	1.2134922	3562.5398
1099.4214	3.2384832	1.2158397	3560.4326
1100.5225	3.2423756	1.218138	3561.667
1101.6235	3.2450449	1.2203442	3561.2351
1102.7246	3.2465436	1.2224925	3554.2568
1103.8257	3.2511616	1.2247578	3557.7266
1104.9268	3.2521963	1.2271986	3552.7886
1106.0278	3.258894	1.2295582	3564.292
1107.1289	3.2642026	1.2323993	3561.4871
1108.23	3.2654083	1.2354585	3557.1277
1109.3311	3.2670882	1.2384932	3557.7515
1110.4321	3.2700181	1.2416712	3559.1157
1111.5332	3.273859	1.2452334	3553.594
1112.6343	3.2764561	1.2483622	3553.156
1113.7354	3.2792208	1.2512051	3553.1121
1114.8364	3.285938	1.2540764	3555.012
1115.9375	3.2886267	1.2566061	3545.2659
1117.0386	3.2908363	1.2592762	3551.8591
1118.1396	3.2961478	1.2624022	3556.4114
1119.2407	3.2987728	1.2660885	3552.082
1120.3418	3.301018	1.269706	3550.4248
1121.4429	3.3063531	1.2724218	3551.0532
1122.5439	3.3042986	1.2749382	3547.3916
1123.645	3.3128891	1.2775	3550.8455
1124.7461	3.3135757	1.2797102	3544.7495
1125.8472	3.3172457	1.2821652	3551.5352
1126.9482	3.322087	1.2851557	3548.1729
1128.0493	3.3243172	1.2880349	3545.6282
1129.1504	3.3293848	1.2908547	3545.5137
1130.2515	3.3288467	1.2934507	3539.2192
1131.3525	3.3332553	1.2962703	3543.7776
1132.4536	3.3361893	1.2990627	3541.4905
1133.5547	3.3427036	1.3017266	3539.1443
1134.6558	3.344991	1.3047825	3545.01
1135.7568	3.3478467	1.3078378	3535.6025
1136.8579	3.348491	1.3112113	3536.1951
1137.959	3.3526542	1.314037	3529.9534
1139.0601	3.3558786	1.3167348	3533.5398
1140.1611	3.360467	1.3193901	3528.6489
1141.2622	3.3621538	1.321792	3529.2585
1142.3633	3.368279	1.3246629	3532.7295
1143.4644	3.3711421	1.3280238	3530.2976
1144.5654	3.3737502	1.3308237	3531.2068
1145.6665	3.3784354	1.333596	3531.5334
1146.7676	3.3826742	1.3367751	3532.0461
1147.8687	3.3835733	1.3398693	3528.8237
1148.9697	3.3875041	1.3427726	3529.6047
1150.0708	3.3906243	1.3460833	3520.8611
1151.1719	3.3924475	1.3492076	3520.8501
1152.2729	3.3958895	1.3520913	3519.8801
1153.374	3.3989871	1.3553478	3516.2266
1154.4751	3.4031126	1.3582758	3517.2402
1155.5762	3.4068353	1.3617104	3519.7205
1156.6772	3.4105904	1.364382	3508.6997
1157.7783	3.4127581	1.3668603	3524.6287
1158.8794	3.4161177	1.3698354	3514.092
1159.9805	3.4204891	1.3731287	3515.6311
1161.0815	3.4233253	1.3764855	3513.2449
1162.1826	3.4272966	1.3793321	3510.1145
1163.2837	3.4292574	1.3822256	3510.804
1164.3848	3.4330711	1.3854406	3509.4705
1165.4858	3.4346449	1.3883713	3506.2639
1166.5869	3.4424424	1.391402	3506.6455
1167.688	3.441314	1.3937111	3502.4629
1168.7891	3.4479148	1.3962289	3510.4458
1169.8901	3.4477177	1.3997893	3510.8425
1170.9912	3.4530771	1.4033061	3506.2954
1172.0923	3.4566996	1.4065086	3498.4087
1173.1934	3.4579825	1.4090458	3489.9756
1174.2944	3.4629014	1.4113371	3506.8562
1175.3955	3.4643457	1.4140891	3494.866
1176.4966	3.4684052	1.4174073	3496.7754
1177.5977	3.4736712	1.421258	3497.675
1178.6987	3.4794993	1.4243752	3497.7856
1179.7998	3.4845617	1.427358	3493.6428
1180.9009	3.4830103	1.4306542	3496.8638
1182.002	3.4864576	1.4343107	3498.4443
1183.103	3.4884913	1.4374828	3484.7593
1184.2041	3.4899223	1.4402462	3481.8928
1185.3052	3.4952414	1.443162	3480.2869
1186.4063	3.4975858	1.4458224	3481.0354
1187.5073	3.5048189	1.4484503	3493.4233
1188.6084	3.5072212	1.451798	3482.1123
1189.7095	3.508564	1.4548514	3478.3108
1190.8105	3.512598	1.4573795	3480.1792
1191.9116	3.5142426	1.4605478	3478.7109
1193.0127	3.5175064	1.4639549	3476.6477
1194.1138	3.5238853	1.467461	3477.4224
1195.2148	3.5228102	1.4706379	3467.4163
1196.3159	3.5264585	1.4737928	3469.439
1197.417	3.5336692	1.4776204	3473.0293
1198.5181	3.535929	1.4809489	3467.1265
1199.6191	3.538836	1.4844421	3461.3215
1200.7202	3.5460401	1.4876112	3465.4998
1201.8213	3.5485427	1.4911364	3467.0125
1202.9224	3.5501277	1.4944402	3458.4263
1204.0234	3.5519981	1.4975495	3460.6252
1205.1245	3.558022	1.5014426	3458.3083
1206.2256	3.5600634	1.5060825	3460.7439
1207.3267	3.5627997	1.509622	3445.0095
1208.4277	3.5639589	1.5130818	3444.5022
1209.5288	3.5670128	1.5167178	3452.6753
1210.6299	3.5709972	1.5206118	3443.2261
1211.731	3.5750833	1.5233181	3433.7102
1212.832	3.5743918	1.526	3441.5427
1213.9331	3.5791647	1.5294085	3443.0598
1215.0342	3.5847046	1.533233	3440.4355
1216.1353	3.5891623	1.5363954	3430.3206
1217.2363	3.5929179	1.539941	3437.4189
1218.3374	3.5966899	1.5438209	3432.6113
1219.4385	3.5982556	1.5473255	3421.6511
1220.5396	3.6023386	1.5505136	3430.3911
1221.6406	3.6047943	1.5542312	3422.3738
1222.7417	3.6095424	1.5573508	3423.8535
1223.8428	3.6112888	1.5608429	3420.7749
1224.9438	3.6150427	1.5645334	3424.1846
1226.0449	3.6178129	1.5685751	3417.2961
1227.146	3.6215842	1.5728459	3415.7163
1228.2471	3.6264312	1.5766308	3414.9292
1229.3481	3.628119	1.5805185	3409.7637
1230.4492	3.631145	1.5837111	3403.0129
1231.5503	3.6366675	1.5868033	3406.999
1232.6514	3.6377947	1.5896574	3402.2817
1233.7524	3.6407769	1.5929255	3407.3206
1234.8535	3.6441684	1.5964978	3400.6272
1235.9546	3.647701	1.6000729	3400.7507
1237.0557	3.6545265	1.6035002	3397.759
1238.1567	3.6520133	1.6075559	3385.7861
1239.2578	3.6590457	1.6109055	3389.905
1240.3589	3.6583037	1.6149608	3386.4148
1241.46	3.664943	1.6182795	3375.7891
1242.561	3.6676049	1.6210603	3379.8147
1243.6621	3.6709623	1.6245085	3376.4028
1244.7632	3.6743002	1.6280509	3374.2878
1245.8643	3.6782825	1.6315179	3372.7429
1246.9653	3.6823874	1.6349075	3368.8535
1248.0664	3.6840093	1.6381201	3366.5186
1249.1675	3.6875267	1.6414372	3364.8816
1250.2686	3.6936131	1.6448532	3363.1458
1251.3696	3.6940372	1.6487787	3360.4888
1252.4707	3.6982515	1.6524054	3359.4395
1253.5718	3.700691	1.6562243	3351.1387
1254.6729	3.7035785	1.6593504	3341.5002
1255.7739	3.7062998	1.6619339	3337.0073
1256.875	3.7099307	1.664735	3344.8281
1257.9761	3.7129738	1.6686726	3345.176
1259.0771	3.7162459	1.6732365	3336.6375
1260.1782	3.7208598	1.67729	3332.522
1261.2793	3.7253718	1.6807069	3328.4736
1262.3804	3.7256055	1.6839267	3330.988
1263.4814	3.7278593	1.688248	3332.6631
1264.5825	3.7333076	1.6926426	3316.866
1265.6836	3.7368138	1.6965914	3313.344
1266.7847	3.741992	1.6999565	3308.1655
1267.8857	3.7460997	1.7032477	3307.9575
1268.9868	3.7457035	1.7073547	3303.0647
1270.0879	3.7497594	1.7112963	3296.4895
1271.189	3.7523961	1.714824	3293.4072
1272.29	3.75804	1.7181358	3288.2729
1273.3911	3.7594321	1.7218696	3293.2598
1274.4922	3.7654934	1.7259361	3287.0195
1275.5933	3.7672744	1.7302498	3273.7075
1276.6943	3.7710671	1.733984	3263.623
1277.7954	3.7740486	1.7369845	3253.1877
1278.8965	3.7782044	1.7403189	3259.6543
1279.9976	3.778851	1.7445523	3244.7639
1281.0986	3.7851546	1.7479025	3244.2988
1282.1997	3.7846859	1.7520251	3223.282
1283.3008	3.7905633	1.7556764	3218.5818
1284.4019	3.7929542	1.7597271	3212.887
1285.5029	3.7986038	1.7659242	3181.7932
1286.604	3.7992544	1.7721508	3139.1611
1287.605	3.8057742	1.7832959	3044.8047