File: datasets/am_bench_2022/raw_data/30-XY.01-2/specimen.dat
MTS793|MPT|ENU|1|2|.|/|:|1|0|0|A

Operator Information						Time:	39.544922	Sec	10/18/2021 10:32:41 AM
Operator	Nick Derimow
Project	AM Bench 2022 mini-tensile challenge
Specimen ID	30-XY.01-2
Material	PBF-L Inconel 625
Specimen Width	2.55	mm
Specimen Thickness	1.52	mm
Notes
Operator Information End

Data Acquisition						Time:	1040.5391	Sec	10/18/2021 10:49:22 AM
Time	Axial Displacement	Axial Extensometer	Axial Force
Sec	mm	mm	N
39.658936	-0.00096180959	0.00024492029	60.858459
40.76001	0.0052231317	0.00032962221	71.582092
41.861084	0.0045414595	0.00039057626	90.47303
42.962158	0.010425877	0.00050881266	108.76003
44.063232	0.013807346	0.00053286279	122.48043
45.164307	0.015198966	0.00059011753	135.0762
46.265381	0.016682785	0.0006297424	148.27496
47.366455	0.024546398	0.00087372347	173.49962
48.467529	0.024138255	0.0008380817	188.8494
49.568604	0.030287802	0.00094387715	215.69725
50.669678	0.032101035	0.0010665238	229.78569
51.770752	0.035234023	0.00113599	249.40446
52.871826	0.03916255	0.0013042475	279.00558
53.9729	0.041546203	0.0014257263	304.57031
55.073975	0.047312398	0.0016381061	322.62802
56.175049	0.046131816	0.0016438635	340.38824
57.276123	0.049765352	0.0016625086	360.41638
58.377197	0.05366417	0.0018917621	383.55093
59.478271	0.057505161	0.001993092	407.02322
60.579346	0.060617864	0.0021017478	434.80496
61.68042	0.06393382	0.0022805592	457.13483
62.781494	0.06916704	0.0024616192	484.39941
63.882568	0.070400693	0.0026206772	510.32214
64.983643	0.074453175	0.0027991894	536.96063
66.084717	0.074239478	0.0027895719	566.19006
67.185791	0.082813442	0.0029665299	587.6817
68.286865	0.086749144	0.0031584073	615.45929
69.387939	0.085774481	0.0032900621	649.69617
70.489014	0.089533202	0.0034385559	674.02258
71.590088	0.091021687	0.0035415257	702.17902
72.691162	0.097549461	0.0037069311	732.6897
73.792236	0.099696048	0.0037514458	759.32428
74.893311	0.10404937	0.0039842604	791.42102
75.994385	0.10664795	0.0041558021	817.97931
77.095459	0.10947827	0.0044101425	857.09216
78.196533	0.11277409	0.004629456	890.23132
79.297607	0.11699955	0.004660299	921.9679
80.398682	0.11978561	0.0048781536	949.81049
81.499756	0.12286958	0.0050080442	977.24805
82.60083	0.12690772	0.0051591955	1009.5849
83.701904	0.12846428	0.0053296122	1040.79
84.802979	0.13248172	0.0054844106	1080.1293
85.904053	0.13710095	0.0056874841	1110.969
87.005127	0.13903466	0.0058278036	1138.9576
88.106201	0.14431305	0.0059348745	1163.4264
89.207275	0.14623857	0.00608675	1192.5768
90.30835	0.1524944	0.0063030557	1225.2749
91.409424	0.15357028	0.006509067	1257.2054
92.510498	0.159115	0.0067220647	1286.0491
93.611572	0.16075535	0.0067916079	1313.1744
94.712646	0.16173755	0.0069869733	1347.0115
95.813721	0.16480759	0.0071111405	1376.6538
96.914795	0.17189881	0.007250878	1402.5742
98.015869	0.16923589	0.0073755244	1438.5735
99.116943	0.17741954	0.0076385154	1472.8915
100.21802	0.17647295	0.0077715204	1505.8798
101.31909	0.18090141	0.0079633007	1537.2709
102.42017	0.18476689	0.0081090955	1564.6483
103.52124	0.18635432	0.0081712008	1579.4739
104.62231	0.19207089	0.0083706314	1614.0452
105.72339	0.19643937	0.0084904376	1638.2676
106.82446	0.1987595	0.008660771	1673.0323
107.92554	0.20453267	0.008800962	1704.9735
109.02661	0.20484205	0.0089479331	1723.4116
110.12769	0.20815754	0.0090764472	1760.0697
111.22876	0.21379568	0.0092849871	1797.2686
112.32983	0.21267718	0.0094186533	1823.0573
113.43091	0.21834707	0.0096793817	1845.3232
114.53198	0.22454703	0.0097698607	1867.6058
115.63306	0.22700238	0.0099011855	1898.6244
116.73413	0.22818092	0.010063622	1922.9615
117.83521	0.22784674	0.010129101	1940.1934
118.93628	0.23802358	0.010336001	1970.7097
120.03735	0.23996876	0.010445857	1987.6029
121.13843	0.24265319	0.010620045	2016.2601
122.2395	0.24659115	0.010673469	2036.0901
123.34058	0.2509791	0.010863929	2061.5261
124.44165	0.25759739	0.010948347	2087.0425
125.54272	0.25565398	0.011236452	2100.4421
126.6438	0.25889939	0.011254315	2121.2312
127.74487	0.2635496	0.011458742	2144.8479
128.84595	0.26573145	0.011585461	2159.665
129.94702	0.269862	0.011697456	2176.6917
131.0481	0.27496067	0.011811781	2197.4624
132.14917	0.27504835	0.011991533	2216.0037
133.25024	0.27710688	0.012083061	2233.8254
134.35132	0.28638932	0.012256221	2255.8718
135.45239	0.28727138	0.012473936	2278.1421
136.55347	0.29154846	0.012617079	2289.9653
137.65454	0.2962496	0.012733947	2307.0234
138.75562	0.29641309	0.012876054	2321.8352
139.85669	0.29787028	0.013074968	2335.6057
140.95776	0.30390468	0.01322861	2353.3738
142.05884	0.3059265	0.013335931	2362.4045
143.15991	0.3105951	0.013536279	2378.3093
144.26099	0.31216988	0.01358889	2388.2722
145.36206	0.31637788	0.013804118	2403.282
146.46313	0.31999743	0.014000184	2419.6584
147.56421	0.32187322	0.014161025	2424.8809
148.66528	0.32665792	0.014412502	2449.1091
149.76636	0.32852918	0.014546691	2460.6587
150.86743	0.33286709	0.014752281	2472.1521
151.96851	0.33516291	0.014987968	2482.1665
153.06958	0.33644423	0.015083332	2487.8584
154.17065	0.34213442	0.015294436	2501.5532
155.27173	0.34749103	0.015482602	2517.8386
156.3728	0.35315841	0.015725009	2532.0032
157.47388	0.35161337	0.015856028	2526.9673
158.57495	0.35474551	0.016119506	2546.5474
159.67603	0.35855198	0.016462281	2567.7563
160.7771	0.36224979	0.016618779	2565.3875
161.87817	0.36477503	0.016844796	2575.4014
162.97925	0.36648479	0.017168619	2589.8701
164.08032	0.37432468	0.017520368	2600.9204
165.1814	0.3745603	0.017749732	2607.6353
166.28247	0.3796753	0.018017836	2619.6482
167.38354	0.38258189	0.018226318	2623.446
168.48462	0.3839106	0.018672574	2636.4634
169.58569	0.38599557	0.018918063	2642.0334
170.68677	0.39117411	0.019212054	2651.6934
171.78784	0.39562979	0.01957581	2657.814
172.88892	0.40025723	0.019848799	2676.7991
173.98999	0.40033159	0.020247104	2676.3269
175.09106	0.40483135	0.020544315	2683.4497
176.19214	0.40936595	0.02107721	2702.9536
177.29321	0.41120341	0.021497538	2708.2515
178.39429	0.41567859	0.021984255	2710.9497
179.49536	0.42009634	0.022256749	2717.7739
180.59644	0.42157608	0.022709668	2725.9453
181.69751	0.42567	0.023159899	2737.4026
182.79858	0.43160722	0.023874246	2749.104
183.89966	0.42947868	0.024370864	2753.9351
185.00073	0.43328857	0.025114603	2757.1008
186.10181	0.43626618	0.025533352	2763.2554
187.20288	0.44108763	0.02626246	2769.9026
188.30396	0.4470056	0.026790172	2783.8928
189.40503	0.44850582	0.027564831	2790.7454
190.5061	0.45317179	0.028140748	2796.6934
191.60718	0.4525854	0.028952729	2798.344
192.70825	0.45609492	0.029663866	2797.5007
193.80933	0.46175823	0.030306859	2805.9209
194.9104	0.46552676	0.031047765	2819.0608
196.01147	0.46748444	0.031747431	2825.2407
197.11255	0.46999478	0.032558978	2830.1951
198.21362	0.47727793	0.03352407	2831.9761
199.3147	0.4769462	0.034368269	2835.6104
200.41577	0.47990587	0.035097551	2835.9333
201.51685	0.48311093	0.035819694	2837.6899
202.61792	0.48581687	0.036715239	2845.3525
203.71899	0.49140358	0.037573028	2852.0962
204.82007	0.49284294	0.038520884	2856.9443
205.92114	0.49621519	0.039638735	2861.4448
207.02222	0.50159365	0.040659707	2861.1853
208.12329	0.50225484	0.041559782	2871.6201
209.22437	0.50635737	0.042559009	2870.6262
210.32544	0.51208484	0.043569386	2874.2798
211.42651	0.51556194	0.044680629	2884.3118
212.52759	0.51636904	0.045586158	2884.1101
213.62866	0.52230716	0.046850409	2896.9309
214.72974	0.52374935	0.048113309	2891.2026
215.83081	0.53104317	0.049278904	2891.1899
216.93188	0.53429639	0.050150432	2896.2236
218.03296	0.53541917	0.051269475	2911.3091
219.13403	0.53811878	0.052584279	2908.9558
220.23511	0.53849268	0.053620316	2908.7397
221.33618	0.54560316	0.054759026	2914.5256
222.43726	0.54538351	0.05604592	2916.1956
223.53833	0.54476458	0.057184409	2919.7056
224.6394	0.55456352	0.058512233	2917.1233
225.74048	0.55829048	0.059605666	2921.4937
226.84155	0.5596149	0.060950633	2924.6902
227.94263	0.56595021	0.062213551	2931.5181
229.0437	0.56619221	0.063512661	2937.3296
230.14478	0.56993878	0.06478779	2926.0757
231.24585	0.57318652	0.066019513	2936.3306
232.34692	0.57796508	0.067302644	2939.2629
233.448	0.57952619	0.068494335	2943.3899
234.54907	0.5850293	0.069703773	2944.2693
235.65015	0.58791244	0.071066752	2950.0757
236.75122	0.59054345	0.072209768	2946.2637
237.85229	0.59730846	0.073219888	2950.8311
238.95337	0.59678453	0.074466139	2954.0134
240.05444	0.60148346	0.075829968	2965.3494
241.15552	0.60676408	0.077009588	2960.9341
242.25659	0.60650855	0.07819546	2965.1733
243.35767	0.60795224	0.079432793	2963.551
244.45874	0.61421406	0.080898881	2974.1108
245.55981	0.61759001	0.082324259	2969.0654
246.66089	0.62298775	0.083767727	2978.2241
247.76196	0.62141353	0.08499603	2973.1428
248.86304	0.62352252	0.086435594	2979.1555
249.96411	0.63027686	0.087629013	2983.5098
251.06519	0.63343686	0.089060135	2985.1719
252.16626	0.63505584	0.090399362	2984.9824
253.26733	0.63745368	0.091999762	2987.3401
254.36841	0.64148062	0.093409173	2983.4585
255.46948	0.6450817	0.094589621	2988.7795
256.57056	0.64956897	0.095859081	2989.5898
257.67163	0.65250015	0.097381271	2989.9055
258.77271	0.65713942	0.098496258	3002.4045
259.87378	0.6568411	0.099967286	2996.855
260.97485	0.66557348	0.10137031	3005.4399
262.07593	0.66834235	0.10287576	3006.0469
263.177	0.66895247	0.1045327	3005.7571
264.27808	0.67253125	0.10573385	3007.968
265.37915	0.67616206	0.10706627	3001.5505
266.48022	0.68046314	0.1082885	3010.1213
267.5813	0.68292916	0.10955767	3011.7896
268.68237	0.68759716	0.11087603	3014.8645
269.78345	0.68901616	0.11209559	3014.405
270.88452	0.69407469	0.11359601	3024.2666
271.9856	0.69816917	0.11519884	3022.0386
273.08667	0.70062786	0.11635228	3017.4771
274.18774	0.7066409	0.11765122	3022.5947
275.28882	0.70491678	0.11876807	3022.1563
276.38989	0.70988286	0.12006308	3023.646
277.49097	0.71265131	0.12132971	3031.7312
278.59204	0.712924	0.12277497	3026.3611
279.69312	0.72055346	0.12411154	3033.198
280.79419	0.72310144	0.12549198	3036.6433
281.89526	0.72606063	0.12683189	3039.8118
282.99634	0.72721928	0.12842572	3034.4019
284.09741	0.73013568	0.12969364	3029.3755
285.19849	0.73529994	0.13110365	3041.0779
286.29956	0.73831612	0.13245375	3039.7891
287.40063	0.74238473	0.13377728	3045.6675
288.50171	0.74162114	0.1352108	3045.9968
289.60278	0.74675483	0.13678065	3050.0032
290.70386	0.75188279	0.13830969	3045.5125
291.80493	0.7558707	0.13973929	3054.5422
292.90601	0.75738543	0.14121282	3045.5405
294.00708	0.76433855	0.14259994	3059.5374
295.10815	0.7643013	0.14390039	3055.1304
296.20923	0.76800549	0.14524643	3057.4387
297.3103	0.77337825	0.14650886	3058.3513
298.41138	0.77484775	0.1478176	3057.3936
299.51245	0.78046781	0.14924328	3067.5369
300.61353	0.78099149	0.15042567	3062.467
301.7146	0.78738528	0.15178543	3076.4768
302.81567	0.78742933	0.15335327	3070.2954
303.91675	0.79166192	0.15485984	3068.2351
305.01782	0.79273999	0.15612341	3065.144
306.1189	0.79922539	0.1576796	3074.8586
307.21997	0.80344486	0.15911761	3071.6316
308.32104	0.80654109	0.16037174	3077.3848
309.42212	0.81163484	0.16148958	3078.7139
310.52319	0.8125335	0.16276565	3081.2427
311.62427	0.81520611	0.16402413	3081.1333
312.72534	0.82041371	0.16536249	3083.8154
313.82642	0.82043463	0.16694562	3085.1716
314.92749	0.82123923	0.16875933	3081.1531
316.02856	0.83021581	0.17013873	3088.4734
317.12964	0.8340382	0.17144357	3096.8186
318.23071	0.83510524	0.17281665	3088.894
319.33179	0.83699346	0.17391899	3084.9905
320.43286	0.84188831	0.17528059	3092.5334
321.53394	0.84408611	0.17664093	3092.4519
322.63501	0.84774953	0.17810786	3095.4617
323.73608	0.85120398	0.17957443	3095.2856
324.83716	0.85272425	0.18079463	3095.9072
325.93823	0.85667777	0.18236628	3106.3618
327.03931	0.86226571	0.18390778	3110.1177
328.14038	0.86640668	0.18519764	3112.0688
329.24146	0.86946636	0.18656346	3104.4995
330.34253	0.87066102	0.18804982	3112.7146
331.4436	0.87769336	0.18950386	3106.6968
332.54468	0.88000417	0.19091406	3120.3672
333.64575	0.88015699	0.19240229	3114.8071
334.74683	0.88291645	0.19382399	3106.9868
335.8479	0.88934827	0.1951625	3120.918
336.94897	0.89404786	0.19640562	3127.0193
338.05005	0.89258981	0.1976838	3115.9478
339.15112	0.89743215	0.19884115	3113.9141
340.2522	0.90102798	0.20028915	3128.5212
341.35327	0.90205711	0.20175655	3119.7661
342.45435	0.91014057	0.20306692	3123.6707
343.55542	0.91358638	0.20408875	3117.6187
344.65649	0.91430432	0.20522049	3120.9463
345.75757	0.91909808	0.2062822	3122.3306
346.85864	0.92016333	0.20773168	3135.8367
347.95972	0.92503601	0.20929396	3137.5269
349.06079	0.92645425	0.2108648	3130.7185
350.16187	0.93161863	0.21227129	3135.6235
351.26294	0.93415004	0.21340299	3127.7424
352.36401	0.93754482	0.21453431	3136.6853
353.46509	0.94225997	0.21585128	3140.1489
354.56616	0.94065624	0.21734475	3142.4688
355.66724	0.94734532	0.2187472	3139.6501
356.76831	0.94965255	0.22006494	3143.1008
357.86938	0.95562547	0.22145797	3142.0288
358.97046	0.95816541	0.2228236	3146.0283
360.07153	0.96131402	0.2241708	3144.6436
361.17261	0.9631654	0.22571555	3155.1904
362.27368	0.96682572	0.22713161	3155.2346
363.37476	0.96962285	0.2288243	3155.7395
364.47583	0.97509605	0.23009922	3152.3923
365.5769	0.97529131	0.23137191	3151.7461
366.67798	0.97838861	0.2326763	3155.8201
367.77905	0.98246115	0.23423669	3157.6855
368.88013	0.9900316	0.23551123	3161.6536
369.9812	0.98762047	0.23679291	3161.6277
371.08228	0.99572051	0.23811319	3165.3621
372.18335	1.0001055	0.23944969	3167.0266
373.28442	0.99933803	0.24089384	3159.1704
374.3855	1.0017213	0.24220975	3160.7563
375.48657	1.0057521	0.2436261	3169.874
376.58765	1.0105877	0.24501909	3166.4126
377.68872	1.0128213	0.24615967	3163.9495
378.78979	1.0165411	0.24731924	3172.8972
379.89087	1.0202316	0.24870451	3169.947
380.99194	1.0244561	0.24987312	3166.0371
382.09302	1.0279241	0.25101152	3170.4167
383.19409	1.0258641	0.25263336	3178.2903
384.29517	1.0341077	0.25422984	3178.6919
385.39624	1.0369179	0.25558642	3181.2124
386.49731	1.0385896	0.25686061	3179.6006
387.59839	1.0424882	0.25808188	3179.5935
388.69946	1.0423954	0.25924104	3173.1211
389.80054	1.0492321	0.26047945	3181.8372
390.90161	1.0544158	0.26196936	3188.8125
392.00269	1.0580343	0.26333931	3189.9973
393.10376	1.0581599	0.26475474	3186.6013
394.20483	1.0623968	0.26601174	3187.3794
395.30591	1.064415	0.26718622	3188.0063
396.40698	1.0677207	0.26872087	3198.5742
397.50806	1.0722581	0.27020043	3196.3296
398.60913	1.0771105	0.27155277	3195.438
399.71021	1.0752585	0.27308184	3199.075
400.81128	1.0828419	0.27452376	3201.7461
401.91235	1.0871544	0.27592006	3200.4197
403.01343	1.0905547	0.27716774	3198.7231
404.1145	1.0905482	0.27848217	3203.2847
405.21558	1.0969812	0.27991387	3208.4036
406.31665	1.0995913	0.28117296	3206.5874
407.41772	1.103212	0.28238019	3205.2351
408.5188	1.1072733	0.28386474	3210.1877
409.61987	1.1092032	0.28522581	3205.9595
410.72095	1.1115326	0.28651381	3206.1096
411.82202	1.1157182	0.28766721	3207.5278
412.9231	1.1210371	0.28883317	3216.1919
414.02417	1.1214447	0.29016709	3208.4475
415.12524	1.1242982	0.29150051	3210.8145
416.22632	1.1272647	0.29300511	3215.134
417.32739	1.1318675	0.29426494	3215.0017
418.42847	1.1332381	0.29562229	3216.7366
419.52954	1.1351069	0.29697934	3216.4541
420.63062	1.1409765	0.29826337	3214.7686
421.73169	1.1480722	0.29985455	3227.5569
422.83276	1.1484574	0.30122715	3224.3811
423.93384	1.1484648	0.30272466	3222.2329
425.03491	1.1558542	0.30411315	3224.2185
426.13599	1.1600697	0.30542681	3225.4568
427.23706	1.1606214	0.30678824	3229.074
428.33813	1.1636153	0.3080433	3227.9771
429.43921	1.1708343	0.3092272	3229.1077
430.54028	1.1710515	0.31067008	3237.1877
431.64136	1.1729478	0.31209308	3231.9751
432.74243	1.1774607	0.31346256	3233.0117
433.84351	1.1801108	0.31468225	3230.7073
434.94458	1.1847018	0.3159385	3235.0674
436.04565	1.188015	0.31732622	3232.7078
437.14673	1.1941699	0.3185606	3242.5801
438.2478	1.1941482	0.3202399	3244.5996
439.34888	1.1984166	0.32177556	3240.2324
440.44995	1.1991892	0.32304668	3242.4468
441.55103	1.2039943	0.32448089	3239.1797
442.6521	1.2087449	0.32570335	3241.627
443.75317	1.2118214	0.32718319	3249.9944
444.85425	1.2184097	0.32852182	3248.6169
445.95532	1.2179635	0.33010331	3254.1519
447.0564	1.2228045	0.33148041	3249.4209
448.15747	1.2231754	0.33276314	3241.7346
449.25854	1.2277485	0.33395654	3255.4243
450.35962	1.2294003	0.33531225	3252.8708
451.46069	1.2313	0.33643275	3249.4897
452.56177	1.2376024	0.33784339	3259.2571
453.66284	1.2392064	0.33894408	3253.2852
454.76392	1.2467037	0.34032348	3262.7048
455.86499	1.2468708	0.34158	3252.9431
456.96606	1.2503288	0.34294301	3261.8237
458.06714	1.2531099	0.34421256	3265.4829
459.16821	1.2598965	0.34566441	3266.3877
460.26929	1.2588385	0.34709057	3259.1399
461.37036	1.2639021	0.34829453	3263.2769
462.47144	1.2693704	0.34969315	3265.115
463.57251	1.2719526	0.35104889	3264.1719
464.67358	1.2723839	0.35230857	3266.8518
465.77466	1.2763946	0.3539328	3275.2249
466.87573	1.2793043	0.3553513	3266.3171
467.97681	1.2809635	0.35662508	3274.1626
469.07788	1.2885828	0.35801712	3274.1143
470.17896	1.2908278	0.35945553	3277.9224
471.28003	1.2935427	0.36081555	3272.5107
472.3811	1.2953262	0.36228549	3275.9319
473.48218	1.2995663	0.36326447	3271.9087
474.58325	1.3023243	0.36441877	3274.0166
475.68433	1.3076077	0.3657482	3280.9771
476.7854	1.3114716	0.36722317	3285.3027
477.88647	1.3126181	0.368637	3278.0806
478.98755	1.3172235	0.37009075	3282.3728
480.08862	1.3203321	0.37151575	3289.9656
481.1897	1.325472	0.37318325	3298.821
482.29077	1.3265181	0.37468162	3284.0059
483.39185	1.3316016	0.37584975	3277.2266
484.49292	1.333755	0.37693164	3290.1865
485.59399	1.3361038	0.3782908	3284.4719
486.69507	1.3407476	0.37926322	3283.9343
487.79614	1.3415537	0.3804228	3288.6533
488.89722	1.3491901	0.38156614	3289.979
489.99829	1.3514611	0.38272637	3290.8015
491.09937	1.3518792	0.38388118	3292.4619
492.20044	1.3544201	0.38541523	3295.9106
493.30151	1.3602251	0.38686174	3298.3572
494.40259	1.3645772	0.38850677	3301.5281
495.50366	1.3697172	0.38975111	3299.4492
496.60474	1.371026	0.39099094	3295.9275
497.70581	1.3715309	0.39227274	3295.2605
498.80688	1.3775258	0.39361915	3298.6548
499.90796	1.381501	0.39479691	3303.4409
501.00903	1.3841891	0.39599702	3302.9294
502.11011	1.3838029	0.39747918	3309.1042
503.21118	1.3894966	0.39885926	3306.4409
504.31226	1.3904446	0.40003434	3301.7556
505.41333	1.3960893	0.40128148	3304.3193
506.5144	1.4000871	0.40276447	3308.9849
507.61548	1.4034154	0.40439773	3316.9714
508.71655	1.4046745	0.40592998	3316.5491
509.81763	1.4089221	0.40741706	3306.5435
510.9187	1.4127728	0.40849051	3308.9441
512.01978	1.4148892	0.40997967	3311.8391
513.12085	1.4194782	0.41124368	3314.5181
514.22192	1.4218814	0.41248122	3316.4932
515.323	1.4287351	0.41408882	3324.165
516.42407	1.4286319	0.41541362	3317.978
517.52515	1.4342041	0.41690108	3321.9883
518.62622	1.4343692	0.41818649	3314.9045
519.72729	1.439657	0.41951197	3323.1099
520.82837	1.4426467	0.42087421	3325.1372
521.92944	1.4485953	0.42205897	3327.8667
523.03052	1.4471357	0.42331916	3322.1443
524.13159	1.4558042	0.42462426	3331.1772
525.23267	1.4550134	0.42581597	3322.728
526.33374	1.4574649	0.42714283	3328.0649
527.43481	1.4617704	0.42839095	3332.3335
528.53589	1.4628389	0.42988086	3327.0867
529.63696	1.4700207	0.43122417	3331.6799
530.73804	1.4720534	0.43275267	3336.3101
531.83911	1.4738374	0.43403742	3331.8208
532.94019	1.4763061	0.43524265	3329.0771
534.04126	1.4818684	0.43663931	3335.1946
535.14233	1.4866337	0.43808082	3340.0112
536.24341	1.4901123	0.43921304	3329.5759
537.34448	1.4909443	0.44054133	3331.9548
538.44556	1.4952337	0.44174421	3338.1731
539.54663	1.4972131	0.44314784	3343.1714
540.64771	1.4998699	0.44465265	3339.8794
541.74878	1.5058342	0.44615823	3345.0164
542.84985	1.5086502	0.44743904	3341.6096
543.95093	1.5092763	0.44877622	3343.908
545.052	1.51533	0.45002535	3348.6697
546.15308	1.5170965	0.45149651	3348.8984
547.25415	1.5195624	0.45306709	3349.7761
548.35522	1.5257404	0.45441556	3345.7236
549.4563	1.5286909	0.45571178	3349.156
550.55737	1.531747	0.45716852	3354.8572
551.65845	1.5348738	0.45864496	3350.418
552.75952	1.5389078	0.46003214	3353.0415
553.8606	1.5416137	0.46139064	3349.8491
554.96167	1.5477847	0.46266073	3354.9897
556.06274	1.5496182	0.46403673	3358.4788
557.16382	1.5537577	0.46522737	3350.2234
558.26489	1.5558106	0.46632761	3349.8757
559.36597	1.5574439	0.46738905	3354.3525
560.46704	1.5635459	0.46860722	3357.1995
561.56812	1.5642596	0.4700883	3363.9155
562.66919	1.5679989	0.47158918	3359.9106
563.77026	1.5711128	0.473012	3366.9248
564.87134	1.5765862	0.47438696	3367.4575
565.97241	1.5793453	0.47577375	3361.3164
567.07349	1.5828414	0.47697487	3367.0503
568.17456	1.5822423	0.47799489	3354.2178
569.27563	1.5879796	0.47928104	3367.2815
570.37671	1.5930471	0.48071095	3381.0505
571.47778	1.5955975	0.48207003	3367.2185
572.57886	1.5958034	0.48350939	3365.4583
573.67993	1.5980632	0.48500022	3367.7454
574.78101	1.6046205	0.48638999	3371.821
575.88208	1.6088507	0.48782364	3377.375
576.98315	1.6114795	0.48941207	3373.0771
578.08423	1.616037	0.49085003	3373.3047
579.1853	1.6201069	0.49224564	3378.5786
580.28638	1.6211947	0.49355364	3374.8516
581.38745	1.6253592	0.49511194	3376.4111
582.48853	1.6251758	0.49640781	3369.6223
583.5896	1.6300352	0.49786538	3377.803
584.69067	1.6369945	0.49900237	3375.9988
585.79175	1.6358745	0.5005213	3374.9299
586.89282	1.6406981	0.50177312	3372.3184
587.9939	1.6448574	0.50298166	3379.7461
589.09497	1.6467414	0.50430369	3384.1538
590.19604	1.6525868	0.50587219	3390.8311
591.29712	1.6560483	0.50760549	3384.3101
592.39819	1.6570874	0.50897497	3386.9775
593.49927	1.6606003	0.51027393	3387.8508
594.60034	1.6644944	0.51159543	3390.2014
595.70142	1.6662123	0.51287442	3385.8235
596.80249	1.6687998	0.51426327	3386.0352
597.90356	1.6761401	0.51566088	3391.8345
599.00464	1.6765543	0.51686817	3384.3982
600.10571	1.6798069	0.51831526	3392.5979
601.20679	1.6854838	0.51971012	3395.2834
602.30786	1.6870334	0.52079219	3386.8484
603.40894	1.6888695	0.52220666	3392.5833
604.51001	1.6932731	0.52381229	3397.9194
605.61108	1.6991396	0.525181	3398.9839
606.71216	1.7008828	0.52651417	3396.0852
607.81323	1.7026454	0.52771854	3394.7065
608.91431	1.7093844	0.52902609	3393.9299
610.01538	1.7127166	0.53046209	3406.1145
611.11646	1.7139004	0.53198439	3403.3311
612.21753	1.7171925	0.53331518	3396.4585
613.3186	1.7198147	0.53482687	3405.7488
614.41968	1.7244846	0.53660321	3407.2463
615.52075	1.7254362	0.53798175	3395.8064
616.62183	1.7304788	0.53931969	3405.3594
617.7229	1.7346437	0.54076385	3404.6736
618.82397	1.7359418	0.54230309	3407.5027
619.92505	1.7420747	0.54356188	3408.197
621.02612	1.7429811	0.54484069	3408.8901
622.1272	1.7439736	0.54639208	3407.0642
623.22827	1.7497395	0.5478853	3410.0571
624.32935	1.7542324	0.54941988	3408.9849
625.43042	1.7573922	0.5507642	3406.0928
626.53149	1.7581908	0.55203587	3402.3831
627.63257	1.7634426	0.55311447	3413.7161
628.73364	1.763893	0.55450559	3408.2253
629.83472	1.7682238	0.55566794	3404.5869
630.93579	1.7756184	0.55671924	3413.459
632.03687	1.776004	0.55793107	3416.8984
633.13794	1.7778218	0.55910832	3413.0735
634.23901	1.7814432	0.56063825	3419.001
635.34009	1.785726	0.562181	3422.0286
636.44116	1.7908162	0.56377053	3417.1218
637.54224	1.789541	0.56491679	3415.6377
638.64331	1.7958584	0.56626236	3420.5864
639.74438	1.7967157	0.56756699	3419.6008
640.84546	1.8041427	0.56902695	3425.1719
641.94653	1.80741	0.57035345	3424.8811
643.04761	1.8075087	0.57175314	3422.002
644.14868	1.8133845	0.57331556	3425.7417
645.24976	1.8170851	0.57451981	3417.8005
646.35083	1.8180492	0.57577407	3419.5408
647.4519	1.8230436	0.57742465	3431.2422
648.55298	1.8264399	0.57900995	3431.9768
649.65405	1.8284534	0.5807969	3430.405
650.75513	1.831705	0.58218181	3423.4026
651.8562	1.8325106	0.58373976	3424.6338
652.95728	1.8373653	0.5851441	3425.7378
654.05835	1.8418982	0.58639121	3424.23
655.15942	1.848753	0.5878281	3431.5745
656.2605	1.8474501	0.58915311	3431.8706
657.36157	1.8518859	0.59077489	3431.8479
658.46265	1.852283	0.5922066	3431.4639
659.56372	1.8572358	0.59364814	3434.4683
660.66479	1.8614395	0.59493923	3427.1106
661.76587	1.8675231	0.59632289	3442.0139
662.86694	1.8701055	0.59781063	3437.9438
663.96802	1.8709756	0.59936798	3440.0811
665.06909	1.8732151	0.60066307	3427.4204
666.17017	1.8754709	0.60204947	3433.5759
667.27124	1.8805324	0.60329765	3434.0132
668.37231	1.8842679	0.60477275	3441.9116
669.47339	1.8904302	0.60606271	3438.3765
670.57446	1.8918327	0.60762465	3449.6409
671.67554	1.8957868	0.60912567	3447.5918
672.77661	1.8992808	0.6105808	3446.6904
673.87769	1.9019769	0.6121673	3446.1604
674.97876	1.9056761	0.61380523	3445.4739
676.07983	1.9079914	0.61516452	3440.4795
677.18091	1.909866	0.61650831	3448.8621
678.28198	1.9163384	0.61784816	3444.2114
679.38306	1.9177943	0.61911023	3448.1348
680.48413	1.91996	0.62072027	3449.6807
681.58521	1.9233695	0.62205076	3446.0256
682.68628	1.9296398	0.62349683	3453.1375
683.78735	1.9308603	0.62487173	3450.5823
684.88843	1.9344941	0.62631226	3446.905
685.9895	1.9374759	0.62769419	3451.4956
687.09058	1.9426881	0.62925273	3459.4333
688.19165	1.9433942	0.63065445	3447.0261
689.29272	1.9469993	0.63199043	3454.5842
690.3938	1.9521621	0.63346803	3460.9084
691.49487	1.9548204	0.63499981	3451.8462
692.59595	1.9537871	0.63630217	3451.5393
693.69702	1.9605863	0.63782442	3455.8767
694.7981	1.966836	0.63930571	3457.5969
695.89917	1.9703175	0.6407252	3455.012
697.00024	1.9733636	0.64209574	3457.8467
698.10132	1.9731932	0.6434648	3454.7754
699.20239	1.9779497	0.64495242	3458.3779
700.30347	1.981676	0.6463874	3457.332
701.40454	1.9857481	0.64767247	3457.7502
702.50562	1.9902372	0.64903933	3464.6646
703.60669	1.9908088	0.65029103	3458.8062
704.70776	1.9915138	0.65154707	3458.9187
705.80884	1.994962	0.6529476	3459.3914
706.90991	2.0010417	0.65457684	3470.0603
708.01099	2.0029924	0.65625936	3463.0601
709.11206	2.0034087	0.6578564	3463.4448
710.21313	2.0100303	0.65938777	3466.2771
711.31421	2.0133491	0.66080302	3460.7292
712.41528	2.017874	0.66216803	3462.7786
713.51636	2.0206673	0.66364229	3469.8701
714.61743	2.0256777	0.66515654	3474.5535
715.71851	2.0271955	0.66664362	3466.4805
716.81958	2.0320764	0.66845375	3475.1021
717.92065	2.0354173	0.67018855	3473.4338
719.02173	2.0357783	0.67200011	3473.7163
720.1228	2.038126	0.6737687	3470.5764
721.22388	2.0458603	0.67534751	3477.1475
722.32495	2.0462613	0.6769374	3478.4539
723.42603	2.0496373	0.67827809	3467.8723
724.5271	2.0517371	0.67942715	3467.0747
725.62817	2.0556455	0.68063092	3468.5022
726.72925	2.0622711	0.68194062	3477.7024
727.83032	2.067126	0.68337464	3482.7769
728.9314	2.0689368	0.68493366	3478.0293
730.03247	2.0713105	0.6863907	3477.0505
731.13354	2.0764771	0.68792993	3477.8606
732.23462	2.0777781	0.68933618	3478.4302
733.33569	2.0832324	0.6906302	3477.2922
734.43677	2.0841644	0.6920855	3481.9829
735.53784	2.0856035	0.69346189	3481.3918
736.63892	2.089721	0.69501233	3479.4158
737.73999	2.0969536	0.69670486	3484.1509
738.84106	2.0969818	0.69824231	3478.0642
739.94214	2.0988863	0.69953984	3487.1565
741.04321	2.1028767	0.70129633	3491.3245
742.14429	2.1053309	0.70291883	3480.8816
743.24536	2.1074171	0.7044093	3482.2205
744.34644	2.1130705	0.70570707	3479.0264
745.44751	2.1164756	0.70707458	3481.3923
746.54858	2.1194079	0.70873839	3487.8044
747.64966	2.1236272	0.71028882	3492.7744
748.75073	2.1267917	0.71189636	3487.072
749.85181	2.128793	0.71347231	3482.1799
750.95288	2.1331737	0.71491432	3487.2964
752.05396	2.1358936	0.71632689	3488.3076
753.15503	2.1396887	0.7179535	3490.3008
754.2561	2.1449292	0.71958899	3494.4817
755.35718	2.1467884	0.72117305	3490.0444
756.45825	2.1488013	0.72258961	3486.7419
757.55933	2.1530502	0.72411108	3488.4941
758.6604	2.1554964	0.72591203	3496.7378
759.76147	2.1587908	0.72747248	3486.9302
760.86255	2.1629198	0.72890788	3489.4561
761.96362	2.1675313	0.7303713	3491.4451
763.0647	2.1689813	0.73170537	3491.1909
764.16577	2.1753578	0.73329651	3494.9309
765.26685	2.1755021	0.73495412	3494.3213
766.36792	2.1798949	0.73659259	3497.9985
767.46899	2.1804845	0.73847264	3501.1138
768.57007	2.1848745	0.7400012	3494.1152
769.67114	2.1884751	0.74149525	3491.666
770.77222	2.1936753	0.74293786	3500.0457
771.87329	2.1934087	0.74430561	3494.0559
772.97437	2.2016146	0.7458204	3496.0952
774.07544	2.2029297	0.74735665	3500.7009
775.17651	2.2071307	0.74889892	3503.0125
776.27759	2.2093129	0.7504738	3494.521
777.37866	2.2114809	0.75198311	3499.051
778.47974	2.2151997	0.753362	3502.667
779.58081	2.2178845	0.75489026	3496.7134
780.68188	2.2219303	0.75631565	3497.6963
781.78296	2.2254617	0.7575888	3505.2021
782.88403	2.2293503	0.7593596	3505.5925
783.98511	2.2329457	0.76106006	3508.188
785.08618	2.2345095	0.76260078	3504.5205
786.18726	2.2403567	0.76414353	3505.7825
787.28833	2.241539	0.76565117	3500.615
788.3894	2.243762	0.76732165	3506.7961
789.49048	2.2473686	0.76896179	3503.427
790.59155	2.2547584	0.77059251	3511.7815
791.69263	2.2529221	0.77221453	3507.9224
792.7937	2.257477	0.77361387	3499.8206
793.89478	2.2595212	0.77543205	3505.52
794.99585	2.2661655	0.77698374	3511.498
796.09692	2.2703013	0.77868623	3512.5603
797.198	2.2742698	0.78037119	3511.1492
798.29907	2.2744937	0.78182143	3506.5791
799.40015	2.277802	0.78329408	3509.3694
800.50122	2.2801645	0.78480941	3503.4475
801.60229	2.28579	0.78642827	3508.512
802.70337	2.2874107	0.7883482	3518.5378
803.80444	2.291744	0.79032934	3514.147
804.90552	2.2982419	0.79193258	3511.0454
806.00659	2.2989821	0.79352766	3510.9404
807.10767	2.3016939	0.79496354	3509.811
808.20874	2.3049896	0.79660463	3512.4861
809.30981	2.3066514	0.79818916	3511.7883
810.41089	2.3144522	0.79971927	3518.1868
811.51196	2.3137763	0.80114824	3506.8928
812.61304	2.3166709	0.80252612	3513.3662
813.71411	2.3191693	0.80424428	3512.5027
814.81519	2.3248005	0.80596548	3512.3074
815.91626	2.3270595	0.8074553	3513.3687
817.01733	2.3317101	0.8090573	3511.2466
818.11841	2.3337357	0.81062561	3521.5347
819.21948	2.3361139	0.81229764	3517.3706
820.32056	2.3384099	0.81399649	3514.3101
821.42163	2.3451872	0.8159616	3524.2576
822.52271	2.3494942	0.81739652	3513.9475
823.62378	2.3507419	0.81912678	3518.0969
824.72485	2.3516793	0.82089955	3514.5215
825.82593	2.356971	0.8225733	3517.9912
826.927	2.3615203	0.82429612	3515.0022
828.02808	2.3632669	0.82603592	3518.8318
829.12915	2.3716691	0.82771164	3521.5454
830.23022	2.3691146	0.8291375	3518.9473
831.3313	2.3714404	0.83059347	3518.7585
832.43237	2.3782921	0.83267325	3524.4263
833.53345	2.3817608	0.83418602	3516.4275
834.63452	2.3851075	0.83564043	3523.9468
835.7356	2.3848147	0.83757621	3528.2881
836.83667	2.3913064	0.83917779	3518.0784
837.93774	2.3925867	0.8407594	3516.8474
839.03882	2.3977623	0.8421787	3527.5859
840.13989	2.3988326	0.84388816	3525.4812
841.24097	2.4018841	0.84584624	3527.5728
842.34204	2.4075282	0.84782869	3530.0142
843.44312	2.4098814	0.84967208	3527.375
844.54419	2.4141097	0.85136724	3523.7476
845.64526	2.4200053	0.85298467	3522.1882
846.74634	2.4224269	0.85451359	3522.6633
847.84741	2.4245238	0.85591018	3522.1519
848.94849	2.4267838	0.85763431	3526.135
850.04956	2.4289699	0.85963881	3528.7209
851.15063	2.4326727	0.86121249	3519.8669
852.25171	2.4358449	0.86275351	3521.8638
853.35278	2.4413087	0.86434132	3530.7454
854.45386	2.4448791	0.86607385	3524.1797
855.55493	2.4472742	0.86769938	3524.9722
856.65601	2.451473	0.86946309	3527.4333
857.75708	2.453799	0.87133604	3535.02
858.85815	2.4586461	0.87283373	3528.7766
859.95923	2.4611187	0.87441987	3530.8384
861.0603	2.4652693	0.87624687	3533.4111
862.16138	2.4672232	0.87794787	3528.8105
863.26245	2.4709127	0.8798402	3537.1777
864.36353	2.4723015	0.88175219	3528.3904
865.4646	2.475178	0.88365525	3530.6064
866.56567	2.4799585	0.88532859	3531.4829
867.66675	2.4860637	0.88736516	3536.8469
868.76782	2.4844286	0.88908982	3530.7063
869.8689	2.4923713	0.89098394	3533.1675
870.96997	2.492749	0.89281648	3533.5464
872.07104	2.4959881	0.89453429	3531.0735
873.17212	2.5007267	0.89624298	3535.1204
874.27319	2.5051267	0.89821273	3542.4395
875.37427	2.5050898	0.9001289	3531.8052
876.47534	2.5140247	0.90197927	3532.8672
877.57642	2.5143518	0.90341032	3533.4834
878.67749	2.5167334	0.90521514	3537.7363
879.77856	2.5217142	0.90697104	3539.1882
880.87964	2.5216925	0.90872592	3535.406
881.98071	2.5256841	0.91065925	3530.7727
883.08179	2.5283601	0.91245955	3533.2097
884.18286	2.5340548	0.91395062	3532.833
885.28394	2.5361793	0.91567284	3531.0999
886.38501	2.5393667	0.91767436	3538.7385
887.48608	2.5414073	0.91969109	3534.7593
888.58716	2.5471683	0.92136997	3533.8989
889.68823	2.548948	0.9230507	3534.6614
890.78931	2.5528672	0.92502648	3535.5278
891.89038	2.5547106	0.92673892	3529.7329
892.99146	2.5612144	0.92829233	3530.5115
894.09253	2.5619669	0.9301216	3542.8203
895.1936	2.5654821	0.93202817	3531.021
896.29468	2.5722749	0.93413633	3546.2041
897.39575	2.5718455	0.9358964	3532.4836
898.49683	2.5744894	0.93799865	3546.0339
899.5979	2.5821729	0.94028723	3547.5708
900.69897	2.5814197	0.9422943	3537.1311
901.80005	2.5878179	0.94426978	3537.0203
902.90112	2.5887914	0.94622511	3537.0786
904.0022	2.594038	0.94778222	3533.6289
905.10327	2.5935194	0.94969475	3537.5569
906.20435	2.6019354	0.95170462	3540.6724
907.30542	2.601903	0.95349109	3536.948
908.40649	2.6075032	0.95522237	3536.7097
909.50757	2.6059046	0.95742041	3546.55
910.60864	2.6140344	0.95975304	3546.1338
911.70972	2.6163962	0.96154779	3542.582
912.81079	2.6202807	0.96306324	3537.1362
913.91187	2.6244605	0.9648658	3536.7234
915.01294	2.624218	0.96677214	3544.2756
916.11401	2.6285651	0.96840066	3529.4644
917.21509	2.6348033	0.96998644	3543.0964
918.31616	2.6345229	0.97151697	3542.7776
919.41724	2.6374109	0.97339368	3545.0208
920.51831	2.6418102	0.97497988	3536.2512
921.61938	2.6443739	0.97678089	3545.3123
922.72046	2.6510646	0.9783904	3539.5876
923.82153	2.6490965	0.98031288	3542.4731
924.92261	2.6522617	0.98213774	3542.5493
926.02368	2.6599779	0.98406929	3544.1563
927.12476	2.6613548	0.98618913	3547.803
928.22583	2.6627474	0.98845023	3539.4893
929.3269	2.6680646	0.99045533	3546.9863
930.42798	2.6679153	0.99221778	3537.0984
931.52905	2.6770349	0.99447513	3547.7922
932.63013	2.6781301	0.99644941	3538.8647
933.7312	2.6828256	0.99871218	3550.8245
934.83228	2.6885083	1.0008811	3545.1313
935.93335	2.6878955	1.0028352	3540.2366
937.03442	2.692296	1.0048617	3547.8972
938.1355	2.6947854	1.0068141	3543.9199
939.23657	2.6983485	1.0085812	3540.8118
940.33765	2.7001708	1.0105218	3546.8159
941.43872	2.7058401	1.0123205	3540.8201
942.53979	2.704778	1.0142097	3540.0093
943.64087	2.7105761	1.0164101	3544.0796
944.74194	2.7118134	1.0187101	3539.8337
945.84302	2.7169006	1.0210216	3540.0544
946.94409	2.7236588	1.0229061	3542.6423
948.04517	2.7241688	1.0247029	3541.5403
949.14624	2.7248571	1.0267223	3546.8823
950.24731	2.730505	1.0287129	3549.8982
951.34839	2.735208	1.030775	3553.9629
952.44946	2.7387352	1.0327859	3544.5061
953.55054	2.7417483	1.0350364	3549.3528
954.65161	2.7463102	1.0371119	3539.9094
955.75269	2.7471275	1.0390824	3539.0166
956.85376	2.7485418	1.0410093	3539.8567
957.95483	2.7551439	1.04321	3546.9907
959.05591	2.756459	1.0453246	3543.5139
960.15698	2.7613552	1.0471511	3542.9739
961.25806	2.7629602	1.0491489	3541.1199
962.35913	2.7668247	1.0511959	3543.0613
963.46021	2.7682259	1.0536278	3550.7051
964.56128	2.7739723	1.0556411	3538.5476
965.66235	2.7737751	1.0577345	3543.1912
966.76343	2.7788024	1.059667	3542.0339
967.8645	2.7850044	1.0617514	3547.0896
968.96558	2.786509	1.0641705	3545.0359
970.06665	2.7934337	1.0665021	3549.2083
971.16772	2.7930455	1.0685403	3541.0188
972.2688	2.795644	1.0709783	3546.9802
973.36987	2.7992167	1.0731171	3536.0952
974.47095	2.8051805	1.0749505	3545.3135
975.57202	2.8050785	1.0770496	3546.771
976.6731	2.8105404	1.0791277	3551.1267
977.77417	2.8120954	1.0814713	3553.7842
978.87524	2.8158438	1.0838118	3542.3076
979.97632	2.8217375	1.0858704	3543.7769
981.07739	2.8231041	1.0883305	3548.1099
982.17847	2.8280447	1.0905097	3546.7498
983.27954	2.8274992	1.0927519	3538.6094
984.38062	2.8313942	1.0948079	3535.1428
985.48169	2.8363152	1.0967828	3547.7231
986.58276	2.8402116	1.0988873	3549.7498
987.68384	2.8432176	1.1011186	3547.2258
988.78491	2.8451738	1.1032827	3541.7817
989.88599	2.8512084	1.1055421	3549.2312
990.98706	2.8522584	1.107674	3542.5901
992.08813	2.8569846	1.1099803	3545.1194
993.18921	2.8590493	1.1119564	3542.999
994.29028	2.8600819	1.1141422	3543.6135
995.39136	2.8672094	1.116214	3542.9822
996.49243	2.8680608	1.1184777	3545.0015
997.59351	2.8738904	1.1207423	3546.0994
998.69458	2.8761084	1.1232755	3542.4102
999.79565	2.8787107	1.1261024	3538.2849
1000.8967	2.8822987	1.1283114	3540.6816
1001.9978	2.8845708	1.1307422	3546.0127
1003.0989	2.8874061	1.1331334	3542.4045
1004.2	2.8946183	1.1355711	3545.3896
1005.301	2.8931692	1.1377945	3547.541
1006.4021	2.8971822	1.1405914	3542.1829
1007.5032	2.9038835	1.1428907	3538.5488
1008.6042	2.9041145	1.1452575	3542.9866
1009.7053	2.9067135	1.147242	3533.4426
1010.8064	2.9109662	1.1494464	3545.1238
1011.9075	2.9173906	1.1519492	3548.3193
1013.0085	2.9221129	1.1544863	3543.2036
1014.1096	2.923413	1.1570437	3545.9827
1015.2107	2.9245257	1.1596843	3543.2722
1016.3118	2.9306862	1.1623579	3538.8855
1017.4128	2.9330668	1.1646011	3539.063
1018.5139	2.9353464	1.1670433	3540.9207
1019.615	2.9378614	1.1697196	3543.5251
1020.7161	2.9413707	1.1721027	3543.03
1021.8171	2.9468799	1.1743674	3543.1079
1022.9182	2.9484782	1.1769319	3540.9683
1024.0193	2.9527936	1.1791481	3534.3345
1025.1204	2.9552794	1.1816503	3539.5725
1026.2214	2.9608383	1.1841505	3539.1978
1027.3225	2.9610512	1.1867611	3540.2585
1028.4236	2.9661987	1.1891204	3539.9114
1029.5247	2.9681895	1.1916733	3547.658
1030.6257	2.973938	1.1941718	3536.502
1031.7268	2.9754586	1.1967809	3536.1516
1032.8279	2.9817851	1.1991242	3538.7407
1033.929	2.9831126	1.2018766	3534.3774
1035.03	2.9845109	1.2044713	3540.2827
1036.1311	2.9883089	1.206892	3536.9148
1037.2322	2.9927833	1.209533	3530.8491
1038.3333	2.9944236	1.2119658	3536.9307
1039.4343	2.9973464	1.214365	3534.5903
1040.5354	3.0009744	1.2165207	3531.6641
1041.6365	3.0061333	1.2191035	3536.3901
1042.7375	3.0064025	1.2218418	3540.2742
1043.8386	3.0114005	1.2248597	3537.8179
1044.9397	3.0161312	1.2273983	3536.478
1046.0408	3.0189416	1.2299389	3533.9653
1047.1418	3.0204742	1.2325579	3534.8782
1048.2429	3.0240321	1.2351743	3533.3967
1049.344	3.0277216	1.2381924	3537.562
1050.4451	3.0322099	1.2405782	3530.6138
1051.5461	3.0316401	1.2433152	3530.6538
1052.6472	3.0383756	1.2459756	3530.9441
1053.7483	3.0401533	1.2487524	3531.6321
1054.8494	3.0418086	1.2514786	3531.8708
1055.9504	3.0466254	1.2543277	3528.1392
1057.0515	3.0522511	1.2568777	3526.2593
1058.1526	3.0530834	1.259601	3530.5928
1059.2537	3.0549808	1.2622092	3525.6045
1060.3547	3.0609143	1.2642748	3521.2156
1061.4558	3.0636384	1.2665569	3526.3154
1062.5569	3.0678086	1.268967	3532.5574
1063.658	3.0689123	1.2721362	3526.7415
1064.759	3.0736964	1.2749805	3529.3142
1065.8601	3.0779505	1.2778586	3529.8687
1066.9612	3.0812888	1.2807064	3526.4248
1068.0623	3.0833585	1.2833782	3519.8835
1069.1633	3.0872755	1.2862616	3524.6467
1070.2644	3.0936449	1.2880026	3519.3057
1071.3655	3.0919974	1.2895324	3508.4912
1072.4666	3.0994058	1.2911729	3516.1003
1073.5676	3.098315	1.2929618	3520.1863
1074.6687	3.1038973	1.2957417	3528.3704
1075.7698	3.1064544	1.2985755	3521.8442
1076.8708	3.1120274	1.3015227	3529.0483
1077.9719	3.1118679	1.3048842	3520.7339
1079.073	3.1178725	1.3084428	3521.6169
1080.1741	3.1206906	1.3120258	3520.7085
1081.2751	3.1246841	1.315135	3518.417
1082.3762	3.1270607	1.3180176	3514.8733
1083.4773	3.1341035	1.3206602	3520.6641
1084.5784	3.1313088	1.3237568	3516.5789
1085.6794	3.1370578	1.3266397	3516.6982
1086.7805	3.138855	1.3298271	3515.4644
1087.8816	3.1436679	1.332984	3519.3931
1088.9827	3.1448381	1.3361398	3515.8179
1090.0837	3.152988	1.3390267	3517.0652
1091.1848	3.1562474	1.3418701	3516.8679
1092.2859	3.158915	1.3451762	3515.5115
1093.387	3.1618986	1.3476292	3510.4558
1094.488	3.1612623	1.3503366	3514.0552
1095.5891	3.167901	1.3531654	3510.0261
1096.6902	3.173089	1.3561717	3513.7332
1097.7913	3.1775715	1.3590047	3507.1086
1098.8923	3.1759095	1.3617723	3508.3242
1099.9934	3.1780193	1.3647467	3502.9597
1101.0945	3.18506	1.3676927	3505.4629
1102.1956	3.1858077	1.3711058	3509.6375
1103.2966	3.1887386	1.3743151	3495.9148
1104.3977	3.1938627	1.3773803	3501.8708
1105.4988	3.1987407	1.3802232	3503.8066
1106.5999	3.1979396	1.3832706	3503.1887
1107.7009	3.2009966	1.3862469	3501.1619
1108.802	3.2074621	1.3896605	3503.3699
1109.9031	3.2089021	1.3927523	3495.0613
1111.0042	3.2152426	1.3960596	3504.8518
1112.1052	3.2168486	1.3984551	3494.9202
1113.2063	3.2189438	1.4010881	3488.6057
1114.3074	3.2225742	1.4043081	3500.4194
1115.4084	3.2268031	1.4077872	3494.54
1116.5095	3.2306786	1.4115669	3498.6929
1117.6106	3.2331865	1.4153448	3490.6052
1118.7117	3.2361422	1.418431	3483.1311
1119.8127	3.2417343	1.4212893	3488.6182
1120.9138	3.2452426	1.4245433	3491.9077
1122.0149	3.2462714	1.4280857	3484.6729
1123.116	3.2471476	1.431168	3479.7117
1124.217	3.2552986	1.4342442	3483.6006
1125.3181	3.2552819	1.4373418	3479.3894
1126.4192	3.2609305	1.4404151	3484.9001
1127.5203	3.260854	1.4439888	3479.2869
1128.6213	3.264667	1.4473567	3479.6448
1129.7224	3.2711082	1.450784	3486.5969
1130.8235	3.274946	1.4540846	3468.1726
1131.9246	3.275744	1.4564505	3469.4797
1133.0256	3.2777019	1.4593602	3480.6755
1134.1267	3.278738	1.4624034	3469.6958
1135.2278	3.2851214	1.4652307	3470.8706
1136.3289	3.290709	1.4684943	3474.3208
1137.4299	3.2945118	1.471807	3474.5425
1138.531	3.2950304	1.4752463	3472.2021
1139.6321	3.2995467	1.4785311	3463.647
1140.7332	3.3030903	1.4816442	3464.5261
1141.8342	3.3059239	1.4853126	3469.5613
1142.9353	3.3090055	1.4888954	3460.5994
1144.0364	3.3109765	1.4921114	3452.248
1145.1375	3.3149166	1.494871	3461.4099
1146.2385	3.3173137	1.4982001	3453.5647
1147.3396	3.321712	1.5016315	3456.3794
1148.4407	3.3262372	1.5052898	3459.7656
1149.5417	3.3285971	1.5092015	3453.4087
1150.6428	3.3343303	1.5127982	3450.427
1151.7439	3.3342547	1.5166919	3442.8049
1152.845	3.3403931	1.5202938	3440.6853
1153.946	3.3411462	1.5236238	3441.2959
1155.0471	3.345376	1.5269212	3435.637
1156.1482	3.3483438	1.5299141	3433.8228
1157.2493	3.3524885	1.5329056	3432.1907
1158.3503	3.3560653	1.5365038	3440.1001
1159.4514	3.3590839	1.5401653	3433.6904
1160.5525	3.3632004	1.5434917	3427.0881
1161.6536	3.3640544	1.5466037	3423.9971
1162.7546	3.3706906	1.5494058	3430.6311
1163.8557	3.3718503	1.5526078	3423.303
1164.9568	3.3742738	1.5552429	3417.1389
1166.0579	3.3786948	1.5580004	3423.821
1167.1589	3.3846633	1.5615084	3427.9456
1168.26	3.382406	1.5642905	3415.5774
1169.3611	3.3898981	1.5679646	3428.5173
1170.4622	3.3942964	1.5717806	3423.5557
1171.5632	3.3930116	1.5754635	3409.7888
1172.6643	3.3991303	1.5788128	3411.5605
1173.7654	3.4043355	1.5821046	3409.8013
1174.8665	3.407831	1.5853722	3410.3147
1175.9675	3.4084513	1.5890826	3401.3108
1177.0686	3.4112425	1.5926089	3402.697
1178.1697	3.4132853	1.5960746	3394.9573
1179.2708	3.4205379	1.5993186	3392.2683
1180.3718	3.4201214	1.6026671	3389.8726
1181.4729	3.4255686	1.6060753	3393.2681
1182.574	3.4240417	1.6096593	3387.9067
1183.675	3.4317267	1.6133685	3387.3413
1184.7761	3.4378393	1.6163821	3378.7993
1185.8772	3.4393942	1.6198717	3385.5229
1186.9783	3.4391425	1.62326	3375.6306
1188.0793	3.4440432	1.6264979	3375.239
1189.1804	3.4480081	1.629657	3377.3242
1190.2815	3.4520175	1.6335198	3370.4597
1191.3826	3.4550803	1.6371493	3365.9216
1192.4836	3.4562643	1.6411371	3360.0569
1193.5847	3.4600577	1.6443582	3357.4177
1194.6858	3.4650302	1.6480523	3361.0569
1195.7869	3.4677496	1.6518041	3354.2271
1196.8879	3.4704738	1.655605	3355.5088
1197.989	3.4717779	1.6588026	3340.7883
1199.0901	3.4754591	1.6619637	3349.7554
1200.1912	3.4807601	1.6659005	3348.2856
1201.2922	3.4844213	1.6694926	3335.7859
1202.3933	3.4855571	1.6727402	3333.1484
1203.4944	3.4897416	1.6761451	3337.418
1204.5955	3.4915318	1.6794726	3320.5708
1205.6965	3.4980993	1.6823242	3322.0117
1206.7976	3.5002995	1.685123	3325.2837
1207.8987	3.5046217	1.6878624	3322.551
1208.9998	3.5089474	1.6914229	3323.282
1210.1008	3.5108325	1.6951146	3315.1553
1211.2019	3.5153897	1.6993113	3319.4187
1212.303	3.5189154	1.7029405	3306.9006
1213.4041	3.5206194	1.7064544	3308.572
1214.5051	3.5258503	1.7099448	3300.4541
1215.6062	3.5263381	1.7133057	3298.9358
1216.7073	3.5309677	1.7164963	3295.0139
1217.8083	3.5329759	1.720456	3296.251
1218.9094	3.5355434	1.7240813	3293.1587
1220.0105	3.5403991	1.7279925	3293.0083
1221.1116	3.5445666	1.7317932	3277.998
1222.2126	3.5466404	1.7354289	3274.8657
1223.3137	3.5523376	1.7387084	3270.4587
1224.4148	3.5526304	1.741943	3274.0601
1225.5159	3.5570812	1.7453516	3263.6499
1226.6169	3.5616791	1.7492177	3259.7051
1227.718	3.56422	1.7530572	3257.0549
1228.8191	3.5670078	1.7568781	3249.6907
1229.9202	3.568284	1.7601984	3248.571
1231.0212	3.5745673	1.7640961	3246.8076
1232.1223	3.5739853	1.7682016	3239.6013
1233.2234	3.5794556	1.7721264	3232.1589
1234.3245	3.5851381	1.7754799	3227.4968
1235.4255	3.5866966	1.779392	3225.7573
1236.5266	3.5901644	1.7827537	3219.5732
1237.6277	3.5940175	1.7863876	3217.2861
1238.7288	3.5958147	1.7902617	3203.9578
1239.8298	3.6026633	1.7934692	3207.7847
1240.9309	3.6012113	1.7970487	3197.5842
1242.032	3.6088881	1.8001062	3202.6682
1243.1331	3.6097252	1.8034691	3190.5457
1244.2341	3.6135323	1.8069632	3187.6267
1245.3352	3.6150069	1.8107481	3181.655
1246.4363	3.6193137	1.8143268	3176.7043
1247.5374	3.6255887	1.8175454	3170.3328
1248.6384	3.6242273	1.8213671	3165.6438
1249.7395	3.626271	1.8250802	3156.009
1250.8406	3.6326334	1.8286952	3150.3337
1251.9417	3.6333823	1.8323308	3144.717
1253.0427	3.6379724	1.8360027	3137.3262
1254.1438	3.6426132	1.8395904	3132.9875
1255.2449	3.646497	1.8437558	3126.0166
1256.3459	3.6475286	1.8476366	3118.3691
1257.447	3.6524549	1.8516632	3113.2681
1258.5481	3.6542525	1.8550662	3102.7534
1259.6492	3.6602681	1.8584813	3103.4866
1260.7502	3.6615531	1.863004	3099.6733
1261.8513	3.6685367	1.8675029	3090.0105
1262.9524	3.6702707	1.8716376	3072.5742
1264.0535	3.6730051	1.8759741	3063.5015
1265.1545	3.6746185	1.8796124	3056.1592
1266.2556	3.6813529	1.883232	3049.647
1267.3567	3.6822369	1.8869517	3039.7539
1268.4578	3.6866128	1.8910547	3033.325
1269.5588	3.685348	1.8949082	3013.8699
1270.6599	3.6960752	1.9005904	3001.9028
1271.761	3.6949637	1.9064772	2962.7234
1272.4617	3.6977315	1.9157461	2888.3105