File: datasets/am_bench_2022/raw_data/60-XY.15-1/specimen.dat
MTS793|MPT|ENU|1|2|.|/|:|1|0|0|A

Operator Information						Time:	11.977295	Sec	11/2/2021 9:13:38 AM
Operator	Nick Derimow
Project	AM Bench 2022 mini-tensile challenge
Specimen ID	60-XY.15-1
Material	PBF-L Inconel 625
Specimen Width	2.55	mm
Specimen Thickness	1.51	mm
Notes
Operator Information End

Data Acquisition						Time:	1012.9707	Sec	11/2/2021 9:30:19 AM
Time	Axial Displacement	Axial Extensometer	Axial Force
Sec	mm	mm	N
12.090576	0.00099637243	5.2023079e-05	56.308788
13.091553	0.0065603405	0.00012907335	71.267365
14.092529	0.0082271285	0.00032350054	85.144424
15.093506	0.01046838	0.00026639024	93.3517
16.094482	0.013695566	0.00036903447	105.77377
17.095459	0.019193148	0.00039685049	118.11672
18.096436	0.019345587	0.00030281473	126.60208
19.097412	0.023335379	0.00044298373	137.03389
20.098389	0.026478354	0.00045159325	155.90692
21.099365	0.033396035	0.00061471615	176.25804
22.100342	0.03400825	0.0006845225	188.58202
23.101318	0.035168342	0.00076560094	202.86357
24.102295	0.040073946	0.00091050187	225.3607
25.103271	0.042504363	0.00093960459	244.99359
26.104248	0.046182923	0.0010647018	266.00937
27.105225	0.050361212	0.0010510725	271.76276
28.106201	0.051404722	0.0012398734	293.84698
29.107178	0.055831753	0.0011986288	313.37366
30.108154	0.056759704	0.0013500289	323.22531
31.109131	0.059200928	0.0014148471	344.73392
32.110107	0.063123308	0.0015888641	359.34396
33.111084	0.064220093	0.0015862784	385.6803
34.112061	0.070470855	0.0017417845	408.05557
35.113037	0.070773475	0.0017880079	426.3602
36.114014	0.071406998	0.0020782575	451.12518
37.11499	0.078305371	0.0021024335	474.99533
38.115967	0.078003772	0.0022202602	499.28473
39.116943	0.081421301	0.0023190381	513.88318
40.11792	0.085601076	0.0023971212	543.97986
41.118896	0.0902059	0.0025316954	565.86664
42.119873	0.093001992	0.0025967893	592.31604
43.12085	0.096491493	0.0027760495	622.23743
44.121826	0.098322809	0.0029374738	649.36658
45.122803	0.10094475	0.0029691325	674.07098
46.123779	0.10248696	0.0031810615	696.79474
47.124756	0.10884647	0.0032775356	722.63806
48.125732	0.11095705	0.0034041654	751.22058
49.126709	0.1133991	0.0036065248	778.27765
50.127686	0.11716679	0.0036558339	805.20618
51.128662	0.12073389	0.0038331721	833.70935
52.129639	0.12358043	0.0038448551	855.41022
53.130615	0.12520665	0.0040068491	884.25238
54.131592	0.13078348	0.0042296085	918.67865
55.132568	0.13066465	0.0042940336	941.50629
56.133545	0.13711989	0.0045377933	975.94104
57.134521	0.13456817	0.0046850913	1001.6298
58.135498	0.14027372	0.0047578402	1022.725
59.136475	0.14112382	0.0048492029	1046.3904
60.137451	0.14582683	0.0049618962	1080.2231
61.138428	0.15239435	0.0051646745	1110.5739
62.139404	0.15369578	0.0052802116	1137.1764
63.140381	0.15379699	0.0053884452	1168.0815
64.141357	0.15896612	0.0055663879	1195.3878
65.142334	0.16037573	0.0056677945	1223.0391
66.143311	0.15955314	0.005820638	1250.311
67.144287	0.16690104	0.0059749847	1283.4094
68.145264	0.17195688	0.0060740402	1313.5192
69.14624	0.17345704	0.0061959974	1336.6881
70.147217	0.17528528	0.0063513732	1371.6812
71.148193	0.18062715	0.0064999377	1397.3906
72.14917	0.18115146	0.0065772012	1421.0801
73.150146	0.18359454	0.0066989544	1443.6713
74.151123	0.18878581	0.0067236223	1477.3839
75.1521	0.19115435	0.0070119789	1506.6594
76.153076	0.19450016	0.0070565455	1530.1761
77.154053	0.19723786	0.0072311363	1567.9888
78.155029	0.20065477	0.0074171135	1596.0654
79.156006	0.20423833	0.0074940328	1608.3967
80.156982	0.20491037	0.0075823767	1636.8785
81.157959	0.20860942	0.0077157472	1663.0797
82.158936	0.21127561	0.0078175273	1695.8644
83.159912	0.21596511	0.0080497973	1728.2852
84.160889	0.21791506	0.0081238486	1758.4863
85.161865	0.21932982	0.0082526412	1780.9658
86.162842	0.22280473	0.0083834911	1807.0239
87.163818	0.22973239	0.0084733469	1833.6072
88.164795	0.23044071	0.0085524917	1853.6068
89.165771	0.23141311	0.008641311	1879.1049
90.166748	0.23561415	0.0087820366	1903.7914
91.167725	0.23650563	0.0088859145	1924.6183
92.168701	0.24295509	0.0090658655	1951.6449
93.169678	0.24485196	0.0091881873	1974.6051
94.170654	0.24743067	0.0092602912	1995.4581
95.171631	0.25073427	0.0093579944	2019.356
96.172607	0.25352532	0.0094350902	2038.6908
97.173584	0.25601408	0.0095379688	2058.9805
98.174561	0.26187634	0.0096697658	2084.7854
99.175537	0.26358494	0.0096725887	2100.0044
100.17651	0.26497877	0.0099565806	2122.3948
101.17749	0.27121374	0.0098662339	2134.3784
102.17847	0.27003911	0.0099627357	2155.8054
103.17944	0.27845737	0.010223169	2181.4749
104.18042	0.28026572	0.010230931	2195.9426
105.1814	0.28154215	0.010405459	2219.8428
106.18237	0.28266189	0.010437012	2235.9812
107.18335	0.28844529	0.010584408	2256.7034
108.18433	0.2924279	0.010767501	2271.1123
109.1853	0.29528978	0.010822493	2290.1465
110.18628	0.29628655	0.010898101	2308.4661
111.18726	0.30434135	0.01100616	2318.624
112.18823	0.30134568	0.011180508	2330.1411
113.18921	0.30503365	0.011215954	2345.0771
114.19019	0.30725324	0.011363423	2366.5344
115.19116	0.3108896	0.011490709	2375.6816
116.19214	0.31474867	0.011676785	2391.3198
117.19312	0.31925109	0.011686562	2409.4482
118.19409	0.31920561	0.01191266	2415.5164
119.19507	0.32334107	0.012044957	2437.9668
120.19604	0.32596081	0.01212813	2441.5129
121.19702	0.32818732	0.012215293	2452.0073
122.198	0.33155221	0.012392677	2468.7068
123.19897	0.33335504	0.012500765	2474.4807
124.19995	0.34117112	0.012707255	2486.7861
125.20093	0.3428551	0.012883522	2505.7134
126.2019	0.34530494	0.013024985	2511.0393
127.20288	0.35022843	0.013270527	2527.6545
128.20386	0.35141495	0.013238687	2530.8035
129.20483	0.35436803	0.013472978	2551.7566
130.20581	0.35605568	0.013604742	2555.0642
131.20679	0.36112294	0.013801336	2565.7319
132.20776	0.36325482	0.014023784	2577.3894
133.20874	0.36741984	0.014091142	2585.7507
134.20972	0.36906281	0.014349307	2593.0361
135.21069	0.37240022	0.014538554	2603.5569
136.21167	0.37543994	0.014672392	2607.0583
137.21265	0.37934414	0.014845731	2617.7654
138.21362	0.38042104	0.015024112	2632.7646
139.2146	0.38379228	0.015384198	2638.6182
140.21558	0.3880623	0.015656495	2653.4072
141.21655	0.3882553	0.01584013	2653.7952
142.21753	0.39279345	0.016037917	2667.0415
143.21851	0.39481607	0.016346529	2670.9722
144.21948	0.40123218	0.016614191	2687.0803
145.22046	0.40148148	0.016982449	2700.0244
146.22144	0.40496585	0.017176487	2699.469
147.22241	0.40893167	0.017444776	2699.0059
148.22339	0.4085809	0.01784941	2718.2959
149.22437	0.41466427	0.01810183	2716.9585
150.22534	0.41718316	0.018514259	2729.74
151.22632	0.41871798	0.018936722	2739.2251
152.22729	0.42526108	0.019427652	2754.2827
153.22827	0.42736715	0.019780405	2753.1567
154.22925	0.42858702	0.020265076	2756.2876
155.23022	0.43110061	0.020753095	2771.26
156.2312	0.43664104	0.021223975	2775.1287
157.23218	0.4398762	0.021656213	2775.3323
158.23315	0.44059372	0.022075685	2783.6558
159.23413	0.44133094	0.022755248	2797.5579
160.23511	0.44620502	0.023232982	2798.1672
161.23608	0.44917467	0.023746831	2796.5291
162.23706	0.45301694	0.024276225	2810.1223
163.23804	0.45570773	0.024817862	2810.5205
164.23901	0.45780784	0.025466809	2823.9392
165.23999	0.4628934	0.026080614	2819.7283
166.24097	0.46429422	0.026647054	2825.7537
167.24194	0.46892038	0.02719418	2831.6641
168.24292	0.47008601	0.027921453	2839.052
169.2439	0.47119507	0.028574847	2842.9204
170.24487	0.47579747	0.029258659	2852.1199
171.24585	0.48156756	0.030064711	2847.3892
172.24683	0.484411	0.030559098	2855.6846
173.2478	0.48559609	0.031187024	2853.354
174.24878	0.49134979	0.032004863	2869.0042
175.24976	0.49195093	0.03294909	2876.2856
176.25073	0.49351829	0.033790525	2875.8394
177.25171	0.49824139	0.034670625	2878.7915
178.25269	0.50107217	0.035449356	2878.2947
179.25366	0.5054484	0.036351517	2887.8684
180.25464	0.50652707	0.037247118	2891.4038
181.25562	0.50908697	0.038102027	2892.0352
182.25659	0.51430959	0.039177567	2903.9255
183.25757	0.51791114	0.040146757	2906.7212
184.25854	0.51963091	0.040924795	2905.446
185.25952	0.5218091	0.041848861	2916.6523
186.2605	0.52556598	0.042661116	2909.2356
187.26147	0.52826744	0.043609634	2914.9358
188.26245	0.53305256	0.044528659	2922.4614
189.26343	0.53327715	0.045554206	2916.6899
190.2644	0.53640062	0.046604615	2925.2573
191.26538	0.53922504	0.047540866	2929.834
192.26636	0.54393893	0.04866809	2933.0061
193.26733	0.54891366	0.049560484	2932.4456
194.26831	0.54965901	0.050514232	2943.2437
195.26929	0.5535171	0.051691037	2949.9487
196.27026	0.55544078	0.052627519	2945.5601
197.27124	0.56177038	0.05389579	2945.428
198.27222	0.56446201	0.054992042	2956.1982
199.27319	0.56386739	0.055947062	2952.7974
200.27417	0.57015896	0.057188101	2961.8584
201.27515	0.57167697	0.058265597	2961.8872
202.27612	0.57247895	0.05952318	2960.8914
203.2771	0.57517952	0.060699258	2967.3635
204.27808	0.57940966	0.061853267	2972.4634
205.27905	0.57892305	0.062731773	2966.4741
206.28003	0.58774883	0.063974462	2974.8579
207.28101	0.58798057	0.064954787	2976.0745
208.28198	0.59065515	0.065885268	2971.2456
209.28296	0.59564507	0.066966429	2979.3806
210.28394	0.59933531	0.068244077	2988.8489
211.28491	0.60025913	0.069388837	2981.6235
212.28589	0.60489941	0.070641406	2991.5667
213.28687	0.60494387	0.071812898	2985.1653
214.28784	0.60742575	0.073207587	2988.0017
215.28882	0.61548787	0.074342668	2997.2517
216.28979	0.61384571	0.075443655	2991.7405
217.29077	0.61716527	0.076448478	2994.0449
218.29175	0.62112135	0.077454664	2993.1184
219.29272	0.62343305	0.07847137	2998.0793
220.2937	0.62622386	0.079559743	3001.0862
221.29468	0.62904191	0.080543444	3010.3335
222.29565	0.63351482	0.081852056	3007.4004
223.29663	0.63887554	0.08322604	3018.8242
224.29761	0.63765931	0.084558517	3011.3315
225.29858	0.64400363	0.085789256	3009.4272
226.29956	0.64449108	0.086833037	3016.551
227.30054	0.64807749	0.08808957	3017.064
228.30151	0.65209824	0.08932706	3025.6174
229.30249	0.65510392	0.090441309	3026.7725
230.30347	0.65785819	0.09176822	3021.6567
231.30444	0.65958667	0.092900388	3028.4553
232.30542	0.66278607	0.094051614	3031.8188
233.3064	0.66869682	0.095300734	3033.7493
234.30737	0.66961396	0.096430965	3038.7476
235.30835	0.67202199	0.097769715	3036.0317
236.30933	0.67529899	0.09897431	3041.7642
237.3103	0.67865282	0.10026477	3044.3376
238.31128	0.67876059	0.1013637	3036.3452
239.31226	0.68659759	0.10273523	3049.8997
240.31323	0.686064	0.10408895	3042.2966
241.31421	0.69159073	0.10501904	3044.1682
242.31519	0.69349575	0.10617559	3052.1787
243.31616	0.69621521	0.10729955	3049.0251
244.31714	0.70208329	0.10831373	3054.5093
245.31812	0.7037369	0.10951185	3052.1006
246.31909	0.70365268	0.1106045	3049.3464
247.32007	0.70816779	0.11183599	3060.9309
248.32104	0.70964116	0.11326329	3056.9246
249.32202	0.71417862	0.11464365	3057.8152
250.323	0.71696866	0.11594985	3058.0105
251.32397	0.72221887	0.11716641	3064.4717
252.32495	0.72462749	0.11828099	3066.3594
253.32593	0.72712719	0.11927082	3066.0259
254.3269	0.72800559	0.12030505	3064.8589
255.32788	0.7354762	0.12151519	3076.5769
256.32886	0.73178309	0.12267859	3067.9871
257.32983	0.73757774	0.12408938	3079.4763
258.33081	0.74058282	0.12557784	3076.9915
259.33179	0.74368429	0.12711677	3081.5498
260.33276	0.74684793	0.12848631	3081.6396
261.33374	0.74890029	0.12953374	3083.0503
262.33472	0.75131035	0.13065164	3080.5881
263.33569	0.7551865	0.13164143	3078.1714
264.33667	0.76005608	0.13274634	3088.5789
265.33765	0.76203281	0.13402221	3090.853
266.33862	0.76656514	0.13540405	3093.4163
267.3396	0.7646777	0.13655126	3087.6313
268.34058	0.77089673	0.13786587	3095.5869
269.34155	0.77568209	0.13927296	3098.0276
270.34253	0.77809256	0.1406053	3096.8386
271.34351	0.78142166	0.14202723	3099.3884
272.34448	0.78368962	0.14323166	3103.2354
273.34546	0.78846097	0.14455712	3102.5432
274.34644	0.79029888	0.14596213	3105.062
275.34741	0.79307693	0.14732482	3105.4927
276.34839	0.79403585	0.14848338	3105.1316
277.34937	0.80126941	0.1496201	3111.9624
278.35034	0.80129892	0.15071949	3107.1743
279.35132	0.80415833	0.15198994	3107.0205
280.35229	0.80914676	0.15329014	3119.7712
281.35327	0.81275898	0.15471987	3120.2102
282.35425	0.81556141	0.155959	3124.0432
283.35522	0.81724912	0.15728915	3118.1226
284.3562	0.81991899	0.15843745	3126.1646
285.35718	0.82367527	0.15957893	3123.6091
286.35815	0.82756215	0.16065253	3118.0569
287.35913	0.83087665	0.16187918	3132.3423
288.36011	0.8337754	0.16304389	3138.3372
289.36108	0.83800596	0.16436644	3130.4116
290.36206	0.83918548	0.1658095	3138.0664
291.36304	0.84098279	0.16683985	3132.4019
292.36401	0.84464961	0.1679388	3136.8181
293.36499	0.84867674	0.16911831	3137.2957
294.36597	0.84955859	0.17042491	3132.0889
295.36694	0.85311544	0.17177159	3139.012
296.36792	0.85325992	0.17347409	3143.2134
297.3689	0.85717452	0.17469649	3137.7007
298.36987	0.86586422	0.17598239	3146.2527
299.37085	0.86553907	0.17723301	3143.5476
300.37183	0.86868697	0.17850175	3147.2913
301.3728	0.86963522	0.17955306	3144.7847
302.37378	0.8752889	0.18083309	3149.2883
303.37476	0.87715447	0.18215536	3155.5642
304.37573	0.87846857	0.18330516	3148.7134
305.37671	0.88419586	0.18451764	3154.1438
306.37769	0.88737243	0.18567568	3153.2998
307.37866	0.88799834	0.18687236	3154.5178
308.37964	0.89047468	0.18811822	3159.2549
309.38062	0.89801437	0.18933998	3159.7634
310.38159	0.89830732	0.19062817	3164.7681
311.38257	0.90132225	0.19172139	3157.0972
312.38354	0.90229344	0.19285883	3163.9958
313.38452	0.90554398	0.193849	3155.1694
314.3855	0.90990728	0.19509244	3163.3345
315.38647	0.91301954	0.19644921	3163.5825
316.38745	0.91668302	0.19775791	3161.8442
317.38843	0.92030257	0.19877891	3170.5911
318.3894	0.92154479	0.19976111	3165.9963
319.39038	0.92448431	0.20097587	3174.7524
320.39136	0.92604351	0.20218849	3172.2261
321.39233	0.93362606	0.2035318	3176.6895
322.39331	0.93294317	0.20481017	3181.5508
323.39429	0.93748534	0.20639932	3187.5405
324.39526	0.94065166	0.20763732	3179.1729
325.39624	0.94384938	0.20871203	3177.8877
326.39722	0.94555587	0.20995106	3182.2969
327.39819	0.94977081	0.21115601	3192.7366
328.39917	0.94882977	0.21216841	3178.4028
329.40015	0.95467508	0.21337299	3182.0957
330.40112	0.95983356	0.21474239	3196.4241
331.4021	0.95834219	0.21622786	3191.917
332.40308	0.96563596	0.21756744	3186.3333
333.40405	0.96604717	0.21873748	3191.6155
334.40503	0.96886873	0.21990626	3190.6282
335.40601	0.97477198	0.2212638	3201.9526
336.40698	0.97596115	0.22272208	3199.7883
337.40796	0.9822883	0.22409636	3198.3188
338.40894	0.98197401	0.22530404	3202.1589
339.40991	0.98325455	0.22650899	3195.2974
340.41089	0.98512971	0.22776556	3202.7385
341.41187	0.98991305	0.22891471	3204.3123
342.41284	0.9955532	0.2303277	3204.9377
343.41382	0.99546057	0.23152997	3200.9395
344.41479	0.99880093	0.23259771	3199.9099
345.41577	1.0026579	0.23365112	3204.3757
346.41675	1.0054387	0.23492703	3216.5127
347.41772	1.0101272	0.23613667	3212.6516
348.4187	1.0129933	0.23744683	3217.7532
349.41968	1.0149994	0.23853855	3213.4773
350.42065	1.0171034	0.23969635	3209.5869
351.42163	1.0216902	0.24070397	3214.5178
352.42261	1.0249352	0.24177618	3221.1736
353.42358	1.02406	0.24328125	3220.2966
354.42456	1.0296489	0.24464907	3217.5974
355.42554	1.0331582	0.24577136	3217.5291
356.42651	1.0347605	0.24690486	3222.4199
357.42749	1.0401791	0.24812612	3227.0286
358.42847	1.0403527	0.24937056	3226.23
359.42944	1.0434309	0.25079983	3225.4656
360.43042	1.0484723	0.2522026	3230.0474
361.4314	1.0528947	0.25341344	3227.9314
362.43237	1.0520285	0.25461194	3229.5647
363.43335	1.0548055	0.2560024	3232.135
364.43433	1.0609753	0.25706181	3224.3594
365.4353	1.0632592	0.25828609	3233.624
366.43628	1.0679529	0.25987437	3240.8467
367.43726	1.0675859	0.26100308	3236.3181
368.43823	1.0738454	0.26226506	3240.0972
369.43921	1.0745304	0.26359129	3248.387
370.44019	1.079164	0.26487318	3238.0098
371.44116	1.0803136	0.2659294	3237.0967
372.44214	1.0855683	0.267299	3244.5518
373.44312	1.0877459	0.26839721	3245.6912
374.44409	1.0900142	0.26954195	3246.0208
375.44507	1.0904566	0.27082184	3243.2446
376.44604	1.0923729	0.27201939	3240.4585
377.44702	1.1011364	0.27322003	3249.5442
378.448	1.1011091	0.27418754	3245.925
379.44897	1.1050693	0.27559471	3247.4097
380.44995	1.1097338	0.27665654	3258.9585
381.45093	1.1110724	0.27792901	3250.6394
382.4519	1.1145009	0.27910495	3261.0061
383.45288	1.115237	0.28037786	3254.1504
384.45386	1.1203673	0.28171626	3260.8013
385.45483	1.1251684	0.28310752	3263.2876
386.45581	1.1245675	0.28445667	3261.2371
387.45679	1.127298	0.28554797	3262.3035
388.45776	1.1319847	0.28680035	3261.8464
389.45874	1.1333517	0.28816912	3263.0188
390.45972	1.1395115	0.28923538	3258.6594
391.46069	1.1399759	0.29035252	3266.4309
392.46167	1.1463982	0.29166323	3271.2085
393.46265	1.1461513	0.29311845	3266.2695
394.46362	1.1491688	0.29429144	3265.6377
395.4646	1.1548623	0.29536632	3270.624
396.46558	1.154247	0.29640979	3263.541
397.46655	1.1573759	0.29754466	3269.4863
398.46753	1.1628385	0.29887527	3278.6477
399.46851	1.1652876	0.30032295	3277.2886
400.46948	1.1662265	0.30166954	3276.5132
401.47046	1.1719964	0.30300996	3277.0698
402.47144	1.1727383	0.30427635	3281.6934
403.47241	1.1778289	0.30565763	3288.3799
404.47339	1.1795553	0.30686477	3276.363
405.47437	1.1822834	0.30788293	3277.8325
406.47534	1.1852682	0.30897579	3276.6072
407.47632	1.1912789	0.31023151	3287.5496
408.47729	1.1923792	0.31144822	3287.4226
409.47827	1.1947553	0.31279013	3289.0811
410.47925	1.1976267	0.31401834	3287.8945
411.48022	1.1992382	0.31531119	3283.2085
412.4812	1.206969	0.31668812	3300.3728
413.48218	1.2081833	0.31797624	3292.2966
414.48315	1.2138002	0.31920689	3295.6553
415.48413	1.2122502	0.32053581	3296.7927
416.48511	1.2160152	0.32151666	3294.7808
417.48608	1.2172736	0.32290307	3305.0212
418.48706	1.22401	0.32411671	3293.8894
419.48804	1.223485	0.32526675	3303.8342
420.48901	1.2267885	0.3265956	3292.1499
421.48999	1.2328058	0.32782924	3305.0156
422.49097	1.235136	0.32912865	3302.7925
423.49194	1.2387744	0.33022785	3307.479
424.49292	1.2386789	0.33142141	3308.3481
425.4939	1.2412083	0.33271113	3303.6865
426.49487	1.2457389	0.33394143	3307.0896
427.49585	1.2483225	0.33528313	3309.2249
428.49683	1.2501261	0.33646289	3301.9868
429.4978	1.2556944	0.33770201	3308.415
430.49878	1.2573831	0.33876672	3305.0454
431.49976	1.2609138	0.33991018	3311.7712
432.50073	1.262772	0.34114373	3308.3979
433.50171	1.2656132	0.34235317	3310.55
434.50269	1.2674065	0.34338057	3312.0339
435.50366	1.274213	0.34454224	3314.1855
436.50464	1.275087	0.34563482	3315.7397
437.50562	1.2798331	0.34679201	3326.344
438.50659	1.280841	0.34818354	3325.9468
439.50757	1.2849526	0.34953231	3326.2097
440.50854	1.2886206	0.35089183	3326.7568
441.50952	1.2923527	0.3522957	3328.5225
442.5105	1.296169	0.35351524	3322.4695
443.51147	1.2940403	0.35471115	3320.3306
444.51245	1.3004345	0.35613975	3330.4075
445.51343	1.304755	0.35735291	3327.98
446.5144	1.3071479	0.35862193	3325.9521
447.51538	1.311942	0.35989821	3331.2217
448.51636	1.3119015	0.3611075	3328.6182
449.51733	1.3139175	0.36231679	3329.6501
450.51831	1.3194215	0.3635636	3331.7742
451.51929	1.3209807	0.36500064	3331.4641
452.52026	1.3219695	0.36612204	3323.4839
453.52124	1.3275576	0.36734936	3340.1475
454.52222	1.3302783	0.36843908	3330.7104
455.52319	1.3303789	0.36961183	3336.0244
456.52417	1.3380079	0.37074906	3337.8167
457.52515	1.3410772	0.37172851	3335.5513
458.52612	1.3417686	0.37277812	3340.2148
459.5271	1.3446963	0.37395355	3337.6245
460.52808	1.3464389	0.37532541	3344.0916
461.52905	1.3489466	0.37648764	3342.8391
462.53003	1.3533711	0.37793157	3345.8645
463.53101	1.356294	0.37913081	3339.0859
464.53198	1.3601013	0.3802048	3345.5278
465.53296	1.3630869	0.38145539	3346.9424
466.53394	1.3684546	0.38258043	3342.1567
467.53491	1.3706045	0.3838819	3353.5063
468.53589	1.3709989	0.38531217	3350.7437
469.53687	1.3743222	0.38638541	3351.1497
470.53784	1.3777989	0.38764182	3353.219
471.53882	1.3798935	0.38871425	3353.7305
472.53979	1.38667	0.39007342	3358.6548
473.54077	1.3875318	0.39139774	3358.575
474.54175	1.3899243	0.39270762	3356.8879
475.54272	1.3935311	0.39400622	3357.1702
476.5437	1.3961678	0.39542344	3357.887
477.54468	1.4008918	0.39669728	3357.6436
478.54565	1.4031152	0.39791897	3354.1294
479.54663	1.4052441	0.39896968	3353.9963
480.54761	1.4093657	0.40014315	3362.762
481.54858	1.4119766	0.40164459	3364.0706
482.54956	1.4137887	0.40278891	3362.9609
483.55054	1.4178895	0.40412006	3372.8098
484.55151	1.4201255	0.4052963	3366.2808
485.55249	1.4215314	0.40658876	3365.0063
486.55347	1.4247009	0.40794003	3361.9487
487.55444	1.4318861	0.40896642	3361.5928
488.55542	1.4340593	0.40999573	3374.2405
489.5564	1.437343	0.41105938	3375.293
490.55737	1.4390069	0.41255677	3379.2524
491.55835	1.4424157	0.41361383	3373.2771
492.55933	1.4422672	0.41491282	3370.0916
493.5603	1.4469119	0.41607136	3374.9045
494.56128	1.4484694	0.41742495	3373.157
495.56226	1.4533564	0.41859749	3374.1787
496.56323	1.4549052	0.41994703	3380.8022
497.56421	1.4599284	0.42109919	3372.8008
498.56519	1.4618541	0.42226237	3381.5769
499.56616	1.4669141	0.42333606	3379.4199
500.56714	1.4683294	0.42454049	3380.0991
501.56812	1.4712677	0.42610455	3380.123
502.56909	1.4715548	0.4275896	3380.948
503.57007	1.4772365	0.42888579	3388.1614
504.57104	1.4798136	0.43016368	3386.8718
505.57202	1.4834493	0.43121985	3383.0525
506.573	1.4849513	0.43251386	3383.4194
507.57397	1.4884216	0.43383199	3392.5115
508.57495	1.4935199	0.43520358	3391.1189
509.57593	1.497391	0.4363085	3389.6443
510.5769	1.4998134	0.4375875	3394.4995
511.57788	1.5040925	0.43870175	3391.4583
512.57886	1.5029228	0.43987432	3387.6921
513.57983	1.5082783	0.44115734	3397.7241
514.58081	1.5106128	0.4426457	3398.2837
515.58179	1.5131674	0.44382408	3389.4067
516.58276	1.5146439	0.44502273	3390.1873
517.58374	1.5216134	0.44633365	3402.8271
518.58472	1.5210352	0.44759986	3400.4951
519.58569	1.5259587	0.44906291	3411.3198
520.58667	1.5293416	0.45048589	3401.0774
521.58765	1.5320615	0.45184734	3407.6836
522.58862	1.53396	0.45295468	3404.1926
523.5896	1.5384253	0.45419759	3399.6123
524.59058	1.540499	0.45552251	3399.3892
525.59155	1.5436165	0.45665124	3401.7261
526.59253	1.5443591	0.45791888	3403.4861
527.59351	1.5503331	0.45929241	3410.0635
528.59448	1.5552737	0.46058536	3405.1362
529.59546	1.5575237	0.46183297	3406.3008
530.59644	1.5588994	0.46308693	3410.1658
531.59741	1.5630903	0.46399704	3407.3108
532.59839	1.5640192	0.46534237	3414.6492
533.59937	1.5672431	0.46657714	3419.4727
534.60034	1.5691303	0.46778536	3410.0273
535.60132	1.5728972	0.46890751	3411.751
536.60229	1.576147	0.4700841	3415.2209
537.60327	1.5791955	0.47144151	3414.9099
538.60425	1.582832	0.4725526	3413.4504
539.60522	1.5886878	0.47377771	3416.2134
540.6062	1.5890248	0.47511309	3420.5176
541.60718	1.5921816	0.47644034	3421.0994
542.60815	1.5952262	0.47750732	3409.8794
543.60913	1.5977346	0.47864789	3414.0771
544.61011	1.6022198	0.47976747	3419.114
545.61108	1.60492	0.48109415	3424.426
546.61206	1.6096815	0.48252583	3426.0042
547.61304	1.6076981	0.48391974	3420.395
548.61401	1.6127105	0.48528051	3427.4954
549.61499	1.6134899	0.48656577	3421.4866
550.61597	1.618607	0.48805356	3431.0825
551.61694	1.6194317	0.48930189	3421.2646
552.61792	1.6270236	0.490821	3433.6521
553.6189	1.6261979	0.49199697	3428.8323
554.61987	1.6304766	0.49340594	3429.7654
555.62085	1.6351917	0.49467075	3429.9785
556.62183	1.6347057	0.49575064	3422.9268
557.6228	1.6402992	0.49703208	3429.2107
558.62378	1.6428871	0.49840948	3436.5835
559.62476	1.6440079	0.49977356	3429.9873
560.62573	1.6484386	0.5010314	3430.509
561.62671	1.6511072	0.50233525	3438.4773
562.62769	1.6554558	0.5037657	3440.5249
563.62866	1.6575725	0.50506735	3436.6289
564.62964	1.6624343	0.50619876	3436.6958
565.63062	1.6629826	0.50741595	3434.9517
566.63159	1.6706907	0.50840682	3441.0911
567.63257	1.6679125	0.50955576	3433.4819
568.63354	1.6713254	0.51084626	3444.8794
569.63452	1.6758116	0.51222211	3442.0042
570.6355	1.6782455	0.51357633	3441.9207
571.63647	1.6842551	0.51507258	3442.8394
572.63745	1.6843531	0.5163427	3436.5862
573.63843	1.6888689	0.51748174	3446.8787
574.6394	1.68843	0.51903707	3443.3789
575.64038	1.6965187	0.52041525	3444.8828
576.64136	1.6988791	0.52156532	3444.1055
577.64233	1.6989604	0.52287287	3449.8052
578.64331	1.7022468	0.5242008	3444.7097
579.64429	1.7097577	0.52555364	3455.875
580.64526	1.7061745	0.52652848	3440.2378
581.64624	1.7109605	0.52797842	3454.0603
582.64722	1.7165549	0.52969396	3457.446
583.64819	1.7184584	0.53103626	3454.4646
584.64917	1.7201725	0.53238547	3449.4431
585.65015	1.7264358	0.53371084	3460.5776
586.65112	1.728126	0.53508449	3450.8496
587.6521	1.7307127	0.53639829	3458.0979
588.65308	1.7313666	0.53765756	3452.0291
589.65405	1.7358646	0.53884977	3458.2405
590.65503	1.7427155	0.5399918	3462.4941
591.65601	1.7435225	0.54131621	3461.2161
592.65698	1.7436938	0.54256791	3457.8943
593.65796	1.7479126	0.54388732	3453.7742
594.65894	1.7514122	0.54520404	3464.5374
595.65991	1.7575366	0.54676002	3470.2893
596.66089	1.7577362	0.54815841	3460.9614
597.66187	1.7599742	0.54933095	3462.1995
598.66284	1.762386	0.55056202	3452.6987
599.66382	1.766829	0.55175745	3461.3667
600.66479	1.7688471	0.55303401	3467.5708
601.66577	1.7706476	0.55425578	3469.4734
602.66675	1.7728164	0.55559558	3463.6113
603.66772	1.7767454	0.55663049	3453.7976
604.6687	1.7796695	0.55795908	3464.4827
605.66968	1.7808796	0.55909985	3464.3423
606.67065	1.7839978	0.56044859	3464.8364
607.67163	1.7871732	0.56160152	3463.6738
608.67261	1.793618	0.56287485	3476.2051
609.67358	1.7970078	0.56441575	3472.6963
610.67456	1.7985309	0.56577784	3465.8232
611.67554	1.8005549	0.56727964	3467.5193
612.67651	1.8048669	0.56855899	3466.2944
613.67749	1.8098508	0.56992161	3481.624
614.67847	1.8100471	0.57151973	3477.2964
615.67944	1.8139031	0.57288092	3469.0815
616.68042	1.8179792	0.57416224	3468.1531
617.6814	1.8183074	0.57534587	3472.9229
618.68237	1.8214579	0.57685649	3475.394
619.68335	1.8265142	0.57817191	3480.3503
620.68433	1.8277446	0.57954049	3482.2417
621.6853	1.8320227	0.58084428	3475.2305
622.68628	1.8350784	0.58227265	3483.0017
623.68726	1.8355082	0.58353776	3473.4658
624.68823	1.8401846	0.5845893	3470.9336
625.68921	1.8436557	0.58611637	3479.8213
626.69019	1.845422	0.58732855	3478.7512
627.69116	1.8498265	0.58892363	3481.6482
628.69214	1.8514611	0.59000051	3482.8875
629.69312	1.8562618	0.59153038	3486.3313
630.69409	1.8603965	0.59286129	3485.6348
631.69507	1.8630905	0.59423101	3484.8979
632.69604	1.8645363	0.59573036	3483.7119
633.69702	1.8688135	0.59699208	3488.4109
634.698	1.8696142	0.59850156	3487.1011
635.69897	1.874904	0.59948903	3484.6604
636.69995	1.8777832	0.60077029	3489.844
637.70093	1.8833252	0.60196698	3491.0132
638.7019	1.881699	0.60320574	3486.0786
639.70288	1.884733	0.60478896	3488.6011
640.70386	1.8887584	0.60612017	3491.6521
641.70483	1.8898293	0.60763472	3489.731
642.70581	1.8981073	0.60873711	3488.8157
643.70679	1.8987761	0.60991871	3490.3892
644.70776	1.9004887	0.61128938	3496.051
645.70874	1.9047014	0.61260676	3492.5474
646.70972	1.9045571	0.61378616	3491.3271
647.71069	1.908339	0.61542034	3498.9316
648.71167	1.9128373	0.61670256	3494.7229
649.71265	1.915295	0.61797839	3496.9304
650.71362	1.9162452	0.6194191	3494.0969
651.7146	1.9219176	0.62069976	3496.8904
652.71558	1.925315	0.62215	3497.9768
653.71655	1.9284742	0.62344033	3496.7859
654.71753	1.9304982	0.62503624	3499.3311
655.71851	1.9363106	0.62653309	3501.6965
656.71948	1.9378729	0.62800431	3502.3843
657.72046	1.9382339	0.62937081	3501.6611
658.72144	1.9409171	0.63087428	3498.4678
659.72241	1.9452617	0.63233107	3502.1978
660.72339	1.9494379	0.63346314	3497.4309
661.72437	1.9536405	0.63495243	3507.1321
662.72534	1.9556618	0.63655078	3509.2615
663.72632	1.9582404	0.63807195	3503.9233
664.72729	1.9594982	0.63951051	3496.5608
665.72827	1.9639382	0.64089167	3507.7166
666.72925	1.967829	0.64212137	3500.6665
667.73022	1.9682056	0.64337581	3497.6104
668.7312	1.974416	0.6447829	3509.667
669.73218	1.9773993	0.6463607	3516.4736
670.73315	1.9762272	0.64781713	3508.5593
671.73413	1.9802686	0.64943099	3506.0117
672.73511	1.987187	0.65079641	3509.8789
673.73608	1.987209	0.6522764	3506.9441
674.73706	1.9937022	0.65357965	3508.2107
675.73804	1.9927473	0.65497929	3504.2031
676.73901	1.9959511	0.65630573	3507.416
677.73999	1.9996629	0.65742886	3509.6855
678.74097	2.0017953	0.65867913	3511.8276
679.74194	2.0059948	0.66041589	3518.2129
680.74292	2.0086904	0.6617738	3511.7605
681.7439	2.0115364	0.66310245	3509.873
682.74487	2.0157566	0.66467738	3521.7144
683.74585	2.0196886	0.66633803	3517.6731
684.74683	2.0212743	0.66785961	3512.8394
685.7478	2.025929	0.66924185	3505.3342
686.74878	2.0300527	0.67033285	3507.7632
687.74976	2.0284615	0.67177415	3519.1455
688.75073	2.0351715	0.67351055	3527.9011
689.75171	2.0375535	0.67505139	3518.8159
690.75269	2.0387819	0.67652512	3516.614
691.75366	2.0434325	0.67785978	3522.9153
692.75464	2.0477715	0.678967	3518.3779
693.75562	2.0467939	0.68035328	3520.3813
694.75659	2.0519655	0.68174332	3520.9619
695.75757	2.0533476	0.68315196	3522.5874
696.75854	2.0566142	0.68460357	3521.2876
697.75952	2.0618973	0.6862011	3526.2004
698.7605	2.0631568	0.68768162	3517.4509
699.76147	2.0660307	0.68905896	3514.7122
700.76245	2.0690536	0.69038701	3519.8252
701.76343	2.0722823	0.69177538	3520.3059
702.7644	2.0743258	0.69310844	3521.1758
703.76538	2.0776262	0.69467831	3529.6116
704.76636	2.0814683	0.69617546	3522.5542
705.76733	2.0839217	0.69739872	3520.6626
706.76831	2.0849023	0.69864714	3524.47
707.76929	2.0890114	0.69996846	3521.4377
708.77026	2.094897	0.70131356	3524.46
709.77124	2.0958762	0.70261651	3522.2944
710.77222	2.100383	0.70412916	3529.946
711.77319	2.1002097	0.7057209	3522.9797
712.77417	2.1023898	0.70737147	3529.166
713.77515	2.1101835	0.70904922	3531.9778
714.77612	2.1133409	0.71076554	3534.2192
715.7771	2.1166565	0.71227932	3533.813
716.77808	2.1178985	0.71388507	3529.1724
717.77905	2.1210904	0.71540165	3530.2817
718.78003	2.1237674	0.71697891	3529.3701
719.78101	2.1252391	0.71825224	3526.5327
720.78198	2.1310351	0.71966362	3535.9402
721.78296	2.1302619	0.72117317	3531.7622
722.78394	2.1375232	0.72249544	3532.3459
723.78491	2.1395426	0.72396535	3530.7085
724.78589	2.1405435	0.72544879	3538.6982
725.78687	2.1458309	0.72689462	3532.8521
726.78784	2.1476948	0.72821075	3529.2925
727.78882	2.1511877	0.72956014	3535.7676
728.78979	2.1510682	0.73115522	3532.748
729.79077	2.1559412	0.73271769	3537.3374
730.79175	2.1574926	0.73416424	3538.9788
731.79272	2.1633918	0.73547786	3537.1145
732.7937	2.167624	0.73714674	3541.5613
733.79468	2.1670642	0.7387507	3540.1907
734.79565	2.1721435	0.74038887	3542.9658
735.79663	2.1768286	0.74195802	3543.7791
736.79761	2.1758788	0.74327582	3539.0083
737.79858	2.1772423	0.74474692	3535.6699
738.79956	2.1828156	0.74622613	3539.1528
739.80054	2.1878576	0.74777484	3539.8662
740.80151	2.1904204	0.74950445	3547.6504
741.80249	2.1932135	0.75079352	3529.2148
742.80347	2.1942828	0.75188029	3530.552
743.80444	2.1999061	0.75325167	3540.5867
744.80542	2.2009726	0.75463206	3542.4194
745.8064	2.2058079	0.75600636	3544.0049
746.80737	2.2044017	0.75714481	3535.1682
747.80835	2.2114882	0.75869602	3540.3052
748.80933	2.212898	0.76037151	3546.4636
749.8103	2.2168012	0.76213759	3545.4463
750.81128	2.2189453	0.7637006	3544.2158
751.81226	2.2220099	0.76544094	3548.4976
752.81323	2.2269907	0.7670204	3547.373
753.81421	2.2305098	0.76849806	3546.1973
754.81519	2.2303433	0.77004725	3541.4653
755.81616	2.2319381	0.77167428	3541.6897
756.81714	2.2407944	0.7731806	3548.7422
757.81812	2.2386332	0.77463508	3545.1511
758.81909	2.2454963	0.77597642	3543.9067
759.82007	2.2474868	0.77775311	3548.5784
760.82104	2.2510643	0.77943009	3548.7368
761.82202	2.2496922	0.78120941	3548.4963
762.823	2.2582929	0.78291774	3547.8984
763.82397	2.2572868	0.78438884	3545.2405
764.82495	2.2624602	0.78594005	3550.8989
765.82593	2.2642708	0.78731126	3540.1216
766.8269	2.2667148	0.78904885	3557.3184
767.82788	2.269052	0.79052073	3548.1257
768.82886	2.2697992	0.79221642	3551.2981
769.82983	2.2737699	0.79407483	3550.3105
770.83081	2.2823334	0.79570258	3554.5442
771.83179	2.2832308	0.7972284	3549.4526
772.83276	2.2841165	0.79864395	3541.7405
773.83374	2.2891281	0.80001688	3553.7813
774.83472	2.2902093	0.80156964	3553.0735
775.83569	2.2960489	0.80300212	3550.0664
776.83667	2.2988966	0.80458784	3551.8396
777.83765	2.3026083	0.80632025	3561.3711
778.83862	2.3051822	0.80832243	3554.698
779.8396	2.3064978	0.80987477	3547.4221
780.84058	2.3099005	0.811382	3551.8955
781.84155	2.3165269	0.81302881	3559.5757
782.84253	2.3174391	0.81453085	3555.2075
783.84351	2.3189819	0.81613338	3552.0049
784.84448	2.3213689	0.81746483	3555.3042
785.84546	2.3253598	0.81890726	3554.4639
786.84644	2.3261545	0.82055199	3555.8979
787.84741	2.3300774	0.82244301	3562.8445
788.84839	2.3329453	0.82422471	3559.8625
789.84937	2.3369122	0.8258732	3554.188
790.85034	2.3397593	0.82755941	3554.9468
791.85132	2.3423641	0.82917255	3556.2769
792.85229	2.3466759	0.83098376	3556.6724
793.85327	2.3511329	0.83252412	3559.6809
794.85425	2.3515229	0.83419377	3558.7632
795.85522	2.3524947	0.83605736	3560.1472
796.8562	2.356391	0.83765423	3553.6223
797.85718	2.3578801	0.8393302	3551.3457
798.85815	2.3627453	0.84097576	3557.9446
799.85913	2.366008	0.84259325	3556.896
800.86011	2.3721547	0.8438406	3558.8738
801.86108	2.373579	0.84535795	3556.1919
802.86206	2.3766341	0.84708458	3559.5417
803.86304	2.3779531	0.84860188	3555.585
804.86401	2.3817847	0.8502152	3560.6565
805.86499	2.3853738	0.85217553	3565.0701
806.86597	2.3873203	0.85418653	3559.5486
807.86694	2.3923581	0.85580015	3560.5742
808.86792	2.3945088	0.85743213	3562.3157
809.8689	2.3949878	0.85887873	3557.5903
810.86987	2.3970749	0.86056155	3559.2104
811.87085	2.4012222	0.86188787	3555.2847
812.87183	2.4070945	0.86335212	3557.0889
813.8728	2.4100368	0.86476845	3559.9966
814.87378	2.4087229	0.86625868	3558.656
815.87476	2.4154408	0.86805433	3567.7092
816.87573	2.4159501	0.86980182	3567.5947
817.87671	2.4170399	0.87181288	3563.1016
818.87769	2.4226031	0.87353963	3550.8462
819.87866	2.4292538	0.87517881	3569.1477
820.87964	2.4294236	0.87710446	3572.3997
821.88062	2.4312172	0.87889057	3560.3984
822.88159	2.4337945	0.88054198	3563.1431
823.88257	2.4388659	0.88218886	3561.1426
824.88354	2.4427369	0.88388622	3563.0276
825.88452	2.4439526	0.88541061	3564.9888
826.8855	2.445991	0.88684601	3557.761
827.88647	2.4504755	0.88837433	3564.7483
828.88745	2.4545865	0.89006686	3568.7869
829.88843	2.4547205	0.89197642	3563.2954
830.8894	2.4578233	0.8938455	3563.3132
831.89038	2.4597607	0.89570367	3565.3293
832.89136	2.4653456	0.89789492	3570.6973
833.89233	2.4674897	0.89984	3564.3979
834.89331	2.4702547	0.90174651	3562.6753
835.89429	2.4741354	0.90355736	3565.4841
836.89526	2.4787683	0.90504229	3563.241
837.89624	2.4792426	0.90659636	3563.7644
838.89722	2.4832947	0.90839207	3570.9956
839.89819	2.484468	0.91052377	3573.0281
840.89917	2.4929469	0.91249299	3566.8691
841.90015	2.4935687	0.91431904	3563.5654
842.90112	2.4962726	0.9161545	3565.9343
843.9021	2.4976368	0.91781741	3557.3591
844.90308	2.5009801	0.91943544	3559.1545
845.90405	2.503731	0.92086166	3563.7769
846.90503	2.5064294	0.92262441	3562.5256
847.90601	2.5108249	0.92445844	3569.6877
848.90698	2.51354	0.92633772	3565.5815
849.90796	2.5128214	0.92803276	3562.2297
850.90894	2.5182588	0.92983198	3568.478
851.90991	2.5238791	0.93168217	3568.0261
852.91089	2.5226505	0.93363106	3567.0754
853.91187	2.5293462	0.9354834	3563.5972
854.91284	2.5318336	0.93709749	3565.054
855.91382	2.5330944	0.9388358	3567.8425
856.91479	2.5391147	0.9406321	3570.2151
857.91577	2.5402644	0.9425903	3575.7903
858.91675	2.5471179	0.94461554	3570.1589
859.91772	2.548389	0.94641834	3568.6277
860.9187	2.5502889	0.94809878	3563.1816
861.91968	2.5520852	0.94989699	3565.999
862.92065	2.5522995	0.95189923	3567.2993
863.92163	2.5596521	0.95391196	3569.5947
864.92261	2.5625627	0.9558022	3571.843
865.92358	2.5652776	0.95785201	3570.1309
866.92456	2.5650446	0.96007019	3568.9719
867.92554	2.570636	0.96191823	3565.7561
868.92651	2.5742052	0.96388072	3573.5544
869.92749	2.5760686	0.96626842	3571.1396
870.92847	2.5787866	0.9683125	3563.72
871.92944	2.5840442	0.97028083	3570.415
872.93042	2.5868356	0.97238761	3571.543
873.9314	2.5873499	0.97410208	3561.6475
874.93237	2.5910113	0.97628403	3570.1265
875.93335	2.5950785	0.97805327	3565.6614
876.93433	2.5950642	0.9798187	3564.4905
877.9353	2.6016753	0.98173338	3565.8005
878.93628	2.6019468	0.98359185	3572.8953
879.93726	2.6054976	0.98542207	3567.9663
880.93823	2.6089642	0.98725975	3563.6123
881.93921	2.61466	0.98891526	3563.4031
882.94019	2.6184051	0.99087924	3578
883.94116	2.6189342	0.99279362	3566.2329
884.94214	2.6215053	0.99447328	3563.3105
885.94312	2.6225164	0.9960646	3564.8228
886.94409	2.629863	0.9978869	3574.2593
887.94507	2.6311569	0.99970418	3569.8176
888.94604	2.634079	1.0014	3565.3196
889.94702	2.6356456	1.0032266	3564.4392
890.948	2.6399429	1.0055674	3575.8669
891.94897	2.6433623	1.0077398	3569.3943
892.94995	2.643347	1.0098214	3570.1228
893.95093	2.6488352	1.0121797	3569.3669
894.9519	2.6509438	1.0146276	3573.0181
895.95288	2.6542599	1.01657	3571.0447
896.95386	2.65978	1.0184336	3571.6458
897.95483	2.6597557	1.0201082	3563.0005
898.95581	2.6644461	1.0222175	3571.0186
899.95679	2.6652856	1.0245113	3566.1255
900.95776	2.6692982	1.0266887	3566.531
901.95874	2.6728115	1.0290803	3573.6453
902.95972	2.675797	1.0313928	3564.3936
903.96069	2.6806455	1.0336444	3571.2747
904.96167	2.6824682	1.0357772	3572.3345
905.96265	2.6851714	1.0381056	3567.488
906.96362	2.6878908	1.0402262	3570.376
907.9646	2.6910844	1.0425389	3566.5908
908.96558	2.6948225	1.0448849	3566.0054
909.96655	2.6966302	1.0469148	3563.2615
910.96753	2.7001565	1.0490481	3568.6775
911.96851	2.7005916	1.0514491	3566.8169
912.96948	2.703738	1.0535692	3568.5923
913.97046	2.7091131	1.0558554	3564.8726
914.97144	2.7120292	1.0575095	3559.7642
915.97241	2.7173264	1.0592865	3561.9912
916.97339	2.7172379	1.0614054	3567.1387
917.97437	2.7167892	1.0634952	3564.1667
918.97534	2.7266183	1.0655059	3567.1646
919.97632	2.7265239	1.0672659	3559.6257
920.97729	2.7294335	1.0692266	3569.1533
921.97827	2.7331026	1.0713958	3570.0134
922.97925	2.7347226	1.0735812	3566.5647
923.98022	2.7396705	1.075972	3561.8289
924.9812	2.7411075	1.0785497	3569.8899
925.98218	2.747412	1.0807924	3562.9282
926.98315	2.7494566	1.0830985	3561.9795
927.98413	2.7517185	1.0853363	3572.6135
928.98511	2.752229	1.0875905	3562.55
929.98608	2.756434	1.0899625	3563.5447
930.98706	2.760149	1.0921832	3564.0564
931.98804	2.7587225	1.0942417	3560.4443
932.98901	2.7636576	1.0966009	3558.7861
933.98999	2.7680392	1.0985767	3559.1792
934.99097	2.7723851	1.1009631	3561.8577
935.99194	2.777211	1.1032933	3565.4609
936.99292	2.7793031	1.1059777	3566.5171
937.9939	2.7819486	1.1081213	3559.4724
938.99487	2.7855737	1.1104063	3566.0679
939.99585	2.786906	1.1128327	3562.4263
940.99683	2.791563	1.1154878	3564.2954
941.9978	2.7937272	1.1176443	3562.8306
942.99878	2.7965858	1.1202582	3560.7546
943.99976	2.7996264	1.1227297	3557.2422
945.00073	2.8037262	1.1249465	3564.4031
946.00171	2.8064234	1.1275226	3562.6526
947.00269	2.8104012	1.1300886	3563.875
948.00366	2.8092372	1.1328121	3559.5559
949.00464	2.8119488	1.1355479	3558.3787
950.00562	2.8168755	1.1378579	3553.1711
951.00659	2.8189287	1.1399974	3554.7327
952.00757	2.8222296	1.1423676	3555.8865
953.00854	2.823544	1.144792	3560.5505
954.00952	2.8278241	1.1470988	3557.2444
955.0105	2.8339608	1.1494069	3560.3994
956.01147	2.8312886	1.1522222	3556.3882
957.01245	2.8374548	1.1551012	3553.8613
958.01343	2.8394861	1.1578821	3560.9275
959.0144	2.8440421	1.1607912	3555.7986
960.01538	2.8467586	1.1631781	3557.8347
961.01636	2.8512201	1.1657381	3555.3765
962.01733	2.8509145	1.167845	3540.2285
963.01831	2.8555739	1.169861	3545.8357
964.01929	2.8583655	1.172276	3555.1975
965.02026	2.861506	1.1745874	3553.0134
966.02124	2.8655183	1.1771792	3554.8279
967.02222	2.8687751	1.1796167	3547.1323
968.02319	2.8721969	1.1822747	3552.3743
969.02417	2.8745418	1.1850406	3555.9365
970.02515	2.877265	1.1872789	3547.3203
971.02612	2.880626	1.1897894	3554.4937
972.0271	2.8824112	1.1923888	3550.5488
973.02808	2.8859856	1.1950053	3548.8579
974.02905	2.8906486	1.1981226	3548.1226
975.03003	2.8923137	1.2010908	3550.1484
976.03101	2.897208	1.2038877	3548.0859
977.03198	2.897011	1.2068191	3544.9219
978.03296	2.9026787	1.2094141	3539.2971
979.03394	2.9014513	1.2120913	3541.1025
980.03491	2.9059823	1.2146275	3545.9509
981.03589	2.9113486	1.2174249	3546.0027
982.03687	2.9129262	1.2203683	3538.7153
983.03784	2.9164412	1.2231827	3538.6226
984.03882	2.9192021	1.2258533	3544.9751
985.03979	2.9219825	1.2288767	3538.084
986.04077	2.9247699	1.2312332	3528.8545
987.04175	2.9259832	1.2335333	3532.7559
988.04272	2.9303112	1.2367271	3543.125
989.0437	2.9350424	1.2398653	3534.4705
990.04468	2.9360874	1.2426246	3536.4194
991.04565	2.9409902	1.2456177	3539.2766
992.04663	2.9455705	1.2487962	3538.73
993.04761	2.9477441	1.2514921	3535.5562
994.04858	2.9489167	1.254115	3532.4099
995.04956	2.9531567	1.2567313	3533.8521
996.05054	2.9559717	1.2592363	3533.7122
997.05151	2.9552424	1.261875	3527.0649
998.05249	2.962302	1.2649735	3531.5703
999.05347	2.9653146	1.2680238	3529.4363
1000.0544	2.9688115	1.2708341	3530.8589
1001.0554	2.9711714	1.2733136	3522.0247
1002.0564	2.9748917	1.2760488	3525.1245
1003.0574	2.9751685	1.2789942	3528.3362
1004.0583	2.9774477	1.2821755	3523.7275
1005.0593	2.9816511	1.2852819	3516.449
1006.0603	2.9837258	1.2882624	3518.9712
1007.0613	2.98984	1.2914283	3518.4478
1008.0623	2.9922333	1.2939942	3521.9231
1009.0632	2.9923823	1.2968661	3516.1497
1010.0642	2.9984574	1.3003137	3519.8916
1011.0652	3.000978	1.3038425	3518.0781
1012.0662	3.0045147	1.3074449	3516.9299
1013.0671	3.0072639	1.3110559	3514.6501
1014.0681	3.0093167	1.3138931	3507.7058
1015.0691	3.0137722	1.3164855	3508.8713
1016.0701	3.0170622	1.318912	3504.4917
1017.071	3.0157011	1.3213978	3505.9329
1018.072	3.0210481	1.3241405	3508.0557
1019.073	3.0263689	1.3271126	3510.658
1020.074	3.0287931	1.3304504	3509.2722
1021.075	3.0307374	1.3334556	3506.626
1022.0759	3.0324838	1.3365337	3501.1941
1023.0769	3.0338337	1.339388	3494.8911
1024.0779	3.0419366	1.3421452	3499.29
1025.0789	3.0423198	1.3452281	3500.7036
1026.0798	3.0465851	1.3484287	3500.418
1027.0808	3.048696	1.3517034	3502.3625
1028.0818	3.0518167	1.3555377	3491.9619
1029.0828	3.0529606	1.3583387	3486.2559
1030.0837	3.0556397	1.360845	3482.0886
1031.0847	3.0613227	1.3633434	3486.2195
1032.0857	3.0632045	1.3661449	3488.072
1033.0867	3.068047	1.3692112	3487.3923
1034.0876	3.0695169	1.371941	3475.4285
1035.0886	3.0701656	1.3746003	3478.2263
1036.0896	3.075783	1.3775693	3483.3223
1037.0906	3.078078	1.380819	3481.4226
1038.0916	3.0820558	1.3840945	3475.8298
1039.0925	3.0834301	1.3872843	3479.6104
1040.0935	3.0856707	1.3902675	3469.4802
1041.0945	3.0890377	1.3923582	3457.8901
1042.0955	3.0936725	1.3942477	3464.7573
1043.0964	3.0951307	1.3965396	3465.4316
1044.0974	3.09852	1.399112	3468.6721
1045.0984	3.1039774	1.4021105	3468.3313
1046.0994	3.106111	1.405279	3466.6516
1047.1003	3.1065471	1.4088476	3465.8601
1048.1013	3.1124043	1.4126041	3459.9807
1049.1023	3.1143312	1.4159354	3461.3496
1050.1033	3.1201234	1.418955	3457.8298
1051.1042	3.1200287	1.422116	3455.8401
1052.1052	3.1241601	1.4252405	3454.147
1053.1062	3.1256046	1.4281601	3453.2102
1054.1072	3.1301851	1.4315113	3447.8762
1055.1082	3.1296799	1.4350096	3445.9526
1056.1091	3.1359186	1.4382768	3445.989
1057.1101	3.1386328	1.4408569	3441.6108
1058.1111	3.1386824	1.4436017	3444.4409
1059.1121	3.1443098	1.446505	3439.2119
1060.113	3.1477699	1.4493197	3431.0405
1061.114	3.1505916	1.4524347	3431.5645
1062.115	3.1536896	1.4554756	3431.7991
1063.116	3.1556323	1.4587371	3425.6519
1064.1169	3.1593397	1.4619774	3425.6636
1065.1179	3.1617956	1.4649564	3419.5703
1066.1189	3.1670201	1.4679803	3418.0989
1067.1199	3.167897	1.470928	3421.0007
1068.1208	3.1704302	1.4741232	3409.1069
1069.1218	3.1771481	1.4773664	3421.1658
1070.1228	3.1781073	1.4806715	3415.7539
1071.1238	3.183748	1.4841617	3411.5461
1072.1248	3.1830764	1.4875361	3405.7339
1073.1257	3.186202	1.4912378	3405.4546
1074.1267	3.1913121	1.4950535	3403.8816
1075.1277	3.1908369	1.4984221	3399.5881
1076.1287	3.1984754	1.501659	3390.3962
1077.1296	3.1985512	1.5040822	3389.7427
1078.1306	3.2043138	1.5068796	3393.0945
1079.1316	3.206095	1.5094374	3385.1672
1080.1326	3.2069097	1.5124532	3390.856
1081.1335	3.2103713	1.5156811	3388.7959
1082.1345	3.214355	1.5192446	3378.3733
1083.1355	3.2183015	1.5223182	3376.9712
1084.1365	3.2200027	1.5254523	3372.5642
1085.1375	3.2241168	1.5287871	3370.1907
1086.1384	3.2257349	1.5321153	3372.407
1087.1394	3.2291451	1.5354283	3373.9243
1088.1404	3.2327425	1.5390402	3362.4656
1089.1414	3.2344413	1.5423257	3359.4424
1090.1423	3.2362027	1.5453707	3352.5977
1091.1433	3.2415268	1.5486561	3356.1609
1092.1443	3.2423439	1.5512745	3346.0989
1093.1453	3.2451432	1.5542325	3344.6909
1094.1462	3.2487283	1.5575321	3349.0313
1095.1472	3.2498248	1.5603284	3337.4985
1096.1482	3.2556312	1.5637033	3338.9353
1097.1492	3.2606711	1.5670934	3336.0386
1098.1501	3.2635458	1.5705656	3335.821
1099.1511	3.2651529	1.5741938	3328.7424
1100.1521	3.2699852	1.577861	3322.8655
1101.1531	3.2707517	1.5809034	3319.4055
1102.1541	3.2741108	1.5840634	3315.7202
1103.155	3.2784035	1.5870776	3313.6035
1104.156	3.2818782	1.5904098	3309.1548
1105.157	3.280767	1.5944145	3308.0342
1106.158	3.2845283	1.5974094	3294.2004
1107.1589	3.2897422	1.6000677	3295.8479
1108.1599	3.2925062	1.6027491	3293.4202
1109.1609	3.2918534	1.6056724	3289.7839
1110.1619	3.3013792	1.6090161	3287.2537
1111.1628	3.3012414	1.6123356	3282.9758
1112.1638	3.302712	1.6161028	3274.3352
1113.1648	3.3060706	1.6197966	3275.7793
1114.1658	3.310956	1.6233326	3267.679
1115.1667	3.3146009	1.6266654	3266.0371
1116.1677	3.3139997	1.6291708	3250.3826
1117.1687	3.3188674	1.6323996	3256.4768
1118.1697	3.3231266	1.6357574	3254.2141
1119.1707	3.3271043	1.6395246	3244.8181
1120.1716	3.3264244	1.6433609	3237.9526
1121.1726	3.3322511	1.6472791	3233.3301
1122.1736	3.3341238	1.6511014	3222.7952
1123.1746	3.3365321	1.6546987	3210.8794
1124.1755	3.341428	1.6577226	3206.866
1125.1765	3.3418987	1.6607378	3204.6538
1126.1775	3.3448539	1.6643146	3193.1934
1127.1785	3.3514633	1.668566	3183.5225
1128.1794	3.352282	1.6731035	3175.7966
1129.1804	3.3548441	1.6771886	3154.8579
1130.1814	3.3594904	1.6809314	3143.2581
1131.1824	3.3629444	1.6848141	3134.314
1132.1833	3.3624656	1.6913505	3091.3362
1133.1843	3.3676939	1.6984576	3042.5259
1133.5847	3.3695807	1.7071619	2958.1785