File: datasets/am_bench_2022/raw_data/30-XY.12-1/specimen.dat
MTS793|MPT|ENU|1|2|.|/|:|1|0|0|A

Operator Information						Time:	30.564209	Sec	10/18/2021 12:08:22 PM
Operator	Nick Derimow
Project	AM Bench 2022 mini-tensile challenge
Specimen ID	30-XY.12-1
Material	PBF-L Inconel 625
Specimen Width	2.54	mm
Specimen Thickness	1.5	mm
Notes
Operator Information End

Data Acquisition						Time:	1031.5579	Sec	10/18/2021 12:25:03 PM
Time	Axial Displacement	Axial Extensometer	Axial Force
Sec	mm	mm	N
30.677734	-0.00072922197	4.4717308e-05	68.02198
31.678711	0.0067414101	0.00015406148	84.533424
32.679688	0.0067612845	0.00018844627	100.48769
33.680664	0.0091852983	0.00019848593	111.96852
34.681641	0.013890619	0.0002535432	121.75999
35.682617	0.016314019	0.00029110382	136.11258
36.683594	0.020217549	0.00047033629	150.49077
37.68457	0.021574697	0.00056385162	161.42482
38.685547	0.02740364	0.00056145026	189.58107
39.686523	0.028344242	0.00067826477	202.27293
40.6875	0.029827448	0.00075503741	221.73149
41.688477	0.035877161	0.00082360522	244.49565
42.689453	0.037507888	0.00086810649	256.5289
43.69043	0.041133638	0.001009136	280.70441
44.691406	0.042628266	0.0010505691	305.71558
45.692383	0.046231225	0.0011855001	325.20322
46.693359	0.047337841	0.0013354782	344.86505
47.694336	0.049090222	0.0013056593	362.6308
48.695313	0.054285642	0.00143991	386.89532
49.696289	0.059075274	0.0014779572	402.67392
50.697266	0.061629444	0.0016590594	433.33148
51.698242	0.064773038	0.001700012	450.88925
52.699219	0.06908799	0.0018143361	479.24716
53.700195	0.069959797	0.0019691291	498.50223
54.701172	0.07291387	0.0020161259	526.43738
55.702148	0.073699214	0.0020811951	545.17401
56.703125	0.075816303	0.0022910866	574.98254
57.704102	0.08190684	0.0023902662	606.59082
58.705078	0.083359718	0.0025619699	629.33539
59.706055	0.087551534	0.0026187042	659.58441
60.707031	0.091731258	0.0027306392	679.58051
61.708008	0.095456123	0.0028124214	705.49335
62.708984	0.096879095	0.0029269964	730.1369
63.709961	0.09996818	0.0030776784	754.84485
64.710938	0.10282144	0.0031205416	779.40906
65.711914	0.10496317	0.0034129343	809.30676
66.712891	0.10871365	0.003426498	836.90985
67.713867	0.11200809	0.0035831556	864.40045
68.714844	0.11396987	0.0037228412	886.82397
69.71582	0.11728843	0.0038427084	917.7569
70.716797	0.11928776	0.0039111329	946.70685
71.717773	0.12397397	0.0040417989	970.15594
72.71875	0.12552516	0.0041728616	995.84192
73.719727	0.1288159	0.0043799551	1025.9492
74.720703	0.13288561	0.0044739004	1056.202
75.72168	0.13278623	0.0044693723	1074.9026
76.722656	0.1371143	0.004659079	1103.6116
77.723633	0.14241862	0.0048962864	1142.1312
78.724609	0.14465992	0.0050065452	1168.3453
79.725586	0.14720078	0.0051385392	1194.2941
80.726563	0.14983746	0.0052316641	1223.5452
81.727539	0.1552199	0.0053351466	1248.5372
82.728516	0.1567885	0.0055435994	1281.9159
83.729492	0.15918715	0.0056977244	1311.9081
84.730469	0.16175669	0.005830321	1335.1769
85.731445	0.16539489	0.0058403234	1361.1056
86.732422	0.16765068	0.0060619675	1388.6593
87.733398	0.1706695	0.0062084841	1421.9625
88.734375	0.17449686	0.0063440213	1448.015
89.735352	0.1762853	0.0064926893	1479.3097
90.736328	0.18040192	0.0065945098	1504.5264
91.737305	0.18308942	0.0066131754	1526.004
92.738281	0.18683811	0.0067737997	1556.6105
93.739258	0.18894808	0.0068882261	1585.5392
94.740234	0.19374385	0.0071048914	1616.5306
95.741211	0.19702739	0.0072039068	1633.8051
96.742188	0.19839053	0.007320873	1658.3302
97.743164	0.20174828	0.0074955006	1687.3044
98.744141	0.20893084	0.0075865397	1713.0859
99.745117	0.20729519	0.0077183121	1738.3468
100.74609	0.21194986	0.0077807088	1761.5051
101.74707	0.21377359	0.0079753287	1793.2281
102.74805	0.21584606	0.0080219246	1817.9476
103.74902	0.22217278	0.0082190717	1848.8528
104.75	0.22259691	0.0082816416	1873.4528
105.75098	0.22645763	0.0084100571	1900.2611
106.75195	0.23043163	0.0085224677	1914.9094
107.75293	0.23245965	0.0086991759	1942.8828
108.75391	0.23616238	0.0087708943	1960.7737
109.75488	0.23864582	0.0089186188	1979.5903
110.75586	0.24356785	0.0090567265	2009.7726
111.75684	0.24402088	0.0090771662	2020.4456
112.75781	0.24829116	0.0092150029	2044.8241
113.75879	0.24956496	0.009245323	2058.3025
114.75977	0.25305688	0.0094323615	2081.6899
115.76074	0.25767794	0.0095458031	2105.6018
116.76172	0.25843686	0.0095268432	2114.3877
117.7627	0.26415893	0.0097415624	2141.0718
118.76367	0.26724991	0.0098557305	2155.9976
119.76465	0.2684553	0.010000697	2175.2527
120.76563	0.27169129	0.010036955	2192.98
121.7666	0.27531371	0.010047109	2202.2905
122.76758	0.27382886	0.010154623	2216.1931
123.76855	0.28048635	0.010303859	2236.1294
124.76953	0.28581756	0.01041956	2257.2356
125.77051	0.28419012	0.010438008	2266.0417
126.77148	0.2883141	0.010664664	2280.9604
127.77246	0.29505661	0.010758229	2302.6714
128.77344	0.29766503	0.010771649	2314.9666
129.77441	0.29674301	0.010831934	2323.6301
130.77539	0.30050087	0.010903314	2332.5583
131.77637	0.30359241	0.010958851	2343.4011
132.77734	0.30791396	0.011075322	2360.8953
133.77832	0.31234202	0.011177463	2373.2822
134.7793	0.31342119	0.011313542	2380.3047
135.78027	0.31752527	0.01131821	2388.7327
136.78125	0.32239243	0.011380504	2405.2869
137.78223	0.3231954	0.011552327	2422.6602
138.7832	0.32555038	0.011631225	2427.2605
139.78418	0.32848027	0.011722635	2445.1672
140.78516	0.33030313	0.01178731	2447.9827
141.78613	0.33864787	0.011974066	2470.9182
142.78711	0.33909556	0.012076329	2474.7791
143.78809	0.34046888	0.012099478	2485.2695
144.78906	0.34324169	0.012194444	2489.8013
145.79004	0.34511453	0.012303744	2507.8271
146.79102	0.35197628	0.012370615	2518.1519
147.79199	0.35371274	0.012562965	2529.9399
148.79297	0.35823581	0.0125944	2537.1858
149.79395	0.35968295	0.012623694	2542.4678
150.79492	0.36316979	0.012888209	2555.2781
151.7959	0.36604989	0.012860599	2566.8428
152.79688	0.36747056	0.013087467	2579.7385
153.79785	0.36978173	0.013169399	2578.9626
154.79883	0.37260979	0.013411573	2592.3623
155.7998	0.37858436	0.013442244	2592.7769
156.80078	0.38207564	0.013546906	2599.239
157.80176	0.38372993	0.013749667	2613.7339
158.80273	0.387095	0.013854435	2627.6277
159.80371	0.38754186	0.014040207	2633.4592
160.80469	0.38986963	0.014147988	2635.0339
161.80566	0.39515245	0.014276617	2646.0225
162.80664	0.39997777	0.01446595	2665.3782
163.80762	0.40014988	0.014693795	2668.6846
164.80859	0.40556368	0.014784032	2673.1318
165.80957	0.4077664	0.014929866	2679.8308
166.81055	0.41116098	0.015133346	2692.9072
167.81152	0.41568866	0.015356962	2701.4805
168.8125	0.41439274	0.015566579	2705.4729
169.81348	0.42009458	0.015767885	2710.0305
170.81445	0.42157385	0.016053202	2719.3677
171.81543	0.42624921	0.016299285	2738.8267
172.81641	0.42974177	0.016371407	2739.741
173.81738	0.43083754	0.016723372	2745.99
174.81836	0.43443492	0.017052403	2753.4607
175.81934	0.43856177	0.01740614	2755.2632
176.82031	0.43822452	0.01760333	2766.2527
177.82129	0.44395533	0.017803404	2767.7966
178.82227	0.44489348	0.018164923	2778.2798
179.82324	0.45045313	0.01854825	2788.1233
180.82422	0.45440626	0.01890876	2794.1123
181.8252	0.45519304	0.01930758	2796.9624
182.82617	0.45741424	0.019690417	2806.8691
183.82715	0.4616552	0.019982966	2807.0237
184.82813	0.46471947	0.020350315	2814.7935
185.8291	0.46814546	0.020876223	2830.521
186.83008	0.47113851	0.021406585	2835.9771
187.83105	0.47412661	0.02196414	2842.7112
188.83203	0.47803521	0.022186317	2834.5603
189.83301	0.47787237	0.022782015	2846.9023
190.83398	0.48454171	0.023225496	2850.4758
191.83496	0.48504549	0.023580171	2849.3145
192.83594	0.48909858	0.024256451	2864.2878
193.83691	0.4922342	0.024906136	2870.4712
194.83789	0.49573106	0.025527904	2869.5952
195.83887	0.50002575	0.02604253	2878.4861
196.83984	0.50026852	0.026680168	2883.9028
197.84082	0.50501454	0.027428696	2886.2993
198.8418	0.50532019	0.028098775	2888.0315
199.84277	0.51021445	0.028829975	2899.2808
200.84375	0.51218176	0.029595489	2898.6729
201.84473	0.51421756	0.030307868	2903.5764
202.8457	0.51854926	0.031112393	2905.8584
203.84668	0.52005851	0.03192297	2906.6018
204.84766	0.52869451	0.032630309	2914.7927
205.84863	0.52615148	0.033391465	2915.1594
206.84961	0.53066927	0.034296956	2925.6611
207.85059	0.53352642	0.035133816	2926.1016
208.85156	0.53889573	0.036017135	2930.7952
209.85254	0.54039145	0.037064172	2933.8982
210.85352	0.54323262	0.038083389	2937.8328
211.85449	0.54499429	0.038885966	2933.6711
212.85547	0.54989439	0.039820511	2938.5896
213.85645	0.55344099	0.040691104	2944.6411
214.85742	0.55638933	0.041667677	2951.937
215.8584	0.55836183	0.042721674	2950.5486
216.85938	0.5631308	0.043901194	2958.0225
217.86035	0.56426549	0.044960327	2957.1777
218.86133	0.57000667	0.046008307	2971.1743
219.8623	0.57015193	0.046983607	2955.2485
220.86328	0.5771364	0.047729068	2962.8616
221.86426	0.57621908	0.048584249	2960.6504
222.86523	0.58017445	0.049773723	2982.1501
223.86621	0.58245158	0.050895017	2978.1199
224.86719	0.58535367	0.052001715	2974.7307
225.86816	0.58658969	0.052963223	2976.1528
226.86914	0.58927232	0.05378608	2976.3643
227.87012	0.59586972	0.054821741	2988.4111
228.87109	0.59603649	0.055770565	2982.8943
229.87207	0.6010319	0.056873672	2988.95
230.87305	0.60329145	0.057928786	2990.5242
231.87402	0.60600722	0.059025642	2994.803
232.875	0.60819507	0.06006863	2996.9236
233.87598	0.6126743	0.061087679	3000.6777
234.87695	0.61521471	0.062248241	3003.2915
235.87793	0.61554623	0.063337587	3002.8706
236.87891	0.62041682	0.064654984	3007.3408
237.87988	0.62396306	0.065679081	3006.5815
238.88086	0.62427366	0.066580921	3004.9844
239.88184	0.63096905	0.067622602	3011.6931
240.88281	0.63360202	0.068743341	3015.668
241.88379	0.63681102	0.069875903	3019.323
242.88477	0.63891643	0.071077116	3017.3914
243.88574	0.64326072	0.072108746	3014.0403
244.88672	0.64663255	0.0732916	3029.2178
245.8877	0.64979559	0.074513391	3029.3931
246.88867	0.6507082	0.075849697	3028.9917
247.88965	0.6534307	0.077143781	3030.6008
248.89063	0.65920597	0.078289814	3033.7759
249.8916	0.66101021	0.079581439	3032.7683
250.89258	0.66167343	0.080804974	3035.2078
251.89355	0.66477853	0.082058758	3035.2207
252.89453	0.66960162	0.083234459	3045.5627
253.89551	0.67203957	0.084397882	3040.6489
254.89648	0.67408127	0.085546091	3039.7544
255.89746	0.67654502	0.086656719	3041.3489
256.89844	0.68035227	0.087722167	3046.0154
257.89941	0.68475395	0.088852458	3050.697
258.90039	0.68558294	0.090021141	3052.0657
259.90137	0.69156379	0.091307938	3053.1482
260.90234	0.69190514	0.092307538	3051.2922
261.90332	0.69645572	0.093350664	3053.2617
262.9043	0.69719946	0.094557375	3049.968
263.90527	0.70015395	0.095526636	3053.2314
264.90625	0.70548415	0.096875243	3063.8018
265.90723	0.70971918	0.098077826	3067.0007
266.9082	0.70705438	0.099213682	3063.8884
267.90918	0.71380383	0.10037854	3068.4622
268.91016	0.71829355	0.10166216	3071.761
269.91113	0.72129643	0.10288925	3073.1155
270.91211	0.72043115	0.10409389	3072.5723
271.91309	0.7264598	0.10524371	3073.8459
272.91406	0.73021543	0.10664608	3079.0005
273.91504	0.73438221	0.10775182	3078.1367
274.91602	0.73611522	0.10893264	3081.376
275.91699	0.73813933	0.11032031	3084.6555
276.91797	0.74188322	0.11146495	3080.5298
277.91895	0.74569905	0.11259004	3082.4922
278.91992	0.7462064	0.11375061	3085.5129
279.9209	0.7521674	0.11506116	3089.103
280.92188	0.75401878	0.11643417	3092.0208
281.92285	0.75443345	0.11770781	3087.9326
282.92383	0.75819093	0.11884373	3090.9771
283.9248	0.76133263	0.12002356	3090.6743
284.92578	0.76629859	0.12130819	3098.9917
285.92676	0.76540363	0.1225094	3096.0786
286.92773	0.76788646	0.12374347	3095.856
287.92871	0.77369565	0.12484344	3100.4846
288.92969	0.77920473	0.12592934	3099.9714
289.93066	0.78317976	0.12687723	3106.896
290.93164	0.78399521	0.12801884	3107.0894
291.93262	0.7834394	0.12930059	3104.0208
292.93359	0.78716606	0.13055226	3109.6035
293.93457	0.79362988	0.13185473	3113.6382
294.93555	0.79358131	0.13317138	3112.542
295.93652	0.79808909	0.13436839	3111.7935
296.9375	0.79944175	0.13520925	3106.7761
297.93848	0.8050158	0.13654317	3118.6436
298.93945	0.80799627	0.13786452	3111.4592
299.94043	0.80964625	0.13895713	3112.1409
300.94141	0.81182808	0.14004141	3116.1619
301.94238	0.81569022	0.14099513	3117.3799
302.94336	0.81794035	0.14215732	3122.0527
303.94434	0.82057542	0.14343095	3126.282
304.94531	0.82575846	0.14478152	3133.2368
305.94629	0.82706529	0.14587328	3122.5884
306.94727	0.82932329	0.14704204	3122.8916
307.94824	0.8346228	0.14815384	3135.356
308.94922	0.83528292	0.14938332	3128.7051
309.9502	0.84021872	0.15052582	3135.9236
310.95117	0.84457487	0.15194196	3141.9297
311.95215	0.84551305	0.15333587	3135.772
312.95313	0.84909773	0.15452284	3129.4758
313.9541	0.85128838	0.15561247	3135.6338
314.95508	0.85441107	0.15700692	3143.364
315.95605	0.85776722	0.15832323	3141.5715
316.95703	0.8629126	0.1594746	3148.7039
317.95801	0.8645584	0.16081363	3146.3452
318.95898	0.87016296	0.1620298	3149.8406
319.95996	0.87122715	0.16340272	3150.3887
320.96094	0.87239301	0.16448818	3146.813
321.96191	0.87514359	0.16573445	3148.5083
322.96289	0.87749368	0.16686119	3145.0029
323.96387	0.8815195	0.16793449	3151.4541
324.96484	0.88355142	0.16896428	3154.0542
325.96582	0.88935632	0.17007963	3157.7502
326.9668	0.89259702	0.17132968	3161.0122
327.96777	0.89086843	0.17253163	3158.8694
328.96875	0.8990525	0.17376782	3164.8508
329.96973	0.90114641	0.17500383	3161.9485
330.9707	0.90530854	0.17627555	3172.4131
331.97168	0.90779769	0.17758594	3167.8889
332.97266	0.90849268	0.17878951	3162.9558
333.97363	0.91456008	0.18006957	3169.0122
334.97461	0.91327691	0.18101972	3164.9561
335.97559	0.91958719	0.18226141	3176.78
336.97656	0.92202371	0.18319027	3166.0876
337.97754	0.9242726	0.18421969	3174.8379
338.97852	0.92838085	0.18542312	3177.5554
339.97949	0.93049836	0.18673016	3175.3608
340.98047	0.93233907	0.18791197	3180.3403
341.98145	0.93586767	0.18910281	3179.2971
342.98242	0.94080245	0.19036879	3181.4556
343.9834	0.94219851	0.19162992	3183.6487
344.98438	0.94441688	0.19274649	3180.5039
345.98535	0.94895655	0.19398017	3183.5474
346.98633	0.95261633	0.19509353	3184.1709
347.9873	0.95402491	0.19640225	3190.8711
348.98828	0.95815688	0.19768099	3189.0928
349.98926	0.96285373	0.19887629	3192.6243
350.99023	0.96345282	0.19978271	3193.3557
351.99121	0.96800613	0.20095003	3188.751
352.99219	0.96948683	0.20231755	3195.4373
353.99316	0.97406548	0.20348872	3197.6523
354.99414	0.97612089	0.20464836	3195.6853
355.99512	0.98101592	0.20573442	3192.6831
356.99609	0.98064959	0.2069823	3202.4763
357.99707	0.98402739	0.20822211	3203.1084
358.99805	0.9872697	0.20941992	3198.6323
359.99902	0.99059421	0.2105993	3201.1738
361	0.99326682	0.21185175	3202.71
362.00098	0.9952032	0.21282455	3206.043
363.00195	1.0000222	0.21416457	3208.3027
364.00293	1.0031594	0.2154641	3212.2644
365.00391	1.0042337	0.2166625	3208.604
366.00488	1.0093387	0.21794002	3213.5815
367.00586	1.0088353	0.21914467	3212.1885
368.00684	1.0148897	0.22059818	3220.8123
369.00781	1.0164168	0.22170438	3209.1777
370.00879	1.0227362	0.22290501	3215.646
371.00977	1.0245918	0.22416635	3228.3323
372.01074	1.0271136	0.22529061	3217.2407
373.01172	1.0275083	0.22629851	3215.8552
374.0127	1.034189	0.22760004	3220.5649
375.01367	1.0362146	0.22864407	3218.739
376.01465	1.0387758	0.22968164	3219.7412
377.01563	1.0417746	0.23075475	3222.0083
378.0166	1.0467415	0.23188728	3223.9944
379.01758	1.0482805	0.23301187	3226.9546
380.01855	1.0501518	0.23429911	3229.0361
381.01953	1.056116	0.23553453	3233.2253
382.02051	1.059092	0.23692708	3238.8701
383.02148	1.0602366	0.23822272	3229.3179
384.02246	1.0629195	0.23932682	3227.9263
385.02344	1.0656222	0.24054259	3233.5378
386.02441	1.0656285	0.24169369	3231.8291
387.02539	1.0724138	0.24289486	3231.0928
388.02637	1.0716249	0.24404325	3239.6143
389.02734	1.0768263	0.24535468	3237.2476
390.02832	1.0837796	0.24664347	3247.7693
391.0293	1.0842906	0.24792415	3247.1587
392.03027	1.08667	0.24925102	3242.7988
393.03125	1.0889906	0.25036976	3239.9324
394.03223	1.092603	0.25160292	3242.4385
395.0332	1.096671	0.25267124	3247.3442
396.03418	1.1007475	0.25386977	3241.772
397.03516	1.1027107	0.25472519	3248.6187
398.03613	1.1033223	0.25588003	3247.2778
399.03711	1.1097783	0.25735459	3255.8611
400.03809	1.1085601	0.25833303	3252.5679
401.03906	1.113638	0.25972807	3258.3845
402.04004	1.1141201	0.26089618	3253.9082
403.04102	1.1190572	0.26233995	3258.0957
404.04199	1.1239046	0.26364347	3255.2002
405.04297	1.1270101	0.26479551	3261.7773
406.04395	1.1296308	0.26580298	3260.6455
407.04492	1.130927	0.2669563	3255.5225
408.0459	1.1342763	0.26815867	3259.3643
409.04688	1.1365638	0.26939985	3265.554
410.04785	1.1408648	0.27063596	3263.9209
411.04883	1.1436154	0.27137408	3254.9937
412.0498	1.1440886	0.27233273	3257.2104
413.05078	1.1489964	0.27350664	3270.0317
414.05176	1.1512049	0.27457926	3266.6304
415.05273	1.1543753	0.27577657	3270.3323
416.05371	1.1593	0.27710453	3271.7744
417.05469	1.1642232	0.27822903	3277.5962
418.05566	1.1631063	0.27931857	3272.5117
419.05664	1.1688361	0.28054008	3280.3359
420.05762	1.1702056	0.28180441	3277.1992
421.05859	1.1721227	0.28276718	3273.2107
422.05957	1.1755532	0.2839902	3280.3313
423.06055	1.1799058	0.28544989	3285.4753
424.06152	1.1854054	0.28674287	3281.4082
425.0625	1.1863598	0.2882084	3288.1216
426.06348	1.1866251	0.28943649	3281.3496
427.06445	1.1926103	0.29081291	3283.8997
428.06543	1.1965642	0.29179996	3284.1646
429.06641	1.197451	0.29287016	3284.0154
430.06738	1.1982429	0.29393396	3284.3191
431.06836	1.2041056	0.29500538	3286.2954
432.06934	1.2055224	0.29619536	3291.6277
433.07031	1.2104522	0.29743549	3294.1169
434.07129	1.2107059	0.29864457	3288.7878
435.07227	1.2129285	0.29978314	3293.3762
436.07324	1.2190018	0.30084908	3290.5525
437.07422	1.2187029	0.30199823	3292.4329
438.0752	1.2249463	0.30327114	3299.0417
439.07617	1.2279044	0.30428651	3297.7454
440.07715	1.2308573	0.30573303	3298.2026
441.07813	1.2331963	0.30681413	3298.1152
442.0791	1.2380784	0.30789453	3300.9001
443.08008	1.2404606	0.30888221	3294.9927
444.08105	1.2440665	0.30990636	3301.0544
445.08203	1.2469482	0.31111354	3300.6079
446.08301	1.249503	0.31225416	3305.4146
447.08398	1.2540648	0.31332013	3301.4333
448.08496	1.2545819	0.31443891	3302.5293
449.08594	1.2550725	0.31548077	3302.7859
450.08691	1.2614657	0.31650284	3307.408
451.08789	1.2652245	0.31774762	3311.8435
452.08887	1.2677009	0.31898886	3308.4348
453.08984	1.2690589	0.32007584	3306.3005
454.09082	1.2715125	0.32133421	3320.1025
455.0918	1.2776666	0.32240722	3313.2717
456.09277	1.2787279	0.32374361	3313.9375
457.09375	1.2831639	0.32509488	3314.2639
458.09473	1.2829641	0.32636976	3316.0447
459.0957	1.2869357	0.32754758	3317.3535
460.09668	1.2921782	0.32884911	3320.3018
461.09766	1.2930866	0.33014429	3325.1726
462.09863	1.2966137	0.33150148	3319.7581
463.09961	1.3006504	0.33280388	3321.4021
464.10059	1.3045168	0.33372653	3324.4309
465.10156	1.3078917	0.33471462	3324.8928
466.10254	1.3112924	0.33586326	3325.5537
467.10352	1.3115997	0.33707219	3329.0317
468.10449	1.3142189	0.33814517	3326.2029
469.10547	1.3165598	0.33928683	3326.7627
470.10645	1.3211117	0.34048828	3329.5522
471.10742	1.3245869	0.34159181	3334.1602
472.1084	1.3302312	0.34292263	3339.3584
473.10938	1.3278546	0.34419784	3336.9075
474.11035	1.3340495	0.34541306	3333.7661
475.11133	1.3350419	0.34648499	3329.2085
476.1123	1.3370849	0.34775156	3333.9329
477.11328	1.3421655	0.34884372	3334.0776
478.11426	1.3462796	0.34991851	3335.0205
479.11523	1.3467237	0.35110256	3342.0105
480.11621	1.3526013	0.35226247	3338.8337
481.11719	1.3517557	0.35328671	3336.157
482.11816	1.357147	0.35437551	3340.6123
483.11914	1.3569748	0.35557327	3341.5835
484.12012	1.3644238	0.35692129	3350.7126
485.12109	1.3659867	0.35803324	3343.292
486.12207	1.3701394	0.35921696	3349.5181
487.12305	1.3722585	0.36047167	3344.2595
488.12402	1.3783138	0.36157355	3347.2585
489.125	1.3796781	0.36285394	3348.2112
490.12598	1.3802043	0.36408815	3355.8455
491.12695	1.3838454	0.36527091	3355.1514
492.12793	1.3867264	0.36643067	3350.0195
493.12891	1.3894321	0.36763337	3358.5083
494.12988	1.3921458	0.36887568	3357.833
495.13086	1.3955966	0.37015936	3351.8501
496.13184	1.3990464	0.37140611	3362.3193
497.13281	1.4030747	0.37273473	3361.562
498.13379	1.4051067	0.3739877	3354.5737
499.13477	1.4081378	0.37515509	3361.3796
500.13574	1.4101404	0.37638208	3364.9014
501.13672	1.4122858	0.37753817	3359.3145
502.1377	1.4197801	0.37866303	3364.6748
503.13867	1.4197408	0.37982649	3367.5708
504.13965	1.4268708	0.38091204	3366.6067
505.14063	1.4272224	0.38184804	3364.3398
506.1416	1.4290466	0.38322136	3369.2832
507.14258	1.4337507	0.38438463	3369.4797
508.14355	1.4359823	0.38552311	3371.4338
509.14453	1.4372371	0.38665873	3369.9258
510.14551	1.44238	0.38790929	3374.2168
511.14648	1.4441451	0.3890523	3372.4797
512.14746	1.4499855	0.3902446	3372.9182
513.14844	1.4490337	0.39121273	3375.1621
514.14941	1.4522878	0.39242297	3373.3694
515.15039	1.4564745	0.39369729	3375.8533
516.15137	1.4608976	0.39480439	3378.4106
517.15234	1.4626486	0.39583662	3375.2112
518.15332	1.4643328	0.39706904	3380.5562
519.1543	1.4690918	0.39816076	3376.4688
520.15527	1.4743148	0.39932132	3383.7473
521.15625	1.4730022	0.40044168	3378.9346
522.15723	1.4764338	0.40167314	3384.1013
523.1582	1.4794083	0.4028714	3384.3896
524.15918	1.4854469	0.40425628	3388.8552
525.16016	1.4858702	0.40538195	3380.6204
526.16113	1.4905076	0.4064703	3387.6042
527.16211	1.4930406	0.40774405	3390.7458
528.16309	1.4952585	0.4089537	3391.699
529.16406	1.4984902	0.41021121	3386.2466
530.16504	1.5019498	0.41141924	3384.9958
531.16602	1.5053838	0.41281289	3397.7612
532.16699	1.5073326	0.41404346	3393.5906
533.16797	1.510181	0.41490588	3388.7659
534.16895	1.5134419	0.41614759	3389.7446
535.16992	1.5178562	0.41739187	3393.1448
536.1709	1.5185298	0.41854578	3395.4888
537.17188	1.5216652	0.41979703	3399.0713
538.17285	1.5245596	0.42100179	3394.6057
539.17383	1.5287365	0.42230314	3398.3989
540.1748	1.5343752	0.42338499	3403.0496
541.17578	1.5335066	0.42454311	3401.3708
542.17676	1.535455	0.42568669	3397.9407
543.17773	1.539061	0.42685789	3403.4622
544.17871	1.5406059	0.42810181	3405.8943
545.17969	1.5467761	0.42932403	3405.1223
546.18066	1.5502068	0.430482	3410.1394
547.18164	1.5502932	0.43174437	3401.2744
548.18262	1.5554277	0.432798	3402.5776
549.18359	1.5562594	0.43377402	3399.4128
550.18457	1.561977	0.43495542	3403.5806
551.18555	1.5662503	0.43591654	3407.8818
552.18652	1.5684277	0.43702683	3409.4736
553.1875	1.5690881	0.43815368	3408.0659
554.18848	1.5736116	0.43929511	3415.0386
555.18945	1.5774174	0.4406499	3417.553
556.19043	1.5780638	0.44176617	3411.4092
557.19141	1.5809209	0.44292513	3413.2273
558.19238	1.5845829	0.44405749	3413.3782
559.19336	1.5881603	0.44536379	3418.8806
560.19434	1.5931883	0.44663963	3419.7549
561.19531	1.5972534	0.44742596	3410.3337
562.19629	1.5977534	0.44862676	3416.894
563.19727	1.6004045	0.44981951	3418.9443
564.19824	1.604068	0.45096806	3423.2632
565.19922	1.6063548	0.45225441	3421.0623
566.2002	1.6080558	0.45362464	3424.9084
567.20117	1.6138368	0.45513803	3429.4778
568.20215	1.6180958	0.45644283	3427.2966
569.20313	1.6178632	0.45769107	3421.5935
570.2041	1.6231401	0.45878655	3427.6433
571.20508	1.622936	0.45992401	3427.5588
572.20605	1.6253995	0.46105096	3422.5293
573.20703	1.6307814	0.46236056	3433.6003
574.20801	1.6362439	0.46370682	3429.031
575.20898	1.638422	0.46485323	3432.8823
576.20996	1.6406742	0.46609175	3438.9241
577.21094	1.6419396	0.46732682	3434.5081
578.21191	1.6467199	0.46856639	3431.6697
579.21289	1.6481829	0.46975872	3429.4646
580.21387	1.6517183	0.47111064	3434.4666
581.21484	1.6560371	0.47249123	3441.6116
582.21582	1.6568069	0.47341126	3428.4446
583.2168	1.6588266	0.474558	3433.3562
584.21777	1.6626052	0.47554213	3432.0359
585.21875	1.6672171	0.4765414	3431.1489
586.21973	1.6697496	0.47745618	3437.6975
587.2207	1.6727912	0.47856501	3438.0105
588.22168	1.6771338	0.47987136	3445.1726
589.22266	1.6757902	0.48117447	3440.1006
590.22363	1.6818428	0.48240402	3442.2456
591.22461	1.6846765	0.48384559	3446.937
592.22559	1.6871415	0.48506457	3447.5461
593.22656	1.6913608	0.4860476	3442.7168
594.22754	1.6918895	0.48704621	3435.9233
595.22852	1.6956633	0.48832735	3444.4155
596.22949	1.700505	0.48954859	3447.3298
597.23047	1.7035573	0.49072406	3446.895
598.23145	1.7041285	0.49220163	3452.426
599.23242	1.7103155	0.49310821	3441.9824
600.2334	1.7108921	0.49432096	3446.6494
601.23438	1.7156231	0.49562272	3456.7251
602.23535	1.7193747	0.49684137	3455.7273
603.23633	1.721168	0.49810195	3455.3809
604.2373	1.7206572	0.49940795	3453.5469
605.23828	1.725789	0.5008558	3456.4546
606.23926	1.729248	0.50229138	3454.6345
607.24023	1.7341533	0.50344777	3457.311
608.24121	1.7371371	0.50460255	3452.5322
609.24219	1.7377044	0.50574064	3452.8411
610.24316	1.7413729	0.50697666	3461.2654
611.24414	1.7443467	0.50811571	3465.7622
612.24512	1.7468499	0.509597	3463.1301
613.24609	1.7510893	0.51096618	3460.0698
614.24707	1.7544762	0.51204914	3457.9211
615.24805	1.7577131	0.51321441	3459.9253
616.24902	1.7588494	0.51457965	3467.1033
617.25	1.7601594	0.51557428	3460.2202
618.25098	1.764906	0.51681226	3461.1868
619.25195	1.7689718	0.5181123	3466.5806
620.25293	1.7684643	0.51957124	3469.9888
621.25391	1.7768306	0.52053404	3462.4829
622.25488	1.7763749	0.52178419	3464.2112
623.25586	1.7824103	0.52282357	3465.9524
624.25684	1.7832216	0.52387172	3465.9734
625.25781	1.7851648	0.52487409	3470.197
626.25879	1.7879725	0.52599603	3468.2551
627.25977	1.7910779	0.52712721	3469.2063
628.26074	1.7950525	0.52825058	3469.1787
629.26172	1.7968624	0.52943122	3472.9944
630.2627	1.8016434	0.53097999	3478.9133
631.26367	1.80409	0.53248489	3480.894
632.26465	1.8070271	0.5337376	3473.248
633.26563	1.8086541	0.53494799	3480.9026
634.2666	1.8135108	0.53607607	3474.3828
635.26758	1.8163236	0.53732544	3483.1201
636.26855	1.8183602	0.53849632	3480.1108
637.26953	1.823723	0.54006737	3477.8091
638.27051	1.824343	0.54107952	3478.7795
639.27148	1.8304029	0.54231429	3481.5562
640.27246	1.8318431	0.54364699	3481.2632
641.27344	1.835053	0.54485333	3479.0676
642.27441	1.8363851	0.54619175	3488.7434
643.27539	1.8406378	0.54747689	3488.2747
644.27637	1.8447272	0.54863197	3482.0327
645.27734	1.847122	0.54979604	3485.8689
646.27832	1.8499475	0.5510022	3483.4167
647.2793	1.8495711	0.55206573	3478.5566
648.28027	1.8587005	0.55335152	3494.5107
649.28125	1.8586246	0.55451781	3488.5344
650.28223	1.8638812	0.55565983	3492.2134
651.2832	1.8640342	0.55687904	3491.7581
652.28418	1.8696702	0.55811238	3492.4775
653.28516	1.8703703	0.55935532	3491.1135
654.28613	1.8729212	0.56028306	3486.3384
655.28711	1.8746462	0.56151217	3493.46
656.28809	1.8833376	0.56273001	3492.0627
657.28906	1.8829824	0.56381094	3494.2107
658.29004	1.8875669	0.56501901	3499.074
659.29102	1.8917791	0.56634539	3493.6853
660.29199	1.8916936	0.56756157	3496.6372
661.29297	1.896613	0.56888109	3503.7466
662.29395	1.8973348	0.57011282	3499.0527
663.29492	1.8997039	0.57147151	3497.7007
664.2959	1.9048126	0.5727669	3503.1079
665.29688	1.9082174	0.57400739	3500.6306
666.29785	1.9109164	0.57523644	3494.3174
667.29883	1.9131653	0.57626575	3494.458
668.2998	1.9139416	0.57736933	3498.9963
669.30078	1.9189341	0.57839984	3502.2517
670.30176	1.923038	0.57984054	3505.0308
671.30273	1.9242514	0.58115548	3501.9661
672.30371	1.9286433	0.58244354	3505.282
673.30469	1.92814	0.58376151	3504.4194
674.30566	1.9342924	0.58512473	3504.0696
675.30664	1.937396	0.5862748	3505.5271
676.30762	1.9375124	0.58772171	3507.2207
677.30859	1.9431528	0.58881211	3506.8374
678.30957	1.9463966	0.59026885	3510.603
679.31055	1.94908	0.59137875	3509.2612
680.31152	1.9494499	0.59259254	3506.6169
681.3125	1.9558239	0.59403992	3515.6819
682.31348	1.9542881	0.59522009	3506.4937
683.31445	1.9575996	0.59642375	3506.626
684.31543	1.9635874	0.59765422	3513.332
685.31641	1.9673487	0.59884387	3510.7148
686.31738	1.9693457	0.6003499	3520.2959
687.31836	1.9750001	0.60196906	3513.4158
688.31934	1.9772201	0.60312051	3513.1719
689.32031	1.9775306	0.60411286	3509.4517
690.32129	1.9826045	0.6053406	3509.9785
691.32227	1.9842875	0.6066348	3514.7983
692.32324	1.9895939	0.60784715	3524.217
693.32422	1.9910432	0.60902613	3516.0024
694.3252	1.9912982	0.61022621	3515.2422
695.32617	1.9945014	0.61145192	3514.4321
696.32715	2.0018864	0.61272472	3522.7322
697.32813	2.0038016	0.61400634	3523.3982
698.3291	2.0041118	0.615179	3517.1018
699.33008	2.0103369	0.61643708	3521.6768
700.33105	2.0113533	0.61757946	3518.7263
701.33203	2.0142312	0.61903238	3526.0532
702.33301	2.0156846	0.62045884	3530.2705
703.33398	2.0224268	0.62183809	3529.238
704.33496	2.0251021	0.62313038	3524.2478
705.33594	2.0265293	0.62449867	3522.9521
706.33691	2.0316427	0.62583196	3528.4624
707.33789	2.0353394	0.62699062	3522.0525
708.33887	2.0353014	0.62801915	3524.5415
709.33984	2.0389709	0.62931532	3532.3564
710.34082	2.0391977	0.6304332	3524.3169
711.3418	2.0416172	0.63170969	3522.792
712.34277	2.0474744	0.63303453	3531.9844
713.34375	2.0515795	0.63415295	3529.2346
714.34473	2.0548718	0.63558334	3532.3169
715.3457	2.056561	0.63681817	3529.4021
716.34668	2.0608501	0.63819212	3535.5081
717.34766	2.0651984	0.6396004	3537.1047
718.34863	2.0665295	0.64098024	3531.957
719.34961	2.0661225	0.64212149	3528.9844
720.35059	2.0718248	0.64334893	3538.2288
721.35156	2.0730441	0.64462996	3529.8252
722.35254	2.0798566	0.64588267	3536.4858
723.35352	2.0808501	0.64701861	3534.835
724.35449	2.0845766	0.64817429	3535.4314
725.35547	2.0874543	0.64940113	3539.1021
726.35645	2.09025	0.65066814	3538.4429
727.35742	2.0941112	0.65190542	3540.5735
728.3584	2.0994253	0.65304315	3539.3628
729.35938	2.0970798	0.65406489	3534.8994
730.36035	2.1026342	0.6555081	3544.2441
731.36133	2.1056638	0.65682912	3542.3662
732.3623	2.1085744	0.65825176	3547.8975
733.36328	2.1110616	0.65940768	3538.3413
734.36426	2.1124001	0.66061568	3540.6394
735.36523	2.1172109	0.66202217	3546.2002
736.36621	2.1190901	0.66333276	3541.2866
737.36719	2.1239944	0.66470176	3545.3005
738.36816	2.1267765	0.66595799	3540.8726
739.36914	2.1302142	0.66711009	3535.3462
740.37012	2.1311858	0.66834873	3545.0715
741.37109	2.1333628	0.66964263	3545.2041
742.37207	2.1367137	0.67098975	3551.0381
743.37305	2.1425786	0.67248505	3546.5286
744.37402	2.1463382	0.67381525	3545.8108
745.375	2.1488438	0.67529851	3552.3247
746.37598	2.1511989	0.67662835	3548.2766
747.37695	2.1511939	0.67771637	3544.8523
748.37793	2.1537983	0.67900366	3544.5498
749.37891	2.158901	0.68045372	3553.9287
750.37988	2.1613848	0.68187016	3549.7273
751.38086	2.1637967	0.68312752	3545.6289
752.38184	2.1705394	0.68431616	3549.9497
753.38281	2.1720908	0.68563169	3552.0776
754.38379	2.1738181	0.68709511	3551.9131
755.38477	2.1771364	0.6884985	3556.9331
756.38574	2.1802597	0.6897999	3552.5039
757.38672	2.1827598	0.69118935	3557.2979
758.3877	2.1863239	0.69242454	3554.3523
759.38867	2.1899199	0.69359231	3554.0229
760.38965	2.1934848	0.69496167	3563.999
761.39063	2.1933687	0.69610977	3550.5432
762.3916	2.1988301	0.69738644	3556.6458
763.39258	2.1980374	0.69880521	3561.793
764.39355	2.2000823	0.700324	3557.4185
765.39453	2.2071609	0.70182997	3558.6567
766.39551	2.2092655	0.70312804	3554.7954
767.39648	2.2147446	0.70433754	3557.0217
768.39746	2.2158651	0.70561802	3554.0491
769.39844	2.2188129	0.70695484	3562.2844
770.39941	2.2219784	0.70821613	3560.5088
771.40039	2.2231758	0.70941025	3556.3579
772.40137	2.2280345	0.71090704	3561.865
773.40234	2.2343469	0.71254939	3569.2122
774.40332	2.2307649	0.71380067	3558.2124
775.4043	2.2357199	0.71511465	3560.2227
776.40527	2.2404466	0.71652097	3563.0154
777.40625	2.2433479	0.71799207	3562.092
778.40723	2.2461367	0.7194398	3568.1484
779.4082	2.247824	0.72069627	3559.7944
780.40918	2.2548795	0.72194791	3564.1355
781.41016	2.2543848	0.72325349	3563.2668
782.41113	2.2571464	0.72456306	3564.6531
783.41211	2.2610798	0.72608918	3571.8298
784.41309	2.2624736	0.72753644	3566.5386
785.41406	2.2666738	0.72916311	3571.3772
786.41504	2.2735121	0.73064262	3567.3796
787.41602	2.2709558	0.73200452	3561.7686
788.41699	2.2765462	0.7332657	3567.4312
789.41797	2.2787459	0.73452681	3570.7742
790.41895	2.279469	0.73576713	3566.8445
791.41992	2.2860963	0.73705637	3568.2898
792.4209	2.2918611	0.73851389	3574.9021
793.42188	2.2932	0.74022567	3572.6758
794.42285	2.2951863	0.741422	3570.0688
795.42383	2.2965493	0.74264407	3564.0652
796.4248	2.2995329	0.74390596	3569.7966
797.42578	2.3031914	0.74516898	3574.1094
798.42676	2.3082223	0.74664414	3578.4585
799.42773	2.3102088	0.74797791	3569.8752
800.42871	2.3122733	0.74921894	3576.7969
801.42969	2.3130102	0.75046223	3575.1365
802.43066	2.3165362	0.75185174	3575.9268
803.43164	2.3195155	0.75296718	3570.4133
804.43262	2.3215222	0.75447786	3575.0789
805.43359	2.3253839	0.75602055	3574.1726
806.43457	2.3297882	0.75712502	3573.7954
807.43555	2.3336008	0.75846362	3575.803
808.43652	2.3357451	0.75981152	3576.1685
809.4375	2.3394985	0.76126176	3580.429
810.43848	2.3413634	0.76279676	3579.4385
811.43945	2.3453164	0.76429683	3579.5203
812.44043	2.3493605	0.76551443	3572.1985
813.44141	2.3490837	0.76682764	3573.2686
814.44238	2.3556638	0.76818043	3580.2363
815.44336	2.3577013	0.76967955	3582.0164
816.44434	2.3582582	0.77133894	3579.4634
817.44531	2.3634458	0.77282798	3579.4863
818.44629	2.365916	0.77408856	3578.3076
819.44727	2.3687172	0.77542377	3579.9209
820.44824	2.3718643	0.7768442	3583.2539
821.44922	2.3746426	0.77826977	3580.5671
822.4502	2.3786955	0.77959192	3582.3855
823.45117	2.3802764	0.78125864	3587.7817
824.45215	2.384661	0.78278089	3580.4495
825.45313	2.3883076	0.78419113	3582.0491
826.4541	2.3900933	0.78557903	3586.1401
827.45508	2.3937058	0.78692889	3589.0752
828.45605	2.3940921	0.78845084	3585.606
829.45703	2.3970983	0.78986311	3586.6418
830.45801	2.4024608	0.79123461	3581.5791
831.45898	2.4056013	0.79254425	3586.9121
832.45996	2.4071541	0.7939027	3580.1348
833.46094	2.413471	0.79516357	3586.5391
834.46191	2.41326	0.79637766	3581.752
835.46289	2.4172604	0.79766953	3585.7146
836.46387	2.4183459	0.79929107	3589.6526
837.46484	2.4227226	0.80075371	3585.5049
838.46582	2.4251251	0.80205971	3585.4465
839.4668	2.4297812	0.80358022	3588.3647
840.46777	2.4315574	0.80493218	3585.5596
841.46875	2.434761	0.80610913	3581.2041
842.46973	2.4344862	0.80745345	3586.2346
843.4707	2.4403007	0.80887902	3587.2432
844.47168	2.447773	0.81033069	3588.0303
845.47266	2.4445777	0.81182504	3591.3887
846.47363	2.4517472	0.81312144	3591.7644
847.47461	2.4548991	0.81439376	3590.6101
848.47559	2.4546762	0.81584203	3593.0002
849.47656	2.4577754	0.81737256	3587.9453
850.47754	2.4615202	0.81908667	3589.946
851.47852	2.4645994	0.82035059	3590.1892
852.47949	2.4684613	0.82174343	3596.2886
853.48047	2.470196	0.82311088	3592.8667
854.48145	2.4754288	0.82435244	3594.0444
855.48242	2.4766285	0.82565165	3594.4749
856.4834	2.4808679	0.82736927	3600.248
857.48438	2.4837432	0.82876158	3594.5068
858.48535	2.4889023	0.83034015	3602.9768
859.48633	2.4894414	0.83178884	3596.1453
860.4873	2.4928982	0.83356404	3591.8918
861.48828	2.4951119	0.83514786	3591.2544
862.48926	2.5002503	0.83681983	3594.5173
863.49023	2.5027788	0.83808166	3593.6025
864.49121	2.5035388	0.83960301	3595.6914
865.49219	2.5075834	0.84137118	3601.7991
866.49316	2.5080898	0.84278649	3593.4104
867.49414	2.5110507	0.84427696	3594.9453
868.49512	2.5167167	0.84563535	3597.2942
869.49609	2.5208409	0.8470059	3595.699
870.49707	2.5225101	0.84857082	3600.2654
871.49805	2.5239272	0.85001206	3601.0605
872.49902	2.5293195	0.851237	3597.3738
873.5	2.5317075	0.85246092	3588.7844
874.50098	2.5317729	0.85373002	3596.217
875.50195	2.5376165	0.85508692	3601.0291
876.50293	2.5406826	0.85649717	3603.6233
877.50391	2.5440643	0.8582626	3603.6433
878.50488	2.5447609	0.85955834	3590.7522
879.50586	2.5488961	0.86097682	3602.1965
880.50684	2.5535204	0.86247933	3595.9714
881.50781	2.5550296	0.86417955	3601.5876
882.50879	2.557647	0.86556542	3594.4265
883.50977	2.5629783	0.86692142	3603.5872
884.51074	2.5629795	0.86838382	3597.8303
885.51172	2.5652783	0.87008667	3603.4128
886.5127	2.5732098	0.87169385	3603.0789
887.51367	2.5734985	0.8733893	3602.375
888.51465	2.5752015	0.87532264	3606.0439
889.51563	2.5779889	0.87718177	3604.7371
890.5166	2.5821927	0.87866086	3599.9707
891.51758	2.5844934	0.88031691	3601.3604
892.51855	2.5879538	0.88210773	3599.8977
893.51953	2.5907948	0.88362008	3601.6533
894.52051	2.5950527	0.88465905	3589.5
895.52148	2.5952928	0.88630128	3599.4011
896.52246	2.6007736	0.88788658	3604.0142
897.52344	2.6038303	0.88920188	3602.219
898.52441	2.6041048	0.89087516	3601.8118
899.52539	2.6106534	0.89268851	3600.7668
900.52637	2.6103325	0.89411348	3603.7241
901.52734	2.6127653	0.8955006	3598.353
902.52832	2.619698	0.8972441	3610.697
903.5293	2.61901	0.89856452	3593.2969
904.53027	2.6254144	0.90011054	3604.2063
905.53125	2.6245143	0.90174919	3606.7151
906.53223	2.6283488	0.90353459	3599.9033
907.5332	2.6320152	0.90485793	3596.9387
908.53418	2.6368687	0.90628356	3606.6819
909.53516	2.6384404	0.90791726	3605.0608
910.53613	2.6428959	0.90947026	3602.5957
911.53711	2.6432953	0.91089404	3608.0789
912.53809	2.646764	0.91233206	3608.4668
913.53906	2.6505659	0.9140296	3602.9912
914.54004	2.6541529	0.91547292	3602.2864
915.54102	2.6569803	0.91711897	3606.4946
916.54199	2.660428	0.91861308	3605.2229
917.54297	2.6648202	0.92032564	3607.032
918.54395	2.6642752	0.92185307	3600.7876
919.54492	2.6697032	0.92345202	3602.1382
920.5459	2.6711271	0.92504352	3610.9275
921.54688	2.6757936	0.92679167	3610.1506
922.54785	2.6783819	0.9285956	3611.863
923.54883	2.681025	0.9302178	3607.0586
924.5498	2.685765	0.93162864	3606.0625
925.55078	2.6887259	0.93349892	3614.5791
926.55176	2.6914365	0.93516177	3612.146
927.55273	2.6922767	0.93663943	3612.9541
928.55371	2.6967537	0.93812025	3604.2007
929.55469	2.7002378	0.93977875	3611.1252
930.55566	2.6999805	0.94137257	3610.7417
931.55664	2.7058775	0.94305795	3607.9124
932.55762	2.7103319	0.94458562	3606.8169
933.55859	2.7091043	0.94614363	3608.9043
934.55957	2.716146	0.9479323	3616.4497
935.56055	2.720186	0.94969851	3617.7083
936.56152	2.7227793	0.95147038	3613.3096
937.5625	2.7230656	0.95282501	3604.8813
938.56348	2.7273083	0.95432484	3605.3311
939.56445	2.7276967	0.95608628	3610.7263
940.56543	2.7318382	0.95753217	3607.208
941.56641	2.7348685	0.95916826	3605.8098
942.56738	2.7379079	0.960944	3615.6201
943.56836	2.7403376	0.962511	3612.9595
944.56934	2.7443829	0.96432006	3612.7314
945.57031	2.7467451	0.96585196	3608.9578
946.57129	2.7496047	0.96702772	3604.0886
947.57227	2.754065	0.96832085	3603.3469
948.57324	2.7577395	0.9698928	3612.7166
949.57422	2.75966	0.97130197	3612.2922
950.5752	2.7660832	0.97317225	3613.46
951.57617	2.7631395	0.97483116	3609.8882
952.57715	2.7706008	0.97647625	3607.3208
953.57813	2.7716069	0.97811276	3612.4868
954.5791	2.7759242	0.97992235	3610.1167
955.58008	2.7797194	0.98158157	3613.9341
956.58105	2.7786798	0.98302698	3603.2771
957.58203	2.782726	0.98479712	3609.1401
958.58301	2.7852025	0.9865433	3606.6477
959.58398	2.7897556	0.98823625	3615.0562
960.58496	2.7947586	0.98994952	3612.8821
961.58594	2.7953756	0.991611	3604.5105
962.58691	2.7979333	0.99355805	3616.3508
963.58789	2.8024077	0.99490708	3606.8447
964.58887	2.8064804	0.99666196	3608.8403
965.58984	2.8087115	0.99839205	3610.1438
966.59082	2.8115501	0.99995446	3614.5061
967.5918	2.812259	1.0019964	3615.2637
968.59277	2.8172245	1.0036823	3609.4629
969.59375	2.8193836	1.0057048	3610.5544
970.59473	2.8239937	1.0074819	3607.9204
971.5957	2.8256567	1.0092075	3612.2373
972.59668	2.8278797	1.0107453	3606.3611
973.59766	2.8335323	1.0125581	3610.7627
974.59863	2.8331537	1.014145	3610.5576
975.59961	2.8370581	1.0157533	3610.4507
976.60059	2.8409023	1.017542	3610.7791
977.60156	2.8413436	1.0190932	3603.5889
978.60254	2.8491313	1.0207272	3611.604
979.60352	2.8475165	1.0223786	3609.2578
980.60449	2.8555229	1.0239754	3603.9155
981.60547	2.8562789	1.0254536	3610.552
982.60645	2.859133	1.0270745	3610.4636
983.60742	2.8585186	1.028981	3611.8066
984.6084	2.8675694	1.0308046	3612.8726
985.60938	2.8692048	1.0327462	3616.6743
986.61035	2.869355	1.0350995	3609.2805
987.61133	2.8746974	1.0368025	3609.1233
988.6123	2.8766088	1.0387055	3605.2051
989.61328	2.8767371	1.0405699	3603.3413
990.61426	2.8799133	1.0423013	3604.5996
991.61523	2.8846164	1.0443809	3609.5591
992.61621	2.8905704	1.0463135	3612.1272
993.61719	2.8881092	1.0481426	3601.6897
994.61816	2.8955066	1.0501733	3608.4082
995.61914	2.8996015	1.0521413	3610.5759
996.62012	2.9012072	1.0542579	3611.0967
997.62109	2.9031577	1.0562688	3606.5188
998.62207	2.9057324	1.0582244	3604.9609
999.62305	2.9112551	1.0600318	3612.7251
1000.624	2.9072466	1.0619509	3606.7405
1001.625	2.9164503	1.0642551	3615.6255
1002.626	2.921145	1.0664408	3613.437
1003.627	2.921376	1.0685326	3606.1333
1004.6279	2.9234393	1.0702004	3602.6572
1005.6289	2.9280663	1.071978	3605.1501
1006.6299	2.9295352	1.073913	3606.3994
1007.6309	2.935981	1.0755931	3604.4395
1008.6318	2.9352715	1.0772448	3607.6626
1009.6328	2.9400015	1.079234	3606.563
1010.6338	2.9389374	1.0811973	3600.3623
1011.6348	2.9445953	1.0831405	3607.6814
1012.6357	2.9504175	1.0852553	3605.8552
1013.6367	2.949409	1.0867444	3599.7048
1014.6377	2.9555111	1.0883037	3601.0471
1015.6387	2.9572811	1.0899169	3600.9263
1016.6396	2.9622855	1.0918444	3607.2104
1017.6406	2.9653935	1.0938319	3611.1958
1018.6416	2.9675431	1.0956831	3604.8914
1019.6426	2.9694502	1.0977412	3606.2717
1020.6436	2.9713147	1.0996127	3604.7136
1021.6445	2.9764643	1.1020751	3608.4063
1022.6455	2.9767661	1.1041658	3596.5596
1023.6465	2.9801602	1.1062195	3601.7065
1024.6475	2.9888179	1.1082906	3606.2463
1025.6484	2.9892795	1.1103694	3594.3562
1026.6494	2.9941442	1.1118462	3597.7778
1027.6504	2.9956057	1.1135235	3595.6121
1028.6514	2.9976845	1.1148227	3590.7454
1029.6523	3.0006366	1.1162924	3597.1899
1030.6533	3.0019195	1.1183628	3602.5422
1031.6543	3.0062883	1.120452	3606.7983
1032.6553	3.0103874	1.1226115	3598.1597
1033.6563	3.0134146	1.1247709	3604.158
1034.6572	3.0161054	1.1269451	3603.4827
1035.6582	3.0195556	1.1286864	3599.072
1036.6592	3.0204632	1.1309034	3602.7058
1037.6602	3.0247595	1.1329988	3598.2563
1038.6611	3.0268247	1.1347814	3595.9783
1039.6621	3.0305524	1.136948	3602.0571
1040.6631	3.0331428	1.1389306	3599.2954
1041.6641	3.0357635	1.1409361	3601.5212
1042.665	3.0404954	1.1428903	3600.4023
1043.666	3.0400937	1.1447608	3597.1406
1044.667	3.0471926	1.1467584	3603.686
1045.668	3.0486884	1.1487734	3596.4521
1046.6689	3.0548115	1.1506857	3595.3176
1047.6699	3.0560455	1.1524315	3593.2505
1048.6709	3.0552249	1.154212	3593.5645
1049.6719	3.0615292	1.1566389	3600.7666
1050.6729	3.0651679	1.1587918	3595.2222
1051.6738	3.0670269	1.1608323	3592.3843
1052.6748	3.0712464	1.1631755	3599.4497
1053.6758	3.0732293	1.1655295	3592.5674
1054.6768	3.0753565	1.1674181	3593.4609
1055.6777	3.0754716	1.1692572	3584.4036
1056.6787	3.0823679	1.1714182	3594.3301
1057.6797	3.0836906	1.1734644	3595.2607
1058.6807	3.0862355	1.1754252	3582.1355
1059.6816	3.0896776	1.1772652	3584.1343
1060.6826	3.0916345	1.1794997	3589.7131
1061.6836	3.0972159	1.1817867	3594.1118
1062.6846	3.0997336	1.1835606	3581.187
1063.6855	3.1026192	1.1856072	3586.4192
1064.6865	3.1048872	1.1876662	3583.4614
1065.6875	3.109189	1.1899583	3586.7678
1066.6885	3.1130927	1.1922427	3588.8784
1067.6895	3.113647	1.1943367	3583.4006
1068.6904	3.1206927	1.1967928	3581.4436
1069.6914	3.1204643	1.1987666	3581.8921
1070.6924	3.1222296	1.2011101	3578.5095
1071.6934	3.1278701	1.2035756	3584.2249
1072.6943	3.1272891	1.205616	3573.97
1073.6953	3.1344883	1.2078317	3586.5137
1074.6963	3.1357639	1.2101984	3575.4253
1075.6973	3.1367571	1.2125953	3574.313
1076.6982	3.1402948	1.2147071	3573.2263
1077.6992	3.1436937	1.2171122	3576.0354
1078.7002	3.1458504	1.2194829	3576.1567
1079.7012	3.1520386	1.2215418	3578.4102
1080.7021	3.1533504	1.2235988	3576.0996
1081.7031	3.1554952	1.2259854	3570.9387
1082.7041	3.1562543	1.2281877	3569.5662
1083.7051	3.1605728	1.2305042	3564.1743
1084.7061	3.1657281	1.2328827	3568.5894
1085.707	3.166712	1.2352101	3564.9587
1086.708	3.173547	1.2373319	3566.229
1087.709	3.1734269	1.2391505	3564.3862
1088.71	3.1780894	1.2414334	3562.6318
1089.7109	3.1823545	1.2433608	3559.6526
1090.7119	3.1797435	1.2453415	3558.5732
1091.7129	3.183193	1.2476004	3564.9595
1092.7139	3.1899245	1.250008	3565.4702
1093.7148	3.1912808	1.2522668	3556.5427
1094.7158	3.1939983	1.2544534	3557.5078
1095.7168	3.1982446	1.2565498	3556.949
1096.7178	3.2026343	1.2590088	3561.2791
1097.7188	3.20241	1.2614584	3553.0779
1098.7197	3.2060864	1.2637807	3545.3325
1099.7207	3.2087801	1.2662812	3555.1248
1100.7217	3.2147267	1.268693	3554.8616
1101.7227	3.2152224	1.2708892	3550.4814
1102.7236	3.2217345	1.27308	3551.8909
1103.7246	3.2198708	1.2754692	3544.4832
1104.7256	3.2278423	1.2777098	3549.0903
1105.7266	3.2295046	1.280049	3549.134
1106.7275	3.2299819	1.2827963	3545.0193
1107.7285	3.236073	1.2853551	3545.2065
1108.7295	3.2376411	1.2874924	3535.8174
1109.7305	3.2429194	1.2897928	3540.8228
1110.7314	3.2444541	1.2916378	3530.7927
1111.7324	3.2471869	1.294017	3543.3708
1112.7334	3.2507253	1.2968726	3541.3093
1113.7344	3.2500565	1.29951	3532.5767
1114.7354	3.2549281	1.3022137	3530.1785
1115.7363	3.2557349	1.3046631	3527.4312
1116.7373	3.2617898	1.3071089	3528.2339
1117.7383	3.2638242	1.3095489	3526.5205
1118.7393	3.2637045	1.3121241	3521.0293
1119.7402	3.269706	1.314483	3523.0483
1120.7412	3.2736897	1.3166273	3526.8652
1121.7422	3.2784743	1.318794	3521.2114
1122.7432	3.2790229	1.3209736	3519.7434
1123.7441	3.2824035	1.3231699	3514.5425
1124.7451	3.2835383	1.325438	3518.1636
1125.7461	3.2894669	1.3278673	3512.3967
1126.7471	3.2890406	1.3305227	3519.0437
1127.748	3.2944694	1.3334261	3508.0962
1128.749	3.3000851	1.3357733	3504.6082
1129.75	3.2995689	1.3382919	3504.3411
1130.751	3.3044624	1.3408067	3504.4163
1131.752	3.3058441	1.3430494	3499.9685
1132.7529	3.3084745	1.345291	3497.344
1133.7539	3.3100729	1.3482591	3501.6626
1134.7549	3.3155167	1.3507414	3494.616
1135.7559	3.3191025	1.3533735	3498.1094
1136.7568	3.3213773	1.3562896	3496.157
1137.7578	3.3254254	1.3588883	3491.2212
1138.7588	3.3256848	1.3614386	3491.772
1139.7598	3.3313041	1.364301	3489.5732
1140.7607	3.3357558	1.3670386	3487.4285
1141.7617	3.3362892	1.3694521	3483.6055
1142.7627	3.3410201	1.3720058	3482.9729
1143.7637	3.3425689	1.3747472	3479.7292
1144.7646	3.3456438	1.3774723	3473.6882
1145.7656	3.3465583	1.3800883	3471.8806
1146.7666	3.3523841	1.3823195	3463.5686
1147.7676	3.3552971	1.3846722	3468.3062
1148.7686	3.3595932	1.3870033	3466.615
1149.7695	3.359971	1.3894588	3462.9258
1150.7705	3.3634312	1.3921958	3461.0654
1151.7715	3.3658142	1.394748	3459.2766
1152.7725	3.3705153	1.3978928	3460.9578
1153.7734	3.373939	1.4011399	3459.459
1154.7744	3.3726938	1.4039515	3446.165
1155.7754	3.3758869	1.4065003	3444.5166
1156.7764	3.3806932	1.4089912	3443.5576
1157.7773	3.3836877	1.4113711	3435.425
1158.7783	3.3855495	1.4136015	3439.2588
1159.7793	3.3891609	1.4157271	3432.3303
1160.7803	3.392746	1.4178966	3429.792
1161.7813	3.3972485	1.4201202	3435.3025
1162.7822	3.397774	1.4226543	3434.1797
1163.7832	3.401577	1.4254702	3434.6763
1164.7842	3.404923	1.4287677	3426.3552
1165.7852	3.4073527	1.4315848	3418.1489
1166.7861	3.4123971	1.4341738	3418.4722
1167.7871	3.4143212	1.4370614	3419.7429
1168.7881	3.4166284	1.4395384	3410.9421
1169.7891	3.4192197	1.4423678	3414.5371
1170.79	3.424329	1.4453343	3408.1597
1171.791	3.425854	1.4485635	3409.9392
1172.792	3.4285963	1.4516214	3398.8816
1173.793	3.4314907	1.4542588	3392.387
1174.7939	3.435503	1.4568391	3394.1753
1175.7949	3.4386423	1.4595172	3390.3203
1176.7959	3.4415193	1.4623116	3387.7585
1177.7969	3.4446332	1.4648677	3387.6162
1178.7979	3.4448776	1.4681371	3387.375
1179.7988	3.4514849	1.4713541	3376.6206
1180.7998	3.4538119	1.4742305	3375.2847
1181.8008	3.4577088	1.4771918	3370.4937
1182.8018	3.4601011	1.4801295	3364.7502
1183.8027	3.4649754	1.4831544	3361.8416
1184.8037	3.4653897	1.4859184	3357.2385
1185.8047	3.4663234	1.4886547	3352.3516
1186.8057	3.4746311	1.4917082	3353.0903
1187.8066	3.4770291	1.4944385	3349.7266
1188.8076	3.4783075	1.4972066	3345.7993
1189.8086	3.4802606	1.5000522	3345.1934
1190.8096	3.4851677	1.5036013	3338.9187
1191.8105	3.4841089	1.5070994	3324.5212
1192.8115	3.4909732	1.5101721	3322.4619
1193.8125	3.4934533	1.5132774	3319.2224
1194.8135	3.4959421	1.5162475	3312.7129
1195.8145	3.499424	1.5193529	3310.5471
1196.8154	3.5016325	1.522059	3301.7402
1197.8164	3.5046756	1.5249209	3305.3154
1198.8174	3.5076468	1.5277507	3293.863
1199.8184	3.5110066	1.5306388	3290.9077
1200.8193	3.5133052	1.5336331	3288.4209
1201.8203	3.5181317	1.5369227	3286.3384
1202.8213	3.5213892	1.5395405	3273.6929
1203.8223	3.5234015	1.5425794	3275.9917
1204.8232	3.5257854	1.5465286	3269.697
1205.8242	3.5292575	1.5499477	3250.6138
1206.8252	3.5313926	1.5528086	3248.0737
1207.8262	3.5336609	1.555863	3245.3491
1208.8271	3.5393476	1.5590037	3239.1726
1209.8281	3.5428681	1.5620641	3232.155
1210.8291	3.5435994	1.5656644	3230.8398
1211.8301	3.5484912	1.5692272	3213.9392
1212.8311	3.5504117	1.5726312	3205.061
1213.832	3.55356	1.5763621	3200.3176
1214.833	3.5576274	1.5794588	3191.8022
1215.834	3.5592539	1.5821927	3180.5515
1216.835	3.5642371	1.5853339	3179.55
1217.8359	3.5626354	1.5894923	3168.3745
1218.8369	3.5694809	1.5930029	3163.4951
1219.8379	3.5692542	1.5963997	3151.228
1220.8389	3.5751889	1.5997627	3145.5981
1221.8398	3.5792038	1.6032506	3136.5979
1222.8408	3.5805917	1.6068654	3118.9768
1223.8418	3.5799849	1.6101961	3115.667
1224.8428	3.5876062	1.6150869	3103.8999
1225.8438	3.5906639	1.6199268	3075.1497
1226.8447	3.5913124	1.624029	3057.4934
1227.8457	3.5948322	1.6274694	3045.6128
1228.8467	3.5992658	1.6310169	3030.2732
1229.8477	3.602144	1.637781	2987.373
1230.1479	3.6053078	1.6403999	2970.2627