File: datasets/am_bench_2022/raw_data/30-XY.12-3/specimen.dat
MTS793|MPT|ENU|1|2|.|/|:|1|0|0|A

Operator Information						Time:	23.630371	Sec	10/18/2021 1:06:50 PM
Operator	Nick Derimow
Project	AM Bench 2022 mini-tensile challenge
Specimen ID	30-XY.12-3
Material	PBF-L Inconel 625
Specimen Width	2.54	mm
Specimen Thickness	1.5	mm
Notes
Operator Information End

Data Acquisition						Time:	1024.624	Sec	10/18/2021 1:23:31 PM
Time	Axial Displacement	Axial Extensometer	Axial Force
Sec	mm	mm	N
23.743896	0.00085810374	7.0946524e-05	68.117256
24.744873	0.0030432658	0.0001785614	80.834076
25.74585	0.0073733805	0.00013333889	95.307022
26.746826	0.0075260242	0.00010475251	104.73413
27.747803	0.011359688	0.00026128409	120.65685
28.748779	0.013257388	0.00023357462	129.2093
29.749756	0.016092002	0.00022883755	141.82526
30.750732	0.020539315	0.00031591929	159.28842
31.751709	0.024354128	0.00035686471	173.51215
32.752686	0.022360591	0.00040598013	182.05821
33.753662	0.02777043	0.00040824214	202.87691
34.754639	0.034007259	0.00047899404	223.09415
35.755615	0.035139486	0.00049986015	241.22696
36.756592	0.03661675	0.00060777931	255.50288
37.757568	0.038362574	0.00071071449	285.84515
38.758545	0.041422982	0.00077382906	298.46536
39.759521	0.045206446	0.00085702201	319.01144
40.760498	0.048005871	0.00092939666	342.54968
41.761475	0.050115634	0.0010035784	359.01782
42.762451	0.052715853	0.0011262825	380.64777
43.763428	0.061715793	0.0012889475	408.15204
44.764404	0.05961566	0.0013969445	426.66803
45.765381	0.063668609	0.001421765	446.96234
46.766357	0.064327896	0.0015320722	470.68002
47.767334	0.068821102	0.0016467896	495.94449
48.768311	0.072665013	0.001804529	519.21082
49.769287	0.074936435	0.0018505147	548.86108
50.770264	0.077481948	0.0019362892	566.18469
51.77124	0.081735022	0.0020414095	598.27069
52.772217	0.085131042	0.0021626221	622.49969
53.773193	0.086463653	0.0022400001	648.78278
54.77417	0.091632381	0.0024231952	676.59467
55.775146	0.093073584	0.0024896322	700.55969
56.776123	0.093807094	0.0025000528	724.92865
57.7771	0.10007092	0.002702188	757.05811
58.778076	0.1036895	0.0028156587	785.23523
59.779053	0.1049819	0.0029615031	802.2431
60.780029	0.1083814	0.003117542	836.90076
61.781006	0.11066224	0.0032500604	863.42908
62.781982	0.1140177	0.0032838089	888.03589
63.782959	0.11968247	0.0034587961	915.00671
64.783936	0.12154385	0.0035502093	944.08832
65.784912	0.12541829	0.0037103049	971.23663
66.785889	0.12605058	0.0038074714	1004.3759
67.786865	0.13042931	0.0039508194	1032.7086
68.787842	0.13131684	0.0041032778	1066.343
69.788818	0.1355361	0.0042786296	1101.7153
70.789795	0.14056224	0.0043822089	1124.6193
71.790771	0.13995986	0.004576378	1146.9075
72.791748	0.14360918	0.0046227151	1179.619
73.792725	0.1482058	0.0047009415	1203.802
74.793701	0.15173806	0.0048625749	1231.8291
75.794678	0.15665177	0.0050167111	1257.5613
76.795654	0.15579614	0.0050599226	1275.8436
77.796631	0.15728651	0.005202706	1305.1687
78.797607	0.16356325	0.0053270403	1334.2703
79.798584	0.16577028	0.0054724463	1362.6418
80.799561	0.16814846	0.0055552241	1392.2941
81.800537	0.17196798	0.0056895129	1414.3296
82.801514	0.17341717	0.005971333	1451.8153
83.80249	0.17868851	0.0060112979	1481.5801
84.803467	0.18181124	0.0061363829	1506.9094
85.804443	0.18336248	0.0063239383	1531.6089
86.80542	0.18703489	0.0064337384	1560.01
87.806396	0.18771861	0.0065911827	1591.2388
88.807373	0.1908538	0.0066928975	1614.4298
89.80835	0.19498333	0.0068272096	1641.4774
90.809326	0.19580863	0.0068454491	1664.2048
91.810303	0.19854121	0.0070417654	1686.5198
92.811279	0.20274307	0.0071575269	1713.1525
93.812256	0.20884609	0.0072572143	1742.2219
94.813232	0.21113719	0.0073823761	1772.2032
95.814209	0.21458751	0.0076639629	1808.5005
96.815186	0.21745899	0.0077643543	1830.2631
97.816162	0.2214535	0.0078300536	1853.1523
98.817139	0.22415027	0.0079004411	1871.0253
99.818115	0.22204216	0.0080408435	1897.3778
100.81909	0.22891656	0.0082307374	1920.8392
101.82007	0.23285103	0.0083626946	1948.3754
102.82104	0.23283525	0.0084724575	1970.3956
103.82202	0.23734695	0.008545558	1989.6727
104.823	0.24293688	0.0086787315	2006.201
105.82397	0.24539347	0.0087362723	2033.9525
106.82495	0.24441025	0.0087771062	2045.5024
107.82593	0.25155127	0.0089824656	2077.9128
108.8269	0.25029528	0.0089878831	2093.6794
109.82788	0.25756288	0.00912436	2116.7205
110.82886	0.25961092	0.0093374392	2137.877
111.82983	0.26502371	0.0093532698	2157.3079
112.83081	0.2654523	0.0095035629	2175.5076
113.83179	0.26938656	0.0095593594	2188.2007
114.83276	0.27108738	0.0097278468	2210.3733
115.83374	0.27461472	0.0097452058	2229.8914
116.83472	0.27747765	0.0097573269	2237.0986
117.83569	0.28104559	0.0099569783	2258.7588
118.83667	0.2823509	0.0099446895	2263.7737
119.83765	0.28765258	0.010100929	2284.6543
120.83862	0.28798574	0.010173767	2304.189
121.8396	0.29247507	0.010258296	2314.9629
122.84058	0.29474035	0.010361121	2334.8599
123.84155	0.29836339	0.010361302	2344.1875
124.84253	0.30064499	0.010433373	2357.9763
125.84351	0.30590039	0.010562736	2374.9409
126.84448	0.30671278	0.010618482	2379.876
127.84546	0.31034935	0.010714423	2393.908
128.84644	0.3119188	0.010876485	2411.0522
129.84741	0.31760511	0.010894848	2432.2749
130.84839	0.31929499	0.011058631	2438.1787
131.84937	0.32197681	0.011045454	2451.2783
132.85034	0.32394513	0.01124158	2459.5178
133.85132	0.32663181	0.011399447	2478.8223
134.85229	0.33216408	0.011385293	2485.3015
135.85327	0.3350952	0.011482374	2491.7722
136.85425	0.33787635	0.011520373	2510.8333
137.85522	0.34202	0.011657746	2519.7354
138.8562	0.34450266	0.011723286	2529.6123
139.85718	0.3481257	0.011929138	2539.7212
140.85815	0.35092652	0.011877108	2543.0107
141.85913	0.35128507	0.012101999	2557.4131
142.86011	0.35577419	0.012199013	2572.2385
143.86108	0.35607925	0.012299166	2575.7471
144.86206	0.36089557	0.012430968	2587.4136
145.86304	0.36159426	0.012600766	2605.572
146.86401	0.36612061	0.012727555	2601.0513
147.86499	0.37164795	0.012804572	2618.2234
148.86597	0.37314647	0.012979893	2621.0828
149.86694	0.37791097	0.013001819	2629.7649
150.86792	0.37974387	0.013166944	2646.1755
151.8689	0.38303769	0.013230218	2647.9041
152.86987	0.38711047	0.013448941	2656.3816
153.87085	0.38741922	0.01359358	2662.3552
154.87183	0.39172518	0.013763264	2670.2524
155.8728	0.39447618	0.013918385	2683.844
156.87378	0.39857113	0.014165267	2700.8047
157.87476	0.39970207	0.014370451	2708.6084
158.87573	0.40365684	0.014531494	2712.1079
159.87671	0.40694734	0.014721229	2724.5562
160.87769	0.41161272	0.014931002	2723.1885
161.87866	0.41257611	0.015014687	2732.23
162.87964	0.4168953	0.015270334	2740.2883
163.88062	0.41991842	0.015496686	2751.509
164.88159	0.42394882	0.015779192	2762.0164
165.88257	0.42539597	0.016046816	2766.064
166.88354	0.43054518	0.016244316	2777.9744
167.88452	0.43040934	0.016695298	2783.271
168.8855	0.43479726	0.0169222	2786.801
169.88647	0.44035035	0.017284123	2796.334
170.88745	0.43781817	0.017655721	2799.7871
171.88843	0.44190302	0.017839592	2808.04
172.8894	0.44568893	0.018291458	2820.4534
173.89038	0.45049357	0.018618345	2824.061
174.89136	0.45330873	0.018907553	2829.782
175.89233	0.45185119	0.019234585	2832.6182
176.89331	0.45716226	0.019759513	2843.0444
177.89429	0.46103507	0.020120643	2848.4255
178.89526	0.46480095	0.020508103	2851.2095
179.89624	0.4656066	0.02094809	2861.8794
180.89722	0.47120595	0.021522665	2867.9097
181.89819	0.47324708	0.021939725	2873.8447
182.89917	0.47539163	0.022410456	2876.9509
183.90015	0.47868547	0.022813194	2883.8086
184.90112	0.48365396	0.023510724	2893.7065
185.9021	0.48744869	0.023993041	2897.8975
186.90308	0.49016207	0.024636058	2899.2891
187.90405	0.49142766	0.025313566	2908.1484
188.90503	0.494434	0.025919875	2908.625
189.90601	0.49706411	0.026408257	2910.8159
190.90698	0.499329	0.027073491	2912.6216
191.90796	0.50541401	0.027653413	2919.042
192.90894	0.50604832	0.028360222	2925.2952
193.90991	0.50799495	0.028983891	2929.9233
194.91089	0.51160938	0.02984341	2937.9761
195.91187	0.51679778	0.030804366	2940.0964
196.91284	0.520226	0.03161481	2939.0256
197.91382	0.51702541	0.032286752	2938.7678
198.91479	0.5262692	0.033053476	2956.9788
199.91577	0.52766812	0.033938255	2957.782
200.91675	0.53040874	0.034819201	2966.2249
201.91772	0.53372943	0.035704695	2962.7874
202.9187	0.53647447	0.036512949	2969.4788
203.91968	0.53754646	0.037559208	2965.3872
204.92065	0.54350233	0.038349885	2974.8669
205.92163	0.54771894	0.039234646	2978.6326
206.92261	0.5501793	0.040249411	2985.5313
207.92358	0.55183965	0.041211087	2985.9482
208.92456	0.55455649	0.042299766	2985.4888
209.92554	0.5591858	0.043201145	2990.7388
210.92651	0.56293321	0.044091348	2999.1003
211.92749	0.56247753	0.045185074	2994.8499
212.92847	0.56154895	0.046147846	2995.5444
213.92944	0.57087833	0.047001321	2995.7561
214.93042	0.57088286	0.04790296	2999.7747
215.9314	0.57733297	0.048779476	3006.8162
216.93237	0.57871658	0.049814146	3013.6631
217.93335	0.58247197	0.051073872	3011.4475
218.93433	0.584342	0.052102063	3007.9783
219.9353	0.58839756	0.053016599	3018.8022
220.93628	0.58867705	0.054081853	3008.449
221.93726	0.59496111	0.054913856	3018.0488
222.93823	0.59981048	0.055866793	3025.2358
223.93921	0.59864467	0.05706827	3030.7012
224.94019	0.60577762	0.058116537	3030.7808
225.94116	0.61046261	0.059338931	3038.3137
226.94214	0.60940289	0.060410913	3034.9724
227.94312	0.61357141	0.061431967	3037.0576
228.94409	0.61583519	0.062614493	3041.231
229.94507	0.61553055	0.063828841	3038.8892
230.94604	0.61933839	0.064890914	3038.1113
231.94702	0.62605917	0.065891474	3045.5955
232.948	0.62711805	0.067017913	3050.3975
233.94897	0.63149565	0.068117648	3048.3867
234.94995	0.63192779	0.069182985	3044.5063
235.95093	0.63846719	0.070312828	3057.0166
236.9519	0.63685983	0.071355827	3052.7986
237.95288	0.64344621	0.072481595	3060.5369
238.95386	0.64327925	0.073629171	3060.4636
239.95483	0.6493091	0.074860319	3069.3457
240.95581	0.65275186	0.07602156	3068.71
241.95679	0.65361935	0.077148668	3064.1472
242.95776	0.65726328	0.078548968	3069.3193
243.95874	0.66072428	0.079825968	3071.7761
244.95972	0.66326016	0.081104264	3073.2261
245.96069	0.66640317	0.082286194	3075.8337
246.96167	0.67079329	0.083376125	3076.79
247.96265	0.67011654	0.084541358	3076.1304
248.96362	0.67643958	0.085714139	3088.1748
249.9646	0.67636257	0.086885549	3084.085
250.96558	0.67865348	0.088090122	3082.5229
251.96655	0.68544489	0.089061469	3081.3987
252.96753	0.68518305	0.089983009	3080.2866
253.96851	0.69188535	0.091052793	3091.6521
254.96948	0.68957561	0.092124932	3092.187
255.97046	0.69803739	0.093238734	3088.9524
256.97144	0.7014764	0.094464757	3099.6897
257.97241	0.70216149	0.095751837	3100.5781
258.97339	0.70497632	0.097105905	3103.3901
259.97437	0.70594645	0.098283134	3096.6104
260.97534	0.71197754	0.099470101	3096.9338
261.97632	0.71564895	0.10066531	3104.6907
262.97729	0.71893334	0.10176521	3110.9941
263.97827	0.72112584	0.10288744	3105.0925
264.97925	0.72414303	0.10400131	3113.3064
265.98022	0.72645968	0.10526697	3114.8982
266.9812	0.72939205	0.10653059	3113.6943
267.98218	0.73374987	0.10760637	3117.6711
268.98315	0.73554343	0.10880234	3121.511
269.98413	0.73997784	0.11022366	3126.1587
270.98511	0.73991412	0.11153489	3122.7043
271.98608	0.74355704	0.11274083	3123.6563
272.98706	0.74690229	0.1138982	3118.4265
273.98804	0.74992192	0.11508938	3127.2876
274.98901	0.75341117	0.1161824	3125.3298
275.98999	0.754888	0.11737174	3126.2754
276.99097	0.75880241	0.1187249	3128.8125
277.99194	0.76114124	0.11998173	3128.5613
278.99292	0.76455688	0.12107185	3129.3059
279.9939	0.76793939	0.12239373	3137.9177
280.99487	0.77051419	0.12366522	3136.9907
281.99585	0.77455014	0.12494054	3140.7354
282.99683	0.77775359	0.1263147	3142.5718
283.9978	0.78220415	0.12765379	3143.4663
284.99878	0.78465748	0.12875898	3139.6003
285.99976	0.78657836	0.12986875	3139.6372
287.00073	0.79018623	0.1307832	3135.9875
288.00171	0.79035485	0.13204865	3149.6138
289.00269	0.79437822	0.13304779	3142.8291
290.00366	0.80195343	0.13415237	3149.7227
291.00464	0.80178356	0.13518982	3147.4119
292.00562	0.80364537	0.13633038	3152.0859
293.00659	0.80371684	0.13768929	3148.1006
294.00757	0.8120802	0.13873349	3150.2947
295.00854	0.81450838	0.13984582	3159.0088
296.00952	0.81628901	0.14104879	3160.1631
297.0105	0.81726944	0.14219424	3163.7563
298.01147	0.82207978	0.14357497	3164.7671
299.01245	0.82414645	0.14477366	3162.2163
300.01343	0.82867229	0.14596939	3166.8301
301.0144	0.83049172	0.14717649	3169.5271
302.01538	0.83445978	0.14835706	3163.2471
303.01636	0.83771276	0.14979634	3174.9421
304.01733	0.84028351	0.15101437	3168.2693
305.01831	0.84253609	0.15204439	3170.9463
306.01929	0.84511399	0.15328051	3171.2046
307.02026	0.84947234	0.15459786	3171.4902
308.02124	0.85202771	0.15566462	3174.5972
309.02222	0.85504186	0.15686697	3175.595
310.02319	0.86024213	0.15806158	3190.3574
311.02417	0.86147702	0.15931101	3184.5818
312.02515	0.86716187	0.16051289	3189.4436
313.02612	0.86861718	0.16189571	3192.7126
314.0271	0.86918515	0.16321614	3186.1875
315.02808	0.87398237	0.16434963	3188.3711
316.02905	0.87596899	0.16561219	3186.4473
317.03003	0.88177902	0.16679932	3189.7031
318.03101	0.88345397	0.16787812	3190.4531
319.03198	0.88610667	0.16893604	3187.3735
320.03296	0.88797218	0.17016593	3191.3716
321.03394	0.89116287	0.17123932	3197.8867
322.03491	0.89588255	0.17243715	3194.7986
323.03589	0.89754003	0.17340018	3200.1379
324.03687	0.90154541	0.17481351	3204.5032
325.03784	0.90292227	0.17610514	3199.8269
326.03882	0.90874463	0.17752899	3209.5388
327.03979	0.90887433	0.17874557	3203.6731
328.04077	0.91313231	0.17987663	3204.5593
329.04175	0.91751975	0.18093817	3206.5383
330.04272	0.92137313	0.18202908	3207.1685
331.0437	0.92266679	0.18320368	3209.9878
332.04468	0.92308128	0.18433882	3210.6033
333.04565	0.92840302	0.18550473	3212.3914
334.04663	0.93292266	0.18674813	3223.3423
335.04761	0.93476713	0.18820681	3218.394
336.04858	0.9350937	0.18948546	3215.2708
337.04956	0.94164294	0.19073585	3223.0596
338.05054	0.94101536	0.19192989	3215.1528
339.05151	0.94381207	0.19304344	3215.0906
340.05249	0.94948816	0.19391133	3221.3943
341.05347	0.95195991	0.19516349	3221.8779
342.05444	0.95143706	0.19649267	3225.0537
343.05542	0.95761502	0.19777411	3226.0505
344.0564	0.96214104	0.198927	3225.3633
345.05737	0.96235907	0.20008859	3227.4114
346.05835	0.96767282	0.20136714	3229.3005
347.05933	0.96978074	0.20264383	3235.2944
348.0603	0.97475463	0.20387316	3233.5671
349.06128	0.97531295	0.20499921	3232.4431
350.06226	0.97840631	0.2061832	3234.3323
351.06323	0.98266041	0.20736647	3235.0808
352.06421	0.98493689	0.20861301	3245.7283
353.06519	0.98596954	0.20964202	3238.6716
354.06616	0.98734379	0.2108551	3238.4316
355.06714	0.99134195	0.21205451	3235.5425
356.06812	0.99551493	0.21315834	3239.926
357.06909	0.99931908	0.21438649	3244.085
358.07007	1.0032732	0.21543513	3238.8862
359.07104	1.0064476	0.21641949	3244.8948
360.07202	1.005074	0.21764714	3244.8118
361.073	1.0131563	0.21892451	3250.1833
362.07397	1.0142702	0.22013451	3246.3398
363.07495	1.0185803	0.22111182	3249.2695
364.07593	1.0223199	0.22231624	3255.4097
365.0769	1.0221341	0.22333486	3251.29
366.07788	1.0264347	0.22443803	3254.2119
367.07886	1.0277841	0.22574058	3260.9619
368.07983	1.0302157	0.2269906	3252.6873
369.08081	1.0347519	0.22819911	3254.791
370.08179	1.037655	0.22932562	3260.2075
371.08276	1.0430782	0.230433	3258.7234
372.08374	1.0454379	0.23165129	3262.8313
373.08472	1.047462	0.23275557	3260.7795
374.08569	1.0496156	0.23388796	3269.1455
375.08667	1.0551101	0.23526634	3272.8306
376.08765	1.0574844	0.23659854	3271.8303
377.08862	1.0590861	0.23766682	3264.645
378.0896	1.0632412	0.23900017	3267.7581
379.09058	1.0638727	0.24037661	3266.0776
380.09155	1.0690466	0.24144052	3274.803
381.09253	1.0704616	0.24253437	3271.3535
382.09351	1.0744548	0.24387349	3276.0129
383.09448	1.0768729	0.24533342	3278.8318
384.09546	1.0792522	0.2464193	3267.6743
385.09644	1.0856016	0.24728766	3274.1064
386.09741	1.0862345	0.24847914	3274.1685
387.09839	1.0896065	0.24943294	3281.8823
388.09937	1.0946329	0.25058788	3281.7097
389.10034	1.0962104	0.25201127	3285.9954
390.10132	1.0983008	0.25334337	3284.217
391.10229	1.1018025	0.25449911	3280.9521
392.10327	1.1074758	0.2558828	3286.8469
393.10425	1.1066666	0.25703555	3286.6079
394.10522	1.1087863	0.2581763	3287.8342
395.1062	1.1118505	0.25919929	3282.7615
396.10718	1.1171294	0.2602863	3287.1155
397.10815	1.1208496	0.26131448	3288.1609
398.10913	1.1227704	0.26245752	3290.6472
399.11011	1.1247251	0.2635439	3297.6504
400.11108	1.127923	0.26487899	3297.6235
401.11206	1.1326817	0.26607203	3298.9326
402.11304	1.1358397	0.2671704	3293.0674
403.11401	1.1364611	0.26815081	3295.2952
404.11499	1.1379253	0.26936525	3297.0964
405.11597	1.1445826	0.2705175	3297.2715
406.11694	1.1494107	0.27151787	3300.7219
407.11792	1.1480054	0.2726281	3301.366
408.1189	1.1503797	0.27384523	3304.4055
409.11987	1.1559877	0.27519453	3313.8025
410.12085	1.1568967	0.27658582	3306.4478
411.12183	1.1634573	0.27779904	3306.825
412.1228	1.1647321	0.27891931	3304.3494
413.12378	1.1674675	0.28002182	3309.2998
414.12476	1.1695601	0.28121182	3307.8391
415.12573	1.174286	0.28248027	3312.6855
416.12671	1.1759688	0.28368813	3313.728
417.12769	1.1811336	0.28520057	3317.2039
418.12866	1.1843992	0.2864854	3318.6406
419.12964	1.1840278	0.28750587	3310.4819
420.13062	1.1895581	0.28859803	3319.2358
421.13159	1.1906408	0.28957385	3319.2649
422.13257	1.1949917	0.29079029	3318.3015
423.13354	1.1967921	0.29189742	3319.0581
424.13452	1.1990912	0.29300231	3318.0413
425.1355	1.2049277	0.29415733	3330.5757
426.13647	1.2070518	0.29541361	3322.8916
427.13745	1.2106693	0.29664078	3330.1016
428.13843	1.2123042	0.2977232	3320.9058
429.1394	1.2161753	0.29885817	3324.3416
430.14038	1.2200766	0.29992336	3326.9189
431.14136	1.2221242	0.30092189	3332.0771
432.14233	1.2262769	0.30215576	3329.4016
433.14331	1.2292387	0.30343363	3336.623
434.14429	1.2305443	0.30450132	3333.9377
435.14526	1.2350398	0.30550948	3332.2661
436.14624	1.2349923	0.30633128	3329.575
437.14722	1.2379146	0.30742458	3333.127
438.14819	1.2428038	0.30875623	3338.5544
439.14917	1.2449745	0.30995899	3336.7322
440.15015	1.2488815	0.31136763	3340.8564
441.15112	1.2544222	0.31255916	3347.3623
442.1521	1.2534418	0.3134748	3333.3499
443.15308	1.2579939	0.31469199	3340.5701
444.15405	1.2604502	0.3158741	3347.1272
445.15503	1.2614987	0.31704727	3346.0303
446.15601	1.2692404	0.31832004	3346.6667
447.15698	1.2722806	0.31950903	3347.051
448.15796	1.2757132	0.3207835	3353.1133
449.15894	1.2747781	0.32204309	3346.5049
450.15991	1.2763699	0.32297999	3340.1406
451.16089	1.2812167	0.32408017	3348.1702
452.16187	1.2857313	0.32520348	3354.3259
453.16284	1.2859302	0.32629535	3352.9729
454.16382	1.2917708	0.32772246	3359.2759
455.16479	1.2940369	0.32875413	3351.8757
456.16577	1.2996409	0.32980511	3353.1567
457.16675	1.3006668	0.33087051	3359.7493
458.16772	1.3036158	0.33212879	3356.9204
459.1687	1.3044858	0.33332458	3361.801
460.16968	1.3095729	0.33448634	3363.9656
461.17065	1.3101161	0.33572793	3361.8994
462.17163	1.3162069	0.33701417	3366.7007
463.17261	1.318637	0.33817717	3360.4812
464.17358	1.3217916	0.33930138	3371.1086
465.17456	1.322284	0.34038752	3364.8757
466.17554	1.3284196	0.34163484	3366.9014
467.17651	1.3310055	0.34295046	3375.8193
468.17749	1.3328155	0.34432682	3367.1245
469.17847	1.3346965	0.34560415	3373.8411
470.17944	1.3384553	0.34653643	3368.6069
471.18042	1.3439639	0.34766531	3371.54
472.1814	1.3457159	0.34877372	3374.321
473.18237	1.3474417	0.34984908	3375.4417
474.18335	1.3512317	0.35090846	3367.9849
475.18433	1.3530114	0.35199007	3371.4026
476.1853	1.3579563	0.35302395	3377.8618
477.18628	1.3603836	0.35411462	3378.9875
478.18726	1.3642862	0.35535899	3382.7991
479.18823	1.3666728	0.356491	3382.2339
480.18921	1.3674334	0.35776204	3383.0261
481.19019	1.3672142	0.35903078	3380.1501
482.19116	1.3726749	0.36016619	3379.1919
483.19214	1.3792105	0.36121097	3379.8838
484.19312	1.3804061	0.3622621	3384.9768
485.19409	1.3829745	0.36342865	3383.5476
486.19507	1.3878456	0.36446935	3387.9961
487.19604	1.3927128	0.36590046	3391.8264
488.19702	1.3916249	0.36716256	3393.2332
489.198	1.3958585	0.36824015	3387.4199
490.19897	1.4012017	0.36932525	3393.8228
491.19995	1.3998379	0.37077427	3393.9934
492.20093	1.4048537	0.37201312	3396.2981
493.2019	1.4084259	0.37317833	3395.3853
494.20288	1.4159138	0.37442636	3400.4939
495.20386	1.415043	0.37554103	3396.4722
496.20483	1.4161115	0.37669873	3390.325
497.20581	1.4204519	0.37766546	3393.3191
498.20679	1.421306	0.37888411	3395.6392
499.20776	1.4248687	0.38007703	3396.6924
500.20874	1.4294387	0.38103312	3399.1443
501.20972	1.4305245	0.38213319	3401.4893
502.21069	1.4393213	0.38332447	3410.1814
503.21167	1.4403013	0.3847672	3412.073
504.21265	1.4384527	0.38589728	3403.8784
505.21362	1.4431634	0.38711473	3406.0249
506.2146	1.4483973	0.38801143	3401.1692
507.21558	1.4527413	0.38897297	3406.7903
508.21655	1.454523	0.38996482	3412.4653
509.21753	1.4545249	0.39106077	3409.1084
510.21851	1.4602954	0.39222455	3411.0667
511.21948	1.4593724	0.39345086	3409.5991
512.22046	1.4655706	0.39474571	3412.2756
513.22144	1.4670495	0.39601883	3412.3909
514.22241	1.4688306	0.3973226	3412.3975
515.22339	1.4724258	0.39841771	3417.3303
516.22437	1.4783448	0.39961877	3413.7581
517.22534	1.4783976	0.40072873	3417.4314
518.22632	1.4828376	0.402145	3416.8076
519.22729	1.4887474	0.40336949	3420.1484
520.22827	1.4910629	0.4044899	3416.7942
521.22925	1.4922727	0.40567148	3417.7817
522.23022	1.494083	0.40691999	3420.3789
523.2312	1.4985557	0.4079164	3420.7979
524.23218	1.5011547	0.40924105	3421.509
525.23315	1.5012933	0.41048095	3423.6851
526.23413	1.5063137	0.41145259	3422.196
527.23511	1.5100812	0.4127115	3426.7163
528.23608	1.5142611	0.41357619	3423.772
529.23706	1.5172976	0.41468644	3434.3301
530.23804	1.5184681	0.4157972	3429.1399
531.23901	1.5232463	0.41693899	3428.323
532.23999	1.5261174	0.41805604	3431.8206
533.24097	1.526381	0.41918337	3433.269
534.24194	1.5286933	0.42055568	3433.9661
535.24292	1.5340886	0.42158315	3427.1338
536.2439	1.5366526	0.42273805	3436.3352
537.24487	1.5400311	0.42385384	3431.5845
538.24585	1.5440383	0.42506143	3438.4268
539.24683	1.5490352	0.42641178	3443.241
540.2478	1.5489887	0.42761582	3437.8313
541.24878	1.5521603	0.42869222	3430.9189
542.24976	1.5532777	0.4296802	3435.9297
543.25073	1.5591528	0.43076649	3442.8721
544.25171	1.558996	0.4318932	3434.6851
545.25269	1.5643659	0.43309814	3442.5435
546.25366	1.5665492	0.43408817	3444.9287
547.25464	1.5679253	0.43539068	3442.8901
548.25562	1.5725092	0.4366225	3444.5444
549.25659	1.5768389	0.43807527	3446.3025
550.25757	1.5799623	0.43919879	3450.7722
551.25854	1.5800585	0.4403199	3442.4946
552.25952	1.5842458	0.44138628	3449.9851
553.2605	1.5900294	0.44253772	3455.0347
554.26147	1.5883976	0.44378027	3449.5466
555.26245	1.5935847	0.44481251	3442.0947
556.26343	1.5982673	0.44579908	3448.5586
557.2644	1.6034809	0.44685248	3452.1123
558.26538	1.6054299	0.44792226	3453.6782
559.26636	1.6056597	0.44908535	3455.4036
560.26733	1.6093879	0.4505384	3463.6707
561.26831	1.6113878	0.45205057	3458.7744
562.26929	1.6138321	0.45351243	3459.3354
563.27026	1.6187961	0.45470864	3459.3005
564.27124	1.6228503	0.45586067	3456.8538
565.27222	1.6225344	0.45693359	3459.314
566.27319	1.6253827	0.45821148	3454.5874
567.27417	1.6299505	0.45930344	3459.5935
568.27515	1.6350286	0.46038345	3463.4695
569.27612	1.639097	0.46154463	3469.9824
570.2771	1.6386008	0.46277988	3461.3604
571.27808	1.6433554	0.4639062	3462.0366
572.27905	1.6452192	0.46502277	3470.3699
573.28003	1.6480488	0.46616289	3465.3074
574.28101	1.65153	0.46727076	3466.7881
575.28198	1.6544138	0.46850511	3470.1187
576.28296	1.6601216	0.46960863	3476.2563
577.28394	1.6633396	0.47096053	3476.5459
578.28491	1.6650953	0.47221577	3474.0427
579.28589	1.6652087	0.47337696	3467.9785
580.28687	1.6691837	0.47434166	3466.3318
581.28784	1.6702935	0.47516194	3464.1211
582.28882	1.6757896	0.47610331	3463.9507
583.28979	1.6785213	0.47702035	3471.8882
584.29077	1.6825495	0.47817838	3482.6704
585.29175	1.6839435	0.47942147	3477.4263
586.29272	1.6854982	0.48057592	3477.9795
587.2937	1.6884048	0.48180705	3476.7322
588.29468	1.6921654	0.48286539	3480.4351
589.29565	1.6985356	0.48406029	3478.5957
590.29663	1.6991621	0.48517573	3483.9019
591.29761	1.6998398	0.48649189	3481.4114
592.29858	1.7042978	0.48767769	3482.6167
593.29956	1.7079406	0.48902076	3483.5789
594.30054	1.7129058	0.49009299	3482.3149
595.30151	1.7156971	0.49113083	3481.0615
596.30249	1.7187413	0.49219152	3487.4849
597.30347	1.7180991	0.49337673	3484.3328
598.30444	1.7244089	0.49469665	3491.3145
599.30542	1.724641	0.49583095	3490.1194
600.3064	1.7292511	0.49696717	3486.2285
601.30737	1.7341871	0.4979552	3486.5754
602.30835	1.737473	0.49887288	3486.9417
603.30933	1.739202	0.50010496	3492.9492
604.3103	1.7440327	0.50122058	3498.6951
605.31128	1.7418207	0.50265455	3494.7227
606.31226	1.7454815	0.5038504	3493.165
607.31323	1.7524441	0.50503165	3501.1357
608.31421	1.7565358	0.50613928	3494.0342
609.31519	1.7558032	0.50729263	3494.4155
610.31616	1.758714	0.50855696	3491.2202
611.31714	1.7642728	0.50972903	3505.0247
612.31812	1.7621266	0.51085281	3488.5149
613.31909	1.7707795	0.51182169	3492.5569
614.32007	1.7725604	0.51286471	3496.2241
615.32104	1.7716954	0.51394391	3499.3215
616.32202	1.7750798	0.5151329	3498.3318
617.323	1.7809867	0.51642591	3504.3826
618.32397	1.7813311	0.51761407	3499.7319
619.32495	1.7860433	0.51862752	3497.0129
620.32593	1.7887279	0.51967293	3496.3245
621.3269	1.7959347	0.52081108	3502.6238
622.32788	1.7962662	0.5219245	3505.0269
623.32886	1.8003711	0.52324003	3506.0234
624.32983	1.8004152	0.52447331	3507.5195
625.33081	1.8056756	0.52572107	3506.7468
626.33179	1.8068514	0.526766	3503.1848
627.33276	1.8147445	0.52779287	3511.4739
628.33374	1.8142151	0.52900547	3510.5149
629.33472	1.8185722	0.53010118	3512.3799
630.33569	1.8172693	0.53117901	3505.4055
631.33667	1.8222435	0.53240597	3514.6987
632.33765	1.8261971	0.53382081	3515.2188
633.33862	1.8268353	0.53513491	3515.1157
634.3396	1.831508	0.53615814	3507.9048
635.34058	1.8336589	0.53739637	3511.1487
636.34155	1.837618	0.53828657	3506.9346
637.34253	1.842093	0.53938591	3515.1206
638.34351	1.8430732	0.54064244	3518.5789
639.34448	1.8467036	0.54180062	3523.0029
640.34546	1.848487	0.54312551	3525.0881
641.34644	1.8531047	0.54446977	3527.0664
642.34741	1.8576987	0.54555166	3517.6045
643.34839	1.8612146	0.54658008	3519.0161
644.34937	1.8609059	0.54775131	3519.6125
645.35034	1.8664168	0.54897314	3520.8652
646.35132	1.8682491	0.55013829	3526.001
647.35229	1.8704813	0.55121434	3523.082
648.35327	1.8730798	0.55244094	3517.542
649.35425	1.8765811	0.55370522	3532.801
650.35522	1.8760656	0.55501437	3521.5986
651.3562	1.8814868	0.55620164	3524.0093
652.35718	1.8862641	0.55739236	3528.3555
653.35815	1.8892769	0.55855519	3521.0188
654.35913	1.8902388	0.55962306	3525.0691
655.36011	1.8934618	0.56080317	3530.3625
656.36108	1.8981053	0.56200761	3526.468
657.36206	1.9017887	0.56298602	3529.3726
658.36304	1.90194	0.56423759	3533.9536
659.36401	1.9071763	0.56545663	3538.2646
660.36499	1.9077994	0.56676745	3529.2019
661.36597	1.9128435	0.5679884	3535.8333
662.36694	1.9184699	0.56897801	3534.7515
663.36792	1.9184661	0.57026201	3541.9368
664.3689	1.9197136	0.57141036	3529.9487
665.36987	1.9266243	0.5725739	3532.9507
666.37085	1.9273324	0.5738399	3541.1782
667.37183	1.9316407	0.57529855	3542.4612
668.3728	1.9307587	0.57668793	3542.2578
669.37378	1.9373174	0.5781647	3545.4758
670.37476	1.9395938	0.57937461	3535.6304
671.37573	1.9445843	0.58038461	3535.5251
672.37671	1.947752	0.58129048	3539.3374
673.37769	1.9497395	0.58250707	3541.0017
674.37866	1.9547659	0.58357608	3544.2805
675.37964	1.9574438	0.58480203	3542.7319
676.38062	1.9572613	0.58591646	3532.6282
677.38159	1.9585875	0.58680153	3536.3193
678.38257	1.9631467	0.58805329	3543.0579
679.38354	1.9653431	0.58932513	3548.2339
680.38452	1.9685888	0.59066492	3548.0935
681.3855	1.9730425	0.59177792	3545.0735
682.38647	1.9761795	0.59302545	3549.2942
683.38745	1.9779985	0.59430492	3548.6035
684.38843	1.9828458	0.59542912	3547.0479
685.3894	1.9809213	0.59652561	3542.1252
686.39038	1.9863493	0.59757656	3551.8208
687.39136	1.9890463	0.59887505	3552.6228
688.39233	1.9962401	0.59978998	3552.7683
689.39331	1.9981036	0.60122889	3555.9712
690.39429	2.0013573	0.60261333	3556.1694
691.39526	2.0032165	0.60403788	3558.3511
692.39624	2.0076134	0.60528255	3552.1619
693.39722	2.007453	0.6066007	3552.2222
694.39819	2.0126131	0.60759586	3551.9719
695.39917	2.0145938	0.60882509	3549.2031
696.40015	2.0159349	0.61002767	3552.0249
697.40112	2.0231719	0.61125708	3552.1895
698.4021	2.0215275	0.61252666	3551.7551
699.40308	2.0303206	0.6135003	3560.8098
700.40405	2.0284212	0.61466497	3556.7744
701.40503	2.0334554	0.61602616	3561.624
702.40601	2.0381153	0.61727417	3562.4812
703.40698	2.0381625	0.61832434	3554.2576
704.40796	2.041795	0.61924142	3549.7439
705.40894	2.0431051	0.62040478	3559.3787
706.40991	2.0497503	0.62182277	3564.3105
707.41089	2.0503306	0.62300509	3566.9163
708.41187	2.0538063	0.62419027	3563.8357
709.41284	2.0563385	0.6254639	3565.2283
710.41382	2.0593727	0.62684649	3559.4763
711.41479	2.0635257	0.6281203	3568.7502
712.41577	2.0668592	0.62955636	3569.7791
713.41675	2.0667944	0.63117629	3561.2451
714.41772	2.0728049	0.63218105	3568.8149
715.4187	2.0746448	0.63318908	3562.3328
716.41968	2.0791054	0.63466299	3573.2336
717.42065	2.0816855	0.63613629	3569.8838
718.42163	2.084321	0.63711941	3573.2844
719.42261	2.0868492	0.63847768	3565.9917
720.42358	2.0873938	0.63982022	3562.7407
721.42456	2.0930758	0.6412465	3567.7444
722.42554	2.0968857	0.64243752	3571.73
723.42651	2.1017945	0.64357781	3572.1902
724.42749	2.1000438	0.64499575	3569.6289
725.42847	2.1062224	0.64601588	3571.9182
726.42944	2.108902	0.64720887	3565.8628
727.43042	2.1099179	0.64850664	3576.9587
728.4314	2.1149325	0.64997101	3574.3086
729.43237	2.1160064	0.65138686	3579.5811
730.43335	2.1202857	0.6527611	3574.9841
731.43433	2.1243837	0.65415043	3584.3923
732.4353	2.1241543	0.65579003	3579.822
733.43628	2.1296773	0.65722775	3571.7273
734.43726	2.133491	0.6584428	3573.6995
735.43823	2.1365917	0.65957958	3577.9634
736.43921	2.139111	0.66088009	3576.6104
737.44019	2.1396592	0.66195834	3573.1758
738.44116	2.1431663	0.66334492	3579.4192
739.44214	2.1458151	0.66482198	3585.8499
740.44312	2.1514452	0.66598898	3581.1516
741.44409	2.1525264	0.66747129	3580.6907
742.44507	2.1588962	0.66879767	3581.3525
743.44604	2.159369	0.6699509	3578.116
744.44702	2.1631601	0.67122525	3586.0886
745.448	2.1638622	0.67253989	3578.1228
746.44897	2.1663697	0.67383629	3585.866
747.44995	2.1711273	0.67511374	3586.8606
748.45093	2.1731899	0.67641973	3578.9707
749.4519	2.1770968	0.67783505	3592.8477
750.45288	2.180208	0.67932564	3583.3203
751.45386	2.1821959	0.68075174	3586.3887
752.45483	2.1852922	0.68200946	3586.4551
753.45581	2.1895692	0.68337363	3584.4431
754.45679	2.190814	0.68446499	3583.1399
755.45776	2.1948588	0.68564701	3589.3162
756.45874	2.1993575	0.68693918	3588.54
757.45972	2.2016687	0.6881988	3593.2366
758.46069	2.2048783	0.68967628	3592.0208
759.46167	2.2067192	0.69088078	3584.4927
760.46265	2.2119095	0.69224048	3591.7478
761.46362	2.2138877	0.69360256	3594.3259
762.4646	2.216439	0.69505143	3592.3757
763.46558	2.2181933	0.69638216	3591.3022
764.46655	2.2238693	0.69766331	3596.2676
765.46753	2.2241457	0.69886577	3591.1038
766.46851	2.2284892	0.70001376	3599.2288
767.46948	2.2283449	0.70117265	3592.9807
768.47046	2.2337453	0.70248187	3594.5515
769.47144	2.2378671	0.70389706	3590.9834
770.47241	2.2387395	0.70503765	3588.8953
771.47339	2.242094	0.70613134	3596.1621
772.47437	2.2440755	0.70722044	3594.1189
773.47534	2.2497418	0.70854163	3604.1216
774.47632	2.2527547	0.70995873	3602.1003
775.47729	2.2548025	0.71153933	3601.1362
776.47827	2.2564633	0.7130028	3604.7659
777.47925	2.2578919	0.71460873	3598.5603
778.48022	2.2604742	0.71566719	3592.0425
779.4812	2.2698002	0.71684337	3601.1904
780.48218	2.2695937	0.71807724	3598.3267
781.48315	2.2712934	0.71932518	3602.8115
782.48413	2.2771885	0.72048885	3600.6904
783.48511	2.2802858	0.72202981	3607.4434
784.48608	2.2810869	0.72352588	3602.2253
785.48706	2.2869205	0.72474623	3600.937
786.48804	2.2879262	0.72596371	3602.687
787.48901	2.2913446	0.72722864	3605.0159
788.48999	2.2945397	0.7286486	3607.9031
789.49097	2.2957869	0.73011041	3601.5476
790.49194	2.3010864	0.73155504	3605.6062
791.49292	2.3024988	0.73272711	3605.0234
792.4939	2.3055122	0.73417652	3607.198
793.49487	2.3125412	0.73543328	3606.0828
794.49585	2.3109429	0.73671639	3603.9258
795.49683	2.3174124	0.73784673	3608.6252
796.4978	2.3170183	0.73901814	3607.2903
797.49878	2.3226304	0.74030256	3609.8435
798.49976	2.3247361	0.74155098	3614.6885
799.50073	2.3240938	0.74314088	3613.9231
800.50171	2.3291295	0.74470294	3613.0327
801.50269	2.332515	0.7462607	3610.7168
802.50366	2.3342481	0.74779606	3606.406
803.50464	2.33899	0.74897623	3607.2114
804.50562	2.3407674	0.75014561	3609.0964
805.50659	2.344383	0.75147849	3608.7263
806.50757	2.3467534	0.75298983	3608.1492
807.50854	2.3523877	0.7543245	3615.7859
808.50952	2.3555384	0.7558077	3618.4709
809.5105	2.3565118	0.75720143	3611.2139
810.51147	2.3623679	0.75864142	3615.5818
811.51245	2.361196	0.75989485	3615.197
812.51343	2.3650148	0.76132506	3611.8525
813.5144	2.3698413	0.76259977	3615.3269
814.51538	2.3714693	0.76385033	3611.02
815.51636	2.3769262	0.76511973	3610.8809
816.51733	2.3783946	0.76678431	3623.3491
817.51831	2.3799837	0.76820952	3618.3342
818.51929	2.3835518	0.76972431	3613.6553
819.52026	2.38639	0.77109802	3618.9026
820.52124	2.3899319	0.77248085	3616.1294
821.52222	2.3941145	0.77410263	3617.8879
822.52319	2.3976431	0.77530676	3620.239
823.52417	2.3999226	0.7767657	3620.6416
824.52515	2.4026237	0.77832901	3621.155
825.52612	2.4047554	0.7794947	3616.7944
826.5271	2.409766	0.78085899	3620.5872
827.52808	2.4083469	0.7821002	3611.3215
828.52905	2.4158103	0.78351694	3619.4836
829.53003	2.4188352	0.78497124	3619.9478
830.53101	2.4228075	0.78627568	3616.771
831.53198	2.4258549	0.78776121	3624.408
832.53296	2.4254658	0.78930879	3621.7222
833.53394	2.4295652	0.79076666	3616.8718
834.53491	2.4305575	0.79230642	3624.6787
835.53589	2.4370313	0.79372972	3623.4773
836.53687	2.4379203	0.79547232	3627.3291
837.53784	2.4402235	0.79689592	3622.2739
838.53882	2.4437239	0.79835337	3623.6682
839.53979	2.4473994	0.79985958	3623.7668
840.54077	2.4492307	0.80131513	3625.5479
841.54175	2.4536507	0.80263382	3618.5779
842.54272	2.4589233	0.80397505	3628.4172
843.5437	2.4585466	0.80540746	3621.1897
844.54468	2.4632506	0.80668038	3622.2544
845.54565	2.4648452	0.80793476	3628.7673
846.54663	2.4662542	0.80954796	3628.1252
847.54761	2.4718518	0.81117356	3626.9072
848.54858	2.4727335	0.81270379	3621.2971
849.54956	2.4755976	0.81407768	3624.7253
850.55054	2.4797602	0.81579041	3625.5317
851.55151	2.4859133	0.81718367	3629.947
852.55249	2.4839869	0.81887573	3620.6206
853.55347	2.4884357	0.82027054	3627.054
854.55444	2.4923091	0.82166785	3628.896
855.55542	2.4949353	0.82312179	3627.6145
856.5564	2.4988098	0.82448661	3628.6758
857.55737	2.5014923	0.82603228	3629.198
858.55835	2.5024626	0.82769376	3628.7544
859.55933	2.5066662	0.82917827	3635.3669
860.5603	2.5118699	0.83077621	3628.9058
861.56128	2.5139694	0.83235902	3625.0381
862.56226	2.5172851	0.83376151	3627.3381
863.56323	2.5188048	0.83507735	3628.5549
864.56421	2.5204937	0.83631057	3625.1584
865.56519	2.5218549	0.83752149	3629.3706
866.56616	2.5266764	0.83888787	3630.3079
867.56714	2.5305805	0.83995724	3627.8469
868.56812	2.5347097	0.84121913	3629.6624
869.56909	2.5380344	0.842628	3638.5212
870.57007	2.5402	0.8441667	3636.8457
871.57104	2.5402958	0.84576935	3638.3135
872.57202	2.5451381	0.84750813	3638.0237
873.573	2.5501606	0.84920067	3634.2861
874.57397	2.5514793	0.85039663	3635.3398
875.57495	2.5557992	0.85170352	3629.792
876.57593	2.5575693	0.85304433	3627.7874
877.5769	2.5599294	0.85445726	3632.6589
878.57788	2.5660696	0.85556877	3631.5664
879.57886	2.5680211	0.85717338	3639.0984
880.57983	2.5734496	0.85895681	3637.9504
881.58081	2.5748658	0.86062264	3640.6008
882.58179	2.5727587	0.86220193	3634.4556
883.58276	2.5797393	0.86411184	3636.2559
884.58374	2.5843863	0.86571687	3634.3384
885.58472	2.5864563	0.86711216	3637.3723
886.58569	2.590131	0.86859715	3640.8093
887.58667	2.5916443	0.87046856	3635.4827
888.58765	2.5925276	0.87188631	3632.5703
889.58862	2.596355	0.87337512	3635.7925
890.5896	2.5995829	0.87517965	3639.8499
891.59058	2.6036515	0.87680256	3636.073
892.59155	2.6059647	0.87819463	3634.375
893.59253	2.6071589	0.87970513	3632.6633
894.59351	2.6126506	0.88132048	3639.6321
895.59448	2.6155288	0.88308644	3643.3398
896.59546	2.6176224	0.88476753	3639.8218
897.59644	2.6208491	0.88648558	3641.6072
898.59741	2.6248612	0.88803428	3641.0061
899.59839	2.6279092	0.88958609	3633.2395
900.59937	2.6281941	0.89104956	3634.488
901.60034	2.6310096	0.89273208	3642.5715
902.60132	2.63694	0.89439219	3639.6721
903.60229	2.6388643	0.89608061	3642.6926
904.60327	2.6411021	0.89766681	3634.0454
905.60425	2.6435726	0.89913958	3641.5173
906.60522	2.6492758	0.9007892	3645.3555
907.6062	2.6509321	0.90246648	3643.0527
908.60718	2.6546097	0.90416783	3644.9407
909.60815	2.654237	0.90596724	3638.1274
910.60913	2.6588717	0.90753281	3637.71
911.61011	2.6617866	0.90914172	3638.2417
912.61108	2.665905	0.91059089	3640.3538
913.61206	2.6695337	0.91188902	3633.4075
914.61304	2.6740456	0.91333133	3641.7385
915.61401	2.6745677	0.91476369	3640.2727
916.61499	2.6797383	0.91630816	3640.9771
917.61597	2.6820531	0.91761208	3647.2708
918.61694	2.6835248	0.91941845	3644.2678
919.61792	2.6881199	0.92095268	3649.6929
920.6189	2.6899066	0.92242485	3645.9309
921.61987	2.6934779	0.92404425	3639.3213
922.62085	2.6963563	0.92548561	3640.0195
923.62183	2.6998808	0.92701191	3645.6045
924.6228	2.7027402	0.92831081	3648.3162
925.62378	2.7066131	0.92997342	3648.6509
926.62476	2.7130699	0.93147427	3648.3149
927.62573	2.7154977	0.9332397	3646.0435
928.62671	2.7162182	0.93506289	3646.5215
929.62769	2.7153084	0.93675339	3644.5554
930.62866	2.7214336	0.93826282	3644.3274
931.62964	2.7236397	0.93972331	3643.2034
932.63062	2.728514	0.94119	3648.1174
933.63159	2.730901	0.94292843	3646.0938
934.63257	2.7325466	0.94446737	3641.2039
935.63354	2.7353768	0.94605076	3645.1084
936.63452	2.7373214	0.94765949	3644.293
937.6355	2.7432737	0.94906873	3641.3845
938.63647	2.7434635	0.95070773	3646.3845
939.63745	2.74635	0.95210546	3644.6279
940.63843	2.7519116	0.95374346	3649.0898
941.6394	2.7544322	0.9552539	3645.2588
942.64038	2.7570503	0.95668125	3642.8799
943.64136	2.7585447	0.95810997	3647.7097
944.64233	2.7611778	0.95991629	3644.519
945.64331	2.7669826	0.96173066	3647.2056
946.64429	2.7678654	0.96326965	3648.9468
947.64526	2.7719123	0.96490556	3646.3936
948.64624	2.7751176	0.96669179	3645.2393
949.64722	2.7784595	0.96844786	3652.8748
950.64819	2.7815769	0.9700582	3647.5579
951.64917	2.7834623	0.97145897	3646.2046
952.65015	2.7874274	0.9731068	3645.2424
953.65112	2.7895012	0.97464013	3653.0115
954.6521	2.7914431	0.97650892	3651.8223
955.65308	2.7966602	0.97827899	3645.6785
956.65405	2.7990592	0.97982329	3649.3267
957.65503	2.7992432	0.98177356	3645.8262
958.65601	2.8075702	0.98375636	3652.5837
959.65698	2.8096421	0.98525137	3649.9175
960.65796	2.8097761	0.98720407	3648.9839
961.65894	2.8130589	0.98895591	3643.5547
962.65991	2.8184128	0.99055201	3650.6643
963.66089	2.8199692	0.99225527	3647.0996
964.66187	2.8224833	0.99380487	3649.9702
965.66284	2.8243358	0.99569869	3646.1575
966.66382	2.8294709	0.99729699	3648.1509
967.66479	2.8308399	0.99892443	3651.5515
968.66577	2.8313739	1.0006263	3647.4172
969.66675	2.8380122	1.0024583	3651.0081
970.66772	2.8393452	1.0040746	3648.2368
971.6687	2.8460693	1.0058601	3646.4153
972.66968	2.8439758	1.0074928	3644.9719
973.67065	2.8493063	1.0094084	3656.0662
974.67163	2.8526781	1.0109513	3642.2156
975.67261	2.8577397	1.0125721	3644.6875
976.67358	2.8580649	1.0140797	3646.8643
977.67456	2.8621931	1.0159147	3650.0657
978.67554	2.8646512	1.0176798	3647.3425
979.67651	2.8652527	1.0192606	3646.0942
980.67749	2.8703628	1.0209923	3643.4719
981.67847	2.8766489	1.0225673	3650.8225
982.67944	2.8747935	1.0244651	3651.1301
983.68042	2.8793325	1.0264636	3651.6094
984.6814	2.8809977	1.0283942	3650.7087
985.68237	2.8840866	1.0303221	3646.1265
986.68335	2.8885021	1.0320386	3648.3015
987.68433	2.8919406	1.0339255	3650.8738
988.6853	2.8956513	1.0360799	3657.3899
989.68628	2.8987834	1.0378125	3646.8889
990.68726	2.9014843	1.0395936	3654.2039
991.68823	2.9025655	1.0413325	3644.1978
992.68921	2.9041717	1.0433285	3647.573
993.69019	2.9125962	1.0448594	3644.2151
994.69116	2.9138358	1.0463682	3648.4333
995.69214	2.9140193	1.0483294	3652.4771
996.69312	2.9196777	1.0502677	3651.8049
997.69409	2.9211812	1.0525044	3653.0295
998.69507	2.9229238	1.0545841	3649.0591
999.69604	2.9272511	1.0563995	3642.9219
1000.697	2.9310019	1.058334	3642.5557
1001.698	2.9332612	1.060012	3649.7986
1002.699	2.9375119	1.0618864	3650.3467
1003.7	2.9376802	1.0638679	3648.7524
1004.7009	2.9446826	1.0656954	3646.9971
1005.7019	2.9439964	1.0672306	3643.3401
1006.7029	2.9511311	1.0690838	3651.3811
1007.7039	2.9532146	1.0708437	3646.2708
1008.7048	2.9560716	1.07274	3653.0674
1009.7058	2.9559159	1.0745612	3645.0884
1010.7068	2.9598653	1.076026	3644.1362
1011.7078	2.9646885	1.0781721	3648.1855
1012.7087	2.9618473	1.0802348	3643.9932
1013.7097	2.9722321	1.0821462	3649.3132
1014.7107	2.9708841	1.0838774	3646.9116
1015.7117	2.9768074	1.0857755	3651.4316
1016.7126	2.9778359	1.0876474	3650.4712
1017.7136	2.9838016	1.0895907	3656.3232
1018.7146	2.9889998	1.0916653	3645.5547
1019.7156	2.9885442	1.0932559	3645.7983
1020.7166	2.9943278	1.0948415	3642.7712
1021.7175	2.9931455	1.0965048	3642.7666
1022.7185	2.9974401	1.0980054	3645.7417
1023.7195	3.0023575	1.0997792	3647.3235
1024.7205	3.0033517	1.1016179	3649.4829
1025.7214	3.0059741	1.1035922	3645.22
1026.7224	3.0064788	1.1056128	3643.4524
1027.7234	3.0115371	1.1078088	3647.9221
1028.7244	3.0167499	1.1102523	3645.5059
1029.7253	3.0180919	1.1120375	3640.3374
1030.7263	3.019779	1.1138337	3642.0891
1031.7273	3.0222235	1.1160176	3651.179
1032.7283	3.02775	1.1180049	3643.2783
1033.7292	3.02773	1.1200824	3644.4465
1034.7302	3.0341654	1.1221076	3643.5024
1035.7312	3.0372937	1.1239332	3639.8157
1036.7322	3.0430088	1.1257014	3637.9216
1037.7332	3.041677	1.1275951	3638.823
1038.7341	3.0475368	1.1298513	3647.4937
1039.7351	3.0466084	1.1320583	3640.1184
1040.7361	3.0493038	1.1340215	3639.2874
1041.7371	3.0526955	1.136011	3641.7522
1042.738	3.0566349	1.1379242	3634.4148
1043.739	3.057256	1.1395634	3634.4817
1044.74	3.0631678	1.1412661	3643.2
1045.741	3.0657256	1.1429987	3637.9602
1046.7419	3.0692258	1.145021	3641.7258
1047.7429	3.073158	1.1471652	3641.8013
1048.7439	3.0760083	1.1493583	3641.5881
1049.7449	3.0773492	1.1515033	3644.394
1050.7458	3.0798242	1.1537076	3637.2668
1051.7468	3.0813293	1.1559566	3634.906
1052.7478	3.0854712	1.1580731	3639.0369
1053.7488	3.0875869	1.1601298	3634.5249
1054.7498	3.0954933	1.162153	3641.7615
1055.7507	3.0962563	1.1638933	3637.6589
1056.7517	3.0983131	1.1661067	3641.1526
1057.7527	3.1047189	1.168101	3640.6626
1058.7537	3.1024675	1.1699985	3630.0393
1059.7546	3.1088295	1.1719698	3630.5183
1060.7556	3.1103108	1.174148	3636.1726
1061.7566	3.1136825	1.1762139	3641.5254
1062.7576	3.1179466	1.1786559	3636.2126
1063.7585	3.121325	1.1814655	3645.8069
1064.7595	3.1228838	1.1840253	3635.5591
1065.7605	3.1271732	1.1861578	3630.0764
1066.7615	3.1301844	1.1882652	3630.1355
1067.7625	3.1307895	1.1900039	3629.7893
1068.7634	3.1331725	1.1917189	3628.2581
1069.7644	3.1369631	1.1939213	3636.2285
1070.7654	3.1404245	1.1962248	3632.0652
1071.7664	3.1482115	1.1985213	3636.6255
1072.7673	3.1489451	1.2007113	3630.4006
1073.7683	3.1494875	1.2029186	3629.7915
1074.7693	3.1524329	1.2053971	3632.6379
1075.7703	3.1544971	1.2078745	3625.8806
1076.7712	3.1592586	1.2100744	3622.9338
1077.7722	3.1612446	1.2123945	3626.533
1078.7732	3.1619651	1.214604	3618.3745
1079.7742	3.1667778	1.2167081	3616.5559
1080.7751	3.1731339	1.2183645	3622.1194
1081.7761	3.1731606	1.2204252	3623.6257
1082.7771	3.1771305	1.222379	3627.7551
1083.7781	3.177568	1.2244412	3622.5811
1084.7791	3.1852446	1.2266164	3624.6047
1085.78	3.1855898	1.2289516	3623.4951
1086.781	3.1921265	1.231189	3620.7234
1087.782	3.1920116	1.2330236	3620.3423
1088.783	3.1948278	1.2355902	3622.3459
1089.7839	3.1965122	1.2381506	3620.085
1090.7849	3.1989017	1.2404613	3614.3672
1091.7859	3.2063441	1.2425835	3620.1272
1092.7869	3.2066665	1.2447364	3615.2058
1093.7878	3.2118182	1.2469711	3623.4814
1094.7888	3.2121012	1.2491999	3613.884
1095.7898	3.2146983	1.2517806	3616.0139
1096.7908	3.2179735	1.2544786	3615.8728
1097.7917	3.223731	1.2571797	3615.6687
1098.7927	3.2253709	1.2599131	3611.2085
1099.7937	3.2292349	1.262427	3613.3618
1100.7947	3.2293732	1.2644556	3611.1838
1101.7957	3.2340066	1.2665712	3611.8523
1102.7966	3.2347822	1.2691131	3609.7673
1103.7976	3.2408216	1.2716761	3606.8206
1104.7986	3.2433112	1.2742321	3608.9216
1105.7996	3.2487209	1.2768679	3611.5366
1106.8005	3.248318	1.2794716	3607.9875
1107.8015	3.2514133	1.2818431	3601.8523
1108.8025	3.2541404	1.2841668	3603.5571
1109.8035	3.2572293	1.2868218	3599.4849
1110.8044	3.2618003	1.2892376	3598.3325
1111.8054	3.2605798	1.2915254	3600.9099
1112.8064	3.2683861	1.2938906	3604.3506
1113.8074	3.2661927	1.296509	3599.3501
1114.8083	3.276233	1.2989802	3597.8101
1115.8093	3.2756157	1.3014139	3595.0034
1116.8103	3.2788844	1.3040007	3595.5674
1117.8113	3.281744	1.306392	3592.6924
1118.8123	3.2877011	1.3084453	3593.3884
1119.8132	3.2884157	1.3106859	3589.1426
1120.8142	3.2918506	1.3129301	3586.6121
1121.8152	3.2941399	1.315394	3588.8452
1122.8162	3.2956514	1.3179094	3587.0383
1123.8171	3.3007338	1.3203522	3584.4783
1124.8181	3.3029876	1.322885	3587.1926
1125.8191	3.3074067	1.3260132	3596.4304
1126.8201	3.3104451	1.3291993	3576.1406
1127.821	3.3124957	1.3313912	3576.7612
1128.822	3.3132074	1.3338735	3578.7693
1129.823	3.3151252	1.3366106	3577.1816
1130.824	3.3222556	1.3391439	3571.0547
1131.825	3.3238316	1.3417615	3574.2942
1132.8259	3.3289948	1.3441365	3582.71
1133.8269	3.3295689	1.347109	3577.571
1134.8279	3.33251	1.350125	3574.9241
1135.8289	3.3365247	1.3533405	3567.5923
1136.8298	3.3417795	1.3557079	3569.5664
1137.8308	3.3423209	1.3584108	3566.4424
1138.8318	3.3460758	1.3609443	3569.7415
1139.8328	3.3481278	1.3635558	3569.5288
1140.8337	3.3520644	1.3660389	3559.9761
1141.8347	3.3524184	1.3687419	3560.5195
1142.8357	3.3574123	1.3711758	3558.0938
1143.8367	3.3614213	1.3735456	3565.115
1144.8376	3.3637171	1.3760172	3552.939
1145.8386	3.3647494	1.3786879	3562.2791
1146.8396	3.3686137	1.3813478	3555.3743
1147.8406	3.372792	1.3842124	3553.4028
1148.8416	3.3751466	1.3872644	3547.5454
1149.8425	3.3820946	1.3897085	3551.4875
1150.8435	3.3814721	1.3924747	3554.9626
1151.8445	3.3834572	1.3950746	3542.5798
1152.8455	3.3866825	1.3971689	3542.9343
1153.8464	3.3908789	1.3994514	3543.4128
1154.8474	3.3943803	1.4016761	3536.9578
1155.8484	3.3954766	1.4041473	3537.3184
1156.8494	3.3994815	1.4066823	3539.219
1157.8503	3.4047134	1.4092164	3538.9304
1158.8513	3.4047821	1.411701	3540.0764
1159.8523	3.4047163	1.4149094	3535.9487
1160.8533	3.4111471	1.417791	3530.0298
1161.8542	3.4153256	1.4204996	3529.8091
1162.8552	3.4175184	1.4235013	3525.1533
1163.8562	3.4215443	1.4262255	3520.5142
1164.8572	3.425467	1.4291587	3530.2754
1165.8582	3.426791	1.4317117	3516.8384
1166.8591	3.4293258	1.4342569	3512.7576
1167.8601	3.4350524	1.4367946	3513.2412
1168.8611	3.436672	1.4388665	3510.7129
1169.8621	3.4374113	1.441579	3517.7412
1170.863	3.4418514	1.4446716	3512.2686
1171.864	3.4451938	1.4479696	3509.5537
1172.865	3.4476922	1.4508967	3501.5508
1173.866	3.45016	1.4535604	3505.5669
1174.8669	3.4545262	1.4561126	3496.9417
1175.8679	3.4544032	1.4589542	3497.3545
1176.8689	3.4598727	1.4622451	3494.8076
1177.8699	3.4648464	1.4650285	3492.6226
1178.8708	3.4655547	1.4680846	3493.4287
1179.8718	3.4680796	1.4709858	3488.2153
1180.8728	3.4710634	1.4736043	3486.6792
1181.8738	3.4750099	1.4761921	3478.0237
1182.8748	3.4759343	1.479197	3484.4539
1183.8757	3.4784665	1.4827129	3471.509
1184.8767	3.4816246	1.4854875	3469.6045
1185.8777	3.4876451	1.4880234	3472.7739
1186.8787	3.4858963	1.4909154	3470.2446
1187.8796	3.4939625	1.4936372	3466.1333
1188.8806	3.4956813	1.496127	3465.0713
1189.8816	3.4977896	1.4992385	3464.8521
1190.8826	3.5047152	1.5020578	3458.9504
1191.8835	3.5044906	1.5048406	3460.0569
1192.8845	3.5072579	1.5074766	3456.2563
1193.8855	3.5105746	1.5103635	3449.656
1194.8865	3.513891	1.5135674	3452.0215
1195.8875	3.5161178	1.5169669	3450.8711
1196.8884	3.519644	1.5204455	3445.1147
1197.8894	3.5232813	1.5236336	3440.7908
1198.8904	3.5251205	1.526647	3432.4136
1199.8914	3.5290217	1.5292494	3428.8767
1200.8923	3.5330889	1.5316252	3428.9287
1201.8933	3.5338719	1.534479	3430.324
1202.8943	3.5375278	1.5374362	3424.8882
1203.8953	3.5393338	1.5404586	3420.7017
1204.8962	3.5426531	1.5438082	3424.7852
1205.8972	3.5440614	1.5476314	3418.4358
1206.8982	3.5497715	1.5513037	3413.0117
1207.8992	3.5552118	1.5548522	3405.2639
1208.9001	3.5550282	1.5578209	3402.3948
1209.9011	3.5595272	1.5612727	3399.7627
1210.9021	3.5601876	1.5643502	3396.1218
1211.9031	3.5652101	1.5671961	3397.6423
1212.9041	3.5668092	1.5708756	3400.0313
1213.905	3.5740066	1.5744846	3385.1233
1214.906	3.5743446	1.5776272	3373.9172
1215.907	3.5776525	1.5804782	3372.7886
1216.908	3.5782788	1.5831711	3372.916
1217.9089	3.5825229	1.5863633	3368.3108
1218.9099	3.5830729	1.5891355	3356.6426
1219.9109	3.589498	1.5917869	3356.5471
1220.9119	3.5913129	1.5948014	3357.3813
1221.9128	3.5948811	1.5978059	3348.7625
1222.9138	3.5975916	1.600891	3352.8486
1223.9148	3.6002252	1.6045839	3344.6787
1224.9158	3.6041307	1.6079575	3338.3752
1225.9167	3.6048956	1.6114239	3330.1609
1226.9177	3.6113207	1.6145594	3331.2432
1227.9187	3.6121292	1.6179241	3322.2334
1228.9197	3.6156883	1.6209148	3319.4304
1229.9207	3.6196358	1.6239523	3312.387
1230.9216	3.6218846	1.6269594	3307.5144
1231.9226	3.6284101	1.6305052	3305.3879
1232.9236	3.6286602	1.6345505	3293.5549
1233.9246	3.6301081	1.6378073	3284.9514
1234.9255	3.6352806	1.6410966	3280.2571
1235.9265	3.6374023	1.644856	3277.5215
1236.9275	3.641505	1.6487352	3265.373
1237.9285	3.6444416	1.652218	3253.9636
1238.9294	3.6465652	1.655578	3237.856
1239.9304	3.6511602	1.6619384	3198.4404
1240.1306	3.6539981	1.6754265	3058.6716