File: datasets/am_bench_2022/raw_data/0-X.11-1/specimen.dat
MTS793|MPT|ENU|1|2|.|/|:|1|0|0|A

Operator Information						Time:	45.253906	Sec	10/12/2021 4:44:07 PM
Operator	Nick Derimow
Project	AM Bench 2022 mini-tensile challenge
Specimen ID	O-X.11-1
Material	PBF-L Inconel 625
Specimen Width	2.56	mm
Specimen Thickness	1.54	mm
Notes
Operator Information End

Data Acquisition						Time:	1046.248	Sec	10/12/2021 5:00:48 PM
Time	Axial Displacement	Axial Extensometer	Axial Force
Sec	mm	mm	N
45.36792	0.0040569836	-6.199754e-05	50.305912
46.468994	0.0047441879	8.6981752e-05	65.535492
47.570068	0.01185708	0.00016197492	83.075111
48.671143	0.013527556	0.00026634126	94.144341
49.772217	0.013519156	0.00040418986	105.94882
50.873291	0.01785849	0.00030316427	121.97295
51.974365	0.024147976	0.00044074241	138.52399
53.075439	0.025639532	0.00063375582	145.33185
54.176514	0.026500074	0.00095161138	166.81093
55.277588	0.032254182	0.00071811251	180.11525
56.378662	0.035917785	0.00081933173	202.776
57.479736	0.035714328	0.00095330377	217.45251
58.580811	0.038342822	0.0010328701	239.71832
59.681885	0.0437355	0.0011771533	262.61923
60.782959	0.04681829	0.0013450553	284.59302
61.884033	0.050667118	0.0013715641	306.04938
62.985107	0.056708839	0.0015740466	332.95581
64.086182	0.056344748	0.0016644814	357.67697
65.187256	0.059583869	0.001863534	377.73984
66.28833	0.064169481	0.0019763173	399.79034
67.389404	0.065496713	0.0020127622	417.31183
68.490479	0.069069959	0.0022359192	447.10422
69.591553	0.075562701	0.002236665	467.21417
70.692627	0.076654568	0.0023668997	496.53177
71.793701	0.081065409	0.0026076487	521.85278
72.894775	0.082522333	0.0026422211	549.13702
73.99585	0.086063057	0.0027339712	572.07208
75.096924	0.089900613	0.0029097605	596.82318
76.197998	0.093312405	0.0031061464	625.92963
77.299072	0.099019386	0.0033550654	661.82758
78.400146	0.098883547	0.0033019218	677.31598
79.501221	0.10360869	0.0035175101	715.29657
80.602295	0.10642691	0.0037118911	740.92279
81.703369	0.1127668	0.0037015607	776.15442
82.804443	0.11547459	0.0040641245	801.09393
83.905518	0.11518268	0.0039809388	824.52826
85.006592	0.1167443	0.0040963241	851.1748
86.107666	0.12427558	0.0043017045	884.67114
87.20874	0.12598683	0.0044023381	919.3175
88.309814	0.13089515	0.0047052568	954.08087
89.410889	0.13643837	0.0047972109	985.40363
90.511963	0.13565917	0.0049153296	1009.0371
91.613037	0.14091872	0.005215033	1050.5931
92.714111	0.14122216	0.005311891	1077.0459
93.815186	0.14548774	0.0053842994	1103.0815
94.91626	0.14943056	0.0056063123	1138.0864
96.017334	0.15131207	0.0056909444	1165.5983
97.118408	0.15799946	0.005829297	1189.9586
98.219482	0.16024624	0.0059829508	1222.6979
99.320557	0.16296202	0.0062212576	1263.4963
100.42163	0.16704099	0.0063736155	1299.8706
101.52271	0.16680762	0.0065842373	1333.3065
102.62378	0.17256679	0.0067381542	1367.1771
103.72485	0.17662707	0.0068944884	1400.4788
104.82593	0.18030219	0.0070595425	1435.5848
105.927	0.18382032	0.0071846959	1465.3625
107.02808	0.18797383	0.0074658771	1496.9528
108.12915	0.1926541	0.0074794572	1524.1975
109.23022	0.19322349	0.0076561654	1547.358
110.3313	0.19467616	0.0080190478	1584.7859
111.43237	0.19639085	0.0079608969	1606.2241
112.53345	0.20007351	0.0082641924	1635.5424
113.63452	0.2040256	0.0084613487	1669.3835
114.7356	0.20802876	0.0086204251	1693.1304
115.83667	0.20997395	0.0088381963	1720.5242
116.93774	0.21924742	0.0089029009	1760.8964
118.03882	0.22009894	0.009311256	1788.368
119.13989	0.22310525	0.0094938772	1820.6555
120.24097	0.22503881	0.0094744246	1838.0074
121.34204	0.22581944	0.0098572802	1863.6165
122.44312	0.23169786	0.0099533899	1893.0089
123.54419	0.2338904	0.010277051	1924.8816
124.64526	0.23746529	0.010496271	1952.2037
125.74634	0.24189068	0.010697224	1979.3931
126.84741	0.2454129	0.010979766	2000.5374
127.94849	0.24809186	0.011270519	2021.7233
129.04956	0.25086766	0.011286456	2041.6932
130.15063	0.2511625	0.011655251	2068.834
131.25171	0.26041958	0.011931712	2101.1804
132.35278	0.26140389	0.012115543	2116.5444
133.45386	0.26551354	0.012471872	2145.6226
134.55493	0.26866326	0.01288914	2163.502
135.65601	0.27119178	0.013201862	2185.3367
136.75708	0.27675411	0.013533548	2209.9099
137.85815	0.27698317	0.013855559	2223.2393
138.95923	0.28273258	0.014138977	2245.0767
140.0603	0.28452942	0.014591371	2268.9402
141.16138	0.2918286	0.015013375	2289.6677
142.26245	0.29167205	0.015417224	2300.0605
143.36353	0.29431018	0.015882013	2322.8677
144.4646	0.2964898	0.016172769	2328.6389
145.56567	0.3009865	0.016883045	2352.6653
146.66675	0.30562848	0.01729702	2366.5349
147.76782	0.31242788	0.017678607	2384.821
148.8689	0.31227645	0.01836605	2398.0474
149.96997	0.31576636	0.018812237	2406.6563
151.07104	0.32139748	0.019365408	2422.8921
152.17212	0.32416305	0.019980581	2429.4124
153.27319	0.32389629	0.020542709	2441.4421
154.37427	0.32836947	0.021214232	2441.1956
155.47534	0.33337429	0.021910841	2471.686
156.57642	0.33564258	0.022773901	2474.5623
157.67749	0.33854645	0.023652526	2485.8726
158.77856	0.3428129	0.024190871	2494.4653
159.87964	0.3471241	0.025196651	2510.7847
160.98071	0.34616774	0.026230454	2513.8235
162.08179	0.35173187	0.027261171	2526.2813
163.18286	0.35402355	0.028172826	2523.7021
164.28394	0.35696599	0.029262194	2533.8232
165.38501	0.36090842	0.030184027	2544.8
166.48608	0.36663055	0.03149832	2560.1997
167.58716	0.37035322	0.032481119	2559.4512
168.68823	0.37057465	0.033609897	2562.5828
169.78931	0.37589663	0.034668967	2572.9731
170.89038	0.37891731	0.035994042	2571.7856
171.99146	0.38027695	0.037316877	2582.7781
173.09253	0.38776809	0.03854439	2584.3953
174.1936	0.38820574	0.039664324	2589.2288
175.29468	0.393866	0.040902499	2596.8818
176.39575	0.39418542	0.042281181	2598.3477
177.49683	0.399708	0.043365158	2595.2334
178.5979	0.40129563	0.044365674	2594.2839
179.69897	0.40261003	0.045517225	2608.8857
180.80005	0.41108093	0.04720214	2623.7048
181.90112	0.41163516	0.048742194	2612.8501
183.0022	0.41523874	0.050079219	2612.5015
184.10327	0.4196133	0.051820673	2628.5593
185.20435	0.42147329	0.05321236	2626.3958
186.30542	0.42620602	0.055062652	2631.1355
187.40649	0.42829937	0.056522433	2633.1355
188.50757	0.43162858	0.057908136	2626.4329
189.60864	0.43471608	0.059431396	2637.8398
190.70972	0.43832743	0.061144907	2641.1907
191.81079	0.44289869	0.062603779	2639.6116
192.91187	0.44603944	0.064175457	2644.4063
194.01294	0.45187283	0.065452784	2649.5083
195.11401	0.45311776	0.067132458	2649.9231
196.21509	0.45716059	0.069115818	2648.1521
197.31616	0.45816103	0.070564233	2648.9592
198.41724	0.46257499	0.072396807	2658.6643
199.51831	0.46349597	0.074332222	2663.6208
200.61938	0.46891731	0.075987794	2659.2446
201.72046	0.4702372	0.077564463	2661.6169
202.82153	0.47492915	0.07935334	2667.5894
203.92261	0.47694919	0.081283815	2657.1353
205.02368	0.47996941	0.08293885	2664.9558
206.12476	0.48448229	0.084778011	2671.3044
207.22583	0.48847249	0.08658018	2666.2263
208.3269	0.49134153	0.08819966	2668.2368
209.42798	0.4951877	0.089863054	2676.0022
210.52905	0.49694607	0.091615014	2671.0176
211.63013	0.50444955	0.093472369	2682.5774
212.7312	0.50555813	0.095547102	2686.4292
213.83228	0.50881338	0.097170278	2676.8108
214.93335	0.51373833	0.098926857	2681.8215
216.03442	0.51395839	0.10048647	2686.4331
217.1355	0.52025235	0.10257076	2686.5637
218.23657	0.52148497	0.10441702	2687.7703
219.33765	0.5231759	0.10581571	2679.6404
220.43872	0.52840221	0.10779729	2688.2368
221.53979	0.5315764	0.10976074	2696.3604
222.64087	0.53379756	0.11175612	2692.2451
223.74194	0.53886563	0.11340762	2698.1948
224.84302	0.54271984	0.11506537	2692.3826
225.94409	0.54417026	0.11726604	2707.1147
227.04517	0.55072236	0.11934695	2697.293
228.14624	0.55183899	0.12127806	2700.0386
229.24731	0.55571431	0.12285951	2700.908
230.34839	0.55757856	0.12434138	2701.4219
231.44946	0.55916113	0.12641796	2701.3572
232.55054	0.56574601	0.12831843	2710.3416
233.65161	0.56640679	0.13016284	2695.8496
234.75269	0.5721451	0.13222183	2706.4241
235.85376	0.57412744	0.13393673	2705.2051
236.95483	0.57910085	0.13633193	2716.5432
238.05591	0.58081597	0.138228	2707.9065
239.15698	0.58562964	0.13983487	2716.1365
240.25806	0.58684278	0.14142986	2712.2766
241.35913	0.58875418	0.14312543	2717.4241
242.46021	0.59807956	0.14518228	2721.5156
243.56128	0.60135734	0.14708789	2711.7544
244.66235	0.59790438	0.1488613	2719.1567
245.76343	0.60271037	0.15076827	2716.3223
246.8645	0.60686183	0.15257758	2718.7129
247.96558	0.61231637	0.15444678	2722.9424
249.06665	0.61544448	0.15602902	2716.6475
250.16772	0.61708146	0.15784912	2719.3838
251.2688	0.62094587	0.15983821	2725.5325
252.36987	0.62266737	0.16182029	2718.6006
253.47095	0.62824959	0.16371231	2722.8884
254.57202	0.63034719	0.16577092	2731.5283
255.6731	0.63583577	0.16783234	2734.8867
256.77417	0.63570547	0.16963558	2725.2944
257.87524	0.6400739	0.17134951	2727.7351
258.97632	0.64466321	0.17317234	2733.772
260.07739	0.64607096	0.17504808	2728.1167
261.17847	0.6506722	0.17697415	2731.6023
262.27954	0.65433228	0.17914452	2739.1157
263.38062	0.65778959	0.18108383	2743.4038
264.48169	0.66112292	0.18304847	2737.293
265.58276	0.66583377	0.18504423	2740.9409
266.68384	0.66709703	0.1872534	2741.8823
267.78491	0.67049432	0.18907031	2740.4067
268.88599	0.67406732	0.19085842	2741.8696
269.98706	0.67829937	0.19287601	2743.4114
271.08813	0.68095922	0.19512779	2748.3096
272.18921	0.68150115	0.19723101	2739.8127
273.29028	0.68529588	0.19914483	2746.9949
274.39136	0.69448698	0.20057347	2743.3726
275.49243	0.69488961	0.20240037	2757.7134
276.59351	0.696886	0.20416866	2752.9573
277.69458	0.70017487	0.20615362	2749.6067
278.79565	0.70353633	0.2081916	2749.8687
279.89673	0.70705485	0.20996119	2757.8127
280.9978	0.7113905	0.21201526	2757.8027
282.09888	0.712973	0.21381445	2758.5212
283.19995	0.71935046	0.21572059	2763.6846
284.30103	0.72051007	0.21777202	2761.9275
285.4021	0.72333342	0.21965788	2762.0144
286.50317	0.72586304	0.22146003	2753.501
287.60425	0.73298579	0.2232445	2763.0044
288.70532	0.73531616	0.22522126	2764.4783
289.8064	0.73868454	0.22719522	2763.4893
290.90747	0.74097943	0.22917996	2765.0918
292.00854	0.74372661	0.23090208	2763.7271
293.10962	0.74632591	0.23293559	2766.4854
294.21069	0.74878371	0.23481524	2771.1094
295.31177	0.75525713	0.23690508	2774.7368
296.41284	0.75510776	0.23909523	2772.3184
297.51392	0.76150668	0.24123432	2773.6062
298.61499	0.76307327	0.24333331	2776.9048
299.71606	0.76400423	0.24534324	2768.167
300.81714	0.77140832	0.24723062	2778.8005
301.91821	0.77360409	0.24918786	2776.519
303.01929	0.77965611	0.25140616	2779.9043
304.12036	0.78239834	0.25309256	2781.9265
305.22144	0.78213811	0.25531146	2777.5447
306.32251	0.78760862	0.25719255	2779.0085
307.42358	0.78877348	0.25895786	2778.3943
308.52466	0.79166174	0.2610825	2778.4885
309.62573	0.79588079	0.26299307	2782.2798
310.72681	0.79702204	0.26526195	2780.5291
311.82788	0.80529481	0.26710609	2783.0046
312.92896	0.80815446	0.26872191	2789.845
314.03003	0.81025338	0.27070224	2790.4177
315.1311	0.81170499	0.27268994	2785.7805
316.23218	0.81301445	0.27440104	2782.7742
317.33325	0.81862426	0.2763935	2790.927
318.43433	0.82224876	0.27862266	2793.0942
319.5354	0.82589436	0.28030026	2787.623
320.63647	0.82768261	0.28184852	2785.2295
321.73755	0.83094156	0.28359759	2791.8052
322.83862	0.83594024	0.28567913	2799.135
323.9397	0.83815962	0.28773099	2792.1016
325.04077	0.84403497	0.2897287	2797.5361
326.14185	0.84609902	0.29143086	2794.8577
327.24292	0.85068876	0.29324788	2802.4768
328.34399	0.8500374	0.29509807	2802.8716
329.44507	0.85772234	0.2969217	2797.2102
330.54614	0.86005807	0.29878253	2804.0842
331.64722	0.86133635	0.30052951	2801.595
332.74829	0.86747241	0.30254158	2807.8252
333.84937	0.86960119	0.30473986	2801.8152
334.95044	0.87290049	0.30668783	2806.5093
336.05151	0.87782562	0.30900997	2807.6548
337.15259	0.87580746	0.3109192	2808.2517
338.25366	0.88155192	0.31328419	2809.4355
339.35474	0.88362765	0.31545058	2810.5076
340.45581	0.8893041	0.31743765	2807.0786
341.55688	0.89137042	0.31948194	2810.3762
342.65796	0.89463097	0.32136503	2806.7817
343.75903	0.89772171	0.32324749	2817.2388
344.86011	0.89919877	0.32527789	2816.4412
345.96118	0.90424132	0.32708839	2807.2246
347.06226	0.91021383	0.32917246	2821.874
348.16333	0.91268986	0.33117643	2816.8528
349.2644	0.91335022	0.33330336	2816.3569
350.36548	0.9175486	0.33544061	2817.3379
351.46655	0.92277038	0.33695823	2819.7075
352.56763	0.92472583	0.33893389	2821.9092
353.6687	0.92915124	0.34063026	2819.084
354.76978	0.92953992	0.34246787	2819.9741
355.87085	0.93283433	0.3444978	2823.0435
356.97192	0.93910062	0.34642714	2825.4421
358.073	0.94197744	0.34887275	2827.5107
359.17407	0.9461742	0.35088208	2828.6023
360.27515	0.9467178	0.35278222	2828.7161
361.37622	0.95237434	0.35468644	2831.1472
362.47729	0.95257819	0.35630569	2826.7605
363.57837	0.95911419	0.35840204	2830.4517
364.67944	0.96046114	0.36078036	2835.3213
365.78052	0.96314639	0.36293441	2824.8262
366.88159	0.96989232	0.36439681	2834.927
367.98267	0.9739967	0.36645484	2835.4502
369.08374	0.97579396	0.36842951	2833.1299
370.18481	0.97823805	0.37037662	2835.28
371.28589	0.98028588	0.37215829	2835.3442
372.38696	0.98473281	0.37396485	2833.0266
373.48804	0.98829252	0.37594324	2839.49
374.58911	0.99026459	0.3781797	2835.6162
375.69019	0.99663782	0.37995049	2848.9531
376.79126	0.99668437	0.3825185	2839.1277
377.89233	1.0033702	0.38493863	2847.0305
378.99341	1.0026183	0.38679507	2833.7695
380.09448	1.0079265	0.3886593	2841.6245
381.19556	1.0099878	0.39047638	2847.4834
382.29663	1.0124391	0.39242104	2847.4312
383.39771	1.0184773	0.39450258	2846.8542
384.49878	1.0215085	0.39655924	2850.335
385.59985	1.0228204	0.39867422	2853.0325
386.70093	1.0276392	0.40075681	2847.1646
387.802	1.0313262	0.40267095	2853.2329
388.90308	1.0332226	0.40461802	2849.9604
390.00415	1.0366868	0.40657321	2854.6343
391.10522	1.0387543	0.40863314	2850.6023
392.2063	1.0452451	0.41039613	2853.5906
393.30737	1.046821	0.41262373	2858.4277
394.40845	1.0478771	0.41476226	2855.7219
395.50952	1.0562562	0.41669741	2857.9558
396.6106	1.0579495	0.41876644	2859.1338
397.71167	1.0588179	0.42063564	2856.6147
398.81274	1.0618623	0.42231628	2858.4727
399.91382	1.065053	0.42423692	2858.4482
401.01489	1.0719413	0.42599824	2865.3376
402.11597	1.0741674	0.4280816	2860.4536
403.21704	1.0765506	0.43029207	2863.0444
404.31812	1.0809108	0.43229815	2866.5757
405.41919	1.0826144	0.43403718	2858.7463
406.52026	1.0865721	0.43577415	2860.5544
407.62134	1.0902086	0.43802062	2875.7646
408.72241	1.0951679	0.44012186	2867.7322
409.82349	1.0938575	0.44208616	2868.9373
410.92456	1.1000031	0.44430527	2868.0981
412.02563	1.1059508	0.44616181	2870.1274
413.12671	1.106779	0.44815868	2873.3889
414.22778	1.1094067	0.44992331	2870.9961
415.32886	1.110389	0.45217958	2877.0042
416.42993	1.1162164	0.45441175	2867.1599
417.53101	1.1205125	0.45646414	2872.0615
418.63208	1.1232039	0.45844078	2876.1553
419.73315	1.1284206	0.46050772	2878.075
420.83423	1.1289762	0.46243039	2873.6433
421.9353	1.1310831	0.46443176	2876.2021
423.03638	1.1324172	0.46670797	2879.5513
424.13745	1.1393981	0.46866283	2879.626
425.23853	1.143277	0.47050464	2870.9121
426.3396	1.1438135	0.47237381	2880.9045
427.44067	1.1512126	0.47431937	2886.7371
428.54175	1.1529295	0.47609788	2885.6658
429.64282	1.1546764	0.47783163	2883.9541
430.7439	1.1597464	0.47979558	2891.426
431.84497	1.1634626	0.48170224	2886.772
432.94604	1.1664362	0.48367286	2885.4099
434.04712	1.1674961	0.48559043	2888.0422
435.14819	1.1745329	0.48767319	2887.3799
436.24927	1.1765813	0.48944524	2888.7183
437.35034	1.1793526	0.49116999	2895.407
438.45142	1.1833562	0.49329153	2892.5261
439.55249	1.1830859	0.49579927	2893.7063
440.65356	1.18889	0.49828786	2903.4507
441.75464	1.1915755	0.50040197	2886.3276
442.85571	1.1944107	0.50245988	2896.1267
443.95679	1.2008481	0.50419849	2891.552
445.05786	1.2053049	0.50601637	2897.4692
446.15894	1.2076266	0.50856376	2904.114
447.26001	1.2116888	0.5107125	2899.926
448.36108	1.2119573	0.5123691	2897.5723
449.46216	1.2162088	0.51403958	2900.4954
450.56323	1.2207837	0.51622999	2901.9365
451.66431	1.2223208	0.51826483	2899.6904
452.76538	1.2274885	0.52022147	2901.5955
453.86646	1.2299606	0.52235842	2901.5125
454.96753	1.2293833	0.52419871	2901.6311
456.0686	1.2378751	0.5258134	2904.1208
457.16968	1.2404131	0.52784693	2903.2537
458.27075	1.2421334	0.5296725	2905.4233
459.37183	1.242744	0.5317452	2909.7588
460.4729	1.2504729	0.53366655	2908.9097
461.57397	1.2506946	0.53561997	2909.7185
462.67505	1.2534387	0.53762329	2906.9878
463.77612	1.2569351	0.53958857	2910.9058
464.8772	1.2611194	0.54114181	2908.1777
465.97827	1.2628398	0.54315203	2914.4922
467.07935	1.2668337	0.54496789	2912.6443
468.18042	1.2731786	0.54707557	2917.0044
469.28149	1.2755898	0.54914558	2915.668
470.38257	1.2780267	0.55101556	2912.6455
471.48364	1.2844504	0.55292678	2918.48
472.58472	1.284608	0.55485755	2915.4736
473.68579	1.2892369	0.5568943	2922.4626
474.78687	1.2930019	0.55919135	2920.3735
475.88794	1.2988576	0.56116545	2924.6704
476.98901	1.2988889	0.5631901	2919.0757
478.09009	1.3014671	0.56508595	2922.4543
479.19116	1.3023936	0.56708395	2916.0991
480.29224	1.3067181	0.56894344	2926.4158
481.39331	1.3098215	0.57148153	2926.79
482.49438	1.3162696	0.57357103	2925.0933
483.59546	1.3160261	0.57535708	2920.6331
484.69653	1.3209827	0.57730108	2924.7871
485.79761	1.3240702	0.57925695	2930.8872
486.89868	1.3299692	0.58115214	2921.8616
487.99976	1.3337148	0.58307189	2934.946
489.10083	1.3339485	0.5853107	2932.5178
490.2019	1.3391215	0.58747774	2932.9839
491.30298	1.3396801	0.58955103	2926.6489
492.40405	1.3437018	0.59161258	2923.9778
493.50513	1.3481992	0.59331214	2935.0723
494.6062	1.3496766	0.59515351	2936.6772
495.70728	1.3538409	0.59700143	2932.0859
496.80835	1.3569155	0.59883958	2935.9448
497.90942	1.360697	0.60072315	2932.5352
499.0105	1.3649131	0.60270548	2937.0259
500.11157	1.3695534	0.60466313	2939.0737
501.21265	1.3678554	0.6067664	2938.4561
502.31372	1.3720092	0.60904598	2941.2825
503.41479	1.3784523	0.61079681	2942.4187
504.51587	1.3792565	0.61297494	2937.6614
505.61694	1.3847258	0.61493182	2943.5349
506.71802	1.3876604	0.6171695	2941.74
507.81909	1.3919971	0.61903429	2940.4612
508.92017	1.3958455	0.62082851	2939.7324
510.02124	1.3968372	0.62277538	2940.6975
511.12231	1.401613	0.62471181	2945.2593
512.22339	1.4043831	0.62704289	2949.2146
513.32446	1.404489	0.62912381	2951.228
514.42554	1.4106954	0.63107425	2947.0356
515.52661	1.4126114	0.63313693	2945.6157
516.62769	1.4153532	0.63484138	2940.7744
517.72876	1.419036	0.63685232	2950.6038
518.82983	1.424735	0.6389311	2954.4419
519.93091	1.4286777	0.64125073	2955.9348
521.03198	1.4287794	0.64327043	2956.9692
522.13306	1.4335856	0.64552677	2955.3562
523.23413	1.4366776	0.64736992	2954.6301
524.33521	1.4380915	0.64913392	2951.4841
525.43628	1.44396	0.65123266	2954.4731
526.53735	1.4464225	0.65326899	2957.9875
527.63843	1.4498519	0.65529561	2952.3484
528.7395	1.4547411	0.65733767	2957.8467
529.84058	1.4557499	0.6592862	2957.0107
530.94165	1.4617085	0.66132069	2960.8479
532.04272	1.4638481	0.66314697	2963.6599
533.1438	1.4632975	0.66517597	2964.9573
534.24487	1.4687021	0.66738188	2962.1516
535.34595	1.4738704	0.66939104	2961.4761
536.44702	1.4755355	0.67103541	2957.6497
537.5481	1.4812905	0.67299676	2964.1328
538.64917	1.4854015	0.6747185	2964.0806
539.75024	1.4842845	0.6771248	2964.7329
540.85132	1.4878249	0.67931521	2957.8823
541.95239	1.4948387	0.68103111	2960.0645
543.05347	1.4942787	0.68284416	2956.3057
544.15454	1.5010188	0.68432009	2966.0742
545.25562	1.5009862	0.68611854	2962.9067
546.35669	1.5045779	0.68810058	2964.761
547.45776	1.5089623	0.69010812	2967.4656
548.55884	1.5150604	0.69216979	2973.0181
549.65991	1.5163991	0.69416618	2976.0486
550.76099	1.5195413	0.69628972	2973.6804
551.86206	1.5229506	0.69875538	2978.5381
552.96313	1.5263675	0.70117474	2978.8376
554.06421	1.5291276	0.70341647	2969.2046
555.16528	1.533134	0.70532757	2975.9309
556.26636	1.5348963	0.707488	2978.5291
557.36743	1.5404463	0.70974243	2978.4866
558.46851	1.5420424	0.71172827	2977.9001
559.56958	1.5457925	0.71364397	2974.2617
560.67065	1.5488516	0.71568829	2974.9424
561.77173	1.5535444	0.71773744	2979.4055
562.8728	1.5522755	0.7196089	2971.7236
563.97388	1.5600506	0.72164547	2978.2766
565.07495	1.5610578	0.72389865	2983.6399
566.17603	1.565689	0.72592759	2978.9111
567.2771	1.5700066	0.72767884	2978.7034
568.37817	1.5732149	0.72888005	2979.6091
569.47925	1.5761832	0.7307778	2980.0962
570.58032	1.5787992	0.73298436	2982.8628
571.6814	1.5814457	0.73460722	2975.28
572.78247	1.5878735	0.73660576	2986.085
573.88354	1.5909511	0.73820412	2984.5991
574.98462	1.5915978	0.7403149	2991.3113
576.08569	1.5974706	0.74277073	2990.9038
577.18677	1.5970316	0.7449286	2985.6172
578.28784	1.6011064	0.74720508	2984.8367
579.38892	1.6056409	0.74911654	2984.4277
580.48999	1.6079996	0.75064856	2981.5408
581.59106	1.6120223	0.75261545	2988.198
582.69214	1.6162294	0.75449491	2988.6692
583.79321	1.6195519	0.75635058	2991.4529
584.89429	1.6213706	0.75837886	2991.7683
585.99536	1.6284976	0.76059163	2994.0022
587.09644	1.6286504	0.76240951	2988.9924
588.19751	1.6305676	0.76423067	2991.5681
589.29858	1.6341746	0.76635408	2990.3127
590.39966	1.6368414	0.7687242	2990.4856
591.50073	1.6412742	0.77073932	2993.0359
592.60181	1.648895	0.77294594	2999.6858
593.70288	1.6486546	0.77533609	2998.3506
594.80396	1.6504196	0.77711225	2987.1475
595.90503	1.6544259	0.77904791	2995.5288
597.0061	1.6586263	0.78124017	3003.5571
598.10718	1.6630738	0.78328294	2995.3193
599.20825	1.6647129	0.78532362	2997.4041
600.30933	1.6671101	0.78737104	2990.9812
601.4104	1.670718	0.78926349	2996.5508
602.51147	1.6762278	0.79113716	3001.7219
603.61255	1.6777412	0.79334569	3001.3425
604.71362	1.6847149	0.79526579	3004.813
605.8147	1.6829787	0.7972756	2994.5027
606.91577	1.6889557	0.79905283	3004.2534
608.01685	1.6916569	0.80074567	3005.8279
609.11792	1.6940857	0.80264336	2998.4912
610.21899	1.6991454	0.80411357	2998.7083
611.32007	1.7024038	0.80609083	3009.8333
612.42114	1.7054404	0.80807966	3001.0237
613.52222	1.7069855	0.81035417	3006.4636
614.62329	1.7119815	0.81236416	3006.5356
615.72437	1.7156781	0.81421369	3014.4927
616.82544	1.7172645	0.81665194	3010.2542
617.92651	1.7216908	0.8187902	3009.9226
619.02759	1.7233899	0.82069296	3005.5537
620.12866	1.730368	0.82283723	3017.4529
621.22974	1.7319161	0.82473791	3010.7336
622.33081	1.7319977	0.82655072	3009.3733
623.43188	1.7398084	0.82911313	3014.9255
624.53296	1.7409251	0.83130109	3016.9595
625.63403	1.7425137	0.83368772	3014.2383
626.73511	1.7471803	0.83574301	3016.0588
627.83618	1.7540506	0.83762771	3011.6919
628.93726	1.7521696	0.83963203	3013.4812
630.03833	1.7600182	0.84152061	3016.3325
631.1394	1.760913	0.84384078	3019.7373
632.24048	1.7644186	0.84551775	3009.1777
633.34155	1.7639605	0.84749269	3020.1313
634.44263	1.7688836	0.84958196	3016.1997
635.5437	1.7737885	0.85180008	3017.874
636.64478	1.7749083	0.85394895	3019.0735
637.74585	1.7790686	0.85605067	3021.5637
638.84692	1.7826681	0.85828209	3017.647
639.948	1.7897613	0.86028761	3024.6909
641.04907	1.787877	0.8621527	3019.79
642.15015	1.7928745	0.86384672	3013.8469
643.25122	1.7983966	0.86592567	3026.8152
644.35229	1.8017716	0.86788154	3028.387
645.45337	1.80265	0.869798	3016.1155
646.55444	1.8063635	0.8716808	3024.6863
647.65552	1.8084791	0.87409067	3022.8757
648.75659	1.8123167	0.87638146	3027.8496
649.85767	1.8167316	0.87836879	3019.4729
650.95874	1.821159	0.88013089	3027.7869
652.05981	1.8235261	0.88215739	3024.158
653.16089	1.8284836	0.88396162	3022.4412
654.26196	1.8301152	0.8858456	3028.1333
655.36304	1.8315252	0.8882125	3026.5237
656.46411	1.8381134	0.89044368	3031.2385
657.56519	1.8389345	0.8924545	3022.4385
658.66626	1.8425204	0.89453733	3038.0632
659.76733	1.8443383	0.89666289	3029.7361
660.86841	1.8494048	0.89871377	3030.6377
661.96948	1.8530836	0.90123117	3040.5686
663.07056	1.8578368	0.90341616	3028.5857
664.17163	1.8610442	0.90518445	3027.9407
665.27271	1.8607115	0.90725625	3029.1978
666.37378	1.8668232	0.90898603	3028.2034
667.47485	1.8690761	0.91064888	3033.3501
668.57593	1.8750128	0.91236383	3037.3013
669.677	1.8733487	0.91463971	3041.0579
670.77808	1.8768814	0.9170807	3038.0266
671.87915	1.8787766	0.91922283	3037.4587
672.98022	1.8862758	0.92145771	3037.135
674.0813	1.8907582	0.92389673	3037.3269
675.18237	1.8936388	0.92587948	3032.1001
676.28345	1.8950076	0.9274376	3032.01
677.38452	1.8950754	0.92949575	3032.3835
678.4856	1.9025726	0.93162835	3042.8601
679.58667	1.905918	0.93369079	3041.8215
680.68774	1.9092388	0.93560892	3034.3689
681.78882	1.9114532	0.93752539	3034.4175
682.88989	1.9161866	0.93970931	3038.46
683.99097	1.9199187	0.94179446	3040.9712
685.09204	1.9209892	0.94371814	3039.8206
686.19312	1.9285004	0.94590706	3043.6228
687.29419	1.9303147	0.94803095	3041.7144
688.39526	1.9316778	0.95019114	3042.76
689.49634	1.9342893	0.95181805	3033.6792
690.59741	1.9404685	0.95388043	3049.166
691.69849	1.9390502	0.95614713	3046.229
692.79956	1.9439939	0.95813972	3043.2075
693.90063	1.9491228	0.96045685	3044.634
695.00171	1.9538513	0.96279073	3053.4661
696.10278	1.9543445	0.96474469	3043.2178
697.20386	1.9572535	0.9671225	3049.2412
698.30493	1.9603285	0.96907854	3045.5474
699.40601	1.9669871	0.97139686	3058.1353
700.50708	1.9673092	0.9737702	3054.636
701.60815	1.9730537	0.97596002	3047.9382
702.70923	1.9741832	0.97824371	3056.2334
703.8103	1.978691	0.98016143	3047.77
704.91138	1.9812326	0.98211926	3046.8911
706.01245	1.9865419	0.98399681	3049.1067
707.11353	1.9867753	0.98639506	3049.7793
708.2146	1.9922302	0.98863208	3049.2844
709.31567	1.9975655	0.99061441	3053.9944
710.41675	1.9979093	0.9926725	3044.7544
711.51782	2.0024469	0.99443406	3053.1377
712.6189	2.0020938	0.99629247	3043.7388
713.71997	2.0119951	0.99798971	3050.7324
714.82104	2.0105441	1.0001096	3050.5325
715.92212	2.0130773	1.0021684	3052.5261
717.02319	2.0178804	1.0043272	3062.2952
718.12427	2.0227203	1.0064355	3055.3091
719.22534	2.0263698	1.0088582	3061.5723
720.32642	2.0265157	1.0108715	3050.8547
721.42749	2.0319233	1.0131389	3058.2451
722.52856	2.0331557	1.0152835	3054.6733
723.62964	2.037864	1.0175366	3060.3049
724.73071	2.0419488	1.019755	3060.5693
725.83179	2.0447516	1.0217544	3059.8459
726.93286	2.0484021	1.0238308	3056.0867
728.03394	2.05197	1.0258723	3061.7742
729.13501	2.0549414	1.0278386	3064.1082
730.23608	2.0542972	1.0303737	3062.7878
731.33716	2.061182	1.0321797	3058.9429
732.43823	2.0640469	1.0343403	3059.0129
733.53931	2.0659506	1.0365236	3061.2117
734.64038	2.0712323	1.038561	3060.2854
735.74146	2.0762966	1.0410659	3063.3555
736.84253	2.0771298	1.0430819	3064.5247
737.9436	2.0838232	1.0451188	3061.0925
739.04468	2.0830958	1.0472325	3061.4426
740.14575	2.0867853	1.0492916	3062.2373
741.24683	2.0907032	1.0513618	3063.3362
742.3479	2.0962815	1.0537531	3070.9771
743.44897	2.09466	1.056118	3067.8901
744.55005	2.0990756	1.0583237	3058.1704
745.65112	2.1054039	1.0602707	3064.2783
746.7522	2.1086764	1.0622938	3065.3933
747.85327	2.1118665	1.064395	3067.5691
748.95435	2.1120887	1.0663908	3060.5757
750.05542	2.1192937	1.0679456	3062.27
751.15649	2.1202629	1.0700663	3063.6941
752.25757	2.1222768	1.0723718	3068.6179
753.35864	2.1266208	1.074262	3064.0146
754.45972	2.1315961	1.0764487	3065.9175
755.56079	2.131722	1.0783896	3063.9827
756.66187	2.1374419	1.0805835	3067.186
757.76294	2.141216	1.0827988	3069.7095
758.86401	2.1439419	1.0845809	3067.9709
759.96509	2.1478338	1.087145	3069.6794
761.06616	2.1473091	1.0891776	3066.9539
762.16724	2.1535957	1.0912962	3072.8142
763.26831	2.1558831	1.0936822	3071.2905
764.36938	2.1604636	1.096006	3070.0327
765.47046	2.1631484	1.0981429	3069.4504
766.57153	2.1655796	1.1001803	3070.0459
767.67261	2.1724234	1.1022046	3072.9517
768.77368	2.174016	1.1045879	3078.2849
769.87476	2.1786082	1.1066508	3070.4258
770.97583	2.1781917	1.1086645	3068.7012
772.0769	2.1815453	1.1109623	3072.4897
773.17798	2.1845918	1.113042	3072.1489
774.27905	2.1933293	1.1152494	3078.1421
775.38013	2.1935146	1.1176877	3075.9822
776.4812	2.197973	1.1200113	3077.8579
777.58228	2.1972635	1.1223644	3072.0359
778.68335	2.203578	1.1249447	3081.4202
779.78442	2.204762	1.1269567	3070.2756
780.8855	2.209363	1.1293924	3079.0225
781.98657	2.2137294	1.1313688	3069.1255
783.08765	2.2147977	1.133639	3077.7822
784.18872	2.2181816	1.1356015	3072.1951
785.28979	2.2243855	1.1379274	3080.3472
786.39087	2.224834	1.1399865	3075.8967
787.49194	2.2304997	1.1425323	3074.7766
788.59302	2.2327173	1.144606	3075.7258
789.69409	2.237093	1.1464156	3073.7432
790.79517	2.239511	1.1486883	3078.5618
791.89624	2.2449915	1.1507351	3082.1614
792.99731	2.2488058	1.1529729	3083.0068
794.09839	2.2486496	1.1552972	3083.8206
795.19946	2.2555876	1.1579503	3088.1748
796.30054	2.257062	1.1603352	3088.2625
797.40161	2.260663	1.162554	3083.9341
798.50269	2.2608483	1.1647472	3070.9844
799.60376	2.2662513	1.1667379	3078.8137
800.70483	2.2690723	1.1686568	3078.0667
801.80591	2.2735286	1.1708519	3082.0374
802.90698	2.2750416	1.1732445	3087.7864
804.00806	2.2806048	1.1753467	3083.3975
805.10913	2.2832797	1.1776398	3084.3066
806.21021	2.2845483	1.1801586	3083.0115
807.31128	2.2892148	1.1825325	3073.4221
808.41235	2.2907746	1.1844028	3079.4607
809.51343	2.2952948	1.1866972	3089.7825
810.6145	2.3036733	1.1889988	3086.8071
811.71558	2.300247	1.1912196	3083.1333
812.81665	2.3040893	1.1938885	3083.9978
813.91772	2.3101404	1.1963722	3086.3145
815.0188	2.312571	1.1986558	3079.9209
816.11987	2.3143952	1.2007043	3081.0432
817.22095	2.321846	1.2026465	3080.3579
818.32202	2.3230677	1.2045745	3082.3428
819.4231	2.3261161	1.2067441	3085.8838
820.52417	2.3303058	1.2089653	3083.8647
821.62524	2.3344264	1.210939	3088.4653
822.72632	2.334594	1.2127442	3078.9939
823.82739	2.3417842	1.2150114	3087.572
824.92847	2.3415365	1.2174063	3091.1064
826.02954	2.3457778	1.2198727	3091.376
827.13062	2.3508184	1.2220789	3084.1072
828.23169	2.3507369	1.2240744	3080.1995
829.33276	2.3571653	1.2263372	3084.4106
830.43384	2.3603659	1.2286264	3089.0356
831.53491	2.3615198	1.2312005	3085.8206
832.63599	2.3649037	1.2334569	3087.4861
833.73706	2.3675137	1.2359918	3086.0852
834.83813	2.369493	1.2385008	3090.5657
835.93921	2.3765118	1.240752	3090.2329
837.04028	2.3793426	1.2433472	3088.4829
838.14136	2.3823259	1.24555	3089.4983
839.24243	2.3834975	1.2478906	3087.4502
840.34351	2.3871655	1.2508669	3093.6614
841.44458	2.3951902	1.2530707	3089.0134
842.54565	2.3960199	1.2552326	3091.21
843.64673	2.3952937	1.2576066	3085.9866
844.7478	2.4013546	1.2601537	3089.1362
845.84888	2.4014807	1.2622162	3087.5964
846.94995	2.411257	1.2647927	3097.4727
848.05103	2.4146566	1.267189	3089.2493
849.1521	2.4149046	1.2693352	3085.5085
850.25317	2.4193709	1.2714913	3092.3333
851.35425	2.420922	1.2736166	3085.1472
852.45532	2.4251101	1.2757812	3094.3845
853.5564	2.4303017	1.2779552	3095.1694
854.65747	2.4303958	1.2802747	3095.1489
855.75854	2.43346	1.2826335	3084.3044
856.85962	2.4360154	1.2851521	3086.2986
857.96069	2.4427328	1.2873865	3093.7527
859.06177	2.4437134	1.289748	3088.0581
860.16284	2.4468479	1.2919554	3093.3616
861.26392	2.4500084	1.2943184	3088.3062
862.36499	2.4548838	1.2968117	3095.0708
863.46606	2.4602494	1.2989668	3091.4592
864.56714	2.4598155	1.3013318	3089.8293
865.66821	2.4615061	1.3038366	3090.7268
866.76929	2.4699016	1.3063278	3092.7263
867.87036	2.4687829	1.3086022	3091.7288
868.97144	2.4739964	1.3105347	3092.9739
870.07251	2.4781561	1.3130866	3093.7935
871.17358	2.4814498	1.3154523	3092.2673
872.27466	2.4835973	1.3179244	3090.8232
873.37573	2.4880042	1.3201128	3088.969
874.47681	2.490994	1.3220755	3092.231
875.57788	2.4903688	1.3249984	3100.7092
876.67896	2.4984341	1.3276678	3095.4546
877.78003	2.4990821	1.3302333	3090.7603
878.8811	2.5032644	1.3327044	3094.0195
879.98218	2.5078776	1.3351612	3096.0994
881.08325	2.5090513	1.3373356	3085.9673
882.18433	2.5136492	1.3396751	3096.9272
883.2854	2.5191736	1.3422945	3098.5842
884.38647	2.52052	1.3447047	3092.6123
885.48755	2.522604	1.3468698	3095.0693
886.58862	2.5257843	1.3493527	3093.3069
887.6897	2.5312262	1.3517269	3095.2874
888.79077	2.5347943	1.3544195	3100.8459
889.89185	2.5346878	1.3572385	3093.7917
890.99292	2.5423403	1.3596323	3095.9229
892.09399	2.5453379	1.3619505	3097.4133
893.19507	2.5468478	1.3642925	3092.8203
894.29614	2.552402	1.3664534	3098.2786
895.39722	2.5511861	1.3686835	3088.9336
896.49829	2.5525565	1.3707267	3095.0605
897.59937	2.5572233	1.3731589	3094.0286
898.70044	2.5613863	1.3755347	3090.7949
899.80151	2.567296	1.3778313	3094.261
900.90259	2.5673943	1.3802079	3096.261
902.00366	2.5727861	1.3825258	3094.7817
903.10474	2.5759158	1.3855568	3102.0237
904.20581	2.5807042	1.3882139	3100.075
905.30688	2.5844822	1.390666	3095.9951
906.40796	2.5865521	1.3931444	3099.8687
907.50903	2.587878	1.3955245	3091.3408
908.61011	2.5920432	1.3983417	3096.8499
909.71118	2.5949194	1.4008579	3095.9595
910.81226	2.6002326	1.4035379	3094.8857
911.91333	2.6042795	1.4061747	3094.1292
913.0144	2.603137	1.4085687	3094.0461
914.11548	2.6102443	1.4110277	3094.4365
915.21655	2.6120965	1.4134606	3095.2322
916.31763	2.6179168	1.4156882	3099.0801
917.4187	2.6167622	1.4183996	3097.353
918.51978	2.6245856	1.4211179	3096.4639
919.62085	2.6249113	1.4235908	3093.2957
920.72192	2.6321154	1.4263232	3100.957
921.823	2.634645	1.4289082	3096.5872
922.92407	2.6382265	1.4310765	3092.5144
924.02515	2.6387522	1.4335415	3097.0837
925.12622	2.6444471	1.436028	3096.7617
926.22729	2.6454287	1.4383473	3095.7495
927.32837	2.6498449	1.4407755	3105.9187
928.42944	2.6535006	1.4434011	3099.0854
929.53052	2.6564457	1.4459597	3095.6206
930.63159	2.6613851	1.448489	3097.1946
931.73267	2.661505	1.4510502	3097.5134
932.83374	2.6690917	1.4539435	3098.2539
933.93481	2.6707885	1.455959	3094.7603
935.03589	2.6732435	1.4579874	3093.0095
936.13696	2.6750309	1.4604651	3099.2109
937.23804	2.6816721	1.4633752	3099.5959
938.33911	2.6838181	1.4658134	3097.6533
939.44019	2.685545	1.4685295	3095.6375
940.54126	2.6917441	1.4712437	3097.7119
941.64233	2.6922066	1.4740484	3094.4844
942.74341	2.6952322	1.4768732	3101.4717
943.84448	2.7016304	1.4800556	3096.4282
944.94556	2.7043579	1.4825734	3093.6328
946.04663	2.7066925	1.4849608	3094.6682
947.14771	2.7066014	1.4875531	3096.0779
948.24878	2.7118852	1.4902896	3098.4214
949.34985	2.7139926	1.4928812	3091.9568
950.45093	2.7182219	1.4955664	3094.3538
951.552	2.7224269	1.4983659	3097.01
952.65308	2.7267303	1.5010637	3100.8738
953.75415	2.7277472	1.5040495	3092.6157
954.85522	2.7311912	1.5067697	3099.6807
955.9563	2.7335451	1.509926	3095.5051
957.05737	2.741658	1.5128573	3097.6631
958.15845	2.7407272	1.515564	3097.0627
959.25952	2.746058	1.5183222	3090.7131
960.3606	2.7479901	1.5206954	3090.1438
961.46167	2.7495129	1.5235624	3097.9333
962.56274	2.752337	1.5262798	3091.511
963.66382	2.7554431	1.5290434	3092.1953
964.76489	2.7627668	1.5315607	3095.4092
965.86597	2.7646632	1.5340691	3095.1509
966.96704	2.7685273	1.5366694	3094.1064
968.06812	2.7741523	1.5389766	3092.5159
969.16919	2.7749391	1.5415637	3105.751
970.27026	2.7790027	1.5445064	3096.644
971.37134	2.782331	1.5472091	3089.4158
972.47241	2.7842615	1.5493001	3093.8777
973.57349	2.7887392	1.5520452	3103.8926
974.67456	2.7924271	1.5550945	3095.0408
975.77563	2.7908862	1.5581279	3094.7681
976.87671	2.7988358	1.5610696	3098.9082
977.97778	2.8001077	1.5636485	3091.3376
979.07886	2.8073351	1.5662115	3095.8303
980.17993	2.807066	1.568996	3091.0054
981.28101	2.8097074	1.5714837	3094.8032
982.38208	2.813004	1.5742464	3093.2451
983.48315	2.8173497	1.5770543	3095.8506
984.58423	2.8196235	1.5795187	3088.3765
985.6853	2.8238208	1.5825665	3096.324
986.78638	2.8250501	1.5854982	3095.5205
987.88745	2.8305843	1.5884219	3090.8718
988.98853	2.8333783	1.5914218	3089.47
990.0896	2.8371165	1.5940797	3091.8479
991.19067	2.8399513	1.5971351	3097.1204
992.29175	2.8407943	1.6002964	3091.6819
993.39282	2.8485694	1.6029054	3091.3179
994.4939	2.8504734	1.6060538	3090.4385
995.59497	2.8513854	1.6092079	3089.3704
996.69604	2.8584881	1.612323	3092.0295
997.79712	2.8618639	1.6147898	3086.9111
998.89819	2.8636353	1.617467	3090.0291
999.99927	2.8712358	1.6203359	3095.0647
1001.1003	2.8714199	1.6229824	3088.761
1002.2014	2.8713884	1.6262952	3089.4031
1003.3025	2.8801837	1.6293141	3086.8035
1004.4036	2.8813834	1.6318556	3091.5618
1005.5046	2.8829615	1.6347284	3094.4087
1006.6057	2.8883576	1.6379857	3093.3269
1007.7068	2.8911974	1.6409061	3088.8191
1008.8079	2.8952467	1.6433147	3086.6865
1009.9089	2.8998315	1.6458604	3085.3813
1011.01	2.8996675	1.6483471	3089.6079
1012.1111	2.9026942	1.6510499	3085.5315
1013.2122	2.9079256	1.653738	3088.3118
1014.3132	2.9113603	1.6567171	3087.1672
1015.4143	2.9145744	1.6597311	3091.7947
1016.5154	2.9143105	1.662832	3087.6807
1017.6165	2.9205527	1.6657686	3089.8545
1018.7175	2.9255528	1.6692541	3088.1704
1019.8186	2.9276731	1.6724141	3091.7346
1020.9197	2.9305353	1.6753861	3085.7168
1022.0208	2.9336295	1.6784246	3085.9595
1023.1218	2.937314	1.6814601	3084.6448
1024.2229	2.9379687	1.6845088	3080.8306
1025.324	2.9423308	1.6877942	3081.0261
1026.425	2.9457703	1.6912907	3080.3108
1027.5261	2.9485564	1.6943581	3083.7659
1028.6272	2.9532797	1.6967894	3075.9641
1029.7283	2.9587209	1.6999593	3086.0747
1030.8293	2.9587073	1.7028635	3084.8733
1031.9304	2.961416	1.7057574	3084.1863
1033.0315	2.9637518	1.709053	3078.0549
1034.1326	2.9720294	1.7119439	3078.7288
1035.2336	2.9724076	1.714307	3081.2932
1036.3347	2.973655	1.7176336	3080.5488
1037.4358	2.9778223	1.7206665	3081.3906
1038.5369	2.9842474	1.7239007	3086.1479
1039.6379	2.9860678	1.7262211	3072.2002
1040.739	2.9889979	1.7296236	3085.27
1041.8401	2.9898934	1.7329257	3077.2549
1042.9412	2.9975607	1.7358828	3082.2231
1044.0422	2.9993486	1.7391031	3077.8833
1045.1433	3.0022831	1.7419468	3072.6296
1046.2444	3.0039525	1.7445784	3073.939
1047.3455	3.0092127	1.7473387	3079.8206
1048.4465	3.0142772	1.7495344	3067.6138
1049.5476	3.0155101	1.751596	3067.7993
1050.6487	3.0200543	1.754202	3081.8389
1051.7498	3.0209985	1.7573273	3075.6042
1052.8508	3.025713	1.7606175	3073.1692
1053.9519	3.0315912	1.7639067	3078.095
1055.053	3.0317252	1.7677656	3074.0205
1056.1541	3.0356765	1.7707005	3067.9209
1057.2551	3.0383811	1.7743798	3079.0557
1058.3562	3.0445013	1.7775111	3072.865
1059.4573	3.0449529	1.7803934	3068.0938
1060.5583	3.0499694	1.7835786	3072.563
1061.6594	3.0502963	1.7866904	3068.5667
1062.7605	3.0554442	1.7898784	3072.4563
1063.8616	3.0576475	1.7929449	3064.2915
1064.9626	3.0613964	1.7957323	3067.4602
1066.0637	3.0630949	1.7987608	3065.2961
1067.1648	3.0667922	1.8021772	3070.1411
1068.2659	3.072885	1.8055241	3066.8799
1069.3669	3.0738499	1.8087659	3064.9951
1070.468	3.0768225	1.8117164	3063.8162
1071.5691	3.081198	1.8152587	3065.698
1072.6702	3.0864563	1.818796	3069.4092
1073.7712	3.0879738	1.8220735	3059.949
1074.8723	3.0912154	1.8251363	3061.6575
1075.9734	3.0946877	1.8279879	3062.5449
1077.0745	3.0977504	1.8310027	3058.5176
1078.1755	3.1031275	1.8336354	3060.4734
1079.2766	3.1043556	1.8366462	3061.1741
1080.3777	3.1095743	1.8402377	3063.6865
1081.4788	3.1104414	1.8431667	3056.6885
1082.5798	3.11375	1.846585	3062.0212
1083.6809	3.1197193	1.8500378	3061.1196
1084.782	3.1230459	1.8532138	3052.0562
1085.8831	3.1235023	1.8562261	3052.6274
1086.9841	3.1277645	1.8594371	3055.76
1088.0852	3.1323073	1.8630224	3054.8247
1089.1863	3.1336362	1.8665252	3051.6865
1090.2874	3.1386437	1.8702285	3056.2788
1091.3884	3.1417568	1.8743491	3056.554
1092.4895	3.1468518	1.8780947	3050.8518
1093.5906	3.1464877	1.8812081	3047.7156
1094.6917	3.1535103	1.8844553	3051.2205
1095.7927	3.1525018	1.8877805	3047.054
1096.8938	3.1556914	1.8904213	3042.6853
1097.9949	3.1601827	1.8938717	3045.4668
1099.0959	3.1638007	1.8975865	3046.8914
1100.197	3.1663399	1.9010329	3040.3879
1101.2981	3.1696174	1.9048958	3039.8889
1102.3992	3.1763604	1.907957	3041.208
1103.5002	3.1778708	1.9108593	3038.0989
1104.6013	3.1820452	1.9144011	3044.6433
1105.7024	3.1835897	1.9177275	3040.2085
1106.8035	3.1879749	1.921344	3040.4282
1107.9045	3.1925774	1.9249125	3036.2585
1109.0056	3.1954978	1.9279051	3033.1826
1110.1067	3.1969917	1.931201	3037.5315
1111.2078	3.201741	1.9341254	3032.3538
1112.3088	3.2019634	1.9372478	3034.3938
1113.4099	3.2065978	1.9405957	3034.866
1114.511	3.2115993	1.9438024	3029.8164
1115.6121	3.214442	1.9474105	3028.8762
1116.7131	3.2154443	1.9503211	3021.1636
1117.8142	3.2195599	1.9536754	3026.4343
1118.9153	3.2215564	1.9571468	3024.4998
1120.0164	3.2258346	1.9610206	3030.042
1121.1174	3.2331829	1.9645227	3020.9392
1122.2185	3.232373	1.9676113	3026.6021
1123.3196	3.2382367	1.971236	3022.0215
1124.4207	3.2408323	1.9745913	3018.6431
1125.5217	3.2444751	1.9777007	3016.1309
1126.6228	3.2485309	1.9811493	3019.2742
1127.7239	3.2509339	1.9850826	3017.48
1128.825	3.2523844	1.9886186	3010.6533
1129.926	3.2592423	1.991635	3009.2629
1131.0271	3.2626159	1.995006	3013.9836
1132.1282	3.2628856	1.9988725	3014.7505
1133.2292	3.2667377	2.0025802	3006.2969
1134.3303	3.2692728	2.006222	3006.658
1135.4314	3.2748759	2.0100095	3004.7791
1136.5325	3.2768772	2.0130126	3001.5261
1137.6335	3.2797475	2.0163906	2999.9377
1138.7346	3.2837465	2.0196311	3003.5159
1139.8357	3.2855098	2.0234654	3001.9534
1140.9368	3.2918622	2.0269554	2999.7974
1142.0378	3.2937026	2.0300643	2999.145
1143.1389	3.2977018	2.0336277	2993.1609
1144.24	3.3025107	2.0363734	2990.738
1145.3411	3.3027065	2.0391335	2990.5305
1146.4421	3.3049216	2.0419662	2992.1025
1147.5432	3.3103869	2.0446477	2991.6091
1148.6443	3.316298	2.0467482	2992.5581
1149.7454	3.3179369	2.0482085	2994.3945
1150.8464	3.320811	2.0492342	2989.3037
1151.9475	3.3257039	2.0494111	2985.9883
1153.0486	3.3276911	2.0492635	2991.5959
1154.1497	3.3294778	2.0497708	2981.3167
1155.2507	3.3312981	2.0496938	2978.7261
1156.3518	3.3379161	2.0496588	2975.2375
1157.4529	3.3398042	2.0497861	2972.7759
1158.554	3.3403482	2.0497625	2975.7085
1159.655	3.3447745	2.0496907	2974.895
1160.7561	3.3477745	2.0495622	2973.2104
1161.8572	3.3532834	2.049361	2971.3184
1162.9583	3.3533435	2.0495725	2968.333
1164.0593	3.3579948	2.0494254	2960.3977
1165.1604	3.3637462	2.049582	2964.0156
1166.2615	3.3661714	2.0494652	2957.2312
1167.3625	3.3695707	2.0494778	2963.8828
1168.4636	3.3717763	2.0497105	2956.2222
1169.5647	3.3731549	2.0494852	2959.0073
1170.6658	3.3803263	2.0494366	2955.0322
1171.7668	3.3841784	2.0494885	2953.293
1172.8679	3.3851461	2.0495095	2949.7627
1173.969	3.3924599	2.0493815	2945.6462
1175.0701	3.3904507	2.0496507	2948.127
1176.1711	3.3936083	2.0499518	2944.1687
1177.2722	3.3994906	2.0495515	2948.3096
1178.3733	3.4027631	2.0496018	2942.7969
1179.4744	3.4065299	2.0496433	2936.3826
1180.5754	3.4100165	2.0496595	2939.1443
1181.6765	3.4114811	2.0499146	2929.2471
1182.7776	3.4152489	2.0498664	2925.363
1183.8787	3.4197345	2.0495934	2928.679
1184.9797	3.4249663	2.0496895	2929.0645
1186.0808	3.4238193	2.0497611	2931.4172
1187.1819	3.4290595	2.0499506	2928.425
1188.283	3.432061	2.0494895	2919.1943
1189.384	3.4346471	2.049423	2921.325
1190.4851	3.4383276	2.0496955	2913.6101
1191.5862	3.4423225	2.0496275	2913.3513
1192.6873	3.4476259	2.0495379	2909.1143
1193.7883	3.4486167	2.0493839	2916.5183
1194.8894	3.451287	2.0493793	2907.2126
1195.9905	3.4549825	2.0493362	2903.7686
1197.0916	3.458776	2.0493979	2897.7642
1198.1926	3.4601247	2.049541	2898.5671
1199.2937	3.4670227	2.049489	2896.7488
1200.3948	3.4668419	2.0495055	2892.9963
1201.4958	3.4715595	2.0497105	2886.885
1202.5969	3.4742813	2.0499229	2882.2217
1203.698	3.4800723	2.0497353	2887.5701
1204.7991	3.481313	2.0496235	2880.7932
1205.9001	3.4866118	2.0494688	2880.8965
1207.0012	3.4896743	2.0499461	2879.6826
1208.1023	3.4917433	2.0497413	2877.1677
1209.2034	3.4946177	2.0495374	2867.3083
1210.3044	3.496793	2.0495842	2866.2507
1211.4055	3.504148	2.0497289	2870.3511
1212.5066	3.5070593	2.0498924	2862.864
1213.6077	3.5091255	2.0497324	2849.9138
1214.7087	3.5131638	2.0498941	2856.8591
1215.8098	3.5109408	2.0496469	2853.7183
1216.9109	3.5172431	2.0498154	2848.1582
1218.012	3.5230477	2.0498426	2846.301
1219.113	3.5238972	2.0500293	2841.7065
1220.2141	3.5287397	2.049931	2833.53
1221.3152	3.5339973	2.0497313	2837.3887
1222.4163	3.5342941	2.0495341	2834.0645
1223.5173	3.5378885	2.0499036	2829.1614
1224.6184	3.5433848	2.0498228	2826.9031
1225.7195	3.5453544	2.0498979	2828.6021
1226.8206	3.5479057	2.0497253	2820.5024
1227.9216	3.5496588	2.0493793	2815.0803
1229.0227	3.5530491	2.0495121	2817.9392
1230.1238	3.5584111	2.0493469	2809.9231
1231.2249	3.5604308	2.0494862	2810.7451
1232.3259	3.5627971	2.0493848	2808.7356
1233.427	3.5688622	2.0494745	2803.9539
1234.5281	3.569932	2.0492938	2794.7275
1235.6292	3.5751863	2.049185	2794.7083
1236.7302	3.5774162	2.0495162	2791.1719
1237.8313	3.5809155	2.0495405	2784.5359
1238.9324	3.5851209	2.0494204	2783.3757
1240.0334	3.5857649	2.0493062	2778.7468
1241.1345	3.5908601	2.0495532	2773.99
1242.2356	3.591928	2.049685	2769.0198
1243.3367	3.5971112	2.0495176	2765.1057
1244.4377	3.5989473	2.0496442	2760.1821
1245.5388	3.6057932	2.049577	2757.0691
1246.6399	3.6081381	2.0494859	2756.0193
1247.741	3.6101561	2.0494568	2749.6277
1248.842	3.6128225	2.0497072	2746.4587
1249.9431	3.6174273	2.0498335	2736.6169
1251.0442	3.6212821	2.0495968	2732.488
1252.1453	3.6265233	2.049535	2735.0334
1253.2463	3.6291537	2.0497103	2727.8306
1254.3474	3.6313536	2.0498571	2727.4973
1255.4485	3.6332746	2.0496011	2722.3364
1256.5496	3.6357944	2.0497282	2717.0688
1257.6506	3.6403747	2.0498211	2708.5417
1258.7517	3.643712	2.0496831	2698.9265
1259.8528	3.646584	2.0495813	2702.0923
1260.9539	3.6519034	2.0498314	2696.8625
1262.0549	3.653312	2.0497186	2697.6736
1263.156	3.6557305	2.0496681	2688.8667
1264.2571	3.6600938	2.049381	2681.8569
1265.3582	3.6647594	2.0496614	2681.1914
1266.4592	3.6661808	2.0495777	2669.5938
1267.5603	3.6708205	2.0496669	2666.1724
1268.6614	3.6753192	2.0492933	2665.5007
1269.7625	3.6757889	2.0499179	2660.7239
1270.8635	3.6797571	2.049679	2647.9282
1271.9646	3.6818805	2.0498621	2647.1106
1273.0657	3.6868961	2.0497382	2631.3887
1274.1667	3.6894226	2.0497162	2629.2979
1275.2678	3.6929014	2.0501728	2622.4365
1276.3689	3.6967964	2.0499353	2618.6023
1277.47	3.699518	2.0496449	2619.5649
1278.571	3.7029085	2.0497799	2603.646
1279.6721	3.7077894	2.0498333	2590.9851
1280.7732	3.7098339	2.0502965	2587.5239
1281.8743	3.7144589	2.0499043	2581.2393
1282.9753	3.7163134	2.0497639	2572.8623
1284.0764	3.7221022	2.0495205	2566.4338
1285.1775	3.7237835	2.049865	2558.5696
1286.2786	3.7247458	2.0501077	2540.3643
1287.3796	3.7289937	2.0498962	2529.1375
1288.4807	3.7325613	2.0499434	2516.22
1289.5818	3.7392967	2.0496893	2506.8528
1290.6829	3.7406242	2.0498171	2485.9578
1291.7839	3.7446771	2.0501628	2454.8313
1292.885	3.7468722	2.049835	2417.7214
1293.4856	3.7530272	2.0498047	2350.5913