File: datasets/am_bench_2022/raw_data/30-XY.12-2/specimen.dat
MTS793|MPT|ENU|1|2|.|/|:|1|0|0|A

Operator Information						Time:	28.991211	Sec	10/18/2021 12:38:53 PM
Operator	Nick Derimow
Project	AM Bench 2022 mini-tensile challenge
Specimen ID	30-XY.12-2
Material	PBF-L Inconel 625
Specimen Width	2.54	mm
Specimen Thickness	1.51	mm
Notes
Operator Information End

Data Acquisition						Time:	1029.9861	Sec	10/18/2021 12:55:34 PM
Time	Axial Displacement	Axial Extensometer	Axial Force
Sec	mm	mm	N
29.105957	-1.6325281e-05	-0.00013120989	57.61232
30.106934	0.0025923464	-1.0034302e-05	69.526054
31.10791	0.0067914845	1.426274e-06	87.032997
32.108887	0.0084879817	2.2734934e-05	98.224976
33.109863	0.011290634	0.00018218416	117.59605
34.11084	0.01229501	0.00022032563	131.04062
35.111816	0.018201759	0.00026522033	151.30664
36.112793	0.020732317	0.00037472532	166.66075
37.11377	0.023319833	0.00041691647	183.71368
38.114746	0.028814189	0.00047521511	202.10034
39.115723	0.030765111	0.00060037686	220.84749
40.116699	0.030204734	0.0005594407	238.40955
41.117676	0.038870085	0.00074951595	264.15829
42.118652	0.040163562	0.00072148384	279.00461
43.119629	0.038331632	0.00085588614	302.39282
44.120605	0.046526399	0.0010335328	324.91571
45.121582	0.043482948	0.0010557962	339.86218
46.122559	0.050015386	0.0011919688	365.87103
47.123535	0.05197189	0.00124338	383.32507
48.124512	0.057232209	0.0013187502	414.14841
49.125488	0.057884172	0.0013809336	426.04648
50.126465	0.062863179	0.0015500691	455.24609
51.127441	0.065770529	0.0016305204	478.15079
52.128418	0.069638662	0.0017443405	512.31775
53.129395	0.073192447	0.001889389	542.17145
54.130371	0.071355395	0.0020688928	562.73267
55.131348	0.077994786	0.0021832774	593.81561
56.132324	0.080190189	0.0021652593	612.7663
57.133301	0.082938395	0.0022643928	641.4668
58.134277	0.085832633	0.0023417473	660.27234
59.135254	0.087289967	0.002492798	681.03967
60.13623	0.088392898	0.0026650077	713.74988
61.137207	0.096540332	0.0027345263	743.08655
62.138184	0.095085405	0.0028994819	767.63336
63.13916	0.098001979	0.0030385107	795.2757
64.140137	0.10362987	0.0032127367	835.73956
65.141113	0.10601782	0.0033241871	867.41779
66.14209	0.10891519	0.0033469915	892.88892
67.143066	0.1117541	0.0035398738	926.59619
68.144043	0.1156519	0.0036539438	952.83533
69.14502	0.11901247	0.0037575469	975.31097
70.145996	0.12069811	0.0038059053	1000.7459
71.146973	0.12493581	0.0039118328	1028.0488
72.147949	0.12736167	0.0041056811	1059.262
73.148926	0.13028629	0.0041883588	1088.6104
74.149902	0.13074294	0.0043014935	1107.7047
75.150879	0.13692737	0.0045400625	1148.9324
76.151855	0.13876416	0.004662991	1165.7145
77.152832	0.14408569	0.004773668	1200.3682
78.153809	0.14468622	0.004912504	1225.8235
79.154785	0.14757991	0.0050843288	1258.2294
80.155762	0.15248761	0.0051469179	1286.3282
81.156738	0.1556482	0.0053132623	1320.4763
82.157715	0.15594898	0.0054319673	1346.027
83.158691	0.16034426	0.0055398452	1371.2904
84.159668	0.1612765	0.0056278366	1398.175
85.160645	0.17064422	0.0057452456	1428.4741
86.161621	0.16917208	0.0059533468	1455.3339
87.162598	0.1722077	0.0060371011	1484.926
88.163574	0.17226425	0.0061779986	1505.3394
89.164551	0.18019204	0.006342181	1544.3743
90.165527	0.18182211	0.0064982525	1562.3501
91.166504	0.18580472	0.0066180308	1589.3436
92.16748	0.18476327	0.0066855536	1609.7373
93.168457	0.19307154	0.0068601514	1649.5103
94.169434	0.19405521	0.0070008519	1674.6643
95.17041	0.19487207	0.0071566459	1700.2642
96.171387	0.19956115	0.0072913719	1721.0933
97.172363	0.2014861	0.0072848196	1735.3843
98.17334	0.20502596	0.0074924501	1771.5308
99.174316	0.20958698	0.0076345932	1796.384
100.17529	0.213452	0.007744418	1819.5708
101.17627	0.21266194	0.0077887308	1843.8093
102.17725	0.21422012	0.007968857	1871.2448
103.17822	0.21627559	0.0080336016	1889.5587
104.1792	0.22157684	0.0081227394	1918.8008
105.18018	0.22479665	0.0082538072	1939.2053
106.18115	0.23009759	0.0084234467	1970.061
107.18213	0.23157255	0.0085278628	1990.8757
108.18311	0.23657286	0.0087031815	2016.2081
109.18408	0.23751166	0.0088893315	2038.7806
110.18506	0.24065895	0.0089393975	2059.3271
111.18604	0.24490465	0.0090015531	2087.1238
112.18701	0.24585739	0.0090697026	2095.5508
113.18799	0.25288156	0.0092091784	2122.9436
114.18896	0.2519528	0.0092453538	2133.408
115.18994	0.25507554	0.009278792	2145.9929
116.19092	0.25842422	0.0093463436	2160.0562
117.19189	0.26397589	0.0094973622	2187.7046
118.19287	0.26706868	0.0096010771	2204.0784
119.19385	0.27037665	0.009669981	2215.155
120.19482	0.27238965	0.0098135555	2238.1147
121.1958	0.27315533	0.0099050011	2251.0476
122.19678	0.2777606	0.0099401306	2272.4666
123.19775	0.27806118	0.010024562	2278.4568
124.19873	0.28218701	0.010116672	2292.3445
125.19971	0.28653169	0.010202192	2312.0298
126.20068	0.29120436	0.010410539	2331.5276
127.20166	0.29440328	0.010378565	2344.1165
128.20264	0.29774013	0.010479677	2348.4656
129.20361	0.30253449	0.010589231	2363.7095
130.20459	0.30140722	0.010635167	2374.7031
131.20557	0.30556765	0.010691544	2388.1301
132.20654	0.30506918	0.010732436	2396.0051
133.20752	0.31255171	0.010872169	2414.978
134.2085	0.31471044	0.010960898	2433.5779
135.20947	0.31844822	0.011052279	2441.4634
136.21045	0.31774402	0.01109106	2447.8047
137.21143	0.32354626	0.011174561	2457.2756
138.2124	0.32872149	0.011394938	2475.0925
139.21338	0.32756823	0.011401868	2483.8359
140.21436	0.33304486	0.011542983	2496.3572
141.21533	0.33429489	0.011732297	2504.647
142.21631	0.33506384	0.011690245	2511.5447
143.21729	0.34220544	0.011813383	2532.8083
144.21826	0.34498313	0.011948233	2543.3652
145.21924	0.34732151	0.011995288	2547.6987
146.22021	0.35184735	0.012091523	2560.0464
147.22119	0.35714081	0.012222365	2576.5408
148.22217	0.35418528	0.012342771	2574.4883
149.22314	0.35828471	0.012452365	2584.856
150.22412	0.35847402	0.012598225	2597.1033
151.2251	0.36686543	0.012690133	2601.4312
152.22607	0.36962998	0.01281887	2612.1411
153.22705	0.37018442	0.012916311	2620.3853
154.22803	0.37529474	0.013154425	2635.634
155.229	0.37710661	0.013188853	2637.3062
156.22998	0.37955603	0.013358202	2642.6565
157.23096	0.38468274	0.01349033	2656.676
158.23193	0.3871502	0.013659102	2657.6006
159.23291	0.38922718	0.013873825	2672.8474
160.23389	0.39196411	0.013923093	2683.3865
161.23486	0.39453831	0.01416904	2690.3557
162.23584	0.39824167	0.014285265	2693.9895
163.23682	0.40012169	0.014471641	2709.7632
164.23779	0.4043656	0.014614202	2720.0701
165.23877	0.40526447	0.01482645	2723.3162
166.23975	0.41161904	0.015179003	2742.9917
167.24072	0.41613275	0.015294523	2742.7378
168.2417	0.41574222	0.015592692	2749.1929
169.24268	0.42117098	0.015864866	2760.9807
170.24365	0.42578998	0.016122064	2769.7024
171.24463	0.42634088	0.016315896	2773.1628
172.24561	0.43000883	0.016603367	2785.5725
173.24658	0.43237841	0.016773872	2785.5134
174.24756	0.43614173	0.017113693	2801.2654
175.24854	0.43507451	0.017387059	2802.3306
176.24951	0.43948141	0.017678352	2802.7026
177.25049	0.44379786	0.017982977	2820.2695
178.25146	0.44698632	0.018515319	2828.1792
179.25244	0.44949269	0.018724944	2828.4199
180.25342	0.45266646	0.019035609	2830.3193
181.25439	0.45821771	0.019367855	2846.7944
182.25537	0.45754752	0.019823376	2850.8975
183.25635	0.4611437	0.020226059	2853.634
184.25732	0.46450019	0.020534327	2854.9326
185.2583	0.46926263	0.021118995	2870.2417
186.25928	0.46942899	0.021655412	2868.6035
187.26025	0.47573692	0.022162095	2880.6501
188.26123	0.47604364	0.022585193	2878.1335
189.26221	0.48101911	0.023025569	2881.572
190.26318	0.48225871	0.02354715	2897.4692
191.26416	0.48461166	0.024174988	2899.085
192.26514	0.4910011	0.024887659	2906.6602
193.26611	0.49634212	0.025415013	2914.7974
194.26709	0.49338862	0.02623372	2914.0542
195.26807	0.4979288	0.026713552	2911.2058
196.26904	0.50064927	0.027341191	2924.5449
197.27002	0.50376791	0.027800694	2916.73
198.271	0.50649971	0.028556958	2933.4641
199.27197	0.51145905	0.029451502	2943.3555
200.27295	0.51351404	0.030244488	2943.302
201.27393	0.516469	0.031056629	2947.2332
202.2749	0.51998627	0.031683728	2943.0691
203.27588	0.5228613	0.032562189	2953.4658
204.27686	0.52723503	0.033224281	2955.1421
205.27783	0.52689821	0.034086373	2959.2649
206.27881	0.53101563	0.035082337	2966.3308
207.27979	0.5340336	0.035978571	2966.061
208.28076	0.53663141	0.036869727	2971.1497
209.28174	0.53963184	0.037875269	2974.583
210.28271	0.54361218	0.03868407	2976.4595
211.28369	0.54764992	0.039654762	2981.5823
212.28467	0.54870015	0.040430143	2978.3977
213.28564	0.55327046	0.041184809	2987.7266
214.28662	0.55678737	0.042194333	2995.8455
215.2876	0.55754358	0.043050181	2987.5188
216.28857	0.56354481	0.044096261	2997.6858
217.28955	0.56259161	0.044927899	2996.4668
218.29053	0.56852257	0.046024106	2999.8872
219.2915	0.56878972	0.046970978	3007.4001
220.29248	0.57168436	0.04800522	3004.2158
221.29346	0.5775854	0.049151912	3011.7307
222.29443	0.57831603	0.050221652	3010.6851
223.29541	0.58429033	0.051316801	3012.9424
224.29639	0.58826905	0.052309111	3022.2649
225.29736	0.58929867	0.053315759	3021.978
226.29834	0.58985472	0.054168701	3015.3657
227.29932	0.59379828	0.055272199	3028.2803
228.30029	0.59764951	0.056277514	3030.4277
229.30127	0.60036594	0.057478998	3034.8611
230.30225	0.60534394	0.058699969	3030.7449
231.30322	0.60643333	0.059594795	3034.9741
232.3042	0.60818017	0.060719363	3032.8752
233.30518	0.61193168	0.062004235	3044.4587
234.30615	0.61814374	0.063093036	3046.9282
235.30713	0.61818224	0.064165853	3046.2695
236.30811	0.62139672	0.065345131	3047.6167
237.30908	0.62751341	0.066613808	3054.1636
238.31006	0.62756425	0.067904502	3052.7703
239.31104	0.63082486	0.068920888	3052.6733
240.31201	0.63436884	0.06998381	3059.0002
241.31299	0.63672549	0.071229145	3056.8276
242.31396	0.63868296	0.072529644	3058.1455
243.31494	0.64208043	0.073871784	3060.6995
244.31592	0.64408875	0.075036108	3060.489
245.31689	0.6496771	0.075993016	3066.2041
246.31787	0.65082264	0.076963335	3061.1055
247.31885	0.65700018	0.078120857	3073.8013
248.31982	0.65592003	0.079150856	3067.5842
249.3208	0.65926611	0.080237575	3069.2241
250.32178	0.66420269	0.081261821	3073.405
251.32275	0.66543812	0.082268007	3073.4143
252.32373	0.67076957	0.083596833	3083.8945
253.32471	0.67282033	0.084833436	3088.9128
254.32568	0.67667055	0.086111866	3088.0083
255.32666	0.68001497	0.087217286	3083.428
256.32764	0.68316716	0.088393979	3090.2151
257.32861	0.68462431	0.089532666	3083.1396
258.32959	0.6896472	0.090747707	3098.3188
259.33057	0.69252402	0.091875292	3091.4841
260.33154	0.6928035	0.093136489	3095.97
261.33252	0.70008731	0.094193205	3092.3357
262.3335	0.70113492	0.095482923	3102.3982
263.33447	0.70421827	0.096622981	3101.0793
264.33545	0.70779788	0.097875901	3104.8381
265.33643	0.70820326	0.098963507	3098.2803
266.3374	0.71321392	0.10015954	3107.3274
267.33838	0.71430373	0.10145438	3104.7273
268.33936	0.71695805	0.10281687	3111.1987
269.34033	0.71828055	0.10394796	3110.2224
270.34131	0.72428542	0.10497866	3109.9087
271.34229	0.72852927	0.10619271	3116.5884
272.34326	0.73115087	0.10737683	3119.3901
273.34424	0.73214108	0.10870005	3115.9551
274.34521	0.73571736	0.10976214	3117.6526
275.34619	0.73757493	0.11092912	3117.0356
276.34717	0.74005002	0.11222458	3119.2986
277.34814	0.74354029	0.11337185	3125.9067
278.34912	0.74671561	0.11450635	3124.552
279.3501	0.75102627	0.11589671	3133.2666
280.35107	0.75250638	0.11727137	3125.3865
281.35205	0.75477779	0.11852734	3134.9587
282.35303	0.76013768	0.11971617	3131.198
283.354	0.76417357	0.12096561	3136.4465
284.35498	0.76596552	0.12201065	3139.2158
285.35596	0.76907718	0.12316396	3133.042
286.35693	0.77351159	0.12423564	3136.7112
287.35791	0.77350438	0.125291	3142.1741
288.35889	0.77975762	0.12673955	3146.5444
289.35986	0.78027785	0.12805307	3145.3499
290.36084	0.78289855	0.12936436	3146.302
291.36182	0.78632551	0.13067386	3145.4458
292.36279	0.79154831	0.13178228	3147.7136
293.36377	0.79360646	0.1332361	3154.6963
294.36475	0.79670453	0.1344344	3148.0632
295.36572	0.80044723	0.13545844	3147.4314
296.3667	0.8008849	0.13658041	3148.6655
297.36768	0.80421472	0.1376929	3149.874
298.36865	0.80992436	0.13890798	3165.3271
299.36963	0.81164914	0.14017597	3162.7317
300.37061	0.81442207	0.14140782	3160.175
301.37158	0.81478453	0.14262204	3166.6284
302.37256	0.81959534	0.14390709	3163.0024
303.37354	0.82001412	0.14499529	3165.9263
304.37451	0.82422519	0.1461385	3164.0767
305.37549	0.8262378	0.14731787	3166.4585
306.37646	0.83224452	0.14848797	3170.1814
307.37744	0.83514315	0.14985813	3173.772
308.37842	0.83876413	0.1511566	3177.1973
309.37939	0.84068531	0.15234682	3173.9097
310.38037	0.84369922	0.15352698	3176.0962
311.38135	0.84480971	0.15464613	3176.4912
312.38232	0.84965473	0.15604515	3183.4119
313.3833	0.85466367	0.15720691	3182.083
314.38428	0.85348368	0.15852673	3187.5369
315.38525	0.85977912	0.15966104	3181.3438
316.38623	0.86033046	0.16081235	3181.1572
317.38721	0.86553669	0.16187279	3186.3379
318.38818	0.86825639	0.16296691	3189.1868
319.38916	0.87190992	0.16413881	3192.0938
320.39014	0.87349415	0.16537076	3187.4475
321.39111	0.87716019	0.16650815	3190.5339
322.39209	0.87989831	0.16769309	3193.4902
323.39307	0.88368344	0.16881749	3192.5342
324.39404	0.8886717	0.16994481	3197.1345
325.39502	0.88836563	0.1711579	3198.1667
326.396	0.88988727	0.17225592	3197.3044
327.39697	0.89573544	0.17362131	3208.137
328.39795	0.89959943	0.17494118	3201.0322
329.39893	0.90008992	0.17622657	3197.9758
330.3999	0.90532339	0.17726718	3206.4175
331.40088	0.9066543	0.17840438	3205.1919
332.40186	0.90623164	0.17936623	3200.0637
333.40283	0.912467	0.18057355	3211.7864
334.40381	0.91493678	0.18170422	3206.7239
335.40479	0.91911179	0.18278882	3208.6741
336.40576	0.9195289	0.18394734	3207.1152
337.40674	0.92624724	0.18534896	3216.0227
338.40771	0.92773163	0.18658422	3214.6968
339.40869	0.93069905	0.18801269	3218.865
340.40967	0.93492097	0.18933252	3220.7061
341.41064	0.93734235	0.19063126	3223.3245
342.41162	0.94007927	0.19172274	3215.3979
343.4126	0.94259942	0.1930317	3220.064
344.41357	0.94536602	0.19436906	3223.1824
345.41455	0.94981307	0.19564314	3227.4746
346.41553	0.95287412	0.19665708	3221.752
347.4165	0.95611775	0.19777964	3230.7373
348.41748	0.95598316	0.19906601	3231.9675
349.41846	0.95970619	0.20045111	3230.3528
350.41943	0.96373671	0.2015128	3228.5845
351.42041	0.96828222	0.20270711	3231.6245
352.42139	0.97053266	0.2039097	3237.3186
353.42236	0.97419566	0.20515317	3237.3413
354.42334	0.9775759	0.20641926	3236.696
355.42432	0.97913861	0.20758075	3241.4695
356.42529	0.98115861	0.20868312	3242.7637
357.42627	0.9835521	0.2099756	3247.7314
358.42725	0.98746914	0.21111593	3243.6653
359.42822	0.99071395	0.21219696	3238.3547
360.4292	0.99494129	0.21311884	3240.9084
361.43018	0.99569857	0.21444964	3247.3848
362.43115	1.0004456	0.21596847	3250.3757
363.43213	1.0003248	0.21733323	3245.0469
364.43311	1.0073653	0.21839327	3244.9092
365.43408	1.0097301	0.21935692	3243.0618
366.43506	1.0122831	0.22062671	3248.6313
367.43604	1.0179543	0.22173075	3255.3892
368.43701	1.0190051	0.22307244	3253.6011
369.43799	1.0195274	0.22432697	3253.2446
370.43896	1.0266027	0.22535858	3253.3955
371.43994	1.026265	0.22652316	3255.0176
372.44092	1.03267	0.22779985	3262.3955
373.44189	1.0324622	0.22910535	3260.7666
374.44287	1.0385441	0.23031162	3263.802
375.44385	1.0380305	0.23164932	3264.0078
376.44482	1.0417341	0.23284444	3257.3704
377.4458	1.0473089	0.23394078	3265.3564
378.44678	1.0451087	0.23510349	3260.0261
379.44775	1.0492841	0.23604354	3259.1604
380.44873	1.0524566	0.23728231	3275.0735
381.44971	1.0545704	0.23858538	3273.9529
382.45068	1.058629	0.23987433	3274.6799
383.45166	1.0609678	0.24107964	3269.9395
384.45264	1.0676116	0.24230826	3278.3167
385.45361	1.0711591	0.24362344	3280.1853
386.45459	1.0723832	0.24481124	3276.5952
387.45557	1.0760037	0.24630739	3279.3591
388.45654	1.0780449	0.24731927	3279.2883
389.45752	1.082383	0.24833056	3280.231
390.4585	1.0841922	0.24939302	3276.5703
391.45947	1.088735	0.25078598	3286.3625
392.46045	1.0890172	0.25196904	3281.4976
393.46143	1.0944735	0.253205	3288.0718
394.4624	1.0922135	0.25438315	3284.6274
395.46338	1.0954398	0.25555876	3289.9067
396.46436	1.1031028	0.25677633	3287.4836
397.46533	1.1051353	0.25787008	3291.4692
398.46631	1.1061982	0.25888419	3283.8342
399.46729	1.1109885	0.2601096	3284.4243
400.46826	1.1143204	0.26131573	3291.8196
401.46924	1.1178871	0.26257476	3294.1748
402.47021	1.1200471	0.26340881	3290.3518
403.47119	1.125998	0.26432875	3296.1348
404.47217	1.1234542	0.26561171	3297.3489
405.47314	1.1277349	0.26695147	3298.3967
406.47412	1.1323798	0.26819715	3303.6255
407.4751	1.1357821	0.26934704	3300.7046
408.47607	1.1377041	0.27041423	3301.5776
409.47705	1.1399519	0.2716161	3302.0225
410.47803	1.1475803	0.27286488	3308.8022
411.479	1.1474209	0.27421287	3304.8889
412.47998	1.149811	0.27539542	3304.7893
413.48096	1.1529003	0.27653718	3309.5913
414.48193	1.1576278	0.27779973	3314.6741
415.48291	1.1591693	0.27907392	3307.6167
416.48389	1.1621723	0.28020829	3312.1572
417.48486	1.1634821	0.28129128	3305.1128
418.48584	1.168359	0.28233457	3308.8313
419.48682	1.171234	0.28357413	3319.7859
420.48779	1.1746939	0.28473234	3321.823
421.48877	1.1771755	0.28588718	3322.9121
422.48975	1.183642	0.28722277	3329.1641
423.49072	1.1816503	0.28838655	3314.4893
424.4917	1.1841015	0.28928408	3312.4539
425.49268	1.1901286	0.29038298	3327.9519
426.49365	1.1919812	0.2915059	3323.886
427.49463	1.1957706	0.29275161	3329.7122
428.49561	1.1986612	0.29398054	3322.5554
429.49658	1.2027991	0.29535735	3333.4094
430.49756	1.2058824	0.29664871	3327.896
431.49854	1.2064818	0.29782835	3330.6206
432.49951	1.208694	0.29902363	3330.5874
433.50049	1.2117077	0.30013826	3331.4768
434.50146	1.2172452	0.30116895	3328.187
435.50244	1.2213377	0.30217502	3332.7148
436.50342	1.2227893	0.3032673	3335.9727
437.50439	1.2278407	0.30437258	3336.481
438.50537	1.2285734	0.30536258	3337.8682
439.50635	1.2293528	0.30658251	3334.2671
440.50732	1.236274	0.307724	3343.8911
441.5083	1.2394174	0.30887428	3340.2744
442.50928	1.2423469	0.30988854	3336.0317
443.51025	1.2435256	0.3109723	3338.5896
444.51123	1.2457092	0.31177485	3340.1116
445.51221	1.2500819	0.31287059	3350.7168
446.51318	1.2507911	0.31406292	3345.5398
447.51416	1.2528377	0.31530726	3348.0332
448.51514	1.2590361	0.31662798	3345.1746
449.51611	1.2621971	0.31764385	3345.7681
450.51709	1.2651969	0.31868395	3355.8528
451.51807	1.2679439	0.31973815	3353.2373
452.51904	1.2692298	0.32095808	3352.9146
453.52002	1.2753559	0.32202998	3353.4153
454.521	1.2776818	0.32329479	3355.8748
455.52197	1.2804022	0.324442	3362.426
456.52295	1.2828912	0.32593676	3357.4995
457.52393	1.2862725	0.32716069	3354.1462
458.5249	1.2882258	0.32833657	3356.0835
459.52588	1.2930868	0.32948202	3351.5532
460.52686	1.294958	0.33060312	3359.458
461.52783	1.2994467	0.33167779	3361.1724
462.52881	1.3002688	0.3328034	3359.8601
463.52979	1.301736	0.33406755	3369.4287
464.53076	1.3067434	0.33536208	3370.0728
465.53174	1.3096186	0.3364892	3364.9731
466.53271	1.3113096	0.33792499	3374.1282
467.53369	1.314134	0.33903775	3362.5615
468.53467	1.3177644	0.34000218	3371.4478
469.53564	1.319943	0.34140211	3372.313
470.53662	1.3235776	0.34237137	3369.3193
471.5376	1.3260597	0.3434788	3363.6233
472.53857	1.3290759	0.34436607	3368.9363
473.53955	1.3363944	0.34558141	3378.2002
474.54053	1.3366284	0.34661889	3378.105
475.5415	1.3414615	0.34781608	3383.74
476.54248	1.3398683	0.34914038	3378.1655
477.54346	1.344586	0.3502377	3373.8057
478.54443	1.3515766	0.35124731	3377.1064
479.54541	1.3555157	0.35221326	3377.2856
480.54639	1.359395	0.35316774	3384.7383
481.54736	1.3577507	0.35431591	3382.9841
482.54834	1.361629	0.35564998	3387.345
483.54932	1.3630621	0.35667977	3379.8918
484.55029	1.3687937	0.35805276	3390.802
485.55127	1.3653662	0.35923523	3384.9539
486.55225	1.3726561	0.36067885	3392.4626
487.55322	1.3783681	0.36186826	3385.4148
488.5542	1.3770444	0.36330399	3384.1096
489.55518	1.3831285	0.36435658	3391.5381
490.55615	1.3843673	0.36564535	3392.8887
491.55713	1.3895503	0.36681381	3389.0164
492.55811	1.3917681	0.3679685	3394.519
493.55908	1.3963662	0.36920899	3393.6755
494.56006	1.39759	0.37057522	3397.5562
495.56104	1.4019357	0.37179452	3400.2129
496.56201	1.402221	0.37305075	3393.5991
497.56299	1.4057987	0.37412682	3390.6858
498.56396	1.4092695	0.37522149	3400.2734
499.56494	1.4100829	0.37644055	3399.0425
500.56592	1.4157977	0.37770823	3401.6111
501.56689	1.4183201	0.37871155	3399.6411
502.56787	1.4202875	0.37985253	3402.2407
503.56885	1.4243356	0.38097626	3404.6948
504.56982	1.4299433	0.38209501	3411.1431
505.5708	1.4291595	0.38321874	3405.7686
506.57178	1.4299282	0.38432142	3408.3254
507.57275	1.4361746	0.38550875	3407.3557
508.57373	1.4369546	0.38653478	3410.7351
509.57471	1.442232	0.38764548	3408.5437
510.57568	1.4462658	0.38867697	3404.301
511.57666	1.4476254	0.38988063	3421.0481
512.57764	1.4514147	0.39115056	3408.6746
513.57861	1.4516448	0.39219606	3411.5588
514.57959	1.4578568	0.39333946	3419.3044
515.58057	1.4581259	0.39460677	3417.2246
516.58154	1.4642384	0.39569157	3415.3215
517.58252	1.4661882	0.39685518	3421.0193
518.5835	1.469916	0.39826694	3418.7651
519.58447	1.4712212	0.3993161	3414.981
520.58545	1.4752723	0.40044406	3423.6272
521.58643	1.474547	0.40178505	3420.8147
522.5874	1.482586	0.40286362	3419.2712
523.58838	1.4821789	0.40390158	3420.6592
524.58936	1.4871064	0.40505826	3431.7288
525.59033	1.4892344	0.40635386	3427.4741
526.59131	1.4915175	0.40746909	3427.363
527.59229	1.49831	0.40867773	3422.7092
528.59326	1.4984947	0.409769	3423.9448
529.59424	1.5021248	0.41095269	3435.4514
530.59521	1.502326	0.41219479	3433.5215
531.59619	1.5068024	0.41352987	3427.9226
532.59717	1.510564	0.41465765	3429.6375
533.59814	1.5147024	0.41605455	3431.9536
534.59912	1.5145216	0.41743228	3437.7485
535.6001	1.5214155	0.4186143	3437.3523
536.60107	1.5206574	0.41986436	3433.0835
537.60205	1.5258411	0.42101714	3441.0481
538.60303	1.5256667	0.42217505	3434.9934
539.604	1.5320976	0.42311615	3440.0339
540.60498	1.5312424	0.42441964	3436.3855
541.60596	1.5401659	0.42562801	3446.2068
542.60693	1.5411695	0.4268176	3442.0369
543.60791	1.542936	0.4280974	3439.6453
544.60889	1.5436572	0.42920879	3439.0684
545.60986	1.5517687	0.43027428	3447.9258
546.61084	1.5543804	0.43157288	3452.783
547.61182	1.5556786	0.43283424	3440.3589
548.61279	1.5578539	0.43402433	3445.6287
549.61377	1.5625744	0.43527552	3449.6116
550.61475	1.5643647	0.43637335	3451.9094
551.61572	1.5664817	0.43757755	3443.8223
552.6167	1.5710835	0.43880475	3453.573
553.61768	1.5714359	0.43999872	3452.5291
554.61865	1.5754801	0.44122022	3446.6191
555.61963	1.5768248	0.44245467	3450.4038
556.62061	1.5834074	0.44364482	3452.4324
557.62158	1.5844806	0.44480169	3450.7815
558.62256	1.5879939	0.44588134	3452.7507
559.62354	1.5915014	0.44685632	3451.6663
560.62451	1.5977522	0.44807386	3464.366
561.62549	1.5969942	0.44931859	3461.46
562.62646	1.6022223	0.45064008	3461.9805
563.62744	1.6039798	0.45207757	3465.5571
564.62842	1.6056179	0.45320097	3453.127
565.62939	1.6085016	0.45456907	3460.177
566.63037	1.6129128	0.45593408	3458.6882
567.63135	1.6136183	0.45732626	3463.1333
568.63232	1.616742	0.45880967	3457.2754
569.6333	1.6191111	0.45989555	3461.699
570.63428	1.6253446	0.46091017	3464.4751
571.63525	1.6280485	0.46233344	3466.6311
572.63623	1.6338987	0.46358117	3472.8057
573.63721	1.6358765	0.46481064	3470.0461
574.63818	1.634912	0.46605524	3469.2771
575.63916	1.6391187	0.46712255	3463.8755
576.64014	1.6460054	0.46807918	3471.2622
577.64111	1.6460721	0.4690966	3471.9702
578.64209	1.6496749	0.47034058	3471.1436
579.64307	1.6514878	0.47147188	3471.4546
580.64404	1.6548061	0.47250801	3472.1101
581.64502	1.6553414	0.47357795	3469.176
582.646	1.6626866	0.47458041	3473.9553
583.64697	1.6609035	0.47578022	3474.8389
584.64795	1.6637642	0.47686407	3477.2786
585.64893	1.6677682	0.47823235	3476.2109
586.6499	1.6717603	0.47950882	3483.3845
587.65088	1.6775556	0.4808512	3483.5208
588.65186	1.6770424	0.4821431	3475.1135
589.65283	1.6781083	0.48318624	3478.1387
590.65381	1.6870868	0.48454458	3489.7161
591.65479	1.687381	0.48565546	3480.3779
592.65576	1.6900967	0.4868848	3484.4915
593.65674	1.6955187	0.48803192	3488.4744
594.65771	1.6985284	0.48904556	3483.0764
595.65869	1.6991097	0.49004674	3485.0403
596.65967	1.7027504	0.49108586	3488.1147
597.66064	1.7057804	0.49228624	3487.9326
598.66162	1.7066581	0.49343917	3487.5452
599.6626	1.7117506	0.49451524	3495.1624
600.66357	1.71615	0.49585724	3492.5562
601.66455	1.7185718	0.49699071	3486.7476
602.66553	1.7191436	0.49806651	3491.8867
603.6665	1.7220451	0.49939206	3491.9346
604.66748	1.7260822	0.50039661	3494.053
605.66846	1.7289553	0.50145173	3494.3477
606.66943	1.7303451	0.50268936	3498.2292
607.67041	1.7342159	0.50385368	3492.4731
608.67139	1.7384896	0.50499338	3499.1575
609.67236	1.7418412	0.50603819	3495.6604
610.67334	1.7445011	0.50701439	3493.9019
611.67432	1.74576	0.50802207	3495.894
612.67529	1.7518466	0.50900424	3502.761
613.67627	1.7529937	0.51010329	3501.762
614.67725	1.7586169	0.51126492	3503.6743
615.67822	1.7607943	0.51242691	3505.5593
616.6792	1.7650265	0.51369601	3506.3208
617.68018	1.7652864	0.51498687	3505.272
618.68115	1.7710048	0.51617193	3508.52
619.68213	1.7696221	0.51740545	3498.7131
620.68311	1.7760687	0.51863295	3509.8752
621.68408	1.7787249	0.51982361	3507.8081
622.68506	1.7808256	0.52113527	3508.2566
623.68604	1.7868112	0.52252549	3514.4612
624.68701	1.7835419	0.52391404	3505.5674
625.68799	1.7912669	0.52528238	3507.1477
626.68896	1.7934951	0.52638441	3509.7358
627.68994	1.7953742	0.52763218	3508.8159
628.69092	1.8020992	0.52873117	3512.3271
629.69189	1.8030968	0.53003818	3509.3301
630.69287	1.805208	0.53144699	3515.281
631.69385	1.8081819	0.53300589	3517.6304
632.69482	1.8062688	0.53424013	3510.6597
633.6958	1.8140272	0.53529209	3511.5823
634.69678	1.8171134	0.53660893	3516.4824
635.69775	1.8201942	0.53801155	3525.584
636.69873	1.8215941	0.5392766	3511.7905
637.69971	1.8253722	0.540591	3518.2578
638.70068	1.8282573	0.54189259	3519.8923
639.70166	1.833334	0.54301745	3521.9473
640.70264	1.8363372	0.5442943	3523.0652
641.70361	1.8384433	0.54554313	3520.9534
642.70459	1.8404815	0.54662466	3523.2209
643.70557	1.8421018	0.54787076	3523.9175
644.70654	1.8451127	0.54925603	3530.3606
645.70752	1.8511465	0.550529	3520.5793
646.7085	1.8504723	0.55180126	3529.0034
647.70947	1.8552752	0.55317873	3530.8069
648.71045	1.8592055	0.55431038	3523.467
649.71143	1.8606328	0.55555058	3530.866
650.7124	1.8646401	0.55660528	3528.4417
651.71338	1.8676432	0.55803287	3528.4067
652.71436	1.869862	0.5591802	3523.3701
653.71533	1.8738245	0.56044155	3532.2515
654.71631	1.8760318	0.56144255	3524.5125
655.71729	1.8805871	0.5625025	3526.1711
656.71826	1.8848166	0.56374389	3542.2354
657.71924	1.8860924	0.5650515	3535.2937
658.72021	1.8904004	0.56638074	3537.7258
659.72119	1.8914951	0.56778538	3538.7754
660.72217	1.894665	0.56914181	3537.5786
661.72314	1.8977133	0.57047522	3532.5991
662.72412	1.901143	0.57180053	3533.8362
663.7251	1.9052585	0.57292223	3532.6321
664.72607	1.9052893	0.57414818	3538.4041
665.72705	1.9119744	0.57525611	3540.0588
666.72803	1.912631	0.57651865	3542.2415
667.729	1.9164526	0.57797009	3547.6968
668.72998	1.9182196	0.57922161	3543.03
669.73096	1.9214038	0.58042848	3544.5566
670.73193	1.9243656	0.58156359	3542.1086
671.73291	1.9297805	0.58295017	3543.8772
672.73389	1.9297315	0.58432412	3543.8745
673.73486	1.9309728	0.5855965	3540.2188
674.73584	1.9343587	0.58679843	3547.4822
675.73682	1.9393641	0.58843094	3544.718
676.73779	1.9419607	0.58959115	3547.5999
677.73877	1.94656	0.59092516	3543.3596
678.73975	1.9482288	0.59217399	3546.2109
679.74072	1.9501891	0.59342027	3543.3403
680.7417	1.9541843	0.59464025	3547.7297
681.74268	1.9603529	0.5958932	3553.1108
682.74365	1.9591308	0.59740072	3553.6753
683.74463	1.9635527	0.59859771	3553.8149
684.74561	1.9659662	0.59979302	3550.1116
685.74658	1.9695704	0.60086226	3548.3857
686.74756	1.9741622	0.60190266	3552.1433
687.74854	1.9787494	0.60299265	3551.3911
688.74951	1.9778813	0.60434538	3556.5696
689.75049	1.981918	0.60575116	3555.0154
690.75146	1.9849848	0.60690057	3550.0862
691.75244	1.9865612	0.60817987	3554.1716
692.75342	1.9899509	0.60927743	3550.0183
693.75439	1.9925388	0.61048788	3556.4133
694.75537	1.996991	0.61186928	3558.7275
695.75635	1.9983346	0.613123	3561.2969
696.75732	2.0028291	0.6145491	3562.2803
697.7583	2.0084343	0.61599404	3562.7808
698.75928	2.0101018	0.61745369	3561.7532
699.76025	2.0118175	0.61856121	3553.5728
700.76123	2.0149183	0.61960846	3557.1816
701.76221	2.0189965	0.6208865	3562.6038
702.76318	2.0201719	0.62238777	3564.134
703.76416	2.0272493	0.62371689	3564.9783
704.76514	2.0253057	0.62503994	3567.5208
705.76611	2.02807	0.62628073	3560.1672
706.76709	2.031564	0.62739015	3561.3862
707.76807	2.0363531	0.62866521	3572.489
708.76904	2.0393589	0.62993544	3564.2776
709.77002	2.0401802	0.63131523	3568.1387
710.771	2.0451689	0.63226092	3568.3928
711.77197	2.0489197	0.63357109	3570.1707
712.77295	2.0512493	0.63486874	3568.1812
713.77393	2.0554132	0.63609129	3567.3167
714.7749	2.0559742	0.63745326	3576.5222
715.77588	2.0610387	0.63891441	3573.811
716.77686	2.063544	0.64046764	3571.6201
717.77783	2.0649896	0.64170837	3573.3245
718.77881	2.0683823	0.64306629	3569.0798
719.77979	2.0727248	0.64432549	3574.2019
720.78076	2.0741806	0.64558578	3569.5967
721.78174	2.0775657	0.64673191	3574.3704
722.78271	2.0800614	0.64820129	3578.2029
723.78369	2.0871406	0.64944744	3570.3652
724.78467	2.0882835	0.65047747	3571.0933
725.78564	2.0902352	0.65174884	3575.1477
726.78662	2.0941505	0.65331781	3577.6667
727.7876	2.0961168	0.65475851	3582.2576
728.78857	2.1001756	0.65632915	3577.1196
729.78955	2.1044075	0.65783453	3582.7727
730.79053	2.1071937	0.65916193	3577.5229
731.7915	2.1068559	0.66061723	3580.8203
732.79248	2.1110938	0.66225016	3581.6987
733.79346	2.1168983	0.66354734	3584.896
734.79443	2.1176987	0.66500628	3581.7117
735.79541	2.1196165	0.66632581	3581.3865
736.79639	2.1224074	0.66772103	3581.0215
737.79736	2.1263306	0.6690765	3589.5703
738.79834	2.1323438	0.6703968	3582.2202
739.79932	2.1346631	0.67179859	3583.708
740.80029	2.1325839	0.67289156	3578.9204
741.80127	2.137614	0.6744287	3585.1797
742.80225	2.1424501	0.67550689	3582.7695
743.80322	2.1442511	0.67693007	3588.8743
744.8042	2.1443937	0.67821252	3581.5457
745.80518	2.1497917	0.67958111	3586.6777
746.80615	2.154043	0.68090332	3586.9573
747.80713	2.1574273	0.68229198	3592.822
748.80811	2.1572735	0.68375492	3587.0178
749.80908	2.1646805	0.68530822	3591.3589
750.81006	2.1653752	0.68672967	3590.7148
751.81104	2.1681981	0.68823659	3590.908
752.81201	2.1728194	0.68989348	3591.8611
753.81299	2.1749611	0.69143581	3589.1384
754.81396	2.1766498	0.69271123	3586.4026
755.81494	2.1803832	0.6938737	3588.6748
756.81592	2.1851251	0.69509494	3596.8911
757.81689	2.1893878	0.69688159	3598.8113
758.81787	2.1874242	0.69840014	3593.2258
759.81885	2.1928215	0.69973844	3597.6633
760.81982	2.196352	0.70147204	3597.7671
761.8208	2.2005749	0.70303911	3596.3506
762.82178	2.2007926	0.70437163	3594.4878
763.82275	2.2029722	0.70578849	3594.9568
764.82373	2.2092373	0.70692122	3596.9949
765.82471	2.2098825	0.70839423	3594.2019
766.82568	2.2116659	0.70955271	3594.5393
767.82666	2.214762	0.71091163	3595.7856
768.82764	2.2192495	0.71202815	3596.2727
769.82861	2.2220466	0.71325904	3595.7888
770.82959	2.2253296	0.71464002	3598.4219
771.83057	2.229022	0.71615416	3604.8215
772.83154	2.2294002	0.7172882	3595.6392
773.83252	2.2326825	0.71879113	3603.2058
774.8335	2.2366703	0.72032601	3598.8552
775.83447	2.2429814	0.72200108	3607.8955
776.83545	2.2416213	0.72382516	3604.5969
777.83643	2.2468469	0.72559869	3610.0212
778.8374	2.2518425	0.72754359	3608.7505
779.83838	2.2517254	0.72928011	3604.1899
780.83936	2.2584631	0.73103106	3610.1072
781.84033	2.2574868	0.73263037	3601.3235
782.84131	2.2609849	0.73411947	3605.7419
783.84229	2.2660291	0.73577541	3605.6299
784.84326	2.2671139	0.737185	3603.0676
785.84424	2.2721069	0.73854774	3609.4224
786.84521	2.274019	0.73993176	3610.7183
787.84619	2.2784498	0.7413457	3605.0796
788.84717	2.2796464	0.74268347	3604.5801
789.84814	2.2809021	0.74415392	3609.4844
790.84912	2.2887354	0.7456885	3610.9822
791.8501	2.2864861	0.74731863	3608.6521
792.85107	2.2951541	0.74897325	3613.0227
793.85205	2.2938299	0.75058168	3611.1331
794.85303	2.2981248	0.752258	3609.637
795.854	2.3011544	0.75387669	3614.1602
796.85498	2.3047364	0.75548595	3614.0601
797.85596	2.3061197	0.75701237	3611.2974
798.85693	2.3086646	0.75865752	3610.0134
799.85791	2.3135722	0.76004356	3610.9436
800.85889	2.3165946	0.76131469	3613.7048
801.85986	2.315459	0.76276755	3603.1038
802.86084	2.3212602	0.76443315	3610.604
803.86182	2.326124	0.76587164	3615.9285
804.86279	2.3277466	0.76735502	3614.1138
805.86377	2.3285239	0.76889813	3612.1387
806.86475	2.3338237	0.77021676	3609.502
807.86572	2.3352637	0.77163494	3614.9795
808.8667	2.3380075	0.77336568	3618.9727
809.86768	2.3449569	0.77488607	3616.5898
810.86865	2.3444085	0.77666444	3615.7349
811.86963	2.3489504	0.77852386	3623.6143
812.87061	2.3519859	0.78014743	3621.843
813.87158	2.3550708	0.78197962	3622.384
814.87256	2.3568585	0.78368497	3613.4004
815.87354	2.3613167	0.78533292	3617.6736
816.87451	2.3608623	0.78665203	3611.5667
817.87549	2.3677602	0.78809601	3607.0139
818.87646	2.36885	0.78930092	3616.2166
819.87744	2.3687527	0.79091126	3616.0376
820.87842	2.3748734	0.7923618	3621.3445
821.87939	2.3779795	0.79407144	3619.4302
822.88037	2.3817215	0.79569805	3627.7573
823.88135	2.3835368	0.79761106	3625.1311
824.88232	2.3860104	0.79934573	3623.2051
825.8833	2.391434	0.80082756	3624.4443
826.88428	2.3922634	0.80243611	3622.981
827.88525	2.393106	0.80417955	3624.3845
828.88623	2.4020593	0.80587447	3625.6062
829.88721	2.4054623	0.80785304	3622.6245
830.88818	2.4045224	0.80948025	3613.5227
831.88916	2.4070735	0.81082851	3617.449
832.89014	2.4119606	0.81214428	3621.3638
833.89111	2.4172142	0.81347787	3619.8801
834.89209	2.4194562	0.81478846	3629.2385
835.89307	2.4196992	0.81653988	3623.0706
836.89404	2.4213998	0.81797183	3624.4734
837.89502	2.4242208	0.819309	3619.2737
838.896	2.4283438	0.82070613	3627.7302
839.89697	2.4318225	0.82218164	3628.7273
840.89795	2.434078	0.82391495	3622.8049
841.89893	2.4369957	0.82551473	3626.6448
842.8999	2.4364202	0.82716346	3627.4714
843.90088	2.4474261	0.82863361	3623.3562
844.90186	2.4492996	0.82972002	3632.0967
845.90283	2.4478185	0.83143723	3631.386
846.90381	2.4536657	0.83327931	3638.1375
847.90479	2.4555967	0.83488399	3632.2671
848.90576	2.4597292	0.83648092	3626.8384
849.90674	2.46299	0.83785284	3630.698
850.90771	2.4650621	0.83936697	3628.6682
851.90869	2.4726362	0.84084827	3636.4609
852.90967	2.4691195	0.84240389	3628.3845
853.91064	2.4722083	0.84423339	3632.5115
854.91162	2.4785073	0.84578037	3630.7913
855.9126	2.4822381	0.84713876	3634.7625
856.91357	2.4849122	0.84875524	3623.9673
857.91455	2.4875655	0.85004008	3628.542
858.91553	2.4877381	0.85151201	3631.3105
859.9165	2.4903069	0.85313261	3632.823
860.91748	2.4935887	0.8548277	3633.6501
861.91846	2.497659	0.85617292	3634.4185
862.91943	2.5020399	0.85788751	3638.7017
863.92041	2.5038056	0.85932028	3626.6748
864.92139	2.5074773	0.86064589	3633.4492
865.92236	2.5109608	0.86210555	3641.9807
866.92334	2.5128219	0.86363477	3633.7544
867.92432	2.5160906	0.8652848	3635.1367
868.92529	2.5208139	0.86704612	3635.0454
869.92627	2.5225811	0.86838335	3629.9509
870.92725	2.5269861	0.869946	3637.4238
871.92822	2.5287387	0.87186348	3639.1213
872.9292	2.5338416	0.87377077	3645.7222
873.93018	2.5342443	0.87562269	3637.7646
874.93115	2.5395231	0.87737948	3637.4194
875.93213	2.5413237	0.87896532	3633.1555
876.93311	2.5460298	0.88066173	3644.4448
877.93408	2.5463574	0.88257736	3641.0132
878.93506	2.5477457	0.88451254	3638.9814
879.93604	2.554126	0.88634604	3642.1108
880.93701	2.5561368	0.88820481	3646.9529
881.93799	2.5571241	0.88993573	3637.0774
882.93896	2.5619547	0.89158505	3638.7644
883.93994	2.565742	0.8934077	3632.5864
884.94092	2.5659394	0.89513361	3645.0813
885.94189	2.5708652	0.89718634	3643.8052
886.94287	2.5732093	0.89866978	3638.3179
887.94385	2.5741346	0.90035468	3635.0945
888.94482	2.5780234	0.90206492	3636.1455
889.9458	2.5811713	0.90344101	3637.4756
890.94678	2.5857704	0.90517431	3642.6443
891.94775	2.5873833	0.90702146	3636.8604
892.94873	2.5914078	0.90873259	3638.5823
893.94971	2.5934441	0.91035491	3639.5308
894.95068	2.5966268	0.91232264	3644.3096
895.95166	2.5981288	0.91418207	3642.6855
896.95264	2.6027036	0.91599929	3641.7485
897.95361	2.6071877	0.91751462	3644.7498
898.95459	2.6112049	0.91925406	3644.7148
899.95557	2.6132176	0.92100704	3642.2246
900.95654	2.6142454	0.92291373	3641.6504
901.95752	2.6196477	0.92485756	3646.8228
902.9585	2.6206076	0.9265449	3641.4651
903.95947	2.6262197	0.92804939	3638.5352
904.96045	2.6275301	0.92932093	3643.436
905.96143	2.6301718	0.93109983	3647.4832
906.9624	2.6341989	0.9327091	3644.2424
907.96338	2.6353335	0.93433583	3639.2849
908.96436	2.6384749	0.93598139	3648.9622
909.96533	2.6409674	0.93790323	3642.2688
910.96631	2.6445441	0.93955791	3639.1265
911.96729	2.6492338	0.94094294	3636.5337
912.96826	2.6518517	0.94248062	3643.5569
913.96924	2.6541228	0.94428134	3644.0168
914.97021	2.656848	0.94598252	3639.5676
915.97119	2.6609311	0.94741583	3645.501
916.97217	2.6646395	0.94939667	3652.6487
917.97314	2.6652501	0.95155042	3650.2585
918.97412	2.6673076	0.9537465	3649.1978
919.9751	2.6723676	0.95553333	3641.5981
920.97607	2.6753078	0.95738298	3647.2297
921.97705	2.6829329	0.95941287	3649.0447
922.97803	2.6833389	0.96110427	3650.1899
923.979	2.685209	0.96311367	3647.2888
924.97998	2.6869681	0.9649567	3652.0549
925.98096	2.692081	0.96689427	3648.2595
926.98193	2.6964941	0.96855885	3645.8118
927.98291	2.6971645	0.97044748	3648.3704
928.98389	2.6992917	0.97231442	3639.2944
929.98486	2.7014155	0.9739958	3647.6055
930.98584	2.706213	0.97614658	3649.3293
931.98682	2.7095959	0.97811127	3651.2627
932.98779	2.707037	0.98023838	3650.1553
933.98877	2.7140732	0.9821806	3651.5815
934.98975	2.7181475	0.98440874	3647.2917
935.99072	2.7216065	0.98618603	3649.2019
936.9917	2.723619	0.9879179	3647.8206
937.99268	2.7295473	0.98967487	3647.4668
938.99365	2.731267	0.99125099	3653.6421
939.99463	2.7336106	0.99282074	3645.6733
940.99561	2.7362678	0.99470693	3650.5081
941.99658	2.7381387	0.9965722	3652.8381
942.99756	2.7425897	0.99873978	3656.179
943.99854	2.7429056	1.0009726	3649.7422
944.99951	2.7497423	1.00305	3654.7056
946.00049	2.7513809	1.0052472	3649.2188
947.00146	2.7546501	1.007074	3650.3884
948.00244	2.7546089	1.0089412	3641.1804
949.00342	2.7593844	1.0106541	3649.6975
950.00439	2.7617533	1.0124371	3645.041
951.00537	2.7671773	1.0138491	3646.2644
952.00635	2.7680078	1.0157284	3651.5134
953.00732	2.7714007	1.0180013	3652.1785
954.0083	2.7752776	1.0198069	3645.6572
955.00928	2.7783508	1.0213324	3644.0554
956.01025	2.778965	1.0232017	3650.5898
957.01123	2.7844119	1.0254614	3654.1838
958.01221	2.7877302	1.0275488	3653.7444
959.01318	2.7864909	1.0300065	3653.168
960.01416	2.7914324	1.0324116	3648.604
961.01514	2.7941015	1.034708	3646.3406
962.01611	2.7984746	1.0369139	3644.5012
963.01709	2.8007233	1.0386328	3644.3926
964.01807	2.8053665	1.0403968	3648.8811
965.01904	2.8087103	1.0424871	3652.9795
966.02002	2.8105633	1.0446197	3648.9316
967.021	2.8108804	1.0465809	3651.657
968.02197	2.8169179	1.0490013	3654.3677
969.02295	2.8206973	1.0512476	3651.4412
970.02393	2.8242276	1.0531077	3651.4185
971.0249	2.8251612	1.0551258	3650.2397
972.02588	2.8306351	1.0573246	3656.0786
973.02686	2.834034	1.059474	3655.6465
974.02783	2.8375375	1.0617059	3654.1404
975.02881	2.8395767	1.0638565	3649.3252
976.02979	2.8402991	1.0657531	3648.1865
977.03076	2.8427479	1.0678345	3648.2324
978.03174	2.847137	1.0694832	3647.062
979.03271	2.848479	1.0713631	3650.9348
980.03369	2.8531218	1.0739505	3653.9185
981.03467	2.8554935	1.0761992	3653.1521
982.03564	2.8622842	1.0781765	3650.0964
983.03662	2.8638241	1.0803946	3651.0535
984.0376	2.8628142	1.0825506	3651.0583
985.03857	2.8683064	1.0850191	3652.9512
986.03955	2.8709123	1.0869156	3646.0298
987.04053	2.8743279	1.0889804	3649.9138
988.0415	2.87749	1.0912801	3652.864
989.04248	2.8796663	1.0933974	3649.1765
990.04346	2.8833637	1.0955516	3647.8667
991.04443	2.8874657	1.0978162	3657.9382
992.04541	2.8876731	1.1000865	3648.3376
993.04639	2.8908019	1.1025407	3659.5579
994.04736	2.893466	1.1055152	3651.8921
995.04834	2.8982487	1.1076939	3643.7913
996.04932	2.9000788	1.109674	3652.2114
997.05029	2.9054215	1.1118127	3651.0161
998.05127	2.9066658	1.1138706	3648.2324
999.05225	2.9118757	1.1159358	3644.7522
1000.0532	2.9140806	1.117589	3645.1289
1001.0542	2.9168541	1.1196215	3647.8853
1002.0552	2.9210668	1.1217625	3651.7209
1003.0562	2.9225924	1.1237214	3648.7637
1004.0571	2.9259684	1.1257045	3642.2659
1005.0581	2.9276283	1.1279441	3651.0754
1006.0591	2.9292834	1.1302088	3649.3215
1007.0601	2.93592	1.1325999	3652.366
1008.061	2.9380679	1.1349828	3648.6895
1009.062	2.9383295	1.1373019	3646.3098
1010.063	2.9420633	1.1392807	3640.6318
1011.064	2.9468803	1.1411203	3643.9526
1012.0649	2.9539917	1.1431584	3652.1023
1013.0659	2.9545486	1.1451606	3652.4587
1014.0669	2.9556777	1.1472188	3650.897
1015.0679	2.9574995	1.1495185	3647.9141
1016.0688	2.9639804	1.1520662	3653.0557
1017.0698	2.964304	1.1547037	3646.5811
1018.0708	2.9651384	1.1570925	3643.1624
1019.0718	2.9719408	1.1589848	3649.6931
1020.0728	2.9719682	1.1613233	3648.2324
1021.0737	2.9796493	1.1634988	3643.7668
1022.0747	2.9797232	1.1653408	3639.4346
1023.0757	2.986042	1.1669207	3646.0215
1024.0767	2.9826257	1.1688297	3646.8372
1025.0776	2.985621	1.1707615	3642.0442
1026.0786	2.991437	1.1727972	3649.4534
1027.0796	2.9935637	1.1754124	3648.0486
1028.0806	2.9993002	1.1781925	3647.592
1029.0815	3.0021944	1.1806701	3644.9897
1030.0825	3.0028532	1.1829983	3646.7683
1031.0835	3.0038846	1.1856362	3642.1843
1032.0845	3.0103393	1.1885208	3646.791
1033.0854	3.0109942	1.1910913	3638.9792
1034.0864	3.014905	1.1938339	3647.3645
1035.0874	3.0211952	1.1963942	3646.6335
1036.0884	3.0206215	1.1987553	3636.3813
1037.0894	3.0269723	1.2008418	3639.8958
1038.0903	3.0273697	1.2031035	3638.8418
1039.0913	3.0325878	1.2054025	3648.2471
1040.0923	3.0337305	1.2079909	3648.7783
1041.0933	3.0390069	1.2108876	3646.9773
1042.0942	3.0391774	1.2140572	3643.9292
1043.0952	3.0422468	1.2165769	3642.0237
1044.0962	3.0431187	1.2193373	3640.9099
1045.0972	3.0489051	1.2219434	3644.0569
1046.0981	3.0509353	1.2245736	3634.3721
1047.0991	3.0553656	1.2270517	3635.3171
1048.1001	3.0573599	1.2297271	3638.3728
1049.1011	3.0618432	1.2319921	3636.8967
1050.1021	3.0618942	1.2343535	3635.1807
1051.103	3.0642533	1.2369527	3635.1328
1052.104	3.0688715	1.2398388	3637.3816
1053.105	3.0737936	1.2426308	3638.5962
1054.106	3.0741079	1.2453905	3633.2014
1055.1069	3.0770092	1.2478049	3632.7976
1056.1079	3.0826941	1.2502046	3639.293
1057.1089	3.0849888	1.252593	3630.6633
1058.1099	3.0853646	1.2549714	3630.6938
1059.1108	3.0892963	1.2575253	3635.0298
1060.1118	3.0952294	1.2604907	3635.2632
1061.1128	3.0960515	1.2634327	3634.2683
1062.1138	3.0993519	1.2659563	3634.9153
1063.1147	3.1011858	1.2686706	3630.0774
1064.1157	3.1074138	1.2715631	3633.595
1065.1167	3.1063778	1.2743059	3630.999
1066.1177	3.1137936	1.2770954	3630.6287
1067.1187	3.113951	1.2800089	3634.4958
1068.1196	3.1196237	1.2827228	3629.1199
1069.1206	3.1209526	1.2851635	3622.1929
1070.1216	3.1238353	1.2873274	3627.8481
1071.1226	3.1264784	1.2900199	3627.8018
1072.1235	3.1293652	1.2929978	3625.2747
1073.1245	3.1358693	1.2954819	3625.5554
1074.1255	3.1333053	1.2983093	3629.9336
1075.1265	3.142035	1.3012632	3629.7749
1076.1274	3.1418962	1.3044891	3628.9089
1077.1284	3.1429994	1.3075705	3619.3613
1078.1294	3.1456368	1.3104639	3617.2461
1079.1304	3.1510355	1.3130031	3618.2324
1080.1313	3.1561902	1.3156245	3627.9414
1081.1323	3.1565115	1.3187965	3627.1584
1082.1333	3.1573133	1.3216876	3615.563
1083.1343	3.160243	1.3241335	3611.8938
1084.1353	3.1681962	1.3265651	3618.3293
1085.1362	3.167526	1.3288347	3617.8008
1086.1372	3.171001	1.3319755	3615.0869
1087.1382	3.1706965	1.3348122	3614.0117
1088.1392	3.1793149	1.3374046	3614.8091
1089.1401	3.1812072	1.3402258	3616.2024
1090.1411	3.182929	1.3432684	3618.0962
1091.1421	3.1857896	1.3465332	3615.6492
1092.1431	3.1898689	1.3495756	3609.0493
1093.144	3.196281	1.3522196	3614.21
1094.145	3.19719	1.3553494	3610.876
1095.146	3.2001996	1.3581408	3612.9045
1096.147	3.200114	1.3612897	3607.5481
1097.1479	3.2051871	1.3645347	3605.9551
1098.1489	3.2066507	1.3676881	3609.0908
1099.1499	3.2088099	1.3706157	3602.2827
1100.1509	3.2106819	1.3736842	3603.6055
1101.1519	3.2153506	1.3766357	3602.0769
1102.1528	3.2196331	1.3794961	3603.4683
1103.1538	3.2211921	1.3825634	3595.8086
1104.1548	3.2263393	1.38545	3594.925
1105.1558	3.2303069	1.3879446	3593.6052
1106.1567	3.2289984	1.3903534	3596.5381
1107.1577	3.2362459	1.3931187	3599.0183
1108.1587	3.2384896	1.3959333	3592.8582
1109.1597	3.2426219	1.3989444	3589.6484
1110.1606	3.2431309	1.4018307	3597.6118
1111.1616	3.2490489	1.405086	3595.554
1112.1626	3.2477806	1.4088309	3594.6509
1113.1636	3.2553432	1.4124621	3591.7991
1114.1646	3.2572811	1.4154079	3585.093
1115.1655	3.2593434	1.4182273	3582.459
1116.1665	3.2629473	1.4208634	3579.8826
1117.1675	3.2641933	1.4235442	3587.5007
1118.1685	3.2696049	1.4261535	3582.3611
1119.1694	3.2702451	1.4285589	3576.644
1120.1704	3.2734864	1.4317116	3585.4453
1121.1714	3.2791994	1.4343334	3577.7336
1122.1724	3.2796526	1.4377093	3572.2598
1123.1733	3.2819209	1.4407251	3576.4907
1124.1743	3.2856092	1.4436808	3569.3875
1125.1753	3.2878644	1.4465491	3574.9829
1126.1763	3.2940173	1.4501477	3573.323
1127.1772	3.2941976	1.4532094	3568.8345
1128.1782	3.297694	1.4565564	3569.8772
1129.1792	3.2985134	1.459605	3558.3391
1130.1802	3.3061225	1.4620074	3564.3459
1131.1812	3.3069346	1.4653667	3568.5613
1132.1821	3.3110774	1.4687452	3566.4385
1133.1831	3.3140836	1.4719141	3560.8279
1134.1841	3.3156006	1.4752533	3554.6824
1135.1851	3.3199742	1.4783651	3560.7866
1136.186	3.3190908	1.4813071	3549.1523
1137.187	3.3236694	1.4843056	3550.3999
1138.188	3.3289299	1.4874777	3552.9573
1139.189	3.3283226	1.490912	3544.2893
1140.1899	3.3351247	1.4938843	3544.2422
1141.1909	3.3374045	1.4970012	3545.7891
1142.1919	3.3389904	1.5005163	3540.3118
1143.1929	3.3424923	1.5038664	3537.7776
1144.1938	3.3473399	1.5070481	3542.6667
1145.1948	3.3502338	1.5104703	3538.719
1146.1958	3.3510931	1.5138346	3539.1152
1147.1968	3.3538744	1.5172858	3529.6191
1148.1978	3.3569353	1.5202434	3526.231
1149.1987	3.3604345	1.523535	3534.0691
1150.1997	3.3644671	1.5272522	3528.5015
1151.2007	3.3667989	1.5311216	3533.146
1152.2017	3.3713849	1.5345794	3520.4543
1153.2026	3.370333	1.5377053	3516.9104
1154.2036	3.3786914	1.5411156	3518.6072
1155.2046	3.3815897	1.5442783	3512.0588
1156.2056	3.3819525	1.5468706	3508.4304
1157.2065	3.3839986	1.5493277	3509.2974
1158.2075	3.3870685	1.5521861	3513.3533
1159.2085	3.3917084	1.5555282	3509.6321
1160.2095	3.3900912	1.5586331	3501.6526
1161.2104	3.3975217	1.5617062	3499.9233
1162.2114	3.3985028	1.5642853	3495.3369
1163.2124	3.4000418	1.5670578	3495.7202
1164.2134	3.4070265	1.5700545	3496.2139
1165.2144	3.4101162	1.5729071	3492.4634
1166.2153	3.4111495	1.5760325	3488.8765
1167.2163	3.4161596	1.5795978	3488.6721
1168.2173	3.4176474	1.5826564	3485.2373
1169.2183	3.4228389	1.585951	3483.1172
1170.2192	3.4211438	1.589427	3484.0054
1171.2202	3.4239712	1.5929139	3471.4399
1172.2212	3.4298658	1.5956746	3472.4919
1173.2222	3.4356363	1.5991454	3480.3281
1174.2231	3.4354095	1.6030806	3468.074
1175.2241	3.440501	1.6066397	3468.0366
1176.2251	3.4415317	1.6098229	3460.4185
1177.2261	3.4448073	1.6131403	3463.7632
1178.2271	3.4469092	1.6166742	3453.6738
1179.228	3.4491763	1.6201869	3452.6235
1180.229	3.4545109	1.6235126	3446.6814
1181.23	3.4582274	1.6264825	3441.8638
1182.231	3.4611912	1.6293807	3446.45
1183.2319	3.4628904	1.6325881	3446.9473
1184.2329	3.4675896	1.6359812	3444.1802
1185.2339	3.4695451	1.6396322	3436.2837
1186.2349	3.4737072	1.6425534	3431.1379
1187.2358	3.4740241	1.6457535	3434.6116
1188.2368	3.4757113	1.6494844	3424.1438
1189.2378	3.4822173	1.6527079	3424.0488
1190.2388	3.4838769	1.6557255	3422.8281
1191.2397	3.4864736	1.6589102	3410.5776
1192.2407	3.4916546	1.6620123	3410.0198
1193.2417	3.493681	1.6647229	3410.959
1194.2427	3.4950039	1.6680784	3408.3049
1195.2437	3.4976182	1.6720281	3399.3943
1196.2446	3.5038168	1.6754848	3395.8188
1197.2456	3.5044856	1.678708	3392.4771
1198.2466	3.5044835	1.6820962	3385.2756
1199.2476	3.5130193	1.6853689	3393.7205
1200.2485	3.5128732	1.6884669	3382.9971
1201.2495	3.5144739	1.6913629	3381.1958
1202.2505	3.5210667	1.6942596	3379.1086
1203.2515	3.5236118	1.6979513	3371.8645
1204.2524	3.5242712	1.7016345	3366.6021
1205.2534	3.5306592	1.7053969	3365.7217
1206.2544	3.5341985	1.7085642	3361.0752
1207.2554	3.5329692	1.7117985	3359.8879
1208.2563	3.5389581	1.7149204	3352.7881
1209.2573	3.5398791	1.7186154	3354.3809
1210.2583	3.5471535	1.7223812	3341.1475
1211.2593	3.5480387	1.7255082	3340.7869
1212.2603	3.5488672	1.729318	3333.2322
1213.2612	3.5533421	1.7325042	3331.1211
1214.2622	3.5573592	1.7362937	3326.9788
1215.2632	3.558917	1.7404528	3317.4614
1216.2642	3.5615525	1.7438512	3311.2805
1217.2651	3.5656993	1.7468097	3303.2505
1218.2661	3.5677283	1.7497896	3305.1138
1219.2671	3.5744762	1.7533633	3304.1836
1220.2681	3.5756767	1.7568076	3296.6094
1221.269	3.5776045	1.760149	3288.623
1222.27	3.5799212	1.7632015	3289.1018
1223.271	3.5824854	1.7664738	3281.1228
1224.272	3.5869284	1.7697212	3276.1946
1225.2729	3.5879724	1.7737536	3270.8545
1226.2739	3.5898082	1.7778227	3258.9014
1227.2749	3.5952523	1.781224	3253.2297
1228.2759	3.5970664	1.7840335	3247.2266
1229.2769	3.6044495	1.7872628	3250.179
1230.2778	3.6043186	1.7906718	3239.3108
1231.2788	3.6089008	1.7938881	3234.0713
1232.2798	3.6117058	1.7975807	3231.9919
1233.2808	3.6101959	1.8013328	3223.0234
1234.2817	3.6163988	1.8053011	3219.4341
1235.2827	3.6206563	1.809232	3207.1924
1236.2837	3.6231532	1.8121638	3199.936
1237.2847	3.6239729	1.8153774	3193.6782
1238.2856	3.6283746	1.8190368	3188.8809
1239.2866	3.6308694	1.822542	3179.4714
1240.2876	3.6346064	1.8258805	3175.3862
1241.2886	3.6392577	1.8294249	3168.6729
1242.2896	3.6409347	1.8331993	3159.1221
1243.2905	3.6452961	1.83685	3148.7971
1244.2915	3.6456442	1.8410357	3141.9751
1245.2925	3.6494229	1.8446559	3132.2822
1246.2935	3.6532891	1.8483374	3125.332
1247.2944	3.6568904	1.8524988	3119.491
1248.2954	3.6583636	1.8573585	3097.5073
1249.2964	3.6626985	1.8609726	3080.9021
1250.2974	3.6658247	1.8649411	3074.7791
1251.2983	3.6715293	1.8716705	3042.2905
1251.7988	3.6702123	1.8771392	3004.8142