File: datasets/am_bench_2022/csv/0-XY.10-3.csv
Time(s),Strain(%),Stress(MPa),SR(s-1),Temp(C),Angle(deg)
23.226074,4.400416535433071e-06,20.292472916666668,0.00025370340306410486,25.0,0.0
25.12793,2.483203937007874e-05,28.01390625,0.00025370340306410486,25.0,0.0
26.529297,2.3972141732283465e-05,31.312609375,0.00025370340306410486,25.0,0.0
27.830566,3.69873562992126e-05,35.60078125,0.00025370340306410486,25.0,0.0
29.131836,6.592356692913386e-05,40.1270234375,0.00025370340306410486,25.0,0.0
30.433105,7.69987716535433e-05,44.60043489583334,0.00025370340306410486,25.0,0.0
31.734375,8.160700393700787e-05,50.712291666666665,0.00025370340306410486,25.0,0.0
33.035645,0.00011583811417322835,56.857505208333336,0.00025370340306410486,25.0,0.0
34.336914,0.00013672690748031495,62.254921875,0.00025370340306410486,25.0,0.0
35.638184,0.00014414735433070867,68.2911875,0.00025370340306410486,25.0,0.0
36.939453,0.00019114098818897638,76.03684375,0.00025370340306410486,25.0,0.0
38.240723,0.00019029319488188975,81.38045572916667,0.00025370340306410486,25.0,0.0
39.541992,0.00021054917322834644,88.8731484375,0.00025370340306410486,25.0,0.0
40.843262,0.00027427992125984255,97.19369531250001,0.00025370340306410486,25.0,0.0
42.144531,0.0003042081299212598,105.32874218750001,0.00025370340306410486,25.0,0.0
43.445801,0.0003341629330708661,110.90768229166666,0.00025370340306410486,25.0,0.0
44.74707,0.0003199304724409449,118.956875,0.00025370340306410486,25.0,0.0
46.04834,0.00035940307086614173,125.34103385416667,0.00025370340306410486,25.0,0.0
47.349609,0.00037145592519685037,133.54179166666668,0.00025370340306410486,25.0,0.0
48.650879,0.0004164847440944882,142.20536458333333,0.00025370340306410486,25.0,0.0
49.952148,0.0004253731102362205,149.75147135416668,0.00025370340306410486,25.0,0.0
51.253418,0.00047636856299212597,159.11634635416667,0.00025370340306410486,25.0,0.0
52.554688,0.0005021926968503937,168.714140625,0.00025370340306410486,25.0,0.0
53.855957,0.0005144069094488189,174.49304166666667,0.00025370340306410486,25.0,0.0
55.157227,0.0005839335236220472,184.78732031250001,0.00025370340306410486,25.0,0.0
56.458496,0.000571870157480315,192.39260416666667,0.00025370340306410486,25.0,0.0
57.759766,0.0006198704724409449,201.927328125,0.00025370340306410486,25.0,0.0
59.061035,0.0006634366732283464,214.37826041666668,0.00025370340306410486,25.0,0.0
60.362305,0.0006947073425196851,224.94103125,0.00025370340306410486,25.0,0.0
61.663574,0.0007185162401574804,232.76953645833333,0.00025370340306410486,25.0,0.0
62.964844,0.0007581864173228346,242.908828125,0.00025370340306410486,25.0,0.0
64.266113,0.0007969661023622046,253.78940885416668,0.00025370340306410486,25.0,0.0
65.567383,0.0008200215551181102,261.03125,0.00025370340306410486,25.0,0.0
66.868652,0.0008803662204724409,269.99106770833333,0.00025370340306410486,25.0,0.0
68.169922,0.0008976141141732283,277.5786458333334,0.00025370340306410486,25.0,0.0
69.471191,0.0009308453543307086,287.4936197916667,0.00025370340306410486,25.0,0.0
70.772461,0.0009645271653543308,297.86856770833333,0.00025370340306410486,25.0,0.0
72.07373,0.00099031718503937,304.230234375,0.00025370340306410486,25.0,0.0
73.375,0.0010249990551181101,312.29072916666667,0.00025370340306410486,25.0,0.0
74.67627,0.0010493986023622046,323.19914062500004,0.00025370340306410486,25.0,0.0
75.977539,0.0010855435433070866,332.33958333333334,0.00025370340306410486,25.0,0.0
77.278809,0.0011231762992125985,343.47320312500005,0.00025370340306410486,25.0,0.0
78.580078,0.001154937244094488,348.9909895833333,0.00025370340306410486,25.0,0.0
79.881348,0.0012007410039370078,360.80039062500003,0.00025370340306410486,25.0,0.0
81.182617,0.0012128295866141732,370.71247395833336,0.00025370340306410486,25.0,0.0
82.483887,0.0012692853346456692,379.9996614583333,0.00025370340306410486,25.0,0.0
83.785156,0.001285514901574803,387.173125,0.00025370340306410486,25.0,0.0
85.086426,0.0013167121062992125,396.8074739583334,0.00025370340306410486,25.0,0.0
86.387695,0.0013703833267716535,408.053203125,0.00025370340306410486,25.0,0.0
87.688965,0.001419216062992126,414.8286197916667,0.00025370340306410486,25.0,0.0
88.990234,0.0014550351377952755,423.78890625,0.00025370340306410486,25.0,0.0
90.291504,0.0014508342913385828,433.4152864583333,0.00025370340306410486,25.0,0.0
91.592773,0.001503258307086614,443.8866927083333,0.00025370340306410486,25.0,0.0
92.894043,0.0015458268110236219,450.7548958333333,0.00025370340306410486,25.0,0.0
94.195313,0.0015966480511811025,459.47596354166666,0.00025370340306410486,25.0,0.0
95.496582,0.0016227769685039368,466.49320312500004,0.00025370340306410486,25.0,0.0
96.797852,0.0016577893897637794,477.95403645833335,0.00025370340306410486,25.0,0.0
98.099121,0.0017052914173228345,488.5922135416667,0.00025370340306410486,25.0,0.0
99.400391,0.0017297795078740157,496.19395833333334,0.00025370340306410486,25.0,0.0
100.70166,0.0017957191732283465,503.927109375,0.00025370340306410486,25.0,0.0
102.00293,0.0018088022440944883,509.1805208333334,0.00025370340306410486,25.0,0.0
103.3042,0.0018567726771653544,515.9876302083334,0.00025370340306410486,25.0,0.0
104.60547,0.0018823296062992125,523.820078125,0.00025370340306410486,25.0,0.0
105.90674,0.0019272849803149607,532.2710416666667,0.00025370340306410486,25.0,0.0
107.20801,0.001982863188976378,536.9594531250001,0.00025370340306410486,25.0,0.0
108.50928,0.0020224397637795275,545.8194791666667,0.00025370340306410486,25.0,0.0
109.81055,0.0020669068897637794,551.2706770833333,0.00025370340306410486,25.0,0.0
111.11182,0.0020903285433070866,556.6924479166667,0.00025370340306410486,25.0,0.0
112.41309,0.002173286023622047,564.268359375,0.00025370340306410486,25.0,0.0
113.71436,0.0022067716535433073,571.9876041666668,0.00025370340306410486,25.0,0.0
115.01563,0.002258637401574803,576.2738541666666,0.00025370340306410486,25.0,0.0
116.31689,0.002291050196850394,580.7409895833333,0.00025370340306410486,25.0,0.0
117.61816,0.0023318068897637797,585.7600520833333,0.00025370340306410486,25.0,0.0
118.91943,0.002395875787401575,591.97578125,0.00025370340306410486,25.0,0.0
120.2207,0.0024309094488188976,596.1458854166667,0.00025370340306410486,25.0,0.0
121.52197,0.0025144173228346454,603.7572135416667,0.00025370340306410486,25.0,0.0
122.82324,0.002537562007874016,607.538359375,0.00025370340306410486,25.0,0.0
124.12451,0.0026094931102362204,612.3680729166666,0.00025370340306410486,25.0,0.0
125.42578,0.0026630076771653544,616.2509895833334,0.00025370340306410486,25.0,0.0
126.72705,0.0027295094488188976,621.8072135416667,0.00025370340306410486,25.0,0.0
128.02832,0.0028071629921259844,625.150859375,0.00025370340306410486,25.0,0.0
129.32959,0.0028281456692913383,628.8501822916668,0.00025370340306410486,25.0,0.0
130.63086,0.0028811923228346456,631.239765625,0.00025370340306410486,25.0,0.0
131.93213,0.002970255118110236,636.3343489583334,0.00025370340306410486,25.0,0.0
133.2334,0.003060407086614173,640.4169010416666,0.00025370340306410486,25.0,0.0
134.53467,0.003125573622047244,642.6101041666667,0.00025370340306410486,25.0,0.0
135.83594,0.0031941789370078743,646.81765625,0.00025370340306410486,25.0,0.0
137.13721,0.0032791893700787403,649.68546875,0.00025370340306410486,25.0,0.0
138.43848,0.003363131496062992,653.3664062500001,0.00025370340306410486,25.0,0.0
139.73975,0.0034397775590551184,657.1417447916667,0.00025370340306410486,25.0,0.0
141.04102,0.003534974212598425,658.3835677083333,0.00025370340306410486,25.0,0.0
142.34229,0.0036498891732283465,663.2659375000001,0.00025370340306410486,25.0,0.0
143.64355,0.0037544891732283468,664.9436197916667,0.00025370340306410486,25.0,0.0
144.94482,0.0038406082677165353,666.1055989583333,0.00025370340306410486,25.0,0.0
146.24609,0.003976075393700787,670.9324479166667,0.00025370340306410486,25.0,0.0
147.54736,0.004117829133858267,674.3609114583334,0.00025370340306410486,25.0,0.0
148.84863,0.0042315704724409445,673.4011458333333,0.00025370340306410486,25.0,0.0
150.1499,0.004299879724409449,675.8968229166667,0.00025370340306410486,25.0,0.0
151.45117,0.004428998425196851,678.4395833333334,0.00025370340306410486,25.0,0.0
152.75244,0.0046016978346456695,681.454140625,0.00025370340306410486,25.0,0.0
154.05371,0.004718092322834645,682.4848177083334,0.00025370340306410486,25.0,0.0
155.35498,0.00490074625984252,685.588828125,0.00025370340306410486,25.0,0.0
156.65625,0.0050561017716535435,687.6532291666667,0.00025370340306410486,25.0,0.0
157.95752,0.005296559842519685,690.8898697916667,0.00025370340306410486,25.0,0.0
159.25879,0.0054844427165354325,692.441953125,0.00025370340306410486,25.0,0.0
160.56006,0.0056727669291338585,693.149765625,0.00025370340306410486,25.0,0.0
161.86133,0.0059136901574803145,694.309296875,0.00025370340306410486,25.0,0.0
163.1626,0.00610204783464567,697.1599479166667,0.00025370340306410486,25.0,0.0
164.46387,0.00639764783464567,697.9046614583334,0.00025370340306410486,25.0,0.0
165.76514,0.00657159842519685,697.7836718750001,0.00025370340306410486,25.0,0.0
167.06641,0.0067788513779527566,700.816484375,0.00025370340306410486,25.0,0.0
168.36768,0.007003052165354331,702.2119010416667,0.00025370340306410486,25.0,0.0
169.66895,0.007254458661417323,703.4197395833334,0.00025370340306410486,25.0,0.0
170.97021,0.007497844094488189,703.0873697916667,0.00025370340306410486,25.0,0.0
172.27148,0.007753779724409449,706.790546875,0.00025370340306410486,25.0,0.0
173.57275,0.008037013976377953,708.2229687500001,0.00025370340306410486,25.0,0.0
174.87402,0.008272410433070865,707.8194270833334,0.00025370340306410486,25.0,0.0
176.17529,0.008541229724409448,709.8426822916667,0.00025370340306410486,25.0,0.0
177.47656,0.008815635433070866,711.022578125,0.00025370340306410486,25.0,0.0
178.77783,0.009135721456692912,712.4117447916666,0.00025370340306410486,25.0,0.0
180.0791,0.009450025393700788,715.27328125,0.00025370340306410486,25.0,0.0
181.38037,0.009760264173228346,715.6755989583334,0.00025370340306410486,25.0,0.0
182.68164,0.010088072244094488,714.8218229166667,0.00025370340306410486,25.0,0.0
183.98291,0.010386666732283464,715.9462500000001,0.00025370340306410486,25.0,0.0
185.28418,0.01064684527559055,715.1433333333333,0.00025370340306410486,25.0,0.0
186.58545,0.010955251574803149,716.0109114583335,0.00025370340306410486,25.0,0.0
187.88672,0.011239772047244094,719.4920833333333,0.00025370340306410486,25.0,0.0
189.18799,0.011593167913385827,721.1588020833334,0.00025370340306410486,25.0,0.0
190.48926,0.011929922440944882,720.54328125,0.00025370340306410486,25.0,0.0
191.79053,0.012275270078740158,723.8784895833334,0.00025370340306410486,25.0,0.0
193.0918,0.012695815748031497,723.4752083333334,0.00025370340306410486,25.0,0.0
194.39307,0.013060072834645668,722.2352864583333,0.00025370340306410486,25.0,0.0
195.69434,0.01334571161417323,722.7445052083334,0.00025370340306410486,25.0,0.0
196.99561,0.013654478149606299,723.600390625,0.00025370340306410486,25.0,0.0
198.29688,0.013967924606299214,727.2660677083334,0.00025370340306410486,25.0,0.0
199.59814,0.014313050787401575,725.9606770833333,0.00025370340306410486,25.0,0.0
200.89941,0.014683620275590552,726.5448958333334,0.00025370340306410486,25.0,0.0
202.20068,0.015001462401574801,728.6879947916667,0.00025370340306410486,25.0,0.0
203.50195,0.015338215551181101,727.7711197916666,0.00025370340306410486,25.0,0.0
204.80322,0.015716744488188977,730.4040364583333,0.00025370340306410486,25.0,0.0
206.10449,0.016063542716535435,729.1079947916667,0.00025370340306410486,25.0,0.0
207.40576,0.016465818307086613,730.4282552083334,0.00025370340306410486,25.0,0.0
208.70703,0.016739222440944883,730.933828125,0.00025370340306410486,25.0,0.0
210.0083,0.017143046850393702,733.4382291666667,0.00025370340306410486,25.0,0.0
211.30957,0.01748710374015748,731.8122916666667,0.00025370340306410486,25.0,0.0
212.61084,0.01786395649606299,735.3545572916668,0.00025370340306410486,25.0,0.0
213.91211,0.018299595472440946,733.2653645833334,0.00025370340306410486,25.0,0.0
215.21338,0.018666367913385825,733.8609635416667,0.00025370340306410486,25.0,0.0
216.51465,0.019040142125984254,735.3928125,0.00025370340306410486,25.0,0.0
217.81592,0.019400597637795274,735.4455208333334,0.00025370340306410486,25.0,0.0
219.11719,0.01972572834645669,733.7651041666667,0.00025370340306410486,25.0,0.0
220.41846,0.020009096456692913,736.8372656250001,0.00025370340306410486,25.0,0.0
221.71973,0.020324246062992126,734.7361979166667,0.00025370340306410486,25.0,0.0
223.021,0.020672523622047245,736.9333333333334,0.00025370340306410486,25.0,0.0
224.32227,0.021093625984251966,737.2396354166667,0.00025370340306410486,25.0,0.0
225.62354,0.021451147637795275,738.3293229166667,0.00025370340306410486,25.0,0.0
226.9248,0.021775732283464567,740.0945052083333,0.00025370340306410486,25.0,0.0
228.22607,0.022119805118110236,738.6866145833334,0.00025370340306410486,25.0,0.0
229.52734,0.022499931102362206,738.5590364583334,0.00025370340306410486,25.0,0.0
230.82861,0.022879423228346456,739.888828125,0.00025370340306410486,25.0,0.0
232.12988,0.023266145669291336,742.0197135416668,0.00025370340306410486,25.0,0.0
233.43115,0.02367896653543307,742.6801041666666,0.00025370340306410486,25.0,0.0
234.73242,0.02408052755905512,743.2027864583334,0.00025370340306410486,25.0,0.0
236.03369,0.024437765748031495,742.676171875,0.00025370340306410486,25.0,0.0
237.33496,0.02483933464566929,743.2531250000001,0.00025370340306410486,25.0,0.0
238.63623,0.02524074212598425,744.2967187500001,0.00025370340306410486,25.0,0.0
239.9375,0.025691602362204725,742.835625,0.00025370340306410486,25.0,0.0
241.23877,0.026048722440944885,743.4599479166667,0.00025370340306410486,25.0,0.0
242.54004,0.026438828740157478,745.7813802083333,0.00025370340306410486,25.0,0.0
243.84131,0.02682240354330709,743.9755208333333,0.00025370340306410486,25.0,0.0
245.14258,0.02718000196850394,745.6701822916667,0.00025370340306410486,25.0,0.0
246.44385,0.02748732677165354,745.7481510416667,0.00025370340306410486,25.0,0.0
247.74512,0.027855653543307088,745.8508854166666,0.00025370340306410486,25.0,0.0
249.04639,0.028304039370078738,745.5835416666667,0.00025370340306410486,25.0,0.0
250.34766,0.028659494094488185,746.1643750000001,0.00025370340306410486,25.0,0.0
251.64893,0.0290318031496063,747.4796354166667,0.00025370340306410486,25.0,0.0
252.9502,0.02937403149606299,747.0356510416667,0.00025370340306410486,25.0,0.0
254.25146,0.02974357086614173,749.6155468750001,0.00025370340306410486,25.0,0.0
255.55273,0.030134911417322836,748.3686979166666,0.00025370340306410486,25.0,0.0
256.854,0.03057889566929134,750.4910677083333,0.00025370340306410486,25.0,0.0
258.15527,0.03098592125984252,749.1926822916666,0.00025370340306410486,25.0,0.0
259.45654,0.03139471456692913,751.8945052083334,0.00025370340306410486,25.0,0.0
260.75781,0.03175858661417323,750.211640625,0.00025370340306410486,25.0,0.0
262.05908,0.032169793307086615,750.8712760416666,0.00025370340306410486,25.0,0.0
263.36035,0.032516486220472436,751.8838802083334,0.00025370340306410486,25.0,0.0
264.66162,0.032948314960629915,753.2580729166667,0.00025370340306410486,25.0,0.0
265.96289,0.033261535433070866,753.1930989583334,0.00025370340306410486,25.0,0.0
267.26416,0.033655173228346456,753.0404427083333,0.00025370340306410486,25.0,0.0
268.56543,0.03409680118110236,753.5879166666666,0.00025370340306410486,25.0,0.0
269.8667,0.03453509448818898,752.92796875,0.00025370340306410486,25.0,0.0
271.16797,0.03491495866141732,754.7109635416666,0.00025370340306410486,25.0,0.0
272.46924,0.03529361417322834,755.3265364583334,0.00025370340306410486,25.0,0.0
273.77051,0.03569385236220472,754.7705989583334,0.00025370340306410486,25.0,0.0
275.07178,0.036138179133858264,754.8840885416666,0.00025370340306410486,25.0,0.0
276.37305,0.03649586614173229,755.3225781250001,0.00025370340306410486,25.0,0.0
277.67432,0.03689907283464566,757.4139322916667,0.00025370340306410486,25.0,0.0
278.97559,0.03724425590551181,756.6154427083334,0.00025370340306410486,25.0,0.0
280.27686,0.0376475688976378,756.4207031249999,0.00025370340306410486,25.0,0.0
281.57813,0.03802863385826772,757.9657291666667,0.00025370340306410486,25.0,0.0
282.87939,0.03845168307086614,758.160078125,0.00025370340306410486,25.0,0.0
284.18066,0.038878799212598424,758.3498697916667,0.00025370340306410486,25.0,0.0
285.48193,0.03930545275590551,759.625234375,0.00025370340306410486,25.0,0.0
286.7832,0.03971741338582677,758.8415885416667,0.00025370340306410486,25.0,0.0
288.08447,0.04005183070866142,758.6950260416667,0.00025370340306410486,25.0,0.0
289.38574,0.040485358267716536,759.3991666666667,0.00025370340306410486,25.0,0.0
290.68701,0.040909537401574804,759.8934895833333,0.00025370340306410486,25.0,0.0
291.98828,0.041307039370078735,760.7121875,0.00025370340306410486,25.0,0.0
293.28955,0.04160851181102362,759.5073177083334,0.00025370340306410486,25.0,0.0
294.59082,0.04196298031496063,761.28578125,0.00025370340306410486,25.0,0.0
295.89209,0.04236186811023622,762.0215104166667,0.00025370340306410486,25.0,0.0
297.19336,0.04276375196850394,762.3615364583334,0.00025370340306410486,25.0,0.0
298.49463,0.04320779724409449,762.5644791666667,0.00025370340306410486,25.0,0.0
299.7959,0.04356956102362205,761.3097395833333,0.00025370340306410486,25.0,0.0
301.09717,0.04396354133858268,761.3091145833334,0.00025370340306410486,25.0,0.0
302.39844,0.04432562992125984,763.2853125,0.00025370340306410486,25.0,0.0
303.69971,0.04472226181102362,765.0389322916667,0.00025370340306410486,25.0,0.0
305.00098,0.04511266929133858,762.4481770833333,0.00025370340306410486,25.0,0.0
306.30225,0.04549989566929134,765.2241927083334,0.00025370340306410486,25.0,0.0
307.60352,0.04588929330708661,763.7884895833333,0.00025370340306410486,25.0,0.0
308.90479,0.046225610236220474,764.9648697916666,0.00025370340306410486,25.0,0.0
310.20605,0.04665323622047244,765.8540104166666,0.00025370340306410486,25.0,0.0
311.50732,0.0471629842519685,767.1515885416667,0.00025370340306410486,25.0,0.0
312.80859,0.04753380708661417,765.8828125,0.00025370340306410486,25.0,0.0
314.10986,0.04794417322834646,767.6520572916667,0.00025370340306410486,25.0,0.0
315.41113,0.04830355708661417,766.3388541666667,0.00025370340306410486,25.0,0.0
316.7124,0.04863367716535433,766.8858333333334,0.00025370340306410486,25.0,0.0
318.01367,0.04903258267716536,768.7168750000001,0.00025370340306410486,25.0,0.0
319.31494,0.049435064960629924,767.535390625,0.00025370340306410486,25.0,0.0
320.61621,0.04982374015748032,769.9406250000001,0.00025370340306410486,25.0,0.0
321.91748,0.05028910236220473,767.0581770833334,0.00025370340306410486,25.0,0.0
323.21875,0.05065261417322834,768.5463541666667,0.00025370340306410486,25.0,0.0
324.52002,0.0510602125984252,769.4200520833333,0.00025370340306410486,25.0,0.0
325.82129,0.05151058661417323,771.5103125,0.00025370340306410486,25.0,0.0
327.12256,0.0518924311023622,768.6044010416667,0.00025370340306410486,25.0,0.0
328.42383,0.05226377559055118,770.18515625,0.00025370340306410486,25.0,0.0
329.7251,0.05260426771653544,769.5720572916667,0.00025370340306410486,25.0,0.0
331.02637,0.0529036811023622,771.7030208333333,0.00025370340306410486,25.0,0.0
332.32764,0.05327643897637795,772.2747135416668,0.00025370340306410486,25.0,0.0
333.62891,0.05357966535433071,771.5661458333333,0.00025370340306410486,25.0,0.0
334.93018,0.053988033464566924,775.1036197916667,0.00025370340306410486,25.0,0.0
336.23145,0.05439157874015749,772.809921875,0.00025370340306410486,25.0,0.0
337.53271,0.05474881889763779,771.9603125000001,0.00025370340306410486,25.0,0.0
338.83398,0.055142421259842526,772.2110677083334,0.00025370340306410486,25.0,0.0
340.13525,0.05558253937007874,773.3924739583333,0.00025370340306410486,25.0,0.0
341.43652,0.056013547244094485,773.5534635416667,0.00025370340306410486,25.0,0.0
342.73779,0.056392858267716534,773.8266666666667,0.00025370340306410486,25.0,0.0
344.03906,0.05680575590551181,774.6491145833334,0.00025370340306410486,25.0,0.0
345.34033,0.057175732283464564,774.0545833333333,0.00025370340306410486,25.0,0.0
346.6416,0.057618759842519685,776.1230989583333,0.00025370340306410486,25.0,0.0
347.94287,0.05805995078740158,776.8480208333333,0.00025370340306410486,25.0,0.0
349.24414,0.05839063385826772,774.8043749999999,0.00025370340306410486,25.0,0.0
350.54541,0.05872486614173228,775.8794791666667,0.00025370340306410486,25.0,0.0
351.84668,0.05912216929133858,777.3657552083333,0.00025370340306410486,25.0,0.0
353.14795,0.059524864173228345,776.5149479166666,0.00025370340306410486,25.0,0.0
354.44922,0.05990355905511811,777.0419531250001,0.00025370340306410486,25.0,0.0
355.75049,0.06027178937007874,776.9793750000001,0.00025370340306410486,25.0,0.0
357.05176,0.06062939960629921,776.6381510416667,0.00025370340306410486,25.0,0.0
358.35303,0.0609851968503937,777.9769791666666,0.00025370340306410486,25.0,0.0
359.6543,0.06143129330708661,780.3145052083335,0.00025370340306410486,25.0,0.0
360.95557,0.06185700196850394,779.22375,0.00025370340306410486,25.0,0.0
362.25684,0.062259580708661416,780.4340364583334,0.00025370340306410486,25.0,0.0
363.55811,0.06261161023622047,779.1168229166667,0.00025370340306410486,25.0,0.0
364.85938,0.06304920669291338,779.8185416666668,0.00025370340306410486,25.0,0.0
366.16064,0.0633931653543307,778.8383593750001,0.00025370340306410486,25.0,0.0
367.46191,0.06374874015748032,779.73671875,0.00025370340306410486,25.0,0.0
368.76318,0.06414772637795275,781.796640625,0.00025370340306410486,25.0,0.0
370.06445,0.06453668307086614,782.9231770833334,0.00025370340306410486,25.0,0.0
371.36572,0.06491730708661417,780.9885677083333,0.00025370340306410486,25.0,0.0
372.66699,0.06529455314960629,782.363125,0.00025370340306410486,25.0,0.0
373.96826,0.06565333070866142,781.9232291666667,0.00025370340306410486,25.0,0.0
375.26953,0.06602557874015748,782.7825520833334,0.00025370340306410486,25.0,0.0
376.5708,0.06642620275590551,785.352578125,0.00025370340306410486,25.0,0.0
377.87207,0.0667987027559055,783.50015625,0.00025370340306410486,25.0,0.0
379.17334,0.06718342322834646,784.2549739583334,0.00025370340306410486,25.0,0.0
380.47461,0.06756638188976379,781.2534895833334,0.00025370340306410486,25.0,0.0
381.77588,0.06789595669291339,782.43546875,0.00025370340306410486,25.0,0.0
383.07715,0.06827473818897638,785.8945833333333,0.00025370340306410486,25.0,0.0
384.37842,0.06868587598425197,785.529765625,0.00025370340306410486,25.0,0.0
385.67969,0.0690954468503937,785.3272135416668,0.00025370340306410486,25.0,0.0
386.98096,0.06954687598425197,784.6519531250001,0.00025370340306410486,25.0,0.0
388.28223,0.06996199606299212,786.6891927083334,0.00025370340306410486,25.0,0.0
389.5835,0.07033223031496064,785.052734375,0.00025370340306410486,25.0,0.0
390.88477,0.07065550984251968,786.107265625,0.00025370340306410486,25.0,0.0
392.18604,0.07101700393700787,787.1265364583334,0.00025370340306410486,25.0,0.0
393.4873,0.07137741338582676,787.4782552083333,0.00025370340306410486,25.0,0.0
394.78857,0.07172658070866142,786.1405729166667,0.00025370340306410486,25.0,0.0
396.08984,0.07213839370078741,786.8420833333333,0.00025370340306410486,25.0,0.0
397.39111,0.0725085157480315,788.3944791666667,0.00025370340306410486,25.0,0.0
398.69238,0.07285887598425196,786.8550520833334,0.00025370340306410486,25.0,0.0
399.99365,0.07319870472440944,788.4737760416667,0.00025370340306410486,25.0,0.0
401.29492,0.07358274409448819,788.7602604166667,0.00025370340306410486,25.0,0.0
402.59619,0.0739271594488189,789.6529427083334,0.00025370340306410486,25.0,0.0
403.89746,0.0742842657480315,789.9229166666668,0.00025370340306410486,25.0,0.0
405.19873,0.07466574212598424,788.0550260416667,0.00025370340306410486,25.0,0.0
406.5,0.07506537992125983,789.817421875,0.00025370340306410486,25.0,0.0
407.80127,0.07549504921259843,791.4819791666667,0.00025370340306410486,25.0,0.0
409.10254,0.0758006811023622,788.5605468750001,0.00025370340306410486,25.0,0.0
410.40381,0.07610156692913386,789.7760937500001,0.00025370340306410486,25.0,0.0
411.70508,0.07644024606299211,790.666015625,0.00025370340306410486,25.0,0.0
413.00635,0.07687456299212599,789.3921614583334,0.00025370340306410486,25.0,0.0
414.30762,0.07726165157480315,791.4848437500001,0.00025370340306410486,25.0,0.0
415.60889,0.07759965157480314,792.5189843750001,0.00025370340306410486,25.0,0.0
416.91016,0.07803872440944883,791.7957812500001,0.00025370340306410486,25.0,0.0
418.21143,0.07847260039370078,791.5538802083333,0.00025370340306410486,25.0,0.0
419.5127,0.07886124015748032,792.084375,0.00025370340306410486,25.0,0.0
420.81396,0.07923758661417322,792.409140625,0.00025370340306410486,25.0,0.0
422.11523,0.07959757283464566,794.4753125,0.00025370340306410486,25.0,0.0
423.4165,0.07998721653543307,794.8848697916667,0.00025370340306410486,25.0,0.0
424.71777,0.08036738385826772,793.7315625,0.00025370340306410486,25.0,0.0
426.01904,0.08072097440944882,793.0374218750001,0.00025370340306410486,25.0,0.0
427.32031,0.08108634645669291,794.4842708333333,0.00025370340306410486,25.0,0.0
428.62158,0.08148510433070867,796.6398958333334,0.00025370340306410486,25.0,0.0
429.92285,0.08185122244094488,794.7737500000001,0.00025370340306410486,25.0,0.0
431.22412,0.08220467913385826,794.6241927083335,0.00025370340306410486,25.0,0.0
432.52539,0.08264179921259843,797.2397395833334,0.00025370340306410486,25.0,0.0
433.82666,0.08297042322834645,795.4772395833334,0.00025370340306410486,25.0,0.0
435.12793,0.08336848818897638,797.5682552083333,0.00025370340306410486,25.0,0.0
436.4292,0.08371181889763779,798.0775260416666,0.00025370340306410486,25.0,0.0
437.73047,0.08410299212598425,795.4874739583333,0.00025370340306410486,25.0,0.0
439.03174,0.08445132874015748,798.48390625,0.00025370340306410486,25.0,0.0
440.33301,0.08486783858267717,796.406796875,0.00025370340306410486,25.0,0.0
441.63428,0.08524797637795276,798.2144010416667,0.00025370340306410486,25.0,0.0
442.93555,0.08558466141732284,797.6588020833333,0.00025370340306410486,25.0,0.0
444.23682,0.08595976574803149,797.3141406249999,0.00025370340306410486,25.0,0.0
445.53809,0.08627941929133857,797.4400260416667,0.00025370340306410486,25.0,0.0
446.83936,0.0867166437007874,799.6395052083333,0.00025370340306410486,25.0,0.0
448.14063,0.08708429921259841,798.5123958333334,0.00025370340306410486,25.0,0.0
449.44189,0.08739765748031496,800.0065364583334,0.00025370340306410486,25.0,0.0
450.74316,0.08776646062992126,799.869921875,0.00025370340306410486,25.0,0.0
452.04443,0.08813082874015749,799.0725260416667,0.00025370340306410486,25.0,0.0
453.3457,0.08856560826771653,799.2138541666667,0.00025370340306410486,25.0,0.0
454.64697,0.0889582125984252,801.029453125,0.00025370340306410486,25.0,0.0
455.94824,0.08934482874015748,801.4251822916666,0.00025370340306410486,25.0,0.0
457.24951,0.08969171456692913,800.2705989583334,0.00025370340306410486,25.0,0.0
458.55078,0.09009989960629922,802.2776822916667,0.00025370340306410486,25.0,0.0
459.85205,0.0905028188976378,801.8754947916667,0.00025370340306410486,25.0,0.0
461.15332,0.09086958661417323,803.18921875,0.00025370340306410486,25.0,0.0
462.45459,0.09125404330708661,802.5500520833333,0.00025370340306410486,25.0,0.0
463.75586,0.09157712795275591,803.5191145833334,0.00025370340306410486,25.0,0.0
465.05713,0.09191203937007873,801.7208854166668,0.00025370340306410486,25.0,0.0
466.3584,0.09225952952755904,804.187890625,0.00025370340306410486,25.0,0.0
467.65967,0.09268136811023622,803.8291927083334,0.00025370340306410486,25.0,0.0
468.96094,0.09308000984251968,801.5483854166666,0.00025370340306410486,25.0,0.0
470.26221,0.09340108858267716,802.3346614583334,0.00025370340306410486,25.0,0.0
471.56348,0.0938051279527559,805.1371875,0.00025370340306410486,25.0,0.0
472.86475,0.0941605374015748,804.5955729166667,0.00025370340306410486,25.0,0.0
474.16602,0.09453795866141733,804.8330989583334,0.00025370340306410486,25.0,0.0
475.46729,0.0948991594488189,803.37625,0.00025370340306410486,25.0,0.0
476.76855,0.09524912007874016,806.3129947916667,0.00025370340306410486,25.0,0.0
478.06982,0.09567974015748032,805.4829947916668,0.00025370340306410486,25.0,0.0
479.37109,0.09601063385826772,806.5563802083334,0.00025370340306410486,25.0,0.0
480.67236,0.09639559448818898,806.0112760416666,0.00025370340306410486,25.0,0.0
481.97363,0.09673839763779526,805.62515625,0.00025370340306410486,25.0,0.0
483.2749,0.09716836614173228,806.9852864583333,0.00025370340306410486,25.0,0.0
484.57617,0.09752483858267716,805.4590104166666,0.00025370340306410486,25.0,0.0
485.87744,0.09791233858267716,807.0227864583334,0.00025370340306410486,25.0,0.0
487.17871,0.0982613779527559,806.83046875,0.00025370340306410486,25.0,0.0
488.47998,0.09858482677165355,806.9680468750001,0.00025370340306410486,25.0,0.0
489.78125,0.09904303149606299,809.1409114583333,0.00025370340306410486,25.0,0.0
491.08252,0.09946887598425197,808.5840885416667,0.00025370340306410486,25.0,0.0
492.38379,0.0998562125984252,806.0022916666667,0.00025370340306410486,25.0,0.0
493.68506,0.10022092716535433,808.1436197916667,0.00025370340306410486,25.0,0.0
494.98633,0.1005728405511811,809.67828125,0.00025370340306410486,25.0,0.0
496.2876,0.10096270078740158,808.7146875,0.00025370340306410486,25.0,0.0
497.58887,0.10132478740157479,809.2733333333333,0.00025370340306410486,25.0,0.0
498.89014,0.1017520748031496,809.2991406250001,0.00025370340306410486,25.0,0.0
500.19141,0.1021266220472441,810.4703385416667,0.00025370340306410486,25.0,0.0
501.49268,0.1024983996062992,809.1643750000001,0.00025370340306410486,25.0,0.0
502.79395,0.10282865354330709,807.3770572916668,0.00025370340306410486,25.0,0.0
504.09521,0.10317825590551181,808.426796875,0.00025370340306410486,25.0,0.0
505.39648,0.1035364468503937,808.1131510416667,0.00025370340306410486,25.0,0.0
506.69775,0.1038850531496063,811.95328125,0.00025370340306410486,25.0,0.0
507.99902,0.10423967716535432,809.8760677083334,0.00025370340306410486,25.0,0.0
509.30029,0.10461793110236221,810.665,0.00025370340306410486,25.0,0.0
510.60156,0.10498454724409449,811.1391666666666,0.00025370340306410486,25.0,0.0
511.90283,0.10538346456692914,811.92296875,0.00025370340306410486,25.0,0.0
513.2041,0.10581783858267715,812.599296875,0.00025370340306410486,25.0,0.0
514.50537,0.10621118307086613,812.3234375000001,0.00025370340306410486,25.0,0.0
515.80664,0.10649273228346455,810.4631510416667,0.00025370340306410486,25.0,0.0
517.10791,0.1069227657480315,813.482421875,0.00025370340306410486,25.0,0.0
518.40918,0.10727699015748031,812.8656510416668,0.00025370340306410486,25.0,0.0
519.71045,0.10764102559055118,814.1604687500001,0.00025370340306410486,25.0,0.0
521.01172,0.10799256299212599,812.81140625,0.00025370340306410486,25.0,0.0
522.31299,0.10830882086614173,812.4469791666668,0.00025370340306410486,25.0,0.0
523.61426,0.10872086614173228,813.7090625000001,0.00025370340306410486,25.0,0.0
524.91553,0.10908253149606299,814.6022135416667,0.00025370340306410486,25.0,0.0
526.2168,0.10956162007874017,814.7216927083334,0.00025370340306410486,25.0,0.0
527.51807,0.10995728740157482,814.9412760416667,0.00025370340306410486,25.0,0.0
528.81934,0.11036906496062991,814.5778125,0.00025370340306410486,25.0,0.0
530.12061,0.11072670472440943,814.1234114583334,0.00025370340306410486,25.0,0.0
531.42188,0.11104676181102362,813.2057291666667,0.00025370340306410486,25.0,0.0
532.72314,0.11139482677165355,815.1865104166668,0.00025370340306410486,25.0,0.0
534.02441,0.11178799409448818,816.2659375000001,0.00025370340306410486,25.0,0.0
535.32568,0.1122448622047244,816.7672395833333,0.00025370340306410486,25.0,0.0
536.62695,0.11265237992125983,815.3107291666668,0.00025370340306410486,25.0,0.0
537.92822,0.11298019291338582,815.0182812500001,0.00025370340306410486,25.0,0.0
539.22949,0.11336257874015747,815.2710677083334,0.00025370340306410486,25.0,0.0
540.53076,0.11366271456692914,816.9036197916668,0.00025370340306410486,25.0,0.0
541.83203,0.11403954921259842,815.714140625,0.00025370340306410486,25.0,0.0
543.1333,0.1144004625984252,818.2416927083334,0.00025370340306410486,25.0,0.0
544.43457,0.11483587992125983,817.47359375,0.00025370340306410486,25.0,0.0
545.73584,0.1151811653543307,817.1388541666668,0.00025370340306410486,25.0,0.0
547.03711,0.11559670866141733,817.095,0.00025370340306410486,25.0,0.0
548.33838,0.11600033070866142,818.3896354166667,0.00025370340306410486,25.0,0.0
549.63965,0.11640203937007874,817.553828125,0.00025370340306410486,25.0,0.0
550.94092,0.11676422047244094,819.0079427083333,0.00025370340306410486,25.0,0.0
552.24219,0.11714475196850394,819.21609375,0.00025370340306410486,25.0,0.0
553.54346,0.11752367519685039,817.2581250000001,0.00025370340306410486,25.0,0.0
554.84473,0.11788731102362204,819.1835416666667,0.00025370340306410486,25.0,0.0
556.146,0.11826428543307087,819.1729947916667,0.00025370340306410486,25.0,0.0
557.44727,0.11864533267716534,820.1815885416667,0.00025370340306410486,25.0,0.0
558.74854,0.11899860826771652,819.6554166666667,0.00025370340306410486,25.0,0.0
560.0498,0.11937782480314961,820.5134114583333,0.00025370340306410486,25.0,0.0
561.35107,0.1197774468503937,822.9858333333334,0.00025370340306410486,25.0,0.0
562.65234,0.12023145078740158,821.6475260416667,0.00025370340306410486,25.0,0.0
563.95361,0.1206163346456693,822.1197135416667,0.00025370340306410486,25.0,0.0
565.25488,0.12097876181102363,820.3208854166667,0.00025370340306410486,25.0,0.0
566.55615,0.12134788779527558,820.8513281250001,0.00025370340306410486,25.0,0.0
567.85742,0.12169841732283465,820.438828125,0.00025370340306410486,25.0,0.0
569.15869,0.12210421062992127,821.286015625,0.00025370340306410486,25.0,0.0
570.45996,0.12248521062992127,823.7457812499999,0.00025370340306410486,25.0,0.0
571.76123,0.12290942322834644,821.7551041666667,0.00025370340306410486,25.0,0.0
573.0625,0.1233075433070866,821.4453385416667,0.00025370340306410486,25.0,0.0
574.36377,0.1236791811023622,822.090078125,0.00025370340306410486,25.0,0.0
575.66504,0.12406650393700787,822.721796875,0.00025370340306410486,25.0,0.0
576.96631,0.12445217519685038,823.7108333333333,0.00025370340306410486,25.0,0.0
578.26758,0.12480725590551181,823.0290625,0.00025370340306410486,25.0,0.0
579.56885,0.12514545472440947,822.3960937500001,0.00025370340306410486,25.0,0.0
580.87012,0.12547589566929135,823.0613020833334,0.00025370340306410486,25.0,0.0
582.17139,0.12580873228346456,824.3842447916667,0.00025370340306410486,25.0,0.0
583.47266,0.12622443897637795,823.9516666666667,0.00025370340306410486,25.0,0.0
584.77393,0.12667297637795275,825.1858333333333,0.00025370340306410486,25.0,0.0
586.0752,0.1270864783464567,824.4400781250001,0.00025370340306410486,25.0,0.0
587.37646,0.12745993307086614,822.3653125,0.00025370340306410486,25.0,0.0
588.67773,0.12781275,823.5493229166667,0.00025370340306410486,25.0,0.0
589.979,0.12814630118110237,824.6571875,0.00025370340306410486,25.0,0.0
591.28027,0.12851768110236222,824.1958072916667,0.00025370340306410486,25.0,0.0
592.58154,0.12889402362204724,825.0745052083333,0.00025370340306410486,25.0,0.0
593.88281,0.12927337007874015,823.9371093750001,0.00025370340306410486,25.0,0.0
595.18408,0.12969935433070864,825.3925260416668,0.00025370340306410486,25.0,0.0
596.48535,0.13015923818897637,827.6236197916668,0.00025370340306410486,25.0,0.0
597.78662,0.1305236122047244,825.4161197916668,0.00025370340306410486,25.0,0.0
599.08789,0.13092116732283463,826.2351302083334,0.00025370340306410486,25.0,0.0
600.38916,0.13127609645669291,824.3934635416667,0.00025370340306410486,25.0,0.0
601.69043,0.13166375,825.98,0.00025370340306410486,25.0,0.0
602.9917,0.13205176771653543,826.5532812499999,0.00025370340306410486,25.0,0.0
604.29297,0.1324303031496063,827.3033854166666,0.00025370340306410486,25.0,0.0
605.59424,0.1328013188976378,827.4333333333334,0.00025370340306410486,25.0,0.0
606.89551,0.13315895866141733,827.6548958333334,0.00025370340306410486,25.0,0.0
608.19678,0.13362825196850395,827.0549739583333,0.00025370340306410486,25.0,0.0
609.49805,0.1340076437007874,827.1001822916667,0.00025370340306410486,25.0,0.0
610.79932,0.1344262972440945,827.9292968750001,0.00025370340306410486,25.0,0.0
612.10059,0.13486997637795275,827.5696354166668,0.00025370340306410486,25.0,0.0
613.40186,0.13529190157480317,827.2626822916667,0.00025370340306410486,25.0,0.0
614.70313,0.1357016594488189,829.1298437500001,0.00025370340306410486,25.0,0.0
616.00439,0.13604782480314961,827.8554166666668,0.00025370340306410486,25.0,0.0
617.30566,0.13638910826771652,826.6260677083334,0.00025370340306410486,25.0,0.0
618.60693,0.13676406692913387,829.0622135416667,0.00025370340306410486,25.0,0.0
619.9082,0.1371794212598425,828.1289322916667,0.00025370340306410486,25.0,0.0
621.20947,0.13753036023622048,827.908203125,0.00025370340306410486,25.0,0.0
622.51074,0.1378796811023622,828.8867187500001,0.00025370340306410486,25.0,0.0
623.81201,0.13826484842519685,829.4007031250001,0.00025370340306410486,25.0,0.0
625.11328,0.13866158267716536,829.8990364583334,0.00025370340306410486,25.0,0.0
626.41455,0.13904406102362205,828.5269531250001,0.00025370340306410486,25.0,0.0
627.71582,0.13948460826771653,831.449453125,0.00025370340306410486,25.0,0.0
629.01709,0.1399124468503937,829.3169010416667,0.00025370340306410486,25.0,0.0
630.31836,0.14029966535433072,828.3218489583334,0.00025370340306410486,25.0,0.0
631.61963,0.14063041338582677,829.6104947916666,0.00025370340306410486,25.0,0.0
632.9209,0.14104260039370078,831.2941927083333,0.00025370340306410486,25.0,0.0
634.22217,0.14144716141732283,829.7725,0.00025370340306410486,25.0,0.0
635.52344,0.14186594291338583,832.0930989583334,0.00025370340306410486,25.0,0.0
636.82471,0.14227715551181103,833.2065625,0.00025370340306410486,25.0,0.0
638.12598,0.14268672637795277,830.45546875,0.00025370340306410486,25.0,0.0
639.42725,0.143138031496063,832.4486979166667,0.00025370340306410486,25.0,0.0
640.72852,0.14358163976377952,830.6940104166666,0.00025370340306410486,25.0,0.0
642.02979,0.14403089370078742,831.4044270833333,0.00025370340306410486,25.0,0.0
643.33105,0.14443318897637794,830.6614583333333,0.00025370340306410486,25.0,0.0
644.63232,0.14478741338582676,830.6700260416667,0.00025370340306410486,25.0,0.0
645.93359,0.1451879625984252,833.0597656250001,0.00025370340306410486,25.0,0.0
647.23486,0.1455587657480315,832.6048437500001,0.00025370340306410486,25.0,0.0
648.53613,0.14596051181102362,832.2034114583333,0.00025370340306410486,25.0,0.0
649.8374,0.14635676377952755,831.6806770833334,0.00025370340306410486,25.0,0.0
651.13867,0.1467477972440945,831.7636458333334,0.00025370340306410486,25.0,0.0
652.43994,0.14711738188976378,834.19578125,0.00025370340306410486,25.0,0.0
653.74121,0.14748747047244093,832.7985677083334,0.00025370340306410486,25.0,0.0
655.04248,0.14786358858267717,832.8352083333333,0.00025370340306410486,25.0,0.0
656.34375,0.14821815354330709,832.43859375,0.00025370340306410486,25.0,0.0
657.64502,0.14862805314960628,834.4247916666668,0.00025370340306410486,25.0,0.0
658.94629,0.1490527716535433,832.9186197916666,0.00025370340306410486,25.0,0.0
660.24756,0.14951324212598424,833.723125,0.00025370340306410486,25.0,0.0
661.54883,0.1499598307086614,835.3516145833333,0.00025370340306410486,25.0,0.0
662.8501,0.15038458464566928,834.8997135416668,0.00025370340306410486,25.0,0.0
664.15137,0.15080416338582678,833.6427604166668,0.00025370340306410486,25.0,0.0
665.45264,0.15120384251968505,833.6984114583333,0.00025370340306410486,25.0,0.0
666.75391,0.1516352716535433,833.2258854166666,0.00025370340306410486,25.0,0.0
668.05518,0.15204804527559054,834.0631510416666,0.00025370340306410486,25.0,0.0
669.35645,0.15244817125984253,834.1398958333334,0.00025370340306410486,25.0,0.0
670.65771,0.1528333031496063,834.2332291666667,0.00025370340306410486,25.0,0.0
671.95898,0.15328392716535433,835.4728125,0.00025370340306410486,25.0,0.0
673.26025,0.15376857874015748,835.2815625000001,0.00025370340306410486,25.0,0.0
674.56152,0.15417287007874014,834.8309114583334,0.00025370340306410486,25.0,0.0
675.86279,0.15459219094488189,835.6530468750001,0.00025370340306410486,25.0,0.0
677.16406,0.1549412539370079,835.14640625,0.00025370340306410486,25.0,0.0
678.46533,0.15536745078740155,835.7263541666666,0.00025370340306410486,25.0,0.0
679.7666,0.15577987204724408,834.69875,0.00025370340306410486,25.0,0.0
681.06787,0.15620006102362205,836.3135677083334,0.00025370340306410486,25.0,0.0
682.36914,0.15657291929133857,834.9801302083333,0.00025370340306410486,25.0,0.0
683.67041,0.15695543307086612,836.3338541666667,0.00025370340306410486,25.0,0.0
684.97168,0.1574437913385827,837.683359375,0.00025370340306410486,25.0,0.0
686.27295,0.15784022047244095,837.1917187500001,0.00025370340306410486,25.0,0.0
687.57422,0.15827748228346455,836.35140625,0.00025370340306410486,25.0,0.0
688.87549,0.15866742322834645,837.0578645833334,0.00025370340306410486,25.0,0.0
690.17676,0.15912262401574803,838.3879427083334,0.00025370340306410486,25.0,0.0
691.47803,0.1595782007874016,835.569375,0.00025370340306410486,25.0,0.0
692.7793,0.15996863582677165,837.8232291666667,0.00025370340306410486,25.0,0.0
694.08057,0.16041585826771654,837.2824479166667,0.00025370340306410486,25.0,0.0
695.38184,0.16082257677165354,836.2297135416667,0.00025370340306410486,25.0,0.0
696.68311,0.16121458267716537,837.3734114583333,0.00025370340306410486,25.0,0.0
697.98438,0.16158700787401575,834.9547135416667,0.00025370340306410486,25.0,0.0
699.28564,0.16196312598425197,836.8190104166667,0.00025370340306410486,25.0,0.0
700.58691,0.1624163090551181,838.5137500000001,0.00025370340306410486,25.0,0.0
701.88818,0.16286894094488188,837.281796875,0.00025370340306410486,25.0,0.0
703.18945,0.16331944881889765,837.0102604166667,0.00025370340306410486,25.0,0.0
704.49072,0.16370916732283464,838.6328385416667,0.00025370340306410486,25.0,0.0
705.79199,0.16419908661417323,840.0945052083333,0.00025370340306410486,25.0,0.0
707.09326,0.16466167913385826,838.5133854166667,0.00025370340306410486,25.0,0.0
708.39453,0.16516847244094487,837.6841927083334,0.00025370340306410486,25.0,0.0
709.6958,0.16560988582677164,837.661875,0.00025370340306410486,25.0,0.0
710.99707,0.16603141338582678,838.6138802083334,0.00025370340306410486,25.0,0.0
712.29834,0.16645527559055118,838.5398958333334,0.00025370340306410486,25.0,0.0
713.59961,0.16683738976377954,837.5605208333334,0.00025370340306410486,25.0,0.0
714.90088,0.16727528543307088,839.1833593750001,0.00025370340306410486,25.0,0.0
716.20215,0.1677029940944882,838.6652083333333,0.00025370340306410486,25.0,0.0
717.50342,0.16809706692913384,839.4156770833334,0.00025370340306410486,25.0,0.0
718.80469,0.16855455511811024,839.9845052083334,0.00025370340306410486,25.0,0.0
720.10596,0.16901854527559057,840.113828125,0.00025370340306410486,25.0,0.0
721.40723,0.1695550216535433,840.3318489583334,0.00025370340306410486,25.0,0.0
722.7085,0.16995818503937007,837.9864322916668,0.00025370340306410486,25.0,0.0
724.00977,0.17026601771653543,836.4007291666667,0.00025370340306410486,25.0,0.0
725.31104,0.17060260826771653,839.2983072916667,0.00025370340306410486,25.0,0.0
726.6123,0.17100664173228347,839.4256510416667,0.00025370340306410486,25.0,0.0
727.91357,0.17141102559055119,838.1865885416668,0.00025370340306410486,25.0,0.0
729.21484,0.17183276377952755,840.9300520833334,0.00025370340306410486,25.0,0.0
730.51611,0.17228232086614173,840.7904947916667,0.00025370340306410486,25.0,0.0
731.81738,0.17273282874015747,841.4684895833334,0.00025370340306410486,25.0,0.0
733.11865,0.17325292716535431,840.0509635416668,0.00025370340306410486,25.0,0.0
734.41992,0.17367908858267717,839.5132812500001,0.00025370340306410486,25.0,0.0
735.72119,0.17410928543307086,839.8208072916667,0.00025370340306410486,25.0,0.0
737.02246,0.17454126771653544,838.9521875,0.00025370340306410486,25.0,0.0
738.32373,0.17500572637795275,841.6280208333334,0.00025370340306410486,25.0,0.0
739.625,0.17544915748031498,839.0232812500001,0.00025370340306410486,25.0,0.0
740.92627,0.17590117913385828,841.3269791666667,0.00025370340306410486,25.0,0.0
742.22754,0.1763474527559055,840.7041666666668,0.00025370340306410486,25.0,0.0
743.52881,0.17677666338582676,839.4015625000001,0.00025370340306410486,25.0,0.0
744.83008,0.17721199999999998,839.6194531250001,0.00025370340306410486,25.0,0.0
746.13135,0.17766195669291338,840.4632031250001,0.00025370340306410486,25.0,0.0
747.43262,0.17808978543307089,841.1708072916666,0.00025370340306410486,25.0,0.0
748.73389,0.1785371712598425,842.3827604166667,0.00025370340306410486,25.0,0.0
750.03516,0.1790319842519685,841.9990625,0.00025370340306410486,25.0,0.0
751.33643,0.17948855708661418,840.9286458333335,0.00025370340306410486,25.0,0.0
752.6377,0.1798948090551181,840.7906770833333,0.00025370340306410486,25.0,0.0
753.93896,0.18036561417322836,842.538203125,0.00025370340306410486,25.0,0.0
755.24023,0.18084579527559053,841.0027083333334,0.00025370340306410486,25.0,0.0
756.5415,0.18131124015748032,843.3815104166667,0.00025370340306410486,25.0,0.0
757.84277,0.18179276968503938,841.1371875000001,0.00025370340306410486,25.0,0.0
759.14404,0.18223315157480313,841.62375,0.00025370340306410486,25.0,0.0
760.44531,0.18265215748031496,841.8852604166667,0.00025370340306410486,25.0,0.0
761.74658,0.18308953543307085,842.6546614583334,0.00025370340306410486,25.0,0.0
763.04785,0.1835785157480315,843.3172916666667,0.00025370340306410486,25.0,0.0
764.34912,0.1841135964566929,843.5556510416668,0.00025370340306410486,25.0,0.0
765.65039,0.1846135255905512,840.4800520833334,0.00025370340306410486,25.0,0.0
766.95166,0.18503682283464568,842.54296875,0.00025370340306410486,25.0,0.0
768.25293,0.18543917913385827,842.0523958333334,0.00025370340306410486,25.0,0.0
769.5542,0.18593955314960628,843.73125,0.00025370340306410486,25.0,0.0
770.85547,0.18645015748031496,842.4177864583334,0.00025370340306410486,25.0,0.0
772.15674,0.1869479035433071,841.1342708333333,0.00025370340306410486,25.0,0.0
773.45801,0.18736830314960629,841.4265364583334,0.00025370340306410486,25.0,0.0
774.75928,0.18774300393700785,843.2304947916666,0.00025370340306410486,25.0,0.0
776.06055,0.18823692322834645,843.6274218750001,0.00025370340306410486,25.0,0.0
777.36182,0.18880460039370078,842.805234375,0.00025370340306410486,25.0,0.0
778.66309,0.18931696456692912,843.1172135416667,0.00025370340306410486,25.0,0.0
779.96436,0.1897240374015748,841.679375,0.00025370340306410486,25.0,0.0
781.26563,0.19020885236220472,842.1822916666667,0.00025370340306410486,25.0,0.0
782.56689,0.19069100393700789,843.5855208333334,0.00025370340306410486,25.0,0.0
783.86816,0.1911614468503937,842.9379687500001,0.00025370340306410486,25.0,0.0
785.16943,0.19162205708661417,842.021171875,0.00025370340306410486,25.0,0.0
786.4707,0.1921166122047244,843.496015625,0.00025370340306410486,25.0,0.0
787.77197,0.19253304527559054,843.69296875,0.00025370340306410486,25.0,0.0
789.07324,0.19300487401574803,843.5211718749999,0.00025370340306410486,25.0,0.0
790.37451,0.1934295098425197,842.4116666666666,0.00025370340306410486,25.0,0.0
791.67578,0.19389139763779528,842.8729427083333,0.00025370340306410486,25.0,0.0
792.97705,0.19436828346456692,842.2198697916667,0.00025370340306410486,25.0,0.0
794.27832,0.19481469488188977,843.4096614583334,0.00025370340306410486,25.0,0.0
795.57959,0.19531007086614172,843.3123958333333,0.00025370340306410486,25.0,0.0
796.88086,0.1958160531496063,843.5965885416666,0.00025370340306410486,25.0,0.0
798.18213,0.19631250787401575,843.028515625,0.00025370340306410486,25.0,0.0
799.4834,0.1968574409448819,844.73953125,0.00025370340306410486,25.0,0.0
800.78467,0.19736088582677166,843.2595052083334,0.00025370340306410486,25.0,0.0
802.08594,0.19781751968503936,842.2611979166667,0.00025370340306410486,25.0,0.0
803.38721,0.19827293307086613,842.8178125000001,0.00025370340306410486,25.0,0.0
804.68848,0.19874084645669293,842.086796875,0.00025370340306410486,25.0,0.0
805.98975,0.19923232283464565,843.5725000000001,0.00025370340306410486,25.0,0.0
807.29102,0.1997367913385827,844.09828125,0.00025370340306410486,25.0,0.0
808.59229,0.20025557086614174,841.3597135416667,0.00025370340306410486,25.0,0.0
809.89355,0.20068480314960627,843.8301041666667,0.00025370340306410486,25.0,0.0
811.19482,0.20113704724409448,843.8815364583334,0.00025370340306410486,25.0,0.0
812.49609,0.20167206692913386,844.7031770833333,0.00025370340306410486,25.0,0.0
813.79736,0.20210501968503936,843.7165625,0.00025370340306410486,25.0,0.0
815.09863,0.20264041338582678,845.2023177083333,0.00025370340306410486,25.0,0.0
816.3999,0.20319007874015746,843.9361458333334,0.00025370340306410486,25.0,0.0
817.70117,0.20371543307086615,841.6525520833334,0.00025370340306410486,25.0,0.0
819.00244,0.20416003937007876,842.5210416666667,0.00025370340306410486,25.0,0.0
820.30371,0.20454515748031496,842.5263802083334,0.00025370340306410486,25.0,0.0
821.60498,0.20505161417322834,843.9342447916667,0.00025370340306410486,25.0,0.0
822.90625,0.2055675,843.88859375,0.00025370340306410486,25.0,0.0
824.20752,0.2060761220472441,844.2106770833333,0.00025370340306410486,25.0,0.0
825.40869,0.2066210433070866,846.9621093750001,0.00025370340306410486,25.0,0.0