File: datasets/am_bench_2022/csv/0-XY.20-2.csv
Time(s),Strain(%),Stress(MPa),SR(s-1),Temp(C),Angle(deg)
12.958008,0.001015290846456693,19.252276675575658,0.00025370340306410486,25.0,0.0
14.259277,0.001036826751968504,24.20608732524671,0.00025370340306410486,25.0,0.0
15.560547,0.0010514907874015747,29.394698293585527,0.00025370340306410486,25.0,0.0
16.861816,0.0010543503740157482,33.93063322368421,0.00025370340306410486,25.0,0.0
18.163086,0.001075866122047244,40.29018040707237,0.00025370340306410486,25.0,0.0
19.464355,0.00111240468503937,44.15993523848684,0.00025370340306410486,25.0,0.0
20.765625,0.0011241254133858268,49.567508737664475,0.00025370340306410486,25.0,0.0
22.066895,0.0011402857874015747,56.99424856085526,0.00025370340306410486,25.0,0.0
23.368164,0.0011573665748031495,63.481142064144734,0.00025370340306410486,25.0,0.0
24.669434,0.001201877559055118,68.70565378289474,0.00025370340306410486,25.0,0.0
25.970703,0.001209847874015748,75.75441252055921,0.00025370340306410486,25.0,0.0
27.271973,0.001238804311023622,82.10214329769737,0.00025370340306410486,25.0,0.0
28.573242,0.0012803150787401574,91.66608501233553,0.00025370340306410486,25.0,0.0
29.874512,0.0012880549606299212,98.73681897615131,0.00025370340306410486,25.0,0.0
31.175781,0.001330451496062992,105.93104440789473,0.00025370340306410486,25.0,0.0
32.477051,0.0013755574803149607,113.77790141858553,0.00025370340306410486,25.0,0.0
33.77832,0.0013777186023622046,119.83946083470394,0.00025370340306410486,25.0,0.0
35.07959,0.001418046968503937,130.3142398231908,0.00025370340306410486,25.0,0.0
36.380859,0.00142197218503937,135.82718955592105,0.00025370340306410486,25.0,0.0
37.682129,0.0014535509842519686,144.43203125,0.00025370340306410486,25.0,0.0
38.983398,0.001506916220472441,151.54957853618419,0.00025370340306410486,25.0,0.0
40.284668,0.0015183981692913386,158.66361276726974,0.00025370340306410486,25.0,0.0
41.585938,0.0015458871259842518,169.31234323601973,0.00025370340306410486,25.0,0.0
42.887207,0.0015672430118110236,177.3131681743421,0.00025370340306410486,25.0,0.0
44.188477,0.0016283892913385827,186.95777909128287,0.00025370340306410486,25.0,0.0
45.489746,0.0016598285826771653,193.37781147203947,0.00025370340306410486,25.0,0.0
46.791016,0.0016968963188976377,203.12029965049342,0.00025370340306410486,25.0,0.0
48.092285,0.0017393648031496063,214.18936831825658,0.00025370340306410486,25.0,0.0
49.393555,0.0017438652165354329,220.44384251644735,0.00025370340306410486,25.0,0.0
50.694824,0.0018122688385826772,232.5975277549342,0.00025370340306410486,25.0,0.0
51.996094,0.0018262513385826774,242.27441920230262,0.00025370340306410486,25.0,0.0
53.297363,0.0018796610433070864,250.54729389391446,0.00025370340306410486,25.0,0.0
54.598633,0.001913337874015748,262.9008018092105,0.00025370340306410486,25.0,0.0
55.899902,0.001940809153543307,269.14327199835526,0.00025370340306410486,25.0,0.0
57.201172,0.001978357677165354,279.86556846217104,0.00025370340306410486,25.0,0.0
58.502441,0.002025301377952756,289.3627672697368,0.00025370340306410486,25.0,0.0
59.803711,0.0020558137795275593,300.28500205592104,0.00025370340306410486,25.0,0.0
61.10498,0.0020940970472440945,308.8988743832237,0.00025370340306410486,25.0,0.0
62.40625,0.002116157283464567,319.4517886513158,0.00025370340306410486,25.0,0.0
63.70752,0.002150651377952756,329.0252621299342,0.00025370340306410486,25.0,0.0
65.008789,0.0022105253937007873,336.51192434210526,0.00025370340306410486,25.0,0.0
66.310059,0.0022239238188976377,347.5530941611842,0.00025370340306410486,25.0,0.0
67.611328,0.002282328346456693,358.4653063322369,0.00025370340306410486,25.0,0.0
68.912598,0.0023021374015748035,365.16395970394734,0.00025370340306410486,25.0,0.0
70.213867,0.0023595586614173227,375.8993883634868,0.00025370340306410486,25.0,0.0
71.515137,0.002405841535433071,384.01051089638156,0.00025370340306410486,25.0,0.0
72.816406,0.0024335789370078737,394.6123560855263,0.00025370340306410486,25.0,0.0
74.117676,0.0025100246062992127,404.5010279605263,0.00025370340306410486,25.0,0.0
75.418945,0.0025080562992125985,411.6152857730263,0.00025370340306410486,25.0,0.0
76.720215,0.00254394625984252,421.2308285361842,0.00025370340306410486,25.0,0.0
78.021484,0.002609853543307087,434.21299342105266,0.00025370340306410486,25.0,0.0
79.322754,0.002658200787401575,442.7217567845395,0.00025370340306410486,25.0,0.0
80.624023,0.002695170275590551,449.24776418585526,0.00025370340306410486,25.0,0.0
81.925293,0.0027248580708661417,458.8529502467105,0.00025370340306410486,25.0,0.0
83.226563,0.0027867499999999997,469.87332956414474,0.00025370340306410486,25.0,0.0
84.527832,0.002807977559055118,477.3615594161184,0.00025370340306410486,25.0,0.0
85.829102,0.0028609580708661418,483.52819181743416,0.00025370340306410486,25.0,0.0
87.130371,0.0028820358267716535,491.54368832236844,0.00025370340306410486,25.0,0.0
88.431641,0.002912147244094488,499.5964997944079,0.00025370340306410486,25.0,0.0
89.73291,0.0029739996062992124,508.57655736019734,0.00025370340306410486,25.0,0.0
91.03418,0.0030325411417322836,516.1509046052631,0.00025370340306410486,25.0,0.0
92.335449,0.0030806019685039373,524.623201069079,0.00025370340306410486,25.0,0.0
93.636719,0.003115008267716535,531.9610402960527,0.00025370340306410486,25.0,0.0
94.937988,0.0031573078740157476,538.5149054276316,0.00025370340306410486,25.0,0.0
96.239258,0.0032056444881889763,545.3991313733552,0.00025370340306410486,25.0,0.0
97.540527,0.003258783464566929,553.9354440789473,0.00025370340306410486,25.0,0.0
98.841797,0.003331204133858268,561.6924599095395,0.00025370340306410486,25.0,0.0
100.14307,0.0033705364173228346,569.2828433388158,0.00025370340306410486,25.0,0.0
101.44434,0.0034086153543307087,573.8221371299342,0.00025370340306410486,25.0,0.0
102.74561,0.003454301181102362,581.4138312088816,0.00025370340306410486,25.0,0.0
104.04688,0.003540029330708661,585.7589432565788,0.00025370340306410486,25.0,0.0
105.34814,0.003576626968503937,591.2480211759868,0.00025370340306410486,25.0,0.0
106.64941,0.0036281911417322833,597.0851922286184,0.00025370340306410486,25.0,0.0
107.95068,0.0036834448818897636,601.3826840049343,0.00025370340306410486,25.0,0.0
109.25195,0.0037159590551181106,605.7532123766448,0.00025370340306410486,25.0,0.0
110.55322,0.0038243592519685036,613.58984375,0.00025370340306410486,25.0,0.0
111.85449,0.0038484041338582675,618.4426141036184,0.00025370340306410486,25.0,0.0
113.15576,0.0038987659448818895,623.8340100740131,0.00025370340306410486,25.0,0.0
114.45703,0.003975028149606299,628.0178865131579,0.00025370340306410486,25.0,0.0
115.7583,0.004041049015748032,631.3687808388158,0.00025370340306410486,25.0,0.0
117.05957,0.00410591811023622,635.6042865953947,0.00025370340306410486,25.0,0.0
118.36084,0.004191558070866142,642.3410002055921,0.00025370340306410486,25.0,0.0
119.66211,0.004278024409448819,645.4245733963816,0.00025370340306410486,25.0,0.0
120.96338,0.004332140157480315,648.5008480674342,0.00025370340306410486,25.0,0.0
122.26465,0.004401140748031496,652.9429738898026,0.00025370340306410486,25.0,0.0
123.56592,0.004494302755905512,655.6625205592105,0.00025370340306410486,25.0,0.0
124.86719,0.004582050984251969,660.3789319490131,0.00025370340306410486,25.0,0.0
126.16846,0.00467980531496063,662.6747275904605,0.00025370340306410486,25.0,0.0
127.46973,0.004764820472440944,666.475431743421,0.00025370340306410486,25.0,0.0
128.771,0.004855831299212598,668.3034025493421,0.00025370340306410486,25.0,0.0
130.07227,0.00497403405511811,673.8619962993421,0.00025370340306410486,25.0,0.0
131.37354,0.0050955929133858265,675.6480777138157,0.00025370340306410486,25.0,0.0
132.6748,0.005207297637795275,677.6058799342105,0.00025370340306410486,25.0,0.0
133.97607,0.005348393700787402,681.6093493009869,0.00025370340306410486,25.0,0.0
135.27734,0.0054873519685039365,685.2661903782895,0.00025370340306410486,25.0,0.0
136.57861,0.0056459066929133855,686.6205283717105,0.00025370340306410486,25.0,0.0
137.87988,0.005779581496062992,687.8785207648026,0.00025370340306410486,25.0,0.0
139.18115,0.005914561614173228,689.9372430098683,0.00025370340306410486,25.0,0.0
140.48242,0.006058485433070865,691.7849249588817,0.00025370340306410486,25.0,0.0
141.78369,0.0062270596456692915,693.8221628289474,0.00025370340306410486,25.0,0.0
143.08496,0.006399646850393701,695.3339072779605,0.00025370340306410486,25.0,0.0
144.38623,0.006617653346456693,701.2814555921052,0.00025370340306410486,25.0,0.0
145.6875,0.0068333381889763775,700.5780736019736,0.00025370340306410486,25.0,0.0
146.98877,0.007009378543307087,700.8456003289474,0.00025370340306410486,25.0,0.0
148.29004,0.0072049659448818896,704.398591694079,0.00025370340306410486,25.0,0.0
149.59131,0.007396533070866141,707.0376490542764,0.00025370340306410486,25.0,0.0
150.89258,0.007664459251968504,705.8375051398026,0.00025370340306410486,25.0,0.0
152.19385,0.007902329330708661,710.1247687088817,0.00025370340306410486,25.0,0.0
153.49512,0.00814895157480315,710.6073190789474,0.00025370340306410486,25.0,0.0
154.79639,0.008384429527559056,711.7185444078947,0.00025370340306410486,25.0,0.0
156.09766,0.00867211653543307,715.3699372944079,0.00025370340306410486,25.0,0.0
157.39893,0.008937858661417322,717.4201274671052,0.00025370340306410486,25.0,0.0
158.7002,0.009227885826771655,716.0871196546053,0.00025370340306410486,25.0,0.0
160.00146,0.009468279133858268,718.3532329358553,0.00025370340306410486,25.0,0.0
161.30273,0.009758106889763779,720.6177014802631,0.00025370340306410486,25.0,0.0
162.604,0.010068957283464568,721.7097296463816,0.00025370340306410486,25.0,0.0
163.90527,0.010347975787401575,723.9708830180921,0.00025370340306410486,25.0,0.0
165.20654,0.01068332657480315,721.0933645148027,0.00025370340306410486,25.0,0.0
166.50781,0.010926170866141732,722.3560855263157,0.00025370340306410486,25.0,0.0
167.80908,0.011173076968503937,725.547697368421,0.00025370340306410486,25.0,0.0
169.11035,0.011496885236220472,725.7884457236843,0.00025370340306410486,25.0,0.0
170.41162,0.011839897244094488,727.4339021381579,0.00025370340306410486,25.0,0.0
171.71289,0.012172197637795276,728.3425421463816,0.00025370340306410486,25.0,0.0
173.01416,0.01247426220472441,727.596525493421,0.00025370340306410486,25.0,0.0
174.31543,0.012728303543307087,728.9119037828948,0.00025370340306410486,25.0,0.0
175.6167,0.013099028543307085,730.600431743421,0.00025370340306410486,25.0,0.0
176.91797,0.013445003937007875,731.896484375,0.00025370340306410486,25.0,0.0
178.21924,0.013746309448818897,731.6558645148026,0.00025370340306410486,25.0,0.0
179.52051,0.01407867874015748,732.0723941200658,0.00025370340306410486,25.0,0.0
180.82178,0.014408883070866142,733.7523129111843,0.00025370340306410486,25.0,0.0
182.12305,0.014764397637795275,734.8416426809212,0.00025370340306410486,25.0,0.0
183.42432,0.015148322440944884,734.6209138569079,0.00025370340306410486,25.0,0.0
184.72559,0.015489145472440943,735.889494243421,0.00025370340306410486,25.0,0.0
186.02686,0.015831457086614174,736.1155427631579,0.00025370340306410486,25.0,0.0
187.32813,0.016172115748031495,739.0922080592105,0.00025370340306410486,25.0,0.0
188.62939,0.016535182086614173,739.2695826480262,0.00025370340306410486,25.0,0.0
189.93066,0.01690975255905512,740.4148077713816,0.00025370340306410486,25.0,0.0
191.23193,0.017273511023622047,740.2586862664474,0.00025370340306410486,25.0,0.0
192.5332,0.017626768307086614,741.18017578125,0.00025370340306410486,25.0,0.0
193.83447,0.017993876574803152,741.525390625,0.00025370340306410486,25.0,0.0
195.13574,0.01838408622047244,742.5077868009868,0.00025370340306410486,25.0,0.0
196.43701,0.018840010433070868,744.0849866365131,0.00025370340306410486,25.0,0.0
197.73828,0.019204262992125985,741.9254985608553,0.00025370340306410486,25.0,0.0
199.03955,0.019559724803149606,742.6845960115131,0.00025370340306410486,25.0,0.0
200.34082,0.019873675196850394,743.5190686677631,0.00025370340306410486,25.0,0.0
201.64209,0.020260925196850393,747.4652806332238,0.00025370340306410486,25.0,0.0
202.94336,0.02065973622047244,747.1758326480264,0.00025370340306410486,25.0,0.0
204.24463,0.021040405511811022,745.7440121299343,0.00025370340306410486,25.0,0.0
205.5459,0.02142943307086614,747.2513877467105,0.00025370340306410486,25.0,0.0
206.84717,0.02175388779527559,748.3981805098684,0.00025370340306410486,25.0,0.0
208.14844,0.022115399606299213,748.49560546875,0.00025370340306410486,25.0,0.0
209.44971,0.02255381299212598,749.1841334292764,0.00025370340306410486,25.0,0.0
210.75098,0.022995523622047244,751.5290655838817,0.00025370340306410486,25.0,0.0
212.05225,0.023347381889763777,749.668122944079,0.00025370340306410486,25.0,0.0
213.35352,0.023751003937007874,751.3505602384868,0.00025370340306410486,25.0,0.0
214.65479,0.02415199212598425,752.5972193667764,0.00025370340306410486,25.0,0.0
215.95605,0.024466541338582677,750.3180252878288,0.00025370340306410486,25.0,0.0
217.25732,0.02483824015748031,751.9103875411184,0.00025370340306410486,25.0,0.0
218.55859,0.025205801181102362,754.0724712171052,0.00025370340306410486,25.0,0.0
219.85986,0.02565431692913386,754.1287006578947,0.00025370340306410486,25.0,0.0
221.16113,0.02611851181102362,754.0428659539474,0.00025370340306410486,25.0,0.0
222.4624,0.026517856299212602,755.192537006579,0.00025370340306410486,25.0,0.0
223.76367,0.026885950787401577,756.1494140625,0.00025370340306410486,25.0,0.0
225.06494,0.02720910433070866,754.8812705592105,0.00025370340306410486,25.0,0.0
226.36621,0.027567218503937008,756.3897255345395,0.00025370340306410486,25.0,0.0
227.66748,0.028000143700787402,758.0569490131579,0.00025370340306410486,25.0,0.0
228.96875,0.02841054724409449,757.9569541529605,0.00025370340306410486,25.0,0.0
230.27002,0.028791102362204724,758.5052425986843,0.00025370340306410486,25.0,0.0
231.57129,0.029287659448818896,758.8445466694079,0.00025370340306410486,25.0,0.0
232.87256,0.029657537401574802,757.727873149671,0.00025370340306410486,25.0,0.0
234.17383,0.030029901574803147,758.9307668585527,0.00025370340306410486,25.0,0.0
235.4751,0.030467360236220473,761.3351408305922,0.00025370340306410486,25.0,0.0
236.77637,0.030825779527559057,760.6294202302631,0.00025370340306410486,25.0,0.0
238.07764,0.03122556496062992,761.9086657072369,0.00025370340306410486,25.0,0.0
239.37891,0.0316390905511811,762.9022409539474,0.00025370340306410486,25.0,0.0
240.68018,0.0320370688976378,761.5936986019736,0.00025370340306410486,25.0,0.0
241.98145,0.03251361811023622,763.634431537829,0.00025370340306410486,25.0,0.0
243.28271,0.03285752755905512,762.7727436266447,0.00025370340306410486,25.0,0.0
244.58398,0.03320366535433071,763.1914319490132,0.00025370340306410486,25.0,0.0
245.88525,0.03364492322834646,765.9648694490131,0.00025370340306410486,25.0,0.0
247.18652,0.034030275590551176,763.701017680921,0.00025370340306410486,25.0,0.0
248.48779,0.034340907480314965,763.0307360197369,0.00025370340306410486,25.0,0.0
249.78906,0.03466061811023622,764.4699835526316,0.00025370340306410486,25.0,0.0
251.09033,0.03507844488188976,767.0143914473684,0.00025370340306410486,25.0,0.0
252.3916,0.035483492125984256,763.7403628700658,0.00025370340306410486,25.0,0.0
253.69287,0.03592782874015748,768.0129266036184,0.00025370340306410486,25.0,0.0
254.99414,0.03630160433070866,765.5224095394736,0.00025370340306410486,25.0,0.0
256.29541,0.036706047244094486,767.3953022203948,0.00025370340306410486,25.0,0.0
257.59668,0.03704820866141732,766.9019582648027,0.00025370340306410486,25.0,0.0
258.89795,0.03748774015748031,770.0944695723684,0.00025370340306410486,25.0,0.0
260.19922,0.03792191141732284,769.430021587171,0.00025370340306410486,25.0,0.0
261.50049,0.03832042716535433,767.9079204358552,0.00025370340306410486,25.0,0.0
262.80176,0.03870347834645669,770.9789782072368,0.00025370340306410486,25.0,0.0
264.10303,0.039058139763779524,768.8753854851974,0.00025370340306410486,25.0,0.0
265.4043,0.039414665354330705,770.1381321957238,0.00025370340306410486,25.0,0.0
266.70557,0.03982639566929134,771.9728875411184,0.00025370340306410486,25.0,0.0
268.00684,0.040213291338582674,771.6996299342105,0.00025370340306410486,25.0,0.0
269.30811,0.04062687795275591,772.2984426398026,0.00025370340306410486,25.0,0.0
270.60938,0.041060049212598426,770.4899773848684,0.00025370340306410486,25.0,0.0
271.91064,0.04143532677165354,772.1716437088816,0.00025370340306410486,25.0,0.0
273.21191,0.041850958661417324,771.9182257401316,0.00025370340306410486,25.0,0.0
274.51318,0.042199492125984256,773.7568873355262,0.00025370340306410486,25.0,0.0
275.81445,0.042613159448818896,774.3231907894738,0.00025370340306410486,25.0,0.0
277.11572,0.04311217125984252,775.2727179276316,0.00025370340306410486,25.0,0.0
278.41699,0.0434970905511811,775.0853721217105,0.00025370340306410486,25.0,0.0
279.71826,0.043911891732283465,774.3348581414474,0.00025370340306410486,25.0,0.0
281.01953,0.04427304330708661,773.2436009457236,0.00025370340306410486,25.0,0.0
282.3208,0.04465293700787402,775.392423930921,0.00025370340306410486,25.0,0.0
283.62207,0.044993848425196846,775.8572933799342,0.00025370340306410486,25.0,0.0
284.92334,0.045344533464566926,776.8155324835526,0.00025370340306410486,25.0,0.0
286.22461,0.04565199803149606,775.4591899671053,0.00025370340306410486,25.0,0.0
287.52588,0.04608263976377953,778.2786800986843,0.00025370340306410486,25.0,0.0
288.82715,0.046490110236220475,777.7186472039474,0.00025370340306410486,25.0,0.0
290.12842,0.04692982283464567,777.6957493832236,0.00025370340306410486,25.0,0.0
291.42969,0.0473591437007874,779.5867855674342,0.00025370340306410486,25.0,0.0
292.73096,0.04785459251968504,781.0098941200658,0.00025370340306410486,25.0,0.0
294.03223,0.04820645078740157,778.6504163240132,0.00025370340306410486,25.0,0.0
295.3335,0.048522600393700786,781.0051912006579,0.00025370340306410486,25.0,0.0
296.63477,0.04894921062992126,780.6602847450658,0.00025370340306410486,25.0,0.0
297.93604,0.04933271062992126,780.6467927631578,0.00025370340306410486,25.0,0.0
299.2373,0.04969452755905512,779.5344623766448,0.00025370340306410486,25.0,0.0
300.53857,0.050040234251968504,782.1735711348684,0.00025370340306410486,25.0,0.0
301.83984,0.05049271456692913,783.5381373355264,0.00025370340306410486,25.0,0.0
303.14111,0.05089266929133858,780.9201788651317,0.00025370340306410486,25.0,0.0
304.44238,0.05125563582677165,782.8537983141447,0.00025370340306410486,25.0,0.0
305.74365,0.05163983858267716,783.5886872944079,0.00025370340306410486,25.0,0.0
307.04492,0.052107541338582676,784.0180921052632,0.00025370340306410486,25.0,0.0
308.34619,0.05254711417322835,785.6476408305921,0.00025370340306410486,25.0,0.0
309.64746,0.05292146850393701,783.6361276726974,0.00025370340306410486,25.0,0.0
310.94873,0.053297986220472444,784.8602230674342,0.00025370340306410486,25.0,0.0
312.25,0.05366408070866142,784.744474712171,0.00025370340306410486,25.0,0.0
313.55127,0.05410552952755905,786.5505499588816,0.00025370340306410486,25.0,0.0
314.85254,0.054471564960629916,785.5837530838816,0.00025370340306410486,25.0,0.0
316.15381,0.05479324803149606,785.380216899671,0.00025370340306410486,25.0,0.0
317.45508,0.05519818897637795,786.4546155427631,0.00025370340306410486,25.0,0.0
318.75635,0.055508937007874015,786.3926295230264,0.00025370340306410486,25.0,0.0
320.05762,0.05596967125984252,788.7496402138158,0.00025370340306410486,25.0,0.0
321.35889,0.05636173031496063,789.2540861430921,0.00025370340306410486,25.0,0.0
322.66016,0.05675915157480315,789.0887643914474,0.00025370340306410486,25.0,0.0
323.96143,0.05715441338582677,788.5191200657895,0.00025370340306410486,25.0,0.0
325.2627,0.05757804527559055,789.6878854851974,0.00025370340306410486,25.0,0.0
326.56396,0.057934988188976376,788.359529194079,0.00025370340306410486,25.0,0.0
327.86523,0.058329,789.4904913651316,0.00025370340306410486,25.0,0.0
329.1665,0.058744366141732285,790.7444490131579,0.00025370340306410486,25.0,0.0
330.46777,0.059136437007874014,788.2660875822369,0.00025370340306410486,25.0,0.0
331.76904,0.059509535433070866,787.6067537006579,0.00025370340306410486,25.0,0.0
333.07031,0.05991715354330709,790.0427631578947,0.00025370340306410486,25.0,0.0
334.37158,0.060302923228346454,790.9175061677631,0.00025370340306410486,25.0,0.0
335.67285,0.060709549212598427,790.8056897615132,0.00025370340306410486,25.0,0.0
336.97412,0.061029647637795274,790.5840357730264,0.00025370340306410486,25.0,0.0
338.27539,0.06145895275590551,791.5984272203948,0.00025370340306410486,25.0,0.0
339.57666,0.0619208779527559,792.753572162829,0.00025370340306410486,25.0,0.0
340.87793,0.06231242125984252,792.576505962171,0.00025370340306410486,25.0,0.0
342.1792,0.06270910236220473,793.0886101973684,0.00025370340306410486,25.0,0.0
343.48047,0.0630562283464567,792.9867907072369,0.00025370340306410486,25.0,0.0
344.78174,0.06344943700787402,793.7634662828947,0.00025370340306410486,25.0,0.0
346.08301,0.06383437992125984,794.4488589638157,0.00025370340306410486,25.0,0.0
347.38428,0.0641698031496063,795.1719520970395,0.00025370340306410486,25.0,0.0
348.68555,0.06462644094488189,795.06591796875,0.00025370340306410486,25.0,0.0
349.98682,0.06500904330708662,796.2040501644736,0.00025370340306410486,25.0,0.0
351.28809,0.06536042913385826,793.35400390625,0.00025370340306410486,25.0,0.0
352.58936,0.06570186023622047,794.1015111019736,0.00025370340306410486,25.0,0.0
353.89063,0.06606890354330709,795.61376953125,0.00025370340306410486,25.0,0.0
355.19189,0.06646653543307086,796.1818462171053,0.00025370340306410486,25.0,0.0
356.49316,0.06684225590551181,798.0049856085527,0.00025370340306410486,25.0,0.0
357.79443,0.06724171850393701,798.3149928042764,0.00025370340306410486,25.0,0.0
359.0957,0.06763037401574803,798.0973992598684,0.00025370340306410486,25.0,0.0
360.39697,0.06799884448818898,800.2823807565788,0.00025370340306410486,25.0,0.0
361.69824,0.06841073818897637,799.6462016858552,0.00025370340306410486,25.0,0.0
362.99951,0.06881495866141732,798.3679584703947,0.00025370340306410486,25.0,0.0
364.30078,0.06919865748031497,800.3829152960526,0.00025370340306410486,25.0,0.0
365.60205,0.06961401377952756,800.9037314967105,0.00025370340306410486,25.0,0.0
366.90332,0.0700257125984252,799.4227744654606,0.00025370340306410486,25.0,0.0
368.20459,0.07039162401574803,799.9164268092105,0.00025370340306410486,25.0,0.0
369.50586,0.07077672047244095,802.4719623766447,0.00025370340306410486,25.0,0.0
370.80713,0.07115190748031495,800.1846474095395,0.00025370340306410486,25.0,0.0
372.1084,0.07156357677165355,801.8171772203947,0.00025370340306410486,25.0,0.0
373.40967,0.07199969488188976,802.4757915296053,0.00025370340306410486,25.0,0.0
374.71094,0.07239601771653544,800.6363075657895,0.00025370340306410486,25.0,0.0
376.01221,0.07276993307086614,800.9410464638157,0.00025370340306410486,25.0,0.0
377.31348,0.07318953543307087,801.6316560444079,0.00025370340306410486,25.0,0.0
378.61475,0.07361253346456693,803.1137438322369,0.00025370340306410486,25.0,0.0
379.91602,0.07395678543307087,803.8247841282895,0.00025370340306410486,25.0,0.0
381.21729,0.07426246456692913,802.1955694901316,0.00025370340306410486,25.0,0.0
382.51855,0.07463154527559054,805.1348941200658,0.00025370340306410486,25.0,0.0
383.81982,0.07507639763779528,803.2628752055921,0.00025370340306410486,25.0,0.0
385.12109,0.07544804133858267,804.2345034950658,0.00025370340306410486,25.0,0.0
386.42236,0.07584993110236221,805.2527240953947,0.00025370340306410486,25.0,0.0
387.72363,0.07626689960629922,804.2233244243421,0.00025370340306410486,25.0,0.0
389.0249,0.07661021456692912,805.9641498766447,0.00025370340306410486,25.0,0.0
390.32617,0.07696147047244094,804.6635742187501,0.00025370340306410486,25.0,0.0
391.62744,0.07734850787401575,805.1998355263158,0.00025370340306410486,25.0,0.0
392.92871,0.0777615157480315,806.6834395559212,0.00025370340306410486,25.0,0.0
394.22998,0.07814989763779528,806.6494140625,0.00025370340306410486,25.0,0.0
395.53125,0.07848585826771654,805.7941252055921,0.00025370340306410486,25.0,0.0
396.83252,0.07890788385826772,808.8386615953948,0.00025370340306410486,25.0,0.0
398.13379,0.07930275984251968,808.6057771381579,0.00025370340306410486,25.0,0.0
399.43506,0.07974327165354331,809.3202097039474,0.00025370340306410486,25.0,0.0
400.73633,0.08015760433070866,808.2324475740131,0.00025370340306410486,25.0,0.0
402.0376,0.08052412598425197,808.2054893092105,0.00025370340306410486,25.0,0.0
403.33887,0.08091470669291338,809.0198139391447,0.00025370340306410486,25.0,0.0
404.64014,0.08129107874015748,807.0460012335526,0.00025370340306410486,25.0,0.0
405.94141,0.08164289960629921,808.386564555921,0.00025370340306410486,25.0,0.0
407.24268,0.08194763385826771,809.4495271381579,0.00025370340306410486,25.0,0.0
408.54395,0.0823510216535433,811.3355263157895,0.00025370340306410486,25.0,0.0
409.84521,0.08276807086614173,811.2282586348684,0.00025370340306410486,25.0,0.0
411.14648,0.08318440748031496,811.1640625,0.00025370340306410486,25.0,0.0
412.44775,0.08359415944881889,813.9253957648026,0.00025370340306410486,25.0,0.0
413.74902,0.08396750984251967,810.1478464226973,0.00025370340306410486,25.0,0.0
415.05029,0.08441190944881889,812.6750873766448,0.00025370340306410486,25.0,0.0
416.35156,0.08478260826771652,811.9022923519736,0.00025370340306410486,25.0,0.0
417.65283,0.08517137007874015,812.6489000822369,0.00025370340306410486,25.0,0.0
418.9541,0.08554009251968504,813.8213147615132,0.00025370340306410486,25.0,0.0
420.25537,0.08588903149606299,813.583830180921,0.00025370340306410486,25.0,0.0
421.55664,0.08632398228346456,812.6860608552631,0.00025370340306410486,25.0,0.0
422.85791,0.08667568897637795,815.0275236430922,0.00025370340306410486,25.0,0.0
424.15918,0.08705991141732283,813.7234272203947,0.00025370340306410486,25.0,0.0
425.46045,0.08746112204724409,816.1367958470395,0.00025370340306410486,25.0,0.0
426.76172,0.08781576968503937,814.9424342105262,0.00025370340306410486,25.0,0.0
428.06299,0.08814859842519684,813.9573910361843,0.00025370340306410486,25.0,0.0
429.36426,0.08860108464566928,815.462556537829,0.00025370340306410486,25.0,0.0
430.66553,0.08895635433070866,816.232267680921,0.00025370340306410486,25.0,0.0
431.9668,0.08925325590551181,813.0723427220395,0.00025370340306410486,25.0,0.0
433.26807,0.0895981535433071,816.0897923519738,0.00025370340306410486,25.0,0.0
434.56934,0.09003841929133859,818.8526932565788,0.00025370340306410486,25.0,0.0
435.87061,0.09046705511811023,816.7848992598684,0.00025370340306410486,25.0,0.0
437.17188,0.09081632283464566,815.5067845394738,0.00025370340306410486,25.0,0.0
438.47314,0.09117027362204724,816.6820775082238,0.00025370340306410486,25.0,0.0
439.77441,0.09151145669291338,815.7508737664474,0.00025370340306410486,25.0,0.0
441.07568,0.09191009842519686,816.985505756579,0.00025370340306410486,25.0,0.0
442.37695,0.09235648228346456,818.6625719572369,0.00025370340306410486,25.0,0.0
443.67822,0.09275555708661418,818.2095754523027,0.00025370340306410486,25.0,0.0
444.97949,0.09316452362204723,818.5028525904605,0.00025370340306410486,25.0,0.0
446.28076,0.09354804133858267,817.5565121299343,0.00025370340306410486,25.0,0.0
447.58203,0.09388815157480314,816.4962222450657,0.00025370340306410486,25.0,0.0
448.8833,0.09428625196850393,819.5894068667762,0.00025370340306410486,25.0,0.0
450.18457,0.09472691732283466,819.7572471217105,0.00025370340306410486,25.0,0.0
451.48584,0.09514020078740158,818.7497173108553,0.00025370340306410486,25.0,0.0
452.78711,0.09553109842519686,820.3795744243421,0.00025370340306410486,25.0,0.0
454.08838,0.09587114370078739,819.6129214638157,0.00025370340306410486,25.0,0.0
455.38965,0.09624743897637796,819.1276726973684,0.00025370340306410486,25.0,0.0
456.69092,0.09668600196850394,820.9496299342106,0.00025370340306410486,25.0,0.0
457.99219,0.0970525590551181,820.8226511101973,0.00025370340306410486,25.0,0.0
459.29346,0.09740727755905511,821.9784128289473,0.00025370340306410486,25.0,0.0
460.59473,0.09783075196850392,823.0844212582236,0.00025370340306410486,25.0,0.0
461.896,0.09815912992125984,821.1371813322368,0.00025370340306410486,25.0,0.0
463.19727,0.09853377559055118,824.0596988075657,0.00025370340306410486,25.0,0.0
464.49854,0.09887331102362204,822.3124486019738,0.00025370340306410486,25.0,0.0
465.7998,0.09926023622047243,823.7662417763157,0.00025370340306410486,25.0,0.0
467.10107,0.09965794488188977,821.8094675164473,0.00025370340306410486,25.0,0.0
468.40234,0.10002899606299212,821.8590152138158,0.00025370340306410486,25.0,0.0
469.70361,0.1004249094488189,822.304045024671,0.00025370340306410486,25.0,0.0
471.00488,0.10080331692913386,824.5210988898026,0.00025370340306410486,25.0,0.0
472.30615,0.10122237992125985,823.6976768092105,0.00025370340306410486,25.0,0.0
473.60742,0.10159253937007874,823.6243832236843,0.00025370340306410486,25.0,0.0
474.90869,0.1020211279527559,824.0898694490131,0.00025370340306410486,25.0,0.0
476.20996,0.10239720078740158,824.5285002055921,0.00025370340306410486,25.0,0.0
477.51123,0.10277050393700786,824.3486071134869,0.00025370340306410486,25.0,0.0
478.8125,0.1031083622047244,824.0887900904605,0.00025370340306410486,25.0,0.0
480.11377,0.10346562598425196,826.100920024671,0.00025370340306410486,25.0,0.0
481.41504,0.1039414311023622,825.9252415707236,0.00025370340306410486,25.0,0.0
482.71631,0.10435968307086614,827.7078022203948,0.00025370340306410486,25.0,0.0
484.01758,0.10477326771653542,825.9480365953948,0.00025370340306410486,25.0,0.0
485.31885,0.10515524212598426,826.3058953536184,0.00025370340306410486,25.0,0.0
486.62012,0.10550151181102363,826.6644736842105,0.00025370340306410486,25.0,0.0
487.92139,0.10586328149606299,826.8569078947369,0.00025370340306410486,25.0,0.0
489.22266,0.10628988976377952,828.504060444079,0.00025370340306410486,25.0,0.0
490.52393,0.10670631102362203,829.038420024671,0.00025370340306410486,25.0,0.0
491.8252,0.10711056692913387,827.7212428042764,0.00025370340306410486,25.0,0.0
493.12646,0.10747765157480314,829.6834909539473,0.00025370340306410486,25.0,0.0
494.42773,0.10794098425196852,828.6254625822369,0.00025370340306410486,25.0,0.0
495.729,0.10831919291338582,828.0706465871712,0.00025370340306410486,25.0,0.0
497.03027,0.1086709527559055,827.5612407483552,0.00025370340306410486,25.0,0.0
498.33154,0.10900165354330708,827.6726716694079,0.00025370340306410486,25.0,0.0
499.63281,0.10938638582677165,827.5776881167764,0.00025370340306410486,25.0,0.0
500.93408,0.10967674606299213,826.1155427631579,0.00025370340306410486,25.0,0.0
502.23535,0.10997106299212597,828.8255550986843,0.00025370340306410486,25.0,0.0
503.53662,0.1103761279527559,830.2077508223683,0.00025370340306410486,25.0,0.0
504.83789,0.11077952755905512,830.7548057154605,0.00025370340306410486,25.0,0.0
506.13916,0.11121041732283464,830.1572522615131,0.00025370340306410486,25.0,0.0
507.44043,0.11159720078740158,830.7823293585527,0.00025370340306410486,25.0,0.0
508.7417,0.11205507874015747,831.4226716694079,0.00025370340306410486,25.0,0.0
510.04297,0.11244582874015749,830.2423159950657,0.00025370340306410486,25.0,0.0
511.34424,0.11282651181102363,831.8527189555921,0.00025370340306410486,25.0,0.0
512.64551,0.11324413188976377,831.9215923108552,0.00025370340306410486,25.0,0.0
513.94678,0.11359449606299213,831.3054841694079,0.00025370340306410486,25.0,0.0
515.24805,0.11403905511811023,831.8422337582238,0.00025370340306410486,25.0,0.0
516.54932,0.11444584645669291,833.8616365131579,0.00025370340306410486,25.0,0.0
517.85059,0.11489459448818898,831.7308799342105,0.00025370340306410486,25.0,0.0
519.15186,0.11529563385826773,834.0562551398026,0.00025370340306410486,25.0,0.0
520.45313,0.1157236496062992,833.4102076480264,0.00025370340306410486,25.0,0.0
521.75439,0.11612182677165354,833.1147717927632,0.00025370340306410486,25.0,0.0
523.05566,0.11649123622047244,833.853669819079,0.00025370340306410486,25.0,0.0
524.35693,0.11684568307086614,831.7060289884869,0.00025370340306410486,25.0,0.0
525.6582,0.11717584448818899,833.5516293174342,0.00025370340306410486,25.0,0.0
526.95947,0.11760040944881889,834.2546515213816,0.00025370340306410486,25.0,0.0
528.26074,0.11798116338582677,835.0369808799343,0.00025370340306410486,25.0,0.0
529.56201,0.11841156102362205,832.9310495476973,0.00025370340306410486,25.0,0.0
530.86328,0.11883641929133858,833.7436266447368,0.00025370340306410486,25.0,0.0
532.16455,0.11918204527559054,836.10302734375,0.00025370340306410486,25.0,0.0
533.46582,0.1196139212598425,834.6262078536184,0.00025370340306410486,25.0,0.0
534.76709,0.11998139173228346,833.9264494243421,0.00025370340306410486,25.0,0.0
536.06836,0.1204061811023622,835.4971988075657,0.00025370340306410486,25.0,0.0
537.36963,0.12078825,837.0048057154605,0.00025370340306410486,25.0,0.0
538.6709,0.121109468503937,835.4844520970395,0.00025370340306410486,25.0,0.0
539.97217,0.12146286220472441,836.139982524671,0.00025370340306410486,25.0,0.0
541.27344,0.12185595866141732,836.9478310032895,0.00025370340306410486,25.0,0.0
542.57471,0.12225272834645669,836.3322111430921,0.00025370340306410486,25.0,0.0
543.87598,0.1226254094488189,837.0964740953947,0.00025370340306410486,25.0,0.0
545.17725,0.12300675000000001,835.1515984786184,0.00025370340306410486,25.0,0.0
546.47852,0.12336638582677166,838.7722553453947,0.00025370340306410486,25.0,0.0
547.77979,0.12378584645669291,837.4052220394736,0.00025370340306410486,25.0,0.0
549.08105,0.12419149803149605,839.901033100329,0.00025370340306410486,25.0,0.0
550.38232,0.12462271653543307,837.6037983141447,0.00025370340306410486,25.0,0.0
551.68359,0.12506090551181104,839.6921001233553,0.00025370340306410486,25.0,0.0
552.98486,0.1255360059055118,839.6099660773026,0.00025370340306410486,25.0,0.0
554.28613,0.1259627775590551,838.5373920641448,0.00025370340306410486,25.0,0.0
555.5874,0.12634126771653542,837.7976716694079,0.00025370340306410486,25.0,0.0
556.88867,0.12674879527559055,837.6488486842105,0.00025370340306410486,25.0,0.0
558.18994,0.12714290157480315,840.5890470805921,0.00025370340306410486,25.0,0.0
559.49121,0.1275696496062992,838.4206414473684,0.00025370340306410486,25.0,0.0
560.79248,0.1279663031496063,838.9299701891448,0.00025370340306410486,25.0,0.0
562.09375,0.12831496653543306,839.6793020148026,0.00025370340306410486,25.0,0.0
563.39502,0.1287403188976378,839.0017475328947,0.00025370340306410486,25.0,0.0
564.69629,0.1291026751968504,840.5796412417762,0.00025370340306410486,25.0,0.0
565.99756,0.1295103562992126,838.3427220394738,0.00025370340306410486,25.0,0.0
567.29883,0.12988967913385827,839.1365131578948,0.00025370340306410486,25.0,0.0
568.6001,0.13027008070866142,841.0103053042762,0.00025370340306410486,25.0,0.0
569.90137,0.13062909448818896,840.2163856907895,0.00025370340306410486,25.0,0.0
571.20264,0.1310240098425197,840.1442742598684,0.00025370340306410486,25.0,0.0
572.50391,0.1314324192913386,840.4065326891447,0.00025370340306410486,25.0,0.0
573.80518,0.13189376771653544,842.1126901726974,0.00025370340306410486,25.0,0.0
575.10645,0.13232156102362205,841.900056537829,0.00025370340306410486,25.0,0.0
576.40771,0.13273738582677166,841.1051089638157,0.00025370340306410486,25.0,0.0
577.70898,0.13312563582677164,841.792634662829,0.00025370340306410486,25.0,0.0
579.01025,0.13354289173228345,841.5845754523027,0.00025370340306410486,25.0,0.0
580.31152,0.1338895492125984,842.478515625,0.00025370340306410486,25.0,0.0
581.61279,0.13428344488188976,842.4051706414474,0.00025370340306410486,25.0,0.0
582.91406,0.13470897244094487,843.3875925164474,0.00025370340306410486,25.0,0.0
584.21533,0.13508755708661419,843.709138569079,0.00025370340306410486,25.0,0.0
585.5166,0.13546025,842.1322471217106,0.00025370340306410486,25.0,0.0
586.81787,0.1358931692913386,844.7105520148026,0.00025370340306410486,25.0,0.0
588.11914,0.13634709251968505,843.567716899671,0.00025370340306410486,25.0,0.0
589.42041,0.13672200196850393,843.7959755345395,0.00025370340306410486,25.0,0.0
590.72168,0.13713109251968505,843.8076428865132,0.00025370340306410486,25.0,0.0
592.02295,0.13753251968503938,843.5698499177631,0.00025370340306410486,25.0,0.0
593.32422,0.13799364566929134,845.0782277960526,0.00025370340306410486,25.0,0.0
594.62549,0.13846202362204726,845.3606856496712,0.00025370340306410486,25.0,0.0
595.92676,0.13887883464566927,844.0352847450658,0.00025370340306410486,25.0,0.0
597.22803,0.1393024842519685,844.6990902549342,0.00025370340306410486,25.0,0.0
598.5293,0.13968524409448818,844.3369397615132,0.00025370340306410486,25.0,0.0
599.83057,0.14010267716535432,845.1940532483553,0.00025370340306410486,25.0,0.0
601.13184,0.14044607283464566,842.8033511513158,0.00025370340306410486,25.0,0.0
602.43311,0.1408484744094488,844.81591796875,0.00025370340306410486,25.0,0.0
603.73438,0.14123962401574802,845.1061626233553,0.00025370340306410486,25.0,0.0
605.03564,0.1416585216535433,845.2766755756579,0.00025370340306410486,25.0,0.0
606.33691,0.1420911377952756,846.1741365131578,0.00025370340306410486,25.0,0.0
607.63818,0.14245114763779526,843.8552117598683,0.00025370340306410486,25.0,0.0
608.93945,0.14284622637795275,844.763826069079,0.00025370340306410486,25.0,0.0
610.24072,0.14323962992125985,847.8802682976973,0.00025370340306410486,25.0,0.0
611.54199,0.1436667874015748,846.9506321957238,0.00025370340306410486,25.0,0.0
612.84326,0.1441293937007874,847.4309210526316,0.00025370340306410486,25.0,0.0
614.14453,0.14455088385826773,845.6939761513158,0.00025370340306410486,25.0,0.0
615.4458,0.14495731102362205,846.7685546875,0.00025370340306410486,25.0,0.0
616.74707,0.14536065157480313,846.9256527549342,0.00025370340306410486,25.0,0.0
618.04834,0.14582079133858267,847.9506064967105,0.00025370340306410486,25.0,0.0
619.34961,0.14624759842519686,845.7355828536184,0.00025370340306410486,25.0,0.0
620.65088,0.14667459448818898,847.8204923930921,0.00025370340306410486,25.0,0.0
621.95215,0.14710446259842522,848.0023129111842,0.00025370340306410486,25.0,0.0
623.25342,0.14758163976377953,849.6773231907895,0.00025370340306410486,25.0,0.0
624.55469,0.1481645098425197,848.236970600329,0.00025370340306410486,25.0,0.0
625.85596,0.1486157342519685,846.2805561266447,0.00025370340306410486,25.0,0.0
627.15723,0.14898803937007873,849.0869911595395,0.00025370340306410486,25.0,0.0
628.4585,0.14936242322834645,846.859220805921,0.00025370340306410486,25.0,0.0
629.75977,0.14978554527559054,848.5496761924342,0.00025370340306410486,25.0,0.0
631.06104,0.1502230531496063,848.3337016858552,0.00025370340306410486,25.0,0.0
632.3623,0.15065939960629923,848.5525544819079,0.00025370340306410486,25.0,0.0
633.66357,0.15109214173228347,847.6455592105264,0.00025370340306410486,25.0,0.0
634.96484,0.1514372972440945,848.3591951069079,0.00025370340306410486,25.0,0.0
636.26611,0.1518654901574803,849.1023077713816,0.00025370340306410486,25.0,0.0
637.56738,0.15228571456692913,847.1705386513158,0.00025370340306410486,25.0,0.0
638.86865,0.15272312795275592,848.9816509046053,0.00025370340306410486,25.0,0.0
640.16992,0.15314291732283464,849.1097604851973,0.00025370340306410486,25.0,0.0
641.47119,0.15356161614173228,849.7108861019736,0.00025370340306410486,25.0,0.0
642.77246,0.15404632677165356,850.5702097039474,0.00025370340306410486,25.0,0.0
644.07373,0.15448425787401573,849.7529810855262,0.00025370340306410486,25.0,0.0
645.375,0.15486539763779528,849.1698704769736,0.00025370340306410486,25.0,0.0
646.67627,0.15530918307086614,849.3301809210526,0.00025370340306410486,25.0,0.0
647.97754,0.1558097086614173,851.0620374177631,0.00025370340306410486,25.0,0.0
649.27881,0.15626636614173228,850.0509611430921,0.00025370340306410486,25.0,0.0
650.58008,0.15666849803149605,850.1436317845395,0.00025370340306410486,25.0,0.0
651.88135,0.15708523622047244,850.1687140213816,0.00025370340306410486,25.0,0.0
653.18262,0.15748716929133857,850.7923005756579,0.00025370340306410486,25.0,0.0
654.48389,0.15786139960629922,850.4543842516448,0.00025370340306410486,25.0,0.0
655.78516,0.15825425,851.5064247532895,0.00025370340306410486,25.0,0.0
657.08643,0.1586964153543307,851.8207750822369,0.00025370340306410486,25.0,0.0
658.3877,0.15926330511811024,851.7328587582238,0.00025370340306410486,25.0,0.0
659.68896,0.1597614625984252,852.7316509046052,0.00025370340306410486,25.0,0.0
660.99023,0.16027480118110235,851.1573293585526,0.00025370340306410486,25.0,0.0
662.2915,0.1606188307086614,849.5546104029605,0.00025370340306410486,25.0,0.0
663.59277,0.16105206692913387,851.9798776726974,0.00025370340306410486,25.0,0.0
664.89404,0.16149335236220472,852.5767372532895,0.00025370340306410486,25.0,0.0
666.19531,0.16199008858267716,853.5071957236842,0.00025370340306410486,25.0,0.0
667.49658,0.16246218700787401,851.6322985197369,0.00025370340306410486,25.0,0.0
668.79785,0.1628927125984252,852.1690481085526,0.00025370340306410486,25.0,0.0
670.09912,0.16333643897637795,852.1516755756579,0.00025370340306410486,25.0,0.0
671.40039,0.16379655511811023,852.4544613486842,0.00025370340306410486,25.0,0.0
672.70166,0.16425998228346456,852.4931640625,0.00025370340306410486,25.0,0.0
674.00293,0.16467949015748032,852.4991262335526,0.00025370340306410486,25.0,0.0
675.3042,0.16516322637795275,854.3135022615132,0.00025370340306410486,25.0,0.0
676.60547,0.16567321062992127,853.4686215049342,0.00025370340306410486,25.0,0.0
677.90674,0.1661476771653543,853.240234375,0.00025370340306410486,25.0,0.0
679.20801,0.1666009311023622,851.4620682565788,0.00025370340306410486,25.0,0.0
680.50928,0.16698007677165355,851.8651829769736,0.00025370340306410486,25.0,0.0
681.81055,0.1674164468503937,853.1691509046052,0.00025370340306410486,25.0,0.0
683.11182,0.16785999606299212,852.4375770970395,0.00025370340306410486,25.0,0.0
684.41309,0.168310187007874,854.7199321546052,0.00025370340306410486,25.0,0.0
685.71436,0.16880449606299214,854.10400390625,0.00025370340306410486,25.0,0.0
687.01563,0.16927973818897638,854.1166735197368,0.00025370340306410486,25.0,0.0
688.31689,0.1696971811023622,852.9472913240131,0.00025370340306410486,25.0,0.0
689.61816,0.17014470866141732,853.9693667763158,0.00025370340306410486,25.0,0.0
690.91943,0.1705920374015748,852.6040296052631,0.00025370340306410486,25.0,0.0
692.2207,0.17106406299212598,853.79248046875,0.00025370340306410486,25.0,0.0
693.52197,0.17152926181102363,854.3733552631579,0.00025370340306410486,25.0,0.0
694.82324,0.17203009251968504,853.4580078125,0.00025370340306410486,25.0,0.0
696.12451,0.17250818503937007,852.3526932565788,0.00025370340306410486,25.0,0.0
697.42578,0.17306553543307088,853.6887078536184,0.00025370340306410486,25.0,0.0
698.72705,0.17351891732283464,855.1225585937501,0.00025370340306410486,25.0,0.0
700.02832,0.17397464763779527,853.4055561266447,0.00025370340306410486,25.0,0.0
701.32959,0.17441240157480314,854.0219469572369,0.00025370340306410486,25.0,0.0
702.63086,0.1748658779527559,855.3922697368421,0.00025370340306410486,25.0,0.0
703.93213,0.17541916732283466,854.7715100740131,0.00025370340306410486,25.0,0.0
705.2334,0.17584891929133858,854.4869192023026,0.00025370340306410486,25.0,0.0
706.53467,0.17631729724409448,856.8295127467105,0.00025370340306410486,25.0,0.0
707.83594,0.17675327952755904,855.372892680921,0.00025370340306410486,25.0,0.0
709.13721,0.17725813582677166,853.3467053865131,0.00025370340306410486,25.0,0.0
710.43848,0.1777919251968504,856.0308131167762,0.00025370340306410486,25.0,0.0
711.73975,0.1782625787401575,855.7130705180921,0.00025370340306410486,25.0,0.0
713.04102,0.17871449606299214,854.1028217516447,0.00025370340306410486,25.0,0.0
714.34229,0.17911754330708662,854.4416118421052,0.00025370340306410486,25.0,0.0
715.64355,0.1795264212598425,855.23291015625,0.00025370340306410486,25.0,0.0
716.94482,0.18004214173228347,855.377595600329,0.00025370340306410486,25.0,0.0
718.24609,0.1805328838582677,855.4428453947369,0.00025370340306410486,25.0,0.0
719.54736,0.18096844291338582,854.8650030838816,0.00025370340306410486,25.0,0.0
720.84863,0.1813876338582677,854.273103412829,0.00025370340306410486,25.0,0.0
722.1499,0.18192077952755906,856.1518297697369,0.00025370340306410486,25.0,0.0
723.45117,0.18243127952755905,855.734220805921,0.00025370340306410486,25.0,0.0
724.75244,0.1829809212598425,856.3947111430921,0.00025370340306410486,25.0,0.0
726.05371,0.1835134311023622,856.1168791118421,0.00025370340306410486,25.0,0.0
727.35498,0.18397549803149604,854.8556486430921,0.00025370340306410486,25.0,0.0
728.65625,0.18443331496062992,855.806306537829,0.00025370340306410486,25.0,0.0
729.95752,0.18484256889763778,856.6906609786184,0.00025370340306410486,25.0,0.0
731.25879,0.18541074803149607,857.0703638980264,0.00025370340306410486,25.0,0.0
732.56006,0.1859837972440945,857.3414113898026,0.00025370340306410486,25.0,0.0
733.86133,0.1865157342519685,855.7740028782895,0.00025370340306410486,25.0,0.0
735.1626,0.1870204153543307,855.4351356907895,0.00025370340306410486,25.0,0.0
736.46387,0.18755209251968505,856.5351819490132,0.00025370340306410486,25.0,0.0
737.76514,0.18811403149606298,856.4116467927631,0.00025370340306410486,25.0,0.0
739.06641,0.1886897440944882,859.0185546875,0.00025370340306410486,25.0,0.0
740.36768,0.1891651968503937,855.7122738486843,0.00025370340306410486,25.0,0.0
741.66895,0.18965566732283465,856.1012541118421,0.00025370340306410486,25.0,0.0
742.97021,0.190198281496063,856.5724455180921,0.00025370340306410486,25.0,0.0
744.27148,0.1906614251968504,855.8090049342105,0.00025370340306410486,25.0,0.0
745.57275,0.19112777362204725,856.4742495888157,0.00025370340306410486,25.0,0.0
746.87402,0.1915676161417323,855.4861996299343,0.00025370340306410486,25.0,0.0
748.17529,0.19208463779527557,857.3697060032895,0.00025370340306410486,25.0,0.0
749.47656,0.19255383661417322,856.2397974917762,0.00025370340306410486,25.0,0.0
750.77783,0.19298374212598424,856.2214740953947,0.00025370340306410486,25.0,0.0
752.0791,0.19351891732283463,857.71630859375,0.00025370340306410486,25.0,0.0
753.38037,0.19412708267716536,855.0846011513157,0.00025370340306410486,25.0,0.0
754.68164,0.19467447244094488,856.7852847450658,0.00025370340306410486,25.0,0.0
755.98291,0.1951828248031496,855.471345600329,0.00025370340306410486,25.0,0.0
757.28418,0.19565561417322835,855.743498149671,0.00025370340306410486,25.0,0.0
758.58545,0.19621588582677163,857.9976870888158,0.00025370340306410486,25.0,0.0
759.88672,0.19675653937007875,857.3357576069078,0.00025370340306410486,25.0,0.0
761.18799,0.19723366141732282,855.5134405838816,0.00025370340306410486,25.0,0.0
762.48926,0.19776265748031496,857.5682308799343,0.00025370340306410486,25.0,0.0
763.79053,0.1983475,856.0565378289474,0.00025370340306410486,25.0,0.0
765.0918,0.19891740157480314,855.1764494243421,0.00025370340306410486,25.0,0.0
766.39307,0.19944911417322836,857.1845703125,0.00025370340306410486,25.0,0.0
766.99365,0.1997827559055118,859.0298622532895,0.00025370340306410486,25.0,0.0