File: datasets/am_bench_2022/csv/0-XY.10-1.csv
Time(s),Strain(%),Stress(MPa),SR(s-1),Temp(C),Angle(deg)
41.661377,2.2473811023622046e-05,17.869231684602646,0.00025370340306410486,25.0,0.0
44.063721,3.7380635826771657e-05,26.25052514486755,0.00025370340306410486,25.0,0.0
45.36499,1.8836593503937007e-05,30.568385244205295,0.00025370340306410486,25.0,0.0
46.66626,6.251325787401575e-05,34.27461713576159,0.00025370340306410486,25.0,0.0
47.967529,8.166652755905512e-05,39.59803394039734,0.00025370340306410486,25.0,0.0
49.268799,6.920125393700787e-05,46.5331255173841,0.00025370340306410486,25.0,0.0
50.570068,0.00010745254527559054,52.79280060016556,0.00025370340306410486,25.0,0.0
51.871338,0.00014502381496062992,57.05481425910595,0.00025370340306410486,25.0,0.0
53.172607,0.00018786901771653542,62.77606063741721,0.00025370340306410486,25.0,0.0
54.473877,0.0002080761811023622,70.72402990480131,0.00025370340306410486,25.0,0.0
55.775146,0.0001886708405511811,77.09624637831126,0.00025370340306410486,25.0,0.0
57.076416,0.0002038785433070866,83.49421823261589,0.00025370340306410486,25.0,0.0
58.377686,0.0002428905118110236,89.47303652731787,0.00025370340306410486,25.0,0.0
59.678955,0.00025099883858267715,97.54878673427152,0.00025370340306410486,25.0,0.0
60.980225,0.0002878086220472441,105.9562241307947,0.00025370340306410486,25.0,0.0
62.281494,0.0003116473622047244,110.78451728062913,0.00025370340306410486,25.0,0.0
63.582764,0.00032303009842519684,118.07444122516556,0.00025370340306410486,25.0,0.0
64.884033,0.00035917279527559055,124.4159638865894,0.00025370340306410486,25.0,0.0
66.185303,0.0003737198622047244,132.74762779387416,0.00025370340306410486,25.0,0.0
67.486572,0.00039750474409448814,141.00524886175495,0.00025370340306410486,25.0,0.0
68.787842,0.00041531230314960626,149.6211118584437,0.00025370340306410486,25.0,0.0
70.089111,0.00045947216535433065,158.26225165562911,0.00025370340306410486,25.0,0.0
71.390381,0.0004951276181102362,165.04365169701987,0.00025370340306410486,25.0,0.0
72.69165,0.0005624439960629921,174.9211118584437,0.00025370340306410486,25.0,0.0
73.99292,0.0005387986614173229,183.88081798427152,0.00025370340306410486,25.0,0.0
75.294189,0.0005610212401574803,191.35762624172185,0.00025370340306410486,25.0,0.0
76.595459,0.0006162095275590551,199.42883640314568,0.00025370340306410486,25.0,0.0
77.896729,0.0006778463976377953,208.38457936672185,0.00025370340306410486,25.0,0.0
79.197998,0.0006867581299212598,218.52103166390725,0.00025370340306410486,25.0,0.0
80.499268,0.0007094855314960629,227.97887779387418,0.00025370340306410486,25.0,0.0
81.800537,0.0007468654330708662,238.93844163907283,0.00025370340306410486,25.0,0.0
83.101807,0.0008070163976377952,246.49163648592716,0.00025370340306410486,25.0,0.0
84.403076,0.000818347559055118,255.14452607615894,0.00025370340306410486,25.0,0.0
85.704346,0.0008602157283464567,265.6649937913907,0.00025370340306410486,25.0,0.0
87.005615,0.0008832842913385826,274.29550393211923,0.00025370340306410486,25.0,0.0
88.306885,0.0009306863188976378,281.97317363410593,0.00025370340306410486,25.0,0.0
89.608154,0.0009667222834645669,293.5043201572848,0.00025370340306410486,25.0,0.0
90.909424,0.0010103467519685038,302.3003673427152,0.00025370340306410486,25.0,0.0
92.210693,0.0010424988385826772,311.3033681705298,0.00025370340306410486,25.0,0.0
93.511963,0.0011021070669291338,320.42658319536423,0.00025370340306410486,25.0,0.0
94.813232,0.0011213825,330.67058153973505,0.00025370340306410486,25.0,0.0
96.114502,0.0011376801968503937,339.00558774834434,0.00025370340306410486,25.0,0.0
97.415771,0.0012062259055118112,348.6925444950331,0.00025370340306410486,25.0,0.0
98.717041,0.0012391726181102361,356.6743325745033,0.00025370340306410486,25.0,0.0
100.01831,0.001279308877952756,369.1026748758278,0.00025370340306410486,25.0,0.0
101.31958,0.0013010894488188977,378.7764124586093,0.00025370340306410486,25.0,0.0
102.62085,0.001342976968503937,387.1922340645695,0.00025370340306410486,25.0,0.0
103.92212,0.001406269035433071,396.5896626655629,0.00025370340306410486,25.0,0.0
105.22339,0.001415988248031496,403.208247102649,0.00025370340306410486,25.0,0.0
106.52466,0.0014595699212598425,412.7200951986755,0.00025370340306410486,25.0,0.0
107.82593,0.0014946726377952756,422.77995653973505,0.00025370340306410486,25.0,0.0
109.1272,0.001548246968503937,431.3028766556291,0.00025370340306410486,25.0,0.0
110.42847,0.0015995021653543307,441.2254242549669,0.00025370340306410486,25.0,0.0
111.72974,0.0016066403346456691,448.6056498344371,0.00025370340306410486,25.0,0.0
113.03101,0.001653040374015748,456.7329521937086,0.00025370340306410486,25.0,0.0
114.33228,0.0016939591732283465,466.243662044702,0.00025370340306410486,25.0,0.0
115.63354,0.0017254338385826772,474.68631001655626,0.00025370340306410486,25.0,0.0
116.93481,0.001796042933070866,486.14259105960264,0.00025370340306410486,25.0,0.0
118.23608,0.001825018622047244,493.2578383692053,0.00025370340306410486,25.0,0.0
119.53735,0.001838942066929134,499.9354045943709,0.00025370340306410486,25.0,0.0
120.83862,0.0018758229921259843,507.8505794701987,0.00025370340306410486,25.0,0.0
122.13989,0.0019479251377952755,516.7102390314569,0.00025370340306410486,25.0,0.0
123.44116,0.001974400984251969,522.4122775248344,0.00025370340306410486,25.0,0.0
124.74243,0.002038923228346457,530.7127483443709,0.00025370340306410486,25.0,0.0
126.0437,0.002066475787401575,538.0619826158941,0.00025370340306410486,25.0,0.0
127.34497,0.0020895872047244097,543.0128052566224,0.00025370340306410486,25.0,0.0
128.64624,0.0021449312992125984,549.4108288493377,0.00025370340306410486,25.0,0.0
129.94751,0.0022015635826771653,557.75390625,0.00025370340306410486,25.0,0.0
131.24878,0.0022448498031496064,564.6716939155629,0.00025370340306410486,25.0,0.0
132.55005,0.0022913265748031497,570.7274161837748,0.00025370340306410486,25.0,0.0
133.85132,0.0023634474409448816,576.7793874172185,0.00025370340306410486,25.0,0.0
135.15259,0.00237398937007874,583.0808412665563,0.00025370340306410486,25.0,0.0
136.45386,0.002463421062992126,590.3309188741722,0.00025370340306410486,25.0,0.0
137.75513,0.002506970275590551,595.0536268625829,0.00025370340306410486,25.0,0.0
139.0564,0.0025683990157480316,598.0889641970198,0.00025370340306410486,25.0,0.0
140.35767,0.002618072244094488,606.1861548013245,0.00025370340306410486,25.0,0.0
141.65894,0.002662073228346457,610.2789993791391,0.00025370340306410486,25.0,0.0
142.96021,0.002751895275590551,613.0904904801324,0.00025370340306410486,25.0,0.0
144.26147,0.0027703246062992124,618.5886537665563,0.00025370340306410486,25.0,0.0
145.56274,0.002849059842519685,622.5757709023179,0.00025370340306410486,25.0,0.0
146.86401,0.00289046594488189,625.6265262831125,0.00025370340306410486,25.0,0.0
148.16528,0.0029940330708661416,630.7572175082781,0.00025370340306410486,25.0,0.0
149.46655,0.003054302559055118,635.0814621274834,0.00025370340306410486,25.0,0.0
150.76782,0.0030986807086614172,637.4525817466887,0.00025370340306410486,25.0,0.0
152.06909,0.003199365551181102,643.6445312499999,0.00025370340306410486,25.0,0.0
153.37036,0.0032589242125984253,645.760425289735,0.00025370340306410486,25.0,0.0
154.67163,0.0033426204724409446,648.7128259519867,0.00025370340306410486,25.0,0.0
155.9729,0.0034465748031496063,653.069355339404,0.00025370340306410486,25.0,0.0
157.27417,0.0035452480314960627,656.172651076159,0.00025370340306410486,25.0,0.0
158.57544,0.0036596330708661413,660.4440449089403,0.00025370340306410486,25.0,0.0
159.87671,0.003739541338582677,662.7028404387416,0.00025370340306410486,25.0,0.0
161.17798,0.003867462598425197,666.9252897350993,0.00025370340306410486,25.0,0.0
162.47925,0.003953989763779528,668.5289217715232,0.00025370340306410486,25.0,0.0
163.78052,0.0041057620078740155,671.6260088990066,0.00025370340306410486,25.0,0.0
165.08179,0.0042075167322834645,676.3852442052979,0.00025370340306410486,25.0,0.0
166.38306,0.00431440905511811,678.026386589404,0.00025370340306410486,25.0,0.0
167.68433,0.0044752986220472435,678.3155784354304,0.00025370340306410486,25.0,0.0
168.9856,0.0046238618110236215,681.414321192053,0.00025370340306410486,25.0,0.0
170.28687,0.0047919017716535435,685.5620343543046,0.00025370340306410486,25.0,0.0
171.58813,0.004927687795275591,687.2258640314569,0.00025370340306410486,25.0,0.0
172.8894,0.005102348622047244,688.2832936672185,0.00025370340306410486,25.0,0.0
174.19067,0.005271286220472441,691.3768625827814,0.00025370340306410486,25.0,0.0
175.49194,0.005457019291338582,691.3730856788079,0.00025370340306410486,25.0,0.0
176.79321,0.005676708464566929,695.7705401490066,0.00025370340306410486,25.0,0.0
178.09448,0.005870859055118111,696.4348872102648,0.00025370340306410486,25.0,0.0
179.39575,0.006100723818897638,699.8732150248344,0.00025370340306410486,25.0,0.0
180.69702,0.006286776377952756,700.4175807119206,0.00025370340306410486,25.0,0.0
181.99829,0.006511506102362205,702.7652628311257,0.00025370340306410486,25.0,0.0
183.29956,0.0067891090551181095,703.1872671771522,0.00025370340306410486,25.0,0.0
184.60083,0.006999635629921259,705.561284147351,0.00025370340306410486,25.0,0.0
185.9021,0.007234839370078741,705.7457833195364,0.00025370340306410486,25.0,0.0
187.20337,0.007460030905511812,709.9574192880794,0.00025370340306410486,25.0,0.0
188.50464,0.007746926771653543,711.1439362582781,0.00025370340306410486,25.0,0.0
189.80591,0.008024182086614174,712.5646730132449,0.00025370340306410486,25.0,0.0
191.10718,0.008282831692913386,713.7155163493378,0.00025370340306410486,25.0,0.0
192.40845,0.008601173228346456,715.0612065397352,0.00025370340306410486,25.0,0.0
193.70972,0.00894965275590551,716.7369101821191,0.00025370340306410486,25.0,0.0
195.01099,0.009253858661417322,715.6429014900663,0.00025370340306410486,25.0,0.0
196.31226,0.009476751377952756,717.3204159768211,0.00025370340306410486,25.0,0.0
197.61353,0.009789532677165353,721.079780629139,0.00025370340306410486,25.0,0.0
198.91479,0.010082806102362203,721.8682998758278,0.00025370340306410486,25.0,0.0
200.21606,0.010402308464566929,721.9454677152318,0.00025370340306410486,25.0,0.0
201.51733,0.010703737204724409,723.4041545943708,0.00025370340306410486,25.0,0.0
202.8186,0.010993949212598424,723.1563793460265,0.00025370340306410486,25.0,0.0
204.11987,0.011309316141732282,723.2845353890729,0.00025370340306410486,25.0,0.0
205.42114,0.011579751771653542,724.6261123758278,0.00025370340306410486,25.0,0.0
206.72241,0.01193491122047244,726.2850786423841,0.00025370340306410486,25.0,0.0
208.02368,0.012311600393700786,726.6363565811257,0.00025370340306410486,25.0,0.0
209.32495,0.012621497637795274,727.3017901490066,0.00025370340306410486,25.0,0.0
210.62622,0.012929964960629921,728.127949089404,0.00025370340306410486,25.0,0.0
211.92749,0.013315648228346456,730.8375672599337,0.00025370340306410486,25.0,0.0
213.22876,0.013629744488188976,731.0328021523178,0.00025370340306410486,25.0,0.0
214.53003,0.014031165157480317,731.2287096440398,0.00025370340306410486,25.0,0.0
215.8313,0.014464812401574803,734.2978321605959,0.00025370340306410486,25.0,0.0
217.13257,0.014813389566929134,731.8279956539734,0.00025370340306410486,25.0,0.0
218.43384,0.015173663188976377,734.6670633278146,0.00025370340306410486,25.0,0.0
219.73511,0.01551475472440945,734.591318294702,0.00025370340306410486,25.0,0.0
221.03638,0.015868768700787402,733.2321761175497,0.00025370340306410486,25.0,0.0
222.33765,0.016154427952755904,735.8015573261589,0.00025370340306410486,25.0,0.0
223.63892,0.016526352755905513,736.9942570364238,0.00025370340306410486,25.0,0.0
224.94019,0.01692944251968504,737.5286372102648,0.00025370340306410486,25.0,0.0
226.24146,0.0173104281496063,738.4530215231788,0.00025370340306410486,25.0,0.0
227.54272,0.01767505039370079,736.6094008692053,0.00025370340306410486,25.0,0.0
228.84399,0.018020236811023622,739.3475010347681,0.00025370340306410486,25.0,0.0
230.14526,0.018385444291338583,739.4813483029801,0.00025370340306410486,25.0,0.0
231.44653,0.018707272637795275,740.1371067880794,0.00025370340306410486,25.0,0.0
232.7478,0.01904289783464567,740.4102597268211,0.00025370340306410486,25.0,0.0
234.04907,0.019468549015748033,742.5109168046357,0.00025370340306410486,25.0,0.0
235.35034,0.01985930905511811,742.7558464403974,0.00025370340306410486,25.0,0.0
236.65161,0.020264838582677167,743.2830349751655,0.00025370340306410486,25.0,0.0
237.95288,0.02067775590551181,743.8216835678808,0.00025370340306410486,25.0,0.0
239.25415,0.021089492125984252,743.7970043460265,0.00025370340306410486,25.0,0.0
240.55542,0.02145473031496063,742.7831384519867,0.00025370340306410486,25.0,0.0
241.85669,0.02181458464566929,744.9226510761589,0.00025370340306410486,25.0,0.0
243.15796,0.02221671653543307,745.6124534354304,0.00025370340306410486,25.0,0.0
244.45923,0.022512639763779527,745.6372102649007,0.00025370340306410486,25.0,0.0
245.7605,0.022880917322834645,745.6606995033112,0.00025370340306410486,25.0,0.0
247.06177,0.02328479527559055,747.2486030629138,0.00025370340306410486,25.0,0.0
248.36304,0.023710068897637795,747.6704263245033,0.00025370340306410486,25.0,0.0
249.66431,0.024082962598425198,747.0406922599337,0.00025370340306410486,25.0,0.0
250.96558,0.024440948818897638,748.0792373758277,0.00025370340306410486,25.0,0.0
252.26685,0.024809108267716536,749.2304170115895,0.00025370340306410486,25.0,0.0
253.56812,0.02520727559055118,748.8560896109271,0.00025370340306410486,25.0,0.0
254.86938,0.025615633858267716,748.6630018625827,0.00025370340306410486,25.0,0.0
256.17065,0.02601549212598425,750.7063327814569,0.00025370340306410486,25.0,0.0
257.47192,0.02642316338582677,753.0240066225165,0.00025370340306410486,25.0,0.0
258.77319,0.026866661417322833,752.1360202814569,0.00025370340306410486,25.0,0.0
260.07446,0.02723898622047244,751.9456746688742,0.00025370340306410486,25.0,0.0
261.37573,0.027657866141732285,753.2908474751655,0.00025370340306410486,25.0,0.0
262.677,0.028052342519685036,752.946709437086,0.00025370340306410486,25.0,0.0
263.97827,0.02846944291338583,753.4629035596026,0.00025370340306410486,25.0,0.0
265.27954,0.028866127952755904,753.460678807947,0.00025370340306410486,25.0,0.0
266.58081,0.029250070866141734,755.15234375,0.00025370340306410486,25.0,0.0
267.88208,0.02958161220472441,753.9669650248344,0.00025370340306410486,25.0,0.0
269.18335,0.02997641338582677,753.7010554635762,0.00025370340306410486,25.0,0.0
270.48462,0.030366562992125982,755.6228011175497,0.00025370340306410486,25.0,0.0
271.78589,0.030830667322834647,757.3989807533112,0.00025370340306410486,25.0,0.0
273.08716,0.031239179133858264,755.2417735927152,0.00025370340306410486,25.0,0.0
274.38843,0.031538885826771654,756.2066949503311,0.00025370340306410486,25.0,0.0
275.6897,0.031903141732283466,758.1105649834437,0.00025370340306410486,25.0,0.0
276.99097,0.03224575196850394,758.9152524834437,0.00025370340306410486,25.0,0.0
278.29224,0.03268512598425197,758.0465387003311,0.00025370340306410486,25.0,0.0
279.59351,0.033123805118110236,758.5393470612582,0.00025370340306410486,25.0,0.0
280.89478,0.03351385236220473,760.7316069950331,0.00025370340306410486,25.0,0.0
282.19604,0.03382961614173228,758.830556705298,0.00025370340306410486,25.0,0.0
283.49731,0.03422246456692913,760.4695519453642,0.00025370340306410486,25.0,0.0
284.79858,0.034643742125984256,759.733521316225,0.00025370340306410486,25.0,0.0
286.09985,0.03509136417322834,761.7904335678808,0.00025370340306410486,25.0,0.0
287.40112,0.03543716929133858,760.3457677980132,0.00025370340306410486,25.0,0.0
288.70239,0.0358520531496063,762.7094370860927,0.00025370340306410486,25.0,0.0
290.00366,0.03629617519685039,762.8185792632449,0.00025370340306410486,25.0,0.0
291.30493,0.03670500984251968,764.5786423841058,0.00025370340306410486,25.0,0.0
292.6062,0.03710182283464567,764.7106270695364,0.00025370340306410486,25.0,0.0
293.90747,0.037531114173228346,765.4058619619204,0.00025370340306410486,25.0,0.0
295.20874,0.03793343503937008,763.2667373758278,0.00025370340306410486,25.0,0.0
296.51001,0.03829331496062992,764.0488151903972,0.00025370340306410486,25.0,0.0
297.81128,0.038698206692913385,764.5757967715231,0.00025370340306410486,25.0,0.0
299.11255,0.03909692716535433,765.6272247516556,0.00025370340306410486,25.0,0.0
300.41382,0.039536990157480315,765.3125776076158,0.00025370340306410486,25.0,0.0
301.71509,0.0399153031496063,765.098354718543,0.00025370340306410486,25.0,0.0
303.01636,0.04023018503937008,765.8594526076158,0.00025370340306410486,25.0,0.0
304.31763,0.04065184645669291,767.7884675082781,0.00025370340306410486,25.0,0.0
305.6189,0.04106500393700788,767.8638762417219,0.00025370340306410486,25.0,0.0
306.92017,0.041472173228346454,768.1940707781456,0.00025370340306410486,25.0,0.0
308.22144,0.04185876771653543,768.8706022350993,0.00025370340306410486,25.0,0.0
309.52271,0.04228487204724409,769.1031663907285,0.00025370340306410486,25.0,0.0
310.82397,0.04261457874015748,768.8114393625827,0.00025370340306410486,25.0,0.0
312.12524,0.0429745,767.6958816225165,0.00025370340306410486,25.0,0.0
313.42651,0.04331103543307086,769.8518987996688,0.00025370340306410486,25.0,0.0
314.72778,0.04366727755905512,770.4663959023178,0.00025370340306410486,25.0,0.0
316.02905,0.04405233267716536,771.0110202814569,0.00025370340306410486,25.0,0.0
317.33032,0.0444116968503937,769.9827452400662,0.00025370340306410486,25.0,0.0
318.63159,0.04481898425196851,770.8929014900662,0.00025370340306410486,25.0,0.0
319.93286,0.04525737007874016,771.851381415563,0.00025370340306410486,25.0,0.0
321.23413,0.04564837204724409,770.9931446605959,0.00025370340306410486,25.0,0.0
322.5354,0.045999555118110234,772.3707315811258,0.00025370340306410486,25.0,0.0
323.83667,0.046364364173228347,774.4182791804635,0.00025370340306410486,25.0,0.0
325.13794,0.04679595472440945,774.5892487582781,0.00025370340306410486,25.0,0.0
326.43921,0.047266551181102366,772.4559188741722,0.00025370340306410486,25.0,0.0
327.74048,0.04761220275590551,772.7958919701987,0.00025370340306410486,25.0,0.0
329.04175,0.04794324212598425,773.9137262003311,0.00025370340306410486,25.0,0.0
330.34302,0.04833839960629921,775.8307895281457,0.00025370340306410486,25.0,0.0
331.64429,0.04879608464566929,775.4916959850992,0.00025370340306410486,25.0,0.0
332.94556,0.04918251377952756,775.2616152731787,0.00025370340306410486,25.0,0.0
334.24683,0.04957666141732283,774.9220302152318,0.00025370340306410486,25.0,0.0
335.5481,0.04985368897637795,774.3369981374171,0.00025370340306410486,25.0,0.0
336.84937,0.05026632086614173,777.3972733857617,0.00025370340306410486,25.0,0.0
338.15063,0.050704738188976375,776.0116670115893,0.00025370340306410486,25.0,0.0
339.4519,0.0511061437007874,778.0155991307947,0.00025370340306410486,25.0,0.0
340.75317,0.05156150196850393,776.564233236755,0.00025370340306410486,25.0,0.0
342.05444,0.05189621456692914,778.0175393211921,0.00025370340306410486,25.0,0.0
343.35571,0.052295021653543314,778.7638658940397,0.00025370340306410486,25.0,0.0
344.65698,0.05274700196850394,778.4691121688742,0.00025370340306410486,25.0,0.0
345.95825,0.05312336220472441,781.4636537665563,0.00025370340306410486,25.0,0.0
347.25952,0.053517163385826766,778.7890883692053,0.00025370340306410486,25.0,0.0
348.56079,0.05385817125984252,779.7837334437086,0.00025370340306410486,25.0,0.0
349.86206,0.054193399606299215,778.0309913079469,0.00025370340306410486,25.0,0.0
351.16333,0.05456244291338583,780.192880794702,0.00025370340306410486,25.0,0.0
352.4646,0.05500965551181102,783.5924306705298,0.00025370340306410486,25.0,0.0
353.76587,0.05535903346456692,780.7922444122516,0.00025370340306410486,25.0,0.0
355.06714,0.055747679133858266,780.7698675496688,0.00025370340306410486,25.0,0.0
356.36841,0.05612870866141733,780.6310016556291,0.00025370340306410486,25.0,0.0
357.66968,0.05653741141732283,782.4139331539735,0.00025370340306410486,25.0,0.0
358.97095,0.05694522834645669,782.9618687913908,0.00025370340306410486,25.0,0.0
360.27222,0.057245868110236214,782.817699710265,0.00025370340306410486,25.0,0.0
361.57349,0.05764302952755905,783.8818294701987,0.00025370340306410486,25.0,0.0
362.87476,0.05801799409448819,785.6024937913907,0.00025370340306410486,25.0,0.0
364.17603,0.05840905511811023,785.035337334437,0.00025370340306410486,25.0,0.0
365.47729,0.05879035433070866,784.266840852649,0.00025370340306410486,25.0,0.0
366.77856,0.059133011811023616,783.986108236755,0.00025370340306410486,25.0,0.0
368.07983,0.05960653346456693,785.5649058360927,0.00025370340306410486,25.0,0.0
369.3811,0.0600253031496063,785.2156974337748,0.00025370340306410486,25.0,0.0
370.68237,0.060445844488188974,786.0247568294702,0.00025370340306410486,25.0,0.0
371.98364,0.06078158464566929,784.7482667632449,0.00025370340306410486,25.0,0.0
373.28491,0.0611350531496063,785.770229718543,0.00025370340306410486,25.0,0.0
374.58618,0.061548155511811024,787.900532905629,0.00025370340306410486,25.0,0.0
375.88745,0.061915086614173234,785.8827090231788,0.00025370340306410486,25.0,0.0
377.18872,0.062306911417322836,785.1095302152319,0.00025370340306410486,25.0,0.0
378.48999,0.06259543110236221,785.4447692466887,0.00025370340306410486,25.0,0.0
379.79126,0.06295628543307086,789.8417839403972,0.00025370340306410486,25.0,0.0
381.09253,0.06334678346456693,786.9331539735099,0.00025370340306410486,25.0,0.0
382.3938,0.06378063582677165,789.4501500413907,0.00025370340306410486,25.0,0.0
383.69507,0.06416710433070866,787.5521523178808,0.00025370340306410486,25.0,0.0
384.99634,0.06460541535433072,789.7608909354304,0.00025370340306410486,25.0,0.0
386.29761,0.06493808070866142,788.9179946192053,0.00025370340306410486,25.0,0.0
387.59888,0.06535750196850393,791.4154853062914,0.00025370340306410486,25.0,0.0
388.90015,0.0657011968503937,789.0713990066224,0.00025370340306410486,25.0,0.0
390.20142,0.06604603543307086,789.6771264486754,0.00025370340306410486,25.0,0.0
391.50269,0.06641467519685039,790.4155111754966,0.00025370340306410486,25.0,0.0
392.80396,0.06679400984251968,790.4986289321191,0.00025370340306410486,25.0,0.0
394.10522,0.06713753937007874,790.1612427566224,0.00025370340306410486,25.0,0.0
395.40649,0.06753399803149607,792.3510968543046,0.00025370340306410486,25.0,0.0
396.70776,0.06794444291338582,792.6223354718543,0.00025370340306410486,25.0,0.0
398.00903,0.06842443110236221,794.4329987582781,0.00025370340306410486,25.0,0.0
399.3103,0.06876819685039369,794.4053445778146,0.00025370340306410486,25.0,0.0
400.61157,0.06913719291338583,793.1536113410596,0.00025370340306410486,25.0,0.0
401.91284,0.06951355905511811,791.6855339403972,0.00025370340306410486,25.0,0.0
403.21411,0.0699301751968504,794.423271937086,0.00025370340306410486,25.0,0.0
404.51538,0.07033724212598425,792.3185016556291,0.00025370340306410486,25.0,0.0
405.81665,0.07066060236220473,792.7468180877484,0.00025370340306410486,25.0,0.0
407.11792,0.07103083661417323,794.4767694536423,0.00025370340306410486,25.0,0.0
408.41919,0.07140837007874017,796.772480339404,0.00025370340306410486,25.0,0.0
409.72046,0.07178702362204725,794.9716732201987,0.00025370340306410486,25.0,0.0
411.02173,0.072165937007874,796.1669857201987,0.00025370340306410486,25.0,0.0
412.323,0.07250477362204724,794.1635192466888,0.00025370340306410486,25.0,0.0
413.62427,0.07291819291338582,795.9046978476821,0.00025370340306410486,25.0,0.0
414.92554,0.07328866338582676,796.6466007864238,0.00025370340306410486,25.0,0.0
416.22681,0.07368334448818897,795.2743687913907,0.00025370340306410486,25.0,0.0
417.52808,0.07406533070866142,797.2557429635762,0.00025370340306410486,25.0,0.0
418.82935,0.07444034055118111,797.3047651076158,0.00025370340306410486,25.0,0.0
420.13062,0.07484542913385826,797.7912613824502,0.00025370340306410486,25.0,0.0
421.43188,0.07524213976377953,797.949037665563,0.00025370340306410486,25.0,0.0
422.73315,0.0756206062992126,798.5760554635762,0.00025370340306410486,25.0,0.0
424.03442,0.07597649212598424,799.394013865894,0.00025370340306410486,25.0,0.0
425.33569,0.07635069291338582,797.7179221854303,0.00025370340306410486,25.0,0.0
426.63696,0.07667006496062992,798.1731684602648,0.00025370340306410486,25.0,0.0
427.93823,0.07704926968503936,799.6839559188742,0.00025370340306410486,25.0,0.0
429.2395,0.07742042125984253,798.8495188327814,0.00025370340306410486,25.0,0.0
430.54077,0.07778797440944882,797.7704108029801,0.00025370340306410486,25.0,0.0
431.84204,0.07817870669291338,800.2807326158941,0.00025370340306410486,25.0,0.0
433.14331,0.07857573622047244,801.8596595612582,0.00025370340306410486,25.0,0.0
434.44458,0.07901407086614173,802.3150869205298,0.00025370340306410486,25.0,0.0
435.74585,0.07936917519685038,800.2372206125827,0.00025370340306410486,25.0,0.0
437.04712,0.07975754330708662,801.6108236754966,0.00025370340306410486,25.0,0.0
438.34839,0.08017379133858268,800.4488565811258,0.00025370340306410486,25.0,0.0
439.64966,0.08050488385826772,802.734375,0.00025370340306410486,25.0,0.0
440.95093,0.08083354921259843,802.528740687086,0.00025370340306410486,25.0,0.0
442.2522,0.08116365748031495,801.32856477649,0.00025370340306410486,25.0,0.0
443.55347,0.0815637125984252,803.6753673427152,0.00025370340306410486,25.0,0.0
444.85474,0.08191387795275591,803.6246637003311,0.00025370340306410486,25.0,0.0
446.15601,0.08231450196850393,804.5440293874171,0.00025370340306410486,25.0,0.0
447.45728,0.08276497440944881,804.5877483443708,0.00025370340306410486,25.0,0.0
448.75854,0.08315669881889765,805.4756570778145,0.00025370340306410486,25.0,0.0
450.05981,0.08354242125984251,802.6884054221854,0.00025370340306410486,25.0,0.0
451.36108,0.08387300393700788,804.5683464403974,0.00025370340306410486,25.0,0.0
452.66235,0.0842973937007874,807.2941587334437,0.00025370340306410486,25.0,0.0
453.96362,0.08465870669291338,806.6673220198676,0.00025370340306410486,25.0,0.0
455.26489,0.085007781496063,805.9866773592715,0.00025370340306410486,25.0,0.0
456.56616,0.08535337007874015,806.4446140314569,0.00025370340306410486,25.0,0.0
457.86743,0.08569779330708661,807.7334695778145,0.00025370340306410486,25.0,0.0
459.1687,0.08602078937007875,804.698002897351,0.00025370340306410486,25.0,0.0
460.46997,0.08633102165354331,807.4733288493377,0.00025370340306410486,25.0,0.0
461.77124,0.08670711220472441,806.1063483029801,0.00025370340306410486,25.0,0.0
463.07251,0.0870846496062992,807.7234840645696,0.00025370340306410486,25.0,0.0
464.37378,0.08746688385826772,808.5154180463576,0.00025370340306410486,25.0,0.0
465.67505,0.08782175984251969,809.3179066639073,0.00025370340306410486,25.0,0.0
466.97632,0.08816023818897638,807.0193501655629,0.00025370340306410486,25.0,0.0
468.27759,0.08854154921259842,808.0493325745033,0.00025370340306410486,25.0,0.0
469.57886,0.08894843897637796,809.3448106374173,0.00025370340306410486,25.0,0.0
470.88013,0.08935867322834645,809.2914942052979,0.00025370340306410486,25.0,0.0
472.1814,0.08973400590551181,808.6188172599337,0.00025370340306410486,25.0,0.0
473.48267,0.09011474212598425,809.5520229718543,0.00025370340306410486,25.0,0.0
474.78394,0.09051432283464567,811.0198675496688,0.00025370340306410486,25.0,0.0
476.08521,0.09086899999999999,809.1502224751655,0.00025370340306410486,25.0,0.0
477.38647,0.09126293110236221,808.6427462748344,0.00025370340306410486,25.0,0.0
478.68774,0.09157560236220472,811.0233340231788,0.00025370340306410486,25.0,0.0
479.98901,0.09197088188976377,809.489936879139,0.00025370340306410486,25.0,0.0
481.29028,0.09242232874015748,812.3249948261589,0.00025370340306410486,25.0,0.0
482.59155,0.09273291141732283,811.0894039735099,0.00025370340306410486,25.0,0.0
483.89282,0.09317377559055118,812.7755070364237,0.00025370340306410486,25.0,0.0
485.19409,0.09349168700787401,811.0044495033112,0.00025370340306410486,25.0,0.0
486.49536,0.09395730708661418,812.4275662251655,0.00025370340306410486,25.0,0.0
487.79663,0.09437325393700788,812.124482615894,0.00025370340306410486,25.0,0.0
489.0979,0.09471805118110235,812.6077711092715,0.00025370340306410486,25.0,0.0
490.39917,0.09502562598425197,811.4782439983444,0.00025370340306410486,25.0,0.0
491.70044,0.09539932283464567,812.1782905629138,0.00025370340306410486,25.0,0.0
493.00171,0.09576098622047244,811.2985823675497,0.00025370340306410486,25.0,0.0
494.30298,0.0960707716535433,815.5086920529801,0.00025370340306410486,25.0,0.0
495.60425,0.09643847244094489,814.7769557119204,0.00025370340306410486,25.0,0.0
496.90552,0.09680606889763779,814.8722061258277,0.00025370340306410486,25.0,0.0
498.20679,0.09715286614173228,814.9654904801324,0.00025370340306410486,25.0,0.0
499.50806,0.09756824606299212,816.57465852649,0.00025370340306410486,25.0,0.0
500.80933,0.09795358661417322,815.2051686672185,0.00025370340306410486,25.0,0.0
502.1106,0.09832740748031496,814.9046719784768,0.00025370340306410486,25.0,0.0
503.41187,0.09871634448818899,815.8770177980133,0.00025370340306410486,25.0,0.0
504.71313,0.09910749409448819,816.1208091887418,0.00025370340306410486,25.0,0.0
506.0144,0.09947156299212598,816.9094060430463,0.00025370340306410486,25.0,0.0
507.31567,0.09989346653543307,816.7259933774834,0.00025370340306410486,25.0,0.0
508.61694,0.10031881692913386,817.9935585678808,0.00025370340306410486,25.0,0.0
509.91821,0.10066960433070865,817.6939414321192,0.00025370340306410486,25.0,0.0
511.21948,0.10103128149606298,818.9276438327813,0.00025370340306410486,25.0,0.0
512.52075,0.10142125787401574,817.4320933360926,0.00025370340306410486,25.0,0.0
513.82202,0.10178682874015749,817.4015159354304,0.00025370340306410486,25.0,0.0
515.12329,0.1020729783464567,817.7677721440398,0.00025370340306410486,25.0,0.0
516.42456,0.10242551377952755,818.1916908112582,0.00025370340306410486,25.0,0.0
517.72583,0.1028694625984252,821.1613979718543,0.00025370340306410486,25.0,0.0
519.0271,0.10322856889763779,817.4419495033112,0.00025370340306410486,25.0,0.0
520.32837,0.1036117283464567,818.8586247930463,0.00025370340306410486,25.0,0.0
521.62964,0.10391634448818898,817.8008071192053,0.00025370340306410486,25.0,0.0
522.93091,0.10434439566929134,822.4348872102648,0.00025370340306410486,25.0,0.0
524.23218,0.10482752165354331,820.0435120033112,0.00025370340306410486,25.0,0.0
525.53345,0.10523270472440946,819.1386072019867,0.00025370340306410486,25.0,0.0
526.83472,0.10553131496062991,818.9734323261589,0.00025370340306410486,25.0,0.0
528.13599,0.10585056299212597,819.7575279387416,0.00025370340306410486,25.0,0.0
529.43726,0.10623022637795276,820.7554325331125,0.00025370340306410486,25.0,0.0
530.73853,0.1065632716535433,820.3578487168874,0.00025370340306410486,25.0,0.0
532.03979,0.1070039586614173,820.9878932119204,0.00025370340306410486,25.0,0.0
533.34106,0.10734620472440945,820.4666545943708,0.00025370340306410486,25.0,0.0
534.64233,0.10771397047244095,820.6292425496689,0.00025370340306410486,25.0,0.0
535.9436,0.10805580511811022,822.014848923841,0.00025370340306410486,25.0,0.0
537.24487,0.10846710039370078,821.3129656456954,0.00025370340306410486,25.0,0.0
538.54614,0.10885300590551181,822.4854873758278,0.00025370340306410486,25.0,0.0
539.84741,0.10918946653543307,822.2836299668874,0.00025370340306410486,25.0,0.0
541.14868,0.10954062992125985,820.5276800496688,0.00025370340306410486,25.0,0.0
542.44995,0.10988807283464566,822.7409716473509,0.00025370340306410486,25.0,0.0
543.75122,0.11030798031496063,822.8676531456953,0.00025370340306410486,25.0,0.0
545.05249,0.11070349606299211,824.638193294702,0.00025370340306410486,25.0,0.0
546.35376,0.1111528307086614,824.290976821192,0.00025370340306410486,25.0,0.0
547.65503,0.11152386811023622,823.0713990066225,0.00025370340306410486,25.0,0.0
548.9563,0.11184744685039369,826.0674410182119,0.00025370340306410486,25.0,0.0
550.25757,0.11221873228346457,823.5589817880794,0.00025370340306410486,25.0,0.0
551.55884,0.1125653188976378,825.8283319536424,0.00025370340306410486,25.0,0.0
552.86011,0.11295352362204725,824.6220250413907,0.00025370340306410486,25.0,0.0
554.16138,0.11341731299212598,824.1481529387416,0.00025370340306410486,25.0,0.0
555.46265,0.11376874606299212,824.3995240066225,0.00025370340306410486,25.0,0.0
556.76392,0.11417750787401573,824.6409871688742,0.00025370340306410486,25.0,0.0
558.06519,0.11451694881889765,826.2039269453643,0.00025370340306410486,25.0,0.0
559.36646,0.11499137007874016,824.5789010761589,0.00025370340306410486,25.0,0.0
560.66772,0.11531033661417323,824.8143367135762,0.00025370340306410486,25.0,0.0
561.96899,0.11572004724409447,827.0083040149007,0.00025370340306410486,25.0,0.0
563.27026,0.11610358267716535,827.9147350993378,0.00025370340306410486,25.0,0.0
564.57153,0.11639259448818898,824.5780215231788,0.00025370340306410486,25.0,0.0
565.8728,0.11679228543307087,827.8765780215232,0.00025370340306410486,25.0,0.0
567.17407,0.11716894488188977,828.0361910182119,0.00025370340306410486,25.0,0.0
568.47534,0.1175653622047244,824.7816380380794,0.00025370340306410486,25.0,0.0
569.77661,0.11788809645669292,828.8328590645694,0.00025370340306410486,25.0,0.0
571.07788,0.11827846062992127,828.3755432533113,0.00025370340306410486,25.0,0.0
572.37915,0.11868939173228346,829.3264952400663,0.00025370340306410486,25.0,0.0
573.68042,0.11912065748031495,830.9530473923841,0.00025370340306410486,25.0,0.0
574.98169,0.11951695669291339,827.486030629139,0.00025370340306410486,25.0,0.0
576.28296,0.11988537992125985,828.6515418046357,0.00025370340306410486,25.0,0.0
577.58423,0.12029322637795274,829.4418201572847,0.00025370340306410486,25.0,0.0
578.8855,0.12072633267716534,828.8116980546357,0.00025370340306410486,25.0,0.0
580.18677,0.12108276377952755,828.3462334437086,0.00025370340306410486,25.0,0.0
581.48804,0.12155082480314962,830.2247257864237,0.00025370340306410486,25.0,0.0
582.78931,0.12189771653543308,829.1175755380794,0.00025370340306410486,25.0,0.0
584.09058,0.12231483267716535,831.6315966473509,0.00025370340306410486,25.0,0.0
585.39185,0.12263477362204725,829.1279232201987,0.00025370340306410486,25.0,0.0
586.69312,0.12297195078740157,830.7280111754967,0.00025370340306410486,25.0,0.0
587.99438,0.123307531496063,830.3163027731788,0.00025370340306410486,25.0,0.0
589.29565,0.12372363779527559,832.1639590231788,0.00025370340306410486,25.0,0.0
590.59692,0.12413995472440945,831.7640469784768,0.00025370340306410486,25.0,0.0
591.89819,0.12454778937007874,832.2349441225165,0.00025370340306410486,25.0,0.0
593.19946,0.12500643897637795,832.1933981788079,0.00025370340306410486,25.0,0.0
594.50073,0.1254005688976378,832.2154904801324,0.00025370340306410486,25.0,0.0
595.802,0.12577052952755904,832.6085213162252,0.00025370340306410486,25.0,0.0
597.10327,0.12613221653543305,832.7109633692052,0.00025370340306410486,25.0,0.0
598.40454,0.12649621456692914,831.1370291804635,0.00025370340306410486,25.0,0.0
599.70581,0.12680674606299214,831.0242911837747,0.00025370340306410486,25.0,0.0
601.00708,0.12709167519685038,830.8238824503311,0.00025370340306410486,25.0,0.0
602.30835,0.12743238385826772,833.3026697019868,0.00025370340306410486,25.0,0.0
603.60962,0.12782740551181102,833.3535802980132,0.00025370340306410486,25.0,0.0
604.91089,0.12824678543307086,833.3315397350993,0.00025370340306410486,25.0,0.0
606.21216,0.12861315354330707,832.7412044701987,0.00025370340306410486,25.0,0.0
607.51343,0.12903817716535432,833.1605701572847,0.00025370340306410486,25.0,0.0
608.8147,0.12942474015748032,832.9063017384105,0.00025370340306410486,25.0,0.0
610.11597,0.12983352362204725,835.2003052566224,0.00025370340306410486,25.0,0.0
611.41724,0.1302073090551181,832.817880794702,0.00025370340306410486,25.0,0.0
612.71851,0.1306147559055118,834.4449503311258,0.00025370340306410486,25.0,0.0
614.01978,0.13101966929133857,834.49697330298,0.00025370340306410486,25.0,0.0
615.32104,0.1313795846456693,834.4709747516556,0.00025370340306410486,25.0,0.0
616.62231,0.13176519488188976,834.5342508278146,0.00025370340306410486,25.0,0.0
617.92358,0.13219531102362206,834.7827762831125,0.00025370340306410486,25.0,0.0
619.22485,0.1325203090551181,834.00043977649,0.00025370340306410486,25.0,0.0
620.52612,0.1328895059055118,835.1794546771523,0.00025370340306410486,25.0,0.0
621.82739,0.1332358937007874,835.6112117135762,0.00025370340306410486,25.0,0.0
623.12866,0.13368862992125985,836.7156974337747,0.00025370340306410486,25.0,0.0
624.42993,0.1341432342519685,835.2388245033112,0.00025370340306410486,25.0,0.0
625.7312,0.1346267342519685,836.0218594784767,0.00025370340306410486,25.0,0.0
627.03247,0.1349750590551181,835.154956539735,0.00025370340306410486,25.0,0.0
628.33374,0.13530437401574802,836.2058412665563,0.00025370340306410486,25.0,0.0
629.63501,0.13565802362204724,836.5336040976821,0.00025370340306410486,25.0,0.0
630.93628,0.13608052559055117,837.5899730960265,0.00025370340306410486,25.0,0.0
632.23755,0.1365158031496063,836.5098044288079,0.00025370340306410486,25.0,0.0
633.53882,0.1369251397637795,838.6689000413908,0.00025370340306410486,25.0,0.0
634.84009,0.13730026181102362,837.7699192880794,0.00025370340306410486,25.0,0.0
636.14136,0.1376580649606299,838.7393160182119,0.00025370340306410486,25.0,0.0
637.44263,0.13806264960629921,838.1308723096026,0.00025370340306410486,25.0,0.0
638.7439,0.13851636023622046,839.0504966887416,0.00025370340306410486,25.0,0.0
640.04517,0.13887130118110236,837.8377483443709,0.00025370340306410486,25.0,0.0
641.34644,0.1392406397637795,836.7082988410597,0.00025370340306410486,25.0,0.0
642.64771,0.1396125570866142,838.4835989238411,0.00025370340306410486,25.0,0.0
643.94897,0.13996416732283465,837.420141763245,0.00025370340306410486,25.0,0.0
645.25024,0.14036776574803148,838.819277731788,0.00025370340306410486,25.0,0.0
646.55151,0.14073933267716535,838.994101821192,0.00025370340306410486,25.0,0.0
647.85278,0.1411631594488189,838.8460006208609,0.00025370340306410486,25.0,0.0
649.15405,0.14157498228346455,837.9256001655629,0.00025370340306410486,25.0,0.0
650.45532,0.14203005511811023,839.3375413907285,0.00025370340306410486,25.0,0.0
651.75659,0.14244636023622048,838.4450020695364,0.00025370340306410486,25.0,0.0
653.05786,0.14286900196850394,840.0142021937086,0.00025370340306410486,25.0,0.0
654.35913,0.14328440354330707,839.1322175082781,0.00025370340306410486,25.0,0.0
655.6604,0.14368082086614173,839.3129139072847,0.00025370340306410486,25.0,0.0
656.96167,0.14404301377952755,839.2293563741722,0.00025370340306410486,25.0,0.0
658.26294,0.1444295275590551,839.6804377069536,0.00025370340306410486,25.0,0.0
659.56421,0.14481693503937007,841.4372671771523,0.00025370340306410486,25.0,0.0
660.86548,0.14519190551181102,839.7646161009934,0.00025370340306410486,25.0,0.0
662.16675,0.1455954803149606,842.5805308360926,0.00025370340306410486,25.0,0.0
663.46802,0.14598586614173228,839.798789321192,0.00025370340306410486,25.0,0.0
664.76929,0.14634926771653545,840.350527731788,0.00025370340306410486,25.0,0.0
666.07056,0.14682312401574804,843.8262624172186,0.00025370340306410486,25.0,0.0
667.37183,0.14731360629921258,841.5108391970199,0.00025370340306410486,25.0,0.0
668.6731,0.14771415551181102,840.9686982615893,0.00025370340306410486,25.0,0.0
669.97437,0.14811688582677165,839.6800496688742,0.00025370340306410486,25.0,0.0
671.27563,0.14848894488188977,838.9772350993377,0.00025370340306410486,25.0,0.0
672.5769,0.14885958464566929,840.846181705298,0.00025370340306410486,25.0,0.0
673.87817,0.14923426181102362,842.8754915149007,0.00025370340306410486,25.0,0.0
675.17944,0.14968925196850394,841.97612272351,0.00025370340306410486,25.0,0.0
676.48071,0.1500711437007874,840.9080867135762,0.00025370340306410486,25.0,0.0
677.78198,0.15046749015748032,843.0216266556291,0.00025370340306410486,25.0,0.0
679.08325,0.150895094488189,843.9053187086092,0.00025370340306410486,25.0,0.0
680.38452,0.15138189370078742,843.0034406043046,0.00025370340306410486,25.0,0.0
681.68579,0.15182369488188976,840.6909923427152,0.00025370340306410486,25.0,0.0
682.98706,0.15222764566929134,844.0514797185431,0.00025370340306410486,25.0,0.0
684.28833,0.15259964763779527,843.2330298013245,0.00025370340306410486,25.0,0.0
685.5896,0.15292669881889764,841.6527059188741,0.00025370340306410486,25.0,0.0
686.89087,0.15326389960629921,842.082289942053,0.00025370340306410486,25.0,0.0
688.19214,0.15365304133858268,845.3240376655629,0.00025370340306410486,25.0,0.0
689.49341,0.15409689763779527,844.0372516556291,0.00025370340306410486,25.0,0.0
690.79468,0.15456349212598425,842.6563276076158,0.00025370340306410486,25.0,0.0
692.09595,0.1549806653543307,844.6524730960265,0.00025370340306410486,25.0,0.0
693.39722,0.1553935216535433,845.9887727649005,0.00025370340306410486,25.0,0.0
694.69849,0.15574240748031495,843.1655111754967,0.00025370340306410486,25.0,0.0
695.99976,0.15617767519685039,844.5847733857615,0.00025370340306410486,25.0,0.0
697.30103,0.15664318897637794,845.3017384105959,0.00025370340306410486,25.0,0.0
698.60229,0.15702377952755905,844.4088886589403,0.00025370340306410486,25.0,0.0
699.90356,0.1573548779527559,841.3865635347682,0.00025370340306410486,25.0,0.0
701.20483,0.1577204724409449,845.0297237168874,0.00025370340306410486,25.0,0.0
702.5061,0.15820361023622048,845.35200227649,0.00025370340306410486,25.0,0.0
703.80737,0.15867326574803148,847.3178290562913,0.00025370340306410486,25.0,0.0
705.10864,0.15914778149606298,844.8426376241721,0.00025370340306410486,25.0,0.0
706.40991,0.15960385039370079,845.6381674254967,0.00025370340306410486,25.0,0.0
707.71118,0.1600181496062992,844.5051997102648,0.00025370340306410486,25.0,0.0
709.01245,0.16040567322834645,844.4905318708609,0.00025370340306410486,25.0,0.0
710.31372,0.16080176181102362,845.7057636589403,0.00025370340306410486,25.0,0.0
711.61499,0.16123617322834646,847.1126345198675,0.00025370340306410486,25.0,0.0
712.91626,0.16163862204724408,847.595224544702,0.00025370340306410486,25.0,0.0
714.21753,0.1621076909448819,846.8526231374171,0.00025370340306410486,25.0,0.0
715.5188,0.16252588582677163,846.5334230132449,0.00025370340306410486,25.0,0.0
716.82007,0.16297451574803148,846.0195053807947,0.00025370340306410486,25.0,0.0
718.12134,0.16340666141732282,847.9475113824502,0.00025370340306410486,25.0,0.0
719.42261,0.16386080708661419,845.7944950331125,0.00025370340306410486,25.0,0.0
720.72388,0.16429075787401573,844.8838213990066,0.00025370340306410486,25.0,0.0
722.02515,0.16464998228346456,844.9919546771523,0.00025370340306410486,25.0,0.0
723.32642,0.16507534448818897,847.7399110099337,0.00025370340306410486,25.0,0.0
724.62769,0.16545222637795276,846.7588990066225,0.00025370340306410486,25.0,0.0
725.92896,0.16590129133858267,845.7902524834437,0.00025370340306410486,25.0,0.0
727.23022,0.16638282283464567,847.1568449917218,0.00025370340306410486,25.0,0.0
728.53149,0.16680312992125984,847.1716421771523,0.00025370340306410486,25.0,0.0
729.83276,0.16723899409448817,847.3665925082781,0.00025370340306410486,25.0,0.0
731.13403,0.16767601968503937,847.475346647351,0.00025370340306410486,25.0,0.0
732.4353,0.16810139566929133,848.073442673841,0.00025370340306410486,25.0,0.0
733.73657,0.16853832874015748,847.9109581953642,0.00025370340306410486,25.0,0.0
735.03784,0.16898515157480315,848.1665459437086,0.00025370340306410486,25.0,0.0
736.33911,0.1694235157480315,847.0491773592715,0.00025370340306410486,25.0,0.0
737.64038,0.16980541929133858,846.8555980960265,0.00025370340306410486,25.0,0.0
738.94165,0.17021294881889762,848.2824917218543,0.00025370340306410486,25.0,0.0
740.24292,0.1706668248031496,847.6220767798013,0.00025370340306410486,25.0,0.0
741.54419,0.1710977854330709,845.3419132864238,0.00025370340306410486,25.0,0.0
742.84546,0.17147875,847.2565707781457,0.00025370340306410486,25.0,0.0
744.14673,0.17195185629921259,849.1497826986754,0.00025370340306410486,25.0,0.0
745.448,0.17238474015748032,848.2715749172185,0.00025370340306410486,25.0,0.0
746.74927,0.172819937007874,846.4684395695364,0.00025370340306410486,25.0,0.0
748.05054,0.1732862598425197,848.5762365480132,0.00025370340306410486,25.0,0.0
749.35181,0.17371842913385827,849.5601200331125,0.00025370340306410486,25.0,0.0
750.65308,0.17414490748031494,846.2898903145696,0.00025370340306410486,25.0,0.0
751.95435,0.17459811417322835,848.9588679635762,0.00025370340306410486,25.0,0.0
753.25562,0.1750446437007874,849.2529749586092,0.00025370340306410486,25.0,0.0
754.55688,0.1754825748031496,848.4329987582781,0.00025370340306410486,25.0,0.0
755.85815,0.17590769094488187,848.8480184188742,0.00025370340306410486,25.0,0.0
757.15942,0.1764137677165354,848.6790149006622,0.00025370340306410486,25.0,0.0
758.46069,0.17687142125984254,849.3718439569536,0.00025370340306410486,25.0,0.0
759.76196,0.17736597637795276,849.6266814983443,0.00025370340306410486,25.0,0.0
761.06323,0.17789643307086614,848.5453745860927,0.00025370340306410486,25.0,0.0
762.3645,0.1783309251968504,847.9845819536423,0.00025370340306410486,25.0,0.0
763.66577,0.17872951377952756,847.9627483443708,0.00025370340306410486,25.0,0.0
764.96704,0.17908308267716536,847.3611599751655,0.00025370340306410486,25.0,0.0
766.26831,0.17950202755905512,849.9183309188742,0.00025370340306410486,25.0,0.0
767.56958,0.17992482086614173,850.0258433360926,0.00025370340306410486,25.0,0.0
768.87085,0.18041772244094487,851.2635813327814,0.00025370340306410486,25.0,0.0
770.17212,0.18095221653543306,850.5024058360926,0.00025370340306410486,25.0,0.0
771.47339,0.18141161811023623,849.586894660596,0.00025370340306410486,25.0,0.0
772.77466,0.18188020669291338,849.801997102649,0.00025370340306410486,25.0,0.0
774.07593,0.18235179921259842,850.8398696192053,0.00025370340306410486,25.0,0.0
775.3772,0.18281821653543306,848.6403663079469,0.00025370340306410486,25.0,0.0
776.67847,0.183226531496063,849.6201107201986,0.00025370340306410486,25.0,0.0
777.97974,0.18366754724409448,849.3599699917218,0.00025370340306410486,25.0,0.0
779.28101,0.1841622657480315,850.4462179221854,0.00025370340306410486,25.0,0.0
780.58228,0.18463497244094487,849.5217042632449,0.00025370340306410486,25.0,0.0
781.88354,0.1850697342519685,848.8364031456954,0.00025370340306410486,25.0,0.0
783.18481,0.18547145669291337,851.8706539735099,0.00025370340306410486,25.0,0.0
784.48608,0.18593299409448819,849.3072226821191,0.00025370340306410486,25.0,0.0
785.78735,0.18637474803149606,849.9453125,0.00025370340306410486,25.0,0.0
787.08862,0.1868688562992126,849.4255225579469,0.00025370340306410486,25.0,0.0
788.38989,0.1873501751968504,849.6736599751656,0.00025370340306410486,25.0,0.0
789.69116,0.1877538562992126,850.0495912665563,0.00025370340306410486,25.0,0.0
790.99243,0.18821047834645668,850.1133588576158,0.00025370340306410486,25.0,0.0
792.2937,0.1887111909448819,851.1685378725165,0.00025370340306410486,25.0,0.0
793.59497,0.18922094094488187,850.1210678807947,0.00025370340306410486,25.0,0.0
794.89624,0.1897187913385827,851.0276283112582,0.00025370340306410486,25.0,0.0
796.19751,0.19023548622047243,849.2671254139073,0.00025370340306410486,25.0,0.0
797.49878,0.19073351377952755,849.912406870861,0.00025370340306410486,25.0,0.0
798.80005,0.1912231161417323,850.0757967715231,0.00025370340306410486,25.0,0.0
800.10132,0.19167299015748032,849.3979977235099,0.00025370340306410486,25.0,0.0
801.40259,0.19216462401574802,849.6921047185431,0.00025370340306410486,25.0,0.0
802.70386,0.19261248031496062,850.5874896523178,0.00025370340306410486,25.0,0.0
804.00513,0.1930028661417323,850.3487686258278,0.00025370340306410486,25.0,0.0
805.3064,0.1934727933070866,851.2701521109271,0.00025370340306410486,25.0,0.0
806.60767,0.1939522342519685,850.321528352649,0.00025370340306410486,25.0,0.0
807.90894,0.19444741141732283,851.0974234271523,0.00025370340306410486,25.0,0.0
809.21021,0.19496648818897638,852.3718698261589,0.00025370340306410486,25.0,0.0
810.51147,0.19544066141732283,852.3001862582781,0.00025370340306410486,25.0,0.0
811.81274,0.1958697559055118,849.7324606788079,0.00025370340306410486,25.0,0.0
813.11401,0.19636972047244095,851.702348923841,0.00025370340306410486,25.0,0.0
814.41528,0.19688320866141734,851.5157026076158,0.00025370340306410486,25.0,0.0
815.71655,0.19738521653543306,851.7490687086092,0.00025370340306410486,25.0,0.0
817.01782,0.19781450787401572,849.733417839404,0.00025370340306410486,25.0,0.0
818.31909,0.19828159448818897,850.3771730132449,0.00025370340306410486,25.0,0.0
819.62036,0.19872116141732285,851.4953176738411,0.00025370340306410486,25.0,0.0
820.92163,0.19916850393700788,852.4669908940398,0.00025370340306410486,25.0,0.0
821.12183,0.19925133858267713,853.6916132036423,0.00025370340306410486,25.0,0.0