File: datasets/am_bench_2022/csv/0-XY.05-2.csv
Time(s),Strain(%),Stress(MPa),SR(s-1),Temp(C),Angle(deg)
35.175293,2.7779070866141734e-05,15.832881887335526,0.00025370340306410486,25.0,0.0
36.476563,2.6302080708661417e-05,20.40659719366776,0.00025370340306410486,25.0,0.0
37.777832,3.057494291338583e-05,25.094965306332238,0.00025370340306410486,25.0,0.0
39.079102,6.58351437007874e-05,29.88034796463816,0.00025370340306410486,25.0,0.0
40.380371,9.035248622047245e-05,34.40355417351974,0.00025370340306410486,25.0,0.0
41.681641,8.971845866141732e-05,38.63615851151315,0.00025370340306410486,25.0,0.0
42.98291,0.00013298695078740159,44.851192434210525,0.00025370340306410486,25.0,0.0
44.28418,0.00014291690354330708,49.84288137335526,0.00025370340306410486,25.0,0.0
45.585449,0.00017705827362204723,53.77393092105263,0.00025370340306410486,25.0,0.0
46.886719,0.00019722450787401573,60.446309621710526,0.00025370340306410486,25.0,0.0
48.187988,0.00021457954724409447,67.19037057976973,0.00025370340306410486,25.0,0.0
49.489258,0.00022284293307086616,73.23403063322368,0.00025370340306410486,25.0,0.0
50.790527,0.0002469615748031496,81.27457339638158,0.00025370340306410486,25.0,0.0
52.091797,0.00029255082677165356,88.74301757812499,0.00025370340306410486,25.0,0.0
53.393066,0.00032494761811023624,93.12835115131578,0.00025370340306410486,25.0,0.0
54.694336,0.0003581976181102362,99.9193050986842,0.00025370340306410486,25.0,0.0
55.995605,0.0003788454330708661,108.07990337171053,0.00025370340306410486,25.0,0.0
57.296875,0.000378191220472441,114.99848889802632,0.00025370340306410486,25.0,0.0
58.598145,0.0004414694488188976,121.49208470394737,0.00025370340306410486,25.0,0.0
59.899414,0.00045252610236220473,130.18175113075657,0.00025370340306410486,25.0,0.0
61.200684,0.0005310953543307086,138.71856496710527,0.00025370340306410486,25.0,0.0
62.501953,0.0005016823818897638,145.8972527754934,0.00025370340306410486,25.0,0.0
63.803223,0.0005466830118110236,153.80581825657893,0.00025370340306410486,25.0,0.0
65.104492,0.0005944389173228346,163.8915347450658,0.00025370340306410486,25.0,0.0
66.405762,0.0006582231299212598,170.93283562911185,0.00025370340306410486,25.0,0.0
67.707031,0.0006792702559055118,182.27991365131578,0.00025370340306410486,25.0,0.0
69.008301,0.0006948893307086614,191.45822882401316,0.00025370340306410486,25.0,0.0
70.30957,0.0007278763976377952,198.86365131578947,0.00025370340306410486,25.0,0.0
71.61084,0.0007665138582677165,207.81044921875,0.00025370340306410486,25.0,0.0
72.912109,0.000801783937007874,216.62737201891449,0.00025370340306410486,25.0,0.0
74.213379,0.0008432530118110236,225.44650750411182,0.00025370340306410486,25.0,0.0
75.514648,0.0008908281889763778,235.7651829769737,0.00025370340306410486,25.0,0.0
76.815918,0.0009131463779527559,244.78325709292764,0.00025370340306410486,25.0,0.0
78.117188,0.0009202852952755906,252.34263209292763,0.00025370340306410486,25.0,0.0
79.418457,0.0010055036023622046,263.3822985197368,0.00025370340306410486,25.0,0.0
80.719727,0.0010365861417322834,272.8266344572369,0.00025370340306410486,25.0,0.0
82.020996,0.0010618448622047244,280.7665244654605,0.00025370340306410486,25.0,0.0
83.322266,0.0010735580905511812,289.7381270559211,0.00025370340306410486,25.0,0.0
84.623535,0.001103960807086614,299.44693153782896,0.00025370340306410486,25.0,0.0
85.924805,0.001162401496062992,308.75493421052636,0.00025370340306410486,25.0,0.0
87.226074,0.001204976496062992,318.2374074835526,0.00025370340306410486,25.0,0.0
88.527344,0.0012288700590551182,326.55347964638156,0.00025370340306410486,25.0,0.0
89.828613,0.001270755374015748,336.8705540707237,0.00025370340306410486,25.0,0.0
91.129883,0.00130997468503937,346.49041426809214,0.00025370340306410486,25.0,0.0
92.431152,0.0013634546062992127,354.71414987664474,0.00025370340306410486,25.0,0.0
93.732422,0.0013863691732283463,362.47869551809214,0.00025370340306410486,25.0,0.0
95.033691,0.0014068828346456693,374.91802014802636,0.00025370340306410486,25.0,0.0
96.334961,0.0014303999212598425,385.0997378700658,0.00025370340306410486,25.0,0.0
97.63623,0.0015146196259842519,393.6997327302632,0.00025370340306410486,25.0,0.0
98.9375,0.0015577358267716533,402.43685752467104,0.00025370340306410486,25.0,0.0
100.23877,0.0015919223228346457,410.0775339226974,0.00025370340306410486,25.0,0.0
101.54004,0.0016208237598425196,417.4989463404605,0.00025370340306410486,25.0,0.0
102.84131,0.001642238681102362,426.1492341694079,0.00025370340306410486,25.0,0.0
104.14258,0.0017081836417322833,436.9814710115132,0.00025370340306410486,25.0,0.0
105.44385,0.0017357905905511812,444.2847193667763,0.00025370340306410486,25.0,0.0
106.74512,0.0018082258464566928,453.8038908305921,0.00025370340306410486,25.0,0.0
108.04639,0.001811618562992126,462.15342310855266,0.00025370340306410486,25.0,0.0
109.34766,0.0018729197637795275,470.2988795230263,0.00025370340306410486,25.0,0.0
110.64893,0.0019022100393700787,476.6676603618421,0.00025370340306410486,25.0,0.0
111.9502,0.0019808913385826773,487.7028680098684,0.00025370340306410486,25.0,0.0
113.25146,0.002043786417322835,496.0561780427631,0.00025370340306410486,25.0,0.0
114.55273,0.002063068503937008,503.1561472039474,0.00025370340306410486,25.0,0.0
115.854,0.0021054958661417323,509.62276418585526,0.00025370340306410486,25.0,0.0
117.15527,0.002169517716535433,518.0123355263157,0.00025370340306410486,25.0,0.0
118.45654,0.0021933322834645666,524.0548930921052,0.00025370340306410486,25.0,0.0
119.75781,0.0022636360236220473,532.0082236842105,0.00025370340306410486,25.0,0.0
121.05908,0.0023441499999999997,541.3064093338816,0.00025370340306410486,25.0,0.0
122.36035,0.0023780403543307085,546.8050472861843,0.00025370340306410486,25.0,0.0
123.66162,0.002407792716535433,553.4680818256579,0.00025370340306410486,25.0,0.0
124.96289,0.0025062159448818897,560.8174599095395,0.00025370340306410486,25.0,0.0
126.26416,0.002545007874015748,564.5695415296053,0.00025370340306410486,25.0,0.0
127.56543,0.0025952102362204726,569.535002055921,0.00025370340306410486,25.0,0.0
128.8667,0.0026171832677165355,573.383634868421,0.00025370340306410486,25.0,0.0
130.16797,0.0026736535433070866,580.43994140625,0.00025370340306410486,25.0,0.0
131.46924,0.0027685185039370078,585.2617701480264,0.00025370340306410486,25.0,0.0
132.77051,0.00282007874015748,590.9432822779605,0.00025370340306410486,25.0,0.0
134.07178,0.0028693399606299214,597.5550729851973,0.00025370340306410486,25.0,0.0
135.37305,0.002926293307086614,600.0678196957238,0.00025370340306410486,25.0,0.0
136.67432,0.0030057909448818897,607.3264031661184,0.00025370340306410486,25.0,0.0
137.97559,0.003091945472440945,610.617033305921,0.00025370340306410486,25.0,0.0
139.27686,0.0031394582677165355,614.9389905427632,0.00025370340306410486,25.0,0.0
140.57813,0.0032412482283464567,621.2826891447368,0.00025370340306410486,25.0,0.0
141.87939,0.0032851171259842523,622.5478001644738,0.00025370340306410486,25.0,0.0
143.18066,0.003373976771653543,628.0298622532895,0.00025370340306410486,25.0,0.0
144.48193,0.00344198188976378,629.7646741365132,0.00025370340306410486,25.0,0.0
145.7832,0.003542747440944882,635.9683902138157,0.00025370340306410486,25.0,0.0
147.08447,0.003617740157480315,638.1630859375,0.00025370340306410486,25.0,0.0
148.38574,0.0036922122047244096,643.5489566200658,0.00025370340306410486,25.0,0.0
149.68701,0.0038175807086614174,646.8678042763158,0.00025370340306410486,25.0,0.0
150.98828,0.003908704724409449,648.7542660361843,0.00025370340306410486,25.0,0.0
152.28955,0.004059502362204724,652.9332339638158,0.00025370340306410486,25.0,0.0
153.59082,0.004106261417322835,655.3792917351973,0.00025370340306410486,25.0,0.0
154.89209,0.004228370275590552,659.0564093338816,0.00025370340306410486,25.0,0.0
156.19336,0.004362606889763779,662.1018194901317,0.00025370340306410486,25.0,0.0
157.49463,0.0044839856299212595,663.9410978618421,0.00025370340306410486,25.0,0.0
158.7959,0.004635375787401575,667.3661081414474,0.00025370340306410486,25.0,0.0
160.09717,0.004758713976377953,670.755525287829,0.00025370340306410486,25.0,0.0
161.39844,0.0049259391732283464,673.7360197368421,0.00025370340306410486,25.0,0.0
162.69971,0.005058911220472441,674.8754625822369,0.00025370340306410486,25.0,0.0
164.00098,0.005182909055118111,674.7607164884869,0.00025370340306410486,25.0,0.0
165.30225,0.005398769881889764,678.0537880345395,0.00025370340306410486,25.0,0.0
166.60352,0.0055775714566929134,679.4585731907895,0.00025370340306410486,25.0,0.0
167.90479,0.005751713976377953,682.6915861430922,0.00025370340306410486,25.0,0.0
169.20605,0.0059264531496062995,683.8794716282895,0.00025370340306410486,25.0,0.0
170.50732,0.006137850590551181,686.2122224506578,0.00025370340306410486,25.0,0.0
171.80859,0.006384475196850394,687.7861585115132,0.00025370340306410486,25.0,0.0
173.10986,0.00658850374015748,688.7908871299343,0.00025370340306410486,25.0,0.0
174.41113,0.006798622440944881,693.7322419819078,0.00025370340306410486,25.0,0.0
175.7124,0.007016870275590552,693.4460320723684,0.00025370340306410486,25.0,0.0
177.01367,0.007299591141732284,694.977873149671,0.00025370340306410486,25.0,0.0
178.31494,0.007530847440944882,696.7201891447369,0.00025370340306410486,25.0,0.0
179.61621,0.007739705708661417,696.4301500822369,0.00025370340306410486,25.0,0.0
180.91748,0.007975641141732282,699.0241313733552,0.00025370340306410486,25.0,0.0
182.21875,0.00829922657480315,701.2513363486842,0.00025370340306410486,25.0,0.0
183.52002,0.008601768700787401,703.3124743009869,0.00025370340306410486,25.0,0.0
184.82129,0.008880345472440945,705.1585886101974,0.00025370340306410486,25.0,0.0
186.12256,0.00920072125984252,704.2617444490131,0.00025370340306410486,25.0,0.0
187.42383,0.009531646653543306,705.7706363075657,0.00025370340306410486,25.0,0.0
188.7251,0.00982908248031496,706.8523591694079,0.00025370340306410486,25.0,0.0
190.02637,0.010115477952755905,708.7240696957236,0.00025370340306410486,25.0,0.0
191.32764,0.010480292519685038,711.2507452713816,0.00025370340306410486,25.0,0.0
192.62891,0.010740854527559055,709.4115953947368,0.00025370340306410486,25.0,0.0
193.93018,0.010978675393700787,709.7892937911184,0.00025370340306410486,25.0,0.0
195.23145,0.011331032874015748,715.0283717105264,0.00025370340306410486,25.0,0.0
196.53271,0.01165989094488189,714.8899568256578,0.00025370340306410486,25.0,0.0
197.83398,0.011944918897637796,713.1355622944079,0.00025370340306410486,25.0,0.0
199.13525,0.012223833267716536,714.3200812088816,0.00025370340306410486,25.0,0.0
200.43652,0.01257440649606299,716.3257349917764,0.00025370340306410486,25.0,0.0
201.73779,0.012977174803149605,717.4216437088816,0.00025370340306410486,25.0,0.0
203.03906,0.013364018503937009,718.5604697779605,0.00025370340306410486,25.0,0.0
204.34033,0.013687807677165353,719.5356702302631,0.00025370340306410486,25.0,0.0
205.6416,0.013984626771653543,719.5216642680922,0.00025370340306410486,25.0,0.0
206.94287,0.014297633267716535,719.877287212171,0.00025370340306410486,25.0,0.0
208.24414,0.014611590354330708,720.2816611842106,0.00025370340306410486,25.0,0.0
209.54541,0.014984953740157481,722.4648951480264,0.00025370340306410486,25.0,0.0
210.84668,0.015298349015748032,721.9826531661184,0.00025370340306410486,25.0,0.0
212.14795,0.01564320964566929,724.0449732730264,0.00025370340306410486,25.0,0.0
213.44922,0.016001427165354333,723.7933285361842,0.00025370340306410486,25.0,0.0
214.75049,0.01632818346456693,724.5802837171053,0.00025370340306410486,25.0,0.0
216.05176,0.016659295866141732,725.1105828536184,0.00025370340306410486,25.0,0.0
217.35303,0.017033542322834643,727.33740234375,0.00025370340306410486,25.0,0.0
218.6543,0.017505650984251966,728.3456774259869,0.00025370340306410486,25.0,0.0
219.95557,0.01783471437007874,726.6245374177632,0.00025370340306410486,25.0,0.0
221.25684,0.01817293543307087,727.6186780427631,0.00025370340306410486,25.0,0.0
222.55811,0.01853558818897638,727.6141550164473,0.00025370340306410486,25.0,0.0
223.85938,0.0188715594488189,730.3712222450658,0.00025370340306410486,25.0,0.0
225.16064,0.01923424133858268,728.8728155838816,0.00025370340306410486,25.0,0.0
226.46191,0.01962297992125984,731.3071546052632,0.00025370340306410486,25.0,0.0
227.76318,0.0200525531496063,729.8894428453947,0.00025370340306410486,25.0,0.0
229.06445,0.020380574803149604,730.8673159950657,0.00025370340306410486,25.0,0.0
230.36572,0.02072703937007874,733.3550318667764,0.00025370340306410486,25.0,0.0
231.66699,0.021124259842519685,732.3967156661183,0.00025370340306410486,25.0,0.0
232.96826,0.021463712598425198,732.9273745888158,0.00025370340306410486,25.0,0.0
234.26953,0.021798318897637795,732.0875822368421,0.00025370340306410486,25.0,0.0
235.5708,0.022107919291338582,734.0745014391447,0.00025370340306410486,25.0,0.0
236.87207,0.0224484468503937,734.9952199835526,0.00025370340306410486,25.0,0.0
238.17334,0.022852326771653542,737.3317228618421,0.00025370340306410486,25.0,0.0
239.47461,0.023220181102362205,737.5403474506579,0.00025370340306410486,25.0,0.0
240.77588,0.023612470472440944,737.5262386924342,0.00025370340306410486,25.0,0.0
242.07715,0.023969852362204724,737.4962993421053,0.00025370340306410486,25.0,0.0
243.37842,0.024375521653543307,740.7040244654605,0.00025370340306410486,25.0,0.0
244.67969,0.02476262992125984,737.5602898848684,0.00025370340306410486,25.0,0.0
245.98096,0.0250583405511811,738.8787006578948,0.00025370340306410486,25.0,0.0
247.28223,0.025418001968503936,740.4599609375,0.00025370340306410486,25.0,0.0
248.5835,0.02583213582677165,741.65771484375,0.00025370340306410486,25.0,0.0
249.88477,0.026249509842519687,740.8411800986842,0.00025370340306410486,25.0,0.0
251.18604,0.026573683070866144,742.1947214226974,0.00025370340306410486,25.0,0.0
252.4873,0.02695182086614173,740.8167917351973,0.00025370340306410486,25.0,0.0
253.78857,0.027354818897637793,742.5238486842105,0.00025370340306410486,25.0,0.0
255.08984,0.027756204724409445,741.764314350329,0.00025370340306410486,25.0,0.0
256.39111,0.028200062992125983,744.56591796875,0.00025370340306410486,25.0,0.0
257.69238,0.0285893562992126,744.2885999177631,0.00025370340306410486,25.0,0.0
258.99365,0.028970206692913388,745.3743318256579,0.00025370340306410486,25.0,0.0
260.29492,0.029328442913385825,745.6716180098684,0.00025370340306410486,25.0,0.0
261.59619,0.029696350393700787,744.2953073601974,0.00025370340306410486,25.0,0.0
262.89746,0.0300793405511811,745.9421001233552,0.00025370340306410486,25.0,0.0
264.19873,0.030451931102362204,746.2416221217105,0.00025370340306410486,25.0,0.0
265.5,0.03075965157480315,745.5056537828947,0.00025370340306410486,25.0,0.0
266.80127,0.031066336614173226,747.5611379523027,0.00025370340306410486,25.0,0.0
268.10254,0.031530499999999996,748.3964329769736,0.00025370340306410486,25.0,0.0
269.40381,0.03193883267716535,746.7273591694079,0.00025370340306410486,25.0,0.0
270.70508,0.03228112204724409,747.838712993421,0.00025370340306410486,25.0,0.0
272.00635,0.03262738582677165,748.5417865953948,0.00025370340306410486,25.0,0.0
273.30762,0.032992714566929135,749.6269017269736,0.00025370340306410486,25.0,0.0
274.60889,0.03336175787401575,750.0761975740131,0.00025370340306410486,25.0,0.0
275.91016,0.033684435039370075,752.8295641447369,0.00025370340306410486,25.0,0.0
277.21143,0.03404686614173228,749.4313579358553,0.00025370340306410486,25.0,0.0
278.5127,0.03440557874015748,750.5048057154605,0.00025370340306410486,25.0,0.0
279.81396,0.03480523228346456,752.2366622121712,0.00025370340306410486,25.0,0.0
281.11523,0.035210751968503935,753.2042043585526,0.00025370340306410486,25.0,0.0
282.4165,0.03561473228346457,751.9289679276316,0.00025370340306410486,25.0,0.0
283.71777,0.03600332283464567,753.4905427631579,0.00025370340306410486,25.0,0.0
285.01904,0.0363760905511811,755.3869757401316,0.00025370340306410486,25.0,0.0
286.32031,0.03680401771653543,754.6384148848684,0.00025370340306410486,25.0,0.0
287.62158,0.0372041220472441,756.5288856907894,0.00025370340306410486,25.0,0.0
288.92285,0.037603226377952756,754.6603618421053,0.00025370340306410486,25.0,0.0
290.22412,0.03800055708661417,755.0827508223684,0.00025370340306410486,25.0,0.0
291.52539,0.0383739311023622,756.9187654194078,0.00025370340306410486,25.0,0.0
292.82666,0.03879139566929134,755.6805612664473,0.00025370340306410486,25.0,0.0
294.12793,0.03914194488188976,756.0297594572368,0.00025370340306410486,25.0,0.0
295.4292,0.03948850196850394,756.7007863898026,0.00025370340306410486,25.0,0.0
296.73047,0.03978331299212598,756.6310906661184,0.00025370340306410486,25.0,0.0
298.03174,0.04019195669291339,758.8514597039474,0.00025370340306410486,25.0,0.0
299.33301,0.04060459645669291,759.3739720394738,0.00025370340306410486,25.0,0.0
300.63428,0.041005627952755905,759.2468390213816,0.00025370340306410486,25.0,0.0
301.93555,0.04138929527559055,759.857267680921,0.00025370340306410486,25.0,0.0
303.23682,0.04172993110236221,759.9055047286184,0.00025370340306410486,25.0,0.0
304.53809,0.0421093562992126,759.5073499177631,0.00025370340306410486,25.0,0.0
305.83936,0.042480476377952756,761.6911492598684,0.00025370340306410486,25.0,0.0
307.14063,0.0428401437007874,761.3407946134869,0.00025370340306410486,25.0,0.0
308.44189,0.04314168700787402,761.0231291118421,0.00025370340306410486,25.0,0.0
309.74316,0.04353440551181102,761.746427837171,0.00025370340306410486,25.0,0.0
311.04443,0.04396633661417323,762.9104646381579,0.00025370340306410486,25.0,0.0
312.3457,0.044342594488188974,763.3253752055921,0.00025370340306410486,25.0,0.0
313.64697,0.04469480118110236,761.5623972039474,0.00025370340306410486,25.0,0.0
314.94824,0.04508593503937008,763.9711657072369,0.00025370340306410486,25.0,0.0
316.24951,0.04544794881889764,763.3787006578947,0.00025370340306410486,25.0,0.0
317.55078,0.04581504330708661,764.4254214638158,0.00025370340306410486,25.0,0.0
318.85205,0.046196911417322836,764.6986019736843,0.00025370340306410486,25.0,0.0
320.15332,0.04659369094488189,764.6890162417762,0.00025370340306410486,25.0,0.0
321.45459,0.04699466535433071,765.8352950246712,0.00025370340306410486,25.0,0.0
322.75586,0.04738583858267717,764.8909076891447,0.00025370340306410486,25.0,0.0
324.05713,0.0477279468503937,764.6870631167762,0.00025370340306410486,25.0,0.0
325.3584,0.04813272440944882,765.8636667351974,0.00025370340306410486,25.0,0.0
326.65967,0.048481100393700786,766.1557874177632,0.00025370340306410486,25.0,0.0
327.96094,0.04885481496062992,766.6162366365131,0.00025370340306410486,25.0,0.0
329.26221,0.04926210039370078,766.119140625,0.00025370340306410486,25.0,0.0
330.56348,0.04963032283464567,767.9917249177631,0.00025370340306410486,25.0,0.0
331.86475,0.04997391338582677,766.8175113075657,0.00025370340306410486,25.0,0.0
333.16602,0.05035131692913385,768.2948961759869,0.00025370340306410486,25.0,0.0
334.46729,0.0507093562992126,767.5369808799343,0.00025370340306410486,25.0,0.0
335.76855,0.051016771653543305,769.2199578536184,0.00025370340306410486,25.0,0.0
337.06982,0.05135610039370078,769.6703330592106,0.00025370340306410486,25.0,0.0
338.37109,0.05175555118110236,769.783203125,0.00025370340306410486,25.0,0.0
339.67236,0.05211999606299213,770.9619911595394,0.00025370340306410486,25.0,0.0
340.97363,0.052490045275590556,771.3610968338816,0.00025370340306410486,25.0,0.0
342.2749,0.05287711614173228,771.67041015625,0.00025370340306410486,25.0,0.0
343.57617,0.05322623818897638,771.986173930921,0.00025370340306410486,25.0,0.0
344.87744,0.05359412598425197,772.3441868832236,0.00025370340306410486,25.0,0.0
346.17871,0.053946598425196855,771.1002775493421,0.00025370340306410486,25.0,0.0
347.47998,0.05434056299212598,774.023591694079,0.00025370340306410486,25.0,0.0
348.78125,0.05470141732283464,772.8375822368422,0.00025370340306410486,25.0,0.0
350.08252,0.05512214763779528,775.8813733552631,0.00025370340306410486,25.0,0.0
351.38379,0.055511736220472445,773.6878083881579,0.00025370340306410486,25.0,0.0
352.68506,0.05588953937007874,773.9992547286184,0.00025370340306410486,25.0,0.0
353.98633,0.05625549212598425,774.4292763157894,0.00025370340306410486,25.0,0.0
355.2876,0.05658979921259843,775.7795538651316,0.00025370340306410486,25.0,0.0
356.58887,0.05700677362204725,776.9415347450657,0.00025370340306410486,25.0,0.0
357.89014,0.05737812401574803,775.7258429276316,0.00025370340306410486,25.0,0.0
359.19141,0.05779724606299212,775.3104183799343,0.00025370340306410486,25.0,0.0
360.49268,0.05818428740157481,775.4743009868421,0.00025370340306410486,25.0,0.0
361.79395,0.05848034645669291,774.438322368421,0.00025370340306410486,25.0,0.0
363.09521,0.058795417322834644,774.9787726151316,0.00025370340306410486,25.0,0.0
364.39648,0.05917046456692913,778.2520816200657,0.00025370340306410486,25.0,0.0
365.69775,0.059568612204724404,777.9415090460527,0.00025370340306410486,25.0,0.0
366.99902,0.05986457677165355,777.5694387335526,0.00025370340306410486,25.0,0.0
368.30029,0.0602425374015748,779.1635228207238,0.00025370340306410486,25.0,0.0
369.60156,0.06063108858267716,780.3128854851974,0.00025370340306410486,25.0,0.0
370.90283,0.06104672440944882,778.5056023848684,0.00025370340306410486,25.0,0.0
372.2041,0.06144345472440945,778.0847296463816,0.00025370340306410486,25.0,0.0
373.50537,0.06184765748031496,781.5914370888157,0.00025370340306410486,25.0,0.0
374.80664,0.062274076771653544,780.1381578947369,0.00025370340306410486,25.0,0.0
376.10791,0.06267225984251967,782.0231548108552,0.00025370340306410486,25.0,0.0
377.40918,0.06301040551181102,780.1053916529605,0.00025370340306410486,25.0,0.0
378.71045,0.06329131496062991,780.6073961759868,0.00025370340306410486,25.0,0.0
380.01172,0.06372397637795275,781.7723838404606,0.00025370340306410486,25.0,0.0
381.31299,0.0640380216535433,781.5717516447369,0.00025370340306410486,25.0,0.0
382.61426,0.06435440748031496,781.1315532483552,0.00025370340306410486,25.0,0.0
383.91553,0.06475558858267716,782.8752055921053,0.00025370340306410486,25.0,0.0
385.2168,0.06512412204724409,784.0539936266447,0.00025370340306410486,25.0,0.0
386.51807,0.06550302362204724,783.45556640625,0.00025370340306410486,25.0,0.0
387.81934,0.06589250590551181,784.7671669407895,0.00025370340306410486,25.0,0.0
389.12061,0.06623864173228347,782.985994037829,0.00025370340306410486,25.0,0.0
390.42188,0.06652510236220473,782.4250359786183,0.00025370340306410486,25.0,0.0
391.72314,0.06684629724409448,785.7028937088816,0.00025370340306410486,25.0,0.0
393.02441,0.06732417322834645,785.3590923108553,0.00025370340306410486,25.0,0.0
394.32568,0.06768805511811024,784.1585886101974,0.00025370340306410486,25.0,0.0
395.62695,0.06804783070866141,785.342130962171,0.00025370340306410486,25.0,0.0
396.92822,0.06846275787401575,786.271484375,0.00025370340306410486,25.0,0.0
398.22949,0.06881285826771653,787.2026110197369,0.00025370340306410486,25.0,0.0
399.53076,0.06924958464566928,787.4188425164473,0.00025370340306410486,25.0,0.0
400.83203,0.06952977952755905,786.4288394325657,0.00025370340306410486,25.0,0.0
402.1333,0.0698987716535433,787.0338969983553,0.00025370340306410486,25.0,0.0
403.43457,0.07024696653543308,787.9558490953948,0.00025370340306410486,25.0,0.0
404.73584,0.07063288779527559,788.218904194079,0.00025370340306410486,25.0,0.0
406.03711,0.07100378149606298,788.9203073601974,0.00025370340306410486,25.0,0.0
407.33838,0.07135391141732284,789.05029296875,0.00025370340306410486,25.0,0.0
408.63965,0.07173379133858268,789.5313527960526,0.00025370340306410486,25.0,0.0
409.94092,0.0720783720472441,788.7020199424342,0.00025370340306410486,25.0,0.0
411.24219,0.07252218503937008,790.7640316611843,0.00025370340306410486,25.0,0.0
412.54346,0.07289055511811024,790.8378135279606,0.00025370340306410486,25.0,0.0
413.84473,0.07320926377952756,790.2183645148026,0.00025370340306410486,25.0,0.0
415.146,0.07353205118110236,789.4616313733553,0.00025370340306410486,25.0,0.0
416.44727,0.0738618877952756,790.8151726973683,0.00025370340306410486,25.0,0.0
417.74854,0.07425158858267716,791.4829872532895,0.00025370340306410486,25.0,0.0
419.0498,0.07456781496062992,791.8228567023026,0.00025370340306410486,25.0,0.0
420.35107,0.07496912598425197,793.1669664884868,0.00025370340306410486,25.0,0.0
421.65234,0.07538302755905511,793.3070775082236,0.00025370340306410486,25.0,0.0
422.95361,0.07585321653543307,794.0614977384869,0.00025370340306410486,25.0,0.0
424.25488,0.07623720275590551,793.1352282072369,0.00025370340306410486,25.0,0.0
425.55615,0.07657920866141732,791.3903937088816,0.00025370340306410486,25.0,0.0
426.85742,0.07690149606299213,793.6849814967105,0.00025370340306410486,25.0,0.0
428.15869,0.07722333267716534,795.3320569490131,0.00025370340306410486,25.0,0.0
429.45996,0.07762010236220472,794.3666735197369,0.00025370340306410486,25.0,0.0
430.76123,0.07801462401574803,795.6095034950658,0.00025370340306410486,25.0,0.0
432.0625,0.07841275,795.5189144736843,0.00025370340306410486,25.0,0.0
433.36377,0.07877486023622048,795.2486122532895,0.00025370340306410486,25.0,0.0
434.66504,0.07909576771653544,795.0227436266448,0.00025370340306410486,25.0,0.0
435.96631,0.0794489311023622,793.6606959292764,0.00025370340306410486,25.0,0.0
437.26758,0.07978726377952755,794.1455078125,0.00025370340306410486,25.0,0.0
438.56885,0.08013341141732284,796.6439915707236,0.00025370340306410486,25.0,0.0
439.87012,0.08047039960629922,796.82763671875,0.00025370340306410486,25.0,0.0
441.17139,0.08087230905511811,797.1666324013158,0.00025370340306410486,25.0,0.0
442.47266,0.08124303149606299,798.599275287829,0.00025370340306410486,25.0,0.0
443.77393,0.08160231299212597,797.0469777960526,0.00025370340306410486,25.0,0.0
445.0752,0.08199427362204724,798.1918431332238,0.00025370340306410486,25.0,0.0
446.37646,0.08238619094488188,797.9260639391448,0.00025370340306410486,25.0,0.0
447.67773,0.08274738582677166,798.4559261924343,0.00025370340306410486,25.0,0.0
448.979,0.08313249803149607,798.7952816611842,0.00025370340306410486,25.0,0.0
450.28027,0.08345512598425196,797.1976254111843,0.00025370340306410486,25.0,0.0
451.58154,0.08375881102362205,797.8288188733553,0.00025370340306410486,25.0,0.0
452.88281,0.08407777755905511,799.4172491776316,0.00025370340306410486,25.0,0.0
454.18408,0.08439382874015748,799.0482627467105,0.00025370340306410486,25.0,0.0
455.48535,0.08476208070866141,800.2035361842105,0.00025370340306410486,25.0,0.0
456.78662,0.08517018503937007,800.0808747944079,0.00025370340306410486,25.0,0.0
458.08789,0.08550825984251968,800.4812140213816,0.00025370340306410486,25.0,0.0
459.38916,0.0859105748031496,800.2941252055921,0.00025370340306410486,25.0,0.0
460.69043,0.08633569094488189,802.1842876233552,0.00025370340306410486,25.0,0.0
461.9917,0.08676429330708661,801.9536389802631,0.00025370340306410486,25.0,0.0
463.29297,0.0870958562992126,802.4001079358553,0.00025370340306410486,25.0,0.0
464.59424,0.08745670472440945,801.6128957648026,0.00025370340306410486,25.0,0.0
465.89551,0.08776038976377952,801.4013157894738,0.00025370340306410486,25.0,0.0
467.19678,0.08807956692913387,802.6529605263157,0.00025370340306410486,25.0,0.0
468.49805,0.08846221653543307,803.1157483552631,0.00025370340306410486,25.0,0.0
469.79932,0.08887150590551181,804.9442845394736,0.00025370340306410486,25.0,0.0
471.10059,0.08924434448818898,804.4296104029605,0.00025370340306410486,25.0,0.0
472.40186,0.08962433070866142,804.6800729851974,0.00025370340306410486,25.0,0.0
473.70313,0.09002719488188976,805.5817999588816,0.00025370340306410486,25.0,0.0
475.00439,0.09038739960629921,802.9072008634869,0.00025370340306410486,25.0,0.0
476.30566,0.09068745275590552,803.5111533717105,0.00025370340306410486,25.0,0.0
477.60693,0.09109284055118111,806.3884662828948,0.00025370340306410486,25.0,0.0
478.9082,0.09142238385826772,805.0208932976974,0.00025370340306410486,25.0,0.0
480.20947,0.09176915354330709,805.9101305509869,0.00025370340306410486,25.0,0.0
481.51074,0.09218894291338582,808.1286235608552,0.00025370340306410486,25.0,0.0
482.81201,0.09250227362204724,805.0897152549343,0.00025370340306410486,25.0,0.0
484.11328,0.09286435826771654,806.3095446134869,0.00025370340306410486,25.0,0.0
485.41455,0.09316446456692913,806.127287212171,0.00025370340306410486,25.0,0.0
486.71582,0.09353998031496064,805.9813425164473,0.00025370340306410486,25.0,0.0
488.01709,0.09389452755905513,807.0738075657895,0.00025370340306410486,25.0,0.0
489.31836,0.09423025,807.323884662829,0.00025370340306410486,25.0,0.0
490.61963,0.09461047637795275,809.9451069078947,0.00025370340306410486,25.0,0.0
491.9209,0.09495245866141731,807.9607319078947,0.00025370340306410486,25.0,0.0
493.22217,0.09534020472440945,808.463224712171,0.00025370340306410486,25.0,0.0
494.52344,0.09568311417322835,809.652497944079,0.00025370340306410486,25.0,0.0
495.82471,0.09607895078740157,808.2980828536184,0.00025370340306410486,25.0,0.0
497.12598,0.09645048818897638,808.893888774671,0.00025370340306410486,25.0,0.0
498.42725,0.09673368700787402,808.472502055921,0.00025370340306410486,25.0,0.0
499.72852,0.09707873031496063,809.7215768914473,0.00025370340306410486,25.0,0.0
501.02979,0.09739391929133859,810.6779399671053,0.00025370340306410486,25.0,0.0
502.33105,0.09782705511811023,811.9411235608552,0.00025370340306410486,25.0,0.0
503.63232,0.09821059645669292,810.5806949013158,0.00025370340306410486,25.0,0.0
504.93359,0.09854550984251968,809.8488641036184,0.00025370340306410486,25.0,0.0
506.23486,0.09891462401574803,813.2334241365131,0.00025370340306410486,25.0,0.0
507.53613,0.09931216732283465,812.0642732319079,0.00025370340306410486,25.0,0.0
508.8374,0.09971849999999999,811.2453227796052,0.00025370340306410486,25.0,0.0
510.13867,0.10011427362204725,812.5621916118421,0.00025370340306410486,25.0,0.0
511.43994,0.10051555905511811,812.0208675986842,0.00025370340306410486,25.0,0.0
512.74121,0.10085979921259844,810.0706722861842,0.00025370340306410486,25.0,0.0
514.04248,0.10120340748031496,813.4805458470395,0.00025370340306410486,25.0,0.0
515.34375,0.10162194094488189,814.0060649671052,0.00025370340306410486,25.0,0.0
516.64502,0.10193925393700788,812.1883994654605,0.00025370340306410486,25.0,0.0
517.94629,0.10232383267716536,813.4622995476974,0.00025370340306410486,25.0,0.0
519.24756,0.10262589370078741,814.7168225740131,0.00025370340306410486,25.0,0.0
520.54883,0.10302833070866142,813.9228258634869,0.00025370340306410486,25.0,0.0
521.8501,0.10343592913385827,812.7160516036184,0.00025370340306410486,25.0,0.0
523.15137,0.1037912342519685,815.1727487664474,0.00025370340306410486,25.0,0.0
524.45264,0.10411121062992126,814.7513877467105,0.00025370340306410486,25.0,0.0
525.75391,0.10439811023622048,814.7370733963816,0.00025370340306410486,25.0,0.0
527.05518,0.10476810433070867,815.1498509457236,0.00025370340306410486,25.0,0.0
528.35645,0.10513775984251969,815.958162006579,0.00025370340306410486,25.0,0.0
529.65771,0.10550889173228346,815.951814350329,0.00025370340306410486,25.0,0.0
530.95898,0.10586559251968504,816.6314504523026,0.00025370340306410486,25.0,0.0
532.26025,0.10620415354330708,816.6957493832236,0.00025370340306410486,25.0,0.0
533.56152,0.10657737598425197,816.6344572368421,0.00025370340306410486,25.0,0.0
534.86279,0.10697904921259843,816.3779553865131,0.00025370340306410486,25.0,0.0
536.16406,0.1073764527559055,816.4670538651316,0.00025370340306410486,25.0,0.0
537.46533,0.10772329921259843,817.3742547286184,0.00025370340306410486,25.0,0.0
538.7666,0.10810996653543307,818.2124794407895,0.00025370340306410486,25.0,0.0
540.06787,0.10848547440944882,817.439119037829,0.00025370340306410486,25.0,0.0
541.36914,0.10892192716535433,820.1324270148027,0.00025370340306410486,25.0,0.0
542.67041,0.10925468110236221,819.1372841282895,0.00025370340306410486,25.0,0.0
543.97168,0.10964954921259841,819.9590100740131,0.00025370340306410486,25.0,0.0
545.27295,0.11001577755905512,819.693359375,0.00025370340306410486,25.0,0.0
546.57422,0.11039156889763778,819.1955694901316,0.00025370340306410486,25.0,0.0
547.87549,0.11076968307086614,819.7781404194079,0.00025370340306410486,25.0,0.0
549.17676,0.11105429527559055,817.4537417763158,0.00025370340306410486,25.0,0.0
550.47803,0.11139792519685039,821.7098324424343,0.00025370340306410486,25.0,0.0
551.7793,0.11182692519685038,821.6041067023026,0.00025370340306410486,25.0,0.0
553.08057,0.11218562204724408,818.754240337171,0.00025370340306410486,25.0,0.0
554.38184,0.11255923031496062,820.0297337582236,0.00025370340306410486,25.0,0.0
555.68311,0.11296524606299213,819.4913394325658,0.00025370340306410486,25.0,0.0
556.98438,0.11329078346456692,820.2309313322369,0.00025370340306410486,25.0,0.0
558.28564,0.1136404901574803,821.5286287006579,0.00025370340306410486,25.0,0.0
559.58691,0.11395624212598425,821.5178865131579,0.00025370340306410486,25.0,0.0
560.88818,0.11432274212598426,822.6461245888157,0.00025370340306410486,25.0,0.0
562.18945,0.11468144881889762,821.4185084292762,0.00025370340306410486,25.0,0.0
563.49072,0.11506678937007875,821.258634868421,0.00025370340306410486,25.0,0.0
564.79199,0.11537708661417322,822.9028577302631,0.00025370340306410486,25.0,0.0
566.09326,0.11576746062992126,821.9872532894736,0.00025370340306410486,25.0,0.0
567.39453,0.11612533661417324,822.3054841694078,0.00025370340306410486,25.0,0.0
568.6958,0.11651510039370079,823.3038394325658,0.00025370340306410486,25.0,0.0
569.99707,0.11688860433070866,823.6757041529605,0.00025370340306410486,25.0,0.0
571.29834,0.11730054527559056,822.9371145148026,0.00025370340306410486,25.0,0.0
572.59961,0.11763640748031497,821.6745476973684,0.00025370340306410486,25.0,0.0
573.90088,0.11797871259842521,825.00244140625,0.00025370340306410486,25.0,0.0
575.20215,0.11834919881889763,824.9989206414474,0.00025370340306410486,25.0,0.0
576.50342,0.11875399409448818,825.1027703536184,0.00025370340306410486,25.0,0.0
577.80469,0.11917602559055117,826.7772923519736,0.00025370340306410486,25.0,0.0
579.10596,0.11954586811023622,824.209138569079,0.00025370340306410486,25.0,0.0
580.40723,0.11996313582677165,825.7512592516448,0.00025370340306410486,25.0,0.0
581.7085,0.12035820472440945,824.0401161595395,0.00025370340306410486,25.0,0.0
583.00977,0.12073469881889765,825.6920487253288,0.00025370340306410486,25.0,0.0
584.31104,0.12108579133858267,824.2884457236842,0.00025370340306410486,25.0,0.0
585.6123,0.12141840354330707,825.9781301398026,0.00025370340306410486,25.0,0.0
586.91357,0.12180747637795275,825.019197162829,0.00025370340306410486,25.0,0.0
588.21484,0.12215790157480315,824.8822985197369,0.00025370340306410486,25.0,0.0
589.51611,0.12247568307086613,826.056306537829,0.00025370340306410486,25.0,0.0
590.81738,0.12285035826771652,828.1143606085526,0.00025370340306410486,25.0,0.0
592.11865,0.12319924606299214,826.0432771381578,0.00025370340306410486,25.0,0.0
593.41992,0.1236082657480315,826.0444078947369,0.00025370340306410486,25.0,0.0
594.72119,0.12392656299212598,825.3664679276317,0.00025370340306410486,25.0,0.0
596.02246,0.12425596062992125,826.5598273026316,0.00025370340306410486,25.0,0.0
597.32373,0.12461178149606297,828.0389597039474,0.00025370340306410486,25.0,0.0
598.625,0.1250320059055118,828.1936677631579,0.00025370340306410486,25.0,0.0
599.92627,0.1254406377952756,827.4155530427631,0.00025370340306410486,25.0,0.0
601.22754,0.12581671062992125,828.5527600740131,0.00025370340306410486,25.0,0.0
602.52881,0.1261888877952756,826.8706311677631,0.00025370340306410486,25.0,0.0
603.83008,0.12653596850393703,827.6000719572368,0.00025370340306410486,25.0,0.0
605.13135,0.12687606692913386,827.7606393914474,0.00025370340306410486,25.0,0.0
606.43262,0.12726608858267716,828.0815686677632,0.00025370340306410486,25.0,0.0
607.73389,0.1277400748031496,831.2697111430921,0.00025370340306410486,25.0,0.0
609.03516,0.12809980314960628,827.817228618421,0.00025370340306410486,25.0,0.0
610.33643,0.12846353346456693,830.920255962171,0.00025370340306410486,25.0,0.0
611.6377,0.12890450196850392,829.6514185855262,0.00025370340306410486,25.0,0.0
612.93896,0.12922769291338584,828.3993369654606,0.00025370340306410486,25.0,0.0
614.24023,0.12956544488188976,829.3459344161184,0.00025370340306410486,25.0,0.0
615.5415,0.12992466732283464,830.8891344572369,0.00025370340306410486,25.0,0.0
616.84277,0.13032082677165355,832.4000822368421,0.00025370340306410486,25.0,0.0
618.14404,0.13078008858267715,831.7175678453947,0.00025370340306410486,25.0,0.0
619.44531,0.13122176181102363,830.648771587171,0.00025370340306410486,25.0,0.0
620.74658,0.1316213464566929,831.7326788651316,0.00025370340306410486,25.0,0.0
622.04785,0.13194330511811025,830.1502107319078,0.00025370340306410486,25.0,0.0
623.34912,0.13229528937007873,829.904142680921,0.00025370340306410486,25.0,0.0
624.65039,0.13265058267716534,830.9735814144736,0.00025370340306410486,25.0,0.0
625.95166,0.1330376496062992,831.3825298108552,0.00025370340306410486,25.0,0.0
627.25293,0.13348280708661417,831.4855571546052,0.00025370340306410486,25.0,0.0
628.5542,0.13384931692913385,831.6732113486842,0.00025370340306410486,25.0,0.0
629.85547,0.13420981889763778,830.7168482730264,0.00025370340306410486,25.0,0.0
631.15674,0.13454734842519686,830.9400699013157,0.00025370340306410486,25.0,0.0
632.45801,0.13492817322834644,832.4438733552631,0.00025370340306410486,25.0,0.0
633.75928,0.1353837618110236,833.1565583881578,0.00025370340306410486,25.0,0.0
635.06055,0.1357236594488189,832.8533100328948,0.00025370340306410486,25.0,0.0
636.36182,0.13607698228346457,832.5466437088816,0.00025370340306410486,25.0,0.0
637.66309,0.13646732086614172,834.1316046463816,0.00025370340306410486,25.0,0.0
638.96436,0.13691143503937006,832.7860557154605,0.00025370340306410486,25.0,0.0
640.26563,0.13733128346456694,835.0324578536184,0.00025370340306410486,25.0,0.0
641.56689,0.1377441161417323,833.5253392269736,0.00025370340306410486,25.0,0.0
642.86816,0.1381173031496063,831.7690172697369,0.00025370340306410486,25.0,0.0
644.16943,0.1384407283464567,833.2656506990131,0.00025370340306410486,25.0,0.0
645.4707,0.13887313188976377,835.3758994654605,0.00025370340306410486,25.0,0.0
646.77197,0.13924785433070866,835.1043636924343,0.00025370340306410486,25.0,0.0
648.07324,0.13972885826771653,835.5641447368422,0.00025370340306410486,25.0,0.0
649.37451,0.14014273425196852,834.3534128289474,0.00025370340306410486,25.0,0.0
650.67578,0.14049816732283466,835.1531147203948,0.00025370340306410486,25.0,0.0
651.97705,0.14089586417322833,835.7064915707236,0.00025370340306410486,25.0,0.0
653.27832,0.141332937007874,834.6982935855264,0.00025370340306410486,25.0,0.0
654.57959,0.14174958464566928,835.1546309621712,0.00025370340306410486,25.0,0.0
655.88086,0.14209078543307085,835.1203741776316,0.00025370340306410486,25.0,0.0
657.18213,0.14248067913385826,834.6557103207236,0.00025370340306410486,25.0,0.0
658.4834,0.14280403543307088,834.9706517269738,0.00025370340306410486,25.0,0.0
659.78467,0.14319965551181102,837.3874126233552,0.00025370340306410486,25.0,0.0
661.08594,0.14361716929133858,836.141935649671,0.00025370340306410486,25.0,0.0
662.38721,0.14398430118110236,836.6200914884868,0.00025370340306410486,25.0,0.0
663.68848,0.1443235433070866,834.7927888569078,0.00025370340306410486,25.0,0.0
664.98975,0.14473049606299213,837.1940532483552,0.00025370340306410486,25.0,0.0
666.29102,0.14509783858267716,835.266935649671,0.00025370340306410486,25.0,0.0
667.59229,0.14544331102362207,836.4102590460526,0.00025370340306410486,25.0,0.0
668.89355,0.14593433464566927,840.0964740953948,0.00025370340306410486,25.0,0.0
670.19482,0.14638553543307087,837.6425267269736,0.00025370340306410486,25.0,0.0
671.49609,0.1467208937007874,836.9584446957236,0.00025370340306410486,25.0,0.0
672.79736,0.14713012401574804,837.6792249177632,0.00025370340306410486,25.0,0.0
674.09863,0.14750184251968504,839.1591796875,0.00025370340306410486,25.0,0.0
675.3999,0.14794465354330708,836.9570055509869,0.00025370340306410486,25.0,0.0
676.70117,0.14832010433070866,836.7887798108553,0.00025370340306410486,25.0,0.0
678.00244,0.14873594094488188,837.565275493421,0.00025370340306410486,25.0,0.0
679.30371,0.1491709960629921,838.029939350329,0.00025370340306410486,25.0,0.0
680.60498,0.14956963188976377,838.7409282483553,0.00025370340306410486,25.0,0.0
681.90625,0.1499747440944882,839.2532123766447,0.00025370340306410486,25.0,0.0
683.20752,0.15040941141732284,838.5773797286183,0.00025370340306410486,25.0,0.0
684.50879,0.15087780118110236,838.73974609375,0.00025370340306410486,25.0,0.0
685.81006,0.1512836751968504,840.199372944079,0.00025370340306410486,25.0,0.0
687.11133,0.15169892519685038,838.6952097039474,0.00025370340306410486,25.0,0.0
688.4126,0.15211454921259843,838.7685546875,0.00025370340306410486,25.0,0.0
689.71387,0.1524848622047244,838.2947933799342,0.00025370340306410486,25.0,0.0
691.01514,0.15288190157480314,840.1852641858552,0.00025370340306410486,25.0,0.0
692.31641,0.15324597047244093,838.7303402549342,0.00025370340306410486,25.0,0.0
693.61768,0.15366560826771652,840.010896381579,0.00025370340306410486,25.0,0.0
694.91895,0.1539941968503937,838.278166118421,0.00025370340306410486,25.0,0.0
696.22021,0.15443149212598425,840.1878854851974,0.00025370340306410486,25.0,0.0
697.52148,0.15487764763779527,840.3186420641448,0.00025370340306410486,25.0,0.0
698.82275,0.1553041023622047,840.0200452302632,0.00025370340306410486,25.0,0.0
700.12402,0.15579045472440944,841.8099557976974,0.00025370340306410486,25.0,0.0
701.42529,0.15616974212598425,841.5272923519736,0.00025370340306410486,25.0,0.0
702.72656,0.15652304133858266,840.7411338404605,0.00025370340306410486,25.0,0.0
704.02783,0.1569099311023622,841.2311626233553,0.00025370340306410486,25.0,0.0
705.3291,0.1573972460629921,839.6970086348684,0.00025370340306410486,25.0,0.0
706.63037,0.1577712657480315,839.1509560032895,0.00025370340306410486,25.0,0.0
707.93164,0.15814367716535432,842.097810444079,0.00025370340306410486,25.0,0.0
709.23291,0.15858016338582676,839.3075657894736,0.00025370340306410486,25.0,0.0
710.53418,0.1590362559055118,842.2354029605264,0.00025370340306410486,25.0,0.0
711.83545,0.1595141496062992,841.2092670641448,0.00025370340306410486,25.0,0.0
713.13672,0.15993960826771653,841.6740594161184,0.00025370340306410486,25.0,0.0
714.43799,0.16040892322834643,840.8817588404605,0.00025370340306410486,25.0,0.0
715.73926,0.16077544488188975,841.16796875,0.00025370340306410486,25.0,0.0
717.04053,0.16116930511811023,841.6786338404605,0.00025370340306410486,25.0,0.0
718.3418,0.16159613582677165,840.5664833470395,0.00025370340306410486,25.0,0.0
719.64307,0.16195901968503937,841.2678094161184,0.00025370340306410486,25.0,0.0
720.94434,0.16241345866141732,842.1469983552631,0.00025370340306410486,25.0,0.0
722.24561,0.16286952755905512,842.3029656661184,0.00025370340306410486,25.0,0.0
723.54688,0.1632342066929134,842.8568564967105,0.00025370340306410486,25.0,0.0
724.84814,0.16367805118110235,842.4597553453947,0.00025370340306410486,25.0,0.0
726.14941,0.16410727362204724,843.2858758223683,0.00025370340306410486,25.0,0.0
727.45068,0.16457899606299212,843.3993883634869,0.00025370340306410486,25.0,0.0
728.75195,0.1650426909448819,843.0292711759869,0.00025370340306410486,25.0,0.0
730.05322,0.1655134153543307,843.2537006578947,0.00025370340306410486,25.0,0.0
731.35449,0.16594864763779527,842.7727179276316,0.00025370340306410486,25.0,0.0
732.65576,0.1664308346456693,844.1429893092106,0.00025370340306410486,25.0,0.0
733.95703,0.16690229724409447,842.3811420641448,0.00025370340306410486,25.0,0.0
735.2583,0.16730499409448818,843.2717670641448,0.00025370340306410486,25.0,0.0
736.55957,0.16773115551181103,843.742341694079,0.00025370340306410486,25.0,0.0
737.86084,0.1681003405511811,842.64404296875,0.00025370340306410486,25.0,0.0
739.16211,0.16852917716535432,844.6597450657894,0.00025370340306410486,25.0,0.0
740.46338,0.16897969685039368,845.2337068256578,0.00025370340306410486,25.0,0.0
741.76465,0.1693570118110236,844.2716128700657,0.00025370340306410486,25.0,0.0
743.06592,0.1698294960629921,844.0979646381579,0.00025370340306410486,25.0,0.0
744.36719,0.17019233267716535,842.3979749177631,0.00025370340306410486,25.0,0.0
745.66846,0.17055030118110237,842.7749794407895,0.00025370340306410486,25.0,0.0
746.96973,0.17098362007874016,845.073087993421,0.00025370340306410486,25.0,0.0
748.271,0.17146394291338582,843.8687037417764,0.00025370340306410486,25.0,0.0
749.57227,0.17189226377952754,844.198396381579,0.00025370340306410486,25.0,0.0
750.87354,0.1723563937007874,844.1058542351973,0.00025370340306410486,25.0,0.0
752.1748,0.17280639566929135,844.5790501644736,0.00025370340306410486,25.0,0.0
753.47607,0.1732584527559055,845.5013620476974,0.00025370340306410486,25.0,0.0
754.77734,0.17369824803149606,843.6238178453947,0.00025370340306410486,25.0,0.0
756.07861,0.17417546062992126,845.870271381579,0.00025370340306410486,25.0,0.0
757.37988,0.17469312992125985,844.7346062911184,0.00025370340306410486,25.0,0.0
758.68115,0.1751251220472441,844.32275390625,0.00025370340306410486,25.0,0.0
759.98242,0.17551524015748032,842.6910978618421,0.00025370340306410486,25.0,0.0
761.28369,0.17591426181102363,845.0459241365131,0.00025370340306410486,25.0,0.0
762.58496,0.17640735039370078,845.7052580180922,0.00025370340306410486,25.0,0.0
763.88623,0.17685297637795275,845.1859066611843,0.00025370340306410486,25.0,0.0
765.1875,0.1773053976377953,845.3292043585526,0.00025370340306410486,25.0,0.0
766.48877,0.17780671062992126,844.9042454769738,0.00025370340306410486,25.0,0.0
767.79004,0.17825110433070868,845.3642578125,0.00025370340306410486,25.0,0.0
769.09131,0.17865237992125985,844.7673982319079,0.00025370340306410486,25.0,0.0
770.39258,0.1790665374015748,844.1189607319078,0.00025370340306410486,25.0,0.0
771.69385,0.17952585826771653,845.8881064967105,0.00025370340306410486,25.0,0.0
772.99512,0.18001224606299213,845.5254420230264,0.00025370340306410486,25.0,0.0
774.29639,0.18052916338582678,845.2214740953947,0.00025370340306410486,25.0,0.0
775.59766,0.18105881102362206,844.9307925575657,0.00025370340306410486,25.0,0.0
776.89893,0.18155139566929135,844.3585269325658,0.00025370340306410486,25.0,0.0
778.2002,0.18198622637795275,844.9157329358553,0.00025370340306410486,25.0,0.0
779.50146,0.18237341141732283,844.9376284950658,0.00025370340306410486,25.0,0.0
780.80273,0.18279666338582676,845.7422902960527,0.00025370340306410486,25.0,0.0
782.104,0.18330880511811024,845.4330283717105,0.00025370340306410486,25.0,0.0
783.40527,0.18368953543307087,843.2119140625,0.00025370340306410486,25.0,0.0
784.70654,0.1841423779527559,845.6423468338817,0.00025370340306410486,25.0,0.0
786.00781,0.18461259842519684,846.2986225328948,0.00025370340306410486,25.0,0.0
787.30908,0.18510509842519685,847.4777960526316,0.00025370340306410486,25.0,0.0
788.61035,0.185644062992126,846.4662571957236,0.00025370340306410486,25.0,0.0
789.91162,0.18613453543307087,845.6948499177632,0.00025370340306410486,25.0,0.0
791.21289,0.18668204133858265,846.8017578125,0.00025370340306410486,25.0,0.0
792.51416,0.18717989173228347,846.6234323601974,0.00025370340306410486,25.0,0.0
793.81543,0.187591,845.2332699424343,0.00025370340306410486,25.0,0.0
795.1167,0.18803137007874016,845.7556537828947,0.00025370340306410486,25.0,0.0
796.41797,0.18855333267716534,845.8160207648027,0.00025370340306410486,25.0,0.0
797.71924,0.1890060590551181,845.9480108963816,0.00025370340306410486,25.0,0.0
799.02051,0.18943970669291338,847.1825914884869,0.00025370340306410486,25.0,0.0
800.32178,0.18998839763779526,846.9553351151316,0.00025370340306410486,25.0,0.0
801.62305,0.19058677952755906,847.0527086759869,0.00025370340306410486,25.0,0.0
802.92432,0.19105618897637794,845.4909539473684,0.00025370340306410486,25.0,0.0
804.22559,0.19148358267716534,845.6134868421052,0.00025370340306410486,25.0,0.0
805.52686,0.19195651181102363,847.9568256578947,0.00025370340306410486,25.0,0.0
806.82813,0.1924337716535433,845.405427631579,0.00025370340306410486,25.0,0.0
808.12939,0.19286251377952754,846.7675524259868,0.00025370340306410486,25.0,0.0
809.43066,0.19325372244094488,844.999177631579,0.00025370340306410486,25.0,0.0
810.73193,0.1937372598425197,846.1535516036184,0.00025370340306410486,25.0,0.0
812.0332,0.19422202755905513,846.0615234375,0.00025370340306410486,25.0,0.0
813.33447,0.19470671456692915,846.0359786184212,0.00025370340306410486,25.0,0.0
814.63574,0.19518621653543308,847.1276212993421,0.00025370340306410486,25.0,0.0
815.93701,0.19576791141732283,847.297029194079,0.00025370340306410486,25.0,0.0
817.23828,0.19630272244094488,846.9809313322368,0.00025370340306410486,25.0,0.0
818.53955,0.19682886417322834,847.068205180921,0.00025370340306410486,25.0,0.0
819.84082,0.1973976771653543,848.3117547286184,0.00025370340306410486,25.0,0.0
821.14209,0.19795435039370077,845.8749229029605,0.00025370340306410486,25.0,0.0
822.44336,0.19838889763779527,845.174470600329,0.00025370340306410486,25.0,0.0
823.74463,0.1987707874015748,845.18212890625,0.00025370340306410486,25.0,0.0
825.0459,0.19930393700787402,847.7958984375,0.00025370340306410486,25.0,0.0
826.34717,0.19988076771653546,846.2079050164474,0.00025370340306410486,25.0,0.0
827.64844,0.20039657480314962,845.2181332236843,0.00025370340306410486,25.0,0.0
828.94971,0.20087590551181103,846.7452199835526,0.00025370340306410486,25.0,0.0
830.25098,0.2014406692913386,846.0970908717105,0.00025370340306410486,25.0,0.0
831.55225,0.20185818897637792,846.5694130345395,0.00025370340306410486,25.0,0.0
832.85352,0.20244627952755906,847.8827868009869,0.00025370340306410486,25.0,0.0
834.15479,0.20297305118110234,846.8360145970394,0.00025370340306410486,25.0,0.0
835.45605,0.2035018503937008,846.9118523848684,0.00025370340306410486,25.0,0.0
836.75732,0.2040398818897638,846.8107267680921,0.00025370340306410486,25.0,0.0
838.05859,0.20453003937007871,845.5913342927631,0.00025370340306410486,25.0,0.0
839.35986,0.2050746062992126,845.4667197779605,0.00025370340306410486,25.0,0.0
840.66113,0.20556440944881887,846.1499794407895,0.00025370340306410486,25.0,0.0
841.9624,0.20608226377952757,845.8639494243421,0.00025370340306410486,25.0,0.0
843.26367,0.2066217519685039,847.2731805098684,0.00025370340306410486,25.0,0.0
844.06445,0.20695316929133856,849.2975431743421,0.00025370340306410486,25.0,0.0