File: datasets/am_bench_2022/csv/0-XY.10-4.csv
Time(s),Strain(%),Stress(MPa),SR(s-1),Temp(C),Angle(deg)
17.913086,8.233011023622047e-06,11.814423508986927,0.00025370340306410486,25.0,0.0
19.314453,5.878078346456693e-05,16.75825878267974,0.00025370340306410486,25.0,0.0
20.615723,5.040303937007874e-05,20.60687806372549,0.00025370340306410486,25.0,0.0
21.916992,5.9806848425196854e-05,25.506592371323528,0.00025370340306410486,25.0,0.0
23.218262,7.953345275590552e-05,29.721364379084964,0.00025370340306410486,25.0,0.0
24.519531,9.570753937007874e-05,33.81873723447712,0.00025370340306410486,25.0,0.0
25.820801,0.00013222451181102362,38.52804074754902,0.00025370340306410486,25.0,0.0
27.12207,0.00015576661023622047,42.347748161764706,0.00025370340306410486,25.0,0.0
28.42334,0.00017047176771653545,47.499678308823526,0.00025370340306410486,25.0,0.0
29.724609,0.0001889327283464567,55.10278799019608,0.00025370340306410486,25.0,0.0
31.025879,0.00020060244094488187,60.76042432598039,0.00025370340306410486,25.0,0.0
32.327148,0.0002513066929133858,66.32199499591503,0.00025370340306410486,25.0,0.0
33.628418,0.000292345,74.63911100898693,0.00025370340306410486,25.0,0.0
34.929688,0.00029524068897637796,80.56891595179738,0.00025370340306410486,25.0,0.0
36.230957,0.000292393405511811,85.95263225081699,0.00025370340306410486,25.0,0.0
37.532227,0.0003567622244094488,92.5035258374183,0.00025370340306410486,25.0,0.0
38.833496,0.000399859094488189,100.03120404411763,0.00025370340306410486,25.0,0.0
40.134766,0.00040796259842519687,107.05521599264705,0.00025370340306410486,25.0,0.0
41.436035,0.00044065921259842523,116.09770986519608,0.00025370340306410486,25.0,0.0
42.737305,0.0004807496850393701,123.91815767973856,0.00025370340306410486,25.0,0.0
44.038574,0.0004917734645669291,131.71032475490196,0.00025370340306410486,25.0,0.0
45.339844,0.0005366689960629921,141.05439899918298,0.00025370340306410486,25.0,0.0
46.641113,0.0005627163779527559,148.76716196895424,0.00025370340306410486,25.0,0.0
47.942383,0.0006012136811023622,157.04363766339867,0.00025370340306410486,25.0,0.0
49.243652,0.0006334354330708662,166.54645629084965,0.00025370340306410486,25.0,0.0
50.544922,0.0006578880118110235,172.98701491013068,0.00025370340306410486,25.0,0.0
51.846191,0.0006973153937007874,184.03235549428103,0.00025370340306410486,25.0,0.0
53.147461,0.0007379294094488188,190.13922079248366,0.00025370340306410486,25.0,0.0
54.44873,0.0007600645078740157,197.90231821895424,0.00025370340306410486,25.0,0.0
55.75,0.0007796797834645668,208.76041411356206,0.00025370340306410486,25.0,0.0
57.05127,0.0008251633464566928,216.64937448937906,0.00025370340306410486,25.0,0.0
58.352539,0.0008521966338582678,225.69240196078428,0.00025370340306410486,25.0,0.0
59.653809,0.0009134294488188976,233.78688470179736,0.00025370340306410486,25.0,0.0
60.955078,0.000931927283464567,243.2505438112745,0.00025370340306410486,25.0,0.0
62.256348,0.0009757840551181102,253.1065665849673,0.00025370340306410486,25.0,0.0
63.557617,0.0009906117913385825,261.69064031862746,0.00025370340306410486,25.0,0.0
64.858887,0.0010435359448818897,271.24744689542484,0.00025370340306410486,25.0,0.0
66.160156,0.0010832795866141732,282.99813623366015,0.00025370340306410486,25.0,0.0
67.461426,0.0011067942913385825,291.4969362745098,0.00025370340306410486,25.0,0.0
68.762695,0.0011614043503937008,301.50439133986924,0.00025370340306410486,25.0,0.0
70.063965,0.001187454153543307,310.1278850081699,0.00025370340306410486,25.0,0.0
71.365234,0.0012311108267716534,317.63613153594764,0.00025370340306410486,25.0,0.0
72.666504,0.0012780657874015748,330.9499846813725,0.00025370340306410486,25.0,0.0
73.967773,0.001328891811023622,338.8328737745098,0.00025370340306410486,25.0,0.0
75.269043,0.0013522782677165353,346.8295547385621,0.00025370340306410486,25.0,0.0
76.570313,0.0013911425590551181,356.7270220588235,0.00025370340306410486,25.0,0.0
77.871582,0.0014233979527559055,365.8888122957516,0.00025370340306410486,25.0,0.0
79.172852,0.0014416064960629921,372.80987030228755,0.00025370340306410486,25.0,0.0
80.474121,0.0014961810826771653,383.715150122549,0.00025370340306410486,25.0,0.0
81.775391,0.0014991872637795276,393.0329605800653,0.00025370340306410486,25.0,0.0
83.07666,0.001577512125984252,403.08902675653593,0.00025370340306410486,25.0,0.0
84.37793,0.0016252543307086614,411.64310151143786,0.00025370340306410486,25.0,0.0
85.679199,0.0016665491338582678,421.6620710784313,0.00025370340306410486,25.0,0.0
86.980469,0.0016949222047244095,429.16671772875816,0.00025370340306410486,25.0,0.0
88.281738,0.0017250866141732286,438.64103349673195,0.00025370340306410486,25.0,0.0
89.583008,0.0017831677755905512,449.49900428921563,0.00025370340306410486,25.0,0.0
90.884277,0.0018161879133858265,455.19184027777777,0.00025370340306410486,25.0,0.0
92.185547,0.001842399153543307,463.6866830065359,0.00025370340306410486,25.0,0.0
93.486816,0.0019157857283464564,476.2667738970588,0.00025370340306410486,25.0,0.0
94.788086,0.001946172874015748,483.0120506535947,0.00025370340306410486,25.0,0.0
96.089355,0.0020002271653543307,490.30006638071893,0.00025370340306410486,25.0,0.0
97.390625,0.0020408820866141732,498.3641237745098,0.00025370340306410486,25.0,0.0
98.691895,0.002070209448818898,505.8740042892157,0.00025370340306410486,25.0,0.0
99.993164,0.0021451496062992125,516.3720383986928,0.00025370340306410486,25.0,0.0
101.29443,0.002162632086614173,522.3042024101306,0.00025370340306410486,25.0,0.0
102.5957,0.002224624803149606,529.8054789624183,0.00025370340306410486,25.0,0.0
103.89697,0.0022666259842519685,537.9598396650326,0.00025370340306410486,25.0,0.0
105.19824,0.0023149633858267713,541.0841503267974,0.00025370340306410486,25.0,0.0
106.49951,0.0023548862204724407,548.7134140114379,0.00025370340306410486,25.0,0.0
107.80078,0.002419820472440945,557.5862694035948,0.00025370340306410486,25.0,0.0
109.10205,0.0024715525590551183,561.5367647058823,0.00025370340306410486,25.0,0.0
110.40332,0.002507199803149606,566.7304942810457,0.00025370340306410486,25.0,0.0
111.70459,0.002534951968503937,573.1209150326797,0.00025370340306410486,25.0,0.0
113.00586,0.002605807086614173,579.4304534313725,0.00025370340306410486,25.0,0.0
114.30713,0.0026605244094488186,584.5208843954248,0.00025370340306410486,25.0,0.0
115.6084,0.0027443746062992126,591.0009446486928,0.00025370340306410486,25.0,0.0
116.90967,0.002796253346456693,595.1744281045751,0.00025370340306410486,25.0,0.0
118.21094,0.002859830905511811,601.9500612745097,0.00025370340306410486,25.0,0.0
119.51221,0.002916459251968504,604.5999029820262,0.00025370340306410486,25.0,0.0
120.81348,0.002955234842519685,609.289675245098,0.00025370340306410486,25.0,0.0
122.11475,0.0030493342519685037,614.4529973447712,0.00025370340306410486,25.0,0.0
123.41602,0.003135366732283465,620.9856004901961,0.00025370340306410486,25.0,0.0
124.71729,0.0031847407480314963,622.0170547385621,0.00025370340306410486,25.0,0.0
126.01855,0.003246831692913386,627.8276143790849,0.00025370340306410486,25.0,0.0
127.31982,0.0033226322834645668,631.078329248366,0.00025370340306410486,25.0,0.0
128.62109,0.0034131141732283462,636.2319240196077,0.00025370340306410486,25.0,0.0
129.92236,0.0035071750000000004,640.0378880718954,0.00025370340306410486,25.0,0.0
131.22363,0.003587032874015748,642.1054942810457,0.00025370340306410486,25.0,0.0
132.5249,0.0036712826771653547,647.4914470996732,0.00025370340306410486,25.0,0.0
133.82617,0.00375084625984252,651.0522620506536,0.00025370340306410486,25.0,0.0
135.12744,0.0038796706692913385,652.702920751634,0.00025370340306410486,25.0,0.0
136.42871,0.003973806299212598,657.5298968545752,0.00025370340306410486,25.0,0.0
137.72998,0.004095450393700788,660.7177798202613,0.00025370340306410486,25.0,0.0
139.03125,0.004200410039370079,662.5751378676471,0.00025370340306410486,25.0,0.0
140.33252,0.004318152952755906,667.0539215686274,0.00025370340306410486,25.0,0.0
141.63379,0.004473626968503937,669.4552440767974,0.00025370340306410486,25.0,0.0
142.93506,0.004577687401574803,672.5986264297385,0.00025370340306410486,25.0,0.0
144.23633,0.004727249606299212,673.5132250816993,0.00025370340306410486,25.0,0.0
145.5376,0.004861628149606299,675.2354473039215,0.00025370340306410486,25.0,0.0
146.83887,0.0049908,678.005540236928,0.00025370340306410486,25.0,0.0
148.14014,0.00514469153543307,680.5534109477125,0.00025370340306410486,25.0,0.0
149.44141,0.005298747047244094,682.644939746732,0.00025370340306410486,25.0,0.0
150.74268,0.005484597440944881,684.0551215277777,0.00025370340306410486,25.0,0.0
152.04395,0.005635599015748032,687.0741676879084,0.00025370340306410486,25.0,0.0
153.34521,0.005820961811023622,687.4315002042483,0.00025370340306410486,25.0,0.0
154.64648,0.006036753346456693,692.4356872957516,0.00025370340306410486,25.0,0.0
155.94775,0.006270841929133858,692.6626327614379,0.00025370340306410486,25.0,0.0
157.24902,0.006506182874015747,695.2325622957516,0.00025370340306410486,25.0,0.0
158.55029,0.006658173228346457,694.9204197303922,0.00025370340306410486,25.0,0.0
159.85156,0.006895232283464567,699.6160896650326,0.00025370340306410486,25.0,0.0
161.15283,0.007161916732283465,700.1125153186274,0.00025370340306410486,25.0,0.0
162.4541,0.0074370303149606295,702.7408598856208,0.00025370340306410486,25.0,0.0
163.75537,0.007685641338582677,702.4750561683006,0.00025370340306410486,25.0,0.0
165.05664,0.00794554251968504,704.5212928921568,0.00025370340306410486,25.0,0.0
166.35791,0.008193481889763779,705.1822661356208,0.00025370340306410486,25.0,0.0
167.65918,0.008464214566929133,709.3930759803922,0.00025370340306410486,25.0,0.0
168.96045,0.008746406692913386,708.1122855392157,0.00025370340306410486,25.0,0.0
170.26172,0.009034193503937008,711.8290441176471,0.00025370340306410486,25.0,0.0
171.56299,0.009261455905511811,710.7835733251634,0.00025370340306410486,25.0,0.0
172.86426,0.009549877755905512,711.1802491830065,0.00025370340306410486,25.0,0.0
174.16553,0.009869046456692914,714.1135620915032,0.00025370340306410486,25.0,0.0
175.4668,0.010192362007874016,712.8635620915031,0.00025370340306410486,25.0,0.0
176.76807,0.010454675196850394,715.3773488562091,0.00025370340306410486,25.0,0.0
178.06934,0.010795912598425196,717.367902369281,0.00025370340306410486,25.0,0.0
179.37061,0.011128927755905512,717.8589665032679,0.00025370340306410486,25.0,0.0
180.67188,0.011437460433070867,719.4397467320262,0.00025370340306410486,25.0,0.0
181.97314,0.011705351968503936,717.5668658088235,0.00025370340306410486,25.0,0.0
183.27441,0.011960479330708661,719.0742442810456,0.00025370340306410486,25.0,0.0
184.57568,0.012262653937007874,721.0892310049019,0.00025370340306410486,25.0,0.0
185.87695,0.012659932677165356,722.3018280228758,0.00025370340306410486,25.0,0.0
187.17822,0.012985345669291338,724.106081495098,0.00025370340306410486,25.0,0.0
188.47949,0.013329795669291338,723.1285488153595,0.00025370340306410486,25.0,0.0
189.78076,0.01363947716535433,722.882199754902,0.00025370340306410486,25.0,0.0
191.08203,0.01396400433070866,726.7883476307189,0.00025370340306410486,25.0,0.0
192.3833,0.014370301377952754,727.3979524101306,0.00025370340306410486,25.0,0.0
193.68457,0.014737463976377953,727.3571793300654,0.00025370340306410486,25.0,0.0
194.98584,0.015022291732283465,727.3874080882352,0.00025370340306410486,25.0,0.0
196.28711,0.015358537401574805,729.2611570669934,0.00025370340306410486,25.0,0.0
197.58838,0.01567340216535433,728.4900684232026,0.00025370340306410486,25.0,0.0
198.88965,0.01607615590551181,729.3178104575163,0.00025370340306410486,25.0,0.0
200.19092,0.01651108346456693,732.2658547794117,0.00025370340306410486,25.0,0.0
201.49219,0.016954111417322833,732.6781811683006,0.00025370340306410486,25.0,0.0
202.79346,0.017335309842519686,733.4679840686274,0.00025370340306410486,25.0,0.0
204.09473,0.017642987992125984,731.687806372549,0.00025370340306410486,25.0,0.0
205.396,0.017989922637795277,732.7248774509803,0.00025370340306410486,25.0,0.0
206.69727,0.018337838385826772,734.0159569035948,0.00025370340306410486,25.0,0.0
207.99854,0.01873107933070866,733.0620149101308,0.00025370340306410486,25.0,0.0
209.2998,0.019085184251968503,735.599290236928,0.00025370340306410486,25.0,0.0
210.60107,0.01943228602362205,736.2542636846405,0.00025370340306410486,25.0,0.0
211.90234,0.0197395531496063,734.6150684232025,0.00025370340306410486,25.0,0.0
213.20361,0.020107057086614172,736.6220894607842,0.00025370340306410486,25.0,0.0
214.50488,0.02053751181102362,738.2246987336601,0.00025370340306410486,25.0,0.0
215.80615,0.020875064960629918,737.7818372140522,0.00025370340306410486,25.0,0.0
217.10742,0.02125462007874016,736.5743974673202,0.00025370340306410486,25.0,0.0
218.40869,0.02156613188976378,736.7573529411765,0.00025370340306410486,25.0,0.0
219.70996,0.021946108267716535,738.9879493464051,0.00025370340306410486,25.0,0.0
221.01123,0.02241051968503937,741.5789675245097,0.00025370340306410486,25.0,0.0
222.3125,0.022805289370078738,741.9978809232026,0.00025370340306410486,25.0,0.0
223.61377,0.02317686023622047,740.9058415032679,0.00025370340306410486,25.0,0.0
224.91504,0.02355554527559055,742.2589869281046,0.00025370340306410486,25.0,0.0
226.21631,0.02394498622047244,742.2698376225491,0.00025370340306410486,25.0,0.0
227.51758,0.024337324803149606,743.7218647875816,0.00025370340306410486,25.0,0.0
228.81885,0.024763738188976377,743.2378472222222,0.00025370340306410486,25.0,0.0
230.12012,0.02510038779527559,743.2828584558823,0.00025370340306410486,25.0,0.0
231.42139,0.025431017716535432,743.435329861111,0.00025370340306410486,25.0,0.0
232.72266,0.025819541338582677,743.8407883986928,0.00025370340306410486,25.0,0.0
234.02393,0.026156318897637795,744.8160998774509,0.00025370340306410486,25.0,0.0
235.3252,0.02656224015748031,746.1372038398692,0.00025370340306410486,25.0,0.0
236.62646,0.02707860039370079,747.828329248366,0.00025370340306410486,25.0,0.0
237.92773,0.027491935039370075,746.8070874183006,0.00025370340306410486,25.0,0.0
239.229,0.027929389763779525,749.5207567401961,0.00025370340306410486,25.0,0.0
240.53027,0.02832387992125984,746.616983251634,0.00025370340306410486,25.0,0.0
241.83154,0.028680236220472444,746.7350388071894,0.00025370340306410486,25.0,0.0
243.13281,0.029058688976377953,747.126225490196,0.00025370340306410486,25.0,0.0
244.43408,0.029415179133858268,748.939950980392,0.00025370340306410486,25.0,0.0
245.73535,0.029832417322834644,750.0919628267974,0.00025370340306410486,25.0,0.0
247.03662,0.03020932283464567,750.7202052696078,0.00025370340306410486,25.0,0.0
248.33789,0.030639263779527557,751.3009599673202,0.00025370340306410486,25.0,0.0
249.63916,0.03099607874015748,750.9689031862745,0.00025370340306410486,25.0,0.0
250.94043,0.031386401574803144,752.2905177696078,0.00025370340306410486,25.0,0.0
252.2417,0.0317684311023622,751.2004187091503,0.00025370340306410486,25.0,0.0
253.54297,0.03212658464566929,751.4805964052287,0.00025370340306410486,25.0,0.0
254.84424,0.03250486417322835,751.4001225490196,0.00025370340306410486,25.0,0.0
256.14551,0.03286333464566929,754.1008220996731,0.00025370340306410486,25.0,0.0
257.44678,0.03331431496062992,752.5430964052288,0.00025370340306410486,25.0,0.0
258.74805,0.03364438188976378,751.3400224673202,0.00025370340306410486,25.0,0.0
260.04932,0.03409265354330709,755.1589562908496,0.00025370340306410486,25.0,0.0
261.35059,0.034530149606299215,755.1371527777777,0.00025370340306410486,25.0,0.0
262.65186,0.03495600984251969,754.5145271650325,0.00025370340306410486,25.0,0.0
263.95313,0.035288257874015745,754.3274101307188,0.00025370340306410486,25.0,0.0
265.25439,0.03569381102362205,756.2920241013071,0.00025370340306410486,25.0,0.0
266.55566,0.036121911417322836,757.5549938725491,0.00025370340306410486,25.0,0.0
267.85693,0.036527360236220476,755.6024050245098,0.00025370340306410486,25.0,0.0
269.1582,0.036902452755905514,757.5103656045751,0.00025370340306410486,25.0,0.0
270.45947,0.037305872047244094,758.2684334150326,0.00025370340306410486,25.0,0.0
271.76074,0.03774701181102362,757.1090175653594,0.00025370340306410486,25.0,0.0
273.06201,0.03812256496062992,757.304789624183,0.00025370340306410486,25.0,0.0
274.36328,0.03847869291338583,760.397620506536,0.00025370340306410486,25.0,0.0
275.66455,0.03887882283464567,758.2349111519607,0.00025370340306410486,25.0,0.0
276.96582,0.039253720472440946,759.1355953839869,0.00025370340306410486,25.0,0.0
278.26709,0.03966409842519685,759.7483149509803,0.00025370340306410486,25.0,0.0
279.56836,0.0401398031496063,761.3571537990196,0.00025370340306410486,25.0,0.0
280.86963,0.04055531692913386,762.3494178921569,0.00025370340306410486,25.0,0.0
282.1709,0.04095245866141732,760.2427491830065,0.00025370340306410486,25.0,0.0
283.47217,0.04135665551181102,761.3956801470587,0.00025370340306410486,25.0,0.0
284.77344,0.04179501181102362,761.5374795751634,0.00025370340306410486,25.0,0.0
286.07471,0.042260887795275585,764.0792483660131,0.00025370340306410486,25.0,0.0
287.37598,0.0426580531496063,762.6125153186274,0.00025370340306410486,25.0,0.0
288.67725,0.04296461811023622,761.918887867647,0.00025370340306410486,25.0,0.0
289.97852,0.04327620472440945,761.6395271650326,0.00025370340306410486,25.0,0.0
291.27979,0.043631003937007876,764.3838592728758,0.00025370340306410486,25.0,0.0
292.58105,0.04402658464566929,763.3124489379085,0.00025370340306410486,25.0,0.0
293.88232,0.044464192913385825,765.0396497140523,0.00025370340306410486,25.0,0.0
295.18359,0.04483542322834645,763.9598907271242,0.00025370340306410486,25.0,0.0
296.48486,0.04530238188976378,765.6913296568626,0.00025370340306410486,25.0,0.0
297.78613,0.04572463582677165,766.789981617647,0.00025370340306410486,25.0,0.0
299.0874,0.04610029527559055,764.9935406454248,0.00025370340306410486,25.0,0.0
300.38867,0.04645566732283465,767.1141748366013,0.00025370340306410486,25.0,0.0
301.68994,0.04683243700787401,767.5751889297386,0.00025370340306410486,25.0,0.0
302.99121,0.04729320275590551,765.368821486928,0.00025370340306410486,25.0,0.0
304.29248,0.04762153346456693,764.8115808823529,0.00025370340306410486,25.0,0.0
305.59375,0.04798482283464567,767.8609068627451,0.00025370340306410486,25.0,0.0
306.89502,0.04840267913385827,767.9395169526143,0.00025370340306410486,25.0,0.0
308.19629,0.04878159448818897,768.7554891748365,0.00025370340306410486,25.0,0.0
309.49756,0.04916042913385826,768.50492749183,0.00025370340306410486,25.0,0.0
310.79883,0.0495415748031496,768.5178206699346,0.00025370340306410486,25.0,0.0
312.1001,0.04993230118110236,770.3956290849673,0.00025370340306410486,25.0,0.0
313.40137,0.0503096062992126,769.3019046160131,0.00025370340306410486,25.0,0.0
314.70264,0.05074092322834645,770.7519658905228,0.00025370340306410486,25.0,0.0
316.00391,0.051141935039370076,771.9412785947712,0.00025370340306410486,25.0,0.0
317.30518,0.05156049409448819,771.123544730392,0.00025370340306410486,25.0,0.0
318.60645,0.05198450787401575,770.730672998366,0.00025370340306410486,25.0,0.0
319.90771,0.052413444881889766,773.1690665849673,0.00025370340306410486,25.0,0.0
321.20898,0.05286367125984252,773.3629238153594,0.00025370340306410486,25.0,0.0
322.51025,0.053205864173228354,772.0437346813725,0.00025370340306410486,25.0,0.0
323.81152,0.053531431102362206,771.7328176062091,0.00025370340306410486,25.0,0.0
325.11279,0.05387183858267717,771.9700010212417,0.00025370340306410486,25.0,0.0
326.41406,0.05422549015748031,772.981898488562,0.00025370340306410486,25.0,0.0
327.71533,0.054660110236220465,773.8509752859476,0.00025370340306410486,25.0,0.0
329.0166,0.05503036417322835,774.249591503268,0.00025370340306410486,25.0,0.0
330.31787,0.05552106299212598,775.849085988562,0.00025370340306410486,25.0,0.0
331.61914,0.055959868110236226,774.1077920751634,0.00025370340306410486,25.0,0.0
332.92041,0.05627786614173228,775.1954656862745,0.00025370340306410486,25.0,0.0
334.22168,0.056602864173228344,774.5805249183006,0.00025370340306410486,25.0,0.0
335.52295,0.05701014763779527,775.1126940359477,0.00025370340306410486,25.0,0.0
336.82422,0.05741627952755905,777.177006740196,0.00025370340306410486,25.0,0.0
338.12549,0.05778781102362205,777.2164011437908,0.00025370340306410486,25.0,0.0
339.42676,0.05815786023622047,775.4027267156863,0.00025370340306410486,25.0,0.0
340.72803,0.05851757480314961,778.3179891748365,0.00025370340306410486,25.0,0.0
342.0293,0.05900582283464567,779.6240042892156,0.00025370340306410486,25.0,0.0
343.33057,0.059505879921259844,777.895756740196,0.00025370340306410486,25.0,0.0
344.63184,0.05986763779527559,778.0895884395424,0.00025370340306410486,25.0,0.0
345.93311,0.060221043307086615,776.5327308006536,0.00025370340306410486,25.0,0.0
347.23438,0.06050641732283464,778.9146241830065,0.00025370340306410486,25.0,0.0
348.53564,0.060900446850393704,778.4719413807189,0.00025370340306410486,25.0,0.0
349.83691,0.06127027755905512,778.0597937091503,0.00025370340306410486,25.0,0.0
351.13818,0.06166371456692913,779.3983864379085,0.00025370340306410486,25.0,0.0
352.43945,0.062103435039370075,782.0510365604574,0.00025370340306410486,25.0,0.0
353.74072,0.062477102362204724,779.7607741013071,0.00025370340306410486,25.0,0.0
355.04199,0.0628242874015748,782.3709150326797,0.00025370340306410486,25.0,0.0
356.34326,0.06320259448818898,780.6826491013071,0.00025370340306410486,25.0,0.0
357.64453,0.06366460039370078,782.8084150326796,0.00025370340306410486,25.0,0.0
358.9458,0.06406267322834647,782.5292330473856,0.00025370340306410486,25.0,0.0
360.24707,0.06441285629921259,781.4571844362744,0.00025370340306410486,25.0,0.0
361.54834,0.06477796456692914,783.4256791258168,0.00025370340306410486,25.0,0.0
362.84961,0.06520322834645668,783.3810508578431,0.00025370340306410486,25.0,0.0
364.15088,0.0655854842519685,783.7501276552287,0.00025370340306410486,25.0,0.0
365.45215,0.06597063779527558,782.4324959150326,0.00025370340306410486,25.0,0.0
366.75342,0.06637963385826771,782.2112183415032,0.00025370340306410486,25.0,0.0
368.05469,0.06678144881889764,785.5082465277777,0.00025370340306410486,25.0,0.0
369.35596,0.06713917716535434,783.010059232026,0.00025370340306410486,25.0,0.0
370.65723,0.0675292283464567,784.3247038398692,0.00025370340306410486,25.0,0.0
371.9585,0.06789813188976378,784.3900122549019,0.00025370340306410486,25.0,0.0
373.25977,0.06829889173228347,785.9554738562091,0.00025370340306410486,25.0,0.0
374.56104,0.06871517322834646,785.6175194035947,0.00025370340306410486,25.0,0.0
375.8623,0.06911598031496063,786.575750612745,0.00025370340306410486,25.0,0.0
377.16357,0.06949762598425197,785.4560100081699,0.00025370340306410486,25.0,0.0
378.46484,0.06992808070866141,786.9613970588234,0.00025370340306410486,25.0,0.0
379.76611,0.07032737992125984,786.2611570669934,0.00025370340306410486,25.0,0.0
381.06738,0.07067098622047244,787.2366472630719,0.00025370340306410486,25.0,0.0
382.36865,0.0710453405511811,785.3167636846405,0.00025370340306410486,25.0,0.0
383.66992,0.07141200196850393,786.6022263071895,0.00025370340306410486,25.0,0.0
384.97119,0.07182190157480316,788.1448886846405,0.00025370340306410486,25.0,0.0
386.27246,0.07221098031496063,787.6767769607842,0.00025370340306410486,25.0,0.0
387.57373,0.07258754527559055,788.2960324754902,0.00025370340306410486,25.0,0.0
388.875,0.0729615531496063,789.2791309232025,0.00025370340306410486,25.0,0.0
390.17627,0.07335760039370079,788.9730136846405,0.00025370340306410486,25.0,0.0
391.47754,0.0737982716535433,790.7095843545751,0.00025370340306410486,25.0,0.0
392.77881,0.07415389173228346,788.8319546568628,0.00025370340306410486,25.0,0.0
394.08008,0.07446783661417322,790.525071486928,0.00025370340306410486,25.0,0.0
395.38135,0.07484317716535432,789.9119689542483,0.00025370340306410486,25.0,0.0
396.68262,0.07522518503937008,792.3301930147059,0.00025370340306410486,25.0,0.0
397.98389,0.07555165551181102,790.3998417075163,0.00025370340306410486,25.0,0.0
399.28516,0.075953781496063,792.2232434640522,0.00025370340306410486,25.0,0.0
400.58643,0.07634429330708661,791.9223090277777,0.00025370340306410486,25.0,0.0
401.8877,0.07672137992125984,791.2390216503268,0.00025370340306410486,25.0,0.0
403.18896,0.07714957086614173,791.9168198529411,0.00025370340306410486,25.0,0.0
404.49023,0.07747954330708662,790.4554483251633,0.00025370340306410486,25.0,0.0
405.7915,0.07782012401574803,791.5092933006536,0.00025370340306410486,25.0,0.0
407.09277,0.07820713188976379,793.6160386029411,0.00025370340306410486,25.0,0.0
408.39404,0.0785707657480315,792.8935610702614,0.00025370340306410486,25.0,0.0
409.69531,0.07899820078740157,796.0924734477125,0.00025370340306410486,25.0,0.0
410.99658,0.07941250590551181,794.7993515114379,0.00025370340306410486,25.0,0.0
412.29785,0.0798152657480315,794.5992647058823,0.00025370340306410486,25.0,0.0
413.59912,0.08022428543307086,794.7914879493463,0.00025370340306410486,25.0,0.0
414.90039,0.08069807086614172,795.2255157271242,0.00025370340306410486,25.0,0.0
416.20166,0.08108372440944882,795.1209150326797,0.00025370340306410486,25.0,0.0
417.50293,0.0814278464566929,794.8230187908497,0.00025370340306410486,25.0,0.0
418.8042,0.08178399606299212,794.1953380310457,0.00025370340306410486,25.0,0.0
420.10547,0.08214388385826772,796.2233200571895,0.00025370340306410486,25.0,0.0
421.40674,0.08254020669291338,794.5356158088234,0.00025370340306410486,25.0,0.0
422.70801,0.08293265944881889,795.98539624183,0.00025370340306410486,25.0,0.0
424.00928,0.08331669291338582,796.2879391339868,0.00025370340306410486,25.0,0.0
425.31055,0.08370770669291339,796.9118923611111,0.00025370340306410486,25.0,0.0
426.61182,0.08402569488188977,796.5160079656863,0.00025370340306410486,25.0,0.0
427.91309,0.08439768897637795,798.5651041666666,0.00025370340306410486,25.0,0.0
429.21436,0.08478991929133858,798.3313163807189,0.00025370340306410486,25.0,0.0
430.51563,0.08517633464566929,798.456214256536,0.00025370340306410486,25.0,0.0
431.81689,0.08556815748031496,797.426189746732,0.00025370340306410486,25.0,0.0
433.11816,0.08594919291338583,797.5408241421568,0.00025370340306410486,25.0,0.0
434.41943,0.08629087007874016,798.1223703022875,0.00025370340306410486,25.0,0.0
435.7207,0.08662163582677165,799.1703431372548,0.00025370340306410486,25.0,0.0
437.02197,0.08698491929133857,799.8538858251633,0.00025370340306410486,25.0,0.0
438.32324,0.08735366929133857,801.3322099673202,0.00025370340306410486,25.0,0.0
439.62451,0.0878372066929134,802.059921364379,0.00025370340306410486,25.0,0.0
440.92578,0.0882623877952756,800.4366830065359,0.00025370340306410486,25.0,0.0
442.22705,0.08860196456692913,798.7865093954248,0.00025370340306410486,25.0,0.0
443.52832,0.08897104330708662,799.4624438316993,0.00025370340306410486,25.0,0.0
444.82959,0.08930374409448819,799.4083435457516,0.00025370340306410486,25.0,0.0
446.13086,0.08968786023622047,802.1138429330065,0.00025370340306410486,25.0,0.0
447.43213,0.09009371653543306,803.1198682598039,0.00025370340306410486,25.0,0.0
448.7334,0.09054005905511811,803.0314287173203,0.00025370340306410486,25.0,0.0
450.03467,0.09092962007874016,803.810125612745,0.00025370340306410486,25.0,0.0
451.33594,0.0913353996062992,802.2028441584966,0.00025370340306410486,25.0,0.0
452.63721,0.0917038877952756,803.0149101307188,0.00025370340306410486,25.0,0.0
453.93848,0.09203909251968503,802.7653186274509,0.00025370340306410486,25.0,0.0
455.23975,0.09235487992125985,801.9904769199346,0.00025370340306410486,25.0,0.0
456.54102,0.0927021653543307,802.9820006127451,0.00025370340306410486,25.0,0.0
457.84229,0.09319486614173228,804.4496527777777,0.00025370340306410486,25.0,0.0
459.14355,0.09359160039370079,806.2299836601308,0.00025370340306410486,25.0,0.0
460.44482,0.09400337204724409,803.8401245915032,0.00025370340306410486,25.0,0.0
461.74609,0.09437552559055118,803.9720690359477,0.00025370340306410486,25.0,0.0
463.04736,0.09473018503937009,805.508220996732,0.00025370340306410486,25.0,0.0
464.34863,0.09512416732283464,805.8754850898692,0.00025370340306410486,25.0,0.0
465.6499,0.09549730708661418,805.3777828839869,0.00025370340306410486,25.0,0.0
466.95117,0.09590600393700786,805.9595843545751,0.00025370340306410486,25.0,0.0
468.25244,0.09632832283464567,805.6934742647059,0.00025370340306410486,25.0,0.0
469.55371,0.09671797047244095,804.8628472222222,0.00025370340306410486,25.0,0.0
470.85498,0.0970985531496063,805.6555351307189,0.00025370340306410486,25.0,0.0
472.15625,0.09743254527559055,805.28227124183,0.00025370340306410486,25.0,0.0
473.45752,0.09779145078740156,806.8512816584966,0.00025370340306410486,25.0,0.0
474.75879,0.09816235039370079,808.438316993464,0.00025370340306410486,25.0,0.0
476.06006,0.0985156122047244,809.2569955065359,0.00025370340306410486,25.0,0.0
477.36133,0.09887874409448819,806.3579452614379,0.00025370340306410486,25.0,0.0
478.6626,0.09933256102362205,808.2340686274509,0.00025370340306410486,25.0,0.0
479.96387,0.09974510039370078,807.6824193218953,0.00025370340306410486,25.0,0.0
481.26514,0.10013942913385826,808.6193831699346,0.00025370340306410486,25.0,0.0
482.56641,0.10050143307086615,808.0917585784314,0.00025370340306410486,25.0,0.0
483.86768,0.10085862598425197,810.7778033088235,0.00025370340306410486,25.0,0.0
485.16895,0.10131232677165354,809.860600490196,0.00025370340306410486,25.0,0.0
486.47021,0.10176017125984252,811.5022977941177,0.00025370340306410486,25.0,0.0
487.77148,0.10212344291338582,808.7943474264705,0.00025370340306410486,25.0,0.0
489.07275,0.10250845472440945,809.133323120915,0.00025370340306410486,25.0,0.0
490.37402,0.10285879724409448,810.3013429330065,0.00025370340306410486,25.0,0.0
491.67529,0.10326241929133857,810.9986468545751,0.00025370340306410486,25.0,0.0
492.97656,0.10365515157480315,811.9423508986928,0.00025370340306410486,25.0,0.0
494.27783,0.10403641141732282,811.5931627859477,0.00025370340306410486,25.0,0.0
495.5791,0.1044172125984252,812.0802440767974,0.00025370340306410486,25.0,0.0
496.88037,0.10481682086614173,809.7209712009803,0.00025370340306410486,25.0,0.0
498.18164,0.10518702755905512,810.9884854983659,0.00025370340306410486,25.0,0.0
499.48291,0.10555635236220473,810.7554891748366,0.00025370340306410486,25.0,0.0
500.78418,0.10600859645669292,811.664164624183,0.00025370340306410486,25.0,0.0
502.08545,0.10638229921259842,811.4981872957516,0.00025370340306410486,25.0,0.0
503.38672,0.10670526771653542,810.7273284313725,0.00025370340306410486,25.0,0.0
504.68799,0.10702751968503936,812.109477124183,0.00025370340306410486,25.0,0.0
505.98926,0.10738161614173228,813.4289726307188,0.00025370340306410486,25.0,0.0
507.29053,0.10774999212598425,812.254212622549,0.00025370340306410486,25.0,0.0
508.5918,0.10815500984251969,814.9721200980392,0.00025370340306410486,25.0,0.0
509.89307,0.1085531062992126,814.214231004902,0.00025370340306410486,25.0,0.0
511.19434,0.10895128346456694,813.102787990196,0.00025370340306410486,25.0,0.0
512.49561,0.1093767874015748,813.2707056781046,0.00025370340306410486,25.0,0.0
513.79688,0.10975010236220473,814.5193270016339,0.00025370340306410486,25.0,0.0
515.09814,0.11015116732283466,816.0908905228758,0.00025370340306410486,25.0,0.0
516.39941,0.11049760236220472,813.8439031862744,0.00025370340306410486,25.0,0.0
517.70068,0.11092302362204726,816.7208180147059,0.00025370340306410486,25.0,0.0
519.00195,0.1113661751968504,816.7138991013072,0.00025370340306410486,25.0,0.0
520.30322,0.11175675,815.1548713235294,0.00025370340306410486,25.0,0.0
521.60449,0.1122027874015748,816.1861979166666,0.00025370340306410486,25.0,0.0
522.90576,0.11259594291338582,816.6874234068628,0.00025370340306410486,25.0,0.0
524.20703,0.11295319488188976,816.1163449754902,0.00025370340306410486,25.0,0.0
525.5083,0.11337916929133858,817.4941023284313,0.00025370340306410486,25.0,0.0
526.80957,0.11378407086614173,816.5956137663397,0.00025370340306410486,25.0,0.0
528.11084,0.1141478346456693,815.4935661764705,0.00025370340306410486,25.0,0.0
529.41211,0.1144908779527559,816.3599877450979,0.00025370340306410486,25.0,0.0
530.71338,0.11487670078740157,817.4193729575163,0.00025370340306410486,25.0,0.0
532.01465,0.11521730314960629,818.7724673202613,0.00025370340306410486,25.0,0.0
533.31592,0.11570581496062993,818.8768892973856,0.00025370340306410486,25.0,0.0
534.61719,0.11613100393700787,817.3888378267974,0.00025370340306410486,25.0,0.0
535.91846,0.1165088346456693,817.4498059640523,0.00025370340306410486,25.0,0.0
537.21973,0.11684801771653543,819.3772722630717,0.00025370340306410486,25.0,0.0
538.521,0.11726354921259842,820.7809180964051,0.00025370340306410486,25.0,0.0
539.82227,0.11767847047244094,818.10258374183,0.00025370340306410486,25.0,0.0
541.12354,0.11803781102362204,818.4277726715686,0.00025370340306410486,25.0,0.0
542.4248,0.11838904527559056,818.2526296977123,0.00025370340306410486,25.0,0.0
543.72607,0.11877155905511812,820.145960988562,0.00025370340306410486,25.0,0.0
545.02734,0.11917230708661417,819.4513888888888,0.00025370340306410486,25.0,0.0
546.32861,0.11959297637795276,818.6711856617646,0.00025370340306410486,25.0,0.0
547.62988,0.11995665944881889,820.7091758578431,0.00025370340306410486,25.0,0.0
548.93115,0.1203836062992126,820.685125612745,0.00025370340306410486,25.0,0.0
550.23242,0.1207807401574803,820.8815359477123,0.00025370340306410486,25.0,0.0
551.53369,0.12117137401574803,820.5425602532679,0.00025370340306410486,25.0,0.0
552.83496,0.12151611811023622,820.1942657271242,0.00025370340306410486,25.0,0.0
554.13623,0.12188734448818897,821.5154973447711,0.00025370340306410486,25.0,0.0
555.4375,0.12224809448818896,822.1307700163397,0.00025370340306410486,25.0,0.0
556.73877,0.12266369488188976,822.3596047794116,0.00025370340306410486,25.0,0.0
558.04004,0.12312319094488189,822.1722324346405,0.00025370340306410486,25.0,0.0
559.34131,0.12354917716535432,823.2914624183006,0.00025370340306410486,25.0,0.0
560.64258,0.12398113385826771,821.7225030637254,0.00025370340306410486,25.0,0.0
561.94385,0.12436256889763779,820.7974366830064,0.00025370340306410486,25.0,0.0
563.24512,0.12469989763779527,821.9482741013072,0.00025370340306410486,25.0,0.0
564.54639,0.12512345472440944,822.4947916666666,0.00025370340306410486,25.0,0.0
565.84766,0.12554362007874015,822.9507506127451,0.00025370340306410486,25.0,0.0
567.14893,0.12593960433070867,822.5606107026143,0.00025370340306410486,25.0,0.0
568.4502,0.12631188779527558,822.5835631127451,0.00025370340306410486,25.0,0.0
569.75146,0.1267638622047244,823.9367085375816,0.00025370340306410486,25.0,0.0
571.05273,0.12720566338582676,823.1999591503268,0.00025370340306410486,25.0,0.0
572.354,0.12762072440944883,824.2883986928103,0.00025370340306410486,25.0,0.0
573.65527,0.12797299015748032,823.4735243055555,0.00025370340306410486,25.0,0.0
574.95654,0.12827636417322835,823.756765727124,0.00025370340306410486,25.0,0.0
576.25781,0.12866438188976378,825.7578635620914,0.00025370340306410486,25.0,0.0
577.55908,0.12903542125984252,825.4686989379085,0.00025370340306410486,25.0,0.0
578.86035,0.12941128149606299,825.2983558006536,0.00025370340306410486,25.0,0.0
580.16162,0.12982586220472442,826.4755923202614,0.00025370340306410486,25.0,0.0
581.46289,0.13021137992125986,825.5112591911765,0.00025370340306410486,25.0,0.0
582.76416,0.1306255157480315,825.283088235294,0.00025370340306410486,25.0,0.0
584.06543,0.13106594488188977,828.7202308006536,0.00025370340306410486,25.0,0.0
585.3667,0.13152065157480314,824.8687448937908,0.00025370340306410486,25.0,0.0
586.66797,0.131918312992126,825.45805249183,0.00025370340306410486,25.0,0.0
587.96924,0.13236044488188978,826.8484221813725,0.00025370340306410486,25.0,0.0
589.27051,0.13274601968503938,826.5100847630719,0.00025370340306410486,25.0,0.0
590.57178,0.1330844409448819,826.9461550245097,0.00025370340306410486,25.0,0.0
591.87305,0.13351990748031495,826.0530535130717,0.00025370340306410486,25.0,0.0
593.17432,0.13395084448818897,827.3590941584966,0.00025370340306410486,25.0,0.0
594.47559,0.13440051968503935,826.2788245506536,0.00025370340306410486,25.0,0.0
595.77686,0.1348086220472441,827.4005565767973,0.00025370340306410486,25.0,0.0
597.07813,0.13522414173228348,826.5685508578431,0.00025370340306410486,25.0,0.0
598.37939,0.13564747637795274,828.4717116013071,0.00025370340306410486,25.0,0.0
599.68066,0.13608723622047245,828.9394403594771,0.00025370340306410486,25.0,0.0
600.98193,0.1365058188976378,828.5375306372548,0.00025370340306410486,25.0,0.0
602.2832,0.13690297440944882,828.2725694444443,0.00025370340306410486,25.0,0.0
603.58447,0.13727862598425197,828.0461856617646,0.00025370340306410486,25.0,0.0
604.88574,0.1376417086614173,827.7622549019608,0.00025370340306410486,25.0,0.0
606.18701,0.13803452559055118,828.1494076797385,0.00025370340306410486,25.0,0.0
607.48828,0.1384527657480315,828.7407322303922,0.00025370340306410486,25.0,0.0
608.78955,0.13889108267716535,829.202920751634,0.00025370340306410486,25.0,0.0
610.09082,0.13927366732283464,826.4856515522875,0.00025370340306410486,25.0,0.0
611.39209,0.1396460787401575,828.4861111111111,0.00025370340306410486,25.0,0.0
612.69336,0.13999365157480315,828.1436121323529,0.00025370340306410486,25.0,0.0
613.99463,0.1403578149606299,828.704963235294,0.00025370340306410486,25.0,0.0
615.2959,0.1407405866141732,831.113587622549,0.00025370340306410486,25.0,0.0
616.59717,0.14116542322834644,830.9429891748365,0.00025370340306410486,25.0,0.0
617.89844,0.14158352362204724,829.2087928921568,0.00025370340306410486,25.0,0.0
619.19971,0.14205619488188975,832.3812806372549,0.00025370340306410486,25.0,0.0
620.50098,0.14240694881889762,829.643918504902,0.00025370340306410486,25.0,0.0
621.80225,0.142795281496063,830.4076031454248,0.00025370340306410486,25.0,0.0
623.10352,0.1432340807086614,831.0649509803922,0.00025370340306410486,25.0,0.0
624.40479,0.1436224133858268,830.8138786764706,0.00025370340306410486,25.0,0.0
625.70605,0.1439818838582677,829.6551521650326,0.00025370340306410486,25.0,0.0
627.00732,0.14441596456692915,832.0099060457516,0.00025370340306410486,25.0,0.0
628.30859,0.1448752027559055,831.7011080473857,0.00025370340306410486,25.0,0.0
629.60986,0.14533902755905512,831.7691738153594,0.00025370340306410486,25.0,0.0
630.91113,0.14583288976377953,831.8280739379085,0.00025370340306410486,25.0,0.0
632.2124,0.14631006692913387,832.5963796977123,0.00025370340306410486,25.0,0.0
633.51367,0.1467111653543307,831.2003421160131,0.00025370340306410486,25.0,0.0
634.81494,0.1470665059055118,831.5211141748365,0.00025370340306410486,25.0,0.0
636.11621,0.14743110236220472,832.6810406454248,0.00025370340306410486,25.0,0.0
637.41748,0.14792874409448817,832.9686223447712,0.00025370340306410486,25.0,0.0
638.71875,0.14830732677165354,832.3564133986928,0.00025370340306410486,25.0,0.0
640.02002,0.14875444291338583,833.9196282679738,0.00025370340306410486,25.0,0.0
641.32129,0.14919395669291338,832.6424377042483,0.00025370340306410486,25.0,0.0
642.62256,0.14966762598425196,832.1111877042483,0.00025370340306410486,25.0,0.0
643.92383,0.15007373622047243,832.375102124183,0.00025370340306410486,25.0,0.0
645.2251,0.15051565551181104,833.2773692810457,0.00025370340306410486,25.0,0.0
646.52637,0.15091182677165355,832.6133323120914,0.00025370340306410486,25.0,0.0
647.82764,0.15122076181102362,832.3138276143791,0.00025370340306410486,25.0,0.0
649.12891,0.1515767125984252,833.3216656454248,0.00025370340306410486,25.0,0.0
650.43018,0.1519910688976378,832.9056883169934,0.00025370340306410486,25.0,0.0
651.73145,0.1524713681102362,836.6793555964052,0.00025370340306410486,25.0,0.0
653.03271,0.15297007677165353,833.4292024101306,0.00025370340306410486,25.0,0.0
654.33398,0.15340862795275592,835.9927747140522,0.00025370340306410486,25.0,0.0
655.63525,0.15387897637795275,834.9205984477123,0.00025370340306410486,25.0,0.0
656.93652,0.15433400196850394,832.5922691993463,0.00025370340306410486,25.0,0.0
658.23779,0.15474002952755905,833.7335580065359,0.00025370340306410486,25.0,0.0
659.53906,0.15508815354330707,834.5433261846405,0.00025370340306410486,25.0,0.0
660.84033,0.1555243464566929,834.5344669117646,0.00025370340306410486,25.0,0.0
662.1416,0.15600077362204723,834.776935253268,0.00025370340306410486,25.0,0.0
663.44287,0.15639588779527558,833.8628982843137,0.00025370340306410486,25.0,0.0
664.74414,0.1568492933070866,836.0051828022875,0.00025370340306410486,25.0,0.0
666.04541,0.1573063838582677,835.5308925653594,0.00025370340306410486,25.0,0.0
667.34668,0.1577595433070866,836.1252297794117,0.00025370340306410486,25.0,0.0
668.64795,0.15822673622047245,835.91117749183,0.00025370340306410486,25.0,0.0
669.94922,0.15862562992125984,835.6381740196077,0.00025370340306410486,25.0,0.0
671.25049,0.15902907677165354,835.7276092728757,0.00025370340306410486,25.0,0.0
672.55176,0.15950960826771654,836.6837214052288,0.00025370340306410486,25.0,0.0
673.85303,0.15993462007874015,834.6745302287582,0.00025370340306410486,25.0,0.0
675.1543,0.16037906299212598,836.5581852532679,0.00025370340306410486,25.0,0.0
676.45557,0.1608088720472441,836.4110243055555,0.00025370340306410486,25.0,0.0
677.75684,0.1612720531496063,837.2398386437908,0.00025370340306410486,25.0,0.0
679.05811,0.16166729724409448,836.2688419117646,0.00025370340306410486,25.0,0.0
680.35938,0.16207445078740157,835.6970230800653,0.00025370340306410486,25.0,0.0
681.66064,0.16245743503937007,838.177619485294,0.00025370340306410486,25.0,0.0
682.96191,0.1629200157480315,835.7675142973856,0.00025370340306410486,25.0,0.0
684.26318,0.16336541929133858,838.2605953839869,0.00025370340306410486,25.0,0.0
685.56445,0.16380481692913385,836.5629340277777,0.00025370340306410486,25.0,0.0
686.86572,0.1642006003937008,836.4580269607843,0.00025370340306410486,25.0,0.0
688.16699,0.16468674212598425,837.3642514297385,0.00025370340306410486,25.0,0.0
689.46826,0.16506722637795276,837.0039828431371,0.00025370340306410486,25.0,0.0
690.76953,0.16549871456692913,837.441610498366,0.00025370340306410486,25.0,0.0
692.0708,0.1659728405511811,838.6319699754902,0.00025370340306410486,25.0,0.0
693.37207,0.16644382283464568,838.8569240196077,0.00025370340306410486,25.0,0.0
694.67334,0.16692472047244095,837.790492238562,0.00025370340306410486,25.0,0.0
695.97461,0.16735197244094488,838.3034109477125,0.00025370340306410486,25.0,0.0
697.27588,0.16782112401574803,839.7771905637255,0.00025370340306410486,25.0,0.0
698.57715,0.16828243897637796,837.3362183415032,0.00025370340306410486,25.0,0.0
699.87842,0.16868074606299213,838.1569904003268,0.00025370340306410486,25.0,0.0
701.17969,0.16921245866141732,838.5132250816993,0.00025370340306410486,25.0,0.0
702.48096,0.1696792874015748,837.851868872549,0.00025370340306410486,25.0,0.0
703.78223,0.17014305511811023,838.1326848447711,0.00025370340306410486,25.0,0.0
705.0835,0.17057291141732284,838.1182853349673,0.00025370340306410486,25.0,0.0
706.38477,0.17100841338582679,839.0175398284313,0.00025370340306410486,25.0,0.0
707.68604,0.1715887244094488,840.872217116013,0.00025370340306410486,25.0,0.0
708.9873,0.1720712755905512,839.6702920751634,0.00025370340306410486,25.0,0.0
710.28857,0.1725333405511811,839.1886999591502,0.00025370340306410486,25.0,0.0
711.58984,0.17289891338582677,837.7846966911765,0.00025370340306410486,25.0,0.0
712.89111,0.17334588779527557,839.8581495098039,0.00025370340306410486,25.0,0.0
714.19238,0.17380443307086615,841.0798611111111,0.00025370340306410486,25.0,0.0
715.49365,0.1742594468503937,839.1390165441176,0.00025370340306410486,25.0,0.0
716.79492,0.1746627874015748,838.2855902777777,0.00025370340306410486,25.0,0.0
718.09619,0.17504621653543306,838.1078176062091,0.00025370340306410486,25.0,0.0
719.39746,0.17550256692913385,840.1053666258169,0.00025370340306410486,25.0,0.0
720.69873,0.17590831299212598,838.7156096813725,0.00025370340306410486,25.0,0.0
722.0,0.17634814370078739,840.0953329248365,0.00025370340306410486,25.0,0.0
723.30127,0.1768656377952756,841.0708741830065,0.00025370340306410486,25.0,0.0
724.60254,0.17739329133858267,840.3359885620914,0.00025370340306410486,25.0,0.0
725.90381,0.17787225196850392,839.5087060866013,0.00025370340306410486,25.0,0.0
727.20508,0.17832073031496062,839.7644761029411,0.00025370340306410486,25.0,0.0
728.50635,0.1788598346456693,839.5503472222222,0.00025370340306410486,25.0,0.0
729.80762,0.1793183090551181,840.0461345996731,0.00025370340306410486,25.0,0.0
731.10889,0.179810562992126,839.5726613562091,0.00025370340306410486,25.0,0.0
732.41016,0.18025361023622047,839.1506331699345,0.00025370340306410486,25.0,0.0
733.71143,0.18073271062992124,838.8003216911765,0.00025370340306410486,25.0,0.0
735.0127,0.1811880531496063,840.7994281045751,0.00025370340306410486,25.0,0.0
736.31396,0.18160499212598424,840.7846456290849,0.00025370340306410486,25.0,0.0
737.61523,0.18210848622047243,842.4120710784313,0.00025370340306410486,25.0,0.0
738.9165,0.1825889625984252,839.5921160130719,0.00025370340306410486,25.0,0.0
740.21777,0.18306845078740158,839.4872089460785,0.00025370340306410486,25.0,0.0
741.51904,0.18352236023622048,841.3459456699346,0.00025370340306410486,25.0,0.0
742.82031,0.18400162598425196,840.1590328839868,0.00025370340306410486,25.0,0.0
744.12158,0.18455731102362202,841.5199652777777,0.00025370340306410486,25.0,0.0
745.42285,0.1850491909448819,840.6769301470587,0.00025370340306410486,25.0,0.0
746.72412,0.18552997047244094,842.0247906454248,0.00025370340306410486,25.0,0.0
748.02539,0.18603808858267715,840.2136948529411,0.00025370340306410486,25.0,0.0
749.32666,0.18654485629921258,839.4195261437908,0.00025370340306410486,25.0,0.0
750.62793,0.18704309448818898,840.5615042892156,0.00025370340306410486,25.0,0.0
751.9292,0.1874516338582677,840.2060866013071,0.00025370340306410486,25.0,0.0
753.23047,0.1880221712598425,842.0624999999999,0.00025370340306410486,25.0,0.0
754.53174,0.18853617913385826,839.8549581290849,0.00025370340306410486,25.0,0.0
755.83301,0.18899092322834646,841.3079299428103,0.00025370340306410486,25.0,0.0
757.13428,0.18946521456692914,841.7765267565359,0.00025370340306410486,25.0,0.0
758.43555,0.18997224015748032,842.1047028186274,0.00025370340306410486,25.0,0.0
759.73682,0.19047182874015747,842.6234426062091,0.00025370340306410486,25.0,0.0
761.03809,0.19096464566929133,841.2493872549019,0.00025370340306410486,25.0,0.0
762.33936,0.19143616732283464,840.9743157679737,0.00025370340306410486,25.0,0.0
763.64063,0.19194832283464566,842.4431168300653,0.00025370340306410486,25.0,0.0
764.94189,0.19243994291338581,841.9953788807188,0.00025370340306410486,25.0,0.0
766.24316,0.19296489763779529,841.3892718545751,0.00025370340306410486,25.0,0.0
767.54443,0.19342909842519684,839.2244944852941,0.00025370340306410486,25.0,0.0
768.8457,0.19394762401574803,841.6387101715685,0.00025370340306410486,25.0,0.0
770.14697,0.19446939960629922,842.157679738562,0.00025370340306410486,25.0,0.0
771.44824,0.1949524901574803,843.1170343137254,0.00025370340306410486,25.0,0.0
772.74951,0.1954694311023622,842.7569444444445,0.00025370340306410486,25.0,0.0
774.05078,0.19603478346456693,842.5706954656862,0.00025370340306410486,25.0,0.0
775.35205,0.1965143779527559,840.9144199346405,0.00025370340306410486,25.0,0.0
776.65332,0.19700145669291338,842.2773692810457,0.00025370340306410486,25.0,0.0
777.95459,0.19753561023622046,841.8846252042483,0.00025370340306410486,25.0,0.0
779.25586,0.1980837007874016,842.5518790849673,0.00025370340306410486,25.0,0.0
780.55713,0.19863086614173228,842.8351715686274,0.00025370340306410486,25.0,0.0
781.8584,0.19915297244094485,842.6605902777777,0.00025370340306410486,25.0,0.0
783.15967,0.19962251968503936,842.4797028186274,0.00025370340306410486,25.0,0.0
784.46094,0.2002372440944882,844.2434385212417,0.00025370340306410486,25.0,0.0
785.76221,0.2006688779527559,840.8131382761437,0.00025370340306410486,25.0,0.0
787.06348,0.2012390157480315,842.7146905637254,0.00025370340306410486,25.0,0.0
788.36475,0.20173431102362205,840.9536356209151,0.00025370340306410486,25.0,0.0
789.66602,0.2022399212598425,841.8775786356209,0.00025370340306410486,25.0,0.0
790.96729,0.20267700787401574,839.5125868055555,0.00025370340306410486,25.0,0.0
792.26855,0.20313293307086616,843.31742749183,0.00025370340306410486,25.0,0.0
793.56982,0.203691968503937,844.2384344362745,0.00025370340306410486,25.0,0.0
794.87109,0.20422086614173227,842.258731617647,0.00025370340306410486,25.0,0.0
796.17236,0.20472324803149605,841.7196180555555,0.00025370340306410486,25.0,0.0
797.47363,0.20529127952755907,843.119842728758,0.00025370340306410486,25.0,0.0
798.7749,0.2058342716535433,842.7679738562091,0.00025370340306410486,25.0,0.0
800.07617,0.2063919881889764,842.4811325571895,0.00025370340306410486,25.0,0.0
801.37744,0.206960905511811,842.6817044526143,0.00025370340306410486,25.0,0.0
802.67871,0.2074527755905512,841.9410743464052,0.00025370340306410486,25.0,0.0
803.97998,0.20790187007874017,839.5591554330065,0.00025370340306410486,25.0,0.0
805.28125,0.20842000000000002,841.5280075571895,0.00025370340306410486,25.0,0.0
806.58252,0.20892281496062992,843.4267514297385,0.00025370340306410486,25.0,0.0
807.18311,0.20928409448818897,845.2662888071895,0.00025370340306410486,25.0,0.0