File: datasets/am_bench_2022/csv/0-XY.05-3.csv
Time(s),Strain(%),Stress(MPa),SR(s-1),Temp(C),Angle(deg)
29.328125,1.7937757677165354e-05,6.187930708741829,0.00025370340306410486,25.0,0.0
30.729492,2.247823031496063e-05,10.747875561683006,0.00025370340306410486,25.0,0.0
32.030762,4.0442287401574805e-05,14.67033624387255,0.00025370340306410486,25.0,0.0
33.332031,5.828695669291339e-05,18.605852736928103,0.00025370340306410486,25.0,0.0
34.633301,8.01536279527559e-05,23.382717013888886,0.00025370340306410486,25.0,0.0
35.93457,0.0001085814409448819,28.02712673611111,0.00025370340306410486,25.0,0.0
37.23584,0.00012367641732283463,32.194143178104575,0.00025370340306410486,25.0,0.0
38.537109,0.00014619708858267715,36.51967677696078,0.00025370340306410486,25.0,0.0
39.838379,0.00017733465748031498,42.074481719771235,0.00025370340306410486,25.0,0.0
41.139648,0.0002081951377952756,48.11127195669934,0.00025370340306410486,25.0,0.0
42.440918,0.00024223830708661417,53.474356617647054,0.00025370340306410486,25.0,0.0
43.742188,0.00026134763779527557,59.93009854983659,0.00025370340306410486,25.0,0.0
45.043457,0.00026799366141732283,65.3853911356209,0.00025370340306410486,25.0,0.0
46.344727,0.0003023867125984252,73.2708767361111,0.00025370340306410486,25.0,0.0
47.645996,0.00035232305118110236,80.0004825367647,0.00025370340306410486,25.0,0.0
48.947266,0.00041421643700787397,88.41530841503267,0.00025370340306410486,25.0,0.0
50.248535,0.00041052923228346457,93.41402675653593,0.00025370340306410486,25.0,0.0
51.549805,0.00042935561023622047,99.49289981617646,0.00025370340306410486,25.0,0.0
52.851074,0.00044419870078740156,107.28380310457516,0.00025370340306410486,25.0,0.0
54.152344,0.0005323395472440945,116.33542687908496,0.00025370340306410486,25.0,0.0
55.453613,0.0005301365354330709,122.82656760620915,0.00025370340306410486,25.0,0.0
56.754883,0.000558833188976378,129.73763531454247,0.00025370340306410486,25.0,0.0
58.056152,0.0006110168700787401,138.19705371732024,0.00025370340306410486,25.0,0.0
59.357422,0.0006313426181102362,146.08535794526142,0.00025370340306410486,25.0,0.0
60.658691,0.0006846733464566929,156.00617340686273,0.00025370340306410486,25.0,0.0
61.959961,0.0007278234645669291,164.43565665849673,0.00025370340306410486,25.0,0.0
63.26123,0.0007841065157480314,173.08691789215683,0.00025370340306410486,25.0,0.0
64.5625,0.0007714720472440945,180.11608966503266,0.00025370340306410486,25.0,0.0
65.86377,0.0008130249999999999,190.16776960784313,0.00025370340306410486,25.0,0.0
67.165039,0.0008684367519685041,198.32213796977123,0.00025370340306410486,25.0,0.0
68.466309,0.0009129783661417322,206.65980647467316,0.00025370340306410486,25.0,0.0
69.767578,0.0009699026968503937,218.04817453022875,0.00025370340306410486,25.0,0.0
71.068848,0.0009795146653543308,226.75704401552284,0.00025370340306410486,25.0,0.0
72.370117,0.0010371771062992125,235.743461499183,0.00025370340306410486,25.0,0.0
73.671387,0.0010688726771653544,244.99682904411762,0.00025370340306410486,25.0,0.0
74.972656,0.0011076456889763779,253.96217830882352,0.00025370340306410486,25.0,0.0
76.273926,0.0011456751771653543,263.76549734477123,0.00025370340306410486,25.0,0.0
77.575195,0.0011592784448818897,272.4199091094771,0.00025370340306410486,25.0,0.0
78.876465,0.0012099119488188975,280.05422794117646,0.00025370340306410486,25.0,0.0
80.177734,0.0012481559448818897,291.1042943218954,0.00025370340306410486,25.0,0.0
81.479004,0.0013128199803149607,302.39065053104576,0.00025370340306410486,25.0,0.0
82.780273,0.0013426982086614172,310.63260825163394,0.00025370340306410486,25.0,0.0
84.081543,0.0013822845472440946,318.9076286764706,0.00025370340306410486,25.0,0.0
85.382813,0.001445166062992126,328.23828125,0.00025370340306410486,25.0,0.0
86.684082,0.0014668098622047244,335.88059129901956,0.00025370340306410486,25.0,0.0
87.985352,0.0015065325196850392,346.27703737745094,0.00025370340306410486,25.0,0.0
89.286621,0.0015622686811023621,356.59277982026146,0.00025370340306410486,25.0,0.0
90.587891,0.0016085968503937007,364.80195567810455,0.00025370340306410486,25.0,0.0
91.88916,0.0016262738385826774,374.09206495098033,0.00025370340306410486,25.0,0.0
93.19043,0.0016788768700787401,382.0290543300653,0.00025370340306410486,25.0,0.0
94.491699,0.0017343145866141733,391.2411151960784,0.00025370340306410486,25.0,0.0
95.792969,0.0017555183070866143,400.2638122957516,0.00025370340306410486,25.0,0.0
97.094238,0.001809330590551181,410.70940563725486,0.00025370340306410486,25.0,0.0
98.395508,0.00184759218503937,418.8228400735294,0.00025370340306410486,25.0,0.0
99.696777,0.0019121700590551181,427.0045955882353,0.00025370340306410486,25.0,0.0
100.99805,0.0019329259055118108,436.8960120506536,0.00025370340306410486,25.0,0.0
102.29932,0.001977263188976378,443.84012459150324,0.00025370340306410486,25.0,0.0
103.60059,0.0020388340551181104,454.3146446078431,0.00025370340306410486,25.0,0.0
104.90186,0.00208712874015748,462.4977532679738,0.00025370340306410486,25.0,0.0
106.20313,0.002143722440944882,470.86943423202615,0.00025370340306410486,25.0,0.0
107.50439,0.002188961614173228,481.3698171977124,0.00025370340306410486,25.0,0.0
108.80566,0.002237824409448819,488.5160590277777,0.00025370340306410486,25.0,0.0
110.10693,0.0022894291338582677,495.4303257761438,0.00025370340306410486,25.0,0.0
111.4082,0.0023484667322834643,505.28061172385617,0.00025370340306410486,25.0,0.0
112.70947,0.0023845303149606298,510.42182393790847,0.00025370340306410486,25.0,0.0
114.01074,0.0024341842519685036,518.2922538807189,0.00025370340306410486,25.0,0.0
115.31201,0.002520790748031496,526.7815819035948,0.00025370340306410486,25.0,0.0
116.61328,0.002533837401574803,532.2125970179737,0.00025370340306410486,25.0,0.0
117.91455,0.0026120559055118108,540.7137714460783,0.00025370340306410486,25.0,0.0
119.21582,0.002669990157480315,547.7940921160131,0.00025370340306410486,25.0,0.0
120.51709,0.002740612992125984,554.3971864787582,0.00025370340306410486,25.0,0.0
121.81836,0.0027881043307086614,559.5759548611111,0.00025370340306410486,25.0,0.0
123.11963,0.002828095472440945,564.7667994281045,0.00025370340306410486,25.0,0.0
124.4209,0.002898008464566929,571.5723039215685,0.00025370340306410486,25.0,0.0
125.72217,0.002943187204724409,576.5377093545751,0.00025370340306410486,25.0,0.0
127.02344,0.0030393277559055114,584.8276909722222,0.00025370340306410486,25.0,0.0
128.32471,0.0031020631889763783,588.9319852941176,0.00025370340306410486,25.0,0.0
129.62598,0.003171593700787401,595.5970945669934,0.00025370340306410486,25.0,0.0
130.92725,0.003241895078740157,600.7483149509803,0.00025370340306410486,25.0,0.0
132.22852,0.0033141340551181104,604.699831495098,0.00025370340306410486,25.0,0.0
133.52979,0.003396954330708661,610.2137459150326,0.00025370340306410486,25.0,0.0
134.83105,0.003459538188976378,612.5418453839869,0.00025370340306410486,25.0,0.0
136.13232,0.0035489557086614176,619.0333690767973,0.00025370340306410486,25.0,0.0
137.43359,0.0036119352362204726,622.7636591094771,0.00025370340306410486,25.0,0.0
138.73486,0.0037064659448818897,628.7931219362745,0.00025370340306410486,25.0,0.0
140.03613,0.0038177618110236218,630.2653441584968,0.00025370340306410486,25.0,0.0
141.3374,0.003919250984251969,635.4595588235293,0.00025370340306410486,25.0,0.0
142.63867,0.004030143307086614,639.3474264705882,0.00025370340306410486,25.0,0.0
143.93994,0.004095056496062992,642.6805555555555,0.00025370340306410486,25.0,0.0
145.24121,0.0042111895669291344,645.1255872140523,0.00025370340306410486,25.0,0.0
146.54248,0.004318358661417322,649.0307904411764,0.00025370340306410486,25.0,0.0
147.84375,0.004462055511811024,654.3433670343137,0.00025370340306410486,25.0,0.0
149.14502,0.004570373228346457,655.5969158496732,0.00025370340306410486,25.0,0.0
150.44629,0.004703744488188976,658.5544321895425,0.00025370340306410486,25.0,0.0
151.74756,0.004847222047244094,662.4679330065359,0.00025370340306410486,25.0,0.0
153.04883,0.004992952755905512,665.0819291258169,0.00025370340306410486,25.0,0.0
154.3501,0.005146546062992126,667.6777471405228,0.00025370340306410486,25.0,0.0
155.65137,0.005322185433070866,669.4195261437908,0.00025370340306410486,25.0,0.0
156.95264,0.005454899409448819,673.0207312091502,0.00025370340306410486,25.0,0.0
158.25391,0.005630906496062992,675.1206341911765,0.00025370340306410486,25.0,0.0
159.55518,0.005812070669291338,678.4317044526143,0.00025370340306410486,25.0,0.0
160.85645,0.0060042064960629925,679.1713899101306,0.00025370340306410486,25.0,0.0
162.15771,0.00616767125984252,682.4929789624183,0.00025370340306410486,25.0,0.0
163.45898,0.006390462795275591,683.0584405637254,0.00025370340306410486,25.0,0.0
164.76025,0.006589991535433071,686.28515625,0.00025370340306410486,25.0,0.0
166.06152,0.006830224409448819,688.6642412173202,0.00025370340306410486,25.0,0.0
167.36279,0.007057006692913386,689.6621732026143,0.00025370340306410486,25.0,0.0
168.66406,0.007316151181102362,691.9250663807188,0.00025370340306410486,25.0,0.0
169.96533,0.007572482677165354,693.5912479575162,0.00025370340306410486,25.0,0.0
171.2666,0.007784723031496063,692.7952665441176,0.00025370340306410486,25.0,0.0
172.56787,0.008049979133858267,697.6502246732025,0.00025370340306410486,25.0,0.0
173.86914,0.008297094094488188,698.2648080065359,0.00025370340306410486,25.0,0.0
175.17041,0.008542576181102362,698.4747497957516,0.00025370340306410486,25.0,0.0
176.47168,0.008812708070866142,700.1585222630719,0.00025370340306410486,25.0,0.0
177.77295,0.009058286811023622,700.1878063725491,0.00025370340306410486,25.0,0.0
179.07422,0.009385048228346456,702.9924938725491,0.00025370340306410486,25.0,0.0
180.37549,0.009665668307086614,705.3984119689542,0.00025370340306410486,25.0,0.0
181.67676,0.009958843503937009,704.3997395833334,0.00025370340306410486,25.0,0.0
182.97803,0.010218139763779527,704.3947610294117,0.00025370340306410486,25.0,0.0
184.2793,0.010507897834645669,706.8991779003268,0.00025370340306410486,25.0,0.0
185.58057,0.01080272874015748,709.0963796977123,0.00025370340306410486,25.0,0.0
186.88184,0.011042245866141732,708.6249489379084,0.00025370340306410486,25.0,0.0
188.18311,0.011360238385826772,711.8417075163399,0.00025370340306410486,25.0,0.0
189.48438,0.011639453937007873,709.9220281862745,0.00025370340306410486,25.0,0.0
190.78564,0.012026247637795275,713.2898539624183,0.00025370340306410486,25.0,0.0
192.08691,0.012367154133858268,713.3909058415032,0.00025370340306410486,25.0,0.0
193.38818,0.012731694291338582,715.2731311274509,0.00025370340306410486,25.0,0.0
194.68945,0.013087242519685039,714.96195874183,0.00025370340306410486,25.0,0.0
195.99072,0.01334657559055118,715.2513786764705,0.00025370340306410486,25.0,0.0
197.29199,0.01365380649606299,718.4645118464051,0.00025370340306410486,25.0,0.0
198.59326,0.014014024409448819,716.961243872549,0.00025370340306410486,25.0,0.0
199.89453,0.014339798031496064,718.4822814542483,0.00025370340306410486,25.0,0.0
201.1958,0.014610557677165353,718.5060253267974,0.00025370340306410486,25.0,0.0
202.49707,0.014919821456692912,719.7431066176471,0.00025370340306410486,25.0,0.0
203.79834,0.015296061023622047,721.6677389705882,0.00025370340306410486,25.0,0.0
205.09961,0.015646777952755906,721.3239634395425,0.00025370340306410486,25.0,0.0
206.40088,0.016045233070866142,723.422487745098,0.00025370340306410486,25.0,0.0
207.70215,0.016414817125984252,724.4237387663399,0.00025370340306410486,25.0,0.0
209.00342,0.016791242913385827,725.3956035539215,0.00025370340306410486,25.0,0.0
210.30469,0.01715992342519685,723.6382250816993,0.00025370340306410486,25.0,0.0
211.60596,0.01753995590551181,724.8030790441176,0.00025370340306410486,25.0,0.0
212.90723,0.017835603149606298,725.9249131944445,0.00025370340306410486,25.0,0.0
214.2085,0.018225157086614173,727.7468852124182,0.00025370340306410486,25.0,0.0
215.50977,0.018595487598425196,726.9499591503267,0.00025370340306410486,25.0,0.0
216.81104,0.01891967440944882,728.2951388888889,0.00025370340306410486,25.0,0.0
218.1123,0.019304850393700786,729.8340482026143,0.00025370340306410486,25.0,0.0
219.41357,0.01966533090551181,729.3161254084966,0.00025370340306410486,25.0,0.0
220.71484,0.019998681102362203,730.5958180147057,0.00025370340306410486,25.0,0.0
222.01611,0.020331944881889764,729.5075571895425,0.00025370340306410486,25.0,0.0
223.31738,0.020664009842519687,732.0346711601306,0.00025370340306410486,25.0,0.0
224.61865,0.021074683070866143,733.9554738562091,0.00025370340306410486,25.0,0.0
225.91992,0.02150597440944882,734.3168147467319,0.00025370340306410486,25.0,0.0
227.22119,0.021813948818897637,731.7794117647059,0.00025370340306410486,25.0,0.0
228.52246,0.022106299212598424,734.0944138071894,0.00025370340306410486,25.0,0.0
229.82373,0.022418192913385825,732.2293964460783,0.00025370340306410486,25.0,0.0
231.125,0.022776122047244097,734.633220996732,0.00025370340306410486,25.0,0.0
232.42627,0.023196043307086613,737.2931474673202,0.00025370340306410486,25.0,0.0
233.72754,0.023600092519685038,736.3815614787582,0.00025370340306410486,25.0,0.0
235.02881,0.023976685039370078,738.0208078022875,0.00025370340306410486,25.0,0.0
236.33008,0.024319169291338583,736.4491166258169,0.00025370340306410486,25.0,0.0
237.63135,0.024659336614173227,737.5161866830065,0.00025370340306410486,25.0,0.0
238.93262,0.024961881889763782,737.7580167483659,0.00025370340306410486,25.0,0.0
240.23389,0.025327996062992124,737.3615451388888,0.00025370340306410486,25.0,0.0
241.53516,0.025688568897637796,739.4548100490196,0.00025370340306410486,25.0,0.0
242.83643,0.026060673228346456,740.6362591911765,0.00025370340306410486,25.0,0.0
244.1377,0.026415259842519686,740.2726715686274,0.00025370340306410486,25.0,0.0
245.43896,0.026847293307086618,741.1528033088234,0.00025370340306410486,25.0,0.0
246.74023,0.02717547440944882,741.320414624183,0.00025370340306410486,25.0,0.0
248.0415,0.02755025,740.0621680964051,0.00025370340306410486,25.0,0.0
249.34277,0.02791210039370079,742.0856566584966,0.00025370340306410486,25.0,0.0
250.64404,0.02829662992125984,742.6776705473856,0.00025370340306410486,25.0,0.0
251.94531,0.028693824803149606,744.419092116013,0.00025370340306410486,25.0,0.0
253.24658,0.02912031299212598,743.4426062091503,0.00025370340306410486,25.0,0.0
254.54785,0.029489051181102358,744.2246221405228,0.00025370340306410486,25.0,0.0
255.84912,0.029930029527559056,745.917356004902,0.00025370340306410486,25.0,0.0
257.15039,0.030367076771653543,747.0499897875817,0.00025370340306410486,25.0,0.0
258.45166,0.030742746062992127,746.9187346813725,0.00025370340306410486,25.0,0.0
259.75293,0.03109976377952756,746.2732077205882,0.00025370340306410486,25.0,0.0
261.0542,0.03153196062992126,746.1567861519607,0.00025370340306410486,25.0,0.0
262.35547,0.031913549212598424,747.1302083333333,0.00025370340306410486,25.0,0.0
263.65674,0.03223816141732283,745.692223243464,0.00025370340306410486,25.0,0.0
264.95801,0.03257186811023622,748.259037990196,0.00025370340306410486,25.0,0.0
266.25928,0.03289975393700787,748.0926776960783,0.00025370340306410486,25.0,0.0
267.56055,0.03327230905511811,749.2042994281045,0.00025370340306410486,25.0,0.0
268.86182,0.03368752165354331,748.7874285130719,0.00025370340306410486,25.0,0.0
270.16309,0.03403579133858268,749.9846303104574,0.00025370340306410486,25.0,0.0
271.46436,0.034480862204724405,751.8044577205882,0.00025370340306410486,25.0,0.0
272.76563,0.034922003937007874,750.9086243872548,0.00025370340306410486,25.0,0.0
274.06689,0.03525093503937008,750.7177798202614,0.00025370340306410486,25.0,0.0
275.36816,0.03558839960629921,753.3235549428103,0.00025370340306410486,25.0,0.0
276.66943,0.03593054724409449,752.7818882761437,0.00025370340306410486,25.0,0.0
277.9707,0.036236226377952756,752.3618259803922,0.00025370340306410486,25.0,0.0
279.27197,0.036644293307086614,754.1099366830065,0.00025370340306410486,25.0,0.0
280.57324,0.03697425787401575,751.5194801879085,0.00025370340306410486,25.0,0.0
281.87451,0.037373356299212596,754.3068831699346,0.00025370340306410486,25.0,0.0
283.17578,0.03776978346456693,753.4070159313725,0.00025370340306410486,25.0,0.0
284.47705,0.03818492125984252,756.198606004902,0.00025370340306410486,25.0,0.0
285.77832,0.03858889173228346,756.3808466094771,0.00025370340306410486,25.0,0.0
287.07959,0.039003809055118105,755.0820567810457,0.00025370340306410486,25.0,0.0
288.38086,0.03934553346456693,756.6026858660131,0.00025370340306410486,25.0,0.0
289.68213,0.039730801181102365,756.8956546160131,0.00025370340306410486,25.0,0.0
290.9834,0.04014108464566929,758.6732281454248,0.00025370340306410486,25.0,0.0
292.28467,0.040592206692913385,758.4258323120914,0.00025370340306410486,25.0,0.0
293.58594,0.04097039566929134,758.1801215277777,0.00025370340306410486,25.0,0.0
294.88721,0.04135819291338582,758.9232281454248,0.00025370340306410486,25.0,0.0
296.18848,0.04172008661417323,757.6805300245098,0.00025370340306410486,25.0,0.0
297.48975,0.04214004133858267,757.726664624183,0.00025370340306410486,25.0,0.0
298.79102,0.042422624015748034,759.4793709150326,0.00025370340306410486,25.0,0.0
300.09229,0.04282078149606299,761.0728145424836,0.00025370340306410486,25.0,0.0
301.39355,0.04315975,761.9693882761437,0.00025370340306410486,25.0,0.0
302.69482,0.043491681102362206,760.1817044526143,0.00025370340306410486,25.0,0.0
303.99609,0.04386492913385827,762.572559232026,0.00025370340306410486,25.0,0.0
305.29736,0.04422463976377953,761.1015369689542,0.00025370340306410486,25.0,0.0
306.59863,0.044603909448818896,761.6228809232025,0.00025370340306410486,25.0,0.0
307.8999,0.04502137795275591,762.9814644607842,0.00025370340306410486,25.0,0.0
309.20117,0.04541324606299212,763.6143280228757,0.00025370340306410486,25.0,0.0
310.50244,0.045819468503937005,763.2662632761437,0.00025370340306410486,25.0,0.0
311.80371,0.04626990157480315,764.7894454656863,0.00025370340306410486,25.0,0.0
313.10498,0.046708425196850395,764.3324397467319,0.00025370340306410486,25.0,0.0
314.40625,0.04709337401574803,763.9313470179737,0.00025370340306410486,25.0,0.0
315.70752,0.047440996062992125,763.5153952205882,0.00025370340306410486,25.0,0.0
317.00879,0.04780383661417323,765.6473907271242,0.00025370340306410486,25.0,0.0
318.31006,0.048175610236220474,767.101970996732,0.00025370340306410486,25.0,0.0
319.61133,0.04857841535433071,766.9232536764706,0.00025370340306410486,25.0,0.0
320.9126,0.04895029330708661,765.5076337826796,0.00025370340306410486,25.0,0.0
322.21387,0.04937892322834646,766.6875255310457,0.00025370340306410486,25.0,0.0
323.51514,0.04968553937007874,765.6275020424836,0.00025370340306410486,25.0,0.0
324.81641,0.05003247244094488,767.8932546977123,0.00025370340306410486,25.0,0.0
326.11768,0.05039623228346457,767.2028696895425,0.00025370340306410486,25.0,0.0
327.41895,0.05079763582677165,768.6194342320262,0.00025370340306410486,25.0,0.0
328.72021,0.05123188779527559,768.9687244689542,0.00025370340306410486,25.0,0.0
330.02148,0.05157089566929134,769.5619383169934,0.00025370340306410486,25.0,0.0
331.32275,0.051918572834645675,769.2726715686274,0.00025370340306410486,25.0,0.0
332.62402,0.05226645669291339,770.5702103758169,0.00025370340306410486,25.0,0.0
333.92529,0.05269763976377952,770.1611264297386,0.00025370340306410486,25.0,0.0
335.22656,0.053038061023622046,770.2412939133986,0.00025370340306410486,25.0,0.0
336.52783,0.05346631692913385,771.1000306372548,0.00025370340306410486,25.0,0.0
337.8291,0.053846318897637795,770.5437346813725,0.00025370340306410486,25.0,0.0
339.13037,0.05418892913385826,770.7414470996731,0.00025370340306410486,25.0,0.0
340.43164,0.054539751968503934,772.8759957107842,0.00025370340306410486,25.0,0.0
341.73291,0.054923074803149605,772.3889910130719,0.00025370340306410486,25.0,0.0
343.03418,0.05530536023622047,773.4917534722222,0.00025370340306410486,25.0,0.0
344.33545,0.05566565157480315,773.2296006944445,0.00025370340306410486,25.0,0.0
345.63672,0.056067108267716534,773.952716503268,0.00025370340306410486,25.0,0.0
346.93799,0.05646688779527559,773.5958690767974,0.00025370340306410486,25.0,0.0
348.23926,0.056888643700787396,775.8715788398691,0.00025370340306410486,25.0,0.0
349.54053,0.05729038976377953,774.5232332516339,0.00025370340306410486,25.0,0.0
350.8418,0.057664285433070867,776.1510161356208,0.00025370340306410486,25.0,0.0
352.14307,0.05806283267716535,774.556015114379,0.00025370340306410486,25.0,0.0
353.44434,0.05843533267716535,774.9528186274509,0.00025370340306410486,25.0,0.0
354.74561,0.05881149803149606,775.7037888071895,0.00025370340306410486,25.0,0.0
356.04688,0.05919838779527559,778.0641595179737,0.00025370340306410486,25.0,0.0
357.34814,0.059655748031496064,777.2843392565359,0.00025370340306410486,25.0,0.0
358.64941,0.06002680511811024,775.9660181781045,0.00025370340306410486,25.0,0.0
359.95068,0.06038016141732284,778.7059844771242,0.00025370340306410486,25.0,0.0
361.25195,0.06075036811023622,776.4975745506534,0.00025370340306410486,25.0,0.0
362.55322,0.06104870866141732,777.875919117647,0.00025370340306410486,25.0,0.0
363.85449,0.06139673818897637,780.1082005718953,0.00025370340306410486,25.0,0.0
365.15576,0.061820624015748026,778.8197508169934,0.00025370340306410486,25.0,0.0
366.45703,0.06219074803149607,780.2417279411765,0.00025370340306410486,25.0,0.0
367.7583,0.06257933858267717,779.867493872549,0.00025370340306410486,25.0,0.0
369.05957,0.06292668307086614,781.2717013888888,0.00025370340306410486,25.0,0.0
370.36084,0.0632861811023622,780.521165236928,0.00025370340306410486,25.0,0.0
371.66211,0.06362131692913385,781.6754238153594,0.00025370340306410486,25.0,0.0
372.96338,0.06401660826771653,781.8628982843137,0.00025370340306410486,25.0,0.0
374.26465,0.06439422440944882,782.229217728758,0.00025370340306410486,25.0,0.0
375.56592,0.06478377755905512,782.7086141748365,0.00025370340306410486,25.0,0.0
376.86719,0.0651593877952756,781.5482536764705,0.00025370340306410486,25.0,0.0
378.16846,0.06546936023622046,781.3271548202614,0.00025370340306410486,25.0,0.0
379.46973,0.06586811811023621,783.313419117647,0.00025370340306410486,25.0,0.0
380.771,0.06623194881889763,782.9360702614377,0.00025370340306410486,25.0,0.0
382.07227,0.06662743897637795,783.2742289624182,0.00025370340306410486,25.0,0.0
383.37354,0.06695717716535432,783.9957107843136,0.00025370340306410486,25.0,0.0
384.6748,0.06732651968503937,784.7545445261437,0.00025370340306410486,25.0,0.0
385.97607,0.06766857283464567,784.1661305147057,0.00025370340306410486,25.0,0.0
387.27734,0.0679961279527559,783.95414624183,0.00025370340306410486,25.0,0.0
388.57861,0.06841851771653543,785.7429789624183,0.00025370340306410486,25.0,0.0
389.87988,0.0687953346456693,785.9476358251633,0.00025370340306410486,25.0,0.0
391.18115,0.0692504251968504,785.8203380310457,0.00025370340306410486,25.0,0.0
392.48242,0.06964623228346456,785.6837724673202,0.00025370340306410486,25.0,0.0
393.78369,0.0700500059055118,786.3468647875817,0.00025370340306410486,25.0,0.0
395.08496,0.07046739763779528,787.5519046160131,0.00025370340306410486,25.0,0.0
396.38623,0.07081281692913387,786.6942401960783,0.00025370340306410486,25.0,0.0
397.6875,0.07121603346456692,787.4836601307189,0.00025370340306410486,25.0,0.0
398.98877,0.07159099212598424,787.4887152777778,0.00025370340306410486,25.0,0.0
400.29004,0.07198804921259842,789.0299223856209,0.00025370340306410486,25.0,0.0
401.59131,0.07240776968503937,789.8100745506536,0.00025370340306410486,25.0,0.0
402.89258,0.0727521279527559,789.0025531045751,0.00025370340306410486,25.0,0.0
404.19385,0.07312067322834646,789.6879084967319,0.00025370340306410486,25.0,0.0
405.49512,0.07344557086614173,787.708869485294,0.00025370340306410486,25.0,0.0
406.79639,0.07377963779527559,789.8486519607843,0.00025370340306410486,25.0,0.0
408.09766,0.07413422244094488,790.1856107026143,0.00025370340306410486,25.0,0.0
409.39893,0.07447490748031496,788.1682495915032,0.00025370340306410486,25.0,0.0
410.7002,0.0747636496062992,790.5521343954248,0.00025370340306410486,25.0,0.0
412.00146,0.07512984842519685,791.8730596405228,0.00025370340306410486,25.0,0.0
413.30273,0.07561351968503936,792.6044475081699,0.00025370340306410486,25.0,0.0
414.604,0.07598127362204724,790.5918351715685,0.00025370340306410486,25.0,0.0
415.90527,0.07635642519685039,792.121706495098,0.00025370340306410486,25.0,0.0
417.20654,0.07670717125984253,792.4711243872548,0.00025370340306410486,25.0,0.0
418.50781,0.07707473031496063,794.5206546160131,0.00025370340306410486,25.0,0.0
419.80908,0.07746624409448818,792.2500510620914,0.00025370340306410486,25.0,0.0
421.11035,0.07781829330708662,795.1103707107843,0.00025370340306410486,25.0,0.0
422.41162,0.07815733464566929,793.4622651143791,0.00025370340306410486,25.0,0.0
423.71289,0.0785130216535433,794.7724162581699,0.00025370340306410486,25.0,0.0
425.01416,0.07891970669291339,793.9905790441177,0.00025370340306410486,25.0,0.0
426.31543,0.07929494488188976,795.1388122957516,0.00025370340306410486,25.0,0.0
427.6167,0.07977627559055119,796.6755259395425,0.00025370340306410486,25.0,0.0
428.91797,0.08013969488188977,794.8652216094771,0.00025370340306410486,25.0,0.0
430.21924,0.08047636023622047,794.0854013480392,0.00025370340306410486,25.0,0.0
431.52051,0.08081048818897638,794.4406913807189,0.00025370340306410486,25.0,0.0
432.82178,0.08118454133858267,797.1979166666666,0.00025370340306410486,25.0,0.0
434.12305,0.08156965944881889,797.113587622549,0.00025370340306410486,25.0,0.0
435.42432,0.08191719094488188,797.8736723856209,0.00025370340306410486,25.0,0.0
436.72559,0.08229787598425196,796.6643178104574,0.00025370340306410486,25.0,0.0
438.02686,0.0826729625984252,798.5362540849673,0.00025370340306410486,25.0,0.0
439.32813,0.0830736751968504,798.4234323937908,0.00025370340306410486,25.0,0.0
440.62939,0.0834555374015748,797.4236877042483,0.00025370340306410486,25.0,0.0
441.93066,0.08381159842519685,797.9554993872548,0.00025370340306410486,25.0,0.0
443.23193,0.08417743897637794,797.1227022058823,0.00025370340306410486,25.0,0.0
444.5332,0.08450427952755905,798.9233302696078,0.00025370340306410486,25.0,0.0
445.83447,0.08484828543307087,798.2477787990196,0.00025370340306410486,25.0,0.0
447.13574,0.0851666653543307,798.7466299019608,0.00025370340306410486,25.0,0.0
448.43701,0.08549751181102362,799.2907220179738,0.00025370340306410486,25.0,0.0
449.73828,0.08588194488188977,799.1375102124182,0.00025370340306410486,25.0,0.0
451.03955,0.0862201594488189,800.472452001634,0.00025370340306410486,25.0,0.0
452.34082,0.08665412401574803,802.3200316584966,0.00025370340306410486,25.0,0.0
453.64209,0.08700826181102363,801.1513735702614,0.00025370340306410486,25.0,0.0
454.94336,0.08744005511811023,800.8853400735294,0.00025370340306410486,25.0,0.0
456.24463,0.08779890354330709,802.0902267156862,0.00025370340306410486,25.0,0.0
457.5459,0.08817891141732283,802.8146956699345,0.00025370340306410486,25.0,0.0
458.84717,0.08856177165354331,801.1912785947712,0.00025370340306410486,25.0,0.0
460.14844,0.08891785039370079,802.3695874183006,0.00025370340306410486,25.0,0.0
461.44971,0.08933411023622047,803.4435508578431,0.00025370340306410486,25.0,0.0
462.75098,0.08969996850393701,802.9507761437908,0.00025370340306410486,25.0,0.0
464.05225,0.09009325984251967,804.4328788807189,0.00025370340306410486,25.0,0.0
465.35352,0.09048060236220472,802.7405790441176,0.00025370340306410486,25.0,0.0
466.65479,0.09083235039370079,804.4659160539215,0.00025370340306410486,25.0,0.0
467.95605,0.09119327559055118,804.4154411764705,0.00025370340306410486,25.0,0.0
469.25732,0.0915216122047244,804.1683006535947,0.00025370340306410486,25.0,0.0
470.55859,0.09185014173228347,803.2081290849673,0.00025370340306410486,25.0,0.0
471.85986,0.09218168700787402,805.5034977532679,0.00025370340306410486,25.0,0.0
473.16113,0.0925519625984252,806.7399152369281,0.00025370340306410486,25.0,0.0
474.4624,0.09293433661417323,806.3432393790848,0.00025370340306410486,25.0,0.0
475.76367,0.09327126574803149,806.1577308006536,0.00025370340306410486,25.0,0.0
477.06494,0.09367711811023621,808.0117953431372,0.00025370340306410486,25.0,0.0
478.36621,0.09409325393700788,806.0818780637254,0.00025370340306410486,25.0,0.0
479.66748,0.09444131299212598,805.6369995915031,0.00025370340306410486,25.0,0.0
480.96875,0.09477071653543306,806.5339052287582,0.00025370340306410486,25.0,0.0
482.27002,0.09509324409448819,807.5087060866013,0.00025370340306410486,25.0,0.0
483.57129,0.0954463248031496,807.5335733251634,0.00025370340306410486,25.0,0.0
484.87256,0.09578898818897638,807.3255718954248,0.00025370340306410486,25.0,0.0
486.17383,0.0962046062992126,808.4914215686274,0.00025370340306410486,25.0,0.0
487.4751,0.09658255118110237,809.4760774101306,0.00025370340306410486,25.0,0.0
488.77637,0.09700982677165354,810.9760263480391,0.00025370340306410486,25.0,0.0
490.07764,0.09742809251968504,808.5328839869281,0.00025370340306410486,25.0,0.0
491.37891,0.09778312204724408,808.1137663398691,0.00025370340306410486,25.0,0.0
492.68018,0.09812019291338582,809.4900428921568,0.00025370340306410486,25.0,0.0
493.98145,0.09847942716535434,807.4728604983659,0.00025370340306410486,25.0,0.0
495.28271,0.09887826181102362,811.6588031045751,0.00025370340306410486,25.0,0.0
496.58398,0.09928031299212597,810.8946844362744,0.00025370340306410486,25.0,0.0
497.88525,0.0996597283464567,809.3202614379085,0.00025370340306410486,25.0,0.0
499.18652,0.10002784645669292,810.0397518382352,0.00025370340306410486,25.0,0.0
500.48779,0.10037859842519685,811.6356719771242,0.00025370340306410486,25.0,0.0
501.78906,0.10070020472440945,810.7659824346405,0.00025370340306410486,25.0,0.0
503.09033,0.10112890157480316,813.414573120915,0.00025370340306410486,25.0,0.0
504.3916,0.10151058267716535,810.2460682189542,0.00025370340306410486,25.0,0.0
505.69287,0.10183570866141733,814.2136693218953,0.00025370340306410486,25.0,0.0
506.99414,0.10225441929133858,812.6397314133986,0.00025370340306410486,25.0,0.0
508.29541,0.10262468503937007,812.5041615604574,0.00025370340306410486,25.0,0.0
509.59668,0.10304826377952755,813.0426879084966,0.00025370340306410486,25.0,0.0
510.89795,0.10340257283464567,812.1447354983659,0.00025370340306410486,25.0,0.0
512.19922,0.10374068700787402,814.6828278186274,0.00025370340306410486,25.0,0.0
513.50049,0.1042112125984252,815.2850796568626,0.00025370340306410486,25.0,0.0
514.80176,0.10458325984251968,813.0125868055555,0.00025370340306410486,25.0,0.0
516.10303,0.10489911811023621,811.7522977941176,0.00025370340306410486,25.0,0.0
517.4043,0.10525518503937008,815.2225541258169,0.00025370340306410486,25.0,0.0
518.70557,0.10558369094488188,813.2813010620914,0.00025370340306410486,25.0,0.0
520.00684,0.10597830118110235,816.6320720996731,0.00025370340306410486,25.0,0.0
521.30811,0.10643630708661415,816.6053921568626,0.00025370340306410486,25.0,0.0
522.60938,0.106805,815.3719618055555,0.00025370340306410486,25.0,0.0
523.91064,0.10713599409448818,813.4409211601306,0.00025370340306410486,25.0,0.0
525.21191,0.10747530511811022,815.4993617238562,0.00025370340306410486,25.0,0.0
526.51318,0.10784386811023622,815.3078788807189,0.00025370340306410486,25.0,0.0
527.81445,0.10810963779527558,814.5832312091503,0.00025370340306410486,25.0,0.0
529.11572,0.10844581692913387,815.8153850081699,0.00025370340306410486,25.0,0.0
530.41699,0.10888248031496063,817.5115655637255,0.00025370340306410486,25.0,0.0
531.71826,0.10928162007874015,816.9563163807188,0.00025370340306410486,25.0,0.0
533.01953,0.1096845374015748,819.1962571486928,0.00025370340306410486,25.0,0.0
534.3208,0.1101215059055118,816.9621119281045,0.00025370340306410486,25.0,0.0
535.62207,0.1104944094488189,816.5838184232026,0.00025370340306410486,25.0,0.0
536.92334,0.11082446456692914,817.4828176062091,0.00025370340306410486,25.0,0.0
538.22461,0.111169937007874,818.2135416666666,0.00025370340306410486,25.0,0.0
539.52588,0.11154247834645668,819.1500204248366,0.00025370340306410486,25.0,0.0
540.82715,0.11186354527559055,818.5965839460785,0.00025370340306410486,25.0,0.0
542.12842,0.11222449409448819,818.4686734068626,0.00025370340306410486,25.0,0.0
543.42969,0.11262249606299213,820.6971507352941,0.00025370340306410486,25.0,0.0
544.73096,0.11300820078740158,819.7985855800653,0.00025370340306410486,25.0,0.0
546.03223,0.1133834625984252,819.1200980392157,0.00025370340306410486,25.0,0.0
547.3335,0.11377929527559055,818.7977175245097,0.00025370340306410486,25.0,0.0
548.63477,0.11411532086614172,818.3133935866013,0.00025370340306410486,25.0,0.0
549.93604,0.11450593110236221,819.9312704248366,0.00025370340306410486,25.0,0.0
551.2373,0.11490246653543307,820.3451031454248,0.00025370340306410486,25.0,0.0
552.53857,0.1153252027559055,822.7098396650326,0.00025370340306410486,25.0,0.0
553.83984,0.11572753346456692,821.3342524509803,0.00025370340306410486,25.0,0.0
555.14111,0.11608631102362206,820.5142718545751,0.00025370340306410486,25.0,0.0
556.44238,0.11646007283464567,820.7429534313725,0.00025370340306410486,25.0,0.0
557.74365,0.11681141141732282,822.8554942810457,0.00025370340306410486,25.0,0.0
559.04492,0.11719101574803148,821.5837418300654,0.00025370340306410486,25.0,0.0
560.34619,0.11765263385826771,822.8799530228757,0.00025370340306410486,25.0,0.0
561.64746,0.11804165944881889,821.8512816584966,0.00025370340306410486,25.0,0.0
562.94873,0.11840400590551181,822.3633323120915,0.00025370340306410486,25.0,0.0
564.25,0.11876041338582677,821.9891493055555,0.00025370340306410486,25.0,0.0
565.55127,0.11912754527559055,823.8614685457516,0.00025370340306410486,25.0,0.0
566.85254,0.11951199409448819,824.1351868872548,0.00025370340306410486,25.0,0.0
568.15381,0.11984492322834644,822.5459048202614,0.00025370340306410486,25.0,0.0
569.45508,0.12023739960629921,823.9961703431371,0.00025370340306410486,25.0,0.0
570.75635,0.12069384448818897,824.0431219362744,0.00025370340306410486,25.0,0.0
572.05762,0.12103479921259842,823.5140420751634,0.00025370340306410486,25.0,0.0
573.35889,0.12137698622047244,824.1450163398692,0.00025370340306410486,25.0,0.0
574.66016,0.12177103346456693,824.3728553921568,0.00025370340306410486,25.0,0.0
575.96143,0.12217561811023622,824.6955933415032,0.00025370340306410486,25.0,0.0
577.2627,0.12259842322834645,826.2405024509803,0.00025370340306410486,25.0,0.0
578.56396,0.12296656496062992,825.0133782679738,0.00025370340306410486,25.0,0.0
579.86523,0.12332002755905512,824.0598703022875,0.00025370340306410486,25.0,0.0
581.1665,0.12368367322834645,824.4009650735294,0.00025370340306410486,25.0,0.0
582.46777,0.12409577952755904,824.8597069035948,0.00025370340306410486,25.0,0.0
583.76904,0.12451812795275591,826.9606821895425,0.00025370340306410486,25.0,0.0
585.07031,0.12491289173228345,826.9781198937908,0.00025370340306410486,25.0,0.0
586.37158,0.1253032657480315,824.6621221405228,0.00025370340306410486,25.0,0.0
587.67285,0.1256282874015748,824.5790951797385,0.00025370340306410486,25.0,0.0
588.97412,0.12597442913385826,825.5951031454248,0.00025370340306410486,25.0,0.0
590.27539,0.12634971456692912,828.4145475898692,0.00025370340306410486,25.0,0.0
591.57666,0.12673087992125984,826.8343290441176,0.00025370340306410486,25.0,0.0
592.87793,0.12707916732283464,827.5748825571894,0.00025370340306410486,25.0,0.0
594.1792,0.12740770866141732,829.37788500817,0.00025370340306410486,25.0,0.0
595.48047,0.1277686811023622,828.301496119281,0.00025370340306410486,25.0,0.0
596.78174,0.1281101751968504,827.7454299428103,0.00025370340306410486,25.0,0.0
598.08301,0.12852608267716537,829.0636744281046,0.00025370340306410486,25.0,0.0
599.38428,0.12889110236220472,828.0104677287582,0.00025370340306410486,25.0,0.0
600.68555,0.1293475118110236,830.4883833741831,0.00025370340306410486,25.0,0.0
601.98682,0.1297625846456693,828.8690767973856,0.00025370340306410486,25.0,0.0
603.28809,0.13021755118110237,830.7690206290848,0.00025370340306410486,25.0,0.0
604.58936,0.130607,827.9695159313725,0.00025370340306410486,25.0,0.0
605.89063,0.13099784448818896,830.0215992647059,0.00025370340306410486,25.0,0.0
607.19189,0.13144220472440946,828.9891237745097,0.00025370340306410486,25.0,0.0
608.49316,0.1318551181102362,830.2243668300653,0.00025370340306410486,25.0,0.0
609.79443,0.13228355708661416,830.5820057189542,0.00025370340306410486,25.0,0.0
611.0957,0.13262908661417325,829.13773999183,0.00025370340306410486,25.0,0.0
612.39697,0.13292351968503938,828.6130259395425,0.00025370340306410486,25.0,0.0
613.69824,0.13327656102362204,830.0105698529411,0.00025370340306410486,25.0,0.0
614.99951,0.133623405511811,829.4180453431372,0.00025370340306410486,25.0,0.0
616.30078,0.1340348779527559,831.1449908088234,0.00025370340306410486,25.0,0.0
617.60205,0.1344688405511811,832.8832465277777,0.00025370340306410486,25.0,0.0
618.90332,0.13488116929133856,831.9664522058823,0.00025370340306410486,25.0,0.0
620.20459,0.13532125787401575,830.4483251633986,0.00025370340306410486,25.0,0.0
621.50586,0.13569413976377953,831.825954861111,0.00025370340306410486,25.0,0.0
622.80713,0.13607293307086613,832.1561989379085,0.00025370340306410486,25.0,0.0
624.1084,0.13639248818897637,831.9834048202613,0.00025370340306410486,25.0,0.0
625.40967,0.1367997933070866,833.9331597222222,0.00025370340306410486,25.0,0.0
626.71094,0.13723840354330707,831.9225132761437,0.00025370340306410486,25.0,0.0
628.01221,0.1375837244094488,830.9228451797385,0.00025370340306410486,25.0,0.0
629.31348,0.1380046751968504,833.0650020424836,0.00025370340306410486,25.0,0.0
630.61475,0.1383873897637795,832.6869638480391,0.00025370340306410486,25.0,0.0
631.91602,0.1388089625984252,832.8153594771242,0.00025370340306410486,25.0,0.0
633.21729,0.13916580511811022,832.3349162581699,0.00025370340306410486,25.0,0.0
634.51855,0.13959324409448817,832.9224366830065,0.00025370340306410486,25.0,0.0
635.81982,0.1400058779527559,833.5737591911764,0.00025370340306410486,25.0,0.0
637.12109,0.14041791338582676,833.5847120098038,0.00025370340306410486,25.0,0.0
638.42236,0.14085998425196852,834.334686478758,0.00025370340306410486,25.0,0.0
639.72363,0.14123934251968503,832.3461754493463,0.00025370340306410486,25.0,0.0
641.0249,0.14166950393700786,834.7377961601308,0.00025370340306410486,25.0,0.0
642.32617,0.14205984448818898,835.5346966911765,0.00025370340306410486,25.0,0.0
643.62744,0.14247031889763778,834.8247549019608,0.00025370340306410486,25.0,0.0
644.92871,0.14288373818897637,835.0574959150326,0.00025370340306410486,25.0,0.0
646.22998,0.1433281338582677,833.7577614379085,0.00025370340306410486,25.0,0.0
647.53125,0.143751937007874,834.4144199346404,0.00025370340306410486,25.0,0.0
648.83252,0.14413405118110237,834.4467677696078,0.00025370340306410486,25.0,0.0
650.13379,0.14453231102362205,836.4513378267973,0.00025370340306410486,25.0,0.0
651.43506,0.1449253031496063,836.3425755718954,0.00025370340306410486,25.0,0.0
652.73633,0.1453747086614173,835.0712060866013,0.00025370340306410486,25.0,0.0
654.0376,0.14577807086614172,836.4400786356209,0.00025370340306410486,25.0,0.0
655.33887,0.14614704527559055,834.8163807189542,0.00025370340306410486,25.0,0.0
656.64014,0.14649852559055118,834.748953227124,0.00025370340306410486,25.0,0.0
657.94141,0.14687065551181103,835.8036662581699,0.00025370340306410486,25.0,0.0
659.24268,0.14726656889763778,836.1429227941177,0.00025370340306410486,25.0,0.0
660.54395,0.14763969685039371,836.2063929738562,0.00025370340306410486,25.0,0.0
661.84521,0.14807029330708663,836.8592473447712,0.00025370340306410486,25.0,0.0
663.14648,0.1484741496062992,837.1237745098039,0.00025370340306410486,25.0,0.0
664.44775,0.14889687204724408,836.9839665032679,0.00025370340306410486,25.0,0.0
665.74902,0.1493478031496063,837.1073325163399,0.00025370340306410486,25.0,0.0
667.05029,0.14975502755905512,835.782475490196,0.00025370340306410486,25.0,0.0
668.35156,0.1501560334645669,836.8200316584966,0.00025370340306410486,25.0,0.0
669.65283,0.15054490551181104,836.8259548611111,0.00025370340306410486,25.0,0.0
670.9541,0.15096655118110236,838.7364940767974,0.00025370340306410486,25.0,0.0
672.25537,0.15138015748031497,837.2416513480392,0.00025370340306410486,25.0,0.0
673.55664,0.1517778897637795,837.9911917892156,0.00025370340306410486,25.0,0.0
674.85791,0.15217896456692914,837.437806372549,0.00025370340306410486,25.0,0.0
676.15918,0.15261576968503937,838.6458078022874,0.00025370340306410486,25.0,0.0
677.46045,0.1530911279527559,839.0775633169934,0.00025370340306410486,25.0,0.0
678.76172,0.15347305511811024,838.7638633578431,0.00025370340306410486,25.0,0.0
680.06299,0.15393219881889764,838.5465686274508,0.00025370340306410486,25.0,0.0
681.36426,0.15431918307086614,838.7912071078431,0.00025370340306410486,25.0,0.0
682.66553,0.1546723877952756,836.5379391339869,0.00025370340306410486,25.0,0.0
683.9668,0.15503280708661415,837.1153747957517,0.00025370340306410486,25.0,0.0
685.26807,0.15541100393700788,838.0166207107842,0.00025370340306410486,25.0,0.0
686.56934,0.1558693248031496,839.0885416666666,0.00025370340306410486,25.0,0.0
687.87061,0.15630070866141732,838.6734068627451,0.00025370340306410486,25.0,0.0
689.17188,0.15674692125984252,840.2885518790849,0.00025370340306410486,25.0,0.0
690.47314,0.15723896456692912,840.2989685457516,0.00025370340306410486,25.0,0.0
691.77441,0.15762914173228346,840.3871017156862,0.00025370340306410486,25.0,0.0
693.07568,0.15805918700787402,841.559002246732,0.00025370340306410486,25.0,0.0
694.37695,0.15840931692913385,838.736621732026,0.00025370340306410486,25.0,0.0
695.67822,0.15879137401574803,838.8528645833333,0.00025370340306410486,25.0,0.0
696.97949,0.15925800196850393,840.6988868464052,0.00025370340306410486,25.0,0.0
698.28076,0.15968120669291339,840.395143995098,0.00025370340306410486,25.0,0.0
699.58203,0.16010396653543307,839.9849366830065,0.00025370340306410486,25.0,0.0
700.8833,0.16052514173228347,839.4076031454248,0.00025370340306410486,25.0,0.0
702.18457,0.16101800590551182,839.9120710784314,0.00025370340306410486,25.0,0.0
703.48584,0.16148226377952754,842.4671670751634,0.00025370340306410486,25.0,0.0
704.78711,0.16196140157480315,839.7592933006534,0.00025370340306410486,25.0,0.0
706.08838,0.16239510826771653,841.032986111111,0.00025370340306410486,25.0,0.0
707.38965,0.1628218562992126,840.5256587009803,0.00025370340306410486,25.0,0.0
708.69092,0.1631727125984252,838.1523182189542,0.00025370340306410486,25.0,0.0
709.99219,0.1634884192913386,840.4076031454248,0.00025370340306410486,25.0,0.0
711.29346,0.16392142125984252,841.1926572712417,0.00025370340306410486,25.0,0.0
712.59473,0.1644377401574803,842.2561019199345,0.00025370340306410486,25.0,0.0
713.896,0.16493270472440946,842.2521190767974,0.00025370340306410486,25.0,0.0
715.19727,0.16532965157480314,840.4984170751633,0.00025370340306410486,25.0,0.0
716.49854,0.16580248622047244,841.2685866013072,0.00025370340306410486,25.0,0.0
717.7998,0.166241155511811,841.4330831290849,0.00025370340306410486,25.0,0.0
719.10107,0.1667163149606299,840.5847375408497,0.00025370340306410486,25.0,0.0
720.40234,0.16713000393700786,842.891339869281,0.00025370340306410486,25.0,0.0
721.70361,0.16752142322834646,842.2023845996731,0.00025370340306410486,25.0,0.0
723.00488,0.1679397598425197,842.043683619281,0.00025370340306410486,25.0,0.0
724.30615,0.16842055118110236,843.2466809640522,0.00025370340306410486,25.0,0.0
725.60742,0.16887178543307085,841.3392820669934,0.00025370340306410486,25.0,0.0
726.90869,0.16935033661417323,842.8500051062091,0.00025370340306410486,25.0,0.0
728.20996,0.1697675334645669,842.0623212826797,0.00025370340306410486,25.0,0.0
729.51123,0.17019153543307086,843.0398029003268,0.00025370340306410486,25.0,0.0
730.8125,0.1706165,843.3041002859477,0.00025370340306410486,25.0,0.0
732.11377,0.17108973622047244,842.7620506535948,0.00025370340306410486,25.0,0.0
733.41504,0.17151963976377954,843.0768995098039,0.00025370340306410486,25.0,0.0
734.71631,0.17194455708661416,844.6802491830065,0.00025370340306410486,25.0,0.0
736.01758,0.17232196850393702,841.3927440767974,0.00025370340306410486,25.0,0.0
737.31885,0.17273707677165354,842.7856158088234,0.00025370340306410486,25.0,0.0
738.62012,0.1731989192913386,843.4369127859476,0.00025370340306410486,25.0,0.0
739.92139,0.17369242913385827,845.8574346405228,0.00025370340306410486,25.0,0.0
741.22266,0.17414227952755904,843.7518892973856,0.00025370340306410486,25.0,0.0
742.52393,0.17462565157480314,844.2456086601306,0.00025370340306410486,25.0,0.0
743.8252,0.17509426377952755,843.2480596405228,0.00025370340306410486,25.0,0.0
745.12646,0.1755036594488189,843.0327563316993,0.00025370340306410486,25.0,0.0
746.42773,0.17593236614173227,843.0267820669934,0.00025370340306410486,25.0,0.0
747.729,0.17642721456692914,844.3166104983659,0.00025370340306410486,25.0,0.0
749.03027,0.17693704527559057,844.6526245915032,0.00025370340306410486,25.0,0.0
750.33154,0.17746300984251967,844.1749897875816,0.00025370340306410486,25.0,0.0
751.63281,0.1779087539370079,843.9000970179738,0.00025370340306410486,25.0,0.0
752.93408,0.17832368700787402,842.6593392565359,0.00025370340306410486,25.0,0.0
754.23535,0.17878549212598427,843.8506689133986,0.00025370340306410486,25.0,0.0
755.53662,0.17917685433070865,845.5224673202614,0.00025370340306410486,25.0,0.0
756.83789,0.17967174803149605,844.981694240196,0.00025370340306410486,25.0,0.0
758.13916,0.1801318188976378,842.6195618872548,0.00025370340306410486,25.0,0.0
759.44043,0.18060885629921258,844.6659773284314,0.00025370340306410486,25.0,0.0
760.7417,0.1809997342519685,845.1268637663399,0.00025370340306410486,25.0,0.0
762.04297,0.1815118188976378,844.4394658905228,0.00025370340306410486,25.0,0.0
763.34424,0.18196461417322835,844.1703176062091,0.00025370340306410486,25.0,0.0
764.64551,0.18242557677165355,844.0596660539215,0.00025370340306410486,25.0,0.0
765.94678,0.18287839566929134,844.383118872549,0.00025370340306410486,25.0,0.0
767.24805,0.18333063976377953,845.2100183823528,0.00025370340306410486,25.0,0.0
768.54932,0.18376932086614173,844.5473090277777,0.00025370340306410486,25.0,0.0
769.85059,0.1842530688976378,845.5560661764705,0.00025370340306410486,25.0,0.0
771.15186,0.18472464960629922,845.0833588643791,0.00025370340306410486,25.0,0.0
772.45313,0.1852289311023622,845.1803257761438,0.00025370340306410486,25.0,0.0
773.75439,0.18574892322834646,845.4073988970588,0.00025370340306410486,25.0,0.0
775.05566,0.1862245748031496,843.4268790849673,0.00025370340306410486,25.0,0.0
776.35693,0.18669230708661416,845.4683159722222,0.00025370340306410486,25.0,0.0
777.6582,0.1872121929133858,845.3458180147057,0.00025370340306410486,25.0,0.0
778.95947,0.1877362342519685,847.771777982026,0.00025370340306410486,25.0,0.0
780.26074,0.18818019488188975,844.0335477941177,0.00025370340306410486,25.0,0.0
781.56201,0.18862542125984252,843.9626225490196,0.00025370340306410486,25.0,0.0
782.86328,0.18911334645669292,845.939031862745,0.00025370340306410486,25.0,0.0
784.16455,0.1896440275590551,845.5252246732026,0.00025370340306410486,25.0,0.0
785.46582,0.19015344881889762,845.5409773284313,0.00025370340306410486,25.0,0.0
786.76709,0.19067388582677167,845.5426113153594,0.00025370340306410486,25.0,0.0
788.06836,0.19115184842519684,845.9734477124183,0.00025370340306410486,25.0,0.0
789.36963,0.19156531496062992,844.3280228758169,0.00025370340306410486,25.0,0.0
790.6709,0.1921065334645669,846.9096711601306,0.00025370340306410486,25.0,0.0
791.97217,0.19260951181102362,846.19140625,0.00025370340306410486,25.0,0.0
793.27344,0.1931813405511811,847.5045700571895,0.00025370340306410486,25.0,0.0
794.57471,0.19367188188976378,845.7561529820262,0.00025370340306410486,25.0,0.0
795.87598,0.1941611220472441,845.7662632761437,0.00025370340306410486,25.0,0.0
797.17725,0.19471991535433072,845.5659722222222,0.00025370340306410486,25.0,0.0
798.47852,0.19525519488188975,846.6855341094771,0.00025370340306410486,25.0,0.0
799.77979,0.19580029527559054,846.1891850490196,0.00025370340306410486,25.0,0.0
801.08105,0.19621187401574802,845.4978553921568,0.00025370340306410486,25.0,0.0
802.38232,0.19668555314960628,844.1755514705882,0.00025370340306410486,25.0,0.0
803.68359,0.1970522244094488,843.9647416258169,0.00025370340306410486,25.0,0.0
804.98486,0.19746913385826773,844.5271139705882,0.00025370340306410486,25.0,0.0
806.28613,0.19797049212598425,847.6132046568626,0.00025370340306410486,25.0,0.0
807.5874,0.19848624015748034,845.6918402777777,0.00025370340306410486,25.0,0.0
808.88867,0.19905805118110234,846.0649509803922,0.00025370340306410486,25.0,0.0
810.18994,0.19954576771653545,844.6908445669934,0.00025370340306410486,25.0,0.0
811.49121,0.20005114173228347,846.028058619281,0.00025370340306410486,25.0,0.0
812.79248,0.20058818897637795,845.8530943627451,0.00025370340306410486,25.0,0.0
814.09375,0.20108761811023623,844.6196640114377,0.00025370340306410486,25.0,0.0
815.39502,0.20160726377952753,844.8097681781045,0.00025370340306410486,25.0,0.0
816.69629,0.20214399606299213,846.0154462826797,0.00025370340306410486,25.0,0.0
817.99756,0.2026329527559055,845.5442197712418,0.00025370340306410486,25.0,0.0
818.49805,0.20289710629921262,848.3892207924836,0.00025370340306410486,25.0,0.0