File: datasets/am_bench_2022/csv/0-XY.20-3.csv
Time(s),Strain(%),Stress(MPa),SR(s-1),Temp(C),Angle(deg)
13.624268,5.890295078740158e-06,15.291232859156736,0.00025370340306410486,25.0,0.0
15.626221,2.576613188976378e-05,21.495278995258236,0.00025370340306410486,25.0,0.0
16.92749,1.5867839566929134e-05,26.13408945277457,0.00025370340306410486,25.0,0.0
18.22876,4.096738582677165e-05,30.97359477124183,0.00025370340306410486,25.0,0.0
19.530029,8.187822440944882e-05,34.873679354094584,0.00025370340306410486,25.0,0.0
20.831299,9.701474212598424e-05,39.148304498269894,0.00025370340306410486,25.0,0.0
22.132568,0.00011133210826771654,44.71034730231962,0.00025370340306410486,25.0,0.0
23.433838,0.0001071552401574803,49.26757657311291,0.00025370340306410486,25.0,0.0
24.735107,0.00014770630511811022,57.6682839933359,0.00025370340306410486,25.0,0.0
26.036377,0.00015320266732283465,62.97440984236832,0.00025370340306410486,25.0,0.0
27.337646,0.00021013673228346456,70.99765218505704,0.00025370340306410486,25.0,0.0
28.638916,0.0002308345472440945,76.43255158272459,0.00025370340306410486,25.0,0.0
29.940186,0.00024207352362204724,81.66536716647444,0.00025370340306410486,25.0,0.0
31.241455,0.00026699661417322836,87.84113546072024,0.00025370340306410486,25.0,0.0
32.542725,0.0002685365157480315,95.38648212226066,0.00025370340306410486,25.0,0.0
33.843994,0.000335285,103.77199026015636,0.00025370340306410486,25.0,0.0
35.145264,0.00035771549212598426,109.2641548122517,0.00025370340306410486,25.0,0.0
36.446533,0.00037752358267716536,116.96211713443547,0.00025370340306410486,25.0,0.0
37.747803,0.0003906589763779527,125.0364808407023,0.00025370340306410486,25.0,0.0
39.049072,0.0004598008267716536,132.49872869409202,0.00025370340306410486,25.0,0.0
40.350342,0.0005019289173228347,142.6323311546841,0.00025370340306410486,25.0,0.0
41.651611,0.0005090023031496064,148.4718082788671,0.00025370340306410486,25.0,0.0
42.952881,0.0005107051181102362,156.3519825708061,0.00025370340306410486,25.0,0.0
44.25415,0.0005402527952755905,164.7804972446495,0.00025370340306410486,25.0,0.0
45.55542,0.0006316716929133858,175.0554607202358,0.00025370340306410486,25.0,0.0
46.856689,0.000638650059055118,183.680543380751,0.00025370340306410486,25.0,0.0
48.157959,0.0006756760433070866,192.18945277457388,0.00025370340306410486,25.0,0.0
49.459229,0.0007004345472440944,201.521425092913,0.00025370340306410486,25.0,0.0
50.760498,0.0007200423818897638,210.52729719338717,0.00025370340306410486,25.0,0.0
52.061768,0.0007807169881889764,220.45347686787133,0.00025370340306410486,25.0,0.0
53.363037,0.0008180107677165354,228.12696398820964,0.00025370340306410486,25.0,0.0
54.664307,0.0008708155708661418,238.04583877995645,0.00025370340306410486,25.0,0.0
55.965576,0.0008838315354330708,247.80376778162247,0.00025370340306410486,25.0,0.0
57.266846,0.000915326279527559,257.20520312700245,0.00025370340306410486,25.0,0.0
58.568115,0.0009756370275590551,266.01545559400233,0.00025370340306410486,25.0,0.0
59.869385,0.00100041718503937,273.17139561707035,0.00025370340306410486,25.0,0.0
61.170654,0.0010627098228346457,283.4849929514289,0.00025370340306410486,25.0,0.0
62.471924,0.0010698479133858267,295.17436883250036,0.00025370340306410486,25.0,0.0
63.773193,0.0011264117322834645,305.57252338844035,0.00025370340306410486,25.0,0.0
65.074463,0.001174678346456693,315.838523644752,0.00025370340306410486,25.0,0.0
66.375732,0.0012306500196850394,326.00494681532746,0.00025370340306410486,25.0,0.0
67.677002,0.0012398215354330708,332.7919005510701,0.00025370340306410486,25.0,0.0
68.978271,0.00128616344488189,341.4615660643342,0.00025370340306410486,25.0,0.0
70.279541,0.0013253076771653541,352.13817762399077,0.00025370340306410486,25.0,0.0
71.580811,0.001352885275590551,360.3691144431629,0.00025370340306410486,25.0,0.0
72.88208,0.0014308511023622046,369.7110342176086,0.00025370340306410486,25.0,0.0
74.18335,0.0014420394291338582,378.73817762399074,0.00025370340306410486,25.0,0.0
75.484619,0.001488059409448819,387.7305139049084,0.00025370340306410486,25.0,0.0
76.785889,0.0015278165354330707,396.4705882352941,0.00025370340306410486,25.0,0.0
78.087158,0.0015737415551181104,404.79838523644753,0.00025370340306410486,25.0,0.0
79.388428,0.001623347125984252,413.4328847879021,0.00025370340306410486,25.0,0.0
80.689697,0.0016535361023622048,422.7659618095604,0.00025370340306410486,25.0,0.0
81.990967,0.0017104232283464567,432.8959630911188,0.00025370340306410486,25.0,0.0
83.292236,0.0017391849606299213,443.1422786107907,0.00025370340306410486,25.0,0.0
84.593506,0.0018030135629921258,450.46356529539923,0.00025370340306410486,25.0,0.0
85.894775,0.0018620982677165355,461.5899525823401,0.00025370340306410486,25.0,0.0
87.196045,0.001897196122047244,466.6942458028964,0.00025370340306410486,25.0,0.0
88.497314,0.0019345511417322835,475.57372805331283,0.00025370340306410486,25.0,0.0
89.798584,0.0019758435039370077,481.71572472126104,0.00025370340306410486,25.0,0.0
91.099854,0.002030875590551181,489.9215942586185,0.00025370340306410486,25.0,0.0
92.401123,0.002082724409448819,499.1959502755351,0.00025370340306410486,25.0,0.0
93.702393,0.002133055905511811,508.0095091631424,0.00025370340306410486,25.0,0.0
95.003662,0.002196436023622047,514.7175957964885,0.00025370340306410486,25.0,0.0
96.304932,0.0022318366141732284,521.3298218633859,0.00025370340306410486,25.0,0.0
97.606201,0.0023204661417322832,532.5688581314879,0.00025370340306410486,25.0,0.0
98.907471,0.002360038779527559,537.788773548635,0.00025370340306410486,25.0,0.0
100.20874,0.0024431277559055116,546.9377675253107,0.00025370340306410486,25.0,0.0
101.51001,0.0024731437007874013,552.2956555171088,0.00025370340306410486,25.0,0.0
102.81128,0.0025238027559055117,559.1499166987056,0.00025370340306410486,25.0,0.0
104.11255,0.0025979604330708663,565.6003844675124,0.00025370340306410486,25.0,0.0
105.41382,0.0026407037401574803,570.4706394976291,0.00025370340306410486,25.0,0.0
106.71509,0.0027181437007874013,576.322798923491,0.00025370340306410486,25.0,0.0
108.01636,0.002771551968503937,584.6436242470844,0.00025370340306410486,25.0,0.0
109.31763,0.0028394836614173227,588.643854927592,0.00025370340306410486,25.0,0.0
110.6189,0.0029190281496062993,595.2769191336666,0.00025370340306410486,25.0,0.0
111.92017,0.0029907907480314962,601.1995642701526,0.00025370340306410486,25.0,0.0
113.22144,0.0030498938976377954,606.125669614251,0.00025370340306410486,25.0,0.0
114.52271,0.0031172062992125982,611.6460848391644,0.00025370340306410486,25.0,0.0
115.82397,0.0032101669291338584,616.3154427784186,0.00025370340306410486,25.0,0.0
117.12524,0.003270785433070866,621.399436114315,0.00025370340306410486,25.0,0.0
118.42651,0.0033495332677165356,624.6520825323594,0.00025370340306410486,25.0,0.0
119.72778,0.003413138188976378,628.5279251569909,0.00025370340306410486,25.0,0.0
121.02905,0.0035242899606299214,633.7863642188902,0.00025370340306410486,25.0,0.0
122.33032,0.003580572244094488,634.9913879277201,0.00025370340306410486,25.0,0.0
123.63159,0.003644284645669291,640.5770088427529,0.00025370340306410486,25.0,0.0
124.93286,0.0037707332677165356,645.5055491477636,0.00025370340306410486,25.0,0.0
126.23413,0.0038612842519685038,648.4673587081891,0.00025370340306410486,25.0,0.0
127.5354,0.003954365157480315,652.8495450467769,0.00025370340306410486,25.0,0.0
128.83667,0.004065650196850393,657.8529539920544,0.00025370340306410486,25.0,0.0
130.13794,0.004213097244094488,659.1352044085609,0.00025370340306410486,25.0,0.0
131.43921,0.004345256299212598,664.40235806741,0.00025370340306410486,25.0,0.0
132.74048,0.004433432480314961,664.9333077021657,0.00025370340306410486,25.0,0.0
134.04175,0.004562360826771653,669.1202101755736,0.00025370340306410486,25.0,0.0
135.34302,0.004698464763779527,671.9718057157503,0.00025370340306410486,25.0,0.0
136.64429,0.004867112401574803,675.2865308214789,0.00025370340306410486,25.0,0.0
137.94556,0.0050199657480314965,678.3903626810201,0.00025370340306410486,25.0,0.0
139.24683,0.00517283031496063,678.4965526079714,0.00025370340306410486,25.0,0.0
140.5481,0.00534706968503937,682.5618095604256,0.00025370340306410486,25.0,0.0
141.84937,0.0055085970472440945,685.7682173523004,0.00025370340306410486,25.0,0.0
143.15063,0.0057001742125984255,686.591644239395,0.00025370340306410486,25.0,0.0
144.4519,0.005877068897637795,690.3120338331411,0.00025370340306410486,25.0,0.0
145.75317,0.006089014173228347,691.5771369985903,0.00025370340306410486,25.0,0.0
147.05444,0.006216983070866142,691.8669229783417,0.00025370340306410486,25.0,0.0
148.35571,0.0063763895669291335,694.9834678969627,0.00025370340306410486,25.0,0.0
149.65698,0.006611464763779528,696.8643342304242,0.00025370340306410486,25.0,0.0
150.95825,0.006839972440944883,698.8346020761246,0.00025370340306410486,25.0,0.0
152.25952,0.0070610208661417324,702.2466743560169,0.00025370340306410486,25.0,0.0
153.56079,0.007292252755905512,703.0152505446623,0.00025370340306410486,25.0,0.0
154.86206,0.0075243507874015745,704.4926054081764,0.00025370340306410486,25.0,0.0
156.16333,0.007798533661417323,707.7396642317057,0.00025370340306410486,25.0,0.0
157.4646,0.00802758405511811,705.6367294630271,0.00025370340306410486,25.0,0.0
158.76587,0.008273145866141732,708.4833269255414,0.00025370340306410486,25.0,0.0
160.06714,0.008536589173228346,708.9510957324105,0.00025370340306410486,25.0,0.0
161.36841,0.008826292913385827,710.7522235037807,0.00025370340306410486,25.0,0.0
162.66968,0.00910272125984252,714.8525695245419,0.00025370340306410486,25.0,0.0
163.97095,0.009401934645669291,714.3793156478278,0.00025370340306410486,25.0,0.0
165.27222,0.009695546850393701,714.889811610919,0.00025370340306410486,25.0,0.0
166.57349,0.009951854921259842,715.9520440856081,0.00025370340306410486,25.0,0.0
167.87476,0.010242044094488189,716.7617582980905,0.00025370340306410486,25.0,0.0
169.17603,0.010582773818897637,718.5920030757401,0.00025370340306410486,25.0,0.0
170.47729,0.010925663385826772,720.0286300140971,0.00025370340306410486,25.0,0.0
171.77856,0.01121836122047244,722.038318595412,0.00025370340306410486,25.0,0.0
173.07983,0.011569765354330708,722.9521209791105,0.00025370340306410486,25.0,0.0
174.3811,0.011868578346456693,721.3108547994361,0.00025370340306410486,25.0,0.0
175.68237,0.012131248031496063,723.196462898885,0.00025370340306410486,25.0,0.0
176.98364,0.012423219881889762,723.9284890426759,0.00025370340306410486,25.0,0.0
178.28491,0.012745024803149606,727.0047930283224,0.00025370340306410486,25.0,0.0
179.58618,0.012964020472440945,725.9064462386261,0.00025370340306410486,25.0,0.0
180.88745,0.013301586023622048,727.0579777008843,0.00025370340306410486,25.0,0.0
182.18872,0.013615683858267716,728.4315263360247,0.00025370340306410486,25.0,0.0
183.48999,0.013948773031496064,730.196975522235,0.00025370340306410486,25.0,0.0
184.79126,0.014239757874015747,728.555478662053,0.00025370340306410486,25.0,0.0
186.09253,0.01453953090551181,729.1098551839036,0.00025370340306410486,25.0,0.0
187.3938,0.014876498031496063,730.5359477124183,0.00025370340306410486,25.0,0.0
188.69507,0.015248337795275591,731.4502627194669,0.00025370340306410486,25.0,0.0
189.99634,0.015562800590551183,732.5232602845059,0.00025370340306410486,25.0,0.0
191.29761,0.01593509783464567,734.1900294758426,0.00025370340306410486,25.0,0.0
192.59888,0.01630017775590551,734.3494809688581,0.00025370340306410486,25.0,0.0
193.90015,0.016593323031496063,734.0650006407792,0.00025370340306410486,25.0,0.0
195.20142,0.016926386023622047,734.8159682173523,0.00025370340306410486,25.0,0.0
196.50269,0.01724226122047244,736.2657439446367,0.00025370340306410486,25.0,0.0
197.80396,0.017659688779527557,738.5692938613354,0.00025370340306410486,25.0,0.0
199.10522,0.018006134842519683,737.6111751890298,0.00025370340306410486,25.0,0.0
200.40649,0.018428948031496063,738.3909521978726,0.00025370340306410486,25.0,0.0
201.70776,0.018811212598425196,737.5853389721901,0.00025370340306410486,25.0,0.0
203.00903,0.01921672086614173,741.0157631680123,0.00025370340306410486,25.0,0.0
204.3103,0.01957623031496063,740.3363065487632,0.00025370340306410486,25.0,0.0
205.61157,0.01995003346456693,741.5056004100987,0.00025370340306410486,25.0,0.0
206.91284,0.020321265748031496,742.438985005767,0.00025370340306410486,25.0,0.0
208.21411,0.020671964566929133,741.5052928360886,0.00025370340306410486,25.0,0.0
209.51538,0.02104686023622047,742.7797257465078,0.00025370340306410486,25.0,0.0
210.81665,0.0213628562992126,743.0323977957196,0.00025370340306410486,25.0,0.0
212.11792,0.02167906692913386,743.995437652185,0.00025370340306410486,25.0,0.0
213.41919,0.022032397637795274,744.2341663462771,0.00025370340306410486,25.0,0.0
214.72046,0.022365041338582678,744.9455337690632,0.00025370340306410486,25.0,0.0
216.02173,0.022775405511811026,742.796667948225,0.00025370340306410486,25.0,0.0
217.323,0.02309726181102362,744.3967448417276,0.00025370340306410486,25.0,0.0
218.62427,0.0234076437007874,747.2135588876074,0.00025370340306410486,25.0,0.0
219.92554,0.023797683070866143,746.7262591311035,0.00025370340306410486,25.0,0.0
221.22681,0.0241863562992126,747.9781109829553,0.00025370340306410486,25.0,0.0
222.52808,0.02457716338582677,748.8064846853774,0.00025370340306410486,25.0,0.0
223.82935,0.024892862204724413,747.8589516852492,0.00025370340306410486,25.0,0.0
225.13062,0.025298137795275594,749.0851980007689,0.00025370340306410486,25.0,0.0
226.43188,0.025657165354330706,749.4017685505576,0.00025370340306410486,25.0,0.0
227.73315,0.026065283464566928,749.484172754069,0.00025370340306410486,25.0,0.0
229.03442,0.02638110433070866,750.2248366013072,0.00025370340306410486,25.0,0.0
230.33569,0.026763952755905512,751.5681660899654,0.00025370340306410486,25.0,0.0
231.63696,0.027161338582677167,752.3788286556453,0.00025370340306410486,25.0,0.0
232.93823,0.027569092519685038,753.480225554274,0.00025370340306410486,25.0,0.0
234.2395,0.02795259842519685,752.5410226835832,0.00025370340306410486,25.0,0.0
235.54077,0.028397257874015744,755.4470588235293,0.00025370340306410486,25.0,0.0
236.84204,0.028799072834645667,753.0374471357171,0.00025370340306410486,25.0,0.0
238.14331,0.029213775590551178,754.4562860438293,0.00025370340306410486,25.0,0.0
239.44458,0.0295965374015748,755.20225554274,0.00025370340306410486,25.0,0.0
240.74585,0.0299170531496063,754.5228758169935,0.00025370340306410486,25.0,0.0
242.04712,0.030260641732283464,755.560143534538,0.00025370340306410486,25.0,0.0
243.34839,0.030676675196850394,756.6530821478918,0.00025370340306410486,25.0,0.0
244.64966,0.031053177165354332,756.8513904908369,0.00025370340306410486,25.0,0.0
245.95093,0.031370190944881894,757.4112008201973,0.00025370340306410486,25.0,0.0
247.2522,0.03170721062992126,757.4840445982314,0.00025370340306410486,25.0,0.0
248.55347,0.03210642913385827,757.0325003203897,0.00025370340306410486,25.0,0.0
249.85474,0.03253504527559055,758.6520825323594,0.00025370340306410486,25.0,0.0
251.15601,0.032945860236220474,758.0579777008843,0.00025370340306410486,25.0,0.0
252.45728,0.0333345157480315,760.9813661412278,0.00025370340306410486,25.0,0.0
253.75854,0.03379331692913386,759.9512238882481,0.00025370340306410486,25.0,0.0
255.05981,0.03420713188976378,761.202819428425,0.00025370340306410486,25.0,0.0
256.36108,0.03459810236220472,759.8512367038319,0.00025370340306410486,25.0,0.0
257.66235,0.03492888188976378,759.7438421120082,0.00025370340306410486,25.0,0.0
258.96362,0.03526845275590551,761.8336280917596,0.00025370340306410486,25.0,0.0
260.26489,0.03569251181102362,762.1806228373703,0.00025370340306410486,25.0,0.0
261.56616,0.03605491141732283,760.8962450339613,0.00025370340306410486,25.0,0.0
262.86743,0.03646347244094488,763.0772779700116,0.00025370340306410486,25.0,0.0
264.1687,0.036812342519685036,763.2291426374471,0.00025370340306410486,25.0,0.0
265.46997,0.03720092125984252,763.7540945790081,0.00025370340306410486,25.0,0.0
266.77124,0.03757881299212599,763.5592977060105,0.00025370340306410486,25.0,0.0
268.07251,0.038008984251968504,765.2827630398565,0.00025370340306410486,25.0,0.0
269.37378,0.03841284448818898,766.601179033705,0.00025370340306410486,25.0,0.0
270.67505,0.038824872047244094,766.528899141356,0.00025370340306410486,25.0,0.0
271.97632,0.03922232283464567,765.9288735101884,0.00025370340306410486,25.0,0.0
273.27759,0.03964944094488189,766.3129565551711,0.00025370340306410486,25.0,0.0
274.57886,0.04010951181102362,767.119313084711,0.00025370340306410486,25.0,0.0
275.88013,0.04048025196850393,767.402409329745,0.00025370340306410486,25.0,0.0
277.1814,0.040956777559055114,768.3485069844932,0.00025370340306410486,25.0,0.0
278.48267,0.04134806102362205,767.9143406382161,0.00025370340306410486,25.0,0.0
279.78394,0.04175495669291338,767.3781878764578,0.00025370340306410486,25.0,0.0
281.08521,0.04209946456692913,768.6511854414969,0.00025370340306410486,25.0,0.0
282.38647,0.042465086614173225,768.6472382417019,0.00025370340306410486,25.0,0.0
283.68774,0.0428521968503937,769.59313084711,0.00025370340306410486,25.0,0.0
284.98901,0.0432211062992126,769.9997693194925,0.00025370340306410486,25.0,0.0
286.29028,0.04359619881889763,772.6151992823274,0.00025370340306410486,25.0,0.0
287.59155,0.04400129527559055,771.8145841343072,0.00025370340306410486,25.0,0.0
288.89282,0.044381539370078736,770.037857234397,0.00025370340306410486,25.0,0.0
290.19409,0.04471151574803149,770.846776880687,0.00025370340306410486,25.0,0.0
291.49536,0.045035468503937005,772.4355247981546,0.00025370340306410486,25.0,0.0
292.79663,0.04545011023622047,772.8578495450469,0.00025370340306410486,25.0,0.0
294.0979,0.04584942322834645,770.00112777137,0.00025370340306410486,25.0,0.0
295.39917,0.04619699606299212,772.9517877739331,0.00025370340306410486,25.0,0.0
296.70044,0.04656171062992126,773.3326925541458,0.00025370340306410486,25.0,0.0
298.00171,0.04704410433070866,773.7594002306805,0.00025370340306410486,25.0,0.0
299.30298,0.04744734251968504,773.6223503780598,0.00025370340306410486,25.0,0.0
300.60425,0.04784158858267716,775.0609765474817,0.00025370340306410486,25.0,0.0
301.90552,0.048213015748031496,775.2331154684097,0.00025370340306410486,25.0,0.0
303.20679,0.0485962125984252,774.4129437395874,0.00025370340306410486,25.0,0.0
304.50806,0.04898544291338583,775.9773420479304,0.00025370340306410486,25.0,0.0
305.80933,0.049406541338582674,777.20389593746,0.00025370340306410486,25.0,0.0
307.1106,0.04986380905511811,776.1864667435601,0.00025370340306410486,25.0,0.0
308.41187,0.050245102362204724,777.8168909393822,0.00025370340306410486,25.0,0.0
309.71313,0.050595086614173224,777.4105856721774,0.00025370340306410486,25.0,0.0
311.0144,0.05095049606299212,778.1686787133153,0.00025370340306410486,25.0,0.0
312.31567,0.05130760826771653,776.8782519543765,0.00025370340306410486,25.0,0.0
313.61694,0.0516767874015748,777.9421760861208,0.00025370340306410486,25.0,0.0
314.91821,0.052126385826771655,780.7122132513135,0.00025370340306410486,25.0,0.0
316.21948,0.052578330708661414,780.2920927848264,0.00025370340306410486,25.0,0.0
317.52075,0.052963531496063,778.9707804690504,0.00025370340306410486,25.0,0.0
318.82202,0.05333696456692913,779.9072920671537,0.00025370340306410486,25.0,0.0
320.12329,0.05372145472440945,779.6700756119441,0.00025370340306410486,25.0,0.0
321.42456,0.0540914094488189,782.0213251313597,0.00025370340306410486,25.0,0.0
322.72583,0.05448,782.39651416122,0.00025370340306410486,25.0,0.0
324.0271,0.05488581102362205,782.8157119056773,0.00025370340306410486,25.0,0.0
325.32837,0.05530402362204725,781.756606433423,0.00025370340306410486,25.0,0.0
326.62964,0.05564325984251968,782.5390747148533,0.00025370340306410486,25.0,0.0
327.93091,0.05604831889763779,782.0906574394464,0.00025370340306410486,25.0,0.0
329.23218,0.0563609311023622,783.7798282711777,0.00025370340306410486,25.0,0.0
330.53345,0.05668420472440945,782.9690888119954,0.00025370340306410486,25.0,0.0
331.83472,0.057069047244094485,784.8546456491093,0.00025370340306410486,25.0,0.0
333.13599,0.05754855511811023,785.807535563245,0.00025370340306410486,25.0,0.0
334.43726,0.057988179133858266,785.152607971293,0.00025370340306410486,25.0,0.0
335.73853,0.05833463779527559,785.5101114955786,0.00025370340306410486,25.0,0.0
337.03979,0.0587621594488189,785.4323977957197,0.00025370340306410486,25.0,0.0
338.34106,0.059161669291338585,785.3199538638985,0.00025370340306410486,25.0,0.0
339.64233,0.0596350157480315,786.119620658721,0.00025370340306410486,25.0,0.0
340.9436,0.05999799409448819,784.5038318595413,0.00025370340306410486,25.0,0.0
342.24487,0.06035429133858267,786.3499423298732,0.00025370340306410486,25.0,0.0
343.54614,0.06077764173228347,786.8560041009869,0.00025370340306410486,25.0,0.0
344.84741,0.061169277559055116,788.2085351787774,0.00025370340306410486,25.0,0.0
346.14868,0.06154767322834646,786.2048955529924,0.00025370340306410486,25.0,0.0
347.44995,0.061896131889763784,787.4004869921826,0.00025370340306410486,25.0,0.0
348.75122,0.06227663385826772,788.2975778546713,0.00025370340306410486,25.0,0.0
350.05249,0.06265579921259842,787.8225041650647,0.00025370340306410486,25.0,0.0
351.35376,0.0630778877952756,788.7719082404203,0.00025370340306410486,25.0,0.0
352.65503,0.06354041732283464,791.8665897731643,0.00025370340306410486,25.0,0.0
353.9563,0.06393295078740158,790.7568627450981,0.00025370340306410486,25.0,0.0
355.25757,0.06433649015748032,790.6414199666795,0.00025370340306410486,25.0,0.0
356.55884,0.06467037598425197,790.0213507625273,0.00025370340306410486,25.0,0.0
357.86011,0.06501758464566929,790.278482634884,0.00025370340306410486,25.0,0.0
359.16138,0.06543544488188976,792.0138408304498,0.00025370340306410486,25.0,0.0
360.46265,0.065781281496063,791.9549660387031,0.00025370340306410486,25.0,0.0
361.76392,0.06614921062992125,791.7526336024606,0.00025370340306410486,25.0,0.0
363.06519,0.06655388385826772,793.0985262078688,0.00025370340306410486,25.0,0.0
364.36646,0.06697099803149606,792.9578623606305,0.00025370340306410486,25.0,0.0
365.66772,0.0673509842519685,793.0518518518519,0.00025370340306410486,25.0,0.0
366.96899,0.0677695374015748,792.9371523772908,0.00025370340306410486,25.0,0.0
368.27026,0.06816913976377953,795.4302447776496,0.00025370340306410486,25.0,0.0
369.57153,0.06856457874015748,794.8659233628092,0.00025370340306410486,25.0,0.0
370.8728,0.06897570866141732,794.9444572600282,0.00025370340306410486,25.0,0.0
372.17407,0.06934986417322835,795.4696142509291,0.00025370340306410486,25.0,0.0
373.47534,0.06971565157480315,794.5968473663976,0.00025370340306410486,25.0,0.0
374.77661,0.07011955511811023,793.1194412405486,0.00025370340306410486,25.0,0.0
376.07788,0.07046630118110236,795.7670383185955,0.00025370340306410486,25.0,0.0
377.37915,0.07087540157480314,795.9069588619762,0.00025370340306410486,25.0,0.0
378.68042,0.07130801771653543,794.4750736896066,0.00025370340306410486,25.0,0.0
379.98169,0.07169226771653543,795.8611303344868,0.00025370340306410486,25.0,0.0
381.28296,0.07206135236220472,797.9501217480457,0.00025370340306410486,25.0,0.0
382.58423,0.07241550787401575,796.3165192874535,0.00025370340306410486,25.0,0.0
383.8855,0.07282499606299213,797.1341791618607,0.00025370340306410486,25.0,0.0
385.18677,0.07322778543307086,797.8158913238498,0.00025370340306410486,25.0,0.0
386.48804,0.07360405708661416,798.7701909521978,0.00025370340306410486,25.0,0.0
387.78931,0.07396305708661417,800.6636678200692,0.00025370340306410486,25.0,0.0
389.09058,0.07439995472440945,799.3395617070358,0.00025370340306410486,25.0,0.0
390.39185,0.07484034842519685,799.1132897603486,0.00025370340306410486,25.0,0.0
391.69312,0.07518495275590552,799.042265795207,0.00025370340306410486,25.0,0.0
392.99438,0.07554271653543307,799.1498910675381,0.00025370340306410486,25.0,0.0
394.29565,0.07588418700787401,799.9720876585928,0.00025370340306410486,25.0,0.0
395.59692,0.07627369291338583,799.522901448161,0.00025370340306410486,25.0,0.0
396.89819,0.0766281062992126,801.0424452133794,0.00025370340306410486,25.0,0.0
398.19946,0.07701050393700787,800.2165577342048,0.00025370340306410486,25.0,0.0
399.50073,0.07735553543307086,801.3725233884404,0.00025370340306410486,25.0,0.0
400.802,0.07775001181102362,801.3294886582084,0.00025370340306410486,25.0,0.0
402.10327,0.07814149015748031,803.0179161860823,0.00025370340306410486,25.0,0.0
403.40454,0.07856509842519685,800.6265026271947,0.00025370340306410486,25.0,0.0
404.70581,0.07897332086614173,801.8716391131616,0.00025370340306410486,25.0,0.0
406.00708,0.07934979133858268,801.9833397411253,0.00025370340306410486,25.0,0.0
407.30835,0.07972982480314961,801.1713443547353,0.00025370340306410486,25.0,0.0
408.60962,0.08017184842519685,803.5648853005255,0.00025370340306410486,25.0,0.0
409.91089,0.08056050000000001,802.7754966038704,0.00025370340306410486,25.0,0.0
411.21216,0.08088870669291338,801.2520825323594,0.00025370340306410486,25.0,0.0
412.51343,0.081233468503937,804.7960784313726,0.00025370340306410486,25.0,0.0
413.8147,0.08169954724409449,804.1509675765731,0.00025370340306410486,25.0,0.0
415.11597,0.08212769094488188,805.961117518903,0.00025370340306410486,25.0,0.0
416.41724,0.08256252952755905,805.0440599769319,0.00025370340306410486,25.0,0.0
417.71851,0.08296991732283465,804.724541842881,0.00025370340306410486,25.0,0.0
419.01978,0.08335547637795275,805.3829809047802,0.00025370340306410486,25.0,0.0
420.32104,0.08375988976377952,806.2198128924773,0.00025370340306410486,25.0,0.0
421.62231,0.0841411377952756,806.0404459823145,0.00025370340306410486,25.0,0.0
422.92358,0.08452939960629921,806.5398180187108,0.00025370340306410486,25.0,0.0
424.22485,0.08492288582677165,805.1941817249775,0.00025370340306410486,25.0,0.0
425.52612,0.0853095,805.5457900807381,0.00025370340306410486,25.0,0.0
426.82739,0.0856246653543307,807.568191721133,0.00025370340306410486,25.0,0.0
428.12866,0.08596604921259843,808.99466871716,0.00025370340306410486,25.0,0.0
429.42993,0.0863836968503937,807.875509419454,0.00025370340306410486,25.0,0.0
430.7312,0.08685409251968504,808.8337818787646,0.00025370340306410486,25.0,0.0
432.03247,0.08723455905511811,807.9447648340382,0.00025370340306410486,25.0,0.0
433.33374,0.08752425196850394,808.7468153274382,0.00025370340306410486,25.0,0.0
434.63501,0.08789962007874015,809.8979623221837,0.00025370340306410486,25.0,0.0
435.93628,0.08827929527559054,808.3904395745227,0.00025370340306410486,25.0,0.0
437.23755,0.08863479921259843,808.6953223119314,0.00025370340306410486,25.0,0.0
438.53882,0.08897075,809.2238369857747,0.00025370340306410486,25.0,0.0
439.84009,0.08938892716535433,811.6477764962194,0.00025370340306410486,25.0,0.0
441.14136,0.08979075984251968,810.5162117134435,0.00025370340306410486,25.0,0.0
442.44263,0.09013540551181101,810.3039600153787,0.00025370340306410486,25.0,0.0
443.7439,0.09053358858267715,811.5842112008202,0.00025370340306410486,25.0,0.0
445.04517,0.09093099212598425,811.2829680891964,0.00025370340306410486,25.0,0.0
446.34644,0.09125395472440945,809.556042547738,0.00025370340306410486,25.0,0.0
447.64771,0.09159805905511811,811.1366653851082,0.00025370340306410486,25.0,0.0
448.94897,0.09198490944881889,812.5079584775086,0.00025370340306410486,25.0,0.0
450.25024,0.09244975,814.1147251057286,0.00025370340306410486,25.0,0.0
451.55151,0.09289152755905512,812.8181468665898,0.00025370340306410486,25.0,0.0
452.85278,0.09334735629921259,814.1736511598103,0.00025370340306410486,25.0,0.0
454.15405,0.09374622637795275,814.1711649365628,0.00025370340306410486,25.0,0.0
455.45532,0.09417016929133859,814.2421889017045,0.00025370340306410486,25.0,0.0
456.75659,0.09453619291338583,814.9255670895809,0.00025370340306410486,25.0,0.0
458.05786,0.09491722834645669,814.4434191977444,0.00025370340306410486,25.0,0.0
459.35913,0.09526816338582678,813.5445854158656,0.00025370340306410486,25.0,0.0
460.6604,0.09558808070866141,814.6618223760092,0.00025370340306410486,25.0,0.0
461.96167,0.09597507677165354,814.994412405485,0.00025370340306410486,25.0,0.0
463.26294,0.0963119842519685,814.4952966807639,0.00025370340306410486,25.0,0.0
464.56421,0.09680172047244094,817.20379341279,0.00025370340306410486,25.0,0.0
465.86548,0.09719228346456692,815.7132897603486,0.00025370340306410486,25.0,0.0
467.16675,0.09751313976377952,815.5385620915033,0.00025370340306410486,25.0,0.0
468.46802,0.09783511023622046,816.1196462898885,0.00025370340306410486,25.0,0.0
469.76929,0.0982486062992126,817.1301806997308,0.00025370340306410486,25.0,0.0
471.07056,0.09866360433070866,817.5579648853005,0.00025370340306410486,25.0,0.0
472.37183,0.09908318307086615,818.0058951685248,0.00025370340306410486,25.0,0.0
473.6731,0.0994511594488189,816.7996667948225,0.00025370340306410486,25.0,0.0
474.97437,0.09984734251968504,817.1008330129438,0.00025370340306410486,25.0,0.0
476.27563,0.10020474803149605,817.9227220299884,0.00025370340306410486,25.0,0.0
477.5769,0.10064222047244094,819.3631680123029,0.00025370340306410486,25.0,0.0
478.87817,0.1010326535433071,818.0201460976548,0.00025370340306410486,25.0,0.0
480.17944,0.10144378543307087,820.4148148148148,0.00025370340306410486,25.0,0.0
481.48071,0.10189051377952756,820.2315775983595,0.00025370340306410486,25.0,0.0
482.78198,0.10230074212598425,819.3885684992952,0.00025370340306410486,25.0,0.0
484.08325,0.1027431653543307,821.3821094450852,0.00025370340306410486,25.0,0.0
485.38452,0.10318020472440945,820.2706394976291,0.00025370340306410486,25.0,0.0
486.68579,0.10357427559055118,820.0541842880943,0.00025370340306410486,25.0,0.0
487.98706,0.10395406692913386,820.1337178008458,0.00025370340306410486,25.0,0.0
489.28833,0.10434726968503936,818.4954248366013,0.00025370340306410486,25.0,0.0
490.5896,0.10470668110236221,820.7074714853262,0.00025370340306410486,25.0,0.0
491.89087,0.1050971968503937,821.0225554273998,0.00025370340306410486,25.0,0.0
493.19214,0.1054870216535433,820.7798282711777,0.00025370340306410486,25.0,0.0
494.49341,0.10584007283464567,821.5848519800078,0.00025370340306410486,25.0,0.0
495.79468,0.10623527165354331,821.3342304241959,0.00025370340306410486,25.0,0.0
497.09595,0.10659500984251968,821.6598231449443,0.00025370340306410486,25.0,0.0
498.39722,0.1069875688976378,822.3702422145328,0.00025370340306410486,25.0,0.0
499.69849,0.10738273031496064,823.1965654235551,0.00025370340306410486,25.0,0.0
500.99976,0.10775624606299213,821.5089580930412,0.00025370340306410486,25.0,0.0
502.30103,0.10811487007874014,822.5412021017557,0.00025370340306410486,25.0,0.0
503.60229,0.10850208858267717,822.6093041138023,0.00025370340306410486,25.0,0.0
504.90356,0.10889945866141731,823.075611944124,0.00025370340306410486,25.0,0.0
506.20483,0.10928095078740158,824.3624759707805,0.00025370340306410486,25.0,0.0
507.5061,0.10972416141732283,825.6307061386646,0.00025370340306410486,25.0,0.0
508.80737,0.11014027952755906,824.438318595412,0.00025370340306410486,25.0,0.0
510.10864,0.11055035433070866,824.3151864667436,0.00025370340306410486,25.0,0.0
511.40991,0.11092102952755906,823.5068307061387,0.00025370340306410486,25.0,0.0
512.71118,0.11129214960629921,824.0797641932589,0.00025370340306410486,25.0,0.0
514.01245,0.11163411417322835,825.3478662053056,0.00025370340306410486,25.0,0.0
515.31372,0.11204959842519684,825.4755350506215,0.00025370340306410486,25.0,0.0
516.61499,0.1124147933070866,826.8240932974497,0.00025370340306410486,25.0,0.0
517.91626,0.11283119291338582,825.1328719723184,0.00025370340306410486,25.0,0.0
519.21753,0.11320545866141732,826.3306420607458,0.00025370340306410486,25.0,0.0
520.5188,0.11359056692913384,827.759682173523,0.00025370340306410486,25.0,0.0
521.82007,0.11404338582677165,828.1379469434833,0.00025370340306410486,25.0,0.0
523.12134,0.11446944094488187,825.0141484044598,0.00025370340306410486,25.0,0.0
524.42261,0.11480016535433071,825.161835191593,0.00025370340306410486,25.0,0.0
525.72388,0.1151471751968504,825.5785979751378,0.00025370340306410486,25.0,0.0
527.02515,0.11560440551181102,828.6822504165065,0.00025370340306410486,25.0,0.0
528.32642,0.11606574212598426,826.1875688837627,0.00025370340306410486,25.0,0.0
529.62769,0.1164820846456693,827.7091887735487,0.00025370340306410486,25.0,0.0
530.92896,0.11690867913385826,829.0555171088043,0.00025370340306410486,25.0,0.0
532.23022,0.11728299212598425,826.7545303088556,0.00025370340306410486,25.0,0.0
533.53149,0.11763385039370079,827.4195822119697,0.00025370340306410486,25.0,0.0
534.83276,0.11805149212598424,828.4537741894143,0.00025370340306410486,25.0,0.0
536.13403,0.11843241141732283,828.8358067409971,0.00025370340306410486,25.0,0.0
537.4353,0.11880403740157479,828.7542739971806,0.00025370340306410486,25.0,0.0
538.73657,0.11919311023622046,827.8121748045623,0.00025370340306410486,25.0,0.0
540.03784,0.11959261220472442,830.112546456491,0.00025370340306410486,25.0,0.0
541.33911,0.11997049212598425,827.4186338587723,0.00025370340306410486,25.0,0.0
542.64038,0.12032523425196849,829.2207612456748,0.00025370340306410486,25.0,0.0
543.94165,0.12067501181102362,830.9333589645008,0.00025370340306410486,25.0,0.0
545.24292,0.12106799212598426,828.7423811354607,0.00025370340306410486,25.0,0.0
546.54419,0.1215148622047244,830.0112264513648,0.00025370340306410486,25.0,0.0
547.84546,0.12198991732283464,832.6124054850699,0.00025370340306410486,25.0,0.0
549.14673,0.1224217342519685,829.9360246059208,0.00025370340306410486,25.0,0.0
550.448,0.12280972637795275,831.3742663078302,0.00025370340306410486,25.0,0.0
551.74927,0.12319447047244095,830.7933615276175,0.00025370340306410486,25.0,0.0
553.05054,0.12360934448818899,832.2481353325644,0.00025370340306410486,25.0,0.0
554.35181,0.12396645669291338,831.4728181468665,0.00025370340306410486,25.0,0.0
555.65308,0.12439298031496063,831.9522747661157,0.00025370340306410486,25.0,0.0
556.95435,0.12482206496062992,832.5775470972703,0.00025370340306410486,25.0,0.0
558.25562,0.1252459842519685,832.8076893502499,0.00025370340306410486,25.0,0.0
559.55688,0.1256853937007874,833.6560297321544,0.00025370340306410486,25.0,0.0
560.85815,0.12611520275590551,832.1633474304755,0.00025370340306410486,25.0,0.0
562.15942,0.1265327283464567,833.1487889273357,0.00025370340306410486,25.0,0.0
563.46069,0.12696600196850394,833.3768806869152,0.00025370340306410486,25.0,0.0
564.76196,0.12730492519685038,831.9763168012303,0.00025370340306410486,25.0,0.0
566.06323,0.12769462007874016,833.0014353453801,0.00025370340306410486,25.0,0.0
567.3645,0.12809189566929133,832.9064462386261,0.00025370340306410486,25.0,0.0
568.66577,0.12854666141732285,835.0006664103549,0.00025370340306410486,25.0,0.0
569.96704,0.1290037992125984,834.7108291682686,0.00025370340306410486,25.0,0.0
571.26831,0.12944599999999998,834.159220812508,0.00025370340306410486,25.0,0.0
572.56958,0.12983456889763778,833.8548506984494,0.00025370340306410486,25.0,0.0
573.87085,0.1301944724409449,834.7354863514033,0.00025370340306410486,25.0,0.0
575.17212,0.1305493307086614,832.5818018710752,0.00025370340306410486,25.0,0.0
576.47339,0.1309007283464567,834.4440087145969,0.00025370340306410486,25.0,0.0
577.77466,0.13129171456692915,835.6108419838523,0.00025370340306410486,25.0,0.0
579.07593,0.13168206692913384,836.1115212097911,0.00025370340306410486,25.0,0.0
580.3772,0.13207817913385828,835.1069332308086,0.00025370340306410486,25.0,0.0
581.67847,0.13249552952755905,836.5021145713187,0.00025370340306410486,25.0,0.0
582.97974,0.13291494291338582,835.0238369857747,0.00025370340306410486,25.0,0.0
584.28101,0.1333511594488189,836.2144047161348,0.00025370340306410486,25.0,0.0
585.58228,0.13378517125984252,837.9969498910675,0.00025370340306410486,25.0,0.0
586.88354,0.13430110433070866,836.4966807638089,0.00025370340306410486,25.0,0.0
588.18481,0.1346804035433071,835.8133538382673,0.00025370340306410486,25.0,0.0
589.48608,0.13502135826771655,836.1634499551456,0.00025370340306410486,25.0,0.0
590.78735,0.135399718503937,836.3254645649109,0.00025370340306410486,25.0,0.0
592.08862,0.13575681692913386,838.4254517493272,0.00025370340306410486,25.0,0.0
593.38989,0.13619678937007876,836.6442906574395,0.00025370340306410486,25.0,0.0
594.69116,0.13662600196850394,837.759579648853,0.00025370340306410486,25.0,0.0
595.99243,0.13701332677165354,837.5074202229911,0.00025370340306410486,25.0,0.0
597.2937,0.13742676968503936,837.9098295527361,0.00025370340306410486,25.0,0.0
598.59497,0.13786167125984253,838.7960271690375,0.00025370340306410486,25.0,0.0
599.89624,0.13833379133858267,839.7373061642958,0.00025370340306410486,25.0,0.0
601.19751,0.13879153937007874,839.6939382288864,0.00025370340306410486,25.0,0.0
602.49878,0.13926328346456693,839.0679994873766,0.00025370340306410486,25.0,0.0
603.80005,0.13970144881889762,837.8467512495195,0.00025370340306410486,25.0,0.0
605.10132,0.14008940748031495,838.5865436370626,0.00025370340306410486,25.0,0.0
606.40259,0.1405140433070866,838.7967961040625,0.00025370340306410486,25.0,0.0
607.70386,0.1408754842519685,838.2085864411123,0.00025370340306410486,25.0,0.0
609.00513,0.14120526968503938,839.8880430603614,0.00025370340306410486,25.0,0.0
610.3064,0.14158927362204723,838.9316929386134,0.00025370340306410486,25.0,0.0
611.60767,0.14199756496062993,838.5697039600154,0.00025370340306410486,25.0,0.0
612.90894,0.14241368307086616,839.7896193771626,0.00025370340306410486,25.0,0.0
614.21021,0.1428846181102362,840.7986671792901,0.00025370340306410486,25.0,0.0
615.51147,0.1433317224409449,841.3692425990004,0.00025370340306410486,25.0,0.0
616.81274,0.14372510236220473,839.5902601563502,0.00025370340306410486,25.0,0.0
618.11401,0.14414168897637794,839.7948737665,0.00025370340306410486,25.0,0.0
619.41528,0.1444971594488189,839.7639625784955,0.00025370340306410486,25.0,0.0
620.71655,0.14493039566929133,843.1396898628733,0.00025370340306410486,25.0,0.0
622.01782,0.1453479094488189,841.2370114058696,0.00025370340306410486,25.0,0.0
623.31909,0.14579927362204723,841.3848776111753,0.00025370340306410486,25.0,0.0
624.62036,0.14620586417322837,840.7414584134307,0.00025370340306410486,25.0,0.0
625.92163,0.14663563976377952,842.0797898244265,0.00025370340306410486,25.0,0.0
627.2229,0.14705933661417322,841.4669229783417,0.00025370340306410486,25.0,0.0
628.52417,0.14749544881889765,840.9092400358837,0.00025370340306410486,25.0,0.0
629.82544,0.14793018700787403,842.1752146610278,0.00025370340306410486,25.0,0.0
631.12671,0.1483708622047244,842.0840445982315,0.00025370340306410486,25.0,0.0
632.42798,0.14887933267716535,841.6898116109189,0.00025370340306410486,25.0,0.0
633.72925,0.14930632677165354,842.9520953479431,0.00025370340306410486,25.0,0.0
635.03052,0.14969177362204725,840.8627963603742,0.00025370340306410486,25.0,0.0
636.33179,0.15004434448818896,841.9268486479559,0.00025370340306410486,25.0,0.0
637.63306,0.15047054133858268,842.6634884018968,0.00025370340306410486,25.0,0.0
638.93433,0.1509561437007874,844.6626682045367,0.00025370340306410486,25.0,0.0
640.2356,0.15138947440944883,842.323209022171,0.00025370340306410486,25.0,0.0
641.53687,0.15184248031496064,845.1316929386134,0.00025370340306410486,25.0,0.0
642.83813,0.15224999803149605,842.1233884403435,0.00025370340306410486,25.0,0.0
644.1394,0.15269482677165355,845.9967448417276,0.00025370340306410486,25.0,0.0
645.44067,0.1531224901574803,843.5922337562475,0.00025370340306410486,25.0,0.0
646.74194,0.15362561023622048,846.0117390747149,0.00025370340306410486,25.0,0.0
648.04321,0.1541461181102362,843.560963731898,0.00025370340306410486,25.0,0.0
649.34448,0.1545666476377953,842.5425349224657,0.00025370340306410486,25.0,0.0
650.64575,0.15503025,843.9382801486607,0.00025370340306410486,25.0,0.0
651.94702,0.15541214173228346,844.126028450596,0.00025370340306410486,25.0,0.0
653.24829,0.15586568897637795,844.6514161220043,0.00025370340306410486,25.0,0.0
654.54956,0.15623934448818896,842.9380238369857,0.00025370340306410486,25.0,0.0
655.85083,0.15664877362204724,843.7078303216712,0.00025370340306410486,25.0,0.0
657.1521,0.15710209842519685,844.9574009996155,0.00025370340306410486,25.0,0.0
658.45337,0.15755492913385827,843.9416634627706,0.00025370340306410486,25.0,0.0
659.75464,0.15796756102362206,845.2726130975266,0.00025370340306410486,25.0,0.0
661.05591,0.15833008267716536,844.3932077406125,0.00025370340306410486,25.0,0.0
662.35718,0.15881539173228346,846.890375496604,0.00025370340306410486,25.0,0.0
663.65845,0.15926595669291338,845.7113161604511,0.00025370340306410486,25.0,0.0
664.95972,0.15976765748031496,846.4167371523772,0.00025370340306410486,25.0,0.0
666.26099,0.16019250393700787,843.4495706779444,0.00025370340306410486,25.0,0.0
667.56226,0.160616437007874,846.7280533128285,0.00025370340306410486,25.0,0.0
668.86353,0.1611284153543307,847.1085736255286,0.00025370340306410486,25.0,0.0
670.16479,0.16152676771653543,844.8713571703191,0.00025370340306410486,25.0,0.0
671.46606,0.16200099015748032,845.444367550942,0.00025370340306410486,25.0,0.0
672.76733,0.16249475787401574,847.5319236191208,0.00025370340306410486,25.0,0.0
674.0686,0.16291365551181103,845.0291170062796,0.00025370340306410486,25.0,0.0
675.36987,0.16336920866141733,847.273715237729,0.00025370340306410486,25.0,0.0
676.67114,0.16384204527559057,846.8142252979623,0.00025370340306410486,25.0,0.0
677.97241,0.1643150807086614,844.8611559656542,0.00025370340306410486,25.0,0.0
679.27368,0.16472123818897638,845.8525695245419,0.00025370340306410486,25.0,0.0
680.57495,0.1651676496062992,846.8045367166474,0.00025370340306410486,25.0,0.0
681.87622,0.1655652992125984,845.8642060745867,0.00025370340306410486,25.0,0.0
683.17749,0.16606572047244095,848.1910803537102,0.00025370340306410486,25.0,0.0
684.47876,0.16648595669291338,846.1609381007305,0.00025370340306410486,25.0,0.0
685.78003,0.16688117913385828,847.070588235294,0.00025370340306410486,25.0,0.0
687.0813,0.16739499803149607,848.7779315647828,0.00025370340306410486,25.0,0.0
688.38257,0.1677986437007874,846.161425092913,0.00025370340306410486,25.0,0.0
689.68384,0.16833722047244096,848.1624247084455,0.00025370340306410486,25.0,0.0
690.98511,0.168803968503937,847.7713956170704,0.00025370340306410486,25.0,0.0
692.28638,0.16921589763779527,846.5409457900807,0.00025370340306410486,25.0,0.0
693.58765,0.16968928543307088,847.158656926823,0.00025370340306410486,25.0,0.0
694.88892,0.17019579527559053,849.6448032807895,0.00025370340306410486,25.0,0.0
696.19019,0.17069853937007873,846.5567858515956,0.00025370340306410486,25.0,0.0
697.49146,0.17112737598425196,845.3167243367935,0.00025370340306410486,25.0,0.0
698.79272,0.17160084448818896,847.0573369216968,0.00025370340306410486,25.0,0.0
700.09399,0.17203544291338582,848.3031654491862,0.00025370340306410486,25.0,0.0
701.39526,0.1725338464566929,849.5705754197104,0.00025370340306410486,25.0,0.0
702.69653,0.17305506889763778,848.3412021017557,0.00025370340306410486,25.0,0.0
703.9978,0.173534781496063,847.7417916186082,0.00025370340306410486,25.0,0.0
705.29907,0.17405553543307087,848.8027169037549,0.00025370340306410486,25.0,0.0
706.60034,0.17442760826771653,846.7202358067409,0.00025370340306410486,25.0,0.0
707.90161,0.17496647834645668,850.5100346020762,0.00025370340306410486,25.0,0.0
709.20288,0.1754663464566929,848.6570293476868,0.00025370340306410486,25.0,0.0
710.50415,0.17592145472440945,847.8289632192747,0.00025370340306410486,25.0,0.0
711.80542,0.17634043503937008,848.2151223888247,0.00025370340306410486,25.0,0.0
713.10669,0.17674194488188977,848.479507881584,0.00025370340306410486,25.0,0.0
714.40796,0.17724242519685038,848.556606433423,0.00025370340306410486,25.0,0.0
715.70923,0.1776503405511811,848.5964628988851,0.00025370340306410486,25.0,0.0
717.0105,0.17808652362204724,848.6249391259771,0.00025370340306410486,25.0,0.0
718.31177,0.1785469094488189,848.128386518006,0.00025370340306410486,25.0,0.0
719.61304,0.17907295669291337,850.8752787389466,0.00025370340306410486,25.0,0.0
720.91431,0.1795543346456693,849.5204664872485,0.00025370340306410486,25.0,0.0
722.21558,0.18004934645669293,848.6917083173139,0.00025370340306410486,25.0,0.0
723.51685,0.18054278543307087,848.6289375881072,0.00025370340306410486,25.0,0.0
724.81812,0.1810050275590551,849.4361655773421,0.00025370340306410486,25.0,0.0
726.11938,0.18146960236220472,849.9596052800206,0.00025370340306410486,25.0,0.0
727.42065,0.18194507874015747,849.9958477508651,0.00025370340306410486,25.0,0.0
728.72192,0.1824703031496063,851.5730103806228,0.00025370340306410486,25.0,0.0
730.02319,0.18302813582677166,848.4750480584391,0.00025370340306410486,25.0,0.0
731.32446,0.1835025433070866,850.0381391772395,0.00025370340306410486,25.0,0.0
732.62573,0.18393277559055118,848.2183775470972,0.00025370340306410486,25.0,0.0
733.927,0.18440969488188977,849.884531590414,0.00025370340306410486,25.0,0.0
735.22827,0.1848421220472441,848.5252338844035,0.00025370340306410486,25.0,0.0
736.52954,0.18530249803149607,849.9407663719082,0.00025370340306410486,25.0,0.0
737.83081,0.185841062992126,852.4435729847494,0.00025370340306410486,25.0,0.0
739.13208,0.1864528562992126,852.4362424708446,0.00025370340306410486,25.0,0.0
740.43335,0.18693512598425197,850.6220428040498,0.00025370340306410486,25.0,0.0
741.73462,0.18747206102362204,850.603947199795,0.00025370340306410486,25.0,0.0
743.03589,0.18794344094488188,848.1883378187877,0.00025370340306410486,25.0,0.0
744.33716,0.1883911692913386,849.8574907087018,0.00025370340306410486,25.0,0.0
745.63843,0.18892313976377953,849.9404075355633,0.00025370340306410486,25.0,0.0
746.9397,0.18944165354330708,849.359067025503,0.00025370340306410486,25.0,0.0
748.24097,0.18997746259842518,849.5067538126362,0.00025370340306410486,25.0,0.0
749.54224,0.1905336279527559,850.7267461232859,0.00025370340306410486,25.0,0.0
750.84351,0.1910506968503937,851.0751505831091,0.00025370340306410486,25.0,0.0
752.14478,0.19153951377952755,850.2700499807765,0.00025370340306410486,25.0,0.0
753.44604,0.19202103346456692,851.044367550942,0.00025370340306410486,25.0,0.0
754.74731,0.19252072637795276,849.9007817506088,0.00025370340306410486,25.0,0.0
756.04858,0.19305559645669293,850.7623478149429,0.00025370340306410486,25.0,0.0
757.34985,0.19354652559055116,851.1363578110984,0.00025370340306410486,25.0,0.0
758.65112,0.1940919901574803,851.8411636550044,0.00025370340306410486,25.0,0.0
759.95239,0.19465127559055118,850.0445982314494,0.00025370340306410486,25.0,0.0
761.25366,0.19513519881889763,850.9871075227477,0.00025370340306410486,25.0,0.0
762.55493,0.1956193464566929,849.9869537357426,0.00025370340306410486,25.0,0.0
763.8562,0.196088874015748,849.8587466359093,0.00025370340306410486,25.0,0.0
765.15747,0.19661980118110237,851.203434576445,0.00025370340306410486,25.0,0.0
766.45874,0.19718068897637794,850.4950660002563,0.00025370340306410486,25.0,0.0
767.76001,0.19771212598425197,851.1161348199411,0.00025370340306410486,25.0,0.0
769.06128,0.19831649606299212,851.118697936691,0.00025370340306410486,25.0,0.0
770.36255,0.1989371653543307,850.5584775086505,0.00025370340306410486,25.0,0.0
771.56372,0.1995620275590551,852.959835960528,0.00025370340306410486,25.0,0.0