File: datasets/am_bench_2022/csv/0-XY.05-4.csv
Time(s),Strain(%),Stress(MPa),SR(s-1),Temp(C),Angle(deg)
30.969238,1.3530806102362204e-05,20.852212487437836,0.00025370340306410486,25.0,0.0
33.371582,5.856265354330709e-05,28.73992836343959,0.00025370340306410486,25.0,0.0
34.873047,4.080994094488189e-05,34.34814595304971,0.00025370340306410486,25.0,0.0
36.374512,5.311469094488189e-05,38.949416342412455,0.00025370340306410486,25.0,0.0
37.675781,0.0001045271968503937,45.121910995438974,0.00025370340306410486,25.0,0.0
38.977051,5.2011994094488185e-05,48.806833818640975,0.00025370340306410486,25.0,0.0
40.27832,8.050272440944882e-05,54.47806065915944,0.00025370340306410486,25.0,0.0
41.57959,9.023343503937008e-05,61.63529775555957,0.00025370340306410486,25.0,0.0
42.880859,0.00020523635826771654,69.20819182106322,0.00025370340306410486,25.0,0.0
44.182129,0.0001685096437007874,73.81395109129797,0.00025370340306410486,25.0,0.0
45.483398,0.00017462975393700786,80.78022006339063,0.00025370340306410486,25.0,0.0
46.784668,0.00021462484251968502,86.48834230937719,0.00025370340306410486,25.0,0.0
48.085938,0.00025809681102362204,94.08931120674106,0.00025370340306410486,25.0,0.0
49.387207,0.00023828651574803148,100.51154430901643,0.00025370340306410486,25.0,0.0
50.688477,0.00023512118110236222,108.09041925425826,0.00025370340306410486,25.0,0.0
51.989746,0.0003369491929133858,114.84607673873272,0.00025370340306410486,25.0,0.0
53.291016,0.0003250864960629921,123.26118741464171,0.00025370340306410486,25.0,0.0
54.592285,0.0003451196062992126,130.81664648130493,0.00025370340306410486,25.0,0.0
55.893555,0.0003869532480314961,139.17368258303915,0.00025370340306410486,25.0,0.0
57.194824,0.00041392507874015745,145.61007807869717,0.00025370340306410486,25.0,0.0
58.496094,0.0004121617125984252,155.2391707681604,0.00025370340306410486,25.0,0.0
59.797363,0.00043225131889763777,162.06223619450103,0.00025370340306410486,25.0,0.0
61.098633,0.0004916392322834646,171.92199087793443,0.00025370340306410486,25.0,0.0
62.399902,0.000535045688976378,178.6747236323344,0.00025370340306410486,25.0,0.0
63.701172,0.0005557340157480315,187.90978431726236,0.00025370340306410486,25.0,0.0
65.002441,0.0005717828740157481,196.74559229005078,0.00025370340306410486,25.0,0.0
66.303711,0.0006199584842519685,206.1838405442317,0.00025370340306410486,25.0,0.0
67.60498,0.0006528349803149606,214.6830906795166,0.00025370340306410486,25.0,0.0
68.90625,0.0007115146850393701,223.959499574819,0.00025370340306410486,25.0,0.0
70.20752,0.0007362350984251968,232.48825211946303,0.00025370340306410486,25.0,0.0
71.508789,0.0007763941338582677,243.62190326487493,0.00025370340306410486,25.0,0.0
72.810059,0.0008053954724409449,251.50841085371198,0.00025370340306410486,25.0,0.0
74.111328,0.0008286883464566928,261.7454582936068,0.00025370340306410486,25.0,0.0
75.412598,0.0008824586614173227,269.33174427294045,0.00025370340306410486,25.0,0.0
76.713867,0.0009276760236220471,278.27819723245807,0.00025370340306410486,25.0,0.0
78.015137,0.0009443252559055118,287.38781663102026,0.00025370340306410486,25.0,0.0
79.316406,0.0009701599212598426,295.1168603602443,0.00025370340306410486,25.0,0.0
80.617676,0.0010193589566929134,305.7328574741671,0.00025370340306410486,25.0,0.0
81.918945,0.001092012933070866,314.3881000850362,0.00025370340306410486,25.0,0.0
83.220215,0.0010928308661417323,321.25245445409337,0.00025370340306410486,25.0,0.0
84.521484,0.0011495519881889764,333.2068183575129,0.00025370340306410486,25.0,0.0
85.822754,0.001176953779527559,340.58239492875003,0.00025370340306410486,25.0,0.0
87.124023,0.0012232488385826772,348.2641533743913,0.00025370340306410486,25.0,0.0
88.425293,0.001303567716535433,359.76893343984335,0.00025370340306410486,25.0,0.0
89.726563,0.001304484094488189,369.4113175458036,0.00025370340306410486,25.0,0.0
91.027832,0.001362235255905512,379.8054217022703,0.00025370340306410486,25.0,0.0
92.329102,0.0013910519094488187,388.20813255340533,0.00025370340306410486,25.0,0.0
93.630371,0.0014564565157480314,397.6191924137398,0.00025370340306410486,25.0,0.0
94.931641,0.0014761661811023622,406.9977839049657,0.00025370340306410486,25.0,0.0
96.23291,0.0015580692913385824,412.1698920297885,0.00025370340306410486,25.0,0.0
97.53418,0.0015679022637795277,423.16092457546324,0.00025370340306410486,25.0,0.0
98.835449,0.0015950426181102362,429.629628675239,0.00025370340306410486,25.0,0.0
100.13672,0.0016466954527559056,439.9586930193007,0.00025370340306410486,25.0,0.0
101.43799,0.0017153542913385827,447.0570773314093,0.00025370340306410486,25.0,0.0
102.73926,0.0017612881102362203,457.53614038704364,0.00025370340306410486,25.0,0.0
104.04053,0.0017688028543307085,464.8587368258304,0.00025370340306410486,25.0,0.0
105.3418,0.0017993938582677167,471.4780838508517,0.00025370340306410486,25.0,0.0
106.64307,0.0018660426377952756,479.16602674775174,0.00025370340306410486,25.0,0.0
107.94434,0.0019279941141732285,488.14881335841477,0.00025370340306410486,25.0,0.0
109.24561,0.001978291732283465,496.2041899657279,0.00025370340306410486,25.0,0.0
110.54688,0.0020234671259842523,502.9562450073441,0.00025370340306410486,25.0,0.0
111.84814,0.00205618562992126,509.5504676991265,0.00025370340306410486,25.0,0.0
113.14941,0.0021284622047244095,519.0270312057104,0.00025370340306410486,25.0,0.0
114.45068,0.002156390748031496,524.8995799726854,0.00025370340306410486,25.0,0.0
115.75195,0.0022129415354330707,531.4620558146727,0.00025370340306410486,25.0,0.0
117.05322,0.002274456496062992,537.9920117504574,0.00025370340306410486,25.0,0.0
118.35449,0.002313932283464567,544.5605432009689,0.00025370340306410486,25.0,0.0
119.65576,0.002373465354330709,549.9532558559023,0.00025370340306410486,25.0,0.0
120.95703,0.002442036220472441,555.3966810111579,0.00025370340306410486,25.0,0.0
122.2583,0.002481593307086614,562.1247455355993,0.00025370340306410486,25.0,0.0
123.55957,0.002550168897637795,568.1675213234727,0.00025370340306410486,25.0,0.0
124.86084,0.0025666478346456694,573.2748730899066,0.00025370340306410486,25.0,0.0
126.16211,0.0026294801181102364,578.3610688793259,0.00025370340306410486,25.0,0.0
127.46338,0.0027254173228346457,584.4904785219162,0.00025370340306410486,25.0,0.0
128.76465,0.00276320374015748,587.7363877650939,0.00025370340306410486,25.0,0.0
130.06592,0.002813799212598425,590.7336820676683,0.00025370340306410486,25.0,0.0
131.36719,0.0028582600393700784,597.1501533228542,0.00025370340306410486,25.0,0.0
132.66846,0.0029585409448818897,602.1392789960574,0.00025370340306410486,25.0,0.0
133.96973,0.0030293793307086614,604.7050016749556,0.00025370340306410486,25.0,0.0
135.271,0.0030647879921259845,610.4912258097767,0.00025370340306410486,25.0,0.0
136.57227,0.003141083661417323,614.5273790810937,0.00025370340306410486,25.0,0.0
137.87354,0.0031956027559055114,616.9070013141959,0.00025370340306410486,25.0,0.0
139.1748,0.0032866732283464567,621.7370319787667,0.00025370340306410486,25.0,0.0
140.47607,0.003371861811023622,625.0288092354473,0.00025370340306410486,25.0,0.0
141.77734,0.003464719881889764,628.3170819697478,0.00025370340306410486,25.0,0.0
143.07861,0.0035524856299212594,633.5578375035432,0.00025370340306410486,25.0,0.0
144.37988,0.0036380742125984252,636.0023964748628,0.00025370340306410486,25.0,0.0
145.68115,0.0037431732283464566,639.5633777411292,0.00025370340306410486,25.0,0.0
146.98242,0.003837749409448819,641.4534233514573,0.00025370340306410486,25.0,0.0
148.28369,0.003974019881889764,644.6167444017832,0.00025370340306410486,25.0,0.0
149.58496,0.004055291338582677,647.0675393614554,0.00025370340306410486,25.0,0.0
150.88623,0.004183190748031496,651.2624526502951,0.00025370340306410486,25.0,0.0
152.1875,0.004328990748031496,654.6447032751823,0.00025370340306410486,25.0,0.0
153.48877,0.00449841594488189,656.7362589223594,0.00025370340306410486,25.0,0.0
154.79004,0.004653842322834645,658.7495554925658,0.00025370340306410486,25.0,0.0
156.09131,0.0048145293307086615,663.9519674285567,0.00025370340306410486,25.0,0.0
157.39258,0.004996118897637795,663.5172520421575,0.00025370340306410486,25.0,0.0
158.69385,0.005124810039370079,664.3544721313166,0.00025370340306410486,25.0,0.0
159.99512,0.0052900610236220474,667.1613884093076,0.00025370340306410486,25.0,0.0
161.29639,0.005447268700787401,669.7113922745897,0.00025370340306410486,25.0,0.0
162.59766,0.0056396021653543306,672.2623238075605,0.00025370340306410486,25.0,0.0
163.89893,0.005863875393700787,675.4560259746954,0.00025370340306410486,25.0,0.0
165.2002,0.006039755905511811,673.4217280387559,0.00025370340306410486,25.0,0.0
166.50146,0.006253387401574803,677.7386296286753,0.00025370340306410486,25.0,0.0
167.80273,0.006481570275590551,679.6960084520834,0.00025370340306410486,25.0,0.0
169.104,0.006652310236220472,679.7678511608732,0.00025370340306410486,25.0,0.0
170.40527,0.006867607086614173,682.2620918906384,0.00025370340306410486,25.0,0.0
171.70654,0.007124361811023622,686.3273120828718,0.00025370340306410486,25.0,0.0
173.00781,0.007432507874015748,685.83904965599,0.00025370340306410486,25.0,0.0
174.30908,0.00768606437007874,686.6513773288325,0.00025370340306410486,25.0,0.0
175.61035,0.007953338582677166,689.5586363284975,0.00025370340306410486,25.0,0.0
176.91162,0.008217830511811023,691.0188110392455,0.00025370340306410486,25.0,0.0
178.21289,0.008519004133858268,692.5858221454893,0.00025370340306410486,25.0,0.0
179.51416,0.00883948464566929,692.0759141392018,0.00025370340306410486,25.0,0.0
180.81543,0.009099340551181102,694.1030484190998,0.00025370340306410486,25.0,0.0
182.1167,0.009378227755905513,695.4810730022934,0.00025370340306410486,25.0,0.0
183.41797,0.009667415748031497,696.9683562243927,0.00025370340306410486,25.0,0.0
184.71924,0.009942824015748032,696.8604117813798,0.00025370340306410486,25.0,0.0
186.02051,0.010265250787401575,696.6144252325612,0.00025370340306410486,25.0,0.0
187.32178,0.010557900196850394,699.3537763805499,0.00025370340306410486,25.0,0.0
188.62305,0.010907389566929134,700.9664493519211,0.00025370340306410486,25.0,0.0
189.92432,0.01120428720472441,701.0248151106761,0.00025370340306410486,25.0,0.0
191.22559,0.011493061023622048,700.8035663668927,0.00025370340306410486,25.0,0.0
192.52686,0.011765304921259843,700.908753575386,0.00025370340306410486,25.0,0.0
193.82813,0.012075081102362203,703.3947741386863,0.00025370340306410486,25.0,0.0
195.12939,0.012343502952755905,704.5723451954545,0.00025370340306410486,25.0,0.0
196.43066,0.01266153720472441,706.4478573453245,0.00025370340306410486,25.0,0.0
197.73193,0.013012763188976378,706.9406550364625,0.00025370340306410486,25.0,0.0
199.0332,0.013346408267716535,706.4078387919707,0.00025370340306410486,25.0,0.0
200.33447,0.013643658661417321,708.4045919550598,0.00025370340306410486,25.0,0.0
201.63574,0.013907970866141732,708.3016723786945,0.00025370340306410486,25.0,0.0
202.93701,0.014302564173228347,710.2948952508569,0.00025370340306410486,25.0,0.0
204.23828,0.014668157480314959,711.2961836782025,0.00025370340306410486,25.0,0.0
205.53955,0.01503588622047244,712.1166284433222,0.00025370340306410486,25.0,0.0
206.84082,0.015336110826771655,712.9908521658465,0.00025370340306410486,25.0,0.0
208.14209,0.015682848818897636,712.3886669930683,0.00025370340306410486,25.0,0.0
209.44336,0.016087352362204724,714.1805086711162,0.00025370340306410486,25.0,0.0
210.74463,0.01642917559055118,715.1323472569383,0.00025370340306410486,25.0,0.0
212.0459,0.01675397244094488,713.4608446929678,0.00025370340306410486,25.0,0.0
213.34717,0.017124351377952755,715.9356044012678,0.00025370340306410486,25.0,0.0
214.64844,0.017462744094488187,714.1772876027521,0.00025370340306410486,25.0,0.0
215.94971,0.017723121456692914,716.1101090009535,0.00025370340306410486,25.0,0.0
217.25098,0.01801315,717.852758522947,0.00025370340306410486,25.0,0.0
218.55225,0.01848796023622047,718.472749761641,0.00025370340306410486,25.0,0.0
219.85352,0.018879444094488187,717.940526193728,0.00025370340306410486,25.0,0.0
221.15479,0.01920622244094488,719.2386425129487,0.00025370340306410486,25.0,0.0
222.45605,0.019513647047244096,719.2565774215993,0.00025370340306410486,25.0,0.0
223.75732,0.019937370078740156,722.9350117246889,0.00025370340306410486,25.0,0.0
225.05859,0.0203118562992126,720.4288143891566,0.00025370340306410486,25.0,0.0
226.35986,0.020690427165354332,723.9004561032804,0.00025370340306410486,25.0,0.0
227.66113,0.02102754724409449,721.606643131394,0.00025370340306410486,25.0,0.0
228.9624,0.02133461811023622,722.2987863014405,0.00025370340306410486,25.0,0.0
230.26367,0.021671049212598426,723.9893318215786,0.00025370340306410486,25.0,0.0
231.56494,0.022029759842519685,723.8887571829825,0.00025370340306410486,25.0,0.0
232.86621,0.02240132283464567,724.0299945886052,0.00025370340306410486,25.0,0.0
234.16748,0.022731015748031495,725.7418764655862,0.00025370340306410486,25.0,0.0
235.46875,0.023026746062992126,723.7835699744892,0.00025370340306410486,25.0,0.0
236.77002,0.023386287401574803,726.696163063365,0.00025370340306410486,25.0,0.0
238.07129,0.023797090551181104,726.4848609786895,0.00025370340306410486,25.0,0.0
239.37256,0.02421208464566929,728.5242610869174,0.00025370340306410486,25.0,0.0
240.67383,0.024592620078740156,728.089545700518,0.00025370340306410486,25.0,0.0
241.9751,0.0248906437007874,728.0198933182158,0.00025370340306410486,25.0,0.0
243.27637,0.025263543307086616,728.714510268766,0.00025370340306410486,25.0,0.0
244.57764,0.025619285433070866,730.459917025279,0.00025370340306410486,25.0,0.0
245.87891,0.025979196850393703,729.0173680006185,0.00025370340306410486,25.0,0.0
247.18018,0.02628608464566929,731.5133094544799,0.00025370340306410486,25.0,0.0
248.48145,0.026639612204724408,730.7385007859407,0.00025370340306410486,25.0,0.0
249.78271,0.027062482283464567,731.5728863349397,0.00025370340306410486,25.0,0.0
251.08398,0.02741751771653543,733.0794959672226,0.00025370340306410486,25.0,0.0
252.38525,0.027782102362204724,731.9477671554102,0.00025370340306410486,25.0,0.0
253.68652,0.028164031496062992,733.3644703275183,0.00025370340306410486,25.0,0.0
254.98779,0.02856862401574803,734.4653026515836,0.00025370340306410486,25.0,0.0
256.28906,0.028901692913385825,735.1309042183112,0.00025370340306410486,25.0,0.0
257.59033,0.02932715354330709,734.3136289844616,0.00025370340306410486,25.0,0.0
258.8916,0.029731110236220475,734.1414435539981,0.00025370340306410486,25.0,0.0
260.19287,0.030067277559055118,735.4114206199913,0.00025370340306410486,25.0,0.0
261.49414,0.03037745472440945,734.9862653644961,0.00025370340306410486,25.0,0.0
262.79541,0.03076642716535433,737.0184502795888,0.00025370340306410486,25.0,0.0
264.09668,0.031168712598425196,737.8860514855568,0.00025370340306410486,25.0,0.0
265.39795,0.03155567322834646,736.6919885587653,0.00025370340306410486,25.0,0.0
266.69922,0.031899972440944876,736.8919782513465,0.00025370340306410486,25.0,0.0
268.00049,0.032253692913385826,738.8692246244235,0.00025370340306410486,25.0,0.0
269.30176,0.03261387598425197,736.4114721570851,0.00025370340306410486,25.0,0.0
270.60303,0.032959364173228346,739.8463163862191,0.00025370340306410486,25.0,0.0
271.9043,0.03333789566929134,740.1253897492721,0.00025370340306410486,25.0,0.0
273.20557,0.033695787401574806,738.811039245497,0.00025370340306410486,25.0,0.0
274.50684,0.0340438937007874,740.8543304043085,0.00025370340306410486,25.0,0.0
275.80811,0.03447888188976378,743.1792460123174,0.00025370340306410486,25.0,0.0
277.10938,0.034813505905511806,738.9952328188215,0.00025370340306410486,25.0,0.0
278.41064,0.03512856692913385,741.8513670214137,0.00025370340306410486,25.0,0.0
279.71191,0.03550099212598425,742.9418661581675,0.00025370340306410486,25.0,0.0
281.01318,0.03590086220472441,744.9809570438323,0.00025370340306410486,25.0,0.0
282.31445,0.036312913385826776,743.6659107892907,0.00025370340306410486,25.0,0.0
283.61572,0.03667228346456693,744.0984358492026,0.00025370340306410486,25.0,0.0
284.91699,0.03705202165354331,743.0423377225759,0.00025370340306410486,25.0,0.0
286.21826,0.03742316929133858,744.7206947200249,0.00025370340306410486,25.0,0.0
287.51953,0.03770286220472441,742.819182106321,0.00025370340306410486,25.0,0.0
288.8208,0.03800901377952756,745.2171257762776,0.00025370340306410486,25.0,0.0
290.12207,0.03836013779527559,746.6315097791637,0.00025370340306410486,25.0,0.0
291.42334,0.038781639763779525,745.5466539541836,0.00025370340306410486,25.0,0.0
292.72461,0.03914542125984252,746.532532790476,0.00025370340306410486,25.0,0.0
294.02588,0.03958186023622047,747.7559976292937,0.00025370340306410486,25.0,0.0
295.32715,0.039942791338582674,747.5411394851445,0.00025370340306410486,25.0,0.0
296.62842,0.04032022834645669,747.117246888448,0.00025370340306410486,25.0,0.0
297.92969,0.0406514625984252,748.1516478985751,0.00025370340306410486,25.0,0.0
299.23096,0.040991742125984255,747.7807096657821,0.00025370340306410486,25.0,0.0
300.53223,0.041327057086614175,747.6272579689232,0.00025370340306410486,25.0,0.0
301.8335,0.041613909448818896,747.8578349266885,0.00025370340306410486,25.0,0.0
303.13477,0.0419715,748.9773494472647,0.00025370340306410486,25.0,0.0
304.43604,0.04237310236220473,749.8108588656687,0.00025370340306410486,25.0,0.0
305.7373,0.042701187007874015,752.1483495245703,0.00025370340306410486,25.0,0.0
307.03857,0.04308254133858268,751.9047336820678,0.00025370340306410486,25.0,0.0
308.33984,0.04343158070866141,752.8567784162652,0.00025370340306410486,25.0,0.0
309.64111,0.043803027559055116,751.2027726956477,0.00025370340306410486,25.0,0.0
310.94238,0.04417459448818897,751.721493544979,0.00025370340306410486,25.0,0.0
312.24365,0.04450739763779527,750.6951580900353,0.00025370340306410486,25.0,0.0
313.54492,0.04492318110236221,753.034143324658,0.00025370340306410486,25.0,0.0
314.84619,0.045295476377952754,754.3655268379417,0.00025370340306410486,25.0,0.0
316.14746,0.04567040748031496,754.5023578220425,0.00025370340306410486,25.0,0.0
317.44873,0.04609528346456693,754.7752209652898,0.00025370340306410486,25.0,0.0
318.75,0.04643839173228346,753.7427010590874,0.00025370340306410486,25.0,0.0
320.05127,0.04682242519685039,754.7177828742238,0.00025370340306410486,25.0,0.0
321.35254,0.04720699015748032,755.479758806401,0.00025370340306410486,25.0,0.0
322.65381,0.0475323405511811,754.461978509032,0.00025370340306410486,25.0,0.0
323.95508,0.047877982283464564,755.9794624681115,0.00025370340306410486,25.0,0.0
325.25635,0.04826230118110236,755.969953874301,0.00025370340306410486,25.0,0.0
326.55762,0.048627206692913386,756.0082201664649,0.00025370340306410486,25.0,0.0
327.85889,0.048982645669291336,756.928286133945,0.00025370340306410486,25.0,0.0
329.16016,0.04933765748031496,757.0512278712604,0.00025370340306410486,25.0,0.0
330.46143,0.04976960826771653,759.3031927229624,0.00025370340306410486,25.0,0.0
331.7627,0.050157555118110236,757.6125698971837,0.00025370340306410486,25.0,0.0
333.06396,0.05044351574803149,758.9530239389801,0.00025370340306410486,25.0,0.0
334.36523,0.05079337204724409,757.56520730796,0.00025370340306410486,25.0,0.0
335.6665,0.05112659448818897,759.9590537789575,0.00025370340306410486,25.0,0.0
336.96777,0.051526137795275595,759.5730151776743,0.00025370340306410486,25.0,0.0
338.26904,0.05184796850393701,759.1341510552221,0.00025370340306410486,25.0,0.0
339.57031,0.05222277362204725,759.347617697838,0.00025370340306410486,25.0,0.0
340.87158,0.0526363405511811,761.4817687530601,0.00025370340306410486,25.0,0.0
342.17285,0.05299473622047244,760.131548431984,0.00025370340306410486,25.0,0.0
343.47412,0.0533586062992126,760.8643543690572,0.00025370340306410486,25.0,0.0
344.77539,0.053743185039370076,763.0236039889712,0.00025370340306410486,25.0,0.0
346.07666,0.054110761811023624,762.8628597933363,0.00025370340306410486,25.0,0.0
347.37793,0.054419370078740155,763.3008993222873,0.00025370340306410486,25.0,0.0
348.6792,0.05475986023622047,761.6173370783622,0.00025370340306410486,25.0,0.0
349.98047,0.0551742125984252,762.7133249156082,0.00025370340306410486,25.0,0.0
351.28174,0.0555006062992126,763.1318576545469,0.00025370340306410486,25.0,0.0
352.58301,0.05586619488188977,764.7392480738011,0.00025370340306410486,25.0,0.0
353.88428,0.05618897637795276,763.9620429303992,0.00025370340306410486,25.0,0.0
355.18555,0.05665696062992126,767.0770479552659,0.00025370340306410486,25.0,0.0
356.48682,0.05706622637795275,764.5530960909116,0.00025370340306410486,25.0,0.0
357.78809,0.05741907283464567,766.952482799495,0.00025370340306410486,25.0,0.0
359.08936,0.05779431889763779,764.9272296235216,0.00025370340306410486,25.0,0.0
360.39063,0.05816014763779528,764.5769577653517,0.00025370340306410486,25.0,0.0
361.69189,0.05851092322834645,768.980183987425,0.00025370340306410486,25.0,0.0
362.99316,0.05888633267716535,767.0005411394852,0.00025370340306410486,25.0,0.0
364.29443,0.05918754724409449,766.6487489370476,0.00025370340306410486,25.0,0.0
365.5957,0.059522805118110235,768.791506686938,0.00025370340306410486,25.0,0.0
366.89697,0.05985012007874015,767.7358466256088,0.00025370340306410486,25.0,0.0
368.19824,0.06025374212598425,768.471280954467,0.00025370340306410486,25.0,0.0
369.49951,0.06067775196850394,768.3053315123561,0.00025370340306410486,25.0,0.0
370.80078,0.061007155511811025,766.4841652279229,0.00025370340306410486,25.0,0.0
372.10205,0.06133255708661417,769.6706264333754,0.00025370340306410486,25.0,0.0
373.40332,0.0616677342519685,768.9068209343675,0.00025370340306410486,25.0,0.0
374.70459,0.06199151771653543,769.983688509805,0.00025370340306410486,25.0,0.0
376.00586,0.06237423622047244,771.9412992501353,0.00025370340306410486,25.0,0.0
377.30713,0.06270261417322835,769.722086221558,0.00025370340306410486,25.0,0.0
378.6084,0.06307314763779528,772.9748756667611,0.00025370340306410486,25.0,0.0
379.90967,0.06340681102362206,770.6377715360632,0.00025370340306410486,25.0,0.0
381.21094,0.06376916732283465,770.912258097766,0.00025370340306410486,25.0,0.0
382.51221,0.06412132677165354,770.6350658386375,0.00025370340306410486,25.0,0.0
383.81348,0.06445043700787402,771.7422372252429,0.00025370340306410486,25.0,0.0
385.11475,0.06479712992125984,774.4953230087356,0.00025370340306410486,25.0,0.0
386.41602,0.06518273031496064,774.678949674028,0.00025370340306410486,25.0,0.0
387.71729,0.0655592125984252,774.03329296261,0.00025370340306410486,25.0,0.0
389.01855,0.06587017913385826,773.1392532275106,0.00025370340306410486,25.0,0.0
390.31982,0.06623773818897638,774.9822454711779,0.00025370340306410486,25.0,0.0
391.62109,0.0666339625984252,775.1290231143867,0.00025370340306410486,25.0,0.0
392.92236,0.06707341141732283,776.1832401370888,0.00025370340306410486,25.0,0.0
394.22363,0.06742270866141732,774.0141211637077,0.00025370340306410486,25.0,0.0
395.5249,0.06776789960629921,775.5035947122942,0.00025370340306410486,25.0,0.0
396.82617,0.06808520669291339,776.2355245187724,0.00025370340306410486,25.0,0.0
398.12744,0.06846312795275591,776.9306826088078,0.00025370340306410486,25.0,0.0
399.42871,0.06887396456692914,776.2883500399413,0.00025370340306410486,25.0,0.0
400.72998,0.0692728996062992,777.3426185997372,0.00025370340306410486,25.0,0.0
402.03125,0.06965290354330708,778.1577035070993,0.00025370340306410486,25.0,0.0
403.33252,0.06998345078740156,777.4772077202567,0.00025370340306410486,25.0,0.0
404.63379,0.0703506751968504,778.2225629396759,0.00025370340306410486,25.0,0.0
405.93506,0.0706894842519685,779.1640425696396,0.00025370340306410486,25.0,0.0
407.23633,0.07103364173228346,776.2978586337517,0.00025370340306410486,25.0,0.0
408.5376,0.07135146456692913,777.6180585976758,0.00025370340306410486,25.0,0.0
409.83887,0.07165735433070866,776.3095060169558,0.00025370340306410486,25.0,0.0
411.14014,0.07201563385826772,780.8272476615044,0.00025370340306410486,25.0,0.0
412.44141,0.07237902362204723,779.4141263174171,0.00025370340306410486,25.0,0.0
413.74268,0.07277168700787401,780.8349782255779,0.00025370340306410486,25.0,0.0
415.04395,0.07314939566929134,780.8696369211741,0.00025370340306410486,25.0,0.0
416.34521,0.07350931692913386,781.2278454917928,0.00025370340306410486,25.0,0.0
417.64648,0.07385441338582677,780.9404231195404,0.00025370340306410486,25.0,0.0
418.94775,0.07418226377952757,780.504573917077,0.00025370340306410486,25.0,0.0
420.24902,0.07457514960629921,783.400133996444,0.00025370340306410486,25.0,0.0
421.55029,0.07495670669291339,783.272991985982,0.00025370340306410486,25.0,0.0
422.85156,0.07528502559055118,781.9546215888887,0.00025370340306410486,25.0,0.0
424.15283,0.07561655314960629,781.5178704872833,0.00025370340306410486,25.0,0.0
425.4541,0.07597741338582677,782.3070322364523,0.00025370340306410486,25.0,0.0
426.75537,0.07635343897637795,783.7192774499447,0.00025370340306410486,25.0,0.0
428.05664,0.07678899212598425,784.7759940216972,0.00025370340306410486,25.0,0.0
429.35791,0.07713617125984251,783.8070966578196,0.00025370340306410486,25.0,0.0
430.65918,0.07748182086614172,784.2670394516454,0.00025370340306410486,25.0,0.0
431.96045,0.07781894488188976,786.014610766099,0.00025370340306410486,25.0,0.0
433.26172,0.07816558464566929,783.9610379570696,0.00025370340306410486,25.0,0.0
434.56299,0.07850759448818898,784.6825057335018,0.00025370340306410486,25.0,0.0
435.86426,0.0788374094488189,785.0668436106889,0.00025370340306410486,25.0,0.0
437.16553,0.07923712992125984,786.3467157986962,0.00025370340306410486,25.0,0.0
438.4668,0.07961383661417322,784.6182132089573,0.00025370340306410486,25.0,0.0
439.76807,0.07999501181102361,787.311515963615,0.00025370340306410486,25.0,0.0
441.06934,0.08038959448818897,786.4691421650734,0.00025370340306410486,25.0,0.0
442.37061,0.08078959645669291,785.6472543613266,0.00025370340306410486,25.0,0.0
443.67188,0.08107616732283465,785.9024918184864,0.00025370340306410486,25.0,0.0
444.97314,0.08135097637795276,788.5518334321129,0.00025370340306410486,25.0,0.0
446.27441,0.08170555511811023,788.2689205555699,0.00025370340306410486,25.0,0.0
447.57568,0.082037,786.7971499987117,0.00025370340306410486,25.0,0.0
448.87695,0.08240288779527559,788.3260236555262,0.00025370340306410486,25.0,0.0
450.17822,0.08273437401574803,788.2244182750536,0.00025370340306410486,25.0,0.0
451.47949,0.08310585826771653,789.0817378308038,0.00025370340306410486,25.0,0.0
452.78076,0.0834993720472441,790.578014275775,0.00025370340306410486,25.0,0.0
454.08203,0.08386985433070866,789.3780503517407,0.00025370340306410486,25.0,0.0
455.3833,0.08420818110236221,790.1894761254414,0.00025370340306410486,25.0,0.0
456.68457,0.0845362283464567,789.9200144303863,0.00025370340306410486,25.0,0.0
457.98584,0.0848799409448819,788.8334063442164,0.00025370340306410486,25.0,0.0
459.28711,0.08524788385826772,790.1680882315047,0.00025370340306410486,25.0,0.0
460.58838,0.08562565157480315,791.5760300976629,0.00025370340306410486,25.0,0.0
461.88965,0.08605101968503938,792.1699177983354,0.00025370340306410486,25.0,0.0
463.19092,0.08639409842519685,790.9240858607984,0.00025370340306410486,25.0,0.0
464.49219,0.08677562795275591,791.8779601618266,0.00025370340306410486,25.0,0.0
465.79346,0.08711150787401575,791.9023629757519,0.00025370340306410486,25.0,0.0
467.09473,0.0874680846456693,793.014327312083,0.00025370340306410486,25.0,0.0
468.396,0.08786308858267716,792.9804674414411,0.00025370340306410486,25.0,0.0
469.69727,0.08820387401574803,792.4469296776355,0.00025370340306410486,25.0,0.0
470.99854,0.08863585039370078,795.4279897956554,0.00025370340306410486,25.0,0.0
472.2998,0.08904208858267716,794.1725977272142,0.00025370340306410486,25.0,0.0
473.60107,0.08937954133858268,792.0535470404825,0.00025370340306410486,25.0,0.0
474.90234,0.0896611377952756,794.5839668101116,0.00025370340306410486,25.0,0.0
476.20361,0.09002901377952756,795.124255933208,0.00025370340306410486,25.0,0.0
477.50488,0.09039586417322834,794.8684515680162,0.00025370340306410486,25.0,0.0
478.80615,0.0907676653543307,795.7603525137218,0.00025370340306410486,25.0,0.0
480.10742,0.09113050984251968,794.9728914886491,0.00025370340306410486,25.0,0.0
481.40869,0.09143716732283465,795.561419331564,0.00025370340306410486,25.0,0.0
482.70996,0.09179419685039371,796.5942999974233,0.00025370340306410486,25.0,0.0
484.01123,0.09221134842519685,797.614476769655,0.00025370340306410486,25.0,0.0
485.3125,0.09253340157480315,797.6816038343599,0.00025370340306410486,25.0,0.0
486.61377,0.09293038188976378,795.8863607081197,0.00025370340306410486,25.0,0.0
487.91504,0.09324552952755905,796.8639420723067,0.00025370340306410486,25.0,0.0
489.21631,0.0935606594488189,796.2820109774011,0.00025370340306410486,25.0,0.0
490.51758,0.09391503149606299,796.7549668874174,0.00025370340306410486,25.0,0.0
491.81885,0.09429914763779527,795.8905609812664,0.00025370340306410486,25.0,0.0
493.12012,0.09464518307086614,797.7606875048317,0.00025370340306410486,25.0,0.0
494.42139,0.09495834251968503,797.6618393588786,0.00025370340306410486,25.0,0.0
495.72266,0.09535163385826771,799.7112634318552,0.00025370340306410486,25.0,0.0
497.02393,0.09574253543307086,798.8115546164353,0.00025370340306410486,25.0,0.0
498.3252,0.09615399015748032,798.8138222485635,0.00025370340306410486,25.0,0.0
499.62646,0.09648987007874016,798.9962635606979,0.00025370340306410486,25.0,0.0
500.92773,0.09683917913385827,799.0528770582628,0.00025370340306410486,25.0,0.0
502.229,0.09723648818897639,800.7027340428274,0.00025370340306410486,25.0,0.0
503.53027,0.09758085826771652,798.9658051382484,0.00025370340306410486,25.0,0.0
504.83154,0.09788142716535432,798.5255495142629,0.00025370340306410486,25.0,0.0
506.13281,0.09826004133858268,801.1628056793879,0.00025370340306410486,25.0,0.0
507.43408,0.09864257874015747,801.125132063803,0.00025370340306410486,25.0,0.0
508.73535,0.09899835236220474,801.6851598938337,0.00025370340306410486,25.0,0.0
510.03662,0.09933786417322833,799.5517045893782,0.00025370340306410486,25.0,0.0
511.33789,0.09968703149606298,800.855670368748,0.00025370340306410486,25.0,0.0
512.63916,0.10004040157480315,800.6265622181567,0.00025370340306410486,25.0,0.0
513.94043,0.10043223031496062,803.123689025176,0.00025370340306410486,25.0,0.0
515.2417,0.10077433464566929,802.5420671528334,0.00025370340306410486,25.0,0.0
516.54297,0.10116608267716536,802.783904965599,0.00025370340306410486,25.0,0.0
517.84424,0.10153031692913386,802.9752879635118,0.00025370340306410486,25.0,0.0
519.14551,0.10186744685039369,800.93583631819,0.00025370340306410486,25.0,0.0
520.44678,0.10218136811023622,803.1313165150617,0.00025370340306410486,25.0,0.0
521.74805,0.10256235826771652,803.1602545932436,0.00025370340306410486,25.0,0.0
523.04932,0.1029590216535433,803.8373747004407,0.00025370340306410486,25.0,0.0
524.35059,0.1033177874015748,802.6124152859021,0.00025370340306410486,25.0,0.0
525.65186,0.1036441811023622,803.1944752235422,0.00025370340306410486,25.0,0.0
526.95313,0.10399186023622047,804.524364161105,0.00025370340306410486,25.0,0.0
528.25439,0.1043580531496063,804.6325147524932,0.00025370340306410486,25.0,0.0
529.55566,0.1047515374015748,805.7327028628856,0.00025370340306410486,25.0,0.0
530.85693,0.10515343503937008,806.4540933336771,0.00025370340306410486,25.0,0.0
532.1582,0.10551652952755906,805.4156208931379,0.00025370340306410486,25.0,0.0
533.45947,0.10586325787401575,806.840518463164,0.00025370340306410486,25.0,0.0
534.76074,0.10625166141732283,805.4154405133095,0.00025370340306410486,25.0,0.0
536.06201,0.10666813188976378,807.9299353209474,0.00025370340306410486,25.0,0.0
537.36328,0.10707676377952755,806.5152678640453,0.00025370340306410486,25.0,0.0
538.66455,0.10739285629921261,807.6744659468653,0.00025370340306410486,25.0,0.0
539.96582,0.10772302952755906,807.3987940320046,0.00025370340306410486,25.0,0.0
541.26709,0.10811871850393702,807.5026412760585,0.00025370340306410486,25.0,0.0
542.56836,0.1084481279527559,807.9916509908006,0.00025370340306410486,25.0,0.0
543.86963,0.10882971653543307,808.5863632849745,0.00025370340306410486,25.0,0.0
545.1709,0.10918978346456693,808.9384131728813,0.00025370340306410486,25.0,0.0
546.47217,0.10960567913385827,808.7512046795681,0.00025370340306410486,25.0,0.0
547.77344,0.10998143503937008,809.5533022392868,0.00025370340306410486,25.0,0.0
549.07471,0.11031617125984253,809.2912876542892,0.00025370340306410486,25.0,0.0
550.37598,0.11063038582677166,808.6989718349784,0.00025370340306410486,25.0,0.0
551.67725,0.11098353149606299,809.4735485865953,0.00025370340306410486,25.0,0.0
552.97852,0.1113096909448819,807.4805576313553,0.00025370340306410486,25.0,0.0
554.27979,0.11163236614173229,809.055995052439,0.00025370340306410486,25.0,0.0
555.58105,0.11203204527559055,810.2796918081791,0.00025370340306410486,25.0,0.0
556.88232,0.11245225787401575,808.9762929368413,0.00025370340306410486,25.0,0.0
558.18359,0.11281497834645668,810.3914757646817,0.00025370340306410486,25.0,0.0
559.48486,0.11314768503937007,809.0278815677585,0.00025370340306410486,25.0,0.0
560.78613,0.11351622440944882,811.2907465148041,0.00025370340306410486,25.0,0.0
562.0874,0.11387348818897637,810.5353673306363,0.00025370340306410486,25.0,0.0
563.38867,0.1142318562992126,810.9222562939676,0.00025370340306410486,25.0,0.0
564.68994,0.11462077559055117,811.1272450846498,0.00025370340306410486,25.0,0.0
565.99121,0.11498462204724409,812.5708763882806,0.00025370340306410486,25.0,0.0
567.29248,0.11532503740157479,811.8793516633598,0.00025370340306410486,25.0,0.0
568.59375,0.11567893503937009,810.8704357461284,0.00025370340306410486,25.0,0.0
569.89502,0.11605317716535432,812.2354729816786,0.00025370340306410486,25.0,0.0
571.19629,0.1164699625984252,811.9811889607546,0.00025370340306410486,25.0,0.0
572.49756,0.11689537401574802,813.0220578761565,0.00025370340306410486,25.0,0.0
573.79883,0.11733776181102362,812.596103795707,0.00025370340306410486,25.0,0.0
575.1001,0.1177342027559055,812.288143891566,0.00025370340306410486,25.0,0.0
576.40137,0.11811832480314961,814.7118045713403,0.00025370340306410486,25.0,0.0
577.70264,0.11850554330708661,813.8268353647538,0.00025370340306410486,25.0,0.0
579.00391,0.11887749803149607,813.6963434431933,0.00025370340306410486,25.0,0.0
580.30518,0.11922473031496061,813.1705877805551,0.00025370340306410486,25.0,0.0
581.60645,0.11959596850393701,813.952766253511,0.00025370340306410486,25.0,0.0
582.90771,0.11995988582677167,814.0320560723582,0.00025370340306410486,25.0,0.0
584.20898,0.12036714566929134,813.6378488417039,0.00025370340306410486,25.0,0.0
585.51025,0.12077091929133858,814.8185121241015,0.00025370340306410486,25.0,0.0
586.81152,0.12103064566929134,812.2915968768523,0.00025370340306410486,25.0,0.0
588.11279,0.12138183267716536,814.9190352256037,0.00025370340306410486,25.0,0.0
589.41406,0.12173724212598425,814.10062617569,0.00025370340306410486,25.0,0.0
590.71533,0.1220323562992126,815.0091993712475,0.00025370340306410486,25.0,0.0
592.0166,0.12238923228346457,814.848068647409,0.00025370340306410486,25.0,0.0
593.31787,0.12274233070866142,815.5866467389905,0.00025370340306410486,25.0,0.0
594.61914,0.12309501968503937,815.1401808951994,0.00025370340306410486,25.0,0.0
595.92041,0.12351725000000001,817.3717628262943,0.00025370340306410486,25.0,0.0
597.22168,0.12384898228346457,815.5346200427759,0.00025370340306410486,25.0,0.0
598.52295,0.12419387992125985,815.7210297111346,0.00025370340306410486,25.0,0.0
599.82422,0.12455570866141734,817.1120674105189,0.00025370340306410486,25.0,0.0
601.12549,0.12494641338582677,817.1575488958179,0.00025370340306410486,25.0,0.0
602.42676,0.12536575787401574,817.9136238307523,0.00025370340306410486,25.0,0.0
603.72803,0.12574898622047243,816.9056613497567,0.00025370340306410486,25.0,0.0
605.0293,0.12619311220472443,817.9907490916587,0.00025370340306410486,25.0,0.0
606.33057,0.12659146653543307,818.2720385497463,0.00025370340306410486,25.0,0.0
607.63184,0.12698847047244094,817.5449532300873,0.00025370340306410486,25.0,0.0
608.93311,0.12738122637795274,818.9059190352257,0.00025370340306410486,25.0,0.0
610.23438,0.1277490157480315,818.9004561032805,0.00025370340306410486,25.0,0.0
611.53564,0.12810355708661417,819.7809673512512,0.00025370340306410486,25.0,0.0
612.83691,0.12847500787401575,818.3957791120159,0.00025370340306410486,25.0,0.0
614.13818,0.12881821456692913,817.4233514572113,0.00025370340306410486,25.0,0.0
615.43945,0.12919582480314962,818.449996134718,0.00025370340306410486,25.0,0.0
616.74072,0.1295573248031496,819.1274254644782,0.00025370340306410486,25.0,0.0
618.04199,0.12993882874015747,819.6769654959157,0.00025370340306410486,25.0,0.0
619.34326,0.13032353740157482,821.0661220913753,0.00025370340306410486,25.0,0.0
620.64453,0.1307240748031496,819.7792666271549,0.00025370340306410486,25.0,0.0
621.9458,0.13110025196850394,820.298090550674,0.00025370340306410486,25.0,0.0
623.24707,0.1315342972440945,821.5410879480507,0.00025370340306410486,25.0,0.0
624.54834,0.13184613188976377,819.4379106862165,0.00025370340306410486,25.0,0.0
625.84961,0.13223684645669292,822.20650913495,0.00025370340306410486,25.0,0.0
627.15088,0.13257642913385825,820.7187878475534,0.00025370340306410486,25.0,0.0
628.45215,0.13296562992125985,820.4320869946145,0.00025370340306410486,25.0,0.0
629.75342,0.13335506692913385,823.7208493313062,0.00025370340306410486,25.0,0.0
631.05469,0.133784655511811,822.8558765171233,0.00025370340306410486,25.0,0.0
632.35596,0.1341851909448819,820.8704099775815,0.00025370340306410486,25.0,0.0
633.65723,0.1345424783464567,821.590872780684,0.00025370340306410486,25.0,0.0
634.9585,0.13496061417322835,821.5258071997322,0.00025370340306410486,25.0,0.0
636.25977,0.1352995748031496,820.0429819362487,0.00025370340306410486,25.0,0.0
637.56104,0.13568235826771652,822.3494988017627,0.00025370340306410486,25.0,0.0
638.8623,0.13605630708661418,820.904115236942,0.00025370340306410486,25.0,0.0
640.16357,0.13647163976377952,823.8879583580283,0.00025370340306410486,25.0,0.0
641.46484,0.13689016338582677,823.4681371917438,0.00025370340306410486,25.0,0.0
642.76611,0.13734226574803152,824.0180379828382,0.00025370340306410486,25.0,0.0
644.06738,0.1377906968503937,824.2113793903163,0.00025370340306410486,25.0,0.0
645.36865,0.13811628149606298,822.3349911098514,0.00025370340306410486,25.0,0.0
646.66992,0.13849199015748032,824.0890818666736,0.00025370340306410486,25.0,0.0
647.97119,0.13891864566929135,823.4498930605304,0.00025370340306410486,25.0,0.0
649.27246,0.13928265551181102,823.0767129641561,0.00025370340306410486,25.0,0.0
650.57373,0.13961796653543307,823.6639266111786,0.00025370340306410486,25.0,0.0
651.875,0.13999496653543309,824.2099878887831,0.00025370340306410486,25.0,0.0
653.17627,0.1403786062992126,823.7775916716057,0.00025370340306410486,25.0,0.0
654.47754,0.14073799409448817,823.1979282088283,0.00025370340306410486,25.0,0.0
655.77881,0.14114776377952756,825.7474167031722,0.00025370340306410486,25.0,0.0
657.08008,0.14157968700787402,825.2662148581443,0.00025370340306410486,25.0,0.0
658.38135,0.14196748031496062,823.8396938696628,0.00025370340306410486,25.0,0.0
659.68262,0.1423226338582677,823.3402994305152,0.00025370340306410486,25.0,0.0
660.98389,0.14269078543307087,823.5357023217462,0.00025370340306410486,25.0,0.0
662.28516,0.14299769094488188,825.0928956116165,0.00025370340306410486,25.0,0.0
663.58643,0.1433290374015748,824.6557837503544,0.00025370340306410486,25.0,0.0
664.8877,0.14375795472440944,826.6237276779964,0.00025370340306410486,25.0,0.0
666.18896,0.14418293110236222,825.6361996547016,0.00025370340306410486,25.0,0.0
667.49023,0.14460465748031495,826.9796170793929,0.00025370340306410486,25.0,0.0
668.7915,0.1450653622047244,825.1939856211509,0.00025370340306410486,25.0,0.0
670.09277,0.1454788405511811,825.3856778416266,0.00025370340306410486,25.0,0.0
671.39404,0.14592700196850392,827.5351096451673,0.00025370340306410486,25.0,0.0
672.69531,0.14629909645669292,826.4113948514445,0.00025370340306410486,25.0,0.0
673.99658,0.1467002539370079,825.7557914809184,0.00025370340306410486,25.0,0.0
675.29785,0.1471041338582677,826.4600974051074,0.00025370340306410486,25.0,0.0
676.59912,0.14745377165354331,826.5569098358544,0.00025370340306410486,25.0,0.0
677.90039,0.14792622047244094,827.6951065529415,0.00025370340306410486,25.0,0.0
679.20166,0.14827193897637794,824.6246295771383,0.00025370340306410486,25.0,0.0
680.50293,0.14868207283464566,826.9976035251373,0.00025370340306410486,25.0,0.0
681.8042,0.14907535826771653,828.1944236864484,0.00025370340306410486,25.0,0.0
683.10547,0.14950452362204725,826.7666400391684,0.00025370340306410486,25.0,0.0
684.40674,0.14984283858267716,827.8384054423173,0.00025370340306410486,25.0,0.0
685.70801,0.15026812007874016,828.4231195402892,0.00025370340306410486,25.0,0.0
687.00928,0.15067573228346456,827.4588089777618,0.00025370340306410486,25.0,0.0
688.31055,0.15107915354330706,829.0166722498519,0.00025370340306410486,25.0,0.0
689.61182,0.15152897047244093,828.6341124024018,0.00025370340306410486,25.0,0.0
690.91309,0.15194634251968503,829.187801169892,0.00025370340306410486,25.0,0.0
692.21436,0.15231206692913385,826.9823743139126,0.00025370340306410486,25.0,0.0
693.51563,0.1527403877952756,829.3973509933776,0.00025370340306410486,25.0,0.0
694.81689,0.1531132086614173,827.5413971706135,0.00025370340306410486,25.0,0.0
696.11816,0.1534933405511811,826.8001906872473,0.00025370340306410486,25.0,0.0
697.41943,0.15384409448818898,828.9207359496999,0.00025370340306410486,25.0,0.0
698.7207,0.15419206496062993,828.944030716108,0.00025370340306410486,25.0,0.0
700.02197,0.15460300787401574,828.8308294895252,0.00025370340306410486,25.0,0.0
701.32324,0.1550629842519685,830.1682686113331,0.00025370340306410486,25.0,0.0
702.62451,0.1554591338582677,830.3224160589585,0.00025370340306410486,25.0,0.0
703.92578,0.1558067401574803,830.0054113948515,0.00025370340306410486,25.0,0.0
705.22705,0.15618466732283465,829.8283041719278,0.00025370340306410486,25.0,0.0
706.52832,0.15657600393700788,829.6656015667278,0.00025370340306410486,25.0,0.0
707.82959,0.1570240492125984,830.9987631097484,0.00025370340306410486,25.0,0.0
709.13086,0.15741770866141733,830.5107068312419,0.00025370340306410486,25.0,0.0
710.43213,0.1578696712598425,831.0568969515809,0.00025370340306410486,25.0,0.0
711.7334,0.1583278523622047,831.4400237070632,0.00025370340306410486,25.0,0.0
713.03467,0.15877621456692914,830.895018939882,0.00025370340306410486,25.0,0.0
714.33594,0.15922140748031496,831.562321230706,0.00025370340306410486,25.0,0.0
715.63721,0.15967132677165352,831.1657948308296,0.00025370340306410486,25.0,0.0
716.93848,0.16008865354330706,828.8429922436675,0.00025370340306410486,25.0,0.0
718.23975,0.1604545531496063,830.4122452134925,0.00025370340306410486,25.0,0.0
719.54102,0.16082626181102364,831.3294251037186,0.00025370340306410486,25.0,0.0
720.84229,0.16123833070866142,831.6095807457418,0.00025370340306410486,25.0,0.0
722.14355,0.1616793464566929,832.5920581338419,0.00025370340306410486,25.0,0.0
723.44482,0.1620964625984252,830.7096915504935,0.00025370340306410486,25.0,0.0
724.74609,0.16247734448818899,831.06099415054,0.00025370340306410486,25.0,0.0
726.04736,0.16289135039370078,831.425258329683,0.00025370340306410486,25.0,0.0
727.34863,0.16329017519685038,832.4541706393177,0.00025370340306410486,25.0,0.0
728.6499,0.16365018503937007,830.3049192156055,0.00025370340306410486,25.0,0.0
729.95117,0.16403394094488188,831.4702244440437,0.00025370340306410486,25.0,0.0
731.25244,0.16444219881889763,832.0260520009277,0.00025370340306410486,25.0,0.0
732.55371,0.16482674212598425,832.0477491174274,0.00025370340306410486,25.0,0.0
733.85498,0.16519138582677165,832.4114463885383,0.00025370340306410486,25.0,0.0
735.15625,0.16563171062992124,832.2864431674698,0.00025370340306410486,25.0,0.0
736.45752,0.16606646062992125,833.41268327879,0.00025370340306410486,25.0,0.0
737.75879,0.16655141732283463,830.8560311284048,0.00025370340306410486,25.0,0.0
739.06006,0.16699025,832.8756667611515,0.00025370340306410486,25.0,0.0
740.36133,0.16738619881889763,832.205040327776,0.00025370340306410486,25.0,0.0
741.6626,0.16777189173228346,832.3421805344398,0.00025370340306410486,25.0,0.0
742.96387,0.1682052933070866,832.7806838972351,0.00025370340306410486,25.0,0.0
744.26514,0.16866948228346457,833.512149869869,0.00025370340306410486,25.0,0.0
745.56641,0.16911154133858267,833.4796299636664,0.00025370340306410486,25.0,0.0
746.86768,0.16953241141732284,832.4479346509652,0.00025370340306410486,25.0,0.0
748.16895,0.16993006102362204,833.5753085783493,0.00025370340306410486,25.0,0.0
749.47021,0.1703736122047244,833.4873089906462,0.00025370340306410486,25.0,0.0
750.77148,0.1708588031496063,833.5849975519882,0.00025370340306410486,25.0,0.0
752.07275,0.17128998622047245,832.466616847476,0.00025370340306410486,25.0,0.0
753.37402,0.1718357086614173,834.0297884402299,0.00025370340306410486,25.0,0.0
754.67529,0.17217301574803148,831.112582781457,0.00025370340306410486,25.0,0.0
755.97656,0.1725646338582677,833.3242971628831,0.00025370340306410486,25.0,0.0
757.27783,0.17304481496062993,835.3475403921974,0.00025370340306410486,25.0,0.0
758.5791,0.17348756692913386,833.1093359445462,0.00025370340306410486,25.0,0.0
759.88037,0.1739250157480315,834.0111062437189,0.00025370340306410486,25.0,0.0
761.18164,0.17438110826771652,833.7140979720155,0.00025370340306410486,25.0,0.0
762.48291,0.17477015748031496,833.0467956811916,0.00025370340306410486,25.0,0.0
763.78418,0.1751675846456693,833.1428608240782,0.00025370340306410486,25.0,0.0
765.08545,0.17555622440944882,833.0890818666736,0.00025370340306410486,25.0,0.0
766.38672,0.17596286023622046,834.1149019506792,0.00025370340306410486,25.0,0.0
767.68799,0.17641792125984251,834.2416832014843,0.00025370340306410486,25.0,0.0
768.98926,0.17689417125984253,835.2766253510965,0.00025370340306410486,25.0,0.0
770.29053,0.17726062401574805,833.8289741541475,0.00025370340306410486,25.0,0.0
771.5918,0.17774041732283466,834.4508464967662,0.00025370340306410486,25.0,0.0
772.89307,0.17819774212598427,834.8775220965291,0.00025370340306410486,25.0,0.0
774.19434,0.17861786023622048,833.198340505579,0.00025370340306410486,25.0,0.0
775.49561,0.17910748622047243,834.1643002551087,0.00025370340306410486,25.0,0.0
776.79688,0.1795489251968504,833.7645527868684,0.00025370340306410486,25.0,0.0
778.09814,0.18004898228346455,833.0703739016158,0.00025370340306410486,25.0,0.0
779.39941,0.18048366141732283,834.5534053134745,0.00025370340306410486,25.0,0.0
780.70068,0.18095161811023622,834.378565722679,0.00025370340306410486,25.0,0.0
782.00195,0.1814360334645669,834.7012394671066,0.00025370340306410486,25.0,0.0
783.30322,0.18191235433070865,833.8250057979232,0.00025370340306410486,25.0,0.0
784.60449,0.18235913188976377,835.295745612905,0.00025370340306410486,25.0,0.0
785.90576,0.18283137007874015,833.6234442239803,0.00025370340306410486,25.0,0.0
787.20703,0.18327683267716535,835.2800783363826,0.00025370340306410486,25.0,0.0
788.5083,0.18365814960629923,834.5155770866082,0.00025370340306410486,25.0,0.0
789.70947,0.18413854133858268,837.5111191279924,0.00025370340306410486,25.0,0.0