File: datasets/am_bench_2022/csv/0-XY.10-2.csv
Time(s),Strain(%),Stress(MPa),SR(s-1),Temp(C),Angle(deg)
16.368896,1.7652500787401573e-06,24.815656452922074,0.00025370340306410486,25.0,0.0
18.37085,1.9861600393700788e-05,33.385168932629874,0.00025370340306410486,25.0,0.0
19.772217,2.7255419291338583e-05,35.70378196022727,0.00025370340306410486,25.0,0.0
21.073486,5.1100013779527556e-05,39.54248427353896,0.00025370340306410486,25.0,0.0
22.374756,5.570824409448819e-05,45.345117187499994,0.00025370340306410486,25.0,0.0
23.676025,8.627148228346456e-05,51.28498630275974,0.00025370340306410486,25.0,0.0
24.977295,9.552283267716535e-05,57.50146103896104,0.00025370340306410486,25.0,0.0
26.278564,0.00013745328937007873,65.15044642857143,0.00025370340306410486,25.0,0.0
27.579834,0.00016389107086614172,70.8272245332792,0.00025370340306410486,25.0,0.0
28.881104,0.00016958607283464568,78.07947696834415,0.00025370340306410486,25.0,0.0
30.182373,0.00019398564566929134,84.26996753246752,0.00025370340306410486,25.0,0.0
31.483643,0.0002289746062992126,89.59206574675325,0.00025370340306410486,25.0,0.0
32.784912,0.0002871767519685039,96.96665482954545,0.00025370340306410486,25.0,0.0
34.086182,0.0002737065748031496,105.27100750811688,0.00025370340306410486,25.0,0.0
35.387451,0.00034540389763779524,111.8623427353896,0.00025370340306410486,25.0,0.0
36.688721,0.0003504116338582677,120.11891741071429,0.00025370340306410486,25.0,0.0
37.98999,0.0003837792125984252,127.96431361607142,0.00025370340306410486,25.0,0.0
39.29126,0.00040744171259842523,138.7044516030844,0.00025370340306410486,25.0,0.0
40.592529,0.00042095464566929133,144.48116375811688,0.00025370340306410486,25.0,0.0
41.893799,0.0004875740354330708,154.03357345779222,0.00025370340306410486,25.0,0.0
43.195068,0.0004881838385826772,161.4463651582792,0.00025370340306410486,25.0,0.0
44.496338,0.000540739409448819,170.00141030844156,0.00025370340306410486,25.0,0.0
45.797607,0.0005818500984251969,175.7584288758117,0.00025370340306410486,25.0,0.0
47.098877,0.0006030109251968504,185.1246271306818,0.00025370340306410486,25.0,0.0
48.400146,0.0006048654527559055,194.46360592532466,0.00025370340306410486,25.0,0.0
49.701416,0.0006562263385826772,202.58917410714284,0.00025370340306410486,25.0,0.0
51.002686,0.0006992094488188976,210.19883066152596,0.00025370340306410486,25.0,0.0
52.303955,0.0007201734645669291,218.87966467126623,0.00025370340306410486,25.0,0.0
53.605225,0.0007847536614173227,229.345018262987,0.00025370340306410486,25.0,0.0
54.906494,0.0008231969488188976,239.7666801948052,0.00025370340306410486,25.0,0.0
56.207764,0.0008440174015748032,248.2505275974026,0.00025370340306410486,25.0,0.0
57.509033,0.0008742230511811024,257.13605925324674,0.00025370340306410486,25.0,0.0
58.810303,0.000929577716535433,266.76265726461037,0.00025370340306410486,25.0,0.0
60.111572,0.0009806134645669292,275.3247514204545,0.00025370340306410486,25.0,0.0
61.412842,0.0010069375393700786,284.22526887175326,0.00025370340306410486,25.0,0.0
62.714111,0.001018832342519685,293.38557731331167,0.00025370340306410486,25.0,0.0
64.015381,0.001062183287401575,303.14389711850646,0.00025370340306410486,25.0,0.0
65.31665,0.0011270990551181103,311.9867593344156,0.00025370340306410486,25.0,0.0
66.61792,0.0011593788188976376,322.9647676542208,0.00025370340306410486,25.0,0.0
67.919189,0.001204643838582677,330.2049512987013,0.00025370340306410486,25.0,0.0
69.220459,0.0012016747047244095,341.1094764610389,0.00025370340306410486,25.0,0.0
70.521729,0.0012495153543307085,351.09676846590907,0.00025370340306410486,25.0,0.0
71.822998,0.001309859744094488,361.42915482954544,0.00025370340306410486,25.0,0.0
73.124268,0.001328820039370079,368.95271915584414,0.00025370340306410486,25.0,0.0
74.425537,0.001389134625984252,377.55623478084414,0.00025370340306410486,25.0,0.0
75.726807,0.0013937567716535433,387.3871245941558,0.00025370340306410486,25.0,0.0
77.028076,0.0014563915157480315,395.0044135551948,0.00025370340306410486,25.0,0.0
78.329346,0.0015010248818897638,405.34068080357144,0.00025370340306410486,25.0,0.0
79.630615,0.0015160222047244094,414.9533025568182,0.00025370340306410486,25.0,0.0
80.931885,0.0015860632480314961,424.4424462256493,0.00025370340306410486,25.0,0.0
82.233154,0.0016142718700787402,432.775289163961,0.00025370340306410486,25.0,0.0
83.534424,0.0016416333267716536,439.7714336444805,0.00025370340306410486,25.0,0.0
84.835693,0.0017137871653543305,450.0687398538961,0.00025370340306410486,25.0,0.0
86.136963,0.0017553578937007876,458.2288707386364,0.00025370340306410486,25.0,0.0
87.438232,0.0017865113582677162,467.7073609983766,0.00025370340306410486,25.0,0.0
88.739502,0.0017986376181102362,476.46210430194805,0.00025370340306410486,25.0,0.0
90.040771,0.001857046220472441,483.97803368506493,0.00025370340306410486,25.0,0.0
91.342041,0.0019107263188976376,489.98739346590907,0.00025370340306410486,25.0,0.0
92.643311,0.0019790751968503935,500.5536221590909,0.00025370340306410486,25.0,0.0
93.94458,0.0019980555118110236,507.4025213068182,0.00025370340306410486,25.0,0.0
95.24585,0.002053939566929134,513.4430549918831,0.00025370340306410486,25.0,0.0
96.547119,0.0021147736220472444,523.3879109172078,0.00025370340306410486,25.0,0.0
97.848389,0.0021647826771653543,529.9950791396104,0.00025370340306410486,25.0,0.0
99.149658,0.0022282925196850396,534.6025010146104,0.00025370340306410486,25.0,0.0
100.45093,0.0022505503937007873,543.6516335227273,0.00025370340306410486,25.0,0.0
101.7522,0.0022727517716535435,548.7965959821428,0.00025370340306410486,25.0,0.0
103.05347,0.00234291062992126,554.1338778409091,0.00025370340306410486,25.0,0.0
104.35474,0.0024084033464566927,560.0352069805194,0.00025370340306410486,25.0,0.0
105.65601,0.002460929724409449,566.9775771103896,0.00025370340306410486,25.0,0.0
106.95728,0.002478599409448819,571.9903865665584,0.00025370340306410486,25.0,0.0
108.25854,0.002560706496062992,579.2869318181818,0.00025370340306410486,25.0,0.0
109.55981,0.0026074911417322834,581.9807477678571,0.00025370340306410486,25.0,0.0
110.86108,0.0026737994094488187,589.8857802353896,0.00025370340306410486,25.0,0.0
112.16235,0.0027539622047244093,594.7071580762987,0.00025370340306410486,25.0,0.0
113.46362,0.002788728937007874,599.2979910714286,0.00025370340306410486,25.0,0.0
114.76489,0.0028553265748031496,603.5610795454546,0.00025370340306410486,25.0,0.0
116.06616,0.002886580905511811,605.7232650162338,0.00025370340306410486,25.0,0.0
117.36743,0.0029820009842519684,611.246778612013,0.00025370340306410486,25.0,0.0
118.6687,0.0030300683070866143,617.1182528409091,0.00025370340306410486,25.0,0.0
119.96997,0.0031060238188976375,620.6912540584415,0.00025370340306410486,25.0,0.0
121.27124,0.003172361220472441,623.7332335633117,0.00025370340306410486,25.0,0.0
122.57251,0.00326663562992126,628.5251369724026,0.00025370340306410486,25.0,0.0
123.87378,0.0033498954724409447,630.9950284090909,0.00025370340306410486,25.0,0.0
125.17505,0.003433836220472441,637.0695515422078,0.00025370340306410486,25.0,0.0
126.47632,0.0035260466535433073,641.2878196022727,0.00025370340306410486,25.0,0.0
127.77759,0.00360422342519685,642.5666852678571,0.00025370340306410486,25.0,0.0
129.07886,0.0036935501968503935,647.3440290178571,0.00025370340306410486,25.0,0.0
130.38013,0.0038146763779527562,651.3384486607142,0.00025370340306410486,25.0,0.0
131.6814,0.003926051181102362,654.0588220373376,0.00025370340306410486,25.0,0.0
132.98267,0.004055520078740158,656.2102272727273,0.00025370340306410486,25.0,0.0
134.28394,0.004113491929133858,658.0561586850649,0.00025370340306410486,25.0,0.0
135.58521,0.004258003149606299,662.0227019074674,0.00025370340306410486,25.0,0.0
136.88647,0.004405950984251969,663.241604099026,0.00025370340306410486,25.0,0.0
138.18774,0.004524055511811023,665.8044338474026,0.00025370340306410486,25.0,0.0
139.48901,0.004637025393700787,670.0627790178571,0.00025370340306410486,25.0,0.0
140.79028,0.004807971850393701,672.4013798701299,0.00025370340306410486,25.0,0.0
142.09155,0.004964782283464567,672.5020292207791,0.00025370340306410486,25.0,0.0
143.39282,0.005133638779527559,677.1202820616883,0.00025370340306410486,25.0,0.0
144.69409,0.005314085826771653,677.6656097808442,0.00025370340306410486,25.0,0.0
145.99536,0.005450123228346457,677.4466314935065,0.00025370340306410486,25.0,0.0
147.29663,0.005617401968503937,681.5736860795454,0.00025370340306410486,25.0,0.0
148.5979,0.005832675984251968,684.0629819399351,0.00025370340306410486,25.0,0.0
149.89917,0.006062835433070866,687.0933695211038,0.00025370340306410486,25.0,0.0
151.20044,0.006280604724409448,687.5281554383116,0.00025370340306410486,25.0,0.0
152.50171,0.006464455118110237,688.9527698863636,0.00025370340306410486,25.0,0.0
153.80298,0.006696575984251969,690.7926897321429,0.00025370340306410486,25.0,0.0
155.10425,0.006952221062992125,693.9508928571428,0.00025370340306410486,25.0,0.0
156.40552,0.007180607086614173,693.603312702922,0.00025370340306410486,25.0,0.0
157.70679,0.007444648031496063,694.567573051948,0.00025370340306410486,25.0,0.0
159.00806,0.0077235131889763775,697.222757711039,0.00025370340306410486,25.0,0.0
160.30933,0.00797113996062992,697.1480570211038,0.00025370340306410486,25.0,0.0
161.6106,0.008246423622047243,699.8032924107143,0.00025370340306410486,25.0,0.0
162.91187,0.008580205118110236,702.0322392451297,0.00025370340306410486,25.0,0.0
164.21313,0.008823322244094487,702.6165280032467,0.00025370340306410486,25.0,0.0
165.5144,0.009093407283464567,703.9778053977273,0.00025370340306410486,25.0,0.0
166.81567,0.00936734153543307,705.8000456574675,0.00025370340306410486,25.0,0.0
168.11694,0.0097205781496063,706.9956118100649,0.00025370340306410486,25.0,0.0
169.41821,0.010030465157480314,706.4046519886364,0.00025370340306410486,25.0,0.0
170.71948,0.010289282677165355,707.2459161931818,0.00025370340306410486,25.0,0.0
172.02075,0.01060859783464567,708.9193131087662,0.00025370340306410486,25.0,0.0
173.32202,0.010906863779527558,710.8354048295455,0.00025370340306410486,25.0,0.0
174.62329,0.011232611811023623,711.0130123782467,0.00025370340306410486,25.0,0.0
175.92456,0.011522861811023622,712.7295556006493,0.00025370340306410486,25.0,0.0
177.22583,0.011849949803149606,713.3461596996754,0.00025370340306410486,25.0,0.0
178.5271,0.01217427874015748,715.5432731331169,0.00025370340306410486,25.0,0.0
179.82837,0.012494801181102362,713.1824269480519,0.00025370340306410486,25.0,0.0
181.12964,0.012854906102362205,715.3465148133116,0.00025370340306410486,25.0,0.0
182.43091,0.01322521318897638,717.5295758928571,0.00025370340306410486,25.0,0.0
183.73218,0.013556611614173228,717.0908837256493,0.00025370340306410486,25.0,0.0
185.03345,0.013916767913385825,719.740919237013,0.00025370340306410486,25.0,0.0
186.33472,0.014286134842519687,719.747843952922,0.00025370340306410486,25.0,0.0
187.63599,0.014663559448818897,720.3212256493507,0.00025370340306410486,25.0,0.0
188.93726,0.01494445807086614,721.5251623376623,0.00025370340306410486,25.0,0.0
190.23853,0.015315189173228345,721.2559608360389,0.00025370340306410486,25.0,0.0
191.53979,0.015684602952755904,722.2179890422077,0.00025370340306410486,25.0,0.0
192.84106,0.016009499606299212,721.7252435064935,0.00025370340306410486,25.0,0.0
194.14233,0.016398172047244093,723.9430803571428,0.00025370340306410486,25.0,0.0
195.4436,0.016790505314960628,724.5692978896103,0.00025370340306410486,25.0,0.0
196.74487,0.017170363188976377,725.5810673701299,0.00025370340306410486,25.0,0.0
198.04614,0.017611148622047244,727.3661728896104,0.00025370340306410486,25.0,0.0
199.34741,0.01796104724409449,727.962205762987,0.00025370340306410486,25.0,0.0
200.64868,0.01830643877952756,728.6152851055195,0.00025370340306410486,25.0,0.0
201.94995,0.018682583070866142,727.9411018668831,0.00025370340306410486,25.0,0.0
203.25122,0.019073932283464566,728.0685876623376,0.00025370340306410486,25.0,0.0
204.55249,0.019382117913385826,728.1382153003246,0.00025370340306410486,25.0,0.0
205.85376,0.01973292125984252,729.681057224026,0.00025370340306410486,25.0,0.0
207.15503,0.020111602362204724,729.4906909496754,0.00025370340306410486,25.0,0.0
208.4563,0.020518106299212597,730.4441203327923,0.00025370340306410486,25.0,0.0
209.75757,0.020898692913385825,731.5670911120129,0.00025370340306410486,25.0,0.0
211.05884,0.02123061811023622,730.8743912337661,0.00025370340306410486,25.0,0.0
212.36011,0.021553153543307085,733.9062753652597,0.00025370340306410486,25.0,0.0
213.66138,0.021952649606299213,733.5726714691558,0.00025370340306410486,25.0,0.0
214.96265,0.022326419291338582,734.3327414772726,0.00025370340306410486,25.0,0.0
216.26392,0.022699326771653542,733.5155742694805,0.00025370340306410486,25.0,0.0
217.56519,0.023042496062992125,734.1491984577922,0.00025370340306410486,25.0,0.0
218.86646,0.023360826771653544,735.1232497970778,0.00025370340306410486,25.0,0.0
220.16772,0.02378505905511811,737.0384030032468,0.00025370340306410486,25.0,0.0
221.46899,0.02421179133858268,735.7448001217532,0.00025370340306410486,25.0,0.0
222.77026,0.024581263779527556,735.6703784496754,0.00025370340306410486,25.0,0.0
224.07153,0.02496067125984252,738.2646864853896,0.00025370340306410486,25.0,0.0
225.3728,0.025355332677165356,737.6039214691558,0.00025370340306410486,25.0,0.0
226.67407,0.025785816929133856,738.7267146915584,0.00025370340306410486,25.0,0.0
227.97534,0.026177515748031493,740.035054788961,0.00025370340306410486,25.0,0.0
229.27661,0.026577576771653545,739.2588017451299,0.00025370340306410486,25.0,0.0
230.57788,0.0269725531496063,740.8251065340909,0.00025370340306410486,25.0,0.0
231.87915,0.027308417322834646,739.9083299512987,0.00025370340306410486,25.0,0.0
233.18042,0.02769200787401575,741.6178469967532,0.00025370340306410486,25.0,0.0
234.48169,0.028099970472440946,740.8415178571429,0.00025370340306410486,25.0,0.0
235.78296,0.028456108267716537,742.7088575487013,0.00025370340306410486,25.0,0.0
237.08423,0.02878715748031496,743.4261109983767,0.00025370340306410486,25.0,0.0
238.3855,0.029170545275590553,743.2755681818181,0.00025370340306410486,25.0,0.0
239.68677,0.029549562992125984,742.3692674512987,0.00025370340306410486,25.0,0.0
240.98804,0.029977759842519682,745.5179839691558,0.00025370340306410486,25.0,0.0
242.28931,0.030401175196850396,743.1432122564935,0.00025370340306410486,25.0,0.0
243.59058,0.030809387795275592,744.0160815746752,0.00025370340306410486,25.0,0.0
244.89185,0.031231950787401572,744.5914924918831,0.00025370340306410486,25.0,0.0
246.19312,0.031570844488188976,745.3193232548701,0.00025370340306410486,25.0,0.0
247.49438,0.03193317125984252,745.8067674512987,0.00025370340306410486,25.0,0.0
248.79565,0.03234511811023622,744.7605012175324,0.00025370340306410486,25.0,0.0
250.09692,0.032667850393700786,745.2917765827922,0.00025370340306410486,25.0,0.0
251.39819,0.03302323228346457,745.7886820211038,0.00025370340306410486,25.0,0.0
252.69946,0.033412809055118106,747.300197849026,0.00025370340306410486,25.0,0.0
254.00073,0.03386284448818897,747.1326603084416,0.00025370340306410486,25.0,0.0
255.302,0.034271976377952755,748.6121144480519,0.00025370340306410486,25.0,0.0
256.60327,0.03459405708661417,749.7322443181818,0.00025370340306410486,25.0,0.0
257.90454,0.03497282086614173,749.9041446834415,0.00025370340306410486,25.0,0.0
259.20581,0.035302257874015745,749.7156554383117,0.00025370340306410486,25.0,0.0
260.50708,0.035661255905511814,749.8738585633117,0.00025370340306410486,25.0,0.0
261.80835,0.036075393700787405,751.152546672078,0.00025370340306410486,25.0,0.0
263.10962,0.03657736417322835,751.1226156655845,0.00025370340306410486,25.0,0.0
264.41089,0.036940903543307084,751.7541599025974,0.00025370340306410486,25.0,0.0
265.71216,0.03740100590551181,751.1983563311687,0.00025370340306410486,25.0,0.0
267.01343,0.03775196653543307,751.7423904220778,0.00025370340306410486,25.0,0.0
268.3147,0.038061925196850394,751.9420403814935,0.00025370340306410486,25.0,0.0
269.61597,0.038431622047244096,753.3074776785713,0.00025370340306410486,25.0,0.0
270.91724,0.03882607874015748,754.9253754058441,0.00025370340306410486,25.0,0.0
272.21851,0.03924394488188976,754.4816101866883,0.00025370340306410486,25.0,0.0
273.51978,0.039701881889763785,753.6293628246754,0.00025370340306410486,25.0,0.0
274.82104,0.04017935039370078,755.7722199675325,0.00025370340306410486,25.0,0.0
276.12231,0.04059702362204724,754.4685978084415,0.00025370340306410486,25.0,0.0
277.42358,0.040903027559055116,754.8907518262986,0.00025370340306410486,25.0,0.0
278.72485,0.041311533464566924,757.9887124594155,0.00025370340306410486,25.0,0.0
280.02612,0.04169989566929134,757.2972301136364,0.00025370340306410486,25.0,0.0
281.32739,0.04210628740157481,757.1972148944806,0.00025370340306410486,25.0,0.0
282.62866,0.04246971062992126,757.0227780032468,0.00025370340306410486,25.0,0.0
283.92993,0.04281868897637795,756.0881189123377,0.00025370340306410486,25.0,0.0
285.2312,0.043177305118110236,756.8288859577922,0.00025370340306410486,25.0,0.0
286.53247,0.04358049606299212,760.2571530032467,0.00025370340306410486,25.0,0.0
287.83374,0.04395538582677165,758.7210582386364,0.00025370340306410486,25.0,0.0
289.13501,0.04427797834645669,757.3958248782467,0.00025370340306410486,25.0,0.0
290.43628,0.04462993110236221,759.0187956574675,0.00025370340306410486,25.0,0.0
291.73755,0.04494995078740157,760.228414163961,0.00025370340306410486,25.0,0.0
293.03882,0.045346454724409443,758.6583806818181,0.00025370340306410486,25.0,0.0
294.34009,0.04569521653543307,760.4157366071428,0.00025370340306410486,25.0,0.0
295.64136,0.046031889763779525,760.3454494724026,0.00025370340306410486,25.0,0.0
296.94263,0.04644795472440945,761.9597199675324,0.00025370340306410486,25.0,0.0
298.2439,0.04686964960629921,763.6735998376623,0.00025370340306410486,25.0,0.0
299.54517,0.04730838188976378,761.6602323457791,0.00025370340306410486,25.0,0.0
300.84644,0.04767568503937008,762.6881594967533,0.00025370340306410486,25.0,0.0
302.14771,0.04807803543307087,763.7539823457793,0.00025370340306410486,25.0,0.0
303.44897,0.048470511811023624,764.5490564123376,0.00025370340306410486,25.0,0.0
304.75024,0.04886029527559055,764.1350700081168,0.00025370340306410486,25.0,0.0
306.05151,0.04928045669291339,764.6025010146103,0.00025370340306410486,25.0,0.0
307.35278,0.04964306692913386,763.6126724837662,0.00025370340306410486,25.0,0.0
308.65405,0.050015748031496055,765.468547077922,0.00025370340306410486,25.0,0.0
309.95532,0.0504521279527559,765.3536678165584,0.00025370340306410486,25.0,0.0
311.25659,0.05085891929133859,764.8821530032467,0.00025370340306410486,25.0,0.0
312.55786,0.05126582086614174,764.7190543831168,0.00025370340306410486,25.0,0.0
313.85913,0.05156272834645669,764.2744774756493,0.00025370340306410486,25.0,0.0
315.1604,0.05200424212598425,767.4063768262987,0.00025370340306410486,25.0,0.0
316.46167,0.05235095275590551,766.4688007305194,0.00025370340306410486,25.0,0.0
317.76294,0.05272806889763779,768.795023336039,0.00025370340306410486,25.0,0.0
319.06421,0.053113188976377956,766.5512885551948,0.00025370340306410486,25.0,0.0
320.36548,0.053523998031496066,769.193942775974,0.00025370340306410486,25.0,0.0
321.66675,0.053908645669291336,769.212205762987,0.00025370340306410486,25.0,0.0
322.96802,0.05422617716535433,767.0330762987013,0.00025370340306410486,25.0,0.0
324.26929,0.054576277559055114,769.9627130681819,0.00025370340306410486,25.0,0.0
325.57056,0.054943169291338585,768.4512479707791,0.00025370340306410486,25.0,0.0
326.87183,0.055369653543307085,770.0618405032467,0.00025370340306410486,25.0,0.0
328.1731,0.055695253937007874,769.9333654626623,0.00025370340306410486,25.0,0.0
329.47437,0.05611214173228347,770.6598772321428,0.00025370340306410486,25.0,0.0
330.77563,0.05650656496062992,770.6750456574675,0.00025370340306410486,25.0,0.0
332.0769,0.05695194488188977,770.1518871753246,0.00025370340306410486,25.0,0.0
333.37817,0.057334289370078735,772.0503246753246,0.00025370340306410486,25.0,0.0
334.67944,0.05770691732283464,770.4203530844155,0.00025370340306410486,25.0,0.0
335.98071,0.05808069094488189,772.4906148538961,0.00025370340306410486,25.0,0.0
337.28198,0.05848142519685039,771.921773538961,0.00025370340306410486,25.0,0.0
338.58325,0.05885735236220472,771.1728896103896,0.00025370340306410486,25.0,0.0
339.88452,0.05925612795275591,773.3908532873376,0.00025370340306410486,25.0,0.0
341.18579,0.0596291968503937,772.4332132711038,0.00025370340306410486,25.0,0.0
342.48706,0.06000027559055118,773.2720931412338,0.00025370340306410486,25.0,0.0
343.78833,0.06034856496062992,774.274807224026,0.00025370340306410486,25.0,0.0
345.0896,0.06078915157480315,775.2588271103896,0.00025370340306410486,25.0,0.0
346.39087,0.061197889763779524,773.2678825081169,0.00025370340306410486,25.0,0.0
347.69214,0.061597088582677165,776.0268871753246,0.00025370340306410486,25.0,0.0
348.99341,0.06193287992125985,774.6531808035713,0.00025370340306410486,25.0,0.0
350.29468,0.06230817913385826,775.128703327922,0.00025370340306410486,25.0,0.0
351.59595,0.06265704724409449,776.2226562499999,0.00025370340306410486,25.0,0.0
352.89722,0.06303237598425197,779.1886921672078,0.00025370340306410486,25.0,0.0
354.19849,0.06342252755905511,778.4006189123376,0.00025370340306410486,25.0,0.0
355.49976,0.06380425,776.8623427353896,0.00025370340306410486,25.0,0.0
356.80103,0.06418187007874016,776.9098011363636,0.00025370340306410486,25.0,0.0
358.10229,0.06451708267716535,777.9047027191558,0.00025370340306410486,25.0,0.0
359.40356,0.06492192519685039,778.5026633522727,0.00025370340306410486,25.0,0.0
360.70483,0.0653232125984252,779.7272219967532,0.00025370340306410486,25.0,0.0
362.0061,0.06567074409448818,780.6273843344155,0.00025370340306410486,25.0,0.0
363.30737,0.0660458188976378,777.9744318181819,0.00025370340306410486,25.0,0.0
364.60864,0.06639495669291338,779.0842380275973,0.00025370340306410486,25.0,0.0
365.90991,0.06674082874015748,780.4630935470778,0.00025370340306410486,25.0,0.0
367.21118,0.06705325984251968,779.535359172078,0.00025370340306410486,25.0,0.0
368.51245,0.06745525196850394,781.1063818993506,0.00025370340306410486,25.0,0.0
369.81372,0.06787256496062992,782.9378297483767,0.00025370340306410486,25.0,0.0
371.11499,0.06825743307086614,781.2350091314935,0.00025370340306410486,25.0,0.0
372.41626,0.06864903346456694,782.1178977272727,0.00025370340306410486,25.0,0.0
373.71753,0.06904156102362205,781.6181513798701,0.00025370340306410486,25.0,0.0
375.0188,0.06941101771653543,782.4565239448052,0.00025370340306410486,25.0,0.0
376.32007,0.06981368897637795,782.4438920454545,0.00025370340306410486,25.0,0.0
377.62134,0.07019848425196851,784.1897321428571,0.00025370340306410486,25.0,0.0
378.92261,0.07052711417322835,782.7541345373377,0.00025370340306410486,25.0,0.0
380.22388,0.07088641338582677,782.0178825081169,0.00025370340306410486,25.0,0.0
381.52515,0.07134251181102362,784.9125405844155,0.00025370340306410486,25.0,0.0
382.82642,0.07177454133858267,783.3477069805194,0.00025370340306410486,25.0,0.0
384.12769,0.07215774015748032,784.8851714691558,0.00025370340306410486,25.0,0.0
385.42896,0.07255395866141733,784.6648234577922,0.00025370340306410486,25.0,0.0
386.73022,0.07293214370078739,784.9535308441558,0.00025370340306410486,25.0,0.0
388.03149,0.07329503937007874,784.5986962256493,0.00025370340306410486,25.0,0.0
389.33276,0.07363499803149606,783.9915026379871,0.00025370340306410486,25.0,0.0
390.63403,0.07405008858267716,786.8811891233767,0.00025370340306410486,25.0,0.0
391.9353,0.07436395078740157,785.6707081980519,0.00025370340306410486,25.0,0.0
393.23657,0.07470635039370079,786.4236759334415,0.00025370340306410486,25.0,0.0
394.53784,0.07502434251968504,786.1622362012987,0.00025370340306410486,25.0,0.0
395.83911,0.07540862204724409,786.7163403003246,0.00025370340306410486,25.0,0.0
397.14038,0.07575041732283463,786.8316000405844,0.00025370340306410486,25.0,0.0
398.44165,0.07610761614173228,787.5458096590909,0.00025370340306410486,25.0,0.0
399.74292,0.07648762007874016,788.9642349837662,0.00025370340306410486,25.0,0.0
401.04419,0.07684371653543307,787.480950689935,0.00025370340306410486,25.0,0.0
402.34546,0.07720327952755907,787.8769784902597,0.00025370340306410486,25.0,0.0
403.64673,0.07759068700787401,788.999416599026,0.00025370340306410486,25.0,0.0
404.948,0.07795974212598425,789.1508218344156,0.00025370340306410486,25.0,0.0
406.24927,0.0783510157480315,788.3222402597403,0.00025370340306410486,25.0,0.0
407.55054,0.07870859645669291,790.4686992694806,0.00025370340306410486,25.0,0.0
408.85181,0.07906089763779527,789.6292613636364,0.00025370340306410486,25.0,0.0
410.15308,0.07948088779527558,790.8555448457791,0.00025370340306410486,25.0,0.0
411.45435,0.07989095078740158,790.3209212662338,0.00025370340306410486,25.0,0.0
412.75562,0.08033792125984252,790.5921012581168,0.00025370340306410486,25.0,0.0
414.05688,0.08068781102362205,790.4378551136364,0.00025370340306410486,25.0,0.0
415.35815,0.08102516929133859,789.7086546266233,0.00025370340306410486,25.0,0.0
416.65942,0.08143801377952756,792.6642400568181,0.00025370340306410486,25.0,0.0
417.96069,0.08181124015748031,791.081828327922,0.00025370340306410486,25.0,0.0
419.26196,0.08223206299212597,793.3558492288961,0.00025370340306410486,25.0,0.0
420.56323,0.08262105511811024,792.5068232548701,0.00025370340306410486,25.0,0.0
421.8645,0.08299642322834645,791.7399299918832,0.00025370340306410486,25.0,0.0
423.16577,0.08334275787401575,792.9741274350649,0.00025370340306410486,25.0,0.0
424.46704,0.08369285236220472,794.7683390827922,0.00025370340306410486,25.0,0.0
425.76831,0.08404423818897637,793.5474330357143,0.00025370340306410486,25.0,0.0
427.06958,0.08439411023622047,794.7643821022727,0.00025370340306410486,25.0,0.0
428.37085,0.08468375590551182,792.938768262987,0.00025370340306410486,25.0,0.0
429.67212,0.08500920078740158,793.4588321834415,0.00025370340306410486,25.0,0.0
430.97339,0.08536003543307086,793.1035409902597,0.00025370340306410486,25.0,0.0
432.27466,0.08570358858267715,795.4572088068181,0.00025370340306410486,25.0,0.0
433.57593,0.08609984842519686,794.8345424107142,0.00025370340306410486,25.0,0.0
434.8772,0.08645122244094489,794.6433137175325,0.00025370340306410486,25.0,0.0
436.17847,0.08689053149606299,796.3429383116883,0.00025370340306410486,25.0,0.0
437.47974,0.08724941338582677,794.6810825892857,0.00025370340306410486,25.0,0.0
438.78101,0.08762722244094488,795.7181158685064,0.00025370340306410486,25.0,0.0
440.08228,0.08798355511811023,795.366984577922,0.00025370340306410486,25.0,0.0
441.38354,0.08836982874015747,796.1143212256493,0.00025370340306410486,25.0,0.0
442.68481,0.08874465157480314,796.4009232954546,0.00025370340306410486,25.0,0.0
443.98608,0.08903318307086613,797.1046570616883,0.00025370340306410486,25.0,0.0
445.28735,0.08940826377952756,798.3284547483767,0.00025370340306410486,25.0,0.0
446.58862,0.08983148031496063,797.7481229707791,0.00025370340306410486,25.0,0.0
447.88989,0.09019566732283464,797.5003043831168,0.00025370340306410486,25.0,0.0
449.19116,0.0905811437007874,798.0574523133116,0.00025370340306410486,25.0,0.0
450.49243,0.09099391732283466,798.3032416801948,0.00025370340306410486,25.0,0.0
451.7937,0.0913878188976378,799.3784243100649,0.00025370340306410486,25.0,0.0
453.09497,0.09175164763779527,798.3218851461039,0.00025370340306410486,25.0,0.0
454.39624,0.09207311417322835,799.1420961850649,0.00025370340306410486,25.0,0.0
455.69751,0.09245691141732283,800.095601663961,0.00025370340306410486,25.0,0.0
456.99878,0.09280244291338582,799.1723823051948,0.00025370340306410486,25.0,0.0
458.30005,0.0931853503937008,800.892476663961,0.00025370340306410486,25.0,0.0
459.60132,0.09356667322834646,800.2119521103896,0.00025370340306410486,25.0,0.0
460.90259,0.09397039566929134,801.5877130681818,0.00025370340306410486,25.0,0.0
462.20386,0.0943375905511811,800.3151887175325,0.00025370340306410486,25.0,0.0
463.50513,0.09470024015748033,801.6019176136364,0.00025370340306410486,25.0,0.0
464.8064,0.09503067125984252,801.4549005681818,0.00025370340306410486,25.0,0.0
466.10767,0.09536360039370079,800.5485237418831,0.00025370340306410486,25.0,0.0
467.40894,0.09572705511811024,802.1897067775974,0.00025370340306410486,25.0,0.0
468.71021,0.09606906496062992,801.6627181412338,0.00025370340306410486,25.0,0.0
470.01147,0.0965099468503937,803.8152901785714,0.00025370340306410486,25.0,0.0
471.31274,0.09686618897637796,802.0199117288961,0.00025370340306410486,25.0,0.0
472.61401,0.09724217322834645,804.1514306006493,0.00025370340306410486,25.0,0.0
473.91528,0.0976841220472441,804.8078581574675,0.00025370340306410486,25.0,0.0
475.21655,0.09804302362204724,802.8550629058441,0.00025370340306410486,25.0,0.0
476.51782,0.09846138188976376,803.1080813717532,0.00025370340306410486,25.0,0.0
477.81909,0.09880416732283465,804.4888139204545,0.00025370340306410486,25.0,0.0
479.12036,0.09923662992125985,805.7082234172078,0.00025370340306410486,25.0,0.0
480.42163,0.0996352066929134,805.6940949675324,0.00025370340306410486,25.0,0.0
481.7229,0.10007186811023622,805.8189427759739,0.00025370340306410486,25.0,0.0
483.02417,0.10049547244094488,805.6775060876623,0.00025370340306410486,25.0,0.0
484.32544,0.10086863582677165,805.2069805194805,0.00025370340306410486,25.0,0.0
485.62671,0.10130728149606298,805.669135551948,0.00025370340306410486,25.0,0.0
486.92798,0.10161674409448819,805.6204088879871,0.00025370340306410486,25.0,0.0
488.22925,0.10198827559055118,805.1976207386363,0.00025370340306410486,25.0,0.0
489.53052,0.1023507027559055,805.8606686282467,0.00025370340306410486,25.0,0.0
490.83179,0.1026847342519685,806.2694551542207,0.00025370340306410486,25.0,0.0
492.13306,0.10304561220472441,804.9904119318181,0.00025370340306410486,25.0,0.0
493.43433,0.10342329330708662,807.7641791801948,0.00025370340306410486,25.0,0.0
494.7356,0.10382874606299212,808.5198102678571,0.00025370340306410486,25.0,0.0
496.03687,0.10423371653543308,808.163859577922,0.00025370340306410486,25.0,0.0
497.33813,0.10462477165354331,806.9007457386364,0.00025370340306410486,25.0,0.0
498.6394,0.10503315748031497,808.2421367694805,0.00025370340306410486,25.0,0.0
499.94067,0.10535601968503938,806.4205560064935,0.00025370340306410486,25.0,0.0
501.24194,0.10565057086614174,806.6084364853896,0.00025370340306410486,25.0,0.0
502.54321,0.10594693897637796,807.7176085633116,0.00025370340306410486,25.0,0.0
503.84448,0.10632981692913385,808.9911982548701,0.00025370340306410486,25.0,0.0
505.14575,0.10674377559055119,809.3470982142857,0.00025370340306410486,25.0,0.0
506.44702,0.10713932480314961,808.745408887987,0.00025370340306410486,25.0,0.0
507.74829,0.10748516141732282,809.0024096996752,0.00025370340306410486,25.0,0.0
509.04956,0.10789118897637795,810.5980874594155,0.00025370340306410486,25.0,0.0
510.35083,0.10817818307086614,808.3165077110389,0.00025370340306410486,25.0,0.0
511.6521,0.10850955118110236,809.9515777191558,0.00025370340306410486,25.0,0.0
512.95337,0.10887048818897638,811.8444348620129,0.00025370340306410486,25.0,0.0
514.25464,0.10931146850393701,811.5271661931819,0.00025370340306410486,25.0,0.0
515.55591,0.10972752755905511,811.5671164772726,0.00025370340306410486,25.0,0.0
516.85718,0.11011139173228347,812.3608461850649,0.00025370340306410486,25.0,0.0
518.15845,0.1105336338582677,812.3064630681818,0.00025370340306410486,25.0,0.0
519.45972,0.11094272440944881,812.8989701704545,0.00025370340306410486,25.0,0.0
520.76099,0.11131694291338581,810.9056158685064,0.00025370340306410486,25.0,0.0
522.06226,0.11168707874015747,811.6696682224026,0.00025370340306410486,25.0,0.0
523.36353,0.11205844488188975,813.9530489042207,0.00025370340306410486,25.0,0.0
524.66479,0.112452,813.7034040178571,0.00025370340306410486,25.0,0.0
525.96606,0.1128855531496063,813.8854251217532,0.00025370340306410486,25.0,0.0
527.26733,0.11327605708661417,811.4288504464286,0.00025370340306410486,25.0,0.0
528.5686,0.11365412401574804,813.7090604707793,0.00025370340306410486,25.0,0.0
529.86987,0.11402030708661416,814.1667004870129,0.00025370340306410486,25.0,0.0
531.17114,0.11441204330708661,812.3534648944805,0.00025370340306410486,25.0,0.0
532.47241,0.11473422440944883,813.0879159902597,0.00025370340306410486,25.0,0.0
533.77368,0.11515962401574802,813.4607853084415,0.00025370340306410486,25.0,0.0
535.07495,0.11551686417322833,813.9031808035714,0.00025370340306410486,25.0,0.0
536.37622,0.11587614566929134,814.5324928977273,0.00025370340306410486,25.0,0.0
537.67749,0.11621874409448818,814.0817775974026,0.00025370340306410486,25.0,0.0
538.97876,0.1166044251968504,815.2192573051948,0.00025370340306410486,25.0,0.0
540.28003,0.117026468503937,814.5476105925325,0.00025370340306410486,25.0,0.0
541.5813,0.11738006102362204,814.6593191964286,0.00025370340306410486,25.0,0.0
542.88257,0.11776630511811023,815.0048701298701,0.00025370340306410486,25.0,0.0
544.18384,0.11811785629921259,815.106255073052,0.00025370340306410486,25.0,0.0
545.48511,0.11847802952755906,815.8666548295454,0.00025370340306410486,25.0,0.0
546.78638,0.11888559448818897,815.5294490665584,0.00025370340306410486,25.0,0.0
548.08765,0.11930610039370078,817.3180296266233,0.00025370340306410486,25.0,0.0
549.38892,0.11973457283464567,815.5648843344155,0.00025370340306410486,25.0,0.0
550.69019,0.12008671062992127,817.343547077922,0.00025370340306410486,25.0,0.0
551.99146,0.12051762401574803,817.8273640422078,0.00025370340306410486,25.0,0.0
553.29272,0.12088800590551181,815.9029271509739,0.00025370340306410486,25.0,0.0
554.59399,0.12127936614173228,816.5765016233767,0.00025370340306410486,25.0,0.0
555.89526,0.12166451968503936,819.3238382711039,0.00025370340306410486,25.0,0.0
557.19653,0.12206058661417322,819.225877637987,0.00025370340306410486,25.0,0.0
558.4978,0.12247575393700788,818.8562297077922,0.00025370340306410486,25.0,0.0
559.79907,0.12288878543307086,818.7956574675325,0.00025370340306410486,25.0,0.0
561.10034,0.12333680511811024,818.2487824675325,0.00025370340306410486,25.0,0.0
562.40161,0.12366158070866143,818.4460734577922,0.00025370340306410486,25.0,0.0
563.70288,0.12401744881889763,818.610059862013,0.00025370340306410486,25.0,0.0
565.00415,0.12443462204724409,819.3823559253246,0.00025370340306410486,25.0,0.0
566.30542,0.1248140964566929,819.0550172483767,0.00025370340306410486,25.0,0.0
567.60669,0.12521374212598424,819.6921672077922,0.00025370340306410486,25.0,0.0
568.90796,0.1255336122047244,819.1202820616883,0.00025370340306410486,25.0,0.0
570.20923,0.12586698818897638,820.0249086850649,0.00025370340306410486,25.0,0.0
571.5105,0.12620177165354332,820.2078429383116,0.00025370340306410486,25.0,0.0
572.81177,0.12654980118110234,820.0023082386363,0.00025370340306410486,25.0,0.0
574.11304,0.12697404921259842,818.9436637581169,0.00025370340306410486,25.0,0.0
575.41431,0.12729236023622045,819.9199472402597,0.00025370340306410486,25.0,0.0
576.71558,0.12767226968503936,820.8436992694805,0.00025370340306410486,25.0,0.0
578.01685,0.1280818405511811,821.1321530032468,0.00025370340306410486,25.0,0.0
579.31812,0.1285399153543307,820.1436181006493,0.00025370340306410486,25.0,0.0
580.61938,0.1288942342519685,819.9493709415584,0.00025370340306410486,25.0,0.0
581.92065,0.12930819291338583,820.1241122159091,0.00025370340306410486,25.0,0.0
583.22192,0.1296596850393701,821.2583705357142,0.00025370340306410486,25.0,0.0
584.52319,0.13012535236220474,821.9311333198052,0.00025370340306410486,25.0,0.0
585.82446,0.13052723818897638,823.153713474026,0.00025370340306410486,25.0,0.0
587.12573,0.13095331692913387,822.3877333603896,0.00025370340306410486,25.0,0.0
588.427,0.1313475059055118,822.1477780032467,0.00025370340306410486,25.0,0.0
589.72827,0.13177898228346457,821.9735693993506,0.00025370340306410486,25.0,0.0
591.02954,0.13220989566929134,823.0228033685065,0.00025370340306410486,25.0,0.0
592.33081,0.1326302027559055,823.6312144886364,0.00025370340306410486,25.0,0.0
593.63208,0.13308335039370078,821.458400974026,0.00025370340306410486,25.0,0.0
594.93335,0.13344449803149608,821.5322646103896,0.00025370340306410486,25.0,0.0
596.23462,0.1337898996062992,823.3956473214286,0.00025370340306410486,25.0,0.0
597.53589,0.13416226377952756,822.6076247970778,0.00025370340306410486,25.0,0.0
598.83716,0.13453669488188974,823.7243557224025,0.00025370340306410486,25.0,0.0
600.13843,0.13494015157480313,823.9560420048701,0.00025370340306410486,25.0,0.0
601.4397,0.1352920433070866,824.1511008522727,0.00025370340306410486,25.0,0.0
602.74097,0.1356596909448819,825.5147372159091,0.00025370340306410486,25.0,0.0
604.04224,0.13607286417322834,823.5054535308441,0.00025370340306410486,25.0,0.0
605.34351,0.13642934055118108,823.4729352678571,0.00025370340306410486,25.0,0.0
606.64478,0.13680134251968504,823.5439072646104,0.00025370340306410486,25.0,0.0
607.94604,0.1372181181102362,825.5837307224026,0.00025370340306410486,25.0,0.0
609.24731,0.13767114763779525,825.6673092532467,0.00025370340306410486,25.0,0.0
610.54858,0.1380571811023622,824.0743202110389,0.00025370340306410486,25.0,0.0
611.84985,0.13843238582677167,824.1813108766233,0.00025370340306410486,25.0,0.0
613.15112,0.13881865354330708,824.4475446428571,0.00025370340306410486,25.0,0.0
614.45239,0.1392169153543307,825.7849786931819,0.00025370340306410486,25.0,0.0
615.75366,0.13969958267716534,825.505073051948,0.00025370340306410486,25.0,0.0
617.05493,0.14013090748031495,825.7785359172078,0.00025370340306410486,25.0,0.0
618.3562,0.14052677362204724,825.5195566152597,0.00025370340306410486,25.0,0.0
619.65747,0.14092123228346456,826.0519987824674,0.00025370340306410486,25.0,0.0
620.95874,0.14131055118110236,827.7529677353896,0.00025370340306410486,25.0,0.0
622.26001,0.14168891141732282,824.6606889204545,0.00025370340306410486,25.0,0.0
623.56128,0.14207994291338583,827.5821073457793,0.00025370340306410486,25.0,0.0
624.86255,0.14255706299212598,826.2672737418831,0.00025370340306410486,25.0,0.0
626.16382,0.1429898996062992,826.2928926542207,0.00025370340306410486,25.0,0.0
627.46509,0.1434482933070866,827.2848518668831,0.00025370340306410486,25.0,0.0
628.76636,0.14385207874015749,827.532112418831,0.00025370340306410486,25.0,0.0
630.06763,0.14420114173228346,826.8712459415584,0.00025370340306410486,25.0,0.0
631.3689,0.14468052559055117,828.3149350649351,0.00025370340306410486,25.0,0.0
632.67017,0.1451090688976378,828.7078683035714,0.00025370340306410486,25.0,0.0
633.97144,0.1455682125984252,827.3519683441558,0.00025370340306410486,25.0,0.0
635.27271,0.14594618503937007,828.0041345373377,0.00025370340306410486,25.0,0.0
636.57397,0.14629223228346455,826.4958400974025,0.00025370340306410486,25.0,0.0
637.87524,0.14667848818897639,829.1817928165584,0.00025370340306410486,25.0,0.0
639.17651,0.14715425787401576,827.9188058035713,0.00025370340306410486,25.0,0.0
640.47778,0.1476013996062992,829.8908025568181,0.00025370340306410486,25.0,0.0
641.77905,0.14797432677165354,828.4964995941558,0.00025370340306410486,25.0,0.0
643.08032,0.14831982283464568,828.6268770292207,0.00025370340306410486,25.0,0.0
644.38159,0.14870402559055118,827.6648995535714,0.00025370340306410486,25.0,0.0
645.68286,0.14916522244094488,830.458781452922,0.00025370340306410486,25.0,0.0
646.98413,0.149583781496063,829.4734679383116,0.00025370340306410486,25.0,0.0
648.2854,0.14995609842519686,828.4138342126623,0.00025370340306410486,25.0,0.0
649.58667,0.15043912007874016,829.1457487824675,0.00025370340306410486,25.0,0.0
650.88794,0.15087398818897638,831.5054788961038,0.00025370340306410486,25.0,0.0
652.18921,0.15129725,829.3890016233765,0.00025370340306410486,25.0,0.0
653.49048,0.15171630118110235,829.4028003246752,0.00025370340306410486,25.0,0.0
654.79175,0.15218146456692913,831.3428622159091,0.00025370340306410486,25.0,0.0
656.09302,0.1526197342519685,830.9311586850648,0.00025370340306410486,25.0,0.0
657.39429,0.1530582618110236,830.1262936282467,0.00025370340306410486,25.0,0.0
658.69556,0.15347934448818898,831.4981737012986,0.00025370340306410486,25.0,0.0
659.99683,0.1540017874015748,830.8115868506493,0.00025370340306410486,25.0,0.0
661.2981,0.15443688976377953,829.1744368912338,0.00025370340306410486,25.0,0.0
662.59937,0.15483709842519686,829.5686637581168,0.00025370340306410486,25.0,0.0
663.90063,0.1552754625984252,830.9478236607142,0.00025370340306410486,25.0,0.0
665.2019,0.15568355314960627,830.0142806412338,0.00025370340306410486,25.0,0.0
666.50317,0.1561037775590551,830.7442167207793,0.00025370340306410486,25.0,0.0
667.80444,0.15653865748031495,831.9441710633116,0.00025370340306410486,25.0,0.0
669.10571,0.15694602362204724,831.386820211039,0.00025370340306410486,25.0,0.0
670.40698,0.15743157677165354,831.0642502029222,0.00025370340306410486,25.0,0.0
671.70825,0.15784787204724407,830.7095424107143,0.00025370340306410486,25.0,0.0
673.00952,0.15820656692913385,831.1882355925324,0.00025370340306410486,25.0,0.0
674.31079,0.1585998996062992,833.2687195616883,0.00025370340306410486,25.0,0.0
675.61206,0.15911139566929133,833.3356584821429,0.00025370340306410486,25.0,0.0
676.91333,0.1595419803149606,830.7477932224026,0.00025370340306410486,25.0,0.0
678.2146,0.1598401220472441,829.4337205762987,0.00025370340306410486,25.0,0.0
679.51587,0.160255031496063,832.0054788961038,0.00025370340306410486,25.0,0.0
680.81714,0.16070110433070864,833.4504109172077,0.00025370340306410486,25.0,0.0
682.11841,0.16125324409448819,833.0707437094155,0.00025370340306410486,25.0,0.0
683.41968,0.16168460433070866,831.4504870129871,0.00025370340306410486,25.0,0.0
684.72095,0.16211652559055117,832.5813971185064,0.00025370340306410486,25.0,0.0
686.02222,0.162583812992126,832.9264407467533,0.00025370340306410486,25.0,0.0
687.32349,0.1629903562992126,833.4302962662338,0.00025370340306410486,25.0,0.0
688.62476,0.16342768700787402,834.7883522727273,0.00025370340306410486,25.0,0.0
689.92603,0.1638582027559055,832.1914316152596,0.00025370340306410486,25.0,0.0
691.22729,0.1642487066929134,833.5703632305194,0.00025370340306410486,25.0,0.0
692.52856,0.16470157283464568,834.197062702922,0.00025370340306410486,25.0,0.0
693.82983,0.16516274606299214,833.8429129464284,0.00025370340306410486,25.0,0.0
695.1311,0.16563722440944884,832.9572849025974,0.00025370340306410486,25.0,0.0
696.43237,0.16610549606299213,833.0957031249999,0.00025370340306410486,25.0,0.0
697.73364,0.16654959842519684,831.8645241477273,0.00025370340306410486,25.0,0.0
699.03491,0.16698774015748033,833.7244318181818,0.00025370340306410486,25.0,0.0
700.33618,0.16739255708661419,833.9675578327922,0.00025370340306410486,25.0,0.0
701.63745,0.16796943307086615,835.5984172077922,0.00025370340306410486,25.0,0.0
702.93872,0.1684813996062992,834.7489600243506,0.00025370340306410486,25.0,0.0
704.23999,0.16891810826771653,833.8464387175325,0.00025370340306410486,25.0,0.0
705.54126,0.16937457677165355,836.7545150162338,0.00025370340306410486,25.0,0.0
706.84253,0.16975213976377954,833.0661525974026,0.00025370340306410486,25.0,0.0
708.1438,0.1702121161417323,834.0847453327922,0.00025370340306410486,25.0,0.0
709.44507,0.1706764566929134,836.0795961850648,0.00025370340306410486,25.0,0.0
710.74634,0.17116303346456693,834.6359577922078,0.00025370340306410486,25.0,0.0
712.04761,0.17152679724409448,834.0655945616884,0.00025370340306410486,25.0,0.0
713.34888,0.17189374212598427,832.6114295860389,0.00025370340306410486,25.0,0.0
714.65015,0.17227806299212597,834.7747818587661,0.00025370340306410486,25.0,0.0
715.95142,0.17273454133858268,833.8086698457791,0.00025370340306410486,25.0,0.0
717.25269,0.1731639311023622,836.4443232548701,0.00025370340306410486,25.0,0.0
718.55396,0.17368182283464567,835.9045758928572,0.00025370340306410486,25.0,0.0
719.85522,0.17417719685039368,835.4245890827923,0.00025370340306410486,25.0,0.0
721.15649,0.17466853740157479,834.0716568587662,0.00025370340306410486,25.0,0.0
722.45776,0.17516033464566927,836.2527394480519,0.00025370340306410486,25.0,0.0
723.75903,0.1755768149606299,834.247362012987,0.00025370340306410486,25.0,0.0
725.0603,0.1760058405511811,835.1226917613636,0.00025370340306410486,25.0,0.0
726.36157,0.17646717716535434,834.8184354707793,0.00025370340306410486,25.0,0.0
727.66284,0.17694097637795275,834.7467278814935,0.00025370340306410486,25.0,0.0
728.96411,0.17738364566929132,834.5438565340909,0.00025370340306410486,25.0,0.0
730.26538,0.177836312992126,836.0381493506493,0.00025370340306410486,25.0,0.0
731.56665,0.17841006496062992,837.2940848214284,0.00025370340306410486,25.0,0.0
732.86792,0.17893362401574803,837.5587713068181,0.00025370340306410486,25.0,0.0
734.16919,0.17945855708661415,836.2226308847402,0.00025370340306410486,25.0,0.0
735.47046,0.1799630846456693,835.3793120941558,0.00025370340306410486,25.0,0.0
736.77173,0.18044685433070864,836.8511820211039,0.00025370340306410486,25.0,0.0
738.073,0.18096889960629922,836.3750507305194,0.00025370340306410486,25.0,0.0
739.37427,0.1813558720472441,835.9464539366883,0.00025370340306410486,25.0,0.0
740.67554,0.18179366141732284,836.894429788961,0.00025370340306410486,25.0,0.0
741.97681,0.18228193897637796,836.9412286931818,0.00025370340306410486,25.0,0.0
743.27808,0.1827739468503937,835.3105215097403,0.00025370340306410486,25.0,0.0
744.57935,0.1832536122047244,837.3627232142857,0.00025370340306410486,25.0,0.0
745.88062,0.183765344488189,836.4684963474026,0.00025370340306410486,25.0,0.0
747.18188,0.18429001771653541,835.1900111607142,0.00025370340306410486,25.0,0.0
748.48315,0.18474612204724408,836.599710836039,0.00025370340306410486,25.0,0.0
749.78442,0.18522057677165354,835.7193587662337,0.00025370340306410486,25.0,0.0
751.08569,0.18567177755905512,836.0498681006494,0.00025370340306410486,25.0,0.0
752.38696,0.1861563937007874,838.2076400162337,0.00025370340306410486,25.0,0.0
753.68823,0.1866886122047244,838.4639559659091,0.00025370340306410486,25.0,0.0
754.9895,0.1871917775590551,838.0603693181818,0.00025370340306410486,25.0,0.0
756.29077,0.18768787992125982,836.0816254058442,0.00025370340306410486,25.0,0.0
757.59204,0.18810376377952756,836.805854301948,0.00025370340306410486,25.0,0.0
758.89331,0.18859625393700788,838.0792157061688,0.00025370340306410486,25.0,0.0
760.19458,0.1890827933070866,837.1599025974025,0.00025370340306410486,25.0,0.0
761.49585,0.18955945472440944,835.2963423295454,0.00025370340306410486,25.0,0.0
762.79712,0.1899926102362205,835.239549512987,0.00025370340306410486,25.0,0.0
764.09839,0.19048001771653544,837.896585836039,0.00025370340306410486,25.0,0.0
765.39966,0.19107802362204723,837.1702516233767,0.00025370340306410486,25.0,0.0
766.70093,0.19156898818897636,835.6261668019481,0.00025370340306410486,25.0,0.0
768.0022,0.19208414566929136,836.7062195616883,0.00025370340306410486,25.0,0.0
769.30347,0.19257697440944882,837.8799208603896,0.00025370340306410486,25.0,0.0
770.60474,0.1930608996062992,835.870890827922,0.00025370340306410486,25.0,0.0
771.90601,0.1935499625984252,837.3148336038961,0.00025370340306410486,25.0,0.0
773.20728,0.19411517322834645,839.1739549512986,0.00025370340306410486,25.0,0.0
774.50854,0.194688,837.606838474026,0.00025370340306410486,25.0,0.0
775.80981,0.19524425984251967,838.0245789366884,0.00025370340306410486,25.0,0.0
777.11108,0.19587459055118112,838.6096032873377,0.00025370340306410486,25.0,0.0
778.41235,0.19636959055118108,838.2003348214286,0.00025370340306410486,25.0,0.0
779.71362,0.19692285433070866,836.9965249594155,0.00025370340306410486,25.0,0.0
781.01489,0.19743765748031494,838.3978287337661,0.00025370340306410486,25.0,0.0
782.31616,0.198003405511811,837.1737773944805,0.00025370340306410486,25.0,0.0
783.61743,0.19847269685039368,837.6559963474026,0.00025370340306410486,25.0,0.0
784.9187,0.19891946850393702,837.0217380275974,0.00025370340306410486,25.0,0.0
786.21997,0.19942787401574802,835.9316913555194,0.00025370340306410486,25.0,0.0
787.52124,0.19988681102362205,835.681640625,0.00025370340306410486,25.0,0.0
788.82251,0.20033594488188974,837.3967126623377,0.00025370340306410486,25.0,0.0
790.12378,0.20089226377952754,840.0316304788961,0.00025370340306410486,25.0,0.0
791.42505,0.20138395669291337,837.0821834415584,0.00025370340306410486,25.0,0.0
792.02563,0.20168309055118108,840.0995586444805,0.00025370340306410486,25.0,0.0