File: datasets/am_bench_2022/csv/0-XY.05-1.csv
Time(s),Strain(%),Stress(MPa),SR(s-1),Temp(C),Angle(deg)
36.358154,5.782898228346457e-06,17.021617796266234,0.00025370340306410486,25.0,0.0
37.759521,4.708657677165354e-05,22.4550880174513,0.00025370340306410486,25.0,0.0
39.060791,5.3596303149606295e-05,27.13688869724026,0.00025370340306410486,25.0,0.0
40.362061,0.00010838044094488189,31.083017958603897,0.00025370340306410486,25.0,0.0
41.66333,9.840873622047244e-05,34.70993557224026,0.00025370340306410486,25.0,0.0
42.9646,0.0001415241712598425,40.40776176948052,0.00025370340306410486,25.0,0.0
44.265869,0.00015411589763779528,45.83854251217532,0.00025370340306410486,25.0,0.0
45.567139,0.00015912200787401574,51.278979809253244,0.00025370340306410486,25.0,0.0
46.868408,0.00023495001968503937,57.892651684253245,0.00025370340306410486,25.0,0.0
48.169678,0.00028144917322834646,64.86361607142857,0.00025370340306410486,25.0,0.0
49.470947,0.0003113791732283464,72.52173041801947,0.00025370340306410486,25.0,0.0
50.772217,0.000321162125984252,76.94019125405843,0.00025370340306410486,25.0,0.0
52.073486,0.00035402917322834644,85.2171875,0.00025370340306410486,25.0,0.0
53.374756,0.00039263761811023627,90.53809354707792,0.00025370340306410486,25.0,0.0
54.676025,0.00040806411417322835,97.56720018262988,0.00025370340306410486,25.0,0.0
55.977295,0.0004425933070866142,101.94153053977273,0.00025370340306410486,25.0,0.0
57.278564,0.00046705419291338585,109.07852069805195,0.00025370340306410486,25.0,0.0
58.579834,0.0005021659645669291,117.00554230925324,0.00025370340306410486,25.0,0.0
59.881104,0.0005302358070866142,126.30649857954545,0.00025370340306410486,25.0,0.0
61.182373,0.0005815402362204724,132.0890625,0.00025370340306410486,25.0,0.0
62.483643,0.000603785,141.0221286525974,0.00025370340306410486,25.0,0.0
63.784912,0.0006359809448818898,147.69393009334416,0.00025370340306410486,25.0,0.0
65.086182,0.0006621856102362205,155.54909699675324,0.00025370340306410486,25.0,0.0
66.387451,0.0006792833070866142,162.81841517857143,0.00025370340306410486,25.0,0.0
67.688721,0.0007530254921259842,173.0761896306818,0.00025370340306410486,25.0,0.0
68.98999,0.0007636917125984252,178.47472859172078,0.00025370340306410486,25.0,0.0
70.29126,0.0008016074015748032,188.51244673295454,0.00025370340306410486,25.0,0.0
71.592529,0.0008266031496062992,197.33585379464284,0.00025370340306410486,25.0,0.0
72.893799,0.0008937702952755905,207.0617365056818,0.00025370340306410486,25.0,0.0
74.195068,0.0009267895275590552,216.65141284496752,0.00025370340306410486,25.0,0.0
75.496338,0.000975046437007874,226.5947062702922,0.00025370340306410486,25.0,0.0
76.797607,0.0010056128740157481,233.6069830560065,0.00025370340306410486,25.0,0.0
78.098877,0.0010239066732283463,243.13562804383116,0.00025370340306410486,25.0,0.0
79.400146,0.0010632243503937008,249.62042918019478,0.00025370340306410486,25.0,0.0
80.701416,0.00113584687007874,262.70076603084414,0.00025370340306410486,25.0,0.0
82.002686,0.0011672625984251968,273.52254971590907,0.00025370340306410486,25.0,0.0
83.303955,0.0012266714566929132,283.9883573457792,0.00025370340306410486,25.0,0.0
84.605225,0.0012301232086614172,290.8921215503247,0.00025370340306410486,25.0,0.0
85.906494,0.0012684591535433072,298.7438616071429,0.00025370340306410486,25.0,0.0
87.207764,0.0013203549015748032,308.86231737012986,0.00025370340306410486,25.0,0.0
88.509033,0.001356426594488189,318.2715604707792,0.00025370340306410486,25.0,0.0
89.810303,0.0013870992913385825,327.2910663555195,0.00025370340306410486,25.0,0.0
91.111572,0.001431216377952756,336.76661424512986,0.00025370340306410486,25.0,0.0
92.412842,0.0014643963976377953,344.7569500811688,0.00025370340306410486,25.0,0.0
93.714111,0.0014910996062992125,351.85447950487014,0.00025370340306410486,25.0,0.0
95.015381,0.0015474045669291337,362.65011160714283,0.00025370340306410486,25.0,0.0
96.31665,0.0016031704330708662,374.52031757305195,0.00025370340306410486,25.0,0.0
97.61792,0.0016172183661417323,381.12007913961037,0.00025370340306410486,25.0,0.0
98.919189,0.0016597953937007872,391.29613940746754,0.00025370340306410486,25.0,0.0
100.22046,0.0016978120472440944,399.92278814935065,0.00025370340306410486,25.0,0.0
101.52173,0.0017539038976377953,410.7049512987013,0.00025370340306410486,25.0,0.0
102.823,0.0017824425,417.4631950081169,0.00025370340306410486,25.0,0.0
104.12427,0.0018419092913385825,428.70386059253246,0.00025370340306410486,25.0,0.0
105.42554,0.001850466279527559,435.8866680194805,0.00025370340306410486,25.0,0.0
106.72681,0.0019178907283464567,445.9692826704545,0.00025370340306410486,25.0,0.0
108.02808,0.0019508947440944882,454.9499289772727,0.00025370340306410486,25.0,0.0
109.32935,0.001998687007874016,462.1631493506493,0.00025370340306410486,25.0,0.0
110.63062,0.00201853937007874,471.45373376623377,0.00025370340306410486,25.0,0.0
111.93188,0.0020805212598425196,479.0275466720779,0.00025370340306410486,25.0,0.0
113.23315,0.0021532385826771652,486.46154626623377,0.00025370340306410486,25.0,0.0
114.53442,0.002193532874015748,496.37680093344153,0.00025370340306410486,25.0,0.0
115.83569,0.0022461998031496062,504.05202414772725,0.00025370340306410486,25.0,0.0
117.13696,0.002268530905511811,511.35625507305195,0.00025370340306410486,25.0,0.0
118.43823,0.002331733464566929,518.6031605113636,0.00025370340306410486,25.0,0.0
119.7395,0.002374225196850394,523.1650517451299,0.00025370340306410486,25.0,0.0
121.04077,0.002390245275590551,530.1173396915584,0.00025370340306410486,25.0,0.0
122.34204,0.002456680905511811,538.5910359172078,0.00025370340306410486,25.0,0.0
123.64331,0.0025277641732283467,545.0096895292209,0.00025370340306410486,25.0,0.0
124.94458,0.002578245275590551,551.8971438717533,0.00025370340306410486,25.0,0.0
126.24585,0.0026306659448818897,558.2576603084416,0.00025370340306410486,25.0,0.0
127.54712,0.002705873031496063,564.8731990665584,0.00025370340306410486,25.0,0.0
128.84839,0.002755729330708661,569.3179281655844,0.00025370340306410486,25.0,0.0
130.14966,0.00277226968503937,574.8749492694806,0.00025370340306410486,25.0,0.0
131.45093,0.0028419190944881886,579.6789772727273,0.00025370340306410486,25.0,0.0
132.7522,0.0028685667322834647,586.1866375811688,0.00025370340306410486,25.0,0.0
134.05347,0.002991311811023622,594.2558847402598,0.00025370340306410486,25.0,0.0
135.35474,0.003021219881889764,595.7363788555194,0.00025370340306410486,25.0,0.0
136.65601,0.003099527755905512,601.171773538961,0.00025370340306410486,25.0,0.0
137.95728,0.003197147440944882,609.0343191964286,0.00025370340306410486,25.0,0.0
139.25854,0.0032512661417322835,611.9963474025974,0.00025370340306410486,25.0,0.0
140.55981,0.003319207283464567,616.0721134334416,0.00025370340306410486,25.0,0.0
141.86108,0.0033711472440944887,619.8881138392857,0.00025370340306410486,25.0,0.0
143.16235,0.0034481334645669287,623.306539163961,0.00025370340306410486,25.0,0.0
144.46362,0.003544864566929134,628.7176085633117,0.00025370340306410486,25.0,0.0
145.76489,0.0036000820866141734,632.0690696022726,0.00025370340306410486,25.0,0.0
147.06616,0.0037117326771653543,637.0884993912338,0.00025370340306410486,25.0,0.0
148.36743,0.00379608031496063,641.593065137987,0.00025370340306410486,25.0,0.0
149.6687,0.0038819370078740155,644.4115513392857,0.00025370340306410486,25.0,0.0
150.96997,0.003967561811023622,647.9241071428572,0.00025370340306410486,25.0,0.0
152.27124,0.004109464960629921,650.6037439123377,0.00025370340306410486,25.0,0.0
153.57251,0.004231066929133858,655.1530793425325,0.00025370340306410486,25.0,0.0
154.87378,0.004324992322834646,658.7807426948052,0.00025370340306410486,25.0,0.0
156.17505,0.0044332226377952755,660.3224939123377,0.00025370340306410486,25.0,0.0
157.47632,0.004563806889763779,664.9162185470778,0.00025370340306410486,25.0,0.0
158.77759,0.00470994094488189,667.0678013392858,0.00025370340306410486,25.0,0.0
160.07886,0.004817179133858268,667.4936333198051,0.00025370340306410486,25.0,0.0
161.38013,0.004996384251968504,672.6926998782468,0.00025370340306410486,25.0,0.0
162.6814,0.0051116663385826775,672.4543425324674,0.00025370340306410486,25.0,0.0
163.98267,0.0052566232283464565,674.7886059253246,0.00025370340306410486,25.0,0.0
165.28394,0.005415447637795275,676.9846540178571,0.00025370340306410486,25.0,0.0
166.58521,0.005606296456692913,680.0442116477273,0.00025370340306410486,25.0,0.0
167.88647,0.005826445275590551,681.0973011363636,0.00025370340306410486,25.0,0.0
169.18774,0.00601318937007874,683.8719815340909,0.00025370340306410486,25.0,0.0
170.48901,0.006220830708661418,686.0855570211039,0.00025370340306410486,25.0,0.0
171.79028,0.006398674409448819,686.6785714285713,0.00025370340306410486,25.0,0.0
173.09155,0.006593601771653543,688.0231838474025,0.00025370340306410486,25.0,0.0
174.39282,0.006758836811023622,689.0254159902597,0.00025370340306410486,25.0,0.0
175.69409,0.00699452657480315,692.0141284496754,0.00025370340306410486,25.0,0.0
176.99536,0.007276366732283464,694.687702922078,0.00025370340306410486,25.0,0.0
178.29663,0.007531206692913386,696.1385957792207,0.00025370340306410486,25.0,0.0
179.5979,0.007815175787401575,699.537210836039,0.00025370340306410486,25.0,0.0
180.89917,0.008020315354330709,698.1084872159091,0.00025370340306410486,25.0,0.0
182.20044,0.008269513779527558,699.445109577922,0.00025370340306410486,25.0,0.0
183.50171,0.008575238385826772,700.8564833603896,0.00025370340306410486,25.0,0.0
184.80298,0.008841830511811023,701.4241071428572,0.00025370340306410486,25.0,0.0
186.10425,0.009136157874015748,702.1832893668832,0.00025370340306410486,25.0,0.0
187.40552,0.00934184153543307,702.4460988230519,0.00025370340306410486,25.0,0.0
188.70679,0.00966590374015748,706.7716872970778,0.00025370340306410486,25.0,0.0
190.00806,0.010000967913385827,707.7583705357142,0.00025370340306410486,25.0,0.0
191.30933,0.01033403661417323,707.6572392451299,0.00025370340306410486,25.0,0.0
192.6106,0.010611703543307087,708.729200487013,0.00025370340306410486,25.0,0.0
193.91187,0.01097946751968504,710.7558086444806,0.00025370340306410486,25.0,0.0
195.21313,0.011287518897637796,710.3674665178572,0.00025370340306410486,25.0,0.0
196.5144,0.011574821653543307,712.7727272727273,0.00025370340306410486,25.0,0.0
197.81567,0.011898109448818897,713.6972909902597,0.00025370340306410486,25.0,0.0
199.11694,0.0122817218503937,715.5508066152597,0.00025370340306410486,25.0,0.0
200.41821,0.012565747440944882,714.8193486201299,0.00025370340306410486,25.0,0.0
201.71948,0.01286723188976378,717.9430549918832,0.00025370340306410486,25.0,0.0
203.02075,0.013135690354330709,716.4997209821429,0.00025370340306410486,25.0,0.0
204.32202,0.013492023228346457,718.3779677353896,0.00025370340306410486,25.0,0.0
205.62329,0.013813637401574805,718.6056716720778,0.00025370340306410486,25.0,0.0
206.92456,0.014095289960629922,717.9906148538961,0.00025370340306410486,25.0,0.0
208.22583,0.014378618897637795,719.9529474431819,0.00025370340306410486,25.0,0.0
209.5271,0.01474585905511811,721.4397067775974,0.00025370340306410486,25.0,0.0
210.82837,0.015128373031496063,721.0817522321428,0.00025370340306410486,25.0,0.0
212.12964,0.015438598818897637,722.0021053165584,0.00025370340306410486,25.0,0.0
213.43091,0.015786939960629923,722.9997463474026,0.00025370340306410486,25.0,0.0
214.73218,0.01609942125984252,723.6195211038961,0.00025370340306410486,25.0,0.0
216.03345,0.016466143897637793,725.7666649756493,0.00025370340306410486,25.0,0.0
217.33472,0.016821897440944884,725.1192167207791,0.00025370340306410486,25.0,0.0
218.63599,0.01722587440944882,726.6685014204545,0.00025370340306410486,25.0,0.0
219.93726,0.01757493996062992,725.3900162337662,0.00025370340306410486,25.0,0.0
221.23853,0.017941333858267718,728.715427150974,0.00025370340306410486,25.0,0.0
222.53979,0.018365481692913386,727.5669389204545,0.00025370340306410486,25.0,0.0
223.84106,0.018748687992125982,727.2764813311688,0.00025370340306410486,25.0,0.0
225.14233,0.019124062204724408,730.2646611201297,0.00025370340306410486,25.0,0.0
226.4436,0.019445509448818895,728.6878804788961,0.00025370340306410486,25.0,0.0
227.74487,0.019746088582677165,728.1883624188312,0.00025370340306410486,25.0,0.0
229.04614,0.0200926968503937,731.2113179788961,0.00025370340306410486,25.0,0.0
230.34741,0.020472324803149606,732.5433745941558,0.00025370340306410486,25.0,0.0
231.64868,0.020890061023622047,733.5203429383116,0.00025370340306410486,25.0,0.0
232.94995,0.021194868110236218,732.4790229301948,0.00025370340306410486,25.0,0.0
234.25122,0.021581748031496064,733.1739042207793,0.00025370340306410486,25.0,0.0
235.55249,0.021941316929133856,732.7346793831169,0.00025370340306410486,25.0,0.0
236.85376,0.02226503937007874,733.7282873376623,0.00025370340306410486,25.0,0.0
238.15503,0.022636074803149605,733.4196428571428,0.00025370340306410486,25.0,0.0
239.4563,0.022991671259842517,734.6443790584416,0.00025370340306410486,25.0,0.0
240.75757,0.02337398622047244,736.0828683035714,0.00025370340306410486,25.0,0.0
242.05884,0.023745846456692914,736.8606686282467,0.00025370340306410486,25.0,0.0
243.36011,0.024131706692913386,735.889838676948,0.00025370340306410486,25.0,0.0
244.66138,0.024501307086614174,737.9755478896104,0.00025370340306410486,25.0,0.0
245.96265,0.024857462598425195,740.0080407873377,0.00025370340306410486,25.0,0.0
247.26392,0.025246372047244097,739.6460278003246,0.00025370340306410486,25.0,0.0
248.56519,0.025570606299212595,740.1000659496754,0.00025370340306410486,25.0,0.0
249.86646,0.025941736220472442,738.8101410308442,0.00025370340306410486,25.0,0.0
251.16772,0.026327452755905513,740.0628551136363,0.00025370340306410486,25.0,0.0
252.46899,0.02670470472440945,741.1400669642858,0.00025370340306410486,25.0,0.0
253.77026,0.027066767716535434,741.1647219967532,0.00025370340306410486,25.0,0.0
255.07153,0.02744011811023622,742.66502637987,0.00025370340306410486,25.0,0.0
256.3728,0.02784126181102362,744.2187753652597,0.00025370340306410486,25.0,0.0
257.67407,0.02825543897637795,743.7151734983765,0.00025370340306410486,25.0,0.0
258.97534,0.02863766535433071,743.9925426136364,0.00025370340306410486,25.0,0.0
260.27661,0.028978482283464568,742.9094460227273,0.00025370340306410486,25.0,0.0
261.57788,0.029367809055118106,743.2827972808441,0.00025370340306410486,25.0,0.0
262.87915,0.029725149606299208,746.101663961039,0.00025370340306410486,25.0,0.0
264.18042,0.030148755905511807,746.0321124188312,0.00025370340306410486,25.0,0.0
265.48169,0.03058948228346457,744.8495586444806,0.00025370340306410486,25.0,0.0
266.78296,0.030959641732283466,745.2372666396104,0.00025370340306410486,25.0,0.0
268.08423,0.03131581692913386,746.6095018262987,0.00025370340306410486,25.0,0.0
269.3855,0.03173760433070866,746.8222402597402,0.00025370340306410486,25.0,0.0
270.68677,0.03214136220472441,746.4706777597403,0.00025370340306410486,25.0,0.0
271.98804,0.0324806968503937,748.4423701298701,0.00025370340306410486,25.0,0.0
273.28931,0.0328466594488189,748.0390371347403,0.00025370340306410486,25.0,0.0
274.59058,0.03320929133858268,746.7339184253246,0.00025370340306410486,25.0,0.0
275.89185,0.03356967913385827,750.4407974837662,0.00025370340306410486,25.0,0.0
277.19312,0.0339438562992126,748.5717836850649,0.00025370340306410486,25.0,0.0
278.49438,0.03427956692913386,749.0170961850649,0.00025370340306410486,25.0,0.0
279.79565,0.03467306889763779,751.5223721590909,0.00025370340306410486,25.0,0.0
281.09692,0.035035029527559054,750.0859121347403,0.00025370340306410486,25.0,0.0
282.39819,0.035394889763779525,750.3020241477273,0.00025370340306410486,25.0,0.0
283.69946,0.035814212598425196,751.8525010146104,0.00025370340306410486,25.0,0.0
285.00073,0.03623808070866141,752.0514153814935,0.00025370340306410486,25.0,0.0
286.302,0.036533322834645665,750.4755986201299,0.00025370340306410486,25.0,0.0
287.60327,0.03682004133858268,751.6290584415584,0.00025370340306410486,25.0,0.0
288.90454,0.03731327362204724,754.5067471590909,0.00025370340306410486,25.0,0.0
290.20581,0.037760917322834646,754.3110034496754,0.00025370340306410486,25.0,0.0
291.50708,0.03812615748031496,753.7563666801948,0.00025370340306410486,25.0,0.0
292.80835,0.03850518700787402,755.927150974026,0.00025370340306410486,25.0,0.0
294.10962,0.03892386220472441,755.4937347808442,0.00025370340306410486,25.0,0.0
295.41089,0.03932401771653543,755.0611049107142,0.00025370340306410486,25.0,0.0
296.71216,0.03971475393700787,756.2547433035714,0.00025370340306410486,25.0,0.0
298.01343,0.04008110433070866,758.0994825487013,0.00025370340306410486,25.0,0.0
299.3147,0.04040281496062992,756.3976258116883,0.00025370340306410486,25.0,0.0
300.61597,0.04080571259842519,757.2050273944806,0.00025370340306410486,25.0,0.0
301.91724,0.04120577362204724,758.1057984983767,0.00025370340306410486,25.0,0.0
303.21851,0.041556856299212595,759.2112165178571,0.00025370340306410486,25.0,0.0
304.51978,0.041949984251968504,758.9699928977273,0.00025370340306410486,25.0,0.0
305.82104,0.042332637795275595,760.439351663961,0.00025370340306410486,25.0,0.0
307.12231,0.04267920866141732,760.2835836038961,0.00025370340306410486,25.0,0.0
308.42358,0.043036858267716534,758.0837053571428,0.00025370340306410486,25.0,0.0
309.72485,0.04343724212598425,761.6775568181818,0.00025370340306410486,25.0,0.0
311.02612,0.04385074212598425,760.3456523944805,0.00025370340306410486,25.0,0.0
312.32739,0.04422237204724409,764.1629464285714,0.00025370340306410486,25.0,0.0
313.62866,0.044630696850393704,761.6602830762987,0.00025370340306410486,25.0,0.0
314.92993,0.04496217913385827,761.0687144886364,0.00025370340306410486,25.0,0.0
316.2312,0.04532364960629921,762.8670099431818,0.00025370340306410486,25.0,0.0
317.53247,0.045669531496062996,763.0951450892857,0.00025370340306410486,25.0,0.0
318.83374,0.046011673228346456,763.7175578327922,0.00025370340306410486,25.0,0.0
320.13501,0.04646955511811024,765.555854301948,0.00025370340306410486,25.0,0.0
321.43628,0.04686116929133858,762.6016385957793,0.00025370340306410486,25.0,0.0
322.73755,0.047265407480314964,766.1364904626622,0.00025370340306410486,25.0,0.0
324.03882,0.04766810236220472,763.6911779626623,0.00025370340306410486,25.0,0.0
325.34009,0.04810353543307087,763.2862976866883,0.00025370340306410486,25.0,0.0
326.64136,0.04847984645669291,763.0493607954545,0.00025370340306410486,25.0,0.0
327.94263,0.04882746850393701,765.5046418425324,0.00025370340306410486,25.0,0.0
329.2439,0.04918843897637795,764.9473163555195,0.00025370340306410486,25.0,0.0
330.54517,0.04955026771653543,766.4129210633116,0.00025370340306410486,25.0,0.0
331.84644,0.050000499999999996,768.679586038961,0.00025370340306410486,25.0,0.0
333.14771,0.050441944881889765,767.7548954951297,0.00025370340306410486,25.0,0.0
334.44897,0.05081124606299212,767.027242288961,0.00025370340306410486,25.0,0.0
335.75024,0.05119245866141733,767.6373021509739,0.00025370340306410486,25.0,0.0
337.05151,0.05157133464566929,767.832614650974,0.00025370340306410486,25.0,0.0
338.35278,0.051949043307086606,768.8623934659091,0.00025370340306410486,25.0,0.0
339.65405,0.05230189566929134,768.6797635957791,0.00025370340306410486,25.0,0.0
340.95532,0.05270180511811024,768.1098569399351,0.00025370340306410486,25.0,0.0
342.25659,0.05300497834645669,768.7824928977273,0.00025370340306410486,25.0,0.0
343.55786,0.05338816732283465,769.7043425324674,0.00025370340306410486,25.0,0.0
344.85913,0.05374455118110236,769.08984375,0.00025370340306410486,25.0,0.0
346.1604,0.05414969881889764,771.9069094967533,0.00025370340306410486,25.0,0.0
347.46167,0.05454829330708661,772.0048701298701,0.00025370340306410486,25.0,0.0
348.76294,0.0549342342519685,770.4016335227273,0.00025370340306410486,25.0,0.0
350.06421,0.055338994094488184,771.8591467126623,0.00025370340306410486,25.0,0.0
351.36548,0.055707098425196847,773.2756696428571,0.00025370340306410486,25.0,0.0
352.66675,0.056106374015748035,772.746575689935,0.00025370340306410486,25.0,0.0
353.96802,0.05645585433070866,770.8104200487012,0.00025370340306410486,25.0,0.0
355.26929,0.05683500590551181,773.3676440746752,0.00025370340306410486,25.0,0.0
356.57056,0.05721903346456693,773.5788605925325,0.00025370340306410486,25.0,0.0
357.87183,0.05755567716535433,773.1198762175325,0.00025370340306410486,25.0,0.0
359.1731,0.05799822244094488,775.4371195211038,0.00025370340306410486,25.0,0.0
360.47437,0.05838300787401575,774.5815239448052,0.00025370340306410486,25.0,0.0
361.77563,0.058782763779527555,774.1548549107142,0.00025370340306410486,25.0,0.0
363.0769,0.05915256496062992,773.3143770292207,0.00025370340306410486,25.0,0.0
364.37817,0.05952377952755906,776.4833603896104,0.00025370340306410486,25.0,0.0
365.67944,0.05990053937007874,777.1279677353896,0.00025370340306410486,25.0,0.0
366.98071,0.06024518897637795,776.0136972402597,0.00025370340306410486,25.0,0.0
368.28198,0.06064263976377953,776.6228946834416,0.00025370340306410486,25.0,0.0
369.58325,0.0610415688976378,776.8640929383116,0.00025370340306410486,25.0,0.0
370.88452,0.061374915354330706,775.3239650974026,0.00025370340306410486,25.0,0.0
372.18579,0.06172283858267716,777.3024807224026,0.00025370340306410486,25.0,0.0
373.48706,0.06211083267716535,776.6004717938312,0.00025370340306410486,25.0,0.0
374.78833,0.0625031437007874,778.3554180194806,0.00025370340306410486,25.0,0.0
376.0896,0.06291819291338582,780.0654677353896,0.00025370340306410486,25.0,0.0
377.39087,0.06336303937007874,779.0623731737013,0.00025370340306410486,25.0,0.0
378.69214,0.06370857086614173,780.5390117694806,0.00025370340306410486,25.0,0.0
379.99341,0.06407667716535433,780.2903307629871,0.00025370340306410486,25.0,0.0
381.29468,0.0644600531496063,779.4802404626623,0.00025370340306410486,25.0,0.0
382.59595,0.0648720531496063,781.5447696834416,0.00025370340306410486,25.0,0.0
383.89722,0.06527753937007874,782.1058238636363,0.00025370340306410486,25.0,0.0
385.19849,0.06565065551181103,781.3280996347402,0.00025370340306410486,25.0,0.0
386.49976,0.0660671968503937,780.4357244318181,0.00025370340306410486,25.0,0.0
387.80103,0.06642044094488189,780.8194754464286,0.00025370340306410486,25.0,0.0
389.10229,0.06682628149606298,782.6294135551948,0.00025370340306410486,25.0,0.0
390.40356,0.06722897047244095,784.1700487012987,0.00025370340306410486,25.0,0.0
391.70483,0.06760216929133858,783.831929788961,0.00025370340306410486,25.0,0.0
393.0061,0.06798647244094488,783.2058898133117,0.00025370340306410486,25.0,0.0
394.30737,0.06831104724409448,782.9814072646103,0.00025370340306410486,25.0,0.0
395.60864,0.06867750984251968,784.2674512987013,0.00025370340306410486,25.0,0.0
396.90991,0.06916769291338583,784.6396357548701,0.00025370340306410486,25.0,0.0
398.21118,0.0695488937007874,783.1410054788961,0.00025370340306410486,25.0,0.0
399.51245,0.06988441535433071,784.9436383928571,0.00025370340306410486,25.0,0.0
400.81372,0.07030910433070867,786.1668019480519,0.00025370340306410486,25.0,0.0
402.11499,0.07066555314960629,785.2423143262987,0.00025370340306410486,25.0,0.0
403.41626,0.07099279330708662,785.267578125,0.00025370340306410486,25.0,0.0
404.71753,0.07137750000000001,785.9866071428571,0.00025370340306410486,25.0,0.0
406.0188,0.07179911614173227,787.1071682224026,0.00025370340306410486,25.0,0.0
407.32007,0.07215497244094488,785.6603845373376,0.00025370340306410486,25.0,0.0
408.62134,0.07250905708661418,787.1781402191558,0.00025370340306410486,25.0,0.0
409.92261,0.0728786279527559,788.5766284496754,0.00025370340306410486,25.0,0.0
411.22388,0.0733309842519685,788.2549969561688,0.00025370340306410486,25.0,0.0
412.52515,0.07371190354330709,787.8114600243507,0.00025370340306410486,25.0,0.0
413.82642,0.07401961811023622,788.3340604707791,0.00025370340306410486,25.0,0.0
415.12769,0.07435438385826772,790.327922077922,0.00025370340306410486,25.0,0.0
416.42896,0.07477181496062993,790.1428317775974,0.00025370340306410486,25.0,0.0
417.73022,0.07509677755905513,789.2488585633117,0.00025370340306410486,25.0,0.0
419.03149,0.07543296259842519,790.4712865259739,0.00025370340306410486,25.0,0.0
420.33276,0.07575623031496062,789.1038707386364,0.00025370340306410486,25.0,0.0
421.63403,0.07611116535433071,790.6036931818182,0.00025370340306410486,25.0,0.0
422.9353,0.0765150748031496,790.0597859172077,0.00025370340306410486,25.0,0.0
424.23657,0.07690813779527558,792.0943841314935,0.00025370340306410486,25.0,0.0
425.53784,0.07729647637795276,790.8206676136364,0.00025370340306410486,25.0,0.0
426.83911,0.07773710433070866,792.3305854301948,0.00025370340306410486,25.0,0.0
428.14038,0.07806803346456692,791.7051288555194,0.00025370340306410486,25.0,0.0
429.44165,0.07845058267716536,790.9023691152597,0.00025370340306410486,25.0,0.0
430.74292,0.07880479724409449,794.2600953733767,0.00025370340306410486,25.0,0.0
432.04419,0.07920863582677165,793.4982751623377,0.00025370340306410486,25.0,0.0
433.34546,0.07956632874015748,793.0173498376623,0.00025370340306410486,25.0,0.0
434.64673,0.0799310905511811,793.7231381899351,0.00025370340306410486,25.0,0.0
435.948,0.08027361220472441,792.5198356331168,0.00025370340306410486,25.0,0.0
437.24927,0.08062058464566929,792.9598721590909,0.00025370340306410486,25.0,0.0
438.55054,0.08104323228346456,793.2248122970778,0.00025370340306410486,25.0,0.0
439.85181,0.08141577952755905,794.7910663555195,0.00025370340306410486,25.0,0.0
441.15308,0.08182068110236221,795.0432224025974,0.00025370340306410486,25.0,0.0
442.45435,0.08222850196850394,792.9233969155845,0.00025370340306410486,25.0,0.0
443.75562,0.08263617913385826,794.5141284496754,0.00025370340306410486,25.0,0.0
445.05688,0.08307292322834645,797.4120586444805,0.00025370340306410486,25.0,0.0
446.35815,0.08344446062992127,794.9130478896104,0.00025370340306410486,25.0,0.0
447.65942,0.08379959055118111,796.6459517045455,0.00025370340306410486,25.0,0.0
448.96069,0.08415738188976378,797.4339742288961,0.00025370340306410486,25.0,0.0
450.26196,0.08449071062992126,796.7025669642857,0.00025370340306410486,25.0,0.0
451.56323,0.08485506692913385,800.0593039772727,0.00025370340306410486,25.0,0.0
452.8645,0.08523855511811024,799.5105012175325,0.00025370340306410486,25.0,0.0
454.16577,0.08563663976377953,798.9557122564935,0.00025370340306410486,25.0,0.0
455.46704,0.0859461437007874,796.5666852678571,0.00025370340306410486,25.0,0.0
456.76831,0.0863074842519685,796.550578327922,0.00025370340306410486,25.0,0.0
458.06958,0.08663968700787401,797.8745180600649,0.00025370340306410486,25.0,0.0
459.37085,0.08703558858267717,798.4192877435065,0.00025370340306410486,25.0,0.0
460.67212,0.08739137401574804,799.1487418831168,0.00025370340306410486,25.0,0.0
461.97339,0.08777236220472441,800.1175172483765,0.00025370340306410486,25.0,0.0
463.27466,0.08819659448818898,801.1801948051948,0.00025370340306410486,25.0,0.0
464.57593,0.08851202952755906,799.0656960227273,0.00025370340306410486,25.0,0.0
465.8772,0.08889020866141732,801.5886008522726,0.00025370340306410486,25.0,0.0
467.17847,0.08924966535433071,800.5178064123377,0.00025370340306410486,25.0,0.0
468.47974,0.08965825787401575,801.1575689935065,0.00025370340306410486,25.0,0.0
469.78101,0.09010005905511811,801.4054129464286,0.00025370340306410486,25.0,0.0
471.08228,0.09046123622047243,803.0405844155844,0.00025370340306410486,25.0,0.0
472.38354,0.09086845472440945,804.014153814935,0.00025370340306410486,25.0,0.0
473.68481,0.0912194468503937,801.0923802759739,0.00025370340306410486,25.0,0.0
474.98608,0.0915967342519685,801.2891132305194,0.00025370340306410486,25.0,0.0
476.28735,0.09194811417322835,802.5872818587662,0.00025370340306410486,25.0,0.0
477.58862,0.0923232125984252,803.7445718344156,0.00025370340306410486,25.0,0.0
478.88989,0.09268234251968503,803.6215249594156,0.00025370340306410486,25.0,0.0
480.19116,0.09307817913385827,803.364346590909,0.00025370340306410486,25.0,0.0
481.49243,0.09342966535433071,803.2179383116883,0.00025370340306410486,25.0,0.0
482.7937,0.09379153937007874,803.2932477678571,0.00025370340306410486,25.0,0.0
484.09497,0.09412869881889764,802.6543476055194,0.00025370340306410486,25.0,0.0
485.39624,0.09450769881889763,804.5200131899351,0.00025370340306410486,25.0,0.0
486.69751,0.09488964960629921,804.3257660308441,0.00025370340306410486,25.0,0.0
487.99878,0.09532727559055118,806.5420556006494,0.00025370340306410486,25.0,0.0
489.30005,0.0957605590551181,805.4270748782468,0.00025370340306410486,25.0,0.0
490.60132,0.09609433858267716,805.6100598620129,0.00025370340306410486,25.0,0.0
491.90259,0.09643890157480314,805.5830712256493,0.00025370340306410486,25.0,0.0
493.20386,0.09674106102362205,804.7179383116883,0.00025370340306410486,25.0,0.0
494.50513,0.09710375196850393,805.5703125,0.00025370340306410486,25.0,0.0
495.8064,0.09750819488188976,805.6522930194805,0.00025370340306410486,25.0,0.0
497.10767,0.0978126535433071,805.5125304383116,0.00025370340306410486,25.0,0.0
498.40894,0.09815775590551182,806.7632660308442,0.00025370340306410486,25.0,0.0
499.71021,0.09852206692913386,806.5974786931819,0.00025370340306410486,25.0,0.0
501.01147,0.09891810826771653,806.6042258522726,0.00025370340306410486,25.0,0.0
502.31274,0.09931884448818896,807.478718547078,0.00025370340306410486,25.0,0.0
503.61401,0.09974585039370079,808.2773183847402,0.00025370340306410486,25.0,0.0
504.91528,0.10016379921259842,808.761515827922,0.00025370340306410486,25.0,0.0
506.21655,0.10052537992125984,807.4658329951299,0.00025370340306410486,25.0,0.0
507.51782,0.10087451377952755,807.2295048701299,0.00025370340306410486,25.0,0.0
508.81909,0.1013084311023622,809.923828125,0.00025370340306410486,25.0,0.0
510.12036,0.10176539173228347,809.1000659496754,0.00025370340306410486,25.0,0.0
511.42163,0.10216703149606299,809.141690340909,0.00025370340306410486,25.0,0.0
512.7229,0.1024843090551181,808.3527546672078,0.00025370340306410486,25.0,0.0
514.02417,0.10288002165354332,809.4780083198051,0.00025370340306410486,25.0,0.0
515.32544,0.10326850787401573,809.6168577516233,0.00025370340306410486,25.0,0.0
516.62671,0.10363273031496063,810.1148792613635,0.00025370340306410486,25.0,0.0
517.92798,0.1040473464566929,811.7327008928571,0.00025370340306410486,25.0,0.0
519.22925,0.10440402362204723,808.9590097402596,0.00025370340306410486,25.0,0.0
520.53052,0.10478051771653545,811.0663808847403,0.00025370340306410486,25.0,0.0
521.83179,0.10512857283464566,811.1905438311688,0.00025370340306410486,25.0,0.0
523.13306,0.10548440551181103,811.1678165584415,0.00025370340306410486,25.0,0.0
524.43433,0.10585822440944882,812.5376420454545,0.00025370340306410486,25.0,0.0
525.7356,0.10625504133858267,811.5573254870129,0.00025370340306410486,25.0,0.0
527.03687,0.10657285826771652,810.7206523944806,0.00025370340306410486,25.0,0.0
528.33813,0.10692955905511811,814.5113636363636,0.00025370340306410486,25.0,0.0
529.6394,0.1073803248031496,812.5086495535714,0.00025370340306410486,25.0,0.0
530.94067,0.10776448228346457,813.1376572646104,0.00025370340306410486,25.0,0.0
532.24194,0.10814192716535434,812.1489194399351,0.00025370340306410486,25.0,0.0
533.54321,0.10847795472440946,812.7722199675325,0.00025370340306410486,25.0,0.0
534.84448,0.10880967519685039,813.9417106331168,0.00025370340306410486,25.0,0.0
536.14575,0.10917200787401575,813.7958096590909,0.00025370340306410486,25.0,0.0
537.44702,0.10960429527559055,815.6103388798701,0.00025370340306410486,25.0,0.0
538.74829,0.11005894488188976,816.7314579951297,0.00025370340306410486,25.0,0.0
540.04956,0.11042148818897639,815.9201501623376,0.00025370340306410486,25.0,0.0
541.35083,0.1108035905511811,813.599507913961,0.00025370340306410486,25.0,0.0
542.6521,0.11123306102362204,816.7751623376623,0.00025370340306410486,25.0,0.0
543.95337,0.11159862204724409,814.8091771509739,0.00025370340306410486,25.0,0.0
545.25464,0.11193923622047243,815.4206574675324,0.00025370340306410486,25.0,0.0
546.55591,0.1122846496062992,815.95408887987,0.00025370340306410486,25.0,0.0
547.85718,0.11263682086614174,815.6047585227273,0.00025370340306410486,25.0,0.0
549.15845,0.11303742716535432,816.3115868506493,0.00025370340306410486,25.0,0.0
550.45972,0.11347521653543306,815.2613636363636,0.00025370340306410486,25.0,0.0
551.76099,0.11380856889763778,814.8958248782468,0.00025370340306410486,25.0,0.0
553.06226,0.1141925846456693,816.7535004058442,0.00025370340306410486,25.0,0.0
554.36353,0.11464118110236221,816.8988940746752,0.00025370340306410486,25.0,0.0
555.66479,0.11506296456692913,817.9775517451299,0.00025370340306410486,25.0,0.0
556.96606,0.11543385236220473,818.3745687905844,0.00025370340306410486,25.0,0.0
558.26733,0.11577377362204724,818.1758319805194,0.00025370340306410486,25.0,0.0
559.5686,0.11613809055118111,815.9421418425325,0.00025370340306410486,25.0,0.0
560.86987,0.11647771850393701,819.0366781655845,0.00025370340306410486,25.0,0.0
562.17114,0.11694081692913386,819.152242288961,0.00025370340306410486,25.0,0.0
563.47241,0.11733485236220471,818.538479099026,0.00025370340306410486,25.0,0.0
564.77368,0.11773512992125984,819.0939021915584,0.00025370340306410486,25.0,0.0
566.07495,0.11806866929133858,820.2721185064935,0.00025370340306410486,25.0,0.0
567.37622,0.118416218503937,818.5686891233765,0.00025370340306410486,25.0,0.0
568.67749,0.11876207874015747,817.2393212256494,0.00025370340306410486,25.0,0.0
569.97876,0.11917762204724408,820.7080204951299,0.00025370340306410486,25.0,0.0
571.28003,0.11955788188976378,820.0374898538961,0.00025370340306410486,25.0,0.0
572.5813,0.11992727952755905,819.2323711444805,0.00025370340306410486,25.0,0.0
573.88257,0.12033721456692914,821.2276532061688,0.00025370340306410486,25.0,0.0
575.18384,0.12073587204724409,819.7697849025974,0.00025370340306410486,25.0,0.0
576.48511,0.12111666141732284,820.591112012987,0.00025370340306410486,25.0,0.0
577.78638,0.121525,821.5668374594155,0.00025370340306410486,25.0,0.0
579.08765,0.12191993897637794,819.2217938311687,0.00025370340306410486,25.0,0.0
580.38892,0.12237667716535433,822.1861049107142,0.00025370340306410486,25.0,0.0
581.69019,0.12274705905511812,820.8241933847403,0.00025370340306410486,25.0,0.0
582.99146,0.12309593503937007,822.5283076298701,0.00025370340306410486,25.0,0.0
584.29272,0.12347550393700787,821.3512073863635,0.00025370340306410486,25.0,0.0
585.59399,0.12389550590551182,823.5297280844155,0.00025370340306410486,25.0,0.0
586.89526,0.12426457283464566,821.1012581168831,0.00025370340306410486,25.0,0.0
588.19653,0.12466654133858267,823.0186434659091,0.00025370340306410486,25.0,0.0
589.4978,0.12505645866141732,822.7729809253248,0.00025370340306410486,25.0,0.0
590.79907,0.12546831692913385,824.0307680600649,0.00025370340306410486,25.0,0.0
592.10034,0.1257683464566929,821.9991375811687,0.00025370340306410486,25.0,0.0
593.40161,0.1261583346456693,822.966695413961,0.00025370340306410486,25.0,0.0
594.70288,0.126498281496063,823.2446732954545,0.00025370340306410486,25.0,0.0
596.00415,0.12688930118110237,823.4029017857142,0.00025370340306410486,25.0,0.0
597.30542,0.1272110964566929,825.4774502840909,0.00025370340306410486,25.0,0.0
598.60669,0.1276533090551181,824.0610034496752,0.00025370340306410486,25.0,0.0
599.90796,0.12810449606299212,825.8510551948052,0.00025370340306410486,25.0,0.0
601.20923,0.12852037992125984,825.1265219155844,0.00025370340306410486,25.0,0.0
602.5105,0.1288784311023622,823.5517197646104,0.00025370340306410486,25.0,0.0
603.81177,0.12916958858267716,824.8173701298701,0.00025370340306410486,25.0,0.0
605.11304,0.12959605511811023,825.9755225243506,0.00025370340306410486,25.0,0.0
606.41431,0.13001811023622045,826.4155844155845,0.00025370340306410486,25.0,0.0
607.71558,0.13047408661417323,826.5997615665584,0.00025370340306410486,25.0,0.0
609.01685,0.13087596062992127,823.6715959821429,0.00025370340306410486,25.0,0.0
610.31812,0.13123312992125985,825.7877688717532,0.00025370340306410486,25.0,0.0
611.61938,0.13167946062992125,827.0923295454545,0.00025370340306410486,25.0,0.0
612.92065,0.13207191338582677,825.3624441964286,0.00025370340306410486,25.0,0.0
614.22192,0.1324758996062992,827.6737520292209,0.00025370340306410486,25.0,0.0
615.52319,0.13287347834645669,827.5578327922077,0.00025370340306410486,25.0,0.0
616.82446,0.1333242086614173,827.2601968344156,0.00025370340306410486,25.0,0.0
618.12573,0.13366809842519684,826.2781554383116,0.00025370340306410486,25.0,0.0
619.427,0.1340971811023622,828.3291903409091,0.00025370340306410486,25.0,0.0
620.72827,0.13456519488188975,826.9482802353896,0.00025370340306410486,25.0,0.0
622.02954,0.1349506062992126,828.619242086039,0.00025370340306410486,25.0,0.0
623.33081,0.13530445669291338,827.341213474026,0.00025370340306410486,25.0,0.0
624.63208,0.13567148228346457,826.660638189935,0.00025370340306410486,25.0,0.0
625.93335,0.13608833858267716,827.2091112012986,0.00025370340306410486,25.0,0.0
627.23462,0.13643940748031497,827.3120941558442,0.00025370340306410486,25.0,0.0
628.53589,0.1368295846456693,829.7136262175325,0.00025370340306410486,25.0,0.0
629.83716,0.13722247047244093,827.4845525568181,0.00025370340306410486,25.0,0.0
631.13843,0.13759224212598425,829.1272321428571,0.00025370340306410486,25.0,0.0
632.4397,0.13799167519685038,829.1032112418831,0.00025370340306410486,25.0,0.0
633.74097,0.13842091141732282,828.3730215097402,0.00025370340306410486,25.0,0.0
635.04224,0.13888135629921258,830.4051592938312,0.00025370340306410486,25.0,0.0
636.34351,0.13929271062992124,828.0687905844155,0.00025370340306410486,25.0,0.0
637.64478,0.13966952165354332,827.9483309659091,0.00025370340306410486,25.0,0.0
638.94604,0.14005798622047244,829.3315239448051,0.00025370340306410486,25.0,0.0
640.24731,0.14046272244094488,831.4569805194806,0.00025370340306410486,25.0,0.0
641.54858,0.14089209842519684,828.6237063717532,0.00025370340306410486,25.0,0.0
642.84985,0.14123714763779527,830.7134993912338,0.00025370340306410486,25.0,0.0
644.15112,0.14167984251968505,830.1962256493506,0.00025370340306410486,25.0,0.0
645.45239,0.1420643622047244,830.4420150162338,0.00025370340306410486,25.0,0.0
646.75366,0.1424450688976378,830.2332589285714,0.00025370340306410486,25.0,0.0
648.05493,0.14294629921259844,832.1811586850649,0.00025370340306410486,25.0,0.0
649.3562,0.14332503543307085,831.3448914366883,0.00025370340306410486,25.0,0.0
650.65747,0.14382272244094488,831.461140422078,0.00025370340306410486,25.0,0.0
651.95874,0.14420445078740157,830.466898336039,0.00025370340306410486,25.0,0.0
653.26001,0.14458260039370077,831.1527495941558,0.00025370340306410486,25.0,0.0
654.56128,0.14495894291338582,830.7867035308442,0.00025370340306410486,25.0,0.0
655.86255,0.14538675787401575,832.8380174512987,0.00025370340306410486,25.0,0.0
657.16382,0.14581889173228346,833.260932426948,0.00025370340306410486,25.0,0.0
658.46509,0.14618853346456692,832.3730722402597,0.00025370340306410486,25.0,0.0
659.76636,0.14666728346456692,832.712307224026,0.00025370340306410486,25.0,0.0
661.06763,0.14708892716535432,831.976359577922,0.00025370340306410486,25.0,0.0
662.3689,0.14748040551181102,833.1915584415584,0.00025370340306410486,25.0,0.0
663.67017,0.1478812125984252,833.0195819805194,0.00025370340306410486,25.0,0.0
664.97144,0.1482771023622047,832.0124036120129,0.00025370340306410486,25.0,0.0
666.27271,0.1487129783464567,833.6625152191558,0.00025370340306410486,25.0,0.0
667.57397,0.14908796062992125,832.8082893668831,0.00025370340306410486,25.0,0.0
668.87524,0.14948047047244095,831.7332335633116,0.00025370340306410486,25.0,0.0
670.17651,0.14989394881889764,833.0543323863636,0.00025370340306410486,25.0,0.0
671.47778,0.15031694094488188,835.10057325487,0.00025370340306410486,25.0,0.0
672.77905,0.15070393700787402,833.4263392857142,0.00025370340306410486,25.0,0.0
674.08032,0.1511385590551181,833.4450842126623,0.00025370340306410486,25.0,0.0
675.38159,0.15154176968503938,833.7317623782468,0.00025370340306410486,25.0,0.0
676.68286,0.1519492066929134,834.5982396509739,0.00025370340306410486,25.0,0.0
677.98413,0.15239869291338584,834.3682274756494,0.00025370340306410486,25.0,0.0
679.2854,0.15279660039370077,833.1023234577922,0.00025370340306410486,25.0,0.0
680.58667,0.1531906594488189,834.4073660714286,0.00025370340306410486,25.0,0.0
681.88794,0.1536154842519685,834.5942065746754,0.00025370340306410486,25.0,0.0
683.18921,0.15403397244094488,833.7711292613636,0.00025370340306410486,25.0,0.0
684.49048,0.1544684527559055,834.332132711039,0.00025370340306410486,25.0,0.0
685.79175,0.15494527755905513,835.3421519886364,0.00025370340306410486,25.0,0.0
687.09302,0.15540426968503937,834.7404880275974,0.00025370340306410486,25.0,0.0
688.39429,0.15587801968503937,836.1173650568181,0.00025370340306410486,25.0,0.0
689.69556,0.1562842342519685,834.9696124188312,0.00025370340306410486,25.0,0.0
690.99683,0.15670909448818895,834.9648944805195,0.00025370340306410486,25.0,0.0
692.2981,0.157190531496063,834.7563413149351,0.00025370340306410486,25.0,0.0
693.59937,0.15763388188976377,833.200284090909,0.00025370340306410486,25.0,0.0
694.90063,0.15801646653543308,834.8332487824675,0.00025370340306410486,25.0,0.0
696.2019,0.15839304330708662,833.3335531655844,0.00025370340306410486,25.0,0.0
697.50317,0.15879416535433072,837.6352475649351,0.00025370340306410486,25.0,0.0
698.80444,0.1592592342519685,836.5947646103897,0.00025370340306410486,25.0,0.0
700.10571,0.15973583661417323,837.5445921266235,0.00025370340306410486,25.0,0.0
701.40698,0.16017753346456692,834.9501572646103,0.00025370340306410486,25.0,0.0
702.70825,0.16058939173228345,837.163479099026,0.00025370340306410486,25.0,0.0
704.00952,0.16095520866141733,836.7002079951299,0.00025370340306410486,25.0,0.0
705.31079,0.1614173562992126,837.2374949269481,0.00025370340306410486,25.0,0.0
706.61206,0.16183133858267718,835.6020698051948,0.00025370340306410486,25.0,0.0
707.91333,0.1622463188976378,836.4631696428571,0.00025370340306410486,25.0,0.0
709.2146,0.1627321909448819,836.5520748782467,0.00025370340306410486,25.0,0.0
710.51587,0.16319613385826773,838.1497311282467,0.00025370340306410486,25.0,0.0
711.81714,0.16367281692913385,836.5432224025973,0.00025370340306410486,25.0,0.0
713.11841,0.16415385433070867,839.9216467126623,0.00025370340306410486,25.0,0.0
714.41968,0.16456107874015746,836.3287084009739,0.00025370340306410486,25.0,0.0
715.72095,0.16495545472440945,837.0915432224026,0.00025370340306410486,25.0,0.0
717.02222,0.16537591535433072,837.8032670454545,0.00025370340306410486,25.0,0.0
718.32349,0.16582894488188976,837.7283887987013,0.00025370340306410486,25.0,0.0
719.62476,0.16625781692913386,838.002054586039,0.00025370340306410486,25.0,0.0
720.92603,0.16678430905511812,839.6435420048701,0.00025370340306410486,25.0,0.0
722.22729,0.1672379153543307,839.6819450081168,0.00025370340306410486,25.0,0.0
723.52856,0.16767360236220472,837.9379565746754,0.00025370340306410486,25.0,0.0
724.82983,0.16811538188976377,838.3030641233765,0.00025370340306410486,25.0,0.0
726.1311,0.1685479842519685,837.7837611607143,0.00025370340306410486,25.0,0.0
727.43237,0.16898293503937006,839.5772118506493,0.00025370340306410486,25.0,0.0
728.73364,0.16940637401574804,838.9671012581169,0.00025370340306410486,25.0,0.0
730.03491,0.1698298720472441,838.6570363230519,0.00025370340306410486,25.0,0.0
731.33618,0.17031480511811023,838.5442877435064,0.00025370340306410486,25.0,0.0
732.63745,0.17079835236220473,840.2983461850649,0.00025370340306410486,25.0,0.0
733.93872,0.17131080118110237,839.0119470373376,0.00025370340306410486,25.0,0.0
735.23999,0.1717460905511811,839.4094460227273,0.00025370340306410486,25.0,0.0
736.54126,0.1721361850393701,836.9389965503246,0.00025370340306410486,25.0,0.0
737.84253,0.17249739173228346,839.7046722808442,0.00025370340306410486,25.0,0.0
739.1438,0.17290090748031495,839.1139914772727,0.00025370340306410486,25.0,0.0
740.44507,0.1732755472440945,838.6867644074675,0.00025370340306410486,25.0,0.0
741.74634,0.17377127559055117,840.8399705762986,0.00025370340306410486,25.0,0.0
743.04761,0.17420617913385827,838.5865716314935,0.00025370340306410486,25.0,0.0
744.34888,0.1746474527559055,838.9677861201299,0.00025370340306410486,25.0,0.0
745.65015,0.17514356692913385,841.767375202922,0.00025370340306410486,25.0,0.0
746.95142,0.17566723228346456,840.4226359577922,0.00025370340306410486,25.0,0.0
748.25269,0.17613414173228348,838.8591213474025,0.00025370340306410486,25.0,0.0
749.55396,0.17657655511811024,839.1411830357142,0.00025370340306410486,25.0,0.0
750.85522,0.1770213838582677,839.583400974026,0.00025370340306410486,25.0,0.0
752.15649,0.17752523031496065,841.6262428977273,0.00025370340306410486,25.0,0.0
753.45776,0.17803680905511812,840.0909598214286,0.00025370340306410486,25.0,0.0
754.75903,0.17854885826771652,838.8195515422077,0.00025370340306410486,25.0,0.0
756.0603,0.17896231299212598,839.3683289366883,0.00025370340306410486,25.0,0.0
757.36157,0.179526187007874,840.7555549918831,0.00025370340306410486,25.0,0.0
758.66284,0.1800031062992126,840.2716619318181,0.00025370340306410486,25.0,0.0
759.96411,0.18037921259842518,839.0516943993506,0.00025370340306410486,25.0,0.0
761.26538,0.18088973622047244,840.4394784902597,0.00025370340306410486,25.0,0.0
762.56665,0.18133455314960628,838.865614853896,0.00025370340306410486,25.0,0.0
763.86792,0.1818493838582677,840.8992238230519,0.00025370340306410486,25.0,0.0
765.16919,0.18237278937007873,840.5726207386364,0.00025370340306410486,25.0,0.0
766.47046,0.18280313976377952,839.6772270698051,0.00025370340306410486,25.0,0.0
767.77173,0.1832829094488189,841.1080560064935,0.00025370340306410486,25.0,0.0
769.073,0.18385473818897638,841.9039924918831,0.00025370340306410486,25.0,0.0
770.37427,0.1843163818897638,839.4668729707793,0.00025370340306410486,25.0,0.0
771.67554,0.1847367125984252,841.6434659090909,0.00025370340306410486,25.0,0.0
772.97681,0.1851625688976378,839.0725700081168,0.00025370340306410486,25.0,0.0
774.27808,0.1855556653543307,839.902445211039,0.00025370340306410486,25.0,0.0
775.57935,0.1860600059055118,841.3323609983765,0.00025370340306410486,25.0,0.0
776.88062,0.1866409625984252,841.7564174107142,0.00025370340306410486,25.0,0.0
778.18188,0.18716149409448818,842.7972301136363,0.00025370340306410486,25.0,0.0
779.48315,0.18767790748031496,842.8384232954545,0.00025370340306410486,25.0,0.0
780.78442,0.18810871456692912,839.2766335227273,0.00025370340306410486,25.0,0.0
782.08569,0.1886553996062992,840.8250558035714,0.00025370340306410486,25.0,0.0
783.38696,0.18920723622047242,840.6300984172078,0.00025370340306410486,25.0,0.0
784.68823,0.18972526771653545,840.7618709415584,0.00025370340306410486,25.0,0.0
785.9895,0.19023540354330706,841.6901633522727,0.00025370340306410486,25.0,0.0
787.29077,0.19073480511811022,841.7404372970778,0.00025370340306410486,25.0,0.0
788.59204,0.1912365157480315,842.3026836444806,0.00025370340306410486,25.0,0.0
789.89331,0.19177303937007875,841.5433238636364,0.00025370340306410486,25.0,0.0
791.19458,0.19229675196850393,841.0684101055195,0.00025370340306410486,25.0,0.0
792.49585,0.1927144527559055,840.7234172077922,0.00025370340306410486,25.0,0.0
793.79712,0.19323505511811023,842.6851410308441,0.00025370340306410486,25.0,0.0
795.09839,0.19373201574803148,841.234577922078,0.00025370340306410486,25.0,0.0
796.39966,0.19430006496062993,841.6019176136364,0.00025370340306410486,25.0,0.0
797.70093,0.19482140748031496,840.2495687905845,0.00025370340306410486,25.0,0.0
799.0022,0.19537860433070867,841.9369926948051,0.00025370340306410486,25.0,0.0
800.30347,0.1959496712598425,841.7144886363636,0.00025370340306410486,25.0,0.0
801.60474,0.19646856102362203,843.0589234983765,0.00025370340306410486,25.0,0.0
802.90601,0.1969688779527559,841.5654423701299,0.00025370340306410486,25.0,0.0
804.20728,0.19747476377952758,842.0165888798701,0.00025370340306410486,25.0,0.0
805.50854,0.1979725,841.8816456980519,0.00025370340306410486,25.0,0.0
806.80981,0.19841072834645668,839.9985795454545,0.00025370340306410486,25.0,0.0
808.11108,0.19887856299212597,840.7921570616883,0.00025370340306410486,25.0,0.0
809.41235,0.1994092716535433,841.5661779626623,0.00025370340306410486,25.0,0.0
810.71362,0.19991181102362204,841.4545200892857,0.00025370340306410486,25.0,0.0
812.01489,0.2004011614173228,840.6973417207793,0.00025370340306410486,25.0,0.0
813.31616,0.20089328740157483,842.2603743912338,0.00025370340306410486,25.0,0.0
814.61743,0.2014413582677165,840.7612621753246,0.00025370340306410486,25.0,0.0
815.9187,0.20200832677165353,842.0687144886363,0.00025370340306410486,25.0,0.0
817.21997,0.202545531496063,841.439351663961,0.00025370340306410486,25.0,0.0
818.52124,0.20305153543307086,840.741020698052,0.00025370340306410486,25.0,0.0
819.82251,0.20357897637795275,843.215046672078,0.00025370340306410486,25.0,0.0
821.12378,0.20413218503937008,841.5632102272727,0.00025370340306410486,25.0,0.0
822.42505,0.2046957086614173,841.7678064123376,0.00025370340306410486,25.0,0.0
823.32593,0.20508785433070867,844.3241680194805,0.00025370340306410486,25.0,0.0