File: datasets/am_bench_2022/csv/0-XY.20-4.csv
Time(s),Strain(%),Stress(MPa),SR(s-1),Temp(C),Angle(deg)
13.475586,4.262753740157481e-06,17.227022204908454,0.00025370340306410486,25.0,0.0
15.077148,1.6507811417322835e-05,22.660819633813794,0.00025370340306410486,25.0,0.0
16.378418,6.067815157480314e-05,27.71240098688482,0.00025370340306410486,25.0,0.0
17.679688,0.00010857362795275591,32.18092455525257,0.00025370340306410486,25.0,0.0
18.980957,7.173984251968504e-05,35.20306973120374,0.00025370340306410486,25.0,0.0
20.282227,8.315948622047243e-05,39.20025970653162,0.00025370340306410486,25.0,0.0
21.583496,9.964816929133859e-05,45.25263472276328,0.00025370340306410486,25.0,0.0
22.884766,0.00013229741929133857,50.300550577847034,0.00025370340306410486,25.0,0.0
24.186035,0.00015084368700787402,56.77916893909882,0.00025370340306410486,25.0,0.0
25.487305,0.0001674775688976378,62.83953772237372,0.00025370340306410486,25.0,0.0
26.788574,0.0002007041929133858,69.95064796779639,0.00025370340306410486,25.0,0.0
28.089844,0.00022564501968503934,76.00638878067784,0.00025370340306410486,25.0,0.0
29.391113,0.0002624056102362205,83.45640306453708,0.00025370340306410486,25.0,0.0
30.692383,0.00026519017716535433,90.7617971691988,0.00025370340306410486,25.0,0.0
31.993652,0.00029994220472440944,95.84619140371382,0.00025370340306410486,25.0,0.0
33.294922,0.00033224923228346455,106.20285936891312,0.00025370340306410486,25.0,0.0
34.596191,0.0003450853543307087,113.29557979483184,0.00025370340306410486,25.0,0.0
35.897461,0.00038506773622047245,119.2173691728347,0.00025370340306410486,25.0,0.0
37.19873,0.00040655287401574803,125.48768731333594,0.00025370340306410486,25.0,0.0
38.5,0.00045407163385826764,136.46074016361513,0.00025370340306410486,25.0,0.0
39.80127,0.0004673328543307086,142.2034644851318,0.00025370340306410486,25.0,0.0
41.102539,0.0005321324606299213,152.1276509544215,0.00025370340306410486,25.0,0.0
42.403809,0.0005305296456692913,160.80740163615116,0.00025370340306410486,25.0,0.0
43.705078,0.0005774896259842519,171.63350733670953,0.00025370340306410486,25.0,0.0
45.006348,0.0005921213779527559,181.05902869757173,0.00025370340306410486,25.0,0.0
46.307617,0.000618706968503937,186.86829762368524,0.00025370340306410486,25.0,0.0
47.608887,0.0006758013385826772,196.8650486949747,0.00025370340306410486,25.0,0.0
48.910156,0.0006897708661417323,206.38410855733022,0.00025370340306410486,25.0,0.0
50.211426,0.0007336413385826772,213.38810024672122,0.00025370340306410486,25.0,0.0
51.512695,0.0007692289960629921,222.913182703545,0.00025370340306410486,25.0,0.0
52.813965,0.0008035962598425197,233.21673548889754,0.00025370340306410486,25.0,0.0
54.115234,0.0008370278149606299,241.62356057654853,0.00025370340306410486,25.0,0.0
55.416504,0.0008638537598425197,249.34686664069602,0.00025370340306410486,25.0,0.0
56.717773,0.0009034834448818899,260.0254772107519,0.00025370340306410486,25.0,0.0
58.019043,0.0009230884448818898,271.3407869107908,0.00025370340306410486,25.0,0.0
59.320313,0.0009697424803149605,280.3190494740943,0.00025370340306410486,25.0,0.0
60.621582,0.001008372657480315,291.84698091157,0.00025370340306410486,25.0,0.0
61.922852,0.0010835130511811022,303.15943383976105,0.00025370340306410486,25.0,0.0
63.224121,0.001115379409448819,315.1603947539281,0.00025370340306410486,25.0,0.0
64.525391,0.0011196595669291337,320.0509544215037,0.00025370340306410486,25.0,0.0
65.82666,0.001155060905511811,330.16792624334505,0.00025370340306410486,25.0,0.0
67.12793,0.0011934751181102363,339.6657317231529,0.00025370340306410486,25.0,0.0
68.429199,0.0012382111417322834,349.3312816517336,0.00025370340306410486,25.0,0.0
69.730469,0.0012584949212598425,355.8523828074276,0.00025370340306410486,25.0,0.0
71.031738,0.0013074690944881889,366.226308271653,0.00025370340306410486,25.0,0.0
72.333008,0.0013536416141732282,377.17436696532917,0.00025370340306410486,25.0,0.0
73.634277,0.0013925414763779527,386.86365407089994,0.00025370340306410486,25.0,0.0
74.935547,0.0014319895866141733,394.9422152967147,0.00025370340306410486,25.0,0.0
76.236816,0.0014693455118110236,405.1671990650565,0.00025370340306410486,25.0,0.0
77.538086,0.001521486377952756,414.2593689131282,0.00025370340306410486,25.0,0.0
78.839355,0.0015302370472440945,423.43596935462926,0.00025370340306410486,25.0,0.0
80.140625,0.0015752624606299212,431.32297104272175,0.00025370340306410486,25.0,0.0
81.441895,0.0016313922637795275,441.18654720166217,0.00025370340306410486,25.0,0.0
82.743164,0.0016603171456692914,448.9320867419816,0.00025370340306410486,25.0,0.0
84.044434,0.0016822554921259844,460.6672899623426,0.00025370340306410486,25.0,0.0
85.345703,0.0017334719881889763,467.7796390079211,0.00025370340306410486,25.0,0.0
86.646973,0.0017828953346456693,475.25744708479425,0.00025370340306410486,25.0,0.0
87.948242,0.0018357775984251968,484.7422412673679,0.00025370340306410486,25.0,0.0
89.249512,0.0018620339173228348,493.8010647967797,0.00025370340306410486,25.0,0.0
90.550781,0.0019070681299212596,502.1939748084664,0.00025370340306410486,25.0,0.0
91.852051,0.001967876712598425,511.2357875600572,0.00025370340306410486,25.0,0.0
93.15332,0.001997296653543307,516.8412933385275,0.00025370340306410486,25.0,0.0
94.45459,0.002025973031496063,525.5867289962342,0.00025370340306410486,25.0,0.0
95.755859,0.002079941929133858,530.6987663939748,0.00025370340306410486,25.0,0.0
97.057129,0.002104043503937008,537.793896896507,0.00025370340306410486,25.0,0.0
98.358398,0.0021633017716535434,546.4844825347358,0.00025370340306410486,25.0,0.0
99.659668,0.0022095307086614172,552.4380210362291,0.00025370340306410486,25.0,0.0
100.96094,0.0022404592519685036,561.003194390339,0.00025370340306410486,25.0,0.0
102.26221,0.0023025872047244093,565.9232826905596,0.00025370340306410486,25.0,0.0
103.56348,0.002319568897637795,571.1410206466693,0.00025370340306410486,25.0,0.0
104.86475,0.002386434251968504,577.7830671341385,0.00025370340306410486,25.0,0.0
106.16602,0.0024356194881889766,583.6542267238021,0.00025370340306410486,25.0,0.0
107.46729,0.002518536614173228,588.7317491234904,0.00025370340306410486,25.0,0.0
108.76855,0.0025459740157480312,595.6971562134788,0.00025370340306410486,25.0,0.0
110.06982,0.002570799409448819,597.7760290871316,0.00025370340306410486,25.0,0.0
111.37109,0.002650537992125984,603.8836255031815,0.00025370340306410486,25.0,0.0
112.67236,0.0026841956692913384,607.6322555512272,0.00025370340306410486,25.0,0.0
113.97363,0.002736712401574803,613.5136216075834,0.00025370340306410486,25.0,0.0
115.2749,0.002778596653543307,615.5919231268666,0.00025370340306410486,25.0,0.0
116.57617,0.0028428568897637795,623.0822490585638,0.00025370340306410486,25.0,0.0
117.87744,0.0029009354330708664,626.0160758343073,0.00025370340306410486,25.0,0.0
119.17871,0.0029721421259842518,629.6926632904818,0.00025370340306410486,25.0,0.0
120.47998,0.0030457143700787404,635.5926762758083,0.00025370340306410486,25.0,0.0
121.78125,0.0030928265748031494,640.2082326970524,0.00025370340306410486,25.0,0.0
123.08252,0.003176911417322835,644.4561745227893,0.00025370340306410486,25.0,0.0
124.38379,0.003250134251968504,648.3266588754708,0.00025370340306410486,25.0,0.0
125.68506,0.003318716338582677,649.605609661083,0.00025370340306410486,25.0,0.0
126.98633,0.0033940958661417323,653.5121672510063,0.00025370340306410486,25.0,0.0
128.2876,0.003491204921259842,659.3102454226724,0.00025370340306410486,25.0,0.0
129.58887,0.0035870259842519683,661.8785092845086,0.00025370340306410486,25.0,0.0
130.89014,0.003654170669291338,664.0399948058694,0.00025370340306410486,25.0,0.0
132.19141,0.003809371062992126,669.3496429035191,0.00025370340306410486,25.0,0.0
133.49268,0.0038964773622047243,671.0552915205818,0.00025370340306410486,25.0,0.0
134.79395,0.0039978913385826775,672.9861836125178,0.00025370340306410486,25.0,0.0
136.09521,0.004097920866141733,675.673133359304,0.00025370340306410486,25.0,0.0
137.39648,0.004232209448818898,679.1247110764837,0.00025370340306410486,25.0,0.0
138.69775,0.0043965964566929135,682.1080379171536,0.00025370340306410486,25.0,0.0
139.99902,0.004540244488188977,682.9885469419556,0.00025370340306410486,25.0,0.0
141.30029,0.0046610675196850394,684.906479677964,0.00025370340306410486,25.0,0.0
142.60156,0.004813930511811023,686.8252954161798,0.00025370340306410486,25.0,0.0
143.90283,0.005015462401574803,689.3949876639398,0.00025370340306410486,25.0,0.0
145.2041,0.00519601062992126,692.6976236852357,0.00025370340306410486,25.0,0.0
146.50537,0.005384915551181102,692.2962732112712,0.00025370340306410486,25.0,0.0
147.80664,0.005602772834645669,696.6893909881834,0.00025370340306410486,25.0,0.0
149.10791,0.005780066535433071,697.5633813790417,0.00025370340306410486,25.0,0.0
150.40918,0.005998257086614173,698.9705752499675,0.00025370340306410486,25.0,0.0
151.71045,0.00624831437007874,700.5822620438904,0.00025370340306410486,25.0,0.0
153.01172,0.006460149015748031,702.1736657576938,0.00025370340306410486,25.0,0.0
154.31299,0.006692841141732284,706.2310868718348,0.00025370340306410486,25.0,0.0
155.61426,0.0069283653543307094,707.2222308791066,0.00025370340306410486,25.0,0.0
156.91553,0.007231431692913386,706.5913517724971,0.00025370340306410486,25.0,0.0
158.2168,0.0075331470472440945,710.01059602649,0.00025370340306410486,25.0,0.0
159.51807,0.007805058070866141,710.9141669912999,0.00025370340306410486,25.0,0.0
160.81934,0.008073144094488189,714.2215037008181,0.00025370340306410486,25.0,0.0
162.12061,0.008360361023622047,713.3574081288145,0.00025370340306410486,25.0,0.0
163.42188,0.008635142322834645,710.4962732112713,0.00025370340306410486,25.0,0.0
164.72314,0.008915987401574803,716.9596935462927,0.00025370340306410486,25.0,0.0
166.02441,0.009192681102362205,716.2330866121283,0.00025370340306410486,25.0,0.0
167.32568,0.009466661417322834,718.8499155953772,0.00025370340306410486,25.0,0.0
168.62695,0.009807048818897638,719.3205298013245,0.00025370340306410486,25.0,0.0
169.92822,0.010123705905511812,721.6727178288535,0.00025370340306410486,25.0,0.0
171.22949,0.010441332283464567,720.3607323724192,0.00025370340306410486,25.0,0.0
172.53076,0.010707756692913385,719.6513699519544,0.00025370340306410486,25.0,0.0
173.83203,0.011002250393700787,722.2612907414623,0.00025370340306410486,25.0,0.0
175.1333,0.01132336377952756,724.1492533437216,0.00025370340306410486,25.0,0.0
176.43457,0.011643644094488188,724.6039735099338,0.00025370340306410486,25.0,0.0
177.73584,0.01202445531496063,727.5754057914558,0.00025370340306410486,25.0,0.0
179.03711,0.012367573622047245,728.8537592520452,0.00025370340306410486,25.0,0.0
180.33838,0.012757123228346457,729.2676016101805,0.00025370340306410486,25.0,0.0
181.63965,0.013106146259842522,727.5957408128814,0.00025370340306410486,25.0,0.0
182.94092,0.013414771850393702,727.9263991689392,0.00025370340306410486,25.0,0.0
184.24219,0.013720687007874014,730.2663550188288,0.00025370340306410486,25.0,0.0
185.54346,0.014045032283464565,731.1450201272563,0.00025370340306410486,25.0,0.0
186.84473,0.014410230905511813,733.0089339046876,0.00025370340306410486,25.0,0.0
188.146,0.014766877755905511,734.0117647058825,0.00025370340306410486,25.0,0.0
189.44727,0.015155360826771654,734.8157382158162,0.00025370340306410486,25.0,0.0
190.74854,0.015477608858267714,732.3317750941436,0.00025370340306410486,25.0,0.0
192.0498,0.01583654783464567,734.3890144137126,0.00025370340306410486,25.0,0.0
193.35107,0.016214166141732284,734.7783924165693,0.00025370340306410486,25.0,0.0
194.65234,0.016596922047244094,737.3594078691079,0.00025370340306410486,25.0,0.0
195.95361,0.01701297992125984,737.4042332164654,0.00025370340306410486,25.0,0.0
197.25488,0.01734460846456693,737.433528113232,0.00025370340306410486,25.0,0.0
198.55615,0.0176630781496063,738.0085962861966,0.00025370340306410486,25.0,0.0
199.85742,0.018023934251968503,739.855161667316,0.00025370340306410486,25.0,0.0
201.15869,0.018328972440944884,741.8011686793924,0.00025370340306410486,25.0,0.0
202.45996,0.018740979330708663,740.1355927801585,0.00025370340306410486,25.0,0.0
203.76123,0.019094997637795274,740.6456823789119,0.00025370340306410486,25.0,0.0
205.0625,0.01949973720472441,742.5782625633035,0.00025370340306410486,25.0,0.0
206.36377,0.019897094488188976,740.2897286066745,0.00025370340306410486,25.0,0.0
207.66504,0.020284297244094487,742.9482924295546,0.00025370340306410486,25.0,0.0
208.96631,0.02065376377952756,744.1185560316843,0.00025370340306410486,25.0,0.0
210.26758,0.02102228149606299,744.0731593299572,0.00025370340306410486,25.0,0.0
211.56885,0.021371157480314963,743.5556421243995,0.00025370340306410486,25.0,0.0
212.87012,0.021737844488188978,745.0041293338527,0.00025370340306410486,25.0,0.0
214.17139,0.0220976968503937,743.6272951564731,0.00025370340306410486,25.0,0.0
215.47266,0.022507637795275592,745.4609790936242,0.00025370340306410486,25.0,0.0
216.77393,0.022939348425196848,747.5413582651604,0.00025370340306410486,25.0,0.0
218.0752,0.023309661417322835,747.9102973639787,0.00025370340306410486,25.0,0.0
219.37646,0.023648816929133856,747.8291390728476,0.00025370340306410486,25.0,0.0
220.67773,0.02407157874015748,748.2580703804701,0.00025370340306410486,25.0,0.0
221.979,0.02446111811023622,751.1704453967018,0.00025370340306410486,25.0,0.0
223.28027,0.024853824803149606,749.7829632515258,0.00025370340306410486,25.0,0.0
224.58154,0.025277003937007877,749.8031164783795,0.00025370340306410486,25.0,0.0
225.88281,0.02566423818897638,751.8167510712894,0.00025370340306410486,25.0,0.0
227.18408,0.02606938779527559,751.1213089209193,0.00025370340306410486,25.0,0.0
228.48535,0.02639203937007874,751.781223217764,0.00025370340306410486,25.0,0.0
229.78662,0.026817387795275593,751.6318400207765,0.00025370340306410486,25.0,0.0
231.08789,0.027214448818897636,753.2995195429165,0.00025370340306410486,25.0,0.0
232.38916,0.02757395866141732,752.0049863654071,0.00025370340306410486,25.0,0.0
233.69043,0.028002722440944882,755.2678613167121,0.00025370340306410486,25.0,0.0
234.9917,0.02839393307086614,753.759407869108,0.00025370340306410486,25.0,0.0
236.29297,0.02878842125984252,754.4853395662901,0.00025370340306410486,25.0,0.0
237.59424,0.029156084645669288,753.9550707700298,0.00025370340306410486,25.0,0.0
238.89551,0.029597015748031492,757.166471886768,0.00025370340306410486,25.0,0.0
240.19678,0.030000980314960627,756.6959355927803,0.00025370340306410486,25.0,0.0
241.49805,0.030410503937007873,755.8561485521361,0.00025370340306410486,25.0,0.0
242.79932,0.030787303149606298,756.9632515257758,0.00025370340306410486,25.0,0.0
244.10059,0.031241641732283467,758.9410985586288,0.00025370340306410486,25.0,0.0
245.40186,0.03166168307086614,758.1442929489676,0.00025370340306410486,25.0,0.0
246.70313,0.03198729330708661,758.8468770289572,0.00025370340306410486,25.0,0.0
248.00439,0.03228333661417323,757.0633164524088,0.00025370340306410486,25.0,0.0
249.30566,0.03265686220472441,758.3797948318401,0.00025370340306410486,25.0,0.0
250.60693,0.03308250590551181,758.882275029217,0.00025370340306410486,25.0,0.0
251.9082,0.03344510236220472,761.995195429165,0.00025370340306410486,25.0,0.0
253.20947,0.03387867322834646,762.0068562524348,0.00025370340306410486,25.0,0.0
254.51074,0.034340779527559054,762.5684975977147,0.00025370340306410486,25.0,0.0
255.81201,0.03472371456692913,760.8768471627062,0.00025370340306410486,25.0,0.0
257.11328,0.03505223031496063,759.0572652902221,0.00025370340306410486,25.0,0.0
258.41455,0.03542573031496063,763.2776262823011,0.00025370340306410486,25.0,0.0
259.71582,0.0358539094488189,763.894611089469,0.00025370340306410486,25.0,0.0
261.01709,0.03625029527559055,763.8771068692378,0.00025370340306410486,25.0,0.0
262.31836,0.03662176181102362,764.9015452538632,0.00025370340306410486,25.0,0.0
263.61963,0.03706676968503937,765.3503960524607,0.00025370340306410486,25.0,0.0
264.9209,0.037427842519685034,764.4571354369563,0.00025370340306410486,25.0,0.0
266.22217,0.037834588582677166,765.3037267887288,0.00025370340306410486,25.0,0.0
267.52344,0.0382186220472441,764.897363978704,0.00025370340306410486,25.0,0.0
268.82471,0.0386116594488189,765.6988702765875,0.00025370340306410486,25.0,0.0
270.12598,0.03900177165354331,765.457732761979,0.00025370340306410486,25.0,0.0
271.42725,0.039393131889763774,765.6734969484484,0.00025370340306410486,25.0,0.0
272.72852,0.039830395669291335,768.4477340605116,0.00025370340306410486,25.0,0.0
274.02979,0.04020481102362205,768.3113361901052,0.00025370340306410486,25.0,0.0
275.33105,0.04063307874015748,768.9204778600183,0.00025370340306410486,25.0,0.0
276.63232,0.04103045866141732,770.0944033242437,0.00025370340306410486,25.0,0.0
277.93359,0.041499531496062995,770.77930138943,0.00025370340306410486,25.0,0.0
279.23486,0.04190441535433071,767.7275678483314,0.00025370340306410486,25.0,0.0
280.53613,0.04230039173228346,770.300220750552,0.00025370340306410486,25.0,0.0
281.8374,0.04271277952755905,770.1962342552916,0.00025370340306410486,25.0,0.0
283.13867,0.04307666141732283,770.3793533307363,0.00025370340306410486,25.0,0.0
284.43994,0.0433780905511811,769.9166342033502,0.00025370340306410486,25.0,0.0
285.74121,0.04371886614173229,770.7450201272563,0.00025370340306410486,25.0,0.0
287.04248,0.04406485433070866,770.475211011557,0.00025370340306410486,25.0,0.0
288.34375,0.044442860236220474,772.1259576678353,0.00025370340306410486,25.0,0.0
289.64502,0.04479170275590551,772.1373068432672,0.00025370340306410486,25.0,0.0
290.94629,0.04528946850393701,772.4018439163746,0.00025370340306410486,25.0,0.0
292.24756,0.04567555905511811,774.244903259317,0.00025370340306410486,25.0,0.0
293.54883,0.046146781496062994,772.1676145955072,0.00025370340306410486,25.0,0.0
294.8501,0.046530604330708665,774.0434489027399,0.00025370340306410486,25.0,0.0
296.15137,0.04696700196850394,774.3519283209973,0.00025370340306410486,25.0,0.0
297.45264,0.04737496850393701,776.3404233216465,0.00025370340306410486,25.0,0.0
298.75391,0.047761322834645674,775.2781976366706,0.00025370340306410486,25.0,0.0
300.05518,0.04817579527559055,775.4409557200364,0.00025370340306410486,25.0,0.0
301.35645,0.04856166929133858,775.7451759511753,0.00025370340306410486,25.0,0.0
302.65771,0.04894296653543307,776.0457862615245,0.00025370340306410486,25.0,0.0
303.95898,0.04937780118110237,779.810258407999,0.00025370340306410486,25.0,0.0
305.26025,0.049821118110236214,778.2390338917023,0.00025370340306410486,25.0,0.0
306.56152,0.050142137795275585,776.2318140501234,0.00025370340306410486,25.0,0.0
307.86279,0.05052340748031496,776.8930788209325,0.00025370340306410486,25.0,0.0
309.16406,0.05097050787401575,777.3763407349695,0.00025370340306410486,25.0,0.0
310.46533,0.05132615157480315,777.1943124269575,0.00025370340306410486,25.0,0.0
311.7666,0.05175096456692913,779.8257888585898,0.00025370340306410486,25.0,0.0
313.06787,0.05217679133858268,779.8391118036619,0.00025370340306410486,25.0,0.0
314.36914,0.05258424409448819,778.4146474483834,0.00025370340306410486,25.0,0.0
315.67041,0.05293700196850394,780.2970783015193,0.00025370340306410486,25.0,0.0
316.97168,0.05338294094488189,781.1837943124269,0.00025370340306410486,25.0,0.0
318.27295,0.05376791929133858,781.6991559537723,0.00025370340306410486,25.0,0.0
319.57422,0.05415325984251968,780.770964809765,0.00025370340306410486,25.0,0.0
320.87549,0.054536706692913384,782.1564472146475,0.00025370340306410486,25.0,0.0
322.17676,0.054890667322834645,781.5033112582781,0.00025370340306410486,25.0,0.0
323.47803,0.05522910039370079,781.2252694455266,0.00025370340306410486,25.0,0.0
324.7793,0.055586375984251965,782.2225165562915,0.00025370340306410486,25.0,0.0
326.08057,0.055997578740157476,783.8102843786521,0.00025370340306410486,25.0,0.0
327.38184,0.05640853346456692,782.7385534346189,0.00025370340306410486,25.0,0.0
328.68311,0.05672587007874016,782.6610050642773,0.00025370340306410486,25.0,0.0
329.98438,0.05716837598425197,786.3213089209194,0.00025370340306410486,25.0,0.0
331.28564,0.05756040551181102,786.2266458901441,0.00025370340306410486,25.0,0.0
332.58691,0.057915915354330716,785.0929749383198,0.00025370340306410486,25.0,0.0
333.88818,0.058307435039370074,785.9027918452149,0.00025370340306410486,25.0,0.0
335.18945,0.05871712795275591,786.2176600441501,0.00025370340306410486,25.0,0.0
336.49072,0.05911616338582677,784.5795870666149,0.00025370340306410486,25.0,0.0
337.79199,0.059531687007874014,788.8531878976758,0.00025370340306410486,25.0,0.0
339.09326,0.059945899606299216,787.4917802882743,0.00025370340306410486,25.0,0.0
340.39453,0.06037237795275591,787.910816777042,0.00025370340306410486,25.0,0.0
341.6958,0.060819757874015744,788.2549798727439,0.00025370340306410486,25.0,0.0
342.99707,0.0612343562992126,788.481963381379,0.00025370340306410486,25.0,0.0
344.29834,0.06160376968503937,786.7039085833009,0.00025370340306410486,25.0,0.0
345.59961,0.06199263779527559,787.615400597325,0.00025370340306410486,25.0,0.0
346.90088,0.0623327125984252,788.9683417737956,0.00025370340306410486,25.0,0.0
348.20215,0.06270345866141731,789.2186728996235,0.00025370340306410486,25.0,0.0
349.50342,0.06311866732283464,790.6781197247111,0.00025370340306410486,25.0,0.0
350.80469,0.06350035433070865,790.3137254901961,0.00025370340306410486,25.0,0.0
352.10596,0.06393212992125984,792.0104402025711,0.00025370340306410486,25.0,0.0
353.40723,0.06434109645669292,790.6837034151409,0.00025370340306410486,25.0,0.0
354.7085,0.06471137204724409,789.6498117127646,0.00025370340306410486,25.0,0.0
356.00977,0.06506427755905511,791.1823139851969,0.00025370340306410486,25.0,0.0
357.31104,0.06545308070866142,791.5009219581873,0.00025370340306410486,25.0,0.0
358.6123,0.06580914173228346,792.2876509544215,0.00025370340306410486,25.0,0.0
359.91357,0.06622369881889764,792.8045968056098,0.00025370340306410486,25.0,0.0
361.21484,0.06663064763779528,791.7288144396832,0.00025370340306410486,25.0,0.0
362.51611,0.06699407874015748,792.7516426438126,0.00025370340306410486,25.0,0.0
363.81738,0.06738502755905511,794.7133359303988,0.00025370340306410486,25.0,0.0
365.11865,0.0677186377952756,794.4129853265811,0.00025370340306410486,25.0,0.0
366.41992,0.06810486614173228,794.9895857680821,0.00025370340306410486,25.0,0.0
367.72119,0.06848713385826771,794.9440592130892,0.00025370340306410486,25.0,0.0
369.02246,0.06892537992125984,794.5658485910922,0.00025370340306410486,25.0,0.0
370.32373,0.06933502755905512,795.6857031554345,0.00025370340306410486,25.0,0.0
371.625,0.06969009055118111,795.9583430723283,0.00025370340306410486,25.0,0.0
372.92627,0.07011073228346457,796.4044669523439,0.00025370340306410486,25.0,0.0
374.22754,0.0705018405511811,796.6660174003376,0.00025370340306410486,25.0,0.0
375.52881,0.07091672047244095,796.9116478379432,0.00025370340306410486,25.0,0.0
376.83008,0.07123656102362205,795.8313465783664,0.00025370340306410486,25.0,0.0
378.13135,0.07161061023622046,796.8077392546423,0.00025370340306410486,25.0,0.0
379.43262,0.07203716535433072,798.652928191144,0.00025370340306410486,25.0,0.0
380.73389,0.07244759251968504,798.1077262693158,0.00025370340306410486,25.0,0.0
382.03516,0.07286662007874016,797.1707310738866,0.00025370340306410486,25.0,0.0
383.33643,0.07322170669291338,797.3101415400598,0.00025370340306410486,25.0,0.0
384.6377,0.07358187598425196,797.6598883261914,0.00025370340306410486,25.0,0.0
385.93896,0.07397787007874015,798.7966757563953,0.00025370340306410486,25.0,0.0
387.24023,0.07438888976377953,798.7006103103492,0.00025370340306410486,25.0,0.0
388.5415,0.07478006299212599,799.7305025321386,0.00025370340306410486,25.0,0.0
389.84277,0.075217218503937,800.3022204908455,0.00025370340306410486,25.0,0.0
391.14404,0.07565168700787402,801.5283469679263,0.00025370340306410486,25.0,0.0
392.44531,0.07604725984251968,801.517880794702,0.00025370340306410486,25.0,0.0
393.74658,0.0763888720472441,800.6981950396053,0.00025370340306410486,25.0,0.0
395.04785,0.07675530118110235,802.6012985326581,0.00025370340306410486,25.0,0.0
396.34912,0.07717865748031497,802.168549539021,0.00025370340306410486,25.0,0.0
397.65039,0.0775431377952756,801.8177898974159,0.00025370340306410486,25.0,0.0
398.95166,0.07787047637795275,800.9099597454876,0.00025370340306410486,25.0,0.0
400.25293,0.0782298405511811,801.5869887027659,0.00025370340306410486,25.0,0.0
401.5542,0.07859411023622047,802.4448772886639,0.00025370340306410486,25.0,0.0
402.85547,0.07898070669291338,802.3997143228153,0.00025370340306410486,25.0,0.0
404.15674,0.07937457283464566,802.9712504869498,0.00025370340306410486,25.0,0.0
405.45801,0.07982436417322834,806.0268536553695,0.00025370340306410486,25.0,0.0
406.75928,0.08023725590551181,803.9759771458253,0.00025370340306410486,25.0,0.0
408.06055,0.08060693897637795,804.2635242176341,0.00025370340306410486,25.0,0.0
409.36182,0.08096746653543307,804.6941695883652,0.00025370340306410486,25.0,0.0
410.66309,0.08137067125984251,805.5921049214388,0.00025370340306410486,25.0,0.0
411.96436,0.08179354133858267,806.3293078820933,0.00025370340306410486,25.0,0.0
413.26563,0.08215396850393701,804.6585897935333,0.00025370340306410486,25.0,0.0
414.56689,0.08252009645669292,805.5345799246852,0.00025370340306410486,25.0,0.0
415.86816,0.08292552559055118,804.8385404492924,0.00025370340306410486,25.0,0.0
417.16943,0.08332004133858267,807.3978184651344,0.00025370340306410486,25.0,0.0
418.4707,0.08368535039370079,805.3437995065576,0.00025370340306410486,25.0,0.0
419.77197,0.08404627952755905,806.2578366445916,0.00025370340306410486,25.0,0.0
421.07324,0.08451950393700787,807.9758732632126,0.00025370340306410486,25.0,0.0
422.37451,0.08485494488188977,808.1551227113363,0.00025370340306410486,25.0,0.0
423.67578,0.08530389173228346,809.1295935592781,0.00025370340306410486,25.0,0.0
424.97705,0.08569522244094488,809.0680950525906,0.00025370340306410486,25.0,0.0
426.27832,0.08607240354330709,808.5236982210102,0.00025370340306410486,25.0,0.0
427.57959,0.08641975984251968,806.5580054538373,0.00025370340306410486,25.0,0.0
428.88086,0.08669384645669291,808.4151408907934,0.00025370340306410486,25.0,0.0
430.18213,0.08707944685039369,810.7424750032463,0.00025370340306410486,25.0,0.0
431.4834,0.08753024212598426,810.4872873652773,0.00025370340306410486,25.0,0.0
432.78467,0.08787422440944882,809.2016880924556,0.00025370340306410486,25.0,0.0
434.08594,0.0882650216535433,810.9240098688482,0.00025370340306410486,25.0,0.0
435.38721,0.08860764960629922,810.763407349695,0.00025370340306410486,25.0,0.0
436.68848,0.08904989173228346,811.4376574470849,0.00025370340306410486,25.0,0.0
437.98975,0.08947552952755905,812.8929229970133,0.00025370340306410486,25.0,0.0
439.29102,0.08987948031496062,809.911933515128,0.00025370340306410486,25.0,0.0
440.59229,0.09028543700787402,813.4075834307233,0.00025370340306410486,25.0,0.0
441.89355,0.0906676811023622,812.79293598234,0.00025370340306410486,25.0,0.0
443.19482,0.09104881692913386,812.8343851447864,0.00025370340306410486,25.0,0.0
444.49609,0.09137067125984251,812.1255421373847,0.00025370340306410486,25.0,0.0
445.79736,0.09182881692913385,814.9604207245812,0.00025370340306410486,25.0,0.0
447.09863,0.09221772440944881,813.714842228282,0.00025370340306410486,25.0,0.0
448.3999,0.09257379921259842,812.3820542786651,0.00025370340306410486,25.0,0.0
449.70117,0.09293235826771654,814.437527593819,0.00025370340306410486,25.0,0.0
451.00244,0.09332408858267716,813.2993377483444,0.00025370340306410486,25.0,0.0
452.30371,0.0937737874015748,815.4085703155434,0.00025370340306410486,25.0,0.0
453.60498,0.09421746653543307,816.0550577847033,0.00025370340306410486,25.0,0.0
454.90625,0.09454252362204725,814.6433969614336,0.00025370340306410486,25.0,0.0
456.20752,0.0949147716535433,815.4706401766005,0.00025370340306410486,25.0,0.0
457.50879,0.09532351968503937,815.3998182054279,0.00025370340306410486,25.0,0.0
458.81006,0.09572408661417323,816.201272562005,0.00025370340306410486,25.0,0.0
460.11133,0.0960663779527559,816.7742630827166,0.00025370340306410486,25.0,0.0
461.4126,0.0964529468503937,816.2979613037268,0.00025370340306410486,25.0,0.0
462.71387,0.09679896456692913,815.6853915075965,0.00025370340306410486,25.0,0.0
464.01514,0.0972250433070866,818.0106479677964,0.00025370340306410486,25.0,0.0
465.31641,0.0975997027559055,818.4863004804571,0.00025370340306410486,25.0,0.0
466.61768,0.09799011811023622,817.7655888845604,0.00025370340306410486,25.0,0.0
467.91895,0.09839689566929134,819.0343851447864,0.00025370340306410486,25.0,0.0
469.22021,0.09872521456692913,816.0082586677055,0.00025370340306410486,25.0,0.0
470.52148,0.0990748877952756,818.6844565640827,0.00025370340306410486,25.0,0.0
471.82275,0.09944713582677164,818.0315024022855,0.00025370340306410486,25.0,0.0
473.12402,0.09985487598425197,818.7940267497728,0.00025370340306410486,25.0,0.0
474.42529,0.10025651377952755,818.473133359304,0.00025370340306410486,25.0,0.0
475.72656,0.10064553937007874,820.3875600571355,0.00025370340306410486,25.0,0.0
477.02783,0.10104205118110236,820.5757693805999,0.00025370340306410486,25.0,0.0
478.3291,0.10141520275590551,820.0304116348526,0.00025370340306410486,25.0,0.0
479.63037,0.10177815748031498,818.8871575120114,0.00025370340306410486,25.0,0.0
480.93164,0.10209035433070868,821.8384105960265,0.00025370340306410486,25.0,0.0
482.23291,0.10250044094488188,820.5670692117907,0.00025370340306410486,25.0,0.0
483.53418,0.1029692066929134,822.2409037787301,0.00025370340306410486,25.0,0.0
484.83545,0.10342608464566928,821.9094143617713,0.00025370340306410486,25.0,0.0
486.13672,0.10380843503937008,821.2205947279574,0.00025370340306410486,25.0,0.0
487.43799,0.1041814094488189,822.2464095572004,0.00025370340306410486,25.0,0.0
488.73926,0.104574531496063,821.245059083236,0.00025370340306410486,25.0,0.0
490.04053,0.10491604921259844,821.0142578885859,0.00025370340306410486,25.0,0.0
491.3418,0.10525581889763778,822.2131151798468,0.00025370340306410486,25.0,0.0
492.64307,0.10569045078740158,823.9050772626932,0.00025370340306410486,25.0,0.0
493.94434,0.10611438385826773,823.7809375405792,0.00025370340306410486,25.0,0.0
495.24561,0.10651791141732282,823.8390079210493,0.00025370340306410486,25.0,0.0
496.54688,0.10692347047244094,824.6715751201143,0.00025370340306410486,25.0,0.0
497.84814,0.10729688976377953,822.0612128295027,0.00025370340306410486,25.0,0.0
499.14941,0.10759736614173229,822.6183352811323,0.00025370340306410486,25.0,0.0
500.45068,0.10789807677165356,822.217634073497,0.00025370340306410486,25.0,0.0
501.75195,0.10825446062992125,823.5763407349694,0.00025370340306410486,25.0,0.0
503.05322,0.10864376771653544,824.7848331385534,0.00025370340306410486,25.0,0.0
504.35449,0.10907531496062992,825.4542007531489,0.00025370340306410486,25.0,0.0
505.65576,0.10946587795275589,825.9006362810026,0.00025370340306410486,25.0,0.0
506.95703,0.10982951377952756,824.609946760161,0.00025370340306410486,25.0,0.0
508.2583,0.11023430905511811,825.3300350603819,0.00025370340306410486,25.0,0.0
509.55957,0.11070423425196851,825.2885079859759,0.00025370340306410486,25.0,0.0
510.86084,0.1110395807086614,824.5639787040644,0.00025370340306410486,25.0,0.0
512.16211,0.11139176574803149,826.6619919490976,0.00025370340306410486,25.0,0.0
513.46338,0.11173354133858268,826.3235943383977,0.00025370340306410486,25.0,0.0
514.76465,0.11213853543307085,827.1502142578886,0.00025370340306410486,25.0,0.0
516.06592,0.11256331299212598,827.2354239709128,0.00025370340306410486,25.0,0.0
517.36719,0.11304998228346456,827.1628879366316,0.00025370340306410486,25.0,0.0
518.66846,0.11351071062992127,826.1262952863265,0.00025370340306410486,25.0,0.0
519.96973,0.11386143897637796,827.1427866510844,0.00025370340306410486,25.0,0.0
521.271,0.11424795472440946,826.9894299441631,0.00025370340306410486,25.0,0.0
522.57227,0.11462388582677165,826.7076483573562,0.00025370340306410486,25.0,0.0
523.87354,0.11498794291338583,825.7390209063758,0.00025370340306410486,25.0,0.0
525.1748,0.11534984251968504,828.3904168289832,0.00025370340306410486,25.0,0.0
526.47607,0.1156953720472441,829.6675756395274,0.00025370340306410486,25.0,0.0
527.77734,0.11610699606299213,829.8186209583172,0.00025370340306410486,25.0,0.0
529.07861,0.11652987401574802,829.8545643422932,0.00025370340306410486,25.0,0.0
530.37988,0.11698603543307087,830.6820672639917,0.00025370340306410486,25.0,0.0
531.68115,0.11742522244094489,831.3792494481237,0.00025370340306410486,25.0,0.0
532.98242,0.11783981496062991,830.653395662901,0.00025370340306410486,25.0,0.0
534.28369,0.1182226811023622,829.2329307882094,0.00025370340306410486,25.0,0.0
535.58496,0.11856033858267717,830.0101545253864,0.00025370340306410486,25.0,0.0
536.88623,0.11898652362204724,832.6574990261006,0.00025370340306410486,25.0,0.0
538.1875,0.11939517913385828,830.9336449811714,0.00025370340306410486,25.0,0.0
539.48877,0.11976713188976379,830.2885599272822,0.00025370340306410486,25.0,0.0
540.79004,0.12011097440944882,832.2889235164265,0.00025370340306410486,25.0,0.0
542.09131,0.12052388779527559,831.8478898844306,0.00025370340306410486,25.0,0.0
543.39258,0.1209394783464567,832.2892351642644,0.00025370340306410486,25.0,0.0
544.69385,0.12136068897637796,832.8094273470979,0.00025370340306410486,25.0,0.0
545.99512,0.12174290944881888,832.3819503960525,0.00025370340306410486,25.0,0.0
547.29639,0.12209113976377953,831.0502532138684,0.00025370340306410486,25.0,0.0
548.59766,0.12246068700787402,831.0652123100896,0.00025370340306410486,25.0,0.0
549.89893,0.12284890354330709,833.2361251785483,0.00025370340306410486,25.0,0.0
551.2002,0.12327171062992126,832.2938839111805,0.00025370340306410486,25.0,0.0
552.50146,0.12368385039370078,831.9987274379952,0.00025370340306410486,25.0,0.0
553.80273,0.12414688976377952,833.6536553694326,0.00025370340306410486,25.0,0.0
555.104,0.1246411496062992,835.9352811323205,0.00025370340306410486,25.0,0.0
556.40527,0.12503041141732282,833.2959875340865,0.00025370340306410486,25.0,0.0
557.70654,0.12544047440944883,833.6322295805741,0.00025370340306410486,25.0,0.0
559.00781,0.12583158858267718,835.3101155694067,0.00025370340306410486,25.0,0.0
560.30908,0.12620276771653544,834.0005973250228,0.00025370340306410486,25.0,0.0
561.61035,0.12656534842519684,834.1656408258668,0.00025370340306410486,25.0,0.0
562.91162,0.12699251771653544,836.6715491494612,0.00025370340306410486,25.0,0.0
564.21289,0.12736624409448818,835.3442929489677,0.00025370340306410486,25.0,0.0
565.51416,0.12773942913385827,835.3900012985326,0.00025370340306410486,25.0,0.0
566.81543,0.12818074999999998,836.4711855603169,0.00025370340306410486,25.0,0.0
568.1167,0.12855638976377953,834.5041163485262,0.00025370340306410486,25.0,0.0
569.41797,0.1289045590551181,833.4957018569017,0.00025370340306410486,25.0,0.0
570.71924,0.12923181102362205,835.0542786651084,0.00025370340306410486,25.0,0.0
572.02051,0.1295781751968504,835.2867160109076,0.00025370340306410486,25.0,0.0
573.32178,0.12999418700787402,834.5550707700298,0.00025370340306410486,25.0,0.0
574.62305,0.13042463188976378,838.4338657317231,0.00025370340306410486,25.0,0.0
575.92432,0.13081041929133858,835.7401895857681,0.00025370340306410486,25.0,0.0
577.22559,0.13117782086614174,835.8178678093755,0.00025370340306410486,25.0,0.0
578.52686,0.13163711614173226,837.9825736917284,0.00025370340306410486,25.0,0.0
579.82813,0.13204465748031496,837.4738605375926,0.00025370340306410486,25.0,0.0
581.12939,0.13242842716535433,838.349616932866,0.00025370340306410486,25.0,0.0
582.43066,0.13275562992125983,836.1696922477602,0.00025370340306410486,25.0,0.0
583.73193,0.13318429133858267,838.0554213738476,0.00025370340306410486,25.0,0.0
585.0332,0.13361073425196848,838.4492922997014,0.00025370340306410486,25.0,0.0
586.33447,0.1339859153543307,839.0072458122322,0.00025370340306410486,25.0,0.0
587.63574,0.13447895472440946,840.2592390598625,0.00025370340306410486,25.0,0.0
588.93701,0.1349747066929134,839.0676016101805,0.00025370340306410486,25.0,0.0
590.23828,0.13541229527559054,838.5912478898845,0.00025370340306410486,25.0,0.0
591.53955,0.1357860688976378,838.3896896506948,0.00025370340306410486,25.0,0.0
592.84082,0.1361525433070866,838.768082067264,0.00025370340306410486,25.0,0.0
594.14209,0.13654760039370079,839.3718997532789,0.00025370340306410486,25.0,0.0
595.44336,0.13698464960629922,840.5409427347098,0.00025370340306410486,25.0,0.0
596.74463,0.1373445649606299,838.6322036099208,0.00025370340306410486,25.0,0.0
598.0459,0.13773832086614174,840.5762108817037,0.00025370340306410486,25.0,0.0
599.34717,0.1382109094488189,840.832229580574,0.00025370340306410486,25.0,0.0
600.64844,0.13867828937007876,841.5185820023374,0.00025370340306410486,25.0,0.0
601.94971,0.13903347834645668,839.5793533307362,0.00025370340306410486,25.0,0.0
603.25098,0.1394153937007874,840.1836125178548,0.00025370340306410486,25.0,0.0
604.55225,0.13987625,842.4852097130243,0.00025370340306410486,25.0,0.0
605.85352,0.1402877440944882,841.3768861186859,0.00025370340306410486,25.0,0.0
607.15479,0.14069634251968502,842.1431242695753,0.00025370340306410486,25.0,0.0
608.45605,0.14113251181102363,841.1905466822491,0.00025370340306410486,25.0,0.0
609.75732,0.14155362795275592,842.9166601740034,0.00025370340306410486,25.0,0.0
611.05859,0.14193190551181104,839.8251136216076,0.00025370340306410486,25.0,0.0
612.35986,0.1422833031496063,841.3019348136606,0.00025370340306410486,25.0,0.0
613.66113,0.14265399015748031,841.4777561355668,0.00025370340306410486,25.0,0.0
614.9624,0.14306289173228345,841.5066095312297,0.00025370340306410486,25.0,0.0
616.26367,0.14348751771653542,843.3915595377225,0.00025370340306410486,25.0,0.0
617.56494,0.14388370078740156,842.4793143747567,0.00025370340306410486,25.0,0.0
618.86621,0.14431887204724408,843.7502661991949,0.00025370340306410486,25.0,0.0
620.16748,0.1447484842519685,843.4798337878199,0.00025370340306410486,25.0,0.0
621.46875,0.14516660826771655,841.4203869627322,0.00025370340306410486,25.0,0.0
622.77002,0.1455159645669291,842.5314894169588,0.00025370340306410486,25.0,0.0
624.07129,0.14592893700787402,844.0906635501883,0.00025370340306410486,25.0,0.0
625.37256,0.14643014370078739,844.7761329697443,0.00025370340306410486,25.0,0.0
626.67383,0.14683356692913385,842.9793793013895,0.00025370340306410486,25.0,0.0
627.9751,0.14725939960629922,842.8095831710168,0.00025370340306410486,25.0,0.0
629.27637,0.14773731692913386,842.8896506947151,0.00025370340306410486,25.0,0.0
630.57764,0.14818107677165354,844.4174003376186,0.00025370340306410486,25.0,0.0
631.87891,0.14858532086614173,841.9965459031295,0.00025370340306410486,25.0,0.0
633.18018,0.14901868700787402,844.5179067653553,0.00025370340306410486,25.0,0.0
634.48145,0.14948098622047243,844.8275548630048,0.00025370340306410486,25.0,0.0
635.78271,0.14992236614173227,844.6651343981301,0.00025370340306410486,25.0,0.0
637.08398,0.15038047637795274,846.4035579794833,0.00025370340306410486,25.0,0.0
638.38525,0.15088231692913384,846.1445526554993,0.00025370340306410486,25.0,0.0
639.68652,0.15128669094488187,844.2546422542526,0.00025370340306410486,25.0,0.0
640.98779,0.15166560236220472,843.6970523308661,0.00025370340306410486,25.0,0.0
642.28906,0.15197906692913385,844.5735618750812,0.00025370340306410486,25.0,0.0
643.59033,0.15235311023622047,844.8842487988574,0.00025370340306410486,25.0,0.0
644.8916,0.15275439566929133,845.5849889624725,0.00025370340306410486,25.0,0.0
646.19287,0.15321417322834646,846.2998831320608,0.00025370340306410486,25.0,0.0
647.49414,0.15367925393700788,845.1528892351643,0.00025370340306410486,25.0,0.0
648.79541,0.1540843661417323,846.4024152707442,0.00025370340306410486,25.0,0.0
650.09668,0.15455706102362204,847.474899363719,0.00025370340306410486,25.0,0.0
651.39795,0.15500090551181103,846.9104272172445,0.00025370340306410486,25.0,0.0
652.69922,0.1553613248031496,846.2564082586678,0.00025370340306410486,25.0,0.0
654.00049,0.1558171122047244,846.6252954161797,0.00025370340306410486,25.0,0.0
655.30176,0.15628201771653544,846.586677054928,0.00025370340306410486,25.0,0.0
656.60303,0.15679527362204723,846.8126477080898,0.00025370340306410486,25.0,0.0
657.9043,0.15721158070866142,847.2567978184651,0.00025370340306410486,25.0,0.0
659.20557,0.15762271062992125,845.8589014413712,0.00025370340306410486,25.0,0.0
660.50684,0.15804054133858267,846.3559537722374,0.00025370340306410486,25.0,0.0
661.80811,0.15848211023622047,847.8146474483833,0.00025370340306410486,25.0,0.0
663.10938,0.1588430216535433,846.8824568237892,0.00025370340306410486,25.0,0.0
664.41064,0.15931405118110237,849.8196338137905,0.00025370340306410486,25.0,0.0
665.71191,0.15984883858267718,846.3780028567719,0.00025370340306410486,25.0,0.0
667.01318,0.1602814192913386,848.001740033762,0.00025370340306410486,25.0,0.0
668.31445,0.16071107677165355,846.9062978833919,0.00025370340306410486,25.0,0.0
669.61572,0.16113162992125984,849.0604856512142,0.00025370340306410486,25.0,0.0
670.91699,0.16154022637795276,846.3721075185042,0.00025370340306410486,25.0,0.0
672.21826,0.1619229527559055,848.2446435527854,0.00025370340306410486,25.0,0.0
673.51953,0.16237449212598426,848.2641215426569,0.00025370340306410486,25.0,0.0
674.8208,0.1628177834645669,847.981379041683,0.00025370340306410486,25.0,0.0
676.12207,0.16328712401574805,847.5433839761071,0.00025370340306410486,25.0,0.0
677.42334,0.16374492913385827,850.1633554083886,0.00025370340306410486,25.0,0.0
678.72461,0.1641958838582677,846.8682508765096,0.00025370340306410486,25.0,0.0
680.02588,0.1646588996062992,847.0252954161797,0.00025370340306410486,25.0,0.0
681.32715,0.16509364960629921,848.9299831190755,0.00025370340306410486,25.0,0.0
682.62842,0.1655582244094488,848.825814829243,0.00025370340306410486,25.0,0.0
683.92969,0.16591203937007873,846.1196208284639,0.00025370340306410486,25.0,0.0
685.23096,0.16638323228346458,850.5033891702377,0.00025370340306410486,25.0,0.0
686.53223,0.166818781496063,849.760862225685,0.00025370340306410486,25.0,0.0
687.8335,0.16731073031496063,849.9138553434619,0.00025370340306410486,25.0,0.0
689.13477,0.1678039468503937,850.1697441890664,0.00025370340306410486,25.0,0.0
690.43604,0.16821610039370077,849.5447604207245,0.00025370340306410486,25.0,0.0
691.7373,0.16863989173228347,849.1699779249448,0.00025370340306410486,25.0,0.0
693.03857,0.16906606496062992,850.4174782495779,0.00025370340306410486,25.0,0.0
694.33984,0.16954733661417323,850.464952603558,0.00025370340306410486,25.0,0.0
695.64111,0.17008435236220473,851.4263602129594,0.00025370340306410486,25.0,0.0
696.94238,0.1705959901574803,848.6087261394624,0.00025370340306410486,25.0,0.0
698.24365,0.17107772047244094,849.5012595766784,0.00025370340306410486,25.0,0.0
699.54492,0.1715154153543307,850.1633554083886,0.00025370340306410486,25.0,0.0
700.84619,0.171961031496063,848.9895857680821,0.00025370340306410486,25.0,0.0
702.14746,0.1724221929133858,849.8762498376834,0.00025370340306410486,25.0,0.0
703.44873,0.17279983661417322,848.7298792364628,0.00025370340306410486,25.0,0.0
704.75,0.17325306692913384,850.5735618750812,0.00025370340306410486,25.0,0.0
706.05127,0.17372507086614172,850.6626671860797,0.00025370340306410486,25.0,0.0
707.35254,0.1742288464566929,851.8551097260097,0.00025370340306410486,25.0,0.0
708.65381,0.1746348622047244,849.4492663290482,0.00025370340306410486,25.0,0.0
709.95508,0.17511959645669292,851.0252175042203,0.00025370340306410486,25.0,0.0
711.25635,0.1755979940944882,851.7107388650825,0.00025370340306410486,25.0,0.0
712.55762,0.1760617716535433,850.0045708349566,0.00025370340306410486,25.0,0.0
713.85889,0.17647765551181102,850.8303077522401,0.00025370340306410486,25.0,0.0
715.16016,0.17692642716535434,850.9886767952215,0.00025370340306410486,25.0,0.0
716.46143,0.17739411220472442,850.2046747175692,0.00025370340306410486,25.0,0.0
717.7627,0.17782697244094486,851.4992858070381,0.00025370340306410486,25.0,0.0
719.06396,0.17832902559055117,851.5452538631347,0.00025370340306410486,25.0,0.0
720.36523,0.17883729527559056,852.5130762238671,0.00025370340306410486,25.0,0.0
721.6665,0.17931203149606298,851.1541098558629,0.00025370340306410486,25.0,0.0
722.96777,0.17981009448818897,850.0925853785224,0.00025370340306410486,25.0,0.0
724.26904,0.18024170078740157,851.3408907934034,0.00025370340306410486,25.0,0.0
725.57031,0.18079275,850.87778210622,0.00025370340306410486,25.0,0.0
726.87158,0.1812477755905512,850.664952603558,0.00025370340306410486,25.0,0.0
728.17285,0.1817046535433071,850.5460589533827,0.00025370340306410486,25.0,0.0
729.47412,0.18217300787401575,853.3196467991171,0.00025370340306410486,25.0,0.0
730.77539,0.18274126968503937,851.887573042462,0.00025370340306410486,25.0,0.0
732.07666,0.1832019625984252,850.4070120763538,0.00025370340306410486,25.0,0.0
733.37793,0.18361165157480314,852.8825347357485,0.00025370340306410486,25.0,0.0
734.6792,0.18410023228346456,851.7043241137516,0.00025370340306410486,25.0,0.0
735.98047,0.18460554724409448,853.4997792494482,0.00025370340306410486,25.0,0.0
737.28174,0.18508267716535431,851.1789118296325,0.00025370340306410486,25.0,0.0
738.58301,0.1855964035433071,851.8492143877419,0.00025370340306410486,25.0,0.0
739.88428,0.1861325275590551,853.0248798857291,0.00025370340306410486,25.0,0.0
741.18555,0.18666106102362204,852.7674587715882,0.00025370340306410486,25.0,0.0
742.48682,0.1870853346456693,851.0844305934295,0.00025370340306410486,25.0,0.0
743.78809,0.18755067322834645,852.1613037267888,0.00025370340306410486,25.0,0.0
745.08936,0.18806049212598425,854.0914686404363,0.00025370340306410486,25.0,0.0
746.39063,0.18857717519685038,852.1770159719517,0.00025370340306410486,25.0,0.0
747.69189,0.18911747637795276,852.4601740033762,0.00025370340306410486,25.0,0.0
748.99316,0.18960091929133857,852.7344760420725,0.00025370340306410486,25.0,0.0
750.29443,0.19015471456692912,852.5176210881704,0.00025370340306410486,25.0,0.0
751.5957,0.19064281692913387,852.2768731333593,0.00025370340306410486,25.0,0.0
752.89697,0.19113987007874014,851.7848071679003,0.00025370340306410486,25.0,0.0
754.19824,0.19157829330708662,851.8379431242696,0.00025370340306410486,25.0,0.0
755.49951,0.192092405511811,851.6861446565382,0.00025370340306410486,25.0,0.0
756.80078,0.19253315157480314,854.4875470718089,0.00025370340306410486,25.0,0.0
758.10205,0.19308552755905511,851.4680950525907,0.00025370340306410486,25.0,0.0
759.40332,0.19357813385826772,852.3123230749253,0.00025370340306410486,25.0,0.0
760.70459,0.19410196259842522,851.8811063498248,0.00025370340306410486,25.0,0.0
762.00586,0.19457871850393701,851.8151668614465,0.00025370340306410486,25.0,0.0
763.30713,0.19508525196850393,852.7709907804182,0.00025370340306410486,25.0,0.0
764.6084,0.195575218503937,852.0198415790157,0.00025370340306410486,25.0,0.0
765.90967,0.1960482657480315,851.8880924555252,0.00025370340306410486,25.0,0.0
767.21094,0.19653864173228347,852.3256460199974,0.00025370340306410486,25.0,0.0
768.51221,0.19700094488188977,853.207219841579,0.00025370340306410486,25.0,0.0
769.81348,0.19755842519685038,852.5224516296586,0.00025370340306410486,25.0,0.0
771.11475,0.19812976377952754,853.3687832748993,0.00025370340306410486,25.0,0.0
772.41602,0.19861785433070864,852.1998441760811,0.00025370340306410486,25.0,0.0
773.71729,0.19917179133858268,853.9312556810804,0.00025370340306410486,25.0,0.0
775.01855,0.1997207874015748,854.4492663290482,0.00025370340306410486,25.0,0.0
776.31982,0.2003503149606299,854.5886248539151,0.00025370340306410486,25.0,0.0
777.62109,0.20093242125984254,851.9709648097651,0.00025370340306410486,25.0,0.0
778.92236,0.2013775,850.8486949746787,0.00025370340306410486,25.0,0.0
780.22363,0.20195562992125984,853.4403064537073,0.00025370340306410486,25.0,0.0
781.5249,0.2025231692913386,853.8470328528763,0.00025370340306410486,25.0,0.0
782.82617,0.20310311023622046,852.6124918841709,0.00025370340306410486,25.0,0.0
784.12744,0.20364273622047246,851.7007921049214,0.00025370340306410486,25.0,0.0
785.42871,0.20412641732283465,851.4240228541748,0.00025370340306410486,25.0,0.0
786.72998,0.20459316929133858,851.0960394753929,0.00025370340306410486,25.0,0.0
788.03125,0.2050669881889764,853.3491234904558,0.00025370340306410486,25.0,0.0
789.33252,0.20557868110236222,851.4224905856383,0.00025370340306410486,25.0,0.0
790.63379,0.20605549212598423,852.4193481366057,0.00025370340306410486,25.0,0.0
791.93506,0.2065561023622047,851.8542786651084,0.00025370340306410486,25.0,0.0
792.63574,0.20687592519685039,855.245682378912,0.00025370340306410486,25.0,0.0