File: datasets/am_bench_2022/csv/0-XY.20-1.csv
Time(s),Strain(%),Stress(MPa),SR(s-1),Temp(C),Angle(deg)
14.579834,8.322964173228346e-07,16.292284759635308,0.00025370340306410486,25.0,0.0
16.581787,2.2221622047244094e-05,23.771701719850807,0.00025370340306410486,25.0,0.0
17.883057,8.05179409448819e-05,27.82024968918359,0.00025370340306410486,25.0,0.0
19.184326,5.392668307086614e-05,31.399080501450477,0.00025370340306410486,25.0,0.0
20.485596,7.676395866141732e-05,36.571200269374216,0.00025370340306410486,25.0,0.0
21.786865,0.00010901028740157479,40.16801181102362,0.00025370340306410486,25.0,0.0
23.088135,0.00011836025984251968,48.35142975549108,0.00025370340306410486,25.0,0.0
24.389404,0.00017957606496062992,53.019182552838785,0.00025370340306410486,25.0,0.0
25.690674,0.00017038340157480317,59.22986686697057,0.00025370340306410486,25.0,0.0
26.991943,0.00020648253937007873,66.88678771239121,0.00025370340306410486,25.0,0.0
28.293213,0.0002555718700787402,73.21395306672191,0.00025370340306410486,25.0,0.0
29.594482,0.00029653915354330704,78.8515877538334,0.00025370340306410486,25.0,0.0
30.895752,0.00032161773622047245,85.54593866556154,0.00025370340306410486,25.0,0.0
32.197021,0.0003341693307086614,94.53599254040613,0.00025370340306410486,25.0,0.0
33.498291,0.00039159708661417323,102.35577341483629,0.00025370340306410486,25.0,0.0
34.799561,0.0004182163582677165,107.96001087857438,0.00025370340306410486,25.0,0.0
36.10083,0.00043699515748031495,115.95087028595108,0.00025370340306410486,25.0,0.0
37.4021,0.0004443938188976378,123.60120182345628,0.00025370340306410486,25.0,0.0
38.703369,0.0004856981102362205,132.3971715706589,0.00025370340306410486,25.0,0.0
40.004639,0.0004989821456692913,137.4666545793618,0.00025370340306410486,25.0,0.0
41.305908,0.0005602178937007874,148.57670430998758,0.00025370340306410486,25.0,0.0
42.607178,0.0005938317125984252,156.41748083298796,0.00025370340306410486,25.0,0.0
43.908447,0.0006023677559055118,164.37816773725652,0.00025370340306410486,25.0,0.0
45.209717,0.0006403824803149607,170.90928305014504,0.00025370340306410486,25.0,0.0
46.510986,0.0006721395866141732,179.62949388727725,0.00025370340306410486,25.0,0.0
47.812256,0.000732046811023622,189.85955501450476,0.00025370340306410486,25.0,0.0
49.113525,0.0007635030118110236,196.50686645254868,0.00025370340306410486,25.0,0.0
50.414795,0.0007934415551181102,205.3342286572731,0.00025370340306410486,25.0,0.0
51.716064,0.0008413073228346456,216.7772301077497,0.00025370340306410486,25.0,0.0
53.017334,0.0008409943700787401,222.26367592208865,0.00025370340306410486,25.0,0.0
54.318604,0.0009080889173228347,235.16026212184002,0.00025370340306410486,25.0,0.0
55.619873,0.0009564046653543307,243.89773622047244,0.00025370340306410486,25.0,0.0
56.921143,0.0009767743307086613,252.99582987981765,0.00025370340306410486,25.0,0.0
58.222412,0.0010175099803149607,262.1645772896809,0.00025370340306410486,25.0,0.0
59.523682,0.0010693096653543307,272.6113240779113,0.00025370340306410486,25.0,0.0
60.824951,0.0010966857677165355,283.25608682138414,0.00025370340306410486,25.0,0.0
62.126221,0.0011215046062992126,293.6974979278906,0.00025370340306410486,25.0,0.0
63.42749,0.0011666138976377952,301.76996995441357,0.00025370340306410486,25.0,0.0
64.72876,0.001185431653543307,310.0167840861997,0.00025370340306410486,25.0,0.0
66.030029,0.0012297746062992125,320.104227103191,0.00025370340306410486,25.0,0.0
67.331299,0.0012739522047244096,331.02478760878574,0.00025370340306410486,25.0,0.0
68.632568,0.0012986663582677167,339.4330967675093,0.00025370340306410486,25.0,0.0
69.933838,0.0013332062401574802,347.98456278491506,0.00025370340306410486,25.0,0.0
71.235107,0.001359531220472441,357.436671156237,0.00025370340306410486,25.0,0.0
72.536377,0.0014077873031496063,365.25466224616656,0.00025370340306410486,25.0,0.0
73.837646,0.0014335830118110237,374.4805998756734,0.00025370340306410486,25.0,0.0
75.138916,0.0014742913385826773,384.6757407791131,0.00025370340306410486,25.0,0.0
76.440186,0.001537385688976378,394.90626295068375,0.00025370340306410486,25.0,0.0
77.741455,0.001546974468503937,405.38520513883134,0.00025370340306410486,25.0,0.0
79.042725,0.0015936397637795275,413.3564287194364,0.00025370340306410486,25.0,0.0
80.343994,0.0016352169094488189,422.6451771653543,0.00025370340306410486,25.0,0.0
81.645264,0.0017046838582677165,432.9780097389142,0.00025370340306410486,25.0,0.0
82.946533,0.0017068794291338581,441.21252072109405,0.00025370340306410486,25.0,0.0
84.247803,0.001777130492125984,451.21477414007455,0.00025370340306410486,25.0,0.0
85.549072,0.0017851283070866141,458.9953377538333,0.00025370340306410486,25.0,0.0
86.850342,0.001821935905511811,468.8859303771239,0.00025370340306410486,25.0,0.0
88.151611,0.0018822302362204726,477.1204672606714,0.00025370340306410486,25.0,0.0
89.452881,0.00189811312992126,484.8783153750518,0.00025370340306410486,25.0,0.0
90.75415,0.0019709915354330708,496.4835008288437,0.00025370340306410486,25.0,0.0
92.05542,0.001990735039370079,502.3180169912971,0.00025370340306410486,25.0,0.0
93.356689,0.0020430324803149607,510.46060401989223,0.00025370340306410486,25.0,0.0
94.657959,0.0020865543307086614,516.1149243680067,0.00025370340306410486,25.0,0.0
95.959229,0.002134387007874016,524.3284552424368,0.00025370340306410486,25.0,0.0
97.260498,0.002183336023622047,530.5821850393701,0.00025370340306410486,25.0,0.0
98.561768,0.002221677362204724,540.7846301284708,0.00025370340306410486,25.0,0.0
99.863037,0.0022812580708661415,546.7542737256526,0.00025370340306410486,25.0,0.0
101.16431,0.002346495866141732,554.9668980522171,0.00025370340306410486,25.0,0.0
102.46558,0.002382038976377953,560.9536106506423,0.00025370340306410486,25.0,0.0
103.76685,0.002411909251968504,565.3874067550765,0.00025370340306410486,25.0,0.0
105.06812,0.0024529992125984254,571.5710992540406,0.00025370340306410486,25.0,0.0
106.36938,0.002530264566929134,578.6006268130957,0.00025370340306410486,25.0,0.0
107.67065,0.0025661122047244095,584.7275435142975,0.00025370340306410486,25.0,0.0
108.97192,0.002609063976377953,589.3226274347286,0.00025370340306410486,25.0,0.0
110.27319,0.002651115157480315,595.0846197679238,0.00025370340306410486,25.0,0.0
111.57446,0.0027185801181102364,601.2682604641524,0.00025370340306410486,25.0,0.0
112.87573,0.002799396456692913,606.5261862826358,0.00025370340306410486,25.0,0.0
114.177,0.002856004527559055,611.4694363862411,0.00025370340306410486,25.0,0.0
115.47827,0.0029197072834645666,616.9909345213426,0.00025370340306410486,25.0,0.0
116.77954,0.0029662248031496062,622.3826668048073,0.00025370340306410486,25.0,0.0
118.08081,0.0030463372047244094,628.0594695399916,0.00025370340306410486,25.0,0.0
119.38208,0.003110057480314961,631.6363966017406,0.00025370340306410486,25.0,0.0
120.68335,0.0032055687007874014,635.696073352673,0.00025370340306410486,25.0,0.0
121.98462,0.0032540047244094487,637.9465654786572,0.00025370340306410486,25.0,0.0
123.28589,0.0033020866141732284,644.2122876087857,0.00025370340306410486,25.0,0.0
124.58716,0.003425561811023622,649.0098684210525,0.00025370340306410486,25.0,0.0
125.88843,0.0034964708661417323,651.6581796518856,0.00025370340306410486,25.0,0.0
127.1897,0.0036049183070866143,656.786650435143,0.00025370340306410486,25.0,0.0
128.49097,0.0036850608267716533,659.7911831744716,0.00025370340306410486,25.0,0.0
129.79224,0.0037526125984251968,661.1338582677165,0.00025370340306410486,25.0,0.0
131.09351,0.003863043110236221,665.9607853294654,0.00025370340306410486,25.0,0.0
132.39478,0.003984734448818898,670.82304185661,0.00025370340306410486,25.0,0.0
133.69604,0.004095121062992126,673.1757148777455,0.00025370340306410486,25.0,0.0
134.99731,0.004231633858267717,675.4402455449648,0.00025370340306410486,25.0,0.0
136.29858,0.0043398391732283464,678.88274450891,0.00025370340306410486,25.0,0.0
137.59985,0.004475315157480315,681.6209852880231,0.00025370340306410486,25.0,0.0
138.90112,0.004621625984251968,682.9973839618731,0.00025370340306410486,25.0,0.0
140.20239,0.004737889763779528,685.2772223373394,0.00025370340306410486,25.0,0.0
141.50366,0.004860258267716536,687.0132355988396,0.00025370340306410486,25.0,0.0
142.80493,0.00500311062992126,691.5406392457521,0.00025370340306410486,25.0,0.0
144.1062,0.005201337992125984,693.044135930377,0.00025370340306410486,25.0,0.0
145.40747,0.005393304133858267,695.8138727724823,0.00025370340306410486,25.0,0.0
146.70874,0.00560434094488189,698.5094280978035,0.00025370340306410486,25.0,0.0
148.01001,0.005773602362204724,699.1828118524659,0.00025370340306410486,25.0,0.0
149.31128,0.005971336811023621,700.129765851637,0.00025370340306410486,25.0,0.0
150.61255,0.006175401968503937,704.2051388313303,0.00025370340306410486,25.0,0.0
151.91382,0.006413061614173227,704.442965188562,0.00025370340306410486,25.0,0.0
153.21509,0.006650275984251968,707.2038437629507,0.00025370340306410486,25.0,0.0
154.51636,0.006936929724409449,709.4011603812681,0.00025370340306410486,25.0,0.0
155.81763,0.007210954921259843,711.3426750932449,0.00025370340306410486,25.0,0.0
157.1189,0.007449627952755906,710.6523259428097,0.00025370340306410486,25.0,0.0
158.42017,0.007700122244094488,712.9969177372565,0.00025370340306410486,25.0,0.0
159.72144,0.007977929133858268,714.8611168669706,0.00025370340306410486,25.0,0.0
161.02271,0.008239207677165355,715.1110132615001,0.00025370340306410486,25.0,0.0
162.32397,0.008483572047244094,718.3380646498134,0.00025370340306410486,25.0,0.0
163.62524,0.008732986811023623,716.7493265644426,0.00025370340306410486,25.0,0.0
164.92651,0.009006563976377953,718.5936075424781,0.00025370340306410486,25.0,0.0
166.22778,0.009317797244094489,722.0109821798591,0.00025370340306410486,25.0,0.0
167.52905,0.009595430511811023,721.6363188976377,0.00025370340306410486,25.0,0.0
168.83032,0.009919586417322834,724.8167737256528,0.00025370340306410486,25.0,0.0
170.13159,0.010256363582677164,724.6720109821798,0.00025370340306410486,25.0,0.0
171.43286,0.010568474803149607,724.3713220058019,0.00025370340306410486,25.0,0.0
172.73413,0.010889130511811024,726.865597803564,0.00025370340306410486,25.0,0.0
174.0354,0.011123135236220473,725.3457314546208,0.00025370340306410486,25.0,0.0
175.33667,0.01144029901574803,728.5135982179859,0.00025370340306410486,25.0,0.0
176.63794,0.011734801574803149,728.9930325321176,0.00025370340306410486,25.0,0.0
177.93921,0.012045420472440945,728.8499274761707,0.00025370340306410486,25.0,0.0
179.24048,0.012390869881889763,730.7739587650227,0.00025370340306410486,25.0,0.0
180.54175,0.01266921811023622,730.962520721094,0.00025370340306410486,25.0,0.0
181.84302,0.013041396456692913,733.6754040613345,0.00025370340306410486,25.0,0.0
183.14429,0.013375465551181102,735.9060298383755,0.00025370340306410486,25.0,0.0
184.44556,0.01371389940944882,733.8113603398259,0.00025370340306410486,25.0,0.0
185.74683,0.01411565,737.033853087443,0.00025370340306410486,25.0,0.0
187.0481,0.01445526003937008,735.4149399088271,0.00025370340306410486,25.0,0.0
188.34937,0.014784820669291338,736.362360132615,0.00025370340306410486,25.0,0.0
189.65063,0.01504818248031496,737.28022689598,0.00025370340306410486,25.0,0.0
190.9519,0.015459214173228345,739.309832159138,0.00025370340306410486,25.0,0.0
192.25317,0.015786133267716534,737.7459593866556,0.00025370340306410486,25.0,0.0
193.55444,0.016070959448818898,738.6039421881475,0.00025370340306410486,25.0,0.0
194.85571,0.01642004133858268,740.9616141732283,0.00025370340306410486,25.0,0.0
196.15698,0.016825112204724407,739.5907324906755,0.00025370340306410486,25.0,0.0
197.45825,0.017236014763779527,742.1685920016577,0.00025370340306410486,25.0,0.0
198.75952,0.017635101968503937,743.5204361790303,0.00025370340306410486,25.0,0.0
200.06079,0.018058112992125983,744.5178719436386,0.00025370340306410486,25.0,0.0
201.36206,0.01840258937007874,742.4422658516369,0.00025370340306410486,25.0,0.0
202.66333,0.018765438582677166,744.6565478657272,0.00025370340306410486,25.0,0.0
203.9646,0.01912257066929134,744.1871373808538,0.00025370340306410486,25.0,0.0
205.26587,0.019492694488188977,746.3318483215913,0.00025370340306410486,25.0,0.0
206.56714,0.019784240157480315,744.609122461666,0.00025370340306410486,25.0,0.0
207.86841,0.020154064960629922,747.200269374223,0.00025370340306410486,25.0,0.0
209.16968,0.020477454724409448,745.2276730211355,0.00025370340306410486,25.0,0.0
210.47095,0.020851681102362206,747.9927994198093,0.00025370340306410486,25.0,0.0
211.77222,0.02132159251968504,749.6003677994198,0.00025370340306410486,25.0,0.0
213.07349,0.021673866141732286,747.9732438872771,0.00025370340306410486,25.0,0.0
214.37476,0.022023003937007873,749.8812163282221,0.00025370340306410486,25.0,0.0
215.67603,0.022401143700787402,750.4517198508081,0.00025370340306410486,25.0,0.0
216.97729,0.022712661417322835,750.164188769167,0.00025370340306410486,25.0,0.0
218.27856,0.023066450787401573,751.052268959801,0.00025370340306410486,25.0,0.0
219.57983,0.023415639763779528,752.2975031081642,0.00025370340306410486,25.0,0.0
220.8811,0.023751803149606298,750.5448093659345,0.00025370340306410486,25.0,0.0
222.18237,0.024090948818897635,752.971793410692,0.00025370340306410486,25.0,0.0
223.48364,0.024499312992125984,755.6785899295483,0.00025370340306410486,25.0,0.0
224.78491,0.02493303149606299,755.3394115209283,0.00025370340306410486,25.0,0.0
226.08618,0.025298490157480317,754.4086976792374,0.00025370340306410486,25.0,0.0
227.38745,0.02568388779527559,755.2271031910484,0.00025370340306410486,25.0,0.0
228.68872,0.026120366141732285,755.7281651471196,0.00025370340306410486,25.0,0.0
229.98999,0.026500049212598423,754.3797399502694,0.00025370340306410486,25.0,0.0
231.29126,0.026915055118110237,755.5528905926232,0.00025370340306410486,25.0,0.0
232.59253,0.02722617322834646,755.9955449647741,0.00025370340306410486,25.0,0.0
233.8938,0.027607446850393697,756.7183226274348,0.00025370340306410486,25.0,0.0
235.19507,0.02796050590551181,757.6737463738085,0.00025370340306410486,25.0,0.0
236.49634,0.02838202559055118,759.1435971819312,0.00025370340306410486,25.0,0.0
237.79761,0.02879268307086614,760.0816411106506,0.00025370340306410486,25.0,0.0
239.09888,0.02919322244094488,760.2526160381268,0.00025370340306410486,25.0,0.0
240.40015,0.029558240157480316,758.558174471612,0.00025370340306410486,25.0,0.0
241.70142,0.029932417322834644,761.62080397845,0.00025370340306410486,25.0,0.0
243.00269,0.030414061023622048,761.1381319933693,0.00025370340306410486,25.0,0.0
244.30396,0.03075342125984252,761.3182242022378,0.00025370340306410486,25.0,0.0
245.60522,0.031107438976377952,761.2947575631993,0.00025370340306410486,25.0,0.0
246.90649,0.03149659842519685,762.7975549108993,0.00025370340306410486,25.0,0.0
248.20776,0.0318519311023622,762.2379040613345,0.00025370340306410486,25.0,0.0
249.50903,0.032242704724409446,764.6096404890178,0.00025370340306410486,25.0,0.0
250.8103,0.032567651574803146,762.777818068794,0.00025370340306410486,25.0,0.0
252.11157,0.032985925196850396,764.9814028180688,0.00025370340306410486,25.0,0.0
253.41284,0.03330853937007874,764.4862722751761,0.00025370340306410486,25.0,0.0
254.71411,0.03360945472440945,765.7287867799419,0.00025370340306410486,25.0,0.0
256.01538,0.03398837598425197,764.2448974305843,0.00025370340306410486,25.0,0.0
257.31665,0.034323261811023624,765.3082003729796,0.00025370340306410486,25.0,0.0
258.61792,0.03478028346456693,766.2814701616245,0.00025370340306410486,25.0,0.0
259.91919,0.0351745216535433,768.8849461251554,0.00025370340306410486,25.0,0.0
261.22046,0.0355647342519685,767.215318068794,0.00025370340306410486,25.0,0.0
262.52173,0.03594314566929133,767.8954361790302,0.00025370340306410486,25.0,0.0
263.823,0.03633075,767.0194778284292,0.00025370340306410486,25.0,0.0
265.12427,0.03670027165354331,770.298202445089,0.00025370340306410486,25.0,0.0
266.42554,0.03706131102362205,769.6055221715707,0.00025370340306410486,25.0,0.0
267.72681,0.037532293307086614,773.2357542478242,0.00025370340306410486,25.0,0.0
269.02808,0.03801591929133858,769.8404993783672,0.00025370340306410486,25.0,0.0
270.32935,0.038439017716535434,769.5548072938251,0.00025370340306410486,25.0,0.0
271.63062,0.03873028346456693,770.0097907169497,0.00025370340306410486,25.0,0.0
272.93188,0.03911887401574803,772.5691307501036,0.00025370340306410486,25.0,0.0
274.23315,0.03951996456692913,772.5757615002071,0.00025370340306410486,25.0,0.0
275.53442,0.0399041751968504,771.6447368421053,0.00025370340306410486,25.0,0.0
276.83569,0.04029506102362205,774.1889763779527,0.00025370340306410486,25.0,0.0
278.13696,0.0406593562992126,771.3475963530874,0.00025370340306410486,25.0,0.0
279.43823,0.04102118897637796,772.8333765022793,0.00025370340306410486,25.0,0.0
280.7395,0.04141197047244094,774.5566721922917,0.00025370340306410486,25.0,0.0
282.04077,0.041773968503937005,774.0724979278905,0.00025370340306410486,25.0,0.0
283.34204,0.042156608267716535,774.1973166183175,0.00025370340306410486,25.0,0.0
284.64331,0.04256791535433071,775.1744975134687,0.00025370340306410486,25.0,0.0
285.94458,0.04287949015748032,774.8791960215499,0.00025370340306410486,25.0,0.0
287.24585,0.04319216338582677,775.0903957728967,0.00025370340306410486,25.0,0.0
288.54712,0.04359924606299213,774.4642302113551,0.00025370340306410486,25.0,0.0
289.84839,0.04394682086614173,774.9710681723994,0.00025370340306410486,25.0,0.0
291.14966,0.04429539960629921,777.285951098218,0.00025370340306410486,25.0,0.0
292.45093,0.04468186023622047,778.2698922503108,0.00025370340306410486,25.0,0.0
293.7522,0.04510770472440945,777.0803719436385,0.00025370340306410486,25.0,0.0
295.05347,0.045585970472440944,779.6239639452963,0.00025370340306410486,25.0,0.0
296.35474,0.045969336614173226,778.2768338168255,0.00025370340306410486,25.0,0.0
297.65601,0.0463790374015748,778.7488344384583,0.00025370340306410486,25.0,0.0
298.95728,0.0467446968503937,780.3318224202238,0.00025370340306410486,25.0,0.0
300.25854,0.04710580905511811,780.5494198093659,0.00025370340306410486,25.0,0.0
301.55981,0.04746119488188976,779.6473010774969,0.00025370340306410486,25.0,0.0
302.86108,0.04784720275590551,782.7662660588478,0.00025370340306410486,25.0,0.0
304.16235,0.04830724803149606,781.2606972648155,0.00025370340306410486,25.0,0.0
305.46362,0.048700681102362205,781.4623394115209,0.00025370340306410486,25.0,0.0
306.76489,0.04907578346456693,782.5353294653956,0.00025370340306410486,25.0,0.0
308.06616,0.0494364094488189,781.0408205553252,0.00025370340306410486,25.0,0.0
309.36743,0.04984083464566929,783.0204620803978,0.00025370340306410486,25.0,0.0
310.6687,0.050172385826771644,782.0760464152506,0.00025370340306410486,25.0,0.0
311.96997,0.05058776968503937,783.0589256112722,0.00025370340306410486,25.0,0.0
313.27124,0.051016214566929126,784.6422244094488,0.00025370340306410486,25.0,0.0
314.57251,0.05140735236220472,786.0011655615416,0.00025370340306410486,25.0,0.0
315.87378,0.0518146220472441,786.2475134687112,0.00025370340306410486,25.0,0.0
317.17505,0.05219466732283465,783.4083091587236,0.00025370340306410486,25.0,0.0
318.47632,0.05253710629921259,783.0485391628678,0.00025370340306410486,25.0,0.0
319.77759,0.05289337204724409,784.9824388727724,0.00025370340306410486,25.0,0.0
321.07886,0.053288348425196856,786.3666597596352,0.00025370340306410486,25.0,0.0
322.38013,0.053697836614173225,785.1216846249481,0.00025370340306410486,25.0,0.0
323.6814,0.05405874409448818,786.0903698715291,0.00025370340306410486,25.0,0.0
324.98267,0.054359102362204724,786.0973891421467,0.00025370340306410486,25.0,0.0
326.28394,0.054705982283464565,786.1166338582676,0.00025370340306410486,25.0,0.0
327.58521,0.05506165551181102,787.1027248238706,0.00025370340306410486,25.0,0.0
328.88647,0.05552734055118111,788.0626295068379,0.00025370340306410486,25.0,0.0
330.18774,0.05595792519685039,790.0555843348528,0.00025370340306410486,25.0,0.0
331.48901,0.05630014763779527,789.0514660174057,0.00025370340306410486,25.0,0.0
332.79028,0.056693228346456695,788.2703066721922,0.00025370340306410486,25.0,0.0
334.09155,0.057132653543307085,790.871632822213,0.00025370340306410486,25.0,0.0
335.39282,0.05752080511811024,790.6874999999999,0.00025370340306410486,25.0,0.0
336.69409,0.05787155118110236,788.2760049730625,0.00025370340306410486,25.0,0.0
337.99536,0.05826650196850394,790.4066773725652,0.00025370340306410486,25.0,0.0
339.29663,0.05866250393700788,791.5541338582677,0.00025370340306410486,25.0,0.0
340.5979,0.05910266929133859,791.4370337753833,0.00025370340306410486,25.0,0.0
341.89917,0.05946254921259843,791.6254144218815,0.00025370340306410486,25.0,0.0
343.20044,0.05981795472440945,792.8169032324906,0.00025370340306410486,25.0,0.0
344.50171,0.06023120275590551,791.8699492333194,0.00025370340306410486,25.0,0.0
345.80298,0.060593748031496066,792.5595990468296,0.00025370340306410486,25.0,0.0
347.10425,0.06098872834645669,794.5999533775382,0.00025370340306410486,25.0,0.0
348.40552,0.06135215157480315,792.3306827600496,0.00025370340306410486,25.0,0.0
349.70679,0.06175006496062992,794.4954931620389,0.00025370340306410486,25.0,0.0
351.00806,0.0621091594488189,795.2640644426026,0.00025370340306410486,25.0,0.0
352.30933,0.06252011023622048,795.0776263986737,0.00025370340306410486,25.0,0.0
353.6106,0.06288655511811024,795.5390592623289,0.00025370340306410486,25.0,0.0
354.91187,0.06322806692913387,794.1810246581019,0.00025370340306410486,25.0,0.0
356.21313,0.06355563976377952,796.1148207625363,0.00025370340306410486,25.0,0.0
357.5144,0.0639210531496063,796.4433278077081,0.00025370340306410486,25.0,0.0
358.81567,0.06432653543307086,795.5236479486116,0.00025370340306410486,25.0,0.0
360.11694,0.06469748622047243,794.411520928305,0.00025370340306410486,25.0,0.0
361.41821,0.0650825059055118,797.4459956485703,0.00025370340306410486,25.0,0.0
362.71948,0.06546943700787401,796.9803926647327,0.00025370340306410486,25.0,0.0
364.02075,0.06581592322834645,795.6485184417737,0.00025370340306410486,25.0,0.0
365.32202,0.0662147125984252,796.6732542478243,0.00025370340306410486,25.0,0.0
366.62329,0.06656856692913386,797.6140178201408,0.00025370340306410486,25.0,0.0
367.92456,0.06689477952755905,797.2999896394529,0.00025370340306410486,25.0,0.0
369.22583,0.06731667125984252,799.4968659345213,0.00025370340306410486,25.0,0.0
370.5271,0.06771952362204724,799.1855573974306,0.00025370340306410486,25.0,0.0
371.82837,0.06813786417322834,799.4876450476585,0.00025370340306410486,25.0,0.0
373.12964,0.06852746062992127,799.6723995026937,0.00025370340306410486,25.0,0.0
374.43091,0.06892174803149606,801.0446280563614,0.00025370340306410486,25.0,0.0
375.73218,0.06932041338582677,800.481195607128,0.00025370340306410486,25.0,0.0
377.03345,0.06970839960629921,799.9023259428097,0.00025370340306410486,25.0,0.0
378.33472,0.07005653543307087,800.6886655615416,0.00025370340306410486,25.0,0.0
379.63599,0.07045577559055119,799.8748186904268,0.00025370340306410486,25.0,0.0
380.93726,0.0708144842519685,799.9837857438872,0.00025370340306410486,25.0,0.0
382.23853,0.07115932283464567,803.5372461665976,0.00025370340306410486,25.0,0.0
383.53979,0.07157473031496063,804.0970783257355,0.00025370340306410486,25.0,0.0
384.84106,0.07200157874015749,803.7723010774969,0.00025370340306410486,25.0,0.0
386.14233,0.07238436811023623,802.6806102362204,0.00025370340306410486,25.0,0.0
387.4436,0.07271092519685039,802.4235391628678,0.00025370340306410486,25.0,0.0
388.74487,0.07309930708661416,803.4085681723994,0.00025370340306410486,25.0,0.0
390.04614,0.0734467559055118,802.826978864484,0.00025370340306410486,25.0,0.0
391.34741,0.07384983858267716,804.2045690012433,0.00025370340306410486,25.0,0.0
392.64868,0.07423057480314961,805.8046259842519,0.00025370340306410486,25.0,0.0
393.94995,0.07461370472440945,807.0577859510981,0.00025370340306410486,25.0,0.0
395.25122,0.0750030531496063,805.4100445503522,0.00025370340306410486,25.0,0.0
396.55249,0.07541157283464567,805.9314908827185,0.00025370340306410486,25.0,0.0
397.85376,0.07580646653543306,806.8202704102777,0.00025370340306410486,25.0,0.0
399.15503,0.07619085826771654,807.3198300870285,0.00025370340306410486,25.0,0.0
400.4563,0.07660170669291338,807.642017198508,0.00025370340306410486,25.0,0.0
401.75757,0.07693849015748032,806.6148725652714,0.00025370340306410486,25.0,0.0
403.05884,0.07732036614173228,808.4524968918358,0.00025370340306410486,25.0,0.0
404.36011,0.07773044094488189,805.9930843348528,0.00025370340306410486,25.0,0.0
405.66138,0.07810992125984252,807.8780045586407,0.00025370340306410486,25.0,0.0
406.96265,0.0784788779527559,807.9192913385826,0.00025370340306410486,25.0,0.0
408.26392,0.07882366929133858,807.6766732283464,0.00025370340306410486,25.0,0.0
409.56519,0.07921752362204725,807.9893027351843,0.00025370340306410486,25.0,0.0
410.86646,0.0795475905511811,808.1814908827185,0.00025370340306410486,25.0,0.0
412.16772,0.07997075984251968,810.0239069622875,0.00025370340306410486,25.0,0.0
413.46899,0.08039234055118111,810.890178201409,0.00025370340306410486,25.0,0.0
414.77026,0.08075406299212598,809.6940789473683,0.00025370340306410486,25.0,0.0
416.07153,0.0811215,810.6953481143804,0.00025370340306410486,25.0,0.0
417.3728,0.08149197440944882,811.8961873186904,0.00025370340306410486,25.0,0.0
418.67407,0.08185579724409449,810.1718296726067,0.00025370340306410486,25.0,0.0
419.97534,0.08224343897637795,811.090059055118,0.00025370340306410486,25.0,0.0
421.27661,0.0825948188976378,809.9454517198508,0.00025370340306410486,25.0,0.0
422.57788,0.08292488582677165,810.7586510567758,0.00025370340306410486,25.0,0.0
423.87915,0.08332471850393701,811.5319622876087,0.00025370340306410486,25.0,0.0
425.18042,0.08368221062992126,812.0465188561955,0.00025370340306410486,25.0,0.0
426.48169,0.08401254724409449,813.4174523414837,0.00025370340306410486,25.0,0.0
427.78296,0.08438891338582677,813.9695140903439,0.00025370340306410486,25.0,0.0
429.08423,0.08474098622047244,814.2540147119767,0.00025370340306410486,25.0,0.0
430.3855,0.08511778543307086,814.9860132615001,0.00025370340306410486,25.0,0.0
431.68677,0.08550888188976379,816.0776523000413,0.00025370340306410486,25.0,0.0
432.98804,0.08593595866141732,813.8730055946953,0.00025370340306410486,25.0,0.0
434.28931,0.0863214468503937,813.8209697472026,0.00025370340306410486,25.0,0.0
435.59058,0.0867780216535433,816.7702807708247,0.00025370340306410486,25.0,0.0
436.89185,0.08713407086614174,813.911779941981,0.00025370340306410486,25.0,0.0
438.19312,0.08746520472440945,814.8652351844177,0.00025370340306410486,25.0,0.0
439.49438,0.08784011614173229,815.6402559055118,0.00025370340306410486,25.0,0.0
440.79565,0.0882538877952756,816.416986116867,0.00025370340306410486,25.0,0.0
442.09692,0.08858184842519685,815.8494353501864,0.00025370340306410486,25.0,0.0
443.39819,0.088941218503937,814.5063717364277,0.00025370340306410486,25.0,0.0
444.69946,0.08931571259842519,815.9449854952342,0.00025370340306410486,25.0,0.0
446.00073,0.08969844881889764,818.1655097389141,0.00025370340306410486,25.0,0.0
447.302,0.09011594488188976,816.7428512225445,0.00025370340306410486,25.0,0.0
448.60327,0.09046975984251969,816.903387898881,0.00025370340306410486,25.0,0.0
449.90454,0.09086340354330709,816.1832003729796,0.00025370340306410486,25.0,0.0
451.20581,0.09125970275590552,817.4789680895151,0.00025370340306410486,25.0,0.0
452.50708,0.09167875393700788,818.7728968089514,0.00025370340306410486,25.0,0.0
453.80835,0.09213674212598426,819.2218711147948,0.00025370340306410486,25.0,0.0
455.10962,0.0925610157480315,820.0833246995442,0.00025370340306410486,25.0,0.0
456.41089,0.09289030118110235,817.3273932863655,0.00025370340306410486,25.0,0.0
457.71216,0.09324734251968504,818.2560091172813,0.00025370340306410486,25.0,0.0
459.01343,0.09365084645669292,821.4551647326978,0.00025370340306410486,25.0,0.0
460.3147,0.09401451771653543,819.6705864069622,0.00025370340306410486,25.0,0.0
461.61597,0.09434914763779527,819.8267198508081,0.00025370340306410486,25.0,0.0
462.91724,0.09470632480314961,820.6790043514297,0.00025370340306410486,25.0,0.0
464.21851,0.09501393307086614,820.3142094902611,0.00025370340306410486,25.0,0.0
465.51978,0.09537452362204725,820.9663023207625,0.00025370340306410486,25.0,0.0
466.82104,0.0956632657480315,820.2019529631164,0.00025370340306410486,25.0,0.0
468.12231,0.09607802362204725,821.6592416079569,0.00025370340306410486,25.0,0.0
469.42358,0.09644296062992126,822.217597389142,0.00025370340306410486,25.0,0.0
470.72485,0.09689397440944882,823.6498394115208,0.00025370340306410486,25.0,0.0
472.02612,0.09730292913385827,821.01194053046,0.00025370340306410486,25.0,0.0
473.32739,0.09770111811023621,822.2786210111893,0.00025370340306410486,25.0,0.0
474.62866,0.09809709645669291,821.9337443016991,0.00025370340306410486,25.0,0.0
475.92993,0.09844649212598425,823.6650176129299,0.00025370340306410486,25.0,0.0
477.2312,0.09886341929133859,822.5277144633236,0.00025370340306410486,25.0,0.0
478.53247,0.09922033267716536,823.0023570244509,0.00025370340306410486,25.0,0.0
479.83374,0.09958834448818897,823.3058174471611,0.00025370340306410486,25.0,0.0
481.13501,0.09995109842519684,825.0045327393285,0.00025370340306410486,25.0,0.0
482.43628,0.10035824212598424,824.1409811438043,0.00025370340306410486,25.0,0.0
483.73755,0.10076205118110235,823.3842985909655,0.00025370340306410486,25.0,0.0
485.03882,0.10114435433070866,825.139349357646,0.00025370340306410486,25.0,0.0
486.34009,0.10156179724409449,825.8819156651471,0.00025370340306410486,25.0,0.0
487.64136,0.10194154330708663,823.7850963530874,0.00025370340306410486,25.0,0.0
488.94263,0.10234783858267717,826.0899036469126,0.00025370340306410486,25.0,0.0
490.2439,0.10274911417322834,825.741866970576,0.00025370340306410486,25.0,0.0
491.54517,0.10313626377952755,825.8880542892664,0.00025370340306410486,25.0,0.0
492.84644,0.10352673228346457,826.4502175714878,0.00025370340306410486,25.0,0.0
494.14771,0.10385898228346456,825.8253988810609,0.00025370340306410486,25.0,0.0
495.44897,0.10424061614173227,826.1715447575632,0.00025370340306410486,25.0,0.0
496.75024,0.1046405059055118,828.7190737670949,0.00025370340306410486,25.0,0.0
498.05151,0.10505282283464566,827.0075891007044,0.00025370340306410486,25.0,0.0
499.35278,0.10533953543307087,824.6282117695814,0.00025370340306410486,25.0,0.0
500.65405,0.10564856496062992,826.7784915043515,0.00025370340306410486,25.0,0.0
501.95532,0.106021468503937,829.0182863655201,0.00025370340306410486,25.0,0.0
503.25659,0.10633458070866142,826.7222596353087,0.00025370340306410486,25.0,0.0
504.55786,0.10672472047244096,829.0286728139246,0.00025370340306410486,25.0,0.0
505.85913,0.10720619291338583,829.978527766266,0.00025370340306410486,25.0,0.0
507.1604,0.10763059448818897,830.9723373394114,0.00025370340306410486,25.0,0.0
508.46167,0.1080143405511811,829.4974875673436,0.00025370340306410486,25.0,0.0
509.76294,0.1083472342519685,827.2349772067964,0.00025370340306410486,25.0,0.0
511.06421,0.10875086811023621,829.229615623705,0.00025370340306410486,25.0,0.0
512.36548,0.10909516732283465,829.8409397016162,0.00025370340306410486,25.0,0.0
513.66675,0.10949126771653543,829.7736997513467,0.00025370340306410486,25.0,0.0
514.96802,0.1099233779527559,831.8930014504765,0.00025370340306410486,25.0,0.0
516.26929,0.11034491732283463,830.669006423539,0.00025370340306410486,25.0,0.0
517.57056,0.11069822637795275,830.8330915872358,0.00025370340306410486,25.0,0.0
518.87183,0.11110386811023623,830.8055325321177,0.00025370340306410486,25.0,0.0
520.1731,0.11153898228346457,830.837831537505,0.00025370340306410486,25.0,0.0
521.47437,0.11189855708661417,829.9682967260671,0.00025370340306410486,25.0,0.0
522.77563,0.1123177716535433,833.1200269374222,0.00025370340306410486,25.0,0.0
524.0769,0.11272236811023621,831.8456796518856,0.00025370340306410486,25.0,0.0
525.37817,0.11310692322834646,832.2964411520928,0.00025370340306410486,25.0,0.0
526.67944,0.11347401968503935,833.7459852880231,0.00025370340306410486,25.0,0.0
527.98071,0.11386770472440945,832.9540250725238,0.00025370340306410486,25.0,0.0
529.28198,0.11422805511811024,833.8165665147119,0.00025370340306410486,25.0,0.0
530.58325,0.1146072598425197,833.2938510153335,0.00025370340306410486,25.0,0.0
531.88452,0.11502713188976377,832.6764919187732,0.00025370340306410486,25.0,0.0
533.18579,0.11537013976377954,834.2425922088686,0.00025370340306410486,25.0,0.0
534.48706,0.11577986417322833,835.0485909656029,0.00025370340306410486,25.0,0.0
535.78833,0.11621788779527559,833.00139867385,0.00025370340306410486,25.0,0.0
537.0896,0.11652621259842519,833.8930791545794,0.00025370340306410486,25.0,0.0
538.39087,0.11688142322834646,834.8398518441774,0.00025370340306410486,25.0,0.0
539.69214,0.11722456102362205,834.4834490261086,0.00025370340306410486,25.0,0.0
540.99341,0.1176170590551181,835.1723995026937,0.00025370340306410486,25.0,0.0
542.29468,0.11798324015748032,834.3128885205139,0.00025370340306410486,25.0,0.0
543.59595,0.11836494488188977,835.0595731454621,0.00025370340306410486,25.0,0.0
544.89722,0.11871931102362204,834.7074181516783,0.00025370340306410486,25.0,0.0
546.19849,0.11911232677165355,837.3456796518856,0.00025370340306410486,25.0,0.0
547.49976,0.11951573818897637,837.8082521757148,0.00025370340306410486,25.0,0.0
548.80103,0.11991871456692914,836.7977362204724,0.00025370340306410486,25.0,0.0
550.10229,0.12028207874015746,835.2293048072937,0.00025370340306410486,25.0,0.0
551.40356,0.12069027755905512,837.7337080397843,0.00025370340306410486,25.0,0.0
552.70483,0.12108687007874015,838.424730625777,0.00025370340306410486,25.0,0.0
554.0061,0.12151502755905512,837.9230988396187,0.00025370340306410486,25.0,0.0
555.30737,0.12197647047244094,838.0485391628678,0.00025370340306410486,25.0,0.0
556.60864,0.12239315157480314,836.0288541234977,0.00025370340306410486,25.0,0.0
557.90991,0.122772062992126,839.2736220472441,0.00025370340306410486,25.0,0.0
559.21118,0.1231258779527559,837.4607076253626,0.00025370340306410486,25.0,0.0
560.51245,0.12349237598425196,837.4235391628678,0.00025370340306410486,25.0,0.0
561.81372,0.12390322637795274,838.8876916701201,0.00025370340306410486,25.0,0.0
563.11499,0.12433066535433072,839.786650435143,0.00025370340306410486,25.0,0.0
564.41626,0.12471070472440944,837.7325683796104,0.00025370340306410486,25.0,0.0
565.71753,0.12508948818897636,838.8076305428926,0.00025370340306410486,25.0,0.0
567.0188,0.1254980374015748,840.0628626191462,0.00025370340306410486,25.0,0.0
568.32007,0.12592230905511811,839.8350341898052,0.00025370340306410486,25.0,0.0
569.62134,0.12631511417322833,840.9572627434728,0.00025370340306410486,25.0,0.0
570.92261,0.12666487992125985,838.9669757563199,0.00025370340306410486,25.0,0.0
572.22388,0.1270382657480315,839.2660847492747,0.00025370340306410486,25.0,0.0
573.52515,0.1273609881889764,837.8289214670534,0.00025370340306410486,25.0,0.0
574.82642,0.12775535236220473,841.463349564857,0.00025370340306410486,25.0,0.0
576.12769,0.12813647047244095,840.327807708247,0.00025370340306410486,25.0,0.0
577.42896,0.12852420472440945,841.8806464981351,0.00025370340306410486,25.0,0.0
578.73022,0.12884622244094487,839.9925404061335,0.00025370340306410486,25.0,0.0
580.03149,0.12925899606299213,840.4651108578532,0.00025370340306410486,25.0,0.0
581.33276,0.1296741279527559,840.8946591380025,0.00025370340306410486,25.0,0.0
582.63403,0.13012701771653543,840.6380024865311,0.00025370340306410486,25.0,0.0
583.9353,0.13055118503937008,840.545534604227,0.00025370340306410486,25.0,0.0
585.23657,0.1309009409448819,840.7575631993368,0.00025370340306410486,25.0,0.0
586.53784,0.1313189940944882,840.8389452963116,0.00025370340306410486,25.0,0.0
587.83911,0.13174402952755904,841.8402403646912,0.00025370340306410486,25.0,0.0
589.14038,0.1321099527559055,842.6193016991297,0.00025370340306410486,25.0,0.0
590.44165,0.13250523228346456,842.7761085785329,0.00025370340306410486,25.0,0.0
591.74292,0.13295706496062992,844.9036210111893,0.00025370340306410486,25.0,0.0
593.04419,0.1334273562992126,843.0218607542478,0.00025370340306410486,25.0,0.0
594.34546,0.13374125393700786,841.7495596767509,0.00025370340306410486,25.0,0.0
595.64673,0.13407796062992128,843.0900331537505,0.00025370340306410486,25.0,0.0
596.948,0.13443970866141733,842.9914266473269,0.00025370340306410486,25.0,0.0
598.24927,0.13484962992125984,843.8655978035639,0.00025370340306410486,25.0,0.0
599.55054,0.1353015,846.1553823041855,0.00025370340306410486,25.0,0.0
600.85181,0.13571060039370078,844.4494664318275,0.00025370340306410486,25.0,0.0
602.15308,0.13613172834645668,843.5079517198508,0.00025370340306410486,25.0,0.0
603.45435,0.1365433405511811,845.6640333609614,0.00025370340306410486,25.0,0.0
604.75562,0.13696954921259843,844.0639763779527,0.00025370340306410486,25.0,0.0
606.05688,0.1373898090551181,843.7582884376294,0.00025370340306410486,25.0,0.0
607.35815,0.1377906377952756,843.6482076253626,0.00025370340306410486,25.0,0.0
608.65942,0.13819707677165355,844.0363396187317,0.00025370340306410486,25.0,0.0
609.96069,0.13856235433070865,845.2860806050559,0.00025370340306410486,25.0,0.0
611.26196,0.13894665157480315,844.8665043514297,0.00025370340306410486,25.0,0.0
612.56323,0.13934614370078738,844.9097596353087,0.00025370340306410486,25.0,0.0
613.8645,0.13977567322834647,846.001968503937,0.00025370340306410486,25.0,0.0
615.16577,0.14019234251968504,846.4356869042686,0.00025370340306410486,25.0,0.0
616.46704,0.14061222637795276,847.0777818068793,0.00025370340306410486,25.0,0.0
617.76831,0.14101689173228346,846.5376864898466,0.00025370340306410486,25.0,0.0
619.06958,0.14144604527559054,846.9347026523,0.00025370340306410486,25.0,0.0
620.37085,0.141862187007874,845.9315167840862,0.00025370340306410486,25.0,0.0
621.67212,0.14229198622047246,846.9291338582677,0.00025370340306410486,25.0,0.0
622.97339,0.14272924803149606,845.7393545379196,0.00025370340306410486,25.0,0.0
624.27466,0.14321543503937006,846.4400642353917,0.00025370340306410486,25.0,0.0
625.57593,0.14358157086614173,847.0920793617903,0.00025370340306410486,25.0,0.0
626.8772,0.14401624999999998,847.6555118110235,0.00025370340306410486,25.0,0.0
628.17847,0.14441109645669292,847.3877693742229,0.00025370340306410486,25.0,0.0
629.47974,0.14478916338582676,847.4979278905926,0.00025370340306410486,25.0,0.0
630.78101,0.14516475393700787,846.9651626605884,0.00025370340306410486,25.0,0.0
632.08228,0.14561201181102362,846.2706433899709,0.00025370340306410486,25.0,0.0
633.38354,0.14600014566929131,848.5688199336925,0.00025370340306410486,25.0,0.0
634.68481,0.14647674803149607,850.5205397845006,0.00025370340306410486,25.0,0.0
635.98608,0.14698298818897637,850.1064805221715,0.00025370340306410486,25.0,0.0
637.28735,0.1474058188976378,848.4582987981765,0.00025370340306410486,25.0,0.0
638.58862,0.1478073996062992,846.9907273104019,0.00025370340306410486,25.0,0.0
639.88989,0.1481531751968504,847.0703999171155,0.00025370340306410486,25.0,0.0
641.19116,0.1485247657480315,847.36305946954,0.00025370340306410486,25.0,0.0
642.49243,0.1489418818897638,850.0648052217156,0.00025370340306410486,25.0,0.0
643.7937,0.14937137598425196,848.8401626605885,0.00025370340306410486,25.0,0.0
645.09497,0.1498087775590551,848.5009842519685,0.00025370340306410486,25.0,0.0
646.39624,0.15019894094488187,847.4053046000829,0.00025370340306410486,25.0,0.0
647.69751,0.150570531496063,848.664758599254,0.00025370340306410486,25.0,0.0
648.99878,0.1509014311023622,847.8038748445917,0.00025370340306410486,25.0,0.0
650.30005,0.15131707874015748,850.89608371322,0.00025370340306410486,25.0,0.0
651.60132,0.1517802716535433,849.5318586821384,0.00025370340306410486,25.0,0.0
652.90259,0.15232164173228346,850.8432967260671,0.00025370340306410486,25.0,0.0
654.20386,0.15276402952755905,851.354926440116,0.00025370340306410486,25.0,0.0
655.50513,0.15319575196850393,849.0924937836718,0.00025370340306410486,25.0,0.0
656.8064,0.15357817322834644,848.9413593037712,0.00025370340306410486,25.0,0.0
658.10767,0.153986968503937,851.4597233733941,0.00025370340306410486,25.0,0.0
659.40894,0.15449013582677165,851.8937007874015,0.00025370340306410486,25.0,0.0
660.71021,0.15485260826771655,849.5867436800662,0.00025370340306410486,25.0,0.0
662.01147,0.15529641732283464,852.0823404475756,0.00025370340306410486,25.0,0.0
663.31274,0.15573629527559055,851.9415665147119,0.00025370340306410486,25.0,0.0
664.61401,0.1561891377952756,850.6602258599253,0.00025370340306410486,25.0,0.0
665.91528,0.15659030708661417,851.8514556568587,0.00025370340306410486,25.0,0.0
667.21655,0.15703092322834647,853.6638520513883,0.00025370340306410486,25.0,0.0
668.51782,0.15753492322834645,850.5947731040197,0.00025370340306410486,25.0,0.0
669.81909,0.15795738976377954,851.1620130542892,0.00025370340306410486,25.0,0.0
671.12036,0.15838881889763778,851.6211665975962,0.00025370340306410486,25.0,0.0
672.42163,0.1587850846456693,849.8894529631165,0.00025370340306410486,25.0,0.0
673.7229,0.15918482283464566,851.3693535018649,0.00025370340306410486,25.0,0.0
675.02417,0.1596044251968504,852.071902196436,0.00025370340306410486,25.0,0.0
676.32544,0.16001695275590552,853.5336717778698,0.00025370340306410486,25.0,0.0
677.62671,0.16041759448818899,851.7412971404889,0.00025370340306410486,25.0,0.0
678.92798,0.1607805374015748,851.4600859925404,0.00025370340306410486,25.0,0.0
680.22925,0.1611650216535433,851.4389763779527,0.00025370340306410486,25.0,0.0
681.53052,0.16153980511811022,851.5257459593867,0.00025370340306410486,25.0,0.0
682.83179,0.1619616594488189,853.419265437215,0.00025370340306410486,25.0,0.0
684.13306,0.16244004527559053,853.5566203895565,0.00025370340306410486,25.0,0.0
685.43433,0.162907155511811,853.5391628677994,0.00025370340306410486,25.0,0.0
686.7356,0.16340911417322834,853.5260049730625,0.00025370340306410486,25.0,0.0
688.03687,0.1638712972440945,851.7215861997513,0.00025370340306410486,25.0,0.0
689.33813,0.16431089173228344,854.4700580190633,0.00025370340306410486,25.0,0.0
690.6394,0.16476989566929134,853.0846197679238,0.00025370340306410486,25.0,0.0
691.94067,0.16521839566929133,854.7077548694571,0.00025370340306410486,25.0,0.0
693.24194,0.16573727362204724,854.7167944467468,0.00025370340306410486,25.0,0.0
694.54321,0.16619094881889765,853.8474409448819,0.00025370340306410486,25.0,0.0
695.84448,0.16662360039370078,853.2756682552838,0.00025370340306410486,25.0,0.0
697.14575,0.16705873622047246,853.7532117695814,0.00025370340306410486,25.0,0.0
698.44702,0.16754199212598425,853.435971819312,0.00025370340306410486,25.0,0.0
699.74829,0.16802104724409447,854.3296208039783,0.00025370340306410486,25.0,0.0
701.04956,0.16848645669291337,853.5602206796518,0.00025370340306410486,25.0,0.0
702.35083,0.16900628346456692,852.8156858682138,0.00025370340306410486,25.0,0.0
703.6521,0.16943002755905512,852.8867592208869,0.00025370340306410486,25.0,0.0
704.95337,0.16997190157480316,855.880206174886,0.00025370340306410486,25.0,0.0
706.25464,0.17042259842519686,853.1171777869871,0.00025370340306410486,25.0,0.0
707.55591,0.17083586417322832,853.8773570244508,0.00025370340306410486,25.0,0.0
708.85718,0.17127359448818896,854.7161728139245,0.00025370340306410486,25.0,0.0
710.15845,0.17173162401574804,854.2337339411521,0.00025370340306410486,25.0,0.0
711.45972,0.17223263188976376,855.1402818068793,0.00025370340306410486,25.0,0.0
712.76099,0.17268771456692913,854.6401004973062,0.00025370340306410486,25.0,0.0
714.06226,0.17310805708661417,853.5024088271861,0.00025370340306410486,25.0,0.0
715.36353,0.1735269901574803,853.7439908827185,0.00025370340306410486,25.0,0.0
716.66479,0.173955687007874,855.0156444260257,0.00025370340306410486,25.0,0.0
717.96606,0.17434491141732283,855.3975341898051,0.00025370340306410486,25.0,0.0
719.26733,0.17479055118110234,854.3812681309573,0.00025370340306410486,25.0,0.0
720.5686,0.1752433818897638,856.9572368421052,0.00025370340306410486,25.0,0.0
721.86987,0.17571693307086614,857.1601740571901,0.00025370340306410486,25.0,0.0
723.17114,0.17622461614173227,856.6781755076668,0.00025370340306410486,25.0,0.0
724.47241,0.17669747637795274,856.1146912556983,0.00025370340306410486,25.0,0.0
725.77368,0.17714457086614172,852.9978760878573,0.00025370340306410486,25.0,0.0
727.07495,0.17757324212598424,856.4062629506838,0.00025370340306410486,25.0,0.0
728.37622,0.17810725590551182,855.4900538748446,0.00025370340306410486,25.0,0.0
729.67749,0.17855960629921258,855.7446902196435,0.00025370340306410486,25.0,0.0
730.97876,0.17896171456692914,854.6904268545378,0.00025370340306410486,25.0,0.0
732.28003,0.17941362992125984,857.1771135515954,0.00025370340306410486,25.0,0.0
733.5813,0.17993792716535434,856.5172503108164,0.00025370340306410486,25.0,0.0
734.88257,0.18046246062992125,855.8108941152093,0.00025370340306410486,25.0,0.0
736.18384,0.1809261220472441,855.740597803564,0.00025370340306410486,25.0,0.0
737.48511,0.18135394881889763,854.5189338997099,0.00025370340306410486,25.0,0.0
738.78638,0.18185191732283465,856.6260101533361,0.00025370340306410486,25.0,0.0
740.08765,0.1824001751968504,856.6382874015748,0.00025370340306410486,25.0,0.0
741.38892,0.18294254133858268,856.7170016576874,0.00025370340306410486,25.0,0.0
742.69019,0.1834802027559055,854.9324233319519,0.00025370340306410486,25.0,0.0
743.99146,0.18395328543307085,855.6388313302942,0.00025370340306410486,25.0,0.0
745.29272,0.18439635433070867,854.0170949026108,0.00025370340306410486,25.0,0.0
746.59399,0.1848571653543307,856.8983630335681,0.00025370340306410486,25.0,0.0
747.89526,0.18532658661417323,854.8246218400332,0.00025370340306410486,25.0,0.0
749.19653,0.18582327559055117,856.3706744716121,0.00025370340306410486,25.0,0.0
750.4978,0.1863405118110236,856.6990002072109,0.00025370340306410486,25.0,0.0
751.79907,0.18678949409448817,856.8245700372979,0.00025370340306410486,25.0,0.0
753.10034,0.18735048031496063,857.7530563613758,0.00025370340306410486,25.0,0.0
754.40161,0.18782649606299212,856.9177890592622,0.00025370340306410486,25.0,0.0
755.70288,0.18824595866141733,856.9840447575631,0.00025370340306410486,25.0,0.0
757.00415,0.18870438582677165,855.5843866556154,0.00025370340306410486,25.0,0.0
758.30542,0.1891572401574803,856.1577652300041,0.00025370340306410486,25.0,0.0
759.60669,0.1896852933070866,855.9415406133443,0.00025370340306410486,25.0,0.0
760.90796,0.19021429724409447,856.1079309987567,0.00025370340306410486,25.0,0.0
762.20923,0.19070962598425195,857.1766732283464,0.00025370340306410486,25.0,0.0
763.5105,0.19118052559055118,856.0330501450476,0.00025370340306410486,25.0,0.0
764.81177,0.19178388188976378,858.2625621632822,0.00025370340306410486,25.0,0.0
766.11304,0.19231336614173228,855.6231610029009,0.00025370340306410486,25.0,0.0
767.41431,0.1927388346456693,856.7775849564856,0.00025370340306410486,25.0,0.0
768.71558,0.19324961614173228,856.8018804392872,0.00025370340306410486,25.0,0.0
770.01685,0.19380199212598426,856.4146808951512,0.00025370340306410486,25.0,0.0
771.31812,0.1943718838582677,856.4757045171984,0.00025370340306410486,25.0,0.0
772.61938,0.19495963582677164,858.1256475341897,0.00025370340306410486,25.0,0.0
773.92065,0.19552976377952758,857.4767146705345,0.00025370340306410486,25.0,0.0
775.22192,0.19600250590551183,855.2545586406962,0.00025370340306410486,25.0,0.0
776.52319,0.19649133464566929,856.7637536261915,0.00025370340306410486,25.0,0.0
777.82446,0.1969865748031496,856.8651056775798,0.00025370340306410486,25.0,0.0
778.52515,0.19730230314960628,859.9235132615001,0.00025370340306410486,25.0,0.0