File: datasets/am_bench_2022/csv/30-XY.18-1.csv
Time(s),Strain(%),Stress(MPa),SR(s-1),Temp(C),Angle(deg)
23.764648,9.925541929133858e-06,19.65741942257218,0.00025370340306410486,25.0,30.0
25.366211,1.541323248031496e-05,25.820470341207347,0.00025370340306410486,25.0,30.0
26.867676,2.9231070866141733e-05,29.92896062992126,0.00025370340306410486,25.0,30.0
28.369141,3.276080118110236e-05,35.11466404199475,0.00025370340306410486,25.0,30.0
29.870605,4.5602785433070865e-05,38.85703412073491,0.00025370340306410486,25.0,30.0
31.37207,8.839858267716535e-05,43.4079186351706,0.00025370340306410486,25.0,30.0
32.873535,0.00010597887204724409,51.75083464566929,0.00025370340306410486,25.0,30.0
34.375,0.00014131388976377953,58.34610498687664,0.00025370340306410486,25.0,30.0
35.876465,0.0001569235216535433,65.21473490813648,0.00025370340306410486,25.0,30.0
37.37793,0.00018877539566929132,74.01633333333334,0.00025370340306410486,25.0,30.0
38.879395,0.00020053080708661418,79.89189501312336,0.00025370340306410486,25.0,30.0
40.380859,0.0002269639566929134,87.13956430446194,0.00025370340306410486,25.0,30.0
41.882324,0.0002621798031496063,95.82518635170604,0.00025370340306410486,25.0,30.0
43.383789,0.0002766227952755906,103.06513385826771,0.00025370340306410486,25.0,30.0
44.885254,0.0002998097637795276,110.69180577427821,0.00025370340306410486,25.0,30.0
46.386719,0.0003225960236220472,120.88579790026246,0.00025370340306410486,25.0,30.0
47.888184,0.00037307683070866144,130.8392939632546,0.00025370340306410486,25.0,30.0
49.389648,0.000402170157480315,142.9544776902887,0.00025370340306410486,25.0,30.0
50.891113,0.0004239111811023622,149.04576902887138,0.00025370340306410486,25.0,30.0
52.392578,0.0004624066535433071,161.53884776902888,0.00025370340306410486,25.0,30.0
53.894043,0.0004865682874015748,170.63706036745407,0.00025370340306410486,25.0,30.0
55.395508,0.0005215542125984252,178.90171653543308,0.00025370340306410486,25.0,30.0
56.896973,0.0005696174606299213,189.02618372703412,0.00025370340306410486,25.0,30.0
58.398438,0.0006011097834645669,200.12751706036747,0.00025370340306410486,25.0,30.0
59.899902,0.0006172822440944881,208.25437270341206,0.00025370340306410486,25.0,30.0
61.401367,0.0006562547047244094,219.70775590551182,0.00025370340306410486,25.0,30.0
62.902832,0.0006979641141732283,230.7749186351706,0.00025370340306410486,25.0,30.0
64.404297,0.0007219069488188976,241.40700262467192,0.00025370340306410486,25.0,30.0
65.905762,0.0007745076574803149,253.14600262467192,0.00025370340306410486,25.0,30.0
67.407227,0.0008065655905511811,263.9270603674541,0.00025370340306410486,25.0,30.0
68.908691,0.0008367431102362205,274.5729133858268,0.00025370340306410486,25.0,30.0
70.410156,0.0009046168110236221,286.0953543307087,0.00025370340306410486,25.0,30.0
71.911621,0.0009357791732283465,298.23687664041995,0.00025370340306410486,25.0,30.0
73.413086,0.0009817661614173229,310.6040419947506,0.00025370340306410486,25.0,30.0
74.914551,0.0010139435433070866,319.77926509186346,0.00025370340306410486,25.0,30.0
76.416016,0.0010698184055118111,334.1290288713911,0.00025370340306410486,25.0,30.0
77.91748,0.0010985366929133857,343.9710761154856,0.00025370340306410486,25.0,30.0
79.418945,0.0011194103149606298,354.41196850393703,0.00025370340306410486,25.0,30.0
80.92041,0.0011703468897637794,366.41089238845143,0.00025370340306410486,25.0,30.0
82.421875,0.0012098355905511811,376.1169816272966,0.00025370340306410486,25.0,30.0
83.92334,0.0012470315748031495,386.7573490813648,0.00025370340306410486,25.0,30.0
85.424805,0.0012876842716535433,399.3962204724409,0.00025370340306410486,25.0,30.0
86.92627,0.0013263147244094488,408.32370078740155,0.00025370340306410486,25.0,30.0
88.427734,0.001384871811023622,422.2409186351706,0.00025370340306410486,25.0,30.0
89.929199,0.0014023801181102362,432.41619422572177,0.00025370340306410486,25.0,30.0
91.430664,0.0014587283464566928,440.7990288713911,0.00025370340306410486,25.0,30.0
92.932129,0.001481351062992126,449.73727034120736,0.00025370340306410486,25.0,30.0
94.433594,0.0015152711811023622,459.24530183727035,0.00025370340306410486,25.0,30.0
95.935059,0.0015748769291338582,469.9717322834646,0.00025370340306410486,25.0,30.0
97.436523,0.0015869025393700788,479.1235433070866,0.00025370340306410486,25.0,30.0
98.937988,0.0016348601377952755,489.9228608923884,0.00025370340306410486,25.0,30.0
100.43945,0.0016723601771653543,496.0144094488189,0.00025370340306410486,25.0,30.0
101.94092,0.0017040246062992126,505.67616797900257,0.00025370340306410486,25.0,30.0
103.44238,0.0017464679724409449,515.9556167979002,0.00025370340306410486,25.0,30.0
104.94385,0.0017767977362204725,523.4944094488188,0.00025370340306410486,25.0,30.0
106.44531,0.0018166946456692912,531.9912598425196,0.00025370340306410486,25.0,30.0
107.94678,0.001874588622047244,540.2017060367455,0.00025370340306410486,25.0,30.0
109.44824,0.0019161866732283464,548.33343832021,0.00025370340306410486,25.0,30.0
110.94971,0.0019551696653543307,554.8990288713911,0.00025370340306410486,25.0,30.0
112.45117,0.001957851062992126,561.249501312336,0.00025370340306410486,25.0,30.0
113.95264,0.0020236,569.0507349081364,0.00025370340306410486,25.0,30.0
115.4541,0.002054910826771654,576.3811023622047,0.00025370340306410486,25.0,30.0
116.95557,0.002083639566929134,580.8567454068241,0.00025370340306410486,25.0,30.0
118.45703,0.002123121062992126,587.5083989501312,0.00025370340306410486,25.0,30.0
119.9585,0.002148992519685039,593.4307611548556,0.00025370340306410486,25.0,30.0
121.45996,0.0021903009842519686,598.8807874015748,0.00025370340306410486,25.0,30.0
122.96143,0.0022444690944881888,604.0720734908136,0.00025370340306410486,25.0,30.0
124.46289,0.0022695576771653543,610.0302624671915,0.00025370340306410486,25.0,30.0
125.96436,0.002315112007874016,615.640498687664,0.00025370340306410486,25.0,30.0
127.46582,0.0023287462598425195,618.0293175853018,0.00025370340306410486,25.0,30.0
128.96729,0.0024032883858267715,626.1558005249344,0.00025370340306410486,25.0,30.0
130.46875,0.002423436023622047,628.7960367454068,0.00025370340306410486,25.0,30.0
131.97021,0.002456113385826772,633.9878477690288,0.00025370340306410486,25.0,30.0
133.47168,0.0025159285433070866,638.2487664041995,0.00025370340306410486,25.0,30.0
134.97314,0.0025451253937007873,641.209343832021,0.00025370340306410486,25.0,30.0
136.47461,0.0025980350393700787,647.0171916010498,0.00025370340306410486,25.0,30.0
137.97607,0.0026384120078740154,649.818530183727,0.00025370340306410486,25.0,30.0
139.47754,0.002688968503937008,654.4667454068242,0.00025370340306410486,25.0,30.0
140.979,0.0027179964566929134,658.6932545931758,0.00025370340306410486,25.0,30.0
142.48047,0.0027528435039370076,661.7121522309711,0.00025370340306410486,25.0,30.0
143.98193,0.0028094478346456695,665.8049343832022,0.00025370340306410486,25.0,30.0
145.4834,0.002857706496062992,670.7163254593175,0.00025370340306410486,25.0,30.0
146.98486,0.0029124051181102363,671.5657480314961,0.00025370340306410486,25.0,30.0
148.48633,0.0029674437007874014,674.482624671916,0.00025370340306410486,25.0,30.0
149.98779,0.003020546850393701,680.607532808399,0.00025370340306410486,25.0,30.0
151.48926,0.0030745074803149607,681.9455643044619,0.00025370340306410486,25.0,30.0
152.99072,0.0031198624015748026,684.5938320209973,0.00025370340306410486,25.0,30.0
154.49219,0.0032167309055118115,690.026062992126,0.00025370340306410486,25.0,30.0
155.99365,0.0032705181102362204,692.0118635170603,0.00025370340306410486,25.0,30.0
157.49512,0.0033560535433070867,697.6952755905512,0.00025370340306410486,25.0,30.0
158.99658,0.0034142297244094486,698.6050656167979,0.00025370340306410486,25.0,30.0
160.49805,0.003519354330708661,702.0529658792651,0.00025370340306410486,25.0,30.0
161.99951,0.0035862622047244095,704.761312335958,0.00025370340306410486,25.0,30.0
163.50098,0.0036688950787401578,707.8641994750656,0.00025370340306410486,25.0,30.0
165.00244,0.003758492716535433,711.4121259842519,0.00025370340306410486,25.0,30.0
166.50391,0.0038647244094488185,713.5780577427821,0.00025370340306410486,25.0,30.0
168.00537,0.0039807501968503935,717.0281364829395,0.00025370340306410486,25.0,30.0
169.50684,0.004113867125984252,720.7979527559055,0.00025370340306410486,25.0,30.0
171.0083,0.0042400972440944885,723.1183989501312,0.00025370340306410486,25.0,30.0
172.50977,0.00436731437007874,727.3254855643045,0.00025370340306410486,25.0,30.0
174.01123,0.00452374842519685,729.3029658792651,0.00025370340306410486,25.0,30.0
175.5127,0.004651673228346457,728.845564304462,0.00025370340306410486,25.0,30.0
177.01416,0.004795190354330708,732.5891338582677,0.00025370340306410486,25.0,30.0
178.51563,0.004949103543307087,734.2605511811024,0.00025370340306410486,25.0,30.0
180.01709,0.005128631299212598,737.2071653543308,0.00025370340306410486,25.0,30.0
181.51855,0.005311154133858268,739.2932545931759,0.00025370340306410486,25.0,30.0
183.02002,0.005523866338582677,741.4927559055118,0.00025370340306410486,25.0,30.0
184.52148,0.0056750279527559054,742.4796325459317,0.00025370340306410486,25.0,30.0
186.02295,0.005877383858267716,744.895406824147,0.00025370340306410486,25.0,30.0
187.52441,0.006090702952755905,745.9167716535433,0.00025370340306410486,25.0,30.0
189.02588,0.006295649606299213,747.097217847769,0.00025370340306410486,25.0,30.0
190.52734,0.006488775196850393,749.8730708661417,0.00025370340306410486,25.0,30.0
192.02881,0.0067227637795275585,750.0464041994751,0.00025370340306410486,25.0,30.0
193.53027,0.006945107874015748,753.2714173228346,0.00025370340306410486,25.0,30.0
195.03174,0.007169101181102363,756.8464566929134,0.00025370340306410486,25.0,30.0
196.5332,0.007450256496062992,757.7180577427821,0.00025370340306410486,25.0,30.0
198.03467,0.007714815157480314,758.1874803149607,0.00025370340306410486,25.0,30.0
199.53613,0.008000115944881888,759.5928608923884,0.00025370340306410486,25.0,30.0
201.0376,0.008244466338582676,759.1181627296588,0.00025370340306410486,25.0,30.0
202.53906,0.008557902559055117,761.4238057742782,0.00025370340306410486,25.0,30.0
204.04053,0.008874000787401574,763.6541207349081,0.00025370340306410486,25.0,30.0
205.54199,0.009158624803149606,765.4359580052494,0.00025370340306410486,25.0,30.0
207.04346,0.009457263188976378,766.0261942257217,0.00025370340306410486,25.0,30.0
208.54492,0.009767307874015748,768.8529658792651,0.00025370340306410486,25.0,30.0
210.04639,0.010052882874015748,768.5982677165354,0.00025370340306410486,25.0,30.0
211.54785,0.010385326968503937,768.8623884514435,0.00025370340306410486,25.0,30.0
213.04932,0.010682383661417322,770.6119947506562,0.00025370340306410486,25.0,30.0
214.55078,0.01099744566929134,772.1918635170604,0.00025370340306410486,25.0,30.0
216.05225,0.011296215354330709,771.5883202099737,0.00025370340306410486,25.0,30.0
217.55371,0.011661169094488189,776.045249343832,0.00025370340306410486,25.0,30.0
219.05518,0.011983835826771653,773.8058792650919,0.00025370340306410486,25.0,30.0
220.55664,0.01230507244094488,776.5558267716535,0.00025370340306410486,25.0,30.0
222.05811,0.012637249409448818,777.6896587926509,0.00025370340306410486,25.0,30.0
223.55957,0.012946504330708663,778.6117322834646,0.00025370340306410486,25.0,30.0
225.06104,0.013254761811023622,778.696719160105,0.00025370340306410486,25.0,30.0
226.5625,0.013614262598425195,781.1819422572178,0.00025370340306410486,25.0,30.0
228.06396,0.013956440748031495,781.3957217847768,0.00025370340306410486,25.0,30.0
229.56543,0.014280784448818898,782.8249868766404,0.00025370340306410486,25.0,30.0
231.06689,0.014593045866141732,782.9777690288714,0.00025370340306410486,25.0,30.0
232.56836,0.014949314173228347,784.4339632545932,0.00025370340306410486,25.0,30.0
234.06982,0.015297565748031497,786.8277427821523,0.00025370340306410486,25.0,30.0
235.57129,0.0156452937007874,786.8132020997375,0.00025370340306410486,25.0,30.0
237.07275,0.01599483464566929,787.0098687664041,0.00025370340306410486,25.0,30.0
238.57422,0.016400275196850393,787.8691076115485,0.00025370340306410486,25.0,30.0
240.07568,0.01683724744094488,791.0238845144356,0.00025370340306410486,25.0,30.0
241.57715,0.01716708070866142,789.7748556430446,0.00025370340306410486,25.0,30.0
243.07861,0.01751834783464567,789.9926771653543,0.00025370340306410486,25.0,30.0
244.58008,0.017887943503937007,790.4829921259843,0.00025370340306410486,25.0,30.0
246.08154,0.018183652362204723,790.8859317585302,0.00025370340306410486,25.0,30.0
247.58301,0.018512994488188977,792.0785564304462,0.00025370340306410486,25.0,30.0
249.08447,0.018872375,794.8830446194225,0.00025370340306410486,25.0,30.0
250.58594,0.019288198031496062,794.0278477690288,0.00025370340306410486,25.0,30.0
252.0874,0.01965809724409449,793.0986351706038,0.00025370340306410486,25.0,30.0
253.58887,0.019984740157480314,794.7031758530184,0.00025370340306410486,25.0,30.0
255.09033,0.020294877952755905,796.4554855643044,0.00025370340306410486,25.0,30.0
256.5918,0.020641,796.2169816272965,0.00025370340306410486,25.0,30.0
258.09326,0.02097407283464567,798.1677952755905,0.00025370340306410486,25.0,30.0
259.59473,0.021339324803149606,798.5917322834646,0.00025370340306410486,25.0,30.0
261.09619,0.02173953937007874,801.8005511811023,0.00025370340306410486,25.0,30.0
262.59766,0.022100192913385826,800.3286614173228,0.00025370340306410486,25.0,30.0
264.09912,0.022433549212598426,800.1402624671916,0.00025370340306410486,25.0,30.0
265.60059,0.022800775590551183,802.1845669291338,0.00025370340306410486,25.0,30.0
267.10205,0.02317924409448819,802.229186351706,0.00025370340306410486,25.0,30.0
268.60352,0.023524797244094488,801.5633333333333,0.00025370340306410486,25.0,30.0
270.10498,0.023890194881889763,803.4838320209974,0.00025370340306410486,25.0,30.0
271.60645,0.024204799212598424,802.4039895013124,0.00025370340306410486,25.0,30.0
273.10791,0.024562903543307087,804.3382677165355,0.00025370340306410486,25.0,30.0
274.60938,0.02500334251968504,804.9349606299213,0.00025370340306410486,25.0,30.0
276.11084,0.025414226377952754,805.5881364829397,0.00025370340306410486,25.0,30.0
277.6123,0.025756681102362202,806.7109186351706,0.00025370340306410486,25.0,30.0
279.11377,0.02612891338582677,806.0750131233596,0.00025370340306410486,25.0,30.0
280.61523,0.026540041338582676,809.8456692913386,0.00025370340306410486,25.0,30.0
282.1167,0.026935755905511814,807.6165354330708,0.00025370340306410486,25.0,30.0
283.61816,0.027292799212598425,807.5296587926509,0.00025370340306410486,25.0,30.0
285.11963,0.027631084645669293,808.5418372703413,0.00025370340306410486,25.0,30.0
286.62109,0.028025572834645667,812.1133595800525,0.00025370340306410486,25.0,30.0
288.12256,0.028425734251968506,809.4704724409448,0.00025370340306410486,25.0,30.0
289.62402,0.02873361220472441,810.3206824146982,0.00025370340306410486,25.0,30.0
291.12549,0.029022877952755908,812.3339107611549,0.00025370340306410486,25.0,30.0
292.62695,0.029388246062992125,813.0219947506562,0.00025370340306410486,25.0,30.0
294.12842,0.029707883858267715,812.3153805774278,0.00025370340306410486,25.0,30.0
295.62988,0.03010898031496063,815.019658792651,0.00025370340306410486,25.0,30.0
297.13135,0.03046051968503937,815.7823884514436,0.00025370340306410486,25.0,30.0
298.63281,0.03081455905511811,814.2016797900262,0.00025370340306410486,25.0,30.0
300.13428,0.031197984251968503,816.5743832020997,0.00025370340306410486,25.0,30.0
301.63574,0.031568641732283464,816.8774278215222,0.00025370340306410486,25.0,30.0
303.13721,0.0319508562992126,817.1988451443569,0.00025370340306410486,25.0,30.0
304.63867,0.0322938405511811,816.6851181102362,0.00025370340306410486,25.0,30.0
306.14014,0.03265437007874016,819.1172965879265,0.00025370340306410486,25.0,30.0
307.6416,0.0330110374015748,817.7061417322834,0.00025370340306410486,25.0,30.0
309.14307,0.03339062401574803,820.2479002624672,0.00025370340306410486,25.0,30.0
310.64453,0.03380606692913386,820.7017060367455,0.00025370340306410486,25.0,30.0
312.146,0.03419273622047244,820.5941994750657,0.00025370340306410486,25.0,30.0
313.64746,0.03455517913385827,819.9728083989501,0.00025370340306410486,25.0,30.0
315.14893,0.03488775196850394,820.2259842519685,0.00025370340306410486,25.0,30.0
316.65039,0.03528238188976378,822.4996325459317,0.00025370340306410486,25.0,30.0
318.15186,0.035648763779527554,821.4154330708661,0.00025370340306410486,25.0,30.0
319.65332,0.036050669291338586,823.9187401574803,0.00025370340306410486,25.0,30.0
321.15479,0.03636668307086614,824.9151706036746,0.00025370340306410486,25.0,30.0
322.65625,0.03678856692913386,826.1332283464567,0.00025370340306410486,25.0,30.0
324.15771,0.03717403149606299,825.7194225721785,0.00025370340306410486,25.0,30.0
325.65918,0.03751415354330708,824.666719160105,0.00025370340306410486,25.0,30.0
327.16064,0.03787814763779527,824.0433595800524,0.00025370340306410486,25.0,30.0
328.66211,0.03819344881889764,824.902782152231,0.00025370340306410486,25.0,30.0
330.16357,0.038555521653543305,826.5961942257217,0.00025370340306410486,25.0,30.0
331.66504,0.03890841338582677,827.5094488188977,0.00025370340306410486,25.0,30.0
333.1665,0.03927734842519685,829.1650131233596,0.00025370340306410486,25.0,30.0
334.66797,0.039668354330708665,829.492309711286,0.00025370340306410486,25.0,30.0
336.16943,0.040044403543307086,828.624120734908,0.00025370340306410486,25.0,30.0
337.6709,0.040416566929133854,830.1775065616797,0.00025370340306410486,25.0,30.0
339.17236,0.04079173818897638,831.5683464566929,0.00025370340306410486,25.0,30.0
340.67383,0.041173281496062995,832.6453805774279,0.00025370340306410486,25.0,30.0
342.17529,0.04148596850393701,830.5523622047244,0.00025370340306410486,25.0,30.0
343.67676,0.04184803937007874,831.3499737532809,0.00025370340306410486,25.0,30.0
345.17822,0.04220477362204724,830.5837007874017,0.00025370340306410486,25.0,30.0
346.67969,0.04261123818897638,833.7939895013122,0.00025370340306410486,25.0,30.0
348.18115,0.04297050590551181,831.0337270341207,0.00025370340306410486,25.0,30.0
349.68262,0.04332125196850394,834.0288976377952,0.00025370340306410486,25.0,30.0
351.18408,0.04370204133858268,833.825905511811,0.00025370340306410486,25.0,30.0
352.68555,0.044040533464566926,834.6328608923884,0.00025370340306410486,25.0,30.0
354.18701,0.044356001968503936,836.0638057742782,0.00025370340306410486,25.0,30.0
355.68848,0.04476617125984252,837.4666666666667,0.00025370340306410486,25.0,30.0
357.18994,0.045183464566929135,836.1345406824147,0.00025370340306410486,25.0,30.0
358.69141,0.045475734251968505,834.4317847769029,0.00025370340306410486,25.0,30.0
360.19287,0.045842114173228345,838.0324934383202,0.00025370340306410486,25.0,30.0
361.69434,0.04616839960629921,836.1850918635171,0.00025370340306410486,25.0,30.0
363.1958,0.04642865354330709,837.3149343832021,0.00025370340306410486,25.0,30.0
364.69727,0.04677991338582677,839.627217847769,0.00025370340306410486,25.0,30.0
366.19873,0.04717087795275591,840.8197375328084,0.00025370340306410486,25.0,30.0
367.7002,0.047606529527559054,840.528188976378,0.00025370340306410486,25.0,30.0
369.20166,0.047974167322834646,839.4029396325459,0.00025370340306410486,25.0,30.0
370.70313,0.04831843700787401,841.8246981627296,0.00025370340306410486,25.0,30.0
372.20459,0.04867676771653543,841.011653543307,0.00025370340306410486,25.0,30.0
373.70605,0.0490271968503937,841.2068241469816,0.00025370340306410486,25.0,30.0
375.20752,0.04935576181102362,840.7923622047244,0.00025370340306410486,25.0,30.0
376.70898,0.04969097834645669,845.0240157480314,0.00025370340306410486,25.0,30.0
378.21045,0.05008187598425197,844.4038582677165,0.00025370340306410486,25.0,30.0
379.71191,0.050403635826771646,844.2508398950131,0.00025370340306410486,25.0,30.0
381.21338,0.05078600787401575,843.6605511811024,0.00025370340306410486,25.0,30.0
382.71484,0.05117075787401575,845.761312335958,0.00025370340306410486,25.0,30.0
384.21631,0.05156158464566929,845.302624671916,0.00025370340306410486,25.0,30.0
385.71777,0.05194914960629922,846.1193700787402,0.00025370340306410486,25.0,30.0
387.21924,0.0522722342519685,845.3758005249344,0.00025370340306410486,25.0,30.0
388.7207,0.05267937204724409,847.9908661417323,0.00025370340306410486,25.0,30.0
390.22217,0.0531056437007874,847.0594750656168,0.00025370340306410486,25.0,30.0
391.72363,0.05339712007874016,845.516404199475,0.00025370340306410486,25.0,30.0
393.2251,0.05374605905511811,848.5088713910761,0.00025370340306410486,25.0,30.0
394.72656,0.054041964566929133,846.2329396325459,0.00025370340306410486,25.0,30.0
396.22803,0.054445787401574804,851.2797900262468,0.00025370340306410486,25.0,30.0
397.72949,0.054820468503937014,850.2285039370079,0.00025370340306410486,25.0,30.0
399.23096,0.055231259842519684,850.6400787401575,0.00025370340306410486,25.0,30.0
400.73242,0.05558751377952756,851.2024409448818,0.00025370340306410486,25.0,30.0
402.23389,0.05594086614173228,851.5416010498687,0.00025370340306410486,25.0,30.0
403.73535,0.056257110236220466,849.9725196850394,0.00025370340306410486,25.0,30.0
405.23682,0.05660454921259842,851.7703674540683,0.00025370340306410486,25.0,30.0
406.73828,0.05695427362204725,851.5223884514435,0.00025370340306410486,25.0,30.0
408.23975,0.05728283858267716,852.9150131233596,0.00025370340306410486,25.0,30.0
409.74121,0.057638196850393696,852.5195275590552,0.00025370340306410486,25.0,30.0
411.24268,0.0579807874015748,853.112624671916,0.00025370340306410486,25.0,30.0
412.74414,0.05831883858267717,854.0825196850393,0.00025370340306410486,25.0,30.0
414.24561,0.05871156692913386,854.0255118110236,0.00025370340306410486,25.0,30.0
415.74707,0.05908566732283465,855.2765091863517,0.00025370340306410486,25.0,30.0
417.24854,0.0594197657480315,853.9832020997375,0.00025370340306410486,25.0,30.0
418.75,0.059774864173228345,855.6358005249344,0.00025370340306410486,25.0,30.0
420.25146,0.06014209645669291,856.4707611548556,0.00025370340306410486,25.0,30.0
421.75293,0.06045692716535433,856.6531758530183,0.00025370340306410486,25.0,30.0
423.25439,0.06083464763779527,856.6098687664041,0.00025370340306410486,25.0,30.0
424.75586,0.06118446653543307,858.6651968503937,0.00025370340306410486,25.0,30.0
426.25732,0.061574425196850385,857.2510498687664,0.00025370340306410486,25.0,30.0
427.75879,0.06192180511811023,858.4114435695537,0.00025370340306410486,25.0,30.0
429.26025,0.06229700393700787,858.8787139107612,0.00025370340306410486,25.0,30.0
430.76172,0.06265212007874016,858.7769553805774,0.00025370340306410486,25.0,30.0
432.26318,0.06300903149606299,860.0497637795276,0.00025370340306410486,25.0,30.0
433.76465,0.06338822047244094,861.5784776902888,0.00025370340306410486,25.0,30.0
435.26611,0.06365935039370078,858.8128871391076,0.00025370340306410486,25.0,30.0
436.76758,0.06398086417322835,859.3236745406824,0.00025370340306410486,25.0,30.0
438.26904,0.06424052559055117,860.1898162729658,0.00025370340306410486,25.0,30.0
439.77051,0.06455862401574804,862.9828346456692,0.00025370340306410486,25.0,30.0
441.27197,0.06492713385826772,861.6171916010499,0.00025370340306410486,25.0,30.0
442.77344,0.06530770669291339,862.4985826771654,0.00025370340306410486,25.0,30.0
444.2749,0.06561861811023621,862.1094488188977,0.00025370340306410486,25.0,30.0
445.77637,0.06598124999999999,863.8031758530184,0.00025370340306410486,25.0,30.0
447.27783,0.0663499783464567,862.846220472441,0.00025370340306410486,25.0,30.0
448.7793,0.0666767657480315,863.6167716535433,0.00025370340306410486,25.0,30.0
450.28076,0.06705031496062992,865.2157217847769,0.00025370340306410486,25.0,30.0
451.78223,0.06741645472440945,866.0858530183727,0.00025370340306410486,25.0,30.0
453.28369,0.06779485039370078,866.7329133858267,0.00025370340306410486,25.0,30.0
454.78516,0.06817354527559055,866.0110761154855,0.00025370340306410486,25.0,30.0
456.28662,0.06851820866141732,866.6910761154855,0.00025370340306410486,25.0,30.0
457.78809,0.06889077952755905,868.277217847769,0.00025370340306410486,25.0,30.0
459.28955,0.06923741732283464,866.5988713910762,0.00025370340306410486,25.0,30.0
460.79102,0.06957338582677165,866.7101049868767,0.00025370340306410486,25.0,30.0
462.29248,0.06987262401574804,869.8674803149606,0.00025370340306410486,25.0,30.0
463.79395,0.07022120078740157,868.7230971128608,0.00025370340306410486,25.0,30.0
465.29541,0.07059560039370079,869.738346456693,0.00025370340306410486,25.0,30.0
466.79688,0.07100231496062992,870.0044094488189,0.00025370340306410486,25.0,30.0
468.29834,0.07135227362204724,869.0782152230971,0.00025370340306410486,25.0,30.0
469.7998,0.0716517342519685,869.4672440944881,0.00025370340306410486,25.0,30.0
471.30127,0.07198739173228347,870.0661679790026,0.00025370340306410486,25.0,30.0
472.80273,0.07234712007874015,870.9554593175852,0.00025370340306410486,25.0,30.0
474.3042,0.07268987598425197,871.1097637795275,0.00025370340306410486,25.0,30.0
475.80566,0.07309008464566928,871.1364829396326,0.00025370340306410486,25.0,30.0
477.30713,0.07343345669291339,871.1719947506562,0.00025370340306410486,25.0,30.0
478.80859,0.0737930905511811,872.0645406824146,0.00025370340306410486,25.0,30.0
480.31006,0.07417337598425197,874.8578215223097,0.00025370340306410486,25.0,30.0
481.81152,0.07451496456692913,872.6460104986877,0.00025370340306410486,25.0,30.0
483.31299,0.07487546653543306,872.1123359580052,0.00025370340306410486,25.0,30.0
484.81445,0.0751860374015748,873.0983202099738,0.00025370340306410486,25.0,30.0
486.31592,0.075514468503937,873.9878740157479,0.00025370340306410486,25.0,30.0
487.81738,0.07586879330708661,875.4113910761155,0.00025370340306410486,25.0,30.0
489.31885,0.07622829133858268,875.5941994750656,0.00025370340306410486,25.0,30.0
490.82031,0.07653833661417322,874.5316535433071,0.00025370340306410486,25.0,30.0
492.32178,0.07696154724409449,875.433937007874,0.00025370340306410486,25.0,30.0
493.82324,0.07727937598425197,876.04,0.00025370340306410486,25.0,30.0
495.32471,0.0776178838582677,875.1763517060367,0.00025370340306410486,25.0,30.0
496.82617,0.07792579330708661,876.6440682414698,0.00025370340306410486,25.0,30.0
498.32764,0.07829285433070866,877.4056430446194,0.00025370340306410486,25.0,30.0
499.8291,0.07869868700787401,877.4833858267716,0.00025370340306410486,25.0,30.0
501.33057,0.07909925984251968,878.5570078740158,0.00025370340306410486,25.0,30.0
502.83203,0.07948638976377952,878.8876640419948,0.00025370340306410486,25.0,30.0
504.3335,0.07983376968503937,878.1169291338583,0.00025370340306410486,25.0,30.0
505.83496,0.08014713976377953,878.20343832021,0.00025370340306410486,25.0,30.0
507.33643,0.0805300688976378,879.5463254593176,0.00025370340306410486,25.0,30.0
508.83789,0.08089967125984251,879.7438845144356,0.00025370340306410486,25.0,30.0
510.33936,0.08120909842519686,878.2605249343832,0.00025370340306410486,25.0,30.0
511.84082,0.08157247047244094,878.980656167979,0.00025370340306410486,25.0,30.0
513.34229,0.08188382283464567,881.6587664041995,0.00025370340306410486,25.0,30.0
514.84375,0.0822252342519685,882.2828346456694,0.00025370340306410486,25.0,30.0
516.34521,0.08263849015748032,883.3278215223097,0.00025370340306410486,25.0,30.0
517.84668,0.08298109448818898,881.1809186351707,0.00025370340306410486,25.0,30.0
519.34814,0.08331432874015747,881.4722834645669,0.00025370340306410486,25.0,30.0
520.84961,0.08362835039370078,882.55656167979,0.00025370340306410486,25.0,30.0
522.35107,0.08392054133858268,882.4776902887138,0.00025370340306410486,25.0,30.0
523.85254,0.08425821653543307,883.3032808398949,0.00025370340306410486,25.0,30.0
525.354,0.08466644488188976,885.2291076115486,0.00025370340306410486,25.0,30.0
526.85547,0.08505675,885.5211023622047,0.00025370340306410486,25.0,30.0
528.35693,0.0853984842519685,883.7858005249344,0.00025370340306410486,25.0,30.0
529.8584,0.08575470472440945,883.2734120734907,0.00025370340306410486,25.0,30.0
531.35986,0.08611177559055118,883.3777427821522,0.00025370340306410486,25.0,30.0
532.86133,0.08645488779527559,886.0465091863517,0.00025370340306410486,25.0,30.0
534.36279,0.08682336417322833,885.795249343832,0.00025370340306410486,25.0,30.0
535.86426,0.08718209448818898,887.647375328084,0.00025370340306410486,25.0,30.0
537.36572,0.08754008070866143,886.2874278215222,0.00025370340306410486,25.0,30.0
538.86719,0.0878806062992126,886.2576902887139,0.00025370340306410486,25.0,30.0
540.36865,0.08821966732283465,886.0662467191602,0.00025370340306410486,25.0,30.0
541.87012,0.08853619881889764,886.2058005249344,0.00025370340306410486,25.0,30.0
543.37158,0.0888270590551181,886.5169553805774,0.00025370340306410486,25.0,30.0
544.87305,0.08921939960629921,889.378346456693,0.00025370340306410486,25.0,30.0
546.37451,0.0896230688976378,887.8994750656168,0.00025370340306410486,25.0,30.0
547.87598,0.0899641062992126,886.9311811023622,0.00025370340306410486,25.0,30.0
549.37744,0.09029244291338583,889.389816272966,0.00025370340306410486,25.0,30.0
550.87891,0.09071448031496063,890.2462992125984,0.00025370340306410486,25.0,30.0
552.38037,0.091105218503937,889.4777952755906,0.00025370340306410486,25.0,30.0
553.88184,0.09143225787401575,889.4715223097113,0.00025370340306410486,25.0,30.0
555.3833,0.09183085826771653,889.9420472440945,0.00025370340306410486,25.0,30.0
556.88477,0.09217441732283464,889.8987926509186,0.00025370340306410486,25.0,30.0
558.38623,0.09253917322834646,890.0739107611548,0.00025370340306410486,25.0,30.0
559.8877,0.09295094488188976,893.0564829396326,0.00025370340306410486,25.0,30.0
561.38916,0.09330963976377953,892.0366666666667,0.00025370340306410486,25.0,30.0
562.89063,0.09362150196850393,892.4273490813648,0.00025370340306410486,25.0,30.0
564.39209,0.09397162204724409,891.0402887139107,0.00025370340306410486,25.0,30.0
565.89355,0.09430903346456693,890.8811286089239,0.00025370340306410486,25.0,30.0
567.39502,0.09460199803149606,892.8702624671917,0.00025370340306410486,25.0,30.0
568.89648,0.09498218897637796,894.4925459317585,0.00025370340306410486,25.0,30.0
570.39795,0.0953806968503937,894.5625196850393,0.00025370340306410486,25.0,30.0
571.89941,0.0957810157480315,894.9965354330708,0.00025370340306410486,25.0,30.0
573.40088,0.09606606692913386,892.3512335958005,0.00025370340306410486,25.0,30.0
574.90234,0.09642029330708661,895.1656430446194,0.00025370340306410486,25.0,30.0
576.40381,0.09678323031496062,895.4262467191601,0.00025370340306410486,25.0,30.0
577.90527,0.09713357677165355,896.5638845144356,0.00025370340306410486,25.0,30.0
579.40674,0.09745536614173228,897.2207086614172,0.00025370340306410486,25.0,30.0
580.9082,0.09783930511811023,895.816089238845,0.00025370340306410486,25.0,30.0
582.40967,0.09817183661417322,895.6435433070866,0.00025370340306410486,25.0,30.0
583.91113,0.09842719094488189,897.1250393700788,0.00025370340306410486,25.0,30.0
585.4126,0.09873012007874014,897.1427296587926,0.00025370340306410486,25.0,30.0
586.91406,0.09896976968503937,896.2402362204724,0.00025370340306410486,25.0,30.0
588.41553,0.09925710433070865,896.9658530183726,0.00025370340306410486,25.0,30.0
589.91699,0.09953012401574804,897.6720209973753,0.00025370340306410486,25.0,30.0
591.41846,0.09982883858267717,897.3445144356955,0.00025370340306410486,25.0,30.0
592.91992,0.1001315905511811,897.9823359580053,0.00025370340306410486,25.0,30.0
594.42139,0.10047705118110235,898.2571916010498,0.00025370340306410486,25.0,30.0
595.92285,0.10076696653543306,899.581627296588,0.00025370340306410486,25.0,30.0
597.42432,0.10114915354330707,900.7268503937007,0.00025370340306410486,25.0,30.0
598.92578,0.10151702362204723,899.5945669291339,0.00025370340306410486,25.0,30.0
600.42725,0.101816031496063,899.8343569553806,0.00025370340306410486,25.0,30.0
601.92871,0.10208225787401574,900.9274803149606,0.00025370340306410486,25.0,30.0
603.43018,0.1023316594488189,900.4428608923885,0.00025370340306410486,25.0,30.0
604.93164,0.10263743897637795,900.8123884514437,0.00025370340306410486,25.0,30.0
606.43311,0.10294511811023623,901.3887139107612,0.00025370340306410486,25.0,30.0
607.93457,0.1032705846456693,901.4628608923884,0.00025370340306410486,25.0,30.0
609.43604,0.10357700984251969,902.0837270341207,0.00025370340306410486,25.0,30.0
610.9375,0.10394652362204725,902.5844881889764,0.00025370340306410486,25.0,30.0
612.43896,0.10430568700787403,902.4322309711285,0.00025370340306410486,25.0,30.0
613.94043,0.10465003346456693,901.9441469816273,0.00025370340306410486,25.0,30.0
615.44189,0.10498786811023621,903.5004986876639,0.00025370340306410486,25.0,30.0
616.94336,0.10534826377952757,903.6012860892388,0.00025370340306410486,25.0,30.0
618.44482,0.10576958070866141,902.6774015748031,0.00025370340306410486,25.0,30.0
619.94629,0.10613394291338583,902.914435695538,0.00025370340306410486,25.0,30.0
621.44775,0.10648714763779527,904.2790551181101,0.00025370340306410486,25.0,30.0
622.94922,0.10685188582677164,904.5206299212598,0.00025370340306410486,25.0,30.0
624.45068,0.10720537204724409,904.8919685039369,0.00025370340306410486,25.0,30.0
625.95215,0.10758025984251969,904.0966404199476,0.00025370340306410486,25.0,30.0
627.45361,0.10793639763779528,905.6532283464567,0.00025370340306410486,25.0,30.0
628.95508,0.10837408070866142,907.122624671916,0.00025370340306410486,25.0,30.0
630.45654,0.10881371062992126,906.9160892388452,0.00025370340306410486,25.0,30.0
631.95801,0.10936926574803149,907.2122834645669,0.00025370340306410486,25.0,30.0
633.45947,0.10980892125984251,906.1158792650918,0.00025370340306410486,25.0,30.0
634.96094,0.11021794094488188,906.3172703412073,0.00025370340306410486,25.0,30.0
636.4624,0.11062873228346456,908.4672703412073,0.00025370340306410486,25.0,30.0
637.96387,0.11110864370078741,906.9819160104986,0.00025370340306410486,25.0,30.0
639.46533,0.11147401377952755,906.0228346456693,0.00025370340306410486,25.0,30.0
640.9668,0.11183019881889764,907.9872965879265,0.00025370340306410486,25.0,30.0
642.46826,0.11226357677165354,907.1722834645669,0.00025370340306410486,25.0,30.0
643.96973,0.1126583877952756,906.0867979002625,0.00025370340306410486,25.0,30.0
645.47119,0.11301811614173228,908.1470603674541,0.00025370340306410486,25.0,30.0
646.97266,0.11340783267716535,908.1720472440944,0.00025370340306410486,25.0,30.0
648.47412,0.11383157874015748,910.0154593175853,0.00025370340306410486,25.0,30.0
649.97559,0.11421154527559056,909.0494750656168,0.00025370340306410486,25.0,30.0
651.47705,0.11456855118110235,906.450498687664,0.00025370340306410486,25.0,30.0
652.97852,0.11489331496062992,910.083595800525,0.00025370340306410486,25.0,30.0
654.47998,0.11523809448818897,907.8127034120735,0.00025370340306410486,25.0,30.0
655.98145,0.11558856496062991,910.3039632545932,0.00025370340306410486,25.0,30.0
657.48291,0.11594677952755905,910.8713648293963,0.00025370340306410486,25.0,30.0
658.98438,0.11631885236220474,910.9377690288713,0.00025370340306410486,25.0,30.0
660.48584,0.11665756496062991,910.9341732283465,0.00025370340306410486,25.0,30.0
661.9873,0.11699123425196849,911.6581364829397,0.00025370340306410486,25.0,30.0
663.48877,0.11734376968503937,911.5586089238845,0.00025370340306410486,25.0,30.0
664.99023,0.1177001535433071,911.1323622047244,0.00025370340306410486,25.0,30.0
666.4917,0.1180955748031496,912.7015223097113,0.00025370340306410486,25.0,30.0
667.99316,0.11851084842519685,913.3849343832021,0.00025370340306410486,25.0,30.0
669.49463,0.11897164566929135,912.267716535433,0.00025370340306410486,25.0,30.0
670.99609,0.11941805905511811,912.7874540682415,0.00025370340306410486,25.0,30.0
672.49756,0.11977852559055117,910.6582414698163,0.00025370340306410486,25.0,30.0
673.99902,0.12018141929133859,912.455091863517,0.00025370340306410486,25.0,30.0
675.50049,0.12059489763779527,913.4742519685038,0.00025370340306410486,25.0,30.0
677.00195,0.12099231299212597,913.6530971128609,0.00025370340306410486,25.0,30.0
678.50342,0.12140316338582677,914.2156430446194,0.00025370340306410486,25.0,30.0
680.00488,0.12179503937007874,912.7666404199474,0.00025370340306410486,25.0,30.0
681.50635,0.12215989566929135,912.8583989501312,0.00025370340306410486,25.0,30.0
683.00781,0.1225576279527559,913.9893963254592,0.00025370340306410486,25.0,30.0
684.50928,0.1229576003937008,912.6712860892388,0.00025370340306410486,25.0,30.0
686.01074,0.12332044881889763,913.8940419947506,0.00025370340306410486,25.0,30.0
687.51221,0.12365801377952756,913.5888976377953,0.00025370340306410486,25.0,30.0
689.01367,0.12401422244094489,915.445905511811,0.00025370340306410486,25.0,30.0
690.51514,0.124392218503937,915.27,0.00025370340306410486,25.0,30.0
692.0166,0.12477238582677165,917.3646194225722,0.00025370340306410486,25.0,30.0
693.51807,0.12520666732283464,915.987375328084,0.00025370340306410486,25.0,30.0
695.01953,0.1256166476377953,916.4220734908137,0.00025370340306410486,25.0,30.0
696.521,0.12603119291338583,915.7218897637795,0.00025370340306410486,25.0,30.0
698.02246,0.1265100846456693,917.2402362204724,0.00025370340306410486,25.0,30.0
699.52393,0.12686882677165354,914.3617585301837,0.00025370340306410486,25.0,30.0
701.02539,0.1271793346456693,916.2580314960629,0.00025370340306410486,25.0,30.0
702.52686,0.12750997637795275,917.7235958005249,0.00025370340306410486,25.0,30.0
704.02832,0.1279170472440945,918.5009186351706,0.00025370340306410486,25.0,30.0
705.52979,0.12847410433070866,918.3004986876641,0.00025370340306410486,25.0,30.0
707.03125,0.12889107874015748,917.3111023622047,0.00025370340306410486,25.0,30.0
708.53271,0.1293402716535433,917.8315485564304,0.00025370340306410486,25.0,30.0
710.03418,0.12969375787401574,917.0160892388451,0.00025370340306410486,25.0,30.0
711.53564,0.13011805511811023,919.2448293963254,0.00025370340306410486,25.0,30.0
713.03711,0.13049443110236222,919.7088188976378,0.00025370340306410486,25.0,30.0
714.53857,0.13095441929133858,919.96968503937,0.00025370340306410486,25.0,30.0
716.04004,0.1314118031496063,917.7643307086614,0.00025370340306410486,25.0,30.0
717.5415,0.13181210433070867,916.7169028871391,0.00025370340306410486,25.0,30.0
719.04297,0.13220305511811023,919.3451706036745,0.00025370340306410486,25.0,30.0
720.54443,0.132586437007874,918.7435170603675,0.00025370340306410486,25.0,30.0
722.0459,0.13297850196850394,919.3665091863517,0.00025370340306410486,25.0,30.0
723.54736,0.1333413622047244,919.6348031496062,0.00025370340306410486,25.0,30.0
725.04883,0.13377002362204723,920.8039895013123,0.00025370340306410486,25.0,30.0
726.55029,0.13414755118110236,920.1781364829396,0.00025370340306410486,25.0,30.0
728.05176,0.13453764566929133,920.4779002624671,0.00025370340306410486,25.0,30.0
729.55322,0.13495695472440944,920.1843307086615,0.00025370340306410486,25.0,30.0
731.05469,0.1353434212598425,922.363280839895,0.00025370340306410486,25.0,30.0
732.55615,0.13575464763779527,921.1995538057743,0.00025370340306410486,25.0,30.0
734.05762,0.13618877559055118,922.4946981627296,0.00025370340306410486,25.0,30.0
735.55908,0.13663417913385828,922.4112073490813,0.00025370340306410486,25.0,30.0
737.06055,0.13706003543307088,922.9509448818898,0.00025370340306410486,25.0,30.0
738.56201,0.13747177755905512,922.2977952755906,0.00025370340306410486,25.0,30.0
740.06348,0.13789426574803149,922.3434908136484,0.00025370340306410486,25.0,30.0
741.56494,0.1382717342519685,920.645905511811,0.00025370340306410486,25.0,30.0
743.06641,0.13864513188976377,922.348871391076,0.00025370340306410486,25.0,30.0
744.56787,0.1390991594488189,922.927375328084,0.00025370340306410486,25.0,30.0
746.06934,0.1395049881889764,923.669527559055,0.00025370340306410486,25.0,30.0
747.5708,0.13988224606299213,921.6873228346457,0.00025370340306410486,25.0,30.0
749.07227,0.14026330511811025,922.5403937007874,0.00025370340306410486,25.0,30.0
750.57373,0.14068323622047244,923.1122309711286,0.00025370340306410486,25.0,30.0
752.0752,0.14107882086614174,923.4921522309711,0.00025370340306410486,25.0,30.0
753.57666,0.14141930511811024,923.2053543307087,0.00025370340306410486,25.0,30.0
755.07813,0.14179415748031496,923.2055905511811,0.00025370340306410486,25.0,30.0
756.57959,0.14218859251968505,924.1691601049869,0.00025370340306410486,25.0,30.0
758.08105,0.14262538582677164,923.9583989501313,0.00025370340306410486,25.0,30.0
759.58252,0.14304961023622048,923.8276640419947,0.00025370340306410486,25.0,30.0
761.08398,0.14346052952755906,923.7153543307087,0.00025370340306410486,25.0,30.0
762.58545,0.14386005708661417,922.738845144357,0.00025370340306410486,25.0,30.0
764.08691,0.14418837598425197,923.342467191601,0.00025370340306410486,25.0,30.0
765.58838,0.14462777165354332,926.757375328084,0.00025370340306410486,25.0,30.0
767.08984,0.1450863523622047,925.3641732283464,0.00025370340306410486,25.0,30.0
768.59131,0.14557439566929134,925.7297375328084,0.00025370340306410486,25.0,30.0
770.09277,0.14600996653543305,924.5961679790026,0.00025370340306410486,25.0,30.0
771.59424,0.14647813385826772,924.8239107611548,0.00025370340306410486,25.0,30.0
773.0957,0.14689978937007872,923.9938845144358,0.00025370340306410486,25.0,30.0
774.59717,0.14730833858267717,925.5448556430446,0.00025370340306410486,25.0,30.0
776.09863,0.1477733720472441,925.504750656168,0.00025370340306410486,25.0,30.0
777.6001,0.1482185531496063,925.2190288713911,0.00025370340306410486,25.0,30.0
779.10156,0.1486373937007874,927.1465091863516,0.00025370340306410486,25.0,30.0
780.60303,0.1490783031496063,924.028687664042,0.00025370340306410486,25.0,30.0
782.10449,0.14944960039370078,925.2016010498687,0.00025370340306410486,25.0,30.0
783.60596,0.149900718503937,926.5056692913386,0.00025370340306410486,25.0,30.0
785.10742,0.15038240157480315,928.1758792650919,0.00025370340306410486,25.0,30.0
786.60889,0.1508799468503937,928.2782677165354,0.00025370340306410486,25.0,30.0
788.11035,0.15137982874015748,927.1120472440945,0.00025370340306410486,25.0,30.0
789.61182,0.15184725590551182,926.8775853018373,0.00025370340306410486,25.0,30.0
791.11328,0.15229637992125983,925.6945406824148,0.00025370340306410486,25.0,30.0
792.61475,0.15270382677165356,927.0236220472441,0.00025370340306410486,25.0,30.0
794.11621,0.1530862342519685,925.7862992125985,0.00025370340306410486,25.0,30.0
795.61768,0.1533995,924.8131496062992,0.00025370340306410486,25.0,30.0
797.11914,0.15383212598425197,927.5258005249344,0.00025370340306410486,25.0,30.0
798.62061,0.15426441141732283,928.4653280839896,0.00025370340306410486,25.0,30.0
800.12207,0.15473411614173227,930.0158530183727,0.00025370340306410486,25.0,30.0
801.62354,0.15522123031496063,927.9946719160105,0.00025370340306410486,25.0,30.0
803.125,0.15568412992125985,928.8608923884515,0.00025370340306410486,25.0,30.0
804.62646,0.1561004468503937,927.072624671916,0.00025370340306410486,25.0,30.0
806.12793,0.1565230531496063,927.6394750656168,0.00025370340306410486,25.0,30.0
807.62939,0.15697125984251967,929.9425459317584,0.00025370340306410486,25.0,30.0
809.13086,0.15748907086614172,928.053937007874,0.00025370340306410486,25.0,30.0
810.63232,0.15788278937007874,928.4806299212598,0.00025370340306410486,25.0,30.0
812.13379,0.15829194881889763,928.738372703412,0.00025370340306410486,25.0,30.0
813.63525,0.15876288582677164,928.4423097112862,0.00025370340306410486,25.0,30.0
815.13672,0.1592490846456693,930.489842519685,0.00025370340306410486,25.0,30.0
816.63818,0.15972997047244095,930.0023884514435,0.00025370340306410486,25.0,30.0
818.13965,0.16016284251968504,929.6190551181102,0.00025370340306410486,25.0,30.0
819.64111,0.1605464842519685,928.3754855643044,0.00025370340306410486,25.0,30.0
821.14258,0.1610100157480315,931.161968503937,0.00025370340306410486,25.0,30.0
822.64404,0.16147642125984252,931.1089501312335,0.00025370340306410486,25.0,30.0
824.14551,0.1619416437007874,928.5506824146981,0.00025370340306410486,25.0,30.0
825.64697,0.1623589566929134,930.9021259842519,0.00025370340306410486,25.0,30.0
827.14844,0.16287743503937008,929.9838582677165,0.00025370340306410486,25.0,30.0
828.6499,0.1633179350393701,930.3636482939633,0.00025370340306410486,25.0,30.0
830.15137,0.1637471003937008,929.3901049868766,0.00025370340306410486,25.0,30.0
831.65283,0.16416987007874015,929.4757217847769,0.00025370340306410486,25.0,30.0
833.1543,0.1646476811023622,929.1583989501312,0.00025370340306410486,25.0,30.0
834.65576,0.16510292913385827,931.4570341207349,0.00025370340306410486,25.0,30.0
836.15723,0.1655677755905512,930.0730708661417,0.00025370340306410486,25.0,30.0
837.65869,0.16599513385826772,931.608530183727,0.00025370340306410486,25.0,30.0
839.16016,0.166415218503937,929.3296062992126,0.00025370340306410486,25.0,30.0
840.66162,0.16685217322834647,930.5512073490813,0.00025370340306410486,25.0,30.0
842.16309,0.16729579527559055,931.3347244094488,0.00025370340306410486,25.0,30.0
843.66455,0.1677432874015748,930.5680052493439,0.00025370340306410486,25.0,30.0
845.16602,0.1682044842519685,930.0287139107611,0.00025370340306410486,25.0,30.0
846.66748,0.16866630314960632,931.8794488188977,0.00025370340306410486,25.0,30.0
848.16895,0.16923836614173227,931.5960367454069,0.00025370340306410486,25.0,30.0
849.67041,0.16974150984251968,931.0725721784777,0.00025370340306410486,25.0,30.0
851.17188,0.17020589763779528,930.7167454068241,0.00025370340306410486,25.0,30.0
852.67334,0.17069536023622045,929.1107349081365,0.00025370340306410486,25.0,30.0
854.1748,0.17116128543307085,932.3317847769029,0.00025370340306410486,25.0,30.0
855.67627,0.17161520669291339,931.7840419947507,0.00025370340306410486,25.0,30.0
857.17773,0.17211273031496063,930.1461154855642,0.00025370340306410486,25.0,30.0
858.6792,0.17253934842519683,930.8259842519685,0.00025370340306410486,25.0,30.0
860.18066,0.17301707677165354,931.8045406824147,0.00025370340306410486,25.0,30.0
861.68213,0.1735362716535433,932.2980052493439,0.00025370340306410486,25.0,30.0
863.18359,0.1740634212598425,931.686377952756,0.00025370340306410486,25.0,30.0
864.68506,0.17449762007874015,930.0202624671915,0.00025370340306410486,25.0,30.0
866.18652,0.1749606929133858,931.6361942257217,0.00025370340306410486,25.0,30.0
867.68799,0.17545135236220472,932.4209711286089,0.00025370340306410486,25.0,30.0
869.18945,0.17593655511811024,930.946719160105,0.00025370340306410486,25.0,30.0
870.69092,0.17639390354330708,932.5157480314961,0.00025370340306410486,25.0,30.0
872.19238,0.17680790944881888,932.401627296588,0.00025370340306410486,25.0,30.0
873.69385,0.17736036614173228,932.8831758530184,0.00025370340306410486,25.0,30.0
875.19531,0.17780637007874014,930.6138320209974,0.00025370340306410486,25.0,30.0
876.69678,0.17827401968503936,931.9194225721784,0.00025370340306410486,25.0,30.0
878.19824,0.17873277559055117,930.7314698162729,0.00025370340306410486,25.0,30.0
879.69971,0.17912337401574802,929.8461679790026,0.00025370340306410486,25.0,30.0
881.20117,0.17954776377952755,933.1336745406825,0.00025370340306410486,25.0,30.0
882.70264,0.1800932874015748,932.3121784776903,0.00025370340306410486,25.0,30.0
884.2041,0.18064177952755905,933.6341732283465,0.00025370340306410486,25.0,30.0
885.70557,0.18122376968503937,932.5446456692913,0.00025370340306410486,25.0,30.0
887.20703,0.18173182874015748,930.6807349081364,0.00025370340306410486,25.0,30.0
888.7085,0.18207310039370078,931.4929133858267,0.00025370340306410486,25.0,30.0
890.20996,0.18252190551181102,932.1149343832021,0.00025370340306410486,25.0,30.0
891.71143,0.1830107460629921,933.9093963254594,0.00025370340306410486,25.0,30.0
893.21289,0.18356178543307086,932.388687664042,0.00025370340306410486,25.0,30.0
894.71436,0.18401120078740157,931.7255905511811,0.00025370340306410486,25.0,30.0
896.21582,0.18449172244094486,933.6181102362204,0.00025370340306410486,25.0,30.0
897.71729,0.1849780748031496,931.9785039370079,0.00025370340306410486,25.0,30.0
899.21875,0.18537619488188975,930.266719160105,0.00025370340306410486,25.0,30.0
900.72021,0.18578413385826772,934.0353280839895,0.00025370340306410486,25.0,30.0
902.22168,0.18624961417322833,933.6682677165354,0.00025370340306410486,25.0,30.0
903.72314,0.18677977755905512,933.449002624672,0.00025370340306410486,25.0,30.0
905.22461,0.18724738188976378,933.8653805774278,0.00025370340306410486,25.0,30.0
906.72607,0.18776901574803148,932.6812073490814,0.00025370340306410486,25.0,30.0
908.22754,0.1882496437007874,933.8582152230971,0.00025370340306410486,25.0,30.0
909.729,0.188716718503937,932.4181627296588,0.00025370340306410486,25.0,30.0
911.23047,0.1892203188976378,933.9273490813648,0.00025370340306410486,25.0,30.0
912.73193,0.18969310826771654,932.344908136483,0.00025370340306410486,25.0,30.0
914.2334,0.19025326181102362,933.3646719160105,0.00025370340306410486,25.0,30.0
915.73486,0.19081877952755905,932.4562729658792,0.00025370340306410486,25.0,30.0
917.23633,0.191353531496063,932.0960367454068,0.00025370340306410486,25.0,30.0
918.73779,0.19192299015748032,934.5648031496063,0.00025370340306410486,25.0,30.0
920.23926,0.19247415748031496,931.5332808398949,0.00025370340306410486,25.0,30.0
921.74072,0.19298009251968504,932.6865879265091,0.00025370340306410486,25.0,30.0
923.24219,0.19352896062992125,933.6217585301837,0.00025370340306410486,25.0,30.0
923.64258,0.1936778307086614,935.865721784777,0.00025370340306410486,25.0,30.0