File: datasets/am_bench_2022/csv/30-XY.12-1.csv
Time(s),Strain(%),Stress(MPa),SR(s-1),Temp(C),Angle(deg)
30.777832,1.779745492125984e-05,18.551890026246717,0.00025370340306410486,25.0,30.0
32.479492,3.4488606299212596e-05,25.57218267716535,0.00025370340306410486,25.0,30.0
34.081055,3.839444094488189e-05,30.341181102362206,0.00025370340306410486,25.0,30.0
35.682617,5.7303901574803146e-05,35.72508661417323,0.00025370340306410486,25.0,30.0
37.28418,7.004485236220473e-05,41.53025984251968,0.00025370340306410486,25.0,30.0
38.885742,0.00011515031299212598,49.60043569553805,0.00025370340306410486,25.0,30.0
40.487305,0.00014435493110236222,57.01261417322835,0.00025370340306410486,25.0,30.0
42.088867,0.00017249558464566927,65.85107086614174,0.00025370340306410486,25.0,30.0
43.69043,0.00019864881889763782,73.67569816272966,0.00025370340306410486,25.0,30.0
45.291992,0.0002286641535433071,82.91674803149606,0.00025370340306410486,25.0,30.0
46.893555,0.0002663435039370079,92.08328346456693,0.00025370340306410486,25.0,30.0
48.495117,0.0002652432283464567,100.69339895013123,0.00025370340306410486,25.0,30.0
50.09668,0.0003107753937007874,109.80561154855643,0.00025370340306410486,25.0,30.0
51.698242,0.000334648031496063,118.34363517060368,0.00025370340306410486,25.0,30.0
53.299805,0.00036080206692913386,128.79834908136482,0.00025370340306410486,25.0,30.0
54.901367,0.00039502954724409447,138.86846981627298,0.00025370340306410486,25.0,30.0
56.50293,0.00043655346456692915,149.95806036745407,0.00025370340306410486,25.0,30.0
58.104492,0.0004833157677165355,161.53782414698162,0.00025370340306410486,25.0,30.0
59.706055,0.0005154929527559055,173.11926771653543,0.00025370340306410486,25.0,30.0
61.307617,0.0005492906692913385,182.1769501312336,0.00025370340306410486,25.0,30.0
62.90918,0.000576495,193.04285826771653,0.00025370340306410486,25.0,30.0
64.510742,0.0006285600984251968,202.95434120734907,0.00025370340306410486,25.0,30.0
66.112305,0.0006557674212598426,215.60640157480313,0.00025370340306410486,25.0,30.0
67.713867,0.0007053455905511811,226.8767585301837,0.00025370340306410486,25.0,30.0
69.31543,0.0007473954330708662,238.25355118110235,0.00025370340306410486,25.0,30.0
70.916992,0.0007841664566929134,249.75717322834646,0.00025370340306410486,25.0,30.0
72.518555,0.0008230274409448818,260.89450393700787,0.00025370340306410486,25.0,30.0
74.120117,0.0008394493503937008,270.5796850393701,0.00025370340306410486,25.0,30.0
75.72168,0.0008797976968503937,282.1266666666666,0.00025370340306410486,25.0,30.0
77.323242,0.0009441643700787403,295.60900262467186,0.00025370340306410486,25.0,30.0
78.924805,0.0009964674015748032,308.3887926509186,0.00025370340306410486,25.0,30.0
80.526367,0.0010219904921259842,318.12299212598424,0.00025370340306410486,25.0,30.0
82.12793,0.0010733295669291339,331.27976377952757,0.00025370340306410486,25.0,30.0
83.729492,0.0011215992913385826,344.3328346456693,0.00025370340306410486,25.0,30.0
85.331055,0.0011386994291338582,355.217375328084,0.00025370340306410486,25.0,30.0
86.932617,0.001202718405511811,367.3954330708661,0.00025370340306410486,25.0,30.0
88.53418,0.0012457860236220473,378.8491338582677,0.00025370340306410486,25.0,30.0
90.135742,0.0012831903543307087,390.57496062992124,0.00025370340306410486,25.0,30.0
91.737305,0.0013018061811023622,400.52598425196845,0.00025370340306410486,25.0,30.0
93.338867,0.0013548328149606298,414.11837270341204,0.00025370340306410486,25.0,30.0
94.94043,0.0014173231692913386,425.7755118110236,0.00025370340306410486,25.0,30.0
96.541992,0.0014332883070866142,435.1634908136483,0.00025370340306410486,25.0,30.0
98.143555,0.0014680644881889763,446.08028871391076,0.00025370340306410486,25.0,30.0
99.745117,0.0015193527755905513,456.2590026246719,0.00025370340306410486,25.0,30.0
101.34668,0.0015437239960629922,467.7177952755905,0.00025370340306410486,25.0,30.0
102.94824,0.0015871999015748032,479.7717585301837,0.00025370340306410486,25.0,30.0
104.5498,0.0016215937598425196,490.2324146981627,0.00025370340306410486,25.0,30.0
106.15137,0.0016684293700787401,501.2441994750656,0.00025370340306410486,25.0,30.0
107.75293,0.0017124362007874016,509.9429921259843,0.00025370340306410486,25.0,30.0
109.35449,0.001733933248031496,518.4435958005249,0.00025370340306410486,25.0,30.0
110.95605,0.0017767816141732284,528.224750656168,0.00025370340306410486,25.0,30.0
112.55762,0.0018127548622047245,533.6512860892389,0.00025370340306410486,25.0,30.0
114.15918,0.0018407675,543.6977165354331,0.00025370340306410486,25.0,30.0
115.76074,0.0018790950984251967,552.6513910761155,0.00025370340306410486,25.0,30.0
117.3623,0.0019081426377952756,558.5862467191602,0.00025370340306410486,25.0,30.0
118.96387,0.0019252072834645669,567.2645144356954,0.00025370340306410486,25.0,30.0
120.56543,0.0019733503937007873,575.6200787401575,0.00025370340306410486,25.0,30.0
122.16699,0.002001866338582677,580.9523622047244,0.00025370340306410486,25.0,30.0
123.76855,0.0020283187007874015,586.9106036745407,0.00025370340306410486,25.0,30.0
125.37012,0.002064542125984252,595.105721784777,0.00025370340306410486,25.0,30.0
126.97168,0.0020932901574803146,599.8167979002625,0.00025370340306410486,25.0,30.0
128.57324,0.002120863779527559,607.8447244094488,0.00025370340306410486,25.0,30.0
130.1748,0.0021372169291338583,610.0382152230972,0.00025370340306410486,25.0,30.0
131.77637,0.0021572541338582677,615.065905511811,0.00025370340306410486,25.0,30.0
133.37793,0.0021800557086614175,618.7942257217849,0.00025370340306410486,25.0,30.0
134.97949,0.0022267251968503938,626.8001049868767,0.00025370340306410486,25.0,30.0
136.58105,0.0022538470472440943,630.6153018372703,0.00025370340306410486,25.0,30.0
138.18262,0.0022756484251968503,636.6050131233595,0.00025370340306410486,25.0,30.0
139.78418,0.00230760531496063,641.7761679790026,0.00025370340306410486,25.0,30.0
141.38574,0.002333116338582677,644.6005249343832,0.00025370340306410486,25.0,30.0
142.9873,0.0023697293307086615,651.3425196850393,0.00025370340306410486,25.0,30.0
144.58887,0.002393462401574803,654.1283464566928,0.00025370340306410486,25.0,30.0
146.19043,0.002419276181102362,659.484435695538,0.00025370340306410486,25.0,30.0
147.79199,0.0024730246062992125,664.0262204724409,0.00025370340306410486,25.0,30.0
149.39355,0.0025011194881889762,667.0977952755906,0.00025370340306410486,25.0,30.0
150.99512,0.0025383809055118107,670.3431233595801,0.00025370340306410486,25.0,30.0
152.59668,0.0025715470472440945,676.1179265091864,0.00025370340306410486,25.0,30.0
154.19824,0.0026047413385826773,676.8382939632546,0.00025370340306410486,25.0,30.0
155.7998,0.0026461110236220475,680.5188713910761,0.00025370340306410486,25.0,30.0
157.40137,0.0026926531496062993,686.6877427821522,0.00025370340306410486,25.0,30.0
159.00293,0.0027455106299212597,690.1250656167979,0.00025370340306410486,25.0,30.0
160.60449,0.002771980708661417,692.576719160105,0.00025370340306410486,25.0,30.0
162.20605,0.0028247659448818897,696.3604461942257,0.00025370340306410486,25.0,30.0
163.80762,0.0028924793307086617,700.4421522309711,0.00025370340306410486,25.0,30.0
165.40918,0.002939422834645669,702.7398950131233,0.00025370340306410486,25.0,30.0
167.01074,0.0029719807086614172,706.0197112860893,0.00025370340306410486,25.0,30.0
168.6123,0.0030393875984251967,709.8314960629922,0.00025370340306410486,25.0,30.0
170.21387,0.0031202232283464564,712.2222834645669,0.00025370340306410486,25.0,30.0
171.81543,0.0032085206692913384,718.8521522309711,0.00025370340306410486,25.0,30.0
173.41699,0.003276422834645669,720.0244094488189,0.00025370340306410486,25.0,30.0
175.01855,0.0033544842519685034,722.579160104987,0.00025370340306410486,25.0,30.0
176.62012,0.003454385433070866,724.4479527559055,0.00025370340306410486,25.0,30.0
178.22168,0.0035293547244094484,727.0430971128609,0.00025370340306410486,25.0,30.0
179.82324,0.0036512303149606297,731.7908923884515,0.00025370340306410486,25.0,30.0
181.4248,0.0037768236220472443,734.086719160105,0.00025370340306410486,25.0,30.0
183.02637,0.0038790751968503932,735.9215485564305,0.00025370340306410486,25.0,30.0
184.62793,0.003994299212598425,739.1109973753281,0.00025370340306410486,25.0,30.0
186.22949,0.004145301377952756,742.5143044619422,0.00025370340306410486,25.0,30.0
187.83105,0.004323649606299213,746.1184251968505,0.00025370340306410486,25.0,30.0
189.43262,0.004422097047244095,746.5979790026247,0.00025370340306410486,25.0,30.0
191.03418,0.004591277755905512,747.9876115485564,0.00025370340306410486,25.0,30.0
192.63574,0.004753251181102362,752.6317847769028,0.00025370340306410486,25.0,30.0
194.2373,0.004953936220472441,751.8220734908136,0.00025370340306410486,25.0,30.0
195.83887,0.005126482283464567,755.5081627296588,0.00025370340306410486,25.0,30.0
197.44043,0.005353213188976378,758.455091863517,0.00025370340306410486,25.0,30.0
199.04199,0.005543327755905512,758.9244094488189,0.00025370340306410486,25.0,30.0
200.64355,0.005778768503937008,761.6325721784776,0.00025370340306410486,25.0,30.0
202.24512,0.0060287748031496065,762.8656430446193,0.00025370340306410486,25.0,30.0
203.84668,0.006284049212598426,762.8876115485564,0.00025370340306410486,25.0,30.0
205.44824,0.0065075131889763774,763.6759842519685,0.00025370340306410486,25.0,30.0
207.0498,0.006766504330708661,765.7867979002624,0.00025370340306410486,25.0,30.0
208.65137,0.007061315551181103,769.5065879265092,0.00025370340306410486,25.0,30.0
210.25293,0.007365153346456693,769.8584251968505,0.00025370340306410486,25.0,30.0
211.85449,0.0076547177165354335,769.9924146981627,0.00025370340306410486,25.0,30.0
213.45605,0.007949343503937008,771.8534120734909,0.00025370340306410486,25.0,30.0
215.05762,0.008240216732283465,774.8225721784777,0.00025370340306410486,25.0,30.0
216.65918,0.008570495275590551,776.5853018372703,0.00025370340306410486,25.0,30.0
218.26074,0.008933560039370078,774.4020734908137,0.00025370340306410486,25.0,30.0
219.8623,0.00924874153543307,775.6557742782153,0.00025370340306410486,25.0,30.0
221.46387,0.009519783464566929,778.2102887139108,0.00025370340306410486,25.0,30.0
223.06543,0.009815892125984252,780.7025721784777,0.00025370340306410486,25.0,30.0
224.66699,0.010185165157480315,781.2917060367454,0.00025370340306410486,25.0,30.0
226.26855,0.010479369291338582,779.1786614173228,0.00025370340306410486,25.0,30.0
227.87012,0.010791681299212598,784.3598687664041,0.00025370340306410486,25.0,30.0
229.47168,0.011111787007874015,784.8509186351706,0.00025370340306410486,25.0,30.0
231.07324,0.011432834448818898,785.2595538057743,0.00025370340306410486,25.0,30.0
232.6748,0.011785475,785.7218635170603,0.00025370340306410486,25.0,30.0
234.27637,0.012114271456692914,787.1724934383202,0.00025370340306410486,25.0,30.0
235.87793,0.012468028937007873,788.1550131233596,0.00025370340306410486,25.0,30.0
237.47949,0.012860290157480313,788.3286614173229,0.00025370340306410486,25.0,30.0
239.08105,0.01315297342519685,789.14375328084,0.00025370340306410486,25.0,30.0
240.68262,0.013469763779527558,791.262965879265,0.00025370340306410486,25.0,30.0
242.28418,0.013855013188976379,791.6788976377953,0.00025370340306410486,25.0,30.0
243.88574,0.014194635039370079,791.0866929133858,0.00025370340306410486,25.0,30.0
245.4873,0.014559667913385825,793.4466404199475,0.00025370340306410486,25.0,30.0
247.08887,0.014995727755905512,795.2536745406824,0.00025370340306410486,25.0,30.0
248.69043,0.015393301377952757,795.9755118110237,0.00025370340306410486,25.0,30.0
250.29199,0.015767949803149606,797.4057742782152,0.00025370340306410486,25.0,30.0
251.89355,0.016153298818897637,796.6458530183727,0.00025370340306410486,25.0,30.0
253.49512,0.0165382531496063,799.2163254593175,0.00025370340306410486,25.0,30.0
255.09668,0.01688809311023622,799.2094488188976,0.00025370340306410486,25.0,30.0
256.69824,0.017227063779527558,800.224908136483,0.00025370340306410486,25.0,30.0
258.2998,0.01757873405511811,800.8148818897637,0.00025370340306410486,25.0,30.0
259.90137,0.01797400354330709,801.3512335958005,0.00025370340306410486,25.0,30.0
261.50293,0.018304260826771654,799.8692913385827,0.00025370340306410486,25.0,30.0
263.10449,0.018654473228346454,802.2503149606299,0.00025370340306410486,25.0,30.0
264.70605,0.01900347874015748,804.1745406824148,0.00025370340306410486,25.0,30.0
266.30762,0.019398076377952756,804.1976902887138,0.00025370340306410486,25.0,30.0
267.90918,0.019759555118110235,805.370656167979,0.00025370340306410486,25.0,30.0
269.51074,0.020143549212598425,805.8861679790026,0.00025370340306410486,25.0,30.0
271.1123,0.02055220275590551,807.2878215223096,0.00025370340306410486,25.0,30.0
272.71387,0.02093059251968504,807.5979527559055,0.00025370340306410486,25.0,30.0
274.31543,0.021296228346456694,807.9783989501312,0.00025370340306410486,25.0,30.0
275.91699,0.021716596456692914,809.6208661417322,0.00025370340306410486,25.0,30.0
277.51855,0.022077547244094487,808.1897375328084,0.00025370340306410486,25.0,30.0
279.12012,0.022420047244094486,809.3544881889765,0.00025370340306410486,25.0,30.0
280.72168,0.02286455905511811,813.8066929133859,0.00025370340306410486,25.0,30.0
282.32324,0.023295566929133857,811.8752230971129,0.00025370340306410486,25.0,30.0
283.9248,0.023626685039370078,811.2006036745407,0.00025370340306410486,25.0,30.0
285.52637,0.02402787598425197,811.0426509186352,0.00025370340306410486,25.0,30.0
287.12793,0.0243780531496063,812.6818635170604,0.00025370340306410486,25.0,30.0
288.72949,0.024752409448818898,814.117532808399,0.00025370340306410486,25.0,30.0
290.33105,0.025075503937007877,814.5748818897638,0.00025370340306410486,25.0,30.0
291.93262,0.025452872047244092,814.703622047244,0.00025370340306410486,25.0,30.0
293.53418,0.025862027559055117,816.7408661417323,0.00025370340306410486,25.0,30.0
295.13574,0.02625933661417323,816.8102624671915,0.00025370340306410486,25.0,30.0
296.7373,0.0265958031496063,817.0542257217847,0.00025370340306410486,25.0,30.0
298.33887,0.02699645669291338,818.5441207349081,0.00025370340306410486,25.0,30.0
299.94043,0.027353765748031496,816.8348818897638,0.00025370340306410486,25.0,30.0
301.54199,0.027695458661417323,817.1564829396325,0.00025370340306410486,25.0,30.0
303.14355,0.028027433070866144,820.1694750656168,0.00025370340306410486,25.0,30.0
304.74512,0.028446181102362206,820.1569291338583,0.00025370340306410486,25.0,30.0
306.34668,0.028811505905511813,821.3568503937008,0.00025370340306410486,25.0,30.0
307.94824,0.029164141732283468,822.9280839895014,0.00025370340306410486,25.0,30.0
309.5498,0.029550785433070867,822.1499737532808,0.00025370340306410486,25.0,30.0
311.15137,0.02995648818897638,824.1464041994751,0.00025370340306410486,25.0,30.0
312.75293,0.03036721062992126,823.1781627296588,0.00025370340306410486,25.0,30.0
314.35449,0.03073182086614173,825.3153280839895,0.00025370340306410486,25.0,30.0
315.95605,0.031165990157480318,824.5594488188976,0.00025370340306410486,25.0,30.0
317.55762,0.0315231751968504,825.7219160104987,0.00025370340306410486,25.0,30.0
319.15918,0.03195463385826772,826.7320472440945,0.00025370340306410486,25.0,30.0
320.76074,0.03233111614173228,826.6236220472441,0.00025370340306410486,25.0,30.0
322.3623,0.032711163385826775,828.2762992125985,0.00025370340306410486,25.0,30.0
323.96387,0.03305797047244094,827.1533070866142,0.00025370340306410486,25.0,30.0
325.56543,0.033396643700787404,829.4376640419947,0.00025370340306410486,25.0,30.0
327.16699,0.03379025196850394,829.1723622047243,0.00025370340306410486,25.0,30.0
328.76855,0.03417510236220472,830.5926771653544,0.00025370340306410486,25.0,30.0
330.37012,0.03455925984251969,831.1140157480315,0.00025370340306410486,25.0,30.0
331.97168,0.03495786220472441,831.4669028871391,0.00025370340306410486,25.0,30.0
333.57324,0.035337874015748026,830.2644094488189,0.00025370340306410486,25.0,30.0
335.1748,0.03568178346456693,830.7325721784777,0.00025370340306410486,25.0,30.0
336.77637,0.03602042519685039,830.7192913385827,0.00025370340306410486,25.0,30.0
338.37793,0.03636120078740157,831.7266141732283,0.00025370340306410486,25.0,30.0
339.97949,0.036757905511811025,833.428031496063,0.00025370340306410486,25.0,30.0
341.58105,0.03714097637795276,835.0832020997375,0.00025370340306410486,25.0,30.0
343.18262,0.03751765157480315,834.2139107611548,0.00025370340306410486,25.0,30.0
344.78418,0.037887285433070864,835.4367979002625,0.00025370340306410486,25.0,30.0
346.38574,0.03827323031496063,835.9012860892389,0.00025370340306410486,25.0,30.0
347.9873,0.03866186023622047,837.4989763779527,0.00025370340306410486,25.0,30.0
349.58887,0.039039775590551176,838.0071916010498,0.00025370340306410486,25.0,30.0
351.19043,0.03938587007874016,839.0260367454067,0.00025370340306410486,25.0,30.0
352.79199,0.03976580511811024,839.5712860892388,0.00025370340306410486,25.0,30.0
354.39355,0.04017116929133858,838.1820472440944,0.00025370340306410486,25.0,30.0
355.99512,0.040498901574803146,837.9745669291339,0.00025370340306410486,25.0,30.0
357.59668,0.04089091338582677,840.4995275590551,0.00025370340306410486,25.0,30.0
359.19824,0.04126835433070866,840.4780577427821,0.00025370340306410486,25.0,30.0
360.7998,0.04164409645669292,841.163779527559,0.00025370340306410486,25.0,30.0
362.40137,0.0419965374015748,841.7177952755906,0.00025370340306410486,25.0,30.0
364.00293,0.04241419291338582,843.1140157480315,0.00025370340306410486,25.0,30.0
365.60449,0.04281013188976378,843.1805249343832,0.00025370340306410486,25.0,30.0
367.20605,0.04317228149606299,843.0271916010498,0.00025370340306410486,25.0,30.0
368.80762,0.04361011417322835,842.1782152230971,0.00025370340306410486,25.0,30.0
370.40918,0.04395310433070866,844.3990551181103,0.00025370340306410486,25.0,30.0
372.01074,0.044348545275590553,844.4201312335957,0.00025370340306410486,25.0,30.0
373.6123,0.04471405511811023,847.0509711286089,0.00025370340306410486,25.0,30.0
375.21387,0.045046240157480315,845.6433333333333,0.00025370340306410486,25.0,30.0
376.81543,0.04538353937007874,846.1286089238845,0.00025370340306410486,25.0,30.0
378.41699,0.045716905511811026,845.3272965879265,0.00025370340306410486,25.0,30.0
380.01855,0.04612187204724409,847.5160367454067,0.00025370340306410486,25.0,30.0
381.62012,0.04651950393700787,850.4302887139107,0.00025370340306410486,25.0,30.0
383.22168,0.04694046456692914,848.4733070866142,0.00025370340306410486,25.0,30.0
384.82324,0.047302759842519686,849.250341207349,0.00025370340306410486,25.0,30.0
386.4248,0.04769584251968504,850.6271391076116,0.00025370340306410486,25.0,30.0
388.02637,0.04804000984251968,850.2924671916011,0.00025370340306410486,25.0,30.0
389.62793,0.04843688188976378,851.2789501312336,0.00025370340306410486,25.0,30.0
391.22949,0.04884096653543307,850.0727296587926,0.00025370340306410486,25.0,30.0
392.83105,0.0492550374015748,850.6781364829396,0.00025370340306410486,25.0,30.0
394.43262,0.04962913779527559,851.1796325459318,0.00025370340306410486,25.0,30.0
396.03418,0.04997436417322834,850.8587926509186,0.00025370340306410486,25.0,30.0
397.63574,0.05029260433070866,852.2533858267716,0.00025370340306410486,25.0,30.0
399.2373,0.05067193897637795,853.4148818897637,0.00025370340306410486,25.0,30.0
400.83887,0.05105401181102362,854.9462467191602,0.00025370340306410486,25.0,30.0
402.44043,0.05147376181102362,854.8628871391076,0.00025370340306410486,25.0,30.0
404.04199,0.05189832086614173,854.3832545931759,0.00025370340306410486,25.0,30.0
405.64355,0.05223646062992126,854.0622309711287,0.00025370340306410486,25.0,30.0
407.24512,0.05260844488188977,856.4105774278215,0.00025370340306410486,25.0,30.0
408.84668,0.05297077755905512,857.3422834645669,0.00025370340306410486,25.0,30.0
410.44824,0.05331447244094488,855.7773490813648,0.00025370340306410486,25.0,30.0
412.0498,0.05360880511811024,854.9108661417323,0.00025370340306410486,25.0,30.0
413.65137,0.05395820078740157,856.6745931758529,0.00025370340306410486,25.0,30.0
415.25293,0.054331035433070864,859.9210236220473,0.00025370340306410486,25.0,30.0
416.85449,0.05471204133858268,858.8704461942258,0.00025370340306410486,25.0,30.0
418.45605,0.055079679133858264,859.2989501312336,0.00025370340306410486,25.0,30.0
420.05762,0.05547330905511811,860.1572703412073,0.00025370340306410486,25.0,30.0
421.65918,0.055802366141732285,859.8223884514435,0.00025370340306410486,25.0,30.0
423.26074,0.05626269488188976,862.8102624671916,0.00025370340306410486,25.0,30.0
424.8623,0.05666698622047245,861.5160104986877,0.00025370340306410486,25.0,30.0
426.46387,0.05709517125984252,862.8051968503937,0.00025370340306410486,25.0,30.0
428.06543,0.05744093700787402,861.9854593175853,0.00025370340306410486,25.0,30.0
429.66699,0.05776924409448819,861.995249343832,0.00025370340306410486,25.0,30.0
431.26855,0.058116600393700785,862.6048293963254,0.00025370340306410486,25.0,30.0
432.87012,0.058500616141732284,865.5532283464566,0.00025370340306410486,25.0,30.0
434.47168,0.058880307086614174,863.1638582677166,0.00025370340306410486,25.0,30.0
436.07324,0.059222259842519685,863.6620734908136,0.00025370340306410486,25.0,30.0
437.6748,0.0595997874015748,864.1829133858267,0.00025370340306410486,25.0,30.0
439.27637,0.05995723818897638,866.6408398950132,0.00025370340306410486,25.0,30.0
440.87793,0.06035537007874015,865.7082414698162,0.00025370340306410486,25.0,30.0
442.47949,0.060677681102362206,866.0080577427821,0.00025370340306410486,25.0,30.0
444.08105,0.06100518897637795,866.4184776902887,0.00025370340306410486,25.0,30.0
445.68262,0.061370690944881894,868.4396587926509,0.00025370340306410486,25.0,30.0
447.28418,0.06172836614173228,867.5197375328083,0.00025370340306410486,25.0,30.0
448.88574,0.0620443405511811,867.3314173228347,0.00025370340306410486,25.0,30.0
450.4873,0.06243118897637795,869.1934383202099,0.00025370340306410486,25.0,30.0
452.08887,0.06279308267716535,868.3555905511811,0.00025370340306410486,25.0,30.0
453.69043,0.06312703346456693,868.8243307086614,0.00025370340306410486,25.0,30.0
455.29199,0.06352121456692914,869.6363517060367,0.00025370340306410486,25.0,30.0
456.89355,0.0639465374015748,870.4851181102362,0.00025370340306410486,25.0,30.0
458.49512,0.06434601181102363,871.9802099737533,0.00025370340306410486,25.0,30.0
460.09668,0.06473407677165355,871.4702887139108,0.00025370340306410486,25.0,30.0
461.69824,0.06514571850393701,873.0131758530183,0.00025370340306410486,25.0,30.0
463.2998,0.06552196653543306,870.2691076115485,0.00025370340306410486,25.0,30.0
464.90137,0.06584983858267716,871.9376640419947,0.00025370340306410486,25.0,30.0
466.50293,0.06618950984251969,872.9292388451444,0.00025370340306410486,25.0,30.0
468.10449,0.06656400984251969,873.0191338582678,0.00025370340306410486,25.0,30.0
469.70605,0.06691679724409448,874.1929921259842,0.00025370340306410486,25.0,30.0
471.30762,0.06730456692913386,875.2742519685039,0.00025370340306410486,25.0,30.0
472.90918,0.06769529527559054,876.6143307086614,0.00025370340306410486,25.0,30.0
474.51074,0.06807759251968504,874.425905511811,0.00025370340306410486,25.0,30.0
476.1123,0.068455031496063,875.0480052493438,0.00025370340306410486,25.0,30.0
477.71387,0.06883063385826772,877.1764304461942,0.00025370340306410486,25.0,30.0
479.31543,0.0691423622047244,876.3528871391077,0.00025370340306410486,25.0,30.0
480.91699,0.06949523818897638,875.8980052493439,0.00025370340306410486,25.0,30.0
482.51855,0.0698506062992126,878.0258005249343,0.00025370340306410486,25.0,30.0
484.12012,0.07026009645669291,879.4521259842519,0.00025370340306410486,25.0,30.0
485.72168,0.07061628543307086,877.2228871391076,0.00025370340306410486,25.0,30.0
487.32324,0.07099206496062992,879.310656167979,0.00025370340306410486,25.0,30.0
488.9248,0.07137534251968504,878.4611023622047,0.00025370340306410486,25.0,30.0
490.52637,0.07177207677165355,879.1775590551181,0.00025370340306410486,25.0,30.0
492.12793,0.07213202165354331,879.2702099737533,0.00025370340306410486,25.0,30.0
493.72949,0.0725221968503937,880.9763779527559,0.00025370340306410486,25.0,30.0
495.33105,0.07291936023622048,880.9316535433071,0.00025370340306410486,25.0,30.0
496.93262,0.07331942716535432,881.4018635170603,0.00025370340306410486,25.0,30.0
498.53418,0.07370052165354331,881.7757742782153,0.00025370340306410486,25.0,30.0
500.13574,0.07409096062992127,883.176220472441,0.00025370340306410486,25.0,30.0
501.7373,0.07444511614173228,881.491653543307,0.00025370340306410486,25.0,30.0
503.33887,0.07480577755905513,882.3614435695538,0.00025370340306410486,25.0,30.0
504.94043,0.07511847244094488,882.5818897637796,0.00025370340306410486,25.0,30.0
506.54199,0.07551413976377952,884.1031758530185,0.00025370340306410486,25.0,30.0
508.14355,0.07589037598425197,884.8907611548556,0.00025370340306410486,25.0,30.0
509.74512,0.0762493937007874,883.654750656168,0.00025370340306410486,25.0,30.0
511.34668,0.07663412598425197,885.3597637795275,0.00025370340306410486,25.0,30.0
512.94824,0.07697397834645668,884.4859317585301,0.00025370340306410486,25.0,30.0
514.5498,0.07735467322834645,887.4951181102363,0.00025370340306410486,25.0,30.0
516.15137,0.07771739960629921,886.7219422572178,0.00025370340306410486,25.0,30.0
517.75293,0.07806768897637795,885.3105511811023,0.00025370340306410486,25.0,30.0
519.35449,0.07842381496062992,887.3107086614173,0.00025370340306410486,25.0,30.0
520.95605,0.07879115157480315,887.4664304461942,0.00025370340306410486,25.0,30.0
522.55762,0.07916456692913386,889.0631496062991,0.00025370340306410486,25.0,30.0
524.15918,0.07957800787401575,889.4633070866141,0.00025370340306410486,25.0,30.0
525.76074,0.07993099015748031,889.0965879265092,0.00025370340306410486,25.0,30.0
527.3623,0.0803329409448819,890.0754593175853,0.00025370340306410486,25.0,30.0
528.96387,0.08070687795275591,891.6036745406825,0.00025370340306410486,25.0,30.0
530.56543,0.08109082874015748,890.2028608923885,0.00025370340306410486,25.0,30.0
532.16699,0.08150461811023621,890.7061942257218,0.00025370340306410486,25.0,30.0
533.76855,0.08182943307086614,890.7022834645669,0.00025370340306410486,25.0,30.0
535.37012,0.08220758858267715,890.1126771653543,0.00025370340306410486,25.0,30.0
536.97168,0.0825846122047244,891.1196325459318,0.00025370340306410486,25.0,30.0
538.57324,0.08296487795275591,891.6473228346457,0.00025370340306410486,25.0,30.0
540.1748,0.08334350196850394,893.1888713910761,0.00025370340306410486,25.0,30.0
541.77637,0.08371834842519685,890.8329921259842,0.00025370340306410486,25.0,30.0
543.37793,0.08408412007874015,892.4641994750656,0.00025370340306410486,25.0,30.0
544.97949,0.08445204921259843,893.6965616797901,0.00025370340306410486,25.0,30.0
546.58105,0.08485382283464567,895.9514960629922,0.00025370340306410486,25.0,30.0
548.18262,0.08519645669291338,893.0649868766404,0.00025370340306410486,25.0,30.0
549.78418,0.0855328937007874,893.6297112860893,0.00025370340306410486,25.0,30.0
551.38574,0.08584787204724409,895.9691863517061,0.00025370340306410486,25.0,30.0
552.9873,0.08619882874015747,896.1013648293964,0.00025370340306410486,25.0,30.0
554.58887,0.0865696220472441,895.6153280839895,0.00025370340306410486,25.0,30.0
556.19043,0.08696184448818897,895.3829921259843,0.00025370340306410486,25.0,30.0
557.79199,0.08732388976377953,895.6228346456693,0.00025370340306410486,25.0,30.0
559.39355,0.08771537401574803,897.048845144357,0.00025370340306410486,25.0,30.0
560.99512,0.08803973818897637,894.1225459317586,0.00025370340306410486,25.0,30.0
562.59668,0.08840407874015747,897.4146719160104,0.00025370340306410486,25.0,30.0
564.19824,0.08877324015748031,898.4942782152231,0.00025370340306410486,25.0,30.0
565.7998,0.08918691141732284,898.3645669291338,0.00025370340306410486,25.0,30.0
567.40137,0.0896688996062992,901.2312860892389,0.00025370340306410486,25.0,30.0
569.00293,0.09005448622047245,899.2539370078739,0.00025370340306410486,25.0,30.0
570.60449,0.09040160826771654,896.7120997375329,0.00025370340306410486,25.0,30.0
572.20605,0.09075806299212598,898.3016535433071,0.00025370340306410486,25.0,30.0
573.80762,0.09118075,900.7310236220471,0.00025370340306410486,25.0,30.0
575.40918,0.09153223031496062,900.527060367454,0.00025370340306410486,25.0,30.0
577.01074,0.09196839370078741,899.2607874015747,0.00025370340306410486,25.0,30.0
578.6123,0.09234571653543307,901.3329658792651,0.00025370340306410486,25.0,30.0
580.21387,0.09273831496062993,901.4348031496063,0.00025370340306410486,25.0,30.0
581.81543,0.09311544291338582,899.583622047244,0.00025370340306410486,25.0,30.0
583.41699,0.09347306496062992,901.072624671916,0.00025370340306410486,25.0,30.0
585.01855,0.09376454133858267,900.7116010498688,0.00025370340306410486,25.0,30.0
586.62012,0.09406736417322835,903.4551968503937,0.00025370340306410486,25.0,30.0
588.22168,0.09446286614173229,904.2447769028871,0.00025370340306410486,25.0,30.0
589.82324,0.09485196850393701,902.6529396325459,0.00025370340306410486,25.0,30.0
591.4248,0.09527831299212598,903.5559842519684,0.00025370340306410486,25.0,30.0
593.02637,0.09563786417322834,902.4283464566929,0.00025370340306410486,25.0,30.0
594.62793,0.09598967322834646,902.8347244094488,0.00025370340306410486,25.0,30.0
596.22949,0.09636783267716535,904.8109711286089,0.00025370340306410486,25.0,30.0
597.83105,0.09677169685039369,906.1090813648294,0.00025370340306410486,25.0,30.0
599.43262,0.0971163877952756,902.8553018372704,0.00025370340306410486,25.0,30.0
601.03418,0.09749548818897637,907.1812598425197,0.00025370340306410486,25.0,30.0
602.63574,0.09791250393700787,906.4249868766404,0.00025370340306410486,25.0,30.0
604.2373,0.09830865157480315,906.4427559055117,0.00025370340306410486,25.0,30.0
605.83887,0.0987622440944882,906.8591338582677,0.00025370340306410486,25.0,30.0
607.44043,0.0991621594488189,906.7974803149606,0.00025370340306410486,25.0,30.0
609.04199,0.09950195275590551,906.9227559055118,0.00025370340306410486,25.0,30.0
610.64355,0.09987479921259844,907.1153280839894,0.00025370340306410486,25.0,30.0
612.24512,0.10031437007874015,908.958031496063,0.00025370340306410486,25.0,30.0
613.84668,0.10074217519685039,908.0485564304462,0.00025370340306410486,25.0,30.0
615.44824,0.10108246062992125,909.0746719160105,0.00025370340306410486,25.0,30.0
617.0498,0.10145536614173227,907.4498162729659,0.00025370340306410486,25.0,30.0
618.65137,0.10185377755905511,911.1637532808398,0.00025370340306410486,25.0,30.0
620.25293,0.1022778031496063,910.7582152230971,0.00025370340306410486,25.0,30.0
621.85449,0.1026453464566929,910.8212073490813,0.00025370340306410486,25.0,30.0
623.45605,0.10294944685039371,909.3548818897638,0.00025370340306410486,25.0,30.0
625.05762,0.10328525196850394,910.2969553805774,0.00025370340306410486,25.0,30.0
626.65918,0.10364664566929134,910.2702362204725,0.00025370340306410486,25.0,30.0
628.26074,0.1039863346456693,910.545590551181,0.00025370340306410486,25.0,30.0
629.8623,0.10439849803149606,911.9917847769029,0.00025370340306410486,25.0,30.0
631.46387,0.10486778937007873,912.7465879265092,0.00025370340306410486,25.0,30.0
633.06543,0.10526477165354331,911.8310761154855,0.00025370340306410486,25.0,30.0
634.66699,0.10563802755905513,914.1812335958004,0.00025370340306410486,25.0,30.0
636.26855,0.1060032125984252,913.414908136483,0.00025370340306410486,25.0,30.0
637.87012,0.1064248562992126,913.8147769028872,0.00025370340306410486,25.0,30.0
639.47168,0.10680142125984252,913.5930708661417,0.00025370340306410486,25.0,30.0
641.07324,0.10720273228346457,912.5589501312336,0.00025370340306410486,25.0,30.0
642.6748,0.10760742125984252,915.0556692913385,0.00025370340306410486,25.0,30.0
644.27637,0.10799841929133858,913.919343832021,0.00025370340306410486,25.0,30.0
645.87793,0.10836527952755905,913.0436482939633,0.00025370340306410486,25.0,30.0
647.47949,0.10870016929133858,914.5756430446194,0.00025370340306410486,25.0,30.0
649.08105,0.10908815157480316,913.7471128608923,0.00025370340306410486,25.0,30.0
650.68262,0.10945244291338582,916.1471128608924,0.00025370340306410486,25.0,30.0
652.28418,0.10986464173228346,916.6607611548557,0.00025370340306410486,25.0,30.0
653.88574,0.1102034035433071,913.8434908136483,0.00025370340306410486,25.0,30.0
655.4873,0.11057803149606299,916.3953543307086,0.00025370340306410486,25.0,30.0
657.08887,0.11095659251968505,918.0096325459317,0.00025370340306410486,25.0,30.0
658.69043,0.11133826181102362,917.9051181102362,0.00025370340306410486,25.0,30.0
660.29199,0.111724718503937,917.7525459317585,0.00025370340306410486,25.0,30.0
661.89355,0.1121376437007874,918.1227296587927,0.00025370340306410486,25.0,30.0
663.49512,0.11256206889763778,919.0290026246719,0.00025370340306410486,25.0,30.0
665.09668,0.11294532283464566,917.0840157480314,0.00025370340306410486,25.0,30.0
666.69824,0.1133502125984252,918.4655643044619,0.00025370340306410486,25.0,30.0
668.2998,0.11365537992125985,918.3717322834646,0.00025370340306410486,25.0,30.0
669.90137,0.11404109842519684,920.6475065616797,0.00025370340306410486,25.0,30.0
671.50293,0.11443642322834646,919.4792125984252,0.00025370340306410486,25.0,30.0
673.10449,0.11483023622047245,920.228372703412,0.00025370340306410486,25.0,30.0
674.70605,0.11527132283464567,920.7036482939633,0.00025370340306410486,25.0,30.0
676.30762,0.11569324999999998,920.5303674540681,0.00025370340306410486,25.0,30.0
677.90918,0.11608334251968504,921.6938582677166,0.00025370340306410486,25.0,30.0
679.51074,0.1164773090551181,921.7444619422572,0.00025370340306410486,25.0,30.0
681.1123,0.11687827952755904,921.0729921259843,0.00025370340306410486,25.0,30.0
682.71387,0.11727679724409448,921.4772703412073,0.00025370340306410486,25.0,30.0
684.31543,0.11764846850393701,922.1343832020997,0.00025370340306410486,25.0,30.0
685.91699,0.11803255511811023,921.9822572178477,0.00025370340306410486,25.0,30.0
687.51855,0.11853683661417322,921.7817060367454,0.00025370340306410486,25.0,30.0
689.12012,0.11888727165354332,922.4617060367453,0.00025370340306410486,25.0,30.0
690.72168,0.1192734468503937,922.0389763779527,0.00025370340306410486,25.0,30.0
692.32324,0.11965495078740157,924.9913385826771,0.00025370340306410486,25.0,30.0
693.9248,0.12004585433070866,923.2271916010499,0.00025370340306410486,25.0,30.0
695.52637,0.12040075984251969,922.705406824147,0.00025370340306410486,25.0,30.0
697.12793,0.12080676377952755,924.2580839895013,0.00025370340306410486,25.0,30.0
698.72949,0.12119324409448819,923.9484776902887,0.00025370340306410486,25.0,30.0
700.33105,0.12157075984251968,923.5502099737532,0.00025370340306410486,25.0,30.0
701.93262,0.12201576574803148,925.404094488189,0.00025370340306410486,25.0,30.0
703.53418,0.1224681496062992,925.662440944882,0.00025370340306410486,25.0,30.0
705.13574,0.1228744468503937,925.422467191601,0.00025370340306410486,25.0,30.0
706.7373,0.12327819881889764,925.0056430446193,0.00025370340306410486,25.0,30.0
708.33887,0.12362581692913385,925.0765091863517,0.00025370340306410486,25.0,30.0
709.94043,0.12403187992125984,925.9134383202099,0.00025370340306410486,25.0,30.0
711.54199,0.12441241141732284,925.1020209973753,0.00025370340306410486,25.0,30.0
713.14355,0.12477468503937007,927.8198687664042,0.00025370340306410486,25.0,30.0
714.74512,0.1252014094488189,926.9159580052493,0.00025370340306410486,25.0,30.0
716.34668,0.12562837007874017,927.9548818897638,0.00025370340306410486,25.0,30.0
717.94824,0.12607182480314963,927.6285039370078,0.00025370340306410486,25.0,30.0
719.5498,0.12647889763779527,926.4461417322834,0.00025370340306410486,25.0,30.0
721.15137,0.12686209251968505,925.6081627296588,0.00025370340306410486,25.0,30.0
722.75293,0.12721735039370077,928.0245144356956,0.00025370340306410486,25.0,30.0
724.35449,0.12759336417322836,927.9347506561679,0.00025370340306410486,25.0,30.0
725.95605,0.12799994291338582,928.1899737532808,0.00025370340306410486,25.0,30.0
727.55762,0.12837330511811024,927.9786351706036,0.00025370340306410486,25.0,30.0
729.15918,0.12873939173228346,927.5636745406824,0.00025370340306410486,25.0,30.0
730.76074,0.12913212598425197,928.3863779527559,0.00025370340306410486,25.0,30.0
732.3623,0.1295771181102362,931.2066929133858,0.00025370340306410486,25.0,30.0
733.96387,0.12994649212598425,928.7991076115485,0.00025370340306410486,25.0,30.0
735.56543,0.13034349606299211,930.0349343832021,0.00025370340306410486,25.0,30.0
737.16699,0.13079822834645669,930.5164304461942,0.00025370340306410486,25.0,30.0
738.76855,0.1311900216535433,929.4813648293963,0.00025370340306410486,25.0,30.0
740.37012,0.13156471062992126,930.4649606299213,0.00025370340306410486,25.0,30.0
741.97168,0.1319805472440945,931.6872703412074,0.00025370340306410486,25.0,30.0
743.57324,0.13245579921259842,930.8715485564305,0.00025370340306410486,25.0,30.0
745.1748,0.13282992519685038,930.1846194225722,0.00025370340306410486,25.0,30.0
746.77637,0.13325524212598425,930.094409448819,0.00025370340306410486,25.0,30.0
748.37793,0.13366213779527558,930.328031496063,0.00025370340306410486,25.0,30.0
749.97949,0.13411365354330707,932.0428608923884,0.00025370340306410486,25.0,30.0
751.58105,0.13448812992125983,930.8028608923885,0.00025370340306410486,25.0,30.0
753.18262,0.13491255511811023,932.5661154855643,0.00025370340306410486,25.0,30.0
754.78418,0.13536909448818898,932.7211286089239,0.00025370340306410486,25.0,30.0
756.38574,0.13578738188976378,932.4157217847769,0.00025370340306410486,25.0,30.0
757.9873,0.13617891929133857,931.7034908136483,0.00025370340306410486,25.0,30.0
759.58887,0.1365990964566929,933.3986351706036,0.00025370340306410486,25.0,30.0
761.19043,0.13700382283464568,931.9823622047244,0.00025370340306410486,25.0,30.0
762.79199,0.13737271456692912,932.8718897637796,0.00025370340306410486,25.0,30.0
764.39355,0.13785905511811022,933.7056430446195,0.00025370340306410486,25.0,30.0
765.99512,0.13830664173228346,932.4652493438319,0.00025370340306410486,25.0,30.0
767.59668,0.13869611220472441,933.8882677165354,0.00025370340306410486,25.0,30.0
769.19824,0.13908051574803149,933.1627559055119,0.00025370340306410486,25.0,30.0
770.7998,0.1394974429133858,934.0619160104987,0.00025370340306410486,25.0,30.0
772.40137,0.1399423307086614,934.8727034120734,0.00025370340306410486,25.0,30.0
774.00293,0.14038977755905513,933.9141469816273,0.00025370340306410486,25.0,30.0
775.60449,0.14085761417322834,936.2261154855643,0.00025370340306410486,25.0,30.0
777.20605,0.14131123228346457,936.5139632545931,0.00025370340306410486,25.0,30.0
778.80762,0.14173171456692912,933.9604724409448,0.00025370340306410486,25.0,30.0
780.40918,0.14211573031496064,935.4686351706036,0.00025370340306410486,25.0,30.0
782.01074,0.14254623228346458,935.8690026246719,0.00025370340306410486,25.0,30.0
783.6123,0.14299919291338584,936.3593438320211,0.00025370340306410486,25.0,30.0
785.21387,0.143496562992126,937.6425721784777,0.00025370340306410486,25.0,30.0
786.81543,0.14393631102362206,936.2924934383201,0.00025370340306410486,25.0,30.0
788.41699,0.14434364173228348,936.3336482939633,0.00025370340306410486,25.0,30.0
790.01855,0.14475463188976379,936.7923097112861,0.00025370340306410486,25.0,30.0
791.62012,0.1451595216535433,936.3647244094487,0.00025370340306410486,25.0,30.0
793.22168,0.1456222086614173,937.9592650918635,0.00025370340306410486,25.0,30.0
794.82324,0.14603112204724408,937.0770078740156,0.00025370340306410486,25.0,30.0
796.4248,0.1464381811023622,936.9544881889764,0.00025370340306410486,25.0,30.0
798.02637,0.14683953937007874,937.9579002624672,0.00025370340306410486,25.0,30.0
799.62793,0.14727281102362205,936.4397375328084,0.00025370340306410486,25.0,30.0
801.22949,0.14767813385826772,937.7000524934383,0.00025370340306410486,25.0,30.0
802.83105,0.1481147972440945,937.5797112860893,0.00025370340306410486,25.0,30.0
804.43262,0.14851926377952754,938.3409186351706,0.00025370340306410486,25.0,30.0
806.03418,0.14895963385826771,938.0085826771654,0.00025370340306410486,25.0,30.0
807.63574,0.14939392716535435,938.4358005249344,0.00025370340306410486,25.0,30.0
809.2373,0.14980862401574802,937.9440682414697,0.00025370340306410486,25.0,30.0
810.83887,0.15024450196850395,938.6156167979003,0.00025370340306410486,25.0,30.0
812.44043,0.15069181692913386,937.5849081364829,0.00025370340306410486,25.0,30.0
814.04199,0.15111763976377954,940.4256430446194,0.00025370340306410486,25.0,30.0
815.64355,0.1515776161417323,940.5158005249344,0.00025370340306410486,25.0,30.0
817.24512,0.1520427657480315,938.5401312335957,0.00025370340306410486,25.0,30.0
818.84668,0.15247444291338583,940.6549868766405,0.00025370340306410486,25.0,30.0
820.44824,0.15292208661417322,940.4865879265092,0.00025370340306410486,25.0,30.0
822.0498,0.15335074803149606,939.7723622047245,0.00025370340306410486,25.0,30.0
823.65137,0.153820968503937,940.3128608923885,0.00025370340306410486,25.0,30.0
825.25293,0.1542918090551181,939.7976902887139,0.00025370340306410486,25.0,30.0
826.85449,0.1547216909448819,940.2147769028871,0.00025370340306410486,25.0,30.0
828.45605,0.15520685826771652,941.103937007874,0.00025370340306410486,25.0,30.0
830.05762,0.15563849803149604,940.0966141732283,0.00025370340306410486,25.0,30.0
831.65918,0.1560510374015748,941.7113910761154,0.00025370340306410486,25.0,30.0
833.26074,0.1564479842519685,940.5504724409449,0.00025370340306410486,25.0,30.0
834.8623,0.15684821456692913,939.7057217847769,0.00025370340306410486,25.0,30.0
836.46387,0.1573407618110236,942.1660367454068,0.00025370340306410486,25.0,30.0
838.06543,0.15777374015748033,941.2875853018372,0.00025370340306410486,25.0,30.0
839.66699,0.15821792519685038,942.5052755905512,0.00025370340306410486,25.0,30.0
841.26855,0.15864768897637796,940.5375853018372,0.00025370340306410486,25.0,30.0
842.87012,0.15909297440944883,941.0499737532808,0.00025370340306410486,25.0,30.0
844.47168,0.1595139153543307,941.7402362204724,0.00025370340306410486,25.0,30.0
846.07324,0.15996971456692913,943.3600787401575,0.00025370340306410486,25.0,30.0
847.6748,0.16038897637795274,942.7973490813648,0.00025370340306410486,25.0,30.0
849.27637,0.16087366338582676,943.1107611548556,0.00025370340306410486,25.0,30.0
850.87793,0.16131973622047244,941.4787139107611,0.00025370340306410486,25.0,30.0
852.47949,0.16176051771653543,943.9077690288714,0.00025370340306410486,25.0,30.0
854.08105,0.16217407677165355,941.9463779527559,0.00025370340306410486,25.0,30.0
855.68262,0.16260529527559056,943.9648556430446,0.00025370340306410486,25.0,30.0
857.28418,0.16305436023622047,942.5059055118111,0.00025370340306410486,25.0,30.0
858.88574,0.16354090157480314,943.2866404199474,0.00025370340306410486,25.0,30.0
860.4873,0.1640874094488189,942.7537532808399,0.00025370340306410486,25.0,30.0
862.08887,0.1645952342519685,944.2316272965879,0.00025370340306410486,25.0,30.0
863.69043,0.16504945078740157,943.0701312335958,0.00025370340306410486,25.0,30.0
865.29199,0.16555186614173228,942.7963779527558,0.00025370340306410486,25.0,30.0
866.89355,0.16600159842519685,943.1692650918635,0.00025370340306410486,25.0,30.0
868.49512,0.16646365157480314,944.1717060367454,0.00025370340306410486,25.0,30.0
870.09668,0.16689688976377953,943.8188188976378,0.00025370340306410486,25.0,30.0
871.69824,0.16740226181102363,944.7386614173228,0.00025370340306410486,25.0,30.0
873.2998,0.16777619881889763,941.5062729658792,0.00025370340306410486,25.0,30.0
874.90137,0.16812791338582678,943.5211023622047,0.00025370340306410486,25.0,30.0
876.50293,0.16860180511811024,945.8328871391077,0.00025370340306410486,25.0,30.0
878.10449,0.1691031653543307,943.5159842519685,0.00025370340306410486,25.0,30.0
879.70605,0.16957972047244096,945.4835170603674,0.00025370340306410486,25.0,30.0
881.30762,0.17004319291338582,944.7667979002624,0.00025370340306410486,25.0,30.0
882.90918,0.17045657677165352,943.120813648294,0.00025370340306410486,25.0,30.0
884.51074,0.1709416968503937,944.3124146981627,0.00025370340306410486,25.0,30.0
886.1123,0.17147064173228346,945.7887401574803,0.00025370340306410486,25.0,30.0
887.71387,0.1720145688976378,946.3209711286089,0.00025370340306410486,25.0,30.0
889.31543,0.17254194094488187,945.3564566929134,0.00025370340306410486,25.0,30.0
890.91699,0.17311853543307085,945.8671653543307,0.00025370340306410486,25.0,30.0
892.51855,0.17364325393700786,944.8550393700788,0.00025370340306410486,25.0,30.0
894.12012,0.17408202952755905,944.4883727034121,0.00025370340306410486,25.0,30.0
895.72168,0.1745230688976378,944.3996325459318,0.00025370340306410486,25.0,30.0
897.32324,0.17498594291338582,946.0863779527559,0.00025370340306410486,25.0,30.0
898.9248,0.17555392322834645,947.2251968503937,0.00025370340306410486,25.0,30.0
900.52637,0.1760065905511811,945.859343832021,0.00025370340306410486,25.0,30.0
902.12793,0.17646986417322835,945.8130183727034,0.00025370340306410486,25.0,30.0
903.72949,0.17694262992125984,945.5680577427822,0.00025370340306410486,25.0,30.0
905.33105,0.17745637992125984,947.1980839895014,0.00025370340306410486,25.0,30.0
906.93262,0.17795133267716534,946.2190288713911,0.00025370340306410486,25.0,30.0
908.53418,0.17840227559055116,946.6356692913386,0.00025370340306410486,25.0,30.0
910.13574,0.17888797047244093,945.8900524934384,0.00025370340306410486,25.0,30.0
911.7373,0.17939024606299211,946.4366404199475,0.00025370340306410486,25.0,30.0
913.33887,0.17988714566929134,945.5000524934383,0.00025370340306410486,25.0,30.0
914.94043,0.1803421594488189,947.2648031496062,0.00025370340306410486,25.0,30.0
916.54199,0.1808293464566929,946.2527296587926,0.00025370340306410486,25.0,30.0
918.14355,0.18134426968503936,946.512125984252,0.00025370340306410486,25.0,30.0
919.74512,0.18185575393700787,947.8079265091864,0.00025370340306410486,25.0,30.0
921.34668,0.18237657874015747,945.8650393700788,0.00025370340306410486,25.0,30.0
922.94824,0.18292417913385825,947.1434908136483,0.00025370340306410486,25.0,30.0
924.5498,0.18339146456692915,946.4730971128608,0.00025370340306410486,25.0,30.0
926.15137,0.18392676968503938,946.6354068241469,0.00025370340306410486,25.0,30.0
927.75293,0.1844600787401575,947.4920209973752,0.00025370340306410486,25.0,30.0
929.35449,0.1849073937007874,945.7517585301837,0.00025370340306410486,25.0,30.0
930.95605,0.18544556102362206,947.8885301837271,0.00025370340306410486,25.0,30.0
932.55762,0.18594205118110235,946.6711023622047,0.00025370340306410486,25.0,30.0
934.15918,0.18646623228346457,947.4882939632546,0.00025370340306410486,25.0,30.0
935.76074,0.1870004803149606,948.120813648294,0.00025370340306410486,25.0,30.0
937.3623,0.18751908661417324,947.2322309711286,0.00025370340306410486,25.0,30.0
938.96387,0.18802402559055117,947.8912860892389,0.00025370340306410486,25.0,30.0
940.56543,0.18849058464566928,946.7737532808399,0.00025370340306410486,25.0,30.0
942.16699,0.18900474409448817,947.7187926509185,0.00025370340306410486,25.0,30.0
943.76855,0.18956338582677165,948.7409186351706,0.00025370340306410486,25.0,30.0
945.37012,0.1900416653543307,946.1345144356956,0.00025370340306410486,25.0,30.0
946.97168,0.19048975590551182,945.9693700787402,0.00025370340306410486,25.0,30.0
948.57324,0.19092377952755904,948.2195800524935,0.00025370340306410486,25.0,30.0
950.1748,0.19142509251968504,949.047217847769,0.00025370340306410486,25.0,30.0
951.77637,0.1919811751968504,948.6107086614173,0.00025370340306410486,25.0,30.0
953.37793,0.19249291929133858,949.8941469816273,0.00025370340306410486,25.0,30.0
954.97949,0.19300695078740157,947.543280839895,0.00025370340306410486,25.0,30.0
956.58105,0.19350924803149605,945.7420209973752,0.00025370340306410486,25.0,30.0
958.18262,0.19408520669291338,947.6219160104987,0.00025370340306410486,25.0,30.0
959.78418,0.19461105511811022,948.9016272965879,0.00025370340306410486,25.0,30.0
961.38574,0.19514947834645668,948.8684251968505,0.00025370340306410486,25.0,30.0
962.9873,0.19568515748031495,946.5478215223097,0.00025370340306410486,25.0,30.0
964.58887,0.19619329921259843,947.2021784776903,0.00025370340306410486,25.0,30.0
964.78906,0.19626365157480313,950.5520997375328,0.00025370340306410486,25.0,30.0