File: datasets/am_bench_2022/csv/30-XY.01-2.csv
Time(s),Strain(%),Stress(MPa),SR(s-1),Temp(C),Angle(deg)
39.759033,5.088833464566929e-05,15.946988648090816,0.00025370340306410486,25.0,30.0
41.260498,6.185887401574803e-05,20.439738390092877,0.00025370340306410486,25.0,30.0
42.761963,8.296627755905512e-05,26.379102167182666,0.00025370340306410486,25.0,30.0
44.263428,0.00011074009842519685,32.363501031991746,0.00025370340306410486,25.0,30.0
45.764893,0.000136463187007874,37.80015479876161,0.00025370340306410486,25.0,30.0
47.266357,0.00014157981102362203,43.023691950464396,0.00025370340306410486,25.0,30.0
48.767822,0.00017854528543307088,49.87876160990712,0.00025370340306410486,25.0,30.0
50.269287,0.00021373935039370077,58.1834907120743,0.00025370340306410486,25.0,30.0
51.770752,0.00022362007874015746,64.3458359133127,0.00025370340306410486,25.0,30.0
53.272217,0.0002747172047244094,74.55168730650155,0.00025370340306410486,25.0,30.0
54.773682,0.00029650864173228343,80.8655185758514,0.00025370340306410486,25.0,30.0
56.275146,0.0003261684251968504,86.9261403508772,0.00025370340306410486,25.0,30.0
57.776611,0.00036175915354330705,95.82791279669763,0.00025370340306410486,25.0,30.0
59.278076,0.00039807769685039373,104.79407120743035,0.00025370340306410486,25.0,30.0
60.779541,0.00042012342519685033,113.15845459236327,0.00025370340306410486,25.0,30.0
62.281006,0.00045745753937007875,119.40789731682148,0.00025370340306410486,25.0,30.0
63.782471,0.0004966018307086614,131.45723168214656,0.00025370340306410486,25.0,30.0
65.283936,0.0005442343503937007,140.59767801857586,0.00025370340306410486,25.0,30.0
66.7854,0.0005799817322834646,149.89215428276574,0.00025370340306410486,25.0,30.0
68.286865,0.0006217337204724409,158.78722652218784,0.00025370340306410486,25.0,30.0
69.78833,0.0006621307086614173,169.0924664602683,0.00025370340306410486,25.0,30.0
71.289795,0.0006919244094488188,179.1167827657379,0.00025370340306410486,25.0,30.0
72.79126,0.0007379218503937008,190.46740196078434,0.00025370340306410486,25.0,30.0
74.292725,0.0007872660433070865,200.98514705882351,0.00025370340306410486,25.0,30.0
75.794189,0.0008307678740157481,210.4653740970072,0.00025370340306410486,25.0,30.0
77.295654,0.0008645430708661418,222.7551418988648,0.00025370340306410486,25.0,30.0
78.797119,0.0009166864173228346,233.66232456140352,0.00025370340306410486,25.0,30.0
80.298584,0.0009459264566929133,245.04827915376677,0.00025370340306410486,25.0,30.0
81.800049,0.000989354153543307,255.4046517027864,0.00025370340306410486,25.0,30.0
83.301514,0.0010382458267716534,264.73645510835917,0.00025370340306410486,25.0,30.0
84.802979,0.0010796083858267715,278.6711300309598,0.00025370340306410486,25.0,30.0
86.304443,0.0011339757086614173,287.3839783281734,0.00025370340306410486,25.0,30.0
87.805908,0.0011777177165354332,296.69950980392156,0.00025370340306410486,25.0,30.0
89.307373,0.001217161968503937,308.5124097007224,0.00025370340306410486,25.0,30.0
90.808838,0.0012446347047244094,320.10807533539736,0.00025370340306410486,25.0,30.0
92.310303,0.0012957399409448819,330.3487874097007,0.00025370340306410486,25.0,30.0
93.811768,0.0013326628346456693,341.3127450980392,0.00025370340306410486,25.0,30.0
95.313232,0.0013685084842519687,352.13795149638804,0.00025370340306410486,25.0,30.0
96.814697,0.0014200839566929134,361.45358617131063,0.00025370340306410486,25.0,30.0
98.316162,0.0014817554921259842,373.90905572755423,0.00025370340306410486,25.0,30.0
99.817627,0.0015133631496062991,385.40337977296184,0.00025370340306410486,25.0,30.0
101.31909,0.0015675788779527559,396.6127192982456,0.00025370340306410486,25.0,30.0
102.82056,0.0015990018503937006,405.5958204334366,0.00025370340306410486,25.0,30.0
104.32202,0.0016456270078740159,416.2916666666667,0.00025370340306410486,25.0,30.0
105.82349,0.0016883928543307085,425.78387512899894,0.00025370340306410486,25.0,30.0
107.32495,0.0017363642322834644,436.7128740970073,0.00025370340306410486,25.0,30.0
108.82642,0.0017728352165354332,445.45789473684215,0.00025370340306410486,25.0,30.0
110.32788,0.0018006163188976378,454.63307533539734,0.00025370340306410486,25.0,30.0
111.82935,0.0018360280314960629,467.54566563467495,0.00025370340306410486,25.0,30.0
113.33081,0.0018986070275590552,477.540092879257,0.00025370340306410486,25.0,30.0
114.83228,0.0019254733070866142,484.71648606811146,0.00025370340306410486,25.0,30.0
116.33374,0.0019649958464566927,494.68622291021677,0.00025370340306410486,25.0,30.0
117.83521,0.0019939175196850394,500.56589267285864,0.00025370340306410486,25.0,30.0
119.33667,0.002021520078740158,508.5103715170279,0.00025370340306410486,25.0,30.0
120.83813,0.00208624625984252,519.1191176470588,0.00025370340306410486,25.0,30.0
122.3396,0.00211756437007874,525.7220588235294,0.00025370340306410486,25.0,30.0
123.84106,0.0021447377952755905,533.2904282765738,0.00025370340306410486,25.0,30.0
125.34253,0.002193353937007874,540.9838235294118,0.00025370340306410486,25.0,30.0
126.84399,0.002243518503937008,548.7920278637772,0.00025370340306410486,25.0,30.0
128.34546,0.002258719094488189,553.300386996904,0.00025370340306410486,25.0,30.0
129.84692,0.002309467716535433,562.3208720330238,0.00025370340306410486,25.0,30.0
131.34839,0.00232813031496063,568.1517027863778,0.00025370340306410486,25.0,30.0
132.84985,0.002376995275590551,575.7570433436533,0.00025370340306410486,25.0,30.0
134.35132,0.002412641929133858,582.0102683178535,0.00025370340306410486,25.0,30.0
135.85278,0.002446220275590551,588.5324819401444,0.00025370340306410486,25.0,30.0
137.35425,0.002492392913385827,592.0368679050567,0.00025370340306410486,25.0,30.0
138.85571,0.0025412094488188974,598.6699174406605,0.00025370340306410486,25.0,30.0
140.35718,0.0025930261811023623,603.6504901960784,0.00025370340306410486,25.0,30.0
141.85864,0.002625341338582677,609.5210010319918,0.00025370340306410486,25.0,30.0
143.36011,0.002660144094488189,613.6355521155831,0.00025370340306410486,25.0,30.0
144.86157,0.0026979462598425196,617.0091847265222,0.00025370340306410486,25.0,30.0
146.36304,0.0027573501968503936,622.4105779153767,0.00025370340306410486,25.0,30.0
147.8645,0.002798380118110236,626.864370485036,0.00025370340306410486,25.0,30.0
149.36597,0.0028399824803149606,633.5766769865841,0.00025370340306410486,25.0,30.0
150.86743,0.002903992322834646,637.8101393188854,0.00025370340306410486,25.0,30.0
152.3689,0.002957873818897638,640.730830753354,0.00025370340306410486,25.0,30.0
153.87036,0.003003582677165354,646.1212590299277,0.00025370340306410486,25.0,30.0
155.37183,0.003050682874015748,648.3818111455108,0.00025370340306410486,25.0,30.0
156.87329,0.0031140852362204724,652.3930598555211,0.00025370340306410486,25.0,30.0
158.37476,0.0031688679133858267,657.8196594427244,0.00025370340306410486,25.0,30.0
159.87622,0.0032308228346456694,660.459907120743,0.00025370340306410486,25.0,30.0
161.37769,0.0033134692913385825,665.8033539731682,0.00025370340306410486,25.0,30.0
162.87915,0.0033774391732283465,668.4570949432405,0.00025370340306410486,25.0,30.0
164.38062,0.0034498791338582677,669.6918988648091,0.00025370340306410486,25.0,30.0
165.88208,0.0035155938976377953,672.9350877192983,0.00025370340306410486,25.0,30.0
167.38354,0.0035878578740157476,676.843653250774,0.00025370340306410486,25.0,30.0
168.88501,0.00368945374015748,680.1481424148607,0.00025370340306410486,25.0,30.0
170.38647,0.0037680358267716536,685.474742002064,0.00025370340306410486,25.0,30.0
171.88794,0.0038504387795275587,686.7278895768835,0.00025370340306410486,25.0,30.0
173.3894,0.003932992913385827,690.5554695562436,0.00025370340306410486,25.0,30.0
174.89087,0.004034658070866141,692.7977038183694,0.00025370340306410486,25.0,30.0
176.39233,0.004146533661417323,695.9719814241486,0.00025370340306410486,25.0,30.0
177.8938,0.0042771484251968505,697.4096233230134,0.00025370340306410486,25.0,30.0
179.39526,0.004397886023622047,700.503818369453,0.00025370340306410486,25.0,30.0
180.89673,0.004499028346456693,705.1044633642931,0.00025370340306410486,25.0,30.0
182.39819,0.004644027165354331,707.8958720330238,0.00025370340306410486,25.0,30.0
183.89966,0.0047974141732283464,710.5095717234262,0.00025370340306410486,25.0,30.0
185.40112,0.004962998622047243,711.6109133126935,0.00025370340306410486,25.0,30.0
186.90259,0.005142337598425197,715.260294117647,0.00025370340306410486,25.0,30.0
188.40405,0.005292147440944882,719.2402992776058,0.00025370340306410486,25.0,30.0
189.90552,0.005478449409448818,719.4315789473684,0.00025370340306410486,25.0,30.0
191.40698,0.005660286417322835,721.2355005159959,0.00025370340306410486,25.0,30.0
192.90845,0.005858977362204724,722.1431630546955,0.00025370340306410486,25.0,30.0
194.40991,0.006044667716535433,725.1671310629515,0.00025370340306410486,25.0,30.0
195.91138,0.0062472574803149605,728.06217750258,0.00025370340306410486,25.0,30.0
197.41284,0.006467274015748032,730.7300309597523,0.00025370340306410486,25.0,30.0
198.91431,0.0067004706692913385,731.4658410732715,0.00025370340306410486,25.0,30.0
200.41577,0.006908966732283464,731.6649380804954,0.00025370340306410486,25.0,30.0
201.91724,0.007100621062992126,733.4320691434469,0.00025370340306410486,25.0,30.0
203.4187,0.007325605118110236,732.35,0.00025370340306410486,25.0,30.0
204.92017,0.007610915551181103,737.7192724458205,0.00025370340306410486,25.0,30.0
206.42163,0.007906394094488189,739.7797213622291,0.00025370340306410486,25.0,30.0
207.9231,0.008137576181102361,739.0085655314757,0.00025370340306410486,25.0,30.0
209.42456,0.00840296062992126,739.5675180598556,0.00025370340306410486,25.0,30.0
210.92603,0.008668806299212599,742.5365067079464,0.00025370340306410486,25.0,30.0
212.42749,0.00895979901574803,744.2418988648091,0.00025370340306410486,25.0,30.0
213.92896,0.009293332874015748,745.6837719298246,0.00025370340306410486,25.0,30.0
215.43042,0.00964493562992126,746.5506707946337,0.00025370340306410486,25.0,30.0
216.93188,0.009872132283464567,747.2197110423116,0.00025370340306410486,25.0,30.0
218.43335,0.010186460236220472,750.1703818369454,0.00025370340306410486,25.0,30.0
219.93481,0.01047715157480315,749.293395252838,0.00025370340306410486,25.0,30.0
221.43628,0.010814214173228346,750.9553405572756,0.00025370340306410486,25.0,30.0
222.93774,0.011125324212598426,751.7249226006193,0.00025370340306410486,25.0,30.0
224.43921,0.011478072637795276,752.4687306501548,0.00025370340306410486,25.0,30.0
225.94067,0.011784197637795275,755.6427502579979,0.00025370340306410486,25.0,30.0
227.44214,0.012127018110236221,755.718524251806,0.00025370340306410486,25.0,30.0
228.9436,0.01246156535433071,758.5201754385964,0.00025370340306410486,25.0,30.0
230.44507,0.01281910374015748,758.0360423116615,0.00025370340306410486,25.0,30.0
231.94653,0.013165285826771653,759.8386222910217,0.00025370340306410486,25.0,30.0
233.448,0.013483136811023623,759.3885190918473,0.00025370340306410486,25.0,30.0
234.94946,0.013821950393700787,760.2692208462332,0.00025370340306410486,25.0,30.0
236.45093,0.014144913976377953,759.7482972136223,0.00025370340306410486,25.0,30.0
237.95239,0.014454532677165352,760.4605779153767,0.00025370340306410486,25.0,30.0
239.45386,0.014764022047244094,761.7497936016512,0.00025370340306410486,25.0,30.0
240.95532,0.015107306102362205,763.0355779153767,0.00025370340306410486,25.0,30.0
242.45679,0.015443466732283464,764.6267801857585,0.00025370340306410486,25.0,30.0
243.95825,0.015802388188976377,765.5817337461301,0.00025370340306410486,25.0,30.0
245.45972,0.016170533267716534,765.6568627450981,0.00025370340306410486,25.0,30.0
246.96118,0.01653933405511811,766.2806501547988,0.00025370340306410486,25.0,30.0
248.46265,0.016896859251968505,767.0696852425181,0.00025370340306410486,25.0,30.0
249.96411,0.017249805708661418,769.7393704850361,0.00025370340306410486,25.0,30.0
251.46558,0.017608344291338583,769.6228844169248,0.00025370340306410486,25.0,30.0
252.96704,0.018045288582677163,770.7882352941177,0.00025370340306410486,25.0,30.0
254.46851,0.018413282677165355,770.28717750258,0.00025370340306410486,25.0,30.0
255.96997,0.01873026535433071,772.8001805985552,0.00025370340306410486,25.0,30.0
257.47144,0.019113440748031493,771.6492260061921,0.00025370340306410486,25.0,30.0
258.9729,0.019440518307086613,771.8146284829721,0.00025370340306410486,25.0,30.0
260.47437,0.019841035433070867,771.8215428276574,0.00025370340306410486,25.0,30.0
261.97583,0.020195911417322833,775.2468782249742,0.00025370340306410486,25.0,30.0
263.47729,0.020634220472440946,774.5892414860681,0.00025370340306410486,25.0,30.0
264.97876,0.020990096456692912,776.0068369453044,0.00025370340306410486,25.0,30.0
266.48022,0.021316633858267715,776.6050825593395,0.00025370340306410486,25.0,30.0
267.98169,0.02164555118110236,777.3962848297214,0.00025370340306410486,25.0,30.0
269.48315,0.022001285433070866,777.4704850361198,0.00025370340306410486,25.0,30.0
270.98462,0.02237759251968504,779.8313983488132,0.00025370340306410486,25.0,30.0
272.48608,0.02278741338582677,779.3683694530444,0.00025370340306410486,25.0,30.0
273.98755,0.02313003149606299,779.2026573787409,0.00025370340306410486,25.0,30.0
275.48901,0.023420633858267717,780.0868679050568,0.00025370340306410486,25.0,30.0
276.99048,0.023766529527559054,781.068782249742,0.00025370340306410486,25.0,30.0
278.49194,0.024121614173228348,781.713080495356,0.00025370340306410486,25.0,30.0
279.99341,0.02451713188976378,782.4259287925696,0.00025370340306410486,25.0,30.0
281.49487,0.024875732283464565,781.9494840041281,0.00025370340306410486,25.0,30.0
282.99634,0.025280653543307084,782.869427244582,0.00025370340306410486,25.0,30.0
284.4978,0.025613342519685035,782.7587977296182,0.00025370340306410486,25.0,30.0
285.99927,0.025983427165354327,784.4522445820434,0.00025370340306410486,25.0,30.0
287.50073,0.02634888976377953,786.5507481940145,0.00025370340306410486,25.0,30.0
289.0022,0.026757633858267717,789.0954334365325,0.00025370340306410486,25.0,30.0
290.50366,0.02715204527559055,786.298839009288,0.00025370340306410486,25.0,30.0
292.00513,0.02756701968503937,789.4665118679051,0.00025370340306410486,25.0,30.0
293.50659,0.027939364173228343,788.1430598555212,0.00025370340306410486,25.0,30.0
295.00806,0.02830482874015748,788.940608875129,0.00025370340306410486,25.0,30.0
296.50952,0.028664555118110235,789.6482198142415,0.00025370340306410486,25.0,30.0
298.01099,0.029000212598425196,789.8758513931888,0.00025370340306410486,25.0,30.0
299.51245,0.029378598425196852,791.4181888544892,0.00025370340306410486,25.0,30.0
301.01392,0.02972050590551181,791.1736584107327,0.00025370340306410486,25.0,30.0
302.51538,0.030092147637795275,791.0357843137256,0.00025370340306410486,25.0,30.0
304.01685,0.03051995472440945,793.0734262125903,0.00025370340306410486,25.0,30.0
305.51831,0.030867679133858267,792.90802373581,0.00025370340306410486,25.0,30.0
307.01978,0.03127109645669291,793.1413312693498,0.00025370340306410486,25.0,30.0
308.52124,0.031591503937007874,793.3823271413829,0.00025370340306410486,25.0,30.0
310.02271,0.031927919291338584,794.3006191950464,0.00025370340306410486,25.0,30.0
311.52417,0.03225306692913386,794.9260835913312,0.00025370340306410486,25.0,30.0
313.02563,0.03262621062992126,795.8547987616099,0.00025370340306410486,25.0,30.0
314.5271,0.03309693307086614,796.6944788441692,0.00025370340306410486,25.0,30.0
316.02856,0.03349187598425197,796.8197626418988,0.00025370340306410486,25.0,30.0
317.53003,0.033842009842519685,795.9929308565531,0.00025370340306410486,25.0,30.0
319.03149,0.034197102362204725,795.4417182662538,0.00025370340306410486,25.0,30.0
320.53296,0.034540594488188976,797.6970588235293,0.00025370340306410486,25.0,30.0
322.03442,0.034888297244094486,798.0775541795665,0.00025370340306410486,25.0,30.0
323.53589,0.03529711023622047,797.400257997936,0.00025370340306410486,25.0,30.0
325.03735,0.035641838582677166,800.1281991744066,0.00025370340306410486,25.0,30.0
326.53882,0.03603699803149606,799.9142930856553,0.00025370340306410486,25.0,30.0
328.04028,0.03641128346456693,802.5207946336429,0.00025370340306410486,25.0,30.0
329.54175,0.03681090157480315,801.7021929824562,0.00025370340306410486,25.0,30.0
331.04321,0.037216137795275585,801.8581527347782,0.00025370340306410486,25.0,30.0
332.54468,0.03758150787401575,805.0482972136224,0.00025370340306410486,25.0,30.0
334.04614,0.03799611220472441,804.276625386997,0.00025370340306410486,25.0,30.0
335.54761,0.03833780511811024,804.9513673890609,0.00025370340306410486,25.0,30.0
337.04907,0.03869575196850394,804.9615067079463,0.00025370340306410486,25.0,30.0
338.55054,0.03903650196850394,804.8670278637771,0.00025370340306410486,25.0,30.0
340.052,0.03935636614173228,806.927915376677,0.00025370340306410486,25.0,30.0
341.55347,0.039757608267716536,805.1430856553147,0.00025370340306410486,25.0,30.0
343.05493,0.04008860039370079,805.1383126934985,0.00025370340306410486,25.0,30.0
344.5564,0.04038545866141732,807.8504385964914,0.00025370340306410486,25.0,30.0
346.05786,0.04069317913385827,807.5877192982457,0.00025370340306410486,25.0,30.0
347.55933,0.041102,808.9756965944273,0.00025370340306410486,25.0,30.0
349.06079,0.04150881889763779,807.71891124871,0.00025370340306410486,25.0,30.0
350.56226,0.041877688976377954,808.7160216718266,0.00025370340306410486,25.0,30.0
352.06372,0.04215529133858268,809.3427502579979,0.00025370340306410486,25.0,30.0
353.56519,0.042508293307086616,808.1996904024768,0.00025370340306410486,25.0,30.0
355.06665,0.042912742125984255,810.9922600619195,0.00025370340306410486,25.0,30.0
356.56812,0.04326008267716536,808.7973168214654,0.00025370340306410486,25.0,30.0
358.06958,0.04363698031496063,811.7083075335397,0.00025370340306410486,25.0,30.0
359.57104,0.04398993503937008,811.0862487100104,0.00025370340306410486,25.0,30.0
361.07251,0.04437042716535433,812.7253611971105,0.00025370340306410486,25.0,30.0
362.57397,0.044807155511811025,814.8127966976264,0.00025370340306410486,25.0,30.0
364.07544,0.04521847440944882,813.2083075335397,0.00025370340306410486,25.0,30.0
365.5769,0.04554565157480315,813.1439886480908,0.00025370340306410486,25.0,30.0
367.07837,0.045924411417322834,814.3910216718267,0.00025370340306410486,25.0,30.0
368.57983,0.04629612992125984,815.8175696594428,0.00025370340306410486,25.0,30.0
370.0813,0.04665256102362205,815.5373839009288,0.00025370340306410486,25.0,30.0
371.58276,0.04696142519685039,814.3107843137254,0.00025370340306410486,25.0,30.0
373.08423,0.04739493307086614,817.1850361197111,0.00025370340306410486,25.0,30.0
374.58569,0.04770662401574803,816.668782249742,0.00025370340306410486,25.0,30.0
376.08716,0.048091297244094486,819.1554695562436,0.00025370340306410486,25.0,30.0
377.58862,0.04842456102362205,816.2171052631579,0.00025370340306410486,25.0,30.0
379.09009,0.048766501968503934,818.4368421052632,0.00025370340306410486,25.0,30.0
380.59155,0.04912051968503937,817.6569401444789,0.00025370340306410486,25.0,30.0
382.09302,0.04941171653543307,817.9609649122808,0.00025370340306410486,25.0,30.0
383.59448,0.04985224015748032,820.4073529411766,0.00025370340306410486,25.0,30.0
385.09595,0.05025191338582677,820.1417440660475,0.00025370340306410486,25.0,30.0
386.59741,0.050578535433070865,820.7057275541796,0.00025370340306410486,25.0,30.0
388.09888,0.050924519685039374,819.9323013415893,0.00025370340306410486,25.0,30.0
389.60034,0.051253816929133854,821.8020381836945,0.00025370340306410486,25.0,30.0
391.10181,0.0516179625984252,822.0170794633643,0.00025370340306410486,25.0,30.0
392.60327,0.05201188188976378,823.653302373581,0.00025370340306410486,25.0,30.0
394.10474,0.052340458661417316,822.6034829721362,0.00025370340306410486,25.0,30.0
395.6062,0.05270628149606299,825.0774509803922,0.00025370340306410486,25.0,30.0
397.10767,0.05307302559055118,825.5293343653251,0.00025370340306410486,25.0,30.0
398.60913,0.05345526968503937,824.4164086687307,0.00025370340306410486,25.0,30.0
400.1106,0.053865240157480315,824.2808049535604,0.00025370340306410486,25.0,30.0
401.61206,0.054254452755905506,824.469685242518,0.00025370340306410486,25.0,30.0
403.11353,0.054585897637795276,824.9296181630548,0.00025370340306410486,25.0,30.0
404.61499,0.054957377952755904,827.435165118679,0.00025370340306410486,25.0,30.0
406.11646,0.05529509448818898,824.4478328173375,0.00025370340306410486,25.0,30.0
407.61792,0.05564754133858267,826.1976264189886,0.00025370340306410486,25.0,30.0
409.11938,0.056012068897637796,827.4851651186791,0.00025370340306410486,25.0,30.0
410.62085,0.05637756299212598,828.0910474716202,0.00025370340306410486,25.0,30.0
412.12231,0.056693045275590555,828.2190402476781,0.00025370340306410486,25.0,30.0
413.62378,0.05702335826771653,828.9973168214655,0.00025370340306410486,25.0,30.0
415.12524,0.057381990157480314,828.3835139318885,0.00025370340306410486,25.0,30.0
416.62671,0.0577775688976378,828.858746130031,0.00025370340306410486,25.0,30.0
418.12817,0.05811210039370078,829.6300825593396,0.00025370340306410486,25.0,30.0
419.62964,0.058508505905511814,830.1539731682147,0.00025370340306410486,25.0,30.0
421.1311,0.05886374015748032,832.9829979360165,0.00025370340306410486,25.0,30.0
422.63257,0.059247874015748034,833.1375128998968,0.00025370340306410486,25.0,30.0
424.13403,0.059642907480314956,831.5265995872033,0.00025370340306410486,25.0,30.0
425.6355,0.06001292519685039,833.1645768833849,0.00025370340306410486,25.0,30.0
427.13696,0.060348635826771656,831.6957172342621,0.00025370340306410486,25.0,30.0
428.63843,0.060684187007874014,832.5924148606812,0.00025370340306410486,25.0,30.0
430.13989,0.06103008661417322,835.5174922600619,0.00025370340306410486,25.0,30.0
431.64136,0.06143564566929134,833.8429050567596,0.00025370340306410486,25.0,30.0
433.14282,0.06178397440944882,835.2884674922601,0.00025370340306410486,25.0,30.0
434.64429,0.062135659448818895,833.8897574819401,0.00025370340306410486,25.0,30.0
436.14575,0.06251217716535433,836.9640092879258,0.00025370340306410486,25.0,30.0
437.64722,0.06285370866141733,836.6554953560371,0.00025370340306410486,25.0,30.0
439.14868,0.06325532874015748,836.2227812177504,0.00025370340306410486,25.0,30.0
440.65015,0.06365513188976378,837.3987616099071,0.00025370340306410486,25.0,30.0
442.15161,0.06401161614173229,837.602270381837,0.00025370340306410486,25.0,30.0
443.65308,0.0643709094488189,836.799484004128,0.00025370340306410486,25.0,30.0
445.15454,0.06475712598425197,838.3327915376677,0.00025370340306410486,25.0,30.0
446.65601,0.06516010236220472,838.3644220846234,0.00025370340306410486,25.0,30.0
448.15747,0.06550455511811024,836.3608359133127,0.00025370340306410486,25.0,30.0
449.65894,0.06584225984251968,838.9278379772961,0.00025370340306410486,25.0,30.0
451.1604,0.0661659311023622,837.3504385964912,0.00025370340306410486,25.0,30.0
452.66187,0.06651254724409449,841.8110423116615,0.00025370340306410486,25.0,30.0
454.16333,0.0668467972440945,841.2936016511868,0.00025370340306410486,25.0,30.0
455.66479,0.06718715354330708,841.096439628483,0.00025370340306410486,25.0,30.0
457.16626,0.0675422874015748,841.4913828689371,0.00025370340306410486,25.0,30.0
458.66772,0.06793323818897638,840.9761351909185,0.00025370340306410486,25.0,30.0
460.16919,0.06830761023622048,842.3528121775026,0.00025370340306410486,25.0,30.0
461.67065,0.06862778543307087,843.765995872033,0.00025370340306410486,25.0,30.0
463.17212,0.06900887401574803,844.2451496388029,0.00025370340306410486,25.0,30.0
464.67358,0.06935208070866142,842.8410216718266,0.00025370340306410486,25.0,30.0
466.17505,0.06977848228346456,845.9390866873065,0.00025370340306410486,25.0,30.0
467.67651,0.07012079921259842,842.2837203302373,0.00025370340306410486,25.0,30.0
469.17798,0.0704984153543307,843.7813725490196,0.00025370340306410486,25.0,30.0
470.67944,0.07087762007874016,844.171439628483,0.00025370340306410486,25.0,30.0
472.18091,0.07127446653543307,845.2769607843138,0.00025370340306410486,25.0,30.0
473.68237,0.07157831496062993,847.1309339525284,0.00025370340306410486,25.0,30.0
475.18384,0.07189183070866141,846.4085139318886,0.00025370340306410486,25.0,30.0
476.6853,0.072256218503937,846.9050051599587,0.00025370340306410486,25.0,30.0
478.18677,0.07265105118110236,846.9434210526316,0.00025370340306410486,25.0,30.0
479.68823,0.07301071456692913,846.1255159958721,0.00025370340306410486,25.0,30.0
481.1897,0.07346126968503937,851.0890092879257,0.00025370340306410486,25.0,30.0
482.69116,0.07383801771653543,846.3572497420021,0.00025370340306410486,25.0,30.0
484.19263,0.07412485236220472,849.0933178534572,0.00025370340306410486,25.0,30.0
485.69409,0.07447432086614174,846.8919504643962,0.00025370340306410486,25.0,30.0
487.19556,0.07477124015748031,848.5860681114551,0.00025370340306410486,25.0,30.0
488.69702,0.07508253937007875,848.2279153766771,0.00025370340306410486,25.0,30.0
490.19849,0.07537946653543307,850.686661506708,0.00025370340306410486,25.0,30.0
491.69995,0.0757198937007874,850.952786377709,0.00025370340306410486,25.0,30.0
493.20142,0.07614231692913387,851.160500515996,0.00025370340306410486,25.0,30.0
494.70288,0.07653325,851.8568369453044,0.00025370340306410486,25.0,30.0
496.20435,0.0769068937007874,850.7158926728587,0.00025370340306410486,25.0,30.0
497.70581,0.07721904330708662,850.1704076367389,0.00025370340306410486,25.0,30.0
499.20728,0.07757296456692914,850.0487100103198,0.00025370340306410486,25.0,30.0
500.70874,0.07786104921259843,852.2708720330237,0.00025370340306410486,25.0,30.0
502.21021,0.07826704724409449,853.9107585139319,0.00025370340306410486,25.0,30.0
503.71167,0.07861930708661417,852.4627966976263,0.00025370340306410486,25.0,30.0
505.21313,0.0789578562992126,854.7209494324046,0.00025370340306410486,25.0,30.0
506.7146,0.0793524153543307,855.3408152734778,0.00025370340306410486,25.0,30.0
508.21606,0.07976945866141731,855.4109907120743,0.00025370340306410486,25.0,30.0
509.71753,0.08018001574803149,856.2159184726522,0.00025370340306410486,25.0,30.0
511.21899,0.08053078543307086,855.4916666666667,0.00025370340306410486,25.0,30.0
512.72046,0.08084976968503936,854.4089783281734,0.00025370340306410486,25.0,30.0
514.22192,0.0811970905511811,855.6484004127967,0.00025370340306410486,25.0,30.0
515.72339,0.0816342283464567,856.8838235294118,0.00025370340306410486,25.0,30.0
517.22485,0.08199070669291339,856.7587977296181,0.00025370340306410486,25.0,30.0
518.72632,0.08234260236220473,855.5477296181631,0.00025370340306410486,25.0,30.0
520.22778,0.08271150590551181,857.8615841073272,0.00025370340306410486,25.0,30.0
521.72925,0.08302145078740157,856.8333849329206,0.00025370340306410486,25.0,30.0
523.23071,0.08338033267716535,857.3089267285862,0.00025370340306410486,25.0,30.0
524.73218,0.0837150748031496,856.0076625386997,0.00025370340306410486,25.0,30.0
526.23364,0.08403937007874016,857.643524251806,0.00025370340306410486,25.0,30.0
527.73511,0.08440927559055117,859.3679566563467,0.00025370340306410486,25.0,30.0
529.23657,0.084793468503937,858.3159958720331,0.00025370340306410486,25.0,30.0
530.73804,0.08518753346456692,860.7611197110424,0.00025370340306410486,25.0,30.0
532.2395,0.08553883070866142,859.0597523219815,0.00025370340306410486,25.0,30.0
533.74097,0.08587298622047244,860.9052373581012,0.00025370340306410486,25.0,30.0
535.24243,0.08624931102362204,859.7503353973168,0.00025370340306410486,25.0,30.0
536.7439,0.08657147637795275,861.3991228070175,0.00025370340306410486,25.0,30.0
538.24536,0.08693578543307087,862.1785861713107,0.00025370340306410486,25.0,30.0
539.74683,0.08729317913385827,862.4285861713107,0.00025370340306410486,25.0,30.0
541.24829,0.08768174803149606,861.8043859649123,0.00025370340306410486,25.0,30.0
542.74976,0.08806364566929134,861.3061403508772,0.00025370340306410486,25.0,30.0
544.25122,0.08843379133858267,863.6920020639835,0.00025370340306410486,25.0,30.0
545.75269,0.08877300984251968,864.8082043343653,0.00025370340306410486,25.0,30.0
547.25415,0.08918643503937008,864.2353199174407,0.00025370340306410486,25.0,30.0
548.75562,0.08951130511811023,862.6370227038184,0.00025370340306410486,25.0,30.0
550.25708,0.0899203248031496,864.8503353973168,0.00025370340306410486,25.0,30.0
551.75854,0.09030275,864.752657378741,0.00025370340306410486,25.0,30.0
553.26001,0.09069312598425197,864.2973168214654,0.00025370340306410486,25.0,30.0
554.76147,0.09102955118110236,864.8542311661507,0.00025370340306410486,25.0,30.0
556.26294,0.09138803543307086,865.7614551083592,0.00025370340306410486,25.0,30.0
557.7644,0.0917241968503937,864.8278637770898,0.00025370340306410486,25.0,30.0
559.26587,0.09198182283464566,865.4332301341589,0.00025370340306410486,25.0,30.0
560.76733,0.09231874212598425,867.5546439628483,0.00025370340306410486,25.0,30.0
562.2688,0.09273327559055118,869.1941692466461,0.00025370340306410486,25.0,30.0
563.77026,0.09311259842519684,868.659649122807,0.00025370340306410486,25.0,30.0
565.27173,0.09349437992125983,866.8024509803921,0.00025370340306410486,25.0,30.0
566.77319,0.09382329527559055,866.2555985552116,0.00025370340306410486,25.0,30.0
568.27466,0.09411499409448819,865.6643962848298,0.00025370340306410486,25.0,30.0
569.77612,0.09447838385826772,868.8357585139319,0.00025370340306410486,25.0,30.0
571.27759,0.0948576653543307,867.8476780185758,0.00025370340306410486,25.0,30.0
572.77905,0.09523745078740158,868.7659700722394,0.00025370340306410486,25.0,30.0
574.28052,0.0956011220472441,868.9130546955626,0.00025370340306410486,25.0,30.0
575.78198,0.09600067913385826,871.2118421052633,0.00025370340306410486,25.0,30.0
577.28345,0.09641035433070866,869.8108101135191,0.00025370340306410486,25.0,30.0
578.78491,0.09677302755905512,871.6612745098039,0.00025370340306410486,25.0,30.0
580.28638,0.0971562283464567,870.7047471620227,0.00025370340306410486,25.0,30.0
581.78784,0.09756038976377954,869.2393188854489,0.00025370340306410486,25.0,30.0
583.28931,0.09793200984251968,873.8093395252839,0.00025370340306410486,25.0,30.0
584.79077,0.09826648228346456,873.3186016511868,0.00025370340306410486,25.0,30.0
586.29224,0.09862770078740157,872.1627708978328,0.00025370340306410486,25.0,30.0
587.7937,0.09896176771653543,872.936274509804,0.00025370340306410486,25.0,30.0
589.29517,0.09933855511811024,873.3597265221879,0.00025370340306410486,25.0,30.0
590.79663,0.09976829527559056,872.2593395252838,0.00025370340306410486,25.0,30.0
592.2981,0.10016545275590552,873.777528379773,0.00025370340306410486,25.0,30.0
593.79956,0.1005201594488189,874.9424922600618,0.00025370340306410486,25.0,30.0
595.30103,0.1008678248031496,874.1688854489165,0.00025370340306410486,25.0,30.0
596.80249,0.10123292716535434,873.590092879257,0.00025370340306410486,25.0,30.0
598.30396,0.10160251181102362,874.3162022703818,0.00025370340306410486,25.0,30.0
599.80542,0.10196314370078739,875.6308823529412,0.00025370340306410486,25.0,30.0
601.30688,0.10231000000000001,875.5904540763673,0.00025370340306410486,25.0,30.0
602.80835,0.10262549409448818,874.3334107327141,0.00025370340306410486,25.0,30.0
604.30981,0.1030372125984252,874.7231682146544,0.00025370340306410486,25.0,30.0
605.81128,0.10340780511811024,875.8927244582044,0.00025370340306410486,25.0,30.0
607.31274,0.10379073031496062,876.7422342621259,0.00025370340306410486,25.0,30.0
608.81421,0.10411009448818896,875.9346749226007,0.00025370340306410486,25.0,30.0
610.31567,0.10450513976377952,877.0601393188855,0.00025370340306410486,25.0,30.0
611.81714,0.10489326377952755,877.3267027863778,0.00025370340306410486,25.0,30.0
613.3186,0.10528087992125983,878.6761609907121,0.00025370340306410486,25.0,30.0
614.82007,0.10574099803149606,879.4127450980392,0.00025370340306410486,25.0,30.0
616.32153,0.10608630708661416,877.730830753354,0.00025370340306410486,25.0,30.0
617.823,0.10647279724409449,877.8573271413828,0.00025370340306410486,25.0,30.0
619.32446,0.10686615354330709,878.8285345717234,0.00025370340306410486,25.0,30.0
620.82593,0.10721498031496063,879.0851393188855,0.00025370340306410486,25.0,30.0
622.32739,0.10762596062992125,879.9240712074304,0.00025370340306410486,25.0,30.0
623.82886,0.10802602755905512,881.35608875129,0.00025370340306410486,25.0,30.0
625.33032,0.10836711023622046,877.9411506707946,0.00025370340306410486,25.0,30.0
626.83179,0.10871698228346456,879.7423374613003,0.00025370340306410486,25.0,30.0
628.33325,0.10906931889763781,881.4353973168215,0.00025370340306410486,25.0,30.0
629.83472,0.10938345275590551,878.3763931888544,0.00025370340306410486,25.0,30.0
631.33618,0.10966336023622048,878.7868163054696,0.00025370340306410486,25.0,30.0
632.83765,0.11000483070866142,882.2343395252839,0.00025370340306410486,25.0,30.0
634.33911,0.11038206496062992,882.8458720330239,0.00025370340306410486,25.0,30.0
635.84058,0.1108119566929134,883.623581011352,0.00025370340306410486,25.0,30.0
637.34204,0.11116479724409449,881.4120227038184,0.00025370340306410486,25.0,30.0
638.84351,0.11148625196850394,881.2567595459237,0.00025370340306410486,25.0,30.0
640.34497,0.11187357677165355,881.7514189886482,0.00025370340306410486,25.0,30.0
641.84644,0.11225792125984252,883.2643188854489,0.00025370340306410486,25.0,30.0
643.3479,0.11263556692913386,884.8463880288958,0.00025370340306410486,25.0,30.0
644.84937,0.11302294881889764,881.9793085655316,0.00025370340306410486,25.0,30.0
646.35083,0.11334135236220473,882.2344685242518,0.00025370340306410486,25.0,30.0
647.85229,0.11376276181102361,884.64935500516,0.00025370340306410486,25.0,30.0
649.35376,0.11421587598425197,884.020536635707,0.00025370340306410486,25.0,30.0
650.85522,0.11462515354330709,886.9386480908153,0.00025370340306410486,25.0,30.0
652.35669,0.11504770078740156,883.2218524251807,0.00025370340306410486,25.0,30.0
653.85815,0.11536453149606299,882.0664602683179,0.00025370340306410486,25.0,30.0
655.35962,0.11574508661417322,884.2515737874097,0.00025370340306410486,25.0,30.0
656.86108,0.11616019488188975,885.9453818369453,0.00025370340306410486,25.0,30.0
658.36255,0.1165524468503937,885.0282765737875,0.00025370340306410486,25.0,30.0
659.86401,0.11693062007874017,886.0871001031992,0.00025370340306410486,25.0,30.0
661.36548,0.1172766437007874,885.9916924664602,0.00025370340306410486,25.0,30.0
662.86694,0.11767925787401574,886.9824045407637,0.00025370340306410486,25.0,30.0
664.36841,0.11809462401574804,886.252141382869,0.00025370340306410486,25.0,30.0
665.86987,0.11844416732283464,886.5423890608876,0.00025370340306410486,25.0,30.0
667.37134,0.11878288188976377,886.2149122807018,0.00025370340306410486,25.0,30.0
668.8728,0.11916985433070865,888.264963880289,0.00025370340306410486,25.0,30.0
670.37427,0.11951162992125985,888.67371001032,0.00025370340306410486,25.0,30.0
671.87573,0.11995999212598425,888.9754643962849,0.00025370340306410486,25.0,30.0
673.3772,0.12037520472440945,888.9973942208463,0.00025370340306410486,25.0,30.0
674.87866,0.12079940748031495,888.6056243550051,0.00025370340306410486,25.0,30.0
676.38013,0.12116523622047246,888.7862487100103,0.00025370340306410486,25.0,30.0
677.88159,0.12153252165354331,889.0136480908152,0.00025370340306410486,25.0,30.0
679.38306,0.12187209251968503,889.611661506708,0.00025370340306410486,25.0,30.0
680.88452,0.12228765748031495,888.1631836945305,0.00025370340306410486,25.0,30.0
682.38599,0.12267230708661417,890.5563983488132,0.00025370340306410486,25.0,30.0
683.88745,0.12303654133858268,891.0552631578947,0.00025370340306410486,25.0,30.0
685.38892,0.12341527755905513,889.7669246646028,0.00025370340306410486,25.0,30.0
686.89038,0.12379612598425198,890.4214912280703,0.00025370340306410486,25.0,30.0
688.39185,0.12420397047244094,891.0074045407637,0.00025370340306410486,25.0,30.0
689.89331,0.12453875393700788,891.2552631578948,0.00025370340306410486,25.0,30.0
691.39478,0.12496532677165355,890.4949948400413,0.00025370340306410486,25.0,30.0
692.89624,0.12532835236220474,890.9151186790506,0.00025370340306410486,25.0,30.0
694.39771,0.12576080118110236,892.5552631578947,0.00025370340306410486,25.0,30.0
695.89917,0.12612700787401573,891.3859649122808,0.00025370340306410486,25.0,30.0
697.40063,0.12648516338582677,891.78782249742,0.00025370340306410486,25.0,30.0
698.9021,0.12689546062992127,892.6711042311662,0.00025370340306410486,25.0,30.0
700.40356,0.12727962992125985,892.2388802889577,0.00025370340306410486,25.0,30.0
701.90503,0.12761821456692912,892.83108875129,0.00025370340306410486,25.0,30.0
703.40649,0.12794924212598427,892.955056759546,0.00025370340306410486,25.0,30.0
704.90796,0.12830795078740156,892.037435500516,0.00025370340306410486,25.0,30.0
706.40942,0.12871061023622046,893.4378482972136,0.00025370340306410486,25.0,30.0
707.91089,0.12915458267716534,893.5975232198142,0.00025370340306410486,25.0,30.0
709.41235,0.12958379527559055,894.1074561403509,0.00025370340306410486,25.0,30.0
710.91382,0.12998670078740157,893.2152992776058,0.00025370340306410486,25.0,30.0
712.41528,0.1303480374015748,893.3897316821466,0.00025370340306410486,25.0,30.0
713.91675,0.13072663188976377,895.2600877192983,0.00025370340306410486,25.0,30.0
715.41821,0.13117071062992125,897.8452270381837,0.00025370340306410486,25.0,30.0
716.91968,0.13161015354330707,896.1224458204335,0.00025370340306410486,25.0,30.0
718.42114,0.1320931968503937,896.1436016511868,0.00025370340306410486,25.0,30.0
719.92261,0.13257273228346456,896.6934210526316,0.00025370340306410486,25.0,30.0
721.42407,0.13299628937007874,895.6720330237358,0.00025370340306410486,25.0,30.0
722.92554,0.1334146377952756,895.1090299277606,0.00025370340306410486,25.0,30.0
724.427,0.13374213385826772,896.3519865841073,0.00025370340306410486,25.0,30.0
725.92847,0.1340470905511811,895.0961300309598,0.00025370340306410486,25.0,30.0
727.42993,0.13438687401574803,896.5973684210527,0.00025370340306410486,25.0,30.0
728.9314,0.13482946062992127,897.3243808049536,0.00025370340306410486,25.0,30.0
730.43286,0.1352325905511811,896.4152734778122,0.00025370340306410486,25.0,30.0
731.93433,0.13562822244094488,898.0288957688339,0.00025370340306410486,25.0,30.0
733.43579,0.13598087598425196,897.3769091847265,0.00025370340306410486,25.0,30.0
734.93726,0.13635435433070867,897.3491228070176,0.00025370340306410486,25.0,30.0
736.43872,0.1367678562992126,897.7080495356038,0.00025370340306410486,25.0,30.0
737.94019,0.13719801771653542,899.1909700722395,0.00025370340306410486,25.0,30.0
739.44165,0.1375844035433071,897.3638802889577,0.00025370340306410486,25.0,30.0
740.94312,0.1379987972440945,898.7372033023736,0.00025370340306410486,25.0,30.0
742.44458,0.13843841732283466,897.8599587203303,0.00025370340306410486,25.0,30.0
743.94604,0.13884871456692913,899.0659184726522,0.00025370340306410486,25.0,30.0
745.44751,0.1391879094488189,898.1920278637771,0.00025370340306410486,25.0,30.0
746.94897,0.1396006594488189,898.277141382869,0.00025370340306410486,25.0,30.0
748.45044,0.1400356692913386,899.0674406604747,0.00025370340306410486,25.0,30.0
749.9519,0.1404869507874016,899.4143188854489,0.00025370340306410486,25.0,30.0
751.45337,0.1408615216535433,899.4287409700723,0.00025370340306410486,25.0,30.0
752.95483,0.14127266535433072,899.9049793601652,0.00025370340306410486,25.0,30.0
754.4563,0.14169616338582677,900.1597007223942,0.00025370340306410486,25.0,30.0
755.95776,0.14212808464566928,901.0593137254903,0.00025370340306410486,25.0,30.0
757.45923,0.14253542716535433,900.8195820433436,0.00025370340306410486,25.0,30.0
758.96069,0.14298375196850394,901.9480650154799,0.00025370340306410486,25.0,30.0
760.46216,0.1433864586614173,899.904411764706,0.00025370340306410486,25.0,30.0
761.96362,0.1437738779527559,900.7856295149638,0.00025370340306410486,25.0,30.0
763.46509,0.1441650275590551,901.3740454076368,0.00025370340306410486,25.0,30.0
764.96655,0.14458933464566928,903.4511351909185,0.00025370340306410486,25.0,30.0
766.46802,0.14501185826771654,902.2146800825594,0.00025370340306410486,25.0,30.0
767.96948,0.14550874803149608,902.1332559339526,0.00025370340306410486,25.0,30.0
769.47095,0.14591048031496062,901.7256449948401,0.00025370340306410486,25.0,30.0
770.97241,0.14629278346456692,902.4719814241487,0.00025370340306410486,25.0,30.0
772.47388,0.14670176771653543,901.1585655314758,0.00025370340306410486,25.0,30.0
773.97534,0.1470874251968504,902.7571981424148,0.00025370340306410486,25.0,30.0
775.47681,0.14752074409448818,904.3553921568628,0.00025370340306410486,25.0,30.0
776.97827,0.14790930118110238,902.837951496388,0.00025370340306410486,25.0,30.0
778.47974,0.1482996062992126,903.6808565531476,0.00025370340306410486,25.0,30.0
779.9812,0.14869828937007876,902.4236068111455,0.00025370340306410486,25.0,30.0
781.48267,0.1490404881889764,901.1256191950465,0.00025370340306410486,25.0,30.0
782.98413,0.14952183070866143,906.8757223942208,0.00025370340306410486,25.0,30.0
784.4856,0.14996588385826773,904.40673374613,0.00025370340306410486,25.0,30.0
785.98706,0.15037091535433073,904.1060113519092,0.00025370340306410486,25.0,30.0
787.48853,0.15076958464566928,904.9801599587204,0.00025370340306410486,25.0,30.0
788.98999,0.15123057086614172,905.4908152734779,0.00025370340306410486,25.0,30.0
790.49146,0.15165490157480316,904.8073787409701,0.00025370340306410486,25.0,30.0
791.99292,0.15207807086614175,903.8001547987616,0.00025370340306410486,25.0,30.0
793.49438,0.15252536417322834,906.669375644995,0.00025370340306410486,25.0,30.0
794.99585,0.15294955511811023,905.9592363261095,0.00025370340306410486,25.0,30.0
796.49731,0.15339721062992126,905.7417440660475,0.00025370340306410486,25.0,30.0
797.99878,0.1538072401574803,905.0372291021672,0.00025370340306410486,25.0,30.0
799.50024,0.15423324803149605,904.140479876161,0.00025370340306410486,25.0,30.0
801.00171,0.1546276712598425,905.369427244582,0.00025370340306410486,25.0,30.0
802.50317,0.15510564763779527,907.0425696594427,0.00025370340306410486,25.0,30.0
804.00464,0.15562918307086615,905.9817337461301,0.00025370340306410486,25.0,30.0
805.5061,0.156063405511811,906.0912022703819,0.00025370340306410486,25.0,30.0
807.00757,0.15645372047244094,905.4602683178534,0.00025370340306410486,25.0,30.0
808.50903,0.15691623228346457,907.5966718266254,0.00025370340306410486,25.0,30.0
810.0105,0.1572819212598425,905.4291537667699,0.00025370340306410486,25.0,30.0
811.51196,0.1577063464566929,904.7711042311662,0.00025370340306410486,25.0,30.0
813.01343,0.1581010964566929,906.7187048503612,0.00025370340306410486,25.0,30.0
814.51489,0.15857649212598424,908.1010319917441,0.00025370340306410486,25.0,30.0
816.01636,0.15898816141732283,906.8692208462332,0.00025370340306410486,25.0,30.0
817.51782,0.15937908858267716,905.7358359133127,0.00025370340306410486,25.0,30.0
819.01929,0.15981108267716534,907.0451496388029,0.00025370340306410486,25.0,30.0
820.52075,0.1603081594488189,907.5721104231167,0.00025370340306410486,25.0,30.0
822.02222,0.1607804901574803,905.8409700722394,0.00025370340306410486,25.0,30.0
823.52368,0.16122989566929133,908.1848555211558,0.00025370340306410486,25.0,30.0
825.02515,0.16169518700787402,907.3224200206398,0.00025370340306410486,25.0,30.0
826.52661,0.16213886614173229,906.6226264189887,0.00025370340306410486,25.0,30.0
828.02808,0.16260549606299213,907.8513415892673,0.00025370340306410486,25.0,30.0
829.52954,0.1630263996062992,908.2262383900929,0.00025370340306410486,25.0,30.0
831.03101,0.16342346456692913,907.9449432404541,0.00025370340306410486,25.0,30.0
832.53247,0.16394113188976378,908.614447884417,0.00025370340306410486,25.0,30.0
834.03394,0.16433534448818896,908.2754901960785,0.00025370340306410486,25.0,30.0
835.5354,0.16479888779527557,908.4924922600619,0.00025370340306410486,25.0,30.0
837.03687,0.16524752952755906,906.3567595459236,0.00025370340306410486,25.0,30.0
838.53833,0.16562944488188977,907.157972136223,0.00025370340306410486,25.0,30.0
840.03979,0.16607829921259842,908.6386222910216,0.00025370340306410486,25.0,30.0
841.54126,0.1665959094488189,909.4240712074304,0.00025370340306410486,25.0,30.0
843.04272,0.1670918248031496,910.721826625387,0.00025370340306410486,25.0,30.0
844.54419,0.16759197637795276,909.1196078431374,0.00025370340306410486,25.0,30.0
846.04565,0.16801549606299213,907.9068885448916,0.00025370340306410486,25.0,30.0
847.54712,0.16842799015748033,909.5524509803921,0.00025370340306410486,25.0,30.0
849.04858,0.16888344881889764,910.3976264189887,0.00025370340306410486,25.0,30.0
850.55005,0.16936746653543305,909.7271671826626,0.00025370340306410486,25.0,30.0
852.05151,0.1697868464566929,909.3259545923632,0.00025370340306410486,25.0,30.0
853.55298,0.17021177559055117,909.6299793601652,0.00025370340306410486,25.0,30.0
855.05444,0.17065202952755906,910.2719040247679,0.00025370340306410486,25.0,30.0
856.55591,0.17112940551181102,910.9889576883385,0.00025370340306410486,25.0,30.0
858.05737,0.1716066653543307,910.4941692466462,0.00025370340306410486,25.0,30.0
859.55884,0.17202096456692914,910.2258513931889,0.00025370340306410486,25.0,30.0
861.0603,0.17248954133858269,911.6127708978328,0.00025370340306410486,25.0,30.0
862.56177,0.17294299409448818,910.0539473684211,0.00025370340306410486,25.0,30.0
864.06323,0.17348977362204726,911.3107585139319,0.00025370340306410486,25.0,30.0
865.5647,0.17396255118110238,911.0841847265222,0.00025370340306410486,25.0,30.0
867.06616,0.174464437007874,911.9252063983489,0.00025370340306410486,25.0,30.0
868.56763,0.1749862716535433,911.2390092879257,0.00025370340306410486,25.0,30.0
870.06909,0.17544329133858266,911.9019607843138,0.00025370340306410486,25.0,30.0
871.57056,0.17592070472440943,910.3636738906089,0.00025370340306410486,25.0,30.0
873.07202,0.1764135807086614,910.3139060887513,0.00025370340306410486,25.0,30.0
874.57349,0.17690372244094488,911.4516511867905,0.00025370340306410486,25.0,30.0
876.07495,0.17743684448818897,911.7927244582044,0.00025370340306410486,25.0,30.0
877.57642,0.17783667716535434,911.6314241486068,0.00025370340306410486,25.0,30.0
879.07788,0.17831059251968503,910.8621517027864,0.00025370340306410486,25.0,30.0
880.57935,0.1787934960629921,911.8619711042312,0.00025370340306410486,25.0,30.0
882.08081,0.17928061023622047,912.0192982456141,0.00025370340306410486,25.0,30.0
883.58228,0.1797532716535433,910.1650154798762,0.00025370340306410486,25.0,30.0
885.08374,0.18016948228346455,912.4173116615068,0.00025370340306410486,25.0,30.0
886.58521,0.18071148622047242,912.4176986584107,0.00025370340306410486,25.0,30.0
888.08667,0.18120200393700786,911.1802373581011,0.00025370340306410486,25.0,30.0
889.58813,0.1816650433070866,911.0984778121775,0.00025370340306410486,25.0,30.0
891.0896,0.1822004409448819,912.7534829721362,0.00025370340306410486,25.0,30.0
892.59106,0.18261751968503936,912.2671052631579,0.00025370340306410486,25.0,30.0
894.09253,0.1830948031496063,914.0403250773994,0.00025370340306410486,25.0,30.0
895.59399,0.1836238996062992,913.4405572755419,0.00025370340306410486,25.0,30.0
897.09546,0.1841168582677165,911.7588493292054,0.00025370340306410486,25.0,30.0
898.59692,0.18467623818897638,913.8796439628484,0.00025370340306410486,25.0,30.0
900.09839,0.18529475393700787,914.7424406604748,0.00025370340306410486,25.0,30.0
901.59985,0.18582728937007872,913.9460268317854,0.00025370340306410486,25.0,30.0
903.10132,0.18633598228346457,911.8844427244583,0.00025370340306410486,25.0,30.0
904.60278,0.18677156496062994,913.5885190918474,0.00025370340306410486,25.0,30.0
906.10425,0.18729260039370077,911.8414860681114,0.00025370340306410486,25.0,30.0
907.60571,0.1877891968503937,912.5012125902992,0.00025370340306410486,25.0,30.0
909.10718,0.18827681692913384,914.9940144478844,0.00025370340306410486,25.0,30.0
910.60864,0.18892776377952755,914.8952012383901,0.00025370340306410486,25.0,30.0
912.11011,0.18939591732283464,913.4115841073271,0.00025370340306410486,25.0,30.0
913.61157,0.18982692519685038,913.529927760578,0.00025370340306410486,25.0,30.0
915.11304,0.19036058661417324,915.5220588235295,0.00025370340306410486,25.0,30.0
916.6145,0.1907616496062992,910.6993292053664,0.00025370340306410486,25.0,30.0
918.11597,0.19121933858267715,914.6856295149639,0.00025370340306410486,25.0,30.0
919.61743,0.19168616732283464,913.6208978328173,0.00025370340306410486,25.0,30.0
921.1189,0.19211490944881887,912.9447110423116,0.00025370340306410486,25.0,30.0
922.62036,0.19257126181102363,913.0102941176472,0.00025370340306410486,25.0,30.0
924.12183,0.19308760433070868,913.9791021671828,0.00025370340306410486,25.0,30.0
925.62329,0.19356744488188976,913.1641124871002,0.00025370340306410486,25.0,30.0
927.12476,0.194131718503937,915.3258513931888,0.00025370340306410486,25.0,30.0
928.62622,0.19471681692913387,913.2820691434468,0.00025370340306410486,25.0,30.0
930.12769,0.19522784448818897,911.9768575851393,0.00025370340306410486,25.0,30.0
931.62915,0.1958080748031496,916.1788957688339,0.00025370340306410486,25.0,30.0
933.13062,0.19634996062992124,914.7383642930857,0.00025370340306410486,25.0,30.0
934.63208,0.19694149606299213,914.5272187822497,0.00025370340306410486,25.0,30.0
936.13354,0.19748881889763778,913.5938596491229,0.00025370340306410486,25.0,30.0
937.63501,0.19801765748031497,914.6756965944272,0.00025370340306410486,25.0,30.0
939.13647,0.19849336614173227,913.062435500516,0.00025370340306410486,25.0,30.0
940.63794,0.1990370472440945,915.2339525283799,0.00025370340306410486,25.0,30.0
942.1394,0.19950791338582677,913.5561919504644,0.00025370340306410486,25.0,30.0
943.64087,0.2000807283464567,914.365221878225,0.00025370340306410486,25.0,30.0
945.14233,0.20071482283464565,915.1920536635707,0.00025370340306410486,25.0,30.0
946.6438,0.20126875984251968,913.9859649122807,0.00025370340306410486,25.0,30.0
948.14526,0.20173391732283463,914.0902734778122,0.00025370340306410486,25.0,30.0
949.64673,0.20226301181102363,913.5113519091848,0.00025370340306410486,25.0,30.0
951.14819,0.20283035433070865,913.5621775025801,0.00025370340306410486,25.0,30.0
952.64966,0.20336232283464564,914.9028895768834,0.00025370340306410486,25.0,30.0
953.95093,0.20394358267716536,917.6484004127967,0.00025370340306410486,25.0,30.0