File: datasets/am_bench_2022/csv/30-XY.12-2.csv
Time(s),Strain(%),Stress(MPa),SR(s-1),Temp(C),Angle(deg)
30.907715,2.7491340551181103e-06,21.728501329717893,0.00025370340306410486,25.0,30.0
32.80957,1.971938976377953e-05,29.41273661156594,0.00025370340306410486,25.0,30.0
34.311035,4.876772440944882e-05,35.49335141054388,0.00025370340306410486,25.0,30.0
35.8125,6.146511811023623e-05,41.14903530270637,0.00025370340306410486,25.0,30.0
37.313965,7.739559251968504e-05,48.8999243885905,0.00025370340306410486,25.0,30.0
38.81543,0.00010636466929133858,56.950448453877044,0.00025370340306410486,25.0,30.0
40.316895,0.00011411342716535433,63.79783594931429,0.00025370340306410486,25.0,30.0
41.818359,0.0001569836318897638,70.8684543984982,0.00025370340306410486,25.0,30.0
43.319824,0.00018495004133858267,80.56942170308182,0.00025370340306410486,25.0,30.0
44.821289,0.00020212116141732283,88.29984356260103,0.00025370340306410486,25.0,30.0
46.322754,0.0002462400590551181,97.73454398498201,0.00025370340306410486,25.0,30.0
47.824219,0.0002713500984251968,106.12898002815874,0.00025370340306410486,25.0,30.0
49.325684,0.0002638667322834646,112.46216040047975,0.00025370340306410486,25.0,30.0
50.827148,0.0003311524606299212,123.90677113208531,0.00025370340306410486,25.0,30.0
52.328613,0.00036508265748031496,135.5825155133754,0.00025370340306410486,25.0,30.0
53.830078,0.0004034138385826772,145.86492152057153,0.00025370340306410486,25.0,30.0
55.331543,0.00039981051181102364,154.95167127287897,0.00025370340306410486,25.0,30.0
56.833008,0.0004527887401574803,163.82073577723315,0.00025370340306410486,25.0,30.0
58.334473,0.0004792628149606299,173.90664076758617,0.00025370340306410486,25.0,30.0
59.835938,0.0005090145275590552,183.71928873129272,0.00025370340306410486,25.0,30.0
61.337402,0.0005507342519685039,194.3273504719195,0.00025370340306410486,25.0,30.0
62.838867,0.0005788097834645669,205.6374563278928,0.00025370340306410486,25.0,30.0
64.340332,0.0006312185039370079,217.8093184543985,0.00025370340306410486,25.0,30.0
65.841797,0.0006550838582677165,230.14907180476612,0.00025370340306410486,25.0,30.0
67.343262,0.000698333996062992,243.18779527559056,0.00025370340306410486,25.0,30.0
68.844727,0.0007310427559055118,252.0790295666684,0.00025370340306410486,25.0,30.0
70.346191,0.0007647460826771654,263.1801376649111,0.00025370340306410486,25.0,30.0
71.847656,0.0008079476377952756,273.63709130729524,0.00025370340306410486,25.0,30.0
73.349121,0.0008526570669291338,286.9518954998175,0.00025370340306410486,25.0,30.0
74.850586,0.0008824547244094488,297.2277467799969,0.00025370340306410486,25.0,30.0
76.352051,0.0009113550590551181,306.5114720759243,0.00025370340306410486,25.0,30.0
77.853516,0.0009614456299212598,318.16345100902123,0.00025370340306410486,25.0,30.0
79.35498,0.001003218838582677,330.33263805600455,0.00025370340306410486,25.0,30.0
80.856445,0.0010486459448818897,342.94642019085364,0.00025370340306410486,25.0,30.0
82.35791,0.0010791791141732284,352.810163216353,0.00025370340306410486,25.0,30.0
83.859375,0.0011198003543307087,362.436512488919,0.00025370340306410486,25.0,30.0
85.36084,0.0011393688582677166,372.1727590342598,0.00025370340306410486,25.0,30.0
86.862305,0.0011944072637795277,385.1430620013558,0.00025370340306410486,25.0,30.0
88.36377,0.0012041733267716536,394.2549408145174,0.00025370340306410486,25.0,30.0
89.865234,0.0012571660433070867,404.0682327788497,0.00025370340306410486,25.0,30.0
91.366699,0.0013145018700787402,417.17703498983155,0.00025370340306410486,25.0,30.0
92.868164,0.0013309864566929135,424.530009907702,0.00025370340306410486,25.0,30.0
94.369629,0.001393680688976378,438.2505866402461,0.00025370340306410486,25.0,30.0
95.871094,0.0014198129921259843,447.2620065703708,0.00025370340306410486,25.0,30.0
97.372559,0.0014436476968503937,455.82682379934295,0.00025370340306410486,25.0,30.0
98.874023,0.0014954820472440945,467.6808155603066,0.00025370340306410486,25.0,30.0
100.37549,0.001525935649606299,476.07793189758564,0.00025370340306410486,25.0,30.0
101.87695,0.0015639280118110237,488.8302132763206,0.00025370340306410486,25.0,30.0
103.37842,0.0015742625787401572,493.94863638733904,0.00025370340306410486,25.0,30.0
104.87988,0.0016146660236220473,505.0261250456276,0.00025370340306410486,25.0,30.0
106.38135,0.0016555919685039369,513.9405798612921,0.00025370340306410486,25.0,30.0
107.88281,0.0016920710433070865,524.3645773582938,0.00025370340306410486,25.0,30.0
109.38428,0.001728008346456693,532.9513740418209,0.00025370340306410486,25.0,30.0
110.88574,0.001743065905511811,541.5617666996924,0.00025370340306410486,25.0,30.0
112.38721,0.0017839894488188978,548.2056891067424,0.00025370340306410486,25.0,30.0
113.88867,0.0017956836023622048,553.5872399228243,0.00025370340306410486,25.0,30.0
115.39014,0.001852173818897638,562.4266308598843,0.00025370340306410486,25.0,30.0
116.8916,0.0018671250393700789,567.797100693539,0.00025370340306410486,25.0,30.0
118.39307,0.0018924918307086612,573.8262762684467,0.00025370340306410486,25.0,30.0
119.89453,0.0019199500787401573,582.8960212754863,0.00025370340306410486,25.0,30.0
121.396,0.001967055216535433,588.0929759607864,0.00025370340306410486,25.0,30.0
122.89746,0.0019692135826771652,592.4390415602023,0.00025370340306410486,25.0,30.0
124.39893,0.002000951968503937,597.7558533660114,0.00025370340306410486,25.0,30.0
125.90039,0.0020325702755905513,605.8929446733066,0.00025370340306410486,25.0,30.0
127.40186,0.002045298622047244,609.8952130155917,0.00025370340306410486,25.0,30.0
128.90332,0.0020722444881889767,614.725322000313,0.00025370340306410486,25.0,30.0
130.40479,0.002110348818897638,620.6075246388904,0.00025370340306410486,25.0,30.0
131.90625,0.0021365366141732284,626.8314126297126,0.00025370340306410486,25.0,30.0
133.40771,0.002143607086614173,630.6199353392085,0.00025370340306410486,25.0,30.0
134.90918,0.002181682283464567,635.4984095531106,0.00025370340306410486,25.0,30.0
136.41064,0.002208365551181102,640.4467852114512,0.00025370340306410486,25.0,30.0
137.91211,0.0022394133858267716,645.2532721489284,0.00025370340306410486,25.0,30.0
139.41357,0.0022566604330708662,647.2520988684362,0.00025370340306410486,25.0,30.0
140.91504,0.0023027805118110236,652.1755227616416,0.00025370340306410486,25.0,30.0
142.4165,0.002292065748031496,657.6192574438129,0.00025370340306410486,25.0,30.0
143.91797,0.002330947047244095,660.7019346091672,0.00025370340306410486,25.0,30.0
145.41943,0.0023679181102362204,664.4835219273089,0.00025370340306410486,25.0,30.0
146.9209,0.002398792519685039,668.3415549877458,0.00025370340306410486,25.0,30.0
148.42236,0.002432757874015748,672.7525421077332,0.00025370340306410486,25.0,30.0
149.92383,0.0024621377952755907,675.6882984825572,0.00025370340306410486,25.0,30.0
151.42529,0.002487040748031496,677.0535015904469,0.00025370340306410486,25.0,30.0
152.92676,0.002543338188976378,682.9079365907077,0.00025370340306410486,25.0,30.0
154.42822,0.0025812885826771654,687.2539500443239,0.00025370340306410486,25.0,30.0
155.92969,0.0026252220472440945,689.4889972362727,0.00025370340306410486,25.0,30.0
157.43115,0.0026817358267716535,694.5003128747979,0.00025370340306410486,25.0,30.0
158.93262,0.0027204096456692915,696.2280857276946,0.00025370340306410486,25.0,30.0
160.43408,0.0027479881889763778,699.0175731344841,0.00025370340306410486,25.0,30.0
161.93555,0.002802636811023622,702.3923449966105,0.00025370340306410486,25.0,30.0
163.43701,0.0028465807086614173,706.7035250560567,0.00025370340306410486,25.0,30.0
164.93848,0.0029175326771653546,712.2167700891694,0.00025370340306410486,25.0,30.0
166.43994,0.002971051377952756,713.4588048182719,0.00025370340306410486,25.0,30.0
167.94141,0.0030298395669291337,715.8172028993065,0.00025370340306410486,25.0,30.0
169.44287,0.003133056102362205,719.8572248005423,0.00025370340306410486,25.0,30.0
170.94434,0.003201221062992126,721.8924492882098,0.00025370340306410486,25.0,30.0
172.4458,0.003274011417322834,724.4595087865673,0.00025370340306410486,25.0,30.0
173.94727,0.0033513165354330707,728.5283151692132,0.00025370340306410486,25.0,30.0
175.44873,0.00344448031496063,732.0758460655994,0.00025370340306410486,25.0,30.0
176.9502,0.0035246177165354333,734.2137456327893,0.00025370340306410486,25.0,30.0
178.45166,0.0036514539370078743,737.7932419043645,0.00025370340306410486,25.0,30.0
179.95313,0.0037308444881889767,739.9607342128592,0.00025370340306410486,25.0,30.0
181.45459,0.0038412224409448813,741.4794806278354,0.00025370340306410486,25.0,30.0
182.95605,0.003956254921259842,743.9058507587214,0.00025370340306410486,25.0,30.0
184.45752,0.004083185826771653,745.2296761745841,0.00025370340306410486,25.0,30.0
185.95898,0.004240838976377953,750.8246597486573,0.00025370340306410486,25.0,30.0
187.46045,0.004385309842519685,751.0879438911195,0.00025370340306410486,25.0,30.0
188.96191,0.004499089566929134,750.8047400531888,0.00025370340306410486,25.0,30.0
190.46338,0.004650572440944882,755.1999009229806,0.00025370340306410486,25.0,30.0
191.96484,0.004852321456692913,757.9316107837514,0.00025370340306410486,25.0,30.0
193.46631,0.005043398818897638,758.409553110497,0.00025370340306410486,25.0,30.0
194.96777,0.005225500590551181,758.6392814308808,0.00025370340306410486,25.0,30.0
196.46924,0.0054016299212598425,761.6764092402358,0.00025370340306410486,25.0,30.0
197.9707,0.005581758267716536,765.5337644052772,0.00025370340306410486,25.0,30.0
199.47217,0.0058017271653543305,766.1278354278563,0.00025370340306410486,25.0,30.0
200.97363,0.006043351181102362,767.6269228763623,0.00025370340306410486,25.0,30.0
202.4751,0.006296402755905511,768.703186108359,0.00025370340306410486,25.0,30.0
203.97656,0.0065219911417322834,771.5161391249935,0.00025370340306410486,25.0,30.0
205.47803,0.0067385427165354336,772.110914115868,0.00025370340306410486,25.0,30.0
206.97949,0.007033455905511811,772.4402669864943,0.00025370340306410486,25.0,30.0
208.48096,0.007304720866141732,776.3312822652136,0.00025370340306410486,25.0,30.0
209.98242,0.007577084251968504,776.3880690410388,0.00025370340306410486,25.0,30.0
211.48389,0.007842077755905513,778.3211399071805,0.00025370340306410486,25.0,30.0
212.98535,0.008047627362204724,777.9043124576316,0.00025370340306410486,25.0,30.0
214.48682,0.008331397637795276,777.7067320227357,0.00025370340306410486,25.0,30.0
215.98828,0.008613198228346457,781.5689106742451,0.00025370340306410486,25.0,30.0
217.48975,0.008909285433070867,781.5925327214892,0.00025370340306410486,25.0,30.0
218.99121,0.009212489566929135,785.0657819262658,0.00025370340306410486,25.0,30.0
220.49268,0.009474014566929133,785.7104083016113,0.00025370340306410486,25.0,30.0
221.99414,0.009845016732283465,785.5561610262293,0.00025370340306410486,25.0,30.0
223.49561,0.010137572440944882,786.903478124837,0.00025370340306410486,25.0,30.0
224.99707,0.01043908248031496,787.6923397820307,0.00025370340306410486,25.0,30.0
226.49854,0.010710978149606299,787.7815873181415,0.00025370340306410486,25.0,30.0
228.0,0.011007635826771655,788.6782343432236,0.00025370340306410486,25.0,30.0
229.50146,0.011371144291338583,792.5115763675236,0.00025370340306410486,25.0,30.0
231.00293,0.01170225,789.7182823173594,0.00025370340306410486,25.0,30.0
232.50439,0.012005591338582677,792.9913959430568,0.00025370340306410486,25.0,30.0
234.00586,0.012339896456692912,793.4711112269907,0.00025370340306410486,25.0,30.0
235.50732,0.012674514173228346,795.133180372321,0.00025370340306410486,25.0,30.0
237.00879,0.013032760826771654,793.048938832977,0.00025370340306410486,25.0,30.0
238.51025,0.013411796062992126,796.4445168691663,0.00025370340306410486,25.0,30.0
240.01172,0.013725251377952757,796.1398811075768,0.00025370340306410486,25.0,30.0
241.51318,0.014035958070866142,796.6580799916567,0.00025370340306410486,25.0,30.0
243.01465,0.014477072047244095,799.6454085623403,0.00025370340306410486,25.0,30.0
244.51611,0.014791839960629922,797.4792981175366,0.00025370340306410486,25.0,30.0
246.01758,0.015098358070866142,798.5043281013715,0.00025370340306410486,25.0,30.0
247.51904,0.0154081218503937,799.7851853783178,0.00025370340306410486,25.0,30.0
249.02051,0.01573211220472441,801.5716483287272,0.00025370340306410486,25.0,30.0
250.52197,0.016036175,803.0068571726548,0.00025370340306410486,25.0,30.0
252.02344,0.016372634645669293,803.9607863586588,0.00025370340306410486,25.0,30.0
253.5249,0.01674916338582677,804.8666110444804,0.00025370340306410486,25.0,30.0
255.02637,0.01712203562992126,804.605308442405,0.00025370340306410486,25.0,30.0
256.52783,0.017449617716535432,806.0639307503781,0.00025370340306410486,25.0,30.0
258.0293,0.01778775964566929,805.1428534181572,0.00025370340306410486,25.0,30.0
259.53076,0.018117081102362206,806.5190071439746,0.00025370340306410486,25.0,30.0
261.03223,0.018477863779527558,806.7435730301924,0.00025370340306410486,25.0,30.0
262.53369,0.018833356102362205,808.3668457005788,0.00025370340306410486,25.0,30.0
264.03516,0.019206081692913386,809.5454711372998,0.00025370340306410486,25.0,30.0
265.53662,0.019546576181102362,808.5003910934975,0.00025370340306410486,25.0,30.0
267.03809,0.019905714566929134,810.8598060176253,0.00025370340306410486,25.0,30.0
268.53955,0.02029385039370079,810.3649423788913,0.00025370340306410486,25.0,30.0
270.04102,0.020599429133858267,810.689706419148,0.00025370340306410486,25.0,30.0
271.54248,0.02093152559055118,811.2388016895239,0.00025370340306410486,25.0,30.0
273.04395,0.021303744094488188,814.504093445273,0.00025370340306410486,25.0,30.0
274.54541,0.021660535433070865,813.7956666840487,0.00025370340306410486,25.0,30.0
276.04688,0.021986687007874015,815.4223549043124,0.00025370340306410486,25.0,30.0
277.54834,0.022348925196850392,814.0761328674976,0.00025370340306410486,25.0,30.0
279.0498,0.022733218503937006,816.310919330448,0.00025370340306410486,25.0,30.0
280.55127,0.023114425196850395,816.1045001825103,0.00025370340306410486,25.0,30.0
282.05273,0.02351003346456693,817.1038744329145,0.00025370340306410486,25.0,30.0
283.5542,0.023848588582677164,817.509855556135,0.00025370340306410486,25.0,30.0
285.05566,0.0241969468503937,819.2738436668927,0.00025370340306410486,25.0,30.0
286.55713,0.024482283464566927,817.9242582259999,0.00025370340306410486,25.0,30.0
288.05859,0.024856277559055118,819.5230484434479,0.00025370340306410486,25.0,30.0
289.56006,0.02527765551181102,819.4646972936331,0.00025370340306410486,25.0,30.0
291.06152,0.025628777559055117,821.7013870782708,0.00025370340306410486,25.0,30.0
292.56299,0.026007372047244095,820.7892788235907,0.00025370340306410486,25.0,30.0
294.06445,0.02639416535433071,820.6298691140429,0.00025370340306410486,25.0,30.0
295.56592,0.026723631889763778,821.7253220003129,0.00025370340306410486,25.0,30.0
297.06738,0.027042881889763778,824.8769098399124,0.00025370340306410486,25.0,30.0
298.56885,0.027371937007874016,823.8872086353445,0.00025370340306410486,25.0,30.0
300.07031,0.02775327559055118,824.0905251082025,0.00025370340306410486,25.0,30.0
301.57178,0.02811188188976378,824.7146060384837,0.00025370340306410486,25.0,30.0
303.07324,0.0284840688976378,825.7358554518435,0.00025370340306410486,25.0,30.0
304.57471,0.028833265748031495,825.6228294310894,0.00025370340306410486,25.0,30.0
306.07617,0.029156942913385827,826.7179172967618,0.00025370340306410486,25.0,30.0
307.57764,0.029537840551181103,828.2252698545133,0.00025370340306410486,25.0,30.0
309.0791,0.029919903543307085,828.2874537206029,0.00025370340306410486,25.0,30.0
310.58057,0.03026346653543307,826.083042185952,0.00025370340306410486,25.0,30.0
312.08203,0.030635651574803146,829.3316472858112,0.00025370340306410486,25.0,30.0
313.5835,0.03099667125984252,828.4689993221047,0.00025370340306410486,25.0,30.0
315.08496,0.03135438976377953,828.2903217395839,0.00025370340306410486,25.0,30.0
316.58643,0.031716687007874014,830.1247848985764,0.00025370340306410486,25.0,30.0
318.08789,0.0320136437007874,830.1862647963707,0.00025370340306410486,25.0,30.0
319.58936,0.0323821062992126,833.0092819523387,0.00025370340306410486,25.0,30.0
321.09082,0.03270413188976378,831.8056526046828,0.00025370340306410486,25.0,30.0
322.59229,0.03307030905511811,832.4364081973197,0.00025370340306410486,25.0,30.0
324.09375,0.033397793307086615,832.4583615789749,0.00025370340306410486,25.0,30.0
325.59521,0.03373043897637795,833.1415758460656,0.00025370340306410486,25.0,30.0
327.09668,0.03409390748031496,834.689263179851,0.00025370340306410486,25.0,30.0
328.59814,0.0344906062992126,836.2647702977525,0.00025370340306410486,25.0,30.0
330.09961,0.03481744881889764,834.3976638681754,0.00025370340306410486,25.0,30.0
331.60107,0.03514163188976378,835.7237054805236,0.00025370340306410486,25.0,30.0
333.10254,0.035475661417322835,836.7222714710331,0.00025370340306410486,25.0,30.0
334.604,0.0358125531496063,837.3641601918965,0.00025370340306410486,25.0,30.0
336.10547,0.03614136220472441,837.2694373468217,0.00025370340306410486,25.0,30.0
337.60693,0.03652502165354331,837.3677843249727,0.00025370340306410486,25.0,30.0
339.1084,0.03692956889763779,839.923189237107,0.00025370340306410486,25.0,30.0
340.60986,0.03731791929133858,838.7506648589457,0.00025370340306410486,25.0,30.0
342.11133,0.03768997637795276,837.9146373259633,0.00025370340306410486,25.0,30.0
343.61279,0.038053072834645665,841.848177504302,0.00025370340306410486,25.0,30.0
345.11426,0.038436265748031495,839.9427960577775,0.00025370340306410486,25.0,30.0
346.61572,0.03874933661417323,840.2846899932211,0.00025370340306410486,25.0,30.0
348.11719,0.039106220472440945,841.7123376961986,0.00025370340306410486,25.0,30.0
349.61865,0.0394936594488189,841.6080721697867,0.00025370340306410486,25.0,30.0
351.12012,0.03983648818897638,841.8594409970276,0.00025370340306410486,25.0,30.0
352.62158,0.04017319094488189,843.4145069614642,0.00025370340306410486,25.0,30.0
354.12305,0.040549883858267716,844.746362830474,0.00025370340306410486,25.0,30.0
355.62451,0.040900964566929134,844.8173854096052,0.00025370340306410486,25.0,30.0
357.12598,0.0412420531496063,845.3541221254628,0.00025370340306410486,25.0,30.0
358.62744,0.04158029724409448,843.0711529436304,0.00025370340306410486,25.0,30.0
360.12891,0.041899088582677164,845.359545288627,0.00025370340306410486,25.0,30.0
361.63037,0.04229598622047244,847.3285185378318,0.00025370340306410486,25.0,30.0
363.13184,0.04270113188976378,848.2827605986339,0.00025370340306410486,25.0,30.0
364.6333,0.04301702952755906,845.8529227720707,0.00025370340306410486,25.0,30.0
366.13477,0.04336759251968504,848.0068832455546,0.00025370340306410486,25.0,30.0
367.63623,0.043714759842519685,849.6760181467383,0.00025370340306410486,25.0,30.0
369.1377,0.044079671259842516,849.0248996193357,0.00025370340306410486,25.0,30.0
370.63916,0.044402374015748036,848.9172706888461,0.00025370340306410486,25.0,30.0
372.14063,0.04475743307086614,851.2020649736664,0.00025370340306410486,25.0,30.0
373.64209,0.04517585236220472,852.3763101632163,0.00025370340306410486,25.0,30.0
375.14355,0.04553500590551181,850.9236585493038,0.00025370340306410486,25.0,30.0
376.64502,0.045886875984251965,849.5056838921626,0.00025370340306410486,25.0,30.0
378.14648,0.046206602362204724,852.141054388069,0.00025370340306410486,25.0,30.0
379.64795,0.046527007874015744,850.649241278615,0.00025370340306410486,25.0,30.0
381.14941,0.0468901062992126,852.752568180633,0.00025370340306410486,25.0,30.0
382.65088,0.047265234251968505,852.126349272566,0.00025370340306410486,25.0,30.0
384.15234,0.0476140374015748,853.9399280387964,0.00025370340306410486,25.0,30.0
385.65381,0.047990828740157476,853.9376336236116,0.00025370340306410486,25.0,30.0
387.15527,0.04839783267716535,856.4216248631174,0.00025370340306410486,25.0,30.0
388.65674,0.04870196062992126,853.075611409501,0.00025370340306410486,25.0,30.0
390.1582,0.049052338582677164,854.2374980445326,0.00025370340306410486,25.0,30.0
391.65967,0.049400511811023624,856.2455545705793,0.00025370340306410486,25.0,30.0
393.16113,0.04974575,856.1951295823122,0.00025370340306410486,25.0,30.0
394.6626,0.05013608267716536,856.4175574907441,0.00025370340306410486,25.0,30.0
396.16406,0.0504740748031496,856.3160296188142,0.00025370340306410486,25.0,30.0
397.66553,0.05079825196850394,858.2110079783074,0.00025370340306410486,25.0,30.0
399.16699,0.05113724803149606,858.2522553058351,0.00025370340306410486,25.0,30.0
400.66846,0.05148313582677165,857.0529540595505,0.00025370340306410486,25.0,30.0
402.16992,0.05179582677165354,858.1245763153779,0.00025370340306410486,25.0,30.0
403.67139,0.05208669291338583,858.3648641601919,0.00025370340306410486,25.0,30.0
405.17285,0.05247008070866142,860.9312979089534,0.00025370340306410486,25.0,30.0
406.67432,0.05282271653543307,861.04090837983,0.00025370340306410486,25.0,30.0
408.17578,0.053178090551181105,859.9170881785473,0.00025370340306410486,25.0,30.0
409.67725,0.0535162716535433,863.2138759972885,0.00025370340306410486,25.0,30.0
411.17871,0.053898204724409454,863.4473066694478,0.00025370340306410486,25.0,30.0
412.68018,0.054256564960629916,861.112713145956,0.00025370340306410486,25.0,30.0
414.18164,0.054597531496062994,862.4610470876571,0.00025370340306410486,25.0,30.0
415.68311,0.054972307086614165,864.1644417792147,0.00025370340306410486,25.0,30.0
417.18457,0.05531555118110236,862.6392032121813,0.00025370340306410486,25.0,30.0
418.68604,0.05561732874015748,864.3345153047923,0.00025370340306410486,25.0,30.0
420.1875,0.05598335826771653,866.5575168170204,0.00025370340306410486,25.0,30.0
421.68896,0.05633379330708661,865.3451009021223,0.00025370340306410486,25.0,30.0
423.19043,0.056695486220472435,864.9144808885645,0.00025370340306410486,25.0,30.0
424.69189,0.05699850196850394,865.484382333003,0.00025370340306410486,25.0,30.0
426.19336,0.0573228779527559,866.4728581112792,0.00025370340306410486,25.0,30.0
427.69482,0.057673167322834645,866.3060958439797,0.00025370340306410486,25.0,30.0
429.19629,0.05806063188976378,868.6169369557282,0.00025370340306410486,25.0,30.0
430.69775,0.058451393700787405,867.8107628930491,0.00025370340306410486,25.0,30.0
432.19922,0.058766671259842515,869.2049069197477,0.00025370340306410486,25.0,30.0
433.70068,0.05911565157480315,868.3438494029306,0.00025370340306410486,25.0,30.0
435.20215,0.059437124015748036,868.8114668613443,0.00025370340306410486,25.0,30.0
436.70361,0.0597489153543307,870.0576993273191,0.00025370340306410486,25.0,30.0
438.20508,0.06005745866141732,870.3691661886636,0.00025370340306410486,25.0,30.0
439.70654,0.06039721062992126,870.2806226208479,0.00025370340306410486,25.0,30.0
441.20801,0.060721216535433074,870.9650362413307,0.00025370340306410486,25.0,30.0
442.70947,0.061043814960629925,871.0594201387079,0.00025370340306410486,25.0,30.0
444.21094,0.061323053149606295,870.2979350263337,0.00025370340306410486,25.0,30.0
445.7124,0.06163479330708661,872.3185065442979,0.00025370340306410486,25.0,30.0
447.21387,0.06196106299212598,871.8835584293685,0.00025370340306410486,25.0,30.0
448.71533,0.062347385826771656,872.1591229076498,0.00025370340306410486,25.0,30.0
450.2168,0.06264413582677165,873.79243364447,0.00025370340306410486,25.0,30.0
451.71826,0.06298807086614173,872.5802002398707,0.00025370340306410486,25.0,30.0
453.21973,0.06334262401574803,874.2499087448507,0.00025370340306410486,25.0,30.0
454.72119,0.06368583858267717,876.4182614590395,0.00025370340306410486,25.0,30.0
456.22266,0.06409115551181102,876.1211607655003,0.00025370340306410486,25.0,30.0
457.72412,0.06444656496062992,875.3107889659487,0.00025370340306410486,25.0,30.0
459.22559,0.06480128346456693,876.9925431506492,0.00025370340306410486,25.0,30.0
460.72705,0.06512649212598424,877.6554987745737,0.00025370340306410486,25.0,30.0
462.22852,0.06544294881889763,877.3662460238827,0.00025370340306410486,25.0,30.0
463.72998,0.06581005708661417,879.528654116911,0.00025370340306410486,25.0,30.0
465.23145,0.06616843700787402,877.8718516973458,0.00025370340306410486,25.0,30.0
466.73291,0.06654670866141732,879.940762371591,0.00025370340306410486,25.0,30.0
468.23438,0.0668688090551181,878.0797570005736,0.00025370340306410486,25.0,30.0
469.73584,0.06725099999999999,878.9532252177088,0.00025370340306410486,25.0,30.0
471.2373,0.06755261811023622,877.3326380560046,0.00025370340306410486,25.0,30.0
472.73877,0.06783223228346456,878.0000521457997,0.00025370340306410486,25.0,30.0
474.24023,0.06815381102362204,878.7894352609898,0.00025370340306410486,25.0,30.0
475.7417,0.06850008661417323,881.1542733482818,0.00025370340306410486,25.0,30.0
477.24316,0.06888527559055119,880.4016269489492,0.00025370340306410486,25.0,30.0
478.74463,0.06917510236220471,879.9121082546801,0.00025370340306410486,25.0,30.0
480.24609,0.06945384842519685,881.0491734890754,0.00025370340306410486,25.0,30.0
481.74756,0.0697973031496063,883.3746675705273,0.00025370340306410486,25.0,30.0
483.24902,0.07016864763779528,880.7966053084424,0.00025370340306410486,25.0,30.0
484.75049,0.07052678543307087,882.6067424518955,0.00025370340306410486,25.0,30.0
486.25195,0.0709178346456693,884.56666840486,0.00025370340306410486,25.0,30.0
487.75342,0.07129881299212598,884.1125567085571,0.00025370340306410486,25.0,30.0
489.25488,0.0716680374015748,883.3745372060281,0.00025370340306410486,25.0,30.0
490.75635,0.07201941732283465,884.041064817229,0.00025370340306410486,25.0,30.0
492.25781,0.07235004133858267,885.5887782239141,0.00025370340306410486,25.0,30.0
493.75928,0.07274491732283464,885.438937268603,0.00025370340306410486,25.0,30.0
495.26074,0.07308723818897638,886.2015174427701,0.00025370340306410486,25.0,30.0
496.76221,0.0734635216535433,885.9039735099338,0.00025370340306410486,25.0,30.0
498.26367,0.0737764468503937,885.3023152735047,0.00025370340306410486,25.0,30.0
499.76514,0.07414107874015748,887.154403712781,0.00025370340306410486,25.0,30.0
501.2666,0.07449324606299212,887.4929863899464,0.00025370340306410486,25.0,30.0
502.76807,0.07481018897637795,886.5101684309328,0.00025370340306410486,25.0,30.0
504.26953,0.07515271653543307,888.2305626531784,0.00025370340306410486,25.0,30.0
505.771,0.07546853149606299,887.7397142410179,0.00025370340306410486,25.0,30.0
507.27246,0.07583836220472441,888.5709704333316,0.00025370340306410486,25.0,30.0
508.77393,0.07614186023622048,889.0839808103457,0.00025370340306410486,25.0,30.0
510.27539,0.07647027165354331,888.1070031808938,0.00025370340306410486,25.0,30.0
511.77686,0.07680875196850394,892.1849090055796,0.00025370340306410486,25.0,30.0
513.27832,0.0771399625984252,888.3600928195234,0.00025370340306410486,25.0,30.0
514.77979,0.07749926181102362,891.0064139333576,0.00025370340306410486,25.0,30.0
516.28125,0.0778196122047244,891.5580904208167,0.00025370340306410486,25.0,30.0
517.78271,0.07817481889763779,891.9953329509308,0.00025370340306410486,25.0,30.0
519.28418,0.07854163385826772,891.9475413255464,0.00025370340306410486,25.0,30.0
520.78564,0.07888002952755906,893.0937060019816,0.00025370340306410486,25.0,30.0
522.28711,0.07924775393700788,892.0467747822913,0.00025370340306410486,25.0,30.0
523.78857,0.07955612007874015,891.5345987380716,0.00025370340306410486,25.0,30.0
525.29004,0.07989597834645669,892.7273817593993,0.00025370340306410486,25.0,30.0
526.7915,0.08026804921259843,893.1358919539031,0.00025370340306410486,25.0,30.0
528.29297,0.08058705708661418,893.2146321113835,0.00025370340306410486,25.0,30.0
529.79443,0.08092090748031495,893.6509881629034,0.00025370340306410486,25.0,30.0
531.2959,0.08134159645669291,895.5222401835533,0.00025370340306410486,25.0,30.0
532.79736,0.0816968248031496,894.6844396933826,0.00025370340306410486,25.0,30.0
534.29883,0.08207356102362205,897.380898993586,0.00025370340306410486,25.0,30.0
535.80029,0.08244785433070867,895.8533920842676,0.00025370340306410486,25.0,30.0
537.30176,0.08281797244094488,896.6745841372477,0.00025370340306410486,25.0,30.0
538.80322,0.083145781496063,896.1048130573082,0.00025370340306410486,25.0,30.0
540.30469,0.08345806496062992,896.3915888825155,0.00025370340306410486,25.0,30.0
541.80615,0.08383275393700787,897.2470928716692,0.00025370340306410486,25.0,30.0
543.30762,0.08419528543307087,897.4910309224591,0.00025370340306410486,25.0,30.0
544.80908,0.084522031496063,897.4214423528185,0.00025370340306410486,25.0,30.0
546.31055,0.0848785688976378,897.5280805131147,0.00025370340306410486,25.0,30.0
547.81201,0.08523541141732283,898.149084841216,0.00025370340306410486,25.0,30.0
549.31348,0.08560618503937008,899.25152526464,0.00025370340306410486,25.0,30.0
550.81494,0.08594573818897637,898.83787870887,0.00025370340306410486,25.0,30.0
552.31641,0.08630079133858268,900.1868644730667,0.00025370340306410486,25.0,30.0
553.81787,0.08666164566929134,899.8319862335089,0.00025370340306410486,25.0,30.0
555.31934,0.08703077755905511,899.1502320488086,0.00025370340306410486,25.0,30.0
556.8208,0.08737441929133859,901.3764926735151,0.00025370340306410486,25.0,30.0
558.32227,0.08768386417322833,900.250769150545,0.00025370340306410486,25.0,30.0
559.82373,0.0879999153543307,902.7768941961725,0.00025370340306410486,25.0,30.0
561.3252,0.08837155314960629,902.6471554466289,0.00025370340306410486,25.0,30.0
562.82666,0.08877711220472441,902.4337226886374,0.00025370340306410486,25.0,30.0
564.32813,0.08913583661417324,901.3041143035929,0.00025370340306410486,25.0,30.0
565.82959,0.089544468503937,903.209547895917,0.00025370340306410486,25.0,30.0
567.33105,0.08992679527559055,903.8241904364604,0.00025370340306410486,25.0,30.0
568.83252,0.09035379527559055,901.8807686290869,0.00025370340306410486,25.0,30.0
570.33398,0.09067173031496062,904.8171507535069,0.00025370340306410486,25.0,30.0
571.83545,0.091068968503937,903.0878395995203,0.00025370340306410486,25.0,30.0
573.33691,0.09141805511811024,903.5930802523857,0.00025370340306410486,25.0,30.0
574.83838,0.0917875157480315,903.565755853366,0.00025370340306410486,25.0,30.0
576.33984,0.09208754527559056,904.4207123116233,0.00025370340306410486,25.0,30.0
577.84131,0.09239478543307086,905.551650414559,0.00025370340306410486,25.0,30.0
579.34277,0.09274398228346457,905.0640611148773,0.00025370340306410486,25.0,30.0
580.84424,0.09304786614173229,904.5572560880222,0.00025370340306410486,25.0,30.0
582.3457,0.09338277952755905,906.2236011889242,0.00025370340306410486,25.0,30.0
583.84717,0.09370884448818897,906.6756791990406,0.00025370340306410486,25.0,30.0
585.34863,0.09406812598425197,907.1560723783699,0.00025370340306410486,25.0,30.0
586.8501,0.09444693307086614,907.9790634614382,0.00025370340306410486,25.0,30.0
588.35156,0.0948276751968504,907.251055952443,0.00025370340306410486,25.0,30.0
589.85303,0.09517057874015748,908.545914376597,0.00025370340306410486,25.0,30.0
591.35449,0.09554697244094487,906.1615998331336,0.00025370340306410486,25.0,30.0
592.85596,0.0959043248031496,908.0044584658706,0.00025370340306410486,25.0,30.0
594.35742,0.096196,907.919408666632,0.00025370340306410486,25.0,30.0
595.85889,0.09650703543307086,908.5713093810293,0.00025370340306410486,25.0,30.0
597.36035,0.09683562992125984,909.9938467956406,0.00025370340306410486,25.0,30.0
598.86182,0.09717551771653543,909.1174062679252,0.00025370340306410486,25.0,30.0
600.36328,0.09753594881889763,910.7715231788079,0.00025370340306410486,25.0,30.0
601.86475,0.0978800964566929,910.156359180268,0.00025370340306410486,25.0,30.0
603.36621,0.09822415944881889,911.5554831308339,0.00025370340306410486,25.0,30.0
604.86768,0.0985671811023622,909.9580747770767,0.00025370340306410486,25.0,30.0
606.36914,0.09887502362204725,912.4875892996819,0.00025370340306410486,25.0,30.0
607.87061,0.09920978346456692,910.6713250247692,0.00025370340306410486,25.0,30.0
609.37207,0.09955240551181102,911.7563748240079,0.00025370340306410486,25.0,30.0
610.87354,0.09984351771653543,911.6365959221985,0.00025370340306410486,25.0,30.0
612.375,0.10013948818897636,910.7081138864265,0.00025370340306410486,25.0,30.0
613.87646,0.10046808661417321,912.1106794597695,0.00025370340306410486,25.0,30.0
615.37793,0.1008059094488189,913.0483913020806,0.00025370340306410486,25.0,30.0
616.87939,0.10118892716535434,911.5096730458362,0.00025370340306410486,25.0,30.0
618.38086,0.10154010236220472,915.0190071439746,0.00025370340306410486,25.0,30.0
619.88232,0.10188280511811022,913.4847212807008,0.00025370340306410486,25.0,30.0
621.38379,0.10227541141732284,914.0951921572718,0.00025370340306410486,25.0,30.0
622.88525,0.10264234251968504,916.3142305887261,0.00025370340306410486,25.0,30.0
624.38672,0.10306632283464567,914.8933357668041,0.00025370340306410486,25.0,30.0
625.88818,0.1034395787401575,913.7414611253064,0.00025370340306410486,25.0,30.0
627.38965,0.10379004921259842,914.9010533451531,0.00025370340306410486,25.0,30.0
628.89111,0.10415170078740156,916.3793085466966,0.00025370340306410486,25.0,30.0
630.39258,0.10454202952755906,917.413490118371,0.00025370340306410486,25.0,30.0
631.89404,0.10496326377952755,915.4536945299056,0.00025370340306410486,25.0,30.0
633.39551,0.10529270866141732,917.0166084371905,0.00025370340306410486,25.0,30.0
634.89697,0.105678155511811,918.4286645460708,0.00025370340306410486,25.0,30.0
636.39844,0.10611087598425196,918.1675444542942,0.00025370340306410486,25.0,30.0
637.8999,0.1064734783464567,915.2476404025656,0.00025370340306410486,25.0,30.0
639.40137,0.10681250984251969,918.3951087239923,0.00025370340306410486,25.0,30.0
640.90283,0.10716943307086614,919.028654116911,0.00025370340306410486,25.0,30.0
642.4043,0.10755073818897637,918.6443135005475,0.00025370340306410486,25.0,30.0
643.90576,0.10791275393700787,918.5848672889399,0.00025370340306410486,25.0,30.0
645.40723,0.10828658661417323,917.69546853001,0.00025370340306410486,25.0,30.0
646.90869,0.10865736614173228,918.2660739427439,0.00025370340306410486,25.0,30.0
648.41016,0.10906449606299211,918.8470563696095,0.00025370340306410486,25.0,30.0
649.91162,0.10939437598425197,921.1813891641028,0.00025370340306410486,25.0,30.0
651.41309,0.10978653346456693,920.082259998957,0.00025370340306410486,25.0,30.0
652.91455,0.11009949409448819,919.3095635396569,0.00025370340306410486,25.0,30.0
654.41602,0.11047021653543307,919.4694686343015,0.00025370340306410486,25.0,30.0
655.91748,0.11078174409448818,920.1765396047349,0.00025370340306410486,25.0,30.0
657.41895,0.11115708858267716,920.6189967148147,0.00025370340306410486,25.0,30.0
658.92041,0.11153677559055117,921.6896803462481,0.00025370340306410486,25.0,30.0
660.42188,0.11195387992125985,920.7941283829588,0.00025370340306410486,25.0,30.0
661.92334,0.11233324803149607,921.8236168326641,0.00025370340306410486,25.0,30.0
663.4248,0.11271006102362205,920.5452886270011,0.00025370340306410486,25.0,30.0
664.92627,0.11307517322834647,921.3318819419096,0.00025370340306410486,25.0,30.0
666.42773,0.11343220275590551,922.3396516660582,0.00025370340306410486,25.0,30.0
667.9292,0.11380515551181102,922.3476821192053,0.00025370340306410486,25.0,30.0
669.43066,0.11417411614173227,923.2162486311728,0.00025370340306410486,25.0,30.0
670.93213,0.11453573425196852,924.1972936329978,0.00025370340306410486,25.0,30.0
672.43359,0.11495108858267716,925.2923293528706,0.00025370340306410486,25.0,30.0
673.93506,0.1153077086614173,924.1912447202377,0.00025370340306410486,25.0,30.0
675.43652,0.11575542322834646,925.3049486363874,0.00025370340306410486,25.0,30.0
676.93799,0.11611406102362204,924.3034624810972,0.00025370340306410486,25.0,30.0
678.43945,0.11648834842519686,924.4863899462898,0.00025370340306410486,25.0,30.0
679.94092,0.1168504940944882,925.0926370130886,0.00025370340306410486,25.0,30.0
681.44238,0.1172236811023622,927.1367262866976,0.00025370340306410486,25.0,30.0
682.94385,0.11764467913385826,926.8911977890182,0.00025370340306410486,25.0,30.0
684.44531,0.11799987795275589,925.117275903426,0.00025370340306410486,25.0,30.0
685.94678,0.11834137401574803,926.485164519998,0.00025370340306410486,25.0,30.0
687.44824,0.11864186023622046,925.6979976012932,0.00025370340306410486,25.0,30.0
688.94971,0.119016031496063,927.7414350524066,0.00025370340306410486,25.0,30.0
690.45117,0.11941011417322835,927.4693904156021,0.00025370340306410486,25.0,30.0
691.95264,0.11975100000000001,927.6092193773791,0.00025370340306410486,25.0,30.0
693.4541,0.12011077362204724,928.348333941701,0.00025370340306410486,25.0,30.0
694.95557,0.12052032283464566,927.3174897012045,0.00025370340306410486,25.0,30.0
696.45703,0.1209046437007874,928.12426344058,0.00025370340306410486,25.0,30.0
697.9585,0.12133140354330708,929.746675705272,0.00025370340306410486,25.0,30.0
699.45996,0.12168498228346457,926.1370391614956,0.00025370340306410486,25.0,30.0
700.96143,0.12202356692913387,928.147885487824,0.00025370340306410486,25.0,30.0
702.46289,0.12242602755905513,929.782265213537,0.00025370340306410486,25.0,30.0
703.96436,0.12283244291338581,928.2000052145801,0.00025370340306410486,25.0,30.0
705.46582,0.12319801377952756,928.7560358763102,0.00025370340306410486,25.0,30.0
706.96729,0.12356981496062992,928.9587787453721,0.00025370340306410486,25.0,30.0
708.46875,0.12393570275590551,930.6848307868802,0.00025370340306410486,25.0,30.0
709.97021,0.12429716732283463,929.954398498201,0.00025370340306410486,25.0,30.0
711.47168,0.12462292913385825,930.0990248735465,0.00025370340306410486,25.0,30.0
712.97314,0.12501276377952755,932.1808416332065,0.00025370340306410486,25.0,30.0
714.47461,0.12542319094488188,931.3966209521824,0.00025370340306410486,25.0,30.0
715.97607,0.125819468503937,931.1692913385828,0.00025370340306410486,25.0,30.0
717.47754,0.12622522637795275,932.7737133023935,0.00025370340306410486,25.0,30.0
718.979,0.12663011417322834,931.3134744746311,0.00025370340306410486,25.0,30.0
720.48047,0.1270173464566929,931.0212494133598,0.00025370340306410486,25.0,30.0
721.98193,0.12740709842519685,932.0359545288627,0.00025370340306410486,25.0,30.0
723.4834,0.127766968503937,931.5420555874225,0.00025370340306410486,25.0,30.0
724.98486,0.12810490748031497,931.0220055274548,0.00025370340306410486,25.0,30.0
726.48633,0.12852033267716537,932.8804036084894,0.00025370340306410486,25.0,30.0
727.98779,0.12891707874015748,932.6292172915472,0.00025370340306410486,25.0,30.0
729.48926,0.12941820472440946,932.6485633832195,0.00025370340306410486,25.0,30.0
730.99072,0.12981817716535432,933.6604786984409,0.00025370340306410486,25.0,30.0
732.49219,0.13023452952755904,934.0694582051417,0.00025370340306410486,25.0,30.0
733.99365,0.1307102874015748,933.7226886374302,0.00025370340306410486,25.0,30.0
735.49512,0.13110454724409448,932.6172498305261,0.00025370340306410486,25.0,30.0
736.99658,0.13150355708661418,933.7951712989519,0.00025370340306410486,25.0,30.0
738.49805,0.13193206496062992,934.3870261250456,0.00025370340306410486,25.0,30.0
739.99951,0.13227073228346456,934.7959013401471,0.00025370340306410486,25.0,30.0
741.50098,0.13262904133858266,935.0807477707671,0.00025370340306410486,25.0,30.0
743.00244,0.13300398622047244,935.3549564582573,0.00025370340306410486,25.0,30.0
744.50391,0.13342114960629922,936.0993377483444,0.00025370340306410486,25.0,30.0
746.00537,0.13382154330708662,936.020910465662,0.00025370340306410486,25.0,30.0
747.50684,0.13421225984251967,935.8571465818429,0.00025370340306410486,25.0,30.0
749.0083,0.13466588779527558,936.9308025238566,0.00025370340306410486,25.0,30.0
750.50977,0.13509622637795274,935.9951504406321,0.00025370340306410486,25.0,30.0
752.01123,0.13553132874015747,937.0669552067582,0.00025370340306410486,25.0,30.0
753.5127,0.13601017322834646,935.878030974605,0.00025370340306410486,25.0,30.0
755.01416,0.1364174783464567,934.7641966939563,0.00025370340306410486,25.0,30.0
756.51563,0.13680158858267716,935.9588048182719,0.00025370340306410486,25.0,30.0
758.01709,0.13724226377952756,938.1674923084946,0.00025370340306410486,25.0,30.0
759.51855,0.13768137992125984,937.2133545392919,0.00025370340306410486,25.0,30.0
761.02002,0.1381543562992126,938.8364186264797,0.00025370340306410486,25.0,30.0
762.52148,0.13856446653543306,937.604395890911,0.00025370340306410486,25.0,30.0
764.02295,0.1389824625984252,936.8744589873286,0.00025370340306410486,25.0,30.0
765.52441,0.13937125196850395,937.7225322000313,0.00025370340306410486,25.0,30.0
767.02588,0.13971972834645668,938.3972206288785,0.00025370340306410486,25.0,30.0
768.52734,0.14008104133858268,938.8201230640872,0.00025370340306410486,25.0,30.0
770.02881,0.14042693503937007,936.7804401105492,0.00025370340306410486,25.0,30.0
771.53027,0.1408677283464567,938.3075298534703,0.00025370340306410486,25.0,30.0
773.03174,0.14127224212598424,937.5008343327945,0.00025370340306410486,25.0,30.0
774.5332,0.14166701771653542,938.5034416227772,0.00025370340306410486,25.0,30.0
776.03467,0.14220375196850393,940.3813943786828,0.00025370340306410486,25.0,30.0
777.53613,0.14275403937007872,939.1698388694791,0.00025370340306410486,25.0,30.0
779.0376,0.14330351771653543,940.3208531052825,0.00025370340306410486,25.0,30.0
780.53906,0.14379357677165353,941.294389111957,0.00025370340306410486,25.0,30.0
782.04053,0.14426662401574802,939.7226364916306,0.00025370340306410486,25.0,30.0
783.54199,0.14472566338582676,938.9367992908171,0.00025370340306410486,25.0,30.0
785.04346,0.1451662440944882,939.6313552693331,0.00025370340306410486,25.0,30.0
786.54492,0.14560925393700788,940.3617093393128,0.00025370340306410486,25.0,30.0
788.04639,0.14600431102362205,938.2079053032278,0.00025370340306410486,25.0,30.0
789.54785,0.14637246456692912,940.9223288314128,0.00025370340306410486,25.0,30.0
791.04932,0.1468567755905512,941.7430254992961,0.00025370340306410486,25.0,30.0
792.55078,0.14734403149606298,942.888486207436,0.00025370340306410486,25.0,30.0
794.05225,0.1478613248031496,941.9903790999635,0.00025370340306410486,25.0,30.0
795.55371,0.1483001811023622,940.6754184700422,0.00025370340306410486,25.0,30.0
797.05518,0.1488046968503937,940.3526881159723,0.00025370340306410486,25.0,30.0
798.55664,0.1492612244094488,941.6414976273662,0.00025370340306410486,25.0,30.0
800.05811,0.14968716338582677,941.6360744642019,0.00025370340306410486,25.0,30.0
801.55957,0.1500753090551181,941.4340355634354,0.00025370340306410486,25.0,30.0
803.06104,0.15053412401574803,941.7482922250613,0.00025370340306410486,25.0,30.0
804.5625,0.15096217322834646,941.4489492621369,0.00025370340306410486,25.0,30.0
806.06396,0.15139436614173227,941.6630599155238,0.00025370340306410486,25.0,30.0
807.56543,0.15184720866141732,941.9044428221307,0.00025370340306410486,25.0,30.0
809.06689,0.15229392716535434,942.9236324764041,0.00025370340306410486,25.0,30.0
810.56836,0.15275769291338584,944.5593419200084,0.00025370340306410486,25.0,30.0
812.06982,0.1532946751968504,943.4624550242478,0.00025370340306410486,25.0,30.0
813.57129,0.15381872637795277,943.5379621421495,0.00025370340306410486,25.0,30.0
815.07275,0.15434274212598426,943.3977942326745,0.00025370340306410486,25.0,30.0
816.57422,0.15476374212598426,942.549408145174,0.00025370340306410486,25.0,30.0
818.07568,0.15515111417322835,942.4072586953122,0.00025370340306410486,25.0,30.0
819.57715,0.1555748818897638,942.0402826302341,0.00025370340306410486,25.0,30.0
821.07861,0.15604263779527558,943.854382854461,0.00025370340306410486,25.0,30.0
822.58008,0.15654531102362204,944.7963967252438,0.00025370340306410486,25.0,30.0
824.08154,0.15707810236220474,944.4507482922251,0.00025370340306410486,25.0,30.0
825.58301,0.15755587992125983,942.4980184596131,0.00025370340306410486,25.0,30.0
827.08447,0.15802970078740156,944.7482140063618,0.00025370340306410486,25.0,30.0
828.58594,0.15855243897637794,946.5861187881317,0.00025370340306410486,25.0,30.0
830.0874,0.15907891929133858,945.4454815664598,0.00025370340306410486,25.0,30.0
831.58887,0.1595094566929134,944.5340251342756,0.00025370340306410486,25.0,30.0
833.09033,0.15993681496062992,944.5056317463628,0.00025370340306410486,25.0,30.0
834.5918,0.16035204133858266,944.2784324972624,0.00025370340306410486,25.0,30.0
836.09326,0.1607965649606299,946.1231423058872,0.00025370340306410486,25.0,30.0
837.59473,0.16119680708661416,944.4988267195077,0.00025370340306410486,25.0,30.0
839.09619,0.161640687007874,944.6725243781614,0.00025370340306410486,25.0,30.0
840.59766,0.1620915,946.6402200552745,0.00025370340306410486,25.0,30.0
842.09912,0.16254902362204726,945.2089482192209,0.00025370340306410486,25.0,30.0
843.60059,0.16301662598425196,946.440162694895,0.00025370340306410486,25.0,30.0
845.10205,0.16339601968503936,946.9033738332378,0.00025370340306410486,25.0,30.0
846.60352,0.16392269881889762,947.8519580747771,0.00025370340306410486,25.0,30.0
848.10498,0.16437017913385826,946.8324555457059,0.00025370340306410486,25.0,30.0
849.60645,0.16485187401574802,946.2255827293112,0.00025370340306410486,25.0,30.0
851.10791,0.16529442716535434,946.76059863378,0.00025370340306410486,25.0,30.0
852.60938,0.1657176318897638,947.4535902383063,0.00025370340306410486,25.0,30.0
854.11084,0.1662364035433071,947.2864368775096,0.00025370340306410486,25.0,30.0
855.6123,0.16669877362204724,946.005449236064,0.00025370340306410486,25.0,30.0
857.11377,0.16711035039370079,946.5581686395161,0.00025370340306410486,25.0,30.0
858.61523,0.16753537401574803,947.5730041195181,0.00025370340306410486,25.0,30.0
860.1167,0.1680395255905512,947.4463941179538,0.00025370340306410486,25.0,30.0
861.61816,0.1684592933070866,946.6870730562654,0.00025370340306410486,25.0,30.0
863.11963,0.1689406594488189,947.7082703238254,0.00025370340306410486,25.0,30.0
864.62109,0.1693474251968504,945.2228972206289,0.00025370340306410486,25.0,30.0
866.12256,0.16978061614173226,947.2016478072691,0.00025370340306410486,25.0,30.0
867.62402,0.17023202755905512,947.3029931689002,0.00025370340306410486,25.0,30.0
869.12549,0.17075789763779528,947.390311310424,0.00025370340306410486,25.0,30.0
870.62695,0.1711678779527559,948.1486937477187,0.00025370340306410486,25.0,30.0
872.12842,0.1717084271653543,947.766204307243,0.00025370340306410486,25.0,30.0
873.62988,0.17225826771653543,949.2619022787715,0.00025370340306410486,25.0,30.0
875.13135,0.17279598818897637,948.6471815195287,0.00025370340306410486,25.0,30.0
876.63281,0.17326565748031497,947.6646764353131,0.00025370340306410486,25.0,30.0
878.13428,0.1737917972440945,949.2573655942014,0.00025370340306410486,25.0,30.0
879.63574,0.17438005314960628,947.9956718986285,0.00025370340306410486,25.0,30.0
881.13721,0.17491489960629922,949.3163164207123,0.00025370340306410486,25.0,30.0
882.63867,0.1754278503937008,947.7980914637326,0.00025370340306410486,25.0,30.0
884.14014,0.175904687007874,948.7957449027481,0.00025370340306410486,25.0,30.0
885.6416,0.17649126574803148,949.8646295040935,0.00025370340306410486,25.0,30.0
887.14307,0.17701483661417322,950.1406372216719,0.00025370340306410486,25.0,30.0
888.64453,0.17749136811023622,949.6997184126819,0.00025370340306410486,25.0,30.0
890.146,0.17790965748031495,948.0032591124785,0.00025370340306410486,25.0,30.0
891.64746,0.1784125649606299,950.3071648328728,0.00025370340306410486,25.0,30.0
893.14893,0.1789362874015748,947.8061219168796,0.00025370340306410486,25.0,30.0
894.65039,0.1794732933070866,950.6002242269385,0.00025370340306410486,25.0,30.0
896.15186,0.18003164173228345,951.1089065025812,0.00025370340306410486,25.0,30.0
897.65332,0.180538187007874,949.47272774678,0.00025370340306410486,25.0,30.0
899.15479,0.18102701574803148,949.7564791156072,0.00025370340306410486,25.0,30.0
900.65625,0.18160772637795275,949.326380560046,0.00025370340306410486,25.0,30.0
902.15771,0.18211075196850393,949.0209626114616,0.00025370340306410486,25.0,30.0
903.65918,0.18257454133858267,949.5100119935339,0.00025370340306410486,25.0,30.0
905.16064,0.18302682086614172,950.3623611618084,0.00025370340306410486,25.0,30.0
906.66211,0.1835256338582677,949.2230015122282,0.00025370340306410486,25.0,30.0
908.16357,0.18398177362204726,949.1536215257861,0.00025370340306410486,25.0,30.0
909.66504,0.1845148838582677,949.2756426969808,0.00025370340306410486,25.0,30.0
911.1665,0.1849969783464567,947.5000521457997,0.00025370340306410486,25.0,30.0
912.66797,0.18542251771653542,949.2852635970173,0.00025370340306410486,25.0,30.0
914.16943,0.18595884251968503,950.7339782030557,0.00025370340306410486,25.0,30.0
915.6709,0.1863910216535433,949.5953746675706,0.00025370340306410486,25.0,30.0
917.17236,0.18698979133858268,951.3501329717892,0.00025370340306410486,25.0,30.0
918.67383,0.18757595866141732,951.4688689576054,0.00025370340306410486,25.0,30.0
920.17529,0.1881508720472441,951.0434635240131,0.00025370340306410486,25.0,30.0
921.67676,0.18878566141732284,950.5284194608124,0.00025370340306410486,25.0,30.0
923.17822,0.18928198818897637,952.0041977368722,0.00025370340306410486,25.0,30.0
924.67969,0.18981979133858268,951.7081921051259,0.00025370340306410486,25.0,30.0
926.18115,0.19040067913385827,951.8223914063723,0.00025370340306410486,25.0,30.0
927.68262,0.19090017322834643,949.9588569640716,0.00025370340306410486,25.0,30.0
929.18408,0.19145137401574802,950.4801063774313,0.00025370340306410486,25.0,30.0
930.68555,0.19205969291338584,952.4001147207592,0.00025370340306410486,25.0,30.0
932.18701,0.19260504133858267,950.6459300203369,0.00025370340306410486,25.0,30.0
933.68848,0.19325451968503937,952.0535798091464,0.00025370340306410486,25.0,30.0
935.18994,0.1938512125984252,951.63787349429,0.00025370340306410486,25.0,30.0
936.69141,0.19437296456692912,951.4694947072013,0.00025370340306410486,25.0,30.0
938.19287,0.19485299212598425,950.3396255931585,0.00025370340306410486,25.0,30.0
939.69434,0.19535065551181102,952.5076915054493,0.00025370340306410486,25.0,30.0
941.1958,0.19586862992125983,952.8340720654952,0.00025370340306410486,25.0,30.0
942.69727,0.1965320255905512,953.1587578870523,0.00025370340306410486,25.0,30.0
944.19873,0.19710303149606298,951.784090316525,0.00025370340306410486,25.0,30.0
944.79932,0.1973401377952756,955.1111748448662,0.00025370340306410486,25.0,30.0