File: datasets/am_bench_2022/csv/30-XY.12-3.csv
Time(s),Strain(%),Stress(MPa),SR(s-1),Temp(C),Angle(deg)
24.044189,2.6596289370078742e-05,17.56251968503937,0.00025370340306410486,25.0,30.0
26.246338,1.2235571062992125e-05,24.926461417322834,0.00025370340306410486,25.0,30.0
27.8479,4.2645344488188974e-05,32.33030183727034,0.00025370340306410486,25.0,30.0
29.449463,3.155642716535433e-05,37.04305249343832,0.00025370340306410486,25.0,30.0
31.051025,5.44217342519685e-05,41.639648293963255,0.00025370340306410486,25.0,30.0
32.652588,7.362864566929134e-05,47.86072965879265,0.00025370340306410486,25.0,30.0
34.25415,7.603651771653544e-05,55.22591076115486,0.00025370340306410486,25.0,30.0
35.855713,0.00012508572047244094,64.81038057742782,0.00025370340306410486,25.0,30.0
37.457275,0.00013369981102362205,71.97363254593175,0.00025370340306410486,25.0,30.0
39.058838,0.00016628918110236219,80.60762467191601,0.00025370340306410486,25.0,30.0
40.6604,0.00020406293307086615,90.77309448818897,0.00025370340306410486,25.0,30.0
42.261963,0.00021257476377952757,98.74674540682415,0.00025370340306410486,25.0,30.0
43.863525,0.00024340885826771652,107.9628530183727,0.00025370340306410486,25.0,30.0
45.465088,0.000270839842519685,115.63253805774279,0.00025370340306410486,25.0,30.0
47.06665,0.00031760759842519684,126.17752230971128,0.00025370340306410486,25.0,30.0
48.668213,0.0003512930118110236,136.00473490813647,0.00025370340306410486,25.0,30.0
50.269775,0.0003698316141732284,147.954312335958,0.00025370340306410486,25.0,30.0
51.871338,0.00041518452755905517,155.91075065616798,0.00025370340306410486,25.0,30.0
53.4729,0.0004440132086614173,168.03772965879264,0.00025370340306410486,25.0,30.0
55.074463,0.0004873505118110236,179.68674803149605,0.00025370340306410486,25.0,30.0
56.676025,0.0005097614763779528,188.71615223097115,0.00025370340306410486,25.0,30.0
58.277588,0.0005443103740157481,202.67628871391074,0.00025370340306410486,25.0,30.0
59.87915,0.0005876766929133858,213.6862755905512,0.00025370340306410486,25.0,30.0
61.480713,0.0006307031889763779,224.62648293963255,0.00025370340306410486,25.0,30.0
63.082275,0.0006554833070866142,233.81725721784775,0.00025370340306410486,25.0,30.0
64.683838,0.0006963320078740157,245.37750918635172,0.00025370340306410486,25.0,30.0
66.2854,0.0007519391732283465,260.2471942257218,0.00025370340306410486,25.0,30.0
67.886963,0.0007706743897637795,271.3363254593176,0.00025370340306410486,25.0,30.0
69.488525,0.0008197314370078741,287.109186351706,0.00025370340306410486,25.0,30.0
71.090088,0.0008623733464566929,296.7620997375328,0.00025370340306410486,25.0,30.0
72.69165,0.0009026744094488189,308.2769028871391,0.00025370340306410486,25.0,30.0
74.293213,0.000943466437007874,320.4648556430446,0.00025370340306410486,25.0,30.0
75.894775,0.0009962857086614173,330.5133595800525,0.00025370340306410486,25.0,30.0
77.496338,0.001032696220472441,340.8407611548556,0.00025370340306410486,25.0,30.0
79.0979,0.0010485218110236221,351.5073490813648,0.00025370340306410486,25.0,30.0
80.699463,0.001106123031496063,365.2039107611548,0.00025370340306410486,25.0,30.0
82.301025,0.0011569007283464567,377.5459842519685,0.00025370340306410486,25.0,30.0
83.902588,0.001193519311023622,389.11167979002624,0.00025370340306410486,25.0,30.0
85.50415,0.0012381752952755904,400.36173228346456,0.00025370340306410486,25.0,30.0
87.105713,0.0012513470078740158,410.4191338582677,0.00025370340306410486,25.0,30.0
88.707275,0.001294643877952756,423.3397900262467,0.00025370340306410486,25.0,30.0
90.308838,0.0013497234645669291,434.2815748031496,0.00025370340306410486,25.0,30.0
91.9104,0.0013891258267716535,443.6881364829396,0.00025370340306410486,25.0,30.0
93.511963,0.001416132342519685,456.5990026246719,0.00025370340306410486,25.0,30.0
95.113525,0.0014639721653543307,467.62391076115483,0.00025370340306410486,25.0,30.0
96.715088,0.001511095905511811,478.5532283464567,0.00025370340306410486,25.0,30.0
98.31665,0.0015448685433070864,488.06503937007875,0.00025370340306410486,25.0,30.0
99.918213,0.0015986212401574804,500.9575590551181,0.00025370340306410486,25.0,30.0
101.51978,0.0016334732480314963,509.54333333333335,0.00025370340306410486,25.0,30.0
103.12134,0.001667364586614173,519.0413385826771,0.00025370340306410486,25.0,30.0
104.7229,0.0016903137992125984,526.2458792650918,0.00025370340306410486,25.0,30.0
106.32446,0.0017317882874015747,535.1720472440945,0.00025370340306410486,25.0,30.0
107.92603,0.001752348149606299,544.2078477690288,0.00025370340306410486,25.0,30.0
109.52759,0.0017941938582677164,553.7620209973753,0.00025370340306410486,25.0,30.0
111.12915,0.0018293630118110234,561.0498425196851,0.00025370340306410486,25.0,30.0
112.73071,0.0018531518897637793,570.1574278215222,0.00025370340306410486,25.0,30.0
114.33228,0.001900374527559055,577.5819422572179,0.00025370340306410486,25.0,30.0
115.93384,0.001922738188976378,584.395249343832,0.00025370340306410486,25.0,30.0
117.5354,0.0019322340157480313,590.4273753280839,0.00025370340306410486,25.0,30.0
119.13696,0.0019747015748031497,597.4640157480314,0.00025370340306410486,25.0,30.0
120.73853,0.0019981088582677166,602.938845144357,0.00025370340306410486,25.0,30.0
122.34009,0.002032555905511811,609.9201312335958,0.00025370340306410486,25.0,30.0
123.94165,0.002043839960629921,615.9192388451444,0.00025370340306410486,25.0,30.0
125.54321,0.0020672250000000002,620.279186351706,0.00025370340306410486,25.0,30.0
127.14478,0.0020968206692913386,625.74312335958,0.00025370340306410486,25.0,30.0
128.74634,0.002130638779527559,633.1642257217848,0.00025370340306410486,25.0,30.0
130.3479,0.0021581614173228347,638.0985039370079,0.00025370340306410486,25.0,30.0
131.94946,0.00219053937007874,644.4853805774278,0.00025370340306410486,25.0,30.0
133.55103,0.002218257677165354,646.6891076115485,0.00025370340306410486,25.0,30.0
135.15259,0.002252685433070866,652.7109186351705,0.00025370340306410486,25.0,30.0
136.75415,0.002276156496062992,657.3098687664043,0.00025370340306410486,25.0,30.0
138.35571,0.002295315748031496,662.6569291338583,0.00025370340306410486,25.0,30.0
139.95728,0.002328219094488189,664.2214173228346,0.00025370340306410486,25.0,30.0
141.55884,0.0023676141732283463,671.7473490813647,0.00025370340306410486,25.0,30.0
143.1604,0.002408953937007874,675.8883202099738,0.00025370340306410486,25.0,30.0
144.76196,0.0024488049212598425,680.8343832020997,0.00025370340306410486,25.0,30.0
146.36353,0.002474627362204724,683.6696325459318,0.00025370340306410486,25.0,30.0
147.96509,0.0025115627952755903,687.3179527559055,0.00025370340306410486,25.0,30.0
149.56665,0.002553958661417323,687.9390026246718,0.00025370340306410486,25.0,30.0
151.16821,0.002603503149606299,694.0482939632547,0.00025370340306410486,25.0,30.0
152.76978,0.0026454167322834646,698.6103149606299,0.00025370340306410486,25.0,30.0
154.37134,0.002705830511811024,702.0162467191601,0.00025370340306410486,25.0,30.0
155.9729,0.002738972440944882,704.7068503937008,0.00025370340306410486,25.0,30.0
157.57446,0.0028083935039370077,709.5682677165355,0.00025370340306410486,25.0,30.0
159.17603,0.002865165157480315,713.5171128608923,0.00025370340306410486,25.0,30.0
160.77759,0.002935454133858268,715.5541994750656,0.00025370340306410486,25.0,30.0
162.37915,0.002992502755905512,718.6874015748032,0.00025370340306410486,25.0,30.0
163.98071,0.0030453834645669292,721.2929658792651,0.00025370340306410486,25.0,30.0
165.58228,0.0031372793307086616,726.2992125984251,0.00025370340306410486,25.0,30.0
167.18384,0.0032446269685039372,729.5930446194226,0.00025370340306410486,25.0,30.0
168.7854,0.0033212157480314963,730.9172965879264,0.00025370340306410486,25.0,30.0
170.38696,0.003427171456692913,736.6696587926509,0.00025370340306410486,25.0,30.0
171.98853,0.003526180905511811,736.7213648293963,0.00025370340306410486,25.0,30.0
173.59009,0.0036405726377952757,741.9879002624672,0.00025370340306410486,25.0,30.0
175.19165,0.003737837401574803,743.9947244094488,0.00025370340306410486,25.0,30.0
176.79321,0.0038767295275590552,746.83968503937,0.00025370340306410486,25.0,30.0
178.39478,0.003990620078740158,747.7596062992126,0.00025370340306410486,25.0,30.0
179.99634,0.004143145078740158,751.9390813648295,0.00025370340306410486,25.0,30.0
181.5979,0.004296170078740158,754.172939632546,0.00025370340306410486,25.0,30.0
183.19946,0.004454122440944882,755.8855118110237,0.00025370340306410486,25.0,30.0
184.80103,0.004615070669291338,757.4848556430446,0.00025370340306410486,25.0,30.0
186.40259,0.004779432283464567,759.3097112860892,0.00025370340306410486,25.0,30.0
188.00415,0.004991613582677165,762.7705511811024,0.00025370340306410486,25.0,30.0
189.60571,0.0051706688976377955,763.5710761154857,0.00025370340306410486,25.0,30.0
191.20728,0.005358027559055119,764.8426509186351,0.00025370340306410486,25.0,30.0
192.80884,0.005554265551181102,767.1782152230971,0.00025370340306410486,25.0,30.0
194.4104,0.00578405688976378,771.0589501312335,0.00025370340306410486,25.0,30.0
196.01196,0.006093307283464566,772.0945406824146,0.00025370340306410486,25.0,30.0
197.61353,0.006314917125984252,773.2232283464567,0.00025370340306410486,25.0,30.0
199.21509,0.0065602244094488185,776.5535170603674,0.00025370340306410486,25.0,30.0
200.81665,0.00683543405511811,775.8404461942257,0.00025370340306410486,25.0,30.0
202.41821,0.0071067311023622045,777.3866929133858,0.00025370340306410486,25.0,30.0
204.01978,0.00741221811023622,779.7188976377952,0.00025370340306410486,25.0,30.0
205.62134,0.007672875590551181,781.2750656167979,0.00025370340306410486,25.0,30.0
207.2229,0.007989328740157479,782.4889763779527,0.00025370340306410486,25.0,30.0
208.82446,0.008298382677165355,783.2684776902887,0.00025370340306410486,25.0,30.0
210.42603,0.008584643307086614,785.5927034120735,0.00025370340306410486,25.0,30.0
212.02759,0.008925400984251968,787.1493700787402,0.00025370340306410486,25.0,30.0
213.62915,0.0092088031496063,785.5125196850394,0.00025370340306410486,25.0,30.0
215.23071,0.009477379724409448,789.1388713910761,0.00025370340306410486,25.0,30.0
216.83228,0.009763537007874017,789.8489501312337,0.00025370340306410486,25.0,30.0
218.43384,0.010166691141732282,791.6153280839895,0.00025370340306410486,25.0,30.0
220.0354,0.010481049212598426,792.7110761154856,0.00025370340306410486,25.0,30.0
221.63696,0.01075682933070866,791.0804724409448,0.00025370340306410486,25.0,30.0
223.23853,0.011071007677165354,795.1087926509186,0.00025370340306410486,25.0,30.0
224.84009,0.011426310826771653,794.1063517060368,0.00025370340306410486,25.0,30.0
226.44165,0.011760932086614174,796.5019422572178,0.00025370340306410486,25.0,30.0
228.04321,0.012113004330708662,795.0781102362205,0.00025370340306410486,25.0,30.0
229.64478,0.012484965748031495,798.4826771653543,0.00025370340306410486,25.0,30.0
231.24634,0.012824171062992126,797.3975065616797,0.00025370340306410486,25.0,30.0
232.8479,0.013159670078740157,799.4611023622048,0.00025370340306410486,25.0,30.0
234.44946,0.013511777559055117,799.4569291338582,0.00025370340306410486,25.0,30.0
236.05103,0.013851277559055119,802.6058267716535,0.00025370340306410486,25.0,30.0
237.65259,0.014192939566929134,802.2478215223097,0.00025370340306410486,25.0,30.0
239.25415,0.014568786023622047,803.5261417322835,0.00025370340306410486,25.0,30.0
240.85571,0.01493687559055118,805.4565879265092,0.00025370340306410486,25.0,30.0
242.45728,0.015308775393700787,807.6588451443569,0.00025370340306410486,25.0,30.0
244.05884,0.015775950196850394,806.723280839895,0.00025370340306410486,25.0,30.0
245.6604,0.01611831181102362,806.0545669291339,0.00025370340306410486,25.0,30.0
247.26196,0.016485478740157482,809.5296325459317,0.00025370340306410486,25.0,30.0
248.86353,0.016845982677165354,809.3477690288713,0.00025370340306410486,25.0,30.0
250.46509,0.01724229192913386,809.1136745406825,0.00025370340306410486,25.0,30.0
252.06665,0.017527108070866142,807.9382152230971,0.00025370340306410486,25.0,30.0
253.66821,0.017834561811023622,810.5107349081364,0.00025370340306410486,25.0,30.0
255.26978,0.01820536318897638,811.991653543307,0.00025370340306410486,25.0,30.0
256.87134,0.018568674212598425,812.3228871391077,0.00025370340306410486,25.0,30.0
258.4729,0.018990306692913385,813.4874540682415,0.00025370340306410486,25.0,30.0
260.07446,0.019389228149606298,814.6797112860893,0.00025370340306410486,25.0,30.0
261.67603,0.019739450787401573,814.6741994750656,0.00025370340306410486,25.0,30.0
263.27759,0.02010113779527559,815.930656167979,0.00025370340306410486,25.0,30.0
264.87915,0.02045041535433071,816.0876377952756,0.00025370340306410486,25.0,30.0
266.48071,0.02085866929133858,816.7415223097112,0.00025370340306410486,25.0,30.0
268.08228,0.021203228346456694,818.2366666666666,0.00025370340306410486,25.0,30.0
269.68384,0.021616354330708663,817.918188976378,0.00025370340306410486,25.0,30.0
271.2854,0.022019582677165354,818.4179527559055,0.00025370340306410486,25.0,30.0
272.88696,0.022391570866141734,819.3282414698164,0.00025370340306410486,25.0,30.0
274.48853,0.022778003937007872,820.2470866141732,0.00025370340306410486,25.0,30.0
276.09009,0.023144846456692913,822.1793175853019,0.00025370340306410486,25.0,30.0
277.69165,0.023527862204724408,821.7321784776902,0.00025370340306410486,25.0,30.0
279.29321,0.023902232283464567,823.6048031496063,0.00025370340306410486,25.0,30.0
280.89478,0.02431792125984252,825.0966404199474,0.00025370340306410486,25.0,30.0
282.49634,0.024745094488188974,825.0477952755905,0.00025370340306410486,25.0,30.0
284.0979,0.02516232086614173,824.8738845144356,0.00025370340306410486,25.0,30.0
285.69946,0.025502114173228344,824.5085039370078,0.00025370340306410486,25.0,30.0
287.30103,0.025814927165354332,826.0561417322834,0.00025370340306410486,25.0,30.0
288.90259,0.026173399606299216,824.3102624671916,0.00025370340306410486,25.0,30.0
290.50415,0.02652388582677165,827.1085826771654,0.00025370340306410486,25.0,30.0
292.10571,0.026866013779527558,828.256745406824,0.00025370340306410486,25.0,30.0
293.70728,0.02724544094488189,827.7779527559054,0.00025370340306410486,25.0,30.0
295.30884,0.02759421653543307,828.7703937007874,0.00025370340306410486,25.0,30.0
296.9104,0.027972990157480317,828.8684514435696,0.00025370340306410486,25.0,30.0
298.51196,0.02838183661417323,830.0551968503937,0.00025370340306410486,25.0,30.0
300.11353,0.028745976377952755,830.5187926509186,0.00025370340306410486,25.0,30.0
301.71509,0.029148143700787398,832.5561942257218,0.00025370340306410486,25.0,30.0
303.31665,0.029576860236220474,833.5497375328084,0.00025370340306410486,25.0,30.0
304.91821,0.029928389763779525,833.6932020997375,0.00025370340306410486,25.0,30.0
306.51978,0.030303893700787402,832.9086089238846,0.00025370340306410486,25.0,30.0
308.12134,0.030673362204724407,833.8993963254593,0.00025370340306410486,25.0,30.0
309.7229,0.031031127952755904,835.4089238845144,0.00025370340306410486,25.0,30.0
311.32446,0.0314153405511811,833.8816535433072,0.00025370340306410486,25.0,30.0
312.92603,0.03182664566929134,835.9725459317585,0.00025370340306410486,25.0,30.0
314.52759,0.0322467874015748,835.2838845144356,0.00025370340306410486,25.0,30.0
316.12915,0.032624637795275586,836.2415485564304,0.00025370340306410486,25.0,30.0
317.73071,0.03296158464566929,835.3366929133858,0.00025370340306410486,25.0,30.0
319.33228,0.03332886023622047,837.6354593175853,0.00025370340306410486,25.0,30.0
320.93384,0.03369028543307087,840.2661679790026,0.00025370340306410486,25.0,30.0
322.5354,0.03403299015748031,837.8706299212598,0.00025370340306410486,25.0,30.0
324.13696,0.0344403031496063,840.4623622047244,0.00025370340306410486,25.0,30.0
325.73853,0.034845887795275594,841.6687926509186,0.00025370340306410486,25.0,30.0
327.34009,0.035253204724409445,840.6376902887139,0.00025370340306410486,25.0,30.0
328.94165,0.03558388779527559,840.6813910761155,0.00025370340306410486,25.0,30.0
330.54321,0.035947594488188975,842.4629133858267,0.00025370340306410486,25.0,30.0
332.14478,0.036321151574803145,843.3410498687664,0.00025370340306410486,25.0,30.0
333.74634,0.03668637204724409,846.0172965879265,0.00025370340306410486,25.0,30.0
335.3479,0.037109340551181105,844.1147244094489,0.00025370340306410486,25.0,30.0
336.94946,0.03751557086614173,843.7031496062992,0.00025370340306410486,25.0,30.0
338.55103,0.03788917716535433,845.5836220472441,0.00025370340306410486,25.0,30.0
340.15259,0.0382078562992126,845.1790813648295,0.00025370340306410486,25.0,30.0
341.75415,0.03859174212598425,845.999028871391,0.00025370340306410486,25.0,30.0
343.35571,0.03898905511811024,847.0669816272966,0.00025370340306410486,25.0,30.0
344.95728,0.03936799409448819,847.0730708661417,0.00025370340306410486,25.0,30.0
346.55884,0.03973740551181103,847.7797900262467,0.00025370340306410486,25.0,30.0
348.1604,0.040153944881889767,848.16656167979,0.00025370340306410486,25.0,30.0
349.76196,0.04051954921259843,848.836062992126,0.00025370340306410486,25.0,30.0
351.36353,0.040851448818897636,848.986404199475,0.00025370340306410486,25.0,30.0
352.96509,0.04125330708661417,848.9635958005249,0.00025370340306410486,25.0,30.0
354.56665,0.04161806102362205,849.622125984252,0.00025370340306410486,25.0,30.0
356.16821,0.04198396850393701,851.8708398950131,0.00025370340306410486,25.0,30.0
357.76978,0.042338891732283467,849.6903674540682,0.00025370340306410486,25.0,30.0
359.37134,0.042698435039370077,853.1001312335958,0.00025370340306410486,25.0,30.0
360.9729,0.043071496062992126,852.5580839895013,0.00025370340306410486,25.0,30.0
362.57446,0.04344047244094488,852.7123359580052,0.00025370340306410486,25.0,30.0
364.17603,0.04377002165354331,853.7819947506562,0.00025370340306410486,25.0,30.0
365.77759,0.04410882480314961,854.4356167979003,0.00025370340306410486,25.0,30.0
367.37915,0.044519226377952754,856.1019160104987,0.00025370340306410486,25.0,30.0
368.98071,0.044900730314960634,855.3936482939632,0.00025370340306410486,25.0,30.0
370.58228,0.0452571811023622,854.3601312335958,0.00025370340306410486,25.0,30.0
372.18384,0.0456310374015748,856.6147244094489,0.00025370340306410486,25.0,30.0
373.7854,0.04596129330708661,856.3982677165354,0.00025370340306410486,25.0,30.0
375.38696,0.0463944842519685,857.4510236220472,0.00025370340306410486,25.0,30.0
376.98853,0.04676421062992126,857.9507086614173,0.00025370340306410486,25.0,30.0
378.59009,0.0471816279527559,859.2156955380577,0.00025370340306410486,25.0,30.0
380.19165,0.047544269685039366,857.6977427821522,0.00025370340306410486,25.0,30.0
381.79321,0.04792958267716535,859.0947769028871,0.00025370340306410486,25.0,30.0
383.39478,0.04836642322834646,859.5851706036744,0.00025370340306410486,25.0,30.0
384.99634,0.04868120275590551,858.2725984251969,0.00025370340306410486,25.0,30.0
386.5979,0.04898594881889764,859.4501574803149,0.00025370340306410486,25.0,30.0
388.19946,0.04935917519685039,861.6356430446194,0.00025370340306410486,25.0,30.0
389.80103,0.04977285236220473,863.1616797900263,0.00025370340306410486,25.0,30.0
391.40259,0.05017304921259842,862.2623884514436,0.00025370340306410486,25.0,30.0
393.00415,0.050567061023622045,862.1761417322834,0.00025370340306410486,25.0,30.0
394.60571,0.0509280688976378,861.1567716535434,0.00025370340306410486,25.0,30.0
396.20728,0.05124329724409449,862.6598687664042,0.00025370340306410486,25.0,30.0
397.80884,0.05158618897637795,864.5719947506561,0.00025370340306410486,25.0,30.0
399.4104,0.05196640354330709,866.5912335958004,0.00025370340306410486,25.0,30.0
401.01196,0.05234853543307086,864.9387139107611,0.00025370340306410486,25.0,30.0
402.61353,0.05269341535433071,865.1964304461942,0.00025370340306410486,25.0,30.0
404.21509,0.05304843307086614,865.3458792650919,0.00025370340306410486,25.0,30.0
405.81665,0.05338383858267716,864.504120734908,0.00025370340306410486,25.0,30.0
407.41821,0.05373894291338582,867.0488976377952,0.00025370340306410486,25.0,30.0
409.01978,0.05415787204724409,869.901312335958,0.00025370340306410486,25.0,30.0
410.62134,0.05457057480314961,868.731811023622,0.00025370340306410486,25.0,30.0
412.2229,0.05492673031496063,867.5254593175853,0.00025370340306410486,25.0,30.0
413.82446,0.055290505905511815,870.0423359580052,0.00025370340306410486,25.0,30.0
415.42603,0.05568128543307087,870.2939107611548,0.00025370340306410486,25.0,30.0
417.02759,0.05611339566929134,871.1761679790026,0.00025370340306410486,25.0,30.0
418.62915,0.05650319094488189,870.1910761154855,0.00025370340306410486,25.0,30.0
420.23071,0.056811850393700784,869.9683989501312,0.00025370340306410486,25.0,30.0
421.83228,0.05718331102362204,871.2930971128608,0.00025370340306410486,25.0,30.0
423.43384,0.05753020866141732,871.3818372703413,0.00025370340306410486,25.0,30.0
425.0354,0.057880773622047244,872.2041732283465,0.00025370340306410486,25.0,30.0
426.63696,0.05826275984251969,872.9823359580053,0.00025370340306410486,25.0,30.0
428.23853,0.05864240551181102,873.4812598425196,0.00025370340306410486,25.0,30.0
429.84009,0.058970194881889766,873.5196587926508,0.00025370340306410486,25.0,30.0
431.44165,0.059291309055118105,873.6386351706037,0.00025370340306410486,25.0,30.0
433.04321,0.0597015846456693,874.3584514435695,0.00025370340306410486,25.0,30.0
434.64478,0.06004493307086614,873.2833858267716,0.00025370340306410486,25.0,30.0
436.24634,0.060353456692913386,874.705249343832,0.00025370340306410486,25.0,30.0
437.8479,0.06071350196850393,877.2730183727034,0.00025370340306410486,25.0,30.0
439.44946,0.06109704330708662,878.1692125984252,0.00025370340306410486,25.0,30.0
441.05103,0.06149388385826772,878.6166666666667,0.00025370340306410486,25.0,30.0
442.65259,0.06183916141732283,877.5308661417323,0.00025370340306410486,25.0,30.0
444.25415,0.06217334645669292,878.005433070866,0.00025370340306410486,25.0,30.0
445.85571,0.06257886417322835,878.15,0.00025370340306410486,25.0,30.0
447.45728,0.0629573877952756,878.1505774278215,0.00025370340306410486,25.0,30.0
449.05884,0.06337014566929135,878.1474803149606,0.00025370340306410486,25.0,30.0
450.6604,0.06369691338582677,878.67,0.00025370340306410486,25.0,30.0
452.26196,0.06403724803149606,878.6906824146981,0.00025370340306410486,25.0,30.0
453.86353,0.06443084842519685,882.4093700787402,0.00025370340306410486,25.0,30.0
455.46509,0.06475922047244094,879.5565879265092,0.00025370340306410486,25.0,30.0
457.06665,0.06510800196850393,881.1279265091864,0.00025370340306410486,25.0,30.0
458.66821,0.0654926751968504,881.8659842519685,0.00025370340306410486,25.0,30.0
460.26978,0.06589064173228347,883.3503674540682,0.00025370340306410486,25.0,30.0
461.87134,0.06625204724409449,884.7280052493438,0.00025370340306410486,25.0,30.0
463.4729,0.06662559645669291,881.5510498687664,0.00025370340306410486,25.0,30.0
465.07446,0.06699561417322834,881.7142519685038,0.00025370340306410486,25.0,30.0
466.67603,0.06738003543307086,884.6511286089238,0.00025370340306410486,25.0,30.0
468.27759,0.06779823031496063,885.6680577427821,0.00025370340306410486,25.0,30.0
469.87915,0.06817744094488189,883.6566666666668,0.00025370340306410486,25.0,30.0
471.48071,0.06849726377952756,883.2485564304462,0.00025370340306410486,25.0,30.0
473.08228,0.0688368937007874,886.0227296587926,0.00025370340306410486,25.0,30.0
474.68384,0.0691815688976378,884.3020734908137,0.00025370340306410486,25.0,30.0
476.2854,0.06950504724409448,887.0101049868766,0.00025370340306410486,25.0,30.0
477.88696,0.06987024212598425,886.389186351706,0.00025370340306410486,25.0,30.0
479.48853,0.07026646653543307,887.3483202099737,0.00025370340306410486,25.0,30.0
481.09009,0.07065236614173229,887.9634120734909,0.00025370340306410486,25.0,30.0
482.69165,0.07101094488188976,887.715564304462,0.00025370340306410486,25.0,30.0
484.29321,0.0713236811023622,888.6298950131234,0.00025370340306410486,25.0,30.0
485.89478,0.07168755118110236,887.8645406824147,0.00025370340306410486,25.0,30.0
487.49634,0.07207801968503938,889.7798687664041,0.00025370340306410486,25.0,30.0
489.0979,0.07245028543307086,889.2387139107611,0.00025370340306410486,25.0,30.0
490.69946,0.07283583070866141,891.1264304461941,0.00025370340306410486,25.0,30.0
492.30103,0.0732611653543307,891.9169553805774,0.00025370340306410486,25.0,30.0
493.90259,0.07363015157480314,890.8046719160104,0.00025370340306410486,25.0,30.0
495.50415,0.07398560826771654,891.3897900262467,0.00025370340306410486,25.0,30.0
497.10571,0.074328968503937,890.4662204724409,0.00025370340306410486,25.0,30.0
498.70728,0.07470579330708661,891.5746456692913,0.00025370340306410486,25.0,30.0
500.30884,0.07502433661417322,892.4369028871391,0.00025370340306410486,25.0,30.0
501.9104,0.0753921968503937,893.8099212598426,0.00025370340306410486,25.0,30.0
503.51196,0.07582088582677166,894.4006036745407,0.00025370340306410486,25.0,30.0
505.11353,0.07616378346456694,893.6532283464567,0.00025370340306410486,25.0,30.0
506.71509,0.0764597125984252,892.9626509186352,0.00025370340306410486,25.0,30.0
508.31665,0.07678699212598425,894.8233858267716,0.00025370340306410486,25.0,30.0
509.91821,0.0771414527559055,895.2825721784777,0.00025370340306410486,25.0,30.0
511.51978,0.07753260236220473,894.8653018372703,0.00025370340306410486,25.0,30.0
513.12134,0.0779278937007874,896.4395275590551,0.00025370340306410486,25.0,30.0
514.7229,0.07832926771653544,896.1314173228346,0.00025370340306410486,25.0,30.0
516.32446,0.07868849803149607,896.0094750656168,0.00025370340306410486,25.0,30.0
517.92603,0.07906908661417324,899.1460892388451,0.00025370340306410486,25.0,30.0
519.52759,0.07946480118110237,896.7358267716536,0.00025370340306410486,25.0,30.0
521.12915,0.07984235236220473,897.9320472440944,0.00025370340306410486,25.0,30.0
522.73071,0.08020384645669291,896.8177690288713,0.00025370340306410486,25.0,30.0
524.33228,0.08057915551181102,898.3666404199474,0.00025370340306410486,25.0,30.0
525.93384,0.08095638385826771,898.858188976378,0.00025370340306410486,25.0,30.0
527.5354,0.08129869291338582,897.4526771653543,0.00025370340306410486,25.0,30.0
529.13696,0.08161084448818898,901.7658267716536,0.00025370340306410486,25.0,30.0
530.73853,0.0819893090551181,900.3155118110236,0.00025370340306410486,25.0,30.0
532.34009,0.08233582086614173,900.5648031496063,0.00025370340306410486,25.0,30.0
533.94165,0.08269851771653543,900.5683202099738,0.00025370340306410486,25.0,30.0
535.54321,0.08305510039370079,900.1286614173229,0.00025370340306410486,25.0,30.0
537.14478,0.08341861811023622,902.0837270341207,0.00025370340306410486,25.0,30.0
538.74634,0.0837863720472441,903.4100787401575,0.00025370340306410486,25.0,30.0
540.3479,0.08419253543307086,903.2374015748031,0.00025370340306410486,25.0,30.0
541.94946,0.08451641141732283,902.2497375328084,0.00025370340306410486,25.0,30.0
543.55103,0.08488241732283465,901.203779527559,0.00025370340306410486,25.0,30.0
545.15259,0.0852172657480315,904.2083202099737,0.00025370340306410486,25.0,30.0
546.75415,0.08556984842519684,904.4334908136483,0.00025370340306410486,25.0,30.0
548.35571,0.08598666338582678,904.2543307086613,0.00025370340306410486,25.0,30.0
549.95728,0.0863828464566929,902.774094488189,0.00025370340306410486,25.0,30.0
551.55884,0.08673256102362205,903.5852755905512,0.00025370340306410486,25.0,30.0
553.1604,0.0870769527559055,905.3882677165354,0.00025370340306410486,25.0,30.0
554.76196,0.08747050787401574,907.0919947506562,0.00025370340306410486,25.0,30.0
556.36353,0.0877878031496063,904.8020209973754,0.00025370340306410486,25.0,30.0
557.96509,0.08813187992125984,906.6778477690289,0.00025370340306410486,25.0,30.0
559.56665,0.08849090944881889,907.1007874015748,0.00025370340306410486,25.0,30.0
561.16821,0.08895522637795275,908.9134908136483,0.00025370340306410486,25.0,30.0
562.76978,0.08939901181102361,907.0328608923885,0.00025370340306410486,25.0,30.0
564.37134,0.08975927362204725,907.0228608923884,0.00025370340306410486,25.0,30.0
565.9729,0.09013384448818898,908.4951968503937,0.00025370340306410486,25.0,30.0
567.57446,0.09048904921259843,908.6660892388452,0.00025370340306410486,25.0,30.0
569.17603,0.09082988188976378,908.3245669291339,0.00025370340306410486,25.0,30.0
570.77759,0.0912087283464567,910.2895275590552,0.00025370340306410486,25.0,30.0
572.37915,0.09154512598425196,910.4702887139107,0.00025370340306410486,25.0,30.0
573.98071,0.09192842519685039,908.3867191601049,0.00025370340306410486,25.0,30.0
575.58228,0.09229452559055118,911.4874803149606,0.00025370340306410486,25.0,30.0
577.18384,0.09266857283464566,910.5422572178478,0.00025370340306410486,25.0,30.0
578.7854,0.09307688779527559,911.6258267716536,0.00025370340306410486,25.0,30.0
580.38696,0.09338824606299213,909.0362729658792,0.00025370340306410486,25.0,30.0
581.98853,0.09366371850393701,910.9554330708662,0.00025370340306410486,25.0,30.0
583.59009,0.09394147244094488,911.1977165354331,0.00025370340306410486,25.0,30.0
585.19165,0.09434192125984252,912.6773753280839,0.00025370340306410486,25.0,30.0
586.79321,0.09470888779527559,912.6222572178477,0.00025370340306410486,25.0,30.0
588.39478,0.09508396850393701,912.94656167979,0.00025370340306410486,25.0,30.0
589.99634,0.0954537125984252,912.6986351706037,0.00025370340306410486,25.0,30.0
591.5979,0.09584267913385827,914.1879002624671,0.00025370340306410486,25.0,30.0
593.19946,0.0962227874015748,914.2118635170604,0.00025370340306410486,25.0,30.0
594.80103,0.09658919094488189,912.6591601049869,0.00025370340306410486,25.0,30.0
596.40259,0.09689820866141732,914.4085826771653,0.00025370340306410486,25.0,30.0
598.00415,0.09728446062992126,913.7008923884515,0.00025370340306410486,25.0,30.0
599.60571,0.09767530511811023,915.8691338582678,0.00025370340306410486,25.0,30.0
601.20728,0.09800341141732283,915.373937007874,0.00025370340306410486,25.0,30.0
602.80884,0.09832762401574803,916.2200262467192,0.00025370340306410486,25.0,30.0
604.4104,0.09870393110236221,919.0562204724409,0.00025370340306410486,25.0,30.0
606.01196,0.09910260039370078,916.06687664042,0.00025370340306410486,25.0,30.0
607.61353,0.0994762224409449,917.1260367454069,0.00025370340306410486,25.0,30.0
609.21509,0.09986596259842519,919.7212335958005,0.00025370340306410486,25.0,30.0
610.81665,0.10021990748031497,918.9321784776903,0.00025370340306410486,25.0,30.0
612.41821,0.10058358858267717,917.1863517060367,0.00025370340306410486,25.0,30.0
614.01978,0.1008701377952756,918.9639632545932,0.00025370340306410486,25.0,30.0
615.62134,0.10124439173228347,919.4803149606298,0.00025370340306410486,25.0,30.0
617.2229,0.10162777362204724,919.0025984251968,0.00025370340306410486,25.0,30.0
618.82446,0.10199035236220473,918.2442257217847,0.00025370340306410486,25.0,30.0
620.42603,0.10232751771653543,920.0928346456693,0.00025370340306410486,25.0,30.0
622.02759,0.10269815748031495,918.3702099737533,0.00025370340306410486,25.0,30.0
623.62915,0.10305401377952755,920.953280839895,0.00025370340306410486,25.0,30.0
625.23071,0.10345427952755906,920.688188976378,0.00025370340306410486,25.0,30.0
626.83228,0.1037887342519685,919.4649868766404,0.00025370340306410486,25.0,30.0
628.43384,0.1041433464566929,920.1204461942257,0.00025370340306410486,25.0,30.0
630.0354,0.10451416338582678,920.8090551181102,0.00025370340306410486,25.0,30.0
631.63696,0.1048805905511811,923.3995538057743,0.00025370340306410486,25.0,30.0
633.23853,0.1053091338582677,922.9853543307087,0.00025370340306410486,25.0,30.0
634.84009,0.1056495374015748,920.8476902887139,0.00025370340306410486,25.0,30.0
636.44165,0.10599407086614174,921.6710498687663,0.00025370340306410486,25.0,30.0
638.04321,0.10633003937007873,922.9973490813649,0.00025370340306410486,25.0,30.0
639.64478,0.10672453346456694,924.1820209973753,0.00025370340306410486,25.0,30.0
641.24634,0.10714454724409449,925.8912073490814,0.00025370340306410486,25.0,30.0
642.8479,0.10752040748031497,922.3875065616799,0.00025370340306410486,25.0,30.0
644.44946,0.10785591929133857,925.4263254593176,0.00025370340306410486,25.0,30.0
646.05103,0.10824016929133858,925.052152230971,0.00025370340306410486,25.0,30.0
647.65259,0.10860587007874016,924.5195275590552,0.00025370340306410486,25.0,30.0
649.25415,0.10898155511811024,925.8036745406823,0.00025370340306410486,25.0,30.0
650.85571,0.10936504330708662,924.2374015748031,0.00025370340306410486,25.0,30.0
652.45728,0.10976523818897638,927.7536745406824,0.00025370340306410486,25.0,30.0
654.05884,0.11012047244094489,924.8806824146982,0.00025370340306410486,25.0,30.0
655.6604,0.11047047440944882,927.1129921259842,0.00025370340306410486,25.0,30.0
657.26196,0.11083845078740157,925.1234908136482,0.00025370340306410486,25.0,30.0
658.86353,0.11117252952755904,927.2735170603675,0.00025370340306410486,25.0,30.0
660.46509,0.11159205118110237,928.1740157480315,0.00025370340306410486,25.0,30.0
662.06665,0.11192924015748032,927.3939107611549,0.00025370340306410486,25.0,30.0
663.66821,0.11233735433070867,927.8615748031496,0.00025370340306410486,25.0,30.0
665.26978,0.11266065157480315,927.4485826771653,0.00025370340306410486,25.0,30.0
666.87134,0.11311206299212598,928.3863254593175,0.00025370340306410486,25.0,30.0
668.4729,0.11355226968503938,929.2838582677165,0.00025370340306410486,25.0,30.0
670.07446,0.11394854527559056,927.9896062992126,0.00025370340306410486,25.0,30.0
671.67603,0.11431024606299213,929.2142257217847,0.00025370340306410486,25.0,30.0
673.27759,0.11464417125984251,928.774435695538,0.00025370340306410486,25.0,30.0
674.87915,0.11499912401574804,930.307847769029,0.00025370340306410486,25.0,30.0
676.48071,0.11537675787401575,928.9220734908137,0.00025370340306410486,25.0,30.0
678.08228,0.11566307086614173,930.6179790026247,0.00025370340306410486,25.0,30.0
679.68384,0.11609684842519685,929.6921259842519,0.00025370340306410486,25.0,30.0
681.2854,0.1164783405511811,930.5142519685039,0.00025370340306410486,25.0,30.0
682.88696,0.11686390551181101,931.4935695538057,0.00025370340306410486,25.0,30.0
684.48853,0.11721069094488189,930.9100524934383,0.00025370340306410486,25.0,30.0
686.09009,0.11754918307086613,931.5208661417323,0.00025370340306410486,25.0,30.0
687.69165,0.11796112401574801,932.6099475065616,0.00025370340306410486,25.0,30.0
689.29321,0.11833164566929134,933.4595800524935,0.00025370340306410486,25.0,30.0
690.89478,0.11876872047244094,932.9627034120734,0.00025370340306410486,25.0,30.0
692.49634,0.1192147342519685,931.6258267716536,0.00025370340306410486,25.0,30.0
694.0979,0.11956736417322836,931.7287401574803,0.00025370340306410486,25.0,30.0
695.69946,0.11990227559055118,932.389186351706,0.00025370340306410486,25.0,30.0
697.30103,0.12030921850393701,934.2201837270342,0.00025370340306410486,25.0,30.0
698.90259,0.12068416338582677,934.4638845144357,0.00025370340306410486,25.0,30.0
700.50415,0.12103699409448818,934.3751181102363,0.00025370340306410486,25.0,30.0
702.10571,0.1214306062992126,935.2035958005249,0.00025370340306410486,25.0,30.0
703.70728,0.12177077559055119,933.665249343832,0.00025370340306410486,25.0,30.0
705.30884,0.12215086023622047,933.6490551181103,0.00025370340306410486,25.0,30.0
706.9104,0.12251964763779527,935.6785564304462,0.00025370340306410486,25.0,30.0
708.51196,0.1229465,935.3427296587927,0.00025370340306410486,25.0,30.0
710.11353,0.12329875393700787,936.0050393700787,0.00025370340306410486,25.0,30.0
711.71509,0.12373232086614172,936.3791338582677,0.00025370340306410486,25.0,30.0
713.31665,0.12417682086614173,935.2617322834645,0.00025370340306410486,25.0,30.0
714.91821,0.12455323228346457,934.8049081364828,0.00025370340306410486,25.0,30.0
716.51978,0.12495338188976378,935.3860892388451,0.00025370340306410486,25.0,30.0
718.12134,0.1253550216535433,935.2671128608923,0.00025370340306410486,25.0,30.0
719.7229,0.12576436811023622,939.2268503937007,0.00025370340306410486,25.0,30.0
721.32446,0.1261884311023622,936.4157217847769,0.00025370340306410486,25.0,30.0
722.92603,0.1265832283464567,937.3341732283465,0.00025370340306410486,25.0,30.0
724.52759,0.1269788838582677,936.1589501312336,0.00025370340306410486,25.0,30.0
726.12915,0.1273335905511811,938.1202887139108,0.00025370340306410486,25.0,30.0
727.73071,0.12776335433070865,939.5334908136483,0.00025370340306410486,25.0,30.0
729.33228,0.12821270078740157,939.0887139107612,0.00025370340306410486,25.0,30.0
730.93384,0.12862627165354332,939.2708923884514,0.00025370340306410486,25.0,30.0
732.5354,0.12911656692913384,939.1716797900262,0.00025370340306410486,25.0,30.0
734.13696,0.1295415905511811,938.2820209973753,0.00025370340306410486,25.0,30.0
735.73853,0.12990807677165356,937.8932545931759,0.00025370340306410486,25.0,30.0
737.34009,0.13031163976377952,937.1789763779527,0.00025370340306410486,25.0,30.0
738.94165,0.13071827755905513,940.1856692913385,0.00025370340306410486,25.0,30.0
740.54321,0.13112357677165354,939.3307874015748,0.00025370340306410486,25.0,30.0
742.14478,0.1315574940944882,941.5742519685039,0.00025370340306410486,25.0,30.0
743.74634,0.13194690748031496,939.811968503937,0.00025370340306410486,25.0,30.0
745.3479,0.13233695472440943,941.0507349081364,0.00025370340306410486,25.0,30.0
746.94946,0.13275534842519685,940.3884776902887,0.00025370340306410486,25.0,30.0
748.55103,0.13320247637795274,941.4217585301836,0.00025370340306410486,25.0,30.0
750.15259,0.13362524803149606,940.3641469816273,0.00025370340306410486,25.0,30.0
751.75415,0.13407608464566928,940.7805774278214,0.00025370340306410486,25.0,30.0
753.35571,0.13450568307086616,940.7292650918635,0.00025370340306410486,25.0,30.0
754.95728,0.1348847716535433,939.947874015748,0.00025370340306410486,25.0,30.0
756.55884,0.13523906692913384,940.4305249343832,0.00025370340306410486,25.0,30.0
758.1604,0.1356709783464567,942.4916272965878,0.00025370340306410486,25.0,30.0
759.76196,0.13608515944881888,941.3745406824147,0.00025370340306410486,25.0,30.0
761.36353,0.13651378543307086,941.5691338582677,0.00025370340306410486,25.0,30.0
762.96509,0.1369671437007874,943.8819947506562,0.00025370340306410486,25.0,30.0
764.56665,0.1373560531496063,942.5343569553805,0.00025370340306410486,25.0,30.0
766.16821,0.1377160157480315,943.0719160104986,0.00025370340306410486,25.0,30.0
767.76978,0.13810350393700788,944.0416797900263,0.00025370340306410486,25.0,30.0
769.37134,0.13854824015748032,943.5340419947506,0.00025370340306410486,25.0,30.0
770.9729,0.1389076279527559,943.7046981627296,0.00025370340306410486,25.0,30.0
772.57446,0.1392505531496063,943.5138582677165,0.00025370340306410486,25.0,30.0
774.17603,0.13968346062992126,944.8738845144358,0.00025370340306410486,25.0,30.0
775.77759,0.14014482283464566,944.4664566929133,0.00025370340306410486,25.0,30.0
777.37915,0.14059807677165354,944.5686089238845,0.00025370340306410486,25.0,30.0
778.98071,0.1409888149606299,943.9526771653543,0.00025370340306410486,25.0,30.0
780.58228,0.1413782401574803,945.4878215223097,0.00025370340306410486,25.0,30.0
782.18384,0.14175925196850395,946.7096850393701,0.00025370340306410486,25.0,30.0
783.7854,0.14220375196850393,947.059028871391,0.00025370340306410486,25.0,30.0
785.38696,0.1426339744094488,944.1241469816273,0.00025370340306410486,25.0,30.0
786.98853,0.1430535059055118,945.0135170603673,0.00025370340306410486,25.0,30.0
788.59009,0.14345018110236218,946.6689238845144,0.00025370340306410486,25.0,30.0
790.19165,0.1439127874015748,945.1907611548556,0.00025370340306410486,25.0,30.0
791.79321,0.14435225393700787,945.7073490813648,0.00025370340306410486,25.0,30.0
793.39478,0.1447605216535433,945.4755118110236,0.00025370340306410486,25.0,30.0
794.99634,0.1451437283464567,945.3108398950131,0.00025370340306410486,25.0,30.0
796.5979,0.14550321062992128,945.5965091863517,0.00025370340306410486,25.0,30.0
798.19946,0.14592154527559056,947.7587139107611,0.00025370340306410486,25.0,30.0
799.80103,0.14637782677165356,948.7114435695538,0.00025370340306410486,25.0,30.0
801.40259,0.14687676771653543,948.3336220472441,0.00025370340306410486,25.0,30.0
803.00415,0.14731143700787402,946.0984251968505,0.00025370340306410486,25.0,30.0
804.60571,0.14770276181102363,948.2876115485565,0.00025370340306410486,25.0,30.0
806.20728,0.14812927559055117,947.5991601049869,0.00025370340306410486,25.0,30.0
807.80884,0.14855588188976376,949.4892388451443,0.00025370340306410486,25.0,30.0
809.4104,0.14903382283464567,949.1948556430447,0.00025370340306410486,25.0,30.0
811.01196,0.14942980708661416,949.8219160104986,0.00025370340306410486,25.0,30.0
812.61353,0.1498891496062992,949.7063779527559,0.00025370340306410486,25.0,30.0
814.21509,0.15028888779527558,947.6949606299212,0.00025370340306410486,25.0,30.0
815.81665,0.15071135433070865,949.8617847769028,0.00025370340306410486,25.0,30.0
817.41821,0.15120948622047245,950.7187139107612,0.00025370340306410486,25.0,30.0
819.01978,0.15167422637795275,949.2546456692912,0.00025370340306410486,25.0,30.0
820.62134,0.1520768622047244,949.1167454068241,0.00025370340306410486,25.0,30.0
822.2229,0.15251953346456693,949.0637532808398,0.00025370340306410486,25.0,30.0
823.82446,0.1529894468503937,950.697375328084,0.00025370340306410486,25.0,30.0
825.42603,0.15340720866141733,948.6453805774279,0.00025370340306410486,25.0,30.0
827.02759,0.15382936811023623,948.9745406824146,0.00025370340306410486,25.0,30.0
828.62915,0.1542824468503937,950.8611023622047,0.00025370340306410486,25.0,30.0
830.23071,0.15474019291338584,948.9908923884514,0.00025370340306410486,25.0,30.0
831.83228,0.15517192716535433,949.4457217847769,0.00025370340306410486,25.0,30.0
833.43384,0.15561824803149607,950.6418897637795,0.00025370340306410486,25.0,30.0
835.0354,0.15613906102362204,952.073779527559,0.00025370340306410486,25.0,30.0
836.63696,0.1566058188976378,950.9005774278215,0.00025370340306410486,25.0,30.0
838.23853,0.15708552952755905,951.7382677165355,0.00025370340306410486,25.0,30.0
839.84009,0.15752381299212598,950.5194750656168,0.00025370340306410486,25.0,30.0
841.44165,0.15796082677165355,950.16,0.00025370340306410486,25.0,30.0
843.04321,0.158390062992126,949.8699212598425,0.00025370340306410486,25.0,30.0
844.64478,0.15882775787401573,951.4766929133858,0.00025370340306410486,25.0,30.0
846.24634,0.159250281496063,952.3570866141732,0.00025370340306410486,25.0,30.0
847.8479,0.1597650413385827,951.679501312336,0.00025370340306410486,25.0,30.0
849.44946,0.16025239173228345,951.9023622047245,0.00025370340306410486,25.0,30.0
851.05103,0.160769531496063,953.4800524934383,0.00025370340306410486,25.0,30.0
852.65259,0.1612074035433071,953.7348293963254,0.00025370340306410486,25.0,30.0
854.25415,0.1616500374015748,951.5621784776903,0.00025370340306410486,25.0,30.0
855.85571,0.16209444488188976,952.9679527559055,0.00025370340306410486,25.0,30.0
857.45728,0.16258418700787403,952.6632545931758,0.00025370340306410486,25.0,30.0
859.05884,0.16309204724409448,952.5638582677166,0.00025370340306410486,25.0,30.0
860.6604,0.16359479133858268,952.9530708661417,0.00025370340306410486,25.0,30.0
862.26196,0.16405372440944882,952.6978477690288,0.00025370340306410486,25.0,30.0
863.86353,0.16451722047244094,951.9276115485565,0.00025370340306410486,25.0,30.0
865.46509,0.16486764370078738,952.7548818897637,0.00025370340306410486,25.0,30.0
867.06665,0.16525031102362203,952.0341207349081,0.00025370340306410486,25.0,30.0
868.66821,0.16564322047244096,953.2960367454068,0.00025370340306410486,25.0,30.0
870.26978,0.16608519881889763,954.4745144356955,0.00025370340306410486,25.0,30.0
871.87134,0.1665987716535433,953.9299475065617,0.00025370340306410486,25.0,30.0
873.4729,0.16712588582677165,954.2909711286088,0.00025370340306410486,25.0,30.0
875.07446,0.1675529625984252,952.9069291338583,0.00025370340306410486,25.0,30.0
876.67603,0.16793308267716536,953.7451443569553,0.00025370340306410486,25.0,30.0
878.27759,0.1683461968503937,954.3082939632546,0.00025370340306410486,25.0,30.0
879.87915,0.16883679724409448,956.1905249343832,0.00025370340306410486,25.0,30.0
881.48071,0.16935957086614173,955.3876377952755,0.00025370340306410486,25.0,30.0
883.08228,0.16989246850393702,955.3639107611548,0.00025370340306410486,25.0,30.0
884.68384,0.17043339173228347,953.922782152231,0.00025370340306410486,25.0,30.0
886.2854,0.17093048031496064,955.2217322834646,0.00025370340306410486,25.0,30.0
887.88696,0.17141479133858267,954.7820734908137,0.00025370340306410486,25.0,30.0
889.48853,0.17188785039370078,954.8383989501311,0.00025370340306410486,25.0,30.0
891.09009,0.1724623897637795,954.2083202099737,0.00025370340306410486,25.0,30.0
892.69165,0.17291462401574803,954.8009711286089,0.00025370340306410486,25.0,30.0
894.29321,0.17340798031496063,956.3264566929133,0.00025370340306410486,25.0,30.0
895.89478,0.17392994291338582,955.0947244094488,0.00025370340306410486,25.0,30.0
897.49634,0.17448206102362204,956.125249343832,0.00025370340306410486,25.0,30.0
899.0979,0.1749680157480315,955.5064829396325,0.00025370340306410486,25.0,30.0
900.69946,0.1754353838582677,953.4634120734908,0.00025370340306410486,25.0,30.0
902.30103,0.1759560905511811,956.6165879265092,0.00025370340306410486,25.0,30.0
903.90259,0.1764930374015748,955.9083202099737,0.00025370340306410486,25.0,30.0
905.50415,0.1769568503937008,956.0644356955381,0.00025370340306410486,25.0,30.0
907.10571,0.17747333464566928,957.1210761154856,0.00025370340306410486,25.0,30.0
908.70728,0.1780014566929134,956.929501312336,0.00025370340306410486,25.0,30.0
910.30884,0.1785384625984252,955.1310498687665,0.00025370340306410486,25.0,30.0
911.9104,0.17904455118110235,956.0990813648294,0.00025370340306410486,25.0,30.0
913.51196,0.17948942716535432,954.2307349081365,0.00025370340306410486,25.0,30.0
915.11353,0.17992733267716535,956.4857480314961,0.00025370340306410486,25.0,30.0
916.71509,0.18037751181102363,955.4558005249344,0.00025370340306410486,25.0,30.0
918.31665,0.18087538582677165,957.1633858267717,0.00025370340306410486,25.0,30.0
919.91821,0.18137538582677165,956.240656167979,0.00025370340306410486,25.0,30.0
921.51978,0.18187751968503937,956.9981102362204,0.00025370340306410486,25.0,30.0
923.12134,0.18231942716535432,957.0354855643044,0.00025370340306410486,25.0,30.0
924.7229,0.18281696062992125,956.2535170603674,0.00025370340306410486,25.0,30.0
926.32446,0.18328844881889764,956.970183727034,0.00025370340306410486,25.0,30.0
927.92603,0.18382535826771654,957.6700524934383,0.00025370340306410486,25.0,30.0
929.52759,0.18435058464566928,957.118530183727,0.00025370340306410486,25.0,30.0
931.12915,0.18485827952755904,956.755905511811,0.00025370340306410486,25.0,30.0
932.73071,0.18533503543307087,956.7787664041995,0.00025370340306410486,25.0,30.0
934.33228,0.18581478149606298,956.633779527559,0.00025370340306410486,25.0,30.0
935.93384,0.18633477362204726,957.0698162729659,0.00025370340306410486,25.0,30.0
937.5354,0.18681273622047245,957.3308923884514,0.00025370340306410486,25.0,30.0
939.13696,0.18727301771653543,957.2085039370078,0.00025370340306410486,25.0,30.0
940.73853,0.18775857283464567,957.7739895013123,0.00025370340306410486,25.0,30.0
942.34009,0.18822909842519686,956.3094750656168,0.00025370340306410486,25.0,30.0
943.94165,0.18870791732283465,957.7899475065617,0.00025370340306410486,25.0,30.0
945.54321,0.18927182677165355,957.1383989501312,0.00025370340306410486,25.0,30.0
947.14478,0.18979931692913385,956.657532808399,0.00025370340306410486,25.0,30.0
948.74634,0.19035645669291337,956.4395538057743,0.00025370340306410486,25.0,30.0
950.3479,0.19087188385826773,955.7235958005249,0.00025370340306410486,25.0,30.0
951.94946,0.19134122244094487,956.2087401574803,0.00025370340306410486,25.0,30.0
953.55103,0.19182523031496063,958.5843832020996,0.00025370340306410486,25.0,30.0
955.15259,0.19239491141732284,958.3375065616798,0.00025370340306410486,25.0,30.0
956.75415,0.1929278208661417,957.2591076115485,0.00025370340306410486,25.0,30.0
958.35571,0.1934908031496063,958.9265879265091,0.00025370340306410486,25.0,30.0
959.95728,0.19410246653543306,959.3733333333333,0.00025370340306410486,25.0,30.0
961.55884,0.19462918110236221,956.6288976377953,0.00025370340306410486,25.0,30.0
963.1604,0.195134155511811,958.4555905511811,0.00025370340306410486,25.0,30.0
964.76196,0.19568527559055118,956.2260892388451,0.00025370340306410486,25.0,30.0
966.36353,0.1962183622047244,957.6912598425197,0.00025370340306410486,25.0,30.0
967.96509,0.19677582874015748,958.2285039370079,0.00025370340306410486,25.0,30.0
969.56665,0.19728687007874018,957.7730971128608,0.00025370340306410486,25.0,30.0
971.16821,0.19782161417322836,958.1633858267717,0.00025370340306410486,25.0,30.0
972.76978,0.19834541338582679,957.6508398950131,0.00025370340306410486,25.0,30.0
973.27026,0.1985292125984252,960.1120472440945,0.00025370340306410486,25.0,30.0