File: datasets/am_bench_2022/csv/30-XY.18-2.csv
Time(s),Strain(%),Stress(MPa),SR(s-1),Temp(C),Angle(deg)
17.750488,4.11218248031496e-06,17.64582624671916,0.00025370340306410486,25.0,30.0
19.652344,2.0771875984251968e-05,23.471543832020995,0.00025370340306410486,25.0,30.0
21.153809,4.510429133858268e-05,28.371603674540683,0.00025370340306410486,25.0,30.0
22.655273,5.3397537401574796e-05,33.14481364829396,0.00025370340306410486,25.0,30.0
24.156738,5.871179330708661e-05,37.60836482939632,0.00025370340306410486,25.0,30.0
25.658203,9.337728543307087e-05,42.239312335958004,0.00025370340306410486,25.0,30.0
27.159668,9.995719685039368e-05,48.704425196850394,0.00025370340306410486,25.0,30.0
28.661133,0.00011432032677165354,55.366808398950134,0.00025370340306410486,25.0,30.0
30.162598,0.00015915797440944882,63.267257217847764,0.00025370340306410486,25.0,30.0
31.664063,0.0001707631496062992,69.74208661417323,0.00025370340306410486,25.0,30.0
33.165527,0.000193846062992126,78.9205564304462,0.00025370340306410486,25.0,30.0
34.666992,0.00022364297244094485,85.7434278215223,0.00025370340306410486,25.0,30.0
36.168457,0.00023471816929133857,92.61389763779528,0.00025370340306410486,25.0,30.0
37.669922,0.0002815595472440945,101.65291601049869,0.00025370340306410486,25.0,30.0
39.171387,0.0002823694488188976,107.76438582677166,0.00025370340306410486,25.0,30.0
40.672852,0.00032731336614173225,118.46917322834645,0.00025370340306410486,25.0,30.0
42.174316,0.00034673423228346456,130.10902624671917,0.00025370340306410486,25.0,30.0
43.675781,0.00037739830708661415,137.25701312335957,0.00025370340306410486,25.0,30.0
45.177246,0.0004186461417322834,145.19938582677165,0.00025370340306410486,25.0,30.0
46.678711,0.00044981899606299206,156.87006036745407,0.00025370340306410486,25.0,30.0
48.180176,0.0004965305118110236,168.37786089238844,0.00025370340306410486,25.0,30.0
49.681641,0.000503231220472441,176.34519160104986,0.00025370340306410486,25.0,30.0
51.183105,0.0005288657874015748,185.58793438320208,0.00025370340306410486,25.0,30.0
52.68457,0.0005646259055118111,199.9605748031496,0.00025370340306410486,25.0,30.0
54.186035,0.0005962595669291339,208.35226771653544,0.00025370340306410486,25.0,30.0
55.6875,0.0006616867716535432,221.18810498687662,0.00025370340306410486,25.0,30.0
57.188965,0.0006849166732283465,232.3315564304462,0.00025370340306410486,25.0,30.0
58.69043,0.000713938188976378,241.19866666666664,0.00025370340306410486,25.0,30.0
60.191895,0.0007591089763779528,250.3063937007874,0.00025370340306410486,25.0,30.0
61.693359,0.0007914425984251968,261.5007375328084,0.00025370340306410486,25.0,30.0
63.194824,0.0008352104527559055,273.5816535433071,0.00025370340306410486,25.0,30.0
64.696289,0.0008540601968503936,285.70931758530185,0.00025370340306410486,25.0,30.0
66.197754,0.0008825792125984251,295.2470341207349,0.00025370340306410486,25.0,30.0
67.699219,0.000925036338582677,307.00687664042,0.00025370340306410486,25.0,30.0
69.200684,0.0009615694685039369,318.25351706036747,0.00025370340306410486,25.0,30.0
70.702148,0.0010090392519685038,328.39784776902883,0.00025370340306410486,25.0,30.0
72.203613,0.0010469055708661418,339.7296062992126,0.00025370340306410486,25.0,30.0
73.705078,0.0010738558070866142,352.4285826771653,0.00025370340306410486,25.0,30.0
75.206543,0.0011164638188976377,362.144750656168,0.00025370340306410486,25.0,30.0
76.708008,0.001161512598425197,374.7428083989501,0.00025370340306410486,25.0,30.0
78.209473,0.0011920530118110237,383.77522309711287,0.00025370340306410486,25.0,30.0
79.710938,0.0012263387992125984,394.93889763779526,0.00025370340306410486,25.0,30.0
81.212402,0.0012442843503937008,404.88690288713906,0.00025370340306410486,25.0,30.0
82.713867,0.001316856850393701,417.0200524934383,0.00025370340306410486,25.0,30.0
84.215332,0.0013382613188976378,427.8368241469816,0.00025370340306410486,25.0,30.0
85.716797,0.0013798465157480314,438.54881889763783,0.00025370340306410486,25.0,30.0
87.218262,0.0014191139566929133,450.89771653543306,0.00025370340306410486,25.0,30.0
88.719727,0.0014403377559055117,459.1434908136483,0.00025370340306410486,25.0,30.0
90.221191,0.0014656405708661417,470.45740157480316,0.00025370340306410486,25.0,30.0
91.722656,0.0015180613976377953,479.8012335958005,0.00025370340306410486,25.0,30.0
93.224121,0.001544367125984252,488.61228346456693,0.00025370340306410486,25.0,30.0
94.725586,0.0015749713385826772,497.0476902887139,0.00025370340306410486,25.0,30.0
96.227051,0.001614440708661417,509.2451968503937,0.00025370340306410486,25.0,30.0
97.728516,0.0016267525000000001,513.7400262467191,0.00025370340306410486,25.0,30.0
99.22998,0.0016793185236220472,522.9669028871391,0.00025370340306410486,25.0,30.0
100.73145,0.0016922200787401573,531.6035170603675,0.00025370340306410486,25.0,30.0
102.23291,0.0017378004330708661,538.6598950131233,0.00025370340306410486,25.0,30.0
103.73438,0.0017642208464566927,548.9098950131233,0.00025370340306410486,25.0,30.0
105.23584,0.0017991027362204723,555.0171128608924,0.00025370340306410486,25.0,30.0
106.7373,0.0018103875,559.4494488188976,0.00025370340306410486,25.0,30.0
108.23877,0.0018605135629921258,568.0446719160104,0.00025370340306410486,25.0,30.0
109.74023,0.001880260157480315,572.5050131233595,0.00025370340306410486,25.0,30.0
111.2417,0.0019022252559055119,580.6504199475065,0.00025370340306410486,25.0,30.0
112.74316,0.0019315380905511811,586.95,0.00025370340306410486,25.0,30.0
114.24463,0.001962432874015748,591.65,0.00025370340306410486,25.0,30.0
115.74609,0.002013471062992126,600.4914173228346,0.00025370340306410486,25.0,30.0
117.24756,0.002035105118110236,605.7894750656168,0.00025370340306410486,25.0,30.0
118.74902,0.0020389633858267715,608.643595800525,0.00025370340306410486,25.0,30.0
120.25049,0.0020865700787401575,616.6259842519685,0.00025370340306410486,25.0,30.0
121.75195,0.0021151659448818898,617.6758530183727,0.00025370340306410486,25.0,30.0
123.25342,0.0021605076771653545,625.9986614173229,0.00025370340306410486,25.0,30.0
124.75488,0.002172445275590551,630.0411548556431,0.00025370340306410486,25.0,30.0
126.25635,0.0022205933070866143,635.907060367454,0.00025370340306410486,25.0,30.0
127.75781,0.0022534616141732283,639.1000524934383,0.00025370340306410486,25.0,30.0
129.25928,0.0022884080708661415,644.845249343832,0.00025370340306410486,25.0,30.0
130.76074,0.0023254001968503937,649.2752755905512,0.00025370340306410486,25.0,30.0
132.26221,0.002349773818897638,650.8041207349082,0.00025370340306410486,25.0,30.0
133.76367,0.002388121062992126,655.8729658792652,0.00025370340306410486,25.0,30.0
135.26514,0.0024148580708661417,658.501154855643,0.00025370340306410486,25.0,30.0
136.7666,0.0024572515748031497,663.8805774278215,0.00025370340306410486,25.0,30.0
138.26807,0.0025100127952755904,670.7191338582677,0.00025370340306410486,25.0,30.0
139.76953,0.0025368736220472443,670.8730708661418,0.00025370340306410486,25.0,30.0
141.271,0.002589812992125984,674.6863254593176,0.00025370340306410486,25.0,30.0
142.77246,0.00262900531496063,678.3113385826772,0.00025370340306410486,25.0,30.0
144.27393,0.002667448622047244,680.4281364829396,0.00025370340306410486,25.0,30.0
145.77539,0.0027087232283464564,686.078346456693,0.00025370340306410486,25.0,30.0
147.27686,0.0027586151574803147,688.2176115485564,0.00025370340306410486,25.0,30.0
148.77832,0.0028256356299212596,690.7367454068241,0.00025370340306410486,25.0,30.0
150.27979,0.002872962598425197,694.8110236220473,0.00025370340306410486,25.0,30.0
151.78125,0.002935665748031496,699.4177165354331,0.00025370340306410486,25.0,30.0
153.28271,0.003002751377952756,702.8110761154855,0.00025370340306410486,25.0,30.0
154.78418,0.00307785531496063,705.1687926509186,0.00025370340306410486,25.0,30.0
156.28564,0.0031514143700787397,708.9180577427821,0.00025370340306410486,25.0,30.0
157.78711,0.003221199212598425,712.5683202099738,0.00025370340306410486,25.0,30.0
159.28857,0.0033050009842519683,713.3386614173228,0.00025370340306410486,25.0,30.0
160.79004,0.0034080539370078735,717.6274015748032,0.00025370340306410486,25.0,30.0
162.2915,0.003506913188976378,720.600656167979,0.00025370340306410486,25.0,30.0
163.79297,0.0036001228346456693,722.2658267716536,0.00025370340306410486,25.0,30.0
165.29443,0.0037289055118110235,725.7677165354331,0.00025370340306410486,25.0,30.0
166.7959,0.0038163068897637794,728.2681627296588,0.00025370340306410486,25.0,30.0
168.29736,0.003939031692913386,730.9339632545932,0.00025370340306410486,25.0,30.0
169.79883,0.004056220078740157,732.369842519685,0.00025370340306410486,25.0,30.0
171.30029,0.0042079844488188975,736.084435695538,0.00025370340306410486,25.0,30.0
172.80176,0.004367209448818897,738.8629658792651,0.00025370340306410486,25.0,30.0
174.30322,0.004508493307086614,740.5160104986877,0.00025370340306410486,25.0,30.0
175.80469,0.004678580708661418,742.879028871391,0.00025370340306410486,25.0,30.0
177.30615,0.0048613413385826774,745.4207349081364,0.00025370340306410486,25.0,30.0
178.80762,0.005039976771653543,747.5410236220472,0.00025370340306410486,25.0,30.0
180.30908,0.0052344328740157485,750.1101574803149,0.00025370340306410486,25.0,30.0
181.81055,0.005419965157480315,749.9514173228346,0.00025370340306410486,25.0,30.0
183.31201,0.005640354921259842,752.139343832021,0.00025370340306410486,25.0,30.0
184.81348,0.005824471259842519,754.51,0.00025370340306410486,25.0,30.0
186.31494,0.006050964173228346,755.520341207349,0.00025370340306410486,25.0,30.0
187.81641,0.006301182677165354,758.0967454068241,0.00025370340306410486,25.0,30.0
189.31787,0.00655114153543307,759.372125984252,0.00025370340306410486,25.0,30.0
190.81934,0.006837867913385827,762.88,0.00025370340306410486,25.0,30.0
192.3208,0.007140766929133858,763.6032545931758,0.00025370340306410486,25.0,30.0
193.82227,0.007389204330708662,762.8201312335958,0.00025370340306410486,25.0,30.0
195.32373,0.007640768307086613,766.8883727034121,0.00025370340306410486,25.0,30.0
196.8252,0.007864892322834644,765.3821522309712,0.00025370340306410486,25.0,30.0
198.32666,0.008146518307086613,768.8422047244094,0.00025370340306410486,25.0,30.0
199.82813,0.008514833661417323,769.8952230971129,0.00025370340306410486,25.0,30.0
201.32959,0.008853416338582677,772.8371391076116,0.00025370340306410486,25.0,30.0
202.83105,0.009181865354330708,773.7553280839894,0.00025370340306410486,25.0,30.0
204.33252,0.009510823031496063,773.9254593175853,0.00025370340306410486,25.0,30.0
205.83398,0.009824221850393701,775.2969291338583,0.00025370340306410486,25.0,30.0
207.33545,0.010101182480314962,775.6734120734908,0.00025370340306410486,25.0,30.0
208.83691,0.010477626181102363,777.9010498687663,0.00025370340306410486,25.0,30.0
210.33838,0.010798113976377952,776.7920209973753,0.00025370340306410486,25.0,30.0
211.83984,0.011155878937007875,779.8068766404199,0.00025370340306410486,25.0,30.0
213.34131,0.011511525393700787,781.3738057742783,0.00025370340306410486,25.0,30.0
214.84277,0.011856842322834646,780.2228871391076,0.00025370340306410486,25.0,30.0
216.34424,0.012135389763779527,781.9710761154855,0.00025370340306410486,25.0,30.0
217.8457,0.012458891732283463,783.6260367454069,0.00025370340306410486,25.0,30.0
219.34717,0.012813768110236221,784.9994488188977,0.00025370340306410486,25.0,30.0
220.84863,0.013131626377952756,784.3159317585302,0.00025370340306410486,25.0,30.0
222.3501,0.013510005708661418,786.8454330708662,0.00025370340306410486,25.0,30.0
223.85156,0.013910541929133859,786.7517585301837,0.00025370340306410486,25.0,30.0
225.35303,0.014212981299212599,786.8485039370079,0.00025370340306410486,25.0,30.0
226.85449,0.014589262007874014,789.658687664042,0.00025370340306410486,25.0,30.0
228.35596,0.014928126968503938,789.6986876640419,0.00025370340306410486,25.0,30.0
229.85742,0.01533066220472441,791.9443307086614,0.00025370340306410486,25.0,30.0
231.35889,0.01573612775590551,792.6423884514436,0.00025370340306410486,25.0,30.0
232.86035,0.0161003468503937,792.1977427821522,0.00025370340306410486,25.0,30.0
234.36182,0.01651849744094488,793.8960892388451,0.00025370340306410486,25.0,30.0
235.86328,0.016895573031496063,794.0817322834646,0.00025370340306410486,25.0,30.0
237.36475,0.01727399665354331,794.3379265091863,0.00025370340306410486,25.0,30.0
238.86621,0.01765437224409449,796.3723622047244,0.00025370340306410486,25.0,30.0
240.36768,0.017994492716535433,795.9746981627296,0.00025370340306410486,25.0,30.0
241.86914,0.01834739783464567,798.240341207349,0.00025370340306410486,25.0,30.0
243.37061,0.018742544094488188,799.2639895013123,0.00025370340306410486,25.0,30.0
244.87207,0.019134113188976377,799.4480839895012,0.00025370340306410486,25.0,30.0
246.37354,0.019522732874015746,799.803779527559,0.00025370340306410486,25.0,30.0
247.875,0.019879498031496065,799.3113385826772,0.00025370340306410486,25.0,30.0
249.37646,0.02028237598425197,800.6669291338583,0.00025370340306410486,25.0,30.0
250.87793,0.0206798562992126,802.8526771653543,0.00025370340306410486,25.0,30.0
252.37939,0.02099934645669291,802.5607086614173,0.00025370340306410486,25.0,30.0
253.88086,0.021359147637795277,804.004278215223,0.00025370340306410486,25.0,30.0
255.38232,0.021715872047244095,805.4144881889763,0.00025370340306410486,25.0,30.0
256.88379,0.022118557086614175,804.4904461942257,0.00025370340306410486,25.0,30.0
258.38525,0.022524938976377952,804.7353543307087,0.00025370340306410486,25.0,30.0
259.88672,0.022905332677165352,805.7956167979002,0.00025370340306410486,25.0,30.0
261.38818,0.0232696437007874,806.2045144356955,0.00025370340306410486,25.0,30.0
262.88965,0.023626212598425195,808.8114173228346,0.00025370340306410486,25.0,30.0
264.39111,0.02401034842519685,810.2064829396326,0.00025370340306410486,25.0,30.0
265.89258,0.024390779527559053,808.4229133858267,0.00025370340306410486,25.0,30.0
267.39404,0.024805470472440947,808.4291863517061,0.00025370340306410486,25.0,30.0
268.89551,0.025190340551181103,812.9871391076116,0.00025370340306410486,25.0,30.0
270.39697,0.025615822834645665,811.4880052493438,0.00025370340306410486,25.0,30.0
271.89844,0.025985836614173224,810.8433595800525,0.00025370340306410486,25.0,30.0
273.3999,0.026415984251968505,813.0150656167979,0.00025370340306410486,25.0,30.0
274.90137,0.026779724409448816,813.2525459317585,0.00025370340306410486,25.0,30.0
276.40283,0.027144551181102358,814.5523884514436,0.00025370340306410486,25.0,30.0
277.9043,0.027571935039370075,815.1333858267716,0.00025370340306410486,25.0,30.0
279.40576,0.02793563188976378,813.2733070866142,0.00025370340306410486,25.0,30.0
280.90723,0.028313375984251966,816.715249343832,0.00025370340306410486,25.0,30.0
282.40869,0.028664950787401573,817.6887926509186,0.00025370340306410486,25.0,30.0
283.91016,0.029044527559055115,817.7442782152231,0.00025370340306410486,25.0,30.0
285.41162,0.02947598031496063,818.6508136482939,0.00025370340306410486,25.0,30.0
286.91309,0.02982171062992126,818.6359317585302,0.00025370340306410486,25.0,30.0
288.41455,0.0301510531496063,817.2251181102362,0.00025370340306410486,25.0,30.0
289.91602,0.030431722440944883,818.4733595800525,0.00025370340306410486,25.0,30.0
291.41748,0.030849659448818897,821.3717847769029,0.00025370340306410486,25.0,30.0
292.91895,0.031244858267716537,821.0561417322834,0.00025370340306410486,25.0,30.0
294.42041,0.0315941811023622,822.0592388451444,0.00025370340306410486,25.0,30.0
295.92188,0.03195847047244094,821.21,0.00025370340306410486,25.0,30.0
297.42334,0.03236119291338583,821.9575328083989,0.00025370340306410486,25.0,30.0
298.9248,0.032720055118110235,822.3338057742783,0.00025370340306410486,25.0,30.0
300.42627,0.03309682283464567,823.7695013123359,0.00025370340306410486,25.0,30.0
301.92773,0.033468271653543304,823.2206036745406,0.00025370340306410486,25.0,30.0
303.4292,0.03387466338582677,825.9822572178477,0.00025370340306410486,25.0,30.0
304.93066,0.034255931102362205,825.3561417322835,0.00025370340306410486,25.0,30.0
306.43213,0.03462572244094488,825.1876902887138,0.00025370340306410486,25.0,30.0
307.93359,0.0349828937007874,825.7666404199475,0.00025370340306410486,25.0,30.0
309.43506,0.03536934645669291,825.9528608923885,0.00025370340306410486,25.0,30.0
310.93652,0.03572220472440945,827.669002624672,0.00025370340306410486,25.0,30.0
312.43799,0.03608875590551181,827.8833595800525,0.00025370340306410486,25.0,30.0
313.93945,0.03649619094488189,828.3308136482939,0.00025370340306410486,25.0,30.0
315.44092,0.03685971456692914,827.0507874015749,0.00025370340306410486,25.0,30.0
316.94238,0.03720622244094488,829.046719160105,0.00025370340306410486,25.0,30.0
318.44385,0.03754755511811023,829.2934908136483,0.00025370340306410486,25.0,30.0
319.94531,0.03792719881889764,829.8850656167979,0.00025370340306410486,25.0,30.0
321.44678,0.038336354330708665,832.5253543307086,0.00025370340306410486,25.0,30.0
322.94824,0.03867845472440945,831.2936482939632,0.00025370340306410486,25.0,30.0
324.44971,0.03904782086614173,831.7053543307086,0.00025370340306410486,25.0,30.0
325.95117,0.039360614173228343,832.4566141732283,0.00025370340306410486,25.0,30.0
327.45264,0.039722204724409446,834.0300524934383,0.00025370340306410486,25.0,30.0
328.9541,0.040082444881889764,834.2488976377953,0.00025370340306410486,25.0,30.0
330.45557,0.0404259842519685,833.4534908136483,0.00025370340306410486,25.0,30.0
331.95703,0.040800470472440946,834.3796062992126,0.00025370340306410486,25.0,30.0
333.4585,0.04116890157480315,835.6192913385827,0.00025370340306410486,25.0,30.0
334.95996,0.04159089763779528,836.8005249343832,0.00025370340306410486,25.0,30.0
336.46143,0.04198082480314961,836.8850918635171,0.00025370340306410486,25.0,30.0
337.96289,0.04235505511811023,834.6764829396326,0.00025370340306410486,25.0,30.0
339.46436,0.04270492913385827,836.7267716535433,0.00025370340306410486,25.0,30.0
340.96582,0.043080450787401574,837.132624671916,0.00025370340306410486,25.0,30.0
342.46729,0.04344661811023622,838.3403412073491,0.00025370340306410486,25.0,30.0
343.96875,0.04380104724409449,839.8931496062993,0.00025370340306410486,25.0,30.0
345.47021,0.044192667322834646,840.2787926509186,0.00025370340306410486,25.0,30.0
346.97168,0.04458435039370079,839.8578477690289,0.00025370340306410486,25.0,30.0
348.47314,0.04492705118110236,839.4355643044619,0.00025370340306410486,25.0,30.0
349.97461,0.04529033464566929,842.9008923884514,0.00025370340306410486,25.0,30.0
351.47607,0.04564385039370079,840.2756955380578,0.00025370340306410486,25.0,30.0
352.97754,0.04602954921259843,842.9810498687664,0.00025370340306410486,25.0,30.0
354.479,0.046388358267716534,842.7693438320209,0.00025370340306410486,25.0,30.0
355.98047,0.04678489960629921,844.8916272965879,0.00025370340306410486,25.0,30.0
357.48193,0.04718371062992126,844.538687664042,0.00025370340306410486,25.0,30.0
358.9834,0.04750567913385827,843.1015748031497,0.00025370340306410486,25.0,30.0
360.48486,0.04789742519685039,845.1116797900263,0.00025370340306410486,25.0,30.0
361.98633,0.04824827362204724,844.5941207349082,0.00025370340306410486,25.0,30.0
363.48779,0.04860363976377953,845.3699737532808,0.00025370340306410486,25.0,30.0
364.98926,0.04901746456692913,846.5744094488189,0.00025370340306410486,25.0,30.0
366.49072,0.04938538779527559,846.7059580052494,0.00025370340306410486,25.0,30.0
367.99219,0.04968610826771653,846.2833595800524,0.00025370340306410486,25.0,30.0
369.49365,0.05007385039370078,848.116719160105,0.00025370340306410486,25.0,30.0
370.99512,0.050416173228346454,847.5200262467192,0.00025370340306410486,25.0,30.0
372.49658,0.05075269291338583,848.5901312335958,0.00025370340306410486,25.0,30.0
373.99805,0.051129773622047237,848.742125984252,0.00025370340306410486,25.0,30.0
375.49951,0.051482637795275586,849.1625459317585,0.00025370340306410486,25.0,30.0
377.00098,0.05186710039370079,851.3659580052494,0.00025370340306410486,25.0,30.0
378.50244,0.05221660236220472,849.6423884514435,0.00025370340306410486,25.0,30.0
380.00391,0.05261336023622048,850.5480052493439,0.00025370340306410486,25.0,30.0
381.50537,0.053002309055118116,853.2029921259842,0.00025370340306410486,25.0,30.0
383.00684,0.05336508267716535,849.784120734908,0.00025370340306410486,25.0,30.0
384.5083,0.053694145669291336,853.4608398950131,0.00025370340306410486,25.0,30.0
386.00977,0.05410458464566929,852.7616010498687,0.00025370340306410486,25.0,30.0
387.51123,0.054450919291338586,851.7075853018373,0.00025370340306410486,25.0,30.0
389.0127,0.05482335433070867,852.9396325459317,0.00025370340306410486,25.0,30.0
390.51416,0.0551807125984252,854.6034908136482,0.00025370340306410486,25.0,30.0
392.01563,0.05548471456692913,851.9640157480314,0.00025370340306410486,25.0,30.0
393.51709,0.055859925196850395,856.3458530183727,0.00025370340306410486,25.0,30.0
395.01855,0.056223700787401576,855.7846719160106,0.00025370340306410486,25.0,30.0
396.52002,0.05653683070866142,855.6645669291338,0.00025370340306410486,25.0,30.0
398.02148,0.05688793503937008,856.8884251968504,0.00025370340306410486,25.0,30.0
399.52295,0.05728066141732283,858.4058792650919,0.00025370340306410486,25.0,30.0
401.02441,0.057659620078740155,856.6343569553806,0.00025370340306410486,25.0,30.0
402.52588,0.058020610236220474,857.7005511811024,0.00025370340306410486,25.0,30.0
404.02734,0.05837150984251969,856.9736482939632,0.00025370340306410486,25.0,30.0
405.52881,0.05877277362204724,858.3395538057744,0.00025370340306410486,25.0,30.0
407.03027,0.05912072637795275,858.8705774278214,0.00025370340306410486,25.0,30.0
408.53174,0.059496334645669294,860.2143569553806,0.00025370340306410486,25.0,30.0
410.0332,0.059909572834645666,861.9583989501311,0.00025370340306410486,25.0,30.0
411.53467,0.06030151968503936,859.6903412073491,0.00025370340306410486,25.0,30.0
413.03613,0.06064056299212599,860.5905774278216,0.00025370340306410486,25.0,30.0
414.5376,0.06098772440944882,859.555249343832,0.00025370340306410486,25.0,30.0
416.03906,0.06133091535433071,860.6769028871391,0.00025370340306410486,25.0,30.0
417.54053,0.06171691929133858,863.7360892388451,0.00025370340306410486,25.0,30.0
419.04199,0.06207673622047244,860.2780577427822,0.00025370340306410486,25.0,30.0
420.54346,0.062397844488188976,863.2296062992125,0.00025370340306410486,25.0,30.0
422.04492,0.06276408464566928,863.7524146981626,0.00025370340306410486,25.0,30.0
423.54639,0.06309940748031495,864.3561154855644,0.00025370340306410486,25.0,30.0
425.04785,0.06348058267716536,864.2241732283464,0.00025370340306410486,25.0,30.0
426.54932,0.06379593700787402,863.5214698162729,0.00025370340306410486,25.0,30.0
428.05078,0.06413368307086614,865.2104199475066,0.00025370340306410486,25.0,30.0
429.55225,0.06449555118110237,865.2264304461943,0.00025370340306410486,25.0,30.0
431.05371,0.0648457342519685,866.166220472441,0.00025370340306410486,25.0,30.0
432.55518,0.06522090354330709,865.5708661417323,0.00025370340306410486,25.0,30.0
434.05664,0.06557536417322835,867.8082414698163,0.00025370340306410486,25.0,30.0
435.55811,0.06594933661417322,866.6467979002625,0.00025370340306410486,25.0,30.0
437.05957,0.06627096062992126,866.4194488188976,0.00025370340306410486,25.0,30.0
438.56104,0.06660178937007874,867.1593175853018,0.00025370340306410486,25.0,30.0
440.0625,0.06696195275590551,868.7744094488188,0.00025370340306410486,25.0,30.0
441.56396,0.06727084645669291,868.8798162729659,0.00025370340306410486,25.0,30.0
443.06543,0.067662218503937,868.5045669291338,0.00025370340306410486,25.0,30.0
444.56689,0.06803990551181102,868.9609448818898,0.00025370340306410486,25.0,30.0
446.06836,0.06843059645669292,870.0461154855643,0.00025370340306410486,25.0,30.0
447.56982,0.06875026771653543,870.8386614173229,0.00025370340306410486,25.0,30.0
449.07129,0.06912242125984253,872.3625721784776,0.00025370340306410486,25.0,30.0
450.57275,0.06951560039370079,873.131128608924,0.00025370340306410486,25.0,30.0
452.07422,0.06988133070866141,871.7992650918635,0.00025370340306410486,25.0,30.0
453.57568,0.07024860826771653,872.9527559055117,0.00025370340306410486,25.0,30.0
455.07715,0.07063101181102362,873.185406824147,0.00025370340306410486,25.0,30.0
456.57861,0.0709823562992126,872.5141207349081,0.00025370340306410486,25.0,30.0
458.08008,0.07136718700787402,873.6951706036746,0.00025370340306410486,25.0,30.0
459.58154,0.0717168188976378,873.5805774278215,0.00025370340306410486,25.0,30.0
461.08301,0.07209832480314961,873.8026246719161,0.00025370340306410486,25.0,30.0
462.58447,0.07243555905511811,874.2573228346456,0.00025370340306410486,25.0,30.0
464.08594,0.07284520078740157,875.544278215223,0.00025370340306410486,25.0,30.0
465.5874,0.07325729330708661,875.8500787401575,0.00025370340306410486,25.0,30.0
467.08887,0.07359438385826772,875.6684776902887,0.00025370340306410486,25.0,30.0
468.59033,0.07393936220472441,876.1627034120735,0.00025370340306410486,25.0,30.0
470.0918,0.0742885531496063,876.7588451443569,0.00025370340306410486,25.0,30.0
471.59326,0.07466700196850394,876.754934383202,0.00025370340306410486,25.0,30.0
473.09473,0.07502582677165354,875.4896325459317,0.00025370340306410486,25.0,30.0
474.59619,0.07533112992125984,877.1853543307086,0.00025370340306410486,25.0,30.0
476.09766,0.07566439566929134,878.5922572178478,0.00025370340306410486,25.0,30.0
477.59912,0.0759861062992126,878.4330183727034,0.00025370340306410486,25.0,30.0
479.10059,0.07631621456692914,877.7230971128608,0.00025370340306410486,25.0,30.0
480.60205,0.07665394291338583,880.2631233595799,0.00025370340306410486,25.0,30.0
482.10352,0.07700004330708661,879.9503412073491,0.00025370340306410486,25.0,30.0
483.60498,0.07740687992125984,880.841627296588,0.00025370340306410486,25.0,30.0
485.10645,0.07780812007874016,881.2128871391076,0.00025370340306410486,25.0,30.0
486.60791,0.07820964763779528,880.8417585301837,0.00025370340306410486,25.0,30.0
488.10938,0.07858981496062992,881.8320209973754,0.00025370340306410486,25.0,30.0
489.61084,0.07894015157480315,881.5934645669291,0.00025370340306410486,25.0,30.0
491.1123,0.07928727165354331,881.4995800524933,0.00025370340306410486,25.0,30.0
492.61377,0.07962241929133858,882.3636220472441,0.00025370340306410486,25.0,30.0
494.11523,0.07998378346456693,883.7393963254592,0.00025370340306410486,25.0,30.0
495.6167,0.08037924015748031,884.6176640419948,0.00025370340306410486,25.0,30.0
497.11816,0.08074668307086615,883.1364304461943,0.00025370340306410486,25.0,30.0
498.61963,0.08106583070866141,883.1366666666667,0.00025370340306410486,25.0,30.0
500.12109,0.08142389960629921,882.8677952755905,0.00025370340306410486,25.0,30.0
501.62256,0.08179206889763779,884.1507874015748,0.00025370340306410486,25.0,30.0
503.12402,0.08217142716535433,884.8640419947507,0.00025370340306410486,25.0,30.0
504.62549,0.08253404133858268,885.6060104986876,0.00025370340306410486,25.0,30.0
506.12695,0.0828653405511811,885.9283464566929,0.00025370340306410486,25.0,30.0
507.62842,0.08322469291338583,885.93968503937,0.00025370340306410486,25.0,30.0
509.12988,0.08359675196850393,886.7176640419947,0.00025370340306410486,25.0,30.0
510.63135,0.08394214173228345,886.2720472440944,0.00025370340306410486,25.0,30.0
512.13281,0.08429259448818897,886.4424934383202,0.00025370340306410486,25.0,30.0
513.63428,0.08466122244094487,888.8612335958005,0.00025370340306410486,25.0,30.0
515.13574,0.08503134645669291,887.6989763779527,0.00025370340306410486,25.0,30.0
516.63721,0.08540759448818898,888.5621784776903,0.00025370340306410486,25.0,30.0
518.13867,0.08573479921259843,887.4757217847769,0.00025370340306410486,25.0,30.0
519.64014,0.08609445078740158,888.2771391076116,0.00025370340306410486,25.0,30.0
521.1416,0.08645410236220473,890.6764041994751,0.00025370340306410486,25.0,30.0
522.64307,0.08679630708661418,888.8443044619422,0.00025370340306410486,25.0,30.0
524.14453,0.08718672440944882,890.0175853018372,0.00025370340306410486,25.0,30.0
525.646,0.08751251968503937,890.5980839895013,0.00025370340306410486,25.0,30.0
527.14746,0.08785345078740157,890.6649868766403,0.00025370340306410486,25.0,30.0
528.64893,0.08822561023622047,891.9392650918635,0.00025370340306410486,25.0,30.0
530.15039,0.08865353149606299,892.1415485564304,0.00025370340306410486,25.0,30.0
531.65186,0.08904613582677165,892.1757217847769,0.00025370340306410486,25.0,30.0
533.15332,0.08936857086614174,891.570997375328,0.00025370340306410486,25.0,30.0
534.65479,0.08969609645669292,893.7077690288714,0.00025370340306410486,25.0,30.0
536.15625,0.09002739566929134,891.714094488189,0.00025370340306410486,25.0,30.0
537.65771,0.09043886614173229,892.9105774278215,0.00025370340306410486,25.0,30.0
539.15918,0.09079732677165354,893.5121522309712,0.00025370340306410486,25.0,30.0
540.66064,0.09118631299212598,893.5190551181103,0.00025370340306410486,25.0,30.0
542.16211,0.09154654527559056,894.1796587926509,0.00025370340306410486,25.0,30.0
543.66357,0.09185071062992126,893.9701837270342,0.00025370340306410486,25.0,30.0
545.16504,0.09215838976377952,895.4434120734908,0.00025370340306410486,25.0,30.0
546.6665,0.09257474212598424,894.8936745406824,0.00025370340306410486,25.0,30.0
548.16797,0.09292961417322834,895.0389501312335,0.00025370340306410486,25.0,30.0
549.66943,0.09325830708661417,895.52343832021,0.00025370340306410486,25.0,30.0
551.1709,0.09364786614173227,896.7397900262466,0.00025370340306410486,25.0,30.0
552.67236,0.09397781102362204,897.1727034120735,0.00025370340306410486,25.0,30.0
554.17383,0.09438733464566929,898.4076377952756,0.00025370340306410486,25.0,30.0
555.67529,0.09476744291338583,897.6514435695539,0.00025370340306410486,25.0,30.0
557.17676,0.09513840551181102,898.536062992126,0.00025370340306410486,25.0,30.0
558.67822,0.09552031496062992,899.0105511811023,0.00025370340306410486,25.0,30.0
560.17969,0.09588514763779528,897.4686351706036,0.00025370340306410486,25.0,30.0
561.68115,0.09622911220472441,897.3548818897638,0.00025370340306410486,25.0,30.0
563.18262,0.09655466732283464,898.5813648293963,0.00025370340306410486,25.0,30.0
564.68408,0.09688170669291338,898.8669553805775,0.00025370340306410486,25.0,30.0
566.18555,0.0972381968503937,898.5261942257217,0.00025370340306410486,25.0,30.0
567.68701,0.09751252952755905,899.1855643044619,0.00025370340306410486,25.0,30.0
569.18848,0.09784981299212599,901.4430446194226,0.00025370340306410486,25.0,30.0
570.68994,0.09819877559055118,901.0851181102363,0.00025370340306410486,25.0,30.0
572.19141,0.09852673622047242,899.9041994750656,0.00025370340306410486,25.0,30.0
573.69287,0.09880267716535432,901.9656955380577,0.00025370340306410486,25.0,30.0
575.19434,0.09908195078740158,900.5053805774278,0.00025370340306410486,25.0,30.0
576.6958,0.09933847440944882,901.5359842519686,0.00025370340306410486,25.0,30.0
578.19727,0.09959954921259842,902.0066929133858,0.00025370340306410486,25.0,30.0
579.69873,0.09994506889763778,902.14343832021,0.00025370340306410486,25.0,30.0
581.2002,0.10033188779527559,903.5783464566929,0.00025370340306410486,25.0,30.0
582.70166,0.10073673031496062,901.9201312335958,0.00025370340306410486,25.0,30.0
584.20313,0.10108044291338582,901.2040419947506,0.00025370340306410486,25.0,30.0
585.70459,0.10141008661417324,903.2000262467192,0.00025370340306410486,25.0,30.0
587.20605,0.10179608661417322,903.452309711286,0.00025370340306410486,25.0,30.0
588.70752,0.10226556692913384,903.8737007874016,0.00025370340306410486,25.0,30.0
590.20898,0.10261974409448818,902.6837007874016,0.00025370340306410486,25.0,30.0
591.71045,0.10300419488188976,904.1051443569554,0.00025370340306410486,25.0,30.0
593.21191,0.10340430905511812,905.7510236220472,0.00025370340306410486,25.0,30.0
594.71338,0.10383131496062992,906.106719160105,0.00025370340306410486,25.0,30.0
596.21484,0.10423815157480315,904.9582414698162,0.00025370340306410486,25.0,30.0
597.71631,0.10462656692913386,905.5430708661416,0.00025370340306410486,25.0,30.0
599.21777,0.10501894881889764,905.4093438320209,0.00025370340306410486,25.0,30.0
600.71924,0.10537814960629922,907.6788188976378,0.00025370340306410486,25.0,30.0
602.2207,0.105760968503937,905.5422572178478,0.00025370340306410486,25.0,30.0
603.72217,0.10610793110236219,908.1317322834647,0.00025370340306410486,25.0,30.0
605.22363,0.10651129527559056,907.7270866141732,0.00025370340306410486,25.0,30.0
606.7251,0.10693337204724408,908.1971128608924,0.00025370340306410486,25.0,30.0
608.22656,0.10730162992125984,905.2881102362204,0.00025370340306410486,25.0,30.0
609.72803,0.10763540551181103,907.0519422572179,0.00025370340306410486,25.0,30.0
611.22949,0.1079764783464567,908.4691076115486,0.00025370340306410486,25.0,30.0
612.73096,0.10841229527559056,907.7144619422572,0.00025370340306410486,25.0,30.0
614.23242,0.10876044291338582,909.9329921259842,0.00025370340306410486,25.0,30.0
615.73389,0.10908350393700787,907.8429921259843,0.00025370340306410486,25.0,30.0
617.23535,0.10948006299212598,911.7612335958005,0.00025370340306410486,25.0,30.0
618.73682,0.10985513779527557,912.1191076115485,0.00025370340306410486,25.0,30.0
620.23828,0.11019639763779526,909.1192650918636,0.00025370340306410486,25.0,30.0
621.73975,0.11052682874015747,909.8079265091864,0.00025370340306410486,25.0,30.0
623.24121,0.11093499212598425,911.5266404199474,0.00025370340306410486,25.0,30.0
624.74268,0.11132352559055118,910.9465354330708,0.00025370340306410486,25.0,30.0
626.24414,0.11172447244094488,913.5166141732284,0.00025370340306410486,25.0,30.0
627.74561,0.11214794685039368,913.9222309711287,0.00025370340306410486,25.0,30.0
629.24707,0.11258892716535432,911.5878477690288,0.00025370340306410486,25.0,30.0
630.74854,0.11298351377952755,911.4410236220472,0.00025370340306410486,25.0,30.0
632.25,0.11335099803149606,911.611469816273,0.00025370340306410486,25.0,30.0
633.75146,0.11379709448818896,913.089842519685,0.00025370340306410486,25.0,30.0
635.25293,0.11416663188976378,913.4333070866141,0.00025370340306410486,25.0,30.0
636.75439,0.1145525,913.1181627296588,0.00025370340306410486,25.0,30.0
638.25586,0.11491588976377953,912.4901312335958,0.00025370340306410486,25.0,30.0
639.75732,0.11524113385826772,914.6290288713911,0.00025370340306410486,25.0,30.0
641.25879,0.11562788385826771,914.6529133858268,0.00025370340306410486,25.0,30.0
642.76025,0.11600788582677166,913.8607874015748,0.00025370340306410486,25.0,30.0
644.26172,0.1163013464566929,913.4606036745407,0.00025370340306410486,25.0,30.0
645.76318,0.11664451771653543,915.4095013123359,0.00025370340306410486,25.0,30.0
647.26465,0.11697645078740157,914.9425721784777,0.00025370340306410486,25.0,30.0
648.76611,0.11728970275590551,915.7017585301837,0.00025370340306410486,25.0,30.0
650.26758,0.1176613877952756,916.6430183727034,0.00025370340306410486,25.0,30.0
651.76904,0.11810418700787402,916.0031233595801,0.00025370340306410486,25.0,30.0
653.27051,0.11847771259842521,916.9686614173228,0.00025370340306410486,25.0,30.0
654.77197,0.1188637342519685,916.0791863517061,0.00025370340306410486,25.0,30.0
656.27344,0.11929360433070865,916.5112073490814,0.00025370340306410486,25.0,30.0
657.7749,0.11964066141732282,914.9692125984252,0.00025370340306410486,25.0,30.0
659.27637,0.11999596456692914,917.0310761154855,0.00025370340306410486,25.0,30.0
660.77783,0.12038645866141733,918.8016535433071,0.00025370340306410486,25.0,30.0
662.2793,0.12085565748031497,918.581154855643,0.00025370340306410486,25.0,30.0
663.78076,0.12132088976377951,919.1287664041995,0.00025370340306410486,25.0,30.0
665.28223,0.12172723425196849,919.2222047244095,0.00025370340306410486,25.0,30.0
666.78369,0.12211188385826771,916.8741469816273,0.00025370340306410486,25.0,30.0
668.28516,0.12248108070866141,918.5430183727034,0.00025370340306410486,25.0,30.0
669.78662,0.12289370078740157,920.694934383202,0.00025370340306410486,25.0,30.0
671.28809,0.12332415748031497,919.282624671916,0.00025370340306410486,25.0,30.0
672.78955,0.12364944881889764,920.7711023622047,0.00025370340306410486,25.0,30.0
674.29102,0.1240226220472441,917.9879002624672,0.00025370340306410486,25.0,30.0
675.79248,0.12443055118110236,920.707559055118,0.00025370340306410486,25.0,30.0
677.29395,0.12483575590551181,919.1962467191602,0.00025370340306410486,25.0,30.0
678.79541,0.12522356299212598,920.919527559055,0.00025370340306410486,25.0,30.0
680.29688,0.1256984744094488,919.5875853018373,0.00025370340306410486,25.0,30.0
681.79834,0.12612684251968503,920.898503937008,0.00025370340306410486,25.0,30.0
683.2998,0.12653880708661416,921.3469291338582,0.00025370340306410486,25.0,30.0
684.80127,0.1269224940944882,919.8167979002625,0.00025370340306410486,25.0,30.0
686.30273,0.12730802362204724,920.3577427821523,0.00025370340306410486,25.0,30.0
687.8042,0.12765919881889762,920.626220472441,0.00025370340306410486,25.0,30.0
689.30566,0.12805750590551182,921.8143832020997,0.00025370340306410486,25.0,30.0
690.80713,0.12852956692913386,921.3522572178478,0.00025370340306410486,25.0,30.0
692.30859,0.12896790748031495,922.3428346456693,0.00025370340306410486,25.0,30.0
693.81006,0.12936462992125985,921.1162467191601,0.00025370340306410486,25.0,30.0
695.31152,0.12975325787401576,922.9468503937007,0.00025370340306410486,25.0,30.0
696.81299,0.1301956220472441,922.2244881889764,0.00025370340306410486,25.0,30.0
698.31445,0.13063297637795276,923.0212335958005,0.00025370340306410486,25.0,30.0
699.81592,0.1311665688976378,925.8880577427822,0.00025370340306410486,25.0,30.0
701.31738,0.13159276377952756,923.314409448819,0.00025370340306410486,25.0,30.0
702.81885,0.13204721456692914,924.0538845144357,0.00025370340306410486,25.0,30.0
704.32031,0.13247275393700786,924.7600262467191,0.00025370340306410486,25.0,30.0
705.82178,0.132897155511811,924.2416272965879,0.00025370340306410486,25.0,30.0
707.32324,0.13331448228346457,925.0087664041994,0.00025370340306410486,25.0,30.0
708.82471,0.13379469881889763,925.8903149606299,0.00025370340306410486,25.0,30.0
710.32617,0.13423325,924.681154855643,0.00025370340306410486,25.0,30.0
711.82764,0.13459768307086614,923.7290026246718,0.00025370340306410486,25.0,30.0
713.3291,0.13494743897637795,925.5690288713911,0.00025370340306410486,25.0,30.0
714.83057,0.1352808248031496,924.6812598425197,0.00025370340306410486,25.0,30.0
716.33203,0.13567080118110236,926.3775065616799,0.00025370340306410486,25.0,30.0
717.8335,0.13612101574803148,925.7565879265092,0.00025370340306410486,25.0,30.0
719.33496,0.13657017519685039,925.7220997375329,0.00025370340306410486,25.0,30.0
720.83643,0.13697088779527558,926.9744619422572,0.00025370340306410486,25.0,30.0
722.33789,0.13742512598425197,927.1697637795276,0.00025370340306410486,25.0,30.0
723.83936,0.1378391909448819,926.2766404199475,0.00025370340306410486,25.0,30.0
725.34082,0.13829050787401576,927.2135433070865,0.00025370340306410486,25.0,30.0
726.84229,0.13876058661417323,925.2675328083989,0.00025370340306410486,25.0,30.0
728.34375,0.1391868779527559,927.8829133858268,0.00025370340306410486,25.0,30.0
729.84521,0.1395287007874016,925.9009448818898,0.00025370340306410486,25.0,30.0
731.34668,0.1399510846456693,928.1079002624672,0.00025370340306410486,25.0,30.0
732.84814,0.14036045472440944,929.2929133858269,0.00025370340306410486,25.0,30.0
734.34961,0.14081030708661416,929.0188451443569,0.00025370340306410486,25.0,30.0
735.85107,0.14120063385826773,927.8442782152231,0.00025370340306410486,25.0,30.0
737.35254,0.14155030708661417,927.3935433070866,0.00025370340306410486,25.0,30.0
738.854,0.14197252559055118,928.7264566929133,0.00025370340306410486,25.0,30.0
740.35547,0.1423711968503937,927.275249343832,0.00025370340306410486,25.0,30.0
741.85693,0.14275185629921258,929.708530183727,0.00025370340306410486,25.0,30.0
743.3584,0.14318904724409448,929.7220997375327,0.00025370340306410486,25.0,30.0
744.85986,0.14364817913385827,929.1992125984251,0.00025370340306410486,25.0,30.0
746.36133,0.14405052165354332,929.8224409448819,0.00025370340306410486,25.0,30.0
747.86279,0.14450039763779526,931.3076115485565,0.00025370340306410486,25.0,30.0
749.36426,0.14491603346456694,929.5660104986877,0.00025370340306410486,25.0,30.0
750.86572,0.14535268503937007,929.0509448818898,0.00025370340306410486,25.0,30.0
752.36719,0.14576727755905514,929.4317585301837,0.00025370340306410486,25.0,30.0
753.86865,0.14619999803149605,929.2154855643045,0.00025370340306410486,25.0,30.0
755.37012,0.1465777716535433,929.4450918635171,0.00025370340306410486,25.0,30.0
756.87158,0.1470203248031496,931.8587401574804,0.00025370340306410486,25.0,30.0
758.37305,0.14745076771653545,930.7841469816273,0.00025370340306410486,25.0,30.0
759.87451,0.1479224901574803,930.1060104986876,0.00025370340306410486,25.0,30.0
761.37598,0.14837958070866142,932.0961679790026,0.00025370340306410486,25.0,30.0
762.87744,0.14881022244094488,931.2396850393701,0.00025370340306410486,25.0,30.0
764.37891,0.1492494783464567,930.5071916010498,0.00025370340306410486,25.0,30.0
765.88037,0.14966943307086614,932.4688451443569,0.00025370340306410486,25.0,30.0
767.38184,0.1500934251968504,933.5718372703412,0.00025370340306410486,25.0,30.0
768.8833,0.15060317322834646,932.2069553805775,0.00025370340306410486,25.0,30.0
770.38477,0.15105343503937008,932.9341207349081,0.00025370340306410486,25.0,30.0
771.88623,0.15149656299212597,932.5984251968504,0.00025370340306410486,25.0,30.0
773.3877,0.1519743622047244,932.4011023622047,0.00025370340306410486,25.0,30.0
774.88916,0.1523779842519685,931.6153018372703,0.00025370340306410486,25.0,30.0
776.39063,0.15283424015748032,932.38656167979,0.00025370340306410486,25.0,30.0
777.89209,0.15341275787401573,934.0019422572178,0.00025370340306410486,25.0,30.0
779.39355,0.15396767913385825,935.4660104986876,0.00025370340306410486,25.0,30.0
780.89502,0.15437985433070864,932.6013648293964,0.00025370340306410486,25.0,30.0
782.39648,0.15475752362204723,932.8382677165355,0.00025370340306410486,25.0,30.0
783.89795,0.15528197440944883,934.517375328084,0.00025370340306410486,25.0,30.0
785.39941,0.15572555905511812,934.3498162729659,0.00025370340306410486,25.0,30.0
786.90088,0.15616813582677164,931.9234645669292,0.00025370340306410486,25.0,30.0
788.40234,0.15650853937007875,933.5683202099738,0.00025370340306410486,25.0,30.0
789.90381,0.15700559251968504,933.5933595800525,0.00025370340306410486,25.0,30.0
791.40527,0.1575342775590551,937.4407874015748,0.00025370340306410486,25.0,30.0
792.90674,0.15801509251968504,934.4483727034121,0.00025370340306410486,25.0,30.0
794.4082,0.15845738779527557,933.3525459317584,0.00025370340306410486,25.0,30.0
795.90967,0.15887343503937007,935.1315223097113,0.00025370340306410486,25.0,30.0
797.41113,0.1593828090551181,933.833464566929,0.00025370340306410486,25.0,30.0
798.9126,0.15977736023622047,933.6412335958005,0.00025370340306410486,25.0,30.0
800.41406,0.16022589763779527,934.103937007874,0.00025370340306410486,25.0,30.0
801.91553,0.16067198228346458,935.364120734908,0.00025370340306410486,25.0,30.0
803.41699,0.16116071653543307,936.1054593175853,0.00025370340306410486,25.0,30.0
804.91846,0.16164413582677167,936.4307874015748,0.00025370340306410486,25.0,30.0
806.41992,0.16211652559055117,934.3353280839895,0.00025370340306410486,25.0,30.0
807.92139,0.16255181692913384,935.3555380577428,0.00025370340306410486,25.0,30.0
809.42285,0.1630226338582677,937.1002099737533,0.00025370340306410486,25.0,30.0
810.92432,0.16354850393700787,936.8808661417322,0.00025370340306410486,25.0,30.0
812.42578,0.1640084566929134,936.5411286089239,0.00025370340306410486,25.0,30.0
813.92725,0.16457301181102363,936.7092650918635,0.00025370340306410486,25.0,30.0
815.42871,0.16509172440944883,937.920157480315,0.00025370340306410486,25.0,30.0
816.93018,0.16553133267716535,934.7038582677166,0.00025370340306410486,25.0,30.0
818.43164,0.16593096456692913,936.3394750656167,0.00025370340306410486,25.0,30.0
819.93311,0.16638553346456694,938.5883202099737,0.00025370340306410486,25.0,30.0
821.43457,0.16682340354330707,935.4801574803149,0.00025370340306410486,25.0,30.0
822.93604,0.16725983267716535,936.5006299212598,0.00025370340306410486,25.0,30.0
824.4375,0.16773134251968505,936.4858792650919,0.00025370340306410486,25.0,30.0
825.93896,0.1681984527559055,937.4534908136483,0.00025370340306410486,25.0,30.0
827.44043,0.16866173818897637,937.141469816273,0.00025370340306410486,25.0,30.0
828.94189,0.1692013720472441,937.7228083989501,0.00025370340306410486,25.0,30.0
830.44336,0.16964506299212598,935.7129133858268,0.00025370340306410486,25.0,30.0
831.94482,0.17014112992125985,938.3968503937008,0.00025370340306410486,25.0,30.0
833.44629,0.17067327755905512,937.7843832020998,0.00025370340306410486,25.0,30.0
834.94775,0.1711778996062992,937.73624671916,0.00025370340306410486,25.0,30.0
836.44922,0.1716350472440945,938.9306824146981,0.00025370340306410486,25.0,30.0
837.95068,0.17212750196850393,936.8787664041995,0.00025370340306410486,25.0,30.0
839.45215,0.17254393700787402,937.2464304461942,0.00025370340306410486,25.0,30.0
840.95361,0.17302999606299213,937.4916797900262,0.00025370340306410486,25.0,30.0
842.45508,0.17349764566929135,938.6655380577428,0.00025370340306410486,25.0,30.0
843.95654,0.1740511712598425,939.488372703412,0.00025370340306410486,25.0,30.0
845.45801,0.17449099015748032,939.1487401574803,0.00025370340306410486,25.0,30.0
846.95947,0.17496413188976379,938.5089763779528,0.00025370340306410486,25.0,30.0
848.46094,0.17547350393700786,938.6600262467191,0.00025370340306410486,25.0,30.0
849.9624,0.17600531102362205,939.5848031496063,0.00025370340306410486,25.0,30.0
851.46387,0.17661670472440943,938.9696587926509,0.00025370340306410486,25.0,30.0
852.96533,0.17715632677165352,939.2379527559054,0.00025370340306410486,25.0,30.0
854.4668,0.17767133267716534,938.0140419947506,0.00025370340306410486,25.0,30.0
855.96826,0.17820099212598425,939.4048818897637,0.00025370340306410486,25.0,30.0
857.46973,0.17864537598425195,937.2924409448818,0.00025370340306410486,25.0,30.0
858.97119,0.17913425,939.0386089238845,0.00025370340306410486,25.0,30.0
860.47266,0.17966938976377952,939.708031496063,0.00025370340306410486,25.0,30.0
861.97412,0.18012260826771653,939.3707874015748,0.00025370340306410486,25.0,30.0
863.47559,0.1805652657480315,938.6382414698162,0.00025370340306410486,25.0,30.0
864.97705,0.18103683464566928,940.3193963254593,0.00025370340306410486,25.0,30.0
866.47852,0.18150956692913386,939.8355380577427,0.00025370340306410486,25.0,30.0
867.97998,0.1819444566929134,938.6931496062992,0.00025370340306410486,25.0,30.0
869.48145,0.18240531299212598,938.8374015748032,0.00025370340306410486,25.0,30.0
870.98291,0.18282259251968505,938.982467191601,0.00025370340306410486,25.0,30.0
872.48438,0.18324662007874015,940.5784776902887,0.00025370340306410486,25.0,30.0
873.98584,0.18367658267716536,940.4233333333334,0.00025370340306410486,25.0,30.0
875.4873,0.18407314173228348,938.9024409448818,0.00025370340306410486,25.0,30.0
876.98877,0.18462868503937008,940.3111286089238,0.00025370340306410486,25.0,30.0
878.49023,0.1851722244094488,941.3044356955381,0.00025370340306410486,25.0,30.0
879.9917,0.18576613582677165,940.7584251968505,0.00025370340306410486,25.0,30.0
881.49316,0.1863564094488189,939.7361679790026,0.00025370340306410486,25.0,30.0
882.99463,0.18683904330708662,940.2850656167979,0.00025370340306410486,25.0,30.0
884.49609,0.1873645964566929,939.6779790026246,0.00025370340306410486,25.0,30.0
885.99756,0.18788470472440943,940.2627559055118,0.00025370340306410486,25.0,30.0
887.49902,0.18844740551181102,941.02312335958,0.00025370340306410486,25.0,30.0
889.00049,0.18896363188976378,940.8483202099737,0.00025370340306410486,25.0,30.0
890.50195,0.18949782086614173,939.0901049868767,0.00025370340306410486,25.0,30.0
892.00342,0.189970468503937,941.4553280839896,0.00025370340306410486,25.0,30.0
893.50488,0.19055845472440944,941.359658792651,0.00025370340306410486,25.0,30.0
894.10547,0.19082800196850394,943.7432020997375,0.00025370340306410486,25.0,30.0