File: datasets/am_bench_2022/csv/30-XY.01-4.csv
Time(s),Strain(%),Stress(MPa),SR(s-1),Temp(C),Angle(deg)
27.310059,1.9823503937007874e-06,21.431532020997377,0.00025370340306410486,25.0,30.0
29.111816,2.4530842519685037e-05,29.535727034120736,0.00025370340306410486,25.0,30.0
30.613281,4.258423818897637e-05,33.62081627296588,0.00025370340306410486,25.0,30.0
32.114746,7.69718405511811e-05,37.659645669291336,0.00025370340306410486,25.0,30.0
33.616211,8.736218897637796e-05,44.05938582677165,0.00025370340306410486,25.0,30.0
35.117676,0.00011376449015748031,51.17308398950131,0.00025370340306410486,25.0,30.0
36.619141,0.00014794054527559055,57.679595800524936,0.00025370340306410486,25.0,30.0
38.120605,0.00017084215551181102,66.17072440944881,0.00025370340306410486,25.0,30.0
39.62207,0.00020462938976377956,73.07374803149607,0.00025370340306410486,25.0,30.0
41.123535,0.00023919507874015748,80.8747532808399,0.00025370340306410486,25.0,30.0
42.625,0.0002601526377952756,88.37774540682413,0.00025370340306410486,25.0,30.0
44.126465,0.000285376594488189,96.19130183727033,0.00025370340306410486,25.0,30.0
45.62793,0.0003225701771653543,106.6793280839895,0.00025370340306410486,25.0,30.0
47.129395,0.00034200574803149605,114.37087139107611,0.00025370340306410486,25.0,30.0
48.630859,0.0003877982677165354,123.60910236220472,0.00025370340306410486,25.0,30.0
50.132324,0.0004092971062992126,131.9600971128609,0.00025370340306410486,25.0,30.0
51.633789,0.0004453825196850394,140.9082283464567,0.00025370340306410486,25.0,30.0
53.135254,0.00047791685039370077,150.76398162729657,0.00025370340306410486,25.0,30.0
54.636719,0.0005193802165354331,161.98600787401574,0.00025370340306410486,25.0,30.0
56.138184,0.0005571789960629921,171.43863779527558,0.00025370340306410486,25.0,30.0
57.639648,0.0005802878937007874,181.5171942257218,0.00025370340306410486,25.0,30.0
59.141113,0.0006121020866141732,190.54116797900264,0.00025370340306410486,25.0,30.0
60.642578,0.0006581860039370079,201.4327874015748,0.00025370340306410486,25.0,30.0
62.144043,0.0006972308464566929,210.89266141732284,0.00025370340306410486,25.0,30.0
63.645508,0.0007345520275590552,220.6671286089239,0.00025370340306410486,25.0,30.0
65.146973,0.0007554063779527559,230.08195275590552,0.00025370340306410486,25.0,30.0
66.648438,0.0008115466929133859,241.6475564304462,0.00025370340306410486,25.0,30.0
68.149902,0.000844759625984252,252.30587926509185,0.00025370340306410486,25.0,30.0
69.651367,0.0008675127755905512,261.9614330708662,0.00025370340306410486,25.0,30.0
71.152832,0.0009347807480314961,275.0615748031496,0.00025370340306410486,25.0,30.0
72.654297,0.0009723447637795276,286.1915485564304,0.00025370340306410486,25.0,30.0
74.155762,0.001002176968503937,297.88461942257214,0.00025370340306410486,25.0,30.0
75.657227,0.001049628779527559,309.8359580052493,0.00025370340306410486,25.0,30.0
77.158691,0.0011043179330708663,321.9203937007874,0.00025370340306410486,25.0,30.0
78.660156,0.0011286714763779526,333.6283727034121,0.00025370340306410486,25.0,30.0
80.161621,0.001171293877952756,343.8690813648294,0.00025370340306410486,25.0,30.0
81.663086,0.0012078092322834646,354.37233595800524,0.00025370340306410486,25.0,30.0
83.164551,0.001238360374015748,364.01107611548554,0.00025370340306410486,25.0,30.0
84.666016,0.001278390098425197,374.61847769028867,0.00025370340306410486,25.0,30.0
86.16748,0.0013244601377952756,385.05937007874013,0.00025370340306410486,25.0,30.0
87.668945,0.001368871122047244,397.20097112860896,0.00025370340306410486,25.0,30.0
89.17041,0.0013934174212598424,403.94380577427825,0.00025370340306410486,25.0,30.0
90.671875,0.001439538346456693,415.10808398950127,0.00025370340306410486,25.0,30.0
92.17334,0.0014572740748031495,423.8939632545932,0.00025370340306410486,25.0,30.0
93.674805,0.001490711220472441,435.6648031496063,0.00025370340306410486,25.0,30.0
95.17627,0.0015452293307086614,444.9001837270341,0.00025370340306410486,25.0,30.0
96.677734,0.0015870517716535433,452.4974803149606,0.00025370340306410486,25.0,30.0
98.179199,0.0016188683464566928,466.16719160104986,0.00025370340306410486,25.0,30.0
99.680664,0.00163295405511811,473.27939632545935,0.00025370340306410486,25.0,30.0
101.18213,0.0016789628543307086,484.7363779527559,0.00025370340306410486,25.0,30.0
102.68359,0.0017226589370078738,492.8309186351706,0.00025370340306410486,25.0,30.0
104.18506,0.0017602132283464568,502.88832020997376,0.00025370340306410486,25.0,30.0
105.68652,0.0017850943897637795,510.68761154855645,0.00025370340306410486,25.0,30.0
107.18799,0.001808795275590551,518.0197375328083,0.00025370340306410486,25.0,30.0
108.68945,0.0018534688779527561,525.6303149606299,0.00025370340306410486,25.0,30.0
110.19092,0.0018867086614173228,533.9354855643045,0.00025370340306410486,25.0,30.0
111.69238,0.001920261929133858,540.7775590551181,0.00025370340306410486,25.0,30.0
113.19385,0.0019580177165354332,547.7982414698163,0.00025370340306410486,25.0,30.0
114.69531,0.0019767765748031495,554.0300524934382,0.00025370340306410486,25.0,30.0
116.19678,0.0020146429133858267,562.1283989501312,0.00025370340306410486,25.0,30.0
117.69824,0.0020449116141732283,570.7470866141732,0.00025370340306410486,25.0,30.0
119.19971,0.002076632283464567,575.1296850393701,0.00025370340306410486,25.0,30.0
120.70117,0.0020956917322834646,579.1048818897638,0.00025370340306410486,25.0,30.0
122.20264,0.002149680708661417,588.1112598425196,0.00025370340306410486,25.0,30.0
123.7041,0.0021700177165354328,590.4337795275591,0.00025370340306410486,25.0,30.0
125.20557,0.0022034826771653543,597.4560104986876,0.00025370340306410486,25.0,30.0
126.70703,0.002255675,603.717217847769,0.00025370340306410486,25.0,30.0
128.2085,0.0022889405511811022,609.4485564304462,0.00025370340306410486,25.0,30.0
129.70996,0.002297812795275591,612.2163254593175,0.00025370340306410486,25.0,30.0
131.21143,0.002359188976377953,616.8803674540682,0.00025370340306410486,25.0,30.0
132.71289,0.0023896875984251967,622.2087139107612,0.00025370340306410486,25.0,30.0
134.21436,0.0024308,625.0932283464567,0.00025370340306410486,25.0,30.0
135.71582,0.0024625149606299214,630.2377427821523,0.00025370340306410486,25.0,30.0
137.21729,0.0024882299212598425,634.0912073490813,0.00025370340306410486,25.0,30.0
138.71875,0.0025519003937007874,638.9413385826772,0.00025370340306410486,25.0,30.0
140.22021,0.0025977559055118107,644.3380577427821,0.00025370340306410486,25.0,30.0
141.72168,0.002632264960629921,648.432125984252,0.00025370340306410486,25.0,30.0
143.22314,0.0026773188976377954,649.8050131233596,0.00025370340306410486,25.0,30.0
144.72461,0.0027341675196850394,655.1247769028871,0.00025370340306410486,25.0,30.0
146.22607,0.0028044094488188973,658.8381364829396,0.00025370340306410486,25.0,30.0
147.72754,0.002848563779527559,662.213622047244,0.00025370340306410486,25.0,30.0
149.229,0.002913890157480315,665.7401574803149,0.00025370340306410486,25.0,30.0
150.73047,0.002971341141732283,670.412467191601,0.00025370340306410486,25.0,30.0
152.23193,0.003033595275590551,671.2395275590551,0.00025370340306410486,25.0,30.0
153.7334,0.0031139734251968503,677.0731496062992,0.00025370340306410486,25.0,30.0
155.23486,0.0032009675196850397,681.3687926509186,0.00025370340306410486,25.0,30.0
156.73633,0.0032757592519685034,682.198687664042,0.00025370340306410486,25.0,30.0
158.23779,0.0033800659448818896,685.6445406824147,0.00025370340306410486,25.0,30.0
159.73926,0.003441879330708661,686.6825984251968,0.00025370340306410486,25.0,30.0
161.24072,0.0035060062992125986,689.5570078740158,0.00025370340306410486,25.0,30.0
162.74219,0.003629366929133858,694.0507874015749,0.00025370340306410486,25.0,30.0
164.24365,0.003733927755905512,696.600813648294,0.00025370340306410486,25.0,30.0
165.74512,0.0038406159448818897,698.7038057742782,0.00025370340306410486,25.0,30.0
167.24658,0.003950495078740157,700.5335170603674,0.00025370340306410486,25.0,30.0
168.74805,0.004096983267716535,704.9055643044619,0.00025370340306410486,25.0,30.0
170.24951,0.004235492716535433,707.2402099737533,0.00025370340306410486,25.0,30.0
171.75098,0.004389240157480314,710.103779527559,0.00025370340306410486,25.0,30.0
173.25244,0.004546479133858268,712.20031496063,0.00025370340306410486,25.0,30.0
174.75391,0.004704944488188976,714.5817847769029,0.00025370340306410486,25.0,30.0
176.25537,0.004896813779527559,715.7529133858267,0.00025370340306410486,25.0,30.0
177.75684,0.005089047637795276,720.1112860892388,0.00025370340306410486,25.0,30.0
179.2583,0.005326754133858268,721.580813648294,0.00025370340306410486,25.0,30.0
180.75977,0.00549215846456693,721.5212860892387,0.00025370340306410486,25.0,30.0
182.26123,0.00569407657480315,723.3958530183727,0.00025370340306410486,25.0,30.0
183.7627,0.005916108661417323,726.5525721784777,0.00025370340306410486,25.0,30.0
185.26416,0.006217597440944882,729.1769291338583,0.00025370340306410486,25.0,30.0
186.76563,0.0063914614173228345,727.7801837270341,0.00025370340306410486,25.0,30.0
188.26709,0.006643334448818899,732.1165354330709,0.00025370340306410486,25.0,30.0
189.76855,0.0069533673228346455,733.7502887139108,0.00025370340306410486,25.0,30.0
191.27002,0.007230275787401575,733.4525721784777,0.00025370340306410486,25.0,30.0
192.77148,0.007461363385826771,734.5244356955382,0.00025370340306410486,25.0,30.0
194.27295,0.007710446062992126,736.1815223097112,0.00025370340306410486,25.0,30.0
195.77441,0.007957794291338582,737.5340157480315,0.00025370340306410486,25.0,30.0
197.27588,0.008254592125984252,739.6534908136483,0.00025370340306410486,25.0,30.0
198.77734,0.008546288188976379,740.7298950131233,0.00025370340306410486,25.0,30.0
200.27881,0.008857160826771654,741.7902099737532,0.00025370340306410486,25.0,30.0
201.78027,0.009146794685039369,741.4514173228347,0.00025370340306410486,25.0,30.0
203.28174,0.009469671062992126,742.432782152231,0.00025370340306410486,25.0,30.0
204.7832,0.00981102933070866,744.6199475065616,0.00025370340306410486,25.0,30.0
206.28467,0.010143485236220473,746.3929396325459,0.00025370340306410486,25.0,30.0
207.78613,0.010485249803149606,746.777532808399,0.00025370340306410486,25.0,30.0
209.2876,0.010795534251968504,748.6681889763779,0.00025370340306410486,25.0,30.0
210.78906,0.011128361023622047,750.1101574803149,0.00025370340306410486,25.0,30.0
212.29053,0.011490822244094487,751.0751706036745,0.00025370340306410486,25.0,30.0
213.79199,0.01183331279527559,750.9723359580053,0.00025370340306410486,25.0,30.0
215.29346,0.012119038188976378,753.3764566929134,0.00025370340306410486,25.0,30.0
216.79492,0.012456813385826772,751.7399475065616,0.00025370340306410486,25.0,30.0
218.29639,0.012777342322834647,754.1508923884514,0.00025370340306410486,25.0,30.0
219.79785,0.013102799212598427,754.1518635170604,0.00025370340306410486,25.0,30.0
221.29932,0.013465027952755906,755.5792125984252,0.00025370340306410486,25.0,30.0
222.80078,0.013834488779527558,757.7124146981628,0.00025370340306410486,25.0,30.0
224.30225,0.014200412007874016,756.436719160105,0.00025370340306410486,25.0,30.0
225.80371,0.014539599803149608,758.3324409448819,0.00025370340306410486,25.0,30.0
227.30518,0.014872939960629923,759.9582414698162,0.00025370340306410486,25.0,30.0
228.80664,0.015239845866141733,760.6663779527559,0.00025370340306410486,25.0,30.0
230.30811,0.015593276181102364,761.6255905511812,0.00025370340306410486,25.0,30.0
231.80957,0.01594711279527559,762.878845144357,0.00025370340306410486,25.0,30.0
233.31104,0.01629189566929134,762.147690288714,0.00025370340306410486,25.0,30.0
234.8125,0.016636722637795275,763.2859842519684,0.00025370340306410486,25.0,30.0
236.31396,0.017034326968503936,763.8322047244094,0.00025370340306410486,25.0,30.0
237.81543,0.01734226476377953,762.9670078740157,0.00025370340306410486,25.0,30.0
239.31689,0.017690313976377953,764.0523097112861,0.00025370340306410486,25.0,30.0
240.81836,0.0180170218503937,765.114409448819,0.00025370340306410486,25.0,30.0
242.31982,0.018361003937007875,768.4201312335957,0.00025370340306410486,25.0,30.0
243.82129,0.018764655314960632,767.5329396325459,0.00025370340306410486,25.0,30.0
245.32275,0.01909831968503937,767.9055118110235,0.00025370340306410486,25.0,30.0
246.82422,0.019466062992125985,769.5117585301838,0.00025370340306410486,25.0,30.0
248.32568,0.019815765748031497,770.3763779527559,0.00025370340306410486,25.0,30.0
249.82715,0.020164545275590553,771.343595800525,0.00025370340306410486,25.0,30.0
251.32861,0.020586580708661418,772.058188976378,0.00025370340306410486,25.0,30.0
252.83008,0.02099725,773.1065354330708,0.00025370340306410486,25.0,30.0
254.33154,0.021340791338582677,772.7141732283465,0.00025370340306410486,25.0,30.0
255.83301,0.021714381889763778,774.6925459317584,0.00025370340306410486,25.0,30.0
257.33447,0.022101509842519684,775.0758792650919,0.00025370340306410486,25.0,30.0
258.83594,0.022454645669291336,775.1652493438321,0.00025370340306410486,25.0,30.0
260.3374,0.022774637795275592,775.0356955380578,0.00025370340306410486,25.0,30.0
261.83887,0.023147604330708664,776.4894488188976,0.00025370340306410486,25.0,30.0
263.34033,0.023511120078740157,775.4924409448819,0.00025370340306410486,25.0,30.0
264.8418,0.023811759842519684,776.6800262467192,0.00025370340306410486,25.0,30.0
266.34326,0.024164716535433072,777.0558530183728,0.00025370340306410486,25.0,30.0
267.84473,0.02448667125984252,780.2632545931758,0.00025370340306410486,25.0,30.0
269.34619,0.02487336220472441,778.0377952755906,0.00025370340306410486,25.0,30.0
270.84766,0.0252424468503937,779.6467454068242,0.00025370340306410486,25.0,30.0
272.34912,0.02557921062992126,779.8305774278215,0.00025370340306410486,25.0,30.0
273.85059,0.02596872834645669,781.3848293963255,0.00025370340306410486,25.0,30.0
275.35205,0.026354832677165353,781.44312335958,0.00025370340306410486,25.0,30.0
276.85352,0.02673665748031496,784.1399475065616,0.00025370340306410486,25.0,30.0
278.35498,0.027207374015748034,784.759028871391,0.00025370340306410486,25.0,30.0
279.85645,0.027593444881889764,783.1297637795276,0.00025370340306410486,25.0,30.0
281.35791,0.027993007874015746,784.0785039370079,0.00025370340306410486,25.0,30.0
282.85938,0.02827306496062992,783.8965879265093,0.00025370340306410486,25.0,30.0
284.36084,0.02860507283464567,784.9021259842519,0.00025370340306410486,25.0,30.0
285.8623,0.028999820866141734,785.8614960629922,0.00025370340306410486,25.0,30.0
287.36377,0.029326356299212597,785.0438582677166,0.00025370340306410486,25.0,30.0
288.86523,0.0296636062992126,787.029028871391,0.00025370340306410486,25.0,30.0
290.3667,0.03002195866141732,787.9770078740157,0.00025370340306410486,25.0,30.0
291.86816,0.030403399606299213,789.7941469816273,0.00025370340306410486,25.0,30.0
293.36963,0.030793155511811023,789.6696587926509,0.00025370340306410486,25.0,30.0
294.87109,0.03117806102362205,789.8635433070866,0.00025370340306410486,25.0,30.0
296.37256,0.03153759448818898,790.7240682414698,0.00025370340306410486,25.0,30.0
297.87402,0.03189882480314961,790.7297112860891,0.00025370340306410486,25.0,30.0
299.37549,0.032256783464566924,791.1367979002625,0.00025370340306410486,25.0,30.0
300.87695,0.03262155118110236,792.1907611548556,0.00025370340306410486,25.0,30.0
302.37842,0.03294072440944882,791.0751443569553,0.00025370340306410486,25.0,30.0
303.87988,0.03326366338582677,792.0448556430446,0.00025370340306410486,25.0,30.0
305.38135,0.033564326771653545,791.917217847769,0.00025370340306410486,25.0,30.0
306.88281,0.03395580905511811,793.9850393700788,0.00025370340306410486,25.0,30.0
308.38428,0.034266129921259846,793.3025459317586,0.00025370340306410486,25.0,30.0
309.88574,0.034679687007874015,797.035590551181,0.00025370340306410486,25.0,30.0
311.38721,0.03508523031496063,797.9038582677165,0.00025370340306410486,25.0,30.0
312.88867,0.03545587007874016,796.2361942257218,0.00025370340306410486,25.0,30.0
314.39014,0.0358629094488189,795.1854855643045,0.00025370340306410486,25.0,30.0
315.8916,0.03615308070866142,795.1354593175853,0.00025370340306410486,25.0,30.0
317.39307,0.03649464566929134,799.0454855643045,0.00025370340306410486,25.0,30.0
318.89453,0.03686096653543307,797.8470078740157,0.00025370340306410486,25.0,30.0
320.396,0.0372596968503937,800.2412598425196,0.00025370340306410486,25.0,30.0
321.89746,0.03763542913385827,799.5051181102363,0.00025370340306410486,25.0,30.0
323.39893,0.0379527125984252,798.9507086614173,0.00025370340306410486,25.0,30.0
324.90039,0.03833307874015748,801.099028871391,0.00025370340306410486,25.0,30.0
326.40186,0.038727442913385826,799.812125984252,0.00025370340306410486,25.0,30.0
327.90332,0.03906886220472441,800.8210498687664,0.00025370340306410486,25.0,30.0
329.40479,0.03946994094488189,804.762467191601,0.00025370340306410486,25.0,30.0
330.90625,0.03983462204724409,800.8111811023622,0.00025370340306410486,25.0,30.0
332.40771,0.040211966535433075,802.3684776902887,0.00025370340306410486,25.0,30.0
333.90918,0.04051773818897638,801.3667979002624,0.00025370340306410486,25.0,30.0
335.41064,0.040837096456692916,804.48,0.00025370340306410486,25.0,30.0
336.91211,0.04120420669291339,805.1330446194225,0.00025370340306410486,25.0,30.0
338.41357,0.04159702559055118,805.0832545931759,0.00025370340306410486,25.0,30.0
339.91504,0.04189325590551181,804.0953543307087,0.00025370340306410486,25.0,30.0
341.4165,0.04224119291338583,806.7579002624673,0.00025370340306410486,25.0,30.0
342.91797,0.042583462598425194,806.5920472440945,0.00025370340306410486,25.0,30.0
344.41943,0.04296977165354331,807.0561679790026,0.00025370340306410486,25.0,30.0
345.9209,0.043340553149606297,807.8947769028871,0.00025370340306410486,25.0,30.0
347.42236,0.043737765748031496,808.0794488188977,0.00025370340306410486,25.0,30.0
348.92383,0.044076610236220476,807.294094488189,0.00025370340306410486,25.0,30.0
350.42529,0.04444332283464567,808.5477427821521,0.00025370340306410486,25.0,30.0
351.92676,0.04479497637795276,809.0711286089239,0.00025370340306410486,25.0,30.0
353.42822,0.045126228346456694,809.0629396325459,0.00025370340306410486,25.0,30.0
354.92969,0.045503547244094486,810.7524409448819,0.00025370340306410486,25.0,30.0
356.43115,0.045948826771653545,812.0641994750656,0.00025370340306410486,25.0,30.0
357.93262,0.046325169291338585,812.0181889763779,0.00025370340306410486,25.0,30.0
359.43408,0.046663423228346455,812.568372703412,0.00025370340306410486,25.0,30.0
360.93555,0.047022527559055116,812.5859842519685,0.00025370340306410486,25.0,30.0
362.43701,0.0473580905511811,812.7356692913386,0.00025370340306410486,25.0,30.0
363.93848,0.04766266929133858,813.9374278215223,0.00025370340306410486,25.0,30.0
365.43994,0.04807184448818898,814.7325721784777,0.00025370340306410486,25.0,30.0
366.94141,0.04847846653543307,814.0623097112862,0.00025370340306410486,25.0,30.0
368.44287,0.048833297244094485,813.5673753280839,0.00025370340306410486,25.0,30.0
369.94434,0.049177222440944884,816.0416535433071,0.00025370340306410486,25.0,30.0
371.4458,0.049460996062992126,814.5972440944881,0.00025370340306410486,25.0,30.0
372.94727,0.04978458661417323,815.833779527559,0.00025370340306410486,25.0,30.0
374.44873,0.05014650196850394,817.1528871391076,0.00025370340306410486,25.0,30.0
375.9502,0.05055324015748032,818.5944881889764,0.00025370340306410486,25.0,30.0
377.45166,0.0509537342519685,819.2350131233596,0.00025370340306410486,25.0,30.0
378.95313,0.051320954724409444,818.8577690288714,0.00025370340306410486,25.0,30.0
380.45459,0.05166750590551181,818.7136745406824,0.00025370340306410486,25.0,30.0
381.95605,0.052021649606299215,819.6904199475066,0.00025370340306410486,25.0,30.0
383.45752,0.05239822047244095,820.1925984251968,0.00025370340306410486,25.0,30.0
384.95898,0.052766360236220465,819.4561417322834,0.00025370340306410486,25.0,30.0
386.46045,0.05308207874015748,818.2035433070866,0.00025370340306410486,25.0,30.0
387.96191,0.05341172244094488,820.5634908136483,0.00025370340306410486,25.0,30.0
389.46338,0.05376142519685039,821.8801312335958,0.00025370340306410486,25.0,30.0
390.96484,0.05411221850393701,820.7830971128608,0.00025370340306410486,25.0,30.0
392.46631,0.054468836614173226,822.6447769028872,0.00025370340306410486,25.0,30.0
393.96777,0.05487854133858268,824.3924146981627,0.00025370340306410486,25.0,30.0
395.46924,0.055315053149606296,823.5883464566929,0.00025370340306410486,25.0,30.0
396.9707,0.05571673228346456,823.2555905511811,0.00025370340306410486,25.0,30.0
398.47217,0.05601972440944882,824.712939632546,0.00025370340306410486,25.0,30.0
399.97363,0.056355903543307086,824.1487664041995,0.00025370340306410486,25.0,30.0
401.4751,0.056715181102362205,825.6589238845144,0.00025370340306410486,25.0,30.0
402.97656,0.05702790551181102,823.8928346456693,0.00025370340306410486,25.0,30.0
404.47803,0.05737113582677165,825.7197375328084,0.00025370340306410486,25.0,30.0
405.97949,0.05773681299212598,825.5847244094489,0.00025370340306410486,25.0,30.0
407.48096,0.05806918503937007,826.9612598425197,0.00025370340306410486,25.0,30.0
408.98242,0.05840845669291339,827.2712073490814,0.00025370340306410486,25.0,30.0
410.48389,0.05880832480314961,829.167060367454,0.00025370340306410486,25.0,30.0
411.98535,0.05912856496062992,826.668687664042,0.00025370340306410486,25.0,30.0
413.48682,0.05949258070866142,829.5443569553805,0.00025370340306410486,25.0,30.0
414.98828,0.05986115551181102,830.4802887139107,0.00025370340306410486,25.0,30.0
416.48975,0.060232687007874014,829.2332545931758,0.00025370340306410486,25.0,30.0
417.99121,0.060594956692913385,831.6655643044619,0.00025370340306410486,25.0,30.0
419.49268,0.060961277559055116,830.8366141732283,0.00025370340306410486,25.0,30.0
420.99414,0.0612883405511811,830.8484251968504,0.00025370340306410486,25.0,30.0
422.49561,0.0616647716535433,831.0962729658793,0.00025370340306410486,25.0,30.0
423.99707,0.06200282283464567,831.9746719160105,0.00025370340306410486,25.0,30.0
425.49854,0.06232003543307086,832.4361679790026,0.00025370340306410486,25.0,30.0
427.0,0.06269046456692913,832.4031758530183,0.00025370340306410486,25.0,30.0
428.50146,0.06310509251968503,833.9941732283464,0.00025370340306410486,25.0,30.0
430.00293,0.06345799803149606,832.3604199475066,0.00025370340306410486,25.0,30.0
431.50439,0.06379783070866141,832.4333333333333,0.00025370340306410486,25.0,30.0
433.00586,0.06414278149606299,833.9282414698163,0.00025370340306410486,25.0,30.0
434.50732,0.06453312795275591,834.203779527559,0.00025370340306410486,25.0,30.0
436.00879,0.06490125590551181,835.4178740157481,0.00025370340306410486,25.0,30.0
437.51025,0.06528286811023622,835.2585826771654,0.00025370340306410486,25.0,30.0
439.01172,0.0656306220472441,834.2353018372703,0.00025370340306410486,25.0,30.0
440.51318,0.0660298779527559,835.2008398950131,0.00025370340306410486,25.0,30.0
442.01465,0.06639851181102362,839.1061942257218,0.00025370340306410486,25.0,30.0
443.51611,0.06672511811023621,835.9876640419947,0.00025370340306410486,25.0,30.0
445.01758,0.06702438385826771,834.7349868766404,0.00025370340306410486,25.0,30.0
446.51904,0.06730331889763778,837.7244619422572,0.00025370340306410486,25.0,30.0
448.02051,0.06761627755905511,837.8870341207349,0.00025370340306410486,25.0,30.0
449.52197,0.06792597440944882,837.6749868766404,0.00025370340306410486,25.0,30.0
451.02344,0.06829376377952756,841.3665879265092,0.00025370340306410486,25.0,30.0
452.5249,0.06872678937007874,841.2619422572178,0.00025370340306410486,25.0,30.0
454.02637,0.06909402755905511,839.639343832021,0.00025370340306410486,25.0,30.0
455.52783,0.06949726181102361,841.3450656167979,0.00025370340306410486,25.0,30.0
457.0293,0.0698661594488189,841.0838582677166,0.00025370340306410486,25.0,30.0
458.53076,0.07023308070866142,839.9442257217847,0.00025370340306410486,25.0,30.0
460.03223,0.07057134251968504,841.2130446194225,0.00025370340306410486,25.0,30.0
461.53369,0.07088531102362206,841.6416797900262,0.00025370340306410486,25.0,30.0
463.03516,0.07124587204724409,843.9410236220473,0.00025370340306410486,25.0,30.0
464.53662,0.07162870275590552,843.2345406824146,0.00025370340306410486,25.0,30.0
466.03809,0.0719944094488189,843.2005249343832,0.00025370340306410486,25.0,30.0
467.53955,0.07234422244094488,843.576719160105,0.00025370340306410486,25.0,30.0
469.04102,0.07270383267716535,843.5435958005249,0.00025370340306410486,25.0,30.0
470.54248,0.07307600984251968,844.3551706036745,0.00025370340306410486,25.0,30.0
472.04395,0.07345396653543307,845.6279002624672,0.00025370340306410486,25.0,30.0
473.54541,0.07382934055118111,846.0831758530184,0.00025370340306410486,25.0,30.0
475.04688,0.07415338188976378,845.4903149606299,0.00025370340306410486,25.0,30.0
476.54834,0.07455623031496063,845.7381889763778,0.00025370340306410486,25.0,30.0
478.0498,0.0749010688976378,846.7754330708661,0.00025370340306410486,25.0,30.0
479.55127,0.07526278543307087,848.2184776902886,0.00025370340306410486,25.0,30.0
481.05273,0.07561969094488188,846.7641994750657,0.00025370340306410486,25.0,30.0
482.5542,0.07598526181102362,847.5197637795275,0.00025370340306410486,25.0,30.0
484.05566,0.07633127952755905,847.7840157480315,0.00025370340306410486,25.0,30.0
485.55713,0.07669047440944882,850.0112860892389,0.00025370340306410486,25.0,30.0
487.05859,0.07707529330708662,849.1570341207349,0.00025370340306410486,25.0,30.0
488.56006,0.07744397440944881,849.4704461942257,0.00025370340306410486,25.0,30.0
490.06152,0.0777967342519685,849.7571391076116,0.00025370340306410486,25.0,30.0
491.56299,0.07812840748031497,849.7507349081365,0.00025370340306410486,25.0,30.0
493.06445,0.07845496653543306,849.7493175853018,0.00025370340306410486,25.0,30.0
494.56592,0.07879322834645669,851.2373753280839,0.00025370340306410486,25.0,30.0
496.06738,0.07918433070866142,850.2142782152231,0.00025370340306410486,25.0,30.0
497.56885,0.07958374606299212,851.7953018372702,0.00025370340306410486,25.0,30.0
499.07031,0.0799357125984252,852.2401312335958,0.00025370340306410486,25.0,30.0
500.57178,0.08030526771653544,851.9921522309711,0.00025370340306410486,25.0,30.0
502.07324,0.08064209842519685,851.209501312336,0.00025370340306410486,25.0,30.0
503.57471,0.0810115,852.4669028871391,0.00025370340306410486,25.0,30.0
505.07617,0.08139735236220473,854.9280577427821,0.00025370340306410486,25.0,30.0
506.57764,0.08177450393700787,854.3786351706037,0.00025370340306410486,25.0,30.0
508.0791,0.0821450688976378,853.1814435695537,0.00025370340306410486,25.0,30.0
509.58057,0.08253193503937008,853.814094488189,0.00025370340306410486,25.0,30.0
511.08203,0.08286424803149607,854.5259055118111,0.00025370340306410486,25.0,30.0
512.5835,0.08323162007874016,855.1112598425196,0.00025370340306410486,25.0,30.0
514.08496,0.08360765748031496,855.4147244094488,0.00025370340306410486,25.0,30.0
515.58643,0.083932281496063,855.6895538057743,0.00025370340306410486,25.0,30.0
517.08789,0.08423402362204725,855.5989501312336,0.00025370340306410486,25.0,30.0
518.58936,0.08450946653543306,855.1485564304462,0.00025370340306410486,25.0,30.0
520.09082,0.08484108070866142,857.3927821522309,0.00025370340306410486,25.0,30.0
521.59229,0.08519310039370079,857.9503937007875,0.00025370340306410486,25.0,30.0
523.09375,0.0855483405511811,856.9691601049868,0.00025370340306410486,25.0,30.0
524.59521,0.08595959448818898,859.3634120734907,0.00025370340306410486,25.0,30.0
526.09668,0.08629937598425197,859.0189763779526,0.00025370340306410486,25.0,30.0
527.59814,0.08667698622047244,860.058530183727,0.00025370340306410486,25.0,30.0
529.09961,0.08706875787401575,858.975721784777,0.00025370340306410486,25.0,30.0
530.60107,0.08743295078740157,858.6569291338583,0.00025370340306410486,25.0,30.0
532.10254,0.08779565354330708,860.2601312335958,0.00025370340306410486,25.0,30.0
533.604,0.0881491220472441,860.2451968503937,0.00025370340306410486,25.0,30.0
535.10547,0.08852207874015748,859.7735170603675,0.00025370340306410486,25.0,30.0
536.60693,0.08890863385826772,860.9205249343831,0.00025370340306410486,25.0,30.0
538.1084,0.08928283070866141,861.1135170603675,0.00025370340306410486,25.0,30.0
539.60986,0.0896292283464567,862.0463254593176,0.00025370340306410486,25.0,30.0
541.11133,0.09004380905511811,861.4151968503937,0.00025370340306410486,25.0,30.0
542.61279,0.09042442913385826,861.5158792650918,0.00025370340306410486,25.0,30.0
544.11426,0.09077875393700786,861.7944881889763,0.00025370340306410486,25.0,30.0
545.61572,0.0911613562992126,863.2090288713911,0.00025370340306410486,25.0,30.0
547.11719,0.09146699409448819,861.7249606299212,0.00025370340306410486,25.0,30.0
548.61865,0.09182037401574804,864.4209448818898,0.00025370340306410486,25.0,30.0
550.12012,0.09221330118110235,864.8048556430447,0.00025370340306410486,25.0,30.0
551.62158,0.0925459842519685,864.6266404199475,0.00025370340306410486,25.0,30.0
553.12305,0.09290565944881889,864.8048556430447,0.00025370340306410486,25.0,30.0
554.62451,0.09325181299212598,864.8604724409448,0.00025370340306410486,25.0,30.0
556.12598,0.09363247834645669,864.8788713910761,0.00025370340306410486,25.0,30.0
557.62744,0.09396737401574802,865.7443044619422,0.00025370340306410486,25.0,30.0
559.12891,0.09428625787401575,865.2341207349081,0.00025370340306410486,25.0,30.0
560.63037,0.09466542322834645,866.659028871391,0.00025370340306410486,25.0,30.0
562.13184,0.09504217519685039,867.4588713910762,0.00025370340306410486,25.0,30.0
563.6333,0.09544397244094488,866.5585564304462,0.00025370340306410486,25.0,30.0
565.13477,0.09583149212598426,868.2850393700787,0.00025370340306410486,25.0,30.0
566.63623,0.09618110039370079,868.2163517060368,0.00025370340306410486,25.0,30.0
568.1377,0.0966272716535433,869.5533595800525,0.00025370340306410486,25.0,30.0
569.63916,0.0970165905511811,868.0781889763779,0.00025370340306410486,25.0,30.0
571.14063,0.09735930708661418,868.2414698162729,0.00025370340306410486,25.0,30.0
572.64209,0.09774696456692913,868.8882939632546,0.00025370340306410486,25.0,30.0
574.14355,0.09813675393700787,869.8125459317585,0.00025370340306410486,25.0,30.0
575.64502,0.09850563976377953,868.631968503937,0.00025370340306410486,25.0,30.0
577.14648,0.09892250787401574,871.1403937007874,0.00025370340306410486,25.0,30.0
578.64795,0.09927093700787401,869.0400787401575,0.00025370340306410486,25.0,30.0
580.14941,0.09959567716535432,869.8993175853019,0.00025370340306410486,25.0,30.0
581.65088,0.09989717322834644,870.0793700787401,0.00025370340306410486,25.0,30.0
583.15234,0.10029586811023622,870.9096587926509,0.00025370340306410486,25.0,30.0
584.65381,0.10066126181102361,871.4067716535433,0.00025370340306410486,25.0,30.0
586.15527,0.10104586614173229,870.126404199475,0.00025370340306410486,25.0,30.0
587.65674,0.10139124409448819,871.6358530183727,0.00025370340306410486,25.0,30.0
589.1582,0.10173665748031496,872.537375328084,0.00025370340306410486,25.0,30.0
590.65967,0.10205191732283465,872.024435695538,0.00025370340306410486,25.0,30.0
592.16113,0.10242942125984253,873.9364829396325,0.00025370340306410486,25.0,30.0
593.6626,0.10276673818897637,871.6559842519686,0.00025370340306410486,25.0,30.0
595.16406,0.10312815551181102,872.9402362204725,0.00025370340306410486,25.0,30.0
596.66553,0.10347455511811024,875.5693963254594,0.00025370340306410486,25.0,30.0
598.16699,0.10381653149606299,872.6514960629921,0.00025370340306410486,25.0,30.0
599.66846,0.10418549212598424,873.7206036745407,0.00025370340306410486,25.0,30.0
601.16992,0.10454122047244095,874.712939632546,0.00025370340306410486,25.0,30.0
602.67139,0.1048804625984252,873.8188451443569,0.00025370340306410486,25.0,30.0
604.17285,0.10528130314960629,876.4685039370078,0.00025370340306410486,25.0,30.0
605.67432,0.1056485531496063,875.2768766404199,0.00025370340306410486,25.0,30.0
607.17578,0.10608455708661417,877.1581102362205,0.00025370340306410486,25.0,30.0
608.67725,0.10646936023622047,876.4512073490814,0.00025370340306410486,25.0,30.0
610.17871,0.10687977559055117,875.5172965879265,0.00025370340306410486,25.0,30.0
611.68018,0.10727016338582678,875.8586614173228,0.00025370340306410486,25.0,30.0
613.18164,0.10763230708661417,877.0567979002625,0.00025370340306410486,25.0,30.0
614.68311,0.10800365157480314,877.8244094488189,0.00025370340306410486,25.0,30.0
616.18457,0.10835661023622048,877.4417322834645,0.00025370340306410486,25.0,30.0
617.68604,0.1087199153543307,878.5088976377953,0.00025370340306410486,25.0,30.0
619.1875,0.10909365354330709,877.4594225721784,0.00025370340306410486,25.0,30.0
620.68896,0.10950364763779528,877.8402887139108,0.00025370340306410486,25.0,30.0
622.19043,0.10986417322834645,876.6311811023622,0.00025370340306410486,25.0,30.0
623.69189,0.11025633070866142,878.7115748031496,0.00025370340306410486,25.0,30.0
625.19336,0.11067640354330707,880.0172440944881,0.00025370340306410486,25.0,30.0
626.69482,0.1110426437007874,878.0350918635171,0.00025370340306410486,25.0,30.0
628.19629,0.11144428346456693,881.2629396325459,0.00025370340306410486,25.0,30.0
629.69775,0.11181977952755905,879.810157480315,0.00025370340306410486,25.0,30.0
631.19922,0.11215944488188977,880.25280839895,0.00025370340306410486,25.0,30.0
632.70068,0.11255420866141733,880.3562992125984,0.00025370340306410486,25.0,30.0
634.20215,0.1129116003937008,880.1693700787401,0.00025370340306410486,25.0,30.0
635.70361,0.11325069094488188,880.0267979002624,0.00025370340306410486,25.0,30.0
637.20508,0.1136445748031496,882.4796062992126,0.00025370340306410486,25.0,30.0
638.70654,0.11403965354330708,881.7435958005249,0.00025370340306410486,25.0,30.0
640.20801,0.11440406496062991,881.836062992126,0.00025370340306410486,25.0,30.0
641.70947,0.11477426968503936,881.4176902887139,0.00025370340306410486,25.0,30.0
643.21094,0.11520243700787401,882.4319947506561,0.00025370340306410486,25.0,30.0
644.7124,0.11564161220472441,883.6559055118109,0.00025370340306410486,25.0,30.0
646.21387,0.11609698818897639,883.5198687664042,0.00025370340306410486,25.0,30.0
647.71533,0.11646161023622047,883.8654330708662,0.00025370340306410486,25.0,30.0
649.2168,0.11680376181102362,883.0592125984251,0.00025370340306410486,25.0,30.0
650.71826,0.11716569488188976,883.3770866141733,0.00025370340306410486,25.0,30.0
652.21973,0.11753410629921261,885.2794750656168,0.00025370340306410486,25.0,30.0
653.72119,0.1179335275590551,885.1388188976379,0.00025370340306410486,25.0,30.0
655.22266,0.11830310039370079,885.1010236220473,0.00025370340306410486,25.0,30.0
656.72412,0.11864960433070866,884.7351181102362,0.00025370340306410486,25.0,30.0
658.22559,0.1190301122047244,883.7533595800525,0.00025370340306410486,25.0,30.0
659.72705,0.11940573818897637,885.1930971128609,0.00025370340306410486,25.0,30.0
661.22852,0.1197811653543307,884.7346194225722,0.00025370340306410486,25.0,30.0
662.72998,0.12016860826771654,885.0479002624671,0.00025370340306410486,25.0,30.0
664.23145,0.12051734251968504,886.1874803149606,0.00025370340306410486,25.0,30.0
665.73291,0.1209749842519685,886.7221522309711,0.00025370340306410486,25.0,30.0
667.23438,0.12134132874015748,885.6722047244094,0.00025370340306410486,25.0,30.0
668.73584,0.12166934251968504,886.6654330708661,0.00025370340306410486,25.0,30.0
670.2373,0.12207153346456694,887.3027034120736,0.00025370340306410486,25.0,30.0
671.73877,0.12247267913385827,889.4239107611548,0.00025370340306410486,25.0,30.0
673.24023,0.12290125787401575,888.1313648293963,0.00025370340306410486,25.0,30.0
674.7417,0.12325645669291338,886.8613910761154,0.00025370340306410486,25.0,30.0
676.24316,0.12363561417322835,887.6659580052494,0.00025370340306410486,25.0,30.0
677.74463,0.12404319094488188,888.676220472441,0.00025370340306410486,25.0,30.0
679.24609,0.12441591929133858,888.7367191601049,0.00025370340306410486,25.0,30.0
680.74756,0.12483318700787402,888.9981102362204,0.00025370340306410486,25.0,30.0
682.24902,0.12532228543307086,888.0707611548556,0.00025370340306410486,25.0,30.0
683.75049,0.1256785413385827,886.7724409448819,0.00025370340306410486,25.0,30.0
685.25195,0.12600344488188975,888.1739895013123,0.00025370340306410486,25.0,30.0
686.75342,0.12638871653543307,889.097217847769,0.00025370340306410486,25.0,30.0
688.25488,0.1268239468503937,888.6502099737534,0.00025370340306410486,25.0,30.0
689.75635,0.1272385748031496,888.9677952755904,0.00025370340306410486,25.0,30.0
691.25781,0.12758082086614175,889.0569291338583,0.00025370340306410486,25.0,30.0
692.75928,0.12796331102362205,889.4185826771653,0.00025370340306410486,25.0,30.0
694.26074,0.1283540964566929,890.8477427821522,0.00025370340306410486,25.0,30.0
695.76221,0.12877671456692913,892.0650393700787,0.00025370340306410486,25.0,30.0
697.26367,0.1291962125984252,890.5190813648294,0.00025370340306410486,25.0,30.0
698.76514,0.12958100196850392,891.2261154855643,0.00025370340306410486,25.0,30.0
700.2666,0.12994585826771654,889.6485564304462,0.00025370340306410486,25.0,30.0
701.76807,0.13036447440944882,891.9350393700787,0.00025370340306410486,25.0,30.0
703.26953,0.13071087401574802,892.0035958005249,0.00025370340306410486,25.0,30.0
704.771,0.13111447244094487,892.567874015748,0.00025370340306410486,25.0,30.0
706.27246,0.13147913976377953,891.9664829396326,0.00025370340306410486,25.0,30.0
707.77393,0.13186445866141733,891.3201837270341,0.00025370340306410486,25.0,30.0
709.27539,0.1322799901574803,892.9684251968504,0.00025370340306410486,25.0,30.0
710.77686,0.13269612007874015,893.028031496063,0.00025370340306410486,25.0,30.0
712.27832,0.13311798622047244,893.32687664042,0.00025370340306410486,25.0,30.0
713.77979,0.1335797342519685,895.1633333333333,0.00025370340306410486,25.0,30.0
715.28125,0.13403147440944882,894.2239895013123,0.00025370340306410486,25.0,30.0
716.78271,0.1344346279527559,894.1121784776902,0.00025370340306410486,25.0,30.0
718.28418,0.13482411023622046,894.2639107611549,0.00025370340306410486,25.0,30.0
719.78564,0.13528318307086615,894.4246981627297,0.00025370340306410486,25.0,30.0
721.28711,0.13566321062992126,893.1879002624672,0.00025370340306410486,25.0,30.0
722.78857,0.1360356692913386,894.567060367454,0.00025370340306410486,25.0,30.0
724.29004,0.1364360649606299,895.180997375328,0.00025370340306410486,25.0,30.0
725.7915,0.13684962401574804,896.1020734908137,0.00025370340306410486,25.0,30.0
727.29297,0.1372576692913386,896.3846719160106,0.00025370340306410486,25.0,30.0
728.79443,0.1376199783464567,894.2750656167979,0.00025370340306410486,25.0,30.0
730.2959,0.13802694488188977,895.9852755905512,0.00025370340306410486,25.0,30.0
731.79736,0.13841282677165354,895.582782152231,0.00025370340306410486,25.0,30.0
733.29883,0.13878264566929133,895.5914435695538,0.00025370340306410486,25.0,30.0
734.80029,0.13913327952755905,895.3878477690289,0.00025370340306410486,25.0,30.0
736.30176,0.1395108188976378,896.5162204724409,0.00025370340306410486,25.0,30.0
737.80322,0.13991367913385827,898.4350656167979,0.00025370340306410486,25.0,30.0
739.30469,0.1404148622047244,898.3427296587927,0.00025370340306410486,25.0,30.0
740.80615,0.14089924409448817,899.4833333333333,0.00025370340306410486,25.0,30.0
742.30762,0.1413342755905512,897.1741207349081,0.00025370340306410486,25.0,30.0
743.80908,0.141684781496063,897.5235958005248,0.00025370340306410486,25.0,30.0
745.31055,0.14206805708661419,897.5896062992126,0.00025370340306410486,25.0,30.0
746.81201,0.14245131102362205,898.5655905511811,0.00025370340306410486,25.0,30.0
748.31348,0.14281136811023623,899.0986089238845,0.00025370340306410486,25.0,30.0
749.81494,0.14326883267716534,899.9494488188976,0.00025370340306410486,25.0,30.0
751.31641,0.14381151771653544,899.1030183727034,0.00025370340306410486,25.0,30.0
752.81787,0.1442421496062992,898.1900262467191,0.00025370340306410486,25.0,30.0
754.31934,0.14465324606299212,898.4111548556431,0.00025370340306410486,25.0,30.0
755.8208,0.14504122637795275,898.1083989501312,0.00025370340306410486,25.0,30.0
757.32227,0.14546024212598427,899.8688976377953,0.00025370340306410486,25.0,30.0
758.82373,0.14589602559055118,899.929186351706,0.00025370340306410486,25.0,30.0
760.3252,0.14634224999999998,899.3568503937007,0.00025370340306410486,25.0,30.0
761.82666,0.1467425531496063,900.1933858267716,0.00025370340306410486,25.0,30.0
763.32813,0.1472085472440945,901.170341207349,0.00025370340306410486,25.0,30.0
764.82959,0.14765424606299213,901.6640682414697,0.00025370340306410486,25.0,30.0
766.33105,0.14807414173228345,899.8910761154856,0.00025370340306410486,25.0,30.0
767.83252,0.14848244488188977,900.7097375328084,0.00025370340306410486,25.0,30.0
769.33398,0.148878874015748,900.0313385826771,0.00025370340306410486,25.0,30.0
770.83545,0.1492698838582677,900.7933595800524,0.00025370340306410486,25.0,30.0
772.33691,0.14968614173228348,900.9300524934383,0.00025370340306410486,25.0,30.0
773.83838,0.15010089763779527,902.3620734908136,0.00025370340306410486,25.0,30.0
775.33984,0.1505699094488189,899.8869553805774,0.00025370340306410486,25.0,30.0
776.84131,0.15097425984251966,902.2922309711286,0.00025370340306410486,25.0,30.0
778.34277,0.15138295078740158,902.3182414698163,0.00025370340306410486,25.0,30.0
779.84424,0.15174781692913386,901.1347769028871,0.00025370340306410486,25.0,30.0
781.3457,0.15219728149606299,902.372467191601,0.00025370340306410486,25.0,30.0
782.84717,0.1526726751968504,902.565905511811,0.00025370340306410486,25.0,30.0
784.34863,0.15315162401574803,904.4888451443569,0.00025370340306410486,25.0,30.0
785.8501,0.15360459645669292,901.9483202099738,0.00025370340306410486,25.0,30.0
787.35156,0.1540628248031496,901.8528346456693,0.00025370340306410486,25.0,30.0
788.85303,0.15449017125984252,902.6754855643045,0.00025370340306410486,25.0,30.0
790.35449,0.15491316338582675,904.7904724409448,0.00025370340306410486,25.0,30.0
791.85596,0.15533536023622047,902.2174540682414,0.00025370340306410486,25.0,30.0
793.35742,0.15574132874015748,902.6436482939632,0.00025370340306410486,25.0,30.0
794.85889,0.156197844488189,904.0637007874016,0.00025370340306410486,25.0,30.0
796.36035,0.15662774803149607,901.4952755905512,0.00025370340306410486,25.0,30.0
797.86182,0.15704765551181102,904.4052230971129,0.00025370340306410486,25.0,30.0
799.36328,0.15753055905511812,903.3620209973753,0.00025370340306410486,25.0,30.0
800.86475,0.15801636023622045,904.0921522309711,0.00025370340306410486,25.0,30.0
802.36621,0.15850433267716535,903.1805511811024,0.00025370340306410486,25.0,30.0
803.86768,0.15889912992125985,903.605091863517,0.00025370340306410486,25.0,30.0
805.36914,0.15935389763779526,904.5739632545932,0.00025370340306410486,25.0,30.0
806.87061,0.15976636614173229,904.6735433070866,0.00025370340306410486,25.0,30.0
808.37207,0.16017356692913387,904.7447244094488,0.00025370340306410486,25.0,30.0
809.87354,0.16056697047244095,904.4940419947507,0.00025370340306410486,25.0,30.0
811.375,0.16105275984251968,904.3722834645669,0.00025370340306410486,25.0,30.0
812.87646,0.16153271653543308,903.9555905511811,0.00025370340306410486,25.0,30.0
814.37793,0.16195582874015746,904.794908136483,0.00025370340306410486,25.0,30.0
815.87939,0.16242221062992127,905.170839895013,0.00025370340306410486,25.0,30.0
817.38086,0.16285123622047243,905.1421522309712,0.00025370340306410486,25.0,30.0
818.88232,0.1632359783464567,905.0328871391075,0.00025370340306410486,25.0,30.0
820.38379,0.16370171653543306,906.1441469816273,0.00025370340306410486,25.0,30.0
821.88525,0.16419533267716535,907.0054855643044,0.00025370340306410486,25.0,30.0
823.38672,0.16463958661417322,905.5387139107611,0.00025370340306410486,25.0,30.0
824.88818,0.16507867716535432,905.6478477690289,0.00025370340306410486,25.0,30.0
826.38965,0.16563703740157482,906.2324409448819,0.00025370340306410486,25.0,30.0
827.89111,0.16617378346456693,906.9330183727034,0.00025370340306410486,25.0,30.0
829.39258,0.16667649212598426,906.105249343832,0.00025370340306410486,25.0,30.0
830.89404,0.1671751062992126,905.978687664042,0.00025370340306410486,25.0,30.0
832.39551,0.16761876181102361,904.7938057742782,0.00025370340306410486,25.0,30.0
833.89697,0.1680866712598425,906.0316797900263,0.00025370340306410486,25.0,30.0
835.39844,0.16852910629921258,907.2695538057743,0.00025370340306410486,25.0,30.0
836.8999,0.16896164960629922,905.6930183727034,0.00025370340306410486,25.0,30.0
838.40137,0.16940412007874014,905.794593175853,0.00025370340306410486,25.0,30.0
839.90283,0.16988446653543307,907.6569291338583,0.00025370340306410486,25.0,30.0
841.4043,0.17030429133858266,907.3447244094489,0.00025370340306410486,25.0,30.0
842.90576,0.170783968503937,907.6779265091864,0.00025370340306410486,25.0,30.0
844.40723,0.17124719488188977,905.8312335958005,0.00025370340306410486,25.0,30.0
845.90869,0.171748437007874,907.7648818897637,0.00025370340306410486,25.0,30.0
847.41016,0.17226015748031495,907.5240157480314,0.00025370340306410486,25.0,30.0
848.91162,0.17278012598425196,908.0168503937007,0.00025370340306410486,25.0,30.0
850.41309,0.17327750787401575,907.2957742782152,0.00025370340306410486,25.0,30.0
851.91455,0.17373124212598423,908.099501312336,0.00025370340306410486,25.0,30.0
853.41602,0.17418578543307087,906.3502887139107,0.00025370340306410486,25.0,30.0
854.91748,0.1746250649606299,907.1288451443569,0.00025370340306410486,25.0,30.0
856.41895,0.1751354940944882,909.4211286089238,0.00025370340306410486,25.0,30.0
857.92041,0.17562581299212598,907.0751443569553,0.00025370340306410486,25.0,30.0
859.42188,0.1761755374015748,909.3021522309712,0.00025370340306410486,25.0,30.0
860.92334,0.1766975118110236,908.2630446194225,0.00025370340306410486,25.0,30.0
862.4248,0.1772720866141732,908.3378215223097,0.00025370340306410486,25.0,30.0
863.92627,0.17775249015748032,908.3897112860893,0.00025370340306410486,25.0,30.0
865.42773,0.17819721456692914,907.350183727034,0.00025370340306410486,25.0,30.0
866.9292,0.17868288582677164,908.1435433070866,0.00025370340306410486,25.0,30.0
868.43066,0.17915399803149606,910.4557480314961,0.00025370340306410486,25.0,30.0
869.93213,0.17971957283464568,908.6323359580052,0.00025370340306410486,25.0,30.0
871.43359,0.1802095748031496,908.234593175853,0.00025370340306410486,25.0,30.0
872.93506,0.18069097637795276,909.0065354330708,0.00025370340306410486,25.0,30.0
874.43652,0.18114232874015748,908.1604461942258,0.00025370340306410486,25.0,30.0
875.93799,0.18161803937007873,908.9152230971129,0.00025370340306410486,25.0,30.0
877.43945,0.18211521062992125,908.1732020997375,0.00025370340306410486,25.0,30.0
878.94092,0.1825237716535433,907.9363517060368,0.00025370340306410486,25.0,30.0
880.44238,0.18301862007874017,909.8907086614173,0.00025370340306410486,25.0,30.0
881.94385,0.1835558937007874,908.4792388451443,0.00025370340306410486,25.0,30.0
883.44531,0.1840838188976378,908.0605511811024,0.00025370340306410486,25.0,30.0
884.94678,0.1846622874015748,909.3237270341207,0.00025370340306410486,25.0,30.0
886.44824,0.18517220078740157,907.8372965879265,0.00025370340306410486,25.0,30.0
887.94971,0.1856252322834646,908.3274278215223,0.00025370340306410486,25.0,30.0
889.45117,0.18611782677165353,908.6724934383202,0.00025370340306410486,25.0,30.0
890.95264,0.1865288405511811,907.5683464566929,0.00025370340306410486,25.0,30.0
892.4541,0.1870863779527559,911.0853280839895,0.00025370340306410486,25.0,30.0
892.5542,0.18712717519685038,912.5245406824147,0.00025370340306410486,25.0,30.0