File: datasets/am_bench_2022/csv/30-XY.01-1.csv
Time(s),Strain(%),Stress(MPa),SR(s-1),Temp(C),Angle(deg)
13.59668,1.2004252362204723e-06,25.795181084437086,0.00025370340306410486,25.0,30.0
16.399414,1.876841437007874e-05,36.95474441225166,0.00025370340306410486,25.0,30.0
18.101074,5.3402653543307086e-05,44.970801427980135,0.00025370340306410486,25.0,30.0
19.802734,3.605891338582677e-05,53.798722061258275,0.00025370340306410486,25.0,30.0
21.404297,8.957598622047243e-05,62.76182481374172,0.00025370340306410486,25.0,30.0
23.005859,6.690912204724409e-05,73.22297185430463,0.00025370340306410486,25.0,30.0
24.607422,9.611777755905511e-05,82.23978942466887,0.00025370340306410486,25.0,30.0
26.208984,0.00014641548228346458,90.89662665562913,0.00025370340306410486,25.0,30.0
27.810547,0.00016510331496062992,99.88360151076158,0.00025370340306410486,25.0,30.0
29.412109,0.00018951316732283464,109.77847682119206,0.00025370340306410486,25.0,30.0
31.013672,0.00020182013779527559,118.58535026903972,0.00025370340306410486,25.0,30.0
32.615234,0.0002301432874015748,128.9906327607616,0.00025370340306410486,25.0,30.0
34.216797,0.0002192963779527559,138.07211558360927,0.00025370340306410486,25.0,30.0
35.818359,0.00025970929133858266,147.00319484685429,0.00025370340306410486,25.0,30.0
37.419922,0.00026176789370078735,155.3609995860927,0.00025370340306410486,25.0,30.0
39.021484,0.00032471397637795274,168.1299720612583,0.00025370340306410486,25.0,30.0
40.623047,0.0003368886614173228,178.77595974751657,0.00025370340306410486,25.0,30.0
42.224609,0.00037339435039370075,188.4508614445364,0.00025370340306410486,25.0,30.0
43.826172,0.0003685414763779527,199.45269298427152,0.00025370340306410486,25.0,30.0
45.427734,0.00041536009842519685,211.86009157698675,0.00025370340306410486,25.0,30.0
47.029297,0.0004252174606299213,223.29644557119207,0.00025370340306410486,25.0,30.0
48.630859,0.0004344133464566929,234.1330918874172,0.00025370340306410486,25.0,30.0
50.232422,0.0005019055511811024,247.0305748137417,0.00025370340306410486,25.0,30.0
51.833984,0.0005073268897637796,259.45221957781456,0.00025370340306410486,25.0,30.0
53.435547,0.0005530792913385826,271.35836610099335,0.00025370340306410486,25.0,30.0
55.037109,0.0005601268700787402,281.971440397351,0.00025370340306410486,25.0,30.0
56.638672,0.0006075151377952755,293.6357874586093,0.00025370340306410486,25.0,30.0
58.240234,0.0006324420472440945,307.0926634933775,0.00025370340306410486,25.0,30.0
59.841797,0.0006786500393700787,318.9255742963576,0.00025370340306410486,25.0,30.0
61.443359,0.0006949372244094489,328.8428187086093,0.00025370340306410486,25.0,30.0
63.044922,0.0007256793503937007,340.2297185430464,0.00025370340306410486,25.0,30.0
64.646484,0.0007470120078740157,352.88547702814566,0.00025370340306410486,25.0,30.0
66.248047,0.0008008565748031495,364.45527214403967,0.00025370340306410486,25.0,30.0
67.849609,0.0008113776771653542,376.269013865894,0.00025370340306410486,25.0,30.0
69.451172,0.0008634879133858267,387.4697847682119,0.00025370340306410486,25.0,30.0
71.052734,0.0008981528149606298,398.70723820364236,0.00025370340306410486,25.0,30.0
72.654297,0.0009560750393700786,409.8640573261589,0.00025370340306410486,25.0,30.0
74.255859,0.0009912804133858269,420.34250827814566,0.00025370340306410486,25.0,30.0
75.857422,0.0010383352952755905,431.0356477649006,0.00025370340306410486,25.0,30.0
77.458984,0.001053283307086614,442.55724855132445,0.00025370340306410486,25.0,30.0
79.060547,0.0010737971456692913,451.10725372516555,0.00025370340306410486,25.0,30.0
80.662109,0.0011447152559055118,462.75807119205297,0.00025370340306410486,25.0,30.0
82.263672,0.0011535301771653543,471.33342818708604,0.00025370340306410486,25.0,30.0
83.865234,0.0011995585039370079,480.8935482201986,0.00025370340306410486,25.0,30.0
85.466797,0.0012602174999999998,492.540278352649,0.00025370340306410486,25.0,30.0
87.068359,0.0012796757086614172,501.7091525248344,0.00025370340306410486,25.0,30.0
88.669922,0.0012926118503937007,508.95726407284764,0.00025370340306410486,25.0,30.0
90.271484,0.0013260812401574803,519.1707108857617,0.00025370340306410486,25.0,30.0
91.873047,0.0013673589173228346,526.4593336092715,0.00025370340306410486,25.0,30.0
93.474609,0.0014056174803149606,535.6483598923841,0.00025370340306410486,25.0,30.0
95.076172,0.0014508850787401575,543.8346181705298,0.00025370340306410486,25.0,30.0
96.677734,0.0015024113188976378,551.5116928807947,0.00025370340306410486,25.0,30.0
98.279297,0.0015230274606299213,560.7861392798013,0.00025370340306410486,25.0,30.0
99.880859,0.001560252775590551,565.216758071192,0.00025370340306410486,25.0,30.0
101.48242,0.001608694566929134,573.0635865066224,0.00025370340306410486,25.0,30.0
103.08398,0.0016057388976377953,578.4697330298013,0.00025370340306410486,25.0,30.0
104.68555,0.001653315,583.4942570364238,0.00025370340306410486,25.0,30.0
106.28711,0.0016697753937007873,589.5516608029801,0.00025370340306410486,25.0,30.0
107.88867,0.0017192914960629923,597.1140055877484,0.00025370340306410486,25.0,30.0
109.49023,0.0017564789566929136,600.7880536009934,0.00025370340306410486,25.0,30.0
111.0918,0.0017917559251968502,606.6209385347681,0.00025370340306410486,25.0,30.0
112.69336,0.0018224780118110235,613.7988151903972,0.00025370340306410486,25.0,30.0
114.29492,0.0018608228346456692,618.6859737168875,0.00025370340306410486,25.0,30.0
115.89648,0.001888289153543307,624.315190397351,0.00025370340306410486,25.0,30.0
117.49805,0.0019638722047244095,628.275093129139,0.00025370340306410486,25.0,30.0
119.09961,0.0019707681102362207,631.0863255380794,0.00025370340306410486,25.0,30.0
120.70117,0.0020352322834645666,638.1188948675497,0.00025370340306410486,25.0,30.0
122.30273,0.0020770141732283465,641.7338317466887,0.00025370340306410486,25.0,30.0
123.9043,0.002091286811023622,647.9080091059602,0.00025370340306410486,25.0,30.0
125.50586,0.002149071850393701,650.4027835264901,0.00025370340306410486,25.0,30.0
127.10742,0.0021682257874015747,652.5114083195365,0.00025370340306410486,25.0,30.0
128.70898,0.002211596850393701,658.2466628725166,0.00025370340306410486,25.0,30.0
130.31055,0.002280862992125984,662.1144712334437,0.00025370340306410486,25.0,30.0
131.91211,0.0023171242125984252,665.0771161009933,0.00025370340306410486,25.0,30.0
133.51367,0.002365357874015748,667.781948468543,0.00025370340306410486,25.0,30.0
135.11523,0.0024215511811023624,673.9404232201987,0.00025370340306410486,25.0,30.0
136.7168,0.002511173228346457,677.7159561258278,0.00025370340306410486,25.0,30.0
138.31836,0.0025509425196850394,681.2664786837748,0.00025370340306410486,25.0,30.0
139.91992,0.002621044881889764,682.5284043874173,0.00025370340306410486,25.0,30.0
141.52148,0.00269731437007874,688.8832264072847,0.00025370340306410486,25.0,30.0
143.12305,0.0027754714566929134,689.6642953228477,0.00025370340306410486,25.0,30.0
144.72461,0.0028722893700787403,695.8143625827814,0.00025370340306410486,25.0,30.0
146.32617,0.0029226265748031493,695.3074555049668,0.00025370340306410486,25.0,30.0
147.92773,0.003013551968503937,700.6756260347681,0.00025370340306410486,25.0,30.0
149.5293,0.003162922244094488,703.291675289735,0.00025370340306410486,25.0,30.0
151.13086,0.0032614187007874015,708.0978114652319,0.00025370340306410486,25.0,30.0
152.73242,0.0034147543307086613,708.8064983443708,0.00025370340306410486,25.0,30.0
154.33398,0.003561048228346456,711.055903352649,0.00025370340306410486,25.0,30.0
155.93555,0.003682589173228346,714.9850993377482,0.00025370340306410486,25.0,30.0
157.53711,0.003838557086614173,716.632553807947,0.00025370340306410486,25.0,30.0
159.13867,0.00401845157480315,719.4300496688742,0.00025370340306410486,25.0,30.0
160.74023,0.004211644488188976,720.559990687086,0.00025370340306410486,25.0,30.0
162.3418,0.004406318897637795,724.8794495033112,0.00025370340306410486,25.0,30.0
163.94336,0.004636131102362205,726.1899058360927,0.00025370340306410486,25.0,30.0
165.54492,0.004825754527559055,727.7638917632449,0.00025370340306410486,25.0,30.0
167.14648,0.005080175787401575,729.837851821192,0.00025370340306410486,25.0,30.0
168.74805,0.0053236462598425195,731.5595250413907,0.00025370340306410486,25.0,30.0
170.34961,0.005504880905511811,731.1908112582781,0.00025370340306410486,25.0,30.0
171.95117,0.0057913084645669285,733.9941018211921,0.00025370340306410486,25.0,30.0
173.55273,0.006088978543307086,734.6866980546357,0.00025370340306410486,25.0,30.0
175.1543,0.006323580511811024,736.4031198261589,0.00025370340306410486,25.0,30.0
176.75586,0.006597268307086614,738.7454211506622,0.00025370340306410486,25.0,30.0
178.35742,0.006899283858267716,739.2623137417218,0.00025370340306410486,25.0,30.0
179.95898,0.007274491732283465,742.5111754966888,0.00025370340306410486,25.0,30.0
181.56055,0.007602510826771654,742.5971388658941,0.00025370340306410486,25.0,30.0
183.16211,0.007883589173228346,744.0076314155629,0.00025370340306410486,25.0,30.0
184.76367,0.008225875787401573,746.2021419701986,0.00025370340306410486,25.0,30.0
186.36523,0.008581825196850393,746.6993222268212,0.00025370340306410486,25.0,30.0
187.9668,0.00896148346456693,749.1385295943709,0.00025370340306410486,25.0,30.0
189.56836,0.009277677755905512,747.0461765314569,0.00025370340306410486,25.0,30.0
191.16992,0.009569689173228346,749.0613358857615,0.00025370340306410486,25.0,30.0
192.77148,0.009929498818897637,751.4617653145696,0.00025370340306410486,25.0,30.0
194.37305,0.010266026574803149,752.0839197019867,0.00025370340306410486,25.0,30.0
195.97461,0.010619937992125983,753.3941949503311,0.00025370340306410486,25.0,30.0
197.57617,0.010997240354330709,754.3457160596026,0.00025370340306410486,25.0,30.0
199.17773,0.011350210826771654,757.3464921357615,0.00025370340306410486,25.0,30.0
200.7793,0.011755573031496063,756.4208143625827,0.00025370340306410486,25.0,30.0
202.38086,0.01206342933070866,756.7755070364238,0.00025370340306410486,25.0,30.0
203.98242,0.012397766141732283,757.2617446192053,0.00025370340306410486,25.0,30.0
205.58398,0.01278228346456693,759.8291597682119,0.00025370340306410486,25.0,30.0
207.18555,0.013128819094488188,760.9921875,0.00025370340306410486,25.0,30.0
208.78711,0.013575364173228348,761.0987944950331,0.00025370340306410486,25.0,30.0
210.38867,0.013877470472440945,760.6306136175497,0.00025370340306410486,25.0,30.0
211.99023,0.014202409645669292,762.6702711092714,0.00025370340306410486,25.0,30.0
213.5918,0.014622251377952755,764.423090852649,0.00025370340306410486,25.0,30.0
215.19336,0.015023960826771652,765.7989704056291,0.00025370340306410486,25.0,30.0
216.79492,0.015486219488188978,766.5080970612582,0.00025370340306410486,25.0,30.0
218.39648,0.015860498228346457,765.8756208609271,0.00025370340306410486,25.0,30.0
219.99805,0.016133164566929134,765.267798013245,0.00025370340306410486,25.0,30.0
221.59961,0.01653426692913386,768.2151541804636,0.00025370340306410486,25.0,30.0
223.20117,0.016901931102362204,767.6610875413907,0.00025370340306410486,25.0,30.0
224.80273,0.0173593218503937,770.1984944122516,0.00025370340306410486,25.0,30.0
226.4043,0.017764856299212598,769.9772609685431,0.00025370340306410486,25.0,30.0
228.00586,0.01811979153543307,770.5488927980132,0.00025370340306410486,25.0,30.0
229.60742,0.018519099999999997,771.3637468956953,0.00025370340306410486,25.0,30.0
231.20898,0.018896640551181104,772.6637003311257,0.00025370340306410486,25.0,30.0
232.81055,0.01935275688976378,774.2831901903974,0.00025370340306410486,25.0,30.0
234.41211,0.01977597244094488,774.4245395281456,0.00025370340306410486,25.0,30.0
236.01367,0.02017607874015748,774.6582160596025,0.00025370340306410486,25.0,30.0
237.61523,0.02057604527559055,775.80078125,0.00025370340306410486,25.0,30.0
239.2168,0.02090015748031496,775.3466990894038,0.00025370340306410486,25.0,30.0
240.81836,0.021349253937007873,778.5862737996689,0.00025370340306410486,25.0,30.0
242.41992,0.021747251968503935,777.3559861341059,0.00025370340306410486,25.0,30.0
244.02148,0.022133712598425198,779.6865945778145,0.00025370340306410486,25.0,30.0
245.62305,0.022582468503937008,778.4560482201987,0.00025370340306410486,25.0,30.0
247.22461,0.022903312992125984,778.7539062499999,0.00025370340306410486,25.0,30.0
248.82617,0.02326340157480315,779.6608288493378,0.00025370340306410486,25.0,30.0
250.42773,0.023645251968503936,782.5622930463576,0.00025370340306410486,25.0,30.0
252.0293,0.024042450787401574,782.7338058774834,0.00025370340306410486,25.0,30.0
253.63086,0.024469053149606297,782.3378259519868,0.00025370340306410486,25.0,30.0
255.23242,0.02483286811023622,782.7322278559602,0.00025370340306410486,25.0,30.0
256.83398,0.025188545275590554,783.3116980546357,0.00025370340306410486,25.0,30.0
258.43555,0.025663370078740158,785.2588990066224,0.00025370340306410486,25.0,30.0
260.03711,0.02604772244094488,785.2266401076158,0.00025370340306410486,25.0,30.0
261.63867,0.026467096456692915,787.457988410596,0.00025370340306410486,25.0,30.0
263.24023,0.02689242519685039,786.9310585678808,0.00025370340306410486,25.0,30.0
264.8418,0.027343889763779525,786.5003362996689,0.00025370340306410486,25.0,30.0
266.44336,0.027698108267716532,786.6866980546357,0.00025370340306410486,25.0,30.0
268.04492,0.02801754133858268,788.377431705298,0.00025370340306410486,25.0,30.0
269.64648,0.028479673228346457,790.9526593543046,0.00025370340306410486,25.0,30.0
271.24805,0.028850246062992125,791.2567518625827,0.00025370340306410486,25.0,30.0
272.84961,0.029280911417322836,792.795581539735,0.00025370340306410486,25.0,30.0
274.45117,0.029629029527559057,790.3404646109271,0.00025370340306410486,25.0,30.0
276.05273,0.0300339625984252,792.4195467715232,0.00025370340306410486,25.0,30.0
277.6543,0.03046503346456693,792.556524213576,0.00025370340306410486,25.0,30.0
279.25586,0.030848281496062994,794.3868998344371,0.00025370340306410486,25.0,30.0
280.85742,0.03126449212598425,795.8347733857617,0.00025370340306410486,25.0,30.0
282.45898,0.031565179133858264,791.6328642384105,0.00025370340306410486,25.0,30.0
284.06055,0.03189966141732283,793.3531922599337,0.00025370340306410486,25.0,30.0
285.66211,0.0323423188976378,795.7980908526489,0.00025370340306410486,25.0,30.0
287.26367,0.03274110039370079,795.3436723923841,0.00025370340306410486,25.0,30.0
288.86523,0.03319350787401575,797.7455246274834,0.00025370340306410486,25.0,30.0
290.4668,0.0335533405511811,796.3140004139073,0.00025370340306410486,25.0,30.0
292.06836,0.033925129921259845,796.7709540562914,0.00025370340306410486,25.0,30.0
293.66992,0.034324244094488185,799.268755173841,0.00025370340306410486,25.0,30.0
295.27148,0.03469747440944882,797.2803187086092,0.00025370340306410486,25.0,30.0
296.87305,0.035099312992125986,798.8173634105959,0.00025370340306410486,25.0,30.0
298.47461,0.03546760039370079,800.2643832781456,0.00025370340306410486,25.0,30.0
300.07617,0.035939785433070866,801.1326055463576,0.00025370340306410486,25.0,30.0
301.67773,0.036330590551181104,799.8184240480132,0.00025370340306410486,25.0,30.0
303.2793,0.03674995669291339,801.1415562913908,0.00025370340306410486,25.0,30.0
304.88086,0.03714272244094488,802.2940035182119,0.00025370340306410486,25.0,30.0
306.48242,0.03758864566929134,802.4998965231788,0.00025370340306410486,25.0,30.0
308.08398,0.03797856102362205,803.5009830298012,0.00025370340306410486,25.0,30.0
309.68555,0.03839558464566929,802.2069536423841,0.00025370340306410486,25.0,30.0
311.28711,0.038767033464566926,806.05512727649,0.00025370340306410486,25.0,30.0
312.88867,0.039189897637795276,805.8282802152318,0.00025370340306410486,25.0,30.0
314.49023,0.03951826968503937,805.2143263658941,0.00025370340306410486,25.0,30.0
316.0918,0.03992015551181102,805.5154439155629,0.00025370340306410486,25.0,30.0
317.69336,0.04026493503937008,804.8952555877484,0.00025370340306410486,25.0,30.0
319.29492,0.04062656496062992,808.2929170115893,0.00025370340306410486,25.0,30.0
320.89648,0.04105174015748032,807.0825745033112,0.00025370340306410486,25.0,30.0
322.49805,0.041450874015748033,806.0193242963576,0.00025370340306410486,25.0,30.0
324.09961,0.04185605708661417,808.537665562914,0.00025370340306410486,25.0,30.0
325.70117,0.04222570866141732,808.9586092715232,0.00025370340306410486,25.0,30.0
327.30273,0.04256337401574803,809.8967301324503,0.00025370340306410486,25.0,30.0
328.9043,0.042963566929133855,811.2912355132449,0.00025370340306410486,25.0,30.0
330.50586,0.043371507874015745,811.649653352649,0.00025370340306410486,25.0,30.0
332.10742,0.043800885826771656,809.6513089817881,0.00025370340306410486,25.0,30.0
333.70898,0.04419551181102362,812.0044236341059,0.00025370340306410486,25.0,30.0
335.31055,0.044650950787401576,814.992885968543,0.00025370340306410486,25.0,30.0
336.91211,0.04503885433070866,812.5375362168874,0.00025370340306410486,25.0,30.0
338.51367,0.045415942913385826,814.1054170115895,0.00025370340306410486,25.0,30.0
340.11523,0.04588829527559055,815.2774730960265,0.00025370340306410486,25.0,30.0
341.7168,0.04631367716535433,815.4811672185431,0.00025370340306410486,25.0,30.0
343.31836,0.046669580708661416,812.9448985927152,0.00025370340306410486,25.0,30.0
344.91992,0.0470844625984252,815.7336506622516,0.00025370340306410486,25.0,30.0
346.52148,0.04745486811023622,815.0982512417219,0.00025370340306410486,25.0,30.0
348.12305,0.04787316338582677,817.0696916390727,0.00025370340306410486,25.0,30.0
349.72461,0.04829882283464567,817.8219681291391,0.00025370340306410486,25.0,30.0
351.32617,0.04868514960629921,817.4638607201987,0.00025370340306410486,25.0,30.0
352.92773,0.049010708661417324,816.4581436258278,0.00025370340306410486,25.0,30.0
354.5293,0.04936418503937008,820.0807119205297,0.00025370340306410486,25.0,30.0
356.13086,0.04973784645669291,817.4966887417219,0.00025370340306410486,25.0,30.0
357.73242,0.05010538385826772,818.919624379139,0.00025370340306410486,25.0,30.0
359.33398,0.050479759842519685,820.5752276490066,0.00025370340306410486,25.0,30.0
360.93555,0.050874840551181105,819.9372154387418,0.00025370340306410486,25.0,30.0
362.53711,0.051262153543307085,819.7190862996688,0.00025370340306410486,25.0,30.0
364.13867,0.05167212992125984,823.0259209437086,0.00025370340306410486,25.0,30.0
365.74023,0.05207933464566929,821.9893936258278,0.00025370340306410486,25.0,30.0
367.3418,0.052508224409448814,823.7907698675497,0.00025370340306410486,25.0,30.0
368.94336,0.05292920078740157,821.7611496274834,0.00025370340306410486,25.0,30.0
370.54492,0.053337275590551174,823.4442259933775,0.00025370340306410486,25.0,30.0
372.14648,0.05373012598425196,823.4487531043046,0.00025370340306410486,25.0,30.0
373.74805,0.05413136023622047,825.3402059188742,0.00025370340306410486,25.0,30.0
375.34961,0.05447221062992126,825.8004190811258,0.00025370340306410486,25.0,30.0
376.95117,0.05485042913385827,825.2772402731788,0.00025370340306410486,25.0,30.0
378.55273,0.05531068700787402,827.1893108443709,0.00025370340306410486,25.0,30.0
380.1543,0.05569688582677165,828.5821864652318,0.00025370340306410486,25.0,30.0
381.75586,0.05609170866141732,826.6152731788079,0.00025370340306410486,25.0,30.0
383.35742,0.05647624015748032,827.811465231788,0.00025370340306410486,25.0,30.0
384.95898,0.056881440944881886,830.0054325331125,0.00025370340306410486,25.0,30.0
386.56055,0.05725813976377952,827.6027524834436,0.00025370340306410486,25.0,30.0
388.16211,0.05766741141732283,827.9656974337747,0.00025370340306410486,25.0,30.0
389.76367,0.05807807874015748,829.3897713162252,0.00025370340306410486,25.0,30.0
391.36523,0.05848097440944882,829.613539942053,0.00025370340306410486,25.0,30.0
392.9668,0.05886095866141732,829.0756415562913,0.00025370340306410486,25.0,30.0
394.56836,0.059245338582677165,831.5841783940398,0.00025370340306410486,25.0,30.0
396.16992,0.05959434842519685,830.3670581539735,0.00025370340306410486,25.0,30.0
397.77148,0.05998036023622048,831.3970405629138,0.00025370340306410486,25.0,30.0
399.37305,0.06038348818897638,832.380639486755,0.00025370340306410486,25.0,30.0
400.97461,0.060788864173228346,834.152085057947,0.00025370340306410486,25.0,30.0
402.57617,0.061195285433070866,834.5033629966888,0.00025370340306410486,25.0,30.0
404.17773,0.06163045275590551,835.475605339404,0.00025370340306410486,25.0,30.0
405.7793,0.06204224015748031,833.2278300910596,0.00025370340306410486,25.0,30.0
407.38086,0.06242864960629921,835.039321192053,0.00025370340306410486,25.0,30.0
408.98242,0.0628421968503937,835.5800651903974,0.00025370340306410486,25.0,30.0
410.58398,0.06323796456692914,834.7313483029801,0.00025370340306410486,25.0,30.0
412.18555,0.06365268503937008,836.2784043874171,0.00025370340306410486,25.0,30.0
413.78711,0.06401767716535432,834.911113410596,0.00025370340306410486,25.0,30.0
415.38867,0.06433728937007874,834.9939724751655,0.00025370340306410486,25.0,30.0
416.99023,0.06470317716535433,837.3684292218543,0.00025370340306410486,25.0,30.0
418.5918,0.06509119291338583,838.5570415976821,0.00025370340306410486,25.0,30.0
420.19336,0.0655053877952756,838.5033112582781,0.00025370340306410486,25.0,30.0
421.79492,0.06599591732283465,839.1144194950331,0.00025370340306410486,25.0,30.0
423.39648,0.06638749409448819,840.15668977649,0.00025370340306410486,25.0,30.0
424.99805,0.06675477952755905,838.2129035596026,0.00025370340306410486,25.0,30.0
426.59961,0.06708882283464568,839.0369153559602,0.00025370340306410486,25.0,30.0
428.20117,0.06740164763779527,838.6463420943708,0.00025370340306410486,25.0,30.0
429.80273,0.06777518700787402,840.0378207781456,0.00025370340306410486,25.0,30.0
431.4043,0.06816330314960631,842.0133226407285,0.00025370340306410486,25.0,30.0
433.00586,0.06857966141732283,842.7310378725165,0.00025370340306410486,25.0,30.0
434.60742,0.06894847047244095,841.9458040149007,0.00025370340306410486,25.0,30.0
436.20898,0.06933154133858267,842.732383071192,0.00025370340306410486,25.0,30.0
437.81055,0.0697216062992126,843.9033009105959,0.00025370340306410486,25.0,30.0
439.41211,0.07007588385826771,842.7980649834437,0.00025370340306410486,25.0,30.0
441.01367,0.07048293897637795,844.341240687086,0.00025370340306410486,25.0,30.0
442.61523,0.07090043503937007,844.8518729304635,0.00025370340306410486,25.0,30.0
444.2168,0.07132785826771652,844.1507657284767,0.00025370340306410486,25.0,30.0
445.81836,0.07176072440944882,842.8984633692053,0.00025370340306410486,25.0,30.0
447.41992,0.07211567125984251,844.3269608857615,0.00025370340306410486,25.0,30.0
449.02148,0.0724761279527559,844.2515521523178,0.00025370340306410486,25.0,30.0
450.62305,0.07290163188976378,847.5356736341059,0.00025370340306410486,25.0,30.0
452.22461,0.07331801968503937,847.3592715231788,0.00025370340306410486,25.0,30.0
453.82617,0.07369669094488189,846.6992704884105,0.00025370340306410486,25.0,30.0
455.42773,0.07406636811023622,847.1882502069536,0.00025370340306410486,25.0,30.0
457.0293,0.07449365551181102,848.3488203642383,0.00025370340306410486,25.0,30.0
458.63086,0.07486133267716535,848.9483650662252,0.00025370340306410486,25.0,30.0
460.23242,0.07525020669291338,848.6287251655629,0.00025370340306410486,25.0,30.0
461.83398,0.07567397440944881,847.9804170115895,0.00025370340306410486,25.0,30.0
463.43555,0.07604620472440944,850.6378311258278,0.00025370340306410486,25.0,30.0
465.03711,0.07647342125984251,851.9231425910596,0.00025370340306410486,25.0,30.0
466.63867,0.07682681496062992,849.5956643211921,0.00025370340306410486,25.0,30.0
468.24023,0.07719830511811024,850.6970716059602,0.00025370340306410486,25.0,30.0
469.8418,0.07761527362204725,851.771445571192,0.00025370340306410486,25.0,30.0
471.44336,0.07799307677165354,852.1411682533112,0.00025370340306410486,25.0,30.0
473.04492,0.07838010236220472,851.8944795115893,0.00025370340306410486,25.0,30.0
474.64648,0.07882039566929135,853.536811879139,0.00025370340306410486,25.0,30.0
476.24805,0.07919351181102362,852.1147040562913,0.00025370340306410486,25.0,30.0
477.84961,0.0795850374015748,853.6243532698676,0.00025370340306410486,25.0,30.0
479.45117,0.07999525787401575,854.0320260761589,0.00025370340306410486,25.0,30.0
481.05273,0.0804039251968504,854.2653145695364,0.00025370340306410486,25.0,30.0
482.6543,0.08080980118110236,854.672056084437,0.00025370340306410486,25.0,30.0
484.25586,0.08116713582677165,854.639331539735,0.00025370340306410486,25.0,30.0
485.85742,0.08149775984251968,854.3515366307946,0.00025370340306410486,25.0,30.0
487.45898,0.08189198818897638,854.8300910596026,0.00025370340306410486,25.0,30.0
489.06055,0.08230281496062991,855.9821243791391,0.00025370340306410486,25.0,30.0
490.66211,0.08269221653543307,856.6624586092715,0.00025370340306410486,25.0,30.0
492.26367,0.08309153740157481,856.9274627483443,0.00025370340306410486,25.0,30.0
493.86523,0.08352554921259843,856.8828125,0.00025370340306410486,25.0,30.0
495.4668,0.08389938582677166,856.3284095612582,0.00025370340306410486,25.0,30.0
497.06836,0.08422043700787402,857.0458143625827,0.00025370340306410486,25.0,30.0
498.66992,0.08457332874015748,858.4251086506623,0.00025370340306410486,25.0,30.0
500.27148,0.08499749606299212,858.4234012831125,0.00025370340306410486,25.0,30.0
501.87305,0.08542593503937007,860.0874896523178,0.00025370340306410486,25.0,30.0
503.47461,0.0858089940944882,858.441147557947,0.00025370340306410486,25.0,30.0
505.07617,0.08617500590551182,861.0011123758277,0.00025370340306410486,25.0,30.0
506.67773,0.08662665748031495,860.8945053807946,0.00025370340306410486,25.0,30.0
508.2793,0.08700783858267716,859.783759312914,0.00025370340306410486,25.0,30.0
509.88086,0.0873900531496063,860.8156819122516,0.00025370340306410486,25.0,30.0
511.48242,0.0877588405511811,861.4142177152318,0.00025370340306410486,25.0,30.0
513.08398,0.0881982657480315,861.3815707781457,0.00025370340306410486,25.0,30.0
514.68555,0.08860065551181102,863.2184913079469,0.00025370340306410486,25.0,30.0
516.28711,0.0890137342519685,862.822744205298,0.00025370340306410486,25.0,30.0
517.88867,0.08943003543307086,862.4094577814569,0.00025370340306410486,25.0,30.0
519.49023,0.08980921062992125,862.82465852649,0.00025370340306410486,25.0,30.0
521.0918,0.09017521653543308,863.211558360927,0.00025370340306410486,25.0,30.0
522.69336,0.0906088622047244,864.1800755380794,0.00025370340306410486,25.0,30.0
524.29492,0.09100787401574803,863.922133692053,0.00025370340306410486,25.0,30.0
525.89648,0.0914264094488189,863.9934292218543,0.00025370340306410486,25.0,30.0
527.49805,0.09179581692913386,865.3261072019868,0.00025370340306410486,25.0,30.0
529.09961,0.09217916338582677,864.3550807119206,0.00025370340306410486,25.0,30.0
530.70117,0.0925788562992126,865.4728373344371,0.00025370340306410486,25.0,30.0
532.30273,0.09289541141732284,865.6818087748345,0.00025370340306410486,25.0,30.0
533.9043,0.0933333937007874,869.1560430463576,0.00025370340306410486,25.0,30.0
535.50586,0.09371439370078741,867.6900869205298,0.00025370340306410486,25.0,30.0
537.10742,0.09411126377952755,866.1559395695364,0.00025370340306410486,25.0,30.0
538.70898,0.09453036220472441,867.2974958609271,0.00025370340306410486,25.0,30.0
540.31055,0.09490917913385827,868.2486548013245,0.00025370340306410486,25.0,30.0
541.91211,0.0953745531496063,868.1516970198676,0.00025370340306410486,25.0,30.0
543.51367,0.09576535039370078,867.2686516970198,0.00025370340306410486,25.0,30.0
545.11523,0.09609414566929134,867.2027628311258,0.00025370340306410486,25.0,30.0
546.7168,0.09645057086614173,869.2503362996689,0.00025370340306410486,25.0,30.0
548.31836,0.09686435826771654,870.2115066225165,0.00025370340306410486,25.0,30.0
549.91992,0.0973202874015748,873.3227183360926,0.00025370340306410486,25.0,30.0
551.52148,0.09779267716535432,868.6680204884105,0.00025370340306410486,25.0,30.0
553.12305,0.09817002362204724,868.5150558774834,0.00025370340306410486,25.0,30.0
554.72461,0.09856244094488188,870.3616514900662,0.00025370340306410486,25.0,30.0
556.32617,0.09896717716535433,870.718491307947,0.00025370340306410486,25.0,30.0
557.92773,0.09935247244094489,869.3882709023178,0.00025370340306410486,25.0,30.0
559.5293,0.09978016929133857,873.346259312914,0.00025370340306410486,25.0,30.0
561.13086,0.10016134645669292,870.994800289735,0.00025370340306410486,25.0,30.0
562.73242,0.1005510531496063,872.2305204884105,0.00025370340306410486,25.0,30.0
564.33398,0.10094763582677166,872.7525351821191,0.00025370340306410486,25.0,30.0
565.93555,0.10138987007874016,873.0508847268211,0.00025370340306410486,25.0,30.0
567.53711,0.10172858464566929,872.9619463990065,0.00025370340306410486,25.0,30.0
569.13867,0.10207277755905513,870.5632502069536,0.00025370340306410486,25.0,30.0
570.74023,0.10245411811023623,874.4297392384105,0.00025370340306410486,25.0,30.0
572.3418,0.10285432677165354,875.7407388245032,0.00025370340306410486,25.0,30.0
573.94336,0.10326329921259843,873.4444846854304,0.00025370340306410486,25.0,30.0
575.54492,0.10358457677165353,873.4886175496689,0.00025370340306410486,25.0,30.0
577.14648,0.10398712007874016,875.586196192053,0.00025370340306410486,25.0,30.0
578.74805,0.10445174212598425,876.9086558360926,0.00025370340306410486,25.0,30.0
580.34961,0.10486161811023621,875.4074141142385,0.00025370340306410486,25.0,30.0
581.95117,0.1052727027559055,877.4158733443709,0.00025370340306410486,25.0,30.0
583.55273,0.10568926574803149,876.6948727235099,0.00025370340306410486,25.0,30.0
585.1543,0.1060740688976378,876.4786061672185,0.00025370340306410486,25.0,30.0
586.75586,0.10648062401574802,876.2662717301324,0.00025370340306410486,25.0,30.0
588.35742,0.10682296259842519,876.5226355546357,0.00025370340306410486,25.0,30.0
589.95898,0.10723774409448818,878.0123137417219,0.00025370340306410486,25.0,30.0
591.56055,0.10762425787401575,877.640443915563,0.00025370340306410486,25.0,30.0
593.16211,0.10805749606299213,878.5613358857617,0.00025370340306410486,25.0,30.0
594.76367,0.10847797834645669,879.5830401490066,0.00025370340306410486,25.0,30.0
596.36523,0.10880324606299213,880.0750983029801,0.00025370340306410486,25.0,30.0
597.9668,0.10925879921259843,878.6287251655629,0.00025370340306410486,25.0,30.0
599.56836,0.10966010826771654,879.4052669701987,0.00025370340306410486,25.0,30.0
601.16992,0.11012872047244093,879.7469991721854,0.00025370340306410486,25.0,30.0
602.77148,0.11061096850393701,882.028740687086,0.00025370340306410486,25.0,30.0
604.37305,0.11100122637795276,879.6306653559602,0.00025370340306410486,25.0,30.0
605.97461,0.11140008464566929,880.4524782698676,0.00025370340306410486,25.0,30.0
607.57617,0.11176539763779528,879.9011537665563,0.00025370340306410486,25.0,30.0
609.17773,0.11214141141732283,881.4237634519867,0.00025370340306410486,25.0,30.0
610.7793,0.11252198818897637,883.4794081125827,0.00025370340306410486,25.0,30.0
612.38086,0.11298525,883.1283112582781,0.00025370340306410486,25.0,30.0
613.98242,0.11342420078740158,881.5294908940398,0.00025370340306410486,25.0,30.0
615.58398,0.11381794291338582,884.0898178807947,0.00025370340306410486,25.0,30.0
617.18555,0.11427092716535434,883.1170064155629,0.00025370340306410486,25.0,30.0
618.78711,0.11461338385826772,881.7045478062914,0.00025370340306410486,25.0,30.0
620.38867,0.11500652755905512,885.4415614652318,0.00025370340306410486,25.0,30.0
621.99023,0.11546859448818897,884.5356995033112,0.00025370340306410486,25.0,30.0
623.5918,0.11591764566929133,884.005742963576,0.00025370340306410486,25.0,30.0
625.19336,0.1163503090551181,882.933335057947,0.00025370340306410486,25.0,30.0
626.79492,0.11674791141732282,884.5965180049668,0.00025370340306410486,25.0,30.0
628.39648,0.11713531692913387,884.6613203642383,0.00025370340306410486,25.0,30.0
629.99805,0.11755253937007873,884.7572692466887,0.00025370340306410486,25.0,30.0
631.59961,0.1179579566929134,884.6220509105959,0.00025370340306410486,25.0,30.0
633.20117,0.11836709251968504,884.8535802980132,0.00025370340306410486,25.0,30.0
634.80273,0.11879312401574804,887.774653352649,0.00025370340306410486,25.0,30.0
636.4043,0.11914957874015748,884.5801169288079,0.00025370340306410486,25.0,30.0
638.00586,0.11958621850393701,887.2977545529801,0.00025370340306410486,25.0,30.0
639.60742,0.11997929330708662,888.2753000827814,0.00025370340306410486,25.0,30.0
641.20898,0.12036386023622048,885.1653300910596,0.00025370340306410486,25.0,30.0
642.81055,0.12076241338582677,886.6932947019867,0.00025370340306410486,25.0,30.0
644.41211,0.1211716437007874,888.1965024834437,0.00025370340306410486,25.0,30.0
646.01367,0.12160683858267717,887.6254139072847,0.00025370340306410486,25.0,30.0
647.61523,0.12196256692913386,889.302255794702,0.00025370340306410486,25.0,30.0
649.2168,0.12241012992125984,888.2972889072847,0.00025370340306410486,25.0,30.0
650.81836,0.1228649311023622,890.0165562913907,0.00025370340306410486,25.0,30.0
652.41992,0.12331868897637796,888.7385658112582,0.00025370340306410486,25.0,30.0
654.02148,0.12377451181102363,889.3938327814569,0.00025370340306410486,25.0,30.0
655.62305,0.12417395669291338,889.2584850993378,0.00025370340306410486,25.0,30.0
657.22461,0.12456894488188976,888.9975165562914,0.00025370340306410486,25.0,30.0
658.82617,0.12498603543307088,890.9976976407283,0.00025370340306410486,25.0,30.0
660.42773,0.12538385039370079,890.8205453228476,0.00025370340306410486,25.0,30.0
662.0293,0.12588138385826772,890.4073106374173,0.00025370340306410486,25.0,30.0
663.63086,0.1262965157480315,890.3121895695364,0.00025370340306410486,25.0,30.0
665.23242,0.12673443503937007,891.5572744205298,0.00025370340306410486,25.0,30.0
666.83398,0.12717491141732284,890.607900455298,0.00025370340306410486,25.0,30.0
668.43555,0.12757828543307084,889.89150455298,0.00025370340306410486,25.0,30.0
670.03711,0.1280138937007874,891.5650351821191,0.00025370340306410486,25.0,30.0
671.63867,0.12845889763779528,890.713886589404,0.00025370340306410486,25.0,30.0
673.24023,0.12890059448818897,893.8559602649007,0.00025370340306410486,25.0,30.0
674.8418,0.12931941141732284,891.8359892384107,0.00025370340306410486,25.0,30.0
676.44336,0.12973753543307087,892.5244722682119,0.00025370340306410486,25.0,30.0
678.04492,0.13020003346456693,893.1496016142383,0.00025370340306410486,25.0,30.0
679.64648,0.13066146456692912,893.1649420529801,0.00025370340306410486,25.0,30.0
681.24805,0.1310666122047244,891.6382450331126,0.00025370340306410486,25.0,30.0
682.84961,0.13146372244094487,893.4582471026489,0.00025370340306410486,25.0,30.0
684.45117,0.13187592125984252,894.6385813327814,0.00025370340306410486,25.0,30.0
686.05273,0.13235153937007874,894.12543977649,0.00025370340306410486,25.0,30.0
687.6543,0.1327165,893.2284250827814,0.00025370340306410486,25.0,30.0
689.25586,0.1331033090551181,895.7011589403972,0.00025370340306410486,25.0,30.0
690.85742,0.13348565748031496,894.4435533940398,0.00025370340306410486,25.0,30.0
692.45898,0.13390039173228346,895.7228632036423,0.00025370340306410486,25.0,30.0
694.06055,0.13437806102362204,896.0178756208609,0.00025370340306410486,25.0,30.0
695.66211,0.13481395078740158,893.5037251655629,0.00025370340306410486,25.0,30.0
697.26367,0.1353015688976378,894.820493584437,0.00025370340306410486,25.0,30.0
698.86523,0.13578625590551183,895.2372723509933,0.00025370340306410486,25.0,30.0
700.4668,0.13622266141732284,895.5263348509933,0.00025370340306410486,25.0,30.0
702.06836,0.13667501181102362,896.388814155629,0.00025370340306410486,25.0,30.0
703.66992,0.13711409055118112,895.9252379966887,0.00025370340306410486,25.0,30.0
705.27148,0.13756857677165354,897.5357512417219,0.00025370340306410486,25.0,30.0
706.87305,0.1379642657480315,896.3230546357615,0.00025370340306410486,25.0,30.0
708.47461,0.13841396456692914,897.9261692880794,0.00025370340306410486,25.0,30.0
710.07617,0.13885699803149607,898.1531715645696,0.00025370340306410486,25.0,30.0
711.67773,0.13925478937007874,898.0776852235099,0.00025370340306410486,25.0,30.0
713.2793,0.13960930708661418,897.4799772350993,0.00025370340306410486,25.0,30.0
714.88086,0.14001402165354332,898.7237168874173,0.00025370340306410486,25.0,30.0
716.48242,0.14039716929133858,897.3001603890729,0.00025370340306410486,25.0,30.0
718.08398,0.1408575433070866,898.2357201986754,0.00025370340306410486,25.0,30.0
719.68555,0.14129332677165354,899.2081436258277,0.00025370340306410486,25.0,30.0
721.28711,0.14173578543307086,900.0678290562914,0.00025370340306410486,25.0,30.0
722.88867,0.14221708070866143,900.424565397351,0.00025370340306410486,25.0,30.0
724.49023,0.14265340354330708,899.7225527731788,0.00025370340306410486,25.0,30.0
726.0918,0.1431164192913386,900.8273747930464,0.00025370340306410486,25.0,30.0
727.69336,0.14354307283464565,900.5694329470198,0.00025370340306410486,25.0,30.0
729.29492,0.1439916811023622,899.9859271523178,0.00025370340306410486,25.0,30.0
730.89648,0.14443256692913387,899.5578435430464,0.00025370340306410486,25.0,30.0
732.49805,0.1448450472440945,899.7838886589403,0.00025370340306410486,25.0,30.0
734.09961,0.14529236417322836,900.7377379966887,0.00025370340306410486,25.0,30.0
735.70117,0.14573687598425197,900.9688534768211,0.00025370340306410486,25.0,30.0
737.30273,0.14620128740157481,901.0227907698675,0.00025370340306410486,25.0,30.0
738.9043,0.1467280492125984,900.9514176324502,0.00025370340306410486,25.0,30.0
740.50586,0.14719356496062994,900.1968646523178,0.00025370340306410486,25.0,30.0
742.10742,0.14764463582677165,900.990195571192,0.00025370340306410486,25.0,30.0
743.70898,0.1480629586614173,902.4292218543046,0.00025370340306410486,25.0,30.0
745.31055,0.14849564370078738,901.4908423013244,0.00025370340306410486,25.0,30.0
746.91211,0.14895941141732283,902.1203952814569,0.00025370340306410486,25.0,30.0
748.51367,0.14940750196850394,902.1757036423841,0.00025370340306410486,25.0,30.0
750.11523,0.14982611811023622,900.6634675082781,0.00025370340306410486,25.0,30.0
751.7168,0.15025768897637795,902.6640366307946,0.00025370340306410486,25.0,30.0
753.31836,0.15060447637795274,900.612065397351,0.00025370340306410486,25.0,30.0
754.91992,0.15100665354330708,903.3558050496689,0.00025370340306410486,25.0,30.0
756.52148,0.15149960039370078,904.014848923841,0.00025370340306410486,25.0,30.0
758.12305,0.1519822933070866,904.1186103062913,0.00025370340306410486,25.0,30.0
759.72461,0.15243916141732283,903.8677048841059,0.00025370340306410486,25.0,30.0
761.32617,0.15298936614173228,904.0326728062914,0.00025370340306410486,25.0,30.0
762.92773,0.15347158858267718,902.1889745447019,0.00025370340306410486,25.0,30.0
764.5293,0.15391899803149606,905.3745084850993,0.00025370340306410486,25.0,30.0
766.13086,0.1544986653543307,905.0611806705298,0.00025370340306410486,25.0,30.0
767.73242,0.15498554527559052,904.5009054221854,0.00025370340306410486,25.0,30.0
769.33398,0.15544472440944881,906.5695105546357,0.00025370340306410486,25.0,30.0
770.93555,0.1559262440944882,903.5587230960265,0.00025370340306410486,25.0,30.0
772.53711,0.15636951181102363,904.5782026076159,0.00025370340306410486,25.0,30.0
774.13867,0.15680837992125984,903.0887831125827,0.00025370340306410486,25.0,30.0
775.74023,0.15725237598425196,905.2332108857615,0.00025370340306410486,25.0,30.0
777.3418,0.15772477755905512,903.8920736754967,0.00025370340306410486,25.0,30.0
778.94336,0.15821643503937008,903.7223716887416,0.00025370340306410486,25.0,30.0
780.54492,0.15866337598425195,904.4148903145696,0.00025370340306410486,25.0,30.0
782.14648,0.15908837598425196,904.9036113410596,0.00025370340306410486,25.0,30.0
783.74805,0.15948785629921258,906.6082108857615,0.00025370340306410486,25.0,30.0
785.34961,0.15996453937007873,906.3592456539735,0.00025370340306410486,25.0,30.0
786.95117,0.16041714763779527,905.9494257036424,0.00025370340306410486,25.0,30.0
788.55273,0.16088763779527557,906.4460368377484,0.00025370340306410486,25.0,30.0
790.1543,0.1613784251968504,906.1231632864237,0.00025370340306410486,25.0,30.0
791.75586,0.16181147440944882,906.3666442466887,0.00025370340306410486,25.0,30.0
793.35742,0.16225595078740157,906.0589300496689,0.00025370340306410486,25.0,30.0
794.95898,0.16269494881889762,905.4013348509934,0.00025370340306410486,25.0,30.0
796.56055,0.16318285039370078,907.7518108443709,0.00025370340306410486,25.0,30.0
798.16211,0.1637077933070866,905.5993377483443,0.00025370340306410486,25.0,30.0
799.76367,0.16412991929133858,907.614574710265,0.00025370340306410486,25.0,30.0
801.36523,0.16464791732283465,907.7809137003311,0.00025370340306410486,25.0,30.0
802.9668,0.16516421259842518,906.6926479718542,0.00025370340306410486,25.0,30.0
804.56836,0.16555813188976376,905.3692570364238,0.00025370340306410486,25.0,30.0
806.16992,0.16600711417322833,906.2727131622516,0.00025370340306410486,25.0,30.0
807.77148,0.16647644094488187,908.8866152731788,0.00025370340306410486,25.0,30.0
809.37305,0.16697992519685037,908.2335730546357,0.00025370340306410486,25.0,30.0
810.97461,0.16743484448818896,909.0600941639073,0.00025370340306410486,25.0,30.0
812.57617,0.16793582874015747,909.2664528145696,0.00025370340306410486,25.0,30.0
814.17773,0.16849642913385826,908.2232771109271,0.00025370340306410486,25.0,30.0
815.7793,0.16900827755905512,908.0723302980132,0.00025370340306410486,25.0,30.0
817.38086,0.1694931751968504,907.7848975579469,0.00025370340306410486,25.0,30.0
818.98242,0.16995837401574804,909.1749793046357,0.00025370340306410486,25.0,30.0
820.58398,0.1704275255905512,910.2263555463576,0.00025370340306410486,25.0,30.0
822.18555,0.17093131299212597,907.5603787251656,0.00025370340306410486,25.0,30.0
823.78711,0.17138868503937008,908.4885916804636,0.00025370340306410486,25.0,30.0
825.38867,0.1718761062992126,909.1151697019867,0.00025370340306410486,25.0,30.0
826.99023,0.17237514173228347,910.4833661009933,0.00025370340306410486,25.0,30.0
828.5918,0.17283352362204724,908.6721854304635,0.00025370340306410486,25.0,30.0
830.19336,0.1733974212598425,909.37587955298,0.00025370340306410486,25.0,30.0
831.79492,0.17390892913385825,909.9354563327814,0.00025370340306410486,25.0,30.0
833.39648,0.1743810846456693,908.705737789735,0.00025370340306410486,25.0,30.0
834.99805,0.17486133661417322,910.0363979718542,0.00025370340306410486,25.0,30.0
836.59961,0.17534750196850393,910.791752897351,0.00025370340306410486,25.0,30.0
838.20117,0.17592681692913387,909.2592353062913,0.00025370340306410486,25.0,30.0
839.80273,0.17641453149606298,909.5127017798013,0.00025370340306410486,25.0,30.0
841.4043,0.17685910236220473,910.4565138658941,0.00025370340306410486,25.0,30.0
843.00586,0.17734445669291338,910.2661682533113,0.00025370340306410486,25.0,30.0
844.60742,0.17782016732283465,909.4819950331125,0.00025370340306410486,25.0,30.0
846.20898,0.17830161614173226,908.5588265728477,0.00025370340306410486,25.0,30.0
847.81055,0.17877488582677165,910.6207315811258,0.00025370340306410486,25.0,30.0
849.41211,0.17933180314960628,912.2661682533112,0.00025370340306410486,25.0,30.0
851.01367,0.1799112342519685,910.3702918046357,0.00025370340306410486,25.0,30.0
852.61523,0.1803916850393701,910.1186879139073,0.00025370340306410486,25.0,30.0
854.2168,0.18090946062992128,909.2869153559602,0.00025370340306410486,25.0,30.0
855.81836,0.18136015551181103,908.8825020695365,0.00025370340306410486,25.0,30.0
857.41992,0.18182882677165355,910.0692259933775,0.00025370340306410486,25.0,30.0
859.02148,0.18230865551181102,911.6250517384105,0.00025370340306410486,25.0,30.0
860.62305,0.18284709251968503,910.8158112582781,0.00025370340306410486,25.0,30.0
862.22461,0.1832940216535433,909.8674979304635,0.00025370340306410486,25.0,30.0
863.82617,0.18371728543307086,911.146445571192,0.00025370340306410486,25.0,30.0
865.42773,0.18420813188976376,911.7020384933775,0.00025370340306410486,25.0,30.0
867.0293,0.18481142913385828,911.8291597682119,0.00025370340306410486,25.0,30.0
868.63086,0.18540241732283463,911.7143004966887,0.00025370340306410486,25.0,30.0
870.23242,0.18586851968503937,909.4230649834436,0.00025370340306410486,25.0,30.0
871.83398,0.18630359842519684,911.0616204470198,0.00025370340306410486,25.0,30.0
873.43555,0.18686449212598424,912.8433619619206,0.00025370340306410486,25.0,30.0
875.03711,0.18742750984251969,912.6768677566225,0.00025370340306410486,25.0,30.0
876.63867,0.18803995866141732,912.9405525662252,0.00025370340306410486,25.0,30.0
878.24023,0.1886348090551181,911.2813534768211,0.00025370340306410486,25.0,30.0
879.8418,0.18912314370078742,911.0513245033113,0.00025370340306410486,25.0,30.0
881.44336,0.18959912401574802,910.8275558774834,0.00025370340306410486,25.0,30.0
883.04492,0.19014148031496064,911.8062396523178,0.00025370340306410486,25.0,30.0
884.64648,0.19069177952755903,912.890030008278,0.00025370340306410486,25.0,30.0
886.24805,0.19119186023622048,910.4270229718543,0.00025370340306410486,25.0,30.0
887.84961,0.19162705511811023,912.7904853062913,0.00025370340306410486,25.0,30.0
889.45117,0.19217923228346456,912.1977700745032,0.00025370340306410486,25.0,30.0
891.05273,0.19269834448818898,911.3794236341059,0.00025370340306410486,25.0,30.0
892.6543,0.19317094488188977,910.4909457781457,0.00025370340306410486,25.0,30.0
894.25586,0.19369797637795275,912.0759778559602,0.00025370340306410486,25.0,30.0
895.85742,0.1942240590551181,912.5769608857615,0.00025370340306410486,25.0,30.0
897.45898,0.1947601594488189,912.8461299668874,0.00025370340306410486,25.0,30.0
899.06055,0.19532148818897638,911.7063845198675,0.00025370340306410486,25.0,30.0
900.66211,0.19582691929133858,912.4275920943709,0.00025370340306410486,25.0,30.0
902.26367,0.1964108090551181,914.7134985513244,0.00025370340306410486,25.0,30.0
903.86523,0.19703342519685038,913.8118015314569,0.00025370340306410486,25.0,30.0
905.4668,0.1975291338582677,911.7268470612582,0.00025370340306410486,25.0,30.0
907.06836,0.1979833661417323,911.6229563327814,0.00025370340306410486,25.0,30.0
908.66992,0.19850580708661417,912.5629397764901,0.00025370340306410486,25.0,30.0
910.27148,0.1990586614173228,912.7262520695364,0.00025370340306410486,25.0,30.0
911.87305,0.19961035433070867,913.6728580298012,0.00025370340306410486,25.0,30.0
913.47461,0.20015311023622048,913.3527266142383,0.00025370340306410486,25.0,30.0
915.07617,0.2007332283464567,912.2120240066224,0.00025370340306410486,25.0,30.0
916.67773,0.20124553149606297,912.696709437086,0.00025370340306410486,25.0,30.0
918.2793,0.20182001968503935,912.3747154387416,0.00025370340306410486,25.0,30.0
919.88086,0.20238501968503936,913.0846181705298,0.00025370340306410486,25.0,30.0
921.48242,0.2029178149606299,911.8430774006622,0.00025370340306410486,25.0,30.0
923.08398,0.20354673228346457,912.5774524006622,0.00025370340306410486,25.0,30.0
924.68555,0.2041034251968504,910.7286061672185,0.00025370340306410486,25.0,30.0
926.28711,0.2046017716535433,911.9046978476821,0.00025370340306410486,25.0,30.0
927.88867,0.20508041338582675,912.7913648592715,0.00025370340306410486,25.0,30.0
929.49023,0.20563470472440942,912.0353114652318,0.00025370340306410486,25.0,30.0
931.0918,0.20617889763779526,911.8507088162252,0.00025370340306410486,25.0,30.0
932.69336,0.20676055118110234,912.3720767798012,0.00025370340306410486,25.0,30.0
934.29492,0.2073076968503937,912.3599441225165,0.00025370340306410486,25.0,30.0
935.89648,0.2078649409448819,913.2171202400662,0.00025370340306410486,25.0,30.0
937.49805,0.20838555118110236,913.1778249172185,0.00025370340306410486,25.0,30.0
939.09961,0.2089434251968504,913.2610202814569,0.00025370340306410486,25.0,30.0
940.70117,0.20948342519685037,913.624042839404,0.00025370340306410486,25.0,30.0
942.30273,0.21011433070866142,913.1864134933774,0.00025370340306410486,25.0,30.0
943.30371,0.21052312992125982,915.4556084437086,0.00025370340306410486,25.0,30.0