File: datasets/am_bench_2022/csv/30-XY.01-3.csv
Time(s),Strain(%),Stress(MPa),SR(s-1),Temp(C),Angle(deg)
38.231689,1.5798821653543305e-06,12.261809081527348,0.00025370340306410486,25.0,30.0
40.033447,2.3036765748031496e-05,19.647552889576883,0.00025370340306410486,25.0,30.0
41.534912,3.597534842519685e-05,23.42020794633643,0.00025370340306410486,25.0,30.0
43.036377,6.037794094488189e-05,29.56652476780186,0.00025370340306410486,25.0,30.0
44.537842,8.217704921259843e-05,35.55207430340557,0.00025370340306410486,25.0,30.0
46.039307,9.222618897637794e-05,40.901444788441694,0.00025370340306410486,25.0,30.0
47.540771,0.00011325776181102361,47.30990970072239,0.00025370340306410486,25.0,30.0
49.042236,0.00015278275787401573,53.12941950464396,0.00025370340306410486,25.0,30.0
50.543701,0.00016513328937007874,62.47802115583075,0.00025370340306410486,25.0,30.0
52.045166,0.00019523915157480316,71.24069659442725,0.00025370340306410486,25.0,30.0
53.546631,0.00021828009842519684,76.96796181630546,0.00025370340306410486,25.0,30.0
55.048096,0.00024087942913385827,84.53837719298245,0.00025370340306410486,25.0,30.0
56.549561,0.00024761641732283464,92.31151702786379,0.00025370340306410486,25.0,30.0
58.051025,0.0003269469291338583,101.8138931888545,0.00025370340306410486,25.0,30.0
59.55249,0.00033996397637795276,111.79311661506708,0.00025370340306410486,25.0,30.0
61.053955,0.00037141917322834644,120.00978586171311,0.00025370340306410486,25.0,30.0
62.55542,0.00040969708661417324,128.38811919504644,0.00025370340306410486,25.0,30.0
64.056885,0.00041690031496062995,138.74238906088752,0.00025370340306410486,25.0,30.0
65.55835,0.0004549773818897638,148.74450206398348,0.00025370340306410486,25.0,30.0
67.059814,0.0004931165551181103,158.24444530443756,0.00025370340306410486,25.0,30.0
68.561279,0.0005231520275590551,170.24040505675956,0.00025370340306410486,25.0,30.0
70.062744,0.0005610152952755905,179.02841073271415,0.00025370340306410486,25.0,30.0
71.564209,0.0005905942322834645,189.79237616099073,0.00025370340306410486,25.0,30.0
73.065674,0.0006331167519685039,199.9948374613003,0.00025370340306410486,25.0,30.0
74.567139,0.0006599145078740158,211.42082043343652,0.00025370340306410486,25.0,30.0
76.068604,0.0006846389566929134,220.35782507739938,0.00025370340306410486,25.0,30.0
77.570068,0.000728194842519685,232.26333591331272,0.00025370340306410486,25.0,30.0
79.071533,0.0007724538779527558,242.91461558307535,0.00025370340306410486,25.0,30.0
80.572998,0.0008195026377952755,255.865673374613,0.00025370340306410486,25.0,30.0
82.074463,0.0008257443307086614,263.4726522187823,0.00025370340306410486,25.0,30.0
83.575928,0.0008687299015748031,274.1693498452012,0.00025370340306410486,25.0,30.0
85.077393,0.0009155379330708661,286.57425180598557,0.00025370340306410486,25.0,30.0
86.578857,0.0009434979724409449,296.1918730650155,0.00025370340306410486,25.0,30.0
88.080322,0.0009970980511811024,308.68003095975234,0.00025370340306410486,25.0,30.0
89.581787,0.0010220244094488189,317.6685758513932,0.00025370340306410486,25.0,30.0
91.083252,0.0010600216338582677,329.3757481940145,0.00025370340306410486,25.0,30.0
92.584717,0.0010915687204724408,340.26261609907124,0.00025370340306410486,25.0,30.0
94.086182,0.001118503464566929,348.60188338493293,0.00025370340306410486,25.0,30.0
95.587646,0.0011476614763779528,360.42027863777093,0.00025370340306410486,25.0,30.0
97.089111,0.00120275562992126,370.5225748194015,0.00025370340306410486,25.0,30.0
98.590576,0.0012416659251968504,381.8366873065016,0.00025370340306410486,25.0,30.0
100.09204,0.0012705841338582677,392.3788441692467,0.00025370340306410486,25.0,30.0
101.59351,0.0013138373818897637,402.924742002064,0.00025370340306410486,25.0,30.0
103.09497,0.0013420677362204726,412.9639576883385,0.00025370340306410486,25.0,30.0
104.59644,0.0013759574212598425,424.80361197110426,0.00025370340306410486,25.0,30.0
106.0979,0.001406178464566929,433.9674148606811,0.00025370340306410486,25.0,30.0
107.59937,0.0014739691338582677,445.3453044375645,0.00025370340306410486,25.0,30.0
109.10083,0.0014805651181102363,455.1670020639835,0.00025370340306410486,25.0,30.0
110.60229,0.0015362464763779527,465.1002321981424,0.00025370340306410486,25.0,30.0
112.10376,0.0015540338188976379,472.1718008255934,0.00025370340306410486,25.0,30.0
113.60522,0.0015935433464566928,480.9395768833849,0.00025370340306410486,25.0,30.0
115.10669,0.0016284560236220472,488.70660474716203,0.00025370340306410486,25.0,30.0
116.60815,0.001636135216535433,495.52716718266254,0.00025370340306410486,25.0,30.0
118.10962,0.0016945091535433073,508.39429824561404,0.00025370340306410486,25.0,30.0
119.61108,0.001726286318897638,516.3269349845201,0.00025370340306410486,25.0,30.0
121.11255,0.001745019842519685,523.1121259029928,0.00025370340306410486,25.0,30.0
122.61401,0.0017696065748031495,531.6707688338494,0.00025370340306410486,25.0,30.0
124.11548,0.0017983708661417322,538.3288699690403,0.00025370340306410486,25.0,30.0
125.61694,0.0018452240944881889,547.6952270381837,0.00025370340306410486,25.0,30.0
127.11841,0.001876869094488189,553.9288183694531,0.00025370340306410486,25.0,30.0
128.61987,0.0019113747637795274,558.7980134158927,0.00025370340306410486,25.0,30.0
130.12134,0.001953463405511811,565.5799019607844,0.00025370340306410486,25.0,30.0
131.6228,0.001975862401574803,573.9095459236325,0.00025370340306410486,25.0,30.0
133.12427,0.0019930740157480314,578.5203044375645,0.00025370340306410486,25.0,30.0
134.62573,0.0020322956692913384,585.7205108359133,0.00025370340306410486,25.0,30.0
136.1272,0.0020762295275590552,590.9428276573788,0.00025370340306410486,25.0,30.0
137.62866,0.002088971653543307,595.3239422084624,0.00025370340306410486,25.0,30.0
139.13013,0.0021160521653543307,601.2149380804954,0.00025370340306410486,25.0,30.0
140.63159,0.002142729724409449,606.0565015479876,0.00025370340306410486,25.0,30.0
142.13306,0.0021778413385826773,610.104721362229,0.00025370340306410486,25.0,30.0
143.63452,0.002202596850393701,614.4176212590299,0.00025370340306410486,25.0,30.0
145.13599,0.0022453403543307086,619.9243808049536,0.00025370340306410486,25.0,30.0
146.63745,0.0022765816929133857,624.1077657378742,0.00025370340306410486,25.0,30.0
148.13892,0.002318194094488189,630.3393446852425,0.00025370340306410486,25.0,30.0
149.64038,0.0023492944881889763,633.4457688338493,0.00025370340306410486,25.0,30.0
151.14185,0.002381357086614173,636.1799019607843,0.00025370340306410486,25.0,30.0
152.64331,0.002419048622047244,641.59262125903,0.00025370340306410486,25.0,30.0
154.14478,0.002433312598425197,644.9858359133127,0.00025370340306410486,25.0,30.0
155.64624,0.002481224212598425,649.5546439628483,0.00025370340306410486,25.0,30.0
157.14771,0.002522606102362205,653.1712332301341,0.00025370340306410486,25.0,30.0
158.64917,0.0025721287401574804,657.1424148606811,0.00025370340306410486,25.0,30.0
160.15063,0.0025867958661417324,660.6998452012384,0.00025370340306410486,25.0,30.0
161.6521,0.0026423448818897635,663.3202012383902,0.00025370340306410486,25.0,30.0
163.15356,0.002695492716535433,668.0396026831786,0.00025370340306410486,25.0,30.0
164.65503,0.002742483070866142,670.0794117647059,0.00025370340306410486,25.0,30.0
166.15649,0.0028019273622047246,676.3151960784314,0.00025370340306410486,25.0,30.0
167.65796,0.002838142716535433,680.0138286893705,0.00025370340306410486,25.0,30.0
169.15942,0.0029029259842519683,681.2300825593395,0.00025370340306410486,25.0,30.0
170.66089,0.0029565746062992122,683.511790505676,0.00025370340306410486,25.0,30.0
172.16235,0.003017028937007874,689.4255933952529,0.00025370340306410486,25.0,30.0
173.66382,0.0030772129921259844,691.4563983488132,0.00025370340306410486,25.0,30.0
175.16528,0.0031537405511811024,695.2711042311662,0.00025370340306410486,25.0,30.0
176.66675,0.0032267061023622044,698.4572239422085,0.00025370340306410486,25.0,30.0
178.16821,0.0032964334645669293,699.9885190918473,0.00025370340306410486,25.0,30.0
179.66968,0.0033707974409448818,701.1832817337462,0.00025370340306410486,25.0,30.0
181.17114,0.0034643242125984254,707.4670536635707,0.00025370340306410486,25.0,30.0
182.67261,0.0035515616141732283,710.2541537667698,0.00025370340306410486,25.0,30.0
184.17407,0.003651992716535433,711.1543085655314,0.00025370340306410486,25.0,30.0
185.67554,0.0037654120078740158,712.3278379772962,0.00025370340306410486,25.0,30.0
187.177,0.003868781496062992,716.6657894736843,0.00025370340306410486,25.0,30.0
188.67847,0.00398328937007874,717.5903250773994,0.00025370340306410486,25.0,30.0
190.17993,0.004113007283464567,720.8825077399381,0.00025370340306410486,25.0,30.0
191.6814,0.00426776437007874,722.1396284829722,0.00025370340306410486,25.0,30.0
193.18286,0.004424504921259843,724.4688596491228,0.00025370340306410486,25.0,30.0
194.68433,0.004585712007874015,726.6703302373581,0.00025370340306410486,25.0,30.0
196.18579,0.004749921062992126,729.103560371517,0.00025370340306410486,25.0,30.0
197.68726,0.004915112401574803,729.3740196078431,0.00025370340306410486,25.0,30.0
199.18872,0.005135369881889763,732.669427244582,0.00025370340306410486,25.0,30.0
200.69019,0.005327094291338583,736.2226780185758,0.00025370340306410486,25.0,30.0
202.19165,0.005568098622047244,738.330185758514,0.00025370340306410486,25.0,30.0
203.69312,0.005796387401574803,739.4095459236327,0.00025370340306410486,25.0,30.0
205.19458,0.006075966141732283,740.4961558307534,0.00025370340306410486,25.0,30.0
206.69604,0.006332097440944881,742.2773735810114,0.00025370340306410486,25.0,30.0
208.19751,0.006587609842519685,744.373503611971,0.00025370340306410486,25.0,30.0
209.69897,0.006834869291338582,744.2674148606811,0.00025370340306410486,25.0,30.0
211.20044,0.007126674015748031,746.7687822497421,0.00025370340306410486,25.0,30.0
212.7019,0.007401631102362204,748.2637512899897,0.00025370340306410486,25.0,30.0
214.20337,0.007697149409448819,748.4581785345717,0.00025370340306410486,25.0,30.0
215.70483,0.007981705708661416,750.676418988648,0.00025370340306410486,25.0,30.0
217.2063,0.008259620472440945,751.0495614035087,0.00025370340306410486,25.0,30.0
218.70776,0.008601734842519686,755.2077657378742,0.00025370340306410486,25.0,30.0
220.20923,0.00889474153543307,752.4539989680082,0.00025370340306410486,25.0,30.0
221.71069,0.00915523090551181,754.4215428276574,0.00025370340306410486,25.0,30.0
223.21216,0.00944985157480315,756.2745872033023,0.00025370340306410486,25.0,30.0
224.71362,0.009778767519685039,756.2566305469556,0.00025370340306410486,25.0,30.0
226.21509,0.010070701181102362,759.2037667698659,0.00025370340306410486,25.0,30.0
227.71655,0.010427306889763779,759.2219814241487,0.00025370340306410486,25.0,30.0
229.21802,0.010780492125984252,762.2309597523221,0.00025370340306410486,25.0,30.0
230.71948,0.011146133070866142,762.9445562435501,0.00025370340306410486,25.0,30.0
232.22095,0.011446439960629922,763.4787667698658,0.00025370340306410486,25.0,30.0
233.72241,0.011746999015748032,762.4168988648091,0.00025370340306410486,25.0,30.0
235.22388,0.012063356102362205,764.7059339525284,0.00025370340306410486,25.0,30.0
236.72534,0.01243420059055118,766.0948142414861,0.00025370340306410486,25.0,30.0
238.22681,0.01278094153543307,766.9139834881321,0.00025370340306410486,25.0,30.0
239.72827,0.013115720472440945,768.7039731682147,0.00025370340306410486,25.0,30.0
241.22974,0.013427052165354331,766.9140350877193,0.00025370340306410486,25.0,30.0
242.7312,0.013741799606299211,769.0186016511868,0.00025370340306410486,25.0,30.0
244.23267,0.014128493503937007,770.4947626418989,0.00025370340306410486,25.0,30.0
245.73413,0.014483155708661417,770.6014705882353,0.00025370340306410486,25.0,30.0
247.2356,0.014840490354330707,769.0011351909185,0.00025370340306410486,25.0,30.0
248.73706,0.015153807677165353,772.7764963880289,0.00025370340306410486,25.0,30.0
250.23853,0.015538344291338584,774.9365583075336,0.00025370340306410486,25.0,30.0
251.73999,0.015924313582677166,773.4151444788441,0.00025370340306410486,25.0,30.0
253.24146,0.016265375787401577,775.3440660474716,0.00025370340306410486,25.0,30.0
254.74292,0.01656798366141732,774.3329463364294,0.00025370340306410486,25.0,30.0
256.24438,0.01689096633858268,776.8843137254902,0.00025370340306410486,25.0,30.0
257.74585,0.017253572047244092,777.638080495356,0.00025370340306410486,25.0,30.0
259.24731,0.017578748818897635,777.2672084623323,0.00025370340306410486,25.0,30.0
260.74878,0.017915447637795272,779.823194014448,0.00025370340306410486,25.0,30.0
262.25024,0.018220424212598424,779.6242776057792,0.00025370340306410486,25.0,30.0
263.75171,0.018604783267716533,781.5291537667698,0.00025370340306410486,25.0,30.0
265.25317,0.018971454527559054,780.2439628482973,0.00025370340306410486,25.0,30.0
266.75464,0.019345857874015746,782.2702012383901,0.00025370340306410486,25.0,30.0
268.2561,0.019731944881889764,783.669814241486,0.00025370340306410486,25.0,30.0
269.75757,0.020111769685039367,783.2503095975233,0.00025370340306410486,25.0,30.0
271.25903,0.02047491338582677,783.7424922600619,0.00025370340306410486,25.0,30.0
272.7605,0.020815714566929135,784.1463106295149,0.00025370340306410486,25.0,30.0
274.26196,0.021195830708661417,786.1579979360165,0.00025370340306410486,25.0,30.0
275.76343,0.021607948818897636,785.3800567595459,0.00025370340306410486,25.0,30.0
277.26489,0.021957222440944883,787.0726006191951,0.00025370340306410486,25.0,30.0
278.76636,0.022344830708661417,788.9689112487101,0.00025370340306410486,25.0,30.0
280.26782,0.02268190157480315,787.5501547987617,0.00025370340306410486,25.0,30.0
281.76929,0.023019996062992126,788.2466718266254,0.00025370340306410486,25.0,30.0
283.27075,0.02335219881889764,790.2927244582044,0.00025370340306410486,25.0,30.0
284.77222,0.023689437007874018,790.2668214654283,0.00025370340306410486,25.0,30.0
286.27368,0.024029204724409448,790.1538957688339,0.00025370340306410486,25.0,30.0
287.77515,0.02441907283464567,791.1843653250775,0.00025370340306410486,25.0,30.0
289.27661,0.024783200787401573,792.5401186790506,0.00025370340306410486,25.0,30.0
290.77808,0.025092655511811023,791.8349587203303,0.00025370340306410486,25.0,30.0
292.27954,0.02545892519685039,793.5428276573788,0.00025370340306410486,25.0,30.0
293.78101,0.025800448818897637,794.0920794633644,0.00025370340306410486,25.0,30.0
295.28247,0.02611413582677165,793.9682404540764,0.00025370340306410486,25.0,30.0
296.78394,0.02645178543307087,794.0401702786378,0.00025370340306410486,25.0,30.0
298.2854,0.026833015748031496,796.2997936016512,0.00025370340306410486,25.0,30.0
299.78687,0.027216442913385826,795.5036893704851,0.00025370340306410486,25.0,30.0
301.28833,0.027589529527559054,796.6243034055727,0.00025370340306410486,25.0,30.0
302.78979,0.027982779527559055,798.2495098039216,0.00025370340306410486,25.0,30.0
304.29126,0.028310539370078738,798.0060629514965,0.00025370340306410486,25.0,30.0
305.79272,0.02864197440944882,798.3378998968009,0.00025370340306410486,25.0,30.0
307.29419,0.02901412401574803,800.493008255934,0.00025370340306410486,25.0,30.0
308.79565,0.029377635826771654,800.7523477812178,0.00025370340306410486,25.0,30.0
310.29712,0.029768411417322834,801.1452012383901,0.00025370340306410486,25.0,30.0
311.79858,0.030144785433070868,803.0154282765737,0.00025370340306410486,25.0,30.0
313.30005,0.030549498031496064,801.1461300309599,0.00025370340306410486,25.0,30.0
314.80151,0.030888029527559056,801.1577399380806,0.00025370340306410486,25.0,30.0
316.30298,0.03123953346456693,803.6317595459236,0.00025370340306410486,25.0,30.0
317.80444,0.03156102362204724,804.4260319917441,0.00025370340306410486,25.0,30.0
319.30591,0.031916574803149605,803.0154282765737,0.00025370340306410486,25.0,30.0
320.80737,0.03226744881889764,805.3998194014448,0.00025370340306410486,25.0,30.0
322.30884,0.03260701181102362,805.9332817337462,0.00025370340306410486,25.0,30.0
323.8103,0.03302913582677165,806.6056759545924,0.00025370340306410486,25.0,30.0
325.31177,0.033435127952755904,806.6416924664603,0.00025370340306410486,25.0,30.0
326.81323,0.03377556692913385,803.68782249742,0.00025370340306410486,25.0,30.0
328.3147,0.03402957874015748,805.6832043343654,0.00025370340306410486,25.0,30.0
329.81616,0.03433386811023622,808.340866873065,0.00025370340306410486,25.0,30.0
331.31763,0.03477357874015748,809.52564499484,0.00025370340306410486,25.0,30.0
332.81909,0.035149277559055114,809.0800825593395,0.00025370340306410486,25.0,30.0
334.32056,0.035494198818897635,811.4913054695562,0.00025370340306410486,25.0,30.0
335.82202,0.03582548228346457,808.9762125902994,0.00025370340306410486,25.0,30.0
337.32349,0.0361855688976378,810.5349587203302,0.00025370340306410486,25.0,30.0
338.82495,0.03651786811023622,810.3300825593395,0.00025370340306410486,25.0,30.0
340.32642,0.03690191338582677,812.793524251806,0.00025370340306410486,25.0,30.0
341.82788,0.03724141535433071,810.991253869969,0.00025370340306410486,25.0,30.0
343.32935,0.037653897637795274,813.2396026831785,0.00025370340306410486,25.0,30.0
344.83081,0.03795732874015748,813.2504385964912,0.00025370340306410486,25.0,30.0
346.33228,0.038319791338582675,814.4843137254903,0.00025370340306410486,25.0,30.0
347.83374,0.03871195275590551,815.1179566563468,0.00025370340306410486,25.0,30.0
349.33521,0.039108775590551176,814.7875386996905,0.00025370340306410486,25.0,30.0
350.83667,0.03947024015748032,816.5506707946337,0.00025370340306410486,25.0,30.0
352.33813,0.03983486023622047,816.2003353973168,0.00025370340306410486,25.0,30.0
353.8396,0.040127307086614175,815.2052631578947,0.00025370340306410486,25.0,30.0
355.34106,0.040548348425196855,817.8076109391125,0.00025370340306410486,25.0,30.0
356.84253,0.04098134448818898,818.9342621259029,0.00025370340306410486,25.0,30.0
358.34399,0.04135078346456693,818.3637254901961,0.00025370340306410486,25.0,30.0
359.84546,0.04168632086614173,817.5635190918473,0.00025370340306410486,25.0,30.0
361.34692,0.04200591338582677,818.9885706914345,0.00025370340306410486,25.0,30.0
362.84839,0.04234589960629921,819.9151186790506,0.00025370340306410486,25.0,30.0
364.34985,0.04264985039370079,818.9935242518061,0.00025370340306410486,25.0,30.0
365.85132,0.042972716535433074,820.3787667698659,0.00025370340306410486,25.0,30.0
367.35278,0.043318397637795276,819.7876934984521,0.00025370340306410486,25.0,30.0
368.85425,0.043617860236220475,822.8010319917441,0.00025370340306410486,25.0,30.0
370.35571,0.04399607086614173,823.000515995872,0.00025370340306410486,25.0,30.0
371.85718,0.04437898228346457,822.7709752321982,0.00025370340306410486,25.0,30.0
373.35864,0.04476261811023622,824.496955624355,0.00025370340306410486,25.0,30.0
374.86011,0.045116269685039366,823.3544891640868,0.00025370340306410486,25.0,30.0
376.36157,0.04544524409448819,825.1252063983488,0.00025370340306410486,25.0,30.0
377.86304,0.04584747244094488,823.3481424148607,0.00025370340306410486,25.0,30.0
379.3645,0.046179631889763775,825.3888802889577,0.00025370340306410486,25.0,30.0
380.86597,0.046552312992125984,826.2428018575852,0.00025370340306410486,25.0,30.0
382.36743,0.0469431437007874,826.3559339525283,0.00025370340306410486,25.0,30.0
383.8689,0.04730169488188976,826.3074819401445,0.00025370340306410486,25.0,30.0
385.37036,0.04762446062992126,825.9145768833849,0.00025370340306410486,25.0,30.0
386.87183,0.04798383267716535,826.9197368421053,0.00025370340306410486,25.0,30.0
388.37329,0.048323891732283464,827.4439886480908,0.00025370340306410486,25.0,30.0
389.87476,0.048677342519685037,827.4778121775026,0.00025370340306410486,25.0,30.0
391.37622,0.049052,829.427012383901,0.00025370340306410486,25.0,30.0
392.87769,0.04938784448818897,828.9576883384933,0.00025370340306410486,25.0,30.0
394.37915,0.049747468503937006,831.6560371517028,0.00025370340306410486,25.0,30.0
395.88062,0.05011115551181102,831.3708978328174,0.00025370340306410486,25.0,30.0
397.38208,0.050461275590551184,830.6211300309599,0.00025370340306410486,25.0,30.0
398.88354,0.050806511811023615,831.9326625386997,0.00025370340306410486,25.0,30.0
400.38501,0.05114737401574803,832.1470846233229,0.00025370340306410486,25.0,30.0
401.88647,0.05150214960629921,831.71826625387,0.00025370340306410486,25.0,30.0
403.38794,0.05185926771653543,832.7416924664602,0.00025370340306410486,25.0,30.0
404.8894,0.05219490748031496,834.323245614035,0.00025370340306410486,25.0,30.0
406.39087,0.052569413385826776,833.9726006191951,0.00025370340306410486,25.0,30.0
407.89233,0.052864714566929136,832.9680598555211,0.00025370340306410486,25.0,30.0
409.3938,0.053200025590551175,834.0011867905057,0.00025370340306410486,25.0,30.0
410.89526,0.05355727755905512,833.0780443756449,0.00025370340306410486,25.0,30.0
412.39673,0.05391405511811023,834.9165376676987,0.00025370340306410486,25.0,30.0
413.89819,0.05428781692913386,837.2255933952529,0.00025370340306410486,25.0,30.0
415.39966,0.05467999212598425,836.0903766769866,0.00025370340306410486,25.0,30.0
416.90112,0.055020372047244095,836.074742002064,0.00025370340306410486,25.0,30.0
418.40259,0.05541285433070866,839.101625386997,0.00025370340306410486,25.0,30.0
419.90405,0.05580585826771653,838.9864293085656,0.00025370340306410486,25.0,30.0
421.40552,0.05616813188976377,837.4146284829721,0.00025370340306410486,25.0,30.0
422.90698,0.05646593307086614,838.6389318885449,0.00025370340306410486,25.0,30.0
424.40845,0.056844122047244094,838.3382868937048,0.00025370340306410486,25.0,30.0
425.90991,0.05719178937007873,841.2023219814241,0.00025370340306410486,25.0,30.0
427.41138,0.05759376771653543,840.9280185758514,0.00025370340306410486,25.0,30.0
428.91284,0.05793362007874015,839.8945820433437,0.00025370340306410486,25.0,30.0
430.41431,0.05820939173228346,840.0315789473684,0.00025370340306410486,25.0,30.0
431.91577,0.05855197244094488,841.1441434468525,0.00025370340306410486,25.0,30.0
433.41724,0.05890612598425196,842.4025541795667,0.00025370340306410486,25.0,30.0
434.9187,0.05927939960629921,842.5206140350878,0.00025370340306410486,25.0,30.0
436.42017,0.05959583267716536,841.1918730650154,0.00025370340306410486,25.0,30.0
437.92163,0.05995918110236221,844.6286119711042,0.00025370340306410486,25.0,30.0
439.4231,0.06034021062992126,844.9766253869968,0.00025370340306410486,25.0,30.0
440.92456,0.0606830374015748,843.8483746130031,0.00025370340306410486,25.0,30.0
442.42603,0.06104186220472441,845.8894994840041,0.00025370340306410486,25.0,30.0
443.92749,0.06140322637795276,844.1894736842105,0.00025370340306410486,25.0,30.0
445.42896,0.06178775787401574,846.498968008256,0.00025370340306410486,25.0,30.0
446.93042,0.06213299015748032,844.0157378740971,0.00025370340306410486,25.0,30.0
448.43188,0.06245967125984252,844.0784829721363,0.00025370340306410486,25.0,30.0
449.93335,0.06278016338582677,845.6294891640867,0.00025370340306410486,25.0,30.0
451.43481,0.06309766535433071,847.0072239422085,0.00025370340306410486,25.0,30.0
452.93628,0.06348327559055118,849.4488906088752,0.00025370340306410486,25.0,30.0
454.43774,0.06383626377952756,847.1265737874097,0.00025370340306410486,25.0,30.0
455.93921,0.06416834251968503,847.4167182662538,0.00025370340306410486,25.0,30.0
457.44067,0.06451390944881889,848.6906862745097,0.00025370340306410486,25.0,30.0
458.94214,0.06489205708661418,847.4060113519092,0.00025370340306410486,25.0,30.0
460.4436,0.06519198228346457,848.1246904024767,0.00025370340306410486,25.0,30.0
461.94507,0.06551983070866142,848.3050825593396,0.00025370340306410486,25.0,30.0
463.44653,0.06593479921259843,851.5925438596491,0.00025370340306410486,25.0,30.0
464.948,0.06626825,850.1750773993808,0.00025370340306410486,25.0,30.0
466.44946,0.06662225787401575,851.6313983488133,0.00025370340306410486,25.0,30.0
467.95093,0.06698264960629921,851.5315789473684,0.00025370340306410486,25.0,30.0
469.45239,0.06732940157480315,852.596568627451,0.00025370340306410486,25.0,30.0
470.95386,0.0676737283464567,850.7842879256966,0.00025370340306410486,25.0,30.0
472.45532,0.06796091141732284,852.5582817337461,0.00025370340306410486,25.0,30.0
473.95679,0.06833662598425197,851.949613003096,0.00025370340306410486,25.0,30.0
475.45825,0.06868213976377953,853.9188080495356,0.00025370340306410486,25.0,30.0
476.95972,0.06902914173228347,852.1944530443757,0.00025370340306410486,25.0,30.0
478.46118,0.06935393503937008,854.107765737874,0.00025370340306410486,25.0,30.0
479.96265,0.06970936811023622,854.5093137254903,0.00025370340306410486,25.0,30.0
481.46411,0.07008446062992126,857.079669762642,0.00025370340306410486,25.0,30.0
482.96558,0.07046690551181102,856.25415376677,0.00025370340306410486,25.0,30.0
484.46704,0.0708068090551181,855.2634158926729,0.00025370340306410486,25.0,30.0
485.96851,0.07116822834645668,856.5317853457173,0.00025370340306410486,25.0,30.0
487.46997,0.071454218503937,856.7626418988648,0.00025370340306410486,25.0,30.0
488.97144,0.07186351377952756,857.945923632611,0.00025370340306410486,25.0,30.0
490.4729,0.0722385,856.6725748194015,0.00025370340306410486,25.0,30.0
491.97437,0.07262414763779527,857.7920020639835,0.00025370340306410486,25.0,30.0
493.47583,0.07293867322834646,857.2613261093912,0.00025370340306410486,25.0,30.0
494.97729,0.07324270472440945,858.7518059855521,0.00025370340306410486,25.0,30.0
496.47876,0.07361248228346456,859.3943498452012,0.00025370340306410486,25.0,30.0
497.98022,0.07397043700787401,860.0165376676987,0.00025370340306410486,25.0,30.0
499.48169,0.0743167716535433,859.0112487100104,0.00025370340306410486,25.0,30.0
500.98315,0.07469012795275591,861.5002063983488,0.00025370340306410486,25.0,30.0
502.48462,0.07508510826771653,860.0070949432404,0.00025370340306410486,25.0,30.0
503.98608,0.07544788188976378,861.9265737874098,0.00025370340306410486,25.0,30.0
505.48755,0.07575045275590551,860.4430082559339,0.00025370340306410486,25.0,30.0
506.98901,0.0760614527559055,862.4810629514964,0.00025370340306410486,25.0,30.0
508.49048,0.07646266929133858,863.9265479876161,0.00025370340306410486,25.0,30.0
509.99194,0.07677034251968504,860.2012125902993,0.00025370340306410486,25.0,30.0
511.49341,0.07708050393700788,864.259004127967,0.00025370340306410486,25.0,30.0
512.99487,0.07747100787401576,863.6863777089784,0.00025370340306410486,25.0,30.0
514.49634,0.07782071062992126,864.5908926728587,0.00025370340306410486,25.0,30.0
515.9978,0.07819969291338583,863.8480650154798,0.00025370340306410486,25.0,30.0
517.49927,0.07857947244094489,864.1143962848298,0.00025370340306410486,25.0,30.0
519.00073,0.07886067716535433,863.726883384933,0.00025370340306410486,25.0,30.0
520.5022,0.07921051968503937,865.7579205366358,0.00025370340306410486,25.0,30.0
522.00366,0.07957937598425197,865.3713622291021,0.00025370340306410486,25.0,30.0
523.50513,0.07993296653543307,866.2452786377709,0.00025370340306410486,25.0,30.0
525.00659,0.08031736417322834,865.6446078431372,0.00025370340306410486,25.0,30.0
526.50806,0.08067875787401575,867.343782249742,0.00025370340306410486,25.0,30.0
528.00952,0.08105506496062992,866.3034055727554,0.00025370340306410486,25.0,30.0
529.51099,0.08140286220472441,867.7371259029928,0.00025370340306410486,25.0,30.0
531.01245,0.08175988385826771,867.1194014447884,0.00025370340306410486,25.0,30.0
532.51392,0.08205122637795276,866.5057791537668,0.00025370340306410486,25.0,30.0
534.01538,0.08240462401574802,868.4631320949434,0.00025370340306410486,25.0,30.0
535.51685,0.08277133267716535,871.1995614035087,0.00025370340306410486,25.0,30.0
537.01831,0.0831212342519685,868.6011351909185,0.00025370340306410486,25.0,30.0
538.51978,0.08346961614173228,869.4582817337462,0.00025370340306410486,25.0,30.0
540.02124,0.08382172440944882,869.8869711042312,0.00025370340306410486,25.0,30.0
541.52271,0.0840808464566929,868.801625386997,0.00025370340306410486,25.0,30.0
543.02417,0.08441056102362204,871.5551341589268,0.00025370340306410486,25.0,30.0
544.52563,0.08478185826771653,869.7710010319918,0.00025370340306410486,25.0,30.0
546.0271,0.08519347637795276,872.564705882353,0.00025370340306410486,25.0,30.0
547.52856,0.08556271456692914,870.505185758514,0.00025370340306410486,25.0,30.0
549.03003,0.08591256889763779,871.3846233230134,0.00025370340306410486,25.0,30.0
550.53149,0.08625736023622048,872.0349071207431,0.00025370340306410486,25.0,30.0
552.03296,0.08664711417322835,871.9311145510836,0.00025370340306410486,25.0,30.0
553.53442,0.08700909448818898,871.5544375644995,0.00025370340306410486,25.0,30.0
555.03589,0.08739727559055119,873.7715428276574,0.00025370340306410486,25.0,30.0
556.53735,0.08772451377952756,873.4987616099071,0.00025370340306410486,25.0,30.0
558.03882,0.08809647440944882,873.5691692466461,0.00025370340306410486,25.0,30.0
559.54028,0.08849464566929133,876.3627966976264,0.00025370340306410486,25.0,30.0
561.04175,0.08885466141732283,876.1998452012384,0.00025370340306410486,25.0,30.0
562.54321,0.08921319881889764,875.080572755418,0.00025370340306410486,25.0,30.0
564.04468,0.08960653149606299,876.5718524251806,0.00025370340306410486,25.0,30.0
565.54614,0.08994687598425197,874.0672084623324,0.00025370340306410486,25.0,30.0
567.04761,0.09022203740157479,876.068137254902,0.00025370340306410486,25.0,30.0
568.54907,0.0905542342519685,874.6259803921569,0.00025370340306410486,25.0,30.0
570.05054,0.0908936279527559,877.7183694530444,0.00025370340306410486,25.0,30.0
571.552,0.0912734311023622,876.9057533539732,0.00025370340306410486,25.0,30.0
573.05347,0.09161968307086614,877.426031991744,0.00025370340306410486,25.0,30.0
574.55493,0.09194007677165354,878.2058823529412,0.00025370340306410486,25.0,30.0
576.0564,0.0922903937007874,876.2729102167183,0.00025370340306410486,25.0,30.0
577.55786,0.09262959645669291,877.8299793601651,0.00025370340306410486,25.0,30.0
579.05933,0.09299403543307086,879.1666408668731,0.00025370340306410486,25.0,30.0
580.56079,0.09335270669291339,878.0288183694531,0.00025370340306410486,25.0,30.0
582.06226,0.09372857874015748,880.2808307533539,0.00025370340306410486,25.0,30.0
583.56372,0.09406433661417322,879.2114809081528,0.00025370340306410486,25.0,30.0
585.06519,0.0943790688976378,880.2932404540763,0.00025370340306410486,25.0,30.0
586.56665,0.09477926377952756,880.3371517027864,0.00025370340306410486,25.0,30.0
588.06812,0.09513986614173228,881.1670020639835,0.00025370340306410486,25.0,30.0
589.56958,0.09550292716535433,880.9908926728586,0.00025370340306410486,25.0,30.0
591.07104,0.09589716141732282,881.3975490196078,0.00025370340306410486,25.0,30.0
592.57251,0.09625781102362205,881.7299793601651,0.00025370340306410486,25.0,30.0
594.07397,0.09658549015748032,881.4752579979361,0.00025370340306410486,25.0,30.0
595.57544,0.09695864173228345,882.0024251805986,0.00025370340306410486,25.0,30.0
597.0769,0.09736517913385827,881.8807275541795,0.00025370340306410486,25.0,30.0
598.57837,0.0977581062992126,884.6649638802891,0.00025370340306410486,25.0,30.0
600.07983,0.09813024212598424,885.2938338493293,0.00025370340306410486,25.0,30.0
601.5813,0.09848088188976377,883.5172084623324,0.00025370340306410486,25.0,30.0
603.08276,0.09884290944881889,884.7881062951498,0.00025370340306410486,25.0,30.0
604.58423,0.09921621456692914,883.409133126935,0.00025370340306410486,25.0,30.0
606.08569,0.09961986023622046,884.2922084623323,0.00025370340306410486,25.0,30.0
607.58716,0.10000286614173229,883.5419504643963,0.00025370340306410486,25.0,30.0
609.08862,0.100287031496063,882.9916408668731,0.00025370340306410486,25.0,30.0
610.59009,0.1006135905511811,884.9577915376677,0.00025370340306410486,25.0,30.0
612.09155,0.1009294842519685,885.666718266254,0.00025370340306410486,25.0,30.0
613.59302,0.10130663582677166,884.8638802889577,0.00025370340306410486,25.0,30.0
615.09448,0.10163379133858269,885.8292311661506,0.00025370340306410486,25.0,30.0
616.59595,0.10192588976377953,886.4860681114551,0.00025370340306410486,25.0,30.0
618.09741,0.10229884251968505,886.3422600619194,0.00025370340306410486,25.0,30.0
619.59888,0.10270449409448819,886.1165892672859,0.00025370340306410486,25.0,30.0
621.10034,0.10305687598425196,887.5263157894738,0.00025370340306410486,25.0,30.0
622.60181,0.103403968503937,887.9618679050568,0.00025370340306410486,25.0,30.0
624.10327,0.10380926771653542,889.4989680082559,0.00025370340306410486,25.0,30.0
625.60474,0.10411902362204724,887.2052115583076,0.00025370340306410486,25.0,30.0
627.1062,0.10448751771653543,888.9366099071208,0.00025370340306410486,25.0,30.0
628.60767,0.10486975000000001,888.8515737874097,0.00025370340306410486,25.0,30.0
630.10913,0.10528063385826772,890.4445304437564,0.00025370340306410486,25.0,30.0
631.6106,0.10568922047244093,889.8468524251807,0.00025370340306410486,25.0,30.0
633.11206,0.10609503543307086,890.216847265222,0.00025370340306410486,25.0,30.0
634.61353,0.10648772244094487,889.3358875129,0.00025370340306410486,25.0,30.0
636.11499,0.10684256889763781,888.8447884416926,0.00025370340306410486,25.0,30.0
637.61646,0.10721029921259843,888.7065789473684,0.00025370340306410486,25.0,30.0
639.11792,0.10755692125984252,890.0065273477812,0.00025370340306410486,25.0,30.0
640.61938,0.10791356496062993,889.6448400412796,0.00025370340306410486,25.0,30.0
642.12085,0.10821172834645669,890.1304953560372,0.00025370340306410486,25.0,30.0
643.62231,0.10859914566929134,891.9756449948401,0.00025370340306410486,25.0,30.0
645.12378,0.10893231102362205,890.2675438596492,0.00025370340306410486,25.0,30.0
646.62524,0.10932434055118109,891.4332043343653,0.00025370340306410486,25.0,30.0
648.12671,0.109698031496063,892.1977296181631,0.00025370340306410486,25.0,30.0
649.62817,0.11005360629921258,892.7159442724458,0.00025370340306410486,25.0,30.0
651.12964,0.11047825393700787,893.7409958720331,0.00025370340306410486,25.0,30.0
652.6311,0.1108565905511811,894.2010061919505,0.00025370340306410486,25.0,30.0
654.13257,0.11122592716535432,893.3162280701755,0.00025370340306410486,25.0,30.0
655.63403,0.1115673996062992,893.0865067079465,0.00025370340306410486,25.0,30.0
657.1355,0.11193505905511811,893.8053147574819,0.00025370340306410486,25.0,30.0
658.63696,0.11227319881889763,894.2524767801858,0.00025370340306410486,25.0,30.0
660.13843,0.1126418188976378,894.7671310629515,0.00025370340306410486,25.0,30.0
661.63989,0.11302805314960629,895.3286635706914,0.00025370340306410486,25.0,30.0
663.14136,0.11343600393700788,895.8200980392157,0.00025370340306410486,25.0,30.0
664.64282,0.1138673287401575,894.3825335397316,0.00025370340306410486,25.0,30.0
666.14429,0.1142784251968504,896.469633642931,0.00025370340306410486,25.0,30.0
667.64575,0.11463422244094489,896.309778121775,0.00025370340306410486,25.0,30.0
669.14722,0.1150136496062992,895.814447884417,0.00025370340306410486,25.0,30.0
670.64868,0.11542529724409449,897.2847007223943,0.00025370340306410486,25.0,30.0
672.15015,0.11579523425196851,894.9852683178535,0.00025370340306410486,25.0,30.0
673.65161,0.11617070866141732,895.0560629514963,0.00025370340306410486,25.0,30.0
675.15308,0.11650517519685039,896.686068111455,0.00025370340306410486,25.0,30.0
676.65454,0.11690521850393701,896.3423890608876,0.00025370340306410486,25.0,30.0
678.15601,0.1172432401574803,897.0202012383901,0.00025370340306410486,25.0,30.0
679.65747,0.11760031692913386,897.5817595459237,0.00025370340306410486,25.0,30.0
681.15894,0.1180068248031496,897.9073271413829,0.00025370340306410486,25.0,30.0
682.6604,0.11841389566929134,898.4438080495356,0.00025370340306410486,25.0,30.0
684.16187,0.11877059645669291,897.8473168214655,0.00025370340306410486,25.0,30.0
685.66333,0.1191426811023622,900.528689370485,0.00025370340306410486,25.0,30.0
687.16479,0.11958508070866142,899.0574819401445,0.00025370340306410486,25.0,30.0
688.66626,0.11996398031496062,899.4722652218783,0.00025370340306410486,25.0,30.0
690.16772,0.12032740551181102,899.8262641898865,0.00025370340306410486,25.0,30.0
691.66919,0.12068700393700788,900.0785861713107,0.00025370340306410486,25.0,30.0
693.17065,0.12113670275590552,901.1670794633643,0.00025370340306410486,25.0,30.0
694.67212,0.12147168503937007,898.9313983488132,0.00025370340306410486,25.0,30.0
696.17358,0.12180815748031497,897.687564499484,0.00025370340306410486,25.0,30.0
697.67505,0.12217299015748032,900.7854231166151,0.00025370340306410486,25.0,30.0
699.17651,0.12251947047244095,901.8695820433436,0.00025370340306410486,25.0,30.0
700.67798,0.12289937992125985,899.9194788441692,0.00025370340306410486,25.0,30.0
702.17944,0.12331539173228347,902.3269349845201,0.00025370340306410486,25.0,30.0
703.68091,0.12375663188976378,902.8272445820434,0.00025370340306410486,25.0,30.0
705.18237,0.12419769291338582,903.0211300309597,0.00025370340306410486,25.0,30.0
706.68384,0.12459530905511812,901.0178018575851,0.00025370340306410486,25.0,30.0
708.1853,0.12498775984251968,902.4641124871001,0.00025370340306410486,25.0,30.0
709.68677,0.12537094291338582,901.7720072239423,0.00025370340306410486,25.0,30.0
711.18823,0.12571199212598425,902.2267801857586,0.00025370340306410486,25.0,30.0
712.6897,0.12609287598425198,901.9085655314757,0.00025370340306410486,25.0,30.0
714.19116,0.1264191751968504,902.7361713106295,0.00025370340306410486,25.0,30.0
715.69263,0.1268203090551181,904.7295923632612,0.00025370340306410486,25.0,30.0
717.19409,0.12722571456692913,905.7101393188855,0.00025370340306410486,25.0,30.0
718.69556,0.1276188720472441,904.4478586171311,0.00025370340306410486,25.0,30.0
720.19702,0.12803589173228347,906.6128740970073,0.00025370340306410486,25.0,30.0
721.69849,0.12842877952755904,902.9691434468524,0.00025370340306410486,25.0,30.0
723.19995,0.12876769291338583,903.8827915376678,0.00025370340306410486,25.0,30.0
724.70142,0.12904188582677165,901.885629514964,0.00025370340306410486,25.0,30.0
726.20288,0.12936968700787402,904.2558049535604,0.00025370340306410486,25.0,30.0
727.70435,0.12971744685039371,904.9865841073272,0.00025370340306410486,25.0,30.0
729.20581,0.13008655118110238,905.981862745098,0.00025370340306410486,25.0,30.0
730.70728,0.1304675748031496,906.2989422084623,0.00025370340306410486,25.0,30.0
732.20874,0.13090252362204724,906.9275025799794,0.00025370340306410486,25.0,30.0
733.71021,0.1313639783464567,907.0280959752322,0.00025370340306410486,25.0,30.0
735.21167,0.13184932283464568,906.7753095975232,0.00025370340306410486,25.0,30.0
736.71313,0.13225617125984251,906.5820175438597,0.00025370340306410486,25.0,30.0
738.2146,0.13265796259842522,906.921697626419,0.00025370340306410486,25.0,30.0
739.71606,0.13312534251968505,907.4200722394221,0.00025370340306410486,25.0,30.0
741.21753,0.13355765354330706,907.4594943240454,0.00025370340306410486,25.0,30.0
742.71899,0.13401207874015747,908.302657378741,0.00025370340306410486,25.0,30.0
744.22046,0.13448388385826773,907.3399380804954,0.00025370340306410486,25.0,30.0
745.72192,0.13490890748031495,907.1521155830753,0.00025370340306410486,25.0,30.0
747.22339,0.13526483267716535,907.0670020639835,0.00025370340306410486,25.0,30.0
748.72485,0.1356183779527559,907.6157636738907,0.00025370340306410486,25.0,30.0
750.22632,0.13607639566929133,909.0259287925697,0.00025370340306410486,25.0,30.0
751.72778,0.13647210826771652,908.7885964912281,0.00025370340306410486,25.0,30.0
753.22925,0.136903937007874,908.8958720330238,0.00025370340306410486,25.0,30.0
754.73071,0.13743507677165354,911.599871001032,0.00025370340306410486,25.0,30.0
756.23218,0.13785045472440946,907.4643962848297,0.00025370340306410486,25.0,30.0
757.73364,0.1382155807086614,907.2613261093911,0.00025370340306410486,25.0,30.0
759.23511,0.1385107874015748,908.2199948400413,0.00025370340306410486,25.0,30.0
760.73657,0.13880958464566928,909.2667440660475,0.00025370340306410486,25.0,30.0
762.23804,0.13921301968503938,909.9769349845202,0.00025370340306410486,25.0,30.0
763.7395,0.13963097834645669,911.3652476780186,0.00025370340306410486,25.0,30.0
765.24097,0.1400131181102362,909.2878998968008,0.00025370340306410486,25.0,30.0
766.74243,0.14039141929133858,910.4175180598555,0.00025370340306410486,25.0,30.0
768.2439,0.1407871909448819,908.1734520123839,0.00025370340306410486,25.0,30.0
769.74536,0.14115672834645668,911.3428018575852,0.00025370340306410486,25.0,30.0
771.24683,0.14160750590551183,910.9357843137255,0.00025370340306410486,25.0,30.0
772.74829,0.14207327952755905,912.1009287925697,0.00025370340306410486,25.0,30.0
774.24976,0.1425717874015748,911.2146284829722,0.00025370340306410486,25.0,30.0
775.75122,0.14298365748031497,911.5872807017545,0.00025370340306410486,25.0,30.0
777.25269,0.1434224094488189,912.3945304437565,0.00025370340306410486,25.0,30.0
778.75415,0.14380201377952756,911.845072239422,0.00025370340306410486,25.0,30.0
780.25562,0.1441975157480315,911.8897316821465,0.00025370340306410486,25.0,30.0
781.75708,0.14457984251968506,911.8159700722395,0.00025370340306410486,25.0,30.0
783.25854,0.14499976181102361,912.0963880288958,0.00025370340306410486,25.0,30.0
784.76001,0.1454335964566929,911.9985810113519,0.00025370340306410486,25.0,30.0
786.26147,0.14586206889763778,913.5150670794634,0.00025370340306410486,25.0,30.0
787.76294,0.1463254842519685,912.3184210526316,0.00025370340306410486,25.0,30.0
789.2644,0.14677809251968504,913.4723684210527,0.00025370340306410486,25.0,30.0
790.76587,0.1471761535433071,912.418137254902,0.00025370340306410486,25.0,30.0
792.26733,0.14755501771653542,911.7521155830754,0.00025370340306410486,25.0,30.0
793.7688,0.1479830688976378,913.9848297213623,0.00025370340306410486,25.0,30.0
795.27026,0.14838345078740156,914.38846749226,0.00025370340306410486,25.0,30.0
796.77173,0.14881973818897637,914.3171052631578,0.00025370340306410486,25.0,30.0
798.27319,0.14925743503937006,914.871439628483,0.00025370340306410486,25.0,30.0
799.77466,0.1497175748031496,913.6506965944274,0.00025370340306410486,25.0,30.0
801.27612,0.15017902952755904,915.3467492260062,0.00025370340306410486,25.0,30.0
802.77759,0.15065475196850392,914.2058565531476,0.00025370340306410486,25.0,30.0
804.27905,0.15106533267716535,913.6576883384934,0.00025370340306410486,25.0,30.0
805.78052,0.15147233267716534,914.5231940144479,0.00025370340306410486,25.0,30.0
807.28198,0.15195787598425195,914.1598813209495,0.00025370340306410486,25.0,30.0
808.78345,0.152372281496063,913.7339009287925,0.00025370340306410486,25.0,30.0
810.28491,0.1528243503937008,915.2666924664603,0.00025370340306410486,25.0,30.0
811.78638,0.15332151968503938,914.7423374613003,0.00025370340306410486,25.0,30.0
813.28784,0.15372813385826772,914.6150412796698,0.00025370340306410486,25.0,30.0
814.78931,0.15414686811023623,915.9025541795667,0.00025370340306410486,25.0,30.0
816.29077,0.1546200098425197,915.6913570691435,0.00025370340306410486,25.0,30.0
817.79224,0.15511624212598424,915.8680340557277,0.00025370340306410486,25.0,30.0
819.2937,0.15554227559055117,915.1089267285862,0.00025370340306410486,25.0,30.0
820.79517,0.15595832283464567,914.6169246646026,0.00025370340306410486,25.0,30.0
822.29663,0.15638600984251969,917.4538183694531,0.00025370340306410486,25.0,30.0
823.7981,0.15691191338582677,915.906475748194,0.00025370340306410486,25.0,30.0
825.29956,0.15732157874015748,916.0301857585139,0.00025370340306410486,25.0,30.0
826.80103,0.1578011496062992,915.4531475748195,0.00025370340306410486,25.0,30.0
828.30249,0.15822832086614172,916.6509287925696,0.00025370340306410486,25.0,30.0
829.80396,0.15866785826771654,917.0363519091846,0.00025370340306410486,25.0,30.0
831.30542,0.15906609448818898,918.5758255933953,0.00025370340306410486,25.0,30.0
832.80688,0.15958270669291338,916.903431372549,0.00025370340306410486,25.0,30.0
834.30835,0.16005317322834645,917.7308565531476,0.00025370340306410486,25.0,30.0
835.80981,0.16046404527559055,915.8853715170279,0.00025370340306410486,25.0,30.0
837.31128,0.16100968700787402,917.6970330237358,0.00025370340306410486,25.0,30.0
838.81274,0.1614661437007874,917.1146284829722,0.00025370340306410486,25.0,30.0
840.31421,0.1619418188976378,917.6147574819402,0.00025370340306410486,25.0,30.0
841.81567,0.1623828937007874,916.56153250774,0.00025370340306410486,25.0,30.0
843.31714,0.16282517519685039,915.9239680082559,0.00025370340306410486,25.0,30.0
844.8186,0.1632812933070866,917.5326883384932,0.00025370340306410486,25.0,30.0
846.32007,0.16375818897637795,918.6723942208462,0.00025370340306410486,25.0,30.0
847.82153,0.16425478346456693,919.3301083591332,0.00025370340306410486,25.0,30.0
849.323,0.16474182874015747,918.7481682146544,0.00025370340306410486,25.0,30.0
850.82446,0.16525711614173227,917.0354489164087,0.00025370340306410486,25.0,30.0
852.32593,0.16581068897637793,919.6218524251806,0.00025370340306410486,25.0,30.0
853.82739,0.16631386614173227,918.6734520123839,0.00025370340306410486,25.0,30.0
855.32886,0.16672881102362205,918.6384416924665,0.00025370340306410486,25.0,30.0
856.83032,0.16717574015748032,918.3155572755418,0.00025370340306410486,25.0,30.0
858.33179,0.16768625196850395,920.7182404540764,0.00025370340306410486,25.0,30.0
859.83325,0.16817401181102362,919.272729618163,0.00025370340306410486,25.0,30.0
861.33472,0.16861724606299214,917.6139318885449,0.00025370340306410486,25.0,30.0
862.83618,0.16912819094488188,919.6815015479876,0.00025370340306410486,25.0,30.0
864.33765,0.16955451771653543,919.0300825593396,0.00025370340306410486,25.0,30.0
865.83911,0.169966281496063,918.9092105263159,0.00025370340306410486,25.0,30.0
867.34058,0.170424405511811,918.8203560371517,0.00025370340306410486,25.0,30.0
868.84204,0.17097647440944883,920.5874097007224,0.00025370340306410486,25.0,30.0
870.34351,0.17147782283464566,921.7345459236326,0.00025370340306410486,25.0,30.0
871.84497,0.17196803543307085,919.987435500516,0.00025370340306410486,25.0,30.0
873.34644,0.17246700196850392,920.4291795665636,0.00025370340306410486,25.0,30.0
874.8479,0.17291817913385826,919.059004127967,0.00025370340306410486,25.0,30.0
876.34937,0.17344061023622045,918.9219556243551,0.00025370340306410486,25.0,30.0
877.85083,0.1739736496062992,921.5035087719299,0.00025370340306410486,25.0,30.0
879.35229,0.17445438188976378,918.6536119711043,0.00025370340306410486,25.0,30.0
880.85376,0.17493789566929135,921.302012383901,0.00025370340306410486,25.0,30.0
882.35522,0.17542639566929133,920.2383384932921,0.00025370340306410486,25.0,30.0
883.85669,0.17592104330708663,921.592363261094,0.00025370340306410486,25.0,30.0
885.35815,0.17646993503937008,920.5569917440661,0.00025370340306410486,25.0,30.0
886.85962,0.17709340157480316,922.1670020639835,0.00025370340306410486,25.0,30.0
888.36108,0.1776355216535433,918.8820691434469,0.00025370340306410486,25.0,30.0
889.86255,0.17815140748031497,920.4321981424149,0.00025370340306410486,25.0,30.0
891.36401,0.17865060826771653,921.1994582043344,0.00025370340306410486,25.0,30.0
892.86548,0.17923955511811024,920.1343911248711,0.00025370340306410486,25.0,30.0
894.36694,0.17973989566929133,919.8170020639835,0.00025370340306410486,25.0,30.0
895.86841,0.18032634448818896,921.838209494324,0.00025370340306410486,25.0,30.0
897.36987,0.18087758070866142,921.3424922600619,0.00025370340306410486,25.0,30.0
898.87134,0.18140827362204726,920.3328689370485,0.00025370340306410486,25.0,30.0
900.3728,0.18192505118110236,920.3627966976264,0.00025370340306410486,25.0,30.0
901.87427,0.1824223622047244,920.6984520123839,0.00025370340306410486,25.0,30.0
903.37573,0.1829114251968504,920.694298245614,0.00025370340306410486,25.0,30.0
904.8772,0.18346201771653545,921.8146542827657,0.00025370340306410486,25.0,30.0
906.37866,0.18404401968503936,921.1247420020641,0.00025370340306410486,25.0,30.0
907.88013,0.18463174606299212,921.4610423116616,0.00025370340306410486,25.0,30.0
909.38159,0.18521215354330708,921.6855263157895,0.00025370340306410486,25.0,30.0
910.88306,0.18572612598425195,920.7580495356037,0.00025370340306410486,25.0,30.0
912.38452,0.18629983267716535,920.6027089783282,0.00025370340306410486,25.0,30.0
913.88599,0.18681843897637795,921.6005675954592,0.00025370340306410486,25.0,30.0
915.38745,0.18736490157480315,922.4218524251806,0.00025370340306410486,25.0,30.0
916.88892,0.187983405511811,921.7610423116615,0.00025370340306410486,25.0,30.0
918.39038,0.18866882283464567,920.8565531475748,0.00025370340306410486,25.0,30.0
919.89185,0.18926556102362205,920.618008255934,0.00025370340306410486,25.0,30.0
921.39331,0.18976565354330707,920.4100361197111,0.00025370340306410486,25.0,30.0
922.89478,0.19034323228346456,921.6021929824561,0.00025370340306410486,25.0,30.0
924.39624,0.19095719488188975,922.2312693498452,0.00025370340306410486,25.0,30.0
925.89771,0.1914813287401575,921.2939886480908,0.00025370340306410486,25.0,30.0
927.39917,0.19213692125984252,922.3444530443757,0.00025370340306410486,25.0,30.0
928.90063,0.19273210039370078,922.3600619195047,0.00025370340306410486,25.0,30.0
930.4021,0.19335158858267715,921.0510577915377,0.00025370340306410486,25.0,30.0
931.90356,0.19397475196850392,919.377915376677,0.00025370340306410486,25.0,30.0
933.40503,0.19448885236220473,919.6684210526315,0.00025370340306410486,25.0,30.0
934.90649,0.19504068897637797,922.2083849329206,0.00025370340306410486,25.0,30.0
936.40796,0.1956208248031496,922.416382868937,0.00025370340306410486,25.0,30.0
937.90942,0.19622737204724408,921.3440660474718,0.00025370340306410486,25.0,30.0
939.41089,0.19681608661417324,921.9623581011352,0.00025370340306410486,25.0,30.0
940.11157,0.1970769094488189,924.315092879257,0.00025370340306410486,25.0,30.0