File: datasets/am_bench_2022/csv/45-XY.02-3.csv
Time(s),Strain(%),Stress(MPa),SR(s-1),Temp(C),Angle(deg)
33.560059,1.1217770669291338e-05,8.99474057464671,0.00025370340306410486,25.0,45.0
35.161621,2.731683464566929e-05,15.597623194451687,0.00025370340306410486,25.0,45.0
36.763184,2.2675330708661416e-05,20.695417948584243,0.00025370340306410486,25.0,45.0
38.364746,3.650950393700788e-05,25.845217447984563,0.00025370340306410486,25.0,45.0
39.966309,4.243661811023622e-05,32.06416019189655,0.00025370340306410486,25.0,45.0
41.567871,6.953103346456693e-05,37.989638629608386,0.00025370340306410486,25.0,45.0
43.169434,7.457586811023621e-05,43.94931949731449,0.00025370340306410486,25.0,45.0
44.770996,0.00010209800196850394,54.0373337852636,0.00025370340306410486,25.0,45.0
46.372559,0.00011073225984251968,58.45828596756532,0.00025370340306410486,25.0,45.0
47.974121,0.0001360498090551181,66.53661156593837,0.00025370340306410486,25.0,45.0
49.575684,0.00016825681692913386,74.09872242790843,0.00025370340306410486,25.0,45.0
51.177246,0.0002108132283464567,83.65253689315325,0.00025370340306410486,25.0,45.0
52.778809,0.00022649364173228347,91.27842988997237,0.00025370340306410486,25.0,45.0
54.380371,0.0002411503937007874,102.82027167961621,0.00025370340306410486,25.0,45.0
55.981934,0.00027519659448818894,110.6240157480315,0.00025370340306410486,25.0,45.0
57.583496,0.00031337608267716533,122.03964645147833,0.00025370340306410486,25.0,45.0
59.185059,0.00035061340551181103,130.04909787766596,0.00025370340306410486,25.0,45.0
60.786621,0.0003730832480314961,139.16926005110287,0.00025370340306410486,25.0,45.0
62.388184,0.000400119783464567,149.78858789174532,0.00025370340306410486,25.0,45.0
63.989746,0.0004310119094488189,159.59547635187985,0.00025370340306410486,25.0,45.0
65.591309,0.00047133635826771653,169.2844136204829,0.00025370340306410486,25.0,45.0
67.192871,0.000500716003937008,179.93138394952288,0.00025370340306410486,25.0,45.0
68.794434,0.0005234232283464567,189.3832716274704,0.00025370340306410486,25.0,45.0
70.395996,0.0005774549212598425,202.53826198049748,0.00025370340306410486,25.0,45.0
71.997559,0.0006243001181102363,216.35180685195806,0.00025370340306410486,25.0,45.0
73.599121,0.0006556044881889764,225.92449288209835,0.00025370340306410486,25.0,45.0
75.200684,0.0006890926771653543,237.37217500130365,0.00025370340306410486,25.0,45.0
76.802246,0.0007295161023622048,247.15746727851072,0.00025370340306410486,25.0,45.0
78.403809,0.0007740238385826772,261.7546540126193,0.00025370340306410486,25.0,45.0
80.005371,0.0008163348622047243,272.1224904833916,0.00025370340306410486,25.0,45.0
81.606934,0.0008669245472440945,283.3473953173072,0.00025370340306410486,25.0,45.0
83.208496,0.0009018548228346456,296.79657923554254,0.00025370340306410486,25.0,45.0
84.810059,0.0009286525393700788,308.6325024769255,0.00025370340306410486,25.0,45.0
86.411621,0.0009927723622047244,320.2652396099494,0.00025370340306410486,25.0,45.0
88.013184,0.0010199681692913385,331.93257548104503,0.00025370340306410486,25.0,45.0
89.614746,0.0010492908070866142,342.0790791051781,0.00025370340306410486,25.0,45.0
91.216309,0.0010815461811023621,355.68540439067635,0.00025370340306410486,25.0,45.0
92.817871,0.001126588562992126,365.92318923710695,0.00025370340306410486,25.0,45.0
94.419434,0.0011735815748031497,380.84421442352823,0.00025370340306410486,25.0,45.0
96.020996,0.0012157257480314959,389.7676383167336,0.00025370340306410486,25.0,45.0
97.622559,0.0012492629921259841,399.4246753923972,0.00025370340306410486,25.0,45.0
99.224121,0.0012869308661417323,412.1318767273296,0.00025370340306410486,25.0,45.0
100.82568,0.0013249304724409449,422.03141784429266,0.00025370340306410486,25.0,45.0
102.42725,0.0013693655708661417,433.00920373363925,0.00025370340306410486,25.0,45.0
104.02881,0.0014122341732283464,447.4455858580592,0.00025370340306410486,25.0,45.0
105.63037,0.0014251824015748032,456.74808364186265,0.00025370340306410486,25.0,45.0
107.23193,0.0014775339173228345,468.8866350315482,0.00025370340306410486,25.0,45.0
108.8335,0.0015037926377952755,479.04998174897014,0.00025370340306410486,25.0,45.0
110.43506,0.0015294941141732283,487.8287271210304,0.00025370340306410486,25.0,45.0
112.03662,0.0015753462598425197,500.4850341554988,0.00025370340306410486,25.0,45.0
113.63818,0.0016113332480314961,509.2800750899515,0.00025370340306410486,25.0,45.0
115.23975,0.001645377125984252,517.145903947437,0.00025370340306410486,25.0,45.0
116.84131,0.0016567484251968506,525.5065964436565,0.00025370340306410486,25.0,45.0
118.44287,0.0016844431692913386,534.9647233665328,0.00025370340306410486,25.0,45.0
120.04443,0.0017328154921259842,542.9939250143401,0.00025370340306410486,25.0,45.0
121.646,0.0017402712007874015,551.0304270740992,0.00025370340306410486,25.0,45.0
123.24756,0.0017674858070866142,558.1680919851906,0.00025370340306410486,25.0,45.0
124.84912,0.0017983717913385825,566.8217135109767,0.00025370340306410486,25.0,45.0
126.45068,0.0018152877559055116,573.1951295823122,0.00025370340306410486,25.0,45.0
128.05225,0.0018323670866141732,580.5159826875945,0.00025370340306410486,25.0,45.0
129.65381,0.0018559355905511813,584.1378474213902,0.00025370340306410486,25.0,45.0
131.25537,0.0018677771456692912,591.8881733326381,0.00025370340306410486,25.0,45.0
132.85693,0.0019049202362204723,597.1871773478647,0.00025370340306410486,25.0,45.0
134.4585,0.001921370905511811,603.8478385566043,0.00025370340306410486,25.0,45.0
136.06006,0.0019215635826771652,607.6926526568285,0.00025370340306410486,25.0,45.0
137.66162,0.00196180094488189,614.1703864003755,0.00025370340306410486,25.0,45.0
139.26318,0.0019732326771653543,617.8638212441988,0.00025370340306410486,25.0,45.0
140.86475,0.0020059852362204725,625.0578036189186,0.00025370340306410486,25.0,45.0
142.46631,0.002047851181102362,627.8411638942483,0.00025370340306410486,25.0,45.0
144.06787,0.0020655285433070865,635.0402304844345,0.00025370340306410486,25.0,45.0
145.66943,0.0020682114173228346,638.7388016895239,0.00025370340306410486,25.0,45.0
147.271,0.002111568897637795,643.1911925744382,0.00025370340306410486,25.0,45.0
148.87256,0.0021376220472440945,648.9542159879021,0.00025370340306410486,25.0,45.0
150.47412,0.0021710381889763776,653.2139802888877,0.00025370340306410486,25.0,45.0
152.07568,0.0021765377952755903,654.3910934974188,0.00025370340306410486,25.0,45.0
153.67725,0.0022058557086614174,659.1158940397352,0.00025370340306410486,25.0,45.0
155.27881,0.002261695275590551,664.4113782134849,0.00025370340306410486,25.0,45.0
156.88037,0.002296889960629921,668.7463367575742,0.00025370340306410486,25.0,45.0
158.48193,0.0023248427165354327,671.9234499661053,0.00025370340306410486,25.0,45.0
160.0835,0.0023508570866141733,676.6216040047975,0.00025370340306410486,25.0,45.0
161.68506,0.0023820444881889765,679.7394795849194,0.00025370340306410486,25.0,45.0
163.28662,0.0024311791338582677,682.0183553214789,0.00025370340306410486,25.0,45.0
164.88818,0.002477099212598425,686.6234551806853,0.00025370340306410486,25.0,45.0
166.48975,0.002544003346456693,689.7054023048444,0.00025370340306410486,25.0,45.0
168.09131,0.0025731492125984252,692.9300203368618,0.00025370340306410486,25.0,45.0
169.69287,0.0026167984251968504,695.7990040152266,0.00025370340306410486,25.0,45.0
171.29443,0.002675963582677165,698.6701256713771,0.00025370340306410486,25.0,45.0
172.896,0.002761474803149606,703.4175574907442,0.00025370340306410486,25.0,45.0
174.49756,0.0028046956692913388,704.943343588674,0.00025370340306410486,25.0,45.0
176.09912,0.0028566425196850393,708.5147051155029,0.00025370340306410486,25.0,45.0
177.70068,0.002925199409448819,709.7934504875633,0.00025370340306410486,25.0,45.0
179.30225,0.0030344832677165353,714.1759399280388,0.00025370340306410486,25.0,45.0
180.90381,0.003129529133858268,716.7936590707618,0.00025370340306410486,25.0,45.0
182.50537,0.0032209545275590553,719.7490222662565,0.00025370340306410486,25.0,45.0
184.10693,0.0033116950787401575,722.5362674036606,0.00025370340306410486,25.0,45.0
185.7085,0.0034138226377952753,725.4753871825625,0.00025370340306410486,25.0,45.0
187.31006,0.0035433783464566926,726.1580017729573,0.00025370340306410486,25.0,45.0
188.91162,0.0036749078740157485,730.1862126505711,0.00025370340306410486,25.0,45.0
190.51318,0.003818481496062992,732.6705167648746,0.00025370340306410486,25.0,45.0
192.11475,0.003970039960629922,735.487276424884,0.00025370340306410486,25.0,45.0
193.71631,0.004123211417322834,736.0025029983835,0.00025370340306410486,25.0,45.0
195.31787,0.004270289960629921,737.2330656515618,0.00025370340306410486,25.0,45.0
196.91943,0.004435685236220472,740.7450852583825,0.00025370340306410486,25.0,45.0
198.521,0.004611323031496063,742.3791521092976,0.00025370340306410486,25.0,45.0
200.12256,0.004811884842519685,744.0829378943527,0.00025370340306410486,25.0,45.0
201.72412,0.005020215551181102,745.8937790061011,0.00025370340306410486,25.0,45.0
203.32568,0.005258228937007873,747.1932262606248,0.00025370340306410486,25.0,45.0
204.92725,0.005477939960629921,748.6041873077124,0.00025370340306410486,25.0,45.0
206.52881,0.005740094094488189,751.1983626218909,0.00025370340306410486,25.0,45.0
208.13037,0.005966445866141732,753.1144339573448,0.00025370340306410486,25.0,45.0
209.73193,0.00624778996062992,754.8330552224018,0.00025370340306410486,25.0,45.0
211.3335,0.006529415944881889,755.5154873024978,0.00025370340306410486,25.0,45.0
212.93506,0.00678842342519685,755.3829587526725,0.00025370340306410486,25.0,45.0
214.53662,0.007092437204724409,758.4926213693487,0.00025370340306410486,25.0,45.0
216.13818,0.00737309311023622,759.7898785002868,0.00025370340306410486,25.0,45.0
217.73975,0.007671509448818898,761.2841163894249,0.00025370340306410486,25.0,45.0
219.34131,0.007983275787401574,763.1049434218073,0.00025370340306410486,25.0,45.0
220.94287,0.00828344251968504,763.3752933201231,0.00025370340306410486,25.0,45.0
222.54443,0.00861769940944882,764.1401679094748,0.00025370340306410486,25.0,45.0
224.146,0.008988857874015748,766.5935495645826,0.00025370340306410486,25.0,45.0
225.74756,0.00931934094488189,766.3696094279605,0.00025370340306410486,25.0,45.0
227.34912,0.009602760826771653,767.9490535537362,0.00025370340306410486,25.0,45.0
228.95068,0.009974190551181103,769.9505657819263,0.00025370340306410486,25.0,45.0
230.55225,0.010298394094488189,770.6785211451217,0.00025370340306410486,25.0,45.0
232.15381,0.010605283267716535,770.9110392657872,0.00025370340306410486,25.0,45.0
233.75537,0.010913775393700788,771.8035406997966,0.00025370340306410486,25.0,45.0
235.35693,0.011247359842519686,772.3749022266256,0.00025370340306410486,25.0,45.0
236.9585,0.011583838582677164,776.2201334932472,0.00025370340306410486,25.0,45.0
238.56006,0.011928125787401574,775.0430985034155,0.00025370340306410486,25.0,45.0
240.16162,0.012258086811023621,775.6741930437503,0.00025370340306410486,25.0,45.0
241.76318,0.012579888779527558,775.6171455389269,0.00025370340306410486,25.0,45.0
243.36475,0.012890893307086614,776.4429264222767,0.00025370340306410486,25.0,45.0
244.96631,0.013226561023622047,779.0255253689315,0.00025370340306410486,25.0,45.0
246.56787,0.013605238385826772,780.0454711372998,0.00025370340306410486,25.0,45.0
248.16943,0.013957963188976377,781.5001042915993,0.00025370340306410486,25.0,45.0
249.771,0.014294456692913385,780.3896334150285,0.00025370340306410486,25.0,45.0
251.37256,0.014696620669291336,782.2626062470669,0.00025370340306410486,25.0,45.0
252.97412,0.015139854133858268,785.4109610470878,0.00025370340306410486,25.0,45.0
254.57568,0.01549630866141732,783.8831412629713,0.00025370340306410486,25.0,45.0
256.17725,0.015802852952755908,783.5648693747719,0.00025370340306410486,25.0,45.0
257.77881,0.016154282874015748,785.5275329822183,0.00025370340306410486,25.0,45.0
259.38037,0.0165044,785.8285446107317,0.00025370340306410486,25.0,45.0
260.98193,0.01687514409448819,788.5226573499505,0.00025370340306410486,25.0,45.0
262.5835,0.017279471653543304,788.2752255305836,0.00025370340306410486,25.0,45.0
264.18506,0.017658946653543305,788.7069406059343,0.00025370340306410486,25.0,45.0
265.78662,0.018028532086614174,789.1481201439224,0.00025370340306410486,25.0,45.0
267.38818,0.018392167322834645,789.0428377744173,0.00025370340306410486,25.0,45.0
268.98975,0.01875865374015748,791.6134171142515,0.00025370340306410486,25.0,45.0
270.59131,0.019085784251968503,792.2242269385201,0.00025370340306410486,25.0,45.0
272.19287,0.0194441218503937,792.1442874276477,0.00025370340306410486,25.0,45.0
273.79443,0.019771076771653545,792.8079470198676,0.00025370340306410486,25.0,45.0
275.396,0.020069220472440943,794.3426500495385,0.00025370340306410486,25.0,45.0
276.99756,0.020424805118110234,793.3513583980811,0.00025370340306410486,25.0,45.0
278.59912,0.020778978346456693,794.3185326171978,0.00025370340306410486,25.0,45.0
280.20068,0.021130484251968503,795.7154403712782,0.00025370340306410486,25.0,45.0
281.80225,0.021487785433070866,795.6826406632946,0.00025370340306410486,25.0,45.0
283.40381,0.021859332677165354,798.0184596130781,0.00025370340306410486,25.0,45.0
285.00537,0.022194350393700785,798.4663138134223,0.00025370340306410486,25.0,45.0
286.60693,0.022622767716535434,800.9443865046671,0.00025370340306410486,25.0,45.0
288.2085,0.023038870078740156,800.7579652708974,0.00025370340306410486,25.0,45.0
289.81006,0.02338556496062992,799.9620900036501,0.00025370340306410486,25.0,45.0
291.41162,0.02377691338582677,801.9742660478698,0.00025370340306410486,25.0,45.0
293.01318,0.02414772834645669,800.014079365907,0.00025370340306410486,25.0,45.0
294.61475,0.024483807086614174,801.576367523596,0.00025370340306410486,25.0,45.0
296.21631,0.024871515748031495,804.4952286593316,0.00025370340306410486,25.0,45.0
297.81787,0.025237765748031497,804.0975126453565,0.00025370340306410486,25.0,45.0
299.41943,0.02557497440944882,803.9483235125412,0.00025370340306410486,25.0,45.0
301.021,0.025929935039370078,803.2735047191949,0.00025370340306410486,25.0,45.0
302.62256,0.026317803149606297,806.2298847577828,0.00025370340306410486,25.0,45.0
304.22412,0.02664033464566929,806.2778067476664,0.00025370340306410486,25.0,45.0
305.82568,0.027033830708661416,807.5922980653909,0.00025370340306410486,25.0,45.0
307.42725,0.027413503937007876,808.4490014079366,0.00025370340306410486,25.0,45.0
309.02881,0.027766917322834643,807.1482244355218,0.00025370340306410486,25.0,45.0
310.63037,0.02811787598425197,810.0942796057778,0.00025370340306410486,25.0,45.0
312.23193,0.02840296850393701,808.1928612400271,0.00025370340306410486,25.0,45.0
313.8335,0.028735114173228344,810.4132554622726,0.00025370340306410486,25.0,45.0
315.43506,0.02910253346456693,811.7355686499452,0.00025370340306410486,25.0,45.0
317.03662,0.029418602362204727,811.5312874797935,0.00025370340306410486,25.0,45.0
318.63818,0.029826706692913384,812.3050790008865,0.00025370340306410486,25.0,45.0
320.23975,0.030143273622047242,812.4018876779476,0.00025370340306410486,25.0,45.0
321.84131,0.03055058661417323,814.2070188246337,0.00025370340306410486,25.0,45.0
323.44287,0.030938984251968504,814.0257339521302,0.00025370340306410486,25.0,45.0
325.04443,0.03128913188976378,814.1973457787975,0.00025370340306410486,25.0,45.0
326.646,0.03160149015748031,814.6086718464828,0.00025370340306410486,25.0,45.0
328.24756,0.031971858267716535,816.0095687542369,0.00025370340306410486,25.0,45.0
329.84912,0.032348897637795276,815.9967930333212,0.00025370340306410486,25.0,45.0
331.45068,0.03278177755905512,818.8896334150285,0.00025370340306410486,25.0,45.0
333.05225,0.03319891338582677,817.7288157688898,0.00025370340306410486,25.0,45.0
334.65381,0.03352021456692913,817.435756374824,0.00025370340306410486,25.0,45.0
336.25537,0.033894450787401574,820.0600980341034,0.00025370340306410486,25.0,45.0
337.85693,0.03428147440944882,819.196068206706,0.00025370340306410486,25.0,45.0
339.4585,0.03465124606299213,820.6950513636127,0.00025370340306410486,25.0,45.0
341.06006,0.034986167322834646,821.021666579757,0.00025370340306410486,25.0,45.0
342.66162,0.0353555531496063,821.7900610105855,0.00025370340306410486,25.0,45.0
344.26318,0.03571867913385827,820.4935860666424,0.00025370340306410486,25.0,45.0
345.86475,0.036078332677165356,822.3262762684467,0.00025370340306410486,25.0,45.0
347.46631,0.036458622047244094,822.1262710538667,0.00025370340306410486,25.0,45.0
349.06787,0.03672454527559055,822.4383115190071,0.00025370340306410486,25.0,45.0
350.66943,0.03706384251968504,821.353183501069,0.00025370340306410486,25.0,45.0
352.271,0.037396899606299217,825.993794649841,0.00025370340306410486,25.0,45.0
353.87256,0.03778236614173228,825.5827032382541,0.00025370340306410486,25.0,45.0
355.47412,0.03821171259842519,825.4776294519477,0.00025370340306410486,25.0,45.0
357.07568,0.038511423228346456,825.8240339990614,0.00025370340306410486,25.0,45.0
358.67725,0.03883057874015748,826.0423684622205,0.00025370340306410486,25.0,45.0
360.27881,0.03916040748031496,828.480471398029,0.00025370340306410486,25.0,45.0
361.88037,0.039566490157480316,830.443187151275,0.00025370340306410486,25.0,45.0
363.48193,0.04001541929133858,829.8520884392763,0.00025370340306410486,25.0,45.0
365.0835,0.04036809842519685,829.1760181467383,0.00025370340306410486,25.0,45.0
366.68506,0.04072189566929134,828.3667153360797,0.00025370340306410486,25.0,45.0
368.28662,0.04110810039370078,830.9829743964124,0.00025370340306410486,25.0,45.0
369.88818,0.0414446811023622,831.0935495645825,0.00025370340306410486,25.0,45.0
371.48975,0.041847893700787404,831.2403399906138,0.00025370340306410486,25.0,45.0
373.09131,0.042225155511811024,832.4267351514835,0.00025370340306410486,25.0,45.0
374.69287,0.042562104330708665,832.4591959117693,0.00025370340306410486,25.0,45.0
376.29443,0.04289893897637795,834.0086040569432,0.00025370340306410486,25.0,45.0
377.896,0.043234214566929136,835.0848672889399,0.00025370340306410486,25.0,45.0
379.49756,0.04355024015748032,834.7113469260051,0.00025370340306410486,25.0,45.0
381.09912,0.04388958464566929,834.1321635292278,0.00025370340306410486,25.0,45.0
382.70068,0.04430580708661418,836.26667361944,0.00025370340306410486,25.0,45.0
384.30225,0.04470635433070866,835.6006674662356,0.00025370340306410486,25.0,45.0
385.90381,0.04502701968503937,835.8244772383584,0.00025370340306410486,25.0,45.0
387.50537,0.04531659645669291,837.355165041456,0.00025370340306410486,25.0,45.0
389.10693,0.045705606299212595,837.3860353548522,0.00025370340306410486,25.0,45.0
390.7085,0.04602614960629921,837.1482244355217,0.00025370340306410486,25.0,45.0
392.31006,0.04643882677165354,839.6949992178131,0.00025370340306410486,25.0,45.0
393.91162,0.046832694881889764,839.2110340512072,0.00025370340306410486,25.0,45.0
395.51318,0.04719198622047244,839.5247692548365,0.00025370340306410486,25.0,45.0
397.11475,0.04752512992125984,839.9620117849507,0.00025370340306410486,25.0,45.0
398.71631,0.0478398562992126,840.0372581738542,0.00025370340306410486,25.0,45.0
400.31787,0.04819838385826772,843.9176357094436,0.00025370340306410486,25.0,45.0
401.91943,0.04855070472440945,842.4896751316682,0.00025370340306410486,25.0,45.0
403.521,0.04894562401574803,843.5077175783491,0.00025370340306410486,25.0,45.0
405.12256,0.04934106496062992,842.3495854408928,0.00025370340306410486,25.0,45.0
406.72412,0.049661692913385826,844.0501121134693,0.00025370340306410486,25.0,45.0
408.32568,0.050041003937007875,845.613338895552,0.00025370340306410486,25.0,45.0
409.92725,0.05038433464566929,843.2053501590447,0.00025370340306410486,25.0,45.0
411.52881,0.05070950196850394,846.3553475517547,0.00025370340306410486,25.0,45.0
413.13037,0.051071799212598426,844.6918183240341,0.00025370340306410486,25.0,45.0
414.73193,0.051422053149606295,846.7445898732858,0.00025370340306410486,25.0,45.0
416.3335,0.05178455708661417,846.5293320123064,0.00025370340306410486,25.0,45.0
417.93506,0.05214475393700787,847.958935182771,0.00025370340306410486,25.0,45.0
419.53662,0.052495141732283465,848.4877718099807,0.00025370340306410486,25.0,45.0
421.13818,0.05286429724409449,850.0334515304793,0.00025370340306410486,25.0,45.0
422.73975,0.05317999803149607,848.186812327267,0.00025370340306410486,25.0,45.0
424.34131,0.053535588582677165,849.1891328153517,0.00025370340306410486,25.0,45.0
425.94287,0.05395458267716535,850.9412316837878,0.00025370340306410486,25.0,45.0
427.54443,0.05431282677165354,851.4035302706368,0.00025370340306410486,25.0,45.0
429.146,0.05469324606299212,849.7857068363143,0.00025370340306410486,25.0,45.0
430.74756,0.05504663779527559,851.5741252542108,0.00025370340306410486,25.0,45.0
432.34912,0.055369100393700785,852.0216405068572,0.00025370340306410486,25.0,45.0
433.95068,0.05573685433070866,853.6236116180842,0.00025370340306410486,25.0,45.0
435.55225,0.056110204724409446,854.3946133388955,0.00025370340306410486,25.0,45.0
437.15381,0.05644878346456693,852.4961672837253,0.00025370340306410486,25.0,45.0
438.75537,0.05686160433070866,855.411221776086,0.00025370340306410486,25.0,45.0
440.35693,0.057221814960629926,855.996219429525,0.00025370340306410486,25.0,45.0
441.9585,0.05757404527559055,855.3741200396308,0.00025370340306410486,25.0,45.0
443.56006,0.05787241929133858,855.2874797935026,0.00025370340306410486,25.0,45.0
445.16162,0.05821543503937008,856.5923502111905,0.00025370340306410486,25.0,45.0
446.76318,0.05859757283464567,856.1809459248058,0.00025370340306410486,25.0,45.0
448.36475,0.058929340551181104,859.0698492986389,0.00025370340306410486,25.0,45.0
449.96631,0.05927644881889763,858.8841581060645,0.00025370340306410486,25.0,45.0
451.56787,0.05967543110236221,859.0095687542369,0.00025370340306410486,25.0,45.0
453.16943,0.060014596456692916,858.0017208113886,0.00025370340306410486,25.0,45.0
454.771,0.06036831692913386,858.8838452312667,0.00025370340306410486,25.0,45.0
456.37256,0.060722348425196845,859.848959691297,0.00025370340306410486,25.0,45.0
457.97412,0.06101936417322835,860.2943108932575,0.00025370340306410486,25.0,45.0
459.57568,0.061362730314960624,861.3320644522083,0.00025370340306410486,25.0,45.0
461.17725,0.061756348425196846,862.0849715805392,0.00025370340306410486,25.0,45.0
462.77881,0.062113736220472435,860.9295770975649,0.00025370340306410486,25.0,45.0
464.38037,0.062471622047244095,860.95757939198,0.00025370340306410486,25.0,45.0
465.98193,0.06281818503937008,861.3855921155551,0.00025370340306410486,25.0,45.0
467.5835,0.06318931299212598,864.8857746258539,0.00025370340306410486,25.0,45.0
469.18506,0.06352122047244095,864.18485685978,0.00025370340306410486,25.0,45.0
470.78662,0.06384207086614173,864.241513271106,0.00025370340306410486,25.0,45.0
472.38818,0.06416694094488189,864.1200657037075,0.00025370340306410486,25.0,45.0
473.98975,0.06455711023622047,866.7617197684726,0.00025370340306410486,25.0,45.0
475.59131,0.06498060826771654,865.7911299994786,0.00025370340306410486,25.0,45.0
477.19287,0.0653738405511811,866.2297022474839,0.00025370340306410486,25.0,45.0
478.79443,0.06574202755905512,868.5634614381812,0.00025370340306410486,25.0,45.0
480.396,0.06611445669291338,865.0463054700945,0.00025370340306410486,25.0,45.0
481.99756,0.0664967716535433,868.212285550399,0.00025370340306410486,25.0,45.0
483.59912,0.0668061594488189,866.6929916045264,0.00025370340306410486,25.0,45.0
485.20068,0.06712515551181103,868.6168848099286,0.00025370340306410486,25.0,45.0
486.80225,0.06749134251968504,869.8769880586119,0.00025370340306410486,25.0,45.0
488.40381,0.06790189960629921,868.9557803618919,0.00025370340306410486,25.0,45.0
490.00537,0.06825824212598425,869.6844918391823,0.00025370340306410486,25.0,45.0
491.60693,0.06860965748031496,868.7829431089325,0.00025370340306410486,25.0,45.0
493.2085,0.06895815551181102,868.7313969859729,0.00025370340306410486,25.0,45.0
494.81006,0.06926136614173228,870.6248631172758,0.00025370340306410486,25.0,45.0
496.41162,0.06964669488188976,872.2889659487928,0.00025370340306410486,25.0,45.0
498.01318,0.07004721456692914,873.7448245293841,0.00025370340306410486,25.0,45.0
499.61475,0.07045676771653543,871.7854200344162,0.00025370340306410486,25.0,45.0
501.21631,0.0708371811023622,872.4209991135215,0.00025370340306410486,25.0,45.0
502.81787,0.07120916535433071,873.0285758982113,0.00025370340306410486,25.0,45.0
504.41943,0.0715405098425197,873.638655681285,0.00025370340306410486,25.0,45.0
506.021,0.07191197047244094,874.9958804818272,0.00025370340306410486,25.0,45.0
507.62256,0.0722768622047244,875.1263231996662,0.00025370340306410486,25.0,45.0
509.22412,0.07261582283464567,874.1747405746468,0.00025370340306410486,25.0,45.0
510.82568,0.07299093897637794,876.2203420764457,0.00025370340306410486,25.0,45.0
512.42725,0.07335552362204724,876.3894769776294,0.00025370340306410486,25.0,45.0
514.02881,0.07368223031496063,876.1254367210721,0.00025370340306410486,25.0,45.0
515.63037,0.0740339842519685,877.7927465192679,0.00025370340306410486,25.0,45.0
517.23193,0.07440732283464567,878.1213172028994,0.00025370340306410486,25.0,45.0
518.8335,0.07478063779527559,877.6049694947072,0.00025370340306410486,25.0,45.0
520.43506,0.07515024015748031,877.8912760077176,0.00025370340306410486,25.0,45.0
522.03662,0.07548270078740157,878.9850602283987,0.00025370340306410486,25.0,45.0
523.63818,0.07583733661417323,878.9934035563435,0.00025370340306410486,25.0,45.0
525.23975,0.07618915551181103,880.6640767586172,0.00025370340306410486,25.0,45.0
526.84131,0.07650910826771654,879.8730249778381,0.00025370340306410486,25.0,45.0
528.44287,0.07688704133858268,881.754992960317,0.00025370340306410486,25.0,45.0
530.04443,0.07716930708661417,880.7594774990874,0.00025370340306410486,25.0,45.0
531.646,0.07759330905511812,881.9044428221307,0.00025370340306410486,25.0,45.0
533.24756,0.07794102755905512,880.6576367523596,0.00025370340306410486,25.0,45.0
534.84912,0.07830975590551181,881.3741461125306,0.00025370340306410486,25.0,45.0
536.45068,0.07868238385826772,883.8624654534078,0.00025370340306410486,25.0,45.0
538.05225,0.07903738976377953,883.6984147676905,0.00025370340306410486,25.0,45.0
539.65381,0.07936885236220473,883.1458257287376,0.00025370340306410486,25.0,45.0
541.25537,0.07969277755905511,883.8472388799083,0.00025370340306410486,25.0,45.0
542.85693,0.0800994783464567,885.1105230223706,0.00025370340306410486,25.0,45.0
544.4585,0.08051996062992126,885.8508890858842,0.00025370340306410486,25.0,45.0
546.06006,0.0809135748031496,885.2027689419617,0.00025370340306410486,25.0,45.0
547.66162,0.08126631102362206,885.2978046618344,0.00025370340306410486,25.0,45.0
549.26318,0.0815915905511811,886.2094696772175,0.00025370340306410486,25.0,45.0
550.86475,0.08195728346456693,886.507117901653,0.00025370340306410486,25.0,45.0
552.46631,0.08235434645669291,887.0297231058039,0.00025370340306410486,25.0,45.0
554.06787,0.08271145275590551,885.7028471606612,0.00025370340306410486,25.0,45.0
555.66943,0.08306308464566929,889.7490483391564,0.00025370340306410486,25.0,45.0
557.271,0.08346376771653544,888.3785002868019,0.00025370340306410486,25.0,45.0
558.87256,0.08385829133858268,889.7960838504458,0.00025370340306410486,25.0,45.0
560.47412,0.08420919488188977,889.0142097304063,0.00025370340306410486,25.0,45.0
562.07568,0.08453779527559055,888.7089221463211,0.00025370340306410486,25.0,45.0
563.67725,0.0848893405511811,889.2887573655942,0.00025370340306410486,25.0,45.0
565.27881,0.0852709625984252,891.4084580487041,0.00025370340306410486,25.0,45.0
566.88037,0.08561357677165354,890.6001720811388,0.00025370340306410486,25.0,45.0
568.48193,0.08605671062992126,891.0393700787401,0.00025370340306410486,25.0,45.0
570.0835,0.08642380708661417,890.5047452677686,0.00025370340306410486,25.0,45.0
571.68506,0.08679897047244094,893.0696928612401,0.00025370340306410486,25.0,45.0
573.28662,0.08711618897637795,891.7885227094957,0.00025370340306410486,25.0,45.0
574.88818,0.08744647834645669,890.826823799343,0.00025370340306410486,25.0,45.0
576.48975,0.08782820669291339,893.6397246701778,0.00025370340306410486,25.0,45.0
578.09131,0.08820378149606299,893.9649319497314,0.00025370340306410486,25.0,45.0
579.69287,0.08857340551181102,894.0963915106638,0.00025370340306410486,25.0,45.0
581.29443,0.08892461614173228,894.9074672785108,0.00025370340306410486,25.0,45.0
582.896,0.0893093937007874,895.0510246649633,0.00025370340306410486,25.0,45.0
584.49756,0.08963342913385827,895.8868696876467,0.00025370340306410486,25.0,45.0
586.09912,0.09002007874015748,894.4144808885644,0.00025370340306410486,25.0,45.0
587.70068,0.0904246751968504,897.7742869061897,0.00025370340306410486,25.0,45.0
589.30225,0.09083752559055118,894.7328049225634,0.00025370340306410486,25.0,45.0
590.90381,0.09118858858267717,895.1071596182928,0.00025370340306410486,25.0,45.0
592.50537,0.09152622244094488,897.5018511758879,0.00025370340306410486,25.0,45.0
594.10693,0.09187057480314961,897.6426448349586,0.00025370340306410486,25.0,45.0
595.7085,0.09226287992125985,898.8999582833602,0.00025370340306410486,25.0,45.0
597.31006,0.09259601574803149,896.8082598946654,0.00025370340306410486,25.0,45.0
598.91162,0.0929441279527559,897.5249517651354,0.00025370340306410486,25.0,45.0
600.51318,0.093271031496063,899.010455232831,0.00025370340306410486,25.0,45.0
602.11475,0.09364271653543307,898.7213328466393,0.00025370340306410486,25.0,45.0
603.71631,0.09405238582677165,898.886061427752,0.00025370340306410486,25.0,45.0
605.31787,0.09440228149606299,899.7259998957084,0.00025370340306410486,25.0,45.0
606.91943,0.09477482874015748,900.0454711373,0.00025370340306410486,25.0,45.0
608.521,0.09514001968503936,900.8852792407572,0.00025370340306410486,25.0,45.0
610.12256,0.0955005157480315,901.6585493038535,0.00025370340306410486,25.0,45.0
611.72412,0.09590753346456693,902.3400427595558,0.00025370340306410486,25.0,45.0
613.32568,0.09629792716535433,902.894091880899,0.00025370340306410486,25.0,45.0
614.92725,0.09662301377952756,900.6775564478282,0.00025370340306410486,25.0,45.0
616.52881,0.09697631692913386,902.7451374041821,0.00025370340306410486,25.0,45.0
618.13037,0.09736876377952755,902.8585545184335,0.00025370340306410486,25.0,45.0
619.73193,0.09776998031496062,903.3468477864109,0.00025370340306410486,25.0,45.0
621.3335,0.09816213188976378,904.6893413985504,0.00025370340306410486,25.0,45.0
622.93506,0.09857292913385826,905.0529279866506,0.00025370340306410486,25.0,45.0
624.53662,0.09895008070866142,903.5898993586068,0.00025370340306410486,25.0,45.0
626.13818,0.09933046062992126,904.3733378526359,0.00025370340306410486,25.0,45.0
627.73975,0.09971536811023621,904.6529957761902,0.00025370340306410486,25.0,45.0
629.34131,0.10006409055118111,904.2981175366324,0.00025370340306410486,25.0,45.0
630.94287,0.1004497716535433,905.4434478802732,0.00025370340306410486,25.0,45.0
632.54443,0.10079160629921259,905.9591698388695,0.00025370340306410486,25.0,45.0
634.146,0.10115546456692913,905.7164050685718,0.00025370340306410486,25.0,45.0
635.74756,0.10152739566929135,906.7163529227721,0.00025370340306410486,25.0,45.0
637.34912,0.10195468307086612,908.2871408458049,0.00025370340306410486,25.0,45.0
638.95068,0.10233473425196851,906.8282578088335,0.00025370340306410486,25.0,45.0
640.55225,0.1026906594488189,907.9375032591125,0.00025370340306410486,25.0,45.0
642.15381,0.10302248622047244,908.7903999582834,0.00025370340306410486,25.0,45.0
643.75537,0.10342583858267718,907.5453146999009,0.00025370340306410486,25.0,45.0
645.35693,0.10380918503937007,909.3311519007144,0.00025370340306410486,25.0,45.0
646.9585,0.10417647047244095,909.246675705272,0.00025370340306410486,25.0,45.0
648.56006,0.10455587401574803,909.1434270219534,0.00025370340306410486,25.0,45.0
650.16162,0.10494127559055118,908.5589508265109,0.00025370340306410486,25.0,45.0
651.76318,0.10531690157480314,911.599859206341,0.00025370340306410486,25.0,45.0
653.36475,0.10574332086614173,911.9008186890545,0.00025370340306410486,25.0,45.0
654.96631,0.10615354921259842,911.6418626479636,0.00025370340306410486,25.0,45.0
656.56787,0.10659652362204723,912.2092350211191,0.00025370340306410486,25.0,45.0
658.16943,0.10699387992125985,912.003937007874,0.00025370340306410486,25.0,45.0
659.771,0.1073556279527559,912.5575950357199,0.00025370340306410486,25.0,45.0
661.37256,0.10766606299212597,910.2032903999583,0.00025370340306410486,25.0,45.0
662.97412,0.108059031496063,911.2841424623247,0.00025370340306410486,25.0,45.0
664.57568,0.10847150196850393,913.4923606403504,0.00025370340306410486,25.0,45.0
666.17725,0.10885254921259842,913.9142723053658,0.00025370340306410486,25.0,45.0
667.77881,0.1092076062992126,915.3081295301663,0.00025370340306410486,25.0,45.0
669.38037,0.10958283464566929,913.470589768994,0.00025370340306410486,25.0,45.0
670.98193,0.10998252559055118,914.9332012306409,0.00025370340306410486,25.0,45.0
672.5835,0.11029313779527558,913.4767690462534,0.00025370340306410486,25.0,45.0
674.18506,0.11062693700787402,914.5610105855974,0.00025370340306410486,25.0,45.0
675.78662,0.1109714940944882,914.7354904312457,0.00025370340306410486,25.0,45.0
677.38818,0.11136840354330708,916.5207279553632,0.00025370340306410486,25.0,45.0
678.98975,0.11182626968503936,916.6250717004745,0.00025370340306410486,25.0,45.0
680.59131,0.11225475393700787,917.8048964905878,0.00025370340306410486,25.0,45.0
682.19287,0.11262148622047244,914.4813839495229,0.00025370340306410486,25.0,45.0
683.79443,0.11298525,916.3830630442718,0.00025370340306410486,25.0,45.0
685.396,0.11338319291338583,917.7121551858999,0.00025370340306410486,25.0,45.0
686.99756,0.1137566496062992,916.4551024664963,0.00025370340306410486,25.0,45.0
688.59912,0.11410593503937007,918.5100641393336,0.00025370340306410486,25.0,45.0
690.20068,0.11452783661417322,919.7801011628513,0.00025370340306410486,25.0,45.0
691.80225,0.11494014173228347,917.9199822704281,0.00025370340306410486,25.0,45.0
693.40381,0.11535142519685039,919.7858372008135,0.00025370340306410486,25.0,45.0
695.00537,0.1157568188976378,918.2753819679824,0.00025370340306410486,25.0,45.0
696.60693,0.11616236614173228,920.4310371799552,0.00025370340306410486,25.0,45.0
698.2085,0.11659380708661417,919.2105125932106,0.00025370340306410486,25.0,45.0
699.81006,0.1169394783464567,918.981357876623,0.00025370340306410486,25.0,45.0
701.41162,0.11727724212598425,919.1544558585806,0.00025370340306410486,25.0,45.0
703.01318,0.11767591338582677,920.1502581217082,0.00025370340306410486,25.0,45.0
704.61475,0.1180274744094488,920.8368357928769,0.00025370340306410486,25.0,45.0
706.21631,0.11843804330708661,920.8393127183606,0.00025370340306410486,25.0,45.0
707.81787,0.1188685216535433,920.4854513218961,0.00025370340306410486,25.0,45.0
709.41943,0.11929153937007873,922.4786202221412,0.00025370340306410486,25.0,45.0
711.021,0.11967350196850395,923.0727694634198,0.00025370340306410486,25.0,45.0
712.62256,0.12006861811023621,922.8232257391668,0.00025370340306410486,25.0,45.0
714.22412,0.12043766141732282,922.3249465505553,0.00025370340306410486,25.0,45.0
715.82568,0.1208447440944882,921.7001095061793,0.00025370340306410486,25.0,45.0
717.42725,0.12117003543307087,921.0404651405329,0.00025370340306410486,25.0,45.0
719.02881,0.12158551968503938,925.2091307295196,0.00025370340306410486,25.0,45.0
720.63037,0.12207139173228346,923.070918287532,0.00025370340306410486,25.0,45.0
722.23193,0.12243898228346456,923.6428534181572,0.00025370340306410486,25.0,45.0
723.8335,0.12288492519685039,925.6337800490171,0.00025370340306410486,25.0,45.0
725.43506,0.12328737401574803,924.9850602283987,0.00025370340306410486,25.0,45.0
727.03662,0.12368665354330709,926.1132085310528,0.00025370340306410486,25.0,45.0
728.63818,0.12411943307086613,926.9120821817802,0.00025370340306410486,25.0,45.0
730.23975,0.12451303543307086,923.773035406998,0.00025370340306410486,25.0,45.0
731.84131,0.12491467519685039,925.1605569171403,0.00025370340306410486,25.0,45.0
733.44287,0.12531092716535433,924.7654742660478,0.00025370340306410486,25.0,45.0
735.04443,0.1257043188976378,925.9793502633363,0.00025370340306410486,25.0,45.0
736.646,0.1261214566929134,927.4047035511289,0.00025370340306410486,25.0,45.0
738.24756,0.12646122637795276,926.3091463732596,0.00025370340306410486,25.0,45.0
739.84912,0.12682533267716534,925.7465714136727,0.00025370340306410486,25.0,45.0
741.45068,0.12717383070866142,925.9328362100433,0.00025370340306410486,25.0,45.0
743.05225,0.12758181692913387,928.838348021067,0.00025370340306410486,25.0,45.0
744.65381,0.12796328740157478,926.1400114720759,0.00025370340306410486,25.0,45.0
746.25537,0.12837195472440943,928.3143348803254,0.00025370340306410486,25.0,45.0
747.85693,0.12879738976377952,928.6715596808677,0.00025370340306410486,25.0,45.0
749.4585,0.12917697047244095,928.8026281483027,0.00025370340306410486,25.0,45.0
751.06006,0.12961309251968503,927.7986129217292,0.00025370340306410486,25.0,45.0
752.66162,0.12995789566929133,928.5809824268655,0.00025370340306410486,25.0,45.0
754.26318,0.13037909448818896,929.8293007248267,0.00025370340306410486,25.0,45.0
755.86475,0.13082249212598424,932.1006413933358,0.00025370340306410486,25.0,45.0
757.46631,0.13127681299212599,930.6515356937999,0.00025370340306410486,25.0,45.0
759.06787,0.13169281299212598,930.962428951348,0.00025370340306410486,25.0,45.0
760.66943,0.13209358464566928,930.0833029149502,0.00025370340306410486,25.0,45.0
762.271,0.132498062992126,930.1758356364395,0.00025370340306410486,25.0,45.0
763.87256,0.1328844842519685,931.6657454242062,0.00025370340306410486,25.0,45.0
765.47412,0.13325803346456694,930.0452364812014,0.00025370340306410486,25.0,45.0
767.07568,0.13370733267716536,933.2566094801065,0.00025370340306410486,25.0,45.0
768.67725,0.13415917913385825,930.7522292329353,0.00025370340306410486,25.0,45.0
770.27881,0.13459570078740157,932.1248891901758,0.00025370340306410486,25.0,45.0
771.88037,0.13501315551181103,931.6070553266935,0.00025370340306410486,25.0,45.0
773.48193,0.13543092913385826,933.1770871356312,0.00025370340306410486,25.0,45.0
775.0835,0.1358752874015748,932.1776607394274,0.00025370340306410486,25.0,45.0
776.68506,0.13636499606299213,932.7616936955728,0.00025370340306410486,25.0,45.0
778.28662,0.136760968503937,932.7638577462586,0.00025370340306410486,25.0,45.0
779.88818,0.13716764173228346,932.4101788600929,0.00025370340306410486,25.0,45.0
781.48975,0.13751929724409448,931.8521927308756,0.00025370340306410486,25.0,45.0
783.09131,0.13794074212598426,933.663789956719,0.00025370340306410486,25.0,45.0
784.69287,0.1383645570866142,933.8975335036763,0.00025370340306410486,25.0,45.0
786.29443,0.1388249311023622,935.9444125775669,0.00025370340306410486,25.0,45.0
787.896,0.13923677952755906,934.1435052406529,0.00025370340306410486,25.0,45.0
789.49756,0.13965172244094487,935.4216248631174,0.00025370340306410486,25.0,45.0
791.09912,0.1400166968503937,934.9489753350367,0.00025370340306410486,25.0,45.0
792.70068,0.14040365748031494,935.3042968138916,0.00025370340306410486,25.0,45.0
794.30225,0.1408752027559055,935.3399384679564,0.00025370340306410486,25.0,45.0
795.90381,0.1413424192913386,935.4891536736716,0.00025370340306410486,25.0,45.0
797.50537,0.14182366732283466,935.691062209939,0.00025370340306410486,25.0,45.0
799.10693,0.14222915551181103,935.2910517807791,0.00025370340306410486,25.0,45.0
800.7085,0.1426547874015748,938.0703446837357,0.00025370340306410486,25.0,45.0
802.31006,0.1430709527559055,936.8252594253534,0.00025370340306410486,25.0,45.0
803.91162,0.14350782677165355,939.3381394378683,0.00025370340306410486,25.0,45.0
805.51318,0.14394120472440944,935.2808833498462,0.00025370340306410486,25.0,45.0
807.11475,0.14435303937007873,938.442587474579,0.00025370340306410486,25.0,45.0
808.71631,0.14478767322834646,937.3749804453251,0.00025370340306410486,25.0,45.0
810.31787,0.1452149842519685,937.7735829378944,0.00025370340306410486,25.0,45.0
811.91943,0.1456053937007874,937.3480471398029,0.00025370340306410486,25.0,45.0
813.521,0.14602288582677164,939.27577306148,0.00025370340306410486,25.0,45.0
815.12256,0.1464418070866142,938.845153047922,0.00025370340306410486,25.0,45.0
816.72412,0.1468302460629921,937.6993533920843,0.00025370340306410486,25.0,45.0
818.32568,0.1472280964566929,937.9842780414037,0.00025370340306410486,25.0,45.0
819.92725,0.14763183464566929,937.5500860405695,0.00025370340306410486,25.0,45.0
821.52881,0.14810605511811023,938.2811701517443,0.00025370340306410486,25.0,45.0
823.13037,0.14855846456692914,940.3653334723888,0.00025370340306410486,25.0,45.0
824.73193,0.14903438582677164,939.2597382280858,0.00025370340306410486,25.0,45.0
826.3335,0.14947467519685037,940.1944256140167,0.00025370340306410486,25.0,45.0
827.93506,0.1499176377952756,940.0039109349742,0.00025370340306410486,25.0,45.0
829.53662,0.1503849940944882,941.8232778849663,0.00025370340306410486,25.0,45.0
831.13818,0.15086485826771653,942.0517547061585,0.00025370340306410486,25.0,45.0
832.73975,0.15136435236220472,941.651353183501,0.00025370340306410486,25.0,45.0
834.34131,0.15186572440944882,940.477890180946,0.00025370340306410486,25.0,45.0
835.94287,0.1522896437007874,941.0980080304531,0.00025370340306410486,25.0,45.0
837.54443,0.15268052362204723,942.0448714606039,0.00025370340306410486,25.0,45.0
839.146,0.15305795866141733,941.0465661990927,0.00025370340306410486,25.0,45.0
840.74756,0.1535165374015748,943.0186681962767,0.00025370340306410486,25.0,45.0
842.34912,0.1539706594488189,942.5725608802211,0.00025370340306410486,25.0,45.0
843.95068,0.15449000590551182,943.6466079157325,0.00025370340306410486,25.0,45.0
845.55225,0.15499191732283463,942.9986702821087,0.00025370340306410486,25.0,45.0
847.15381,0.15544686023622048,942.6397246701779,0.00025370340306410486,25.0,45.0
848.75537,0.15588834448818897,941.1446785211451,0.00025370340306410486,25.0,45.0
850.35693,0.15628093897637796,942.2784064243625,0.00025370340306410486,25.0,45.0
851.9585,0.15670515157480314,943.0991813109455,0.00025370340306410486,25.0,45.0
853.56006,0.15720512598425196,944.2512645356417,0.00025370340306410486,25.0,45.0
855.16162,0.15760481889763778,942.6091150857799,0.00025370340306410486,25.0,45.0
856.76318,0.1580146003937008,944.3410074568493,0.00025370340306410486,25.0,45.0
858.36475,0.15849816141732284,943.8443187151275,0.00025370340306410486,25.0,45.0
859.96631,0.15898433661417322,942.5109506179277,0.00025370340306410486,25.0,45.0
861.56787,0.15945928543307086,943.0101945038327,0.00025370340306410486,25.0,45.0
863.16943,0.1599266653543307,944.5128278667154,0.00025370340306410486,25.0,45.0
864.771,0.16036277755905512,943.996062992126,0.00025370340306410486,25.0,45.0
866.37256,0.1608330905511811,943.7586431662929,0.00025370340306410486,25.0,45.0
867.97412,0.16132792716535432,944.5633571465819,0.00025370340306410486,25.0,45.0
869.57568,0.16179974212598425,946.0227616415498,0.00025370340306410486,25.0,45.0
871.17725,0.16228541338582678,945.4140376492675,0.00025370340306410486,25.0,45.0
872.77881,0.16277702362204724,946.138629608385,0.00025370340306410486,25.0,45.0
874.38037,0.16328555118110236,944.4139072847682,0.00025370340306410486,25.0,45.0
875.98193,0.16375809448818898,947.6079678781874,0.00025370340306410486,25.0,45.0
877.5835,0.16421240354330707,945.4451165458622,0.00025370340306410486,25.0,45.0
879.18506,0.1646884192913386,945.2228972206289,0.00025370340306410486,25.0,45.0
880.78662,0.16509603149606297,944.7783282056631,0.00025370340306410486,25.0,45.0
882.38818,0.16558343897637795,945.4995828336027,0.00025370340306410486,25.0,45.0
883.98975,0.16608306299212597,947.7308233821766,0.00025370340306410486,25.0,45.0
885.59131,0.1664502874015748,944.8448401731241,0.00025370340306410486,25.0,45.0
887.19287,0.16688617716535434,946.6885331386557,0.00025370340306410486,25.0,45.0
888.79443,0.16734540157480315,947.0649736663712,0.00025370340306410486,25.0,45.0
890.396,0.1678338208661417,945.2503780570476,0.00025370340306410486,25.0,45.0
891.99756,0.16830564763779526,945.3184283255985,0.00025370340306410486,25.0,45.0
893.59912,0.168736937007874,947.732283464567,0.00025370340306410486,25.0,45.0
895.20068,0.1692252716535433,945.1388642644835,0.00025370340306410486,25.0,45.0
896.80225,0.16971014566929135,947.5236220472441,0.00025370340306410486,25.0,45.0
898.40381,0.1702610787401575,946.7066016582365,0.00025370340306410486,25.0,45.0
900.00537,0.17076364566929134,948.0632267820828,0.00025370340306410486,25.0,45.0
901.60693,0.17131245472440945,947.5493299264745,0.00025370340306410486,25.0,45.0
903.2085,0.17185652362204726,947.8106325285498,0.00025370340306410486,25.0,45.0
904.81006,0.1723855492125984,946.678025760025,0.00025370340306410486,25.0,45.0
906.41162,0.17285345866141733,947.977733743547,0.00025370340306410486,25.0,45.0
908.01318,0.17337360236220473,947.265761067946,0.00025370340306410486,25.0,45.0
909.61475,0.17382807677165354,946.6809459248058,0.00025370340306410486,25.0,45.0
911.21631,0.1743296594488189,948.0031287479793,0.00025370340306410486,25.0,45.0
912.81787,0.1748523248031496,949.7806747666475,0.00025370340306410486,25.0,45.0
914.41943,0.17540479527559055,950.2624758825676,0.00025370340306410486,25.0,45.0
916.021,0.17591472047244094,948.826823799343,0.00025370340306410486,25.0,45.0
917.62256,0.17643688188976378,947.224383375919,0.00025370340306410486,25.0,45.0
919.22412,0.17689317519685038,948.3365489909788,0.00025370340306410486,25.0,45.0
920.82568,0.17731097047244093,948.5542577045419,0.00025370340306410486,25.0,45.0
922.42725,0.17773343503937009,949.0878656724201,0.00025370340306410486,25.0,45.0
924.02881,0.17827918307086613,948.952416957814,0.00025370340306410486,25.0,45.0
925.63037,0.17873433661417323,946.6436616780518,0.00025370340306410486,25.0,45.0
927.23193,0.17926822047244095,949.7324920477655,0.00025370340306410486,25.0,45.0
928.8335,0.17987784251968503,950.894691557595,0.00025370340306410486,25.0,45.0
930.43506,0.1804099783464567,949.0465401261929,0.00025370340306410486,25.0,45.0
932.03662,0.18089492322834644,949.9022005527455,0.00025370340306410486,25.0,45.0
933.63818,0.18145051377952756,949.5964697293633,0.00025370340306410486,25.0,45.0
935.23975,0.18192596653543308,950.3140480784273,0.00025370340306410486,25.0,45.0
936.84131,0.1823808622047244,950.7006831099754,0.00025370340306410486,25.0,45.0
938.44287,0.18292894291338582,951.5928716691872,0.00025370340306410486,25.0,45.0
940.04443,0.18353388385826772,951.3829326797727,0.00025370340306410486,25.0,45.0
941.646,0.1841466377952756,951.2671950774366,0.00025370340306410486,25.0,45.0
943.24756,0.18468156496062993,948.9154977316578,0.00025370340306410486,25.0,45.0
944.84912,0.18512336811023622,949.7931636856651,0.00025370340306410486,25.0,45.0
946.45068,0.18561943503937006,951.4422485268811,0.00025370340306410486,25.0,45.0
948.05225,0.18615803543307088,951.8174897012046,0.00025370340306410486,25.0,45.0
949.65381,0.18680105118110235,952.3904416749231,0.00025370340306410486,25.0,45.0
951.25537,0.18725432677165355,948.9806017625281,0.00025370340306410486,25.0,45.0
952.85693,0.18777469488188975,950.6507013610054,0.00025370340306410486,25.0,45.0
954.4585,0.18834350787401574,952.9725191635814,0.00025370340306410486,25.0,45.0
956.06006,0.1889374783464567,950.2109819054075,0.00025370340306410486,25.0,45.0
957.66162,0.18946807677165353,951.9089012880013,0.00025370340306410486,25.0,45.0
959.26318,0.19000333267716535,952.568936747145,0.00025370340306410486,25.0,45.0
960.86475,0.1905076968503937,950.03485946707,0.00025370340306410486,25.0,45.0
962.46631,0.1910472125984252,951.5427595557178,0.00025370340306410486,25.0,45.0
964.06787,0.1916384251968504,949.9585180163738,0.00025370340306410486,25.0,45.0
965.66943,0.19218495669291338,952.7813005162434,0.00025370340306410486,25.0,45.0
967.271,0.1927399842519685,952.0708400688326,0.00025370340306410486,25.0,45.0
968.87256,0.19331103937007874,952.7404182093134,0.00025370340306410486,25.0,45.0
970.47412,0.19393849606299213,953.4336183970381,0.00025370340306410486,25.0,45.0
972.07568,0.1945554153543307,950.7051937216457,0.00025370340306410486,25.0,45.0
973.67725,0.19512209448818896,951.5723522970226,0.00025370340306410486,25.0,45.0
975.27881,0.19571958267716535,952.1961724983053,0.00025370340306410486,25.0,45.0
976.88037,0.19626566929133857,951.9630025551442,0.00025370340306410486,25.0,45.0
978.48193,0.19680594881889765,952.7971528393389,0.00025370340306410486,25.0,45.0
980.0835,0.19733076771653543,950.2652135370496,0.00025370340306410486,25.0,45.0
981.68506,0.197885,953.5307660217969,0.00025370340306410486,25.0,45.0
983.28662,0.19841694881889763,952.9216509360172,0.00025370340306410486,25.0,45.0
984.88818,0.19898433070866142,951.4274130468791,0.00025370340306410486,25.0,45.0
986.48975,0.19949405511811022,952.9910309224592,0.00025370340306410486,25.0,45.0
988.09131,0.20013336614173227,953.1361526829014,0.00025370340306410486,25.0,45.0
989.69287,0.2007777559055118,950.944099702769,0.00025370340306410486,25.0,45.0
991.29443,0.2013415748031496,953.0609845126976,0.00025370340306410486,25.0,45.0
992.896,0.20194543307086613,950.9414141940866,0.00025370340306410486,25.0,45.0
994.49756,0.20249478346456692,952.697710799395,0.00025370340306410486,25.0,45.0
996.09912,0.20307994094488185,952.8912760077176,0.00025370340306410486,25.0,45.0
997.70068,0.20370267716535434,952.5241174323409,0.00025370340306410486,25.0,45.0
999.30225,0.2042895275590551,951.4511654586223,0.00025370340306410486,25.0,45.0
1000.9038,0.20484053149606302,953.6815456015019,0.00025370340306410486,25.0,45.0
1002.5054,0.20548246062992126,951.5359545288628,0.00025370340306410486,25.0,45.0
1004.1069,0.20616124015748033,952.5334254575794,0.00025370340306410486,25.0,45.0
1005.7085,0.20676734251968507,953.2203681493456,0.00025370340306410486,25.0,45.0
1007.3101,0.20737938976377954,953.237133023935,0.00025370340306410486,25.0,45.0
1008.9116,0.2080375,953.5809824268656,0.00025370340306410486,25.0,45.0
1010.5132,0.20869456692913385,952.2450591854825,0.00025370340306410486,25.0,45.0
1012.1147,0.20933167322834648,951.2531417844292,0.00025370340306410486,25.0,45.0
1013.5161,0.2099217913385827,956.3520623663763,0.00025370340306410486,25.0,45.0