File: datasets/am_bench_2022/csv/45-XY.08-3.csv
Time(s),Strain(%),Stress(MPa),SR(s-1),Temp(C),Angle(deg)
35.469727,8.696893503937008e-06,11.053044891640868,0.00025370340306410486,25.0,45.0
37.071289,3.641747047244095e-05,16.436486326109392,0.00025370340306410486,25.0,45.0
38.672852,4.861876771653543e-05,20.3309584623323,0.00025370340306410486,25.0,45.0
40.274414,5.5158135826771654e-05,25.88938080495356,0.00025370340306410486,25.0,45.0
41.875977,8.406934251968504e-05,31.140526315789476,0.00025370340306410486,25.0,45.0
43.477539,7.661602755905512e-05,34.944460784313726,0.00025370340306410486,25.0,45.0
45.079102,9.299097244094488e-05,41.04817337461301,0.00025370340306410486,25.0,45.0
46.680664,0.00012614257874015748,48.75547729618163,0.00025370340306410486,25.0,45.0
48.282227,0.00014860918897637794,57.11486326109391,0.00025370340306410486,25.0,45.0
49.883789,0.00014291116338582677,64.36072239422086,0.00025370340306410486,25.0,45.0
51.485352,0.00015523507677165353,71.08448658410732,0.00025370340306410486,25.0,45.0
53.086914,0.00018492712598425196,81.10126676986583,0.00025370340306410486,25.0,45.0
54.688477,0.00019603377755905515,90.80126676986585,0.00025370340306410486,25.0,45.0
56.290039,0.00020970561023622047,99.89526057791538,0.00025370340306410486,25.0,45.0
57.891602,0.00024848608267716537,109.298044375645,0.00025370340306410486,25.0,45.0
59.493164,0.00024941452755905514,118.17477038183695,0.00025370340306410486,25.0,45.0
61.094727,0.0002732323031496063,127.5297471620227,0.00025370340306410486,25.0,45.0
62.696289,0.0002852288976377953,135.73760577915377,0.00025370340306410486,25.0,45.0
64.297852,0.00028921059055118107,146.06267285861713,0.00025370340306410486,25.0,45.0
65.899414,0.0003056395669291338,156.77270381836945,0.00025370340306410486,25.0,45.0
67.500977,0.00035081903543307086,166.8273632610939,0.00025370340306410486,25.0,45.0
69.102539,0.0003526896653543307,176.00820949432403,0.00025370340306410486,25.0,45.0
70.704102,0.000384434468503937,188.66316305469556,0.00025370340306410486,25.0,45.0
72.305664,0.0003873714763779528,198.38014705882355,0.00025370340306410486,25.0,45.0
73.907227,0.0004309755708661417,210.43814757481942,0.00025370340306410486,25.0,45.0
75.508789,0.00043507903543307087,220.919455624355,0.00025370340306410486,25.0,45.0
77.110352,0.00048251633858267714,234.97110165118679,0.00025370340306410486,25.0,45.0
78.711914,0.000490061811023622,243.83670794633645,0.00025370340306410486,25.0,45.0
80.313477,0.0004894495669291338,254.2037874097007,0.00025370340306410486,25.0,45.0
81.915039,0.0005279758858267717,266.27985036119713,0.00025370340306410486,25.0,45.0
83.516602,0.0005669039763779528,279.216511867905,0.00025370340306410486,25.0,45.0
85.118164,0.0005905112204724409,291.46950464396286,0.00025370340306410486,25.0,45.0
86.719727,0.0006221731102362205,304.3550825593395,0.00025370340306410486,25.0,45.0
88.321289,0.0006505218897637795,317.5916924664603,0.00025370340306410486,25.0,45.0
89.922852,0.0006605913582677166,326.50686274509803,0.00025370340306410486,25.0,45.0
91.524414,0.0007087385433070866,340.3802373581011,0.00025370340306410486,25.0,45.0
93.125977,0.0007152668307086614,350.90515995872033,0.00025370340306410486,25.0,45.0
94.727539,0.0007600599212598425,363.3509545923633,0.00025370340306410486,25.0,45.0
96.329102,0.0007886143503937007,375.1371259029928,0.00025370340306410486,25.0,45.0
97.930664,0.0008061903937007875,385.4094427244582,0.00025370340306410486,25.0,45.0
99.532227,0.000819152559055118,397.55815273477816,0.00025370340306410486,25.0,45.0
101.13379,0.0008598744488188977,409.35921052631585,0.00025370340306410486,25.0,45.0
102.73535,0.000863734311023622,420.3103715170279,0.00025370340306410486,25.0,45.0
104.33691,0.0008904116732283465,431.36767285861714,0.00025370340306410486,25.0,45.0
105.93848,0.0009108352165354332,440.6067079463364,0.00025370340306410486,25.0,45.0
107.54004,0.0009521566929133857,454.72063983488135,0.00025370340306410486,25.0,45.0
109.1416,0.0009733134842519686,464.74579463364296,0.00025370340306410486,25.0,45.0
110.74316,0.00102378218503937,473.8480392156863,0.00025370340306410486,25.0,45.0
112.34473,0.0010488994881889765,484.0029669762642,0.00025370340306410486,25.0,45.0
113.94629,0.0010756254133858268,495.75954592363263,0.00025370340306410486,25.0,45.0
115.54785,0.0011154382677165354,507.04334365325076,0.00025370340306410486,25.0,45.0
117.14941,0.0011449157283464568,515.9703302373581,0.00025370340306410486,25.0,45.0
118.75098,0.0011813132874015748,523.6874097007225,0.00025370340306410486,25.0,45.0
120.35254,0.00121973218503937,533.1635706914344,0.00025370340306410486,25.0,45.0
121.9541,0.0012388588582677167,541.8488390092879,0.00025370340306410486,25.0,45.0
123.55566,0.0012678360039370079,550.0167698658411,0.00025370340306410486,25.0,45.0
125.15723,0.001312710531496063,557.9420794633644,0.00025370340306410486,25.0,45.0
126.75879,0.0013245996653543307,564.7506707946336,0.00025370340306410486,25.0,45.0
128.36035,0.0013663566338582677,571.7797471620228,0.00025370340306410486,25.0,45.0
129.96191,0.0013703899212598424,577.7732198142415,0.00025370340306410486,25.0,45.0
131.56348,0.001402175255905512,584.4879514963881,0.00025370340306410486,25.0,45.0
133.16504,0.0014198342716535432,592.1989938080495,0.00025370340306410486,25.0,45.0
134.7666,0.0014439466338582677,597.6357069143447,0.00025370340306410486,25.0,45.0
136.36816,0.0014950977755905511,606.0417440660475,0.00025370340306410486,25.0,45.0
137.96973,0.0015132779921259842,610.34262125903,0.00025370340306410486,25.0,45.0
139.57129,0.0015306031692913385,615.0811919504645,0.00025370340306410486,25.0,45.0
141.17285,0.001556186122047244,621.5842879256966,0.00025370340306410486,25.0,45.0
142.77441,0.0015863167913385827,626.9972910216719,0.00025370340306410486,25.0,45.0
144.37598,0.0016126878937007874,630.9714912280702,0.00025370340306410486,25.0,45.0
145.97754,0.0016446300590551182,637.6999226006193,0.00025370340306410486,25.0,45.0
147.5791,0.0016659274606299211,641.8751805985552,0.00025370340306410486,25.0,45.0
149.18066,0.0016925757480314959,645.2672600619195,0.00025370340306410486,25.0,45.0
150.78223,0.0017203493307086616,649.593008255934,0.00025370340306410486,25.0,45.0
152.38379,0.0017721202362204723,654.36955624355,0.00025370340306410486,25.0,45.0
153.98535,0.001789609842519685,659.8171310629515,0.00025370340306410486,25.0,45.0
155.58691,0.0018215789566929134,661.6081785345718,0.00025370340306410486,25.0,45.0
157.18848,0.0018552515748031498,667.2198916408669,0.00025370340306410486,25.0,45.0
158.79004,0.001894300590551181,670.1273477812177,0.00025370340306410486,25.0,45.0
160.3916,0.0019222285236220472,671.9100103199174,0.00025370340306410486,25.0,45.0
161.99316,0.0019647903346456694,678.2187564499484,0.00025370340306410486,25.0,45.0
163.59473,0.0019905765748031495,680.1845459236326,0.00025370340306410486,25.0,45.0
165.19629,0.0020207484251968505,682.2322755417957,0.00025370340306410486,25.0,45.0
166.79785,0.00209591594488189,687.6091589267286,0.00025370340306410486,25.0,45.0
168.39941,0.002110521062992126,690.6653250773993,0.00025370340306410486,25.0,45.0
170.00098,0.002203059842519685,694.9459752321982,0.00025370340306410486,25.0,45.0
171.60254,0.002244072440944882,697.0966976264191,0.00025370340306410486,25.0,45.0
173.2041,0.002284758661417323,698.1608617131063,0.00025370340306410486,25.0,45.0
174.80566,0.0023493043307086614,702.2756707946337,0.00025370340306410486,25.0,45.0
176.40723,0.0024336377952755904,705.9025799793601,0.00025370340306410486,25.0,45.0
178.00879,0.002502276181102362,708.4453818369453,0.00025370340306410486,25.0,45.0
179.61035,0.002612643503937008,711.220072239422,0.00025370340306410486,25.0,45.0
181.21191,0.002686028937007874,714.3016253869969,0.00025370340306410486,25.0,45.0
182.81348,0.0028036472440944884,718.3998452012385,0.00025370340306410486,25.0,45.0
184.41504,0.00289909468503937,720.8274509803922,0.00025370340306410486,25.0,45.0
186.0166,0.003013996062992126,722.17979876161,0.00025370340306410486,25.0,45.0
187.61816,0.0031348208661417325,726.9222910216719,0.00025370340306410486,25.0,45.0
189.21973,0.0032754064960629926,727.3382610939113,0.00025370340306410486,25.0,45.0
190.82129,0.003408789763779527,728.8283539731683,0.00025370340306410486,25.0,45.0
192.42285,0.0035715864173228346,733.4849845201238,0.00025370340306410486,25.0,45.0
194.02441,0.0037349078740157478,735.3844427244583,0.00025370340306410486,25.0,45.0
195.62598,0.0039031352362204723,734.7975232198144,0.00025370340306410486,25.0,45.0
197.22754,0.00410099468503937,739.5844169246645,0.00025370340306410486,25.0,45.0
198.8291,0.004304469094488189,740.4157894736842,0.00025370340306410486,25.0,45.0
200.43066,0.004520037401574803,741.9579721362229,0.00025370340306410486,25.0,45.0
202.03223,0.004685495275590551,742.2237874097007,0.00025370340306410486,25.0,45.0
203.63379,0.004926758070866142,746.4458462332301,0.00025370340306410486,25.0,45.0
205.23535,0.005159175787401575,746.9095717234262,0.00025370340306410486,25.0,45.0
206.83691,0.005357269291338582,746.4901960784315,0.00025370340306410486,25.0,45.0
208.43848,0.005587538385826772,749.5566821465428,0.00025370340306410486,25.0,45.0
210.04004,0.005837141141732284,751.2344427244583,0.00025370340306410486,25.0,45.0
211.6416,0.006090802755905512,751.9770639834882,0.00025370340306410486,25.0,45.0
213.24316,0.00634042657480315,754.4730650154798,0.00025370340306410486,25.0,45.0
214.84473,0.0066466688976377945,756.6120743034056,0.00025370340306410486,25.0,45.0
216.44629,0.006938180118110236,755.6853457172343,0.00025370340306410486,25.0,45.0
218.04785,0.007220604133858268,756.7615583075336,0.00025370340306410486,25.0,45.0
219.64941,0.0075079992125984246,757.2793085655314,0.00025370340306410486,25.0,45.0
221.25098,0.007813780905511812,759.3982198142414,0.00025370340306410486,25.0,45.0
222.85254,0.008134784448818898,761.2346233230135,0.00025370340306410486,25.0,45.0
224.4541,0.008483419488188976,763.0433178534571,0.00025370340306410486,25.0,45.0
226.05566,0.00882783503937008,763.8263157894737,0.00025370340306410486,25.0,45.0
227.65723,0.00910488090551181,765.8164860681115,0.00025370340306410486,25.0,45.0
229.25879,0.009428565354330709,765.1274509803922,0.00025370340306410486,25.0,45.0
230.86035,0.009747649606299213,765.9626676986584,0.00025370340306410486,25.0,45.0
232.46191,0.010034081102362204,765.1723684210527,0.00025370340306410486,25.0,45.0
234.06348,0.01038415059055118,767.0714396284831,0.00025370340306410486,25.0,45.0
235.66504,0.01071358149606299,769.7276573787409,0.00025370340306410486,25.0,45.0
237.2666,0.010991845866141731,768.9874871001032,0.00025370340306410486,25.0,45.0
238.86816,0.01127645157480315,767.5761609907121,0.00025370340306410486,25.0,45.0
240.46973,0.011626150787401575,770.7214654282766,0.00025370340306410486,25.0,45.0
242.07129,0.011990065354330708,773.1498452012383,0.00025370340306410486,25.0,45.0
243.67285,0.01233765098425197,773.8919504643962,0.00025370340306410486,25.0,45.0
245.27441,0.01270458346456693,774.624871001032,0.00025370340306410486,25.0,45.0
246.87598,0.013033885826771653,774.8688338493292,0.00025370340306410486,25.0,45.0
248.47754,0.013401220078740159,776.9329463364294,0.00025370340306410486,25.0,45.0
250.0791,0.013750225393700789,776.8462848297214,0.00025370340306410486,25.0,45.0
251.68066,0.014066877952755904,777.3339783281734,0.00025370340306410486,25.0,45.0
253.28223,0.014412507283464566,778.0039215686274,0.00025370340306410486,25.0,45.0
254.88379,0.014812895275590552,779.5855521155831,0.00025370340306410486,25.0,45.0
256.48535,0.015195773031496062,780.5781217750258,0.00025370340306410486,25.0,45.0
258.08691,0.015584859055118111,780.3938596491228,0.00025370340306410486,25.0,45.0
259.68848,0.015946877952755904,781.9271155830753,0.00025370340306410486,25.0,45.0
261.29004,0.016261921653543305,780.7944014447885,0.00025370340306410486,25.0,45.0
262.8916,0.01663009035433071,784.2668730650155,0.00025370340306410486,25.0,45.0
264.49316,0.017053123622047243,785.0514963880289,0.00025370340306410486,25.0,45.0
266.09473,0.01741828700787402,784.6921568627452,0.00025370340306410486,25.0,45.0
267.69629,0.017748663188976378,786.0809081527348,0.00025370340306410486,25.0,45.0
269.29785,0.018102721062992124,786.1714912280702,0.00025370340306410486,25.0,45.0
270.89941,0.018510242913385825,785.6948658410734,0.00025370340306410486,25.0,45.0
272.50098,0.01877982342519685,786.0580495356037,0.00025370340306410486,25.0,45.0
274.10254,0.019159204724409448,787.5639060887513,0.00025370340306410486,25.0,45.0
275.7041,0.01953041811023622,789.4499484004128,0.00025370340306410486,25.0,45.0
277.30566,0.019871535433070867,789.6419762641899,0.00025370340306410486,25.0,45.0
278.90723,0.020214958661417322,789.7125902992776,0.00025370340306410486,25.0,45.0
280.50879,0.02061368307086614,792.1246388028895,0.00025370340306410486,25.0,45.0
282.11035,0.020944818897637794,791.1979102167184,0.00025370340306410486,25.0,45.0
283.71191,0.021334925196850395,792.7525799793601,0.00025370340306410486,25.0,45.0
285.31348,0.02181232086614173,793.4616873065015,0.00025370340306410486,25.0,45.0
286.91504,0.022188688976377952,791.9899122807018,0.00025370340306410486,25.0,45.0
288.5166,0.02252572440944882,791.059391124871,0.00025370340306410486,25.0,45.0
290.11816,0.02288174212598425,794.9012899896801,0.00025370340306410486,25.0,45.0
291.71973,0.02324346653543307,795.4713880288958,0.00025370340306410486,25.0,45.0
293.32129,0.023580023622047242,795.9470588235295,0.00025370340306410486,25.0,45.0
294.92285,0.0239490157480315,796.5627708978328,0.00025370340306410486,25.0,45.0
296.52441,0.024304456692913385,797.271568627451,0.00025370340306410486,25.0,45.0
298.12598,0.02467850590551181,798.0389576883385,0.00025370340306410486,25.0,45.0
299.72754,0.025045942913385827,799.253302373581,0.00025370340306410486,25.0,45.0
301.3291,0.025446753937007873,799.1758255933953,0.00025370340306410486,25.0,45.0
302.93066,0.02579479527559055,800.1276315789473,0.00025370340306410486,25.0,45.0
304.53223,0.026162391732283463,801.2061145510836,0.00025370340306410486,25.0,45.0
306.13379,0.026554779527559056,802.5042827657379,0.00025370340306410486,25.0,45.0
307.73535,0.026943655511811024,800.8319659442725,0.00025370340306410486,25.0,45.0
309.33691,0.02734791929133858,801.6415892672859,0.00025370340306410486,25.0,45.0
310.93848,0.027690114173228343,800.8775025799794,0.00025370340306410486,25.0,45.0
312.54004,0.02796671653543307,802.2718524251807,0.00025370340306410486,25.0,45.0
314.1416,0.02833980905511811,803.8421310629516,0.00025370340306410486,25.0,45.0
315.74316,0.02870346456692913,806.0160990712075,0.00025370340306410486,25.0,45.0
317.34473,0.02907610433070866,805.1745872033024,0.00025370340306410486,25.0,45.0
318.94629,0.029464482283464568,806.0375902992777,0.00025370340306410486,25.0,45.0
320.54785,0.029842901574803148,806.9059855521156,0.00025370340306410486,25.0,45.0
322.14941,0.03024876377952756,808.4373581011353,0.00025370340306410486,25.0,45.0
323.75098,0.03064116338582677,807.3226006191951,0.00025370340306410486,25.0,45.0
325.35254,0.031014484251968504,808.6860165118679,0.00025370340306410486,25.0,45.0
326.9541,0.031394232283464565,808.5933178534572,0.00025370340306410486,25.0,45.0
328.55566,0.03175777952755906,809.0020897832818,0.00025370340306410486,25.0,45.0
330.15723,0.03211455118110236,808.6491744066047,0.00025370340306410486,25.0,45.0
331.75879,0.03250266141732284,810.433617131063,0.00025370340306410486,25.0,45.0
333.36035,0.032866531496062994,810.4628998968009,0.00025370340306410486,25.0,45.0
334.96191,0.033247145669291336,811.415866873065,0.00025370340306410486,25.0,45.0
336.56348,0.03361935826771654,813.7996904024768,0.00025370340306410486,25.0,45.0
338.16504,0.0340320374015748,811.3664086687307,0.00025370340306410486,25.0,45.0
339.7666,0.03439158070866141,813.0187564499483,0.00025370340306410486,25.0,45.0
341.36816,0.03478562795275591,814.1614809081527,0.00025370340306410486,25.0,45.0
342.96973,0.03510173228346457,813.4237874097007,0.00025370340306410486,25.0,45.0
344.57129,0.03549279724409449,816.0165376676987,0.00025370340306410486,25.0,45.0
346.17285,0.035833582677165354,816.7768575851393,0.00025370340306410486,25.0,45.0
347.77441,0.036191061023622045,816.6960526315789,0.00025370340306410486,25.0,45.0
349.37598,0.03658737204724409,815.4175180598556,0.00025370340306410486,25.0,45.0
350.97754,0.03695232283464567,818.26955624355,0.00025370340306410486,25.0,45.0
352.5791,0.03734667519685039,818.2250773993808,0.00025370340306410486,25.0,45.0
354.18066,0.03772461811023622,818.140737874097,0.00025370340306410486,25.0,45.0
355.78223,0.03809570472440945,817.8348813209494,0.00025370340306410486,25.0,45.0
357.38379,0.03843113385826772,818.9107585139319,0.00025370340306410486,25.0,45.0
358.98535,0.03880873031496063,820.227657378741,0.00025370340306410486,25.0,45.0
360.58691,0.03919664173228346,820.1834365325077,0.00025370340306410486,25.0,45.0
362.18848,0.039607163385826774,821.8669762641899,0.00025370340306410486,25.0,45.0
363.79004,0.03996774803149606,820.4556759545924,0.00025370340306410486,25.0,45.0
365.3916,0.040326931102362205,824.3951238390093,0.00025370340306410486,25.0,45.0
366.99316,0.04077976377952756,823.1177760577916,0.00025370340306410486,25.0,45.0
368.59473,0.04117302362204724,822.7450206398348,0.00025370340306410486,25.0,45.0
370.19629,0.04151987992125984,824.1265479876162,0.00025370340306410486,25.0,45.0
371.79785,0.04185788385826771,825.01346749226,0.00025370340306410486,25.0,45.0
373.39941,0.04224698228346457,825.6062951496389,0.00025370340306410486,25.0,45.0
375.00098,0.04258869881889764,824.6444272445821,0.00025370340306410486,25.0,45.0
376.60254,0.04294884251968504,825.8527089783281,0.00025370340306410486,25.0,45.0
378.2041,0.04332884251968504,826.0925696594428,0.00025370340306410486,25.0,45.0
379.80566,0.04374407086614173,827.7160216718266,0.00025370340306410486,25.0,45.0
381.40723,0.04408909842519685,825.7764963880289,0.00025370340306410486,25.0,45.0
383.00879,0.04446785236220473,829.324226006192,0.00025370340306410486,25.0,45.0
384.61035,0.0448651062992126,828.5475748194015,0.00025370340306410486,25.0,45.0
386.21191,0.045231791338582676,826.6311919504644,0.00025370340306410486,25.0,45.0
387.81348,0.04558712598425197,828.7504127966977,0.00025370340306410486,25.0,45.0
389.41504,0.045969346456692914,830.8633384932921,0.00025370340306410486,25.0,45.0
391.0166,0.04633438582677166,831.2552373581011,0.00025370340306410486,25.0,45.0
392.61816,0.04673007677165354,831.0092105263158,0.00025370340306410486,25.0,45.0
394.21973,0.04712123818897638,831.5731424148606,0.00025370340306410486,25.0,45.0
395.82129,0.047509956692913385,833.5526573787411,0.00025370340306410486,25.0,45.0
397.42285,0.047901704724409445,832.6833591331269,0.00025370340306410486,25.0,45.0
399.02441,0.048293192913385824,833.3537409700723,0.00025370340306410486,25.0,45.0
400.62598,0.04866476968503937,833.8408152734779,0.00025370340306410486,25.0,45.0
402.22754,0.04903986220472441,835.7481682146542,0.00025370340306410486,25.0,45.0
403.8291,0.04939919094488189,834.7179824561404,0.00025370340306410486,25.0,45.0
405.43066,0.04978854527559055,835.6231166150671,0.00025370340306410486,25.0,45.0
407.03223,0.05014246653543307,835.2160990712074,0.00025370340306410486,25.0,45.0
408.63379,0.050507246062992124,836.9641898864809,0.00025370340306410486,25.0,45.0
410.23535,0.050899368110236216,836.4778121775026,0.00025370340306410486,25.0,45.0
411.83691,0.05123582480314961,835.9289989680084,0.00025370340306410486,25.0,45.0
413.43848,0.051607907480314956,837.9143704850362,0.00025370340306410486,25.0,45.0
415.04004,0.05196832086614173,839.3766253869969,0.00025370340306410486,25.0,45.0
416.6416,0.052368612204724406,839.2253353973168,0.00025370340306410486,25.0,45.0
418.24316,0.05276651968503937,837.6751547987616,0.00025370340306410486,25.0,45.0
419.84473,0.05308460039370078,837.4103973168216,0.00025370340306410486,25.0,45.0
421.44629,0.05341358858267716,840.3203818369453,0.00025370340306410486,25.0,45.0
423.04785,0.0538342874015748,839.574742002064,0.00025370340306410486,25.0,45.0
424.64941,0.054220866141732285,839.6605263157894,0.00025370340306410486,25.0,45.0
426.25098,0.054573196850393704,840.5018575851393,0.00025370340306410486,25.0,45.0
427.85254,0.05493769488188976,840.5455624355005,0.00025370340306410486,25.0,45.0
429.4541,0.055351555118110234,842.0756707946337,0.00025370340306410486,25.0,45.0
431.05566,0.0557208562992126,844.0334365325077,0.00025370340306410486,25.0,45.0
432.65723,0.0560700590551181,843.29326625387,0.00025370340306410486,25.0,45.0
434.25879,0.05641180118110237,843.2459752321982,0.00025370340306410486,25.0,45.0
435.86035,0.056756399606299204,842.5606037151704,0.00025370340306410486,25.0,45.0
437.46191,0.057178594488188975,844.6501547987616,0.00025370340306410486,25.0,45.0
439.06348,0.057586482283464566,844.5848297213622,0.00025370340306410486,25.0,45.0
440.66504,0.057955631889763784,846.0531475748195,0.00025370340306410486,25.0,45.0
442.2666,0.05830881299212599,845.6771671826626,0.00025370340306410486,25.0,45.0
443.86816,0.0586944311023622,846.6546697626419,0.00025370340306410486,25.0,45.0
445.46973,0.05902615748031496,848.0822239422085,0.00025370340306410486,25.0,45.0
447.07129,0.05941180905511811,846.212564499484,0.00025370340306410486,25.0,45.0
448.67285,0.05984274606299213,849.4408926728586,0.00025370340306410486,25.0,45.0
450.27441,0.060241710629921265,849.4560629514964,0.00025370340306410486,25.0,45.0
451.87598,0.06059967913385826,848.9837203302374,0.00025370340306410486,25.0,45.0
453.47754,0.060900852362204716,847.1295407636738,0.00025370340306410486,25.0,45.0
455.0791,0.06118709448818897,848.3053405572756,0.00025370340306410486,25.0,45.0
456.68066,0.06157752952755906,850.830830753354,0.00025370340306410486,25.0,45.0
458.28223,0.06191281102362205,850.2774251805986,0.00025370340306410486,25.0,45.0
459.88379,0.06225310826771654,851.0900928792571,0.00025370340306410486,25.0,45.0
461.48535,0.06262695866141732,853.0786119711044,0.00025370340306410486,25.0,45.0
463.08691,0.06301238188976378,851.8784571723427,0.00025370340306410486,25.0,45.0
464.68848,0.06339259645669292,852.3674148606812,0.00025370340306410486,25.0,45.0
466.29004,0.0637786594488189,853.7830753353973,0.00025370340306410486,25.0,45.0
467.8916,0.06419373228346456,854.1012125902993,0.00025370340306410486,25.0,45.0
469.49316,0.06464573031496063,854.8782507739938,0.00025370340306410486,25.0,45.0
471.09473,0.06508618307086614,854.3736326109391,0.00025370340306410486,25.0,45.0
472.69629,0.06545053543307087,853.1620227038185,0.00025370340306410486,25.0,45.0
474.29785,0.06579596062992125,854.4644220846234,0.00025370340306410486,25.0,45.0
475.89941,0.06611115551181103,854.7722910216719,0.00025370340306410486,25.0,45.0
477.50098,0.06645110039370078,855.6447368421052,0.00025370340306410486,25.0,45.0
479.10254,0.06683884251968504,856.1720072239423,0.00025370340306410486,25.0,45.0
480.7041,0.06719202952755905,856.6757223942209,0.00025370340306410486,25.0,45.0
482.30566,0.0675231751968504,856.5785861713106,0.00025370340306410486,25.0,45.0
483.90723,0.06789874212598425,856.3905830753355,0.00025370340306410486,25.0,45.0
485.50879,0.06825479724409449,858.4391898864809,0.00025370340306410486,25.0,45.0
487.11035,0.06866756692913385,858.0189370485036,0.00025370340306410486,25.0,45.0
488.71191,0.06903430511811023,859.8365067079463,0.00025370340306410486,25.0,45.0
490.31348,0.06944032086614174,858.0043859649123,0.00025370340306410486,25.0,45.0
491.91504,0.06978781102362205,859.0299019607844,0.00025370340306410486,25.0,45.0
493.5166,0.07012572047244094,858.546826625387,0.00025370340306410486,25.0,45.0
495.11816,0.07042686023622047,860.5848813209494,0.00025370340306410486,25.0,45.0
496.71973,0.07084238976377953,861.1416150670796,0.00025370340306410486,25.0,45.0
498.32129,0.07121362992125983,861.9845717234263,0.00025370340306410486,25.0,45.0
499.92285,0.0716434625984252,862.5302373581011,0.00025370340306410486,25.0,45.0
501.52441,0.0719914468503937,859.7932404540763,0.00025370340306410486,25.0,45.0
503.12598,0.07237995078740157,863.6646026831785,0.00025370340306410486,25.0,45.0
504.72754,0.0727848562992126,861.6247936016513,0.00025370340306410486,25.0,45.0
506.3291,0.07322815551181103,862.9445046439629,0.00025370340306410486,25.0,45.0
507.93066,0.07359864763779528,864.1674148606812,0.00025370340306410486,25.0,45.0
509.53223,0.07395762598425197,865.0135964912281,0.00025370340306410486,25.0,45.0
511.13379,0.0743389251968504,865.7965428276574,0.00025370340306410486,25.0,45.0
512.73535,0.07476248818897638,865.3035861713107,0.00025370340306410486,25.0,45.0
514.33691,0.07510378937007874,864.3228844169247,0.00025370340306410486,25.0,45.0
515.93848,0.07549426968503936,865.621310629515,0.00025370340306410486,25.0,45.0
517.54004,0.07584827165354331,866.5784055727554,0.00025370340306410486,25.0,45.0
519.1416,0.07615308267716535,865.490479876161,0.00025370340306410486,25.0,45.0
520.74316,0.07654467716535433,868.5299535603715,0.00025370340306410486,25.0,45.0
522.34473,0.07692692716535433,865.1999742002065,0.00025370340306410486,25.0,45.0
523.94629,0.07729349606299213,866.125902992776,0.00025370340306410486,25.0,45.0
525.54785,0.07763282677165353,867.6432146542827,0.00025370340306410486,25.0,45.0
527.14941,0.07797928346456692,868.0361971104231,0.00025370340306410486,25.0,45.0
528.75098,0.07835867716535433,870.322342621259,0.00025370340306410486,25.0,45.0
530.35254,0.07874035236220472,868.3503095975233,0.00025370340306410486,25.0,45.0
531.9541,0.07912049606299212,869.3767027863777,0.00025370340306410486,25.0,45.0
533.55566,0.0795385374015748,869.67564499484,0.00025370340306410486,25.0,45.0
535.15723,0.07988237401574802,872.142234262126,0.00025370340306410486,25.0,45.0
536.75879,0.08026109842519685,871.0522445820434,0.00025370340306410486,25.0,45.0
538.36035,0.0806658937007874,872.4767801857585,0.00025370340306410486,25.0,45.0
539.96191,0.08104995078740157,871.2285345717235,0.00025370340306410486,25.0,45.0
541.56348,0.08149284251968504,872.3237874097007,0.00025370340306410486,25.0,45.0
543.16504,0.08192007283464567,870.0632610939114,0.00025370340306410486,25.0,45.0
544.7666,0.08228313188976377,873.3386222910217,0.00025370340306410486,25.0,45.0
546.36816,0.08266359842519685,872.5672858617131,0.00025370340306410486,25.0,45.0
547.96973,0.08299144291338582,872.9044633642931,0.00025370340306410486,25.0,45.0
549.57129,0.08334526181102361,874.6150154798762,0.00025370340306410486,25.0,45.0
551.17285,0.0837287027559055,874.2034055727555,0.00025370340306410486,25.0,45.0
552.77441,0.0841177874015748,874.5853457172343,0.00025370340306410486,25.0,45.0
554.37598,0.08448107086614173,876.3329463364292,0.00025370340306410486,25.0,45.0
555.97754,0.08486404921259842,875.0398090815274,0.00025370340306410486,25.0,45.0
557.5791,0.0852631122047244,877.2886480908153,0.00025370340306410486,25.0,45.0
559.18066,0.08559997244094487,875.3871259029928,0.00025370340306410486,25.0,45.0
560.78223,0.08592779330708661,877.2007997936016,0.00025370340306410486,25.0,45.0
562.38379,0.08633898228346457,875.9979102167183,0.00025370340306410486,25.0,45.0
563.98535,0.0867171437007874,877.4551341589267,0.00025370340306410486,25.0,45.0
565.58691,0.08712129921259842,877.1290505675954,0.00025370340306410486,25.0,45.0
567.18848,0.08749916141732283,876.8231166150672,0.00025370340306410486,25.0,45.0
568.79004,0.0878890846456693,880.2919246646027,0.00025370340306410486,25.0,45.0
570.3916,0.0883865374015748,879.6273993808051,0.00025370340306410486,25.0,45.0
571.99316,0.088767812992126,879.0119969040247,0.00025370340306410486,25.0,45.0
573.59473,0.08912450787401574,879.7398864809081,0.00025370340306410486,25.0,45.0
575.19629,0.08945397637795276,878.3354489164086,0.00025370340306410486,25.0,45.0
576.79785,0.08980452952755906,879.6137254901961,0.00025370340306410486,25.0,45.0
578.39941,0.09022465354330708,881.5096491228071,0.00025370340306410486,25.0,45.0
580.00098,0.09072459842519685,883.0921052631579,0.00025370340306410486,25.0,45.0
581.60254,0.09117514173228347,882.9299019607844,0.00025370340306410486,25.0,45.0
583.2041,0.09154054921259842,880.0603715170279,0.00025370340306410486,25.0,45.0
584.80566,0.09187766141732283,879.9621259029929,0.00025370340306410486,25.0,45.0
586.40723,0.09226424212598425,883.2151702786379,0.00025370340306410486,25.0,45.0
588.00879,0.09264537007874016,881.2273477812178,0.00025370340306410486,25.0,45.0
589.61035,0.0929893996062992,883.7802373581012,0.00025370340306410486,25.0,45.0
591.21191,0.09341925196850394,884.9222652218783,0.00025370340306410486,25.0,45.0
592.81348,0.09375839960629921,882.2062951496388,0.00025370340306410486,25.0,45.0
594.41504,0.09409943700787401,883.8339783281733,0.00025370340306410486,25.0,45.0
596.0166,0.09446825787401575,884.4820433436532,0.00025370340306410486,25.0,45.0
597.61816,0.09482492913385827,885.1470072239422,0.00025370340306410486,25.0,45.0
599.21973,0.09519175,884.6008513931889,0.00025370340306410486,25.0,45.0
600.82129,0.09555692322834645,885.3477038183695,0.00025370340306410486,25.0,45.0
602.42285,0.09597771653543308,886.1545665634675,0.00025370340306410486,25.0,45.0
604.02441,0.09634851377952755,885.25415376677,0.00025370340306410486,25.0,45.0
605.62598,0.09676287204724408,885.904076367389,0.00025370340306410486,25.0,45.0
607.22754,0.09714593307086614,887.4993034055727,0.00025370340306410486,25.0,45.0
608.8291,0.09751204330708661,885.680830753354,0.00025370340306410486,25.0,45.0
610.43066,0.09789648228346456,887.155959752322,0.00025370340306410486,25.0,45.0
612.03223,0.09827639566929133,886.155701754386,0.00025370340306410486,25.0,45.0
613.63379,0.09874864566929134,890.4935500515995,0.00025370340306410486,25.0,45.0
615.23535,0.0991983090551181,887.2247936016512,0.00025370340306410486,25.0,45.0
616.83691,0.09956085236220473,888.26762125903,0.00025370340306410486,25.0,45.0
618.43848,0.09995738779527559,889.1682146542828,0.00025370340306410486,25.0,45.0
620.04004,0.10039042519685039,889.1991486068111,0.00025370340306410486,25.0,45.0
621.6416,0.10081932086614173,888.134520123839,0.00025370340306410486,25.0,45.0
623.24316,0.10119147440944881,887.9841073271414,0.00025370340306410486,25.0,45.0
624.84473,0.10156368700787402,890.3467750257998,0.00025370340306410486,25.0,45.0
626.44629,0.10195314566929134,891.7466202270382,0.00025370340306410486,25.0,45.0
628.04785,0.10237473228346458,890.40064499484,0.00025370340306410486,25.0,45.0
629.64941,0.1027961062992126,890.7110423116616,0.00025370340306410486,25.0,45.0
631.25098,0.10316068110236222,890.8083591331269,0.00025370340306410486,25.0,45.0
632.85254,0.10352743700787402,890.4007739938081,0.00025370340306410486,25.0,45.0
634.4541,0.10389107086614172,892.805185758514,0.00025370340306410486,25.0,45.0
636.05566,0.10426733267716536,891.4633642930856,0.00025370340306410486,25.0,45.0
637.65723,0.10471505905511812,893.4387254901961,0.00025370340306410486,25.0,45.0
639.25879,0.10509687007874015,893.7989422084623,0.00025370340306410486,25.0,45.0
640.86035,0.1055118720472441,892.0237616099072,0.00025370340306410486,25.0,45.0
642.46191,0.10583176574803149,894.3033539731683,0.00025370340306410486,25.0,45.0
644.06348,0.10624857677165354,894.1897832817339,0.00025370340306410486,25.0,45.0
645.66504,0.10664558070866141,894.7398090815274,0.00025370340306410486,25.0,45.0
647.2666,0.10701808661417322,894.8096491228071,0.00025370340306410486,25.0,45.0
648.86816,0.10749888976377953,896.1528637770898,0.00025370340306410486,25.0,45.0
650.46973,0.10794124212598424,894.681346749226,0.00025370340306410486,25.0,45.0
652.07129,0.10834046456692914,894.6317079463365,0.00025370340306410486,25.0,45.0
653.67285,0.1087180157480315,895.0509029927761,0.00025370340306410486,25.0,45.0
655.27441,0.10911829330708663,895.0599587203302,0.00025370340306410486,25.0,45.0
656.87598,0.10950297834645668,896.0554179566564,0.00025370340306410486,25.0,45.0
658.47754,0.10992929133858267,895.8089525283798,0.00025370340306410486,25.0,45.0
660.0791,0.11027563188976378,894.8800825593395,0.00025370340306410486,25.0,45.0
661.68066,0.1107004094488189,897.8813209494325,0.00025370340306410486,25.0,45.0
663.28223,0.11110082874015748,896.889705882353,0.00025370340306410486,25.0,45.0
664.88379,0.11148717913385826,896.6029927760578,0.00025370340306410486,25.0,45.0
666.48535,0.11186090551181102,898.6121001031992,0.00025370340306410486,25.0,45.0
668.08691,0.11232104527559054,898.8033281733747,0.00025370340306410486,25.0,45.0
669.68848,0.11275160826771653,897.8844169246646,0.00025370340306410486,25.0,45.0
671.29004,0.11314970275590551,898.0883642930856,0.00025370340306410486,25.0,45.0
672.8916,0.11355759645669292,898.1734520123839,0.00025370340306410486,25.0,45.0
674.49316,0.1139682933070866,897.7089783281734,0.00025370340306410486,25.0,45.0
676.09473,0.1143895846456693,900.3279411764706,0.00025370340306410486,25.0,45.0
677.69629,0.11480701771653543,899.5522703818369,0.00025370340306410486,25.0,45.0
679.29785,0.11520750590551182,901.4686016511868,0.00025370340306410486,25.0,45.0
680.89941,0.11560746850393701,899.8494324045408,0.00025370340306410486,25.0,45.0
682.50098,0.11600460039370078,900.3326109391124,0.00025370340306410486,25.0,45.0
684.10254,0.11643610039370078,901.0709494324045,0.00025370340306410486,25.0,45.0
685.7041,0.11684501574803148,901.1837719298246,0.00025370340306410486,25.0,45.0
687.30566,0.11726907677165355,901.3230908152735,0.00025370340306410486,25.0,45.0
688.90723,0.1177444468503937,901.4566821465429,0.00025370340306410486,25.0,45.0
690.50879,0.11810490157480315,899.618782249742,0.00025370340306410486,25.0,45.0
692.11035,0.11853565157480316,903.0860681114552,0.00025370340306410486,25.0,45.0
693.71191,0.11896834842519685,902.3788957688339,0.00025370340306410486,25.0,45.0
695.31348,0.11936984645669291,902.4443498452013,0.00025370340306410486,25.0,45.0
696.91504,0.11980966535433071,903.1918214654282,0.00025370340306410486,25.0,45.0
698.5166,0.12016813779527559,902.8778121775026,0.00025370340306410486,25.0,45.0
700.11816,0.12053257086614172,902.808101135191,0.00025370340306410486,25.0,45.0
701.71973,0.12092099803149607,902.7202270381837,0.00025370340306410486,25.0,45.0
703.32129,0.12133008858267716,903.4921310629516,0.00025370340306410486,25.0,45.0
704.92285,0.12173895472440946,905.2615841073272,0.00025370340306410486,25.0,45.0
706.52441,0.12224277952755905,906.429205366357,0.00025370340306410486,25.0,45.0
708.12598,0.12268251574803149,903.8072755417958,0.00025370340306410486,25.0,45.0
709.72754,0.12309615748031495,903.408875128999,0.00025370340306410486,25.0,45.0
711.3291,0.12347194881889764,903.4055985552117,0.00025370340306410486,25.0,45.0
712.93066,0.123866218503937,905.3730134158927,0.00025370340306410486,25.0,45.0
714.53223,0.12433657874015748,907.154076367389,0.00025370340306410486,25.0,45.0
716.13379,0.12476901771653542,906.7629772961817,0.00025370340306410486,25.0,45.0
717.73535,0.12520657283464567,906.0360423116616,0.00025370340306410486,25.0,45.0
719.33691,0.12564376377952755,908.25,0.00025370340306410486,25.0,45.0
720.93848,0.12610998228346457,907.4084623323014,0.00025370340306410486,25.0,45.0
722.54004,0.12654222047244093,907.1407120743035,0.00025370340306410486,25.0,45.0
724.1416,0.1269411496062992,906.2258255933953,0.00025370340306410486,25.0,45.0
725.74316,0.12730713188976378,906.390221878225,0.00025370340306410486,25.0,45.0
727.34473,0.12771759448818898,906.6512899896802,0.00025370340306410486,25.0,45.0
728.94629,0.128167,907.5568111455109,0.00025370340306410486,25.0,45.0
730.54785,0.12857695669291339,907.4133126934985,0.00025370340306410486,25.0,45.0
732.14941,0.12898008661417323,907.6896542827658,0.00025370340306410486,25.0,45.0
733.75098,0.12945729921259844,909.3437048503612,0.00025370340306410486,25.0,45.0
735.35254,0.12995884645669292,907.9998710010319,0.00025370340306410486,25.0,45.0
736.9541,0.13035068897637794,907.0008771929826,0.00025370340306410486,25.0,45.0
738.55566,0.13071160236220472,907.8561919504644,0.00025370340306410486,25.0,45.0
740.15723,0.1311124901574803,910.9383126934985,0.00025370340306410486,25.0,45.0
741.75879,0.13152208464566928,910.4526831785346,0.00025370340306410486,25.0,45.0
743.36035,0.13196639566929133,908.6763415892673,0.00025370340306410486,25.0,45.0
744.96191,0.13241188188976377,911.0024251805986,0.00025370340306410486,25.0,45.0
746.56348,0.1328282342519685,910.4497678018575,0.00025370340306410486,25.0,45.0
748.16504,0.13327627952755905,910.6858617131063,0.00025370340306410486,25.0,45.0
749.7666,0.13369067125984252,910.3639834881321,0.00025370340306410486,25.0,45.0
751.36816,0.13414051181102363,910.3987616099071,0.00025370340306410486,25.0,45.0
752.96973,0.1345201496062992,909.7486584107328,0.00025370340306410486,25.0,45.0
754.57129,0.13493408661417322,911.1471620227039,0.00025370340306410486,25.0,45.0
756.17285,0.1354131181102362,911.821826625387,0.00025370340306410486,25.0,45.0
757.77441,0.1359947440944882,912.2141124871001,0.00025370340306410486,25.0,45.0
759.37598,0.1364473287401575,911.4820691434469,0.00025370340306410486,25.0,45.0
760.97754,0.1368799783464567,911.4058049535604,0.00025370340306410486,25.0,45.0
762.5791,0.13731457677165354,911.340221878225,0.00025370340306410486,25.0,45.0
764.18066,0.1377526122047244,911.941253869969,0.00025370340306410486,25.0,45.0
765.78223,0.1381515157480315,912.4345717234262,0.00025370340306410486,25.0,45.0
767.38379,0.1385768562992126,913.2671568627451,0.00025370340306410486,25.0,45.0
768.98535,0.1390485433070866,913.126496388029,0.00025370340306410486,25.0,45.0
770.58691,0.13947964370078741,914.2320691434469,0.00025370340306410486,25.0,45.0
772.18848,0.13993674606299214,913.9566821465428,0.00025370340306410486,25.0,45.0
773.79004,0.14041408858267718,912.5801341589267,0.00025370340306410486,25.0,45.0
775.3916,0.14092834251968503,914.1465944272446,0.00025370340306410486,25.0,45.0
776.99316,0.14137895472440945,915.6120743034056,0.00025370340306410486,25.0,45.0
778.59473,0.14183400393700787,914.3775541795666,0.00025370340306410486,25.0,45.0
780.19629,0.14217467716535434,913.1323529411765,0.00025370340306410486,25.0,45.0
781.79785,0.1426289409448819,915.9913054695563,0.00025370340306410486,25.0,45.0
783.39941,0.14307068307086615,915.9223942208463,0.00025370340306410486,25.0,45.0
785.00098,0.14354037401574804,915.4902992776058,0.00025370340306410486,25.0,45.0
786.60254,0.14401982874015748,915.3998452012385,0.00025370340306410486,25.0,45.0
788.2041,0.1445001377952756,914.8920536635707,0.00025370340306410486,25.0,45.0
789.80566,0.14494104921259843,915.1834365325078,0.00025370340306410486,25.0,45.0
791.40723,0.1453817716535433,915.5893962848298,0.00025370340306410486,25.0,45.0
793.00879,0.14590929527559054,916.8725232198143,0.00025370340306410486,25.0,45.0
794.61035,0.1463689429133858,914.9089267285862,0.00025370340306410486,25.0,45.0
796.21191,0.14678974409448817,915.417105263158,0.00025370340306410486,25.0,45.0
797.81348,0.14727792716535432,915.5834107327142,0.00025370340306410486,25.0,45.0
799.41504,0.147725031496063,914.8641382868936,0.00025370340306410486,25.0,45.0
801.0166,0.14818445669291339,916.6522961816306,0.00025370340306410486,25.0,45.0
802.61816,0.1486388838582677,915.7986842105263,0.00025370340306410486,25.0,45.0
804.21973,0.1491037874015748,917.9337203302373,0.00025370340306410486,25.0,45.0
805.82129,0.1496081751968504,916.71762125903,0.00025370340306410486,25.0,45.0
807.42285,0.15010527559055117,918.4160990712074,0.00025370340306410486,25.0,45.0
809.02441,0.15059129921259842,917.4090299277606,0.00025370340306410486,25.0,45.0
810.62598,0.15098615748031496,916.4273735810115,0.00025370340306410486,25.0,45.0
812.22754,0.15138762007874015,918.3974974200207,0.00025370340306410486,25.0,45.0
813.8291,0.15186539566929133,915.9409184726522,0.00025370340306410486,25.0,45.0
815.43066,0.1523356968503937,917.8400670794634,0.00025370340306410486,25.0,45.0
817.03223,0.15285831692913385,918.4026831785345,0.00025370340306410486,25.0,45.0
818.63379,0.15330748818897638,916.3034055727554,0.00025370340306410486,25.0,45.0
820.23535,0.1537674409448819,917.9923116615067,0.00025370340306410486,25.0,45.0
821.83691,0.1542015216535433,918.6271671826626,0.00025370340306410486,25.0,45.0
823.43848,0.15468308858267715,918.9398348813211,0.00025370340306410486,25.0,45.0
825.04004,0.15518109251968504,919.904927760578,0.00025370340306410486,25.0,45.0
826.6416,0.1556704842519685,920.5308307533539,0.00025370340306410486,25.0,45.0
828.24316,0.15622948818897636,918.9861197110424,0.00025370340306410486,25.0,45.0
829.84473,0.1567036377952756,916.7972394220847,0.00025370340306410486,25.0,45.0
831.44629,0.15718601377952757,921.246826625387,0.00025370340306410486,25.0,45.0
833.04785,0.15769912992125984,920.4152476780187,0.00025370340306410486,25.0,45.0
834.64941,0.15816124212598426,919.1733230134159,0.00025370340306410486,25.0,45.0
836.25098,0.15862010433070867,921.0108617131064,0.00025370340306410486,25.0,45.0
837.85254,0.1591430059055118,922.8052631578947,0.00025370340306410486,25.0,45.0
839.4541,0.1596829311023622,919.623116615067,0.00025370340306410486,25.0,45.0
841.05566,0.16017676968503936,919.8574303405574,0.00025370340306410486,25.0,45.0
842.65723,0.16067201771653544,921.2865583075336,0.00025370340306410486,25.0,45.0
844.25879,0.1611663248031496,920.1844685242519,0.00025370340306410486,25.0,45.0
845.86035,0.16165107086614172,921.6445820433437,0.00025370340306410486,25.0,45.0
847.46191,0.16210502755905512,919.9019607843137,0.00025370340306410486,25.0,45.0
849.06348,0.16263077952755906,923.0320949432405,0.00025370340306410486,25.0,45.0
850.66504,0.16315330708661416,922.2632610939113,0.00025370340306410486,25.0,45.0
852.2666,0.16363772440944882,920.872549019608,0.00025370340306410486,25.0,45.0
853.86816,0.16410376574803148,920.944040247678,0.00025370340306410486,25.0,45.0
855.46973,0.16456095078740157,920.6006191950465,0.00025370340306410486,25.0,45.0
857.07129,0.16500338582677165,922.3049535603715,0.00025370340306410486,25.0,45.0
858.67285,0.1654956751968504,922.4088751289991,0.00025370340306410486,25.0,45.0
860.27441,0.16596035629921257,922.9999742002065,0.00025370340306410486,25.0,45.0
861.87598,0.16653313582677165,922.3789731682147,0.00025370340306410486,25.0,45.0
863.47754,0.16711109055118112,921.8414344685243,0.00025370340306410486,25.0,45.0
865.0791,0.16765036023622049,922.5353715170279,0.00025370340306410486,25.0,45.0
866.68066,0.16819121259842518,921.8363777089784,0.00025370340306410486,25.0,45.0
868.28223,0.1687215531496063,921.2439370485037,0.00025370340306410486,25.0,45.0
869.88379,0.16922598818897638,921.9567079463365,0.00025370340306410486,25.0,45.0
871.48535,0.16970756496062991,922.0590557275542,0.00025370340306410486,25.0,45.0
873.08691,0.1702605964566929,923.9191434468524,0.00025370340306410486,25.0,45.0
874.68848,0.1708027657480315,921.3715428276574,0.00025370340306410486,25.0,45.0
876.29004,0.1713123503937008,922.5844427244582,0.00025370340306410486,25.0,45.0
877.8916,0.17182620472440943,923.4285345717234,0.00025370340306410486,25.0,45.0
879.49316,0.172313812992126,922.1149122807018,0.00025370340306410486,25.0,45.0
881.09473,0.17284058661417323,924.3495356037153,0.00025370340306410486,25.0,45.0
882.69629,0.17338297637795275,923.4863003095975,0.00025370340306410486,25.0,45.0
884.29785,0.17385825393700788,922.478044375645,0.00025370340306410486,25.0,45.0
885.89941,0.17432842716535432,922.9597007223942,0.00025370340306410486,25.0,45.0
887.50098,0.17488814763779528,923.780701754386,0.00025370340306410486,25.0,45.0
889.10254,0.1754425059055118,922.7153250773994,0.00025370340306410486,25.0,45.0
890.7041,0.1759401338582677,923.1805985552116,0.00025370340306410486,25.0,45.0
892.30566,0.17645620669291337,922.0727296181631,0.00025370340306410486,25.0,45.0
893.90723,0.17698082086614172,924.1078431372549,0.00025370340306410486,25.0,45.0
895.50879,0.1775410118110236,925.5802631578948,0.00025370340306410486,25.0,45.0
897.11035,0.1780292992125984,922.5508513931889,0.00025370340306410486,25.0,45.0
898.71191,0.17853116338582678,924.1217234262126,0.00025370340306410486,25.0,45.0
900.31348,0.17908258858267714,925.0222394220847,0.00025370340306410486,25.0,45.0
901.91504,0.179682718503937,925.0632610939113,0.00025370340306410486,25.0,45.0
903.5166,0.18027311023622047,924.5392672858618,0.00025370340306410486,25.0,45.0
905.11816,0.18090956496062993,924.4600103199174,0.00025370340306410486,25.0,45.0
906.71973,0.1814908405511811,924.7877966976264,0.00025370340306410486,25.0,45.0
908.32129,0.18203348818897638,924.6025541795666,0.00025370340306410486,25.0,45.0
909.92285,0.18259806692913386,925.3320175438596,0.00025370340306410486,25.0,45.0
911.52441,0.1832185059055118,924.2910216718267,0.00025370340306410486,25.0,45.0
913.12598,0.18382315354330708,927.036919504644,0.00025370340306410486,25.0,45.0
914.72754,0.18436155511811023,923.1764447884418,0.00025370340306410486,25.0,45.0
916.3291,0.18486649212598424,924.4912538699691,0.00025370340306410486,25.0,45.0
917.93066,0.18540722834645668,925.1183694530445,0.00025370340306410486,25.0,45.0
919.53223,0.18593691141732285,924.8702012383901,0.00025370340306410486,25.0,45.0
921.13379,0.18652187007874016,924.2395510835913,0.00025370340306410486,25.0,45.0
922.73535,0.18709946062992125,924.1455882352941,0.00025370340306410486,25.0,45.0
924.33691,0.18764066732283463,925.1165376676986,0.00025370340306410486,25.0,45.0
925.93848,0.18817045472440946,926.6567853457173,0.00025370340306410486,25.0,45.0
927.54004,0.1888322775590551,927.0135964912281,0.00025370340306410486,25.0,45.0
929.1416,0.18943675000000001,925.0769091847266,0.00025370340306410486,25.0,45.0
930.74316,0.19000458858267716,923.9308565531476,0.00025370340306410486,25.0,45.0
932.34473,0.19062441929133858,924.5652734778122,0.00025370340306410486,25.0,45.0
933.94629,0.19121344881889762,925.6712848297213,0.00025370340306410486,25.0,45.0
935.54785,0.19184641929133858,925.2035345717235,0.00025370340306410486,25.0,45.0
937.14941,0.1923862755905512,923.8609391124871,0.00025370340306410486,25.0,45.0
938.75098,0.1929547716535433,925.0056759545924,0.00025370340306410486,25.0,45.0
940.35254,0.1934911437007874,924.2483746130031,0.00025370340306410486,25.0,45.0
941.9541,0.19408378740157478,925.5649380804954,0.00025370340306410486,25.0,45.0
943.55566,0.19469451181102362,925.5273477812178,0.00025370340306410486,25.0,45.0
945.15723,0.19535265157480317,925.502270381837,0.00025370340306410486,25.0,45.0
946.75879,0.195969218503937,925.1570949432405,0.00025370340306410486,25.0,45.0
948.36035,0.19658726574803148,926.8158926728587,0.00025370340306410486,25.0,45.0
949.96191,0.19724307086614173,926.432972136223,0.00025370340306410486,25.0,45.0
951.56348,0.19784952755905513,925.8953818369454,0.00025370340306410486,25.0,45.0
953.16504,0.19840915354330707,924.6387770897833,0.00025370340306410486,25.0,45.0
954.7666,0.19899887795275592,925.6965428276574,0.00025370340306410486,25.0,45.0
956.36816,0.19962594488188978,925.5495872033024,0.00025370340306410486,25.0,45.0
957.96973,0.20025301181102362,925.7938596491229,0.00025370340306410486,25.0,45.0
959.57129,0.20086746062992128,924.2469298245614,0.00025370340306410486,25.0,45.0
961.17285,0.20148358267716535,925.4869711042312,0.00025370340306410486,25.0,45.0
962.77441,0.20205761811023623,924.0323271413829,0.00025370340306410486,25.0,45.0
964.37598,0.20269763779527558,925.0040505675955,0.00025370340306410486,25.0,45.0
965.97754,0.20332647637795273,924.5484004127967,0.00025370340306410486,25.0,45.0
967.5791,0.20395082677165352,925.7348813209495,0.00025370340306410486,25.0,45.0
969.18066,0.20460872047244094,925.0046181630547,0.00025370340306410486,25.0,45.0
970.78223,0.20530970472440946,925.1724200206398,0.00025370340306410486,25.0,45.0
972.38379,0.20605145669291336,925.6919246646028,0.00025370340306410486,25.0,45.0
973.98535,0.2068237007874016,925.0178276573787,0.00025370340306410486,25.0,45.0
975.58691,0.2074617716535433,923.9738906088751,0.00025370340306410486,25.0,45.0
977.18848,0.208059094488189,924.0131320949433,0.00025370340306410486,25.0,45.0
978.79004,0.2085592125984252,924.594298245614,0.00025370340306410486,25.0,45.0
980.3916,0.20918271653543305,926.9337977296182,0.00025370340306410486,25.0,45.0
981.99316,0.2098451181102362,925.9048245614035,0.00025370340306410486,25.0,45.0
983.59473,0.2104657874015748,924.6546439628484,0.00025370340306410486,25.0,45.0
985.19629,0.2110872244094488,925.2384158926728,0.00025370340306410486,25.0,45.0
985.39648,0.21119330708661416,928.0094943240455,0.00025370340306410486,25.0,45.0