File: datasets/am_bench_2022/csv/45-XY.13-3.csv
Time(s),Strain(%),Stress(MPa),SR(s-1),Temp(C),Angle(deg)
27.839355,1.2534345078740157e-05,27.707433692498963,0.00025370340306410486,25.0,45.0
29.440918,2.3120714566929135e-05,32.19321902196436,0.00025370340306410486,25.0,45.0
30.842285,4.1227549212598424e-05,37.667325424782426,0.00025370340306410486,25.0,45.0
32.243652,4.875991535433071e-05,43.8805066307501,0.00025370340306410486,25.0,45.0
33.64502,8.054282283464566e-05,50.70300196850393,0.00025370340306410486,25.0,45.0
35.046387,0.00010616104527559056,57.69107956900124,0.00025370340306410486,25.0,45.0
36.447754,0.00013387033267716535,66.56701201823455,0.00025370340306410486,25.0,45.0
37.849121,0.0001548220433070866,70.5827678201409,0.00025370340306410486,25.0,45.0
39.250488,0.00017102860236220473,79.13416390385412,0.00025370340306410486,25.0,45.0
40.651855,0.00021116726377952755,86.04732697886448,0.00025370340306410486,25.0,45.0
42.053223,0.00021989529527559055,93.9912401574803,0.00025370340306410486,25.0,45.0
43.45459,0.0002526403346456693,102.79560194778284,0.00025370340306410486,25.0,45.0
44.855957,0.0002990435039370079,108.99613033568171,0.00025370340306410486,25.0,45.0
46.257324,0.00031889513779527554,119.4515696228761,0.00025370340306410486,25.0,45.0
47.658691,0.0003631171062992126,128.8180195814339,0.00025370340306410486,25.0,45.0
49.060059,0.0003916588582677165,137.5130853709076,0.00025370340306410486,25.0,45.0
50.461426,0.00040584777559055123,146.5183174471612,0.00025370340306410486,25.0,45.0
51.862793,0.0004569061614173228,156.904711458765,0.00025370340306410486,25.0,45.0
53.26416,0.0004726365748031496,163.56944415665146,0.00025370340306410486,25.0,45.0
54.665527,0.0005088381299212598,175.96208816825526,0.00025370340306410486,25.0,45.0
56.066895,0.0005463287598425196,185.01199492333194,0.00025370340306410486,25.0,45.0
57.468262,0.0005754091732283465,194.81877072109404,0.00025370340306410486,25.0,45.0
58.869629,0.0006142379921259842,203.87617074181517,0.00025370340306410486,25.0,45.0
60.270996,0.000648206968503937,215.59676232905096,0.00025370340306410486,25.0,45.0
61.672363,0.0006810308661417323,225.87981247409863,0.00025370340306410486,25.0,45.0
63.07373,0.0007206687795275591,235.71352828429337,0.00025370340306410486,25.0,45.0
64.475098,0.0007349504527559054,244.06180066307502,0.00025370340306410486,25.0,45.0
65.876465,0.0007948521850393701,254.6699803149606,0.00025370340306410486,25.0,45.0
67.277832,0.000812062874015748,265.38574906755076,0.00025370340306410486,25.0,45.0
68.679199,0.0008558074409448819,276.8403698715292,0.00025370340306410486,25.0,45.0
70.080566,0.00088837,287.6489846663904,0.00025370340306410486,25.0,45.0
71.481934,0.0009295526968503937,296.9175818483216,0.00025370340306410486,25.0,45.0
72.883301,0.0009563569094488189,305.93607542478236,0.00025370340306410486,25.0,45.0
74.284668,0.0009858889960629922,317.0095576046415,0.00025370340306410486,25.0,45.0
75.686035,0.0010208676771653543,328.824311023622,0.00025370340306410486,25.0,45.0
77.087402,0.0010619809842519685,338.75681205967675,0.00025370340306410486,25.0,45.0
78.48877,0.0010997360433070867,349.07050352258597,0.00025370340306410486,25.0,45.0
79.890137,0.0011404040354330708,361.98109200165766,0.00025370340306410486,25.0,45.0
81.291504,0.0011666622047244095,370.19889660174056,0.00025370340306410486,25.0,45.0
82.692871,0.0012205688188976379,383.92024968918355,0.00025370340306410486,25.0,45.0
84.094238,0.001251301279527559,392.10619560712803,0.00025370340306410486,25.0,45.0
85.495605,0.0012764736614173228,401.1651989225031,0.00025370340306410486,25.0,45.0
86.896973,0.0013127347440944881,410.8492540406133,0.00025370340306410486,25.0,45.0
88.29834,0.0013395308858267715,420.3141317861583,0.00025370340306410486,25.0,45.0
89.699707,0.0013887236811023621,432.74886033982597,0.00025370340306410486,25.0,45.0
91.101074,0.0014247636811023621,442.76727621218396,0.00025370340306410486,25.0,45.0
92.502441,0.0014495359448818898,452.67716535433067,0.00025370340306410486,25.0,45.0
93.903809,0.0014696487401574803,459.7523052217157,0.00025370340306410486,25.0,45.0
95.305176,0.0015121236614173228,471.2520721094074,0.00025370340306410486,25.0,45.0
96.706543,0.001551075216535433,481.9916079569001,0.00025370340306410486,25.0,45.0
98.10791,0.0015831539566929134,490.8270824699544,0.00025370340306410486,25.0,45.0
99.509277,0.0016139591141732283,498.01598114380437,0.00025370340306410486,25.0,45.0
100.91064,0.0016236421062992127,507.95423228346453,0.00025370340306410486,25.0,45.0
102.31201,0.0016493693503937007,516.8415354330708,0.00025370340306410486,25.0,45.0
103.71338,0.001682965157480315,522.9248083298799,0.00025370340306410486,25.0,45.0
105.11475,0.0017232113188976378,531.6890540820556,0.00025370340306410486,25.0,45.0
106.51611,0.0017474253346456694,540.1618835474512,0.00025370340306410486,25.0,45.0
107.91748,0.001775815275590551,547.0201253626192,0.00025370340306410486,25.0,45.0
109.31885,0.001790368838582677,550.6647845006216,0.00025370340306410486,25.0,45.0
110.72021,0.0018066576377952755,556.2225704517199,0.00025370340306410486,25.0,45.0
112.12158,0.0018683516929133856,566.7875569830087,0.00025370340306410486,25.0,45.0
113.52295,0.001874089409448819,571.9322938251139,0.00025370340306410486,25.0,45.0
114.92432,0.001905800216535433,579.1251036054703,0.00025370340306410486,25.0,45.0
116.32568,0.001929480374015748,585.5477103191048,0.00025370340306410486,25.0,45.0
117.72705,0.001963212775590551,593.5992022378781,0.00025370340306410486,25.0,45.0
119.12842,0.001991303346456693,598.3865261085786,0.00025370340306410486,25.0,45.0
120.52979,0.002001406496062992,601.4513831330295,0.00025370340306410486,25.0,45.0
121.93115,0.0020179139763779525,607.6703014919187,0.00025370340306410486,25.0,45.0
123.33252,0.002060545078740157,613.4860909656029,0.00025370340306410486,25.0,45.0
124.73389,0.0020890232283464565,617.0140126398674,0.00025370340306410486,25.0,45.0
126.13525,0.0020991118110236223,620.2141266058848,0.00025370340306410486,25.0,45.0
127.53662,0.0021255836614173227,626.2748912142561,0.00025370340306410486,25.0,45.0
128.93799,0.0021634950787401577,631.9472648155822,0.00025370340306410486,25.0,45.0
130.33936,0.002180790748031496,634.3937266887691,0.00025370340306410486,25.0,45.0
131.74072,0.002220713188976378,638.0913800248653,0.00025370340306410486,25.0,45.0
133.14209,0.002243563188976378,644.8268234562785,0.00025370340306410486,25.0,45.0
134.54346,0.0022834456692913383,649.9143182760049,0.00025370340306410486,25.0,45.0
135.94482,0.0023118765748031496,650.4011085785329,0.00025370340306410486,25.0,45.0
137.34619,0.002333645866141732,656.3373653128884,0.00025370340306410486,25.0,45.0
138.74756,0.0023561173228346458,659.5465706589307,0.00025370340306410486,25.0,45.0
140.14893,0.0024221163385826773,665.2904838375466,0.00025370340306410486,25.0,45.0
141.55029,0.0024415639763779528,666.45438769167,0.00025370340306410486,25.0,45.0
142.95166,0.0024608476377952753,670.3967053460423,0.00025370340306410486,25.0,45.0
144.35303,0.0025153881889763783,675.3524917115624,0.00025370340306410486,25.0,45.0
145.75439,0.0025529870078740157,677.4405304600082,0.00025370340306410486,25.0,45.0
147.15576,0.0025942299212598423,681.1281340654787,0.00025370340306410486,25.0,45.0
148.55713,0.0026427555118110234,685.5773414836303,0.00025370340306410486,25.0,45.0
149.9585,0.00268493937007874,687.8697420223788,0.00025370340306410486,25.0,45.0
151.35986,0.002728229527559055,690.440349150435,0.00025370340306410486,25.0,45.0
152.76123,0.002791867716535433,695.663929755491,0.00025370340306410486,25.0,45.0
154.1626,0.002844349803149606,697.98526212184,0.00025370340306410486,25.0,45.0
155.56396,0.002888559842519685,701.4735288023206,0.00025370340306410486,25.0,45.0
156.96533,0.00294351437007874,702.7711873186904,0.00025370340306410486,25.0,45.0
158.3667,0.003008782677165354,705.4386655615416,0.00025370340306410486,25.0,45.0
159.76807,0.0030815391732283465,710.1666234977206,0.00025370340306410486,25.0,45.0
161.16943,0.0031585507874015745,713.6515489017819,0.00025370340306410486,25.0,45.0
162.5708,0.0032196639763779527,715.8484769995856,0.00025370340306410486,25.0,45.0
163.97217,0.0032761090551181103,717.9537919602155,0.00025370340306410486,25.0,45.0
165.37354,0.0033751661417322837,720.536520928305,0.00025370340306410486,25.0,45.0
166.7749,0.003455015748031496,722.8204776212184,0.00025370340306410486,25.0,45.0
168.17627,0.003559633661417323,725.6495026937422,0.00025370340306410486,25.0,45.0
169.57764,0.0036598267716535437,727.8027610857853,0.00025370340306410486,25.0,45.0
170.979,0.0037500679133858268,728.798590965603,0.00025370340306410486,25.0,45.0
172.38037,0.003864839763779527,732.7536002900953,0.00025370340306410486,25.0,45.0
173.78174,0.0039954559055118116,734.5534345213428,0.00025370340306410486,25.0,45.0
175.18311,0.004101949015748031,736.6850393700787,0.00025370340306410486,25.0,45.0
176.58447,0.004227845866141732,738.8119819726481,0.00025370340306410486,25.0,45.0
177.98584,0.00434834625984252,740.1762847078325,0.00025370340306410486,25.0,45.0
179.38721,0.004470345078740157,743.3271342726895,0.00025370340306410486,25.0,45.0
180.78857,0.004595180511811024,744.9860650642354,0.00025370340306410486,25.0,45.0
182.18994,0.00473516594488189,747.8820192706174,0.00025370340306410486,25.0,45.0
183.59131,0.004888921456692914,748.9465913800248,0.00025370340306410486,25.0,45.0
184.99268,0.005063185826771653,751.5445503522585,0.00025370340306410486,25.0,45.0
186.39404,0.0052281395669291335,751.697472026523,0.00025370340306410486,25.0,45.0
187.79541,0.005424688976377953,756.5385412349772,0.00025370340306410486,25.0,45.0
189.19678,0.005615562007874016,757.7308588893493,0.00025370340306410486,25.0,45.0
190.59814,0.005815844094488189,760.8224979278905,0.00025370340306410486,25.0,45.0
191.99951,0.005999975984251968,758.6094591794446,0.00025370340306410486,25.0,45.0
193.40088,0.006190748228346456,761.7116659759636,0.00025370340306410486,25.0,45.0
194.80225,0.006410560236220472,763.2826875259013,0.00025370340306410486,25.0,45.0
196.20361,0.006622172834645669,762.3166442188146,0.00025370340306410486,25.0,45.0
197.60498,0.00685611437007874,767.0242177786987,0.00025370340306410486,25.0,45.0
199.00635,0.007096427952755905,766.0737929962702,0.00025370340306410486,25.0,45.0
200.40771,0.007346450000000001,767.003677994198,0.00025370340306410486,25.0,45.0
201.80908,0.007546458464566928,767.6787194363861,0.00025370340306410486,25.0,45.0
203.21045,0.007770495078740156,770.2333713220058,0.00025370340306410486,25.0,45.0
204.61182,0.008033708858267716,773.3461717778698,0.00025370340306410486,25.0,45.0
206.01318,0.00827334035433071,772.5817706174886,0.00025370340306410486,25.0,45.0
207.41455,0.008531720669291339,773.6641110650642,0.00025370340306410486,25.0,45.0
208.81592,0.008807622440944882,774.0143752590136,0.00025370340306410486,25.0,45.0
210.21729,0.009055730511811024,775.4412815996684,0.00025370340306410486,25.0,45.0
211.61865,0.009332172637795275,778.2566825528388,0.00025370340306410486,25.0,45.0
213.02002,0.009631739566929134,777.5505853709075,0.00025370340306410486,25.0,45.0
214.42139,0.009870728543307087,778.845213427269,0.00025370340306410486,25.0,45.0
215.82275,0.010163463188976377,781.8207107335267,0.00025370340306410486,25.0,45.0
217.22412,0.010448312992125985,782.966146912557,0.00025370340306410486,25.0,45.0
218.62549,0.010675873228346457,782.2648155822627,0.00025370340306410486,25.0,45.0
220.02686,0.010920751574803149,780.6114535847493,0.00025370340306410486,25.0,45.0
221.42822,0.011209726968503936,782.9765333609614,0.00025370340306410486,25.0,45.0
222.82959,0.01151635216535433,784.9544135930377,0.00025370340306410486,25.0,45.0
224.23096,0.01180268248031496,785.6631527144633,0.00025370340306410486,25.0,45.0
225.63232,0.012063754330708661,786.6103657273103,0.00025370340306410486,25.0,45.0
227.03369,0.012414917125984252,789.2049834231246,0.00025370340306410486,25.0,45.0
228.43506,0.01275236968503937,788.4913748445917,0.00025370340306410486,25.0,45.0
229.83643,0.013059537598425196,789.5928823041857,0.00025370340306410486,25.0,45.0
231.23779,0.013366805118110238,791.0647016162453,0.00025370340306410486,25.0,45.0
232.63916,0.01370046496062992,790.3465861997513,0.00025370340306410486,25.0,45.0
234.04053,0.013991110826771654,792.7566307501035,0.00025370340306410486,25.0,45.0
235.44189,0.014315859448818899,793.1835888934935,0.00025370340306410486,25.0,45.0
236.84326,0.014632563385826771,793.0091949854951,0.00025370340306410486,25.0,45.0
238.24463,0.014970650984251968,794.607853294654,0.00025370340306410486,25.0,45.0
239.646,0.015247718700787402,794.3437888520513,0.00025370340306410486,25.0,45.0
241.04736,0.015606272047244095,796.7707728968089,0.00025370340306410486,25.0,45.0
242.44873,0.01589394803149606,796.6350756319933,0.00025370340306410486,25.0,45.0
243.8501,0.016205574606299213,797.0850600911727,0.00025370340306410486,25.0,45.0
245.25146,0.016491343897637796,797.6299471612101,0.00025370340306410486,25.0,45.0
246.65283,0.016810590944881888,797.9634531703274,0.00025370340306410486,25.0,45.0
248.0542,0.01711958779527559,800.225290095317,0.00025370340306410486,25.0,45.0
249.45557,0.017473208661417324,800.8364587650227,0.00025370340306410486,25.0,45.0
250.85693,0.017807767519685037,801.5985806050559,0.00025370340306410486,25.0,45.0
252.2583,0.018101772244094486,802.4824906755076,0.00025370340306410486,25.0,45.0
253.65967,0.018442027559055118,804.4561230832987,0.00025370340306410486,25.0,45.0
255.06104,0.01877369586614173,802.4874119353501,0.00025370340306410486,25.0,45.0
256.4624,0.019103319488188976,804.1907376709489,0.00025370340306410486,25.0,45.0
257.86377,0.01940454153543307,805.953947368421,0.00025370340306410486,25.0,45.0
259.26514,0.019720891732283464,805.7405200994612,0.00025370340306410486,25.0,45.0
260.6665,0.020003840551181103,805.5642094902611,0.00025370340306410486,25.0,45.0
262.06787,0.0203410374015748,807.0307190219643,0.00025370340306410486,25.0,45.0
263.46924,0.020671374015748034,805.7128056361375,0.00025370340306410486,25.0,45.0
264.87061,0.02099108661417323,807.4927735184417,0.00025370340306410486,25.0,45.0
266.27197,0.021312624015748034,809.2929185661002,0.00025370340306410486,25.0,45.0
267.67334,0.021610496062992125,807.8786520928304,0.00025370340306410486,25.0,45.0
269.07471,0.022043401574803147,809.2256268130957,0.00025370340306410486,25.0,45.0
270.47607,0.02241701377952756,811.9854952341483,0.00025370340306410486,25.0,45.0
271.87744,0.02275297244094488,811.5578377538333,0.00025370340306410486,25.0,45.0
273.27881,0.02307632283464567,811.5255128470783,0.00025370340306410486,25.0,45.0
274.68018,0.023383125984251966,814.1743939079984,0.00025370340306410486,25.0,45.0
276.08154,0.023693094488188977,812.7574077911313,0.00025370340306410486,25.0,45.0
277.48291,0.024049350393700784,813.5003626191462,0.00025370340306410486,25.0,45.0
278.88428,0.024406852362204724,814.8794809365934,0.00025370340306410486,25.0,45.0
280.28564,0.024782068897637795,814.0971301284708,0.00025370340306410486,25.0,45.0
281.68701,0.025116051181102363,814.5089877745545,0.00025370340306410486,25.0,45.0
283.08838,0.02546922244094488,815.4873601326149,0.00025370340306410486,25.0,45.0
284.48975,0.0257789468503937,814.9079983423125,0.00025370340306410486,25.0,45.0
285.89111,0.026098972440944883,816.0668514297555,0.00025370340306410486,25.0,45.0
287.29248,0.026475151574803152,819.498342312474,0.00025370340306410486,25.0,45.0
288.69385,0.026779055118110236,818.2168721508496,0.00025370340306410486,25.0,45.0
290.09521,0.027063811023622045,817.4795897223373,0.00025370340306410486,25.0,45.0
291.49658,0.027422639763779528,819.8085111893907,0.00025370340306410486,25.0,45.0
292.89795,0.02772974409448819,818.9424212598425,0.00025370340306410486,25.0,45.0
294.29932,0.02808166338582677,820.2935920016577,0.00025370340306410486,25.0,45.0
295.70068,0.028422127952755904,820.2443276004973,0.00025370340306410486,25.0,45.0
297.10205,0.028767761811023623,821.6268648984666,0.00025370340306410486,25.0,45.0
298.50342,0.02906196062992126,820.8524658101946,0.00025370340306410486,25.0,45.0
299.90479,0.029375269685039368,822.3658827186075,0.00025370340306410486,25.0,45.0
301.30615,0.02977183070866142,823.6934573145461,0.00025370340306410486,25.0,45.0
302.70752,0.030156236220472442,824.2445607128055,0.00025370340306410486,25.0,45.0
304.10889,0.030511021653543306,825.2633651056776,0.00025370340306410486,25.0,45.0
305.51025,0.030835694881889763,824.2121840033153,0.00025370340306410486,25.0,45.0
306.91162,0.031161159448818896,825.7431361375881,0.00025370340306410486,25.0,45.0
308.31299,0.031500348425196854,823.9472389142146,0.00025370340306410486,25.0,45.0
309.71436,0.031839838582677166,826.2170793617903,0.00025370340306410486,25.0,45.0
311.11572,0.03216862598425197,826.783283257356,0.00025370340306410486,25.0,45.0
312.51709,0.03251447244094488,827.2954309987566,0.00025370340306410486,25.0,45.0
313.91846,0.032907082677165356,828.9241866970576,0.00025370340306410486,25.0,45.0
315.31982,0.03320947244094488,829.1183433485288,0.00025370340306410486,25.0,45.0
316.72119,0.033542557086614175,829.3462235806049,0.00025370340306410486,25.0,45.0
318.12256,0.033932669291338584,830.0532791131371,0.00025370340306410486,25.0,45.0
319.52393,0.0342501751968504,830.1239639452962,0.00025370340306410486,25.0,45.0
320.92529,0.03452421653543307,830.1849357646083,0.00025370340306410486,25.0,45.0
322.32666,0.03490469094488189,834.4369042685454,0.00025370340306410486,25.0,45.0
323.72803,0.03522802559055118,830.6034759635309,0.00025370340306410486,25.0,45.0
325.12939,0.035516622047244095,833.1069985495234,0.00025370340306410486,25.0,45.0
326.53076,0.035851431102362205,832.853657273104,0.00025370340306410486,25.0,45.0
327.93213,0.03616330511811024,833.026548901782,0.00025370340306410486,25.0,45.0
329.3335,0.0365086811023622,834.4594125569829,0.00025370340306410486,25.0,45.0
330.73486,0.036763812992125985,834.3710111893907,0.00025370340306410486,25.0,45.0
332.13623,0.0371593248031496,837.8092105263157,0.00025370340306410486,25.0,45.0
333.5376,0.03750646062992126,836.178538126813,0.00025370340306410486,25.0,45.0
334.93896,0.03790179330708661,836.6934832159137,0.00025370340306410486,25.0,45.0
336.34033,0.038204946850393696,836.5125621632822,0.00025370340306410486,25.0,45.0
337.7417,0.03847529921259842,836.1770876502279,0.00025370340306410486,25.0,45.0
339.14307,0.038783712598425196,837.1577393286365,0.00025370340306410486,25.0,45.0
340.54443,0.03917142519685039,839.4802631578947,0.00025370340306410486,25.0,45.0
341.9458,0.03956404921259842,840.7942395358474,0.00025370340306410486,25.0,45.0
343.34717,0.039903781496062996,838.7661365520099,0.00025370340306410486,25.0,45.0
344.74854,0.0402646062992126,841.3791701201823,0.00025370340306410486,25.0,45.0
346.1499,0.04057940551181102,841.1799886033982,0.00025370340306410486,25.0,45.0
347.55127,0.0409426968503937,841.2322834645669,0.00025370340306410486,25.0,45.0
348.95264,0.041277657480314964,839.6762329050973,0.00025370340306410486,25.0,45.0
350.354,0.041638124015748026,843.770954206382,0.00025370340306410486,25.0,45.0
351.75537,0.04194124606299213,841.490727310402,0.00025370340306410486,25.0,45.0
353.15674,0.04226420472440945,841.0957573559883,0.00025370340306410486,25.0,45.0
354.55811,0.04254391732283465,842.60746477414,0.00025370340306410486,25.0,45.0
355.95947,0.04287490551181102,842.9579102776626,0.00025370340306410486,25.0,45.0
357.36084,0.04318111220472441,844.2368680066307,0.00025370340306410486,25.0,45.0
358.76221,0.04354929724409449,843.6752745544965,0.00025370340306410486,25.0,45.0
360.16357,0.04386920078740157,844.9127382925818,0.00025370340306410486,25.0,45.0
361.56494,0.04422052165354331,844.9686852465809,0.00025370340306410486,25.0,45.0
362.96631,0.044544377952755905,843.5847233733941,0.00025370340306410486,25.0,45.0
364.36768,0.04484655905511811,844.9649036469125,0.00025370340306410486,25.0,45.0
365.76904,0.04516563385826772,849.1448404475756,0.00025370340306410486,25.0,45.0
367.17041,0.04556893307086614,849.6901160381268,0.00025370340306410486,25.0,45.0
368.57178,0.04592399803149606,847.6033464566929,0.00025370340306410486,25.0,45.0
369.97314,0.04620031692913386,845.4528854123497,0.00025370340306410486,25.0,45.0
371.37451,0.046551576771653544,849.6104434314132,0.00025370340306410486,25.0,45.0
372.77588,0.04691217913385827,847.1576616245337,0.00025370340306410486,25.0,45.0
374.17725,0.04721803346456693,850.4898725652714,0.00025370340306410486,25.0,45.0
375.57861,0.04749509842519685,850.1417581848322,0.00025370340306410486,25.0,45.0
376.97998,0.04790994881889764,849.9510464152506,0.00025370340306410486,25.0,45.0
378.38135,0.04821099409448819,850.7754351429755,0.00025370340306410486,25.0,45.0
379.78271,0.0485811062992126,852.3073974305843,0.00025370340306410486,25.0,45.0
381.18408,0.04892869881889764,851.302838789888,0.00025370340306410486,25.0,45.0
382.58545,0.04924753937007874,852.7286054703687,0.00025370340306410486,25.0,45.0
383.98682,0.04952974015748031,852.2094902610858,0.00025370340306410486,25.0,45.0
385.38818,0.04983323228346457,853.5721612101119,0.00025370340306410486,25.0,45.0
386.78955,0.05017753149606299,854.090887898881,0.00025370340306410486,25.0,45.0
388.19092,0.05049630905511811,854.5964566929133,0.00025370340306410486,25.0,45.0
389.59229,0.050849572834645675,855.210241400746,0.00025370340306410486,25.0,45.0
390.99365,0.05121061614173228,855.9236427683381,0.00025370340306410486,25.0,45.0
392.39502,0.051610395669291334,854.849150435143,0.00025370340306410486,25.0,45.0
393.79639,0.051939527559055114,856.600859925404,0.00025370340306410486,25.0,45.0
395.19775,0.052257346456692916,855.979356610029,0.00025370340306410486,25.0,45.0
396.59912,0.05257556102362205,855.8418980522171,0.00025370340306410486,25.0,45.0
398.00049,0.052869724409448815,857.6541131371737,0.00025370340306410486,25.0,45.0
399.40186,0.05318577559055118,857.8890126398674,0.00025370340306410486,25.0,45.0
400.80322,0.05355685629921259,859.4073249067551,0.00025370340306410486,25.0,45.0
402.20459,0.05387803543307087,857.7186593452134,0.00025370340306410486,25.0,45.0
403.60596,0.054200059055118106,859.2119767923747,0.00025370340306410486,25.0,45.0
405.00732,0.05455300984251968,859.3662712391214,0.00025370340306410486,25.0,45.0
406.40869,0.05484827559055118,858.4040095317033,0.00025370340306410486,25.0,45.0
407.81006,0.05519372440944882,860.6362929962702,0.00025370340306410486,25.0,45.0
409.21143,0.05553840551181103,862.066618317447,0.00025370340306410486,25.0,45.0
410.61279,0.0558957342519685,862.4304289266473,0.00025370340306410486,25.0,45.0
412.01416,0.056206915354330714,861.2907946539576,0.00025370340306410486,25.0,45.0
413.41553,0.05653976377952755,861.7065116038126,0.00025370340306410486,25.0,45.0
414.81689,0.05687309251968504,862.6509272689598,0.00025370340306410486,25.0,45.0
416.21826,0.05724731692913385,861.3138209697472,0.00025370340306410486,25.0,45.0
417.61963,0.0575906122047244,862.1108837546622,0.00025370340306410486,25.0,45.0
419.021,0.057905055118110234,862.4235391628678,0.00025370340306410486,25.0,45.0
420.42236,0.058220767716535435,863.5568535018649,0.00025370340306410486,25.0,45.0
421.82373,0.058553801181102365,865.2821176958142,0.00025370340306410486,25.0,45.0
423.2251,0.05890250590551181,864.9247047244094,0.00025370340306410486,25.0,45.0
424.62646,0.059178061023622046,863.7354952341483,0.00025370340306410486,25.0,45.0
426.02783,0.05950679527559055,866.2542996270203,0.00025370340306410486,25.0,45.0
427.4292,0.059882251968503934,865.032713427269,0.00025370340306410486,25.0,45.0
428.83057,0.06022200393700787,865.8560920016577,0.00025370340306410486,25.0,45.0
430.23193,0.06052849409448818,866.0085474513054,0.00025370340306410486,25.0,45.0
431.6333,0.0608921220472441,866.5878574388728,0.00025370340306410486,25.0,45.0
433.03467,0.061231681102362205,868.3883651056775,0.00025370340306410486,25.0,45.0
434.43604,0.06155489566929134,868.6898829258184,0.00025370340306410486,25.0,45.0
435.8374,0.061899899606299214,870.1782532117695,0.00025370340306410486,25.0,45.0
437.23877,0.06219924803149606,868.8100393700787,0.00025370340306410486,25.0,45.0
438.64014,0.06253480511811023,869.544394944053,0.00025370340306410486,25.0,45.0
440.0415,0.06287501574803149,869.0340602983838,0.00025370340306410486,25.0,45.0
441.44287,0.06317505118110237,869.9194985495234,0.00025370340306410486,25.0,45.0
442.84424,0.0634903562992126,871.917996270203,0.00025370340306410486,25.0,45.0
444.24561,0.06383503149606298,869.8391784086199,0.00025370340306410486,25.0,45.0
445.64697,0.06414326771653543,869.2706433899709,0.00025370340306410486,25.0,45.0
447.04834,0.06448543700787401,871.6123860339825,0.00025370340306410486,25.0,45.0
448.44971,0.0649182342519685,874.9639452963116,0.00025370340306410486,25.0,45.0
449.85107,0.0652628031496063,872.8492022378781,0.00025370340306410486,25.0,45.0
451.25244,0.06558933267716535,873.6987929962702,0.00025370340306410486,25.0,45.0
452.65381,0.06594115748031495,874.0263416908413,0.00025370340306410486,25.0,45.0
454.05518,0.06627767125984252,871.320115002072,0.00025370340306410486,25.0,45.0
455.45654,0.06654473818897638,871.5958868628263,0.00025370340306410486,25.0,45.0
456.85791,0.06690190157480315,875.4807811852465,0.00025370340306410486,25.0,45.0
458.25928,0.06722457677165354,875.7104486116866,0.00025370340306410486,25.0,45.0
459.66064,0.06756986023622047,876.7194363862411,0.00025370340306410486,25.0,45.0
461.06201,0.0679241811023622,876.1535951098217,0.00025370340306410486,25.0,45.0
462.46338,0.06823249409448819,875.8759324492332,0.00025370340306410486,25.0,45.0
463.86475,0.06852783464566929,875.8109977206796,0.00025370340306410486,25.0,45.0
465.26611,0.06884839173228346,876.9542840861998,0.00025370340306410486,25.0,45.0
466.66748,0.06916399212598424,876.4725704517198,0.00025370340306410486,25.0,45.0
468.06885,0.06947378937007874,878.3374948197264,0.00025370340306410486,25.0,45.0
469.47021,0.06981005708661417,878.9562784915043,0.00025370340306410486,25.0,45.0
470.87158,0.07013489566929133,878.0495234148362,0.00025370340306410486,25.0,45.0
472.27295,0.07044961023622047,876.9135671363448,0.00025370340306410486,25.0,45.0
473.67432,0.07076967322834644,877.4144477828428,0.00025370340306410486,25.0,45.0
475.07568,0.07111975787401575,878.5334127641939,0.00025370340306410486,25.0,45.0
476.47705,0.07147595472440944,881.5279993783671,0.00025370340306410486,25.0,45.0
477.87842,0.07182753346456693,880.7512173642768,0.00025370340306410486,25.0,45.0
479.27979,0.0722638562992126,881.4136189390799,0.00025370340306410486,25.0,45.0
480.68115,0.07260872440944882,881.3026315789473,0.00025370340306410486,25.0,45.0
482.08252,0.07293427952755906,881.6458246995442,0.00025370340306410486,25.0,45.0
483.48389,0.07325505314960629,880.8183019063406,0.00025370340306410486,25.0,45.0
484.88525,0.07358883858267716,881.9957003729796,0.00025370340306410486,25.0,45.0
486.28662,0.07392559842519686,881.0529164939909,0.00025370340306410486,25.0,45.0
487.68799,0.07426385039370079,881.8863707003729,0.00025370340306410486,25.0,45.0
489.08936,0.0746160748031496,884.1975756319933,0.00025370340306410486,25.0,45.0
490.49072,0.07493285236220473,881.3947627434728,0.00025370340306410486,25.0,45.0
491.89209,0.0752446220472441,883.8796881475341,0.00025370340306410486,25.0,45.0
493.29346,0.07561308464566929,884.5127952755905,0.00025370340306410486,25.0,45.0
494.69482,0.07596297440944882,883.8098580605056,0.00025370340306410486,25.0,45.0
496.09619,0.07631651968503937,882.77248238707,0.00025370340306410486,25.0,45.0
497.49756,0.07661931299212599,885.2324906755075,0.00025370340306410486,25.0,45.0
498.89893,0.0769630905511811,886.8996840033153,0.00025370340306410486,25.0,45.0
500.30029,0.0772799094488189,885.5907065893078,0.00025370340306410486,25.0,45.0
501.70166,0.07765047834645669,885.1383133029424,0.00025370340306410486,25.0,45.0
503.10303,0.07798247637795275,886.4307397430583,0.00025370340306410486,25.0,45.0
504.50439,0.07827098818897638,888.0307967260671,0.00025370340306410486,25.0,45.0
505.90576,0.07859249015748032,886.7070814338997,0.00025370340306410486,25.0,45.0
507.30713,0.0789514094488189,887.9945607128055,0.00025370340306410486,25.0,45.0
508.7085,0.07923416732283464,887.4968400331537,0.00025370340306410486,25.0,45.0
510.10986,0.0795803720472441,887.5871322005802,0.00025370340306410486,25.0,45.0
511.51123,0.07995495472440946,889.1577134272688,0.00025370340306410486,25.0,45.0
512.9126,0.08026954527559055,886.4772845006216,0.00025370340306410486,25.0,45.0
514.31396,0.0805921968503937,889.8134583506009,0.00025370340306410486,25.0,45.0
515.71533,0.08091848622047243,889.0234148363033,0.00025370340306410486,25.0,45.0
517.1167,0.08126937204724409,890.8156340654785,0.00025370340306410486,25.0,45.0
518.51807,0.08163181692913385,891.1847285536676,0.00025370340306410486,25.0,45.0
519.91943,0.0819940216535433,891.3617384997928,0.00025370340306410486,25.0,45.0
521.3208,0.08237674606299213,891.4575994612516,0.00025370340306410486,25.0,45.0
522.72217,0.08272127362204724,889.98666079569,0.00025370340306410486,25.0,45.0
524.12354,0.08302353346456692,890.392457521757,0.00025370340306410486,25.0,45.0
525.5249,0.08335415748031497,892.7118731869042,0.00025370340306410486,25.0,45.0
526.92627,0.08371333267716535,893.5267302113551,0.00025370340306410486,25.0,45.0
528.32764,0.08400826377952755,891.4971249481972,0.00025370340306410486,25.0,45.0
529.729,0.08433695275590551,890.2521239121425,0.00025370340306410486,25.0,45.0
531.13037,0.08468693700787401,892.8931050559469,0.00025370340306410486,25.0,45.0
532.53174,0.08506821259842519,893.0550663075011,0.00025370340306410486,25.0,45.0
533.93311,0.08546190748031496,892.6175922088686,0.00025370340306410486,25.0,45.0
535.33447,0.08576000196850393,892.2919343141317,0.00025370340306410486,25.0,45.0
536.73584,0.0860345,893.9060816411105,0.00025370340306410486,25.0,45.0
538.13721,0.0863631594488189,894.944674678823,0.00025370340306410486,25.0,45.0
539.53857,0.0866718188976378,895.6003677994198,0.00025370340306410486,25.0,45.0
540.93994,0.08703432677165354,896.6730211355159,0.00025370340306410486,25.0,45.0
542.34131,0.08738773031496062,897.0944881889762,0.00025370340306410486,25.0,45.0
543.74268,0.0877635688976378,895.6338064649813,0.00025370340306410486,25.0,45.0
545.14404,0.08807755511811023,897.1729693327808,0.00025370340306410486,25.0,45.0
546.54541,0.08842590157480315,897.1729693327808,0.00025370340306410486,25.0,45.0
547.94678,0.08882058858267716,898.4201201823455,0.00025370340306410486,25.0,45.0
549.34814,0.08913534448818898,896.2166649399088,0.00025370340306410486,25.0,45.0
550.74951,0.08951183267716535,897.1589307915458,0.00025370340306410486,25.0,45.0
552.15088,0.08986934251968505,897.780926232905,0.00025370340306410486,25.0,45.0
553.55225,0.09016951968503938,897.5275331537505,0.00025370340306410486,25.0,45.0
554.95361,0.09056586614173229,899.6937422295897,0.00025370340306410486,25.0,45.0
556.35498,0.09090827755905512,898.3603398259428,0.00025370340306410486,25.0,45.0
557.75635,0.09126067125984252,898.3623860339826,0.00025370340306410486,25.0,45.0
559.15771,0.09162246456692913,898.7177527973477,0.00025370340306410486,25.0,45.0
560.55908,0.09195523622047244,899.3198300870285,0.00025370340306410486,25.0,45.0
561.96045,0.09227244291338582,900.3489173228346,0.00025370340306410486,25.0,45.0
563.36182,0.09263614173228346,901.1406444260256,0.00025370340306410486,25.0,45.0
564.76318,0.09298543897637795,901.1424834231248,0.00025370340306410486,25.0,45.0
566.16455,0.09329881692913386,899.8624637380852,0.00025370340306410486,25.0,45.0
567.56592,0.09363442125984252,900.8091587235806,0.00025370340306410486,25.0,45.0
568.96729,0.09394848228346456,902.9873860339826,0.00025370340306410486,25.0,45.0
570.36865,0.09431576181102362,902.8270824699543,0.00025370340306410486,25.0,45.0
571.77002,0.09469135826771653,904.593814753419,0.00025370340306410486,25.0,45.0
573.17139,0.09507875393700788,901.875181309573,0.00025370340306410486,25.0,45.0
574.57275,0.09541531496062992,903.521653543307,0.00025370340306410486,25.0,45.0
575.97412,0.09576772047244093,902.9694104848735,0.00025370340306410486,25.0,45.0
577.37549,0.09612942125984252,902.7171052631578,0.00025370340306410486,25.0,45.0
578.77686,0.09648358661417324,904.2578999171155,0.00025370340306410486,25.0,45.0
580.17822,0.09682684842519684,902.8511707418152,0.00025370340306410486,25.0,45.0
581.57959,0.09718398818897638,901.747461665976,0.00025370340306410486,25.0,45.0
582.98096,0.09752641141732284,904.5307190219643,0.00025370340306410486,25.0,45.0
584.38232,0.09785538582677165,904.2662660588479,0.00025370340306410486,25.0,45.0
585.78369,0.09824228740157481,906.2641939494404,0.00025370340306410486,25.0,45.0
587.18506,0.09858596456692913,904.7692965188561,0.00025370340306410486,25.0,45.0
588.58643,0.09892494881889763,904.2863137173642,0.00025370340306410486,25.0,45.0
589.98779,0.09929013385826771,904.9683744301698,0.00025370340306410486,25.0,45.0
591.38916,0.09969753346456693,908.6565996684625,0.00025370340306410486,25.0,45.0
592.79053,0.10008578543307088,906.3623342312474,0.00025370340306410486,25.0,45.0
594.19189,0.10048192125984252,908.6609510982179,0.00025370340306410486,25.0,45.0
595.59326,0.1008643877952756,906.8454465395773,0.00025370340306410486,25.0,45.0
596.99463,0.10115689566929133,907.2338375466225,0.00025370340306410486,25.0,45.0
598.396,0.10148337204724409,906.5860702445088,0.00025370340306410486,25.0,45.0
599.79736,0.1018521594488189,908.0453532946539,0.00025370340306410486,25.0,45.0
601.19873,0.10217175984251968,906.4931102362203,0.00025370340306410486,25.0,45.0
602.6001,0.10250474803149606,908.1162453377538,0.00025370340306410486,25.0,45.0
604.00146,0.10285952362204723,909.896964359718,0.00025370340306410486,25.0,45.0
605.40283,0.10317662598425198,908.5644426025694,0.00025370340306410486,25.0,45.0
606.8042,0.10351767519685039,909.9138520513882,0.00025370340306410486,25.0,45.0
608.20557,0.10387099606299213,909.1734873601326,0.00025370340306410486,25.0,45.0
609.60693,0.10417914566929133,907.2605936593451,0.00025370340306410486,25.0,45.0
611.0083,0.10453782874015749,909.7706174886033,0.00025370340306410486,25.0,45.0
612.40967,0.10481152952755904,907.0663334024035,0.00025370340306410486,25.0,45.0
613.81104,0.10512980511811024,909.7954569001243,0.00025370340306410486,25.0,45.0
615.2124,0.10544247047244094,910.2280097389141,0.00025370340306410486,25.0,45.0
616.61377,0.10585055118110236,912.5231299212599,0.00025370340306410486,25.0,45.0
618.01514,0.10625350393700787,911.8210215499378,0.00025370340306410486,25.0,45.0
619.4165,0.10664609645669292,911.9382770410276,0.00025370340306410486,25.0,45.0
620.81787,0.10701153937007875,912.1014815582263,0.00025370340306410486,25.0,45.0
622.21924,0.10736953149606299,913.028387898881,0.00025370340306410486,25.0,45.0
623.62061,0.10773174606299213,910.8775642353916,0.00025370340306410486,25.0,45.0
625.02197,0.10809759842519684,908.9474202237877,0.00025370340306410486,25.0,45.0
626.42334,0.1084535846456693,913.785951098218,0.00025370340306410486,25.0,45.0
627.82471,0.10883284842519685,914.000440323249,0.00025370340306410486,25.0,45.0
629.22607,0.10925804724409449,913.9430428926647,0.00025370340306410486,25.0,45.0
630.62744,0.10966994094488189,913.7690634065478,0.00025370340306410486,25.0,45.0
632.02881,0.11004885433070866,914.5205656858682,0.00025370340306410486,25.0,45.0
633.43018,0.11038865944881888,911.5990209283049,0.00025370340306410486,25.0,45.0
634.83154,0.11072717322834646,913.4647741400745,0.00025370340306410486,25.0,45.0
636.23291,0.11104843897637796,913.7419446746787,0.00025370340306410486,25.0,45.0
637.63428,0.11139882874015748,914.8121373808536,0.00025370340306410486,25.0,45.0
639.03564,0.11173907874015748,915.0333350600911,0.00025370340306410486,25.0,45.0
640.43701,0.11211380314960631,914.9547503108164,0.00025370340306410486,25.0,45.0
641.83838,0.1124955059055118,917.1257511396601,0.00025370340306410486,25.0,45.0
643.23975,0.11287871259842519,915.6534397016161,0.00025370340306410486,25.0,45.0
644.64111,0.11319545078740158,914.6545016576874,0.00025370340306410486,25.0,45.0
646.04248,0.11356604330708661,915.6374326564442,0.00025370340306410486,25.0,45.0
647.44385,0.11393207283464567,916.0962753833402,0.00025370340306410486,25.0,45.0
648.84521,0.11426883858267717,915.5834283050145,0.00025370340306410486,25.0,45.0
650.24658,0.11462096456692913,917.2772741400746,0.00025370340306410486,25.0,45.0
651.64795,0.11502933858267717,915.7225445503523,0.00025370340306410486,25.0,45.0
653.04932,0.11538389173228347,917.8039007459594,0.00025370340306410486,25.0,45.0
654.45068,0.11573591141732284,919.2582625362618,0.00025370340306410486,25.0,45.0
655.85205,0.11606006496062993,917.0874948197264,0.00025370340306410486,25.0,45.0
657.25342,0.11642501377952755,918.3437888520514,0.00025370340306410486,25.0,45.0
658.65479,0.11677793700787402,917.8370803978449,0.00025370340306410486,25.0,45.0
660.05615,0.11719654133858268,920.5479434314132,0.00025370340306410486,25.0,45.0
661.45752,0.11757364566929134,917.9091121011189,0.00025370340306410486,25.0,45.0
662.85889,0.11794998818897638,918.5137277248238,0.00025370340306410486,25.0,45.0
664.26025,0.11831712007874015,918.6272275176128,0.00025370340306410486,25.0,45.0
665.66162,0.1186731535433071,919.4720006216328,0.00025370340306410486,25.0,45.0
667.06299,0.11900161220472441,919.6128781599668,0.00025370340306410486,25.0,45.0
668.46436,0.11938781102362206,918.5249689183588,0.00025370340306410486,25.0,45.0
669.86572,0.11975771062992126,919.7884117281392,0.00025370340306410486,25.0,45.0
671.26709,0.12011816732283465,917.3172917530045,0.00025370340306410486,25.0,45.0
672.66846,0.120532312992126,921.836510567758,0.00025370340306410486,25.0,45.0
674.06982,0.12092759251968505,920.0077186075424,0.00025370340306410486,25.0,45.0
675.47119,0.12128166535433071,918.3754144218814,0.00025370340306410486,25.0,45.0
676.87256,0.12168622637795276,922.7076253626191,0.00025370340306410486,25.0,45.0
678.27393,0.12211354921259841,921.050740779113,0.00025370340306410486,25.0,45.0
679.67529,0.12244271259842521,920.4172451305428,0.00025370340306410486,25.0,45.0
681.07666,0.12282092125984251,922.65522689598,0.00025370340306410486,25.0,45.0
682.47803,0.12324825590551179,922.5971042271032,0.00025370340306410486,25.0,45.0
683.87939,0.12356181299212599,922.1546311645255,0.00025370340306410486,25.0,45.0
685.28076,0.12392379330708661,922.5114743058433,0.00025370340306410486,25.0,45.0
686.68213,0.12429030314960629,923.3607283464565,0.00025370340306410486,25.0,45.0
688.0835,0.12468622834645669,923.1464204309988,0.00025370340306410486,25.0,45.0
689.48486,0.12512577755905513,923.4643856195606,0.00025370340306410486,25.0,45.0
690.88623,0.1255138779527559,921.6418617903024,0.00025370340306410486,25.0,45.0
692.2876,0.12588213582677166,923.3466380024864,0.00025370340306410486,25.0,45.0
693.68896,0.12623309842519684,922.924730625777,0.00025370340306410486,25.0,45.0
695.09033,0.1266419645669291,924.5284397016162,0.00025370340306410486,25.0,45.0
696.4917,0.12700171653543307,924.615908619975,0.00025370340306410486,25.0,45.0
697.89307,0.12743000196850393,925.1950113966018,0.00025370340306410486,25.0,45.0
699.29443,0.12785147047244094,924.3513779527558,0.00025370340306410486,25.0,45.0
700.6958,0.12823184842519686,924.0656340654785,0.00025370340306410486,25.0,45.0
702.09717,0.12862379724409448,924.9475756319933,0.00025370340306410486,25.0,45.0
703.49854,0.12903824803149605,925.0380750103606,0.00025370340306410486,25.0,45.0
704.8999,0.1293913346456693,925.1514452963116,0.00025370340306410486,25.0,45.0
706.30127,0.129796624015748,926.8225756319933,0.00025370340306410486,25.0,45.0
707.70264,0.1301947657480315,925.2303149606298,0.00025370340306410486,25.0,45.0
709.104,0.13058013188976378,925.1740830915871,0.00025370340306410486,25.0,45.0
710.50537,0.13095826771653543,925.9028698715292,0.00025370340306410486,25.0,45.0
711.90674,0.1313089744094488,926.2027300041441,0.00025370340306410486,25.0,45.0
713.30811,0.1317503405511811,924.4372668876916,0.00025370340306410486,25.0,45.0
714.70947,0.13211565551181104,924.6394270617488,0.00025370340306410486,25.0,45.0
716.11084,0.1324648346456693,925.7944208454206,0.00025370340306410486,25.0,45.0
717.51221,0.13282715551181104,925.9210267302113,0.00025370340306410486,25.0,45.0
718.91357,0.13323988188976377,925.7556723995026,0.00025370340306410486,25.0,45.0
720.31494,0.13361037007874016,928.5724461251554,0.00025370340306410486,25.0,45.0
721.71631,0.13398142125984253,927.5279216742643,0.00025370340306410486,25.0,45.0
723.11768,0.13438853937007875,927.5988655200995,0.00025370340306410486,25.0,45.0
724.51904,0.13477290748031495,926.8497720679652,0.00025370340306410486,25.0,45.0
725.92041,0.13521301968503938,926.8363551595523,0.00025370340306410486,25.0,45.0
727.32178,0.13563642322834646,926.1348166183174,0.00025370340306410486,25.0,45.0
728.72314,0.1359945433070866,926.9201460837131,0.00025370340306410486,25.0,45.0
730.12451,0.1363650905511811,927.1207262743472,0.00025370340306410486,25.0,45.0
731.52588,0.13676973228346456,929.697342519685,0.00025370340306410486,25.0,45.0
732.92725,0.13714648622047243,927.078248031496,0.00025370340306410486,25.0,45.0
734.32861,0.13759607874015747,929.7770669291339,0.00025370340306410486,25.0,45.0
735.72998,0.1379793562992126,928.6108837546622,0.00025370340306410486,25.0,45.0
737.13135,0.13842018307086612,930.096223580605,0.00025370340306410486,25.0,45.0
738.53271,0.13880247440944882,928.3448508081226,0.00025370340306410486,25.0,45.0
739.93408,0.13916395078740157,928.611401782014,0.00025370340306410486,25.0,45.0
741.33545,0.13954529133858268,930.2036106506423,0.00025370340306410486,25.0,45.0
742.73682,0.13995242125984253,928.9019633236635,0.00025370340306410486,25.0,45.0
744.13818,0.14045697244094488,930.283723580605,0.00025370340306410486,25.0,45.0
745.53955,0.14088081102362204,928.0912246166597,0.00025370340306410486,25.0,45.0
746.94092,0.14132159251968504,930.0014504765851,0.00025370340306410486,25.0,45.0
748.34229,0.14173228937007873,929.9086199751347,0.00025370340306410486,25.0,45.0
749.74365,0.14212766338582677,928.6742384997926,0.00025370340306410486,25.0,45.0
751.14502,0.14252540551181103,930.0846456692914,0.00025370340306410486,25.0,45.0
752.54639,0.1428364527559055,928.5212909241608,0.00025370340306410486,25.0,45.0
753.94775,0.14321619881889763,931.830605055947,0.00025370340306410486,25.0,45.0
755.34912,0.14365683858267717,931.7297969332781,0.00025370340306410486,25.0,45.0
756.75049,0.14408681299212597,929.4696176958142,0.00025370340306410486,25.0,45.0
758.15186,0.14449963385826772,932.3066462909242,0.00025370340306410486,25.0,45.0
759.55322,0.14496267322834647,931.925818483216,0.00025370340306410486,25.0,45.0
760.95459,0.14537437992125984,932.3863707003729,0.00025370340306410486,25.0,45.0
762.35596,0.14578521653543305,930.9513054289266,0.00025370340306410486,25.0,45.0
763.75732,0.1461497913385827,930.3906444260257,0.00025370340306410486,25.0,45.0
765.15869,0.14655043307086615,931.8023207625362,0.00025370340306410486,25.0,45.0
766.56006,0.1469646496062992,930.8572834645669,0.00025370340306410486,25.0,45.0
767.96143,0.14735970669291337,931.7165095317032,0.00025370340306410486,25.0,45.0
769.36279,0.14774414566929134,930.7634428097804,0.00025370340306410486,25.0,45.0
770.76416,0.1481774527559055,932.8252952755905,0.00025370340306410486,25.0,45.0
772.16553,0.148609937007874,932.806335474513,0.00025370340306410486,25.0,45.0
773.56689,0.14901477952755907,930.5313665561541,0.00025370340306410486,25.0,45.0
774.96826,0.14944848622047244,933.7526419394944,0.00025370340306410486,25.0,45.0
776.36963,0.14985775196850393,931.9091380024864,0.00025370340306410486,25.0,45.0
777.771,0.15020855118110238,932.6525331537505,0.00025370340306410486,25.0,45.0
779.17236,0.1506424094488189,932.0318068794031,0.00025370340306410486,25.0,45.0
780.57373,0.1511388405511811,932.1797813924575,0.00025370340306410486,25.0,45.0
781.9751,0.15157070472440945,932.4835008288437,0.00025370340306410486,25.0,45.0
783.37646,0.1520029901574803,933.9306620389557,0.00025370340306410486,25.0,45.0
784.77783,0.15250898425196852,934.3457314546208,0.00025370340306410486,25.0,45.0
786.1792,0.15293656692913385,932.8249067550767,0.00025370340306410486,25.0,45.0
787.58057,0.15334105708661416,933.5258754662245,0.00025370340306410486,25.0,45.0
788.98193,0.15375536811023624,933.6873963945295,0.00025370340306410486,25.0,45.0
790.3833,0.154112937007874,932.7709801077497,0.00025370340306410486,25.0,45.0
791.78467,0.154582687007874,935.0436179030252,0.00025370340306410486,25.0,45.0
793.18604,0.15497470472440944,932.3688613758806,0.00025370340306410486,25.0,45.0
794.5874,0.15539137401574804,932.9668203481144,0.00025370340306410486,25.0,45.0
795.98877,0.15578269881889764,933.7368421052631,0.00025370340306410486,25.0,45.0
797.39014,0.15624645472440946,934.2188147534189,0.00025370340306410486,25.0,45.0
798.7915,0.1567230098425197,934.9883961873186,0.00025370340306410486,25.0,45.0
800.19287,0.15718144881889765,933.3044446746788,0.00025370340306410486,25.0,45.0
801.59424,0.15757967322834646,931.3381164525487,0.00025370340306410486,25.0,45.0
802.99561,0.157987812992126,934.8822264815582,0.00025370340306410486,25.0,45.0
804.39697,0.15844216929133859,934.0918980522172,0.00025370340306410486,25.0,45.0
805.79834,0.15890225196850394,933.4288230418566,0.00025370340306410486,25.0,45.0
807.19971,0.1594163307086614,937.7201875259013,0.00025370340306410486,25.0,45.0
808.60107,0.15991741929133857,934.2133754662246,0.00025370340306410486,25.0,45.0
810.00244,0.16033777362204724,933.7189960629921,0.00025370340306410486,25.0,45.0
811.40381,0.16073700787401576,935.0107231661831,0.00025370340306410486,25.0,45.0
812.80518,0.161184687007874,935.2632874015748,0.00025370340306410486,25.0,45.0
814.20654,0.1616440649606299,933.9427320762535,0.00025370340306410486,25.0,45.0
815.60791,0.16207541338582676,933.6483112308329,0.00025370340306410486,25.0,45.0
817.00928,0.16253956692913385,934.9124015748031,0.00025370340306410486,25.0,45.0
818.41064,0.16298742322834647,934.7894736842104,0.00025370340306410486,25.0,45.0
819.81201,0.16345205708661417,935.4649554496476,0.00025370340306410486,25.0,45.0
821.21338,0.1639511062992126,934.2446125155408,0.00025370340306410486,25.0,45.0
822.61475,0.16441415551181102,933.9290043514297,0.00025370340306410486,25.0,45.0
824.01611,0.16485573425196848,937.0307967260671,0.00025370340306410486,25.0,45.0
825.41748,0.16533764173228346,935.7612670949026,0.00025370340306410486,25.0,45.0
826.81885,0.16577101771653543,936.1783827186075,0.00025370340306410486,25.0,45.0
828.22021,0.1661817972440945,934.8845058019062,0.00025370340306410486,25.0,45.0
829.62158,0.16659105118110237,934.3585008288436,0.00025370340306410486,25.0,45.0
831.02295,0.16702676377952758,936.9100704517198,0.00025370340306410486,25.0,45.0
832.42432,0.16748727952755907,936.5703740157479,0.00025370340306410486,25.0,45.0
833.82568,0.16794323228346456,936.6684624948197,0.00025370340306410486,25.0,45.0
835.22705,0.16839358661417322,936.0486686697056,0.00025370340306410486,25.0,45.0
836.62842,0.1688790964566929,936.8606765437214,0.00025370340306410486,25.0,45.0
838.02979,0.1693142440944882,936.6196384169083,0.00025370340306410486,25.0,45.0
839.43115,0.16982824015748033,936.1162194363861,0.00025370340306410486,25.0,45.0
840.83252,0.17023653346456694,936.5384376295068,0.00025370340306410486,25.0,45.0
842.23389,0.17073036023622046,937.272352880232,0.00025370340306410486,25.0,45.0
843.63525,0.17122255511811024,936.8138986738498,0.00025370340306410486,25.0,45.0
845.03662,0.17173815944881887,937.1717519685039,0.00025370340306410486,25.0,45.0
846.43799,0.17225948818897638,937.2309883961873,0.00025370340306410486,25.0,45.0
847.83936,0.1726645531496063,935.1511085785329,0.00025370340306410486,25.0,45.0
849.24072,0.17313540748031495,936.6766732283464,0.00025370340306410486,25.0,45.0
850.64209,0.17372321653543307,937.4339774140075,0.00025370340306410486,25.0,45.0
852.04346,0.17426451574803148,936.0673953584749,0.00025370340306410486,25.0,45.0
853.44482,0.1747860688976378,935.5554289266473,0.00025370340306410486,25.0,45.0
854.84619,0.1752341594488189,936.4607853294654,0.00025370340306410486,25.0,45.0
856.24756,0.17567329724409447,935.2942136344799,0.00025370340306410486,25.0,45.0
857.64893,0.1761751968503937,936.1783050145046,0.00025370340306410486,25.0,45.0
859.05029,0.1766696811023622,937.3085111893907,0.00025370340306410486,25.0,45.0
860.45166,0.17722153937007873,936.581174886034,0.00025370340306410486,25.0,45.0
861.85303,0.17767902952755907,935.8665043514297,0.00025370340306410486,25.0,45.0
863.25439,0.17813405511811023,936.0694933692498,0.00025370340306410486,25.0,45.0
864.65576,0.17860399212598424,938.1981195607127,0.00025370340306410486,25.0,45.0
866.05713,0.17902666929133856,938.376010153336,0.00025370340306410486,25.0,45.0
867.4585,0.17956812007874015,938.7927890592623,0.00025370340306410486,25.0,45.0
868.85986,0.18012860433070865,938.2926595524243,0.00025370340306410486,25.0,45.0
870.26123,0.18064390157480315,935.8004040613343,0.00025370340306410486,25.0,45.0
871.6626,0.18118837007874014,937.7248756734355,0.00025370340306410486,25.0,45.0
873.06396,0.18166227362204723,937.113188976378,0.00025370340306410486,25.0,45.0
874.46533,0.18215453937007875,937.5765903439701,0.00025370340306410486,25.0,45.0
875.8667,0.18267229133858268,939.358992954828,0.00025370340306410486,25.0,45.0
877.26807,0.18315303543307088,938.5320140903439,0.00025370340306410486,25.0,45.0
878.66943,0.18376454527559055,938.8397741400745,0.00025370340306410486,25.0,45.0
880.0708,0.18424086614173227,935.555636137588,0.00025370340306410486,25.0,45.0
881.47217,0.18471044094488187,937.5934003315374,0.00025370340306410486,25.0,45.0
882.87354,0.18519931692913386,936.7636759220886,0.00025370340306410486,25.0,45.0
884.2749,0.18568922440944882,938.0815893079154,0.00025370340306410486,25.0,45.0
885.67627,0.18618454133858267,937.630076668048,0.00025370340306410486,25.0,45.0
886.07666,0.18638589566929134,940.4562007874016,0.00025370340306410486,25.0,45.0