File: datasets/am_bench_2022/csv/45-XY.13-1.csv
Time(s),Strain(%),Stress(MPa),SR(s-1),Temp(C),Angle(deg)
31.101563,2.9676840551181103e-05,17.97501207635372,0.00025370340306410486,25.0,45.0
32.50293,5.53130157480315e-05,22.559482664589016,0.00025370340306410486,25.0,45.0
33.904297,4.853547834645669e-05,25.95437189975328,0.00025370340306410486,25.0,45.0
35.305664,7.192430708661418e-05,31.595462926892615,0.00025370340306410486,25.0,45.0
36.707031,0.00010698688385826771,37.43399558498896,0.00025370340306410486,25.0,45.0
38.108398,0.00012765082086614173,43.003578756005716,0.00025370340306410486,25.0,45.0
39.509766,0.00014460816732283463,49.62233476171926,0.00025370340306410486,25.0,45.0
40.911133,0.0001828070255905512,57.934727957408136,0.00025370340306410486,25.0,45.0
42.3125,0.00020428872047244094,65.17618231398521,0.00025370340306410486,25.0,45.0
43.713867,0.000219346594488189,73.98297104272172,0.00025370340306410486,25.0,45.0
45.115234,0.0002611171062992126,81.99758213219063,0.00025370340306410486,25.0,45.0
46.516602,0.00030854070866141736,90.50163874821452,0.00025370340306410486,25.0,45.0
47.917969,0.00031133094488188976,98.17804960394754,0.00025370340306410486,25.0,45.0
49.319336,0.0003645560039370079,108.19811712764576,0.00025370340306410486,25.0,45.0
50.720703,0.0003879545275590551,119.16624853915077,0.00025370340306410486,25.0,45.0
52.12207,0.00042573633858267716,129.83437995065577,0.00025370340306410486,25.0,45.0
53.523438,0.000472354842519685,139.36140241527076,0.00025370340306410486,25.0,45.0
54.924805,0.0004994406102362205,149.43495390209063,0.00025370340306410486,25.0,45.0
56.326172,0.0005164132874015748,159.01824178678095,0.00025370340306410486,25.0,45.0
57.727539,0.0005597188582677166,168.7160238930009,0.00025370340306410486,25.0,45.0
59.128906,0.0005996512401574803,178.8547876899104,0.00025370340306410486,25.0,45.0
60.530273,0.0006390358858267717,188.1544500714193,0.00025370340306410486,25.0,45.0
61.931641,0.0006465684448818898,195.55660823269707,0.00025370340306410486,25.0,45.0
63.333008,0.0006849808858267717,206.1465783664459,0.00025370340306410486,25.0,45.0
64.734375,0.0007319986811023622,217.07362160758345,0.00025370340306410486,25.0,45.0
66.135742,0.0007433532086614173,228.1806726399169,0.00025370340306410486,25.0,45.0
67.537109,0.0007794934448818898,238.52328269055968,0.00025370340306410486,25.0,45.0
68.938477,0.0008318150590551181,248.7040358395014,0.00025370340306410486,25.0,45.0
70.339844,0.0008712287992125984,258.149339046877,0.00025370340306410486,25.0,45.0
71.741211,0.0009177448818897638,268.3904168289833,0.00025370340306410486,25.0,45.0
73.142578,0.0009449142913385827,280.62236073237244,0.00025370340306410486,25.0,45.0
74.543945,0.0009638215157480314,290.1164524087781,0.00025370340306410486,25.0,45.0
75.945313,0.0010067311023622047,300.0115569406571,0.00025370340306410486,25.0,45.0
77.34668,0.0010293858070866142,311.0827684716271,0.00025370340306410486,25.0,45.0
78.748047,0.0010700063188976378,322.77200363589145,0.00025370340306410486,25.0,45.0
80.149414,0.0011098432677165355,335.3901571224516,0.00025370340306410486,25.0,45.0
81.550781,0.0011515268307086613,343.4771588105441,0.00025370340306410486,25.0,45.0
82.952148,0.0011819955708661416,354.60729775353855,0.00025370340306410486,25.0,45.0
84.353516,0.0012122608858267717,363.6563563173614,0.00025370340306410486,25.0,45.0
85.754883,0.0012472395669291337,375.58509284508506,0.00025370340306410486,25.0,45.0
87.15625,0.001281148877952756,384.7216725100636,0.00025370340306410486,25.0,45.0
88.557617,0.0013124392913385825,393.90673938449555,0.00025370340306410486,25.0,45.0
89.958984,0.001364968188976378,405.3924425399299,0.00025370340306410486,25.0,45.0
91.360352,0.0013817684645669292,413.91795870666147,0.00025370340306410486,25.0,45.0
92.761719,0.001410389035433071,423.88715751201147,0.00025370340306410486,25.0,45.0
94.163086,0.0014426801771653544,433.2628749513051,0.00025370340306410486,25.0,45.0
95.564453,0.0014807522047244094,443.5319568887158,0.00025370340306410486,25.0,45.0
96.96582,0.0015190180118110235,453.0618101545254,0.00025370340306410486,25.0,45.0
98.367188,0.001537248188976378,460.8011427087392,0.00025370340306410486,25.0,45.0
99.768555,0.0016078638976377954,471.3998701467342,0.00025370340306410486,25.0,45.0
101.16992,0.0016323212007874014,482.1834047526296,0.00025370340306410486,25.0,45.0
102.57129,0.0016582163582677164,491.81750422023117,0.00025370340306410486,25.0,45.0
103.97266,0.0016831262992125983,499.86716010907674,0.00025370340306410486,25.0,45.0
105.37402,0.0017278197047244093,508.47110764835736,0.00025370340306410486,25.0,45.0
106.77539,0.0017625079921259844,518.873133359304,0.00025370340306410486,25.0,45.0
108.17676,0.00177756718503937,526.4242565900532,0.00025370340306410486,25.0,45.0
109.57813,0.0018083846062992126,533.7378781976367,0.00025370340306410486,25.0,45.0
110.97949,0.0018663533858267714,543.1061420594729,0.00025370340306410486,25.0,45.0
112.38086,0.0018763324803149606,547.0633683937152,0.00025370340306410486,25.0,45.0
113.78223,0.0018905641141732286,554.4931567328919,0.00025370340306410486,25.0,45.0
115.18359,0.0019296076181102362,561.4900921958188,0.00025370340306410486,25.0,45.0
116.58496,0.0019675225196850396,567.430619400078,0.00025370340306410486,25.0,45.0
117.98633,0.001985102559055118,572.9644721464746,0.00025370340306410486,25.0,45.0
119.3877,0.0020013773622047245,578.9815348656018,0.00025370340306410486,25.0,45.0
120.78906,0.0020452574803149605,585.6081028437866,0.00025370340306410486,25.0,45.0
122.19043,0.0020749582677165356,591.5561875081158,0.00025370340306410486,25.0,45.0
123.5918,0.0021113283464566928,598.0382547721075,0.00025370340306410486,25.0,45.0
124.99316,0.0021242041338582675,604.2111154395534,0.00025370340306410486,25.0,45.0
126.39453,0.0021567096456692916,607.4545903129465,0.00025370340306410486,25.0,45.0
127.7959,0.0021886141732283463,613.3797169198806,0.00025370340306410486,25.0,45.0
129.19727,0.0022198232283464564,616.5980262303598,0.00025370340306410486,25.0,45.0
130.59863,0.002258419094488189,621.8587975587586,0.00025370340306410486,25.0,45.0
132.0,0.002282457283464567,626.9332813920271,0.00025370340306410486,25.0,45.0
133.40137,0.002309975787401575,632.1236722503571,0.00025370340306410486,25.0,45.0
134.80273,0.0023452659448818898,636.7137514608493,0.00025370340306410486,25.0,45.0
136.2041,0.0023910232283464567,640.1094663030776,0.00025370340306410486,25.0,45.0
137.60547,0.0024205279527559054,645.3412543825477,0.00025370340306410486,25.0,45.0
139.00684,0.002450884448818898,649.6599402674979,0.00025370340306410486,25.0,45.0
140.4082,0.002486248622047244,653.5526814699391,0.00025370340306410486,25.0,45.0
141.80957,0.0024967956692913385,655.8002077652253,0.00025370340306410486,25.0,45.0
143.21094,0.0025429675196850395,659.7476171925724,0.00025370340306410486,25.0,45.0
144.6123,0.00259138405511811,663.2677834047527,0.00025370340306410486,25.0,45.0
146.01367,0.002632108464566929,667.4594208544345,0.00025370340306410486,25.0,45.0
147.41504,0.0026927482283464568,670.6455784962992,0.00025370340306410486,25.0,45.0
148.81641,0.002724070472440945,673.976418646929,0.00025370340306410486,25.0,45.0
150.21777,0.002784756102362205,680.2520451889366,0.00025370340306410486,25.0,45.0
151.61914,0.0028056120078740155,680.3836125178549,0.00025370340306410486,25.0,45.0
153.02051,0.002865018503937008,684.7364238410596,0.00025370340306410486,25.0,45.0
154.42188,0.0028989281496062994,685.6684846123879,0.00025370340306410486,25.0,45.0
155.82324,0.0029590726377952755,692.0104921438775,0.00025370340306410486,25.0,45.0
157.22461,0.0029978120078740155,692.99696143358,0.00025370340306410486,25.0,45.0
158.62598,0.0030607901574803147,694.3971951694585,0.00025370340306410486,25.0,45.0
160.02734,0.0031278858267716533,698.6548240488248,0.00025370340306410486,25.0,45.0
161.42871,0.003201156692913386,701.914348785872,0.00025370340306410486,25.0,45.0
162.83008,0.0032752513779527558,705.2106999091027,0.00025370340306410486,25.0,45.0
164.23145,0.0033353557086614172,706.774003376185,0.00025370340306410486,25.0,45.0
165.63281,0.003424716929133858,709.6292689261135,0.00025370340306410486,25.0,45.0
167.03418,0.0035152314960629925,712.871679002727,0.00025370340306410486,25.0,45.0
168.43555,0.003592712401574803,714.4207245812232,0.00025370340306410486,25.0,45.0
169.83691,0.003694437401574803,717.8921958187249,0.00025370340306410486,25.0,45.0
171.23828,0.0038088724409448813,720.1854824048826,0.00025370340306410486,25.0,45.0
172.63965,0.003922964960629921,722.0571354369563,0.00025370340306410486,25.0,45.0
174.04102,0.004034108070866142,724.0975717439295,0.00025370340306410486,25.0,45.0
175.44238,0.0041621135826771655,727.5047656148552,0.00025370340306410486,25.0,45.0
176.84375,0.004275472440944882,730.2406700428517,0.00025370340306410486,25.0,45.0
178.24512,0.0043997222440944886,730.2469029996105,0.00025370340306410486,25.0,45.0
179.64648,0.004576285236220472,735.8429554603299,0.00025370340306410486,25.0,45.0
181.04785,0.0047237454724409446,735.8512660693417,0.00025370340306410486,25.0,45.0
182.44922,0.004872675393700787,737.4074016361512,0.00025370340306410486,25.0,45.0
183.85059,0.005048549803149606,738.3626022594468,0.00025370340306410486,25.0,45.0
185.25195,0.0051887852362204724,740.7870666147254,0.00025370340306410486,25.0,45.0
186.65332,0.0053472545275590555,742.9641345279833,0.00025370340306410486,25.0,45.0
188.05469,0.005576428149606299,744.9661602389301,0.00025370340306410486,25.0,45.0
189.45605,0.005777152362204724,745.310011686794,0.00025370340306410486,25.0,45.0
190.85742,0.005924358858267717,745.7978963770939,0.00025370340306410486,25.0,45.0
192.25879,0.006143137204724409,748.9524996753669,0.00025370340306410486,25.0,45.0
193.66016,0.006337515157480315,749.0077132839891,0.00025370340306410486,25.0,45.0
195.06152,0.006550560039370079,751.369042981431,0.00025370340306410486,25.0,45.0
196.46289,0.006799749606299213,753.6883261914038,0.00025370340306410486,25.0,45.0
197.86426,0.007038287007874016,754.2201012855473,0.00025370340306410486,25.0,45.0
199.26563,0.00725561437007874,755.9394624074796,0.00025370340306410486,25.0,45.0
200.66699,0.007496428149606299,757.1284248798858,0.00025370340306410486,25.0,45.0
202.06836,0.007749100196850394,756.5192832099727,0.00025370340306410486,25.0,45.0
203.46973,0.008090501968503937,759.3756914686404,0.00025370340306410486,25.0,45.0
204.87109,0.008336498622047245,760.6549539020906,0.00025370340306410486,25.0,45.0
206.27246,0.00859559409448819,764.456122581483,0.00025370340306410486,25.0,45.0
207.67383,0.008901204921259842,764.235423970913,0.00025370340306410486,25.0,45.0
209.0752,0.009177344291338582,765.3824178678094,0.00025370340306410486,25.0,45.0
210.47656,0.009461885433070865,765.7828853395663,0.00025370340306410486,25.0,45.0
211.87793,0.009751721062992127,767.4305155174653,0.00025370340306410486,25.0,45.0
213.2793,0.01005703562992126,768.3994805869369,0.00025370340306410486,25.0,45.0
214.68066,0.010361021653543306,770.0289832489287,0.00025370340306410486,25.0,45.0
216.08203,0.010643966141732283,770.3328658615765,0.00025370340306410486,25.0,45.0
217.4834,0.010915886023622047,770.0438124918842,0.00025370340306410486,25.0,45.0
218.88477,0.011187706102362204,771.605609661083,0.00025370340306410486,25.0,45.0
220.28613,0.011515365748031496,773.1654330606415,0.00025370340306410486,25.0,45.0
221.6875,0.01180763622047244,774.3991689390989,0.00025370340306410486,25.0,45.0
223.08887,0.012119524409448818,775.8654720166212,0.00025370340306410486,25.0,45.0
224.49023,0.01243858307086614,776.5384495520062,0.00025370340306410486,25.0,45.0
225.8916,0.012723538385826771,776.4621737436697,0.00025370340306410486,25.0,45.0
227.29297,0.013034562007874015,777.5017530190885,0.00025370340306410486,25.0,45.0
228.69434,0.013352604921259843,777.171276457603,0.00025370340306410486,25.0,45.0
230.0957,0.013669435039370079,778.2239968835216,0.00025370340306410486,25.0,45.0
231.49707,0.013976312401574804,780.1109206596547,0.00025370340306410486,25.0,45.0
232.89844,0.01426641712598425,782.0722243864433,0.00025370340306410486,25.0,45.0
234.2998,0.01463574311023622,782.7803402155564,0.00025370340306410486,25.0,45.0
235.70117,0.014948947637795274,782.0144656538112,0.00025370340306410486,25.0,45.0
237.10254,0.015228049606299213,783.4528243085315,0.00025370340306410486,25.0,45.0
238.50391,0.015545322637795275,784.1267367874303,0.00025370340306410486,25.0,45.0
239.90527,0.01588768838582677,786.4858589793533,0.00025370340306410486,25.0,45.0
241.30664,0.01625812598425197,786.161667315933,0.00025370340306410486,25.0,45.0
242.70801,0.016587740944881888,787.3989352032205,0.00025370340306410486,25.0,45.0
244.10938,0.016946574409448818,786.8819374107259,0.00025370340306410486,25.0,45.0
245.51074,0.017342005118110237,788.9725230489547,0.00025370340306410486,25.0,45.0
246.91211,0.017696878543307086,789.1030255810934,0.00025370340306410486,25.0,45.0
248.31348,0.018018173228346458,789.0768991040125,0.00025370340306410486,25.0,45.0
249.71484,0.018329069291338585,789.8018698870277,0.00025370340306410486,25.0,45.0
251.11621,0.0186887562992126,790.8977535385015,0.00025370340306410486,25.0,45.0
252.51758,0.019017992716535433,792.1633813790418,0.00025370340306410486,25.0,45.0
253.91895,0.01934491338582677,791.5554603298274,0.00025370340306410486,25.0,45.0
255.32031,0.01967274468503937,791.6265939488378,0.00025370340306410486,25.0,45.0
256.72168,0.019986141732283465,794.3576418646929,0.00025370340306410486,25.0,45.0
258.12305,0.02031246062992126,794.5312297104273,0.00025370340306410486,25.0,45.0
259.52441,0.020639124015748033,795.0869757174393,0.00025370340306410486,25.0,45.0
260.92578,0.020981816929133857,796.050357096481,0.00025370340306410486,25.0,45.0
262.32715,0.02132605118110236,797.1586027788599,0.00025370340306410486,25.0,45.0
263.72852,0.021651338582677166,796.7373587845734,0.00025370340306410486,25.0,45.0
265.12988,0.02195407874015748,796.8148811842618,0.00025370340306410486,25.0,45.0
266.53125,0.02228181692913386,799.3115958966368,0.00025370340306410486,25.0,45.0
267.93262,0.022624094488188976,797.2884041033632,0.00025370340306410486,25.0,45.0
269.33398,0.02294056496062992,799.4696532917803,0.00025370340306410486,25.0,45.0
270.73535,0.02331423622047244,800.5576938059993,0.00025370340306410486,25.0,45.0
272.13672,0.02366832086614173,799.5188676795221,0.00025370340306410486,25.0,45.0
273.53809,0.02399596062992126,802.4400467471758,0.00025370340306410486,25.0,45.0
274.93945,0.024384529527559054,802.8783794312428,0.00025370340306410486,25.0,45.0
276.34082,0.024760960629921263,803.6714452668485,0.00025370340306410486,25.0,45.0
277.74219,0.025072980314960632,802.3730944033243,0.00025370340306410486,25.0,45.0
279.14355,0.025403555118110235,804.1757693806,0.00025370340306410486,25.0,45.0
280.54492,0.02579004724409449,805.0424360472666,0.00025370340306410486,25.0,45.0
281.94629,0.026159647637795276,804.9421373847553,0.00025370340306410486,25.0,45.0
283.34766,0.02653000590551181,805.9416439423452,0.00025370340306410486,25.0,45.0
284.74902,0.026874011811023623,806.8289313076225,0.00025370340306410486,25.0,45.0
286.15039,0.02726001377952756,806.4653681340086,0.00025370340306410486,25.0,45.0
287.55176,0.02756890157480315,805.9913517724972,0.00025370340306410486,25.0,45.0
288.95313,0.027940244094488188,808.454382547721,0.00025370340306410486,25.0,45.0
290.35449,0.028291559055118112,808.6781456953643,0.00025370340306410486,25.0,45.0
291.75586,0.028630938976377956,808.88484612388,0.00025370340306410486,25.0,45.0
293.15723,0.028960990157480316,809.3390209063758,0.00025370340306410486,25.0,45.0
294.55859,0.029318301181102364,809.7004285157772,0.00025370340306410486,25.0,45.0
295.95996,0.029676606299212597,810.2370860927152,0.00025370340306410486,25.0,45.0
297.36133,0.02997738779527559,810.3389170237632,0.00025370340306410486,25.0,45.0
298.7627,0.03028651377952756,811.9110245422672,0.00025370340306410486,25.0,45.0
300.16406,0.030666814960629923,812.9274120244124,0.00025370340306410486,25.0,45.0
301.56543,0.030997114173228348,812.8835995325283,0.00025370340306410486,25.0,45.0
302.9668,0.03129105905511811,812.5838722243866,0.00025370340306410486,25.0,45.0
304.36816,0.03160920275590551,814.1547331515387,0.00025370340306410486,25.0,45.0
305.76953,0.03194579527559055,815.9234125438255,0.00025370340306410486,25.0,45.0
307.1709,0.03230149409448819,815.8997013374886,0.00025370340306410486,25.0,45.0
308.57227,0.03269412204724409,817.0295805739515,0.00025370340306410486,25.0,45.0
309.97363,0.0330635157480315,816.7591741332295,0.00025370340306410486,25.0,45.0
311.375,0.03341115157480315,817.4518633943644,0.00025370340306410486,25.0,45.0
312.77637,0.03382300984251969,819.1689910401248,0.00025370340306410486,25.0,45.0
314.17773,0.034184372047244095,817.7151279054668,0.00025370340306410486,25.0,45.0
315.5791,0.03451641338582677,818.3072587975588,0.00025370340306410486,25.0,45.0
316.98047,0.03489516929133858,819.488040514219,0.00025370340306410486,25.0,45.0
318.38184,0.03522831889763779,819.1001428385924,0.00025370340306410486,25.0,45.0
319.7832,0.03554071850393701,820.4115309700039,0.00025370340306410486,25.0,45.0
321.18457,0.03591419881889764,822.5024542267239,0.00025370340306410486,25.0,45.0
322.58594,0.03627774212598425,821.7495130502532,0.00025370340306410486,25.0,45.0
323.9873,0.03667069881889764,823.8586677054928,0.00025370340306410486,25.0,45.0
325.38867,0.03706761220472441,821.8081547850929,0.00025370340306410486,25.0,45.0
326.79004,0.03739921653543307,822.8448253473575,0.00025370340306410486,25.0,45.0
328.19141,0.037740793307086615,824.8103103493053,0.00025370340306410486,25.0,45.0
329.59277,0.03813186417322835,825.0771847811973,0.00025370340306410486,25.0,45.0
330.99414,0.03850205511811024,824.496221269965,0.00025370340306410486,25.0,45.0
332.39551,0.038794364173228346,822.0095312297104,0.00025370340306410486,25.0,45.0
333.79688,0.03908832677165354,825.20303856642,0.00025370340306410486,25.0,45.0
335.19824,0.039361921259842524,826.3087131541358,0.00025370340306410486,25.0,45.0
336.59961,0.03968789960629921,826.7787819763668,0.00025370340306410486,25.0,45.0
338.00098,0.04001881102362204,827.5108687183482,0.00025370340306410486,25.0,45.0
339.40234,0.04042697440944882,828.4841189455916,0.00025370340306410486,25.0,45.0
340.80371,0.04080836023622047,828.3096480976498,0.00025370340306410486,25.0,45.0
342.20508,0.041181937007874016,828.145617452279,0.00025370340306410486,25.0,45.0
343.60645,0.04148607677165354,827.6625892741203,0.00025370340306410486,25.0,45.0
345.00781,0.04185431496062992,830.197273081418,0.00025370340306410486,25.0,45.0
346.40918,0.04222917716535433,831.7806778340475,0.00025370340306410486,25.0,45.0
347.81055,0.04260629133858267,830.0265160368783,0.00025370340306410486,25.0,45.0
349.21191,0.04293213779527559,832.3853785222699,0.00025370340306410486,25.0,45.0
350.61328,0.043319889763779526,831.4059472795741,0.00025370340306410486,25.0,45.0
352.01465,0.043709218503937004,833.8453187897676,0.00025370340306410486,25.0,45.0
353.41602,0.04404330708661417,831.4765095442151,0.00025370340306410486,25.0,45.0
354.81738,0.04437862598425197,835.0289053369693,0.00025370340306410486,25.0,45.0
356.21875,0.044746870078740154,833.8457602908715,0.00025370340306410486,25.0,45.0
357.62012,0.04511993503937008,835.7827295156474,0.00025370340306410486,25.0,45.0
359.02148,0.04544159251968504,835.8784573432023,0.00025370340306410486,25.0,45.0
360.42285,0.045793797244094485,835.9666536813402,0.00025370340306410486,25.0,45.0
361.82422,0.046150326771653545,835.5563173613817,0.00025370340306410486,25.0,45.0
363.22559,0.046462616141732284,835.0122841189457,0.00025370340306410486,25.0,45.0
364.62695,0.04682643307086614,836.4370081807557,0.00025370340306410486,25.0,45.0
366.02832,0.04717760433070866,837.7134657836644,0.00025370340306410486,25.0,45.0
367.42969,0.04752061023622047,835.4050383067134,0.00025370340306410486,25.0,45.0
368.83105,0.04781434448818897,837.188598883262,0.00025370340306410486,25.0,45.0
370.23242,0.04813199409448819,837.7361121932217,0.00025370340306410486,25.0,45.0
371.63379,0.04846504330708661,839.2887676925075,0.00025370340306410486,25.0,45.0
373.03516,0.04878298818897638,838.5788858589793,0.00025370340306410486,25.0,45.0
374.43652,0.04918629527559055,840.7811972471108,0.00025370340306410486,25.0,45.0
375.83789,0.04953569488188976,839.7997402934684,0.00025370340306410486,25.0,45.0
377.23926,0.04992347834645669,840.3718478119725,0.00025370340306410486,25.0,45.0
378.64063,0.050309440944881885,842.8244124139723,0.00025370340306410486,25.0,45.0
380.04199,0.05069851968503938,839.3297234125439,0.00025370340306410486,25.0,45.0
381.44336,0.051007442913385825,842.6486690040255,0.00025370340306410486,25.0,45.0
382.84473,0.05131012992125984,841.3039605246073,0.00025370340306410486,25.0,45.0
384.24609,0.05164630511811023,842.402077652253,0.00025370340306410486,25.0,45.0
385.64746,0.052008555118110235,843.6385923905987,0.00025370340306410486,25.0,45.0
387.04883,0.052389356299212604,843.4232697052331,0.00025370340306410486,25.0,45.0
388.4502,0.05271838976377953,845.3577457473057,0.00025370340306410486,25.0,45.0
389.85156,0.05302687992125984,845.0846123880017,0.00025370340306410486,25.0,45.0
391.25293,0.053402025590551176,845.2804570834957,0.00025370340306410486,25.0,45.0
392.6543,0.05373737204724409,845.7935333073627,0.00025370340306410486,25.0,45.0
394.05566,0.05405443110236221,844.9229191014155,0.00025370340306410486,25.0,45.0
395.45703,0.05443395866141732,845.6826386183612,0.00025370340306410486,25.0,45.0
396.8584,0.05485746850393701,847.6117906765356,0.00025370340306410486,25.0,45.0
398.25977,0.055164895669291336,845.9339825996624,0.00025370340306410486,25.0,45.0
399.66113,0.05547164960629921,847.2990780418128,0.00025370340306410486,25.0,45.0
401.0625,0.05589076574803149,849.2387741851708,0.00025370340306410486,25.0,45.0
402.46387,0.05623213582677165,847.9666277106869,0.00025370340306410486,25.0,45.0
403.86523,0.056609106299212605,849.004804570835,0.00025370340306410486,25.0,45.0
405.2666,0.05690595078740157,848.0571614076094,0.00025370340306410486,25.0,45.0
406.66797,0.05724697637795276,849.9154395533049,0.00025370340306410486,25.0,45.0
408.06934,0.057590259842519684,850.645864173484,0.00025370340306410486,25.0,45.0
409.4707,0.05794011417322834,850.503752759382,0.00025370340306410486,25.0,45.0
410.87207,0.05822793503937008,848.8874431891962,0.00025370340306410486,25.0,45.0
412.27344,0.05856177559055118,852.0273730684328,0.00025370340306410486,25.0,45.0
413.6748,0.05895349999999999,852.7309180625894,0.00025370340306410486,25.0,45.0
415.07617,0.05930483267716536,852.2215296714712,0.00025370340306410486,25.0,45.0
416.47754,0.059650316929133855,853.6932346448513,0.00025370340306410486,25.0,45.0
417.87891,0.06005328149606299,854.224048824828,0.00025370340306410486,25.0,45.0
419.28027,0.06040047244094488,851.7649396182314,0.00025370340306410486,25.0,45.0
420.68164,0.06070866732283464,854.5455655109727,0.00025370340306410486,25.0,45.0
422.08301,0.061044889763779524,855.0838072977535,0.00025370340306410486,25.0,45.0
423.48438,0.06143712401574803,855.1883132060772,0.00025370340306410486,25.0,45.0
424.88574,0.061799468503937,855.58636540709,0.00025370340306410486,25.0,45.0
426.28711,0.06212623818897637,855.6648487209454,0.00025370340306410486,25.0,45.0
427.68848,0.06246083267716535,855.043293078821,0.00025370340306410486,25.0,45.0
429.08984,0.06282691535433071,856.7557979483184,0.00025370340306410486,25.0,45.0
430.49121,0.063220968503937,858.1613556680951,0.00025370340306410486,25.0,45.0
431.89258,0.06357583858267717,857.6984547461369,0.00025370340306410486,25.0,45.0
433.29395,0.06392026181102363,858.4257109466304,0.00025370340306410486,25.0,45.0
434.69531,0.06426626181102361,857.4247240618101,0.00025370340306410486,25.0,45.0
436.09668,0.06463040157480315,858.720607713284,0.00025370340306410486,25.0,45.0
437.49805,0.06495129921259842,858.914998052201,0.00025370340306410486,25.0,45.0
438.89941,0.06530208070866142,858.4935462926893,0.00025370340306410486,25.0,45.0
440.30078,0.06559617913385826,858.9662381508896,0.00025370340306410486,25.0,45.0
441.70215,0.06594169291338582,861.1180625892741,0.00025370340306410486,25.0,45.0
443.10352,0.06627053937007873,860.715958966368,0.00025370340306410486,25.0,45.0
444.50488,0.06655526181102363,859.9740553174913,0.00025370340306410486,25.0,45.0
445.90625,0.06682676181102362,859.053733281392,0.00025370340306410486,25.0,45.0
447.30762,0.06713082874015748,861.9942604856514,0.00025370340306410486,25.0,45.0
448.70898,0.06752340944881889,861.6921438774185,0.00025370340306410486,25.0,45.0
450.11035,0.0679009783464567,861.3591221919232,0.00025370340306410486,25.0,45.0
451.51172,0.06820698622047244,862.8138942994417,0.00025370340306410486,25.0,45.0
452.91309,0.06859554724409449,864.0504869497469,0.00025370340306410486,25.0,45.0
454.31445,0.06892801377952756,863.033216465394,0.00025370340306410486,25.0,45.0
455.71582,0.06925987598425197,863.1105051292041,0.00025370340306410486,25.0,45.0
457.11719,0.06963725,865.1751460849241,0.00025370340306410486,25.0,45.0
458.51855,0.07003776968503937,865.407038047007,0.00025370340306410486,25.0,45.0
459.91992,0.07041296062992125,865.7296974418907,0.00025370340306410486,25.0,45.0
461.32129,0.07081515748031496,865.5920529801325,0.00025370340306410486,25.0,45.0
462.72266,0.07112620472440945,865.3319568887158,0.00025370340306410486,25.0,45.0
464.12402,0.07143425984251969,866.3178288533958,0.00025370340306410486,25.0,45.0
465.52539,0.07177651771653544,865.8737566549798,0.00025370340306410486,25.0,45.0
466.92676,0.07214922834645669,867.93535904428,0.00025370340306410486,25.0,45.0
468.32813,0.07254763582677165,869.1573042462019,0.00025370340306410486,25.0,45.0
469.72949,0.07291247244094488,868.0782236073237,0.00025370340306410486,25.0,45.0
471.13086,0.07325194881889764,868.2449552006234,0.00025370340306410486,25.0,45.0
472.53223,0.07360988188976378,869.5071808855994,0.00025370340306410486,25.0,45.0
473.93359,0.07392785236220473,868.096221269965,0.00025370340306410486,25.0,45.0
475.33496,0.07424856692913387,867.6895987534086,0.00025370340306410486,25.0,45.0
476.73633,0.0745457874015748,869.2680171406312,0.00025370340306410486,25.0,45.0
478.1377,0.07491191535433071,870.9534865601871,0.00025370340306410486,25.0,45.0
479.53906,0.07523878543307087,870.8533177509414,0.00025370340306410486,25.0,45.0
480.94043,0.07557001377952756,870.1330995974549,0.00025370340306410486,25.0,45.0
482.3418,0.07587771062992126,870.1811712764576,0.00025370340306410486,25.0,45.0
483.74316,0.07620034448818898,870.0783274899364,0.00025370340306410486,25.0,45.0
485.14453,0.07654270669291338,872.2534995455136,0.00025370340306410486,25.0,45.0
486.5459,0.07692762598425197,872.4471367354889,0.00025370340306410486,25.0,45.0
487.94727,0.0772887027559055,872.3412543825477,0.00025370340306410486,25.0,45.0
489.34863,0.07763000393700788,871.9471756914687,0.00025370340306410486,25.0,45.0
490.75,0.07800282677165354,872.4677314634463,0.00025370340306410486,25.0,45.0
492.15137,0.07836952952755906,873.852123100896,0.00025370340306410486,25.0,45.0
493.55273,0.0786894409448819,874.0144916244644,0.00025370340306410486,25.0,45.0
494.9541,0.07902291732283465,873.6503051551747,0.00025370340306410486,25.0,45.0
496.35547,0.07940501968503937,875.7317491234904,0.00025370340306410486,25.0,45.0
497.75684,0.07976177362204724,875.8302817815869,0.00025370340306410486,25.0,45.0
499.1582,0.08010905905511811,875.6527463965718,0.00025370340306410486,25.0,45.0
500.55957,0.08041659842519684,874.775925204519,0.00025370340306410486,25.0,45.0
501.96094,0.08080421062992126,876.2249837683419,0.00025370340306410486,25.0,45.0
503.3623,0.0811656220472441,876.3799506557591,0.00025370340306410486,25.0,45.0
504.76367,0.08154472637795275,877.8499155953772,0.00025370340306410486,25.0,45.0
506.16504,0.08190531692913386,876.0551097260096,0.00025370340306410486,25.0,45.0
507.56641,0.08227158661417322,876.7835086352422,0.00025370340306410486,25.0,45.0
508.96777,0.08259950590551181,877.492377613297,0.00025370340306410486,25.0,45.0
510.36914,0.08296060236220472,878.4419945461628,0.00025370340306410486,25.0,45.0
511.77051,0.08333395866141732,877.5512790546683,0.00025370340306410486,25.0,45.0
513.17188,0.08363262598425196,877.2539150759642,0.00025370340306410486,25.0,45.0
514.57324,0.08398556102362205,879.1936112193222,0.00025370340306410486,25.0,45.0
515.97461,0.08434901968503937,878.5338787170498,0.00025370340306410486,25.0,45.0
517.37598,0.08471343503937008,879.5408648227502,0.00025370340306410486,25.0,45.0
518.77734,0.08505322244094488,880.6650305155175,0.00025370340306410486,25.0,45.0
520.17871,0.08543438779527558,880.0895208414493,0.00025370340306410486,25.0,45.0
521.58008,0.08582885826771654,879.4930009089728,0.00025370340306410486,25.0,45.0
522.98145,0.08617076968503937,880.4534476042073,0.00025370340306410486,25.0,45.0
524.38281,0.08649136811023622,881.1335410985587,0.00025370340306410486,25.0,45.0
525.78418,0.08680502559055119,881.2075834307234,0.00025370340306410486,25.0,45.0
527.18555,0.0871387283464567,882.4925594078692,0.00025370340306410486,25.0,45.0
528.58691,0.0874704901574803,882.0141799766265,0.00025370340306410486,25.0,45.0
529.98828,0.08786711417322834,882.3405791455656,0.00025370340306410486,25.0,45.0
531.38965,0.0882445531496063,882.9200883002208,0.00025370340306410486,25.0,45.0
532.79102,0.08863508070866141,883.7959745487599,0.00025370340306410486,25.0,45.0
534.19238,0.08897560826771654,884.7925723931957,0.00025370340306410486,25.0,45.0
535.59375,0.08939346259842519,884.8836255031814,0.00025370340306410486,25.0,45.0
536.99512,0.0897479625984252,883.9611479028698,0.00025370340306410486,25.0,45.0
538.39648,0.09016198622047245,884.2988962472407,0.00025370340306410486,25.0,45.0
539.79785,0.09052803937007874,884.4841708868978,0.00025370340306410486,25.0,45.0
541.19922,0.09089133464566929,885.2726658875472,0.00025370340306410486,25.0,45.0
542.60059,0.0912086003937008,884.9014413712506,0.00025370340306410486,25.0,45.0
544.00195,0.09158034842519684,884.5096480976497,0.00025370340306410486,25.0,45.0
545.40332,0.09192122637795276,887.7472536034281,0.00025370340306410486,25.0,45.0
546.80469,0.0923044153543307,885.4813920270095,0.00025370340306410486,25.0,45.0
548.20605,0.09261106889763779,885.2535255161669,0.00025370340306410486,25.0,45.0
549.60742,0.09296003740157481,888.2409816906895,0.00025370340306410486,25.0,45.0
551.00879,0.09331323622047244,888.0122062069862,0.00025370340306410486,25.0,45.0
552.41016,0.09369698818897637,886.7867289962343,0.00025370340306410486,25.0,45.0
553.81152,0.09402503740157481,886.4173743669653,0.00025370340306410486,25.0,45.0
555.21289,0.09434116338582677,887.5756654979873,0.00025370340306410486,25.0,45.0
556.61426,0.09469456889763779,888.6809505259058,0.00025370340306410486,25.0,45.0
558.01563,0.09503521850393701,888.5927541877679,0.00025370340306410486,25.0,45.0
559.41699,0.09541939763779528,889.4329307882094,0.00025370340306410486,25.0,45.0
560.81836,0.0957122874015748,888.1888585897935,0.00025370340306410486,25.0,45.0
562.21973,0.0960361122047244,888.887573042462,0.00025370340306410486,25.0,45.0
563.62109,0.0964830531496063,890.8483833268407,0.00025370340306410486,25.0,45.0
565.02246,0.09691054133858268,890.8342293208675,0.00025370340306410486,25.0,45.0
566.42383,0.09728542913385826,890.4703025581094,0.00025370340306410486,25.0,45.0
567.8252,0.09765054724409448,891.5609920789508,0.00025370340306410486,25.0,45.0
569.22656,0.09800792322834646,891.1226074535775,0.00025370340306410486,25.0,45.0
570.62793,0.09840861811023621,891.8252434748734,0.00025370340306410486,25.0,45.0
572.0293,0.09876563582677166,891.3333073626802,0.00025370340306410486,25.0,45.0
573.43066,0.09914983858267716,893.366004415011,0.00025370340306410486,25.0,45.0
574.83203,0.0995013188976378,891.8184131930919,0.00025370340306410486,25.0,45.0
576.2334,0.09985748031496061,891.1494870796,0.00025370340306410486,25.0,45.0
577.63477,0.10022251181102362,892.8987663939748,0.00025370340306410486,25.0,45.0
579.03613,0.10059744685039369,893.2630307752241,0.00025370340306410486,25.0,45.0
580.4375,0.1009489842519685,893.5263991689392,0.00025370340306410486,25.0,45.0
581.83887,0.10134510826771653,894.0626152447734,0.00025370340306410486,25.0,45.0
583.24023,0.10168080708661417,894.978496299182,0.00025370340306410486,25.0,45.0
584.6416,0.1020535590551181,894.973691728347,0.00025370340306410486,25.0,45.0
586.04297,0.10239587598425196,895.7419555901831,0.00025370340306410486,25.0,45.0
587.44434,0.10270070275590551,893.7014154005973,0.00025370340306410486,25.0,45.0
588.8457,0.10306629921259841,895.5482664589015,0.00025370340306410486,25.0,45.0
590.24707,0.1034548779527559,895.9409946760161,0.00025370340306410486,25.0,45.0
591.64844,0.10379580905511812,894.7009738994936,0.00025370340306410486,25.0,45.0
593.0498,0.1041223090551181,896.024698091157,0.00025370340306410486,25.0,45.0
594.45117,0.10449027362204724,895.5238540449292,0.00025370340306410486,25.0,45.0
595.85254,0.10487507677165354,895.8007531489418,0.00025370340306410486,25.0,45.0
597.25391,0.10527181102362204,895.881651733541,0.00025370340306410486,25.0,45.0
598.65527,0.10568696653543308,897.1628619659784,0.00025370340306410486,25.0,45.0
600.05664,0.10612243307086613,897.2010388261265,0.00025370340306410486,25.0,45.0
601.45801,0.10650583858267716,896.2413972211401,0.00025370340306410486,25.0,45.0
602.85938,0.10692041929133857,899.1673548889755,0.00025370340306410486,25.0,45.0
604.26074,0.10725164763779528,896.379950655759,0.00025370340306410486,25.0,45.0
605.66211,0.10756955905511811,897.0824827944424,0.00025370340306410486,25.0,45.0
607.06348,0.10789305511811023,898.3249448123621,0.00025370340306410486,25.0,45.0
608.46484,0.10828712598425197,899.8448253473575,0.00025370340306410486,25.0,45.0
609.86621,0.10866870078740157,898.5205038306714,0.00025370340306410486,25.0,45.0
611.26758,0.10904667322834645,900.9387611998442,0.00025370340306410486,25.0,45.0
612.66895,0.10944550984251968,899.5186858849501,0.00025370340306410486,25.0,45.0
614.07031,0.10984776968503936,901.0713933255422,0.00025370340306410486,25.0,45.0
615.47168,0.11028645078740158,899.3389949357227,0.00025370340306410486,25.0,45.0
616.87305,0.11068113188976376,898.6551097260096,0.00025370340306410486,25.0,45.0
618.27441,0.11099914960629921,898.6246201791976,0.00025370340306410486,25.0,45.0
619.67578,0.11134707283464566,900.2103622906117,0.00025370340306410486,25.0,45.0
621.07715,0.11172425984251969,900.8763017789898,0.00025370340306410486,25.0,45.0
622.47852,0.11209703543307087,900.10808985846,0.00025370340306410486,25.0,45.0
623.87988,0.11246146850393701,902.5671990650566,0.00025370340306410486,25.0,45.0
625.28125,0.11285470669291338,901.3274899363719,0.00025370340306410486,25.0,45.0
626.68262,0.11318970078740158,900.3897935333074,0.00025370340306410486,25.0,45.0
628.08398,0.11356139763779528,901.742734709778,0.00025370340306410486,25.0,45.0
629.48535,0.11391240748031496,902.0158940397351,0.00025370340306410486,25.0,45.0
630.88672,0.1142796811023622,902.2562004934424,0.00025370340306410486,25.0,45.0
632.28809,0.11470279133858266,902.5558498896247,0.00025370340306410486,25.0,45.0
633.68945,0.11510952165354331,901.4434748733931,0.00025370340306410486,25.0,45.0
635.09082,0.11550232677165355,902.974185170757,0.00025370340306410486,25.0,45.0
636.49219,0.11591603937007874,905.2457862615246,0.00025370340306410486,25.0,45.0
637.89355,0.1163227125984252,904.466225165563,0.00025370340306410486,25.0,45.0
639.29492,0.11671264173228346,902.9797688611869,0.00025370340306410486,25.0,45.0
640.69629,0.11709227952755905,903.696558888456,0.00025370340306410486,25.0,45.0
642.09766,0.11744278543307088,903.8893650175302,0.00025370340306410486,25.0,45.0
643.49902,0.11782398622047245,903.5892221789379,0.00025370340306410486,25.0,45.0
644.90039,0.11819148228346456,902.9322165952474,0.00025370340306410486,25.0,45.0
646.30176,0.11857631889763778,904.9791195948578,0.00025370340306410486,25.0,45.0
647.70313,0.11900920275590551,905.212517854824,0.00025370340306410486,25.0,45.0
649.10449,0.11948075984251968,906.1940786910791,0.00025370340306410486,25.0,45.0
650.50586,0.11983313188976377,905.1098558628751,0.00025370340306410486,25.0,45.0
651.90723,0.12022064370078739,906.2946890014284,0.00025370340306410486,25.0,45.0
653.30859,0.12062217716535432,905.7431502402286,0.00025370340306410486,25.0,45.0
654.70996,0.12096165354330708,905.4234514998053,0.00025370340306410486,25.0,45.0
656.11133,0.12131678346456692,906.1335151279055,0.00025370340306410486,25.0,45.0
657.5127,0.12169527165354331,906.2592650305156,0.00025370340306410486,25.0,45.0
658.91406,0.12206374212598425,907.8284638358655,0.00025370340306410486,25.0,45.0
660.31543,0.12246141535433072,909.0258667705493,0.00025370340306410486,25.0,45.0
661.7168,0.12288175787401574,907.2556031684198,0.00025370340306410486,25.0,45.0
663.11816,0.12328021653543306,907.8015842098429,0.00025370340306410486,25.0,45.0
664.51953,0.12366283661417322,907.1348136605636,0.00025370340306410486,25.0,45.0
665.9209,0.12404093897637795,907.8150889494871,0.00025370340306410486,25.0,45.0
667.32227,0.1244136909448819,907.5999480586937,0.00025370340306410486,25.0,45.0
668.72363,0.12481375787401575,908.6670562264642,0.00025370340306410486,25.0,45.0
670.125,0.12519671653543307,907.7722893130763,0.00025370340306410486,25.0,45.0
671.52637,0.1255713464566929,907.9039864952605,0.00025370340306410486,25.0,45.0
672.92773,0.12601301968503936,910.5111284248799,0.00025370340306410486,25.0,45.0
674.3291,0.1264479094488189,909.2462537332815,0.00025370340306410486,25.0,45.0
675.73047,0.12685157874015748,909.9354629268926,0.00025370340306410486,25.0,45.0
677.13184,0.12723176968503938,908.8742760680431,0.00025370340306410486,25.0,45.0
678.5332,0.12761217125984253,908.627736657577,0.00025370340306410486,25.0,45.0
679.93457,0.12803437992125985,910.4645370731074,0.00025370340306410486,25.0,45.0
681.33594,0.12849597440944882,909.1511492014024,0.00025370340306410486,25.0,45.0
682.7373,0.1288691496062992,909.7153356706922,0.00025370340306410486,25.0,45.0
684.13867,0.12928272047244094,910.9630177898975,0.00025370340306410486,25.0,45.0
685.54004,0.1296845118110236,912.7123490455785,0.00025370340306410486,25.0,45.0
686.94141,0.13006876377952756,910.1359044279965,0.00025370340306410486,25.0,45.0
688.34277,0.1304529311023622,912.8033502142579,0.00025370340306410486,25.0,45.0
689.74414,0.1309238090551181,911.3375405791456,0.00025370340306410486,25.0,45.0
691.14551,0.1313540059055118,913.1072328269057,0.00025370340306410486,25.0,45.0
692.54688,0.13172164173228348,912.3207115958967,0.00025370340306410486,25.0,45.0
693.94824,0.13209137795275588,912.2704324113752,0.00025370340306410486,25.0,45.0
695.34961,0.13244189566929135,911.5433580054539,0.00025370340306410486,25.0,45.0
696.75098,0.13287356102362205,913.2811063498248,0.00025370340306410486,25.0,45.0
698.15234,0.13330028543307085,914.2966627710687,0.00025370340306410486,25.0,45.0
699.55371,0.13375746850393702,913.1334372159461,0.00025370340306410486,25.0,45.0
700.95508,0.13420757874015746,912.3995844695494,0.00025370340306410486,25.0,45.0
702.35645,0.13460190748031495,911.984287754837,0.00025370340306410486,25.0,45.0
703.75781,0.13501872834645667,912.7121672510065,0.00025370340306410486,25.0,45.0
705.15918,0.13541373818897637,913.8668224905857,0.00025370340306410486,25.0,45.0
706.56055,0.13580475984251966,913.0026230359693,0.00025370340306410486,25.0,45.0
707.96191,0.13625770866141731,914.4454746136865,0.00025370340306410486,25.0,45.0
709.36328,0.13669996653543307,914.0533696922478,0.00025370340306410486,25.0,45.0
710.76465,0.1371049153543307,913.9705752499676,0.00025370340306410486,25.0,45.0
712.16602,0.13754759645669293,914.6254772107519,0.00025370340306410486,25.0,45.0
713.56738,0.13799513582677164,914.1844955200623,0.00025370340306410486,25.0,45.0
714.96875,0.13838636811023622,913.4455005843397,0.00025370340306410486,25.0,45.0
716.37012,0.13880978346456693,914.1529671471237,0.00025370340306410486,25.0,45.0
717.77148,0.13924054527559054,914.5888845604467,0.00025370340306410486,25.0,45.0
719.17285,0.1396764094488189,916.0562004934424,0.00025370340306410486,25.0,45.0
720.57422,0.1400698937007874,915.033995584989,0.00025370340306410486,25.0,45.0
721.97559,0.14048557874015746,915.8112712634722,0.00025370340306410486,25.0,45.0
723.37695,0.14095366141732285,916.0185949876641,0.00025370340306410486,25.0,45.0
724.77832,0.14143234251968503,916.060459680561,0.00025370340306410486,25.0,45.0
726.17969,0.14182042913385826,914.1131541358266,0.00025370340306410486,25.0,45.0
727.58105,0.14218575393700786,915.7419815608363,0.00025370340306410486,25.0,45.0
728.98242,0.14259547637795275,917.2164394234516,0.00025370340306410486,25.0,45.0
730.38379,0.14306237598425198,916.853395662901,0.00025370340306410486,25.0,45.0
731.78516,0.14352612992125985,916.824542267238,0.00025370340306410486,25.0,45.0
733.18652,0.14391669291338582,915.9291520581743,0.00025370340306410486,25.0,45.0
734.58789,0.1443196003937008,915.909855862875,0.00025370340306410486,25.0,45.0
735.98926,0.14473281889763778,916.8451629658487,0.00025370340306410486,25.0,45.0
737.39063,0.14514530118110236,917.4119205298014,0.00025370340306410486,25.0,45.0
738.79199,0.14557555708661418,916.1312037397742,0.00025370340306410486,25.0,45.0
740.19336,0.14597787598425196,917.4164394234516,0.00025370340306410486,25.0,45.0
741.59473,0.14641419881889764,918.3606025191534,0.00025370340306410486,25.0,45.0
742.99609,0.14690051574803148,918.0400207765226,0.00025370340306410486,25.0,45.0
744.39746,0.1474069094488189,918.3833008700169,0.00025370340306410486,25.0,45.0
745.79883,0.14784402952755904,917.7718737826257,0.00025370340306410486,25.0,45.0
747.2002,0.14828713385826772,918.2927412024412,0.00025370340306410486,25.0,45.0
748.60156,0.14873858070866142,917.5957408128816,0.00025370340306410486,25.0,45.0
750.00293,0.14923974015748032,918.9328139202702,0.00025370340306410486,25.0,45.0
751.4043,0.14969526968503935,917.5299831190755,0.00025370340306410486,25.0,45.0
752.80566,0.1500937066929134,918.482586677055,0.00025370340306410486,25.0,45.0
754.20703,0.15053037992125984,919.0920919361123,0.00025370340306410486,25.0,45.0
755.6084,0.15095966338582675,916.8909232567199,0.00025370340306410486,25.0,45.0
757.00977,0.15137230708661417,921.1568108037917,0.00025370340306410486,25.0,45.0
758.41113,0.15184788976377953,919.3976366705624,0.00025370340306410486,25.0,45.0
759.8125,0.1523262992125984,918.5518244383846,0.00025370340306410486,25.0,45.0
761.21387,0.15284320472440943,920.2472665887548,0.00025370340306410486,25.0,45.0
762.61523,0.15327905905511813,919.4883781327101,0.00025370340306410486,25.0,45.0
764.0166,0.1536428937007874,916.783145046098,0.00025370340306410486,25.0,45.0
765.41797,0.15397265354330708,918.4865861576419,0.00025370340306410486,25.0,45.0
766.81934,0.1543942874015748,920.8223607323724,0.00025370340306410486,25.0,45.0
768.2207,0.15491741141732285,919.9734320218154,0.00025370340306410486,25.0,45.0
769.62207,0.1553677440944882,918.5524477340605,0.00025370340306410486,25.0,45.0
771.02344,0.15580354921259842,919.9024022854175,0.00025370340306410486,25.0,45.0
772.4248,0.15629308267716535,921.3482924295547,0.00025370340306410486,25.0,45.0
773.82617,0.15672560236220473,920.0915465523958,0.00025370340306410486,25.0,45.0
775.22754,0.15718437007874014,921.0445136995196,0.00025370340306410486,25.0,45.0
776.62891,0.15762127952755906,920.7951434878587,0.00025370340306410486,25.0,45.0
778.03027,0.15810502755905512,921.5414881184263,0.00025370340306410486,25.0,45.0
779.43164,0.158599031496063,921.1217504220232,0.00025370340306410486,25.0,45.0
780.83301,0.1591067972440945,920.6067004285159,0.00025370340306410486,25.0,45.0
782.23438,0.15961124212598427,920.7054927931438,0.00025370340306410486,25.0,45.0
783.63574,0.16008502952755907,920.8704843526815,0.00025370340306410486,25.0,45.0
785.03711,0.16053585236220472,921.7477470458382,0.00025370340306410486,25.0,45.0
786.43848,0.16103255511811024,921.3664199454616,0.00025370340306410486,25.0,45.0
787.83984,0.1615084527559055,921.1493831969874,0.00025370340306410486,25.0,45.0
789.24121,0.16198544291338582,921.8096870536294,0.00025370340306410486,25.0,45.0
790.64258,0.16235950984251968,920.093182703545,0.00025370340306410486,25.0,45.0
792.04395,0.16291952362204726,923.1938189845474,0.00025370340306410486,25.0,45.0
793.44531,0.16344752755905512,921.6289313076225,0.00025370340306410486,25.0,45.0
794.84668,0.1638778307086614,921.3841319309181,0.00025370340306410486,25.0,45.0
796.24805,0.16431976181102362,922.8282300999871,0.00025370340306410486,25.0,45.0
797.64941,0.16476055511811025,921.1123750162317,0.00025370340306410486,25.0,45.0
799.05078,0.16517232086614173,922.3620828463836,0.00025370340306410486,25.0,45.0
800.45215,0.16562093897637795,922.5250227243216,0.00025370340306410486,25.0,45.0
801.85352,0.166080281496063,922.7524477340606,0.00025370340306410486,25.0,45.0
803.25488,0.16657333464566929,922.5300350603818,0.00025370340306410486,25.0,45.0
804.65625,0.1670784251968504,922.7994546162837,0.00025370340306410486,25.0,45.0
806.05762,0.16764742716535433,924.2995974548761,0.00025370340306410486,25.0,45.0
807.45898,0.1681318090551181,920.83687832749,0.00025370340306410486,25.0,45.0
808.86035,0.16856834251968503,922.3864952603558,0.00025370340306410486,25.0,45.0
810.26172,0.16907235236220472,922.1033891702376,0.00025370340306410486,25.0,45.0
811.66309,0.16953447637795274,921.4476561485521,0.00025370340306410486,25.0,45.0
813.06445,0.17004812007874015,922.9411504999351,0.00025370340306410486,25.0,45.0
814.46582,0.17050127952755906,921.5343202181535,0.00025370340306410486,25.0,45.0
815.86719,0.17097728543307086,924.0023633294377,0.00025370340306410486,25.0,45.0
817.26855,0.17152367519685038,922.9665757693806,0.00025370340306410486,25.0,45.0
818.66992,0.17200916141732284,922.7875340864823,0.00025370340306410486,25.0,45.0
820.07129,0.17250092322834645,922.4440462277627,0.00025370340306410486,25.0,45.0
821.47266,0.17292741338582676,922.1215166861448,0.00025370340306410486,25.0,45.0
822.87402,0.173433218503937,923.1651733541099,0.00025370340306410486,25.0,45.0
824.27539,0.17395114566929135,922.784911050513,0.00025370340306410486,25.0,45.0
825.67676,0.17446882677165354,924.1379820802495,0.00025370340306410486,25.0,45.0
827.07813,0.17497050196850394,922.6971042721725,0.00025370340306410486,25.0,45.0
828.47949,0.17545403937007872,923.3251266069342,0.00025370340306410486,25.0,45.0
829.88086,0.17603824606299212,923.1184261784185,0.00025370340306410486,25.0,45.0
831.28223,0.17647483858267715,923.0871055707051,0.00025370340306410486,25.0,45.0
832.68359,0.17701383858267716,923.8432151668615,0.00025370340306410486,25.0,45.0
834.08496,0.1775490964566929,926.0587715881055,0.00025370340306410486,25.0,45.0
835.48633,0.17811167913385828,922.9834566939359,0.00025370340306410486,25.0,45.0
836.8877,0.17856228149606299,922.9845214907156,0.00025370340306410486,25.0,45.0
838.28906,0.17902006299212597,925.149305285028,0.00025370340306410486,25.0,45.0
839.69043,0.1795321712598425,924.5697182184132,0.00025370340306410486,25.0,45.0
841.0918,0.18007899606299213,924.1134398130114,0.00025370340306410486,25.0,45.0
842.49316,0.18057868897637794,922.9484482534737,0.00025370340306410486,25.0,45.0
843.89453,0.18104433267716535,924.1128165173355,0.00025370340306410486,25.0,45.0
845.2959,0.18157257283464567,923.7128424879886,0.00025370340306410486,25.0,45.0
846.69727,0.18213411220472442,924.5084015062979,0.00025370340306410486,25.0,45.0
848.09863,0.1827528976377953,924.374159200104,0.00025370340306410486,25.0,45.0
849.5,0.1832617657480315,922.3827554863004,0.00025370340306410486,25.0,45.0
850.90137,0.18372597834645668,925.4060251915337,0.00025370340306410486,25.0,45.0
852.30273,0.18429573031496063,926.3056745877159,0.00025370340306410486,25.0,45.0
853.7041,0.1849035688976378,924.5413063238541,0.00025370340306410486,25.0,45.0
855.10547,0.18548453937007875,924.4753668354759,0.00025370340306410486,25.0,45.0
856.50684,0.18601781299212597,925.151253084015,0.00025370340306410486,25.0,45.0
857.9082,0.18660030708661415,925.1055966757564,0.00025370340306410486,25.0,45.0
859.30957,0.18715902952755906,924.5340864822751,0.00025370340306410486,25.0,45.0
860.71094,0.18766552952755905,923.8416828983248,0.00025370340306410486,25.0,45.0
862.1123,0.18817985433070866,925.1462407479548,0.00025370340306410486,25.0,45.0
863.51367,0.1887035649606299,923.7903389170239,0.00025370340306410486,25.0,45.0
864.91504,0.18926015354330708,924.0995714842228,0.00025370340306410486,25.0,45.0
866.31641,0.18984031299212598,926.0759641604988,0.00025370340306410486,25.0,45.0
867.71777,0.1904078937007874,924.9887547071809,0.00025370340306410486,25.0,45.0
869.11914,0.1909339527559055,923.8894948707959,0.00025370340306410486,25.0,45.0
870.52051,0.19139798818897638,924.152369822101,0.00025370340306410486,25.0,45.0
871.92188,0.19191867322834644,924.2888975457734,0.00025370340306410486,25.0,45.0
873.32324,0.19243573031496064,925.0173483963123,0.00025370340306410486,25.0,45.0
873.72363,0.19260742322834645,926.9339566290092,0.00025370340306410486,25.0,45.0