File: datasets/am_bench_2022/csv/45-XY.02-2.csv
Time(s),Strain(%),Stress(MPa),SR(s-1),Temp(C),Angle(deg)
35.264404,2.0305856299212597e-06,12.575989988006468,0.00025370340306410486,25.0,45.0
37.666748,9.738196850393701e-06,19.223603535485218,0.00025370340306410486,25.0,45.0
39.268311,2.151196653543307e-05,25.76761276529176,0.00025370340306410486,25.0,45.0
40.869873,4.945498228346457e-05,32.09201908536267,0.00025370340306410486,25.0,45.0
42.471436,5.4920084645669295e-05,36.583190801480946,0.00025370340306410486,25.0,45.0
44.072998,0.00010335441732283466,44.30867184648277,0.00025370340306410486,25.0,45.0
45.674561,0.00011469601968503937,51.37386973979246,0.00025370340306410486,25.0,45.0
47.276123,0.000128886531496063,59.128367315012774,0.00025370340306410486,25.0,45.0
48.877686,0.00017342974803149608,68.82623455180685,0.00025370340306410486,25.0,45.0
50.479248,0.00018732562401574802,77.40643479167753,0.00025370340306410486,25.0,45.0
52.080811,0.0002339056496062992,86.42452677686812,0.00025370340306410486,25.0,45.0
53.682373,0.00026289248031496063,95.76156593836366,0.00025370340306410486,25.0,45.0
55.283936,0.000269052125984252,104.08454659227199,0.00025370340306410486,25.0,45.0
56.885498,0.00031723881889763776,115.29547895916984,0.00025370340306410486,25.0,45.0
58.487061,0.0003612760433070866,126.1148354800021,0.00025370340306410486,25.0,45.0
60.088623,0.0003780706496062992,133.52119205298013,0.00025370340306410486,25.0,45.0
61.690186,0.00042988566929133857,144.84019398237473,0.00025370340306410486,25.0,45.0
63.291748,0.00045605647637795275,156.4967252437816,0.00025370340306410486,25.0,45.0
64.893311,0.0004931873228346456,167.03255462272514,0.00025370340306410486,25.0,45.0
66.494873,0.0005268124212598425,176.92507430776453,0.00025370340306410486,25.0,45.0
68.096436,0.0005621451968503937,187.97061584189393,0.00025370340306410486,25.0,45.0
69.697998,0.000602362342519685,199.22496219429527,0.00025370340306410486,25.0,45.0
71.299561,0.0006366771456692914,209.0577436512489,0.00025370340306410486,25.0,45.0
72.901123,0.0006680266338582677,217.9131250977734,0.00025370340306410486,25.0,45.0
74.502686,0.0007166448818897638,230.0931506492152,0.00025370340306410486,25.0,45.0
76.104248,0.0007518843503937008,242.064246232466,0.00025370340306410486,25.0,45.0
77.705811,0.000765293188976378,250.59129686603742,0.00025370340306410486,25.0,45.0
79.307373,0.0008030895472440944,263.3483600146008,0.00025370340306410486,25.0,45.0
80.908936,0.0008602567125984253,277.15719351306257,0.00025370340306410486,25.0,45.0
82.510498,0.0009051305118110237,287.7323095374668,0.00025370340306410486,25.0,45.0
84.112061,0.000922900157480315,299.2613547478751,0.00025370340306410486,25.0,45.0
85.713623,0.0009812287204724408,311.2191948688533,0.00025370340306410486,25.0,45.0
87.315186,0.001025902598425197,323.8476039005058,0.00025370340306410486,25.0,45.0
88.916748,0.0010604239566929133,333.9321583146478,0.00025370340306410486,25.0,45.0
90.518311,0.0010961673031496062,346.8148824112218,0.00025370340306410486,25.0,45.0
92.119873,0.0011286219881889764,357.13437972571313,0.00025370340306410486,25.0,45.0
93.721436,0.0011816244094488189,368.18493507847944,0.00025370340306410486,25.0,45.0
95.322998,0.0012202886811023622,382.1929133858267,0.00025370340306410486,25.0,45.0
96.924561,0.0012547938188976378,392.8397298847578,0.00025370340306410486,25.0,45.0
98.526123,0.0012779890748031498,402.66094801063775,0.00025370340306410486,25.0,45.0
100.12769,0.0013332936811023622,415.076967200292,0.00025370340306410486,25.0,45.0
101.72925,0.0013630331299212598,426.8961516399854,0.00025370340306410486,25.0,45.0
103.33081,0.001396171062992126,436.1565938363665,0.00025370340306410486,25.0,45.0
104.93237,0.0014484934251968505,451.10358763101635,0.00025370340306410486,25.0,45.0
106.53394,0.0014794114173228346,459.7838817333264,0.00025370340306410486,25.0,45.0
108.1355,0.001492390531496063,467.82176565677634,0.00025370340306410486,25.0,45.0
109.73706,0.001539422125984252,478.3011419930125,0.00025370340306410486,25.0,45.0
111.33862,0.001576856909448819,490.6560202325703,0.00025370340306410486,25.0,45.0
112.94019,0.0016019864763779528,497.0521457996559,0.00025370340306410486,25.0,45.0
114.54175,0.0016339304724409449,507.5025551441832,0.00025370340306410486,25.0,45.0
116.14331,0.0016632667716535432,514.7451895499818,0.00025370340306410486,25.0,45.0
117.74487,0.001697795374015748,525.9252489961934,0.00025370340306410486,25.0,45.0
119.34644,0.0017241418897637796,532.7985086301298,0.00025370340306410486,25.0,45.0
120.948,0.0017619777952755907,540.9796370652344,0.00025370340306410486,25.0,45.0
122.54956,0.00179290062992126,549.2678468999322,0.00025370340306410486,25.0,45.0
124.15112,0.001808709468503937,557.8273974031391,0.00025370340306410486,25.0,45.0
125.75269,0.0018584732677165354,566.8476299734057,0.00025370340306410486,25.0,45.0
127.35425,0.001862481437007874,573.6139907180477,0.00025370340306410486,25.0,45.0
128.95581,0.0018939438188976378,579.280752985347,0.00025370340306410486,25.0,45.0
130.55737,0.001914515059055118,585.9163059915523,0.00025370340306410486,25.0,45.0
132.15894,0.001938127933070866,591.2338739114564,0.00025370340306410486,25.0,45.0
133.7605,0.001968132283464567,598.3129008708348,0.00025370340306410486,25.0,45.0
135.36206,0.0019992484251968503,602.8423632476404,0.00025370340306410486,25.0,45.0
136.96362,0.0020166415354330707,607.9701204567972,0.00025370340306410486,25.0,45.0
138.56519,0.002045329133858268,614.4114564321844,0.00025370340306410486,25.0,45.0
140.16675,0.0020599706692913384,616.7725921677009,0.00025370340306410486,25.0,45.0
141.76831,0.0021051937007874016,624.1103665849716,0.00025370340306410486,25.0,45.0
143.36987,0.002136702165354331,628.7423215310007,0.00025370340306410486,25.0,45.0
144.97144,0.002159440748031496,632.3083120404651,0.00025370340306410486,25.0,45.0
146.573,0.002204959251968504,639.7972571309381,0.00025370340306410486,25.0,45.0
148.17456,0.0022255537401574804,642.2075402826302,0.00025370340306410486,25.0,45.0
149.77612,0.002246240157480315,648.1880638264588,0.00025370340306410486,25.0,45.0
151.37769,0.0022746647637795275,648.3810815038848,0.00025370340306410486,25.0,45.0
152.97925,0.0023306251968503934,654.5227094957502,0.00025370340306410486,25.0,45.0
154.58081,0.0023595903543307084,658.6422015956615,0.00025370340306410486,25.0,45.0
156.18237,0.0023779649606299213,662.4427439119779,0.00025370340306410486,25.0,45.0
157.78394,0.002419718897637795,665.0448193148042,0.00025370340306410486,25.0,45.0
159.3855,0.0024659057086614173,667.9733795692757,0.00025370340306410486,25.0,45.0
160.98706,0.002511734842519685,675.0367888616571,0.00025370340306410486,25.0,45.0
162.58862,0.0025530633858267715,679.2964227981437,0.00025370340306410486,25.0,45.0
164.19019,0.0026188720472440944,682.2878187412005,0.00025370340306410486,25.0,45.0
165.79175,0.002672773031496063,685.1501799030087,0.00025370340306410486,25.0,45.0
167.39331,0.0027042147637795274,689.9080930281066,0.00025370340306410486,25.0,45.0
168.99487,0.0028021531496062995,693.3285706836314,0.00025370340306410486,25.0,45.0
170.59644,0.0028626122047244094,695.378187412004,0.00025370340306410486,25.0,45.0
172.198,0.0029183364173228344,699.3507847942848,0.00025370340306410486,25.0,45.0
173.79956,0.003013190748031496,702.319393022892,0.00025370340306410486,25.0,45.0
175.40112,0.0030932958661417324,705.1504145591073,0.00025370340306410486,25.0,45.0
177.00269,0.0031818470472440947,709.1250195546749,0.00025370340306410486,25.0,45.0
178.60425,0.003284937598425197,710.9847994994003,0.00025370340306410486,25.0,45.0
180.20581,0.0033970240157480316,715.8147259738229,0.00025370340306410486,25.0,45.0
181.80737,0.003527256299212598,715.648328727121,0.00025370340306410486,25.0,45.0
183.40894,0.0036318818897637796,719.5080825989467,0.00025370340306410486,25.0,45.0
185.0105,0.003755894881889764,722.0745163477081,0.00025370340306410486,25.0,45.0
186.61206,0.00390871751968504,723.8680971997705,0.00025370340306410486,25.0,45.0
188.21362,0.0040613324803149605,724.8653856181885,0.00025370340306410486,25.0,45.0
189.81519,0.004235933661417323,727.9032956145383,0.00025370340306410486,25.0,45.0
191.41675,0.004444294094488189,732.9877718099807,0.00025370340306410486,25.0,45.0
193.01831,0.004647083661417323,731.7629973405642,0.00025370340306410486,25.0,45.0
194.61987,0.004844922244094488,735.3080252385671,0.00025370340306410486,25.0,45.0
196.22144,0.0050813718503937,738.4980706054127,0.00025370340306410486,25.0,45.0
197.823,0.005326090354330709,739.1608437190384,0.00025370340306410486,25.0,45.0
199.42456,0.005569207086614173,741.178651509621,0.00025370340306410486,25.0,45.0
201.02612,0.005840904724409449,742.9610210147573,0.00025370340306410486,25.0,45.0
202.62769,0.006050533267716536,742.5143140220055,0.00025370340306410486,25.0,45.0
204.22925,0.006361520669291338,745.9521562288157,0.00025370340306410486,25.0,45.0
205.83081,0.006599915748031496,747.7807008395474,0.00025370340306410486,25.0,45.0
207.43237,0.006926204921259843,747.1623559472284,0.00025370340306410486,25.0,45.0
209.03394,0.00722679625984252,749.8001251499192,0.00025370340306410486,25.0,45.0
210.6355,0.0075088718503937,751.0689106742452,0.00025370340306410486,25.0,45.0
212.23706,0.007808441732283464,751.3263284142463,0.00025370340306410486,25.0,45.0
213.83862,0.008123475,752.8623611618084,0.00025370340306410486,25.0,45.0
215.44019,0.00839462342519685,752.08940397351,0.00025370340306410486,25.0,45.0
217.04175,0.00870024468503937,756.6524743181936,0.00025370340306410486,25.0,45.0
218.64331,0.009077309251968504,756.7738175939928,0.00025370340306410486,25.0,45.0
220.24487,0.009446190748031496,757.3004119518173,0.00025370340306410486,25.0,45.0
221.84644,0.009850110433070866,759.6441831360484,0.00025370340306410486,25.0,45.0
223.448,0.010214308267716537,759.0154090837983,0.00025370340306410486,25.0,45.0
225.04956,0.010565287795275592,761.3868436147469,0.00025370340306410486,25.0,45.0
226.65112,0.01089823346456693,761.2279032173958,0.00025370340306410486,25.0,45.0
228.25269,0.011205926181102362,763.447280596548,0.00025370340306410486,25.0,45.0
229.85425,0.011529811614173229,764.5169995306878,0.00025370340306410486,25.0,45.0
231.45581,0.01192878877952756,765.208035667727,0.00025370340306410486,25.0,45.0
233.05737,0.012283041929133858,766.3948219220941,0.00025370340306410486,25.0,45.0
234.65894,0.012652049409448819,766.491056995359,0.00025370340306410486,25.0,45.0
236.2605,0.012945784251968503,766.1636856651196,0.00025370340306410486,25.0,45.0
237.86206,0.013296130118110235,767.9614121082546,0.00025370340306410486,25.0,45.0
239.46362,0.013672808267716535,772.1017625280284,0.00025370340306410486,25.0,45.0
241.06519,0.014078608267716536,771.881524743182,0.00025370340306410486,25.0,45.0
242.66675,0.014436819881889764,770.7445116545862,0.00025370340306410486,25.0,45.0
244.26831,0.01483776377952756,773.2918339677739,0.00025370340306410486,25.0,45.0
245.86987,0.0152267031496063,773.453329509308,0.00025370340306410486,25.0,45.0
247.47144,0.01555705275590551,772.002581217083,0.00025370340306410486,25.0,45.0
249.073,0.015887092913385824,774.2743651248892,0.00025370340306410486,25.0,45.0
250.67456,0.016219186417322833,775.7107211764093,0.00025370340306410486,25.0,45.0
252.27612,0.016561213582677165,776.1220472440945,0.00025370340306410486,25.0,45.0
253.87769,0.01699065748031496,778.7937633623611,0.00025370340306410486,25.0,45.0
255.47925,0.017397693897637796,776.6076028575899,0.00025370340306410486,25.0,45.0
257.08081,0.01776252303149606,778.5499035302706,0.00025370340306410486,25.0,45.0
258.68237,0.01809106279527559,778.4805235438286,0.00025370340306410486,25.0,45.0
260.28394,0.018466022047244096,779.4868331855869,0.00025370340306410486,25.0,45.0
261.8855,0.01880970649606299,779.8637951712989,0.00025370340306410486,25.0,45.0
263.48706,0.019207885629921262,782.8533920842676,0.00025370340306410486,25.0,45.0
265.08862,0.019576374212598426,782.3586588100328,0.00025370340306410486,25.0,45.0
266.69019,0.020004749999999998,785.4704333315951,0.00025370340306410486,25.0,45.0
268.29175,0.02040810433070866,783.4760650779581,0.00025370340306410486,25.0,45.0
269.89331,0.020747226377952753,783.0589247536111,0.00025370340306410486,25.0,45.0
271.49487,0.021066159448818896,784.5886217865152,0.00025370340306410486,25.0,45.0
273.09644,0.021428962598425198,786.0983730510507,0.00025370340306410486,25.0,45.0
274.698,0.02179705118110236,786.272279292903,0.00025370340306410486,25.0,45.0
276.29956,0.02220271653543307,786.212885227095,0.00025370340306410486,25.0,45.0
277.90112,0.022610476377952757,789.6142775199459,0.00025370340306410486,25.0,45.0
279.50269,0.022963435039370077,788.0193460916723,0.00025370340306410486,25.0,45.0
281.10425,0.02332111811023622,787.384705636961,0.00025370340306410486,25.0,45.0
282.70581,0.023715667322834644,790.6185534755176,0.00025370340306410486,25.0,45.0
284.30737,0.02405821653543307,788.8154038692184,0.00025370340306410486,25.0,45.0
285.90894,0.02441192519685039,793.0459404494968,0.00025370340306410486,25.0,45.0
287.5105,0.024803844488188977,794.3926317985087,0.00025370340306410486,25.0,45.0
289.11206,0.025220163385826774,793.7950930802524,0.00025370340306410486,25.0,45.0
290.71362,0.025549647637795273,792.2527506909319,0.00025370340306410486,25.0,45.0
292.31519,0.02593497244094488,796.2478489857642,0.00025370340306410486,25.0,45.0
293.91675,0.0262944625984252,795.0352766334672,0.00025370340306410486,25.0,45.0
295.51831,0.026663726377952755,795.934713458831,0.00025370340306410486,25.0,45.0
297.11987,0.027010179133858263,795.0567867758252,0.00025370340306410486,25.0,45.0
298.72144,0.027416391732283465,797.2335349637586,0.00025370340306410486,25.0,45.0
300.323,0.02779743307086614,797.0333472388799,0.00025370340306410486,25.0,45.0
301.92456,0.028187421259842516,797.1685873702874,0.00025370340306410486,25.0,45.0
303.52612,0.02855302755905512,799.3780570475049,0.00025370340306410486,25.0,45.0
305.12769,0.028904744094488188,798.7483704437608,0.00025370340306410486,25.0,45.0
306.72925,0.029266437007874013,798.8763883819158,0.00025370340306410486,25.0,45.0
308.33081,0.0296845905511811,800.0416384210251,0.00025370340306410486,25.0,45.0
309.93237,0.03005052952755906,802.7579131250977,0.00025370340306410486,25.0,45.0
311.53394,0.03048512401574803,802.0994681128435,0.00025370340306410486,25.0,45.0
313.1355,0.030818409448818897,800.6983626218909,0.00025370340306410486,25.0,45.0
314.73706,0.031181891732283466,802.5004953850968,0.00025370340306410486,25.0,45.0
316.33862,0.03159372440944882,805.133936486416,0.00025370340306410486,25.0,45.0
317.94019,0.031933086614173226,803.2712363769099,0.00025370340306410486,25.0,45.0
319.54175,0.032296305118110234,805.3703655420557,0.00025370340306410486,25.0,45.0
321.14331,0.03266379330708661,806.6218647337957,0.00025370340306410486,25.0,45.0
322.74487,0.03297489960629921,804.8038275016947,0.00025370340306410486,25.0,45.0
324.34644,0.03332353149606299,807.4729884757784,0.00025370340306410486,25.0,45.0
325.948,0.0337013188976378,807.142879491057,0.00025370340306410486,25.0,45.0
327.54956,0.03407227362204724,805.8544610731606,0.00025370340306410486,25.0,45.0
329.15112,0.034484889763779523,809.6187881316159,0.00025370340306410486,25.0,45.0
330.75269,0.034861606299212596,808.5358241643636,0.00025370340306410486,25.0,45.0
332.35425,0.03525167716535433,809.6251499191741,0.00025370340306410486,25.0,45.0
333.95581,0.03564805708661417,810.0955571778694,0.00025370340306410486,25.0,45.0
335.55737,0.03603754527559055,811.5799916566721,0.00025370340306410486,25.0,45.0
337.15894,0.036381718503937004,811.9099702768942,0.00025370340306410486,25.0,45.0
338.7605,0.03670344881889764,811.3961516399854,0.00025370340306410486,25.0,45.0
340.36206,0.03707493897637795,812.8703916149555,0.00025370340306410486,25.0,45.0
341.96362,0.03744755118110236,814.8263023413464,0.00025370340306410486,25.0,45.0
343.56519,0.037788763779527564,814.4438129008709,0.00025370340306410486,25.0,45.0
345.16675,0.03819544881889764,815.5009907701935,0.00025370340306410486,25.0,45.0
346.76831,0.03856784842519685,814.3202534285863,0.00025370340306410486,25.0,45.0
348.36987,0.038901765748031496,816.4850863012985,0.00025370340306410486,25.0,45.0
349.97144,0.03926170866141732,815.8987067841686,0.00025370340306410486,25.0,45.0
351.573,0.039596935039370076,817.3717995515461,0.00025370340306410486,25.0,45.0
353.17456,0.04001245078740157,818.6157376023361,0.00025370340306410486,25.0,45.0
354.77612,0.04037848031496063,817.1948167075142,0.00025370340306410486,25.0,45.0
356.37769,0.040715889763779524,817.1211086197007,0.00025370340306410486,25.0,45.0
357.97925,0.04111408661417323,818.7151014235803,0.00025370340306410486,25.0,45.0
359.58081,0.0414687342519685,819.6795119153153,0.00025370340306410486,25.0,45.0
361.18237,0.04184003149606299,820.4792198988372,0.00025370340306410486,25.0,45.0
362.78394,0.04221342716535433,821.5416123481255,0.00025370340306410486,25.0,45.0
364.3855,0.04256168897637795,820.5414559107264,0.00025370340306410486,25.0,45.0
365.98706,0.042884685039370075,822.7493351410544,0.00025370340306410486,25.0,45.0
367.58862,0.04325902755905512,821.0018772487877,0.00025370340306410486,25.0,45.0
369.19019,0.04362833267716536,821.4019398237473,0.00025370340306410486,25.0,45.0
370.79175,0.04399001771653543,823.7069406059343,0.00025370340306410486,25.0,45.0
372.39331,0.04440316929133858,826.5044845387704,0.00025370340306410486,25.0,45.0
373.99487,0.044754190944881894,825.2239662095218,0.00025370340306410486,25.0,45.0
375.59644,0.045125222440944884,824.7324920477656,0.00025370340306410486,25.0,45.0
377.198,0.04546298031496063,825.0172081138865,0.00025370340306410486,25.0,45.0
378.79956,0.04582699015748032,825.3805600458884,0.00025370340306410486,25.0,45.0
380.40112,0.04618724015748031,827.4866246023884,0.00025370340306410486,25.0,45.0
382.00269,0.04655838779527559,827.811831881942,0.00025370340306410486,25.0,45.0
383.60425,0.04693376771653543,827.2015695885697,0.00025370340306410486,25.0,45.0
385.20581,0.04733729527559055,829.7735307920947,0.00025370340306410486,25.0,45.0
386.80737,0.04773184448818898,829.533946915576,0.00025370340306410486,25.0,45.0
388.40894,0.04805145866141732,829.7524117432341,0.00025370340306410486,25.0,45.0
390.0105,0.04843309448818898,829.8005162434166,0.00025370340306410486,25.0,45.0
391.61206,0.048839883858267714,831.7925379360693,0.00025370340306410486,25.0,45.0
393.21362,0.04918319488188976,832.2164050685717,0.00025370340306410486,25.0,45.0
394.81519,0.049536692913385826,830.1181623820202,0.00025370340306410486,25.0,45.0
396.41675,0.049829072834645674,831.4789070240392,0.00025370340306410486,25.0,45.0
398.01831,0.0502400216535433,833.7279553631954,0.00025370340306410486,25.0,45.0
399.61987,0.0506556811023622,835.0666162590603,0.00025370340306410486,25.0,45.0
401.22144,0.0509743562992126,833.739714241018,0.00025370340306410486,25.0,45.0
402.823,0.05128327952755906,833.6996923397821,0.00025370340306410486,25.0,45.0
404.42456,0.05164367519685039,835.9978620222141,0.00025370340306410486,25.0,45.0
406.02612,0.05193959251968504,835.6086979193826,0.00025370340306410486,25.0,45.0
407.62769,0.05232820866141732,837.8376701256714,0.00025370340306410486,25.0,45.0
409.22925,0.052778358267716534,838.326667361944,0.00025370340306410486,25.0,45.0
410.83081,0.053152683070866145,839.1187359858164,0.00025370340306410486,25.0,45.0
412.43237,0.05353928543307086,839.6644939250143,0.00025370340306410486,25.0,45.0
414.03394,0.0539034842519685,840.3548260937582,0.00025370340306410486,25.0,45.0
415.6355,0.05430259448818897,841.5025812170829,0.00025370340306410486,25.0,45.0
417.23706,0.054636545275590545,839.1381342232884,0.00025370340306410486,25.0,45.0
418.83862,0.055011415354330705,839.1723940136623,0.00025370340306410486,25.0,45.0
420.44019,0.05531886614173229,837.6347447463107,0.00025370340306410486,25.0,45.0
422.04175,0.055638748031496064,841.5362674036606,0.00025370340306410486,25.0,45.0
423.64331,0.05604303937007874,842.0533190801481,0.00025370340306410486,25.0,45.0
425.24487,0.05640162204724409,841.4447254523648,0.00025370340306410486,25.0,45.0
426.84644,0.05673136023622047,842.6936173541222,0.00025370340306410486,25.0,45.0
428.448,0.0571112342519685,843.9896229858686,0.00025370340306410486,25.0,45.0
430.04956,0.05746227952755906,844.8394170099598,0.00025370340306410486,25.0,45.0
431.65112,0.057786169291338584,845.4939771601398,0.00025370340306410486,25.0,45.0
433.25269,0.05816047637795276,844.1969546853002,0.00025370340306410486,25.0,45.0
434.85425,0.058560970472440944,844.7991865255254,0.00025370340306410486,25.0,45.0
436.45581,0.0589267657480315,846.3718516973457,0.00025370340306410486,25.0,45.0
438.05737,0.05929975787401574,847.2981957553319,0.00025370340306410486,25.0,45.0
439.65894,0.05968789173228346,846.830917244616,0.00025370340306410486,25.0,45.0
441.2605,0.06002513976377953,846.4137247744694,0.00025370340306410486,25.0,45.0
442.86206,0.06039087401574804,847.7348125358502,0.00025370340306410486,25.0,45.0
444.46362,0.06071279921259842,848.3208270323826,0.00025370340306410486,25.0,45.0
446.06519,0.06111187401574803,849.2769724148719,0.00025370340306410486,25.0,45.0
447.66675,0.061477832677165355,849.429238149867,0.00025370340306410486,25.0,45.0
449.26831,0.06179350196850394,847.881524743182,0.00025370340306410486,25.0,45.0
450.86987,0.062160094488188974,848.9907701934609,0.00025370340306410486,25.0,45.0
452.47144,0.06254564763779528,852.4993481775043,0.00025370340306410486,25.0,45.0
454.073,0.06293365748031496,849.9416488501852,0.00025370340306410486,25.0,45.0
455.67456,0.06325332874015749,850.8952651613913,0.00025370340306410486,25.0,45.0
457.27612,0.06363810236220473,852.8105021640507,0.00025370340306410486,25.0,45.0
458.87769,0.06396929527559056,853.1100537101737,0.00025370340306410486,25.0,45.0
460.47925,0.06436923228346457,854.8682014913699,0.00025370340306410486,25.0,45.0
462.08081,0.06470587598425197,852.5192157271732,0.00025370340306410486,25.0,45.0
463.68237,0.0650379311023622,854.6489805496168,0.00025370340306410486,25.0,45.0
465.28394,0.06532065354330709,852.1382385148877,0.00025370340306410486,25.0,45.0
466.8855,0.0656651811023622,853.7739740313917,0.00025370340306410486,25.0,45.0
468.48706,0.06600224803149607,855.5709443604318,0.00025370340306410486,25.0,45.0
470.08862,0.06637539173228346,855.6234551806851,0.00025370340306410486,25.0,45.0
471.69019,0.06673129527559055,856.0909422745998,0.00025370340306410486,25.0,45.0
473.29175,0.06715254133858267,858.2889138029932,0.00025370340306410486,25.0,45.0
474.89331,0.06757278937007874,857.0319393022893,0.00025370340306410486,25.0,45.0
476.49487,0.06791649999999999,856.2855243260157,0.00025370340306410486,25.0,45.0
478.09644,0.0683166909448819,858.9268133701831,0.00025370340306410486,25.0,45.0
479.698,0.06870756496062992,858.706810241435,0.00025370340306410486,25.0,45.0
481.29956,0.06906901181102362,859.377431297909,0.00025370340306410486,25.0,45.0
482.90112,0.0694194409448819,858.8704176878553,0.00025370340306410486,25.0,45.0
484.50269,0.06977059251968504,858.688480992856,0.00025370340306410486,25.0,45.0
486.10425,0.07011956102362205,859.7556447828127,0.00025370340306410486,25.0,45.0
487.70581,0.07046277559055118,860.1612087396361,0.00025370340306410486,25.0,45.0
489.30737,0.07082804133858267,863.0866402461281,0.00025370340306410486,25.0,45.0
490.90894,0.07121275590551181,860.678338634823,0.00025370340306410486,25.0,45.0
492.5105,0.07155092913385826,862.4518694269177,0.00025370340306410486,25.0,45.0
494.11206,0.0718999566929134,860.7708713563122,0.00025370340306410486,25.0,45.0
495.71362,0.07226241929133859,863.5982166136517,0.00025370340306410486,25.0,45.0
497.31519,0.07264677952755906,862.7558794389112,0.00025370340306410486,25.0,45.0
498.91675,0.07299062204724409,863.1953642384107,0.00025370340306410486,25.0,45.0
500.51831,0.07335980708661417,864.3508630129843,0.00025370340306410486,25.0,45.0
502.11987,0.0736746909448819,863.4716066120874,0.00025370340306410486,25.0,45.0
503.72144,0.07401522244094488,864.626818584763,0.00025370340306410486,25.0,45.0
505.323,0.07433998622047244,864.6960160609063,0.00025370340306410486,25.0,45.0
506.92456,0.07472543307086614,867.0236741930437,0.00025370340306410486,25.0,45.0
508.52612,0.07511649015748031,868.7194816707514,0.00025370340306410486,25.0,45.0
510.12769,0.07544967125984252,867.1561245241696,0.00025370340306410486,25.0,45.0
511.72925,0.07586140748031496,868.0912290764979,0.00025370340306410486,25.0,45.0
513.33081,0.07622040157480316,867.634692600511,0.00025370340306410486,25.0,45.0
514.93237,0.07659961220472442,868.0435417427126,0.00025370340306410486,25.0,45.0
516.53394,0.0769256968503937,868.4173228346457,0.00025370340306410486,25.0,45.0
518.1355,0.07733206889763779,870.0527194034521,0.00025370340306410486,25.0,45.0
519.73706,0.07771491732283464,870.4006622516556,0.00025370340306410486,25.0,45.0
521.33862,0.07809520866141732,871.6043698180112,0.00025370340306410486,25.0,45.0
522.94019,0.07849280511811023,871.3979506700736,0.00025370340306410486,25.0,45.0
524.54175,0.0788253188976378,870.7317359336705,0.00025370340306410486,25.0,45.0
526.14331,0.07920474015748032,873.0491474161756,0.00025370340306410486,25.0,45.0
527.74487,0.07959788976377952,872.0645304270741,0.00025370340306410486,25.0,45.0
529.34644,0.07999054133858267,874.0586379517131,0.00025370340306410486,25.0,45.0
530.948,0.08036472047244093,873.4410491734891,0.00025370340306410486,25.0,45.0
532.54956,0.08072306299212598,872.30909422746,0.00025370340306410486,25.0,45.0
534.15112,0.08106282677165354,873.4224070501122,0.00025370340306410486,25.0,45.0
535.75269,0.08142438582677165,873.4042603118319,0.00025370340306410486,25.0,45.0
537.35425,0.08173809645669292,875.3923971424102,0.00025370340306410486,25.0,45.0
538.95581,0.08207783070866141,874.5217969442562,0.00025370340306410486,25.0,45.0
540.55737,0.08239287401574803,876.5750899515044,0.00025370340306410486,25.0,45.0
542.15894,0.08277041732283465,875.1558637951713,0.00025370340306410486,25.0,45.0
543.7605,0.0831251122047244,876.131668144131,0.00025370340306410486,25.0,45.0
545.36206,0.0834363877952756,876.0794180528758,0.00025370340306410486,25.0,45.0
546.96362,0.08381787598425197,877.9817228972206,0.00025370340306410486,25.0,45.0
548.56519,0.08419170078740157,877.9890493820723,0.00025370340306410486,25.0,45.0
550.16675,0.08456976771653543,879.1803462481097,0.00025370340306410486,25.0,45.0
551.76831,0.08494300787401574,878.9298638994629,0.00025370340306410486,25.0,45.0
553.36987,0.08534188385826771,878.2440423423893,0.00025370340306410486,25.0,45.0
554.97144,0.0857643779527559,878.5925587943892,0.00025370340306410486,25.0,45.0
556.573,0.08615251181102361,880.0816863951609,0.00025370340306410486,25.0,45.0
558.17456,0.08651253346456693,880.7971789122386,0.00025370340306410486,25.0,45.0
559.77612,0.0868976811023622,878.704854773948,0.00025370340306410486,25.0,45.0
561.37769,0.08721927755905512,880.5481566459821,0.00025370340306410486,25.0,45.0
562.97925,0.08760565748031496,882.5809042081661,0.00025370340306410486,25.0,45.0
564.58081,0.08797599212598425,882.155759503572,0.00025370340306410486,25.0,45.0
566.18237,0.08831592716535433,882.0335297491787,0.00025370340306410486,25.0,45.0
567.78394,0.08864266141732283,885.3016895239089,0.00025370340306410486,25.0,45.0
569.3855,0.08903047244094488,884.0210929759609,0.00025370340306410486,25.0,45.0
570.98706,0.0893676437007874,883.0561349533295,0.00025370340306410486,25.0,45.0
572.58862,0.08969268897637794,884.8259894665484,0.00025370340306410486,25.0,45.0
574.19019,0.09000965551181102,884.9479584919435,0.00025370340306410486,25.0,45.0
575.79175,0.09036957677165354,884.5497470928717,0.00025370340306410486,25.0,45.0
577.39331,0.09071675,884.9533034364082,0.00025370340306410486,25.0,45.0
578.99487,0.09108367125984251,886.8782917036033,0.00025370340306410486,25.0,45.0
580.59644,0.09150814173228346,886.6924701465297,0.00025370340306410486,25.0,45.0
582.198,0.09192091535433071,886.6495802263128,0.00025370340306410486,25.0,45.0
583.79956,0.09228139566929133,888.6711685873703,0.00025370340306410486,25.0,45.0
585.40112,0.09263692322834646,887.6511185274027,0.00025370340306410486,25.0,45.0
587.00269,0.09299954330708662,887.8700787401574,0.00025370340306410486,25.0,45.0
588.60425,0.09331961220472441,887.6582364290556,0.00025370340306410486,25.0,45.0
590.20581,0.09371228740157479,889.1900975126454,0.00025370340306410486,25.0,45.0
591.80737,0.09410857086614173,888.6857433383741,0.00025370340306410486,25.0,45.0
593.40894,0.09449071456692913,891.0612713145956,0.00025370340306410486,25.0,45.0
595.0105,0.09482598622047243,887.8485685977994,0.00025370340306410486,25.0,45.0
596.61206,0.09516254724409448,890.229832611983,0.00025370340306410486,25.0,45.0
598.21362,0.09561039763779527,890.6553423371747,0.00025370340306410486,25.0,45.0
599.81519,0.096012281496063,891.4516086979194,0.00025370340306410486,25.0,45.0
601.41675,0.09641168700787402,891.0713354539291,0.00025370340306410486,25.0,45.0
603.01831,0.09686149015748031,889.3720863534442,0.00025370340306410486,25.0,45.0
604.61987,0.09722221456692913,889.6405590029723,0.00025370340306410486,25.0,45.0
606.22144,0.09756520078740157,892.0393179329405,0.00025370340306410486,25.0,45.0
607.823,0.09786033070866142,890.9527559055118,0.00025370340306410486,25.0,45.0
609.42456,0.09817804330708661,891.4838087292069,0.00025370340306410486,25.0,45.0
611.02612,0.09853679133858269,892.6221515356939,0.00025370340306410486,25.0,45.0
612.62769,0.09890507283464567,893.8352192730875,0.00025370340306410486,25.0,45.0
614.22925,0.09929731299212599,892.5908901288001,0.00025370340306410486,25.0,45.0
615.83081,0.09964759645669291,895.0158783959952,0.00025370340306410486,25.0,45.0
617.43237,0.10002727165354332,895.410465661991,0.00025370340306410486,25.0,45.0
619.03394,0.10037866929133858,894.8008551911144,0.00025370340306410486,25.0,45.0
620.6355,0.10072351968503936,894.9711372998904,0.00025370340306410486,25.0,45.0
622.23706,0.10108094685039369,895.9121864733795,0.00025370340306410486,25.0,45.0
623.83862,0.1014779527559055,896.6310423945351,0.00025370340306410486,25.0,45.0
625.44019,0.10187586023622047,896.8900505814257,0.00025370340306410486,25.0,45.0
627.04175,0.10227117519685039,896.7501434009491,0.00025370340306410486,25.0,45.0
628.64331,0.10261912204724408,896.6857172654743,0.00025370340306410486,25.0,45.0
630.24487,0.10304267913385827,896.4569536423842,0.00025370340306410486,25.0,45.0
631.84644,0.10338091141732283,896.0213537049591,0.00025370340306410486,25.0,45.0
633.448,0.10373620472440946,897.9214423528185,0.00025370340306410486,25.0,45.0
635.04956,0.10413172047244093,897.9678521145122,0.00025370340306410486,25.0,45.0
636.65112,0.10450612598425198,899.4137769202691,0.00025370340306410486,25.0,45.0
638.25269,0.10491520472440945,899.1618866350316,0.00025370340306410486,25.0,45.0
639.85425,0.10530776181102362,900.8695572821609,0.00025370340306410486,25.0,45.0
641.45581,0.10570016732283465,899.0574907441206,0.00025370340306410486,25.0,45.0
643.05737,0.10607669685039371,899.3684361474683,0.00025370340306410486,25.0,45.0
644.65894,0.10638786023622046,897.3602753298222,0.00025370340306410486,25.0,45.0
646.2605,0.10673383858267715,901.9297856807634,0.00025370340306410486,25.0,45.0
647.86206,0.10710119291338584,901.8248161860563,0.00025370340306410486,25.0,45.0
649.46362,0.10748255708661417,903.6125567085571,0.00025370340306410486,25.0,45.0
651.06519,0.10786704133858267,902.0950357198728,0.00025370340306410486,25.0,45.0
652.66675,0.1082539094488189,902.9042603118319,0.00025370340306410486,25.0,45.0
654.26831,0.10864579724409448,902.5810867184649,0.00025370340306410486,25.0,45.0
655.86987,0.10898032283464566,903.0009646972937,0.00025370340306410486,25.0,45.0
657.47144,0.10935985629921259,903.2862022214111,0.00025370340306410486,25.0,45.0
659.073,0.10979891338582676,904.6559159409709,0.00025370340306410486,25.0,45.0
660.67456,0.11013912795275592,904.0834072065495,0.00025370340306410486,25.0,45.0
662.27612,0.11056330708661417,904.7506909318455,0.00025370340306410486,25.0,45.0
663.87769,0.1109927657480315,907.3397820305574,0.00025370340306410486,25.0,45.0
665.47925,0.11137921062992126,904.4454815664598,0.00025370340306410486,25.0,45.0
667.08081,0.11171275,905.1278354278563,0.00025370340306410486,25.0,45.0
668.68237,0.11206786614173228,904.3678103978724,0.00025370340306410486,25.0,45.0
670.28394,0.11247079724409448,906.43333159514,0.00025370340306410486,25.0,45.0
671.8855,0.11279544291338582,905.6389164102832,0.00025370340306410486,25.0,45.0
673.48706,0.11320251377952756,907.8805339729885,0.00025370340306410486,25.0,45.0
675.08862,0.11368992322834647,907.0244303071388,0.00025370340306410486,25.0,45.0
676.69019,0.1140081968503937,906.3113886426448,0.00025370340306410486,25.0,45.0
678.29175,0.11438078543307087,907.4301767742609,0.00025370340306410486,25.0,45.0
679.89331,0.11478504133858268,907.6593836366482,0.00025370340306410486,25.0,45.0
681.49487,0.11513405708661417,909.9431089325756,0.00025370340306410486,25.0,45.0
683.09644,0.1155386751968504,908.9607342128592,0.00025370340306410486,25.0,45.0
684.698,0.11589800590551182,907.3769619857121,0.00025370340306410486,25.0,45.0
686.29956,0.11628219685039369,908.93030713876,0.00025370340306410486,25.0,45.0
687.90112,0.11667496653543306,910.8744589873286,0.00025370340306410486,25.0,45.0
689.50269,0.11705247047244094,908.7355425770455,0.00025370340306410486,25.0,45.0
691.10425,0.1174423405511811,910.5525629660531,0.00025370340306410486,25.0,45.0
692.70581,0.1178373622047244,909.804088230693,0.00025370340306410486,25.0,45.0
694.30737,0.11827964566929133,911.4294467330657,0.00025370340306410486,25.0,45.0
695.90894,0.11861751377952756,910.2813265891433,0.00025370340306410486,25.0,45.0
697.5105,0.1190567342519685,913.2749908744851,0.00025370340306410486,25.0,45.0
699.11206,0.11945392716535431,910.3136569849298,0.00025370340306410486,25.0,45.0
700.71362,0.11985406299212599,912.2385148876258,0.00025370340306410486,25.0,45.0
702.31519,0.1202059901574803,912.6582364290557,0.00025370340306410486,25.0,45.0
703.91675,0.12059028740157479,913.6846743494812,0.00025370340306410486,25.0,45.0
705.51831,0.12096045669291339,912.7110861970068,0.00025370340306410486,25.0,45.0
707.11987,0.12135780314960629,914.1645721437138,0.00025370340306410486,25.0,45.0
708.72144,0.12177512795275591,914.2566616259061,0.00025370340306410486,25.0,45.0
710.323,0.12218263385826772,914.017260259686,0.00025370340306410486,25.0,45.0
711.92456,0.12256566535433071,912.6383167335872,0.00025370340306410486,25.0,45.0
713.52612,0.12293592913385826,915.7328309954634,0.00025370340306410486,25.0,45.0
715.12769,0.12328989566929134,914.773035406998,0.00025370340306410486,25.0,45.0
716.72925,0.12366911417322836,913.4220941753142,0.00025370340306410486,25.0,45.0
718.33081,0.12405350393700787,917.4137508473693,0.00025370340306410486,25.0,45.0
719.93237,0.12448898228346457,915.8822287114773,0.00025370340306410486,25.0,45.0
721.53394,0.12483761023622048,916.0414298378265,0.00025370340306410486,25.0,45.0
723.1355,0.12523653937007875,914.7105386661104,0.00025370340306410486,25.0,45.0
724.73706,0.12558748031496064,914.7604421963812,0.00025370340306410486,25.0,45.0
726.33862,0.1259537775590551,917.498800646608,0.00025370340306410486,25.0,45.0
727.94019,0.12638335433070866,917.4019137508475,0.00025370340306410486,25.0,45.0
729.54175,0.12681250787401574,918.6676226729937,0.00025370340306410486,25.0,45.0
731.14331,0.12724385433070864,917.4125254210772,0.00025370340306410486,25.0,45.0
732.74487,0.12762575787401576,916.8549303853575,0.00025370340306410486,25.0,45.0
734.34644,0.12803554133858266,918.0717526203264,0.00025370340306410486,25.0,45.0
735.948,0.12841019291338582,919.5480784272827,0.00025370340306410486,25.0,45.0
737.54956,0.12878847244094488,919.0015383010898,0.00025370340306410486,25.0,45.0
739.15112,0.12915818503937007,918.613495332951,0.00025370340306410486,25.0,45.0
740.75269,0.12961545078740158,920.2989518694269,0.00025370340306410486,25.0,45.0
742.35425,0.13005958858267716,920.2477707670648,0.00025370340306410486,25.0,45.0
743.95581,0.13048349606299212,919.1420190853628,0.00025370340306410486,25.0,45.0
745.55737,0.13085778543307086,918.2817959013402,0.00025370340306410486,25.0,45.0
747.15894,0.13130289566929135,920.6661625906033,0.00025370340306410486,25.0,45.0
748.7605,0.1316713307086614,918.976977629452,0.00025370340306410486,25.0,45.0
750.36206,0.13209801968503937,920.5449757522032,0.00025370340306410486,25.0,45.0
751.96362,0.1324102874015748,919.2706888460134,0.00025370340306410486,25.0,45.0
753.56519,0.13274909448818897,919.6233248161861,0.00025370340306410486,25.0,45.0
755.16675,0.13311913582677165,920.9032956145383,0.00025370340306410486,25.0,45.0
756.76831,0.133548312992126,924.1587057412526,0.00025370340306410486,25.0,45.0
758.36987,0.13398789763779528,920.9187046983366,0.00025370340306410486,25.0,45.0
759.97144,0.13439891141732282,921.6568284924649,0.00025370340306410486,25.0,45.0
761.573,0.13481317519685038,922.6662668822026,0.00025370340306410486,25.0,45.0
763.17456,0.13515511614173228,922.5946446263754,0.00025370340306410486,25.0,45.0
764.77612,0.1356008838582677,921.916227772853,0.00025370340306410486,25.0,45.0
766.37769,0.13601177952755905,923.959847734265,0.00025370340306410486,25.0,45.0
767.97925,0.13651365551181102,925.5331386556813,0.00025370340306410486,25.0,45.0
769.58081,0.136907844488189,922.2459456640768,0.00025370340306410486,25.0,45.0
771.18237,0.13736121456692912,924.681363091203,0.00025370340306410486,25.0,45.0
772.78394,0.13778317716535432,922.8153517234186,0.00025370340306410486,25.0,45.0
774.3855,0.13817593307086615,924.4421703081817,0.00025370340306410486,25.0,45.0
775.98706,0.13857483858267716,924.3261198310477,0.00025370340306410486,25.0,45.0
777.58862,0.1390006594488189,925.0737341607133,0.00025370340306410486,25.0,45.0
779.19019,0.13943092716535432,924.5084997653439,0.00025370340306410486,25.0,45.0
780.79175,0.1398055098425197,924.7804140376493,0.00025370340306410486,25.0,45.0
782.39331,0.1401677618110236,923.3609271523179,0.00025370340306410486,25.0,45.0
783.99487,0.14057097244094488,925.2174740574646,0.00025370340306410486,25.0,45.0
785.59644,0.14101476968503937,927.0803827501695,0.00025370340306410486,25.0,45.0
787.198,0.14146774015748032,926.3617875580122,0.00025370340306410486,25.0,45.0
788.79956,0.14187645472440943,926.6367784324973,0.00025370340306410486,25.0,45.0
790.40112,0.14222631496062993,926.1960421338061,0.00025370340306410486,25.0,45.0
792.00269,0.14260620078740158,926.8399645408563,0.00025370340306410486,25.0,45.0
793.60425,0.14306996653543308,926.7151274964801,0.00025370340306410486,25.0,45.0
795.20581,0.14344601574803148,926.7429472805966,0.00025370340306410486,25.0,45.0
796.80737,0.14382895275590551,926.9817750430202,0.00025370340306410486,25.0,45.0
798.40894,0.1442327283464567,928.7956927569484,0.00025370340306410486,25.0,45.0
800.0105,0.14465846653543307,929.1198049747093,0.00025370340306410486,25.0,45.0
801.61206,0.14510154724409446,927.776059863378,0.00025370340306410486,25.0,45.0
803.21362,0.14553053740157482,927.6535433070866,0.00025370340306410486,25.0,45.0
804.81519,0.14598597244094488,928.1075246388904,0.00025370340306410486,25.0,45.0
806.41675,0.14644349606299212,929.4146112530636,0.00025370340306410486,25.0,45.0
808.01831,0.14687558267716536,930.299395108724,0.00025370340306410486,25.0,45.0
809.61987,0.14734103937007875,930.005449236064,0.00025370340306410486,25.0,45.0
811.22144,0.14778012992125983,929.2906606872816,0.00025370340306410486,25.0,45.0
812.823,0.14824194881889766,930.3142827345257,0.00025370340306410486,25.0,45.0
814.42456,0.14871065551181104,929.1917401053346,0.00025370340306410486,25.0,45.0
816.02612,0.14909273622047245,928.6510663816031,0.00025370340306410486,25.0,45.0
817.62769,0.1494993248031496,929.2676122438337,0.00025370340306410486,25.0,45.0
819.22925,0.14999137007874017,930.0679459769516,0.00025370340306410486,25.0,45.0
820.83081,0.15042178937007875,932.3083902591646,0.00025370340306410486,25.0,45.0
822.43237,0.1508428464566929,930.2593471345884,0.00025370340306410486,25.0,45.0
824.03394,0.15123595669291337,930.458022631277,0.00025370340306410486,25.0,45.0
825.6355,0.1516140590551181,931.1898107107472,0.00025370340306410486,25.0,45.0
827.23706,0.15204668503937008,932.5098034103353,0.00025370340306410486,25.0,45.0
828.83862,0.15242887007874015,932.8136830578297,0.00025370340306410486,25.0,45.0
830.44019,0.1528738996062992,930.3984460551703,0.00025370340306410486,25.0,45.0
832.04175,0.15328668503937007,931.5239088491422,0.00025370340306410486,25.0,45.0
833.64331,0.15373383661417322,931.2742086874903,0.00025370340306410486,25.0,45.0
835.24487,0.1541654783464567,930.4973666371174,0.00025370340306410486,25.0,45.0
836.84644,0.15459185039370077,931.9413099024873,0.00025370340306410486,25.0,45.0
838.448,0.15501432677165353,932.6828231735933,0.00025370340306410486,25.0,45.0
840.04956,0.1554855807086614,933.1930698232258,0.00025370340306410486,25.0,45.0
841.65112,0.15595835826771653,932.4495750117329,0.00025370340306410486,25.0,45.0
843.25269,0.15643110039370078,933.4193565208323,0.00025370340306410486,25.0,45.0
844.85425,0.15684542125984252,933.176513531835,0.00025370340306410486,25.0,45.0
846.45581,0.1572680748031496,931.4107524638891,0.00025370340306410486,25.0,45.0
848.05737,0.1577106279527559,933.3751108098243,0.00025370340306410486,25.0,45.0
849.65894,0.15817980314960628,933.8735464358347,0.00025370340306410486,25.0,45.0
851.2605,0.1586243031496063,933.8835845022684,0.00025370340306410486,25.0,45.0
852.86206,0.15911575,934.0247171090369,0.00025370340306410486,25.0,45.0
854.46362,0.15956162204724408,934.7195598894509,0.00025370340306410486,25.0,45.0
856.06519,0.16001623622047242,933.3131355269333,0.00025370340306410486,25.0,45.0
857.66675,0.1604317559055118,934.1272096782604,0.00025370340306410486,25.0,45.0
859.26831,0.1608754468503937,934.8325598373051,0.00025370340306410486,25.0,45.0
860.86987,0.1612627598425197,934.4715023204882,0.00025370340306410486,25.0,45.0
862.47144,0.16172183267716536,935.632893570423,0.00025370340306410486,25.0,45.0
864.073,0.16223138188976377,935.8080513114668,0.00025370340306410486,25.0,45.0
865.67456,0.16268679527559055,934.7864629504094,0.00025370340306410486,25.0,45.0
867.27612,0.1631272125984252,936.3415549877458,0.00025370340306410486,25.0,45.0
868.87769,0.16354217913385827,935.3234603952651,0.00025370340306410486,25.0,45.0
870.47925,0.16398675000000001,935.4747614329666,0.00025370340306410486,25.0,45.0
872.08081,0.16444249212598425,936.9093445272982,0.00025370340306410486,25.0,45.0
873.68237,0.16485985433070866,938.2193513062523,0.00025370340306410486,25.0,45.0
875.28394,0.16536226968503936,938.3293528706263,0.00025370340306410486,25.0,45.0
876.8855,0.16585156692913386,938.8992543150649,0.00025370340306410486,25.0,45.0
878.48706,0.16635255118110237,937.5910987119988,0.00025370340306410486,25.0,45.0
880.08862,0.16682752165354328,937.4155238045576,0.00025370340306410486,25.0,45.0
881.69019,0.16730462992125986,938.7306930176775,0.00025370340306410486,25.0,45.0
883.29175,0.16779004330708663,937.8617614851123,0.00025370340306410486,25.0,45.0
884.89331,0.16826027559055118,938.0276372738176,0.00025370340306410486,25.0,45.0
886.49487,0.16871696653543305,937.5530844240496,0.00025370340306410486,25.0,45.0
888.09644,0.16916708661417323,939.0450278980028,0.00025370340306410486,25.0,45.0
889.698,0.1696084311023622,937.5676591750534,0.00025370340306410486,25.0,45.0
891.29956,0.17005501968503936,938.2233665328257,0.00025370340306410486,25.0,45.0
892.90112,0.17047938582677163,938.2278771444961,0.00025370340306410486,25.0,45.0
894.50269,0.17088361811023622,937.0399176096365,0.00025370340306410486,25.0,45.0
896.10425,0.17138363976377952,938.9420399436825,0.00025370340306410486,25.0,45.0
897.70581,0.17183155511811024,938.6917922511342,0.00025370340306410486,25.0,45.0
899.30737,0.17222047637795274,938.5025551441832,0.00025370340306410486,25.0,45.0
900.90894,0.17278667322834645,939.8295093080253,0.00025370340306410486,25.0,45.0
902.5105,0.17324783464566929,938.5831464775513,0.00025370340306410486,25.0,45.0
904.11206,0.17376039960629922,940.3443447880273,0.00025370340306410486,25.0,45.0
905.71362,0.17423656692913386,939.2682640663295,0.00025370340306410486,25.0,45.0
907.31519,0.17474277362204724,939.4909787766595,0.00025370340306410486,25.0,45.0
908.91675,0.17524895472440943,939.7366897846379,0.00025370340306410486,25.0,45.0
910.51831,0.17581231299212596,940.2496219429526,0.00025370340306410486,25.0,45.0
912.11987,0.17631855314960632,938.7310058924753,0.00025370340306410486,25.0,45.0
913.72144,0.1767674409448819,940.2257391667101,0.00025370340306410486,25.0,45.0
915.323,0.17731160433070867,941.4398237471971,0.00025370340306410486,25.0,45.0
916.92456,0.17775454330708662,940.9848255723001,0.00025370340306410486,25.0,45.0
918.52612,0.17821967125984253,941.2677686812327,0.00025370340306410486,25.0,45.0
920.12769,0.17872119488188978,940.2316055691714,0.00025370340306410486,25.0,45.0
921.72925,0.17921898818897639,938.9883193408771,0.00025370340306410486,25.0,45.0
923.33081,0.17964784842519685,940.3217395838766,0.00025370340306410486,25.0,45.0
924.93237,0.18016174999999998,940.7406007196121,0.00025370340306410486,25.0,45.0
926.53394,0.18067863188976377,942.5428377744173,0.00025370340306410486,25.0,45.0
928.1355,0.18118011023622047,940.6022057673255,0.00025370340306410486,25.0,45.0
929.73706,0.1816297618110236,940.3000469312198,0.00025370340306410486,25.0,45.0
931.33862,0.18213775000000001,941.3423893205402,0.00025370340306410486,25.0,45.0
932.94019,0.18265314173228347,941.9239974970017,0.00025370340306410486,25.0,45.0
934.54175,0.1830839153543307,940.1938520102206,0.00025370340306410486,25.0,45.0
936.14331,0.18360695669291338,940.2890963132919,0.00025370340306410486,25.0,45.0
937.74487,0.18412710236220473,943.1674140897951,0.00025370340306410486,25.0,45.0
939.34644,0.18468304330708663,941.3614746832143,0.00025370340306410486,25.0,45.0
940.948,0.18519611417322834,943.9413359753872,0.00025370340306410486,25.0,45.0
942.54956,0.18568609251968504,940.6703864003755,0.00025370340306410486,25.0,45.0
944.15112,0.18616986417322834,941.865307399489,0.00025370340306410486,25.0,45.0
945.75269,0.18667092913385827,942.9963237211242,0.00025370340306410486,25.0,45.0
947.35425,0.18718674409448818,942.497131981019,0.00025370340306410486,25.0,45.0
948.95581,0.1877956968503937,942.6550555352766,0.00025370340306410486,25.0,45.0
950.55737,0.18835027952755906,941.6275486259583,0.00025370340306410486,25.0,45.0
952.15894,0.18887846062992125,942.9118475256819,0.00025370340306410486,25.0,45.0
953.7605,0.1894542440944882,943.8601188924232,0.00025370340306410486,25.0,45.0
955.36206,0.18991627362204724,940.582416436356,0.00025370340306410486,25.0,45.0
956.96362,0.19046267716535434,943.2473796735674,0.00025370340306410486,25.0,45.0
958.56519,0.1909592381889764,943.5480784272827,0.00025370340306410486,25.0,45.0
960.16675,0.1914994094488189,943.4569275694844,0.00025370340306410486,25.0,45.0
961.76831,0.19200264763779526,941.5053970902643,0.00025370340306410486,25.0,45.0
963.36987,0.19245595866141732,943.8061219168795,0.00025370340306410486,25.0,45.0
964.97144,0.193021968503937,943.3896334150285,0.00025370340306410486,25.0,45.0
966.573,0.19352377362204723,941.9014444386505,0.00025370340306410486,25.0,45.0
968.17456,0.19404860039370078,944.3452312666215,0.00025370340306410486,25.0,45.0
969.77612,0.19455620078740157,943.3247640402566,0.00025370340306410486,25.0,45.0
971.37769,0.1951034153543307,943.5222401835532,0.00025370340306410486,25.0,45.0
972.97925,0.19564587598425198,943.5823121447568,0.00025370340306410486,25.0,45.0
974.58081,0.19616431889763777,942.7978307347344,0.00025370340306410486,25.0,45.0
976.18237,0.19678069881889765,944.861213954216,0.00025370340306410486,25.0,45.0
977.78394,0.19745537401574803,945.388642644835,0.00025370340306410486,25.0,45.0
979.3855,0.19805531496062992,944.3836627209679,0.00025370340306410486,25.0,45.0
980.98706,0.1986045472440945,942.2544975752204,0.00025370340306410486,25.0,45.0
982.58862,0.19906391732283465,942.9757000573603,0.00025370340306410486,25.0,45.0
984.19019,0.19970125984251966,945.8750847369245,0.00025370340306410486,25.0,45.0
984.39038,0.19980364173228346,946.6581060645565,0.00025370340306410486,25.0,45.0