File: datasets/am_bench_2022/csv/45-XY.08-2.csv
Time(s),Strain(%),Stress(MPa),SR(s-1),Temp(C),Angle(deg)
80.003418,1.4547423228346457e-06,358.40047374654563,0.00025370340306410486,25.0,45.0
81.705078,3.911797637795276e-05,370.15265166469277,0.00025370340306410486,25.0,45.0
83.106445,6.697891338582677e-05,382.5939728911699,0.00025370340306410486,25.0,45.0
84.507813,0.00011491553543307085,392.51175154625616,0.00025370340306410486,25.0,45.0
85.90918,0.00014048233267716534,402.7874457165417,0.00025370340306410486,25.0,45.0
87.310547,0.00017194398622047245,410.8077378602448,0.00025370340306410486,25.0,45.0
88.711914,0.00022215537401574804,421.5116199499935,0.00025370340306410486,25.0,45.0
90.113281,0.00023859484251968503,433.38186603500463,0.00025370340306410486,25.0,45.0
91.514648,0.0002735428937007874,443.0652191077774,0.00025370340306410486,25.0,45.0
92.916016,0.00030400187007874015,452.14388735359915,0.00025370340306410486,25.0,45.0
94.317383,0.0003341569291338583,460.8368469535465,0.00025370340306410486,25.0,45.0
95.71875,0.0003940514173228346,470.95781023818927,0.00025370340306410486,25.0,45.0
97.120117,0.0003965050787401574,478.4575075667852,0.00025370340306410486,25.0,45.0
98.521484,0.0004345030905511811,486.75365179628903,0.00025370340306410486,25.0,45.0
99.922852,0.0004832197440944882,497.8187393078037,0.00025370340306410486,25.0,45.0
101.32422,0.0005079048818897638,504.99673641268595,0.00025370340306410486,25.0,45.0
102.72559,0.0005394762598425197,513.3538360310567,0.00025370340306410486,25.0,45.0
104.12695,0.0005603224803149606,521.492696407422,0.00025370340306410486,25.0,45.0
105.52832,0.0006030813779527559,529.824134754573,0.00025370340306410486,25.0,45.0
106.92969,0.0006447196062992126,538.7991841031716,0.00025370340306410486,25.0,45.0
108.33105,0.0006627030118110236,545.0221081721279,0.00025370340306410486,25.0,45.0
109.73242,0.0006912171653543306,551.0396894328202,0.00025370340306410486,25.0,45.0
111.13379,0.0007141494291338583,557.4866956178446,0.00025370340306410486,25.0,45.0
112.53516,0.0007510035826771653,563.0978286616661,0.00025370340306410486,25.0,45.0
113.93652,0.0007819320078740157,571.865640215818,0.00025370340306410486,25.0,45.0
115.33789,0.0008142013385826772,575.7173838662983,0.00025370340306410486,25.0,45.0
116.73926,0.0008276666535433072,583.6047637847086,0.00025370340306410486,25.0,45.0
118.14063,0.0008486813582677165,588.7570469798658,0.00025370340306410486,25.0,45.0
119.54199,0.0008954839763779527,593.966732464798,0.00025370340306410486,25.0,45.0
120.94336,0.0009240416732283463,597.6176338991974,0.00025370340306410486,25.0,45.0
122.34473,0.0009480620866141732,603.703697854981,0.00025370340306410486,25.0,45.0
123.74609,0.0009788445866141732,607.8424266350836,0.00025370340306410486,25.0,45.0
125.14746,0.0010047579921259842,613.5201473878143,0.00025370340306410486,25.0,45.0
126.54883,0.0010299513779527558,617.3716015265167,0.00025370340306410486,25.0,45.0
127.9502,0.0010632102165354332,620.9158310303987,0.00025370340306410486,25.0,45.0
129.35156,0.001089965216535433,625.6301618634031,0.00025370340306410486,25.0,45.0
130.75293,0.0011039726377952757,630.3516778523491,0.00025370340306410486,25.0,45.0
132.1543,0.0011724642716535434,635.6817739176208,0.00025370340306410486,25.0,45.0
133.55566,0.0011844124999999999,640.1697591788393,0.00025370340306410486,25.0,45.0
134.95703,0.0012269114370078741,646.011896302145,0.00025370340306410486,25.0,45.0
136.3584,0.0012617247440944882,649.2252138439269,0.00025370340306410486,25.0,45.0
137.75977,0.0012804479133858267,650.5640479010397,0.00025370340306410486,25.0,45.0
139.16113,0.0013181651968503937,656.4068430056587,0.00025370340306410486,25.0,45.0
140.5625,0.0013430737598425196,660.182076589025,0.00025370340306410486,25.0,45.0
141.96387,0.0013950105708661416,663.7408343203053,0.00025370340306410486,25.0,45.0
143.36523,0.0014168988582677164,663.9733122779313,0.00025370340306410486,25.0,45.0
144.7666,0.0014528462598425197,668.3851822608239,0.00025370340306410486,25.0,45.0
146.16797,0.001499747342519685,673.3246742992499,0.00025370340306410486,25.0,45.0
147.56934,0.0015531893897637796,674.5912356889064,0.00025370340306410486,25.0,45.0
148.9707,0.0015878257874015749,678.5761284379524,0.00025370340306410486,25.0,45.0
150.37207,0.0016419310433070868,682.8792999078827,0.00025370340306410486,25.0,45.0
151.77344,0.0016833613385826773,684.6432951704172,0.00025370340306410486,25.0,45.0
153.1748,0.0017486982086614173,687.9874983550468,0.00025370340306410486,25.0,45.0
154.57617,0.0018088645669291337,691.4112646400843,0.00025370340306410486,25.0,45.0
155.97754,0.0018534543897637795,694.1628898539282,0.00025370340306410486,25.0,45.0
157.37891,0.0019097808858267716,696.88716936439,0.00025370340306410486,25.0,45.0
158.78027,0.001999005905511811,698.0136860113173,0.00025370340306410486,25.0,45.0
160.18164,0.0020530771653543304,703.3135938939334,0.00025370340306410486,25.0,45.0
161.58301,0.002119513385826772,704.2102908277406,0.00025370340306410486,25.0,45.0
162.98438,0.0022095403543307087,706.6750098697198,0.00025370340306410486,25.0,45.0
164.38574,0.002300824803149606,709.6740886958811,0.00025370340306410486,25.0,45.0
165.78711,0.0023880708661417325,713.1133307014081,0.00025370340306410486,25.0,45.0
167.18848,0.002482283464566929,714.9603105671799,0.00025370340306410486,25.0,45.0
168.58984,0.002597078346456693,716.1537307540467,0.00025370340306410486,25.0,45.0
169.99121,0.0027296679133858265,721.2323463613634,0.00025370340306410486,25.0,45.0
171.39258,0.0028677990157480317,723.0617712856956,0.00025370340306410486,25.0,45.0
172.79395,0.0029844944881889765,724.3308856428479,0.00025370340306410486,25.0,45.0
174.19531,0.003103512204724409,726.4615607316753,0.00025370340306410486,25.0,45.0
175.59668,0.0032500374015748032,729.3821818660351,0.00025370340306410486,25.0,45.0
176.99805,0.003404106496062992,731.2409790761943,0.00025370340306410486,25.0,45.0
178.39941,0.0035754053149606294,733.1645479668377,0.00025370340306410486,25.0,45.0
179.80078,0.003738104133858268,735.6757468087907,0.00025370340306410486,25.0,45.0
181.20215,0.003912607480314961,736.8898539281486,0.00025370340306410486,25.0,45.0
182.60352,0.004129125,737.3836031056718,0.00025370340306410486,25.0,45.0
184.00488,0.004293597244094488,740.5569417028556,0.00025370340306410486,25.0,45.0
185.40625,0.004478275196850393,741.6318199763127,0.00025370340306410486,25.0,45.0
186.80762,0.0046691805118110235,741.5431504145282,0.00025370340306410486,25.0,45.0
188.20898,0.004881849606299212,744.1637583892618,0.00025370340306410486,25.0,45.0
189.61035,0.005097038188976378,744.963863666272,0.00025370340306410486,25.0,45.0
191.01172,0.005312889173228347,745.0001052770102,0.00025370340306410486,25.0,45.0
192.41309,0.005537932677165355,748.7441768653771,0.00025370340306410486,25.0,45.0
193.81445,0.0058142370078740156,749.5138307672063,0.00025370340306410486,25.0,45.0
195.21582,0.006068553543307087,752.4338202395053,0.00025370340306410486,25.0,45.0
196.61719,0.006313835433070867,750.8254243979471,0.00025370340306410486,25.0,45.0
198.01855,0.006593782086614174,753.7060929069614,0.00025370340306410486,25.0,45.0
199.41992,0.006835574015748032,754.5189367021977,0.00025370340306410486,25.0,45.0
200.82129,0.007112867716535433,757.5355441505462,0.00025370340306410486,25.0,45.0
202.22266,0.0073521954724409455,756.0196341623898,0.00025370340306410486,25.0,45.0
203.62402,0.007582070078740157,756.565495459929,0.00025370340306410486,25.0,45.0
205.02539,0.0078752937007874,759.1420186866693,0.00025370340306410486,25.0,45.0
206.42676,0.008164864763779528,760.6735096723254,0.00025370340306410486,25.0,45.0
207.82813,0.008464557677165354,760.9728648506383,0.00025370340306410486,25.0,45.0
209.22949,0.008787964960629922,761.0654033425452,0.00025370340306410486,25.0,45.0
210.63086,0.009078151771653543,762.1198315567839,0.00025370340306410486,25.0,45.0
212.03223,0.009374622637795274,765.4461639689433,0.00025370340306410486,25.0,45.0
213.43359,0.009726313582677166,764.9013554415055,0.00025370340306410486,25.0,45.0
214.83496,0.010049233858267715,765.8236083695224,0.00025370340306410486,25.0,45.0
216.23633,0.010399480708661417,766.9676273193842,0.00025370340306410486,25.0,45.0
217.6377,0.010675163976377952,766.642689827609,0.00025370340306410486,25.0,45.0
219.03906,0.01099004783464567,769.0715094091329,0.00025370340306410486,25.0,45.0
220.44043,0.011313394881889764,768.1778918278721,0.00025370340306410486,25.0,45.0
221.8418,0.011611143897637795,771.5475457297014,0.00025370340306410486,25.0,45.0
223.24316,0.011932978937007874,771.144071588367,0.00025370340306410486,25.0,45.0
224.64453,0.012225811614173228,771.1330964600606,0.00025370340306410486,25.0,45.0
226.0459,0.012495632677165353,771.8160021055403,0.00025370340306410486,25.0,45.0
227.44727,0.012795773818897639,772.7067245690223,0.00025370340306410486,25.0,45.0
228.84863,0.013139544685039372,773.8250822476642,0.00025370340306410486,25.0,45.0
230.25,0.013467131299212598,776.1335438873538,0.00025370340306410486,25.0,45.0
231.65137,0.013853556692913386,775.9449664429532,0.00025370340306410486,25.0,45.0
233.05273,0.014138715944881891,774.59199894723,0.00025370340306410486,25.0,45.0
234.4541,0.014450516929133858,777.7564679563102,0.00025370340306410486,25.0,45.0
235.85547,0.01481927381889764,778.6891959468352,0.00025370340306410486,25.0,45.0
237.25684,0.015189505905511812,779.9608895907357,0.00025370340306410486,25.0,45.0
238.6582,0.015533048228346455,780.2296881168576,0.00025370340306410486,25.0,45.0
240.05957,0.01587128976377953,781.7531254112384,0.00025370340306410486,25.0,45.0
241.46094,0.016268363188976377,782.2552177918147,0.00025370340306410486,25.0,45.0
242.8623,0.016667300787401574,782.3296223187263,0.00025370340306410486,25.0,45.0
244.26367,0.016966302362204724,781.6845111198843,0.00025370340306410486,25.0,45.0
245.66504,0.017269801968503935,781.1703118831425,0.00025370340306410486,25.0,45.0
247.06641,0.01757669251968504,784.4948545861298,0.00025370340306410486,25.0,45.0
248.46777,0.017914189173228345,784.5352283195158,0.00025370340306410486,25.0,45.0
249.86914,0.01825365255905512,785.2358731412029,0.00025370340306410486,25.0,45.0
251.27051,0.018580889960629923,786.5068561652851,0.00025370340306410486,25.0,45.0
252.67188,0.01891778976377953,784.6933543887354,0.00025370340306410486,25.0,45.0
254.07324,0.01926368149606299,787.1321752862219,0.00025370340306410486,25.0,45.0
255.47461,0.019639434251968506,786.3608632714831,0.00025370340306410486,25.0,45.0
256.87598,0.019968751968503937,787.1229898670879,0.00025370340306410486,25.0,45.0
258.27734,0.020318417322834646,788.2762731938413,0.00025370340306410486,25.0,45.0
259.67871,0.020649265748031498,791.25537570733,0.00025370340306410486,25.0,45.0
261.08008,0.020951667322834645,789.4889064350574,0.00025370340306410486,25.0,45.0
262.48145,0.021302797244094486,791.0958283984735,0.00025370340306410486,25.0,45.0
263.88281,0.0216315,791.6694301881827,0.00025370340306410486,25.0,45.0
265.28418,0.02197122440944882,792.5812870114489,0.00025370340306410486,25.0,45.0
266.68555,0.02230858070866142,791.8744045269115,0.00025370340306410486,25.0,45.0
268.08691,0.02267616535433071,791.6414791419925,0.00025370340306410486,25.0,45.0
269.48828,0.023016791338582678,794.1186208711674,0.00025370340306410486,25.0,45.0
270.88965,0.02336673622047244,793.5471246216608,0.00025370340306410486,25.0,45.0
272.29102,0.023690978346456695,794.9272799052508,0.00025370340306410486,25.0,45.0
273.69238,0.023997773622047244,794.8428477431241,0.00025370340306410486,25.0,45.0
275.09375,0.024330200787401574,796.6357678641926,0.00025370340306410486,25.0,45.0
276.49512,0.024733303149606298,798.3659955257272,0.00025370340306410486,25.0,45.0
277.89648,0.02513084645669291,796.5514672983288,0.00025370340306410486,25.0,45.0
279.29785,0.025507047244094486,797.1890775101988,0.00025370340306410486,25.0,45.0
280.69922,0.025807224409448815,797.9823924200554,0.00025370340306410486,25.0,45.0
282.10059,0.02607898622047244,797.8186077115411,0.00025370340306410486,25.0,45.0
283.50195,0.026432523622047243,800.1489669693382,0.00025370340306410486,25.0,45.0
284.90332,0.026760933070866143,800.0762995130939,0.00025370340306410486,25.0,45.0
286.30469,0.02712458661417323,800.8343992630611,0.00025370340306410486,25.0,45.0
287.70605,0.027488206692913384,801.2927227266747,0.00025370340306410486,25.0,45.0
289.10742,0.027815543307086615,801.4563232004211,0.00025370340306410486,25.0,45.0
290.50879,0.028240856299212597,804.816133701803,0.00025370340306410486,25.0,45.0
291.91016,0.02861184251968504,803.0473746545599,0.00025370340306410486,25.0,45.0
293.31152,0.028915342519685038,802.6879063034611,0.00025370340306410486,25.0,45.0
294.71289,0.029226562992125983,802.727437820766,0.00025370340306410486,25.0,45.0
296.11426,0.029542076771653544,803.6494538755101,0.00025370340306410486,25.0,45.0
297.51563,0.029850964566929133,805.644268982761,0.00025370340306410486,25.0,45.0
298.91699,0.03020729133858268,806.9175154625609,0.00025370340306410486,25.0,45.0
300.31836,0.030568025590551183,806.4280563232005,0.00025370340306410486,25.0,45.0
301.71973,0.030896413385826767,804.7525200684302,0.00025370340306410486,25.0,45.0
303.12109,0.031200145669291336,807.4401631793658,0.00025370340306410486,25.0,45.0
304.52246,0.031513419291338586,807.8269772338466,0.00025370340306410486,25.0,45.0
305.92383,0.03183794094488189,808.5544940123701,0.00025370340306410486,25.0,45.0
307.3252,0.03219949606299212,807.9579944729571,0.00025370340306410486,25.0,45.0
308.72656,0.032543293307086614,810.2636925911305,0.00025370340306410486,25.0,45.0
310.12793,0.0329173405511811,810.0594288722201,0.00025370340306410486,25.0,45.0
311.5293,0.0332463937007874,810.0934333464929,0.00025370340306410486,25.0,45.0
312.93066,0.03360321259842519,811.7313593893934,0.00025370340306410486,25.0,45.0
314.33203,0.03395104527559055,810.9581260692197,0.00025370340306410486,25.0,45.0
315.7334,0.034286496062992125,810.8459797341756,0.00025370340306410486,25.0,45.0
317.13477,0.034630391732283466,812.6341097512832,0.00025370340306410486,25.0,45.0
318.53613,0.034964090551181104,812.2764574286091,0.00025370340306410486,25.0,45.0
319.9375,0.03527353937007874,814.533307014081,0.00025370340306410486,25.0,45.0
321.33887,0.03565738779527559,815.0057902355575,0.00025370340306410486,25.0,45.0
322.74023,0.0360091437007874,815.603895249375,0.00025370340306410486,25.0,45.0
324.1416,0.03636853149606299,813.9455717857614,0.00025370340306410486,25.0,45.0
325.54297,0.0367161594488189,814.2347150940914,0.00025370340306410486,25.0,45.0
326.94434,0.03702142716535433,815.8859586787736,0.00025370340306410486,25.0,45.0
328.3457,0.03743783661417323,817.3276220555337,0.00025370340306410486,25.0,45.0
329.74707,0.03778786614173228,817.60186866693,0.00025370340306410486,25.0,45.0
331.14844,0.038111421259842515,816.6893012238453,0.00025370340306410486,25.0,45.0
332.5498,0.03843348228346457,818.2512435846822,0.00025370340306410486,25.0,45.0
333.95117,0.03874941929133858,817.588103697855,0.00025370340306410486,25.0,45.0
335.35254,0.03904901574803149,818.4582708251086,0.00025370340306410486,25.0,45.0
336.75391,0.039336009842519684,818.2202658244507,0.00025370340306410486,25.0,45.0
338.15527,0.03964422637795276,819.8851954204501,0.00025370340306410486,25.0,45.0
339.55664,0.03996396456692913,819.2800894854587,0.00025370340306410486,25.0,45.0
340.95801,0.04031691929133858,822.1070930385578,0.00025370340306410486,25.0,45.0
342.35938,0.040719232283464565,822.1348072114753,0.00025370340306410486,25.0,45.0
343.76074,0.041086165354330705,822.8646137649691,0.00025370340306410486,25.0,45.0
345.16211,0.04144527755905512,821.8154494012371,0.00025370340306410486,25.0,45.0
346.56348,0.04180928149606299,822.062192393736,0.00025370340306410486,25.0,45.0
347.96484,0.042134129921259846,822.3303855770497,0.00025370340306410486,25.0,45.0
349.36621,0.04252800787401575,826.2187919463088,0.00025370340306410486,25.0,45.0
350.76758,0.042874659448818894,824.7442295038821,0.00025370340306410486,25.0,45.0
352.16895,0.043196982283464566,823.9568364258455,0.00025370340306410486,25.0,45.0
353.57031,0.0434868031496063,826.2440321094881,0.00025370340306410486,25.0,45.0
354.97168,0.043816253937007874,825.5384392683249,0.00025370340306410486,25.0,45.0
356.37305,0.044150937007874015,824.9733649164365,0.00025370340306410486,25.0,45.0
357.77441,0.0444716968503937,826.9671009343335,0.00025370340306410486,25.0,45.0
359.17578,0.04487415157480315,829.3647585208581,0.00025370340306410486,25.0,45.0
360.57715,0.045237960629921255,828.4095802079221,0.00025370340306410486,25.0,45.0
361.97852,0.04554951181102362,827.2213712330571,0.00025370340306410486,25.0,45.0
363.37988,0.04588700787401575,828.1068824845376,0.00025370340306410486,25.0,45.0
364.78125,0.046279210629921255,829.0706671930518,0.00025370340306410486,25.0,45.0
366.18262,0.0466406968503937,828.6171338333993,0.00025370340306410486,25.0,45.0
367.58398,0.04697042322834646,830.175417818134,0.00025370340306410486,25.0,45.0
368.98535,0.047278724409448816,831.4941966048166,0.00025370340306410486,25.0,45.0
370.38672,0.047633647637795276,830.143676799579,0.00025370340306410486,25.0,45.0
371.78809,0.04798344094488189,831.9017765495461,0.00025370340306410486,25.0,45.0
373.18945,0.048272740157480315,831.010211869983,0.00025370340306410486,25.0,45.0
374.59082,0.048567998031496064,832.3777075931044,0.00025370340306410486,25.0,45.0
375.99219,0.048920110236220476,834.5176470588236,0.00025370340306410486,25.0,45.0
377.39355,0.049282728346456695,833.4061323858404,0.00025370340306410486,25.0,45.0
378.79492,0.049625612204724404,834.599947361495,0.00025370340306410486,25.0,45.0
380.19629,0.049932165354330704,833.4690353993948,0.00025370340306410486,25.0,45.0
381.59766,0.05029669881889763,833.993630740887,0.00025370340306410486,25.0,45.0
382.99902,0.05056076574803149,832.7049611791026,0.00025370340306410486,25.0,45.0
384.40039,0.050977964566929136,836.5355178312938,0.00025370340306410486,25.0,45.0
385.80176,0.05134270866141732,836.4870114488749,0.00025370340306410486,25.0,45.0
387.20313,0.0516398562992126,835.7264113699172,0.00025370340306410486,25.0,45.0
388.60449,0.051967618110236216,836.7245690222398,0.00025370340306410486,25.0,45.0
390.00586,0.05225430118110236,836.1787866824583,0.00025370340306410486,25.0,45.0
391.40723,0.05263724803149606,837.9680484274247,0.00025370340306410486,25.0,45.0
392.80859,0.052976726377952754,837.2994078168181,0.00025370340306410486,25.0,45.0
394.20996,0.05331680708661417,838.1471246216609,0.00025370340306410486,25.0,45.0
395.61133,0.05372938188976378,841.0887748387947,0.00025370340306410486,25.0,45.0
397.0127,0.05405948818897637,839.4483747861561,0.00025370340306410486,25.0,45.0
398.41406,0.054425094488188976,839.9007500986974,0.00025370340306410486,25.0,45.0
399.81543,0.0547515590551181,840.159178839321,0.00025370340306410486,25.0,45.0
401.2168,0.05506073425196851,841.525069088038,0.00025370340306410486,25.0,45.0
402.61816,0.05540599606299213,841.1462297670747,0.00025370340306410486,25.0,45.0
404.01953,0.055693007874015744,841.4272141071194,0.00025370340306410486,25.0,45.0
405.4209,0.056035923228346454,842.8268982760891,0.00025370340306410486,25.0,45.0
406.82227,0.05633600393700788,842.6586656138966,0.00025370340306410486,25.0,45.0
408.22363,0.056664482283464566,841.9344387419399,0.00025370340306410486,25.0,45.0
409.625,0.0569656437007874,842.6441637057508,0.00025370340306410486,25.0,45.0
411.02637,0.05734087007874015,844.592788524806,0.00025370340306410486,25.0,45.0
412.42773,0.057659913385826767,843.5612054217661,0.00025370340306410486,25.0,45.0
413.8291,0.0580088779527559,844.4384261086985,0.00025370340306410486,25.0,45.0
415.23047,0.05840250787401575,845.1311751546257,0.00025370340306410486,25.0,45.0
416.63184,0.058750803149606304,845.726700881695,0.00025370340306410486,25.0,45.0
418.0332,0.05901862401574803,844.7078562968813,0.00025370340306410486,25.0,45.0
419.43457,0.05937158267716536,847.3553362284513,0.00025370340306410486,25.0,45.0
420.83594,0.05978571653543307,846.1591525200685,0.00025370340306410486,25.0,45.0
422.2373,0.06009162007874016,846.3559678905119,0.00025370340306410486,25.0,45.0
423.63867,0.06043381889763779,847.99210422424,0.00025370340306410486,25.0,45.0
425.04004,0.06080263385826771,847.3974996710094,0.00025370340306410486,25.0,45.0
426.44141,0.06109689566929134,847.5943676799579,0.00025370340306410486,25.0,45.0
427.84277,0.06141279527559055,849.4987235162522,0.00025370340306410486,25.0,45.0
429.24414,0.06177681692913385,849.3220950125017,0.00025370340306410486,25.0,45.0
430.64551,0.06214684645669291,851.57225950783,0.00025370340306410486,25.0,45.0
432.04688,0.06248947440944882,849.7329911830504,0.00025370340306410486,25.0,45.0
433.44824,0.06275328937007874,848.6687985261219,0.00025370340306410486,25.0,45.0
434.84961,0.06306771653543307,850.670377681274,0.00025370340306410486,25.0,45.0
436.25098,0.06336948228346458,850.1281747598368,0.00025370340306410486,25.0,45.0
437.65234,0.06368099212598426,850.8691143571523,0.00025370340306410486,25.0,45.0
439.05371,0.064022281496063,852.3942360836952,0.00025370340306410486,25.0,45.0
440.45508,0.06431231496062992,852.8693512304252,0.00025370340306410486,25.0,45.0
441.85645,0.06461620472440945,851.3412027898408,0.00025370340306410486,25.0,45.0
443.25781,0.0649398937007874,852.0155809974998,0.00025370340306410486,25.0,45.0
444.65918,0.06525133464566929,854.5411501513357,0.00025370340306410486,25.0,45.0
446.06055,0.06557850196850394,853.9300697460194,0.00025370340306410486,25.0,45.0
447.46191,0.0659600846456693,855.0183708382683,0.00025370340306410486,25.0,45.0
448.86328,0.06632887598425197,854.5379918410318,0.00025370340306410486,25.0,45.0
450.26465,0.06665998031496063,854.9969732859588,0.00025370340306410486,25.0,45.0
451.66602,0.06696861614173227,856.3165416502172,0.00025370340306410486,25.0,45.0
453.06738,0.06734731102362206,855.3183839978946,0.00025370340306410486,25.0,45.0
454.46875,0.0677111279527559,855.9931306750889,0.00025370340306410486,25.0,45.0
455.87012,0.06808758858267717,858.7516515330965,0.00025370340306410486,25.0,45.0
457.27148,0.06842752165354331,856.40592183182,0.00025370340306410486,25.0,45.0
458.67285,0.06880127755905512,857.0464271614687,0.00025370340306410486,25.0,45.0
460.07422,0.06914728937007875,858.7655217791817,0.00025370340306410486,25.0,45.0
461.47559,0.06948137992125984,857.8617712856956,0.00025370340306410486,25.0,45.0
462.87695,0.06980697637795276,859.515146729833,0.00025370340306410486,25.0,45.0
464.27832,0.07012614960629922,859.4617976049481,0.00025370340306410486,25.0,45.0
465.67969,0.07043243897637795,859.222897749704,0.00025370340306410486,25.0,45.0
467.08105,0.07074730511811024,859.544176865377,0.00025370340306410486,25.0,45.0
468.48242,0.07106913385826771,859.7948414265036,0.00025370340306410486,25.0,45.0
469.88379,0.07140226377952755,860.991946308725,0.00025370340306410486,25.0,45.0
471.28516,0.07177886417322835,862.0369259113041,0.00025370340306410486,25.0,45.0
472.68652,0.07209051574803149,860.7641531780498,0.00025370340306410486,25.0,45.0
474.08789,0.07242692322834646,861.2871167258851,0.00025370340306410486,25.0,45.0
475.48926,0.07275359448818898,862.7057770759312,0.00025370340306410486,25.0,45.0
476.89063,0.0730846220472441,862.6580339518358,0.00025370340306410486,25.0,45.0
478.29199,0.0734159625984252,863.2479536781157,0.00025370340306410486,25.0,45.0
479.69336,0.07378462401574803,865.551230425056,0.00025370340306410486,25.0,45.0
481.09473,0.07418774212598425,863.9490722463484,0.00025370340306410486,25.0,45.0
482.49609,0.0745109153543307,864.1945782339783,0.00025370340306410486,25.0,45.0
483.89746,0.07484439173228345,864.0904855902094,0.00025370340306410486,25.0,45.0
485.29883,0.07514551771653542,864.487458876168,0.00025370340306410486,25.0,45.0
486.7002,0.07544185629921259,865.6877747071984,0.00025370340306410486,25.0,45.0
488.10156,0.0757768405511811,865.3320963284643,0.00025370340306410486,25.0,45.0
489.50293,0.0761030059055118,865.6192656928544,0.00025370340306410486,25.0,45.0
490.9043,0.07649481102362204,866.8648769574945,0.00025370340306410486,25.0,45.0
492.30566,0.07688139763779528,868.0371627845769,0.00025370340306410486,25.0,45.0
493.70703,0.0772218996062992,867.4112909593368,0.00025370340306410486,25.0,45.0
495.1084,0.07755607283464566,865.8689038031321,0.00025370340306410486,25.0,45.0
496.50977,0.0778922716535433,867.189288064219,0.00025370340306410486,25.0,45.0
497.91113,0.07826423622047243,867.9789445979735,0.00025370340306410486,25.0,45.0
499.3125,0.07863782086614172,870.3950256612713,0.00025370340306410486,25.0,45.0
500.71387,0.07892570669291338,867.1687327279906,0.00025370340306410486,25.0,45.0
502.11523,0.07925132086614174,869.1933149098567,0.00025370340306410486,25.0,45.0
503.5166,0.07962914173228347,869.9650217133834,0.00025370340306410486,25.0,45.0
504.91797,0.07994485236220472,869.1668377418082,0.00025370340306410486,25.0,45.0
506.31934,0.08024768700787402,870.0614028161601,0.00025370340306410486,25.0,45.0
507.7207,0.08060566141732284,872.4437689169629,0.00025370340306410486,25.0,45.0
509.12207,0.0809148720472441,869.8166600868535,0.00025370340306410486,25.0,45.0
510.52344,0.08122324409448818,869.8270035530992,0.00025370340306410486,25.0,45.0
511.9248,0.08154692125984252,872.2635346756153,0.00025370340306410486,25.0,45.0
513.32617,0.08187420669291338,869.8991709435453,0.00025370340306410486,25.0,45.0
514.72754,0.08217780905511811,870.5956310040796,0.00025370340306410486,25.0,45.0
516.12891,0.08248832283464566,871.3726279773655,0.00025370340306410486,25.0,45.0
517.53027,0.08278715551181103,873.3939728911699,0.00025370340306410486,25.0,45.0
518.93164,0.08316993897637795,873.5396499539414,0.00025370340306410486,25.0,45.0
520.33301,0.08354989566929133,873.5989735491513,0.00025370340306410486,25.0,45.0
521.73438,0.08391025196850393,874.3026977233848,0.00025370340306410486,25.0,45.0
523.13574,0.08427122244094488,873.9795499407818,0.00025370340306410486,25.0,45.0
524.53711,0.08463022440944881,873.8693512304251,0.00025370340306410486,25.0,45.0
525.93848,0.08497616535433071,875.5781813396501,0.00025370340306410486,25.0,45.0
527.33984,0.08530189173228346,874.1408343203054,0.00025370340306410486,25.0,45.0
528.74121,0.08564158464566929,876.0455849453875,0.00025370340306410486,25.0,45.0
530.14258,0.08601476377952755,875.997131201474,0.00025370340306410486,25.0,45.0
531.54395,0.08640495275590551,876.4201868666931,0.00025370340306410486,25.0,45.0
532.94531,0.08672650590551181,876.7442821423872,0.00025370340306410486,25.0,45.0
534.34668,0.08701730708661416,875.4601921305436,0.00025370340306410486,25.0,45.0
535.74805,0.0873705059055118,876.9942360836953,0.00025370340306410486,25.0,45.0
537.14941,0.0877415216535433,878.8250822476642,0.00025370340306410486,25.0,45.0
538.55078,0.08808003543307086,876.5997894459798,0.00025370340306410486,25.0,45.0
539.95215,0.08843989960629921,877.8577970785631,0.00025370340306410486,25.0,45.0
541.35352,0.08876369488188976,880.4171075141467,0.00025370340306410486,25.0,45.0
542.75488,0.08910080118110236,879.24945387551,0.00025370340306410486,25.0,45.0
544.15625,0.08946853149606299,878.0652717462824,0.00025370340306410486,25.0,45.0
545.55762,0.08977534842519685,878.6656138965653,0.00025370340306410486,25.0,45.0
546.95898,0.09011474212598425,879.7669693380708,0.00025370340306410486,25.0,45.0
548.36035,0.09039294291338583,879.3727595736283,0.00025370340306410486,25.0,45.0
549.76172,0.09080619881889763,881.2678510330308,0.00025370340306410486,25.0,45.0
551.16309,0.09118888779527559,880.6042900381631,0.00025370340306410486,25.0,45.0
552.56445,0.09157790748031495,882.8669298591922,0.00025370340306410486,25.0,45.0
553.96582,0.09194020472440945,881.7520726411371,0.00025370340306410486,25.0,45.0
555.36719,0.09221814763779528,879.2725621792342,0.00025370340306410486,25.0,45.0
556.76855,0.09249924015748032,881.0811948940651,0.00025370340306410486,25.0,45.0
558.16992,0.09282510629921259,882.5985787603634,0.00025370340306410486,25.0,45.0
559.57129,0.0932022874015748,883.5703382023952,0.00025370340306410486,25.0,45.0
560.97266,0.09356594488188975,882.140123700487,0.00025370340306410486,25.0,45.0
562.37402,0.09391461614173229,883.1783129359127,0.00025370340306410486,25.0,45.0
563.77539,0.09424828346456693,883.0770364521649,0.00025370340306410486,25.0,45.0
565.17676,0.0945878248031496,884.5158573496514,0.00025370340306410486,25.0,45.0
566.57813,0.09492237992125985,884.8135017765496,0.00025370340306410486,25.0,45.0
567.97949,0.09531193307086615,884.9431767337809,0.00025370340306410486,25.0,45.0
569.38086,0.09565593307086614,885.0246348203711,0.00025370340306410486,25.0,45.0
570.78223,0.09599917125984252,884.2808264245296,0.00025370340306410486,25.0,45.0
572.18359,0.09631430708661418,883.8893012238453,0.00025370340306410486,25.0,45.0
573.58496,0.09666452559055118,885.1135675746809,0.00025370340306410486,25.0,45.0
574.98633,0.09701212598425198,886.4826161337019,0.00025370340306410486,25.0,45.0
576.3877,0.09731839173228346,885.7763126727201,0.00025370340306410486,25.0,45.0
577.78906,0.09772799212598425,888.3973680747467,0.00025370340306410486,25.0,45.0
579.19043,0.09809814566929133,886.0120542176603,0.00025370340306410486,25.0,45.0
580.5918,0.09840699212598425,884.1734965126991,0.00025370340306410486,25.0,45.0
581.99316,0.09874627559055119,886.2734570338204,0.00025370340306410486,25.0,45.0
583.39453,0.09906286023622046,887.2983287274642,0.00025370340306410486,25.0,45.0
584.7959,0.09941973818897637,888.1954204500593,0.00025370340306410486,25.0,45.0
586.19727,0.09976932874015748,887.8306882484538,0.00025370340306410486,25.0,45.0
587.59863,0.1001132283464567,888.9628372154232,0.00025370340306410486,25.0,45.0
589.0,0.10048120472440944,890.5716015265167,0.00025370340306410486,25.0,45.0
590.40137,0.10082071653543306,886.334938807738,0.00025370340306410486,25.0,45.0
591.80273,0.10113398228346458,889.1657586524543,0.00025370340306410486,25.0,45.0
593.2041,0.10145428543307088,889.0976444268983,0.00025370340306410486,25.0,45.0
594.60547,0.10180242125984253,889.5931043558364,0.00025370340306410486,25.0,45.0
596.00684,0.10220511614173228,891.4016581129097,0.00025370340306410486,25.0,45.0
597.4082,0.10256756692913387,890.1622318726149,0.00025370340306410486,25.0,45.0
598.80957,0.1028867342519685,890.6501908145809,0.00025370340306410486,25.0,45.0
600.21094,0.10323705118110237,891.8161073825504,0.00025370340306410486,25.0,45.0
601.6123,0.10365656102362204,891.8283984734834,0.00025370340306410486,25.0,45.0
603.01367,0.1040238562992126,891.5311488353732,0.00025370340306410486,25.0,45.0
604.41504,0.10437777755905511,891.5559942097645,0.00025370340306410486,25.0,45.0
605.81641,0.10469445472440946,892.4843795236217,0.00025370340306410486,25.0,45.0
607.21777,0.10508441929133859,893.3514409790762,0.00025370340306410486,25.0,45.0
608.61914,0.10545711417322834,894.1257270693513,0.00025370340306410486,25.0,45.0
610.02051,0.10581193700787402,894.6083695223057,0.00025370340306410486,25.0,45.0
611.42188,0.1061743405511811,894.9597052243716,0.00025370340306410486,25.0,45.0
612.82324,0.10654437007874015,894.4824055796817,0.00025370340306410486,25.0,45.0
614.22461,0.10687456496062991,893.1713383339913,0.00025370340306410486,25.0,45.0
615.62598,0.10717292913385826,895.2888274772997,0.00025370340306410486,25.0,45.0
617.02734,0.10752084251968505,896.2732991183052,0.00025370340306410486,25.0,45.0
618.42871,0.10791056102362204,895.384945387551,0.00025370340306410486,25.0,45.0
619.83008,0.10827285826771653,894.7543360968549,0.00025370340306410486,25.0,45.0
621.23145,0.10863025196850394,894.3318594551915,0.00025370340306410486,25.0,45.0
622.63281,0.10897521850393702,894.5898407685222,0.00025370340306410486,25.0,45.0
624.03418,0.10933115748031497,896.4377154888803,0.00025370340306410486,25.0,45.0
625.43555,0.10966224409448819,896.4638768258983,0.00025370340306410486,25.0,45.0
626.83691,0.1100874783464567,897.8442953020135,0.00025370340306410486,25.0,45.0
628.23828,0.11047488582677166,895.8702724042638,0.00025370340306410486,25.0,45.0
629.63965,0.11085968700787402,896.7440452691145,0.00025370340306410486,25.0,45.0
631.04102,0.11119911811023621,896.3942360836953,0.00025370340306410486,25.0,45.0
632.44238,0.11153092125984251,896.3601789709173,0.00025370340306410486,25.0,45.0
633.84375,0.11189474409448819,898.4908277404923,0.00025370340306410486,25.0,45.0
635.24512,0.11225244094488189,898.7669430188183,0.00025370340306410486,25.0,45.0
636.64648,0.11262879527559055,898.3663113567575,0.00025370340306410486,25.0,45.0
638.04785,0.11299028346456692,898.1580471114621,0.00025370340306410486,25.0,45.0
639.44922,0.11338230118110236,898.4310040794842,0.00025370340306410486,25.0,45.0
640.85059,0.11372800984251968,899.800236873273,0.00025370340306410486,25.0,45.0
642.25195,0.11412442716535434,900.8295565205949,0.00025370340306410486,25.0,45.0
643.65332,0.1145538031496063,899.9649953941308,0.00025370340306410486,25.0,45.0
645.05469,0.11495784842519685,899.8341097512831,0.00025370340306410486,25.0,45.0
646.45605,0.1152959035433071,901.485932359521,0.00025370340306410486,25.0,45.0
647.85742,0.11562511417322835,900.2052375312542,0.00025370340306410486,25.0,45.0
649.25879,0.11604087992125985,901.5245427029873,0.00025370340306410486,25.0,45.0
650.66016,0.1164081653543307,898.7922621397554,0.00025370340306410486,25.0,45.0
652.06152,0.11674213779527559,901.3873667587842,0.00025370340306410486,25.0,45.0
653.46289,0.11711714370078741,903.4916962758258,0.00025370340306410486,25.0,45.0
654.86426,0.11752041338582678,901.5628372154231,0.00025370340306410486,25.0,45.0
656.26563,0.11788196062992125,901.7261218581393,0.00025370340306410486,25.0,45.0
657.66699,0.11822416929133858,900.9166206079749,0.00025370340306410486,25.0,45.0
659.06836,0.11853938188976378,900.1584682195025,0.00025370340306410486,25.0,45.0
660.46973,0.11888611023622048,901.8211606790369,0.00025370340306410486,25.0,45.0
661.87109,0.11923650984251968,902.2903539939466,0.00025370340306410486,25.0,45.0
663.27246,0.11957849803149607,902.9750756678511,0.00025370340306410486,25.0,45.0
664.67383,0.11995008858267717,903.6411369917096,0.00025370340306410486,25.0,45.0
666.0752,0.12032330905511811,903.5280431635742,0.00025370340306410486,25.0,45.0
667.47656,0.12070291338582677,902.9368864324255,0.00025370340306410486,25.0,45.0
668.87793,0.12106363976377953,903.8271614686143,0.00025370340306410486,25.0,45.0
670.2793,0.12147115748031495,904.7916567969471,0.00025370340306410486,25.0,45.0
671.68066,0.12195172440944883,905.2005790235559,0.00025370340306410486,25.0,45.0
673.08203,0.12233965944881889,903.9058823529413,0.00025370340306410486,25.0,45.0
674.4834,0.12266101968503935,902.9473614949337,0.00025370340306410486,25.0,45.0
675.88477,0.12298795472440945,904.1260165811292,0.00025370340306410486,25.0,45.0
677.28613,0.12335783070866142,905.5887353599159,0.00025370340306410486,25.0,45.0
678.6875,0.12375815551181103,905.1272535859982,0.00025370340306410486,25.0,45.0
680.08887,0.12411714566929134,906.2267403605739,0.00025370340306410486,25.0,45.0
681.49023,0.12450295669291338,905.4725621792342,0.00025370340306410486,25.0,45.0
682.8916,0.12489772047244095,906.0364784840111,0.00025370340306410486,25.0,45.0
684.29297,0.12528619488188975,905.9455454665089,0.00025370340306410486,25.0,45.0
685.69434,0.1256730374015748,907.3520463218846,0.00025370340306410486,25.0,45.0
687.0957,0.12606627559055117,905.5063034609818,0.00025370340306410486,25.0,45.0
688.49707,0.12642918307086615,907.6911962100277,0.00025370340306410486,25.0,45.0
689.89844,0.1267747381889764,906.0198973549152,0.00025370340306410486,25.0,45.0
691.2998,0.12712984251968504,906.1120936965391,0.00025370340306410486,25.0,45.0
692.70117,0.12749791338582678,907.1518357678642,0.00025370340306410486,25.0,45.0
694.10254,0.12791902952755904,909.3708382681933,0.00025370340306410486,25.0,45.0
695.50391,0.12837796259842518,908.665587577313,0.00025370340306410486,25.0,45.0
696.90527,0.12874993897637796,908.5310961968681,0.00025370340306410486,25.0,45.0
698.30664,0.12916344094488189,908.1832083168839,0.00025370340306410486,25.0,45.0
699.70801,0.1295354311023622,908.2037636531123,0.00025370340306410486,25.0,45.0
701.10938,0.1298802342519685,908.1022502960917,0.00025370340306410486,25.0,45.0
702.51074,0.1302372283464567,908.8332938544546,0.00025370340306410486,25.0,45.0
703.91211,0.13064352559055117,909.5315436241611,0.00025370340306410486,25.0,45.0
705.31348,0.13106834842519685,911.6106329780235,0.00025370340306410486,25.0,45.0
706.71484,0.13150484842519686,909.3596789051192,0.00025370340306410486,25.0,45.0
708.11621,0.13187187401574804,909.3265692854324,0.00025370340306410486,25.0,45.0
709.51758,0.13223275196850393,909.7467561521254,0.00025370340306410486,25.0,45.0
710.91895,0.13259848818897638,909.7689696012634,0.00025370340306410486,25.0,45.0
712.32031,0.1330248248031496,912.0541123832083,0.00025370340306410486,25.0,45.0
713.72168,0.1334312972440945,911.3790498749837,0.00025370340306410486,25.0,45.0
715.12305,0.13384653543307087,911.7942624029478,0.00025370340306410486,25.0,45.0
716.52441,0.13420027952755906,909.862929332807,0.00025370340306410486,25.0,45.0
717.92578,0.13456352755905512,910.8876694301882,0.00025370340306410486,25.0,45.0
719.32715,0.13500420275590552,912.414212396368,0.00025370340306410486,25.0,45.0
720.72852,0.1353976653543307,910.7355704697987,0.00025370340306410486,25.0,45.0
722.12988,0.1357119960629921,911.9511777865509,0.00025370340306410486,25.0,45.0
723.53125,0.1361341220472441,913.0203447822082,0.00025370340306410486,25.0,45.0
724.93262,0.13652704330708662,910.4542702987236,0.00025370340306410486,25.0,45.0
726.33398,0.13685580708661418,911.6488485327018,0.00025370340306410486,25.0,45.0
727.73535,0.13723318307086613,913.0883800500067,0.00025370340306410486,25.0,45.0
729.13672,0.13761635433070865,913.0875378339256,0.00025370340306410486,25.0,45.0
730.53809,0.13797928543307086,911.8098697197,0.00025370340306410486,25.0,45.0
731.93945,0.13835333858267718,912.5749703908409,0.00025370340306410486,25.0,45.0
733.34082,0.1387483031496063,911.2759836820635,0.00025370340306410486,25.0,45.0
734.74219,0.1391197401574803,913.1324647979999,0.00025370340306410486,25.0,45.0
736.14355,0.13952012401574804,914.8259771022504,0.00025370340306410486,25.0,45.0
737.54492,0.1399528562992126,914.3109882879327,0.00025370340306410486,25.0,45.0
738.94629,0.14039604133858266,914.3311488353731,0.00025370340306410486,25.0,45.0
740.34766,0.14084602165354332,913.8986445584947,0.00025370340306410486,25.0,45.0
741.74902,0.141272405511811,914.9952362152915,0.00025370340306410486,25.0,45.0
743.15039,0.1416820590551181,914.148861692328,0.00025370340306410486,25.0,45.0
744.55176,0.1421015216535433,913.408685353336,0.00025370340306410486,25.0,45.0
745.95313,0.14249649606299214,912.818949861824,0.00025370340306410486,25.0,45.0
747.35449,0.142880968503937,915.4325042768787,0.00025370340306410486,25.0,45.0
748.75586,0.1432935905511811,914.4375049348599,0.00025370340306410486,25.0,45.0
750.15723,0.14374929527559055,914.9202000263194,0.00025370340306410486,25.0,45.0
751.55859,0.14417923622047243,916.2883274115015,0.00025370340306410486,25.0,45.0
752.95996,0.14457994881889763,914.9515988945915,0.00025370340306410486,25.0,45.0
754.36133,0.14497436023622048,914.3824976970656,0.00025370340306410486,25.0,45.0
755.7627,0.14535961811023623,915.0960652717463,0.00025370340306410486,25.0,45.0
757.16406,0.14577965551181102,916.0389524937492,0.00025370340306410486,25.0,45.0
758.56543,0.14622260826771655,915.729806553494,0.00025370340306410486,25.0,45.0
759.9668,0.14662784842519686,915.0963021450191,0.00025370340306410486,25.0,45.0
761.36816,0.14699327952755906,915.9577839189368,0.00025370340306410486,25.0,45.0
762.76953,0.14742299606299214,917.9643900513227,0.00025370340306410486,25.0,45.0
764.1709,0.14781346456692915,916.3527832609556,0.00025370340306410486,25.0,45.0
765.57227,0.14824267716535433,918.2665877089091,0.00025370340306410486,25.0,45.0
766.97363,0.14860841141732284,916.7253849190685,0.00025370340306410486,25.0,45.0
768.375,0.14905907283464567,917.1634951967366,0.00025370340306410486,25.0,45.0
769.77637,0.1494852342519685,915.8966179760496,0.00025370340306410486,25.0,45.0
771.17773,0.14990393307086614,918.3091196210028,0.00025370340306410486,25.0,45.0
772.5791,0.15034648622047242,919.5878141860771,0.00025370340306410486,25.0,45.0
773.98047,0.1507656082677165,918.335333596526,0.00025370340306410486,25.0,45.0
775.38184,0.15119179330708662,919.0180550072379,0.00025370340306410486,25.0,45.0
776.7832,0.1516208523622047,917.2689301223846,0.00025370340306410486,25.0,45.0
778.18457,0.15205756102362203,919.4643768916964,0.00025370340306410486,25.0,45.0
779.58594,0.15253812992125984,918.5519410448744,0.00025370340306410486,25.0,45.0
780.9873,0.1529597618110236,919.7035399394657,0.00025370340306410486,25.0,45.0
782.38867,0.15334921062992127,916.41381760758,0.00025370340306410486,25.0,45.0
783.79004,0.15373736811023622,918.2990130280301,0.00025370340306410486,25.0,45.0
785.19141,0.15414794881889762,919.7958152388474,0.00025370340306410486,25.0,45.0
786.59277,0.15462958464566928,920.3782866166601,0.00025370340306410486,25.0,45.0
787.99414,0.1550803149606299,919.750388208975,0.00025370340306410486,25.0,45.0
789.39551,0.15557749803149606,920.755915252007,0.00025370340306410486,25.0,45.0
790.79688,0.15604343503937007,919.7405448085275,0.00025370340306410486,25.0,45.0
792.19824,0.15643429133858266,918.4103697854981,0.00025370340306410486,25.0,45.0
793.59961,0.15681139566929134,917.8116331096198,0.00025370340306410486,25.0,45.0
795.00098,0.15722445078740158,919.2027898407686,0.00025370340306410486,25.0,45.0
796.40234,0.15762333267716536,919.895407290433,0.00025370340306410486,25.0,45.0
797.80371,0.1580962992125984,919.1969996052113,0.00025370340306410486,25.0,45.0
799.20508,0.158504812992126,920.2125016449534,0.00025370340306410486,25.0,45.0
800.60645,0.15894559448818898,921.3440452691144,0.00025370340306410486,25.0,45.0
802.00781,0.15939085826771654,921.6626924595342,0.00025370340306410486,25.0,45.0
803.40918,0.15984575393700787,921.3054875641533,0.00025370340306410486,25.0,45.0
804.81055,0.16029042913385827,920.9051190946177,0.00025370340306410486,25.0,45.0
806.21191,0.16070368503937008,919.3569417028557,0.00025370340306410486,25.0,45.0
807.61328,0.16111385433070866,920.7769180155284,0.00025370340306410486,25.0,45.0
809.01465,0.16154466141732282,921.0740360573761,0.00025370340306410486,25.0,45.0
810.41602,0.16193951968503936,919.5161731806818,0.00025370340306410486,25.0,45.0
811.81738,0.16238867716535432,921.7437294380841,0.00025370340306410486,25.0,45.0
813.21875,0.16283528937007874,921.2019739439402,0.00025370340306410486,25.0,45.0
814.62012,0.16334925196850392,922.3490196078432,0.00025370340306410486,25.0,45.0
816.02148,0.16387339566929135,923.0499802605607,0.00025370340306410486,25.0,45.0
817.42285,0.1643258877952756,920.2507961573892,0.00025370340306410486,25.0,45.0
818.82422,0.16480462598425197,923.4143703118833,0.00025370340306410486,25.0,45.0
820.22559,0.16533284251968505,922.7544676931176,0.00025370340306410486,25.0,45.0
821.62695,0.1657888877952756,922.8680879063036,0.00025370340306410486,25.0,45.0
823.02832,0.1662419527559055,922.7422555599421,0.00025370340306410486,25.0,45.0
824.42969,0.1666968503937008,922.3216475852087,0.00025370340306410486,25.0,45.0
825.83105,0.16720249212598426,922.2660086853534,0.00025370340306410486,25.0,45.0
827.23242,0.16763566929133858,922.9975523095145,0.00025370340306410486,25.0,45.0
828.63379,0.16807871456692913,923.0342939860509,0.00025370340306410486,25.0,45.0
830.03516,0.16852936417322834,924.082326621924,0.00025370340306410486,25.0,45.0
831.43652,0.16898241732283464,923.4087906303462,0.00025370340306410486,25.0,45.0
832.83789,0.1694143996062992,921.8147914199238,0.00025370340306410486,25.0,45.0
834.23926,0.1698278996062992,922.3201737070668,0.00025370340306410486,25.0,45.0
835.64063,0.1702435374015748,922.2241084353205,0.00025370340306410486,25.0,45.0
837.04199,0.17067697244094487,922.5306750888275,0.00025370340306410486,25.0,45.0
838.44336,0.17116542716535435,923.6054744045271,0.00025370340306410486,25.0,45.0
839.84473,0.17164121850393702,925.4171075141467,0.00025370340306410486,25.0,45.0
841.24609,0.17216622047244093,925.6993814975656,0.00025370340306410486,25.0,45.0
842.64746,0.17266003543307087,924.5624950651402,0.00025370340306410486,25.0,45.0
844.04883,0.17314724606299212,923.996736412686,0.00025370340306410486,25.0,45.0
845.4502,0.17356686023622048,924.26327148309,0.00025370340306410486,25.0,45.0
846.85156,0.17403048622047243,924.3097776023162,0.00025370340306410486,25.0,45.0
848.25293,0.1745801279527559,925.0304776944336,0.00025370340306410486,25.0,45.0
849.6543,0.17514737992125984,925.2555599420978,0.00025370340306410486,25.0,45.0
851.05566,0.17565048818897636,923.4626398210291,0.00025370340306410486,25.0,45.0
852.45703,0.1761911062992126,924.124332148967,0.00025370340306410486,25.0,45.0
853.8584,0.17672454527559056,923.5904461113305,0.00025370340306410486,25.0,45.0
855.25977,0.17725630511811025,924.8886169232795,0.00025370340306410486,25.0,45.0
856.66113,0.17772166732283465,924.4069482826688,0.00025370340306410486,25.0,45.0
858.0625,0.17820806692913385,925.6497697065404,0.00025370340306410486,25.0,45.0
859.46387,0.1786788503937008,924.6737465455982,0.00025370340306410486,25.0,45.0
860.86523,0.17920246653543306,923.2044479536781,0.00025370340306410486,25.0,45.0
862.2666,0.1796115216535433,923.140965916568,0.00025370340306410486,25.0,45.0
863.66797,0.18000946456692912,922.69495986314,0.00025370340306410486,25.0,45.0
865.06934,0.18044184448818898,924.7690222397684,0.00025370340306410486,25.0,45.0
866.4707,0.18101458858267716,924.4786419265694,0.00025370340306410486,25.0,45.0
867.87207,0.18150229133858267,924.0530332938546,0.00025370340306410486,25.0,45.0
869.27344,0.18195981496062993,925.3572312146335,0.00025370340306410486,25.0,45.0
870.6748,0.1823833248031496,926.438794578234,0.00025370340306410486,25.0,45.0
872.07617,0.18292748818897636,926.2494275562575,0.00025370340306410486,25.0,45.0
873.47754,0.18343859842519686,926.0995657323332,0.00025370340306410486,25.0,45.0
874.87891,0.18401603543307085,926.4815107250954,0.00025370340306410486,25.0,45.0
876.28027,0.18453016141732284,925.5134359784183,0.00025370340306410486,25.0,45.0
877.68164,0.1850394625984252,927.1885248058957,0.00025370340306410486,25.0,45.0
879.08301,0.1855298996062992,924.5761284379524,0.00025370340306410486,25.0,45.0
880.48438,0.1859722874015748,924.3642847743125,0.00025370340306410486,25.0,45.0
881.88574,0.1864620905511811,926.7551256744309,0.00025370340306410486,25.0,45.0
883.28711,0.18699850787401576,924.8237136465325,0.00025370340306410486,25.0,45.0
884.68848,0.18751401771653542,925.9618107645744,0.00025370340306410486,25.0,45.0
886.08984,0.18812457874015748,925.7495196736413,0.00025370340306410486,25.0,45.0
887.49121,0.1887090216535433,924.6794578233978,0.00025370340306410486,25.0,45.0
888.89258,0.18923397637795275,926.0962231872616,0.00025370340306410486,25.0,45.0
890.29395,0.18978062598425197,926.6490327674694,0.00025370340306410486,25.0,45.0
891.69531,0.19034880511811025,924.9248585340177,0.00025370340306410486,25.0,45.0
893.09668,0.19082640551181101,925.2713778128702,0.00025370340306410486,25.0,45.0
894.49805,0.19122919488188975,925.29111725227,0.00025370340306410486,25.0,45.0
895.89941,0.1918827460629921,926.5147256217924,0.00025370340306410486,25.0,45.0
897.30078,0.19246186023622047,927.0207395709962,0.00025370340306410486,25.0,45.0
898.70215,0.1930472539370079,926.284642716147,0.00025370340306410486,25.0,45.0
900.10352,0.1935356594488189,925.1312277931307,0.00025370340306410486,25.0,45.0
901.50488,0.19401396259842518,926.323884721674,0.00025370340306410486,25.0,45.0
902.90625,0.19452785433070865,925.8974865113832,0.00025370340306410486,25.0,45.0
904.30762,0.19501943897637794,925.3231741018557,0.00025370340306410486,25.0,45.0
905.70898,0.19559385039370078,925.5889195946836,0.00025370340306410486,25.0,45.0
907.11035,0.19607646062992123,926.032820107909,0.00025370340306410486,25.0,45.0
908.51172,0.1966469409448819,926.3592841163312,0.00025370340306410486,25.0,45.0
909.91309,0.19719110236220472,926.2711935781025,0.00025370340306410486,25.0,45.0
911.31445,0.19778251968503938,928.0052901697592,0.00025370340306410486,25.0,45.0
912.71582,0.19835027559055118,925.3789972364785,0.00025370340306410486,25.0,45.0
914.11719,0.19896171259842518,925.3552309514411,0.00025370340306410486,25.0,45.0
915.51855,0.19952082677165356,927.4296617976049,0.00025370340306410486,25.0,45.0
916.91992,0.20014807086614173,927.1917357547046,0.00025370340306410486,25.0,45.0
918.32129,0.20076149606299212,924.9713120147388,0.00025370340306410486,25.0,45.0
919.72266,0.20131358267716534,926.630003947888,0.00025370340306410486,25.0,45.0
921.12402,0.20189446850393702,926.5592577970785,0.00025370340306410486,25.0,45.0
922.52539,0.20260299212598423,928.6078694565076,0.00025370340306410486,25.0,45.0
923.92676,0.20324368110236218,925.0764837478617,0.00025370340306410486,25.0,45.0
925.32813,0.2037553346456693,924.4275036188973,0.00025370340306410486,25.0,45.0
926.72949,0.20434206692913384,926.7967627319385,0.00025370340306410486,25.0,45.0
928.13086,0.20495956692913386,927.1306224503224,0.00025370340306410486,25.0,45.0
929.53223,0.2055897244094488,925.8769838136598,0.00025370340306410486,25.0,45.0
930.33301,0.20596068897637795,929.6808264245295,0.00025370340306410486,25.0,45.0