File: datasets/am_bench_2022/csv/45-XY.08-1.csv
Time(s),Strain(%),Stress(MPa),SR(s-1),Temp(C),Angle(deg)
26.662598,1.598586751968504e-05,24.127133410226836,0.00025370340306410486,25.0,45.0
28.26416,1.706759468503937e-05,29.1361886453928,0.00025370340306410486,25.0,45.0
29.765625,2.611082874015748e-05,34.35812379853902,0.00025370340306410486,25.0,45.0
31.26709,6.634407283464568e-05,39.65084454696911,0.00025370340306410486,25.0,45.0
32.768555,8.59028937007874e-05,45.438964500833016,0.00025370340306410486,25.0,45.0
34.27002,0.0001150099153543307,51.34334743047546,0.00025370340306410486,25.0,45.0
35.771484,0.00012931920472440946,57.77510957324106,0.00025370340306410486,25.0,45.0
37.272949,0.0001559715748031496,65.6292272202999,0.00025370340306410486,25.0,45.0
38.774414,0.00017824156299212597,70.55626553889529,0.00025370340306410486,25.0,45.0
40.275879,0.00019515131299212597,77.9927925156991,0.00025370340306410486,25.0,45.0
41.777344,0.00023821976377952754,85.26478277585544,0.00025370340306410486,25.0,45.0
43.278809,0.00025362590551181104,96.1125772138921,0.00025370340306410486,25.0,45.0
44.780273,0.0002925459251968504,103.59693451236704,0.00025370340306410486,25.0,45.0
46.281738,0.0003234308267716535,112.98299628348072,0.00025370340306410486,25.0,45.0
47.783203,0.00033589204724409445,122.0771011149558,0.00025370340306410486,25.0,45.0
49.284668,0.0003769882086614173,132.3834473920287,0.00025370340306410486,25.0,45.0
50.786133,0.00040192582677165355,139.30817890554914,0.00025370340306410486,25.0,45.0
52.287598,0.0004244723031496063,148.75635524798156,0.00025370340306410486,25.0,45.0
53.789063,0.0004669303149606299,160.47479430988082,0.00025370340306410486,25.0,45.0
55.290527,0.0004989793897637795,169.2761681404588,0.00025370340306410486,25.0,45.0
56.791992,0.0005462287598425197,182.5271716006664,0.00025370340306410486,25.0,45.0
58.293457,0.0005688906102362205,190.09387415096757,0.00025370340306410486,25.0,45.0
59.794922,0.0006139016732283465,201.37471485326157,0.00025370340306410486,25.0,45.0
61.296387,0.0006562185039370079,211.75654235550428,0.00025370340306410486,25.0,45.0
62.797852,0.0006615406496062992,223.39896450083302,0.00025370340306410486,25.0,45.0
64.299316,0.0007090636417322835,233.88114827630397,0.00025370340306410486,25.0,45.0
65.800781,0.0007434564763779528,242.6893451236704,0.00025370340306410486,25.0,45.0
67.302246,0.0007905568307086615,253.6450108932462,0.00025370340306410486,25.0,45.0
68.803711,0.0008057919291338582,263.62750224272713,0.00025370340306410486,25.0,45.0
70.305176,0.0008476310433070866,275.67891836473154,0.00025370340306410486,25.0,45.0
71.806641,0.0008797955118110236,287.06415481225173,0.00025370340306410486,25.0,45.0
73.308105,0.0009089638582677166,298.09306676919135,0.00025370340306410486,25.0,45.0
74.80957,0.0009513796456692913,310.09973087274125,0.00025370340306410486,25.0,45.0
76.311035,0.0010125084251968505,323.76257849545044,0.00025370340306410486,25.0,45.0
77.8125,0.0010028663976377951,333.0536716647443,0.00025370340306410486,25.0,45.0
79.313965,0.00105579062992126,344.70759964116365,0.00025370340306410486,25.0,45.0
80.81543,0.0011024166141732283,356.20451108547996,0.00025370340306410486,25.0,45.0
82.316895,0.001118690748031496,364.42358067409975,0.00025370340306410486,25.0,45.0
83.818359,0.0011580285826771654,374.363578110983,0.00025370340306410486,25.0,45.0
85.319824,0.001180313031496063,384.89252851467387,0.00025370340306410486,25.0,45.0
86.821289,0.00122467781496063,398.20202486223246,0.00025370340306410486,25.0,45.0
88.322754,0.0012497178346456692,407.7566833269255,0.00025370340306410486,25.0,45.0
89.824219,0.0012780585433070865,417.3105472254261,0.00025370340306410486,25.0,45.0
91.325684,0.001303636653543307,430.51690375496605,0.00025370340306410486,25.0,45.0
92.827148,0.0013364292913385827,439.5632961681405,0.00025370340306410486,25.0,45.0
94.328613,0.0013743924212598424,450.320953479431,0.00025370340306410486,25.0,45.0
95.830078,0.0013934513385826773,459.8716647443291,0.00025370340306410486,25.0,45.0
97.331543,0.0014383524606299213,470.09145200563887,0.00025370340306410486,25.0,45.0
98.833008,0.00145251718503937,480.17877739331027,0.00025370340306410486,25.0,45.0
100.33447,0.001473166594488189,489.9831090606177,0.00025370340306410486,25.0,45.0
101.83594,0.0015018439173228348,498.3306164295784,0.00025370340306410486,25.0,45.0
103.3374,0.0015401708661417323,510.0161476355248,0.00025370340306410486,25.0,45.0
104.83887,0.0015702725590551181,516.2247340766372,0.00025370340306410486,25.0,45.0
106.34033,0.0015826030511811025,524.9905164680251,0.00025370340306410486,25.0,45.0
107.8418,0.0016109235039370078,532.9995642701525,0.00025370340306410486,25.0,45.0
109.34326,0.0016300225787401574,540.3893630654876,0.00025370340306410486,25.0,45.0
110.84473,0.0016569493503937008,547.6309880815071,0.00025370340306410486,25.0,45.0
112.34619,0.0016817544291338584,555.5486095091632,0.00025370340306410486,25.0,45.0
113.84766,0.0017116005708661417,563.4581058567218,0.00025370340306410486,25.0,45.0
115.34912,0.0017115851771653543,570.4415224913495,0.00025370340306410486,25.0,45.0
116.85059,0.0017231792322834646,576.5202358067411,0.00025370340306410486,25.0,45.0
118.35205,0.0017607698228346458,583.1984108676149,0.00025370340306410486,25.0,45.0
119.85352,0.0017633962204724408,587.1238754325259,0.00025370340306410486,25.0,45.0
121.35498,0.0017913320472440944,595.2964500833014,0.00025370340306410486,25.0,45.0
122.85645,0.0018230025196850394,599.9514033064206,0.00025370340306410486,25.0,45.0
124.35791,0.0018380360433070866,605.0205049339997,0.00025370340306410486,25.0,45.0
125.85938,0.0018753153543307087,611.072946302704,0.00025370340306410486,25.0,45.0
127.36084,0.0018966439173228348,615.8409329744969,0.00025370340306410486,25.0,45.0
128.8623,0.0019066406102362205,620.9602204280405,0.00025370340306410486,25.0,45.0
130.36377,0.0019367078346456692,624.7944892989875,0.00025370340306410486,25.0,45.0
131.86523,0.0019523760629921259,629.0227092144047,0.00025370340306410486,25.0,45.0
133.3667,0.0019638700196850396,635.877354863514,0.00025370340306410486,25.0,45.0
134.86816,0.00200729094488189,639.3919261822375,0.00025370340306410486,25.0,45.0
136.36963,0.002034297637795276,642.5724208637703,0.00025370340306410486,25.0,45.0
137.87109,0.002050228937007874,647.5807766243753,0.00025370340306410486,25.0,45.0
139.37256,0.0020786391732283463,650.8975009611688,0.00025370340306410486,25.0,45.0
140.87402,0.0021216527559055117,655.0097398436499,0.00025370340306410486,25.0,45.0
142.37549,0.002159496653543307,659.7166474432911,0.00025370340306410486,25.0,45.0
143.87695,0.002179506299212598,664.1271305907984,0.00025370340306410486,25.0,45.0
145.37842,0.00221368405511811,669.0848647955914,0.00025370340306410486,25.0,45.0
146.87988,0.0022459023622047243,671.0312187620146,0.00025370340306410486,25.0,45.0
148.38135,0.0022864009842519686,672.9242855312059,0.00025370340306410486,25.0,45.0
149.88281,0.00231938562992126,676.0857362552865,0.00025370340306410486,25.0,45.0
151.38428,0.002373646456692913,681.8854799436115,0.00025370340306410486,25.0,45.0
152.88574,0.002416095472440945,682.8602332436243,0.00025370340306410486,25.0,45.0
154.38721,0.002468870472440945,686.440779187492,0.00025370340306410486,25.0,45.0
155.88867,0.0025044283464566927,689.2430603613994,0.00025370340306410486,25.0,45.0
157.39014,0.0025691456692913386,691.78985005767,0.00025370340306410486,25.0,45.0
158.8916,0.0026284527559055117,694.0483403819044,0.00025370340306410486,25.0,45.0
160.39307,0.002704401181102362,699.1115468409587,0.00025370340306410486,25.0,45.0
161.89453,0.0028441883858267717,702.7191336665385,0.00025370340306410486,25.0,45.0
163.396,0.0029028996062992127,703.9861848007178,0.00025370340306410486,25.0,45.0
164.89746,0.00298159625984252,706.6327053697296,0.00025370340306410486,25.0,45.0
166.39893,0.0030719092519685036,709.397693194925,0.00025370340306410486,25.0,45.0
167.90039,0.0031744511811023623,714.0922209406639,0.00025370340306410486,25.0,45.0
169.40186,0.0032652305118110237,715.3789568114828,0.00025370340306410486,25.0,45.0
170.90332,0.0034073572834645667,718.5956170703575,0.00025370340306410486,25.0,45.0
172.40479,0.003548591732283464,720.2200435729848,0.00025370340306410486,25.0,45.0
173.90625,0.0036467864173228342,721.755273612713,0.00025370340306410486,25.0,45.0
175.40771,0.003755560433070866,723.8609765474818,0.00025370340306410486,25.0,45.0
176.90918,0.00392209311023622,729.5291810841984,0.00025370340306410486,25.0,45.0
178.41064,0.004071108267716535,728.8691785210817,0.00025370340306410486,25.0,45.0
179.91211,0.004263216338582677,732.3085479943611,0.00025370340306410486,25.0,45.0
181.41357,0.0044119881889763774,731.9343329488657,0.00025370340306410486,25.0,45.0
182.91504,0.004628893503937008,735.9853389721902,0.00025370340306410486,25.0,45.0
184.4165,0.004820691732283464,735.441599384852,0.00025370340306410486,25.0,45.0
185.91797,0.005008788385826771,738.4617711136742,0.00025370340306410486,25.0,45.0
187.41943,0.0051918490157480315,739.9929514289375,0.00025370340306410486,25.0,45.0
188.9209,0.00541246437007874,742.5824682814302,0.00025370340306410486,25.0,45.0
190.42236,0.005666801968503937,744.5747276688453,0.00025370340306410486,25.0,45.0
191.92383,0.005935000590551181,745.5047289504037,0.00025370340306410486,25.0,45.0
193.42529,0.006202199803149606,747.046469306677,0.00025370340306410486,25.0,45.0
194.92676,0.006481213779527559,748.5459694989107,0.00025370340306410486,25.0,45.0
196.42822,0.006712119488188977,750.2532359348968,0.00025370340306410486,25.0,45.0
197.92969,0.006963105118110236,750.4270921440472,0.00025370340306410486,25.0,45.0
199.43115,0.007209857874015748,751.5218505702935,0.00025370340306410486,25.0,45.0
200.93262,0.007450403149606299,753.569524541843,0.00025370340306410486,25.0,45.0
202.43408,0.007721881496062992,753.9316673074458,0.00025370340306410486,25.0,45.0
203.93555,0.008064617716535433,757.4154043316673,0.00025370340306410486,25.0,45.0
205.43701,0.008396112007874016,757.7962322183776,0.00025370340306410486,25.0,45.0
206.93848,0.008722313385826772,758.9784185569653,0.00025370340306410486,25.0,45.0
208.43994,0.008974034448818898,758.475048058439,0.00025370340306410486,25.0,45.0
209.94141,0.009299122440944883,760.6841214917339,0.00025370340306410486,25.0,45.0
211.44287,0.009620277755905512,760.8712802768166,0.00025370340306410486,25.0,45.0
212.94434,0.009953309842519685,764.5195181340509,0.00025370340306410486,25.0,45.0
214.4458,0.010327204330708661,764.4246571831346,0.00025370340306410486,25.0,45.0
215.94727,0.010701059251968504,765.4034858387799,0.00025370340306410486,25.0,45.0
217.44873,0.011004192125984252,763.4208125080097,0.00025370340306410486,25.0,45.0
218.9502,0.011329792125984253,764.5185185185185,0.00025370340306410486,25.0,45.0
220.45166,0.011595938385826772,766.2849929514289,0.00025370340306410486,25.0,45.0
221.95313,0.011933660236220472,768.7154427784186,0.00025370340306410486,25.0,45.0
223.45459,0.012262768307086613,767.7110342176086,0.00025370340306410486,25.0,45.0
224.95605,0.012577209251968504,768.1579648853005,0.00025370340306410486,25.0,45.0
226.45752,0.01297393937007874,770.9641676278355,0.00025370340306410486,25.0,45.0
227.95898,0.013297233070866141,771.2533384595669,0.00025370340306410486,25.0,45.0
229.46045,0.01362263720472441,771.59477124183,0.00025370340306410486,25.0,45.0
230.96191,0.013975564370078741,772.4907343329489,0.00025370340306410486,25.0,45.0
232.46338,0.01438902913385827,774.969729591183,0.00025370340306410486,25.0,45.0
233.96484,0.014731302559055118,775.2129181084198,0.00025370340306410486,25.0,45.0
235.46631,0.01504595905511811,775.635550429322,0.00025370340306410486,25.0,45.0
236.96777,0.015414182086614174,775.9053697295913,0.00025370340306410486,25.0,45.0
238.46924,0.015772978937007874,776.6695629885942,0.00025370340306410486,25.0,45.0
239.9707,0.016159121259842518,777.79743688325,0.00025370340306410486,25.0,45.0
241.47217,0.01653373602362205,779.1622196591055,0.00025370340306410486,25.0,45.0
242.97363,0.016887793897637796,777.9344611047034,0.00025370340306410486,25.0,45.0
244.4751,0.017188712401574803,778.5231321286684,0.00025370340306410486,25.0,45.0
245.97656,0.017533249015748032,779.6063821607074,0.00025370340306410486,25.0,45.0
247.47803,0.01791192618110236,782.4244265026273,0.00025370340306410486,25.0,45.0
248.97949,0.018310224212598425,783.3776496219403,0.00025370340306410486,25.0,45.0
250.48096,0.018671709448818897,782.2015378700501,0.00025370340306410486,25.0,45.0
251.98242,0.018998563976377954,782.6197359989748,0.00025370340306410486,25.0,45.0
253.48389,0.019344735826771653,786.2098936306548,0.00025370340306410486,25.0,45.0
254.98535,0.019719411417322835,784.1641676278354,0.00025370340306410486,25.0,45.0
256.48682,0.02006058464566929,785.6680507497116,0.00025370340306410486,25.0,45.0
257.98828,0.020357566929133857,785.1012431116238,0.00025370340306410486,25.0,45.0
259.48975,0.02070667716535433,785.9269255414584,0.00025370340306410486,25.0,45.0
260.99121,0.021055088582677163,787.9181084198385,0.00025370340306410486,25.0,45.0
262.49268,0.02143371062992126,788.3591439190055,0.00025370340306410486,25.0,45.0
263.99414,0.021789027559055117,788.6950660002564,0.00025370340306410486,25.0,45.0
265.49561,0.02216202755905512,789.4525438933744,0.00025370340306410486,25.0,45.0
266.99707,0.022526370078740157,791.5263616557735,0.00025370340306410486,25.0,45.0
268.49854,0.02290316535433071,787.689196462899,0.00025370340306410486,25.0,45.0
270.0,0.02328644881889764,792.4084326541074,0.00025370340306410486,25.0,45.0
271.50146,0.023649728346456695,791.0155068563373,0.00025370340306410486,25.0,45.0
273.00293,0.024029779527559057,793.3401512238883,0.00025370340306410486,25.0,45.0
274.50439,0.02436403149606299,791.965269768038,0.00025370340306410486,25.0,45.0
276.00586,0.024690364173228348,795.5304370114059,0.00025370340306410486,25.0,45.0
277.50732,0.025112484251968503,795.2282455465847,0.00025370340306410486,25.0,45.0
279.00879,0.025514771653543305,795.4008970908625,0.00025370340306410486,25.0,45.0
280.51025,0.02588378346456693,796.4920927848264,0.00025370340306410486,25.0,45.0
282.01172,0.02625623228346457,795.6668973471742,0.00025370340306410486,25.0,45.0
283.51318,0.026583555118110235,796.9109060617711,0.00025370340306410486,25.0,45.0
285.01465,0.026975527559055117,796.4335255670896,0.00025370340306410486,25.0,45.0
286.51611,0.027381415354330706,798.8968858131489,0.00025370340306410486,25.0,45.0
288.01758,0.02770451377952756,798.4634884018967,0.00025370340306410486,25.0,45.0
289.51904,0.028086984251968507,800.3068563373062,0.00025370340306410486,25.0,45.0
291.02051,0.028476175196850393,799.8513135973344,0.00025370340306410486,25.0,45.0
292.52197,0.028855187007874015,800.2653082147891,0.00025370340306410486,25.0,45.0
294.02344,0.02916466338582677,800.6961425092913,0.00025370340306410486,25.0,45.0
295.5249,0.029456047244094487,800.7794438036652,0.00025370340306410486,25.0,45.0
297.02637,0.02980013188976378,800.9882609252851,0.00025370340306410486,25.0,45.0
298.52783,0.030147106299212596,800.8325515827246,0.00025370340306410486,25.0,45.0
300.0293,0.030517509842519684,803.4556965269768,0.00025370340306410486,25.0,45.0
301.53076,0.030870478346456693,804.3100346020761,0.00025370340306410486,25.0,45.0
303.03223,0.03135862795275591,803.9220812508009,0.00025370340306410486,25.0,45.0
304.53369,0.03169710236220472,804.8206587210047,0.00025370340306410486,25.0,45.0
306.03516,0.032097511811023625,806.8236575676023,0.00025370340306410486,25.0,45.0
307.53662,0.0324780374015748,804.9875432525952,0.00025370340306410486,25.0,45.0
309.03809,0.03281824606299213,805.521824939126,0.00025370340306410486,25.0,45.0
310.53955,0.03313340157480315,807.9142893758811,0.00025370340306410486,25.0,45.0
312.04102,0.03354674015748031,806.9663975394079,0.00025370340306410486,25.0,45.0
313.54248,0.033921627952755905,808.755017301038,0.00025370340306410486,25.0,45.0
315.04395,0.03428677755905512,809.0934256055363,0.00025370340306410486,25.0,45.0
316.54541,0.03464273622047244,810.0248109701397,0.00025370340306410486,25.0,45.0
318.04688,0.03502017125984252,809.1477893118032,0.00025370340306410486,25.0,45.0
319.54834,0.035361698818897634,810.328232731001,0.00025370340306410486,25.0,45.0
321.0498,0.035732574803149605,812.8481097013969,0.00025370340306410486,25.0,45.0
322.55127,0.036122019685039364,812.1029603998462,0.00025370340306410486,25.0,45.0
324.05273,0.036448647637795276,810.6871203383314,0.00025370340306410486,25.0,45.0
325.5542,0.03682431889763779,814.2306036139946,0.00025370340306410486,25.0,45.0
327.05566,0.03720393503937008,815.6279892349096,0.00025370340306410486,25.0,45.0
328.55713,0.03761740748031496,813.1562988594131,0.00025370340306410486,25.0,45.0
330.05859,0.038018996062992125,812.954299628348,0.00025370340306410486,25.0,45.0
331.56006,0.038329375984251964,812.9558118672305,0.00025370340306410486,25.0,45.0
333.06152,0.03861386220472441,813.1912854030502,0.00025370340306410486,25.0,45.0
334.56299,0.038899326771653545,814.7895937459951,0.00025370340306410486,25.0,45.0
336.06445,0.039254814960629915,816.4199666794822,0.00025370340306410486,25.0,45.0
337.56592,0.03961767322834646,818.1828527489428,0.00025370340306410486,25.0,45.0
339.06738,0.03995290157480315,815.7216711521211,0.00025370340306410486,25.0,45.0
340.56885,0.0403565531496063,819.8770216583365,0.00025370340306410486,25.0,45.0
342.07031,0.040707824803149606,816.8999871844162,0.00025370340306410486,25.0,45.0
343.57178,0.04106148228346457,819.8454440599769,0.00025370340306410486,25.0,45.0
345.07324,0.041452677165354335,820.0503139818019,0.00025370340306410486,25.0,45.0
346.57471,0.041838816929133854,820.4119953863898,0.00025370340306410486,25.0,45.0
348.07617,0.042221437007874014,820.2320902217095,0.00025370340306410486,25.0,45.0
349.57764,0.042559655511811026,820.4953992054338,0.00025370340306410486,25.0,45.0
351.0791,0.04297428937007874,822.1860822760477,0.00025370340306410486,25.0,45.0
352.58057,0.0433500905511811,822.7446366782007,0.00025370340306410486,25.0,45.0
354.08203,0.043699576771653544,822.3818787645777,0.00025370340306410486,25.0,45.0
355.5835,0.044032320866141735,822.3461489170832,0.00025370340306410486,25.0,45.0
357.08496,0.04435729921259842,821.7904139433551,0.00025370340306410486,25.0,45.0
358.58643,0.04468497834645669,823.2727156221966,0.00025370340306410486,25.0,45.0
360.08789,0.045069996062992126,825.1575291554531,0.00025370340306410486,25.0,45.0
361.58936,0.04545865354330708,826.0709470716391,0.00025370340306410486,25.0,45.0
363.09082,0.04585173818897638,825.5295911828783,0.00025370340306410486,25.0,45.0
364.59229,0.046234082677165354,826.2697424067667,0.00025370340306410486,25.0,45.0
366.09375,0.046550391732283466,825.4832244008714,0.00025370340306410486,25.0,45.0
367.59521,0.04686383858267717,826.9384339356658,0.00025370340306410486,25.0,45.0
369.09668,0.047231206692913384,826.5960271690375,0.00025370340306410486,25.0,45.0
370.59814,0.0475626594488189,829.5611944124055,0.00025370340306410486,25.0,45.0
372.09961,0.04793167716535433,828.8720235806741,0.00025370340306410486,25.0,45.0
373.60107,0.04828004330708661,831.515622196591,0.00025370340306410486,25.0,45.0
375.10254,0.048638999999999995,827.9976675637574,0.00025370340306410486,25.0,45.0
376.604,0.049026031496062994,831.3722670767653,0.00025370340306410486,25.0,45.0
378.10547,0.04937310826771654,829.3250800973984,0.00025370340306410486,25.0,45.0
379.60693,0.04970112795275591,829.6915801614764,0.00025370340306410486,25.0,45.0
381.1084,0.050055476377952754,831.5933358964501,0.00025370340306410486,25.0,45.0
382.60986,0.05038704527559055,832.8309624503396,0.00025370340306410486,25.0,45.0
384.11133,0.0507903622047244,833.1044982698962,0.00025370340306410486,25.0,45.0
385.61279,0.05117452362204725,832.368037934128,0.00025370340306410486,25.0,45.0
387.11426,0.05152358661417323,833.1704472638729,0.00025370340306410486,25.0,45.0
388.61572,0.051922856299212596,835.4234268870947,0.00025370340306410486,25.0,45.0
390.11719,0.05232070472440945,832.4129693707548,0.00025370340306410486,25.0,45.0
391.61865,0.05267843307086614,836.4198897859798,0.00025370340306410486,25.0,45.0
393.12012,0.053021218503937005,835.1556068178905,0.00025370340306410486,25.0,45.0
394.62158,0.05334372244094488,834.6965526079713,0.00025370340306410486,25.0,45.0
396.12305,0.05365100984251969,835.8526464180443,0.00025370340306410486,25.0,45.0
397.62451,0.05406421653543307,837.4204793028322,0.00025370340306410486,25.0,45.0
399.12598,0.05437456692913385,836.5601947968729,0.00025370340306410486,25.0,45.0
400.62744,0.05471843110236221,837.317108804306,0.00025370340306410486,25.0,45.0
402.12891,0.05509223818897637,837.4496475714469,0.00025370340306410486,25.0,45.0
403.63037,0.05544804133858268,837.5514545687556,0.00025370340306410486,25.0,45.0
405.13184,0.05573554724409449,837.5716775599128,0.00025370340306410486,25.0,45.0
406.6333,0.0560585374015748,839.9326156606434,0.00025370340306410486,25.0,45.0
408.13477,0.05641856496062991,840.6845828527489,0.00025370340306410486,25.0,45.0
409.63623,0.05676312204724409,839.9035755478662,0.00025370340306410486,25.0,45.0
411.1377,0.057153080708661416,841.2155324875048,0.00025370340306410486,25.0,45.0
412.63916,0.057529165354330704,842.3805972062028,0.00025370340306410486,25.0,45.0
414.14063,0.057871728346456694,841.6365500448545,0.00025370340306410486,25.0,45.0
415.64209,0.05823467716535433,842.5812123542227,0.00025370340306410486,25.0,45.0
417.14355,0.05858770472440945,843.9331026528258,0.00025370340306410486,25.0,45.0
418.64502,0.05898128937007874,842.6372164552096,0.00025370340306410486,25.0,45.0
420.14648,0.0593531968503937,843.39825708061,0.00025370340306410486,25.0,45.0
421.64795,0.05970733464566928,843.5725233884403,0.00025370340306410486,25.0,45.0
423.14941,0.06004469881889764,844.959784698193,0.00025370340306410486,25.0,45.0
424.65088,0.060453541338582675,845.0555940023067,0.00025370340306410486,25.0,45.0
426.15234,0.06080368897637795,844.7916442393952,0.00025370340306410486,25.0,45.0
427.65381,0.06114611614173228,843.5990772779701,0.00025370340306410486,25.0,45.0
429.15527,0.06148213188976378,844.8961425092913,0.00025370340306410486,25.0,45.0
430.65674,0.06181526181102362,846.8234268870948,0.00025370340306410486,25.0,45.0
432.1582,0.06216885826771653,844.3493528130206,0.00025370340306410486,25.0,45.0
433.65967,0.06250113188976378,847.6302191464822,0.00025370340306410486,25.0,45.0
435.16113,0.06294496259842519,847.1023965141612,0.00025370340306410486,25.0,45.0
436.6626,0.06331998031496062,848.2729463027041,0.00025370340306410486,25.0,45.0
438.16406,0.063678687007874,849.6425477380495,0.00025370340306410486,25.0,45.0
439.66553,0.06400228346456693,849.5147507368961,0.00025370340306410486,25.0,45.0
441.16699,0.0643266594488189,848.7459438677432,0.00025370340306410486,25.0,45.0
442.66846,0.06464711023622047,850.6365500448545,0.00025370340306410486,25.0,45.0
444.16992,0.06504454921259842,851.5561707035755,0.00025370340306410486,25.0,45.0
445.67139,0.06542284448818898,849.1791105984877,0.00025370340306410486,25.0,45.0
447.17285,0.06578666141732283,851.5430475458157,0.00025370340306410486,25.0,45.0
448.67432,0.066107968503937,850.7439446366782,0.00025370340306410486,25.0,45.0
450.17578,0.0664196496062992,850.9557093425606,0.00025370340306410486,25.0,45.0
451.67725,0.06677762401574804,853.4738946559015,0.00025370340306410486,25.0,45.0
453.17871,0.06711355708661418,853.9383314109958,0.00025370340306410486,25.0,45.0
454.68018,0.06745334448818897,853.0622068435217,0.00025370340306410486,25.0,45.0
456.18164,0.06783060826771653,853.8833269255415,0.00025370340306410486,25.0,45.0
457.68311,0.06819797440944882,853.0072536204024,0.00025370340306410486,25.0,45.0
459.18457,0.06859399409448819,855.8381391772394,0.00025370340306410486,25.0,45.0
460.68604,0.06893917125984252,854.2585928489043,0.00025370340306410486,25.0,45.0
462.1875,0.06931431102362205,855.6264513648597,0.00025370340306410486,25.0,45.0
463.68896,0.06972283858267717,856.207535563245,0.00025370340306410486,25.0,45.0
465.19043,0.07009248031496063,855.9798795335128,0.00025370340306410486,25.0,45.0
466.69189,0.07049992716535433,857.0549275919518,0.00025370340306410486,25.0,45.0
468.19336,0.07084622244094488,854.2593361527618,0.00025370340306410486,25.0,45.0
469.69482,0.07121066141732284,855.9030885556837,0.00025370340306410486,25.0,45.0
471.19629,0.0715201062992126,857.3748301935153,0.00025370340306410486,25.0,45.0
472.69775,0.07181589370078739,857.2467256183519,0.00025370340306410486,25.0,45.0
474.19922,0.07218882283464567,860.0854799436115,0.00025370340306410486,25.0,45.0
475.70068,0.07251542125984252,857.1731897987953,0.00025370340306410486,25.0,45.0
477.20215,0.07284046062992126,857.3450211457132,0.00025370340306410486,25.0,45.0
478.70361,0.07320443503937007,861.1079072151737,0.00025370340306410486,25.0,45.0
480.20508,0.07359601377952756,860.8100474176599,0.00025370340306410486,25.0,45.0
481.70654,0.07392535826771654,859.7948737665001,0.00025370340306410486,25.0,45.0
483.20801,0.07431067716535433,859.2565423555043,0.00025370340306410486,25.0,45.0
484.70947,0.07468577559055117,862.5648853005254,0.00025370340306410486,25.0,45.0
486.21094,0.07508126574803149,862.9537357426631,0.00025370340306410486,25.0,45.0
487.7124,0.07546456102362205,861.3659105472254,0.00025370340306410486,25.0,45.0
489.21387,0.07586751377952757,864.3745226195053,0.00025370340306410486,25.0,45.0
490.71533,0.07625401771653544,862.5974112520826,0.00025370340306410486,25.0,45.0
492.2168,0.07663824409448819,863.9896706394976,0.00025370340306410486,25.0,45.0
493.71826,0.07699426968503938,864.5465333845957,0.00025370340306410486,25.0,45.0
495.21973,0.07734997440944882,863.6978854286813,0.00025370340306410486,25.0,45.0
496.72119,0.07770983661417323,863.5677816224529,0.00025370340306410486,25.0,45.0
498.22266,0.07807768503937007,864.8307574009997,0.00025370340306410486,25.0,45.0
499.72412,0.07843748228346456,866.4330129437395,0.00025370340306410486,25.0,45.0
501.22559,0.07880297834645669,864.791951813405,0.00025370340306410486,25.0,45.0
502.72705,0.07916017125984252,865.8047673971549,0.00025370340306410486,25.0,45.0
504.22852,0.07947736811023622,866.1655773420479,0.00025370340306410486,25.0,45.0
505.72998,0.07985683661417323,866.241906958862,0.00025370340306410486,25.0,45.0
507.23145,0.08021566732283465,868.1419710367807,0.00025370340306410486,25.0,45.0
508.73291,0.08054040748031496,865.9423555042932,0.00025370340306410486,25.0,45.0
510.23438,0.08092658661417323,868.122952710496,0.00025370340306410486,25.0,45.0
511.73584,0.08129286811023623,868.3096757657312,0.00025370340306410486,25.0,45.0
513.2373,0.08162802755905511,867.2520825323593,0.00025370340306410486,25.0,45.0
514.73877,0.08192945866141732,869.0102780981674,0.00025370340306410486,25.0,45.0
516.24023,0.08227677362204724,867.8264001025248,0.00025370340306410486,25.0,45.0
517.7417,0.08267819488188977,871.6029988465974,0.00025370340306410486,25.0,45.0
519.24316,0.08308575393700787,869.5548122516981,0.00025370340306410486,25.0,45.0
520.74463,0.08342112401574804,869.0391387927721,0.00025370340306410486,25.0,45.0
522.24609,0.08372114173228347,870.046418044342,0.00025370340306410486,25.0,45.0
523.74756,0.08406473622047243,870.4275022427272,0.00025370340306410486,25.0,45.0
525.24902,0.08442428937007875,872.5354350890683,0.00025370340306410486,25.0,45.0
526.75049,0.08485038582677165,872.6554658464694,0.00025370340306410486,25.0,45.0
528.25195,0.08521382086614172,872.0786876842241,0.00025370340306410486,25.0,45.0
529.75342,0.08560427952755906,873.2640779187492,0.00025370340306410486,25.0,45.0
531.25488,0.08600122440944881,872.7984364987826,0.00025370340306410486,25.0,45.0
532.75635,0.08632991338582678,872.720799692426,0.00025370340306410486,25.0,45.0
534.25781,0.08671142913385826,874.0034089452774,0.00025370340306410486,25.0,45.0
535.75928,0.08710517125984252,873.1847238241702,0.00025370340306410486,25.0,45.0
537.26074,0.08748111614173228,874.718082788671,0.00025370340306410486,25.0,45.0
538.76221,0.08786410433070865,874.40809944893,0.00025370340306410486,25.0,45.0
540.26367,0.08820529921259843,874.7475586312956,0.00025370340306410486,25.0,45.0
541.76514,0.08854282874015748,874.4790465205691,0.00025370340306410486,25.0,45.0
543.2666,0.08894891535433071,875.3837242086378,0.00025370340306410486,25.0,45.0
544.76807,0.08930629724409449,876.0404459823145,0.00025370340306410486,25.0,45.0
546.26953,0.08970829921259842,875.0655901576317,0.00025370340306410486,25.0,45.0
547.771,0.0900228779527559,876.0052800205049,0.00025370340306410486,25.0,45.0
549.27246,0.09036342322834647,876.9307958477508,0.00025370340306410486,25.0,45.0
550.77393,0.090710718503937,878.0751249519416,0.00025370340306410486,25.0,45.0
552.27539,0.09101508464566929,876.5340510060233,0.00025370340306410486,25.0,45.0
553.77686,0.09139010039370078,877.3874150967576,0.00025370340306410486,25.0,45.0
555.27832,0.09178676968503936,877.5544277841856,0.00025370340306410486,25.0,45.0
556.77979,0.0922235748031496,879.4129950019222,0.00025370340306410486,25.0,45.0
558.28125,0.0925692874015748,877.7920287069076,0.00025370340306410486,25.0,45.0
559.78271,0.09295613582677166,881.1694989106753,0.00025370340306410486,25.0,45.0
561.28418,0.09339795669291338,878.6915545303088,0.00025370340306410486,25.0,45.0
562.78564,0.09378367913385827,879.6350121748046,0.00025370340306410486,25.0,45.0
564.28711,0.09419765551181103,880.8350890683071,0.00025370340306410486,25.0,45.0
565.78857,0.09461844881889764,879.2225041650647,0.00025370340306410486,25.0,45.0
567.29004,0.09497303740157481,881.2472126105345,0.00025370340306410486,25.0,45.0
568.7915,0.09530066338582677,881.1554273997182,0.00025370340306410486,25.0,45.0
570.29297,0.09563978346456693,881.8833781878765,0.00025370340306410486,25.0,45.0
571.79443,0.09600864566929133,881.8986287325388,0.00025370340306410486,25.0,45.0
573.2959,0.09637757283464567,882.4425477380495,0.00025370340306410486,25.0,45.0
574.79736,0.09676631692913386,884.8375240292196,0.00025370340306410486,25.0,45.0
576.29883,0.0971827342519685,883.4466487248494,0.00025370340306410486,25.0,45.0
577.80029,0.09760241732283464,884.2197103678072,0.00025370340306410486,25.0,45.0
579.30176,0.09795014370078739,883.5040881712162,0.00025370340306410486,25.0,45.0
580.80322,0.09829181299212598,883.1715494040753,0.00025370340306410486,25.0,45.0
582.30469,0.09860889173228347,883.9332308086633,0.00025370340306410486,25.0,45.0
583.80615,0.09895623031496063,884.2631295655517,0.00025370340306410486,25.0,45.0
585.30762,0.09931736614173228,884.4379853902345,0.00025370340306410486,25.0,45.0
586.80908,0.09971489763779526,884.6033064206074,0.00025370340306410486,25.0,45.0
588.31055,0.10004230118110236,885.7684736639753,0.00025370340306410486,25.0,45.0
589.81201,0.1004399625984252,886.8870690759964,0.00025370340306410486,25.0,45.0
591.31348,0.1008622874015748,887.7631423811355,0.00025370340306410486,25.0,45.0
592.81494,0.10132666338582677,886.7288222478535,0.00025370340306410486,25.0,45.0
594.31641,0.10169656496062993,887.2882481097014,0.00025370340306410486,25.0,45.0
595.81787,0.1020280157480315,884.8709983339742,0.00025370340306410486,25.0,45.0
597.31934,0.10238109055118111,886.1014481609637,0.00025370340306410486,25.0,45.0
598.8208,0.10275023031496064,886.6332692554146,0.00025370340306410486,25.0,45.0
600.32227,0.10314453543307087,887.6247853389722,0.00025370340306410486,25.0,45.0
601.82373,0.10344097440944883,886.8201204664872,0.00025370340306410486,25.0,45.0
603.3252,0.10391054921259843,889.5441240548507,0.00025370340306410486,25.0,45.0
604.82666,0.10431362007874016,888.9941304626426,0.00025370340306410486,25.0,45.0
606.32813,0.1047351811023622,890.5623734461105,0.00025370340306410486,25.0,45.0
607.82959,0.105123187007874,888.9650390875304,0.00025370340306410486,25.0,45.0
609.33105,0.10547626181102362,889.0512623349994,0.00025370340306410486,25.0,45.0
610.83252,0.10586247244094488,890.327771369986,0.00025370340306410486,25.0,45.0
612.33398,0.106218281496063,890.1219530949635,0.00025370340306410486,25.0,45.0
613.83545,0.10658319488188978,891.6022555427401,0.00025370340306410486,25.0,45.0
615.33691,0.10692940748031496,890.8982186338587,0.00025370340306410486,25.0,45.0
616.83838,0.1072668188976378,891.1406382160707,0.00025370340306410486,25.0,45.0
618.33984,0.10764297244094488,892.9122901448161,0.00025370340306410486,25.0,45.0
619.84131,0.10801977362204725,891.399948737665,0.00025370340306410486,25.0,45.0
621.34277,0.10838874606299212,891.9569909009356,0.00025370340306410486,25.0,45.0
622.84424,0.10875431889763779,891.5162117134436,0.00025370340306410486,25.0,45.0
624.3457,0.10913117716535432,891.9054978854286,0.00025370340306410486,25.0,45.0
625.84717,0.10949054133858267,893.165526079713,0.00025370340306410486,25.0,45.0
627.34863,0.10987170472440944,892.4262463155196,0.00025370340306410486,25.0,45.0
628.8501,0.11033341929133858,895.1402281173907,0.00025370340306410486,25.0,45.0
630.35156,0.11073370866141732,895.2980648468538,0.00025370340306410486,25.0,45.0
631.85303,0.11114216535433072,895.1950019223376,0.00025370340306410486,25.0,45.0
633.35449,0.1115819251968504,893.9904652056902,0.00025370340306410486,25.0,45.0
634.85596,0.11196558858267718,893.4662565679866,0.00025370340306410486,25.0,45.0
636.35742,0.11233178149606299,894.0912725874663,0.00025370340306410486,25.0,45.0
637.85889,0.11273552165354331,896.2591567345893,0.00025370340306410486,25.0,45.0
639.36035,0.11310945866141732,895.5635012174805,0.00025370340306410486,25.0,45.0
640.86182,0.11351993307086614,896.5599641163654,0.00025370340306410486,25.0,45.0
642.36328,0.11389241535433071,895.918697936691,0.00025370340306410486,25.0,45.0
643.86475,0.11430440157480316,896.5555811867231,0.00025370340306410486,25.0,45.0
645.36621,0.11473373228346458,896.20184544406,0.00025370340306410486,25.0,45.0
646.86768,0.11511409842519686,897.1103934384212,0.00025370340306410486,25.0,45.0
648.36914,0.1154806437007874,896.4208637703448,0.00025370340306410486,25.0,45.0
649.87061,0.11584955905511812,897.6905805459439,0.00025370340306410486,25.0,45.0
651.37207,0.11623472440944882,896.850826605152,0.00025370340306410486,25.0,45.0
652.87354,0.11664418897637796,898.1349480968859,0.00025370340306410486,25.0,45.0
654.375,0.11695953149606299,896.2791234140716,0.00025370340306410486,25.0,45.0
655.87646,0.11738370866141731,899.6189926951173,0.00025370340306410486,25.0,45.0
657.37793,0.11781560826771653,898.0534153530693,0.00025370340306410486,25.0,45.0
658.87939,0.1181671594488189,897.3080097398437,0.00025370340306410486,25.0,45.0
660.38086,0.11859367125984252,898.9136485966936,0.00025370340306410486,25.0,45.0
661.88232,0.11901156102362204,899.9767525310779,0.00025370340306410486,25.0,45.0
663.38379,0.11939900393700786,898.6942458028963,0.00025370340306410486,25.0,45.0
664.88525,0.11980480708661417,899.6957836729464,0.00025370340306410486,25.0,45.0
666.38672,0.1202028562992126,900.3340510060233,0.00025370340306410486,25.0,45.0
667.88818,0.1205780964566929,901.3797001153403,0.00025370340306410486,25.0,45.0
669.38965,0.1209848622047244,900.6305523516596,0.00025370340306410486,25.0,45.0
670.89111,0.12143403346456694,901.0552351659618,0.00025370340306410486,25.0,45.0
672.39258,0.12188998425196851,901.8928360886838,0.00025370340306410486,25.0,45.0
673.89404,0.12229972047244095,902.8575676022042,0.00025370340306410486,25.0,45.0
675.39551,0.12267473622047245,901.8067922593874,0.00025370340306410486,25.0,45.0
676.89697,0.1230173464566929,901.9073945918237,0.00025370340306410486,25.0,45.0
678.39844,0.12349914566929134,903.0957324106113,0.00025370340306410486,25.0,45.0
679.8999,0.12394437401574802,901.565064718698,0.00025370340306410486,25.0,45.0
681.40137,0.12430994488188975,901.7530437011405,0.00025370340306410486,25.0,45.0
682.90283,0.12471152559055118,903.239343842112,0.00025370340306410486,25.0,45.0
684.4043,0.1251478720472441,903.4032807894399,0.00025370340306410486,25.0,45.0
685.90576,0.12551163582677166,901.9417659874407,0.00025370340306410486,25.0,45.0
687.40723,0.12586663582677166,903.2813789568115,0.00025370340306410486,25.0,45.0
688.90869,0.12627368307086614,903.4684864795593,0.00025370340306410486,25.0,45.0
690.41016,0.12665863779527559,903.048981161092,0.00025370340306410486,25.0,45.0
691.91162,0.12711545866141732,905.2166089965398,0.00025370340306410486,25.0,45.0
693.41309,0.12751532677165356,903.1687556068179,0.00025370340306410486,25.0,45.0
694.91455,0.12786509251968503,903.9710367807253,0.00025370340306410486,25.0,45.0
696.41602,0.12827661023622047,905.2198128924772,0.00025370340306410486,25.0,45.0
697.91748,0.12881057677165353,905.4307574009997,0.00025370340306410486,25.0,45.0
699.41895,0.12917938582677166,905.036575676022,0.00025370340306410486,25.0,45.0
700.92041,0.12959291141732282,905.0998590285787,0.00025370340306410486,25.0,45.0
702.42188,0.13005394488188976,907.5318723567858,0.00025370340306410486,25.0,45.0
703.92334,0.13048199409448819,907.0202486223247,0.00025370340306410486,25.0,45.0
705.4248,0.13086991732283462,905.7963860053825,0.00025370340306410486,25.0,45.0
706.92627,0.131352562992126,906.8002306805075,0.00025370340306410486,25.0,45.0
708.42773,0.1318079744094488,906.3336665385109,0.00025370340306410486,25.0,45.0
709.9292,0.1322213346456693,906.121209791106,0.00025370340306410486,25.0,45.0
711.43066,0.13257994881889762,906.1782135076253,0.00025370340306410486,25.0,45.0
712.93213,0.13301770275590552,907.7266179674484,0.00025370340306410486,25.0,45.0
714.43359,0.13338408464566928,906.80235806741,0.00025370340306410486,25.0,45.0
715.93506,0.1337870964566929,908.5244649493785,0.00025370340306410486,25.0,45.0
717.43652,0.13423953937007874,908.4723311546841,0.00025370340306410486,25.0,45.0
718.93799,0.1346581909448819,907.0537998205817,0.00025370340306410486,25.0,45.0
720.43945,0.1350602874015748,908.8627450980392,0.00025370340306410486,25.0,45.0
721.94092,0.1354316909448819,908.314186851211,0.00025370340306410486,25.0,45.0
723.44238,0.13581311417322836,907.6512623349994,0.00025370340306410486,25.0,45.0
724.94385,0.13621267519685037,909.519671921056,0.00025370340306410486,25.0,45.0
726.44531,0.1366300374015748,910.2043829296425,0.00025370340306410486,25.0,45.0
727.94678,0.1370588622047244,910.6343970267845,0.00025370340306410486,25.0,45.0
729.44824,0.13753091338582676,910.9104190695886,0.00025370340306410486,25.0,45.0
730.94971,0.13792877362204725,907.561271305908,0.00025370340306410486,25.0,45.0
732.45117,0.1383373818897638,909.2523388440343,0.00025370340306410486,25.0,45.0
733.95264,0.1388296594488189,910.6171728822247,0.00025370340306410486,25.0,45.0
735.4541,0.13926519685039368,910.1580674099705,0.00025370340306410486,25.0,45.0
736.95557,0.13972468110236222,910.3154427784185,0.00025370340306410486,25.0,45.0
738.45703,0.1401702125984252,909.5096501345637,0.00025370340306410486,25.0,45.0
739.9585,0.1405768976377953,909.6702806612841,0.00025370340306410486,25.0,45.0
741.45996,0.14095943503937008,911.0173010380622,0.00025370340306410486,25.0,45.0
742.96143,0.1414470905511811,911.7297193387159,0.00025370340306410486,25.0,45.0
744.46289,0.14183895472440944,910.0287325387671,0.00025370340306410486,25.0,45.0
745.96436,0.14223904527559056,911.9066256567986,0.00025370340306410486,25.0,45.0
747.46582,0.1427462125984252,913.4168909393823,0.00025370340306410486,25.0,45.0
748.96729,0.1432355590551181,912.4534153530693,0.00025370340306410486,25.0,45.0
750.46875,0.14366046456692913,911.920082019736,0.00025370340306410486,25.0,45.0
751.97021,0.1440815688976378,911.9357170319108,0.00025370340306410486,25.0,45.0
753.47168,0.14452293700787402,911.6926823016788,0.00025370340306410486,25.0,45.0
754.97314,0.1449561496062992,912.2894784057414,0.00025370340306410486,25.0,45.0
756.47461,0.14540881692913385,912.5717544534155,0.00025370340306410486,25.0,45.0
757.97607,0.14588090157480316,912.6962706651288,0.00025370340306410486,25.0,45.0
759.47754,0.14633286417322833,911.7716006664103,0.00025370340306410486,25.0,45.0
760.979,0.14674530905511812,913.7884147122902,0.00025370340306410486,25.0,45.0
762.48047,0.14717283267716535,913.7040625400488,0.00025370340306410486,25.0,45.0
763.98193,0.14759872440944882,914.5168524926311,0.00025370340306410486,25.0,45.0
765.4834,0.1480875748031496,913.0709214404716,0.00025370340306410486,25.0,45.0
766.98486,0.14858577952755905,913.4610278098168,0.00025370340306410486,25.0,45.0
768.48633,0.14901655118110235,914.1434832756632,0.00025370340306410486,25.0,45.0
769.98779,0.1494555964566929,912.8693066769191,0.00025370340306410486,25.0,45.0
771.48926,0.14991031692913384,914.2194284249648,0.00025370340306410486,25.0,45.0
772.99072,0.15033555118110234,914.4924516211713,0.00025370340306410486,25.0,45.0
774.49219,0.15080719094488187,915.2661540433166,0.00025370340306410486,25.0,45.0
775.99365,0.1513066377952756,915.7098808150712,0.00025370340306410486,25.0,45.0
777.49512,0.1517735590551181,914.6805074971165,0.00025370340306410486,25.0,45.0
778.99658,0.1523096377952756,915.7618095604255,0.00025370340306410486,25.0,45.0
780.49805,0.15280297244094487,914.0551839036268,0.00025370340306410486,25.0,45.0
781.99951,0.15322359448818898,915.591849288735,0.00025370340306410486,25.0,45.0
783.50098,0.15370310826771652,916.7628348071255,0.00025370340306410486,25.0,45.0
785.00244,0.15418299606299213,914.8311162373446,0.00025370340306410486,25.0,45.0
786.50391,0.15465417716535432,917.7008586441112,0.00025370340306410486,25.0,45.0
788.00537,0.155049,916.3971549404075,0.00025370340306410486,25.0,45.0
789.50684,0.15545448622047245,916.5660387030629,0.00025370340306410486,25.0,45.0
791.0083,0.15590053543307086,916.8160451108548,0.00025370340306410486,25.0,45.0
792.50977,0.15638771062992127,917.084992951429,0.00025370340306410486,25.0,45.0
794.01123,0.15687161023622045,916.1638087914905,0.00025370340306410486,25.0,45.0
795.5127,0.157296562992126,915.6061771113675,0.00025370340306410486,25.0,45.0
797.01416,0.15772858070866141,915.7637575291554,0.00025370340306410486,25.0,45.0
798.51563,0.15816536023622046,917.2227861079072,0.00025370340306410486,25.0,45.0
800.01709,0.1586360374015748,918.2206843521723,0.00025370340306410486,25.0,45.0
801.51855,0.1591636318897638,919.0377290785596,0.00025370340306410486,25.0,45.0
803.02002,0.15959645866141733,916.9408176342432,0.00025370340306410486,25.0,45.0
804.52148,0.16005927362204722,918.923414071511,0.00025370340306410486,25.0,45.0
806.02295,0.16058608267716537,918.5053440984237,0.00025370340306410486,25.0,45.0
807.52441,0.16116082283464567,917.7952326028451,0.00025370340306410486,25.0,45.0
809.02588,0.16167588582677167,917.8177623990773,0.00025370340306410486,25.0,45.0
810.52734,0.16215037598425197,917.7470972702806,0.00025370340306410486,25.0,45.0
812.02881,0.16258789566929133,916.1101114955786,0.00025370340306410486,25.0,45.0
813.53027,0.1630937027559055,919.4591311034218,0.00025370340306410486,25.0,45.0
815.03174,0.1636767244094488,917.8630014097142,0.00025370340306410486,25.0,45.0
816.5332,0.16422588582677167,920.1570421632705,0.00025370340306410486,25.0,45.0
818.03467,0.16471558267716535,917.5473535819557,0.00025370340306410486,25.0,45.0
819.53613,0.16514668307086613,918.3290016660259,0.00025370340306410486,25.0,45.0
821.0376,0.16563703740157482,919.837652185057,0.00025370340306410486,25.0,45.0
822.53906,0.1661223464566929,920.7354863514033,0.00025370340306410486,25.0,45.0
824.04053,0.1666148937007874,919.2105087786748,0.00025370340306410486,25.0,45.0
825.54199,0.16706022637795276,919.1093169293862,0.00025370340306410486,25.0,45.0
827.04346,0.16752103740157478,919.2966807638088,0.00025370340306410486,25.0,45.0
828.54492,0.16802879133858267,920.6509547609894,0.00025370340306410486,25.0,45.0
830.04639,0.16858871062992126,921.2325259515571,0.00025370340306410486,25.0,45.0
831.54785,0.16912265354330708,920.1364603357683,0.00025370340306410486,25.0,45.0
833.04932,0.1696505531496063,919.367012687428,0.00025370340306410486,25.0,45.0
834.55078,0.17013303346456693,920.6338587722671,0.00025370340306410486,25.0,45.0
836.05225,0.17068831889763778,922.4596437267717,0.00025370340306410486,25.0,45.0
837.55371,0.17125111417322836,919.7669357939254,0.00025370340306410486,25.0,45.0
839.05518,0.1717716338582677,919.5805972062027,0.00025370340306410486,25.0,45.0
840.55664,0.17224786023622046,921.6693066769192,0.00025370340306410486,25.0,45.0
842.05811,0.1727303188976378,920.6118415993849,0.00025370340306410486,25.0,45.0
843.55957,0.1732354094488189,920.8085095476099,0.00025370340306410486,25.0,45.0
845.06104,0.17374574409448817,920.8287838011021,0.00025370340306410486,25.0,45.0
846.5625,0.17418360433070865,919.5009867999488,0.00025370340306410486,25.0,45.0
848.06396,0.17474013188976378,923.1179546328335,0.00025370340306410486,25.0,45.0
849.56543,0.17538808661417324,922.2248109701397,0.00025370340306410486,25.0,45.0
851.06689,0.17596282677165354,920.7304113802384,0.00025370340306410486,25.0,45.0
852.56836,0.1765183937007874,921.2464949378444,0.00025370340306410486,25.0,45.0
854.06982,0.17700872244094487,920.440625400487,0.00025370340306410486,25.0,45.0
855.57129,0.17748856496062992,920.8578239138793,0.00025370340306410486,25.0,45.0
857.07275,0.17801660433070865,920.764141996668,0.00025370340306410486,25.0,45.0
858.57422,0.17854426968503936,919.5050621555812,0.00025370340306410486,25.0,45.0
860.07568,0.17905724606299211,921.4829680891966,0.00025370340306410486,25.0,45.0
861.57715,0.17960339173228348,922.6156606433423,0.00025370340306410486,25.0,45.0
863.07861,0.18016700590551182,920.2592848904268,0.00025370340306410486,25.0,45.0
864.58008,0.18067097047244093,921.4300909906447,0.00025370340306410486,25.0,45.0
866.08154,0.18122814566929132,922.6941945405613,0.00025370340306410486,25.0,45.0
867.58301,0.18173466732283464,921.5019095219787,0.00025370340306410486,25.0,45.0
869.08447,0.18223104133858267,921.1668332692554,0.00025370340306410486,25.0,45.0
870.58594,0.18276222637795275,922.7608868383955,0.00025370340306410486,25.0,45.0
872.0874,0.18329364566929132,922.6988850442139,0.00025370340306410486,25.0,45.0
873.58887,0.18383264566929133,921.0758938869666,0.00025370340306410486,25.0,45.0
875.09033,0.18434434251968504,922.6562091503267,0.00025370340306410486,25.0,45.0
876.5918,0.18499589763779525,925.6844546969114,0.00025370340306410486,25.0,45.0
878.09326,0.18572977362204723,923.7467640651032,0.00025370340306410486,25.0,45.0
879.59473,0.18628495472440945,923.1452261950532,0.00025370340306410486,25.0,45.0
881.09619,0.18689205314960627,922.5202101755734,0.00025370340306410486,25.0,45.0
882.59766,0.18745962401574803,921.8072279892349,0.00025370340306410486,25.0,45.0
884.09912,0.18794074212598424,921.832013328207,0.00025370340306410486,25.0,45.0
885.60059,0.18846736417322835,922.7278995258234,0.00025370340306410486,25.0,45.0
887.10205,0.18909413976377953,922.0921953094963,0.00025370340306410486,25.0,45.0
888.60352,0.189618062992126,923.2063565295399,0.00025370340306410486,25.0,45.0
890.10498,0.1902953031496063,923.5771369985904,0.00025370340306410486,25.0,45.0
891.60645,0.19089747440944882,923.8367550941945,0.00025370340306410486,25.0,45.0
893.10791,0.19143024212598425,922.7495066000256,0.00025370340306410486,25.0,45.0
894.60938,0.19200238976377954,922.1401255927208,0.00025370340306410486,25.0,45.0
896.11084,0.19256312992125985,922.1033961296938,0.00025370340306410486,25.0,45.0
897.6123,0.1930659212598425,923.1473023196207,0.00025370340306410486,25.0,45.0
899.11377,0.19367494488188977,922.2935793925413,0.00025370340306410486,25.0,45.0
900.61523,0.19429694488188975,924.167730360118,0.00025370340306410486,25.0,45.0
902.1167,0.19499997440944883,924.4164552095348,0.00025370340306410486,25.0,45.0
903.61816,0.19570078740157482,922.1320517749583,0.00025370340306410486,25.0,45.0
905.11963,0.1963346496062992,923.5546584646931,0.00025370340306410486,25.0,45.0
906.62109,0.19693200787401574,922.0502114571319,0.00025370340306410486,25.0,45.0
908.12256,0.19756257874015748,922.6369857747021,0.00025370340306410486,25.0,45.0
909.62402,0.19814749999999998,923.8615916955017,0.00025370340306410486,25.0,45.0
911.12549,0.19876667322834649,923.3401512238883,0.00025370340306410486,25.0,45.0
912.62695,0.1993534842519685,924.1796232218378,0.00025370340306410486,25.0,45.0
914.12842,0.19999415354330707,922.2313725490196,0.00025370340306410486,25.0,45.0
915.62988,0.2005605905511811,921.5761886453928,0.00025370340306410486,25.0,45.0
917.13135,0.20119578740157482,923.0367294630271,0.00025370340306410486,25.0,45.0
918.63281,0.20178464566929133,920.9867230552352,0.00025370340306410486,25.0,45.0
920.13428,0.20238470472440942,924.2508778674869,0.00025370340306410486,25.0,45.0
920.33447,0.20249531496062992,926.4108163526848,0.00025370340306410486,25.0,45.0