File: datasets/am_bench_2022/csv/45-XY.13-4.csv
Time(s),Strain(%),Stress(MPa),SR(s-1),Temp(C),Angle(deg)
32.004883,5.653636811023622e-05,19.545533595800528,0.00025370340306410486,25.0,45.0
33.40625,7.076640551181103e-05,24.145549868766405,0.00025370340306410486,25.0,45.0
34.807617,7.754938582677165e-05,29.962918635170602,0.00025370340306410486,25.0,45.0
36.208984,0.00011020267322834646,35.23286089238845,0.00025370340306410486,25.0,45.0
37.610352,0.00014499723031496063,39.46738320209974,0.00025370340306410486,25.0,45.0
39.011719,0.00012094230905511812,44.85130708661417,0.00025370340306410486,25.0,45.0
40.413086,0.0001829936220472441,49.92937795275591,0.00025370340306410486,25.0,45.0
41.814453,0.00018833449606299213,58.12542257217848,0.00025370340306410486,25.0,45.0
43.21582,0.000221372342519685,65.60053018372703,0.00025370340306410486,25.0,45.0
44.617188,0.0002614821653543307,72.7870341207349,0.00025370340306410486,25.0,45.0
46.018555,0.00028059007874015746,79.50409711286089,0.00025370340306410486,25.0,45.0
47.419922,0.00031833155511811026,87.40249606299213,0.00025370340306410486,25.0,45.0
48.821289,0.0003243490157480315,96.81705774278215,0.00025370340306410486,25.0,45.0
50.222656,0.0003797036811023622,104.19127296587926,0.00025370340306410486,25.0,45.0
51.624023,0.00038576407480314965,111.69942257217848,0.00025370340306410486,25.0,45.0
53.025391,0.00041856881889763776,120.03884251968503,0.00025370340306410486,25.0,45.0
54.426758,0.00044152206692913386,130.22845406824146,0.00025370340306410486,25.0,45.0
55.828125,0.0004982930118110236,139.53693963254594,0.00025370340306410486,25.0,45.0
57.229492,0.0005264887007874015,149.37250656167978,0.00025370340306410486,25.0,45.0
58.630859,0.0005441454330708662,156.74513648293964,0.00025370340306410486,25.0,45.0
60.032227,0.0005878615748031496,165.64802099737534,0.00025370340306410486,25.0,45.0
61.433594,0.0006368591929133858,174.81426771653543,0.00025370340306410486,25.0,45.0
62.834961,0.0006450045866141732,185.18753543307088,0.00025370340306410486,25.0,45.0
64.236328,0.0006876271653543307,195.4007375328084,0.00025370340306410486,25.0,45.0
65.637695,0.0007286007283464566,206.90384514435695,0.00025370340306410486,25.0,45.0
67.039063,0.0007696567125984252,215.1473727034121,0.00025370340306410486,25.0,45.0
68.44043,0.0008015910826771654,225.41058530183727,0.00025370340306410486,25.0,45.0
69.841797,0.0008366423622047243,234.75048556430446,0.00025370340306410486,25.0,45.0
71.243164,0.0008719186811023622,243.8835249343832,0.00025370340306410486,25.0,45.0
72.644531,0.0009152051968503936,253.68916797900263,0.00025370340306410486,25.0,45.0
74.045898,0.0009518092913385827,265.898687664042,0.00025370340306410486,25.0,45.0
75.447266,0.0009986472047244094,275.30207349081365,0.00025370340306410486,25.0,45.0
76.848633,0.001025670590551181,285.36979002624673,0.00025370340306410486,25.0,45.0
78.25,0.00105411718503937,296.04711286089236,0.00025370340306410486,25.0,45.0
79.651367,0.001088489311023622,305.07509186351706,0.00025370340306410486,25.0,45.0
81.052734,0.0011197315157480314,317.2007874015748,0.00025370340306410486,25.0,45.0
82.454102,0.0011921862992125985,325.5647244094488,0.00025370340306410486,25.0,45.0
83.855469,0.0012082393307086613,338.3602362204724,0.00025370340306410486,25.0,45.0
85.256836,0.0012490233858267717,348.9196587926509,0.00025370340306410486,25.0,45.0
86.658203,0.0013008440551181104,359.18036745406823,0.00025370340306410486,25.0,45.0
88.05957,0.0013359415354330707,370.8107086614173,0.00025370340306410486,25.0,45.0
89.460938,0.0013806426377952756,381.2877165354331,0.00025370340306410486,25.0,45.0
90.862305,0.0014025593307086615,391.89049868766404,0.00025370340306410486,25.0,45.0
92.263672,0.0014456295078740158,401.5913910761155,0.00025370340306410486,25.0,45.0
93.665039,0.0014813173228346455,410.8425459317585,0.00025370340306410486,25.0,45.0
95.066406,0.00152807218503937,420.34918635170607,0.00025370340306410486,25.0,45.0
96.467773,0.0015690383661417322,431.77335958005244,0.00025370340306410486,25.0,45.0
97.869141,0.001597336653543307,441.0093175853018,0.00025370340306410486,25.0,45.0
99.270508,0.001640552027559055,450.80527559055116,0.00025370340306410486,25.0,45.0
100.67188,0.001674893996062992,460.44674540682416,0.00025370340306410486,25.0,45.0
102.07324,0.001727357716535433,469.97133858267716,0.00025370340306410486,25.0,45.0
103.47461,0.001742103405511811,477.9655380577428,0.00025370340306410486,25.0,45.0
104.87598,0.001774549192913386,486.5751443569554,0.00025370340306410486,25.0,45.0
106.27734,0.001790868405511811,494.9523884514436,0.00025370340306410486,25.0,45.0
107.67871,0.001847726751968504,507.1711286089238,0.00025370340306410486,25.0,45.0
109.08008,0.001888845374015748,513.9098950131233,0.00025370340306410486,25.0,45.0
110.48145,0.0019156141141732281,522.1966141732283,0.00025370340306410486,25.0,45.0
111.88281,0.0019491787598425196,530.1922834645669,0.00025370340306410486,25.0,45.0
113.28418,0.0019571969488188976,537.0979265091863,0.00025370340306410486,25.0,45.0
114.68555,0.0019880978346456693,545.0265879265093,0.00025370340306410486,25.0,45.0
116.08691,0.002013638188976378,550.7898425196851,0.00025370340306410486,25.0,45.0
117.48828,0.002062371653543307,558.5441469816273,0.00025370340306410486,25.0,45.0
118.88965,0.002081097834645669,565.9203412073491,0.00025370340306410486,25.0,45.0
120.29102,0.0021151564960629923,570.1523622047243,0.00025370340306410486,25.0,45.0
121.69238,0.0021403066929133858,576.5794750656169,0.00025370340306410486,25.0,45.0
123.09375,0.0021588,583.2003149606298,0.00025370340306410486,25.0,45.0
124.49512,0.002184311811023622,589.4108923884514,0.00025370340306410486,25.0,45.0
125.89648,0.0022268641732283464,592.9733595800525,0.00025370340306410486,25.0,45.0
127.29785,0.0022612870078740155,598.6854855643045,0.00025370340306410486,25.0,45.0
128.69922,0.002251221062992126,604.2008136482939,0.00025370340306410486,25.0,45.0
130.10059,0.0022952937007874015,607.3438845144357,0.00025370340306410486,25.0,45.0
131.50195,0.0023356616141732285,614.6907349081365,0.00025370340306410486,25.0,45.0
132.90332,0.0023462923228346456,619.9155905511811,0.00025370340306410486,25.0,45.0
134.30469,0.002395754527559055,625.5520472440945,0.00025370340306410486,25.0,45.0
135.70605,0.002420752559055118,629.9047244094488,0.00025370340306410486,25.0,45.0
137.10742,0.002447366338582677,633.2182414698162,0.00025370340306410486,25.0,45.0
138.50879,0.0024916980314960632,638.756062992126,0.00025370340306410486,25.0,45.0
139.91016,0.0024984561023622047,642.7930446194225,0.00025370340306410486,25.0,45.0
141.31152,0.0025498437007874016,646.4266404199475,0.00025370340306410486,25.0,45.0
142.71289,0.0025579746062992124,649.7306036745406,0.00025370340306410486,25.0,45.0
144.11426,0.002587906889763779,653.4760367454068,0.00025370340306410486,25.0,45.0
145.51563,0.0026428541338582674,657.0629133858268,0.00025370340306410486,25.0,45.0
146.91699,0.002683587401574803,660.4067979002624,0.00025370340306410486,25.0,45.0
148.31836,0.0026903826771653544,662.8815223097113,0.00025370340306410486,25.0,45.0
149.71973,0.0027329931102362203,667.3687139107611,0.00025370340306410486,25.0,45.0
151.12109,0.0027533383858267717,672.3113648293963,0.00025370340306410486,25.0,45.0
152.52246,0.0028129462598425197,675.4543832020997,0.00025370340306410486,25.0,45.0
153.92383,0.002832779527559055,676.8188188976378,0.00025370340306410486,25.0,45.0
155.3252,0.002899026181102362,681.6371653543307,0.00025370340306410486,25.0,45.0
156.72656,0.002955986811023622,686.4052755905511,0.00025370340306410486,25.0,45.0
158.12793,0.0029896265748031495,688.6249081364829,0.00025370340306410486,25.0,45.0
159.5293,0.003040330118110236,690.9573753280839,0.00025370340306410486,25.0,45.0
160.93066,0.0030848102362204723,694.5121522309711,0.00025370340306410486,25.0,45.0
162.33203,0.003147959448818898,695.6063779527559,0.00025370340306410486,25.0,45.0
163.7334,0.0032248236220472444,701.2589501312336,0.00025370340306410486,25.0,45.0
165.13477,0.003293863582677165,704.531469816273,0.00025370340306410486,25.0,45.0
166.53613,0.003341043503937008,704.748188976378,0.00025370340306410486,25.0,45.0
167.9375,0.00344788188976378,710.3381627296587,0.00025370340306410486,25.0,45.0
169.33887,0.003505238582677165,710.8170341207349,0.00025370340306410486,25.0,45.0
170.74023,0.0035946990157480316,714.751154855643,0.00025370340306410486,25.0,45.0
172.1416,0.0036992397637795275,717.7469816272966,0.00025370340306410486,25.0,45.0
173.54297,0.0037978557086614175,719.6639632545931,0.00025370340306410486,25.0,45.0
174.94434,0.003868492125984252,719.9229133858267,0.00025370340306410486,25.0,45.0
176.3457,0.003969383070866142,723.4256430446194,0.00025370340306410486,25.0,45.0
177.74707,0.0040604722440944875,726.2961154855643,0.00025370340306410486,25.0,45.0
179.14844,0.004193691732283464,727.9444881889764,0.00025370340306410486,25.0,45.0
180.5498,0.0043252864173228345,729.6999212598425,0.00025370340306410486,25.0,45.0
181.95117,0.004449984645669291,731.9628083989501,0.00025370340306410486,25.0,45.0
183.35254,0.004555832480314961,732.0551443569553,0.00025370340306410486,25.0,45.0
184.75391,0.004699861023622047,735.1920734908136,0.00025370340306410486,25.0,45.0
186.15527,0.004860921850393701,737.4017585301838,0.00025370340306410486,25.0,45.0
187.55664,0.00501835,741.2060104986876,0.00025370340306410486,25.0,45.0
188.95801,0.005207350787401575,743.626062992126,0.00025370340306410486,25.0,45.0
190.35938,0.005355812007874015,743.3069028871391,0.00025370340306410486,25.0,45.0
191.76074,0.005573523031496063,745.8482677165355,0.00025370340306410486,25.0,45.0
193.16211,0.005746239763779528,748.680157480315,0.00025370340306410486,25.0,45.0
194.56348,0.0059151523622047245,748.5975590551182,0.00025370340306410486,25.0,45.0
195.96484,0.006107314960629921,751.0656430446195,0.00025370340306410486,25.0,45.0
197.36621,0.00631165,750.6334120734908,0.00025370340306410486,25.0,45.0
198.76758,0.006509077362204725,752.1751706036746,0.00025370340306410486,25.0,45.0
200.16895,0.006745650787401575,754.7496587926508,0.00025370340306410486,25.0,45.0
201.57031,0.006988467913385827,756.5848031496063,0.00025370340306410486,25.0,45.0
202.97168,0.00719859468503937,757.2873753280841,0.00025370340306410486,25.0,45.0
204.37305,0.007461580511811024,758.0437007874016,0.00025370340306410486,25.0,45.0
205.77441,0.007666169291338583,760.1621522309711,0.00025370340306410486,25.0,45.0
207.17578,0.007946387401574802,761.4807086614173,0.00025370340306410486,25.0,45.0
208.57715,0.008232263188976378,762.5594750656168,0.00025370340306410486,25.0,45.0
209.97852,0.008467325196850393,762.4214435695537,0.00025370340306410486,25.0,45.0
211.37988,0.008668091338582677,765.2571128608924,0.00025370340306410486,25.0,45.0
212.78125,0.008894595472440944,765.997874015748,0.00025370340306410486,25.0,45.0
214.18262,0.009164280905511812,766.1613385826772,0.00025370340306410486,25.0,45.0
215.58398,0.009403533267716535,768.6411286089239,0.00025370340306410486,25.0,45.0
216.98535,0.009656115157480315,768.5655905511811,0.00025370340306410486,25.0,45.0
218.38672,0.009934870275590552,771.5888188976378,0.00025370340306410486,25.0,45.0
219.78809,0.010249174803149606,771.3431496062992,0.00025370340306410486,25.0,45.0
221.18945,0.01050794094488189,771.7529921259843,0.00025370340306410486,25.0,45.0
222.59082,0.010765998818897638,773.6263517060368,0.00025370340306410486,25.0,45.0
223.99219,0.011029592322834646,774.0204199475065,0.00025370340306410486,25.0,45.0
225.39355,0.011342948031496063,776.8174803149606,0.00025370340306410486,25.0,45.0
226.79492,0.011668477559055118,776.8917322834645,0.00025370340306410486,25.0,45.0
228.19629,0.011952968700787402,776.1110761154856,0.00025370340306410486,25.0,45.0
229.59766,0.012185088779527559,778.1572440944882,0.00025370340306410486,25.0,45.0
230.99902,0.012427325,777.0186876640421,0.00025370340306410486,25.0,45.0
232.40039,0.012746548622047243,780.4834908136482,0.00025370340306410486,25.0,45.0
233.80176,0.013068379921259842,781.4558792650919,0.00025370340306410486,25.0,45.0
235.20313,0.01336476338582677,779.502624671916,0.00025370340306410486,25.0,45.0
236.60449,0.013642262401574803,782.4771653543306,0.00025370340306410486,25.0,45.0
238.00586,0.013982002952755904,785.6812598425197,0.00025370340306410486,25.0,45.0
239.40723,0.014246302165354332,784.3508398950131,0.00025370340306410486,25.0,45.0
240.80859,0.014569094094488188,785.507217847769,0.00025370340306410486,25.0,45.0
242.20996,0.014913981102362204,788.536404199475,0.00025370340306410486,25.0,45.0
243.61133,0.015263389960629922,787.5838057742783,0.00025370340306410486,25.0,45.0
245.0127,0.01560507244094488,786.1607611548557,0.00025370340306410486,25.0,45.0
246.41406,0.015897604527559055,788.9687401574803,0.00025370340306410486,25.0,45.0
247.81543,0.016150001771653544,789.8918635170603,0.00025370340306410486,25.0,45.0
249.2168,0.016444961023622046,789.1230446194226,0.00025370340306410486,25.0,45.0
250.61816,0.016793608661417322,790.2513648293963,0.00025370340306410486,25.0,45.0
252.01953,0.017087532677165354,790.3165879265092,0.00025370340306410486,25.0,45.0
253.4209,0.01734414488188976,791.3024934383202,0.00025370340306410486,25.0,45.0
254.82227,0.017600751377952757,792.4902099737533,0.00025370340306410486,25.0,45.0
256.22363,0.017895216535433068,793.6694488188976,0.00025370340306410486,25.0,45.0
257.625,0.018221326181102362,792.9156167979003,0.00025370340306410486,25.0,45.0
259.02637,0.018497892322834643,793.6830446194226,0.00025370340306410486,25.0,45.0
260.42773,0.018756324803149607,794.7191338582677,0.00025370340306410486,25.0,45.0
261.8291,0.019092099606299213,797.2931758530183,0.00025370340306410486,25.0,45.0
263.23047,0.019430897047244093,795.5894488188976,0.00025370340306410486,25.0,45.0
264.63184,0.019741358267716537,796.5308923884514,0.00025370340306410486,25.0,45.0
266.0332,0.02003000393700787,798.351312335958,0.00025370340306410486,25.0,45.0
267.43457,0.02034515748031496,801.0987664041994,0.00025370340306410486,25.0,45.0
268.83594,0.020649218503937007,799.7429921259842,0.00025370340306410486,25.0,45.0
270.2373,0.02097862992125984,799.2307349081365,0.00025370340306410486,25.0,45.0
271.63867,0.021288732283464566,799.016719160105,0.00025370340306410486,25.0,45.0
273.04004,0.021643515748031496,801.5804461942257,0.00025370340306410486,25.0,45.0
274.44141,0.021985405511811024,802.369186351706,0.00025370340306410486,25.0,45.0
275.84277,0.02234423031496063,803.551968503937,0.00025370340306410486,25.0,45.0
277.24414,0.022622574803149605,803.00343832021,0.00025370340306410486,25.0,45.0
278.64551,0.02290631496062992,803.8712073490814,0.00025370340306410486,25.0,45.0
280.04688,0.02323330118110236,806.0859580052494,0.00025370340306410486,25.0,45.0
281.44824,0.023480629921259842,805.4412073490814,0.00025370340306410486,25.0,45.0
282.84961,0.023778082677165354,805.9196062992125,0.00025370340306410486,25.0,45.0
284.25098,0.024135665354330708,807.5357480314962,0.00025370340306410486,25.0,45.0
285.65234,0.024468488188976376,806.6753018372702,0.00025370340306410486,25.0,45.0
287.05371,0.02482373228346457,807.8467191601051,0.00025370340306410486,25.0,45.0
288.45508,0.025115405511811024,808.9992388451443,0.00025370340306410486,25.0,45.0
289.85645,0.02541812992125984,808.7281889763779,0.00025370340306410486,25.0,45.0
291.25781,0.025722173228346457,810.3506561679791,0.00025370340306410486,25.0,45.0
292.65918,0.026036600393700787,810.4978477690288,0.00025370340306410486,25.0,45.0
294.06055,0.026336811023622047,810.3661154855644,0.00025370340306410486,25.0,45.0
295.46191,0.026592127952755906,810.3966666666666,0.00025370340306410486,25.0,45.0
296.86328,0.026890718503937008,811.7975065616798,0.00025370340306410486,25.0,45.0
298.26465,0.027241082677165355,812.8592913385827,0.00025370340306410486,25.0,45.0
299.66602,0.027548647637795277,812.410341207349,0.00025370340306410486,25.0,45.0
301.06738,0.027881080708661413,813.8091338582677,0.00025370340306410486,25.0,45.0
302.46875,0.028235476377952755,814.8597112860892,0.00025370340306410486,25.0,45.0
303.87012,0.02856642913385827,815.3442782152231,0.00025370340306410486,25.0,45.0
305.27148,0.028883903543307086,817.0794750656167,0.00025370340306410486,25.0,45.0
306.67285,0.029213620078740156,816.3183989501313,0.00025370340306410486,25.0,45.0
308.07422,0.029568218503937007,818.121312335958,0.00025370340306410486,25.0,45.0
309.47559,0.029886531496062994,818.2887664041995,0.00025370340306410486,25.0,45.0
310.87695,0.030204671259842518,819.1461942257218,0.00025370340306410486,25.0,45.0
312.27832,0.030535324803149605,818.6940682414698,0.00025370340306410486,25.0,45.0
313.67969,0.03087082086614173,819.6981627296589,0.00025370340306410486,25.0,45.0
315.08105,0.03117211811023622,819.8851706036745,0.00025370340306410486,25.0,45.0
316.48242,0.03145286023622047,821.1910236220472,0.00025370340306410486,25.0,45.0
317.88379,0.03177502755905511,819.9038057742782,0.00025370340306410486,25.0,45.0
319.28516,0.032076600393700784,821.7228871391076,0.00025370340306410486,25.0,45.0
320.68652,0.03241887204724409,821.132125984252,0.00025370340306410486,25.0,45.0
322.08789,0.032733269685039375,822.7412073490813,0.00025370340306410486,25.0,45.0
323.48926,0.033043307086614175,822.0066141732284,0.00025370340306410486,25.0,45.0
324.89063,0.033316462598425196,823.1240157480315,0.00025370340306410486,25.0,45.0
326.29199,0.033574238188976376,822.7908923884514,0.00025370340306410486,25.0,45.0
327.69336,0.03385781102362204,825.1193700787402,0.00025370340306410486,25.0,45.0
329.09473,0.03419950787401575,826.4802887139108,0.00025370340306410486,25.0,45.0
330.49609,0.034572988188976375,826.317847769029,0.00025370340306410486,25.0,45.0
331.89746,0.03489203346456693,826.4561942257218,0.00025370340306410486,25.0,45.0
333.29883,0.03517725984251968,827.6708661417323,0.00025370340306410486,25.0,45.0
334.7002,0.03548004527559055,826.7077690288714,0.00025370340306410486,25.0,45.0
336.10156,0.035838984251968506,826.4720734908136,0.00025370340306410486,25.0,45.0
337.50293,0.03614638385826772,828.421811023622,0.00025370340306410486,25.0,45.0
338.9043,0.03644417716535433,829.2054855643045,0.00025370340306410486,25.0,45.0
340.30566,0.036746041338582676,829.608031496063,0.00025370340306410486,25.0,45.0
341.70703,0.03708623228346457,829.4337532808399,0.00025370340306410486,25.0,45.0
343.1084,0.037447594488188976,831.1822572178478,0.00025370340306410486,25.0,45.0
344.50977,0.03781706692913386,831.0372703412073,0.00025370340306410486,25.0,45.0
345.91113,0.038119511811023625,831.0897375328084,0.00025370340306410486,25.0,45.0
347.3125,0.03840915748031496,832.5773228346457,0.00025370340306410486,25.0,45.0
348.71387,0.038735041338582674,832.7321522309711,0.00025370340306410486,25.0,45.0
350.11523,0.039009061023622046,832.0410498687663,0.00025370340306410486,25.0,45.0
351.5166,0.03934997834645669,832.7715485564304,0.00025370340306410486,25.0,45.0
352.91797,0.03963810039370079,832.3848293963255,0.00025370340306410486,25.0,45.0
354.31934,0.039949732283464566,834.0633333333334,0.00025370340306410486,25.0,45.0
355.7207,0.04029509448818898,836.590839895013,0.00025370340306410486,25.0,45.0
357.12207,0.0406490216535433,835.4568503937007,0.00025370340306410486,25.0,45.0
358.52344,0.04094043897637795,834.8764304461941,0.00025370340306410486,25.0,45.0
359.9248,0.04125279724409449,835.6753543307086,0.00025370340306410486,25.0,45.0
361.32617,0.04164805118110236,838.6087664041995,0.00025370340306410486,25.0,45.0
362.72754,0.04192306692913386,835.7070078740157,0.00025370340306410486,25.0,45.0
364.12891,0.042236586614173226,838.2554855643044,0.00025370340306410486,25.0,45.0
365.53027,0.04254014960629921,837.6568766404199,0.00025370340306410486,25.0,45.0
366.93164,0.04285769881889764,840.1972703412074,0.00025370340306410486,25.0,45.0
368.33301,0.04317944881889764,838.4545144356955,0.00025370340306410486,25.0,45.0
369.73438,0.04362857086614173,843.2979265091864,0.00025370340306410486,25.0,45.0
371.13574,0.04393925590551181,840.4246981627296,0.00025370340306410486,25.0,45.0
372.53711,0.0442135748031496,839.7627559055118,0.00025370340306410486,25.0,45.0
373.93848,0.044528468503937005,842.2274278215223,0.00025370340306410486,25.0,45.0
375.33984,0.044831566929133856,841.6524409448818,0.00025370340306410486,25.0,45.0
376.74121,0.04507751181102362,842.4238320209973,0.00025370340306410486,25.0,45.0
378.14258,0.045394043307086615,842.9972703412072,0.00025370340306410486,25.0,45.0
379.54395,0.04582051377952756,845.4136745406825,0.00025370340306410486,25.0,45.0
380.94531,0.04618870669291338,844.9828871391076,0.00025370340306410486,25.0,45.0
382.34668,0.04652062401574803,845.4899475065616,0.00025370340306410486,25.0,45.0
383.74805,0.04684924803149606,843.2181364829396,0.00025370340306410486,25.0,45.0
385.14941,0.04712713779527559,845.6360892388452,0.00025370340306410486,25.0,45.0
386.55078,0.047453812992125984,844.2768503937008,0.00025370340306410486,25.0,45.0
387.95215,0.04775004330708661,846.9936220472441,0.00025370340306410486,25.0,45.0
389.35352,0.048106696850393704,848.479343832021,0.00025370340306410486,25.0,45.0
390.75488,0.04847896653543307,847.6907349081365,0.00025370340306410486,25.0,45.0
392.15625,0.04884661023622047,848.7053543307086,0.00025370340306410486,25.0,45.0
393.55762,0.04914054527559055,847.2574278215222,0.00025370340306410486,25.0,45.0
394.95898,0.049431557086614175,848.2887664041995,0.00025370340306410486,25.0,45.0
396.36035,0.04976030905511811,847.8175328083989,0.00025370340306410486,25.0,45.0
397.76172,0.050012210629921255,848.8338845144357,0.00025370340306410486,25.0,45.0
399.16309,0.050300159448818896,847.7617847769029,0.00025370340306410486,25.0,45.0
400.56445,0.05064423031496063,849.8135958005249,0.00025370340306410486,25.0,45.0
401.96582,0.05092904133858267,849.7643832020997,0.00025370340306410486,25.0,45.0
403.36719,0.051227687007874015,850.2389501312337,0.00025370340306410486,25.0,45.0
404.76855,0.05154576181102362,851.1675853018372,0.00025370340306410486,25.0,45.0
406.16992,0.05190963188976378,853.1507086614173,0.00025370340306410486,25.0,45.0
407.57129,0.05225571456692913,853.2812860892387,0.00025370340306410486,25.0,45.0
408.97266,0.05256827559055118,853.848188976378,0.00025370340306410486,25.0,45.0
410.37402,0.052914832677165353,854.2361942257218,0.00025370340306410486,25.0,45.0
411.77539,0.053199862204724405,852.1493963254593,0.00025370340306410486,25.0,45.0
413.17676,0.05351978543307087,853.780656167979,0.00025370340306410486,25.0,45.0
414.57813,0.05387923818897638,854.6550131233596,0.00025370340306410486,25.0,45.0
415.97949,0.05419598031496063,854.4869291338583,0.00025370340306410486,25.0,45.0
417.38086,0.05447864566929133,853.9871128608924,0.00025370340306410486,25.0,45.0
418.78223,0.054786499999999995,857.7287401574803,0.00025370340306410486,25.0,45.0
420.18359,0.055153637795275594,857.0652755905512,0.00025370340306410486,25.0,45.0
421.58496,0.05542523228346456,855.1112598425196,0.00025370340306410486,25.0,45.0
422.98633,0.05577111614173228,856.5384251968504,0.00025370340306410486,25.0,45.0
424.3877,0.05609509251968504,858.7061417322834,0.00025370340306410486,25.0,45.0
425.78906,0.05642121653543307,857.1661417322834,0.00025370340306410486,25.0,45.0
427.19043,0.05669524606299213,857.8301312335958,0.00025370340306410486,25.0,45.0
428.5918,0.05708206496062992,860.9688976377952,0.00025370340306410486,25.0,45.0
429.99316,0.05744123622047244,860.3916797900262,0.00025370340306410486,25.0,45.0
431.39453,0.057755503937007874,858.9020997375328,0.00025370340306410486,25.0,45.0
432.7959,0.058108320866141726,861.3663779527559,0.00025370340306410486,25.0,45.0
434.19727,0.05836753149606299,859.6587401574802,0.00025370340306410486,25.0,45.0
435.59863,0.05868285039370079,861.8496587926509,0.00025370340306410486,25.0,45.0
437.0,0.059011637795275594,862.3238582677166,0.00025370340306410486,25.0,45.0
438.40137,0.05936689566929134,862.795406824147,0.00025370340306410486,25.0,45.0
439.80273,0.05967390551181102,863.424278215223,0.00025370340306410486,25.0,45.0
441.2041,0.05996681889763779,863.5351181102362,0.00025370340306410486,25.0,45.0
442.60547,0.060279421259842515,862.5232020997375,0.00025370340306410486,25.0,45.0
444.00684,0.0606178248031496,862.6516797900263,0.00025370340306410486,25.0,45.0
445.4082,0.06091760039370078,865.1454855643044,0.00025370340306410486,25.0,45.0
446.80957,0.0612369094488189,862.6908398950131,0.00025370340306410486,25.0,45.0
448.21094,0.06156602559055118,864.6759842519685,0.00025370340306410486,25.0,45.0
449.6123,0.061917251968503936,865.4225721784777,0.00025370340306410486,25.0,45.0
451.01367,0.062231045275590556,865.077375328084,0.00025370340306410486,25.0,45.0
452.41504,0.0625415059055118,866.5932283464567,0.00025370340306410486,25.0,45.0
453.81641,0.06285776771653544,866.7962467191601,0.00025370340306410486,25.0,45.0
455.21777,0.06318524803149606,865.1451706036746,0.00025370340306410486,25.0,45.0
456.61914,0.06350799803149607,869.1353805774278,0.00025370340306410486,25.0,45.0
458.02051,0.06384958661417323,868.1599737532808,0.00025370340306410486,25.0,45.0
459.42188,0.06417210236220473,867.324251968504,0.00025370340306410486,25.0,45.0
460.82324,0.0645408188976378,869.2291076115486,0.00025370340306410486,25.0,45.0
462.22461,0.06488015354330708,870.4869816272966,0.00025370340306410486,25.0,45.0
463.62598,0.06518434842519685,869.8083202099738,0.00025370340306410486,25.0,45.0
465.02734,0.06549567716535433,868.9682414698162,0.00025370340306410486,25.0,45.0
466.42871,0.06579788976377952,869.8140419947507,0.00025370340306410486,25.0,45.0
467.83008,0.06610379724409449,868.7194225721785,0.00025370340306410486,25.0,45.0
469.23145,0.06634214566929134,869.6838845144357,0.00025370340306410486,25.0,45.0
470.63281,0.06659473228346456,871.5345406824147,0.00025370340306410486,25.0,45.0
472.03418,0.06692082677165354,872.035249343832,0.00025370340306410486,25.0,45.0
473.43555,0.0672941653543307,871.7240419947506,0.00025370340306410486,25.0,45.0
474.83691,0.06761913976377952,871.2936220472442,0.00025370340306410486,25.0,45.0
476.23828,0.06792848622047244,872.2169291338582,0.00025370340306410486,25.0,45.0
477.63965,0.06823427755905512,872.9696062992126,0.00025370340306410486,25.0,45.0
479.04102,0.06857548425196851,875.842309711286,0.00025370340306410486,25.0,45.0
480.44238,0.06894419488188977,874.1430183727034,0.00025370340306410486,25.0,45.0
481.84375,0.06924627165354331,874.2788451443569,0.00025370340306410486,25.0,45.0
483.24512,0.06956134842519685,873.9890813648294,0.00025370340306410486,25.0,45.0
484.64648,0.06987411417322835,875.3451968503937,0.00025370340306410486,25.0,45.0
486.04785,0.07020174606299212,874.8322309711285,0.00025370340306410486,25.0,45.0
487.44922,0.07055083858267718,877.0403937007874,0.00025370340306410486,25.0,45.0
488.85059,0.07085061023622047,875.8094488188976,0.00025370340306410486,25.0,45.0
490.25195,0.07118440157480314,874.0272178477691,0.00025370340306410486,25.0,45.0
491.65332,0.07152575,878.2000262467192,0.00025370340306410486,25.0,45.0
493.05469,0.07190120669291339,878.7534120734907,0.00025370340306410486,25.0,45.0
494.45605,0.07224473031496063,878.2867979002624,0.00025370340306410486,25.0,45.0
495.85742,0.07255743897637795,876.9426771653543,0.00025370340306410486,25.0,45.0
497.25879,0.07284325787401574,877.8662467191601,0.00025370340306410486,25.0,45.0
498.66016,0.07318342716535432,879.334094488189,0.00025370340306410486,25.0,45.0
500.06152,0.07354882874015747,878.8736220472441,0.00025370340306410486,25.0,45.0
501.46289,0.07389459448818897,879.3464829396326,0.00025370340306410486,25.0,45.0
502.86426,0.07418767716535433,880.1173490813649,0.00025370340306410486,25.0,45.0
504.26563,0.07448729724409449,879.8453805774278,0.00025370340306410486,25.0,45.0
505.66699,0.07483055118110236,879.559842519685,0.00025370340306410486,25.0,45.0
507.06836,0.07515046259842519,880.4080577427821,0.00025370340306410486,25.0,45.0
508.46973,0.07553626181102362,882.8255118110236,0.00025370340306410486,25.0,45.0
509.87109,0.07586316732283464,881.1390026246719,0.00025370340306410486,25.0,45.0
511.27246,0.07611659842519686,881.3456167979003,0.00025370340306410486,25.0,45.0
512.67383,0.07640902952755906,881.4615223097112,0.00025370340306410486,25.0,45.0
514.0752,0.07669248622047244,880.5164304461942,0.00025370340306410486,25.0,45.0
515.47656,0.07701179330708662,881.5512335958005,0.00025370340306410486,25.0,45.0
516.87793,0.07736435826771652,885.4223097112861,0.00025370340306410486,25.0,45.0
518.2793,0.07773406102362204,885.1848293963254,0.00025370340306410486,25.0,45.0
519.68066,0.07809578937007873,882.954750656168,0.00025370340306410486,25.0,45.0
521.08203,0.07848561811023622,884.8585301837271,0.00025370340306410486,25.0,45.0
522.4834,0.07885259842519685,885.0027821522309,0.00025370340306410486,25.0,45.0
523.88477,0.07921211417322835,885.6636220472441,0.00025370340306410486,25.0,45.0
525.28613,0.07956161811023622,886.9041994750656,0.00025370340306410486,25.0,45.0
526.6875,0.07986381102362204,884.3169553805775,0.00025370340306410486,25.0,45.0
528.08887,0.08016658661417324,885.2833858267717,0.00025370340306410486,25.0,45.0
529.49023,0.08047457677165354,887.4735433070865,0.00025370340306410486,25.0,45.0
530.8916,0.08080260236220471,887.5801049868766,0.00025370340306410486,25.0,45.0
532.29297,0.08118194291338583,888.7848556430447,0.00025370340306410486,25.0,45.0
533.69434,0.08155836811023623,889.9303937007874,0.00025370340306410486,25.0,45.0
535.0957,0.08185790944881889,886.8019947506561,0.00025370340306410486,25.0,45.0
536.49707,0.08216868700787403,886.9389238845143,0.00025370340306410486,25.0,45.0
537.89844,0.08246236220472442,888.4547769028871,0.00025370340306410486,25.0,45.0
539.2998,0.08280658661417323,888.2155643044619,0.00025370340306410486,25.0,45.0
540.70117,0.08312283661417323,887.0301049868766,0.00025370340306410486,25.0,45.0
542.10254,0.08340078346456693,887.2091338582677,0.00025370340306410486,25.0,45.0
543.50391,0.0837583248031496,889.9036745406823,0.00025370340306410486,25.0,45.0
544.90527,0.084087781496063,891.3696587926509,0.00025370340306410486,25.0,45.0
546.30664,0.08445146259842519,891.0351181102362,0.00025370340306410486,25.0,45.0
547.70801,0.08476922637795276,890.8665091863517,0.00025370340306410486,25.0,45.0
549.10938,0.08511147834645669,892.5457742782153,0.00025370340306410486,25.0,45.0
550.51074,0.08542587007874015,892.9796325459317,0.00025370340306410486,25.0,45.0
551.91211,0.08580651181102363,891.6877427821522,0.00025370340306410486,25.0,45.0
553.31348,0.08614891535433071,892.4471391076115,0.00025370340306410486,25.0,45.0
554.71484,0.08648706102362204,893.6909711286089,0.00025370340306410486,25.0,45.0
556.11621,0.0868517283464567,893.2189763779527,0.00025370340306410486,25.0,45.0
557.51758,0.08718237007874015,891.927532808399,0.00025370340306410486,25.0,45.0
558.91895,0.08753696456692912,893.3189501312336,0.00025370340306410486,25.0,45.0
560.32031,0.08784625787401575,893.2334645669291,0.00025370340306410486,25.0,45.0
561.72168,0.08823803543307086,893.1224146981627,0.00025370340306410486,25.0,45.0
563.12305,0.08857775787401574,895.5815748031497,0.00025370340306410486,25.0,45.0
564.52441,0.0889172342519685,894.9953018372703,0.00025370340306410486,25.0,45.0
565.92578,0.08929004527559055,896.1258005249344,0.00025370340306410486,25.0,45.0
567.32715,0.08965022047244095,895.7690026246719,0.00025370340306410486,25.0,45.0
568.72852,0.089955218503937,894.7918635170604,0.00025370340306410486,25.0,45.0
570.12988,0.09028170669291338,895.7258792650919,0.00025370340306410486,25.0,45.0
571.53125,0.09058762007874016,896.1406036745407,0.00025370340306410486,25.0,45.0
572.93262,0.09093437795275591,897.0869816272966,0.00025370340306410486,25.0,45.0
574.33398,0.09122730905511811,894.79,0.00025370340306410486,25.0,45.0
575.73535,0.09153794488188977,896.7291601049869,0.00025370340306410486,25.0,45.0
577.13672,0.09185563188976378,896.0232545931758,0.00025370340306410486,25.0,45.0
578.53809,0.09215668897637795,896.1430183727034,0.00025370340306410486,25.0,45.0
579.93945,0.0924471437007874,897.8567454068241,0.00025370340306410486,25.0,45.0
581.34082,0.092801,899.5051181102363,0.00025370340306410486,25.0,45.0
582.74219,0.09316753937007874,899.017874015748,0.00025370340306410486,25.0,45.0
584.14355,0.09352526771653544,900.5906824146982,0.00025370340306410486,25.0,45.0
585.54492,0.09390350984251968,897.3416797900262,0.00025370340306410486,25.0,45.0
586.94629,0.09421101377952755,899.1129658792651,0.00025370340306410486,25.0,45.0
588.34766,0.0946238405511811,901.3087401574803,0.00025370340306410486,25.0,45.0
589.74902,0.0949674468503937,899.645249343832,0.00025370340306410486,25.0,45.0
591.15039,0.09528766338582677,899.214593175853,0.00025370340306410486,25.0,45.0
592.55176,0.0956584625984252,901.8871128608923,0.00025370340306410486,25.0,45.0
593.95313,0.09604749409448819,899.837375328084,0.00025370340306410486,25.0,45.0
595.35449,0.09640897047244094,900.5822309711286,0.00025370340306410486,25.0,45.0
596.75586,0.09679267519685039,900.1000787401574,0.00025370340306410486,25.0,45.0
598.15723,0.09712775196850394,900.6062467191601,0.00025370340306410486,25.0,45.0
599.55859,0.09748948031496063,901.7475065616798,0.00025370340306410486,25.0,45.0
600.95996,0.09781457874015748,902.8843832020998,0.00025370340306410486,25.0,45.0
602.36133,0.09815037007874015,902.1753543307087,0.00025370340306410486,25.0,45.0
603.7627,0.0985137716535433,904.7303674540682,0.00025370340306410486,25.0,45.0
605.16406,0.09888776574803149,905.4060892388452,0.00025370340306410486,25.0,45.0
606.56543,0.09920823622047244,900.615091863517,0.00025370340306410486,25.0,45.0
607.9668,0.0995080531496063,906.1495275590552,0.00025370340306410486,25.0,45.0
609.36816,0.09990601968503936,903.0907086614172,0.00025370340306410486,25.0,45.0
610.76953,0.10028872244094487,904.5050656167979,0.00025370340306410486,25.0,45.0
612.1709,0.10061212401574803,904.5208398950132,0.00025370340306410486,25.0,45.0
613.57227,0.10090809448818898,904.3550656167979,0.00025370340306410486,25.0,45.0
614.97363,0.10124992913385827,904.0801049868767,0.00025370340306410486,25.0,45.0
616.375,0.10158663582677165,905.832965879265,0.00025370340306410486,25.0,45.0
617.77637,0.10191206889763779,905.1476377952756,0.00025370340306410486,25.0,45.0
619.17773,0.10228904527559055,905.0856167979003,0.00025370340306410486,25.0,45.0
620.5791,0.10264601574803149,906.2751706036745,0.00025370340306410486,25.0,45.0
621.98047,0.10300999015748032,906.5229133858268,0.00025370340306410486,25.0,45.0
623.38184,0.10333868503937009,905.3009186351705,0.00025370340306410486,25.0,45.0
624.7832,0.10372569291338582,905.7738845144357,0.00025370340306410486,25.0,45.0
626.18457,0.10412871653543307,906.4487664041995,0.00025370340306410486,25.0,45.0
627.58594,0.10443081102362205,904.7381102362205,0.00025370340306410486,25.0,45.0
628.9873,0.10477072047244095,906.455748031496,0.00025370340306410486,25.0,45.0
630.38867,0.105181781496063,907.7733595800526,0.00025370340306410486,25.0,45.0
631.79004,0.1055465905511811,906.6007086614173,0.00025370340306410486,25.0,45.0
633.19141,0.10595069488188975,907.9834645669291,0.00025370340306410486,25.0,45.0
634.59277,0.10628511417322835,908.10968503937,0.00025370340306410486,25.0,45.0
635.99414,0.10669530708661416,910.0425196850395,0.00025370340306410486,25.0,45.0
637.39551,0.10704003937007874,910.046220472441,0.00025370340306410486,25.0,45.0
638.79688,0.10739252755905511,909.1693175853019,0.00025370340306410486,25.0,45.0
640.19824,0.10772610236220471,908.5991863517061,0.00025370340306410486,25.0,45.0
641.59961,0.10807015551181103,907.9284251968504,0.00025370340306410486,25.0,45.0
643.00098,0.10840606496062992,909.9304461942257,0.00025370340306410486,25.0,45.0
644.40234,0.10874096653543307,907.4008661417322,0.00025370340306410486,25.0,45.0
645.80371,0.10909276181102363,910.3569553805775,0.00025370340306410486,25.0,45.0
647.20508,0.10944828937007874,910.1722047244094,0.00025370340306410486,25.0,45.0
648.60645,0.10980320669291338,912.7234383202099,0.00025370340306410486,25.0,45.0
650.00781,0.11019651574803149,912.03312335958,0.00025370340306410486,25.0,45.0
651.40918,0.11052431692913386,911.1764566929133,0.00025370340306410486,25.0,45.0
652.81055,0.1109115964566929,911.7246456692914,0.00025370340306410486,25.0,45.0
654.21191,0.11124166141732283,911.9934645669291,0.00025370340306410486,25.0,45.0
655.61328,0.11162781299212597,911.6758267716535,0.00025370340306410486,25.0,45.0
657.01465,0.11204817913385827,910.6833595800524,0.00025370340306410486,25.0,45.0
658.41602,0.11244175787401575,912.2666141732283,0.00025370340306410486,25.0,45.0
659.81738,0.11281200984251968,911.314593175853,0.00025370340306410486,25.0,45.0
661.21875,0.11313409842519685,912.5330708661418,0.00025370340306410486,25.0,45.0
662.62012,0.1134870905511811,912.5485826771654,0.00025370340306410486,25.0,45.0
664.02148,0.11383655314960629,912.766062992126,0.00025370340306410486,25.0,45.0
665.42285,0.11424259251968502,914.0755118110236,0.00025370340306410486,25.0,45.0
666.82422,0.11466657086614172,914.2417322834646,0.00025370340306410486,25.0,45.0
668.22559,0.11502883267716535,912.9813648293963,0.00025370340306410486,25.0,45.0
669.62695,0.11537381299212598,913.6109973753281,0.00025370340306410486,25.0,45.0
671.02832,0.1156878405511811,913.4399212598424,0.00025370340306410486,25.0,45.0
672.42969,0.11606867716535434,915.9069553805774,0.00025370340306410486,25.0,45.0
673.83105,0.11645218700787402,915.2522572178477,0.00025370340306410486,25.0,45.0
675.23242,0.11687866535433071,915.4124409448818,0.00025370340306410486,25.0,45.0
676.63379,0.11727534251968502,914.8907874015748,0.00025370340306410486,25.0,45.0
678.03516,0.11762966141732284,916.0149081364829,0.00025370340306410486,25.0,45.0
679.43652,0.11797879330708662,915.8899737532809,0.00025370340306410486,25.0,45.0
680.83789,0.11832857283464567,916.3793963254593,0.00025370340306410486,25.0,45.0
682.23926,0.1186801692913386,917.1876377952756,0.00025370340306410486,25.0,45.0
683.64063,0.11907578937007873,917.0740157480316,0.00025370340306410486,25.0,45.0
685.04199,0.11946886220472441,917.7045406824146,0.00025370340306410486,25.0,45.0
686.44336,0.1198700688976378,916.8328871391076,0.00025370340306410486,25.0,45.0
687.84473,0.12021814566929134,917.3483989501312,0.00025370340306410486,25.0,45.0
689.24609,0.12057279330708662,916.9809186351705,0.00025370340306410486,25.0,45.0
690.64746,0.12095772440944882,918.3599475065616,0.00025370340306410486,25.0,45.0
692.04883,0.1213234940944882,915.5340157480315,0.00025370340306410486,25.0,45.0
693.4502,0.1216828346456693,917.3725721784776,0.00025370340306410486,25.0,45.0
694.85156,0.12211182480314961,917.9682414698162,0.00025370340306410486,25.0,45.0
696.25293,0.1224697224409449,915.8909973753281,0.00025370340306410486,25.0,45.0
697.6543,0.12279324212598425,917.5999212598425,0.00025370340306410486,25.0,45.0
699.05566,0.1232165748031496,920.763937007874,0.00025370340306410486,25.0,45.0
700.45703,0.12368413188976378,919.3853543307087,0.00025370340306410486,25.0,45.0
701.8584,0.12403130511811024,918.475091863517,0.00025370340306410486,25.0,45.0
703.25977,0.12448211811023621,919.6156430446194,0.00025370340306410486,25.0,45.0
704.66113,0.1248252559055118,919.0006824146982,0.00025370340306410486,25.0,45.0
706.0625,0.12523406299212597,919.2325721784777,0.00025370340306410486,25.0,45.0
707.46387,0.1256612933070866,921.4183202099737,0.00025370340306410486,25.0,45.0
708.86523,0.12600121456692914,917.1673228346456,0.00025370340306410486,25.0,45.0
710.2666,0.12635964173228348,919.238530183727,0.00025370340306410486,25.0,45.0
711.66797,0.1267183720472441,920.1645406824147,0.00025370340306410486,25.0,45.0
713.06934,0.12711279527559055,919.5873753280839,0.00025370340306410486,25.0,45.0
714.4707,0.12747810826771655,919.9488451443569,0.00025370340306410486,25.0,45.0
715.87207,0.12788862992125982,920.4002362204725,0.00025370340306410486,25.0,45.0
717.27344,0.12827739763779528,921.3529396325459,0.00025370340306410486,25.0,45.0
718.6748,0.12865174409448818,920.9891076115485,0.00025370340306410486,25.0,45.0
720.07617,0.12905124803149606,921.91312335958,0.00025370340306410486,25.0,45.0
721.47754,0.1294563720472441,922.1386089238846,0.00025370340306410486,25.0,45.0
722.87891,0.12985886811023623,924.2089501312336,0.00025370340306410486,25.0,45.0
724.28027,0.1302922913385827,921.6207874015748,0.00025370340306410486,25.0,45.0
725.68164,0.13065657283464568,922.5792913385826,0.00025370340306410486,25.0,45.0
727.08301,0.1310239625984252,920.7949606299212,0.00025370340306410486,25.0,45.0
728.48438,0.13138362007874016,921.0618372703412,0.00025370340306410486,25.0,45.0
729.88574,0.1317672598425197,922.2301312335958,0.00025370340306410486,25.0,45.0
731.28711,0.1321460905511811,922.50375328084,0.00025370340306410486,25.0,45.0
732.68848,0.13255594291338582,920.7458005249343,0.00025370340306410486,25.0,45.0
734.08984,0.13296642913385825,921.9205511811024,0.00025370340306410486,25.0,45.0
735.49121,0.13337746653543306,923.2848556430446,0.00025370340306410486,25.0,45.0
736.89258,0.13380453149606297,922.9541469816273,0.00025370340306410486,25.0,45.0
738.29395,0.13427387007874014,924.8709448818897,0.00025370340306410486,25.0,45.0
739.69531,0.13469012992125984,924.5470866141732,0.00025370340306410486,25.0,45.0
741.09668,0.13510280905511812,922.607217847769,0.00025370340306410486,25.0,45.0
742.49805,0.1355086968503937,922.2661417322834,0.00025370340306410486,25.0,45.0
743.89941,0.13592022637795276,924.2493175853018,0.00025370340306410486,25.0,45.0
745.30078,0.13631746456692911,923.4670341207349,0.00025370340306410486,25.0,45.0
746.70215,0.13665430118110236,923.6175065616798,0.00025370340306410486,25.0,45.0
748.10352,0.13707721259842517,925.041653543307,0.00025370340306410486,25.0,45.0
749.50488,0.13748185629921258,925.7389501312335,0.00025370340306410486,25.0,45.0
750.90625,0.13784289763779525,924.4756955380577,0.00025370340306410486,25.0,45.0
752.30762,0.13827676771653544,924.8619160104987,0.00025370340306410486,25.0,45.0
753.70898,0.1386747933070866,925.1590551181102,0.00025370340306410486,25.0,45.0
755.11035,0.13904018897637796,922.6415223097113,0.00025370340306410486,25.0,45.0
756.51172,0.13935603543307087,924.5180052493438,0.00025370340306410486,25.0,45.0
757.91309,0.13969134645669293,923.6738320209973,0.00025370340306410486,25.0,45.0
759.31445,0.1400981003937008,926.1342519685039,0.00025370340306410486,25.0,45.0
760.71582,0.14057728543307085,925.5160892388451,0.00025370340306410486,25.0,45.0
762.11719,0.14101611811023623,926.8005511811023,0.00025370340306410486,25.0,45.0
763.51855,0.14151850984251968,928.5857217847769,0.00025370340306410486,25.0,45.0
764.91992,0.14195987795275591,926.5531496062993,0.00025370340306410486,25.0,45.0
766.32129,0.14231757677165355,925.7772703412073,0.00025370340306410486,25.0,45.0
767.72266,0.14272959842519686,925.8245669291339,0.00025370340306410486,25.0,45.0
769.12402,0.14316860826771655,925.3180839895012,0.00025370340306410486,25.0,45.0
770.52539,0.14361845866141731,927.7139895013123,0.00025370340306410486,25.0,45.0
771.92676,0.14397899606299214,927.3187664041994,0.00025370340306410486,25.0,45.0
773.32813,0.14436697834645668,926.3383464566929,0.00025370340306410486,25.0,45.0
774.72949,0.14477769881889763,927.8768241469817,0.00025370340306410486,25.0,45.0
776.13086,0.14524598228346458,926.8214435695538,0.00025370340306410486,25.0,45.0
777.53223,0.14568468700787401,927.7564829396325,0.00025370340306410486,25.0,45.0
778.93359,0.14608035433070865,927.1223622047245,0.00025370340306410486,25.0,45.0
780.33496,0.14652989960629922,928.6866404199475,0.00025370340306410486,25.0,45.0
781.73633,0.14697116141732283,927.12343832021,0.00025370340306410486,25.0,45.0
783.1377,0.14739644291338583,929.5495275590552,0.00025370340306410486,25.0,45.0
784.53906,0.1478553996062992,929.195748031496,0.00025370340306410486,25.0,45.0
785.94043,0.14825786023622045,927.5355380577428,0.00025370340306410486,25.0,45.0
787.3418,0.14870424999999998,927.3628346456693,0.00025370340306410486,25.0,45.0
788.74316,0.14908643503937008,929.2692650918634,0.00025370340306410486,25.0,45.0
790.14453,0.14948557480314958,927.0592388451443,0.00025370340306410486,25.0,45.0
791.5459,0.14987553937007872,929.7214698162729,0.00025370340306410486,25.0,45.0
792.94727,0.1503220334645669,928.6875590551181,0.00025370340306410486,25.0,45.0
794.34863,0.15078393503937007,927.864908136483,0.00025370340306410486,25.0,45.0
795.75,0.15117213976377952,928.8117847769029,0.00025370340306410486,25.0,45.0
797.15137,0.1515750216535433,926.6652755905512,0.00025370340306410486,25.0,45.0
798.55273,0.1520020748031496,929.4304724409449,0.00025370340306410486,25.0,45.0
799.9541,0.15244964960629923,928.9757742782152,0.00025370340306410486,25.0,45.0
801.35547,0.1529678346456693,931.3764829396326,0.00025370340306410486,25.0,45.0
802.75684,0.15341563188976376,928.7597637795276,0.00025370340306410486,25.0,45.0
804.1582,0.15384740157480314,929.2887401574802,0.00025370340306410486,25.0,45.0
805.55957,0.1542670748031496,928.35343832021,0.00025370340306410486,25.0,45.0
806.96094,0.15469146456692912,929.9087664041995,0.00025370340306410486,25.0,45.0
808.3623,0.15520412401574804,931.0692388451444,0.00025370340306410486,25.0,45.0
809.76367,0.15570616338582677,928.750997375328,0.00025370340306410486,25.0,45.0
811.16504,0.15610106889763778,928.9293700787401,0.00025370340306410486,25.0,45.0
812.56641,0.15653065551181103,928.4055380577428,0.00025370340306410486,25.0,45.0
813.96777,0.15696768307086614,930.1761679790026,0.00025370340306410486,25.0,45.0
815.36914,0.15735946456692912,929.122125984252,0.00025370340306410486,25.0,45.0
816.77051,0.15782112007874016,930.8965354330709,0.00025370340306410486,25.0,45.0
818.17188,0.1582892283464567,930.8766666666667,0.00025370340306410486,25.0,45.0
819.57324,0.15876957283464566,931.3216272965878,0.00025370340306410486,25.0,45.0
820.97461,0.15917351181102363,927.52656167979,0.00025370340306410486,25.0,45.0
822.37598,0.15957874015748033,929.4971916010498,0.00025370340306410486,25.0,45.0
823.77734,0.16001817322834647,930.0175065616797,0.00025370340306410486,25.0,45.0
825.17871,0.1604963248031496,931.9464829396326,0.00025370340306410486,25.0,45.0
826.58008,0.16090741929133856,929.7148031496063,0.00025370340306410486,25.0,45.0
827.98145,0.16133958858267716,930.7947244094489,0.00025370340306410486,25.0,45.0
829.38281,0.1618262342519685,931.6986876640419,0.00025370340306410486,25.0,45.0
830.78418,0.16232619881889765,930.2942519685039,0.00025370340306410486,25.0,45.0
832.18555,0.16274173031496061,930.0860104986876,0.00025370340306410486,25.0,45.0
833.58691,0.16312102952755905,930.8143307086614,0.00025370340306410486,25.0,45.0
834.98828,0.16358565157480315,932.0978215223097,0.00025370340306410486,25.0,45.0
836.38965,0.16402626771653545,929.493779527559,0.00025370340306410486,25.0,45.0
837.79102,0.1645004311023622,931.9086089238846,0.00025370340306410486,25.0,45.0
839.19238,0.16499308464566928,932.1699212598425,0.00025370340306410486,25.0,45.0
840.59375,0.16543271456692915,931.3256167979004,0.00025370340306410486,25.0,45.0
841.99512,0.16588748228346456,930.3749343832021,0.00025370340306410486,25.0,45.0
843.39648,0.16640339173228347,932.167532808399,0.00025370340306410486,25.0,45.0
844.79785,0.16690615748031495,930.9770341207349,0.00025370340306410486,25.0,45.0
846.19922,0.1674200964566929,931.5489238845144,0.00025370340306410486,25.0,45.0
847.60059,0.16786715354330708,931.2055905511811,0.00025370340306410486,25.0,45.0
849.00195,0.16836217716535432,931.7194488188976,0.00025370340306410486,25.0,45.0
850.40332,0.16876242125984253,931.5294488188975,0.00025370340306410486,25.0,45.0
851.80469,0.16931718897637796,931.5035695538057,0.00025370340306410486,25.0,45.0
853.20605,0.16979212598425197,929.7918897637794,0.00025370340306410486,25.0,45.0
854.60742,0.17022538582677166,931.729501312336,0.00025370340306410486,25.0,45.0
856.00879,0.17066417322834646,931.9216010498687,0.00025370340306410486,25.0,45.0
857.41016,0.17114639566929132,930.7319947506562,0.00025370340306410486,25.0,45.0
858.81152,0.17166455708661418,932.9497637795275,0.00025370340306410486,25.0,45.0
860.21289,0.17214828149606298,931.5697637795275,0.00025370340306410486,25.0,45.0
861.61426,0.17266487007874015,932.7085564304462,0.00025370340306410486,25.0,45.0
863.01563,0.17307451181102362,931.2685301837271,0.00025370340306410486,25.0,45.0
864.41699,0.1735271909448819,932.6589763779527,0.00025370340306410486,25.0,45.0
865.81836,0.1740153622047244,931.5458005249344,0.00025370340306410486,25.0,45.0
867.21973,0.17452183661417323,932.880813648294,0.00025370340306410486,25.0,45.0
868.62109,0.1749742913385827,929.728188976378,0.00025370340306410486,25.0,45.0
870.02246,0.17545349999999998,931.7897900262467,0.00025370340306410486,25.0,45.0
871.42383,0.17595639566929133,932.9730183727033,0.00025370340306410486,25.0,45.0
872.8252,0.17645482283464567,930.4144094488189,0.00025370340306410486,25.0,45.0
874.22656,0.17699119291338583,932.2579002624672,0.00025370340306410486,25.0,45.0
875.62793,0.17752874999999999,932.8014698162729,0.00025370340306410486,25.0,45.0
877.0293,0.1779926811023622,930.2911286089239,0.00025370340306410486,25.0,45.0
878.43066,0.178458594488189,932.4215485564305,0.00025370340306410486,25.0,45.0
879.83203,0.17892050787401573,932.310498687664,0.00025370340306410486,25.0,45.0
881.2334,0.17951007677165354,932.46031496063,0.00025370340306410486,25.0,45.0
882.63477,0.18005121259842521,932.8597900262467,0.00025370340306410486,25.0,45.0
884.03613,0.1805202460629921,931.6409448818898,0.00025370340306410486,25.0,45.0
885.4375,0.18100655314960631,932.1220472440946,0.00025370340306410486,25.0,45.0
886.83887,0.1815192460629921,932.2079790026246,0.00025370340306410486,25.0,45.0
887.13916,0.18166539566929132,934.7244881889764,0.00025370340306410486,25.0,45.0