File: datasets/am_bench_2022/csv/45-XY.02-4.csv
Time(s),Strain(%),Stress(MPa),SR(s-1),Temp(C),Angle(deg)
34.128662,1.575188248031496e-05,6.7854086063955785,0.00025370340306410486,25.0,45.0
35.730225,2.9004255905511807e-05,11.44774522963548,0.00025370340306410486,25.0,45.0
37.331787,3.6044559055118106e-05,17.97649217002237,0.00025370340306410486,25.0,45.0
38.93335,5.0178608267716536e-05,23.811301223845245,0.00025370340306410486,25.0,45.0
40.534912,7.381588385826771e-05,27.479534149230165,0.00025370340306410486,25.0,45.0
42.136475,8.625514763779528e-05,34.56068430056587,0.00025370340306410486,25.0,45.0
43.738037,0.00011407897244094488,38.311917357547046,0.00025370340306410486,25.0,45.0
45.3396,0.00011897941535433071,44.29685748124754,0.00025370340306410486,25.0,45.0
46.941162,0.00014484126181102362,53.127369390709305,0.00025370340306410486,25.0,45.0
48.542725,0.00013682147244094487,60.2642742466114,0.00025370340306410486,25.0,45.0
50.144287,0.00019382170275590552,68.74645348072116,0.00025370340306410486,25.0,45.0
51.74585,0.00021666844488188976,77.99323595209897,0.00025370340306410486,25.0,45.0
53.347412,0.00024226409448818898,86.52737728648506,0.00025370340306410486,25.0,45.0
54.948975,0.0002687488779527559,96.33867350967233,0.00025370340306410486,25.0,45.0
56.550537,0.0003027434251968504,105.33112251612056,0.00025370340306410486,25.0,45.0
58.1521,0.0003230734251968504,115.08173443874195,0.00025370340306410486,25.0,45.0
59.753662,0.00036196175196850396,123.21346756152126,0.00025370340306410486,25.0,45.0
61.355225,0.00038612354330708665,131.5407290432952,0.00025370340306410486,25.0,45.0
62.956787,0.0004165081299212598,142.23120673772866,0.00025370340306410486,25.0,45.0
64.55835,0.000458395,153.3471719963153,0.00025370340306410486,25.0,45.0
66.159912,0.00047414801181102365,163.24961442295043,0.00025370340306410486,25.0,45.0
67.761475,0.0005044055511811024,177.02347940518493,0.00025370340306410486,25.0,45.0
69.363037,0.0005511644488188977,188.64780365837612,0.00025370340306410486,25.0,45.0
70.9646,0.000597708996062992,199.2515041452823,0.00025370340306410486,25.0,45.0
72.566162,0.0006370514566929134,210.2621371233057,0.00025370340306410486,25.0,45.0
74.167725,0.000642986062992126,220.26181602842482,0.00025370340306410486,25.0,45.0
75.769287,0.0007041244094488189,231.25418344519017,0.00025370340306410486,25.0,45.0
77.37085,0.0007311422047244095,242.50569548624821,0.00025370340306410486,25.0,45.0
78.972412,0.0007643406102362205,254.9195341492302,0.00025370340306410486,25.0,45.0
80.573975,0.0008024087401574802,267.83874193972895,0.00025370340306410486,25.0,45.0
82.175537,0.0008540479133858269,279.8153441242269,0.00025370340306410486,25.0,45.0
83.7771,0.0008873794488188976,292.39302539807875,0.00025370340306410486,25.0,45.0
85.378662,0.0009156267716535433,304.1390182918805,0.00025370340306410486,25.0,45.0
86.980225,0.000977469153543307,315.08448480063174,0.00025370340306410486,25.0,45.0
88.581787,0.0009850458661417323,325.2671404132123,0.00025370340306410486,25.0,45.0
90.18335,0.0010388695275590552,339.2589024871694,0.00025370340306410486,25.0,45.0
91.784912,0.0010840104330708661,351.9874983550468,0.00025370340306410486,25.0,45.0
93.386475,0.0011296731102362204,365.0139492038426,0.00025370340306410486,25.0,45.0
94.988037,0.0011500563385826773,375.1185419134097,0.00025370340306410486,25.0,45.0
96.5896,0.0011928466535433072,388.39118305040137,0.00025370340306410486,25.0,45.0
98.191162,0.0012241849409448818,399.60402684563763,0.00025370340306410486,25.0,45.0
99.792725,0.0012573083070866141,409.42031846295566,0.00025370340306410486,25.0,45.0
101.39429,0.0012996265551181102,418.93364916436377,0.00025370340306410486,25.0,45.0
102.99585,0.0013352378149606298,428.7183313593894,0.00025370340306410486,25.0,45.0
104.59741,0.001361705433070866,441.6334517699698,0.00025370340306410486,25.0,45.0
106.19897,0.0013985644488188976,452.30767206211345,0.00025370340306410486,25.0,45.0
107.80054,0.0014419396062992126,462.87335175681017,0.00025370340306410486,25.0,45.0
109.4021,0.0014740391732283463,472.89272272667466,0.00025370340306410486,25.0,45.0
111.00366,0.0014979772637795275,484.69674957231217,0.00025370340306410486,25.0,45.0
112.60522,0.001524539311023622,491.52559547308863,0.00025370340306410486,25.0,45.0
114.20679,0.0015749768307086612,503.17994472956974,0.00025370340306410486,25.0,45.0
115.80835,0.0015946712007874017,510.8725095407291,0.00025370340306410486,25.0,45.0
117.40991,0.001621474409448819,521.4271351493618,0.00025370340306410486,25.0,45.0
119.01147,0.001642849724409449,529.3370706671931,0.00025370340306410486,25.0,45.0
120.61304,0.001693626594488189,537.6195025661272,0.00025370340306410486,25.0,45.0
122.2146,0.0017139558267716536,547.8196341623899,0.00025370340306410486,25.0,45.0
123.81616,0.0017374645866141732,554.3817081194895,0.00025370340306410486,25.0,45.0
125.41772,0.0017728685826771653,560.5387024608501,0.00025370340306410486,25.0,45.0
127.01929,0.0017978560826771655,568.7196473220162,0.00025370340306410486,25.0,45.0
128.62085,0.0018196186023622047,573.6509803921568,0.00025370340306410486,25.0,45.0
130.22241,0.0018391499803149607,582.1692064745362,0.00025370340306410486,25.0,45.0
131.82397,0.0018635841732283465,589.2362152914858,0.00025370340306410486,25.0,45.0
133.42554,0.001890222933070866,592.1930253980788,0.00025370340306410486,25.0,45.0
135.0271,0.0019009892322834647,597.8834583497829,0.00025370340306410486,25.0,45.0
136.62866,0.001946301929133858,605.7763389919727,0.00025370340306410486,25.0,45.0
138.23022,0.0019710935039370077,609.6701408080011,0.00025370340306410486,25.0,45.0
139.83179,0.0019853187007874014,616.6441637057508,0.00025370340306410486,25.0,45.0
141.43335,0.002022280905511811,620.5422292406896,0.00025370340306410486,25.0,45.0
143.03491,0.002060592716535433,625.131780497434,0.00025370340306410486,25.0,45.0
144.63647,0.002095419488188976,628.9089617054876,0.00025370340306410486,25.0,45.0
146.23804,0.0021105336614173228,634.448716936439,0.00025370340306410486,25.0,45.0
147.8396,0.00212783405511811,640.126253454402,0.00025370340306410486,25.0,45.0
149.44116,0.0021633498031496065,640.2433741281748,0.00025370340306410486,25.0,45.0
151.04272,0.002209279724409449,647.7326753520201,0.00025370340306410486,25.0,45.0
152.64429,0.002247653543307087,651.3821029082775,0.00025370340306410486,25.0,45.0
154.24585,0.0022711503937007877,656.3276220555338,0.00025370340306410486,25.0,45.0
155.84741,0.0023447407480314962,662.2330569811818,0.00025370340306410486,25.0,45.0
157.44897,0.0023783844488188977,665.2238715620476,0.00025370340306410486,25.0,45.0
159.05054,0.002451287007874016,667.780550072378,0.00025370340306410486,25.0,45.0
160.6521,0.002484357874015748,669.8133438610345,0.00025370340306410486,25.0,45.0
162.25366,0.0025369167322834645,673.1793393867615,0.00025370340306410486,25.0,45.0
163.85522,0.002594902559055118,678.5764442689829,0.00025370340306410486,25.0,45.0
165.45679,0.002684556692913386,683.7520200026321,0.00025370340306410486,25.0,45.0
167.05835,0.0027347454724409447,683.7811290959338,0.00025370340306410486,25.0,45.0
168.65991,0.0028016570866141732,686.9309382813528,0.00025370340306410486,25.0,45.0
170.26147,0.0028641521653543305,690.8397157520727,0.00025370340306410486,25.0,45.0
171.86304,0.002968218503937008,696.2781418607713,0.00025370340306410486,25.0,45.0
173.4646,0.0030516330708661417,696.4121068561653,0.00025370340306410486,25.0,45.0
175.06616,0.003159147440944882,700.4640347414135,0.00025370340306410486,25.0,45.0
176.66772,0.003235803937007874,701.7175944203185,0.00025370340306410486,25.0,45.0
178.26929,0.0033568931102362204,705.579760494802,0.00025370340306410486,25.0,45.0
179.87085,0.0034866230314960626,710.8661666008686,0.00025370340306410486,25.0,45.0
181.47241,0.003604484842519685,711.5936833793921,0.00025370340306410486,25.0,45.0
183.07397,0.0037493096456692916,715.122305566522,0.00025370340306410486,25.0,45.0
184.67554,0.003909518700787401,716.4369785498093,0.00025370340306410486,25.0,45.0
186.2771,0.0040755074803149605,719.550940913278,0.00025370340306410486,25.0,45.0
187.87866,0.004254321456692914,720.0334517699698,0.00025370340306410486,25.0,45.0
189.48022,0.004404142716535433,721.9317541781813,0.00025370340306410486,25.0,45.0
191.08179,0.004627053346456693,725.3895775759969,0.00025370340306410486,25.0,45.0
192.68335,0.0048543484251968505,726.9407027240427,0.00025370340306410486,25.0,45.0
194.28491,0.0050672175196850395,727.856165284906,0.00025370340306410486,25.0,45.0
195.88647,0.005299142913385827,731.9756810106594,0.00025370340306410486,25.0,45.0
197.48804,0.005546474015748031,732.4891433083302,0.00025370340306410486,25.0,45.0
199.0896,0.00583991437007874,733.6607974733517,0.00025370340306410486,25.0,45.0
200.69116,0.006121565748031496,736.1282800368471,0.00025370340306410486,25.0,45.0
202.29272,0.00643927874015748,738.0328990656666,0.00025370340306410486,25.0,45.0
203.89429,0.006687773818897637,738.2510593499145,0.00025370340306410486,25.0,45.0
205.49585,0.007002642322834645,739.575365179629,0.00025370340306410486,25.0,45.0
207.09741,0.007268729133858268,739.1584682195027,0.00025370340306410486,25.0,45.0
208.69897,0.00753890374015748,742.3730754046585,0.00025370340306410486,25.0,45.0
210.30054,0.007850511023622046,743.4207658902487,0.00025370340306410486,25.0,45.0
211.9021,0.00815914625984252,742.1646795631004,0.00025370340306410486,25.0,45.0
213.50366,0.00849097283464567,746.2653770232927,0.00025370340306410486,25.0,45.0
215.10522,0.008839142913385827,746.6554020265825,0.00025370340306410486,25.0,45.0
216.70679,0.009157443307086614,745.8338465587578,0.00025370340306410486,25.0,45.0
218.30835,0.00950430531496063,748.1317015396764,0.00025370340306410486,25.0,45.0
219.90991,0.009825796259842519,748.1822608237926,0.00025370340306410486,25.0,45.0
221.51147,0.010210940748031496,752.0425582313462,0.00025370340306410486,25.0,45.0
223.11304,0.010573567716535432,752.6878799842085,0.00025370340306410486,25.0,45.0
224.7146,0.010932329330708661,751.191551519937,0.00025370340306410486,25.0,45.0
226.31616,0.011329298622047245,753.1029345966575,0.00025370340306410486,25.0,45.0
227.91772,0.011736930511811024,753.6506908803791,0.00025370340306410486,25.0,45.0
229.51929,0.012083112598425197,754.798710356626,0.00025370340306410486,25.0,45.0
231.12085,0.012486888582677167,757.0975128306357,0.00025370340306410486,25.0,45.0
232.72241,0.012852929133858267,756.8471114620346,0.00025370340306410486,25.0,45.0
234.32397,0.013190912598425197,757.9250164495329,0.00025370340306410486,25.0,45.0
235.92554,0.013498599606299212,756.6542176602186,0.00025370340306410486,25.0,45.0
237.5271,0.013844633661417324,760.0027898407686,0.00025370340306410486,25.0,45.0
239.12866,0.014193288582677164,758.6318199763127,0.00025370340306410486,25.0,45.0
240.73022,0.01448276122047244,759.495802079221,0.00025370340306410486,25.0,45.0
242.33179,0.014850098228346457,761.3897618107646,0.00025370340306410486,25.0,45.0
243.93335,0.015210977755905512,760.9789182787209,0.00025370340306410486,25.0,45.0
245.53491,0.01555962972440945,764.5352809580208,0.00025370340306410486,25.0,45.0
247.13647,0.015957275196850394,764.0025266482432,0.00025370340306410486,25.0,45.0
248.73804,0.016335302559055118,764.1445979734176,0.00025370340306410486,25.0,45.0
250.3396,0.016706391338582677,767.812975391499,0.00025370340306410486,25.0,45.0
251.94116,0.017115558858267717,766.5631267272009,0.00025370340306410486,25.0,45.0
253.54272,0.017509889566929133,767.8515330964601,0.00025370340306410486,25.0,45.0
255.14429,0.017899053346456695,770.0120015791553,0.00025370340306410486,25.0,45.0
256.74585,0.018332517322834647,770.3354651927885,0.00025370340306410486,25.0,45.0
258.34741,0.018704915748031493,770.9564416370575,0.00025370340306410486,25.0,45.0
259.94897,0.01912211594488189,770.7109882879328,0.00025370340306410486,25.0,45.0
261.55054,0.019507956299212596,771.5059613106988,0.00025370340306410486,25.0,45.0
263.1521,0.019884566929133856,772.2249769706541,0.00025370340306410486,25.0,45.0
264.75366,0.020281891732283463,772.3795236215292,0.00025370340306410486,25.0,45.0
266.35522,0.020605875984251967,773.1042768785368,0.00025370340306410486,25.0,45.0
267.95679,0.020950374015748032,774.8858270825109,0.00025370340306410486,25.0,45.0
269.55835,0.021367311023622045,774.5140413212265,0.00025370340306410486,25.0,45.0
271.15991,0.021710175196850392,773.96228451112,0.00025370340306410486,25.0,45.0
272.76147,0.022044903543307088,776.2240294775629,0.00025370340306410486,25.0,45.0
274.36304,0.022422950787401575,776.3907093038558,0.00025370340306410486,25.0,45.0
275.9646,0.022782612204724408,776.9916831161996,0.00025370340306410486,25.0,45.0
277.56616,0.023150582677165354,776.3826819318332,0.00025370340306410486,25.0,45.0
279.16772,0.02351583464566929,778.6436373207001,0.00025370340306410486,25.0,45.0
280.76929,0.023904903543307085,778.7201737070668,0.00025370340306410486,25.0,45.0
282.37085,0.024264242125984253,779.9557046979866,0.00025370340306410486,25.0,45.0
283.97241,0.02466005118110236,781.8468219502566,0.00025370340306410486,25.0,45.0
285.57397,0.02505009251968504,781.7913672851691,0.00025370340306410486,25.0,45.0
287.17554,0.025402818897637795,780.3048559020925,0.00025370340306410486,25.0,45.0
288.7771,0.025779240157480315,782.7607316752205,0.00025370340306410486,25.0,45.0
290.37866,0.02619656692913386,783.6381892354258,0.00025370340306410486,25.0,45.0
291.98022,0.026558655511811025,783.9893670219767,0.00025370340306410486,25.0,45.0
293.58179,0.026941665354330707,784.1482037110146,0.00025370340306410486,25.0,45.0
295.18335,0.02729316338582677,785.9314909856561,0.00025370340306410486,25.0,45.0
296.78491,0.027701669291338583,783.5360968548493,0.00025370340306410486,25.0,45.0
298.38647,0.028036409448818893,787.2389261744968,0.00025370340306410486,25.0,45.0
299.98804,0.028437937007874014,786.6815633636005,0.00025370340306410486,25.0,45.0
301.5896,0.02885383661417323,788.7253585998159,0.00025370340306410486,25.0,45.0
303.19116,0.02928182874015748,788.9673904461114,0.00025370340306410486,25.0,45.0
304.79272,0.02963524212598425,788.5102250296092,0.00025370340306410486,25.0,45.0
306.39429,0.029982517716535435,789.5166732464799,0.00025370340306410486,25.0,45.0
307.99585,0.030330220472440942,789.2160810632978,0.00025370340306410486,25.0,45.0
309.59741,0.030720990157480317,789.4085274378208,0.00025370340306410486,25.0,45.0
311.19897,0.03106895275590551,790.9829714436112,0.00025370340306410486,25.0,45.0
312.80054,0.031385403543307086,789.6296881168576,0.00025370340306410486,25.0,45.0
314.4021,0.03174666929133858,793.8693512304251,0.00025370340306410486,25.0,45.0
316.00366,0.032100923228346456,792.6099486774576,0.00025370340306410486,25.0,45.0
317.60522,0.0325031437007874,793.6185813922885,0.00025370340306410486,25.0,45.0
319.20679,0.03289558858267717,793.2686932491117,0.00025370340306410486,25.0,45.0
320.80835,0.03325635039370079,793.1509145940256,0.00025370340306410486,25.0,45.0
322.40991,0.03358315551181102,795.9391762073958,0.00025370340306410486,25.0,45.0
324.01147,0.03395870866141732,794.5014607185157,0.00025370340306410486,25.0,45.0
325.61304,0.03430670866141732,797.612133175418,0.00025370340306410486,25.0,45.0
327.2146,0.03474654330708661,797.9577839189368,0.00025370340306410486,25.0,45.0
328.81616,0.035119289370078736,797.2136860113173,0.00025370340306410486,25.0,45.0
330.41772,0.035497944881889766,797.0998289248587,0.00025370340306410486,25.0,45.0
332.01929,0.035871917322834644,799.9713120147388,0.00025370340306410486,25.0,45.0
333.62085,0.036265578740157484,799.4744834846691,0.00025370340306410486,25.0,45.0
335.22241,0.03665027952755905,800.9051980523753,0.00025370340306410486,25.0,45.0
336.82397,0.03702854724409449,802.7388077378604,0.00025370340306410486,25.0,45.0
338.42554,0.037450935039370074,801.3517831293592,0.00025370340306410486,25.0,45.0
340.0271,0.037821033464566924,803.1074351888407,0.00025370340306410486,25.0,45.0
341.62866,0.03819877755905512,803.47916831162,0.00025370340306410486,25.0,45.0
343.23022,0.03856809448818898,802.7279378865642,0.00025370340306410486,25.0,45.0
344.83179,0.03896055905511811,803.4193972891171,0.00025370340306410486,25.0,45.0
346.43335,0.039314950787401576,804.5232004211081,0.00025370340306410486,25.0,45.0
348.03491,0.03965936811023622,803.7675483616266,0.00025370340306410486,25.0,45.0
349.63647,0.039961342519685035,804.1249374917753,0.00025370340306410486,25.0,45.0
351.23804,0.0403396968503937,807.0400315831031,0.00025370340306410486,25.0,45.0
352.8396,0.0407468031496063,805.5018818265562,0.00025370340306410486,25.0,45.0
354.44116,0.04108372440944882,807.8795367811555,0.00025370340306410486,25.0,45.0
356.04272,0.041473653543307086,807.4609290696145,0.00025370340306410486,25.0,45.0
357.64429,0.04184125,809.0284511119885,0.00025370340306410486,25.0,45.0
359.24585,0.04223735826771654,809.1194894065009,0.00025370340306410486,25.0,45.0
360.84741,0.04259511220472441,807.9292801684433,0.00025370340306410486,25.0,45.0
362.44897,0.042971956692913385,811.1945782339783,0.00025370340306410486,25.0,45.0
364.05054,0.04333911811023622,809.9932359520991,0.00025370340306410486,25.0,45.0
365.6521,0.043711397637795274,812.527490459271,0.00025370340306410486,25.0,45.0
367.25366,0.044090901574803144,811.109567048296,0.00025370340306410486,25.0,45.0
368.85522,0.044432864173228344,811.6506119226215,0.00025370340306410486,25.0,45.0
370.45679,0.044777996062992126,813.735333596526,0.00025370340306410486,25.0,45.0
372.05835,0.045137273622047246,812.1372022634557,0.00025370340306410486,25.0,45.0
373.65991,0.04549894094488189,812.3102513488618,0.00025370340306410486,25.0,45.0
375.26147,0.04585107283464567,813.9095144097909,0.00025370340306410486,25.0,45.0
376.86304,0.046286474409448816,815.4468482695092,0.00025370340306410486,25.0,45.0
378.4646,0.04665069488188976,815.6287406237664,0.00025370340306410486,25.0,45.0
380.06616,0.047029527559055116,816.9116989077512,0.00025370340306410486,25.0,45.0
381.66772,0.04734982480314961,816.8642716146862,0.00025370340306410486,25.0,45.0
383.26929,0.04768356102362205,815.8918805105936,0.00025370340306410486,25.0,45.0
384.87085,0.0480763562992126,818.7801289643376,0.00025370340306410486,25.0,45.0
386.47241,0.04849812007874015,819.1509409132782,0.00025370340306410486,25.0,45.0
388.07397,0.048889084645669295,818.8910909330175,0.00025370340306410486,25.0,45.0
389.67554,0.04922526968503937,818.1245163837348,0.00025370340306410486,25.0,45.0
391.2771,0.049549645669291334,819.0710093433347,0.00025370340306410486,25.0,45.0
392.87866,0.049933299212598425,821.3166995657324,0.00025370340306410486,25.0,45.0
394.48022,0.05037979330708661,820.1952362152915,0.00025370340306410486,25.0,45.0
396.08179,0.05067381496062993,820.6528753783393,0.00025370340306410486,25.0,45.0
397.68335,0.05098241732283464,822.4854322937229,0.00025370340306410486,25.0,45.0
399.28491,0.051387346456692906,823.6832477957627,0.00025370340306410486,25.0,45.0
400.88647,0.051783523622047245,821.771759442032,0.00025370340306410486,25.0,45.0
402.48804,0.05211630118110236,820.533412291091,0.00025370340306410486,25.0,45.0
404.0896,0.052464840551181106,823.3056717989209,0.00025370340306410486,25.0,45.0
405.69116,0.05280121456692913,823.6473746545598,0.00025370340306410486,25.0,45.0
407.29272,0.05320249606299212,826.3387550993554,0.00025370340306410486,25.0,45.0
408.89429,0.05355137598425196,826.3535991577841,0.00025370340306410486,25.0,45.0
410.49585,0.05391264173228347,827.018502434531,0.00025370340306410486,25.0,45.0
412.09741,0.05429728543307087,827.497723384656,0.00025370340306410486,25.0,45.0
413.69897,0.05466448818897637,826.9141729174893,0.00025370340306410486,25.0,45.0
415.30054,0.055049324803149606,826.9580997499672,0.00025370340306410486,25.0,45.0
416.9021,0.05536863188976378,827.4396367943152,0.00025370340306410486,25.0,45.0
418.50366,0.05574435826771654,830.0919331490986,0.00025370340306410486,25.0,45.0
420.10522,0.05610131102362205,828.9666271877879,0.00025370340306410486,25.0,45.0
421.70679,0.0564683031496063,828.9533886037638,0.00025370340306410486,25.0,45.0
423.30835,0.056763903543307084,828.1571259376235,0.00025370340306410486,25.0,45.0
424.90991,0.057130218503937014,830.8024740097381,0.00025370340306410486,25.0,45.0
426.51147,0.05751320866141733,830.4996446900909,0.00025370340306410486,25.0,45.0
428.11304,0.05786924606299213,832.025266482432,0.00025370340306410486,25.0,45.0
429.7146,0.05823201968503937,831.481089617055,0.00025370340306410486,25.0,45.0
431.31616,0.058551208661417324,831.6161600210555,0.00025370340306410486,25.0,45.0
432.91772,0.058966692913385826,833.031977891828,0.00025370340306410486,25.0,45.0
434.51929,0.059361116141732284,833.9631793657061,0.00025370340306410486,25.0,45.0
436.12085,0.059683661417322835,833.3182260823793,0.00025370340306410486,25.0,45.0
437.72241,0.06004140157480315,832.8821160679038,0.00025370340306410486,25.0,45.0
439.32397,0.06044772834645669,835.3646006053428,0.00025370340306410486,25.0,45.0
440.92554,0.06086052559055118,834.1057507566786,0.00025370340306410486,25.0,45.0
442.5271,0.06124082086614173,837.1512830635611,0.00025370340306410486,25.0,45.0
444.12866,0.06162127559055118,837.4421897618109,0.00025370340306410486,25.0,45.0
445.73022,0.06200257677165354,837.0928806421898,0.00025370340306410486,25.0,45.0
447.33179,0.062372692913385826,838.2656138965655,0.00025370340306410486,25.0,45.0
448.93335,0.06277117716535432,835.7997894459797,0.00025370340306410486,25.0,45.0
450.53491,0.06310566141732284,838.3616791683116,0.00025370340306410486,25.0,45.0
452.13647,0.06340685236220472,837.8515594157127,0.00025370340306410486,25.0,45.0
453.73804,0.06375328149606299,840.8007895775761,0.00025370340306410486,25.0,45.0
455.3396,0.06412117519685039,840.5516515330966,0.00025370340306410486,25.0,45.0
456.94116,0.06447244881889765,840.8634293986051,0.00025370340306410486,25.0,45.0
458.54272,0.06483597244094488,840.9125148045796,0.00025370340306410486,25.0,45.0
460.14429,0.06517594291338583,840.0729569680221,0.00025370340306410486,25.0,45.0
461.74585,0.06553515354330709,842.241847611528,0.00025370340306410486,25.0,45.0
463.34741,0.06586160629921259,843.6419265692855,0.00025370340306410486,25.0,45.0
464.94897,0.06625399409448819,842.686616660087,0.00025370340306410486,25.0,45.0
466.55054,0.06660963976377952,844.0108172127913,0.00025370340306410486,25.0,45.0
468.1521,0.06696858070866142,845.0174496644296,0.00025370340306410486,25.0,45.0
469.75366,0.06734410826771653,843.2178970917226,0.00025370340306410486,25.0,45.0
471.35522,0.0677418405511811,843.3155678378735,0.00025370340306410486,25.0,45.0
472.95679,0.06809543700787402,846.8159231477827,0.00025370340306410486,25.0,45.0
474.55835,0.0685180374015748,846.2824055796816,0.00025370340306410486,25.0,45.0
476.15991,0.06889416338582677,848.1141465982367,0.00025370340306410486,25.0,45.0
477.76147,0.06927971653543308,847.104092643769,0.00025370340306410486,25.0,45.0
479.36304,0.0696319409448819,846.8175286221872,0.00025370340306410486,25.0,45.0
480.9646,0.06999208070866142,847.3155678378735,0.00025370340306410486,25.0,45.0
482.56616,0.07036140551181103,847.6988551125148,0.00025370340306410486,25.0,45.0
484.16772,0.07073993700787401,849.0833793920253,0.00025370340306410486,25.0,45.0
485.76929,0.07110317913385826,846.8392946440322,0.00025370340306410486,25.0,45.0
487.37085,0.07139692519685038,849.099749967101,0.00025370340306410486,25.0,45.0
488.97241,0.07172726181102362,848.7708909066984,0.00025370340306410486,25.0,45.0
490.57397,0.0720914842519685,850.4565337544415,0.00025370340306410486,25.0,45.0
492.17554,0.07248653346456693,850.6741676536387,0.00025370340306410486,25.0,45.0
493.7771,0.07285781299212599,851.5023029345967,0.00025370340306410486,25.0,45.0
495.37866,0.07320891732283465,851.4009474930913,0.00025370340306410486,25.0,45.0
496.98022,0.07362142125984251,850.7332806948284,0.00025370340306410486,25.0,45.0
498.58179,0.07394585629921259,851.8675352020003,0.00025370340306410486,25.0,45.0
500.18335,0.07430823031496063,852.51875246743,0.00025370340306410486,25.0,45.0
501.78491,0.07469875787401575,852.8040531648901,0.00025370340306410486,25.0,45.0
503.38647,0.07509464763779528,855.6905645479669,0.00025370340306410486,25.0,45.0
504.98804,0.07546103543307087,853.1105671798921,0.00025370340306410486,25.0,45.0
506.5896,0.07580183070866142,854.497776023161,0.00025370340306410486,25.0,45.0
508.19116,0.0762032716535433,854.9940781681802,0.00025370340306410486,25.0,45.0
509.79272,0.07657996456692913,854.9942097644428,0.00025370340306410486,25.0,45.0
511.39429,0.0769720059055118,855.6757731280433,0.00025370340306410486,25.0,45.0
512.99585,0.0772836811023622,856.073983418871,0.00025370340306410486,25.0,45.0
514.59741,0.07768054527559055,858.4030003947888,0.00025370340306410486,25.0,45.0
516.19897,0.07806001968503937,856.541308066851,0.00025370340306410486,25.0,45.0
517.80054,0.07844891732283464,858.9867087774708,0.00025370340306410486,25.0,45.0
519.4021,0.07882938976377953,858.7995262534545,0.00025370340306410486,25.0,45.0
521.00366,0.07919564173228347,858.7323068824846,0.00025370340306410486,25.0,45.0
522.60522,0.07959308070866142,860.1046190288197,0.00025370340306410486,25.0,45.0
524.20679,0.07991202952755906,858.3014080800106,0.00025370340306410486,25.0,45.0
525.80835,0.080260968503937,859.507250954073,0.00025370340306410486,25.0,45.0
527.40991,0.08053463976377953,858.522252928017,0.00025370340306410486,25.0,45.0
529.01147,0.0809086062992126,861.7387287801027,0.00025370340306410486,25.0,45.0
530.61304,0.08128040157480315,860.8251875246744,0.00025370340306410486,25.0,45.0
532.2146,0.08160277755905512,859.0483747861562,0.00025370340306410486,25.0,45.0
533.81616,0.08196606102362204,861.1136991709436,0.00025370340306410486,25.0,45.0
535.41772,0.08229887204724409,861.4028424792737,0.00025370340306410486,25.0,45.0
537.01929,0.08264863976377952,863.1621265956047,0.00025370340306410486,25.0,45.0
538.62085,0.08303432677165354,864.2183708382682,0.00025370340306410486,25.0,45.0
540.22241,0.08340367716535432,862.1518094486117,0.00025370340306410486,25.0,45.0
541.82397,0.08384498622047243,867.120673772865,0.00025370340306410486,25.0,45.0
543.42554,0.08424849015748032,864.6376891696277,0.00025370340306410486,25.0,45.0
545.0271,0.08458441732283464,865.1661271219898,0.00025370340306410486,25.0,45.0
546.62866,0.08496548818897637,865.7225161205422,0.00025370340306410486,25.0,45.0
548.23022,0.08533853346456692,865.6791419923675,0.00025370340306410486,25.0,45.0
549.83179,0.08567107677165353,865.9819976312674,0.00025370340306410486,25.0,45.0
551.43335,0.08605349606299212,867.8282668772208,0.00025370340306410486,25.0,45.0
553.03491,0.08642685826771652,866.9086985129622,0.00025370340306410486,25.0,45.0
554.63647,0.0868490531496063,868.8008948545862,0.00025370340306410486,25.0,45.0
556.23804,0.08723657874015747,868.4660613238585,0.00025370340306410486,25.0,45.0
557.8396,0.08760862007874015,867.8105277010134,0.00025370340306410486,25.0,45.0
559.44116,0.08795923818897639,866.565442821424,0.00025370340306410486,25.0,45.0
561.04272,0.08830534842519684,868.6844058428742,0.00025370340306410486,25.0,45.0
562.64429,0.08861674803149606,867.3419660481643,0.00025370340306410486,25.0,45.0
564.24585,0.08898245472440944,870.6515330964602,0.00025370340306410486,25.0,45.0
565.84741,0.08934888779527558,869.9069351230427,0.00025370340306410486,25.0,45.0
567.44897,0.0897692716535433,871.6351098828794,0.00025370340306410486,25.0,45.0
569.05054,0.09010908267716534,870.1783655744177,0.00025370340306410486,25.0,45.0
570.6521,0.09050342913385827,872.0155020397422,0.00025370340306410486,25.0,45.0
572.25366,0.09089156299212597,870.9738386629821,0.00025370340306410486,25.0,45.0
573.85522,0.09125030511811023,871.6536123174103,0.00025370340306410486,25.0,45.0
575.45679,0.09160000196850394,872.2210554020266,0.00025370340306410486,25.0,45.0
577.05835,0.0920519940944882,873.0601658112911,0.00025370340306410486,25.0,45.0
578.65991,0.09247024015748032,874.2017370706673,0.00025370340306410486,25.0,45.0
580.26147,0.09283530118110236,872.386577181208,0.00025370340306410486,25.0,45.0
581.86304,0.09321120472440945,871.818502434531,0.00025370340306410486,25.0,45.0
583.4646,0.09356215551181103,875.8377681273853,0.00025370340306410486,25.0,45.0
585.06616,0.09392305118110235,873.8867745756022,0.00025370340306410486,25.0,45.0
586.66772,0.09434477165354331,874.1890248716937,0.00025370340306410486,25.0,45.0
588.26929,0.09471962401574803,874.4535596789052,0.00025370340306410486,25.0,45.0
589.87085,0.09507332086614173,874.9150414528228,0.00025370340306410486,25.0,45.0
591.47241,0.0954102874015748,874.296144229504,0.00025370340306410486,25.0,45.0
593.07397,0.09575501968503937,875.104092643769,0.00025370340306410486,25.0,45.0
594.67554,0.09610404724409449,876.9276220555337,0.00025370340306410486,25.0,45.0
596.2771,0.09649305511811024,874.8877483879459,0.00025370340306410486,25.0,45.0
597.87866,0.09678079527559055,876.5593630740888,0.00025370340306410486,25.0,45.0
599.48022,0.09709703346456693,878.1691801552836,0.00025370340306410486,25.0,45.0
601.08179,0.09747889763779527,879.2943018818266,0.00025370340306410486,25.0,45.0
602.68335,0.09784568307086615,878.3874457165418,0.00025370340306410486,25.0,45.0
604.28491,0.09824228740157481,878.5350967232531,0.00025370340306410486,25.0,45.0
605.88647,0.0986766279527559,880.7054875641533,0.00025370340306410486,25.0,45.0
607.48804,0.09907839566929133,879.5191998947231,0.00025370340306410486,25.0,45.0
609.0896,0.09941680511811024,880.0913278062905,0.00025370340306410486,25.0,45.0
610.69116,0.09981771653543307,878.4564021581788,0.00025370340306410486,25.0,45.0
612.29272,0.10017182480314961,881.320673772865,0.00025370340306410486,25.0,45.0
613.89429,0.10057408464566929,883.092591130412,0.00025370340306410486,25.0,45.0
615.49585,0.10098174409448818,881.6740097381235,0.00025370340306410486,25.0,45.0
617.09741,0.10137884251968503,883.0258191867351,0.00025370340306410486,25.0,45.0
618.69897,0.10177422637795275,881.9777602316095,0.00025370340306410486,25.0,45.0
620.30054,0.10215780905511812,883.2836952230557,0.00025370340306410486,25.0,45.0
621.9021,0.10253785826771653,882.1079352546388,0.00025370340306410486,25.0,45.0
623.50366,0.10292582874015749,883.7108566916701,0.00025370340306410486,25.0,45.0
625.10522,0.10324045472440944,883.8078168180024,0.00025370340306410486,25.0,45.0
626.70679,0.10362640551181102,883.1917357547046,0.00025370340306410486,25.0,45.0
628.30835,0.10404650196850393,885.0608764311094,0.00025370340306410486,25.0,45.0
629.90991,0.10435960236220473,884.2396367943152,0.00025370340306410486,25.0,45.0
631.51147,0.10470740944881889,885.3593630740888,0.00025370340306410486,25.0,45.0
633.11304,0.10513403937007873,886.9629951309383,0.00025370340306410486,25.0,45.0
634.7146,0.10555556692913387,885.4646664034742,0.00025370340306410486,25.0,45.0
636.31616,0.10589280314960631,885.8467956310042,0.00025370340306410486,25.0,45.0
637.91772,0.1062718188976378,886.5563100407949,0.00025370340306410486,25.0,45.0
639.51929,0.10667068897637794,886.4821687064087,0.00025370340306410486,25.0,45.0
641.12085,0.10703012401574803,887.1065403342545,0.00025370340306410486,25.0,45.0
642.72241,0.10740802755905512,886.0403474141335,0.00025370340306410486,25.0,45.0
644.32397,0.10780062007874015,890.0246611396237,0.00025370340306410486,25.0,45.0
645.92554,0.1081312027559055,888.5331490985657,0.00025370340306410486,25.0,45.0
647.5271,0.10850379133858266,886.7787603632058,0.00025370340306410486,25.0,45.0
649.12866,0.10886139566929133,888.0428740623767,0.00025370340306410486,25.0,45.0
650.73022,0.10924121062992126,890.5136465324387,0.00025370340306410486,25.0,45.0
652.33179,0.10959501377952756,889.8542439794711,0.00025370340306410486,25.0,45.0
653.93335,0.11000548818897639,889.3075667851034,0.00025370340306410486,25.0,45.0
655.53491,0.11039236614173228,889.9233846558758,0.00025370340306410486,25.0,45.0
657.13647,0.11079684448818897,891.5026714041322,0.00025370340306410486,25.0,45.0
658.73804,0.11119857874015747,892.5289643374128,0.00025370340306410486,25.0,45.0
660.3396,0.1116275433070866,891.6323463613634,0.00025370340306410486,25.0,45.0
661.94116,0.11201595866141732,892.0033425450719,0.00025370340306410486,25.0,45.0
663.54272,0.11242466141732282,892.2822213449139,0.00025370340306410486,25.0,45.0
665.14429,0.11282600787401575,892.7968416896961,0.00025370340306410486,25.0,45.0
666.74585,0.11321970275590551,892.4692722726675,0.00025370340306410486,25.0,45.0
668.34741,0.11359617519685039,892.9616002105541,0.00025370340306410486,25.0,45.0
669.94897,0.1139388188976378,893.5060402684564,0.00025370340306410486,25.0,45.0
671.55054,0.1143108090551181,893.7249111725229,0.00025370340306410486,25.0,45.0
673.1521,0.11470572440944882,895.9372285827083,0.00025370340306410486,25.0,45.0
674.75366,0.11512008267716536,895.1562047637848,0.00025370340306410486,25.0,45.0
676.35522,0.11554862598425197,893.5839978944599,0.00025370340306410486,25.0,45.0
677.95679,0.11596842716535433,895.4418739307805,0.00025370340306410486,25.0,45.0
679.55835,0.11634886417322833,895.1643110935651,0.00025370340306410486,25.0,45.0
681.15991,0.11671680708661418,896.4907487827347,0.00025370340306410486,25.0,45.0
682.76147,0.117111218503937,895.1671798920911,0.00025370340306410486,25.0,45.0
684.36304,0.11745592716535433,895.6317673378078,0.00025370340306410486,25.0,45.0
685.9646,0.11785621653543306,897.7529938149756,0.00025370340306410486,25.0,45.0
687.56616,0.11831000984251969,896.3533622845111,0.00025370340306410486,25.0,45.0
689.16772,0.11872181102362206,895.949756546914,0.00025370340306410486,25.0,45.0
690.76929,0.11911483661417323,898.4276615344124,0.00025370340306410486,25.0,45.0
692.37085,0.11946255118110237,897.8195552046324,0.00025370340306410486,25.0,45.0
693.97241,0.11987121850393702,898.4276615344124,0.00025370340306410486,25.0,45.0
695.57397,0.12025098622047244,896.9195683642585,0.00025370340306410486,25.0,45.0
697.17554,0.12061348425196851,897.53464929596,0.00025370340306410486,25.0,45.0
698.7771,0.1209473405511811,897.2453480721149,0.00025370340306410486,25.0,45.0
700.37866,0.1213136377952756,898.7530727727334,0.00025370340306410486,25.0,45.0
701.98022,0.12170727559055118,899.112777997105,0.00025370340306410486,25.0,45.0
703.58179,0.12214372637795275,899.5455191472563,0.00025370340306410486,25.0,45.0
705.18335,0.12257322047244094,899.9222002895118,0.00025370340306410486,25.0,45.0
706.78491,0.12295770669291338,898.8075536254771,0.00025370340306410486,25.0,45.0
708.38647,0.12333902362204725,900.2647453612318,0.00025370340306410486,25.0,45.0
709.98804,0.12375163188976376,902.6606658770892,0.00025370340306410486,25.0,45.0
711.5896,0.12414190157480315,902.0417423345178,0.00025370340306410486,25.0,45.0
713.19116,0.12452032086614173,902.2660613238585,0.00025370340306410486,25.0,45.0
714.79272,0.12488481299212598,902.557152256876,0.00025370340306410486,25.0,45.0
716.39429,0.12531400196850392,901.4746150809317,0.00025370340306410486,25.0,45.0
717.99585,0.1257299783464567,902.8876167916832,0.00025370340306410486,25.0,45.0
719.59741,0.126128344488189,902.3467035136204,0.00025370340306410486,25.0,45.0
721.19897,0.12657857086614174,902.2344519015661,0.00025370340306410486,25.0,45.0
722.80054,0.1270420905511811,904.3158836689038,0.00025370340306410486,25.0,45.0
724.4021,0.12742463976377952,902.1100407948416,0.00025370340306410486,25.0,45.0
726.00366,0.127803,902.8912225292802,0.00025370340306410486,25.0,45.0
727.60522,0.12818499803149608,904.3315699434137,0.00025370340306410486,25.0,45.0
729.20679,0.1286366909448819,904.0348466903541,0.00025370340306410486,25.0,45.0
730.80835,0.12901562598425195,904.08509014344,0.00025370340306410486,25.0,45.0
732.40991,0.12941041338582676,905.2218976181077,0.00025370340306410486,25.0,45.0
734.01147,0.1298471338582677,905.5177260165812,0.00025370340306410486,25.0,45.0
735.61304,0.1302090807086614,903.3799973680748,0.00025370340306410486,25.0,45.0
737.2146,0.13064155511811024,906.187208843269,0.00025370340306410486,25.0,45.0
738.81616,0.1310105157480315,903.4983550467168,0.00025370340306410486,25.0,45.0
740.41772,0.13139837992125986,905.9731806816687,0.00025370340306410486,25.0,45.0
742.01929,0.13179972637795276,908.466824582182,0.00025370340306410486,25.0,45.0
743.62085,0.13217352362204723,905.0524016317937,0.00025370340306410486,25.0,45.0
745.22241,0.13260983267716533,908.5519147256219,0.00025370340306410486,25.0,45.0
746.82397,0.13305269094488187,907.7800763258324,0.00025370340306410486,25.0,45.0
748.42554,0.13347502755905513,907.6466113962365,0.00025370340306410486,25.0,45.0
750.0271,0.13391015354330707,907.4138702460851,0.00025370340306410486,25.0,45.0
751.62866,0.13425995472440944,907.2907487827347,0.00025370340306410486,25.0,45.0
753.23022,0.13468947244094487,909.7723121463351,0.00025370340306410486,25.0,45.0
754.83179,0.13510292716535433,907.215001973944,0.00025370340306410486,25.0,45.0
756.43335,0.13549028740157482,907.7512041058035,0.00025370340306410486,25.0,45.0
758.03491,0.13594933661417322,910.3848137912884,0.00025370340306410486,25.0,45.0
759.63647,0.13636769488188977,910.0280036846955,0.00025370340306410486,25.0,45.0
761.23804,0.13676596653543308,907.6745624424267,0.00025370340306410486,25.0,45.0
762.8396,0.13713242913385826,907.859665745493,0.00025370340306410486,25.0,45.0
764.44116,0.13752271062992125,910.3907093038558,0.00025370340306410486,25.0,45.0
766.04272,0.13797195078740157,910.1989209106462,0.00025370340306410486,25.0,45.0
767.64429,0.13841168897637796,910.6839847348335,0.00025370340306410486,25.0,45.0
769.24585,0.13882855708661418,908.9105145413871,0.00025370340306410486,25.0,45.0
770.84741,0.13919088976377952,909.4955652059482,0.00025370340306410486,25.0,45.0
772.44897,0.13963095472440945,912.7608632714832,0.00025370340306410486,25.0,45.0
774.05054,0.14004240354330708,910.3015396762733,0.00025370340306410486,25.0,45.0
775.6521,0.14043642716535432,910.641505461245,0.00025370340306410486,25.0,45.0
777.25366,0.14082769488188976,912.3887616791684,0.00025370340306410486,25.0,45.0
778.85522,0.14128749606299212,912.8839847348336,0.00025370340306410486,25.0,45.0
780.45679,0.1417301062992126,911.1796552177918,0.00025370340306410486,25.0,45.0
782.05835,0.14215302952755904,912.9109093301751,0.00025370340306410486,25.0,45.0
783.65991,0.14262786023622048,912.8337939202527,0.00025370340306410486,25.0,45.0
785.26147,0.14305101771653542,912.5245953414924,0.00025370340306410486,25.0,45.0
786.86304,0.1434469901574803,913.1316225819188,0.00025370340306410486,25.0,45.0
788.4646,0.14386191141732282,913.2251875246744,0.00025370340306410486,25.0,45.0
790.06616,0.14428129133858267,913.329464403211,0.00025370340306410486,25.0,45.0
791.66772,0.14466130511811023,914.6913804447955,0.00025370340306410486,25.0,45.0
793.26929,0.14514326968503938,916.0778260297409,0.00025370340306410486,25.0,45.0
794.87085,0.14560984055118112,914.9754441373866,0.00025370340306410486,25.0,45.0
796.47241,0.1459778877952756,913.9731280431636,0.00025370340306410486,25.0,45.0
798.07397,0.14643324212598424,914.1564416370576,0.00025370340306410486,25.0,45.0
799.67554,0.14686737007874015,915.9110146071853,0.00025370340306410486,25.0,45.0
801.2771,0.1473679311023622,915.9563889985526,0.00025370340306410486,25.0,45.0
802.87866,0.14780921653543308,915.7428609027504,0.00025370340306410486,25.0,45.0
804.48022,0.1482235748031496,915.41579155152,0.00025370340306410486,25.0,45.0
806.08179,0.1486451023622047,916.8987498355048,0.00025370340306410486,25.0,45.0
807.68335,0.14909343897637797,916.1053822871431,0.00025370340306410486,25.0,45.0
809.28491,0.149526875984252,914.7957889195948,0.00025370340306410486,25.0,45.0
810.88647,0.149960968503937,915.670430319779,0.00025370340306410486,25.0,45.0
812.48804,0.15032406496062992,916.0637452296355,0.00025370340306410486,25.0,45.0
814.0896,0.1507782086614173,916.7940255296751,0.00025370340306410486,25.0,45.0
815.69116,0.15115874015748032,916.5731806816688,0.00025370340306410486,25.0,45.0
817.29272,0.15160292322834645,918.1900513225426,0.00025370340306410486,25.0,45.0
818.89429,0.1520407007874016,915.6713514936176,0.00025370340306410486,25.0,45.0
820.49585,0.15248340748031494,917.695012501645,0.00025370340306410486,25.0,45.0
822.09741,0.15292444488188978,917.8499276220557,0.00025370340306410486,25.0,45.0
823.69897,0.15333887401574803,919.0628240557969,0.00025370340306410486,25.0,45.0
825.30054,0.15380105708661418,918.5086985129623,0.00025370340306410486,25.0,45.0
826.9021,0.1542532066929134,919.0431635741546,0.00025370340306410486,25.0,45.0
828.50366,0.15471751377952755,918.3990788261615,0.00025370340306410486,25.0,45.0
830.10522,0.1551883661417323,919.8820897486512,0.00025370340306410486,25.0,45.0
831.70679,0.15564666535433072,919.5934728253718,0.00025370340306410486,25.0,45.0
833.30835,0.15609582283464565,919.0609817081196,0.00025370340306410486,25.0,45.0
834.90991,0.1565898622047244,919.5723121463351,0.00025370340306410486,25.0,45.0
836.51147,0.15703086614173228,919.7573101723913,0.00025370340306410486,25.0,45.0
838.11304,0.1574812440944882,919.5129622318727,0.00025370340306410486,25.0,45.0
839.7146,0.15791927952755905,921.1769180155285,0.00025370340306410486,25.0,45.0
841.31616,0.15834309448818898,920.2727200947494,0.00025370340306410486,25.0,45.0
842.91772,0.15881037992125985,920.5315962626662,0.00025370340306410486,25.0,45.0
844.51929,0.1592166437007874,920.7816291617319,0.00025370340306410486,25.0,45.0
846.12085,0.15972392716535433,921.2192656928544,0.00025370340306410486,25.0,45.0
847.72241,0.16022057086614175,919.8510593499145,0.00025370340306410486,25.0,45.0
849.32397,0.16062310039370079,919.7043031977893,0.00025370340306410486,25.0,45.0
850.92554,0.16103784645669292,920.2329253849192,0.00025370340306410486,25.0,45.0
852.5271,0.16147750196850394,920.7332280563232,0.00025370340306410486,25.0,45.0
854.12866,0.16192832480314961,921.480800105277,0.00025370340306410486,25.0,45.0
855.73022,0.1624300846456693,921.5377812870115,0.00025370340306410486,25.0,45.0
857.33179,0.16291075787401574,922.2035530990921,0.00025370340306410486,25.0,45.0
858.93335,0.1633450866141732,921.2995920515858,0.00025370340306410486,25.0,45.0
860.53491,0.1637521811023622,922.1675483616266,0.00025370340306410486,25.0,45.0
862.13647,0.16421484448818896,921.3007500986972,0.00025370340306410486,25.0,45.0
863.73804,0.1646777066929134,923.2821423871562,0.00025370340306410486,25.0,45.0
865.3396,0.16520705118110235,922.8037636531124,0.00025370340306410486,25.0,45.0
866.94116,0.16567507677165355,921.5853928148442,0.00025370340306410486,25.0,45.0
868.54272,0.16614314763779528,922.8435320436901,0.00025370340306410486,25.0,45.0
870.14429,0.16663299803149606,923.2018949861824,0.00025370340306410486,25.0,45.0
871.74585,0.16706530708661418,924.1833399131466,0.00025370340306410486,25.0,45.0
873.34741,0.16757966732283464,925.1579681537046,0.00025370340306410486,25.0,45.0
874.94897,0.16808063976377952,924.0401105408608,0.00025370340306410486,25.0,45.0
876.55054,0.1685549901574803,923.5237531254113,0.00025370340306410486,25.0,45.0
878.1521,0.16903643700787402,925.8530859323596,0.00025370340306410486,25.0,45.0
879.75366,0.16952016141732282,924.2680879063035,0.00025370340306410486,25.0,45.0
881.35522,0.169955781496063,923.8409790761943,0.00025370340306410486,25.0,45.0
882.95679,0.17032388582677166,923.0883537307541,0.00025370340306410486,25.0,45.0
884.55835,0.17076176968503937,925.6534544018951,0.00025370340306410486,25.0,45.0
886.15991,0.17127216338582676,924.8041058033953,0.00025370340306410486,25.0,45.0
887.76147,0.17181498818897636,923.888985392815,0.00025370340306410486,25.0,45.0
889.36304,0.17225091141732285,924.7150414528228,0.00025370340306410486,25.0,45.0
890.9646,0.17271350393700785,923.6773259639427,0.00025370340306410486,25.0,45.0
892.56616,0.17317480708661417,926.0889064350573,0.00025370340306410486,25.0,45.0
894.16772,0.17367613188976377,926.5216739044613,0.00025370340306410486,25.0,45.0
895.76929,0.1741484625984252,924.2097381234374,0.00025370340306410486,25.0,45.0
897.37085,0.17466931102362204,927.5836294249243,0.00025370340306410486,25.0,45.0
898.97241,0.17516083858267717,926.5272535859982,0.00025370340306410486,25.0,45.0
900.57397,0.175691437007874,927.7549940781682,0.00025370340306410486,25.0,45.0
902.17554,0.17623327559055116,927.4909856560074,0.00025370340306410486,25.0,45.0
903.7771,0.1767813464566929,925.5153046453481,0.00025370340306410486,25.0,45.0
905.37866,0.17726964566929135,924.3390972496383,0.00025370340306410486,25.0,45.0
906.98022,0.17771580118110236,925.8347150940914,0.00025370340306410486,25.0,45.0
908.58179,0.17824863976377953,927.2392156862746,0.00025370340306410486,25.0,45.0
910.18335,0.17881060236220472,926.896144229504,0.00025370340306410486,25.0,45.0
911.78491,0.17927084842519686,928.0605342808266,0.00025370340306410486,25.0,45.0
913.38647,0.1797390846456693,924.8017370706673,0.00025370340306410486,25.0,45.0
914.98804,0.1802118031496063,925.9076983813661,0.00025370340306410486,25.0,45.0
916.5896,0.1806494409448819,926.4168180023688,0.00025370340306410486,25.0,45.0
918.19116,0.18116920866141734,928.1400184234768,0.00025370340306410486,25.0,45.0
919.79272,0.1816440059055118,926.2393999210423,0.00025370340306410486,25.0,45.0
921.39429,0.1821876633858268,927.5200157915516,0.00025370340306410486,25.0,45.0
922.99585,0.18275543307086614,925.9787603632058,0.00025370340306410486,25.0,45.0
924.59741,0.18328714566929133,927.6159494670352,0.00025370340306410486,25.0,45.0
926.19897,0.18378229921259842,927.5291485721806,0.00025370340306410486,25.0,45.0
927.80054,0.18424009251968504,927.0904066324517,0.00025370340306410486,25.0,45.0
929.4021,0.1848067716535433,927.9213054349258,0.00025370340306410486,25.0,45.0
931.00366,0.18529820472440944,928.6706408737994,0.00025370340306410486,25.0,45.0
932.60522,0.18577718897637793,927.1182260823794,0.00025370340306410486,25.0,45.0
934.20679,0.1862158346456693,927.9793920252665,0.00025370340306410486,25.0,45.0
935.80835,0.18674536417322835,930.3085932359522,0.00025370340306410486,25.0,45.0
937.40991,0.1873056594488189,928.0200026319254,0.00025370340306410486,25.0,45.0
939.01147,0.18780284251968504,928.834057112778,0.00025370340306410486,25.0,45.0
940.61304,0.18834993897637797,927.3102776681143,0.00025370340306410486,25.0,45.0
942.2146,0.18886414566929133,929.046295565206,0.00025370340306410486,25.0,45.0
943.81616,0.18937158267716536,928.5356494275563,0.00025370340306410486,25.0,45.0
945.41772,0.1898983562992126,929.1791814712462,0.00025370340306410486,25.0,45.0
947.01929,0.190434,929.0529016975918,0.00025370340306410486,25.0,45.0
948.62085,0.19096581889763778,927.7585998157653,0.00025370340306410486,25.0,45.0
950.22241,0.19150632086614175,928.5788393209633,0.00025370340306410486,25.0,45.0
951.82397,0.19204138976377952,928.7387024608502,0.00025370340306410486,25.0,45.0
953.42554,0.19260732874015749,928.6748782734571,0.00025370340306410486,25.0,45.0
955.0271,0.19319962007874014,930.0955915252008,0.00025370340306410486,25.0,45.0
956.62866,0.19377000590551183,928.0890117120674,0.00025370340306410486,25.0,45.0
958.23022,0.1942888720472441,927.4165021713384,0.00025370340306410486,25.0,45.0
959.83179,0.1948366023622047,928.9100144755889,0.00025370340306410486,25.0,45.0
961.43335,0.19536732874015747,929.854191340966,0.00025370340306410486,25.0,45.0
963.03491,0.1958580118110236,928.4388208974866,0.00025370340306410486,25.0,45.0
964.63647,0.19643493307086615,930.3097512830636,0.00025370340306410486,25.0,45.0
966.23804,0.19703824803149608,930.0915383603107,0.00025370340306410486,25.0,45.0
967.8396,0.19761198818897638,927.5616002105542,0.00025370340306410486,25.0,45.0
969.44116,0.19813372047244093,929.6497697065404,0.00025370340306410486,25.0,45.0
971.04272,0.19863458661417321,929.000789577576,0.00025370340306410486,25.0,45.0
972.64429,0.19922988188976376,931.9394920384262,0.00025370340306410486,25.0,45.0
974.24585,0.19980257874015747,931.5156467956311,0.00025370340306410486,25.0,45.0
975.84741,0.20038531496062992,930.2370048690618,0.00025370340306410486,25.0,45.0
977.44897,0.20087803149606298,928.8062903013555,0.00025370340306410486,25.0,45.0
979.05054,0.20140976377952755,929.7911567311489,0.00025370340306410486,25.0,45.0
980.6521,0.2019858464566929,931.6730096065272,0.00025370340306410486,25.0,45.0
982.25366,0.20265287401574802,930.463718910383,0.00025370340306410486,25.0,45.0
983.85522,0.20320527559055115,929.4725621792342,0.00025370340306410486,25.0,45.0
985.45679,0.20375267716535433,928.9553099091987,0.00025370340306410486,25.0,45.0
987.05835,0.2042884251968504,929.0103171469931,0.00025370340306410486,25.0,45.0
988.65991,0.20489017716535435,931.3451243584683,0.00025370340306410486,25.0,45.0
990.26147,0.20540868110236218,929.6393209632847,0.00025370340306410486,25.0,45.0
991.86304,0.20602482283464565,931.478378734044,0.00025370340306410486,25.0,45.0
993.4646,0.2065141535433071,929.0265561258061,0.00025370340306410486,25.0,45.0
995.06616,0.2070654527559055,931.8507435188841,0.00025370340306410486,25.0,45.0
996.66772,0.20760818897637798,930.6226871956837,0.00025370340306410486,25.0,45.0
998.26929,0.2082099409448819,930.2451111988421,0.00025370340306410486,25.0,45.0
999.87085,0.2088327559055118,929.5283326753522,0.00025370340306410486,25.0,45.0
1001.4724,0.20944096456692915,930.7948151072511,0.00025370340306410486,25.0,45.0
1003.074,0.21005799212598422,931.6020002631926,0.00025370340306410486,25.0,45.0
1004.6755,0.21065259842519685,929.7781550203975,0.00025370340306410486,25.0,45.0
1006.2771,0.21122891732283464,929.2480589551258,0.00025370340306410486,25.0,45.0
1007.8787,0.2118398031496063,929.3926306092908,0.00025370340306410486,25.0,45.0
1009.4802,0.21251468503937007,930.8692196341624,0.00025370340306410486,25.0,45.0
1011.0818,0.2131564960629921,931.1268324779578,0.00025370340306410486,25.0,45.0
1012.6833,0.2137956496062992,929.9165679694697,0.00025370340306410486,25.0,45.0
1014.2849,0.21432940944881887,929.2358994604555,0.00025370340306410486,25.0,45.0
1015.8865,0.21489895669291337,933.2122647716806,0.00025370340306410486,25.0,45.0