File: datasets/am_bench_2022/csv/45-XY.13-2.csv
Time(s),Strain(%),Stress(MPa),SR(s-1),Temp(C),Angle(deg)
36.217529,5.004621062992126e-06,17.328422542526944,0.00025370340306410486,25.0,45.0
38.719971,2.903278346456693e-06,25.60714686404363,0.00025370340306410486,25.0,45.0
40.221436,1.770221437007874e-05,30.579181924425402,0.00025370340306410486,25.0,45.0
41.7229,2.283336220472441e-05,35.5598389819504,0.00025370340306410486,25.0,45.0
43.224365,4.829590551181102e-05,39.906806908193744,0.00025370340306410486,25.0,45.0
44.72583,7.517030118110237e-05,46.34432930788209,0.00025370340306410486,25.0,45.0
46.227295,8.25889251968504e-05,51.87834047526296,0.00025370340306410486,25.0,45.0
47.72876,9.714324606299213e-05,61.312034800675235,0.00025370340306410486,25.0,45.0
49.230225,0.00013161291732283464,68.9318036618621,0.00025370340306410486,25.0,45.0
50.731689,0.00015250836811023623,76.42337878197637,0.00025370340306410486,25.0,45.0
52.233154,0.00017605288582677164,85.37212569796131,0.00025370340306410486,25.0,45.0
53.734619,0.00019319656692913384,92.72463056745877,0.00025370340306410486,25.0,45.0
55.236084,0.00021240992125984252,101.61935073367096,0.00025370340306410486,25.0,45.0
56.737549,0.00023683854330708661,108.06936501753019,0.00025370340306410486,25.0,45.0
58.239014,0.00027752675196850396,116.57246331645241,0.00025370340306410486,25.0,45.0
59.740479,0.00030685155511811025,125.74734709777951,0.00025370340306410486,25.0,45.0
61.241943,0.00032689517716535433,136.0647292559408,0.00025370340306410486,25.0,45.0
62.743408,0.0003547994881889764,143.31498506687444,0.00025370340306410486,25.0,45.0
64.244873,0.00036892627952755903,154.58850538891053,0.00025370340306410486,25.0,45.0
65.746338,0.0004185893503937008,163.44002337358788,0.00025370340306410486,25.0,45.0
67.247803,0.0004675407480314961,174.85961303726788,0.00025370340306410486,25.0,45.0
68.749268,0.00047239417322834644,184.47159070250618,0.00025370340306410486,25.0,45.0
70.250732,0.0005100431102362205,195.393437215946,0.00025370340306410486,25.0,45.0
71.752197,0.0005499762795275591,205.44961433580056,0.00025370340306410486,25.0,45.0
73.253662,0.0005936851968503937,215.96839371510197,0.00025370340306410486,25.0,45.0
74.755127,0.0006105094488188976,226.28649785742112,0.00025370340306410486,25.0,45.0
76.256592,0.0006503280708661418,240.3748318400208,0.00025370340306410486,25.0,45.0
77.758057,0.0007079244094488189,251.26725879755878,0.00025370340306410486,25.0,45.0
79.259521,0.0007348631496062992,262.0481495909622,0.00025370340306410486,25.0,45.0
80.760986,0.0007555553346456693,272.6069081937411,0.00025370340306410486,25.0,45.0
82.262451,0.0007914033661417323,282.4134527983379,0.00025370340306410486,25.0,45.0
83.763916,0.0008264040354330708,294.7953772237372,0.00025370340306410486,25.0,45.0
85.265381,0.0008555013582677164,303.8682249058564,0.00025370340306410486,25.0,45.0
86.766846,0.0008966628937007874,315.34574730554476,0.00025370340306410486,25.0,45.0
88.268311,0.0009493280905511811,328.15701856901705,0.00025370340306410486,25.0,45.0
89.769775,0.0009828986023622047,337.14847422412674,0.00025370340306410486,25.0,45.0
91.27124,0.0010271005708661417,349.9882093234645,0.00025370340306410486,25.0,45.0
92.772705,0.0010424169881889764,361.2408778080769,0.00025370340306410486,25.0,45.0
94.27417,0.0011029261811023622,371.3127126347228,0.00025370340306410486,25.0,45.0
95.775635,0.0011356373228346456,382.78714452668487,0.00025370340306410486,25.0,45.0
97.2771,0.0011438579921259843,392.1443968315803,0.00025370340306410486,25.0,45.0
98.778564,0.0011955560236220472,402.8794182573692,0.00025370340306410486,25.0,45.0
100.28003,0.001219569842519685,414.7919490975198,0.00025370340306410486,25.0,45.0
101.78149,0.0012818834842519685,425.46380989481884,0.00025370340306410486,25.0,45.0
103.28296,0.0012999670078740156,435.2053759252045,0.00025370340306410486,25.0,45.0
104.78442,0.00133873531496063,443.1451240098689,0.00025370340306410486,25.0,45.0
106.28589,0.0013844835236220471,454.6979093624205,0.00025370340306410486,25.0,45.0
107.78735,0.0014084394094488189,466.38249577976893,0.00025370340306410486,25.0,45.0
109.28882,0.0014445207283464566,475.3331515387612,0.00025370340306410486,25.0,45.0
110.79028,0.001489294527559055,488.2442280223348,0.00025370340306410486,25.0,45.0
112.29175,0.0015300550984251968,497.3039085833009,0.00025370340306410486,25.0,45.0
113.79321,0.0015588363582677164,503.7047396442021,0.00025370340306410486,25.0,45.0
115.29468,0.0015786009251968502,513.8008310609013,0.00025370340306410486,25.0,45.0
116.79614,0.0016145960039370079,521.6625113621608,0.00025370340306410486,25.0,45.0
118.29761,0.0016374441929133856,531.2545643422933,0.00025370340306410486,25.0,45.0
119.79907,0.0016734990354330707,538.9143228152187,0.00025370340306410486,25.0,45.0
121.30054,0.0016966909842519684,546.0535255161667,0.00025370340306410486,25.0,45.0
122.802,0.0017409970078740157,556.3466822490586,0.00025370340306410486,25.0,45.0
124.30347,0.0017603888582677165,564.136475782366,0.00025370340306410486,25.0,45.0
125.80493,0.001781751161417323,569.4243345020128,0.00025370340306410486,25.0,45.0
127.3064,0.0018080382874015749,576.0326970523308,0.00025370340306410486,25.0,45.0
128.80786,0.001852215807086614,581.7222698350864,0.00025370340306410486,25.0,45.0
130.30933,0.0018559596062992128,586.5712245162966,0.00025370340306410486,25.0,45.0
131.81079,0.0018858501181102361,593.7938189845474,0.00025370340306410486,25.0,45.0
133.31226,0.0019115368307086613,598.9572003635892,0.00025370340306410486,25.0,45.0
134.81372,0.0019223225787401575,604.1559537722374,0.00025370340306410486,25.0,45.0
136.31519,0.0019746877952755908,612.0172704843528,0.00025370340306410486,25.0,45.0
137.81665,0.001978863976377953,614.8828463835866,0.00025370340306410486,25.0,45.0
139.31812,0.0020146458661417324,620.8153486560187,0.00025370340306410486,25.0,45.0
140.81958,0.002036199409448819,626.4486170627192,0.00025370340306410486,25.0,45.0
142.32104,0.0020738273622047244,630.2363589144268,0.00025370340306410486,25.0,45.0
143.82251,0.002086018897637795,634.9513309959746,0.00025370340306410486,25.0,45.0
145.32397,0.002111432283464567,640.4578106739385,0.00025370340306410486,25.0,45.0
146.82544,0.002157862992125984,646.7381119335151,0.00025370340306410486,25.0,45.0
148.3269,0.002178286417322835,649.1194909751981,0.00025370340306410486,25.0,45.0
149.82837,0.0022212799212598428,655.7549928580704,0.00025370340306410486,25.0,45.0
151.32983,0.002246537007874016,658.9777431502403,0.00025370340306410486,25.0,45.0
152.8313,0.002274207480314961,660.9533047656149,0.00025370340306410486,25.0,45.0
154.33276,0.002292428149606299,664.8673678743021,0.00025370340306410486,25.0,45.0
155.83423,0.0023386740157480316,669.1573302168549,0.00025370340306410486,25.0,45.0
157.33569,0.0023903616141732285,673.2084144916245,0.00025370340306410486,25.0,45.0
158.83716,0.0024063864173228347,677.9917413322945,0.00025370340306410486,25.0,45.0
160.33862,0.002448196653543307,679.5400857031555,0.00025370340306410486,25.0,45.0
161.84009,0.002496948031496063,684.1678223607323,0.00025370340306410486,25.0,45.0
163.34155,0.0025328253937007875,686.2202311388132,0.00025370340306410486,25.0,45.0
164.84302,0.002576133464566929,689.9471756914686,0.00025370340306410486,25.0,45.0
166.34448,0.0026113283464566928,693.5940267497728,0.00025370340306410486,25.0,45.0
167.84595,0.002667050590551181,695.3968315803143,0.00025370340306410486,25.0,45.0
169.34741,0.0027352897637795276,698.4529541617972,0.00025370340306410486,25.0,45.0
170.84888,0.002793631496062992,701.7696662771069,0.00025370340306410486,25.0,45.0
172.35034,0.002851879527559055,706.0390858330088,0.00025370340306410486,25.0,45.0
173.85181,0.002917637598425197,707.5577717179588,0.00025370340306410486,25.0,45.0
175.35327,0.0029816840551181102,710.5902350344112,0.00025370340306410486,25.0,45.0
176.85474,0.0030379620078740156,714.3614335800546,0.00025370340306410486,25.0,45.0
178.3562,0.003110319291338583,715.7842358135307,0.00025370340306410486,25.0,45.0
179.85767,0.003195039960629921,718.5061420594728,0.00025370340306410486,25.0,45.0
181.35913,0.0032990700787401575,722.0847941825737,0.00025370340306410486,25.0,45.0
182.8606,0.0034107100393700783,725.1993507336709,0.00025370340306410486,25.0,45.0
184.36206,0.0035248604330708664,730.4377353590443,0.00025370340306410486,25.0,45.0
185.86353,0.003639148031496063,732.9086352421764,0.00025370340306410486,25.0,45.0
187.36499,0.0037398710629921255,733.1072847682119,0.00025370340306410486,25.0,45.0
188.86646,0.003872865354330709,738.4064147513311,0.00025370340306410486,25.0,45.0
190.36792,0.003996510826771654,737.8073496948449,0.00025370340306410486,25.0,45.0
191.86938,0.004144187401574803,740.5189455914816,0.00025370340306410486,25.0,45.0
193.37085,0.004275151181102362,742.7228931307623,0.00025370340306410486,25.0,45.0
194.87231,0.00445924625984252,744.6527983378783,0.00025370340306410486,25.0,45.0
196.37378,0.004653782283464567,749.3460329827296,0.00025370340306410486,25.0,45.0
197.87524,0.004798632283464567,746.0020776522531,0.00025370340306410486,25.0,45.0
199.37671,0.0049547039370078745,747.5922088040514,0.00025370340306410486,25.0,45.0
200.87817,0.00513537874015748,752.1274899363718,0.00025370340306410486,25.0,45.0
202.37964,0.005355325196850394,754.7439553304765,0.00025370340306410486,25.0,45.0
203.8811,0.0055233039370078734,755.0740423321647,0.00025370340306410486,25.0,45.0
205.38257,0.0057800584645669294,758.3123750162317,0.00025370340306410486,25.0,45.0
206.88403,0.006004190354330708,759.8505129204,0.00025370340306410486,25.0,45.0
208.3855,0.006250317716535433,761.7852746396571,0.00025370340306410486,25.0,45.0
209.88696,0.006486982874015748,763.1680560966108,0.00025370340306410486,25.0,45.0
211.38843,0.006791412401574803,763.9120633683938,0.00025370340306410486,25.0,45.0
212.88989,0.007052671850393701,766.0940657057525,0.00025370340306410486,25.0,45.0
214.39136,0.007306924409448818,768.9952213998182,0.00025370340306410486,25.0,45.0
215.89282,0.007531485433070867,767.1212310089599,0.00025370340306410486,25.0,45.0
217.39429,0.007806212401574803,770.8088559927282,0.00025370340306410486,25.0,45.0
218.89575,0.00812017657480315,772.7621867289962,0.00025370340306410486,25.0,45.0
220.39722,0.008416797637795275,773.066069341644,0.00025370340306410486,25.0,45.0
221.89868,0.008749138385826772,775.073289183223,0.00025370340306410486,25.0,45.0
223.40015,0.009051299803149606,774.2313985196728,0.00025370340306410486,25.0,45.0
224.90161,0.009334761220472441,776.1984677314634,0.00025370340306410486,25.0,45.0
226.40308,0.009625658858267716,777.2320997273082,0.00025370340306410486,25.0,45.0
227.90454,0.009922340748031496,778.8028308011947,0.00025370340306410486,25.0,45.0
229.40601,0.010271194488188976,781.523022984028,0.00025370340306410486,25.0,45.0
230.90747,0.010699468503937009,781.889624724062,0.00025370340306410486,25.0,45.0
232.40894,0.01101781220472441,781.4756005713544,0.00025370340306410486,25.0,45.0
233.9104,0.01132845590551181,785.1974548759902,0.00025370340306410486,25.0,45.0
235.41187,0.011643136023622047,783.5643422932087,0.00025370340306410486,25.0,45.0
236.91333,0.011903108464566929,784.627580833658,0.00025370340306410486,25.0,45.0
238.41479,0.01218755846456693,785.97930138943,0.00025370340306410486,25.0,45.0
239.91626,0.012552088385826771,788.0781976366707,0.00025370340306410486,25.0,45.0
241.41772,0.012865377952755906,788.2881963381379,0.00025370340306410486,25.0,45.0
242.91919,0.01320290688976378,790.5000908972861,0.00025370340306410486,25.0,45.0
244.42065,0.01356569153543307,789.7006622516557,0.00025370340306410486,25.0,45.0
245.92212,0.01389075255905512,789.7142968445656,0.00025370340306410486,25.0,45.0
247.42358,0.014203267716535432,790.9544994156603,0.00025370340306410486,25.0,45.0
248.92505,0.014515756496062992,794.786832878847,0.00025370340306410486,25.0,45.0
250.42651,0.014901530708661416,793.6213738475524,0.00025370340306410486,25.0,45.0
251.92798,0.015302027362204726,796.0202311388132,0.00025370340306410486,25.0,45.0
253.42944,0.015716081692913386,796.6654979872744,0.00025370340306410486,25.0,45.0
254.93091,0.01607477283464567,796.6489546812103,0.00025370340306410486,25.0,45.0
256.43237,0.016412823818897637,798.392598363849,0.00025370340306410486,25.0,45.0
257.93384,0.016745769488188976,799.4798597584729,0.00025370340306410486,25.0,45.0
259.4353,0.017051851968503937,798.7108946890014,0.00025370340306410486,25.0,45.0
260.93677,0.017417800196850394,799.1046357615895,0.00025370340306410486,25.0,45.0
262.43823,0.017812642716535435,802.4364887676926,0.00025370340306410486,25.0,45.0
263.9397,0.018194892716535432,802.8994156603038,0.00025370340306410486,25.0,45.0
265.44116,0.01856029527559055,801.1375146084924,0.00025370340306410486,25.0,45.0
266.94263,0.01887887657480315,803.6796779639009,0.00025370340306410486,25.0,45.0
268.44409,0.019192550393700786,801.8404363069732,0.00025370340306410486,25.0,45.0
269.94556,0.019548356692913386,805.4373977405531,0.00025370340306410486,25.0,45.0
271.44702,0.019980435039370078,806.167744448773,0.00025370340306410486,25.0,45.0
272.94849,0.02033555708661417,805.6399168939099,0.00025370340306410486,25.0,45.0
274.44995,0.02068259842519685,807.306635501883,0.00025370340306410486,25.0,45.0
275.95142,0.020974108267716535,805.1958187248409,0.00025370340306410486,25.0,45.0
277.45288,0.021333641732283463,807.9921049214388,0.00025370340306410486,25.0,45.0
278.95435,0.021706720472440946,808.1004025451241,0.00025370340306410486,25.0,45.0
280.45581,0.022048580708661416,809.5916114790288,0.00025370340306410486,25.0,45.0
281.95728,0.022388356299212597,809.5729126087521,0.00025370340306410486,25.0,45.0
283.45874,0.02274082874015748,811.3940786910791,0.00025370340306410486,25.0,45.0
284.96021,0.023120718503937005,812.9276717309441,0.00025370340306410486,25.0,45.0
286.46167,0.023471206692913384,812.6100766134269,0.00025370340306410486,25.0,45.0
287.96313,0.023859484251968502,812.9863913777432,0.00025370340306410486,25.0,45.0
289.4646,0.024280125984251968,814.2892871055708,0.00025370340306410486,25.0,45.0
290.96606,0.024628982283464565,814.9648097649656,0.00025370340306410486,25.0,45.0
292.46753,0.02501152559055118,815.4254512400987,0.00025370340306410486,25.0,45.0
293.96899,0.025360722440944884,816.583794312427,0.00025370340306410486,25.0,45.0
295.47046,0.025728291338582676,816.526710816777,0.00025370340306410486,25.0,45.0
296.97192,0.026103937007874015,818.2394234514999,0.00025370340306410486,25.0,45.0
298.47339,0.02648232874015748,817.444253992988,0.00025370340306410486,25.0,45.0
299.97485,0.026836647637795277,818.8674977275679,0.00025370340306410486,25.0,45.0
301.47632,0.027217395669291336,818.7570445396701,0.00025370340306410486,25.0,45.0
302.97778,0.02759387992125984,819.8749513050253,0.00025370340306410486,25.0,45.0
304.47925,0.02788682874015748,820.5365017530191,0.00025370340306410486,25.0,45.0
305.98071,0.028204466535433067,820.2347747045839,0.00025370340306410486,25.0,45.0
307.48218,0.02847275787401575,818.3692767173095,0.00025370340306410486,25.0,45.0
308.98364,0.02881434645669291,821.8196857550969,0.00025370340306410486,25.0,45.0
310.48511,0.029147100393700786,821.8443059342943,0.00025370340306410486,25.0,45.0
311.98657,0.029515515748031497,825.4382288014544,0.00025370340306410486,25.0,45.0
313.48804,0.029900405511811022,825.2590312946371,0.00025370340306410486,25.0,45.0
314.9895,0.03026667913385827,824.4817556161538,0.00025370340306410486,25.0,45.0
316.49097,0.03064436614173228,823.9850928450852,0.00025370340306410486,25.0,45.0
317.99243,0.030970655511811024,825.400311647838,0.00025370340306410486,25.0,45.0
319.4939,0.03133800196850394,826.6288274250097,0.00025370340306410486,25.0,45.0
320.99536,0.03172338188976378,827.2323854044929,0.00025370340306410486,25.0,45.0
322.49683,0.03207560039370079,828.2632904817557,0.00025370340306410486,25.0,45.0
323.99829,0.032453673228346455,829.7461888066485,0.00025370340306410486,25.0,45.0
325.49976,0.032813503937007875,829.6157122451631,0.00025370340306410486,25.0,45.0
327.00122,0.03317904921259843,828.7158810544086,0.00025370340306410486,25.0,45.0
328.50269,0.03347894094488189,828.6073756654981,0.00025370340306410486,25.0,45.0
330.00415,0.03380724409448819,830.4972860667447,0.00025370340306410486,25.0,45.0
331.50562,0.03414644488188977,831.2535255161667,0.00025370340306410486,25.0,45.0
333.00708,0.034523872047244095,832.3639267627581,0.00025370340306410486,25.0,45.0
334.50854,0.03492759645669291,832.3523957927542,0.00025370340306410486,25.0,45.0
336.01001,0.03527903937007874,832.4154785092845,0.00025370340306410486,25.0,45.0
337.51147,0.035586035433070866,833.4571094663031,0.00025370340306410486,25.0,45.0
339.01294,0.03596377559055118,833.8476821192054,0.00025370340306410486,25.0,45.0
340.5144,0.03631652559055118,833.8148811842619,0.00025370340306410486,25.0,45.0
342.01587,0.036696001968503936,836.0008310609013,0.00025370340306410486,25.0,45.0
343.51733,0.037050454724409446,835.0088819633814,0.00025370340306410486,25.0,45.0
345.0188,0.03739262795275591,836.8764576029088,0.00025370340306410486,25.0,45.0
346.52026,0.037780547244094485,838.1448902739904,0.00025370340306410486,25.0,45.0
348.02173,0.03814505511811024,837.7482145175951,0.00025370340306410486,25.0,45.0
349.52319,0.03851830118110236,839.3689131281651,0.00025370340306410486,25.0,45.0
351.02466,0.03886280905511811,839.7960005194132,0.00025370340306410486,25.0,45.0
352.52612,0.03919085826771653,838.2257109466303,0.00025370340306410486,25.0,45.0
354.02759,0.03948595078740157,839.2832619140371,0.00025370340306410486,25.0,45.0
355.52905,0.03985562598425197,840.8121282950266,0.00025370340306410486,25.0,45.0
357.03052,0.04026882086614173,842.0550577847033,0.00025370340306410486,25.0,45.0
358.53198,0.04064587598425197,841.2503830671341,0.00025370340306410486,25.0,45.0
360.03345,0.04101055118110236,841.7512790546683,0.00025370340306410486,25.0,45.0
361.53491,0.041368017716535435,842.3691728346969,0.00025370340306410486,25.0,45.0
363.03638,0.041650344488188974,842.7414881184262,0.00025370340306410486,25.0,45.0
364.53784,0.0419966811023622,844.1410725879757,0.00025370340306410486,25.0,45.0
366.03931,0.04230395275590551,843.9568887157512,0.00025370340306410486,25.0,45.0
367.54077,0.04269752952755906,845.2617582132192,0.00025370340306410486,25.0,45.0
369.04224,0.04299246456692913,843.0658096351124,0.00025370340306410486,25.0,45.0
370.5437,0.04330067716535433,845.4505908323595,0.00025370340306410486,25.0,45.0
372.04517,0.0436780905511811,848.4699909102715,0.00025370340306410486,25.0,45.0
373.54663,0.04405363976377953,848.4925074665628,0.00025370340306410486,25.0,45.0
375.0481,0.04440840748031496,847.6408518374237,0.00025370340306410486,25.0,45.0
376.54956,0.044774167322834645,848.2998052201013,0.00025370340306410486,25.0,45.0
378.05103,0.045162690944881886,849.4099727308143,0.00025370340306410486,25.0,45.0
379.55249,0.04548933464566929,845.6927931437476,0.00025370340306410486,25.0,45.0
381.05396,0.04579750787401575,848.1224776003116,0.00025370340306410486,25.0,45.0
382.55542,0.04612748818897638,849.5235943383976,0.00025370340306410486,25.0,45.0
384.05688,0.04642859448818898,850.9346058953383,0.00025370340306410486,25.0,45.0
385.55835,0.04678889173228346,851.5531229710427,0.00025370340306410486,25.0,45.0
387.05981,0.047138761811023625,851.4347487339307,0.00025370340306410486,25.0,45.0
388.56128,0.047492824803149605,852.945617452279,0.00025370340306410486,25.0,45.0
390.06274,0.04789162795275591,853.2647188676796,0.00025370340306410486,25.0,45.0
391.56421,0.048277444881889765,853.139514348786,0.00025370340306410486,25.0,45.0
393.06567,0.04862343307086614,853.661264770809,0.00025370340306410486,25.0,45.0
394.56714,0.048938033464566925,854.3152317880796,0.00025370340306410486,25.0,45.0
396.0686,0.04931665944881889,855.0360212959357,0.00025370340306410486,25.0,45.0
397.57007,0.049696769685039374,854.1073886508245,0.00025370340306410486,25.0,45.0
399.07153,0.05005651377952756,854.2809764965589,0.00025370340306410486,25.0,45.0
400.573,0.05038195866141732,854.9047656148553,0.00025370340306410486,25.0,45.0
402.07446,0.05073384842519685,856.4649006622517,0.00025370340306410486,25.0,45.0
403.57593,0.051039773622047244,856.0292429554604,0.00025370340306410486,25.0,45.0
405.07739,0.05139887992125984,858.0301259576678,0.00025370340306410486,25.0,45.0
406.57886,0.05177971653543307,859.3791975068174,0.00025370340306410486,25.0,45.0
408.08032,0.05211185433070866,859.935177249708,0.00025370340306410486,25.0,45.0
409.58179,0.05246218307086615,858.7807817166603,0.00025370340306410486,25.0,45.0
411.08325,0.05275833070866142,859.553486560187,0.00025370340306410486,25.0,45.0
412.58472,0.05317297440944881,859.4555252564603,0.00025370340306410486,25.0,45.0
414.08618,0.05349247047244095,860.1258537852227,0.00025370340306410486,25.0,45.0
415.58765,0.05388785039370079,861.0186469289703,0.00025370340306410486,25.0,45.0
417.08911,0.05423502362204725,861.325723931957,0.00025370340306410486,25.0,45.0
418.59058,0.054551667322834646,860.954603298273,0.00025370340306410486,25.0,45.0
420.09204,0.05488177952755906,863.3946760161019,0.00025370340306410486,25.0,45.0
421.59351,0.05519393700787401,863.4380470068822,0.00025370340306410486,25.0,45.0
423.09497,0.055501364173228346,863.0465913517725,0.00025370340306410486,25.0,45.0
424.59644,0.05579048228346457,861.164861706272,0.00025370340306410486,25.0,45.0
426.0979,0.056144271653543305,864.6908713154137,0.00025370340306410486,25.0,45.0
427.59937,0.056516244094488195,864.0467471756915,0.00025370340306410486,25.0,45.0
429.10083,0.056862173228346455,866.3875860277886,0.00025370340306410486,25.0,45.0
430.60229,0.057203722440944876,864.9552006232958,0.00025370340306410486,25.0,45.0
432.10376,0.05762205118110237,866.6963770938839,0.00025370340306410486,25.0,45.0
433.60522,0.05800512204724409,865.9843396961434,0.00025370340306410486,25.0,45.0
435.10669,0.05836243897637795,867.3958446954941,0.00025370340306410486,25.0,45.0
436.60815,0.05869211220472441,867.4678872873653,0.00025370340306410486,25.0,45.0
438.10962,0.05900655708661417,868.2958057395144,0.00025370340306410486,25.0,45.0
439.61108,0.0593730905511811,869.7620568757304,0.00025370340306410486,25.0,45.0
441.11255,0.05975941732283464,867.8458901441372,0.00025370340306410486,25.0,45.0
442.61401,0.060111265748031495,869.9085833008701,0.00025370340306410486,25.0,45.0
444.11548,0.06047193307086614,869.2646409557201,0.00025370340306410486,25.0,45.0
445.61694,0.06081596850393701,868.9253603428126,0.00025370340306410486,25.0,45.0
447.11841,0.06118342913385827,869.8621737436697,0.00025370340306410486,25.0,45.0
448.61987,0.061534515748031496,871.351876379691,0.00025370340306410486,25.0,45.0
450.12134,0.061850860236220474,871.8594987663939,0.00025370340306410486,25.0,45.0
451.6228,0.06216430118110236,870.70455784963,0.00025370340306410486,25.0,45.0
453.12427,0.06250337795275591,872.9608362550318,0.00025370340306410486,25.0,45.0
454.62573,0.06276070472440945,870.8747435398001,0.00025370340306410486,25.0,45.0
456.1272,0.0630908779527559,873.011063498247,0.00025370340306410486,25.0,45.0
457.62866,0.06343944685039371,873.7933515127905,0.00025370340306410486,25.0,45.0
459.13013,0.0637533031496063,872.6131930918064,0.00025370340306410486,25.0,45.0
460.63159,0.06414760433070867,876.6665368134009,0.00025370340306410486,25.0,45.0
462.13306,0.06451292322834645,874.2986884820153,0.00025370340306410486,25.0,45.0
463.63452,0.06488993503937007,874.5025840799897,0.00025370340306410486,25.0,45.0
465.13599,0.0652207342519685,874.3947279574082,0.00025370340306410486,25.0,45.0
466.63745,0.06555120472440945,876.2924555252565,0.00025370340306410486,25.0,45.0
468.13892,0.06591646653543307,876.1228931307622,0.00025370340306410486,25.0,45.0
469.64038,0.06629122440944882,877.5370731073887,0.00025370340306410486,25.0,45.0
471.14185,0.06661379330708661,877.0071419296196,0.00025370340306410486,25.0,45.0
472.64331,0.0669584625984252,879.6028827425009,0.00025370340306410486,25.0,45.0
474.14478,0.0673395905511811,878.2950266199196,0.00025370340306410486,25.0,45.0
475.64624,0.06773297047244094,878.9950915465524,0.00025370340306410486,25.0,45.0
477.14771,0.06812446653543307,880.6441760810285,0.00025370340306410486,25.0,45.0
478.64917,0.06841636417322834,878.506661472536,0.00025370340306410486,25.0,45.0
480.15063,0.06874799803149606,879.4101285547332,0.00025370340306410486,25.0,45.0
481.6521,0.0690383405511811,878.9997662641216,0.00025370340306410486,25.0,45.0
483.15356,0.06940763188976377,880.2715491494612,0.00025370340306410486,25.0,45.0
484.65503,0.06977790748031497,880.6430333722894,0.00025370340306410486,25.0,45.0
486.15649,0.07013509055118111,879.9357486040774,0.00025370340306410486,25.0,45.0
487.65796,0.07043316535433071,880.2071938709258,0.00025370340306410486,25.0,45.0
489.15942,0.07084691929133857,884.6360992078951,0.00025370340306410486,25.0,45.0
490.66089,0.07118051771653543,882.0491624464356,0.00025370340306410486,25.0,45.0
492.16235,0.07153759448818897,883.5965718737826,0.00025370340306410486,25.0,45.0
493.66382,0.0718765905511811,882.5945201921828,0.00025370340306410486,25.0,45.0
495.16528,0.07226366732283465,885.5854564342294,0.00025370340306410486,25.0,45.0
496.66675,0.07270249015748032,884.6675496688742,0.00025370340306410486,25.0,45.0
498.16821,0.07304173818897637,884.0261264770809,0.00025370340306410486,25.0,45.0
499.66968,0.07336811417322835,883.6890793403454,0.00025370340306410486,25.0,45.0
501.17114,0.07373460039370079,886.0218672899624,0.00025370340306410486,25.0,45.0
502.67261,0.07406306496062992,885.1593039864953,0.00025370340306410486,25.0,45.0
504.17407,0.07445842716535432,887.3466562784055,0.00025370340306410486,25.0,45.0
505.67554,0.07485130708661418,886.0836255031813,0.00025370340306410486,25.0,45.0
507.177,0.07517461614173228,885.9240358395015,0.00025370340306410486,25.0,45.0
508.67847,0.0755113405511811,887.561667315933,0.00025370340306410486,25.0,45.0
510.17993,0.07585354527559054,888.502324373458,0.00025370340306410486,25.0,45.0
511.6814,0.07622905511811023,889.4379950655759,0.00025370340306410486,25.0,45.0
513.18286,0.07655370078740158,888.2492922997013,0.00025370340306410486,25.0,45.0
514.68433,0.07686737598425197,888.2246721205039,0.00025370340306410486,25.0,45.0
516.18579,0.07728208070866141,891.1106869237761,0.00025370340306410486,25.0,45.0
517.68726,0.07766694094488188,890.1247370471367,0.00025370340306410486,25.0,45.0
519.18872,0.07802406496062993,889.3702895727828,0.00025370340306410486,25.0,45.0
520.69019,0.07834601771653543,889.0504090377873,0.00025370340306410486,25.0,45.0
522.19165,0.07864139370078739,889.4039475392806,0.00025370340306410486,25.0,45.0
523.69312,0.07896430905511811,891.4798337878198,0.00025370340306410486,25.0,45.0
525.19458,0.07934373228346457,892.8933125568109,0.00025370340306410486,25.0,45.0
526.69604,0.07969652559055118,891.3336709518245,0.00025370340306410486,25.0,45.0
528.19751,0.080023781496063,890.6711076483574,0.00025370340306410486,25.0,45.0
529.69897,0.08032966732283464,892.4704064407221,0.00025370340306410486,25.0,45.0
531.20044,0.08068355118110236,893.2228282041293,0.00025370340306410486,25.0,45.0
532.7019,0.08103462007874015,892.2091156992599,0.00025370340306410486,25.0,45.0
534.20337,0.08146818503937009,894.1323724191664,0.00025370340306410486,25.0,45.0
535.70483,0.08185382086614174,894.0858330087002,0.00025370340306410486,25.0,45.0
537.2063,0.08223708661417323,894.5444487728868,0.00025370340306410486,25.0,45.0
538.70776,0.08255327165354331,892.5565770679133,0.00025370340306410486,25.0,45.0
540.20923,0.08296419881889763,896.6864563043762,0.00025370340306410486,25.0,45.0
541.71069,0.08333702559055119,894.6122062069861,0.00025370340306410486,25.0,45.0
543.21216,0.08368169488188976,895.3075704453968,0.00025370340306410486,25.0,45.0
544.71362,0.08401292913385827,895.5936112193223,0.00025370340306410486,25.0,45.0
546.21509,0.08434625787401574,898.0450331125828,0.00025370340306410486,25.0,45.0
547.71655,0.0847370374015748,897.3202960654461,0.00025370340306410486,25.0,45.0
549.21802,0.08510639763779528,895.8843786521231,0.00025370340306410486,25.0,45.0
550.71948,0.08545391141732284,898.8833657966499,0.00025370340306410486,25.0,45.0
552.22095,0.08579750196850393,897.3740812881445,0.00025370340306410486,25.0,45.0
553.72241,0.08619722834645668,899.6970263602129,0.00025370340306410486,25.0,45.0
555.22388,0.08657654527559054,897.7935592780159,0.00025370340306410486,25.0,45.0
556.72534,0.08692415748031496,898.8980651863394,0.00025370340306410486,25.0,45.0
558.22681,0.08724853346456693,899.01010258408,0.00025370340306410486,25.0,45.0
559.72827,0.08758982283464567,899.1668354759123,0.00025370340306410486,25.0,45.0
561.22974,0.08800336614173228,901.4312946370602,0.00025370340306410486,25.0,45.0
562.7312,0.08839120078740158,900.0123620309051,0.00025370340306410486,25.0,45.0
564.23267,0.08878402165354331,899.1144007271783,0.00025370340306410486,25.0,45.0
565.73413,0.08909709842519685,900.3854304635762,0.00025370340306410486,25.0,45.0
567.2356,0.08941979133858267,899.7019867549669,0.00025370340306410486,25.0,45.0
568.73706,0.08977943110236221,901.6509284508506,0.00025370340306410486,25.0,45.0
570.23853,0.09013565748031495,901.6851058304118,0.00025370340306410486,25.0,45.0
571.73999,0.09052246653543307,901.0821192052981,0.00025370340306410486,25.0,45.0
573.24146,0.09086628937007873,902.8067263991691,0.00025370340306410486,25.0,45.0
574.74292,0.09123859645669291,903.5010777821062,0.00025370340306410486,25.0,45.0
576.24438,0.09166349015748032,903.813608622257,0.00025370340306410486,25.0,45.0
577.74585,0.0920293779527559,904.7089468900143,0.00025370340306410486,25.0,45.0
579.24731,0.09241881496062992,903.5962602259447,0.00025370340306410486,25.0,45.0
580.74878,0.09283107874015747,904.2290871315414,0.00025370340306410486,25.0,45.0
582.25024,0.09318549606299213,902.9711466043372,0.00025370340306410486,25.0,45.0
583.75171,0.09356169291338583,904.7798208024932,0.00025370340306410486,25.0,45.0
585.25317,0.09393009055118111,905.8317880794702,0.00025370340306410486,25.0,45.0
586.75464,0.09426987992125985,904.2905856382288,0.00025370340306410486,25.0,45.0
588.2561,0.0945937559055118,906.1785482404882,0.00025370340306410486,25.0,45.0
589.75757,0.09496974606299212,905.1728866380989,0.00025370340306410486,25.0,45.0
591.25903,0.09533981692913386,908.3110505129205,0.00025370340306410486,25.0,45.0
592.7605,0.09572291732283464,906.8489806518635,0.00025370340306410486,25.0,45.0
594.26196,0.09604972834645668,905.9009479288405,0.00025370340306410486,25.0,45.0
595.76343,0.09642551377952756,907.8684846123881,0.00025370340306410486,25.0,45.0
597.26489,0.09676659842519685,907.1429944163096,0.00025370340306410486,25.0,45.0
598.76636,0.09710309448818898,908.1309700038956,0.00025370340306410486,25.0,45.0
600.26782,0.0974146279527559,907.5863134657836,0.00025370340306410486,25.0,45.0
601.76929,0.0977933405511811,909.3715621347877,0.00025370340306410486,25.0,45.0
603.27075,0.09817210039370079,908.310660953123,0.00025370340306410486,25.0,45.0
604.77222,0.09854953346456692,910.0090118166472,0.00025370340306410486,25.0,45.0
606.27368,0.09894315944881889,908.5818984547461,0.00025370340306410486,25.0,45.0
607.77515,0.0992746220472441,908.5946500454487,0.00025370340306410486,25.0,45.0
609.27661,0.0996772342519685,910.6471886767953,0.00025370340306410486,25.0,45.0
610.77808,0.10010662204724409,909.9301389429945,0.00025370340306410486,25.0,45.0
612.27954,0.1004874468503937,908.4597844435788,0.00025370340306410486,25.0,45.0
613.78101,0.10088184645669292,911.4590832359434,0.00025370340306410486,25.0,45.0
615.28247,0.1012660964566929,911.8465653811194,0.00025370340306410486,25.0,45.0
616.78394,0.10163142125984251,911.8184651343981,0.00025370340306410486,25.0,45.0
618.2854,0.1019943996062992,911.9821321906246,0.00025370340306410486,25.0,45.0
619.78687,0.10236188385826772,911.6480457083496,0.00025370340306410486,25.0,45.0
621.28833,0.10272008661417323,912.497338008051,0.00025370340306410486,25.0,45.0
622.78979,0.10309418897637795,913.9231268666408,0.00025370340306410486,25.0,45.0
624.29126,0.10344640748031497,913.4266718607973,0.00025370340306410486,25.0,45.0
625.79272,0.10390591338582678,914.5694844825347,0.00025370340306410486,25.0,45.0
627.29419,0.10426387007874016,912.3661082976238,0.00025370340306410486,25.0,45.0
628.79565,0.10468604330708661,914.9865731723153,0.00025370340306410486,25.0,45.0
630.29712,0.10506307677165355,913.4366186209584,0.00025370340306410486,25.0,45.0
631.79858,0.10548903937007874,914.2342033502143,0.00025370340306410486,25.0,45.0
633.30005,0.10585141929133857,914.9078820932348,0.00025370340306410486,25.0,45.0
634.80151,0.10617225196850394,912.5239059862356,0.00025370340306410486,25.0,45.0
636.30298,0.10647876968503937,913.9486300480457,0.00025370340306410486,25.0,45.0
637.80444,0.10689100393700789,916.2692377613298,0.00025370340306410486,25.0,45.0
639.30591,0.10729366338582677,915.2520971302429,0.00025370340306410486,25.0,45.0
640.80737,0.10764786614173229,915.6966368004156,0.00025370340306410486,25.0,45.0
642.30884,0.10810412204724411,916.3746786131671,0.00025370340306410486,25.0,45.0
643.8103,0.10848885433070866,915.8687702895729,0.00025370340306410486,25.0,45.0
645.31177,0.10882210039370079,917.549954551357,0.00025370340306410486,25.0,45.0
646.81323,0.10918726181102363,916.6022594468251,0.00025370340306410486,25.0,45.0
648.3147,0.10962014566929135,917.9206856252434,0.00025370340306410486,25.0,45.0
649.81616,0.11000267125984252,916.8611868588495,0.00025370340306410486,25.0,45.0
651.31763,0.11035431496062993,916.5900792104923,0.00025370340306410486,25.0,45.0
652.81909,0.11078284645669292,919.896377093884,0.00025370340306410486,25.0,45.0
654.32056,0.1111714625984252,916.7314115049994,0.00025370340306410486,25.0,45.0
655.82202,0.11153196456692914,916.5741592001038,0.00025370340306410486,25.0,45.0
657.32349,0.11192609448818898,918.7172574990261,0.00025370340306410486,25.0,45.0
658.82495,0.11232922440944881,918.4948967666537,0.00025370340306410486,25.0,45.0
660.32642,0.11277921653543307,919.6038955979743,0.00025370340306410486,25.0,45.0
661.82788,0.1131787657480315,919.0996493961824,0.00025370340306410486,25.0,45.0
663.32935,0.113549687007874,918.3011297234126,0.00025370340306410486,25.0,45.0
664.83081,0.1139318622047244,918.6213738475524,0.00025370340306410486,25.0,45.0
666.33228,0.11435051377952757,920.3512530840151,0.00025370340306410486,25.0,45.0
667.83374,0.1147755964566929,919.7400857031554,0.00025370340306410486,25.0,45.0
669.33521,0.11517401968503937,922.1037527593819,0.00025370340306410486,25.0,45.0
670.83667,0.11554253543307086,919.8483313855345,0.00025370340306410486,25.0,45.0
672.33813,0.11590759055118109,921.1787560057136,0.00025370340306410486,25.0,45.0
673.8396,0.1163081279527559,922.2908713154136,0.00025370340306410486,25.0,45.0
675.34106,0.11671628937007875,920.5991689390988,0.00025370340306410486,25.0,45.0
676.84253,0.1170558248031496,922.1078301519284,0.00025370340306410486,25.0,45.0
678.34399,0.11743293110236219,921.9386573172316,0.00025370340306410486,25.0,45.0
679.84546,0.11787102362204724,922.8112452928192,0.00025370340306410486,25.0,45.0
681.34692,0.11826450984251968,922.9971951694586,0.00025370340306410486,25.0,45.0
682.84839,0.11872609251968504,923.2400986884821,0.00025370340306410486,25.0,45.0
684.34985,0.11911819291338582,922.173380080509,0.00025370340306410486,25.0,45.0
685.85132,0.11949567322834645,923.3267108167771,0.00025370340306410486,25.0,45.0
687.35278,0.1198736811023622,922.771614076094,0.00025370340306410486,25.0,45.0
688.85425,0.1202885216535433,922.9616932865862,0.00025370340306410486,25.0,45.0
690.35571,0.12068107874015747,924.5232307492533,0.00025370340306410486,25.0,45.0
691.85718,0.1211250748031496,925.0439163744969,0.00025370340306410486,25.0,45.0
693.35864,0.12155997637795277,924.9031034930529,0.00025370340306410486,25.0,45.0
694.86011,0.12197681102362205,924.5480327230231,0.00025370340306410486,25.0,45.0
696.36157,0.12235222637795276,924.6095831710168,0.00025370340306410486,25.0,45.0
697.86304,0.12277100787401574,925.1155694065706,0.00025370340306410486,25.0,45.0
699.3645,0.12314458070866141,924.1105830411635,0.00025370340306410486,25.0,45.0
700.86597,0.12354909448818897,925.4302298402805,0.00025370340306410486,25.0,45.0
702.36743,0.1239287342519685,926.6284638358655,0.00025370340306410486,25.0,45.0
703.8689,0.12437071062992125,925.8088300220751,0.00025370340306410486,25.0,45.0
705.37036,0.1248070216535433,925.8171925723933,0.00025370340306410486,25.0,45.0
706.87183,0.1252284901574803,927.004960394754,0.00025370340306410486,25.0,45.0
708.37329,0.12566707677165354,926.499753278795,0.00025370340306410486,25.0,45.0
709.87476,0.1260632834645669,926.5497208154786,0.00025370340306410486,25.0,45.0
711.37622,0.12638819881889762,924.3782885339567,0.00025370340306410486,25.0,45.0
712.87769,0.12677507874015748,925.2622776262824,0.00025370340306410486,25.0,45.0
714.37915,0.12718125787401574,927.2137644461759,0.00025370340306410486,25.0,45.0
715.88062,0.12758766141732283,927.4223087910661,0.00025370340306410486,25.0,45.0
717.38208,0.12802208267716533,927.2205427866512,0.00025370340306410486,25.0,45.0
718.88354,0.1284605649606299,928.6068302817816,0.00025370340306410486,25.0,45.0
720.38501,0.129008,929.2726399168939,0.00025370340306410486,25.0,45.0
721.88647,0.12947572047244094,928.6135566809505,0.00025370340306410486,25.0,45.0
723.38794,0.1298230118110236,925.4939618231399,0.00025370340306410486,25.0,45.0
724.8894,0.13016404921259844,928.7318010647969,0.00025370340306410486,25.0,45.0
726.39087,0.13058189173228346,930.0903778730036,0.00025370340306410486,25.0,45.0
727.89233,0.130997468503937,928.4679651993248,0.00025370340306410486,25.0,45.0
729.3938,0.1314417342519685,930.0530840150631,0.00025370340306410486,25.0,45.0
730.89526,0.13191663582677166,929.3168939098819,0.00025370340306410486,25.0,45.0
732.39673,0.132333281496063,929.2450071419296,0.00025370340306410486,25.0,45.0
733.89819,0.13273435826771654,929.6679651993247,0.00025370340306410486,25.0,45.0
735.39966,0.13314016141732285,930.8032463316453,0.00025370340306410486,25.0,45.0
736.90112,0.1335055216535433,929.4573951434879,0.00025370340306410486,25.0,45.0
738.40259,0.13391970472440945,929.9233606025192,0.00025370340306410486,25.0,45.0
739.90405,0.13430919881889763,929.9822620438904,0.00025370340306410486,25.0,45.0
741.40552,0.13470574606299213,930.376574470848,0.00025370340306410486,25.0,45.0
742.90698,0.1351595748031496,929.8711855603169,0.00025370340306410486,25.0,45.0
744.40845,0.13563580118110236,931.906661472536,0.00025370340306410486,25.0,45.0
745.90991,0.13605382086614173,931.1584209842878,0.00025370340306410486,25.0,45.0
747.41138,0.1365009842519685,931.5495130502533,0.00025370340306410486,25.0,45.0
748.91284,0.13690344488188974,930.7723672250357,0.00025370340306410486,25.0,45.0
750.41431,0.13731217125984252,931.6119724711076,0.00025370340306410486,25.0,45.0
751.91577,0.13776041338582679,933.5750422023115,0.00025370340306410486,25.0,45.0
753.41724,0.13821282283464567,931.4492663290482,0.00025370340306410486,25.0,45.0
754.9187,0.1386753562992126,931.6501233606026,0.00025370340306410486,25.0,45.0
756.42017,0.13908140748031494,932.7061420594729,0.00025370340306410486,25.0,45.0
757.92163,0.13949133070866143,932.1606025191534,0.00025370340306410486,25.0,45.0
759.4231,0.13998111023622048,932.5200623295677,0.00025370340306410486,25.0,45.0
760.92456,0.14049245472440944,933.0262043890405,0.00025370340306410486,25.0,45.0
762.42603,0.1409077972440945,932.4539150759641,0.00025370340306410486,25.0,45.0
763.92749,0.14128998228346457,932.9619270224647,0.00025370340306410486,25.0,45.0
765.42896,0.14167588779527557,931.2276068043111,0.00025370340306410486,25.0,45.0
766.93042,0.14209160629921258,933.08435268147,0.00025370340306410486,25.0,45.0
768.43188,0.14257103740157478,934.6101285547333,0.00025370340306410486,25.0,45.0
769.93335,0.14301591338582675,933.608830022075,0.00025370340306410486,25.0,45.0
771.43481,0.14345931102362203,933.7334891572524,0.00025370340306410486,25.0,45.0
772.93628,0.14388826377952754,931.8884820153228,0.00025370340306410486,25.0,45.0
774.43774,0.14430094488188974,933.149798727438,0.00025370340306410486,25.0,45.0
775.93921,0.14470788582677163,934.1441630957019,0.00025370340306410486,25.0,45.0
777.44067,0.14515778543307087,936.2054018958578,0.00025370340306410486,25.0,45.0
778.94214,0.14561120275590553,934.3347097779509,0.00025370340306410486,25.0,45.0
780.4436,0.14604512007874015,935.4207505518764,0.00025370340306410486,25.0,45.0
781.94507,0.14650428543307087,935.3790416828984,0.00025370340306410486,25.0,45.0
783.44653,0.14699885236220472,934.3878976756266,0.00025370340306410486,25.0,45.0
784.948,0.1474895688976378,935.5586027788598,0.00025370340306410486,25.0,45.0
786.44946,0.14795887401574803,935.2889494870797,0.00025370340306410486,25.0,45.0
787.95093,0.14846658070866142,936.1917153616414,0.00025370340306410486,25.0,45.0
789.45239,0.1489912775590551,935.327178288534,0.00025370340306410486,25.0,45.0
790.95386,0.14947255118110236,935.066380989482,0.00025370340306410486,25.0,45.0
792.45532,0.14988202755905514,935.6346188806648,0.00025370340306410486,25.0,45.0
793.95679,0.15037,934.2631865991431,0.00025370340306410486,25.0,45.0
795.45825,0.1508545570866142,935.1374107258798,0.00025370340306410486,25.0,45.0
796.95972,0.15129238188976377,935.7134917543177,0.00025370340306410486,25.0,45.0
798.46118,0.15176031299212597,937.3374366965329,0.00025370340306410486,25.0,45.0
799.96265,0.15226631889763778,936.4678872873653,0.00025370340306410486,25.0,45.0
801.46411,0.15274727362204724,935.493987793793,0.00025370340306410486,25.0,45.0
802.96558,0.1532318562992126,936.6570315543437,0.00025370340306410486,25.0,45.0
804.46704,0.1536642598425197,935.3023763147644,0.00025370340306410486,25.0,45.0
805.96851,0.15410215354330709,937.080509024802,0.00025370340306410486,25.0,45.0
807.46997,0.15454288779527559,935.1850149331257,0.00025370340306410486,25.0,45.0
808.97144,0.15498111023622047,935.5908063887807,0.00025370340306410486,25.0,45.0
810.4729,0.15541526181102364,936.7182703544995,0.00025370340306410486,25.0,45.0
811.97437,0.1559126338582677,938.5550707700299,0.00025370340306410486,25.0,45.0
813.47583,0.1563801653543307,936.9134917543176,0.00025370340306410486,25.0,45.0
814.97729,0.15682939566929133,937.5422152967147,0.00025370340306410486,25.0,45.0
816.47876,0.15728931299212598,937.0950266199195,0.00025370340306410486,25.0,45.0
817.98022,0.1577177972440945,936.6940657057526,0.00025370340306410486,25.0,45.0
819.48169,0.15819892913385827,937.2600701207635,0.00025370340306410486,25.0,45.0
820.98315,0.15872788385826772,937.815062978834,0.00025370340306410486,25.0,45.0
822.48462,0.1591838248031496,936.150422023114,0.00025370340306410486,25.0,45.0
823.98608,0.15966659842519687,938.8255551227113,0.00025370340306410486,25.0,45.0
825.48755,0.16019427559055116,938.5811712764577,0.00025370340306410486,25.0,45.0
826.98901,0.160720968503937,938.3570964809765,0.00025370340306410486,25.0,45.0
828.49048,0.1612206968503937,936.6491105051292,0.00025370340306410486,25.0,45.0
829.99194,0.16165666732283462,937.8581223217764,0.00025370340306410486,25.0,45.0
831.49341,0.16220452559055118,939.0808726139462,0.00025370340306410486,25.0,45.0
832.99487,0.1627069409448819,937.9133359303987,0.00025370340306410486,25.0,45.0
834.49634,0.16319274212598425,939.2611868588496,0.00025370340306410486,25.0,45.0
835.9978,0.16372890157480316,937.6088559927283,0.00025370340306410486,25.0,45.0
837.49927,0.16422416141732282,937.926217374367,0.00025370340306410486,25.0,45.0
839.00073,0.16465447637795275,937.5103233346318,0.00025370340306410486,25.0,45.0
840.5022,0.1651522086614173,939.1414881184262,0.00025370340306410486,25.0,45.0
842.00366,0.16569542125984252,938.8760680431113,0.00025370340306410486,25.0,45.0
843.50513,0.1661886377952756,937.8000259706531,0.00025370340306410486,25.0,45.0
845.00659,0.16670511023622048,939.8472406181016,0.00025370340306410486,25.0,45.0
846.50806,0.16718336614173226,937.9266588754708,0.00025370340306410486,25.0,45.0
848.00952,0.16766251574803148,938.7340605116219,0.00025370340306410486,25.0,45.0
849.51099,0.1682246653543307,938.4508245682379,0.00025370340306410486,25.0,45.0
851.01245,0.16868249409448818,938.7437475652513,0.00025370340306410486,25.0,45.0
852.51392,0.16923670078740158,939.7856901701078,0.00025370340306410486,25.0,45.0
854.01538,0.1697627224409449,938.4418127515908,0.00025370340306410486,25.0,45.0
855.51685,0.17023999409448817,938.9119075444747,0.00025370340306410486,25.0,45.0
857.01831,0.1707623562992126,939.6934424100767,0.00025370340306410486,25.0,45.0
858.51978,0.1712924271653543,939.109206596546,0.00025370340306410486,25.0,45.0
860.02124,0.17181498818897636,940.509700038956,0.00025370340306410486,25.0,45.0
861.52271,0.17235152362204723,939.0686404363071,0.00025370340306410486,25.0,45.0
863.02417,0.1728756811023622,938.6469289702637,0.00025370340306410486,25.0,45.0
864.52563,0.17341828346456692,939.4192702246462,0.00025370340306410486,25.0,45.0
866.0271,0.17397662992125984,939.2905596675757,0.00025370340306410486,25.0,45.0
867.52856,0.1745224940944882,940.6065186339438,0.00025370340306410486,25.0,45.0
869.03003,0.1749891692913386,939.064952603558,0.00025370340306410486,25.0,45.0
870.53149,0.17557769488188976,940.7287105570706,0.00025370340306410486,25.0,45.0
872.03296,0.17610464566929132,939.9781067393845,0.00025370340306410486,25.0,45.0
873.53442,0.17667864566929134,940.1981301129724,0.00025370340306410486,25.0,45.0
875.03589,0.17724352755905512,940.7602908713154,0.00025370340306410486,25.0,45.0
876.53735,0.17774753937007873,938.7122451629659,0.00025370340306410486,25.0,45.0
878.03882,0.1782404625984252,938.512271133619,0.00025370340306410486,25.0,45.0
879.54028,0.178740437007874,938.3155694065706,0.00025370340306410486,25.0,45.0
881.04175,0.1791561909448819,937.4609531229711,0.00025370340306410486,25.0,45.0
882.54321,0.17960470472440945,939.7494091676406,0.00025370340306410486,25.0,45.0
884.04468,0.18013011811023621,939.0103103493053,0.00025370340306410486,25.0,45.0
885.54614,0.18065205708661417,941.2247240618102,0.00025370340306410486,25.0,45.0
887.04761,0.1812397618110236,940.8309829892222,0.00025370340306410486,25.0,45.0
888.54907,0.1818151102362205,940.4076353720296,0.00025370340306410486,25.0,45.0
890.05054,0.18235832283464565,940.0970783015193,0.00025370340306410486,25.0,45.0
891.552,0.18290332874015747,939.781379041683,0.00025370340306410486,25.0,45.0
893.05347,0.18343068897637796,937.4380470068822,0.00025370340306410486,25.0,45.0
894.55493,0.18399211220472442,940.2033242436048,0.00025370340306410486,25.0,45.0
896.0564,0.18459545669291338,939.0389559797429,0.00025370340306410486,25.0,45.0
897.55786,0.18517812598425196,940.0400727178289,0.00025370340306410486,25.0,45.0
899.05933,0.18579708858267716,940.7299831190755,0.00025370340306410486,25.0,45.0
900.56079,0.18641668307086615,939.0000259706532,0.00025370340306410486,25.0,45.0
902.06226,0.1870102657480315,941.1461628359954,0.00025370340306410486,25.0,45.0
903.56372,0.1875887125984252,939.3480067523699,0.00025370340306410486,25.0,45.0
905.06519,0.18819369881889764,938.7887027658745,0.00025370340306410486,25.0,45.0
906.56665,0.18873328543307086,939.528450850539,0.00025370340306410486,25.0,45.0
908.06812,0.1893208838582677,940.4035060381769,0.00025370340306410486,25.0,45.0
909.56958,0.18980312992125983,937.9702636021296,0.00025370340306410486,25.0,45.0
911.07104,0.19034901771653542,940.7442929489678,0.00025370340306410486,25.0,45.0
911.57153,0.19058571062992125,942.3748344370862,0.00025370340306410486,25.0,45.0