File: datasets/am_bench_2022/csv/45-XY.02-1.csv
Time(s),Strain(%),Stress(MPa),SR(s-1),Temp(C),Angle(deg)
27.297363,2.1878645669291337e-05,15.593324142156861,0.00025370340306410486,25.0,45.0
28.999023,2.7489753937007877e-05,21.356443525326796,0.00025370340306410486,25.0,45.0
30.600586,6.181181496062993e-05,26.9074729370915,0.00025370340306410486,25.0,45.0
32.202148,7.239495866141732e-05,32.105351307189544,0.00025370340306410486,25.0,45.0
33.803711,7.64992283464567e-05,38.233126531862744,0.00025370340306410486,25.0,45.0
35.405273,0.00011065109055118109,44.89336448120915,0.00025370340306410486,25.0,45.0
37.006836,0.00016016552952755907,52.244789113562085,0.00025370340306410486,25.0,45.0
38.608398,0.0001749852342519685,60.54864940767973,0.00025370340306410486,25.0,45.0
40.209961,0.0002116207874015748,68.3255131740196,0.00025370340306410486,25.0,45.0
41.811523,0.0002531842125984252,76.92281709558823,0.00025370340306410486,25.0,45.0
43.413086,0.0002767997047244094,85.87964154411765,0.00025370340306410486,25.0,45.0
45.014648,0.00026161116141732284,94.1407066993464,0.00025370340306410486,25.0,45.0
46.616211,0.000282065374015748,105.69165645424836,0.00025370340306410486,25.0,45.0
48.217773,0.00030762228346456694,111.79391850490195,0.00025370340306410486,25.0,45.0
49.819336,0.0003389115157480315,121.05580320669934,0.00025370340306410486,25.0,45.0
51.420898,0.0003746952559055118,131.27970537173204,0.00025370340306410486,25.0,45.0
53.022461,0.00038722645669291337,139.82568678513073,0.00025370340306410486,25.0,45.0
54.624023,0.00044631594488188977,148.99662224264705,0.00025370340306410486,25.0,45.0
56.225586,0.0005051954724409449,161.07040185866012,0.00025370340306410486,25.0,45.0
57.827148,0.0005409511614173229,170.605961499183,0.00025370340306410486,25.0,45.0
59.428711,0.0005823578937007873,180.83877910539215,0.00025370340306410486,25.0,45.0
61.030273,0.0006053329133858267,192.6078201593137,0.00025370340306410486,25.0,45.0
62.631836,0.0006037462204724409,203.10197865604573,0.00025370340306410486,25.0,45.0
64.233398,0.0006813359251968504,215.19815155228756,0.00025370340306410486,25.0,45.0
65.834961,0.0007154436614173228,226.25745506535947,0.00025370340306410486,25.0,45.0
67.436523,0.0007559261614173228,235.7968009599673,0.00025370340306410486,25.0,45.0
69.038086,0.000815623622047244,248.10533854166667,0.00025370340306410486,25.0,45.0
70.639648,0.0008116758661417323,258.00977839052285,0.00025370340306410486,25.0,45.0
72.241211,0.0008781637598425197,270.38153594771245,0.00025370340306410486,25.0,45.0
73.842773,0.0009094239370078741,281.91983251633985,0.00025370340306410486,25.0,45.0
75.444336,0.0009542903937007875,297.34724775326794,0.00025370340306410486,25.0,45.0
77.045898,0.0010326942913385826,309.63786764705884,0.00025370340306410486,25.0,45.0
78.647461,0.0010299702559055117,319.97362642973854,0.00025370340306410486,25.0,45.0
80.249023,0.0010902235236220472,330.66582414215685,0.00025370340306410486,25.0,45.0
81.850586,0.0011232615551181103,342.15231821895424,0.00025370340306410486,25.0,45.0
83.452148,0.0011515392913385826,351.3252144607843,0.00025370340306410486,25.0,45.0
85.053711,0.0012172036811023623,365.0956648284313,0.00025370340306410486,25.0,45.0
86.655273,0.0012683572047244094,376.2723141339869,0.00025370340306410486,25.0,45.0
88.256836,0.001275518779527559,386.50755718954247,0.00025370340306410486,25.0,45.0
89.858398,0.0013204279527559055,397.05032169117646,0.00025370340306410486,25.0,45.0
91.459961,0.001339589094488189,409.10843035130716,0.00025370340306410486,25.0,45.0
93.061523,0.0014025085433070866,418.5455218545751,0.00025370340306410486,25.0,45.0
94.663086,0.0014185493897637795,429.2188010620915,0.00025370340306410486,25.0,45.0
96.264648,0.0014971428346456691,439.0125102124183,0.00025370340306410486,25.0,45.0
97.866211,0.0015001258267716537,451.97564338235287,0.00025370340306410486,25.0,45.0
99.467773,0.0015241275393700789,459.54330065359477,0.00025370340306410486,25.0,45.0
101.06934,0.0015768435236220473,469.8880208333333,0.00025370340306410486,25.0,45.0
102.6709,0.0016022853149606298,480.02302900326794,0.00025370340306410486,25.0,45.0
104.27246,0.0016443262795275589,487.9081903594771,0.00025370340306410486,25.0,45.0
105.87402,0.0016776593700787402,498.02387152777777,0.00025370340306410486,25.0,45.0
107.47559,0.0017098035629921262,508.8469924428104,0.00025370340306410486,25.0,45.0
109.07715,0.0017413869488188975,517.1167534722222,0.00025370340306410486,25.0,45.0
110.67871,0.0017445644488188975,525.7720077614379,0.00025370340306410486,25.0,45.0
112.28027,0.001798310551181102,535.0084763071895,0.00025370340306410486,25.0,45.0
113.88184,0.0018036772047244096,538.3422436683006,0.00025370340306410486,25.0,45.0
115.4834,0.0018281097637795275,546.935023488562,0.00025370340306410486,25.0,45.0
117.08496,0.0018879501771653544,553.4257557189542,0.00025370340306410486,25.0,45.0
118.68652,0.0018960213385826772,560.9607077205882,0.00025370340306410486,25.0,45.0
120.28809,0.001920162027559055,566.3477839052288,0.00025370340306410486,25.0,45.0
121.88965,0.001971148818897638,575.6301572712418,0.00025370340306410486,25.0,45.0
123.49121,0.0019684593503937007,580.3770169526143,0.00025370340306410486,25.0,45.0
125.09277,0.002002436811023622,586.653262867647,0.00025370340306410486,25.0,45.0
126.69434,0.002030365551181102,592.0278033088234,0.00025370340306410486,25.0,45.0
128.2959,0.002063666338582677,596.2905433006536,0.00025370340306410486,25.0,45.0
129.89746,0.0020696387795275588,601.2377961601306,0.00025370340306410486,25.0,45.0
131.49902,0.0021029001968503936,606.3195210375817,0.00025370340306410486,25.0,45.0
133.10059,0.0021299116141732283,612.0846864787582,0.00025370340306410486,25.0,45.0
134.70215,0.002127603937007874,616.4303257761437,0.00025370340306410486,25.0,45.0
136.30371,0.002198329724409449,620.2713950163397,0.00025370340306410486,25.0,45.0
137.90527,0.0022266248031496062,625.4966554330065,0.00025370340306410486,25.0,45.0
139.50684,0.0022616025590551183,631.3705320669934,0.00025370340306410486,25.0,45.0
141.1084,0.002295205708661417,634.3010110294117,0.00025370340306410486,25.0,45.0
142.70996,0.00230886062992126,639.0376582924836,0.00025370340306410486,25.0,45.0
144.31152,0.002374328937007874,643.57914624183,0.00025370340306410486,25.0,45.0
145.91309,0.0023735222440944884,647.8371374591503,0.00025370340306410486,25.0,45.0
147.51465,0.0024145411417322835,651.6371783088234,0.00025370340306410486,25.0,45.0
149.11621,0.0024728531496062993,656.0735804738562,0.00025370340306410486,25.0,45.0
150.71777,0.002508572440944882,659.7503319035947,0.00025370340306410486,25.0,45.0
152.31934,0.0025889909448818895,662.7993515114377,0.00025370340306410486,25.0,45.0
153.9209,0.0026171641732283465,665.687806372549,0.00025370340306410486,25.0,45.0
155.52246,0.002650072244094488,667.1939848856209,0.00025370340306410486,25.0,45.0
157.12402,0.002697219094488189,670.3963950163397,0.00025370340306410486,25.0,45.0
158.72559,0.002754564566929134,674.7485702614379,0.00025370340306410486,25.0,45.0
160.32715,0.0028411049212598424,678.2953686683006,0.00025370340306410486,25.0,45.0
161.92871,0.0029117423228346455,683.2250561683005,0.00025370340306410486,25.0,45.0
163.53027,0.0030049962598425197,684.2408854166666,0.00025370340306410486,25.0,45.0
165.13184,0.0030924364173228343,686.537607230392,0.00025370340306410486,25.0,45.0
166.7334,0.0031565980314960627,690.2767565359477,0.00025370340306410486,25.0,45.0
168.33496,0.003271857283464567,693.105570874183,0.00025370340306410486,25.0,45.0
169.93652,0.0033736911417322833,696.1788960375817,0.00025370340306410486,25.0,45.0
171.53809,0.0035272814960629925,700.668377246732,0.00025370340306410486,25.0,45.0
173.13965,0.003665061220472441,703.1182598039214,0.00025370340306410486,25.0,45.0
174.74121,0.003819232874015748,704.8191636029411,0.00025370340306410486,25.0,45.0
176.34277,0.003984267322834646,708.3040236928103,0.00025370340306410486,25.0,45.0
177.94434,0.0041646557086614175,710.1867340686274,0.00025370340306410486,25.0,45.0
179.5459,0.004403526771653544,711.9187602124183,0.00025370340306410486,25.0,45.0
181.14746,0.00453334468503937,713.2022314133986,0.00025370340306410486,25.0,45.0
182.74902,0.004745053346456693,716.3957312091502,0.00025370340306410486,25.0,45.0
184.35059,0.004959658661417322,718.3139808006536,0.00025370340306410486,25.0,45.0
185.95215,0.0051762259842519686,719.3036151960783,0.00025370340306410486,25.0,45.0
187.55371,0.005365576377952755,719.9956852532679,0.00025370340306410486,25.0,45.0
189.15527,0.005665333464566929,723.299325980392,0.00025370340306410486,25.0,45.0
190.75684,0.005891601181102362,723.1456801470588,0.00025370340306410486,25.0,45.0
192.3584,0.006170254724409448,725.8803615196078,0.00025370340306410486,25.0,45.0
193.95996,0.006433046850393701,728.340456495098,0.00025370340306410486,25.0,45.0
195.56152,0.006719339173228347,729.059819240196,0.00025370340306410486,25.0,45.0
197.16309,0.007055405118110236,730.6295955882352,0.00025370340306410486,25.0,45.0
198.76465,0.0073760468503937015,731.1672538807189,0.00025370340306410486,25.0,45.0
200.36621,0.007669287401574802,732.7135927287582,0.00025370340306410486,25.0,45.0
201.96777,0.007981461614173228,732.0131740196077,0.00025370340306410486,25.0,45.0
203.56934,0.008312055511811025,735.0282118055555,0.00025370340306410486,25.0,45.0
205.1709,0.008628534251968504,734.8410947712418,0.00025370340306410486,25.0,45.0
206.77246,0.008921785826771654,736.2224775326797,0.00025370340306410486,25.0,45.0
208.37402,0.009320359448818897,738.4691074346405,0.00025370340306410486,25.0,45.0
209.97559,0.009664017519685038,738.6491779003267,0.00025370340306410486,25.0,45.0
211.57715,0.010031589370078739,741.3515625,0.00025370340306410486,25.0,45.0
213.17871,0.010386311023622046,741.2848754084966,0.00025370340306410486,25.0,45.0
214.78027,0.010730857874015749,742.919398488562,0.00025370340306410486,25.0,45.0
216.38184,0.011115365748031496,743.9890727124182,0.00025370340306410486,25.0,45.0
217.9834,0.011455855708661417,744.1872191584966,0.00025370340306410486,25.0,45.0
219.58496,0.01176096594488189,744.817018995098,0.00025370340306410486,25.0,45.0
221.18652,0.012171074212598425,746.4908854166666,0.00025370340306410486,25.0,45.0
222.78809,0.01249025157480315,747.1763429330065,0.00025370340306410486,25.0,45.0
224.38965,0.012850117519685038,746.738893995098,0.00025370340306410486,25.0,45.0
225.99121,0.013200391732283464,748.4008374183006,0.00025370340306410486,25.0,45.0
227.59277,0.013529419881889763,749.8212060866013,0.00025370340306410486,25.0,45.0
229.19434,0.013963356102362203,752.9339256535948,0.00025370340306410486,25.0,45.0
230.7959,0.014390557283464566,751.3081086601306,0.00025370340306410486,25.0,45.0
232.39746,0.014737896653543307,752.0309180964052,0.00025370340306410486,25.0,45.0
233.99902,0.015128716338582676,753.8268229166666,0.00025370340306410486,25.0,45.0
235.60059,0.015469817913385826,753.5424581290849,0.00025370340306410486,25.0,45.0
237.20215,0.015826269488188976,754.7182138480392,0.00025370340306410486,25.0,45.0
238.80371,0.016217011417322836,756.9023948120914,0.00025370340306410486,25.0,45.0
240.40527,0.016631026181102362,755.7757352941176,0.00025370340306410486,25.0,45.0
242.00684,0.017006403346456693,755.8148743872549,0.00025370340306410486,25.0,45.0
243.6084,0.01737155216535433,756.9851664624182,0.00025370340306410486,25.0,45.0
245.20996,0.017733606496062992,758.1328635620914,0.00025370340306410486,25.0,45.0
246.81152,0.018129057677165356,758.6818321078431,0.00025370340306410486,25.0,45.0
248.41309,0.01851960157480315,760.1119536356208,0.00025370340306410486,25.0,45.0
250.01465,0.018929351377952756,761.7710375816993,0.00025370340306410486,25.0,45.0
251.61621,0.019318125000000002,761.8591196895424,0.00025370340306410486,25.0,45.0
253.21777,0.019696586614173228,762.138556985294,0.00025370340306410486,25.0,45.0
254.81934,0.020054759842519684,763.1154769199345,0.00025370340306410486,25.0,45.0
256.4209,0.020436608267716535,763.1015880310457,0.00025370340306410486,25.0,45.0
258.02246,0.020841072834645667,764.1755004084968,0.00025370340306410486,25.0,45.0
259.62402,0.021219204724409448,764.470383986928,0.00025370340306410486,25.0,45.0
261.22559,0.021564826771653545,764.739915236928,0.00025370340306410486,25.0,45.0
262.82715,0.02191725393700787,765.2965175653594,0.00025370340306410486,25.0,45.0
264.42871,0.02232326968503937,767.6581392973856,0.00025370340306410486,25.0,45.0
266.03027,0.02271667125984252,769.0660232843136,0.00025370340306410486,25.0,45.0
267.63184,0.023132153543307086,768.1717473447711,0.00025370340306410486,25.0,45.0
269.2334,0.02348513188976378,768.0273948120914,0.00025370340306410486,25.0,45.0
270.83496,0.023839547244094487,769.4706137663399,0.00025370340306410486,25.0,45.0
272.43652,0.02420493503937008,770.3231975081699,0.00025370340306410486,25.0,45.0
274.03809,0.024598822834645668,769.4017565359476,0.00025370340306410486,25.0,45.0
275.63965,0.024974903543307087,771.9753625408496,0.00025370340306410486,25.0,45.0
277.24121,0.025379064960629923,772.7498212826796,0.00025370340306410486,25.0,45.0
278.84277,0.02577742716535433,774.4855238970588,0.00025370340306410486,25.0,45.0
280.44434,0.026218153543307084,773.0573171977123,0.00025370340306410486,25.0,45.0
282.0459,0.026554314960629922,774.2388174019607,0.00025370340306410486,25.0,45.0
283.64746,0.02696138385826772,775.5819291258169,0.00025370340306410486,25.0,45.0
285.24902,0.027356982283464563,775.9155943627451,0.00025370340306410486,25.0,45.0
286.85059,0.027727801181102362,775.5680912990196,0.00025370340306410486,25.0,45.0
288.45215,0.028090155511811023,776.2018229166666,0.00025370340306410486,25.0,45.0
290.05371,0.028509781496062994,777.6636284722222,0.00025370340306410486,25.0,45.0
291.65527,0.028869299212598423,778.3685406454248,0.00025370340306410486,25.0,45.0
293.25684,0.029214937007874014,776.8439031862745,0.00025370340306410486,25.0,45.0
294.8584,0.029552913385826773,778.33407373366,0.00025370340306410486,25.0,45.0
296.45996,0.029912057086614176,779.414266748366,0.00025370340306410486,25.0,45.0
298.06152,0.030218889763779528,780.0385774101306,0.00025370340306410486,25.0,45.0
299.66309,0.030637612204724406,781.8116064133986,0.00025370340306410486,25.0,45.0
301.26465,0.030998742125984254,783.0217269199346,0.00025370340306410486,25.0,45.0
302.86621,0.03138245275590551,783.633629493464,0.00025370340306410486,25.0,45.0
304.46777,0.031800620078740155,782.5757250816993,0.00025370340306410486,25.0,45.0
306.06934,0.0321850905511811,782.6515778186274,0.00025370340306410486,25.0,45.0
307.6709,0.03258573622047244,783.6460375816993,0.00025370340306410486,25.0,45.0
309.27246,0.03297586811023622,784.1928615196078,0.00025370340306410486,25.0,45.0
310.87402,0.033306679133858264,785.5631638071894,0.00025370340306410486,25.0,45.0
312.47559,0.033681226377952754,786.3965992647057,0.00025370340306410486,25.0,45.0
314.07715,0.034072933070866146,787.5089613970588,0.00025370340306410486,25.0,45.0
315.67871,0.034442801181102364,787.4231515522875,0.00025370340306410486,25.0,45.0
317.28027,0.034840320866141736,787.851664624183,0.00025370340306410486,25.0,45.0
318.88184,0.03527545669291338,789.3003216911765,0.00025370340306410486,25.0,45.0
320.4834,0.035571665354330706,788.1191278594771,0.00025370340306410486,25.0,45.0
322.08496,0.035945818897637795,790.1639348447711,0.00025370340306410486,25.0,45.0
323.68652,0.0363753779527559,791.9544015522875,0.00025370340306410486,25.0,45.0
325.28809,0.036762370078740156,790.5089358660131,0.00025370340306410486,25.0,45.0
326.88965,0.03712568307086614,790.6245659722222,0.00025370340306410486,25.0,45.0
328.49121,0.03753309842519685,792.8508476307189,0.00025370340306410486,25.0,45.0
330.09277,0.03789975787401575,793.1330422794117,0.00025370340306410486,25.0,45.0
331.69434,0.038275269685039366,792.9711499183006,0.00025370340306410486,25.0,45.0
333.2959,0.03862273425196851,793.613791870915,0.00025370340306410486,25.0,45.0
334.89746,0.03901674606299213,795.0857077205882,0.00025370340306410486,25.0,45.0
336.49902,0.039368850393700784,794.6120302287582,0.00025370340306410486,25.0,45.0
338.10059,0.03972576181102362,795.2067504084968,0.00025370340306410486,25.0,45.0
339.70215,0.04007600196850394,797.4575929330065,0.00025370340306410486,25.0,45.0
341.30371,0.040491911417322834,796.2123927696077,0.00025370340306410486,25.0,45.0
342.90527,0.040887275590551185,797.0429176879085,0.00025370340306410486,25.0,45.0
344.50684,0.041270720472440944,796.9371425653594,0.00025370340306410486,25.0,45.0
346.1084,0.04165112992125984,796.8451286764706,0.00025370340306410486,25.0,45.0
347.70996,0.04200466338582677,799.0296160130719,0.00025370340306410486,25.0,45.0
349.31152,0.042406501968503936,799.8482179330065,0.00025370340306410486,25.0,45.0
350.91309,0.0427698937007874,799.4551419526143,0.00025370340306410486,25.0,45.0
352.51465,0.043123620078740155,799.245455473856,0.00025370340306410486,25.0,45.0
354.11621,0.04342556496062992,801.0901756535948,0.00025370340306410486,25.0,45.0
355.71777,0.04382767716535433,799.9020118464051,0.00025370340306410486,25.0,45.0
357.31934,0.04417703937007874,800.5047998366013,0.00025370340306410486,25.0,45.0
358.9209,0.044592724409448815,802.6055198120915,0.00025370340306410486,25.0,45.0
360.52246,0.04497861220472441,803.7926113153594,0.00025370340306410486,25.0,45.0
362.12402,0.045306482283464566,802.7427747140522,0.00025370340306410486,25.0,45.0
363.72559,0.04563855511811024,805.0936734068626,0.00025370340306410486,25.0,45.0
365.32715,0.046041915354330706,805.6561478758169,0.00025370340306410486,25.0,45.0
366.92871,0.046361728346456695,805.2992238562091,0.00025370340306410486,25.0,45.0
368.53027,0.04681385236220472,806.941916870915,0.00025370340306410486,25.0,45.0
370.13184,0.04716677755905512,805.6340124591503,0.00025370340306410486,25.0,45.0
371.7334,0.04753441929133858,806.9558823529411,0.00025370340306410486,25.0,45.0
373.33496,0.04790092716535433,807.6563776552287,0.00025370340306410486,25.0,45.0
374.93652,0.0482450374015748,807.2506638071894,0.00025370340306410486,25.0,45.0
376.53809,0.048628698818897635,808.036279616013,0.00025370340306410486,25.0,45.0
378.13965,0.049016659448818896,808.8012663398692,0.00025370340306410486,25.0,45.0
379.74121,0.04940094488188976,809.8879697712417,0.00025370340306410486,25.0,45.0
381.34277,0.04982227952755905,808.891850490196,0.00025370340306410486,25.0,45.0
382.94434,0.0502381437007874,810.3191891339869,0.00025370340306410486,25.0,45.0
384.5459,0.05053409645669292,810.0426623774508,0.00025370340306410486,25.0,45.0
386.14746,0.05093810039370079,813.0026807598039,0.00025370340306410486,25.0,45.0
387.74902,0.0513607716535433,811.8936121323528,0.00025370340306410486,25.0,45.0
389.35059,0.05169096062992126,811.9919066584966,0.00025370340306410486,25.0,45.0
390.95215,0.052008021653543304,812.9865451388888,0.00025370340306410486,25.0,45.0
392.55371,0.05239460039370079,813.2402216094771,0.00025370340306410486,25.0,45.0
394.15527,0.052795822834645664,816.0738102532679,0.00025370340306410486,25.0,45.0
395.75684,0.05318235039370079,813.6500459558823,0.00025370340306410486,25.0,45.0
397.3584,0.05349748622047244,814.9748008578431,0.00025370340306410486,25.0,45.0
398.95996,0.05392932086614173,816.724188112745,0.00025370340306410486,25.0,45.0
400.56152,0.05429422834645669,816.1332975898692,0.00025370340306410486,25.0,45.0
402.16309,0.05462115157480315,815.051087622549,0.00025370340306410486,25.0,45.0
403.76465,0.054946389763779524,819.3979013480391,0.00025370340306410486,25.0,45.0
405.36621,0.055346797244094484,817.3244995915032,0.00025370340306410486,25.0,45.0
406.96777,0.0557108779527559,818.5950776143791,0.00025370340306410486,25.0,45.0
408.56934,0.056069045275590555,818.1047794117646,0.00025370340306410486,25.0,45.0
410.1709,0.05637888976377952,817.9801623774509,0.00025370340306410486,25.0,45.0
411.77246,0.056722051181102365,818.6407015931372,0.00025370340306410486,25.0,45.0
413.37402,0.05710736220472441,820.8799785539214,0.00025370340306410486,25.0,45.0
414.97559,0.057488954724409444,819.8996885212417,0.00025370340306410486,25.0,45.0
416.57715,0.05785422834645669,821.9315767973856,0.00025370340306410486,25.0,45.0
418.17871,0.058230598425196844,823.0555810866013,0.00025370340306410486,25.0,45.0
419.78027,0.0586191437007874,822.5032169117646,0.00025370340306410486,25.0,45.0
421.38184,0.059022895669291336,823.6480034722222,0.00025370340306410486,25.0,45.0
422.9834,0.05943484251968504,823.5041870915032,0.00025370340306410486,25.0,45.0
424.58496,0.05981209448818898,822.8434180964052,0.00025370340306410486,25.0,45.0
426.18652,0.06020170078740157,824.2893178104574,0.00025370340306410486,25.0,45.0
427.78809,0.060570738188976375,826.0037530637254,0.00025370340306410486,25.0,45.0
429.38965,0.06093665551181102,825.2380770016339,0.00025370340306410486,25.0,45.0
430.99121,0.06127400984251968,825.5271650326796,0.00025370340306410486,25.0,45.0
432.59277,0.061623482283464565,825.2221711601306,0.00025370340306410486,25.0,45.0
434.19434,0.061997629921259845,825.8788296568628,0.00025370340306410486,25.0,45.0
435.7959,0.06234668700787401,827.1964103349673,0.00025370340306410486,25.0,45.0
437.39746,0.06275075,828.0201184640522,0.00025370340306410486,25.0,45.0
438.99902,0.06306904133858268,826.9489634395425,0.00025370340306410486,25.0,45.0
440.60059,0.06336732874015748,826.1089154411764,0.00025370340306410486,25.0,45.0
442.20215,0.06369950787401574,829.0897926879085,0.00025370340306410486,25.0,45.0
443.80371,0.06409461614173229,829.3960375816993,0.00025370340306410486,25.0,45.0
445.40527,0.06445774212598425,829.5069699754902,0.00025370340306410486,25.0,45.0
447.00684,0.0648282125984252,830.7238306781046,0.00025370340306410486,25.0,45.0
448.6084,0.06520539960629922,830.3515114379085,0.00025370340306410486,25.0,45.0
450.20996,0.06558718503937008,831.0519301470587,0.00025370340306410486,25.0,45.0
451.81152,0.06592232086614173,832.7282220179737,0.00025370340306410486,25.0,45.0
453.41309,0.06631286614173229,833.6986570669934,0.00025370340306410486,25.0,45.0
455.01465,0.0667245905511811,832.946742238562,0.00025370340306410486,25.0,45.0
456.61621,0.06705843503937008,833.0400582107842,0.00025370340306410486,25.0,45.0
458.21777,0.06746342913385826,834.2490553513071,0.00025370340306410486,25.0,45.0
459.81934,0.06779089763779526,834.301598243464,0.00025370340306410486,25.0,45.0
461.4209,0.06813981889763779,833.0962265114379,0.00025370340306410486,25.0,45.0
463.02246,0.06844851968503937,834.718852124183,0.00025370340306410486,25.0,45.0
464.62402,0.06882744291338583,835.4321640114379,0.00025370340306410486,25.0,45.0
466.22559,0.06925914763779528,837.800883374183,0.00025370340306410486,25.0,45.0
467.82715,0.06963906299212598,836.6846660539214,0.00025370340306410486,25.0,45.0
469.42871,0.06998088582677166,836.4021139705882,0.00025370340306410486,25.0,45.0
471.03027,0.07031808661417323,837.3467371323529,0.00025370340306410486,25.0,45.0
472.63184,0.07070001968503936,838.3238613153594,0.00025370340306410486,25.0,45.0
474.2334,0.07102035433070866,837.6900020424836,0.00025370340306410486,25.0,45.0
475.83496,0.0713835374015748,839.6002859477125,0.00025370340306410486,25.0,45.0
477.43652,0.07174949015748032,839.1879595588234,0.00025370340306410486,25.0,45.0
479.03809,0.07210139763779527,841.1892361111111,0.00025370340306410486,25.0,45.0
480.63965,0.0725225374015748,839.638556985294,0.00025370340306410486,25.0,45.0
482.24121,0.07287214566929133,840.3815359477123,0.00025370340306410486,25.0,45.0
483.84277,0.07317763779527559,841.0789675245097,0.00025370340306410486,25.0,45.0
485.44434,0.07354339566929133,842.099290236928,0.00025370340306410486,25.0,45.0
487.0459,0.07394918307086615,842.6712367238562,0.00025370340306410486,25.0,45.0
488.64746,0.07436108267716535,840.5787632761437,0.00025370340306410486,25.0,45.0
490.24902,0.07472162007874016,844.1653390522875,0.00025370340306410486,25.0,45.0
491.85059,0.07511553937007874,843.6270935457516,0.00025370340306410486,25.0,45.0
493.45215,0.07550217125984252,844.027445874183,0.00025370340306410486,25.0,45.0
495.05371,0.07585406102362205,842.5460069444443,0.00025370340306410486,25.0,45.0
496.65527,0.0762139311023622,844.5244332107842,0.00025370340306410486,25.0,45.0
498.25684,0.07656201968503937,844.7959303513071,0.00025370340306410486,25.0,45.0
499.8584,0.07692172440944882,845.7240604575163,0.00025370340306410486,25.0,45.0
501.45996,0.07733454527559054,846.0982945261437,0.00025370340306410486,25.0,45.0
503.06152,0.07766970472440946,845.8585580065359,0.00025370340306410486,25.0,45.0
504.66309,0.07805525590551181,847.3172487745097,0.00025370340306410486,25.0,45.0
506.26465,0.07839373031496064,846.5046466503267,0.00025370340306410486,25.0,45.0
507.86621,0.07875644488188976,847.4296364379084,0.00025370340306410486,25.0,45.0
509.46777,0.07917627559055118,849.5959201388888,0.00025370340306410486,25.0,45.0
511.06934,0.07954072637795276,849.1943678513071,0.00025370340306410486,25.0,45.0
512.6709,0.07990238385826771,847.3033598856208,0.00025370340306410486,25.0,45.0
514.27246,0.08020801181102362,848.646165236928,0.00025370340306410486,25.0,45.0
515.87402,0.0806026751968504,849.7189031862745,0.00025370340306410486,25.0,45.0
517.47559,0.08100334645669291,849.8496732026143,0.00025370340306410486,25.0,45.0
519.07715,0.08134591338582677,852.2063674428103,0.00025370340306410486,25.0,45.0
520.67871,0.08176826771653543,851.6934997957517,0.00025370340306410486,25.0,45.0
522.28027,0.08212004133858267,852.4992595996732,0.00025370340306410486,25.0,45.0
523.88184,0.08247650787401575,851.4774050245097,0.00025370340306410486,25.0,45.0
525.4834,0.08283158858267717,851.091069240196,0.00025370340306410486,25.0,45.0
527.08496,0.0832022283464567,851.3682598039215,0.00025370340306410486,25.0,45.0
528.68652,0.08355633661417323,853.0225949754902,0.00025370340306410486,25.0,45.0
530.28809,0.08393019881889764,853.2173202614379,0.00025370340306410486,25.0,45.0
531.88965,0.08426186023622048,853.0358200571895,0.00025370340306410486,25.0,45.0
533.49121,0.08467203543307086,854.64945874183,0.00025370340306410486,25.0,45.0
535.09277,0.08506075,854.2264603758168,0.00025370340306410486,25.0,45.0
536.69434,0.0854790688976378,855.0592064950979,0.00025370340306410486,25.0,45.0
538.2959,0.08583406102362204,854.3925142973854,0.00025370340306410486,25.0,45.0
539.89746,0.0861421279527559,855.6486162173202,0.00025370340306410486,25.0,45.0
541.49902,0.08649047047244093,856.9476102941176,0.00025370340306410486,25.0,45.0
543.10059,0.08685869881889763,857.5508578431372,0.00025370340306410486,25.0,45.0
544.70215,0.08725584448818897,858.7682546977125,0.00025370340306410486,25.0,45.0
546.30371,0.08765605708661417,856.836550245098,0.00025370340306410486,25.0,45.0
547.90527,0.0880259468503937,858.3513837826796,0.00025370340306410486,25.0,45.0
549.50684,0.0884378937007874,858.700137867647,0.00025370340306410486,25.0,45.0
551.1084,0.08880198622047245,859.46400122549,0.00025370340306410486,25.0,45.0
552.70996,0.0892126062992126,860.4455422794117,0.00025370340306410486,25.0,45.0
554.31152,0.08959346062992127,858.2636335784313,0.00025370340306410486,25.0,45.0
555.91309,0.09000817716535434,858.0398029003268,0.00025370340306410486,25.0,45.0
557.51465,0.09036879527559055,860.2406556372549,0.00025370340306410486,25.0,45.0
559.11621,0.09069121259842519,860.0858353758169,0.00025370340306410486,25.0,45.0
560.71777,0.09101590551181103,863.0104421977125,0.00025370340306410486,25.0,45.0
562.31934,0.09137924803149605,860.8468392565359,0.00025370340306410486,25.0,45.0
563.9209,0.09171655905511811,861.9203176062091,0.00025370340306410486,25.0,45.0
565.52246,0.09211112401574803,862.2918198529411,0.00025370340306410486,25.0,45.0
567.12402,0.09245048228346456,860.9325980392157,0.00025370340306410486,25.0,45.0
568.72559,0.09280102362204724,863.8457414215685,0.00025370340306410486,25.0,45.0
570.32715,0.09318032283464567,864.2436683006534,0.00025370340306410486,25.0,45.0
571.92871,0.09356478346456693,864.0390369689542,0.00025370340306410486,25.0,45.0
573.53027,0.09394008858267716,863.5168760212418,0.00025370340306410486,25.0,45.0
575.13184,0.09433063385826772,865.7773948120914,0.00025370340306410486,25.0,45.0
576.7334,0.09469318307086615,863.9000204248365,0.00025370340306410486,25.0,45.0
578.33496,0.09511575984251967,865.63671875,0.00025370340306410486,25.0,45.0
579.93652,0.09550026968503937,864.2151245915032,0.00025370340306410486,25.0,45.0
581.53809,0.09586757086614173,864.930300245098,0.00025370340306410486,25.0,45.0
583.13965,0.09616123031496063,865.7905433006536,0.00025370340306410486,25.0,45.0
584.74121,0.09652046456692913,867.4249387254902,0.00025370340306410486,25.0,45.0
586.34277,0.09690085433070866,867.513454861111,0.00025370340306410486,25.0,45.0
587.94434,0.09728860826771653,868.8745404411765,0.00025370340306410486,25.0,45.0
589.5459,0.0976693562992126,866.6557649101306,0.00025370340306410486,25.0,45.0
591.14746,0.09804972244094488,868.4167177287582,0.00025370340306410486,25.0,45.0
592.74902,0.09844043897637796,867.7147160947711,0.00025370340306410486,25.0,45.0
594.35059,0.09881229921259842,868.707541870915,0.00025370340306410486,25.0,45.0
595.95215,0.09914059251968503,868.5969669117646,0.00025370340306410486,25.0,45.0
597.55371,0.09953075787401575,869.4193218954248,0.00025370340306410486,25.0,45.0
599.15527,0.09995270669291338,870.6869383169934,0.00025370340306410486,25.0,45.0
600.75684,0.10037056102362205,870.4796262254902,0.00025370340306410486,25.0,45.0
602.3584,0.10077889960629922,871.1486928104575,0.00025370340306410486,25.0,45.0
603.95996,0.10116228149606299,871.5404667075163,0.00025370340306410486,25.0,45.0
605.56152,0.10157111417322834,871.76273999183,0.00025370340306410486,25.0,45.0
607.16309,0.10190211811023622,872.9899662990196,0.00025370340306410486,25.0,45.0
608.76465,0.10229034645669291,872.1470077614379,0.00025370340306410486,25.0,45.0
610.36621,0.10262329921259843,871.8433159722222,0.00025370340306410486,25.0,45.0
611.96777,0.10298894094488188,873.6511182598039,0.00025370340306410486,25.0,45.0
613.56934,0.10338318897637794,873.5060763888888,0.00025370340306410486,25.0,45.0
615.1709,0.10375978937007874,873.4873876633986,0.00025370340306410486,25.0,45.0
616.77246,0.10411383858267717,872.7753778594771,0.00025370340306410486,25.0,45.0
618.37402,0.10449928543307085,875.3004238153594,0.00025370340306410486,25.0,45.0
619.97559,0.10489418897637795,875.2228860294117,0.00025370340306410486,25.0,45.0
621.57715,0.10531784055118111,873.5522620506536,0.00025370340306410486,25.0,45.0
623.17871,0.10562772637795276,874.4630055147059,0.00025370340306410486,25.0,45.0
624.78027,0.10604799803149606,875.6233149509803,0.00025370340306410486,25.0,45.0
626.38184,0.10642886811023622,877.2300347222222,0.00025370340306410486,25.0,45.0
627.9834,0.10684964370078741,877.5679381127451,0.00025370340306410486,25.0,45.0
629.58496,0.1072420374015748,876.7827308006536,0.00025370340306410486,25.0,45.0
631.18652,0.10756680118110236,876.5387050653594,0.00025370340306410486,25.0,45.0
632.78809,0.10794935039370078,877.9340022467319,0.00025370340306410486,25.0,45.0
634.38965,0.1083778937007874,878.1083537581699,0.00025370340306410486,25.0,45.0
635.99121,0.10876519488188975,878.0149101307189,0.00025370340306410486,25.0,45.0
637.59277,0.10915920669291339,878.1213745915032,0.00025370340306410486,25.0,45.0
639.19434,0.10953600787401574,878.9504953022875,0.00025370340306410486,25.0,45.0
640.7959,0.10998365157480315,880.4605545343137,0.00025370340306410486,25.0,45.0
642.39746,0.11039774015748033,880.1998825571894,0.00025370340306410486,25.0,45.0
643.99902,0.11072060236220471,878.7606975081699,0.00025370340306410486,25.0,45.0
645.60059,0.11114594291338582,880.7770629084966,0.00025370340306410486,25.0,45.0
647.20215,0.11151804921259843,879.3688725490196,0.00025370340306410486,25.0,45.0
648.80371,0.1118863779527559,881.0845588235294,0.00025370340306410486,25.0,45.0
650.40527,0.11227303346456692,881.2332261029412,0.00025370340306410486,25.0,45.0
652.00684,0.11265743700787402,880.8968035130719,0.00025370340306410486,25.0,45.0
653.6084,0.11304716732283465,881.138148488562,0.00025370340306410486,25.0,45.0
655.20996,0.11340440748031495,881.8942504084966,0.00025370340306410486,25.0,45.0
656.81152,0.11375975984251968,882.3777573529411,0.00025370340306410486,25.0,45.0
658.41309,0.11411572047244094,882.1670751633986,0.00025370340306410486,25.0,45.0
660.01465,0.11450691732283465,882.0574193218954,0.00025370340306410486,25.0,45.0
661.61621,0.11493156496062992,883.5178462009803,0.00025370340306410486,25.0,45.0
663.21777,0.11530962007874015,883.0558619281045,0.00025370340306410486,25.0,45.0
664.81934,0.11567791338582678,884.5097528594771,0.00025370340306410486,25.0,45.0
666.4209,0.11607673622047245,883.7396854575162,0.00025370340306410486,25.0,45.0
668.02246,0.11647369488188977,883.5573682598039,0.00025370340306410486,25.0,45.0
669.62402,0.11688512992125984,884.1660539215685,0.00025370340306410486,25.0,45.0
671.22559,0.11723583661417322,883.4402573529411,0.00025370340306410486,25.0,45.0
672.82715,0.11768006692913385,885.0897416258169,0.00025370340306410486,25.0,45.0
674.42871,0.11808287992125985,886.4407169117646,0.00025370340306410486,25.0,45.0
676.03027,0.11853532283464567,885.7369791666666,0.00025370340306410486,25.0,45.0
677.63184,0.11894221850393699,885.5237438725491,0.00025370340306410486,25.0,45.0
679.2334,0.11930219291338584,886.6525735294117,0.00025370340306410486,25.0,45.0
680.83496,0.11972574999999999,886.5162632761437,0.00025370340306410486,25.0,45.0
682.43652,0.1201777125984252,889.6895680147059,0.00025370340306410486,25.0,45.0
684.03809,0.12061164173228348,886.6812448937908,0.00025370340306410486,25.0,45.0
685.63965,0.1210098779527559,887.098371119281,0.00025370340306410486,25.0,45.0
687.24121,0.12134683267716535,886.3544985702614,0.00025370340306410486,25.0,45.0
688.84277,0.12170508070866141,887.668887867647,0.00025370340306410486,25.0,45.0
690.44434,0.12214923031496064,890.6976613562091,0.00025370340306410486,25.0,45.0
692.0459,0.12250063976377952,886.1564287173202,0.00025370340306410486,25.0,45.0
693.64746,0.12293073228346456,887.5896650326797,0.00025370340306410486,25.0,45.0
695.24902,0.12326328543307087,888.4461805555555,0.00025370340306410486,25.0,45.0
696.85059,0.12364946062992126,890.283905228758,0.00025370340306410486,25.0,45.0
698.45215,0.1240039192913386,890.356694240196,0.00025370340306410486,25.0,45.0
700.05371,0.1244277342519685,891.6505055147059,0.00025370340306410486,25.0,45.0
701.65527,0.1249174192913386,890.645858864379,0.00025370340306410486,25.0,45.0
703.25684,0.12532674409448818,890.0750868055554,0.00025370340306410486,25.0,45.0
704.8584,0.12573638582677166,891.0811121323528,0.00025370340306410486,25.0,45.0
706.45996,0.12612886023622047,891.107102736928,0.00025370340306410486,25.0,45.0
708.06152,0.1265676122047244,891.020960988562,0.00025370340306410486,25.0,45.0
709.66309,0.12701676968503936,891.5978349673202,0.00025370340306410486,25.0,45.0
711.26465,0.1273792086614173,891.2535232843137,0.00025370340306410486,25.0,45.0
712.86621,0.12781986023622047,893.5290032679737,0.00025370340306410486,25.0,45.0
714.46777,0.12822286023622048,893.1411100898691,0.00025370340306410486,25.0,45.0
716.06934,0.1285936062992126,890.9130667892156,0.00025370340306410486,25.0,45.0
717.6709,0.12902040157480316,893.825444240196,0.00025370340306410486,25.0,45.0
719.27246,0.12941407480314962,892.7647569444443,0.00025370340306410486,25.0,45.0
720.87402,0.12980589173228346,892.9734987745097,0.00025370340306410486,25.0,45.0
722.47559,0.1302508622047244,893.7635059232025,0.00025370340306410486,25.0,45.0
724.07715,0.1306546594488189,894.716681985294,0.00025370340306410486,25.0,45.0
725.67871,0.13103157677165353,892.2398641748366,0.00025370340306410486,25.0,45.0
727.28027,0.1313762283464567,893.9870812908496,0.00025370340306410486,25.0,45.0
728.88184,0.13176168700787402,895.0899203431371,0.00025370340306410486,25.0,45.0
730.4834,0.1321576712598425,895.3642258986927,0.00025370340306410486,25.0,45.0
732.08496,0.1325380374015748,894.1362336601306,0.00025370340306410486,25.0,45.0
733.68652,0.1329547775590551,895.7506382761437,0.00025370340306410486,25.0,45.0
735.28809,0.1333593622047244,896.7453788807189,0.00025370340306410486,25.0,45.0
736.88965,0.1338104566929134,895.1217575571895,0.00025370340306410486,25.0,45.0
738.49121,0.13426177362204725,895.7036866830065,0.00025370340306410486,25.0,45.0
740.09277,0.13470067716535433,897.6186427696077,0.00025370340306410486,25.0,45.0
741.69434,0.13513148622047244,895.9236621732026,0.00025370340306410486,25.0,45.0
743.2959,0.13548491338582677,896.4487336601306,0.00025370340306410486,25.0,45.0
744.89746,0.135881437007874,897.7507404003268,0.00025370340306410486,25.0,45.0
746.49902,0.1363120334645669,898.7264093137254,0.00025370340306410486,25.0,45.0
748.10059,0.13671858858267716,897.9617289624183,0.00025370340306410486,25.0,45.0
749.70215,0.13720719291338582,897.1103451797386,0.00025370340306410486,25.0,45.0
751.30371,0.13761266929133856,897.5952818627451,0.00025370340306410486,25.0,45.0
752.90527,0.13803526377952755,899.0939797794117,0.00025370340306410486,25.0,45.0
754.50684,0.13847136417322833,897.6624029820262,0.00025370340306410486,25.0,45.0
756.1084,0.13893717125984253,900.4298662173202,0.00025370340306410486,25.0,45.0
757.70996,0.1393649409448819,898.6468035130719,0.00025370340306410486,25.0,45.0
759.31152,0.13976102952755906,897.5981413398692,0.00025370340306410486,25.0,45.0
760.91309,0.14023641141732285,898.8836039624182,0.00025370340306410486,25.0,45.0
762.51465,0.14063924803149605,898.8310610702613,0.00025370340306410486,25.0,45.0
764.11621,0.14099684055118109,898.6912530637254,0.00025370340306410486,25.0,45.0
765.71777,0.14139210826771653,899.9572099673202,0.00025370340306410486,25.0,45.0
767.31934,0.14175901771653543,899.3588899101308,0.00025370340306410486,25.0,45.0
768.9209,0.14220399803149608,900.9384446486928,0.00025370340306410486,25.0,45.0
770.52246,0.1426866909448819,901.0486366421568,0.00025370340306410486,25.0,45.0
772.12402,0.14310077952755904,902.2169117647057,0.00025370340306410486,25.0,45.0
773.72559,0.14355196653543306,901.3228400735294,0.00025370340306410486,25.0,45.0
775.32715,0.1439700688976378,900.5331648284313,0.00025370340306410486,25.0,45.0
776.92871,0.14441903937007874,902.0379646650326,0.00025370340306410486,25.0,45.0
778.53027,0.14488496456692912,902.6943167892156,0.00025370340306410486,25.0,45.0
780.13184,0.14530819291338581,900.6197916666665,0.00025370340306410486,25.0,45.0
781.7334,0.14575006496062992,902.6025582107843,0.00025370340306410486,25.0,45.0
783.33496,0.14613663779527558,903.0320925245097,0.00025370340306410486,25.0,45.0
784.93652,0.14658160826771655,904.5118974673202,0.00025370340306410486,25.0,45.0
786.53809,0.14708842322834645,903.0410028594771,0.00025370340306410486,25.0,45.0
788.13965,0.1475070531496063,901.7929432189542,0.00025370340306410486,25.0,45.0
789.74121,0.14792260629921258,902.8919781454247,0.00025370340306410486,25.0,45.0
791.34277,0.14831278346456694,902.4485294117646,0.00025370340306410486,25.0,45.0
792.94434,0.1487521437007874,904.3944035947711,0.00025370340306410486,25.0,45.0
794.5459,0.14923877755905512,903.82626123366,0.00025370340306410486,25.0,45.0
796.14746,0.1496501909448819,903.7328941993463,0.00025370340306410486,25.0,45.0
797.74902,0.15009237992125984,904.3398692810456,0.00025370340306410486,25.0,45.0
799.35059,0.15048254330708663,902.4588950163399,0.00025370340306410486,25.0,45.0
800.95215,0.15094430511811022,906.6925806781046,0.00025370340306410486,25.0,45.0
802.55371,0.1513764035433071,905.8623876633986,0.00025370340306410486,25.0,45.0
804.15527,0.15179024409448819,904.180606617647,0.00025370340306410486,25.0,45.0
805.75684,0.15222920669291337,905.6899254493463,0.00025370340306410486,25.0,45.0
807.3584,0.15270082283464567,905.6147365196078,0.00025370340306410486,25.0,45.0
808.95996,0.15311412401574803,904.5145271650325,0.00025370340306410486,25.0,45.0
810.56152,0.1535751811023622,906.2106311274509,0.00025370340306410486,25.0,45.0
812.16309,0.15399180314960628,905.0199142156863,0.00025370340306410486,25.0,45.0
813.76465,0.15441830511811025,905.2568933823529,0.00025370340306410486,25.0,45.0
815.36621,0.15488692913385826,907.9787837009803,0.00025370340306410486,25.0,45.0
816.96777,0.15540728346456692,907.4213643790849,0.00025370340306410486,25.0,45.0
818.56934,0.1558342559055118,908.116983251634,0.00025370340306410486,25.0,45.0
820.1709,0.15629398622047244,906.4325214460783,0.00025370340306410486,25.0,45.0
821.77246,0.15672508661417323,907.8083129084966,0.00025370340306410486,25.0,45.0
823.37402,0.15711599015748032,906.9262663398691,0.00025370340306410486,25.0,45.0
824.97559,0.15755935236220472,906.7373366013071,0.00025370340306410486,25.0,45.0
826.57715,0.1580392283464567,909.1678410947712,0.00025370340306410486,25.0,45.0
828.17871,0.15847922244094487,907.4426062091503,0.00025370340306410486,25.0,45.0
829.78027,0.158961094488189,906.6215277777777,0.00025370340306410486,25.0,45.0
831.38184,0.15935402755905512,906.6230851715685,0.00025370340306410486,25.0,45.0
832.9834,0.15979973622047244,909.5807291666665,0.00025370340306410486,25.0,45.0
834.58496,0.16032215551181103,907.9506229575163,0.00025370340306410486,25.0,45.0
836.18652,0.16079189566929133,909.0767718545751,0.00025370340306410486,25.0,45.0
837.78809,0.16131750787401575,909.0001531862745,0.00025370340306410486,25.0,45.0
839.38965,0.16170768307086614,909.676393995098,0.00025370340306410486,25.0,45.0
840.99121,0.16215542125984253,906.8126276552287,0.00025370340306410486,25.0,45.0
842.59277,0.16257944685039372,910.381561478758,0.00025370340306410486,25.0,45.0
844.19434,0.16310455511811023,911.3405841503267,0.00025370340306410486,25.0,45.0
845.7959,0.16362224803149605,908.9137561274508,0.00025370340306410486,25.0,45.0
847.39746,0.16401237598425197,909.451873978758,0.00025370340306410486,25.0,45.0
848.99902,0.16448108267716535,909.7701950571895,0.00025370340306410486,25.0,45.0
850.60059,0.16496028937007876,910.8731617647059,0.00025370340306410486,25.0,45.0
852.20215,0.1654447539370079,909.5450622957516,0.00025370340306410486,25.0,45.0
853.80371,0.1658788346456693,908.9290492238562,0.00025370340306410486,25.0,45.0
855.40527,0.16637565354330708,911.809206495098,0.00025370340306410486,25.0,45.0
857.00684,0.16692107086614172,910.0017105800653,0.00025370340306410486,25.0,45.0
858.6084,0.16735511811023623,909.567938112745,0.00025370340306410486,25.0,45.0
860.20996,0.16777420275590552,910.5888735702614,0.00025370340306410486,25.0,45.0
861.81152,0.16827461220472442,912.1528288398692,0.00025370340306410486,25.0,45.0
863.41309,0.16872819488188975,912.1000306372548,0.00025370340306410486,25.0,45.0
865.01465,0.16918138976377953,911.4114583333333,0.00025370340306410486,25.0,45.0
866.61621,0.16963222637795275,912.9176368464051,0.00025370340306410486,25.0,45.0
868.21777,0.17009883267716536,911.0593596813725,0.00025370340306410486,25.0,45.0
869.81934,0.17054164173228348,910.5890522875817,0.00025370340306410486,25.0,45.0
871.4209,0.1710632657480315,913.1623519199346,0.00025370340306410486,25.0,45.0
873.02246,0.17160494094488188,910.7185202205882,0.00025370340306410486,25.0,45.0
874.62402,0.1720471771653543,912.3389501633986,0.00025370340306410486,25.0,45.0
876.22559,0.17257928937007874,912.0021701388888,0.00025370340306410486,25.0,45.0
877.82715,0.173055562992126,911.7466809640522,0.00025370340306410486,25.0,45.0
879.42871,0.17346529724409449,912.3477328431372,0.00025370340306410486,25.0,45.0
881.03027,0.17394225196850394,913.0398029003268,0.00025370340306410486,25.0,45.0
882.63184,0.1744197224409449,913.0884395424836,0.00025370340306410486,25.0,45.0
884.2334,0.17490688582677164,913.6362081290848,0.00025370340306410486,25.0,45.0
885.83496,0.17545570472440944,913.0493515114377,0.00025370340306410486,25.0,45.0
887.43652,0.17592719291338582,915.3829912173202,0.00025370340306410486,25.0,45.0
889.03809,0.1764256653543307,912.0746783088234,0.00025370340306410486,25.0,45.0
890.63965,0.1769879094488189,913.8220230800653,0.00025370340306410486,25.0,45.0
892.24121,0.1774783090551181,912.8590430964051,0.00025370340306410486,25.0,45.0
893.84277,0.17796208070866143,912.6236979166666,0.00025370340306410486,25.0,45.0
895.44434,0.17844263779527558,913.5301011029411,0.00025370340306410486,25.0,45.0
897.0459,0.17890239173228348,912.7393790849673,0.00025370340306410486,25.0,45.0
898.64746,0.17944806692913384,914.0518790849673,0.00025370340306410486,25.0,45.0
900.24902,0.17995589173228346,912.5858609068626,0.00025370340306410486,25.0,45.0
901.85059,0.18041402559055117,913.437295751634,0.00025370340306410486,25.0,45.0
903.45215,0.18092785826771654,913.5375306372548,0.00025370340306410486,25.0,45.0
905.05371,0.18140754527559055,913.6503523284314,0.00025370340306410486,25.0,45.0
906.65527,0.18188589763779525,914.7809180964051,0.00025370340306410486,25.0,45.0
908.25684,0.18242147047244095,915.3478860294116,0.00025370340306410486,25.0,45.0
909.8584,0.1830130688976378,914.8962418300653,0.00025370340306410486,25.0,45.0
911.45996,0.18357038582677165,914.5299734477123,0.00025370340306410486,25.0,45.0
913.06152,0.1840211751968504,912.6155790441177,0.00025370340306410486,25.0,45.0
914.66309,0.18446966338582677,912.6274254493463,0.00025370340306410486,25.0,45.0
916.26465,0.18495097244094486,914.8112745098039,0.00025370340306410486,25.0,45.0
917.86621,0.1854941594488189,914.7310049019608,0.00025370340306410486,25.0,45.0
919.46777,0.18604664173228347,915.7074908088234,0.00025370340306410486,25.0,45.0
921.06934,0.18659509842519684,915.1250510620914,0.00025370340306410486,25.0,45.0
922.6709,0.1871574468503937,916.7009293300653,0.00025370340306410486,25.0,45.0
924.27246,0.18769354724409448,914.6727685866013,0.00025370340306410486,25.0,45.0
925.87402,0.1882273622047244,913.9297896241828,0.00025370340306410486,25.0,45.0
927.47559,0.1886975688976378,914.8242953431371,0.00025370340306410486,25.0,45.0
929.07715,0.18924634251968503,915.6703431372549,0.00025370340306410486,25.0,45.0
930.67871,0.18982217322834646,915.8787785947711,0.00025370340306410486,25.0,45.0
932.28027,0.190367062992126,915.0163398692811,0.00025370340306410486,25.0,45.0
933.88184,0.19089973818897638,915.5595128676471,0.00025370340306410486,25.0,45.0
935.4834,0.1914372598425197,916.310840482026,0.00025370340306410486,25.0,45.0
937.08496,0.19204636417322835,917.5078124999999,0.00025370340306410486,25.0,45.0
938.68652,0.19260400787401574,915.3047640931372,0.00025370340306410486,25.0,45.0
940.28809,0.19306650787401575,914.2939899918299,0.00025370340306410486,25.0,45.0
941.88965,0.1935914625984252,914.9798815359477,0.00025370340306410486,25.0,45.0
943.49121,0.19408213385826772,916.306934232026,0.00025370340306410486,25.0,45.0
945.09277,0.19459082677165354,915.1268637663397,0.00025370340306410486,25.0,45.0
946.69434,0.19512344291338582,918.2193116830065,0.00025370340306410486,25.0,45.0
948.2959,0.19572446456692913,917.06063623366,0.00025370340306410486,25.0,45.0
949.89746,0.1963967755905512,915.9527675653594,0.00025370340306410486,25.0,45.0
951.49902,0.1969572440944882,916.2537020016339,0.00025370340306410486,25.0,45.0
953.10059,0.19746937007874016,918.3259803921568,0.00025370340306410486,25.0,45.0
954.70215,0.19800529527559055,916.6311785130719,0.00025370340306410486,25.0,45.0
956.30371,0.19850096456692914,914.1789215686274,0.00025370340306410486,25.0,45.0
957.90527,0.19901496062992124,917.4349468954248,0.00025370340306410486,25.0,45.0
959.50684,0.19973100393700788,917.8147212009802,0.00025370340306410486,25.0,45.0
961.1084,0.2004376771653543,917.0209865196078,0.00025370340306410486,25.0,45.0
962.70996,0.20097667322834648,917.8857741013072,0.00025370340306410486,25.0,45.0
964.31152,0.20150013779527556,916.114200367647,0.00025370340306410486,25.0,45.0
965.91309,0.20209395669291338,917.4021650326797,0.00025370340306410486,25.0,45.0
967.51465,0.20258543307086613,916.9433210784313,0.00025370340306410486,25.0,45.0
969.11621,0.2031122440944882,916.5073274101306,0.00025370340306410486,25.0,45.0
970.71777,0.20368842519685038,917.0710529003268,0.00025370340306410486,25.0,45.0
972.31934,0.20425641732283464,916.4911662581699,0.00025370340306410486,25.0,45.0
973.9209,0.20484307086614173,915.9916513480391,0.00025370340306410486,25.0,45.0
975.52246,0.20538433070866144,918.80672998366,0.00025370340306410486,25.0,45.0
977.12402,0.2059623622047244,916.8141084558823,0.00025370340306410486,25.0,45.0
978.72559,0.206606437007874,918.0199908088234,0.00025370340306410486,25.0,45.0
980.32715,0.20717399606299214,916.9734477124182,0.00025370340306410486,25.0,45.0
981.92871,0.20777456692913385,916.3405330882352,0.00025370340306410486,25.0,45.0
983.53027,0.20836279527559057,917.522390727124,0.00025370340306410486,25.0,45.0
985.13184,0.2090542716535433,918.3631280637254,0.00025370340306410486,25.0,45.0
986.7334,0.2096948622047244,917.0298457924837,0.00025370340306410486,25.0,45.0
988.33496,0.21031301181102363,919.5224162581699,0.00025370340306410486,25.0,45.0
989.93652,0.2109021653543307,918.125510620915,0.00025370340306410486,25.0,45.0
991.53809,0.2114517716535433,916.0283139297385,0.00025370340306410486,25.0,45.0
993.13965,0.2120313779527559,917.9202665441176,0.00025370340306410486,25.0,45.0
994.74121,0.2126550393700787,918.6071537990196,0.00025370340306410486,25.0,45.0
995.3418,0.21292061023622047,920.0210886437908,0.00025370340306410486,25.0,45.0