File: datasets/am_bench_2022/csv/45-XY.08-4.csv
Time(s),Strain(%),Stress(MPa),SR(s-1),Temp(C),Angle(deg)
30.275146,2.047295275590551e-05,13.506552631578948,0.00025370340306410486,25.0,45.0
31.776611,4.2392860236220476e-05,19.434965428276573,0.00025370340306410486,25.0,45.0
33.278076,6.623099606299213e-05,25.806315789473683,0.00025370340306410486,25.0,45.0
34.779541,8.980676574803149e-05,31.68104489164087,0.00025370340306410486,25.0,45.0
36.281006,0.00010153213779527559,36.868926728586175,0.00025370340306410486,25.0,45.0
37.782471,0.00010929136811023622,41.29107069143446,0.00025370340306410486,25.0,45.0
39.283936,0.00012687307283464568,48.333516511867906,0.00025370340306410486,25.0,45.0
40.7854,0.00015937289566929133,55.45755675954592,0.00025370340306410486,25.0,45.0
42.286865,0.000166486812992126,61.023054695562436,0.00025370340306410486,25.0,45.0
43.78833,0.00018348125984251967,69.74033539731683,0.00025370340306410486,25.0,45.0
45.289795,0.0001995738779527559,77.89726006191951,0.00025370340306410486,25.0,45.0
46.79126,0.0002333143307086614,84.1340737874097,0.00025370340306410486,25.0,45.0
48.292725,0.0002574741141732283,92.48311145510836,0.00025370340306410486,25.0,45.0
49.794189,0.00027295307086614177,100.63261867905057,0.00025370340306410486,25.0,45.0
51.295654,0.0003148954330708661,107.78217234262125,0.00025370340306410486,25.0,45.0
52.797119,0.0003227643700787402,116.49139834881322,0.00025370340306410486,25.0,45.0
54.298584,0.00036527377952755904,126.17320949432406,0.00025370340306410486,25.0,45.0
55.800049,0.0003774051181102362,133.35268317853456,0.00025370340306410486,25.0,45.0
57.301514,0.00040467377952755907,143.05552631578948,0.00025370340306410486,25.0,45.0
58.802979,0.0004448602165354331,153.03795407636738,0.00025370340306410486,25.0,45.0
60.304443,0.000465057125984252,161.65806759545924,0.00025370340306410486,25.0,45.0
61.805908,0.0004887710039370079,171.1815995872033,0.00025370340306410486,25.0,45.0
63.307373,0.0005374691535433071,183.51896800825594,0.00025370340306410486,25.0,45.0
64.808838,0.000562056437007874,194.79370227038186,0.00025370340306410486,25.0,45.0
66.310303,0.0005789637795275591,204.74476264189886,0.00025370340306410486,25.0,45.0
67.811768,0.0006117243307086614,216.18423890608875,0.00025370340306410486,25.0,45.0
69.313232,0.0006686453346456693,227.08769091847265,0.00025370340306410486,25.0,45.0
70.814697,0.0007039089566929134,238.91793085655314,0.00025370340306410486,25.0,45.0
72.316162,0.0007327156889763779,250.60713880288958,0.00025370340306410486,25.0,45.0
73.817627,0.000748079311023622,260.80175438596495,0.00025370340306410486,25.0,45.0
75.319092,0.0008018601181102362,273.6140608875129,0.00025370340306410486,25.0,45.0
76.820557,0.0008386181299212599,285.96145510835913,0.00025370340306410486,25.0,45.0
78.322021,0.0008894161811023622,297.02412280701753,0.00025370340306410486,25.0,45.0
79.823486,0.0009172453937007875,308.19303405572754,0.00025370340306410486,25.0,45.0
81.324951,0.0009463959842519686,315.4441176470588,0.00025370340306410486,25.0,45.0
82.826416,0.0009914764763779527,327.8385706914345,0.00025370340306410486,25.0,45.0
84.327881,0.0010105697834645669,337.7944530443757,0.00025370340306410486,25.0,45.0
85.829346,0.001058954094488189,350.7676470588235,0.00025370340306410486,25.0,45.0
87.330811,0.001093339881889764,361.4955882352941,0.00025370340306410486,25.0,45.0
88.832275,0.0011201723425196851,369.4174664602683,0.00025370340306410486,25.0,45.0
90.33374,0.0011648049606299213,381.2133642930857,0.00025370340306410486,25.0,45.0
91.835205,0.0011773774409448818,390.9436016511868,0.00025370340306410486,25.0,45.0
93.33667,0.001229332874015748,402.74930340557273,0.00025370340306410486,25.0,45.0
94.838135,0.0012822966141732284,413.77262641898864,0.00025370340306410486,25.0,45.0
96.3396,0.00130283687007874,423.774484004128,0.00025370340306410486,25.0,45.0
97.841064,0.001343002342519685,435.11847265221877,0.00025370340306410486,25.0,45.0
99.342529,0.0013776245472440945,445.34827141382874,0.00025370340306410486,25.0,45.0
100.84399,0.0014212092519685039,455.34138286893705,0.00025370340306410486,25.0,45.0
102.34546,0.0014566777952755906,466.8875128998968,0.00025370340306410486,25.0,45.0
103.84692,0.0014916758070866142,475.92474200206397,0.00025370340306410486,25.0,45.0
105.34839,0.0015146352952755905,483.6862487100104,0.00025370340306410486,25.0,45.0
106.84985,0.0015297122637795276,496.3199432404541,0.00025370340306410486,25.0,45.0
108.35132,0.0015729099606299213,505.01271929824566,0.00025370340306410486,25.0,45.0
109.85278,0.0016054413582677167,513.6238132094943,0.00025370340306410486,25.0,45.0
111.35425,0.0016462360236220472,525.0992776057791,0.00025370340306410486,25.0,45.0
112.85571,0.0016822503543307088,531.5899380804954,0.00025370340306410486,25.0,45.0
114.35718,0.0016887945472440944,539.9609649122807,0.00025370340306410486,25.0,45.0
115.85864,0.001730689566929134,547.4282765737873,0.00025370340306410486,25.0,45.0
117.36011,0.0017372159842519684,554.9789989680082,0.00025370340306410486,25.0,45.0
118.86157,0.0017655149803149606,562.064189886481,0.00025370340306410486,25.0,45.0
120.36304,0.0017831281692913385,570.7059339525284,0.00025370340306410486,25.0,45.0
121.8645,0.0018072655511811022,575.3645510835913,0.00025370340306410486,25.0,45.0
123.36597,0.001843629842519685,581.8043085655315,0.00025370340306410486,25.0,45.0
124.86743,0.001877411751968504,586.526367389061,0.00025370340306410486,25.0,45.0
126.3689,0.0018938486811023623,593.0827657378741,0.00025370340306410486,25.0,45.0
127.87036,0.0019242343503937007,597.5688338493293,0.00025370340306410486,25.0,45.0
129.37183,0.0019477641732283464,603.4786635706914,0.00025370340306410486,25.0,45.0
130.87329,0.0019671149803149606,610.2727554179567,0.00025370340306410486,25.0,45.0
132.37476,0.0020074933070866143,615.7588235294118,0.00025370340306410486,25.0,45.0
133.87622,0.0020153307086614174,619.1866099071207,0.00025370340306410486,25.0,45.0
135.37769,0.002044556299212598,624.1208720330238,0.00025370340306410486,25.0,45.0
136.87915,0.002067136811023622,630.1508255933952,0.00025370340306410486,25.0,45.0
138.38062,0.002092743897637795,634.0423890608876,0.00025370340306410486,25.0,45.0
139.88208,0.0021330738188976377,639.065737874097,0.00025370340306410486,25.0,45.0
141.38354,0.002163458661417323,642.3953302373582,0.00025370340306410486,25.0,45.0
142.88501,0.002173820275590551,644.809520123839,0.00025370340306410486,25.0,45.0
144.38647,0.002212904527559055,650.7711300309597,0.00025370340306410486,25.0,45.0
145.88794,0.0022463838582677167,655.0272187822497,0.00025370340306410486,25.0,45.0
147.3894,0.0022835824803149607,659.6233230134159,0.00025370340306410486,25.0,45.0
148.89087,0.0023222399606299213,663.1254385964912,0.00025370340306410486,25.0,45.0
150.39233,0.002336802559055118,666.2693498452013,0.00025370340306410486,25.0,45.0
151.8938,0.0023907374015748033,670.5131320949432,0.00025370340306410486,25.0,45.0
153.39526,0.0024122112204724407,673.6926470588236,0.00025370340306410486,25.0,45.0
154.89673,0.002463667125984252,677.2097523219813,0.00025370340306410486,25.0,45.0
156.39819,0.00249956968503937,680.1566305469556,0.00025370340306410486,25.0,45.0
157.89966,0.002558072440944882,684.7976264189887,0.00025370340306410486,25.0,45.0
159.40112,0.002604033070866142,687.0759029927762,0.00025370340306410486,25.0,45.0
160.90259,0.0026338232283464567,690.4102167182663,0.00025370340306410486,25.0,45.0
162.40405,0.0026827368110236218,693.1857843137255,0.00025370340306410486,25.0,45.0
163.90552,0.002734632480314961,694.9545407636739,0.00025370340306410486,25.0,45.0
165.40698,0.002791889960629921,699.212951496388,0.00025370340306410486,25.0,45.0
166.90845,0.002852019094488189,702.4300567595459,0.00025370340306410486,25.0,45.0
168.40991,0.002915724212598425,704.5976522187823,0.00025370340306410486,25.0,45.0
169.91138,0.0030135165354330706,707.4348039215687,0.00025370340306410486,25.0,45.0
171.41284,0.0030905377952755906,711.4409700722395,0.00025370340306410486,25.0,45.0
172.91431,0.0031847212598425196,713.4684210526316,0.00025370340306410486,25.0,45.0
174.41577,0.0032823271653543303,717.1760577915377,0.00025370340306410486,25.0,45.0
175.91724,0.003424522244094488,720.4274251805986,0.00025370340306410486,25.0,45.0
177.4187,0.0035135442913385826,722.7685500515995,0.00025370340306410486,25.0,45.0
178.92017,0.0036284929133858267,724.3001031991745,0.00025370340306410486,25.0,45.0
180.42163,0.0037566322834645667,727.880572755418,0.00025370340306410486,25.0,45.0
181.9231,0.003884497244094488,729.7828173374613,0.00025370340306410486,25.0,45.0
183.42456,0.004035285039370079,731.712693498452,0.00025370340306410486,25.0,45.0
184.92603,0.004182350393700787,734.0314757481941,0.00025370340306410486,25.0,45.0
186.42749,0.0043557153543307085,735.8182404540764,0.00025370340306410486,25.0,45.0
187.92896,0.00449361751968504,739.6039215686275,0.00025370340306410486,25.0,45.0
189.43042,0.004671402559055118,739.7096233230135,0.00025370340306410486,25.0,45.0
190.93188,0.004898815354330709,741.9337977296182,0.00025370340306410486,25.0,45.0
192.43335,0.0050557535433070865,742.5748710010321,0.00025370340306410486,25.0,45.0
193.93481,0.005267310039370078,746.9406862745099,0.00025370340306410486,25.0,45.0
195.43628,0.005497266141732284,746.9345717234262,0.00025370340306410486,25.0,45.0
196.93774,0.005682548228346456,747.8731424148607,0.00025370340306410486,25.0,45.0
198.43921,0.005888817125984252,751.2196336429308,0.00025370340306410486,25.0,45.0
199.94067,0.006112638582677165,752.7599329205367,0.00025370340306410486,25.0,45.0
201.44214,0.006345184251968504,753.2039989680084,0.00025370340306410486,25.0,45.0
202.9436,0.006572059645669291,753.9641382868937,0.00025370340306410486,25.0,45.0
204.44507,0.006787739173228347,753.7826109391125,0.00025370340306410486,25.0,45.0
205.94653,0.007042366535433072,757.098839009288,0.00025370340306410486,25.0,45.0
207.448,0.007313777362204724,758.1857069143448,0.00025370340306410486,25.0,45.0
208.94946,0.007578570669291339,758.8664860681115,0.00025370340306410486,25.0,45.0
210.45093,0.007888217913385826,759.9027605779154,0.00025370340306410486,25.0,45.0
211.95239,0.008182443307086614,762.4709494324045,0.00025370340306410486,25.0,45.0
213.45386,0.00842262244094488,762.3648864809082,0.00025370340306410486,25.0,45.0
214.95532,0.00869918937007874,762.5127192982457,0.00025370340306410486,25.0,45.0
216.45679,0.00898025216535433,765.7000257997937,0.00025370340306410486,25.0,45.0
217.95825,0.009243037795275591,764.8848813209495,0.00025370340306410486,25.0,45.0
219.45972,0.009526910039370078,766.9545407636739,0.00025370340306410486,25.0,45.0
220.96118,0.009859340748031497,767.3479102167182,0.00025370340306410486,25.0,45.0
222.46265,0.010129416338582678,769.1249742002065,0.00025370340306410486,25.0,45.0
223.96411,0.010395562598425195,769.827786377709,0.00025370340306410486,25.0,45.0
225.46558,0.010692673622047245,770.5435242518059,0.00025370340306410486,25.0,45.0
226.96704,0.011051462401574803,772.2414344685243,0.00025370340306410486,25.0,45.0
228.46851,0.011406525787401575,773.3835913312694,0.00025370340306410486,25.0,45.0
229.96997,0.011688686417322834,772.0184468524252,0.00025370340306410486,25.0,45.0
231.47144,0.011974913385826772,773.2877192982456,0.00025370340306410486,25.0,45.0
232.9729,0.012300285236220471,775.3438338493293,0.00025370340306410486,25.0,45.0
234.47437,0.012606546653543308,775.8035087719298,0.00025370340306410486,25.0,45.0
235.97583,0.012941305118110237,776.134649122807,0.00025370340306410486,25.0,45.0
237.47729,0.013257787598425197,777.1458462332301,0.00025370340306410486,25.0,45.0
238.97876,0.013591853740157481,779.019040247678,0.00025370340306410486,25.0,45.0
240.48022,0.013937274606299212,779.6573013415893,0.00025370340306410486,25.0,45.0
241.98169,0.01428607027559055,780.4733488132096,0.00025370340306410486,25.0,45.0
243.48315,0.014644642716535435,780.7512125902992,0.00025370340306410486,25.0,45.0
244.98462,0.014977075000000001,782.5240454076368,0.00025370340306410486,25.0,45.0
246.48608,0.015365735629921258,782.463596491228,0.00025370340306410486,25.0,45.0
247.98755,0.01569448523622047,784.464963880289,0.00025370340306410486,25.0,45.0
249.48901,0.016076865748031497,783.5357585139318,0.00025370340306410486,25.0,45.0
250.99048,0.016393518307086612,785.7882610939113,0.00025370340306410486,25.0,45.0
252.49194,0.016719336023622047,784.6112229102167,0.00025370340306410486,25.0,45.0
253.99341,0.017069709842519685,787.4159442724458,0.00025370340306410486,25.0,45.0
255.49487,0.017389631692913386,785.707972136223,0.00025370340306410486,25.0,45.0
256.99634,0.017716345472440945,786.0143962848298,0.00025370340306410486,25.0,45.0
258.4978,0.018047432874015747,787.677141382869,0.00025370340306410486,25.0,45.0
259.99927,0.018418449803149606,787.6936532507741,0.00025370340306410486,25.0,45.0
261.50073,0.01876678779527559,790.5787925696594,0.00025370340306410486,25.0,45.0
263.0022,0.019144164173228347,792.1378740970072,0.00025370340306410486,25.0,45.0
264.50366,0.01952029094488189,791.3197368421053,0.00025370340306410486,25.0,45.0
266.00513,0.01987277559055118,791.4997420020641,0.00025370340306410486,25.0,45.0
267.50659,0.020186944881889764,791.4222652218783,0.00025370340306410486,25.0,45.0
269.00806,0.02053142913385827,793.4662280701755,0.00025370340306410486,25.0,45.0
270.50952,0.020859909448818895,794.0974200206399,0.00025370340306410486,25.0,45.0
272.01099,0.02119345472440945,793.4675438596491,0.00025370340306410486,25.0,45.0
273.51245,0.021549490157480315,795.0426728586172,0.00025370340306410486,25.0,45.0
275.01392,0.02188121653543307,795.3150412796697,0.00025370340306410486,25.0,45.0
276.51538,0.02217685433070866,795.5874613003097,0.00025370340306410486,25.0,45.0
278.01685,0.02253758464566929,796.6131062951497,0.00025370340306410486,25.0,45.0
279.51831,0.022900055118110236,796.6037151702786,0.00025370340306410486,25.0,45.0
281.01978,0.023254698818897638,798.7699948400412,0.00025370340306410486,25.0,45.0
282.52124,0.02364428346456693,798.8719040247678,0.00025370340306410486,25.0,45.0
284.02271,0.02398429527559055,799.1332301341589,0.00025370340306410486,25.0,45.0
285.52417,0.02434676181102362,800.3262383900928,0.00025370340306410486,25.0,45.0
287.02563,0.02470746062992126,800.828302373581,0.00025370340306410486,25.0,45.0
288.5271,0.02508315748031496,801.5526057791537,0.00025370340306410486,25.0,45.0
290.02856,0.02536236811023622,800.8684984520123,0.00025370340306410486,25.0,45.0
291.53003,0.025706068897637793,802.9614551083591,0.00025370340306410486,25.0,45.0
293.03149,0.026080106299212598,804.1167698658411,0.00025370340306410486,25.0,45.0
294.53296,0.02639840748031496,802.1889060887513,0.00025370340306410486,25.0,45.0
296.03442,0.026751614173228345,805.9135448916409,0.00025370340306410486,25.0,45.0
297.53589,0.027114938976377952,805.8666408668731,0.00025370340306410486,25.0,45.0
299.03735,0.027476096456692915,805.8346233230134,0.00025370340306410486,25.0,45.0
300.53882,0.027764110236220472,804.8700980392157,0.00025370340306410486,25.0,45.0
302.04028,0.028106834645669293,809.4904540763674,0.00025370340306410486,25.0,45.0
303.54175,0.028436706692913385,805.9856811145511,0.00025370340306410486,25.0,45.0
305.04321,0.028757043307086613,807.5192466460268,0.00025370340306410486,25.0,45.0
306.54468,0.029099887795275593,810.0863777089784,0.00025370340306410486,25.0,45.0
308.04614,0.029462259842519684,809.4581269349845,0.00025370340306410486,25.0,45.0
309.54761,0.029785218503937005,809.8325335397317,0.00025370340306410486,25.0,45.0
311.04907,0.030146216535433073,811.2273219814242,0.00025370340306410486,25.0,45.0
312.55054,0.030473226377952755,810.6703818369452,0.00025370340306410486,25.0,45.0
314.052,0.030815411417322833,812.2520897832818,0.00025370340306410486,25.0,45.0
315.55347,0.031159220472440942,812.6710784313726,0.00025370340306410486,25.0,45.0
317.05493,0.03149465157480315,812.0246388028895,0.00025370340306410486,25.0,45.0
318.5564,0.03185288976377952,813.6397058823529,0.00025370340306410486,25.0,45.0
320.05786,0.032242348425196854,813.8265737874096,0.00025370340306410486,25.0,45.0
321.55933,0.032623602362204726,815.7285087719298,0.00025370340306410486,25.0,45.0
323.06079,0.032979161417322836,812.4608101135192,0.00025370340306410486,25.0,45.0
324.56226,0.033328793307086615,814.4906604747163,0.00025370340306410486,25.0,45.0
326.06372,0.03365411417322835,816.0999484004128,0.00025370340306410486,25.0,45.0
327.56519,0.034014692913385824,815.2636480908152,0.00025370340306410486,25.0,45.0
329.06665,0.03433742913385827,817.3032507739939,0.00025370340306410486,25.0,45.0
330.56812,0.03468879133858268,818.645278637771,0.00025370340306410486,25.0,45.0
332.06958,0.035095860236220466,819.8541279669763,0.00025370340306410486,25.0,45.0
333.57104,0.035427,818.7182920536636,0.00025370340306410486,25.0,45.0
335.07251,0.03575274409448819,818.3167956656347,0.00025370340306410486,25.0,45.0
336.57397,0.03605554133858268,818.5173374613003,0.00025370340306410486,25.0,45.0
338.07544,0.036404974409448815,819.8356811145511,0.00025370340306410486,25.0,45.0
339.5769,0.036802383858267715,821.362306501548,0.00025370340306410486,25.0,45.0
341.07837,0.03715558858267716,820.211274509804,0.00025370340306410486,25.0,45.0
342.57983,0.03749539566929134,823.453689370485,0.00025370340306410486,25.0,45.0
344.0813,0.03787720669291338,823.2641640866873,0.00025370340306410486,25.0,45.0
345.58276,0.038259893700787403,824.5243034055728,0.00025370340306410486,25.0,45.0
347.08423,0.03860793503937008,823.0729360165119,0.00025370340306410486,25.0,45.0
348.58569,0.03894016535433071,824.724226006192,0.00025370340306410486,25.0,45.0
350.08716,0.03930643307086614,824.4400928792569,0.00025370340306410486,25.0,45.0
351.58862,0.03964048622047244,824.2026315789474,0.00025370340306410486,25.0,45.0
353.09009,0.03995002165354331,824.2469040247678,0.00025370340306410486,25.0,45.0
354.59155,0.04031193307086614,826.2591847265221,0.00025370340306410486,25.0,45.0
356.09302,0.040692141732283464,825.0429566563467,0.00025370340306410486,25.0,45.0
357.59448,0.04107277755905511,827.0933952528379,0.00025370340306410486,25.0,45.0
359.09595,0.04141575984251968,827.3990712074303,0.00025370340306410486,25.0,45.0
360.59741,0.04172457086614173,827.2666150670794,0.00025370340306410486,25.0,45.0
362.09888,0.04204952165354331,828.5496646026833,0.00025370340306410486,25.0,45.0
363.60034,0.042420068897637796,829.7250257997937,0.00025370340306410486,25.0,45.0
365.10181,0.04282843700787401,830.644943240454,0.00025370340306410486,25.0,45.0
366.60327,0.04318157086614173,830.0768059855521,0.00025370340306410486,25.0,45.0
368.10474,0.04354665157480315,830.1001805985552,0.00025370340306410486,25.0,45.0
369.6062,0.043910885826771655,832.6817853457172,0.00025370340306410486,25.0,45.0
371.10767,0.04425986614173228,831.1457688338494,0.00025370340306410486,25.0,45.0
372.60913,0.044629440944881894,832.3290505675955,0.00025370340306410486,25.0,45.0
374.1106,0.04491830708661417,834.0893704850362,0.00025370340306410486,25.0,45.0
375.61206,0.04524093110236221,833.2387770897833,0.00025370340306410486,25.0,45.0
377.11353,0.04556533661417323,833.6184726522188,0.00025370340306410486,25.0,45.0
378.61499,0.04586506102362205,833.3410732714138,0.00025370340306410486,25.0,45.0
380.11646,0.046175944881889766,833.958617131063,0.00025370340306410486,25.0,45.0
381.61792,0.04653391732283464,836.1686016511868,0.00025370340306410486,25.0,45.0
383.11938,0.04693133267716536,837.4511609907121,0.00025370340306410486,25.0,45.0
384.62085,0.047279017716535435,835.4666666666667,0.00025370340306410486,25.0,45.0
386.12231,0.047632964566929135,836.8301083591332,0.00025370340306410486,25.0,45.0
387.62378,0.048028801181102365,837.7623839009287,0.00025370340306410486,25.0,45.0
389.12524,0.04836337401574803,836.8719298245614,0.00025370340306410486,25.0,45.0
390.62671,0.0487275157480315,839.2212332301342,0.00025370340306410486,25.0,45.0
392.12817,0.04906874015748031,837.6808823529411,0.00025370340306410486,25.0,45.0
393.62964,0.04941626968503937,838.9699948400413,0.00025370340306410486,25.0,45.0
395.1311,0.04974877559055118,839.8576109391125,0.00025370340306410486,25.0,45.0
396.63257,0.0501044153543307,840.5354231166151,0.00025370340306410486,25.0,45.0
398.13403,0.050496767716535426,841.600722394221,0.00025370340306410486,25.0,45.0
399.6355,0.05085540354330708,840.0894736842106,0.00025370340306410486,25.0,45.0
401.13696,0.05116840551181102,841.6536377708978,0.00025370340306410486,25.0,45.0
402.63843,0.051530338582677165,842.1759287925697,0.00025370340306410486,25.0,45.0
404.13989,0.05190369488188976,842.8962590299278,0.00025370340306410486,25.0,45.0
405.64136,0.05226714960629921,841.7692208462333,0.00025370340306410486,25.0,45.0
407.14282,0.0526256968503937,842.101496388029,0.00025370340306410486,25.0,45.0
408.64429,0.05288374606299213,841.6230908152735,0.00025370340306410486,25.0,45.0
410.14575,0.053266700787401575,844.3629256965945,0.00025370340306410486,25.0,45.0
411.64722,0.05359734645669292,843.504540763674,0.00025370340306410486,25.0,45.0
413.14868,0.053913427165354334,845.0348297213623,0.00025370340306410486,25.0,45.0
414.65015,0.054240978346456685,847.0756191950464,0.00025370340306410486,25.0,45.0
416.15161,0.054587112204724404,846.9732198142415,0.00025370340306410486,25.0,45.0
417.65308,0.054962346456692915,845.9319659442725,0.00025370340306410486,25.0,45.0
419.15454,0.0552834311023622,847.5273735810114,0.00025370340306410486,25.0,45.0
420.65601,0.055644679133858274,848.6554179566564,0.00025370340306410486,25.0,45.0
422.15747,0.05600427165354331,848.2234004127968,0.00025370340306410486,25.0,45.0
423.65894,0.0563088248031496,848.3224716202271,0.00025370340306410486,25.0,45.0
425.1604,0.05668287992125984,850.3514447884417,0.00025370340306410486,25.0,45.0
426.66187,0.057065486220472444,850.9793601651188,0.00025370340306410486,25.0,45.0
428.16333,0.05745425393700787,850.9368421052633,0.00025370340306410486,25.0,45.0
429.66479,0.05780621456692913,851.1386480908152,0.00025370340306410486,25.0,45.0
431.16626,0.05814564566929133,849.8990454076368,0.00025370340306410486,25.0,45.0
432.66772,0.05846947637795276,850.1135964912281,0.00025370340306410486,25.0,45.0
434.16919,0.0588264468503937,851.3046955624355,0.00025370340306410486,25.0,45.0
435.67065,0.05922782677165354,851.5808823529412,0.00025370340306410486,25.0,45.0
437.17212,0.05954610236220472,852.1562177502581,0.00025370340306410486,25.0,45.0
438.67358,0.059882352362204724,853.3024767801858,0.00025370340306410486,25.0,45.0
440.17505,0.06022663976377953,852.5203560371517,0.00025370340306410486,25.0,45.0
441.67651,0.06056262598425197,853.3410216718266,0.00025370340306410486,25.0,45.0
443.17798,0.060845037401574806,854.4545149638802,0.00025370340306410486,25.0,45.0
444.67944,0.06117165354330708,853.3930598555212,0.00025370340306410486,25.0,45.0
446.18091,0.061518328740157474,854.3136222910216,0.00025370340306410486,25.0,45.0
447.68237,0.061886322834645666,854.7401186790505,0.00025370340306410486,25.0,45.0
449.18384,0.06225474606299212,856.6903250773994,0.00025370340306410486,25.0,45.0
450.6853,0.06258963976377953,856.3353457172343,0.00025370340306410486,25.0,45.0
452.18677,0.06289517913385827,855.4412280701755,0.00025370340306410486,25.0,45.0
453.68823,0.06325406299212598,856.9796439628483,0.00025370340306410486,25.0,45.0
455.1897,0.0636061811023622,859.1616099071208,0.00025370340306410486,25.0,45.0
456.69116,0.06393520472440946,858.2725232198143,0.00025370340306410486,25.0,45.0
458.19263,0.06429320078740158,858.4071207430342,0.00025370340306410486,25.0,45.0
459.69409,0.06462263385826772,859.6028379772962,0.00025370340306410486,25.0,45.0
461.19556,0.0649993405511811,858.6415634674923,0.00025370340306410486,25.0,45.0
462.69702,0.06541294094488188,861.3895252837978,0.00025370340306410486,25.0,45.0
464.19849,0.06586966732283465,860.4808049535603,0.00025370340306410486,25.0,45.0
465.69995,0.06622223228346456,860.7225490196079,0.00025370340306410486,25.0,45.0
467.20142,0.06659232086614174,860.9313725490196,0.00025370340306410486,25.0,45.0
468.70288,0.06691252559055119,861.1763931888545,0.00025370340306410486,25.0,45.0
470.20435,0.06721231496062992,860.7863777089783,0.00025370340306410486,25.0,45.0
471.70581,0.0675342559055118,861.1229618163054,0.00025370340306410486,25.0,45.0
473.20728,0.06784338582677166,860.7138802889577,0.00025370340306410486,25.0,45.0
474.70874,0.06818797244094488,865.3975748194015,0.00025370340306410486,25.0,45.0
476.21021,0.06860746259842519,864.7279411764706,0.00025370340306410486,25.0,45.0
477.71167,0.06895826181102363,862.4444014447885,0.00025370340306410486,25.0,45.0
479.21313,0.06921517125984253,863.4899380804954,0.00025370340306410486,25.0,45.0
480.7146,0.06959476377952756,865.2122033023736,0.00025370340306410486,25.0,45.0
482.21606,0.06996107480314961,865.8240712074304,0.00025370340306410486,25.0,45.0
483.71753,0.07031513582677165,865.8326883384933,0.00025370340306410486,25.0,45.0
485.21899,0.07069255708661418,866.8485036119711,0.00025370340306410486,25.0,45.0
486.72046,0.07105558858267717,866.4241486068112,0.00025370340306410486,25.0,45.0
488.22192,0.07139382677165354,866.4087719298246,0.00025370340306410486,25.0,45.0
489.72339,0.07173289960629922,867.0651186790506,0.00025370340306410486,25.0,45.0
491.22485,0.0720516377952756,866.0596491228071,0.00025370340306410486,25.0,45.0
492.72632,0.07239326181102362,867.8445304437565,0.00025370340306410486,25.0,45.0
494.22778,0.07276417125984251,870.9490712074304,0.00025370340306410486,25.0,45.0
495.72925,0.07314757086614172,869.0847523219815,0.00025370340306410486,25.0,45.0
497.23071,0.07353117125984253,869.9852167182663,0.00025370340306410486,25.0,45.0
498.73218,0.07389119094488189,872.6721104231167,0.00025370340306410486,25.0,45.0
500.23364,0.07427290748031495,870.9201496388029,0.00025370340306410486,25.0,45.0
501.73511,0.07461081889763779,869.0633384932921,0.00025370340306410486,25.0,45.0
503.23657,0.07493361614173227,872.803044375645,0.00025370340306410486,25.0,45.0
504.73804,0.0753191220472441,871.4803663570692,0.00025370340306410486,25.0,45.0
506.2395,0.0756862125984252,872.2246388028896,0.00025370340306410486,25.0,45.0
507.74097,0.07603727559055118,871.5083333333333,0.00025370340306410486,25.0,45.0
509.24243,0.07638015551181103,871.7552373581011,0.00025370340306410486,25.0,45.0
510.7439,0.07675033661417323,871.8771413828689,0.00025370340306410486,25.0,45.0
512.24536,0.07705944291338583,872.0030959752322,0.00025370340306410486,25.0,45.0
513.74683,0.07737300590551181,873.3707688338494,0.00025370340306410486,25.0,45.0
515.24829,0.07768920472440945,873.7513931888545,0.00025370340306410486,25.0,45.0
516.74976,0.07802996062992125,873.3267285861714,0.00025370340306410486,25.0,45.0
518.25122,0.07841869881889763,874.9026315789474,0.00025370340306410486,25.0,45.0
519.75269,0.07877419094488189,874.6084107327141,0.00025370340306410486,25.0,45.0
521.25415,0.0790989251968504,874.3388286893705,0.00025370340306410486,25.0,45.0
522.75562,0.0794092027559055,875.0155572755418,0.00025370340306410486,25.0,45.0
524.25708,0.07977934448818898,875.3976522187822,0.00025370340306410486,25.0,45.0
525.75854,0.08015826771653543,876.9523735810113,0.00025370340306410486,25.0,45.0
527.26001,0.08049344488188977,876.3811919504644,0.00025370340306410486,25.0,45.0
528.76147,0.08082515354330709,875.3837719298247,0.00025370340306410486,25.0,45.0
530.26294,0.08118247047244094,877.384520123839,0.00025370340306410486,25.0,45.0
531.7644,0.0815246751968504,877.4622549019608,0.00025370340306410486,25.0,45.0
533.26587,0.08191281496062992,879.7952528379774,0.00025370340306410486,25.0,45.0
534.76733,0.08232380511811023,878.5641124871001,0.00025370340306410486,25.0,45.0
536.2688,0.08272808464566929,878.9384932920537,0.00025370340306410486,25.0,45.0
537.77026,0.08310866338582677,878.5212590299278,0.00025370340306410486,25.0,45.0
539.27173,0.08345523818897638,879.2214912280702,0.00025370340306410486,25.0,45.0
540.77319,0.08382516732283464,879.6745098039215,0.00025370340306410486,25.0,45.0
542.27466,0.0841785905511811,880.4241228070176,0.00025370340306410486,25.0,45.0
543.77612,0.08457519488188976,881.2267285861712,0.00025370340306410486,25.0,45.0
545.27759,0.0848979527559055,879.3302115583075,0.00025370340306410486,25.0,45.0
546.77905,0.08521821653543307,881.3031991744066,0.00025370340306410486,25.0,45.0
548.28052,0.08555963976377953,881.7912280701754,0.00025370340306410486,25.0,45.0
549.78198,0.08592348622047244,880.6811145510836,0.00025370340306410486,25.0,45.0
551.28345,0.08627781102362204,882.3761093911249,0.00025370340306410486,25.0,45.0
552.78491,0.08665393700787401,884.9918730650155,0.00025370340306410486,25.0,45.0
554.28638,0.0870759625984252,883.823581011352,0.00025370340306410486,25.0,45.0
555.78784,0.08741945669291339,881.6590557275542,0.00025370340306410486,25.0,45.0
557.28931,0.0877711062992126,884.2180598555212,0.00025370340306410486,25.0,45.0
558.79077,0.08815724015748032,884.7416924664603,0.00025370340306410486,25.0,45.0
560.29224,0.08850605118110236,885.2588235294118,0.00025370340306410486,25.0,45.0
561.7937,0.08880959448818898,885.5472394220847,0.00025370340306410486,25.0,45.0
563.29517,0.08915846456692914,886.6068111455108,0.00025370340306410486,25.0,45.0
564.79663,0.08955884842519685,886.7615841073272,0.00025370340306410486,25.0,45.0
566.2981,0.08985549212598425,884.1358617131064,0.00025370340306410486,25.0,45.0
567.79956,0.09020474212598426,885.9642156862745,0.00025370340306410486,25.0,45.0
569.30103,0.09058925196850393,886.9774509803922,0.00025370340306410486,25.0,45.0
570.80249,0.0909870531496063,889.0969040247678,0.00025370340306410486,25.0,45.0
572.30396,0.09131099606299213,886.3711300309599,0.00025370340306410486,25.0,45.0
573.80542,0.09165872047244095,887.6719556243551,0.00025370340306410486,25.0,45.0
575.30688,0.09202619291338583,888.739705882353,0.00025370340306410486,25.0,45.0
576.80835,0.09239284842519685,889.9036119711043,0.00025370340306410486,25.0,45.0
578.30981,0.09279576181102363,888.4655830753354,0.00025370340306410486,25.0,45.0
579.81128,0.09316579724409449,887.958230134159,0.00025370340306410486,25.0,45.0
581.31274,0.09354959645669292,886.9776315789474,0.00025370340306410486,25.0,45.0
582.81421,0.09389760826771654,890.571955624355,0.00025370340306410486,25.0,45.0
584.31567,0.09426601377952755,889.7498452012384,0.00025370340306410486,25.0,45.0
585.81714,0.09462998818897637,890.5119453044376,0.00025370340306410486,25.0,45.0
587.3186,0.0949760059055118,891.0790763673891,0.00025370340306410486,25.0,45.0
588.82007,0.0953315748031496,890.7596749226007,0.00025370340306410486,25.0,45.0
590.32153,0.09568709645669292,891.5014705882353,0.00025370340306410486,25.0,45.0
591.823,0.09604265354330709,890.0246646026832,0.00025370340306410486,25.0,45.0
593.32446,0.09638042913385828,892.5194788441693,0.00025370340306410486,25.0,45.0
594.82593,0.0967237657480315,891.1840041279671,0.00025370340306410486,25.0,45.0
596.32739,0.09706121259842519,893.2285345717235,0.00025370340306410486,25.0,45.0
597.82886,0.09742404921259842,892.4513931888545,0.00025370340306410486,25.0,45.0
599.33032,0.0978429251968504,893.1795923632611,0.00025370340306410486,25.0,45.0
600.83179,0.09820860826771653,893.9237358101135,0.00025370340306410486,25.0,45.0
602.33325,0.09860957283464566,893.6376418988649,0.00025370340306410486,25.0,45.0
603.83472,0.09902602952755905,895.6796439628483,0.00025370340306410486,25.0,45.0
605.33618,0.09934087992125984,894.773374613003,0.00025370340306410486,25.0,45.0
606.83765,0.09969768503937008,894.3659184726523,0.00025370340306410486,25.0,45.0
608.33911,0.10004177362204725,895.9712848297214,0.00025370340306410486,25.0,45.0
609.84058,0.1003751496062992,896.7561661506709,0.00025370340306410486,25.0,45.0
611.34204,0.10079261614173228,895.9334107327143,0.00025370340306410486,25.0,45.0
612.84351,0.10115648622047245,895.9216460268318,0.00025370340306410486,25.0,45.0
614.34497,0.10155648228346456,896.6988390092879,0.00025370340306410486,25.0,45.0
615.84644,0.10192661811023622,896.9433694530444,0.00025370340306410486,25.0,45.0
617.3479,0.10229271653543306,896.7759545923633,0.00025370340306410486,25.0,45.0
618.84937,0.10266568110236221,897.2798503611971,0.00025370340306410486,25.0,45.0
620.35083,0.10303137992125984,898.0893704850362,0.00025370340306410486,25.0,45.0
621.85229,0.10344343897637795,897.5802889576884,0.00025370340306410486,25.0,45.0
623.35376,0.10383225393700786,898.2810371517028,0.00025370340306410486,25.0,45.0
624.85522,0.10422754527559056,897.1908410732715,0.00025370340306410486,25.0,45.0
626.35669,0.10456522637795275,897.4123839009287,0.00025370340306410486,25.0,45.0
627.85815,0.10490728346456693,897.8285861713107,0.00025370340306410486,25.0,45.0
629.35962,0.1052590688976378,898.7717750257998,0.00025370340306410486,25.0,45.0
630.86108,0.1056299901574803,899.881991744066,0.00025370340306410486,25.0,45.0
632.36255,0.10599329724409448,897.6526831785346,0.00025370340306410486,25.0,45.0
633.86401,0.1062898779527559,900.7124871001032,0.00025370340306410486,25.0,45.0
635.36548,0.10664561614173228,901.5099845201239,0.00025370340306410486,25.0,45.0
636.86694,0.1070452598425197,901.3726780185758,0.00025370340306410486,25.0,45.0
638.36841,0.10745337598425196,902.9579979360166,0.00025370340306410486,25.0,45.0
639.86987,0.10783410629921258,900.8874613003097,0.00025370340306410486,25.0,45.0
641.37134,0.10827223622047243,902.5408926728587,0.00025370340306410486,25.0,45.0
642.8728,0.10867181102362204,902.0660990712074,0.00025370340306410486,25.0,45.0
644.37427,0.10903456496062992,900.0840557275543,0.00025370340306410486,25.0,45.0
645.87573,0.10938108267716534,902.7326367389061,0.00025370340306410486,25.0,45.0
647.3772,0.10973691535433072,902.4260835913312,0.00025370340306410486,25.0,45.0
648.87866,0.11008888779527559,902.5184210526315,0.00025370340306410486,25.0,45.0
650.38013,0.11048203149606299,903.592363261094,0.00025370340306410486,25.0,45.0
651.88159,0.11083696062992127,903.5755417956657,0.00025370340306410486,25.0,45.0
653.38306,0.11121174212598425,905.1471362229103,0.00025370340306410486,25.0,45.0
654.88452,0.1115886122047244,902.9313725490197,0.00025370340306410486,25.0,45.0
656.38599,0.11199758464566929,903.3904282765737,0.00025370340306410486,25.0,45.0
657.88745,0.1124221161417323,905.5587719298246,0.00025370340306410486,25.0,45.0
659.38892,0.11281781692913385,904.1826883384932,0.00025370340306410486,25.0,45.0
660.89038,0.11313440354330709,903.9186274509805,0.00025370340306410486,25.0,45.0
662.39185,0.11347158070866141,904.5551341589268,0.00025370340306410486,25.0,45.0
663.89331,0.11381372047244094,906.3184726522188,0.00025370340306410486,25.0,45.0
665.39478,0.11414832677165355,904.7402992776058,0.00025370340306410486,25.0,45.0
666.89624,0.11453524212598426,906.6118679050568,0.00025370340306410486,25.0,45.0
668.39771,0.11493577755905511,906.3143704850361,0.00025370340306410486,25.0,45.0
669.89917,0.11535786811023623,907.1199174406605,0.00025370340306410486,25.0,45.0
671.40063,0.11573954921259844,909.0435758513933,0.00025370340306410486,25.0,45.0
672.9021,0.11614815748031496,907.1246388028896,0.00025370340306410486,25.0,45.0
674.40356,0.11651928937007874,908.346181630547,0.00025370340306410486,25.0,45.0
675.90503,0.11688678543307086,905.2908926728586,0.00025370340306410486,25.0,45.0
677.40649,0.11728095078740157,909.4483230134159,0.00025370340306410486,25.0,45.0
678.90796,0.11770151574803149,907.944427244582,0.00025370340306410486,25.0,45.0
680.40942,0.1181240157480315,908.1432920536636,0.00025370340306410486,25.0,45.0
681.91089,0.11847538976377954,907.226883384933,0.00025370340306410486,25.0,45.0
683.41235,0.11888682677165355,908.7456398348813,0.00025370340306410486,25.0,45.0
684.91382,0.11925376968503937,908.5014447884417,0.00025370340306410486,25.0,45.0
686.41528,0.11963371456692914,908.0389834881321,0.00025370340306410486,25.0,45.0
687.91675,0.12002111023622047,909.0790247678018,0.00025370340306410486,25.0,45.0
689.41821,0.12039949409448819,910.5231424148607,0.00025370340306410486,25.0,45.0
690.91968,0.12074503543307086,910.0621517027864,0.00025370340306410486,25.0,45.0
692.42114,0.12114854133858267,910.1292827657378,0.00025370340306410486,25.0,45.0
693.92261,0.12154871259842519,911.8572239422085,0.00025370340306410486,25.0,45.0
695.42407,0.12193148622047245,910.7501547987616,0.00025370340306410486,25.0,45.0
696.92554,0.12231668700787401,911.1760835913312,0.00025370340306410486,25.0,45.0
698.427,0.12263498425196849,910.6036635706914,0.00025370340306410486,25.0,45.0
699.92847,0.12301826181102363,912.3193756449948,0.00025370340306410486,25.0,45.0
701.42993,0.1234035433070866,910.4224974200206,0.00025370340306410486,25.0,45.0
702.9314,0.1238227716535433,912.6922600619196,0.00025370340306410486,25.0,45.0
704.43286,0.12423140354330707,912.7453044375645,0.00025370340306410486,25.0,45.0
705.93433,0.12458091141732283,910.9677760577915,0.00025370340306410486,25.0,45.0
707.43579,0.12497619094488188,912.925128998968,0.00025370340306410486,25.0,45.0
708.93726,0.12537812401574802,912.6082301341589,0.00025370340306410486,25.0,45.0
710.43872,0.12578650984251968,913.6976006191951,0.00025370340306410486,25.0,45.0
711.94019,0.12618862992125984,912.7789473684211,0.00025370340306410486,25.0,45.0
713.44165,0.1265687618110236,913.796310629515,0.00025370340306410486,25.0,45.0
714.94312,0.12698768307086614,913.210036119711,0.00025370340306410486,25.0,45.0
716.44458,0.12737505511811023,913.3444272445821,0.00025370340306410486,25.0,45.0
717.94604,0.12779163188976378,914.9226522187823,0.00025370340306410486,25.0,45.0
719.44751,0.12815844685039368,915.0705624355006,0.00025370340306410486,25.0,45.0
720.94897,0.1285762657480315,914.4652476780185,0.00025370340306410486,25.0,45.0
722.45044,0.12895712401574805,913.537048503612,0.00025370340306410486,25.0,45.0
723.9519,0.1294012618110236,913.9648606811145,0.00025370340306410486,25.0,45.0
725.45337,0.1298550905511811,914.9046439628484,0.00025370340306410486,25.0,45.0
726.95483,0.1302365,915.736145510836,0.00025370340306410486,25.0,45.0
728.4563,0.130667062992126,915.4301599587203,0.00025370340306410486,25.0,45.0
729.95776,0.13102200393700786,914.5488390092879,0.00025370340306410486,25.0,45.0
731.45923,0.13136889566929133,917.0198916408668,0.00025370340306410486,25.0,45.0
732.96069,0.1317846968503937,916.8015737874097,0.00025370340306410486,25.0,45.0
734.46216,0.1322396279527559,917.0347007223943,0.00025370340306410486,25.0,45.0
735.96362,0.13262556692913385,915.5473684210526,0.00025370340306410486,25.0,45.0
737.46509,0.13303453937007875,916.2839009287926,0.00025370340306410486,25.0,45.0
738.96655,0.13340936811023624,917.1943240454077,0.00025370340306410486,25.0,45.0
740.46802,0.1337765,917.1515995872033,0.00025370340306410486,25.0,45.0
741.96948,0.13423223031496065,918.2269349845201,0.00025370340306410486,25.0,45.0
743.47095,0.1346111181102362,916.9880288957689,0.00025370340306410486,25.0,45.0
744.97241,0.13501032874015748,918.4205624355005,0.00025370340306410486,25.0,45.0
746.47388,0.1353885472440945,918.6744582043344,0.00025370340306410486,25.0,45.0
747.97534,0.13575425984251968,917.8362745098038,0.00025370340306410486,25.0,45.0
749.47681,0.13622138188976377,918.2113777089783,0.00025370340306410486,25.0,45.0
750.97827,0.13664039763779529,917.7117647058824,0.00025370340306410486,25.0,45.0
752.47974,0.13707831692913386,919.8438338493293,0.00025370340306410486,25.0,45.0
753.9812,0.13748192716535432,916.9781475748194,0.00025370340306410486,25.0,45.0
755.48267,0.13781801181102363,917.4731682146544,0.00025370340306410486,25.0,45.0
756.98413,0.13824181496062993,921.7524251805986,0.00025370340306410486,25.0,45.0
758.4856,0.13874683464566928,921.8797987616099,0.00025370340306410486,25.0,45.0
759.98706,0.13914464960629921,921.0020639834881,0.00025370340306410486,25.0,45.0
761.48853,0.1395678779527559,920.5158410732715,0.00025370340306410486,25.0,45.0
762.98999,0.13997017322834646,921.2972652218782,0.00025370340306410486,25.0,45.0
764.49146,0.14039066929133856,921.5940660474716,0.00025370340306410486,25.0,45.0
765.99292,0.14082660433070865,921.8344943240454,0.00025370340306410486,25.0,45.0
767.49438,0.14126296062992125,920.0985036119712,0.00025370340306410486,25.0,45.0
768.99585,0.14165761811023622,919.4712074303405,0.00025370340306410486,25.0,45.0
770.49731,0.14202561811023623,920.8269349845201,0.00025370340306410486,25.0,45.0
771.99878,0.14244337992125986,921.1638028895769,0.00025370340306410486,25.0,45.0
773.50024,0.14283796653543307,919.5125902992776,0.00025370340306410486,25.0,45.0
775.00171,0.14323702559055118,921.9127192982456,0.00025370340306410486,25.0,45.0
776.50317,0.1436880846456693,920.6793085655315,0.00025370340306410486,25.0,45.0
778.00464,0.14406191535433072,920.0353715170279,0.00025370340306410486,25.0,45.0
779.5061,0.1444396653543307,923.4507739938081,0.00025370340306410486,25.0,45.0
781.00757,0.14487528346456693,923.0196078431372,0.00025370340306410486,25.0,45.0
782.50903,0.1453560748031496,923.6297213622291,0.00025370340306410486,25.0,45.0
784.0105,0.1458758090551181,923.3203302373581,0.00025370340306410486,25.0,45.0
785.51196,0.14631969881889764,921.9313209494325,0.00025370340306410486,25.0,45.0
787.01343,0.14669105511811023,921.5275541795666,0.00025370340306410486,25.0,45.0
788.51489,0.14713784448818898,922.4543085655314,0.00025370340306410486,25.0,45.0
790.01636,0.14758831692913385,923.9295923632611,0.00025370340306410486,25.0,45.0
791.51782,0.14802876968503936,925.8917956656347,0.00025370340306410486,25.0,45.0
793.01929,0.14843454921259844,924.7378482972136,0.00025370340306410486,25.0,45.0
794.52075,0.1488951594488189,922.9106553147575,0.00025370340306410486,25.0,45.0
796.02222,0.14933565944881888,923.3018575851393,0.00025370340306410486,25.0,45.0
797.52368,0.14976969291338582,924.138338493292,0.00025370340306410486,25.0,45.0
799.02515,0.15018900393700788,923.6576109391125,0.00025370340306410486,25.0,45.0
800.52661,0.15060290354330708,923.8615067079464,0.00025370340306410486,25.0,45.0
802.02808,0.15097087992125982,922.3968008255935,0.00025370340306410486,25.0,45.0
803.52954,0.15137634448818899,925.0810113519092,0.00025370340306410486,25.0,45.0
805.03101,0.15179372834645669,924.502270381837,0.00025370340306410486,25.0,45.0
806.53247,0.15219924015748032,923.7711300309597,0.00025370340306410486,25.0,45.0
808.03394,0.152636031496063,926.5795665634676,0.00025370340306410486,25.0,45.0
809.5354,0.15307803346456691,924.0057533539732,0.00025370340306410486,25.0,45.0
811.03687,0.15358205708661418,926.0459236326109,0.00025370340306410486,25.0,45.0
812.53833,0.15398356692913384,925.6492260061921,0.00025370340306410486,25.0,45.0
814.03979,0.15449638976377952,927.0629256965944,0.00025370340306410486,25.0,45.0
815.54126,0.1549360787401575,925.85608875129,0.00025370340306410486,25.0,45.0
817.04272,0.15537575787401572,923.7444014447885,0.00025370340306410486,25.0,45.0
818.54419,0.15581557677165353,925.7746388028895,0.00025370340306410486,25.0,45.0
820.04565,0.15628377755905512,926.9367647058824,0.00025370340306410486,25.0,45.0
821.54712,0.15672588385826772,926.3331527347781,0.00025370340306410486,25.0,45.0
823.04858,0.15719202165354332,927.1022961816305,0.00025370340306410486,25.0,45.0
824.55005,0.1576088897637795,926.3229360165119,0.00025370340306410486,25.0,45.0
826.05151,0.15808007086614173,927.9695046439629,0.00025370340306410486,25.0,45.0
827.55298,0.1585237972440945,926.3189886480909,0.00025370340306410486,25.0,45.0
829.05444,0.15890578346456694,926.3622549019608,0.00025370340306410486,25.0,45.0
830.55591,0.15936235826771653,926.0854231166151,0.00025370340306410486,25.0,45.0
832.05737,0.15984293700787403,926.1766769865841,0.00025370340306410486,25.0,45.0
833.55884,0.16024183070866144,925.6846233230134,0.00025370340306410486,25.0,45.0
835.0603,0.16069415748031496,926.0014447884417,0.00025370340306410486,25.0,45.0
836.56177,0.16115926181102364,927.6542569659443,0.00025370340306410486,25.0,45.0
838.06323,0.1616005,927.5839009287926,0.00025370340306410486,25.0,45.0
839.5647,0.16203806692913386,928.5353199174407,0.00025370340306410486,25.0,45.0
841.06616,0.16252153346456694,927.5391124871,0.00025370340306410486,25.0,45.0
842.56763,0.16296156299212597,927.0233746130032,0.00025370340306410486,25.0,45.0
844.06909,0.16338695078740156,928.3427760577916,0.00025370340306410486,25.0,45.0
845.57056,0.1638731496062992,929.7349845201238,0.00025370340306410486,25.0,45.0
847.07202,0.16438139763779527,927.6417182662539,0.00025370340306410486,25.0,45.0
848.57349,0.16482850196850393,929.1119711042312,0.00025370340306410486,25.0,45.0
850.07495,0.1653007874015748,927.6882094943242,0.00025370340306410486,25.0,45.0
851.57642,0.16574339763779528,928.7513673890609,0.00025370340306410486,25.0,45.0
853.07788,0.16625791141732282,929.2916924664603,0.00025370340306410486,25.0,45.0
854.57935,0.16677820866141732,929.1082043343653,0.00025370340306410486,25.0,45.0
856.08081,0.16728817913385827,928.0539731682147,0.00025370340306410486,25.0,45.0
857.58228,0.16770111811023622,928.632198142415,0.00025370340306410486,25.0,45.0
859.08374,0.16816632677165355,927.7419246646027,0.00025370340306410486,25.0,45.0
860.58521,0.16859476574803148,928.2884674922601,0.00025370340306410486,25.0,45.0
862.08667,0.16908442716535432,929.3465428276573,0.00025370340306410486,25.0,45.0
863.58813,0.16949268307086615,927.6421568627452,0.00025370340306410486,25.0,45.0
865.0896,0.16992656496062994,929.214963880289,0.00025370340306410486,25.0,45.0
866.59106,0.17043091732283464,929.4386996904025,0.00025370340306410486,25.0,45.0
868.09253,0.17090980708661418,930.3085655314758,0.00025370340306410486,25.0,45.0
869.59399,0.17142692322834646,929.1562693498453,0.00025370340306410486,25.0,45.0
871.09546,0.1719583090551181,928.8747678018576,0.00025370340306410486,25.0,45.0
872.59692,0.17245788582677166,929.978947368421,0.00025370340306410486,25.0,45.0
874.09839,0.17291532677165353,929.2111971104232,0.00025370340306410486,25.0,45.0
875.59985,0.1734093661417323,929.9767285861714,0.00025370340306410486,25.0,45.0
877.10132,0.1738770157480315,929.8776057791538,0.00025370340306410486,25.0,45.0
878.60278,0.17432493110236222,930.2526315789474,0.00025370340306410486,25.0,45.0
880.10425,0.17476645078740158,928.3183436532508,0.00025370340306410486,25.0,45.0
881.60571,0.17520638582677167,929.3191434468525,0.00025370340306410486,25.0,45.0
883.10718,0.17569087401574804,930.2271671826626,0.00025370340306410486,25.0,45.0
884.60864,0.17620855511811023,930.8400412796698,0.00025370340306410486,25.0,45.0
886.11011,0.1767530216535433,930.6730650154799,0.00025370340306410486,25.0,45.0
887.61157,0.1772731653543307,930.480959752322,0.00025370340306410486,25.0,45.0
889.11304,0.1777326850393701,929.7756191950465,0.00025370340306410486,25.0,45.0
890.6145,0.17822500984251968,930.2940660474717,0.00025370340306410486,25.0,45.0
892.11597,0.1787013779527559,930.593008255934,0.00025370340306410486,25.0,45.0
893.61743,0.17923222244094486,931.5565273477812,0.00025370340306410486,25.0,45.0
895.1189,0.179736468503937,931.0549019607843,0.00025370340306410486,25.0,45.0
896.62036,0.18025080511811023,931.0234778121775,0.00025370340306410486,25.0,45.0
898.12183,0.18075897047244094,930.365995872033,0.00025370340306410486,25.0,45.0
899.62329,0.1812897559055118,931.2683694530444,0.00025370340306410486,25.0,45.0
901.12476,0.18179068110236218,930.1697368421053,0.00025370340306410486,25.0,45.0
902.62622,0.182325562992126,931.0511351909184,0.00025370340306410486,25.0,45.0
904.12769,0.18278496456692914,929.6151960784315,0.00025370340306410486,25.0,45.0
905.62915,0.18327044881889762,930.0927760577915,0.00025370340306410486,25.0,45.0
907.13062,0.1838490728346457,932.0167182662539,0.00025370340306410486,25.0,45.0
908.63208,0.18437469488188976,930.9224974200207,0.00025370340306410486,25.0,45.0
910.13354,0.18481894881889763,929.540608875129,0.00025370340306410486,25.0,45.0
911.63501,0.18523060826771653,929.7228328173375,0.00025370340306410486,25.0,45.0
913.13647,0.18574014566929134,931.9888286893705,0.00025370340306410486,25.0,45.0
914.23755,0.18618286417322835,933.6886738906089,0.00025370340306410486,25.0,45.0