File: datasets/am_bench_2022/csv/60-XY.09-3.csv
Time(s),Strain(%),Stress(MPa),SR(s-1),Temp(C),Angle(deg)
13.458252,1.6976930708661417e-06,20.48566225165563,0.00025370340306410486,25.0,60.0
14.959717,3.268725196850394e-05,25.60615294363039,0.00025370340306410486,25.0,60.0
16.361084,3.5124968503937006e-05,30.77974657141367,0.00025370340306410486,25.0,60.0
17.762451,4.523561023622047e-05,34.84384679564061,0.00025370340306410486,25.0,60.0
19.163818,6.779681102362205e-05,37.67386713250248,0.00025370340306410486,25.0,60.0
20.565186,7.53453090551181e-05,44.038029931689,0.00025370340306410486,25.0,60.0
21.966553,9.872042125984251e-05,50.824052250091256,0.00025370340306410486,25.0,60.0
23.36792,0.00013065316732283462,56.6467878187412,0.00025370340306410486,25.0,60.0
24.769287,0.00015546090551181102,63.209146373259635,0.00025370340306410486,25.0,60.0
26.170654,0.0001628055216535433,69.92938937268603,0.00025370340306410486,25.0,60.0
27.572021,0.00020631279527559055,77.13077905824686,0.00025370340306410486,25.0,60.0
28.973389,0.00022252316929133857,84.67088178547218,0.00025370340306410486,25.0,60.0
30.374756,0.00023878679133858266,90.74503832716275,0.00025370340306410486,25.0,60.0
31.776123,0.0002766484448818898,99.92288418417897,0.00025370340306410486,25.0,60.0
33.17749,0.0002890417322834645,106.37740783229911,0.00025370340306410486,25.0,60.0
34.578857,0.0003540639763779527,115.37348907545498,0.00025370340306410486,25.0,60.0
35.980225,0.0003651305118110236,124.35858059133336,0.00025370340306410486,25.0,60.0
37.381592,0.0004121846259842519,134.59166970850498,0.00025370340306410486,25.0,60.0
38.782959,0.0004400512401574803,144.6302289200605,0.00025370340306410486,25.0,60.0
40.184326,0.00046765625984251973,152.50214840694582,0.00025370340306410486,25.0,60.0
41.585693,0.0004878628346456693,160.02395056578192,0.00025370340306410486,25.0,60.0
42.987061,0.0005163809645669291,168.35774625853887,0.00025370340306410486,25.0,60.0
44.388428,0.0005507320669291339,176.96452521249412,0.00025370340306410486,25.0,60.0
45.789795,0.0005945831889763779,188.24673567294155,0.00025370340306410486,25.0,60.0
47.191162,0.0006281260236220473,198.15333733117797,0.00025370340306410486,25.0,60.0
48.592529,0.0006616938188976377,206.45409865985297,0.00025370340306410486,25.0,60.0
49.993896,0.0006681952952755906,216.24110914115866,0.00025370340306410486,25.0,60.0
51.395264,0.000719193188976378,229.4071935130625,0.00025370340306410486,25.0,60.0
52.796631,0.0007445109448818898,238.90853887469365,0.00025370340306410486,25.0,60.0
54.197998,0.0007920804921259843,249.77295458100852,0.00025370340306410486,25.0,60.0
55.599365,0.0008195621259842519,258.92373937529334,0.00025370340306410486,25.0,60.0
57.000732,0.0008661516338582676,270.5259686082286,0.00025370340306410486,25.0,60.0
58.4021,0.0008988872440944882,278.1511185274026,0.00025370340306410486,25.0,60.0
59.803467,0.0009259558267716535,290.15085779840433,0.00025370340306410486,25.0,60.0
61.204834,0.0009436206102362204,297.83524534598735,0.00025370340306410486,25.0,60.0
62.606201,0.0009961067913385826,308.4020441153465,0.00025370340306410486,25.0,60.0
64.007568,0.0010415919881889763,321.9478281274444,0.00025370340306410486,25.0,60.0
65.408936,0.0010926455118110236,332.5732909214163,0.00025370340306410486,25.0,60.0
66.810303,0.0011030005314960631,341.6522135891954,0.00025370340306410486,25.0,60.0
68.21167,0.001139995846456693,352.65007561140953,0.00025370340306410486,25.0,60.0
69.613037,0.001178623090551181,364.3488293267978,0.00025370340306410486,25.0,60.0
71.014404,0.00122623218503937,374.60051102883665,0.00025370340306410486,25.0,60.0
72.415771,0.001253383090551181,384.73971424101785,0.00025370340306410486,25.0,60.0
73.817139,0.0012857193307086615,394.32270428117016,0.00025370340306410486,25.0,60.0
75.218506,0.0013232179724409448,404.4058507587214,0.00025370340306410486,25.0,60.0
76.619873,0.0013587458267716535,414.3807164832873,0.00025370340306410486,25.0,60.0
78.02124,0.0014154257874015748,424.775460186682,0.00025370340306410486,25.0,60.0
79.422607,0.001433864153543307,435.0524847473536,0.00025370340306410486,25.0,60.0
80.823975,0.0014761277559055118,444.9760129321583,0.00025370340306410486,25.0,60.0
82.225342,0.001474472559055118,454.8867132502477,0.00025370340306410486,25.0,60.0
83.626709,0.0015133423425196851,464.50730041195186,0.00025370340306410486,25.0,60.0
85.028076,0.001549631122047244,473.6060384836001,0.00025370340306410486,25.0,60.0
86.429443,0.0016064933070866142,484.4182093132398,0.00025370340306410486,25.0,60.0
87.830811,0.0016299716141732284,492.4689993221046,0.00025370340306410486,25.0,60.0
89.232178,0.0016536226377952758,501.2337435469573,0.00025370340306410486,25.0,60.0
90.633545,0.0016844638976377952,508.17575741774,0.00025370340306410486,25.0,60.0
92.034912,0.001719732224409449,518.9552067580956,0.00025370340306410486,25.0,60.0
93.436279,0.001762006397637795,527.812431558638,0.00025370340306410486,25.0,60.0
94.837646,0.0017888030118110236,533.621812587996,0.00025370340306410486,25.0,60.0
96.239014,0.0018073027755905512,543.8335245345988,0.00025370340306410486,25.0,60.0
97.640381,0.0018353337401574802,549.059993742504,0.00025370340306410486,25.0,60.0
99.041748,0.0018542515157480316,556.3802732439902,0.00025370340306410486,25.0,60.0
100.44312,0.0018795235433070865,564.3791781821975,0.00025370340306410486,25.0,60.0
101.84448,0.0019202303937007872,570.264092402357,0.00025370340306410486,25.0,60.0
103.24585,0.001944174744094488,575.879699640194,0.00025370340306410486,25.0,60.0
104.64722,0.0019385297834645671,582.1270793137613,0.00025370340306410486,25.0,60.0
106.04858,0.0020098875984251967,589.9707201334933,0.00025370340306410486,25.0,60.0
107.44995,0.0020185801181102363,594.5978255201544,0.00025370340306410486,25.0,60.0
108.85132,0.002053320866141732,601.2785628617614,0.00025370340306410486,25.0,60.0
110.25269,0.0020888238188976377,606.5753246076029,0.00025370340306410486,25.0,60.0
111.65405,0.002098705118110236,610.6108358971685,0.00025370340306410486,25.0,60.0
113.05542,0.0021225883858267715,617.2965792355426,0.00025370340306410486,25.0,60.0
114.45679,0.0021549673228346456,621.6973457787975,0.00025370340306410486,25.0,60.0
115.85815,0.002198013976377953,627.4585962350733,0.00025370340306410486,25.0,60.0
117.25952,0.002216074212598425,632.0637482400792,0.00025370340306410486,25.0,60.0
118.66089,0.002255660433070866,635.6797726443135,0.00025370340306410486,25.0,60.0
120.06226,0.002277950590551181,637.9686603744068,0.00025370340306410486,25.0,60.0
121.46362,0.002314586811023622,643.9270480262815,0.00025370340306410486,25.0,60.0
122.86499,0.0023595259842519685,649.4513740418209,0.00025370340306410486,25.0,60.0
124.26636,0.002385937992125984,654.0787401574803,0.00025370340306410486,25.0,60.0
125.66772,0.002425892125984252,655.8394691557595,0.00025370340306410486,25.0,60.0
127.06909,0.002459254330708661,661.5168952390885,0.00025370340306410486,25.0,60.0
128.47046,0.002500006299212598,664.6451217604422,0.00025370340306410486,25.0,60.0
129.87183,0.0025311976377952756,666.0353548521667,0.00025370340306410486,25.0,60.0
131.27319,0.0025752187007874014,674.0943317515774,0.00025370340306410486,25.0,60.0
132.67456,0.0026172661417322835,675.4409970276895,0.00025370340306410486,25.0,60.0
134.07593,0.002683731496062992,678.3390780622622,0.00025370340306410486,25.0,60.0
135.47729,0.0027297240157480316,682.9462637534547,0.00025370340306410486,25.0,60.0
136.87866,0.0027771035433070863,684.3826198049748,0.00025370340306410486,25.0,60.0
138.28003,0.002837155118110236,687.6874902226625,0.00025370340306410486,25.0,60.0
139.6814,0.002887311811023622,690.3221046044741,0.00025370340306410486,25.0,60.0
141.08276,0.002951360433070866,693.7102518642124,0.00025370340306410486,25.0,60.0
142.48413,0.003036419094488189,697.9267872972832,0.00025370340306410486,25.0,60.0
143.8855,0.0031091198818897635,700.3225999895709,0.00025370340306410486,25.0,60.0
145.28687,0.003170497047244094,702.1488501851176,0.00025370340306410486,25.0,60.0
146.68823,0.0032579818897637797,705.2433644469938,0.00025370340306410486,25.0,60.0
148.0896,0.0033475990157480315,707.11818845492,0.00025370340306410486,25.0,60.0
149.49097,0.003479849803149606,710.7776763831673,0.00025370340306410486,25.0,60.0
150.89233,0.003576319094488189,712.1270271679616,0.00025370340306410486,25.0,60.0
152.2937,0.0036895275590551183,715.5917505344944,0.00025370340306410486,25.0,60.0
153.69507,0.003833137401574803,720.1176409240235,0.00025370340306410486,25.0,60.0
155.09644,0.003967527755905511,721.2482661521615,0.00025370340306410486,25.0,60.0
156.4978,0.0041329440944881885,724.7508734421442,0.00025370340306410486,25.0,60.0
157.89917,0.004303045472440944,726.4100224226938,0.00025370340306410486,25.0,60.0
159.30054,0.004469429527559055,726.5767846899932,0.00025370340306410486,25.0,60.0
160.7019,0.004620197440944882,730.1030661730197,0.00025370340306410486,25.0,60.0
162.10327,0.004778448228346457,732.0273504719195,0.00025370340306410486,25.0,60.0
163.50464,0.0049780316929133855,733.9942639620378,0.00025370340306410486,25.0,60.0
164.90601,0.005166522637795276,735.7642488397561,0.00025370340306410486,25.0,60.0
166.30737,0.005370111220472441,739.2964488710435,0.00025370340306410486,25.0,60.0
167.70874,0.0056436106299212595,740.1524743181936,0.00025370340306410486,25.0,60.0
169.11011,0.005842588385826772,741.4689732492049,0.00025370340306410486,25.0,60.0
170.51147,0.006086785629921259,743.2943369661574,0.00025370340306410486,25.0,60.0
171.91284,0.0062947594488188974,744.829092141628,0.00025370340306410486,25.0,60.0
173.31421,0.006507043700787401,745.0670334254576,0.00025370340306410486,25.0,60.0
174.71558,0.006755593897637795,748.9871982061845,0.00025370340306410486,25.0,60.0
176.11694,0.006992731496062992,750.616832664129,0.00025370340306410486,25.0,60.0
177.51831,0.0072033562992125984,749.6946602701153,0.00025370340306410486,25.0,60.0
178.91968,0.007450169291338583,753.2607289982792,0.00025370340306410486,25.0,60.0
180.32104,0.007738269094488189,755.2211503363404,0.00025370340306410486,25.0,60.0
181.72241,0.008034931299212598,755.4033216874382,0.00025370340306410486,25.0,60.0
183.12378,0.008286711023622047,756.3681493455703,0.00025370340306410486,25.0,60.0
184.52515,0.008511731102362204,756.6375345465923,0.00025370340306410486,25.0,60.0
185.92651,0.008847960433070866,760.5748813683058,0.00025370340306410486,25.0,60.0
187.32788,0.009142300984251969,760.1286697606508,0.00025370340306410486,25.0,60.0
188.72925,0.00938708405511811,762.1261406893674,0.00025370340306410486,25.0,60.0
190.13062,0.00968163562992126,763.2570787923033,0.00025370340306410486,25.0,60.0
191.53198,0.009963228740157482,764.0704750482348,0.00025370340306410486,25.0,60.0
192.93335,0.010223206299212598,765.7952495176514,0.00025370340306410486,25.0,60.0
194.33472,0.010581777952755906,766.3999582833603,0.00025370340306410486,25.0,60.0
195.73608,0.010859106889763779,765.6615737602336,0.00025370340306410486,25.0,60.0
197.13745,0.011149380905511812,766.9199040517286,0.00025370340306410486,25.0,60.0
198.53882,0.011478497244094488,769.2265995724046,0.00025370340306410486,25.0,60.0
199.94019,0.01174770374015748,768.9345570214319,0.00025370340306410486,25.0,60.0
201.34155,0.012032211811023623,770.1108880429682,0.00025370340306410486,25.0,60.0
202.74292,0.012313976377952755,771.5606455649997,0.00025370340306410486,25.0,60.0
204.14429,0.012611633070866142,771.2809354956458,0.00025370340306410486,25.0,60.0
205.54565,0.012875692913385826,772.268029410231,0.00025370340306410486,25.0,60.0
206.94702,0.013180012598425198,776.6403243468739,0.00025370340306410486,25.0,60.0
208.34839,0.013512776377952757,774.1275746988581,0.00025370340306410486,25.0,60.0
209.74976,0.01383605531496063,775.757261302602,0.00025370340306410486,25.0,60.0
211.15112,0.014128423031496064,776.1358658810033,0.00025370340306410486,25.0,60.0
212.55249,0.01443229094488189,777.3069301767742,0.00025370340306410486,25.0,60.0
213.95386,0.014715015551181104,778.811075767847,0.00025370340306410486,25.0,60.0
215.35522,0.015048651968503938,778.9837044376076,0.00025370340306410486,25.0,60.0
216.75659,0.015339790748031497,781.1605569171403,0.00025370340306410486,25.0,60.0
218.15796,0.015707560433070866,782.6918965427335,0.00025370340306410486,25.0,60.0
219.55933,0.016005206692913387,782.8672628669761,0.00025370340306410486,25.0,60.0
220.96069,0.01632712027559055,782.3260155394482,0.00025370340306410486,25.0,60.0
222.36206,0.016609662992125986,785.1223079730928,0.00025370340306410486,25.0,60.0
223.76343,0.016959325393700788,786.5449236064035,0.00025370340306410486,25.0,60.0
225.16479,0.017314203346456693,785.8678886165719,0.00025370340306410486,25.0,60.0
226.56616,0.01759497283464567,785.2825259425354,0.00025370340306410486,25.0,60.0
227.96753,0.017917458267716537,784.7315794962716,0.00025370340306410486,25.0,60.0
229.3689,0.018264037992125986,788.6989101527872,0.00025370340306410486,25.0,60.0
230.77026,0.018564512007874016,787.2011784950723,0.00025370340306410486,25.0,60.0
232.17163,0.018845796259842517,790.076211086197,0.00025370340306410486,25.0,60.0
233.573,0.019151300984251968,788.3600146008239,0.00025370340306410486,25.0,60.0
234.97437,0.01951163031496063,792.3139959326277,0.00025370340306410486,25.0,60.0
236.37573,0.019851375984251966,791.4220681024144,0.00025370340306410486,25.0,60.0
237.7771,0.02016381496062992,790.4536163112062,0.00025370340306410486,25.0,60.0
239.17847,0.020471234251968503,792.9383115190071,0.00025370340306410486,25.0,60.0
240.57983,0.020754442913385827,794.5068832455545,0.00025370340306410486,25.0,60.0
241.9812,0.021104102362204724,792.5769411273922,0.00025370340306410486,25.0,60.0
243.38257,0.021417789370078738,794.2669082755384,0.00025370340306410486,25.0,60.0
244.78394,0.021726240157480314,794.401209782552,0.00025370340306410486,25.0,60.0
246.1853,0.022053498031496064,795.9798456484331,0.00025370340306410486,25.0,60.0
247.58667,0.022347055118110238,795.9984356260104,0.00025370340306410486,25.0,60.0
248.98804,0.022710637795275587,797.981670751421,0.00025370340306410486,25.0,60.0
250.3894,0.022995917322834646,796.6025968608229,0.00025370340306410486,25.0,60.0
251.79077,0.02332055118110236,799.3236168326642,0.00025370340306410486,25.0,60.0
253.19214,0.023680179133858267,800.2515774104396,0.00025370340306410486,25.0,60.0
254.59351,0.023972438976377953,798.2155185899776,0.00025370340306410486,25.0,60.0
255.99487,0.024289133858267718,801.2198988371487,0.00025370340306410486,25.0,60.0
257.39624,0.02461008661417323,802.6986494237889,0.00025370340306410486,25.0,60.0
258.79761,0.02497752559055118,803.6436095322522,0.00025370340306410486,25.0,60.0
260.19897,0.025337159448818897,802.0510246649632,0.00025370340306410486,25.0,60.0
261.60034,0.025612314960629916,801.6881420451582,0.00025370340306410486,25.0,60.0
263.00171,0.02592527559055118,803.6084111174846,0.00025370340306410486,25.0,60.0
264.40308,0.026280435039370078,805.4102831516922,0.00025370340306410486,25.0,60.0
265.80444,0.026626917322834644,806.1318506544297,0.00025370340306410486,25.0,60.0
267.20581,0.026884064960629922,803.9800803045315,0.00025370340306410486,25.0,60.0
268.60718,0.027196805118110234,806.7099650623143,0.00025370340306410486,25.0,60.0
270.00854,0.027530088582677165,807.2828648902331,0.00025370340306410486,25.0,60.0
271.40991,0.027875535433070864,807.9664441779214,0.00025370340306410486,25.0,60.0
272.81128,0.02824012598425197,807.9835740731085,0.00025370340306410486,25.0,60.0
274.21265,0.028579372047244096,809.1077853678886,0.00025370340306410486,25.0,60.0
275.61401,0.028844049212598425,806.4218595192158,0.00025370340306410486,25.0,60.0
277.01538,0.029118984251968502,808.6576106794598,0.00025370340306410486,25.0,60.0
278.41675,0.029416094488188976,810.1494237889139,0.00025370340306410486,25.0,60.0
279.81812,0.029690694881889763,810.155915940971,0.00025370340306410486,25.0,60.0
281.21948,0.03003617716535433,811.7286854043907,0.00025370340306410486,25.0,60.0
282.62085,0.030369375984251965,813.7945194764562,0.00025370340306410486,25.0,60.0
284.02222,0.0306721594488189,811.2241487198206,0.00025370340306410486,25.0,60.0
285.42358,0.03101827559055118,812.2155185899776,0.00025370340306410486,25.0,60.0
286.82495,0.03131594291338583,813.7709235021119,0.00025370340306410486,25.0,60.0
288.22632,0.03164985826771653,815.2138238514888,0.00025370340306410486,25.0,60.0
289.62769,0.03195588385826772,815.1037701413151,0.00025370340306410486,25.0,60.0
291.02905,0.03230202755905512,816.2063409292382,0.00025370340306410486,25.0,60.0
292.43042,0.03267581102362205,815.9124993481776,0.00025370340306410486,25.0,60.0
293.83179,0.03304086614173229,816.7845857016217,0.00025370340306410486,25.0,60.0
295.23315,0.03338965157480315,817.2579652708974,0.00025370340306410486,25.0,60.0
296.63452,0.03370612992125984,817.2111904886061,0.00025370340306410486,25.0,60.0
298.03589,0.03403596850393701,817.5904990353027,0.00025370340306410486,25.0,60.0
299.43726,0.034366127952755905,818.2584345830943,0.00025370340306410486,25.0,60.0
300.83862,0.03469361614173228,817.7638316733587,0.00025370340306410486,25.0,60.0
302.23999,0.03499740157480315,821.4997914168014,0.00025370340306410486,25.0,60.0
303.64136,0.03532291535433071,821.5617927725921,0.00025370340306410486,25.0,60.0
305.04272,0.03565649212598425,821.0240913594411,0.00025370340306410486,25.0,60.0
306.44409,0.0359802874015748,822.3167335871095,0.00025370340306410486,25.0,60.0
307.84546,0.03626162598425197,822.309224591959,0.00025370340306410486,25.0,60.0
309.24683,0.036564419291338586,822.0535276633468,0.00025370340306410486,25.0,60.0
310.64819,0.03691288976377952,822.9433957344737,0.00025370340306410486,25.0,60.0
312.04956,0.03722925393700787,823.3903373833239,0.00025370340306410486,25.0,60.0
313.45093,0.03753571456692913,823.9783594931429,0.00025370340306410486,25.0,60.0
314.85229,0.03784366141732283,824.4924388590499,0.00025370340306410486,25.0,60.0
316.25366,0.038169647637795276,826.1019450383271,0.00025370340306410486,25.0,60.0
317.65503,0.03845369881889764,825.686082286072,0.00025370340306410486,25.0,60.0
319.0564,0.038809482283464564,826.8241643635605,0.00025370340306410486,25.0,60.0
320.45776,0.03917292322834646,827.0015643739897,0.00025370340306410486,25.0,60.0
321.85913,0.03948427755905512,827.487119987485,0.00025370340306410486,25.0,60.0
323.2605,0.039809476377952756,827.4534598738071,0.00025370340306410486,25.0,60.0
324.66187,0.040135942913385826,825.4550242477969,0.00025370340306410486,25.0,60.0
326.06323,0.040435425196850394,828.3476821192053,0.00025370340306410486,25.0,60.0
327.4646,0.04075479921259842,828.7578088334984,0.00025370340306410486,25.0,60.0
328.86597,0.0410935748031496,829.6255931584711,0.00025370340306410486,25.0,60.0
330.26733,0.041408334645669294,829.7939197997601,0.00025370340306410486,25.0,60.0
331.6687,0.041724415354330704,831.4503832716275,0.00025370340306410486,25.0,60.0
333.07007,0.04202462992125984,831.110914115868,0.00025370340306410486,25.0,60.0
334.47144,0.04233472047244095,831.8730510507379,0.00025370340306410486,25.0,60.0
335.8728,0.04266071062992126,833.008343327945,0.00025370340306410486,25.0,60.0
337.27417,0.04302187795275591,833.011654586223,0.00025370340306410486,25.0,60.0
338.67554,0.04334096062992126,833.0730041195183,0.00025370340306410486,25.0,60.0
340.0769,0.04369816535433071,834.787427647703,0.00025370340306410486,25.0,60.0
341.47827,0.04406751181102362,835.5644522083746,0.00025370340306410486,25.0,60.0
342.87964,0.04439805708661417,833.8333680971998,0.00025370340306410486,25.0,60.0
344.28101,0.044663133858267715,834.923189237107,0.00025370340306410486,25.0,60.0
345.68237,0.04501891338582677,836.1306513010377,0.00025370340306410486,25.0,60.0
347.08374,0.04531437598425197,835.5819471241592,0.00025370340306410486,25.0,60.0
348.48511,0.04564334842519685,836.2391927830213,0.00025370340306410486,25.0,60.0
349.88647,0.04595152952755906,837.6635813735204,0.00025370340306410486,25.0,60.0
351.28784,0.0462513562992126,837.9439693382699,0.00025370340306410486,25.0,60.0
352.68921,0.04656938188976378,838.9259790373885,0.00025370340306410486,25.0,60.0
354.09058,0.04691632677165354,839.290139229285,0.00025370340306410486,25.0,60.0
355.49194,0.047245566929133856,841.3682014913699,0.00025370340306410486,25.0,60.0
356.89331,0.047617421259842516,838.847421390207,0.00025370340306410486,25.0,60.0
358.29468,0.04791124212598425,841.5640089690775,0.00025370340306410486,25.0,60.0
359.69604,0.04822714566929134,840.1944777598166,0.00025370340306410486,25.0,60.0
361.09741,0.048522903543307086,842.2640141836575,0.00025370340306410486,25.0,60.0
362.49878,0.04885094291338583,840.692131198832,0.00025370340306410486,25.0,60.0
363.90015,0.04923391141732284,844.2264952808051,0.00025370340306410486,25.0,60.0
365.30151,0.0495997125984252,843.0588204620118,0.00025370340306410486,25.0,60.0
366.70288,0.04992117716535433,842.3558168639515,0.00025370340306410486,25.0,60.0
368.10425,0.050259669291338585,845.1219950982949,0.00025370340306410486,25.0,60.0
369.50562,0.05058576377952755,844.7700370235177,0.00025370340306410486,25.0,60.0
370.90698,0.05086813582677165,844.9627157532461,0.00025370340306410486,25.0,60.0
372.30835,0.05121670472440945,845.3605621317204,0.00025370340306410486,25.0,60.0
373.70972,0.05155315944881889,845.1698649423789,0.00025370340306410486,25.0,60.0
375.11108,0.05186594291338583,844.6666058299005,0.00025370340306410486,25.0,60.0
376.51245,0.052143187007874015,846.642566616259,0.00025370340306410486,25.0,60.0
377.91382,0.05246854330708661,847.0458883036971,0.00025370340306410486,25.0,60.0
379.31519,0.05276313385826772,847.1367262866977,0.00025370340306410486,25.0,60.0
380.71655,0.053115429133858263,847.3158471085154,0.00025370340306410486,25.0,60.0
382.11792,0.05345424409448819,847.9450644000626,0.00025370340306410486,25.0,60.0
383.51929,0.053851242125984244,849.5517547061585,0.00025370340306410486,25.0,60.0
384.92065,0.05416809055118111,848.9089273609011,0.00025370340306410486,25.0,60.0
386.32202,0.05452665748031496,848.7676122438338,0.00025370340306410486,25.0,60.0
387.72339,0.0548034311023622,848.8838452312666,0.00025370340306410486,25.0,60.0
389.12476,0.055091494094488186,850.4900401522658,0.00025370340306410486,25.0,60.0
390.52612,0.055377466535433066,850.3494811492935,0.00025370340306410486,25.0,60.0
391.92749,0.05569475590551182,851.5707618501331,0.00025370340306410486,25.0,60.0
393.32886,0.056062720472440944,852.6436616780518,0.00025370340306410486,25.0,60.0
394.73022,0.05643383070866142,854.0224748396517,0.00025370340306410486,25.0,60.0
396.13159,0.056767112204724406,854.2636752359598,0.00025370340306410486,25.0,60.0
397.53296,0.05712537992125984,853.3460134536164,0.00025370340306410486,25.0,60.0
398.93433,0.057454149606299215,853.3515669812796,0.00025370340306410486,25.0,60.0
400.33569,0.05777080511811024,854.3970902643792,0.00025370340306410486,25.0,60.0
401.73706,0.05808345866141732,855.0536841007457,0.00025370340306410486,25.0,60.0
403.13843,0.0584302342519685,856.0711268707306,0.00025370340306410486,25.0,60.0
404.53979,0.05873769094488188,854.7994472545237,0.00025370340306410486,25.0,60.0
405.94116,0.059095301181102365,857.1453824894404,0.00025370340306410486,25.0,60.0
407.34253,0.05944219291338582,857.1950774365125,0.00025370340306410486,25.0,60.0
408.7439,0.05979944488188976,857.4277519945769,0.00025370340306410486,25.0,60.0
410.14526,0.06012335826771654,856.6706471293737,0.00025370340306410486,25.0,60.0
411.54663,0.06042256102362205,855.6256192313709,0.00025370340306410486,25.0,60.0
412.948,0.06074755708661417,858.6832142670908,0.00025370340306410486,25.0,60.0
414.34937,0.06104794488188977,858.8646295040934,0.00025370340306410486,25.0,60.0
415.75073,0.06137797047244094,860.4082494655055,0.00025370340306410486,25.0,60.0
417.1521,0.06174020472440945,860.190149658445,0.00025370340306410486,25.0,60.0
418.55347,0.06216531496062992,861.0119935339209,0.00025370340306410486,25.0,60.0
419.95483,0.06246292716535433,858.9643062001356,0.00025370340306410486,25.0,60.0
421.3562,0.06275181102362204,860.7607029253794,0.00025370340306410486,25.0,60.0
422.75757,0.06300022637795276,859.2750690931845,0.00025370340306410486,25.0,60.0
424.15894,0.06332226181102361,862.1843354017834,0.00025370340306410486,25.0,60.0
425.5603,0.06363443503937008,861.6419408666633,0.00025370340306410486,25.0,60.0
426.96167,0.0639542874015748,861.052875840851,0.00025370340306410486,25.0,60.0
428.36304,0.0642560531496063,863.0364759868593,0.00025370340306410486,25.0,60.0
429.7644,0.06464436417322834,865.2401835532148,0.00025370340306410486,25.0,60.0
431.16577,0.06501277559055117,864.0827032382542,0.00025370340306410486,25.0,60.0
432.56714,0.0653484842519685,864.8969077540805,0.00025370340306410486,25.0,60.0
433.96851,0.06563586614173228,864.2532200031288,0.00025370340306410486,25.0,60.0
435.36987,0.06597673425196851,865.8364446993795,0.00025370340306410486,25.0,60.0
436.77124,0.06633935433070866,866.4808885644261,0.00025370340306410486,25.0,60.0
438.17261,0.06666248622047244,865.1054909527038,0.00025370340306410486,25.0,60.0
439.57397,0.06693767125984253,865.3197580434896,0.00025370340306410486,25.0,60.0
440.97534,0.06730303543307087,867.169239192783,0.00025370340306410486,25.0,60.0
442.37671,0.06766516338582677,866.93333159514,0.00025370340306410486,25.0,60.0
443.77808,0.0680710688976378,867.0280544402148,0.00025370340306410486,25.0,60.0
445.17944,0.06839131299212599,867.0507117901653,0.00025370340306410486,25.0,60.0
446.58081,0.06874496456692913,869.0808520623664,0.00025370340306410486,25.0,60.0
447.98218,0.06902444881889765,866.7640141836575,0.00025370340306410486,25.0,60.0
449.38354,0.06936834842519685,870.1520832246963,0.00025370340306410486,25.0,60.0
450.78491,0.06970653543307087,869.576836835793,0.00025370340306410486,25.0,60.0
452.18628,0.07002828937007874,868.6776085936277,0.00025370340306410486,25.0,60.0
453.58765,0.07039231692913386,869.4852427386974,0.00025370340306410486,25.0,60.0
454.98901,0.07069858858267716,869.528028367315,0.00025370340306410486,25.0,60.0
456.39038,0.07103730905511811,871.9822182823174,0.00025370340306410486,25.0,60.0
457.79175,0.07135533661417323,869.9268915888825,0.00025370340306410486,25.0,60.0
459.19312,0.07166948818897638,870.7197684726495,0.00025370340306410486,25.0,60.0
460.59448,0.071981718503937,870.4068936747145,0.00025370340306410486,25.0,60.0
461.99585,0.07238386811023623,874.0529019137509,0.00025370340306410486,25.0,60.0
463.39722,0.07275850393700786,872.7428429889973,0.00025370340306410486,25.0,60.0
464.79858,0.07307155708661417,872.257730614799,0.00025370340306410486,25.0,60.0
466.19995,0.07340378346456693,872.2013870782708,0.00025370340306410486,25.0,60.0
467.60132,0.07372813582677165,873.7378109193305,0.00025370340306410486,25.0,60.0
469.00269,0.0740510688976378,875.1267664389634,0.00025370340306410486,25.0,60.0
470.40405,0.07436098818897638,873.8593367054284,0.00025370340306410486,25.0,60.0
471.80542,0.07471121850393701,873.5947228450749,0.00025370340306410486,25.0,60.0
473.20679,0.07502478346456694,876.9285081086718,0.00025370340306410486,25.0,60.0
474.60815,0.0753809842519685,876.5182510298796,0.00025370340306410486,25.0,60.0
476.00952,0.07574831692913385,877.7975178599364,0.00025370340306410486,25.0,60.0
477.41089,0.07612234645669291,876.1575324607603,0.00025370340306410486,25.0,60.0
478.81226,0.07645619881889763,874.6575585336601,0.00025370340306410486,25.0,60.0
480.21362,0.07672656102362205,876.004249882672,0.00025370340306410486,25.0,60.0
481.61499,0.07708675196850394,879.5679459769516,0.00025370340306410486,25.0,60.0
483.01636,0.07743945078740158,878.113938572248,0.00025370340306410486,25.0,60.0
484.41772,0.07779757874015748,877.9906398289618,0.00025370340306410486,25.0,60.0
485.81909,0.07816375984251968,879.091359440997,0.00025370340306410486,25.0,60.0
487.22046,0.07845585236220472,878.8550607498565,0.00025370340306410486,25.0,60.0
488.62183,0.07880138188976378,879.5295666684049,0.00025370340306410486,25.0,60.0
490.02319,0.07918325196850394,879.6253585023726,0.00025370340306410486,25.0,60.0
491.42456,0.07951675,879.1035876310164,0.00025370340306410486,25.0,60.0
492.82593,0.07982875984251968,879.5848672889399,0.00025370340306410486,25.0,60.0
494.22729,0.08012163188976378,880.4057725400219,0.00025370340306410486,25.0,60.0
495.62866,0.08042321456692914,879.2217760859363,0.00025370340306410486,25.0,60.0
497.03003,0.08075990551181103,881.6397768159776,0.00025370340306410486,25.0,60.0
498.4314,0.08109731102362204,882.443343588674,0.00025370340306410486,25.0,60.0
499.83276,0.08146467716535434,882.0640871877771,0.00025370340306410486,25.0,60.0
501.23413,0.0817894468503937,881.4059550503208,0.00025370340306410486,25.0,60.0
502.6355,0.08208031299212598,882.2866193878083,0.00025370340306410486,25.0,60.0
504.03687,0.08245771062992126,885.0021379777859,0.00025370340306410486,25.0,60.0
505.43823,0.08290867125984253,884.7474578922668,0.00025370340306410486,25.0,60.0
506.8396,0.08326477952755906,884.2256609480107,0.00025370340306410486,25.0,60.0
508.24097,0.0836093188976378,885.3123794128383,0.00025370340306410486,25.0,60.0
509.64233,0.08397795866141733,886.4742139020702,0.00025370340306410486,25.0,60.0
511.0437,0.08427531299212598,884.1450696146426,0.00025370340306410486,25.0,60.0
512.44507,0.08462514960629922,885.3494290034937,0.00025370340306410486,25.0,60.0
513.84644,0.08498867322834645,887.6024143505241,0.00025370340306410486,25.0,60.0
515.2478,0.08539278149606298,885.8333159514001,0.00025370340306410486,25.0,60.0
516.64917,0.08572496062992126,887.5419512958231,0.00025370340306410486,25.0,60.0
518.05054,0.08602841535433071,885.4162538457527,0.00025370340306410486,25.0,60.0
519.4519,0.0863347874015748,886.1038483600146,0.00025370340306410486,25.0,60.0
520.85327,0.08672242913385826,889.6120613234604,0.00025370340306410486,25.0,60.0
522.25464,0.08711340944881889,887.6204828701049,0.00025370340306410486,25.0,60.0
523.65601,0.08744623228346457,887.4251968503937,0.00025370340306410486,25.0,60.0
525.05737,0.08774382086614173,888.3035667726964,0.00025370340306410486,25.0,60.0
526.45874,0.08806924212598424,889.389711633728,0.00025370340306410486,25.0,60.0
527.86011,0.08842776181102362,889.1323460395265,0.00025370340306410486,25.0,60.0
529.26147,0.08878812401574804,890.6451739062419,0.00025370340306410486,25.0,60.0
530.66284,0.08912289566929134,889.7180998070605,0.00025370340306410486,25.0,60.0
532.06421,0.08941235826771653,890.0412734004276,0.00025370340306410486,25.0,60.0
533.46558,0.08974490748031497,890.7219846691348,0.00025370340306410486,25.0,60.0
534.86694,0.09008830314960631,890.7161443395735,0.00025370340306410486,25.0,60.0
536.26831,0.09043111023622047,892.0409083798301,0.00025370340306410486,25.0,60.0
537.66968,0.09083749606299213,891.0999113521406,0.00025370340306410486,25.0,60.0
539.07104,0.09114424803149607,890.9399541116964,0.00025370340306410486,25.0,60.0
540.47241,0.09149013188976378,891.3209834697816,0.00025370340306410486,25.0,60.0
541.87378,0.09178797834645669,892.5136100537102,0.00025370340306410486,25.0,60.0
543.27515,0.09220373818897638,892.4585440892737,0.00025370340306410486,25.0,60.0
544.67651,0.09260117125984252,892.4539813318038,0.00025370340306410486,25.0,60.0
546.07788,0.09298149212598425,893.9275173384783,0.00025370340306410486,25.0,60.0
547.47925,0.09334841732283464,894.9616467643531,0.00025370340306410486,25.0,60.0
548.88062,0.09370537204724409,892.9728320383794,0.00025370340306410486,25.0,60.0
550.28198,0.09401457086614173,892.6518224956981,0.00025370340306410486,25.0,60.0
551.68335,0.09430425196850394,892.9250143400949,0.00025370340306410486,25.0,60.0
553.08472,0.09461923425196851,894.6253585023726,0.00025370340306410486,25.0,60.0
554.48608,0.09495211811023622,896.9854252489962,0.00025370340306410486,25.0,60.0
555.88745,0.09531524803149606,894.5777493872869,0.00025370340306410486,25.0,60.0
557.28882,0.09563455511811024,896.0857276946342,0.00025370340306410486,25.0,60.0
558.69019,0.09601748622047243,896.2626062470669,0.00025370340306410486,25.0,60.0
560.09155,0.09636847834645669,896.4106742451895,0.00025370340306410486,25.0,60.0
561.49292,0.09678506102362204,897.2959274130469,0.00025370340306410486,25.0,60.0
562.89429,0.09715187007874015,896.6118266673619,0.00025370340306410486,25.0,60.0
564.29565,0.09751122244094487,897.0101684309329,0.00025370340306410486,25.0,60.0
565.69702,0.09781507677165353,896.1711425144704,0.00025370340306410486,25.0,60.0
567.09839,0.09815676968503936,898.8287792668301,0.00025370340306410486,25.0,60.0
568.49976,0.09854705708661417,899.0023726338843,0.00025370340306410486,25.0,60.0
569.90112,0.09893916929133859,897.5177034989831,0.00025370340306410486,25.0,60.0
571.30249,0.09925960236220473,898.3995671898629,0.00025370340306410486,25.0,60.0
572.70386,0.09956865551181103,895.5640089690776,0.00025370340306410486,25.0,60.0
574.10522,0.09990180708661417,899.6948688533139,0.00025370340306410486,25.0,60.0
575.50659,0.10026154724409449,900.8762840903165,0.00025370340306410486,25.0,60.0
576.90796,0.1006029842519685,899.4594044949679,0.00025370340306410486,25.0,60.0
578.30933,0.10107345078740158,902.2786150075611,0.00025370340306410486,25.0,60.0
579.71069,0.10145940157480315,900.1152422172395,0.00025370340306410486,25.0,60.0
581.11206,0.10180229330708661,900.1766178234344,0.00025370340306410486,25.0,60.0
582.51343,0.10216040157480316,901.7877665954009,0.00025370340306410486,25.0,60.0
583.91479,0.10250563976377954,902.2899306460865,0.00025370340306410486,25.0,60.0
585.31616,0.10287443700787402,901.4920999113522,0.00025370340306410486,25.0,60.0
586.71753,0.10324277755905512,903.4420138707827,0.00025370340306410486,25.0,60.0
588.1189,0.10357929724409448,901.4673828023152,0.00025370340306410486,25.0,60.0
589.52026,0.10393183267716537,903.1289044167493,0.00025370340306410486,25.0,60.0
590.92163,0.10426524409448819,901.5655994159671,0.00025370340306410486,25.0,60.0
592.323,0.1046548090551181,905.0249778380352,0.00025370340306410486,25.0,60.0
593.72437,0.1050557559055118,904.1492934244146,0.00025370340306410486,25.0,60.0
595.12573,0.10546512795275591,902.5442978568076,0.00025370340306410486,25.0,60.0
596.5271,0.10581870669291339,903.1176930698232,0.00025370340306410486,25.0,60.0
597.92847,0.10618800984251968,903.4493925014341,0.00025370340306410486,25.0,60.0
599.32983,0.10650660039370079,902.921077332221,0.00025370340306410486,25.0,60.0
600.7312,0.10687368503937007,905.9320018772488,0.00025370340306410486,25.0,60.0
602.13257,0.10723864763779528,905.8810815038848,0.00025370340306410486,25.0,60.0
603.53394,0.1075712125984252,905.3837409396673,0.00025370340306410486,25.0,60.0
604.9353,0.10789853346456693,904.8483339417011,0.00025370340306410486,25.0,60.0
606.33667,0.10823120472440945,907.696511446003,0.00025370340306410486,25.0,60.0
607.73804,0.10865455118110236,905.6192574438129,0.00025370340306410486,25.0,60.0
609.1394,0.10897776574803149,905.6199614121083,0.00025370340306410486,25.0,60.0
610.54077,0.10934488582677164,905.8793606924963,0.00025370340306410486,25.0,60.0
611.94214,0.10980560039370078,905.9554153412943,0.00025370340306410486,25.0,60.0
613.34351,0.1102242874015748,907.4061114877197,0.00025370340306410486,25.0,60.0
614.74487,0.1105413779527559,907.1896803462481,0.00025370340306410486,25.0,60.0
616.14624,0.11089183661417322,907.6284611774521,0.00025370340306410486,25.0,60.0
617.54761,0.11124851377952755,908.1327110601242,0.00025370340306410486,25.0,60.0
618.94897,0.11154102362204725,908.8319080148095,0.00025370340306410486,25.0,60.0
620.35034,0.11196520078740158,908.7640402565573,0.00025370340306410486,25.0,60.0
621.75171,0.11237776377952756,908.1503624133077,0.00025370340306410486,25.0,60.0
623.15308,0.11275244094488189,907.8008291182146,0.00025370340306410486,25.0,60.0
624.55444,0.11313765354330708,909.3533660113678,0.00025370340306410486,25.0,60.0
625.95581,0.1135169527559055,910.9702508212964,0.00025370340306410486,25.0,60.0
627.35718,0.1139362027559055,909.2510038066434,0.00025370340306410486,25.0,60.0
628.75854,0.11432994488188977,909.7619544245711,0.00025370340306410486,25.0,60.0
630.15991,0.11472340551181102,909.3331334411014,0.00025370340306410486,25.0,60.0
631.56128,0.11502777755905512,908.0611148771966,0.00025370340306410486,25.0,60.0
632.96265,0.11537586614173229,909.9410752463889,0.00025370340306410486,25.0,60.0
634.36401,0.11573602755905511,912.4886061427752,0.00025370340306410486,25.0,60.0
635.76538,0.11615222834645669,912.2924857902697,0.00025370340306410486,25.0,60.0
637.16675,0.11652234055118109,911.2717317620067,0.00025370340306410486,25.0,60.0
638.56812,0.11687406692913385,911.7786671533607,0.00025370340306410486,25.0,60.0
639.96948,0.11724436614173227,910.0957657610679,0.00025370340306410486,25.0,60.0
641.37085,0.11750846850393701,910.3037232100955,0.00025370340306410486,25.0,60.0
642.77222,0.1178873562992126,913.5452625541012,0.00025370340306410486,25.0,60.0
644.17358,0.11827998425196849,911.8578505501381,0.00025370340306410486,25.0,60.0
645.57495,0.11861986023622048,911.5275590551181,0.00025370340306410486,25.0,60.0
646.97632,0.11904645669291337,913.5869531209261,0.00025370340306410486,25.0,60.0
648.37769,0.11944722637795276,913.8303175679199,0.00025370340306410486,25.0,60.0
649.77905,0.11986467125984251,913.3646295040935,0.00025370340306410486,25.0,60.0
651.18042,0.1202118090551181,913.4262397663869,0.00025370340306410486,25.0,60.0
652.58179,0.12057644094488189,912.9655576993273,0.00025370340306410486,25.0,60.0
653.98315,0.1209305846456693,914.225608802211,0.00025370340306410486,25.0,60.0
655.38452,0.12134426181102363,914.2014131511708,0.00025370340306410486,25.0,60.0
656.78589,0.12177430708661419,914.7061323460396,0.00025370340306410486,25.0,60.0
658.18726,0.12215993110236222,914.0913072951973,0.00025370340306410486,25.0,60.0
659.58862,0.12252967913385827,913.8741721854304,0.00025370340306410486,25.0,60.0
660.98999,0.12292987401574804,914.309693904156,0.00025370340306410486,25.0,60.0
662.39136,0.12334771653543307,915.3240339990614,0.00025370340306410486,25.0,60.0
663.79272,0.12374922834645669,914.3333159514001,0.00025370340306410486,25.0,60.0
665.19409,0.12412405708661417,914.4548938832977,0.00025370340306410486,25.0,60.0
666.59546,0.12447592322834644,914.2055587422434,0.00025370340306410486,25.0,60.0
667.99683,0.12488026181102363,916.4519215727173,0.00025370340306410486,25.0,60.0
669.39819,0.12535124409448817,916.2403921364134,0.00025370340306410486,25.0,60.0
670.79956,0.12579225787401574,917.2020910465661,0.00025370340306410486,25.0,60.0
672.20093,0.12614393700787402,914.6333107368201,0.00025370340306410486,25.0,60.0
673.60229,0.12647718503937008,915.7358815247433,0.00025370340306410486,25.0,60.0
675.00366,0.1268305531496063,916.1963550086041,0.00025370340306410486,25.0,60.0
676.40503,0.12715652559055118,916.1725504510612,0.00025370340306410486,25.0,60.0
677.8064,0.12746978937007872,916.8911456432185,0.00025370340306410486,25.0,60.0
679.20776,0.1278837244094488,919.4323668978464,0.00025370340306410486,25.0,60.0
680.60913,0.12832436417322834,918.1600354591437,0.00025370340306410486,25.0,60.0
682.0105,0.12870175196850395,916.5235438285446,0.00025370340306410486,25.0,60.0
683.41187,0.12906054133858266,919.338035146269,0.00025370340306410486,25.0,60.0
684.81323,0.12943617913385827,918.7195598894509,0.00025370340306410486,25.0,60.0
686.2146,0.12988686417322834,921.0069093184544,0.00025370340306410486,25.0,60.0
687.61597,0.130357,918.340616363352,0.00025370340306410486,25.0,60.0
689.01733,0.13078994488188975,921.8568337070449,0.00025370340306410486,25.0,60.0
690.4187,0.13119106692913385,919.086066642332,0.00025370340306410486,25.0,60.0
691.82007,0.1315991122047244,919.6025707879231,0.00025370340306410486,25.0,60.0
693.22144,0.13200020078740157,920.5298795432028,0.00025370340306410486,25.0,60.0
694.6228,0.13242524606299214,921.0653647598687,0.00025370340306410486,25.0,60.0
696.02417,0.1327881437007874,919.0885696407154,0.00025370340306410486,25.0,60.0
697.42554,0.13315214173228346,919.488945090473,0.00025370340306410486,25.0,60.0
698.8269,0.1335744311023622,920.6450435417427,0.00025370340306410486,25.0,60.0
700.22827,0.13398918897637796,922.0546748709392,0.00025370340306410486,25.0,60.0
701.62964,0.13442383267716534,920.7793450487563,0.00025370340306410486,25.0,60.0
703.03101,0.13480410629921258,920.64999739271,0.00025370340306410486,25.0,60.0
704.43237,0.13517402952755905,922.3968816811806,0.00025370340306410486,25.0,60.0
705.83374,0.1355857716535433,921.7094696772175,0.00025370340306410486,25.0,60.0
707.23511,0.135994062992126,921.9092141627992,0.00025370340306410486,25.0,60.0
708.63647,0.1364125157480315,920.7519685039371,0.00025370340306410486,25.0,60.0
710.03784,0.13676878346456692,921.1946341972154,0.00025370340306410486,25.0,60.0
711.43921,0.13712569488188978,921.2609636543777,0.00025370340306410486,25.0,60.0
712.84058,0.13752743897637795,921.3870521979455,0.00025370340306410486,25.0,60.0
714.24194,0.1378414783464567,922.5897429212077,0.00025370340306410486,25.0,60.0
715.64331,0.13830715748031497,923.3809772122856,0.00025370340306410486,25.0,60.0
717.04468,0.1387403937007874,922.4631329196434,0.00025370340306410486,25.0,60.0
718.44604,0.13916769291338582,922.4926735151483,0.00025370340306410486,25.0,60.0
719.84741,0.1395899940944882,922.6192835167128,0.00025370340306410486,25.0,60.0
721.24878,0.13999357086614173,922.6376127652917,0.00025370340306410486,25.0,60.0
722.65015,0.1403911968503937,923.9798977942327,0.00025370340306410486,25.0,60.0
724.05151,0.14079155708661417,922.6118266673619,0.00025370340306410486,25.0,60.0
725.45288,0.1411578779527559,924.2079053032278,0.00025370340306410486,25.0,60.0
726.85425,0.1415842992125984,925.07120508943,0.00025370340306410486,25.0,60.0
728.25562,0.14204072047244096,925.3251029879543,0.00025370340306410486,25.0,60.0
729.65698,0.14250649212598424,923.9603691922615,0.00025370340306410486,25.0,60.0
731.05835,0.14291666141732284,923.9347656046306,0.00025370340306410486,25.0,60.0
732.45972,0.14332050590551182,923.4880325389789,0.00025370340306410486,25.0,60.0
733.86108,0.14370798425196848,924.3309693904156,0.00025370340306410486,25.0,60.0
735.26245,0.1441213681102362,925.9486624602388,0.00025370340306410486,25.0,60.0
736.66382,0.14457317716535434,925.0754028263024,0.00025370340306410486,25.0,60.0
738.06519,0.14506530314960628,925.0294363039058,0.00025370340306410486,25.0,60.0
739.46655,0.1454608405511811,924.1834749960891,0.00025370340306410486,25.0,60.0
740.86792,0.14579310236220472,924.5140272201074,0.00025370340306410486,25.0,60.0
742.26929,0.14620509055118108,924.0102727225322,0.00025370340306410486,25.0,60.0
743.67065,0.14664496653543307,925.7917036032748,0.00025370340306410486,25.0,60.0
745.07202,0.14706250393700787,926.2708192105126,0.00025370340306410486,25.0,60.0
746.47339,0.14748263582677165,926.4353652813265,0.00025370340306410486,25.0,60.0
747.87476,0.14790097047244094,926.0730041195181,0.00025370340306410486,25.0,60.0
749.27612,0.14826972244094488,926.9740313917715,0.00025370340306410486,25.0,60.0
750.67749,0.14876048622047244,926.9073108411118,0.00025370340306410486,25.0,60.0
752.07886,0.1492435649606299,925.3322991083069,0.00025370340306410486,25.0,60.0
753.48022,0.1496982618110236,926.7546800855192,0.00025370340306410486,25.0,60.0
754.88159,0.1500778188976378,926.2250612713146,0.00025370340306410486,25.0,60.0
756.28296,0.15051441141732283,926.8479167753038,0.00025370340306410486,25.0,60.0
757.68433,0.1509686161417323,926.3992282421651,0.00025370340306410486,25.0,60.0
759.08569,0.15139112795275592,926.968034624811,0.00025370340306410486,25.0,60.0
760.48706,0.15182095078740157,929.000912551494,0.00025370340306410486,25.0,60.0
761.88843,0.1522252283464567,927.6823799342963,0.00025370340306410486,25.0,60.0
763.28979,0.15272969881889764,929.0648172289722,0.00025370340306410486,25.0,60.0
764.69116,0.15319523622047246,927.9434739531731,0.00025370340306410486,25.0,60.0
766.09253,0.15365461417322834,927.8176461386035,0.00025370340306410486,25.0,60.0
767.4939,0.15404759448818897,927.0741513271107,0.00025370340306410486,25.0,60.0
768.89526,0.15444756692913386,926.8476039005058,0.00025370340306410486,25.0,60.0
770.29663,0.15483053937007873,928.648328727121,0.00025370340306410486,25.0,60.0
771.698,0.15524482677165355,928.1963810815039,0.00025370340306410486,25.0,60.0
773.09937,0.15569108661417322,928.7335610366584,0.00025370340306410486,25.0,60.0
774.50073,0.15618102952755905,929.6425405433592,0.00025370340306410486,25.0,60.0
775.9021,0.1566206614173228,930.1400114720759,0.00025370340306410486,25.0,60.0
777.30347,0.15706242716535435,928.2221671794338,0.00025370340306410486,25.0,60.0
778.70483,0.1574921437007874,929.4108567554885,0.00025370340306410486,25.0,60.0
780.1062,0.15799622637795274,929.0569171403243,0.00025370340306410486,25.0,60.0
781.50757,0.15835417125984252,927.446211607655,0.00025370340306410486,25.0,60.0
782.90894,0.15876803543307086,928.6365437763988,0.00025370340306410486,25.0,60.0
784.3103,0.15918424803149608,929.5002085831986,0.00025370340306410486,25.0,60.0
785.71167,0.15961836417322833,929.2182301715598,0.00025370340306410486,25.0,60.0
787.11304,0.160070468503937,930.9208687490222,0.00025370340306410486,25.0,60.0
788.5144,0.16052902362204724,929.963185065443,0.00025370340306410486,25.0,60.0
789.91577,0.16094025,929.1680659122908,0.00025370340306410486,25.0,60.0
791.31714,0.16140786417322833,931.152422172394,0.00025370340306410486,25.0,60.0
792.71851,0.16185972244094488,930.6561245241696,0.00025370340306410486,25.0,60.0
794.11987,0.1623750905511811,931.7621108619701,0.00025370340306410486,25.0,60.0
795.52124,0.16285832283464566,930.6007456849351,0.00025370340306410486,25.0,60.0
796.92261,0.16337330511811024,930.8375397611723,0.00025370340306410486,25.0,60.0
798.32397,0.16384157677165354,929.5049277780676,0.00025370340306410486,25.0,60.0
799.72534,0.16431779133858268,931.2964749439433,0.00025370340306410486,25.0,60.0
801.12671,0.1648292657480315,931.7606507795797,0.00025370340306410486,25.0,60.0
802.52808,0.1653290059055118,930.3335766803984,0.00025370340306410486,25.0,60.0
803.92944,0.16574839763779528,929.3467434948114,0.00025370340306410486,25.0,60.0
805.33081,0.16618001377952757,930.4899097877666,0.00025370340306410486,25.0,60.0
806.73218,0.16666655511811024,932.398341763571,0.00025370340306410486,25.0,60.0
808.13354,0.16711336614173228,931.6847786410805,0.00025370340306410486,25.0,60.0
809.53491,0.16758696456692915,929.5631746362831,0.00025370340306410486,25.0,60.0
810.93628,0.16805240944881888,931.2721750013037,0.00025370340306410486,25.0,60.0
812.33765,0.1685074586614173,930.4662877405225,0.00025370340306410486,25.0,60.0
813.73901,0.16901382874015747,931.6016321635292,0.00025370340306410486,25.0,60.0
815.14038,0.16949781102362205,931.1307295197372,0.00025370340306410486,25.0,60.0
816.54175,0.16991304921259842,930.0553527663347,0.00025370340306410486,25.0,60.0
817.94312,0.1703274527559055,930.7055065964437,0.00025370340306410486,25.0,60.0
819.34448,0.1708266535433071,930.7501955467487,0.00025370340306410486,25.0,60.0
820.74585,0.17129846850393698,931.1289565625489,0.00025370340306410486,25.0,60.0
822.14722,0.17172389173228347,930.1612608854357,0.00025370340306410486,25.0,60.0
823.54858,0.17221398622047243,932.1981540386922,0.00025370340306410486,25.0,60.0
824.94995,0.1727171181102362,930.9178703655421,0.00025370340306410486,25.0,60.0
826.35132,0.17321553346456692,931.2256348751108,0.00025370340306410486,25.0,60.0
827.75269,0.1736465157480315,931.4724930906815,0.00025370340306410486,25.0,60.0
829.15405,0.17413493503937008,932.1574020962612,0.00025370340306410486,25.0,60.0
830.55542,0.17459042913385828,931.0714658184284,0.00025370340306410486,25.0,60.0
831.95679,0.17509986023622046,931.7166136517704,0.00025370340306410486,25.0,60.0
833.35815,0.1756084842519685,931.7960317046462,0.00025370340306410486,25.0,60.0
834.75952,0.17616078937007873,931.7407310841112,0.00025370340306410486,25.0,60.0
836.16089,0.1767671122047244,933.8627261824059,0.00025370340306410486,25.0,60.0
837.56226,0.17723809448818897,931.6712728789696,0.00025370340306410486,25.0,60.0
838.96362,0.17770686023622048,931.6003806643375,0.00025370340306410486,25.0,60.0
840.36499,0.17815815354330708,932.6289044167493,0.00025370340306410486,25.0,60.0
841.76636,0.17864354527559054,932.1781039787246,0.00025370340306410486,25.0,60.0
843.16772,0.17915227362204725,932.560463054701,0.00025370340306410486,25.0,60.0
844.56909,0.1795834212598425,932.0314439171925,0.00025370340306410486,25.0,60.0
845.97046,0.18011570866141732,932.3009594827137,0.00025370340306410486,25.0,60.0
847.37183,0.1805238838582677,932.311519007144,0.00025370340306410486,25.0,60.0
848.77319,0.1810232125984252,932.3584241539345,0.00025370340306410486,25.0,60.0
850.17456,0.1815672224409449,932.4132293893728,0.00025370340306410486,25.0,60.0
851.57593,0.18208875196850394,932.3629608385045,0.00025370340306410486,25.0,60.0
852.97729,0.18258437401574804,930.6587839599521,0.00025370340306410486,25.0,60.0
854.37866,0.18306098818897637,930.38029931689,0.00025370340306410486,25.0,60.0
855.78003,0.18349504527559055,932.1957292590082,0.00025370340306410486,25.0,60.0
857.1814,0.18402781496062992,933.0920634092925,0.00025370340306410486,25.0,60.0
858.58276,0.18455538779527558,933.490014079366,0.00025370340306410486,25.0,60.0
859.98413,0.18509160629921262,933.4170621056473,0.00025370340306410486,25.0,60.0
861.3855,0.18562316732283463,933.8572508734422,0.00025370340306410486,25.0,60.0
862.78687,0.18611232283464568,932.3385044584659,0.00025370340306410486,25.0,60.0
864.18823,0.18661661614173228,932.4490796266361,0.00025370340306410486,25.0,60.0
865.5896,0.18712438188976377,932.8751890285238,0.00025370340306410486,25.0,60.0
866.99097,0.18768016141732283,932.3472388799082,0.00025370340306410486,25.0,60.0
868.39233,0.18821475984251967,932.6744798456485,0.00025370340306410486,25.0,60.0
869.7937,0.1887181614173228,932.4278041403766,0.00025370340306410486,25.0,60.0
871.19507,0.18922990551181101,932.9382072274079,0.00025370340306410486,25.0,60.0
872.59644,0.18980676771653543,932.9955415341294,0.00025370340306410486,25.0,60.0
873.9978,0.19038248031496063,934.7605725608802,0.00025370340306410486,25.0,60.0
874.2981,0.1905364311023622,935.3031496062993,0.00025370340306410486,25.0,60.0