File: datasets/am_bench_2022/csv/60-XY.04-4.csv
Time(s),Strain(%),Stress(MPa),SR(s-1),Temp(C),Angle(deg)
18.723389,2.0641198818897636e-05,8.996781561245243,0.00025370340306410486,25.0,60.0
20.224854,6.0950267716535434e-05,13.216130781665537,0.00025370340306410486,25.0,60.0
21.726318,6.247727362204724e-05,18.518591802680294,0.00025370340306410486,25.0,60.0
23.227783,7.813025787401575e-05,24.32784246753924,0.00025370340306410486,25.0,60.0
24.729248,0.00010910711023622047,28.621345883089116,0.00025370340306410486,25.0,60.0
26.230713,0.00011763589566929133,33.2882724096574,0.00025370340306410486,25.0,60.0
27.732178,0.00015089800984251968,39.00938363664807,0.00025370340306410486,25.0,60.0
29.233643,0.0001386289468503937,42.83716170412473,0.00025370340306410486,25.0,60.0
30.735107,0.00018695519291338583,50.07969181832404,0.00025370340306410486,25.0,60.0
32.236572,0.0002086532677165354,56.72108515409084,0.00025370340306410486,25.0,60.0
33.738037,0.00023950588582677165,62.609401887677954,0.00025370340306410486,25.0,60.0
35.239502,0.0002783500590551181,71.46874902226627,0.00025370340306410486,25.0,60.0
36.740967,0.0003198489566929134,79.46492934244147,0.00025370340306410486,25.0,60.0
38.242432,0.00032768139763779527,86.31539865463837,0.00025370340306410486,25.0,60.0
39.743896,0.00037478958661417324,93.54668874172185,0.00025370340306410486,25.0,60.0
41.245361,0.00039028287401574806,100.9448193148042,0.00025370340306410486,25.0,60.0
42.746826,0.0004345139173228347,107.97865411691087,0.00025370340306410486,25.0,60.0
44.248291,0.00046921749999999997,118.44613338895552,0.00025370340306410486,25.0,60.0
45.749756,0.0005066976377952755,125.9124993481775,0.00025370340306410486,25.0,60.0
47.251221,0.0005214874803149606,135.82469103613704,0.00025370340306410486,25.0,60.0
48.752686,0.0005719594291338583,146.37974396412372,0.00025370340306410486,25.0,60.0
50.25415,0.0006280932874015748,158.0985920634093,0.00025370340306410486,25.0,60.0
51.755615,0.0006454249212598425,164.48599103092246,0.00025370340306410486,25.0,60.0
53.25708,0.0006766923818897637,173.2795145226052,0.00025370340306410486,25.0,60.0
54.758545,0.000731495905511811,187.74303592845598,0.00025370340306410486,25.0,60.0
56.26001,0.0007637012795275591,195.78475256818064,0.00025370340306410486,25.0,60.0
57.761475,0.0008118032677165354,207.18999061375607,0.00025370340306410486,25.0,60.0
59.262939,0.0008347486417322835,220.54979141680138,0.00025370340306410486,25.0,60.0
60.764404,0.0009088923622047243,229.48811336496846,0.00025370340306410486,25.0,60.0
62.265869,0.000926962874015748,239.90215622881576,0.00025370340306410486,25.0,60.0
63.767334,0.000986687224409449,250.37452156228815,0.00025370340306410486,25.0,60.0
65.268799,0.0010246196456692913,260.75548834541377,0.00025370340306410486,25.0,60.0
66.770264,0.0010646197637795276,271.83261198310475,0.00025370340306410486,25.0,60.0
68.271729,0.0011001148818897636,284.2973353496376,0.00025370340306410486,25.0,60.0
69.773193,0.0011503666141732284,295.19718934139854,0.00025370340306410486,25.0,60.0
71.274658,0.0011802607874015747,307.7277467799969,0.00025370340306410486,25.0,60.0
72.776123,0.0012614290354330709,319.78862700109505,0.00025370340306410486,25.0,60.0
74.277588,0.0012765851181102362,328.5376753402513,0.00025370340306410486,25.0,60.0
75.779053,0.0013465796062992125,341.1523439536945,0.00025370340306410486,25.0,60.0
77.280518,0.00137061781496063,350.5169213119883,0.00025370340306410486,25.0,60.0
78.781982,0.0014023351181102362,361.7004484538771,0.00025370340306410486,25.0,60.0
80.283447,0.001451885059055118,372.6857433383741,0.00025370340306410486,25.0,60.0
81.784912,0.0014704484448818896,381.8793346195964,0.00025370340306410486,25.0,60.0
83.286377,0.0015204939173228346,392.5590811910101,0.00025370340306410486,25.0,60.0
84.787842,0.0015561894291338581,404.0930541794859,0.00025370340306410486,25.0,60.0
86.289307,0.0016083037007874016,416.7182301715597,0.00025370340306410486,25.0,60.0
87.790771,0.0016503688779527558,427.06009803410336,0.00025370340306410486,25.0,60.0
89.292236,0.0016802337007874016,436.3109454033478,0.00025370340306410486,25.0,60.0
90.793701,0.0017213637007874015,445.5014079365907,0.00025370340306410486,25.0,60.0
92.295166,0.0017394907480314961,456.6835792876884,0.00025370340306410486,25.0,60.0
93.796631,0.001787045964566929,466.7332742347604,0.00025370340306410486,25.0,60.0
95.298096,0.0018271588188976376,476.55222401835533,0.00025370340306410486,25.0,60.0
96.799561,0.0018645679330708661,486.9044428221307,0.00025370340306410486,25.0,60.0
98.301025,0.0018947194881889762,495.51478333420243,0.00025370340306410486,25.0,60.0
99.80249,0.0019339646653543305,506.0184074672785,0.00025370340306410486,25.0,60.0
101.30396,0.001964053346456693,512.9634197215414,0.00025370340306410486,25.0,60.0
102.80542,0.0020001025590551183,524.3169682432081,0.00025370340306410486,25.0,60.0
104.30688,0.0020380923228346458,535.6704124732753,0.00025370340306410486,25.0,60.0
105.80835,0.002063833464566929,540.7689941075247,0.00025370340306410486,25.0,60.0
107.30981,0.0020909795275590552,549.3752933201231,0.00025370340306410486,25.0,60.0
108.81128,0.0021342415354330705,558.7705063357147,0.00025370340306410486,25.0,60.0
110.31274,0.0021578094488188975,566.1753663242426,0.00025370340306410486,25.0,60.0
111.81421,0.002178232874015748,571.2675600980341,0.00025370340306410486,25.0,60.0
113.31567,0.0022034948818897638,577.7021431923658,0.00025370340306410486,25.0,60.0
114.81714,0.0022255814960629922,582.8713823851489,0.00025370340306410486,25.0,60.0
116.3186,0.002268324409448819,591.6616259060332,0.00025370340306410486,25.0,60.0
117.82007,0.002285580905511811,596.1762788757367,0.00025370340306410486,25.0,60.0
119.32153,0.0023167094488188975,603.3408510194504,0.00025370340306410486,25.0,60.0
120.823,0.0023382832677165356,607.4192000834333,0.00025370340306410486,25.0,60.0
122.32446,0.0023639452755905514,611.8858789174532,0.00025370340306410486,25.0,60.0
123.82593,0.0023903718503937004,616.4083016113052,0.00025370340306410486,25.0,60.0
125.32739,0.002411773031496063,621.3623872347082,0.00025370340306410486,25.0,60.0
126.82886,0.0024583891732283467,628.4735099337748,0.00025370340306410486,25.0,60.0
128.33032,0.0024744891732283465,631.9198779788288,0.00025370340306410486,25.0,60.0
129.83179,0.0024802848425196852,635.8669239192783,0.00025370340306410486,25.0,60.0
131.33325,0.002512637007874016,641.7042290243521,0.00025370340306410486,25.0,60.0
132.83472,0.0025577608267716534,645.6053605882046,0.00025370340306410486,25.0,60.0
134.33618,0.002605603346456693,650.3405642175524,0.00025370340306410486,25.0,60.0
135.83765,0.002614547244094488,653.8155081608176,0.00025370340306410486,25.0,60.0
137.33911,0.002646734448818898,658.665615059707,0.00025370340306410486,25.0,60.0
138.84058,0.0026819090551181103,660.9763258069563,0.00025370340306410486,25.0,60.0
140.34204,0.002722505905511811,665.6411847525682,0.00025370340306410486,25.0,60.0
141.84351,0.002760846062992126,670.6469990092298,0.00025370340306410486,25.0,60.0
143.34497,0.0027811,674.4374250404129,0.00025370340306410486,25.0,60.0
144.84644,0.002834930905511811,677.9967408875215,0.00025370340306410486,25.0,60.0
146.3479,0.002882277165354331,681.0534755175471,0.00025370340306410486,25.0,60.0
147.84937,0.0028790844488188975,682.1477811962246,0.00025370340306410486,25.0,60.0
149.35083,0.002957323622047244,687.4158106064557,0.00025370340306410486,25.0,60.0
150.85229,0.0030046858267716537,689.9528341242113,0.00025370340306410486,25.0,60.0
152.35376,0.0030669746062992127,695.0299838348021,0.00025370340306410486,25.0,60.0
153.85522,0.0031066127952755905,697.3664806799812,0.00025370340306410486,25.0,60.0
155.35669,0.0031913110236220475,701.5398133180373,0.00025370340306410486,25.0,60.0
156.85815,0.0032566976377952756,703.4348698962299,0.00025370340306410486,25.0,60.0
158.35962,0.0033137088582677163,707.0272201074204,0.00025370340306410486,25.0,60.0
159.86108,0.0033914342519685042,708.8695572821609,0.00025370340306410486,25.0,60.0
161.36255,0.003445587795275591,711.9030870313397,0.00025370340306410486,25.0,60.0
162.86401,0.0035469614173228347,714.9748135787662,0.00025370340306410486,25.0,60.0
164.36548,0.0036563456692913386,720.1233769619857,0.00025370340306410486,25.0,60.0
165.86694,0.0037526850393700788,721.5132711060124,0.00025370340306410486,25.0,60.0
167.36841,0.003879040748031496,726.1742973353497,0.00025370340306410486,25.0,60.0
168.86987,0.003987592913385827,726.9127600771758,0.00025370340306410486,25.0,60.0
170.37134,0.004126111023622047,730.3034624810972,0.00025370340306410486,25.0,60.0
171.8728,0.004244120866141733,731.9490535537362,0.00025370340306410486,25.0,60.0
173.37427,0.004385445078740157,735.3441883506284,0.00025370340306410486,25.0,60.0
174.87573,0.004510886614173228,737.1552380455754,0.00025370340306410486,25.0,60.0
176.3772,0.004671244881889763,738.5359545288628,0.00025370340306410486,25.0,60.0
177.87866,0.004830526771653543,740.7953798821505,0.00025370340306410486,25.0,60.0
179.38013,0.00499931062992126,742.3090681545602,0.00025370340306410486,25.0,60.0
180.88159,0.005171104133858268,744.5141315117068,0.00025370340306410486,25.0,60.0
182.38306,0.005363041141732284,746.9925170777494,0.00025370340306410486,25.0,60.0
183.88452,0.0055371391732283465,748.611070553267,0.00025370340306410486,25.0,60.0
185.38599,0.0057436606299212595,750.973796735673,0.00025370340306410486,25.0,60.0
186.88745,0.0059841409448818895,753.4686082286072,0.00025370340306410486,25.0,60.0
188.38892,0.0062178872047244085,755.1921833446316,0.00025370340306410486,25.0,60.0
189.89038,0.006473263976377952,756.7699327319185,0.00025370340306410486,25.0,60.0
191.39185,0.006699988779527558,757.6111748448662,0.00025370340306410486,25.0,60.0
192.89331,0.006902684251968503,759.0707879230328,0.00025370340306410486,25.0,60.0
194.39478,0.007121160826771653,761.4589091098712,0.00025370340306410486,25.0,60.0
195.89624,0.007379261811023622,762.6476508317255,0.00025370340306410486,25.0,60.0
197.39771,0.007610471062992127,763.6811545080044,0.00025370340306410486,25.0,60.0
198.89917,0.007854087401574804,762.8905720394222,0.00025370340306410486,25.0,60.0
200.40063,0.008135354133858267,767.1255149397716,0.00025370340306410486,25.0,60.0
201.9021,0.008412708661417323,768.7196641810502,0.00025370340306410486,25.0,60.0
203.40356,0.008715973622047245,770.097590864056,0.00025370340306410486,25.0,60.0
204.90503,0.009010623622047244,770.7492829952548,0.00025370340306410486,25.0,60.0
206.40649,0.009339343897637796,772.6246284611775,0.00025370340306410486,25.0,60.0
207.90796,0.009626533661417323,773.7751212389842,0.00025370340306410486,25.0,60.0
209.40942,0.00992979940944882,772.635448714606,0.00025370340306410486,25.0,60.0
210.91089,0.010185402755905511,774.8627001095061,0.00025370340306410486,25.0,60.0
212.41235,0.010436688188976377,775.9414663398863,0.00025370340306410486,25.0,60.0
213.91382,0.01069996220472441,777.0854669656359,0.00025370340306410486,25.0,60.0
215.41528,0.01102285688976378,779.9980966783125,0.00025370340306410486,25.0,60.0
216.91675,0.011351012401574804,779.5429159931168,0.00025370340306410486,25.0,60.0
218.41821,0.011637162992125985,780.9687646660062,0.00025370340306410486,25.0,60.0
219.91968,0.011853497440944882,781.2999687125202,0.00025370340306410486,25.0,60.0
221.42114,0.012122512598425197,782.1880116806592,0.00025370340306410486,25.0,60.0
222.92261,0.012433534842519686,784.0800177295719,0.00025370340306410486,25.0,60.0
224.42407,0.012758742322834646,783.8721906450436,0.00025370340306410486,25.0,60.0
225.92554,0.013035136811023623,787.2499608906503,0.00025370340306410486,25.0,60.0
227.427,0.013353726968503937,787.1636856651196,0.00025370340306410486,25.0,60.0
228.92847,0.01366972401574803,789.7132502476926,0.00025370340306410486,25.0,60.0
230.42993,0.014018224803149605,789.3237471971632,0.00025370340306410486,25.0,60.0
231.9314,0.014308263582677165,788.1168065912291,0.00025370340306410486,25.0,60.0
233.43286,0.014598416732283464,791.269098399124,0.00025370340306410486,25.0,60.0
234.93433,0.014932576771653543,791.7834384940293,0.00025370340306410486,25.0,60.0
236.43579,0.015282418307086614,794.3835323564688,0.00025370340306410486,25.0,60.0
237.93726,0.01561080846456693,794.4604213380612,0.00025370340306410486,25.0,60.0
239.43872,0.01589603523622047,793.4747875058664,0.00025370340306410486,25.0,60.0
240.94019,0.016226194094488187,797.5015643739897,0.00025370340306410486,25.0,60.0
242.44165,0.016541517913385827,797.4146894717632,0.00025370340306410486,25.0,60.0
243.94312,0.01684611318897638,796.9203994368254,0.00025370340306410486,25.0,60.0
245.44458,0.01712186535433071,797.6351879856078,0.00025370340306410486,25.0,60.0
246.94604,0.017435322244094487,798.9235542577046,0.00025370340306410486,25.0,60.0
248.44751,0.017759033858267718,799.3758929968192,0.00025370340306410486,25.0,60.0
249.94897,0.01809845472440945,802.2246180320176,0.00025370340306410486,25.0,60.0
251.45044,0.018414976771653543,800.6614433957345,0.00025370340306410486,25.0,60.0
252.9519,0.01874147342519685,804.1633988632216,0.00025370340306410486,25.0,60.0
254.45337,0.019047798031496064,803.8910413516192,0.00025370340306410486,25.0,60.0
255.95483,0.019356012992125984,805.224409448819,0.00025370340306410486,25.0,60.0
257.4563,0.01964612657480315,804.5300620535015,0.00025370340306410486,25.0,60.0
258.95776,0.019986415354330708,805.5464358345935,0.00025370340306410486,25.0,60.0
260.45923,0.02028160433070866,806.0023987067842,0.00025370340306410486,25.0,60.0
261.96069,0.020602846456692914,805.8349846169891,0.00025370340306410486,25.0,60.0
263.46216,0.02096328937007874,808.5491995619752,0.00025370340306410486,25.0,60.0
264.96362,0.021327596456692913,809.4013401470512,0.00025370340306410486,25.0,60.0
266.46509,0.02165321653543307,809.283647077228,0.00025370340306410486,25.0,60.0
267.96655,0.02191798031496063,808.7590864055901,0.00025370340306410486,25.0,60.0
269.46802,0.022242490157480317,811.5784012097826,0.00025370340306410486,25.0,60.0
270.96948,0.022555423228346458,812.4326536997445,0.00025370340306410486,25.0,60.0
272.47095,0.022867423228346458,812.6033529749178,0.00025370340306410486,25.0,60.0
273.97241,0.023186562992125983,813.3849663659593,0.00025370340306410486,25.0,60.0
275.47388,0.023490606299212596,814.9385983209053,0.00025370340306410486,25.0,60.0
276.97534,0.023858718503937008,815.4834176357095,0.00025370340306410486,25.0,60.0
278.47681,0.02419345472440945,814.9302549929604,0.00025370340306410486,25.0,60.0
279.97827,0.02449231496062992,816.8486207435992,0.00025370340306410486,25.0,60.0
281.47974,0.02482900984251968,817.7951452260521,0.00025370340306410486,25.0,60.0
282.9812,0.025189224409448818,818.098790217448,0.00025370340306410486,25.0,60.0
284.48267,0.02553408464566929,819.9557803618919,0.00025370340306410486,25.0,60.0
285.98413,0.02586475196850394,818.680919851906,0.00025370340306410486,25.0,60.0
287.4856,0.026184742125984248,819.1345100902123,0.00025370340306410486,25.0,60.0
288.98706,0.02643408464566929,819.9730927673776,0.00025370340306410486,25.0,60.0
290.48853,0.02674644881889764,821.3529227720708,0.00025370340306410486,25.0,60.0
291.98999,0.02707949212598425,823.0211972675601,0.00025370340306410486,25.0,60.0
293.49146,0.027357116141732283,821.4319236585493,0.00025370340306410486,25.0,60.0
294.99292,0.027709242125984253,824.9298638994629,0.00025370340306410486,25.0,60.0
296.49438,0.028074562992125983,825.1037701413152,0.00025370340306410486,25.0,60.0
297.99585,0.02837274409448819,821.978203055744,0.00025370340306410486,25.0,60.0
299.49731,0.028681129921259842,825.2806747666476,0.00025370340306410486,25.0,60.0
300.99878,0.02901682086614173,826.7311623298743,0.00025370340306410486,25.0,60.0
302.50024,0.02934487401574803,827.5276112009177,0.00025370340306410486,25.0,60.0
304.00171,0.029657864173228344,827.5617927725922,0.00025370340306410486,25.0,60.0
305.50317,0.030012578740157482,829.1187359858163,0.00025370340306410486,25.0,60.0
307.00464,0.03031795275590551,829.5366845700579,0.00025370340306410486,25.0,60.0
308.5061,0.030646391732283465,828.7975178599364,0.00025370340306410486,25.0,60.0
310.00757,0.030944470472440942,831.522266256453,0.00025370340306410486,25.0,60.0
311.50903,0.03126087598425197,831.5243520884393,0.00025370340306410486,25.0,60.0
313.0105,0.03161577559055118,832.5831204046514,0.00025370340306410486,25.0,60.0
314.51196,0.03193797637795275,831.961672837253,0.00025370340306410486,25.0,60.0
316.01343,0.03228650196850393,833.6380560045889,0.00025370340306410486,25.0,60.0
317.51489,0.032566992125984254,834.0037544975752,0.00025370340306410486,25.0,60.0
319.01636,0.03285015748031496,834.0767064712937,0.00025370340306410486,25.0,60.0
320.51782,0.03317058070866142,834.888486207436,0.00025370340306410486,25.0,60.0
322.01929,0.03353806692913386,836.7857850550138,0.00025370340306410486,25.0,60.0
323.52075,0.03388602755905512,837.1319288731293,0.00025370340306410486,25.0,60.0
325.02222,0.03420916535433071,835.8584762997341,0.00025370340306410486,25.0,60.0
326.52368,0.034525594488188975,837.554101267143,0.00025370340306410486,25.0,60.0
328.02515,0.03486428149606299,837.9293945872661,0.00025370340306410486,25.0,60.0
329.52661,0.0352042874015748,839.3023152735047,0.00025370340306410486,25.0,60.0
331.02808,0.03550131496062992,838.6133128226521,0.00025370340306410486,25.0,60.0
332.52954,0.03585178937007874,841.0328257808833,0.00025370340306410486,25.0,60.0
334.03101,0.03612740748031496,839.8193669499922,0.00025370340306410486,25.0,60.0
335.53247,0.03640642519685039,840.6680659122908,0.00025370340306410486,25.0,60.0
337.03394,0.03670907874015748,840.4335141054389,0.00025370340306410486,25.0,60.0
338.5354,0.03707068700787401,844.6454607081399,0.00025370340306410486,25.0,60.0
340.03687,0.03740803937007874,844.0273765448194,0.00025370340306410486,25.0,60.0
341.53833,0.03775849212598425,843.8800907336914,0.00025370340306410486,25.0,60.0
343.03979,0.03808863188976378,842.7550451061168,0.00025370340306410486,25.0,60.0
344.54126,0.03843441535433071,846.1240287844814,0.00025370340306410486,25.0,60.0
346.04272,0.038808370078740155,846.1111748448662,0.00025370340306410486,25.0,60.0
347.54419,0.03913442125984252,846.0384314543463,0.00025370340306410486,25.0,60.0
349.04565,0.039422688976377955,846.3971684830786,0.00025370340306410486,25.0,60.0
350.54712,0.03976133464566929,847.7933722688637,0.00025370340306410486,25.0,60.0
352.04858,0.04010229921259842,849.7634145069615,0.00025370340306410486,25.0,60.0
353.55005,0.04037953346456693,848.3505501381863,0.00025370340306410486,25.0,60.0
355.05151,0.04072273818897638,849.8702351775564,0.00025370340306410486,25.0,60.0
356.55298,0.04102525,850.1867862543672,0.00025370340306410486,25.0,60.0
358.05444,0.04136888582677165,851.3020023987068,0.00025370340306410486,25.0,60.0
359.55591,0.041668019685039366,850.2260520415081,0.00025370340306410486,25.0,60.0
361.05737,0.04197589566929134,852.7878969599,0.00025370340306410486,25.0,60.0
362.55884,0.04230089173228346,852.5913333680973,0.00025370340306410486,25.0,60.0
364.0603,0.042648891732283464,853.3367836470773,0.00025370340306410486,25.0,60.0
365.56177,0.04295499015748031,853.9602909735621,0.00025370340306410486,25.0,60.0
367.06323,0.04327055118110236,853.0296709600042,0.00025370340306410486,25.0,60.0
368.5647,0.043588519685039365,855.4956979715284,0.00025370340306410486,25.0,60.0
370.06616,0.04390540354330709,855.789096313292,0.00025370340306410486,25.0,60.0
371.56763,0.04423075984251969,856.1442874276477,0.00025370340306410486,25.0,60.0
373.06909,0.04457641338582677,857.5068050268551,0.00025370340306410486,25.0,60.0
374.57056,0.04485564763779528,857.5686760181468,0.00025370340306410486,25.0,60.0
376.07202,0.0452108031496063,857.5889868071127,0.00025370340306410486,25.0,60.0
377.57349,0.0455448031496063,856.3621786515097,0.00025370340306410486,25.0,60.0
379.07495,0.045884694881889766,857.669239192783,0.00025370340306410486,25.0,60.0
380.57642,0.04618920472440945,860.040308703134,0.00025370340306410486,25.0,60.0
382.07788,0.04651610039370079,858.447880273244,0.00025370340306410486,25.0,60.0
383.57935,0.04682500984251969,861.1423058872608,0.00025370340306410486,25.0,60.0
385.08081,0.047142712598425195,861.690749335141,0.00025370340306410486,25.0,60.0
386.58228,0.04748343503937008,861.8333941700996,0.00025370340306410486,25.0,60.0
388.08374,0.04780545275590551,863.1685612973876,0.00025370340306410486,25.0,60.0
389.58521,0.04808738188976378,861.0246128174375,0.00025370340306410486,25.0,60.0
391.08667,0.04840643307086614,863.3714345309486,0.00025370340306410486,25.0,60.0
392.58813,0.048757822834645664,861.7906867601814,0.00025370340306410486,25.0,60.0
394.0896,0.04909238385826772,864.4999478542004,0.00025370340306410486,25.0,60.0
395.59106,0.049435728346456695,866.9658705741252,0.00025370340306410486,25.0,60.0
397.09253,0.0497259842519685,864.7466235594723,0.00025370340306410486,25.0,60.0
398.59399,0.05004935826771653,866.3833759190697,0.00025370340306410486,25.0,60.0
400.09546,0.05037484842519685,865.5196328935705,0.00025370340306410486,25.0,60.0
401.59692,0.05068777165354331,866.289539552589,0.00025370340306410486,25.0,60.0
403.09839,0.05102168110236221,868.0152005005997,0.00025370340306410486,25.0,60.0
404.59985,0.05133594291338582,869.5440632007093,0.00025370340306410486,25.0,60.0
406.10132,0.05161473031496063,868.0630703446838,0.00025370340306410486,25.0,60.0
407.60278,0.05189472440944882,871.7018824633676,0.00025370340306410486,25.0,60.0
409.10425,0.0522348937007874,870.1901496584451,0.00025370340306410486,25.0,60.0
410.60571,0.05259862992125984,871.4373989675132,0.00025370340306410486,25.0,60.0
412.10718,0.052984692913385825,870.8890858841321,0.00025370340306410486,25.0,60.0
413.60864,0.053310624015748036,870.326823799343,0.00025370340306410486,25.0,60.0
415.11011,0.05361718307086614,870.6609480106378,0.00025370340306410486,25.0,60.0
416.61157,0.05398793897637795,871.8280492256349,0.00025370340306410486,25.0,60.0
418.11304,0.054338832677165355,872.3964384418836,0.00025370340306410486,25.0,60.0
419.6145,0.05462816141732283,873.7659435782448,0.00025370340306410486,25.0,60.0
421.11597,0.05491960236220473,873.7394795849195,0.00025370340306410486,25.0,60.0
422.61743,0.0552749783464567,875.1958856964071,0.00025370340306410486,25.0,60.0
424.1189,0.05561986220472441,873.6496584450123,0.00025370340306410486,25.0,60.0
425.62036,0.05596719488188977,875.167883401992,0.00025370340306410486,25.0,60.0
427.12183,0.05627180708661417,875.8076862908692,0.00025370340306410486,25.0,60.0
428.62329,0.056632889763779524,876.3142305887261,0.00025370340306410486,25.0,60.0
430.12476,0.056984998031496065,877.5742034729103,0.00025370340306410486,25.0,60.0
431.62622,0.05725589960629922,876.5717265474267,0.00025370340306410486,25.0,60.0
433.12769,0.057549486220472436,877.6001199353393,0.00025370340306410486,25.0,60.0
434.62915,0.057862992125984246,878.8020545445065,0.00025370340306410486,25.0,60.0
436.13062,0.05817022637795275,879.1376388381916,0.00025370340306410486,25.0,60.0
437.63208,0.05849639763779527,878.5437503259112,0.00025370340306410486,25.0,60.0
439.13354,0.05875629921259843,878.9777858893467,0.00025370340306410486,25.0,60.0
440.63501,0.05908949803149606,880.1186838400167,0.00025370340306410486,25.0,60.0
442.13647,0.059413,879.9505136361266,0.00025370340306410486,25.0,60.0
443.63794,0.05974541929133858,881.0246649632372,0.00025370340306410486,25.0,60.0
445.1394,0.06003699606299213,882.3379830004693,0.00025370340306410486,25.0,60.0
446.64087,0.0603549468503937,882.7088439276216,0.00025370340306410486,25.0,60.0
448.14233,0.06070848622047244,883.0403608489337,0.00025370340306410486,25.0,60.0
449.6438,0.0610489311023622,884.1759660009387,0.00025370340306410486,25.0,60.0
451.14526,0.061403954724409446,884.9372686030141,0.00025370340306410486,25.0,60.0
452.64673,0.06178415157480315,884.4759607863588,0.00025370340306410486,25.0,60.0
454.14819,0.06214379133858268,886.5285758982113,0.00025370340306410486,25.0,60.0
455.64966,0.06251029527559056,886.0750117328049,0.00025370340306410486,25.0,60.0
457.15112,0.06281054724409449,883.1569067111645,0.00025370340306410486,25.0,60.0
458.65259,0.06309343503937008,886.4936121395422,0.00025370340306410486,25.0,60.0
460.15405,0.06338736811023622,886.7875058664025,0.00025370340306410486,25.0,60.0
461.65552,0.06367389370078741,887.584710851541,0.00025370340306410486,25.0,60.0
463.15698,0.0640027874015748,889.5321739583876,0.00025370340306410486,25.0,60.0
464.65845,0.06431967716535433,886.7581738540961,0.00025370340306410486,25.0,60.0
466.15991,0.06468873818897637,889.2994472545237,0.00025370340306410486,25.0,60.0
467.66138,0.06501724606299213,888.096365437764,0.00025370340306410486,25.0,60.0
469.16284,0.0653408346456693,890.4431871512751,0.00025370340306410486,25.0,60.0
470.66431,0.06569385826771654,891.4158366793555,0.00025370340306410486,25.0,60.0
472.16577,0.06603129921259843,891.5311831881943,0.00025370340306410486,25.0,60.0
473.66724,0.06634049212598425,891.3886426448349,0.00025370340306410486,25.0,60.0
475.1687,0.06665110433070866,889.8359232413828,0.00025370340306410486,25.0,60.0
476.67017,0.06700717125984253,891.2109297596079,0.00025370340306410486,25.0,60.0
478.17163,0.06726140157480315,891.7723575116024,0.00025370340306410486,25.0,60.0
479.6731,0.06760463779527559,894.0141575846066,0.00025370340306410486,25.0,60.0
481.17456,0.06795404133858268,892.5591854826095,0.00025370340306410486,25.0,60.0
482.67603,0.06829724212598424,894.3293528706263,0.00025370340306410486,25.0,60.0
484.17749,0.06861512992125984,894.4930124628461,0.00025370340306410486,25.0,60.0
485.67896,0.06891125393700787,894.902122334046,0.00025370340306410486,25.0,60.0
487.18042,0.06922751574803149,895.6106012410701,0.00025370340306410486,25.0,60.0
488.68188,0.0695713562992126,894.7712624498097,0.00025370340306410486,25.0,60.0
490.18335,0.06990109448818897,895.0646347186733,0.00025370340306410486,25.0,60.0
491.68481,0.07027970078740158,896.6479115607239,0.00025370340306410486,25.0,60.0
493.18628,0.07060363779527559,896.0994159670439,0.00025370340306410486,25.0,60.0
494.68774,0.07098523031496064,897.9695729259009,0.00025370340306410486,25.0,60.0
496.18921,0.07131229330708662,897.0025290712833,0.00025370340306410486,25.0,60.0
497.69067,0.07166587992125983,898.4728320383794,0.00025370340306410486,25.0,60.0
499.19214,0.07194224212598424,896.8454919956198,0.00025370340306410486,25.0,60.0
500.6936,0.07224286023622048,899.3569379986442,0.00025370340306410486,25.0,60.0
502.19507,0.07253737401574803,901.1633206445222,0.00025370340306410486,25.0,60.0
503.69653,0.07286639566929133,899.7779892579653,0.00025370340306410486,25.0,60.0
505.198,0.07325203149606299,901.6249413359753,0.00025370340306410486,25.0,60.0
506.69946,0.07358055511811024,901.1375345465923,0.00025370340306410486,25.0,60.0
508.20093,0.07386712204724409,899.8480732127028,0.00025370340306410486,25.0,60.0
509.70239,0.07411038582677165,900.37273817594,0.00025370340306410486,25.0,60.0
511.20386,0.07443985433070867,902.5292016478073,0.00025370340306410486,25.0,60.0
512.70532,0.0748221279527559,902.5349376857695,0.00025370340306410486,25.0,60.0
514.20679,0.0751785,901.9048339156282,0.00025370340306410486,25.0,60.0
515.70825,0.07552270472440945,903.0299838348021,0.00025370340306410486,25.0,60.0
517.20972,0.07585847440944882,904.170621056474,0.00025370340306410486,25.0,60.0
518.71118,0.07616079724409448,902.315325650519,0.00025370340306410486,25.0,60.0
520.21265,0.07651833070866142,905.8118840277416,0.00025370340306410486,25.0,60.0
521.71411,0.07684891338582676,904.7606768524795,0.00025370340306410486,25.0,60.0
523.21558,0.07721643307086613,905.8587370287323,0.00025370340306410486,25.0,60.0
524.71704,0.07757634842519685,906.6254367210722,0.00025370340306410486,25.0,60.0
526.21851,0.07791444094488188,905.0913855138969,0.00025370340306410486,25.0,60.0
527.71997,0.0782293248031496,906.9809667831256,0.00025370340306410486,25.0,60.0
529.22144,0.07855025,905.9616467643532,0.00025370340306410486,25.0,60.0
530.7229,0.07889660236220472,908.3656984929864,0.00025370340306410486,25.0,60.0
532.22437,0.07926683267716536,908.5357198727643,0.00025370340306410486,25.0,60.0
533.72583,0.07955376181102362,907.3210095426813,0.00025370340306410486,25.0,60.0
535.22729,0.07985823818897637,908.5125410648172,0.00025370340306410486,25.0,60.0
536.72876,0.08021695669291339,909.4238932054022,0.00025370340306410486,25.0,60.0
538.23022,0.08058448228346457,910.2093914585181,0.00025370340306410486,25.0,60.0
539.73169,0.08089906102362204,909.8456745059186,0.00025370340306410486,25.0,60.0
541.23315,0.08125326377952756,909.163033842624,0.00025370340306410486,25.0,60.0
542.73462,0.08159012401574803,912.0548052354383,0.00025370340306410486,25.0,60.0
544.23608,0.08192400196850394,911.220472440945,0.00025370340306410486,25.0,60.0
545.73755,0.08219852952755906,909.3855660426552,0.00025370340306410486,25.0,60.0
547.23901,0.08258022834645669,913.5739166710122,0.00025370340306410486,25.0,60.0
548.74048,0.082953531496063,912.0094123168379,0.00025370340306410486,25.0,60.0
550.24194,0.08326228543307086,910.6454346352401,0.00025370340306410486,25.0,60.0
551.74341,0.08361868700787402,912.3100589247537,0.00025370340306410486,25.0,60.0
553.24487,0.08396367322834646,913.4520780101163,0.00025370340306410486,25.0,60.0
554.74634,0.08433893503937008,914.1568545653648,0.00025370340306410486,25.0,60.0
556.2478,0.08463319881889764,913.027871929916,0.00025370340306410486,25.0,60.0
557.74927,0.08494817519685038,912.4424571100798,0.00025370340306410486,25.0,60.0
559.25073,0.08527280511811024,915.8308390259165,0.00025370340306410486,25.0,60.0
560.7522,0.0856157657480315,916.2200292016478,0.00025370340306410486,25.0,60.0
562.25366,0.0859675905511811,915.3610835897169,0.00025370340306410486,25.0,60.0
563.75513,0.08631914763779527,915.9951504406321,0.00025370340306410486,25.0,60.0
565.25659,0.08666347637795276,915.9196433227304,0.00025370340306410486,25.0,60.0
566.75806,0.08700584448818897,916.735307920947,0.00025370340306410486,25.0,60.0
568.25952,0.08734988582677165,917.1796944256141,0.00025370340306410486,25.0,60.0
569.76099,0.0877085157480315,916.2716535433071,0.00025370340306410486,25.0,60.0
571.26245,0.08800219291338583,917.787271210304,0.00025370340306410486,25.0,60.0
572.76392,0.08836006692913385,918.5364759868593,0.00025370340306410486,25.0,60.0
574.26538,0.08870414763779527,919.5793398341764,0.00025370340306410486,25.0,60.0
575.76685,0.08906157086614172,918.5755071179017,0.00025370340306410486,25.0,60.0
577.26831,0.08938835236220473,918.0661469468635,0.00025370340306410486,25.0,60.0
578.76978,0.08972767125984252,919.0354852166658,0.00025370340306410486,25.0,60.0
580.27124,0.09003317322834646,918.8648120143923,0.00025370340306410486,25.0,60.0
581.77271,0.09036652559055118,920.1023100589248,0.00025370340306410486,25.0,60.0
583.27417,0.09071419291338582,919.6702299629765,0.00025370340306410486,25.0,60.0
584.77563,0.09102037007874016,920.3601188924232,0.00025370340306410486,25.0,60.0
586.2771,0.09137183267716535,921.8372268863743,0.00025370340306410486,25.0,60.0
587.77856,0.09173293307086615,922.057725400219,0.00025370340306410486,25.0,60.0
589.28003,0.09206733464566928,923.3228607185691,0.00025370340306410486,25.0,60.0
590.78149,0.09240830118110235,924.4398758929968,0.00025370340306410486,25.0,60.0
592.28296,0.09273684251968504,922.8278145695364,0.00025370340306410486,25.0,60.0
593.78442,0.0930988996062992,925.0638786045783,0.00025370340306410486,25.0,60.0
595.28589,0.0935039527559055,925.8524795327736,0.00025370340306410486,25.0,60.0
596.78735,0.09391936220472441,923.1874120039631,0.00025370340306410486,25.0,60.0
598.28882,0.09425833267716535,923.6739062418523,0.00025370340306410486,25.0,60.0
599.79028,0.09460729724409449,925.1752098868436,0.00025370340306410486,25.0,60.0
601.29175,0.09490858070866141,925.2110340512072,0.00025370340306410486,25.0,60.0
602.79321,0.09523926377952756,925.0508943004642,0.00025370340306410486,25.0,60.0
604.29468,0.09559738385826771,926.1793554779164,0.00025370340306410486,25.0,60.0
605.79614,0.09592098031496063,925.0749595870052,0.00025370340306410486,25.0,60.0
607.29761,0.09626312007874016,925.5367627887574,0.00025370340306410486,25.0,60.0
608.79907,0.09661597244094487,926.695155655212,0.00025370340306410486,25.0,60.0
610.30054,0.09694311811023622,925.5160087604943,0.00025370340306410486,25.0,60.0
611.802,0.09730395472440945,926.0705011211347,0.00025370340306410486,25.0,60.0
613.30347,0.09763866141732283,928.3228085727695,0.00025370340306410486,25.0,60.0
614.80493,0.09798256692913386,927.4726234551807,0.00025370340306410486,25.0,60.0
616.3064,0.09831716929133857,926.9917088178547,0.00025370340306410486,25.0,60.0
617.80786,0.09865941535433069,928.8738593106326,0.00025370340306410486,25.0,60.0
619.30933,0.09907586220472442,929.7669864942379,0.00025370340306410486,25.0,60.0
620.81079,0.09940654921259844,928.830004693122,0.00025370340306410486,25.0,60.0
622.31226,0.09974079330708661,928.7338739114565,0.00025370340306410486,25.0,60.0
623.81372,0.100070437007874,930.6687177347865,0.00025370340306410486,25.0,60.0
625.31519,0.10039227952755907,929.0925848672889,0.00025370340306410486,25.0,60.0
626.81665,0.10076394094488189,931.0805652604683,0.00025370340306410486,25.0,60.0
628.31812,0.10113922637795275,931.6431402200552,0.00025370340306410486,25.0,60.0
629.81958,0.10149102362204725,930.9141158679669,0.00025370340306410486,25.0,60.0
631.32104,0.1019066594488189,931.7786671533609,0.00025370340306410486,25.0,60.0
632.82251,0.10227062401574803,929.1034572665172,0.00025370340306410486,25.0,60.0
634.32397,0.10263929133858267,931.4185743338373,0.00025370340306410486,25.0,60.0
635.82544,0.10301162204724411,931.1988319340877,0.00025370340306410486,25.0,60.0
637.3269,0.10333375590551182,933.1354747875058,0.00025370340306410486,25.0,60.0
638.82837,0.10371601181102362,931.7074359910309,0.00025370340306410486,25.0,60.0
640.32983,0.1040308720472441,932.3938832977004,0.00025370340306410486,25.0,60.0
641.8313,0.10436012992125983,933.1785472180215,0.00025370340306410486,25.0,60.0
643.33276,0.1047260531496063,933.3888773009334,0.00025370340306410486,25.0,60.0
644.83423,0.10508101771653544,933.1723940136621,0.00025370340306410486,25.0,60.0
646.33569,0.10540280118110236,935.0126975022162,0.00025370340306410486,25.0,60.0
647.83716,0.1057607342519685,933.9848777180998,0.00025370340306410486,25.0,60.0
649.33862,0.10613983267716535,934.3069041038744,0.00025370340306410486,25.0,60.0
650.84009,0.10649032677165356,936.268029410231,0.00025370340306410486,25.0,60.0
652.34155,0.10685857283464567,935.9189393544351,0.00025370340306410486,25.0,60.0
653.84302,0.10725055708661418,936.7476664754655,0.00025370340306410486,25.0,60.0
655.34448,0.10760357283464568,936.9847734265005,0.00025370340306410486,25.0,60.0
656.84595,0.10799202362204725,936.0257078792304,0.00025370340306410486,25.0,60.0
658.34741,0.10835226771653543,937.8590238306305,0.00025370340306410486,25.0,60.0
659.84888,0.1086534468503937,935.991969546853,0.00025370340306410486,25.0,60.0
661.35034,0.10900520866141733,938.215283933879,0.00025370340306410486,25.0,60.0
662.85181,0.10940942913385827,937.751368827241,0.00025370340306410486,25.0,60.0
664.35327,0.10983506299212599,937.3940136621995,0.00025370340306410486,25.0,60.0
665.85474,0.11024568897637796,939.2787714449601,0.00025370340306410486,25.0,60.0
667.3562,0.11060911417322834,937.8425979037388,0.00025370340306410486,25.0,60.0
668.85767,0.11100391141732283,939.1088804296814,0.00025370340306410486,25.0,60.0
670.35913,0.11131783464566929,937.7569223549043,0.00025370340306410486,25.0,60.0
671.8606,0.11162832874015748,938.7096782604161,0.00025370340306410486,25.0,60.0
673.36206,0.11199942716535434,940.691375084737,0.00025370340306410486,25.0,60.0
674.86353,0.11241854921259843,941.1602701152422,0.00025370340306410486,25.0,60.0
676.36499,0.1127323188976378,938.0266204307243,0.00025370340306410486,25.0,60.0
677.86646,0.1130498996062992,939.2176565677635,0.00025370340306410486,25.0,60.0
679.36792,0.11342259448818898,941.9096052562967,0.00025370340306410486,25.0,60.0
680.86938,0.1137645216535433,940.9940553788392,0.00025370340306410486,25.0,60.0
682.37085,0.11414199212598425,941.5975126453565,0.00025370340306410486,25.0,60.0
683.87231,0.11456754330708661,943.6261146164676,0.00025370340306410486,25.0,60.0
685.37378,0.11496441732283465,941.3362621890807,0.00025370340306410486,25.0,60.0
686.87524,0.1153603188976378,941.1370913072952,0.00025370340306410486,25.0,60.0
688.37671,0.1157501909448819,942.251055952443,0.00025370340306410486,25.0,60.0
689.87817,0.11610653937007874,943.2477446941649,0.00025370340306410486,25.0,60.0
691.37964,0.1164889468503937,943.5756374824008,0.00025370340306410486,25.0,60.0
692.8811,0.11683856102362204,941.9723105803828,0.00025370340306410486,25.0,60.0
694.38257,0.11715761023622047,942.8456484330187,0.00025370340306410486,25.0,60.0
695.88403,0.11753811811023622,944.0819471241592,0.00025370340306410486,25.0,60.0
697.3855,0.11792540748031495,944.3848099285602,0.00025370340306410486,25.0,60.0
698.88696,0.11829512007874014,944.7414089795068,0.00025370340306410486,25.0,60.0
700.38843,0.11865707874015746,943.9205819471242,0.00025370340306410486,25.0,60.0
701.88989,0.11899468897637797,944.1712468060697,0.00025370340306410486,25.0,60.0
703.39136,0.119384031496063,944.9736142253741,0.00025370340306410486,25.0,60.0
704.89282,0.11974415944881889,945.561219168796,0.00025370340306410486,25.0,60.0
706.39429,0.12011451771653542,945.0041195181728,0.00025370340306410486,25.0,60.0
707.89575,0.12054574803149606,944.7478229128644,0.00025370340306410486,25.0,60.0
709.39722,0.1209206594488189,946.7674558064349,0.00025370340306410486,25.0,60.0
710.89868,0.12129113385826772,947.098034103353,0.00025370340306410486,25.0,60.0
712.40015,0.1216825531496063,945.4263962037859,0.00025370340306410486,25.0,60.0
713.90161,0.12204530905511811,944.6376388381916,0.00025370340306410486,25.0,60.0
715.40308,0.12241533858267716,946.7070448975335,0.00025370340306410486,25.0,60.0
716.90454,0.12278145078740156,946.7814048078428,0.00025370340306410486,25.0,60.0
718.40601,0.12316637007874015,948.2416957814048,0.00025370340306410486,25.0,60.0
719.90747,0.12355538385826771,947.234551806852,0.00025370340306410486,25.0,60.0
721.40894,0.12387592322834645,946.712728789696,0.00025370340306410486,25.0,60.0
722.9104,0.124202468503937,946.4696250717004,0.00025370340306410486,25.0,60.0
724.41187,0.12457653543307086,949.9802888877301,0.00025370340306410486,25.0,60.0
725.91333,0.1250222440944882,949.0551963289357,0.00025370340306410486,25.0,60.0
727.41479,0.1254259251968504,948.4631068467435,0.00025370340306410486,25.0,60.0
728.91626,0.12580178543307086,948.9526516139125,0.00025370340306410486,25.0,60.0
730.41772,0.12622158858267715,948.95304270741,0.00025370340306410486,25.0,60.0
731.91919,0.1265664035433071,948.7126766438963,0.00025370340306410486,25.0,60.0
733.42065,0.1269809724409449,948.6808677061063,0.00025370340306410486,25.0,60.0
734.92212,0.12731414763779528,948.6751316681442,0.00025370340306410486,25.0,60.0
736.42358,0.1277173248031496,950.1876988058613,0.00025370340306410486,25.0,60.0
737.92505,0.1281089783464567,949.1876205871617,0.00025370340306410486,25.0,60.0
739.42651,0.1285195590551181,950.2084267612244,0.00025370340306410486,25.0,60.0
740.92798,0.12892504527559054,949.657115294363,0.00025370340306410486,25.0,60.0
742.42944,0.12932283661417324,950.4836783647077,0.00025370340306410486,25.0,60.0
743.93091,0.1297553818897638,951.5706575585338,0.00025370340306410486,25.0,60.0
745.43237,0.13014485236220472,949.5028940918809,0.00025370340306410486,25.0,60.0
746.93384,0.1305149527559055,951.4771340668509,0.00025370340306410486,25.0,60.0
748.4353,0.13087398818897636,951.0006778953955,0.00025370340306410486,25.0,60.0
749.93677,0.13128540157480315,953.095166084372,0.00025370340306410486,25.0,60.0
751.43823,0.13172646456692913,952.0150701361006,0.00025370340306410486,25.0,60.0
752.9397,0.13214918897637795,952.1910100641393,0.00025370340306410486,25.0,60.0
754.44116,0.13250138385826774,951.029697032904,0.00025370340306410486,25.0,60.0
755.94263,0.13287570669291338,950.9066068728164,0.00025370340306410486,25.0,60.0
757.44409,0.1332062559055118,951.4181310945404,0.00025370340306410486,25.0,60.0
758.94556,0.13362175196850393,954.9692339782031,0.00025370340306410486,25.0,60.0
760.44702,0.13409043307086613,951.561349533295,0.00025370340306410486,25.0,60.0
761.94849,0.13444725196850393,951.7332220889607,0.00025370340306410486,25.0,60.0
763.44995,0.13478926377952755,953.5785055013819,0.00025370340306410486,25.0,60.0
764.95142,0.13525283070866143,954.8513323251813,0.00025370340306410486,25.0,60.0
766.45288,0.1356532716535433,953.5808520623664,0.00025370340306410486,25.0,60.0
767.95435,0.13604591141732283,954.8315429942118,0.00025370340306410486,25.0,60.0
769.45581,0.1364308307086614,953.2007091828754,0.00025370340306410486,25.0,60.0
770.95728,0.13680612992125984,953.9088752151015,0.00025370340306410486,25.0,60.0
772.45874,0.13715437007874015,954.0867184648276,0.00025370340306410486,25.0,60.0
773.96021,0.13762435629921257,955.5530062053501,0.00025370340306410486,25.0,60.0
775.46167,0.13805800393700787,955.7629973405643,0.00025370340306410486,25.0,60.0
776.96313,0.13848516141732284,953.8575637482401,0.00025370340306410486,25.0,60.0
778.4646,0.138920405511811,954.8848881472597,0.00025370340306410486,25.0,60.0
779.96606,0.13932772244094488,954.1311466861345,0.00025370340306410486,25.0,60.0
781.46753,0.13970435826771652,955.2190645043542,0.00025370340306410486,25.0,60.0
782.96899,0.14008518307086615,955.7539500443239,0.00025370340306410486,25.0,60.0
784.47046,0.14051337401574804,955.1542733482819,0.00025370340306410486,25.0,60.0
785.97192,0.14090979133858267,957.0416384210251,0.00025370340306410486,25.0,60.0
787.47339,0.14139352755905513,956.1061688480993,0.00025370340306410486,25.0,60.0
788.97485,0.14181768307086615,955.3470042238098,0.00025370340306410486,25.0,60.0
790.47632,0.14220626377952755,956.5291495020076,0.00025370340306410486,25.0,60.0
791.97778,0.14255253346456692,956.8392605725609,0.00025370340306410486,25.0,60.0
793.47925,0.1429422401574803,956.1346665276112,0.00025370340306410486,25.0,60.0
794.98071,0.1433248720472441,956.6933826980237,0.00025370340306410486,25.0,60.0
796.48218,0.14375231102362204,957.9050424988268,0.00025370340306410486,25.0,60.0
797.98364,0.14414982086614173,956.8131615998332,0.00025370340306410486,25.0,60.0
799.48511,0.14452877952755905,955.9947593471346,0.00025370340306410486,25.0,60.0
800.98657,0.14490262204724408,956.665302184909,0.00025370340306410486,25.0,60.0
802.48804,0.14533957874015746,956.61818845492,0.00025370340306410486,25.0,60.0
803.9895,0.14578541732283465,957.871669187047,0.00025370340306410486,25.0,60.0
805.49097,0.14624292913385828,958.7281639463941,0.00025370340306410486,25.0,60.0
806.99243,0.14663968700787403,958.22120248214,0.00025370340306410486,25.0,60.0
808.4939,0.1471016122047244,957.1569588569641,0.00025370340306410486,25.0,60.0
809.99536,0.14757339173228345,958.9987485008082,0.00025370340306410486,25.0,60.0
811.49683,0.1480346594488189,959.1255410126714,0.00025370340306410486,25.0,60.0
812.99829,0.14844374803149607,958.5716222558273,0.00025370340306410486,25.0,60.0
814.49976,0.148832468503937,957.9541899150023,0.00025370340306410486,25.0,60.0
816.00122,0.14922082677165355,959.6201960682067,0.00025370340306410486,25.0,60.0
817.50269,0.1495837224409449,958.2608593627784,0.00025370340306410486,25.0,60.0
819.00415,0.1500058838582677,959.9712676643896,0.00025370340306410486,25.0,60.0
820.50562,0.1504934094488189,961.0495124367733,0.00025370340306410486,25.0,60.0
822.00708,0.15101659251968502,959.0401261928351,0.00025370340306410486,25.0,60.0
823.50854,0.1514103464566929,958.6177191427231,0.00025370340306410486,25.0,60.0
825.01001,0.1518139094488189,960.6303384262399,0.00025370340306410486,25.0,60.0
826.51147,0.15223764370078738,960.0181206653804,0.00025370340306410486,25.0,60.0
828.01294,0.15266535236220471,959.0580643479168,0.00025370340306410486,25.0,60.0
829.5144,0.1530999625984252,960.8372268863743,0.00025370340306410486,25.0,60.0
831.01587,0.1535408720472441,958.8054961672838,0.00025370340306410486,25.0,60.0
832.51733,0.15400392322834647,960.4806799812276,0.00025370340306410486,25.0,60.0
834.0188,0.15444396456692913,960.9654794806278,0.00025370340306410486,25.0,60.0
835.52026,0.15488255118110236,960.1276529175575,0.00025370340306410486,25.0,60.0
837.02173,0.15528910826771655,960.2792929029566,0.00025370340306410486,25.0,60.0
838.52319,0.1557519940944882,959.1877509516609,0.00025370340306410486,25.0,60.0
840.02466,0.15618172244094486,960.5606455649998,0.00025370340306410486,25.0,60.0
841.52612,0.15667117322834645,960.6691609740835,0.00025370340306410486,25.0,60.0
843.02759,0.15710108858267716,961.3351149814882,0.00025370340306410486,25.0,60.0
844.52905,0.15756954921259841,960.8700526672576,0.00025370340306410486,25.0,60.0
846.03052,0.1580378779527559,960.836079678782,0.00025370340306410486,25.0,60.0
847.53198,0.1584872716535433,962.1084111174845,0.00025370340306410486,25.0,60.0
849.03345,0.1589596161417323,961.9588048182719,0.00025370340306410486,25.0,60.0
850.53491,0.1594700688976378,961.9378161339104,0.00025370340306410486,25.0,60.0
852.03638,0.15990382086614172,960.9467591385514,0.00025370340306410486,25.0,60.0
853.53784,0.16037104921259843,963.1886113573552,0.00025370340306410486,25.0,60.0
855.03931,0.16086224803149607,961.0565781926266,0.00025370340306410486,25.0,60.0
856.54077,0.16127430511811022,961.838504458466,0.00025370340306410486,25.0,60.0
858.04224,0.1617137834645669,959.2549668874173,0.00025370340306410486,25.0,60.0
859.5437,0.1621437125984252,961.2997862022214,0.00025370340306410486,25.0,60.0
861.04517,0.1626087342519685,962.19395630182,0.00025370340306410486,25.0,60.0
862.54663,0.163125781496063,963.0614277519946,0.00025370340306410486,25.0,60.0
864.0481,0.16360196062992127,960.7968660374407,0.00025370340306410486,25.0,60.0
865.54956,0.16397669488188976,959.9860249256923,0.00025370340306410486,25.0,60.0
867.05103,0.16431992716535432,962.0015904468895,0.00025370340306410486,25.0,60.0
868.55249,0.16471490157480315,963.8901027272254,0.00025370340306410486,25.0,60.0
870.05396,0.16518851181102362,961.8238514887627,0.00025370340306410486,25.0,60.0
871.55542,0.1656828307086614,962.3837148667675,0.00025370340306410486,25.0,60.0
873.05688,0.1662069527559055,963.3769619857121,0.00025370340306410486,25.0,60.0
874.55835,0.16664025984251968,961.9602127548626,0.00025370340306410486,25.0,60.0
876.05981,0.16712687204724408,962.5015383010898,0.00025370340306410486,25.0,60.0
877.56128,0.1676071338582677,961.6057256088022,0.00025370340306410486,25.0,60.0
879.06274,0.16808942716535433,961.1431402200552,0.00025370340306410486,25.0,60.0
880.56421,0.1685139940944882,962.2364812014392,0.00025370340306410486,25.0,60.0
882.06567,0.16902944488188976,962.7647963706523,0.00025370340306410486,25.0,60.0
883.56714,0.169522812992126,962.3056526046827,0.00025370340306410486,25.0,60.0
885.0686,0.1700375846456693,962.8520884392763,0.00025370340306410486,25.0,60.0
886.57007,0.1705344153543307,962.9319497314492,0.00025370340306410486,25.0,60.0
888.07153,0.1710463937007874,962.544688950305,0.00025370340306410486,25.0,60.0
889.573,0.1715401377952756,960.96362830474,0.00025370340306410486,25.0,60.0
891.07446,0.1720324625984252,963.9339573447359,0.00025370340306410486,25.0,60.0
892.57593,0.1724977657480315,962.4980966783125,0.00025370340306410486,25.0,60.0
894.07739,0.17294483661417323,962.4143765969651,0.00025370340306410486,25.0,60.0
895.57886,0.1733787657480315,961.9864942378891,0.00025370340306410486,25.0,60.0
897.08032,0.17384454921259843,964.177738958127,0.00025370340306410486,25.0,60.0
898.58179,0.17433131299212598,961.9679042603118,0.00025370340306410486,25.0,60.0
899.88306,0.17480942913385827,965.0159566146948,0.00025370340306410486,25.0,60.0