File: datasets/am_bench_2022/csv/60-XY.15-4.csv
Time(s),Strain(%),Stress(MPa),SR(s-1),Temp(C),Angle(deg)
10.867188,6.023376574803149e-08,20.11402965879265,0.00025370340306410486,25.0,60.0
12.268555,3.8619665354330704e-05,24.2698469816273,0.00025370340306410486,25.0,60.0
13.669922,4.7523551181102366e-05,28.997307086614175,0.00025370340306410486,25.0,60.0
15.071289,6.308699212598426e-05,32.17256430446194,0.00025370340306410486,25.0,60.0
16.472656,7.764695669291339e-05,36.80470341207349,0.00025370340306410486,25.0,60.0
17.874023,0.00010405914173228346,41.592131233595794,0.00025370340306410486,25.0,60.0
19.275391,0.00010782602559055117,46.46209186351706,0.00025370340306410486,25.0,60.0
20.676758,0.0001393223622047244,53.99182414698163,0.00025370340306410486,25.0,60.0
22.078125,0.00015299520472440944,60.4847375328084,0.00025370340306410486,25.0,60.0
23.479492,0.0001688353307086614,67.07900524934384,0.00025370340306410486,25.0,60.0
24.880859,0.00020302188976377953,74.04644881889763,0.00025370340306410486,25.0,60.0
26.282227,0.0002272945866141732,81.00851968503937,0.00025370340306410486,25.0,60.0
27.683594,0.00025320907480314963,88.2103622047244,0.00025370340306410486,25.0,60.0
29.084961,0.00027541614173228347,94.01914698162729,0.00025370340306410486,25.0,60.0
30.486328,0.0003000655708661417,101.89966666666666,0.00025370340306410486,25.0,60.0
31.887695,0.0003520064566929134,111.42106299212598,0.00025370340306410486,25.0,60.0
33.289063,0.00036885106299212596,120.83071391076116,0.00025370340306410486,25.0,60.0
34.69043,0.00039248651574803146,128.05789238845145,0.00025370340306410486,25.0,60.0
36.091797,0.0004311524409448819,139.83261679790024,0.00025370340306410486,25.0,60.0
37.493164,0.00045608822834645665,146.6275905511811,0.00025370340306410486,25.0,60.0
38.894531,0.0004718188779527559,155.4483097112861,0.00025370340306410486,25.0,60.0
40.295898,0.0005084743897637795,165.47444619422572,0.00025370340306410486,25.0,60.0
41.697266,0.0005247245078740157,172.25083989501312,0.00025370340306410486,25.0,60.0
43.098633,0.0005577799015748032,181.4061128608924,0.00025370340306410486,25.0,60.0
44.5,0.0005831837401574804,190.64116272965882,0.00025370340306410486,25.0,60.0
45.901367,0.0006247592716535433,200.83828083989502,0.00025370340306410486,25.0,60.0
47.302734,0.0006513043503937007,210.4805065616798,0.00025370340306410486,25.0,60.0
48.704102,0.0007053183070866142,225.06934908136483,0.00025370340306410486,25.0,60.0
50.105469,0.0007512651574803149,236.3699212598425,0.00025370340306410486,25.0,60.0
51.506836,0.0007460613779527559,242.8096089238845,0.00025370340306410486,25.0,60.0
52.908203,0.0007890493897637794,255.698280839895,0.00025370340306410486,25.0,60.0
54.30957,0.0008238496062992125,266.9815748031496,0.00025370340306410486,25.0,60.0
55.710938,0.0008512273622047244,274.814435695538,0.00025370340306410486,25.0,60.0
57.112305,0.0008887251968503938,283.5061942257218,0.00025370340306410486,25.0,60.0
58.513672,0.0009327915157480315,295.5924409448819,0.00025370340306410486,25.0,60.0
59.915039,0.0009618672047244094,307.06146981627296,0.00025370340306410486,25.0,60.0
61.316406,0.0009914251377952756,315.5958530183727,0.00025370340306410486,25.0,60.0
62.717773,0.0010332279724409449,329.51417322834646,0.00025370340306410486,25.0,60.0
64.119141,0.0010656295472440945,338.8723884514436,0.00025370340306410486,25.0,60.0
65.520508,0.0011052231496062991,347.5199212598425,0.00025370340306410486,25.0,60.0
66.921875,0.0011381680314960629,360.71204724409444,0.00025370340306410486,25.0,60.0
68.323242,0.0011725870866141732,368.3148031496063,0.00025370340306410486,25.0,60.0
69.724609,0.0012153500196850392,379.9231496062992,0.00025370340306410486,25.0,60.0
71.125977,0.001242669311023622,389.1048556430446,0.00025370340306410486,25.0,60.0
72.527344,0.0012597341338582678,398.8903412073491,0.00025370340306410486,25.0,60.0
73.928711,0.0013025299606299213,409.3295275590551,0.00025370340306410486,25.0,60.0
75.330078,0.0013399180708661416,419.6256955380577,0.00025370340306410486,25.0,60.0
76.731445,0.0013591792322834645,429.42971128608923,0.00025370340306410486,25.0,60.0
78.132813,0.001407119153543307,437.92734908136487,0.00025370340306410486,25.0,60.0
79.53418,0.001455411437007874,449.27797900262465,0.00025370340306410486,25.0,60.0
80.935547,0.0014671539763779528,458.66383202099735,0.00025370340306410486,25.0,60.0
82.336914,0.0015070651771653544,468.9844094488189,0.00025370340306410486,25.0,60.0
83.738281,0.001531044625984252,478.5305249343832,0.00025370340306410486,25.0,60.0
85.139648,0.0015743219881889764,488.6400262467191,0.00025370340306410486,25.0,60.0
86.541016,0.0016112036417322833,498.0598950131233,0.00025370340306410486,25.0,60.0
87.942383,0.0016265363582677163,505.83926509186347,0.00025370340306410486,25.0,60.0
89.34375,0.0016763516732283465,514.7886351706037,0.00025370340306410486,25.0,60.0
90.745117,0.001690712559055118,522.2228083989501,0.00025370340306410486,25.0,60.0
92.146484,0.001715138503937008,530.8779002624672,0.00025370340306410486,25.0,60.0
93.547852,0.0017661348228346458,540.0755118110236,0.00025370340306410486,25.0,60.0
94.949219,0.0017928568307086614,547.2562729658792,0.00025370340306410486,25.0,60.0
96.350586,0.0018209829527559055,555.192125984252,0.00025370340306410486,25.0,60.0
97.751953,0.0018471184645669292,561.2771128608923,0.00025370340306410486,25.0,60.0
99.15332,0.0018746040354330707,570.788530183727,0.00025370340306410486,25.0,60.0
100.55469,0.0018912983464566928,575.720183727034,0.00025370340306410486,25.0,60.0
101.95605,0.0019337248622047242,581.5567979002625,0.00025370340306410486,25.0,60.0
103.35742,0.001971646850393701,588.8090026246718,0.00025370340306410486,25.0,60.0
104.75879,0.0019789925196850395,593.2827296587926,0.00025370340306410486,25.0,60.0
106.16016,0.00202804625984252,600.0169291338583,0.00025370340306410486,25.0,60.0
107.56152,0.002035993897637795,604.1362992125985,0.00025370340306410486,25.0,60.0
108.96289,0.0020697718503937005,611.6610761154856,0.00025370340306410486,25.0,60.0
110.36426,0.002070078346456693,615.4797900262467,0.00025370340306410486,25.0,60.0
111.76563,0.0020979437007874013,621.2741994750656,0.00025370340306410486,25.0,60.0
113.16699,0.0021410438976377953,625.5123622047244,0.00025370340306410486,25.0,60.0
114.56836,0.002169006299212598,631.6564566929134,0.00025370340306410486,25.0,60.0
115.96973,0.002191995866141732,633.9675853018372,0.00025370340306410486,25.0,60.0
117.37109,0.002248075590551181,640.7741732283464,0.00025370340306410486,25.0,60.0
118.77246,0.002272530118110236,643.0501312335958,0.00025370340306410486,25.0,60.0
120.17383,0.0023200844488188974,648.8615748031497,0.00025370340306410486,25.0,60.0
121.5752,0.0023511468503937005,653.1632020997375,0.00025370340306410486,25.0,60.0
122.97656,0.002363847440944882,656.2580839895013,0.00025370340306410486,25.0,60.0
124.37793,0.00241811062992126,659.9490813648293,0.00025370340306410486,25.0,60.0
125.7793,0.002464460433070866,666.982125984252,0.00025370340306410486,25.0,60.0
127.18066,0.0024975582677165356,669.7154855643045,0.00025370340306410486,25.0,60.0
128.58203,0.002562825,674.2164304461942,0.00025370340306410486,25.0,60.0
129.9834,0.0025825314960629922,676.3674540682415,0.00025370340306410486,25.0,60.0
131.38477,0.00265410531496063,679.8838320209974,0.00025370340306410486,25.0,60.0
132.78613,0.0026987482283464567,683.8396325459317,0.00025370340306410486,25.0,60.0
134.1875,0.0027598818897637796,685.3419422572179,0.00025370340306410486,25.0,60.0
135.58887,0.002803045472440945,690.2179790026247,0.00025370340306410486,25.0,60.0
136.99023,0.0028779830708661417,692.9762992125984,0.00025370340306410486,25.0,60.0
138.3916,0.002935253346456693,695.2447769028871,0.00025370340306410486,25.0,60.0
139.79297,0.0030043431102362204,698.5671391076116,0.00025370340306410486,25.0,60.0
141.19434,0.003078737992125984,699.9857742782152,0.00025370340306410486,25.0,60.0
142.5957,0.0031360557086614177,701.4449868766404,0.00025370340306410486,25.0,60.0
143.99707,0.0032155129921259845,705.8611023622047,0.00025370340306410486,25.0,60.0
145.39844,0.003329586023622047,709.8050393700787,0.00025370340306410486,25.0,60.0
146.7998,0.0034367133858267717,712.1796062992127,0.00025370340306410486,25.0,60.0
148.20117,0.0035627297244094484,716.3856167979003,0.00025370340306410486,25.0,60.0
149.60254,0.0036711312992125985,715.9451443569554,0.00025370340306410486,25.0,60.0
151.00391,0.0038086866141732283,720.0566929133859,0.00025370340306410486,25.0,60.0
152.40527,0.003916009448818898,719.9653805774278,0.00025370340306410486,25.0,60.0
153.80664,0.004079251574803149,725.9154855643044,0.00025370340306410486,25.0,60.0
155.20801,0.004228192716535433,727.919501312336,0.00025370340306410486,25.0,60.0
156.60938,0.004402068110236221,730.2708661417322,0.00025370340306410486,25.0,60.0
158.01074,0.004559329330708661,728.913937007874,0.00025370340306410486,25.0,60.0
159.41211,0.00470919625984252,732.6277690288714,0.00025370340306410486,25.0,60.0
160.81348,0.004913650196850394,736.3978477690289,0.00025370340306410486,25.0,60.0
162.21484,0.005123129133858267,737.5734383202099,0.00025370340306410486,25.0,60.0
163.61621,0.005295322637795276,739.4630446194226,0.00025370340306410486,25.0,60.0
165.01758,0.005492692716535433,740.8329921259842,0.00025370340306410486,25.0,60.0
166.41895,0.0057122931102362206,741.2410498687664,0.00025370340306410486,25.0,60.0
167.82031,0.005888642322834646,744.1370341207349,0.00025370340306410486,25.0,60.0
169.22168,0.0061306255905511815,747.27031496063,0.00025370340306410486,25.0,60.0
170.62305,0.006396649803149606,748.1283727034121,0.00025370340306410486,25.0,60.0
172.02441,0.006633761614173229,749.3384514435695,0.00025370340306410486,25.0,60.0
173.42578,0.006840070866141731,749.1057217847768,0.00025370340306410486,25.0,60.0
174.82715,0.007082727165354331,750.9468241469816,0.00025370340306410486,25.0,60.0
176.22852,0.007357171850393701,753.5703412073491,0.00025370340306410486,25.0,60.0
177.62988,0.007604825196850394,754.3732545931758,0.00025370340306410486,25.0,60.0
179.03125,0.00782402775590551,757.2245669291339,0.00025370340306410486,25.0,60.0
180.43262,0.008085115551181103,756.7286089238845,0.00025370340306410486,25.0,60.0
181.83398,0.00834983779527559,758.9456167979002,0.00025370340306410486,25.0,60.0
183.23535,0.008609689960629921,760.4395538057743,0.00025370340306410486,25.0,60.0
184.63672,0.008920174606299213,762.2114435695538,0.00025370340306410486,25.0,60.0
186.03809,0.009189469094488189,762.1962729658792,0.00025370340306410486,25.0,60.0
187.43945,0.009507133661417323,763.9375590551181,0.00025370340306410486,25.0,60.0
188.84082,0.009760635236220472,763.2239107611548,0.00025370340306410486,25.0,60.0
190.24219,0.010065600196850393,765.4714698162729,0.00025370340306410486,25.0,60.0
191.64355,0.010396212401574803,769.231496062992,0.00025370340306410486,25.0,60.0
193.04492,0.010757124803149606,768.6275328083989,0.00025370340306410486,25.0,60.0
194.44629,0.011048779133858268,769.1233333333333,0.00025370340306410486,25.0,60.0
195.84766,0.011371187598425196,771.4213910761155,0.00025370340306410486,25.0,60.0
197.24902,0.011643325984251968,771.8528346456693,0.00025370340306410486,25.0,60.0
198.65039,0.01197802559055118,771.7613910761154,0.00025370340306410486,25.0,60.0
200.05176,0.012312926377952756,773.7994750656168,0.00025370340306410486,25.0,60.0
201.45313,0.012600539173228346,774.9619422572179,0.00025370340306410486,25.0,60.0
202.85449,0.01291278307086614,776.8289501312336,0.00025370340306410486,25.0,60.0
204.25586,0.013211448622047246,774.7720734908137,0.00025370340306410486,25.0,60.0
205.65723,0.01352621377952756,776.8562992125985,0.00025370340306410486,25.0,60.0
207.05859,0.013856817125984251,777.3877165354331,0.00025370340306410486,25.0,60.0
208.45996,0.014206099803149606,778.6091863517061,0.00025370340306410486,25.0,60.0
209.86133,0.01448878622047244,777.511968503937,0.00025370340306410486,25.0,60.0
211.2627,0.014730451968503937,778.8260892388452,0.00025370340306410486,25.0,60.0
212.66406,0.014993973818897638,779.6909711286089,0.00025370340306410486,25.0,60.0
214.06543,0.01531934842519685,783.1176377952755,0.00025370340306410486,25.0,60.0
215.4668,0.015664455511811025,783.4698162729659,0.00025370340306410486,25.0,60.0
216.86816,0.015978166141732284,782.5247244094487,0.00025370340306410486,25.0,60.0
218.26953,0.01630463346456693,785.3263254593176,0.00025370340306410486,25.0,60.0
219.6709,0.016594499212598424,785.0142519685039,0.00025370340306410486,25.0,60.0
221.07227,0.016889757874015747,787.449501312336,0.00025370340306410486,25.0,60.0
222.47363,0.017292859251968502,787.8738320209974,0.00025370340306410486,25.0,60.0
223.875,0.01762121279527559,786.308845144357,0.00025370340306410486,25.0,60.0
225.27637,0.017870890748031495,785.8502362204724,0.00025370340306410486,25.0,60.0
226.67773,0.018226821653543307,788.9528083989501,0.00025370340306410486,25.0,60.0
228.0791,0.018615227165354332,788.6223359580052,0.00025370340306410486,25.0,60.0
229.48047,0.018964816338582675,791.2153543307086,0.00025370340306410486,25.0,60.0
230.88184,0.019305909251968505,791.9561154855643,0.00025370340306410486,25.0,60.0
232.2832,0.019660009842519685,792.7847769028872,0.00025370340306410486,25.0,60.0
233.68457,0.019986332677165354,793.1898162729658,0.00025370340306410486,25.0,60.0
235.08594,0.020326456692913386,795.423937007874,0.00025370340306410486,25.0,60.0
236.4873,0.020674736220472438,795.6263517060368,0.00025370340306410486,25.0,60.0
237.88867,0.02102119094488189,795.8710761154855,0.00025370340306410486,25.0,60.0
239.29004,0.021353080708661418,796.234593175853,0.00025370340306410486,25.0,60.0
240.69141,0.021702600393700786,795.6664829396326,0.00025370340306410486,25.0,60.0
242.09277,0.021989714566929133,797.4330708661416,0.00025370340306410486,25.0,60.0
243.49414,0.022282145669291337,796.5305774278215,0.00025370340306410486,25.0,60.0
244.89551,0.022583807086614175,799.494094488189,0.00025370340306410486,25.0,60.0
246.29688,0.022944490157480315,799.0649081364829,0.00025370340306410486,25.0,60.0
247.69824,0.023242633858267716,799.3274803149606,0.00025370340306410486,25.0,60.0
249.09961,0.023583555118110236,801.3733333333333,0.00025370340306410486,25.0,60.0
250.50098,0.023979173228346456,802.5354855643044,0.00025370340306410486,25.0,60.0
251.90234,0.024295588582677163,802.3285564304462,0.00025370340306410486,25.0,60.0
253.30371,0.02461077559055118,801.8911023622047,0.00025370340306410486,25.0,60.0
254.70508,0.024920590551181104,804.5717060367455,0.00025370340306410486,25.0,60.0
256.10645,0.025251580708661413,802.8406299212598,0.00025370340306410486,25.0,60.0
257.50781,0.025618749999999996,804.127716535433,0.00025370340306410486,25.0,60.0
258.90918,0.02593436811023622,805.205905511811,0.00025370340306410486,25.0,60.0
260.31055,0.026252368110236218,805.1632283464567,0.00025370340306410486,25.0,60.0
261.71191,0.026606460629921256,806.0655118110235,0.00025370340306410486,25.0,60.0
263.11328,0.026941161417322838,807.50312335958,0.00025370340306410486,25.0,60.0
264.51465,0.027316431102362204,808.8028346456692,0.00025370340306410486,25.0,60.0
265.91602,0.027650988188976378,808.4841732283464,0.00025370340306410486,25.0,60.0
267.31738,0.02796878149606299,808.8739632545931,0.00025370340306410486,25.0,60.0
268.71875,0.028299,809.4942519685039,0.00025370340306410486,25.0,60.0
270.12012,0.028586763779527558,808.6290026246719,0.00025370340306410486,25.0,60.0
271.52148,0.028882348425196852,810.9379527559055,0.00025370340306410486,25.0,60.0
272.92285,0.029275669291338582,813.722939632546,0.00025370340306410486,25.0,60.0
274.32422,0.02967232086614173,812.8312335958005,0.00025370340306410486,25.0,60.0
275.72559,0.030012517716535434,812.6081102362205,0.00025370340306410486,25.0,60.0
277.12695,0.030348364173228344,811.6888188976378,0.00025370340306410486,25.0,60.0
278.52832,0.030728344488188973,814.1859842519685,0.00025370340306410486,25.0,60.0
279.92969,0.031059643700787405,813.5027034120734,0.00025370340306410486,25.0,60.0
281.33105,0.03137091535433071,814.7817847769029,0.00025370340306410486,25.0,60.0
282.73242,0.03166558661417323,814.9342257217847,0.00025370340306410486,25.0,60.0
284.13379,0.031969872047244094,816.1486614173228,0.00025370340306410486,25.0,60.0
285.53516,0.032264437007874014,817.3199475065617,0.00025370340306410486,25.0,60.0
286.93652,0.03261533661417323,817.2706036745407,0.00025370340306410486,25.0,60.0
288.33789,0.032934092519685036,817.5455118110235,0.00025370340306410486,25.0,60.0
289.73926,0.0332259311023622,816.8379527559055,0.00025370340306410486,25.0,60.0
291.14063,0.033566212598425196,820.0151706036745,0.00025370340306410486,25.0,60.0
292.54199,0.03385976181102362,818.8854068241469,0.00025370340306410486,25.0,60.0
293.94336,0.03417450590551181,819.352467191601,0.00025370340306410486,25.0,60.0
295.34473,0.03457155905511811,822.2002624671916,0.00025370340306410486,25.0,60.0
296.74609,0.034967574803149604,822.8554068241469,0.00025370340306410486,25.0,60.0
298.14746,0.03527336023622047,821.0245406824147,0.00025370340306410486,25.0,60.0
299.54883,0.03562291535433071,822.1288188976379,0.00025370340306410486,25.0,60.0
300.9502,0.03598929330708661,822.8002887139107,0.00025370340306410486,25.0,60.0
302.35156,0.03635465354330709,823.1608136482939,0.00025370340306410486,25.0,60.0
303.75293,0.03672730905511811,824.168372703412,0.00025370340306410486,25.0,60.0
305.1543,0.03707471456692913,824.2711548556431,0.00025370340306410486,25.0,60.0
306.55566,0.03733602362204724,823.805249343832,0.00025370340306410486,25.0,60.0
307.95703,0.037656407480314964,824.602467191601,0.00025370340306410486,25.0,60.0
309.3584,0.038003734251968506,827.0663517060368,0.00025370340306410486,25.0,60.0
310.75977,0.038281663385826774,825.0928608923884,0.00025370340306410486,25.0,60.0
312.16113,0.03858105905511811,826.1805249343832,0.00025370340306410486,25.0,60.0
313.5625,0.03894138582677165,826.8948031496063,0.00025370340306410486,25.0,60.0
314.96387,0.03932371653543307,829.4022309711286,0.00025370340306410486,25.0,60.0
316.36523,0.0396765216535433,829.5076377952756,0.00025370340306410486,25.0,60.0
317.7666,0.03998324212598425,828.262125984252,0.00025370340306410486,25.0,60.0
319.16797,0.040352641732283465,829.6195800524935,0.00025370340306410486,25.0,60.0
320.56934,0.04067733267716535,829.7055643044619,0.00025370340306410486,25.0,60.0
321.9707,0.04098783464566929,831.9132283464567,0.00025370340306410486,25.0,60.0
323.37207,0.04131555708661417,830.9900262467191,0.00025370340306410486,25.0,60.0
324.77344,0.041660828740157474,831.4622834645669,0.00025370340306410486,25.0,60.0
326.1748,0.04195962204724409,832.0263254593176,0.00025370340306410486,25.0,60.0
327.57617,0.04231695472440945,831.9022572178477,0.00025370340306410486,25.0,60.0
328.97754,0.04268249803149606,833.5497375328084,0.00025370340306410486,25.0,60.0
330.37891,0.043055687007874016,835.5302887139107,0.00025370340306410486,25.0,60.0
331.78027,0.04338462204724409,833.7377952755905,0.00025370340306410486,25.0,60.0
333.18164,0.04368723031496063,834.7417847769028,0.00025370340306410486,25.0,60.0
334.58301,0.04402980118110236,835.1830971128609,0.00025370340306410486,25.0,60.0
335.98438,0.04439503149606299,837.2943832020998,0.00025370340306410486,25.0,60.0
337.38574,0.04476009645669292,836.0708398950131,0.00025370340306410486,25.0,60.0
338.78711,0.04506997047244095,836.5939895013123,0.00025370340306410486,25.0,60.0
340.18848,0.04538109842519685,836.0939895013123,0.00025370340306410486,25.0,60.0
341.58984,0.04571381496062992,837.9854593175853,0.00025370340306410486,25.0,60.0
342.99121,0.04600347244094488,837.6976902887139,0.00025370340306410486,25.0,60.0
344.39258,0.04630390354330709,839.7414173228346,0.00025370340306410486,25.0,60.0
345.79395,0.04666975590551181,838.5812598425197,0.00025370340306410486,25.0,60.0
347.19531,0.04701143307086614,840.0259317585301,0.00025370340306410486,25.0,60.0
348.59668,0.0473763562992126,841.6724409448818,0.00025370340306410486,25.0,60.0
349.99805,0.047763472440944886,841.1205249343832,0.00025370340306410486,25.0,60.0
351.39941,0.048084976377952754,840.4577427821522,0.00025370340306410486,25.0,60.0
352.80078,0.04841311220472441,839.3137007874016,0.00025370340306410486,25.0,60.0
354.20215,0.04868580708661417,840.2612860892389,0.00025370340306410486,25.0,60.0
355.60352,0.04898982677165355,842.0844619422572,0.00025370340306410486,25.0,60.0
357.00488,0.04934032086614173,844.3909186351706,0.00025370340306410486,25.0,60.0
358.40625,0.04972647047244094,842.9565879265092,0.00025370340306410486,25.0,60.0
359.80762,0.050040639763779524,842.3948556430446,0.00025370340306410486,25.0,60.0
361.20898,0.050369033464566934,844.1738845144356,0.00025370340306410486,25.0,60.0
362.61035,0.050698114173228344,845.0052493438319,0.00025370340306410486,25.0,60.0
364.01172,0.05108795669291338,846.6541732283464,0.00025370340306410486,25.0,60.0
365.41309,0.051403895669291336,844.8138320209973,0.00025370340306410486,25.0,60.0
366.81445,0.05167773818897638,842.8810236220472,0.00025370340306410486,25.0,60.0
368.21582,0.05198140354330708,846.1768503937008,0.00025370340306410486,25.0,60.0
369.61719,0.05232304527559054,846.3275065616798,0.00025370340306410486,25.0,60.0
371.01855,0.05267809251968504,847.5381627296588,0.00025370340306410486,25.0,60.0
372.41992,0.05303839566929134,847.7953543307086,0.00025370340306410486,25.0,60.0
373.82129,0.05340573228346457,848.3748818897639,0.00025370340306410486,25.0,60.0
375.22266,0.053726253937007876,847.8534908136484,0.00025370340306410486,25.0,60.0
376.62402,0.054057470472440944,849.5634908136482,0.00025370340306410486,25.0,60.0
378.02539,0.054357230314960626,849.7488188976378,0.00025370340306410486,25.0,60.0
379.42676,0.054684509842519685,850.491811023622,0.00025370340306410486,25.0,60.0
380.82813,0.05505669291338582,852.3418897637795,0.00025370340306410486,25.0,60.0
382.22949,0.05538475393700787,850.8385301837271,0.00025370340306410486,25.0,60.0
383.63086,0.05572115551181102,851.5330971128609,0.00025370340306410486,25.0,60.0
385.03223,0.05605979330708662,852.4390288713911,0.00025370340306410486,25.0,60.0
386.43359,0.05638769488188976,852.2203412073491,0.00025370340306410486,25.0,60.0
387.83496,0.056731982283464565,852.1695800524934,0.00025370340306410486,25.0,60.0
389.23633,0.0570383779527559,853.7795013123359,0.00025370340306410486,25.0,60.0
390.6377,0.05732069488188977,853.6682677165354,0.00025370340306410486,25.0,60.0
392.03906,0.05765681692913385,854.475406824147,0.00025370340306410486,25.0,60.0
393.44043,0.05802191338582677,854.1734645669292,0.00025370340306410486,25.0,60.0
394.8418,0.05838696259842519,853.7429133858267,0.00025370340306410486,25.0,60.0
396.24316,0.058734740157480314,856.2392913385826,0.00025370340306410486,25.0,60.0
397.64453,0.05905793700787401,856.4559580052494,0.00025370340306410486,25.0,60.0
399.0459,0.059388066929133856,855.5179002624672,0.00025370340306410486,25.0,60.0
400.44727,0.059684120078740154,857.9382152230971,0.00025370340306410486,25.0,60.0
401.84863,0.059971236220472436,856.758530183727,0.00025370340306410486,25.0,60.0
403.25,0.060346295275590545,857.9199475065617,0.00025370340306410486,25.0,60.0
404.65137,0.06066510826771653,858.2638845144357,0.00025370340306410486,25.0,60.0
406.05273,0.06097581496062992,859.5732545931758,0.00025370340306410486,25.0,60.0
407.4541,0.061342887795275594,860.2773490813648,0.00025370340306410486,25.0,60.0
408.85547,0.06176226181102362,860.5936482939633,0.00025370340306410486,25.0,60.0
410.25684,0.06208490748031496,860.6807874015748,0.00025370340306410486,25.0,60.0
411.6582,0.06240626771653543,860.6688188976378,0.00025370340306410486,25.0,60.0
413.05957,0.06276618503937008,861.2798162729658,0.00025370340306410486,25.0,60.0
414.46094,0.0631141377952756,862.3915223097113,0.00025370340306410486,25.0,60.0
415.8623,0.06340662401574804,861.367217847769,0.00025370340306410486,25.0,60.0
417.26367,0.0637746594488189,862.0946456692913,0.00025370340306410486,25.0,60.0
418.66504,0.06409029921259843,861.4153280839895,0.00025370340306410486,25.0,60.0
420.06641,0.06438615748031495,862.0052493438319,0.00025370340306410486,25.0,60.0
421.46777,0.06468624015748031,862.6532020997375,0.00025370340306410486,25.0,60.0
422.86914,0.06497058858267717,862.9461154855643,0.00025370340306410486,25.0,60.0
424.27051,0.06531756889763779,864.248845144357,0.00025370340306410486,25.0,60.0
425.67188,0.06559558070866141,863.9064041994751,0.00025370340306410486,25.0,60.0
427.07324,0.06592928346456693,864.319842519685,0.00025370340306410486,25.0,60.0
428.47461,0.06626215551181101,864.8398950131233,0.00025370340306410486,25.0,60.0
429.87598,0.06660451181102361,867.3872440944881,0.00025370340306410486,25.0,60.0
431.27734,0.0669394783464567,866.9453543307086,0.00025370340306410486,25.0,60.0
432.67871,0.06728459251968504,866.0887401574803,0.00025370340306410486,25.0,60.0
434.08008,0.06761783267716535,866.7627821522309,0.00025370340306410486,25.0,60.0
435.48145,0.0679382125984252,866.5276115485565,0.00025370340306410486,25.0,60.0
436.88281,0.0682626062992126,867.7714435695538,0.00025370340306410486,25.0,60.0
438.28418,0.06861368700787401,866.2175328083989,0.00025370340306410486,25.0,60.0
439.68555,0.06892337401574802,867.6453543307086,0.00025370340306410486,25.0,60.0
441.08691,0.06928727362204724,870.0673228346456,0.00025370340306410486,25.0,60.0
442.48828,0.06960660826771653,869.3836745406824,0.00025370340306410486,25.0,60.0
443.88965,0.0699392342519685,868.7942782152231,0.00025370340306410486,25.0,60.0
445.29102,0.07029280118110236,870.237217847769,0.00025370340306410486,25.0,60.0
446.69238,0.07068011417322835,870.6617847769029,0.00025370340306410486,25.0,60.0
448.09375,0.07101618307086614,869.881312335958,0.00025370340306410486,25.0,60.0
449.49512,0.07136152559055117,870.7322834645669,0.00025370340306410486,25.0,60.0
450.89648,0.07170845275590551,872.4233333333333,0.00025370340306410486,25.0,60.0
452.29785,0.07202746062992126,872.1648818897637,0.00025370340306410486,25.0,60.0
453.69922,0.07235335039370079,871.4160104986876,0.00025370340306410486,25.0,60.0
455.10059,0.07268624015748032,872.7572965879265,0.00025370340306410486,25.0,60.0
456.50195,0.07300998228346457,872.5330971128608,0.00025370340306410486,25.0,60.0
457.90332,0.07338357283464567,874.5774015748032,0.00025370340306410486,25.0,60.0
459.30469,0.07370781299212598,872.9163517060367,0.00025370340306410486,25.0,60.0
460.70605,0.0740856279527559,876.4525459317586,0.00025370340306410486,25.0,60.0
462.10742,0.0744236968503937,873.0981364829397,0.00025370340306410486,25.0,60.0
463.50879,0.07476193503937008,876.6245406824147,0.00025370340306410486,25.0,60.0
464.91016,0.07511947047244094,875.5727296587926,0.00025370340306410486,25.0,60.0
466.31152,0.07546969488188976,876.0243044619422,0.00025370340306410486,25.0,60.0
467.71289,0.07578302362204724,875.6514960629921,0.00025370340306410486,25.0,60.0
469.11426,0.07611102559055118,875.5763254593176,0.00025370340306410486,25.0,60.0
470.51563,0.07650157677165355,877.5366404199475,0.00025370340306410486,25.0,60.0
471.91699,0.07680620472440945,876.1038845144358,0.00025370340306410486,25.0,60.0
473.31836,0.07712889173228346,876.6995538057743,0.00025370340306410486,25.0,60.0
474.71973,0.07745970866141731,878.1307086614173,0.00025370340306410486,25.0,60.0
476.12109,0.07777386614173229,878.7139370078739,0.00025370340306410486,25.0,60.0
477.52246,0.0780747342519685,878.228346456693,0.00025370340306410486,25.0,60.0
478.92383,0.0784691751968504,879.5016010498688,0.00025370340306410486,25.0,60.0
480.3252,0.07881294488188977,878.071627296588,0.00025370340306410486,25.0,60.0
481.72656,0.07913569094488189,879.9509186351705,0.00025370340306410486,25.0,60.0
483.12793,0.07948924803149605,879.5551706036745,0.00025370340306410486,25.0,60.0
484.5293,0.07989454133858268,881.4194225721785,0.00025370340306410486,25.0,60.0
485.93066,0.08026491141732284,882.0265091863517,0.00025370340306410486,25.0,60.0
487.33203,0.08064479724409448,881.5161154855642,0.00025370340306410486,25.0,60.0
488.7334,0.08099241732283465,880.6265879265092,0.00025370340306410486,25.0,60.0
490.13477,0.08133209842519684,881.2055380577427,0.00025370340306410486,25.0,60.0
491.53613,0.08168553149606299,882.3958005249343,0.00025370340306410486,25.0,60.0
492.9375,0.08196443503937008,879.3035958005248,0.00025370340306410486,25.0,60.0
494.33887,0.08228730905511811,882.2792388451444,0.00025370340306410486,25.0,60.0
495.74023,0.0826457874015748,883.2288188976378,0.00025370340306410486,25.0,60.0
497.1416,0.08295166141732283,882.1740944881889,0.00025370340306410486,25.0,60.0
498.54297,0.0832459468503937,885.1416272965879,0.00025370340306410486,25.0,60.0
499.94434,0.0835970688976378,884.6271391076116,0.00025370340306410486,25.0,60.0
501.3457,0.08397771653543307,885.3207349081365,0.00025370340306410486,25.0,60.0
502.74707,0.08432076181102362,884.5785826771654,0.00025370340306410486,25.0,60.0
504.14844,0.08470244094488188,886.9522572178478,0.00025370340306410486,25.0,60.0
505.5498,0.08507535826771653,885.7021259842519,0.00025370340306410486,25.0,60.0
506.95117,0.08544200196850393,884.8644356955381,0.00025370340306410486,25.0,60.0
508.35254,0.08570810039370079,885.0245144356956,0.00025370340306410486,25.0,60.0
509.75391,0.08600991338582678,885.7305249343832,0.00025370340306410486,25.0,60.0
511.15527,0.08637335433070865,887.1752493438321,0.00025370340306410486,25.0,60.0
512.55664,0.08669592322834646,886.4255905511811,0.00025370340306410486,25.0,60.0
513.95801,0.08710262598425196,889.1172965879265,0.00025370340306410486,25.0,60.0
515.35938,0.08748029921259842,889.0353280839895,0.00025370340306410486,25.0,60.0
516.76074,0.08786402755905512,888.6921259842519,0.00025370340306410486,25.0,60.0
518.16211,0.08820527559055118,887.7181364829396,0.00025370340306410486,25.0,60.0
519.56348,0.08856242322834645,887.4608398950131,0.00025370340306410486,25.0,60.0
520.96484,0.08889849212598425,888.1008661417322,0.00025370340306410486,25.0,60.0
522.36621,0.08929266141732284,889.0107349081366,0.00025370340306410486,25.0,60.0
523.76758,0.08957001181102361,887.3002099737533,0.00025370340306410486,25.0,60.0
525.16895,0.08991285039370078,890.0634120734908,0.00025370340306410486,25.0,60.0
526.57031,0.0902756751968504,891.3521784776904,0.00025370340306410486,25.0,60.0
527.97168,0.09059616141732282,890.4309711286089,0.00025370340306410486,25.0,60.0
529.37305,0.09099070866141733,891.2122309711285,0.00025370340306410486,25.0,60.0
530.77441,0.09131277952755906,890.7661679790026,0.00025370340306410486,25.0,60.0
532.17578,0.09168200393700787,891.0332545931758,0.00025370340306410486,25.0,60.0
533.57715,0.09196909842519685,890.1049868766405,0.00025370340306410486,25.0,60.0
534.97852,0.09233615354330708,891.5823359580053,0.00025370340306410486,25.0,60.0
536.37988,0.09266087598425196,892.0166666666667,0.00025370340306410486,25.0,60.0
537.78125,0.09302973818897638,892.6362467191601,0.00025370340306410486,25.0,60.0
539.18262,0.09334793110236221,892.3169291338583,0.00025370340306410486,25.0,60.0
540.58398,0.09373031692913386,893.5664829396326,0.00025370340306410486,25.0,60.0
541.98535,0.09411005511811023,893.5007874015747,0.00025370340306410486,25.0,60.0
543.38672,0.0944616811023622,893.0276377952756,0.00025370340306410486,25.0,60.0
544.78809,0.09479090354330709,893.3963517060367,0.00025370340306410486,25.0,60.0
546.18945,0.09512159251968504,894.011496062992,0.00025370340306410486,25.0,60.0
547.59082,0.09546572047244095,895.548372703412,0.00025370340306410486,25.0,60.0
548.99219,0.0958790688976378,895.0012598425196,0.00025370340306410486,25.0,60.0
550.39355,0.09625619291338582,896.2802099737532,0.00025370340306410486,25.0,60.0
551.79492,0.09660807677165355,895.5654855643045,0.00025370340306410486,25.0,60.0
553.19629,0.09696194291338582,894.9442257217848,0.00025370340306410486,25.0,60.0
554.59766,0.09728883661417323,896.141811023622,0.00025370340306410486,25.0,60.0
555.99902,0.09766598818897637,897.3672440944882,0.00025370340306410486,25.0,60.0
557.40039,0.09803900393700787,896.6901312335958,0.00025370340306410486,25.0,60.0
558.80176,0.09839145275590551,896.5726771653543,0.00025370340306410486,25.0,60.0
560.20313,0.09875115748031497,897.7889501312335,0.00025370340306410486,25.0,60.0
561.60449,0.09914612007874014,898.1235170603675,0.00025370340306410486,25.0,60.0
563.00586,0.09950261023622048,897.6287664041995,0.00025370340306410486,25.0,60.0
564.40723,0.0998575748031496,898.1959842519684,0.00025370340306410486,25.0,60.0
565.80859,0.10020661220472442,898.0564829396326,0.00025370340306410486,25.0,60.0
567.20996,0.10055555905511811,899.0010761154856,0.00025370340306410486,25.0,60.0
568.61133,0.10084323228346458,898.752309711286,0.00025370340306410486,25.0,60.0
570.0127,0.10118261614173228,899.9791076115486,0.00025370340306410486,25.0,60.0
571.41406,0.10151908858267718,899.4627559055118,0.00025370340306410486,25.0,60.0
572.81543,0.10190927559055117,899.8186614173228,0.00025370340306410486,25.0,60.0
574.2168,0.10225668503937006,899.2930183727034,0.00025370340306410486,25.0,60.0
575.61816,0.10256048031496062,898.7303937007874,0.00025370340306410486,25.0,60.0
577.01953,0.10292523031496062,899.0096587926508,0.00025370340306410486,25.0,60.0
578.4209,0.1032909311023622,901.1115748031496,0.00025370340306410486,25.0,60.0
579.82227,0.10369207677165354,901.7116797900262,0.00025370340306410486,25.0,60.0
581.22363,0.10404956299212599,901.9294750656168,0.00025370340306410486,25.0,60.0
582.625,0.1044321122047244,902.0799999999999,0.00025370340306410486,25.0,60.0
584.02637,0.10477104921259843,900.824251968504,0.00025370340306410486,25.0,60.0
585.42773,0.10516140157480314,902.799343832021,0.00025370340306410486,25.0,60.0
586.8291,0.10556933070866141,901.9827821522309,0.00025370340306410486,25.0,60.0
588.23047,0.1059580275590551,901.918845144357,0.00025370340306410486,25.0,60.0
589.63184,0.10632092322834645,901.1085039370079,0.00025370340306410486,25.0,60.0
591.0332,0.10666339173228347,904.6329133858268,0.00025370340306410486,25.0,60.0
592.43457,0.10709595866141731,905.4853543307086,0.00025370340306410486,25.0,60.0
593.83594,0.10748938582677164,903.3204461942257,0.00025370340306410486,25.0,60.0
595.2373,0.10788081692913386,903.8959317585302,0.00025370340306410486,25.0,60.0
596.63867,0.10821563582677166,904.6994750656169,0.00025370340306410486,25.0,60.0
598.04004,0.10857199606299213,904.2830446194226,0.00025370340306410486,25.0,60.0
599.44141,0.10889475196850393,905.7046194225721,0.00025370340306410486,25.0,60.0
600.84277,0.10930670472440945,906.1641994750656,0.00025370340306410486,25.0,60.0
602.24414,0.10970277165354331,904.7063517060367,0.00025370340306410486,25.0,60.0
603.64551,0.11004263582677166,905.1857742782151,0.00025370340306410486,25.0,60.0
605.04688,0.1103993248031496,904.8688976377953,0.00025370340306410486,25.0,60.0
606.44824,0.11075117913385826,905.5183464566928,0.00025370340306410486,25.0,60.0
607.84961,0.1110704625984252,906.6092913385827,0.00025370340306410486,25.0,60.0
609.25098,0.1114353307086614,908.0412073490814,0.00025370340306410486,25.0,60.0
610.65234,0.11181119094488189,907.5748293963254,0.00025370340306410486,25.0,60.0
612.05371,0.11222607677165354,906.5601312335957,0.00025370340306410486,25.0,60.0
613.45508,0.11265281299212598,907.5676640419948,0.00025370340306410486,25.0,60.0
614.85645,0.113006968503937,907.1824146981627,0.00025370340306410486,25.0,60.0
616.25781,0.11337276377952757,907.735721784777,0.00025370340306410486,25.0,60.0
617.65918,0.1137963188976378,909.633937007874,0.00025370340306410486,25.0,60.0
619.06055,0.11416076377952755,908.5572965879265,0.00025370340306410486,25.0,60.0
620.46191,0.1145341377952756,908.4092125984251,0.00025370340306410486,25.0,60.0
621.86328,0.11498143110236221,910.5056692913386,0.00025370340306410486,25.0,60.0
623.26465,0.11540355708661416,910.3545144356955,0.00025370340306410486,25.0,60.0
624.66602,0.11575405118110235,908.7010236220473,0.00025370340306410486,25.0,60.0
626.06738,0.11613556692913386,909.3992125984253,0.00025370340306410486,25.0,60.0
627.46875,0.11648139173228346,909.6194488188976,0.00025370340306410486,25.0,60.0
628.87012,0.11683632086614172,909.5194225721784,0.00025370340306410486,25.0,60.0
630.27148,0.11717899999999999,909.6954593175852,0.00025370340306410486,25.0,60.0
631.67285,0.11755944881889764,909.4233070866142,0.00025370340306410486,25.0,60.0
633.07422,0.11793076968503936,909.7134120734908,0.00025370340306410486,25.0,60.0
634.47559,0.11828707283464568,909.515905511811,0.00025370340306410486,25.0,60.0
635.87695,0.11867858464566929,911.1870866141733,0.00025370340306410486,25.0,60.0
637.27832,0.11907913385826771,910.6097375328084,0.00025370340306410486,25.0,60.0
638.67969,0.11943626771653544,911.4565354330708,0.00025370340306410486,25.0,60.0
640.08105,0.11985814763779527,910.3729133858267,0.00025370340306410486,25.0,60.0
641.48242,0.12025420078740158,912.2836745406823,0.00025370340306410486,25.0,60.0
642.88379,0.12064111417322833,912.9471391076115,0.00025370340306410486,25.0,60.0
644.28516,0.12099239566929133,912.3740157480315,0.00025370340306410486,25.0,60.0
645.68652,0.12139341338582676,911.2175853018373,0.00025370340306410486,25.0,60.0
647.08789,0.12176057874015749,912.8379002624672,0.00025370340306410486,25.0,60.0
648.48926,0.12211874803149605,913.9139632545932,0.00025370340306410486,25.0,60.0
649.89063,0.12251708858267715,913.1765354330709,0.00025370340306410486,25.0,60.0
651.29199,0.12296167125984252,914.4856167979002,0.00025370340306410486,25.0,60.0
652.69336,0.12339097834645668,913.6671391076115,0.00025370340306410486,25.0,60.0
654.09473,0.12376281496062991,913.4195275590552,0.00025370340306410486,25.0,60.0
655.49609,0.12407190157480313,912.4319422572178,0.00025370340306410486,25.0,60.0
656.89746,0.12442189173228346,914.5958267716535,0.00025370340306410486,25.0,60.0
658.29883,0.12481593897637794,914.5263779527559,0.00025370340306410486,25.0,60.0
659.7002,0.12525307086614174,914.9803674540683,0.00025370340306410486,25.0,60.0
661.10156,0.12565439370078738,914.9268503937008,0.00025370340306410486,25.0,60.0
662.50293,0.1260603031496063,914.5907086614174,0.00025370340306410486,25.0,60.0
663.9043,0.1265308877952756,914.6143569553806,0.00025370340306410486,25.0,60.0
665.30566,0.12699688188976377,917.820157480315,0.00025370340306410486,25.0,60.0
666.70703,0.12738001771653543,912.485249343832,0.00025370340306410486,25.0,60.0
668.1084,0.1276821594488189,914.158372703412,0.00025370340306410486,25.0,60.0
669.50977,0.12804341338582675,915.0718110236221,0.00025370340306410486,25.0,60.0
670.91113,0.12840694291338584,916.3921522309711,0.00025370340306410486,25.0,60.0
672.3125,0.12883355118110235,916.6108661417323,0.00025370340306410486,25.0,60.0
673.71387,0.1291938779527559,915.6192388451444,0.00025370340306410486,25.0,60.0
675.11523,0.12954142716535433,915.1543307086614,0.00025370340306410486,25.0,60.0
676.5166,0.12992325984251968,916.2405511811023,0.00025370340306410486,25.0,60.0
677.91797,0.13031347047244093,916.6227034120735,0.00025370340306410486,25.0,60.0
679.31934,0.1306698188976378,916.9342519685039,0.00025370340306410486,25.0,60.0
680.7207,0.13109558267716534,917.6950656167979,0.00025370340306410486,25.0,60.0
682.12207,0.13148877362204725,917.0848556430446,0.00025370340306410486,25.0,60.0
683.52344,0.13192386417322832,918.7182152230971,0.00025370340306410486,25.0,60.0
684.9248,0.13240087598425196,920.6412335958005,0.00025370340306410486,25.0,60.0
686.32617,0.1328126653543307,919.1261417322835,0.00025370340306410486,25.0,60.0
687.72754,0.1332021377952756,917.584094488189,0.00025370340306410486,25.0,60.0
689.12891,0.13359020078740155,919.2375065616798,0.00025370340306410486,25.0,60.0
690.53027,0.13394832086614172,917.0556167979003,0.00025370340306410486,25.0,60.0
691.93164,0.13437253543307084,918.8666929133858,0.00025370340306410486,25.0,60.0
693.33301,0.13472555118110235,917.8323359580053,0.00025370340306410486,25.0,60.0
694.73438,0.13512171062992126,918.3816010498688,0.00025370340306410486,25.0,60.0
696.13574,0.13558436417322836,921.0251968503937,0.00025370340306410486,25.0,60.0
697.53711,0.13608712992125985,919.3506036745407,0.00025370340306410486,25.0,60.0
698.93848,0.1365008090551181,917.8590551181103,0.00025370340306410486,25.0,60.0
700.33984,0.13692554921259842,918.6574803149606,0.00025370340306410486,25.0,60.0
701.74121,0.1373244192913386,919.700813648294,0.00025370340306410486,25.0,60.0
703.14258,0.13769007283464565,920.4703149606299,0.00025370340306410486,25.0,60.0
704.54395,0.13813178149606298,920.8970866141733,0.00025370340306410486,25.0,60.0
705.94531,0.13852620472440944,918.9361417322834,0.00025370340306410486,25.0,60.0
707.34668,0.13893558661417324,920.6038057742783,0.00025370340306410486,25.0,60.0
708.74805,0.13939767519685037,921.675590551181,0.00025370340306410486,25.0,60.0
710.14941,0.13983341141732283,920.9223359580053,0.00025370340306410486,25.0,60.0
711.55078,0.14018482086614173,918.7641732283465,0.00025370340306410486,25.0,60.0
712.95215,0.14055389960629922,920.5910498687664,0.00025370340306410486,25.0,60.0
714.35352,0.1409748405511811,922.2147506561679,0.00025370340306410486,25.0,60.0
715.75488,0.1414545649606299,920.8811286089239,0.00025370340306410486,25.0,60.0
717.15625,0.1418660590551181,921.7570866141732,0.00025370340306410486,25.0,60.0
718.55762,0.14228722244094488,921.0573490813648,0.00025370340306410486,25.0,60.0
719.95898,0.1426710157480315,920.8659580052494,0.00025370340306410486,25.0,60.0
721.36035,0.1431581653543307,922.7455118110237,0.00025370340306410486,25.0,60.0
722.76172,0.14357747440944882,923.5659055118109,0.00025370340306410486,25.0,60.0
724.16309,0.143960375984252,921.9739370078739,0.00025370340306410486,25.0,60.0
725.56445,0.1443598681102362,922.1941732283465,0.00025370340306410486,25.0,60.0
726.96582,0.1447671633858268,921.8202099737533,0.00025370340306410486,25.0,60.0
728.36719,0.14516863779527558,923.5144619422572,0.00025370340306410486,25.0,60.0
729.76855,0.14564482874015747,924.0945669291339,0.00025370340306410486,25.0,60.0
731.16992,0.14609655708661418,924.0967454068241,0.00025370340306410486,25.0,60.0
732.57129,0.14658217125984252,924.6976115485564,0.00025370340306410486,25.0,60.0
733.97266,0.14701618307086614,923.0192650918634,0.00025370340306410486,25.0,60.0
735.37402,0.14742535433070866,923.5546456692913,0.00025370340306410486,25.0,60.0
736.77539,0.1478596122047244,923.4194225721785,0.00025370340306410486,25.0,60.0
738.17676,0.14828612401574803,922.4040419947506,0.00025370340306410486,25.0,60.0
739.57813,0.14864492519685038,923.8666404199475,0.00025370340306410486,25.0,60.0
740.97949,0.14903482086614173,923.329842519685,0.00025370340306410486,25.0,60.0
742.38086,0.14949528937007875,924.3348556430446,0.00025370340306410486,25.0,60.0
743.78223,0.1499784153543307,926.575905511811,0.00025370340306410486,25.0,60.0
745.18359,0.15041916141732284,924.1578215223096,0.00025370340306410486,25.0,60.0
746.58496,0.15086633661417323,923.348687664042,0.00025370340306410486,25.0,60.0
747.98633,0.1512985059055118,923.3420209973754,0.00025370340306410486,25.0,60.0
749.3877,0.15171153740157478,924.9296325459318,0.00025370340306410486,25.0,60.0
750.78906,0.15218337598425197,925.3361679790027,0.00025370340306410486,25.0,60.0
752.19043,0.15270521062992126,925.2273490813648,0.00025370340306410486,25.0,60.0
753.5918,0.15311801968503938,925.2116535433071,0.00025370340306410486,25.0,60.0
754.99316,0.15351673818897638,924.3383727034121,0.00025370340306410486,25.0,60.0
756.39453,0.15391768503937006,923.6468503937008,0.00025370340306410486,25.0,60.0
757.7959,0.154354405511811,925.5243044619423,0.00025370340306410486,25.0,60.0
759.19727,0.15478494291338582,925.7044094488189,0.00025370340306410486,25.0,60.0
760.59863,0.15525447047244093,926.3830183727034,0.00025370340306410486,25.0,60.0
762.0,0.15572427952755905,925.1561679790026,0.00025370340306410486,25.0,60.0
763.40137,0.1561583149606299,924.3303674540682,0.00025370340306410486,25.0,60.0
764.80273,0.15660505511811024,926.4524146981627,0.00025370340306410486,25.0,60.0
766.2041,0.1571146751968504,926.335905511811,0.00025370340306410486,25.0,60.0
767.60547,0.15756559448818896,926.0931233595801,0.00025370340306410486,25.0,60.0
769.00684,0.15800088385826772,926.1486089238846,0.00025370340306410486,25.0,60.0
770.4082,0.15848616929133857,927.3414960629921,0.00025370340306410486,25.0,60.0
771.80957,0.15894713188976378,926.877375328084,0.00025370340306410486,25.0,60.0
773.21094,0.15943263976377953,927.0527559055117,0.00025370340306410486,25.0,60.0
774.6123,0.15982487992125985,924.5682939632545,0.00025370340306410486,25.0,60.0
776.01367,0.16030243307086614,927.7139370078739,0.00025370340306410486,25.0,60.0
777.41504,0.1607479311023622,928.374908136483,0.00025370340306410486,25.0,60.0
778.81641,0.1612515433070866,925.7848293963254,0.00025370340306410486,25.0,60.0
780.21777,0.16166414173228347,926.0260367454068,0.00025370340306410486,25.0,60.0
781.61914,0.16205944488188975,925.7194750656167,0.00025370340306410486,25.0,60.0
783.02051,0.1624611062992126,926.6797112860892,0.00025370340306410486,25.0,60.0
784.42188,0.16290506692913387,927.2961417322836,0.00025370340306410486,25.0,60.0
785.82324,0.16339532677165353,928.4678215223097,0.00025370340306410486,25.0,60.0
787.22461,0.16391081299212598,927.9259580052493,0.00025370340306410486,25.0,60.0
788.62598,0.1644133346456693,926.7809973753281,0.00025370340306410486,25.0,60.0
790.02734,0.16484201968503936,926.1875065616797,0.00025370340306410486,25.0,60.0
791.42871,0.16531858661417323,929.1116797900263,0.00025370340306410486,25.0,60.0
792.83008,0.16581281102362203,928.9713648293963,0.00025370340306410486,25.0,60.0
794.23145,0.16629941141732282,926.5995275590551,0.00025370340306410486,25.0,60.0
795.63281,0.16673522834645668,925.3716535433072,0.00025370340306410486,25.0,60.0
797.03418,0.16721857874015747,927.4276902887138,0.00025370340306410486,25.0,60.0
798.43555,0.16762201181102362,927.9481364829396,0.00025370340306410486,25.0,60.0
799.83691,0.16807146456692912,929.5442257217849,0.00025370340306410486,25.0,60.0
801.23828,0.1685772125984252,927.2882677165354,0.00025370340306410486,25.0,60.0
802.63965,0.1691034350393701,930.0849868766404,0.00025370340306410486,25.0,60.0
804.04102,0.16964340748031495,927.7621784776903,0.00025370340306410486,25.0,60.0
805.44238,0.17010461614173228,928.1324934383202,0.00025370340306410486,25.0,60.0
806.84375,0.1706060118110236,927.6082677165355,0.00025370340306410486,25.0,60.0
808.24512,0.17109589566929134,927.0386089238845,0.00025370340306410486,25.0,60.0
809.64648,0.17158052362204723,927.3032545931759,0.00025370340306410486,25.0,60.0
811.04785,0.17207403346456693,929.6876377952756,0.00025370340306410486,25.0,60.0
812.44922,0.17251208070866142,928.6843569553806,0.00025370340306410486,25.0,60.0
813.85059,0.1729927657480315,928.8861942257217,0.00025370340306410486,25.0,60.0
815.25195,0.1734490472440945,930.2471128608923,0.00025370340306410486,25.0,60.0
816.65332,0.1739677598425197,928.9925721784776,0.00025370340306410486,25.0,60.0
818.05469,0.17442482677165352,926.9837532808399,0.00025370340306410486,25.0,60.0
819.45605,0.1749073307086614,929.5985564304463,0.00025370340306410486,25.0,60.0
820.85742,0.17537103937007872,926.8608398950132,0.00025370340306410486,25.0,60.0
822.25879,0.17582811614173227,929.0407611548557,0.00025370340306410486,25.0,60.0
823.66016,0.1763645590551181,929.6705774278215,0.00025370340306410486,25.0,60.0
825.06152,0.17686091929133857,929.9108136482939,0.00025370340306410486,25.0,60.0
826.46289,0.17737431692913386,928.7595800524934,0.00025370340306410486,25.0,60.0
827.86426,0.17789218700787401,928.7131758530184,0.00025370340306410486,25.0,60.0
829.26563,0.17832068307086615,928.2940419947506,0.00025370340306410486,25.0,60.0
830.66699,0.17880149803149606,929.1389238845144,0.00025370340306410486,25.0,60.0
832.06836,0.17927873228346455,930.0086614173229,0.00025370340306410486,25.0,60.0
833.46973,0.1798157381889764,929.3275590551181,0.00025370340306410486,25.0,60.0
834.87109,0.18025987401574803,928.0994225721784,0.00025370340306410486,25.0,60.0
836.27246,0.18079368897637793,929.8155380577429,0.00025370340306410486,25.0,60.0
837.67383,0.18132476771653544,929.4665616797901,0.00025370340306410486,25.0,60.0
839.0752,0.18187886811023624,930.2708136482939,0.00025370340306410486,25.0,60.0
840.47656,0.1825025,929.3056430446194,0.00025370340306410486,25.0,60.0
841.87793,0.18301606102362203,927.164908136483,0.00025370340306410486,25.0,60.0
843.2793,0.1835097007874016,929.2380577427821,0.00025370340306410486,25.0,60.0
844.68066,0.18399402362204723,928.073097112861,0.00025370340306410486,25.0,60.0
846.08203,0.18453600393700786,930.5591076115485,0.00025370340306410486,25.0,60.0
847.4834,0.18504684448818898,929.2010761154855,0.00025370340306410486,25.0,60.0
848.88477,0.18559920669291338,929.0233858267716,0.00025370340306410486,25.0,60.0
850.28613,0.18617272637795276,929.3736482939632,0.00025370340306410486,25.0,60.0
851.6875,0.18672642716535431,929.4816272965878,0.00025370340306410486,25.0,60.0
853.08887,0.1871948405511811,929.7285826771653,0.00025370340306410486,25.0,60.0
854.49023,0.18768572244094486,928.8090551181102,0.00025370340306410486,25.0,60.0
855.8916,0.18814993503937008,928.275590551181,0.00025370340306410486,25.0,60.0
857.29297,0.1885840748031496,929.7468241469816,0.00025370340306410486,25.0,60.0
858.69434,0.1890986220472441,929.0332545931758,0.00025370340306410486,25.0,60.0
860.0957,0.18962742519685039,928.8540157480314,0.00025370340306410486,25.0,60.0
861.49707,0.19013507480314962,931.7014435695537,0.00025370340306410486,25.0,60.0
862.89844,0.19076953543307085,930.631312335958,0.00025370340306410486,25.0,60.0
864.2998,0.19137584842519684,928.3861154855643,0.00025370340306410486,25.0,60.0
865.70117,0.19191462401574802,929.4578477690288,0.00025370340306410486,25.0,60.0
867.10254,0.19247842913385826,929.5879265091863,0.00025370340306410486,25.0,60.0
868.50391,0.19302514763779527,929.0210761154855,0.00025370340306410486,25.0,60.0
869.90527,0.1935999350393701,928.7145144356956,0.00025370340306410486,25.0,60.0
871.30664,0.19411024606299213,928.2692388451444,0.00025370340306410486,25.0,60.0
872.70801,0.1947037933070866,929.7487664041994,0.00025370340306410486,25.0,60.0
873.1084,0.1949055688976378,932.3816272965879,0.00025370340306410486,25.0,60.0