File: datasets/am_bench_2022/csv/60-XY.04-1.csv
Time(s),Strain(%),Stress(MPa),SR(s-1),Temp(C),Angle(deg)
26.102783,2.03720374015748e-06,24.540361585115132,0.00025370340306410486,25.0,60.0
28.705322,9.336646259842519e-06,33.46711811266447,0.00025370340306410486,25.0,60.0
30.206787,3.320845866141732e-05,40.05880705180921,0.00025370340306410486,25.0,60.0
31.708252,4.6869e-05,45.26971885279605,0.00025370340306410486,25.0,60.0
33.209717,5.7121618110236217e-05,51.53365542763158,0.00025370340306410486,25.0,60.0
34.711182,6.636087007874016e-05,59.54105160361842,0.00025370340306410486,25.0,60.0
36.212646,8.180170078740158e-05,67.05290398848685,0.00025370340306410486,25.0,60.0
37.714111,0.00012430891141732283,76.62787314967105,0.00025370340306410486,25.0,60.0
39.215576,0.00014903013976377954,83.90792043585526,0.00025370340306410486,25.0,60.0
40.717041,0.00014837271456692914,92.63270713404604,0.00025370340306410486,25.0,60.0
42.218506,0.00017384191141732284,102.89369346217104,0.00025370340306410486,25.0,60.0
43.719971,0.0002017082874015748,109.04769479851974,0.00025370340306410486,25.0,60.0
45.221436,0.00023275391732283462,118.57297748766447,0.00025370340306410486,25.0,60.0
46.7229,0.0002615301968503937,126.93085166529605,0.00025370340306410486,25.0,60.0
48.224365,0.0002872099409448819,136.25844469572368,0.00025370340306410486,25.0,60.0
49.72583,0.00031897488188976377,145.44596782483552,0.00025370340306410486,25.0,60.0
51.227295,0.0003490474803149606,155.20597759046052,0.00025370340306410486,25.0,60.0
52.72876,0.0003764889566929134,166.66291632401314,0.00025370340306410486,25.0,60.0
54.230225,0.0004100694881889764,176.49333624588814,0.00025370340306410486,25.0,60.0
55.731689,0.00043260832677165353,185.87617444490132,0.00025370340306410486,25.0,60.0
57.233154,0.0004560937401574803,195.38093647203948,0.00025370340306410486,25.0,60.0
58.734619,0.0004924171062992126,204.00524259868422,0.00025370340306410486,25.0,60.0
60.236084,0.0005357462992125984,215.58529502467104,0.00025370340306410486,25.0,60.0
61.737549,0.0005867151574803149,228.03665707236843,0.00025370340306410486,25.0,60.0
63.239014,0.0006002498622047244,236.177490234375,0.00025370340306410486,25.0,60.0
64.740479,0.0006454795472440945,250.3089689555921,0.00025370340306410486,25.0,60.0
66.241943,0.0006666675984251969,258.9492958470395,0.00025370340306410486,25.0,60.0
67.743408,0.0007002693307086614,271.7958213404606,0.00025370340306410486,25.0,60.0
69.244873,0.0007394805314960629,281.41524465460526,0.00025370340306410486,25.0,60.0
70.746338,0.0007976923622047245,293.1180355674342,0.00025370340306410486,25.0,60.0
72.247803,0.0008222998031496064,301.08018092105266,0.00025370340306410486,25.0,60.0
73.749268,0.0008590975,312.37435752467104,0.00025370340306410486,25.0,60.0
75.250732,0.0008767921653543306,321.0200709292763,0.00025370340306410486,25.0,60.0
76.752197,0.0008935002362204724,332.98761307565786,0.00025370340306410486,25.0,60.0
78.253662,0.0009576249212598425,343.8046618009868,0.00025370340306410486,25.0,60.0
79.755127,0.000995256496062992,355.9528166118421,0.00025370340306410486,25.0,60.0
81.256592,0.001049958503937008,367.96612870065786,0.00025370340306410486,25.0,60.0
82.758057,0.0010931054133858267,377.5463353207237,0.00025370340306410486,25.0,60.0
84.259521,0.00111171718503937,387.35107421875,0.00025370340306410486,25.0,60.0
85.760986,0.001140754842519685,397.2329872532895,0.00025370340306410486,25.0,60.0
87.262451,0.001170579153543307,408.2070569490131,0.00025370340306410486,25.0,60.0
88.763916,0.0012055132874015746,418.9063013980263,0.00025370340306410486,25.0,60.0
90.265381,0.0012418070078740156,429.90555612664474,0.00025370340306410486,25.0,60.0
91.766846,0.0013016142322834646,440.49691611842104,0.00025370340306410486,25.0,60.0
93.268311,0.0013291541535433071,450.64697265625,0.00025370340306410486,25.0,60.0
94.769775,0.0013551450196850393,458.7278988486842,0.00025370340306410486,25.0,60.0
96.27124,0.0013862067322834646,469.4463147615131,0.00025370340306410486,25.0,60.0
97.772705,0.0014293058858267716,482.0576171875,0.00025370340306410486,25.0,60.0
99.27417,0.001472777657480315,489.1782483552631,0.00025370340306410486,25.0,60.0
100.77563,0.0014867763779527559,498.70728824013156,0.00025370340306410486,25.0,60.0
102.2771,0.0015459432283464567,506.1704872532895,0.00025370340306410486,25.0,60.0
103.77856,0.0015607604133858267,515.1616981907895,0.00025370340306410486,25.0,60.0
105.28003,0.0015894279133858269,524.3920384457236,0.00025370340306410486,25.0,60.0
106.78149,0.0016281097047244095,533.5855520148027,0.00025370340306410486,25.0,60.0
108.28296,0.0016522439763779525,541.2680150082236,0.00025370340306410486,25.0,60.0
109.78442,0.0016842251968503935,548.8622275904605,0.00025370340306410486,25.0,60.0
111.28589,0.0017108010629921261,556.3397152549342,0.00025370340306410486,25.0,60.0
112.78735,0.0017408607874015746,562.0173982319078,0.00025370340306410486,25.0,60.0
114.28882,0.0017532010039370079,568.8363743832236,0.00025370340306410486,25.0,60.0
115.79028,0.0018075658464566928,577.4190481085526,0.00025370340306410486,25.0,60.0
117.29175,0.0018270953937007874,581.3974352384869,0.00025370340306410486,25.0,60.0
118.79321,0.0018481698622047245,587.9396587171053,0.00025370340306410486,25.0,60.0
120.29468,0.0018943931692913386,595.7722553453947,0.00025370340306410486,25.0,60.0
121.79614,0.0019104738779527556,599.608244243421,0.00025370340306410486,25.0,60.0
123.29761,0.0019594277165354327,604.7807360197369,0.00025370340306410486,25.0,60.0
124.79907,0.001981842125984252,611.914396587171,0.00025370340306410486,25.0,60.0
126.30054,0.002031238779527559,617.6105314555921,0.00025370340306410486,25.0,60.0
127.802,0.0020345153543307086,621.6305766858552,0.00025370340306410486,25.0,60.0
129.30347,0.0020592962598425194,627.6274928042762,0.00025370340306410486,25.0,60.0
130.80493,0.002077831692913386,629.0481599506579,0.00025370340306410486,25.0,60.0
132.3064,0.0021079937007874015,634.2461965460526,0.00025370340306410486,25.0,60.0
133.80786,0.002127716929133858,637.7862613075658,0.00025370340306410486,25.0,60.0
135.30933,0.002178420669291339,644.9713199013157,0.00025370340306410486,25.0,60.0
136.81079,0.0022175954724409446,646.5642732319078,0.00025370340306410486,25.0,60.0
138.31226,0.0022430226377952757,652.8597090871712,0.00025370340306410486,25.0,60.0
139.81372,0.0022720555118110235,655.458341899671,0.00025370340306410486,25.0,60.0
141.31519,0.0023222773622047243,658.2107576069078,0.00025370340306410486,25.0,60.0
142.81665,0.002342407283464567,662.9325914884869,0.00025370340306410486,25.0,60.0
144.31812,0.0024046307086614174,664.3588353207236,0.00025370340306410486,25.0,60.0
145.81958,0.0024334610236220475,669.6674033717105,0.00025370340306410486,25.0,60.0
147.32104,0.002484171653543307,671.9022666529605,0.00025370340306410486,25.0,60.0
148.82251,0.0025145547244094487,676.1066509046052,0.00025370340306410486,25.0,60.0
150.32397,0.002558718897637795,679.4823447779605,0.00025370340306410486,25.0,60.0
151.82544,0.0026055771653543305,683.2934056332236,0.00025370340306410486,25.0,60.0
153.3269,0.0026570299212598427,686.2210629111842,0.00025370340306410486,25.0,60.0
154.82837,0.0027365541338582678,690.5757863898027,0.00025370340306410486,25.0,60.0
156.32983,0.0028038438976377956,692.93115234375,0.00025370340306410486,25.0,60.0
157.8313,0.0028836988188976377,697.1870631167762,0.00025370340306410486,25.0,60.0
159.33276,0.0029294212598425197,699.2507709703947,0.00025370340306410486,25.0,60.0
160.83423,0.0030136240157480317,703.2080078125,0.00025370340306410486,25.0,60.0
162.33569,0.003117414566929134,705.4597553453948,0.00025370340306410486,25.0,60.0
163.83716,0.003186932283464567,707.3043020148026,0.00025370340306410486,25.0,60.0
165.33862,0.003330686023622047,709.4103361430921,0.00025370340306410486,25.0,60.0
166.84009,0.0034088147637795275,711.5823396381579,0.00025370340306410486,25.0,60.0
168.34155,0.003540367125984252,715.9455951891447,0.00025370340306410486,25.0,60.0
169.84302,0.0036653761811023624,717.62939453125,0.00025370340306410486,25.0,60.0
171.34448,0.0037785064960629924,722.049650493421,0.00025370340306410486,25.0,60.0
172.84595,0.00394740374015748,722.7111430921053,0.00025370340306410486,25.0,60.0
174.34741,0.0040686462598425194,724.0702097039474,0.00025370340306410486,25.0,60.0
175.84888,0.004226964763779527,724.5334858141448,0.00025370340306410486,25.0,60.0
177.35034,0.0043782966535433065,727.7942280016448,0.00025370340306410486,25.0,60.0
178.85181,0.004527507283464567,729.3871813322369,0.00025370340306410486,25.0,60.0
180.35327,0.004685847637795275,733.0353618421053,0.00025370340306410486,25.0,60.0
181.85474,0.004899765157480315,734.5587222450657,0.00025370340306410486,25.0,60.0
183.3562,0.0050811988188976375,736.109529194079,0.00025370340306410486,25.0,60.0
184.85767,0.005267679724409449,736.0643503289474,0.00025370340306410486,25.0,60.0
186.35913,0.005498147244094488,739.112150493421,0.00025370340306410486,25.0,60.0
187.8606,0.0057091734251968505,740.5608552631579,0.00025370340306410486,25.0,60.0
189.36206,0.00594733248031496,741.2192639802631,0.00025370340306410486,25.0,60.0
190.86353,0.006142249015748032,743.0146998355264,0.00025370340306410486,25.0,60.0
192.36499,0.006448841929133858,744.2384097450658,0.00025370340306410486,25.0,60.0
193.86646,0.00657285531496063,745.3145559210527,0.00025370340306410486,25.0,60.0
195.36792,0.006845201181102362,748.383634868421,0.00025370340306410486,25.0,60.0
196.86938,0.007124885433070866,748.2844880756579,0.00025370340306410486,25.0,60.0
198.37085,0.007359866141732283,750.9313836348683,0.00025370340306410486,25.0,60.0
199.87231,0.007650534842519685,751.0809004934212,0.00025370340306410486,25.0,60.0
201.37378,0.00790369094488189,754.3622789884868,0.00025370340306410486,25.0,60.0
202.87524,0.008231972047244095,754.61865234375,0.00025370340306410486,25.0,60.0
204.37671,0.008484938188976379,756.386076274671,0.00025370340306410486,25.0,60.0
205.87817,0.008741007283464566,755.5812345805921,0.00025370340306410486,25.0,60.0
207.37964,0.009003444488188976,757.6659385279605,0.00025370340306410486,25.0,60.0
208.8811,0.0092536218503937,757.4669253700658,0.00025370340306410486,25.0,60.0
210.38257,0.009559351574803148,762.0307103207238,0.00025370340306410486,25.0,60.0
211.88403,0.009838169094488189,762.7237356085527,0.00025370340306410486,25.0,60.0
213.3855,0.010181805708661418,762.8589638157895,0.00025370340306410486,25.0,60.0
214.88696,0.01045271279527559,764.836271587171,0.00025370340306410486,25.0,60.0
216.38843,0.010750274803149606,766.542146381579,0.00025370340306410486,25.0,60.0
217.88989,0.011063528543307086,765.740876850329,0.00025370340306410486,25.0,60.0
219.39136,0.011290999999999999,764.910490337171,0.00025370340306410486,25.0,60.0
220.89282,0.011601960433070865,767.4916735197369,0.00025370340306410486,25.0,60.0
222.39429,0.011881799409448819,770.4443102384869,0.00025370340306410486,25.0,60.0
223.89575,0.01218788188976378,769.8901110197369,0.00025370340306410486,25.0,60.0
225.39722,0.012479797244094487,770.1697419819079,0.00025370340306410486,25.0,60.0
226.89868,0.012790774015748033,772.2789884868421,0.00025370340306410486,25.0,60.0
228.40015,0.013079624803149607,774.1768092105262,0.00025370340306410486,25.0,60.0
229.90161,0.013431264370078739,774.3660310444079,0.00025370340306410486,25.0,60.0
231.40308,0.013762994094488189,776.4279913651317,0.00025370340306410486,25.0,60.0
232.90454,0.01406148661417323,775.2676295230262,0.00025370340306410486,25.0,60.0
234.40601,0.01434972440944882,776.7685546875,0.00025370340306410486,25.0,60.0
235.90747,0.014618706496062991,777.4447214226974,0.00025370340306410486,25.0,60.0
237.40894,0.014926522440944882,778.2865953947369,0.00025370340306410486,25.0,60.0
238.9104,0.015275756692913386,779.3865131578947,0.00025370340306410486,25.0,60.0
240.41187,0.015595204724409449,780.6036441200657,0.00025370340306410486,25.0,60.0
241.91333,0.015918532086614173,780.6652446546053,0.00025370340306410486,25.0,60.0
243.41479,0.016220908267716536,782.1765779194079,0.00025370340306410486,25.0,60.0
244.91626,0.0165403344488189,784.1997327302631,0.00025370340306410486,25.0,60.0
246.41772,0.016829956692913386,783.4120836759869,0.00025370340306410486,25.0,60.0
247.91919,0.01716053956692913,785.348478618421,0.00025370340306410486,25.0,60.0
249.42065,0.017517152362204722,784.1982935855264,0.00025370340306410486,25.0,60.0
250.92212,0.017794052952755907,786.1870888157895,0.00025370340306410486,25.0,60.0
252.42358,0.0180765781496063,787.2002467105264,0.00025370340306410486,25.0,60.0
253.92505,0.018370471259842522,787.3862047697368,0.00025370340306410486,25.0,60.0
255.42651,0.018738001968503937,789.6625462582236,0.00025370340306410486,25.0,60.0
256.92798,0.019129091338582677,792.333650287829,0.00025370340306410486,25.0,60.0
258.42944,0.01946228937007874,792.2761615953948,0.00025370340306410486,25.0,60.0
259.93091,0.019821588582677165,791.1435032894738,0.00025370340306410486,25.0,60.0
261.43237,0.020120732283464567,790.3782380756579,0.00025370340306410486,25.0,60.0
262.93384,0.0204408562992126,792.7946134868421,0.00025370340306410486,25.0,60.0
264.4353,0.02070016535433071,793.7064401726974,0.00025370340306410486,25.0,60.0
265.93677,0.021042814960629923,794.964021381579,0.00025370340306410486,25.0,60.0
267.43823,0.021385033464566928,795.77978515625,0.00025370340306410486,25.0,60.0
268.9397,0.021700905511811024,796.52001953125,0.00025370340306410486,25.0,60.0
270.44116,0.022038964566929133,797.2273591694079,0.00025370340306410486,25.0,60.0
271.94263,0.02237374212598425,797.3494037828948,0.00025370340306410486,25.0,60.0
273.44409,0.022700742125984254,799.158048930921,0.00025370340306410486,25.0,60.0
274.94556,0.023018336614173227,797.95361328125,0.00025370340306410486,25.0,60.0
276.44702,0.023362870078740158,797.7995219983553,0.00025370340306410486,25.0,60.0
277.94849,0.02363662401574803,799.7861585115131,0.00025370340306410486,25.0,60.0
279.44995,0.023972938976377953,802.5348735608552,0.00025370340306410486,25.0,60.0
280.95142,0.02432658661417323,802.7061574835527,0.00025370340306410486,25.0,60.0
282.45288,0.0246813031496063,803.9476254111842,0.00025370340306410486,25.0,60.0
283.95435,0.024984809055118108,802.6845189144736,0.00025370340306410486,25.0,60.0
285.45581,0.025292665354330706,802.3007298519738,0.00025370340306410486,25.0,60.0
286.95728,0.025597562992125983,804.7476613898026,0.00025370340306410486,25.0,60.0
288.45874,0.02594241338582677,807.5771227384869,0.00025370340306410486,25.0,60.0
289.96021,0.026283364173228345,805.9150390625,0.00025370340306410486,25.0,60.0
291.46167,0.026615033464566926,804.3081568667764,0.00025370340306410486,25.0,60.0
292.96313,0.026914570866141733,807.7944592927631,0.00025370340306410486,25.0,60.0
294.4646,0.027265326771653546,807.0595703125,0.00025370340306410486,25.0,60.0
295.96606,0.02762726377952756,810.0325863486842,0.00025370340306410486,25.0,60.0
297.46753,0.027971653543307086,809.3188990542764,0.00025370340306410486,25.0,60.0
298.96899,0.028252832677165354,809.7213199013158,0.00025370340306410486,25.0,60.0
300.47046,0.028583466535433068,809.9389134457238,0.00025370340306410486,25.0,60.0
301.97192,0.028934937007874015,811.5794099506579,0.00025370340306410486,25.0,60.0
303.47339,0.029255789370078743,812.9104132401316,0.00025370340306410486,25.0,60.0
304.97485,0.029578812992125985,813.4762798108553,0.00025370340306410486,25.0,60.0
306.47632,0.029957795275590553,814.1793791118421,0.00025370340306410486,25.0,60.0
307.97778,0.03028443307086614,813.591154399671,0.00025370340306410486,25.0,60.0
309.47925,0.030612549212598424,814.9881784539474,0.00025370340306410486,25.0,60.0
310.98071,0.030918263779527555,815.8149928042764,0.00025370340306410486,25.0,60.0
312.48218,0.031274340551181105,816.4627878289474,0.00025370340306410486,25.0,60.0
313.98364,0.03162002559055118,817.7875719572369,0.00025370340306410486,25.0,60.0
315.48511,0.031944907480314956,817.9589329769738,0.00025370340306410486,25.0,60.0
316.98657,0.03225637401574803,818.4973273026316,0.00025370340306410486,25.0,60.0
318.48804,0.03258257086614173,818.2621556332236,0.00025370340306410486,25.0,60.0
319.9895,0.032866925196850395,817.494962993421,0.00025370340306410486,25.0,60.0
321.49097,0.033123748031496064,818.6396741365131,0.00025370340306410486,25.0,60.0
322.99243,0.03343288385826772,821.8630242598683,0.00025370340306410486,25.0,60.0
324.4939,0.0337693405511811,820.7650596217105,0.00025370340306410486,25.0,60.0
325.99536,0.03407877362204724,822.8270713404605,0.00025370340306410486,25.0,60.0
327.49683,0.03441834448818898,822.8194644325657,0.00025370340306410486,25.0,60.0
328.99829,0.03475890354330709,822.667634662829,0.00025370340306410486,25.0,60.0
330.49976,0.035069970472440946,824.9795949835527,0.00025370340306410486,25.0,60.0
332.00122,0.035442614173228346,825.5765316611843,0.00025370340306410486,25.0,60.0
333.50269,0.035817923228346454,825.8070518092105,0.00025370340306410486,25.0,60.0
335.00415,0.0361226062992126,824.2420076069079,0.00025370340306410486,25.0,60.0
336.50562,0.03647013188976378,827.8282791940788,0.00025370340306410486,25.0,60.0
338.00708,0.03677114763779527,828.1064710115132,0.00025370340306410486,25.0,60.0
339.50854,0.03714322440944882,829.54150390625,0.00025370340306410486,25.0,60.0
341.01001,0.03747692519685039,827.2635947779605,0.00025370340306410486,25.0,60.0
342.51147,0.0378266437007874,829.3352693256578,0.00025370340306410486,25.0,60.0
344.01294,0.03817273031496063,829.99072265625,0.00025370340306410486,25.0,60.0
345.5144,0.0384342283464567,830.0204564144736,0.00025370340306410486,25.0,60.0
347.01587,0.03878298031496063,831.1555818256578,0.00025370340306410486,25.0,60.0
348.51733,0.03910012401574803,830.7305715460526,0.00025370340306410486,25.0,60.0
350.0188,0.03943913582677165,833.3093133223683,0.00025370340306410486,25.0,60.0
351.52026,0.03978781889763779,830.9437191611842,0.00025370340306410486,25.0,60.0
353.02173,0.04010956692913386,833.0865799753288,0.00025370340306410486,25.0,60.0
354.52319,0.040431344488188976,833.8378649259868,0.00025370340306410486,25.0,60.0
356.02466,0.040752076771653545,833.6558388157895,0.00025370340306410486,25.0,60.0
357.52612,0.04103890354330709,835.0282689144738,0.00025370340306410486,25.0,60.0
359.02759,0.04134408464566929,837.4640727796053,0.00025370340306410486,25.0,60.0
360.52905,0.04169806692913386,837.0364412006579,0.00025370340306410486,25.0,60.0
362.03052,0.042064059055118105,838.0224866365132,0.00025370340306410486,25.0,60.0
363.53198,0.04236631299212599,836.867341694079,0.00025370340306410486,25.0,60.0
365.03345,0.042738935039370075,838.033537212171,0.00025370340306410486,25.0,60.0
366.53491,0.043041153543307085,839.6281609786183,0.00025370340306410486,25.0,60.0
368.03638,0.0433842874015748,838.7689915707236,0.00025370340306410486,25.0,60.0
369.53784,0.04371787992125985,839.2718698601974,0.00025370340306410486,25.0,60.0
371.03931,0.0440228405511811,839.1013826069079,0.00025370340306410486,25.0,60.0
372.54077,0.04434392322834646,840.0441509046052,0.00025370340306410486,25.0,60.0
374.04224,0.04467702165354331,842.2936369243421,0.00025370340306410486,25.0,60.0
375.5437,0.04502403543307087,840.5069387335526,0.00025370340306410486,25.0,60.0
377.04517,0.04540676181102362,842.5671258223684,0.00025370340306410486,25.0,60.0
378.54663,0.04576267125984252,842.925935444079,0.00025370340306410486,25.0,60.0
380.0481,0.04608404724409449,843.3843801398027,0.00025370340306410486,25.0,60.0
381.54956,0.04642305118110236,845.1793791118422,0.00025370340306410486,25.0,60.0
383.05103,0.04676486023622047,843.7014288651316,0.00025370340306410486,25.0,60.0
384.55249,0.04706687204724409,845.5706208881579,0.00025370340306410486,25.0,60.0
386.05396,0.04738499409448819,845.3088764391447,0.00025370340306410486,25.0,60.0
387.55542,0.04773925196850393,848.1979337993421,0.00025370340306410486,25.0,60.0
389.05688,0.04813218503937008,848.4047337582236,0.00025370340306410486,25.0,60.0
390.55835,0.04846824803149607,846.4985865542764,0.00025370340306410486,25.0,60.0
392.05981,0.04874754527559055,846.7258172286184,0.00025370340306410486,25.0,60.0
393.56128,0.04906847637795276,848.8458059210526,0.00025370340306410486,25.0,60.0
395.06274,0.04938670669291339,849.4104132401317,0.00025370340306410486,25.0,60.0
396.56421,0.049693149606299204,849.5549701891448,0.00025370340306410486,25.0,60.0
398.06567,0.050034303149606295,849.1160310444079,0.00025370340306410486,25.0,60.0
399.56714,0.050365913385826765,849.5842156661183,0.00025370340306410486,25.0,60.0
401.0686,0.0506659842519685,850.5815686677631,0.00025370340306410486,25.0,60.0
402.57007,0.05101251181102362,850.6089638157895,0.00025370340306410486,25.0,60.0
404.07153,0.051370309055118114,853.4512489720395,0.00025370340306410486,25.0,60.0
405.573,0.051716062992125986,852.6581260279605,0.00025370340306410486,25.0,60.0
407.07446,0.052034578740157475,853.7967465049343,0.00025370340306410486,25.0,60.0
408.57593,0.05233785236220473,853.7997018914474,0.00025370340306410486,25.0,60.0
410.07739,0.05272203937007874,855.0237972861843,0.00025370340306410486,25.0,60.0
411.57886,0.053103602362204724,855.3016293174342,0.00025370340306410486,25.0,60.0
413.08032,0.053420257874015754,854.0704923930922,0.00025370340306410486,25.0,60.0
414.58179,0.0537715374015748,856.368986430921,0.00025370340306410486,25.0,60.0
416.08325,0.05410239763779527,856.87744140625,0.00025370340306410486,25.0,60.0
417.58472,0.05440868700787402,857.2506938733553,0.00025370340306410486,25.0,60.0
419.08618,0.054705523622047246,857.1821803042762,0.00025370340306410486,25.0,60.0
420.58765,0.055040208661417324,859.2914268092105,0.00025370340306410486,25.0,60.0
422.08911,0.05538585629921259,858.0199167351974,0.00025370340306410486,25.0,60.0
423.59058,0.055735047244094484,860.670564350329,0.00025370340306410486,25.0,60.0
425.09204,0.05608007480314961,861.2484580592105,0.00025370340306410486,25.0,60.0
426.59351,0.05645890354330708,860.5004625822368,0.00025370340306410486,25.0,60.0
428.09497,0.05681400393700787,859.4620939555922,0.00025370340306410486,25.0,60.0
429.59644,0.0571103720472441,858.8110865542762,0.00025370340306410486,25.0,60.0
431.0979,0.05742187598425196,861.7809673108552,0.00025370340306410486,25.0,60.0
432.59937,0.05775185039370079,862.277986225329,0.00025370340306410486,25.0,60.0
434.10083,0.05810935433070866,862.0736533717106,0.00025370340306410486,25.0,60.0
435.60229,0.05844427165354331,862.5741416529605,0.00025370340306410486,25.0,60.0
437.10376,0.058777043307086614,865.0838815789473,0.00025370340306410486,25.0,60.0
438.60522,0.05911204921259842,863.3718390213816,0.00025370340306410486,25.0,60.0
440.10669,0.059399114173228344,863.5746813322369,0.00025370340306410486,25.0,60.0
441.60815,0.059688125984251966,865.558259662829,0.00025370340306410486,25.0,60.0
443.10962,0.06002820078740157,865.5710063733552,0.00025370340306410486,25.0,60.0
444.61108,0.06036408858267716,866.7965923108553,0.00025370340306410486,25.0,60.0
446.11255,0.06073711614173228,867.8819644325658,0.00025370340306410486,25.0,60.0
447.61401,0.061147108267716535,866.7644171463817,0.00025370340306410486,25.0,60.0
449.11548,0.06144418700787401,866.780915912829,0.00025370340306410486,25.0,60.0
450.61694,0.061779950787401575,868.7963610197369,0.00025370340306410486,25.0,60.0
452.11841,0.06217107677165354,867.37451171875,0.00025370340306410486,25.0,60.0
453.61987,0.06249802165354331,868.3370939555922,0.00025370340306410486,25.0,60.0
455.12134,0.06281769881889764,868.8516909950658,0.00025370340306410486,25.0,60.0
456.6228,0.0631193937007874,868.5002312911184,0.00025370340306410486,25.0,60.0
458.12427,0.06343318110236221,871.6229954769736,0.00025370340306410486,25.0,60.0
459.62573,0.06376611614173229,869.2179790296052,0.00025370340306410486,25.0,60.0
461.1272,0.0640937716535433,870.8934518914474,0.00025370340306410486,25.0,60.0
462.62866,0.0644811437007874,873.7610505756578,0.00025370340306410486,25.0,60.0
464.13013,0.06479868503937007,870.1906095805921,0.00025370340306410486,25.0,60.0
465.63159,0.06515205905511812,872.2706877055922,0.00025370340306410486,25.0,60.0
467.13306,0.06547032874015747,874.1201171875,0.00025370340306410486,25.0,60.0
468.63452,0.06580698228346456,872.7387438322369,0.00025370340306410486,25.0,60.0
470.13599,0.06611224015748031,873.5228721217105,0.00025370340306410486,25.0,60.0
471.63745,0.0664203779527559,875.0225894325658,0.00025370340306410486,25.0,60.0
473.13892,0.06677950787401575,873.200529399671,0.00025370340306410486,25.0,60.0
474.64038,0.06708475196850393,876.4293277138158,0.00025370340306410486,25.0,60.0
476.14185,0.06743324606299213,874.4248560855262,0.00025370340306410486,25.0,60.0
477.64331,0.06775531692913386,876.1619294819079,0.00025370340306410486,25.0,60.0
479.14478,0.06815373425196851,877.3887746710527,0.00025370340306410486,25.0,60.0
480.64624,0.0685121122047244,877.1994757401316,0.00025370340306410486,25.0,60.0
482.14771,0.06878591929133858,875.8170230263158,0.00025370340306410486,25.0,60.0
483.64917,0.06910986614173228,878.2878032483552,0.00025370340306410486,25.0,60.0
485.15063,0.06944653937007873,879.1769891036184,0.00025370340306410486,25.0,60.0
486.6521,0.06979099015748032,881.2734375,0.00025370340306410486,25.0,60.0
488.15356,0.07016914566929133,880.2859529194079,0.00025370340306410486,25.0,60.0
489.65503,0.07049499409448819,878.3094418174343,0.00025370340306410486,25.0,60.0
491.15649,0.07081727559055118,880.0734991776316,0.00025370340306410486,25.0,60.0
492.65796,0.07112806496062993,880.7421361019736,0.00025370340306410486,25.0,60.0
494.15942,0.07150803346456693,882.6949784128288,0.00025370340306410486,25.0,60.0
495.66089,0.07183734251968504,881.7445518092106,0.00025370340306410486,25.0,60.0
497.16235,0.07221274606299212,881.9714226973684,0.00025370340306410486,25.0,60.0
498.66382,0.07253710433070866,882.722322162829,0.00025370340306410486,25.0,60.0
500.16528,0.07284724803149606,881.1611328125,0.00025370340306410486,25.0,60.0
501.66675,0.07320592519685039,884.0417351973684,0.00025370340306410486,25.0,60.0
503.16821,0.07353582283464567,883.7662931743421,0.00025370340306410486,25.0,60.0
504.66968,0.07390700787401575,884.9725534539474,0.00025370340306410486,25.0,60.0
506.17114,0.07429381692913385,884.6350740131579,0.00025370340306410486,25.0,60.0
507.67261,0.07460555511811023,884.6845189144736,0.00025370340306410486,25.0,60.0
509.17407,0.07493047637795275,885.7859529194079,0.00025370340306410486,25.0,60.0
510.67554,0.07524813582677164,885.1231496710527,0.00025370340306410486,25.0,60.0
512.177,0.07559722244094488,887.6137952302631,0.00025370340306410486,25.0,60.0
513.67847,0.07588264960629922,885.4726048519736,0.00025370340306410486,25.0,60.0
515.17993,0.07625167125984252,889.617341694079,0.00025370340306410486,25.0,60.0
516.6814,0.07657751968503937,889.0708521792762,0.00025370340306410486,25.0,60.0
518.18286,0.07693646062992125,888.3220343338816,0.00025370340306410486,25.0,60.0
519.68433,0.07733094881889764,889.6945672286184,0.00025370340306410486,25.0,60.0
521.18579,0.07769552362204724,889.1788394325657,0.00025370340306410486,25.0,60.0
522.68726,0.07804294881889763,889.4266550164474,0.00025370340306410486,25.0,60.0
524.18872,0.07837602559055118,889.1253083881579,0.00025370340306410486,25.0,60.0
525.69019,0.07874749212598425,890.048494037829,0.00025370340306410486,25.0,60.0
527.19165,0.07911271653543307,891.1200657894738,0.00025370340306410486,25.0,60.0
528.69312,0.079456218503937,888.9480108963817,0.00025370340306410486,25.0,60.0
530.19458,0.07970932086614173,889.5463096217105,0.00025370340306410486,25.0,60.0
531.69604,0.08004132283464567,891.5685906661183,0.00025370340306410486,25.0,60.0
533.19751,0.08041648031496064,892.4976870888158,0.00025370340306410486,25.0,60.0
534.69897,0.08080018503937007,892.4309724506578,0.00025370340306410486,25.0,60.0
536.20044,0.08112359448818897,891.3558285361842,0.00025370340306410486,25.0,60.0
537.7019,0.08144824606299213,893.4669767680921,0.00025370340306410486,25.0,60.0
539.20337,0.081850781496063,893.4887438322368,0.00025370340306410486,25.0,60.0
540.70483,0.08216971456692913,893.903474506579,0.00025370340306410486,25.0,60.0
542.2063,0.08247726968503938,895.2038445723684,0.00025370340306410486,25.0,60.0
543.70776,0.08283079724409448,893.818025287829,0.00025370340306410486,25.0,60.0
545.20923,0.08320306889763779,895.7022769325657,0.00025370340306410486,25.0,60.0
546.71069,0.08355531102362204,895.4441046463816,0.00025370340306410486,25.0,60.0
548.21216,0.08386675,896.2323704769738,0.00025370340306410486,25.0,60.0
549.71362,0.08424105118110235,898.0417865953947,0.00025370340306410486,25.0,60.0
551.21509,0.08465624803149606,898.3037366365131,0.00025370340306410486,25.0,60.0
552.71655,0.08499981299212599,896.1220703125,0.00025370340306410486,25.0,60.0
554.21802,0.0853934094488189,897.6088096217105,0.00025370340306410486,25.0,60.0
555.71948,0.08573931692913385,894.4853258634868,0.00025370340306410486,25.0,60.0
557.22095,0.08609228543307086,898.2858501233553,0.00025370340306410486,25.0,60.0
558.72241,0.08643566338582677,898.7717156661183,0.00025370340306410486,25.0,60.0
560.22388,0.08678186417322833,899.6185495476973,0.00025370340306410486,25.0,60.0
561.72534,0.08711824803149605,900.5824424342105,0.00025370340306410486,25.0,60.0
563.22681,0.08746381496062992,899.4778217516447,0.00025370340306410486,25.0,60.0
564.72827,0.08781491929133858,901.2935084292764,0.00025370340306410486,25.0,60.0
566.22974,0.08812945669291339,899.9142423930921,0.00025370340306410486,25.0,60.0
567.7312,0.08849678149606299,900.9785413240132,0.00025370340306410486,25.0,60.0
569.23267,0.0888594311023622,901.775236430921,0.00025370340306410486,25.0,60.0
570.73413,0.08926449015748032,902.8443410773026,0.00025370340306410486,25.0,60.0
572.2356,0.08961563582677165,901.0071443256578,0.00025370340306410486,25.0,60.0
573.73706,0.08993059645669291,899.9956311677632,0.00025370340306410486,25.0,60.0
575.23853,0.09023751968503937,901.1552734375,0.00025370340306410486,25.0,60.0
576.73999,0.09057600393700786,903.4921104029606,0.00025370340306410486,25.0,60.0
578.24146,0.09095812598425197,904.0284231085526,0.00025370340306410486,25.0,60.0
579.74292,0.09132805511811024,903.3629728618422,0.00025370340306410486,25.0,60.0
581.24438,0.09169827952755906,902.9996916118421,0.00025370340306410486,25.0,60.0
582.74585,0.09204672637795276,904.4344675164474,0.00025370340306410486,25.0,60.0
584.24731,0.09236296456692912,904.7679636101974,0.00025370340306410486,25.0,60.0
585.74878,0.0927528937007874,907.1033357319079,0.00025370340306410486,25.0,60.0
587.25024,0.09313733858267717,905.0118215460526,0.00025370340306410486,25.0,60.0
588.75171,0.09346831299212598,905.5786903782895,0.00025370340306410486,25.0,60.0
590.25317,0.09381750590551181,907.4238024259869,0.00025370340306410486,25.0,60.0
591.75464,0.09425362204724409,905.6545024671053,0.00025370340306410486,25.0,60.0
593.2561,0.09464531692913386,908.5249280427631,0.00025370340306410486,25.0,60.0
594.75757,0.0950359625984252,907.984709087171,0.00025370340306410486,25.0,60.0
596.25903,0.09538002755905511,907.0143657483552,0.00025370340306410486,25.0,60.0
597.7605,0.0957435157480315,908.4904142680922,0.00025370340306410486,25.0,60.0
599.26196,0.09613199606299212,907.9564144736842,0.00025370340306410486,25.0,60.0
600.76343,0.09648686614173228,909.4758943256579,0.00025370340306410486,25.0,60.0
602.26489,0.09681597047244095,908.4531506990132,0.00025370340306410486,25.0,60.0
603.76636,0.09714433070866142,908.0807719983553,0.00025370340306410486,25.0,60.0
605.26782,0.09746608464566929,910.040193256579,0.00025370340306410486,25.0,60.0
606.76929,0.09781372047244094,908.6171618009869,0.00025370340306410486,25.0,60.0
608.27075,0.09819594685039369,910.8479389391447,0.00025370340306410486,25.0,60.0
609.77222,0.09859912992125984,910.660978618421,0.00025370340306410486,25.0,60.0
611.27368,0.0990017657480315,911.8774671052631,0.00025370340306410486,25.0,60.0
612.77515,0.09934918700787401,911.4281712582238,0.00025370340306410486,25.0,60.0
614.27661,0.09970142913385827,913.2938682154605,0.00025370340306410486,25.0,60.0
615.77808,0.1000246437007874,911.8342413651316,0.00025370340306410486,25.0,60.0
617.27954,0.10040371850393702,912.4548725328948,0.00025370340306410486,25.0,60.0
618.78101,0.10078901377952755,912.1213507401316,0.00025370340306410486,25.0,60.0
620.28247,0.10114597244094488,912.5776624177631,0.00025370340306410486,25.0,60.0
621.78394,0.10145381692913387,914.0933131167762,0.00025370340306410486,25.0,60.0
623.2854,0.10181280511811022,913.5808490953947,0.00025370340306410486,25.0,60.0
624.78687,0.10221236811023622,915.6692537006579,0.00025370340306410486,25.0,60.0
626.28833,0.10266047047244095,914.1388003700658,0.00025370340306410486,25.0,60.0
627.78979,0.10302579527559055,915.4132144325657,0.00025370340306410486,25.0,60.0
629.29126,0.10339367716535433,914.5436112253288,0.00025370340306410486,25.0,60.0
630.79272,0.10376014173228346,915.7537777549343,0.00025370340306410486,25.0,60.0
632.29419,0.10411028346456692,915.4514288651316,0.00025370340306410486,25.0,60.0
633.79565,0.10448221456692913,916.2267937911184,0.00025370340306410486,25.0,60.0
635.29712,0.10486717913385828,916.5368009868421,0.00025370340306410486,25.0,60.0
636.79858,0.10528366141732283,918.1441200657895,0.00025370340306410486,25.0,60.0
638.30005,0.1056766653543307,916.7792197779605,0.00025370340306410486,25.0,60.0
639.80151,0.10602341535433071,915.9066097861843,0.00025370340306410486,25.0,60.0
641.30298,0.10634244094488189,916.1152857730264,0.00025370340306410486,25.0,60.0
642.80444,0.10667576968503936,918.9883069490131,0.00025370340306410486,25.0,60.0
644.30591,0.10704446259842519,918.093595805921,0.00025370340306410486,25.0,60.0
645.80737,0.10736860433070866,919.2523129111842,0.00025370340306410486,25.0,60.0
647.30884,0.10774901771653544,919.2123509457238,0.00025370340306410486,25.0,60.0
648.8103,0.10813254133858269,919.0693102384868,0.00025370340306410486,25.0,60.0
650.31177,0.10846199803149606,919.6871916118421,0.00025370340306410486,25.0,60.0
651.81323,0.10885811023622048,919.1187551398027,0.00025370340306410486,25.0,60.0
653.3147,0.10920220866141732,919.3630499588816,0.00025370340306410486,25.0,60.0
654.81616,0.10958782086614173,921.9738641036184,0.00025370340306410486,25.0,60.0
656.31763,0.10991488385826771,920.350431743421,0.00025370340306410486,25.0,60.0
657.81909,0.1103458562992126,921.0080180921052,0.00025370340306410486,25.0,60.0
659.32056,0.11070022244094488,921.7765984786184,0.00025370340306410486,25.0,60.0
660.82202,0.11106533661417324,921.04296875,0.00025370340306410486,25.0,60.0
662.32349,0.11148200590551181,922.0028525904606,0.00025370340306410486,25.0,60.0
663.82495,0.11186959842519685,922.9115439967105,0.00025370340306410486,25.0,60.0
665.32642,0.11229592519685039,922.7284642269738,0.00025370340306410486,25.0,60.0
666.82788,0.11268562007874015,920.9732730263158,0.00025370340306410486,25.0,60.0
668.32935,0.11313795866141732,923.4065069901316,0.00025370340306410486,25.0,60.0
669.83081,0.11354109842519684,922.9966334292764,0.00025370340306410486,25.0,60.0
671.33228,0.11390136614173228,922.6360505756579,0.00025370340306410486,25.0,60.0
672.83374,0.1142269625984252,923.2109375,0.00025370340306410486,25.0,60.0
674.33521,0.11458640944881891,922.3924753289474,0.00025370340306410486,25.0,60.0
675.83667,0.1149822874015748,925.7175421463816,0.00025370340306410486,25.0,60.0
677.33813,0.11536496653543307,924.1062654194079,0.00025370340306410486,25.0,60.0
678.8396,0.11572442322834645,924.7689401726974,0.00025370340306410486,25.0,60.0
680.34106,0.11610223228346457,925.8673673930921,0.00025370340306410486,25.0,60.0
681.84253,0.11652277362204724,925.2742084703948,0.00025370340306410486,25.0,60.0
683.34399,0.11688950787401575,923.8032997532895,0.00025370340306410486,25.0,60.0
684.84546,0.11727613976377953,925.51025390625,0.00025370340306410486,25.0,60.0
686.34692,0.11767353149606298,926.5551500822369,0.00025370340306410486,25.0,60.0
687.84839,0.1180631909448819,926.6874743009869,0.00025370340306410486,25.0,60.0
689.34985,0.11847021456692915,927.2698910361842,0.00025370340306410486,25.0,60.0
690.85132,0.11879075393700786,924.9251644736842,0.00025370340306410486,25.0,60.0
692.35278,0.11915937598425196,927.014982524671,0.00025370340306410486,25.0,60.0
693.85425,0.11956880708661417,926.6508275082236,0.00025370340306410486,25.0,60.0
695.35571,0.1199427559055118,928.2818667763158,0.00025370340306410486,25.0,60.0
696.85718,0.1203410964566929,926.3602744654605,0.00025370340306410486,25.0,60.0
698.35864,0.12071889370078741,927.2583521792764,0.00025370340306410486,25.0,60.0
699.86011,0.12112615354330708,928.500642475329,0.00025370340306410486,25.0,60.0
701.36157,0.12149378937007874,928.3200812088817,0.00025370340306410486,25.0,60.0
702.86304,0.12189120472440945,927.8609169407895,0.00025370340306410486,25.0,60.0
704.3645,0.12229541338582677,928.1679944490131,0.00025370340306410486,25.0,60.0
705.86597,0.12270530118110236,930.1594623766447,0.00025370340306410486,25.0,60.0
707.36743,0.12310356102362205,929.3595034950657,0.00025370340306410486,25.0,60.0
708.8689,0.12346988385826772,929.4652292351973,0.00025370340306410486,25.0,60.0
710.37036,0.12384769291338582,929.5965511924342,0.00025370340306410486,25.0,60.0
711.87183,0.12423651968503936,930.3507144325657,0.00025370340306410486,25.0,60.0
713.37329,0.12467781692913386,930.2724609375,0.00025370340306410486,25.0,60.0
714.87476,0.12507911417322834,930.1267732319079,0.00025370340306410486,25.0,60.0
716.37622,0.12540974409448818,929.3374280427631,0.00025370340306410486,25.0,60.0
717.87769,0.12579864173228347,932.1195261101974,0.00025370340306410486,25.0,60.0
719.37915,0.12624525393700786,931.39892578125,0.00025370340306410486,25.0,60.0
720.88062,0.12671836023622046,931.4484220805921,0.00025370340306410486,25.0,60.0
722.38208,0.12707184645669292,931.6741879111842,0.00025370340306410486,25.0,60.0
723.88354,0.12751164173228346,929.9135228207236,0.00025370340306410486,25.0,60.0
725.38501,0.12787811614173228,929.8052785773027,0.00025370340306410486,25.0,60.0
726.88647,0.128268187007874,931.9560032894738,0.00025370340306410486,25.0,60.0
728.38794,0.128674437007874,931.9789782072369,0.00025370340306410486,25.0,60.0
729.8894,0.1290455570866142,931.3147358141448,0.00025370340306410486,25.0,60.0
731.39087,0.1294561377952756,932.6758583470395,0.00025370340306410486,25.0,60.0
732.89233,0.12988153543307088,933.5376747532895,0.00025370340306410486,25.0,60.0
734.3938,0.13033828543307086,934.5751696134869,0.00025370340306410486,25.0,60.0
735.89526,0.13076092716535434,932.7560392680921,0.00025370340306410486,25.0,60.0
737.39673,0.13118660826771653,933.5837273848684,0.00025370340306410486,25.0,60.0
738.89819,0.13159221259842518,933.8064607319079,0.00025370340306410486,25.0,60.0
740.39966,0.1320151003937008,935.1062140213816,0.00025370340306410486,25.0,60.0
741.90112,0.13245956692913385,933.7134046052632,0.00025370340306410486,25.0,60.0
743.40259,0.13285786220472443,933.6652189555922,0.00025370340306410486,25.0,60.0
744.90405,0.13324604330708661,934.4072779605264,0.00025370340306410486,25.0,60.0
746.40552,0.13364803346456694,935.4164782072369,0.00025370340306410486,25.0,60.0
747.90698,0.1340288937007874,934.5463096217105,0.00025370340306410486,25.0,60.0
749.40845,0.13443446259842518,934.5498817845395,0.00025370340306410486,25.0,60.0
750.90991,0.13478623622047245,933.502107319079,0.00025370340306410486,25.0,60.0
752.41138,0.1351701929133858,935.6359477796052,0.00025370340306410486,25.0,60.0
753.91284,0.13555878543307087,935.6025133634869,0.00025370340306410486,25.0,60.0
755.41431,0.1359261279527559,933.7298519736843,0.00025370340306410486,25.0,60.0
756.91577,0.13634489763779528,936.0987356085526,0.00025370340306410486,25.0,60.0
758.41724,0.13677994094488188,936.0865542763158,0.00025370340306410486,25.0,60.0
759.9187,0.13717378937007874,935.4992804276317,0.00025370340306410486,25.0,60.0
761.42017,0.13761985039370078,937.6880910773027,0.00025370340306410486,25.0,60.0
762.92163,0.1380511751968504,937.3333675986842,0.00025370340306410486,25.0,60.0
764.4231,0.13844531496062992,936.0785875822369,0.00025370340306410486,25.0,60.0
765.92456,0.1388627244094488,937.8783922697369,0.00025370340306410486,25.0,60.0
767.42603,0.13931413582677163,937.1849814967105,0.00025370340306410486,25.0,60.0
768.92749,0.13974420472440946,938.6715152138157,0.00025370340306410486,25.0,60.0
770.42896,0.14019582677165354,938.6787880345394,0.00025370340306410486,25.0,60.0
771.93042,0.14060996259842518,939.5852950246712,0.00025370340306410486,25.0,60.0
773.43188,0.14106274606299213,937.7827662417764,0.00025370340306410486,25.0,60.0
774.93335,0.14145206496062993,936.9470600328947,0.00025370340306410486,25.0,60.0
776.43481,0.141921405511811,937.4618626644736,0.00025370340306410486,25.0,60.0
777.93628,0.1423714311023622,939.6327097039474,0.00025370340306410486,25.0,60.0
779.43774,0.14277046653543307,940.2344777960527,0.00025370340306410486,25.0,60.0
780.93921,0.14315396456692914,937.9839381167764,0.00025370340306410486,25.0,60.0
782.44067,0.1435689566929134,939.7583264802632,0.00025370340306410486,25.0,60.0
783.94214,0.14400122047244093,939.0896124588816,0.00025370340306410486,25.0,60.0
785.4436,0.14442030511811024,937.9449527138158,0.00025370340306410486,25.0,60.0
786.94507,0.14482284842519685,938.9779502467106,0.00025370340306410486,25.0,60.0
788.44653,0.14528173425196853,938.7578381990131,0.00025370340306410486,25.0,60.0
789.948,0.14566018897637795,939.9456208881579,0.00025370340306410486,25.0,60.0
791.44946,0.14616453937007876,941.7747224506579,0.00025370340306410486,25.0,60.0
792.95093,0.14657850984251966,940.9284025493421,0.00025370340306410486,25.0,60.0
794.45239,0.1471098838582677,941.639314350329,0.00025370340306410486,25.0,60.0
795.95386,0.14761025787401574,939.2967979029605,0.00025370340306410486,25.0,60.0
797.45532,0.14808518307086613,940.4919048108553,0.00025370340306410486,25.0,60.0
798.95679,0.14847963976377954,940.3814761513157,0.00025370340306410486,25.0,60.0
800.45825,0.1488324468503937,938.4408151726973,0.00025370340306410486,25.0,60.0
801.95972,0.14924391732283465,940.5350791529605,0.00025370340306410486,25.0,60.0
803.46118,0.14968847637795274,942.8870014391447,0.00025370340306410486,25.0,60.0
804.96265,0.1502260098425197,941.9719880756579,0.00025370340306410486,25.0,60.0
806.46411,0.15071005118110237,939.9365748355264,0.00025370340306410486,25.0,60.0
807.96558,0.1511353090551181,940.9041683799342,0.00025370340306410486,25.0,60.0
809.46704,0.15156399409448817,941.0918482730264,0.00025370340306410486,25.0,60.0
810.96851,0.15204438582677166,941.8214689555921,0.00025370340306410486,25.0,60.0
812.46997,0.15251237598425196,940.8337787828948,0.00025370340306410486,25.0,60.0
813.97144,0.15292567716535432,941.2792454769738,0.00025370340306410486,25.0,60.0
815.4729,0.1533418188976378,940.7480725740131,0.00025370340306410486,25.0,60.0
816.97437,0.153749781496063,942.4520199424342,0.00025370340306410486,25.0,60.0
818.47583,0.1541618523622047,942.0024157072369,0.00025370340306410486,25.0,60.0
819.97729,0.15459991141732285,941.2700966282895,0.00025370340306410486,25.0,60.0
821.47876,0.15501573622047243,942.2998560855264,0.00025370340306410486,25.0,60.0
822.98022,0.1554253188976378,941.7143040707238,0.00025370340306410486,25.0,60.0
824.48169,0.155851468503937,943.9071751644736,0.00025370340306410486,25.0,60.0
825.98315,0.15630722047244094,943.3056126644736,0.00025370340306410486,25.0,60.0
827.48462,0.1567235846456693,941.3157637746712,0.00025370340306410486,25.0,60.0
828.98608,0.1571994724409449,942.8197985197369,0.00025370340306410486,25.0,60.0
830.48755,0.15766360236220472,942.6696648848684,0.00025370340306410486,25.0,60.0
831.98901,0.1581461771653543,943.6930509868421,0.00025370340306410486,25.0,60.0
833.49048,0.158609062992126,942.1755756578948,0.00025370340306410486,25.0,60.0
834.99194,0.15910848622047244,944.5996607730264,0.00025370340306410486,25.0,60.0
836.49341,0.15964713385826773,943.10986328125,0.00025370340306410486,25.0,60.0
837.99487,0.1601153464566929,944.8633583470395,0.00025370340306410486,25.0,60.0
839.49634,0.16060855118110237,943.7176963404605,0.00025370340306410486,25.0,60.0
840.9978,0.1611121751968504,944.1251541940788,0.00025370340306410486,25.0,60.0
842.49927,0.16156712007874016,944.916015625,0.00025370340306410486,25.0,60.0
844.00073,0.1620521220472441,943.5022615131579,0.00025370340306410486,25.0,60.0
845.5022,0.16247199606299212,943.1596165707236,0.00025370340306410486,25.0,60.0
847.00366,0.16292862795275592,944.091154399671,0.00025370340306410486,25.0,60.0
848.50513,0.16336957283464565,945.6682771381579,0.00025370340306410486,25.0,60.0
850.00659,0.16388056496062992,944.0199424342105,0.00025370340306410486,25.0,60.0
851.50806,0.16439735433070865,944.0730108963816,0.00025370340306410486,25.0,60.0
853.00952,0.16484901181102363,943.9766395970395,0.00025370340306410486,25.0,60.0
854.51099,0.16533087007874014,944.939298930921,0.00025370340306410486,25.0,60.0
856.01245,0.16577991141732284,944.8448036595395,0.00025370340306410486,25.0,60.0
857.51392,0.16622488188976378,943.7304944490131,0.00025370340306410486,25.0,60.0
859.01538,0.16663313779527558,944.6242033305921,0.00025370340306410486,25.0,60.0
860.51685,0.16710109448818897,946.5933388157895,0.00025370340306410486,25.0,60.0
862.01831,0.16757002165354332,943.5750925164474,0.00025370340306410486,25.0,60.0
863.51978,0.16801386614173228,945.3108552631579,0.00025370340306410486,25.0,60.0
865.02124,0.16853514763779526,946.5621145148026,0.00025370340306410486,25.0,60.0
866.52271,0.16900966338582676,946.1205797697369,0.00025370340306410486,25.0,60.0
868.02417,0.1695819251968504,946.5020045230264,0.00025370340306410486,25.0,60.0
869.52563,0.17009215551181103,946.2437551398027,0.00025370340306410486,25.0,60.0
871.0271,0.1706020216535433,944.9061472039474,0.00025370340306410486,25.0,60.0
872.52856,0.17112798622047243,945.4367033305921,0.00025370340306410486,25.0,60.0
874.03003,0.17164754330708662,945.3763363486843,0.00025370340306410486,25.0,60.0
875.53149,0.17209520078740156,945.3403834292762,0.00025370340306410486,25.0,60.0
877.03296,0.1725679429133858,945.5806435032895,0.00025370340306410486,25.0,60.0
878.53442,0.17309128937007875,946.8721217105264,0.00025370340306410486,25.0,60.0
880.03589,0.17357328937007874,946.5851922286184,0.00025370340306410486,25.0,60.0
881.53735,0.17407985826771655,945.9310495476974,0.00025370340306410486,25.0,60.0
883.03882,0.17460097637795277,945.1388003700657,0.00025370340306410486,25.0,60.0
884.54028,0.17504432677165352,945.516755756579,0.00025370340306410486,25.0,60.0
886.04175,0.17550721456692914,945.1359734786184,0.00025370340306410486,25.0,60.0
887.54321,0.17602995078740158,947.6734426398026,0.00025370340306410486,25.0,60.0
889.04468,0.17663700393700787,945.4272974917764,0.00025370340306410486,25.0,60.0
890.54614,0.17708570472440943,948.0336400082236,0.00025370340306410486,25.0,60.0
892.04761,0.17763595669291338,947.5438939144738,0.00025370340306410486,25.0,60.0
893.54907,0.17807910826771653,945.2009919819079,0.00025370340306410486,25.0,60.0
895.05054,0.17854382480314962,946.8919870476974,0.00025370340306410486,25.0,60.0
896.552,0.17896382677165354,945.6358449835526,0.00025370340306410486,25.0,60.0
898.05347,0.17945429724409448,946.683259662829,0.00025370340306410486,25.0,60.0
899.55493,0.179999187007874,945.7578895970395,0.00025370340306410486,25.0,60.0
901.0564,0.18051525984251968,945.7851819490132,0.00025370340306410486,25.0,60.0
902.55786,0.1810617913385827,947.598478618421,0.00025370340306410486,25.0,60.0
904.05933,0.18161372244094487,946.9053505345395,0.00025370340306410486,25.0,60.0
905.56079,0.18212910236220473,946.3135279605264,0.00025370340306410486,25.0,60.0
907.06226,0.1827082303149606,947.982267680921,0.00025370340306410486,25.0,60.0
908.56372,0.18323767913385827,945.5940583881579,0.00025370340306410486,25.0,60.0
910.06519,0.18369040354330707,944.7821751644738,0.00025370340306410486,25.0,60.0
911.56665,0.1841802303149606,946.9199732730264,0.00025370340306410486,25.0,60.0
913.06812,0.18468880511811023,946.3357319078948,0.00025370340306410486,25.0,60.0
914.56958,0.18521151968503938,946.4401983963817,0.00025370340306410486,25.0,60.0
916.07104,0.18576574803149606,946.5270353618422,0.00025370340306410486,25.0,60.0
917.57251,0.18629613582677165,946.6599249588816,0.00025370340306410486,25.0,60.0
919.07397,0.18682698031496064,946.40625,0.00025370340306410486,25.0,60.0
920.57544,0.18738417913385827,947.5548673930921,0.00025370340306410486,25.0,60.0
922.0769,0.18796056102362205,948.7740028782895,0.00025370340306410486,25.0,60.0
923.57837,0.18861784251968503,946.7129420230264,0.00025370340306410486,25.0,60.0
925.07983,0.1891043720472441,947.093904194079,0.00025370340306410486,25.0,60.0
926.5813,0.1896688562992126,946.8567280016447,0.00025370340306410486,25.0,60.0
928.08276,0.19026291929133857,943.1914319490131,0.00025370340306410486,25.0,60.0
929.58423,0.19071458858267715,947.1057000411184,0.00025370340306410486,25.0,60.0
931.08569,0.19124003543307086,946.1933079769738,0.00025370340306410486,25.0,60.0
932.58716,0.19172937992125985,945.4128546463816,0.00025370340306410486,25.0,60.0
934.08862,0.1923044251968504,946.3625102796052,0.00025370340306410486,25.0,60.0
935.59009,0.19283196062992125,945.9746607730264,0.00025370340306410486,25.0,60.0
937.09155,0.1934084133858268,947.1050575657895,0.00025370340306410486,25.0,60.0
938.59302,0.193953125984252,945.1053659539474,0.00025370340306410486,25.0,60.0
940.09448,0.1945321594488189,947.2990080180921,0.00025370340306410486,25.0,60.0
941.59595,0.19508685826771655,946.1800729851974,0.00025370340306410486,25.0,60.0
943.09741,0.19558882874015748,945.1416272615131,0.00025370340306410486,25.0,60.0
944.59888,0.1960768248031496,946.5619860197369,0.00025370340306410486,25.0,60.0
945.49976,0.19650460433070865,949.6131013569079,0.00025370340306410486,25.0,60.0