File: datasets/am_bench_2022/csv/60-XY.09-1.csv
Time(s),Strain(%),Stress(MPa),SR(s-1),Temp(C),Angle(deg)
16.274658,9.46576653543307e-06,15.790849500064928,0.00025370340306410486,25.0,60.0
17.776123,1.626346830708661e-05,21.68952941176471,0.00025370340306410486,25.0,60.0
19.17749,2.279719094488189e-05,26.334860407739253,0.00025370340306410486,25.0,60.0
20.578857,4.5760909448818895e-05,31.297662641215428,0.00025370340306410486,25.0,60.0
21.980225,6.623932086614174e-05,35.54485391507597,0.00025370340306410486,25.0,60.0
23.381592,7.890444291338582e-05,38.973273600831064,0.00025370340306410486,25.0,60.0
24.782959,8.003295472440944e-05,43.18383067134138,0.00025370340306410486,25.0,60.0
26.184326,0.00012462033267716534,49.18847941825737,0.00025370340306410486,25.0,60.0
27.585693,0.00015863606496062992,54.83314894169589,0.00025370340306410486,25.0,60.0
28.987061,0.00015903214173228347,62.37704973380081,0.00025370340306410486,25.0,60.0
30.388428,0.00021054307086614172,67.94405661602389,0.00025370340306410486,25.0,60.0
31.789795,0.00022001381889763777,75.38484612388001,0.00025370340306410486,25.0,60.0
33.191162,0.0002412028937007874,83.86304895468122,0.00025370340306410486,25.0,60.0
34.592529,0.000289310531496063,89.79781327100378,0.00025370340306410486,25.0,60.0
35.993896,0.0002737954724409449,97.52019997402935,0.00025370340306410486,25.0,60.0
37.395264,0.00032965346456692915,104.16180755746008,0.00025370340306410486,25.0,60.0
38.796631,0.0003894896850393701,112.06571354369562,0.00025370340306410486,25.0,60.0
40.197998,0.00040328755905511807,122.19424490325932,0.00025370340306410486,25.0,60.0
41.599365,0.00044839606299212594,130.2962913907285,0.00025370340306410486,25.0,60.0
43.000732,0.00048521874015748027,136.8629165043501,0.00025370340306410486,25.0,60.0
44.4021,0.0004729109842519685,145.64470328528765,0.00025370340306410486,25.0,60.0
45.803467,0.0005427796062992126,153.60151408907936,0.00025370340306410486,25.0,60.0
47.204834,0.0005827136023622047,163.3505726529022,0.00025370340306410486,25.0,60.0
48.606201,0.0005780575787401575,172.977626282301,0.00025370340306410486,25.0,60.0
50.007568,0.000643286279527559,182.0154265679782,0.00025370340306410486,25.0,60.0
51.408936,0.0006912390354330708,190.977125048695,0.00025370340306410486,25.0,60.0
52.810303,0.0006986675590551181,200.4412128295027,0.00025370340306410486,25.0,60.0
54.21167,0.0007327468110236221,210.8632697052331,0.00025370340306410486,25.0,60.0
55.613037,0.0007958388779527558,219.40746136865343,0.00025370340306410486,25.0,60.0
57.014404,0.0008312152952755906,230.28855213608625,0.00025370340306410486,25.0,60.0
58.415771,0.000857604625984252,240.72184911050516,0.00025370340306410486,25.0,60.0
59.817139,0.0009223300787401574,250.55864433190496,0.00025370340306410486,25.0,60.0
61.218506,0.0009507911614173229,260.2691598493702,0.00025370340306410486,25.0,60.0
62.619873,0.0009846187007874015,271.03464485131803,0.00025370340306410486,25.0,60.0
64.02124,0.0010279404133858268,280.96525126606934,0.00025370340306410486,25.0,60.0
65.422607,0.001061868877952756,290.91572523048956,0.00025370340306410486,25.0,60.0
66.823975,0.0011082948622047244,301.62243864433196,0.00025370340306410486,25.0,60.0
68.225342,0.0011537187401574804,311.0606674457863,0.00025370340306410486,25.0,60.0
69.626709,0.0011907301968503937,322.11712764576026,0.00025370340306410486,25.0,60.0
71.028076,0.0012340002952755905,333.5848071679003,0.00025370340306410486,25.0,60.0
72.429443,0.0012516143897637797,340.7945981041423,0.00025370340306410486,25.0,60.0
73.830811,0.0012979183661417323,351.78763796909493,0.00025370340306410486,25.0,60.0
75.232178,0.0013389007677165354,361.1242436047267,0.00025370340306410486,25.0,60.0
76.633545,0.0013859463188976378,370.57771717958707,0.00025370340306410486,25.0,60.0
78.034912,0.0014171064763779527,381.39083235943383,0.00025370340306410486,25.0,60.0
79.436279,0.0014382066141732284,391.00114270873917,0.00025370340306410486,25.0,60.0
80.837646,0.0014872862204724409,400.5032073756655,0.00025370340306410486,25.0,60.0
82.239014,0.0015255810826771653,411.18366445916115,0.00025370340306410486,25.0,60.0
83.640381,0.0015483617322834646,420.86129074146214,0.00025370340306410486,25.0,60.0
85.041748,0.0015769443503937009,431.65365536943256,0.00025370340306410486,25.0,60.0
86.443115,0.001644295472440945,443.1622126996494,0.00025370340306410486,25.0,60.0
87.844482,0.0016452957283464567,451.60929749383195,0.00025370340306410486,25.0,60.0
89.24585,0.001696717933070866,461.1864692897027,0.00025370340306410486,25.0,60.0
90.647217,0.001739875196850394,470.77506817296455,0.00025370340306410486,25.0,60.0
92.048584,0.0017753774803149606,480.3623944942215,0.00025370340306410486,25.0,60.0
93.449951,0.0018029897244094487,489.5029996104402,0.00025370340306410486,25.0,60.0
94.851318,0.0018363754330708662,497.4390079210492,0.00025370340306410486,25.0,60.0
96.252686,0.0018793801771653544,508.0413193091806,0.00025370340306410486,25.0,60.0
97.654053,0.0019072166338582677,518.026152447734,0.00025370340306410486,25.0,60.0
99.05542,0.0019182436417322832,524.3630437605506,0.00025370340306410486,25.0,60.0
100.45679,0.001984161220472441,532.2050123360602,0.00025370340306410486,25.0,60.0
101.85815,0.00198844468503937,538.651629658486,0.00025370340306410486,25.0,60.0
103.25952,0.0020497799212598426,546.1954811063499,0.00025370340306410486,25.0,60.0
104.66089,0.0020619133858267714,553.1564731853007,0.00025370340306410486,25.0,60.0
106.06226,0.002087677559055118,560.1064537073107,0.00025370340306410486,25.0,60.0
107.46362,0.0021168978346456694,566.9457732761979,0.00025370340306410486,25.0,60.0
108.86499,0.0021520403543307085,574.586183612518,0.00025370340306410486,25.0,60.0
110.26636,0.0021870299212598423,579.9439553304766,0.00025370340306410486,25.0,60.0
111.66772,0.0022031785433070865,585.592780158421,0.00025370340306410486,25.0,60.0
113.06909,0.002234671653543307,591.1110764835736,0.00025370340306410486,25.0,60.0
114.47046,0.0022706899606299213,597.5558239189716,0.00025370340306410486,25.0,60.0
115.87183,0.002298571850393701,603.4467731463448,0.00025370340306410486,25.0,60.0
117.27319,0.0023345877952755906,609.6043890403844,0.00025370340306410486,25.0,60.0
118.67456,0.0023568110236220473,612.0879106609532,0.00025370340306410486,25.0,60.0
120.07593,0.002365286614173228,616.0479158550838,0.00025370340306410486,25.0,60.0
121.47729,0.002437498228346457,622.5159849370212,0.00025370340306410486,25.0,60.0
122.87866,0.0024580645669291337,626.2887157512012,0.00025370340306410486,25.0,60.0
124.28003,0.002490529133858268,630.4554733151539,0.00025370340306410486,25.0,60.0
125.6814,0.0025449358267716536,635.2712894429295,0.00025370340306410486,25.0,60.0
127.08276,0.002556885433070866,638.1217763926763,0.00025370340306410486,25.0,60.0
128.48413,0.002627226181102362,644.8221010258408,0.00025370340306410486,25.0,60.0
129.8855,0.0026761187007874015,647.1251525775874,0.00025370340306410486,25.0,60.0
131.28687,0.00270413031496063,652.7062459420854,0.00025370340306410486,25.0,60.0
132.68823,0.0027543415354330707,655.3443189196208,0.00025370340306410486,25.0,60.0
134.0896,0.0028063374015748033,658.2045708349566,0.00025370340306410486,25.0,60.0
135.49097,0.0028444379921259842,661.7204518893651,0.00025370340306410486,25.0,60.0
136.89233,0.0029051874015748034,666.3512790546683,0.00025370340306410486,25.0,60.0
138.2937,0.0029818423228346455,670.4902480197377,0.00025370340306410486,25.0,60.0
139.69507,0.00302751968503937,672.8023633294378,0.00025370340306410486,25.0,60.0
141.09644,0.003113030708661417,676.6031684196857,0.00025370340306410486,25.0,60.0
142.4978,0.0031841295275590554,678.935203220361,0.00025370340306410486,25.0,60.0
143.89917,0.0032454200787401574,681.1735099337749,0.00025370340306410486,25.0,60.0
145.30054,0.0033145,684.6074016361513,0.00025370340306410486,25.0,60.0
146.7019,0.003401579724409449,688.3845734320219,0.00025370340306410486,25.0,60.0
148.10327,0.0034868549212598425,691.2372678872874,0.00025370340306410486,25.0,60.0
149.50464,0.0035776643700787397,692.9184521490715,0.00025370340306410486,25.0,60.0
150.90601,0.0036809990157480313,697.9766523828074,0.00025370340306410486,25.0,60.0
152.30737,0.0038286200787401576,700.1307622386704,0.00025370340306410486,25.0,60.0
153.70874,0.003946344094488189,702.63030775224,0.00025370340306410486,25.0,60.0
155.11011,0.004056283858267716,704.9163225555122,0.00025370340306410486,25.0,60.0
156.51147,0.004186395472440945,707.2783274899364,0.00025370340306410486,25.0,60.0
157.91284,0.004328504921259842,710.9296974418907,0.00025370340306410486,25.0,60.0
159.31421,0.0044644832677165356,713.693026879626,0.00025370340306410486,25.0,60.0
160.71558,0.004624535039370078,714.3492533437216,0.00025370340306410486,25.0,60.0
162.11694,0.004793507086614173,717.2800934943515,0.00025370340306410486,25.0,60.0
163.51831,0.0049790811023622044,720.5503700818076,0.00025370340306410486,25.0,60.0
164.91968,0.0051753088582677164,720.7169977924946,0.00025370340306410486,25.0,60.0
166.32104,0.0053865692913385825,723.4313206077132,0.00025370340306410486,25.0,60.0
167.72241,0.0055507279527559055,725.0555512271134,0.00025370340306410486,25.0,60.0
169.12378,0.005744537992125984,725.9668095052591,0.00025370340306410486,25.0,60.0
170.52515,0.005961297834645669,729.1156992598364,0.00025370340306410486,25.0,60.0
171.92651,0.006166070472440945,728.9950915465524,0.00025370340306410486,25.0,60.0
173.32788,0.006393478149606299,731.937280872614,0.00025370340306410486,25.0,60.0
174.72925,0.006591576377952756,733.1829113102195,0.00025370340306410486,25.0,60.0
176.13062,0.006822528149606298,733.3635631736139,0.00025370340306410486,25.0,60.0
177.53198,0.007064370669291339,735.5902869757175,0.00025370340306410486,25.0,60.0
178.93335,0.007348514960629921,738.4235294117647,0.00025370340306410486,25.0,60.0
180.33472,0.00759021220472441,739.9555901830931,0.00025370340306410486,25.0,60.0
181.73608,0.00784364566929134,739.4330087001688,0.00025370340306410486,25.0,60.0
183.13745,0.008108746259842519,742.4312946370601,0.00025370340306410486,25.0,60.0
184.53882,0.00838768622047244,743.354914946111,0.00025370340306410486,25.0,60.0
185.94019,0.008616419685039371,743.6881703674848,0.00025370340306410486,25.0,60.0
187.34155,0.008879604921259842,745.0963251525776,0.00025370340306410486,25.0,60.0
188.74292,0.009160460236220472,746.6758083365797,0.00025370340306410486,25.0,60.0
190.14429,0.009434903346456693,745.947721075185,0.00025370340306410486,25.0,60.0
191.54565,0.009724498622047243,748.9420335021426,0.00025370340306410486,25.0,60.0
192.94702,0.009999661811023621,751.0667965199325,0.00025370340306410486,25.0,60.0
194.34839,0.010299645866141733,751.803999480587,0.00025370340306410486,25.0,60.0
195.74976,0.010571108858267717,751.5432800934943,0.00025370340306410486,25.0,60.0
197.15112,0.010860496456692913,753.0245942085444,0.00025370340306410486,25.0,60.0
198.55249,0.011154292125984252,754.8249837683418,0.00025370340306410486,25.0,60.0
199.95386,0.011445063385826772,753.7477470458382,0.00025370340306410486,25.0,60.0
201.35522,0.011745857086614174,757.0194260485652,0.00025370340306410486,25.0,60.0
202.75659,0.012060395669291337,758.4892091936113,0.00025370340306410486,25.0,60.0
204.15796,0.012389392913385828,757.9550967406831,0.00025370340306410486,25.0,60.0
205.55933,0.01273230157480315,760.1993767043241,0.00025370340306410486,25.0,60.0
206.96069,0.013093156102362205,760.1235423970913,0.00025370340306410486,25.0,60.0
208.36206,0.013356796653543307,761.7061420594729,0.00025370340306410486,25.0,60.0
209.76343,0.01367125374015748,762.1705752499676,0.00025370340306410486,25.0,60.0
211.16479,0.013937912598425197,762.4787170497339,0.00025370340306410486,25.0,60.0
212.56616,0.014232173818897638,764.0175561615375,0.00025370340306410486,25.0,60.0
213.96753,0.01457260374015748,765.3285287624984,0.00025370340306410486,25.0,60.0
215.3689,0.014883290157480316,765.7750681729646,0.00025370340306410486,25.0,60.0
216.77026,0.015128909842519684,764.7501363459291,0.00025370340306410486,25.0,60.0
218.17163,0.015367599803149607,766.1465004544864,0.00025370340306410486,25.0,60.0
219.573,0.015761305708661418,770.3777691208934,0.00025370340306410486,25.0,60.0
220.97437,0.016108875393700785,769.2851058304117,0.00025370340306410486,25.0,60.0
222.37573,0.016387195669291338,768.7492014024153,0.00025370340306410486,25.0,60.0
223.7771,0.016697587204724407,770.4949487079601,0.00025370340306410486,25.0,60.0
225.17847,0.01701354744094488,771.1913777431503,0.00025370340306410486,25.0,60.0
226.57983,0.017310822637795275,771.959407869108,0.00025370340306410486,25.0,60.0
227.9812,0.017617317322834645,774.0598883261915,0.00025370340306410486,25.0,60.0
229.38257,0.017969364566929134,773.3515907025062,0.00025370340306410486,25.0,60.0
230.78394,0.018315058267716535,775.9362160758344,0.00025370340306410486,25.0,60.0
232.1853,0.018650978346456692,774.6856771847813,0.00025370340306410486,25.0,60.0
233.58667,0.018947644881889762,776.5317750941437,0.00025370340306410486,25.0,60.0
234.98804,0.019345533661417322,776.7987274379951,0.00025370340306410486,25.0,60.0
236.3894,0.019647166338582676,776.6956758862486,0.00025370340306410486,25.0,60.0
237.79077,0.019969159448818895,778.6657317231528,0.00025370340306410486,25.0,60.0
239.19214,0.020266330708661417,778.4680431112843,0.00025370340306410486,25.0,60.0
240.59351,0.0205981437007874,780.9303207375666,0.00025370340306410486,25.0,60.0
241.99487,0.020942604330708662,779.7524996753668,0.00025370340306410486,25.0,60.0
243.39624,0.021257942913385827,780.843137254902,0.00025370340306410486,25.0,60.0
244.79761,0.02160412401574803,781.957018569017,0.00025370340306410486,25.0,60.0
246.19897,0.021935759842519685,782.1850409037787,0.00025370340306410486,25.0,60.0
247.60034,0.022226854330708663,782.3735878457344,0.00025370340306410486,25.0,60.0
249.00171,0.02255003937007874,781.8403583950136,0.00025370340306410486,25.0,60.0
250.40308,0.022836411417322833,783.4568757304246,0.00025370340306410486,25.0,60.0
251.80444,0.02312990157480315,783.2405401895858,0.00025370340306410486,25.0,60.0
253.20581,0.023424667322834644,784.9373847552267,0.00025370340306410486,25.0,60.0
254.60718,0.023738952755905512,785.575613556681,0.00025370340306410486,25.0,60.0
256.00854,0.024125891732283463,787.0133748863784,0.00025370340306410486,25.0,60.0
257.40991,0.024464206692913385,788.5349175431763,0.00025370340306410486,25.0,60.0
258.81128,0.024789513779527556,788.1040124659136,0.00025370340306410486,25.0,60.0
260.21265,0.0250705905511811,788.9097000389561,0.00025370340306410486,25.0,60.0
261.61401,0.025396246062992126,789.10808985846,0.00025370340306410486,25.0,60.0
263.01538,0.025685375984251968,789.3120633683938,0.00025370340306410486,25.0,60.0
264.41675,0.02604288188976378,791.5191793273601,0.00025370340306410486,25.0,60.0
265.81812,0.026403082677165356,792.4442539929879,0.00025370340306410486,25.0,60.0
267.21948,0.026729769685039373,791.9618750811584,0.00025370340306410486,25.0,60.0
268.62085,0.027047828740157483,794.0427736657576,0.00025370340306410486,25.0,60.0
270.02222,0.027364265748031497,792.3249448123621,0.00025370340306410486,25.0,60.0
271.42358,0.02768666929133858,792.9335670692119,0.00025370340306410486,25.0,60.0
272.82495,0.028015572834645668,796.2422802233476,0.00025370340306410486,25.0,60.0
274.22632,0.028390179133858266,796.0816257628879,0.00025370340306410486,25.0,60.0
275.62769,0.02864133464566929,794.7041423191794,0.00025370340306410486,25.0,60.0
277.02905,0.028946852362204727,797.6692637319828,0.00025370340306410486,25.0,60.0
278.43042,0.029359364173228347,797.9352551616674,0.00025370340306410486,25.0,60.0
279.83179,0.029694643700787404,797.4036099207896,0.00025370340306410486,25.0,60.0
281.23315,0.030001549212598424,799.1530710297365,0.00025370340306410486,25.0,60.0
282.63452,0.03033608070866142,798.9868328788469,0.00025370340306410486,25.0,60.0
284.03589,0.03063149803149606,798.2936761459551,0.00025370340306410486,25.0,60.0
285.43726,0.030940490157480315,799.4481495909622,0.00025370340306410486,25.0,60.0
286.83862,0.03124602559055118,800.0600181794573,0.00025370340306410486,25.0,60.0
288.23999,0.031515706692913384,799.6345149980522,0.00025370340306410486,25.0,60.0
289.64136,0.031806637795275594,800.8537332813921,0.00025370340306410486,25.0,60.0
291.04272,0.032160354330708664,802.2663290481755,0.00025370340306410486,25.0,60.0
292.44409,0.032523456692913386,803.1457992468512,0.00025370340306410486,25.0,60.0
293.84546,0.032868007874015746,804.0744318919621,0.00025370340306410486,25.0,60.0
295.24683,0.033182856299212596,804.5025581093364,0.00025370340306410486,25.0,60.0
296.64819,0.03351250393700787,805.4894429294898,0.00025370340306410486,25.0,60.0
298.04956,0.033835779527559055,805.0386962732114,0.00025370340306410486,25.0,60.0
299.45093,0.0341268937007874,805.4039735099338,0.00025370340306410486,25.0,60.0
300.85229,0.03443124803149607,806.954914946111,0.00025370340306410486,25.0,60.0
302.25366,0.034768204724409446,806.8737047136736,0.00025370340306410486,25.0,60.0
303.65503,0.03506885826771654,806.8130892091937,0.00025370340306410486,25.0,60.0
305.0564,0.03537037795275591,809.7984417608104,0.00025370340306410486,25.0,60.0
306.45776,0.0357230531496063,809.3496688741723,0.00025370340306410486,25.0,60.0
307.85913,0.03606219094488189,808.1304505908323,0.00025370340306410486,25.0,60.0
309.2605,0.03639660039370079,808.9935073367096,0.00025370340306410486,25.0,60.0
310.66187,0.036724858267716536,809.0691598493703,0.00025370340306410486,25.0,60.0
312.06323,0.0371061062992126,811.8388261264771,0.00025370340306410486,25.0,60.0
313.4646,0.037422942913385826,810.2626412154266,0.00025370340306410486,25.0,60.0
314.86597,0.03771090551181103,810.1304246201793,0.00025370340306410486,25.0,60.0
316.26733,0.03801533267716535,811.1045318789768,0.00025370340306410486,25.0,60.0
317.6687,0.03836194291338583,811.7393844955201,0.00025370340306410486,25.0,60.0
319.07007,0.03867265157480315,812.5854824048826,0.00025370340306410486,25.0,60.0
320.47144,0.039007828740157485,814.7287365277236,0.00025370340306410486,25.0,60.0
321.8728,0.03933921850393701,813.8809505259057,0.00025370340306410486,25.0,60.0
323.27417,0.039597580708661415,814.7673029476692,0.00025370340306410486,25.0,60.0
324.67554,0.03990029724409449,815.0026490066225,0.00025370340306410486,25.0,60.0
326.0769,0.040239265748031494,817.4170627191273,0.00025370340306410486,25.0,60.0
327.47827,0.0406110905511811,818.3260875211012,0.00025370340306410486,25.0,60.0
328.87964,0.04098439960629921,818.1783664459161,0.00025370340306410486,25.0,60.0
330.28101,0.04132077559055118,816.6852356836774,0.00025370340306410486,25.0,60.0
331.68237,0.04159056299212598,816.4610829762369,0.00025370340306410486,25.0,60.0
333.08374,0.04194267913385827,818.8158940397352,0.00025370340306410486,25.0,60.0
334.48511,0.04228514173228346,819.2541488118427,0.00025370340306410486,25.0,60.0
335.88647,0.042611687007874016,820.0733411245293,0.00025370340306410486,25.0,60.0
337.28784,0.04289377362204724,820.1572782755487,0.00025370340306410486,25.0,60.0
338.68921,0.04321211811023622,820.7872224386444,0.00025370340306410486,25.0,60.0
340.09058,0.043509940944881885,821.9538501493313,0.00025370340306410486,25.0,60.0
341.49194,0.043880517716535436,821.7716919880536,0.00025370340306410486,25.0,60.0
342.89331,0.04425842913385827,823.2814439683159,0.00025370340306410486,25.0,60.0
344.29468,0.04462169488188976,822.9632774964291,0.00025370340306410486,25.0,60.0
345.69604,0.04492700590551181,822.4937021166083,0.00025370340306410486,25.0,60.0
347.09741,0.04523019291338583,823.4189585768082,0.00025370340306410486,25.0,60.0
348.49878,0.0455204311023622,824.1284508505389,0.00025370340306410486,25.0,60.0
349.90015,0.04587711220472441,825.8156603038566,0.00025370340306410486,25.0,60.0
351.30151,0.04622202362204724,825.7792754187769,0.00025370340306410486,25.0,60.0
352.70288,0.0465626062992126,825.9594078691078,0.00025370340306410486,25.0,60.0
354.10425,0.04690377165354331,825.9088170367485,0.00025370340306410486,25.0,60.0
355.50562,0.04720804527559055,825.9154135826517,0.00025370340306410486,25.0,60.0
356.90698,0.047530562992125984,826.9157512011427,0.00025370340306410486,25.0,60.0
358.30835,0.0478661437007874,827.6278405401896,0.00025370340306410486,25.0,60.0
359.70972,0.04814313188976378,827.4745357745747,0.00025370340306410486,25.0,60.0
361.11108,0.04841919094488189,827.4322295805739,0.00025370340306410486,25.0,60.0
362.51245,0.04872861614173229,828.3339825996625,0.00025370340306410486,25.0,60.0
363.91382,0.04904460039370079,828.3398259966239,0.00025370340306410486,25.0,60.0
365.31519,0.04932887992125984,828.4745617452279,0.00025370340306410486,25.0,60.0
366.71655,0.049650405511811026,830.8226983508636,0.00025370340306410486,25.0,60.0
368.11792,0.049983868110236224,832.1110245422674,0.00025370340306410486,25.0,60.0
369.51929,0.05033717322834646,831.5212829502663,0.00025370340306410486,25.0,60.0
370.92065,0.05067465551181102,832.0501493312557,0.00025370340306410486,25.0,60.0
372.32202,0.05104422637795276,832.9693286586157,0.00025370340306410486,25.0,60.0
373.72339,0.05138339763779527,831.7245033112582,0.00025370340306410486,25.0,60.0
375.12476,0.05168555118110236,833.2608492403584,0.00025370340306410486,25.0,60.0
376.52612,0.05202587401574803,835.1893260615504,0.00025370340306410486,25.0,60.0
377.92749,0.052351181102362206,835.2155044799377,0.00025370340306410486,25.0,60.0
379.32886,0.0526575,834.5472795740814,0.00025370340306410486,25.0,60.0
380.73022,0.05296853543307087,836.0837034151409,0.00025370340306410486,25.0,60.0
382.13159,0.053267240157480314,836.4901441371251,0.00025370340306410486,25.0,60.0
383.53296,0.05363883070866142,837.87071808856,0.00025370340306410486,25.0,60.0
384.93433,0.0539864842519685,836.7013374886378,0.00025370340306410486,25.0,60.0
386.33569,0.054281809055118105,836.5208933904688,0.00025370340306410486,25.0,60.0
387.73706,0.054635635826771646,839.5052850279185,0.00025370340306410486,25.0,60.0
389.13843,0.0549961968503937,839.0544864303338,0.00025370340306410486,25.0,60.0
390.53979,0.05533108070866142,837.518997532788,0.00025370340306410486,25.0,60.0
391.94116,0.05560779527559055,837.9477470458382,0.00025370340306410486,25.0,60.0
393.34253,0.05590354921259843,839.180911569926,0.00025370340306410486,25.0,60.0
394.7439,0.05622911023622047,838.5616932865862,0.00025370340306410486,25.0,60.0
396.14526,0.0565571811023622,839.0251395922608,0.00025370340306410486,25.0,60.0
397.54663,0.05691255708661417,843.2911310219453,0.00025370340306410486,25.0,60.0
398.948,0.05723352952755906,840.3456693935854,0.00025370340306410486,25.0,60.0
400.34937,0.05756907480314961,841.4480197376965,0.00025370340306410486,25.0,60.0
401.75073,0.057835413385826775,839.7830671341385,0.00025370340306410486,25.0,60.0
403.1521,0.05815359448818897,843.7028178158681,0.00025370340306410486,25.0,60.0
404.55347,0.05850586023622047,843.9539800025971,0.00025370340306410486,25.0,60.0
405.95483,0.058797129921259836,843.0967926243345,0.00025370340306410486,25.0,60.0
407.3562,0.05913834448818898,843.4740683028178,0.00025370340306410486,25.0,60.0
408.75757,0.05946701377952756,842.5500584339696,0.00025370340306410486,25.0,60.0
410.15894,0.059772541338582674,842.8999350733671,0.00025370340306410486,25.0,60.0
411.5603,0.06011557283464567,846.4391897156214,0.00025370340306410486,25.0,60.0
412.96167,0.06051940551181103,845.3559278015842,0.00025370340306410486,25.0,60.0
414.36304,0.060864984251968506,847.163277496429,0.00025370340306410486,25.0,60.0
415.7644,0.06120848425196851,846.5360862225685,0.00025370340306410486,25.0,60.0
417.16577,0.06154513385826771,848.6156343332036,0.00025370340306410486,25.0,60.0
418.56714,0.06190890354330709,848.7686274509804,0.00025370340306410486,25.0,60.0
419.96851,0.06217950590551181,846.2911310219451,0.00025370340306410486,25.0,60.0
421.36987,0.06245762992125984,846.5668874172186,0.00025370340306410486,25.0,60.0
422.77124,0.06282946062992126,850.4019477989872,0.00025370340306410486,25.0,60.0
424.17261,0.06320236023622047,848.6586157641866,0.00025370340306410486,25.0,60.0
425.57397,0.06350558070866141,848.1329178028827,0.00025370340306410486,25.0,60.0
426.97534,0.06379452362204724,848.7154395533048,0.00025370340306410486,25.0,60.0
428.37671,0.0641000846456693,850.4002856771848,0.00025370340306410486,25.0,60.0
429.77808,0.0644379311023622,849.6392416569277,0.00025370340306410486,25.0,60.0
431.17944,0.06468049015748031,849.5192052980133,0.00025370340306410486,25.0,60.0
432.58081,0.06497105708661417,852.212336060252,0.00025370340306410486,25.0,60.0
433.98218,0.06527382677165354,852.831112842488,0.00025370340306410486,25.0,60.0
435.38354,0.0655934153543307,853.0260225944683,0.00025370340306410486,25.0,60.0
436.78491,0.06593635433070866,851.6478379431243,0.00025370340306410486,25.0,60.0
438.18628,0.06625196456692913,852.3734579924685,0.00025370340306410486,25.0,60.0
439.58765,0.06657141338582677,855.8803012595768,0.00025370340306410486,25.0,60.0
440.98901,0.06696255118110236,855.3523438514479,0.00025370340306410486,25.0,60.0
442.39038,0.0673148877952756,853.812985326581,0.00025370340306410486,25.0,60.0
443.79175,0.06770326771653543,856.75605765485,0.00025370340306410486,25.0,60.0
445.19312,0.06808295866141732,856.1537722373719,0.00025370340306410486,25.0,60.0
446.59448,0.06841771456692913,854.8852876249838,0.00025370340306410486,25.0,60.0
447.99585,0.06879937598425197,855.0046227762629,0.00025370340306410486,25.0,60.0
449.39722,0.06907126968503936,856.456927671731,0.00025370340306410486,25.0,60.0
450.79858,0.06943633661417323,856.9798208024932,0.00025370340306410486,25.0,60.0
452.19995,0.06974240354330707,857.6172185430463,0.00025370340306410486,25.0,60.0
453.60132,0.07003491732283464,856.8092455525257,0.00025370340306410486,25.0,60.0
455.00269,0.0703315216535433,857.883391767303,0.00025370340306410486,25.0,60.0
456.40405,0.07064757283464566,858.3302687962603,0.00025370340306410486,25.0,60.0
457.80542,0.0710118937007874,861.3012336060252,0.00025370340306410486,25.0,60.0
459.20679,0.07134025984251968,858.1081677704195,0.00025370340306410486,25.0,60.0
460.60815,0.07165763582677165,859.04041033632,0.00025370340306410486,25.0,60.0
462.00952,0.07199186220472441,858.8508245682378,0.00025370340306410486,25.0,60.0
463.41089,0.07230616535433071,859.7050772626933,0.00025370340306410486,25.0,60.0
464.81226,0.07264917322834645,859.5190494740943,0.00025370340306410486,25.0,60.0
466.21362,0.07299035826771653,860.3596675756395,0.00025370340306410486,25.0,60.0
467.61499,0.07330129330708661,861.4564601999741,0.00025370340306410486,25.0,60.0
469.01636,0.07364425393700788,862.8233476171927,0.00025370340306410486,25.0,60.0
470.41772,0.07400476968503937,861.5563173613816,0.00025370340306410486,25.0,60.0
471.81909,0.0743691968503937,864.4185430463576,0.00025370340306410486,25.0,60.0
473.22046,0.07468493110236221,861.9871445266848,0.00025370340306410486,25.0,60.0
474.62183,0.07501492716535434,863.5729126087522,0.00025370340306410486,25.0,60.0
476.02319,0.07539650196850393,864.7843916374497,0.00025370340306410486,25.0,60.0
477.42456,0.07573329724409449,864.1862874951306,0.00025370340306410486,25.0,60.0
478.82593,0.07604500787401575,863.2077132839892,0.00025370340306410486,25.0,60.0
480.22729,0.07635302165354331,864.2638358654721,0.00025370340306410486,25.0,60.0
481.62866,0.07667989763779527,865.3105310998573,0.00025370340306410486,25.0,60.0
483.03003,0.07699260433070866,866.8418906635502,0.00025370340306410486,25.0,60.0
484.4314,0.07735358858267717,865.2239709128685,0.00025370340306410486,25.0,60.0
485.83276,0.07778363385826771,867.1760810284378,0.00025370340306410486,25.0,60.0
487.23413,0.07809336023622047,864.8135566809506,0.00025370340306410486,25.0,60.0
488.6355,0.07841394094488188,865.6108037917154,0.00025370340306410486,25.0,60.0
490.03687,0.07868417913385826,866.0619400077912,0.00025370340306410486,25.0,60.0
491.43823,0.07901695669291339,867.9106349824699,0.00025370340306410486,25.0,60.0
492.8396,0.07935561811023621,868.4650564861706,0.00025370340306410486,25.0,60.0
494.24097,0.07969742322834646,867.8515517465265,0.00025370340306410486,25.0,60.0
495.64233,0.08007559645669292,868.9348136605637,0.00025370340306410486,25.0,60.0
497.0437,0.08044089763779527,869.7427087391249,0.00025370340306410486,25.0,60.0
498.44507,0.08078960826771654,870.732476301779,0.00025370340306410486,25.0,60.0
499.84644,0.08112236811023622,870.796623815089,0.00025370340306410486,25.0,60.0
501.2478,0.08146896653543306,870.0034281262174,0.00025370340306410486,25.0,60.0
502.64917,0.08176895472440944,870.182677574341,0.00025370340306410486,25.0,60.0
504.05054,0.08205329133858268,870.0229580573952,0.00025370340306410486,25.0,60.0
505.4519,0.08237287401574803,872.0520451889366,0.00025370340306410486,25.0,60.0
506.85327,0.0827258090551181,871.8464355278536,0.00025370340306410486,25.0,60.0
508.25464,0.08311743307086614,872.6736787430204,0.00025370340306410486,25.0,60.0
509.65601,0.08343674606299212,873.3012595766784,0.00025370340306410486,25.0,60.0
511.05737,0.08380112598425198,872.7298532658097,0.00025370340306410486,25.0,60.0
512.45874,0.08418133464566929,873.3881833528114,0.00025370340306410486,25.0,60.0
513.86011,0.08454136811023621,873.7941566030387,0.00025370340306410486,25.0,60.0
515.26147,0.08488643503937007,873.1865472016622,0.00025370340306410486,25.0,60.0
516.66284,0.08521374015748032,873.449552006233,0.00025370340306410486,25.0,60.0
518.06421,0.08553478937007875,874.6480976496559,0.00025370340306410486,25.0,60.0
519.46558,0.08590922440944883,875.5300090897287,0.00025370340306410486,25.0,60.0
520.86694,0.08628441732283465,876.5816387482146,0.00025370340306410486,25.0,60.0
522.26831,0.08664672637795276,874.1645760290871,0.00025370340306410486,25.0,60.0
523.66968,0.08698451377952757,875.6985326580964,0.00025370340306410486,25.0,60.0
525.07104,0.0872971968503937,875.5629139072848,0.00025370340306410486,25.0,60.0
526.47241,0.08761778937007875,877.6966627710688,0.00025370340306410486,25.0,60.0
527.87378,0.08799190157480315,877.4917543176211,0.00025370340306410486,25.0,60.0
529.27515,0.08832984842519684,876.4256070640178,0.00025370340306410486,25.0,60.0
530.67651,0.08865972637795275,878.0928191144008,0.00025370340306410486,25.0,60.0
532.07788,0.08904472834645669,877.5393585248669,0.00025370340306410486,25.0,60.0
533.47925,0.08940701968503936,878.3714322815218,0.00025370340306410486,25.0,60.0
534.88062,0.08973104330708662,878.7372808726141,0.00025370340306410486,25.0,60.0
536.28198,0.09007015748031495,880.0735229191015,0.00025370340306410486,25.0,60.0
537.68335,0.0904801437007874,880.6669523438514,0.00025370340306410486,25.0,60.0
539.08472,0.09079838385826772,878.1912219192313,0.00025370340306410486,25.0,60.0
540.48608,0.09112068897637796,880.0785352551617,0.00025370340306410486,25.0,60.0
541.88745,0.09149297047244094,879.7308401506299,0.00025370340306410486,25.0,60.0
543.28882,0.09179406299212597,879.0866900402546,0.00025370340306410486,25.0,60.0
544.69019,0.0920578720472441,878.8534995455136,0.00025370340306410486,25.0,60.0
546.09155,0.09236446062992126,880.4847162706143,0.00025370340306410486,25.0,60.0
547.49292,0.09275176181102361,882.0720685625245,0.00025370340306410486,25.0,60.0
548.89429,0.09314956299212598,881.0277106869238,0.00025370340306410486,25.0,60.0
550.29565,0.09350638188976378,882.4948448253474,0.00025370340306410486,25.0,60.0
551.69702,0.09387038188976378,881.4791585508376,0.00025370340306410486,25.0,60.0
553.09839,0.09419359645669291,882.7364238410596,0.00025370340306410486,25.0,60.0
554.49976,0.0946285157480315,885.0924035839502,0.00025370340306410486,25.0,60.0
555.90112,0.09499154724409449,885.0541228411895,0.00025370340306410486,25.0,60.0
557.30249,0.0953758031496063,883.3329178028828,0.00025370340306410486,25.0,60.0
558.70386,0.09574116338582676,883.672328269056,0.00025370340306410486,25.0,60.0
560.10522,0.09610461023622047,884.4640176600442,0.00025370340306410486,25.0,60.0
561.50659,0.09649975590551181,884.7996623815089,0.00025370340306410486,25.0,60.0
562.90796,0.09689235433070865,884.9903389170238,0.00025370340306410486,25.0,60.0
564.30933,0.09722829330708661,885.9017270484353,0.00025370340306410486,25.0,60.0
565.71069,0.09754499606299212,883.6310609011817,0.00025370340306410486,25.0,60.0
567.11206,0.09784859842519684,886.1507077002988,0.00025370340306410486,25.0,60.0
568.51343,0.098227,886.1154395533049,0.00025370340306410486,25.0,60.0
569.91479,0.09855259645669291,885.8946890014283,0.00025370340306410486,25.0,60.0
571.31616,0.0988913090551181,886.488845604467,0.00025370340306410486,25.0,60.0
572.71753,0.09922874409448819,886.8258927412026,0.00025370340306410486,25.0,60.0
574.1189,0.09955185433070866,885.6616543306066,0.00025370340306410486,25.0,60.0
575.52026,0.09985568503937008,885.8253733281393,0.00025370340306410486,25.0,60.0
576.92163,0.10019516141732283,887.3000389559797,0.00025370340306410486,25.0,60.0
578.323,0.10056583661417322,888.7787040644073,0.00025370340306410486,25.0,60.0
579.72437,0.10095651771653542,889.5450201272562,0.00025370340306410486,25.0,60.0
581.12573,0.10138301771653542,888.9769120893391,0.00025370340306410486,25.0,60.0
582.5271,0.1017201712598425,888.4722763277497,0.00025370340306410486,25.0,60.0
583.92847,0.10202684251968504,888.021971172575,0.00025370340306410486,25.0,60.0
585.32983,0.10237073031496063,888.905518763797,0.00025370340306410486,25.0,60.0
586.7312,0.10274558267716535,889.4139722114012,0.00025370340306410486,25.0,60.0
588.13257,0.10314581496062991,891.1218283339826,0.00025370340306410486,25.0,60.0
589.53394,0.10350525000000001,891.2299441630958,0.00025370340306410486,25.0,60.0
590.9353,0.10390594881889764,890.3502142578886,0.00025370340306410486,25.0,60.0
592.33667,0.10427525196850393,892.8087261394625,0.00025370340306410486,25.0,60.0
593.73804,0.10469779921259843,890.3104531878978,0.00025370340306410486,25.0,60.0
595.1394,0.10504032677165354,892.5261914037138,0.00025370340306410486,25.0,60.0
596.54077,0.1053751811023622,890.0435008440463,0.00025370340306410486,25.0,60.0
597.94214,0.10573391141732283,892.8006232956759,0.00025370340306410486,25.0,60.0
599.34351,0.10611019488188976,893.9114660433711,0.00025370340306410486,25.0,60.0
600.74487,0.10646488976377953,892.702454226724,0.00025370340306410486,25.0,60.0
602.14624,0.10681639173228347,892.0223087910662,0.00025370340306410486,25.0,60.0
603.54761,0.1071907401574803,893.0941695883653,0.00025370340306410486,25.0,60.0
604.94897,0.10758997440944881,894.3320348006753,0.00025370340306410486,25.0,60.0
606.35034,0.10798506692913386,893.1040124659136,0.00025370340306410486,25.0,60.0
607.75171,0.10835286614173227,893.2212959355928,0.00025370340306410486,25.0,60.0
609.15308,0.10871918897637795,894.6078431372549,0.00025370340306410486,25.0,60.0
610.55444,0.10902466338582678,893.0869497467861,0.00025370340306410486,25.0,60.0
611.95581,0.10941321850393701,894.3048954681211,0.00025370340306410486,25.0,60.0
613.35718,0.10978824803149605,896.5701597195169,0.00025370340306410486,25.0,60.0
614.75854,0.11014400984251968,893.185404492923,0.00025370340306410486,25.0,60.0
616.15991,0.1104920275590551,893.8177639267628,0.00025370340306410486,25.0,60.0
617.56128,0.11082282283464566,895.0940916764057,0.00025370340306410486,25.0,60.0
618.96265,0.1112190748031496,896.2377353590443,0.00025370340306410486,25.0,60.0
620.36401,0.11159440944881889,896.3962342552916,0.00025370340306410486,25.0,60.0
621.76538,0.11196835826771653,897.9083755356448,0.00025370340306410486,25.0,60.0
623.16675,0.112336968503937,895.3269185820023,0.00025370340306410486,25.0,60.0
624.56812,0.11268461023622046,896.128606674458,0.00025370340306410486,25.0,60.0
625.96948,0.1130411594488189,897.6619400077911,0.00025370340306410486,25.0,60.0
627.37085,0.1134501437007874,897.198701467342,0.00025370340306410486,25.0,60.0
628.77222,0.11384104724409448,897.4879366316064,0.00025370340306410486,25.0,60.0
630.17358,0.11421519488188978,897.5883911180366,0.00025370340306410486,25.0,60.0
631.57495,0.11462788582677164,898.5742111414103,0.00025370340306410486,25.0,60.0
632.97632,0.11497977755905511,897.1385274639658,0.00025370340306410486,25.0,60.0
634.37769,0.11533206692913385,898.5216465394105,0.00025370340306410486,25.0,60.0
635.77905,0.11572573818897638,898.2557070510323,0.00025370340306410486,25.0,60.0
637.18042,0.11619688582677166,899.147695104532,0.00025370340306410486,25.0,60.0
638.58179,0.11658107677165354,899.5747305544735,0.00025370340306410486,25.0,60.0
639.98315,0.11698966141732284,899.8746396571873,0.00025370340306410486,25.0,60.0
641.38452,0.11733617913385826,899.0690040254514,0.00025370340306410486,25.0,60.0
642.78589,0.11772186023622047,899.3131801064798,0.00025370340306410486,25.0,60.0
644.18726,0.11811096850393701,901.4501233606026,0.00025370340306410486,25.0,60.0
645.58862,0.11846637795275591,901.24698091157,0.00025370340306410486,25.0,60.0
646.98999,0.11880450590551182,901.1110245422673,0.00025370340306410486,25.0,60.0
648.39136,0.11918827559055117,901.9962342552916,0.00025370340306410486,25.0,60.0
649.79272,0.11955744881889763,900.4243604726659,0.00025370340306410486,25.0,60.0
651.19409,0.1198989901574803,902.04041033632,0.00025370340306410486,25.0,60.0
652.59546,0.12030378543307087,901.9144266978315,0.00025370340306410486,25.0,60.0
653.99683,0.12065756496062992,900.6321256979613,0.00025370340306410486,25.0,60.0
655.39819,0.12107347244094487,901.8988443059344,0.00025370340306410486,25.0,60.0
656.79956,0.12142992716535433,901.3115179846774,0.00025370340306410486,25.0,60.0
658.20093,0.12180853346456692,901.9951434878589,0.00025370340306410486,25.0,60.0
659.60229,0.12226125787401575,903.5339306583561,0.00025370340306410486,25.0,60.0
661.00366,0.12266615944881891,901.9243994286456,0.00025370340306410486,25.0,60.0
662.40503,0.12298875196850395,902.7787040644072,0.00025370340306410486,25.0,60.0
663.8064,0.12344656889763779,904.2981950396053,0.00025370340306410486,25.0,60.0
665.20776,0.12382307677165354,901.8803791715362,0.00025370340306410486,25.0,60.0
666.60913,0.12421561023622046,903.9884690299962,0.00025370340306410486,25.0,60.0
668.0105,0.12461659251968503,904.1798208024933,0.00025370340306410486,25.0,60.0
669.41187,0.12497331692913387,903.4071679002727,0.00025370340306410486,25.0,60.0
670.81323,0.1253799311023622,903.4104661732242,0.00025370340306410486,25.0,60.0
672.2146,0.12577877755905512,905.3258797558759,0.00025370340306410486,25.0,60.0
673.61597,0.12616817913385828,903.7856382288015,0.00025370340306410486,25.0,60.0
675.01733,0.12658224409448818,906.1946500454486,0.00025370340306410486,25.0,60.0
676.4187,0.1269868149606299,904.6154785092846,0.00025370340306410486,25.0,60.0
677.82007,0.12734819881889764,904.5637969094923,0.00025370340306410486,25.0,60.0
679.22144,0.12773729527559055,906.844098169069,0.00025370340306410486,25.0,60.0
680.6228,0.12812244881889764,906.4738865082458,0.00025370340306410486,25.0,60.0
682.02417,0.12849708858267717,905.987637969095,0.00025370340306410486,25.0,60.0
683.42554,0.12889960826771654,906.0622516556292,0.00025370340306410486,25.0,60.0
684.8269,0.12926908661417325,906.5590442799636,0.00025370340306410486,25.0,60.0
686.22827,0.12968805511811024,907.4870276587457,0.00025370340306410486,25.0,60.0
687.62964,0.13004269094488188,906.1954031943905,0.00025370340306410486,25.0,60.0
689.03101,0.13040250196850395,906.4636800415531,0.00025370340306410486,25.0,60.0
690.43237,0.130807531496063,907.3607323724192,0.00025370340306410486,25.0,60.0
691.83374,0.1312622874015748,908.7143487858721,0.00025370340306410486,25.0,60.0
693.23511,0.13164116338582676,906.9144786391378,0.00025370340306410486,25.0,60.0
694.63647,0.13203832086614173,907.9510193481366,0.00025370340306410486,25.0,60.0
696.03784,0.1324114842519685,907.6174522789248,0.00025370340306410486,25.0,60.0
697.43921,0.13284157677165354,907.1312556810803,0.00025370340306410486,25.0,60.0
698.84058,0.1332611909448819,907.38233995585,0.00025370340306410486,25.0,60.0
700.24194,0.13366646653543307,908.3389429944164,0.00025370340306410486,25.0,60.0
701.64331,0.13407892322834644,909.7674587715882,0.00025370340306410486,25.0,60.0
703.04468,0.1344847874015748,908.9458511881575,0.00025370340306410486,25.0,60.0
704.44604,0.1348653405511811,909.3003506038177,0.00025370340306410486,25.0,60.0
705.84741,0.13526505511811024,909.4102843786521,0.00025370340306410486,25.0,60.0
707.24878,0.13567104724409448,909.9286845864175,0.00025370340306410486,25.0,60.0
708.65015,0.136104531496063,910.267835346059,0.00025370340306410486,25.0,60.0
710.05151,0.1365470964566929,909.5889624724063,0.00025370340306410486,25.0,60.0
711.45288,0.1369596122047244,909.7962342552916,0.00025370340306410486,25.0,60.0
712.85425,0.1374167125984252,909.1445526554993,0.00025370340306410486,25.0,60.0
714.25562,0.13783445078740156,909.983794312427,0.00025370340306410486,25.0,60.0
715.65698,0.13824906692913386,910.689494870796,0.00025370340306410486,25.0,60.0
717.05835,0.13862578346456694,910.5608881963382,0.00025370340306410486,25.0,60.0
718.45972,0.13902039566929134,909.6740683028178,0.00025370340306410486,25.0,60.0
719.86108,0.1393623937007874,910.4389040384366,0.00025370340306410486,25.0,60.0
721.26245,0.1397640688976378,910.5678223607324,0.00025370340306410486,25.0,60.0
722.66382,0.1402033248031496,911.4502791845215,0.00025370340306410486,25.0,60.0
724.06519,0.14060099803149606,913.0109855862876,0.00025370340306410486,25.0,60.0
725.46655,0.14102043503937006,912.1034151408909,0.00025370340306410486,25.0,60.0
726.86792,0.14143018307086613,911.1460589533827,0.00025370340306410486,25.0,60.0
728.26929,0.14187249999999998,913.469912998312,0.00025370340306410486,25.0,60.0
729.67065,0.14230913976377954,911.9925204518894,0.00025370340306410486,25.0,60.0
731.07202,0.1427229468503937,913.0860667445787,0.00025370340306410486,25.0,60.0
732.47339,0.14314847440944883,912.3032593169719,0.00025370340306410486,25.0,60.0
733.87476,0.14357308661417323,912.052123100896,0.00025370340306410486,25.0,60.0
735.27612,0.14400723818897637,913.1689390988184,0.00025370340306410486,25.0,60.0
736.67749,0.14448019291338585,913.3153356706921,0.00025370340306410486,25.0,60.0
738.07886,0.14487278543307086,913.1303726788728,0.00025370340306410486,25.0,60.0
739.48022,0.14525703543307086,911.7194390338917,0.00025370340306410486,25.0,60.0
740.88159,0.14566366141732282,912.8949746786133,0.00025370340306410486,25.0,60.0
742.28296,0.1460872066929134,914.3612517854824,0.00025370340306410486,25.0,60.0
743.68433,0.1465486496062992,915.7037267887288,0.00025370340306410486,25.0,60.0
745.08569,0.1470258031496063,914.5009998701468,0.00025370340306410486,25.0,60.0
746.48706,0.14743573818897637,911.6281262173744,0.00025370340306410486,25.0,60.0
747.88843,0.14785656102362205,914.2043370990781,0.00025370340306410486,25.0,60.0
749.28979,0.1482614842519685,913.1043760550577,0.00025370340306410486,25.0,60.0
750.69116,0.14877680708661417,914.5715101934815,0.00025370340306410486,25.0,60.0
752.09253,0.14919733661417323,914.3824957797689,0.00025370340306410486,25.0,60.0
753.4939,0.14962407283464565,912.8074016361512,0.00025370340306410486,25.0,60.0
754.89526,0.1499919094488189,912.4926632904818,0.00025370340306410486,25.0,60.0
756.29663,0.15043522440944881,914.9720555771978,0.00025370340306410486,25.0,60.0
757.698,0.15093557480314962,915.5813530710298,0.00025370340306410486,25.0,60.0
759.09937,0.15139674803149608,915.4555771977665,0.00025370340306410486,25.0,60.0
760.50073,0.1517684094488189,914.2108037917154,0.00025370340306410486,25.0,60.0
761.9021,0.15216922637795277,915.5816127775614,0.00025370340306410486,25.0,60.0
763.30347,0.15265202362204724,915.2275029216986,0.00025370340306410486,25.0,60.0
764.70483,0.15304474606299212,915.5310219452019,0.00025370340306410486,25.0,60.0
766.1062,0.1535199881889764,916.6255291520582,0.00025370340306410486,25.0,60.0
767.50757,0.15393425196850394,915.7968835216207,0.00025370340306410486,25.0,60.0
768.90894,0.15440125590551182,916.2526425139592,0.00025370340306410486,25.0,60.0
770.3103,0.15495024015748032,917.0039735099339,0.00025370340306410486,25.0,60.0
771.71167,0.15544273031496061,915.8302298402806,0.00025370340306410486,25.0,60.0
773.11304,0.15584510826771653,914.6472146474484,0.00025370340306410486,25.0,60.0
774.5144,0.15625615748031496,917.5323983898196,0.00025370340306410486,25.0,60.0
775.91577,0.15667889370078739,915.9626282301,0.00025370340306410486,25.0,60.0
777.31714,0.15716897637795274,916.3561095961564,0.00025370340306410486,25.0,60.0
778.71851,0.1575760846456693,915.4178418387223,0.00025370340306410486,25.0,60.0
780.11987,0.15801794488188975,918.5512530840151,0.00025370340306410486,25.0,60.0
781.52124,0.158487718503937,916.6115049993508,0.00025370340306410486,25.0,60.0
782.92261,0.1589736594488189,916.3397480846644,0.00025370340306410486,25.0,60.0
784.32397,0.1594684842519685,918.060303856642,0.00025370340306410486,25.0,60.0
785.72534,0.15995114173228347,917.1158291131022,0.00025370340306410486,25.0,60.0
787.12671,0.16040220078740158,916.5506297883392,0.00025370340306410486,25.0,60.0
788.52808,0.16083871062992128,918.7232567199065,0.00025370340306410486,25.0,60.0
789.92944,0.16126686614173227,915.5462926892612,0.00025370340306410486,25.0,60.0
791.33081,0.16168767716535434,917.2769510453189,0.00025370340306410486,25.0,60.0
792.73218,0.16209734251968502,917.7534865601871,0.00025370340306410486,25.0,60.0
794.13354,0.16255408070866142,917.9097779509154,0.00025370340306410486,25.0,60.0
795.53491,0.16300388385826772,918.2770808985846,0.00025370340306410486,25.0,60.0
796.93628,0.16347467913385827,918.0837553564472,0.00025370340306410486,25.0,60.0
798.33765,0.16395428543307086,920.4213738475523,0.00025370340306410486,25.0,60.0
799.73901,0.16446329527559053,917.8632385404493,0.00025370340306410486,25.0,60.0
801.14038,0.16487495472440944,915.5863654070899,0.00025370340306410486,25.0,60.0
802.54175,0.1653454311023622,920.2185430463577,0.00025370340306410486,25.0,60.0
803.94312,0.16580329724409448,917.1688352162057,0.00025370340306410486,25.0,60.0
805.34448,0.16629934055118112,920.3274639657187,0.00025370340306410486,25.0,60.0
806.74585,0.1668398188976378,918.0665887547073,0.00025370340306410486,25.0,60.0
808.14722,0.16734752559055116,918.7476691338788,0.00025370340306410486,25.0,60.0
809.54858,0.16777495472440945,917.299259836385,0.00025370340306410486,25.0,60.0
810.94995,0.16819981299212597,918.9886248539151,0.00025370340306410486,25.0,60.0
812.35132,0.16868207086614173,919.321101155694,0.00025370340306410486,25.0,60.0
813.75269,0.1691884527559055,918.5090248019739,0.00025370340306410486,25.0,60.0
815.15405,0.16968746653543307,919.1754057914558,0.00025370340306410486,25.0,60.0
816.55542,0.17014869881889763,917.6828463835866,0.00025370340306410486,25.0,60.0
817.95679,0.17059787992125985,919.3625762887937,0.00025370340306410486,25.0,60.0
819.35815,0.17104756692913387,919.4285936891313,0.00025370340306410486,25.0,60.0
820.75952,0.1714906003937008,919.2840929749383,0.00025370340306410486,25.0,60.0
822.16089,0.17199347244094487,920.2810544085183,0.00025370340306410486,25.0,60.0
823.56226,0.17246979330708662,919.50808985846,0.00025370340306410486,25.0,60.0
824.96362,0.17298390748031495,918.6858589793534,0.00025370340306410486,25.0,60.0
826.36499,0.17348211023622048,918.5268406700429,0.00025370340306410486,25.0,60.0
827.76636,0.17401863582677166,920.0083625503182,0.00025370340306410486,25.0,60.0
829.16772,0.17456222244094488,919.032229580574,0.00025370340306410486,25.0,60.0
830.56909,0.1750430374015748,918.8214257888586,0.00025370340306410486,25.0,60.0
831.97046,0.17550179330708662,919.8507466562784,0.00025370340306410486,25.0,60.0
833.37183,0.17602724212598425,920.7650435008441,0.00025370340306410486,25.0,60.0
834.77319,0.17651767716535433,920.0939618231399,0.00025370340306410486,25.0,60.0
836.17456,0.1769952657480315,917.9221399818206,0.00025370340306410486,25.0,60.0
837.57593,0.1775028779527559,919.9141410206466,0.00025370340306410486,25.0,60.0
838.37671,0.17779806299212597,922.0541228411895,0.00025370340306410486,25.0,60.0