File: datasets/am_bench_2022/csv/60-XY.09-4.csv
Time(s),Strain(%),Stress(MPa),SR(s-1),Temp(C),Angle(deg)
11.69458,3.553994881889764e-06,14.501886480908153,0.00025370340306410486,25.0,60.0
13.39624,2.2500561023622047e-05,18.523878482972137,0.00025370340306410486,25.0,60.0
14.897705,3.72928405511811e-05,24.57840737874097,0.00025370340306410486,25.0,60.0
16.39917,5.477774606299213e-05,30.354081527347784,0.00025370340306410486,25.0,60.0
17.900635,8.395897637795276e-05,35.84861455108359,0.00025370340306410486,25.0,60.0
19.4021,8.771558267716534e-05,41.011349329205366,0.00025370340306410486,25.0,60.0
20.903564,0.00011743243110236219,46.6072084623323,0.00025370340306410486,25.0,60.0
22.405029,0.00013275711023622046,55.0367750257998,0.00025370340306410486,25.0,60.0
23.906494,0.00017330575984251967,60.17830495356038,0.00025370340306410486,25.0,60.0
25.407959,0.00021342124015748034,68.11857327141382,0.00025370340306410486,25.0,60.0
26.909424,0.00024478527559055116,76.55188080495356,0.00025370340306410486,25.0,60.0
28.410889,0.0002713999409448819,84.83087461300309,0.00025370340306410486,25.0,60.0
29.912354,0.0002862059251968504,93.79021671826627,0.00025370340306410486,25.0,60.0
31.413818,0.00034525080708661414,101.2310810113519,0.00025370340306410486,25.0,60.0
32.915283,0.0003666974212598425,110.68752321981424,0.00025370340306410486,25.0,60.0
34.416748,0.0004014564960629921,120.4316460268318,0.00025370340306410486,25.0,60.0
35.918213,0.00045862852362204724,130.1548890608875,0.00025370340306410486,25.0,60.0
37.419678,0.00047345647637795274,140.94343395252838,0.00025370340306410486,25.0,60.0
38.921143,0.0005118689173228346,150.56395252837976,0.00025370340306410486,25.0,60.0
40.422607,0.0005610292322834645,160.5149484004128,0.00025370340306410486,25.0,60.0
41.924072,0.0005860620472440944,169.26193756449948,0.00025370340306410486,25.0,60.0
43.425537,0.0006338212007874016,178.6474148606811,0.00025370340306410486,25.0,60.0
44.927002,0.000676030748031496,192.0141305469556,0.00025370340306410486,25.0,60.0
46.428467,0.0007102713188976378,200.18948658410733,0.00025370340306410486,25.0,60.0
47.929932,0.0007483306496062992,210.28770123839007,0.00025370340306410486,25.0,60.0
49.431396,0.0007935480708661418,220.82163570691435,0.00025370340306410486,25.0,60.0
50.932861,0.0008238239370078741,232.9211016511868,0.00025370340306410486,25.0,60.0
52.434326,0.0008767577952755905,243.4750335397317,0.00025370340306410486,25.0,60.0
53.935791,0.0009082663779527559,255.30160216718266,0.00025370340306410486,25.0,60.0
55.437256,0.0009683599803149606,263.3697626418989,0.00025370340306410486,25.0,60.0
56.938721,0.0009568152362204724,276.23402992776056,0.00025370340306410486,25.0,60.0
58.440186,0.0010135638582677165,284.93315273477816,0.00025370340306410486,25.0,60.0
59.94165,0.001047026751968504,296.29907120743036,0.00025370340306410486,25.0,60.0
61.443115,0.0010815625984251969,305.9476006191951,0.00025370340306410486,25.0,60.0
62.94458,0.0011364976181102362,318.0135706914345,0.00025370340306410486,25.0,60.0
64.446045,0.0011914473031496063,330.00203818369454,0.00025370340306410486,25.0,60.0
65.94751,0.0012167632283464566,338.5454076367389,0.00025370340306410486,25.0,60.0
67.448975,0.0012659350393700787,349.5370743034056,0.00025370340306410486,25.0,60.0
68.950439,0.0012846313385826771,361.36932404540767,0.00025370340306410486,25.0,60.0
70.451904,0.001356544842519685,372.2395252837978,0.00025370340306410486,25.0,60.0
71.953369,0.0013712211417322834,382.5339783281734,0.00025370340306410486,25.0,60.0
73.454834,0.0014301119881889764,394.34329205366356,0.00025370340306410486,25.0,60.0
74.956299,0.0014589487992125985,406.5284055727554,0.00025370340306410486,25.0,60.0
76.457764,0.001514259094488189,419.9801341589268,0.00025370340306410486,25.0,60.0
77.959229,0.001560766279527559,429.25219298245617,0.00025370340306410486,25.0,60.0
79.460693,0.0016019118700787403,437.4154024767802,0.00025370340306410486,25.0,60.0
80.962158,0.0016188804527559055,449.2364293085655,0.00025370340306410486,25.0,60.0
82.463623,0.0016683949015748032,458.8901444788442,0.00025370340306410486,25.0,60.0
83.965088,0.0017032390157480314,470.26976264189886,0.00025370340306410486,25.0,60.0
85.466553,0.0017297252559055117,478.44592363261097,0.00025370340306410486,25.0,60.0
86.968018,0.0017529819094488188,488.0276831785346,0.00025370340306410486,25.0,60.0
88.469482,0.0018001392913385825,494.5143704850361,0.00025370340306410486,25.0,60.0
89.970947,0.0018477452755905513,504.46767285861716,0.00025370340306410486,25.0,60.0
91.472412,0.0018802675,510.73333333333335,0.00025370340306410486,25.0,60.0
92.973877,0.001907129744094488,521.9987616099071,0.00025370340306410486,25.0,60.0
94.475342,0.0019183672047244093,530.0205366357069,0.00025370340306410486,25.0,60.0
95.976807,0.001953555807086614,536.129927760578,0.00025370340306410486,25.0,60.0
97.478271,0.00197817125984252,545.0534055727554,0.00025370340306410486,25.0,60.0
98.979736,0.0020344905511811024,554.5472910216719,0.00025370340306410486,25.0,60.0
100.4812,0.002049237007874016,561.2546697626419,0.00025370340306410486,25.0,60.0
101.98267,0.0020984005905511807,569.4195304437565,0.00025370340306410486,25.0,60.0
103.48413,0.0021264919291338583,573.7285861713107,0.00025370340306410486,25.0,60.0
104.9856,0.0021511165354330705,581.5292311661508,0.00025370340306410486,25.0,60.0
106.48706,0.002174540157480315,587.1679050567595,0.00025370340306410486,25.0,60.0
107.98853,0.0021970165354330707,595.0458462332301,0.00025370340306410486,25.0,60.0
109.48999,0.0022538568897637794,599.503044375645,0.00025370340306410486,25.0,60.0
110.99146,0.0022790173228346457,602.7663312693498,0.00025370340306410486,25.0,60.0
112.49292,0.002315647047244094,612.0056243550052,0.00025370340306410486,25.0,60.0
113.99438,0.0023370208661417325,614.846439628483,0.00025370340306410486,25.0,60.0
115.49585,0.0023628811023622045,620.8074045407636,0.00025370340306410486,25.0,60.0
116.99731,0.0023814679133858266,625.9486584107327,0.00025370340306410486,25.0,60.0
118.49878,0.002404655708661417,627.6196594427245,0.00025370340306410486,25.0,60.0
120.00024,0.002452436811023622,635.6116099071207,0.00025370340306410486,25.0,60.0
121.50171,0.002492143307086614,639.2300825593395,0.00025370340306410486,25.0,60.0
123.00317,0.0025099102362204726,642.5703044375645,0.00025370340306410486,25.0,60.0
124.50464,0.002554944881889764,647.256991744066,0.00025370340306410486,25.0,60.0
126.0061,0.002594105118110236,651.9489938080495,0.00025370340306410486,25.0,60.0
127.50757,0.002632717125984252,657.8631836945304,0.00025370340306410486,25.0,60.0
129.00903,0.002658043307086614,658.56826625387,0.00025370340306410486,25.0,60.0
130.5105,0.0027119968503937007,663.8325851393189,0.00025370340306410486,25.0,60.0
132.01196,0.002748046653543307,667.3065015479876,0.00025370340306410486,25.0,60.0
133.51343,0.0027862076771653544,668.4572755417956,0.00025370340306410486,25.0,60.0
135.01489,0.0028242460629921257,673.5244582043345,0.00025370340306410486,25.0,60.0
136.51636,0.0028820913385826773,677.1422858617132,0.00025370340306410486,25.0,60.0
138.01782,0.00294625,680.9718782249743,0.00025370340306410486,25.0,60.0
139.51929,0.003026097440944882,684.8204334365325,0.00025370340306410486,25.0,60.0
141.02075,0.003082852559055118,687.7253095975233,0.00025370340306410486,25.0,60.0
142.52222,0.0031501139763779524,693.5596233230134,0.00025370340306410486,25.0,60.0
144.02368,0.0032414080708661414,694.5431114551084,0.00025370340306410486,25.0,60.0
145.52515,0.003344406496062992,697.165479876161,0.00025370340306410486,25.0,60.0
147.02661,0.003453559645669291,703.8451496388029,0.00025370340306410486,25.0,60.0
148.52808,0.003552218700787402,704.537564499484,0.00025370340306410486,25.0,60.0
150.02954,0.0036398513779527563,705.7936790505677,0.00025370340306410486,25.0,60.0
151.53101,0.0037416783464566928,708.6313209494325,0.00025370340306410486,25.0,60.0
153.03247,0.0038975454724409445,713.650257997936,0.00025370340306410486,25.0,60.0
154.53394,0.004042315354330708,714.1726780185759,0.00025370340306410486,25.0,60.0
156.0354,0.0041976354330708655,717.4184984520124,0.00025370340306410486,25.0,60.0
157.53687,0.004337242913385827,718.7717234262126,0.00025370340306410486,25.0,60.0
159.03833,0.0044817490157480315,721.540737874097,0.00025370340306410486,25.0,60.0
160.53979,0.004672088976377953,722.0819401444788,0.00025370340306410486,25.0,60.0
162.04126,0.004827078346456693,723.4331527347781,0.00025370340306410486,25.0,60.0
163.54272,0.005005483070866142,725.1788441692466,0.00025370340306410486,25.0,60.0
165.04419,0.005202514960629921,728.8116615067079,0.00025370340306410486,25.0,60.0
166.54565,0.00542530374015748,731.0400412796697,0.00025370340306410486,25.0,60.0
168.04712,0.005643573818897638,732.0422600619195,0.00025370340306410486,25.0,60.0
169.54858,0.00582370157480315,732.3669504643964,0.00025370340306410486,25.0,60.0
171.05005,0.006053339763779528,735.9443498452013,0.00025370340306410486,25.0,60.0
172.55151,0.006240467716535434,735.5988648090815,0.00025370340306410486,25.0,60.0
174.05298,0.006501696456692914,738.1738648090816,0.00025370340306410486,25.0,60.0
175.55444,0.006808743897637796,741.0985552115584,0.00025370340306410486,25.0,60.0
177.05591,0.007109765748031497,743.5073529411765,0.00025370340306410486,25.0,60.0
178.55737,0.007359175984251968,742.1909700722395,0.00025370340306410486,25.0,60.0
180.05884,0.007605671456692913,744.8784055727555,0.00025370340306410486,25.0,60.0
181.5603,0.007942754527559055,748.8269865841073,0.00025370340306410486,25.0,60.0
183.06177,0.008242371259842519,748.4457172342622,0.00025370340306410486,25.0,60.0
184.56323,0.008518794488188977,747.9159184726522,0.00025370340306410486,25.0,60.0
186.0647,0.008795828346456692,748.6585397316821,0.00025370340306410486,25.0,60.0
187.56616,0.009103821850393701,751.4297471620227,0.00025370340306410486,25.0,60.0
189.06763,0.00940843622047244,751.8229876160991,0.00025370340306410486,25.0,60.0
190.56909,0.009705086023622047,753.4405830753354,0.00025370340306410486,25.0,60.0
192.07056,0.010014363582677165,752.4461300309598,0.00025370340306410486,25.0,60.0
193.57202,0.010297948228346456,756.6713622291022,0.00025370340306410486,25.0,60.0
195.07349,0.0105888281496063,759.3546955624355,0.00025370340306410486,25.0,60.0
196.57495,0.010916589173228346,756.9174406604748,0.00025370340306410486,25.0,60.0
198.07642,0.011251739173228347,759.544169246646,0.00025370340306410486,25.0,60.0
199.57788,0.011540036417322834,758.6113777089784,0.00025370340306410486,25.0,60.0
201.07935,0.011851509448818897,760.9618163054695,0.00025370340306410486,25.0,60.0
202.58081,0.01214749035433071,760.4212074303406,0.00025370340306410486,25.0,60.0
204.08228,0.012514797440944882,764.8275025799794,0.00025370340306410486,25.0,60.0
205.58374,0.012854247637795274,763.2760577915377,0.00025370340306410486,25.0,60.0
207.08521,0.013209458464566929,765.9090815273478,0.00025370340306410486,25.0,60.0
208.58667,0.013583479133858267,766.1575077399381,0.00025370340306410486,25.0,60.0
210.08813,0.013974876574803148,765.1241744066048,0.00025370340306410486,25.0,60.0
211.5896,0.014320585039370079,766.626625386997,0.00025370340306410486,25.0,60.0
213.09106,0.014689111417322835,766.9602683178534,0.00025370340306410486,25.0,60.0
214.59253,0.015041610433070866,769.3181114551084,0.00025370340306410486,25.0,60.0
216.09399,0.015333670275590551,768.3945046439628,0.00025370340306410486,25.0,60.0
217.59546,0.015673592716535432,771.25415376677,0.00025370340306410486,25.0,60.0
219.09692,0.01607617342519685,772.0005675954592,0.00025370340306410486,25.0,60.0
220.59839,0.016428754527559052,772.033617131063,0.00025370340306410486,25.0,60.0
222.09985,0.016760133858267717,773.816253869969,0.00025370340306410486,25.0,60.0
223.60132,0.01713447125984252,772.7537667698659,0.00025370340306410486,25.0,60.0
225.10278,0.017504998228346457,775.9638802889577,0.00025370340306410486,25.0,60.0
226.60425,0.01785263248031496,777.5788183694531,0.00025370340306410486,25.0,60.0
228.10571,0.01815176003937008,775.1517801857585,0.00025370340306410486,25.0,60.0
229.60718,0.018531812992125984,776.7561403508772,0.00025370340306410486,25.0,60.0
231.10864,0.018888202952755905,775.8404282765738,0.00025370340306410486,25.0,60.0
232.61011,0.019155900393700787,776.7020897832817,0.00025370340306410486,25.0,60.0
234.11157,0.019538157677165352,782.7972394220847,0.00025370340306410486,25.0,60.0
235.61304,0.019940897637795277,780.0376160990712,0.00025370340306410486,25.0,60.0
237.1145,0.020318744094488188,781.8523477812178,0.00025370340306410486,25.0,60.0
238.61597,0.020679198818897637,780.8606811145511,0.00025370340306410486,25.0,60.0
240.11743,0.02104010433070866,781.4399122807018,0.00025370340306410486,25.0,60.0
241.6189,0.021349828740157478,783.0013157894738,0.00025370340306410486,25.0,60.0
243.12036,0.021727763779527558,784.3894994840042,0.00025370340306410486,25.0,60.0
244.62183,0.0221168031496063,783.6835913312694,0.00025370340306410486,25.0,60.0
246.12329,0.022453161417322835,785.0480392156862,0.00025370340306410486,25.0,60.0
247.62476,0.022713980314960632,785.3517027863777,0.00025370340306410486,25.0,60.0
249.12622,0.023073293307086615,786.1485552115583,0.00025370340306410486,25.0,60.0
250.62769,0.023505555118110234,787.1770897832818,0.00025370340306410486,25.0,60.0
252.12915,0.023819740157480316,788.1716718266254,0.00025370340306410486,25.0,60.0
253.63062,0.024214580708661417,788.7526057791538,0.00025370340306410486,25.0,60.0
255.13208,0.02460839566929134,789.7749484004128,0.00025370340306410486,25.0,60.0
256.63354,0.024934917322834645,788.871955624355,0.00025370340306410486,25.0,60.0
258.13501,0.025326314960629922,793.2785345717235,0.00025370340306410486,25.0,60.0
259.63647,0.025678147637795277,791.1579205366357,0.00025370340306410486,25.0,60.0
261.13794,0.026019635826771657,789.8237616099073,0.00025370340306410486,25.0,60.0
262.6394,0.026396379921259844,792.5039731682147,0.00025370340306410486,25.0,60.0
264.14087,0.026795734251968507,795.715092879257,0.00025370340306410486,25.0,60.0
265.64233,0.027191903543307083,794.9778121775025,0.00025370340306410486,25.0,60.0
267.1438,0.027530370078740155,795.9677760577915,0.00025370340306410486,25.0,60.0
268.64526,0.027918677165354327,796.1321723426213,0.00025370340306410486,25.0,60.0
270.14673,0.028235720472440943,794.9342879256966,0.00025370340306410486,25.0,60.0
271.64819,0.028572137795275593,796.7718782249742,0.00025370340306410486,25.0,60.0
273.14966,0.028873950787401577,795.5827399380805,0.00025370340306410486,25.0,60.0
274.65112,0.029273127952755905,796.833875128999,0.00025370340306410486,25.0,60.0
276.15259,0.029626407480314962,798.0005933952528,0.00025370340306410486,25.0,60.0
277.65405,0.03002399212598425,798.9178276573788,0.00025370340306410486,25.0,60.0
279.15552,0.03038375,798.4698400412797,0.00025370340306410486,25.0,60.0
280.65698,0.030715334645669293,798.8685758513932,0.00025370340306410486,25.0,60.0
282.15845,0.03105307874015748,802.6404540763674,0.00025370340306410486,25.0,60.0
283.65991,0.031475553149606296,802.887951496388,0.00025370340306410486,25.0,60.0
285.16138,0.031860204724409445,803.3390608875129,0.00025370340306410486,25.0,60.0
286.66284,0.03222077559055118,801.9207688338494,0.00025370340306410486,25.0,60.0
288.16431,0.032574641732283464,803.396439628483,0.00025370340306410486,25.0,60.0
289.66577,0.032954968503937004,805.2863777089783,0.00025370340306410486,25.0,60.0
291.16724,0.03338271850393701,804.6913312693499,0.00025370340306410486,25.0,60.0
292.6687,0.03372934448818898,804.153044375645,0.00025370340306410486,25.0,60.0
294.17017,0.034128736220472446,806.7709494324046,0.00025370340306410486,25.0,60.0
295.67163,0.034480799212598424,806.7117389060887,0.00025370340306410486,25.0,60.0
297.1731,0.034793226377952756,806.3307791537668,0.00025370340306410486,25.0,60.0
298.67456,0.035092501968503935,807.2736584107327,0.00025370340306410486,25.0,60.0
300.17603,0.035484234251968505,809.9191434468524,0.00025370340306410486,25.0,60.0
301.67749,0.03585018700787401,808.4718008255934,0.00025370340306410486,25.0,60.0
303.17896,0.03625157677165355,808.3965428276573,0.00025370340306410486,25.0,60.0
304.68042,0.03662666732283465,809.5016511867906,0.00025370340306410486,25.0,60.0
306.18188,0.03691779330708662,808.1908152734778,0.00025370340306410486,25.0,60.0
307.68335,0.0372716062992126,812.7049019607842,0.00025370340306410486,25.0,60.0
309.18481,0.03762112204724409,812.0309339525284,0.00025370340306410486,25.0,60.0
310.68628,0.03802620078740157,812.8351651186791,0.00025370340306410486,25.0,60.0
312.18774,0.038376157480314955,812.3313209494324,0.00025370340306410486,25.0,60.0
313.68921,0.03871781299212598,813.3914602683179,0.00025370340306410486,25.0,60.0
315.19067,0.0390963562992126,816.4153766769866,0.00025370340306410486,25.0,60.0
316.69214,0.03942674803149606,812.9257997936016,0.00025370340306410486,25.0,60.0
318.1936,0.03982830118110236,817.3142930856553,0.00025370340306410486,25.0,60.0
319.69507,0.040193911417322835,814.9769349845202,0.00025370340306410486,25.0,60.0
321.19653,0.04053774409448819,815.8243808049535,0.00025370340306410486,25.0,60.0
322.698,0.04088635433070866,815.9890866873066,0.00025370340306410486,25.0,60.0
324.19946,0.04118025984251968,815.8219040247678,0.00025370340306410486,25.0,60.0
325.70093,0.04157949409448819,818.0806501547987,0.00025370340306410486,25.0,60.0
327.20239,0.041934165354330706,817.7885706914345,0.00025370340306410486,25.0,60.0
328.70386,0.04239958267716536,821.5854231166151,0.00025370340306410486,25.0,60.0
330.20532,0.042785049212598424,818.2075851393189,0.00025370340306410486,25.0,60.0
331.70679,0.04312379527559055,818.3528121775026,0.00025370340306410486,25.0,60.0
333.20825,0.043493988188976374,820.8931888544893,0.00025370340306410486,25.0,60.0
334.70972,0.043847746062992125,821.0458720330237,0.00025370340306410486,25.0,60.0
336.21118,0.04419681692913386,821.2532249742002,0.00025370340306410486,25.0,60.0
337.71265,0.04457475,822.6230908152735,0.00025370340306410486,25.0,60.0
339.21411,0.04489820275590551,821.2859133126935,0.00025370340306410486,25.0,60.0
340.71558,0.045229641732283464,823.3921052631579,0.00025370340306410486,25.0,60.0
342.21704,0.04560431496062992,823.3238132094943,0.00025370340306410486,25.0,60.0
343.71851,0.045976629921259844,822.4132610939113,0.00025370340306410486,25.0,60.0
345.21997,0.046344433070866144,826.5996904024768,0.00025370340306410486,25.0,60.0
346.72144,0.04670975984251968,825.4705108359134,0.00025370340306410486,25.0,60.0
348.2229,0.04704907874015748,825.3447110423116,0.00025370340306410486,25.0,60.0
349.72437,0.04737785433070866,825.5510577915377,0.00025370340306410486,25.0,60.0
351.22583,0.04775256102362204,827.2854231166151,0.00025370340306410486,25.0,60.0
352.72729,0.04817389566929134,827.2041279669762,0.00025370340306410486,25.0,60.0
354.22876,0.04860298031496063,826.8905056759546,0.00025370340306410486,25.0,60.0
355.73022,0.04894709645669291,827.6554953560371,0.00025370340306410486,25.0,60.0
357.23169,0.04925946062992126,828.3941434468525,0.00025370340306410486,25.0,60.0
358.73315,0.04958203543307086,828.5475748194015,0.00025370340306410486,25.0,60.0
360.23462,0.04990786614173228,830.0070175438597,0.00025370340306410486,25.0,60.0
361.73608,0.050299045275590544,830.7648864809081,0.00025370340306410486,25.0,60.0
363.23755,0.05071489960629922,831.4984262125904,0.00025370340306410486,25.0,60.0
364.73901,0.05110230708661417,831.3424148606811,0.00025370340306410486,25.0,60.0
366.24048,0.05145578543307087,832.9788957688339,0.00025370340306410486,25.0,60.0
367.74194,0.05180694291338583,831.1570433436533,0.00025370340306410486,25.0,60.0
369.24341,0.05213295669291338,833.6851909184727,0.00025370340306410486,25.0,60.0
370.74487,0.052493564960629915,831.3099071207431,0.00025370340306410486,25.0,60.0
372.24634,0.052869055118110235,835.187306501548,0.00025370340306410486,25.0,60.0
373.7478,0.053280984251968505,835.9820949432404,0.00025370340306410486,25.0,60.0
375.24927,0.05364433858267716,836.6005675954592,0.00025370340306410486,25.0,60.0
376.75073,0.05401859842519685,836.5333075335398,0.00025370340306410486,25.0,60.0
378.2522,0.054346811023622044,835.7676728586172,0.00025370340306410486,25.0,60.0
379.75366,0.05471439960629921,837.5512383900929,0.00025370340306410486,25.0,60.0
381.25513,0.055106870078740156,837.847342621259,0.00025370340306410486,25.0,60.0
382.75659,0.055487401574803155,836.7306501547988,0.00025370340306410486,25.0,60.0
384.25806,0.05581458661417323,839.2767285861713,0.00025370340306410486,25.0,60.0
385.75952,0.05616519881889764,837.3394736842105,0.00025370340306410486,25.0,60.0
387.26099,0.05650770275590551,839.6809339525284,0.00025370340306410486,25.0,60.0
388.76245,0.05683321653543307,839.8415376676987,0.00025370340306410486,25.0,60.0
390.26392,0.057176271653543304,839.7240196078432,0.00025370340306410486,25.0,60.0
391.76538,0.05760127755905512,840.6734778121776,0.00025370340306410486,25.0,60.0
393.26685,0.05796768700787401,843.2732456140351,0.00025370340306410486,25.0,60.0
394.76831,0.05827681692913386,842.2235552115584,0.00025370340306410486,25.0,60.0
396.26978,0.058642171259842515,843.1291279669763,0.00025370340306410486,25.0,60.0
397.77124,0.05904102952755906,842.2899380804954,0.00025370340306410486,25.0,60.0
399.27271,0.059391405511811025,841.4674406604747,0.00025370340306410486,25.0,60.0
400.77417,0.05973284842519685,843.6591589267285,0.00025370340306410486,25.0,60.0
402.27563,0.060172062992125984,844.1946336429309,0.00025370340306410486,25.0,60.0
403.7771,0.06048504527559055,842.7735036119711,0.00025370340306410486,25.0,60.0
405.27856,0.060840291338582674,844.3817595459236,0.00025370340306410486,25.0,60.0
406.78003,0.06126394094488189,846.3505159958721,0.00025370340306410486,25.0,60.0
408.28149,0.06156609448818898,844.1317595459236,0.00025370340306410486,25.0,60.0
409.78296,0.061942362204724405,848.5264963880289,0.00025370340306410486,25.0,60.0
411.28442,0.062297988188976375,846.3149380804954,0.00025370340306410486,25.0,60.0
412.78589,0.06257913976377953,846.7198658410733,0.00025370340306410486,25.0,60.0
414.28735,0.06297511811023622,847.7141382868937,0.00025370340306410486,25.0,60.0
415.78882,0.06333713385826771,848.6519091847266,0.00025370340306410486,25.0,60.0
417.29028,0.0637233720472441,849.6985552115583,0.00025370340306410486,25.0,60.0
418.79175,0.06405550984251968,850.1847781217751,0.00025370340306410486,25.0,60.0
420.29321,0.06436191141732282,847.7359391124871,0.00025370340306410486,25.0,60.0
421.79468,0.06470127559055118,850.567492260062,0.00025370340306410486,25.0,60.0
423.29614,0.06510689763779527,850.3846233230134,0.00025370340306410486,25.0,60.0
424.79761,0.06546162795275591,849.7668472652219,0.00025370340306410486,25.0,60.0
426.29907,0.06583279133858268,851.1487874097008,0.00025370340306410486,25.0,60.0
427.80054,0.06621027755905512,852.0755933952529,0.00025370340306410486,25.0,60.0
429.302,0.0665590748031496,850.3639576883385,0.00025370340306410486,25.0,60.0
430.80347,0.06696209251968503,853.582894736842,0.00025370340306410486,25.0,60.0
432.30493,0.06738714566929134,853.3771671826626,0.00025370340306410486,25.0,60.0
433.8064,0.06776719488188977,851.943137254902,0.00025370340306410486,25.0,60.0
435.30786,0.06806374606299212,853.7374613003096,0.00025370340306410486,25.0,60.0
436.80933,0.06842139763779528,856.0385448916409,0.00025370340306410486,25.0,60.0
438.31079,0.06882286614173229,854.731604747162,0.00025370340306410486,25.0,60.0
439.81226,0.06915630708661417,855.2786635706915,0.00025370340306410486,25.0,60.0
441.31372,0.06950629527559056,855.0703560371518,0.00025370340306410486,25.0,60.0
442.81519,0.06991184251968503,855.130701754386,0.00025370340306410486,25.0,60.0
444.31665,0.07027774803149606,858.7812693498452,0.00025370340306410486,25.0,60.0
445.81812,0.07064269685039369,857.8151186790506,0.00025370340306410486,25.0,60.0
447.31958,0.07098120078740157,855.671568627451,0.00025370340306410486,25.0,60.0
448.82104,0.07129625393700788,857.1592105263157,0.00025370340306410486,25.0,60.0
450.32251,0.07160886811023622,856.1460526315789,0.00025370340306410486,25.0,60.0
451.82397,0.07193279724409449,858.9432920536636,0.00025370340306410486,25.0,60.0
453.32544,0.07233054724409448,859.5245872033024,0.00025370340306410486,25.0,60.0
454.8269,0.07272315748031496,860.732585139319,0.00025370340306410486,25.0,60.0
456.32837,0.0730926062992126,859.5386480908153,0.00025370340306410486,25.0,60.0
457.82983,0.07341633070866142,861.4554179566564,0.00025370340306410486,25.0,60.0
459.3313,0.07383153937007873,863.2979360165119,0.00025370340306410486,25.0,60.0
460.83276,0.07419025984251969,860.0191176470588,0.00025370340306410486,25.0,60.0
462.33423,0.07453465157480316,862.9023735810113,0.00025370340306410486,25.0,60.0
463.83569,0.07488353937007873,862.5093911248711,0.00025370340306410486,25.0,60.0
465.33716,0.07517630511811023,860.8958978328174,0.00025370340306410486,25.0,60.0
466.83862,0.07555088188976378,862.5434726522188,0.00025370340306410486,25.0,60.0
468.34009,0.07596109842519685,864.9559081527349,0.00025370340306410486,25.0,60.0
469.84155,0.07636760039370079,864.2142156862745,0.00025370340306410486,25.0,60.0
471.34302,0.07674807874015747,863.7211558307533,0.00025370340306410486,25.0,60.0
472.84448,0.07705668503937008,864.7463364293086,0.00025370340306410486,25.0,60.0
474.34595,0.07744616338582677,863.9773219814242,0.00025370340306410486,25.0,60.0
475.84741,0.0777978248031496,863.3128740970072,0.00025370340306410486,25.0,60.0
477.34888,0.0781688405511811,866.733746130031,0.00025370340306410486,25.0,60.0
478.85034,0.07859105905511811,865.5626160990713,0.00025370340306410486,25.0,60.0
480.35181,0.0789396811023622,867.0140350877193,0.00025370340306410486,25.0,60.0
481.85327,0.07928260826771653,865.3344685242519,0.00025370340306410486,25.0,60.0
483.35474,0.07958673228346456,866.6481424148608,0.00025370340306410486,25.0,60.0
484.8562,0.07997501377952757,867.1219298245613,0.00025370340306410486,25.0,60.0
486.35767,0.0803555905511811,868.2237874097008,0.00025370340306410486,25.0,60.0
487.85913,0.08074945078740157,868.483359133127,0.00025370340306410486,25.0,60.0
489.3606,0.08108930314960629,866.2671310629515,0.00025370340306410486,25.0,60.0
490.86206,0.08139598622047244,869.0018059855522,0.00025370340306410486,25.0,60.0
492.36353,0.08175813582677165,870.7641382868937,0.00025370340306410486,25.0,60.0
493.86499,0.08216004527559055,869.918137254902,0.00025370340306410486,25.0,60.0
495.36646,0.08258761417322835,869.2625128998968,0.00025370340306410486,25.0,60.0
496.86792,0.08293166732283465,870.2767285861713,0.00025370340306410486,25.0,60.0
498.36938,0.08329001771653542,872.2768575851393,0.00025370340306410486,25.0,60.0
499.87085,0.08364611417322834,871.6412280701755,0.00025370340306410486,25.0,60.0
501.37231,0.08402640354330708,871.9637254901961,0.00025370340306410486,25.0,60.0
502.87378,0.08435698622047244,872.4723684210527,0.00025370340306410486,25.0,60.0
504.37524,0.0847174783464567,872.9190660474716,0.00025370340306410486,25.0,60.0
505.87671,0.08512410433070866,872.9851393188854,0.00025370340306410486,25.0,60.0
507.37817,0.08549473228346456,874.3050051599588,0.00025370340306410486,25.0,60.0
508.87964,0.08582900984251969,874.0483230134158,0.00025370340306410486,25.0,60.0
510.3811,0.0861821968503937,874.0558823529412,0.00025370340306410486,25.0,60.0
511.88257,0.0865951653543307,875.7026315789474,0.00025370340306410486,25.0,60.0
513.38403,0.08706680511811024,875.2007997936016,0.00025370340306410486,25.0,60.0
514.8855,0.08744023031496063,875.0358359133127,0.00025370340306410486,25.0,60.0
516.38696,0.08777655118110236,874.4763157894738,0.00025370340306410486,25.0,60.0
517.88843,0.0880988562992126,874.6031217750258,0.00025370340306410486,25.0,60.0
519.38989,0.08843707677165354,876.4162280701755,0.00025370340306410486,25.0,60.0
520.89136,0.08880307086614174,877.9330237358101,0.00025370340306410486,25.0,60.0
522.39282,0.08920527952755906,877.6083333333333,0.00025370340306410486,25.0,60.0
523.89429,0.08957572637795275,877.7041795665635,0.00025370340306410486,25.0,60.0
525.39575,0.08986160433070867,875.2563725490196,0.00025370340306410486,25.0,60.0
526.89722,0.09022148031496062,878.7587977296182,0.00025370340306410486,25.0,60.0
528.39868,0.09057805118110236,878.835758513932,0.00025370340306410486,25.0,60.0
529.90015,0.09092613976377953,880.2310629514964,0.00025370340306410486,25.0,60.0
531.40161,0.09130606102362204,879.5773219814242,0.00025370340306410486,25.0,60.0
532.90308,0.09173268110236221,878.8132868937048,0.00025370340306410486,25.0,60.0
534.40454,0.09210897637795275,881.5824045407636,0.00025370340306410486,25.0,60.0
535.90601,0.09249925787401575,879.5273735810114,0.00025370340306410486,25.0,60.0
537.40747,0.09286572637795276,880.6441434468524,0.00025370340306410486,25.0,60.0
538.90894,0.09324709055118109,880.1,0.00025370340306410486,25.0,60.0
540.4104,0.0936438720472441,882.4468524251806,0.00025370340306410486,25.0,60.0
541.91187,0.09411210826771653,882.6626418988649,0.00025370340306410486,25.0,60.0
543.41333,0.09450220275590551,883.5199174406605,0.00025370340306410486,25.0,60.0
544.91479,0.09491585039370079,881.7837719298246,0.00025370340306410486,25.0,60.0
546.41626,0.09527681692913385,881.2868163054695,0.00025370340306410486,25.0,60.0
547.91772,0.09560397834645669,883.1690660474717,0.00025370340306410486,25.0,60.0
549.41919,0.0960207716535433,884.9269349845201,0.00025370340306410486,25.0,60.0
550.92065,0.09638363779527559,883.8959494324046,0.00025370340306410486,25.0,60.0
552.42212,0.09673380314960629,884.3681114551084,0.00025370340306410486,25.0,60.0
553.92358,0.09711954921259842,882.546697626419,0.00025370340306410486,25.0,60.0
555.42505,0.09747694881889764,884.0762899896802,0.00025370340306410486,25.0,60.0
556.92651,0.09788806889763779,886.653044375645,0.00025370340306410486,25.0,60.0
558.42798,0.09827563385826772,884.927012383901,0.00025370340306410486,25.0,60.0
559.92944,0.09866920078740159,885.8939370485036,0.00025370340306410486,25.0,60.0
561.43091,0.09900289173228347,884.6923116615067,0.00025370340306410486,25.0,60.0
562.93237,0.09931845669291338,886.4125128998968,0.00025370340306410486,25.0,60.0
564.43384,0.0996847086614173,887.5608359133128,0.00025370340306410486,25.0,60.0
565.9353,0.10013042913385826,885.9442466460268,0.00025370340306410486,25.0,60.0
567.43677,0.1004967874015748,886.8801341589267,0.00025370340306410486,25.0,60.0
568.93823,0.10083503149606299,885.8187048503613,0.00025370340306410486,25.0,60.0
570.4397,0.10118107874015747,887.3873581011352,0.00025370340306410486,25.0,60.0
571.94116,0.10160258267716535,888.0738648090816,0.00025370340306410486,25.0,60.0
573.44263,0.10198061417322836,889.15544375645,0.00025370340306410486,25.0,60.0
574.94409,0.10238092716535432,889.9467492260062,0.00025370340306410486,25.0,60.0
576.44556,0.10280677165354331,889.4418988648091,0.00025370340306410486,25.0,60.0
577.94702,0.10316276968503936,888.0715944272446,0.00025370340306410486,25.0,60.0
579.44849,0.10361907283464566,890.0649638802889,0.00025370340306410486,25.0,60.0
580.94995,0.10402565157480315,892.5296955624354,0.00025370340306410486,25.0,60.0
582.45142,0.10443300393700786,888.1207430340559,0.00025370340306410486,25.0,60.0
583.95288,0.10477375984251967,890.0062693498452,0.00025370340306410486,25.0,60.0
585.45435,0.1051891968503937,892.0144994840041,0.00025370340306410486,25.0,60.0
586.95581,0.10559301968503938,891.1850361197111,0.00025370340306410486,25.0,60.0
588.45728,0.10596358858267717,892.3394736842106,0.00025370340306410486,25.0,60.0
589.95874,0.1063624468503937,891.7815273477812,0.00025370340306410486,25.0,60.0
591.46021,0.10677250984251968,891.5794633642931,0.00025370340306410486,25.0,60.0
592.96167,0.10714738582677165,892.61346749226,0.00025370340306410486,25.0,60.0
594.46313,0.10746239960629922,891.1721620227039,0.00025370340306410486,25.0,60.0
595.9646,0.10776324999999999,890.9662022703819,0.00025370340306410486,25.0,60.0
597.46606,0.10807936614173227,892.0997420020641,0.00025370340306410486,25.0,60.0
598.96753,0.10844114763779528,894.3030959752323,0.00025370340306410486,25.0,60.0
600.46899,0.10883992322834644,894.6511093911249,0.00025370340306410486,25.0,60.0
601.97046,0.1092776062992126,897.0863519091847,0.00025370340306410486,25.0,60.0
603.47192,0.1096828838582677,894.0281733746131,0.00025370340306410486,25.0,60.0
604.97339,0.11014268307086614,894.7057791537668,0.00025370340306410486,25.0,60.0
606.47485,0.11058711417322835,892.761790505676,0.00025370340306410486,25.0,60.0
607.97632,0.11094799212598425,893.9447110423117,0.00025370340306410486,25.0,60.0
609.47778,0.11130675787401574,895.7049019607844,0.00025370340306410486,25.0,60.0
610.97925,0.11170068897637794,896.9017285861713,0.00025370340306410486,25.0,60.0
612.48071,0.11207793503937007,895.6176728586172,0.00025370340306410486,25.0,60.0
613.98218,0.11236707480314961,895.0453560371517,0.00025370340306410486,25.0,60.0
615.48364,0.11281740748031496,898.5547213622291,0.00025370340306410486,25.0,60.0
616.98511,0.11324720669291338,894.2736326109391,0.00025370340306410486,25.0,60.0
618.48657,0.11362791338582677,896.3937306501548,0.00025370340306410486,25.0,60.0
619.98804,0.11402245275590552,897.0073013415893,0.00025370340306410486,25.0,60.0
621.4895,0.11444270078740157,897.3485036119712,0.00025370340306410486,25.0,60.0
622.99097,0.11484120866141732,898.8551599587203,0.00025370340306410486,25.0,60.0
624.49243,0.11525375787401576,898.751883384933,0.00025370340306410486,25.0,60.0
625.9939,0.11569623031496062,898.4450464396285,0.00025370340306410486,25.0,60.0
627.49536,0.1161011062992126,899.3936016511868,0.00025370340306410486,25.0,60.0
628.99683,0.11651924212598426,899.3361971104231,0.00025370340306410486,25.0,60.0
630.49829,0.1168877125984252,899.4009545923633,0.00025370340306410486,25.0,60.0
631.99976,0.11722472440944881,898.2116357069144,0.00025370340306410486,25.0,60.0
633.50122,0.11762021653543306,898.203560371517,0.00025370340306410486,25.0,60.0
635.00269,0.11801431102362205,900.1606037151703,0.00025370340306410486,25.0,60.0
636.50415,0.11838038582677166,900.4046181630547,0.00025370340306410486,25.0,60.0
638.00562,0.11880441141732283,901.6731166150672,0.00025370340306410486,25.0,60.0
639.50708,0.1192563405511811,901.4917698658411,0.00025370340306410486,25.0,60.0
641.00854,0.11970251771653544,901.83782249742,0.00025370340306410486,25.0,60.0
642.51001,0.1201011062992126,900.9452270381838,0.00025370340306410486,25.0,60.0
644.01147,0.12048708267716536,902.337951496388,0.00025370340306410486,25.0,60.0
645.51294,0.1209133838582677,900.2611197110423,0.00025370340306410486,25.0,60.0
647.0144,0.12131697047244093,902.1174406604747,0.00025370340306410486,25.0,60.0
648.51587,0.12174276771653543,902.9548503611971,0.00025370340306410486,25.0,60.0
650.01733,0.12211715157480314,901.3613261093911,0.00025370340306410486,25.0,60.0
651.5188,0.12247520078740157,900.6535861713107,0.00025370340306410486,25.0,60.0
653.02026,0.12287896456692912,904.1407378740971,0.00025370340306410486,25.0,60.0
654.52173,0.1233036594488189,904.3036119711043,0.00025370340306410486,25.0,60.0
656.02319,0.12373092322834646,904.3967234262126,0.00025370340306410486,25.0,60.0
657.52466,0.12418526771653544,904.5917956656347,0.00025370340306410486,25.0,60.0
659.02612,0.12454022047244093,903.3455624355006,0.00025370340306410486,25.0,60.0
660.52759,0.12494415944881891,903.5664086687307,0.00025370340306410486,25.0,60.0
662.02905,0.1253824645669291,905.0105263157894,0.00025370340306410486,25.0,60.0
663.53052,0.12574659251968504,903.6824819401445,0.00025370340306410486,25.0,60.0
665.03198,0.1261438562992126,905.2873581011352,0.00025370340306410486,25.0,60.0
666.53345,0.1265255374015748,905.4898090815274,0.00025370340306410486,25.0,60.0
668.03491,0.12694779133858267,905.8451754385965,0.00025370340306410486,25.0,60.0
669.53638,0.1273636279527559,903.8827915376678,0.00025370340306410486,25.0,60.0
671.03784,0.12781665748031495,906.3774767801857,0.00025370340306410486,25.0,60.0
672.53931,0.12824464960629922,906.1569143446853,0.00025370340306410486,25.0,60.0
674.04077,0.12866893307086613,907.3041021671827,0.00025370340306410486,25.0,60.0
675.54224,0.12908007677165353,906.8515995872033,0.00025370340306410486,25.0,60.0
677.0437,0.12949043307086616,908.0824303405573,0.00025370340306410486,25.0,60.0
678.54517,0.12988972637795276,906.8639318885449,0.00025370340306410486,25.0,60.0
680.04663,0.1303725472440945,906.2217750257998,0.00025370340306410486,25.0,60.0
681.5481,0.13076251181102364,906.9751031991744,0.00025370340306410486,25.0,60.0
683.04956,0.13120324606299213,907.5489938080495,0.00025370340306410486,25.0,60.0
684.55103,0.131628,908.1999226006192,0.00025370340306410486,25.0,60.0
686.05249,0.1320899940944882,909.4793085655315,0.00025370340306410486,25.0,60.0
687.55396,0.13254221456692913,908.7258513931888,0.00025370340306410486,25.0,60.0
689.05542,0.13294197637795274,908.6660216718267,0.00025370340306410486,25.0,60.0
690.55688,0.13330050787401573,907.8297213622292,0.00025370340306410486,25.0,60.0
692.05835,0.133791718503937,909.7400154798762,0.00025370340306410486,25.0,60.0
693.55981,0.1342346692913386,909.1713622291021,0.00025370340306410486,25.0,60.0
695.06128,0.13466825787401573,910.4037925696595,0.00025370340306410486,25.0,60.0
696.56274,0.13505438582677165,909.84262125903,0.00025370340306410486,25.0,60.0
698.06421,0.1355088838582677,910.3789215686276,0.00025370340306410486,25.0,60.0
699.56567,0.13594632086614172,912.1312435500516,0.00025370340306410486,25.0,60.0
701.06714,0.13637893503937007,909.8553663570692,0.00025370340306410486,25.0,60.0
702.5686,0.13677788779527558,910.166769865841,0.00025370340306410486,25.0,60.0
704.07007,0.137209094488189,911.9577657378742,0.00025370340306410486,25.0,60.0
705.57153,0.1376354311023622,910.9608617131064,0.00025370340306410486,25.0,60.0
707.073,0.13806117125984252,910.8639834881321,0.00025370340306410486,25.0,60.0
708.57446,0.1384876850393701,910.3106295149639,0.00025370340306410486,25.0,60.0
710.07593,0.13890491732283464,910.5096749226007,0.00025370340306410486,25.0,60.0
711.57739,0.13932610433070866,912.1294633642931,0.00025370340306410486,25.0,60.0
713.07886,0.13973947637795275,911.5663054695564,0.00025370340306410486,25.0,60.0
714.58032,0.1401460787401575,912.909262125903,0.00025370340306410486,25.0,60.0
716.08179,0.14054770472440944,912.936661506708,0.00025370340306410486,25.0,60.0
717.58325,0.14107555905511812,912.8907378740971,0.00025370340306410486,25.0,60.0
719.08472,0.14160375196850394,914.0458720330238,0.00025370340306410486,25.0,60.0
720.58618,0.14206020866141733,913.4498194014449,0.00025370340306410486,25.0,60.0
722.08765,0.1425627303149606,913.1761867905057,0.00025370340306410486,25.0,60.0
723.58911,0.14298697834645668,913.0001547987616,0.00025370340306410486,25.0,60.0
725.09058,0.14341136811023622,913.9372291021673,0.00025370340306410486,25.0,60.0
726.59204,0.14388955511811022,914.8581011351909,0.00025370340306410486,25.0,60.0
728.09351,0.14433376181102361,912.7851651186791,0.00025370340306410486,25.0,60.0
729.59497,0.14475706102362204,912.3810371517028,0.00025370340306410486,25.0,60.0
731.09644,0.14517581889763778,913.5958978328173,0.00025370340306410486,25.0,60.0
732.5979,0.14558552952755904,913.9503869969041,0.00025370340306410486,25.0,60.0
734.09937,0.14600675196850393,914.1857069143447,0.00025370340306410486,25.0,60.0
735.60083,0.14638894881889764,914.2593911248711,0.00025370340306410486,25.0,60.0
737.10229,0.1468713248031496,915.8591073271415,0.00025370340306410486,25.0,60.0
738.60376,0.14726926771653542,915.5098297213622,0.00025370340306410486,25.0,60.0
740.10522,0.147708968503937,915.5959494324046,0.00025370340306410486,25.0,60.0
741.60669,0.1481604035433071,916.7068627450981,0.00025370340306410486,25.0,60.0
743.10815,0.14861623818897637,916.0258255933952,0.00025370340306410486,25.0,60.0
744.60962,0.14907268307086616,917.3199174406606,0.00025370340306410486,25.0,60.0
746.11108,0.14952486811023621,915.6966460268319,0.00025370340306410486,25.0,60.0
747.61255,0.14995506692913385,914.6164086687306,0.00025370340306410486,25.0,60.0
749.11401,0.15034735433070867,916.3820949432404,0.00025370340306410486,25.0,60.0
750.61548,0.15085933267716536,917.1004127966977,0.00025370340306410486,25.0,60.0
752.11694,0.15133932677165354,918.6241486068111,0.00025370340306410486,25.0,60.0
753.61841,0.15187200196850392,917.5314241486068,0.00025370340306410486,25.0,60.0
755.11987,0.15229580511811022,917.3567595459236,0.00025370340306410486,25.0,60.0
756.62134,0.15275228543307087,914.709262125903,0.00025370340306410486,25.0,60.0
758.1228,0.15322192913385826,916.9285087719298,0.00025370340306410486,25.0,60.0
759.62427,0.15365266732283464,917.6042311661507,0.00025370340306410486,25.0,60.0
761.12573,0.15409500787401575,917.3353973168215,0.00025370340306410486,25.0,60.0
762.6272,0.15455977165354332,920.5777605779155,0.00025370340306410486,25.0,60.0
764.12866,0.15507348622047243,917.1724458204335,0.00025370340306410486,25.0,60.0
765.63013,0.15554174606299212,917.9847523219815,0.00025370340306410486,25.0,60.0
767.13159,0.15590236614173228,916.2125902992776,0.00025370340306410486,25.0,60.0
768.63306,0.15629677755905513,918.5764447884418,0.00025370340306410486,25.0,60.0
770.13452,0.15680774606299214,918.1331527347782,0.00025370340306410486,25.0,60.0
771.63599,0.1573121692913386,918.8692208462332,0.00025370340306410486,25.0,60.0
773.13745,0.1578288523622047,919.9714396284829,0.00025370340306410486,25.0,60.0
774.63892,0.1582581811023622,918.7262383900929,0.00025370340306410486,25.0,60.0
776.14038,0.1587454133858268,920.0391640866874,0.00025370340306410486,25.0,60.0
777.64185,0.15925175984251969,918.5889318885448,0.00025370340306410486,25.0,60.0
779.14331,0.15974170275590552,921.5913570691434,0.00025370340306410486,25.0,60.0
780.64478,0.16019283267716536,918.3589525283797,0.00025370340306410486,25.0,60.0
782.14624,0.16063693503937007,919.9438596491228,0.00025370340306410486,25.0,60.0
783.64771,0.1610958779527559,919.7675438596491,0.00025370340306410486,25.0,60.0
785.14917,0.16155625393700787,918.756217750258,0.00025370340306410486,25.0,60.0
786.65063,0.16206619094488187,920.5441950464397,0.00025370340306410486,25.0,60.0
788.1521,0.162563655511811,919.2761867905058,0.00025370340306410486,25.0,60.0
789.65356,0.16302098031496062,919.437435500516,0.00025370340306410486,25.0,60.0
791.15503,0.16353194881889765,920.3787151702787,0.00025370340306410486,25.0,60.0
792.65649,0.16407683858267716,920.8764447884417,0.00025370340306410486,25.0,60.0
794.15796,0.16453677952755905,919.380185758514,0.00025370340306410486,25.0,60.0
795.65942,0.1651032125984252,923.2475748194014,0.00025370340306410486,25.0,60.0
797.16089,0.16567428937007875,920.5350619195046,0.00025370340306410486,25.0,60.0
798.66235,0.16618028346456692,921.1188338493292,0.00025370340306410486,25.0,60.0
800.16382,0.16665428149606298,919.7206398348814,0.00025370340306410486,25.0,60.0
801.66528,0.16712366732283465,918.3136738906089,0.00025370340306410486,25.0,60.0
803.16675,0.16756739370078738,919.2781991744066,0.00025370340306410486,25.0,60.0
804.66821,0.16804129921259842,920.6928534571724,0.00025370340306410486,25.0,60.0
806.16968,0.16850308267716535,920.5769607843138,0.00025370340306410486,25.0,60.0
807.67114,0.1689826751968504,920.9640608875129,0.00025370340306410486,25.0,60.0
809.17261,0.16949553346456692,922.3055211558308,0.00025370340306410486,25.0,60.0
810.67407,0.16996224606299212,921.7202270381837,0.00025370340306410486,25.0,60.0
812.17554,0.1704635,921.5302115583075,0.00025370340306410486,25.0,60.0
813.677,0.17092176377952756,922.076625386997,0.00025370340306410486,25.0,60.0
815.17847,0.17139908070866142,921.8443756449949,0.00025370340306410486,25.0,60.0
816.67993,0.17188087007874014,918.777012383901,0.00025370340306410486,25.0,60.0
818.1814,0.17237500196850392,922.3116873065015,0.00025370340306410486,25.0,60.0
819.68286,0.17285508858267717,920.9679824561404,0.00025370340306410486,25.0,60.0
821.18433,0.17340406102362205,921.8091847265223,0.00025370340306410486,25.0,60.0
822.68579,0.17393561023622048,922.2083333333334,0.00025370340306410486,25.0,60.0
824.18726,0.17439164566929133,922.3074819401445,0.00025370340306410486,25.0,60.0
825.68872,0.1748947874015748,923.8989164086688,0.00025370340306410486,25.0,60.0
827.19019,0.1755403838582677,923.7513931888545,0.00025370340306410486,25.0,60.0
828.69165,0.1761232066929134,921.0389576883385,0.00025370340306410486,25.0,60.0
830.19312,0.17662948228346456,923.2721878224975,0.00025370340306410486,25.0,60.0
831.69458,0.17721508661417323,922.971181630547,0.00025370340306410486,25.0,60.0
833.19604,0.17771744291338581,922.8300309597523,0.00025370340306410486,25.0,60.0
834.69751,0.1781996437007874,921.6560629514964,0.00025370340306410486,25.0,60.0
836.19897,0.1787203622047244,921.7545665634675,0.00025370340306410486,25.0,60.0
837.70044,0.17922393897637795,922.3271929824562,0.00025370340306410486,25.0,60.0
839.2019,0.17971010433070866,922.2534829721362,0.00025370340306410486,25.0,60.0
840.70337,0.18021431496062992,923.1442724458204,0.00025370340306410486,25.0,60.0
842.20483,0.18074880905511811,922.782714138287,0.00025370340306410486,25.0,60.0
843.7063,0.18129021456692912,922.6663054695563,0.00025370340306410486,25.0,60.0
845.20776,0.18182078937007873,924.1099845201239,0.00025370340306410486,25.0,60.0
846.70923,0.18241200196850393,924.5211042311662,0.00025370340306410486,25.0,60.0
848.21069,0.18298340748031497,924.0359907120744,0.00025370340306410486,25.0,60.0
849.71216,0.18355619881889765,924.6720330237358,0.00025370340306410486,25.0,60.0
851.21362,0.18416337992125983,923.2457430340557,0.00025370340306410486,25.0,60.0
852.71509,0.18462184448818897,922.629411764706,0.00025370340306410486,25.0,60.0
854.21655,0.1852224311023622,924.6324045407637,0.00025370340306410486,25.0,60.0
855.71802,0.1857401811023622,922.5501547987616,0.00025370340306410486,25.0,60.0
857.21948,0.18626296653543306,924.1361971104232,0.00025370340306410486,25.0,60.0
858.72095,0.18674619881889765,923.5242002063984,0.00025370340306410486,25.0,60.0
860.22241,0.1872764094488189,922.5091073271415,0.00025370340306410486,25.0,60.0
861.72388,0.1878569094488189,926.4811661506709,0.00025370340306410486,25.0,60.0
863.22534,0.18841821456692914,924.1549019607843,0.00025370340306410486,25.0,60.0
864.72681,0.18896094488188978,923.567492260062,0.00025370340306410486,25.0,60.0
866.22827,0.18950428543307085,921.9967492260063,0.00025370340306410486,25.0,60.0
867.72974,0.1899536909448819,923.1487358101135,0.00025370340306410486,25.0,60.0
869.2312,0.19051046653543308,925.0942466460269,0.00025370340306410486,25.0,60.0
870.73267,0.19116336023622046,926.2539215686274,0.00025370340306410486,25.0,60.0
872.23413,0.19176249212598426,924.4883126934984,0.00025370340306410486,25.0,60.0
873.7356,0.19226557677165354,923.7543601651187,0.00025370340306410486,25.0,60.0
875.23706,0.1928329114173228,925.1055727554179,0.00025370340306410486,25.0,60.0
876.73853,0.1934586437007874,922.608746130031,0.00025370340306410486,25.0,60.0
878.23999,0.193999437007874,924.1881578947368,0.00025370340306410486,25.0,60.0
879.74146,0.19450816535433071,922.017234262126,0.00025370340306410486,25.0,60.0
881.24292,0.19507189960629923,924.9067337461302,0.00025370340306410486,25.0,60.0
882.74438,0.19554271653543306,925.4971104231166,0.00025370340306410486,25.0,60.0
884.24585,0.19615243307086613,924.9547213622291,0.00025370340306410486,25.0,60.0
885.74731,0.1967550964566929,924.899742002064,0.00025370340306410486,25.0,60.0
887.24878,0.1973319094488189,923.7747162022704,0.00025370340306410486,25.0,60.0
888.75024,0.19787277559055116,923.3362487100103,0.00025370340306410486,25.0,60.0
890.25171,0.19845000000000002,924.7834623323014,0.00025370340306410486,25.0,60.0
891.75317,0.1991183464566929,923.8743550051599,0.00025370340306410486,25.0,60.0
893.25464,0.1997301377952756,923.7971878224974,0.00025370340306410486,25.0,60.0
894.7561,0.20035529527559054,923.7735036119711,0.00025370340306410486,25.0,60.0
896.25757,0.20091431102362206,924.3096749226006,0.00025370340306410486,25.0,60.0
897.75903,0.20146996062992123,924.1335655314757,0.00025370340306410486,25.0,60.0
899.2605,0.20207108267716536,923.7301083591332,0.00025370340306410486,25.0,60.0
900.76196,0.20270527559055118,923.5358101135191,0.00025370340306410486,25.0,60.0
902.26343,0.2033049803149606,923.8392156862745,0.00025370340306410486,25.0,60.0
903.76489,0.20396702755905513,924.9971878224974,0.00025370340306410486,25.0,60.0
905.26636,0.2045932086614173,923.8169762641899,0.00025370340306410486,25.0,60.0
906.76782,0.20529352362204725,925.6292569659443,0.00025370340306410486,25.0,60.0
908.26929,0.20593265748031495,922.8011093911249,0.00025370340306410486,25.0,60.0
909.77075,0.20644970472440946,924.5461300309598,0.00025370340306410486,25.0,60.0
911.27222,0.2070898622047244,924.9233488132095,0.00025370340306410486,25.0,60.0
912.77368,0.2076537598425197,923.9697110423117,0.00025370340306410486,25.0,60.0
914.27515,0.20827602362204725,922.8537151702787,0.00025370340306410486,25.0,60.0
915.77661,0.20898070866141732,925.4125128998969,0.00025370340306410486,25.0,60.0
917.27808,0.20960322834645667,922.6688338493292,0.00025370340306410486,25.0,60.0
918.77954,0.21027616141732283,923.9983746130031,0.00025370340306410486,25.0,60.0
920.28101,0.2109359251968504,925.0538699690403,0.00025370340306410486,25.0,60.0
921.78247,0.21156950787401574,923.5528637770898,0.00025370340306410486,25.0,60.0
923.28394,0.21225515748031495,922.8086687306502,0.00025370340306410486,25.0,60.0
924.7854,0.21282214566929133,923.4622807017545,0.00025370340306410486,25.0,60.0
925.58618,0.21321968503937008,927.2983746130031,0.00025370340306410486,25.0,60.0