File: datasets/am_bench_2022/csv/60-XY.15-2.csv
Time(s),Strain(%),Stress(MPa),SR(s-1),Temp(C),Angle(deg)
17.709961,1.6933616929133856e-05,13.89432229580574,0.00025370340306410486,25.0,60.0
19.211426,3.181967125984252e-05,20.153458252175046,0.00025370340306410486,25.0,60.0
20.812988,5.756774606299212e-06,24.166977535385016,0.00025370340306410486,25.0,60.0
22.214355,5.913812992125984e-05,28.736517335410984,0.00025370340306410486,25.0,60.0
23.615723,4.959477165354331e-05,33.24808985845994,0.00025370340306410486,25.0,60.0
25.01709,8.671592913385827e-05,38.7651162186729,0.00025370340306410486,25.0,60.0
26.418457,9.20229311023622e-05,43.086121282950266,0.00025370340306410486,25.0,60.0
27.819824,0.00010375233661417323,50.69280872613946,0.00025370340306410486,25.0,60.0
29.221191,0.0001540476181102362,56.45827295156474,0.00025370340306410486,25.0,60.0
30.622559,0.00015481475590551182,62.603290481755614,0.00025370340306410486,25.0,60.0
32.023926,0.00016156486220472442,67.39060381768603,0.00025370340306410486,25.0,60.0
33.425293,0.00020172874015748029,76.61488637839243,0.00025370340306410486,25.0,60.0
34.82666,0.0001999097244094488,81.88611608881963,0.00025370340306410486,25.0,60.0
36.228027,0.00020470267716535433,88.37522919101416,0.00025370340306410486,25.0,60.0
37.629395,0.0002534816535433071,97.82522529541619,0.00025370340306410486,25.0,60.0
39.030762,0.00027609346456692913,106.15032073756656,0.00025370340306410486,25.0,60.0
40.432129,0.0002860677755905512,115.80280742760681,0.00025370340306410486,25.0,60.0
41.833496,0.00030683173228346453,124.0926529022205,0.00025370340306410486,25.0,60.0
43.234863,0.00034259933070866143,130.01832489287105,0.00025370340306410486,25.0,60.0
44.63623,0.00033906698818897635,140.0409453317751,0.00025370340306410486,25.0,60.0
46.037598,0.00036004472440944883,147.87463965718737,0.00025370340306410486,25.0,60.0
47.438965,0.0004037786614173228,156.48458122321776,0.00025370340306410486,25.0,60.0
48.840332,0.0004291613188976378,165.9941462147773,0.00025370340306410486,25.0,60.0
50.241699,0.00045469364173228346,173.6646201791975,0.00025370340306410486,25.0,60.0
51.643066,0.0005111411417322835,184.36897026360214,0.00025370340306410486,25.0,60.0
53.044434,0.0005259575984251968,193.56902220490846,0.00025370340306410486,25.0,60.0
54.445801,0.0005492512401574803,202.9759355927802,0.00025370340306410486,25.0,60.0
55.847168,0.0005971628346456692,212.18223347617194,0.00025370340306410486,25.0,60.0
57.248535,0.0006270918503937009,222.47017270484355,0.00025370340306410486,25.0,60.0
58.649902,0.0006511421456692914,232.53779509154657,0.00025370340306410486,25.0,60.0
60.05127,0.0006925143700787402,241.5243786521231,0.00025370340306410486,25.0,60.0
61.452637,0.0007203122047244095,254.04334761719258,0.00025370340306410486,25.0,60.0
62.854004,0.0007378664763779528,259.9292819114401,0.00025370340306410486,25.0,60.0
64.255371,0.0008007107283464567,271.2331645240878,0.00025370340306410486,25.0,60.0
65.656738,0.0008148989960629921,281.55514868198935,0.00025370340306410486,25.0,60.0
67.058105,0.0008438164763779528,290.0626152447734,0.00025370340306410486,25.0,60.0
68.459473,0.0008957243307086614,301.81269964939617,0.00025370340306410486,25.0,60.0
69.86084,0.0009325300787401575,310.84129333852746,0.00025370340306410486,25.0,60.0
71.262207,0.0009504868307086614,321.48850798597584,0.00025370340306410486,25.0,60.0
72.663574,0.0009992430314960628,331.29531229710426,0.00025370340306410486,25.0,60.0
74.064941,0.0010348769291338583,342.6810284378653,0.00025370340306410486,25.0,60.0
75.466309,0.0010618051771653543,352.0117906765355,0.00025370340306410486,25.0,60.0
76.867676,0.0011097103543307085,361.18195039605246,0.00025370340306410486,25.0,60.0
78.269043,0.0011377712992125984,372.60428515777176,0.00025370340306410486,25.0,60.0
79.67041,0.0011802613385826772,383.1998182054279,0.00025370340306410486,25.0,60.0
81.071777,0.0012151577952755905,391.48243085313595,0.00025370340306410486,25.0,60.0
82.473145,0.001251761062992126,401.38135307102976,0.00025370340306410486,25.0,60.0
83.874512,0.001291578031496063,415.03565770679137,0.00025370340306410486,25.0,60.0
85.275879,0.0013341205905511811,424.2564861706272,0.00025370340306410486,25.0,60.0
86.677246,0.0013694219291338584,433.55948578106745,0.00025370340306410486,25.0,60.0
88.078613,0.0013895485826771652,441.53821581612783,0.00025370340306410486,25.0,60.0
89.47998,0.0014347232283464567,452.2480976496559,0.00025370340306410486,25.0,60.0
90.881348,0.0014608313385826772,459.50931047915856,0.00025370340306410486,25.0,60.0
92.282715,0.0015033958070866142,470.88902739903915,0.00025370340306410486,25.0,60.0
93.684082,0.001525259251968504,477.38872873652775,0.00025370340306410486,25.0,60.0
95.085449,0.0015360182283464566,483.88185949876646,0.00025370340306410486,25.0,60.0
96.486816,0.0016130910236220471,497.1932216595248,0.00025370340306410486,25.0,60.0
97.888184,0.0016467209448818897,505.3907284768212,0.00025370340306410486,25.0,60.0
99.289551,0.001680473681102362,513.0732112712635,0.00025370340306410486,25.0,60.0
100.69092,0.001697040590551181,520.385560316842,0.00025370340306410486,25.0,60.0
102.09229,0.0017417457283464566,530.5875081158291,0.00025370340306410486,25.0,60.0
103.49365,0.001750165590551181,536.4530580444099,0.00025370340306410486,25.0,60.0
104.89502,0.0018064040748031495,546.797273081418,0.00025370340306410486,25.0,60.0
106.29639,0.00182966405511811,554.1381638748214,0.00025370340306410486,25.0,60.0
107.69775,0.0018587935433070867,560.6738865082457,0.00025370340306410486,25.0,60.0
109.09912,0.001889391338582677,567.671055707051,0.00025370340306410486,25.0,60.0
110.50049,0.0019288253346456694,575.8697571743929,0.00025370340306410486,25.0,60.0
111.90186,0.001982215748031496,582.537280872614,0.00025370340306410486,25.0,60.0
113.30322,0.0019807765748031496,586.9403713803403,0.00025370340306410486,25.0,60.0
114.70459,0.002031792125984252,594.8885079859758,0.00025370340306410486,25.0,60.0
116.10596,0.0020579364173228345,599.1801843916376,0.00025370340306410486,25.0,60.0
117.50732,0.0020826883858267716,604.3967536683548,0.00025370340306410486,25.0,60.0
118.90869,0.002132283661417323,613.0926113491754,0.00025370340306410486,25.0,60.0
120.31006,0.002153263779527559,617.8161537462668,0.00025370340306410486,25.0,60.0
121.71143,0.002162753937007874,622.6361251785482,0.00025370340306410486,25.0,60.0
123.11279,0.002203141338582677,626.8102064666928,0.00025370340306410486,25.0,60.0
124.51416,0.002245192716535433,630.5872484092976,0.00025370340306410486,25.0,60.0
125.91553,0.0022912472440944883,637.5161927022465,0.00025370340306410486,25.0,60.0
127.31689,0.002317458661417323,639.1344760420724,0.00025370340306410486,25.0,60.0
128.71826,0.002355648622047244,644.9567069211791,0.00025370340306410486,25.0,60.0
130.11963,0.002403522244094488,649.5397221140113,0.00025370340306410486,25.0,60.0
131.521,0.0024481395669291336,653.4835735618751,0.00025370340306410486,25.0,60.0
132.92236,0.0024785543307086614,654.4349824698091,0.00025370340306410486,25.0,60.0
134.32373,0.0025199755905511807,659.3701597195169,0.00025370340306410486,25.0,60.0
135.7251,0.002559296653543307,665.1236982210103,0.00025370340306410486,25.0,60.0
137.12646,0.0025927271653543305,666.2698091156993,0.00025370340306410486,25.0,60.0
138.52783,0.0026522537401574803,669.5575379820802,0.00025370340306410486,25.0,60.0
139.9292,0.0027255395669291338,673.8980651863395,0.00025370340306410486,25.0,60.0
141.33057,0.0027943555118110234,677.8380989481886,0.00025370340306410486,25.0,60.0
142.73193,0.002841714566929134,680.9455135696663,0.00025370340306410486,25.0,60.0
144.1333,0.002913318307086614,685.3531749123491,0.00025370340306410486,25.0,60.0
145.53467,0.002977186220472441,689.0735748604077,0.00025370340306410486,25.0,60.0
146.93604,0.003058932086614173,689.9677704194261,0.00025370340306410486,25.0,60.0
148.3374,0.00312887874015748,693.5574600701208,0.00025370340306410486,25.0,60.0
149.73877,0.003208262598425197,698.0670042851579,0.00025370340306410486,25.0,60.0
151.14014,0.0033140269685039366,701.1911440072718,0.00025370340306410486,25.0,60.0
152.5415,0.0034163738188976375,701.7825217504221,0.00025370340306410486,25.0,60.0
153.94287,0.003515289173228346,705.3476691338788,0.00025370340306410486,25.0,60.0
155.34424,0.003610717125984252,708.9016231658227,0.00025370340306410486,25.0,60.0
156.74561,0.003755205511811024,711.0041293338528,0.00025370340306410486,25.0,60.0
158.14697,0.0038482293307086617,713.0626412154267,0.00025370340306410486,25.0,60.0
159.54834,0.003978637598425197,715.5949616932867,0.00025370340306410486,25.0,60.0
160.94971,0.004110848622047244,717.479366316063,0.00025370340306410486,25.0,60.0
162.35107,0.004243773031496063,718.7969094922738,0.00025370340306410486,25.0,60.0
163.75244,0.004368629330708662,720.2210621997144,0.00025370340306410486,25.0,60.0
165.15381,0.004525042322834645,723.2445916114791,0.00025370340306410486,25.0,60.0
166.55518,0.0046734324803149605,725.0178418387222,0.00025370340306410486,25.0,60.0
167.95654,0.004867096456692913,727.7552785352552,0.00025370340306410486,25.0,60.0
169.35791,0.005034346259842519,730.2251395922608,0.00025370340306410486,25.0,60.0
170.75928,0.005248115354330709,731.8245422672381,0.00025370340306410486,25.0,60.0
172.16064,0.005414725196850393,734.1251266069341,0.00025370340306410486,25.0,60.0
173.56201,0.005631630511811024,736.7927541877679,0.00025370340306410486,25.0,60.0
174.96338,0.005860912401574803,738.0754966887417,0.00025370340306410486,25.0,60.0
176.36475,0.006109383267716535,740.5744708479418,0.00025370340306410486,25.0,60.0
177.76611,0.006319058070866141,741.9037008180757,0.00025370340306410486,25.0,60.0
179.16748,0.0065115338582677155,740.7509933774835,0.00025370340306410486,25.0,60.0
180.56885,0.006735744291338582,745.7137514608493,0.00025370340306410486,25.0,60.0
181.97021,0.0070041801181102365,746.4475522659395,0.00025370340306410486,25.0,60.0
183.37158,0.007226955314960631,745.7446305674588,0.00025370340306410486,25.0,60.0
184.77295,0.0074905108267716534,749.3169458511883,0.00025370340306410486,25.0,60.0
186.17432,0.007785927952755905,749.2043890403844,0.00025370340306410486,25.0,60.0
187.57568,0.008030233661417323,751.2589014413713,0.00025370340306410486,25.0,60.0
188.97705,0.008317681496062993,752.6714452668485,0.00025370340306410486,25.0,60.0
190.37842,0.008564818503937007,753.2127256200495,0.00025370340306410486,25.0,60.0
191.77979,0.008802531692913385,752.8244383846254,0.00025370340306410486,25.0,60.0
193.18115,0.009055753937007874,756.369666277107,0.00025370340306410486,25.0,60.0
194.58252,0.009339535236220473,758.7442410076613,0.00025370340306410486,25.0,60.0
195.98389,0.009617354724409449,758.3339306583562,0.00025370340306410486,25.0,60.0
197.38525,0.009879343700787403,759.2184391637451,0.00025370340306410486,25.0,60.0
198.78662,0.010224908464566928,761.4998831320607,0.00025370340306410486,25.0,60.0
200.18799,0.010455455511811023,759.1803402155565,0.00025370340306410486,25.0,60.0
201.58936,0.01075833188976378,762.1954811063499,0.00025370340306410486,25.0,60.0
202.99072,0.011043416929133859,763.841864692897,0.00025370340306410486,25.0,60.0
204.39209,0.011314838188976377,765.0465653811193,0.00025370340306410486,25.0,60.0
205.79346,0.011658436811023621,767.0369562394495,0.00025370340306410486,25.0,60.0
207.19482,0.011922925,765.5548110634983,0.00025370340306410486,25.0,60.0
208.59619,0.012231600590551181,768.6857550967408,0.00025370340306410486,25.0,60.0
209.99756,0.012520973425196851,768.1414102064667,0.00025370340306410486,25.0,60.0
211.39893,0.012840046062992126,767.7038047006884,0.00025370340306410486,25.0,60.0
212.80029,0.013161016535433072,769.2208284638358,0.00025370340306410486,25.0,60.0
214.20166,0.013452810826771654,770.0395792754189,0.00025370340306410486,25.0,60.0
215.60303,0.013744071456692913,772.1499285807039,0.00025370340306410486,25.0,60.0
217.00439,0.014100006692913385,773.2016361511493,0.00025370340306410486,25.0,60.0
218.40576,0.014434922047244095,771.7288663809895,0.00025370340306410486,25.0,60.0
219.80713,0.01480138937007874,774.6657057524998,0.00025370340306410486,25.0,60.0
221.2085,0.015123860236220471,775.1442410076614,0.00025370340306410486,25.0,60.0
222.60986,0.01543407125984252,776.4941955590183,0.00025370340306410486,25.0,60.0
224.01123,0.015697777952755905,777.965822620439,0.00025370340306410486,25.0,60.0
225.4126,0.01605438346456693,778.1860797299053,0.00025370340306410486,25.0,60.0
226.81396,0.016411349803149605,778.809297493832,0.00025370340306410486,25.0,60.0
228.21533,0.016704707677165354,778.2309829892222,0.00025370340306410486,25.0,60.0
229.6167,0.016984862795275592,779.3294637060123,0.00025370340306410486,25.0,60.0
231.01807,0.017353814566929134,781.10201272562,0.00025370340306410486,25.0,60.0
232.41943,0.017675993503937008,781.6265679781847,0.00025370340306410486,25.0,60.0
233.8208,0.018003318897637795,780.3815348656019,0.00025370340306410486,25.0,60.0
235.22217,0.018251863188976376,782.7897156213479,0.00025370340306410486,25.0,60.0
236.62354,0.018552473622047243,782.7473055447344,0.00025370340306410486,25.0,60.0
238.0249,0.01887352618110236,783.3495390209065,0.00025370340306410486,25.0,60.0
239.42627,0.01923185374015748,784.6788728736528,0.00025370340306410486,25.0,60.0
240.82764,0.019575414960629922,787.5874561745229,0.00025370340306410486,25.0,60.0
242.229,0.019915958661417325,786.4309310479159,0.00025370340306410486,25.0,60.0
243.63037,0.020258175196850393,787.5248149590963,0.00025370340306410486,25.0,60.0
245.03174,0.020603818897637793,787.1463965718739,0.00025370340306410486,25.0,60.0
246.43311,0.02091860433070866,789.1508894948709,0.00025370340306410486,25.0,60.0
247.83447,0.021269068897637796,788.6893650175302,0.00025370340306410486,25.0,60.0
249.23584,0.021511206692913384,788.5628619659785,0.00025370340306410486,25.0,60.0
250.63721,0.021785683070866143,789.3236722503572,0.00025370340306410486,25.0,60.0
252.03857,0.022143179133858267,791.6245682378913,0.00025370340306410486,25.0,60.0
253.43994,0.022489082677165356,791.8497078301519,0.00025370340306410486,25.0,60.0
254.84131,0.022861452755905513,794.0276847162706,0.00025370340306410486,25.0,60.0
256.24268,0.02326648031496063,793.7660563563174,0.00025370340306410486,25.0,60.0
257.64404,0.023591015748031494,793.6235294117648,0.00025370340306410486,25.0,60.0
259.04541,0.023886053149606297,793.7987274379951,0.00025370340306410486,25.0,60.0
260.44678,0.02426629527559055,797.5480327230231,0.00025370340306410486,25.0,60.0
261.84814,0.02467691929133858,797.210414231918,0.00025370340306410486,25.0,60.0
263.24951,0.024996100393700784,793.5666536813401,0.00025370340306410486,25.0,60.0
264.65088,0.025294870078740157,796.2225684975978,0.00025370340306410486,25.0,60.0
266.05225,0.02566247440944882,796.7020906375795,0.00025370340306410486,25.0,60.0
267.45361,0.0259981437007874,798.059342942475,0.00025370340306410486,25.0,60.0
268.85498,0.026342037401574803,797.3033112582782,0.00025370340306410486,25.0,60.0
270.25635,0.026626236220472443,798.4284118945592,0.00025370340306410486,25.0,60.0
271.65771,0.02696531692913386,802.011063498247,0.00025370340306410486,25.0,60.0
273.05908,0.02724616338582677,799.6674717569148,0.00025370340306410486,25.0,60.0
274.46045,0.02754474015748031,799.7239838981951,0.00025370340306410486,25.0,60.0
275.86182,0.027843763779527558,800.6390338917024,0.00025370340306410486,25.0,60.0
277.26318,0.028127789370078742,801.4935982339956,0.00025370340306410486,25.0,60.0
278.66455,0.028470785433070866,802.6251395922608,0.00025370340306410486,25.0,60.0
280.06592,0.028838346456692917,805.5241397221141,0.00025370340306410486,25.0,60.0
281.46729,0.029209582677165353,803.1062978833918,0.00025370340306410486,25.0,60.0
282.86865,0.029503277559055116,804.0529541617973,0.00025370340306410486,25.0,60.0
284.27002,0.029821740157480316,804.3168939098819,0.00025370340306410486,25.0,60.0
285.67139,0.030184795275590547,805.3492014024154,0.00025370340306410486,25.0,60.0
287.07275,0.030521761811023625,805.8961173873523,0.00025370340306410486,25.0,60.0
288.47412,0.030925230314960632,809.8286975717439,0.00025370340306410486,25.0,60.0
289.87549,0.0313201437007874,806.9787040644072,0.00025370340306410486,25.0,60.0
291.27686,0.03162312598425197,808.0797818465135,0.00025370340306410486,25.0,60.0
292.67822,0.03192921456692913,808.5072587975588,0.00025370340306410486,25.0,60.0
294.07959,0.03221333267716535,807.2443578756007,0.00025370340306410486,25.0,60.0
295.48096,0.03251820078740158,809.9466822490587,0.00025370340306410486,25.0,60.0
296.88232,0.03286775590551181,810.1447084794182,0.00025370340306410486,25.0,60.0
298.28369,0.03324175393700787,812.8826386183614,0.00025370340306410486,25.0,60.0
299.68506,0.033614165354330705,811.9147643163226,0.00025370340306410486,25.0,60.0
301.08643,0.03392429133858268,812.8450590832359,0.00025370340306410486,25.0,60.0
302.48779,0.03426472440944882,814.1594857810675,0.00025370340306410486,25.0,60.0
303.88916,0.03459631889763779,813.0226464095573,0.00025370340306410486,25.0,60.0
305.29053,0.034911751968503935,813.6614465653812,0.00025370340306410486,25.0,60.0
306.69189,0.03521769094488189,814.66414751331,0.00025370340306410486,25.0,60.0
308.09326,0.03552992322834646,815.1787300350604,0.00025370340306410486,25.0,60.0
309.49463,0.03581162992125984,814.3117257499027,0.00025370340306410486,25.0,60.0
310.896,0.036188895669291336,816.7686014803273,0.00025370340306410486,25.0,60.0
312.29736,0.03653723622047244,817.5222438644332,0.00025370340306410486,25.0,60.0
313.69873,0.03689990157480315,817.3043241137515,0.00025370340306410486,25.0,60.0
315.1001,0.037230122047244095,817.6297104272172,0.00025370340306410486,25.0,60.0
316.50146,0.03757500590551181,815.9614595507077,0.00025370340306410486,25.0,60.0
317.90283,0.03787545669291338,817.753486560187,0.00025370340306410486,25.0,60.0
319.3042,0.03821060236220472,817.951876379691,0.00025370340306410486,25.0,60.0
320.70557,0.038486358267716535,817.4296065446047,0.00025370340306410486,25.0,60.0
322.10693,0.03879873622047244,819.6127515907026,0.00025370340306410486,25.0,60.0
323.5083,0.039148431102362206,820.1610959615634,0.00025370340306410486,25.0,60.0
324.90967,0.039525259842519686,822.9620049344242,0.00025370340306410486,25.0,60.0
326.31104,0.03990240354330708,821.3963381379042,0.00025370340306410486,25.0,60.0
327.7124,0.040237330708661416,822.2926373198286,0.00025370340306410486,25.0,60.0
329.11377,0.040574055118110235,821.6822490585638,0.00025370340306410486,25.0,60.0
330.51514,0.04089185433070866,823.4340475262953,0.00025370340306410486,25.0,60.0
331.9165,0.04117167125984252,823.403999480587,0.00025370340306410486,25.0,60.0
333.31787,0.04149526968503937,825.3058304116348,0.00025370340306410486,25.0,60.0
334.71924,0.04179863188976378,823.0687702895727,0.00025370340306410486,25.0,60.0
336.12061,0.04215313188976377,825.7715361641345,0.00025370340306410486,25.0,60.0
337.52197,0.04250978937007874,824.2534995455137,0.00025370340306410486,25.0,60.0
338.92334,0.042807785433070865,825.1161147902869,0.00025370340306410486,25.0,60.0
340.32471,0.04315152755905512,825.6764835735619,0.00025370340306410486,25.0,60.0
341.72607,0.04349636614173229,824.4778340475262,0.00025370340306410486,25.0,60.0
343.12744,0.04380120669291339,827.0495779768862,0.00025370340306410486,25.0,60.0
344.52881,0.04412586023622047,827.6925074665629,0.00025370340306410486,25.0,60.0
345.93018,0.04447445472440945,828.0812621737437,0.00025370340306410486,25.0,60.0
347.33154,0.04484042716535433,826.9152317880795,0.00025370340306410486,25.0,60.0
348.73291,0.045200279527559055,829.7372029606545,0.00025370340306410486,25.0,60.0
350.13428,0.04553570669291338,830.5260096091417,0.00025370340306410486,25.0,60.0
351.53564,0.04590972637795275,829.1023763147643,0.00025370340306410486,25.0,60.0
352.93701,0.04619578543307086,828.4912868458642,0.00025370340306410486,25.0,60.0
354.33838,0.04653203543307087,830.951408907934,0.00025370340306410486,25.0,60.0
355.73975,0.046871104330708666,833.0556810803791,0.00025370340306410486,25.0,60.0
357.14111,0.047237811023622046,831.3780547980782,0.00025370340306410486,25.0,60.0
358.54248,0.04753515551181102,832.5360083106091,0.00025370340306410486,25.0,60.0
359.94385,0.047861350393700784,832.9598753408649,0.00025370340306410486,25.0,60.0
361.34521,0.048226895669291336,835.4191663420336,0.00025370340306410486,25.0,60.0
362.74658,0.04860547834645669,835.2598883261915,0.00025370340306410486,25.0,60.0
364.14795,0.04896133464566929,833.4276068043112,0.00025370340306410486,25.0,60.0
365.54932,0.049266265748031494,835.6871055707052,0.00025370340306410486,25.0,60.0
366.95068,0.04961660826771654,835.4198675496689,0.00025370340306410486,25.0,60.0
368.35205,0.04993770472440945,835.9405531749123,0.00025370340306410486,25.0,60.0
369.75342,0.05029463976377952,836.5584988962473,0.00025370340306410486,25.0,60.0
371.15479,0.05061237401574803,835.6287754837035,0.00025370340306410486,25.0,60.0
372.55615,0.050919797244094483,837.0016880924555,0.00025370340306410486,25.0,60.0
373.95752,0.051245198818897636,837.6434748733931,0.00025370340306410486,25.0,60.0
375.35889,0.051538580708661415,836.4578106739385,0.00025370340306410486,25.0,60.0
376.76025,0.05183856496062992,836.5421373847553,0.00025370340306410486,25.0,60.0
378.16162,0.052121874015748026,837.1245552525647,0.00025370340306410486,25.0,60.0
379.56299,0.052465698818897635,840.14899363719,0.00025370340306410486,25.0,60.0
380.96436,0.052819395669291336,839.9771458252175,0.00025370340306410486,25.0,60.0
382.36572,0.05313224409448818,840.1858719646799,0.00025370340306410486,25.0,60.0
383.76709,0.053453685039370084,841.363744968186,0.00025370340306410486,25.0,60.0
385.16846,0.05380547637795276,843.2544864303337,0.00025370340306410486,25.0,60.0
386.56982,0.05416746259842519,842.1076743280095,0.00025370340306410486,25.0,60.0
387.97119,0.05454689763779527,842.4963511232309,0.00025370340306410486,25.0,60.0
389.37256,0.05488415551181102,841.9790936242047,0.00025370340306410486,25.0,60.0
390.77393,0.05522252952755905,842.5535385014933,0.00025370340306410486,25.0,60.0
392.17529,0.055562592519685046,842.9174392935982,0.00025370340306410486,25.0,60.0
393.57666,0.055895141732283465,844.324451369952,0.00025370340306410486,25.0,60.0
394.97803,0.05619998228346457,844.8364368263863,0.00025370340306410486,25.0,60.0
396.37939,0.05650854133858267,844.4915725230491,0.00025370340306410486,25.0,60.0
397.78076,0.05691073818897638,845.0896766653682,0.00025370340306410486,25.0,60.0
399.18213,0.05724476377952756,844.6414751330996,0.00025370340306410486,25.0,60.0
400.5835,0.05755358267716536,846.6352421763407,0.00025370340306410486,25.0,60.0
401.98486,0.05786486417322834,846.938241786781,0.00025370340306410486,25.0,60.0
403.38623,0.05817782283464567,845.3200883002208,0.00025370340306410486,25.0,60.0
404.7876,0.05847776574803149,846.3584209842878,0.00025370340306410486,25.0,60.0
406.18896,0.058791781496063,847.399662381509,0.00025370340306410486,25.0,60.0
407.59033,0.05914479724409449,848.8685625243476,0.00025370340306410486,25.0,60.0
408.9917,0.05950335236220473,848.2719127386055,0.00025370340306410486,25.0,60.0
410.39307,0.05981004527559055,849.5246591351773,0.00025370340306410486,25.0,60.0
411.79443,0.06012985826771654,849.5483184002079,0.00025370340306410486,25.0,60.0
413.1958,0.0605128937007874,849.1294637060122,0.00025370340306410486,25.0,60.0
414.59717,0.06084906102362205,851.076821192053,0.00025370340306410486,25.0,60.0
415.99854,0.061155263779527555,849.5652512660695,0.00025370340306410486,25.0,60.0
417.3999,0.0615421653543307,852.4066225165562,0.00025370340306410486,25.0,60.0
418.80127,0.06185991141732283,851.1188676795222,0.00025370340306410486,25.0,60.0
420.20264,0.0622125,853.2971302428257,0.00025370340306410486,25.0,60.0
421.604,0.06254868503937008,853.0822490585639,0.00025370340306410486,25.0,60.0
423.00537,0.06285597834645669,852.3667315932996,0.00025370340306410486,25.0,60.0
424.40674,0.06312036811023622,851.2147773016492,0.00025370340306410486,25.0,60.0
425.80811,0.06341324606299213,852.7655369432541,0.00025370340306410486,25.0,60.0
427.20947,0.06379930314960629,854.4620179197508,0.00025370340306410486,25.0,60.0
428.61084,0.064193687007874,855.204466952344,0.00025370340306410486,25.0,60.0
430.01221,0.06457803543307086,854.8107258797559,0.00025370340306410486,25.0,60.0
431.41357,0.06493458464566929,857.0381508894949,0.00025370340306410486,25.0,60.0
432.81494,0.0652810846456693,855.5440072717829,0.00025370340306410486,25.0,60.0
434.21631,0.06559904724409449,855.7125308401506,0.00025370340306410486,25.0,60.0
435.61768,0.06585985236220472,854.987949616933,0.00025370340306410486,25.0,60.0
437.01904,0.06613587598425197,854.593559278016,0.00025370340306410486,25.0,60.0
438.42041,0.06645752362204725,856.3038566419946,0.00025370340306410486,25.0,60.0
439.82178,0.06679484842519684,857.2863783924166,0.00025370340306410486,25.0,60.0
441.22314,0.06717686417322834,857.2460459680561,0.00025370340306410486,25.0,60.0
442.62451,0.06751789566929134,857.4805869367615,0.00025370340306410486,25.0,60.0
444.02588,0.06787532874015748,860.4380989481886,0.00025370340306410486,25.0,60.0
445.42725,0.06823826574803149,859.6201272562005,0.00025370340306410486,25.0,60.0
446.82861,0.06854688976377953,860.0245162965848,0.00025370340306410486,25.0,60.0
448.22998,0.06886155118110236,859.6477600311648,0.00025370340306410486,25.0,60.0
449.63135,0.06925051771653543,859.8954940916764,0.00025370340306410486,25.0,60.0
451.03271,0.06950713582677165,859.2292429554603,0.00025370340306410486,25.0,60.0
452.43408,0.06980653149606299,859.936008310609,0.00025370340306410486,25.0,60.0
453.83545,0.07013047834645669,859.616517335411,0.00025370340306410486,25.0,60.0
455.23682,0.07048792519685039,862.7844695494092,0.00025370340306410486,25.0,60.0
456.63818,0.07086751181102362,863.0088559927283,0.00025370340306410486,25.0,60.0
458.03955,0.07121724803149605,861.1710167510713,0.00025370340306410486,25.0,60.0
459.44092,0.07154749803149606,863.2202571094664,0.00025370340306410486,25.0,60.0
460.84229,0.07184271062992126,863.5610440202571,0.00025370340306410486,25.0,60.0
462.24365,0.07217626771653543,863.6658096351124,0.00025370340306410486,25.0,60.0
463.64502,0.07253149015748032,863.8946890014284,0.00025370340306410486,25.0,60.0
465.04639,0.07287252165354331,862.2180755746007,0.00025370340306410486,25.0,60.0
466.44775,0.07320360826771653,864.6802233476172,0.00025370340306410486,25.0,60.0
467.84912,0.07357391338582676,864.6726139462407,0.00025370340306410486,25.0,60.0
469.25049,0.07396641338582677,863.9976626412155,0.00025370340306410486,25.0,60.0
470.65186,0.07430246456692914,866.9367354888976,0.00025370340306410486,25.0,60.0
472.05322,0.07467719881889763,865.7831969874043,0.00025370340306410486,25.0,60.0
473.45459,0.07494912795275589,865.3847032852876,0.00025370340306410486,25.0,60.0
474.85596,0.07520208267716535,865.4770289572783,0.00025370340306410486,25.0,60.0
476.25732,0.07556470866141732,869.0820412933385,0.00025370340306410486,25.0,60.0
477.65869,0.0759017874015748,867.2055057784703,0.00025370340306410486,25.0,60.0
479.06006,0.076265,868.5079080638878,0.00025370340306410486,25.0,60.0
480.46143,0.0766011968503937,866.1240618101546,0.00025370340306410486,25.0,60.0
481.86279,0.07692924606299213,868.5181664718868,0.00025370340306410486,25.0,60.0
483.26416,0.07725923622047244,868.2577847032853,0.00025370340306410486,25.0,60.0
484.66553,0.07759279921259843,870.9283989092326,0.00025370340306410486,25.0,60.0
486.06689,0.07785147440944881,869.8129074146215,0.00025370340306410486,25.0,60.0
487.46826,0.0782541279527559,870.6657057524998,0.00025370340306410486,25.0,60.0
488.86963,0.07864618700787401,871.6864563043761,0.00025370340306410486,25.0,60.0
490.271,0.07898954133858267,869.4011686793923,0.00025370340306410486,25.0,60.0
491.67236,0.07930126968503938,869.7167121153097,0.00025370340306410486,25.0,60.0
493.07373,0.07963435826771653,871.2531619270225,0.00025370340306410486,25.0,60.0
494.4751,0.08000648818897638,872.0789248149591,0.00025370340306410486,25.0,60.0
495.87646,0.08033225393700787,871.5930658356059,0.00025370340306410486,25.0,60.0
497.27783,0.08065437204724409,872.4457862615245,0.00025370340306410486,25.0,60.0
498.6792,0.08101063188976378,873.4875990131152,0.00025370340306410486,25.0,60.0
500.08057,0.08138134251968503,872.4851837423711,0.00025370340306410486,25.0,60.0
501.48193,0.08170310236220472,873.0523828074276,0.00025370340306410486,25.0,60.0
502.8833,0.08203862992125985,875.4839111803662,0.00025370340306410486,25.0,60.0
504.28467,0.08239567125984251,873.4674457862616,0.00025370340306410486,25.0,60.0
505.68604,0.08273973622047244,873.2406960135048,0.00025370340306410486,25.0,60.0
507.0874,0.08308951377952756,876.0777041942605,0.00025370340306410486,25.0,60.0
508.48877,0.08346872047244094,874.738085962862,0.00025370340306410486,25.0,60.0
509.89014,0.08384636417322834,877.6624334502013,0.00025370340306410486,25.0,60.0
511.2915,0.0841840688976378,874.0941955590184,0.00025370340306410486,25.0,60.0
512.69287,0.08451865354330708,875.6762238670302,0.00025370340306410486,25.0,60.0
514.09424,0.08486635433070866,875.5790676535515,0.00025370340306410486,25.0,60.0
515.49561,0.08522120078740157,877.4444617582133,0.00025370340306410486,25.0,60.0
516.89697,0.0855635,876.6377613296975,0.00025370340306410486,25.0,60.0
518.29834,0.08592155118110235,876.1711466043372,0.00025370340306410486,25.0,60.0
519.69971,0.08625975393700787,877.9111024542267,0.00025370340306410486,25.0,60.0
521.10107,0.08660104330708662,877.850824568238,0.00025370340306410486,25.0,60.0
522.50244,0.08693772244094489,877.6751850409038,0.00025370340306410486,25.0,60.0
523.90381,0.08721046062992126,879.3981560836256,0.00025370340306410486,25.0,60.0
525.30518,0.08753240157480316,877.6527463965718,0.00025370340306410486,25.0,60.0
526.70654,0.08789141929133858,880.0366445916114,0.00025370340306410486,25.0,60.0
528.10791,0.08823416338582676,879.0222828204129,0.00025370340306410486,25.0,60.0
529.50928,0.08853890354330708,877.6600960914167,0.00025370340306410486,25.0,60.0
530.91064,0.08885981889763779,880.2755486300481,0.00025370340306410486,25.0,60.0
532.31201,0.08920988385826771,881.2124139722115,0.00025370340306410486,25.0,60.0
533.71338,0.08955907677165353,880.2218932606156,0.00025370340306410486,25.0,60.0
535.11475,0.08993802362204724,881.0788728736528,0.00025370340306410486,25.0,60.0
536.51611,0.09027699015748031,881.211842617842,0.00025370340306410486,25.0,60.0
537.91748,0.09065776771653543,881.8037397740553,0.00025370340306410486,25.0,60.0
539.31885,0.0910715905511811,882.2024931827036,0.00025370340306410486,25.0,60.0
540.72021,0.09146278149606299,882.481158291131,0.00025370340306410486,25.0,60.0
542.12158,0.09183741141732282,882.1611479028699,0.00025370340306410486,25.0,60.0
543.52295,0.09215045275590551,881.1997922347747,0.00025370340306410486,25.0,60.0
544.92432,0.09247433070866141,883.3898714452669,0.00025370340306410486,25.0,60.0
546.32568,0.09283783661417322,884.8439942864563,0.00025370340306410486,25.0,60.0
547.72705,0.09319762992125984,883.847448383327,0.00025370340306410486,25.0,60.0
549.12842,0.09357591929133859,884.9408648227504,0.00025370340306410486,25.0,60.0
550.52979,0.09390029527559055,885.1691468640437,0.00025370340306410486,25.0,60.0
551.93115,0.09420802755905511,885.1956888715752,0.00025370340306410486,25.0,60.0
553.33252,0.09455463188976378,883.6135047396442,0.00025370340306410486,25.0,60.0
554.73389,0.09494226771653544,886.3211271263473,0.00025370340306410486,25.0,60.0
556.13525,0.09529130118110236,884.9591481625763,0.00025370340306410486,25.0,60.0
557.53662,0.09562075196850393,886.1972471107648,0.00025370340306410486,25.0,60.0
558.93799,0.09591145866141731,885.2859888326192,0.00025370340306410486,25.0,60.0
560.33936,0.09622483464566929,886.3386313465784,0.00025370340306410486,25.0,60.0
561.74072,0.09655030905511812,885.6908972860668,0.00025370340306410486,25.0,60.0
563.14209,0.09695205905511811,887.6135826516038,0.00025370340306410486,25.0,60.0
564.54346,0.09730773818897638,888.4827944422802,0.00025370340306410486,25.0,60.0
565.94482,0.09769237598425197,888.4513439813012,0.00025370340306410486,25.0,60.0
567.34619,0.09804385039370078,887.553798208025,0.00025370340306410486,25.0,60.0
568.74756,0.09844078937007873,889.540319439034,0.00025370340306410486,25.0,60.0
570.14893,0.09877659448818897,886.8408778080769,0.00025370340306410486,25.0,60.0
571.55029,0.09913203937007875,888.9817426308272,0.00025370340306410486,25.0,60.0
572.95166,0.0995341003937008,889.499753278795,0.00025370340306410486,25.0,60.0
574.35303,0.09992685826771652,889.6719646799118,0.00025370340306410486,25.0,60.0
575.75439,0.10034638976377952,890.6693156732892,0.00025370340306410486,25.0,60.0
577.15576,0.10074233858267717,891.2028827425011,0.00025370340306410486,25.0,60.0
578.55713,0.10110982283464566,889.2722503570966,0.00025370340306410486,25.0,60.0
579.9585,0.10142849606299212,889.7945201921829,0.00025370340306410486,25.0,60.0
581.35986,0.10173454527559056,889.6838072977536,0.00025370340306410486,25.0,60.0
582.76123,0.10206394291338583,891.0791066095313,0.00025370340306410486,25.0,60.0
584.1626,0.10244020275590551,891.7485261654332,0.00025370340306410486,25.0,60.0
585.56396,0.10278506496062993,892.6787430203871,0.00025370340306410486,25.0,60.0
586.96533,0.10318825393700787,893.0213998182055,0.00025370340306410486,25.0,60.0
588.3667,0.10352255511811023,891.4741202441242,0.00025370340306410486,25.0,60.0
589.76807,0.10385489763779526,891.9159329957148,0.00025370340306410486,25.0,60.0
591.16943,0.10416946456692913,892.0369562394495,0.00025370340306410486,25.0,60.0
592.5708,0.10451151181102361,893.6125178548241,0.00025370340306410486,25.0,60.0
593.97217,0.10483397440944882,892.8027009479289,0.00025370340306410486,25.0,60.0
595.37354,0.10518492716535432,894.3883911180367,0.00025370340306410486,25.0,60.0
596.7749,0.10554579330708662,895.39597454876,0.00025370340306410486,25.0,60.0
598.17627,0.10589114763779527,894.6201532268536,0.00025370340306410486,25.0,60.0
599.57764,0.10618393897637796,892.8320737566551,0.00025370340306410486,25.0,60.0
600.979,0.10656892716535432,894.3542137384756,0.00025370340306410486,25.0,60.0
602.38037,0.10698343897637795,895.3210751850409,0.00025370340306410486,25.0,60.0
603.78174,0.10741922047244094,896.12829502662,0.00025370340306410486,25.0,60.0
605.18311,0.10782687992125985,895.0239189715622,0.00025370340306410486,25.0,60.0
606.58447,0.10816204921259842,895.1755096740684,0.00025370340306410486,25.0,60.0
607.98584,0.10847507874015748,895.8618620958317,0.00025370340306410486,25.0,60.0
609.38721,0.10884948622047246,896.3804440981692,0.00025370340306410486,25.0,60.0
610.78857,0.10929396259842518,897.8880924555253,0.00025370340306410486,25.0,60.0
612.18994,0.10968941929133859,897.2755486300481,0.00025370340306410486,25.0,60.0
613.59131,0.11004979133858268,895.7715101934814,0.00025370340306410486,25.0,60.0
614.99268,0.11041876574803149,899.8892871055708,0.00025370340306410486,25.0,60.0
616.39404,0.11079482677165355,895.5916893909882,0.00025370340306410486,25.0,60.0
617.79541,0.11113584055118111,896.756369302688,0.00025370340306410486,25.0,60.0
619.19678,0.11146250393700788,898.9252045188937,0.00025370340306410486,25.0,60.0
620.59814,0.11182761811023621,898.7453317750942,0.00025370340306410486,25.0,60.0
621.99951,0.11223045472440946,898.1654330606415,0.00025370340306410486,25.0,60.0
623.40088,0.11261726181102363,898.4244383846254,0.00025370340306410486,25.0,60.0
624.80225,0.11298911023622048,898.0500973899493,0.00025370340306410486,25.0,60.0
626.20361,0.11335921062992126,899.0586677054929,0.00025370340306410486,25.0,60.0
627.60498,0.11374267519685038,898.845396701727,0.00025370340306410486,25.0,60.0
629.00635,0.11411457086614174,899.7936112193222,0.00025370340306410486,25.0,60.0
630.40771,0.11448768700787401,899.1958966368004,0.00025370340306410486,25.0,60.0
631.80908,0.11481451377952756,898.8335281132321,0.00025370340306410486,25.0,60.0
633.21045,0.11522113976377953,900.4931567328919,0.00025370340306410486,25.0,60.0
634.61182,0.11557779527559055,899.5341643942346,0.00025370340306410486,25.0,60.0
636.01318,0.11599224606299213,901.0690040254514,0.00025370340306410486,25.0,60.0
637.41455,0.11636106692913387,900.0647188676795,0.00025370340306410486,25.0,60.0
638.81592,0.11675700393700789,900.6644591611479,0.00025370340306410486,25.0,60.0
640.21729,0.11711411614173228,900.3777431502403,0.00025370340306410486,25.0,60.0
641.61865,0.11754791535433072,903.7389170237632,0.00025370340306410486,25.0,60.0
643.02002,0.11793006496062991,901.1962602259447,0.00025370340306410486,25.0,60.0
644.42139,0.11831059645669291,901.7034930528504,0.00025370340306410486,25.0,60.0
645.82275,0.11875527362204724,903.2430853135957,0.00025370340306410486,25.0,60.0
647.22412,0.11913502952755906,902.1897415920012,0.00025370340306410486,25.0,60.0
648.62549,0.11948631102362205,903.071834826646,0.00025370340306410486,25.0,60.0
650.02686,0.11991262401574804,901.0713933255422,0.00025370340306410486,25.0,60.0
651.42822,0.12031506102362204,904.9190754447475,0.00025370340306410486,25.0,60.0
652.82959,0.1206551122047244,903.6558628749513,0.00025370340306410486,25.0,60.0
654.23096,0.12104357480314959,904.1658226204389,0.00025370340306410486,25.0,60.0
655.63232,0.12138652559055119,903.459031294637,0.00025370340306410486,25.0,60.0
657.03369,0.12178824606299213,902.564394234515,0.00025370340306410486,25.0,60.0
658.43506,0.12217958464566929,904.078561225815,0.00025370340306410486,25.0,60.0
659.83643,0.12256280118110235,903.4620958317103,0.00025370340306410486,25.0,60.0
661.23779,0.12292920669291338,905.8299961044021,0.00025370340306410486,25.0,60.0
662.63916,0.12333163188976377,904.9510972600962,0.00025370340306410486,25.0,60.0
664.04053,0.12374968503937007,904.9796130372679,0.00025370340306410486,25.0,60.0
665.44189,0.12412126377952755,905.2954940916765,0.00025370340306410486,25.0,60.0
666.84326,0.12446604330708662,904.6349564991559,0.00025370340306410486,25.0,60.0
668.24463,0.12486944291338582,906.0606674457863,0.00025370340306410486,25.0,60.0
669.646,0.1252365157480315,905.2805349954552,0.00025370340306410486,25.0,60.0
671.04736,0.12566306496062993,904.9977405531749,0.00025370340306410486,25.0,60.0
672.44873,0.1260483937007874,906.0748733930659,0.00025370340306410486,25.0,60.0
673.8501,0.12651193700787403,907.3578756005714,0.00025370340306410486,25.0,60.0
675.25146,0.12686751181102363,906.2518374237112,0.00025370340306410486,25.0,60.0
676.65283,0.12724252952755905,906.7590702506169,0.00025370340306410486,25.0,60.0
678.0542,0.12763745669291338,906.1469679262434,0.00025370340306410486,25.0,60.0
679.45557,0.12801930118110236,906.5341124529282,0.00025370340306410486,25.0,60.0
680.85693,0.12836239173228345,907.8848201532269,0.00025370340306410486,25.0,60.0
682.2583,0.1287481220472441,907.9250227243215,0.00025370340306410486,25.0,60.0
683.65967,0.12916337007874015,908.2993117776913,0.00025370340306410486,25.0,60.0
685.06104,0.12958736220472442,909.1064017660045,0.00025370340306410486,25.0,60.0
686.4624,0.13002030511811025,909.5387611998442,0.00025370340306410486,25.0,60.0
687.86377,0.1304320807086614,908.1922867160109,0.00025370340306410486,25.0,60.0
689.26514,0.13083103346456693,908.7936891312818,0.00025370340306410486,25.0,60.0
690.6665,0.1312116712598425,908.2064147513311,0.00025370340306410486,25.0,60.0
692.06787,0.13160185826771653,908.1662121802364,0.00025370340306410486,25.0,60.0
693.46924,0.13200838976377954,908.16919880535,0.00025370340306410486,25.0,60.0
694.87061,0.13237938188976378,908.8082067263992,0.00025370340306410486,25.0,60.0
696.27197,0.132806281496063,909.8539410466174,0.00025370340306410486,25.0,60.0
697.67334,0.13322668307086613,911.2652123100896,0.00025370340306410486,25.0,60.0
699.07471,0.13360124212598426,910.2117906765355,0.00025370340306410486,25.0,60.0
700.47607,0.13399773031496062,910.284196857551,0.00025370340306410486,25.0,60.0
701.87744,0.1343515216535433,909.656927671731,0.00025370340306410486,25.0,60.0
703.27881,0.13473898622047242,913.7233346318661,0.00025370340306410486,25.0,60.0
704.68018,0.13516810433070864,911.6158420984289,0.00025370340306410486,25.0,60.0
706.08154,0.13564009645669292,912.8536293987794,0.00025370340306410486,25.0,60.0
707.48291,0.13605424212598424,910.9788079470198,0.00025370340306410486,25.0,60.0
708.88428,0.136464905511811,911.9620828463837,0.00025370340306410486,25.0,60.0
710.28564,0.136850281496063,910.4985066874432,0.00025370340306410486,25.0,60.0
711.68701,0.13726101377952757,911.4142059472796,0.00025370340306410486,25.0,60.0
713.08838,0.13774119488188974,911.9676665368135,0.00025370340306410486,25.0,60.0
714.48975,0.1381700433070866,912.0331645240879,0.00025370340306410486,25.0,60.0
715.89111,0.13853731496062993,911.4020257109468,0.00025370340306410486,25.0,60.0
717.29248,0.13894221653543307,911.4587715881055,0.00025370340306410486,25.0,60.0
718.69385,0.1393466594488189,911.1127645760291,0.00025370340306410486,25.0,60.0
720.09521,0.13981157677165354,913.1698740423323,0.00025370340306410486,25.0,60.0
721.49658,0.14026331692913385,912.1795610959616,0.00025370340306410486,25.0,60.0
722.89795,0.14060047047244095,909.4043890403843,0.00025370340306410486,25.0,60.0
724.29932,0.14093803346456693,910.1453317750942,0.00025370340306410486,25.0,60.0
725.70068,0.1413198562992126,912.7793793013896,0.00025370340306410486,25.0,60.0
727.10205,0.14178633267716534,914.1236982210103,0.00025370340306410486,25.0,60.0
728.50342,0.14218112007874018,912.5376704324113,0.00025370340306410486,25.0,60.0
729.90479,0.14256674212598425,912.4023113881315,0.00025370340306410486,25.0,60.0
731.30615,0.14301381299212598,915.5402155564213,0.00025370340306410486,25.0,60.0
732.70752,0.14347674606299213,915.752993117777,0.00025370340306410486,25.0,60.0
734.10889,0.1438409901574803,913.4438644331906,0.00025370340306410486,25.0,60.0
735.51025,0.14431103543307086,914.5348136605636,0.00025370340306410486,25.0,60.0
736.91162,0.1446947224409449,914.0492403583951,0.00025370340306410486,25.0,60.0
738.31299,0.1450939783464567,914.3326061550449,0.00025370340306410486,25.0,60.0
739.71436,0.14553289566929134,915.567614595507,0.00025370340306410486,25.0,60.0
741.11572,0.14598197047244094,914.6665627840541,0.00025370340306410486,25.0,60.0
742.51709,0.14637327362204725,914.4663290481756,0.00025370340306410486,25.0,60.0
743.91846,0.1467606909448819,914.6092974938321,0.00025370340306410486,25.0,60.0
745.31982,0.14713852362204724,913.426931567329,0.00025370340306410486,25.0,60.0
746.72119,0.14750806102362204,915.2410076613427,0.00025370340306410486,25.0,60.0
748.12256,0.147985812992126,916.4319439033892,0.00025370340306410486,25.0,60.0
749.52393,0.1485124350393701,915.2475262952864,0.00025370340306410486,25.0,60.0
750.92529,0.1489750157480315,916.2530061031035,0.00025370340306410486,25.0,60.0
752.32666,0.14940411023622047,916.6557070510324,0.00025370340306410486,25.0,60.0
753.72803,0.14992153346456694,917.7847552265939,0.00025370340306410486,25.0,60.0
755.12939,0.15032962598425198,914.5899753278796,0.00025370340306410486,25.0,60.0
756.53076,0.150750531496063,916.7702116608234,0.00025370340306410486,25.0,60.0
757.93213,0.15117355905511812,916.8195299311778,0.00025370340306410486,25.0,60.0
759.3335,0.15161394094488187,914.0506947149721,0.00025370340306410486,25.0,60.0
760.73486,0.15203258267716535,915.9056226464096,0.00025370340306410486,25.0,60.0
762.13623,0.152536218503937,917.8156862745099,0.00025370340306410486,25.0,60.0
763.5376,0.15295298031496063,915.7625243474873,0.00025370340306410486,25.0,60.0
764.93896,0.15337355708661418,916.8852876249839,0.00025370340306410486,25.0,60.0
766.34033,0.1537893346456693,917.6545903129464,0.00025370340306410486,25.0,60.0
767.7417,0.15421243307086613,917.0971821841321,0.00025370340306410486,25.0,60.0
769.14307,0.15465612401574805,917.88131411505,0.00025370340306410486,25.0,60.0
770.54443,0.15509276377952755,917.5767822360732,0.00025370340306410486,25.0,60.0
771.9458,0.15551145078740158,917.6566679651993,0.00025370340306410486,25.0,60.0
773.34717,0.1559749940944882,916.7896636800416,0.00025370340306410486,25.0,60.0
774.74854,0.15642830708661418,919.3335410985586,0.00025370340306410486,25.0,60.0
776.1499,0.1569103779527559,917.300402545124,0.00025370340306410486,25.0,60.0
777.55127,0.15736154133858268,918.3219062459422,0.00025370340306410486,25.0,60.0
778.95264,0.15783498818897637,918.1048175561616,0.00025370340306410486,25.0,60.0
780.354,0.15835767913385826,920.1615374626672,0.00025370340306410486,25.0,60.0
781.75537,0.15887865551181102,919.4373457992469,0.00025370340306410486,25.0,60.0
783.15674,0.15936387007874017,917.0791066095312,0.00025370340306410486,25.0,60.0
784.55811,0.1597935649606299,916.868484612388,0.00025370340306410486,25.0,60.0
785.95947,0.16016774803149605,918.0194779898715,0.00025370340306410486,25.0,60.0
787.36084,0.16054515748031495,916.1956369302688,0.00025370340306410486,25.0,60.0
788.76221,0.16101622244094488,918.5397221140112,0.00025370340306410486,25.0,60.0
790.16357,0.16148600787401576,917.2294507206857,0.00025370340306410486,25.0,60.0
791.56494,0.16193472047244095,919.7633034670822,0.00025370340306410486,25.0,60.0
792.96631,0.1623926909448819,919.4865342163356,0.00025370340306410486,25.0,60.0
794.36768,0.16284758661417323,919.5742371120634,0.00025370340306410486,25.0,60.0
795.76904,0.16330363188976377,918.4581742630828,0.00025370340306410486,25.0,60.0
797.17041,0.1637440492125984,920.0948448253474,0.00025370340306410486,25.0,60.0
798.57178,0.16421912598425198,919.1014154005974,0.00025370340306410486,25.0,60.0
799.97314,0.16471198031496062,920.8152447734061,0.00025370340306410486,25.0,60.0
801.37451,0.1651730590551181,917.7851967276978,0.00025370340306410486,25.0,60.0
802.77588,0.16559300196850393,919.405116218673,0.00025370340306410486,25.0,60.0
804.17725,0.16608434251968504,919.3481885469421,0.00025370340306410486,25.0,60.0
805.57861,0.1665593248031496,919.319153356707,0.00025370340306410486,25.0,60.0
806.97998,0.16700131496062992,919.754291650435,0.00025370340306410486,25.0,60.0
808.38135,0.16744387992125984,920.3426827684717,0.00025370340306410486,25.0,60.0
809.78271,0.1679168208661417,920.1745487599013,0.00025370340306410486,25.0,60.0
811.18408,0.16834789763779529,918.6355278535256,0.00025370340306410486,25.0,60.0
812.58545,0.1688240905511811,920.1452538631347,0.00025370340306410486,25.0,60.0
813.98682,0.16933860236220472,921.4815218802753,0.00025370340306410486,25.0,60.0
815.38818,0.16981854921259842,920.8316841968576,0.00025370340306410486,25.0,60.0
816.78955,0.17032677165354332,920.2965329178029,0.00025370340306410486,25.0,60.0
818.19092,0.17084591929133858,920.6938839111805,0.00025370340306410486,25.0,60.0
819.59229,0.17127774803149606,919.6833398259967,0.00025370340306410486,25.0,60.0
820.99365,0.1717059625984252,920.1237501623166,0.00025370340306410486,25.0,60.0
822.39502,0.17214100590551182,921.2853395662902,0.00025370340306410486,25.0,60.0
823.79639,0.17258854527559053,920.52123100896,0.00025370340306410486,25.0,60.0
825.19775,0.17313622834645667,920.3127126347227,0.00025370340306410486,25.0,60.0
826.59912,0.17369237007874017,920.0124918841709,0.00025370340306410486,25.0,60.0
828.00049,0.17416764763779527,919.9786261524478,0.00025370340306410486,25.0,60.0
829.40186,0.17464528149606298,920.5784443578757,0.00025370340306410486,25.0,60.0
830.80322,0.17524082283464568,921.9971172574991,0.00025370340306410486,25.0,60.0
832.20459,0.17570129330708661,920.2528502791845,0.00025370340306410486,25.0,60.0
833.60596,0.17624073818897637,921.1064796779639,0.00025370340306410486,25.0,60.0
835.00732,0.17669719488188976,921.6573432021817,0.00025370340306410486,25.0,60.0
836.40869,0.1772255649606299,920.6122841189456,0.00025370340306410486,25.0,60.0
837.81006,0.1776585433070866,921.6020516815998,0.00025370340306410486,25.0,60.0
839.21143,0.17811930511811022,919.9317750941436,0.00025370340306410486,25.0,60.0
840.61279,0.17859655314960632,921.7010258407998,0.00025370340306410486,25.0,60.0
842.01416,0.1791252401574803,921.0217634073497,0.00025370340306410486,25.0,60.0
843.41553,0.17965078149606298,922.6732632125699,0.00025370340306410486,25.0,60.0
844.81689,0.1801901909448819,922.1561355668096,0.00025370340306410486,25.0,60.0
846.21826,0.1807445964566929,920.9654590312946,0.00025370340306410486,25.0,60.0
847.61963,0.18124771653543306,920.3374886378393,0.00025370340306410486,25.0,60.0
849.021,0.18171915551181103,921.1729905207117,0.00025370340306410486,25.0,60.0
850.42236,0.1822323188976378,922.9280353200883,0.00025370340306410486,25.0,60.0
851.82373,0.1827278248031496,921.1234644851318,0.00025370340306410486,25.0,60.0
853.2251,0.1832231181102362,921.6665368134009,0.00025370340306410486,25.0,60.0
854.62646,0.18371511417322836,921.0752629528633,0.00025370340306410486,25.0,60.0
856.02783,0.18419541338582676,921.9609661082976,0.00025370340306410486,25.0,60.0
857.4292,0.1847418149606299,922.9763407349695,0.00025370340306410486,25.0,60.0
858.83057,0.18525199803149606,921.3268666406962,0.00025370340306410486,25.0,60.0
860.23193,0.18574959251968504,920.9913777431503,0.00025370340306410486,25.0,60.0
861.6333,0.18631580118110236,921.805116218673,0.00025370340306410486,25.0,60.0
863.03467,0.18690976968503936,922.3205557719778,0.00025370340306410486,25.0,60.0
864.43604,0.18740537992125986,921.0880924555253,0.00025370340306410486,25.0,60.0
865.8374,0.1879563720472441,922.8964550058434,0.00025370340306410486,25.0,60.0
867.23877,0.18850178937007875,921.3844955200624,0.00025370340306410486,25.0,60.0
868.64014,0.18906513582677165,922.0378132710038,0.00025370340306410486,25.0,60.0
870.0415,0.18961248818897639,921.3198805349955,0.00025370340306410486,25.0,60.0
871.44287,0.19012844488188976,920.7854564342293,0.00025370340306410486,25.0,60.0
872.84424,0.19062753937007873,921.6999350733671,0.00025370340306410486,25.0,60.0
874.24561,0.191207031496063,921.8600960914167,0.00025370340306410486,25.0,60.0
875.64697,0.1917727224409449,921.3310998571615,0.00025370340306410486,25.0,60.0
877.04834,0.19228396259842517,921.8616803012596,0.00025370340306410486,25.0,60.0
878.44971,0.1928153464566929,921.30455784963,0.00025370340306410486,25.0,60.0
879.85107,0.1933489842519685,921.8442539929879,0.00025370340306410486,25.0,60.0
881.15234,0.19386648818897637,924.9562134787691,0.00025370340306410486,25.0,60.0