File: datasets/am_bench_2022/csv/60-XY.15-1.csv
Time(s),Strain(%),Stress(MPa),SR(s-1),Temp(C),Angle(deg)
12.190674,3.197513779527559e-05,14.715887547071809,0.00025370340306410486,25.0,60.0
13.692139,4.016028937007874e-05,20.25786053759252,0.00025370340306410486,25.0,60.0
15.093506,5.243902362204724e-05,24.244046227762627,0.00025370340306410486,25.0,60.0
16.494873,4.777009251968504e-05,28.92049863654071,0.00025370340306410486,25.0,60.0
17.89624,9.76265531496063e-05,32.90908972860667,0.00025370340306410486,25.0,60.0
19.297607,9.80024625984252e-05,36.99268926113492,0.00025370340306410486,25.0,60.0
20.698975,0.00010625456692913385,41.6632073756655,0.00025370340306410486,25.0,60.0
22.100342,0.00013474852362204724,48.975982339955856,0.00025370340306410486,25.0,60.0
23.501709,0.0001484792401574803,55.08273730684327,0.00025370340306410486,25.0,60.0
24.903076,0.00019964492125984252,64.01593299571485,0.00025370340306410486,25.0,60.0
26.304443,0.00021420811023622045,67.17275938189846,0.00025370340306410486,25.0,60.0
27.705811,0.00022246665354330709,74.38811323204779,0.00025370340306410486,25.0,60.0
29.107178,0.00023595055118110238,81.38518633943643,0.00025370340306410486,25.0,60.0
30.508545,0.00026614574803149603,85.96447214647448,0.00025370340306410486,25.0,60.0
31.909912,0.00029594749999999997,94.15093364498118,0.00025370340306410486,25.0,60.0
33.311279,0.0003295645275590551,100.38553954031944,0.00025370340306410486,25.0,60.0
34.712646,0.00035821338582677165,108.75161147902871,0.00025370340306410486,25.0,60.0
36.114014,0.0004091058070866142,117.16015582391898,0.00025370340306410486,25.0,60.0
37.515381,0.0004132413385826771,125.34766393974809,0.00025370340306410486,25.0,60.0
38.916748,0.0004564704724409448,132.224196857551,0.00025370340306410486,25.0,60.0
40.318115,0.0004844828937007874,143.41012336060254,0.00025370340306410486,25.0,60.0
41.719482,0.0005325687401574803,151.74208544344893,0.00025370340306410486,25.0,60.0
43.12085,0.000546466437007874,161.59912478898846,0.00025370340306410486,25.0,60.0
44.522217,0.0005773926771653543,171.4532294507207,0.00025370340306410486,25.0,60.0
45.923584,0.0006246436417322834,181.17030255810937,0.00025370340306410486,25.0,60.0
47.324951,0.0006598885236220472,190.46069341643945,0.00025370340306410486,25.0,60.0
48.726318,0.000691144468503937,198.43355927801585,0.00025370340306410486,25.0,60.0
50.127686,0.000719652342519685,209.1173042462018,0.00025370340306410486,25.0,60.0
51.529053,0.0007388215354330709,217.62736787430205,0.00025370340306410486,25.0,60.0
52.93042,0.0008054111614173228,228.01133359303986,0.00025370340306410486,25.0,60.0
54.331787,0.0008346424015748032,239.73100376574473,0.00025370340306410486,25.0,60.0
55.733154,0.0008679375393700788,248.79126347227634,0.00025370340306410486,25.0,60.0
57.134521,0.0009222620669291339,260.1298013245033,0.00025370340306410486,25.0,60.0
58.535889,0.0009408625787401574,269.41101155694065,0.00025370340306410486,25.0,60.0
59.937256,0.0009661146259842521,278.24635761589406,0.00025370340306410486,25.0,60.0
61.338623,0.0010178087992125985,289.6378911829633,0.00025370340306410486,25.0,60.0
62.73999,0.0010497980905511811,300.1888326191404,0.00025370340306410486,25.0,60.0
64.141357,0.001095745649606299,310.4500194779899,0.00025370340306410486,25.0,60.0
65.542725,0.0011199611417322835,319.9315932995715,0.00025370340306410486,25.0,60.0
66.944092,0.001165481003937008,330.9322165952474,0.00025370340306410486,25.0,60.0
68.345459,0.00120822531496063,341.94870796000527,0.00025370340306410486,25.0,60.0
69.746826,0.0012329054527559055,351.2532138683288,0.00025370340306410486,25.0,60.0
71.148193,0.0012795152952755904,362.911466043371,0.00025370340306410486,25.0,60.0
72.549561,0.001325062559055118,372.7326061550448,0.00025370340306410486,25.0,60.0
73.950928,0.0013524604921259843,381.9357745747306,0.00025370340306410486,25.0,60.0
75.352295,0.0013771454133858268,392.12112712634723,0.00025370340306410486,25.0,60.0
76.753662,0.001409751968503937,402.3480846643293,0.00025370340306410486,25.0,60.0
78.155029,0.0014600617125984253,414.5086092715232,0.00025370340306410486,25.0,60.0
79.556396,0.0014584476771653543,422.2897545773276,0.00025370340306410486,25.0,60.0
80.957764,0.0015138894094488189,432.14899363719,0.00025370340306410486,25.0,60.0
82.359131,0.001552599429133858,443.1887547071809,0.00025370340306410486,25.0,60.0
83.760498,0.001593382933070866,453.90112972341257,0.00025370340306410486,25.0,60.0
85.161865,0.0016245356692913388,462.5284508505389,0.00025370340306410486,25.0,60.0
86.563232,0.0016727167519685038,472.04534476042073,0.00025370340306410486,25.0,60.0
87.9646,0.001682685216535433,480.20155823918975,0.00025370340306410486,25.0,60.0
89.365967,0.0017150446456692915,489.96436826386184,0.00025370340306410486,25.0,60.0
90.767334,0.001750037992125984,498.1909622126997,0.00025370340306410486,25.0,60.0
92.168701,0.0017846191929133859,506.8549279314375,0.00025370340306410486,25.0,60.0
93.570068,0.0017963364566929135,514.2475262952864,0.00025370340306410486,25.0,60.0
94.971436,0.0018139589763779527,522.8216595247371,0.00025370340306410486,25.0,60.0
96.372803,0.001852988720472441,530.873133359304,0.00025370340306410486,25.0,60.0
97.77417,0.0019063936614173228,538.8573951434878,0.00025370340306410486,25.0,60.0
99.175537,0.0019040528937007875,545.3848591092066,0.00025370340306410486,25.0,60.0
100.5769,0.0019357437007874016,552.7474873393066,0.00025370340306410486,25.0,60.0
101.97827,0.0019654945078740158,558.2122321776393,0.00025370340306410486,25.0,60.0
103.37964,0.0020056244094488187,565.9532268536555,0.00025370340306410486,25.0,60.0
104.78101,0.0020227665354330708,573.9411504999351,0.00025370340306410486,25.0,60.0
106.18237,0.0020545299212598425,580.6989222178938,0.00025370340306410486,25.0,60.0
107.58374,0.0021036659448818895,586.820360992079,0.00025370340306410486,25.0,60.0
108.98511,0.0021320944881889764,593.3899233865733,0.00025370340306410486,25.0,60.0
110.38647,0.0021471299212598425,599.8295286326451,0.00025370340306410486,25.0,60.0
111.78784,0.0021850503937007873,604.1266588754708,0.00025370340306410486,25.0,60.0
113.18921,0.0022078649606299214,609.0318400207766,0.00025370340306410486,25.0,60.0
114.59058,0.0022470895669291337,615.5073367095183,0.00025370340306410486,25.0,60.0
115.99194,0.0022944374015748032,620.4978054798079,0.00025370340306410486,25.0,60.0
117.39331,0.002334826377952756,625.753174912349,0.00025370340306410486,25.0,60.0
118.79468,0.0023527687007874015,630.2165692767173,0.00025370340306410486,25.0,60.0
120.19604,0.002387427165354331,634.0768471627063,0.00025370340306410486,25.0,60.0
121.59741,0.0024074102362204725,637.8915465523958,0.00025370340306410486,25.0,60.0
122.99878,0.0024524759842519685,642.114192961953,0.00025370340306410486,25.0,60.0
124.40015,0.0025072417322834647,647.531515387612,0.00025370340306410486,25.0,60.0
125.80151,0.002536942716535433,653.8281781586807,0.00025370340306410486,25.0,60.0
127.20288,0.0026123084645669294,656.4483833268407,0.00025370340306410486,25.0,60.0
128.60425,0.0026396224409448816,659.0447734060511,0.00025370340306410486,25.0,60.0
130.00562,0.002680667125984252,663.3831190754447,0.00025370340306410486,25.0,60.0
131.40698,0.002747723031496063,667.5798208024931,0.00025370340306410486,25.0,60.0
132.80835,0.002778443503937008,669.6322295805741,0.00025370340306410486,25.0,60.0
134.20972,0.0028246667322834648,673.4284118945591,0.00025370340306410486,25.0,60.0
135.61108,0.002862253937007874,677.2820412933386,0.00025370340306410486,25.0,60.0
137.01245,0.0029114450787401575,679.3600051941307,0.00025370340306410486,25.0,60.0
138.41382,0.002977882086614173,685.0358395013635,0.00025370340306410486,25.0,60.0
139.81519,0.0030405417322834647,688.481963381379,0.00025370340306410486,25.0,60.0
141.21655,0.0031181358267716535,689.2079470198676,0.00025370340306410486,25.0,60.0
142.61792,0.0031790974409448823,693.1167900272692,0.00025370340306410486,25.0,60.0
144.01929,0.0032693767716535428,695.6677054927933,0.00025370340306410486,25.0,60.0
145.42065,0.0033439716535433065,699.3889884430594,0.00025370340306410486,25.0,60.0
146.82202,0.003416076181102362,702.6645630437606,0.00025370340306410486,25.0,60.0
148.22339,0.0035136633858267713,705.9592001038827,0.00025370340306410486,25.0,60.0
149.62476,0.003606590354330709,708.3656667965199,0.00025370340306410486,25.0,60.0
151.02612,0.0036965655511811022,709.2984287754838,0.00025370340306410486,25.0,60.0
152.42749,0.003829885826771653,712.9604466952344,0.00025370340306410486,25.0,60.0
153.82886,0.003951169291338583,718.4288533956629,0.00025370340306410486,25.0,60.0
155.23022,0.004085254921259843,719.7143228152189,0.00025370340306410486,25.0,60.0
156.63159,0.004208620669291339,720.7837164004675,0.00025370340306410486,25.0,60.0
158.03296,0.004325356496062992,723.1244253992988,0.00025370340306410486,25.0,60.0
159.43433,0.004475867322834646,725.1625243474874,0.00025370340306410486,25.0,60.0
160.83569,0.004630792913385827,727.8538631346578,0.00025370340306410486,25.0,60.0
162.23706,0.004778784448818897,729.8071159589664,0.00025370340306410486,25.0,60.0
163.63843,0.004942349606299213,731.4545124009869,0.00025370340306410486,25.0,60.0
165.03979,0.005103195275590551,733.4381249188418,0.00025370340306410486,25.0,60.0
166.44116,0.005270578937007874,733.7202700947929,0.00025370340306410486,25.0,60.0
167.84253,0.005443966929133858,736.909544215037,0.00025370340306410486,25.0,60.0
169.2439,0.005624969881889764,738.3249967536684,0.00025370340306410486,25.0,60.0
170.64526,0.0058262267716535435,739.3137254901961,0.00025370340306410486,25.0,60.0
172.04663,0.005965830905511811,740.1585508375537,0.00025370340306410486,25.0,60.0
173.448,0.0061745263779527555,741.9580314244904,0.00025370340306410486,25.0,60.0
174.84937,0.006402614566929134,745.6232956758863,0.00025370340306410486,25.0,60.0
176.25073,0.0066516781496063,746.8742760680431,0.00025370340306410486,25.0,60.0
177.6521,0.006882328543307086,749.3144007271783,0.00025370340306410486,25.0,60.0
179.05347,0.007120599803149607,750.5575899233866,0.00025370340306410486,25.0,60.0
180.45483,0.007397808267716535,752.8993117776912,0.00025370340306410486,25.0,60.0
181.8562,0.007618290551181102,752.9448383326842,0.00025370340306410486,25.0,60.0
183.25757,0.007902904921259842,754.8944812362031,0.00025370340306410486,25.0,60.0
184.65894,0.008121679921259842,754.6005973250227,0.00025370340306410486,25.0,60.0
186.0603,0.008359406299212599,755.3506038176861,0.00025370340306410486,25.0,60.0
187.46167,0.008602337007874016,756.3585508375536,0.00025370340306410486,25.0,60.0
188.86304,0.008902381299212598,759.1259316971822,0.00025370340306410486,25.0,60.0
190.2644,0.009174136811023623,759.7084274769511,0.00025370340306410486,25.0,60.0
191.66577,0.009431456692913386,760.5383456693937,0.00025370340306410486,25.0,60.0
193.06714,0.009727115748031496,761.0320218153487,0.00025370340306410486,25.0,60.0
194.46851,0.009966707677165353,762.8071679002727,0.00025370340306410486,25.0,60.0
195.86987,0.010289941141732283,763.9044539670173,0.00025370340306410486,25.0,60.0
197.27124,0.010609407480314961,764.9468900142839,0.00025370340306410486,25.0,60.0
198.67261,0.010893072244094488,766.1468121023244,0.00025370340306410486,25.0,60.0
200.07397,0.011195131692913387,768.4183612517855,0.00025370340306410486,25.0,60.0
201.47534,0.011524489173228347,769.2428775483704,0.00025370340306410486,25.0,60.0
202.87671,0.011828774212598425,768.8434229320867,0.00025370340306410486,25.0,60.0
204.27808,0.012175839960629922,771.9681599792235,0.00025370340306410486,25.0,60.0
205.67944,0.012448652952755906,769.9175172055577,0.00025370340306410486,25.0,60.0
207.08081,0.012726983464566929,770.6987923646279,0.00025370340306410486,25.0,60.0
208.48218,0.013016473818897638,771.74192961953,0.00025370340306410486,25.0,60.0
209.88354,0.013302300393700787,774.344812362031,0.00025370340306410486,25.0,60.0
211.28491,0.013659219881889763,774.3470977795092,0.00025370340306410486,25.0,60.0
212.68628,0.014020747440944881,775.3962602259447,0.00025370340306410486,25.0,60.0
214.08765,0.014363389173228346,776.4315543435918,0.00025370340306410486,25.0,60.0
215.48901,0.014679664763779526,777.200467471757,0.00025370340306410486,25.0,60.0
216.89038,0.01495742342519685,776.9191273860538,0.00025370340306410486,25.0,60.0
218.29175,0.015246981102362205,777.3323983898194,0.00025370340306410486,25.0,60.0
219.69312,0.015552076377952754,778.7255421373848,0.00025370340306410486,25.0,60.0
221.09448,0.0158262812992126,781.5585248669004,0.00025370340306410486,25.0,60.0
222.49585,0.01616460216535433,782.3633294377354,0.00025370340306410486,25.0,60.0
223.89722,0.0165483218503937,783.2741462147774,0.00025370340306410486,25.0,60.0
225.29858,0.016887648818897635,781.5679002726919,0.00025370340306410486,25.0,60.0
226.69995,0.017198323228346454,785.329905207116,0.00025370340306410486,25.0,60.0
228.10132,0.01752147618110236,785.1009738994936,0.00025370340306410486,25.0,60.0
229.50269,0.01789179192913386,787.6746396571875,0.00025370340306410486,25.0,60.0
230.90405,0.018202293503937008,785.388443059343,0.00025370340306410486,25.0,60.0
232.30542,0.018514097244094488,787.383145046098,0.00025370340306410486,25.0,60.0
233.70679,0.018850228543307087,787.3863394364369,0.00025370340306410486,25.0,60.0
235.10815,0.019180457874015747,789.6847682119205,0.00025370340306410486,25.0,60.0
236.50952,0.01953706062992126,789.131982859369,0.00025370340306410486,25.0,60.0
237.91089,0.0198743405511811,788.5883651473835,0.00025370340306410486,25.0,60.0
239.31226,0.020223470472440944,792.0788728736528,0.00025370340306410486,25.0,60.0
240.71362,0.020560273622047244,790.5303986495261,0.00025370340306410486,25.0,60.0
242.11499,0.02083828937007874,791.6345929100116,0.00025370340306410486,25.0,60.0
243.51636,0.02115029527559055,792.154135826516,0.00025370340306410486,25.0,60.0
244.91772,0.02144522244094488,793.4409816906896,0.00025370340306410486,25.0,60.0
246.31909,0.02177253937007874,791.9351772497079,0.00025370340306410486,25.0,60.0
247.72046,0.022121801181102362,795.4077392546424,0.00025370340306410486,25.0,60.0
249.12183,0.022519523622047243,795.5344241007662,0.00025370340306410486,25.0,60.0
250.52319,0.022889688976377952,797.2752629528633,0.00025370340306410486,25.0,60.0
251.92456,0.023186846456692913,796.8458901441371,0.00025370340306410486,25.0,60.0
253.32593,0.023478507874015748,796.2669523438515,0.00025370340306410486,25.0,60.0
254.72729,0.02377488779527559,796.9189455914817,0.00025370340306410486,25.0,60.0
256.12866,0.024121049212598424,799.0321516686145,0.00025370340306410486,25.0,60.0
257.53003,0.02447346850393701,798.8067523698222,0.00025370340306410486,25.0,60.0
258.9314,0.024906509842519683,802.5684975977147,0.00025370340306410486,25.0,60.0
260.33276,0.025292580708661416,800.3219322165953,0.00025370340306410486,25.0,60.0
261.73413,0.025588153543307086,800.5475392806129,0.00025370340306410486,25.0,60.0
263.1355,0.025877001968503937,798.7682119205299,0.00025370340306410486,25.0,60.0
264.53687,0.0261690374015748,802.4509544215038,0.00025370340306410486,25.0,60.0
265.93823,0.02654668897637795,803.9920010388262,0.00025370340306410486,25.0,60.0
267.3396,0.026880169291338584,801.8780158420984,0.00025370340306410486,25.0,60.0
268.74097,0.027250944881889762,804.3805479807818,0.00025370340306410486,25.0,60.0
270.14233,0.027637600393700786,805.4801194650046,0.00025370340306410486,25.0,60.0
271.5437,0.027983161417322835,802.7876899104012,0.00025370340306410486,25.0,60.0
272.94507,0.028351464566929135,806.5332294507207,0.00025370340306410486,25.0,60.0
274.34644,0.02873270275590551,806.4048824827945,0.00025370340306410486,25.0,60.0
275.7478,0.029094088582677164,807.0939618231398,0.00025370340306410486,25.0,60.0
277.14917,0.02939080905511811,807.6289832489288,0.00025370340306410486,25.0,60.0
278.55054,0.02971688188976378,808.4796779639008,0.00025370340306410486,25.0,60.0
279.9519,0.030047379921259842,810.2791066095313,0.00025370340306410486,25.0,60.0
281.35327,0.030456667322834648,810.3389689650695,0.00025370340306410486,25.0,60.0
282.75464,0.0307942874015748,809.9268926113492,0.00025370340306410486,25.0,60.0
284.15601,0.03115392125984252,811.0499935073367,0.00025370340306410486,25.0,60.0
285.55737,0.0314644468503937,811.6490325931699,0.00025370340306410486,25.0,60.0
286.95874,0.03175550984251968,811.7757174392937,0.00025370340306410486,25.0,60.0
288.36011,0.03209525393700787,815.046669263732,0.00025370340306410486,25.0,60.0
289.76147,0.03245061023622047,813.8120503830671,0.00025370340306410486,25.0,60.0
291.16284,0.03278935433070866,811.3703155434359,0.00025370340306410486,25.0,60.0
292.56421,0.033108710629921254,815.5218802752889,0.00025370340306410486,25.0,60.0
293.96558,0.0334630531496063,816.1026619919492,0.00025370340306410486,25.0,60.0
295.36694,0.03381330511811024,815.2219192312688,0.00025370340306410486,25.0,60.0
296.76831,0.03427308661417323,815.923983898195,0.00025370340306410486,25.0,60.0
298.16968,0.034598049212598424,815.9087131541359,0.00025370340306410486,25.0,60.0
299.57104,0.03495201771653543,815.5050253213869,0.00025370340306410486,25.0,60.0
300.97241,0.035254137795275586,816.4952084144917,0.00025370340306410486,25.0,60.0
302.37378,0.03559706496062992,817.8907414621478,0.00025370340306410486,25.0,60.0
303.77515,0.03594997440944882,817.5935592780158,0.00025370340306410486,25.0,60.0
305.17651,0.03626096062992126,817.990364887677,0.00025370340306410486,25.0,60.0
306.57788,0.03659097834645669,818.5004544864304,0.00025370340306410486,25.0,60.0
307.97925,0.03695031496062992,819.6603817686015,0.00025370340306410486,25.0,60.0
309.38062,0.03727164960629921,820.6111933515128,0.00025370340306410486,25.0,60.0
310.78198,0.03761632677165354,819.7702636021296,0.00025370340306410486,25.0,60.0
312.18335,0.03791642125984252,821.3433320348007,0.00025370340306410486,25.0,60.0
313.58472,0.0382231594488189,821.0044409816907,0.00025370340306410486,25.0,60.0
314.98608,0.03856149803149606,822.8681729645501,0.00025370340306410486,25.0,60.0
316.38745,0.038928722440944884,821.1515907025062,0.00025370340306410486,25.0,60.0
317.78882,0.03920993503937008,822.781560836255,0.00025370340306410486,25.0,60.0
319.19019,0.03950869881889764,822.593247630178,0.00025370340306410486,25.0,60.0
320.59155,0.03985105511811023,824.151720555772,0.00025370340306410486,25.0,60.0
321.99292,0.04023863188976378,826.4028567718478,0.00025370340306410486,25.0,60.0
323.39429,0.0406297874015748,827.8250876509545,0.00025370340306410486,25.0,60.0
324.79565,0.04096709448818898,824.1051292039996,0.00025370340306410486,25.0,60.0
326.19702,0.041275897637795274,824.7338527463967,0.00025370340306410486,25.0,60.0
327.59839,0.04162820078740157,829.0043630697312,0.00025370340306410486,25.0,60.0
328.99976,0.041906521653543305,825.5533567069212,0.00025370340306410486,25.0,60.0
330.40112,0.04227212401574803,830.1322165952474,0.00025370340306410486,25.0,60.0
331.80249,0.04269207283464567,828.4389819503962,0.00025370340306410486,25.0,60.0
333.20386,0.04299916338582677,829.3792234774705,0.00025370340306410486,25.0,60.0
334.60522,0.04331651968503937,828.0224646149851,0.00025370340306410486,25.0,60.0
336.00659,0.04374096456692913,830.4339436436827,0.00025370340306410486,25.0,60.0
337.40796,0.04411345669291338,830.6242825607064,0.00025370340306410486,25.0,60.0
338.80933,0.044447200787401574,831.058693676146,0.00025370340306410486,25.0,60.0
340.21069,0.044770948818897635,830.1360083106091,0.00025370340306410486,25.0,60.0
341.61206,0.045137415354330704,833.916919880535,0.00025370340306410486,25.0,60.0
343.01343,0.045497952755905506,832.7851967276978,0.00025370340306410486,25.0,60.0
344.41479,0.045786950787401574,831.0375016231659,0.00025370340306410486,25.0,60.0
345.81616,0.04608173622047244,832.9999480586937,0.00025370340306410486,25.0,60.0
347.21753,0.04645249606299212,833.9938968965071,0.00025370340306410486,25.0,60.0
348.6189,0.046784415354330706,834.8233476171926,0.00025370340306410486,25.0,60.0
350.02026,0.04706460826771654,833.3376964030646,0.00025370340306410486,25.0,60.0
351.42163,0.04738267125984252,834.831268666407,0.00025370340306410486,25.0,60.0
352.823,0.047726622047244094,837.3538501493314,0.00025370340306410486,25.0,60.0
354.22437,0.0481264153543307,835.3611479028699,0.00025370340306410486,25.0,60.0
355.62573,0.048419645669291335,834.765199324763,0.00025370340306410486,25.0,60.0
357.0271,0.04873791732283465,837.3981560836256,0.00025370340306410486,25.0,60.0
358.42847,0.04908869291338582,837.8730035060382,0.00025370340306410486,25.0,60.0
359.82983,0.04950074803149607,838.694143617712,0.00025370340306410486,25.0,60.0
361.2312,0.04984170866141732,838.2055057784703,0.00025370340306410486,25.0,60.0
362.63257,0.05017835236220473,839.7205557719777,0.00025370340306410486,25.0,60.0
364.03394,0.0505225157480315,836.8594727957409,0.00025370340306410486,25.0,60.0
365.4353,0.05084371850393701,839.7932736008311,0.00025370340306410486,25.0,60.0
366.83667,0.051253781496062994,840.7629918192442,0.00025370340306410486,25.0,60.0
368.23804,0.05155938976377952,840.3547331515388,0.00025370340306410486,25.0,60.0
369.6394,0.05195071653543307,843.0311907544476,0.00025370340306410486,25.0,60.0
371.04077,0.05228910826771654,842.7440851837424,0.00025370340306410486,25.0,60.0
372.44214,0.052617913385826776,842.6312946370603,0.00025370340306410486,25.0,60.0
373.84351,0.05294290551181102,844.1387352291911,0.00025370340306410486,25.0,60.0
375.24487,0.05325955511811024,843.3738215816128,0.00025370340306410486,25.0,60.0
376.64624,0.0536043937007874,842.951097260096,0.00025370340306410486,25.0,60.0
378.04761,0.053910694881889765,844.9463186599144,0.00025370340306410486,25.0,60.0
379.44897,0.05425092716535433,843.3735099337749,0.00025370340306410486,25.0,60.0
380.85034,0.05457767322834645,846.5816647188677,0.00025370340306410486,25.0,60.0
382.25171,0.05489159448818898,847.4950785612258,0.00025370340306410486,25.0,60.0
383.65308,0.05523392322834646,845.7338008050903,0.00025370340306410486,25.0,60.0
385.05444,0.05562999999999999,847.5889105310998,0.00025370340306410486,25.0,60.0
386.45581,0.055995407480314965,846.9645760290871,0.00025370340306410486,25.0,60.0
387.85718,0.056302078740157475,846.4585897935333,0.00025370340306410486,25.0,60.0
389.25854,0.056662610236220476,847.341124529282,0.00025370340306410486,25.0,60.0
390.65991,0.05696357283464567,847.2018958576809,0.00025370340306410486,25.0,60.0
392.06128,0.057319879921259836,848.7069990910272,0.00025370340306410486,25.0,60.0
393.46265,0.05770048228346456,848.2715231788079,0.00025370340306410486,25.0,60.0
394.86401,0.0580275688976378,848.4579405272042,0.00025370340306410486,25.0,60.0
396.26538,0.058315212598425196,848.742578885859,0.00025370340306410486,25.0,60.0
397.66675,0.05862670078740157,850.929905207116,0.00025370340306410486,25.0,60.0
399.06812,0.05901321456692914,852.3615374626671,0.00025370340306410486,25.0,60.0
400.46948,0.05938376771653543,850.9318789767563,0.00025370340306410486,25.0,60.0
401.87085,0.05973909645669291,850.8876769250746,0.00025370340306410486,25.0,60.0
403.27222,0.06011295669291339,852.6225684975977,0.00025370340306410486,25.0,60.0
404.67358,0.06044879527559056,850.0297623685236,0.00025370340306410486,25.0,60.0
406.07495,0.060743246062992126,851.9237241916635,0.00025370340306410486,25.0,60.0
407.47632,0.06106919488188976,853.7981041423192,0.00025370340306410486,25.0,60.0
408.87769,0.06141976968503937,853.4437865212311,0.00025370340306410486,25.0,60.0
410.27905,0.06176852165354331,853.2252434748734,0.00025370340306410486,25.0,60.0
411.68042,0.06212532283464566,855.9635631736139,0.00025370340306410486,25.0,60.0
413.08179,0.06248106102362205,855.5566809505259,0.00025370340306410486,25.0,60.0
414.48315,0.06283600196850395,855.9032073756655,0.00025370340306410486,25.0,60.0
415.88452,0.06319380118110236,855.1228671601091,0.00025370340306410486,25.0,60.0
417.28589,0.06349150787401574,856.482586677055,0.00025370340306410486,25.0,60.0
418.68726,0.06382998622047244,854.4758343072328,0.00025370340306410486,25.0,60.0
420.08862,0.06421391929133859,856.9984677314635,0.00025370340306410486,25.0,60.0
421.48999,0.06453331496062993,858.3341384235814,0.00025370340306410486,25.0,60.0
422.89136,0.0648854468503937,857.009297493832,0.00025370340306410486,25.0,60.0
424.29272,0.06521232086614173,858.9427606804312,0.00025370340306410486,25.0,60.0
425.69409,0.06554689960629921,857.5931956888717,0.00025370340306410486,25.0,60.0
427.09546,0.06589824409448819,859.6283599532528,0.00025370340306410486,25.0,60.0
428.49683,0.06623285236220473,857.547539280613,0.00025370340306410486,25.0,60.0
429.89819,0.06655317913385826,860.3535385014933,0.00025370340306410486,25.0,60.0
431.29956,0.06687848228346457,860.342241267368,0.00025370340306410486,25.0,60.0
432.70093,0.06721075393700787,860.0169848071679,0.00025370340306410486,25.0,60.0
434.10229,0.06750987007874015,859.9229970133749,0.00025370340306410486,25.0,60.0
435.50366,0.06782327559055118,860.715621347877,0.00025370340306410486,25.0,60.0
436.90503,0.06811066141732283,860.9764705882353,0.00025370340306410486,25.0,60.0
438.3064,0.06848652952755906,862.5459550707701,0.00025370340306410486,25.0,60.0
439.70776,0.06886397440944882,863.867497727568,0.00025370340306410486,25.0,60.0
441.10913,0.06922321456692913,862.3495130502532,0.00025370340306410486,25.0,60.0
442.5105,0.06958961417322834,862.867030255811,0.00025370340306410486,25.0,60.0
443.91187,0.06995598228346456,864.1280872613947,0.00025370340306410486,25.0,60.0
445.31323,0.07030687598425196,863.3956888715751,0.00025370340306410486,25.0,60.0
446.7146,0.07064437598425197,864.3465264251396,0.00025370340306410486,25.0,60.0
448.11597,0.07100615748031497,864.7964939618232,0.00025370340306410486,25.0,60.0
449.51733,0.0713222027559055,864.7318789767563,0.00025370340306410486,25.0,60.0
450.9187,0.0716913405511811,867.5558239189717,0.00025370340306410486,25.0,60.0
452.32007,0.07203144488188976,864.3488637839242,0.00025370340306410486,25.0,60.0
453.72144,0.072348281496063,866.5567588624855,0.00025370340306410486,25.0,60.0
455.1228,0.07264713188976378,865.3356966627712,0.00025370340306410486,25.0,60.0
456.52417,0.07298209842519686,866.8527983378782,0.00025370340306410486,25.0,60.0
457.92554,0.07325212007874016,866.2790286975718,0.00025370340306410486,25.0,60.0
459.3269,0.0735773405511811,867.5681080379172,0.00025370340306410486,25.0,60.0
460.72827,0.07392973031496063,867.825659005324,0.00025370340306410486,25.0,60.0
462.12964,0.07428404921259843,870.0267757434101,0.00025370340306410486,25.0,60.0
463.53101,0.07463204921259842,867.1824178678095,0.00025370340306410486,25.0,60.0
464.93237,0.07494682086614173,870.0082586677056,0.00025370340306410486,25.0,60.0
466.33374,0.07526058464566929,868.3490196078433,0.00025370340306410486,25.0,60.0
467.73511,0.07562217322834645,871.5564731853007,0.00025370340306410486,25.0,60.0
469.13647,0.07596350984251969,869.8278145695365,0.00025370340306410486,25.0,60.0
470.53784,0.07630744488188977,870.8528762498378,0.00025370340306410486,25.0,60.0
471.93921,0.07662084448818898,871.5337748344372,0.00025370340306410486,25.0,60.0
473.34058,0.07699204133858269,872.782989222179,0.00025370340306410486,25.0,60.0
474.74194,0.0773658188976378,872.7434878587196,0.00025370340306410486,25.0,60.0
476.14331,0.07772016732283464,871.910972600961,0.00025370340306410486,25.0,60.0
477.54468,0.0780900157480315,872.0019737696404,0.00025370340306410486,25.0,60.0
478.94604,0.07841727362204724,871.747071808856,0.00025370340306410486,25.0,60.0
480.34741,0.07873324803149606,871.7571484222829,0.00025370340306410486,25.0,60.0
481.74878,0.07912547047244095,874.5456953642384,0.00025370340306410486,25.0,60.0
483.15015,0.07946068307086614,875.3493572263343,0.00025370340306410486,25.0,60.0
484.55151,0.07978273622047244,874.2451110245423,0.00025370340306410486,25.0,60.0
485.95288,0.08015533464566929,874.2533437215947,0.00025370340306410486,25.0,60.0
487.35425,0.08047789763779528,874.2147253603428,0.00025370340306410486,25.0,60.0
488.75562,0.08077114566929133,876.9548889754578,0.00025370340306410486,25.0,60.0
490.15698,0.08109339173228346,877.3643163225555,0.00025370340306410486,25.0,60.0
491.55835,0.08142004527559055,876.0620958317102,0.00025370340306410486,25.0,60.0
492.95972,0.08175523818897637,875.0070380470069,0.00025370340306410486,25.0,60.0
494.36108,0.08214165354330707,879.5447344500715,0.00025370340306410486,25.0,60.0
495.76245,0.08245211417322834,877.1942604856513,0.00025370340306410486,25.0,60.0
497.16382,0.08281668897637795,877.8605635631736,0.00025370340306410486,25.0,60.0
498.56519,0.08312251377952756,878.2176081028439,0.00025370340306410486,25.0,60.0
499.96655,0.08342685039370078,878.169172834697,0.00025370340306410486,25.0,60.0
501.36792,0.08383477755905512,881.5225814829244,0.00025370340306410486,25.0,60.0
502.76929,0.08421432283464567,877.6306713413842,0.00025370340306410486,25.0,60.0
504.17065,0.08455649803149606,877.2396571873783,0.00025370340306410486,25.0,60.0
505.57202,0.0848857972440945,878.6008310609012,0.00025370340306410486,25.0,60.0
506.97339,0.08522647047244093,880.7995844695494,0.00025370340306410486,25.0,60.0
508.37476,0.08562207874015748,880.0987144526686,0.00025370340306410486,25.0,60.0
509.77612,0.08593829921259842,878.824204648747,0.00025370340306410486,25.0,60.0
511.17749,0.08628845275590552,880.5865472016621,0.00025370340306410486,25.0,60.0
512.57886,0.08658943307086614,879.8057654850021,0.00025370340306410486,25.0,60.0
513.98022,0.0869637342519685,882.5942604856513,0.00025370340306410486,25.0,60.0
515.38159,0.08731569488188975,881.4351642643813,0.00025370340306410486,25.0,60.0
516.78296,0.08766094488188976,881.6210621997144,0.00025370340306410486,25.0,60.0
518.18433,0.08800138188976378,881.2380989481886,0.00025370340306410486,25.0,60.0
519.58569,0.08839821062992126,885.9420335021426,0.00025370340306410486,25.0,60.0
520.98706,0.08877172637795275,883.9235423970913,0.00025370340306410486,25.0,60.0
522.38843,0.08911943897637796,883.2027009479289,0.00025370340306410486,25.0,60.0
523.78979,0.08947413385826772,883.8800415530451,0.00025370340306410486,25.0,60.0
525.19116,0.08980935039370079,883.9538501493313,0.00025370340306410486,25.0,60.0
526.59253,0.09014151181102362,883.9075704453968,0.00025370340306410486,25.0,60.0
527.9939,0.09050788779527559,883.6190105181146,0.00025370340306410486,25.0,60.0
529.39526,0.09087006692913385,883.3195429165044,0.00025370340306410486,25.0,60.0
530.79663,0.09119795275590552,884.8541488118427,0.00025370340306410486,25.0,60.0
532.198,0.09149138188976379,886.2733930658356,0.00025370340306410486,25.0,60.0
533.59937,0.0918458937007874,888.0593948837814,0.00025370340306410486,25.0,60.0
535.00073,0.0921691437007874,886.4383846253734,0.00025370340306410486,25.0,60.0
536.4021,0.09251479133858267,886.8278145695365,0.00025370340306410486,25.0,60.0
537.80347,0.09283760826771653,886.5346838072978,0.00025370340306410486,25.0,60.0
539.20483,0.0931629153543307,886.2477080898585,0.00025370340306410486,25.0,60.0
540.6062,0.09352619881889764,888.3307622386703,0.00025370340306410486,25.0,60.0
542.00757,0.09387767322834646,886.567588624854,0.00025370340306410486,25.0,60.0
543.40894,0.09419087401574804,887.5799766264122,0.00025370340306410486,25.0,60.0
544.8103,0.09451263976377952,888.710167510713,0.00025370340306410486,25.0,60.0
546.21167,0.09487938385826772,889.0902220490846,0.00025370340306410486,25.0,60.0
547.61304,0.09525979133858267,888.2989222178938,0.00025370340306410486,25.0,60.0
549.0144,0.09562936417322834,889.3769900012986,0.00025370340306410486,25.0,60.0
550.41577,0.09600831102362205,890.9137514608493,0.00025370340306410486,25.0,60.0
551.81714,0.09634862598425196,888.6319958446954,0.00025370340306410486,25.0,60.0
553.21851,0.09674606496062992,889.0873652772367,0.00025370340306410486,25.0,60.0
554.61987,0.09712715354330709,890.7324763017791,0.00025370340306410486,25.0,60.0
556.02124,0.09748313779527558,891.2470068822231,0.00025370340306410486,25.0,60.0
557.42261,0.09779574015748031,890.3731463446306,0.00025370340306410486,25.0,60.0
558.82397,0.09814836417322834,891.6415011037528,0.00025370340306410486,25.0,60.0
560.22534,0.09853315354330708,891.9537722373718,0.00025370340306410486,25.0,60.0
561.62671,0.09888489173228346,892.995013634593,0.00025370340306410486,25.0,60.0
563.02808,0.09928264763779529,892.0044929229971,0.00025370340306410486,25.0,60.0
564.42944,0.09960680118110236,890.6438904038438,0.00025370340306410486,25.0,60.0
565.83081,0.09992373818897639,890.355408388521,0.00025370340306410486,25.0,60.0
567.23218,0.1002219251968504,891.5192052980133,0.00025370340306410486,25.0,60.0
568.63354,0.1005602874015748,894.6576808206727,0.00025370340306410486,25.0,60.0
570.03491,0.10093556102362206,894.6690299961044,0.00025370340306410486,25.0,60.0
571.43628,0.10134504921259843,893.9947798987145,0.00025370340306410486,25.0,60.0
572.83765,0.10167110433070867,892.806258927412,0.00025370340306410486,25.0,60.0
574.23901,0.10203877559055118,896.4239449422154,0.00025370340306410486,25.0,60.0
575.64038,0.1024439468503937,894.6585638228802,0.00025370340306410486,25.0,60.0
577.04175,0.10275336220472442,893.71466043371,0.00025370340306410486,25.0,60.0
578.44312,0.10312519881889763,895.3120114270874,0.00025370340306410486,25.0,60.0
579.84448,0.1034736279527559,895.0427476951045,0.00025370340306410486,25.0,60.0
581.24585,0.10381542716535433,896.8679132580185,0.00025370340306410486,25.0,60.0
582.64722,0.10427046456692914,897.9213089209194,0.00025370340306410486,25.0,60.0
584.04858,0.1046309783464567,896.2935982339957,0.00025370340306410486,25.0,60.0
585.44995,0.10500638188976379,897.0891312816518,0.00025370340306410486,25.0,60.0
586.85132,0.1053679527559055,896.8004415011037,0.00025370340306410486,25.0,60.0
588.25269,0.10572833858267718,895.7249707830152,0.00025370340306410486,25.0,60.0
589.65405,0.10607278937007875,898.1276457602909,0.00025370340306410486,25.0,60.0
591.05542,0.10639535826771652,899.5555122711337,0.00025370340306410486,25.0,60.0
592.45679,0.10675649409448817,898.5218802752889,0.00025370340306410486,25.0,60.0
593.85815,0.10710428937007874,897.704090377873,0.00025370340306410486,25.0,60.0
595.25952,0.10750131889763778,901.2011946500455,0.00025370340306410486,25.0,60.0
596.66089,0.10790519881889764,898.8342812621738,0.00025370340306410486,25.0,60.0
598.06226,0.10823051377952755,897.0472925594079,0.00025370340306410486,25.0,60.0
599.46362,0.108564687007874,897.4889754577329,0.00025370340306410486,25.0,60.0
600.86499,0.10889308661417323,899.7302687962602,0.00025370340306410486,25.0,60.0
602.26636,0.10926455905511812,901.2181275159071,0.00025370340306410486,25.0,60.0
603.66772,0.1095729311023622,896.9737956109597,0.00025370340306410486,25.0,60.0
605.06909,0.10992299212598426,900.634151408908,0.00025370340306410486,25.0,60.0
606.47046,0.11027983267716535,901.6515517465265,0.00025370340306410486,25.0,60.0
607.87183,0.1105926751968504,900.6399428645631,0.00025370340306410486,25.0,60.0
609.27319,0.11097754724409449,901.1019088430074,0.00025370340306410486,25.0,60.0
610.67456,0.1113735905511811,900.0969224776003,0.00025370340306410486,25.0,60.0
612.07593,0.11176877559055118,902.089806518634,0.00025370340306410486,25.0,60.0
613.47729,0.11211924606299212,901.845708349565,0.00025370340306410486,25.0,60.0
614.87866,0.11255221259842518,901.9836644591612,0.00025370340306410486,25.0,60.0
616.28003,0.11294338582677166,902.3521101155695,0.00025370340306410486,25.0,60.0
617.6814,0.11325706102362205,901.9407609401377,0.00025370340306410486,25.0,60.0
619.08276,0.11366251377952756,902.7889105311,0.00025370340306410486,25.0,60.0
620.48413,0.1140324625984252,903.2936242046487,0.00025370340306410486,25.0,60.0
621.8855,0.11440005118110236,903.2894429294897,0.00025370340306410486,25.0,60.0
623.28687,0.1147654468503937,902.9862355538243,0.00025370340306410486,25.0,60.0
624.68823,0.1150766338582677,901.4241267367875,0.00025370340306410486,25.0,60.0
626.0896,0.1154716437007874,903.3232307492533,0.00025370340306410486,25.0,60.0
627.49097,0.11585656299212597,903.7487339306584,0.00025370340306410486,25.0,60.0
628.89233,0.1162067874015748,904.6082586677056,0.00025370340306410486,25.0,60.0
630.2937,0.11660609251968505,904.8732372419166,0.00025370340306410486,25.0,60.0
631.69507,0.11697460826771654,905.0507466562784,0.00025370340306410486,25.0,60.0
633.09644,0.11737015748031496,905.8815478509285,0.00025370340306410486,25.0,60.0
634.4978,0.1177540688976378,906.133593039865,0.00025370340306410486,25.0,60.0
635.89917,0.11805969488188975,903.4888975457733,0.00025370340306410486,25.0,60.0
637.30054,0.1183797874015748,905.1428905336969,0.00025370340306410486,25.0,60.0
638.7019,0.11874128740157482,905.3573821581613,0.00025370340306410486,25.0,60.0
640.10327,0.11913883267716537,907.2144396831582,0.00025370340306410486,25.0,60.0
641.50464,0.11955086614173228,906.1405531749124,0.00025370340306410486,25.0,60.0
642.90601,0.11986806102362206,905.7080119465005,0.00025370340306410486,25.0,60.0
644.30737,0.12022700393700787,907.8684067004285,0.00025370340306410486,25.0,60.0
645.70874,0.12059188188976379,907.0373717699,0.00025370340306410486,25.0,60.0
647.11011,0.12093233267716536,908.6191923126867,0.00025370340306410486,25.0,60.0
648.51147,0.12134198622047244,907.8091936112194,0.00025370340306410486,25.0,60.0
649.91284,0.12169916732283463,907.3122191923128,0.00025370340306410486,25.0,60.0
651.31421,0.12207537007874014,907.3747305544734,0.00025370340306410486,25.0,60.0
652.71558,0.12247047244094487,908.4474224126737,0.00025370340306410486,25.0,60.0
654.11694,0.12286824015748031,908.0810803791717,0.00025370340306410486,25.0,60.0
655.51831,0.12328596653543307,908.62020516816,0.00025370340306410486,25.0,60.0
656.91968,0.12365939763779528,909.7127905466823,0.00025370340306410486,25.0,60.0
658.32104,0.12407396653543308,909.0268276847163,0.00025370340306410486,25.0,60.0
659.72241,0.12447462007874016,909.5436436826386,0.00025370340306410486,25.0,60.0
661.12378,0.1248216535433071,910.635917413323,0.00025370340306410486,25.0,60.0
662.52515,0.1252309783464567,910.6013504739644,0.00025370340306410486,25.0,60.0
663.92651,0.12565589566929133,909.1538241786782,0.00025370340306410486,25.0,60.0
665.32788,0.1260274744094488,908.9897156213478,0.00025370340306410486,25.0,60.0
666.72925,0.12640184448818897,909.14595507077,0.00025370340306410486,25.0,60.0
668.13062,0.12676416732283463,911.0465913517726,0.00025370340306410486,25.0,60.0
669.53198,0.12716449212598424,912.3882872354241,0.00025370340306410486,25.0,60.0
670.93335,0.1275967657480315,911.4571873782626,0.00025370340306410486,25.0,60.0
672.33472,0.12800788582677167,911.4413452798339,0.00025370340306410486,25.0,60.0
673.73608,0.12840086614173227,910.7762887936633,0.00025370340306410486,25.0,60.0
675.13745,0.12878548031496062,912.0866640696014,0.00025370340306410486,25.0,60.0
676.53882,0.1291264940944882,910.6412413972213,0.00025370340306410486,25.0,60.0
677.94019,0.12946639173228347,910.4037917153616,0.00025370340306410486,25.0,60.0
679.34155,0.12986692913385825,914.1081417997664,0.00025370340306410486,25.0,60.0
680.74292,0.13027043307086614,912.0271393325543,0.00025370340306410486,25.0,60.0
682.14429,0.1306385748031496,913.5903129463707,0.00025370340306410486,25.0,60.0
683.54565,0.13110458070866143,912.8965588884561,0.00025370340306410486,25.0,60.0
684.94702,0.13152969881889762,912.5459810414233,0.00025370340306410486,25.0,60.0
686.34839,0.13187959448818898,912.184443578756,0.00025370340306410486,25.0,60.0
687.74976,0.1322390059055118,913.9450720685626,0.00025370340306410486,25.0,60.0
689.15112,0.13271416535433073,914.5640306453707,0.00025370340306410486,25.0,60.0
690.55249,0.13310637007874015,913.555590183093,0.00025370340306410486,25.0,60.0
691.95386,0.13345504527559054,913.1454096870538,0.00025370340306410486,25.0,60.0
693.35522,0.13381300196850393,913.4243864433191,0.00025370340306410486,25.0,60.0
694.75659,0.1342014409448819,914.4168030125958,0.00025370340306410486,25.0,60.0
696.15796,0.13457305511811024,913.1226593948838,0.00025370340306410486,25.0,60.0
697.55933,0.13502846850393702,915.2949746786132,0.00025370340306410486,25.0,60.0
698.96069,0.13543861417322833,915.6769770159719,0.00025370340306410486,25.0,60.0
700.36206,0.13579892913385827,913.7483963121673,0.00025370340306410486,25.0,60.0
701.76343,0.13617625590551183,914.2464355278536,0.00025370340306410486,25.0,60.0
703.16479,0.1365508976377953,914.6637579535126,0.00025370340306410486,25.0,60.0
704.56616,0.13700203937007874,916.6631086871836,0.00025370340306410486,25.0,60.0
705.96753,0.13732108858267716,914.5244773406051,0.00025370340306410486,25.0,60.0
707.3689,0.13769310039370078,915.3070770029867,0.00025370340306410486,25.0,60.0
708.77026,0.13805385039370077,915.3252824308532,0.00025370340306410486,25.0,60.0
710.17163,0.13839214173228345,916.0548759901312,0.00025370340306410486,25.0,60.0
711.573,0.13886599803149605,917.3563173613817,0.00025370340306410486,25.0,60.0
712.97437,0.13933139566929134,918.3543176210883,0.00025370340306410486,25.0,60.0
714.37573,0.1397604192913386,916.8451629658487,0.00025370340306410486,25.0,60.0
715.7771,0.14021246456692915,917.7543176210883,0.00025370340306410486,25.0,60.0
717.17847,0.1406506751968504,919.0132710037658,0.00025370340306410486,25.0,60.0
718.57983,0.1410843464566929,916.8318919620829,0.00025370340306410486,25.0,60.0
719.9812,0.14144266732283464,917.417945721335,0.00025370340306410486,25.0,60.0
721.38257,0.1418363503937008,916.7235423970914,0.00025370340306410486,25.0,60.0
722.78394,0.1422235118110236,917.3733021685496,0.00025370340306410486,25.0,60.0
724.1853,0.14263964173228347,917.1025840799897,0.00025370340306410486,25.0,60.0
725.58667,0.14303929724409448,917.2369302687963,0.00025370340306410486,25.0,60.0
726.98804,0.14339502362204723,914.9321646539411,0.00025370340306410486,25.0,60.0
728.3894,0.14381659842519684,919.8365926503052,0.00025370340306410486,25.0,60.0
729.79077,0.14423576574803149,918.6696273211271,0.00025370340306410486,25.0,60.0
731.19214,0.14464926771653544,918.513076223867,0.00025370340306410486,25.0,60.0
732.59351,0.14505002755905513,918.5129463706013,0.00025370340306410486,25.0,60.0
733.99487,0.14547617716535433,919.7277236722504,0.00025370340306410486,25.0,60.0
735.39624,0.14594273622047244,917.1836644591612,0.00025370340306410486,25.0,60.0
736.79761,0.1463141377952756,919.1035709648098,0.00025370340306410486,25.0,60.0
738.19897,0.1467264783464567,918.482586677055,0.00025370340306410486,25.0,60.0
739.60034,0.14715508070866143,919.9218023633294,0.00025370340306410486,25.0,60.0
741.00171,0.14759230511811022,918.4873912478898,0.00025370340306410486,25.0,60.0
742.40308,0.14793956102362205,918.0489546812104,0.00025370340306410486,25.0,60.0
743.80444,0.1482778877952756,919.5134917543177,0.00025370340306410486,25.0,60.0
745.20581,0.14863379133858268,919.0482275029218,0.00025370340306410486,25.0,60.0
746.60718,0.14902148031496062,919.3710167510714,0.00025370340306410486,25.0,60.0
748.00854,0.14942159251968504,922.0126477080898,0.00025370340306410486,25.0,60.0
749.40991,0.1498987933070866,920.7339566290092,0.00025370340306410486,25.0,60.0
750.81128,0.15033476377952754,920.4559927282171,0.00025370340306410486,25.0,60.0
752.21265,0.15079417716535432,920.5225814829244,0.00025370340306410486,25.0,60.0
753.61401,0.15122821259842517,919.0407998961174,0.00025370340306410486,25.0,60.0
755.01538,0.15165922047244093,922.5136216075834,0.00025370340306410486,25.0,60.0
756.41675,0.15206974015748032,919.7022464614986,0.00025370340306410486,25.0,60.0
757.81812,0.15248722047244095,920.6988962472407,0.00025370340306410486,25.0,60.0
759.21948,0.15289809251968503,921.62981430983,0.00025370340306410486,25.0,60.0
760.62085,0.1533671161417323,923.0543306064147,0.00025370340306410486,25.0,60.0
762.02222,0.1538555688976378,922.3476171925724,0.00025370340306410486,25.0,60.0
763.42358,0.15428562598425197,921.3691468640437,0.00025370340306410486,25.0,60.0
764.82495,0.15471260826771654,922.1916374496819,0.00025370340306410486,25.0,60.0
766.22632,0.15512431496062992,921.8092455525257,0.00025370340306410486,25.0,60.0
767.62769,0.15554225196850394,920.5624464355279,0.00025370340306410486,25.0,60.0
769.02905,0.15600910433070866,922.5999740293469,0.00025370340306410486,25.0,60.0
770.43042,0.15650246062992126,922.2656278405402,0.00025370340306410486,25.0,60.0
771.83179,0.1569347244094488,921.816023893001,0.00025370340306410486,25.0,60.0
773.23315,0.15728255511811023,921.117880794702,0.00025370340306410486,25.0,60.0
774.63452,0.157704468503937,922.2881443968316,0.00025370340306410486,25.0,60.0
776.03589,0.1581356279527559,922.6709258537853,0.00025370340306410486,25.0,60.0
777.43726,0.1585643937007874,922.582989222179,0.00025370340306410486,25.0,60.0
778.83862,0.15911858858267716,923.1782885339567,0.00025370340306410486,25.0,60.0
780.23999,0.15951529921259844,922.0479677963901,0.00025370340306410486,25.0,60.0
781.64136,0.15996767322834646,923.1788079470199,0.00025370340306410486,25.0,60.0
783.04272,0.16041556496062992,923.2728996234256,0.00025370340306410486,25.0,60.0
784.44409,0.16078927952755903,921.9091806258928,0.00025370340306410486,25.0,60.0
785.84546,0.16120221653543307,923.1174912349046,0.00025370340306410486,25.0,60.0
787.24683,0.16166740354330708,923.5758472925594,0.00025370340306410486,25.0,60.0
788.64819,0.16216910236220472,925.0373717699001,0.00025370340306410486,25.0,60.0
790.04956,0.1626235531496063,923.1755096740684,0.00025370340306410486,25.0,60.0
791.45093,0.16309580314960628,923.1822880145436,0.00025370340306410486,25.0,60.0
792.85229,0.1635794803149606,923.6910531099858,0.00025370340306410486,25.0,60.0
794.25366,0.16400917322834646,924.2599142968446,0.00025370340306410486,25.0,60.0
795.65503,0.16450917125984252,924.2586417348397,0.00025370340306410486,25.0,60.0
797.0564,0.16497187007874015,922.6948967666536,0.00025370340306410486,25.0,60.0
798.45776,0.16540765354330708,923.2472146474485,0.00025370340306410486,25.0,60.0
799.85913,0.16586481299212597,923.7491234904559,0.00025370340306410486,25.0,60.0
801.2605,0.1662276279527559,923.4840150629789,0.00025370340306410486,25.0,60.0
802.66187,0.1666665433070866,924.2347487339307,0.00025370340306410486,25.0,60.0
804.06323,0.1671067598425197,924.0593689131282,0.00025370340306410486,25.0,60.0
805.4646,0.16759007480314958,927.0452149071549,0.00025370340306410486,25.0,60.0
806.86597,0.16814695472440944,924.4380210362291,0.00025370340306410486,25.0,60.0
808.26733,0.16858156496062993,922.8559927282171,0.00025370340306410486,25.0,60.0
809.6687,0.16902884645669292,923.5840280483054,0.00025370340306410486,25.0,60.0
811.07007,0.1694581062992126,923.7228152188028,0.00025370340306410486,25.0,60.0
812.47144,0.16984239173228347,924.5568887157513,0.00025370340306410486,25.0,60.0
813.8728,0.17023000984251968,924.5543695623945,0.00025370340306410486,25.0,60.0
815.27417,0.1706474527559055,924.5038306713415,0.00025370340306410486,25.0,60.0
816.67554,0.17115467913385826,926.1571743929361,0.00025370340306410486,25.0,60.0
818.0769,0.17168388188976377,925.3864173483964,0.00025370340306410486,25.0,60.0
819.47827,0.1721399744094488,924.8762758083367,0.00025370340306410486,25.0,60.0
820.87964,0.17265835826771653,927.7755356447215,0.00025370340306410486,25.0,60.0
822.28101,0.1731269114173228,925.712582781457,0.00025370340306410486,25.0,60.0
823.68237,0.1736041712598425,925.0707960005194,0.00025370340306410486,25.0,60.0
825.08374,0.17404034055118112,923.9154914946112,0.00025370340306410486,25.0,60.0
826.48511,0.1744645433070866,923.9379301389431,0.00025370340306410486,25.0,60.0
827.88647,0.17487683661417322,925.7884170886899,0.00025370340306410486,25.0,60.0
829.28784,0.17537897047244094,927.3403713803402,0.00025370340306410486,25.0,60.0
830.68921,0.17586992322834646,925.0869757174394,0.00025370340306410486,25.0,60.0
832.09058,0.17638615944881889,925.8773146344631,0.00025370340306410486,25.0,60.0
833.49194,0.17700037992125983,926.3069990910273,0.00025370340306410486,25.0,60.0
834.89331,0.177509155511811,925.250045448643,0.00025370340306410486,25.0,60.0
836.29468,0.17798433858267715,924.096714712375,0.00025370340306410486,25.0,60.0
837.69604,0.1783964094488189,923.9860018179459,0.00025370340306410486,25.0,60.0
839.09741,0.17889116141732284,927.0461238800157,0.00025370340306410486,25.0,60.0
840.49878,0.17946038582677165,926.9914037138035,0.00025370340306410486,25.0,60.0
841.90015,0.17998406299212596,925.4812102324374,0.00025370340306410486,25.0,60.0
843.30151,0.18045732086614175,925.327515907025,0.00025370340306410486,25.0,60.0
844.70288,0.1809218031496063,926.0326451110246,0.00025370340306410486,25.0,60.0
846.10425,0.18134202755905512,927.1655629139074,0.00025370340306410486,25.0,60.0
847.50562,0.18183403543307086,927.2786910790808,0.00025370340306410486,25.0,60.0
848.90698,0.18234994488188977,926.004804570835,0.00025370340306410486,25.0,60.0
850.30835,0.18281022637795277,926.0134268276848,0.00025370340306410486,25.0,60.0
851.70972,0.1833390649606299,928.3632774964291,0.00025370340306410486,25.0,60.0
853.11108,0.18384467125984252,926.9163225555124,0.00025370340306410486,25.0,60.0
854.51245,0.1843348976377953,924.3947019867551,0.00025370340306410486,25.0,60.0
855.91382,0.1848101968503937,926.5920010388262,0.00025370340306410486,25.0,60.0
857.31519,0.18528931102362203,927.2512400986885,0.00025370340306410486,25.0,60.0
857.71558,0.18546625787401574,929.731177769121,0.00025370340306410486,25.0,60.0