File: datasets/am_bench_2022/csv/60-XY.09-2.csv
Time(s),Strain(%),Stress(MPa),SR(s-1),Temp(C),Angle(deg)
11.468018,6.329996456692913e-06,16.799318530061033,0.00025370340306410486,25.0,60.0
12.969482,3.7336694881889764e-05,21.32897156213479,0.00025370340306410486,25.0,60.0
14.470947,4.2676765748031494e-05,26.001067393844956,0.00025370340306410486,25.0,60.0
15.972412,5.763441338582677e-05,30.827360083106093,0.00025370340306410486,25.0,60.0
17.473877,7.060627165354331e-05,35.48953382677574,0.00025370340306410486,25.0,60.0
18.975342,9.581309842519685e-05,39.7612180236333,0.00025370340306410486,25.0,60.0
20.476807,9.981976771653545e-05,45.1102324373458,0.00025370340306410486,25.0,60.0
21.978271,0.00011326493503937007,52.12831840020777,0.00025370340306410486,25.0,60.0
23.479736,0.00013913503149606298,59.45475652512661,0.00025370340306410486,25.0,60.0
24.981201,0.00014582847834645668,66.37521620568758,0.00025370340306410486,25.0,60.0
26.482666,0.00017793001377952754,74.58983508635244,0.00025370340306410486,25.0,60.0
27.984131,0.00018558821850393702,82.89038566419946,0.00025370340306410486,25.0,60.0
29.485596,0.00020566893700787404,90.58036358914427,0.00025370340306410486,25.0,60.0
30.987061,0.00022739687007874014,99.58473445007144,0.00025370340306410486,25.0,60.0
32.488525,0.00025965145669291337,107.1971925723932,0.00025370340306410486,25.0,60.0
33.98999,0.00030771795275590547,116.34642513959227,0.00025370340306410486,25.0,60.0
35.491455,0.0002964386614173228,123.37129463706013,0.00025370340306410486,25.0,60.0
36.99292,0.00033276366141732285,131.73759771458253,0.00025370340306410486,25.0,60.0
38.494385,0.0003609276968503937,141.95398259966237,0.00025370340306410486,25.0,60.0
39.99585,0.00037616444881889764,150.37460070120764,0.00025370340306410486,25.0,60.0
41.497314,0.0004248440157480315,160.2895753798208,0.00025370340306410486,25.0,60.0
42.998779,0.0004529356299212598,170.9682768471627,0.00025370340306410486,25.0,60.0
44.500244,0.0004912248622047243,181.2443916374497,0.00025370340306410486,25.0,60.0
46.001709,0.0005231341929133859,190.3985716140761,0.00025370340306410486,25.0,60.0
47.503174,0.0005498633858267717,200.44295546032984,0.00025370340306410486,25.0,60.0
49.004639,0.0005883064370078739,211.56265679781848,0.00025370340306410486,25.0,60.0
50.506104,0.0006061204527559055,222.76947409427348,0.00025370340306410486,25.0,60.0
52.007568,0.00061956,228.74973120373977,0.00025370340306410486,25.0,60.0
53.509033,0.0006912823031496063,243.39880275288925,0.00025370340306410486,25.0,60.0
55.010498,0.000719036751968504,254.41461368653424,0.00025370340306410486,25.0,60.0
56.511963,0.000741904311023622,264.0573172315284,0.00025370340306410486,25.0,60.0
58.013428,0.0007884770275590551,276.16725100636285,0.00025370340306410486,25.0,60.0
59.514893,0.0008533742716535434,288.8809764965589,0.00025370340306410486,25.0,60.0
61.016357,0.0008987368307086615,303.00184391637447,0.00025370340306410486,25.0,60.0
62.517822,0.0009115513976377952,313.0252434748734,0.00025370340306410486,25.0,60.0
64.019287,0.000966964094488189,323.7071029736398,0.00025370340306410486,25.0,60.0
65.520752,0.0009873304527559055,334.48201532268536,0.00025370340306410486,25.0,60.0
67.022217,0.0010055459645669292,344.9775613556681,0.00025370340306410486,25.0,60.0
68.523682,0.001069146220472441,356.73608622256853,0.00025370340306410486,25.0,60.0
70.025146,0.001105723720472441,367.4576288793663,0.00025370340306410486,25.0,60.0
71.526611,0.001133932342519685,379.14943513829377,0.00025370340306410486,25.0,60.0
73.028076,0.0011608772637795276,390.28941695883657,0.00025370340306410486,25.0,60.0
74.529541,0.001210250748031496,401.89998701467346,0.00025370340306410486,25.0,60.0
76.031006,0.0012495700787401574,412.72419166342036,0.00025370340306410486,25.0,60.0
77.532471,0.0012773283464566929,420.9107648357356,0.00025370340306410486,25.0,60.0
79.033936,0.0012994636614173229,429.94961693286587,0.00025370340306410486,25.0,60.0
80.5354,0.0013459773622047245,440.4057135436957,0.00025370340306410486,25.0,60.0
82.036865,0.0013622191338582676,450.6443838462538,0.00025370340306410486,25.0,60.0
83.53833,0.0014038350393700786,459.92045188936504,0.00025370340306410486,25.0,60.0
85.039795,0.0014486702559055118,470.9768861186859,0.00025370340306410486,25.0,60.0
86.54126,0.001471599842519685,482.21610180496043,0.00025370340306410486,25.0,60.0
88.042725,0.0015160382283464567,495.6372938579405,0.00025370340306410486,25.0,60.0
89.544189,0.0015416629921259843,504.73904687702895,0.00025370340306410486,25.0,60.0
91.045654,0.0015772054133858268,511.8825347357486,0.00025370340306410486,25.0,60.0
92.547119,0.0016182219291338582,522.0759381898455,0.00025370340306410486,25.0,60.0
94.048584,0.001654043562992126,532.1626542007531,0.00025370340306410486,25.0,60.0
95.550049,0.0016609454330708659,537.77626282301,0.00025370340306410486,25.0,60.0
97.051514,0.0016910088188976378,547.1736397870407,0.00025370340306410486,25.0,60.0
98.552979,0.0017282085433070863,554.3337748344371,0.00025370340306410486,25.0,60.0
100.05444,0.0017444540748031497,561.7473834566939,0.00025370340306410486,25.0,60.0
101.55591,0.0017761861417322834,567.8784573432022,0.00025370340306410486,25.0,60.0
103.05737,0.0018199034842519685,575.6122062069861,0.00025370340306410486,25.0,60.0
104.55884,0.0018304736417322834,582.4372938579405,0.00025370340306410486,25.0,60.0
106.0603,0.0018399412204724408,588.3893000908972,0.00025370340306410486,25.0,60.0
107.56177,0.0018706077755905512,595.3416439423452,0.00025370340306410486,25.0,60.0
109.06323,0.0018804163582677167,599.9901830931049,0.00025370340306410486,25.0,60.0
110.5647,0.001923218877952756,608.1848850798598,0.00025370340306410486,25.0,60.0
112.06616,0.001951399094488189,613.7136735488898,0.00025370340306410486,25.0,60.0
113.56763,0.0019687840551181105,617.2775223996883,0.00025370340306410486,25.0,60.0
115.06909,0.0019822622047244096,623.4116348526165,0.00025370340306410486,25.0,60.0
116.57056,0.0020024525590551182,626.93535904428,0.00025370340306410486,25.0,60.0
118.07202,0.002038771062992126,634.7980262303597,0.00025370340306410486,25.0,60.0
119.57349,0.0020577968503937005,638.2624594208545,0.00025370340306410486,25.0,60.0
121.07495,0.002086672244094488,643.7866251136217,0.00025370340306410486,25.0,60.0
122.57642,0.002094917125984252,646.3272562004935,0.00025370340306410486,25.0,60.0
124.07788,0.0021147096456692912,652.1432021815349,0.00025370340306410486,25.0,60.0
125.57935,0.0021505484251968503,653.7936371899754,0.00025370340306410486,25.0,60.0
127.08081,0.002168359842519685,660.2931307622388,0.00025370340306410486,25.0,60.0
128.58228,0.002210929921259842,665.2033502142579,0.00025370340306410486,25.0,60.0
130.08374,0.0022340864173228344,670.5068432671081,0.00025370340306410486,25.0,60.0
131.58521,0.0022885521653543306,671.5494870796001,0.00025370340306410486,25.0,60.0
133.08667,0.0022896645669291337,674.4068822230879,0.00025370340306410486,25.0,60.0
134.58813,0.002365393503937008,681.4794442280223,0.00025370340306410486,25.0,60.0
136.0896,0.002390701181102362,683.7410466173225,0.00025370340306410486,25.0,60.0
137.59106,0.0024532133858267717,686.671679002727,0.00025370340306410486,25.0,60.0
139.09253,0.002482596062992126,687.7066874431893,0.00025370340306410486,25.0,60.0
140.59399,0.002526001181102362,692.8579664978574,0.00025370340306410486,25.0,60.0
142.09546,0.0025838854330708662,695.9545253863134,0.00025370340306410486,25.0,60.0
143.59692,0.002654328346456693,701.8699649396183,0.00025370340306410486,25.0,60.0
145.09839,0.0027133088582677167,701.8939358524867,0.00025370340306410486,25.0,60.0
146.59985,0.0027937647637795277,707.3675626542008,0.00025370340306410486,25.0,60.0
148.10132,0.002889648622047244,709.5358784573432,0.00025370340306410486,25.0,60.0
149.60278,0.002973016535433071,711.4350344111155,0.00025370340306410486,25.0,60.0
151.10425,0.0030550655511811025,713.9397221140111,0.00025370340306410486,25.0,60.0
152.60571,0.003209108070866142,717.5863913777432,0.00025370340306410486,25.0,60.0
154.10718,0.003303787204724409,719.926217374367,0.00025370340306410486,25.0,60.0
155.60864,0.0034375047244094487,722.6596026490067,0.00025370340306410486,25.0,60.0
157.11011,0.0035553092519685038,724.1291520581743,0.00025370340306410486,25.0,60.0
158.61157,0.0037141011811023623,727.2044150110377,0.00025370340306410486,25.0,60.0
160.11304,0.003865220078740157,728.6664069601351,0.00025370340306410486,25.0,60.0
161.6145,0.004065926377952756,731.8171925723932,0.00025370340306410486,25.0,60.0
163.11597,0.004258896062992126,732.6706661472537,0.00025370340306410486,25.0,60.0
164.61743,0.00444860748031496,736.3603428126218,0.00025370340306410486,25.0,60.0
166.1189,0.004621732677165354,736.5180885599273,0.00025370340306410486,25.0,60.0
167.62036,0.00486225,741.2821451759512,0.00025370340306410486,25.0,60.0
169.12183,0.0050641903543307085,740.5080898584599,0.00025370340306410486,25.0,60.0
170.62329,0.005304577952755905,741.6409557200365,0.00025370340306410486,25.0,60.0
172.12476,0.0055443935039370075,745.559745487599,0.00025370340306410486,25.0,60.0
173.62622,0.005780450393700788,744.97527593819,0.00025370340306410486,25.0,60.0
175.12769,0.006029502165354331,746.584443578756,0.00025370340306410486,25.0,60.0
176.62915,0.006259313385826771,746.9256979613039,0.00025370340306410486,25.0,60.0
178.13062,0.0064531114173228335,748.4902739903908,0.00025370340306410486,25.0,60.0
179.63208,0.006735779527559055,751.0540968705362,0.00025370340306410486,25.0,60.0
181.13354,0.007039888582677165,753.3534865601871,0.00025370340306410486,25.0,60.0
182.63501,0.00735528937007874,753.9789637709389,0.00025370340306410486,25.0,60.0
184.13647,0.007702809842519685,755.859810414232,0.00025370340306410486,25.0,60.0
185.63794,0.00795962244094488,755.8928450850539,0.00025370340306410486,25.0,60.0
187.1394,0.008213223818897638,756.0377873003507,0.00025370340306410486,25.0,60.0
188.64087,0.008526236220472442,759.3939488378134,0.00025370340306410486,25.0,60.0
190.14233,0.008819411417322835,759.685157771718,0.00025370340306410486,25.0,60.0
191.6438,0.009137620078740158,760.6591351772498,0.00025370340306410486,25.0,60.0
193.14526,0.009457087992125983,763.5550188287236,0.00025370340306410486,25.0,60.0
194.64673,0.009810709645669291,764.2320477860018,0.00025370340306410486,25.0,60.0
196.14819,0.010136244291338583,764.5425529152058,0.00025370340306410486,25.0,60.0
197.64966,0.010396445472440945,764.8314764316323,0.00025370340306410486,25.0,60.0
199.15112,0.010748393897637794,769.0101285547332,0.00025370340306410486,25.0,60.0
200.65259,0.011148355905511812,767.7849629918194,0.00025370340306410486,25.0,60.0
202.15405,0.011489259448818897,768.3754317621089,0.00025370340306410486,25.0,60.0
203.65552,0.011786759842519685,768.8742500973899,0.00025370340306410486,25.0,60.0
205.15698,0.012123037598425196,770.5597974289054,0.00025370340306410486,25.0,60.0
206.65845,0.01249172401574803,773.421971172575,0.00025370340306410486,25.0,60.0
208.15991,0.012849186220472441,771.3933255421374,0.00025370340306410486,25.0,60.0
209.66138,0.013162640157480313,772.8681989352033,0.00025370340306410486,25.0,60.0
211.16284,0.013463178543307086,774.0820153226854,0.00025370340306410486,25.0,60.0
212.66431,0.01379135905511811,776.248746915985,0.00025370340306410486,25.0,60.0
214.16577,0.01413428090551181,774.9744448772886,0.00025370340306410486,25.0,60.0
215.66724,0.014474174015748032,776.5010258407999,0.00025370340306410486,25.0,60.0
217.1687,0.014824467125984252,776.6347487339307,0.00025370340306410486,25.0,60.0
218.67017,0.015157813188976377,779.2340475262954,0.00025370340306410486,25.0,60.0
220.17163,0.015530136811023621,781.6891312816517,0.00025370340306410486,25.0,60.0
221.6731,0.015852358267716537,780.4103882612649,0.00025370340306410486,25.0,60.0
223.17456,0.016234759448818897,781.3163225555123,0.00025370340306410486,25.0,60.0
224.67603,0.016562073031496063,780.8426178418388,0.00025370340306410486,25.0,60.0
226.17749,0.016903490157480317,783.2882742500974,0.00025370340306410486,25.0,60.0
227.67896,0.01726454842519685,783.9287365277238,0.00025370340306410486,25.0,60.0
229.18042,0.017663129527559055,785.6437086092715,0.00025370340306410486,25.0,60.0
230.68188,0.01799393248031496,784.116270614206,0.00025370340306410486,25.0,60.0
232.18335,0.018319202952755905,786.7232307492534,0.00025370340306410486,25.0,60.0
233.68481,0.018742111417322835,785.5688352162058,0.00025370340306410486,25.0,60.0
235.18628,0.019138435433070866,787.1487599013116,0.00025370340306410486,25.0,60.0
236.68774,0.019484039763779527,786.9315932995715,0.00025370340306410486,25.0,60.0
238.18921,0.019821135826771655,787.7160888196339,0.00025370340306410486,25.0,60.0
239.69067,0.02016046653543307,789.8763537202962,0.00025370340306410486,25.0,60.0
241.19214,0.020527980314960628,793.0099727308142,0.00025370340306410486,25.0,60.0
242.6936,0.020907257874015747,791.0371899753279,0.00025370340306410486,25.0,60.0
244.19507,0.021256275590551182,792.2229840280484,0.00025370340306410486,25.0,60.0
245.69653,0.0216231062992126,792.1514608492404,0.00025370340306410486,25.0,60.0
247.198,0.02199018897637795,792.2857550967408,0.00025370340306410486,25.0,60.0
248.69946,0.022359484251968504,793.8103882612647,0.00025370340306410486,25.0,60.0
250.20093,0.022694903543307086,793.6810284378653,0.00025370340306410486,25.0,60.0
251.70239,0.023084872047244093,796.3395403194392,0.00025370340306410486,25.0,60.0
253.20386,0.02345284251968504,795.5221919231269,0.00025370340306410486,25.0,60.0
254.70532,0.023847917322834648,799.1563693026881,0.00025370340306410486,25.0,60.0
256.20679,0.02421597244094488,797.4657317231529,0.00025370340306410486,25.0,60.0
257.70825,0.024525858267716534,797.162472406181,0.00025370340306410486,25.0,60.0
259.20972,0.024886875984251967,800.0397870406441,0.00025370340306410486,25.0,60.0
260.71118,0.025216340551181105,798.0739903908584,0.00025370340306410486,25.0,60.0
262.21265,0.025588714566929134,800.6349824698091,0.00025370340306410486,25.0,60.0
263.71411,0.026011824803149605,801.9343202181535,0.00025370340306410486,25.0,60.0
265.21558,0.02641304724409449,802.5656667965201,0.00025370340306410486,25.0,60.0
266.71704,0.026813783464566927,803.1825217504221,0.00025370340306410486,25.0,60.0
268.21851,0.02721516338582677,802.7308141799766,0.00025370340306410486,25.0,60.0
269.71997,0.027578385826771655,803.977691208934,0.00025370340306410486,25.0,60.0
271.22144,0.027947895669291338,804.223893000909,0.00025370340306410486,25.0,60.0
272.7229,0.02828935039370079,806.3655109726011,0.00025370340306410486,25.0,60.0
274.22437,0.028667003937007874,806.0384625373329,0.00025370340306410486,25.0,60.0
275.72583,0.029047299212598424,807.1304246201793,0.00025370340306410486,25.0,60.0
277.22729,0.029367501968503937,806.2185430463577,0.00025370340306410486,25.0,60.0
278.72876,0.0297420374015748,808.5633813790417,0.00025370340306410486,25.0,60.0
280.23022,0.03011104724409449,807.0307492533437,0.00025370340306410486,25.0,60.0
281.73169,0.03043869488188976,807.446513439813,0.00025370340306410486,25.0,60.0
283.23315,0.03076209842519685,810.2215556421245,0.00025370340306410486,25.0,60.0
284.73462,0.03111033858267716,808.7535904427997,0.00025370340306410486,25.0,60.0
286.23608,0.03143727952755906,810.9374366965329,0.00025370340306410486,25.0,60.0
287.73755,0.03181531889763779,812.4830801194651,0.00025370340306410486,25.0,60.0
289.23901,0.03221674803149606,811.6963511232308,0.00025370340306410486,25.0,60.0
290.74048,0.03258162598425197,811.6323594338398,0.00025370340306410486,25.0,60.0
292.24194,0.032923277559055115,812.9551227113362,0.00025370340306410486,25.0,60.0
293.74341,0.033326907480314964,815.0495779768861,0.00025370340306410486,25.0,60.0
295.24487,0.033723653543307086,814.9926503051552,0.00025370340306410486,25.0,60.0
296.74634,0.034109330708661414,815.7337228931308,0.00025370340306410486,25.0,60.0
298.2478,0.03444236220472441,814.5124788988443,0.00025370340306410486,25.0,60.0
299.74927,0.034817263779527555,815.8847422412673,0.00025370340306410486,25.0,60.0
301.25073,0.03517099606299213,815.9836644591612,0.00025370340306410486,25.0,60.0
302.7522,0.035586228346456694,817.6680690819375,0.00025370340306410486,25.0,60.0
304.25366,0.035953289370078745,817.176418646929,0.00025370340306410486,25.0,60.0
305.75513,0.036326726377952756,818.9760550577847,0.00025370340306410486,25.0,60.0
307.25659,0.036653641732283464,818.0109596156344,0.00025370340306410486,25.0,60.0
308.75806,0.03703033267716536,819.4591351772498,0.00025370340306410486,25.0,60.0
310.25952,0.03738642125984252,820.4822230879107,0.00025370340306410486,25.0,60.0
311.76099,0.037715395669291336,818.8338397610701,0.00025370340306410486,25.0,60.0
313.26245,0.038127407480314957,821.0893390468771,0.00025370340306410486,25.0,60.0
314.76392,0.038503259842519684,822.7237241916635,0.00025370340306410486,25.0,60.0
316.26538,0.03888207874015748,820.6352421763409,0.00025370340306410486,25.0,60.0
317.76685,0.039201872047244096,821.6498896247241,0.00025370340306410486,25.0,60.0
319.26831,0.03950853346456693,824.1807038047007,0.00025370340306410486,25.0,60.0
320.76978,0.0398883031496063,822.9088689780548,0.00025370340306410486,25.0,60.0
322.27124,0.04026125984251968,825.2537592520453,0.00025370340306410486,25.0,60.0
323.77271,0.04064080905511811,824.8815738215816,0.00025370340306410486,25.0,60.0
325.27417,0.041024929133858266,824.4764835735618,0.00025370340306410486,25.0,60.0
326.77563,0.04136752362204724,825.4207245812232,0.00025370340306410486,25.0,60.0
328.2771,0.04171225393700788,826.7917932736009,0.00025370340306410486,25.0,60.0
329.77856,0.04208215551181103,827.3439033891702,0.00025370340306410486,25.0,60.0
331.28003,0.0424681062992126,828.207998961174,0.00025370340306410486,25.0,60.0
332.78149,0.04284284448818897,828.1002726918583,0.00025370340306410486,25.0,60.0
334.28296,0.0432173031496063,829.7503181405012,0.00025370340306410486,25.0,60.0
335.78442,0.043600600393700784,829.4940397350994,0.00025370340306410486,25.0,60.0
337.28589,0.043988324803149605,831.9780547980782,0.00025370340306410486,25.0,60.0
338.78735,0.04432959645669291,830.9699779249448,0.00025370340306410486,25.0,60.0
340.28882,0.044640555118110235,830.0313206077134,0.00025370340306410486,25.0,60.0
341.79028,0.04499556299212599,833.8050123360604,0.00025370340306410486,25.0,60.0
343.29175,0.045424309055118114,832.521568627451,0.00025370340306410486,25.0,60.0
344.79321,0.04581247637795276,833.4730035060383,0.00025370340306410486,25.0,60.0
346.29468,0.04619283661417323,833.8253473574861,0.00025370340306410486,25.0,60.0
347.79614,0.046599263779527555,834.0006752369821,0.00025370340306410486,25.0,60.0
349.29761,0.04694353937007874,833.8954940916765,0.00025370340306410486,25.0,60.0
350.79907,0.04726505118110236,833.3141150499936,0.00025370340306410486,25.0,60.0
352.30054,0.047580712598425196,835.2142319179328,0.00025370340306410486,25.0,60.0
353.802,0.04797772047244095,837.6272432151669,0.00025370340306410486,25.0,60.0
355.30347,0.048359964566929134,836.6884041033633,0.00025370340306410486,25.0,60.0
356.80493,0.04871981299212599,837.4646149850669,0.00025370340306410486,25.0,60.0
358.3064,0.049085549212598424,837.2681210232438,0.00025370340306410486,25.0,60.0
359.80786,0.04949020669291339,837.5368913128166,0.00025370340306410486,25.0,60.0
361.30933,0.04979281692913386,838.6329827295157,0.00025370340306410486,25.0,60.0
362.81079,0.05011007677165354,837.5077782106221,0.00025370340306410486,25.0,60.0
364.31226,0.05048918700787401,839.2554213738475,0.00025370340306410486,25.0,60.0
365.81372,0.050900923228346454,839.5478509284509,0.00025370340306410486,25.0,60.0
367.31519,0.051260417322834644,840.0819633813791,0.00025370340306410486,25.0,60.0
368.81665,0.05163828543307087,840.2524607193872,0.00025370340306410486,25.0,60.0
370.31812,0.052030320866141726,841.2673678743022,0.00025370340306410486,25.0,60.0
371.81958,0.05243727362204725,843.0525386313466,0.00025370340306410486,25.0,60.0
373.32104,0.05278484055118109,842.0399168939099,0.00025370340306410486,25.0,60.0
374.82251,0.05312572637795275,842.886430333723,0.00025370340306410486,25.0,60.0
376.32397,0.0534870905511811,843.6961693286586,0.00025370340306410486,25.0,60.0
377.82544,0.053852092519685035,844.5435657706792,0.00025370340306410486,25.0,60.0
379.3269,0.05424208070866142,846.4135047396443,0.00025370340306410486,25.0,60.0
380.82837,0.054651568897637795,845.8541488118427,0.00025370340306410486,25.0,60.0
382.32983,0.05495752362204724,844.7174912349045,0.00025370340306410486,25.0,60.0
383.8313,0.055324021653543304,846.314037138034,0.00025370340306410486,25.0,60.0
385.33276,0.05571274212598425,848.1209972730815,0.00025370340306410486,25.0,60.0
386.83423,0.05611026968503936,846.083235943384,0.00025370340306410486,25.0,60.0
388.33569,0.05645416929133858,847.88837813271,0.00025370340306410486,25.0,60.0
389.83716,0.056755285433070866,846.2350863524217,0.00025370340306410486,25.0,60.0
391.33862,0.05711863188976378,850.068302817816,0.00025370340306410486,25.0,60.0
392.84009,0.05752196062992126,851.2902480197376,0.00025370340306410486,25.0,60.0
394.34155,0.05788087992125984,848.5158810544085,0.00025370340306410486,25.0,60.0
395.84302,0.058247114173228344,850.3061420594728,0.00025370340306410486,25.0,60.0
397.34448,0.05860236614173228,850.2460979093624,0.00025370340306410486,25.0,60.0
398.84595,0.059003970472440936,851.8124399428647,0.00025370340306410486,25.0,60.0
400.34741,0.0593413405511811,851.5321386832879,0.00025370340306410486,25.0,60.0
401.84888,0.05971148818897638,851.0909492273731,0.00025370340306410486,25.0,60.0
403.35034,0.06002222834645669,852.8851318010649,0.00025370340306410486,25.0,60.0
404.85181,0.060430216535433075,854.1103752759382,0.00025370340306410486,25.0,60.0
406.35327,0.06081834448818897,854.0545124009869,0.00025370340306410486,25.0,60.0
407.85474,0.061203358267716536,853.6237371769901,0.00025370340306410486,25.0,60.0
409.3562,0.06156916338582677,855.8540708998833,0.00025370340306410486,25.0,60.0
410.85767,0.06193406496062993,854.4974418906636,0.00025370340306410486,25.0,60.0
412.35913,0.06230440748031497,855.683235943384,0.00025370340306410486,25.0,60.0
413.8606,0.06269943897637796,856.4838072977535,0.00025370340306410486,25.0,60.0
415.36206,0.06311594488188976,855.8092974938321,0.00025370340306410486,25.0,60.0
416.86353,0.06344613976377952,856.2213738475523,0.00025370340306410486,25.0,60.0
418.36499,0.0637831594488189,857.1185560316842,0.00025370340306410486,25.0,60.0
419.86646,0.06409103149606299,858.7790676535515,0.00025370340306410486,25.0,60.0
421.36792,0.0644428405511811,858.1742890533696,0.00025370340306410486,25.0,60.0
422.86938,0.0648186909448819,858.4005973250228,0.00025370340306410486,25.0,60.0
424.37085,0.06518939960629921,858.8982469809116,0.00025370340306410486,25.0,60.0
425.87231,0.06554046456692912,859.7608881963382,0.00025370340306410486,25.0,60.0
427.37378,0.06591991535433071,860.6330866121283,0.00025370340306410486,25.0,60.0
428.87524,0.06632436417322835,860.8486690040255,0.00025370340306410486,25.0,60.0
430.37671,0.06669414173228345,861.0200493442411,0.00025370340306410486,25.0,60.0
431.87817,0.06702999803149606,860.8309050772626,0.00025370340306410486,25.0,60.0
433.37964,0.06741222637795274,860.0557070510323,0.00025370340306410486,25.0,60.0
434.8811,0.06775698228346456,860.7361121932217,0.00025370340306410486,25.0,60.0
436.38257,0.06810060629921261,861.8755746007012,0.00025370340306410486,25.0,60.0
437.88403,0.06851869488188976,863.0094273470978,0.00025370340306410486,25.0,60.0
439.3855,0.06892174803149606,863.7241916634204,0.00025370340306410486,25.0,60.0
440.88696,0.06927857874015748,862.0139722114012,0.00025370340306410486,25.0,60.0
442.38843,0.06966892913385826,865.3676405661603,0.00025370340306410486,25.0,60.0
443.88989,0.07003418503937008,864.3955330476562,0.00025370340306410486,25.0,60.0
445.39136,0.07034062598425196,865.6439683158031,0.00025370340306410486,25.0,60.0
446.89282,0.0706938779527559,866.1528632645111,0.00025370340306410486,25.0,60.0
448.39429,0.07112288385826772,866.1219841579016,0.00025370340306410486,25.0,60.0
449.89575,0.07150527559055117,865.6172704843527,0.00025370340306410486,25.0,60.0
451.39722,0.07189017716535433,865.6046487469159,0.00025370340306410486,25.0,60.0
452.89868,0.07225567716535433,865.6013504739644,0.00025370340306410486,25.0,60.0
454.40015,0.07265763385826772,867.7115439553306,0.00025370340306410486,25.0,60.0
455.90161,0.07300119291338582,866.4736787430205,0.00025370340306410486,25.0,60.0
457.40308,0.07330913779527559,868.1308401506298,0.00025370340306410486,25.0,60.0
458.90454,0.07367760039370079,869.2278665108428,0.00025370340306410486,25.0,60.0
460.40601,0.07405549212598425,869.0768471627061,0.00025370340306410486,25.0,60.0
461.90747,0.07441750787401574,869.8424620179197,0.00025370340306410486,25.0,60.0
463.40894,0.0747869625984252,869.7584988962473,0.00025370340306410486,25.0,60.0
464.9104,0.07514676181102362,871.0359953252826,0.00025370340306410486,25.0,60.0
466.41187,0.0754753720472441,871.7375665497988,0.00025370340306410486,25.0,60.0
467.91333,0.07587004330708662,871.9322685365537,0.00025370340306410486,25.0,60.0
469.41479,0.07625511417322835,872.857732761979,0.00025370340306410486,25.0,60.0
470.91626,0.07667306299212598,872.0132450331126,0.00025370340306410486,25.0,60.0
472.41772,0.07702914173228347,872.7692767173095,0.00025370340306410486,25.0,60.0
473.91919,0.07745986220472441,872.5366575769382,0.00025370340306410486,25.0,60.0
475.42065,0.07783901377952757,872.3934294247501,0.00025370340306410486,25.0,60.0
476.92212,0.07818928543307087,872.8172964550058,0.00025370340306410486,25.0,60.0
478.42358,0.07860867716535433,874.0359953252826,0.00025370340306410486,25.0,60.0
479.92505,0.07896722440944881,874.7515907025063,0.00025370340306410486,25.0,60.0
481.42651,0.07935697244094489,875.041527074406,0.00025370340306410486,25.0,60.0
482.92798,0.07975842913385826,874.8470068822231,0.00025370340306410486,25.0,60.0
484.42944,0.08014414173228346,874.68082067264,0.00025370340306410486,25.0,60.0
485.93091,0.08053674015748032,873.3933774834438,0.00025370340306410486,25.0,60.0
487.43237,0.0808816496062992,876.1580833657966,0.00025370340306410486,25.0,60.0
488.93384,0.0811853622047244,875.6197117257499,0.00025370340306410486,25.0,60.0
490.4353,0.0815311220472441,877.8179716919882,0.00025370340306410486,25.0,60.0
491.93677,0.0819304153543307,878.0469809115699,0.00025370340306410486,25.0,60.0
493.43823,0.08235628346456693,877.4627191273861,0.00025370340306410486,25.0,60.0
494.9397,0.08269638779527559,876.9015192832101,0.00025370340306410486,25.0,60.0
496.44116,0.0830226594488189,878.3491754317622,0.00025370340306410486,25.0,60.0
497.94263,0.08338690354330708,878.9491754317621,0.00025370340306410486,25.0,60.0
499.44409,0.08377259251968504,879.3129983119076,0.00025370340306410486,25.0,60.0
500.94556,0.08410961614173228,879.426619919491,0.00025370340306410486,25.0,60.0
502.44702,0.08449442322834645,881.4140501233607,0.00025370340306410486,25.0,60.0
503.94849,0.08489127559055118,880.4111673808596,0.00025370340306410486,25.0,60.0
505.44995,0.08529896259842519,881.6104661732243,0.00025370340306410486,25.0,60.0
506.95142,0.08562314566929134,879.8410855733023,0.00025370340306410486,25.0,60.0
508.45288,0.08598807086614174,881.6926373198286,0.00025370340306410486,25.0,60.0
509.95435,0.08640141535433071,882.2062848980653,0.00025370340306410486,25.0,60.0
511.45581,0.08677876574803149,883.6497597714582,0.00025370340306410486,25.0,60.0
512.95728,0.08714976968503937,882.1326840670043,0.00025370340306410486,25.0,60.0
514.45874,0.08752182874015747,882.5770159719517,0.00025370340306410486,25.0,60.0
515.96021,0.08789445275590552,883.2336319958447,0.00025370340306410486,25.0,60.0
517.46167,0.08830877559055117,883.8244383846254,0.00025370340306410486,25.0,60.0
518.96313,0.08867925,882.2052720425919,0.00025370340306410486,25.0,60.0
520.4646,0.08905450787401574,884.2824827944423,0.00025370340306410486,25.0,60.0
521.96606,0.08946604921259842,886.1084015062979,0.00025370340306410486,25.0,60.0
523.46753,0.08983152165354331,885.2656278405402,0.00025370340306410486,25.0,60.0
524.96899,0.09024118503937008,887.9725230489547,0.00025370340306410486,25.0,60.0
526.47046,0.09066896653543306,884.3789118296326,0.00025370340306410486,25.0,60.0
527.97192,0.09106682086614173,888.7524737047137,0.00025370340306410486,25.0,60.0
529.47339,0.09143373031496063,884.793585248669,0.00025370340306410486,25.0,60.0
530.97485,0.09172416732283464,885.1603947539281,0.00025370340306410486,25.0,60.0
532.47632,0.09207631692913386,886.9624204648746,0.00025370340306410486,25.0,60.0
533.97778,0.09245306299212598,886.9714063108687,0.00025370340306410486,25.0,60.0
535.47925,0.09281419881889764,887.8428515777172,0.00025370340306410486,25.0,60.0
536.98071,0.09320135433070866,889.0730294766914,0.00025370340306410486,25.0,60.0
538.48218,0.09354665551181102,887.67425009739,0.00025370340306410486,25.0,60.0
539.98364,0.09397377362204724,889.898454746137,0.00025370340306410486,25.0,60.0
541.48511,0.09435140748031497,889.1429165043502,0.00025370340306410486,25.0,60.0
542.98657,0.09476024409448819,889.3422672380211,0.00025370340306410486,25.0,60.0
544.48804,0.09516792716535433,890.4812102324374,0.00025370340306410486,25.0,60.0
545.9895,0.09558041338582676,890.358940397351,0.00025370340306410486,25.0,60.0
547.49097,0.09594238188976378,890.3318270354499,0.00025370340306410486,25.0,60.0
548.99243,0.09633066338582677,892.2019997402936,0.00025370340306410486,25.0,60.0
550.4939,0.09677087992125984,891.0879106609532,0.00025370340306410486,25.0,60.0
551.99536,0.09717272440944881,891.982677574341,0.00025370340306410486,25.0,60.0
553.49683,0.09752755511811023,891.3211790676536,0.00025370340306410486,25.0,60.0
554.99829,0.09790326968503937,890.898454746137,0.00025370340306410486,25.0,60.0
556.49976,0.09829116338582677,893.376574470848,0.00025370340306410486,25.0,60.0
558.00122,0.09863860039370079,891.577223737177,0.00025370340306410486,25.0,60.0
559.50269,0.09903980511811024,893.1044539670173,0.00025370340306410486,25.0,60.0
561.00415,0.09941002362204725,893.6823789118296,0.00025370340306410486,25.0,60.0
562.50562,0.09978338582677165,894.2457343202182,0.00025370340306410486,25.0,60.0
564.00708,0.10017677559055117,895.0372159459811,0.00025370340306410486,25.0,60.0
565.50854,0.1005512401574803,894.9457213348916,0.00025370340306410486,25.0,60.0
567.01001,0.10091277559055117,894.9135696662772,0.00025370340306410486,25.0,60.0
568.51147,0.10125375393700788,894.7882352941176,0.00025370340306410486,25.0,60.0
570.01294,0.10161301377952757,896.6832099727309,0.00025370340306410486,25.0,60.0
571.5144,0.10199652362204725,896.6658356057656,0.00025370340306410486,25.0,60.0
573.01587,0.10237193897637796,895.3446045968057,0.00025370340306410486,25.0,60.0
574.51733,0.10280293503937007,895.5617192572394,0.00025370340306410486,25.0,60.0
576.0188,0.10320768307086614,895.8955460329827,0.00025370340306410486,25.0,60.0
577.52026,0.1035680688976378,897.6507726269316,0.00025370340306410486,25.0,60.0
579.02173,0.10390396653543309,896.0373198285937,0.00025370340306410486,25.0,60.0
580.52319,0.10429670078740158,898.3880534995455,0.00025370340306410486,25.0,60.0
582.02466,0.10470537992125985,896.4358654720166,0.00025370340306410486,25.0,60.0
583.52612,0.10515508858267716,898.7913517724971,0.00025370340306410486,25.0,60.0
585.02759,0.10559980118110235,898.1641085573303,0.00025370340306410486,25.0,60.0
586.52905,0.10605690354330707,900.4627191273861,0.00025370340306410486,25.0,60.0
588.03052,0.10643440748031495,898.8564861706271,0.00025370340306410486,25.0,60.0
589.53198,0.10680915354330708,897.6142578885859,0.00025370340306410486,25.0,60.0
591.03345,0.10722564566929134,902.059005323984,0.00025370340306410486,25.0,60.0
592.53491,0.10767266929133858,900.3296195299313,0.00025370340306410486,25.0,60.0
594.03638,0.1080467125984252,900.4522010128555,0.00025370340306410486,25.0,60.0
595.53784,0.1084419094488189,900.7212829502663,0.00025370340306410486,25.0,60.0
597.03931,0.10880461811023621,901.7381119335153,0.00025370340306410486,25.0,60.0
598.54077,0.10920792322834645,903.078743020387,0.00025370340306410486,25.0,60.0
600.04224,0.10957831692913386,901.3958446954941,0.00025370340306410486,25.0,60.0
601.5437,0.10996348228346456,901.8493182703545,0.00025370340306410486,25.0,60.0
603.04517,0.11038472834645668,900.8069341643943,0.00025370340306410486,25.0,60.0
604.54663,0.11080724015748031,904.1493312556812,0.00025370340306410486,25.0,60.0
606.0481,0.1112364527559055,902.4167251006363,0.00025370340306410486,25.0,60.0
607.54956,0.11164934448818897,901.422594468251,0.00025370340306410486,25.0,60.0
609.05103,0.11209877165354332,904.3622386703025,0.00025370340306410486,25.0,60.0
610.55249,0.11246308858267716,902.8456044669524,0.00025370340306410486,25.0,60.0
612.05396,0.11284001771653542,903.642669783145,0.00025370340306410486,25.0,60.0
613.55542,0.11324163188976377,903.6615504479938,0.00025370340306410486,25.0,60.0
615.05688,0.11362493307086614,904.2103882612648,0.00025370340306410486,25.0,60.0
616.55835,0.11405569291338584,905.2374756525127,0.00025370340306410486,25.0,60.0
618.05981,0.11449392913385827,905.2760940137646,0.00025370340306410486,25.0,60.0
619.56128,0.11487055314960629,903.6918582002338,0.00025370340306410486,25.0,60.0
621.06274,0.11529869685039369,907.2754447474355,0.00025370340306410486,25.0,60.0
622.56421,0.11572132677165353,905.4400727178289,0.00025370340306410486,25.0,60.0
624.06567,0.11609945275590551,905.6928710557071,0.00025370340306410486,25.0,60.0
625.56714,0.11653041338582676,905.875211011557,0.00025370340306410486,25.0,60.0
627.0686,0.11693741338582678,906.742085443449,0.00025370340306410486,25.0,60.0
628.57007,0.11736071259842519,906.9161407609402,0.00025370340306410486,25.0,60.0
630.07153,0.11779366732283464,907.6229580573952,0.00025370340306410486,25.0,60.0
631.573,0.11818966338582677,907.2642254252695,0.00025370340306410486,25.0,60.0
633.07446,0.11866097440944882,908.9103493052851,0.00025370340306410486,25.0,60.0
634.57593,0.11904332283464567,907.7414621477731,0.00025370340306410486,25.0,60.0
636.07739,0.11942872440944882,906.9740293468382,0.00025370340306410486,25.0,60.0
637.57886,0.1198273937007874,907.5577976886119,0.00025370340306410486,25.0,60.0
639.08032,0.12022124212598426,908.3369692247761,0.00025370340306410486,25.0,60.0
640.58179,0.12060600984251969,908.023555382418,0.00025370340306410486,25.0,60.0
642.08325,0.12101405511811023,909.1136216075835,0.00025370340306410486,25.0,60.0
643.58472,0.12144110826771654,909.6155304505909,0.00025370340306410486,25.0,60.0
645.08618,0.12186817322834645,910.3417218543046,0.00025370340306410486,25.0,60.0
646.58765,0.12227714566929133,908.3603168419686,0.00025370340306410486,25.0,60.0
648.08911,0.1226777874015748,910.1389429944163,0.00025370340306410486,25.0,60.0
649.59058,0.12309830511811025,911.3984677314636,0.00025370340306410486,25.0,60.0
651.09204,0.12351646456692914,912.2328269055967,0.00025370340306410486,25.0,60.0
652.59351,0.12396854527559056,909.4712115309701,0.00025370340306410486,25.0,60.0
654.09497,0.12433718897637797,911.4393195688872,0.00025370340306410486,25.0,60.0
655.59644,0.12479199212598424,910.1452798337879,0.00025370340306410486,25.0,60.0
657.0979,0.12525580511811024,913.117387352292,0.00025370340306410486,25.0,60.0
658.59937,0.12575262401574802,912.9584209842877,0.00025370340306410486,25.0,60.0
660.10083,0.12616655905511812,911.2469289702636,0.00025370340306410486,25.0,60.0
661.60229,0.1265464212598425,912.4619659784444,0.00025370340306410486,25.0,60.0
663.10376,0.12695973622047244,914.4827425009739,0.00025370340306410486,25.0,60.0
664.60522,0.12740606692913387,911.891572523049,0.00025370340306410486,25.0,60.0
666.10669,0.12781676377952758,912.9697182184133,0.00025370340306410486,25.0,60.0
667.60815,0.1282801771653543,914.9729905207117,0.00025370340306410486,25.0,60.0
669.10962,0.128773031496063,914.1030775223998,0.00025370340306410486,25.0,60.0
670.61108,0.129153937007874,913.3787300350605,0.00025370340306410486,25.0,60.0
672.11255,0.1295171496062992,912.7279574081288,0.00025370340306410486,25.0,60.0
673.61401,0.12992858661417322,913.1106090118167,0.00025370340306410486,25.0,60.0
675.11548,0.1303092342519685,914.065108427477,0.00025370340306410486,25.0,60.0
676.61694,0.1307075059055118,914.4255551227114,0.00025370340306410486,25.0,60.0
678.11841,0.1311713897637795,915.2488767692508,0.00025370340306410486,25.0,60.0
679.61987,0.13155193307086613,914.9639267627581,0.00025370340306410486,25.0,60.0
681.12134,0.13192392322834645,914.7427606804312,0.00025370340306410486,25.0,60.0
682.6228,0.1323353346456693,915.3286326451112,0.00025370340306410486,25.0,60.0
684.12427,0.13283276377952755,915.4054798078172,0.00025370340306410486,25.0,60.0
685.62573,0.13332486614173228,915.9143747565253,0.00025370340306410486,25.0,60.0
687.1272,0.133795718503937,915.595325282431,0.00025370340306410486,25.0,60.0
688.62866,0.1342157559055118,915.8558369042981,0.00025370340306410486,25.0,60.0
690.13013,0.1346987539370079,917.9817426308273,0.00025370340306410486,25.0,60.0
691.63159,0.13513918307086614,917.6828463835866,0.00025370340306410486,25.0,60.0
693.13306,0.13559819685039368,917.8910790806389,0.00025370340306410486,25.0,60.0
694.63452,0.1360404212598425,916.654694195559,0.00025370340306410486,25.0,60.0
696.13599,0.13645244488188976,916.7263212569796,0.00025370340306410486,25.0,60.0
697.63745,0.13687583661417324,917.1186079729906,0.00025370340306410486,25.0,60.0
699.13892,0.137316405511811,918.9745487599014,0.00025370340306410486,25.0,60.0
700.64038,0.13776776968503937,918.0805349954552,0.00025370340306410486,25.0,60.0
702.14185,0.13825362992125986,919.3782365926504,0.00025370340306410486,25.0,60.0
703.64331,0.13877639173228346,919.8132710037657,0.00025370340306410486,25.0,60.0
705.14478,0.13919240354330709,918.2260485651215,0.00025370340306410486,25.0,60.0
706.64624,0.1396369153543307,919.0647708089859,0.00025370340306410486,25.0,60.0
708.14771,0.14005870078740157,919.727983378782,0.00025370340306410486,25.0,60.0
709.64917,0.14048919291338582,917.6500194779899,0.00025370340306410486,25.0,60.0
711.15063,0.1409275787401575,921.0845864173484,0.00025370340306410486,25.0,60.0
712.6521,0.14132942913385826,918.509855862875,0.00025370340306410486,25.0,60.0
714.15356,0.14178520669291336,920.1882352941177,0.00025370340306410486,25.0,60.0
715.65503,0.14220051377952755,918.0603817686016,0.00025370340306410486,25.0,60.0
717.15649,0.14263047637795276,920.9475133099598,0.00025370340306410486,25.0,60.0
718.65796,0.14305747244094488,920.1034670821972,0.00025370340306410486,25.0,60.0
720.15942,0.1435145275590551,920.6024672120503,0.00025370340306410486,25.0,60.0
721.66089,0.1439447125984252,921.7235943383977,0.00025370340306410486,25.0,60.0
723.16235,0.14442812007874015,921.6218932606156,0.00025370340306410486,25.0,60.0
724.66382,0.1448549153543307,920.3269705233088,0.00025370340306410486,25.0,60.0
726.16528,0.14529221259842517,921.370497338008,0.00025370340306410486,25.0,60.0
727.66675,0.14579062598425196,922.0144396831581,0.00025370340306410486,25.0,60.0
729.16821,0.14622381496062992,920.8434748733931,0.00025370340306410486,25.0,60.0
730.66968,0.14670302362204724,922.06414751331,0.00025370340306410486,25.0,60.0
732.17114,0.14718350984251968,922.9673289183223,0.00025370340306410486,25.0,60.0
733.67261,0.1476988897637795,923.8451889365018,0.00025370340306410486,25.0,60.0
735.17407,0.14815546456692913,922.0798078171666,0.00025370340306410486,25.0,60.0
736.67554,0.14864769488188975,922.1993767043241,0.00025370340306410486,25.0,60.0
738.177,0.1490991771653543,922.5260355797948,0.00025370340306410486,25.0,60.0
739.67847,0.14949760039370077,921.3515387611999,0.00025370340306410486,25.0,60.0
741.17993,0.1499253937007874,922.0614725360343,0.00025370340306410486,25.0,60.0
742.6814,0.15039644685039372,924.7804700688223,0.00025370340306410486,25.0,60.0
744.18286,0.15082798228346458,922.4948448253474,0.00025370340306410486,25.0,60.0
745.68433,0.15132037598425196,923.1910401246591,0.00025370340306410486,25.0,60.0
747.18579,0.1517148937007874,923.0618880664849,0.00025370340306410486,25.0,60.0
748.68726,0.15214597244094488,923.0129333852747,0.00025370340306410486,25.0,60.0
750.18872,0.15272449999999999,923.5890144137126,0.00025370340306410486,25.0,60.0
751.69019,0.153208718503937,924.6674198156085,0.00025370340306410486,25.0,60.0
753.19165,0.15364359645669293,924.1729126087521,0.00025370340306410486,25.0,60.0
754.69312,0.15413038385826772,925.0554473445007,0.00025370340306410486,25.0,60.0
756.19458,0.15459751771653543,924.1096480976497,0.00025370340306410486,25.0,60.0
757.69604,0.15513523818897637,924.4543825477211,0.00025370340306410486,25.0,60.0
759.19751,0.15563825196850395,924.4189845474614,0.00025370340306410486,25.0,60.0
760.69897,0.15615696456692915,924.0050902480198,0.00025370340306410486,25.0,60.0
762.20044,0.15664975984251966,923.0879885729126,0.00025370340306410486,25.0,60.0
763.7019,0.15705597440944882,924.3221659524737,0.00025370340306410486,25.0,60.0
765.20337,0.15760771653543307,926.3910660953123,0.00025370340306410486,25.0,60.0
766.70483,0.15808972834645668,927.0524607193871,0.00025370340306410486,25.0,60.0
768.2063,0.1585638307086614,925.6085962861966,0.00025370340306410486,25.0,60.0
769.70776,0.15907119881889764,925.3255681080379,0.00025370340306410486,25.0,60.0
771.20923,0.15956506102362206,926.2991299831192,0.00025370340306410486,25.0,60.0
772.71069,0.16007760236220472,926.6490845344761,0.00025370340306410486,25.0,60.0
774.21216,0.16055834645669292,925.1321127126348,0.00025370340306410486,25.0,60.0
775.71362,0.1610169842519685,926.1447604207245,0.00025370340306410486,25.0,60.0
777.21509,0.16145560629921257,924.7944163095702,0.00025370340306410486,25.0,60.0
778.71655,0.16193437992125984,927.3326321256981,0.00025370340306410486,25.0,60.0
780.21802,0.1624219527559055,924.8682768471627,0.00025370340306410486,25.0,60.0
781.71948,0.1629462283464567,925.0860148032724,0.00025370340306410486,25.0,60.0
783.22095,0.16334107283464566,924.9358005453837,0.00025370340306410486,25.0,60.0
784.72241,0.16383588582677167,926.8879106609533,0.00025370340306410486,25.0,60.0
786.22388,0.16421712007874015,925.8320477860018,0.00025370340306410486,25.0,60.0
787.72534,0.1647248503937008,927.4196857550968,0.00025370340306410486,25.0,60.0
789.22681,0.16523036417322834,927.7466822490586,0.00025370340306410486,25.0,60.0
790.72827,0.1657019212598425,927.8540708998831,0.00025370340306410486,25.0,60.0
792.22974,0.16625523622047245,927.5236722503572,0.00025370340306410486,25.0,60.0
793.7312,0.1667702755905512,926.9420594727958,0.00025370340306410486,25.0,60.0
795.23267,0.16731679724409448,929.0517335410987,0.00025370340306410486,25.0,60.0
796.73413,0.16784131692913384,926.4783794312428,0.00025370340306410486,25.0,60.0
798.2356,0.16833125984251968,927.0957537982081,0.00025370340306410486,25.0,60.0
799.73706,0.16882938188976376,928.113855343462,0.00025370340306410486,25.0,60.0
801.23853,0.16931268503937008,928.2180236332945,0.00025370340306410486,25.0,60.0
802.73999,0.16982405118110236,928.6505129203999,0.00025370340306410486,25.0,60.0
804.24146,0.17032502362204724,927.7667056226464,0.00025370340306410486,25.0,60.0
805.74292,0.17089332086614173,928.665601869887,0.00025370340306410486,25.0,60.0
807.24438,0.17134134251968505,928.4579405272043,0.00025370340306410486,25.0,60.0
808.74585,0.1718255,928.0709258537853,0.00025370340306410486,25.0,60.0
810.24731,0.17236454724409447,929.7825996623816,0.00025370340306410486,25.0,60.0
811.74878,0.17287487204724408,928.6003635891443,0.00025370340306410486,25.0,60.0
813.25024,0.17335820866141732,926.8954681210233,0.00025370340306410486,25.0,60.0
814.75171,0.1738667244094488,927.6717828853396,0.00025370340306410486,25.0,60.0
816.25317,0.17444587598425199,929.7094403324244,0.00025370340306410486,25.0,60.0
817.75464,0.1749963503937008,929.9833528113232,0.00025370340306410486,25.0,60.0
819.2561,0.17550648622047244,929.756369302688,0.00025370340306410486,25.0,60.0
820.75757,0.1760256338582677,928.9802103622907,0.00025370340306410486,25.0,60.0
822.25903,0.17647295078740158,927.7560576548501,0.00025370340306410486,25.0,60.0
823.7605,0.17710498228346455,929.8011946500455,0.00025370340306410486,25.0,60.0
825.26196,0.17752916141732283,926.0845864173484,0.00025370340306410486,25.0,60.0
826.76343,0.17800153937007873,930.1944163095702,0.00025370340306410486,25.0,60.0
828.26489,0.1785964940944882,930.3500844046229,0.00025370340306410486,25.0,60.0
829.76636,0.17914813188976378,929.7697441890664,0.00025370340306410486,25.0,60.0
831.26782,0.17972868897637795,930.253395662901,0.00025370340306410486,25.0,60.0
832.76929,0.18024109055118112,929.5075444747436,0.00025370340306410486,25.0,60.0
834.27075,0.18082965157480316,929.1070250616804,0.00025370340306410486,25.0,60.0
835.77222,0.181389405511811,930.1952993117777,0.00025370340306410486,25.0,60.0
837.27368,0.18190818897637795,927.6044669523438,0.00025370340306410486,25.0,60.0
838.77515,0.18245801968503939,930.0178418387222,0.00025370340306410486,25.0,60.0
840.27661,0.18299049606299211,930.8521750422022,0.00025370340306410486,25.0,60.0
841.77808,0.18355854527559054,930.1616932865861,0.00025370340306410486,25.0,60.0
843.27954,0.18408647047244095,930.5593299571485,0.00025370340306410486,25.0,60.0
844.78101,0.18473132677165352,930.5462667186081,0.00025370340306410486,25.0,60.0
846.28247,0.18537824803149605,931.9716660174004,0.00025370340306410486,25.0,60.0
847.78394,0.18600835629921258,929.260459680561,0.00025370340306410486,25.0,60.0
849.2854,0.18648784448818898,928.4785612258148,0.00025370340306410486,25.0,60.0
850.78687,0.18701363188976378,929.4759901311518,0.00025370340306410486,25.0,60.0
852.28833,0.18742190157480315,928.2823789118296,0.00025370340306410486,25.0,60.0
853.78979,0.18796720078740156,929.4241786780939,0.00025370340306410486,25.0,60.0
855.29126,0.1884310964566929,929.9037008180757,0.00025370340306410486,25.0,60.0
856.79272,0.18904295866141732,931.0163355408389,0.00025370340306410486,25.0,60.0
858.29419,0.1895996062992126,930.9571224516297,0.00025370340306410486,25.0,60.0
859.79565,0.19014220866141732,930.3249707830153,0.00025370340306410486,25.0,60.0
861.29712,0.1906856771653543,931.1669393585248,0.00025370340306410486,25.0,60.0
862.79858,0.1913200216535433,931.6737826256331,0.00025370340306410486,25.0,60.0
864.30005,0.19184993897637795,930.1534086482275,0.00025370340306410486,25.0,60.0
865.80151,0.19239051181102362,930.4030125957668,0.00025370340306410486,25.0,60.0
867.30298,0.19293368897637794,930.2789507856123,0.00025370340306410486,25.0,60.0
868.80444,0.19353043897637795,930.5881054408519,0.00025370340306410486,25.0,60.0
870.30591,0.1941941968503937,930.9448902739905,0.00025370340306410486,25.0,60.0
871.80737,0.19480002952755907,930.5253343721595,0.00025370340306410486,25.0,60.0
873.30884,0.19538334448818898,930.2225684975978,0.00025370340306410486,25.0,60.0
874.8103,0.1960126437007874,930.8968965069472,0.00025370340306410486,25.0,60.0
876.31177,0.1966284251968504,930.5526554992858,0.00025370340306410486,25.0,60.0
877.81323,0.19718655511811026,929.4035839501364,0.00025370340306410486,25.0,60.0
879.3147,0.19771391732283464,931.5143228152189,0.00025370340306410486,25.0,60.0
880.81616,0.19832937007874016,931.4450331125829,0.00025370340306410486,25.0,60.0
882.31763,0.19892173228346455,930.790676535515,0.00025370340306410486,25.0,60.0
883.81909,0.19948452755905513,930.6364887676926,0.00025370340306410486,25.0,60.0
885.32056,0.2000596062992126,930.0878327489936,0.00025370340306410486,25.0,60.0
886.82202,0.20061708661417324,929.7942085443449,0.00025370340306410486,25.0,60.0
888.32349,0.20113218503937005,930.4999610440203,0.00025370340306410486,25.0,60.0
889.82495,0.20177543307086615,930.3997922347747,0.00025370340306410486,25.0,60.0
891.32642,0.20237454724409448,929.8413193091807,0.00025370340306410486,25.0,60.0
892.82788,0.20304824803149607,931.7495649915596,0.00025370340306410486,25.0,60.0
894.32935,0.20377027559055116,931.327334112453,0.00025370340306410486,25.0,60.0
895.83081,0.20446257874015747,931.3029996104402,0.00025370340306410486,25.0,60.0
897.33228,0.20505072834645668,929.3592001038827,0.00025370340306410486,25.0,60.0
898.83374,0.20561990157480314,930.9658745617453,0.00025370340306410486,25.0,60.0
900.33521,0.20625992125984252,930.3094403324244,0.00025370340306410486,25.0,60.0
901.83667,0.20681458661417323,928.9368393715101,0.00025370340306410486,25.0,60.0
903.33813,0.20734564960629923,929.0455784962992,0.00025370340306410486,25.0,60.0
904.53931,0.2078633661417323,933.9051292039994,0.00025370340306410486,25.0,60.0