File: datasets/am_bench_2022/csv/60-XY.15-3.csv
Time(s),Strain(%),Stress(MPa),SR(s-1),Temp(C),Angle(deg)
19.525146,7.82962716535433e-06,22.638318659914297,0.00025370340306410486,25.0,60.0
21.427002,1.972036220472441e-05,29.490715491494612,0.00025370340306410486,25.0,60.0
22.828369,4.642999606299212e-05,33.63463446305675,0.00025370340306410486,25.0,60.0
24.229736,7.679237598425197e-05,38.08973120373978,0.00025370340306410486,25.0,60.0
25.631104,0.0001012828996062992,42.77114920140242,0.00025370340306410486,25.0,60.0
27.032471,0.0001595681220472441,48.29961044020258,0.00025370340306410486,25.0,60.0
28.433838,0.00016976266535433072,54.46152967147124,0.00025370340306410486,25.0,60.0
29.835205,0.00021354984251968504,59.83246851058304,0.00025370340306410486,25.0,60.0
31.236572,0.00027100421259842523,67.37087650954422,0.00025370340306410486,25.0,60.0
32.637939,0.00029208116141732284,74.58990780418128,0.00025370340306410486,25.0,60.0
34.039307,0.00033192397637795274,81.2804960394754,0.00025370340306410486,25.0,60.0
35.440674,0.0003732919881889764,89.44147773016492,0.00025370340306410486,25.0,60.0
36.842041,0.0004172606496062992,96.1957486040774,0.00025370340306410486,25.0,60.0
38.243408,0.0004397750590551181,105.66197636670563,0.00025370340306410486,25.0,60.0
39.644775,0.0004569897637795275,113.125100636281,0.00025370340306410486,25.0,60.0
41.046143,0.0005279199212598425,122.35878197636671,0.00025370340306410486,25.0,60.0
42.44751,0.0005269406692913385,130.4300376574471,0.00025370340306410486,25.0,60.0
43.848877,0.0005660607086614173,140.475507077003,0.00025370340306410486,25.0,60.0
45.250244,0.0006115950984251969,149.01651473834568,0.00025370340306410486,25.0,60.0
46.651611,0.000640289311023622,159.81505259057263,0.00025370340306410486,25.0,60.0
48.052979,0.0006744097244094488,168.17289702636023,0.00025370340306410486,25.0,60.0
49.454346,0.0007143323818897638,177.6603012595767,0.00025370340306410486,25.0,60.0
50.855713,0.0007483648425196849,185.63399298792365,0.00025370340306410486,25.0,60.0
52.25708,0.0007852809251968504,196.17179587066616,0.00025370340306410486,25.0,60.0
53.658447,0.0008171243700787401,204.73695883651473,0.00025370340306410486,25.0,60.0
55.059814,0.0008493652755905512,214.18494221529673,0.00025370340306410486,25.0,60.0
56.461182,0.0008604326181102363,222.48370860927156,0.00025370340306410486,25.0,60.0
57.862549,0.0009205091535433071,234.01904427996365,0.00025370340306410486,25.0,60.0
59.263916,0.0009535107874015748,242.42395273341126,0.00025370340306410486,25.0,60.0
60.665283,0.0009991145078740158,254.84148811842618,0.00025370340306410486,25.0,60.0
62.06665,0.0010422767322834645,265.14504609790936,0.00025370340306410486,25.0,60.0
63.468018,0.0010703611614173228,274.4547980781717,0.00025370340306410486,25.0,60.0
64.869385,0.0011242468700787401,286.886118685885,0.00025370340306410486,25.0,60.0
66.270752,0.0011484856496062992,295.3890663550189,0.00025370340306410486,25.0,60.0
67.672119,0.0011859028937007874,304.0577587326321,0.00025370340306410486,25.0,60.0
69.073486,0.001215021220472441,313.7508894948708,0.00025370340306410486,25.0,60.0
70.474854,0.0012630844291338583,325.52304895468126,0.00025370340306410486,25.0,60.0
71.876221,0.001303714566929134,338.19322165952474,0.00025370340306410486,25.0,60.0
73.277588,0.0013418820078740156,346.5238021036229,0.00025370340306410486,25.0,60.0
74.678955,0.0013705937007874014,354.15979742890534,0.00025370340306410486,25.0,60.0
76.080322,0.0014281731692913386,367.4561745227893,0.00025370340306410486,25.0,60.0
77.481689,0.00145472,376.6477340605116,0.00025370340306410486,25.0,60.0
78.883057,0.0014792718897637795,387.14842228282043,0.00025370340306410486,25.0,60.0
80.284424,0.001523795531496063,398.19901311517987,0.00025370340306410486,25.0,60.0
81.685791,0.0015481162401574803,407.55735618750816,0.00025370340306410486,25.0,60.0
83.087158,0.0016018476968503938,415.3370731073887,0.00025370340306410486,25.0,60.0
84.488525,0.0016333947834645671,427.0300480457084,0.00025370340306410486,25.0,60.0
85.889893,0.001672824566929134,437.87736657576943,0.00025370340306410486,25.0,60.0
87.29126,0.0016997885433070866,445.11902350344116,0.00025370340306410486,25.0,60.0
88.692627,0.0017683593700787402,455.97379561095966,0.00025370340306410486,25.0,60.0
90.093994,0.0017814526968503936,463.9922347747046,0.00025370340306410486,25.0,60.0
91.495361,0.0018200250393700787,475.19207895078563,0.00025370340306410486,25.0,60.0
92.896729,0.0018629976968503937,485.0280742760681,0.00025370340306410486,25.0,60.0
94.298096,0.0018886886220472441,492.2652382807428,0.00025370340306410486,25.0,60.0
95.699463,0.0019135100196850394,500.0338917023763,0.00025370340306410486,25.0,60.0
97.10083,0.001944977913385827,510.18137904168293,0.00025370340306410486,25.0,60.0
98.502197,0.0019800141732283466,519.0317880794702,0.00025370340306410486,25.0,60.0
99.903564,0.002009237401574803,526.6315024022854,0.00025370340306410486,25.0,60.0
101.30493,0.0020549458661417324,537.9970393455396,0.00025370340306410486,25.0,60.0
102.7063,0.002086098031496063,546.0544085183742,0.00025370340306410486,25.0,60.0
104.10767,0.002098084842519685,552.1728087261395,0.00025370340306410486,25.0,60.0
105.50903,0.0021426375984251967,561.09798727438,0.00025370340306410486,25.0,60.0
106.9104,0.0021387568897637795,564.906661472536,0.00025370340306410486,25.0,60.0
108.31177,0.0021778832677165354,573.2134527983378,0.00025370340306410486,25.0,60.0
109.71313,0.002211284842519685,581.689494870796,0.00025370340306410486,25.0,60.0
111.1145,0.002217538779527559,584.005298013245,0.00025370340306410486,25.0,60.0
112.51587,0.0022313124015748034,589.8666926373198,0.00025370340306410486,25.0,60.0
113.91724,0.0022758683070866143,595.484196857551,0.00025370340306410486,25.0,60.0
115.3186,0.0023051173228346455,602.557641864693,0.00025370340306410486,25.0,60.0
116.71997,0.002315205905511811,607.5073367095182,0.00025370340306410486,25.0,60.0
118.12134,0.002365371653543307,613.0226723802105,0.00025370340306410486,25.0,60.0
119.52271,0.0023843956692913386,618.4476042072458,0.00025370340306410486,25.0,60.0
120.92407,0.0024044370078740154,623.6335540838852,0.00025370340306410486,25.0,60.0
122.32544,0.002449175,627.974652642514,0.00025370340306410486,25.0,60.0
123.72681,0.002465207874015748,631.7931437475653,0.00025370340306410486,25.0,60.0
125.12817,0.002486538976377953,635.3384755226595,0.00025370340306410486,25.0,60.0
126.52954,0.002535899409448819,643.7530190884302,0.00025370340306410486,25.0,60.0
127.93091,0.002563149606299213,643.5805479807818,0.00025370340306410486,25.0,60.0
129.33228,0.0025821137795275593,651.1089988313207,0.00025370340306410486,25.0,60.0
130.73364,0.002603982283464567,651.9930658356058,0.00025370340306410486,25.0,60.0
132.13501,0.002654717125984252,658.6487988572912,0.00025370340306410486,25.0,60.0
133.53638,0.00267186968503937,661.4977015971953,0.00025370340306410486,25.0,60.0
134.93774,0.0027037194881889765,665.1900272691857,0.00025370340306410486,25.0,60.0
136.33911,0.0027629403543307086,668.7378522269836,0.00025370340306410486,25.0,60.0
137.74048,0.002808044094488189,671.094299441631,0.00025370340306410486,25.0,60.0
139.14185,0.0028450681102362204,674.1268146993897,0.00025370340306410486,25.0,60.0
140.54321,0.002866328346456693,677.1528892351643,0.00025370340306410486,25.0,60.0
141.94458,0.002926549409448819,681.0999610440203,0.00025370340306410486,25.0,60.0
143.34595,0.0030040907480314957,684.4738085962863,0.00025370340306410486,25.0,60.0
144.74731,0.003065248622047244,688.1681599792234,0.00025370340306410486,25.0,60.0
146.14868,0.003103294881889764,690.279548110635,0.00025370340306410486,25.0,60.0
147.55005,0.0031872145669291337,695.117413322945,0.00025370340306410486,25.0,60.0
148.95142,0.0032764588582677168,697.848435268147,0.00025370340306410486,25.0,60.0
150.35278,0.0033126726377952754,698.4128035320089,0.00025370340306410486,25.0,60.0
151.75415,0.0033781805118110234,700.4561485521361,0.00025370340306410486,25.0,60.0
153.15552,0.0034658679133858267,704.676016101805,0.00025370340306410486,25.0,60.0
154.55688,0.003571878346456693,709.0851837423711,0.00025370340306410486,25.0,60.0
155.95825,0.00367713937007874,710.0302298402805,0.00025370340306410486,25.0,60.0
157.35962,0.0037969978346456693,713.0393195688871,0.00025370340306410486,25.0,60.0
158.76099,0.003888173818897638,714.8241007661343,0.00025370340306410486,25.0,60.0
160.16235,0.003986942519685039,717.6536034281263,0.00025370340306410486,25.0,60.0
161.56372,0.004130153149606299,719.3793533307363,0.00025370340306410486,25.0,60.0
162.96509,0.004261347834645669,722.6096351123231,0.00025370340306410486,25.0,60.0
164.36646,0.004401718700787401,724.1427087391248,0.00025370340306410486,25.0,60.0
165.76782,0.004548254133858268,725.8114790286976,0.00025370340306410486,25.0,60.0
167.16919,0.004736802362204725,729.5362420464875,0.00025370340306410486,25.0,60.0
168.57056,0.0048938511811023626,730.3389689650695,0.00025370340306410486,25.0,60.0
169.97192,0.005054338582677165,733.9686274509804,0.00025370340306410486,25.0,60.0
171.37329,0.005251159251968504,734.5261654330607,0.00025370340306410486,25.0,60.0
172.77466,0.005398159842519685,734.8173743669654,0.00025370340306410486,25.0,60.0
174.17603,0.0056176944881889766,738.0004934424102,0.00025370340306410486,25.0,60.0
175.57739,0.005857198818897638,739.8393715101935,0.00025370340306410486,25.0,60.0
176.97876,0.006064744685039369,740.9948578106739,0.00025370340306410486,25.0,60.0
178.38013,0.006226731102362204,742.9182443838463,0.00025370340306410486,25.0,60.0
179.78149,0.006429605314960629,742.1041942604858,0.00025370340306410486,25.0,60.0
181.18286,0.006653707283464567,745.8068302817817,0.00025370340306410486,25.0,60.0
182.58423,0.0069001,746.7598233995586,0.00025370340306410486,25.0,60.0
183.9856,0.007135355118110236,748.9725230489547,0.00025370340306410486,25.0,60.0
185.38696,0.007356446653543307,748.1164264381249,0.00025370340306410486,25.0,60.0
186.78833,0.00762267657480315,750.4502272432152,0.00025370340306410486,25.0,60.0
188.1897,0.007852582677165355,751.6309050772627,0.00025370340306410486,25.0,60.0
189.59106,0.008083607086614172,752.7839241656928,0.00025370340306410486,25.0,60.0
190.99243,0.008350384842519685,755.8748474224127,0.00025370340306410486,25.0,60.0
192.3938,0.008636037598425196,757.0415011037528,0.00025370340306410486,25.0,60.0
193.79517,0.00887883779527559,760.6564601999742,0.00025370340306410486,25.0,60.0
195.19653,0.009158352755905512,757.1790157122452,0.00025370340306410486,25.0,60.0
196.5979,0.00938602283464567,758.7198805349955,0.00025370340306410486,25.0,60.0
197.99927,0.009678921653543306,759.9618750811584,0.00025370340306410486,25.0,60.0
199.40063,0.0099160781496063,760.5093624204649,0.00025370340306410486,25.0,60.0
200.802,0.010246908070866142,763.8012206206986,0.00025370340306410486,25.0,60.0
202.20337,0.01056486968503937,763.4127515907024,0.00025370340306410486,25.0,60.0
203.60474,0.01086088287401575,763.7071808855993,0.00025370340306410486,25.0,60.0
205.0061,0.011157569291338583,766.1179846773147,0.00025370340306410486,25.0,60.0
206.40747,0.011462402165354331,767.258382028308,0.00025370340306410486,25.0,60.0
207.80884,0.01179658996062992,767.6431891962084,0.00025370340306410486,25.0,60.0
209.21021,0.012057793700787403,767.8304895468121,0.00025370340306410486,25.0,60.0
210.61157,0.01238365098425197,770.8602259446825,0.00025370340306410486,25.0,60.0
212.01294,0.012665699606299213,767.7429165043502,0.00025370340306410486,25.0,60.0
213.41431,0.012935551377952754,771.1449162446437,0.00025370340306410486,25.0,60.0
214.81567,0.013291032086614172,773.5275418776782,0.00025370340306410486,25.0,60.0
216.21704,0.013595740354330709,771.4630827165304,0.00025370340306410486,25.0,60.0
217.61841,0.0138922,775.4272172445137,0.00025370340306410486,25.0,60.0
219.01978,0.01420519035433071,774.5984417608104,0.00025370340306410486,25.0,60.0
220.42114,0.014512101574803149,776.0687443189197,0.00025370340306410486,25.0,60.0
221.82251,0.014817396456692914,775.7514608492404,0.00025370340306410486,25.0,60.0
223.22388,0.01507138503937008,775.9077522399689,0.00025370340306410486,25.0,60.0
224.62524,0.015356636614173228,777.9869887027659,0.00025370340306410486,25.0,60.0
226.02661,0.015631447244094487,779.596156343332,0.00025370340306410486,25.0,60.0
227.42798,0.015945113582677164,781.0453967017271,0.00025370340306410486,25.0,60.0
228.82935,0.016288726181102362,781.0982729515648,0.00025370340306410486,25.0,60.0
230.23071,0.016623365748031495,781.2444877288664,0.00025370340306410486,25.0,60.0
231.63208,0.01690619901574803,781.2272951564731,0.00025370340306410486,25.0,60.0
233.03345,0.017244616732283464,783.6512660693417,0.00025370340306410486,25.0,60.0
234.43481,0.017587249409448818,783.0545643422932,0.00025370340306410486,25.0,60.0
235.83618,0.017870898031496062,782.6061031034931,0.00025370340306410486,25.0,60.0
237.23755,0.01817570748031496,784.4418646928971,0.00025370340306410486,25.0,60.0
238.63892,0.018519541535433073,785.4931307622387,0.00025370340306410486,25.0,60.0
240.04028,0.018836747047244095,787.6610570055838,0.00025370340306410486,25.0,60.0
241.44165,0.01921090255905512,786.7358524866901,0.00025370340306410486,25.0,60.0
242.84302,0.019552696456692914,787.2875990131151,0.00025370340306410486,25.0,60.0
244.24438,0.019872970472440944,786.2227243215168,0.00025370340306410486,25.0,60.0
245.64575,0.020176501968503936,789.3282171146606,0.00025370340306410486,25.0,60.0
247.04712,0.020469830708661416,789.9431242695754,0.00025370340306410486,25.0,60.0
248.44849,0.02083163188976378,790.8483573561875,0.00025370340306410486,25.0,60.0
249.84985,0.021188179133858266,792.186027788599,0.00025370340306410486,25.0,60.0
251.25122,0.02149863188976378,790.5022464614985,0.00025370340306410486,25.0,60.0
252.65259,0.021787397637795275,792.3081937410727,0.00025370340306410486,25.0,60.0
254.05396,0.022097161417322837,793.6237891182964,0.00025370340306410486,25.0,60.0
255.45532,0.022488488188976377,794.3271263472276,0.00025370340306410486,25.0,60.0
256.85669,0.02283842913385827,794.7375665497988,0.00025370340306410486,25.0,60.0
258.25806,0.02317681692913386,795.2513180106481,0.00025370340306410486,25.0,60.0
259.65942,0.023490787401574804,796.6050123360603,0.00025370340306410486,25.0,60.0
261.06079,0.023828751968503935,796.8776522529541,0.00025370340306410486,25.0,60.0
262.46216,0.024092125984251967,797.802233476172,0.00025370340306410486,25.0,60.0
263.86353,0.02441478937007874,796.346890014284,0.00025370340306410486,25.0,60.0
265.26489,0.024828852362204723,798.7447604207246,0.00025370340306410486,25.0,60.0
266.66626,0.02520689566929134,798.8459420854434,0.00025370340306410486,25.0,60.0
268.06763,0.025511994094488188,799.7455914816258,0.00025370340306410486,25.0,60.0
269.46899,0.025794047244094488,796.3024022854175,0.00025370340306410486,25.0,60.0
270.87036,0.026071212598425195,800.7884690299962,0.00025370340306410486,25.0,60.0
272.27173,0.026429338582677164,802.4841189455915,0.00025370340306410486,25.0,60.0
273.6731,0.0267494468503937,802.180080509025,0.00025370340306410486,25.0,60.0
275.07446,0.027108838582677163,803.063186599143,0.00025370340306410486,25.0,60.0
276.47583,0.02744740157480315,802.4532917802883,0.00025370340306410486,25.0,60.0
277.8772,0.02782126377952756,805.4083625503182,0.00025370340306410486,25.0,60.0
279.27856,0.028196059055118114,805.2026749772757,0.00025370340306410486,25.0,60.0
280.67993,0.028596114173228347,804.5489676665369,0.00025370340306410486,25.0,60.0
282.0813,0.028901720472440946,805.6042591871186,0.00025370340306410486,25.0,60.0
283.48267,0.029228671259842517,806.7325022724322,0.00025370340306410486,25.0,60.0
284.88403,0.029577627952755908,807.5485261654331,0.00025370340306410486,25.0,60.0
286.2854,0.029898604330708664,807.6290351902351,0.00025370340306410486,25.0,60.0
287.68677,0.03025060433070866,808.801895857681,0.00025370340306410486,25.0,60.0
289.08813,0.03057919881889764,807.1529931177769,0.00025370340306410486,25.0,60.0
290.4895,0.030911015748031494,807.2821451759512,0.00025370340306410486,25.0,60.0
291.89087,0.03122922244094488,808.9071029736399,0.00025370340306410486,25.0,60.0
293.29224,0.03152031102362205,808.934242306194,0.00025370340306410486,25.0,60.0
294.6936,0.031859718503937005,810.5271523178808,0.00025370340306410486,25.0,60.0
296.09497,0.03214826771653543,809.4341254382548,0.00025370340306410486,25.0,60.0
297.49634,0.03242712007874016,810.9386573172316,0.00025370340306410486,25.0,60.0
298.89771,0.03278295669291338,812.1280093494352,0.00025370340306410486,25.0,60.0
300.29907,0.033086232283464564,812.0168030125958,0.00025370340306410486,25.0,60.0
301.70044,0.03341148622047244,812.6276847162707,0.00025370340306410486,25.0,60.0
303.10181,0.033691299212598426,814.2277885988833,0.00025370340306410486,25.0,60.0
304.50317,0.03401820669291339,815.7339566290093,0.00025370340306410486,25.0,60.0
305.90454,0.034358742125984255,815.6111414102064,0.00025370340306410486,25.0,60.0
307.30591,0.034714220472440944,815.663835865472,0.00025370340306410486,25.0,60.0
308.70728,0.03512350590551181,816.8507726269315,0.00025370340306410486,25.0,60.0
310.10864,0.03543135826771653,815.270744059213,0.00025370340306410486,25.0,60.0
311.51001,0.03571224409448819,815.3197506817297,0.00025370340306410486,25.0,60.0
312.91138,0.03603971653543307,818.5251785482405,0.00025370340306410486,25.0,60.0
314.31274,0.036414498031496066,817.6104402025711,0.00025370340306410486,25.0,60.0
315.71411,0.03673855708661417,819.7485261654331,0.00025370340306410486,25.0,60.0
317.11548,0.037089679133858265,819.0011686793923,0.00025370340306410486,25.0,60.0
318.51685,0.03747757874015748,820.8565900532399,0.00025370340306410486,25.0,60.0
319.91821,0.03781575590551181,820.8051681599792,0.00025370340306410486,25.0,60.0
321.31958,0.03813462992125984,821.6264381249189,0.00025370340306410486,25.0,60.0
322.72095,0.03840617125984252,820.6106999091028,0.00025370340306410486,25.0,60.0
324.12231,0.03877266535433071,822.703441111544,0.00025370340306410486,25.0,60.0
325.52368,0.039079840551181105,820.7046617322427,0.00025370340306410486,25.0,60.0
326.92505,0.03944462401574803,825.0328009349435,0.00025370340306410486,25.0,60.0
328.32642,0.03983843307086614,823.4369042981431,0.00025370340306410486,25.0,60.0
329.72778,0.040133397637795276,823.2869497467863,0.00025370340306410486,25.0,60.0
331.12915,0.040424527559055116,824.03030775224,0.00025370340306410486,25.0,60.0
332.53052,0.04070123031496063,824.5274120244125,0.00025370340306410486,25.0,60.0
333.93188,0.0409976968503937,824.0342293208674,0.00025370340306410486,25.0,60.0
335.33325,0.04132426968503937,826.5108946890015,0.00025370340306410486,25.0,60.0
336.73462,0.041690372047244094,827.5352811323205,0.00025370340306410486,25.0,60.0
338.13599,0.042027537401574805,826.7372549019608,0.00025370340306410486,25.0,60.0
339.53735,0.04238701968503937,828.6061810154525,0.00025370340306410486,25.0,60.0
340.93872,0.04275866141732283,827.163095701857,0.00025370340306410486,25.0,60.0
342.34009,0.043090476377952755,828.2638618361252,0.00025370340306410486,25.0,60.0
343.74146,0.04344228543307087,830.3848071679002,0.00025370340306410486,25.0,60.0
345.14282,0.04378723228346457,830.4548759901312,0.00025370340306410486,25.0,60.0
346.54419,0.044105242125984254,830.8035320088301,0.00025370340306410486,25.0,60.0
347.94556,0.04442875590551181,829.3549409167641,0.00025370340306410486,25.0,60.0
349.34692,0.044777379921259845,831.7154395533048,0.00025370340306410486,25.0,60.0
350.74829,0.045093478346456696,828.6420724581224,0.00025370340306410486,25.0,60.0
352.14966,0.04544033661417323,832.6202311388131,0.00025370340306410486,25.0,60.0
353.55103,0.04578645275590552,833.3202700947929,0.00025370340306410486,25.0,60.0
354.95239,0.046091708661417326,831.4645890144137,0.00025370340306410486,25.0,60.0
356.35376,0.04641513779527559,833.0166991299832,0.00025370340306410486,25.0,60.0
357.75513,0.046777309055118114,835.4934683807297,0.00025370340306410486,25.0,60.0
359.15649,0.04710561811023622,833.8241527074407,0.00025370340306410486,25.0,60.0
360.55786,0.047461092519685034,834.2587196467991,0.00025370340306410486,25.0,60.0
361.95923,0.04780166141732284,834.4655499285807,0.00025370340306410486,25.0,60.0
363.3606,0.04814340748031496,836.3356187508117,0.00025370340306410486,25.0,60.0
364.76196,0.04843899606299213,836.65404492923,0.00025370340306410486,25.0,60.0
366.16333,0.04874238976377953,836.2953642384106,0.00025370340306410486,25.0,60.0
367.5647,0.049075377952755905,836.3950396052461,0.00025370340306410486,25.0,60.0
368.96606,0.0494237657480315,837.7168419685756,0.00025370340306410486,25.0,60.0
370.36743,0.049781992125984255,838.4037657447086,0.00025370340306410486,25.0,60.0
371.7688,0.050142677165354324,839.051629658486,0.00025370340306410486,25.0,60.0
373.17017,0.050484541338582684,838.686612128295,0.00025370340306410486,25.0,60.0
374.57153,0.050836208661417324,839.4495520062329,0.00025370340306410486,25.0,60.0
375.9729,0.051138803149606296,838.6294766913388,0.00025370340306410486,25.0,60.0
377.37427,0.05142667125984252,839.2891572523049,0.00025370340306410486,25.0,60.0
378.77563,0.05175910039370078,839.9126087521103,0.00025370340306410486,25.0,60.0
380.177,0.052156651574803155,840.3542137384756,0.00025370340306410486,25.0,60.0
381.57837,0.05250098031496062,842.2486949746786,0.00025370340306410486,25.0,60.0
382.97974,0.05280419488188977,842.0076353720297,0.00025370340306410486,25.0,60.0
384.3811,0.053120604330708664,842.3013894299443,0.00025370340306410486,25.0,60.0
385.78247,0.053421688976377946,839.9772756784834,0.00025370340306410486,25.0,60.0
387.18384,0.053748429133858265,844.3953252824309,0.00025370340306410486,25.0,60.0
388.58521,0.0540884468503937,842.4987663939748,0.00025370340306410486,25.0,60.0
389.98657,0.054393826771653546,843.6021295935593,0.00025370340306410486,25.0,60.0
391.38794,0.054694472440944886,844.3435398000261,0.00025370340306410486,25.0,60.0
392.78931,0.05506249606299213,846.1721854304636,0.00025370340306410486,25.0,60.0
394.19067,0.05546109448818898,846.1487858719647,0.00025370340306410486,25.0,60.0
395.59204,0.055798084645669294,846.3832748993638,0.00025370340306410486,25.0,60.0
396.99341,0.05613021653543307,845.6731853006104,0.00025370340306410486,25.0,60.0
398.39478,0.056491663385826764,848.4322555512271,0.00025370340306410486,25.0,60.0
399.79614,0.05683662992125984,846.9212569796131,0.00025370340306410486,25.0,60.0
401.19751,0.05712557283464567,847.239605246072,0.00025370340306410486,25.0,60.0
402.59888,0.05744615354330709,848.873445007142,0.00025370340306410486,25.0,60.0
404.00024,0.05781158858267716,847.9851188157384,0.00025370340306410486,25.0,60.0
405.40161,0.058089543307086614,849.3553045059083,0.00025370340306410486,25.0,60.0
406.80298,0.05842805708661418,849.2110634982471,0.00025370340306410486,25.0,60.0
408.20435,0.05875503149606299,849.6855992728217,0.00025370340306410486,25.0,60.0
409.60571,0.059153872047244094,852.2993896896508,0.00025370340306410486,25.0,60.0
411.00708,0.059480872047244095,849.8881703674848,0.00025370340306410486,25.0,60.0
412.40845,0.059761864173228346,849.9032593169718,0.00025370340306410486,25.0,60.0
413.80981,0.06012546456692913,850.796000519413,0.00025370340306410486,25.0,60.0
415.21118,0.0604455157480315,851.9318270354499,0.00025370340306410486,25.0,60.0
416.61255,0.060736299212598426,852.3593818984548,0.00025370340306410486,25.0,60.0
418.01392,0.06106683661417323,852.7832229580574,0.00025370340306410486,25.0,60.0
419.41528,0.06142351377952755,854.1243734579924,0.00025370340306410486,25.0,60.0
420.81665,0.06180279527559055,854.6443578756007,0.00025370340306410486,25.0,60.0
422.21802,0.06215057874015748,854.1494870796,0.00025370340306410486,25.0,60.0
423.61938,0.0625070688976378,855.3214647448384,0.00025370340306410486,25.0,60.0
425.02075,0.06285083267716535,856.0119465004545,0.00025370340306410486,25.0,60.0
426.42212,0.06316907283464566,854.3208154785093,0.00025370340306410486,25.0,60.0
427.82349,0.06350574606299213,856.7140890793404,0.00025370340306410486,25.0,60.0
429.22485,0.06385717716535433,856.9384235813532,0.00025370340306410486,25.0,60.0
430.62622,0.06417433858267717,856.1927022464615,0.00025370340306410486,25.0,60.0
432.02759,0.06451034842519685,857.4545903129465,0.00025370340306410486,25.0,60.0
433.42896,0.06487388976377953,857.8265160368784,0.00025370340306410486,25.0,60.0
434.83032,0.06518555118110236,856.3417218543048,0.00025370340306410486,25.0,60.0
436.23169,0.06553193897637795,859.518036618621,0.00025370340306410486,25.0,60.0
437.63306,0.06585587598425197,859.5574860407739,0.00025370340306410486,25.0,60.0
439.03442,0.06618090354330708,859.4844305934296,0.00025370340306410486,25.0,60.0
440.43579,0.06644868307086614,858.1216725100637,0.00025370340306410486,25.0,60.0
441.83716,0.06670667322834646,856.8526944552656,0.00025370340306410486,25.0,60.0
443.23853,0.0670573779527559,861.4529022204908,0.00025370340306410486,25.0,60.0
444.63989,0.06745007677165354,861.5501623165824,0.00025370340306410486,25.0,60.0
446.04126,0.06784999606299212,861.6528243085313,0.00025370340306410486,25.0,60.0
447.44263,0.06814663582677165,860.6122841189457,0.00025370340306410486,25.0,60.0
448.84399,0.06851976968503937,863.4525646019997,0.00025370340306410486,25.0,60.0
450.24536,0.06880981889763779,859.7601869887028,0.00025370340306410486,25.0,60.0
451.64673,0.06913343897637796,861.8885599272822,0.00025370340306410486,25.0,60.0
453.0481,0.06949255118110235,863.1579794831841,0.00025370340306410486,25.0,60.0
454.44946,0.06986611811023623,862.6796000519414,0.00025370340306410486,25.0,60.0
455.85083,0.07018182283464568,862.8756525126607,0.00025370340306410486,25.0,60.0
457.2522,0.07053540944881889,863.8717309440333,0.00025370340306410486,25.0,60.0
458.65356,0.07087443307086615,865.1690170107778,0.00025370340306410486,25.0,60.0
460.05493,0.07122319094488189,863.8943773535905,0.00025370340306410486,25.0,60.0
461.4563,0.07153670275590551,863.9434618880666,0.00025370340306410486,25.0,60.0
462.85767,0.07188849409448818,865.7565251266069,0.00025370340306410486,25.0,60.0
464.25903,0.07224451968503938,866.7062459420855,0.00025370340306410486,25.0,60.0
465.6604,0.07258286417322835,866.6985845994028,0.00025370340306410486,25.0,60.0
467.06177,0.0729156062992126,866.0543306064149,0.00025370340306410486,25.0,60.0
468.46313,0.07324441732283464,865.3687832748994,0.00025370340306410486,25.0,60.0
469.8645,0.07359954527559055,867.3331515387612,0.00025370340306410486,25.0,60.0
471.26587,0.07396298622047244,868.6080768731334,0.00025370340306410486,25.0,60.0
472.66724,0.07432047440944882,868.7543695623946,0.00025370340306410486,25.0,60.0
474.0686,0.0746710905511811,868.1848591092066,0.00025370340306410486,25.0,60.0
475.46997,0.07502596259842519,868.9854824048825,0.00025370340306410486,25.0,60.0
476.87134,0.0753463779527559,867.996935462927,0.00025370340306410486,25.0,60.0
478.27271,0.07565304921259842,870.6120503830672,0.00025370340306410486,25.0,60.0
479.67407,0.07594418503937007,870.1929619529931,0.00025370340306410486,25.0,60.0
481.07544,0.0762453405511811,870.5805479807817,0.00025370340306410486,25.0,60.0
482.47681,0.07661581102362204,872.0165433060642,0.00025370340306410486,25.0,60.0
483.87817,0.07696619291338581,871.4138942994416,0.00025370340306410486,25.0,60.0
485.27954,0.07735051968503937,871.8800415530452,0.00025370340306410486,25.0,60.0
486.68091,0.07765783661417323,872.5235423970913,0.00025370340306410486,25.0,60.0
488.08228,0.07803989763779527,871.8438384625374,0.00025370340306410486,25.0,60.0
489.48364,0.07838525196850393,873.7039345539541,0.00025370340306410486,25.0,60.0
490.88501,0.07881913976377952,872.1850668744319,0.00025370340306410486,25.0,60.0
492.28638,0.07921034251968505,874.2574730554473,0.00025370340306410486,25.0,60.0
493.68774,0.0795709094488189,873.6171406310868,0.00025370340306410486,25.0,60.0
495.08911,0.07989285826771653,874.4382288014543,0.00025370340306410486,25.0,60.0
496.49048,0.08019271653543307,872.3855083755357,0.00025370340306410486,25.0,60.0
497.89185,0.08055154724409448,876.0448513180107,0.00025370340306410486,25.0,60.0
499.29321,0.08090041141732283,872.8865342163356,0.00025370340306410486,25.0,60.0
500.69458,0.08120261614173228,875.9740812881445,0.00025370340306410486,25.0,60.0
502.09595,0.08157039960629921,876.9313076223867,0.00025370340306410486,25.0,60.0
503.49731,0.08196117913385827,876.1106609531231,0.00025370340306410486,25.0,60.0
504.89868,0.08228034645669291,876.2208544344891,0.00025370340306410486,25.0,60.0
506.30005,0.08260896259842519,876.5411245292819,0.00025370340306410486,25.0,60.0
507.70142,0.08291503543307087,877.1546292689262,0.00025370340306410486,25.0,60.0
509.10278,0.0832494783464567,877.4224386443319,0.00025370340306410486,25.0,60.0
510.50415,0.08352926377952756,877.7713543695625,0.00025370340306410486,25.0,60.0
511.90552,0.08388854527559056,878.9321906245942,0.00025370340306410486,25.0,60.0
513.30688,0.08422088188976379,876.9379820802493,0.00025370340306410486,25.0,60.0
514.70825,0.08460722637795275,879.8346967926244,0.00025370340306410486,25.0,60.0
516.10962,0.08501984842519685,878.6804570834958,0.00025370340306410486,25.0,60.0
517.51099,0.08536307874015749,880.5555901830932,0.00025370340306410486,25.0,60.0
518.91235,0.08571122047244094,879.6622776262824,0.00025370340306410486,25.0,60.0
520.31372,0.08604798818897638,879.7028178158681,0.00025370340306410486,25.0,60.0
521.71509,0.0863885374015748,880.0933904687703,0.00025370340306410486,25.0,60.0
523.11646,0.08672648228346456,880.0131151798467,0.00025370340306410486,25.0,60.0
524.51782,0.08706666338582678,880.4490066225167,0.00025370340306410486,25.0,60.0
525.91919,0.0874212342519685,881.8757563952735,0.00025370340306410486,25.0,60.0
527.32056,0.08780173031496064,882.2995455135698,0.00025370340306410486,25.0,60.0
528.72192,0.08816448622047243,881.1213608622257,0.00025370340306410486,25.0,60.0
530.12329,0.08852873228346456,882.6905077262693,0.00025370340306410486,25.0,60.0
531.52466,0.08890535039370077,883.3794052720426,0.00025370340306410486,25.0,60.0
532.92603,0.08923183070866142,880.7062459420855,0.00025370340306410486,25.0,60.0
534.32739,0.08960799803149606,884.7746266718609,0.00025370340306410486,25.0,60.0
535.72876,0.08997586220472441,882.255161667316,0.00025370340306410486,25.0,60.0
537.13013,0.09028283267716536,881.8164134527983,0.00025370340306410486,25.0,60.0
538.53149,0.09058763188976378,884.0430074016361,0.00025370340306410486,25.0,60.0
539.93286,0.09093760433070866,883.4237112063369,0.00025370340306410486,25.0,60.0
541.33423,0.09126832086614173,884.4631086871835,0.00025370340306410486,25.0,60.0
542.7356,0.09161673818897638,884.7086352421763,0.00025370340306410486,25.0,60.0
544.13696,0.09205112598425197,886.2650824568238,0.00025370340306410486,25.0,60.0
545.53833,0.09243940551181103,885.1603947539281,0.00025370340306410486,25.0,60.0
546.9397,0.09277792125984251,884.6802752889236,0.00025370340306410486,25.0,60.0
548.34106,0.09317747047244095,887.178678093754,0.00025370340306410486,25.0,60.0
549.74243,0.09355907677165354,888.0745357745748,0.00025370340306410486,25.0,60.0
551.1438,0.09392641929133859,886.0603557979483,0.00025370340306410486,25.0,60.0
552.54517,0.09423494881889763,886.0725360342813,0.00025370340306410486,25.0,60.0
553.94653,0.09457092913385827,887.23383976107,0.00025370340306410486,25.0,60.0
555.3479,0.09491641338582676,886.8576808206726,0.00025370340306410486,25.0,60.0
556.74927,0.09524660826771653,888.7643163225555,0.00025370340306410486,25.0,60.0
558.15063,0.09555595472440945,887.9079080638878,0.00025370340306410486,25.0,60.0
559.552,0.09588042519685039,889.6557330216856,0.00025370340306410486,25.0,60.0
560.95337,0.0962656968503937,889.1457732761979,0.00025370340306410486,25.0,60.0
562.35474,0.0966367933070866,890.7154135826516,0.00025370340306410486,25.0,60.0
563.7561,0.09707166141732283,891.065290222049,0.00025370340306410486,25.0,60.0
565.15747,0.09745328346456693,888.2948707960005,0.00025370340306410486,25.0,60.0
566.55884,0.09779565748031496,890.3930138942994,0.00025370340306410486,25.0,60.0
567.96021,0.09815345078740156,889.9872224386443,0.00025370340306410486,25.0,60.0
569.36157,0.09849490354330707,889.2124659135178,0.00025370340306410486,25.0,60.0
570.76294,0.09883178740157479,890.7670951824439,0.00025370340306410486,25.0,60.0
572.16431,0.0992314901574803,891.2637319828594,0.00025370340306410486,25.0,60.0
573.56567,0.09961482480314961,892.5699519542917,0.00025370340306410486,25.0,60.0
574.96704,0.09998993700787402,891.4437605505778,0.00025370340306410486,25.0,60.0
576.36841,0.10038853543307087,894.1369951954292,0.00025370340306410486,25.0,60.0
577.76978,0.1008113188976378,893.472328269056,0.00025370340306410486,25.0,60.0
579.17114,0.10114907086614172,890.0911829632515,0.00025370340306410486,25.0,60.0
580.57251,0.10137874803149606,890.8680431112844,0.00025370340306410486,25.0,60.0
581.97388,0.1016578562992126,891.4839371510194,0.00025370340306410486,25.0,60.0
583.37524,0.10197035826771654,892.737280872614,0.00025370340306410486,25.0,60.0
584.77661,0.1023766220472441,894.0740423321646,0.00025370340306410486,25.0,60.0
586.17798,0.10270797834645669,893.9621867289962,0.00025370340306410486,25.0,60.0
587.57935,0.10304817125984252,894.4907414621479,0.00025370340306410486,25.0,60.0
588.98071,0.10346155511811024,896.0256330346708,0.00025370340306410486,25.0,60.0
590.38208,0.10388725787401575,895.5673548889755,0.00025370340306410486,25.0,60.0
591.78345,0.10427316338582676,894.529593559278,0.00025370340306410486,25.0,60.0
593.18481,0.10463513188976378,895.5439553304766,0.00025370340306410486,25.0,60.0
594.58618,0.10500423622047243,894.1696403064537,0.00025370340306410486,25.0,60.0
595.98755,0.10536160433070867,896.3442410076615,0.00025370340306410486,25.0,60.0
597.38892,0.10576159055118109,894.8693935852486,0.00025370340306410486,25.0,60.0
598.79028,0.10613377952755905,897.6521750422024,0.00025370340306410486,25.0,60.0
600.19165,0.10651938976377952,895.4320997273082,0.00025370340306410486,25.0,60.0
601.59302,0.1069565216535433,898.2871575120114,0.00025370340306410486,25.0,60.0
602.99438,0.1072799940944882,897.0516036878329,0.00025370340306410486,25.0,60.0
604.39575,0.10760293897637795,896.5726269315674,0.00025370340306410486,25.0,60.0
605.79712,0.10798850393700787,898.6318919620829,0.00025370340306410486,25.0,60.0
607.19849,0.10833468110236219,897.5920010388261,0.00025370340306410486,25.0,60.0
608.59985,0.10872562992125984,896.8201012855474,0.00025370340306410486,25.0,60.0
610.00122,0.10908457283464566,899.3679002726918,0.00025370340306410486,25.0,60.0
611.40259,0.10948495669291339,898.6325931697182,0.00025370340306410486,25.0,60.0
612.80396,0.10987138976377953,899.6155044799377,0.00025370340306410486,25.0,60.0
614.20532,0.11025141535433071,900.1472795740814,0.00025370340306410486,25.0,60.0
615.60669,0.11060416141732284,899.9567328918322,0.00025370340306410486,25.0,60.0
617.00806,0.11102379921259843,900.6829242955461,0.00025370340306410486,25.0,60.0
618.40942,0.11141255708661417,899.3300610310349,0.00025370340306410486,25.0,60.0
619.81079,0.1117899192913386,900.2279184521491,0.00025370340306410486,25.0,60.0
621.21216,0.11218175000000001,901.0150370081808,0.00025370340306410486,25.0,60.0
622.61353,0.11252755118110234,899.1187118556032,0.00025370340306410486,25.0,60.0
624.01489,0.11289057480314961,900.452434748734,0.00025370340306410486,25.0,60.0
625.41626,0.11327603346456694,900.733593039865,0.00025370340306410486,25.0,60.0
626.81763,0.11366847440944881,901.8338397610701,0.00025370340306410486,25.0,60.0
628.21899,0.11412179921259843,901.4857031554344,0.00025370340306410486,25.0,60.0
629.62036,0.11452552559055118,901.0406440721985,0.00025370340306410486,25.0,60.0
631.02173,0.11488581692913385,902.5880534995456,0.00025370340306410486,25.0,60.0
632.4231,0.11527398622047244,903.5081937410725,0.00025370340306410486,25.0,60.0
633.82446,0.11565217125984252,903.0893909881834,0.00025370340306410486,25.0,60.0
635.22583,0.11603060236220472,902.8878846903001,0.00025370340306410486,25.0,60.0
636.6272,0.1164250964566929,902.2859888326192,0.00025370340306410486,25.0,60.0
638.02856,0.11674813385826771,903.6741721854305,0.00025370340306410486,25.0,60.0
639.42993,0.11710132677165354,904.1781067393846,0.00025370340306410486,25.0,60.0
640.8313,0.11750575787401574,904.4274250097391,0.00025370340306410486,25.0,60.0
642.23267,0.11786446653543307,903.3416699129984,0.00025370340306410486,25.0,60.0
643.63403,0.11828735433070867,905.3147123750163,0.00025370340306410486,25.0,60.0
645.0354,0.11870255708661416,904.7310738865083,0.00025370340306410486,25.0,60.0
646.43677,0.11912154921259842,904.699104012466,0.00025370340306410486,25.0,60.0
647.83813,0.11950560039370078,904.475860277886,0.00025370340306410486,25.0,60.0
649.2395,0.11987907874015746,905.8608752110116,0.00025370340306410486,25.0,60.0
650.64087,0.12025828346456692,905.3043760550578,0.00025370340306410486,25.0,60.0
652.04224,0.12065266141732284,906.5701856901702,0.00025370340306410486,25.0,60.0
653.4436,0.12107059645669292,906.9237501623167,0.00025370340306410486,25.0,60.0
654.84497,0.12148920275590552,906.2163874821453,0.00025370340306410486,25.0,60.0
656.24634,0.12193813779527558,907.7777950915466,0.00025370340306410486,25.0,60.0
657.64771,0.12229157677165355,905.6041033631997,0.00025370340306410486,25.0,60.0
659.04907,0.12264435826771654,904.656122581483,0.00025370340306410486,25.0,60.0
660.45044,0.1230430531496063,906.3936631606285,0.00025370340306410486,25.0,60.0
661.85181,0.12339249212598424,907.5769380599922,0.00025370340306410486,25.0,60.0
663.25317,0.12378745472440944,907.0354499415661,0.00025370340306410486,25.0,60.0
664.65454,0.12411539763779528,906.2309050772628,0.00025370340306410486,25.0,60.0
666.05591,0.12451581692913385,906.180573951435,0.00025370340306410486,25.0,60.0
667.45728,0.12489933858267717,908.5057005583691,0.00025370340306410486,25.0,60.0
668.85864,0.12531787401574804,908.89798727438,0.00025370340306410486,25.0,60.0
670.26001,0.12569807677165354,908.377223737177,0.00025370340306410486,25.0,60.0
671.66138,0.12614372637795274,908.2080768731333,0.00025370340306410486,25.0,60.0
673.06274,0.12656439763779526,908.2333722893131,0.00025370340306410486,25.0,60.0
674.46411,0.12697187992125986,909.1869887027659,0.00025370340306410486,25.0,60.0
675.86548,0.1273993307086614,908.1976626412155,0.00025370340306410486,25.0,60.0
677.26685,0.12774932086614174,907.9578236592652,0.00025370340306410486,25.0,60.0
678.66821,0.12811722637795275,910.2079210492144,0.00025370340306410486,25.0,60.0
680.06958,0.12851914763779526,909.3642643812492,0.00025370340306410486,25.0,60.0
681.47095,0.1289215374015748,909.4128814439684,0.00025370340306410486,25.0,60.0
682.87231,0.12930262007874016,910.3357486040775,0.00025370340306410486,25.0,60.0
684.27368,0.12968383267716535,908.9099597454876,0.00025370340306410486,25.0,60.0
685.67505,0.1301062618110236,911.6607972990522,0.00025370340306410486,25.0,60.0
687.07642,0.13053617913385826,910.0199194909752,0.00025370340306410486,25.0,60.0
688.47778,0.1309370433070866,910.0007271782886,0.00025370340306410486,25.0,60.0
689.87915,0.131330281496063,910.873938449552,0.00025370340306410486,25.0,60.0
691.28052,0.1317515492125984,911.1905726529022,0.00025370340306410486,25.0,60.0
692.68188,0.1321520157480315,910.6596286196599,0.00025370340306410486,25.0,60.0
694.08325,0.13260143307086614,911.417945721335,0.00025370340306410486,25.0,60.0
695.48462,0.13300591141732285,913.1874561745229,0.00025370340306410486,25.0,60.0
696.88599,0.1334055787401575,911.0687183482664,0.00025370340306410486,25.0,60.0
698.28735,0.13380161023622048,911.7120893390469,0.00025370340306410486,25.0,60.0
699.68872,0.13422893307086614,912.5117517205558,0.00025370340306410486,25.0,60.0
701.09009,0.1346667559055118,914.0107518504091,0.00025370340306410486,25.0,60.0
702.49146,0.13512046850393702,912.5627321127126,0.00025370340306410486,25.0,60.0
703.89282,0.1355383346456693,911.9075444747436,0.00025370340306410486,25.0,60.0
705.29419,0.1359285688976378,912.9822620438905,0.00025370340306410486,25.0,60.0
706.69556,0.13632708661417323,913.1439553304766,0.00025370340306410486,25.0,60.0
708.09692,0.13680537795275588,912.6038696273212,0.00025370340306410486,25.0,60.0
709.49829,0.13722675196850392,912.9269185820024,0.00025370340306410486,25.0,60.0
710.89966,0.13763933858267716,913.5950136345929,0.00025370340306410486,25.0,60.0
712.30103,0.1380490748031496,913.3843916374498,0.00025370340306410486,25.0,60.0
713.70239,0.13842912401574803,914.2425659005324,0.00025370340306410486,25.0,60.0
715.10376,0.13892406496062992,914.0065186339436,0.00025370340306410486,25.0,60.0
716.50513,0.1393612440944882,913.1770419426049,0.00025370340306410486,25.0,60.0
717.90649,0.13975179527559056,913.8989222178938,0.00025370340306410486,25.0,60.0
719.30786,0.14016448818897637,912.758446954941,0.00025370340306410486,25.0,60.0
720.70923,0.14063331102362203,915.521256979613,0.00025370340306410486,25.0,60.0
722.1106,0.14098435629921258,913.7593559278017,0.00025370340306410486,25.0,60.0
723.51196,0.1413470531496063,912.9797428905338,0.00025370340306410486,25.0,60.0
724.91333,0.141691468503937,913.794857810674,0.00025370340306410486,25.0,60.0
726.3147,0.1420512440944882,914.3821321906246,0.00025370340306410486,25.0,60.0
727.71606,0.14247935433070866,915.5993767043242,0.00025370340306410486,25.0,60.0
729.11743,0.1429896535433071,915.8622516556292,0.00025370340306410486,25.0,60.0
730.5188,0.14350716929133858,916.0042072458123,0.00025370340306410486,25.0,60.0
731.92017,0.14392751181102362,914.2060511621868,0.00025370340306410486,25.0,60.0
733.32153,0.1443422342519685,916.0929229970135,0.00025370340306410486,25.0,60.0
734.7229,0.1447865688976378,917.0672639916894,0.00025370340306410486,25.0,60.0
736.12427,0.1452459251968504,917.1494870796001,0.00025370340306410486,25.0,60.0
737.52563,0.14568493307086613,915.4241267367875,0.00025370340306410486,25.0,60.0
738.927,0.1460941062992126,916.0059992208804,0.00025370340306410486,25.0,60.0
740.32837,0.14655638188976378,918.0533437215946,0.00025370340306410486,25.0,60.0
741.72974,0.1469867559055118,916.7179067653551,0.00025370340306410486,25.0,60.0
743.1311,0.14747932677165354,917.3610699909103,0.00025370340306410486,25.0,60.0
744.53247,0.14790377559055118,917.2115049993508,0.00025370340306410486,25.0,60.0
745.93384,0.1483386318897638,915.8209063757954,0.00025370340306410486,25.0,60.0
747.33521,0.1487129192913386,916.8778600181795,0.00025370340306410486,25.0,60.0
748.73657,0.14914284842519684,917.598389819504,0.00025370340306410486,25.0,60.0
750.13794,0.14963119488188975,918.9233086612128,0.00025370340306410486,25.0,60.0
751.53931,0.15009952559055117,918.6452928191144,0.00025370340306410486,25.0,60.0
752.94067,0.15056721062992126,915.2444357875602,0.00025370340306410486,25.0,60.0
754.34204,0.15101768307086616,918.566783534606,0.00025370340306410486,25.0,60.0
755.74341,0.15149347637795274,918.8405142189326,0.00025370340306410486,25.0,60.0
757.14478,0.15189170078740158,915.567614595507,0.00025370340306410486,25.0,60.0
758.54614,0.15229831496062993,919.4878587196469,0.00025370340306410486,25.0,60.0
759.94751,0.1527490688976378,918.1607323724191,0.00025370340306410486,25.0,60.0
761.34888,0.15316634842519683,917.7221140111674,0.00025370340306410486,25.0,60.0
762.75024,0.15363387007874016,918.5239838981951,0.00025370340306410486,25.0,60.0
764.15161,0.15410902952755906,918.8257369172836,0.00025370340306410486,25.0,60.0
765.55298,0.15456303346456693,919.4426697831451,0.00025370340306410486,25.0,60.0
766.95435,0.15495258661417322,918.1828074276068,0.00025370340306410486,25.0,60.0
768.35571,0.15535427362204723,917.968237891183,0.00025370340306410486,25.0,60.0
769.75708,0.15586157086614172,922.4050123360603,0.00025370340306410486,25.0,60.0
771.15845,0.15630503740157478,918.8205947279575,0.00025370340306410486,25.0,60.0
772.55981,0.15674123228346457,918.7657447084795,0.00025370340306410486,25.0,60.0
773.96118,0.15726516535433072,920.3792754187768,0.00025370340306410486,25.0,60.0
775.36255,0.15776237204724408,919.483547591222,0.00025370340306410486,25.0,60.0
776.76392,0.15818690157480314,919.6576029087132,0.00025370340306410486,25.0,60.0
778.16528,0.1587573464566929,921.8043630697313,0.00025370340306410486,25.0,60.0
779.56665,0.15926403346456694,919.2617582132191,0.00025370340306410486,25.0,60.0
780.96802,0.15974383858267716,919.4845604466952,0.00025370340306410486,25.0,60.0
782.36938,0.1602322913385827,920.4658875470719,0.00025370340306410486,25.0,60.0
783.77075,0.1606574566929134,918.978989741592,0.00025370340306410486,25.0,60.0
785.17212,0.16112920078740156,920.8943254122842,0.00025370340306410486,25.0,60.0
786.57349,0.1616243779527559,920.3377483443709,0.00025370340306410486,25.0,60.0
787.97485,0.16216208661417322,921.2406440721984,0.00025370340306410486,25.0,60.0
789.37622,0.16262141732283464,919.9521101155694,0.00025370340306410486,25.0,60.0
790.77759,0.16313090748031495,920.3760550577847,0.00025370340306410486,25.0,60.0
792.17896,0.16354988976377954,920.14595507077,0.00025370340306410486,25.0,60.0
793.58032,0.16396424606299212,919.8898584599402,0.00025370340306410486,25.0,60.0
794.98169,0.1644602086614173,921.2176081028439,0.00025370340306410486,25.0,60.0
796.38306,0.1649602657480315,921.1971432281522,0.00025370340306410486,25.0,60.0
797.78442,0.16533227952755905,919.8188546941956,0.00025370340306410486,25.0,60.0
799.18579,0.16577716732283462,921.303285287625,0.00025370340306410486,25.0,60.0
800.58716,0.1662788188976378,923.4159979223477,0.00025370340306410486,25.0,60.0
801.98853,0.16680486614173226,921.798078171666,0.00025370340306410486,25.0,60.0
803.38989,0.16726302362204726,920.2503830671342,0.00025370340306410486,25.0,60.0
804.79126,0.16773801771653543,921.2717049733801,0.00025370340306410486,25.0,60.0
806.19263,0.16815765551181103,919.8758343072329,0.00025370340306410486,25.0,60.0
807.59399,0.1686327460629921,922.7260096091417,0.00025370340306410486,25.0,60.0
808.99536,0.16913147637795276,920.488196338138,0.00025370340306410486,25.0,60.0
810.39673,0.16955397637795278,922.0047266588755,0.00025370340306410486,25.0,60.0
811.7981,0.17008448228346457,922.6553954031945,0.00025370340306410486,25.0,60.0
813.19946,0.1706113838582677,920.6340994676017,0.00025370340306410486,25.0,60.0
814.60083,0.17112071062992126,923.103285287625,0.00025370340306410486,25.0,60.0
816.0022,0.17164970275590552,920.706012206207,0.00025370340306410486,25.0,60.0
817.40356,0.17213099803149606,921.9899493572264,0.00025370340306410486,25.0,60.0
818.80493,0.17262856889763778,923.1392286716011,0.00025370340306410486,25.0,60.0
820.2063,0.17317308267716536,921.5915075964161,0.00025370340306410486,25.0,60.0
821.60767,0.17368815748031496,922.2753408648227,0.00025370340306410486,25.0,60.0
823.00903,0.1742471968503937,923.4264640955721,0.00025370340306410486,25.0,60.0
824.4104,0.17473830314960628,921.5400337618491,0.00025370340306410486,25.0,60.0
825.81177,0.17531288976377954,923.2584339696144,0.00025370340306410486,25.0,60.0
827.21313,0.1758465964566929,922.3619529931178,0.00025370340306410486,25.0,60.0
828.6145,0.17634678346456692,923.209297493832,0.00025370340306410486,25.0,60.0
830.01587,0.17688496062992126,923.5380599922088,0.00025370340306410486,25.0,60.0
831.41724,0.17743287795275592,921.4990780418128,0.00025370340306410486,25.0,60.0
832.8186,0.1779197716535433,921.3510193481367,0.00025370340306410486,25.0,60.0
834.21997,0.17839646653543306,922.094766913388,0.00025370340306410486,25.0,60.0
835.62134,0.17892457874015746,923.6580703804701,0.00025370340306410486,25.0,60.0
837.02271,0.17947650787401573,921.9737176990002,0.00025370340306410486,25.0,60.0
838.42407,0.17998144685039372,921.5898714452669,0.00025370340306410486,25.0,60.0
839.82544,0.18047009842519685,922.0093494351383,0.00025370340306410486,25.0,60.0
841.22681,0.1809749311023622,924.9296714712375,0.00025370340306410486,25.0,60.0
842.62817,0.18150061417322833,922.8023633294378,0.00025370340306410486,25.0,60.0
844.02954,0.1820303208661417,922.8955720036358,0.00025370340306410486,25.0,60.0
845.43091,0.18257980905511811,920.8798078171666,0.00025370340306410486,25.0,60.0
846.83228,0.183108718503937,921.5692507466563,0.00025370340306410486,25.0,60.0
848.23364,0.18365320866141732,923.5868588495001,0.00025370340306410486,25.0,60.0
849.63501,0.18415113188976376,921.7250486949747,0.00025370340306410486,25.0,60.0
851.03638,0.18466668897637795,922.9665757693806,0.00025370340306410486,25.0,60.0
852.43774,0.18526147834645668,924.6909492273732,0.00025370340306410486,25.0,60.0
853.83911,0.18586023622047243,923.998545643423,0.00025370340306410486,25.0,60.0
855.24048,0.1864462618110236,923.1242695753798,0.00025370340306410486,25.0,60.0
856.64185,0.18699520078740156,922.8123100895988,0.00025370340306410486,25.0,60.0
858.04321,0.18754896062992127,922.9244773406051,0.00025370340306410486,25.0,60.0
859.34448,0.18809339173228345,926.4664589014415,0.00025370340306410486,25.0,60.0