File: datasets/am_bench_2022/csv/60-XY.04-2.csv
Time(s),Strain(%),Stress(MPa),SR(s-1),Temp(C),Angle(deg)
11.95874,4.580485236220472e-06,11.446000522875817,0.00025370340306410486,25.0,60.0
13.760498,4.838615748031497e-06,17.455418300653598,0.00025370340306410486,25.0,60.0
15.261963,4.301186023622047e-05,24.997263267973857,0.00025370340306410486,25.0,60.0
16.763428,4.152276968503937e-05,28.800601307189545,0.00025370340306410486,25.0,60.0
18.264893,6.43443188976378e-05,34.02614117647059,0.00025370340306410486,25.0,60.0
19.766357,9.937704527559055e-05,39.303066666666666,0.00025370340306410486,25.0,60.0
21.267822,0.00011660380905511812,43.52292026143791,0.00025370340306410486,25.0,60.0
22.769287,0.00015092184251968505,50.54004444444445,0.00025370340306410486,25.0,60.0
24.270752,0.00016171975393700788,57.28357647058824,0.00025370340306410486,25.0,60.0
25.772217,0.00018790929330708662,63.81414640522876,0.00025370340306410486,25.0,60.0
27.273682,0.00021355090551181103,69.15075816993465,0.00025370340306410486,25.0,60.0
28.775146,0.00023960171259842519,79.3697751633987,0.00025370340306410486,25.0,60.0
30.276611,0.0002679085236220473,86.3450640522876,0.00025370340306410486,25.0,60.0
31.778076,0.00030041883858267714,93.54350065359479,0.00025370340306410486,25.0,60.0
33.279541,0.00033357287401574804,102.13258562091505,0.00025370340306410486,25.0,60.0
34.781006,0.0003464930905511811,110.66671895424838,0.00025370340306410486,25.0,60.0
36.282471,0.0004105634645669291,121.23415424836602,0.00025370340306410486,25.0,60.0
37.783936,0.0004351967716535433,131.1148679738562,0.00025370340306410486,25.0,60.0
39.2854,0.00047186942913385825,140.5904366013072,0.00025370340306410486,25.0,60.0
40.786865,0.0004955639763779527,149.36015947712417,0.00025370340306410486,25.0,60.0
42.28833,0.0005336053543307086,158.01393986928105,0.00025370340306410486,25.0,60.0
43.789795,0.0005617445866141732,167.8650614379085,0.00025370340306410486,25.0,60.0
45.29126,0.0006390810236220472,180.88091764705882,0.00025370340306410486,25.0,60.0
46.792725,0.0006370057086614173,191.30240261437908,0.00025370340306410486,25.0,60.0
48.294189,0.000680225,201.05543790849674,0.00025370340306410486,25.0,60.0
49.795654,0.0007227854330708662,212.09383267973857,0.00025370340306410486,25.0,60.0
51.297119,0.0007645238976377953,223.82352941176472,0.00025370340306410486,25.0,60.0
52.798584,0.0007964453346456693,235.04562091503269,0.00025370340306410486,25.0,60.0
54.300049,0.0008308383661417324,246.7781411764706,0.00025370340306410486,25.0,60.0
55.801514,0.0008797656299212598,255.30153725490197,0.00025370340306410486,25.0,60.0
57.302979,0.0009238603543307086,268.95769934640526,0.00025370340306410486,25.0,60.0
58.804443,0.0009620807874015749,280.1357385620915,0.00025370340306410486,25.0,60.0
60.305908,0.0009933579133858267,290.96922875816995,0.00025370340306410486,25.0,60.0
61.807373,0.0010299159842519685,299.4787189542484,0.00025370340306410486,25.0,60.0
63.308838,0.0010733773228346457,310.0131503267974,0.00025370340306410486,25.0,60.0
64.810303,0.0011100644685039368,322.71623529411767,0.00025370340306410486,25.0,60.0
66.311768,0.001153214586614173,332.4016470588236,0.00025370340306410486,25.0,60.0
67.813232,0.0011615633070866142,341.69168627450983,0.00025370340306410486,25.0,60.0
69.314697,0.0012245656299212598,354.63113725490194,0.00025370340306410486,25.0,60.0
70.816162,0.0012373374803149606,363.747137254902,0.00025370340306410486,25.0,60.0
72.317627,0.0012985258267716536,377.6278692810458,0.00025370340306410486,25.0,60.0
73.819092,0.0013437068897637794,387.64067973856214,0.00025370340306410486,25.0,60.0
75.320557,0.0013684668700787402,398.7418823529412,0.00025370340306410486,25.0,60.0
76.822021,0.0014189122047244093,411.04833986928105,0.00025370340306410486,25.0,60.0
78.323486,0.001422405846456693,420.9392941176471,0.00025370340306410486,25.0,60.0
79.824951,0.001490633661417323,430.8680784313726,0.00025370340306410486,25.0,60.0
81.326416,0.0015367321062992126,443.13260130718953,0.00025370340306410486,25.0,60.0
82.827881,0.0015736047834645668,454.1887843137255,0.00025370340306410486,25.0,60.0
84.329346,0.0016194014763779526,463.93241830065364,0.00025370340306410486,25.0,60.0
85.830811,0.0016292692716535432,472.54556862745096,0.00025370340306410486,25.0,60.0
87.332275,0.001687569527559055,483.9828235294118,0.00025370340306410486,25.0,60.0
88.83374,0.0017195936417322834,492.4445751633987,0.00025370340306410486,25.0,60.0
90.335205,0.0017467735826771653,502.1037647058824,0.00025370340306410486,25.0,60.0
91.83667,0.0017841423622047244,509.6833725490196,0.00025370340306410486,25.0,60.0
93.338135,0.0018154976771653543,521.8744575163399,0.00025370340306410486,25.0,60.0
94.8396,0.0018594284251968506,528.710431372549,0.00025370340306410486,25.0,60.0
96.341064,0.0019009014173228345,537.9197908496733,0.00025370340306410486,25.0,60.0
97.842529,0.0019263408267716537,546.9081307189543,0.00025370340306410486,25.0,60.0
99.343994,0.001967799901574803,554.2279477124183,0.00025370340306410486,25.0,60.0
100.84546,0.0019963133858267716,561.9378823529413,0.00025370340306410486,25.0,60.0
102.34692,0.0020204102362204727,568.4863790849673,0.00025370340306410486,25.0,60.0
103.84839,0.0020595529527559055,575.4068496732026,0.00025370340306410486,25.0,60.0
105.34985,0.0020737216535433073,582.3477124183007,0.00025370340306410486,25.0,60.0
106.85132,0.0021115316929133858,589.631137254902,0.00025370340306410486,25.0,60.0
108.35278,0.0021434356299212596,594.191816993464,0.00025370340306410486,25.0,60.0
109.85425,0.0021857562992125983,601.5576470588236,0.00025370340306410486,25.0,60.0
111.35571,0.0022069009842519685,607.8650196078432,0.00025370340306410486,25.0,60.0
112.85718,0.0022535824803149606,613.4629542483661,0.00025370340306410486,25.0,60.0
114.35864,0.002272425,619.2908758169935,0.00025370340306410486,25.0,60.0
115.86011,0.0022975133858267717,623.7793725490196,0.00025370340306410486,25.0,60.0
117.36157,0.0023264639763779524,627.2664575163399,0.00025370340306410486,25.0,60.0
118.86304,0.0023560946850393703,632.5998169934642,0.00025370340306410486,25.0,60.0
120.3645,0.0023694751968503934,636.3076339869281,0.00025370340306410486,25.0,60.0
121.86597,0.002403938582677165,642.0921307189543,0.00025370340306410486,25.0,60.0
123.36743,0.002440291535433071,646.5613594771243,0.00025370340306410486,25.0,60.0
124.8689,0.0024647307086614174,650.7418039215686,0.00025370340306410486,25.0,60.0
126.37036,0.002502669881889764,655.1095947712419,0.00025370340306410486,25.0,60.0
127.87183,0.0025300935039370078,659.8405490196079,0.00025370340306410486,25.0,60.0
129.37329,0.00255861968503937,663.6699607843138,0.00025370340306410486,25.0,60.0
130.87476,0.0026155023622047246,667.5875816993465,0.00025370340306410486,25.0,60.0
132.37622,0.00263840531496063,670.6807320261438,0.00025370340306410486,25.0,60.0
133.87769,0.002684344881889764,676.0763137254902,0.00025370340306410486,25.0,60.0
135.37915,0.0027250088582677166,676.5189019607843,0.00025370340306410486,25.0,60.0
136.88062,0.002767778937007874,683.178431372549,0.00025370340306410486,25.0,60.0
138.38208,0.0027998366141732283,685.3409673202615,0.00025370340306410486,25.0,60.0
139.88354,0.0028541110236220473,688.9442352941177,0.00025370340306410486,25.0,60.0
141.38501,0.0028816712598425196,691.7336732026145,0.00025370340306410486,25.0,60.0
142.88647,0.0029485891732283463,692.7794248366014,0.00025370340306410486,25.0,60.0
144.38794,0.003022372244094488,699.6668758169935,0.00025370340306410486,25.0,60.0
145.8894,0.0030703273622047244,700.3481045751633,0.00025370340306410486,25.0,60.0
147.39087,0.0031503889763779525,706.9320522875818,0.00025370340306410486,25.0,60.0
148.89233,0.0032388114173228346,708.5912679738564,0.00025370340306410486,25.0,60.0
150.3938,0.0033199633858267716,711.7349019607843,0.00025370340306410486,25.0,60.0
151.89526,0.0034207836614173225,715.5524967320262,0.00025370340306410486,25.0,60.0
153.39673,0.003527711614173228,716.8266143790851,0.00025370340306410486,25.0,60.0
154.89819,0.0036386013779527555,719.9410980392157,0.00025370340306410486,25.0,60.0
156.39966,0.0037504003937007873,724.5277385620916,0.00025370340306410486,25.0,60.0
157.90112,0.003880941141732283,726.7430065359478,0.00025370340306410486,25.0,60.0
159.40259,0.004026316929133858,728.2600522875817,0.00025370340306410486,25.0,60.0
160.90405,0.004174490551181103,731.5265620915034,0.00025370340306410486,25.0,60.0
162.40552,0.004315983464566929,733.7279215686275,0.00025370340306410486,25.0,60.0
163.90698,0.004469900000000001,735.7336470588235,0.00025370340306410486,25.0,60.0
165.40845,0.00468013031496063,739.0883398692812,0.00025370340306410486,25.0,60.0
166.90991,0.0048540586614173225,738.7294379084968,0.00025370340306410486,25.0,60.0
168.41138,0.0050089161417322834,741.3979607843138,0.00025370340306410486,25.0,60.0
169.91284,0.005187051771653543,743.9613333333333,0.00025370340306410486,25.0,60.0
171.41431,0.005407152165354331,745.9018300653596,0.00025370340306410486,25.0,60.0
172.91577,0.005617392322834646,746.5528104575163,0.00025370340306410486,25.0,60.0
174.41724,0.005846190157480315,748.655660130719,0.00025370340306410486,25.0,60.0
175.9187,0.006076751181102362,750.6205228758171,0.00025370340306410486,25.0,60.0
177.42017,0.0063139637795275585,753.3908496732026,0.00025370340306410486,25.0,60.0
178.92163,0.006594562401574803,754.5849934640523,0.00025370340306410486,25.0,60.0
180.4231,0.006842701181102362,754.8339084967321,0.00025370340306410486,25.0,60.0
181.92456,0.007079956102362205,757.2638954248366,0.00025370340306410486,25.0,60.0
183.42603,0.007309299015748032,758.6710326797387,0.00025370340306410486,25.0,60.0
184.92749,0.0075994389763779525,760.192183006536,0.00025370340306410486,25.0,60.0
186.42896,0.00786076437007874,763.109751633987,0.00025370340306410486,25.0,60.0
187.93042,0.008165850196850394,764.286274509804,0.00025370340306410486,25.0,60.0
189.43188,0.008461647047244093,765.2486797385621,0.00025370340306410486,25.0,60.0
190.93335,0.008784260826771653,764.806274509804,0.00025370340306410486,25.0,60.0
192.43481,0.009067605118110236,767.8018300653596,0.00025370340306410486,25.0,60.0
193.93628,0.009345984055118111,769.8295686274511,0.00025370340306410486,25.0,60.0
195.43774,0.00967318405511811,769.3902483660131,0.00025370340306410486,25.0,60.0
196.93921,0.009947131496062992,769.4729673202615,0.00025370340306410486,25.0,60.0
198.44067,0.010249785039370077,772.6551633986928,0.00025370340306410486,25.0,60.0
199.94214,0.010599091141732284,774.615816993464,0.00025370340306410486,25.0,60.0
201.4436,0.010917194291338582,775.7014117647059,0.00025370340306410486,25.0,60.0
202.94507,0.011243188582677165,777.0572810457517,0.00025370340306410486,25.0,60.0
204.44653,0.011512216929133859,776.0675294117647,0.00025370340306410486,25.0,60.0
205.948,0.011815176968503937,777.900522875817,0.00025370340306410486,25.0,60.0
207.44946,0.012152048818897638,780.1002614379086,0.00025370340306410486,25.0,60.0
208.95093,0.012471083858267718,778.7222222222223,0.00025370340306410486,25.0,60.0
210.45239,0.012771675196850395,780.0961830065361,0.00025370340306410486,25.0,60.0
211.95386,0.013126529724409449,782.6306666666667,0.00025370340306410486,25.0,60.0
213.45532,0.013427038976377953,784.2950326797386,0.00025370340306410486,25.0,60.0
214.95679,0.013760905511811024,784.3401568627451,0.00025370340306410486,25.0,60.0
216.45825,0.014092648622047245,784.8506405228759,0.00025370340306410486,25.0,60.0
217.95972,0.014433676771653543,786.6139346405229,0.00025370340306410486,25.0,60.0
219.46118,0.01478485,786.5190849673203,0.00025370340306410486,25.0,60.0
220.96265,0.015148549803149605,787.8849411764706,0.00025370340306410486,25.0,60.0
222.46411,0.015432823228346455,788.6272679738563,0.00025370340306410486,25.0,60.0
223.96558,0.015768341338582677,790.2011241830065,0.00025370340306410486,25.0,60.0
225.46704,0.01608206062992126,790.4561045751634,0.00025370340306410486,25.0,60.0
226.96851,0.016399562401574804,791.4146666666667,0.00025370340306410486,25.0,60.0
228.46997,0.01673515531496063,794.3597385620916,0.00025370340306410486,25.0,60.0
229.97144,0.017087088188976376,795.664705882353,0.00025370340306410486,25.0,60.0
231.4729,0.01740912775590551,794.9858823529412,0.00025370340306410486,25.0,60.0
232.97437,0.017787763976377952,796.3344313725491,0.00025370340306410486,25.0,60.0
234.47583,0.01811460098425197,796.2489150326797,0.00025370340306410486,25.0,60.0
235.97729,0.01848439468503937,796.6282352941178,0.00025370340306410486,25.0,60.0
237.47876,0.018865641535433072,799.488549019608,0.00025370340306410486,25.0,60.0
238.98022,0.019243649999999998,800.1701699346406,0.00025370340306410486,25.0,60.0
240.48169,0.019582698228346455,800.0137254901961,0.00025370340306410486,25.0,60.0
241.98315,0.019906419291338583,801.7253856209151,0.00025370340306410486,25.0,60.0
243.48462,0.02028381496062992,802.4463790849674,0.00025370340306410486,25.0,60.0
244.98608,0.020629358267716533,802.495477124183,0.00025370340306410486,25.0,60.0
246.48755,0.02097386220472441,803.2043921568628,0.00025370340306410486,25.0,60.0
247.98901,0.021269970472440943,802.9151895424837,0.00025370340306410486,25.0,60.0
249.49048,0.021590844488188977,807.716888888889,0.00025370340306410486,25.0,60.0
250.99194,0.021971214566929135,807.1773594771242,0.00025370340306410486,25.0,60.0
252.49341,0.022248194881889765,807.1732026143792,0.00025370340306410486,25.0,60.0
253.99487,0.022632744094488188,807.9021699346406,0.00025370340306410486,25.0,60.0
255.49634,0.022982139763779528,809.25722875817,0.00025370340306410486,25.0,60.0
256.9978,0.023297395669291336,807.6647320261438,0.00025370340306410486,25.0,60.0
258.49927,0.02360749212598425,811.3636862745099,0.00025370340306410486,25.0,60.0
260.00073,0.023950496062992127,810.5922614379086,0.00025370340306410486,25.0,60.0
261.5022,0.024329253937007876,812.6136732026145,0.00025370340306410486,25.0,60.0
263.00366,0.024723108267716534,813.0098039215686,0.00025370340306410486,25.0,60.0
264.50513,0.025058482283464568,813.5342745098039,0.00025370340306410486,25.0,60.0
266.00659,0.025456372047244092,816.0315816993465,0.00025370340306410486,25.0,60.0
267.50806,0.025825659448818896,814.0441307189543,0.00025370340306410486,25.0,60.0
269.00952,0.02611344291338583,814.7070326797385,0.00025370340306410486,25.0,60.0
270.51099,0.02645152362204724,816.2088366013072,0.00025370340306410486,25.0,60.0
272.01245,0.026769557086614174,816.446091503268,0.00025370340306410486,25.0,60.0
273.51392,0.02715542125984252,819.162274509804,0.00025370340306410486,25.0,60.0
275.01538,0.027454840551181102,816.8511895424838,0.00025370340306410486,25.0,60.0
276.51685,0.027790759842519684,818.8623267973857,0.00025370340306410486,25.0,60.0
278.01831,0.028186608267716535,819.0923137254903,0.00025370340306410486,25.0,60.0
279.51978,0.028482311023622045,819.9202091503269,0.00025370340306410486,25.0,60.0
281.02124,0.02884575,819.6518954248368,0.00025370340306410486,25.0,60.0
282.52271,0.02919765157480315,821.9671633986928,0.00025370340306410486,25.0,60.0
284.02417,0.029529332677165353,823.1821960784314,0.00025370340306410486,25.0,60.0
285.52563,0.0298888405511811,822.4783006535948,0.00025370340306410486,25.0,60.0
287.0271,0.030192196850393697,823.5385359477125,0.00025370340306410486,25.0,60.0
288.52856,0.030532633858267717,826.5033202614379,0.00025370340306410486,25.0,60.0
290.03003,0.030926320866141735,826.3201568627451,0.00025370340306410486,25.0,60.0
291.53149,0.03136866929133858,826.3481045751635,0.00025370340306410486,25.0,60.0
293.03296,0.0316939625984252,826.4913986928105,0.00025370340306410486,25.0,60.0
294.53442,0.031978724409448815,826.3710065359477,0.00025370340306410486,25.0,60.0
296.03589,0.03230461220472441,828.739477124183,0.00025370340306410486,25.0,60.0
297.53735,0.032605946850393704,826.7500130718955,0.00025370340306410486,25.0,60.0
299.03882,0.032947933070866145,830.846980392157,0.00025370340306410486,25.0,60.0
300.54028,0.03334108661417323,832.9073464052289,0.00025370340306410486,25.0,60.0
302.04175,0.03373373228346457,831.2174379084968,0.00025370340306410486,25.0,60.0
303.54321,0.03405738779527559,832.0235294117647,0.00025370340306410486,25.0,60.0
305.04468,0.034406338582677165,833.0450980392158,0.00025370340306410486,25.0,60.0
306.54614,0.034802468503937006,832.4338039215687,0.00025370340306410486,25.0,60.0
308.04761,0.03513116535433071,834.2900392156863,0.00025370340306410486,25.0,60.0
309.54907,0.035483950787401575,834.3471633986928,0.00025370340306410486,25.0,60.0
311.05054,0.03582981496062992,834.9636862745099,0.00025370340306410486,25.0,60.0
312.552,0.03613131102362205,834.5507189542484,0.00025370340306410486,25.0,60.0
314.05347,0.0364981968503937,837.5728366013072,0.00025370340306410486,25.0,60.0
315.55493,0.03685775787401575,838.3023006535948,0.00025370340306410486,25.0,60.0
317.0564,0.03720988385826771,838.2206013071896,0.00025370340306410486,25.0,60.0
318.55786,0.03750953149606299,837.1607581699348,0.00025370340306410486,25.0,60.0
320.05933,0.0378448248031496,840.097411764706,0.00025370340306410486,25.0,60.0
321.56079,0.03817998425196851,839.8845228758171,0.00025370340306410486,25.0,60.0
323.06226,0.03849445472440945,838.4634771241831,0.00025370340306410486,25.0,60.0
324.56372,0.038861777559055115,841.9680000000001,0.00025370340306410486,25.0,60.0
326.06519,0.03916887204724409,841.1018039215686,0.00025370340306410486,25.0,60.0
327.56665,0.039526251968503935,843.4586143790851,0.00025370340306410486,25.0,60.0
329.06812,0.03987218110236221,842.6792156862746,0.00025370340306410486,25.0,60.0
330.56958,0.04021582283464567,843.1282614379086,0.00025370340306410486,25.0,60.0
332.07104,0.040501726377952754,843.7917385620916,0.00025370340306410486,25.0,60.0
333.57251,0.0408631437007874,844.9384575163399,0.00025370340306410486,25.0,60.0
335.07397,0.041199580708661414,845.2114509803922,0.00025370340306410486,25.0,60.0
336.57544,0.04156990748031496,845.2652549019608,0.00025370340306410486,25.0,60.0
338.0769,0.04192475196850393,847.9167320261439,0.00025370340306410486,25.0,60.0
339.57837,0.04229401771653543,849.4220392156863,0.00025370340306410486,25.0,60.0
341.07983,0.04261750196850393,845.5090980392157,0.00025370340306410486,25.0,60.0
342.5813,0.042946049212598425,847.8800261437908,0.00025370340306410486,25.0,60.0
344.08276,0.04332027362204724,848.160366013072,0.00025370340306410486,25.0,60.0
345.58423,0.04366272047244095,850.4711111111112,0.00025370340306410486,25.0,60.0
347.08569,0.04401706496062992,851.3815424836602,0.00025370340306410486,25.0,60.0
348.58716,0.04437180118110236,851.2208888888889,0.00025370340306410486,25.0,60.0
350.08862,0.04474767716535433,851.1559215686276,0.00025370340306410486,25.0,60.0
351.59009,0.04508420275590551,850.6260130718955,0.00025370340306410486,25.0,60.0
353.09155,0.045386566929133856,852.778980392157,0.00025370340306410486,25.0,60.0
354.59302,0.04572277952755905,856.1318431372549,0.00025370340306410486,25.0,60.0
356.09448,0.04605684645669291,854.3263006535948,0.00025370340306410486,25.0,60.0
357.59595,0.046427610236220475,854.0517647058824,0.00025370340306410486,25.0,60.0
359.09741,0.04673662992125984,853.3866928104576,0.00025370340306410486,25.0,60.0
360.59888,0.047070498031496065,854.9806535947713,0.00025370340306410486,25.0,60.0
362.10034,0.04737684842519685,856.5576470588236,0.00025370340306410486,25.0,60.0
363.60181,0.04773190157480315,857.6122091503269,0.00025370340306410486,25.0,60.0
365.10327,0.04811341535433071,856.9888104575164,0.00025370340306410486,25.0,60.0
366.60474,0.048470614173228344,857.8775424836602,0.00025370340306410486,25.0,60.0
368.1062,0.04878081692913386,857.2385098039216,0.00025370340306410486,25.0,60.0
369.60767,0.04913375393700787,858.6302483660131,0.00025370340306410486,25.0,60.0
371.10913,0.049529049212598424,859.9098823529412,0.00025370340306410486,25.0,60.0
372.6106,0.049932688976377954,859.1670588235295,0.00025370340306410486,25.0,60.0
374.11206,0.05027139566929134,862.0809150326797,0.00025370340306410486,25.0,60.0
375.61353,0.050594171259842516,860.17322875817,0.00025370340306410486,25.0,60.0
377.11499,0.050932972440944885,860.7798431372549,0.00025370340306410486,25.0,60.0
378.61646,0.05127997637795275,863.7247320261439,0.00025370340306410486,25.0,60.0
380.11792,0.05163960433070866,863.646091503268,0.00025370340306410486,25.0,60.0
381.61938,0.051962383858267715,863.0557385620916,0.00025370340306410486,25.0,60.0
383.12085,0.05224123622047244,864.7451241830065,0.00025370340306410486,25.0,60.0
384.62231,0.05264022244094488,864.8228235294117,0.00025370340306410486,25.0,60.0
386.12378,0.05297876771653544,865.8841307189543,0.00025370340306410486,25.0,60.0
387.62524,0.053317135826771646,866.6166797385621,0.00025370340306410486,25.0,60.0
389.12671,0.05362928543307086,866.6482875816995,0.00025370340306410486,25.0,60.0
390.62817,0.053975572834645665,866.4133333333334,0.00025370340306410486,25.0,60.0
392.12964,0.054295812992125984,865.1901437908498,0.00025370340306410486,25.0,60.0
393.6311,0.05459842913385826,868.179320261438,0.00025370340306410486,25.0,60.0
395.13257,0.05493233267716535,868.1179869281046,0.00025370340306410486,25.0,60.0
396.63403,0.05522724606299212,868.675843137255,0.00025370340306410486,25.0,60.0
398.1355,0.05555642716535433,870.64522875817,0.00025370340306410486,25.0,60.0
399.63696,0.055910435039370085,870.4300653594772,0.00025370340306410486,25.0,60.0
401.13843,0.05630465354330709,871.4045228758171,0.00025370340306410486,25.0,60.0
402.63989,0.05670291338582677,871.5680522875817,0.00025370340306410486,25.0,60.0
404.14136,0.05704946456692914,872.5956862745098,0.00025370340306410486,25.0,60.0
405.64282,0.057383263779527564,873.1424836601308,0.00025370340306410486,25.0,60.0
407.14429,0.05772192913385827,872.3811503267974,0.00025370340306410486,25.0,60.0
408.64575,0.0580634311023622,872.4338039215687,0.00025370340306410486,25.0,60.0
410.14722,0.05839677755905512,873.9087320261438,0.00025370340306410486,25.0,60.0
411.64868,0.05874894881889763,874.0223529411765,0.00025370340306410486,25.0,60.0
413.15015,0.05908812598425196,874.4574117647059,0.00025370340306410486,25.0,60.0
414.65161,0.059416866141732284,875.641071895425,0.00025370340306410486,25.0,60.0
416.15308,0.05974156496062992,874.6492549019608,0.00025370340306410486,25.0,60.0
417.65454,0.060043232283464566,872.8708496732028,0.00025370340306410486,25.0,60.0
419.15601,0.06033374015748031,878.0173333333333,0.00025370340306410486,25.0,60.0
420.65747,0.06071796653543307,878.9831111111112,0.00025370340306410486,25.0,60.0
422.15894,0.061057960629921255,878.5077647058823,0.00025370340306410486,25.0,60.0
423.6604,0.06137723228346457,877.6305882352941,0.00025370340306410486,25.0,60.0
425.16187,0.06171295472440945,878.408705882353,0.00025370340306410486,25.0,60.0
426.66333,0.062011000000000004,878.6144313725491,0.00025370340306410486,25.0,60.0
428.16479,0.062326037401574795,879.0579607843138,0.00025370340306410486,25.0,60.0
429.66626,0.06268374606299212,879.8570196078432,0.00025370340306410486,25.0,60.0
431.16772,0.06304934055118111,880.9336732026145,0.00025370340306410486,25.0,60.0
432.66919,0.06336925984251969,881.2708758169936,0.00025370340306410486,25.0,60.0
434.17065,0.06374022834645669,882.1222745098039,0.00025370340306410486,25.0,60.0
435.67212,0.06403879527559055,881.5092549019608,0.00025370340306410486,25.0,60.0
437.17358,0.06437055905511811,883.8939869281046,0.00025370340306410486,25.0,60.0
438.67505,0.06472222637795275,884.3305098039216,0.00025370340306410486,25.0,60.0
440.17651,0.0650437972440945,883.6670326797387,0.00025370340306410486,25.0,60.0
441.67798,0.06538323228346457,885.3840000000001,0.00025370340306410486,25.0,60.0
443.17944,0.06574550787401574,886.820366013072,0.00025370340306410486,25.0,60.0
444.68091,0.06608001968503936,885.7597385620916,0.00025370340306410486,25.0,60.0
446.18237,0.06643277952755905,886.104026143791,0.00025370340306410486,25.0,60.0
447.68384,0.06675031496062991,885.880705882353,0.00025370340306410486,25.0,60.0
449.1853,0.06708165354330708,887.0468758169935,0.00025370340306410486,25.0,60.0
450.68677,0.06744590551181102,887.5379869281047,0.00025370340306410486,25.0,60.0
452.18823,0.0678059625984252,888.7039215686275,0.00025370340306410486,25.0,60.0
453.6897,0.06814860039370078,889.1796862745098,0.00025370340306410486,25.0,60.0
455.19116,0.06849145669291339,890.0005751633987,0.00025370340306410486,25.0,60.0
456.69263,0.06879264763779527,890.122797385621,0.00025370340306410486,25.0,60.0
458.19409,0.06914052559055119,887.674640522876,0.00025370340306410486,25.0,60.0
459.69556,0.06948633858267717,891.1996339869282,0.00025370340306410486,25.0,60.0
461.19702,0.06981704330708662,889.0900653594772,0.00025370340306410486,25.0,60.0
462.69849,0.07021930511811024,892.2927581699347,0.00025370340306410486,25.0,60.0
464.19995,0.07062597244094489,891.5093333333334,0.00025370340306410486,25.0,60.0
465.70142,0.0709367716535433,891.2455424836602,0.00025370340306410486,25.0,60.0
467.20288,0.07131872244094488,893.9237908496732,0.00025370340306410486,25.0,60.0
468.70435,0.07164321062992125,892.0081568627452,0.00025370340306410486,25.0,60.0
470.20581,0.07197409842519685,892.7924705882353,0.00025370340306410486,25.0,60.0
471.70728,0.07228854330708662,892.1353464052288,0.00025370340306410486,25.0,60.0
473.20874,0.07262370078740157,893.5917647058824,0.00025370340306410486,25.0,60.0
474.71021,0.07296233267716536,895.5629019607844,0.00025370340306410486,25.0,60.0
476.21167,0.0733116594488189,894.5018823529413,0.00025370340306410486,25.0,60.0
477.71313,0.07366376181102362,895.183503267974,0.00025370340306410486,25.0,60.0
479.2146,0.07404019094488189,896.8103529411765,0.00025370340306410486,25.0,60.0
480.71606,0.07441634645669291,896.9891241830067,0.00025370340306410486,25.0,60.0
482.21753,0.07477965354330708,897.5481307189543,0.00025370340306410486,25.0,60.0
483.71899,0.07506550787401574,896.8825359477124,0.00025370340306410486,25.0,60.0
485.22046,0.07541403149606299,897.2118692810458,0.00025370340306410486,25.0,60.0
486.72192,0.07579127755905513,898.7386405228758,0.00025370340306410486,25.0,60.0
488.22339,0.07615911417322835,897.152,0.00025370340306410486,25.0,60.0
489.72485,0.07645523031496063,898.7865620915034,0.00025370340306410486,25.0,60.0
491.22632,0.0768122716535433,899.7320522875818,0.00025370340306410486,25.0,60.0
492.72778,0.07717874015748032,901.2179607843137,0.00025370340306410486,25.0,60.0
494.22925,0.07751053149606299,898.9571241830066,0.00025370340306410486,25.0,60.0
495.73071,0.07782374212598425,901.884522875817,0.00025370340306410486,25.0,60.0
497.23218,0.07816699803149606,900.4458300653596,0.00025370340306410486,25.0,60.0
498.73364,0.07851309842519685,900.9684444444445,0.00025370340306410486,25.0,60.0
500.23511,0.07886216535433072,901.3352679738563,0.00025370340306410486,25.0,60.0
501.73657,0.07919621653543307,902.0323398692811,0.00025370340306410486,25.0,60.0
503.23804,0.07952524999999999,901.6868235294119,0.00025370340306410486,25.0,60.0
504.7395,0.07987971062992126,904.7212549019608,0.00025370340306410486,25.0,60.0
506.24097,0.08023749606299212,902.4468235294119,0.00025370340306410486,25.0,60.0
507.74243,0.0805594311023622,904.4249673202614,0.00025370340306410486,25.0,60.0
509.2439,0.0808624468503937,904.7171764705884,0.00025370340306410486,25.0,60.0
510.74536,0.08124886220472441,905.8602091503269,0.00025370340306410486,25.0,60.0
512.24683,0.08157607283464567,904.1263267973857,0.00025370340306410486,25.0,60.0
513.74829,0.08197991732283465,907.7172810457516,0.00025370340306410486,25.0,60.0
515.24976,0.08239084251968504,906.3253071895426,0.00025370340306410486,25.0,60.0
516.75122,0.08271512007874016,906.4236078431372,0.00025370340306410486,25.0,60.0
518.25269,0.08305155118110236,906.5380653594772,0.00025370340306410486,25.0,60.0
519.75415,0.08337744685039371,908.2600000000001,0.00025370340306410486,25.0,60.0
521.25562,0.08372509645669292,909.7135947712419,0.00025370340306410486,25.0,60.0
522.75708,0.08415957677165355,909.8586928104576,0.00025370340306410486,25.0,60.0
524.25854,0.08451373031496064,908.3447058823531,0.00025370340306410486,25.0,60.0
525.76001,0.08488958070866141,908.4792941176472,0.00025370340306410486,25.0,60.0
527.26147,0.08520446456692912,908.9844444444444,0.00025370340306410486,25.0,60.0
528.76294,0.08552461614173229,910.6458039215687,0.00025370340306410486,25.0,60.0
530.2644,0.0858657874015748,909.6262222222223,0.00025370340306410486,25.0,60.0
531.76587,0.08622549212598425,910.5312418300655,0.00025370340306410486,25.0,60.0
533.26733,0.08658537401574803,910.6930980392158,0.00025370340306410486,25.0,60.0
534.7688,0.08692335433070866,912.2518431372549,0.00025370340306410486,25.0,60.0
536.27026,0.08728729527559055,911.3903529411765,0.00025370340306410486,25.0,60.0
537.77173,0.08763123622047243,913.0662222222223,0.00025370340306410486,25.0,60.0
539.27319,0.08795886811023622,911.9675555555557,0.00025370340306410486,25.0,60.0
540.77466,0.08831162007874015,913.3343006535949,0.00025370340306410486,25.0,60.0
542.27612,0.08862252755905511,913.029071895425,0.00025370340306410486,25.0,60.0
543.77759,0.08900074015748032,914.7261699346406,0.00025370340306410486,25.0,60.0
545.27905,0.08937559842519685,914.8504575163399,0.00025370340306410486,25.0,60.0
546.78052,0.0897655807086614,915.2633464052288,0.00025370340306410486,25.0,60.0
548.28198,0.09012549606299212,916.5016732026145,0.00025370340306410486,25.0,60.0
549.78345,0.0904217657480315,914.7563137254903,0.00025370340306410486,25.0,60.0
551.28491,0.09083357677165355,916.0387973856209,0.00025370340306410486,25.0,60.0
552.78638,0.09116913582677166,916.1786405228759,0.00025370340306410486,25.0,60.0
554.28784,0.0915793562992126,917.2398954248366,0.00025370340306410486,25.0,60.0
555.78931,0.09194691732283464,916.8728366013072,0.00025370340306410486,25.0,60.0
557.29077,0.09231364960629922,915.5389019607843,0.00025370340306410486,25.0,60.0
558.79224,0.0926760531496063,916.9850457516341,0.00025370340306410486,25.0,60.0
560.2937,0.09305650787401575,917.8506666666667,0.00025370340306410486,25.0,60.0
561.79517,0.0934346811023622,919.0810718954249,0.00025370340306410486,25.0,60.0
563.29663,0.09376021850393701,918.9227712418302,0.00025370340306410486,25.0,60.0
564.7981,0.09414771850393701,919.729934640523,0.00025370340306410486,25.0,60.0
566.29956,0.09448375787401575,919.5686013071896,0.00025370340306410486,25.0,60.0
567.80103,0.09478959448818898,920.2091503267975,0.00025370340306410486,25.0,60.0
569.30249,0.09517212007874015,920.1708758169935,0.00025370340306410486,25.0,60.0
570.80396,0.09545252755905512,920.6244967320262,0.00025370340306410486,25.0,60.0
572.30542,0.09577011417322835,920.1131764705882,0.00025370340306410486,25.0,60.0
573.80688,0.09609636220472441,922.0858300653596,0.00025370340306410486,25.0,60.0
575.30835,0.0964906968503937,920.9610457516341,0.00025370340306410486,25.0,60.0
576.80981,0.09688277362204724,922.8198954248367,0.00025370340306410486,25.0,60.0
578.31128,0.09727800196850393,922.0144052287583,0.00025370340306410486,25.0,60.0
579.81274,0.09765070078740158,922.3589281045752,0.00025370340306410486,25.0,60.0
581.31421,0.09799815551181103,922.4290196078432,0.00025370340306410486,25.0,60.0
582.81567,0.09841541141732284,924.2905620915034,0.00025370340306410486,25.0,60.0
584.31714,0.09877274606299212,924.5597124183007,0.00025370340306410486,25.0,60.0
585.8186,0.09916105511811024,923.9021699346406,0.00025370340306410486,25.0,60.0
587.32007,0.09953047637795276,924.2636078431374,0.00025370340306410486,25.0,60.0
588.82153,0.09989624606299213,924.947660130719,0.00025370340306410486,25.0,60.0
590.323,0.10023973622047244,927.5887843137255,0.00025370340306410486,25.0,60.0
591.82446,0.10059485236220472,925.6808366013073,0.00025370340306410486,25.0,60.0
593.32593,0.10097067913385828,925.8121307189543,0.00025370340306410486,25.0,60.0
594.82739,0.10138758267716536,926.2407320261439,0.00025370340306410486,25.0,60.0
596.32886,0.10176079330708662,925.8903267973857,0.00025370340306410486,25.0,60.0
597.83032,0.10205919094488188,924.7107973856209,0.00025370340306410486,25.0,60.0
599.33179,0.1024255846456693,927.0991633986929,0.00025370340306410486,25.0,60.0
600.83325,0.1027903562992126,928.3579084967321,0.00025370340306410486,25.0,60.0
602.33472,0.10320388188976377,927.2602091503269,0.00025370340306410486,25.0,60.0
603.83618,0.10355970275590551,927.3416993464052,0.00025370340306410486,25.0,60.0
605.33765,0.10390422440944881,927.9559215686274,0.00025370340306410486,25.0,60.0
606.83911,0.10426572440944883,929.7638954248366,0.00025370340306410486,25.0,60.0
608.34058,0.10468340354330709,929.1465098039216,0.00025370340306410486,25.0,60.0
609.84204,0.10504889173228346,929.3901960784315,0.00025370340306410486,25.0,60.0
611.34351,0.10544379724409449,930.5865882352941,0.00025370340306410486,25.0,60.0
612.84497,0.1058197283464567,930.9191111111112,0.00025370340306410486,25.0,60.0
614.34644,0.1062156181102362,929.7553464052288,0.00025370340306410486,25.0,60.0
615.8479,0.10662623228346457,929.9158692810457,0.00025370340306410486,25.0,60.0
617.34937,0.10699171062992124,930.9896470588236,0.00025370340306410486,25.0,60.0
618.85083,0.1073792933070866,931.3397385620915,0.00025370340306410486,25.0,60.0
620.35229,0.10776495078740156,932.4144052287583,0.00025370340306410486,25.0,60.0
621.85376,0.1081341122047244,930.8320522875817,0.00025370340306410486,25.0,60.0
623.35522,0.108536468503937,933.728183006536,0.00025370340306410486,25.0,60.0
624.85669,0.10892886023622046,933.64245751634,0.00025370340306410486,25.0,60.0
626.35815,0.10929104133858267,932.3252287581699,0.00025370340306410486,25.0,60.0
627.85962,0.10964631102362205,931.9250980392158,0.00025370340306410486,25.0,60.0
629.36108,0.11003045669291339,932.7671111111111,0.00025370340306410486,25.0,60.0
630.86255,0.11041616141732283,934.9131241830066,0.00025370340306410486,25.0,60.0
632.36401,0.1108199468503937,935.2480261437909,0.00025370340306410486,25.0,60.0
633.86548,0.1112162125984252,934.3372810457516,0.00025370340306410486,25.0,60.0
635.36694,0.11158523425196851,934.6991895424837,0.00025370340306410486,25.0,60.0
636.86841,0.11194324803149606,934.0341699346405,0.00025370340306410486,25.0,60.0
638.36987,0.1123159527559055,935.7751111111112,0.00025370340306410486,25.0,60.0
639.87134,0.11268919881889763,934.8631633986929,0.00025370340306410486,25.0,60.0
641.3728,0.11307655905511811,936.1161568627451,0.00025370340306410486,25.0,60.0
642.87427,0.11341342913385827,936.5408104575164,0.00025370340306410486,25.0,60.0
644.37573,0.11374280511811022,936.6357647058825,0.00025370340306410486,25.0,60.0
645.8772,0.11418792716535434,938.2123137254903,0.00025370340306410486,25.0,60.0
647.37866,0.11463425787401574,937.5989281045753,0.00025370340306410486,25.0,60.0
648.88013,0.11501028346456692,936.5406797385621,0.00025370340306410486,25.0,60.0
650.38159,0.11532435826771652,935.5729934640523,0.00025370340306410486,25.0,60.0
651.88306,0.11565929330708662,937.0844183006537,0.00025370340306410486,25.0,60.0
653.38452,0.1161129094488189,938.101568627451,0.00025370340306410486,25.0,60.0
654.88599,0.11654593503937008,937.6928104575164,0.00025370340306410486,25.0,60.0
656.38745,0.11692249015748032,936.7012549019609,0.00025370340306410486,25.0,60.0
657.88892,0.11734496653543307,940.0811764705883,0.00025370340306410486,25.0,60.0
659.39038,0.1177717027559055,938.8903529411765,0.00025370340306410486,25.0,60.0
660.89185,0.11820748622047245,940.5136732026145,0.00025370340306410486,25.0,60.0
662.39331,0.1186045846456693,939.3517647058825,0.00025370340306410486,25.0,60.0
663.89478,0.11899121653543307,940.1800522875818,0.00025370340306410486,25.0,60.0
665.39624,0.11941464370078739,941.6491241830065,0.00025370340306410486,25.0,60.0
666.89771,0.11977013582677165,940.914274509804,0.00025370340306410486,25.0,60.0
668.39917,0.12013076771653543,941.432026143791,0.00025370340306410486,25.0,60.0
669.90063,0.1205415,941.8886535947713,0.00025370340306410486,25.0,60.0
671.4021,0.12093608858267715,941.7884444444445,0.00025370340306410486,25.0,60.0
672.90356,0.12131251181102364,941.7604183006537,0.00025370340306410486,25.0,60.0
674.40503,0.12163948031496062,938.8763137254903,0.00025370340306410486,25.0,60.0
675.90649,0.1220004409448819,941.7279477124183,0.00025370340306410486,25.0,60.0
677.40796,0.12240175196850393,941.9660130718955,0.00025370340306410486,25.0,60.0
678.90942,0.12280029330708661,942.8646535947713,0.00025370340306410486,25.0,60.0
680.41089,0.12322651377952755,943.9018562091503,0.00025370340306410486,25.0,60.0
681.91235,0.12362846850393701,944.4794771241831,0.00025370340306410486,25.0,60.0
683.41382,0.12406482677165354,943.177411764706,0.00025370340306410486,25.0,60.0
684.91528,0.12445380511811024,943.3168627450981,0.00025370340306410486,25.0,60.0
686.41675,0.12490072440944881,945.1169934640524,0.00025370340306410486,25.0,60.0
687.91821,0.1252932342519685,942.4272941176471,0.00025370340306410486,25.0,60.0
689.41968,0.12567392913385828,944.999477124183,0.00025370340306410486,25.0,60.0
690.92114,0.12609011811023624,945.2810980392159,0.00025370340306410486,25.0,60.0
692.42261,0.12652445669291337,943.8865359477124,0.00025370340306410486,25.0,60.0
693.92407,0.1269609783464567,944.6569150326798,0.00025370340306410486,25.0,60.0
695.42554,0.127356,945.3812549019608,0.00025370340306410486,25.0,60.0
696.927,0.1277392066929134,945.6644967320262,0.00025370340306410486,25.0,60.0
698.42847,0.1282022342519685,946.7555816993464,0.00025370340306410486,25.0,60.0
699.92993,0.12860561023622047,946.3706928104576,0.00025370340306410486,25.0,60.0
701.4314,0.12901926377952755,944.8574640522877,0.00025370340306410486,25.0,60.0
702.93286,0.12943492322834646,947.250954248366,0.00025370340306410486,25.0,60.0
704.43433,0.1298798937007874,946.9231895424838,0.00025370340306410486,25.0,60.0
705.93579,0.1302673248031496,947.4782222222224,0.00025370340306410486,25.0,60.0
707.43726,0.13067673031496063,946.0021699346405,0.00025370340306410486,25.0,60.0
708.93872,0.13107313582677166,946.3615163398694,0.00025370340306410486,25.0,60.0
710.44019,0.13140126771653543,946.2130980392158,0.00025370340306410486,25.0,60.0
711.94165,0.13177379527559055,947.2455947712418,0.00025370340306410486,25.0,60.0
713.44312,0.13217097637795275,947.8684183006537,0.00025370340306410486,25.0,60.0
714.94458,0.1325847125984252,949.7541437908498,0.00025370340306410486,25.0,60.0
716.44604,0.1330993070866142,948.6929411764706,0.00025370340306410486,25.0,60.0
717.94751,0.13352051771653545,950.0231633986929,0.00025370340306410486,25.0,60.0
719.44897,0.13398030708661418,949.6251503267976,0.00025370340306410486,25.0,60.0
720.95044,0.13438155708661417,948.6372810457517,0.00025370340306410486,25.0,60.0
722.4519,0.1347768720472441,949.2957385620915,0.00025370340306410486,25.0,60.0
723.95337,0.13521523622047243,947.9851503267975,0.00025370340306410486,25.0,60.0
725.45483,0.13566688385826772,949.1397385620916,0.00025370340306410486,25.0,60.0
726.9563,0.1360452086614173,948.5631895424837,0.00025370340306410486,25.0,60.0
728.45776,0.13646873031496062,951.1291764705884,0.00025370340306410486,25.0,60.0
729.95923,0.13701072047244095,951.2073725490196,0.00025370340306410486,25.0,60.0
731.46069,0.1374383720472441,949.6918954248366,0.00025370340306410486,25.0,60.0
732.96216,0.13783005118110236,949.2392941176471,0.00025370340306410486,25.0,60.0
734.46362,0.13823442322834645,951.4543790849674,0.00025370340306410486,25.0,60.0
735.96509,0.13862053937007873,951.2487843137257,0.00025370340306410486,25.0,60.0
737.46655,0.13906628346456693,951.7833464052288,0.00025370340306410486,25.0,60.0
738.96802,0.13950668897637794,951.6088366013073,0.00025370340306410486,25.0,60.0
740.46948,0.1398973464566929,949.6045751633989,0.00025370340306410486,25.0,60.0
741.97095,0.14040092322834646,953.4729934640524,0.00025370340306410486,25.0,60.0
743.47241,0.14090004133858267,950.6190065359477,0.00025370340306410486,25.0,60.0
744.97388,0.14129080314960632,951.2900130718955,0.00025370340306410486,25.0,60.0
746.47534,0.14169856692913385,950.5856732026145,0.00025370340306410486,25.0,60.0
747.97681,0.14205163188976377,951.7317124183007,0.00025370340306410486,25.0,60.0
749.47827,0.14246488582677164,951.3885751633987,0.00025370340306410486,25.0,60.0
750.97974,0.14292039173228346,953.2410980392157,0.00025370340306410486,25.0,60.0
752.4812,0.14337268307086615,952.1398954248367,0.00025370340306410486,25.0,60.0
753.98267,0.14383074803149606,953.0545359477125,0.00025370340306410486,25.0,60.0
755.48413,0.144276281496063,953.0917385620916,0.00025370340306410486,25.0,60.0
756.9856,0.14476715157480313,955.4953725490196,0.00025370340306410486,25.0,60.0
758.48706,0.14520813188976378,952.1763398692812,0.00025370340306410486,25.0,60.0
759.98853,0.1457097381889764,954.6576993464054,0.00025370340306410486,25.0,60.0
761.48999,0.146144968503937,953.0541437908497,0.00025370340306410486,25.0,60.0
762.99146,0.14657043897637795,953.782431372549,0.00025370340306410486,25.0,60.0
764.49292,0.14696689173228344,952.1828496732027,0.00025370340306410486,25.0,60.0
765.99438,0.14733795275590553,952.903137254902,0.00025370340306410486,25.0,60.0
767.49585,0.14776931299212598,953.6909542483661,0.00025370340306410486,25.0,60.0
768.99731,0.14830547244094486,955.0643398692811,0.00025370340306410486,25.0,60.0
770.49878,0.14881817913385825,954.5593986928105,0.00025370340306410486,25.0,60.0
772.00024,0.1492960255905512,953.3983006535949,0.00025370340306410486,25.0,60.0
773.50171,0.1497083287401575,954.384522875817,0.00025370340306410486,25.0,60.0
775.00317,0.15013092322834645,954.9648888888889,0.00025370340306410486,25.0,60.0
776.50464,0.15060068503937007,954.8261437908498,0.00025370340306410486,25.0,60.0
778.0061,0.15104566732283464,956.4043921568627,0.00025370340306410486,25.0,60.0
779.50757,0.1514851220472441,954.0711895424837,0.00025370340306410486,25.0,60.0
781.00903,0.1519010531496063,954.2204705882355,0.00025370340306410486,25.0,60.0
782.5105,0.15232158267716533,956.5106666666667,0.00025370340306410486,25.0,60.0
784.01196,0.15277015354330709,955.2839738562093,0.00025370340306410486,25.0,60.0
785.51343,0.1532158405511811,955.9235816993465,0.00025370340306410486,25.0,60.0
787.01489,0.1537270905511811,957.8296732026145,0.00025370340306410486,25.0,60.0
788.51636,0.1542497933070866,956.036183006536,0.00025370340306410486,25.0,60.0
790.01782,0.15472319094488188,956.9579869281047,0.00025370340306410486,25.0,60.0
791.51929,0.15525329724409448,956.2934640522877,0.00025370340306410486,25.0,60.0
793.02075,0.15563671456692912,954.4013071895425,0.00025370340306410486,25.0,60.0
794.52222,0.15604525393700788,956.5193464052288,0.00025370340306410486,25.0,60.0
796.02368,0.15651352559055118,956.6914248366014,0.00025370340306410486,25.0,60.0
797.52515,0.1570464586614173,957.7840261437909,0.00025370340306410486,25.0,60.0
799.02661,0.15756564173228346,958.3120784313727,0.00025370340306410486,25.0,60.0
800.52808,0.1580830275590551,958.6476078431373,0.00025370340306410486,25.0,60.0
802.02954,0.15858727362204725,957.4550065359479,0.00025370340306410486,25.0,60.0
803.53101,0.15902825393700787,956.1298823529413,0.00025370340306410486,25.0,60.0
805.03247,0.15950950393700786,958.035137254902,0.00025370340306410486,25.0,60.0
806.53394,0.1599204468503937,957.382431372549,0.00025370340306410486,25.0,60.0
808.0354,0.16042036417322836,958.7557385620916,0.00025370340306410486,25.0,60.0
809.53687,0.1609629409448819,958.6284183006537,0.00025370340306410486,25.0,60.0
811.03833,0.16148584251968504,958.6467189542484,0.00025370340306410486,25.0,60.0
812.53979,0.16192998031496061,955.5151633986928,0.00025370340306410486,25.0,60.0
814.04126,0.16233806102362203,957.5530457516342,0.00025370340306410486,25.0,60.0
815.54272,0.1628024251968504,959.5250457516341,0.00025370340306410486,25.0,60.0
817.04419,0.1632933188976378,958.8843660130719,0.00025370340306410486,25.0,60.0
818.54565,0.16383954527559055,958.7230065359478,0.00025370340306410486,25.0,60.0
820.04712,0.1643383366141732,956.8097777777779,0.00025370340306410486,25.0,60.0
821.54858,0.1648272224409449,957.8460130718955,0.00025370340306410486,25.0,60.0
823.05005,0.16531342322834647,957.3707450980393,0.00025370340306410486,25.0,60.0
824.55151,0.1658305413385827,959.6015947712418,0.00025370340306410486,25.0,60.0
826.05298,0.16636113976377953,957.8209150326797,0.00025370340306410486,25.0,60.0
827.55444,0.1668690334645669,959.1166797385621,0.00025370340306410486,25.0,60.0
829.05591,0.1674102165354331,958.7734901960785,0.00025370340306410486,25.0,60.0
830.55737,0.16796572440944882,960.1051764705884,0.00025370340306410486,25.0,60.0
832.05884,0.16851253937007873,957.9963137254903,0.00025370340306410486,25.0,60.0
833.5603,0.16900660039370077,959.7357647058825,0.00025370340306410486,25.0,60.0
835.06177,0.169499968503937,959.704549019608,0.00025370340306410486,25.0,60.0
836.56323,0.16998870472440947,960.3437647058823,0.00025370340306410486,25.0,60.0
838.0647,0.1704686968503937,959.1627712418301,0.00025370340306410486,25.0,60.0
839.56616,0.17094598031496064,960.6462483660132,0.00025370340306410486,25.0,60.0
841.06763,0.1714934153543307,960.0584575163399,0.00025370340306410486,25.0,60.0
842.56909,0.17194886417322836,958.305385620915,0.00025370340306410486,25.0,60.0
844.07056,0.17252340354330709,960.529071895425,0.00025370340306410486,25.0,60.0
845.57202,0.1730655,959.4632156862746,0.00025370340306410486,25.0,60.0
847.07349,0.1736256909448819,958.902614379085,0.00025370340306410486,25.0,60.0
848.57495,0.1741568996062992,960.3886535947713,0.00025370340306410486,25.0,60.0
850.07642,0.17467717322834644,960.1778300653594,0.00025370340306410486,25.0,60.0
851.57788,0.17523618897637794,960.3169673202615,0.00025370340306410486,25.0,60.0
853.07935,0.1757177086614173,959.6504836601308,0.00025370340306410486,25.0,60.0
854.58081,0.17616091732283465,959.4563137254903,0.00025370340306410486,25.0,60.0
856.08228,0.17665008661417322,959.1177777777779,0.00025370340306410486,25.0,60.0
857.58374,0.17715588188976378,960.283137254902,0.00025370340306410486,25.0,60.0
859.08521,0.17770649606299213,960.050614379085,0.00025370340306410486,25.0,60.0
860.58667,0.17821420275590552,960.5755294117647,0.00025370340306410486,25.0,60.0
862.08813,0.17873393700787402,959.6113464052288,0.00025370340306410486,25.0,60.0
863.5896,0.17930481692913386,961.4853333333334,0.00025370340306410486,25.0,60.0
865.09106,0.17990867716535433,959.8815947712418,0.00025370340306410486,25.0,60.0
866.59253,0.18047649409448818,960.3755555555556,0.00025370340306410486,25.0,60.0
868.09399,0.18104525984251968,960.2520522875818,0.00025370340306410486,25.0,60.0
869.59546,0.18150061417322833,959.590614379085,0.00025370340306410486,25.0,60.0
871.09692,0.18203488582677166,962.0084705882354,0.00025370340306410486,25.0,60.0
872.59839,0.18262206102362205,961.618091503268,0.00025370340306410486,25.0,60.0
874.09985,0.18328864763779526,961.7310065359477,0.00025370340306410486,25.0,60.0
875.60132,0.18391674803149607,961.6910588235295,0.00025370340306410486,25.0,60.0
877.10278,0.18446241338582678,959.2062483660131,0.00025370340306410486,25.0,60.0
878.60425,0.18501650196850392,960.0852810457517,0.00025370340306410486,25.0,60.0
880.10571,0.18565232283464567,960.5570980392158,0.00025370340306410486,25.0,60.0
881.60718,0.18621300590551182,961.3956601307191,0.00025370340306410486,25.0,60.0
883.10864,0.186864468503937,963.4125490196079,0.00025370340306410486,25.0,60.0