File: datasets/am_bench_2022/csv/60-XY.04-3.csv
Time(s),Strain(%),Stress(MPa),SR(s-1),Temp(C),Angle(deg)
17.014893,5.5563015748031495e-06,15.098820691434469,0.00025370340306410486,25.0,60.0
19.217041,2.549082283464567e-05,22.367973426212593,0.00025370340306410486,25.0,60.0
20.618408,2.8939281496062993e-05,26.685054179566563,0.00025370340306410486,25.0,60.0
22.019775,5.829656496062991e-05,30.39877450980392,0.00025370340306410486,25.0,60.0
23.421143,6.220643503937008e-05,34.91361713106295,0.00025370340306410486,25.0,60.0
24.82251,8.90144842519685e-05,38.05394478844169,0.00025370340306410486,25.0,60.0
26.223877,0.0001051514625984252,45.44557791537668,0.00025370340306410486,25.0,60.0
27.625244,0.00015371243110236222,49.877391640866875,0.00025370340306410486,25.0,60.0
29.026611,0.00014691070472440943,55.06567079463365,0.00025370340306410486,25.0,60.0
30.427979,0.0001673925374015748,60.12148348813209,0.00025370340306410486,25.0,60.0
31.829346,0.00021544612204724408,67.47363261093912,0.00025370340306410486,25.0,60.0
33.230713,0.00022535812992125983,73.52650670794634,0.00025370340306410486,25.0,60.0
34.63208,0.00026132496062992127,82.43012125902993,0.00025370340306410486,25.0,60.0
36.033447,0.00030210753937007874,89.05005675954594,0.00025370340306410486,25.0,60.0
37.434814,0.0002867893307086614,94.89405572755419,0.00025370340306410486,25.0,60.0
38.836182,0.00032941167322834644,103.31870227038183,0.00025370340306410486,25.0,60.0
40.237549,0.00034437659448818895,112.24568369453046,0.00025370340306410486,25.0,60.0
41.638916,0.0003777599015748031,120.97905830753353,0.00025370340306410486,25.0,60.0
43.040283,0.00042055405511811023,129.59795149638802,0.00025370340306410486,25.0,60.0
44.44165,0.00043838665354330706,139.78225490196078,0.00025370340306410486,25.0,60.0
45.843018,0.0004433258070866142,146.80408410732713,0.00025370340306410486,25.0,60.0
47.244385,0.00050272,156.47307017543858,0.00025370340306410486,25.0,60.0
48.645752,0.0005291491141732283,165.35560629514964,0.00025370340306410486,25.0,60.0
50.047119,0.0005496630118110237,174.27973168214655,0.00025370340306410486,25.0,60.0
51.448486,0.0005742914960629921,183.99832043343653,0.00025370340306410486,25.0,60.0
52.849854,0.0006252264566929134,193.54479618163055,0.00025370340306410486,25.0,60.0
54.251221,0.0006576966141732284,202.33732198142414,0.00025370340306410486,25.0,60.0
55.652588,0.0006915629330708662,214.79773735810113,0.00025370340306410486,25.0,60.0
57.053955,0.0007195849606299213,223.89342363261096,0.00025370340306410486,25.0,60.0
58.455322,0.0007356517913385827,232.17918214654284,0.00025370340306410486,25.0,60.0
59.856689,0.0007754042322834646,243.128459752322,0.00025370340306410486,25.0,60.0
61.258057,0.0008005120866141732,250.790544375645,0.00025370340306410486,25.0,60.0
62.659424,0.0008465901771653544,262.7465170278638,0.00025370340306410486,25.0,60.0
64.060791,0.0008788213779527559,274.8204334365325,0.00025370340306410486,25.0,60.0
65.462158,0.000906647657480315,283.4417440660475,0.00025370340306410486,25.0,60.0
66.863525,0.0009561999803149605,294.14205366357066,0.00025370340306410486,25.0,60.0
68.264893,0.0009791618503937009,302.834391124871,0.00025370340306410486,25.0,60.0
69.66626,0.001022933090551181,312.95250257997935,0.00025370340306410486,25.0,60.0
71.067627,0.0010158637401574803,320.8325851393189,0.00025370340306410486,25.0,60.0
72.468994,0.0010844988385826772,333.3314499484004,0.00025370340306410486,25.0,60.0
73.870361,0.0011086741732283464,343.20092879256964,0.00025370340306410486,25.0,60.0
75.271729,0.00114795718503937,353.625,0.00025370340306410486,25.0,60.0
76.673096,0.001173213346456693,364.3240712074304,0.00025370340306410486,25.0,60.0
78.074463,0.0012283597440944881,374.59419504643967,0.00025370340306410486,25.0,60.0
79.47583,0.0012551460039370078,385.91235810113517,0.00025370340306410486,25.0,60.0
80.877197,0.001288078346456693,394.84891640866874,0.00025370340306410486,25.0,60.0
82.278564,0.001326268346456693,404.60381836945305,0.00025370340306410486,25.0,60.0
83.679932,0.0013563280511811025,412.1666408668731,0.00025370340306410486,25.0,60.0
85.081299,0.001360770905511811,422.2009803921569,0.00025370340306410486,25.0,60.0
86.482666,0.001419072244094488,433.66808565531477,0.00025370340306410486,25.0,60.0
87.884033,0.0014464935629921259,445.1418988648091,0.00025370340306410486,25.0,60.0
89.2854,0.0014885909842519685,456.11984004127964,0.00025370340306410486,25.0,60.0
90.686768,0.001530388937007874,465.110036119711,0.00025370340306410486,25.0,60.0
92.088135,0.0015515465551181101,473.5033797729618,0.00025370340306410486,25.0,60.0
93.489502,0.0016138480118110235,486.72621259029927,0.00025370340306410486,25.0,60.0
94.890869,0.001617880374015748,492.28818369453046,0.00025370340306410486,25.0,60.0
96.292236,0.0016811949212598425,503.24618163054697,0.00025370340306410486,25.0,60.0
97.693604,0.0017000045078740158,511.0389834881321,0.00025370340306410486,25.0,60.0
99.094971,0.0017408191732283464,520.3903766769866,0.00025370340306410486,25.0,60.0
100.49634,0.0017535999212598425,526.7330237358101,0.00025370340306410486,25.0,60.0
101.89771,0.0017881758267716534,536.5853715170279,0.00025370340306410486,25.0,60.0
103.29907,0.0018142622047244094,544.9136738906088,0.00025370340306410486,25.0,60.0
104.70044,0.0018317914173228346,551.5737616099071,0.00025370340306410486,25.0,60.0
106.10181,0.0018707025590551183,559.1854489164086,0.00025370340306410486,25.0,60.0
107.50317,0.0019006121259842518,565.9169504643962,0.00025370340306410486,25.0,60.0
108.90454,0.0019211292716535431,573.9240970072238,0.00025370340306410486,25.0,60.0
110.30591,0.0019589378543307086,580.0234520123839,0.00025370340306410486,25.0,60.0
111.70728,0.0019935872047244095,584.6454334365326,0.00025370340306410486,25.0,60.0
113.10864,0.001986578346456693,592.3958204334366,0.00025370340306410486,25.0,60.0
114.51001,0.002010752755905512,596.9651444788441,0.00025370340306410486,25.0,60.0
115.91138,0.002061359448818898,602.3082817337461,0.00025370340306410486,25.0,60.0
117.31274,0.0020650515748031496,608.1827657378742,0.00025370340306410486,25.0,60.0
118.71411,0.0020833720472440945,613.6388286893705,0.00025370340306410486,25.0,60.0
120.11548,0.002114577165354331,618.4345975232197,0.00025370340306410486,25.0,60.0
121.51685,0.002150051968503937,625.4029411764706,0.00025370340306410486,25.0,60.0
122.91821,0.0021645427165354328,631.5534313725491,0.00025370340306410486,25.0,60.0
124.31958,0.0021849442913385825,636.1136222910217,0.00025370340306410486,25.0,60.0
125.72095,0.0022129332677165354,638.8386738906089,0.00025370340306410486,25.0,60.0
127.12231,0.002275338188976378,644.7993292053665,0.00025370340306410486,25.0,60.0
128.52368,0.0022771783464566927,648.7772445820434,0.00025370340306410486,25.0,60.0
129.92505,0.0022938041338582678,652.1852683178535,0.00025370340306410486,25.0,60.0
131.32642,0.00231773562992126,657.162951496388,0.00025370340306410486,25.0,60.0
132.72778,0.0023479769685039367,659.9686016511869,0.00025370340306410486,25.0,60.0
134.12915,0.002381639960629921,665.9511351909185,0.00025370340306410486,25.0,60.0
135.53052,0.002408898031496063,666.8883126934985,0.00025370340306410486,25.0,60.0
136.93188,0.002425044881889764,668.363802889577,0.00025370340306410486,25.0,60.0
138.33325,0.0024840681102362206,674.3438596491228,0.00025370340306410486,25.0,60.0
139.73462,0.0025077151574803146,679.9141898864809,0.00025370340306410486,25.0,60.0
141.13599,0.00255051811023622,681.1512125902993,0.00025370340306410486,25.0,60.0
142.53735,0.0025885450787401574,685.7282765737874,0.00025370340306410486,25.0,60.0
143.93872,0.002625513779527559,688.6380546955625,0.00025370340306410486,25.0,60.0
145.34009,0.002648312992125984,689.8820691434469,0.00025370340306410486,25.0,60.0
146.74146,0.002724974409448819,695.5410732714138,0.00025370340306410486,25.0,60.0
148.14282,0.0027712856299212598,697.5564499484004,0.00025370340306410486,25.0,60.0
149.54419,0.002811400393700787,700.6677760577916,0.00025370340306410486,25.0,60.0
150.94556,0.002860863976377953,704.5358617131063,0.00025370340306410486,25.0,60.0
152.34692,0.0029452956692913386,706.2478070175438,0.00025370340306410486,25.0,60.0
153.74829,0.0030136673228346456,707.3086429308565,0.00025370340306410486,25.0,60.0
155.14966,0.0030791848425196847,711.1753353973169,0.00025370340306410486,25.0,60.0
156.55103,0.0031779616141732283,715.0979618163055,0.00025370340306410486,25.0,60.0
157.95239,0.0032864594488188977,716.6521929824562,0.00025370340306410486,25.0,60.0
159.35376,0.003389615157480315,719.8835397316822,0.00025370340306410486,25.0,60.0
160.75513,0.0034856224409448816,721.2850103199174,0.00025370340306410486,25.0,60.0
162.15649,0.0036319043307086614,723.00608875129,0.00025370340306410486,25.0,60.0
163.55786,0.003776881496062992,728.3547471620227,0.00025370340306410486,25.0,60.0
164.95923,0.0039059118110236217,730.7876676986584,0.00025370340306410486,25.0,60.0
166.3606,0.004061759448818898,731.8823271413829,0.00025370340306410486,25.0,60.0
167.76196,0.004251029921259843,734.5440660474716,0.00025370340306410486,25.0,60.0
169.16333,0.004396404921259842,735.6996388028897,0.00025370340306410486,25.0,60.0
170.5647,0.004594810433070866,738.7663312693498,0.00025370340306410486,25.0,60.0
171.96606,0.00478473031496063,739.1501547987616,0.00025370340306410486,25.0,60.0
173.36743,0.004973832677165354,740.3163312693499,0.00025370340306410486,25.0,60.0
174.7688,0.005158176574803149,743.4097265221878,0.00025370340306410486,25.0,60.0
176.17017,0.005368962007874016,743.5884674922601,0.00025370340306410486,25.0,60.0
177.57153,0.005577037598425197,746.5954592363262,0.00025370340306410486,25.0,60.0
178.9729,0.005828339173228347,750.0267027863778,0.00025370340306410486,25.0,60.0
180.37427,0.006049182480314961,748.1096749226007,0.00025370340306410486,25.0,60.0
181.77563,0.006308163779527558,752.1378740970073,0.00025370340306410486,25.0,60.0
183.177,0.006542232283464567,752.3416924664602,0.00025370340306410486,25.0,60.0
184.57837,0.006750201181102361,753.0691434468525,0.00025370340306410486,25.0,60.0
185.97974,0.007021567125984252,754.8265737874098,0.00025370340306410486,25.0,60.0
187.3811,0.0072541192913385824,754.7278121775025,0.00025370340306410486,25.0,60.0
188.78247,0.007492961614173227,755.1717492260062,0.00025370340306410486,25.0,60.0
190.18384,0.0077293218503937,758.3688596491228,0.00025370340306410486,25.0,60.0
191.58521,0.007957322047244095,760.6889576883385,0.00025370340306410486,25.0,60.0
192.98657,0.008289293700787402,762.7504385964913,0.00025370340306410486,25.0,60.0
194.38794,0.008572060826771654,763.0780185758514,0.00025370340306410486,25.0,60.0
195.78931,0.008881822440944882,763.485629514964,0.00025370340306410486,25.0,60.0
197.19067,0.009133968897637795,765.1339525283798,0.00025370340306410486,25.0,60.0
198.59204,0.009427377952755906,765.0550309597523,0.00025370340306410486,25.0,60.0
199.99341,0.009701075393700787,766.8738648090815,0.00025370340306410486,25.0,60.0
201.39478,0.0099375718503937,766.6203302373581,0.00025370340306410486,25.0,60.0
202.79614,0.010237773818897638,768.0184726522187,0.00025370340306410486,25.0,60.0
204.19751,0.010548427952755906,770.4100619195046,0.00025370340306410486,25.0,60.0
205.59888,0.010808189173228346,771.430959752322,0.00025370340306410486,25.0,60.0
207.00024,0.011115197047244094,772.070794633643,0.00025370340306410486,25.0,60.0
208.40161,0.01142258562992126,773.2244066047472,0.00025370340306410486,25.0,60.0
209.80298,0.011731771456692913,774.8953560371517,0.00025370340306410486,25.0,60.0
211.20435,0.012063783661417323,776.8763157894737,0.00025370340306410486,25.0,60.0
212.60571,0.01234932716535433,775.2156346749226,0.00025370340306410486,25.0,60.0
214.00708,0.012592175,777.8131320949433,0.00025370340306410486,25.0,60.0
215.40845,0.01284787657480315,776.8237874097008,0.00025370340306410486,25.0,60.0
216.80981,0.013138176377952756,780.0297471620228,0.00025370340306410486,25.0,60.0
218.21118,0.013478601968503937,780.9266769865841,0.00025370340306410486,25.0,60.0
219.61255,0.01373005157480315,778.227399380805,0.00025370340306410486,25.0,60.0
221.01392,0.013983697047244096,782.3947368421052,0.00025370340306410486,25.0,60.0
222.41528,0.014295604921259843,783.4432920536636,0.00025370340306410486,25.0,60.0
223.81665,0.014620406299212598,783.1965686274509,0.00025370340306410486,25.0,60.0
225.21802,0.014910506692913387,783.2106811145511,0.00025370340306410486,25.0,60.0
226.61938,0.015220950984251967,786.3943498452013,0.00025370340306410486,25.0,60.0
228.02075,0.01557149940944882,787.2913570691435,0.00025370340306410486,25.0,60.0
229.42212,0.015852437598425195,786.0096749226007,0.00025370340306410486,25.0,60.0
230.82349,0.016175313188976376,787.5327141382869,0.00025370340306410486,25.0,60.0
232.22485,0.016506789173228346,789.1855263157895,0.00025370340306410486,25.0,60.0
233.62622,0.016844205118110238,790.3061403508772,0.00025370340306410486,25.0,60.0
235.02759,0.01715849940944882,788.9519607843138,0.00025370340306410486,25.0,60.0
236.42896,0.01741728248031496,790.4089267285862,0.00025370340306410486,25.0,60.0
237.83032,0.01774949035433071,792.4896542827657,0.00025370340306410486,25.0,60.0
239.23169,0.018111664763779525,794.1687306501548,0.00025370340306410486,25.0,60.0
240.63306,0.01841002834645669,793.9705624355006,0.00025370340306410486,25.0,60.0
242.03442,0.018722033070866142,793.2193240454076,0.00025370340306410486,25.0,60.0
243.43579,0.019012073228346457,794.9168988648091,0.00025370340306410486,25.0,60.0
244.83716,0.01932040846456693,795.9610423116616,0.00025370340306410486,25.0,60.0
246.23853,0.01961578307086614,795.7515479876162,0.00025370340306410486,25.0,60.0
247.63989,0.019896911417322836,797.1021929824561,0.00025370340306410486,25.0,60.0
249.04126,0.020247159448818896,798.8514963880289,0.00025370340306410486,25.0,60.0
250.44263,0.020539037401574804,797.5942466460268,0.00025370340306410486,25.0,60.0
251.84399,0.02080546456692913,800.0678534571724,0.00025370340306410486,25.0,60.0
253.24536,0.021108023622047244,801.8127966976264,0.00025370340306410486,25.0,60.0
254.64673,0.02143962007874016,801.6660474716202,0.00025370340306410486,25.0,60.0
256.0481,0.02178530905511811,800.1961558307534,0.00025370340306410486,25.0,60.0
257.44946,0.022067757874015746,801.5644994840042,0.00025370340306410486,25.0,60.0
258.85083,0.022389714566929134,804.9660216718266,0.00025370340306410486,25.0,60.0
260.2522,0.022746466535433073,805.2871517027864,0.00025370340306410486,25.0,60.0
261.65356,0.023097612204724408,806.8617131062953,0.00025370340306410486,25.0,60.0
263.05493,0.023405962598425194,805.828895768834,0.00025370340306410486,25.0,60.0
264.4563,0.023742403543307086,805.824613003096,0.00025370340306410486,25.0,60.0
265.85767,0.024012476377952757,806.6133384932921,0.00025370340306410486,25.0,60.0
267.25903,0.02433336220472441,806.5544633642932,0.00025370340306410486,25.0,60.0
268.6604,0.024641342519685038,806.2550051599588,0.00025370340306410486,25.0,60.0
270.06177,0.024933403543307087,809.7496904024769,0.00025370340306410486,25.0,60.0
271.46313,0.025298757874015747,810.6689370485036,0.00025370340306410486,25.0,60.0
272.8645,0.025612375984251964,810.720665634675,0.00025370340306410486,25.0,60.0
274.26587,0.025916246062992122,809.5619453044376,0.00025370340306410486,25.0,60.0
275.66724,0.026214437007874014,810.2656862745099,0.00025370340306410486,25.0,60.0
277.0686,0.02652090748031496,812.7911248710011,0.00025370340306410486,25.0,60.0
278.46997,0.02682858070866142,812.8627450980392,0.00025370340306410486,25.0,60.0
279.87134,0.02713517913385827,812.690608875129,0.00025370340306410486,25.0,60.0
281.27271,0.027488834645669293,813.9176728586172,0.00025370340306410486,25.0,60.0
282.67407,0.02781962007874016,814.3561145510837,0.00025370340306410486,25.0,60.0
284.07544,0.028126096456692916,814.6816563467493,0.00025370340306410486,25.0,60.0
285.47681,0.02844280905511811,817.2039215686275,0.00025370340306410486,25.0,60.0
286.87817,0.02867456496062992,815.5864551083591,0.00025370340306410486,25.0,60.0
288.27954,0.028963881889763777,817.0162280701754,0.00025370340306410486,25.0,60.0
289.68091,0.029296000000000003,820.2997678018577,0.00025370340306410486,25.0,60.0
291.08228,0.029628322834645667,818.2254643962848,0.00025370340306410486,25.0,60.0
292.48364,0.029975173228346457,819.624226006192,0.00025370340306410486,25.0,60.0
293.88501,0.030234100393700787,818.1495614035088,0.00025370340306410486,25.0,60.0
295.28638,0.03056198622047244,818.9502579979361,0.00025370340306410486,25.0,60.0
296.68774,0.030830883858267717,820.580572755418,0.00025370340306410486,25.0,60.0
298.08911,0.03117680118110236,822.3707430340557,0.00025370340306410486,25.0,60.0
299.49048,0.031499675196850395,822.1557791537668,0.00025370340306410486,25.0,60.0
300.89185,0.03182111614173229,822.0439628482973,0.00025370340306410486,25.0,60.0
302.29321,0.032133893700787404,824.6097781217751,0.00025370340306410486,25.0,60.0
303.69458,0.03251556889763779,826.732714138287,0.00025370340306410486,25.0,60.0
305.09595,0.032890374015748035,825.9599845201238,0.00025370340306410486,25.0,60.0
306.49731,0.03320082283464567,825.277012383901,0.00025370340306410486,25.0,60.0
307.89868,0.033480809055118105,824.705959752322,0.00025370340306410486,25.0,60.0
309.30005,0.033747204724409445,825.4000773993808,0.00025370340306410486,25.0,60.0
310.70142,0.03412469488188976,829.2649638802891,0.00025370340306410486,25.0,60.0
312.10278,0.03447368897637795,826.8522187822497,0.00025370340306410486,25.0,60.0
313.50415,0.03476070078740157,826.8379772961816,0.00025370340306410486,25.0,60.0
314.90552,0.03503540551181102,828.5369453044376,0.00025370340306410486,25.0,60.0
316.30688,0.03536791141732283,829.7704850361197,0.00025370340306410486,25.0,60.0
317.70825,0.035678618110236225,831.3633900928793,0.00025370340306410486,25.0,60.0
319.10962,0.035943572834645665,829.3824303405572,0.00025370340306410486,25.0,60.0
320.51099,0.03630247637795275,833.4327399380805,0.00025370340306410486,25.0,60.0
321.91235,0.03664018307086614,831.5292311661508,0.00025370340306410486,25.0,60.0
323.31372,0.03692821850393701,832.7586429308566,0.00025370340306410486,25.0,60.0
324.71509,0.037249135826771654,833.5546697626419,0.00025370340306410486,25.0,60.0
326.11646,0.03753675,832.0985294117647,0.00025370340306410486,25.0,60.0
327.51782,0.037853925196850394,834.4848039215686,0.00025370340306410486,25.0,60.0
328.91919,0.038163537401574806,835.7273735810114,0.00025370340306410486,25.0,60.0
330.32056,0.038536480314960625,834.9210010319918,0.00025370340306410486,25.0,60.0
331.72192,0.03884627165354331,833.917492260062,0.00025370340306410486,25.0,60.0
333.12329,0.03915905118110236,834.3677244582044,0.00025370340306410486,25.0,60.0
334.52466,0.03948994488188976,837.6515221878225,0.00025370340306410486,25.0,60.0
335.92603,0.03979091929133858,836.3173890608875,0.00025370340306410486,25.0,60.0
337.32739,0.04006511811023622,837.9543085655315,0.00025370340306410486,25.0,60.0
338.72876,0.04042862401574803,840.0300051599587,0.00025370340306410486,25.0,60.0
340.13013,0.040765490157480315,837.7522961816305,0.00025370340306410486,25.0,60.0
341.53149,0.041098322834645665,840.9448400412797,0.00025370340306410486,25.0,60.0
342.93286,0.041460072834645666,842.2351393188854,0.00025370340306410486,25.0,60.0
344.33423,0.041717915354330705,840.3893446852425,0.00025370340306410486,25.0,60.0
345.7356,0.04204685039370079,842.8613777089784,0.00025370340306410486,25.0,60.0
347.13696,0.04235491929133858,843.9576109391126,0.00025370340306410486,25.0,60.0
348.53833,0.042682472440944884,843.1001031991744,0.00025370340306410486,25.0,60.0
349.9397,0.04297237992125984,842.1149122807018,0.00025370340306410486,25.0,60.0
351.34106,0.04330781692913386,846.3906346749226,0.00025370340306410486,25.0,60.0
352.74243,0.043666299212598424,845.6467492260062,0.00025370340306410486,25.0,60.0
354.1438,0.04397233858267716,845.5887512899897,0.00025370340306410486,25.0,60.0
355.54517,0.04428132283464567,844.2727296181631,0.00025370340306410486,25.0,60.0
356.94653,0.04460756496062992,846.2199948400413,0.00025370340306410486,25.0,60.0
358.3479,0.04491369291338583,846.3949174406605,0.00025370340306410486,25.0,60.0
359.74927,0.04521277559055118,846.6973942208463,0.00025370340306410486,25.0,60.0
361.15063,0.04552874015748031,847.7655314757482,0.00025370340306410486,25.0,60.0
362.552,0.04585318700787402,846.8697884416924,0.00025370340306410486,25.0,60.0
363.95337,0.04611983858267717,848.8029927760577,0.00025370340306410486,25.0,60.0
365.35474,0.04642047834645669,849.7771155830753,0.00025370340306410486,25.0,60.0
366.7561,0.046772474409448817,850.6862229102167,0.00025370340306410486,25.0,60.0
368.15747,0.047083730314960624,850.6934468524253,0.00025370340306410486,25.0,60.0
369.55884,0.04745375393700787,851.513673890609,0.00025370340306410486,25.0,60.0
370.96021,0.047800226377952754,851.5298761609907,0.00025370340306410486,25.0,60.0
372.36157,0.04811455511811023,852.1853973168215,0.00025370340306410486,25.0,60.0
373.76294,0.04847010039370079,852.5434726522188,0.00025370340306410486,25.0,60.0
375.16431,0.048755141732283465,851.7721878224975,0.00025370340306410486,25.0,60.0
376.56567,0.04907338385826771,854.1345459236327,0.00025370340306410486,25.0,60.0
377.96704,0.04938221259842519,854.2651702786378,0.00025370340306410486,25.0,60.0
379.36841,0.049656511811023624,854.2928276573788,0.00025370340306410486,25.0,60.0
380.76978,0.04998687795275591,856.7616357069144,0.00025370340306410486,25.0,60.0
382.17114,0.05031382874015748,856.3335655314758,0.00025370340306410486,25.0,60.0
383.57251,0.05067815748031496,856.7961042311662,0.00025370340306410486,25.0,60.0
384.97388,0.05103499212598425,855.6289215686274,0.00025370340306410486,25.0,60.0
386.37524,0.051314765748031496,856.011016511868,0.00025370340306410486,25.0,60.0
387.77661,0.05162964960629922,856.481475748194,0.00025370340306410486,25.0,60.0
389.17798,0.05198006692913386,858.7846233230134,0.00025370340306410486,25.0,60.0
390.57935,0.05229459842519685,857.7291279669763,0.00025370340306410486,25.0,60.0
391.98071,0.052569312992125986,856.6368679050569,0.00025370340306410486,25.0,60.0
393.38208,0.052877685039370084,858.8594427244582,0.00025370340306410486,25.0,60.0
394.78345,0.0531723248031496,860.0609391124871,0.00025370340306410486,25.0,60.0
396.18481,0.053460157480314956,860.496052631579,0.00025370340306410486,25.0,60.0
397.58618,0.05375119881889763,861.0695046439629,0.00025370340306410486,25.0,60.0
398.98755,0.054102362204724405,861.1482198142415,0.00025370340306410486,25.0,60.0
400.38892,0.054424830708661415,860.5354747162023,0.00025370340306410486,25.0,60.0
401.79028,0.054735789370078745,862.1402992776058,0.00025370340306410486,25.0,60.0
403.19165,0.0550885374015748,865.8392414860682,0.00025370340306410486,25.0,60.0
404.59302,0.05544402362204724,861.7575851393188,0.00025370340306410486,25.0,60.0
405.99438,0.05575322834645669,864.4670020639836,0.00025370340306410486,25.0,60.0
407.39575,0.05610033661417323,863.4092363261094,0.00025370340306410486,25.0,60.0
408.79712,0.05645027952755905,864.1012125902993,0.00025370340306410486,25.0,60.0
410.19849,0.056799923228346455,866.6738906088751,0.00025370340306410486,25.0,60.0
411.59985,0.05714999015748031,865.0936532507741,0.00025370340306410486,25.0,60.0
413.00122,0.057405679133858266,865.4481682146543,0.00025370340306410486,25.0,60.0
414.40259,0.057729293307086614,865.2215944272446,0.00025370340306410486,25.0,60.0
415.80396,0.058005954724409454,866.8137254901961,0.00025370340306410486,25.0,60.0
417.20532,0.05834050393700787,867.9499742002065,0.00025370340306410486,25.0,60.0
418.60669,0.05870277755905511,869.3244324045407,0.00025370340306410486,25.0,60.0
420.00806,0.05900465551181102,867.6316305469556,0.00025370340306410486,25.0,60.0
421.40942,0.059286035433070865,868.4820949432406,0.00025370340306410486,25.0,60.0
422.81079,0.05961035236220472,868.1452270381836,0.00025370340306410486,25.0,60.0
424.21216,0.05991697047244094,869.459649122807,0.00025370340306410486,25.0,60.0
425.61353,0.060250933070866146,870.0803405572756,0.00025370340306410486,25.0,60.0
427.01489,0.06060034251968503,871.3782765737874,0.00025370340306410486,25.0,60.0
428.41626,0.06091832283464567,870.5415376676987,0.00025370340306410486,25.0,60.0
429.81763,0.06119884645669291,871.0618163054696,0.00025370340306410486,25.0,60.0
431.21899,0.06150186811023622,871.858101135191,0.00025370340306410486,25.0,60.0
432.62036,0.06182947047244095,872.704850361197,0.00025370340306410486,25.0,60.0
434.02173,0.0621907657480315,873.8436016511869,0.00025370340306410486,25.0,60.0
435.4231,0.06253611417322834,872.7140350877194,0.00025370340306410486,25.0,60.0
436.82446,0.06288006102362205,873.1189886480907,0.00025370340306410486,25.0,60.0
438.22583,0.06318607480314961,874.3223168214655,0.00025370340306410486,25.0,60.0
439.6272,0.0634588188976378,875.3703560371517,0.00025370340306410486,25.0,60.0
441.02856,0.06376746062992127,874.6510577915377,0.00025370340306410486,25.0,60.0
442.42993,0.06408131102362204,874.5262125902992,0.00025370340306410486,25.0,60.0
443.8313,0.06439652952755906,877.842879256966,0.00025370340306410486,25.0,60.0
445.23267,0.06475875787401575,876.9519349845202,0.00025370340306410486,25.0,60.0
446.63403,0.06510101377952757,878.1413828689371,0.00025370340306410486,25.0,60.0
448.0354,0.06546790551181102,877.6946078431373,0.00025370340306410486,25.0,60.0
449.43677,0.0658070059055118,877.1807017543861,0.00025370340306410486,25.0,60.0
450.83813,0.06615140551181102,879.0785087719299,0.00025370340306410486,25.0,60.0
452.2395,0.06650003346456693,878.1539989680083,0.00025370340306410486,25.0,60.0
453.64087,0.06683697637795274,879.0320433436533,0.00025370340306410486,25.0,60.0
455.04224,0.06717279133858267,882.6302115583076,0.00025370340306410486,25.0,60.0
456.4436,0.06755724212598425,881.6963622291022,0.00025370340306410486,25.0,60.0
457.84497,0.06786669291338582,880.0187306501548,0.00025370340306410486,25.0,60.0
459.24634,0.06810219094488189,879.998968008256,0.00025370340306410486,25.0,60.0
460.64771,0.06839313779527559,881.8201238390093,0.00025370340306410486,25.0,60.0
462.04907,0.06876339763779526,882.4518833849329,0.00025370340306410486,25.0,60.0
463.45044,0.06909883661417322,881.5402734778122,0.00025370340306410486,25.0,60.0
464.85181,0.06940099606299212,883.146826625387,0.00025370340306410486,25.0,60.0
466.25317,0.06969691338582677,883.3809597523219,0.00025370340306410486,25.0,60.0
467.65454,0.07001353346456693,883.6091073271414,0.00025370340306410486,25.0,60.0
469.05591,0.07036443307086615,883.9373323013416,0.00025370340306410486,25.0,60.0
470.45728,0.07065598622047244,884.1388286893705,0.00025370340306410486,25.0,60.0
471.85864,0.07099099212598425,886.2796697626419,0.00025370340306410486,25.0,60.0
473.26001,0.07131749803149606,886.0025283797729,0.00025370340306410486,25.0,60.0
474.66138,0.07163339566929135,886.4110423116616,0.00025370340306410486,25.0,60.0
476.06274,0.0719618031496063,884.5793085655315,0.00025370340306410486,25.0,60.0
477.46411,0.07227456299212598,885.9065273477813,0.00025370340306410486,25.0,60.0
478.86548,0.07264762598425197,888.7006707946337,0.00025370340306410486,25.0,60.0
480.26685,0.07297581496062992,887.3034571723426,0.00025370340306410486,25.0,60.0
481.66821,0.0733508188976378,888.22435500516,0.00025370340306410486,25.0,60.0
483.06958,0.07370146653543308,887.1575335397317,0.00025370340306410486,25.0,60.0
484.47095,0.07402132480314962,888.128173374613,0.00025370340306410486,25.0,60.0
485.87231,0.07434409842519685,889.3882352941176,0.00025370340306410486,25.0,60.0
487.27368,0.07466543700787402,889.7364293085656,0.00025370340306410486,25.0,60.0
488.67505,0.07500483070866142,888.441847265222,0.00025370340306410486,25.0,60.0
490.07642,0.07532660826771653,891.1738648090815,0.00025370340306410486,25.0,60.0
491.47778,0.07567551771653544,890.7924922600619,0.00025370340306410486,25.0,60.0
492.87915,0.07603201377952755,892.6948400412797,0.00025370340306410486,25.0,60.0
494.28052,0.07634110039370079,890.470923632611,0.00025370340306410486,25.0,60.0
495.68188,0.07667053346456693,893.3273735810114,0.00025370340306410486,25.0,60.0
497.08325,0.07704398425196851,890.7541279669763,0.00025370340306410486,25.0,60.0
498.48462,0.07736113779527559,893.1200206398349,0.00025370340306410486,25.0,60.0
499.88599,0.07767442125984252,893.9195820433437,0.00025370340306410486,25.0,60.0
501.28735,0.0779635905511811,893.0013415892673,0.00025370340306410486,25.0,60.0
502.68872,0.0782826220472441,893.8348555211559,0.00025370340306410486,25.0,60.0
504.09009,0.07859821062992126,893.9979876160991,0.00025370340306410486,25.0,60.0
505.49146,0.07891058267716536,893.6349845201239,0.00025370340306410486,25.0,60.0
506.89282,0.07922755511811023,896.0924664602683,0.00025370340306410486,25.0,60.0
508.29419,0.07956507874015749,895.2090041279671,0.00025370340306410486,25.0,60.0
509.69556,0.07991338976377953,895.2425180598556,0.00025370340306410486,25.0,60.0
511.09692,0.08021625984251968,895.922342621259,0.00025370340306410486,25.0,60.0
512.49829,0.08054618503937007,896.4538957688338,0.00025370340306410486,25.0,60.0
513.89966,0.08088432480314961,897.0314241486068,0.00025370340306410486,25.0,60.0
515.30103,0.0812094094488189,897.5438854489164,0.00025370340306410486,25.0,60.0
516.70239,0.08152511614173229,897.6284313725491,0.00025370340306410486,25.0,60.0
518.10376,0.08190400984251969,899.6108875128999,0.00025370340306410486,25.0,60.0
519.50513,0.08224965157480316,898.5496904024768,0.00025370340306410486,25.0,60.0
520.90649,0.08258112007874016,898.5748710010321,0.00025370340306410486,25.0,60.0
522.30786,0.08290583070866142,898.2049535603716,0.00025370340306410486,25.0,60.0
523.70923,0.08326961811023623,901.0435500515997,0.00025370340306410486,25.0,60.0
525.1106,0.08361715551181102,899.4835397316822,0.00025370340306410486,25.0,60.0
526.51196,0.08396207677165354,899.9757223942208,0.00025370340306410486,25.0,60.0
527.91333,0.08428920472440946,901.3689628482972,0.00025370340306410486,25.0,60.0
529.3147,0.084663218503937,902.0511609907121,0.00025370340306410486,25.0,60.0
530.71606,0.08496753543307087,900.5870227038183,0.00025370340306410486,25.0,60.0
532.11743,0.0852786062992126,901.6624097007224,0.00025370340306410486,25.0,60.0
533.5188,0.08563754330708662,902.1401702786378,0.00025370340306410486,25.0,60.0
534.92017,0.08594847834645669,900.8941434468524,0.00025370340306410486,25.0,60.0
536.32153,0.08628067322834646,903.1804695562436,0.00025370340306410486,25.0,60.0
537.7229,0.08662871062992125,903.0978328173375,0.00025370340306410486,25.0,60.0
539.12427,0.08694998818897638,902.589963880289,0.00025370340306410486,25.0,60.0
540.52563,0.08729973228346456,903.5338493292054,0.00025370340306410486,25.0,60.0
541.927,0.08760650787401575,903.5842363261095,0.00025370340306410486,25.0,60.0
543.32837,0.08796069881889763,903.9781475748194,0.00025370340306410486,25.0,60.0
544.72974,0.08829306496062993,905.8208720330238,0.00025370340306410486,25.0,60.0
546.1311,0.08863875984251968,904.6437564499483,0.00025370340306410486,25.0,60.0
547.53247,0.08898632677165354,905.6773735810114,0.00025370340306410486,25.0,60.0
548.93384,0.08931500787401575,906.775386996904,0.00025370340306410486,25.0,60.0
550.33521,0.0896785905511811,907.3448658410733,0.00025370340306410486,25.0,60.0
551.73657,0.09001438385826771,905.903818369453,0.00025370340306410486,25.0,60.0
553.13794,0.09036138582677165,907.30064499484,0.00025370340306410486,25.0,60.0
554.53931,0.09072071653543307,908.7122033023736,0.00025370340306410486,25.0,60.0
555.94067,0.09102711023622047,905.3910474716203,0.00025370340306410486,25.0,60.0
557.34204,0.09133666732283464,906.802141382869,0.00025370340306410486,25.0,60.0
558.74341,0.09166615354330708,908.5981940144479,0.00025370340306410486,25.0,60.0
560.14478,0.09202368110236221,909.166898864809,0.00025370340306410486,25.0,60.0
561.54614,0.09243366929133857,908.8214138286894,0.00025370340306410486,25.0,60.0
562.94751,0.09281464566929133,907.8283539731682,0.00025370340306410486,25.0,60.0
564.34888,0.09313052165354331,909.0951496388029,0.00025370340306410486,25.0,60.0
565.75024,0.0934654625984252,910.0428018575851,0.00025370340306410486,25.0,60.0
567.15161,0.09381254921259842,910.7752321981425,0.00025370340306410486,25.0,60.0
568.55298,0.09420239566929134,910.9330237358101,0.00025370340306410486,25.0,60.0
569.95435,0.0945390216535433,911.0436790505677,0.00025370340306410486,25.0,60.0
571.35571,0.09488429921259842,909.9588493292055,0.00025370340306410486,25.0,60.0
572.75708,0.09522698622047245,911.572084623323,0.00025370340306410486,25.0,60.0
574.15845,0.09552265551181102,910.9849845201239,0.00025370340306410486,25.0,60.0
575.55981,0.09583870669291339,911.1528379772963,0.00025370340306410486,25.0,60.0
576.96118,0.09615730511811023,912.3149122807017,0.00025370340306410486,25.0,60.0
578.36255,0.0965568779527559,915.011274509804,0.00025370340306410486,25.0,60.0
579.76392,0.09694912598425197,916.3278637770898,0.00025370340306410486,25.0,60.0
581.16528,0.09730059251968505,914.518653250774,0.00025370340306410486,25.0,60.0
582.56665,0.09761972440944883,912.9413054695563,0.00025370340306410486,25.0,60.0
583.96802,0.09792838976377953,915.2073787409702,0.00025370340306410486,25.0,60.0
585.36938,0.09826139566929133,915.2715428276574,0.00025370340306410486,25.0,60.0
586.77075,0.09861585039370079,916.0966976264191,0.00025370340306410486,25.0,60.0
588.17212,0.09894401574803148,915.7784055727554,0.00025370340306410486,25.0,60.0
589.57349,0.09935993307086613,915.6669246646027,0.00025370340306410486,25.0,60.0
590.97485,0.09976404921259843,916.4637770897833,0.00025370340306410486,25.0,60.0
592.37622,0.1001746279527559,918.3142930856553,0.00025370340306410486,25.0,60.0
593.77759,0.10051354133858269,916.0390608875128,0.00025370340306410486,25.0,60.0
595.17896,0.10085631496062993,916.4688338493293,0.00025370340306410486,25.0,60.0
596.58032,0.1011675964566929,916.8326367389062,0.00025370340306410486,25.0,60.0
597.98169,0.10151281102362204,918.2733488132095,0.00025370340306410486,25.0,60.0
599.38306,0.10188586811023621,917.5605779153767,0.00025370340306410486,25.0,60.0
600.78442,0.10224910433070865,917.0926470588236,0.00025370340306410486,25.0,60.0
602.18579,0.10258426377952756,918.2556501547988,0.00025370340306410486,25.0,60.0
603.58716,0.10293685826771654,918.366253869969,0.00025370340306410486,25.0,60.0
604.98853,0.10328038188976377,917.5197626418989,0.00025370340306410486,25.0,60.0
606.38989,0.1036182874015748,918.5072239422085,0.00025370340306410486,25.0,60.0
607.79126,0.10392360826771654,919.3171310629515,0.00025370340306410486,25.0,60.0
609.19263,0.10429867125984253,919.9536119711044,0.00025370340306410486,25.0,60.0
610.59399,0.10463528543307087,920.2635190918473,0.00025370340306410486,25.0,60.0
611.99536,0.10501223818897637,922.3957172342622,0.00025370340306410486,25.0,60.0
613.39673,0.10533234251968503,918.9967234262126,0.00025370340306410486,25.0,60.0
614.7981,0.10566280905511811,920.659649122807,0.00025370340306410486,25.0,60.0
616.19946,0.105964281496063,919.9083333333333,0.00025370340306410486,25.0,60.0
617.60083,0.10632053543307086,920.8095717234262,0.00025370340306410486,25.0,60.0
619.0022,0.10668076771653542,921.7817079463364,0.00025370340306410486,25.0,60.0
620.40356,0.10706657874015747,922.0584107327142,0.00025370340306410486,25.0,60.0
621.80493,0.10747867322834645,923.8529927760578,0.00025370340306410486,25.0,60.0
623.2063,0.10786719488188977,923.7590815273478,0.00025370340306410486,25.0,60.0
624.60767,0.1082346437007874,924.3527605779153,0.00025370340306410486,25.0,60.0
626.00903,0.10861721653543306,923.5156346749227,0.00025370340306410486,25.0,60.0
627.4104,0.10897245078740157,924.5945562435501,0.00025370340306410486,25.0,60.0
628.81177,0.1093595157480315,924.1050825593395,0.00025370340306410486,25.0,60.0
630.21313,0.1097672342519685,923.5525541795665,0.00025370340306410486,25.0,60.0
631.6145,0.11016964763779528,924.4512641898865,0.00025370340306410486,25.0,60.0
633.01587,0.11053033661417323,924.374226006192,0.00025370340306410486,25.0,60.0
634.41724,0.11086087204724408,924.1302889576884,0.00025370340306410486,25.0,60.0
635.8186,0.11114721062992126,925.5977554179567,0.00025370340306410486,25.0,60.0
637.21997,0.11144753346456694,925.2704850361197,0.00025370340306410486,25.0,60.0
638.62134,0.11180574803149605,924.4624097007224,0.00025370340306410486,25.0,60.0
640.02271,0.11215906889763778,927.1979618163056,0.00025370340306410486,25.0,60.0
641.42407,0.11251054921259841,925.6984778121775,0.00025370340306410486,25.0,60.0
642.82544,0.11288312401574804,925.2483230134159,0.00025370340306410486,25.0,60.0
644.22681,0.11326015944881888,928.2392156862745,0.00025370340306410486,25.0,60.0
645.62817,0.11364296653543307,926.603431372549,0.00025370340306410486,25.0,60.0
647.02954,0.11397671653543308,926.2250515995872,0.00025370340306410486,25.0,60.0
648.43091,0.1143119350393701,928.7879772961817,0.00025370340306410486,25.0,60.0
649.83228,0.11469971653543307,926.9096233230134,0.00025370340306410486,25.0,60.0
651.23364,0.11501497637795274,928.3670794633643,0.00025370340306410486,25.0,60.0
652.63501,0.11541586417322836,929.1163828689371,0.00025370340306410486,25.0,60.0
654.03638,0.11579956299212597,929.6258255933952,0.00025370340306410486,25.0,60.0
655.43774,0.11620296259842519,930.4686790505676,0.00025370340306410486,25.0,60.0
656.83911,0.11656759448818897,929.8860423116615,0.00025370340306410486,25.0,60.0
658.24048,0.11693333070866141,928.4947110423117,0.00025370340306410486,25.0,60.0
659.64185,0.11726901771653545,928.8450464396285,0.00025370340306410486,25.0,60.0
661.04321,0.11766835629921259,931.0242776057792,0.00025370340306410486,25.0,60.0
662.44458,0.11807625,929.3472910216718,0.00025370340306410486,25.0,60.0
663.84595,0.11847764173228346,930.8344427244582,0.00025370340306410486,25.0,60.0
665.24731,0.11888767125984252,931.325,0.00025370340306410486,25.0,60.0
666.64868,0.11924741141732284,929.1973168214655,0.00025370340306410486,25.0,60.0
668.05005,0.11959569881889764,930.136790505676,0.00025370340306410486,25.0,60.0
669.45142,0.11991934842519686,930.4403250773994,0.00025370340306410486,25.0,60.0
670.85278,0.12033003346456693,932.4812693498452,0.00025370340306410486,25.0,60.0
672.25415,0.120671187007874,930.9243292053665,0.00025370340306410486,25.0,60.0
673.65552,0.12102712598425196,931.4436016511868,0.00025370340306410486,25.0,60.0
675.05688,0.12137338385826771,932.6869711042312,0.00025370340306410486,25.0,60.0
676.45825,0.12174210039370077,930.9546955624355,0.00025370340306410486,25.0,60.0
677.85962,0.1221157440944882,933.2677760577915,0.00025370340306410486,25.0,60.0
679.26099,0.12250666929133858,932.629334365325,0.00025370340306410486,25.0,60.0
680.66235,0.12289410039370077,934.2131836945305,0.00025370340306410486,25.0,60.0
682.06372,0.12320009055118109,932.225773993808,0.00025370340306410486,25.0,60.0
683.46509,0.12353088385826771,935.1092363261095,0.00025370340306410486,25.0,60.0
684.86646,0.12391722440944881,933.7057533539733,0.00025370340306410486,25.0,60.0
686.26782,0.12434208267716534,935.4515737874098,0.00025370340306410486,25.0,60.0
687.66919,0.12473902755905512,933.3046955624355,0.00025370340306410486,25.0,60.0
689.07056,0.125153655511811,933.3974716202271,0.00025370340306410486,25.0,60.0
690.47192,0.12548480118110236,933.7962590299278,0.00025370340306410486,25.0,60.0
691.87329,0.125873968503937,935.3318885448916,0.00025370340306410486,25.0,60.0
693.27466,0.12622953149606297,934.9730650154798,0.00025370340306410486,25.0,60.0
694.67603,0.1265905964566929,936.0860423116615,0.00025370340306410486,25.0,60.0
696.07739,0.12701644291338582,936.3779411764706,0.00025370340306410486,25.0,60.0
697.47876,0.1274453720472441,936.2854747162023,0.00025370340306410486,25.0,60.0
698.88013,0.12783302559055118,933.9354489164086,0.00025370340306410486,25.0,60.0
700.28149,0.12816685826771654,935.0926728586171,0.00025370340306410486,25.0,60.0
701.68286,0.12857395275590552,938.2544633642932,0.00025370340306410486,25.0,60.0
703.08423,0.12903167716535432,936.0810113519092,0.00025370340306410486,25.0,60.0
704.4856,0.12943732874015748,936.7215944272446,0.00025370340306410486,25.0,60.0
705.88696,0.12982720078740156,937.7404282765739,0.00025370340306410486,25.0,60.0
707.28833,0.13020208661417323,937.2767801857585,0.00025370340306410486,25.0,60.0
708.6897,0.13058637401574802,936.4795407636739,0.00025370340306410486,25.0,60.0
710.09106,0.13100808858267718,939.5374097007224,0.00025370340306410486,25.0,60.0
711.49243,0.1314879527559055,939.5933436532508,0.00025370340306410486,25.0,60.0
712.8938,0.13188188188976377,937.1988648090816,0.00025370340306410486,25.0,60.0
714.29517,0.13216789173228347,935.9086687306501,0.00025370340306410486,25.0,60.0
715.69653,0.1325184311023622,938.7163054695562,0.00025370340306410486,25.0,60.0
717.0979,0.13286645078740159,939.029979360165,0.00025370340306410486,25.0,60.0
718.49927,0.13325936023622048,940.1908926728587,0.00025370340306410486,25.0,60.0
719.90063,0.1337105590551181,939.8212332301342,0.00025370340306410486,25.0,60.0
721.302,0.13413199212598426,939.2754901960785,0.00025370340306410486,25.0,60.0
722.70337,0.13452062007874016,938.6308823529412,0.00025370340306410486,25.0,60.0
724.10474,0.13492222440944882,939.8076883384932,0.00025370340306410486,25.0,60.0
725.5061,0.13532251377952756,940.1541279669764,0.00025370340306410486,25.0,60.0
726.90747,0.1357234842519685,939.3521671826626,0.00025370340306410486,25.0,60.0
728.30884,0.13611725,942.162048503612,0.00025370340306410486,25.0,60.0
729.71021,0.13655256299212598,942.2089009287926,0.00025370340306410486,25.0,60.0
731.11157,0.13699732283464566,941.3160474716203,0.00025370340306410486,25.0,60.0
732.51294,0.13739998228346456,940.097729618163,0.00025370340306410486,25.0,60.0
733.91431,0.13781152362204724,941.4105263157895,0.00025370340306410486,25.0,60.0
735.31567,0.1381865748031496,939.8954850361198,0.00025370340306410486,25.0,60.0
736.71704,0.13856872637795276,941.3954076367389,0.00025370340306410486,25.0,60.0
738.11841,0.1389525531496063,941.5971104231166,0.00025370340306410486,25.0,60.0
739.51978,0.13934563976377953,942.702657378741,0.00025370340306410486,25.0,60.0
740.92114,0.13975612598425197,942.434778121775,0.00025370340306410486,25.0,60.0
742.32251,0.140137031496063,942.615608875129,0.00025370340306410486,25.0,60.0
743.72388,0.14052231496062992,942.45544375645,0.00025370340306410486,25.0,60.0
745.12524,0.14091811023622047,941.8628998968009,0.00025370340306410486,25.0,60.0
746.52661,0.1413280216535433,941.6166924664602,0.00025370340306410486,25.0,60.0
747.92798,0.14171215551181102,942.3622807017545,0.00025370340306410486,25.0,60.0
749.32935,0.14210709448818898,943.1876676986584,0.00025370340306410486,25.0,60.0
750.73071,0.142537468503937,943.1523993808049,0.00025370340306410486,25.0,60.0
752.13208,0.14297417716535432,942.6937306501549,0.00025370340306410486,25.0,60.0
753.53345,0.1434285807086614,943.0115583075335,0.00025370340306410486,25.0,60.0
754.93481,0.14386574803149607,943.8637254901962,0.00025370340306410486,25.0,60.0
756.33618,0.14431679527559055,943.5849845201238,0.00025370340306410486,25.0,60.0
757.73755,0.1447304153543307,943.6464138286893,0.00025370340306410486,25.0,60.0
759.13892,0.14514796456692913,942.7055727554181,0.00025370340306410486,25.0,60.0
760.54028,0.14556354133858268,943.4195304437566,0.00025370340306410486,25.0,60.0
761.94165,0.14596082874015748,943.2624355005161,0.00025370340306410486,25.0,60.0
763.34302,0.14635065157480315,944.6782249742002,0.00025370340306410486,25.0,60.0
764.74438,0.14675605708661418,943.9263931888545,0.00025370340306410486,25.0,60.0
766.14575,0.14715294488188976,943.2347781217751,0.00025370340306410486,25.0,60.0
767.54712,0.1475992401574803,945.5112229102167,0.00025370340306410486,25.0,60.0
768.94849,0.1481169094488189,944.987048503612,0.00025370340306410486,25.0,60.0
770.34985,0.14860058661417322,945.9675180598555,0.00025370340306410486,25.0,60.0
771.75122,0.14904817322834646,944.7656346749226,0.00025370340306410486,25.0,60.0
773.15259,0.14950557874015746,944.0083333333333,0.00025370340306410486,25.0,60.0
774.55396,0.1499487775590551,946.9698916408669,0.00025370340306410486,25.0,60.0
775.95532,0.15033930511811022,943.8048761609907,0.00025370340306410486,25.0,60.0
777.35669,0.15073087795275592,944.6922084623324,0.00025370340306410486,25.0,60.0
778.75806,0.1512002874015748,946.642234262126,0.00025370340306410486,25.0,60.0
780.15942,0.1516725374015748,946.7539731682147,0.00025370340306410486,25.0,60.0
781.56079,0.15206698425196852,945.3060629514964,0.00025370340306410486,25.0,60.0
782.96216,0.15245782874015748,944.9506965944273,0.00025370340306410486,25.0,60.0
784.36353,0.1528456220472441,946.0325077399382,0.00025370340306410486,25.0,60.0
785.76489,0.15330337007874015,946.6860681114551,0.00025370340306410486,25.0,60.0
787.16626,0.1537154153543307,945.1557791537668,0.00025370340306410486,25.0,60.0
788.56763,0.15410038188976377,945.4303405572755,0.00025370340306410486,25.0,60.0
789.96899,0.1545367874015748,947.2370227038183,0.00025370340306410486,25.0,60.0
791.37036,0.15493129133858266,947.2204592363262,0.00025370340306410486,25.0,60.0
792.77173,0.15539070472440944,946.2548503611971,0.00025370340306410486,25.0,60.0
794.1731,0.15582157086614173,946.8687306501548,0.00025370340306410486,25.0,60.0
795.57446,0.15626274015748032,946.5945562435501,0.00025370340306410486,25.0,60.0
796.97583,0.15670382677165354,946.7908926728587,0.00025370340306410486,25.0,60.0
798.3772,0.1571643307086614,947.9105521155831,0.00025370340306410486,25.0,60.0
799.77856,0.15766856496062992,948.5539215686274,0.00025370340306410486,25.0,60.0
801.17993,0.15817174212598425,947.8805727554179,0.00025370340306410486,25.0,60.0
802.5813,0.15863525196850392,947.905830753354,0.00025370340306410486,25.0,60.0
803.98267,0.1590970807086614,949.0064241486068,0.00025370340306410486,25.0,60.0
805.38403,0.15958599212598423,949.4071981424149,0.00025370340306410486,25.0,60.0
806.7854,0.1600091968503937,947.917492260062,0.00025370340306410486,25.0,60.0
808.18677,0.16053422244094487,948.2613261093911,0.00025370340306410486,25.0,60.0
809.58813,0.16096418503937007,947.9845717234263,0.00025370340306410486,25.0,60.0
810.9895,0.1614285964566929,948.8809339525285,0.00025370340306410486,25.0,60.0
812.39087,0.16186913188976376,947.2045149638803,0.00025370340306410486,25.0,60.0
813.79224,0.16231745669291336,949.2550825593395,0.00025370340306410486,25.0,60.0
815.1936,0.16284133267716536,950.1834107327142,0.00025370340306410486,25.0,60.0
816.59497,0.16326737598425198,948.1201238390092,0.00025370340306410486,25.0,60.0
817.99634,0.16375836417322834,949.0350877192983,0.00025370340306410486,25.0,60.0
819.39771,0.16418621456692914,947.7605263157895,0.00025370340306410486,25.0,60.0
820.79907,0.1646425905511811,948.7884932920537,0.00025370340306410486,25.0,60.0
822.20044,0.16515473228346456,949.6026057791538,0.00025370340306410486,25.0,60.0
823.60181,0.16557649409448819,947.5145510835914,0.00025370340306410486,25.0,60.0
825.00317,0.16598310826771653,948.3282249742003,0.00025370340306410486,25.0,60.0
826.40454,0.16642289173228345,950.659520123839,0.00025370340306410486,25.0,60.0
827.80591,0.16695715157480315,950.1253869969041,0.00025370340306410486,25.0,60.0
829.20728,0.16741421653543306,948.568653250774,0.00025370340306410486,25.0,60.0
830.60864,0.16786945472440945,950.53173374613,0.00025370340306410486,25.0,60.0
832.01001,0.16841508267716535,950.0748194014448,0.00025370340306410486,25.0,60.0
833.41138,0.16890643307086614,949.7758771929824,0.00025370340306410486,25.0,60.0
834.81274,0.16931979527559055,948.9830495356038,0.00025370340306410486,25.0,60.0
836.21411,0.16979444881889763,950.6209752321982,0.00025370340306410486,25.0,60.0
837.61548,0.17031095669291338,949.6497678018577,0.00025370340306410486,25.0,60.0
839.01685,0.17080280118110236,949.8167440660475,0.00025370340306410486,25.0,60.0
840.41821,0.1713388188976378,951.2369969040247,0.00025370340306410486,25.0,60.0
841.81958,0.17189963188976376,951.0703302373581,0.00025370340306410486,25.0,60.0
843.22095,0.1724074212598425,949.5146542827657,0.00025370340306410486,25.0,60.0
844.62231,0.17286539173228346,948.7712848297214,0.00025370340306410486,25.0,60.0
846.02368,0.1732966437007874,948.8450464396285,0.00025370340306410486,25.0,60.0
847.42505,0.17376554921259843,949.4579205366357,0.00025370340306410486,25.0,60.0
848.82642,0.1743093720472441,950.2270639834882,0.00025370340306410486,25.0,60.0
850.22778,0.17479729724409448,949.6808823529412,0.00025370340306410486,25.0,60.0
851.62915,0.17530460433070866,950.9939886480909,0.00025370340306410486,25.0,60.0
853.03052,0.17578255708661417,950.7121259029929,0.00025370340306410486,25.0,60.0
854.43188,0.17634918897637794,949.9609907120744,0.00025370340306410486,25.0,60.0
855.83325,0.17687763976377952,949.2016769865842,0.00025370340306410486,25.0,60.0
857.23462,0.17736956692913386,948.9819143446853,0.00025370340306410486,25.0,60.0
858.63599,0.17780416338582677,949.6729618163056,0.00025370340306410486,25.0,60.0
860.03735,0.178232531496063,949.7432404540764,0.00025370340306410486,25.0,60.0
861.43872,0.1786746377952756,949.8194014447885,0.00025370340306410486,25.0,60.0
862.84009,0.17913233858267716,950.1434726522189,0.00025370340306410486,25.0,60.0
864.24146,0.17964531299212597,951.1914602683179,0.00025370340306410486,25.0,60.0
865.04224,0.17997475787401576,953.5169762641899,0.00025370340306410486,25.0,60.0