File: datasets/am_bench_2022/csv/90-XY.17-2.csv
Time(s),Strain(%),Stress(MPa),SR(s-1),Temp(C),Angle(deg)
12.435059,1.487796122047244e-05,9.957526026528564,0.00025370340306410486,25.0,90.0
13.836426,3.10187716535433e-05,14.238048670929556,0.00025370340306410486,25.0,90.0
15.237793,5.090912401574803e-05,18.76562331554193,0.00025370340306410486,25.0,90.0
16.63916,6.711326181102362e-05,23.95261586429213,0.00025370340306410486,25.0,90.0
18.040527,9.612106102362204e-05,29.136204618717958,0.00025370340306410486,25.0,90.0
19.441895,0.00011188375196850393,32.91038418855361,0.00025370340306410486,25.0,90.0
20.843262,0.00013377461023622047,37.382048301009355,0.00025370340306410486,25.0,90.0
22.244629,0.00013874019488188975,41.49802885377583,0.00025370340306410486,25.0,90.0
23.645996,0.00015525307677165354,44.996414416318764,0.00025370340306410486,25.0,90.0
25.047363,0.00019316638582677167,53.820662685620675,0.00025370340306410486,25.0,90.0
26.44873,0.0001853613562992126,58.76466205147175,0.00025370340306410486,25.0,90.0
27.850098,0.00023493872047244092,66.24754003065053,0.00025370340306410486,25.0,90.0
29.251465,0.00025915096456692913,75.52791840617238,0.00025370340306410486,25.0,90.0
30.652832,0.00029037726377952755,82.86829519632194,0.00025370340306410486,25.0,90.0
32.054199,0.000304670216535433,90.23166252708344,0.00025370340306410486,25.0,90.0
33.455566,0.00033925687007874014,98.97048301009353,0.00025370340306410486,25.0,90.0
34.856934,0.0003704950590551181,108.21739946097341,0.00025370340306410486,25.0,90.0
36.258301,0.00040278917322834646,115.52147651006712,0.00025370340306410486,25.0,90.0
37.659668,0.00040398948818897633,124.57943772129154,0.00025370340306410486,25.0,90.0
39.061035,0.00044863435039370076,132.30016910637846,0.00025370340306410486,25.0,90.0
40.462402,0.0004812374212598426,142.74143634730223,0.00025370340306410486,25.0,90.0
41.86377,0.0005156869291338583,150.80791100776833,0.00025370340306410486,25.0,90.0
43.265137,0.0005436495078740157,162.02531046874174,0.00025370340306410486,25.0,90.0
44.666504,0.0005756828937007874,169.1824023674893,0.00025370340306410486,25.0,90.0
46.067871,0.0006007850590551181,177.7354515668763,0.00025370340306410486,25.0,90.0
47.469238,0.0006448507283464567,187.69637742429848,0.00025370340306410486,25.0,90.0
48.870605,0.0006728195472440945,196.5221238704222,0.00025370340306410486,25.0,90.0
50.271973,0.0007040265157480315,207.06993605665062,0.00025370340306410486,25.0,90.0
51.67334,0.0007330091141732283,217.01696084130424,0.00025370340306410486,25.0,90.0
53.074707,0.0007566554527559055,224.8428156212017,0.00025370340306410486,25.0,90.0
54.476074,0.0008093626771653544,234.78606721978545,0.00025370340306410486,25.0,90.0
55.877441,0.0008269909842519684,244.91637689584104,0.00025370340306410486,25.0,90.0
57.278809,0.0008573863779527559,253.17741108703694,0.00025370340306410486,25.0,90.0
58.680176,0.0009130225393700788,263.56704803678065,0.00025370340306410486,25.0,90.0
60.081543,0.0009351059842519684,276.6794641441632,0.00025370340306410486,25.0,90.0
61.48291,0.0009682787598425196,284.9139142842044,0.00025370340306410486,25.0,90.0
62.884277,0.0010310972047244094,298.9087354013634,0.00025370340306410486,25.0,90.0
64.285645,0.0010520198622047245,305.02925011890295,0.00025370340306410486,25.0,90.0
65.687012,0.0011012915157480314,318.0688051577446,0.00025370340306410486,25.0,90.0
67.088379,0.0011306907874015749,330.8099138614384,0.00025370340306410486,25.0,90.0
68.489746,0.0011747451771653543,341.483882048301,0.00025370340306410486,25.0,90.0
69.891113,0.0012003747047244094,350.0697828039951,0.00025370340306410486,25.0,90.0
71.29248,0.0012347556299212598,358.81480209269137,0.00025370340306410486,25.0,90.0
72.693848,0.0012847364763779528,372.6065898641864,0.00025370340306410486,25.0,90.0
74.095215,0.0013285769291338583,382.07176451936795,0.00025370340306410486,25.0,90.0
75.496582,0.001370606437007874,392.60970776303964,0.00025370340306410486,25.0,90.0
76.897949,0.001400266220472441,403.0469798657718,0.00025370340306410486,25.0,90.0
78.299316,0.0014317835236220473,412.6502404481319,0.00025370340306410486,25.0,90.0
79.700684,0.0014733104133858267,423.2713628917191,0.00025370340306410486,25.0,90.0
81.102051,0.0015097518110236219,433.25458436822913,0.00025370340306410486,25.0,90.0
82.503418,0.001541225570866142,442.990884109285,0.00025370340306410486,25.0,90.0
83.904785,0.001580354311023622,448.9713840300164,0.00025370340306410486,25.0,90.0
85.306152,0.0015980013976377955,461.5883052370132,0.00025370340306410486,25.0,90.0
86.70752,0.0016496503937007874,469.73727738730645,0.00025370340306410486,25.0,90.0
88.108887,0.0016720556692913387,480.18057390477196,0.00025370340306410486,25.0,90.0
89.510254,0.0017197586417322835,488.86040796913807,0.00025370340306410486,25.0,90.0
90.911621,0.0017360389960629921,496.39150768905563,0.00025370340306410486,25.0,90.0
92.312988,0.001768275216535433,505.0374940548539,0.00025370340306410486,25.0,90.0
93.714355,0.0018050914370078739,514.0826507424827,0.00025370340306410486,25.0,90.0
95.115723,0.0018466892913385827,523.5548274586482,0.00025370340306410486,25.0,90.0
96.51709,0.0018807122637795274,532.4538920889922,0.00025370340306410486,25.0,90.0
97.918457,0.001931373090551181,542.0096707710194,0.00025370340306410486,25.0,90.0
99.319824,0.001958924842519685,550.055355916081,0.00025370340306410486,25.0,90.0
100.72119,0.0019697702755905513,557.7073402737409,0.00025370340306410486,25.0,90.0
102.12256,0.0020373417322834646,566.7033768429953,0.00025370340306410486,25.0,90.0
103.52393,0.002043786417322835,572.9241135126565,0.00025370340306410486,25.0,90.0
104.92529,0.0020808956692913386,580.6262749035565,0.00025370340306410486,25.0,90.0
106.32666,0.0020974964566929134,587.2754848596945,0.00025370340306410486,25.0,90.0
107.72803,0.0021395712598425197,594.9248269301906,0.00025370340306410486,25.0,90.0
109.12939,0.0021669779527559055,601.3452148179464,0.00025370340306410486,25.0,90.0
110.53076,0.00218512342519685,607.2922898060561,0.00025370340306410486,25.0,90.0
111.93213,0.0022220549212598425,612.0498335359086,0.00025370340306410486,25.0,90.0
113.3335,0.0022311574803149607,616.96805474819,0.00025370340306410486,25.0,90.0
114.73486,0.002269000196850394,623.6806003276437,0.00025370340306410486,25.0,90.0
116.13623,0.0022992076771653543,628.9589124346033,0.00025370340306410486,25.0,90.0
117.5376,0.002304364566929134,633.0478253976643,0.00025370340306410486,25.0,90.0
118.93896,0.0023489811023622046,638.6455107541087,0.00025370340306410486,25.0,90.0
120.34033,0.002360968700787402,642.7191248744913,0.00025370340306410486,25.0,90.0
121.7417,0.0024214883858267714,650.2113829731014,0.00025370340306410486,25.0,90.0
123.14307,0.002430414566929134,652.9455424615547,0.00025370340306410486,25.0,90.0
124.54443,0.0024563,656.0015325265549,0.00025370340306410486,25.0,90.0
125.9458,0.002498337007874016,663.4787560112032,0.00025370340306410486,25.0,90.0
127.34717,0.0025111165354330706,665.0317602917085,0.00025370340306410486,25.0,90.0
128.74854,0.00255755374015748,672.2965438883898,0.00025370340306410486,25.0,90.0
130.1499,0.00258456594488189,674.3364688474344,0.00025370340306410486,25.0,90.0
131.55127,0.0026086039370078738,678.829704592295,0.00025370340306410486,25.0,90.0
132.95264,0.0026307570866141734,683.226946044496,0.00025370340306410486,25.0,90.0
134.354,0.0026836610236220474,686.7284257253078,0.00025370340306410486,25.0,90.0
135.75537,0.002704383070866142,688.6384822702531,0.00025370340306410486,25.0,90.0
137.15674,0.0027450653543307085,692.7048036780637,0.00025370340306410486,25.0,90.0
138.55811,0.0027937466535433073,697.969375891772,0.00025370340306410486,25.0,90.0
139.95947,0.0028196610236220472,699.7424034244042,0.00025370340306410486,25.0,90.0
141.36084,0.0028814938976377954,704.0388944670507,0.00025370340306410486,25.0,90.0
142.76221,0.002914142322834646,706.0052053057126,0.00025370340306410486,25.0,90.0
144.16357,0.002973341338582677,713.3290175976325,0.00025370340306410486,25.0,90.0
145.56494,0.002998399803149606,713.4873434444855,0.00025370340306410486,25.0,90.0
146.96631,0.003070200393700787,718.9947946942873,0.00025370340306410486,25.0,90.0
148.36768,0.0031035059055118113,719.0796121122443,0.00025370340306410486,25.0,90.0
149.76904,0.0031518734251968503,723.8134016804946,0.00025370340306410486,25.0,90.0
151.17041,0.003232016338582677,726.705807747186,0.00025370340306410486,25.0,90.0
152.57178,0.00327611968503937,730.6187179622681,0.00025370340306410486,25.0,90.0
153.97314,0.0033479501968503938,732.9247212387041,0.00025370340306410486,25.0,90.0
155.37451,0.0034122299212598424,734.1701897162184,0.00025370340306410486,25.0,90.0
156.77588,0.0035003714566929135,738.4468107593933,0.00025370340306410486,25.0,90.0
158.17725,0.0035783844488188974,742.1436875759657,0.00025370340306410486,25.0,90.0
159.57861,0.0036564029527559054,745.5342968873857,0.00025370340306410486,25.0,90.0
160.97998,0.003737764566929134,746.2798182106432,0.00025370340306410486,25.0,90.0
162.38135,0.003828793307086614,749.6293135337947,0.00025370340306410486,25.0,90.0
163.78271,0.003905724803149606,751.6535433070866,0.00025370340306410486,25.0,90.0
165.18408,0.004016404921259842,753.348385562543,0.00025370340306410486,25.0,90.0
166.58545,0.004146287401574803,756.4440363578714,0.00025370340306410486,25.0,90.0
167.98682,0.004271985039370078,759.0200813824446,0.00025370340306410486,25.0,90.0
169.38818,0.004398933070866142,762.1364477091371,0.00025370340306410486,25.0,90.0
170.78955,0.0045469793307086614,762.025154573799,0.00025370340306410486,25.0,90.0
172.19092,0.004677094291338582,766.0080061301062,0.00025370340306410486,25.0,90.0
173.59229,0.004836080511811024,768.5271627120435,0.00025370340306410486,25.0,90.0
174.99365,0.005007238188976378,771.3657982349522,0.00025370340306410486,25.0,90.0
176.39502,0.005155860039370078,770.2509644348148,0.00025370340306410486,25.0,90.0
177.79639,0.005302559448818898,772.6839296094698,0.00025370340306410486,25.0,90.0
179.19775,0.005489670275590551,776.6619193573957,0.00025370340306410486,25.0,90.0
180.59912,0.005674553937007874,778.1506632140781,0.00025370340306410486,25.0,90.0
182.00049,0.005874369881889763,779.4644612376474,0.00025370340306410486,25.0,90.0
183.40186,0.006064946062992126,779.986075146647,0.00025370340306410486,25.0,90.0
184.80322,0.0062809779527559055,783.6507689055646,0.00025370340306410486,25.0,90.0
186.20459,0.006479948818897637,782.7127305395551,0.00025370340306410486,25.0,90.0
187.60596,0.006676947047244094,787.0723193996723,0.00025370340306410486,25.0,90.0
189.00732,0.006877102952755906,790.169846218887,0.00025370340306410486,25.0,90.0
190.40869,0.00713475216535433,788.2014743962374,0.00025370340306410486,25.0,90.0
191.81006,0.007372303937007873,790.5749616868361,0.00025370340306410486,25.0,90.0
193.21143,0.007635789173228347,792.827881414152,0.00025370340306410486,25.0,90.0
194.61279,0.007892737992125984,795.8637372509644,0.00025370340306410486,25.0,90.0
196.01416,0.00812874625984252,795.3603551233948,0.00025370340306410486,25.0,90.0
197.41553,0.00838884409448819,797.0303070337684,0.00025370340306410486,25.0,90.0
198.81689,0.008639200393700787,798.7949585160915,0.00025370340306410486,25.0,90.0
200.21826,0.008874264763779527,799.2885641811553,0.00025370340306410486,25.0,90.0
201.61963,0.009144347637795276,801.1345716852506,0.00025370340306410486,25.0,90.0
203.021,0.009387668503937008,801.6175553559161,0.00025370340306410486,25.0,90.0
204.42236,0.009641335826771654,802.802066268562,0.00025370340306410486,25.0,90.0
205.82373,0.009899229330708663,805.2067061248216,0.00025370340306410486,25.0,90.0
207.2251,0.010129964173228347,803.9603128468002,0.00025370340306410486,25.0,90.0
208.62646,0.01044275059055118,809.777862918142,0.00025370340306410486,25.0,90.0
210.02783,0.010732782874015748,807.3854832743223,0.00025370340306410486,25.0,90.0
211.4292,0.011002000393700787,808.6670189716218,0.00025370340306410486,25.0,90.0
212.83057,0.011310168307086614,811.3628388733287,0.00025370340306410486,25.0,90.0
214.23193,0.011596096850393702,810.907017914707,0.00025370340306410486,25.0,90.0
215.6333,0.011863712007874016,811.9310363050255,0.00025370340306410486,25.0,90.0
217.03467,0.01214795748031496,814.3792210537441,0.00025370340306410486,25.0,90.0
218.43604,0.012430467913385828,815.1074618189505,0.00025370340306410486,25.0,90.0
219.8374,0.012746836023622048,815.6835861121385,0.00025370340306410486,25.0,90.0
221.23877,0.013016715748031498,817.8659303493104,0.00025370340306410486,25.0,90.0
222.64014,0.013225776377952756,816.8094646726205,0.00025370340306410486,25.0,90.0
224.0415,0.013506944881889764,817.8339322517571,0.00025370340306410486,25.0,90.0
225.44287,0.01381756220472441,820.1739417639908,0.00025370340306410486,25.0,90.0
226.84424,0.014065314566929133,816.6111610209798,0.00025370340306410486,25.0,90.0
228.24561,0.014302269488188975,820.6520636262749,0.00025370340306410486,25.0,90.0
229.64697,0.014548062401574803,823.7672673466152,0.00025370340306410486,25.0,90.0
231.04834,0.01485793031496063,824.5918987475559,0.00025370340306410486,25.0,90.0
232.44971,0.015138460629921259,822.9681340168049,0.00025370340306410486,25.0,90.0
233.85107,0.015395219685039369,824.7040109919145,0.00025370340306410486,25.0,90.0
235.25244,0.015759196653543306,828.7204724409448,0.00025370340306410486,25.0,90.0
236.65381,0.016103718700787403,827.4341013581355,0.00025370340306410486,25.0,90.0
238.05518,0.01641427440944882,828.1586693441843,0.00025370340306410486,25.0,90.0
239.45654,0.01667468248031496,828.3443164403106,0.00025370340306410486,25.0,90.0
240.85791,0.01697020216535433,829.4900650002643,0.00025370340306410486,25.0,90.0
242.25928,0.017229474999999998,830.6801775616973,0.00025370340306410486,25.0,90.0
243.66064,0.017534756692913385,831.0880674311684,0.00025370340306410486,25.0,90.0
245.06201,0.017848150393700787,831.9641705860593,0.00025370340306410486,25.0,90.0
246.46338,0.018174930118110236,834.7914178512921,0.00025370340306410486,25.0,90.0
247.86475,0.01849823248031496,835.0667970195,0.00025370340306410486,25.0,90.0
249.26611,0.01880785846456693,834.5465306769539,0.00025370340306410486,25.0,90.0
250.66748,0.019092168503937006,836.6018601701633,0.00025370340306410486,25.0,90.0
252.06885,0.019364647047244093,835.8327167996617,0.00025370340306410486,25.0,90.0
253.47021,0.019647560826771653,836.8674364529937,0.00025370340306410486,25.0,90.0
254.87158,0.019940102362204726,837.4847804259366,0.00025370340306410486,25.0,90.0
256.27295,0.020299108267716536,839.2044073349891,0.00025370340306410486,25.0,90.0
257.67432,0.020644931102362204,842.1139618453733,0.00025370340306410486,25.0,90.0
259.07568,0.02090317716535433,837.6632933467208,0.00025370340306410486,25.0,90.0
260.47705,0.021166746062992126,841.2998995930877,0.00025370340306410486,25.0,90.0
261.87842,0.02143803346456693,840.4889023939121,0.00025370340306410486,25.0,90.0
263.27979,0.021707647637795275,843.4910954922581,0.00025370340306410486,25.0,90.0
264.68115,0.022008273622047242,844.8793795909738,0.00025370340306410486,25.0,90.0
266.08252,0.02230753149606299,844.8855889658088,0.00025370340306410486,25.0,90.0
267.48389,0.022613844488188976,845.4827458648205,0.00025370340306410486,25.0,90.0
268.88525,0.022916167322834646,848.1743645299371,0.00025370340306410486,25.0,90.0
270.28662,0.023204440944881888,845.7827775722666,0.00025370340306410486,25.0,90.0
271.68799,0.023495417322834646,849.2261797812187,0.00025370340306410486,25.0,90.0
273.08936,0.023766161417322833,847.88899751625,0.00025370340306410486,25.0,90.0
274.49072,0.024095326771653543,848.9379590973947,0.00025370340306410486,25.0,90.0
275.89209,0.024404421259842518,850.467473445014,0.00025370340306410486,25.0,90.0
277.29346,0.024711496062992125,849.6758706336204,0.00025370340306410486,25.0,90.0
278.69482,0.025036427165354327,852.3769486867833,0.00025370340306410486,25.0,90.0
280.09619,0.02535675787401575,853.644031073297,0.00025370340306410486,25.0,90.0
281.49756,0.025714285433070867,855.078766580352,0.00025370340306410486,25.0,90.0
282.89893,0.026033976377952756,853.0453152248587,0.00025370340306410486,25.0,90.0
284.30029,0.026330653543307086,854.8104158959995,0.00025370340306410486,25.0,90.0
285.70166,0.026613285433070868,855.7336046081488,0.00025370340306410486,25.0,90.0
287.10303,0.026911226377952756,857.5605612217936,0.00025370340306410486,25.0,90.0
288.50439,0.02722334842519685,857.7615071605982,0.00025370340306410486,25.0,90.0
289.90576,0.027550592519685037,857.6629234265179,0.00025370340306410486,25.0,90.0
291.30713,0.027889025590551182,862.09728901337,0.00025370340306410486,25.0,90.0
292.7085,0.028200001968503936,860.4232679807641,0.00025370340306410486,25.0,90.0
294.10986,0.028489539370078743,860.2788934101358,0.00025370340306410486,25.0,90.0
295.51123,0.02874585433070866,860.5451302647572,0.00025370340306410486,25.0,90.0
296.9126,0.02901317716535433,859.530994028431,0.00025370340306410486,25.0,90.0
298.31396,0.029305551181102365,859.9380912117527,0.00025370340306410486,25.0,90.0
299.71533,0.02955419094488189,861.0355123394811,0.00025370340306410486,25.0,90.0
301.1167,0.02982109251968504,862.6429477355598,0.00025370340306410486,25.0,90.0
302.51807,0.030146909448818898,865.9907255720551,0.00025370340306410486,25.0,90.0
303.91943,0.030451185039370082,864.623315541933,0.00025370340306410486,25.0,90.0
305.3208,0.030770033464566925,865.2470538498123,0.00025370340306410486,25.0,90.0
306.72217,0.03111952559055118,867.372298261375,0.00025370340306410486,25.0,90.0
308.12354,0.031424084645669294,866.9651218094382,0.00025370340306410486,25.0,90.0
309.5249,0.03170299803149606,866.2074723880991,0.00025370340306410486,25.0,90.0
310.92627,0.031990982283464565,868.2453627860276,0.00025370340306410486,25.0,90.0
312.32764,0.032315476377952755,869.7613222004967,0.00025370340306410486,25.0,90.0
313.729,0.03261733267716536,868.7747978650319,0.00025370340306410486,25.0,90.0
315.13037,0.03294473622047244,870.0609839877397,0.00025370340306410486,25.0,90.0
316.53174,0.033229860236220474,871.171378745442,0.00025370340306410486,25.0,90.0
317.93311,0.03354037007874015,870.1860698620726,0.00025370340306410486,25.0,90.0
319.33447,0.03385180905511811,871.4287639380648,0.00025370340306410486,25.0,90.0
320.73584,0.03420012992125984,872.8604608148813,0.00025370340306410486,25.0,90.0
322.13721,0.03452717519685039,873.9733128996459,0.00025370340306410486,25.0,90.0
323.53857,0.034859033464566924,874.9942926597263,0.00025370340306410486,25.0,90.0
324.93994,0.0351369468503937,872.0703641071711,0.00025370340306410486,25.0,90.0
326.34131,0.03543487007874016,874.284495058923,0.00025370340306410486,25.0,90.0
327.74268,0.03570912795275591,874.3206415473234,0.00025370340306410486,25.0,90.0
329.14404,0.036016135826771656,876.1112667124663,0.00025370340306410486,25.0,90.0
330.54541,0.03632351377952756,875.4598636579824,0.00025370340306410486,25.0,90.0
331.94678,0.036604799212598425,877.575622258627,0.00025370340306410486,25.0,90.0
333.34814,0.03697088188976378,877.9366907995561,0.00025370340306410486,25.0,90.0
334.74951,0.037222482283464566,878.5962320985044,0.00025370340306410486,25.0,90.0
336.15088,0.03754051968503937,878.5518945198965,0.00025370340306410486,25.0,90.0
337.55225,0.037895834645669285,880.8697616656978,0.00025370340306410486,25.0,90.0
338.95361,0.03822825787401575,881.5215610632563,0.00025370340306410486,25.0,90.0
340.35498,0.038494533464566924,880.422475294615,0.00025370340306410486,25.0,90.0
341.75635,0.03877735039370079,881.943402208952,0.00025370340306410486,25.0,90.0
343.15771,0.039094448818897634,882.4284997093483,0.00025370340306410486,25.0,90.0
344.55908,0.03944108858267716,882.8431009882154,0.00025370340306410486,25.0,90.0
345.96045,0.039726043307086616,882.2464725466363,0.00025370340306410486,25.0,90.0
347.36182,0.0400121279527559,884.0555408761824,0.00025370340306410486,25.0,90.0
348.76318,0.04030433267716536,886.4557945357501,0.00025370340306410486,25.0,90.0
350.16455,0.04062356299212598,885.3443164403108,0.00025370340306410486,25.0,90.0
351.56592,0.040938053149606295,885.596919093167,0.00025370340306410486,25.0,90.0
352.96729,0.041272470472440946,887.604502457327,0.00025370340306410486,25.0,90.0
354.36865,0.041565771653543304,888.3305501241875,0.00025370340306410486,25.0,90.0
355.77002,0.04191584251968504,888.4055118110236,0.00025370340306410486,25.0,90.0
357.17139,0.042203273622047247,888.2874015748031,0.00025370340306410486,25.0,90.0
358.57275,0.04251848622047244,888.2031654600222,0.00025370340306410486,25.0,90.0
359.97412,0.042850362204724414,889.7373566559214,0.00025370340306410486,25.0,90.0
361.37549,0.043129316929133854,889.8287269460444,0.00025370340306410486,25.0,90.0
362.77686,0.0434409625984252,891.0030914759815,0.00025370340306410486,25.0,90.0
364.17822,0.043766391732283465,891.7468953125825,0.00025370340306410486,25.0,90.0
365.57959,0.044066763779527555,893.7953812820376,0.00025370340306410486,25.0,90.0
366.98096,0.044418299212598426,893.5567563282777,0.00025370340306410486,25.0,90.0
368.38232,0.04475992913385826,893.7953020134229,0.00025370340306410486,25.0,90.0
369.78369,0.04504125393700787,893.1898219098451,0.00025370340306410486,25.0,90.0
371.18506,0.045302687007874015,892.4257781535697,0.00025370340306410486,25.0,90.0
372.58643,0.04556160826771653,893.1022300903662,0.00025370340306410486,25.0,90.0
373.98779,0.04587405118110236,894.5504412619564,0.00025370340306410486,25.0,90.0
375.38916,0.04619054921259842,895.1535433070866,0.00025370340306410486,25.0,90.0
376.79053,0.04647100984251969,895.651033134281,0.00025370340306410486,25.0,90.0
378.19189,0.04678856692913386,895.2252814035828,0.00025370340306410486,25.0,90.0
379.59326,0.04710736614173228,898.2404217090314,0.00025370340306410486,25.0,90.0
380.99463,0.047428496062992126,899.102388627596,0.00025370340306410486,25.0,90.0
382.396,0.047756214566929134,900.8287269460445,0.00025370340306410486,25.0,90.0
383.79736,0.04802403149606299,897.9625323680177,0.00025370340306410486,25.0,90.0
385.19873,0.04830315748031496,901.3644770913703,0.00025370340306410486,25.0,90.0
386.6001,0.048628921259842514,899.1560534798921,0.00025370340306410486,25.0,90.0
388.00146,0.048994017716535436,901.1068805157744,0.00025370340306410486,25.0,90.0
389.40283,0.04936453740157481,902.1593563388469,0.00025370340306410486,25.0,90.0
390.8042,0.04969917913385827,902.1664376684458,0.00025370340306410486,25.0,90.0
392.20557,0.05002533267716535,902.3037837552185,0.00025370340306410486,25.0,90.0
393.60693,0.05030640748031496,902.503567087671,0.00025370340306410486,25.0,90.0
395.0083,0.05060428543307086,904.0402420335041,0.00025370340306410486,25.0,90.0
396.40967,0.05093588188976378,903.5946731490778,0.00025370340306410486,25.0,90.0
397.81104,0.05128711023622047,906.1154151033134,0.00025370340306410486,25.0,90.0
399.2124,0.05157577559055118,904.4196216244782,0.00025370340306410486,25.0,90.0
400.61377,0.051897078740157476,906.0625957829096,0.00025370340306410486,25.0,90.0
402.01514,0.052197007874015745,905.8966073032816,0.00025370340306410486,25.0,90.0
403.4165,0.05245120078740158,904.9843312371189,0.00025370340306410486,25.0,90.0
404.81787,0.05275597047244095,906.0815674047456,0.00025370340306410486,25.0,90.0
406.21924,0.05305517322834646,908.0649474184854,0.00025370340306410486,25.0,90.0
407.62061,0.053341159448818905,909.2363525867991,0.00025370340306410486,25.0,90.0
409.02197,0.053614336614173225,910.2053585583681,0.00025370340306410486,25.0,90.0
410.42334,0.05397660433070866,909.9062252285578,0.00025370340306410486,25.0,90.0
411.82471,0.054309153543307086,910.5966020187074,0.00025370340306410486,25.0,90.0
413.22607,0.05465848031496063,909.1998626010675,0.00025370340306410486,25.0,90.0
414.62744,0.05496284448818898,910.0617502510173,0.00025370340306410486,25.0,90.0
416.02881,0.0553343937007874,912.0620409026052,0.00025370340306410486,25.0,90.0
417.43018,0.05566387401574803,912.0913438672515,0.00025370340306410486,25.0,90.0
418.83154,0.05601366535433071,912.8013792738994,0.00025370340306410486,25.0,90.0
420.23291,0.056339383858267714,911.7381493420704,0.00025370340306410486,25.0,90.0
421.63428,0.05659526771653543,911.1887914178512,0.00025370340306410486,25.0,90.0
423.03564,0.05691205708661417,914.6860170163293,0.00025370340306410486,25.0,90.0
424.43701,0.0572535,915.8146699783332,0.00025370340306410486,25.0,90.0
425.83838,0.05760184645669291,915.3715584209691,0.00025370340306410486,25.0,90.0
427.23975,0.057925212598425195,916.3077736088358,0.00025370340306410486,25.0,90.0
428.64111,0.05822033858267716,915.1275167785234,0.00025370340306410486,25.0,90.0
430.04248,0.058554505905511804,917.2691433705014,0.00025370340306410486,25.0,90.0
431.44385,0.0588701811023622,917.3829995243883,0.00025370340306410486,25.0,90.0
432.84521,0.05917970866141733,916.8188183691803,0.00025370340306410486,25.0,90.0
434.24658,0.05951262795275591,917.3988796702425,0.00025370340306410486,25.0,90.0
435.64795,0.059792681102362195,918.5256566083601,0.00025370340306410486,25.0,90.0
437.04932,0.06011678149606299,918.3834751360778,0.00025370340306410486,25.0,90.0
438.45068,0.0604471594488189,919.0515245996935,0.00025370340306410486,25.0,90.0
439.85205,0.06075767125984252,919.8796438196903,0.00025370340306410486,25.0,90.0
441.25342,0.06104769291338582,920.6384558473815,0.00025370340306410486,25.0,90.0
442.65479,0.0612956220472441,918.9616075675103,0.00025370340306410486,25.0,90.0
444.05615,0.0615761279527559,922.212730539555,0.00025370340306410486,25.0,90.0
445.45752,0.061888968503937,922.4994715425671,0.00025370340306410486,25.0,90.0
446.85889,0.06221287598425197,921.9677376737304,0.00025370340306410486,25.0,90.0
448.26025,0.062512781496063,923.2247529461501,0.00025370340306410486,25.0,90.0
449.66162,0.06287583070866141,924.769618982191,0.00025370340306410486,25.0,90.0
451.06299,0.06325283070866142,925.0232521270411,0.00025370340306410486,25.0,90.0
452.46436,0.06355289566929133,922.4174285261322,0.00025370340306410486,25.0,90.0
453.86572,0.0638576062992126,924.682899117476,0.00025370340306410486,25.0,90.0
455.26709,0.06420164173228346,926.5641811552078,0.00025370340306410486,25.0,90.0
456.66846,0.06452726181102363,924.4994451196956,0.00025370340306410486,25.0,90.0
458.06982,0.06488338188976378,927.5614331765576,0.00025370340306410486,25.0,90.0
459.47119,0.06521896259842519,924.5735612746392,0.00025370340306410486,25.0,90.0
460.87256,0.06554708661417322,927.2581778787718,0.00025370340306410486,25.0,90.0
462.27393,0.06587758858267716,928.7158748612799,0.00025370340306410486,25.0,90.0
463.67529,0.06619636614173229,929.3341436347301,0.00025370340306410486,25.0,90.0
465.07666,0.06650340157480315,929.9840670084023,0.00025370340306410486,25.0,90.0
466.47803,0.06682164173228347,926.7997674787296,0.00025370340306410486,25.0,90.0
467.87939,0.06708367913385826,927.4079691380858,0.00025370340306410486,25.0,90.0
469.28076,0.06743066338582676,929.8214342334725,0.00025370340306410486,25.0,90.0
470.68213,0.06777458858267717,929.551339639592,0.00025370340306410486,25.0,90.0
472.0835,0.0681105157480315,929.2418749669713,0.00025370340306410486,25.0,90.0
473.48486,0.06840299409448819,930.6654071764519,0.00025370340306410486,25.0,90.0
474.88623,0.06872525196850393,931.1701104476034,0.00025370340306410486,25.0,90.0
476.2876,0.06907603346456692,931.5057601860169,0.00025370340306410486,25.0,90.0
477.68896,0.06936473031496064,931.3559160809597,0.00025370340306410486,25.0,90.0
479.09033,0.06970913976377953,931.9162394969085,0.00025370340306410486,25.0,90.0
480.4917,0.07001410826771653,933.1797019500078,0.00025370340306410486,25.0,90.0
481.89307,0.07035945275590551,934.6657242509116,0.00025370340306410486,25.0,90.0
483.29443,0.07066825787401575,933.7068646620514,0.00025370340306410486,25.0,90.0
484.6958,0.07094374803149606,932.6519579347882,0.00025370340306410486,25.0,90.0
486.09717,0.07124858858267716,934.9374570628336,0.00025370340306410486,25.0,90.0
487.49854,0.07154551377952756,934.8066110024837,0.00025370340306410486,25.0,90.0
488.8999,0.0718798405511811,935.5584209691908,0.00025370340306410486,25.0,90.0
490.30127,0.07222917322834645,936.5608254505099,0.00025370340306410486,25.0,90.0
491.70264,0.07261538188976377,936.7351107118321,0.00025370340306410486,25.0,90.0
493.104,0.07292090354330709,937.0721872853142,0.00025370340306410486,25.0,90.0
494.50537,0.07329020472440945,937.6590128415155,0.00025370340306410486,25.0,90.0
495.90674,0.07366916535433071,939.2194947946942,0.00025370340306410486,25.0,90.0
497.30811,0.07400168307086613,936.3452148179464,0.00025370340306410486,25.0,90.0
498.70947,0.07430427165354331,939.665116524864,0.00025370340306410486,25.0,90.0
500.11084,0.07464040354330709,937.925751730698,0.00025370340306410486,25.0,90.0
501.51221,0.07494970275590551,938.8211435818845,0.00025370340306410486,25.0,90.0
502.91357,0.07529008858267716,940.3004016276489,0.00025370340306410486,25.0,90.0
504.31494,0.07559074606299213,940.3087248322147,0.00025370340306410486,25.0,90.0
505.71631,0.07593647637795276,941.9036357871373,0.00025370340306410486,25.0,90.0
507.11768,0.07627683858267716,939.8611478095439,0.00025370340306410486,25.0,90.0
508.51904,0.07661928346456692,941.0699149183532,0.00025370340306410486,25.0,90.0
509.92041,0.07697119685039369,941.911245574169,0.00025370340306410486,25.0,90.0
511.32178,0.07732342125984253,941.281139354225,0.00025370340306410486,25.0,90.0
512.72314,0.07761093897637796,941.8612006552871,0.00025370340306410486,25.0,90.0
514.12451,0.07792490748031496,943.4075463721397,0.00025370340306410486,25.0,90.0
515.52588,0.07823464566929134,943.9872113301274,0.00025370340306410486,25.0,90.0
516.92725,0.07852739566929133,942.4989166622628,0.00025370340306410486,25.0,90.0
518.32861,0.07883852362204724,943.094144691645,0.00025370340306410486,25.0,90.0
519.72998,0.07916775787401574,944.9942662368545,0.00025370340306410486,25.0,90.0
521.13135,0.07950443503937007,944.8202716271204,0.00025370340306410486,25.0,90.0
522.53271,0.0798275216535433,944.493288590604,0.00025370340306410486,25.0,90.0
523.93408,0.08018936023622046,947.2142102203667,0.00025370340306410486,25.0,90.0
525.33545,0.08053665748031495,946.2645193679649,0.00025370340306410486,25.0,90.0
526.73682,0.08090748031496063,947.5445489615811,0.00025370340306410486,25.0,90.0
528.13818,0.08125681889763779,945.9934999735771,0.00025370340306410486,25.0,90.0
529.53955,0.08159744488188976,947.064603921154,0.00025370340306410486,25.0,90.0
530.94092,0.08195667913385828,946.9296623157004,0.00025370340306410486,25.0,90.0
532.34229,0.0822903779527559,949.2132854198594,0.00025370340306410486,25.0,90.0
533.74365,0.08265922244094488,947.3400095122337,0.00025370340306410486,25.0,90.0
535.14502,0.08299456889763779,947.3226496855677,0.00025370340306410486,25.0,90.0
536.54639,0.08338774212598425,949.4181683665381,0.00025370340306410486,25.0,90.0
537.94775,0.0837689311023622,949.8190297521535,0.00025370340306410486,25.0,90.0
539.34912,0.08411274212598426,949.0998784547904,0.00025370340306410486,25.0,90.0
540.75049,0.0843822657480315,947.2206574010462,0.00025370340306410486,25.0,90.0
542.15186,0.08469510236220472,950.7409237435925,0.00025370340306410486,25.0,90.0
543.55322,0.08506486811023621,950.5393172329968,0.00025370340306410486,25.0,90.0
544.95459,0.08540849803149606,952.9442741637162,0.00025370340306410486,25.0,90.0
546.35596,0.08573791338582677,951.0804840670083,0.00025370340306410486,25.0,90.0
547.75732,0.08608282874015748,953.0590551181101,0.00025370340306410486,25.0,90.0
549.15869,0.08642687598425197,951.1288114992337,0.00025370340306410486,25.0,90.0
550.56006,0.08678802952755905,954.2794218675685,0.00025370340306410486,25.0,90.0
551.96143,0.08713566732283465,951.4495587380436,0.00025370340306410486,25.0,90.0
553.36279,0.08743983267716536,951.6727527347672,0.00025370340306410486,25.0,90.0
554.76416,0.08771908858267716,953.9677112508587,0.00025370340306410486,25.0,90.0
556.16553,0.08806668897637794,952.9226074089731,0.00025370340306410486,25.0,90.0
557.56689,0.08841005511811023,955.6300533742007,0.00025370340306410486,25.0,90.0
558.96826,0.08874513779527558,955.9930507847592,0.00025370340306410486,25.0,90.0
560.36963,0.08911682283464567,956.2666860434391,0.00025370340306410486,25.0,90.0
561.771,0.089491,955.0727685884901,0.00025370340306410486,25.0,90.0
563.17236,0.08988153937007874,956.3355176240553,0.00025370340306410486,25.0,90.0
564.57373,0.09020923622047244,955.0543782698303,0.00025370340306410486,25.0,90.0
565.9751,0.09055680314960629,957.3760503091476,0.00025370340306410486,25.0,90.0
567.37646,0.09093458267716535,955.7161655128679,0.00025370340306410486,25.0,90.0
568.77783,0.09130558661417322,958.1662262854727,0.00025370340306410486,25.0,90.0
570.1792,0.09168904527559055,956.9780425936691,0.00025370340306410486,25.0,90.0
571.58057,0.09199460629921259,957.8236009089468,0.00025370340306410486,25.0,90.0
572.98193,0.09233924015748032,959.8648734344448,0.00025370340306410486,25.0,90.0
574.3833,0.09271199803149606,960.9651482323098,0.00025370340306410486,25.0,90.0
575.78467,0.09310377559055118,958.4523067166939,0.00025370340306410486,25.0,90.0
577.18604,0.09348680511811024,959.5874861279923,0.00025370340306410486,25.0,90.0
578.5874,0.09383330511811024,960.0150346139618,0.00025370340306410486,25.0,90.0
579.98877,0.0942223188976378,958.7034561116102,0.00025370340306410486,25.0,90.0
581.39014,0.09453815354330708,957.4032658669344,0.00025370340306410486,25.0,90.0
582.7915,0.09486786811023622,960.4609998414627,0.00025370340306410486,25.0,90.0
584.19287,0.0951345748031496,959.3751255086402,0.00025370340306410486,25.0,90.0
585.59424,0.0954045846456693,958.8086719864715,0.00025370340306410486,25.0,90.0
586.99561,0.09573604724409449,961.1075146646937,0.00025370340306410486,25.0,90.0
588.39697,0.0960820531496063,962.0709454103471,0.00025370340306410486,25.0,90.0
589.79834,0.09648084251968503,961.0164086032869,0.00025370340306410486,25.0,90.0
591.19971,0.09684745078740158,961.2584685303598,0.00025370340306410486,25.0,90.0
592.60107,0.09721017125984252,963.2249379062516,0.00025370340306410486,25.0,90.0
594.00244,0.09756822834645669,962.9915446810759,0.00025370340306410486,25.0,90.0
595.40381,0.09797286417322834,964.3723775299899,0.00025370340306410486,25.0,90.0
596.80518,0.09834184448818897,962.3072979971462,0.00025370340306410486,25.0,90.0
598.20654,0.09872685826771653,963.0562014479733,0.00025370340306410486,25.0,90.0
599.60791,0.09910003149606299,963.9234529408656,0.00025370340306410486,25.0,90.0
601.00928,0.09943408661417322,964.311472810865,0.00025370340306410486,25.0,90.0
602.41064,0.09979192716535433,965.3257411615493,0.00025370340306410486,25.0,90.0
603.81201,0.10019288582677165,964.2365903926438,0.00025370340306410486,25.0,90.0
605.21338,0.10051544291338581,965.2392326798076,0.00025370340306410486,25.0,90.0
606.61475,0.10094717716535433,964.5180996670717,0.00025370340306410486,25.0,90.0
608.01611,0.1013364251968504,966.3128732230618,0.00025370340306410486,25.0,90.0
609.41748,0.1016780846456693,965.508825239127,0.00025370340306410486,25.0,90.0
610.81885,0.10207134645669291,966.5518680970248,0.00025370340306410486,25.0,90.0
612.22021,0.10239957086614174,966.8463510014267,0.00025370340306410486,25.0,90.0
613.62158,0.10274979527559056,965.3540664799449,0.00025370340306410486,25.0,90.0
615.02295,0.1030885905511811,967.018522433018,0.00025370340306410486,25.0,90.0
616.42432,0.10344742716535432,966.8791946308725,0.00025370340306410486,25.0,90.0
617.82568,0.1038521062992126,967.945516038683,0.00025370340306410486,25.0,90.0
619.22705,0.10421320669291338,968.8221212281351,0.00025370340306410486,25.0,90.0
620.62842,0.10463100196850394,968.230962320985,0.00025370340306410486,25.0,90.0
622.02979,0.10505459448818898,970.9321460656345,0.00025370340306410486,25.0,90.0
623.43115,0.10542809645669292,967.3182370660044,0.00025370340306410486,25.0,90.0
624.83252,0.10574846062992126,967.4205464249853,0.00025370340306410486,25.0,90.0
626.23389,0.10606157283464568,969.4989695080061,0.00025370340306410486,25.0,90.0
627.63525,0.10644066141732282,971.1549172964117,0.00025370340306410486,25.0,90.0
629.03662,0.10685276574803149,970.545949373778,0.00025370340306410486,25.0,90.0
630.43799,0.10725080314960629,970.2790783702372,0.00025370340306410486,25.0,90.0
631.83936,0.10756720078740156,968.5284310098821,0.00025370340306410486,25.0,90.0
633.24072,0.10800346456692912,970.730750938012,0.00025370340306410486,25.0,90.0
634.64209,0.1083846161417323,970.516408603287,0.00025370340306410486,25.0,90.0
636.04346,0.10871217322834646,970.3224118797231,0.00025370340306410486,25.0,90.0
637.44482,0.10910183267716535,970.4838292025577,0.00025370340306410486,25.0,90.0
638.84619,0.10949799212598425,971.7703852454684,0.00025370340306410486,25.0,90.0
640.24756,0.10986467716535432,971.5193151191671,0.00025370340306410486,25.0,90.0
641.64893,0.11028452559055117,971.8457961211224,0.00025370340306410486,25.0,90.0
643.05029,0.11063567716535433,971.3819161866511,0.00025370340306410486,25.0,90.0
644.45166,0.11102675590551181,971.7983142207895,0.00025370340306410486,25.0,90.0
645.85303,0.11140928346456692,970.2339216826084,0.00025370340306410486,25.0,90.0
647.25439,0.11172942322834646,970.9172435660306,0.00025370340306410486,25.0,90.0
648.65576,0.11213542716535432,974.7782592612164,0.00025370340306410486,25.0,90.0
650.05713,0.11253149212598425,974.7957247793689,0.00025370340306410486,25.0,90.0
651.4585,0.11293705118110237,973.6205675632827,0.00025370340306410486,25.0,90.0
652.85986,0.1132768562992126,973.6995983723511,0.00025370340306410486,25.0,90.0
654.26123,0.11369886417322835,974.8166252708344,0.00025370340306410486,25.0,90.0
655.6626,0.11406085629921259,972.9083919040321,0.00025370340306410486,25.0,90.0
657.06396,0.11441164370078741,974.2375944617661,0.00025370340306410486,25.0,90.0
658.46533,0.1148733562992126,975.7912857369338,0.00025370340306410486,25.0,90.0
659.8667,0.11529503543307086,974.0198699994714,0.00025370340306410486,25.0,90.0
661.26807,0.11571861614173228,976.3288590604027,0.00025370340306410486,25.0,90.0
662.66943,0.11615310826771653,975.0318395603234,0.00025370340306410486,25.0,90.0
664.0708,0.11648376181102361,976.805131321672,0.00025370340306410486,25.0,90.0
665.47217,0.11684766732283465,975.0450509961422,0.00025370340306410486,25.0,90.0
666.87354,0.11727450787401573,976.1988056862019,0.00025370340306410486,25.0,90.0
668.2749,0.11769296062992125,975.5112032975743,0.00025370340306410486,25.0,90.0
669.67627,0.11805200984251968,975.8131638746498,0.00025370340306410486,25.0,90.0
671.07764,0.11847584645669292,975.5501506103683,0.00025370340306410486,25.0,90.0
672.479,0.11887762795275592,977.1429477355599,0.00025370340306410486,25.0,90.0
673.88037,0.11929669094488189,977.0959150240448,0.00025370340306410486,25.0,90.0
675.28174,0.11972924606299212,978.199809755324,0.00025370340306410486,25.0,90.0
676.68311,0.12016058267716535,977.3386091000369,0.00025370340306410486,25.0,90.0
678.08447,0.1205268464566929,976.0503091475981,0.00025370340306410486,25.0,90.0
679.48584,0.12093174606299213,976.1814458595359,0.00025370340306410486,25.0,90.0
680.88721,0.12127251377952757,976.243645299371,0.00025370340306410486,25.0,90.0
682.28857,0.12165846456692914,978.9132008666701,0.00025370340306410486,25.0,90.0
683.68994,0.12210624015748031,976.7078951540452,0.00025370340306410486,25.0,90.0
685.09131,0.12249938385826771,978.9016012260213,0.00025370340306410486,25.0,90.0
686.49268,0.12294930511811024,979.2117528933044,0.00025370340306410486,25.0,90.0
687.89404,0.12338270669291337,979.9193573957617,0.00025370340306410486,25.0,90.0
689.29541,0.1237822559055118,979.1722771230777,0.00025370340306410486,25.0,90.0
690.69678,0.12412297637795275,977.1097341859113,0.00025370340306410486,25.0,90.0
692.09814,0.12449637401574802,979.3185805633356,0.00025370340306410486,25.0,90.0
693.49951,0.12494276377952755,980.3293082492205,0.00025370340306410486,25.0,90.0
694.90088,0.12537544881889762,979.2687206045554,0.00025370340306410486,25.0,90.0
696.30225,0.12581988976377953,979.5546160756751,0.00025370340306410486,25.0,90.0
697.70361,0.1262076023622047,980.3473814934206,0.00025370340306410486,25.0,90.0
699.10498,0.12662423622047242,980.3207208159382,0.00025370340306410486,25.0,90.0
700.50635,0.12695487795275592,980.1085451566876,0.00025370340306410486,25.0,90.0
701.90771,0.12742637598425197,980.5790836548116,0.00025370340306410486,25.0,90.0
703.30908,0.12786144291338583,979.9112984199122,0.00025370340306410486,25.0,90.0
704.71045,0.12829066732283465,979.4250911589071,0.00025370340306410486,25.0,90.0
706.11182,0.1286825098425197,980.2687998731701,0.00025370340306410486,25.0,90.0
707.51318,0.12919440551181102,982.5541668868573,0.00025370340306410486,25.0,90.0
708.91455,0.1296884665354331,981.599693494689,0.00025370340306410486,25.0,90.0
710.31592,0.13015562401574804,982.1546530676953,0.00025370340306410486,25.0,90.0
711.71729,0.13059487992125984,981.0684616604133,0.00025370340306410486,25.0,90.0
713.11865,0.13103871062992126,981.0267135232257,0.00025370340306410486,25.0,90.0
714.52002,0.13145755118110236,981.7422448871743,0.00025370340306410486,25.0,90.0
715.92139,0.1318463188976378,981.9155260793742,0.00025370340306410486,25.0,90.0
717.32275,0.13227170669291338,983.2406066691327,0.00025370340306410486,25.0,90.0
718.72412,0.13271911614173226,983.3800665856365,0.00025370340306410486,25.0,90.0
720.12549,0.13311712992125985,983.269037679015,0.00025370340306410486,25.0,90.0
721.52686,0.1334943405511811,981.7587591819478,0.00025370340306410486,25.0,90.0
722.92822,0.13393308070866142,982.8454262009195,0.00025370340306410486,25.0,90.0
724.32959,0.13438599409448818,982.792659726259,0.00025370340306410486,25.0,90.0
725.73096,0.13490941141732282,982.8401152037203,0.00025370340306410486,25.0,90.0
727.13232,0.1353527027559055,982.0885430428579,0.00025370340306410486,25.0,90.0
728.53369,0.13573802165354332,985.0229086297098,0.00025370340306410486,25.0,90.0
729.93506,0.1361662716535433,983.863763673836,0.00025370340306410486,25.0,90.0
731.33643,0.13663331102362203,983.4634043227818,0.00025370340306410486,25.0,90.0
732.73779,0.13702960039370077,984.0409026052951,0.00025370340306410486,25.0,90.0
734.13916,0.13746721259842518,982.9053532737938,0.00025370340306410486,25.0,90.0
735.54053,0.13790655118110234,984.2223484648312,0.00025370340306410486,25.0,90.0
736.94189,0.13835918307086614,984.1821592770701,0.00025370340306410486,25.0,90.0
738.34326,0.1388321712598425,984.4293716641124,0.00025370340306410486,25.0,90.0
739.74463,0.13923910236220471,982.4503514241927,0.00025370340306410486,25.0,90.0
741.146,0.13964564566929133,983.674813718755,0.00025370340306410486,25.0,90.0
742.54736,0.14009580118110235,983.9549754267293,0.00025370340306410486,25.0,90.0
743.94873,0.14055322047244093,986.3140622522856,0.00025370340306410486,25.0,90.0
745.3501,0.1410581220472441,986.2091634518839,0.00025370340306410486,25.0,90.0
746.75146,0.14159180708661417,983.5982402367489,0.00025370340306410486,25.0,90.0
748.15283,0.14203013582677165,985.2118057390477,0.00025370340306410486,25.0,90.0
749.5542,0.1424775118110236,985.0287745072134,0.00025370340306410486,25.0,90.0
750.95557,0.14293929527559054,986.9097394704855,0.00025370340306410486,25.0,90.0
752.35693,0.1434461811023622,984.2451249801828,0.00025370340306410486,25.0,90.0
753.7583,0.1439359251968504,985.0225915552501,0.00025370340306410486,25.0,90.0
755.15967,0.14440230708661417,986.3688897109338,0.00025370340306410486,25.0,90.0
756.56104,0.14486918307086616,984.7370660043333,0.00025370340306410486,25.0,90.0
757.9624,0.14530816929133858,985.7173545420916,0.00025370340306410486,25.0,90.0
759.36377,0.14580776771653542,986.2443322940337,0.00025370340306410486,25.0,90.0
760.76514,0.14628938188976376,985.1305289858901,0.00025370340306410486,25.0,90.0
762.1665,0.14678311417322834,986.5517888284098,0.00025370340306410486,25.0,90.0
763.56787,0.1473244251968504,986.269539713576,0.00025370340306410486,25.0,90.0
764.96924,0.14783762401574801,986.2703323997251,0.00025370340306410486,25.0,90.0
766.37061,0.14827784055118112,985.4546055065264,0.00025370340306410486,25.0,90.0
767.77197,0.14873066141732283,986.0667441737568,0.00025370340306410486,25.0,90.0
769.17334,0.1491830098425197,986.7124134650953,0.00025370340306410486,25.0,90.0
770.57471,0.14967091141732283,984.7970723458225,0.00025370340306410486,25.0,90.0
771.97607,0.1502074468503937,987.1987264175871,0.00025370340306410486,25.0,90.0
773.37744,0.15076893897637797,986.6280980816994,0.00025370340306410486,25.0,90.0
774.77881,0.15123492322834647,984.6603868308407,0.00025370340306410486,25.0,90.0
776.18018,0.15169765748031497,986.7366696612588,0.00025370340306410486,25.0,90.0
777.58154,0.15213038976377954,983.6220472440945,0.00025370340306410486,25.0,90.0
778.98291,0.1526247559055118,987.7662104317498,0.00025370340306410486,25.0,90.0
780.38428,0.15312832086614173,985.3901601226021,0.00025370340306410486,25.0,90.0
781.78564,0.15367281299212598,987.4532315172012,0.00025370340306410486,25.0,90.0
783.18701,0.15414168307086615,984.3741478623896,0.00025370340306410486,25.0,90.0
784.58838,0.15461693503937007,987.0531363948633,0.00025370340306410486,25.0,90.0
785.98975,0.1551300531496063,985.7933467209216,0.00025370340306410486,25.0,90.0
787.39111,0.1556096692913386,986.5993764202293,0.00025370340306410486,25.0,90.0
788.79248,0.15619162401574804,986.7977593404851,0.00025370340306410486,25.0,90.0
790.19385,0.15672725787401573,987.2551128256619,0.00025370340306410486,25.0,90.0
791.59521,0.1572847598425197,986.5924272049886,0.00025370340306410486,25.0,90.0
792.99658,0.15784242716535432,986.9017333403793,0.00025370340306410486,25.0,90.0
794.39795,0.1583800531496063,986.8970829149711,0.00025370340306410486,25.0,90.0
795.79932,0.1588311594488189,984.0643661153093,0.00025370340306410486,25.0,90.0
797.20068,0.15932735826771652,986.899355281932,0.00025370340306410486,25.0,90.0
798.60205,0.15987771456692915,986.1105268720604,0.00025370340306410486,25.0,90.0
800.00342,0.1604667913385827,987.4091053215662,0.00025370340306410486,25.0,90.0
801.40479,0.16094575196850394,985.0681974316968,0.00025370340306410486,25.0,90.0
802.80615,0.1614587755905512,985.2631453786397,0.00025370340306410486,25.0,90.0
804.20752,0.16198140748031495,986.4978597473973,0.00025370340306410486,25.0,90.0
805.60889,0.162466,986.4687417428526,0.00025370340306410486,25.0,90.0
807.01025,0.16298609645669293,988.2161655128679,0.00025370340306410486,25.0,90.0
808.41162,0.16356125787401574,985.5855572583628,0.00025370340306410486,25.0,90.0
809.81299,0.164150781496063,986.9228452148179,0.00025370340306410486,25.0,90.0
811.21436,0.16470639566929135,986.4715161443745,0.00025370340306410486,25.0,90.0
812.61572,0.16526590354330709,988.1932833060296,0.00025370340306410486,25.0,90.0
814.01709,0.1658836338582677,987.4505892300375,0.00025370340306410486,25.0,90.0
815.41846,0.16641560433070868,987.255826243196,0.00025370340306410486,25.0,90.0
816.81982,0.166865937007874,985.5896792263383,0.00025370340306410486,25.0,90.0
817.62061,0.16720846456692914,990.3309728901337,0.00025370340306410486,25.0,90.0