File: datasets/am_bench_2022/csv/90-XY.16-4.csv
Time(s),Strain(%),Stress(MPa),SR(s-1),Temp(C),Angle(deg)
11.45874,2.1568173228346456e-05,17.972535328779266,0.00025370340306410486,25.0,90.0
12.76001,4.91661437007874e-05,23.451965896647025,0.00025370340306410486,25.0,90.0
14.061279,5.435516732283465e-05,28.313028628044012,0.00025370340306410486,25.0,90.0
15.362549,6.907968897637795e-05,31.927908431975805,0.00025370340306410486,25.0,90.0
16.663818,7.361310236220472e-05,36.974818793346195,0.00025370340306410486,25.0,90.0
17.965088,7.760040748031497e-05,41.76338582677165,0.00025370340306410486,25.0,90.0
19.266357,0.00010952749999999999,49.50807216978673,0.00025370340306410486,25.0,90.0
20.567627,0.00013131188779527559,55.86457475100381,0.00025370340306410486,25.0,90.0
21.868896,0.00014905572637795276,61.82174740574647,0.00025370340306410486,25.0,90.0
23.170166,0.00014642441929133858,68.88873389998436,0.00025370340306410486,25.0,90.0
24.471436,0.00016612843307086615,74.69267612243834,0.00025370340306410486,25.0,90.0
25.772705,0.00018755546456692912,80.14417009959848,0.00025370340306410486,25.0,90.0
27.073975,0.00022607356299212598,87.70378317776503,0.00025370340306410486,25.0,90.0
28.375244,0.00023856305118110237,95.81403243468739,0.00025370340306410486,25.0,90.0
29.676514,0.00026591881889763777,101.63087031339624,0.00025370340306410486,25.0,90.0
30.977783,0.00029976029527559053,109.98152735047192,0.00025370340306410486,25.0,90.0
32.279053,0.00033160732283464567,118.11131042394535,0.00025370340306410486,25.0,90.0
33.580322,0.000369242342519685,127.88109714762477,0.00025370340306410486,25.0,90.0
34.881592,0.0003933361614173228,134.33636648067997,0.00025370340306410486,25.0,90.0
36.182861,0.0004201234645669291,143.23388694790634,0.00025370340306410486,25.0,90.0
37.484131,0.0004196499606299213,150.25417166397247,0.00025370340306410486,25.0,90.0
38.7854,0.0004776308464566929,158.43115450800437,0.00025370340306410486,25.0,90.0
40.08667,0.0005160733464566929,168.8379412838296,0.00025370340306410486,25.0,90.0
41.387939,0.0005285230905511811,176.5356520832247,0.00025370340306410486,25.0,90.0
42.689209,0.0005685982283464567,184.88827240965742,0.00025370340306410486,25.0,90.0
43.990479,0.0005846964566929134,193.05136361266102,0.00025370340306410486,25.0,90.0
45.291748,0.0006210029133858268,203.32179955154612,0.00025370340306410486,25.0,90.0
46.593018,0.0006665673622047244,212.89579444125775,0.00025370340306410486,25.0,90.0
47.894287,0.0006954162204724409,223.7853183501069,0.00025370340306410486,25.0,90.0
49.195557,0.0007319178937007874,231.14023569901445,0.00025370340306410486,25.0,90.0
50.496826,0.0007477201181102362,241.56331542994212,0.00025370340306410486,25.0,90.0
51.798096,0.0007974870275590552,251.07241226469208,0.00025370340306410486,25.0,90.0
53.099365,0.0008197957874015748,261.32035772018565,0.00025370340306410486,25.0,90.0
54.400635,0.0008713018503937008,271.7958491943474,0.00025370340306410486,25.0,90.0
55.701904,0.0008857811811023621,280.87727486050994,0.00025370340306410486,25.0,90.0
57.003174,0.0009226199409448819,290.3655942013871,0.00025370340306410486,25.0,90.0
58.304443,0.0009670968110236219,298.4498096678313,0.00025370340306410486,25.0,90.0
59.605713,0.0010053731692913387,310.3880429681389,0.00025370340306410486,25.0,90.0
60.906982,0.0010287675984251969,319.09315847108513,0.00025370340306410486,25.0,90.0
62.208252,0.0010598146653543307,325.32963967252437,0.00025370340306410486,25.0,90.0
63.509521,0.0010924775787401575,335.5025290712833,0.00025370340306410486,25.0,90.0
64.810791,0.0011416435433070867,345.6801898107107,0.00025370340306410486,25.0,90.0
66.112061,0.0011576095866141732,353.5592115555092,0.00025370340306410486,25.0,90.0
67.41333,0.0011959197440944882,363.3871043437451,0.00025370340306410486,25.0,90.0
68.7146,0.0012269939370078739,371.3987589299682,0.00025370340306410486,25.0,90.0
70.015869,0.00126794031496063,382.8501068988893,0.00025370340306410486,25.0,90.0
71.317139,0.0013214235433070866,394.532121812588,0.00025370340306410486,25.0,90.0
72.618408,0.0013317624015748031,401.6602440423424,0.00025370340306410486,25.0,90.0
73.919678,0.001372625472440945,410.34697815091,0.00025370340306410486,25.0,90.0
75.220947,0.0014303000984251968,420.02516034833394,0.00025370340306410486,25.0,90.0
76.522217,0.0014546520669291337,431.26857694112744,0.00025370340306410486,25.0,90.0
77.823486,0.0014891015551181102,438.63735203629346,0.00025370340306410486,25.0,90.0
79.124756,0.0015318125984251968,445.3549303853575,0.00025370340306410486,25.0,90.0
80.426025,0.0015537131692913387,457.0739688168118,0.00025370340306410486,25.0,90.0
81.727295,0.001597972992125984,465.71450174688425,0.00025370340306410486,25.0,90.0
83.028564,0.001637657775590551,474.52005005996773,0.00025370340306410486,25.0,90.0
84.329834,0.0016734916929133858,484.53598060176256,0.00025370340306410486,25.0,90.0
85.631104,0.00169405468503937,492.3495072221932,0.00025370340306410486,25.0,90.0
86.932373,0.0017413985039370077,501.39935860666424,0.00025370340306410486,25.0,90.0
88.233643,0.0017635385039370078,509.2792929029567,0.00025370340306410486,25.0,90.0
89.534912,0.0018083299803149607,518.1621995098295,0.00025370340306410486,25.0,90.0
90.836182,0.0018542863385826772,528.0108202534286,0.00025370340306410486,25.0,90.0
92.137451,0.001884347165354331,535.0857276946342,0.00025370340306410486,25.0,90.0
93.438721,0.0019178357283464566,542.8939875892997,0.00025370340306410486,25.0,90.0
94.73999,0.0019336533661417324,548.009386243938,0.00025370340306410486,25.0,90.0
96.04126,0.001973156496062992,554.7218803775356,0.00025370340306410486,25.0,90.0
97.342529,0.002002666929133858,563.4148719820619,0.00025370340306410486,25.0,90.0
98.643799,0.0020338431102362203,570.0390832768421,0.00025370340306410486,25.0,90.0
99.945068,0.0020750175196850395,578.3142305887261,0.00025370340306410486,25.0,90.0
101.24634,0.0020845649606299212,583.1482765813214,0.00025370340306410486,25.0,90.0
102.54761,0.0021301551181102363,589.5131146686134,0.00025370340306410486,25.0,90.0
103.84888,0.0021630649606299212,597.1916358137353,0.00025370340306410486,25.0,90.0
105.15015,0.002188078149606299,603.4715805391876,0.00025370340306410486,25.0,90.0
106.45142,0.0022134183070866144,607.4740574646712,0.00025370340306410486,25.0,90.0
107.75269,0.0022351179133858266,610.5899515044063,0.00025370340306410486,25.0,90.0
109.05396,0.002272366338582677,617.4673045836158,0.00025370340306410486,25.0,90.0
110.35522,0.0022961108267716534,623.1759920738384,0.00025370340306410486,25.0,90.0
111.65649,0.0023288415354330706,627.8360014600823,0.00025370340306410486,25.0,90.0
112.95776,0.002368030118110236,632.8721645721437,0.00025370340306410486,25.0,90.0
114.25903,0.0024056013779527557,637.983939093706,0.00025370340306410486,25.0,90.0
115.5603,0.002434220275590551,643.3886426448349,0.00025370340306410486,25.0,90.0
116.86157,0.002472840354330709,648.5926109401887,0.00025370340306410486,25.0,90.0
118.16284,0.0024883102362204725,651.1587057412526,0.00025370340306410486,25.0,90.0
119.46411,0.002506930118110236,655.5616884809929,0.00025370340306410486,25.0,90.0
120.76538,0.00254504094488189,659.3363404077802,0.00025370340306410486,25.0,90.0
122.06665,0.002594736220472441,662.7659957240444,0.00025370340306410486,25.0,90.0
123.36792,0.0026324444881889765,668.8404077801533,0.00025370340306410486,25.0,90.0
124.66919,0.0026651952755905512,672.6624080930281,0.00025370340306410486,25.0,90.0
125.97046,0.002684454724409449,673.8220785315742,0.00025370340306410486,25.0,90.0
127.27173,0.002741780905511811,679.4726234551807,0.00025370340306410486,25.0,90.0
128.573,0.002758495472440945,683.1030401001199,0.00025370340306410486,25.0,90.0
129.87427,0.0028044710629921256,687.1877509516609,0.00025370340306410486,25.0,90.0
131.17554,0.0028653706692913384,690.2290243520885,0.00025370340306410486,25.0,90.0
132.47681,0.0028838856299212598,692.9734317150754,0.00025370340306410486,25.0,90.0
133.77808,0.0029336616141732285,697.7511602440424,0.00025370340306410486,25.0,90.0
135.07935,0.0029904818897637797,701.200161651979,0.00025370340306410486,25.0,90.0
136.38062,0.0030193734251968505,704.170151744277,0.00025370340306410486,25.0,90.0
137.68188,0.003076861811023622,705.950305052928,0.00025370340306410486,25.0,90.0
138.98315,0.00313899311023622,708.8882776242374,0.00025370340306410486,25.0,90.0
140.28442,0.0031940984251968506,714.1547948062783,0.00025370340306410486,25.0,90.0
141.58569,0.0032242927165354327,716.408171246806,0.00025370340306410486,25.0,90.0
142.88696,0.0032498893700787404,716.7661782343432,0.00025370340306410486,25.0,90.0
144.18823,0.0033148326771653544,721.4290556395682,0.00025370340306410486,25.0,90.0
145.4895,0.0033890322834645666,724.8805339729885,0.00025370340306410486,25.0,90.0
146.79077,0.003458847440944882,728.2291286436878,0.00025370340306410486,25.0,90.0
148.09204,0.003528432086614173,730.2150232048809,0.00025370340306410486,25.0,90.0
149.39331,0.0035980159448818897,731.4024352088439,0.00025370340306410486,25.0,90.0
150.69458,0.003693678937007874,735.9319236585493,0.00025370340306410486,25.0,90.0
151.99585,0.0037422594488188974,737.4123950565781,0.00025370340306410486,25.0,90.0
153.29712,0.003833919488188976,740.7528028367315,0.00025370340306410486,25.0,90.0
154.59839,0.0038805387795275586,743.140611148772,0.00025370340306410486,25.0,90.0
155.89966,0.003987261811023622,745.6634249361214,0.00025370340306410486,25.0,90.0
157.20093,0.004079973228346457,747.1118788131616,0.00025370340306410486,25.0,90.0
158.5022,0.004219339960629921,750.6247848985764,0.00025370340306410486,25.0,90.0
159.80347,0.004323572637795276,752.1892892527508,0.00025370340306410486,25.0,90.0
161.10474,0.004418117716535433,756.0415341294259,0.00025370340306410486,25.0,90.0
162.40601,0.004566446259842519,758.275303749283,0.00025370340306410486,25.0,90.0
163.70728,0.004706050393700788,761.119257443813,0.00025370340306410486,25.0,90.0
165.00854,0.004827484251968504,761.7792146842572,0.00025370340306410486,25.0,90.0
166.30981,0.004978367519685039,764.8231214475674,0.00025370340306410486,25.0,90.0
167.61108,0.005122271259842519,764.5783751368828,0.00025370340306410486,25.0,90.0
168.91235,0.005249336614173228,767.1749752307452,0.00025370340306410486,25.0,90.0
170.21362,0.005409145669291338,767.5985816342494,0.00025370340306410486,25.0,90.0
171.51489,0.005559431102362205,769.927569484278,0.00025370340306410486,25.0,90.0
172.81616,0.0057081291338582675,772.4569014965845,0.00025370340306410486,25.0,90.0
174.11743,0.005892838779527559,774.9636804505398,0.00025370340306410486,25.0,90.0
175.4187,0.006112606299212598,777.9694947072013,0.00025370340306410486,25.0,90.0
176.71997,0.006317093503937008,777.8249465505554,0.00025370340306410486,25.0,90.0
178.02124,0.006473624606299212,779.5185378317777,0.00025370340306410486,25.0,90.0
179.32251,0.006654257283464567,780.0931323981854,0.00025370340306410486,25.0,90.0
180.62378,0.006871322244094488,783.0470876570893,0.00025370340306410486,25.0,90.0
181.92505,0.00705837125984252,784.8028888773009,0.00025370340306410486,25.0,90.0
183.22632,0.007273360826771653,786.0008604056943,0.00025370340306410486,25.0,90.0
184.52759,0.007499004330708661,787.348177504302,0.00025370340306410486,25.0,90.0
185.82886,0.007732923228346456,788.5262814830267,0.00025370340306410486,25.0,90.0
187.13013,0.00797768562992126,790.5547791625385,0.00025370340306410486,25.0,90.0
188.4314,0.008222154921259843,790.9642019085363,0.00025370340306410486,25.0,90.0
189.73267,0.008441743307086613,792.9964801585232,0.00025370340306410486,25.0,90.0
191.03394,0.008673219488188976,795.1030140272202,0.00025370340306410486,25.0,90.0
192.33521,0.00894992559055118,795.9384679564062,0.00025370340306410486,25.0,90.0
193.63647,0.009172428937007874,796.0668769880587,0.00025370340306410486,25.0,90.0
194.93774,0.00940393661417323,797.0932366897847,0.00025370340306410486,25.0,90.0
196.23901,0.009623744094488188,797.5908119101007,0.00025370340306410486,25.0,90.0
197.54028,0.009893984645669292,801.8038535745945,0.00025370340306410486,25.0,90.0
198.84155,0.010137602362204724,799.6411326067686,0.00025370340306410486,25.0,90.0
200.14282,0.010388983267716536,801.3664285341816,0.00025370340306410486,25.0,90.0
201.44409,0.01060382027559055,803.1137560619492,0.00025370340306410486,25.0,90.0
202.74536,0.01083132342519685,804.238332377327,0.00025370340306410486,25.0,90.0
204.04663,0.01110922342519685,805.6633727903218,0.00025370340306410486,25.0,90.0
205.3479,0.011409129133858267,807.8670803566772,0.00025370340306410486,25.0,90.0
206.64917,0.011651324212598424,806.2500651822495,0.00025370340306410486,25.0,90.0
207.95044,0.011888586417322834,808.7017260259686,0.00025370340306410486,25.0,90.0
209.25171,0.012178328937007874,811.3299004015227,0.00025370340306410486,25.0,90.0
210.55298,0.012416492322834646,811.2957188298483,0.00025370340306410486,25.0,90.0
211.85425,0.01266209311023622,811.0658601449654,0.00025370340306410486,25.0,90.0
213.15552,0.012933756102362203,814.4876675183814,0.00025370340306410486,25.0,90.0
214.45679,0.013219392125984252,812.6457475100381,0.00025370340306410486,25.0,90.0
215.75806,0.01346136437007874,813.8264848516452,0.00025370340306410486,25.0,90.0
217.05933,0.013725109055118109,816.0697450070397,0.00025370340306410486,25.0,90.0
218.3606,0.013991077165354332,816.3637430254993,0.00025370340306410486,25.0,90.0
219.66187,0.014265550393700786,817.9686864473066,0.00025370340306410486,25.0,90.0
220.96313,0.014514104921259841,815.3046096886895,0.00025370340306410486,25.0,90.0
222.2644,0.014782798228346458,820.0779318975857,0.00025370340306410486,25.0,90.0
223.56567,0.015071905708661418,818.9809667831256,0.00025370340306410486,25.0,90.0
224.86694,0.015354973425196851,820.0401261928351,0.00025370340306410486,25.0,90.0
226.16821,0.01566782145669291,823.0586900975127,0.00025370340306410486,25.0,90.0
227.46948,0.015909183661417324,822.1689263179851,0.00025370340306410486,25.0,90.0
228.77075,0.016183859251968503,824.342728268238,0.00025370340306410486,25.0,90.0
230.07202,0.016446696062992126,824.3117275903426,0.00025370340306410486,25.0,90.0
231.37329,0.01669571417322835,823.5223966209522,0.00025370340306410486,25.0,90.0
232.67456,0.01700254311023622,826.3866611044481,0.00025370340306410486,25.0,90.0
233.97583,0.01731195649606299,826.3193148041926,0.00025370340306410486,25.0,90.0
235.2771,0.017618795669291337,827.1209261094018,0.00025370340306410486,25.0,90.0
236.57837,0.017888434842519684,829.5378317776502,0.00025370340306410486,25.0,90.0
237.87964,0.018164899803149604,827.9351306252281,0.00025370340306410486,25.0,90.0
239.18091,0.018410349409448818,828.5427856286177,0.00025370340306410486,25.0,90.0
240.48218,0.01873270590551181,831.8414767690464,0.00025370340306410486,25.0,90.0
241.78345,0.019049786811023622,831.1796162069146,0.00025370340306410486,25.0,90.0
243.08472,0.019345051181102364,831.9227720707098,0.00025370340306410486,25.0,90.0
244.38599,0.019628287598425196,834.1839182353862,0.00025370340306410486,25.0,90.0
245.68726,0.019871980314960628,833.8958126922877,0.00025370340306410486,25.0,90.0
246.98853,0.020130679133858267,833.1183188194192,0.00025370340306410486,25.0,90.0
248.28979,0.020382344488188976,834.3982896177713,0.00025370340306410486,25.0,90.0
249.59106,0.020670068897637794,835.7157011002764,0.00025370340306410486,25.0,90.0
250.89233,0.02095668307086614,837.6588100328519,0.00025370340306410486,25.0,90.0
252.1936,0.021214364173228348,837.5597069406059,0.00025370340306410486,25.0,90.0
253.49487,0.02150360433070866,837.8441622777286,0.00025370340306410486,25.0,90.0
254.79614,0.021784870078740158,838.5715440371279,0.00025370340306410486,25.0,90.0
256.09741,0.022087318897637796,839.0570996506232,0.00025370340306410486,25.0,90.0
257.39868,0.02237025,839.5932106168848,0.00025370340306410486,25.0,90.0
258.69995,0.022708604330708662,842.3370443760756,0.00025370340306410486,25.0,90.0
260.00122,0.023009805118110235,841.2793450487563,0.00025370340306410486,25.0,90.0
261.30249,0.02326132283464567,842.1527611200918,0.00025370340306410486,25.0,90.0
262.60376,0.023517248031496064,841.151222819002,0.00025370340306410486,25.0,90.0
263.90503,0.02376242519685039,843.9151066381603,0.00025370340306410486,25.0,90.0
265.2063,0.024071915354330706,845.2736611565938,0.00025370340306410486,25.0,90.0
266.50757,0.02437823622047244,845.4911091411587,0.00025370340306410486,25.0,90.0
267.80884,0.024706736220472442,846.9375293320123,0.00025370340306410486,25.0,90.0
269.11011,0.024997633858267716,845.774834437086,0.00025370340306410486,25.0,90.0
270.41138,0.02534022834645669,845.7781456953643,0.00025370340306410486,25.0,90.0
271.71265,0.02560547244094488,848.1935130625228,0.00025370340306410486,25.0,90.0
273.01392,0.025882492125984254,847.8717995515461,0.00025370340306410486,25.0,90.0
274.31519,0.026150411417322834,849.3904156020233,0.00025370340306410486,25.0,90.0
275.61646,0.0264568031496063,851.3997236272619,0.00025370340306410486,25.0,90.0
276.91772,0.026776846456692913,850.7972832038379,0.00025370340306410486,25.0,90.0
278.21899,0.027115393700787405,853.6791990405173,0.00025370340306410486,25.0,90.0
279.52026,0.02738728937007874,852.3136830578297,0.00025370340306410486,25.0,90.0
280.82153,0.02765890748031496,852.8435365281326,0.00025370340306410486,25.0,90.0
282.1228,0.027907687007874018,851.9140637221672,0.00025370340306410486,25.0,90.0
283.42407,0.028200596456692914,853.6504145591073,0.00025370340306410486,25.0,90.0
284.72534,0.02847955118110236,853.4613078166553,0.00025370340306410486,25.0,90.0
286.02661,0.028726765748031496,853.8402252698545,0.00025370340306410486,25.0,90.0
287.32788,0.029002608267716536,855.449548938833,0.00025370340306410486,25.0,90.0
288.62915,0.02927242125984252,855.4854513218961,0.00025370340306410486,25.0,90.0
289.93042,0.02952143503937008,857.8370965218752,0.00025370340306410486,25.0,90.0
291.23169,0.029818978346456696,855.9689732492049,0.00025370340306410486,25.0,90.0
292.53296,0.030113450787401574,858.7370548052355,0.00025370340306410486,25.0,90.0
293.83423,0.03037792125984252,858.5260468269281,0.00025370340306410486,25.0,90.0
295.1355,0.03068420472440945,858.947124159149,0.00025370340306410486,25.0,90.0
296.43677,0.031017061023622044,860.5834072065495,0.00025370340306410486,25.0,90.0
297.73804,0.031292608267716536,859.564999739271,0.00025370340306410486,25.0,90.0
299.03931,0.031551210629921264,860.7545757939198,0.00025370340306410486,25.0,90.0
300.34058,0.031833728346456695,862.6317463628305,0.00025370340306410486,25.0,90.0
301.64185,0.03214248818897638,864.0538666110446,0.00025370340306410486,25.0,90.0
302.94312,0.03246309448818898,863.5090994420399,0.00025370340306410486,25.0,90.0
304.24438,0.032751133858267716,862.6479897794234,0.00025370340306410486,25.0,90.0
305.54565,0.03304786023622047,862.9572925900819,0.00025370340306410486,25.0,90.0
306.84692,0.033342346456692915,864.910283151692,0.00025370340306410486,25.0,90.0
308.14819,0.0336276968503937,865.3561818845492,0.00025370340306410486,25.0,90.0
309.44946,0.033875809055118104,865.7258173854095,0.00025370340306410486,25.0,90.0
310.75073,0.03419195866141732,868.489701204568,0.00025370340306410486,25.0,90.0
312.052,0.034498484251968504,867.0943317515774,0.00025370340306410486,25.0,90.0
313.35327,0.03482208267716535,869.0049799238672,0.00025370340306410486,25.0,90.0
314.65454,0.03515039566929134,869.0011472075925,0.00025370340306410486,25.0,90.0
315.95581,0.035445846456692916,867.6933044793242,0.00025370340306410486,25.0,90.0
317.25708,0.03572145866141732,869.6084111174845,0.00025370340306410486,25.0,90.0
318.55835,0.035966824803149604,868.4836522918079,0.00025370340306410486,25.0,90.0
319.85962,0.03625976771653543,869.4783073473432,0.00025370340306410486,25.0,90.0
321.16089,0.036550641732283465,871.5757417740002,0.00025370340306410486,25.0,90.0
322.46216,0.036811462598425194,870.4667309798195,0.00025370340306410486,25.0,90.0
323.76343,0.03712072637795276,873.2173176200657,0.00025370340306410486,25.0,90.0
325.0647,0.03740942913385827,873.0427074099181,0.00025370340306410486,25.0,90.0
326.36597,0.03771211614173228,873.3495854408927,0.00025370340306410486,25.0,90.0
327.66724,0.03802567716535433,875.7553579809147,0.00025370340306410486,25.0,90.0
328.96851,0.038361094488188974,874.9308285967566,0.00025370340306410486,25.0,90.0
330.26978,0.03865931496062992,876.6220733169944,0.00025370340306410486,25.0,90.0
331.57104,0.038959417322834644,877.2262866976065,0.00025370340306410486,25.0,90.0
332.87231,0.039223728346456696,876.2599468112844,0.00025370340306410486,25.0,90.0
334.17358,0.039505102362204725,877.8486207435991,0.00025370340306410486,25.0,90.0
335.47485,0.039787966535433074,877.476508317255,0.00025370340306410486,25.0,90.0
336.77612,0.04008825,877.8574855295407,0.00025370340306410486,25.0,90.0
338.07739,0.04037465551181102,877.321817802576,0.00025370340306410486,25.0,90.0
339.37866,0.04067267913385827,879.0546227251396,0.00025370340306410486,25.0,90.0
340.67993,0.04097652952755906,878.7635448714607,0.00025370340306410486,25.0,90.0
341.9812,0.041247789370078745,879.4757782760598,0.00025370340306410486,25.0,90.0
343.28247,0.04153777362204725,881.6156333107368,0.00025370340306410486,25.0,90.0
344.58374,0.041830135826771656,883.1451217604423,0.00025370340306410486,25.0,90.0
345.88501,0.04209071456692913,882.20910465662,0.00025370340306410486,25.0,90.0
347.18628,0.04236703149606299,881.6344318715128,0.00025370340306410486,25.0,90.0
348.48755,0.04267356496062992,883.4858163424935,0.00025370340306410486,25.0,90.0
349.78882,0.0429820905511811,882.2519945768369,0.00025370340306410486,25.0,90.0
351.09009,0.043258742125984254,884.6068988892945,0.00025370340306410486,25.0,90.0
352.39136,0.04354159842519685,885.2415393440059,0.00025370340306410486,25.0,90.0
353.69263,0.04385147834645669,884.3098764144548,0.00025370340306410486,25.0,90.0
354.9939,0.044144948818897634,885.8486728893987,0.00025370340306410486,25.0,90.0
356.29517,0.044462976377952754,886.3747197163268,0.00025370340306410486,25.0,90.0
357.59644,0.044771765748031496,885.781509099442,0.00025370340306410486,25.0,90.0
358.89771,0.04504643897637795,884.9597955884653,0.00025370340306410486,25.0,90.0
360.19897,0.04533291732283464,888.5512593210617,0.00025370340306410486,25.0,90.0
361.50024,0.045627464566929135,886.416201699953,0.00025370340306410486,25.0,90.0
362.80151,0.04586396653543307,887.1918965427335,0.00025370340306410486,25.0,90.0
364.10278,0.04614468700787402,887.0719872764249,0.00025370340306410486,25.0,90.0
365.40405,0.046416242125984254,888.9238149867028,0.00025370340306410486,25.0,90.0
366.70532,0.0467175374015748,889.7826563070345,0.00025370340306410486,25.0,90.0
368.00659,0.04702454133858267,890.4476456171457,0.00025370340306410486,25.0,90.0
369.30786,0.04733421653543307,890.2768681232727,0.00025370340306410486,25.0,90.0
370.60913,0.04766700984251969,891.3072951973719,0.00025370340306410486,25.0,90.0
371.9104,0.048000661417322836,890.9084319758044,0.00025370340306410486,25.0,90.0
373.21167,0.04832541535433071,891.5339208426761,0.00025370340306410486,25.0,90.0
374.51294,0.04862567125984252,892.5757417740002,0.00025370340306410486,25.0,90.0
375.81421,0.048930277559055116,892.7654221202483,0.00025370340306410486,25.0,90.0
377.11548,0.049203423228346456,892.8217135109767,0.00025370340306410486,25.0,90.0
378.41675,0.04945558070866141,891.9285081086718,0.00025370340306410486,25.0,90.0
379.71802,0.04971689763779527,894.003337331178,0.00025370340306410486,25.0,90.0
381.01929,0.05003067716535434,895.339104135162,0.00025370340306410486,25.0,90.0
382.32056,0.050356492125984254,896.2335349637586,0.00025370340306410486,25.0,90.0
383.62183,0.05060553937007874,893.5332429472807,0.00025370340306410486,25.0,90.0
384.9231,0.050912228346456694,895.2908692704804,0.00025370340306410486,25.0,90.0
386.22437,0.05118358267716535,895.6566981279658,0.00025370340306410486,25.0,90.0
387.52563,0.05149739763779527,897.3260937581477,0.00025370340306410486,25.0,90.0
388.8269,0.051759618110236216,898.9357303019242,0.00025370340306410486,25.0,90.0
390.12817,0.05203164566929133,897.4778380351462,0.00025370340306410486,25.0,90.0
391.42944,0.05229600590551181,898.9746049955677,0.00025370340306410486,25.0,90.0
392.73071,0.05256437992125984,898.4803410335297,0.00025370340306410486,25.0,90.0
394.03198,0.052873620078740156,898.7877144496011,0.00025370340306410486,25.0,90.0
395.33325,0.05316053149606299,900.6153204359389,0.00025370340306410486,25.0,90.0
396.63452,0.05346381102362204,899.8453355582208,0.00025370340306410486,25.0,90.0
397.93579,0.05378613976377953,901.4969233978203,0.00025370340306410486,25.0,90.0
399.23706,0.054086433070866136,901.7836992230276,0.00025370340306410486,25.0,90.0
400.53833,0.054375222440944886,900.4899097877666,0.00025370340306410486,25.0,90.0
401.8396,0.0547022559055118,903.1969546853,0.00025370340306410486,25.0,90.0
403.14087,0.05496845866141732,903.0664598216614,0.00025370340306410486,25.0,90.0
404.44214,0.055269352362204725,903.685300099077,0.00025370340306410486,25.0,90.0
405.74341,0.05562478543307086,905.1446524482453,0.00025370340306410486,25.0,90.0
407.04468,0.05592219881889764,903.2586953120926,0.00025370340306410486,25.0,90.0
408.34595,0.05621404330708661,904.0930020336863,0.00025370340306410486,25.0,90.0
409.64722,0.05648807283464567,904.3855660426553,0.00025370340306410486,25.0,90.0
410.94849,0.056790830708661415,906.7649788809512,0.00025370340306410486,25.0,90.0
412.24976,0.057133017716535436,905.3333159514001,0.00025370340306410486,25.0,90.0
413.55103,0.05740829527559055,906.0479741356834,0.00025370340306410486,25.0,90.0
414.85229,0.05772330905511811,906.6991708817856,0.00025370340306410486,25.0,90.0
416.15356,0.05800008267716535,906.460447410961,0.00025370340306410486,25.0,90.0
417.45483,0.05825519881889763,907.1556812848726,0.00025370340306410486,25.0,90.0
418.7561,0.058518021653543306,908.0381967982479,0.00025370340306410486,25.0,90.0
420.05737,0.058856665354330706,910.7742608332899,0.00025370340306410486,25.0,90.0
421.35864,0.059177051181102364,910.6911925744381,0.00025370340306410486,25.0,90.0
422.65991,0.059438625984251967,908.5654429785681,0.00025370340306410486,25.0,90.0
423.96118,0.05974032086614173,909.4199561975283,0.00025370340306410486,25.0,90.0
425.26245,0.060072698818897645,910.3223653334725,0.00025370340306410486,25.0,90.0
426.56372,0.06035636220472441,909.2074620639308,0.00025370340306410486,25.0,90.0
427.86499,0.06063656102362205,910.3032799707984,0.00025370340306410486,25.0,90.0
429.16626,0.06092673031496063,912.5908379830005,0.00025370340306410486,25.0,90.0
430.46753,0.06119700393700788,910.8309693904156,0.00025370340306410486,25.0,90.0
431.7688,0.06145164960629921,911.4124472023778,0.00025370340306410486,25.0,90.0
433.07007,0.061661604330708664,912.3094853209575,0.00025370340306410486,25.0,90.0
434.37134,0.06193607283464567,912.6685612973876,0.00025370340306410486,25.0,90.0
435.67261,0.06226542322834646,914.3108932575482,0.00025370340306410486,25.0,90.0
436.97388,0.06257060433070866,914.0355895082652,0.00025370340306410486,25.0,90.0
438.27515,0.06285059251968503,913.3779266830056,0.00025370340306410486,25.0,90.0
439.57642,0.06318440157480315,913.3593367054284,0.00025370340306410486,25.0,90.0
440.87769,0.06346368700787401,916.0811388642645,0.00025370340306410486,25.0,90.0
442.17896,0.0637619153543307,916.5582990040152,0.00025370340306410486,25.0,90.0
443.48022,0.0640925216535433,916.4129686603744,0.00025370340306410486,25.0,90.0
444.78149,0.06443089566929133,915.5724044428222,0.00025370340306410486,25.0,90.0
446.08276,0.06473182283464567,916.2586692391928,0.00025370340306410486,25.0,90.0
447.38403,0.0650614094488189,917.0008082598946,0.00025370340306410486,25.0,90.0
448.6853,0.06539652755905512,916.5888564426135,0.00025370340306410486,25.0,90.0
449.98657,0.0656536594488189,917.0968608228608,0.00025370340306410486,25.0,90.0
451.28784,0.06593786614173229,916.4218855921156,0.00025370340306410486,25.0,90.0
452.58911,0.06620315551181102,919.1277832820566,0.00025370340306410486,25.0,90.0
453.89038,0.06648111417322834,919.2732961359962,0.00025370340306410486,25.0,90.0
455.19165,0.06680674606299213,920.5597330135058,0.00025370340306410486,25.0,90.0
456.49292,0.06711921850393701,920.3495593679929,0.00025370340306410486,25.0,90.0
457.79419,0.06743475984251969,919.8018720342077,0.00025370340306410486,25.0,90.0
459.09546,0.06773550393700788,920.7826563070346,0.00025370340306410486,25.0,90.0
460.39673,0.0680538031496063,920.793789435261,0.00025370340306410486,25.0,90.0
461.698,0.06840101771653544,922.6234291077853,0.00025370340306410486,25.0,90.0
462.99927,0.06868732480314961,921.1056473901027,0.00025370340306410486,25.0,90.0
464.30054,0.0689493031496063,921.3121969025395,0.00025370340306410486,25.0,90.0
465.60181,0.06921616929133859,921.6090368670805,0.00025370340306410486,25.0,90.0
466.90308,0.0695283248031496,924.8393648641603,0.00025370340306410486,25.0,90.0
468.20435,0.06983690748031496,923.118344892319,0.00025370340306410486,25.0,90.0
469.50562,0.07016990748031496,925.1851436616781,0.00025370340306410486,25.0,90.0
470.80688,0.07047138188976378,923.5268811597225,0.00025370340306410486,25.0,90.0
472.10815,0.07076452362204724,923.5695885696407,0.00025370340306410486,25.0,90.0
473.40942,0.07100614566929134,923.9800281587319,0.00025370340306410486,25.0,90.0
474.71069,0.0713366220472441,924.7127548625958,0.00025370340306410486,25.0,90.0
476.01196,0.07162531102362205,926.0325650518851,0.00025370340306410486,25.0,90.0
477.31323,0.07193809448818898,925.7104865203107,0.00025370340306410486,25.0,90.0
478.6145,0.07222684842519685,926.7825520154352,0.00025370340306410486,25.0,90.0
479.91577,0.07255458070866141,927.874093966731,0.00025370340306410486,25.0,90.0
481.21704,0.07288069291338582,926.5858580591334,0.00025370340306410486,25.0,90.0
482.51831,0.07321132874015747,927.5988423632476,0.00025370340306410486,25.0,90.0
483.81958,0.07353121062992127,927.7430254992961,0.00025370340306410486,25.0,90.0
485.12085,0.073829968503937,926.8199144808887,0.00025370340306410486,25.0,90.0
486.42212,0.07413432086614173,927.9735360066746,0.00025370340306410486,25.0,90.0
487.72339,0.07443159251968505,928.2072013349325,0.00025370340306410486,25.0,90.0
489.02466,0.07475933070866142,930.2796057777547,0.00025370340306410486,25.0,90.0
490.32593,0.07506493307086615,930.1510924545028,0.00025370340306410486,25.0,90.0
491.6272,0.07538751377952756,929.4254836522919,0.00025370340306410486,25.0,90.0
492.92847,0.07564995669291338,928.9825050842154,0.00025370340306410486,25.0,90.0
494.22974,0.07594576181102362,930.1226208478907,0.00025370340306410486,25.0,90.0
495.53101,0.07624714763779528,930.1534390154873,0.00025370340306410486,25.0,90.0
496.83228,0.07660646456692913,930.7155185899776,0.00025370340306410486,25.0,90.0
498.13354,0.07691381102362205,933.1343275799135,0.00025370340306410486,25.0,90.0
499.43481,0.07723395078740157,931.4201126349272,0.00025370340306410486,25.0,90.0
500.73608,0.07750147244094488,931.8622568702091,0.00025370340306410486,25.0,90.0
502.03735,0.0777949842519685,932.6278093549565,0.00025370340306410486,25.0,90.0
503.33862,0.07804801181102362,932.3266152161443,0.00025370340306410486,25.0,90.0
504.63989,0.07832961417322834,932.5895082651092,0.00025370340306410486,25.0,90.0
505.94116,0.07865812007874015,933.5831986233509,0.00025370340306410486,25.0,90.0
507.24243,0.07900744685039371,933.6366219950984,0.00025370340306410486,25.0,90.0
508.5437,0.07931872244094487,933.5735255775147,0.00025370340306410486,25.0,90.0
509.84497,0.07962663188976378,934.4420399436825,0.00025370340306410486,25.0,90.0
511.14624,0.07994695866141732,935.5217447984566,0.00025370340306410486,25.0,90.0
512.44751,0.08027822244094489,934.6947384888147,0.00025370340306410486,25.0,90.0
513.74878,0.08058305708661417,934.4670438546176,0.00025370340306410486,25.0,90.0
515.05005,0.08084776968503937,935.8781352662044,0.00025370340306410486,25.0,90.0
516.35132,0.08116741141732284,935.0584554414141,0.00025370340306410486,25.0,90.0
517.65259,0.08151288385826772,937.9260311831882,0.00025370340306410486,25.0,90.0
518.95386,0.08186750196850394,937.5230484434479,0.00025370340306410486,25.0,90.0
520.25513,0.08221779133858267,936.3482296501016,0.00025370340306410486,25.0,90.0
521.5564,0.08251801377952755,937.9129947332742,0.00025370340306410486,25.0,90.0
522.85767,0.08288170078740156,938.3194190957919,0.00025370340306410486,25.0,90.0
524.15894,0.08320831299212599,939.2147885487824,0.00025370340306410486,25.0,90.0
525.46021,0.08349613385826772,939.025160348334,0.00025370340306410486,25.0,90.0
526.76147,0.08374603937007874,936.611513792564,0.00025370340306410486,25.0,90.0
528.06274,0.0840313090551181,939.653491161287,0.00025370340306410486,25.0,90.0
529.36401,0.08433218897637795,939.3999582833603,0.00025370340306410486,25.0,90.0
530.66528,0.08466107677165353,939.4753871825625,0.00025370340306410486,25.0,90.0
531.96655,0.08497922244094488,941.4499661052303,0.00025370340306410486,25.0,90.0
533.26782,0.08532590354330709,939.8716952599468,0.00025370340306410486,25.0,90.0
534.56909,0.08562008858267715,940.2034207644574,0.00025370340306410486,25.0,90.0
535.87036,0.0859228996062992,939.8674453772749,0.00025370340306410486,25.0,90.0
537.17163,0.0862110374015748,940.8695572821609,0.00025370340306410486,25.0,90.0
538.4729,0.08651451181102361,940.1861605047714,0.00025370340306410486,25.0,90.0
539.77417,0.0868588562992126,941.3980028158733,0.00025370340306410486,25.0,90.0
541.07544,0.08716247047244095,941.468034624811,0.00025370340306410486,25.0,90.0
542.37671,0.08748765157480315,944.466365959222,0.00025370340306410486,25.0,90.0
543.67798,0.08782411220472441,941.1081243155865,0.00025370340306410486,25.0,90.0
544.97925,0.08817549212598425,943.4846169891015,0.00025370340306410486,25.0,90.0
546.28052,0.08848168700787401,942.1811023622047,0.00025370340306410486,25.0,90.0
547.58179,0.08880046062992125,942.7326484851645,0.00025370340306410486,25.0,90.0
548.88306,0.08913078543307086,945.306200135579,0.00025370340306410486,25.0,90.0
550.18433,0.08944637992125984,943.7488397559578,0.00025370340306410486,25.0,90.0
551.4856,0.08978739763779527,945.7550451061167,0.00025370340306410486,25.0,90.0
552.78687,0.09013059448818898,943.3042185951922,0.00025370340306410486,25.0,90.0
554.08813,0.09047218897637796,946.5632007091829,0.00025370340306410486,25.0,90.0
555.3894,0.0909156279527559,946.6821713510976,0.00025370340306410486,25.0,90.0
556.69067,0.09128306496062992,944.8827762423737,0.00025370340306410486,25.0,90.0
557.99194,0.09158686023622048,944.6672576523962,0.00025370340306410486,25.0,90.0
559.29321,0.09189984842519686,946.3308650988164,0.00025370340306410486,25.0,90.0
560.59448,0.09225392716535433,946.5695103509412,0.00025370340306410486,25.0,90.0
561.89575,0.09256441141732283,946.0903686708036,0.00025370340306410486,25.0,90.0
563.19702,0.09284561614173228,944.905303227825,0.00025370340306410486,25.0,90.0
564.49829,0.09312377362204725,946.5412473275278,0.00025370340306410486,25.0,90.0
565.79956,0.09339528149606299,946.2658132137456,0.00025370340306410486,25.0,90.0
567.10083,0.09368695078740158,948.0595244303072,0.00025370340306410486,25.0,90.0
568.4021,0.09405997244094488,948.3074516347708,0.00025370340306410486,25.0,90.0
569.70337,0.09440987401574803,948.9641236898368,0.00025370340306410486,25.0,90.0
571.00464,0.09477512204724409,949.148015852323,0.00025370340306410486,25.0,90.0
572.30591,0.09507931102362205,947.7045158262501,0.00025370340306410486,25.0,90.0
573.60718,0.09533759448818897,948.2020389007666,0.00025370340306410486,25.0,90.0
574.90845,0.09563267322834645,948.8402513427544,0.00025370340306410486,25.0,90.0
576.20972,0.0959560748031496,949.0770454189915,0.00025370340306410486,25.0,90.0
577.51099,0.09623951968503937,949.6946081243157,0.00025370340306410486,25.0,90.0
578.81226,0.09655413976377952,948.700917766074,0.00025370340306410486,25.0,90.0
580.11353,0.09687484842519685,949.9340355634354,0.00025370340306410486,25.0,90.0
581.41479,0.09719803937007875,951.6863690879701,0.00025370340306410486,25.0,90.0
582.71606,0.09748959842519685,950.7722271471033,0.00025370340306410486,25.0,90.0
584.01733,0.09786518897637794,950.6636856651196,0.00025370340306410486,25.0,90.0
585.3186,0.09825318897637796,952.1523178807947,0.00025370340306410486,25.0,90.0
586.61987,0.09861961614173229,953.2890702403922,0.00025370340306410486,25.0,90.0
587.92114,0.09899158267716536,952.5003128747979,0.00025370340306410486,25.0,90.0
589.22241,0.0993945,952.6053605882047,0.00025370340306410486,25.0,90.0
590.52368,0.0997460846456693,953.012280335819,0.00025370340306410486,25.0,90.0
591.82495,0.10007135236220473,951.9409970276895,0.00025370340306410486,25.0,90.0
593.12622,0.10037037401574803,952.6984147676905,0.00025370340306410486,25.0,90.0
594.42749,0.10066621456692913,952.1747927204464,0.00025370340306410486,25.0,90.0
595.72876,0.10106602362204724,953.8236950513636,0.00025370340306410486,25.0,90.0
597.03003,0.10142891929133858,953.6315117067321,0.00025370340306410486,25.0,90.0
598.3313,0.1017252283464567,954.0232570266465,0.00025370340306410486,25.0,90.0
599.63257,0.10208063976377953,954.7349168274496,0.00025370340306410486,25.0,90.0
600.93384,0.10240708070866142,955.3211659800803,0.00025370340306410486,25.0,90.0
602.23511,0.10271695472440945,953.9314543463524,0.00025370340306410486,25.0,90.0
603.53638,0.10309856496062991,955.399410752464,0.00025370340306410486,25.0,90.0
604.83765,0.10341125393700787,954.5818949783595,0.00025370340306410486,25.0,90.0
606.13892,0.10374738779527558,954.5327475621839,0.00025370340306410486,25.0,90.0
607.44019,0.10408774409448819,955.1529436303906,0.00025370340306410486,25.0,90.0
608.74146,0.10441912401574804,955.624550242478,0.00025370340306410486,25.0,90.0
610.04272,0.10475491732283465,955.8134223288315,0.00025370340306410486,25.0,90.0
611.34399,0.10508589763779527,956.2968660374407,0.00025370340306410486,25.0,90.0
612.64526,0.10537236417322834,955.6044219638109,0.00025370340306410486,25.0,90.0
613.94653,0.10567658267716536,956.9405537883923,0.00025370340306410486,25.0,90.0
615.2478,0.1060207874015748,957.1767742608333,0.00025370340306410486,25.0,90.0
616.54907,0.1063971535433071,956.6755488345415,0.00025370340306410486,25.0,90.0
617.85034,0.10679304330708661,958.5837200813475,0.00025370340306410486,25.0,90.0
619.15161,0.1071304783464567,957.0203629347656,0.00025370340306410486,25.0,90.0
620.45288,0.10750677362204723,958.598034103353,0.00025370340306410486,25.0,90.0
621.75415,0.10782496653543307,956.9935599937426,0.00025370340306410486,25.0,90.0
623.05542,0.10814947244094489,958.1969546853002,0.00025370340306410486,25.0,90.0
624.35669,0.10848380905511812,959.7466235594724,0.00025370340306410486,25.0,90.0
625.65796,0.10886208661417324,959.0673723731554,0.00025370340306410486,25.0,90.0
626.95923,0.10927613976377952,959.0816342493612,0.00025370340306410486,25.0,90.0
628.2605,0.10963149212598425,959.0579339834177,0.00025370340306410486,25.0,90.0
629.56177,0.1100102874015748,960.6564373989675,0.00025370340306410486,25.0,90.0
630.86304,0.11037112992125984,960.1896021275487,0.00025370340306410486,25.0,90.0
632.16431,0.11070121850393701,959.6051259321063,0.00025370340306410486,25.0,90.0
633.46558,0.11104915551181102,959.0464879803932,0.00025370340306410486,25.0,90.0
634.76685,0.11145113582677164,960.2018303175679,0.00025370340306410486,25.0,90.0
636.06812,0.11178770078740158,960.6402722010743,0.00025370340306410486,25.0,90.0
637.36938,0.11216602755905511,959.6867862543672,0.00025370340306410486,25.0,90.0
638.67065,0.11253274803149607,961.3674714501747,0.00025370340306410486,25.0,90.0
639.97192,0.11289619488188975,961.1216300776972,0.00025370340306410486,25.0,90.0
641.27319,0.11325470275590552,961.5134275434114,0.00025370340306410486,25.0,90.0
642.57446,0.11361108661417324,963.1380820774887,0.00025370340306410486,25.0,90.0
643.87573,0.1140438779527559,962.5875267247224,0.00025370340306410486,25.0,90.0
645.177,0.1144110216535433,959.4649580226313,0.00025370340306410486,25.0,90.0
646.47827,0.1147794901574803,960.3910674245191,0.00025370340306410486,25.0,90.0
647.77954,0.11509334251968505,959.812431558638,0.00025370340306410486,25.0,90.0
649.08081,0.11540720472440945,960.5065964436565,0.00025370340306410486,25.0,90.0
650.38208,0.11579688779527558,960.9513479689211,0.00025370340306410486,25.0,90.0
651.68335,0.11613750393700786,962.818350106899,0.00025370340306410486,25.0,90.0
652.98462,0.1165147027559055,961.4499661052303,0.00025370340306410486,25.0,90.0
654.28589,0.1168982716535433,964.5902383063044,0.00025370340306410486,25.0,90.0
655.58716,0.11725730708661417,962.3152213589195,0.00025370340306410486,25.0,90.0
656.88843,0.11762095472440945,963.588934661313,0.00025370340306410486,25.0,90.0
658.1897,0.11797668110236222,963.3469260051103,0.00025370340306410486,25.0,90.0
659.49097,0.11835480708661418,964.7048026281483,0.00025370340306410486,25.0,90.0
660.79224,0.11872297244094487,962.2458935182772,0.00025370340306410486,25.0,90.0
662.09351,0.11913062992125985,965.8514105438808,0.00025370340306410486,25.0,90.0
663.39478,0.1195325157480315,963.949105699536,0.00025370340306410486,25.0,90.0
664.69604,0.11988902952755906,962.8981592532722,0.00025370340306410486,25.0,90.0
665.99731,0.12030592125984253,965.8965427334829,0.00025370340306410486,25.0,90.0
667.29858,0.12068522047244094,964.9000365020597,0.00025370340306410486,25.0,90.0
668.59985,0.12106416732283465,964.0525368931533,0.00025370340306410486,25.0,90.0
669.90112,0.12141068307086612,965.2556708557125,0.00025370340306410486,25.0,90.0
671.20239,0.12180552952755905,966.0838765187465,0.00025370340306410486,25.0,90.0
672.50366,0.12214372637795275,965.0318089377901,0.00025370340306410486,25.0,90.0
673.80493,0.12252978543307086,965.924545027898,0.00025370340306410486,25.0,90.0
675.1062,0.12292501771653543,966.3190801480941,0.00025370340306410486,25.0,90.0
676.40747,0.12325313582677166,963.3752411743234,0.00025370340306410486,25.0,90.0
677.70874,0.12362045472440944,965.5515982687596,0.00025370340306410486,25.0,90.0
679.01001,0.12394813976377952,965.1068467434948,0.00025370340306410486,25.0,90.0
680.31128,0.12432414173228346,966.8706523439538,0.00025370340306410486,25.0,90.0
681.61255,0.12476212007874014,966.4288209834698,0.00025370340306410486,25.0,90.0
682.91382,0.12514352952755906,965.0281065860145,0.00025370340306410486,25.0,90.0
684.21509,0.12550148622047244,966.0040673723732,0.00025370340306410486,25.0,90.0
685.51636,0.12583324212598423,965.2798665067529,0.00025370340306410486,25.0,90.0
686.81763,0.12620988976377953,967.8560254471502,0.00025370340306410486,25.0,90.0
688.1189,0.12661358267716535,966.913177243573,0.00025370340306410486,25.0,90.0
689.42017,0.1270484153543307,967.2480054231631,0.00025370340306410486,25.0,90.0
690.72144,0.12747400196850395,967.7842206810241,0.00025370340306410486,25.0,90.0
692.02271,0.1278354311023622,966.7679251186316,0.00025370340306410486,25.0,90.0
693.32397,0.1282996909448819,967.8688793867653,0.00025370340306410486,25.0,90.0
694.62524,0.12871824803149606,966.9397716013975,0.00025370340306410486,25.0,90.0
695.92651,0.1290875157480315,965.9536945299056,0.00025370340306410486,25.0,90.0
697.22778,0.12944450984251968,967.9031391771393,0.00025370340306410486,25.0,90.0
698.52905,0.12982491141732283,968.0884132033165,0.00025370340306410486,25.0,90.0
699.83032,0.13021047637795274,969.2831516921312,0.00025370340306410486,25.0,90.0
701.13159,0.13061840551181103,970.0456797204985,0.00025370340306410486,25.0,90.0
702.43286,0.13102831496062992,966.4214423528184,0.00025370340306410486,25.0,90.0
703.73413,0.13138275196850394,967.8233039578663,0.00025370340306410486,25.0,90.0
705.0354,0.13179282677165355,969.6064035041977,0.00025370340306410486,25.0,90.0
706.33667,0.13221376771653542,968.1016060906294,0.00025370340306410486,25.0,90.0
707.63794,0.13262909842519685,969.6430098555562,0.00025370340306410486,25.0,90.0
708.93921,0.1330694586614173,969.7412264692078,0.00025370340306410486,25.0,90.0
710.24048,0.1334799212598425,967.313187672733,0.00025370340306410486,25.0,90.0
711.54175,0.13389937007874014,968.281222297544,0.00025370340306410486,25.0,90.0
712.84302,0.13434226377952754,967.6908275538406,0.00025370340306410486,25.0,90.0
714.14429,0.13467475984251967,968.3825676591752,0.00025370340306410486,25.0,90.0
715.44556,0.13498829330708662,968.2796318506545,0.00025370340306410486,25.0,90.0
716.74683,0.13535768897637795,969.0856494759347,0.00025370340306410486,25.0,90.0
718.0481,0.13571952952755906,969.0112895656255,0.00025370340306410486,25.0,90.0
719.34937,0.13615364566929133,969.9944464723367,0.00025370340306410486,25.0,90.0
720.65063,0.13662121456692913,970.451660843719,0.00025370340306410486,25.0,90.0
721.9519,0.13701544881889763,968.505605673463,0.00025370340306410486,25.0,90.0
723.25317,0.13740786614173228,971.2156489544768,0.00025370340306410486,25.0,90.0
724.55444,0.1378383818897638,970.0328779266831,0.00025370340306410486,25.0,90.0
725.85571,0.13827004527559053,969.2682640663295,0.00025370340306410486,25.0,90.0
727.15698,0.13866272047244094,969.8143609532253,0.00025370340306410486,25.0,90.0
728.45825,0.13906942716535434,969.8351149814882,0.00025370340306410486,25.0,90.0
729.75952,0.13946543503937006,970.968477864108,0.00025370340306410486,25.0,90.0
731.06079,0.13991007677165354,970.3871825624445,0.00025370340306410486,25.0,90.0
732.36206,0.14032201771653544,971.0258903895292,0.00025370340306410486,25.0,90.0
733.66333,0.14076217716535433,970.573186629817,0.00025370340306410486,25.0,90.0
734.9646,0.14115345472440943,968.1820670594983,0.00025370340306410486,25.0,90.0
736.26587,0.14154344291338583,969.3492204202952,0.00025370340306410486,25.0,90.0
737.56714,0.1420185905511811,971.2985347030298,0.00025370340306410486,25.0,90.0
738.86841,0.14244838976377952,970.4674610210149,0.00025370340306410486,25.0,90.0
740.16968,0.14286167913385825,971.0987119987485,0.00025370340306410486,25.0,90.0
741.47095,0.14331578937007874,971.1761745841372,0.00025370340306410486,25.0,90.0
742.77222,0.14379660433070865,970.3866089586484,0.00025370340306410486,25.0,90.0
744.07349,0.14425449212598426,969.9281691609741,0.00025370340306410486,25.0,90.0
745.37476,0.14471152362204726,972.2085831986233,0.00025370340306410486,25.0,90.0
746.67603,0.1451829527559055,971.0406476508317,0.00025370340306410486,25.0,90.0
747.97729,0.14563956102362205,971.2025342858634,0.00025370340306410486,25.0,90.0
749.27856,0.14605356692913385,969.6862126505711,0.00025370340306410486,25.0,90.0
750.57983,0.14640614960629922,972.6557595035721,0.00025370340306410486,25.0,90.0
751.8811,0.1468624311023622,970.8277884966367,0.00025370340306410486,25.0,90.0
753.18237,0.14729987992125984,970.5151222819003,0.00025370340306410486,25.0,90.0
754.48364,0.1476972598425197,968.526359701726,0.00025370340306410486,25.0,90.0
755.78491,0.1481230688976378,972.1333628826198,0.00025370340306410486,25.0,90.0
757.08618,0.14858730511811025,970.9487406789383,0.00025370340306410486,25.0,90.0
758.38745,0.14901801771653542,970.8220785315743,0.00025370340306410486,25.0,90.0
759.68872,0.1493998405511811,970.2142931636857,0.00025370340306410486,25.0,90.0
760.4895,0.14973448228346456,974.7743129790895,0.00025370340306410486,25.0,90.0