File: datasets/am_bench_2022/csv/90-XY.07-3.csv
Time(s),Strain(%),Stress(MPa),SR(s-1),Temp(C),Angle(deg)
17.758301,1.3362399212598426e-05,18.158024717109036,0.00025370340306410486,25.0,90.0
19.159668,5.9830297244094486e-05,23.35815299577619,0.00025370340306410486,25.0,90.0
20.460938,6.625350590551181e-05,27.39420138707827,0.00025370340306410486,25.0,90.0
21.762207,9.578745472440945e-05,31.900146008239034,0.00025370340306410486,25.0,90.0
23.063477,0.00010683280511811023,36.763203316472854,0.00025370340306410486,25.0,90.0
24.364746,0.00012017068897637795,41.037219064504356,0.00025370340306410486,25.0,90.0
25.666016,0.00014291660433070867,46.94644626375346,0.00025370340306410486,25.0,90.0
26.967285,0.00016887766929133858,52.574453772748605,0.00025370340306410486,25.0,90.0
28.268555,0.00020008622047244093,58.21224383375919,0.00025370340306410486,25.0,90.0
29.569824,0.0002284116141732283,64.27194555978517,0.00025370340306410486,25.0,90.0
30.871094,0.00027061389763779526,72.2268498722428,0.00025370340306410486,25.0,90.0
32.172363,0.0002867444094488189,78.0468634301507,0.00025370340306410486,25.0,90.0
33.473633,0.00031221685039370075,84.18897116337278,0.00025370340306410486,25.0,90.0
34.774902,0.00032334206692913385,90.66244720237785,0.00025370340306410486,25.0,90.0
36.076172,0.0003700186811023622,98.65331125827815,0.00025370340306410486,25.0,90.0
37.377441,0.0003996897834645669,104.99433696615739,0.00025370340306410486,25.0,90.0
38.678711,0.0004490582086614173,113.85641914793764,0.00025370340306410486,25.0,90.0
39.97998,0.00048525151574803143,121.31930698232257,0.00025370340306410486,25.0,90.0
41.28125,0.00048652277559055123,128.6826510924545,0.00025370340306410486,25.0,90.0
42.58252,0.0005238821062992126,135.30864316629294,0.00025370340306410486,25.0,90.0
43.883789,0.0005502779527559056,142.88184543984983,0.00025370340306410486,25.0,90.0
45.185059,0.0005806038582677165,152.55587161704125,0.00025370340306410486,25.0,90.0
46.486328,0.0006249776771653543,160.3232387756166,0.00025370340306410486,25.0,90.0
47.787598,0.0006347840157480316,168.317119466027,0.00025370340306410486,25.0,90.0
49.088867,0.0007011420275590552,176.84774990874487,0.00025370340306410486,25.0,90.0
50.390137,0.0007196991732283465,186.799548938833,0.00025370340306410486,25.0,90.0
51.691406,0.0007818779330708661,198.0149840955311,0.00025370340306410486,25.0,90.0
52.992676,0.0008062950787401574,207.355303227825,0.00025370340306410486,25.0,90.0
54.293945,0.0008345343307086615,215.3836835792877,0.00025370340306410486,25.0,90.0
55.595215,0.0008637962795275591,225.63820722740783,0.00025370340306410486,25.0,90.0
56.896484,0.0009009988582677164,236.2671794336966,0.00025370340306410486,25.0,90.0
58.197754,0.0009509561614173227,244.0820462011785,0.00025370340306410486,25.0,90.0
59.499023,0.0009802440551181103,252.1923502111905,0.00025370340306410486,25.0,90.0
60.800293,0.001017114153543307,261.4411534650884,0.00025370340306410486,25.0,90.0
62.101563,0.0010463617125984251,270.8246336757574,0.00025370340306410486,25.0,90.0
63.402832,0.0010922463976377954,281.5309224591959,0.00025370340306410486,25.0,90.0
64.704102,0.0011146129921259843,290.42725660948014,0.00025370340306410486,25.0,90.0
66.005371,0.0011688036811023622,301.8376179798717,0.00025370340306410486,25.0,90.0
67.306641,0.0011906703346456693,310.37967356729416,0.00025370340306410486,25.0,90.0
68.60791,0.001242515216535433,321.05618709912915,0.00025370340306410486,25.0,90.0
69.90918,0.0012822150393700788,330.4694425614017,0.00025370340306410486,25.0,90.0
71.210449,0.0013057119488188976,337.320905251082,0.00025370340306410486,25.0,90.0
72.511719,0.0013446867913385827,347.17393231475205,0.00025370340306410486,25.0,90.0
73.812988,0.0013663308858267718,353.6922615633311,0.00025370340306410486,25.0,90.0
75.114258,0.0014227438188976378,367.6937737915211,0.00025370340306410486,25.0,90.0
76.415527,0.0014481580118110235,377.70754028263025,0.00025370340306410486,25.0,90.0
77.716797,0.0015062318503937008,386.7356207957449,0.00025370340306410486,25.0,90.0
79.018066,0.0015241475196850394,394.6708557125724,0.00025370340306410486,25.0,90.0
80.319336,0.0015374208858267716,403.40798873650726,0.00025370340306410486,25.0,90.0
81.620605,0.0016186109448818897,415.90835375710486,0.00025370340306410486,25.0,90.0
82.921875,0.001636319094488189,422.58491943473956,0.00025370340306410486,25.0,90.0
84.223145,0.0016679092716535432,431.1520050059968,0.00025370340306410486,25.0,90.0
85.524414,0.0017068895078740157,442.61013192887316,0.00025370340306410486,25.0,90.0
86.825684,0.0017499411811023624,450.73595974344266,0.00025370340306410486,25.0,90.0
88.126953,0.0017803413582677164,459.8848360014601,0.00025370340306410486,25.0,90.0
89.428223,0.0018265840748031496,471.92696980758205,0.00025370340306410486,25.0,90.0
90.729492,0.0018581982677165353,478.0538144652448,0.00025370340306410486,25.0,90.0
92.030762,0.0018891638188976378,486.486520310789,0.00025370340306410486,25.0,90.0
93.332031,0.0019291784251968505,493.8385044584659,0.00025370340306410486,25.0,90.0
94.633301,0.0019658193700787404,504.9414663398863,0.00025370340306410486,25.0,90.0
95.93457,0.001981877559055118,512.6065338686968,0.00025370340306410486,25.0,90.0
97.23584,0.0020339812992125985,521.4282734525734,0.00025370340306410486,25.0,90.0
98.537109,0.0020639846456692915,529.7509777337435,0.00025370340306410486,25.0,90.0
99.838379,0.002119148818897638,539.3011159201127,0.00025370340306410486,25.0,90.0
101.13965,0.0021398336614173227,546.0239349220421,0.00025370340306410486,25.0,90.0
102.44092,0.002180656496062992,552.4926995880481,0.00025370340306410486,25.0,90.0
103.74219,0.002198636023622047,558.6303384262397,0.00025370340306410486,25.0,90.0
105.04346,0.0022136574803149605,563.9083798300046,0.00025370340306410486,25.0,90.0
106.34473,0.0022653110236220473,572.8044271783908,0.00025370340306410486,25.0,90.0
107.646,0.0022866517716535434,579.5160348333942,0.00025370340306410486,25.0,90.0
108.94727,0.0023241366141732284,585.9151066381603,0.00025370340306410486,25.0,90.0
110.24854,0.002345422440944882,591.7314752046723,0.00025370340306410486,25.0,90.0
111.5498,0.002417787007874016,599.1779736142254,0.00025370340306410486,25.0,90.0
112.85107,0.002439657677165354,605.6157376023361,0.00025370340306410486,25.0,90.0
114.15234,0.0024510037401574802,612.6835532147886,0.00025370340306410486,25.0,90.0
115.45361,0.0024785889763779528,616.3410074568493,0.00025370340306410486,25.0,90.0
116.75488,0.0025071901574803147,622.9393805079001,0.00025370340306410486,25.0,90.0
118.05615,0.002554903346456693,625.0844761954424,0.00025370340306410486,25.0,90.0
119.35742,0.0025985746062992124,634.272878969599,0.00025370340306410486,25.0,90.0
120.65869,0.0026304846456692912,636.7916253845754,0.00025370340306410486,25.0,90.0
121.95996,0.002681334251968504,643.5300359806017,0.00025370340306410486,25.0,90.0
123.26123,0.0027034242125984253,646.3224956979715,0.00025370340306410486,25.0,90.0
124.5625,0.0027316917322834644,650.9418313604839,0.00025370340306410486,25.0,90.0
125.86377,0.002784186023622047,657.8820201282787,0.00025370340306410486,25.0,90.0
127.16504,0.0028203084645669293,660.5246388903374,0.00025370340306410486,25.0,90.0
128.46631,0.002864552755905512,665.2223496897325,0.00025370340306410486,25.0,90.0
129.76758,0.0028989687007874017,670.9078583720081,0.00025370340306410486,25.0,90.0
131.06885,0.002944055511811024,673.4066068728164,0.00025370340306410486,25.0,90.0
132.37012,0.0029785509842519685,677.3913281535172,0.00025370340306410486,25.0,90.0
133.67139,0.0030376791338582675,681.4869114042864,0.00025370340306410486,25.0,90.0
134.97266,0.0030974234251968506,686.1112791364656,0.00025370340306410486,25.0,90.0
136.27393,0.0031127734251968505,687.8064087187778,0.00025370340306410486,25.0,90.0
137.5752,0.0031574387795275586,689.9350784794285,0.00025370340306410486,25.0,90.0
138.87646,0.003215980708661417,693.5917244615947,0.00025370340306410486,25.0,90.0
140.17773,0.0032440986220472444,697.4786462950409,0.00025370340306410486,25.0,90.0
141.479,0.0032856185039370077,699.1086457735829,0.00025370340306410486,25.0,90.0
142.78027,0.0033471785433070865,705.7525942535328,0.00025370340306410486,25.0,90.0
144.08154,0.003406641535433071,708.1279397194556,0.00025370340306410486,25.0,90.0
145.38281,0.0034717446850393704,710.0223444751525,0.00025370340306410486,25.0,90.0
146.68408,0.003508979330708661,713.8542785628619,0.00025370340306410486,25.0,90.0
147.98535,0.003579660433070866,718.8048443447881,0.00025370340306410486,25.0,90.0
149.28662,0.0036641694881889768,721.569093184544,0.00025370340306410486,25.0,90.0
150.58789,0.003733701968503937,722.8083120404651,0.00025370340306410486,25.0,90.0
151.88916,0.003825946850393701,725.2381498670281,0.00025370340306410486,25.0,90.0
153.19043,0.00387808031496063,728.6114616467644,0.00025370340306410486,25.0,90.0
154.4917,0.00397238405511811,732.5732387756167,0.00025370340306410486,25.0,90.0
155.79297,0.00407308937007874,735.1055430985034,0.00025370340306410486,25.0,90.0
157.09424,0.004154492519685039,737.9316107837515,0.00025370340306410486,25.0,90.0
158.39551,0.004281787795275591,741.3466131303123,0.00025370340306410486,25.0,90.0
159.69678,0.004364575787401575,743.5034416227774,0.00025370340306410486,25.0,90.0
160.99805,0.004460463582677166,744.1930698232258,0.00025370340306410486,25.0,90.0
162.29932,0.004551029133858267,746.1745580643479,0.00025370340306410486,25.0,90.0
163.60059,0.004655332086614173,749.0057360379622,0.00025370340306410486,25.0,90.0
164.90186,0.0047863405511811025,751.45304270741,0.00025370340306410486,25.0,90.0
166.20313,0.004916587598425197,754.1590186160505,0.00025370340306410486,25.0,90.0
167.50439,0.00506233031496063,757.8728163946394,0.00025370340306410486,25.0,90.0
168.80566,0.0052365968503937,761.101814673828,0.00025370340306410486,25.0,90.0
170.10693,0.005358603149606299,760.8080513114669,0.00025370340306410486,25.0,90.0
171.4082,0.005499806299212599,762.7817698284402,0.00025370340306410486,25.0,90.0
172.70947,0.005649043503937008,764.0814778119623,0.00025370340306410486,25.0,90.0
174.01074,0.005806706692913386,767.828179590134,0.00025370340306410486,25.0,90.0
175.31201,0.005995265551181102,768.5360848933619,0.00025370340306410486,25.0,90.0
176.61328,0.006141601181102362,770.8038535745947,0.00025370340306410486,25.0,90.0
177.91455,0.0063026074803149605,770.5976690827554,0.00025370340306410486,25.0,90.0
179.21582,0.00648807342519685,772.60304010012,0.00025370340306410486,25.0,90.0
180.51709,0.006663779527559055,773.916227772853,0.00025370340306410486,25.0,90.0
181.81836,0.0068634645669291335,776.9828440319133,0.00025370340306410486,25.0,90.0
183.11963,0.0071077159448818894,778.2163529227721,0.00025370340306410486,25.0,90.0
184.4209,0.0073459336614173235,780.3917974657141,0.00025370340306410486,25.0,90.0
185.72217,0.007548684842519684,780.9925692235491,0.00025370340306410486,25.0,90.0
187.02344,0.007712914370078741,782.7895395525891,0.00025370340306410486,25.0,90.0
188.32471,0.007931778740157481,782.9817750430203,0.00025370340306410486,25.0,90.0
189.62598,0.00821725846456693,785.0990509464464,0.00025370340306410486,25.0,90.0
190.92725,0.00842318720472441,785.8552171872557,0.00025370340306410486,25.0,90.0
192.22852,0.008640235826771652,787.500756114095,0.00025370340306410486,25.0,90.0
193.52979,0.00892648779527559,790.7040986598529,0.00025370340306410486,25.0,90.0
194.83105,0.009160075984251968,791.0283673150127,0.00025370340306410486,25.0,90.0
196.13232,0.009424702165354331,792.2148146216823,0.00025370340306410486,25.0,90.0
197.43359,0.009666107480314962,794.4467852114512,0.00025370340306410486,25.0,90.0
198.73486,0.009901607480314961,793.9051467904261,0.00025370340306410486,25.0,90.0
200.03613,0.010154002559055119,794.3778484643062,0.00025370340306410486,25.0,90.0
201.3374,0.0103910218503937,797.1362569745007,0.00025370340306410486,25.0,90.0
202.63867,0.010644902559055118,797.677582520728,0.00025370340306410486,25.0,90.0
203.93994,0.010891012992125984,798.4909527037597,0.00025370340306410486,25.0,90.0
205.24121,0.011142427559055118,801.2678208270324,0.00025370340306410486,25.0,90.0
206.54248,0.011389225196850393,799.8161860562132,0.00025370340306410486,25.0,90.0
207.84375,0.011643442519685038,800.9267090785837,0.00025370340306410486,25.0,90.0
209.14502,0.01187832933070866,805.3040882306931,0.00025370340306410486,25.0,90.0
210.44629,0.012144364173228346,803.9704072586953,0.00025370340306410486,25.0,90.0
211.74756,0.012462112401574804,806.4340355634354,0.00025370340306410486,25.0,90.0
213.04883,0.012730842322834645,805.8487250351984,0.00025370340306410486,25.0,90.0
214.3501,0.012967525787401575,806.5939928038797,0.00025370340306410486,25.0,90.0
215.65137,0.013215659448818898,808.776972414872,0.00025370340306410486,25.0,90.0
216.95264,0.013421448031496063,807.043333159514,0.00025370340306410486,25.0,90.0
218.25391,0.01367938188976378,807.5624445950879,0.00025370340306410486,25.0,90.0
219.55518,0.013968795866141734,809.6133910413517,0.00025370340306410486,25.0,90.0
220.85645,0.014241972637795277,811.7305365802785,0.00025370340306410486,25.0,90.0
222.15771,0.014571852952755905,813.7822391406373,0.00025370340306410486,25.0,90.0
223.45898,0.014855093700787402,813.0858580591333,0.00025370340306410486,25.0,90.0
224.76025,0.01517138405511811,813.939224070501,0.00025370340306410486,25.0,90.0
226.06152,0.015450038779527558,815.3358710955833,0.00025370340306410486,25.0,90.0
227.36279,0.01574603937007874,815.6670490691974,0.00025370340306410486,25.0,90.0
228.66406,0.016057046850393702,818.7581738540961,0.00025370340306410486,25.0,90.0
229.96533,0.016354184251968506,818.8991239505658,0.00025370340306410486,25.0,90.0
231.2666,0.01658317972440945,818.386504667049,0.00025370340306410486,25.0,90.0
232.56787,0.01687904094488189,822.3283881733325,0.00025370340306410486,25.0,90.0
233.86914,0.017160929527559054,820.8142827345258,0.00025370340306410486,25.0,90.0
235.17041,0.01739597342519685,820.2462324659749,0.00025370340306410486,25.0,90.0
236.47168,0.01768156968503937,823.2343692965533,0.00025370340306410486,25.0,90.0
237.77295,0.01798296338582677,823.6239244928821,0.00025370340306410486,25.0,90.0
239.07422,0.018301204330708663,825.5188767794754,0.00025370340306410486,25.0,90.0
240.37549,0.018599730511811022,825.7591646242895,0.00025370340306410486,25.0,90.0
241.67676,0.01894603149606299,827.5745945664077,0.00025370340306410486,25.0,90.0
242.97803,0.019251109251968504,827.2115033634041,0.00025370340306410486,25.0,90.0
244.2793,0.01949164429133858,826.35910204933,0.00025370340306410486,25.0,90.0
245.58057,0.019746732283464567,828.2271731762007,0.00025370340306410486,25.0,90.0
246.88184,0.02002150590551181,828.4013401470512,0.00025370340306410486,25.0,90.0
248.18311,0.020318305118110235,829.3849142201595,0.00025370340306410486,25.0,90.0
249.48438,0.02058770275590551,829.7827605986338,0.00025370340306410486,25.0,90.0
250.78564,0.0208473562992126,831.6476508317255,0.00025370340306410486,25.0,90.0
252.08691,0.021127653543307087,830.4282995254732,0.00025370340306410486,25.0,90.0
253.38818,0.021409899606299212,833.4174531991449,0.00025370340306410486,25.0,90.0
254.68945,0.021700291338582676,833.6376127652918,0.00025370340306410486,25.0,90.0
255.99072,0.022010700787401576,834.0426031183189,0.00025370340306410486,25.0,90.0
257.29199,0.02229565748031496,833.4129165145748,0.00025370340306410486,25.0,90.0
258.59326,0.02261875,836.5684674349482,0.00025370340306410486,25.0,90.0
259.89453,0.02290407283464567,836.4327579913438,0.00025370340306410486,25.0,90.0
261.1958,0.023190785433070866,836.8065390832768,0.00025370340306410486,25.0,90.0
262.49707,0.023522,838.1818584762998,0.00025370340306410486,25.0,90.0
263.79834,0.023844275590551182,840.0497470928717,0.00025370340306410486,25.0,90.0
265.09961,0.02413732086614173,840.1982322573916,0.00025370340306410486,25.0,90.0
266.40088,0.02451747244094488,840.8826458778746,0.00025370340306410486,25.0,90.0
267.70215,0.02479673228346457,841.3459873807166,0.00025370340306410486,25.0,90.0
269.00342,0.02509584842519685,840.4746832142671,0.00025370340306410486,25.0,90.0
270.30469,0.025389783464566926,843.3726860301404,0.00025370340306410486,25.0,90.0
271.60596,0.025697220472440944,841.9955154612296,0.00025370340306410486,25.0,90.0
272.90723,0.02596657480314961,844.3071387599729,0.00025370340306410486,25.0,90.0
274.2085,0.02629552559055118,845.9331230119413,0.00025370340306410486,25.0,90.0
275.50977,0.02661828543307087,846.1403243468739,0.00025370340306410486,25.0,90.0
276.81104,0.026881053149606298,845.671507535068,0.00025370340306410486,25.0,90.0
278.1123,0.027222001968503936,848.0103770141314,0.00025370340306410486,25.0,90.0
279.41357,0.027494291338582676,845.7883141262971,0.00025370340306410486,25.0,90.0
280.71484,0.027800086614173228,848.1729415445586,0.00025370340306410486,25.0,90.0
282.01611,0.028064750000000003,846.3935443500026,0.00025370340306410486,25.0,90.0
283.31738,0.028369202755905515,849.3091724461594,0.00025370340306410486,25.0,90.0
284.61865,0.028632962598425193,849.9020701882463,0.00025370340306410486,25.0,90.0
285.91992,0.02892151377952756,849.3436147468323,0.00025370340306410486,25.0,90.0
287.22119,0.02919199409448819,849.9618292746519,0.00025370340306410486,25.0,90.0
288.52246,0.029507854330708662,851.6685873702874,0.00025370340306410486,25.0,90.0
289.82373,0.029774881889763783,851.3435886739323,0.00025370340306410486,25.0,90.0
291.125,0.030041923228346454,853.0693278406424,0.00025370340306410486,25.0,90.0
292.42627,0.030324759842519686,852.5705271940345,0.00025370340306410486,25.0,90.0
293.72754,0.03062873031496063,856.4004275955572,0.00025370340306410486,25.0,90.0
295.02881,0.030943793307086614,854.4427960577775,0.00025370340306410486,25.0,90.0
296.33008,0.03123199212598425,854.1205610888043,0.00025370340306410486,25.0,90.0
297.63135,0.03149927362204724,856.6919486885331,0.00025370340306410486,25.0,90.0
298.93262,0.03185062795275591,858.0585597330136,0.00025370340306410486,25.0,90.0
300.23389,0.0321373405511811,856.0543880690411,0.00025370340306410486,25.0,90.0
301.53516,0.03242316929133858,858.5373624654534,0.00025370340306410486,25.0,90.0
302.83643,0.032765576771653544,859.504406320071,0.00025370340306410486,25.0,90.0
304.1377,0.03302542913385827,860.3490379099965,0.00025370340306410486,25.0,90.0
305.43896,0.03335811811023622,860.0867966835272,0.00025370340306410486,25.0,90.0
306.74023,0.03368485433070866,861.702899306461,0.00025370340306410486,25.0,90.0
308.0415,0.03402117913385827,860.7993429629244,0.00025370340306410486,25.0,90.0
309.34277,0.03431733267716535,860.0276372738176,0.00025370340306410486,25.0,90.0
310.64404,0.03459492913385827,862.6461386035355,0.00025370340306410486,25.0,90.0
311.94531,0.034895923228346455,863.4663920321218,0.00025370340306410486,25.0,90.0
313.24658,0.03517902559055118,863.8770923502111,0.00025370340306410486,25.0,90.0
314.54785,0.03549000196850394,865.341216040048,0.00025370340306410486,25.0,90.0
315.84912,0.03574484448818898,862.4677738958127,0.00025370340306410486,25.0,90.0
317.15039,0.03600527755905512,863.9938467956407,0.00025370340306410486,25.0,90.0
318.45166,0.03628290157480315,864.9991395943057,0.00025370340306410486,25.0,90.0
319.75293,0.036570135826771655,866.8092767377589,0.00025370340306410486,25.0,90.0
321.0542,0.03693846850393701,867.6595661469469,0.00025370340306410486,25.0,90.0
322.35547,0.03726686614173228,867.3670803566773,0.00025370340306410486,25.0,90.0
323.65674,0.03758381692913386,868.7460238827763,0.00025370340306410486,25.0,90.0
324.95801,0.03785297440944882,866.7439119778902,0.00025370340306410486,25.0,90.0
326.25928,0.03814444094488189,867.8805861187881,0.00025370340306410486,25.0,90.0
327.56055,0.03844346456692913,870.3039839390938,0.00025370340306410486,25.0,90.0
328.86182,0.03876803149606299,872.0595765761068,0.00025370340306410486,25.0,90.0
330.16309,0.03904827559055118,870.961203525056,0.00025370340306410486,25.0,90.0
331.46436,0.03934909251968504,871.862439380508,0.00025370340306410486,25.0,90.0
332.76563,0.03961476377952756,871.6335193200188,0.00025370340306410486,25.0,90.0
334.06689,0.03989781889763779,872.317567919904,0.00025370340306410486,25.0,90.0
335.36816,0.04024815748031496,873.1252020649737,0.00025370340306410486,25.0,90.0
336.66943,0.04057945866141732,875.0156958856963,0.00025370340306410486,25.0,90.0
337.9707,0.040893255905511815,874.6817020389008,0.00025370340306410486,25.0,90.0
339.27197,0.04122037007874016,875.4331230119413,0.00025370340306410486,25.0,90.0
340.57324,0.04151459448818898,874.2736090107942,0.00025370340306410486,25.0,90.0
341.87451,0.041803541338582675,875.2479011315638,0.00025370340306410486,25.0,90.0
343.17578,0.04202450984251968,874.5509985920634,0.00025370340306410486,25.0,90.0
344.47705,0.0422908188976378,876.7447984564843,0.00025370340306410486,25.0,90.0
345.77832,0.04259579724409449,877.6595140011472,0.00025370340306410486,25.0,90.0
347.07959,0.04293160039370079,879.0708661417324,0.00025370340306410486,25.0,90.0
348.38086,0.043241383858267715,878.1870730562653,0.00025370340306410486,25.0,90.0
349.68213,0.04352484842519685,878.1981540386922,0.00025370340306410486,25.0,90.0
350.9834,0.043857047244094484,879.5239609949418,0.00025370340306410486,25.0,90.0
352.28467,0.0442209153543307,880.9048078427282,0.00025370340306410486,25.0,90.0
353.58594,0.04452820472440945,880.3235125410648,0.00025370340306410486,25.0,90.0
354.88721,0.044748923228346456,880.1250456275748,0.00025370340306410486,25.0,90.0
356.18848,0.045047173228346456,882.4382593732075,0.00025370340306410486,25.0,90.0
357.48975,0.045318942913385826,883.6625123846275,0.00025370340306410486,25.0,90.0
358.79102,0.045589035433070864,881.1342754341138,0.00025370340306410486,25.0,90.0
360.09229,0.04588901968503937,882.0233613182459,0.00025370340306410486,25.0,90.0
361.39355,0.046230551181102364,884.2162486311728,0.00025370340306410486,25.0,90.0
362.69482,0.046538342519685034,884.2079835219273,0.00025370340306410486,25.0,90.0
363.99609,0.04686826377952756,886.0300881264014,0.00025370340306410486,25.0,90.0
365.29736,0.047176090551181105,884.4284038170725,0.00025370340306410486,25.0,90.0
366.59863,0.04745033070866141,885.664389633415,0.00025370340306410486,25.0,90.0
367.8999,0.04777006299212599,888.2011524221724,0.00025370340306410486,25.0,90.0
369.20117,0.048080433070866145,887.2328309954634,0.00025370340306410486,25.0,90.0
370.50244,0.048421602362204726,888.7214110653388,0.00025370340306410486,25.0,90.0
371.80371,0.04870915551181102,887.5479219898837,0.00025370340306410486,25.0,90.0
373.10498,0.049010866141732286,888.8460395265162,0.00025370340306410486,25.0,90.0
374.40625,0.04936783464566929,890.4267612243834,0.00025370340306410486,25.0,90.0
375.70752,0.0496749094488189,887.9649319497314,0.00025370340306410486,25.0,90.0
377.00879,0.04995300393700787,890.5927152317881,0.00025370340306410486,25.0,90.0
378.31006,0.050218901574803146,892.4293424414664,0.00025370340306410486,25.0,90.0
379.61133,0.05052375393700787,891.4894144026699,0.00025370340306410486,25.0,90.0
380.9126,0.0508345374015748,890.1757052719404,0.00025370340306410486,25.0,90.0
382.21387,0.051125818897637794,891.7978828805341,0.00025370340306410486,25.0,90.0
383.51514,0.05145556299212598,893.6336757574177,0.00025370340306410486,25.0,90.0
384.81641,0.05173913188976378,894.2197423997497,0.00025370340306410486,25.0,90.0
386.11768,0.05207796850393701,893.9701726025969,0.00025370340306410486,25.0,90.0
387.41895,0.05240063188976378,892.9930646086458,0.00025370340306410486,25.0,90.0
388.72021,0.0526942657480315,894.6152422172395,0.00025370340306410486,25.0,90.0
390.02148,0.05298777755905512,894.3482557230016,0.00025370340306410486,25.0,90.0
391.32275,0.05325816338582678,894.7068884601345,0.00025370340306410486,25.0,90.0
392.62402,0.05354721653543307,895.2296240287845,0.00025370340306410486,25.0,90.0
393.92529,0.05383902165354331,896.6536997444856,0.00025370340306410486,25.0,90.0
395.22656,0.054148437007874015,896.9124732752776,0.00025370340306410486,25.0,90.0
396.52783,0.05445374803149606,897.205454450644,0.00025370340306410486,25.0,90.0
397.8291,0.05476287007874016,898.10757678469,0.00025370340306410486,25.0,90.0
399.13037,0.055077167322834644,898.0465401261928,0.00025370340306410486,25.0,90.0
400.43164,0.05534703740157481,898.2848464306201,0.00025370340306410486,25.0,90.0
401.73291,0.05565312598425196,899.4689471763049,0.00025370340306410486,25.0,90.0
403.03418,0.05598162598425197,899.3509412316838,0.00025370340306410486,25.0,90.0
404.33545,0.05628305905511811,898.9530948532096,0.00025370340306410486,25.0,90.0
405.63672,0.056567318897637796,899.669082755384,0.00025370340306410486,25.0,90.0
406.93799,0.056886127952755904,902.7344475152527,0.00025370340306410486,25.0,90.0
408.23926,0.05721800590551181,901.1947645617146,0.00025370340306410486,25.0,90.0
409.54053,0.05755472047244094,900.8480992856025,0.00025370340306410486,25.0,90.0
410.8418,0.05782789763779528,901.6973197058977,0.00025370340306410486,25.0,90.0
412.14307,0.05812684251968504,903.5341294258748,0.00025370340306410486,25.0,90.0
413.44434,0.0584740748031496,903.7854461073161,0.00025370340306410486,25.0,90.0
414.74561,0.05875111417322835,902.3043750325911,0.00025370340306410486,25.0,90.0
416.04688,0.05907510236220473,903.3774834437086,0.00025370340306410486,25.0,90.0
417.34814,0.059398669291338586,904.9858945611932,0.00025370340306410486,25.0,90.0
418.64941,0.05968382086614173,904.6486676748189,0.00025370340306410486,25.0,90.0
419.95068,0.06000563779527559,905.8355060749857,0.00025370340306410486,25.0,90.0
421.25195,0.06032718700787402,904.67424518955,0.00025370340306410486,25.0,90.0
422.55322,0.060618809055118114,904.4015487302498,0.00025370340306410486,25.0,90.0
423.85449,0.06100765354330709,908.2034989831569,0.00025370340306410486,25.0,90.0
425.15576,0.06129707086614174,906.3440840590291,0.00025370340306410486,25.0,90.0
426.45703,0.061591990157480306,907.9327840642437,0.00025370340306410486,25.0,90.0
427.7583,0.061850460629921264,908.0852323095376,0.00025370340306410486,25.0,90.0
429.05957,0.06213164763779527,908.1105751681702,0.00025370340306410486,25.0,90.0
430.36084,0.0624033405511811,907.4551285393961,0.00025370340306410486,25.0,90.0
431.66211,0.06270802952755905,909.8472649528081,0.00025370340306410486,25.0,90.0
432.96338,0.06301873622047244,909.5056838921624,0.00025370340306410486,25.0,90.0
434.26465,0.06331484055118111,909.2549408145175,0.00025370340306410486,25.0,90.0
435.56592,0.06357603346456693,908.9026177191427,0.00025370340306410486,25.0,90.0
436.86719,0.06394633858267716,909.9388590499035,0.00025370340306410486,25.0,90.0
438.16846,0.06422050787401574,910.1184231110185,0.00025370340306410486,25.0,90.0
439.46973,0.06451744094488189,911.6271575324607,0.00025370340306410486,25.0,90.0
440.771,0.06481710039370078,909.9353652813267,0.00025370340306410486,25.0,90.0
442.07227,0.06509554133858267,911.399097877666,0.00025370340306410486,25.0,90.0
443.37354,0.06537065551181102,914.5670594983575,0.00025370340306410486,25.0,90.0
444.6748,0.06574421653543307,913.0616884809929,0.00025370340306410486,25.0,90.0
445.97607,0.06608768897637794,913.5602805444022,0.00025370340306410486,25.0,90.0
447.27734,0.06639499803149607,913.2934504875632,0.00025370340306410486,25.0,90.0
448.57861,0.06674082283464566,914.7402617719143,0.00025370340306410486,25.0,90.0
449.87988,0.06709551771653544,916.8176722115035,0.00025370340306410486,25.0,90.0
451.18115,0.06739790551181103,914.818037232101,0.00025370340306410486,25.0,90.0
452.48242,0.06764693700787401,914.2122334045993,0.00025370340306410486,25.0,90.0
453.78369,0.0679821594488189,915.795588465349,0.00025370340306410486,25.0,90.0
455.08496,0.06828806102362205,915.9139072847682,0.00025370340306410486,25.0,90.0
456.38623,0.06859130118110236,916.6773217917297,0.00025370340306410486,25.0,90.0
457.6875,0.0688563248031496,915.6300776972415,0.00025370340306410486,25.0,90.0
458.98877,0.06918286417322835,916.2160139750744,0.00025370340306410486,25.0,90.0
460.29004,0.0695091122047244,916.9605256296607,0.00025370340306410486,25.0,90.0
461.59131,0.06980225984251968,915.4603170464619,0.00025370340306410486,25.0,90.0
462.89258,0.07012080511811024,918.1447567398446,0.00025370340306410486,25.0,90.0
464.19385,0.0704072657480315,918.6041612348125,0.00025370340306410486,25.0,90.0
465.49512,0.07071963779527558,920.3086249152631,0.00025370340306410486,25.0,90.0
466.79639,0.07103425787401575,921.5393179329405,0.00025370340306410486,25.0,90.0
468.09766,0.07135069094488189,919.4547635187986,0.00025370340306410486,25.0,90.0
469.39893,0.0716486496062992,919.4914220159567,0.00025370340306410486,25.0,90.0
470.7002,0.07196536417322834,921.4472805965479,0.00025370340306410486,25.0,90.0
472.00146,0.07234445078740158,922.2898002815873,0.00025370340306410486,25.0,90.0
473.30273,0.07269240551181103,920.8701308859571,0.00025370340306410486,25.0,90.0
474.604,0.07301093700787402,922.8252854982532,0.00025370340306410486,25.0,90.0
475.90527,0.07330400984251968,922.0104291599312,0.00025370340306410486,25.0,90.0
477.20654,0.07362395669291338,923.9090577254003,0.00025370340306410486,25.0,90.0
478.50781,0.07391048622047244,921.8157167440163,0.00025370340306410486,25.0,90.0
479.80908,0.07424398622047244,923.9729624028785,0.00025370340306410486,25.0,90.0
481.11035,0.07462687992125984,926.9880846847786,0.00025370340306410486,25.0,90.0
482.41162,0.07494218700787401,924.3021849090056,0.00025370340306410486,25.0,90.0
483.71289,0.07527850196850394,924.9354174271263,0.00025370340306410486,25.0,90.0
485.01416,0.07559250590551181,925.5777493872869,0.00025370340306410486,25.0,90.0
486.31543,0.07588140551181102,925.421364134119,0.00025370340306410486,25.0,90.0
487.6167,0.07622169881889763,927.099103092246,0.00025370340306410486,25.0,90.0
488.91797,0.07654755314960629,927.02576002503,0.00025370340306410486,25.0,90.0
490.21924,0.07689907283464567,926.8611618084163,0.00025370340306410486,25.0,90.0
491.52051,0.07722001181102361,925.7729832611983,0.00025370340306410486,25.0,90.0
492.82178,0.07749345275590551,926.0965479480627,0.00025370340306410486,25.0,90.0
494.12305,0.07776413779527559,928.3646816498931,0.00025370340306410486,25.0,90.0
495.42432,0.07808143897637795,928.6331021536215,0.00025370340306410486,25.0,90.0
496.72559,0.0784275688976378,928.6389164102832,0.00025370340306410486,25.0,90.0
498.02686,0.07873887401574803,926.8933618397039,0.00025370340306410486,25.0,90.0
499.32813,0.07904418897637795,928.3588152474318,0.00025370340306410486,25.0,90.0
500.62939,0.07935792913385827,928.459221984669,0.00025370340306410486,25.0,90.0
501.93066,0.07967315354330709,929.3770402044116,0.00025370340306410486,25.0,90.0
503.23193,0.08004761220472441,930.9538248944048,0.00025370340306410486,25.0,90.0
504.5332,0.08031110433070866,929.3035928455963,0.00025370340306410486,25.0,90.0
505.83447,0.08062653346456693,931.3457527246181,0.00025370340306410486,25.0,90.0
507.13574,0.08095901771653544,931.9546070813997,0.00025370340306410486,25.0,90.0
508.43701,0.08128587598425197,930.8754758304218,0.00025370340306410486,25.0,90.0
509.73828,0.08157395472440944,931.7772592167701,0.00025370340306410486,25.0,90.0
511.03955,0.08185907677165354,931.5272983261198,0.00025370340306410486,25.0,90.0
512.34082,0.08217516929133858,933.4425353287793,0.00025370340306410486,25.0,90.0
513.64209,0.08255275590551181,931.8326380560046,0.00025370340306410486,25.0,90.0
514.94336,0.08285918503937008,933.5192939458726,0.00025370340306410486,25.0,90.0
516.24463,0.08323574015748031,933.5067007352558,0.00025370340306410486,25.0,90.0
517.5459,0.08355852559055119,932.4511133128226,0.00025370340306410486,25.0,90.0
518.84717,0.08389033464566929,935.4581529957762,0.00025370340306410486,25.0,90.0
520.14844,0.08420946653543307,933.6751316681442,0.00025370340306410486,25.0,90.0
521.44971,0.08449399015748031,933.7609375814778,0.00025370340306410486,25.0,90.0
522.75098,0.08483089763779528,935.5051885070658,0.00025370340306410486,25.0,90.0
524.05225,0.08523264763779527,934.9270740991814,0.00025370340306410486,25.0,90.0
525.35352,0.0855621751968504,935.5801220211712,0.00025370340306410486,25.0,90.0
526.65479,0.08592725787401574,936.2341085675549,0.00025370340306410486,25.0,90.0
527.95605,0.08622985236220472,935.8583459352349,0.00025370340306410486,25.0,90.0
529.25732,0.08656346850393701,937.1728893987589,0.00025370340306410486,25.0,90.0
530.55859,0.08688285039370079,938.5215362152579,0.00025370340306410486,25.0,90.0
531.85986,0.0872299251968504,937.1239244928821,0.00025370340306410486,25.0,90.0
533.16113,0.08758814566929134,938.699249100485,0.00025370340306410486,25.0,90.0
534.4624,0.08791462795275591,937.2272513949001,0.00025370340306410486,25.0,90.0
535.76367,0.08823072637795276,937.1157897481359,0.00025370340306410486,25.0,90.0
537.06494,0.08855039173228346,938.9942378891382,0.00025370340306410486,25.0,90.0
538.36621,0.08886801968503936,937.9532773635084,0.00025370340306410486,25.0,90.0
539.66748,0.08917056692913386,938.954242060802,0.00025370340306410486,25.0,90.0
540.96875,0.08946989173228347,939.5227616415498,0.00025370340306410486,25.0,90.0
542.27002,0.08982300196850393,940.4594305678678,0.00025370340306410486,25.0,90.0
543.57129,0.09016998818897637,940.118944569015,0.00025370340306410486,25.0,90.0
544.87256,0.09050062992125985,940.0835375710486,0.00025370340306410486,25.0,90.0
546.17383,0.0908704901574803,942.2019085362674,0.00025370340306410486,25.0,90.0
547.4751,0.09120326181102362,941.331673358711,0.00025370340306410486,25.0,90.0
548.77637,0.09152544291338582,941.382724096574,0.00025370340306410486,25.0,90.0
550.07764,0.09187804330708661,941.8364707722793,0.00025370340306410486,25.0,90.0
551.37891,0.0922766437007874,942.9152109297596,0.00025370340306410486,25.0,90.0
552.68018,0.09263812598425197,941.8595713615268,0.00025370340306410486,25.0,90.0
553.98145,0.09297278543307087,941.1426187620586,0.00025370340306410486,25.0,90.0
555.28271,0.09327822440944881,943.1250977733744,0.00025370340306410486,25.0,90.0
556.58398,0.0936203346456693,942.3691922615633,0.00025370340306410486,25.0,90.0
557.88525,0.09398750787401575,943.5419512958231,0.00025370340306410486,25.0,90.0
559.18652,0.09428875787401575,943.0700839547375,0.00025370340306410486,25.0,90.0
560.48779,0.0946294311023622,944.3572508734421,0.00025370340306410486,25.0,90.0
561.78906,0.0949470846456693,944.1612608854357,0.00025370340306410486,25.0,90.0
563.09033,0.0952675,944.0568649945247,0.00025370340306410486,25.0,90.0
564.3916,0.09560999803149606,944.1626688220264,0.00025370340306410486,25.0,90.0
565.69287,0.09594836614173229,944.4992699588048,0.00025370340306410486,25.0,90.0
566.99414,0.09626261023622047,945.3345413776921,0.00025370340306410486,25.0,90.0
568.29541,0.09658762007874015,944.9912395056579,0.00025370340306410486,25.0,90.0
569.59668,0.09690100787401575,946.2543411378214,0.00025370340306410486,25.0,90.0
570.89795,0.09723117322834646,945.6847525681807,0.00025370340306410486,25.0,90.0
572.19922,0.09751941141732284,944.5332429472807,0.00025370340306410486,25.0,90.0
573.50049,0.09782547244094487,945.1442613547479,0.00025370340306410486,25.0,90.0
574.80176,0.09816471456692913,948.4513740418209,0.00025370340306410486,25.0,90.0
576.10303,0.09858499212598426,948.8199926995882,0.00025370340306410486,25.0,90.0
577.4043,0.09894056496062993,946.5610366584972,0.00025370340306410486,25.0,90.0
578.70557,0.09925753740157481,947.2907128330813,0.00025370340306410486,25.0,90.0
580.00684,0.09964261023622047,948.3147781196225,0.00025370340306410486,25.0,90.0
581.30811,0.09999220078740158,947.2094696772175,0.00025370340306410486,25.0,90.0
582.60938,0.10034307086614173,948.6508838713041,0.00025370340306410486,25.0,90.0
583.91064,0.10068351968503937,948.9363560515201,0.00025370340306410486,25.0,90.0
585.21191,0.10099050787401576,948.8181675966001,0.00025370340306410486,25.0,90.0
586.51318,0.10135012992125984,949.824529384158,0.00025370340306410486,25.0,90.0
587.81445,0.10172779921259843,950.1880116806591,0.00025370340306410486,25.0,90.0
589.11572,0.10216084842519685,951.4510350941232,0.00025370340306410486,25.0,90.0
590.41699,0.10254283267716537,951.3885383532356,0.00025370340306410486,25.0,90.0
591.71826,0.10286932086614173,950.6061427751995,0.00025370340306410486,25.0,90.0
593.01953,0.10320373031496063,951.0024769254837,0.00025370340306410486,25.0,90.0
594.3208,0.10354670275590551,951.902591646243,0.00025370340306410486,25.0,90.0
595.62207,0.10387418700787401,950.0985816342494,0.00025370340306410486,25.0,90.0
596.92334,0.10420326968503937,951.1972414871982,0.00025370340306410486,25.0,90.0
598.22461,0.10455490157480314,951.274834437086,0.00025370340306410486,25.0,90.0
599.52588,0.10491275196850394,950.8385566042655,0.00025370340306410486,25.0,90.0
600.82715,0.10534538976377954,952.8135526933306,0.00025370340306410486,25.0,90.0
602.12842,0.10572924212598425,951.8585545184336,0.00025370340306410486,25.0,90.0
603.42969,0.10605999999999999,951.3836887938677,0.00025370340306410486,25.0,90.0
604.73096,0.10642174606299212,952.4152109297597,0.00025370340306410486,25.0,90.0
606.03223,0.10672080314960629,953.0229180789487,0.00025370340306410486,25.0,90.0
607.3335,0.10704409842519685,951.9337226886374,0.00025370340306410486,25.0,90.0
608.63477,0.10735822047244094,952.3393387912604,0.00025370340306410486,25.0,90.0
609.93604,0.10769277952755905,952.741826145904,0.00025370340306410486,25.0,90.0
611.2373,0.10809058267716534,954.1976586535955,0.00025370340306410486,25.0,90.0
612.53857,0.10850348622047243,955.8368357928769,0.00025370340306410486,25.0,90.0
613.83984,0.10888107086614174,954.7883141262972,0.00025370340306410486,25.0,90.0
615.14111,0.10928592519685039,954.012567137717,0.00025370340306410486,25.0,90.0
616.44238,0.10963593897637795,954.0915680241957,0.00025370340306410486,25.0,90.0
617.74365,0.10995376771653544,953.7456588621786,0.00025370340306410486,25.0,90.0
619.04492,0.1102771811023622,955.0608802210983,0.00025370340306410486,25.0,90.0
620.34619,0.1106257874015748,955.6635813735204,0.00025370340306410486,25.0,90.0
621.64746,0.11098491535433071,956.2834384940293,0.00025370340306410486,25.0,90.0
622.94873,0.111389781496063,955.7577827605987,0.00025370340306410486,25.0,90.0
624.25,0.11180348228346455,957.7257130938103,0.00025370340306410486,25.0,90.0
625.55127,0.11223215551181102,956.8117015174428,0.00025370340306410486,25.0,90.0
626.85254,0.11259391338582678,955.6592271992491,0.00025370340306410486,25.0,90.0
628.15381,0.11298247047244094,957.4327840642437,0.00025370340306410486,25.0,90.0
629.45508,0.11337790157480315,956.6505970694061,0.00025370340306410486,25.0,90.0
630.75635,0.11370492913385827,957.4033738332378,0.00025370340306410486,25.0,90.0
632.05762,0.11412422637795276,957.8361578974814,0.00025370340306410486,25.0,90.0
633.35889,0.11449738976377953,955.5054492360641,0.00025370340306410486,25.0,90.0
634.66016,0.11479114173228346,958.1671012149972,0.00025370340306410486,25.0,90.0
635.96143,0.115116,956.1355008604057,0.00025370340306410486,25.0,90.0
637.2627,0.11552190944881889,958.9250925587944,0.00025370340306410486,25.0,90.0
638.56396,0.11592203543307086,958.3826458778746,0.00025370340306410486,25.0,90.0
639.86523,0.11630281299212597,959.305756896282,0.00025370340306410486,25.0,90.0
641.1665,0.11663747834645669,958.2600250299839,0.00025370340306410486,25.0,90.0
642.46777,0.11697967716535435,958.2605986337801,0.00025370340306410486,25.0,90.0
643.76904,0.11736419685039369,959.9666266882203,0.00025370340306410486,25.0,90.0
645.07031,0.11776176574803149,959.6207175262033,0.00025370340306410486,25.0,90.0
646.37158,0.11814629724409448,959.6773739375293,0.00025370340306410486,25.0,90.0
647.67285,0.11856456299212598,958.9335662512384,0.00025370340306410486,25.0,90.0
648.97412,0.11892416141732283,960.5028419460813,0.00025370340306410486,25.0,90.0
650.27539,0.11933991535433072,959.6423058872607,0.00025370340306410486,25.0,90.0
651.57666,0.11970603740157479,958.8361057516818,0.00025370340306410486,25.0,90.0
652.87793,0.12008855118110236,960.1146686134432,0.00025370340306410486,25.0,90.0
654.1792,0.1204787283464567,960.6412890441675,0.00025370340306410486,25.0,90.0
655.48047,0.12089858858267716,961.0205454450645,0.00025370340306410486,25.0,90.0
656.78174,0.12126259842519684,959.9639933253376,0.00025370340306410486,25.0,90.0
658.08301,0.12167598228346456,962.4958022631278,0.00025370340306410486,25.0,90.0
659.38428,0.12214279921259842,962.5112634927257,0.00025370340306410486,25.0,90.0
660.68555,0.12252950196850393,960.376675183814,0.00025370340306410486,25.0,90.0
661.98682,0.12290798031496063,960.8703916149553,0.00025370340306410486,25.0,90.0
663.28809,0.12333930511811024,962.7299108306826,0.00025370340306410486,25.0,90.0
664.58936,0.12367221062992127,960.6387338999843,0.00025370340306410486,25.0,90.0
665.89063,0.12403717125984251,962.1328414246233,0.00025370340306410486,25.0,90.0
667.19189,0.12439793307086615,962.2817959013402,0.00025370340306410486,25.0,90.0
668.49316,0.12478910629921261,964.1440006257496,0.00025370340306410486,25.0,90.0
669.79443,0.1251919527559055,962.4977838035146,0.00025370340306410486,25.0,90.0
671.0957,0.12557742322834645,963.3420764457424,0.00025370340306410486,25.0,90.0
672.39697,0.12599333070866142,962.8310736820149,0.00025370340306410486,25.0,90.0
673.69824,0.1264198090551181,962.2971267664391,0.00025370340306410486,25.0,90.0
674.99951,0.12683194881889764,963.647885487824,0.00025370340306410486,25.0,90.0
676.30078,0.127179968503937,961.7283725295927,0.00025370340306410486,25.0,90.0
677.60205,0.12757092913385826,962.0840329561454,0.00025370340306410486,25.0,90.0
678.90332,0.12790971456692915,962.2111383428064,0.00025370340306410486,25.0,90.0
680.20459,0.12833952362204726,963.2835949314283,0.00025370340306410486,25.0,90.0
681.50586,0.12869256496062992,961.9551285393961,0.00025370340306410486,25.0,90.0
682.80713,0.1290577125984252,964.1672315794963,0.00025370340306410486,25.0,90.0
684.1084,0.1295368622047244,965.4836783647077,0.00025370340306410486,25.0,90.0
685.40967,0.13000024212598424,963.7423997497001,0.00025370340306410486,25.0,90.0
686.71094,0.13046885236220473,964.5372581738541,0.00025370340306410486,25.0,90.0
688.01221,0.13088044291338582,964.5278458570162,0.00025370340306410486,25.0,90.0
689.31348,0.13131662401574803,963.9279084319759,0.00025370340306410486,25.0,90.0
690.61475,0.1316845649606299,963.3746675705272,0.00025370340306410486,25.0,90.0
691.91602,0.132069718503937,963.9473848881472,0.00025370340306410486,25.0,90.0
693.21729,0.1324284035433071,963.4695989988006,0.00025370340306410486,25.0,90.0
694.51855,0.13286710629921258,965.1909318454399,0.00025370340306410486,25.0,90.0
695.81982,0.13328536023622048,965.166371173802,0.00025370340306410486,25.0,90.0
697.12109,0.13370221850393701,965.1115659383637,0.00025370340306410486,25.0,90.0
698.42236,0.13417882086614172,967.6226729936903,0.00025370340306410486,25.0,90.0
699.72363,0.13467907677165356,966.6612348125358,0.00025370340306410486,25.0,90.0
701.0249,0.13507450984251967,964.8179850863013,0.00025370340306410486,25.0,90.0
702.32617,0.13546605708661416,965.2561923137091,0.00025370340306410486,25.0,90.0
703.62744,0.13588129527559056,965.0002868018981,0.00025370340306410486,25.0,90.0
704.92871,0.13627112992125986,965.7982739740314,0.00025370340306410486,25.0,90.0
706.22998,0.13673211614173228,966.4695729259008,0.00025370340306410486,25.0,90.0
707.53125,0.13713159645669293,964.6782604161235,0.00025370340306410486,25.0,90.0
708.83252,0.13755435629921262,966.0962350732649,0.00025370340306410486,25.0,90.0
710.13379,0.13807317322834645,967.4340616363352,0.00025370340306410486,25.0,90.0
711.43506,0.13842608464566927,962.629399801846,0.00025370340306410486,25.0,90.0
712.73633,0.13877784645669292,964.6133910413516,0.00025370340306410486,25.0,90.0
714.0376,0.1391237401574803,966.5768107628932,0.00025370340306410486,25.0,90.0
715.33887,0.1394808405511811,965.0494342180738,0.00025370340306410486,25.0,90.0
716.64014,0.13989942322834645,968.5202064973666,0.00025370340306410486,25.0,90.0
717.94141,0.1403483346456693,968.8569901444439,0.00025370340306410486,25.0,90.0
719.24268,0.14081555118110234,966.9932471189445,0.00025370340306410486,25.0,90.0
720.54395,0.14125748228346457,967.0525108202534,0.00025370340306410486,25.0,90.0
721.84521,0.14168783267716534,967.212728789696,0.00025370340306410486,25.0,90.0
723.14648,0.1420889311023622,966.6675183813944,0.00025370340306410486,25.0,90.0
724.44775,0.1425279527559055,968.3517755644783,0.00025370340306410486,25.0,90.0
725.74902,0.14305058464566928,968.5611930958961,0.00025370340306410486,25.0,90.0
727.05029,0.14349770078740157,966.6090890128801,0.00025370340306410486,25.0,90.0
728.35156,0.14391709251968504,967.321504927778,0.00025370340306410486,25.0,90.0
729.65283,0.1443838622047244,968.1786254367211,0.00025370340306410486,25.0,90.0
730.9541,0.14489371653543306,967.6591489805496,0.00025370340306410486,25.0,90.0
732.25537,0.14535740157480315,967.9128643687751,0.00025370340306410486,25.0,90.0
733.55664,0.14585711811023622,968.6046044741097,0.00025370340306410486,25.0,90.0
734.85791,0.1463806535433071,968.8522188037754,0.00025370340306410486,25.0,90.0
736.15918,0.14685645866141733,966.3008030453146,0.00025370340306410486,25.0,90.0
737.46045,0.1472670255905512,966.6262710538666,0.00025370340306410486,25.0,90.0
738.76172,0.14767938976377953,969.0525890389529,0.00025370340306410486,25.0,90.0
740.06299,0.14817611417322835,968.8308390259165,0.00025370340306410486,25.0,90.0
741.36426,0.14862973228346457,967.5310788965949,0.00025370340306410486,25.0,90.0
742.66553,0.14906875196850394,967.1204828701049,0.00025370340306410486,25.0,90.0
743.9668,0.14950937007874016,967.932731918444,0.00025370340306410486,25.0,90.0
745.26807,0.14998141929133857,969.54242060802,0.00025370340306410486,25.0,90.0
746.56934,0.15043520078740155,968.7219846691348,0.00025370340306410486,25.0,90.0
747.87061,0.15087510236220472,967.629530166345,0.00025370340306410486,25.0,90.0
749.17188,0.15133429133858267,966.8815247431819,0.00025370340306410486,25.0,90.0
750.47314,0.15174488385826773,969.2245398133181,0.00025370340306410486,25.0,90.0
751.77441,0.15223774803149606,969.4670438546176,0.00025370340306410486,25.0,90.0
753.07568,0.15275647244094487,968.536814934557,0.00025370340306410486,25.0,90.0
754.37695,0.15315161220472442,965.8607707149189,0.00025370340306410486,25.0,90.0
755.67822,0.15355491732283463,967.9694425614017,0.00025370340306410486,25.0,90.0
756.97949,0.1540243149606299,969.2692809094228,0.00025370340306410486,25.0,90.0
758.28076,0.15464470866141733,968.1076550033895,0.00025370340306410486,25.0,90.0
759.58203,0.1551361535433071,967.9859988527924,0.00025370340306410486,25.0,90.0
760.8833,0.15558198031496062,967.7662043072431,0.00025370340306410486,25.0,90.0
762.18457,0.15607162992125984,967.7413829066069,0.00025370340306410486,25.0,90.0
763.28564,0.156510874015748,971.3152735047192,0.00025370340306410486,25.0,90.0