File: datasets/am_bench_2022/csv/90-XY.16-3.csv
Time(s),Strain(%),Stress(MPa),SR(s-1),Temp(C),Angle(deg)
12.287598,1.5937853346456692e-05,15.789710761154854,0.00025370340306410486,25.0,90.0
13.588867,2.343553346456693e-05,21.02295091863517,0.00025370340306410486,25.0,90.0
14.890137,6.130123818897638e-05,25.51035433070866,0.00025370340306410486,25.0,90.0
16.191406,8.174011811023622e-05,28.427881889763782,0.00025370340306410486,25.0,90.0
17.492676,6.314444881889763e-05,32.66009186351706,0.00025370340306410486,25.0,90.0
18.793945,6.999297047244094e-05,36.749314960629924,0.00025370340306410486,25.0,90.0
20.095215,0.00011254858070866142,40.1433280839895,0.00025370340306410486,25.0,90.0
21.396484,0.0001382974842519685,45.919816272965875,0.00025370340306410486,25.0,90.0
22.697754,0.0001500438346456693,52.16848556430446,0.00025370340306410486,25.0,90.0
23.999023,0.0001743466003937008,57.26625196850393,0.00025370340306410486,25.0,90.0
25.300293,0.00019830311023622045,64.5777217847769,0.00025370340306410486,25.0,90.0
26.601563,0.00022684488188976377,70.9417874015748,0.00025370340306410486,25.0,90.0
27.902832,0.00025059326771653543,77.54616010498688,0.00025370340306410486,25.0,90.0
29.204102,0.00027106462598425196,83.54987139107612,0.00025370340306410486,25.0,90.0
30.505371,0.00030711513779527557,89.78536482939633,0.00025370340306410486,25.0,90.0
31.806641,0.0003462158464566929,96.00991076115486,0.00025370340306410486,25.0,90.0
33.10791,0.0003442661417322835,106.27583202099737,0.00025370340306410486,25.0,90.0
34.40918,0.000389328031496063,113.05659842519684,0.00025370340306410486,25.0,90.0
35.710449,0.0003999466732283464,120.41256692913386,0.00025370340306410486,25.0,90.0
37.011719,0.0004542833464566929,126.71372703412072,0.00025370340306410486,25.0,90.0
38.312988,0.00048627572834645665,137.9315406824147,0.00025370340306410486,25.0,90.0
39.614258,0.0004959967913385826,143.88933858267717,0.00025370340306410486,25.0,90.0
40.915527,0.0005343860236220472,152.6556377952756,0.00025370340306410486,25.0,90.0
42.216797,0.0006029371850393701,161.65995800524934,0.00025370340306410486,25.0,90.0
43.518066,0.0006124137598425197,170.50166141732282,0.00025370340306410486,25.0,90.0
44.819336,0.0006445650984251969,178.29551443569554,0.00025370340306410486,25.0,90.0
46.120605,0.0006840683464566929,187.16365091863517,0.00025370340306410486,25.0,90.0
47.421875,0.000697559468503937,194.07092388451443,0.00025370340306410486,25.0,90.0
48.723145,0.0007333085039370079,204.40841994750656,0.00025370340306410486,25.0,90.0
50.024414,0.0007751008267716536,213.50278740157478,0.00025370340306410486,25.0,90.0
51.325684,0.0008130071259842519,224.44911286089237,0.00025370340306410486,25.0,90.0
52.626953,0.0008445913188976378,231.98770866141732,0.00025370340306410486,25.0,90.0
53.928223,0.0008762223818897638,241.41461154855642,0.00025370340306410486,25.0,90.0
55.229492,0.0009189933661417323,251.23728346456693,0.00025370340306410486,25.0,90.0
56.530762,0.0009787651181102361,259.8154146981627,0.00025370340306410486,25.0,90.0
57.832031,0.001009308188976378,269.6838320209974,0.00025370340306410486,25.0,90.0
59.133301,0.0010070874015748032,276.15322834645673,0.00025370340306410486,25.0,90.0
60.43457,0.001060306811023622,288.42590551181104,0.00025370340306410486,25.0,90.0
61.73584,0.0010901576181102362,296.3735433070866,0.00025370340306410486,25.0,90.0
63.037109,0.0011216991141732285,307.1501837270341,0.00025370340306410486,25.0,90.0
64.338379,0.001163603779527559,315.2332283464567,0.00025370340306410486,25.0,90.0
65.639648,0.0011984733661417324,326.72128608923884,0.00025370340306410486,25.0,90.0
66.940918,0.0012246201574803149,333.0702362204724,0.00025370340306410486,25.0,90.0
68.242188,0.0012717454527559054,343.03587926509186,0.00025370340306410486,25.0,90.0
69.543457,0.0013060149212598424,354.6215223097113,0.00025370340306410486,25.0,90.0
70.844727,0.0013479493700787402,363.30317585301833,0.00025370340306410486,25.0,90.0
72.145996,0.0013880285039370077,374.40955380577424,0.00025370340306410486,25.0,90.0
73.447266,0.0014236186811023622,384.98627296587927,0.00025370340306410486,25.0,90.0
74.748535,0.001458110157480315,393.0778477690289,0.00025370340306410486,25.0,90.0
76.049805,0.0015016673622047245,402.99167979002624,0.00025370340306410486,25.0,90.0
77.351074,0.0015219675393700787,411.4255380577428,0.00025370340306410486,25.0,90.0
78.652344,0.0015421611023622049,420.4509973753281,0.00025370340306410486,25.0,90.0
79.953613,0.0016067085433070865,429.8559842519685,0.00025370340306410486,25.0,90.0
81.254883,0.0016274964566929135,438.65162729658795,0.00025370340306410486,25.0,90.0
82.556152,0.00166508468503937,448.08152230971126,0.00025370340306410486,25.0,90.0
83.857422,0.0017019331496062992,458.9041994750656,0.00025370340306410486,25.0,90.0
85.158691,0.0017331093700787403,465.6210498687664,0.00025370340306410486,25.0,90.0
86.459961,0.0017527294685039368,473.459842519685,0.00025370340306410486,25.0,90.0
87.76123,0.0017987512795275592,481.1103412073491,0.00025370340306410486,25.0,90.0
89.0625,0.001842451220472441,491.6989501312336,0.00025370340306410486,25.0,90.0
90.36377,0.0018671549212598423,500.7956692913386,0.00025370340306410486,25.0,90.0
91.665039,0.0018990780118110235,509.3302624671916,0.00025370340306410486,25.0,90.0
92.966309,0.0019385028346456691,518.2192125984252,0.00025370340306410486,25.0,90.0
94.267578,0.0019691427165354327,524.767532808399,0.00025370340306410486,25.0,90.0
95.568848,0.0020085692913385826,534.5097900262467,0.00025370340306410486,25.0,90.0
96.870117,0.002037811023622047,543.2151968503937,0.00025370340306410486,25.0,90.0
98.171387,0.002073365748031496,550.2593175853018,0.00025370340306410486,25.0,90.0
99.472656,0.002097548622047244,555.8318110236221,0.00025370340306410486,25.0,90.0
100.77393,0.002135181692913386,564.5672440944883,0.00025370340306410486,25.0,90.0
102.0752,0.002143231102362205,572.6576640419947,0.00025370340306410486,25.0,90.0
103.37646,0.0021852454724409446,578.4369291338583,0.00025370340306410486,25.0,90.0
104.67773,0.002230782086614173,584.4644619422572,0.00025370340306410486,25.0,90.0
105.979,0.002256158464566929,593.3469553805774,0.00025370340306410486,25.0,90.0
107.28027,0.002276101377952756,599.2996062992125,0.00025370340306410486,25.0,90.0
108.58154,0.00233083562992126,606.5562204724409,0.00025370340306410486,25.0,90.0
109.88281,0.0023591167322834644,611.1938057742782,0.00025370340306410486,25.0,90.0
111.18408,0.0023705244094488188,616.0544619422573,0.00025370340306410486,25.0,90.0
112.48535,0.0023893771653543307,623.8463254593175,0.00025370340306410486,25.0,90.0
113.78662,0.0024312866141732283,629.0649606299213,0.00025370340306410486,25.0,90.0
115.08789,0.002462696850393701,634.3520472440945,0.00025370340306410486,25.0,90.0
116.38916,0.0024773277559055114,639.2712598425197,0.00025370340306410486,25.0,90.0
117.69043,0.0025121950787401577,643.9435170603674,0.00025370340306410486,25.0,90.0
118.9917,0.0025423220472440946,648.8584251968504,0.00025370340306410486,25.0,90.0
120.29297,0.0025618901574803146,651.4592125984252,0.00025370340306410486,25.0,90.0
121.59424,0.0025906950787401577,656.400971128609,0.00025370340306410486,25.0,90.0
122.89551,0.0026468555118110237,662.2130446194226,0.00025370340306410486,25.0,90.0
124.19678,0.002662173622047244,664.6299212598425,0.00025370340306410486,25.0,90.0
125.49805,0.002674749212598425,667.0799212598425,0.00025370340306410486,25.0,90.0
126.79932,0.002718896062992126,672.1736745406823,0.00025370340306410486,25.0,90.0
128.10059,0.0027452889763779527,675.7940682414699,0.00025370340306410486,25.0,90.0
129.40186,0.002762681102362205,681.0007874015747,0.00025370340306410486,25.0,90.0
130.70313,0.0028195185039370076,683.7396587926509,0.00025370340306410486,25.0,90.0
132.00439,0.0028601098425196847,687.3758792650918,0.00025370340306410486,25.0,90.0
133.30566,0.0028698096456692915,690.8292125984252,0.00025370340306410486,25.0,90.0
134.60693,0.0029046811023622048,695.1931233595801,0.00025370340306410486,25.0,90.0
135.9082,0.0029439970472440943,698.3980839895013,0.00025370340306410486,25.0,90.0
137.20947,0.0029990370078740156,701.4234383202099,0.00025370340306410486,25.0,90.0
138.51074,0.0030371751968503937,704.6741732283464,0.00025370340306410486,25.0,90.0
139.81201,0.0031006529527559056,709.8679002624672,0.00025370340306410486,25.0,90.0
141.11328,0.0031545854330708657,713.922939632546,0.00025370340306410486,25.0,90.0
142.41455,0.003192113188976378,717.4459842519685,0.00025370340306410486,25.0,90.0
143.71582,0.003238293700787402,718.8918635170604,0.00025370340306410486,25.0,90.0
145.01709,0.003288202559055118,721.9641207349082,0.00025370340306410486,25.0,90.0
146.31836,0.0033550470472440944,726.2629921259842,0.00025370340306410486,25.0,90.0
147.61963,0.003397027755905512,727.1720734908137,0.00025370340306410486,25.0,90.0
148.9209,0.003468088385826772,731.4054593175853,0.00025370340306410486,25.0,90.0
150.22217,0.0035440996062992124,735.761154855643,0.00025370340306410486,25.0,90.0
151.52344,0.0035953228346456696,738.3634120734908,0.00025370340306410486,25.0,90.0
152.82471,0.003675623622047244,740.5620209973753,0.00025370340306410486,25.0,90.0
154.12598,0.0037554996062992125,743.7880577427821,0.00025370340306410486,25.0,90.0
155.42725,0.003835493307086614,744.8834908136483,0.00025370340306410486,25.0,90.0
156.72852,0.0039045600393700784,747.0553280839895,0.00025370340306410486,25.0,90.0
158.02979,0.003976776771653544,747.9932283464567,0.00025370340306410486,25.0,90.0
159.33105,0.004072078543307087,750.985091863517,0.00025370340306410486,25.0,90.0
160.63232,0.004159306692913386,754.7040419947506,0.00025370340306410486,25.0,90.0
161.93359,0.004280426771653543,755.10343832021,0.00025370340306410486,25.0,90.0
163.23486,0.004397982677165354,759.7737532808399,0.00025370340306410486,25.0,90.0
164.53613,0.004527725590551181,762.02312335958,0.00025370340306410486,25.0,90.0
165.8374,0.004666406102362204,764.4327559055118,0.00025370340306410486,25.0,90.0
167.13867,0.004788924015748031,766.3983727034121,0.00025370340306410486,25.0,90.0
168.43994,0.004941076181102362,767.0385826771653,0.00025370340306410486,25.0,90.0
169.74121,0.00505640905511811,770.4098950131233,0.00025370340306410486,25.0,90.0
171.04248,0.00519311594488189,770.8091076115486,0.00025370340306410486,25.0,90.0
172.34375,0.005333913188976378,771.2176115485564,0.00025370340306410486,25.0,90.0
173.64502,0.005471643307086614,774.712467191601,0.00025370340306410486,25.0,90.0
174.94629,0.005661531889763779,777.1254330708662,0.00025370340306410486,25.0,90.0
176.24756,0.005842699015748031,777.697217847769,0.00025370340306410486,25.0,90.0
177.54883,0.006046754527559055,781.2089238845144,0.00025370340306410486,25.0,90.0
178.8501,0.006254710433070866,780.3427034120735,0.00025370340306410486,25.0,90.0
180.15137,0.006430442125984252,782.5922047244095,0.00025370340306410486,25.0,90.0
181.45264,0.0066454440944881885,786.4269291338583,0.00025370340306410486,25.0,90.0
182.75391,0.0068591708661417325,786.3847769028872,0.00025370340306410486,25.0,90.0
184.05518,0.0070797594488188976,788.6198950131234,0.00025370340306410486,25.0,90.0
185.35645,0.007289502165354331,789.3111286089239,0.00025370340306410486,25.0,90.0
186.65771,0.007518757874015748,792.6353543307087,0.00025370340306410486,25.0,90.0
187.95898,0.007725702165354331,793.9802887139107,0.00025370340306410486,25.0,90.0
189.26025,0.007934009645669291,794.354908136483,0.00025370340306410486,25.0,90.0
190.56152,0.008201727362204725,795.3439632545932,0.00025370340306410486,25.0,90.0
191.86279,0.00849008405511811,798.0267454068241,0.00025370340306410486,25.0,90.0
193.16406,0.008705786417322834,797.3411023622048,0.00025370340306410486,25.0,90.0
194.46533,0.008955936614173229,798.8249868766404,0.00025370340306410486,25.0,90.0
195.7666,0.00917508779527559,800.0179527559055,0.00025370340306410486,25.0,90.0
197.06787,0.009389703543307086,801.6774540682414,0.00025370340306410486,25.0,90.0
198.36914,0.00958865374015748,803.0030708661417,0.00025370340306410486,25.0,90.0
199.67041,0.009870540157480314,804.1300262467191,0.00025370340306410486,25.0,90.0
200.97168,0.010135395866141733,803.9851181102363,0.00025370340306410486,25.0,90.0
202.27295,0.01033136220472441,804.8176377952756,0.00025370340306410486,25.0,90.0
203.57422,0.010573263385826771,806.2803674540681,0.00025370340306410486,25.0,90.0
204.87549,0.010771541141732283,806.6223622047245,0.00025370340306410486,25.0,90.0
206.17676,0.01100675,807.7013910761154,0.00025370340306410486,25.0,90.0
207.47803,0.011270422047244094,810.2832545931758,0.00025370340306410486,25.0,90.0
208.7793,0.01152977933070866,809.5888188976377,0.00025370340306410486,25.0,90.0
210.08057,0.011802890748031496,811.0073490813649,0.00025370340306410486,25.0,90.0
211.38184,0.012060376574803149,812.2074803149605,0.00025370340306410486,25.0,90.0
212.68311,0.012360979527559055,815.7429658792651,0.00025370340306410486,25.0,90.0
213.98438,0.0126841031496063,815.0224146981627,0.00025370340306410486,25.0,90.0
215.28564,0.012954452165354331,815.6134645669291,0.00025370340306410486,25.0,90.0
216.58691,0.013204285629921259,816.7233858267716,0.00025370340306410486,25.0,90.0
217.88818,0.013496675393700787,818.0609711286089,0.00025370340306410486,25.0,90.0
219.18945,0.013771889370078741,817.9918897637796,0.00025370340306410486,25.0,90.0
220.49072,0.01403894566929134,818.8141469816273,0.00025370340306410486,25.0,90.0
221.79199,0.014301690157480316,821.6283727034121,0.00025370340306410486,25.0,90.0
223.09326,0.01452439212598425,820.0313910761154,0.00025370340306410486,25.0,90.0
224.39453,0.014800876181102363,821.7936745406823,0.00025370340306410486,25.0,90.0
225.6958,0.015055083070866141,821.5965879265092,0.00025370340306410486,25.0,90.0
226.99707,0.0152728468503937,823.2062992125984,0.00025370340306410486,25.0,90.0
228.29834,0.015538552559055119,825.5268503937008,0.00025370340306410486,25.0,90.0
229.59961,0.015823059055118112,825.4184251968504,0.00025370340306410486,25.0,90.0
230.90088,0.016105075196850394,825.9065879265091,0.00025370340306410486,25.0,90.0
232.20215,0.01637920531496063,828.5136482939633,0.00025370340306410486,25.0,90.0
233.50342,0.016668176377952756,827.9446719160105,0.00025370340306410486,25.0,90.0
234.80469,0.016946062598425196,828.5250393700787,0.00025370340306410486,25.0,90.0
236.10596,0.01720617716535433,830.162782152231,0.00025370340306410486,25.0,90.0
237.40723,0.01748124153543307,830.6826509186352,0.00025370340306410486,25.0,90.0
238.7085,0.017773505118110235,831.6245931758531,0.00025370340306410486,25.0,90.0
240.00977,0.018015982086614174,831.6197900262467,0.00025370340306410486,25.0,90.0
241.31104,0.018305010236220474,832.8684514435695,0.00025370340306410486,25.0,90.0
242.6123,0.018593073425196848,833.0555643044619,0.00025370340306410486,25.0,90.0
243.91357,0.018871291141732284,835.8363779527559,0.00025370340306410486,25.0,90.0
245.21484,0.019156124803149606,835.7394225721785,0.00025370340306410486,25.0,90.0
246.51611,0.019428793897637797,836.9516010498688,0.00025370340306410486,25.0,90.0
247.81738,0.01973431692913386,836.7402887139108,0.00025370340306410486,25.0,90.0
249.11865,0.0200957874015748,838.4399737532808,0.00025370340306410486,25.0,90.0
250.41992,0.020348639763779527,838.3417322834646,0.00025370340306410486,25.0,90.0
251.72119,0.020582905511811023,837.6280839895013,0.00025370340306410486,25.0,90.0
253.02246,0.02085204724409449,837.7698950131233,0.00025370340306410486,25.0,90.0
254.32373,0.021170866141732286,841.0040157480315,0.00025370340306410486,25.0,90.0
255.625,0.02144930511811024,841.8328346456693,0.00025370340306410486,25.0,90.0
256.92627,0.02175375196850394,841.9779527559056,0.00025370340306410486,25.0,90.0
258.22754,0.022090757874015748,842.6715485564304,0.00025370340306410486,25.0,90.0
259.52881,0.022374761811023623,844.0314960629921,0.00025370340306410486,25.0,90.0
260.83008,0.022663645669291337,843.3772440944882,0.00025370340306410486,25.0,90.0
262.13135,0.022934557086614172,843.6122309711286,0.00025370340306410486,25.0,90.0
263.43262,0.023212958661417323,845.6252755905512,0.00025370340306410486,25.0,90.0
264.73389,0.023458194881889764,845.6016272965879,0.00025370340306410486,25.0,90.0
266.03516,0.023764889763779527,846.5155905511812,0.00025370340306410486,25.0,90.0
267.33643,0.024018627952755906,844.8126771653543,0.00025370340306410486,25.0,90.0
268.6377,0.024333187007874013,848.4328346456693,0.00025370340306410486,25.0,90.0
269.93896,0.02458821062992126,846.2900787401575,0.00025370340306410486,25.0,90.0
271.24023,0.024878643700787403,848.0534645669292,0.00025370340306410486,25.0,90.0
272.5415,0.025136824803149604,850.7971391076115,0.00025370340306410486,25.0,90.0
273.84277,0.02543216338582677,851.328687664042,0.00025370340306410486,25.0,90.0
275.14404,0.025708226377952753,851.4867716535433,0.00025370340306410486,25.0,90.0
276.44531,0.02599078346456693,851.8686089238845,0.00025370340306410486,25.0,90.0
277.74658,0.02630562992125984,854.0800262467191,0.00025370340306410486,25.0,90.0
279.04785,0.02661390157480315,852.4304461942257,0.00025370340306410486,25.0,90.0
280.34912,0.026883431102362205,852.4001312335957,0.00025370340306410486,25.0,90.0
281.65039,0.02714177559055118,853.8547244094487,0.00025370340306410486,25.0,90.0
282.95166,0.027452854330708657,856.3376640419947,0.00025370340306410486,25.0,90.0
284.25293,0.027823816929133858,857.520498687664,0.00025370340306410486,25.0,90.0
285.5542,0.028116328740157483,854.2040157480315,0.00025370340306410486,25.0,90.0
286.85547,0.028409545275590548,856.9428871391076,0.00025370340306410486,25.0,90.0
288.15674,0.028688856299212598,856.804094488189,0.00025370340306410486,25.0,90.0
289.45801,0.028953940944881892,859.0060367454068,0.00025370340306410486,25.0,90.0
290.75928,0.029303805118110232,860.1233070866142,0.00025370340306410486,25.0,90.0
292.06055,0.029600738188976378,859.8034383202099,0.00025370340306410486,25.0,90.0
293.36182,0.029881990157480314,861.234435695538,0.00025370340306410486,25.0,90.0
294.66309,0.03016556496062992,862.2960367454069,0.00025370340306410486,25.0,90.0
295.96436,0.030473045275590548,861.3328083989501,0.00025370340306410486,25.0,90.0
297.26563,0.03073842913385827,861.2566666666667,0.00025370340306410486,25.0,90.0
298.56689,0.031012220472440944,862.167375328084,0.00025370340306410486,25.0,90.0
299.86816,0.03131546850393701,864.5541732283464,0.00025370340306410486,25.0,90.0
301.16943,0.03157565748031496,864.1643832020998,0.00025370340306410486,25.0,90.0
302.4707,0.0318395905511811,863.0095538057743,0.00025370340306410486,25.0,90.0
303.77197,0.03208976771653543,865.8624671916011,0.00025370340306410486,25.0,90.0
305.07324,0.03237117716535433,865.722467191601,0.00025370340306410486,25.0,90.0
306.37451,0.03265544881889764,865.4709448818897,0.00025370340306410486,25.0,90.0
307.67578,0.032933423228346456,865.6951706036746,0.00025370340306410486,25.0,90.0
308.97705,0.03326379133858268,865.6496587926509,0.00025370340306410486,25.0,90.0
310.27832,0.03356428149606299,867.7903674540682,0.00025370340306410486,25.0,90.0
311.57959,0.0338872125984252,867.5881102362204,0.00025370340306410486,25.0,90.0
312.88086,0.03419927952755906,868.435564304462,0.00025370340306410486,25.0,90.0
314.18213,0.03447953543307087,869.1971391076115,0.00025370340306410486,25.0,90.0
315.4834,0.034764787401574807,869.3982939632546,0.00025370340306410486,25.0,90.0
316.78467,0.035032864173228345,869.7774540682415,0.00025370340306410486,25.0,90.0
318.08594,0.03533938188976378,871.8463517060367,0.00025370340306410486,25.0,90.0
319.38721,0.035673549212598424,871.4941207349082,0.00025370340306410486,25.0,90.0
320.68848,0.03598034645669291,873.2942257217849,0.00025370340306410486,25.0,90.0
321.98975,0.03624751181102362,871.0105774278214,0.00025370340306410486,25.0,90.0
323.29102,0.036557651574803146,874.1063517060368,0.00025370340306410486,25.0,90.0
324.59229,0.036840346456692916,875.332309711286,0.00025370340306410486,25.0,90.0
325.89355,0.03713956299212598,874.1355118110235,0.00025370340306410486,25.0,90.0
327.19482,0.0374437342519685,875.2635695538057,0.00025370340306410486,25.0,90.0
328.49609,0.0377318188976378,876.1251706036745,0.00025370340306410486,25.0,90.0
329.79736,0.03804707874015748,877.4439107611548,0.00025370340306410486,25.0,90.0
331.09863,0.038354885826771656,877.2222572178478,0.00025370340306410486,25.0,90.0
332.3999,0.0386374468503937,877.0891601049868,0.00025370340306410486,25.0,90.0
333.70117,0.03892722440944882,877.0710236220473,0.00025370340306410486,25.0,90.0
335.00244,0.03924700393700788,879.1585826771653,0.00025370340306410486,25.0,90.0
336.30371,0.0395227125984252,877.5951968503938,0.00025370340306410486,25.0,90.0
337.60498,0.039756757874015745,878.6089238845144,0.00025370340306410486,25.0,90.0
338.90625,0.040046635826771655,880.6279790026247,0.00025370340306410486,25.0,90.0
340.20752,0.04034490551181102,880.4002624671915,0.00025370340306410486,25.0,90.0
341.50879,0.04066623622047244,881.626719160105,0.00025370340306410486,25.0,90.0
342.81006,0.04094153346456693,880.5666666666666,0.00025370340306410486,25.0,90.0
344.11133,0.041226291338582674,882.395091863517,0.00025370340306410486,25.0,90.0
345.4126,0.04151026377952756,881.754435695538,0.00025370340306410486,25.0,90.0
346.71387,0.04180401181102362,883.215564304462,0.00025370340306410486,25.0,90.0
348.01514,0.042063253937007876,883.5930446194226,0.00025370340306410486,25.0,90.0
349.31641,0.04237928346456693,884.4192125984252,0.00025370340306410486,25.0,90.0
350.61768,0.04271702362204724,885.7402624671915,0.00025370340306410486,25.0,90.0
351.91895,0.04304160433070866,886.4712860892388,0.00025370340306410486,25.0,90.0
353.22021,0.04332851771653543,884.8545144356956,0.00025370340306410486,25.0,90.0
354.52148,0.043626218503937005,885.0710236220473,0.00025370340306410486,25.0,90.0
355.82275,0.04393791929133858,886.8506824146982,0.00025370340306410486,25.0,90.0
357.12402,0.044219897637795276,886.8221784776903,0.00025370340306410486,25.0,90.0
358.42529,0.04454515551181103,888.3541732283464,0.00025370340306410486,25.0,90.0
359.72656,0.044838732283464564,889.0903674540682,0.00025370340306410486,25.0,90.0
361.02783,0.04511880118110236,887.3048818897638,0.00025370340306410486,25.0,90.0
362.3291,0.045371537401574805,887.643280839895,0.00025370340306410486,25.0,90.0
363.63037,0.04567129330708661,891.7581102362204,0.00025370340306410486,25.0,90.0
364.93164,0.04601708267716535,889.7471128608923,0.00025370340306410486,25.0,90.0
366.23291,0.04634285236220472,890.9758267716536,0.00025370340306410486,25.0,90.0
367.53418,0.04662368503937008,890.1483202099737,0.00025370340306410486,25.0,90.0
368.83545,0.0468744094488189,890.6077690288714,0.00025370340306410486,25.0,90.0
370.13672,0.047149659448818895,889.8967979002625,0.00025370340306410486,25.0,90.0
371.43799,0.04742539566929133,892.3236745406824,0.00025370340306410486,25.0,90.0
372.73926,0.047749074803149605,893.8016535433071,0.00025370340306410486,25.0,90.0
374.04053,0.04806063385826771,892.8168241469816,0.00025370340306410486,25.0,90.0
375.3418,0.048386021653543304,894.705748031496,0.00025370340306410486,25.0,90.0
376.64307,0.04871680118110236,893.4304986876641,0.00025370340306410486,25.0,90.0
377.94434,0.04898750787401575,895.4132283464567,0.00025370340306410486,25.0,90.0
379.24561,0.04928918700787401,894.75656167979,0.00025370340306410486,25.0,90.0
380.54688,0.04956641338582678,895.3231496062992,0.00025370340306410486,25.0,90.0
381.84814,0.04985900984251969,896.902939632546,0.00025370340306410486,25.0,90.0
383.14941,0.050114992125984255,896.5621784776903,0.00025370340306410486,25.0,90.0
384.45068,0.05043343700787402,898.4658792650919,0.00025370340306410486,25.0,90.0
385.75195,0.05071681102362205,896.4802099737532,0.00025370340306410486,25.0,90.0
387.05322,0.05099904133858267,897.9401837270341,0.00025370340306410486,25.0,90.0
388.35449,0.0513195,897.7143044619422,0.00025370340306410486,25.0,90.0
389.65576,0.05165658267716535,900.3046981627297,0.00025370340306410486,25.0,90.0
390.95703,0.05202209448818897,901.4592125984252,0.00025370340306410486,25.0,90.0
392.2583,0.05232464173228346,899.4592913385826,0.00025370340306410486,25.0,90.0
393.55957,0.05259648818897638,900.329186351706,0.00025370340306410486,25.0,90.0
394.86084,0.052884836614173224,902.3118897637795,0.00025370340306410486,25.0,90.0
396.16211,0.05317805511811024,902.0364829396325,0.00025370340306410486,25.0,90.0
397.46338,0.05346450393700788,900.3279527559055,0.00025370340306410486,25.0,90.0
398.76465,0.05375711811023622,903.3412073490814,0.00025370340306410486,25.0,90.0
400.06592,0.05405296456692913,901.8983989501312,0.00025370340306410486,25.0,90.0
401.36719,0.05431946062992126,902.3245144356955,0.00025370340306410486,25.0,90.0
402.66846,0.05460007874015748,903.1824671916011,0.00025370340306410486,25.0,90.0
403.96973,0.05488301771653543,903.3194750656168,0.00025370340306410486,25.0,90.0
405.271,0.05522113976377952,905.6773228346457,0.00025370340306410486,25.0,90.0
406.57227,0.05551789566929134,904.0101312335958,0.00025370340306410486,25.0,90.0
407.87354,0.055814746062992124,905.7715748031496,0.00025370340306410486,25.0,90.0
409.1748,0.05610267913385827,906.6431758530184,0.00025370340306410486,25.0,90.0
410.47607,0.056407799212598426,905.7748031496063,0.00025370340306410486,25.0,90.0
411.77734,0.05672253149606299,907.9699999999999,0.00025370340306410486,25.0,90.0
413.07861,0.05704411417322834,905.9064829396326,0.00025370340306410486,25.0,90.0
414.37988,0.057342131889763774,907.0738057742782,0.00025370340306410486,25.0,90.0
415.68115,0.05760374212598426,908.230997375328,0.00025370340306410486,25.0,90.0
416.98242,0.0579173405511811,909.2204461942257,0.00025370340306410486,25.0,90.0
418.28369,0.05823877755905511,908.0446456692913,0.00025370340306410486,25.0,90.0
419.58496,0.05855803740157481,910.0877427821522,0.00025370340306410486,25.0,90.0
420.88623,0.05883053543307086,909.8598950131234,0.00025370340306410486,25.0,90.0
422.1875,0.059106974409448815,911.0086351706036,0.00025370340306410486,25.0,90.0
423.48877,0.059404242125984254,910.2300787401574,0.00025370340306410486,25.0,90.0
424.79004,0.059679092519685034,911.5989238845144,0.00025370340306410486,25.0,90.0
426.09131,0.059982171259842516,911.0014435695538,0.00025370340306410486,25.0,90.0
427.39258,0.060302423228346454,912.3352493438321,0.00025370340306410486,25.0,90.0
428.69385,0.06066290354330709,913.1900787401574,0.00025370340306410486,25.0,90.0
429.99512,0.06093339960629921,911.2492388451443,0.00025370340306410486,25.0,90.0
431.29639,0.06122322244094488,912.5371128608924,0.00025370340306410486,25.0,90.0
432.59766,0.06155033661417322,914.8652755905512,0.00025370340306410486,25.0,90.0
433.89893,0.0618460905511811,914.5844881889764,0.00025370340306410486,25.0,90.0
435.2002,0.06213775984251968,913.2810498687664,0.00025370340306410486,25.0,90.0
436.50146,0.062446624015748034,914.2128346456693,0.00025370340306410486,25.0,90.0
437.80273,0.06277192716535433,914.7197637795275,0.00025370340306410486,25.0,90.0
439.104,0.06308731692913386,916.7286351706036,0.00025370340306410486,25.0,90.0
440.40527,0.06341469488188976,916.0110236220472,0.00025370340306410486,25.0,90.0
441.70654,0.0637160157480315,918.4310761154856,0.00025370340306410486,25.0,90.0
443.00781,0.06400471653543308,915.6244356955381,0.00025370340306410486,25.0,90.0
444.30908,0.06428291732283464,916.652965879265,0.00025370340306410486,25.0,90.0
445.61035,0.06455316732283464,917.089842519685,0.00025370340306410486,25.0,90.0
446.91162,0.06478117322834646,917.7785039370078,0.00025370340306410486,25.0,90.0
448.21289,0.06510193503937008,920.371312335958,0.00025370340306410486,25.0,90.0
449.51416,0.06539590551181101,918.1158792650918,0.00025370340306410486,25.0,90.0
450.81543,0.06572960236220472,920.7767454068241,0.00025370340306410486,25.0,90.0
452.1167,0.06607417125984251,920.7911811023622,0.00025370340306410486,25.0,90.0
453.41797,0.06637919291338583,919.4093175853019,0.00025370340306410486,25.0,90.0
454.71924,0.06668987795275591,919.7908398950132,0.00025370340306410486,25.0,90.0
456.02051,0.06704234842519685,921.3639632545932,0.00025370340306410486,25.0,90.0
457.32178,0.06734070078740158,921.2476640419947,0.00025370340306410486,25.0,90.0
458.62305,0.06761470472440945,919.4784514435695,0.00025370340306410486,25.0,90.0
459.92432,0.06790524212598426,921.5070078740157,0.00025370340306410486,25.0,90.0
461.22559,0.06820373622047243,921.8754593175853,0.00025370340306410486,25.0,90.0
462.52686,0.06851925196850393,923.6105249343832,0.00025370340306410486,25.0,90.0
463.82813,0.06883520472440945,924.3813910761154,0.00025370340306410486,25.0,90.0
465.12939,0.06911138582677165,921.7885564304462,0.00025370340306410486,25.0,90.0
466.43066,0.06943108070866143,925.1756955380578,0.00025370340306410486,25.0,90.0
467.73193,0.06980139173228346,924.0739895013123,0.00025370340306410486,25.0,90.0
469.0332,0.07008251968503937,923.7097637795275,0.00025370340306410486,25.0,90.0
470.33447,0.07044440551181103,926.5856955380577,0.00025370340306410486,25.0,90.0
471.63574,0.07074703543307087,927.3328608923885,0.00025370340306410486,25.0,90.0
472.93701,0.07101471062992126,925.1200787401575,0.00025370340306410486,25.0,90.0
474.23828,0.07136533267716536,926.1150393700788,0.00025370340306410486,25.0,90.0
475.53955,0.07170271653543307,926.4379265091864,0.00025370340306410486,25.0,90.0
476.84082,0.07200835433070867,925.8825459317586,0.00025370340306410486,25.0,90.0
478.14209,0.07233813779527559,927.34624671916,0.00025370340306410486,25.0,90.0
479.44336,0.07267143700787403,927.1690026246719,0.00025370340306410486,25.0,90.0
480.74463,0.0729447342519685,927.3054330708661,0.00025370340306410486,25.0,90.0
482.0459,0.07324610039370079,927.8531758530185,0.00025370340306410486,25.0,90.0
483.34717,0.0735294153543307,927.649343832021,0.00025370340306410486,25.0,90.0
484.64844,0.07382173622047244,927.8217060367454,0.00025370340306410486,25.0,90.0
485.94971,0.07413825787401575,929.5115485564304,0.00025370340306410486,25.0,90.0
487.25098,0.07440968700787401,927.8418897637796,0.00025370340306410486,25.0,90.0
488.55225,0.07476766732283464,930.6945669291339,0.00025370340306410486,25.0,90.0
489.85352,0.07507849212598425,929.7047244094489,0.00025370340306410486,25.0,90.0
491.15479,0.07539398031496063,932.0714960629921,0.00025370340306410486,25.0,90.0
492.45605,0.07572427559055118,931.3061417322835,0.00025370340306410486,25.0,90.0
493.75732,0.07602072637795276,931.3118897637795,0.00025370340306410486,25.0,90.0
495.05859,0.0762829625984252,931.6063517060368,0.00025370340306410486,25.0,90.0
496.35986,0.0766241062992126,932.001653543307,0.00025370340306410486,25.0,90.0
497.66113,0.07692281496062991,932.4559580052494,0.00025370340306410486,25.0,90.0
498.9624,0.0772566653543307,932.7876377952756,0.00025370340306410486,25.0,90.0
500.26367,0.07757504133858267,932.6491601049869,0.00025370340306410486,25.0,90.0
501.56494,0.07792991732283465,933.2839895013122,0.00025370340306410486,25.0,90.0
502.86621,0.07824556299212598,933.7779790026246,0.00025370340306410486,25.0,90.0
504.16748,0.07851772047244095,933.6554593175853,0.00025370340306410486,25.0,90.0
505.46875,0.07882494881889764,935.407375328084,0.00025370340306410486,25.0,90.0
506.77002,0.07915113779527559,935.2400524934383,0.00025370340306410486,25.0,90.0
508.07129,0.07944792913385827,934.805748031496,0.00025370340306410486,25.0,90.0
509.37256,0.07974971850393701,936.8012073490813,0.00025370340306410486,25.0,90.0
510.67383,0.08006132874015748,937.1691076115486,0.00025370340306410486,25.0,90.0
511.9751,0.08033956299212598,934.9060892388452,0.00025370340306410486,25.0,90.0
513.27637,0.08070363385826772,936.9358530183728,0.00025370340306410486,25.0,90.0
514.57764,0.08101401181102362,937.9504199475066,0.00025370340306410486,25.0,90.0
515.87891,0.08135992322834645,935.943464566929,0.00025370340306410486,25.0,90.0
517.18018,0.0816422716535433,936.6960104986877,0.00025370340306410486,25.0,90.0
518.48145,0.08189874212598425,935.7932545931758,0.00025370340306410486,25.0,90.0
519.78271,0.08221092716535433,938.7194750656168,0.00025370340306410486,25.0,90.0
521.08398,0.0825519468503937,940.5356167979003,0.00025370340306410486,25.0,90.0
522.38525,0.0828944153543307,939.513937007874,0.00025370340306410486,25.0,90.0
523.68652,0.08322363582677166,939.3465091863517,0.00025370340306410486,25.0,90.0
524.98779,0.08356090748031496,939.666062992126,0.00025370340306410486,25.0,90.0
526.28906,0.08387264566929134,938.7373753280839,0.00025370340306410486,25.0,90.0
527.59033,0.0841608779527559,939.1771916010499,0.00025370340306410486,25.0,90.0
528.8916,0.08449388385826771,941.4501312335958,0.00025370340306410486,25.0,90.0
530.19287,0.08482201968503937,940.6318635170604,0.00025370340306410486,25.0,90.0
531.49414,0.08515499212598425,941.1317322834645,0.00025370340306410486,25.0,90.0
532.79541,0.08549814566929134,941.7509186351706,0.00025370340306410486,25.0,90.0
534.09668,0.08584808858267716,941.5366404199475,0.00025370340306410486,25.0,90.0
535.39795,0.08618178740157481,942.6131233595801,0.00025370340306410486,25.0,90.0
536.69922,0.08649612598425196,940.0985826771654,0.00025370340306410486,25.0,90.0
538.00049,0.0867683937007874,943.7602624671915,0.00025370340306410486,25.0,90.0
539.30176,0.08711525590551181,943.574094488189,0.00025370340306410486,25.0,90.0
540.60303,0.08744206102362205,944.1884251968504,0.00025370340306410486,25.0,90.0
541.9043,0.08778921653543308,943.4559317585303,0.00025370340306410486,25.0,90.0
543.20557,0.08812508661417322,944.4794225721785,0.00025370340306410486,25.0,90.0
544.50684,0.088441437007874,944.2792388451444,0.00025370340306410486,25.0,90.0
545.80811,0.08877529330708661,945.8231496062992,0.00025370340306410486,25.0,90.0
547.10938,0.08912071259842519,945.6132283464567,0.00025370340306410486,25.0,90.0
548.41064,0.08946237795275591,945.0599737532808,0.00025370340306410486,25.0,90.0
549.71191,0.08976498228346456,944.8855380577428,0.00025370340306410486,25.0,90.0
551.01318,0.09006911220472441,943.6398425196851,0.00025370340306410486,25.0,90.0
552.31445,0.09038556299212598,947.0067979002624,0.00025370340306410486,25.0,90.0
553.61572,0.09066433267716535,946.1711023622047,0.00025370340306410486,25.0,90.0
554.91699,0.09101351771653543,946.59624671916,0.00025370340306410486,25.0,90.0
556.21826,0.09134061023622046,945.719842519685,0.00025370340306410486,25.0,90.0
557.51953,0.09164640551181102,947.1870603674541,0.00025370340306410486,25.0,90.0
558.8208,0.09198550196850394,947.5303937007874,0.00025370340306410486,25.0,90.0
560.12207,0.09231858858267716,946.6748818897637,0.00025370340306410486,25.0,90.0
561.42334,0.09262005118110236,947.7203937007873,0.00025370340306410486,25.0,90.0
562.72461,0.0929860216535433,949.4581364829396,0.00025370340306410486,25.0,90.0
564.02588,0.09334849409448819,949.4018897637795,0.00025370340306410486,25.0,90.0
565.32715,0.09366658661417322,947.6466929133858,0.00025370340306410486,25.0,90.0
566.62842,0.09395897244094488,947.5672440944883,0.00025370340306410486,25.0,90.0
567.92969,0.0943055590551181,950.0121784776903,0.00025370340306410486,25.0,90.0
569.23096,0.09468753937007875,949.6434120734908,0.00025370340306410486,25.0,90.0
570.53223,0.09504671062992125,949.6881364829396,0.00025370340306410486,25.0,90.0
571.8335,0.0953813405511811,950.0569553805774,0.00025370340306410486,25.0,90.0
573.13477,0.09571664763779528,950.1686614173228,0.00025370340306410486,25.0,90.0
574.43604,0.09605526181102363,950.3981102362204,0.00025370340306410486,25.0,90.0
575.7373,0.09642980905511811,952.164251968504,0.00025370340306410486,25.0,90.0
577.03857,0.096788,951.9990813648294,0.00025370340306410486,25.0,90.0
578.33984,0.09708912007874015,951.6459842519686,0.00025370340306410486,25.0,90.0
579.64111,0.09737201968503936,952.0791601049868,0.00025370340306410486,25.0,90.0
580.94238,0.09775677952755905,952.3614435695538,0.00025370340306410486,25.0,90.0
582.24365,0.09806482283464567,952.2473228346456,0.00025370340306410486,25.0,90.0
583.54492,0.09844331299212598,954.2699737532809,0.00025370340306410486,25.0,90.0
584.84619,0.09880855511811024,950.931968503937,0.00025370340306410486,25.0,90.0
586.14746,0.09912291141732282,952.2220734908136,0.00025370340306410486,25.0,90.0
587.44873,0.09941698031496062,950.8145669291339,0.00025370340306410486,25.0,90.0
588.75,0.09974590944881889,954.3723622047244,0.00025370340306410486,25.0,90.0
590.05127,0.10006684645669292,953.6556430446194,0.00025370340306410486,25.0,90.0
591.35254,0.10039055511811024,953.7907874015748,0.00025370340306410486,25.0,90.0
592.65381,0.10065239173228346,953.0353543307086,0.00025370340306410486,25.0,90.0
593.95508,0.10095059251968505,953.7775853018372,0.00025370340306410486,25.0,90.0
595.25635,0.10126378543307087,955.0242257217848,0.00025370340306410486,25.0,90.0
596.55762,0.10163244291338583,956.4854855643044,0.00025370340306410486,25.0,90.0
597.85889,0.10199380118110236,954.7916272965879,0.00025370340306410486,25.0,90.0
599.16016,0.10240677559055117,955.3622572178477,0.00025370340306410486,25.0,90.0
600.46143,0.10277510433070866,953.6729921259843,0.00025370340306410486,25.0,90.0
601.7627,0.10308004921259842,954.4379002624671,0.00025370340306410486,25.0,90.0
603.06396,0.10344287598425196,956.678372703412,0.00025370340306410486,25.0,90.0
604.36523,0.10380927952755907,955.4033333333333,0.00025370340306410486,25.0,90.0
605.6665,0.104134781496063,957.8208398950131,0.00025370340306410486,25.0,90.0
606.96777,0.10448456102362205,956.8493175853017,0.00025370340306410486,25.0,90.0
608.26904,0.10489523425196849,957.7025984251968,0.00025370340306410486,25.0,90.0
609.57031,0.105273218503937,958.2106824146982,0.00025370340306410486,25.0,90.0
610.87158,0.10562358464566929,956.4446194225721,0.00025370340306410486,25.0,90.0
612.17285,0.10599408267716535,957.6171128608925,0.00025370340306410486,25.0,90.0
613.47412,0.10635205118110236,959.0248818897637,0.00025370340306410486,25.0,90.0
614.77539,0.10671779921259843,959.4219160104986,0.00025370340306410486,25.0,90.0
616.07666,0.10707279921259842,956.4783727034121,0.00025370340306410486,25.0,90.0
617.37793,0.1073979842519685,958.9338845144357,0.00025370340306410486,25.0,90.0
618.6792,0.10774526377952756,958.9417060367454,0.00025370340306410486,25.0,90.0
619.98047,0.10804939960629921,958.0979002624672,0.00025370340306410486,25.0,90.0
621.28174,0.10836504527559054,958.8789763779528,0.00025370340306410486,25.0,90.0
622.58301,0.10867565944881889,959.7168503937008,0.00025370340306410486,25.0,90.0
623.88428,0.10897302559055118,959.1185564304462,0.00025370340306410486,25.0,90.0
625.18555,0.10934936811023623,960.6251181102361,0.00025370340306410486,25.0,90.0
626.48682,0.10969156496062991,960.1563254593176,0.00025370340306410486,25.0,90.0
627.78809,0.1100709940944882,961.7570603674541,0.00025370340306410486,25.0,90.0
629.08936,0.11047373622047243,961.6470341207349,0.00025370340306410486,25.0,90.0
630.39063,0.11085501771653543,960.6981102362204,0.00025370340306410486,25.0,90.0
631.69189,0.11123483267716536,960.7657742782152,0.00025370340306410486,25.0,90.0
632.99316,0.11161860236220472,960.9739632545932,0.00025370340306410486,25.0,90.0
634.29443,0.11194461023622047,959.6178477690288,0.00025370340306410486,25.0,90.0
635.5957,0.11226586417322834,961.8637532808399,0.00025370340306410486,25.0,90.0
636.89697,0.11262528740157479,962.8407611548556,0.00025370340306410486,25.0,90.0
638.19824,0.11302115354330709,961.2843044619423,0.00025370340306410486,25.0,90.0
639.49951,0.11335996259842519,960.8703412073492,0.00025370340306410486,25.0,90.0
640.80078,0.11376609448818897,962.5191601049868,0.00025370340306410486,25.0,90.0
642.10205,0.11415862992125984,961.6542257217848,0.00025370340306410486,25.0,90.0
643.40332,0.11446563976377952,961.4126509186351,0.00025370340306410486,25.0,90.0
644.70459,0.11484668700787402,961.5638057742783,0.00025370340306410486,25.0,90.0
646.00586,0.11526429527559055,963.3162467191601,0.00025370340306410486,25.0,90.0
647.30713,0.1156681279527559,963.673280839895,0.00025370340306410486,25.0,90.0
648.6084,0.11604560826771654,962.1512860892389,0.00025370340306410486,25.0,90.0
649.90967,0.11645766732283465,962.4159842519686,0.00025370340306410486,25.0,90.0
651.21094,0.11681186811023621,963.3767191601049,0.00025370340306410486,25.0,90.0
652.51221,0.1171660590551181,963.7460892388451,0.00025370340306410486,25.0,90.0
653.81348,0.11750992322834647,965.169842519685,0.00025370340306410486,25.0,90.0
655.11475,0.11789493700787401,964.3760367454069,0.00025370340306410486,25.0,90.0
656.41602,0.11822683464566928,964.3413648293964,0.00025370340306410486,25.0,90.0
657.71729,0.11862605511811022,966.7134383202099,0.00025370340306410486,25.0,90.0
659.01855,0.11900032086614173,965.66343832021,0.00025370340306410486,25.0,90.0
660.31982,0.11936494291338581,964.8374803149607,0.00025370340306410486,25.0,90.0
661.62109,0.11970626181102363,963.9811811023623,0.00025370340306410486,25.0,90.0
662.92236,0.12007149212598427,967.0838845144357,0.00025370340306410486,25.0,90.0
664.22363,0.120535,967.1723884514436,0.00025370340306410486,25.0,90.0
665.5249,0.12082547834645668,963.1127821522309,0.00025370340306410486,25.0,90.0
666.82617,0.12118693110236221,965.9633333333333,0.00025370340306410486,25.0,90.0
668.12744,0.1215961968503937,967.3105249343832,0.00025370340306410486,25.0,90.0
669.42871,0.12200046456692912,967.2162204724409,0.00025370340306410486,25.0,90.0
670.72998,0.12239065157480314,966.6755118110236,0.00025370340306410486,25.0,90.0
672.03125,0.12271488779527559,966.8193700787401,0.00025370340306410486,25.0,90.0
673.33252,0.12310839566929134,964.6718372703411,0.00025370340306410486,25.0,90.0
674.63379,0.12344056299212598,964.7018897637795,0.00025370340306410486,25.0,90.0
675.93506,0.12376428149606299,964.6438845144357,0.00025370340306410486,25.0,90.0
677.23633,0.12416184842519684,966.202939632546,0.00025370340306410486,25.0,90.0
678.5376,0.12462739960629922,968.6078215223097,0.00025370340306410486,25.0,90.0
679.83887,0.1250175748031496,966.1111023622047,0.00025370340306410486,25.0,90.0
681.14014,0.12545288779527558,966.9417060367454,0.00025370340306410486,25.0,90.0
682.44141,0.12579880511811023,967.2296587926509,0.00025370340306410486,25.0,90.0
683.74268,0.12614189566929132,966.7722572178478,0.00025370340306410486,25.0,90.0
685.04395,0.12651514173228345,966.4555905511811,0.00025370340306410486,25.0,90.0
686.34521,0.12689858267716536,968.7048293963255,0.00025370340306410486,25.0,90.0
687.64648,0.12728903937007874,968.4358792650918,0.00025370340306410486,25.0,90.0
688.94775,0.12770300984251967,969.9697375328084,0.00025370340306410486,25.0,90.0
690.24902,0.12821131496062993,970.2256167979002,0.00025370340306410486,25.0,90.0
691.55029,0.1286337342519685,968.558031496063,0.00025370340306410486,25.0,90.0
692.85156,0.12904781102362203,968.1087664041995,0.00025370340306410486,25.0,90.0
694.15283,0.12940469881889763,966.3387664041994,0.00025370340306410486,25.0,90.0
695.4541,0.12979780905511812,969.6940157480315,0.00025370340306410486,25.0,90.0
696.75537,0.13012759251968506,968.0824934383202,0.00025370340306410486,25.0,90.0
698.05664,0.13049751771653542,968.3883989501312,0.00025370340306410486,25.0,90.0
699.35791,0.13090217125984252,968.7110498687664,0.00025370340306410486,25.0,90.0
700.65918,0.1313052775590551,969.2567979002624,0.00025370340306410486,25.0,90.0
701.96045,0.13168532874015748,968.7755643044619,0.00025370340306410486,25.0,90.0
703.26172,0.13208393897637796,968.8056955380578,0.00025370340306410486,25.0,90.0
704.56299,0.13247050196850393,968.713280839895,0.00025370340306410486,25.0,90.0
705.86426,0.13284538976377952,970.2504199475067,0.00025370340306410486,25.0,90.0
707.16553,0.13319885236220474,969.2812073490813,0.00025370340306410486,25.0,90.0
708.4668,0.13366959842519685,972.3193175853017,0.00025370340306410486,25.0,90.0
709.76807,0.13410646062992126,969.1917060367454,0.00025370340306410486,25.0,90.0
711.06934,0.13452147637795275,969.4354593175854,0.00025370340306410486,25.0,90.0
712.37061,0.1349708464566929,969.909186351706,0.00025370340306410486,25.0,90.0
713.67188,0.1354395748031496,971.882624671916,0.00025370340306410486,25.0,90.0
714.97314,0.13589645472440945,970.5525984251968,0.00025370340306410486,25.0,90.0
716.27441,0.13629362401574804,968.6609973753281,0.00025370340306410486,25.0,90.0
717.57568,0.13663006102362205,968.1750131233596,0.00025370340306410486,25.0,90.0
718.87695,0.13702833267716535,972.020656167979,0.00025370340306410486,25.0,90.0
720.17822,0.13743390157480315,970.6765879265091,0.00025370340306410486,25.0,90.0
721.47949,0.13789937007874015,970.9743832020997,0.00025370340306410486,25.0,90.0
722.78076,0.1383303779527559,970.7293963254592,0.00025370340306410486,25.0,90.0
724.08203,0.13874245866141732,971.8800524934383,0.00025370340306410486,25.0,90.0
725.3833,0.13913998031496064,970.5758005249344,0.00025370340306410486,25.0,90.0
726.68457,0.13958877559055116,973.1558792650918,0.00025370340306410486,25.0,90.0
727.98584,0.1399664901574803,970.0497637795276,0.00025370340306410486,25.0,90.0
729.28711,0.14034540157480313,971.7284514435696,0.00025370340306410486,25.0,90.0
730.58838,0.1407498681102362,970.0645669291338,0.00025370340306410486,25.0,90.0
731.88965,0.14114084251968503,970.2852755905512,0.00025370340306410486,25.0,90.0
733.19092,0.14152196062992126,971.5496587926509,0.00025370340306410486,25.0,90.0
734.49219,0.14184782677165353,970.7089501312336,0.00025370340306410486,25.0,90.0
735.79346,0.14222753543307087,971.4033070866142,0.00025370340306410486,25.0,90.0
737.09473,0.14267651771653544,973.8218372703411,0.00025370340306410486,25.0,90.0
738.396,0.14318148031496064,973.5390551181101,0.00025370340306410486,25.0,90.0
739.69727,0.14365075984251968,972.1815485564305,0.00025370340306410486,25.0,90.0
740.99854,0.14412288188976377,972.8987139107611,0.00025370340306410486,25.0,90.0
742.2998,0.14459534251968503,972.8971128608923,0.00025370340306410486,25.0,90.0
743.60107,0.14499646456692913,972.3827034120735,0.00025370340306410486,25.0,90.0
744.90234,0.1454677283464567,972.3271391076116,0.00025370340306410486,25.0,90.0
746.20361,0.14593143700787403,973.1262729658793,0.00025370340306410486,25.0,90.0
747.50488,0.14640087007874017,972.6903937007875,0.00025370340306410486,25.0,90.0
748.80615,0.1468829744094488,972.9512598425197,0.00025370340306410486,25.0,90.0
750.10742,0.14730286023622047,973.2036745406824,0.00025370340306410486,25.0,90.0
751.40869,0.14772032677165356,973.7995538057743,0.00025370340306410486,25.0,90.0
752.70996,0.14810143307086612,972.6810498687664,0.00025370340306410486,25.0,90.0
754.01123,0.1485083405511811,971.0432545931758,0.00025370340306410486,25.0,90.0
755.3125,0.14900366929133857,974.9548818897638,0.00025370340306410486,25.0,90.0
756.61377,0.14943779724409448,972.2252493438319,0.00025370340306410486,25.0,90.0
757.91504,0.14988370472440946,972.7720472440944,0.00025370340306410486,25.0,90.0
759.21631,0.15038141535433072,973.2236745406824,0.00025370340306410486,25.0,90.0
760.51758,0.1508873622047244,973.3109448818897,0.00025370340306410486,25.0,90.0
761.81885,0.15130254133858267,972.847217847769,0.00025370340306410486,25.0,90.0
763.12012,0.1517918877952756,972.5535958005249,0.00025370340306410486,25.0,90.0
764.42139,0.1522258976377953,971.9710498687664,0.00025370340306410486,25.0,90.0
765.72266,0.15265304527559054,971.39343832021,0.00025370340306410486,25.0,90.0
767.02393,0.15312205708661417,975.3167979002624,0.00025370340306410486,25.0,90.0
768.3252,0.1535976496062992,972.2915223097112,0.00025370340306410486,25.0,90.0
769.62646,0.1540493779527559,972.3158005249344,0.00025370340306410486,25.0,90.0
770.92773,0.1544809251968504,972.9632545931757,0.00025370340306410486,25.0,90.0
772.229,0.15498115748031496,974.0370341207349,0.00025370340306410486,25.0,90.0
773.53027,0.15553961023622045,971.9437007874016,0.00025370340306410486,25.0,90.0
774.83154,0.15592343897637795,971.4748818897638,0.00025370340306410486,25.0,90.0
776.13281,0.1562787440944882,972.9858792650919,0.00025370340306410486,25.0,90.0
777.43408,0.15665141338582678,972.0350131233595,0.00025370340306410486,25.0,90.0
778.63525,0.1571733996062992,977.0415485564304,0.00025370340306410486,25.0,90.0