File: datasets/am_bench_2022/csv/90-XY.07-4.csv
Time(s),Strain(%),Stress(MPa),SR(s-1),Temp(C),Angle(deg)
11.95459,2.979195472440945e-05,15.28055065264493,0.00025370340306410486,25.0,90.0
13.255859,4.879801377952756e-05,19.480814088675157,0.00025370340306410486,25.0,90.0
14.557129,0.00010857233267716536,22.680539290810124,0.00025370340306410486,25.0,90.0
15.858398,0.00013615658661417321,27.842503831316385,0.00025370340306410486,25.0,90.0
17.159668,0.00015858448031496063,32.55742218464302,0.00025370340306410486,25.0,90.0
18.460938,0.000184897437007874,36.44702478465359,0.00025370340306410486,25.0,90.0
19.762207,0.00024136848425196852,41.392931881836915,0.00025370340306410486,25.0,90.0
21.063477,0.00025539606299212597,46.27350578660889,0.00025370340306410486,25.0,90.0
22.364746,0.0003124574015748032,52.27718120805369,0.00025370340306410486,25.0,90.0
23.666016,0.0003401795866141732,58.234447497754054,0.00025370340306410486,25.0,90.0
24.967285,0.00038161234251968506,63.556312424034246,0.00025370340306410486,25.0,90.0
26.268555,0.00039215192913385826,69.47159012841516,0.00025370340306410486,25.0,90.0
27.569824,0.0004447268307086614,74.06644295302014,0.00025370340306410486,25.0,90.0
28.871094,0.0004804217913385827,80.87181472282407,0.00025370340306410486,25.0,90.0
30.172363,0.0005082625590551181,87.51346509538656,0.00025370340306410486,25.0,90.0
31.473633,0.0005474358464566929,96.25123659039264,0.00025370340306410486,25.0,90.0
32.774902,0.0006170364960629921,104.44008613856154,0.00025370340306410486,25.0,90.0
34.076172,0.0006441875787401575,111.81003276436083,0.00025370340306410486,25.0,90.0
35.377441,0.0006969867322834646,120.29413148020927,0.00025370340306410486,25.0,90.0
36.678711,0.0007160768700787401,127.23195582095862,0.00025370340306410486,25.0,90.0
37.97998,0.0007739491338582677,135.44439042435133,0.00025370340306410486,25.0,90.0
39.28125,0.0008457413582677165,143.4494530465571,0.00025370340306410486,25.0,90.0
40.58252,0.0008621286023622047,151.63730381017808,0.00025370340306410486,25.0,90.0
41.883789,0.000903453937007874,159.77791576388523,0.00025370340306410486,25.0,90.0
43.185059,0.0009232563582677165,167.93191090207682,0.00025370340306410486,25.0,90.0
44.486328,0.0010032321259842518,178.15122866353113,0.00025370340306410486,25.0,90.0
45.787598,0.0010389507480314962,188.610035406648,0.00025370340306410486,25.0,90.0
47.088867,0.001081962716535433,196.04061195370713,0.00025370340306410486,25.0,90.0
48.390137,0.0011224387598425195,203.92689848332716,0.00025370340306410486,25.0,90.0
49.691406,0.0011734778149606298,213.62606352058341,0.00025370340306410486,25.0,90.0
50.992676,0.0012168342716535434,224.3849970934841,0.00025370340306410486,25.0,90.0
52.293945,0.0012746499606299212,232.48632352164032,0.00025370340306410486,25.0,90.0
53.595215,0.0012949856102362205,244.3101067484014,0.00025370340306410486,25.0,90.0
54.896484,0.0013364869488188976,253.30251017280557,0.00025370340306410486,25.0,90.0
56.197754,0.0013643468700787402,260.85105955715267,0.00025370340306410486,25.0,90.0
57.499023,0.0013945220866141731,271.4142313586641,0.00025370340306410486,25.0,90.0
58.800293,0.001442730590551181,280.6211488664588,0.00025370340306410486,25.0,90.0
60.101563,0.001474424527559055,292.58130317602917,0.00025370340306410486,25.0,90.0
61.402832,0.0015175381692913387,300.1824763515299,0.00025370340306410486,25.0,90.0
62.704102,0.0015534082874015746,309.552581514559,0.00025370340306410486,25.0,90.0
64.005371,0.001601923405511811,319.0828092797125,0.00025370340306410486,25.0,90.0
65.306641,0.0016185700590551182,328.12661840088776,0.00025370340306410486,25.0,90.0
66.60791,0.0016559727559055117,336.6159699836178,0.00025370340306410486,25.0,90.0
67.90918,0.001686211594488189,347.11398826824495,0.00025370340306410486,25.0,90.0
69.210449,0.0017254840748031494,356.51936796491043,0.00025370340306410486,25.0,90.0
70.511719,0.0017513201968503936,366.95901812609,0.00025370340306410486,25.0,90.0
71.812988,0.0018016017125984253,375.60563864080746,0.00025370340306410486,25.0,90.0
73.114258,0.0018229367125984252,385.02430904190663,0.00025370340306410486,25.0,90.0
74.415527,0.0018780365354330707,395.24903556518524,0.00025370340306410486,25.0,90.0
75.716797,0.0019115302362204723,404.3353590868255,0.00025370340306410486,25.0,90.0
77.018066,0.001971790157480315,416.7475823072451,0.00025370340306410486,25.0,90.0
78.319336,0.001979653149606299,422.43415420387885,0.00025370340306410486,25.0,90.0
79.620605,0.0020203913385826774,433.1897690641019,0.00025370340306410486,25.0,90.0
80.921875,0.0020732801181102363,442.61744966442956,0.00025370340306410486,25.0,90.0
82.223145,0.0021046956692913387,453.65047825397664,0.00025370340306410486,25.0,90.0
83.524414,0.002121621653543307,460.27220842361146,0.00025370340306410486,25.0,90.0
84.825684,0.002175253346456693,472.06714051683133,0.00025370340306410486,25.0,90.0
86.126953,0.0021983937007874015,481.53860381546264,0.00025370340306410486,25.0,90.0
87.428223,0.0022398700787401573,490.6209374834857,0.00025370340306410486,25.0,90.0
88.729492,0.0022574998031496063,498.3770543782698,0.00025370340306410486,25.0,90.0
90.030762,0.002321778346456693,508.12587856048196,0.00025370340306410486,25.0,90.0
91.332031,0.002333298228346457,515.1980394229245,0.00025370340306410486,25.0,90.0
92.633301,0.002364556496062992,524.756777466575,0.00025370340306410486,25.0,90.0
93.93457,0.0024004872047244095,530.8527717592348,0.00025370340306410486,25.0,90.0
95.23584,0.002448978937007874,537.507002060984,0.00025370340306410486,25.0,90.0
96.537109,0.002479043307086614,549.5882523912699,0.00025370340306410486,25.0,90.0
97.838379,0.002502624212598425,555.3397452835175,0.00025370340306410486,25.0,90.0
99.139648,0.0025515498031496065,563.6764255139249,0.00025370340306410486,25.0,90.0
100.44092,0.002561440157480315,569.3385034085504,0.00025370340306410486,25.0,90.0
101.74219,0.0026149167322834645,579.1400676425515,0.00025370340306410486,25.0,90.0
103.04346,0.0026374190944881888,583.3258468530361,0.00025370340306410486,25.0,90.0
104.34473,0.00267584311023622,590.12762247001,0.00025370340306410486,25.0,90.0
105.646,0.0026899141732283464,594.5098293082492,0.00025370340306410486,25.0,90.0
106.94727,0.0027273505905511812,601.5282724726524,0.00025370340306410486,25.0,90.0
108.24854,0.0027725753937007875,610.3024097658933,0.00025370340306410486,25.0,90.0
109.5498,0.0027826561023622048,613.3132431432648,0.00025370340306410486,25.0,90.0
110.85107,0.002808636614173228,618.9591766633198,0.00025370340306410486,25.0,90.0
112.15234,0.002875198031496063,625.4081540981873,0.00025370340306410486,25.0,90.0
113.45361,0.002891356692913386,632.5872747450193,0.00025370340306410486,25.0,90.0
114.75488,0.002932138385826772,636.3578977963324,0.00025370340306410486,25.0,90.0
116.05615,0.0029733106299212595,642.9056175025102,0.00025370340306410486,25.0,90.0
117.35742,0.0030062500000000002,647.7641230248903,0.00025370340306410486,25.0,90.0
118.65869,0.003026387401574803,650.5284574327537,0.00025370340306410486,25.0,90.0
119.95996,0.0030812627952755906,657.1335147703852,0.00025370340306410486,25.0,90.0
121.26123,0.0031167783464566934,662.429768007187,0.00025370340306410486,25.0,90.0
122.5625,0.0031444312992125988,665.452227448079,0.00025370340306410486,25.0,90.0
123.86377,0.0031987931102362204,669.4003593510542,0.00025370340306410486,25.0,90.0
125.16504,0.003224574212598425,673.1825820430164,0.00025370340306410486,25.0,90.0
126.46631,0.003242429527559055,675.0190773133224,0.00025370340306410486,25.0,90.0
127.76758,0.003298944094488189,680.9788088569466,0.00025370340306410486,25.0,90.0
129.06885,0.003328516535433071,684.7625112297204,0.00025370340306410486,25.0,90.0
130.37012,0.0033834667322834642,688.5014004121967,0.00025370340306410486,25.0,90.0
131.67139,0.0034262364173228347,691.3643713998837,0.00025370340306410486,25.0,90.0
132.97266,0.003448299606299213,692.5755958357554,0.00025370340306410486,25.0,90.0
134.27393,0.0034891464566929133,697.5129736299741,0.00025370340306410486,25.0,90.0
135.5752,0.0035492966535433075,702.292580457644,0.00025370340306410486,25.0,90.0
136.87646,0.003583175196850394,704.534640384717,0.00025370340306410486,25.0,90.0
138.17773,0.003629051968503937,707.4717539502193,0.00025370340306410486,25.0,90.0
139.479,0.003674532874015748,710.6310574433229,0.00025370340306410486,25.0,90.0
140.78027,0.003764931692913386,715.160439676584,0.00025370340306410486,25.0,90.0
142.08154,0.0038011838582677165,718.1249537599746,0.00025370340306410486,25.0,90.0
143.38281,0.003858827559055118,720.9583047085556,0.00025370340306410486,25.0,90.0
144.68408,0.00389833031496063,721.0139776990962,0.00025370340306410486,25.0,90.0
145.98535,0.003996576771653543,727.7811657770966,0.00025370340306410486,25.0,90.0
147.28662,0.00405618405511811,729.7399196744702,0.00025370340306410486,25.0,90.0
148.58789,0.0041177218503937,729.866538075358,0.00025370340306410486,25.0,90.0
149.88916,0.004202670472440945,734.4339692437774,0.00025370340306410486,25.0,90.0
151.19043,0.004310759645669291,739.2815621201712,0.00025370340306410486,25.0,90.0
152.4917,0.004386267519685039,740.4389103207736,0.00025370340306410486,25.0,90.0
153.79297,0.004481615157480315,742.1285472705174,0.00025370340306410486,25.0,90.0
155.09424,0.0045801222440944875,746.3296253236801,0.00025370340306410486,25.0,90.0
156.39551,0.00469416751968504,748.8161232362734,0.00025370340306410486,25.0,90.0
157.69678,0.004811563385826771,752.2608994345505,0.00025370340306410486,25.0,90.0
158.99805,0.004901968307086614,752.268377107224,0.00025370340306410486,25.0,90.0
160.29932,0.005000519094488188,754.8580299106907,0.00025370340306410486,25.0,90.0
161.60059,0.005136433661417323,756.9712783385298,0.00025370340306410486,25.0,90.0
162.90186,0.0052840992125984245,761.2595782909686,0.00025370340306410486,25.0,90.0
164.20313,0.00540968248031496,764.2381493420705,0.00025370340306410486,25.0,90.0
165.50439,0.0055713,763.8660624636684,0.00025370340306410486,25.0,90.0
166.80566,0.005715170275590552,765.0767055963643,0.00025370340306410486,25.0,90.0
168.10693,0.005883011417322834,768.8496274375099,0.00025370340306410486,25.0,90.0
169.4082,0.006034353937007873,769.0439940812768,0.00025370340306410486,25.0,90.0
170.70947,0.006173998425196851,769.8689954024203,0.00025370340306410486,25.0,90.0
172.01074,0.006334075984251968,771.0975268192147,0.00025370340306410486,25.0,90.0
173.31201,0.006493546259842519,774.2817999260159,0.00025370340306410486,25.0,90.0
174.61328,0.006704632283464566,775.5928235480632,0.00025370340306410486,25.0,90.0
175.91455,0.006879271456692913,777.5253923796438,0.00025370340306410486,25.0,90.0
177.21582,0.007070829133858268,779.336997304867,0.00025370340306410486,25.0,90.0
178.51709,0.00728611122047244,778.367040109919,0.00025370340306410486,25.0,90.0
179.81836,0.007493062007874016,783.8437879828779,0.00025370340306410486,25.0,90.0
181.11963,0.007715368897637796,783.0125244411563,0.00025370340306410486,25.0,90.0
182.4209,0.007916141338582677,786.2182264968556,0.00025370340306410486,25.0,90.0
183.72217,0.008131895078740157,784.9512762247,0.00025370340306410486,25.0,90.0
185.02344,0.008336926968503936,789.4278655604292,0.00025370340306410486,25.0,90.0
186.32471,0.008565017322834646,790.093854040057,0.00025370340306410486,25.0,90.0
187.62598,0.008809624409448819,790.6648787190192,0.00025370340306410486,25.0,90.0
188.92725,0.009064561811023622,792.707763039687,0.00025370340306410486,25.0,90.0
190.22852,0.009342967913385826,795.8134809491096,0.00025370340306410486,25.0,90.0
191.52979,0.009595304330708663,795.0196321936268,0.00025370340306410486,25.0,90.0
192.83105,0.00981486909448819,797.1103683348306,0.00025370340306410486,25.0,90.0
194.13232,0.010038283858267716,797.4542620091951,0.00025370340306410486,25.0,90.0
195.43359,0.010293890748031496,799.9396765840511,0.00025370340306410486,25.0,90.0
196.73486,0.010542171062992127,798.4220261057972,0.00025370340306410486,25.0,90.0
198.03613,0.010825648228346457,802.5911060614068,0.00025370340306410486,25.0,90.0
199.3374,0.011067224409448819,801.0985044654652,0.00025370340306410486,25.0,90.0
200.63867,0.011349912992125984,804.3265866934418,0.00025370340306410486,25.0,90.0
201.93994,0.011592843897637794,804.0481160492523,0.00025370340306410486,25.0,90.0
203.24121,0.011839509448818897,805.0114146805474,0.00025370340306410486,25.0,90.0
204.54248,0.012086997047244094,805.8496010146382,0.00025370340306410486,25.0,90.0
205.84375,0.012326253740157481,807.6650636791205,0.00025370340306410486,25.0,90.0
207.14502,0.012613975196850393,808.8108122390742,0.00025370340306410486,25.0,90.0
208.44629,0.012868202755905512,808.353194525181,0.00025370340306410486,25.0,90.0
209.74756,0.013095067125984253,810.1718279342599,0.00025370340306410486,25.0,90.0
211.04883,0.013329587401574803,810.5462928711091,0.00025370340306410486,25.0,90.0
212.3501,0.013528903543307087,811.5269513290705,0.00025370340306410486,25.0,90.0
213.65137,0.013802257677165353,812.887464989695,0.00025370340306410486,25.0,90.0
214.95264,0.014133723622047244,814.2956719336256,0.00025370340306410486,25.0,90.0
216.25391,0.014381046062992125,813.6250594514611,0.00025370340306410486,25.0,90.0
217.55518,0.014669471653543308,816.7423241557892,0.00025370340306410486,25.0,90.0
218.85645,0.014969713779527558,817.3218041536754,0.00025370340306410486,25.0,90.0
220.15771,0.01522840748031496,817.648417269989,0.00025370340306410486,25.0,90.0
221.45898,0.01547741377952756,818.1784072292977,0.00025370340306410486,25.0,90.0
222.76025,0.015783848228346456,820.3370237277387,0.00025370340306410486,25.0,90.0
224.06152,0.016123474409448817,821.372958833166,0.00025370340306410486,25.0,90.0
225.36279,0.016413522047244094,821.7173809649632,0.00025370340306410486,25.0,90.0
226.66406,0.016724360826771652,822.6551551022565,0.00025370340306410486,25.0,90.0
227.96533,0.016957650590551182,821.7537652592084,0.00025370340306410486,25.0,90.0
229.2666,0.017191562007874018,822.4811604925223,0.00025370340306410486,25.0,90.0
230.56787,0.01744589527559055,824.619959837235,0.00025370340306410486,25.0,90.0
231.86914,0.01774820688976378,827.0262114886646,0.00025370340306410486,25.0,90.0
233.17041,0.018014474212598424,825.9742641230248,0.00025370340306410486,25.0,90.0
234.47168,0.018286856102362203,827.9112719970407,0.00025370340306410486,25.0,90.0
235.77295,0.01858101181102362,828.6918300480896,0.00025370340306410486,25.0,90.0
237.07422,0.018873694881889766,829.5616709824023,0.00025370340306410486,25.0,90.0
238.37549,0.019220931496062993,829.9707763039686,0.00025370340306410486,25.0,90.0
239.67676,0.019458223818897637,829.3370501506103,0.00025370340306410486,25.0,90.0
240.97803,0.01971401377952756,831.5283517412672,0.00025370340306410486,25.0,90.0
242.2793,0.019936413385826773,831.1083866194577,0.00025370340306410486,25.0,90.0
243.58057,0.020208188976377953,834.0930349310363,0.00025370340306410486,25.0,90.0
244.88184,0.020508509842519684,834.4579083654811,0.00025370340306410486,25.0,90.0
246.18311,0.02077854724409449,833.8608043122126,0.00025370340306410486,25.0,90.0
247.48438,0.021091751968503936,836.8468001902446,0.00025370340306410486,25.0,90.0
248.78564,0.021350858267716533,836.3093061353908,0.00025370340306410486,25.0,90.0
250.08691,0.021650917322834647,837.4089996300797,0.00025370340306410486,25.0,90.0
251.38818,0.021946720472440947,837.4527294826402,0.00025370340306410486,25.0,90.0
252.68945,0.02226666535433071,838.742852613222,0.00025370340306410486,25.0,90.0
253.99072,0.022520358267716537,836.6170797442265,0.00025370340306410486,25.0,90.0
255.29199,0.02275629724409449,840.3475136077789,0.00025370340306410486,25.0,90.0
256.59326,0.02303938188976378,841.3624953759974,0.00025370340306410486,25.0,90.0
257.89453,0.023287068897637795,840.961633990382,0.00025370340306410486,25.0,90.0
259.1958,0.02359218503937008,842.560164878719,0.00025370340306410486,25.0,90.0
260.49707,0.02390283464566929,842.8881784072292,0.00025370340306410486,25.0,90.0
261.79834,0.0242013562992126,843.9225281403583,0.00025370340306410486,25.0,90.0
263.09961,0.02449758464566929,845.31300533742,0.00025370340306410486,25.0,90.0
264.40088,0.02479375196850394,844.2946678645035,0.00025370340306410486,25.0,90.0
265.70215,0.02508853346456693,844.2821698462188,0.00025370340306410486,25.0,90.0
267.00342,0.025371840551181104,845.53033345664,0.00025370340306410486,25.0,90.0
268.30469,0.025684055118110238,847.5069756381123,0.00025370340306410486,25.0,90.0
269.60596,0.02597455118110236,847.4517518363895,0.00025370340306410486,25.0,90.0
270.90723,0.026198854330708662,847.6440574961687,0.00025370340306410486,25.0,90.0
272.2085,0.026449877952755906,848.3457168525074,0.00025370340306410486,25.0,90.0
273.50977,0.02676826771653543,850.895418274058,0.00025370340306410486,25.0,90.0
274.81104,0.02705601181102362,849.472863710828,0.00025370340306410486,25.0,90.0
276.1123,0.02734298228346457,850.3576071447444,0.00025370340306410486,25.0,90.0
277.41357,0.02755665551181102,850.606616287058,0.00025370340306410486,25.0,90.0
278.71484,0.027844165354330708,852.2728161496591,0.00025370340306410486,25.0,90.0
280.01611,0.028125364173228345,851.1187443851396,0.00025370340306410486,25.0,90.0
281.31738,0.028402372047244093,852.4716482587328,0.00025370340306410486,25.0,90.0
282.61865,0.028690883858267714,854.6463562860012,0.00025370340306410486,25.0,90.0
283.91992,0.028971834645669287,855.2552713628917,0.00025370340306410486,25.0,90.0
285.22119,0.029266470472440947,855.6952914442741,0.00025370340306410486,25.0,90.0
286.52246,0.029597037401574804,856.2652063626274,0.00025370340306410486,25.0,90.0
287.82373,0.029904425196850392,854.9368493367859,0.00025370340306410486,25.0,90.0
289.125,0.030164183070866143,855.7732124927337,0.00025370340306410486,25.0,90.0
290.42627,0.03046900590551181,858.376525920837,0.00025370340306410486,25.0,90.0
291.72754,0.03070936811023622,857.8031231834275,0.00025370340306410486,25.0,90.0
293.02881,0.031009950787401572,858.1219679754795,0.00025370340306410486,25.0,90.0
294.33008,0.03130114960629921,859.8889446705068,0.00025370340306410486,25.0,90.0
295.63135,0.0316039842519685,860.3709506949215,0.00025370340306410486,25.0,90.0
296.93262,0.03187703937007874,860.3228346456693,0.00025370340306410486,25.0,90.0
298.23389,0.03220251574803149,862.300533742007,0.00025370340306410486,25.0,90.0
299.53516,0.03254438188976378,861.5909475241768,0.00025370340306410486,25.0,90.0
300.83643,0.03279129921259843,861.9454896158114,0.00025370340306410486,25.0,90.0
302.1377,0.033049147637795276,863.6774295830471,0.00025370340306410486,25.0,90.0
303.43896,0.03332293307086614,862.1998361781957,0.00025370340306410486,25.0,90.0
304.74023,0.03357851377952756,864.6835068435238,0.00025370340306410486,25.0,90.0
306.0415,0.03393084842519685,866.5914759816096,0.00025370340306410486,25.0,90.0
307.34277,0.03423075590551181,864.4945568884425,0.00025370340306410486,25.0,90.0
308.64404,0.03449352559055118,865.5952016065105,0.00025370340306410486,25.0,90.0
309.94531,0.0347724468503937,867.5628600116261,0.00025370340306410486,25.0,90.0
311.24658,0.03507570275590551,868.4321989113777,0.00025370340306410486,25.0,90.0
312.54785,0.03534768307086614,868.2369867357185,0.00025370340306410486,25.0,90.0
313.84912,0.03562600984251968,867.7004703271151,0.00025370340306410486,25.0,90.0
315.15039,0.03594407283464567,870.1770332399725,0.00025370340306410486,25.0,90.0
316.45166,0.03625023031496063,870.7079479997886,0.00025370340306410486,25.0,90.0
317.75293,0.036459568897637795,868.5646303440258,0.00025370340306410486,25.0,90.0
319.0542,0.03676563779527559,871.3414099244305,0.00025370340306410486,25.0,90.0
320.35547,0.03705303149606299,871.3795381282036,0.00025370340306410486,25.0,90.0
321.65674,0.037392037401574804,874.833932251757,0.00025370340306410486,25.0,90.0
322.95801,0.03767633661417323,873.4923902129683,0.00025370340306410486,25.0,90.0
324.25928,0.03798280511811024,872.7858426253765,0.00025370340306410486,25.0,90.0
325.56055,0.03825133661417322,873.3504729694023,0.00025370340306410486,25.0,90.0
326.86182,0.03853643503937008,873.5982666596204,0.00025370340306410486,25.0,90.0
328.16309,0.038784419291338586,876.6797283728795,0.00025370340306410486,25.0,90.0
329.46436,0.039117521653543305,876.6744437985519,0.00025370340306410486,25.0,90.0
330.76563,0.03944211023622047,877.9465465306769,0.00025370340306410486,25.0,90.0
332.06689,0.03971225393700788,875.619378534059,0.00025370340306410486,25.0,90.0
333.36816,0.03998254724409449,877.2315964699043,0.00025370340306410486,25.0,90.0
334.66943,0.040313921259842525,878.4378534059081,0.00025370340306410486,25.0,90.0
335.9707,0.040585529527559054,879.2388627596047,0.00025370340306410486,25.0,90.0
337.27197,0.04089141535433071,879.5983723511071,0.00025370340306410486,25.0,90.0
338.57324,0.041187807086614174,879.7385985308883,0.00025370340306410486,25.0,90.0
339.87451,0.041511777559055114,880.9082862125455,0.00025370340306410486,25.0,90.0
341.17578,0.041803641732283466,880.6251651429477,0.00025370340306410486,25.0,90.0
342.47705,0.04211224212598425,880.7691962162447,0.00025370340306410486,25.0,90.0
343.77832,0.04239636811023622,881.5352481107647,0.00025370340306410486,25.0,90.0
345.07959,0.042741108267716536,882.5513396395919,0.00025370340306410486,25.0,90.0
346.38086,0.043002675196850394,881.7685092215821,0.00025370340306410486,25.0,90.0
347.68213,0.04325949409448819,884.2166411245574,0.00025370340306410486,25.0,90.0
348.9834,0.043502911417322834,881.8043122126512,0.00025370340306410486,25.0,90.0
350.28467,0.04374004527559055,883.5347724990751,0.00025370340306410486,25.0,90.0
351.58594,0.044031411417322835,884.5302013422818,0.00025370340306410486,25.0,90.0
352.88721,0.04433556496062992,886.1708502880093,0.00025370340306410486,25.0,90.0
354.18848,0.04461625,886.1614437457063,0.00025370340306410486,25.0,90.0
355.48975,0.044881738188976374,884.6702425619616,0.00025370340306410486,25.0,90.0
356.79102,0.04517829133858268,888.8560481953177,0.00025370340306410486,25.0,90.0
358.09229,0.04543196653543307,885.3218569994187,0.00025370340306410486,25.0,90.0
359.39355,0.04575186023622047,889.8849548168895,0.00025370340306410486,25.0,90.0
360.69482,0.04607290551181103,887.0887015800877,0.00025370340306410486,25.0,90.0
361.99609,0.046370460629921256,888.7382021878137,0.00025370340306410486,25.0,90.0
363.29736,0.046630818897637795,889.9103736194049,0.00025370340306410486,25.0,90.0
364.59863,0.046946687007874015,890.5361729112719,0.00025370340306410486,25.0,90.0
365.8999,0.0472495905511811,891.1594620303334,0.00025370340306410486,25.0,90.0
367.20117,0.04761136614173228,891.5816202504888,0.00025370340306410486,25.0,90.0
368.50244,0.047910494094488186,891.8042329440364,0.00025370340306410486,25.0,90.0
369.80371,0.04818556496062992,891.2977857633566,0.00025370340306410486,25.0,90.0
371.10498,0.04846633267716535,893.6415209004914,0.00025370340306410486,25.0,90.0
372.40625,0.04875928543307086,892.9235322094805,0.00025370340306410486,25.0,90.0
373.70752,0.04906531102362205,893.4074671035247,0.00025370340306410486,25.0,90.0
375.00879,0.04937766732283464,893.1811816308197,0.00025370340306410486,25.0,90.0
376.31006,0.04965130905511811,895.1696612587856,0.00025370340306410486,25.0,90.0
377.61133,0.0499440688976378,894.635866405961,0.00025370340306410486,25.0,90.0
378.9126,0.05023851377952756,895.8378428367595,0.00025370340306410486,25.0,90.0
380.21387,0.05052806496062992,895.9997621941552,0.00025370340306410486,25.0,90.0
381.51514,0.050791295275590544,897.130608254505,0.00025370340306410486,25.0,90.0
382.81641,0.05110287598425197,897.6756592506473,0.00025370340306410486,25.0,90.0
384.11768,0.051399338582677166,898.3439729429795,0.00025370340306410486,25.0,90.0
385.41895,0.0516747874015748,896.6166041325371,0.00025370340306410486,25.0,90.0
386.72021,0.05191308267716535,897.4849653860381,0.00025370340306410486,25.0,90.0
388.02148,0.05220879921259842,898.2802938223326,0.00025370340306410486,25.0,90.0
389.32275,0.052514824803149604,899.3753897373566,0.00025370340306410486,25.0,90.0
390.62402,0.05280627755905511,898.7587591819479,0.00025370340306410486,25.0,90.0
391.92529,0.05309634645669291,899.7878771864926,0.00025370340306410486,25.0,90.0
393.22656,0.05337257480314961,900.4886910109391,0.00025370340306410486,25.0,90.0
394.52783,0.053701250000000006,902.2864239285525,0.00025370340306410486,25.0,90.0
395.8291,0.05402093897637795,900.9605770755165,0.00025370340306410486,25.0,90.0
397.13037,0.054303151574803143,903.0130000528458,0.00025370340306410486,25.0,90.0
398.43164,0.054604647637795274,901.6881836918036,0.00025370340306410486,25.0,90.0
399.73291,0.05485017125984252,903.1314273635259,0.00025370340306410486,25.0,90.0
401.03418,0.05518435039370079,904.0646831897691,0.00025370340306410486,25.0,90.0
402.33545,0.05548611023622048,903.405194736564,0.00025370340306410486,25.0,90.0
403.63672,0.05583655708661417,907.1920150081911,0.00025370340306410486,25.0,90.0
404.93799,0.05620039173228346,904.868731173704,0.00025370340306410486,25.0,90.0
406.23926,0.05645344881889764,904.4654124610262,0.00025370340306410486,25.0,90.0
407.54053,0.056696935039370074,904.488109707763,0.00025370340306410486,25.0,90.0
408.8418,0.056962803149606306,906.0698884954816,0.00025370340306410486,25.0,90.0
410.14307,0.05727317125984253,907.7040109919146,0.00025370340306410486,25.0,90.0
411.44434,0.057583360236220474,906.491756064049,0.00025370340306410486,25.0,90.0
412.74561,0.05789387401574803,907.1213074036885,0.00025370340306410486,25.0,90.0
414.04688,0.05816127362204724,906.7559847804259,0.00025370340306410486,25.0,90.0
415.34814,0.05844630905511811,909.2025577339745,0.00025370340306410486,25.0,90.0
416.64941,0.058746994094488185,908.8024890345082,0.00025370340306410486,25.0,90.0
417.95068,0.05907173425196851,908.9681340168049,0.00025370340306410486,25.0,90.0
419.25195,0.05933926377952756,907.8794852824605,0.00025370340306410486,25.0,90.0
420.55322,0.059594161417322836,909.6931511916715,0.00025370340306410486,25.0,90.0
421.85449,0.05986533267716535,908.9526502140252,0.00025370340306410486,25.0,90.0
423.15576,0.06013352362204724,910.6670982402367,0.00025370340306410486,25.0,90.0
424.45703,0.06041617716535433,911.6726734661523,0.00025370340306410486,25.0,90.0
425.7583,0.06071793700787402,910.1479416582994,0.00025370340306410486,25.0,90.0
427.05957,0.060983301181102366,911.1132484278392,0.00025370340306410486,25.0,90.0
428.36084,0.061311309055118106,913.846113195582,0.00025370340306410486,25.0,90.0
429.66211,0.061587507874015755,912.9287903609363,0.00025370340306410486,25.0,90.0
430.96338,0.061933614173228346,912.5274797865031,0.00025370340306410486,25.0,90.0
432.26465,0.06222294291338583,914.6523542778629,0.00025370340306410486,25.0,90.0
433.56592,0.06253074015748032,913.1765047825397,0.00025370340306410486,25.0,90.0
434.86719,0.0628365531496063,915.0329493209322,0.00025370340306410486,25.0,90.0
436.16846,0.06316855708661417,917.1117423241558,0.00025370340306410486,25.0,90.0
437.46973,0.0634912716535433,916.0746974581197,0.00025370340306410486,25.0,90.0
438.771,0.06380084645669291,915.2017650478253,0.00025370340306410486,25.0,90.0
440.07227,0.0640762716535433,915.9527823283835,0.00025370340306410486,25.0,90.0
441.37354,0.06437539173228347,916.1661205939861,0.00025370340306410486,25.0,90.0
442.6748,0.06465620275590551,916.2331289964592,0.00025370340306410486,25.0,90.0
443.97607,0.06495069488188976,917.6280716588278,0.00025370340306410486,25.0,90.0
445.27734,0.0652641122047244,918.0855836812344,0.00025370340306410486,25.0,90.0
446.57861,0.06559976377952756,919.2685356444539,0.00025370340306410486,25.0,90.0
447.87988,0.06591935826771653,919.1197220313903,0.00025370340306410486,25.0,90.0
449.18115,0.06619358661417322,918.6145431485494,0.00025370340306410486,25.0,90.0
450.48242,0.06644489370078739,920.1660413253712,0.00025370340306410486,25.0,90.0
451.78369,0.06675190551181102,920.6850922158219,0.00025370340306410486,25.0,90.0
453.08496,0.06709206692913386,921.4422924483432,0.00025370340306410486,25.0,90.0
454.38623,0.06741461417322835,921.640463985626,0.00025370340306410486,25.0,90.0
455.6875,0.06773306889763779,922.0376525920838,0.00025370340306410486,25.0,90.0
456.98877,0.06798372637795276,920.2271574274691,0.00025370340306410486,25.0,90.0
458.29004,0.0682585059055118,921.3523754161603,0.00025370340306410486,25.0,90.0
459.59131,0.06853090354330708,922.8248427839137,0.00025370340306410486,25.0,90.0
460.89258,0.06881865551181102,923.0197907308566,0.00025370340306410486,25.0,90.0
462.19385,0.06909717716535434,922.7080272684035,0.00025370340306410486,25.0,90.0
463.49512,0.0694145846456693,925.1852507530517,0.00025370340306410486,25.0,90.0
464.79639,0.06977900590551181,925.2975479575119,0.00025370340306410486,25.0,90.0
466.09766,0.0701216437007874,924.1419965121809,0.00025370340306410486,25.0,90.0
467.39893,0.07040049409448819,924.4840141626592,0.00025370340306410486,25.0,90.0
468.7002,0.07065861417322834,924.06066691328,0.00025370340306410486,25.0,90.0
470.00146,0.07095240157480315,925.2617978121863,0.00025370340306410486,25.0,90.0
471.30273,0.07120728740157481,926.0082967816942,0.00025370340306410486,25.0,90.0
472.604,0.07149177559055118,926.5017967552714,0.00025370340306410486,25.0,90.0
473.90527,0.07187592125984252,928.9180626750514,0.00025370340306410486,25.0,90.0
475.20654,0.07222763582677165,927.226444009935,0.00025370340306410486,25.0,90.0
476.50781,0.07254231889763779,925.6262749035565,0.00025370340306410486,25.0,90.0
477.80908,0.07280645669291338,927.3596417058606,0.00025370340306410486,25.0,90.0
479.11035,0.07314003740157479,929.8363367330761,0.00025370340306410486,25.0,90.0
480.41162,0.07341891338582676,928.8346985150346,0.00025370340306410486,25.0,90.0
481.71289,0.0737271377952756,931.0136870475083,0.00025370340306410486,25.0,90.0
483.01416,0.07401959448818897,928.9426887914178,0.00025370340306410486,25.0,90.0
484.31543,0.07428284645669292,931.1399355281932,0.00025370340306410486,25.0,90.0
485.6167,0.07459082480314962,930.9971727527347,0.00025370340306410486,25.0,90.0
486.91797,0.07491053149606298,932.1841938381863,0.00025370340306410486,25.0,90.0
488.21924,0.0752726751968504,932.3508428896051,0.00025370340306410486,25.0,90.0
489.52051,0.07556523818897638,930.7982349521745,0.00025370340306410486,25.0,90.0
490.82178,0.07586211023622047,931.6154151033135,0.00025370340306410486,25.0,90.0
492.12305,0.07616635826771653,931.8535380225122,0.00025370340306410486,25.0,90.0
493.42432,0.076445812992126,931.9820324472863,0.00025370340306410486,25.0,90.0
494.72559,0.07673129527559056,932.6011995983723,0.00025370340306410486,25.0,90.0
496.02686,0.07698351181102363,932.3759181947893,0.00025370340306410486,25.0,90.0
497.32813,0.07729116141732284,933.737383078793,0.00025370340306410486,25.0,90.0
498.62939,0.07756291338582677,933.644691645088,0.00025370340306410486,25.0,90.0
499.93066,0.07784727952755906,935.6609681340168,0.00025370340306410486,25.0,90.0
501.23193,0.07815839173228346,934.0377318606985,0.00025370340306410486,25.0,90.0
502.5332,0.07850813976377953,935.0356180309675,0.00025370340306410486,25.0,90.0
503.83447,0.0788390748031496,934.9892987369867,0.00025370340306410486,25.0,90.0
505.13574,0.07913937992125984,934.7380436505838,0.00025370340306410486,25.0,90.0
506.43701,0.07941285826771653,934.6953442900174,0.00025370340306410486,25.0,90.0
507.73828,0.07972785826771654,938.8654018918776,0.00025370340306410486,25.0,90.0
509.03955,0.08009869291338582,936.835174126724,0.00025370340306410486,25.0,90.0
510.34082,0.08041917322834645,936.5298578449505,0.00025370340306410486,25.0,90.0
511.64209,0.08074262204724408,937.5350895735347,0.00025370340306410486,25.0,90.0
512.94336,0.0810583562992126,939.3207736616815,0.00025370340306410486,25.0,90.0
514.24463,0.08136564960629922,937.3592982085293,0.00025370340306410486,25.0,90.0
515.5459,0.08169672440944882,939.4739734714368,0.00025370340306410486,25.0,90.0
516.84717,0.0819859842519685,938.2926861491306,0.00025370340306410486,25.0,90.0
518.14844,0.08225463779527559,939.1502140252602,0.00025370340306410486,25.0,90.0
519.44971,0.08257721850393701,938.9484225545631,0.00025370340306410486,25.0,90.0
520.75098,0.08284640748031495,939.5587380436505,0.00025370340306410486,25.0,90.0
522.05225,0.08318537401574803,939.9204935792421,0.00025370340306410486,25.0,90.0
523.35352,0.08350225393700787,939.2034825344819,0.00025370340306410486,25.0,90.0
524.65479,0.08383345866141732,942.1222057813243,0.00025370340306410486,25.0,90.0
525.95605,0.08411964763779527,940.4059874227131,0.00025370340306410486,25.0,90.0
527.25732,0.08444630118110236,941.7545050996142,0.00025370340306410486,25.0,90.0
528.55859,0.08474726181102363,941.5247053849813,0.00025370340306410486,25.0,90.0
529.85986,0.08504371850393701,941.5436241610738,0.00025370340306410486,25.0,90.0
531.16113,0.08533174015748031,942.6374253553876,0.00025370340306410486,25.0,90.0
532.4624,0.0856446653543307,943.4130159065687,0.00025370340306410486,25.0,90.0
533.76367,0.08594597834645669,943.5101728055804,0.00025370340306410486,25.0,90.0
535.06494,0.08624885433070865,943.1135126565555,0.00025370340306410486,25.0,90.0
536.36621,0.08659563385826771,944.9964593352005,0.00025370340306410486,25.0,90.0
537.66748,0.08693032874015748,944.3770543782697,0.00025370340306410486,25.0,90.0
538.96875,0.0872338622047244,944.8160175447867,0.00025370340306410486,25.0,90.0
540.27002,0.08754525393700788,944.3729852560376,0.00025370340306410486,25.0,90.0
541.57129,0.08786168110236221,943.7858954711197,0.00025370340306410486,25.0,90.0
542.87256,0.08820577559055118,945.3327960682766,0.00025370340306410486,25.0,90.0
544.17383,0.08857806299212599,945.8394546319292,0.00025370340306410486,25.0,90.0
545.4751,0.08887700196850394,945.6459335200549,0.00025370340306410486,25.0,90.0
546.77637,0.08920385433070865,946.2342651799397,0.00025370340306410486,25.0,90.0
548.07764,0.08952129527559055,946.6964540506262,0.00025370340306410486,25.0,90.0
549.37891,0.08982672244094489,946.4791259314061,0.00025370340306410486,25.0,90.0
550.68018,0.09018611023622047,947.827379379591,0.00025370340306410486,25.0,90.0
551.98145,0.09049496850393701,946.3445542461554,0.00025370340306410486,25.0,90.0
553.28271,0.09079708661417323,946.0339005443111,0.00025370340306410486,25.0,90.0
554.58398,0.09111003543307086,947.8498123976113,0.00025370340306410486,25.0,90.0
555.88525,0.09142301181102362,947.9935528193204,0.00025370340306410486,25.0,90.0
557.18652,0.09178022440944882,949.9515140305448,0.00025370340306410486,25.0,90.0
558.48779,0.09210873622047244,948.7217935845267,0.00025370340306410486,25.0,90.0
559.78906,0.09249367322834647,948.7806901654071,0.00025370340306410486,25.0,90.0
561.09033,0.09280920669291338,949.1957934788352,0.00025370340306410486,25.0,90.0
562.3916,0.09307977559055118,947.0284838556254,0.00025370340306410486,25.0,90.0
563.69287,0.09333503149606298,949.3259789673941,0.00025370340306410486,25.0,90.0
564.99414,0.0936607440944882,951.2079744226602,0.00025370340306410486,25.0,90.0
566.29541,0.09395428543307087,951.0298578449506,0.00025370340306410486,25.0,90.0
567.59668,0.09426150787401574,949.586851979073,0.00025370340306410486,25.0,90.0
568.89795,0.0945556122047244,949.8205094329652,0.00025370340306410486,25.0,90.0
570.19922,0.09486687007874016,951.0004491888178,0.00025370340306410486,25.0,90.0
571.50049,0.09520275,952.9107963853511,0.00025370340306410486,25.0,90.0
572.80176,0.09552546062992126,951.1944723352534,0.00025370340306410486,25.0,90.0
574.10303,0.09584580511811024,950.7509908576864,0.00025370340306410486,25.0,90.0
575.4043,0.0961695374015748,953.8112085821487,0.00025370340306410486,25.0,90.0
576.70557,0.09651118307086615,953.1454843312371,0.00025370340306410486,25.0,90.0
578.00684,0.09686778543307087,953.4918881784072,0.00025370340306410486,25.0,90.0
579.30811,0.09715853346456693,953.5607197590233,0.00025370340306410486,25.0,90.0
580.60938,0.09748749212598425,953.1346509538656,0.00025370340306410486,25.0,90.0
581.91064,0.09779314173228347,954.14891930455,0.00025370340306410486,25.0,90.0
583.21191,0.0981473188976378,954.4992073138508,0.00025370340306410486,25.0,90.0
584.51318,0.09849214566929133,955.2428790360935,0.00025370340306410486,25.0,90.0
585.81445,0.09887389763779528,955.2388099138615,0.00025370340306410486,25.0,90.0
587.11572,0.09917284842519684,953.306954499815,0.00025370340306410486,25.0,90.0
588.41699,0.09948332086614174,954.3609628494424,0.00025370340306410486,25.0,90.0
589.71826,0.09983925787401575,955.1575331607039,0.00025370340306410486,25.0,90.0
591.01953,0.10015617125984252,955.037996089415,0.00025370340306410486,25.0,90.0
592.3208,0.10050834448818899,955.9240870897848,0.00025370340306410486,25.0,90.0
593.62207,0.10083823425196851,955.189319875284,0.00025370340306410486,25.0,90.0
594.92334,0.10118585433070865,956.6932304602864,0.00025370340306410486,25.0,90.0
596.22461,0.10148219881889764,955.2311208582148,0.00025370340306410486,25.0,90.0
597.52588,0.10181060039370078,957.0284045870105,0.00025370340306410486,25.0,90.0
598.82715,0.1021481279527559,958.0953337208687,0.00025370340306410486,25.0,90.0
600.12842,0.10251280905511811,957.7031126142789,0.00025370340306410486,25.0,90.0
601.42969,0.1028105374015748,958.1673888918247,0.00025370340306410486,25.0,90.0
602.73096,0.1031406279527559,958.2114358188447,0.00025370340306410486,25.0,90.0
604.03223,0.10348834251968504,959.1379802356919,0.00025370340306410486,25.0,90.0
605.3335,0.10379599803149606,959.2754584368229,0.00025370340306410486,25.0,90.0
606.63477,0.1040780059055118,958.4075463721397,0.00025370340306410486,25.0,90.0
607.93604,0.10441569881889763,958.0978967394176,0.00025370340306410486,25.0,90.0
609.2373,0.10471166732283464,958.387174338107,0.00025370340306410486,25.0,90.0
610.53857,0.1050666437007874,958.7322834645669,0.00025370340306410486,25.0,90.0
611.83984,0.10539499803149606,960.9390688580035,0.00025370340306410486,25.0,90.0
613.14111,0.10574765157480315,958.683850340855,0.00025370340306410486,25.0,90.0
614.44238,0.10605613976377953,960.3110236220472,0.00025370340306410486,25.0,90.0
615.74365,0.10639694291338582,960.9935263964487,0.00025370340306410486,25.0,90.0
617.04492,0.10673711220472441,961.1137768852718,0.00025370340306410486,25.0,90.0
618.34619,0.10710345669291338,962.0655815674046,0.00025370340306410486,25.0,90.0
619.64746,0.10745104133858267,960.9222374887702,0.00025370340306410486,25.0,90.0
620.94873,0.10783165551181102,962.0641811552078,0.00025370340306410486,25.0,90.0
622.25,0.1082325433070866,961.2717592347936,0.00025370340306410486,25.0,90.0
623.55127,0.10858268503937007,960.485123923268,0.00025370340306410486,25.0,90.0
624.85254,0.10886646456692914,959.9970406383766,0.00025370340306410486,25.0,90.0
626.15381,0.10918363582677164,961.8588490197114,0.00025370340306410486,25.0,90.0
627.45508,0.10952910826771654,963.3565502298788,0.00025370340306410486,25.0,90.0
628.75635,0.1098752716535433,962.1577709665487,0.00025370340306410486,25.0,90.0
630.05762,0.11023517716535432,962.5183110500449,0.00025370340306410486,25.0,90.0
631.35889,0.11057844291338582,961.0095915024044,0.00025370340306410486,25.0,90.0
632.66016,0.11096669488188976,963.2695925593192,0.00025370340306410486,25.0,90.0
633.96143,0.11130782480314962,962.180494636157,0.00025370340306410486,25.0,90.0
635.2627,0.11165219488188977,963.9978333245257,0.00025370340306410486,25.0,90.0
636.56396,0.11200868503937007,962.264149447762,0.00025370340306410486,25.0,90.0
637.86523,0.11236898818897638,964.8790360936426,0.00025370340306410486,25.0,90.0
639.1665,0.11270529724409449,964.6233683876764,0.00025370340306410486,25.0,90.0
640.46777,0.11309630511811024,964.4242456270147,0.00025370340306410486,25.0,90.0
641.76904,0.11341691535433071,962.1776409660201,0.00025370340306410486,25.0,90.0
643.07031,0.1137163937007874,965.5986894255667,0.00025370340306410486,25.0,90.0
644.37158,0.11410912598425198,963.8068223854568,0.00025370340306410486,25.0,90.0
645.67285,0.11445114960629921,965.9896686571897,0.00025370340306410486,25.0,90.0
646.97412,0.11479716141732282,964.810521587486,0.00025370340306410486,25.0,90.0
648.27539,0.11512593700787402,965.946837182265,0.00025370340306410486,25.0,90.0
649.57666,0.11547177362204723,966.5681181630819,0.00025370340306410486,25.0,90.0
650.87793,0.11581634251968505,964.0263964487659,0.00025370340306410486,25.0,90.0
652.1792,0.11619972440944881,965.5693864609206,0.00025370340306410486,25.0,90.0
653.48047,0.11658221456692912,967.6988321090736,0.00025370340306410486,25.0,90.0
654.78174,0.11695682086614174,966.1461713258997,0.00025370340306410486,25.0,90.0
656.08301,0.11732310826771652,965.7459705120751,0.00025370340306410486,25.0,90.0
657.38428,0.11767369488188976,966.5961264070179,0.00025370340306410486,25.0,90.0
658.68555,0.11799688582677165,966.334592823548,0.00025370340306410486,25.0,90.0
659.98682,0.11831774212598424,968.4952703059769,0.00025370340306410486,25.0,90.0
661.28809,0.1187176220472441,967.5202134968029,0.00025370340306410486,25.0,90.0
662.58936,0.11909422244094488,968.5148232309888,0.00025370340306410486,25.0,90.0
663.89063,0.11950487204724408,967.6627120435448,0.00025370340306410486,25.0,90.0
665.19189,0.11983963188976378,966.0023252127041,0.00025370340306410486,25.0,90.0
666.49316,0.12017386417322835,969.3274322253342,0.00025370340306410486,25.0,90.0
667.79443,0.12052144881889763,966.2396554457538,0.00025370340306410486,25.0,90.0
669.0957,0.12083942913385827,968.5619616339903,0.00025370340306410486,25.0,90.0
670.39697,0.12122202559055119,968.8186598319505,0.00025370340306410486,25.0,90.0
671.69824,0.12154157874015747,967.2608201659356,0.00025370340306410486,25.0,90.0
672.99951,0.12189359842519686,968.0945410347197,0.00025370340306410486,25.0,90.0
674.30078,0.1222523405511811,969.3464038471701,0.00025370340306410486,25.0,90.0
675.60205,0.12265964763779527,968.6564762458383,0.00025370340306410486,25.0,90.0
676.90332,0.12302795275590551,966.8656396977224,0.00025370340306410486,25.0,90.0
678.20459,0.12337905708661416,969.3488611742323,0.00025370340306410486,25.0,90.0
679.50586,0.1237492401574803,970.4295037784706,0.00025370340306410486,25.0,90.0
680.80713,0.1240843622047244,968.2007081329598,0.00025370340306410486,25.0,90.0
682.1084,0.12444729330708662,969.0053374200708,0.00025370340306410486,25.0,90.0
683.40967,0.12479857480314961,971.6971674681604,0.00025370340306410486,25.0,90.0
684.71094,0.12519691732283467,971.043307086614,0.00025370340306410486,25.0,90.0
686.01221,0.12560291929133857,969.941869682397,0.00025370340306410486,25.0,90.0
687.31348,0.1259990098425197,971.5638905036199,0.00025370340306410486,25.0,90.0
688.61475,0.1263713503937008,970.9436400147968,0.00025370340306410486,25.0,90.0
689.91602,0.1267448779527559,970.3891296306083,0.00025370340306410486,25.0,90.0
691.21729,0.12709496062992126,969.8874385668233,0.00025370340306410486,25.0,90.0
692.51855,0.12745644881889764,971.089045077419,0.00025370340306410486,25.0,90.0
693.81982,0.127831781496063,971.4304814247213,0.00025370340306410486,25.0,90.0
695.12109,0.12815390551181102,971.0930349310362,0.00025370340306410486,25.0,90.0
696.42236,0.12847637992125982,969.8583469851503,0.00025370340306410486,25.0,90.0
697.72363,0.1288665787401575,970.6539396501612,0.00025370340306410486,25.0,90.0
699.0249,0.12927111614173228,971.8520583417005,0.00025370340306410486,25.0,90.0
700.32617,0.12964179133858267,972.2133118427311,0.00025370340306410486,25.0,90.0
701.62744,0.1300256437007874,971.6945251809966,0.00025370340306410486,25.0,90.0
702.92871,0.13043117716535432,971.9730750938012,0.00025370340306410486,25.0,90.0
704.22998,0.13082259842519686,971.6306082545051,0.00025370340306410486,25.0,90.0
705.53125,0.1311982244094488,973.2937694868677,0.00025370340306410486,25.0,90.0
706.83252,0.13154665354330708,970.2257305924007,0.00025370340306410486,25.0,90.0
708.13379,0.13191536811023621,972.543465623844,0.00025370340306410486,25.0,90.0
709.43506,0.13230775,971.258970564921,0.00025370340306410486,25.0,90.0
710.73633,0.13260244094488188,972.3515563071394,0.00025370340306410486,25.0,90.0
712.0376,0.1329708405511811,972.2839401786186,0.00025370340306410486,25.0,90.0
713.33887,0.13332429133858267,972.4784917824869,0.00025370340306410486,25.0,90.0
714.64014,0.13368271653543307,973.4858109179305,0.00025370340306410486,25.0,90.0
715.94141,0.13409485826771655,972.6763462453099,0.00025370340306410486,25.0,90.0
717.24268,0.134527812992126,973.4843312371188,0.00025370340306410486,25.0,90.0
718.54395,0.13492706889763778,972.0483010093536,0.00025370340306410486,25.0,90.0
719.84521,0.1353464842519685,973.5049674998678,0.00025370340306410486,25.0,90.0
721.14648,0.1357195531496063,972.6330127358241,0.00025370340306410486,25.0,90.0
722.44775,0.13612333858267717,974.2769381176346,0.00025370340306410486,25.0,90.0
723.74902,0.1364912933070866,972.8503408550441,0.00025370340306410486,25.0,90.0
725.05029,0.13691751181102363,974.8156740474554,0.00025370340306410486,25.0,90.0
726.35156,0.1373558877952756,974.3168102309357,0.00025370340306410486,25.0,90.0
727.65283,0.13772162401574803,972.4308249220525,0.00025370340306410486,25.0,90.0
728.9541,0.13811416929133857,974.3842149764836,0.00025370340306410486,25.0,90.0
730.25537,0.13852939566929134,973.2814564286847,0.00025370340306410486,25.0,90.0
731.55664,0.1389485649606299,974.881202769117,0.00025370340306410486,25.0,90.0
732.85791,0.13933401181102362,973.5507054906727,0.00025370340306410486,25.0,90.0
734.15918,0.13968532677165355,972.5891243460338,0.00025370340306410486,25.0,90.0
735.46045,0.14001648425196853,973.512762247001,0.00025370340306410486,25.0,90.0
736.76172,0.14041488582677167,975.6737568038894,0.00025370340306410486,25.0,90.0
738.06299,0.1408655688976378,972.8511071183216,0.00025370340306410486,25.0,90.0
739.36426,0.1412475433070866,973.7687470274269,0.00025370340306410486,25.0,90.0
740.66553,0.14162107086614173,974.0599270728743,0.00025370340306410486,25.0,90.0
741.9668,0.14204328937007873,975.4551339639592,0.00025370340306410486,25.0,90.0
743.26807,0.14244973818897638,974.044337578608,0.00025370340306410486,25.0,90.0
744.56934,0.14280164173228346,974.7302489034508,0.00025370340306410486,25.0,90.0
745.87061,0.1431506220472441,973.1719072028748,0.00025370340306410486,25.0,90.0
747.17188,0.1435454783464567,975.4475241769275,0.00025370340306410486,25.0,90.0
748.47314,0.14394755118110236,975.2523912698832,0.00025370340306410486,25.0,90.0
749.77441,0.14434015748031495,974.7809543941235,0.00025370340306410486,25.0,90.0
751.07568,0.14480061417322834,976.8967129947682,0.00025370340306410486,25.0,90.0
752.37695,0.1452532342519685,976.6604925223272,0.00025370340306410486,25.0,90.0
753.67822,0.1456801220472441,975.4979654388839,0.00025370340306410486,25.0,90.0
754.97949,0.14604850984251969,974.9435871690534,0.00025370340306410486,25.0,90.0
756.28076,0.14643074212598425,974.5446546530676,0.00025370340306410486,25.0,90.0
757.58203,0.1467779153543307,974.628573693389,0.00025370340306410486,25.0,90.0
758.8833,0.147226781496063,975.709956138033,0.00025370340306410486,25.0,90.0
760.18457,0.14765593503937008,975.0815145590022,0.00025370340306410486,25.0,90.0
761.48584,0.14807044488188975,975.476879987317,0.00025370340306410486,25.0,90.0
762.78711,0.14851002952755907,975.7117528933044,0.00025370340306410486,25.0,90.0
764.08838,0.1489162913385827,973.5153516884214,0.00025370340306410486,25.0,90.0
765.38965,0.14932304527559054,975.1313745177825,0.00025370340306410486,25.0,90.0
766.69092,0.14971667125984253,975.3283041800983,0.00025370340306410486,25.0,90.0
767.99219,0.15011226771653544,976.0686730433863,0.00025370340306410486,25.0,90.0
769.29346,0.1505388405511811,975.3386883686518,0.00025370340306410486,25.0,90.0
770.59473,0.15100395669291336,975.7733710299635,0.00025370340306410486,25.0,90.0
771.896,0.15150962204724408,976.5470062886435,0.00025370340306410486,25.0,90.0
773.19727,0.15196407086614172,973.8795117053321,0.00025370340306410486,25.0,90.0
774.49854,0.15238148031496063,976.2427204988638,0.00025370340306410486,25.0,90.0
775.7998,0.15277115157480314,974.9804206521164,0.00025370340306410486,25.0,90.0
777.10107,0.15318697637795275,975.1425249696136,0.00025370340306410486,25.0,90.0
778.40234,0.15360722440944882,975.4118004544735,0.00025370340306410486,25.0,90.0
779.70361,0.15396269291338582,975.275669819796,0.00025370340306410486,25.0,90.0
781.00488,0.15435263385826772,975.1709824023674,0.00025370340306410486,25.0,90.0
782.30615,0.15478982480314962,977.4168472229562,0.00025370340306410486,25.0,90.0
783.60742,0.15524124803149605,977.3971886064577,0.00025370340306410486,25.0,90.0
784.90869,0.1556450688976378,974.7257305924007,0.00025370340306410486,25.0,90.0
786.20996,0.15605956692913386,973.8128732230618,0.00025370340306410486,25.0,90.0
787.51123,0.15649059842519686,976.8449241663583,0.00025370340306410486,25.0,90.0
788.8125,0.15694506102362205,976.022168789304,0.00025370340306410486,25.0,90.0
790.11377,0.1574061279527559,976.6779580404798,0.00025370340306410486,25.0,90.0
790.81445,0.1577276062992126,978.5635734291602,0.00025370340306410486,25.0,90.0