File: datasets/am_bench_2022/csv/90-XY.17-4.csv
Time(s),Strain(%),Stress(MPa),SR(s-1),Temp(C),Angle(deg)
11.75415,1.2982148031496063e-06,12.826224904833916,0.00025370340306410486,25.0,90.0
13.255615,3.6091564960629925e-05,17.036173019763257,0.00025370340306410486,25.0,90.0
14.656982,2.399976968503937e-05,22.481665797570006,0.00025370340306410486,25.0,90.0
15.958252,5.380213188976378e-05,26.936181363091205,0.00025370340306410486,25.0,90.0
17.259521,7.928342913385827e-05,31.95456536475987,0.00025370340306410486,25.0,90.0
18.560791,9.812835433070865e-05,36.568295353809255,0.00025370340306410486,25.0,90.0
19.862061,0.00010794678346456693,39.51945299056161,0.00025370340306410486,25.0,90.0
21.16333,0.00011845733267716536,46.58688011680659,0.00025370340306410486,25.0,90.0
22.4646,0.00014309990157480314,51.07042029514523,0.00025370340306410486,25.0,90.0
23.765869,0.00015127114566929135,55.86096104708766,0.00025370340306410486,25.0,90.0
25.067139,0.0001867225216535433,61.48626740366064,0.00025370340306410486,25.0,90.0
26.368408,0.00020738968503937008,67.59512958231215,0.00025370340306410486,25.0,90.0
27.669678,0.0002147268503937008,73.43609532252177,0.00025370340306410486,25.0,90.0
28.970947,0.00023004023622047245,79.70133232518121,0.00025370340306410486,25.0,90.0
30.272217,0.0002518786614173228,86.09696772175002,0.00025370340306410486,25.0,90.0
31.573486,0.0002916908267716535,90.68206705949837,0.00025370340306410486,25.0,90.0
32.874756,0.0003051545275590551,100.77296761745842,0.00025370340306410486,25.0,90.0
34.176025,0.00034859990157480315,108.19937425040413,0.00025370340306410486,25.0,90.0
35.477295,0.00035892007874015745,116.26695259946811,0.00025370340306410486,25.0,90.0
36.778564,0.0004063583661417323,124.3451817281118,0.00025370340306410486,25.0,90.0
38.079834,0.0004215063779527559,133.0818949783595,0.00025370340306410486,25.0,90.0
39.381104,0.00046074663385826774,141.42699066590185,0.00025370340306410486,25.0,90.0
40.682373,0.0004800285826771653,146.26448088856444,0.00025370340306410486,25.0,90.0
41.983643,0.0004830204527559055,154.7041820931324,0.00025370340306410486,25.0,90.0
43.284912,0.0005216427952755905,162.6082598946655,0.00025370340306410486,25.0,90.0
44.586182,0.000562056751968504,171.4205324086145,0.00025370340306410486,25.0,90.0
45.887451,0.0005931078346456693,181.19311153986547,0.00025370340306410486,25.0,90.0
47.188721,0.0006096086023622047,187.94405798612922,0.00025370340306410486,25.0,90.0
48.48999,0.0006464321062992125,198.63291182145278,0.00025370340306410486,25.0,90.0
49.79126,0.0006694095472440945,206.75211190488605,0.00025370340306410486,25.0,90.0
51.092529,0.0007230177559055119,216.1515017990301,0.00025370340306410486,25.0,90.0
52.393799,0.0007529965748031495,228.27255045106116,0.00025370340306410486,25.0,90.0
53.695068,0.0007896500787401574,237.5723027585128,0.00025370340306410486,25.0,90.0
54.996338,0.0008236995472440944,248.41903843145437,0.00025370340306410486,25.0,90.0
56.297607,0.0008523862992125984,256.40469051467903,0.00025370340306410486,25.0,90.0
57.598877,0.0008959130708661418,265.6946341972154,0.00025370340306410486,25.0,90.0
58.900146,0.0009160960826771653,274.25204672263646,0.00025370340306410486,25.0,90.0
60.201416,0.0009473586417322833,282.756974500704,0.00025370340306410486,25.0,90.0
61.502686,0.000981579901574803,293.70472440944883,0.00025370340306410486,25.0,90.0
62.803955,0.0010007450590551182,303.40798873650726,0.00025370340306410486,25.0,90.0
64.105225,0.0010631206692913386,314.4555717786932,0.00025370340306410486,25.0,90.0
65.406494,0.0010818542716535431,322.1383167335871,0.00025370340306410486,25.0,90.0
66.707764,0.001113736220472441,331.4925431506492,0.00025370340306410486,25.0,90.0
68.009033,0.0011408792322834646,340.54051728633254,0.00025370340306410486,25.0,90.0
69.310303,0.0012088320472440944,352.55149397716013,0.00025370340306410486,25.0,90.0
70.611572,0.0012084867322834645,362.58090420816603,0.00025370340306410486,25.0,90.0
71.912842,0.0012628838582677165,370.1290087083485,0.00025370340306410486,25.0,90.0
73.214111,0.0012855675196850394,379.16900453668455,0.00025370340306410486,25.0,90.0
74.515381,0.0013249699015748032,389.4848777180998,0.00025370340306410486,25.0,90.0
75.81665,0.001352407342519685,396.48500808259894,0.00025370340306410486,25.0,90.0
77.11792,0.0013625347440944882,404.8713041664494,0.00025370340306410486,25.0,90.0
78.419189,0.0014245322244094488,415.32484225895604,0.00025370340306410486,25.0,90.0
79.720459,0.0014723663582677166,426.1192052980133,0.00025370340306410486,25.0,90.0
81.021729,0.0014843070866141731,435.8258330291495,0.00025370340306410486,25.0,90.0
82.322998,0.0015258035629921258,444.5302967096,0.00025370340306410486,25.0,90.0
83.624268,0.0015703774212598425,454.16858737028736,0.00025370340306410486,25.0,90.0
84.925537,0.0015989873622047244,461.31496062992125,0.00025370340306410486,25.0,90.0
86.226807,0.0016103652559055117,468.4353652813266,0.00025370340306410486,25.0,90.0
87.528076,0.0016369944881889763,479.7749648015852,0.00025370340306410486,25.0,90.0
88.829346,0.001675932933070866,486.3470824425093,0.00025370340306410486,25.0,90.0
90.130615,0.0017309493503937009,499.44615946185536,0.00025370340306410486,25.0,90.0
91.431885,0.001756179940944882,506.52573395213017,0.00025370340306410486,25.0,90.0
92.733154,0.001790181653543307,513.6369348698962,0.00025370340306410486,25.0,90.0
94.034424,0.0018177794094488189,520.1073160556917,0.00025370340306410486,25.0,90.0
95.335693,0.0018366324606299213,526.950617927726,0.00025370340306410486,25.0,90.0
96.636963,0.0018708842322834648,534.9965583772228,0.00025370340306410486,25.0,90.0
97.938232,0.0019106892913385825,543.9014965844501,0.00025370340306410486,25.0,90.0
99.239502,0.001927428720472441,548.9225634875111,0.00025370340306410486,25.0,90.0
100.54077,0.001951075688976378,557.3744329144288,0.00025370340306410486,25.0,90.0
101.84204,0.0019950501968503936,566.9421703081816,0.00025370340306410486,25.0,90.0
103.14331,0.0020217127952755908,571.193330552224,0.00025370340306410486,25.0,90.0
104.44458,0.0020679694881889765,580.2587474578922,0.00025370340306410486,25.0,90.0
105.74585,0.002087275787401575,586.8062522813788,0.00025370340306410486,25.0,90.0
107.04712,0.002114103149606299,591.6356572978046,0.00025370340306410486,25.0,90.0
108.34839,0.0021489690944881887,599.2248787610158,0.00025370340306410486,25.0,90.0
109.64966,0.0021670338582677165,603.7913385826772,0.00025370340306410486,25.0,90.0
110.95093,0.0021798234251968504,607.844709808625,0.00025370340306410486,25.0,90.0
112.2522,0.0022212043307086615,614.4505397090264,0.00025370340306410486,25.0,90.0
113.55347,0.0022300257874015746,619.6961203525055,0.00025370340306410486,25.0,90.0
114.85474,0.0022673149606299214,625.2820566303384,0.00025370340306410486,25.0,90.0
116.15601,0.0022896872047244096,627.9826093758148,0.00025370340306410486,25.0,90.0
117.45728,0.002331601377952756,633.8542264170621,0.00025370340306410486,25.0,90.0
118.75854,0.002340916535433071,639.3031235333995,0.00025370340306410486,25.0,90.0
120.05981,0.002361602559055118,643.9147676904626,0.00025370340306410486,25.0,90.0
121.36108,0.002380931102362205,645.2802836731502,0.00025370340306410486,25.0,90.0
122.66235,0.0024124124015748034,651.8421025186422,0.00025370340306410486,25.0,90.0
123.96362,0.0024428970472440944,656.8118058090421,0.00025370340306410486,25.0,90.0
125.26489,0.002466968503937008,660.6411847525682,0.00025370340306410486,25.0,90.0
126.56616,0.002517625787401575,666.6765396047348,0.00025370340306410486,25.0,90.0
127.86743,0.002524796850393701,669.6911404286384,0.00025370340306410486,25.0,90.0
129.1687,0.0025567641732283466,672.4839912395057,0.00025370340306410486,25.0,90.0
130.46997,0.0025784889763779528,676.7435730301925,0.00025370340306410486,25.0,90.0
131.77124,0.002616693307086614,681.3297439641236,0.00025370340306410486,25.0,90.0
133.07251,0.002657450787401575,683.6956510403087,0.00025370340306410486,25.0,90.0
134.37378,0.0026871316929133857,688.0761850132972,0.00025370340306410486,25.0,90.0
135.67505,0.002725279527559055,691.1699692339782,0.00025370340306410486,25.0,90.0
136.97632,0.002751647244094488,696.1804244668092,0.00025370340306410486,25.0,90.0
138.27759,0.002770864960629921,698.8949522865934,0.00025370340306410486,25.0,90.0
139.57886,0.0028089726377952757,702.7979350263337,0.00025370340306410486,25.0,90.0
140.88013,0.002866601181102362,705.6883767012567,0.00025370340306410486,25.0,90.0
142.1814,0.0029018122047244094,707.0898472128071,0.00025370340306410486,25.0,90.0
143.48267,0.0029296421259842518,711.0228659331491,0.00025370340306410486,25.0,90.0
144.78394,0.0029724251968503935,714.918782917036,0.00025370340306410486,25.0,90.0
146.08521,0.0030063529527559053,718.8481253585023,0.00025370340306410486,25.0,90.0
147.38647,0.0030754978346456694,721.0144183136049,0.00025370340306410486,25.0,90.0
148.68774,0.0031039566929133857,722.3056526046827,0.00025370340306410486,25.0,90.0
149.98901,0.003161143897637795,726.7350471919486,0.00025370340306410486,25.0,90.0
151.29028,0.0032267566929133854,730.3767273296137,0.00025370340306410486,25.0,90.0
152.59155,0.0032793372047244095,732.3706262710539,0.00025370340306410486,25.0,90.0
153.89282,0.0033140592519685036,733.7006831099756,0.00025370340306410486,25.0,90.0
155.19409,0.0034130923228346453,738.6453824894405,0.00025370340306410486,25.0,90.0
156.49536,0.0034621960629921257,741.56515617667,0.00025370340306410486,25.0,90.0
157.79663,0.0035234687007874017,742.4276737758773,0.00025370340306410486,25.0,90.0
159.0979,0.003602093897637795,744.8366011367784,0.00025370340306410486,25.0,90.0
160.39917,0.0036919974409448815,748.070005736038,0.00025370340306410486,25.0,90.0
161.70044,0.00379255531496063,751.2016217343693,0.00025370340306410486,25.0,90.0
163.00171,0.0039000818897637793,751.6420973040622,0.00025370340306410486,25.0,90.0
164.30298,0.003987350984251969,754.5152787192992,0.00025370340306410486,25.0,90.0
165.60425,0.004092933464566929,757.9318715127497,0.00025370340306410486,25.0,90.0
166.90552,0.004200742125984252,759.7544975752203,0.00025370340306410486,25.0,90.0
168.20679,0.004335758267716535,762.5464619074934,0.00025370340306410486,25.0,90.0
169.50806,0.004449671456692913,763.8282056630338,0.00025370340306410486,25.0,90.0
170.80933,0.004562306102362205,765.6232465974865,0.00025370340306410486,25.0,90.0
172.1106,0.004734906299212599,769.678495072222,0.00025370340306410486,25.0,90.0
173.41187,0.00485689094488189,769.6820670594983,0.00025370340306410486,25.0,90.0
174.71313,0.004995004133858267,771.6234030348855,0.00025370340306410486,25.0,90.0
176.0144,0.005138373228346456,772.7668822026386,0.00025370340306410486,25.0,90.0
177.31567,0.005307910236220472,776.0832768420504,0.00025370340306410486,25.0,90.0
178.61694,0.00547199311023622,777.6419930124629,0.00025370340306410486,25.0,90.0
179.91821,0.005621131692913386,778.8025499296032,0.00025370340306410486,25.0,90.0
181.21948,0.005802803346456693,779.6811805809042,0.00025370340306410486,25.0,90.0
182.52075,0.005996925787401575,781.3230693017678,0.00025370340306410486,25.0,90.0
183.82202,0.006173864173228346,781.6052041508057,0.00025370340306410486,25.0,90.0
185.12329,0.006352691338582677,784.9419617249831,0.00025370340306410486,25.0,90.0
186.42456,0.006527348818897638,786.6240287844814,0.00025370340306410486,25.0,90.0
187.72583,0.006729047637795276,788.3732074881368,0.00025370340306410486,25.0,90.0
189.0271,0.00693158248031496,789.7653178286489,0.00025370340306410486,25.0,90.0
190.32837,0.007139591535433071,790.9535641654065,0.00025370340306410486,25.0,90.0
191.62964,0.007361497834645669,791.4075976430099,0.00025370340306410486,25.0,90.0
192.93091,0.007570821653543307,792.3592324138291,0.00025370340306410486,25.0,90.0
194.23218,0.007794189566929134,795.0476873337852,0.00025370340306410486,25.0,90.0
195.53345,0.007985185433070866,795.619387808312,0.00025370340306410486,25.0,90.0
196.83472,0.008214254921259842,797.8166553684101,0.00025370340306410486,25.0,90.0
198.13599,0.008497044685039371,799.2503519841478,0.00025370340306410486,25.0,90.0
199.43726,0.008705262007874016,798.8494550763936,0.00025370340306410486,25.0,90.0
200.73853,0.008959334842519685,800.6967721750013,0.00025370340306410486,25.0,90.0
202.03979,0.009203037007874015,801.7484225895605,0.00025370340306410486,25.0,90.0
203.34106,0.009425125196850395,802.2177347864629,0.00025370340306410486,25.0,90.0
204.64233,0.009626852559055118,805.2538718256244,0.00025370340306410486,25.0,90.0
205.9436,0.009886499606299212,804.9011576367524,0.00025370340306410486,25.0,90.0
207.24487,0.0101321281496063,806.6446524482453,0.00025370340306410486,25.0,90.0
208.54614,0.010361850196850392,806.0067789539553,0.00025370340306410486,25.0,90.0
209.84741,0.010603414763779528,807.2073577723314,0.00025370340306410486,25.0,90.0
211.14868,0.010881156496062992,808.6176930698232,0.00025370340306410486,25.0,90.0
212.44995,0.011137258464566929,810.0773582937894,0.00025370340306410486,25.0,90.0
213.75122,0.011390642716535433,808.7082181780258,0.00025370340306410486,25.0,90.0
215.05249,0.01160539094488189,811.201361005371,0.00025370340306410486,25.0,90.0
216.35376,0.011846617519685038,812.7808312040464,0.00025370340306410486,25.0,90.0
217.65503,0.012060804724409449,813.8201230640872,0.00025370340306410486,25.0,90.0
218.9563,0.01230162716535433,814.3868957605465,0.00025370340306410486,25.0,90.0
220.25757,0.012546798228346458,816.8395734473588,0.00025370340306410486,25.0,90.0
221.55884,0.012834645866141732,816.9207383845231,0.00025370340306410486,25.0,90.0
222.86011,0.013147359055118109,819.2896438441884,0.00025370340306410486,25.0,90.0
224.16138,0.013326215551181101,815.8139177139282,0.00025370340306410486,25.0,90.0
225.46265,0.013587587204724411,818.6066903060959,0.00025370340306410486,25.0,90.0
226.76392,0.013803067322834645,820.326823799343,0.00025370340306410486,25.0,90.0
228.06519,0.014092074999999999,821.1185534755175,0.00025370340306410486,25.0,90.0
229.36646,0.014332967913385827,823.382880533973,0.00025370340306410486,25.0,90.0
230.66772,0.014546201181102364,821.8027845857016,0.00025370340306410486,25.0,90.0
231.96899,0.014876322047244093,826.9734317150754,0.00025370340306410486,25.0,90.0
233.27026,0.0150930531496063,825.8905459665225,0.00025370340306410486,25.0,90.0
234.57153,0.01539868405511811,826.821817802576,0.00025370340306410486,25.0,90.0
235.8728,0.0156703031496063,826.6386817541846,0.00025370340306410486,25.0,90.0
237.17407,0.01594606692913386,828.4107003180894,0.00025370340306410486,25.0,90.0
238.47534,0.016219426968503935,827.9069197476144,0.00025370340306410486,25.0,90.0
239.77661,0.016451314566929134,829.2210721176409,0.00025370340306410486,25.0,90.0
241.07788,0.016715270472440945,830.0793398341764,0.00025370340306410486,25.0,90.0
242.37915,0.01696951712598425,830.9289252750692,0.00025370340306410486,25.0,90.0
243.68042,0.01727133464566929,833.5180685195808,0.00025370340306410486,25.0,90.0
244.98169,0.01757231751968504,833.2648745893518,0.00025370340306410486,25.0,90.0
246.28296,0.017826771062992127,833.9841476769046,0.00025370340306410486,25.0,90.0
247.58423,0.018124373228346456,834.2848725035199,0.00025370340306410486,25.0,90.0
248.8855,0.01835089448818898,834.1767742608333,0.00025370340306410486,25.0,90.0
250.18677,0.018594298228346455,833.611070553267,0.00025370340306410486,25.0,90.0
251.48804,0.018842723622047242,836.5540751942431,0.00025370340306410486,25.0,90.0
252.78931,0.01910208602362205,835.9328101371435,0.00025370340306410486,25.0,90.0
254.09058,0.019376529921259843,837.1949470720134,0.00025370340306410486,25.0,90.0
255.39185,0.019675038582677166,838.7634145069615,0.00025370340306410486,25.0,90.0
256.69312,0.019960543307086614,838.9478020545446,0.00025370340306410486,25.0,90.0
257.99438,0.020214015748031496,839.9766647546539,0.00025370340306410486,25.0,90.0
259.29565,0.020470610236220474,841.1938520102206,0.00025370340306410486,25.0,90.0
260.59692,0.02073684251968504,843.3531574281692,0.00025370340306410486,25.0,90.0
261.89819,0.02100904527559055,842.1484330187203,0.00025370340306410486,25.0,90.0
263.19946,0.02125465157480315,844.1338843406164,0.00025370340306410486,25.0,90.0
264.50073,0.021512358267716535,843.8072691244721,0.00025370340306410486,25.0,90.0
265.802,0.021741858267716536,842.5853626740366,0.00025370340306410486,25.0,90.0
267.10327,0.02203374803149606,845.092715231788,0.00025370340306410486,25.0,90.0
268.40454,0.022334629921259844,848.2232361683267,0.00025370340306410486,25.0,90.0
269.70581,0.022636582677165354,845.9204776555249,0.00025370340306410486,25.0,90.0
271.00708,0.022952974409448816,847.3500286801899,0.00025370340306410486,25.0,90.0
272.30835,0.0232053562992126,847.7215675027376,0.00025370340306410486,25.0,90.0
273.60962,0.02346999409448819,848.2586170933931,0.00025370340306410486,25.0,90.0
274.91089,0.023761167322834644,850.4024352088439,0.00025370340306410486,25.0,90.0
276.21216,0.024037677165354328,849.3622568702091,0.00025370340306410486,25.0,90.0
277.51343,0.02432662992125984,850.3594931428274,0.00025370340306410486,25.0,90.0
278.8147,0.02462375,852.0976430098556,0.00025370340306410486,25.0,90.0
280.11597,0.02491036417322835,853.3510455232831,0.00025370340306410486,25.0,90.0
281.41724,0.025184011811023622,852.7849767951192,0.00025370340306410486,25.0,90.0
282.71851,0.02540874803149606,852.9765604630547,0.00025370340306410486,25.0,90.0
284.01978,0.02567997244094488,854.4357824477239,0.00025370340306410486,25.0,90.0
285.32104,0.02589699409448819,853.9125514939772,0.00025370340306410486,25.0,90.0
286.62231,0.02616192125984252,856.477890180946,0.00025370340306410486,25.0,90.0
287.92358,0.02642439960629921,857.225452364812,0.00025370340306410486,25.0,90.0
289.22485,0.02667840157480315,856.4869374771862,0.00025370340306410486,25.0,90.0
290.52612,0.026949891732283467,856.8409813839496,0.00025370340306410486,25.0,90.0
291.82739,0.02721904133858268,857.9050164259269,0.00025370340306410486,25.0,90.0
293.12866,0.027466374015748033,858.1284611774521,0.00025370340306410486,25.0,90.0
294.42993,0.02777356692913386,860.218490900558,0.00025370340306410486,25.0,90.0
295.7312,0.028043433070866142,860.5814517390625,0.00025370340306410486,25.0,90.0
297.03247,0.028325541338582675,860.8753976117224,0.00025370340306410486,25.0,90.0
298.33374,0.028604659448818896,861.5654690514679,0.00025370340306410486,25.0,90.0
299.63501,0.028864244094488185,862.1502841946082,0.00025370340306410486,25.0,90.0
300.93628,0.029132521653543304,861.7566355530062,0.00025370340306410486,25.0,90.0
302.23755,0.029435885826771657,863.014835480002,0.00025370340306410486,25.0,90.0
303.53882,0.029700872047244097,862.8858006987538,0.00025370340306410486,25.0,90.0
304.84009,0.02996928346456693,863.5756896282004,0.00025370340306410486,25.0,90.0
306.14136,0.03023486614173228,866.2160139750744,0.00025370340306410486,25.0,90.0
307.44263,0.030561,865.500469312197,0.00025370340306410486,25.0,90.0
308.7439,0.030862781496062988,865.1188142045158,0.00025370340306410486,25.0,90.0
310.04517,0.031144435039370078,866.3397559576576,0.00025370340306410486,25.0,90.0
311.34644,0.031445224409448816,867.8432236533348,0.00025370340306410486,25.0,90.0
312.64771,0.03173445472440945,868.3096678312562,0.00025370340306410486,25.0,90.0
313.94897,0.03200966535433071,869.0795223444752,0.00025370340306410486,25.0,90.0
315.25024,0.03229054133858268,868.9402930593941,0.00025370340306410486,25.0,90.0
316.55151,0.03255459251968504,869.5708139959326,0.00025370340306410486,25.0,90.0
317.85278,0.03282063976377953,869.6829013922928,0.00025370340306410486,25.0,90.0
319.15405,0.03310133661417323,870.2887052197946,0.00025370340306410486,25.0,90.0
320.45532,0.03336894488188977,871.7437033946916,0.00025370340306410486,25.0,90.0
321.75659,0.0335974842519685,870.9809407102258,0.00025370340306410486,25.0,90.0
323.05786,0.03386814173228347,872.8943265369975,0.00025370340306410486,25.0,90.0
324.35913,0.034176433070866145,873.9552589038952,0.00025370340306410486,25.0,90.0
325.6604,0.03444958464566929,873.5706054127339,0.00025370340306410486,25.0,90.0
326.96167,0.03471946850393701,874.8440058403295,0.00025370340306410486,25.0,90.0
328.26294,0.03500723622047244,875.0688324555457,0.00025370340306410486,25.0,90.0
329.56421,0.03527749212598425,874.3800907336914,0.00025370340306410486,25.0,90.0
330.86548,0.03562752952755906,877.5862491526308,0.00025370340306410486,25.0,90.0
332.16675,0.03592236811023622,876.878343849403,0.00025370340306410486,25.0,90.0
333.46802,0.036210688976377955,878.4287688376702,0.00025370340306410486,25.0,90.0
334.76929,0.036475291338582676,878.1088543567816,0.00025370340306410486,25.0,90.0
336.07056,0.0367270531496063,878.6653804036084,0.00025370340306410486,25.0,90.0
337.37183,0.03698716338582677,878.8418417896439,0.00025370340306410486,25.0,90.0
338.6731,0.03725942322834645,878.9322104604474,0.00025370340306410486,25.0,90.0
339.97437,0.03753670866141732,879.6083068258852,0.00025370340306410486,25.0,90.0
341.27563,0.037854974409448815,881.4141158679669,0.00025370340306410486,25.0,90.0
342.5769,0.03817197244094488,881.9136726286698,0.00025370340306410486,25.0,90.0
343.87817,0.03846305905511811,880.7962924336445,0.00025370340306410486,25.0,90.0
345.17944,0.03875899606299213,884.0189810710748,0.00025370340306410486,25.0,90.0
346.48071,0.039044990157480315,883.7386452521249,0.00025370340306410486,25.0,90.0
347.78198,0.039320480314960625,884.3637430254993,0.00025370340306410486,25.0,90.0
349.08325,0.03960447637795276,884.3277624237368,0.00025370340306410486,25.0,90.0
350.38452,0.039905253937007876,885.0752724618031,0.00025370340306410486,25.0,90.0
351.68579,0.04016674015748032,883.6535954528863,0.00025370340306410486,25.0,90.0
352.98706,0.04044847440944882,884.2199509829484,0.00025370340306410486,25.0,90.0
354.28833,0.04072917913385827,885.8510976690827,0.00025370340306410486,25.0,90.0
355.5896,0.04098997637795276,886.6040569432133,0.00025370340306410486,25.0,90.0
356.89087,0.041248440944881885,888.5710486520311,0.00025370340306410486,25.0,90.0
358.19214,0.04152843307086614,886.9585440892736,0.00025370340306410486,25.0,90.0
359.49341,0.041816594488188974,887.8527141888721,0.00025370340306410486,25.0,90.0
360.79468,0.042064029527559055,888.9298117536633,0.00025370340306410486,25.0,90.0
362.09595,0.04237212007874016,889.8716431141472,0.00025370340306410486,25.0,90.0
363.39722,0.042653139763779525,891.7406007196121,0.00025370340306410486,25.0,90.0
364.69849,0.042909976377952755,890.8383480210668,0.00025370340306410486,25.0,90.0
365.99976,0.04322790551181102,889.9592219846692,0.00025370340306410486,25.0,90.0
367.30103,0.043533183070866135,890.7475100380665,0.00025370340306410486,25.0,90.0
368.60229,0.043808814960629924,892.7265474266048,0.00025370340306410486,25.0,90.0
369.90356,0.04409640748031496,893.3445012254264,0.00025370340306410486,25.0,90.0
371.20483,0.0444042874015748,894.2302497783804,0.00025370340306410486,25.0,90.0
372.5061,0.04469538385826771,893.4225374146113,0.00025370340306410486,25.0,90.0
373.80737,0.04496815157480315,894.0683892162486,0.00025370340306410486,25.0,90.0
375.10864,0.04525653346456693,895.1626688220264,0.00025370340306410486,25.0,90.0
376.40991,0.04557033267716535,897.1820931323982,0.00025370340306410486,25.0,90.0
377.71118,0.04592181102362205,897.1776607394274,0.00025370340306410486,25.0,90.0
379.01245,0.046216907480314956,896.5073004119519,0.00025370340306410486,25.0,90.0
380.31372,0.04653594881889764,897.2292850810868,0.00025370340306410486,25.0,90.0
381.61499,0.04678880511811023,896.1661886635031,0.00025370340306410486,25.0,90.0
382.91626,0.047057600393700785,896.6519267872973,0.00025370340306410486,25.0,90.0
384.21753,0.047345925196850394,897.9534077280075,0.00025370340306410486,25.0,90.0
385.5188,0.0476246062992126,897.1631381342232,0.00025370340306410486,25.0,90.0
386.82007,0.04789848818897638,900.9125254210774,0.00025370340306410486,25.0,90.0
388.12134,0.048190895669291335,898.7902174479846,0.00025370340306410486,25.0,90.0
389.42261,0.04845336023622047,900.5197632580696,0.00025370340306410486,25.0,90.0
390.72388,0.048708801181102365,900.7208635344423,0.00025370340306410486,25.0,90.0
392.02515,0.04900954133858267,901.854096052563,0.00025370340306410486,25.0,90.0
393.32642,0.04927539960629921,901.2377848464306,0.00025370340306410486,25.0,90.0
394.62769,0.04955847047244094,903.0657037075664,0.00025370340306410486,25.0,90.0
395.92896,0.04980369881889763,901.6795640611149,0.00025370340306410486,25.0,90.0
397.23022,0.0501454468503937,904.775016947385,0.00025370340306410486,25.0,90.0
398.53149,0.05045173031496063,903.2359597434427,0.00025370340306410486,25.0,90.0
399.83276,0.05071465354330709,902.8846534911613,0.00025370340306410486,25.0,90.0
401.13403,0.05097194488188976,902.815456015018,0.00025370340306410486,25.0,90.0
402.4353,0.0512573248031496,903.8735464358347,0.00025370340306410486,25.0,90.0
403.73657,0.05156761023622047,906.262736611566,0.00025370340306410486,25.0,90.0
405.03784,0.0518427874015748,906.1405329300725,0.00025370340306410486,25.0,90.0
406.33911,0.052167112204724406,907.2217500130365,0.00025370340306410486,25.0,90.0
407.64038,0.052429982283464564,906.2959795588465,0.00025370340306410486,25.0,90.0
408.94165,0.05273408858267717,908.0105595244304,0.00025370340306410486,25.0,90.0
410.24292,0.0530142657480315,907.797126766439,0.00025370340306410486,25.0,90.0
411.54419,0.05331004133858268,909.8470563696094,0.00025370340306410486,25.0,90.0
412.84546,0.05366886614173229,910.253637169526,0.00025370340306410486,25.0,90.0
414.14673,0.05397694488188976,909.1383949522866,0.00025370340306410486,25.0,90.0
415.448,0.05428119881889764,909.7240183553215,0.00025370340306410486,25.0,90.0
416.74927,0.05452460433070866,909.5740470355113,0.00025370340306410486,25.0,90.0
418.05054,0.054831515748031495,910.1147468321427,0.00025370340306410486,25.0,90.0
419.35181,0.055136379921259845,912.1569067111645,0.00025370340306410486,25.0,90.0
420.65308,0.055410513779527555,910.7442248526881,0.00025370340306410486,25.0,90.0
421.95435,0.05569125984251968,910.9282995254732,0.00025370340306410486,25.0,90.0
423.25562,0.05597374803149606,911.82424258226,0.00025370340306410486,25.0,90.0
424.55688,0.05620687401574803,912.5283151692131,0.00025370340306410486,25.0,90.0
425.85815,0.05650356102362205,913.5844761954424,0.00025370340306410486,25.0,90.0
427.15942,0.056812484251968505,913.8515669812797,0.00025370340306410486,25.0,90.0
428.46069,0.057055297244094486,913.8247640402566,0.00025370340306410486,25.0,90.0
429.76196,0.057337362204724414,915.391823538614,0.00025370340306410486,25.0,90.0
431.06323,0.057613192913385826,915.185769411274,0.00025370340306410486,25.0,90.0
432.3645,0.057863889763779534,913.7905824685821,0.00025370340306410486,25.0,90.0
433.66577,0.058180562992125984,917.9388329770037,0.00025370340306410486,25.0,90.0
434.96704,0.05850785433070866,918.2005266725765,0.00025370340306410486,25.0,90.0
436.26831,0.05881281889763779,917.4269958804819,0.00025370340306410486,25.0,90.0
437.56958,0.05911288976377953,918.4531730719091,0.00025370340306410486,25.0,90.0
438.87085,0.059448897637795275,917.2940762371591,0.00025370340306410486,25.0,90.0
440.17212,0.05969775393700787,917.2111383428065,0.00025370340306410486,25.0,90.0
441.47339,0.05998034251968504,917.5929238149868,0.00025370340306410486,25.0,90.0
442.77466,0.060255572834645665,918.1852479532774,0.00025370340306410486,25.0,90.0
444.07593,0.06053317519685039,919.6753923971424,0.00025370340306410486,25.0,90.0
445.3772,0.060864801181102365,920.9460030244564,0.00025370340306410486,25.0,90.0
446.67847,0.061159622047244094,922.0186942691766,0.00025370340306410486,25.0,90.0
447.97974,0.06150494094488188,920.8241643635605,0.00025370340306410486,25.0,90.0
449.28101,0.06182759251968504,920.803488553997,0.00025370340306410486,25.0,90.0
450.58228,0.062116645669291336,922.5558220785316,0.00025370340306410486,25.0,90.0
451.88354,0.062379692913385826,920.7540282630234,0.00025370340306410486,25.0,90.0
453.18481,0.06266472047244094,921.6917140324347,0.00025370340306410486,25.0,90.0
454.48608,0.06295276574803149,923.1954163842103,0.00025370340306410486,25.0,90.0
455.78735,0.06326079133858267,923.4866506752882,0.00025370340306410486,25.0,90.0
457.08862,0.06355449606299213,924.1683787870887,0.00025370340306410486,25.0,90.0
458.38989,0.06386317322834646,924.1697867236795,0.00025370340306410486,25.0,90.0
459.69116,0.06416652362204725,924.392266777911,0.00025370340306410486,25.0,90.0
460.99243,0.0644605157480315,925.5894821922095,0.00025370340306410486,25.0,90.0
462.2937,0.0647584468503937,927.6595922198467,0.00025370340306410486,25.0,90.0
463.59497,0.06504998622047244,924.9593002033687,0.00025370340306410486,25.0,90.0
464.89624,0.06532959448818898,927.2316316420713,0.00025370340306410486,25.0,90.0
466.19751,0.06559416732283464,926.0394482974397,0.00025370340306410486,25.0,90.0
467.49878,0.0659049311023622,928.5035719872765,0.00025370340306410486,25.0,90.0
468.80005,0.06625822440944881,927.4838869479063,0.00025370340306410486,25.0,90.0
470.10132,0.06654357086614174,926.5599415967044,0.00025370340306410486,25.0,90.0
471.40259,0.06682529527559056,928.9229285081087,0.00025370340306410486,25.0,90.0
472.70386,0.06709091732283463,929.0765239609949,0.00025370340306410486,25.0,90.0
474.00513,0.06740607677165354,930.5768629086928,0.00025370340306410486,25.0,90.0
475.3064,0.06770913976377953,929.679850863013,0.00025370340306410486,25.0,90.0
476.60767,0.06800698622047244,929.3009855556135,0.00025370340306410486,25.0,90.0
477.90894,0.06829088385826772,930.0189289252751,0.00025370340306410486,25.0,90.0
479.21021,0.06860708070866142,931.4183918235386,0.00025370340306410486,25.0,90.0
480.51147,0.0689464468503937,930.6832924857903,0.00025370340306410486,25.0,90.0
481.81274,0.06927204921259843,932.1781039787246,0.00025370340306410486,25.0,90.0
483.11401,0.0696017933070866,932.7082703238254,0.00025370340306410486,25.0,90.0
484.41528,0.06993815354330708,932.1821713510976,0.00025370340306410486,25.0,90.0
485.71655,0.07021012401574803,931.2055326693435,0.00025370340306410486,25.0,90.0
487.01782,0.07054251377952757,932.0714136726288,0.00025370340306410486,25.0,90.0
488.31909,0.07082887992125984,933.5740470355113,0.00025370340306410486,25.0,90.0
489.62036,0.0711314094488189,934.3254158627523,0.00025370340306410486,25.0,90.0
490.92163,0.07147516141732284,933.7746258538874,0.00025370340306410486,25.0,90.0
492.2229,0.07179172440944881,934.5725869531209,0.00025370340306410486,25.0,90.0
493.52417,0.0720840748031496,933.6705949835741,0.00025370340306410486,25.0,90.0
494.82544,0.07236894488188976,934.842728268238,0.00025370340306410486,25.0,90.0
496.12671,0.07270941732283465,937.1850393700787,0.00025370340306410486,25.0,90.0
497.42798,0.0730443720472441,938.1585753767534,0.00025370340306410486,25.0,90.0
498.72925,0.07336051181102361,935.4462376805549,0.00025370340306410486,25.0,90.0
500.03052,0.07361380708661418,937.0017208113887,0.00025370340306410486,25.0,90.0
501.33179,0.07388618110236221,935.9318715127497,0.00025370340306410486,25.0,90.0
502.63306,0.0741521496062992,938.0299838348021,0.00025370340306410486,25.0,90.0
503.93433,0.07441176968503938,936.6036137039162,0.00025370340306410486,25.0,90.0
505.2356,0.07469777952755904,937.237732700631,0.00025370340306410486,25.0,90.0
506.53687,0.07497511023622047,938.0574125254211,0.00025370340306410486,25.0,90.0
507.83813,0.07531230511811024,939.5411430359285,0.00025370340306410486,25.0,90.0
509.1394,0.07570013385826771,939.0566824842259,0.00025370340306410486,25.0,90.0
510.44067,0.07600756692913385,938.0105073786307,0.00025370340306410486,25.0,90.0
511.74194,0.07631764566929133,940.7889138029932,0.00025370340306410486,25.0,90.0
513.04321,0.07661164566929134,939.2373937529331,0.00025370340306410486,25.0,90.0
514.34448,0.07691527755905511,940.4332012306409,0.00025370340306410486,25.0,90.0
515.64575,0.0771897342519685,939.9846169891016,0.00025370340306410486,25.0,90.0
516.94702,0.07745652362204725,940.000156437399,0.00025370340306410486,25.0,90.0
518.24829,0.07776065354330708,942.6205089430047,0.00025370340306410486,25.0,90.0
519.54956,0.07814783070866141,943.220446368045,0.00025370340306410486,25.0,90.0
520.85083,0.0784793346456693,943.1569067111644,0.00025370340306410486,25.0,90.0
522.1521,0.07880825787401574,944.4119257443814,0.00025370340306410486,25.0,90.0
523.45337,0.07918893503937008,944.8235907597643,0.00025370340306410486,25.0,90.0
524.75464,0.07950766732283464,943.6184752568181,0.00025370340306410486,25.0,90.0
526.05591,0.07984843503937009,943.3033842623977,0.00025370340306410486,25.0,90.0
527.35718,0.0801413248031496,943.8882515513375,0.00025370340306410486,25.0,90.0
528.65845,0.08042990944881889,943.836809719977,0.00025370340306410486,25.0,90.0
529.95972,0.080668468503937,944.3746936434271,0.00025370340306410486,25.0,90.0
531.26099,0.08099821850393701,947.0393440058403,0.00025370340306410486,25.0,90.0
532.56226,0.08139153937007874,945.2917557490745,0.00025370340306410486,25.0,90.0
533.86353,0.08173318503937008,944.7235229702248,0.00025370340306410486,25.0,90.0
535.16479,0.08205202952755905,946.1968764666007,0.00025370340306410486,25.0,90.0
536.46606,0.08234807086614172,946.5728216092194,0.00025370340306410486,25.0,90.0
537.76733,0.08264809448818898,947.4864420920895,0.00025370340306410486,25.0,90.0
539.0686,0.0829843622047244,947.7307451634771,0.00025370340306410486,25.0,90.0
540.36987,0.08333422834645669,947.5110027637274,0.00025370340306410486,25.0,90.0
541.67114,0.08365873818897637,946.7919121864734,0.00025370340306410486,25.0,90.0
542.97241,0.08392001968503937,946.1920790530322,0.00025370340306410486,25.0,90.0
544.27368,0.08423814763779527,948.1607915732387,0.00025370340306410486,25.0,90.0
545.57495,0.08458220669291339,948.6466079157324,0.00025370340306410486,25.0,90.0
546.87622,0.08488624803149605,948.7814830265422,0.00025370340306410486,25.0,90.0
548.17749,0.08516139763779527,950.0456015017991,0.00025370340306410486,25.0,90.0
549.47876,0.08547424015748031,949.6983626218909,0.00025370340306410486,25.0,90.0
550.78003,0.08582956889763779,949.6720289930646,0.00025370340306410486,25.0,90.0
552.0813,0.08615374409448819,951.45001825103,0.00025370340306410486,25.0,90.0
553.38257,0.08651151968503937,949.5861448610315,0.00025370340306410486,25.0,90.0
554.68384,0.08683700984251969,951.0667466235594,0.00025370340306410486,25.0,90.0
555.98511,0.0871714409448819,951.3997236272619,0.00025370340306410486,25.0,90.0
557.28638,0.08749757677165354,951.936225687021,0.00025370340306410486,25.0,90.0
558.58765,0.0878426968503937,953.4507482922251,0.00025370340306410486,25.0,90.0
559.88892,0.08816832283464567,951.4399019658966,0.00025370340306410486,25.0,90.0
561.19019,0.08845289960629922,952.1593314908484,0.00025370340306410486,25.0,90.0
562.49146,0.08873761811023621,951.3633780049017,0.00025370340306410486,25.0,90.0
563.79272,0.08901587007874015,952.874093966731,0.00025370340306410486,25.0,90.0
565.09399,0.0893061968503937,952.395604109089,0.00025370340306410486,25.0,90.0
566.39526,0.08966652362204725,953.7123116232988,0.00025370340306410486,25.0,90.0
567.69653,0.08999644881889764,954.4416488501852,0.00025370340306410486,25.0,90.0
568.9978,0.09033133858267717,955.3060958439798,0.00025370340306410486,25.0,90.0
570.29907,0.09069017322834647,954.2144756739845,0.00025370340306410486,25.0,90.0
571.60034,0.0910030748031496,953.2953538092506,0.00025370340306410486,25.0,90.0
572.90161,0.09130313385826772,954.6705689106743,0.00025370340306410486,25.0,90.0
574.20288,0.09162194291338582,955.6756531261407,0.00025370340306410486,25.0,90.0
575.50415,0.09194367322834646,955.3527402617719,0.00025370340306410486,25.0,90.0
576.80542,0.09229451968503938,957.0516243416592,0.00025370340306410486,25.0,90.0
578.10669,0.0926396968503937,957.9767169004537,0.00025370340306410486,25.0,90.0
579.40796,0.0929623248031496,956.6960421338061,0.00025370340306410486,25.0,90.0
580.70923,0.09329698031496063,956.9966887417219,0.00025370340306410486,25.0,90.0
582.0105,0.09356634448818897,958.2890702403921,0.00025370340306410486,25.0,90.0
583.31177,0.09389705708661417,959.2483443708609,0.00025370340306410486,25.0,90.0
584.61304,0.09424565551181102,958.994994003233,0.00025370340306410486,25.0,90.0
585.91431,0.09458132480314961,957.7865672420087,0.00025370340306410486,25.0,90.0
587.21558,0.0949099311023622,957.7295979558846,0.00025370340306410486,25.0,90.0
588.51685,0.09523634251968505,958.6608176461385,0.00025370340306410486,25.0,90.0
589.81812,0.0956078622047244,958.5226834228503,0.00025370340306410486,25.0,90.0
591.11938,0.09593025,960.3478385566043,0.00025370340306410486,25.0,90.0
592.42065,0.09632592322834645,960.0813213745633,0.00025370340306410486,25.0,90.0
593.72192,0.09669408661417322,959.320149136987,0.00025370340306410486,25.0,90.0
595.02319,0.09698697637795275,958.2037075663555,0.00025370340306410486,25.0,90.0
596.32446,0.09729187598425197,958.2935287062627,0.00025370340306410486,25.0,90.0
597.62573,0.09756366338582677,959.4133336809721,0.00025370340306410486,25.0,90.0
598.927,0.09790792125984252,961.0463836887939,0.00025370340306410486,25.0,90.0
600.22827,0.09829099212598426,961.003493768577,0.00025370340306410486,25.0,90.0
601.52954,0.09863813188976378,961.2242269385201,0.00025370340306410486,25.0,90.0
602.83081,0.09896612007874016,961.4751003806643,0.00025370340306410486,25.0,90.0
604.13208,0.09931667322834646,961.2774417270689,0.00025370340306410486,25.0,90.0
605.43335,0.09960501771653545,960.840016686656,0.00025370340306410486,25.0,90.0
606.73462,0.09987495078740158,960.7415393440059,0.00025370340306410486,25.0,90.0
608.03589,0.1002302559055118,963.0046670490692,0.00025370340306410486,25.0,90.0
609.33716,0.10058896259842519,961.5672680815561,0.00025370340306410486,25.0,90.0
610.63843,0.10092029724409449,962.5218490900559,0.00025370340306410486,25.0,90.0
611.9397,0.1012686437007874,961.8300307660218,0.00025370340306410486,25.0,90.0
613.24097,0.10163395669291339,964.0309485320957,0.00025370340306410486,25.0,90.0
614.54224,0.10199313385826772,963.4611774521562,0.00025370340306410486,25.0,90.0
615.84351,0.10236276377952755,963.3288574855295,0.00025370340306410486,25.0,90.0
617.14478,0.10272623425196852,963.6520310788966,0.00025370340306410486,25.0,90.0
618.44604,0.1031148622047244,965.4946289826355,0.00025370340306410486,25.0,90.0
619.74731,0.10348346062992125,963.5369974448557,0.00025370340306410486,25.0,90.0
621.04858,0.10383149015748032,964.062731396986,0.00025370340306410486,25.0,90.0
622.34985,0.10417393503937007,965.7815873181415,0.00025370340306410486,25.0,90.0
623.65112,0.10446770078740157,963.4089795067007,0.00025370340306410486,25.0,90.0
624.95239,0.10480298818897638,965.4733795692757,0.00025370340306410486,25.0,90.0
626.25366,0.10517008464566929,965.2127027167961,0.00025370340306410486,25.0,90.0
627.55493,0.10560238188976377,968.2084789070241,0.00025370340306410486,25.0,90.0
628.8562,0.10596900984251967,965.5621056473901,0.00025370340306410486,25.0,90.0
630.15747,0.10631328543307086,964.1198831934089,0.00025370340306410486,25.0,90.0
631.45874,0.10666840157480315,967.9572925900819,0.00025370340306410486,25.0,90.0
632.76001,0.10701767519685039,966.8472910257078,0.00025370340306410486,25.0,90.0
634.06128,0.10734689763779527,966.0309746049957,0.00025370340306410486,25.0,90.0
635.36255,0.10771391141732282,968.8026802941024,0.00025370340306410486,25.0,90.0
636.66382,0.10811544488188976,967.902878448141,0.00025370340306410486,25.0,90.0
637.96509,0.10849615157480315,968.9296813891641,0.00025370340306410486,25.0,90.0
639.26636,0.10882788582677165,968.8989935860667,0.00025370340306410486,25.0,90.0
640.56763,0.10916440551181103,966.6237419825833,0.00025370340306410486,25.0,90.0
641.8689,0.10955198818897637,968.5483913020806,0.00025370340306410486,25.0,90.0
643.17017,0.10985623031496063,967.28938311519,0.00025370340306410486,25.0,90.0
644.47144,0.11021068897637797,968.8743807686291,0.00025370340306410486,25.0,90.0
645.77271,0.11054528543307088,969.4324972623456,0.00025370340306410486,25.0,90.0
647.07397,0.11088355314960631,969.1944777598166,0.00025370340306410486,25.0,90.0
648.37524,0.11124938188976378,970.2151796422798,0.00025370340306410486,25.0,90.0
649.67651,0.11162334251968503,970.3878083120405,0.00025370340306410486,25.0,90.0
650.97778,0.11194253346456692,967.897716013975,0.00025370340306410486,25.0,90.0
652.27905,0.11233749606299212,969.7765552484748,0.00025370340306410486,25.0,90.0
653.58032,0.11266998031496063,970.0819471241592,0.00025370340306410486,25.0,90.0
654.88159,0.11305862992125984,970.5597590864056,0.00025370340306410486,25.0,90.0
656.18286,0.11342458858267715,969.941674923085,0.00025370340306410486,25.0,90.0
657.48413,0.11375493700787401,969.6779996871253,0.00025370340306410486,25.0,90.0
658.7854,0.1140640590551181,968.8862700109506,0.00025370340306410486,25.0,90.0
660.08667,0.1143900905511811,970.8535745945665,0.00025370340306410486,25.0,90.0
661.38794,0.11471268307086614,971.3691922615633,0.00025370340306410486,25.0,90.0
662.68921,0.11515396850393701,973.1415758460656,0.00025370340306410486,25.0,90.0
663.99048,0.11562457480314961,972.2958752672472,0.00025370340306410486,25.0,90.0
665.29175,0.1160533405511811,972.2425822599989,0.00025370340306410486,25.0,90.0
666.59302,0.11641445275590552,972.0112634927257,0.00025370340306410486,25.0,90.0
667.89429,0.11677630511811024,971.8402774156542,0.00025370340306410486,25.0,90.0
669.19556,0.11716914370078739,972.20000521458,0.00025370340306410486,25.0,90.0
670.49683,0.11753185236220473,973.4788288053397,0.00025370340306410486,25.0,90.0
671.7981,0.11786478149606298,971.3111279136466,0.00025370340306410486,25.0,90.0
673.09937,0.11817443307086613,972.4169317411482,0.00025370340306410486,25.0,90.0
674.40063,0.11852317913385826,971.833785263597,0.00025370340306410486,25.0,90.0
675.7019,0.11892471259842519,974.0841111748449,0.00025370340306410486,25.0,90.0
677.00317,0.11936153937007873,973.79697032904,0.00025370340306410486,25.0,90.0
678.30444,0.11974894685039371,972.8305000782187,0.00025370340306410486,25.0,90.0
679.60571,0.12010765354330707,974.3990718047661,0.00025370340306410486,25.0,90.0
680.90698,0.12042560039370077,972.3521927308755,0.00025370340306410486,25.0,90.0
682.20825,0.12074159842519686,973.4696511446003,0.00025370340306410486,25.0,90.0
683.50952,0.12110664173228346,974.3461177452156,0.00025370340306410486,25.0,90.0
684.81079,0.12150558267716537,974.853939615164,0.00025370340306410486,25.0,90.0
686.11206,0.1219741122047244,975.4514783334203,0.00025370340306410486,25.0,90.0
687.41333,0.12236540157480316,974.7321009542682,0.00025370340306410486,25.0,90.0
688.7146,0.12272688976377953,974.4063982896178,0.00025370340306410486,25.0,90.0
690.01587,0.12310590748031497,976.4253272148928,0.00025370340306410486,25.0,90.0
691.31714,0.12345430118110236,974.9071022579132,0.00025370340306410486,25.0,90.0
692.61841,0.12385046062992125,975.8658549303854,0.00025370340306410486,25.0,90.0
693.91968,0.12420804330708661,974.9129686603744,0.00025370340306410486,25.0,90.0
695.22095,0.12461188779527559,976.2657349950462,0.00025370340306410486,25.0,90.0
696.52222,0.1249940964566929,974.8159514001147,0.00025370340306410486,25.0,90.0
697.82349,0.1253884724409449,976.6954163842103,0.00025370340306410486,25.0,90.0
699.12476,0.12580918897637797,976.2157011002764,0.00025370340306410486,25.0,90.0
700.42603,0.126222281496063,976.835141054388,0.00025370340306410486,25.0,90.0
701.72729,0.12664652952755906,976.1351879856078,0.00025370340306410486,25.0,90.0
703.02856,0.1270394625984252,976.4421963810815,0.00025370340306410486,25.0,90.0
704.32983,0.12743923622047243,976.5353809250665,0.00025370340306410486,25.0,90.0
705.6311,0.12783471456692913,977.361057516817,0.00025370340306410486,25.0,90.0
706.93237,0.12825099803149606,977.4571622255827,0.00025370340306410486,25.0,90.0
708.23364,0.12862600196850393,976.4857902695938,0.00025370340306410486,25.0,90.0
709.53491,0.1290061811023622,978.0382750169474,0.00025370340306410486,25.0,90.0
710.83618,0.129388718503937,978.378943526099,0.00025370340306410486,25.0,90.0
712.13745,0.12972026377952756,977.12577566877,0.00025370340306410486,25.0,90.0
713.43872,0.13009014173228345,976.0574125254211,0.00025370340306410486,25.0,90.0
714.73999,0.1305461279527559,975.6701256713771,0.00025370340306410486,25.0,90.0
716.04126,0.13093496653543307,975.6129738749544,0.00025370340306410486,25.0,90.0
717.34253,0.1312332125984252,977.5369974448557,0.00025370340306410486,25.0,90.0
718.6438,0.1316106220472441,978.6572456588622,0.00025370340306410486,25.0,90.0
719.94507,0.132101562992126,979.7440162694895,0.00025370340306410486,25.0,90.0
721.24634,0.1324846751968504,977.903321687438,0.00025370340306410486,25.0,90.0
722.54761,0.13289534842519685,979.1528654116911,0.00025370340306410486,25.0,90.0
723.84888,0.13337686811023622,979.752281378735,0.00025370340306410486,25.0,90.0
725.15015,0.13381644094488188,978.3860092819523,0.00025370340306410486,25.0,90.0
726.45142,0.13420864566929133,977.4418835062836,0.00025370340306410486,25.0,90.0
727.75269,0.13456970078740157,977.3046357615895,0.00025370340306410486,25.0,90.0
729.05396,0.13493701968503935,977.2214632111383,0.00025370340306410486,25.0,90.0
730.35522,0.1352745374015748,978.771053866611,0.00025370340306410486,25.0,90.0
731.65649,0.13571408464566928,980.4024091359441,0.00025370340306410486,25.0,90.0
732.95776,0.13618593700787401,980.4710851540908,0.00025370340306410486,25.0,90.0
734.25903,0.13663130511811025,977.8359753871825,0.00025370340306410486,25.0,90.0
735.5603,0.13702880118110236,978.6100797830735,0.00025370340306410486,25.0,90.0
736.86157,0.1374333149606299,980.3518537831777,0.00025370340306410486,25.0,90.0
738.16284,0.1378548188976378,978.6623298743286,0.00025370340306410486,25.0,90.0
739.46411,0.13828697637795276,981.069249621943,0.00025370340306410486,25.0,90.0
740.76538,0.13870927755905513,979.0914376596966,0.00025370340306410486,25.0,90.0
742.06665,0.13916267125984252,981.1775303749282,0.00025370340306410486,25.0,90.0
743.36792,0.13958185236220472,980.2424258226,0.00025370340306410486,25.0,90.0
744.66919,0.13997005708661417,979.2079313761277,0.00025370340306410486,25.0,90.0
745.97046,0.14034047440944883,979.269854513219,0.00025370340306410486,25.0,90.0
747.27173,0.1407634094488189,981.4397194555979,0.00025370340306410486,25.0,90.0
748.573,0.14123493110236218,980.5852062366376,0.00025370340306410486,25.0,90.0
749.87427,0.14169673818897638,979.9241539344006,0.00025370340306410486,25.0,90.0
751.17554,0.142090468503937,979.2741826145904,0.00025370340306410486,25.0,90.0
752.47681,0.14251030511811025,981.0060228398602,0.00025370340306410486,25.0,90.0
753.77808,0.14290594881889762,979.9025134275435,0.00025370340306410486,25.0,90.0
755.07935,0.14333835236220474,981.9544245711008,0.00025370340306410486,25.0,90.0
756.38062,0.1438193779527559,980.4472023778485,0.00025370340306410486,25.0,90.0
757.68188,0.1442997007874016,981.01061167023,0.00025370340306410486,25.0,90.0
758.98315,0.14471583070866142,978.9297596078636,0.00025370340306410486,25.0,90.0
760.28442,0.14513785039370078,980.3326902018042,0.00025370340306410486,25.0,90.0
761.58569,0.14552321456692913,979.6478333420243,0.00025370340306410486,25.0,90.0
762.88696,0.1459308622047244,980.7359336705429,0.00025370340306410486,25.0,90.0
764.18823,0.1463670433070866,980.8630651301038,0.00025370340306410486,25.0,90.0
765.4895,0.14682759448818897,981.7402878448141,0.00025370340306410486,25.0,90.0
766.79077,0.14733249803149606,981.4478020545446,0.00025370340306410486,25.0,90.0
768.09204,0.1477351220472441,980.9141680137665,0.00025370340306410486,25.0,90.0
769.39331,0.14817598622047243,982.3105021640507,0.00025370340306410486,25.0,90.0
770.69458,0.14862415748031496,981.0825468008552,0.00025370340306410486,25.0,90.0
771.99585,0.14906818897637794,981.6331021536215,0.00025370340306410486,25.0,90.0
773.29712,0.1495786653543307,980.6177973614225,0.00025370340306410486,25.0,90.0
774.59839,0.15008808661417322,982.3173854096053,0.00025370340306410486,25.0,90.0
775.89966,0.15055323622047243,981.0975126453565,0.00025370340306410486,25.0,90.0
777.20093,0.15094114763779526,980.3475256818064,0.00025370340306410486,25.0,90.0
778.5022,0.15136579527559055,981.8616050477134,0.00025370340306410486,25.0,90.0
779.80347,0.15183593307086615,981.1466339886323,0.00025370340306410486,25.0,90.0
781.10474,0.15232682677165355,981.6978933096939,0.00025370340306410486,25.0,90.0
782.40601,0.15274649999999998,981.5643479167753,0.00025370340306410486,25.0,90.0
783.70728,0.1532136692913386,982.9185221880377,0.00025370340306410486,25.0,90.0
785.00854,0.1536844625984252,980.9041820931325,0.00025370340306410486,25.0,90.0
786.30981,0.15417616732283465,982.3075819992699,0.00025370340306410486,25.0,90.0
787.61108,0.15463211811023622,980.5361891849612,0.00025370340306410486,25.0,90.0
788.91235,0.15508913779527558,981.8732596339364,0.00025370340306410486,25.0,90.0
790.21362,0.15554669881889763,982.6656932784065,0.00025370340306410486,25.0,90.0
791.51489,0.1560125649606299,981.0143661678052,0.00025370340306410486,25.0,90.0
792.81616,0.1563989625984252,981.3650988162905,0.00025370340306410486,25.0,90.0
794.11743,0.15683819488188977,981.8340459925953,0.00025370340306410486,25.0,90.0
795.4187,0.1573125905511811,981.9485581686396,0.00025370340306410486,25.0,90.0
796.71997,0.15780661811023622,982.3383740939668,0.00025370340306410486,25.0,90.0
798.02124,0.158262968503937,982.3279449340356,0.00025370340306410486,25.0,90.0
799.32251,0.15870825590551182,981.1762528028368,0.00025370340306410486,25.0,90.0
800.62378,0.1592165728346457,983.7222453981332,0.00025370340306410486,25.0,90.0
801.92505,0.15977640944881888,982.2085831986234,0.00025370340306410486,25.0,90.0
803.22632,0.16025420866141732,981.7050894300464,0.00025370340306410486,25.0,90.0
804.52759,0.16071702559055118,982.4541638421025,0.00025370340306410486,25.0,90.0
805.82886,0.16120737992125986,981.5538405381448,0.00025370340306410486,25.0,90.0
807.13013,0.16171292716535432,981.746519267873,0.00025370340306410486,25.0,90.0
808.4314,0.1621393818897638,980.5755331908015,0.00025370340306410486,25.0,90.0
809.73267,0.16264192716535433,982.8986807112688,0.00025370340306410486,25.0,90.0
811.03394,0.1632554566929134,983.6620691453304,0.00025370340306410486,25.0,90.0
812.33521,0.16379633267716537,984.6730979819577,0.00025370340306410486,25.0,90.0