File: datasets/am_bench_2022/csv/90-XY.16-1.csv
Time(s),Strain(%),Stress(MPa),SR(s-1),Temp(C),Angle(deg)
14.519043,6.007314566929134e-06,14.49505065616798,0.00025370340306410486,25.0,90.0
15.820313,3.2375734251968506e-05,20.763561417322833,0.00025370340306410486,25.0,90.0
17.121582,3.0463956692913383e-05,25.646794488188977,0.00025370340306410486,25.0,90.0
18.422852,4.760784448818897e-05,28.52039632545932,0.00025370340306410486,25.0,90.0
19.724121,7.101905905511811e-05,32.460963254593175,0.00025370340306410486,25.0,90.0
21.025391,7.780123031496063e-05,36.87964829396326,0.00025370340306410486,25.0,90.0
22.32666,9.944061614173228e-05,40.92724409448819,0.00025370340306410486,25.0,90.0
23.62793,0.00010319944488188975,44.75700787401575,0.00025370340306410486,25.0,90.0
24.929199,0.0001152265,51.73259842519685,0.00025370340306410486,25.0,90.0
26.230469,0.00013477725,57.44100262467192,0.00025370340306410486,25.0,90.0
27.531738,0.00015538473228346455,62.824346456692915,0.00025370340306410486,25.0,90.0
28.833008,0.00017240419291338584,69.37122047244094,0.00025370340306410486,25.0,90.0
30.134277,0.00021047236220472442,76.54397375328084,0.00025370340306410486,25.0,90.0
31.435547,0.00021856718503937005,83.08986614173227,0.00025370340306410486,25.0,90.0
32.736816,0.00024849940944881893,90.59389763779528,0.00025370340306410486,25.0,90.0
34.038086,0.0002613081299212598,97.78351181102363,0.00025370340306410486,25.0,90.0
35.339355,0.0002960512401574803,106.31838057742783,0.00025370340306410486,25.0,90.0
36.640625,0.0003195602559055118,114.2645091863517,0.00025370340306410486,25.0,90.0
37.941895,0.0003344178937007874,120.00769291338582,0.00025370340306410486,25.0,90.0
39.243164,0.0003905662992125984,128.18319160104986,0.00025370340306410486,25.0,90.0
40.544434,0.00041472627952755906,136.8814934383202,0.00025370340306410486,25.0,90.0
41.845703,0.00044758647637795274,144.65602887139107,0.00025370340306410486,25.0,90.0
43.146973,0.0004593467125984252,153.0230656167979,0.00025370340306410486,25.0,90.0
44.448242,0.0004922417913385827,163.9848215223097,0.00025370340306410486,25.0,90.0
45.749512,0.000517101968503937,172.2960787401575,0.00025370340306410486,25.0,90.0
47.050781,0.000572164625984252,183.1218897637795,0.00025370340306410486,25.0,90.0
48.352051,0.0006084184251968504,193.5188188976378,0.00025370340306410486,25.0,90.0
49.65332,0.0006451789763779528,201.92879002624673,0.00025370340306410486,25.0,90.0
50.95459,0.0006492913385826772,209.0530026246719,0.00025370340306410486,25.0,90.0
52.255859,0.0006930254921259843,219.06377952755906,0.00025370340306410486,25.0,90.0
53.557129,0.0007164157283464567,227.36981364829396,0.00025370340306410486,25.0,90.0
54.858398,0.0007486138582677165,236.29092650918633,0.00025370340306410486,25.0,90.0
56.159668,0.0008069684645669292,246.74224409448817,0.00025370340306410486,25.0,90.0
57.460938,0.0008370751181102362,256.0103937007874,0.00025370340306410486,25.0,90.0
58.762207,0.0008612252362204724,265.8813648293963,0.00025370340306410486,25.0,90.0
60.063477,0.0008878229330708661,274.36440944881895,0.00025370340306410486,25.0,90.0
61.364746,0.0008998572637795275,281.59866141732283,0.00025370340306410486,25.0,90.0
62.666016,0.000938736122047244,289.89049868766404,0.00025370340306410486,25.0,90.0
63.967285,0.0009877843700787402,300.90989501312333,0.00025370340306410486,25.0,90.0
65.268555,0.0010123226181102361,312.2574540682415,0.00025370340306410486,25.0,90.0
66.569824,0.0010626808661417322,320.905249343832,0.00025370340306410486,25.0,90.0
67.871094,0.0010795476968503937,328.8853280839895,0.00025370340306410486,25.0,90.0
69.172363,0.0011180323031496063,338.7728346456693,0.00025370340306410486,25.0,90.0
70.473633,0.0011609038582677167,348.1560367454068,0.00025370340306410486,25.0,90.0
71.774902,0.0011921033464566929,359.1038057742782,0.00025370340306410486,25.0,90.0
73.076172,0.0012229231496062992,366.9426509186352,0.00025370340306410486,25.0,90.0
74.377441,0.0012739040748031495,379.28391076115486,0.00025370340306410486,25.0,90.0
75.678711,0.0012973112598425197,389.5019947506562,0.00025370340306410486,25.0,90.0
76.97998,0.001357519527559055,399.070656167979,0.00025370340306410486,25.0,90.0
78.28125,0.0013835540157480315,409.205564304462,0.00025370340306410486,25.0,90.0
79.58252,0.0014291128346456692,418.5928346456693,0.00025370340306410486,25.0,90.0
80.883789,0.0014724775393700788,427.83889763779524,0.00025370340306410486,25.0,90.0
82.185059,0.0014879973622047243,436.5126509186352,0.00025370340306410486,25.0,90.0
83.486328,0.0015455919685039368,448.15459317585305,0.00025370340306410486,25.0,90.0
84.787598,0.0015501277559055117,454.5453280839895,0.00025370340306410486,25.0,90.0
86.088867,0.0016230334448818896,463.1405774278215,0.00025370340306410486,25.0,90.0
87.390137,0.001639681751968504,474.58094488188976,0.00025370340306410486,25.0,90.0
88.691406,0.0016986035039370077,483.8882152230971,0.00025370340306410486,25.0,90.0
89.992676,0.0017233466141732283,491.79199475065616,0.00025370340306410486,25.0,90.0
91.293945,0.0017422018503937008,500.73406824146986,0.00025370340306410486,25.0,90.0
92.595215,0.0017752656496062991,509.72782152230974,0.00025370340306410486,25.0,90.0
93.896484,0.0018184608661417322,516.9486089238845,0.00025370340306410486,25.0,90.0
95.197754,0.001844577125984252,522.369343832021,0.00025370340306410486,25.0,90.0
96.499023,0.0018906308464566928,535.5597112860893,0.00025370340306410486,25.0,90.0
97.800293,0.0019251601771653544,542.2982414698163,0.00025370340306410486,25.0,90.0
99.101563,0.0019777074803149605,550.9995538057743,0.00025370340306410486,25.0,90.0
100.40283,0.001985173031496063,556.6574803149606,0.00025370340306410486,25.0,90.0
101.7041,0.0020205429133858268,563.3764829396325,0.00025370340306410486,25.0,90.0
103.00537,0.0020472344488188976,572.5285301837271,0.00025370340306410486,25.0,90.0
104.30664,0.002092818700787402,579.8231496062992,0.00025370340306410486,25.0,90.0
105.60791,0.0021240673228346456,585.7833858267716,0.00025370340306410486,25.0,90.0
106.90918,0.002164279724409449,591.2600787401574,0.00025370340306410486,25.0,90.0
108.21045,0.002190394094488189,596.3303412073491,0.00025370340306410486,25.0,90.0
109.51172,0.0022027003937007874,601.0816535433071,0.00025370340306410486,25.0,90.0
110.81299,0.002238213976377953,608.8548818897638,0.00025370340306410486,25.0,90.0
112.11426,0.002265362598425197,615.431811023622,0.00025370340306410486,25.0,90.0
113.41553,0.002301948031496063,617.6578477690289,0.00025370340306410486,25.0,90.0
114.7168,0.002345001377952756,624.3731233595801,0.00025370340306410486,25.0,90.0
116.01807,0.002385625,631.1995800524934,0.00025370340306410486,25.0,90.0
117.31934,0.002398604527559055,637.185564304462,0.00025370340306410486,25.0,90.0
118.62061,0.0024500366141732284,641.9488188976377,0.00025370340306410486,25.0,90.0
119.92188,0.0024903125984251967,648.6628083989501,0.00025370340306410486,25.0,90.0
121.22314,0.0025126025590551182,651.6761154855643,0.00025370340306410486,25.0,90.0
122.52441,0.0025344490157480316,655.0410236220472,0.00025370340306410486,25.0,90.0
123.82568,0.0025861444881889765,659.6579002624673,0.00025370340306410486,25.0,90.0
125.12695,0.0026210942913385826,665.2335433070866,0.00025370340306410486,25.0,90.0
126.42822,0.0026361787401574803,667.5393700787401,0.00025370340306410486,25.0,90.0
127.72949,0.0026788970472440944,672.9527559055117,0.00025370340306410486,25.0,90.0
129.03076,0.0027111840551181103,675.5155118110237,0.00025370340306410486,25.0,90.0
130.33203,0.0027558700787401573,678.3107611548556,0.00025370340306410486,25.0,90.0
131.6333,0.0028124714566929135,685.0286614173227,0.00025370340306410486,25.0,90.0
132.93457,0.0028265338582677164,686.8308923884514,0.00025370340306410486,25.0,90.0
134.23584,0.0028903509842519684,692.1350131233596,0.00025370340306410486,25.0,90.0
135.53711,0.0029187950787401573,693.6982939632545,0.00025370340306410486,25.0,90.0
136.83838,0.0029797147637795275,698.8725984251969,0.00025370340306410486,25.0,90.0
138.13965,0.003012548622047244,702.3301574803149,0.00025370340306410486,25.0,90.0
139.44092,0.003045515354330709,704.0093438320209,0.00025370340306410486,25.0,90.0
140.74219,0.003119694094488189,707.6944094488189,0.00025370340306410486,25.0,90.0
142.04346,0.0031597570866141733,710.7401312335958,0.00025370340306410486,25.0,90.0
143.34473,0.0032193596456692917,715.6556167979003,0.00025370340306410486,25.0,90.0
144.646,0.0032956135826771654,719.0881364829397,0.00025370340306410486,25.0,90.0
145.94727,0.0033636431102362203,722.261469816273,0.00025370340306410486,25.0,90.0
147.24854,0.003423930118110236,724.2105511811023,0.00025370340306410486,25.0,90.0
148.5498,0.0034733738188976377,727.2075065616798,0.00025370340306410486,25.0,90.0
149.85107,0.0035310820866141734,727.3482939632546,0.00025370340306410486,25.0,90.0
151.15234,0.0036288061023622047,732.2660367454067,0.00025370340306410486,25.0,90.0
152.45361,0.0037205285433070862,735.9629921259842,0.00025370340306410486,25.0,90.0
153.75488,0.00377870531496063,736.9353280839895,0.00025370340306410486,25.0,90.0
155.05615,0.003871969291338583,742.0524146981627,0.00025370340306410486,25.0,90.0
156.35742,0.003982264566929134,743.2031496062991,0.00025370340306410486,25.0,90.0
157.65869,0.004093975590551181,745.9243307086614,0.00025370340306410486,25.0,90.0
158.95996,0.00418557125984252,747.579160104987,0.00025370340306410486,25.0,90.0
160.26123,0.004301156102362204,750.697375328084,0.00025370340306410486,25.0,90.0
161.5625,0.004431261023622048,753.8633858267717,0.00025370340306410486,25.0,90.0
162.86377,0.004563875590551181,754.739658792651,0.00025370340306410486,25.0,90.0
164.16504,0.0046769141732283465,757.3654855643044,0.00025370340306410486,25.0,90.0
165.46631,0.004846763976377953,761.5044094488188,0.00025370340306410486,25.0,90.0
166.76758,0.005023015748031496,762.1653805774279,0.00025370340306410486,25.0,90.0
168.06885,0.005180008070866142,763.424593175853,0.00025370340306410486,25.0,90.0
169.37012,0.005303118700787402,765.1319160104987,0.00025370340306410486,25.0,90.0
170.67139,0.00539629311023622,765.2854330708661,0.00025370340306410486,25.0,90.0
171.97266,0.005565071850393701,768.7794750656167,0.00025370340306410486,25.0,90.0
173.27393,0.005736767125984252,769.4249343832021,0.00025370340306410486,25.0,90.0
174.5752,0.005925250984251968,773.2962729658793,0.00025370340306410486,25.0,90.0
175.87646,0.006122847440944882,774.4878215223097,0.00025370340306410486,25.0,90.0
177.17773,0.006314302559055118,775.3819160104987,0.00025370340306410486,25.0,90.0
178.479,0.00654266437007874,778.9462467191601,0.00025370340306410486,25.0,90.0
179.78027,0.006779677755905511,779.5505511811023,0.00025370340306410486,25.0,90.0
181.08154,0.007014121062992125,780.5612860892389,0.00025370340306410486,25.0,90.0
182.38281,0.007194250590551181,781.596220472441,0.00025370340306410486,25.0,90.0
183.68408,0.007419844094488189,784.2255643044618,0.00025370340306410486,25.0,90.0
184.98535,0.007661484055118109,786.1639632545932,0.00025370340306410486,25.0,90.0
186.28662,0.007914574212598426,788.84624671916,0.00025370340306410486,25.0,90.0
187.58789,0.008160301968503937,788.2620209973753,0.00025370340306410486,25.0,90.0
188.88916,0.008395898622047244,789.7719160104987,0.00025370340306410486,25.0,90.0
190.19043,0.008647597834645668,789.6202362204725,0.00025370340306410486,25.0,90.0
191.4917,0.008876422244094488,791.7404986876641,0.00025370340306410486,25.0,90.0
192.79297,0.009136844291338582,792.6333070866141,0.00025370340306410486,25.0,90.0
194.09424,0.009368470078740157,794.8955905511812,0.00025370340306410486,25.0,90.0
195.39551,0.009631733661417324,795.0365091863517,0.00025370340306410486,25.0,90.0
196.69678,0.009938617716535434,798.7435433070866,0.00025370340306410486,25.0,90.0
197.99805,0.010190672440944883,796.6775065616798,0.00025370340306410486,25.0,90.0
199.29932,0.01044994527559055,799.6748031496063,0.00025370340306410486,25.0,90.0
200.60059,0.010734727559055118,798.7955118110236,0.00025370340306410486,25.0,90.0
201.90186,0.010997254921259842,802.5010761154856,0.00025370340306410486,25.0,90.0
203.20313,0.011246460039370078,802.9695538057742,0.00025370340306410486,25.0,90.0
204.50439,0.011560380314960629,803.4261154855643,0.00025370340306410486,25.0,90.0
205.80566,0.011785213188976377,805.1248293963255,0.00025370340306410486,25.0,90.0
207.10693,0.012080070078740157,807.327217847769,0.00025370340306410486,25.0,90.0
208.4082,0.012393880905511813,809.0985564304463,0.00025370340306410486,25.0,90.0
209.70947,0.012667943503937008,806.094409448819,0.00025370340306410486,25.0,90.0
211.01074,0.012887323622047244,806.0769816272966,0.00025370340306410486,25.0,90.0
212.31201,0.013164226968503936,810.0352755905511,0.00025370340306410486,25.0,90.0
213.61328,0.013478837992125983,810.3728346456693,0.00025370340306410486,25.0,90.0
214.91455,0.013758642519685041,811.0659842519685,0.00025370340306410486,25.0,90.0
216.21582,0.01403666653543307,812.8885826771653,0.00025370340306410486,25.0,90.0
217.51709,0.01436353720472441,813.3113648293963,0.00025370340306410486,25.0,90.0
218.81836,0.014669958464566929,814.0328871391075,0.00025370340306410486,25.0,90.0
220.11963,0.014963920669291338,814.3534120734907,0.00025370340306410486,25.0,90.0
221.4209,0.015227706299212598,816.7214435695538,0.00025370340306410486,25.0,90.0
222.72217,0.015540052952755906,818.2248818897638,0.00025370340306410486,25.0,90.0
224.02344,0.015855400196850392,818.3796325459318,0.00025370340306410486,25.0,90.0
225.32471,0.01616914153543307,817.9385564304462,0.00025370340306410486,25.0,90.0
226.62598,0.01642587401574803,818.3871916010498,0.00025370340306410486,25.0,90.0
227.92725,0.016696118897637797,820.0350918635171,0.00025370340306410486,25.0,90.0
229.22852,0.01699139803149606,819.3013385826772,0.00025370340306410486,25.0,90.0
230.52979,0.017251848622047244,823.0297637795275,0.00025370340306410486,25.0,90.0
231.83105,0.017601027165354333,822.8303412073491,0.00025370340306410486,25.0,90.0
233.13232,0.01790907066929134,824.6370603674541,0.00025370340306410486,25.0,90.0
234.43359,0.018254385826771653,824.5434908136482,0.00025370340306410486,25.0,90.0
235.73486,0.018552104133858268,824.8337270341208,0.00025370340306410486,25.0,90.0
237.03613,0.01885439094488189,827.1056955380577,0.00025370340306410486,25.0,90.0
238.3374,0.019147266141732285,826.9008923884514,0.00025370340306410486,25.0,90.0
239.63867,0.01942146062992126,828.0828871391076,0.00025370340306410486,25.0,90.0
240.93994,0.01971017125984252,829.2779002624671,0.00025370340306410486,25.0,90.0
242.24121,0.019992592519685038,827.7155905511811,0.00025370340306410486,25.0,90.0
243.54248,0.020301476377952755,830.6545669291339,0.00025370340306410486,25.0,90.0
244.84375,0.020565161417322834,830.1686614173228,0.00025370340306410486,25.0,90.0
246.14502,0.020885147637795275,832.5379265091864,0.00025370340306410486,25.0,90.0
247.44629,0.02123832086614173,831.0848031496064,0.00025370340306410486,25.0,90.0
248.74756,0.0215391968503937,833.3797900262467,0.00025370340306410486,25.0,90.0
250.04883,0.02180611220472441,832.5320997375328,0.00025370340306410486,25.0,90.0
251.3501,0.02216413976377953,836.784750656168,0.00025370340306410486,25.0,90.0
252.65137,0.022527862204724407,836.7655380577428,0.00025370340306410486,25.0,90.0
253.95264,0.022828370078740157,834.9956692913386,0.00025370340306410486,25.0,90.0
255.25391,0.02313630905511811,836.8956692913387,0.00025370340306410486,25.0,90.0
256.55518,0.02340641929133858,836.8629396325459,0.00025370340306410486,25.0,90.0
257.85645,0.023674328740157482,839.1269553805774,0.00025370340306410486,25.0,90.0
259.15771,0.023993153543307087,838.1104199475066,0.00025370340306410486,25.0,90.0
260.45898,0.024299155511811023,839.269658792651,0.00025370340306410486,25.0,90.0
261.76025,0.024627064960629923,841.1005249343832,0.00025370340306410486,25.0,90.0
263.06152,0.02491244094488189,841.1920997375328,0.00025370340306410486,25.0,90.0
264.36279,0.025249,842.9899475065617,0.00025370340306410486,25.0,90.0
265.66406,0.025560712598425194,842.6702624671916,0.00025370340306410486,25.0,90.0
266.96533,0.0258489468503937,841.095721784777,0.00025370340306410486,25.0,90.0
268.2666,0.026185602362204723,843.327532808399,0.00025370340306410486,25.0,90.0
269.56787,0.026462362204724407,844.6705511811024,0.00025370340306410486,25.0,90.0
270.86914,0.026756872047244095,845.3873490813648,0.00025370340306410486,25.0,90.0
272.17041,0.027044964566929137,845.7774015748032,0.00025370340306410486,25.0,90.0
273.47168,0.027374372047244095,846.9552230971128,0.00025370340306410486,25.0,90.0
274.77295,0.027679478346456694,846.8299475065616,0.00025370340306410486,25.0,90.0
276.07422,0.027962377952755902,848.1249868766405,0.00025370340306410486,25.0,90.0
277.37549,0.02826042125984252,849.1438320209974,0.00025370340306410486,25.0,90.0
278.67676,0.028583082677165354,848.5389238845145,0.00025370340306410486,25.0,90.0
279.97803,0.028900403543307085,849.4482152230971,0.00025370340306410486,25.0,90.0
281.2793,0.02919566338582677,850.0712598425197,0.00025370340306410486,25.0,90.0
282.58057,0.029491903543307083,850.7538845144356,0.00025370340306410486,25.0,90.0
283.88184,0.029830147637795276,852.4494225721785,0.00025370340306410486,25.0,90.0
285.18311,0.030161824803149603,851.9005249343832,0.00025370340306410486,25.0,90.0
286.48438,0.030452625984251965,853.9971653543307,0.00025370340306410486,25.0,90.0
287.78564,0.030813025590551178,853.0277165354331,0.00025370340306410486,25.0,90.0
289.08691,0.031142842519685042,854.8928083989501,0.00025370340306410486,25.0,90.0
290.38818,0.03146841929133858,854.9452230971128,0.00025370340306410486,25.0,90.0
291.68945,0.03174268503937008,853.6660104986877,0.00025370340306410486,25.0,90.0
292.99072,0.0320237283464567,856.0762729658792,0.00025370340306410486,25.0,90.0
294.29199,0.03235184645669291,856.6088976377953,0.00025370340306410486,25.0,90.0
295.59326,0.03264961417322834,857.2757742782152,0.00025370340306410486,25.0,90.0
296.89453,0.03301707283464567,857.9132283464567,0.00025370340306410486,25.0,90.0
298.1958,0.033315938976377954,858.9987926509186,0.00025370340306410486,25.0,90.0
299.49707,0.0335969468503937,859.049028871391,0.00025370340306410486,25.0,90.0
300.79834,0.03389816732283464,860.0168241469817,0.00025370340306410486,25.0,90.0
302.09961,0.034227598425196855,859.9946981627296,0.00025370340306410486,25.0,90.0
303.40088,0.03460144094488189,861.9533333333333,0.00025370340306410486,25.0,90.0
304.70215,0.0349441062992126,861.5584776902887,0.00025370340306410486,25.0,90.0
306.00342,0.0352414842519685,863.4777690288714,0.00025370340306410486,25.0,90.0
307.30469,0.03552716929133858,861.3853543307087,0.00025370340306410486,25.0,90.0
308.60596,0.0358524251968504,863.159501312336,0.00025370340306410486,25.0,90.0
309.90723,0.03611321653543307,863.9689501312336,0.00025370340306410486,25.0,90.0
311.2085,0.03640125787401575,864.4868241469817,0.00025370340306410486,25.0,90.0
312.50977,0.036669228346456695,861.7830183727034,0.00025370340306410486,25.0,90.0
313.81104,0.03692750590551181,864.7067454068242,0.00025370340306410486,25.0,90.0
315.1123,0.037217958661417326,866.6925459317584,0.00025370340306410486,25.0,90.0
316.41357,0.03754354921259842,868.324593175853,0.00025370340306410486,25.0,90.0
317.71484,0.037864143700787396,864.7862729658792,0.00025370340306410486,25.0,90.0
319.01611,0.038157923228346456,866.7787401574803,0.00025370340306410486,25.0,90.0
320.31738,0.03846343700787401,870.6314173228346,0.00025370340306410486,25.0,90.0
321.61865,0.038806970472440944,868.4493963254592,0.00025370340306410486,25.0,90.0
322.91992,0.039124102362204725,868.0230183727034,0.00025370340306410486,25.0,90.0
324.22119,0.03948137795275591,870.2204199475066,0.00025370340306410486,25.0,90.0
325.52246,0.039801403543307086,868.575905511811,0.00025370340306410486,25.0,90.0
326.82373,0.04013146062992126,869.8817585301837,0.00025370340306410486,25.0,90.0
328.125,0.040399692913385826,869.6146194225721,0.00025370340306410486,25.0,90.0
329.42627,0.04067062598425197,871.7725459317585,0.00025370340306410486,25.0,90.0
330.72754,0.040977935039370084,872.9257742782153,0.00025370340306410486,25.0,90.0
332.02881,0.04136293110236221,874.8244881889764,0.00025370340306410486,25.0,90.0
333.33008,0.04164831102362205,871.0949606299213,0.00025370340306410486,25.0,90.0
334.63135,0.04191841535433071,873.3538057742783,0.00025370340306410486,25.0,90.0
335.93262,0.042247027559055114,875.7029396325458,0.00025370340306410486,25.0,90.0
337.23389,0.042565405511811025,875.2959055118109,0.00025370340306410486,25.0,90.0
338.53516,0.042955498031496064,876.6551706036745,0.00025370340306410486,25.0,90.0
339.83643,0.04328508070866142,874.818530183727,0.00025370340306410486,25.0,90.0
341.1377,0.0435865531496063,877.5175853018372,0.00025370340306410486,25.0,90.0
342.43896,0.043902149606299214,876.5784514435695,0.00025370340306410486,25.0,90.0
343.74023,0.0442316968503937,879.7027559055118,0.00025370340306410486,25.0,90.0
345.0415,0.044578131889763783,878.2513648293964,0.00025370340306410486,25.0,90.0
346.34277,0.04484566141732284,876.5381627296588,0.00025370340306410486,25.0,90.0
347.64404,0.045105035433070866,876.8609186351706,0.00025370340306410486,25.0,90.0
348.94531,0.045386047244094486,880.2550393700786,0.00025370340306410486,25.0,90.0
350.24658,0.045681527559055114,880.0049343832021,0.00025370340306410486,25.0,90.0
351.54785,0.04601129527559055,881.658687664042,0.00025370340306410486,25.0,90.0
352.84912,0.04633897440944882,881.2462204724409,0.00025370340306410486,25.0,90.0
354.15039,0.04669038582677165,881.8575853018373,0.00025370340306410486,25.0,90.0
355.45166,0.04699184448818897,882.0200262467191,0.00025370340306410486,25.0,90.0
356.75293,0.04730535039370079,883.5961942257218,0.00025370340306410486,25.0,90.0
358.0542,0.04762122440944882,882.2046456692914,0.00025370340306410486,25.0,90.0
359.35547,0.047882051181102364,883.3512073490814,0.00025370340306410486,25.0,90.0
360.65674,0.04818053543307087,883.794435695538,0.00025370340306410486,25.0,90.0
361.95801,0.04856438976377953,886.9257217847769,0.00025370340306410486,25.0,90.0
363.25928,0.04889317716535433,885.2429396325459,0.00025370340306410486,25.0,90.0
364.56055,0.04918591338582677,886.8055118110235,0.00025370340306410486,25.0,90.0
365.86182,0.04950412795275591,886.155748031496,0.00025370340306410486,25.0,90.0
367.16309,0.04983979133858268,886.3411286089239,0.00025370340306410486,25.0,90.0
368.46436,0.05016449015748031,888.8181627296588,0.00025370340306410486,25.0,90.0
369.76563,0.05046922440944882,888.4521522309711,0.00025370340306410486,25.0,90.0
371.06689,0.05077343700787401,888.9039632545931,0.00025370340306410486,25.0,90.0
372.36816,0.051077149606299214,889.2861417322833,0.00025370340306410486,25.0,90.0
373.66943,0.051376698818897636,887.4671916010499,0.00025370340306410486,25.0,90.0
374.9707,0.051714222440944875,892.0594750656168,0.00025370340306410486,25.0,90.0
376.27197,0.05207074015748031,891.3367191601051,0.00025370340306410486,25.0,90.0
377.57324,0.05234861220472441,889.5259842519685,0.00025370340306410486,25.0,90.0
378.87451,0.05268164173228347,891.9938582677165,0.00025370340306410486,25.0,90.0
380.17578,0.053005360236220475,892.1977427821522,0.00025370340306410486,25.0,90.0
381.47705,0.053270413385826776,890.6588451443569,0.00025370340306410486,25.0,90.0
382.77832,0.05357169881889763,892.6451443569554,0.00025370340306410486,25.0,90.0
384.07959,0.05389051968503936,891.6507874015748,0.00025370340306410486,25.0,90.0
385.38086,0.05414138582677165,892.2888188976377,0.00025370340306410486,25.0,90.0
386.68213,0.05445418700787401,895.0494488188975,0.00025370340306410486,25.0,90.0
387.9834,0.05483513582677165,894.9691076115486,0.00025370340306410486,25.0,90.0
389.28467,0.05521762007874016,896.5060892388451,0.00025370340306410486,25.0,90.0
390.58594,0.055500547244094485,892.7903674540682,0.00025370340306410486,25.0,90.0
391.88721,0.05580523031496063,895.5897112860893,0.00025370340306410486,25.0,90.0
393.18848,0.05610449606299212,896.4854068241469,0.00025370340306410486,25.0,90.0
394.48975,0.05641846653543307,896.401128608924,0.00025370340306410486,25.0,90.0
395.79102,0.056742220472440937,896.1669816272967,0.00025370340306410486,25.0,90.0
397.09229,0.05707975984251968,898.3297112860892,0.00025370340306410486,25.0,90.0
398.39355,0.05741649803149606,899.3142257217849,0.00025370340306410486,25.0,90.0
399.69482,0.05772298031496063,898.4064304461942,0.00025370340306410486,25.0,90.0
400.99609,0.058019466535433065,897.2837532808398,0.00025370340306410486,25.0,90.0
402.29736,0.0584271062992126,901.3008136482939,0.00025370340306410486,25.0,90.0
403.59863,0.05880862401574803,900.4018372703412,0.00025370340306410486,25.0,90.0
404.8999,0.059128411417322835,899.8598687664042,0.00025370340306410486,25.0,90.0
406.20117,0.05939016732283464,898.07968503937,0.00025370340306410486,25.0,90.0
407.50244,0.05968204330708661,899.3740157480314,0.00025370340306410486,25.0,90.0
408.80371,0.05999020866141732,901.7288451443569,0.00025370340306410486,25.0,90.0
410.10498,0.060302722440944874,901.0640419947507,0.00025370340306410486,25.0,90.0
411.40625,0.060625151574803145,903.8615748031496,0.00025370340306410486,25.0,90.0
412.70752,0.06093105905511811,903.3390288713911,0.00025370340306410486,25.0,90.0
414.00879,0.06126929724409449,903.071627296588,0.00025370340306410486,25.0,90.0
415.31006,0.06156237007874016,903.7843832020998,0.00025370340306410486,25.0,90.0
416.61133,0.061937311023622044,906.1085039370079,0.00025370340306410486,25.0,90.0
417.9126,0.062257590551181095,903.5548293963254,0.00025370340306410486,25.0,90.0
419.21387,0.0625107342519685,904.916062992126,0.00025370340306410486,25.0,90.0
420.51514,0.06277240354330708,903.9516797900262,0.00025370340306410486,25.0,90.0
421.81641,0.06309667913385826,906.5533595800525,0.00025370340306410486,25.0,90.0
423.11768,0.06338969881889764,904.9927821522309,0.00025370340306410486,25.0,90.0
424.41895,0.06370542125984252,906.0023884514435,0.00025370340306410486,25.0,90.0
425.72021,0.06400591929133859,906.0282152230972,0.00025370340306410486,25.0,90.0
427.02148,0.06430725196850393,906.8220209973753,0.00025370340306410486,25.0,90.0
428.32275,0.06463799803149606,909.482467191601,0.00025370340306410486,25.0,90.0
429.62402,0.06502256102362204,909.0776115485564,0.00025370340306410486,25.0,90.0
430.92529,0.06535494488188975,908.7532545931759,0.00025370340306410486,25.0,90.0
432.22656,0.06565174212598425,909.0395538057743,0.00025370340306410486,25.0,90.0
433.52783,0.06595868110236221,908.6890288713911,0.00025370340306410486,25.0,90.0
434.8291,0.06630640157480314,909.8240682414698,0.00025370340306410486,25.0,90.0
436.13037,0.06665568110236221,910.6744619422572,0.00025370340306410486,25.0,90.0
437.43164,0.06698080708661418,910.6833595800524,0.00025370340306410486,25.0,90.0
438.73291,0.06733618897637796,910.8186351706037,0.00025370340306410486,25.0,90.0
440.03418,0.06762938976377952,910.9424409448819,0.00025370340306410486,25.0,90.0
441.33545,0.06796242519685039,912.1016797900262,0.00025370340306410486,25.0,90.0
442.63672,0.06827842322834646,911.906062992126,0.00025370340306410486,25.0,90.0
443.93799,0.0686048346456693,913.3716010498688,0.00025370340306410486,25.0,90.0
445.23926,0.06891643897637795,912.9934645669291,0.00025370340306410486,25.0,90.0
446.54053,0.0692616594488189,913.5540419947506,0.00025370340306410486,25.0,90.0
447.8418,0.06956484448818898,912.717217847769,0.00025370340306410486,25.0,90.0
449.14307,0.06990706102362206,914.4984251968503,0.00025370340306410486,25.0,90.0
450.44434,0.07022738976377953,915.8306299212599,0.00025370340306410486,25.0,90.0
451.74561,0.07054825196850394,916.5836745406823,0.00025370340306410486,25.0,90.0
453.04688,0.07094058070866142,915.8043569553805,0.00025370340306410486,25.0,90.0
454.34814,0.07124065551181102,916.3883202099737,0.00025370340306410486,25.0,90.0
455.64941,0.07154554330708661,917.1901312335958,0.00025370340306410486,25.0,90.0
456.95068,0.07183605708661418,916.4071391076116,0.00025370340306410486,25.0,90.0
458.25195,0.072114468503937,916.1096325459317,0.00025370340306410486,25.0,90.0
459.55322,0.07239674015748032,915.5443832020997,0.00025370340306410486,25.0,90.0
460.85449,0.0726800157480315,917.3092388451443,0.00025370340306410486,25.0,90.0
462.15576,0.07300915354330709,918.4369816272966,0.00025370340306410486,25.0,90.0
463.45703,0.07338343700787402,920.0479790026246,0.00025370340306410486,25.0,90.0
464.7583,0.07377194094488189,919.0958267716535,0.00025370340306410486,25.0,90.0
466.05957,0.07407911023622048,920.2996325459318,0.00025370340306410486,25.0,90.0
467.36084,0.07441138385826772,919.1245406824147,0.00025370340306410486,25.0,90.0
468.66211,0.07474880708661417,919.6447244094488,0.00025370340306410486,25.0,90.0
469.96338,0.07508837007874015,919.282624671916,0.00025370340306410486,25.0,90.0
471.26465,0.07545016929133859,920.303280839895,0.00025370340306410486,25.0,90.0
472.56592,0.0757832342519685,921.5253805774278,0.00025370340306410486,25.0,90.0
473.86719,0.0761522559055118,922.0202099737533,0.00025370340306410486,25.0,90.0
475.16846,0.07649067519685039,921.0718372703412,0.00025370340306410486,25.0,90.0
476.46973,0.07679545669291338,922.0739632545932,0.00025370340306410486,25.0,90.0
477.771,0.0771219625984252,921.6796325459318,0.00025370340306410486,25.0,90.0
479.07227,0.07742886220472442,922.7397375328084,0.00025370340306410486,25.0,90.0
480.37354,0.07771348622047243,920.7163254593175,0.00025370340306410486,25.0,90.0
481.6748,0.07802611220472441,923.8575328083989,0.00025370340306410486,25.0,90.0
482.97607,0.07837890551181102,925.692125984252,0.00025370340306410486,25.0,90.0
484.27734,0.07869881102362204,923.279343832021,0.00025370340306410486,25.0,90.0
485.57861,0.07898116535433071,924.6287139107611,0.00025370340306410486,25.0,90.0
486.87988,0.07931076181102363,924.063937007874,0.00025370340306410486,25.0,90.0
488.18115,0.07971139173228346,927.3651443569554,0.00025370340306410486,25.0,90.0
489.48242,0.08007357283464567,926.7981889763779,0.00025370340306410486,25.0,90.0
490.78369,0.08038667913385826,924.6223884514435,0.00025370340306410486,25.0,90.0
492.08496,0.08072320472440944,924.5093438320209,0.00025370340306410486,25.0,90.0
493.38623,0.08107355118110236,927.7832545931759,0.00025370340306410486,25.0,90.0
494.6875,0.08141478149606299,926.9630446194226,0.00025370340306410486,25.0,90.0
495.98877,0.08174525984251968,927.7189238845144,0.00025370340306410486,25.0,90.0
497.29004,0.08212318503937008,927.583280839895,0.00025370340306410486,25.0,90.0
498.59131,0.08246463976377952,927.7428871391077,0.00025370340306410486,25.0,90.0
499.89258,0.08275353346456693,926.7760104986876,0.00025370340306410486,25.0,90.0
501.19385,0.08303848031496062,927.0162992125984,0.00025370340306410486,25.0,90.0
502.49512,0.08335696062992126,927.7552755905512,0.00025370340306410486,25.0,90.0
503.79639,0.0836972874015748,927.6371653543307,0.00025370340306410486,25.0,90.0
505.09766,0.08405350787401575,928.9466929133858,0.00025370340306410486,25.0,90.0
506.39893,0.08440289960629921,929.4922572178477,0.00025370340306410486,25.0,90.0
507.7002,0.08479243503937008,930.7299475065616,0.00025370340306410486,25.0,90.0
509.00146,0.08519581692913386,931.8507349081365,0.00025370340306410486,25.0,90.0
510.30273,0.08557347834645669,932.9224671916011,0.00025370340306410486,25.0,90.0
511.604,0.08597084055118111,931.8338320209974,0.00025370340306410486,25.0,90.0
512.90527,0.08634686023622047,931.2663517060367,0.00025370340306410486,25.0,90.0
514.20654,0.08666395669291338,933.3744619422572,0.00025370340306410486,25.0,90.0
515.50781,0.08696664960629921,932.0682152230971,0.00025370340306410486,25.0,90.0
516.80908,0.08727705708661417,932.990183727034,0.00025370340306410486,25.0,90.0
518.11035,0.08761797637795275,933.1596062992126,0.00025370340306410486,25.0,90.0
519.41162,0.08804626181102361,934.7651706036745,0.00025370340306410486,25.0,90.0
520.71289,0.08834322440944882,931.9597900262467,0.00025370340306410486,25.0,90.0
522.01416,0.08864390944881889,932.4992913385826,0.00025370340306410486,25.0,90.0
523.31543,0.08902634251968504,935.2559580052493,0.00025370340306410486,25.0,90.0
524.6167,0.0893555590551181,933.8023359580053,0.00025370340306410486,25.0,90.0
525.91797,0.0897069901574803,934.6159317585302,0.00025370340306410486,25.0,90.0
527.21924,0.09003105511811023,935.5816010498688,0.00025370340306410486,25.0,90.0
528.52051,0.09035133661417322,934.8084251968504,0.00025370340306410486,25.0,90.0
529.82178,0.09065669291338582,936.3512598425198,0.00025370340306410486,25.0,90.0
531.12305,0.09099713779527559,935.8386351706037,0.00025370340306410486,25.0,90.0
532.42432,0.09133571062992125,934.8544356955381,0.00025370340306410486,25.0,90.0
533.72559,0.09165304724409448,937.3039895013123,0.00025370340306410486,25.0,90.0
535.02686,0.09197393307086614,937.4843044619422,0.00025370340306410486,25.0,90.0
536.32813,0.09236348031496062,938.0807349081364,0.00025370340306410486,25.0,90.0
537.62939,0.09272928740157481,937.8996062992126,0.00025370340306410486,25.0,90.0
538.93066,0.09300932283464568,937.2948818897637,0.00025370340306410486,25.0,90.0
540.23193,0.09335999803149606,937.6491076115485,0.00025370340306410486,25.0,90.0
541.5332,0.09372778149606299,937.9169028871391,0.00025370340306410486,25.0,90.0
542.83447,0.09406450196850394,938.0648556430446,0.00025370340306410486,25.0,90.0
544.13574,0.0944058248031496,939.3443307086613,0.00025370340306410486,25.0,90.0
545.43701,0.09480217322834646,941.0674015748032,0.00025370340306410486,25.0,90.0
546.73828,0.09522406299212598,939.9781364829396,0.00025370340306410486,25.0,90.0
548.03955,0.0955998248031496,938.7532545931758,0.00025370340306410486,25.0,90.0
549.34082,0.09594748622047243,940.4130183727034,0.00025370340306410486,25.0,90.0
550.64209,0.09629602559055118,939.7411023622046,0.00025370340306410486,25.0,90.0
551.94336,0.09660855708661417,940.3399212598425,0.00025370340306410486,25.0,90.0
553.24463,0.09689453149606299,939.0466666666666,0.00025370340306410486,25.0,90.0
554.5459,0.09722357677165354,941.4214435695538,0.00025370340306410486,25.0,90.0
555.84717,0.09753617322834646,942.4343307086614,0.00025370340306410486,25.0,90.0
557.14844,0.09786323622047244,942.8523884514436,0.00025370340306410486,25.0,90.0
558.44971,0.09824624212598425,942.7850393700787,0.00025370340306410486,25.0,90.0
559.75098,0.09859048228346456,942.9306299212599,0.00025370340306410486,25.0,90.0
561.05225,0.09896792716535434,942.6258005249344,0.00025370340306410486,25.0,90.0
562.35352,0.09931427952755906,942.8817847769029,0.00025370340306410486,25.0,90.0
563.65479,0.0996923464566929,943.4861154855643,0.00025370340306410486,25.0,90.0
564.95605,0.10006852559055118,942.3079002624671,0.00025370340306410486,25.0,90.0
566.25732,0.10039858070866142,942.8912860892389,0.00025370340306410486,25.0,90.0
567.55859,0.10076217913385827,945.4271391076115,0.00025370340306410486,25.0,90.0
568.85986,0.10114221850393701,943.1029921259843,0.00025370340306410486,25.0,90.0
570.16113,0.1015358779527559,947.3989763779527,0.00025370340306410486,25.0,90.0
571.4624,0.10191814566929133,943.8676377952755,0.00025370340306410486,25.0,90.0
572.76367,0.10223515354330709,944.8834908136483,0.00025370340306410486,25.0,90.0
574.06494,0.10257608464566928,945.0813648293964,0.00025370340306410486,25.0,90.0
575.36621,0.10296629724409448,946.0589501312335,0.00025370340306410486,25.0,90.0
576.66748,0.10338284842519685,945.8436482939633,0.00025370340306410486,25.0,90.0
577.96875,0.10373661614173228,945.329028871391,0.00025370340306410486,25.0,90.0
579.27002,0.10402168503937008,945.8032283464566,0.00025370340306410486,25.0,90.0
580.57129,0.10437839763779527,947.6367716535433,0.00025370340306410486,25.0,90.0
581.87256,0.10477864173228346,947.8220734908136,0.00025370340306410486,25.0,90.0
583.17383,0.10519184842519684,947.7362729658793,0.00025370340306410486,25.0,90.0
584.4751,0.10556759251968505,947.8079790026246,0.00025370340306410486,25.0,90.0
585.77637,0.1059348661417323,947.8402099737533,0.00025370340306410486,25.0,90.0
587.07764,0.10629290354330707,948.8869553805774,0.00025370340306410486,25.0,90.0
588.37891,0.10664351574803149,948.2553805774278,0.00025370340306410486,25.0,90.0
589.68018,0.107002,947.8941732283464,0.00025370340306410486,25.0,90.0
590.98145,0.10739164763779528,948.9027034120735,0.00025370340306410486,25.0,90.0
592.28271,0.10772377952755904,948.0451968503937,0.00025370340306410486,25.0,90.0
593.58398,0.10813847834645668,949.0422834645669,0.00025370340306410486,25.0,90.0
594.88525,0.10855840944881891,949.9827559055118,0.00025370340306410486,25.0,90.0
596.18652,0.10890501968503938,948.7902624671916,0.00025370340306410486,25.0,90.0
597.48779,0.10928465944881889,949.1187139107611,0.00025370340306410486,25.0,90.0
598.78906,0.10969777362204725,948.7396325459317,0.00025370340306410486,25.0,90.0
600.09033,0.11004644881889764,949.2017060367455,0.00025370340306410486,25.0,90.0
601.3916,0.11034333267716535,948.8691338582678,0.00025370340306410486,25.0,90.0
602.69287,0.11071315157480316,949.9977690288714,0.00025370340306410486,25.0,90.0
603.99414,0.11105064566929133,949.5777952755906,0.00025370340306410486,25.0,90.0
605.29541,0.1114307657480315,951.6194750656168,0.00025370340306410486,25.0,90.0
606.59668,0.1117489468503937,949.679343832021,0.00025370340306410486,25.0,90.0
607.89795,0.11215682874015746,952.1456167979002,0.00025370340306410486,25.0,90.0
609.19922,0.1125792933070866,952.8670078740157,0.00025370340306410486,25.0,90.0
610.50049,0.1129746437007874,952.3746456692913,0.00025370340306410486,25.0,90.0
611.80176,0.11330454527559054,950.8387401574803,0.00025370340306410486,25.0,90.0
613.10303,0.11365281102362206,953.2132283464567,0.00025370340306410486,25.0,90.0
614.4043,0.11401307874015747,952.8636220472441,0.00025370340306410486,25.0,90.0
615.70557,0.11445363582677165,954.2786876640421,0.00025370340306410486,25.0,90.0
617.00684,0.1149102342519685,953.5361417322835,0.00025370340306410486,25.0,90.0
618.30811,0.11535020472440945,951.844908136483,0.00025370340306410486,25.0,90.0
619.60938,0.11575266535433071,952.2569291338582,0.00025370340306410486,25.0,90.0
620.91064,0.11611300393700787,953.9250918635171,0.00025370340306410486,25.0,90.0
622.21191,0.11653116338582677,954.3501312335958,0.00025370340306410486,25.0,90.0
623.51318,0.11692927165354332,952.4222572178477,0.00025370340306410486,25.0,90.0
624.81445,0.11731925984251967,953.0392650918635,0.00025370340306410486,25.0,90.0
626.11572,0.11768879527559055,953.7294488188976,0.00025370340306410486,25.0,90.0
627.41699,0.11808260826771652,954.8671653543307,0.00025370340306410486,25.0,90.0
628.71826,0.1185114468503937,955.4504199475065,0.00025370340306410486,25.0,90.0
630.01953,0.11888257874015747,955.1930183727035,0.00025370340306410486,25.0,90.0
631.3208,0.11928310236220473,956.0440419947506,0.00025370340306410486,25.0,90.0
632.62207,0.119675718503937,955.6283727034121,0.00025370340306410486,25.0,90.0
633.92334,0.12004835433070865,954.8692913385827,0.00025370340306410486,25.0,90.0
635.22461,0.1204709251968504,957.4961942257218,0.00025370340306410486,25.0,90.0
636.52588,0.12084975393700788,956.4043569553805,0.00025370340306410486,25.0,90.0
637.82715,0.12124562204724411,956.9216797900262,0.00025370340306410486,25.0,90.0
639.12842,0.12167237007874014,957.1964566929134,0.00025370340306410486,25.0,90.0
640.42969,0.12200430118110235,955.8536745406824,0.00025370340306410486,25.0,90.0
641.73096,0.12245793110236221,954.5490813648294,0.00025370340306410486,25.0,90.0
643.03223,0.12277224015748031,955.1040157480315,0.00025370340306410486,25.0,90.0
644.3335,0.1231920059055118,958.8442257217848,0.00025370340306410486,25.0,90.0
645.63477,0.12354513976377952,956.1592125984253,0.00025370340306410486,25.0,90.0
646.93604,0.12388474606299212,956.8597112860892,0.00025370340306410486,25.0,90.0
648.2373,0.12423414960629921,958.6795538057743,0.00025370340306410486,25.0,90.0
649.53857,0.12470774803149605,957.8820997375328,0.00025370340306410486,25.0,90.0
650.83984,0.12512020472440946,957.5331758530183,0.00025370340306410486,25.0,90.0
652.14111,0.1255358405511811,958.8416010498687,0.00025370340306410486,25.0,90.0
653.44238,0.12597697440944883,958.9018372703413,0.00025370340306410486,25.0,90.0
654.74365,0.12638523031496063,958.5586351706037,0.00025370340306410486,25.0,90.0
656.04492,0.12679311220472442,957.2006824146981,0.00025370340306410486,25.0,90.0
657.34619,0.12722345078740158,958.1299475065617,0.00025370340306410486,25.0,90.0
658.64746,0.1276026437007874,957.1409448818897,0.00025370340306410486,25.0,90.0
659.94873,0.1279877283464567,958.174278215223,0.00025370340306410486,25.0,90.0
661.25,0.1284186062992126,960.5965354330709,0.00025370340306410486,25.0,90.0
662.55127,0.12880818307086614,959.6306036745407,0.00025370340306410486,25.0,90.0
663.85254,0.12924733267716534,959.4643307086614,0.00025370340306410486,25.0,90.0
665.15381,0.12967893897637794,958.0595800524934,0.00025370340306410486,25.0,90.0
666.45508,0.13013009251968505,959.7497900262466,0.00025370340306410486,25.0,90.0
667.75635,0.13057279724409449,961.414435695538,0.00025370340306410486,25.0,90.0
669.05762,0.13102957086614175,959.9836745406824,0.00025370340306410486,25.0,90.0
670.35889,0.13143952952755905,960.8485039370079,0.00025370340306410486,25.0,90.0
671.66016,0.1318538287401575,957.9321259842519,0.00025370340306410486,25.0,90.0
672.96143,0.13225101968503936,959.9947769028871,0.00025370340306410486,25.0,90.0
674.2627,0.1326226811023622,960.0912860892388,0.00025370340306410486,25.0,90.0
675.56396,0.13305235039370078,961.26687664042,0.00025370340306410486,25.0,90.0
676.86523,0.13350359842519685,961.2273228346456,0.00025370340306410486,25.0,90.0
678.1665,0.13392090157480316,960.7252755905512,0.00025370340306410486,25.0,90.0
679.46777,0.13432402952755906,959.7645406824147,0.00025370340306410486,25.0,90.0
680.76904,0.13470552362204724,959.4025459317585,0.00025370340306410486,25.0,90.0
682.07031,0.13511118700787403,961.6444094488189,0.00025370340306410486,25.0,90.0
683.37158,0.13559154330708661,961.6626771653544,0.00025370340306410486,25.0,90.0
684.67285,0.13599199803149606,960.4398687664042,0.00025370340306410486,25.0,90.0
685.97412,0.13639848228346457,960.4729396325458,0.00025370340306410486,25.0,90.0
687.27539,0.13686598031496064,962.2186876640419,0.00025370340306410486,25.0,90.0
688.57666,0.13731882283464567,962.4271391076115,0.00025370340306410486,25.0,90.0
689.87793,0.13782870078740156,962.5563254593175,0.00025370340306410486,25.0,90.0
691.1792,0.13828555708661416,961.2131758530184,0.00025370340306410486,25.0,90.0
692.48047,0.1386924527559055,961.1517060367454,0.00025370340306410486,25.0,90.0
693.78174,0.13912786023622048,961.5144619422572,0.00025370340306410486,25.0,90.0
695.08301,0.13959027559055118,963.4386876640419,0.00025370340306410486,25.0,90.0
696.38428,0.14009643503937008,962.7939370078741,0.00025370340306410486,25.0,90.0
697.68555,0.14059388779527557,963.6244619422572,0.00025370340306410486,25.0,90.0
698.98682,0.1410392559055118,959.4418897637795,0.00025370340306410486,25.0,90.0
700.28809,0.141463844488189,964.7316010498687,0.00025370340306410486,25.0,90.0
701.58936,0.14191972637795275,964.1607349081365,0.00025370340306410486,25.0,90.0
702.89063,0.14238414960629922,963.3016272965879,0.00025370340306410486,25.0,90.0
704.19189,0.1428284625984252,961.9611023622048,0.00025370340306410486,25.0,90.0
705.49316,0.143232437007874,963.809842519685,0.00025370340306410486,25.0,90.0
706.79443,0.1437069035433071,962.880813648294,0.00025370340306410486,25.0,90.0
708.0957,0.1441383681102362,963.7170603674541,0.00025370340306410486,25.0,90.0
709.39697,0.14459633858267718,964.7598687664041,0.00025370340306410486,25.0,90.0
710.69824,0.14512941338582677,967.0105249343833,0.00025370340306410486,25.0,90.0
711.99951,0.14558158661417323,960.6107086614173,0.00025370340306410486,25.0,90.0
713.30078,0.146006,962.4405249343832,0.00025370340306410486,25.0,90.0
714.60205,0.14644857677165354,963.9346719160105,0.00025370340306410486,25.0,90.0
715.90332,0.14695037007874015,963.100813648294,0.00025370340306410486,25.0,90.0
717.20459,0.14745568503937007,963.0192388451444,0.00025370340306410486,25.0,90.0
718.50586,0.14789361417322833,963.4814960629922,0.00025370340306410486,25.0,90.0
719.80713,0.1484134527559055,963.2852230971129,0.00025370340306410486,25.0,90.0
721.1084,0.1488826279527559,964.3082939632545,0.00025370340306410486,25.0,90.0
722.40967,0.14936727952755904,964.1644619422573,0.00025370340306410486,25.0,90.0
723.71094,0.14980093897637795,962.7493963254593,0.00025370340306410486,25.0,90.0
725.01221,0.1503081653543307,964.2037270341207,0.00025370340306410486,25.0,90.0
726.31348,0.15075355708661417,963.0204461942257,0.00025370340306410486,25.0,90.0
727.61475,0.15122987795275591,963.9123622047244,0.00025370340306410486,25.0,90.0
728.91602,0.15168273228346457,964.0070078740157,0.00025370340306410486,25.0,90.0
730.21729,0.1521811003937008,964.6045406824147,0.00025370340306410486,25.0,90.0
731.51855,0.15270449606299213,966.8653805774278,0.00025370340306410486,25.0,90.0
732.81982,0.1532836692913386,964.6314435695539,0.00025370340306410486,25.0,90.0
734.12109,0.1537787283464567,964.3719422572178,0.00025370340306410486,25.0,90.0
735.42236,0.15425678543307086,964.211154855643,0.00025370340306410486,25.0,90.0
736.72363,0.15477424212598423,964.8537532808399,0.00025370340306410486,25.0,90.0
738.0249,0.15524105905511812,964.4046719160106,0.00025370340306410486,25.0,90.0
739.32617,0.1557332440944882,965.4799999999999,0.00025370340306410486,25.0,90.0
740.62744,0.15625098228346457,964.9145669291339,0.00025370340306410486,25.0,90.0
741.92871,0.15666230314960627,963.2264566929134,0.00025370340306410486,25.0,90.0
743.22998,0.1571245433070866,964.2916535433071,0.00025370340306410486,25.0,90.0
744.53125,0.15753513385826773,966.7480577427822,0.00025370340306410486,25.0,90.0
745.83252,0.15803833661417324,963.0159580052493,0.00025370340306410486,25.0,90.0
747.13379,0.15852371456692915,964.3412335958005,0.00025370340306410486,25.0,90.0
748.43506,0.15910394488188975,964.8398950131233,0.00025370340306410486,25.0,90.0
749.73633,0.15966066141732285,964.6877165354331,0.00025370340306410486,25.0,90.0
751.0376,0.16023977755905514,964.9544881889764,0.00025370340306410486,25.0,90.0
752.33887,0.1606911062992126,962.8769816272966,0.00025370340306410486,25.0,90.0
753.64014,0.161136124015748,964.9893963254592,0.00025370340306410486,25.0,90.0
754.94141,0.16165171456692912,966.6378215223098,0.00025370340306410486,25.0,90.0
756.24268,0.16218677362204725,963.5405249343831,0.00025370340306410486,25.0,90.0
757.54395,0.16273349212598423,965.559842519685,0.00025370340306410486,25.0,90.0
758.84521,0.16323476968503936,965.3811811023622,0.00025370340306410486,25.0,90.0
760.14648,0.16389794291338583,964.530341207349,0.00025370340306410486,25.0,90.0
761.44775,0.16445792125984252,965.3590026246719,0.00025370340306410486,25.0,90.0
762.74902,0.1650355472440945,964.0108398950131,0.00025370340306410486,25.0,90.0
764.05029,0.165597344488189,965.4476377952756,0.00025370340306410486,25.0,90.0
765.35156,0.16618520078740157,966.3268503937007,0.00025370340306410486,25.0,90.0
766.65283,0.16667893307086612,964.1818110236221,0.00025370340306410486,25.0,90.0
767.9541,0.16728052952755906,966.2500262467191,0.00025370340306410486,25.0,90.0
769.25537,0.16787865354330708,964.4067979002625,0.00025370340306410486,25.0,90.0
770.55664,0.1683675157480315,962.8374278215223,0.00025370340306410486,25.0,90.0
771.85791,0.16887136417322834,964.2256430446195,0.00025370340306410486,25.0,90.0
773.15918,0.16934663976377953,966.270341207349,0.00025370340306410486,25.0,90.0
774.46045,0.16989217519685038,965.2807086614173,0.00025370340306410486,25.0,90.0
775.76172,0.170431468503937,963.3651968503938,0.00025370340306410486,25.0,90.0
777.06299,0.17096200787401575,965.4279002624671,0.00025370340306410486,25.0,90.0
778.36426,0.17141835826771654,963.5639632545931,0.00025370340306410486,25.0,90.0
779.36523,0.17196641732283463,967.9593963254592,0.00025370340306410486,25.0,90.0