File: datasets/am_bench_2022/csv/90-XY.07-2.csv
Time(s),Strain(%),Stress(MPa),SR(s-1),Temp(C),Angle(deg)
23.087891,3.4595614173228343e-06,15.532604161234811,0.00025370340306410486,25.0,90.0
24.38916,1.7799508858267714e-05,19.610547530896387,0.00025370340306410486,25.0,90.0
25.69043,6.045413779527559e-05,22.61145747510038,0.00025370340306410486,25.0,90.0
26.991699,7.642030511811024e-05,27.467487093914585,0.00025370340306410486,25.0,90.0
28.292969,7.69551220472441e-05,31.599825311571152,0.00025370340306410486,25.0,90.0
29.594238,8.429469685039369e-05,36.8617875580122,0.00025370340306410486,25.0,90.0
30.895508,0.00012307837992125986,42.56605047713407,0.00025370340306410486,25.0,90.0
32.196777,0.0001419095905511811,47.07635709443604,0.00025370340306410486,25.0,90.0
33.498047,0.0001520353622047244,51.981300516243415,0.00025370340306410486,25.0,90.0
34.799316,0.00018005198228346456,58.13697658653595,0.00025370340306410486,25.0,90.0
36.100586,0.0002302657874015748,63.76281222297544,0.00025370340306410486,25.0,90.0
37.401855,0.0002457227755905512,71.2735907597643,0.00025370340306410486,25.0,90.0
38.703125,0.0002848750787401575,76.3156515617667,0.00025370340306410486,25.0,90.0
40.004395,0.0003137409251968504,85.70059967669604,0.00025370340306410486,25.0,90.0
41.305664,0.0003263657086614173,91.44842780414038,0.00025370340306410486,25.0,90.0
42.606934,0.00036017795275590546,99.39896751316682,0.00025370340306410486,25.0,90.0
43.908203,0.00038177196850393703,108.44364081973197,0.00025370340306410486,25.0,90.0
45.209473,0.0004175145669291338,113.7466365959222,0.00025370340306410486,25.0,90.0
46.510742,0.0004442211614173229,121.79165667205505,0.00025370340306410486,25.0,90.0
47.812012,0.00047195765748031494,128.2723184022527,0.00025370340306410486,25.0,90.0
49.113281,0.00048068954724409446,137.10454450644002,0.00025370340306410486,25.0,90.0
50.414551,0.0005446294291338583,146.90829900401522,0.00025370340306410486,25.0,90.0
51.71582,0.000579083779527559,153.7171377170569,0.00025370340306410486,25.0,90.0
53.01709,0.0006078600787401575,160.97584085101946,0.00025370340306410486,25.0,90.0
54.318359,0.0006194854330708662,168.76686916618868,0.00025370340306410486,25.0,90.0
55.619629,0.0006695074409448819,179.40368670803565,0.00025370340306410486,25.0,90.0
56.920898,0.0006999785236220472,185.85162173436927,0.00025370340306410486,25.0,90.0
58.222168,0.0007491162795275591,196.3549069197476,0.00025370340306410486,25.0,90.0
59.523438,0.0007656315748031496,205.67364551285394,0.00025370340306410486,25.0,90.0
60.824707,0.0008113589763779528,217.14600823903635,0.00025370340306410486,25.0,90.0
62.125977,0.000831155531496063,223.8286515096209,0.00025370340306410486,25.0,90.0
63.427246,0.0008842257086614173,235.21770610627314,0.00025370340306410486,25.0,90.0
64.728516,0.0009258327165354331,243.9292929029567,0.00025370340306410486,25.0,90.0
66.029785,0.0009638178543307087,255.09237367680035,0.00025370340306410486,25.0,90.0
67.331055,0.0009929377165354331,261.85409605256297,0.00025370340306410486,25.0,90.0
68.632324,0.0010418747834645668,273.4571882984826,0.00025370340306410486,25.0,90.0
69.933594,0.001056247401574803,281.3375919069719,0.00025370340306410486,25.0,90.0
71.234863,0.0011075682283464567,292.23053658027845,0.00025370340306410486,25.0,90.0
72.536133,0.0011485917913385826,299.94190957918346,0.00025370340306410486,25.0,90.0
73.837402,0.0011624426377952754,308.1762006570371,0.00025370340306410486,25.0,90.0
75.138672,0.0011988243503937008,317.8697137195599,0.00025370340306410486,25.0,90.0
76.439941,0.0012370578937007874,327.9387026125046,0.00025370340306410486,25.0,90.0
77.741211,0.001277653937007874,336.30494863638734,0.00025370340306410486,25.0,90.0
79.04248,0.0013205351968503937,345.57540282630237,0.00025370340306410486,25.0,90.0
80.34375,0.0013446155708661416,354.8833237732701,0.00025370340306410486,25.0,90.0
81.64502,0.0013707774803149604,364.0870313396256,0.00025370340306410486,25.0,90.0
82.946289,0.0014333845472440944,376.2774156541691,0.00025370340306410486,25.0,90.0
84.247559,0.0014833031692913386,387.650909944204,0.00025370340306410486,25.0,90.0
85.548828,0.0015217867716535434,393.9510090212234,0.00025370340306410486,25.0,90.0
86.850098,0.001537487342519685,402.1464514783334,0.00025370340306410486,25.0,90.0
88.151367,0.0015868904330708661,414.53042707409924,0.00025370340306410486,25.0,90.0
89.452637,0.0016322847047244094,422.2429212076967,0.00025370340306410486,25.0,90.0
90.753906,0.0016651748818897639,433.68503937007875,0.00025370340306410486,25.0,90.0
92.055176,0.0016976021456692914,443.7104343745111,0.00025370340306410486,25.0,90.0
93.356445,0.001753530255905512,454.8356364394848,0.00025370340306410486,25.0,90.0
94.657715,0.0017788277755905512,460.8937268603014,0.00025370340306410486,25.0,90.0
95.958984,0.0018203273622047244,470.4348959691297,0.00025370340306410486,25.0,90.0
97.260254,0.001845896377952756,477.57430776450957,0.00025370340306410486,25.0,90.0
98.561523,0.0018923858661417325,485.07939197997604,0.00025370340306410486,25.0,90.0
99.862793,0.001919795905511811,494.0602023257027,0.00025370340306410486,25.0,90.0
101.16406,0.001956578937007874,505.92631798508626,0.00025370340306410486,25.0,90.0
102.46533,0.001984196062992126,512.8096156854565,0.00025370340306410486,25.0,90.0
103.7666,0.0020246795275590548,524.2510820253428,0.00025370340306410486,25.0,90.0
105.06787,0.00207101968503937,531.5775147311884,0.00025370340306410486,25.0,90.0
106.36914,0.0020883562992125983,538.8731031965376,0.00025370340306410486,25.0,90.0
107.67041,0.0021226413385826773,546.4630286280441,0.00025370340306410486,25.0,90.0
108.97168,0.002161427362204724,552.2744433435887,0.00025370340306410486,25.0,90.0
110.27295,0.0021972883858267715,560.658627522553,0.00025370340306410486,25.0,90.0
111.57422,0.002204594291338583,566.6769046253324,0.00025370340306410486,25.0,90.0
112.87549,0.00224568405511811,574.2538457527246,0.00025370340306410486,25.0,90.0
114.17676,0.0022846015748031498,581.887286854044,0.00025370340306410486,25.0,90.0
115.47803,0.0023100425196850394,590.0612973874954,0.00025370340306410486,25.0,90.0
116.7793,0.002348679527559055,596.9808624915264,0.00025370340306410486,25.0,90.0
118.08057,0.00237156968503937,600.4950982948324,0.00025370340306410486,25.0,90.0
119.38184,0.002413492716535433,607.5941231683788,0.00025370340306410486,25.0,90.0
120.68311,0.0024486391732283464,614.3164728581112,0.00025370340306410486,25.0,90.0
121.98438,0.0024593846456692913,619.5518589977578,0.00025370340306410486,25.0,90.0
123.28564,0.00250463031496063,625.4141419408667,0.00025370340306410486,25.0,90.0
124.58691,0.0025339035433070865,629.380455754289,0.00025370340306410486,25.0,90.0
125.88818,0.0025653192913385825,637.318480471398,0.00025370340306410486,25.0,90.0
127.18945,0.0026111482283464565,640.4534077280075,0.00025370340306410486,25.0,90.0
128.49072,0.0026392267716535433,645.5396047348386,0.00025370340306410486,25.0,90.0
129.79199,0.0026610588582677164,649.4108828283883,0.00025370340306410486,25.0,90.0
131.09326,0.0027121043307086613,655.2682379934296,0.00025370340306410486,25.0,90.0
132.39453,0.00272933031496063,657.7629973405642,0.00025370340306410486,25.0,90.0
133.6958,0.0027917460629921257,665.5173906241853,0.00025370340306410486,25.0,90.0
134.99707,0.00280209842519685,666.2310319653751,0.00025370340306410486,25.0,90.0
136.29834,0.002841531496062992,671.4357303019242,0.00025370340306410486,25.0,90.0
137.59961,0.002878177755905512,675.1604265526412,0.00025370340306410486,25.0,90.0
138.90088,0.0028932659448818896,677.9698075819994,0.00025370340306410486,25.0,90.0
140.20215,0.0029685472440944883,683.6714814621682,0.00025370340306410486,25.0,90.0
141.50342,0.003011040748031496,687.3235907597643,0.00025370340306410486,25.0,90.0
142.80469,0.0030418393700787404,688.9642279814361,0.00025370340306410486,25.0,90.0
144.10596,0.003089434251968504,693.4531469990093,0.00025370340306410486,25.0,90.0
145.40723,0.0031355872047244093,696.3916149554153,0.00025370340306410486,25.0,90.0
146.7085,0.0031812120078740153,699.7485008082599,0.00025370340306410486,25.0,90.0
148.00977,0.0032402417322834644,703.9391458518016,0.00025370340306410486,25.0,90.0
149.31104,0.003300086220472441,705.6147729050425,0.00025370340306410486,25.0,90.0
150.6123,0.0033255706692913384,708.4984616989102,0.00025370340306410486,25.0,90.0
151.91357,0.003405394291338583,711.0581425666162,0.00025370340306410486,25.0,90.0
153.21484,0.003471625590551181,715.4934557021431,0.00025370340306410486,25.0,90.0
154.51611,0.003522429133858268,718.3123272670387,0.00025370340306410486,25.0,90.0
155.81738,0.003609425393700787,723.1348751108098,0.00025370340306410486,25.0,90.0
157.11865,0.0036821131889763783,725.6761485112374,0.00025370340306410486,25.0,90.0
158.41992,0.0037622501968503936,728.2237836992231,0.00025370340306410486,25.0,90.0
159.72119,0.0038195490157480316,729.5114720759243,0.00025370340306410486,25.0,90.0
161.02246,0.00392249094488189,735.6205871617041,0.00025370340306410486,25.0,90.0
162.32373,0.004006278346456693,737.184387547583,0.00025370340306410486,25.0,90.0
163.625,0.004115354133858268,739.5623142305888,0.00025370340306410486,25.0,90.0
164.92627,0.004208881692913386,741.1476508317255,0.00025370340306410486,25.0,90.0
166.22754,0.004303893503937008,742.0404651405329,0.00025370340306410486,25.0,90.0
167.52881,0.004427197047244095,746.6238462741826,0.00025370340306410486,25.0,90.0
168.83008,0.004549034448818897,750.4745007039684,0.00025370340306410486,25.0,90.0
170.13135,0.0046736297244094486,750.685899775773,0.00025370340306410486,25.0,90.0
171.43262,0.0048004031496062995,753.7742869061898,0.00025370340306410486,25.0,90.0
172.73389,0.004964013188976378,756.8231996662669,0.00025370340306410486,25.0,90.0
174.03516,0.00510668188976378,756.98182718882,0.00025370340306410486,25.0,90.0
175.33643,0.0052567718503937,758.6288261980498,0.00025370340306410486,25.0,90.0
176.6377,0.005394863188976378,760.6212911299995,0.00025370340306410486,25.0,90.0
177.93896,0.0055526976377952755,764.8623350889086,0.00025370340306410486,25.0,90.0
179.24023,0.005747571062992126,766.0842936851437,0.00025370340306410486,25.0,90.0
180.5415,0.0059150933070866146,767.8652291807895,0.00025370340306410486,25.0,90.0
181.84277,0.006139580118110236,769.9858163424935,0.00025370340306410486,25.0,90.0
183.14404,0.006271113385826772,770.6993273191845,0.00025370340306410486,25.0,90.0
184.44531,0.006449042913385827,773.8691401157637,0.00025370340306410486,25.0,90.0
185.74658,0.006668113385826771,775.259842519685,0.00025370340306410486,25.0,90.0
187.04785,0.006884214763779527,776.2560358763102,0.00025370340306410486,25.0,90.0
188.34912,0.0071211688976377955,777.1541429837827,0.00025370340306410486,25.0,90.0
189.65039,0.007308379330708661,778.8873389998436,0.00025370340306410486,25.0,90.0
190.95166,0.007555138779527558,779.016817020389,0.00025370340306410486,25.0,90.0
192.25293,0.007766368700787401,781.7326224122647,0.00025370340306410486,25.0,90.0
193.5542,0.007968989173228348,784.5545705793398,0.00025370340306410486,25.0,90.0
194.85547,0.008222122047244094,783.9565886217865,0.00025370340306410486,25.0,90.0
196.15674,0.008386846456692913,784.2040725869531,0.00025370340306410486,25.0,90.0
197.45801,0.008660415551181102,787.484382333003,0.00025370340306410486,25.0,90.0
198.75928,0.008858292913385827,787.7660478698441,0.00025370340306410486,25.0,90.0
200.06055,0.009100142716535432,788.8944569014966,0.00025370340306410486,25.0,90.0
201.36182,0.009328282283464566,789.0465401261928,0.00025370340306410486,25.0,90.0
202.66309,0.009582577362204723,793.720446368045,0.00025370340306410486,25.0,90.0
203.96436,0.009823594881889764,793.2427647702978,0.00025370340306410486,25.0,90.0
205.26563,0.010084124015748031,794.6175105595245,0.00025370340306410486,25.0,90.0
206.56689,0.010321012007874017,794.707409918131,0.00025370340306410486,25.0,90.0
207.86816,0.010607517716535434,796.7983261198311,0.00025370340306410486,25.0,90.0
209.16943,0.010867193897637796,796.9099702768942,0.00025370340306410486,25.0,90.0
210.4707,0.011123027559055119,798.6970068310999,0.00025370340306410486,25.0,90.0
211.77197,0.011365526377952757,799.9686343015071,0.00025370340306410486,25.0,90.0
213.07324,0.01162755216535433,799.2306930176775,0.00025370340306410486,25.0,90.0
214.37451,0.011833405118110237,801.5589768994108,0.00025370340306410486,25.0,90.0
215.67578,0.012059504527559056,801.6254888668718,0.00025370340306410486,25.0,90.0
216.97705,0.012262838779527559,802.8329509308026,0.00025370340306410486,25.0,90.0
218.27832,0.012550896062992124,807.3589977577307,0.00025370340306410486,25.0,90.0
219.57959,0.012826865354330707,805.5873702873234,0.00025370340306410486,25.0,90.0
220.88086,0.013093710433070865,806.4940553788392,0.00025370340306410486,25.0,90.0
222.18213,0.013351934645669292,807.4617249830527,0.00025370340306410486,25.0,90.0
223.4834,0.013630181692913385,808.8053397298848,0.00025370340306410486,25.0,90.0
224.78467,0.013873469488188976,808.2614851123742,0.00025370340306410486,25.0,90.0
226.08594,0.014118015748031496,810.9840433853053,0.00025370340306410486,25.0,90.0
227.38721,0.014362780511811023,809.8860875006518,0.00025370340306410486,25.0,90.0
228.68848,0.01462589311023622,812.3111279136466,0.00025370340306410486,25.0,90.0
229.98975,0.014919167322834645,813.8129790895343,0.00025370340306410486,25.0,90.0
231.29102,0.015241388779527559,815.527141888721,0.00025370340306410486,25.0,90.0
232.59229,0.015516885629921259,814.9998174897013,0.00025370340306410486,25.0,90.0
233.89355,0.01581838779527559,816.6682744954894,0.00025370340306410486,25.0,90.0
235.19482,0.01604794350393701,816.1762788757367,0.00025370340306410486,25.0,90.0
236.49609,0.016301505118110238,817.12728789696,0.00025370340306410486,25.0,90.0
237.79736,0.01654258562992126,818.7905824685822,0.00025370340306410486,25.0,90.0
239.09863,0.01683121496062992,819.6392292850811,0.00025370340306410486,25.0,90.0
240.3999,0.017066754527559055,819.2842988997236,0.00025370340306410486,25.0,90.0
241.70117,0.01733934311023622,819.5236220472441,0.00025370340306410486,25.0,90.0
243.00244,0.017621935826771653,821.8382958752672,0.00025370340306410486,25.0,90.0
244.30371,0.017914203937007874,822.3770141315117,0.00025370340306410486,25.0,90.0
245.60498,0.018205836811023623,823.8033842623977,0.00025370340306410486,25.0,90.0
246.90625,0.018475110826771654,824.7585128017938,0.00025370340306410486,25.0,90.0
248.20752,0.01870354586614173,823.1872555665641,0.00025370340306410486,25.0,90.0
249.50879,0.018980056299212598,825.1838660895864,0.00025370340306410486,25.0,90.0
250.81006,0.019261339173228347,826.3444751525266,0.00025370340306410486,25.0,90.0
252.11133,0.019529857874015746,827.0144965323043,0.00025370340306410486,25.0,90.0
253.4126,0.019828767716535432,828.3432757991344,0.00025370340306410486,25.0,90.0
254.71387,0.02011437992125984,828.2556969286123,0.00025370340306410486,25.0,90.0
256.01514,0.02038368503937008,830.0037023517756,0.00025370340306410486,25.0,90.0
257.31641,0.02073080905511811,831.7507170047453,0.00025370340306410486,25.0,90.0
258.61768,0.02101732086614173,831.3480992856025,0.00025370340306410486,25.0,90.0
259.91895,0.021235673228346456,831.5561088804297,0.00025370340306410486,25.0,90.0
261.22021,0.02151822834645669,832.9828701048132,0.00025370340306410486,25.0,90.0
262.52148,0.021806753937007876,833.9741617562705,0.00025370340306410486,25.0,90.0
263.82275,0.022073391732283464,834.9817489701205,0.00025370340306410486,25.0,90.0
265.12402,0.02236995275590551,835.2728528966992,0.00025370340306410486,25.0,90.0
266.42529,0.02259884645669291,835.2111644157063,0.00025370340306410486,25.0,90.0
267.72656,0.022921759842519686,836.3058872607811,0.00025370340306410486,25.0,90.0
269.02783,0.02322379724409449,837.2130416644939,0.00025370340306410486,25.0,90.0
270.3291,0.02349994488188976,839.381368305783,0.00025370340306410486,25.0,90.0
271.63037,0.023774372047244093,838.167726964593,0.00025370340306410486,25.0,90.0
272.93164,0.024073496062992125,838.5205715179642,0.00025370340306410486,25.0,90.0
274.23291,0.02434180708661417,839.8709912916514,0.00025370340306410486,25.0,90.0
275.53418,0.024597350393700788,840.057125723523,0.00025370340306410486,25.0,90.0
276.83545,0.024877090551181102,842.1099233456745,0.00025370340306410486,25.0,90.0
278.13672,0.025162301181102364,843.8863743025499,0.00025370340306410486,25.0,90.0
279.43799,0.02544752559055118,843.7141888720864,0.00025370340306410486,25.0,90.0
280.73926,0.0257265,843.1681702038901,0.00025370340306410486,25.0,90.0
282.04053,0.02603628937007874,844.5832246962507,0.00025370340306410486,25.0,90.0
283.3418,0.026337372047244092,844.2338739114565,0.00025370340306410486,25.0,90.0
284.64307,0.02665225196850394,845.9697293632998,0.00025370340306410486,25.0,90.0
285.94434,0.026935409448818896,845.9702508212964,0.00025370340306410486,25.0,90.0
287.24561,0.027194464566929134,845.625306356573,0.00025370340306410486,25.0,90.0
288.54688,0.027459850393700785,846.4246753923971,0.00025370340306410486,25.0,90.0
289.84814,0.027665358267716534,846.2167179433696,0.00025370340306410486,25.0,90.0
291.14941,0.027929551181102363,849.0264379204256,0.00025370340306410486,25.0,90.0
292.45068,0.02824474409448819,850.2003441622778,0.00025370340306410486,25.0,90.0
293.75195,0.028519933070866144,848.5686760181468,0.00025370340306410486,25.0,90.0
295.05322,0.028839872047244097,850.5183553214789,0.00025370340306410486,25.0,90.0
296.35449,0.029125417322834645,850.7000312874798,0.00025370340306410486,25.0,90.0
297.65576,0.029495185039370077,853.7180215883611,0.00025370340306410486,25.0,90.0
298.95703,0.02974910433070866,852.5893518277103,0.00025370340306410486,25.0,90.0
300.2583,0.03000251377952756,851.788340199197,0.00025370340306410486,25.0,90.0
301.55957,0.0302777874015748,851.4134118996715,0.00025370340306410486,25.0,90.0
302.86084,0.030552460629921258,853.0885435678157,0.00025370340306410486,25.0,90.0
304.16211,0.030852956692913387,855.1369348698962,0.00025370340306410486,25.0,90.0
305.46338,0.03114116535433071,855.9078583720081,0.00025370340306410486,25.0,90.0
306.76465,0.03144547244094488,856.7099650623143,0.00025370340306410486,25.0,90.0
308.06592,0.03170803346456692,856.3586588100329,0.00025370340306410486,25.0,90.0
309.36719,0.03199558267716535,857.3926057256089,0.00025370340306410486,25.0,90.0
310.66846,0.032329062992125984,857.5897429212077,0.00025370340306410486,25.0,90.0
311.96973,0.03262041732283465,858.8241382906607,0.00025370340306410486,25.0,90.0
313.271,0.03289762204724409,858.4823747197164,0.00025370340306410486,25.0,90.0
314.57227,0.03315564763779527,858.0982687594515,0.00025370340306410486,25.0,90.0
315.87354,0.03342632086614173,858.5046409761694,0.00025370340306410486,25.0,90.0
317.1748,0.03369368503937008,861.2853939615163,0.00025370340306410486,25.0,90.0
318.47607,0.034021712598425194,863.4238671325024,0.00025370340306410486,25.0,90.0
319.77734,0.03428987992125984,861.101684309329,0.00025370340306410486,25.0,90.0
321.07861,0.03460296062992126,863.2864368775096,0.00025370340306410486,25.0,90.0
322.37988,0.03486536220472441,862.1643374876154,0.00025370340306410486,25.0,90.0
323.68115,0.035136761811023626,865.4624810971477,0.00025370340306410486,25.0,90.0
324.98242,0.035430996062992125,865.0093862439381,0.00025370340306410486,25.0,90.0
326.28369,0.035708366141732284,863.3622047244095,0.00025370340306410486,25.0,90.0
327.58496,0.0359843248031496,865.2530635657298,0.00025370340306410486,25.0,90.0
328.88623,0.036282653543307085,866.8261980497471,0.00025370340306410486,25.0,90.0
330.1875,0.03660287204724409,868.0697710799395,0.00025370340306410486,25.0,90.0
331.48877,0.03687570078740157,865.7312926943735,0.00025370340306410486,25.0,90.0
332.79004,0.037160007874015744,866.9178703655421,0.00025370340306410486,25.0,90.0
334.09131,0.037428937007874016,866.27121030401,0.00025370340306410486,25.0,90.0
335.39258,0.037698523622047245,868.7386973979246,0.00025370340306410486,25.0,90.0
336.69385,0.03796413188976378,869.1404286384733,0.00025370340306410486,25.0,90.0
337.99512,0.03829307677165355,871.556812848725,0.00025370340306410486,25.0,90.0
339.29639,0.03854498031496063,869.358189497836,0.00025370340306410486,25.0,90.0
340.59766,0.03883721653543307,871.3664285341815,0.00025370340306410486,25.0,90.0
341.89893,0.039123198818897635,871.8514105438808,0.00025370340306410486,25.0,90.0
343.2002,0.03944491338582677,872.981227512124,0.00025370340306410486,25.0,90.0
344.50146,0.03976418503937008,872.2979610992335,0.00025370340306410486,25.0,90.0
345.80273,0.040005244094488183,872.2005005996767,0.00025370340306410486,25.0,90.0
347.104,0.04033079724409449,874.5098294832351,0.00025370340306410486,25.0,90.0
348.40527,0.04057955511811023,873.0455754288992,0.00025370340306410486,25.0,90.0
349.70654,0.04088559448818898,875.8091985190592,0.00025370340306410486,25.0,90.0
351.00781,0.041201153543307084,874.6639203212181,0.00025370340306410486,25.0,90.0
352.30908,0.041499261811023626,876.8467174219116,0.00025370340306410486,25.0,90.0
353.61035,0.041781527559055114,875.4717630494864,0.00025370340306410486,25.0,90.0
354.91162,0.04206612401574803,876.1949470720134,0.00025370340306410486,25.0,90.0
356.21289,0.042358055118110235,876.353183501069,0.00025370340306410486,25.0,90.0
357.51416,0.04265733661417323,877.3985242738698,0.00025370340306410486,25.0,90.0
358.81543,0.04295555905511811,878.5393440058402,0.00025370340306410486,25.0,90.0
360.1167,0.04323160433070866,879.6384731709861,0.00025370340306410486,25.0,90.0
361.41797,0.0435024094488189,880.4519737185169,0.00025370340306410486,25.0,90.0
362.71924,0.04374764960629921,879.9098920581947,0.00025370340306410486,25.0,90.0
364.02051,0.044067127952755906,881.3302132763207,0.00025370340306410486,25.0,90.0
365.32178,0.04434080118110236,879.4067111644157,0.00025370340306410486,25.0,90.0
366.62305,0.044606704724409446,878.8243208009595,0.00025370340306410486,25.0,90.0
367.92432,0.04493011023622047,883.2865672420087,0.00025370340306410486,25.0,90.0
369.22559,0.04522319094488189,881.9138029931689,0.00025370340306410486,25.0,90.0
370.52686,0.04546070866141732,881.5988945090473,0.00025370340306410486,25.0,90.0
371.82813,0.045773114173228345,883.5775408040884,0.00025370340306410486,25.0,90.0
373.12939,0.04608124212598425,883.6054909527038,0.00025370340306410486,25.0,90.0
374.43066,0.04634688188976378,884.1018668196277,0.00025370340306410486,25.0,90.0
375.73193,0.04663923622047244,883.59696511446,0.00025370340306410486,25.0,90.0
377.0332,0.04692716141732283,885.7453459873807,0.00025370340306410486,25.0,90.0
378.33447,0.047239374015748035,887.1182666736195,0.00025370340306410486,25.0,90.0
379.63574,0.04748983858267717,884.6359962455024,0.00025370340306410486,25.0,90.0
380.93701,0.047785633858267715,887.0317567919905,0.00025370340306410486,25.0,90.0
382.23828,0.04805806692913386,886.4200865620274,0.00025370340306410486,25.0,90.0
383.53955,0.04840094291338583,889.8139698597279,0.00025370340306410486,25.0,90.0
384.84082,0.04871679527559055,889.0711790165302,0.00025370340306410486,25.0,90.0
386.14209,0.04902757677165354,889.9785680763415,0.00025370340306410486,25.0,90.0
387.44336,0.04935162007874015,891.3290139229285,0.00025370340306410486,25.0,90.0
388.74463,0.049659234251968505,889.428038796475,0.00025370340306410486,25.0,90.0
390.0459,0.049898332677165355,888.8278927882359,0.00025370340306410486,25.0,90.0
391.34717,0.050165616141732275,890.8745111331282,0.00025370340306410486,25.0,90.0
392.64844,0.050446202755905514,890.6450956875424,0.00025370340306410486,25.0,90.0
393.94971,0.05074451377952756,891.7257652396099,0.00025370340306410486,25.0,90.0
395.25098,0.051064824803149604,893.8573030192418,0.00025370340306410486,25.0,90.0
396.55225,0.05136575196850394,892.5020336861866,0.00025370340306410486,25.0,90.0
397.85352,0.05166666141732283,892.6885331386557,0.00025370340306410486,25.0,90.0
399.15479,0.05195046456692914,893.4164363560515,0.00025370340306410486,25.0,90.0
400.45605,0.0522505,894.4645147833342,0.00025370340306410486,25.0,90.0
401.75732,0.05255536811023622,894.517260259686,0.00025370340306410486,25.0,90.0
403.05859,0.05282109055118111,896.4597434426657,0.00025370340306410486,25.0,90.0
404.35986,0.05308920078740157,895.9079365907077,0.00025370340306410486,25.0,90.0
405.66113,0.05340979724409449,896.47726443135,0.00025370340306410486,25.0,90.0
406.9624,0.05372505118110236,897.1228555039892,0.00025370340306410486,25.0,90.0
408.26367,0.05402237007874015,896.9863117275904,0.00025370340306410486,25.0,90.0
409.56494,0.05429112598425197,896.661208739636,0.00025370340306410486,25.0,90.0
410.86621,0.05451344094488189,897.5381967982479,0.00025370340306410486,25.0,90.0
412.16748,0.054812688976377956,898.8285967565313,0.00025370340306410486,25.0,90.0
413.46875,0.05512000590551181,898.3919799760129,0.00025370340306410486,25.0,90.0
414.77002,0.05546243307086614,900.4820096991187,0.00025370340306410486,25.0,90.0
416.07129,0.05576588779527559,899.5721437138238,0.00025370340306410486,25.0,90.0
417.37256,0.05610856889763779,900.8251290608541,0.00025370340306410486,25.0,90.0
418.67383,0.05640156299212598,899.946368045054,0.00025370340306410486,25.0,90.0
419.9751,0.05664947440944882,898.7001355790791,0.00025370340306410486,25.0,90.0
421.27637,0.0569495157480315,901.3062783542786,0.00025370340306410486,25.0,90.0
422.57764,0.0572985374015748,904.1608176461386,0.00025370340306410486,25.0,90.0
423.87891,0.05756853543307087,901.7691244720238,0.00025370340306410486,25.0,90.0
425.18018,0.05784667716535433,902.1172498305262,0.00025370340306410486,25.0,90.0
426.48145,0.05809942125984252,902.4537206028056,0.00025370340306410486,25.0,90.0
427.78271,0.058400931102362205,903.5651822495698,0.00025370340306410486,25.0,90.0
429.08398,0.05868018700787401,901.917427126245,0.00025370340306410486,25.0,90.0
430.38525,0.05894238779527559,902.3014027220107,0.00025370340306410486,25.0,90.0
431.68652,0.05919498622047244,904.8410856755488,0.00025370340306410486,25.0,90.0
432.98779,0.059458765748031495,905.1598529488449,0.00025370340306410486,25.0,90.0
434.28906,0.05979263385826771,906.4455076393597,0.00025370340306410486,25.0,90.0
435.59033,0.06011187007874015,908.2585649475935,0.00025370340306410486,25.0,90.0
436.8916,0.060422952755905514,906.1864212337696,0.00025370340306410486,25.0,90.0
438.19287,0.06067033661417323,906.7304062157793,0.00025370340306410486,25.0,90.0
439.49414,0.06095754724409448,908.4051728633259,0.00025370340306410486,25.0,90.0
440.79541,0.06126899212598425,907.8936486416019,0.00025370340306410486,25.0,90.0
442.09668,0.06154311614173228,908.5468530009908,0.00025370340306410486,25.0,90.0
443.39795,0.061831905511811024,908.9756479115607,0.00025370340306410486,25.0,90.0
444.69922,0.06209346653543307,907.9879803931793,0.00025370340306410486,25.0,90.0
446.00049,0.06242844488188976,909.2129373728945,0.00025370340306410486,25.0,90.0
447.30176,0.06269741535433071,909.8631694217031,0.00025370340306410486,25.0,90.0
448.60303,0.06299702952755905,910.3967773895813,0.00025370340306410486,25.0,90.0
449.9043,0.06335237401574803,911.160009386244,0.00025370340306410486,25.0,90.0
451.20557,0.06367342519685039,911.456510403087,0.00025370340306410486,25.0,90.0
452.50684,0.06394760039370079,911.8446837357251,0.00025370340306410486,25.0,90.0
453.80811,0.06425429330708662,912.6343797257131,0.00025370340306410486,25.0,90.0
455.10938,0.06452293700787402,910.8300829118215,0.00025370340306410486,25.0,90.0
456.41064,0.06484311220472441,912.0992856025448,0.00025370340306410486,25.0,90.0
457.71191,0.06515915157480315,913.2586431662929,0.00025370340306410486,25.0,90.0
459.01318,0.0654566594488189,911.104239453512,0.00025370340306410486,25.0,90.0
460.31445,0.06572102559055118,912.6064295770976,0.00025370340306410486,25.0,90.0
461.61572,0.06603118700787401,912.708348542525,0.00025370340306410486,25.0,90.0
462.91699,0.06634871062992126,913.8177765031027,0.00025370340306410486,25.0,90.0
464.21826,0.06663954724409449,916.0415341294258,0.00025370340306410486,25.0,90.0
465.51953,0.06696009251968504,916.9054075194243,0.00025370340306410486,25.0,90.0
466.8208,0.067238281496063,917.4036867080357,0.00025370340306410486,25.0,90.0
468.12207,0.06752299212598425,915.5568910674245,0.00025370340306410486,25.0,90.0
469.42334,0.06783898031496062,916.9360171038223,0.00025370340306410486,25.0,90.0
470.72461,0.06815903149606299,916.412447202378,0.00025370340306410486,25.0,90.0
472.02588,0.06845427362204724,917.6136778432498,0.00025370340306410486,25.0,90.0
473.32715,0.0687348031496063,916.5884132033166,0.00025370340306410486,25.0,90.0
474.62842,0.06902769881889763,916.678468999322,0.00025370340306410486,25.0,90.0
475.92969,0.06936910039370078,918.3567815612453,0.00025370340306410486,25.0,90.0
477.23096,0.06967097834645669,918.6647546540127,0.00025370340306410486,25.0,90.0
478.53223,0.06996300590551181,918.7302497783803,0.00025370340306410486,25.0,90.0
479.8335,0.0702183779527559,919.1357876623039,0.00025370340306410486,25.0,90.0
481.13477,0.07048553149606299,919.0992595296449,0.00025370340306410486,25.0,90.0
482.43604,0.0707874094488189,919.9447775981645,0.00025370340306410486,25.0,90.0
483.7373,0.07116781692913385,920.8696094279605,0.00025370340306410486,25.0,90.0
485.03857,0.07145780905511812,921.1575846065599,0.00025370340306410486,25.0,90.0
486.33984,0.07175929921259842,921.427725921677,0.00025370340306410486,25.0,90.0
487.64111,0.07210593897637795,922.4617510559524,0.00025370340306410486,25.0,90.0
488.94238,0.07238072440944882,922.7859414924128,0.00025370340306410486,25.0,90.0
490.24365,0.07270023622047245,921.8197319705897,0.00025370340306410486,25.0,90.0
491.54492,0.07300223228346456,923.6173280492256,0.00025370340306410486,25.0,90.0
492.84619,0.07334897637795276,922.8796214214946,0.00025370340306410486,25.0,90.0
494.14746,0.07363808267716535,922.765761067946,0.00025370340306410486,25.0,90.0
495.44873,0.07391783267716535,923.6615737602336,0.00025370340306410486,25.0,90.0
496.75,0.07417733464566928,922.9441779214684,0.00025370340306410486,25.0,90.0
498.05127,0.07448060826771653,925.7299629764823,0.00025370340306410486,25.0,90.0
499.35254,0.0748013188976378,925.3006726808156,0.00025370340306410486,25.0,90.0
500.65381,0.07506370866141733,922.4976534390155,0.00025370340306410486,25.0,90.0
501.95508,0.07533447440944882,923.9650101684309,0.00025370340306410486,25.0,90.0
503.25635,0.0755959842519685,925.12880012515,0.00025370340306410486,25.0,90.0
504.55762,0.07588533070866142,926.5041977368724,0.00025370340306410486,25.0,90.0
505.85889,0.07620949015748031,926.1323199666267,0.00025370340306410486,25.0,90.0
507.16016,0.0764761909448819,927.1955988945091,0.00025370340306410486,25.0,90.0
508.46143,0.07680159448818898,927.9921781300517,0.00025370340306410486,25.0,90.0
509.7627,0.07710952559055119,927.3971424101788,0.00025370340306410486,25.0,90.0
511.06396,0.07741197244094489,927.8702873233561,0.00025370340306410486,25.0,90.0
512.36523,0.0777626535433071,928.97423997497,0.00025370340306410486,25.0,90.0
513.6665,0.07812709251968504,928.9606820670596,0.00025370340306410486,25.0,90.0
514.96777,0.07843294881889763,927.5531626427492,0.00025370340306410486,25.0,90.0
516.26904,0.0787125216535433,927.7756948427804,0.00025370340306410486,25.0,90.0
517.57031,0.0790174842519685,928.7709235021119,0.00025370340306410486,25.0,90.0
518.87158,0.07936059251968504,931.2474578922668,0.00025370340306410486,25.0,90.0
520.17285,0.07967265551181103,930.726521353705,0.00025370340306410486,25.0,90.0
521.47412,0.08004165748031496,931.2686030140272,0.00025370340306410486,25.0,90.0
522.77539,0.08034472637795276,929.0648693747719,0.00025370340306410486,25.0,90.0
524.07666,0.08064547244094489,930.9755436199614,0.00025370340306410486,25.0,90.0
525.37793,0.08092909842519685,932.7233665328258,0.00025370340306410486,25.0,90.0
526.6792,0.08123008464566929,933.3403556343537,0.00025370340306410486,25.0,90.0
527.98047,0.08156988385826772,932.4895708400688,0.00025370340306410486,25.0,90.0
529.28174,0.08189692913385827,933.5222923293529,0.00025370340306410486,25.0,90.0
530.58301,0.08219469291338583,931.6458778745372,0.00025370340306410486,25.0,90.0
531.88428,0.08246077952755905,933.4911091411586,0.00025370340306410486,25.0,90.0
533.18555,0.08279919881889763,932.9944725452366,0.00025370340306410486,25.0,90.0
534.48682,0.08312356496062992,934.140324346874,0.00025370340306410486,25.0,90.0
535.78809,0.08343044488188976,934.1650675288105,0.00025370340306410486,25.0,90.0
537.08936,0.08372182874015748,933.5007821869948,0.00025370340306410486,25.0,90.0
538.39063,0.08405742716535433,934.7895916983887,0.00025370340306410486,25.0,90.0
539.69189,0.08434365157480314,935.7980653908328,0.00025370340306410486,25.0,90.0
540.99316,0.08464106496062991,935.200917766074,0.00025370340306410486,25.0,90.0
542.29443,0.08498699606299212,936.4918391823538,0.00025370340306410486,25.0,90.0
543.5957,0.08532555708661417,934.7823955780362,0.00025370340306410486,25.0,90.0
544.89697,0.08558710826771654,935.6007456849351,0.00025370340306410486,25.0,90.0
546.19824,0.08590826181102362,937.6889242321531,0.00025370340306410486,25.0,90.0
547.49951,0.0862129153543307,936.9320800959483,0.00025370340306410486,25.0,90.0
548.80078,0.08650347047244095,937.0980862491527,0.00025370340306410486,25.0,90.0
550.10205,0.08679686417322835,936.7645877874537,0.00025370340306410486,25.0,90.0
551.40332,0.0871644311023622,939.3671064295771,0.00025370340306410486,25.0,90.0
552.70459,0.08748979133858267,937.3259633936486,0.00025370340306410486,25.0,90.0
554.00586,0.08777562401574802,937.2847942848204,0.00025370340306410486,25.0,90.0
555.30713,0.08810165551181103,938.4998957084007,0.00025370340306410486,25.0,90.0
556.6084,0.08845914763779528,938.8697919382595,0.00025370340306410486,25.0,90.0
557.90967,0.08875268897637795,938.316055691714,0.00025370340306410486,25.0,90.0
559.21094,0.08906666929133858,942.2593992803879,0.00025370340306410486,25.0,90.0
560.51221,0.0893905472440945,940.0340251342755,0.00025370340306410486,25.0,90.0
561.81348,0.08970254921259842,939.9104135161913,0.00025370340306410486,25.0,90.0
563.11475,0.09003542716535433,940.8480992856025,0.00025370340306410486,25.0,90.0
564.41602,0.09034799803149607,940.4190697189341,0.00025370340306410486,25.0,90.0
565.71729,0.09065904527559054,941.6446785211451,0.00025370340306410486,25.0,90.0
567.01855,0.09099826968503937,941.1372216717945,0.00025370340306410486,25.0,90.0
568.31982,0.09125190157480315,939.2952495176513,0.00025370340306410486,25.0,90.0
569.62109,0.09155469881889765,941.0753506805027,0.00025370340306410486,25.0,90.0
570.92236,0.09185234842519685,942.9989310111071,0.00025370340306410486,25.0,90.0
572.22363,0.09223109448818897,943.4235021119049,0.00025370340306410486,25.0,90.0
573.5249,0.09254069291338582,942.0701361005371,0.00025370340306410486,25.0,90.0
574.82617,0.09285883858267717,944.8751368827241,0.00025370340306410486,25.0,90.0
576.12744,0.09317697834645669,943.3572248005424,0.00025370340306410486,25.0,90.0
577.42871,0.09347367519685039,942.8894509047296,0.00025370340306410486,25.0,90.0
578.72998,0.0937681377952756,942.8895030505294,0.00025370340306410486,25.0,90.0
580.03125,0.09406610236220472,943.6136256974501,0.00025370340306410486,25.0,90.0
581.33252,0.09438899409448819,943.632424258226,0.00025370340306410486,25.0,90.0
582.63379,0.0946858090551181,944.1902800229442,0.00025370340306410486,25.0,90.0
583.93506,0.09504578937007874,945.6501277572091,0.00025370340306410486,25.0,90.0
585.23633,0.09536077362204724,945.4307764509568,0.00025370340306410486,25.0,90.0
586.5376,0.09571737401574802,945.7727225322001,0.00025370340306410486,25.0,90.0
587.83887,0.09602619291338584,943.9897794232675,0.00025370340306410486,25.0,90.0
589.14014,0.09633178937007875,944.6712468060698,0.00025370340306410486,25.0,90.0
590.44141,0.09664005511811023,945.9858424153934,0.00025370340306410486,25.0,90.0
591.74268,0.09698568503937008,947.5691192574438,0.00025370340306410486,25.0,90.0
593.04395,0.09734676377952756,947.1717421911665,0.00025370340306410486,25.0,90.0
594.34521,0.0976777283464567,945.426969807582,0.00025370340306410486,25.0,90.0
595.64648,0.09803758464566929,947.4712415914898,0.00025370340306410486,25.0,90.0
596.94775,0.09838044094488188,946.070761850133,0.00025370340306410486,25.0,90.0
598.24902,0.09872862992125984,947.3214527819783,0.00025370340306410486,25.0,90.0
599.55029,0.09906336614173229,948.4038952912343,0.00025370340306410486,25.0,90.0
600.85156,0.09943087204724409,949.0053710173646,0.00025370340306410486,25.0,90.0
602.15283,0.09975744291338583,948.1951817281118,0.00025370340306410486,25.0,90.0
603.4541,0.10009349409448819,947.1405329300725,0.00025370340306410486,25.0,90.0
604.75537,0.10041587401574803,948.2405485738125,0.00025370340306410486,25.0,90.0
606.05664,0.1007062716535433,949.6778693226261,0.00025370340306410486,25.0,90.0
607.35791,0.10106447440944881,950.0821557073577,0.00025370340306410486,25.0,90.0
608.65918,0.10139713385826772,948.6767221150337,0.00025370340306410486,25.0,90.0
609.96045,0.10171180708661419,948.3967773895813,0.00025370340306410486,25.0,90.0
611.26172,0.10199701771653542,948.4264222766857,0.00025370340306410486,25.0,90.0
612.56299,0.10227123425196849,949.4415967043855,0.00025370340306410486,25.0,90.0
613.86426,0.10263282677165356,950.5579079105179,0.00025370340306410486,25.0,90.0
615.16553,0.10294627952755905,949.347264952808,0.00025370340306410486,25.0,90.0
616.4668,0.10326022440944882,950.5764196693956,0.00025370340306410486,25.0,90.0
617.76807,0.1036094625984252,951.1313552693331,0.00025370340306410486,25.0,90.0
619.06934,0.10393730118110235,950.3613964645148,0.00025370340306410486,25.0,90.0
620.37061,0.10425206692913386,951.0304010011994,0.00025370340306410486,25.0,90.0
621.67188,0.10459405511811024,952.1279918652554,0.00025370340306410486,25.0,90.0
622.97314,0.10491982677165354,951.3686186577671,0.00025370340306410486,25.0,90.0
624.27441,0.10522433858267716,950.9161495541534,0.00025370340306410486,25.0,90.0
625.57568,0.10555266929133858,950.8102935808521,0.00025370340306410486,25.0,90.0
626.87695,0.10588289960629922,952.634249361214,0.00025370340306410486,25.0,90.0
628.17822,0.10628449212598425,953.9181571674402,0.00025370340306410486,25.0,90.0
629.47949,0.10665970669291337,952.6604786984408,0.00025370340306410486,25.0,90.0
630.78076,0.10699399803149608,952.225895604109,0.00025370340306410486,25.0,90.0
632.08203,0.10728937007874016,952.0346248109714,0.00025370340306410486,25.0,90.0
633.3833,0.1076149311023622,952.7587474578922,0.00025370340306410486,25.0,90.0
634.68457,0.10795998031496062,954.2773635083695,0.00025370340306410486,25.0,90.0
635.98584,0.10827532283464568,952.97575220316,0.00025370340306410486,25.0,90.0
637.28711,0.10858958464566928,953.0019293945873,0.00025370340306410486,25.0,90.0
638.58838,0.10894076968503937,954.4884497053762,0.00025370340306410486,25.0,90.0
639.88965,0.10930893503937007,955.7572091568024,0.00025370340306410486,25.0,90.0
641.19092,0.10970081102362206,954.2624758825677,0.00025370340306410486,25.0,90.0
642.49219,0.11003979527559056,953.9851384470982,0.00025370340306410486,25.0,90.0
643.79346,0.11038316732283464,953.2843510455233,0.00025370340306410486,25.0,90.0
645.09473,0.11069794488188976,952.6103665849715,0.00025370340306410486,25.0,90.0
646.396,0.11097459055118111,954.058637951713,0.00025370340306410486,25.0,90.0
647.69727,0.11131271850393701,954.9109871199875,0.00025370340306410486,25.0,90.0
648.99854,0.1116206437007874,953.7370548052354,0.00025370340306410486,25.0,90.0
650.2998,0.11196002755905511,955.6233508890858,0.00025370340306410486,25.0,90.0
651.60107,0.11225192519685039,954.1871773478647,0.00025370340306410486,25.0,90.0
652.90234,0.11265499606299213,956.9891797465714,0.00025370340306410486,25.0,90.0
654.20361,0.11303962204724409,955.4157063148564,0.00025370340306410486,25.0,90.0
655.50488,0.1134108720472441,957.017573134484,0.00025370340306410486,25.0,90.0
656.80615,0.11379893700787402,958.2512645356417,0.00025370340306410486,25.0,90.0
658.10742,0.11422420669291339,956.978489857642,0.00025370340306410486,25.0,90.0
659.40869,0.11461684645669293,957.0229702247484,0.00025370340306410486,25.0,90.0
660.70996,0.11499573425196849,958.322417479272,0.00025370340306410486,25.0,90.0
662.01123,0.11533673622047245,957.3998018459613,0.00025370340306410486,25.0,90.0
663.3125,0.11564496653543307,957.6472336653283,0.00025370340306410486,25.0,90.0
664.61377,0.11602255314960629,957.6623298743286,0.00025370340306410486,25.0,90.0
665.91504,0.11636092716535433,957.1795640611149,0.00025370340306410486,25.0,90.0
667.21631,0.11673073425196849,957.8521927308755,0.00025370340306410486,25.0,90.0
668.51758,0.1170838562992126,958.7240183553215,0.00025370340306410486,25.0,90.0
669.81885,0.11742503346456692,957.9741096104709,0.00025370340306410486,25.0,90.0
671.12012,0.11775393897637797,959.4186786254367,0.00025370340306410486,25.0,90.0
672.42139,0.1181110964566929,959.0911769306983,0.00025370340306410486,25.0,90.0
673.72266,0.11843541535433069,958.7376284090317,0.00025370340306410486,25.0,90.0
675.02393,0.11875838188976377,958.9261876205871,0.00025370340306410486,25.0,90.0
676.3252,0.11906901968503937,958.7002137977786,0.00025370340306410486,25.0,90.0
677.62646,0.11937915157480315,958.7951712989518,0.00025370340306410486,25.0,90.0
678.92773,0.11974960236220472,959.7414089795068,0.00025370340306410486,25.0,90.0
680.229,0.12012614566929133,959.2125723522971,0.00025370340306410486,25.0,90.0
681.53027,0.1205087874015748,958.1364916305992,0.00025370340306410486,25.0,90.0
682.83154,0.12089867125984252,960.8532617197685,0.00025370340306410486,25.0,90.0
684.13281,0.12127132874015747,959.6364394847994,0.00025370340306410486,25.0,90.0
685.43408,0.12162859251968504,960.2235229702247,0.00025370340306410486,25.0,90.0
686.73535,0.12199962007874017,959.528341242113,0.00025370340306410486,25.0,90.0
688.03662,0.12234188976377952,959.8247379673568,0.00025370340306410486,25.0,90.0
689.33789,0.12267193307086613,958.2186734108567,0.00025370340306410486,25.0,90.0
690.63916,0.12299769291338583,960.0552224018355,0.00025370340306410486,25.0,90.0
691.94043,0.12340151377952756,961.5832507691506,0.00025370340306410486,25.0,90.0
693.2417,0.1237140748031496,959.1669187046983,0.00025370340306410486,25.0,90.0
694.54297,0.12411143110236221,960.9229545810085,0.00025370340306410486,25.0,90.0
695.84424,0.12452531889763781,960.9540334776034,0.00025370340306410486,25.0,90.0
697.14551,0.12491355905511811,961.2316837878709,0.00025370340306410486,25.0,90.0
698.44678,0.1252731594488189,961.0414298378266,0.00025370340306410486,25.0,90.0
699.74805,0.1256749035433071,961.8498983156907,0.00025370340306410486,25.0,90.0
701.04932,0.12605708858267717,961.5084476195442,0.00025370340306410486,25.0,90.0
702.35059,0.12640232677165356,961.044089273609,0.00025370340306410486,25.0,90.0
703.65186,0.12678092125984253,962.0876570892215,0.00025370340306410486,25.0,90.0
704.95313,0.1271401338582677,961.2129112999947,0.00025370340306410486,25.0,90.0
706.25439,0.12754858858267715,963.3467956406112,0.00025370340306410486,25.0,90.0
707.55566,0.1279281929133858,961.5887782239141,0.00025370340306410486,25.0,90.0
708.85693,0.1282775374015748,961.4262658392867,0.00025370340306410486,25.0,90.0
710.1582,0.1286295216535433,962.3824894404755,0.00025370340306410486,25.0,90.0
711.45947,0.12896395275590553,960.6380560045889,0.00025370340306410486,25.0,90.0
712.76074,0.12933438188976376,962.3373572508734,0.00025370340306410486,25.0,90.0
714.06201,0.12974248622047244,962.0838243729468,0.00025370340306410486,25.0,90.0
715.36328,0.13012582086614174,963.1671012149972,0.00025370340306410486,25.0,90.0
716.66455,0.1304566279527559,960.4640193982375,0.00025370340306410486,25.0,90.0
717.96582,0.13073513779527557,959.7731657714971,0.00025370340306410486,25.0,90.0
719.26709,0.13105224015748032,963.0058664024614,0.00025370340306410486,25.0,90.0
720.56836,0.13142036811023622,964.1262449809668,0.00025370340306410486,25.0,90.0
721.86963,0.13180066535433071,963.4098138394952,0.00025370340306410486,25.0,90.0
723.1709,0.1321501850393701,963.1391510663817,0.00025370340306410486,25.0,90.0
724.47217,0.13253412992125985,964.8938572248006,0.00025370340306410486,25.0,90.0
725.77344,0.13293255511811022,963.8014809407102,0.00025370340306410486,25.0,90.0
727.07471,0.13333609448818898,963.7552797622152,0.00025370340306410486,25.0,90.0
728.37598,0.1336993307086614,964.1652761120092,0.00025370340306410486,25.0,90.0
729.67725,0.13406337795275589,964.0533712259478,0.00025370340306410486,25.0,90.0
730.97852,0.13440740551181102,963.526359701726,0.00025370340306410486,25.0,90.0
732.27979,0.1347835964566929,964.2039682953538,0.00025370340306410486,25.0,90.0
733.58105,0.13517939173228347,964.4068415289148,0.00025370340306410486,25.0,90.0
734.88232,0.13561184251968503,963.879256400897,0.00025370340306410486,25.0,90.0
736.18359,0.1360356692913386,965.0971736976587,0.00025370340306410486,25.0,90.0
737.48486,0.1364325787401575,962.7371069510351,0.00025370340306410486,25.0,90.0
738.78613,0.13679124015748031,963.6658236429056,0.00025370340306410486,25.0,90.0
740.0874,0.1371321003937008,963.3347760337905,0.00025370340306410486,25.0,90.0
741.38867,0.13748144488188976,964.00453668457,0.00025370340306410486,25.0,90.0
742.68994,0.13789890157480314,964.9563800385879,0.00025370340306410486,25.0,90.0
743.99121,0.13829560039370078,962.2200552745476,0.00025370340306410486,25.0,90.0
745.29248,0.13866324803149607,965.5782186994838,0.00025370340306410486,25.0,90.0
746.59375,0.1390131437007874,964.4665484695207,0.00025370340306410486,25.0,90.0
747.89502,0.1394359153543307,964.494237889138,0.00025370340306410486,25.0,90.0
749.19629,0.13980755118110236,963.666527611201,0.00025370340306410486,25.0,90.0
750.49756,0.14021403740157481,965.0764196693956,0.00025370340306410486,25.0,90.0
751.79883,0.14058862992125984,963.953798821505,0.00025370340306410486,25.0,90.0
753.1001,0.1409291751968504,963.842102518642,0.00025370340306410486,25.0,90.0
754.40137,0.14133034448818896,966.2485529540596,0.00025370340306410486,25.0,90.0
755.70264,0.14169771062992126,963.9986181363091,0.00025370340306410486,25.0,90.0
757.00391,0.1420601850393701,964.042733482818,0.00025370340306410486,25.0,90.0
758.30518,0.14243573031496062,964.4577619022788,0.00025370340306410486,25.0,90.0
759.60645,0.1428128818897638,964.7706888460135,0.00025370340306410486,25.0,90.0
760.90771,0.14319898622047245,964.6277832820567,0.00025370340306410486,25.0,90.0
762.20898,0.14364064763779527,965.5757939197998,0.00025370340306410486,25.0,90.0
763.51025,0.1440130472440945,963.2583824372947,0.00025370340306410486,25.0,90.0
764.81152,0.14438023622047244,964.8013766491109,0.00025370340306410486,25.0,90.0
766.11279,0.14480754921259842,965.0391093497419,0.00025370340306410486,25.0,90.0
767.41406,0.14527964566929133,966.4667570527193,0.00025370340306410486,25.0,90.0
768.71533,0.14570330708661416,965.6345361631121,0.00025370340306410486,25.0,90.0
770.0166,0.14613825787401574,965.2699848777181,0.00025370340306410486,25.0,90.0
771.31787,0.146634031496063,966.9153412942587,0.00025370340306410486,25.0,90.0
772.61914,0.14704553937007875,966.7843249726235,0.00025370340306410486,25.0,90.0
773.92041,0.14740522047244095,963.298039317933,0.00025370340306410486,25.0,90.0
775.22168,0.1477456594488189,963.7811180059447,0.00025370340306410486,25.0,90.0
776.52295,0.14813811023622048,966.2420608020024,0.00025370340306410486,25.0,90.0
777.82422,0.14852483661417323,964.7249309068155,0.00025370340306410486,25.0,90.0
779.12549,0.14893745866141733,965.9489231892371,0.00025370340306410486,25.0,90.0
780.42676,0.1493656850393701,965.4445950878657,0.00025370340306410486,25.0,90.0
781.72803,0.14972114173228346,964.5301402722012,0.00025370340306410486,25.0,90.0
783.0293,0.15011254921259842,966.5244303071388,0.00025370340306410486,25.0,90.0
784.33057,0.15050616338582676,965.1519267872973,0.00025370340306410486,25.0,90.0
785.63184,0.15095175393700788,966.0956614694686,0.00025370340306410486,25.0,90.0
786.93311,0.1513956929133858,965.879543202795,0.00025370340306410486,25.0,90.0
788.23438,0.15180981496062992,965.0160869791938,0.00025370340306410486,25.0,90.0
789.53564,0.15222073622047244,965.4470720133494,0.00025370340306410486,25.0,90.0
790.83691,0.15262624606299213,964.7995254732232,0.00025370340306410486,25.0,90.0
792.13818,0.15306227559055116,963.8161860562133,0.00025370340306410486,25.0,90.0
793.43945,0.1533716909448819,964.0515721958596,0.00025370340306410486,25.0,90.0
794.74072,0.15371149606299211,964.2857068363144,0.00025370340306410486,25.0,90.0
796.04199,0.15406905511811023,965.0341554987746,0.00025370340306410486,25.0,90.0
797.34326,0.15448243897637795,965.0818428325599,0.00025370340306410486,25.0,90.0
798.64453,0.15485237401574803,963.8900245085259,0.00025370340306410486,25.0,90.0
799.9458,0.1552603838582677,965.0738645252126,0.00025370340306410486,25.0,90.0
801.24707,0.15570265551181103,966.2171090368671,0.00025370340306410486,25.0,90.0
802.54834,0.1561963188976378,965.7358293789435,0.00025370340306410486,25.0,90.0
803.84961,0.15657135826771654,964.8871825624447,0.00025370340306410486,25.0,90.0
805.15088,0.15693831299212596,964.2671690045368,0.00025370340306410486,25.0,90.0
806.45215,0.15738578346456694,967.2346300255514,0.00025370340306410486,25.0,90.0
806.95264,0.15756399803149607,968.2611200917767,0.00025370340306410486,25.0,90.0