File: datasets/am_bench_2022/csv/90-XY.17-3.csv
Time(s),Strain(%),Stress(MPa),SR(s-1),Temp(C),Angle(deg)
11.768799,1.311895255905512e-05,14.731554466287742,0.00025370340306410486,25.0,90.0
13.170166,1.7651560629921262e-05,18.256866298169683,0.00025370340306410486,25.0,90.0
14.471436,1.1627443700787402e-05,21.1297726443135,0.00025370340306410486,25.0,90.0
15.772705,2.440792125984252e-05,24.88388668717735,0.00025370340306410486,25.0,90.0
17.073975,4.27496968503937e-05,27.951947645617146,0.00025370340306410486,25.0,90.0
18.375244,3.372561811023622e-05,32.00775929498879,0.00025370340306410486,25.0,90.0
19.676514,5.34933622047244e-05,34.466770089169316,0.00025370340306410486,25.0,90.0
20.977783,7.580913582677166e-05,39.5798638994629,0.00025370340306410486,25.0,90.0
22.279053,8.506794685039371e-05,43.71398289617771,0.00025370340306410486,25.0,90.0
23.580322,0.00010881735433070865,48.980067268081555,0.00025370340306410486,25.0,90.0
24.881592,0.00012283443503937008,55.56012671429317,0.00025370340306410486,25.0,90.0
26.182861,0.00015777036417322833,60.803592845596285,0.00025370340306410486,25.0,90.0
27.484131,0.00016403244291338584,68.18499243885906,0.00025370340306410486,25.0,90.0
28.7854,0.00017261910433070865,73.98567294154456,0.00025370340306410486,25.0,90.0
30.08667,0.00018760256889763778,80.07797622151537,0.00025370340306410486,25.0,90.0
31.387939,0.00022769303149606298,88.18096156854565,0.00025370340306410486,25.0,90.0
32.689209,0.00024247966535433072,93.68088856442613,0.00025370340306410486,25.0,90.0
33.990479,0.00028037844488188975,99.87683944308286,0.00025370340306410486,25.0,90.0
35.291748,0.00030185145669291337,106.33198101892893,0.00025370340306410486,25.0,90.0
36.593018,0.00033480222440944885,113.81945820514159,0.00025370340306410486,25.0,90.0
37.894287,0.00035370118110236216,122.6149397716014,0.00025370340306410486,25.0,90.0
39.195557,0.000382767874015748,129.41503624133077,0.00025370340306410486,25.0,90.0
40.496826,0.00039920976377952756,136.39996871252023,0.00025370340306410486,25.0,90.0
41.798096,0.00044452149606299214,146.23131615998332,0.00025370340306410486,25.0,90.0
43.099365,0.00048303901574803145,153.79976273661157,0.00025370340306410486,25.0,90.0
44.400635,0.00047109665354330704,163.8157089221463,0.00025370340306410486,25.0,90.0
45.701904,0.0005313799803149606,171.53655942013873,0.00025370340306410486,25.0,90.0
47.003174,0.0005401997637795276,180.16372216717946,0.00025370340306410486,25.0,90.0
48.304443,0.0005940507874015748,188.47576263231997,0.00025370340306410486,25.0,90.0
49.605713,0.0006118083464566929,197.54979923867134,0.00025370340306410486,25.0,90.0
50.906982,0.0006493723622047244,207.11242895134797,0.00025370340306410486,25.0,90.0
52.208252,0.0006939833070866142,214.5094853209574,0.00025370340306410486,25.0,90.0
53.509521,0.0007382722440944882,226.68728163946395,0.00025370340306410486,25.0,90.0
54.810791,0.0007776068700787402,234.44150284194606,0.00025370340306410486,25.0,90.0
56.112061,0.0008037607086614172,242.69625593158472,0.00025370340306410486,25.0,90.0
57.41333,0.0008447086614173228,252.16846482765814,0.00025370340306410486,25.0,90.0
58.7146,0.0008819258070866142,261.46036919226157,0.00025370340306410486,25.0,90.0
60.015869,0.0008869731102362204,269.8999322104604,0.00025370340306410486,25.0,90.0
61.317139,0.0009405716338582678,279.72401835532145,0.00025370340306410486,25.0,90.0
62.618408,0.0009909967913385828,290.2666996923398,0.00025370340306410486,25.0,90.0
63.919678,0.0010386914173228345,298.26190227877146,0.00025370340306410486,25.0,90.0
65.220947,0.001066746594488189,307.94146633988635,0.00025370340306410486,25.0,90.0
66.522217,0.0010919761811023622,315.0943317515774,0.00025370340306410486,25.0,90.0
67.823486,0.001130300098425197,326.5326171976847,0.00025370340306410486,25.0,90.0
69.124756,0.0011781463385826772,337.5782708452834,0.00025370340306410486,25.0,90.0
70.426025,0.0012391659448818897,347.37088700005216,0.00025370340306410486,25.0,90.0
71.727295,0.001246479940944882,356.68691661886635,0.00025370340306410486,25.0,90.0
73.028564,0.0012959273818897638,364.9305157219586,0.00025370340306410486,25.0,90.0
74.329834,0.0013414377952755904,374.7268603014027,0.00025370340306410486,25.0,90.0
75.631104,0.0013950805118110236,384.81204046514057,0.00025370340306410486,25.0,90.0
76.932373,0.0014144443307086614,393.54010011993535,0.00025370340306410486,25.0,90.0
78.233643,0.0014555606692913386,402.1923658549304,0.00025370340306410486,25.0,90.0
79.534912,0.0014839047637795276,410.8785785055014,0.00025370340306410486,25.0,90.0
80.836182,0.0015363570275590552,421.87151274964805,0.00025370340306410486,25.0,90.0
82.137451,0.001591532559055118,429.9235021119049,0.00025370340306410486,25.0,90.0
83.438721,0.0016249100196850394,441.1120352505606,0.00025370340306410486,25.0,90.0
84.73999,0.0016423682874015747,447.9243103717996,0.00025370340306410486,25.0,90.0
86.04126,0.0016986304527559057,457.74200865620276,0.00025370340306410486,25.0,90.0
87.342529,0.0017111697440944883,466.0031026750795,0.00025370340306410486,25.0,90.0
88.643799,0.0017656708267716535,476.89367471450174,0.00025370340306410486,25.0,90.0
89.945068,0.001785354901574803,483.47833342024296,0.00025370340306410486,25.0,90.0
91.246338,0.0018181867716535432,492.1878291703604,0.00025370340306410486,25.0,90.0
92.547607,0.0018649685039370078,501.42517077749386,0.00025370340306410486,25.0,90.0
93.848877,0.001917307007874016,509.8252333524535,0.00025370340306410486,25.0,90.0
95.150146,0.0019300043307086613,520.7263127705064,0.00025370340306410486,25.0,90.0
96.451416,0.0019807498031496062,528.5091776607395,0.00025370340306410486,25.0,90.0
97.752686,0.001987696850393701,533.6765396047349,0.00025370340306410486,25.0,90.0
99.053955,0.0020194576771653543,540.9863117275904,0.00025370340306410486,25.0,90.0
100.35522,0.002049407086614173,548.589847212807,0.00025370340306410486,25.0,90.0
101.65649,0.0020888681102362206,558.1528654116911,0.00025370340306410486,25.0,90.0
102.95776,0.0021131911417322834,564.6318767273297,0.00025370340306410486,25.0,90.0
104.25903,0.002154488976377953,570.7336653282579,0.00025370340306410486,25.0,90.0
105.5603,0.0021720950787401574,578.6446524482453,0.00025370340306410486,25.0,90.0
106.86157,0.002192036023622047,584.256505188507,0.00025370340306410486,25.0,90.0
108.16284,0.002235353937007874,590.7709235021119,0.00025370340306410486,25.0,90.0
109.46411,0.0022644820866141733,596.9381550816082,0.00025370340306410486,25.0,90.0
110.76538,0.0022947409448818897,603.3113104239453,0.00025370340306410486,25.0,90.0
112.06665,0.002319196062992126,609.835897168483,0.00025370340306410486,25.0,90.0
113.36792,0.0023284757874015745,614.4476716900454,0.00025370340306410486,25.0,90.0
114.66919,0.0023671271653543306,620.9735881524743,0.00025370340306410486,25.0,90.0
115.97046,0.0023907029527559056,623.9122646920791,0.00025370340306410486,25.0,90.0
117.27173,0.0024360438976377954,631.8010377014132,0.00025370340306410486,25.0,90.0
118.573,0.002445305905511811,633.2768159774731,0.00025370340306410486,25.0,90.0
119.87427,0.0024953759842519683,641.9187307712364,0.00025370340306410486,25.0,90.0
121.17554,0.0025250100393700787,645.2576002502998,0.00025370340306410486,25.0,90.0
122.47681,0.002548534251968504,648.5343640819732,0.00025370340306410486,25.0,90.0
123.77808,0.0025661295275590554,653.2459456640768,0.00025370340306410486,25.0,90.0
125.07935,0.0026019464566929135,657.920920894822,0.00025370340306410486,25.0,90.0
126.38062,0.002638026968503937,661.8481514314022,0.00025370340306410486,25.0,90.0
127.68188,0.0026532708661417322,664.6006413933359,0.00025370340306410486,25.0,90.0
128.98315,0.0026805681102362203,668.6260885435678,0.00025370340306410486,25.0,90.0
130.28442,0.0027173090551181104,672.7890180945925,0.00025370340306410486,25.0,90.0
131.58569,0.0027630501968503936,678.4082494655056,0.00025370340306410486,25.0,90.0
132.88696,0.0027925009842519684,680.5366845700579,0.00025370340306410486,25.0,90.0
134.18823,0.0028260807086614172,685.0634614381812,0.00025370340306410486,25.0,90.0
135.4895,0.0028729374015748032,688.1056473901028,0.00025370340306410486,25.0,90.0
136.79077,0.0028882937007874017,691.5033894769776,0.00025370340306410486,25.0,90.0
138.09204,0.002944756496062992,696.8785263597017,0.00025370340306410486,25.0,90.0
139.39331,0.002962486614173228,697.5687281639464,0.00025370340306410486,25.0,90.0
140.69458,0.0030218897637795277,702.1274182614591,0.00025370340306410486,25.0,90.0
141.99585,0.0030601082677165353,706.4208426761224,0.00025370340306410486,25.0,90.0
143.29712,0.003117095866141732,708.6875162955624,0.00025370340306410486,25.0,90.0
144.59839,0.0031538629921259846,711.4385461751057,0.00025370340306410486,25.0,90.0
145.89966,0.003200047834645669,715.0921937737916,0.00025370340306410486,25.0,90.0
147.20093,0.003239509842519685,716.8749022266256,0.00025370340306410486,25.0,90.0
148.5022,0.0033280541338582678,720.9662877405226,0.00025370340306410486,25.0,90.0
149.80347,0.0033530275590551183,721.8220003128748,0.00025370340306410486,25.0,90.0
151.10474,0.003414228149606299,726.018798560776,0.00025370340306410486,25.0,90.0
152.40601,0.003484488779527559,729.0894300464098,0.00025370340306410486,25.0,90.0
153.70728,0.0035349133858267713,731.5265161391251,0.00025370340306410486,25.0,90.0
155.00854,0.0036068127952755906,732.9444125775669,0.00025370340306410486,25.0,90.0
156.30981,0.0036821807086614175,736.4355477916254,0.00025370340306410486,25.0,90.0
157.61108,0.0037381458661417326,737.9587265995724,0.00025370340306410486,25.0,90.0
158.91235,0.0038230035433070866,741.2855764718151,0.00025370340306410486,25.0,90.0
160.21362,0.0039329173228346455,745.2692809094227,0.00025370340306410486,25.0,90.0
161.51489,0.004007203543307086,746.6972414871982,0.00025370340306410486,25.0,90.0
162.81616,0.004100208070866142,750.2129373728947,0.00025370340306410486,25.0,90.0
164.11743,0.0041894299212598424,752.0357459456641,0.00025370340306410486,25.0,90.0
165.4187,0.004332510039370079,753.2948323512541,0.00025370340306410486,25.0,90.0
166.71997,0.004425064173228347,757.17273296136,0.00025370340306410486,25.0,90.0
168.02124,0.004530806496062992,757.5362674036606,0.00025370340306410486,25.0,90.0
169.32251,0.004668151377952756,761.2797882880534,0.00025370340306410486,25.0,90.0
170.62378,0.004784542519685039,763.7188298482557,0.00025370340306410486,25.0,90.0
171.92505,0.0049114072834645665,764.922876362309,0.00025370340306410486,25.0,90.0
173.22632,0.005048192125984252,764.528654116911,0.00025370340306410486,25.0,90.0
174.52759,0.00519716968503937,769.1055952443031,0.00025370340306410486,25.0,90.0
175.82886,0.005367386811023622,770.8995932627627,0.00025370340306410486,25.0,90.0
177.13013,0.005510437401574803,770.5894561193096,0.00025370340306410486,25.0,90.0
178.4314,0.005692607283464567,773.8763101632163,0.00025370340306410486,25.0,90.0
179.73267,0.005883242519685039,773.9675392397143,0.00025370340306410486,25.0,90.0
181.03394,0.006034351377952755,775.3664806799812,0.00025370340306410486,25.0,90.0
182.33521,0.006251537992125984,777.8047661260886,0.00025370340306410486,25.0,90.0
183.63647,0.0064308366141732284,781.253193930229,0.00025370340306410486,25.0,90.0
184.93774,0.006646494291338583,782.8699483756584,0.00025370340306410486,25.0,90.0
186.23901,0.006893783070866141,784.6920008343328,0.00025370340306410486,25.0,90.0
187.54028,0.007103391535433072,783.2916514574752,0.00025370340306410486,25.0,90.0
188.84155,0.0072851425196850395,786.5160869791938,0.00025370340306410486,25.0,90.0
190.14282,0.007486442322834646,790.076211086197,0.00025370340306410486,25.0,90.0
191.44409,0.007698011811023622,788.5930020336862,0.00025370340306410486,25.0,90.0
192.74536,0.007893412795275589,789.7884966365959,0.00025370340306410486,25.0,90.0
194.04663,0.008150006102362205,792.468790738906,0.00025370340306410486,25.0,90.0
195.3479,0.008381711023622047,792.6084632632841,0.00025370340306410486,25.0,90.0
196.64917,0.008574403149606299,795.9686603744069,0.00025370340306410486,25.0,90.0
197.95044,0.008802608661417322,795.343171507535,0.00025370340306410486,25.0,90.0
199.25171,0.009057902559055118,797.5952703759713,0.00025370340306410486,25.0,90.0
200.55298,0.009311723228346456,796.9139072847682,0.00025370340306410486,25.0,90.0
201.85425,0.009542406692913386,798.8779266830057,0.00025370340306410486,25.0,90.0
203.15552,0.009779742125984252,800.1398028888774,0.00025370340306410486,25.0,90.0
204.45679,0.010016603740157481,800.4545027898004,0.00025370340306410486,25.0,90.0
205.75806,0.010264407480314961,803.5914637325964,0.00025370340306410486,25.0,90.0
207.05933,0.01051810059055118,803.6161026229337,0.00025370340306410486,25.0,90.0
208.3606,0.010737930118110237,805.1322938937268,0.00025370340306410486,25.0,90.0
209.66187,0.011062099212598426,807.2496219429524,0.00025370340306410486,25.0,90.0
210.96313,0.011311423031496062,806.5398133180372,0.00025370340306410486,25.0,90.0
212.2644,0.011555226377952756,807.7075663555302,0.00025370340306410486,25.0,90.0
213.56567,0.011801263582677165,807.6495802263128,0.00025370340306410486,25.0,90.0
214.86694,0.012021599803149605,809.7912342910779,0.00025370340306410486,25.0,90.0
216.16821,0.012314241929133857,811.5363195494604,0.00025370340306410486,25.0,90.0
217.46948,0.012551638188976377,811.5684674349482,0.00025370340306410486,25.0,90.0
218.77075,0.012820516141732283,813.030609584398,0.00025370340306410486,25.0,90.0
220.07202,0.013089526181102361,813.5076915054492,0.00025370340306410486,25.0,90.0
221.37329,0.013366727362204725,814.2707409918131,0.00025370340306410486,25.0,90.0
222.67456,0.013646967322834647,816.7923293528706,0.00025370340306410486,25.0,90.0
223.97583,0.013914280511811023,816.6958335506075,0.00025370340306410486,25.0,90.0
225.2771,0.014138870078740156,817.0636439484799,0.00025370340306410486,25.0,90.0
226.57837,0.014380578346456691,817.0675288105543,0.00025370340306410486,25.0,90.0
227.87964,0.014577385039370078,818.490144443865,0.00025370340306410486,25.0,90.0
229.18091,0.014829345275590551,822.8366532825781,0.00025370340306410486,25.0,90.0
230.48218,0.015119457283464567,821.2921468425719,0.00025370340306410486,25.0,90.0
231.78345,0.015392549015748032,820.8159514001147,0.00025370340306410486,25.0,90.0
233.08472,0.015689660039370078,824.1137039161496,0.00025370340306410486,25.0,90.0
234.38599,0.016016674409448817,825.2189862856546,0.00025370340306410486,25.0,90.0
235.68726,0.016292065748031496,824.7426083328987,0.00025370340306410486,25.0,90.0
236.98853,0.016558265748031497,827.7623715909683,0.00025370340306410486,25.0,90.0
238.28979,0.016862196456692912,825.4676956771132,0.00025370340306410486,25.0,90.0
239.59106,0.017117340748031496,826.8052093653857,0.00025370340306410486,25.0,90.0
240.89233,0.017399012401574803,828.380142879491,0.00025370340306410486,25.0,90.0
242.1936,0.017619322244094487,828.5264118475257,0.00025370340306410486,25.0,90.0
243.49487,0.017889599409448818,830.7064712937373,0.00025370340306410486,25.0,90.0
244.79614,0.018141324803149606,831.4616467643531,0.00025370340306410486,25.0,90.0
246.09741,0.018427600196850392,832.2579131250977,0.00025370340306410486,25.0,90.0
247.39868,0.018743754133858266,832.6600876049434,0.00025370340306410486,25.0,90.0
248.69995,0.019025535629921257,834.1735412212547,0.00025370340306410486,25.0,90.0
250.00122,0.019281935433070867,833.6307555926371,0.00025370340306410486,25.0,90.0
251.30249,0.019548732086614173,836.7140585075872,0.00025370340306410486,25.0,90.0
252.60376,0.019852982283464566,836.5786619387809,0.00025370340306410486,25.0,90.0
253.90503,0.020145785433070863,838.0366063513584,0.00025370340306410486,25.0,90.0
255.2063,0.02040448031496063,838.8324033999061,0.00025370340306410486,25.0,90.0
256.50757,0.02069483464566929,838.7506648589457,0.00025370340306410486,25.0,90.0
257.80884,0.020977570866141732,838.8843406163634,0.00025370340306410486,25.0,90.0
259.11011,0.021239931102362206,838.6318245815299,0.00025370340306410486,25.0,90.0
260.41138,0.021523061023622045,841.1932262606247,0.00025370340306410486,25.0,90.0
261.71265,0.021828391732283466,841.0422902435209,0.00025370340306410486,25.0,90.0
263.01392,0.022108224409448818,841.6219950982949,0.00025370340306410486,25.0,90.0
264.31519,0.022382527559055117,842.2945716222558,0.00025370340306410486,25.0,90.0
265.61646,0.022622492125984252,841.8975074307765,0.00025370340306410486,25.0,90.0
266.91772,0.02287830708661417,843.4905094644627,0.00025370340306410486,25.0,90.0
268.21899,0.023109728346456693,843.4173228346457,0.00025370340306410486,25.0,90.0
269.52026,0.02341437401574803,845.9956979715284,0.00025370340306410486,25.0,90.0
270.82153,0.023719001968503937,847.5666423319601,0.00025370340306410486,25.0,90.0
272.1228,0.023964805118110236,845.0548313083382,0.00025370340306410486,25.0,90.0
273.42407,0.024204102362204723,846.128487250352,0.00025370340306410486,25.0,90.0
274.72534,0.024481919291338583,848.0574646712207,0.00025370340306410486,25.0,90.0
276.02661,0.024781437007874014,848.9215205715179,0.00025370340306410486,25.0,90.0
277.32788,0.025078982283464567,850.4892840381708,0.00025370340306410486,25.0,90.0
278.62915,0.025353437007874017,850.4089273609011,0.00025370340306410486,25.0,90.0
279.93042,0.025630791338582676,850.7534285863273,0.00025370340306410486,25.0,90.0
281.23169,0.025969405511811025,853.5192157271731,0.00025370340306410486,25.0,90.0
282.53296,0.026280253937007874,853.7011524221724,0.00025370340306410486,25.0,90.0
283.83423,0.026568714566929132,852.1645982166136,0.00025370340306410486,25.0,90.0
285.1355,0.02686583464566929,854.0657037075663,0.00025370340306410486,25.0,90.0
286.43677,0.027147088582677167,852.6010846326329,0.00025370340306410486,25.0,90.0
287.73804,0.02737500787401575,855.5298795432028,0.00025370340306410486,25.0,90.0
289.03931,0.02762969291338583,854.151822495698,0.00025370340306410486,25.0,90.0
290.34058,0.02789420866141732,854.898185326172,0.00025370340306410486,25.0,90.0
291.64185,0.02817982874015748,856.714997131981,0.00025370340306410486,25.0,90.0
292.94312,0.02849591535433071,857.260911508578,0.00025370340306410486,25.0,90.0
294.24438,0.02877450590551181,857.6062992125984,0.00025370340306410486,25.0,90.0
295.54565,0.029083588582677164,859.4553371225948,0.00025370340306410486,25.0,90.0
296.84692,0.029372232283464562,859.8659592219847,0.00025370340306410486,25.0,90.0
298.14819,0.029603409448818896,857.8611618084163,0.00025370340306410486,25.0,90.0
299.44946,0.029842265748031494,858.2242008656203,0.00025370340306410486,25.0,90.0
300.75073,0.030103742125984254,859.9114042863848,0.00025370340306410486,25.0,90.0
302.052,0.03037495866141732,862.2639098920582,0.00025370340306410486,25.0,90.0
303.35327,0.030684194881889764,863.9217813005163,0.00025370340306410486,25.0,90.0
304.65454,0.031026708661417324,863.9157845335558,0.00025370340306410486,25.0,90.0
305.95581,0.03135699212598425,864.2519685039371,0.00025370340306410486,25.0,90.0
307.25708,0.031612787401574804,863.4767169004538,0.00025370340306410486,25.0,90.0
308.55835,0.031873486220472445,864.6842311101841,0.00025370340306410486,25.0,90.0
309.85962,0.032207314960629924,865.261067945977,0.00025370340306410486,25.0,90.0
311.16089,0.03245825196850394,865.5754028263024,0.00025370340306410486,25.0,90.0
312.46216,0.03273002165354331,863.9525212494134,0.00025370340306410486,25.0,90.0
313.76343,0.03295901968503937,867.8599624550243,0.00025370340306410486,25.0,90.0
315.0647,0.033224232283464564,868.0513114668614,0.00025370340306410486,25.0,90.0
316.36597,0.03356030708661417,869.0988684361475,0.00025370340306410486,25.0,90.0
317.66724,0.03390546850393701,870.0711268707306,0.00025370340306410486,25.0,90.0
318.96851,0.034187080708661416,870.5429942118162,0.00025370340306410486,25.0,90.0
320.26978,0.034467372047244094,870.8945090472962,0.00025370340306410486,25.0,90.0
321.57104,0.034774185039370076,871.0547270167389,0.00025370340306410486,25.0,90.0
322.87231,0.03502006102362205,870.6039787245138,0.00025370340306410486,25.0,90.0
324.17358,0.03535112992125984,873.0374406841529,0.00025370340306410486,25.0,90.0
325.47485,0.03562976181102362,872.9416227772854,0.00025370340306410486,25.0,90.0
326.77612,0.03593077362204724,871.7351254106483,0.00025370340306410486,25.0,90.0
328.07739,0.03619057677165354,873.1923658549304,0.00025370340306410486,25.0,90.0
329.37866,0.03643882086614173,874.0124889190176,0.00025370340306410486,25.0,90.0
330.67993,0.036752614173228344,874.7469364342702,0.00025370340306410486,25.0,90.0
331.9812,0.03704233070866141,875.8160035459143,0.00025370340306410486,25.0,90.0
333.28247,0.03729077755905512,874.633493247119,0.00025370340306410486,25.0,90.0
334.58374,0.037573133858267715,877.7129895186943,0.00025370340306410486,25.0,90.0
335.88501,0.037841041338582675,876.8712780935496,0.00025370340306410486,25.0,90.0
337.18628,0.0381174468503937,878.7001355790791,0.00025370340306410486,25.0,90.0
338.48755,0.03841293503937008,878.5592115555093,0.00025370340306410486,25.0,90.0
339.78882,0.03872179724409449,878.8599103092247,0.00025370340306410486,25.0,90.0
341.09009,0.03902806299212599,878.4247796839965,0.00025370340306410486,25.0,90.0
342.39136,0.03935752165354331,880.6617041247328,0.00025370340306410486,25.0,90.0
343.69263,0.039633998031496066,878.7052197945457,0.00025370340306410486,25.0,90.0
344.9939,0.03993100590551181,880.8560515200501,0.00025370340306410486,25.0,90.0
346.29517,0.040213881889763776,881.0674505918548,0.00025370340306410486,25.0,90.0
347.59644,0.040456978346456694,879.4818793346196,0.00025370340306410486,25.0,90.0
348.89771,0.040751269685039365,883.1048912760077,0.00025370340306410486,25.0,90.0
350.19897,0.041082167322834644,885.2064452208375,0.00025370340306410486,25.0,90.0
351.50024,0.04141357086614173,884.8485946706993,0.00025370340306410486,25.0,90.0
352.80151,0.041720661417322835,883.536215257861,0.00025370340306410486,25.0,90.0
354.10278,0.04201193503937008,883.6916097408355,0.00025370340306410486,25.0,90.0
355.40405,0.042339789370078734,887.5453929186004,0.00025370340306410486,25.0,90.0
356.70532,0.042576639763779525,884.8091203003598,0.00025370340306410486,25.0,90.0
358.00659,0.04281783858267716,885.3406945820514,0.00025370340306410486,25.0,90.0
359.30786,0.04305411811023622,887.344240496428,0.00025370340306410486,25.0,90.0
360.60913,0.04334771456692913,888.6090368670804,0.00025370340306410486,25.0,90.0
361.9104,0.043694683070866144,889.3856442613547,0.00025370340306410486,25.0,90.0
363.21167,0.04398625590551181,887.7864368775095,0.00025370340306410486,25.0,90.0
364.51294,0.0442796062992126,889.3734682171352,0.00025370340306410486,25.0,90.0
365.81421,0.04455113385826772,889.2202638577463,0.00025370340306410486,25.0,90.0
367.11548,0.04485011417322835,890.8088856442614,0.00025370340306410486,25.0,90.0
368.41675,0.0451073720472441,891.3453094853211,0.00025370340306410486,25.0,90.0
369.71802,0.045405944881889766,891.2926683005685,0.00025370340306410486,25.0,90.0
371.01929,0.045679765748031495,892.9390154873025,0.00025370340306410486,25.0,90.0
372.32056,0.04600591929133858,893.3767794754133,0.00025370340306410486,25.0,90.0
373.62183,0.04631620866141732,891.9530687803098,0.00025370340306410486,25.0,90.0
374.9231,0.04662765157480315,893.9042081660323,0.00025370340306410486,25.0,90.0
376.22437,0.04693548622047244,894.8063305000783,0.00025370340306410486,25.0,90.0
377.52563,0.04721957677165354,892.844996610523,0.00025370340306410486,25.0,90.0
378.8269,0.04748879527559055,895.3193148041926,0.00025370340306410486,25.0,90.0
380.12817,0.0478041594488189,895.216822234969,0.00025370340306410486,25.0,90.0
381.42944,0.048063826771653544,894.3724513740418,0.00025370340306410486,25.0,90.0
382.73071,0.04833020078740157,895.7957188298483,0.00025370340306410486,25.0,90.0
384.03198,0.04861182677165354,896.1424362517599,0.00025370340306410486,25.0,90.0
385.33325,0.048876553149606296,896.5299577619023,0.00025370340306410486,25.0,90.0
386.63452,0.049186527559055115,897.7591385513898,0.00025370340306410486,25.0,90.0
387.93579,0.049493309055118104,897.095922198467,0.00025370340306410486,25.0,90.0
389.23706,0.04976422834645669,898.7238097721229,0.00025370340306410486,25.0,90.0
390.53833,0.05005246653543307,897.8167335871096,0.00025370340306410486,25.0,90.0
391.8396,0.05030054133858268,899.7264952808052,0.00025370340306410486,25.0,90.0
393.14087,0.05061449212598425,899.8133962559316,0.00025370340306410486,25.0,90.0
394.44214,0.05096678740157481,900.5847629973406,0.00025370340306410486,25.0,90.0
395.74341,0.051303108267716536,902.3227824998696,0.00025370340306410486,25.0,90.0
397.04468,0.05163225393700787,900.8004901705167,0.00025370340306410486,25.0,90.0
398.34595,0.0519380846456693,900.5903686708036,0.00025370340306410486,25.0,90.0
399.64722,0.052233649606299205,902.6367784324973,0.00025370340306410486,25.0,90.0
400.94849,0.05246526968503937,902.0176252802837,0.00025370340306410486,25.0,90.0
402.24976,0.052736031496062985,901.7978307347344,0.00025370340306410486,25.0,90.0
403.55103,0.0530246437007874,905.0916983886948,0.00025370340306410486,25.0,90.0
404.85229,0.05329754724409449,904.0811649371644,0.00025370340306410486,25.0,90.0
406.15356,0.053607297244094486,906.1300776972414,0.00025370340306410486,25.0,90.0
407.45483,0.05388276968503937,904.5653908327685,0.00025370340306410486,25.0,90.0
408.7561,0.054188588582677166,907.3302914950201,0.00025370340306410486,25.0,90.0
410.05737,0.05448765551181102,905.6542733482819,0.00025370340306410486,25.0,90.0
411.35864,0.05479095866141732,907.3287010481306,0.00025370340306410486,25.0,90.0
412.65991,0.05510761417322835,907.4066068728164,0.00025370340306410486,25.0,90.0
413.96118,0.055371336614173226,906.4845909162018,0.00025370340306410486,25.0,90.0
415.26245,0.055646379921259835,908.4477499087449,0.00025370340306410486,25.0,90.0
416.56372,0.055982801181102354,909.4409448818899,0.00025370340306410486,25.0,90.0
417.86499,0.05629144881889763,909.8485946706993,0.00025370340306410486,25.0,90.0
419.16626,0.05653461220472441,908.6486416019189,0.00025370340306410486,25.0,90.0
420.46753,0.05682053937007874,909.4723887990823,0.00025370340306410486,25.0,90.0
421.7688,0.05711015551181102,911.3369661573761,0.00025370340306410486,25.0,90.0
423.07007,0.05742492125984252,911.6818584762998,0.00025370340306410486,25.0,90.0
424.37134,0.057742240157480314,912.5676070292538,0.00025370340306410486,25.0,90.0
425.67261,0.05802980905511811,909.081060645565,0.00025370340306410486,25.0,90.0
426.97388,0.05831466141732284,910.5303227824999,0.00025370340306410486,25.0,90.0
428.27515,0.05860005511811024,911.4493142827346,0.00025370340306410486,25.0,90.0
429.57642,0.058937706692913386,914.82121812588,0.00025370340306410486,25.0,90.0
430.87769,0.05922101574803149,912.9432914428743,0.00025370340306410486,25.0,90.0
432.17896,0.059520082677165354,913.432288679147,0.00025370340306410486,25.0,90.0
433.48022,0.05983430511811023,914.3249204776556,0.00025370340306410486,25.0,90.0
434.78149,0.060120007874015745,914.5043541742713,0.00025370340306410486,25.0,90.0
436.08276,0.06043087401574803,915.7881316159983,0.00025370340306410486,25.0,90.0
437.38403,0.060749775590551176,914.3114668613443,0.00025370340306410486,25.0,90.0
438.6853,0.06105318503937008,915.7074099181311,0.00025370340306410486,25.0,90.0
439.98657,0.06136010039370079,917.6756791990405,0.00025370340306410486,25.0,90.0
441.28784,0.061666643700787394,915.6789122386192,0.00025370340306410486,25.0,90.0
442.58911,0.06192521259842519,917.4332273035407,0.00025370340306410486,25.0,90.0
443.89038,0.06218345472440944,917.2616154768733,0.00025370340306410486,25.0,90.0
445.19165,0.062462956692913386,916.3482296501016,0.00025370340306410486,25.0,90.0
446.49292,0.06273963188976378,918.7129895186944,0.00025370340306410486,25.0,90.0
447.79419,0.0630291653543307,918.9173228346457,0.00025370340306410486,25.0,90.0
449.09546,0.06335549606299212,919.7849507222193,0.00025370340306410486,25.0,90.0
450.39673,0.06368805511811024,920.4373468217135,0.00025370340306410486,25.0,90.0
451.698,0.06395198228346458,919.3686968764665,0.00025370340306410486,25.0,90.0
452.99927,0.06430608464566928,922.1085154090839,0.00025370340306410486,25.0,90.0
454.30054,0.06460254133858268,921.7271731762006,0.00025370340306410486,25.0,90.0
455.60181,0.0649231751968504,921.7726703864004,0.00025370340306410486,25.0,90.0
456.90308,0.0652553405511811,921.6087761380821,0.00025370340306410486,25.0,90.0
458.20435,0.06554436417322834,922.0420555874224,0.00025370340306410486,25.0,90.0
459.50562,0.06578176181102362,922.1906971893414,0.00025370340306410486,25.0,90.0
460.80688,0.06607526771653544,924.6818845491996,0.00025370340306410486,25.0,90.0
462.10815,0.06640324606299212,924.6780779058247,0.00025370340306410486,25.0,90.0
463.40942,0.06676048818897637,925.0774886582885,0.00025370340306410486,25.0,90.0
464.71069,0.06707377559055118,924.9442822130678,0.00025370340306410486,25.0,90.0
466.01196,0.06738127952755905,924.922120248214,0.00025370340306410486,25.0,90.0
467.31323,0.0676704094488189,923.3939093706002,0.00025370340306410486,25.0,90.0
468.6145,0.06796814960629921,925.6471554466289,0.00025370340306410486,25.0,90.0
469.91577,0.06826545275590551,925.7244876675185,0.00025370340306410486,25.0,90.0
471.21704,0.06855913385826772,928.1173280492256,0.00025370340306410486,25.0,90.0
472.51831,0.06888261811023622,925.2253741461125,0.00025370340306410486,25.0,90.0
473.81958,0.06919357677165354,927.2965531626427,0.00025370340306410486,25.0,90.0
475.12085,0.06952881299212599,928.0046409761693,0.00025370340306410486,25.0,90.0
476.42212,0.06982904133858268,927.0452625541012,0.00025370340306410486,25.0,90.0
477.72339,0.07012644881889764,929.1664233196017,0.00025370340306410486,25.0,90.0
479.02466,0.07044932283464567,928.7455284976795,0.00025370340306410486,25.0,90.0
480.32593,0.07076786811023622,928.1421494498619,0.00025370340306410486,25.0,90.0
481.6272,0.07104570275590551,928.1144600302446,0.00025370340306410486,25.0,90.0
482.92847,0.07131469291338582,929.5801741669709,0.00025370340306410486,25.0,90.0
484.22974,0.07160997637795276,930.5337122594775,0.00025370340306410486,25.0,90.0
485.53101,0.0719236279527559,931.3348021066903,0.00025370340306410486,25.0,90.0
486.83228,0.07226376771653543,930.6003545914377,0.00025370340306410486,25.0,90.0
488.13354,0.07260875984251969,932.8840277415654,0.00025370340306410486,25.0,90.0
489.43481,0.07289293700787401,930.9990353027065,0.00025370340306410486,25.0,90.0
490.73608,0.07318619094488188,930.719846691349,0.00025370340306410486,25.0,90.0
492.03735,0.07349801771653544,932.2696459300204,0.00025370340306410486,25.0,90.0
493.33862,0.07388927362204724,933.6340668509151,0.00025370340306410486,25.0,90.0
494.63989,0.07417546456692913,932.2313187672734,0.00025370340306410486,25.0,90.0
495.94116,0.07453733858267717,935.1479637065235,0.00025370340306410486,25.0,90.0
497.24243,0.07486254133858268,934.5064660791573,0.00025370340306410486,25.0,90.0
498.5437,0.07515031692913385,932.54393283621,0.00025370340306410486,25.0,90.0
499.84497,0.07546198031496062,933.6583146477552,0.00025370340306410486,25.0,90.0
501.14624,0.07572343700787401,934.6860301402722,0.00025370340306410486,25.0,90.0
502.44751,0.07602163582677166,934.968321426709,0.00025370340306410486,25.0,90.0
503.74878,0.07633154527559055,936.1556812848726,0.00025370340306410486,25.0,90.0
505.05005,0.0766099153543307,935.2486572456589,0.00025370340306410486,25.0,90.0
506.35132,0.07692934448818897,937.4833915628096,0.00025370340306410486,25.0,90.0
507.65259,0.07728727755905512,935.1677008916932,0.00025370340306410486,25.0,90.0
508.95386,0.07757690551181103,936.2028993064608,0.00025370340306410486,25.0,90.0
510.25513,0.07787834842519685,939.377118423111,0.00025370340306410486,25.0,90.0
511.5564,0.07820956496062992,938.6742451895501,0.00025370340306410486,25.0,90.0
512.85767,0.07852567519685039,938.0876570892216,0.00025370340306410486,25.0,90.0
514.15894,0.07878168307086614,936.1478594149241,0.00025370340306410486,25.0,90.0
515.46021,0.07908817716535432,940.2635709443605,0.00025370340306410486,25.0,90.0
516.76147,0.0793858188976378,939.1177191427231,0.00025370340306410486,25.0,90.0
518.06274,0.07977019291338583,941.193486989623,0.00025370340306410486,25.0,90.0
519.36401,0.08009923228346456,938.576523960995,0.00025370340306410486,25.0,90.0
520.66528,0.08040681299212599,939.6733587109559,0.00025370340306410486,25.0,90.0
521.96655,0.08069907480314961,939.1714293163686,0.00025370340306410486,25.0,90.0
523.26782,0.08101021653543307,940.9605777754603,0.00025370340306410486,25.0,90.0
524.56909,0.08134952165354331,941.1823538613966,0.00025370340306410486,25.0,90.0
525.87036,0.08168140748031495,941.1614173228347,0.00025370340306410486,25.0,90.0
527.17163,0.08202386417322835,942.1719247014654,0.00025370340306410486,25.0,90.0
528.4729,0.08236468503937008,940.634092923815,0.00025370340306410486,25.0,90.0
529.77417,0.08264346456692913,940.1016321635293,0.00025370340306410486,25.0,90.0
531.07544,0.08296277165354331,942.0539709026439,0.00025370340306410486,25.0,90.0
532.37671,0.08332719881889764,943.7227929290295,0.00025370340306410486,25.0,90.0
533.67798,0.08360808661417322,941.5990248735465,0.00025370340306410486,25.0,90.0
534.97925,0.08389068700787401,944.382593732075,0.00025370340306410486,25.0,90.0
536.28052,0.08423175787401575,945.691505449236,0.00025370340306410486,25.0,90.0
537.58179,0.08458043503937007,944.8491161286959,0.00025370340306410486,25.0,90.0
538.88306,0.08492368897637795,945.2728528966992,0.00025370340306410486,25.0,90.0
540.18433,0.08523707677165354,944.3769098399124,0.00025370340306410486,25.0,90.0
541.4856,0.08555889566929134,945.2972310580383,0.00025370340306410486,25.0,90.0
542.78687,0.08586372244094488,946.3682275642697,0.00025370340306410486,25.0,90.0
544.08813,0.0862593720472441,946.1352401314074,0.00025370340306410486,25.0,90.0
545.3894,0.0865588031496063,945.6093236689785,0.00025370340306410486,25.0,90.0
546.69067,0.08689078937007874,946.6651718204098,0.00025370340306410486,25.0,90.0
547.99194,0.08719456692913385,945.0859102049329,0.00025370340306410486,25.0,90.0
549.29321,0.08751166338582678,946.0506596443656,0.00025370340306410486,25.0,90.0
550.59448,0.08785502952755905,947.6325285498252,0.00025370340306410486,25.0,90.0
551.89575,0.08822428937007874,947.4080148094072,0.00025370340306410486,25.0,90.0
553.19702,0.08851722637795276,946.5938885122804,0.00025370340306410486,25.0,90.0
554.49829,0.08886631299212598,947.4110653386871,0.00025370340306410486,25.0,90.0
555.79956,0.08918448228346457,947.4084059029045,0.00025370340306410486,25.0,90.0
557.10083,0.08949254330708661,948.9750743077645,0.00025370340306410486,25.0,90.0
558.4021,0.08980529724409449,949.2764770297753,0.00025370340306410486,25.0,90.0
559.70337,0.09013111023622046,948.7986129217292,0.00025370340306410486,25.0,90.0
561.00464,0.09049329133858268,950.1778171768264,0.00025370340306410486,25.0,90.0
562.30591,0.0908277283464567,948.3600928195234,0.00025370340306410486,25.0,90.0
563.60718,0.09114901771653544,949.32121812588,0.00025370340306410486,25.0,90.0
564.90845,0.09145231496062992,949.7053240861449,0.00025370340306410486,25.0,90.0
566.20972,0.09181781692913386,951.5624967408876,0.00025370340306410486,25.0,90.0
567.51099,0.09215349803149607,950.3185065442979,0.00025370340306410486,25.0,90.0
568.81226,0.09252170866141732,951.8841320331647,0.00025370340306410486,25.0,90.0
570.11353,0.09287385236220472,951.6039265787141,0.00025370340306410486,25.0,90.0
571.41479,0.09316309251968503,951.1964853731032,0.00025370340306410486,25.0,90.0
572.71606,0.09349551181102363,950.9929863899464,0.00025370340306410486,25.0,90.0
574.01733,0.09379062401574803,952.3414506961465,0.00025370340306410486,25.0,90.0
575.3186,0.09411778740157481,954.6880638264588,0.00025370340306410486,25.0,90.0
576.61987,0.09449249212598425,954.1984408405904,0.00025370340306410486,25.0,90.0
577.92114,0.09484177755905511,953.5438806904104,0.00025370340306410486,25.0,90.0
579.22241,0.0951872559055118,955.6035354852166,0.00025370340306410486,25.0,90.0
580.52368,0.09557230511811024,954.2135109766908,0.00025370340306410486,25.0,90.0
581.82495,0.09593099999999999,954.4174792720446,0.00025370340306410486,25.0,90.0
583.12622,0.09629043503937008,954.3246076028577,0.00025370340306410486,25.0,90.0
584.42749,0.09659770472440944,951.6537779631851,0.00025370340306410486,25.0,90.0
585.72876,0.09687456692913386,954.8806904103875,0.00025370340306410486,25.0,90.0
587.03003,0.09719798031496063,953.4039474370339,0.00025370340306410486,25.0,90.0
588.3313,0.09751423818897638,954.5209626114616,0.00025370340306410486,25.0,90.0
589.63257,0.09782162992125984,956.368488293268,0.00025370340306410486,25.0,90.0
590.93384,0.09816471456692913,956.857276946342,0.00025370340306410486,25.0,90.0
592.23511,0.09845370866141732,955.6148771966418,0.00025370340306410486,25.0,90.0
593.53638,0.09875154330708662,955.2007352557752,0.00025370340306410486,25.0,90.0
594.83765,0.0991183346456693,957.095922198467,0.00025370340306410486,25.0,90.0
596.13892,0.09948397637795275,957.1795640611149,0.00025370340306410486,25.0,90.0
597.44019,0.09986970669291338,957.900453668457,0.00025370340306410486,25.0,90.0
598.74146,0.10025923622047243,958.1030140272201,0.00025370340306410486,25.0,90.0
600.04272,0.10059322244094489,957.9144548156646,0.00025370340306410486,25.0,90.0
601.34399,0.10095834645669291,957.3078948740679,0.00025370340306410486,25.0,90.0
602.64526,0.10131236220472441,958.9397455284977,0.00025370340306410486,25.0,90.0
603.94653,0.1016696496062992,958.8859571361528,0.00025370340306410486,25.0,90.0
605.2478,0.10203972637795276,959.4158106064556,0.00025370340306410486,25.0,90.0
606.54907,0.10241701771653543,959.1717682640664,0.00025370340306410486,25.0,90.0
607.85034,0.10273625590551182,957.8910413516192,0.00025370340306410486,25.0,90.0
609.15161,0.10310078149606298,959.6918704698337,0.00025370340306410486,25.0,90.0
610.45288,0.10348192322834646,961.6263492725661,0.00025370340306410486,25.0,90.0
611.75415,0.10387363582677166,960.6272096782604,0.00025370340306410486,25.0,90.0
613.05542,0.1042448503937008,961.327736350837,0.00025370340306410486,25.0,90.0
614.35669,0.10459526377952755,960.1116180841633,0.00025370340306410486,25.0,90.0
615.65796,0.10491701181102361,960.6893413985504,0.00025370340306410486,25.0,90.0
616.95923,0.10527858070866142,961.8673410856757,0.00025370340306410486,25.0,90.0
618.2605,0.10569324409448817,961.2092089482192,0.00025370340306410486,25.0,90.0
619.56177,0.10596631102362204,958.8871043437451,0.00025370340306410486,25.0,90.0
620.86304,0.10629945078740158,961.0504510611671,0.00025370340306410486,25.0,90.0
622.16431,0.10662552952755905,962.2961881420453,0.00025370340306410486,25.0,90.0
623.46558,0.1069732066929134,961.4728059654794,0.00025370340306410486,25.0,90.0
624.76685,0.1073240531496063,961.4838869479063,0.00025370340306410486,25.0,90.0
626.06812,0.10767931102362203,962.1487458935184,0.00025370340306410486,25.0,90.0
627.36938,0.10805343503937007,962.0150179903009,0.00025370340306410486,25.0,90.0
628.67065,0.10839741732283463,961.9884236324764,0.00025370340306410486,25.0,90.0
629.97192,0.10878140944881891,963.5684413620482,0.00025370340306410486,25.0,90.0
631.27319,0.10916270472440945,963.1783125619232,0.00025370340306410486,25.0,90.0
632.57446,0.10950738976377952,963.0262293372269,0.00025370340306410486,25.0,90.0
633.87573,0.1098589744094488,964.2090003650206,0.00025370340306410486,25.0,90.0
635.177,0.11015274015748032,963.1198831934088,0.00025370340306410486,25.0,90.0
636.47827,0.11048653740157481,964.9657923554257,0.00025370340306410486,25.0,90.0
637.77954,0.11086210433070866,964.7566876988059,0.00025370340306410486,25.0,90.0
639.08081,0.1112456751968504,964.4966626688221,0.00025370340306410486,25.0,90.0
640.38208,0.1116061062992126,965.1055691714033,0.00025370340306410486,25.0,90.0
641.68335,0.11198729527559055,964.0529801324503,0.00025370340306410486,25.0,90.0
642.98462,0.11240495078740156,966.2572091568024,0.00025370340306410486,25.0,90.0
644.28589,0.1128121161417323,966.27121030401,0.00025370340306410486,25.0,90.0
645.58716,0.11319819685039369,965.4479845648433,0.00025370340306410486,25.0,90.0
646.88843,0.11361649606299212,965.3902330917246,0.00025370340306410486,25.0,90.0
648.1897,0.11401003937007874,967.4866246023882,0.00025370340306410486,25.0,90.0
649.49097,0.11440272637795275,966.3164728581113,0.00025370340306410486,25.0,90.0
650.79224,0.11476642125984252,966.5227094957502,0.00025370340306410486,25.0,90.0
652.09351,0.1151178405511811,966.0065964436565,0.00025370340306410486,25.0,90.0
653.39478,0.1154230216535433,966.3866871773479,0.00025370340306410486,25.0,90.0
654.69604,0.1158048090551181,967.8530270636701,0.00025370340306410486,25.0,90.0
655.99731,0.11614828543307087,965.8213745632789,0.00025370340306410486,25.0,90.0
657.29858,0.11651554724409448,968.2560880221098,0.00025370340306410486,25.0,90.0
658.59985,0.11689150196850392,966.5512853939615,0.00025370340306410486,25.0,90.0
659.90112,0.1173222283464567,968.9665484695208,0.00025370340306410486,25.0,90.0
661.20239,0.11772271653543306,967.3844188350629,0.00025370340306410486,25.0,90.0
662.50366,0.11808112007874015,966.683501068989,0.00025370340306410486,25.0,90.0
663.80493,0.11849060826771654,968.3039057203943,0.00025370340306410486,25.0,90.0
665.1062,0.11891250984251969,968.5931323981854,0.00025370340306410486,25.0,90.0
666.40747,0.11928006496062991,968.6825102987955,0.00025370340306410486,25.0,90.0
667.70874,0.11965496259842519,968.1166240809304,0.00025370340306410486,25.0,90.0
669.01001,0.12003145866141732,969.4646451478334,0.00025370340306410486,25.0,90.0
670.31128,0.12046027165354331,969.8657767116858,0.00025370340306410486,25.0,90.0
671.61255,0.12081849803149605,968.8075819992699,0.00025370340306410486,25.0,90.0
672.91382,0.12122267125984251,970.077436512489,0.00025370340306410486,25.0,90.0
674.21509,0.12164017322834646,970.5190853626741,0.00025370340306410486,25.0,90.0
675.51636,0.12205078937007874,969.9464462637535,0.00025370340306410486,25.0,90.0
676.81763,0.12237454330708662,968.0276372738176,0.00025370340306410486,25.0,90.0
678.1189,0.12272604527559056,969.0846847786412,0.00025370340306410486,25.0,90.0
679.42017,0.1230939409448819,970.4440214840695,0.00025370340306410486,25.0,90.0
680.72144,0.1235123937007874,970.5399436825363,0.00025370340306410486,25.0,90.0
682.02271,0.12396487204724409,970.2535068050269,0.00025370340306410486,25.0,90.0
683.32397,0.12438323031496062,969.0153569379986,0.00025370340306410486,25.0,90.0
684.62524,0.12476965157480316,970.6163894248318,0.00025370340306410486,25.0,90.0
685.92651,0.12518431496062993,970.9928560254472,0.00025370340306410486,25.0,90.0
687.22778,0.1256656338582677,972.112739218856,0.00025370340306410486,25.0,90.0
688.52905,0.12606556102362204,969.6530479219899,0.00025370340306410486,25.0,90.0
689.83032,0.12645159448818896,969.981071074725,0.00025370340306410486,25.0,90.0
691.13159,0.1268168720472441,971.4597695155655,0.00025370340306410486,25.0,90.0
692.43286,0.12723557086614173,972.9982791886114,0.00025370340306410486,25.0,90.0
693.73413,0.12762558267716534,970.2636230901601,0.00025370340306410486,25.0,90.0
695.0354,0.12800698228346455,971.0643479167753,0.00025370340306410486,25.0,90.0
696.33667,0.12846925787401575,972.6837617979872,0.00025370340306410486,25.0,90.0
697.63794,0.12888319291338582,971.7000052145801,0.00025370340306410486,25.0,90.0
698.93921,0.1292263779527559,971.0828596756531,0.00025370340306410486,25.0,90.0
700.24048,0.12973583267716535,974.3412681858476,0.00025370340306410486,25.0,90.0
701.54175,0.13012116338582677,969.8681493455703,0.00025370340306410486,25.0,90.0
702.84302,0.13047455511811024,971.5629399801846,0.00025370340306410486,25.0,90.0
704.14429,0.1308991338582677,973.195312092611,0.00025370340306410486,25.0,90.0
705.44556,0.1313165649606299,973.9741878291703,0.00025370340306410486,25.0,90.0
706.74683,0.13172671062992125,973.3802732439902,0.00025370340306410486,25.0,90.0
708.0481,0.13213094291338584,971.3285706836314,0.00025370340306410486,25.0,90.0
709.34937,0.13248611811023622,972.4011576367524,0.00025370340306410486,25.0,90.0
710.65063,0.13293850393700787,973.7217760859363,0.00025370340306410486,25.0,90.0
711.9519,0.1334335157480315,972.9132554622726,0.00025370340306410486,25.0,90.0
713.25317,0.13383854527559055,974.2783282056631,0.00025370340306410486,25.0,90.0
714.55444,0.1343051279527559,973.8438233300308,0.00025370340306410486,25.0,90.0
715.85571,0.13476066929133856,975.0799134379726,0.00025370340306410486,25.0,90.0
717.15698,0.13517974409448819,973.4627678990457,0.00025370340306410486,25.0,90.0
718.45825,0.1355764783464567,973.8868957605465,0.00025370340306410486,25.0,90.0
719.75952,0.13599895669291337,973.2684465766282,0.00025370340306410486,25.0,90.0
721.06079,0.13643676771653543,974.4434478802733,0.00025370340306410486,25.0,90.0
722.36206,0.13686036023622047,974.9567450591854,0.00025370340306410486,25.0,90.0
723.66333,0.13730619881889763,974.8318037232101,0.00025370340306410486,25.0,90.0
724.9646,0.137813718503937,974.685456536476,0.00025370340306410486,25.0,90.0
726.26587,0.1382660216535433,974.7058976899411,0.00025370340306410486,25.0,90.0
727.56714,0.13862227559055118,972.5343119361736,0.00025370340306410486,25.0,90.0
728.86841,0.139004812992126,974.2046722636492,0.00025370340306410486,25.0,90.0
730.16968,0.13940449212598424,975.0188767794754,0.00025370340306410486,25.0,90.0
731.47095,0.13986791929133857,974.355608280753,0.00025370340306410486,25.0,90.0
732.77222,0.14026459448818898,973.9556499973928,0.00025370340306410486,25.0,90.0
734.07349,0.1407052125984252,974.944855816864,0.00025370340306410486,25.0,90.0
735.37476,0.1411823661417323,974.2827084528341,0.00025370340306410486,25.0,90.0
736.67603,0.14167342322834645,975.9518694269177,0.00025370340306410486,25.0,90.0
737.97729,0.1421463070866142,974.8882515513376,0.00025370340306410486,25.0,90.0
739.27856,0.1425682086614173,973.4918652552537,0.00025370340306410486,25.0,90.0
740.57983,0.14294675787401573,974.8035928455963,0.00025370340306410486,25.0,90.0
741.8811,0.1433774350393701,974.9204776555249,0.00025370340306410486,25.0,90.0
743.18237,0.14380854921259842,975.4048860614278,0.00025370340306410486,25.0,90.0
744.48364,0.1442790374015748,975.7176044219639,0.00025370340306410486,25.0,90.0
745.78491,0.14481438976377953,976.1180580904208,0.00025370340306410486,25.0,90.0
747.08618,0.14529283267716536,975.0978776659541,0.00025370340306410486,25.0,90.0
748.38745,0.1457943346456693,975.1630599155238,0.00025370340306410486,25.0,90.0
749.68872,0.14627431496062993,974.8891380299318,0.00025370340306410486,25.0,90.0
750.98999,0.1467460846456693,975.0779579704855,0.00025370340306410486,25.0,90.0
752.29126,0.1472428090551181,977.935599937425,0.00025370340306410486,25.0,90.0
753.59253,0.14774609251968504,973.6705428377745,0.00025370340306410486,25.0,90.0
754.8938,0.14816592913385826,973.5471137299891,0.00025370340306410486,25.0,90.0
756.19507,0.14861488976377954,976.9635240131407,0.00025370340306410486,25.0,90.0
757.49634,0.14909029527559053,975.7920946967722,0.00025370340306410486,25.0,90.0
758.79761,0.14955639566929135,974.6719507743652,0.00025370340306410486,25.0,90.0
760.09888,0.1500009429133858,975.2882619804975,0.00025370340306410486,25.0,90.0
761.40015,0.15046838188976377,975.1240287844814,0.00025370340306410486,25.0,90.0
762.70142,0.15095647244094487,973.9568754236847,0.00025370340306410486,25.0,90.0
764.00269,0.15143281692913385,976.632267820827,0.00025370340306410486,25.0,90.0
765.30396,0.15191598818897636,976.46365437764,0.00025370340306410486,25.0,90.0
766.60522,0.15238925984251966,975.8570683631434,0.00025370340306410486,25.0,90.0
767.90649,0.15287319488188975,976.1521092975961,0.00025370340306410486,25.0,90.0
769.20776,0.15337690157480316,976.3019502529071,0.00025370340306410486,25.0,90.0
770.50903,0.15381962992125983,974.4462376805548,0.00025370340306410486,25.0,90.0
771.8103,0.15424410236220473,975.7977003702352,0.00025370340306410486,25.0,90.0
773.11157,0.1548117066929134,975.366819627679,0.00025370340306410486,25.0,90.0
774.41284,0.15533848031496061,975.5008082598947,0.00025370340306410486,25.0,90.0
775.71411,0.15583057086614174,977.1691349011837,0.00025370340306410486,25.0,90.0
777.01538,0.1563404842519685,974.033503676279,0.00025370340306410486,25.0,90.0
778.31665,0.1567820748031496,975.3642123376962,0.00025370340306410486,25.0,90.0
779.61792,0.15726387598425196,976.4306721593575,0.00025370340306410486,25.0,90.0
780.91919,0.15787240551181103,977.9158627522553,0.00025370340306410486,25.0,90.0
781.11938,0.1579610374015748,978.4947854200344,0.00025370340306410486,25.0,90.0