File: datasets/am_bench_2022/csv/90-XY.17-1.csv
Time(s),Strain(%),Stress(MPa),SR(s-1),Temp(C),Angle(deg)
11.016357,7.847153937007873e-06,7.940844761954425,0.00025370340306410486,25.0,90.0
12.317627,3.561451771653543e-05,11.740751681702038,0.00025370340306410486,25.0,90.0
13.618896,4.455127362204724e-05,15.013670282108777,0.00025370340306410486,25.0,90.0
14.920166,6.587889173228347e-05,20.454577097564794,0.00025370340306410486,25.0,90.0
16.221436,7.575317913385826e-05,24.670620013557908,0.00025370340306410486,25.0,90.0
17.522705,8.706574803149606e-05,28.730291495020076,0.00025370340306410486,25.0,90.0
18.823975,0.00010860066929133859,32.7721671794337,0.00025370340306410486,25.0,90.0
20.125244,0.00011325427952755904,36.495697971528394,0.00025370340306410486,25.0,90.0
21.426514,0.00014714477362204724,40.55609323668979,0.00025370340306410486,25.0,90.0
22.727783,0.00016616232677165354,46.489839390937064,0.00025370340306410486,25.0,90.0
24.029053,0.00019338762007874017,53.484040778015334,0.00025370340306410486,25.0,90.0
25.330322,0.00021743769685039373,58.23167075142097,0.00025370340306410486,25.0,90.0
26.631592,0.0002257331496062992,62.970751420973045,0.00025370340306410486,25.0,90.0
27.932861,0.0002819477165354331,72.23531574281692,0.00025370340306410486,25.0,90.0
29.234131,0.00029002072834645665,77.68704959065548,0.00025370340306410486,25.0,90.0
30.5354,0.000305309094488189,84.82346300255514,0.00025370340306410486,25.0,90.0
31.83667,0.0003426617913385827,92.89886843614748,0.00025370340306410486,25.0,90.0
33.137939,0.0003709298818897638,99.70337904781769,0.00025370340306410486,25.0,90.0
34.439209,0.0003924351771653543,106.68985503467695,0.00025370340306410486,25.0,90.0
35.740479,0.0004433701377952756,114.00537101736455,0.00025370340306410486,25.0,90.0
37.041748,0.000452214311023622,123.75080825989467,0.00025370340306410486,25.0,90.0
38.343018,0.0004901008070866142,131.092579652709,0.00025370340306410486,25.0,90.0
39.644287,0.000519963031496063,137.02063148563383,0.00025370340306410486,25.0,90.0
40.945557,0.0005650208858267717,146.31327110601242,0.00025370340306410486,25.0,90.0
42.246826,0.0005793622440944882,154.04188872086354,0.00025370340306410486,25.0,90.0
43.548096,0.0006256952755905511,162.90632267820828,0.00025370340306410486,25.0,90.0
44.849365,0.0006486232677165354,170.70661469468635,0.00025370340306410486,25.0,90.0
46.150635,0.0006754912401574802,183.28411638942484,0.00025370340306410486,25.0,90.0
47.451904,0.0007245920669291338,191.33803775355895,0.00025370340306410486,25.0,90.0
48.753174,0.0007360092913385826,199.09493142827347,0.00025370340306410486,25.0,90.0
50.054443,0.0007906475787401574,210.00476351879857,0.00025370340306410486,25.0,90.0
51.355713,0.000813259468503937,217.9581112791365,0.00025370340306410486,25.0,90.0
52.656982,0.000845806811023622,228.5135944099703,0.00025370340306410486,25.0,90.0
53.958252,0.0008778575984251969,237.1930489649059,0.00025370340306410486,25.0,90.0
55.259521,0.000895615157480315,243.9358476299734,0.00025370340306410486,25.0,90.0
56.560791,0.000942833031496063,253.12052980132452,0.00025370340306410486,25.0,90.0
57.862061,0.0009896219881889764,264.3071387599729,0.00025370340306410486,25.0,90.0
59.16333,0.0010188812007874016,272.91654064765083,0.00025370340306410486,25.0,90.0
60.4646,0.0010524460236220473,283.7473014548678,0.00025370340306410486,25.0,90.0
61.765869,0.0010653338385826772,291.2016999530688,0.00025370340306410486,25.0,90.0
63.067139,0.0011112311811023621,303.0821817802576,0.00025370340306410486,25.0,90.0
64.368408,0.0011428229133858268,312.7148667674819,0.00025370340306410486,25.0,90.0
65.669678,0.0011901980708661417,321.77611200917767,0.00025370340306410486,25.0,90.0
66.970947,0.0012304577952755905,329.5609323668979,0.00025370340306410486,25.0,90.0
68.272217,0.001255085590551181,340.33879126036396,0.00025370340306410486,25.0,90.0
69.573486,0.0012797352952755906,348.6474422485269,0.00025370340306410486,25.0,90.0
70.874756,0.00130049031496063,358.9523126662147,0.00025370340306410486,25.0,90.0
72.176025,0.0013499273228346456,368.53193930228923,0.00025370340306410486,25.0,90.0
73.477295,0.0013892521456692914,378.68879386765394,0.00025370340306410486,25.0,90.0
74.778564,0.0014336017125984252,387.59091620169994,0.00025370340306410486,25.0,90.0
76.079834,0.0014584393307086614,397.99129165145746,0.00025370340306410486,25.0,90.0
77.381104,0.0015145482086614175,409.88619179225117,0.00025370340306410486,25.0,90.0
78.682373,0.001526313031496063,418.40055796005635,0.00025370340306410486,25.0,90.0
79.983643,0.0015735197244094489,426.58288574855294,0.00025370340306410486,25.0,90.0
81.284912,0.0016159896850393702,434.93909370600204,0.00025370340306410486,25.0,90.0
82.586182,0.0016409280511811022,445.2661521614434,0.00025370340306410486,25.0,90.0
83.887451,0.0016818880905511812,453.3887208635345,0.00025370340306410486,25.0,90.0
85.188721,0.0016974837007874015,461.8630912030036,0.00025370340306410486,25.0,90.0
86.48999,0.0017289222637795274,469.8484903791,0.00025370340306410486,25.0,90.0
87.79126,0.001780090374015748,481.7990561610263,0.00025370340306410486,25.0,90.0
89.092529,0.0017992011811023621,490.54455858580593,0.00025370340306410486,25.0,90.0
90.393799,0.0018576510236220473,500.3682536371695,0.00025370340306410486,25.0,90.0
91.695068,0.0019086424015748032,508.4438650466705,0.00025370340306410486,25.0,90.0
92.996338,0.0019174613582677166,516.5705011211347,0.00025370340306410486,25.0,90.0
94.297607,0.001942870157480315,523.5152787192992,0.00025370340306410486,25.0,90.0
95.598877,0.001963923720472441,531.8926317985087,0.00025370340306410486,25.0,90.0
96.900146,0.00200293562992126,538.0524847473536,0.00025370340306410486,25.0,90.0
98.201416,0.0020296710629921257,545.7154142983783,0.00025370340306410486,25.0,90.0
99.502686,0.002073579527559055,556.1367262866977,0.00025370340306410486,25.0,90.0
100.80396,0.0020898381889763776,561.1351358398082,0.00025370340306410486,25.0,90.0
102.10522,0.0021218942913385826,568.9419356520833,0.00025370340306410486,25.0,90.0
103.40649,0.0021590874015748034,575.4700943838974,0.00025370340306410486,25.0,90.0
104.70776,0.0021676675196850392,582.0182249569797,0.00025370340306410486,25.0,90.0
106.00903,0.0022223759842519685,590.02424779684,0.00025370340306410486,25.0,90.0
107.3103,0.0022375047244094486,594.1719247014654,0.00025370340306410486,25.0,90.0
108.61157,0.0022599053149606296,600.2555665641133,0.00025370340306410486,25.0,90.0
109.91284,0.002290157086614173,606.0214579965584,0.00025370340306410486,25.0,90.0
111.21411,0.002304164566929134,611.5679981227512,0.00025370340306410486,25.0,90.0
112.51538,0.002342234251968504,616.7799707983522,0.00025370340306410486,25.0,90.0
113.81665,0.002377685039370079,621.2114772905043,0.00025370340306410486,25.0,90.0
115.11792,0.0024103897637795277,628.8479689211034,0.00025370340306410486,25.0,90.0
116.41919,0.0024239332677165356,631.3788131615999,0.00025370340306410486,25.0,90.0
117.72046,0.0024439753937007874,636.0905251082025,0.00025370340306410486,25.0,90.0
119.02173,0.0024776383858267715,640.2986650675289,0.00025370340306410486,25.0,90.0
120.323,0.0025097220472440947,644.431506492152,0.00025370340306410486,25.0,90.0
121.62427,0.0025428114173228346,650.2737133023935,0.00025370340306410486,25.0,90.0
122.92554,0.0025717192913385827,655.6596443656464,0.00025370340306410486,25.0,90.0
124.22681,0.0026098874015748033,660.6226208478907,0.00025370340306410486,25.0,90.0
125.52808,0.002648366338582677,663.8480992856025,0.00025370340306410486,25.0,90.0
126.82935,0.0026848968503937008,666.6994576836836,0.00025370340306410486,25.0,90.0
128.13062,0.0027049251968503936,670.6248370443761,0.00025370340306410486,25.0,90.0
129.43188,0.002751050787401575,674.6106273139699,0.00025370340306410486,25.0,90.0
130.73315,0.002767631496062992,677.7308494550764,0.00025370340306410486,25.0,90.0
132.03442,0.00281593031496063,681.4138290660687,0.00025370340306410486,25.0,90.0
133.33569,0.002860234842519685,687.1673097981957,0.00025370340306410486,25.0,90.0
134.63696,0.0028990734251968507,688.9225374146113,0.00025370340306410486,25.0,90.0
135.93823,0.00291464468503937,692.1156854565365,0.00025370340306410486,25.0,90.0
137.2395,0.002970130118110236,696.4594827136674,0.00025370340306410486,25.0,90.0
138.54077,0.0029989049212598424,697.4940553788393,0.00025370340306410486,25.0,90.0
139.84204,0.003033456692913386,701.1103926578713,0.00025370340306410486,25.0,90.0
141.14331,0.0030783250000000002,703.8486207435992,0.00025370340306410486,25.0,90.0
142.44458,0.00312627125984252,709.0018511758877,0.00025370340306410486,25.0,90.0
143.74585,0.0031738915354330706,712.1873598581634,0.00025370340306410486,25.0,90.0
145.04712,0.0032289389763779527,713.5371017364552,0.00025370340306410486,25.0,90.0
146.34839,0.0032803854330708663,717.0087604943423,0.00025370340306410486,25.0,90.0
147.64966,0.0033351608267716535,720.532278249987,0.00025370340306410486,25.0,90.0
148.95093,0.0034136374015748035,722.1110444803671,0.00025370340306410486,25.0,90.0
150.2522,0.0034419320866141733,724.1603483339417,0.00025370340306410486,25.0,90.0
151.55347,0.0035306141732283462,729.5123585545184,0.00025370340306410486,25.0,90.0
152.85474,0.0035755124015748032,730.253480732127,0.00025370340306410486,25.0,90.0
154.15601,0.00364351279527559,734.9259268915889,0.00025370340306410486,25.0,90.0
155.45728,0.0037171015748031495,736.8097199770559,0.00025370340306410486,25.0,90.0
156.75854,0.003790506692913386,738.4838869479064,0.00025370340306410486,25.0,90.0
158.05981,0.0038569470472440944,742.2880794701987,0.00025370340306410486,25.0,90.0
159.36108,0.003965696456692913,744.7938937268603,0.00025370340306410486,25.0,90.0
160.66235,0.004059943110236221,746.5128278667153,0.00025370340306410486,25.0,90.0
161.96362,0.004162123031496063,749.8925535798093,0.00025370340306410486,25.0,90.0
163.26489,0.004251005118110236,750.8322208896074,0.00025370340306410486,25.0,90.0
164.56616,0.004363116141732283,753.2146842571832,0.00025370340306410486,25.0,90.0
165.86743,0.004487786811023622,755.4460290973562,0.00025370340306410486,25.0,90.0
167.1687,0.0045843080708661416,755.7934765604631,0.00025370340306410486,25.0,90.0
168.46997,0.004716895866141732,758.8117797361423,0.00025370340306410486,25.0,90.0
169.77124,0.004866560433070866,760.4677478229129,0.00025370340306410486,25.0,90.0
171.07251,0.00502314625984252,764.3946654846952,0.00025370340306410486,25.0,90.0
172.37378,0.005163419094488189,765.6762788757366,0.00025370340306410486,25.0,90.0
173.67505,0.005313220275590551,766.1050477134067,0.00025370340306410486,25.0,90.0
174.97632,0.005458473818897637,769.373650727434,0.00025370340306410486,25.0,90.0
176.27759,0.005611668700787401,770.9752568180634,0.00025370340306410486,25.0,90.0
177.57886,0.00579633248031496,774.3102675079523,0.00025370340306410486,25.0,90.0
178.88013,0.005965041141732283,772.9000625749596,0.00025370340306410486,25.0,90.0
180.1814,0.006114141141732283,774.167726964593,0.00025370340306410486,25.0,90.0
181.48267,0.0062818037401574794,777.0016947384888,0.00025370340306410486,25.0,90.0
182.78394,0.0064768549212598425,779.3495332950931,0.00025370340306410486,25.0,90.0
184.08521,0.006668799803149607,780.5933931271836,0.00025370340306410486,25.0,90.0
185.38647,0.006860601771653543,781.0228920060489,0.00025370340306410486,25.0,90.0
186.68774,0.007079278346456694,783.5094905355373,0.00025370340306410486,25.0,90.0
187.98901,0.0072834992125984255,783.8018459613079,0.00025370340306410486,25.0,90.0
189.29028,0.007494863188976377,786.1034572665172,0.00025370340306410486,25.0,90.0
190.59155,0.007691150787401574,786.3010637743131,0.00025370340306410486,25.0,90.0
191.89282,0.007947743307086615,788.525916462429,0.00025370340306410486,25.0,90.0
193.19409,0.008150081496062991,787.97121551859,0.00025370340306410486,25.0,90.0
194.49536,0.008371534645669292,790.8836105751682,0.00025370340306410486,25.0,90.0
195.79663,0.008616200393700786,791.1219168795953,0.00025370340306410486,25.0,90.0
197.0979,0.008844730905511812,793.5842154664442,0.00025370340306410486,25.0,90.0
198.39917,0.009078066141732283,794.0411951817281,0.00025370340306410486,25.0,90.0
199.70044,0.009304467716535432,796.6534390154873,0.00025370340306410486,25.0,90.0
201.00171,0.0095663687007874,796.5501903321688,0.00025370340306410486,25.0,90.0
202.30298,0.009816368700787401,796.9710069353914,0.00025370340306410486,25.0,90.0
203.60425,0.010063627559055119,799.5373885383533,0.00025370340306410486,25.0,90.0
204.90552,0.010309597244094488,800.0807216978673,0.00025370340306410486,25.0,90.0
206.20679,0.010560127362204724,801.1708035667727,0.00025370340306410486,25.0,90.0
207.50806,0.010865390748031497,803.9876675183815,0.00025370340306410486,25.0,90.0
208.80933,0.011110618897637795,802.1766178234344,0.00025370340306410486,25.0,90.0
210.1106,0.011322333464566929,802.318949783595,0.00025370340306410486,25.0,90.0
211.41187,0.01157605216535433,805.4326797726443,0.00025370340306410486,25.0,90.0
212.71313,0.011805843110236221,805.6673619439954,0.00025370340306410486,25.0,90.0
214.0144,0.012059893307086615,807.4128382958753,0.00025370340306410486,25.0,90.0
215.31567,0.012316098622047245,807.9298378265631,0.00025370340306410486,25.0,90.0
216.61694,0.012597032480314962,808.9579965583772,0.00025370340306410486,25.0,90.0
217.91821,0.01283740472440945,809.7559576576107,0.00025370340306410486,25.0,90.0
219.21948,0.013092959645669292,810.6593575637484,0.00025370340306410486,25.0,90.0
220.52075,0.01336849311023622,813.3574073108412,0.00025370340306410486,25.0,90.0
221.82202,0.01364208346456693,811.9531209261094,0.00025370340306410486,25.0,90.0
223.12329,0.013911917716535434,812.8858528445534,0.00025370340306410486,25.0,90.0
224.42456,0.014196745472440946,815.0188507065756,0.00025370340306410486,25.0,90.0
225.72583,0.014476306496062992,814.9625332429473,0.00025370340306410486,25.0,90.0
227.0271,0.014738989370078741,818.1563331073683,0.00025370340306410486,25.0,90.0
228.32837,0.015027303346456692,817.3088856442613,0.00025370340306410486,25.0,90.0
229.62964,0.015307499409448819,819.4361735412213,0.00025370340306410486,25.0,90.0
230.93091,0.015596574606299212,819.2033946915576,0.00025370340306410486,25.0,90.0
232.23218,0.015834138188976377,817.9091620169995,0.00025370340306410486,25.0,90.0
233.53345,0.016079530708661416,819.7215414298379,0.00025370340306410486,25.0,90.0
234.83472,0.016370868897637794,822.0494342180737,0.00025370340306410486,25.0,90.0
236.13599,0.016666409055118108,822.7238097721229,0.00025370340306410486,25.0,90.0
237.43726,0.01698548464566929,823.3445012254264,0.00025370340306410486,25.0,90.0
238.73853,0.017260098622047245,825.1728372529593,0.00025370340306410486,25.0,90.0
240.03979,0.017524831889763778,825.0182249569797,0.00025370340306410486,25.0,90.0
241.34106,0.017788755511811024,824.8051050737863,0.00025370340306410486,25.0,90.0
242.64233,0.018033945472440947,826.3773009334099,0.00025370340306410486,25.0,90.0
243.9436,0.018338043700787402,826.0444542942066,0.00025370340306410486,25.0,90.0
245.24487,0.018612290944881888,827.2518642123378,0.00025370340306410486,25.0,90.0
246.54614,0.01888896712598425,828.6580539187569,0.00025370340306410486,25.0,90.0
247.84741,0.01913247342519685,829.0243781613391,0.00025370340306410486,25.0,90.0
249.14868,0.01942060118110236,832.1207957449027,0.00025370340306410486,25.0,90.0
250.44995,0.0197209468503937,831.3164728581113,0.00025370340306410486,25.0,90.0
251.75122,0.019997425196850393,832.8765708922147,0.00025370340306410486,25.0,90.0
253.05249,0.020315779527559055,833.257287375502,0.00025370340306410486,25.0,90.0
254.35376,0.02058721653543307,833.4765865359545,0.00025370340306410486,25.0,90.0
255.65503,0.02084657874015748,834.2448245293842,0.00025370340306410486,25.0,90.0
256.9563,0.021143433070866142,835.817593992804,0.00025370340306410486,25.0,90.0
258.25757,0.02144748818897638,834.7382020128279,0.00025370340306410486,25.0,90.0
259.55884,0.02170726968503937,834.7498044532513,0.00025370340306410486,25.0,90.0
260.86011,0.0219603031496063,835.8216613651771,0.00025370340306410486,25.0,90.0
262.16138,0.02221447440944882,837.1594357824478,0.00025370340306410486,25.0,90.0
263.46265,0.022514051181102362,838.8429629243365,0.00025370340306410486,25.0,90.0
264.76392,0.022817996062992126,838.2828648902331,0.00025370340306410486,25.0,90.0
266.06519,0.023115838582677163,841.9896751316682,0.00025370340306410486,25.0,90.0
267.36646,0.023437092519685038,840.7857850550139,0.00025370340306410486,25.0,90.0
268.66772,0.023742665354330707,842.7194816707514,0.00025370340306410486,25.0,90.0
269.96899,0.024020972440944883,841.5634353652813,0.00025370340306410486,25.0,90.0
271.27026,0.024333807086614173,843.0996766960421,0.00025370340306410486,25.0,90.0
272.57153,0.02461674212598425,842.4371643114148,0.00025370340306410486,25.0,90.0
273.8728,0.024907009842519687,845.1026229337227,0.00025370340306410486,25.0,90.0
275.17407,0.025246159448818896,846.0065964436566,0.00025370340306410486,25.0,90.0
276.47534,0.025525442913385828,846.5397611722376,0.00025370340306410486,25.0,90.0
277.77661,0.025760456692913384,844.3358450226834,0.00025370340306410486,25.0,90.0
279.07788,0.02604480708661417,847.1703864003754,0.00025370340306410486,25.0,90.0
280.37915,0.026359751968503934,847.7966835271419,0.00025370340306410486,25.0,90.0
281.68042,0.02664366141732283,848.2201856390468,0.00025370340306410486,25.0,90.0
282.98169,0.0268842342519685,847.7613547478751,0.00025370340306410486,25.0,90.0
284.28296,0.027135334645669293,848.9941596704385,0.00025370340306410486,25.0,90.0
285.58423,0.02740590157480315,849.959978098764,0.00025370340306410486,25.0,90.0
286.8855,0.027706505905511807,852.0208061740627,0.00025370340306410486,25.0,90.0
288.18677,0.028027444881889765,850.3317776503103,0.00025370340306410486,25.0,90.0
289.48804,0.028259844488188975,852.5286280440112,0.00025370340306410486,25.0,90.0
290.78931,0.028512659448818898,852.6915836679356,0.00025370340306410486,25.0,90.0
292.09058,0.0288222342519685,852.9484278041404,0.00025370340306410486,25.0,90.0
293.39185,0.029140698818897637,853.8874693643427,0.00025370340306410486,25.0,90.0
294.69312,0.02944145275590551,854.1260363977682,0.00025370340306410486,25.0,90.0
295.99438,0.02973149409448819,855.6109141158679,0.00025370340306410486,25.0,90.0
297.29565,0.03002459251968504,855.6020754028264,0.00025370340306410486,25.0,90.0
298.59692,0.030303653543307087,855.3992021692653,0.00025370340306410486,25.0,90.0
299.89819,0.03061642125984252,856.9588048182718,0.00025370340306410486,25.0,90.0
301.19946,0.030901338582677164,857.6579235542578,0.00025370340306410486,25.0,90.0
302.50073,0.031216023622047246,858.4837044376076,0.00025370340306410486,25.0,90.0
303.802,0.031505055118110234,859.4891276007717,0.00025370340306410486,25.0,90.0
305.10327,0.03179097047244094,857.864551285394,0.00025370340306410486,25.0,90.0
306.40454,0.03204381102362205,860.0734212859155,0.00025370340306410486,25.0,90.0
307.70581,0.03232163582677165,861.2949366428535,0.00025370340306410486,25.0,90.0
309.00708,0.03261005118110236,860.9277780674767,0.00025370340306410486,25.0,90.0
310.30835,0.032865208661417324,862.9257183083903,0.00025370340306410486,25.0,90.0
311.60962,0.033158397637795274,862.8702091046566,0.00025370340306410486,25.0,90.0
312.91089,0.03342344881889764,864.0723783699224,0.00025370340306410486,25.0,90.0
314.21216,0.03375913779527559,863.5648172289723,0.00025370340306410486,25.0,90.0
315.51343,0.03403676377952756,862.7567659175054,0.00025370340306410486,25.0,90.0
316.8147,0.03429965748031496,864.1262971267664,0.00025370340306410486,25.0,90.0
318.11597,0.03455972440944882,863.0381185795484,0.00025370340306410486,25.0,90.0
319.41724,0.03483229724409449,866.3640819731971,0.00025370340306410486,25.0,90.0
320.71851,0.0351231437007874,866.9739531730719,0.00025370340306410486,25.0,90.0
322.01978,0.0353941437007874,866.6806851958075,0.00025370340306410486,25.0,90.0
323.32104,0.03567655708661417,868.7719403452052,0.00025370340306410486,25.0,90.0
324.62231,0.03600742322834646,868.1656932784065,0.00025370340306410486,25.0,90.0
325.92358,0.03631202165354331,867.8713563122491,0.00025370340306410486,25.0,90.0
327.22485,0.036589240157480316,869.4929603170465,0.00025370340306410486,25.0,90.0
328.52612,0.036912261811023625,869.03637169526,0.00025370340306410486,25.0,90.0
329.82739,0.03721155511811024,870.030896386296,0.00025370340306410486,25.0,90.0
331.12866,0.037502080708661414,871.1950774365125,0.00025370340306410486,25.0,90.0
332.42993,0.037804342519685036,872.2691766178235,0.00025370340306410486,25.0,90.0
333.7312,0.03813088385826771,873.0352766334672,0.00025370340306410486,25.0,90.0
335.03247,0.038376080708661414,872.1211086197007,0.00025370340306410486,25.0,90.0
336.33374,0.03867316338582677,872.3171768264067,0.00025370340306410486,25.0,90.0
337.63501,0.03895847047244095,874.5773061479898,0.00025370340306410486,25.0,90.0
338.93628,0.03930370078740157,875.3123794128383,0.00025370340306410486,25.0,90.0
340.23755,0.039612137795275594,875.6209782552015,0.00025370340306410486,25.0,90.0
341.53882,0.039884133858267716,875.5602544715023,0.00025370340306410486,25.0,90.0
342.84009,0.04021642125984252,876.3594409970277,0.00025370340306410486,25.0,90.0
344.14136,0.04048939763779527,876.8102414350525,0.00025370340306410486,25.0,90.0
345.44263,0.040794049212598424,878.349090055796,0.00025370340306410486,25.0,90.0
346.7439,0.04108265944881889,878.4855034676957,0.00025370340306410486,25.0,90.0
348.04517,0.04136502755905512,878.389555196329,0.00025370340306410486,25.0,90.0
349.34644,0.04163956496062992,878.2926943734682,0.00025370340306410486,25.0,90.0
350.64771,0.041927318897637796,880.4978620222141,0.00025370340306410486,25.0,90.0
351.94897,0.04221098031496063,879.6664754654013,0.00025370340306410486,25.0,90.0
353.25024,0.04250733070866142,881.2161443395735,0.00025370340306410486,25.0,90.0
354.55151,0.042811990157480315,880.3699223027585,0.00025370340306410486,25.0,90.0
355.85278,0.043127858267716535,881.9868071126871,0.00025370340306410486,25.0,90.0
357.15405,0.04341793503937008,881.21061688481,0.00025370340306410486,25.0,90.0
358.45532,0.04371301377952756,884.588491422016,0.00025370340306410486,25.0,90.0
359.75659,0.04398994291338582,883.3035146268968,0.00025370340306410486,25.0,90.0
361.05786,0.044290557086614175,884.0417166397248,0.00025370340306410486,25.0,90.0
362.35913,0.04459842716535433,883.4123429107785,0.00025370340306410486,25.0,90.0
363.6604,0.044893870078740156,884.7329352870627,0.00025370340306410486,25.0,90.0
364.96167,0.04517025984251968,886.0353548521667,0.00025370340306410486,25.0,90.0
366.26294,0.04546988779527559,885.5422902435208,0.00025370340306410486,25.0,90.0
367.56421,0.04577210236220473,884.990613756062,0.00025370340306410486,25.0,90.0
368.86548,0.046018610236220475,886.6811545080044,0.00025370340306410486,25.0,90.0
370.16675,0.046312641732283465,885.8841841789645,0.00025370340306410486,25.0,90.0
371.46802,0.04659836023622047,887.4532773635084,0.00025370340306410486,25.0,90.0
372.76929,0.04687765157480315,889.171064295771,0.00025370340306410486,25.0,90.0
374.07056,0.0472008562992126,890.7356207957449,0.00025370340306410486,25.0,90.0
375.37183,0.04752534448818897,889.1278875736559,0.00025370340306410486,25.0,90.0
376.6731,0.047826917322834644,890.85758982114,0.00025370340306410486,25.0,90.0
377.97437,0.048138870078740154,892.0575950357199,0.00025370340306410486,25.0,90.0
379.27563,0.04843257283464567,891.7309798195755,0.00025370340306410486,25.0,90.0
380.5769,0.048739295275590545,892.2882880533973,0.00025370340306410486,25.0,90.0
381.87817,0.04905657874015748,892.0562653178287,0.00025370340306410486,25.0,90.0
383.17944,0.04933979133858268,892.891979976013,0.00025370340306410486,25.0,90.0
384.48071,0.04960631102362205,893.7680033373313,0.00025370340306410486,25.0,90.0
385.78198,0.04989151574803149,892.2658653595453,0.00025370340306410486,25.0,90.0
387.08325,0.050189761811023616,894.0082911821453,0.00025370340306410486,25.0,90.0
388.38452,0.050451072834645665,894.7070188246337,0.00025370340306410486,25.0,90.0
389.68579,0.05076880708661417,895.2247223236168,0.00025370340306410486,25.0,90.0
390.98706,0.051079309055118115,896.4980184596131,0.00025370340306410486,25.0,90.0
392.28833,0.051349155511811025,896.4950722219326,0.00025370340306410486,25.0,90.0
393.5896,0.05166938976377953,896.6763570944361,0.00025370340306410486,25.0,90.0
394.89087,0.052001814960629916,898.4385722480054,0.00025370340306410486,25.0,90.0
396.19214,0.05230582677165354,896.776059863378,0.00025370340306410486,25.0,90.0
397.49341,0.0525906968503937,897.6904625332429,0.00025370340306410486,25.0,90.0
398.79468,0.052880952755905514,897.1961724983054,0.00025370340306410486,25.0,90.0
400.09595,0.05317314566929134,898.166970850498,0.00025370340306410486,25.0,90.0
401.39722,0.05350364566929133,899.5561610262295,0.00025370340306410486,25.0,90.0
402.69849,0.053789009842519685,900.1167805183292,0.00025370340306410486,25.0,90.0
403.99976,0.05408621062992126,900.2042290243521,0.00025370340306410486,25.0,90.0
405.30103,0.054400966535433075,901.6959639151066,0.00025370340306410486,25.0,90.0
406.60229,0.05473665748031496,902.604083016113,0.00025370340306410486,25.0,90.0
407.90356,0.05503046850393701,900.5575689628201,0.00025370340306410486,25.0,90.0
409.20483,0.055299458661417326,903.4163581373521,0.00025370340306410486,25.0,90.0
410.5061,0.05562590551181102,903.9106481722898,0.00025370340306410486,25.0,90.0
411.80737,0.055920110236220476,903.9704854773948,0.00025370340306410486,25.0,90.0
413.10864,0.05618447047244094,901.4822182823174,0.00025370340306410486,25.0,90.0
414.40991,0.05645130708661418,904.2478750586641,0.00025370340306410486,25.0,90.0
415.71118,0.05678225984251968,904.2988215049278,0.00025370340306410486,25.0,90.0
417.01245,0.05710767322834646,905.3961516399854,0.00025370340306410486,25.0,90.0
418.31372,0.0574263937007874,905.2732439901966,0.00025370340306410486,25.0,90.0
419.61499,0.05771138779527559,905.9406580799916,0.00025370340306410486,25.0,90.0
420.91626,0.0579923562992126,905.6711946602701,0.00025370340306410486,25.0,90.0
422.21753,0.05826515354330709,906.106977107994,0.00025370340306410486,25.0,90.0
423.5188,0.058568320866141735,907.0331647285811,0.00025370340306410486,25.0,90.0
424.82007,0.05886961811023622,907.2171090368671,0.00025370340306410486,25.0,90.0
426.12134,0.05917026968503937,909.2249830526151,0.00025370340306410486,25.0,90.0
427.42261,0.059430742125984246,906.9635240131407,0.00025370340306410486,25.0,90.0
428.72388,0.059674151574803144,907.1220733169943,0.00025370340306410486,25.0,90.0
430.02515,0.05994012598425197,910.734995046149,0.00025370340306410486,25.0,90.0
431.32642,0.06024831102362204,910.3841320331647,0.00025370340306410486,25.0,90.0
432.62769,0.06051422637795275,909.8108411117485,0.00025370340306410486,25.0,90.0
433.92896,0.06084924409448819,912.177582520728,0.00025370340306410486,25.0,90.0
435.23022,0.06120693110236221,910.3943786827971,0.00025370340306410486,25.0,90.0
436.53149,0.061465137795275585,909.6756531261407,0.00025370340306410486,25.0,90.0
437.83276,0.06173207874015747,911.0670073525578,0.00025370340306410486,25.0,90.0
439.13403,0.061984822834645674,912.5382489440476,0.00025370340306410486,25.0,90.0
440.4353,0.06230910039370079,914.4972101997184,0.00025370340306410486,25.0,90.0
441.73657,0.0626215905511811,913.0595765761068,0.00025370340306410486,25.0,90.0
443.03784,0.06289194094488189,914.2410700318089,0.00025370340306410486,25.0,90.0
444.33911,0.0632186811023622,914.6735412212546,0.00025370340306410486,25.0,90.0
445.64038,0.06356112007874015,916.347734265005,0.00025370340306410486,25.0,90.0
446.94165,0.06383245669291338,914.5998331334412,0.00025370340306410486,25.0,90.0
448.24292,0.06415811023622048,916.4231631642072,0.00025370340306410486,25.0,90.0
449.54419,0.06448008858267716,916.833654899098,0.00025370340306410486,25.0,90.0
450.84546,0.06478562007874016,917.8742764770298,0.00025370340306410486,25.0,90.0
452.14673,0.06514540748031496,917.0161651978933,0.00025370340306410486,25.0,90.0
453.448,0.06546740157480314,917.0052667257652,0.00025370340306410486,25.0,90.0
454.74927,0.06573783267716535,916.5136100537102,0.00025370340306410486,25.0,90.0
456.05054,0.0660545059055118,918.0476091150858,0.00025370340306410486,25.0,90.0
457.35181,0.0663361968503937,917.7923554257706,0.00025370340306410486,25.0,90.0
458.65308,0.06662732086614173,918.9393022892007,0.00025370340306410486,25.0,90.0
459.95435,0.06692910433070866,918.8825155133754,0.00025370340306410486,25.0,90.0
461.25562,0.06724716929133859,920.0614016790947,0.00025370340306410486,25.0,90.0
462.55688,0.06757636614173229,920.6235855451844,0.00025370340306410486,25.0,90.0
463.85815,0.06788064960629922,921.2629451947646,0.00025370340306410486,25.0,90.0
465.15942,0.06815730708661417,920.6017625280284,0.00025370340306410486,25.0,90.0
466.46069,0.06846609645669291,920.4902226625645,0.00025370340306410486,25.0,90.0
467.76196,0.06874366141732284,921.5708922146321,0.00025370340306410486,25.0,90.0
469.06323,0.06908580708661417,921.6507795797048,0.00025370340306410486,25.0,90.0
470.3645,0.06935925590551181,922.1380560045889,0.00025370340306410486,25.0,90.0
471.66577,0.06971142125984252,922.5562131720291,0.00025370340306410486,25.0,90.0
472.96704,0.06999174606299212,921.8630651301038,0.00025370340306410486,25.0,90.0
474.26831,0.07023533267716535,921.9272305365803,0.00025370340306410486,25.0,90.0
475.56958,0.0705286751968504,922.956979715284,0.00025370340306410486,25.0,90.0
476.87085,0.07083787401574804,924.4973405642177,0.00025370340306410486,25.0,90.0
478.17212,0.07115639960629921,924.3342024299943,0.00025370340306410486,25.0,90.0
479.47339,0.07145042322834645,925.0508160817647,0.00025370340306410486,25.0,90.0
480.77466,0.07176933661417323,925.0168952390885,0.00025370340306410486,25.0,90.0
482.07593,0.07208095866141732,925.4034781248371,0.00025370340306410486,25.0,90.0
483.3772,0.07237726968503937,925.5264639933254,0.00025370340306410486,25.0,90.0
484.67847,0.07268569881889764,926.9455597851593,0.00025370340306410486,25.0,90.0
485.97974,0.07300824015748031,927.0581164937164,0.00025370340306410486,25.0,90.0
487.28101,0.07330767716535433,926.9915263075559,0.00025370340306410486,25.0,90.0
488.58228,0.07364862598425197,928.6258017416698,0.00025370340306410486,25.0,90.0
489.88354,0.07394869094488189,926.3120665380404,0.00025370340306410486,25.0,90.0
491.18481,0.07424906692913386,928.9201908536268,0.00025370340306410486,25.0,90.0
492.48608,0.07461331692913385,930.8186890545967,0.00025370340306410486,25.0,90.0
493.78735,0.07498385236220473,928.8441883506284,0.00025370340306410486,25.0,90.0
495.08862,0.07532387992125984,930.6666840485999,0.00025370340306410486,25.0,90.0
496.38989,0.07565259645669291,931.1892892527508,0.00025370340306410486,25.0,90.0
497.69116,0.07591567913385827,928.1365437763988,0.00025370340306410486,25.0,90.0
498.99243,0.0761840748031496,930.0974865724567,0.00025370340306410486,25.0,90.0
500.2937,0.07640799212598426,929.1862126505711,0.00025370340306410486,25.0,90.0
501.59497,0.07666483267716535,931.2230797309277,0.00025370340306410486,25.0,90.0
502.89624,0.07698210236220472,931.6466339886323,0.00025370340306410486,25.0,90.0
504.19751,0.07727930511811024,932.1941388121187,0.00025370340306410486,25.0,90.0
505.49878,0.0776257342519685,933.619544245711,0.00025370340306410486,25.0,90.0
506.80005,0.07793640551181102,932.8823069301768,0.00025370340306410486,25.0,90.0
508.10132,0.07825626968503936,931.8256505188508,0.00025370340306410486,25.0,90.0
509.40259,0.07857221062992126,932.5315742816916,0.00025370340306410486,25.0,90.0
510.70386,0.07892241535433071,934.2339521301559,0.00025370340306410486,25.0,90.0
512.00513,0.07922224606299212,932.4800803045315,0.00025370340306410486,25.0,90.0
513.3064,0.07949653937007874,933.741513271106,0.00025370340306410486,25.0,90.0
514.60767,0.0797999311023622,935.0216144339573,0.00025370340306410486,25.0,90.0
515.90894,0.08013888582677164,936.1097147624758,0.00025370340306410486,25.0,90.0
517.21021,0.08052227362204724,936.4308025238566,0.00025370340306410486,25.0,90.0
518.51147,0.08086847834645669,936.216222558273,0.00025370340306410486,25.0,90.0
519.81274,0.08121121062992126,938.0584293685143,0.00025370340306410486,25.0,90.0
521.11401,0.08155752755905511,937.9455858580591,0.00025370340306410486,25.0,90.0
522.41528,0.08191615354330709,936.92271992491,0.00025370340306410486,25.0,90.0
523.71655,0.08219485236220472,937.1355269333055,0.00025370340306410486,25.0,90.0
525.01782,0.08253588976377953,938.5687020910466,0.00025370340306410486,25.0,90.0
526.31909,0.08285534842519685,939.3587891745319,0.00025370340306410486,25.0,90.0
527.62036,0.08318725787401575,939.2687073056265,0.00025370340306410486,25.0,90.0
528.92163,0.08349399803149607,937.2786671533609,0.00025370340306410486,25.0,90.0
530.2229,0.08381073031496063,938.6819888407988,0.00025370340306410486,25.0,90.0
531.52417,0.08411978346456693,938.8879126036397,0.00025370340306410486,25.0,90.0
532.82544,0.084416937007874,938.8505501381865,0.00025370340306410486,25.0,90.0
534.12671,0.08470113976377952,939.7233143870262,0.00025370340306410486,25.0,90.0
535.42798,0.08503547047244094,939.8952651613913,0.00025370340306410486,25.0,90.0
536.72925,0.08533416929133858,939.2489179746572,0.00025370340306410486,25.0,90.0
538.03052,0.08566564960629922,941.6234030348855,0.00025370340306410486,25.0,90.0
539.33179,0.08595353543307087,940.8979506700734,0.00025370340306410486,25.0,90.0
540.63306,0.086317968503937,942.0425248996194,0.00025370340306410486,25.0,90.0
541.93433,0.08661273622047244,941.7178651509621,0.00025370340306410486,25.0,90.0
543.2356,0.08692273228346457,943.519997914168,0.00025370340306410486,25.0,90.0
544.53687,0.08727092125984252,942.2030557438599,0.00025370340306410486,25.0,90.0
545.83813,0.08761778346456692,942.4912134327581,0.00025370340306410486,25.0,90.0
547.1394,0.08791301377952755,942.1026750795223,0.00025370340306410486,25.0,90.0
548.44067,0.08823159448818897,944.1275225530583,0.00025370340306410486,25.0,90.0
549.74194,0.08851685826771653,943.462898263545,0.00025370340306410486,25.0,90.0
551.04321,0.08885869881889763,945.7072274078323,0.00025370340306410486,25.0,90.0
552.34448,0.08919295275590551,944.1209521823017,0.00025370340306410486,25.0,90.0
553.64575,0.08953618503937008,946.2622933722689,0.00025370340306410486,25.0,90.0
554.94702,0.08994822637795276,945.2105386661104,0.00025370340306410486,25.0,90.0
556.24829,0.09031388976377953,945.1957814048078,0.00025370340306410486,25.0,90.0
557.54956,0.09059979921259843,944.5936538561818,0.00025370340306410486,25.0,90.0
558.85083,0.09092282677165354,945.3934139855035,0.00025370340306410486,25.0,90.0
560.1521,0.09122123622047244,946.7597643009856,0.00025370340306410486,25.0,90.0
561.45337,0.09153749212598425,946.4936121395422,0.00025370340306410486,25.0,90.0
562.75464,0.09188771062992125,946.2950148615529,0.00025370340306410486,25.0,90.0
564.05591,0.09226134251968504,946.712728789696,0.00025370340306410486,25.0,90.0
565.35718,0.09257280708661417,946.1966157376023,0.00025370340306410486,25.0,90.0
566.65845,0.09286076968503937,947.2450591854827,0.00025370340306410486,25.0,90.0
567.95972,0.09317129330708661,948.7710017208113,0.00025370340306410486,25.0,90.0
569.26099,0.09353654330708662,949.1685091515878,0.00025370340306410486,25.0,90.0
570.56226,0.09383000787401576,947.6723679407625,0.00025370340306410486,25.0,90.0
571.86353,0.09411947637795276,948.4972101997184,0.00025370340306410486,25.0,90.0
573.16479,0.0944215374015748,948.0863795171299,0.00025370340306410486,25.0,90.0
574.46606,0.09471329330708661,948.4194347395318,0.00025370340306410486,25.0,90.0
575.76733,0.09506229133858268,949.2804140376493,0.00025370340306410486,25.0,90.0
577.0686,0.09541863582677165,951.0638786045783,0.00025370340306410486,25.0,90.0
578.36987,0.09576018897637796,951.2671429316368,0.00025370340306410486,25.0,90.0
579.67114,0.09610762598425196,950.5921416279919,0.00025370340306410486,25.0,90.0
580.97241,0.09644562992125984,949.7489179746572,0.00025370340306410486,25.0,90.0
582.27368,0.09672713385826771,951.7923554257704,0.00025370340306410486,25.0,90.0
583.57495,0.09706151771653544,951.3029670960004,0.00025370340306410486,25.0,90.0
584.87622,0.09742641929133858,952.8692704802628,0.00025370340306410486,25.0,90.0
586.17749,0.09779013188976378,952.1158418939355,0.00025370340306410486,25.0,90.0
587.47876,0.0981520531496063,953.1840225269855,0.00025370340306410486,25.0,90.0
588.78003,0.09850209645669292,952.2574177400011,0.00025370340306410486,25.0,90.0
590.0813,0.09889701181102362,953.9440736298691,0.00025370340306410486,25.0,90.0
591.38257,0.09926958858267716,953.2280857276946,0.00025370340306410486,25.0,90.0
592.68384,0.09959010433070865,950.6793033321167,0.00025370340306410486,25.0,90.0
593.98511,0.09988823228346456,951.6017103822287,0.00025370340306410486,25.0,90.0
595.28638,0.10018477755905512,952.4817228972206,0.00025370340306410486,25.0,90.0
596.58765,0.10046425,953.6410022422695,0.00025370340306410486,25.0,90.0
597.88892,0.10081203346456694,955.5402044115347,0.00025370340306410486,25.0,90.0
599.19019,0.10114638385826771,954.583485425249,0.00025370340306410486,25.0,90.0
600.49146,0.1015135748031496,954.3537571048652,0.00025370340306410486,25.0,90.0
601.79272,0.10188056496062992,954.7276685612974,0.00025370340306410486,25.0,90.0
603.09399,0.10221576968503938,955.1722115033634,0.00025370340306410486,25.0,90.0
604.39526,0.10260411614173229,955.5960264900662,0.00025370340306410486,25.0,90.0
605.69653,0.10294423818897637,954.1285393961516,0.00025370340306410486,25.0,90.0
606.9978,0.10327479724409448,956.5143661678053,0.00025370340306410486,25.0,90.0
608.29907,0.103630218503937,954.7860979298118,0.00025370340306410486,25.0,90.0
609.60034,0.10395207283464566,956.9593784220682,0.00025370340306410486,25.0,90.0
610.90161,0.10431304527559056,957.5904468895031,0.00025370340306410486,25.0,90.0
612.20288,0.10465710826771653,955.0242217239402,0.00025370340306410486,25.0,90.0
613.50415,0.10500594881889763,958.6993794649842,0.00025370340306410486,25.0,90.0
614.80542,0.10533574606299213,956.2999165667205,0.00025370340306410486,25.0,90.0
616.10669,0.10566502559055117,957.8447619544246,0.00025370340306410486,25.0,90.0
617.40796,0.10599829527559054,958.6343275799134,0.00025370340306410486,25.0,90.0
618.70923,0.10635991338582677,957.8624393805079,0.00025370340306410486,25.0,90.0
620.0105,0.10669460236220471,956.2402878448141,0.00025370340306410486,25.0,90.0
621.31177,0.10697704330708661,958.4760911508579,0.00025370340306410486,25.0,90.0
622.61304,0.10734050196850393,959.8127705063357,0.00025370340306410486,25.0,90.0
623.91431,0.1077727657480315,960.4367732179173,0.00025370340306410486,25.0,90.0
625.21558,0.10815872834645669,957.8070083954738,0.00025370340306410486,25.0,90.0
626.51685,0.10850559842519686,958.4756479115607,0.00025370340306410486,25.0,90.0
627.81812,0.10887573228346456,959.586979193826,0.00025370340306410486,25.0,90.0
629.11938,0.1092413405511811,959.1081764613862,0.00025370340306410486,25.0,90.0
630.42065,0.10957733070866142,960.0825207279553,0.00025370340306410486,25.0,90.0
631.72192,0.10986810433070865,958.9362517599208,0.00025370340306410486,25.0,90.0
633.02319,0.11020429527559056,960.2475100380665,0.00025370340306410486,25.0,90.0
634.32446,0.11058653937007874,962.73635083694,0.00025370340306410486,25.0,90.0
635.62573,0.11096100393700786,961.8722427908432,0.00025370340306410486,25.0,90.0
636.927,0.1113282874015748,960.6867341085676,0.00025370340306410486,25.0,90.0
638.22827,0.11167612992125985,961.1566981279658,0.00025370340306410486,25.0,90.0
639.52954,0.1120340059055118,961.0737080878135,0.00025370340306410486,25.0,90.0
640.83081,0.11243174803149605,962.6124784898577,0.00025370340306410486,25.0,90.0
642.13208,0.1127374094488189,960.951217604422,0.00025370340306410486,25.0,90.0
643.43335,0.11313220866141732,962.3648120143923,0.00025370340306410486,25.0,90.0
644.73462,0.11356103346456693,963.940006257496,0.00025370340306410486,25.0,90.0
646.03589,0.11390304527559056,961.0358241643636,0.00025370340306410486,25.0,90.0
647.33716,0.11417403543307086,960.5373363925536,0.00025370340306410486,25.0,90.0
648.63843,0.11452364960629921,961.6835010689889,0.00025370340306410486,25.0,90.0
649.9397,0.11485324606299213,962.7406267925119,0.00025370340306410486,25.0,90.0
651.24097,0.11523803543307086,963.4304375032591,0.00025370340306410486,25.0,90.0
652.54224,0.1156038779527559,964.6624863117277,0.00025370340306410486,25.0,90.0
653.84351,0.11594130118110237,962.7140063617876,0.00025370340306410486,25.0,90.0
655.14478,0.11628701968503936,963.9153673671586,0.00025370340306410486,25.0,90.0
656.44604,0.11666202362204724,965.0653386869687,0.00025370340306410486,25.0,90.0
657.74731,0.11703218307086614,963.818480471398,0.00025370340306410486,25.0,90.0
659.04858,0.11743102952755906,966.2686812327266,0.00025370340306410486,25.0,90.0
660.34985,0.11788909448818898,965.8431975804349,0.00025370340306410486,25.0,90.0
661.65112,0.11830663188976379,965.1582103561559,0.00025370340306410486,25.0,90.0
662.95239,0.11867704921259842,964.6354747875059,0.00025370340306410486,25.0,90.0
664.25366,0.11904395669291339,964.6359962455025,0.00025370340306410486,25.0,90.0
665.55493,0.11939521456692913,964.7015695885697,0.00025370340306410486,25.0,90.0
666.8562,0.11972942125984251,965.1765396047349,0.00025370340306410486,25.0,90.0
668.15747,0.12009593307086613,966.0727433905199,0.00025370340306410486,25.0,90.0
669.45874,0.1204071437007874,963.2968921103405,0.00025370340306410486,25.0,90.0
670.76001,0.12075845866141732,966.0865620274287,0.00025370340306410486,25.0,90.0
672.06128,0.12113914173228346,966.0514157584607,0.00025370340306410486,25.0,90.0
673.36255,0.12159137598425196,968.7000834332795,0.00025370340306410486,25.0,90.0
674.66382,0.12202373228346457,965.1237680554831,0.00025370340306410486,25.0,90.0
675.96509,0.1223982440944882,966.6103665849715,0.00025370340306410486,25.0,90.0
677.26636,0.12274238976377952,967.358189497836,0.00025370340306410486,25.0,90.0
678.56763,0.12309151181102361,967.3541742712624,0.00025370340306410486,25.0,90.0
679.8689,0.12345918307086615,967.5158001772958,0.00025370340306410486,25.0,90.0
681.17017,0.12385057874015748,967.3331073682015,0.00025370340306410486,25.0,90.0
682.47144,0.12419718897637795,968.656359180268,0.00025370340306410486,25.0,90.0
683.77271,0.12459587204724408,967.4787505866403,0.00025370340306410486,25.0,90.0
685.07397,0.12498837007874015,968.5818689054597,0.00025370340306410486,25.0,90.0
686.37524,0.12537164763779526,968.5076654325495,0.00025370340306410486,25.0,90.0
687.67651,0.12581895275590552,969.332429472806,0.00025370340306410486,25.0,90.0
688.97778,0.1262014901574803,967.57728007509,0.00025370340306410486,25.0,90.0
690.27905,0.12660470078740158,968.1128174375555,0.00025370340306410486,25.0,90.0
691.58032,0.1269560157480315,968.0603587631017,0.00025370340306410486,25.0,90.0
692.88159,0.1273093031496063,968.0095687542369,0.00025370340306410486,25.0,90.0
694.18286,0.12771921456692914,969.6832924857904,0.00025370340306410486,25.0,90.0
695.48413,0.12813264370078742,969.0351723418678,0.00025370340306410486,25.0,90.0
696.7854,0.12850350787401574,969.9735620795745,0.00025370340306410486,25.0,90.0
698.08667,0.1289210688976378,968.6507535068051,0.00025370340306410486,25.0,90.0
699.38794,0.12932639173228347,970.0902904521041,0.00025370340306410486,25.0,90.0
700.68921,0.12976718503937007,970.8424936121396,0.00025370340306410486,25.0,90.0
701.99048,0.1301529251968504,967.8804036084894,0.00025370340306410486,25.0,90.0
703.29175,0.13054613976377952,970.5662512384628,0.00025370340306410486,25.0,90.0
704.59302,0.13094720472440946,969.9244668091985,0.00025370340306410486,25.0,90.0
705.89429,0.13135617716535433,969.5621577931897,0.00025370340306410486,25.0,90.0
707.19556,0.13173764566929133,969.762736611566,0.00025370340306410486,25.0,90.0
708.49683,0.1321296397637795,970.8056526046827,0.00025370340306410486,25.0,90.0
709.7981,0.1325301062992126,970.5850758721385,0.00025370340306410486,25.0,90.0
711.09937,0.13291171653543307,969.7975439328362,0.00025370340306410486,25.0,90.0
712.40063,0.13332757677165355,969.8823330030766,0.00025370340306410486,25.0,90.0
713.7019,0.13370586614173227,968.164546070814,0.00025370340306410486,25.0,90.0
715.00317,0.13406796456692913,970.6450435417427,0.00025370340306410486,25.0,90.0
716.30444,0.13450184645669291,971.1432184387547,0.00025370340306410486,25.0,90.0
717.60571,0.13493342913385828,970.8033581894978,0.00025370340306410486,25.0,90.0
718.90698,0.1352747598425197,971.0470876570892,0.00025370340306410486,25.0,90.0
720.20825,0.1356556653543307,971.6011889242322,0.00025370340306410486,25.0,90.0
721.50952,0.13608771653543306,971.5409865985296,0.00025370340306410486,25.0,90.0
722.81079,0.1364774468503937,972.3630912030037,0.00025370340306410486,25.0,90.0
724.11206,0.13689425787401577,971.6651196746102,0.00025370340306410486,25.0,90.0
725.41333,0.1373089783464567,970.8657245658862,0.00025370340306410486,25.0,90.0
726.7146,0.13771987598425198,972.6755749074413,0.00025370340306410486,25.0,90.0
728.01587,0.13814825393700786,971.0762371590969,0.00025370340306410486,25.0,90.0
729.31714,0.13857909842519683,972.4903269541638,0.00025370340306410486,25.0,90.0
730.61841,0.13904113976377955,970.9947593471346,0.00025370340306410486,25.0,90.0
731.91968,0.13952032283464566,972.833941700996,0.00025370340306410486,25.0,90.0
733.22095,0.1398963838582677,970.8804296813893,0.00025370340306410486,25.0,90.0
734.52222,0.14029709645669292,971.5969390415602,0.00025370340306410486,25.0,90.0
735.82349,0.14070801574803152,971.6018928925275,0.00025370340306410486,25.0,90.0
737.12476,0.14115114370078738,973.3143870261251,0.00025370340306410486,25.0,90.0
738.42603,0.14156448031496063,970.9433435886739,0.00025370340306410486,25.0,90.0
739.72729,0.1419667775590551,972.5021119048861,0.00025370340306410486,25.0,90.0
741.02856,0.14234984251968505,971.7864890233092,0.00025370340306410486,25.0,90.0
742.32983,0.14278533267716537,972.632267820827,0.00025370340306410486,25.0,90.0
743.6311,0.14322355511811022,972.3633258591021,0.00025370340306410486,25.0,90.0
744.93237,0.1436749311023622,972.253793606925,0.00025370340306410486,25.0,90.0
746.23364,0.14410281692913385,973.3763883819158,0.00025370340306410486,25.0,90.0
747.53491,0.14450616929133858,971.0056578192626,0.00025370340306410486,25.0,90.0
748.83618,0.1448908307086614,973.6738019502529,0.00025370340306410486,25.0,90.0
750.13745,0.14538675787401575,974.5294884497054,0.00025370340306410486,25.0,90.0
751.43872,0.1457795157480315,971.5782969181832,0.00025370340306410486,25.0,90.0
752.73999,0.14623493897637796,973.7925640089691,0.00025370340306410486,25.0,90.0
754.04126,0.14673585236220474,972.7026907232622,0.00025370340306410486,25.0,90.0
755.34253,0.14720989763779527,971.8015852323095,0.00025370340306410486,25.0,90.0
756.6438,0.14765188779527558,972.625593158471,0.00025370340306410486,25.0,90.0
757.94507,0.14813509448818898,973.013505762111,0.00025370340306410486,25.0,90.0
759.24634,0.14850517125984253,971.7462585388747,0.00025370340306410486,25.0,90.0
760.54761,0.1488682559055118,972.3001251499193,0.00025370340306410486,25.0,90.0
761.84888,0.14935301181102362,974.0571778693227,0.00025370340306410486,25.0,90.0
763.15015,0.1498378523622047,972.9406841528915,0.00025370340306410486,25.0,90.0
764.45142,0.1503371220472441,973.8473170986077,0.00025370340306410486,25.0,90.0
765.75269,0.1507964901574803,973.8753976117224,0.00025370340306410486,25.0,90.0
767.05396,0.15129973818897638,976.0130885957136,0.00025370340306410486,25.0,90.0
768.35522,0.1517949842519685,974.0702403921365,0.00025370340306410486,25.0,90.0
769.65649,0.15222542913385828,971.563956823278,0.00025370340306410486,25.0,90.0
770.95776,0.15260916338582678,973.7995776190228,0.00025370340306410486,25.0,90.0
772.25903,0.1530481496062992,973.3308129530166,0.00025370340306410486,25.0,90.0
773.5603,0.15347802952755904,974.5318610835898,0.00025370340306410486,25.0,90.0
774.86157,0.15400774803149606,973.7093132398185,0.00025370340306410486,25.0,90.0
776.16284,0.1544894311023622,974.3996454085624,0.00025370340306410486,25.0,90.0
777.46411,0.1549847007874016,973.2676643896335,0.00025370340306410486,25.0,90.0
778.76538,0.15545622244094487,974.6044219638109,0.00025370340306410486,25.0,90.0
780.06665,0.1559609744094488,975.5430724305158,0.00025370340306410486,25.0,90.0
781.36792,0.1564657834645669,973.7505605673464,0.00025370340306410486,25.0,90.0
782.66919,0.15688932874015749,973.9150544923606,0.00025370340306410486,25.0,90.0
783.97046,0.15740889763779528,973.9508265109246,0.00025370340306410486,25.0,90.0
785.27173,0.15784279133858267,973.5436199614121,0.00025370340306410486,25.0,90.0
786.573,0.15821137795275592,972.4449340355634,0.00025370340306410486,25.0,90.0
787.87427,0.15865599606299213,974.1172237576263,0.00025370340306410486,25.0,90.0
789.17554,0.15915453937007873,974.9154977316578,0.00025370340306410486,25.0,90.0
790.47681,0.15966718503937008,974.335167127288,0.00025370340306410486,25.0,90.0
791.77808,0.16021079724409448,974.3535485216667,0.00025370340306410486,25.0,90.0
793.07935,0.16060100787401574,972.6115137925641,0.00025370340306410486,25.0,90.0
794.38062,0.16104386614173227,974.4384158106064,0.00025370340306410486,25.0,90.0
795.68188,0.16157929724409448,973.5550659644366,0.00025370340306410486,25.0,90.0
796.98315,0.16208509251968503,975.0649736663712,0.00025370340306410486,25.0,90.0
798.28442,0.1626183779527559,973.9855816863952,0.00025370340306410486,25.0,90.0
799.58569,0.1631888464566929,973.7342128591541,0.00025370340306410486,25.0,90.0
800.88696,0.16373054527559056,973.5312614068937,0.00025370340306410486,25.0,90.0
802.18823,0.1641086003937008,971.9141158679669,0.00025370340306410486,25.0,90.0
803.4895,0.1645867874015748,973.7873494290035,0.00025370340306410486,25.0,90.0
804.39038,0.16500055708661415,976.5818428325598,0.00025370340306410486,25.0,90.0