File: datasets/am_bench_2022/csv/90-XY.16-2.csv
Time(s),Strain(%),Stress(MPa),SR(s-1),Temp(C),Angle(deg)
12.901611,9.741424409448819e-06,23.845448131902973,0.00025370340306410486,25.0,90.0
14.202881,3.4772405511811025e-05,27.836976166569784,0.00025370340306410486,25.0,90.0
15.50415,5.6203478346456694e-05,33.05125508640279,0.00025370340306410486,25.0,90.0
16.80542,9.055054133858268e-05,36.85407176451937,0.00025370340306410486,25.0,90.0
18.106689,9.170971062992127e-05,40.9323442371717,0.00025370340306410486,25.0,90.0
19.407959,8.519776771653542e-05,44.22239338371294,0.00025370340306410486,25.0,90.0
20.709229,9.73861594488189e-05,49.91885800348782,0.00025370340306410486,25.0,90.0
22.010498,0.00013198409448818898,55.53201395127622,0.00025370340306410486,25.0,90.0
23.311768,0.00014829046653543307,61.44311948422555,0.00025370340306410486,25.0,90.0
24.613037,0.00017007163582677165,66.0303017491941,0.00025370340306410486,25.0,90.0
25.914307,0.00020153003937007873,73.06906938646091,0.00025370340306410486,25.0,90.0
27.215576,0.0002065085433070866,79.30932727368811,0.00025370340306410486,25.0,90.0
28.516846,0.0002400217125984252,87.38078528774507,0.00025370340306410486,25.0,90.0
29.818115,0.0002600320669291339,94.16447709137029,0.00025370340306410486,25.0,90.0
31.119385,0.00029748818897637794,101.24894836970883,0.00025370340306410486,25.0,90.0
32.420654,0.00032362431102362206,109.98055805104897,0.00025370340306410486,25.0,90.0
33.721924,0.00034125763779527555,117.95743011150452,0.00025370340306410486,25.0,90.0
35.023193,0.00035284828740157477,122.69372721027321,0.00025370340306410486,25.0,90.0
36.324463,0.0003988523622047244,131.35668498652433,0.00025370340306410486,25.0,90.0
37.625732,0.00040240082677165355,139.9136368440522,0.00025370340306410486,25.0,90.0
38.927002,0.00045462970472440943,148.1365296200391,0.00025370340306410486,25.0,90.0
40.228271,0.0004742955905511811,157.29133594039,0.00025370340306410486,25.0,90.0
41.529541,0.0005015370078740157,166.07176451936797,0.00025370340306410486,25.0,90.0
42.830811,0.0005553678543307086,176.7871875495429,0.00025370340306410486,25.0,90.0
44.13208,0.0005762963976377953,183.3962426676531,0.00025370340306410486,25.0,90.0
45.43335,0.0006015768700787401,193.6938725360672,0.00025370340306410486,25.0,90.0
46.734619,0.0006504629133858267,203.7117766738889,0.00025370340306410486,25.0,90.0
48.035889,0.0006637910826771654,211.04167151085977,0.00025370340306410486,25.0,90.0
49.337158,0.0007028256496062992,221.5033821275696,0.00025370340306410486,25.0,90.0
50.638428,0.0007635338582677165,230.9262696189822,0.00025370340306410486,25.0,90.0
51.939697,0.0007774243700787402,240.49869206785394,0.00025370340306410486,25.0,90.0
53.240967,0.0008188465748031495,250.12199175606403,0.00025370340306410486,25.0,90.0
54.542236,0.0008451827559055118,256.46994926808645,0.00025370340306410486,25.0,90.0
55.843506,0.0008660477755905512,268.00628864344975,0.00025370340306410486,25.0,90.0
57.144775,0.0009240358858267717,277.0386566612059,0.00025370340306410486,25.0,90.0
58.446045,0.00097430218503937,289.07863446599373,0.00025370340306410486,25.0,90.0
59.747314,0.0009785032283464567,296.88912963060824,0.00025370340306410486,25.0,90.0
61.048584,0.0010210523818897637,306.6050309147598,0.00025370340306410486,25.0,90.0
62.349854,0.001032210649606299,312.1207789462559,0.00025370340306410486,25.0,90.0
63.651123,0.0010649549015748032,323.1588543042858,0.00025370340306410486,25.0,90.0
64.952393,0.001121993090551181,333.95222744807904,0.00025370340306410486,25.0,90.0
66.253662,0.0011553463582677165,346.4761401469111,0.00025370340306410486,25.0,90.0
67.554932,0.0011887068503937009,356.183269037679,0.00025370340306410486,25.0,90.0
68.856201,0.0012293071062992125,363.2091370290123,0.00025370340306410486,25.0,90.0
70.157471,0.0012521706299212598,371.76237911536225,0.00025370340306410486,25.0,90.0
71.45874,0.0012986263976377953,385.2992918670401,0.00025370340306410486,25.0,90.0
72.76001,0.0013252069488188976,394.6399091053216,0.00025370340306410486,25.0,90.0
74.061279,0.0013717528937007874,402.27527347672145,0.00025370340306410486,25.0,90.0
75.362549,0.0014066979330708662,412.86027585477984,0.00025370340306410486,25.0,90.0
76.663818,0.0014373512795275592,419.6954764043756,0.00025370340306410486,25.0,90.0
77.965088,0.0014689089173228346,431.6342810336627,0.00025370340306410486,25.0,90.0
79.266357,0.0015050774212598426,440.21788299952436,0.00025370340306410486,25.0,90.0
80.567627,0.001545770531496063,451.12627490355646,0.00025370340306410486,25.0,90.0
81.868896,0.0015857849409448817,458.6599376420229,0.00025370340306410486,25.0,90.0
83.170166,0.0016214194094488188,468.30373090947523,0.00025370340306410486,25.0,90.0
84.471436,0.001645050255905512,475.91087565396606,0.00025370340306410486,25.0,90.0
85.772705,0.0016910669291338584,486.27873487290594,0.00025370340306410486,25.0,90.0
87.073975,0.0017308784055118111,495.8493103630502,0.00025370340306410486,25.0,90.0
88.375244,0.0017570122637795276,502.9497436981451,0.00025370340306410486,25.0,90.0
89.676514,0.001787681751968504,511.71399883739366,0.00025370340306410486,25.0,90.0
90.977783,0.0018141318503937008,517.9182740580246,0.00025370340306410486,25.0,90.0
92.279053,0.0018413094291338582,525.522459440892,0.00025370340306410486,25.0,90.0
93.580322,0.0018881448622047245,536.1698990646303,0.00025370340306410486,25.0,90.0
94.881592,0.0019320629724409448,543.3050784759287,0.00025370340306410486,25.0,90.0
96.182861,0.001958949212598425,550.4875019817154,0.00025370340306410486,25.0,90.0
97.484131,0.001972726968503937,555.7611108175237,0.00025370340306410486,25.0,90.0
98.7854,0.001997960433070866,562.8849019711462,0.00025370340306410486,25.0,90.0
100.08667,0.0020285332677165355,570.6307403688633,0.00025370340306410486,25.0,90.0
101.38794,0.0020700641732283465,577.6768747027427,0.00025370340306410486,25.0,90.0
102.68921,0.0021181468503937008,584.9058024626116,0.00025370340306410486,25.0,90.0
103.99048,0.0021296127952755905,589.9196480473497,0.00025370340306410486,25.0,90.0
105.29175,0.002157742913385827,597.0687787348728,0.00025370340306410486,25.0,90.0
106.59302,0.0022012261811023624,603.7560376261692,0.00025370340306410486,25.0,90.0
107.89429,0.0022380931102362204,608.5295143476193,0.00025370340306410486,25.0,90.0
109.19556,0.0022530307086614174,613.5865613274851,0.00025370340306410486,25.0,90.0
110.49683,0.002301761023622047,619.8893938593245,0.00025370340306410486,25.0,90.0
111.7981,0.002307868307086614,623.3586376367384,0.00025370340306410486,25.0,90.0
113.09937,0.002344845866141732,629.7828304180098,0.00025370340306410486,25.0,90.0
114.40063,0.0023552814960629918,633.9179041378217,0.00025370340306410486,25.0,90.0
115.7019,0.0024102326771653546,639.4702742694076,0.00025370340306410486,25.0,90.0
117.00317,0.0024232543307086615,644.3944934735507,0.00025370340306410486,25.0,90.0
118.30444,0.0024603925196850394,647.5429900121545,0.00025370340306410486,25.0,90.0
119.60571,0.0025012606299212596,653.2031126142789,0.00025370340306410486,25.0,90.0
120.90698,0.002544324212598425,658.9915711039475,0.00025370340306410486,25.0,90.0
122.20825,0.0025645718503937006,661.7271574274693,0.00025370340306410486,25.0,90.0
123.50952,0.0026126537401574804,666.6826613116313,0.00025370340306410486,25.0,90.0
124.81079,0.0026235250000000002,668.4314854938435,0.00025370340306410486,25.0,90.0
126.11206,0.0026712212598425196,672.8250805897584,0.00025370340306410486,25.0,90.0
127.41333,0.002711331889763779,675.9295037784707,0.00025370340306410486,25.0,90.0
128.7146,0.0027317793307086616,680.5765470591343,0.00025370340306410486,25.0,90.0
130.01587,0.0027728653543307087,684.3340643661153,0.00025370340306410486,25.0,90.0
131.31714,0.002811264960629921,688.2559319346826,0.00025370340306410486,25.0,90.0
132.61841,0.0028361251968503937,689.467473445014,0.00025370340306410486,25.0,90.0
133.91968,0.0028759850393700786,694.1967711250858,0.00025370340306410486,25.0,90.0
135.22095,0.00292894468503937,696.1837182264968,0.00025370340306410486,25.0,90.0
136.52222,0.002960148622047244,699.9072821434232,0.00025370340306410486,25.0,90.0
137.82349,0.0029940088582677163,703.2202082122285,0.00025370340306410486,25.0,90.0
139.12476,0.003040292716535433,706.6651957934788,0.00025370340306410486,25.0,90.0
140.42603,0.0031011153543307086,709.7600010569149,0.00025370340306410486,25.0,90.0
141.72729,0.0031459456692913387,712.6178724303757,0.00025370340306410486,25.0,90.0
143.02856,0.0031915222440944877,715.7362468953125,0.00025370340306410486,25.0,90.0
144.32983,0.0032526291338582677,720.5407969138085,0.00025370340306410486,25.0,90.0
145.6311,0.0033199277559055117,723.4322253342493,0.00025370340306410486,25.0,90.0
146.93237,0.0033749854330708665,724.0077683242614,0.00025370340306410486,25.0,90.0
148.23364,0.003447446062992126,727.4666807588649,0.00025370340306410486,25.0,90.0
149.53491,0.0035242338582677168,731.9398615441526,0.00025370340306410486,25.0,90.0
150.83618,0.003593949212598425,734.5909211013052,0.00025370340306410486,25.0,90.0
152.13745,0.0036924200787401573,737.6257464461237,0.00025370340306410486,25.0,90.0
153.43872,0.003773523622047244,738.5530042805052,0.00025370340306410486,25.0,90.0
154.73999,0.0038397730314960626,741.2438038366009,0.00025370340306410486,25.0,90.0
156.04126,0.003961386023622047,745.6974316968767,0.00025370340306410486,25.0,90.0
157.34253,0.004061092913385827,745.3855361200655,0.00025370340306410486,25.0,90.0
158.6438,0.004140548622047244,748.8848227025312,0.00025370340306410486,25.0,90.0
159.94507,0.004232227165354331,751.31300533742,0.00025370340306410486,25.0,90.0
161.24634,0.004348336220472441,754.4886381651958,0.00025370340306410486,25.0,90.0
162.54761,0.004470009645669291,756.6300797970723,0.00025370340306410486,25.0,90.0
163.84888,0.0046051907480314964,757.5714738677799,0.00025370340306410486,25.0,90.0
165.15015,0.004711576377952755,757.9436928605401,0.00025370340306410486,25.0,90.0
166.45142,0.004848803346456693,761.1686307667917,0.00025370340306410486,25.0,90.0
167.75269,0.004975472047244095,764.4841198541457,0.00025370340306410486,25.0,90.0
169.05396,0.005113829921259843,764.8599587803202,0.00025370340306410486,25.0,90.0
170.35522,0.00528565157480315,767.5045711567933,0.00025370340306410486,25.0,90.0
171.65649,0.005467661417322835,769.2111980130001,0.00025370340306410486,25.0,90.0
172.95776,0.005653686417322835,771.9168472229561,0.00025370340306410486,25.0,90.0
174.25903,0.00584185,771.8520054959573,0.00025370340306410486,25.0,90.0
175.5603,0.006019205314960629,773.3374464936849,0.00025370340306410486,25.0,90.0
176.86157,0.006175336811023622,776.1040532685091,0.00025370340306410486,25.0,90.0
178.16284,0.0063754265748031495,779.822993182899,0.00025370340306410486,25.0,90.0
179.46411,0.006573182283464567,778.3367066532791,0.00025370340306410486,25.0,90.0
180.76538,0.0067606832677165355,781.0253923796438,0.00025370340306410486,25.0,90.0
182.06665,0.006974697440944882,780.2879828779792,0.00025370340306410486,25.0,90.0
183.36792,0.007219536417322835,782.4522010252074,0.00025370340306410486,25.0,90.0
184.66919,0.007450599606299212,784.6718807800031,0.00025370340306410486,25.0,90.0
185.97046,0.007641189370078741,786.236801775617,0.00025370340306410486,25.0,90.0
187.27173,0.007893329921259844,787.6363155947788,0.00025370340306410486,25.0,90.0
188.573,0.008132781692913387,788.5521587486128,0.00025370340306410486,25.0,90.0
189.87427,0.008353079133858268,788.6879458859588,0.00025370340306410486,25.0,90.0
191.17554,0.008621590354330709,791.9742377001531,0.00025370340306410486,25.0,90.0
192.47681,0.008844967716535432,793.3047349785975,0.00025370340306410486,25.0,90.0
193.77808,0.009066467716535433,792.9203878877556,0.00025370340306410486,25.0,90.0
195.07935,0.009328239763779528,795.7027691169476,0.00025370340306410486,25.0,90.0
196.38062,0.009597939763779527,796.4736563969772,0.00025370340306410486,25.0,90.0
197.68188,0.009784477952755905,795.9699043492046,0.00025370340306410486,25.0,90.0
198.98315,0.01002858996062992,799.2449135972097,0.00025370340306410486,25.0,90.0
200.28442,0.010288563976377953,802.8647677429583,0.00025370340306410486,25.0,90.0
201.58569,0.010588959448818899,801.5061301062199,0.00025370340306410486,25.0,90.0
202.88696,0.010855380118110236,803.3663795381282,0.00025370340306410486,25.0,90.0
204.18823,0.011119509842519686,802.8080642604239,0.00025370340306410486,25.0,90.0
205.4895,0.011318381496062992,803.7862125455795,0.00025370340306410486,25.0,90.0
206.79077,0.011586941338582677,805.8746234740792,0.00025370340306410486,25.0,90.0
208.09204,0.011855986417322835,807.1939703006923,0.00025370340306410486,25.0,90.0
209.39331,0.012108437992125983,807.9952174602336,0.00025370340306410486,25.0,90.0
210.69458,0.012398949606299212,810.0159065687259,0.00025370340306410486,25.0,90.0
211.99585,0.012657446653543307,808.9582254399407,0.00025370340306410486,25.0,90.0
213.29712,0.01292186023622047,810.9606299212597,0.00025370340306410486,25.0,90.0
214.59839,0.013223400393700787,813.3000581303177,0.00025370340306410486,25.0,90.0
215.89966,0.013514009842519685,813.0838926174496,0.00025370340306410486,25.0,90.0
217.20093,0.013765763188976377,814.0993764202293,0.00025370340306410486,25.0,90.0
218.5022,0.013989802559055117,813.3945463192939,0.00025370340306410486,25.0,90.0
219.80347,0.014266088582677165,815.5792157691697,0.00025370340306410486,25.0,90.0
221.10474,0.014536849803149607,816.1070918987475,0.00025370340306410486,25.0,90.0
222.40601,0.014823988976377952,818.0435184695873,0.00025370340306410486,25.0,90.0
223.70728,0.01507818149606299,817.8345928235481,0.00025370340306410486,25.0,90.0
225.00854,0.015349131692913385,818.6395920308619,0.00025370340306410486,25.0,90.0
226.30981,0.01564176062992126,820.9732072081592,0.00025370340306410486,25.0,90.0
227.61108,0.015921789566929134,821.0704697986577,0.00025370340306410486,25.0,90.0
228.91235,0.016165493897637793,820.3448184748719,0.00025370340306410486,25.0,90.0
230.21362,0.016450619488188975,822.5900491465412,0.00025370340306410486,25.0,90.0
231.51489,0.016736353543307086,823.0491729641177,0.00025370340306410486,25.0,90.0
232.81616,0.017016439763779527,823.5152988426781,0.00025370340306410486,25.0,90.0
234.11743,0.01729400905511811,827.5349838820482,0.00025370340306410486,25.0,90.0
235.4187,0.01763826830708661,824.699307720763,0.00025370340306410486,25.0,90.0
236.71997,0.017924751968503936,827.3758389261744,0.00025370340306410486,25.0,90.0
238.02124,0.01826051653543307,827.3328224911482,0.00025370340306410486,25.0,90.0
239.32251,0.01853088464566929,826.3417005760186,0.00025370340306410486,25.0,90.0
240.62378,0.01875707874015748,827.8381070654758,0.00025370340306410486,25.0,90.0
241.92505,0.018998965944881888,828.8094910954921,0.00025370340306410486,25.0,90.0
243.22632,0.01932129724409449,831.619748454262,0.00025370340306410486,25.0,90.0
244.52759,0.019593893307086614,830.5402684563759,0.00025370340306410486,25.0,90.0
245.82886,0.01983722440944882,831.8549648575806,0.00025370340306410486,25.0,90.0
247.13013,0.02013326377952756,833.8097024784653,0.00025370340306410486,25.0,90.0
248.4314,0.020401279527559053,832.7253078264546,0.00025370340306410486,25.0,90.0
249.73267,0.020728206692913385,836.2200760978702,0.00025370340306410486,25.0,90.0
251.03394,0.021012037401574805,833.6465148232309,0.00025370340306410486,25.0,90.0
252.33521,0.0212719468503937,835.0777096654864,0.00025370340306410486,25.0,90.0
253.63647,0.021534877952755903,836.0568884426359,0.00025370340306410486,25.0,90.0
254.93774,0.021823588582677165,838.4903556518523,0.00025370340306410486,25.0,90.0
256.23901,0.02210449212598425,840.0488294667864,0.00025370340306410486,25.0,90.0
257.54028,0.0224311437007874,838.646065634413,0.00025370340306410486,25.0,90.0
258.84155,0.022710078740157482,838.4205464249854,0.00025370340306410486,25.0,90.0
260.14282,0.0229766594488189,839.0667970195001,0.00025370340306410486,25.0,90.0
261.44409,0.023259001968503938,842.2037467631982,0.00025370340306410486,25.0,90.0
262.74536,0.023528208661417322,840.6669397030068,0.00025370340306410486,25.0,90.0
264.04663,0.023759574803149604,842.9796543888389,0.00025370340306410486,25.0,90.0
265.3479,0.02404214566929134,843.5748295724779,0.00025370340306410486,25.0,90.0
266.64917,0.024383163385826773,844.7240395286159,0.00025370340306410486,25.0,90.0
267.95044,0.024684049212598425,845.4253289647519,0.00025370340306410486,25.0,90.0
269.25171,0.024992503937007873,844.8397188606457,0.00025370340306410486,25.0,90.0
270.55298,0.025303318897637796,846.1451144110341,0.00025370340306410486,25.0,90.0
271.85425,0.02556785433070866,847.6335411932569,0.00025370340306410486,25.0,90.0
273.15552,0.025829978346456697,847.4219468371822,0.00025370340306410486,25.0,90.0
274.45679,0.026122017716535436,847.4343920097236,0.00025370340306410486,25.0,90.0
275.75806,0.026360248031496062,848.4064101886593,0.00025370340306410486,25.0,90.0
277.05933,0.026649039370078738,848.5903397981292,0.00025370340306410486,25.0,90.0
278.3606,0.026931220472440946,849.5864027902552,0.00025370340306410486,25.0,90.0
279.66187,0.027207106299212597,849.5951223378956,0.00025370340306410486,25.0,90.0
280.96313,0.027526049212598425,850.9510384188553,0.00025370340306410486,25.0,90.0
282.2644,0.02781517125984252,852.823733023305,0.00025370340306410486,25.0,90.0
283.56567,0.028075803149606296,851.2082914971198,0.00025370340306410486,25.0,90.0
284.86694,0.028409521653543306,853.5174655181526,0.00025370340306410486,25.0,90.0
286.16821,0.02871239566929134,854.4324631400941,0.00025370340306410486,25.0,90.0
287.46948,0.02902809645669291,854.242852613222,0.00025370340306410486,25.0,90.0
288.77075,0.02927681496062992,853.6313216720392,0.00025370340306410486,25.0,90.0
290.07202,0.02954366929133858,855.2335253395339,0.00025370340306410486,25.0,90.0
291.37329,0.02984982677165354,855.8977699096338,0.00025370340306410486,25.0,90.0
292.67456,0.0301719094488189,857.0867991333298,0.00025370340306410486,25.0,90.0
293.97583,0.030476259842519685,857.7470538498123,0.00025370340306410486,25.0,90.0
295.2771,0.030763543307086614,859.0493579242191,0.00025370340306410486,25.0,90.0
296.57837,0.031055431102362207,858.3572372245414,0.00025370340306410486,25.0,90.0
297.87964,0.03133696062992126,860.63214078106,0.00025370340306410486,25.0,90.0
299.18091,0.03160778543307086,858.8853775828356,0.00025370340306410486,25.0,90.0
300.48218,0.03189028543307087,859.948290440205,0.00025370340306410486,25.0,90.0
301.78345,0.03216393307086614,861.5875389737356,0.00025370340306410486,25.0,90.0
303.08472,0.032460442913385824,860.8000581303176,0.00025370340306410486,25.0,90.0
304.38599,0.032775169291338585,864.318765523437,0.00025370340306410486,25.0,90.0
305.68726,0.03307308070866142,863.2532103789039,0.00025370340306410486,25.0,90.0
306.98853,0.033365616141732286,862.5796121122443,0.00025370340306410486,25.0,90.0
308.28979,0.033657694881889764,862.3196374782011,0.00025370340306410486,25.0,90.0
309.59106,0.03388363385826772,862.8256618929345,0.00025370340306410486,25.0,90.0
310.89233,0.03415961811023622,864.2183321883422,0.00025370340306410486,25.0,90.0
312.1936,0.034393328740157485,866.059794958516,0.00025370340306410486,25.0,90.0
313.49487,0.03469745275590551,867.2231675738518,0.00025370340306410486,25.0,90.0
314.79614,0.03498172834645669,867.5936426570839,0.00025370340306410486,25.0,90.0
316.09741,0.03528163779527559,867.6972467367754,0.00025370340306410486,25.0,90.0
317.39868,0.03556875196850393,868.3744649368492,0.00025370340306410486,25.0,90.0
318.69995,0.035859336614173225,868.9685832056227,0.00025370340306410486,25.0,90.0
320.00122,0.0361826062992126,869.609602071553,0.00025370340306410486,25.0,90.0
321.30249,0.03646894094488189,869.8317655762827,0.00025370340306410486,25.0,90.0
322.60376,0.03674991929133858,869.2617185435712,0.00025370340306410486,25.0,90.0
323.90503,0.03704753346456693,872.0416688685726,0.00025370340306410486,25.0,90.0
325.2063,0.03735590354330708,871.8810970776303,0.00025370340306410486,25.0,90.0
326.50757,0.03761597834645669,871.9582518628124,0.00025370340306410486,25.0,90.0
327.80884,0.037903352362204726,873.8518469587275,0.00025370340306410486,25.0,90.0
329.11011,0.03822762401574803,874.956745759129,0.00025370340306410486,25.0,90.0
330.41138,0.03851949212598425,873.9566136447709,0.00025370340306410486,25.0,90.0
331.71265,0.03881324606299213,874.6999947154256,0.00025370340306410486,25.0,90.0
333.01392,0.03908406889763779,874.8072979971463,0.00025370340306410486,25.0,90.0
334.31519,0.039404986220472435,876.2900967077101,0.00025370340306410486,25.0,90.0
335.61646,0.03970532086614173,876.2677693811763,0.00025370340306410486,25.0,90.0
336.91772,0.03996476968503937,874.5926650108333,0.00025370340306410486,25.0,90.0
338.21899,0.040238273622047245,877.9690588173122,0.00025370340306410486,25.0,90.0
339.52026,0.04051858661417323,877.4792580457644,0.00025370340306410486,25.0,90.0
340.82153,0.04080093897637795,877.0353538022512,0.00025370340306410486,25.0,90.0
342.1228,0.04107982283464567,879.4505099614225,0.00025370340306410486,25.0,90.0
343.42407,0.041289844488188975,878.2383343021719,0.00025370340306410486,25.0,90.0
344.72534,0.04159027952755905,881.567748242879,0.00025370340306410486,25.0,90.0
346.02661,0.04189728346456693,879.8782169846218,0.00025370340306410486,25.0,90.0
347.32788,0.042177877952755904,880.8244200179676,0.00025370340306410486,25.0,90.0
348.62915,0.042520801181102366,882.1172382814564,0.00025370340306410486,25.0,90.0
349.93042,0.04282349015748031,881.1704539449347,0.00025370340306410486,25.0,90.0
351.23169,0.043111726377952755,881.7192834117211,0.00025370340306410486,25.0,90.0
352.53296,0.04341077362204725,882.0529250118904,0.00025370340306410486,25.0,90.0
353.83423,0.04371324803149606,884.325186281245,0.00025370340306410486,25.0,90.0
355.1355,0.04398523228346456,883.5061301062199,0.00025370340306410486,25.0,90.0
356.43677,0.0442555748031496,882.8956825027744,0.00025370340306410486,25.0,90.0
357.73804,0.04451942125984252,884.6930983459282,0.00025370340306410486,25.0,90.0
359.03931,0.0448012657480315,884.2198647148972,0.00025370340306410486,25.0,90.0
360.34058,0.04510687007874016,886.6698990646303,0.00025370340306410486,25.0,90.0
361.64185,0.04541241535433071,886.3775564128309,0.00025370340306410486,25.0,90.0
362.94312,0.045688637795275586,885.7873487290599,0.00025370340306410486,25.0,90.0
364.24438,0.04599427952755906,887.0783173915341,0.00025370340306410486,25.0,90.0
365.54565,0.046357072834645664,890.3425196850393,0.00025370340306410486,25.0,90.0
366.84692,0.04665818503937008,887.4511176874703,0.00025370340306410486,25.0,90.0
368.14819,0.04691468897637795,886.9147069703536,0.00025370340306410486,25.0,90.0
369.44946,0.04715885433070866,888.4138350155895,0.00025370340306410486,25.0,90.0
370.75073,0.04745767322834646,891.6959255931934,0.00025370340306410486,25.0,90.0
372.052,0.047728897637795274,892.6948422554564,0.00025370340306410486,25.0,90.0
373.35327,0.04802036220472441,891.4244834328595,0.00025370340306410486,25.0,90.0
374.65454,0.048301862204724405,891.6261956349416,0.00025370340306410486,25.0,90.0
375.95581,0.04862247637795275,892.4403635787137,0.00025370340306410486,25.0,90.0
377.25708,0.048944797244094486,892.5848702637003,0.00025370340306410486,25.0,90.0
378.55835,0.049237948818897634,892.8843206679702,0.00025370340306410486,25.0,90.0
379.85962,0.04956120866141732,895.4235057866089,0.00025370340306410486,25.0,90.0
381.16089,0.04983549015748032,891.5249696136975,0.00025370340306410486,25.0,90.0
382.46216,0.050132921259842526,895.1010939068858,0.00025370340306410486,25.0,90.0
383.76343,0.05040259645669291,893.1125350103049,0.00025370340306410486,25.0,90.0
385.0647,0.050643620078740154,891.6377952755905,0.00025370340306410486,25.0,90.0
386.36597,0.05093141141732284,896.0560164878718,0.00025370340306410486,25.0,90.0
387.66724,0.05118068897637795,895.3919568778734,0.00025370340306410486,25.0,90.0
388.96851,0.051491525590551174,897.7194419489509,0.00025370340306410486,25.0,90.0
390.26978,0.05177711811023622,897.1427363525868,0.00025370340306410486,25.0,90.0
391.57104,0.05211062795275591,897.5669555567299,0.00025370340306410486,25.0,90.0
392.87231,0.0524329625984252,898.4960101463827,0.00025370340306410486,25.0,90.0
394.17358,0.05274507086614173,898.5869048248163,0.00025370340306410486,25.0,90.0
395.47485,0.05303787992125984,898.5560693336151,0.00025370340306410486,25.0,90.0
396.77612,0.053284692913385834,898.1638482270253,0.00025370340306410486,25.0,90.0
398.07739,0.053558187007874014,898.5461871796227,0.00025370340306410486,25.0,90.0
399.37866,0.05384421456692914,900.7628547270516,0.00025370340306410486,25.0,90.0
400.67993,0.054168261811023626,901.0011626063521,0.00025370340306410486,25.0,90.0
401.9812,0.05449674409448819,903.0675104370342,0.00025370340306410486,25.0,90.0
403.28247,0.054759273622047244,900.7922633831844,0.00025370340306410486,25.0,90.0
404.58374,0.055011496062992125,900.3124504571157,0.00025370340306410486,25.0,90.0
405.88501,0.05532686220472441,905.8562331554193,0.00025370340306410486,25.0,90.0
407.18628,0.05567000393700787,903.8412778100724,0.00025370340306410486,25.0,90.0
408.48755,0.055983415354330705,904.4503250013211,0.00025370340306410486,25.0,90.0
409.78882,0.05628337007874015,904.2818791946308,0.00025370340306410486,25.0,90.0
411.09009,0.056593143700787406,904.2143951804683,0.00025370340306410486,25.0,90.0
412.39136,0.05684861023622047,902.7096126407017,0.00025370340306410486,25.0,90.0
413.69263,0.05711446062992126,905.9874227131005,0.00025370340306410486,25.0,90.0
414.9939,0.057425173228346456,908.0886223114727,0.00025370340306410486,25.0,90.0
416.29517,0.05773562204724409,907.5886223114727,0.00025370340306410486,25.0,90.0
417.59644,0.05803534645669291,907.8197431696876,0.00025370340306410486,25.0,90.0
418.89771,0.05832074015748031,908.1227342387571,0.00025370340306410486,25.0,90.0
420.19897,0.05858568700787401,906.4934471278337,0.00025370340306410486,25.0,90.0
421.50024,0.058880066929133855,909.1708238651377,0.00025370340306410486,25.0,90.0
422.80151,0.05917058661417322,905.7345558315277,0.00025370340306410486,25.0,90.0
424.10278,0.059456267716535435,907.2732917613486,0.00025370340306410486,25.0,90.0
425.40405,0.0597398937007874,909.7874544205464,0.00025370340306410486,25.0,90.0
426.70532,0.0600450216535433,911.1484172699888,0.00025370340306410486,25.0,90.0
428.00659,0.060306318897637795,909.5687787348728,0.00025370340306410486,25.0,90.0
429.30786,0.06058345078740158,910.9778576335675,0.00025370340306410486,25.0,90.0
430.60913,0.06090099803149606,911.6152565660835,0.00025370340306410486,25.0,90.0
431.9104,0.06118980511811024,911.2790519473656,0.00025370340306410486,25.0,90.0
433.21167,0.06146787598425197,910.5523437087141,0.00025370340306410486,25.0,90.0
434.51294,0.06176593503937008,913.6243196110553,0.00025370340306410486,25.0,90.0
435.81421,0.062116816929133865,913.9430587116207,0.00025370340306410486,25.0,90.0
437.11548,0.062418417322834645,914.6913015906567,0.00025370340306410486,25.0,90.0
438.41675,0.06269209448818898,913.9993130053374,0.00025370340306410486,25.0,90.0
439.71802,0.06304070669291338,916.1858584790995,0.00025370340306410486,25.0,90.0
441.01929,0.06336299409448819,915.2575701527242,0.00025370340306410486,25.0,90.0
442.32056,0.06366878346456692,914.8352269724674,0.00025370340306410486,25.0,90.0
443.62183,0.06397882283464568,914.7872958833165,0.00025370340306410486,25.0,90.0
444.9231,0.06429093700787401,916.1338582677165,0.00025370340306410486,25.0,90.0
446.22437,0.064596,915.6710616709823,0.00025370340306410486,25.0,90.0
447.52563,0.06494188188976378,916.4683453997781,0.00025370340306410486,25.0,90.0
448.8269,0.06523887992125985,918.0106748401415,0.00025370340306410486,25.0,90.0
450.12817,0.06553016141732283,918.047323363103,0.00025370340306410486,25.0,90.0
451.42944,0.06577992716535433,916.9446176610473,0.00025370340306410486,25.0,90.0
452.73071,0.06606608661417322,917.1108967922634,0.00025370340306410486,25.0,90.0
454.03198,0.06634834645669291,916.608439465201,0.00025370340306410486,25.0,90.0
455.33325,0.06660311023622047,919.1624213919569,0.00025370340306410486,25.0,90.0
456.63452,0.06688098818897638,917.5688051577446,0.00025370340306410486,25.0,90.0
457.93579,0.06716843897637796,919.6924906198806,0.00025370340306410486,25.0,90.0
459.23706,0.06745188385826772,920.3261110817524,0.00025370340306410486,25.0,90.0
460.53833,0.06775166732283465,919.5383924324896,0.00025370340306410486,25.0,90.0
461.8396,0.06803822047244094,920.3757068118163,0.00025370340306410486,25.0,90.0
463.14087,0.06831922440944882,921.7391798340643,0.00025370340306410486,25.0,90.0
464.44214,0.06864866338582677,923.5205834170057,0.00025370340306410486,25.0,90.0
465.74341,0.0689804311023622,923.4189082069439,0.00025370340306410486,25.0,90.0
467.04468,0.06933536614173229,923.198435765999,0.00025370340306410486,25.0,90.0
468.34595,0.06964639566929134,923.2028219626908,0.00025370340306410486,25.0,90.0
469.64722,0.06992297637795275,922.4596786978808,0.00025370340306410486,25.0,90.0
470.94849,0.07020764763779527,922.8776885271891,0.00025370340306410486,25.0,90.0
472.24976,0.07054857874015748,924.7803730909475,0.00025370340306410486,25.0,90.0
473.55103,0.0708879625984252,923.292289806056,0.00025370340306410486,25.0,90.0
474.85229,0.07119006889763779,925.6604660994557,0.00025370340306410486,25.0,90.0
476.15356,0.07144702559055119,923.31752364847,0.00025370340306410486,25.0,90.0
477.45483,0.07171422047244094,924.8862495375997,0.00025370340306410486,25.0,90.0
478.7561,0.07198993897637795,925.6506632140781,0.00025370340306410486,25.0,90.0
480.05737,0.07230459448818898,928.2299846747345,0.00025370340306410486,25.0,90.0
481.35864,0.07261278937007874,926.8789832478993,0.00025370340306410486,25.0,90.0
482.65991,0.07289611614173228,927.6803889446704,0.00025370340306410486,25.0,90.0
483.96118,0.07323637992125984,927.9545526607831,0.00025370340306410486,25.0,90.0
485.26245,0.07361477559055118,928.016989906463,0.00025370340306410486,25.0,90.0
486.56372,0.07394183858267717,926.7339745283517,0.00025370340306410486,25.0,90.0
487.86499,0.07430199409448819,929.0034085504412,0.00025370340306410486,25.0,90.0
489.16626,0.0745596968503937,926.9281297891455,0.00025370340306410486,25.0,90.0
490.46753,0.07483752755905512,928.4846218887068,0.00025370340306410486,25.0,90.0
491.7688,0.07507280708661418,927.3477778364953,0.00025370340306410486,25.0,90.0
493.07007,0.07533189960629921,928.9514083390583,0.00025370340306410486,25.0,90.0
494.37134,0.07564971062992125,930.4243248956296,0.00025370340306410486,25.0,90.0
495.67261,0.07597411614173229,931.1016223643186,0.00025370340306410486,25.0,90.0
496.97388,0.07629583464566929,931.0815409818739,0.00025370340306410486,25.0,90.0
498.27515,0.07658789173228346,931.7277387306452,0.00025370340306410486,25.0,90.0
499.57642,0.07691751771653543,932.2625904983353,0.00025370340306410486,25.0,90.0
500.87769,0.0772241594488189,932.6746023357817,0.00025370340306410486,25.0,90.0
502.17896,0.07748726377952757,930.3586112138667,0.00025370340306410486,25.0,90.0
503.48022,0.0777680688976378,932.8714791523543,0.00025370340306410486,25.0,90.0
504.78149,0.07808698228346457,933.6948158325846,0.00025370340306410486,25.0,90.0
506.08276,0.07837624212598425,933.8252391269883,0.00025370340306410486,25.0,90.0
507.38403,0.07870616141732284,933.7264175870633,0.00025370340306410486,25.0,90.0
508.6853,0.0790410748031496,933.8225968398245,0.00025370340306410486,25.0,90.0
509.98657,0.07938538976377953,935.7298789832479,0.00025370340306410486,25.0,90.0
511.28784,0.07971759251968503,934.7491412566718,0.00025370340306410486,25.0,90.0
512.58911,0.08002061417322834,934.9072557205517,0.00025370340306410486,25.0,90.0
513.89038,0.08038490748031496,937.3197695925593,0.00025370340306410486,25.0,90.0
515.19165,0.08069067322834646,934.9942662368545,0.00025370340306410486,25.0,90.0
516.49292,0.0810083090551181,938.234238757068,0.00025370340306410486,25.0,90.0
517.79419,0.08132761023622047,936.5310732970459,0.00025370340306410486,25.0,90.0
519.09546,0.08166349606299213,938.2784970670613,0.00025370340306410486,25.0,90.0
520.39673,0.08196011811023622,937.2142894889816,0.00025370340306410486,25.0,90.0
521.698,0.08224195472440946,938.7556677059662,0.00025370340306410486,25.0,90.0
522.99927,0.08256912401574804,938.4186175553558,0.00025370340306410486,25.0,90.0
524.30054,0.08286847834645669,937.6081223907414,0.00025370340306410486,25.0,90.0
525.60181,0.08319010826771653,937.7527347672144,0.00025370340306410486,25.0,90.0
526.90308,0.08348812007874015,938.296887385721,0.00025370340306410486,25.0,90.0
528.20435,0.0837829409448819,938.5621465940918,0.00025370340306410486,25.0,90.0
529.50562,0.08406021850393701,937.4849653860381,0.00025370340306410486,25.0,90.0
530.80688,0.08434262598425196,940.7356920150082,0.00025370340306410486,25.0,90.0
532.10815,0.08470339173228347,939.9148390847117,0.00025370340306410486,25.0,90.0
533.40942,0.0850254625984252,940.3511599640649,0.00025370340306410486,25.0,90.0
534.71069,0.08531470275590551,940.8921418379749,0.00025370340306410486,25.0,90.0
536.01196,0.08562293503937009,940.9890345082703,0.00025370340306410486,25.0,90.0
537.31323,0.08593089566929134,941.3545420916345,0.00025370340306410486,25.0,90.0
538.6145,0.08626383070866141,941.1665697828039,0.00025370340306410486,25.0,90.0
539.91577,0.08657870866141733,943.9027109866299,0.00025370340306410486,25.0,90.0
541.21704,0.08691763385826771,942.1121386672304,0.00025370340306410486,25.0,90.0
542.51831,0.08720480511811024,941.998467473445,0.00025370340306410486,25.0,90.0
543.81958,0.08760639566929133,944.8313692332082,0.00025370340306410486,25.0,90.0
545.12085,0.08798203543307087,945.1123236273318,0.00025370340306410486,25.0,90.0
546.42212,0.08833868897637795,944.3203508957353,0.00025370340306410486,25.0,90.0
547.72339,0.08866118700787401,944.6119272842573,0.00025370340306410486,25.0,90.0
549.02466,0.08894135236220473,943.7454949003858,0.00025370340306410486,25.0,90.0
550.32593,0.08927627755905511,945.4003593510542,0.00025370340306410486,25.0,90.0
551.6272,0.08957808464566928,945.0935369655973,0.00025370340306410486,25.0,90.0
552.92847,0.08990972834645669,946.2882471066956,0.00025370340306410486,25.0,90.0
554.22974,0.09021089566929134,945.704195952016,0.00025370340306410486,25.0,90.0
555.53101,0.09048504921259842,946.3912170374675,0.00025370340306410486,25.0,90.0
556.83228,0.0908147283464567,946.676848279871,0.00025370340306410486,25.0,90.0
558.13354,0.09121646653543307,947.2110394757701,0.00025370340306410486,25.0,90.0
559.43481,0.0915922283464567,944.9740791629233,0.00025370340306410486,25.0,90.0
560.73608,0.09189839960629921,945.4191195899169,0.00025370340306410486,25.0,90.0
562.03735,0.09219281496062992,947.4092902816677,0.00025370340306410486,25.0,90.0
563.33862,0.09255400984251969,949.0873011678909,0.00025370340306410486,25.0,90.0
564.63989,0.09287073622047244,946.5466099455688,0.00025370340306410486,25.0,90.0
565.94116,0.09313819488188976,947.6015959414469,0.00025370340306410486,25.0,90.0
567.24243,0.09346085826771652,948.1923056597791,0.00025370340306410486,25.0,90.0
568.5437,0.09378563779527559,949.9450668498652,0.00025370340306410486,25.0,90.0
569.84497,0.09411764566929134,948.1762405538233,0.00025370340306410486,25.0,90.0
571.14624,0.09441669094488188,948.3795645510753,0.00025370340306410486,25.0,90.0
572.44751,0.09473746456692914,949.6098927231411,0.00025370340306410486,25.0,90.0
573.74878,0.0950886220472441,949.7826983036516,0.00025370340306410486,25.0,90.0
575.05005,0.09546170866141732,950.6777730803784,0.00025370340306410486,25.0,90.0
576.35132,0.09579084251968503,950.7116207789462,0.00025370340306410486,25.0,90.0
577.65259,0.09609886220472441,949.3350155894943,0.00025370340306410486,25.0,90.0
578.95386,0.09638963976377952,950.4208106537018,0.00025370340306410486,25.0,90.0
580.25513,0.09680149212598425,951.5720551709559,0.00025370340306410486,25.0,90.0
581.5564,0.0971668405511811,950.7694340220895,0.00025370340306410486,25.0,90.0
582.85767,0.09747956496062991,951.4048512392326,0.00025370340306410486,25.0,90.0
584.15894,0.09783847244094487,951.3746498969508,0.00025370340306410486,25.0,90.0
585.46021,0.09818181496062993,952.84495058923,0.00025370340306410486,25.0,90.0
586.76147,0.098522687007874,952.3211171590128,0.00025370340306410486,25.0,90.0
588.06274,0.09885666141732283,953.4223696031283,0.00025370340306410486,25.0,90.0
589.36401,0.09919483661417323,952.0612217935845,0.00025370340306410486,25.0,90.0
590.66528,0.09950045078740156,953.0992443058711,0.00025370340306410486,25.0,90.0
591.96655,0.09982910826771654,953.1089679226337,0.00025370340306410486,25.0,90.0
593.26782,0.10012841141732283,950.9447761982772,0.00025370340306410486,25.0,90.0
594.56909,0.10046757086614173,953.4648047349785,0.00025370340306410486,25.0,90.0
595.87036,0.10086071456692913,953.4361623421232,0.00025370340306410486,25.0,90.0
597.17163,0.10114016535433071,951.6890028008244,0.00025370340306410486,25.0,90.0
598.4729,0.10144989763779529,953.6458806743117,0.00025370340306410486,25.0,90.0
599.77417,0.10174423622047245,953.7287163768957,0.00025370340306410486,25.0,90.0
601.07544,0.10206654724409449,955.7286899540242,0.00025370340306410486,25.0,90.0
602.37671,0.10245702952755906,956.4089203614649,0.00025370340306410486,25.0,90.0
603.67798,0.10277114960629921,956.6545209533372,0.00025370340306410486,25.0,90.0
604.97925,0.10310749409448819,956.7302489034508,0.00025370340306410486,25.0,90.0
606.28052,0.10342592125984253,956.1021243988797,0.00025370340306410486,25.0,90.0
607.58179,0.10372415551181102,955.0968926702953,0.00025370340306410486,25.0,90.0
608.88306,0.10404091732283463,957.1346509538656,0.00025370340306410486,25.0,90.0
610.18433,0.10442257480314959,956.5562014479733,0.00025370340306410486,25.0,90.0
611.4856,0.10481771259842519,957.2719970406383,0.00025370340306410486,25.0,90.0
612.78687,0.10514207677165353,957.902129683454,0.00025370340306410486,25.0,90.0
614.08813,0.10547138188976378,957.5254452253871,0.00025370340306410486,25.0,90.0
615.3894,0.10587817125984253,958.5834698515034,0.00025370340306410486,25.0,90.0
616.69067,0.10631300393700788,957.9986260106748,0.00025370340306410486,25.0,90.0
617.99194,0.1066936279527559,958.1766104740262,0.00025370340306410486,25.0,90.0
619.29321,0.10703041732283464,958.9496908524018,0.00025370340306410486,25.0,90.0
620.59448,0.107312437007874,955.5501241874966,0.00025370340306410486,25.0,90.0
621.89575,0.10762328543307086,960.2135496485757,0.00025370340306410486,25.0,90.0
623.19702,0.10800532874015749,959.5367013687047,0.00025370340306410486,25.0,90.0
624.49829,0.1083401594488189,961.158986418644,0.00025370340306410486,25.0,90.0
625.79956,0.10868586614173227,959.7170110447603,0.00025370340306410486,25.0,90.0
627.10083,0.10904770669291339,959.9077577551128,0.00025370340306410486,25.0,90.0
628.4021,0.10939355511811025,958.0446810759393,0.00025370340306410486,25.0,90.0
629.70337,0.10974263976377954,958.3349098980076,0.00025370340306410486,25.0,90.0
631.00464,0.11003192322834646,962.4465201078053,0.00025370340306410486,25.0,90.0
632.30591,0.11041438976377954,961.6551815251281,0.00025370340306410486,25.0,90.0
633.60718,0.11074301377952757,959.4698250805897,0.00025370340306410486,25.0,90.0
634.90845,0.11112074015748033,960.4459123817576,0.00025370340306410486,25.0,90.0
636.20972,0.11145194488188975,960.7196797547957,0.00025370340306410486,25.0,90.0
637.51099,0.11180421062992126,962.6308196374781,0.00025370340306410486,25.0,90.0
638.81226,0.11221537598425195,962.8475136077788,0.00025370340306410486,25.0,90.0
640.11353,0.11263033267716534,962.2457062833588,0.00025370340306410486,25.0,90.0
641.41479,0.11292247834645668,960.2096126407018,0.00025370340306410486,25.0,90.0
642.71606,0.11325572440944882,962.1142260740897,0.00025370340306410486,25.0,90.0
644.01733,0.11361444291338582,963.4522802938224,0.00025370340306410486,25.0,90.0
645.3186,0.11399391929133858,962.1105004491887,0.00025370340306410486,25.0,90.0
646.61987,0.11437995275590551,963.7520477725519,0.00025370340306410486,25.0,90.0
647.92114,0.11481848031496063,963.5576282830417,0.00025370340306410486,25.0,90.0
649.22241,0.11520062992125985,964.8193468266131,0.00025370340306410486,25.0,90.0
650.52368,0.11555051377952756,962.5146382708872,0.00025370340306410486,25.0,90.0
651.82495,0.11598403346456693,965.2014479733657,0.00025370340306410486,25.0,90.0
653.12622,0.11631823031496064,962.0234635100142,0.00025370340306410486,25.0,90.0
654.42749,0.11663568307086614,963.031865983195,0.00025370340306410486,25.0,90.0
655.72876,0.11700039763779528,964.6758177878771,0.00025370340306410486,25.0,90.0
657.03003,0.11733730511811023,963.1985678803572,0.00025370340306410486,25.0,90.0
658.3313,0.117641968503937,963.8097817470803,0.00025370340306410486,25.0,90.0
659.63257,0.11805232677165353,963.9131215980552,0.00025370340306410486,25.0,90.0
660.93384,0.11846833858267716,966.14133594039,0.00025370340306410486,25.0,90.0
662.23511,0.11883018897637795,965.3342757490884,0.00025370340306410486,25.0,90.0
663.53638,0.11924312795275592,964.7088463774243,0.00025370340306410486,25.0,90.0
664.83765,0.11955110039370079,965.5491993869894,0.00025370340306410486,25.0,90.0
666.13892,0.11997562007874016,966.2993182899116,0.00025370340306410486,25.0,90.0
667.44019,0.12033870275590552,965.8972942979443,0.00025370340306410486,25.0,90.0
668.74146,0.12077422834645668,966.9322253342493,0.00025370340306410486,25.0,90.0
670.04272,0.1211482125984252,965.5235956243724,0.00025370340306410486,25.0,90.0
671.34399,0.12145042322834647,964.3943613591924,0.00025370340306410486,25.0,90.0
672.64526,0.12180686614173229,968.0125508640278,0.00025370340306410486,25.0,90.0
673.94653,0.12218579133858268,965.3833430217196,0.00025370340306410486,25.0,90.0
675.2478,0.12254848818897637,966.0274005178883,0.00025370340306410486,25.0,90.0
676.54907,0.12294142125984253,968.1945251809966,0.00025370340306410486,25.0,90.0
677.85034,0.12329600984251968,967.7601860170163,0.00025370340306410486,25.0,90.0
679.15161,0.12369956102362203,966.7457855519737,0.00025370340306410486,25.0,90.0
680.45288,0.12408491338582678,967.5637583892617,0.00025370340306410486,25.0,90.0
681.75415,0.12448069881889763,964.8739893251599,0.00025370340306410486,25.0,90.0
683.05542,0.12485693503937008,968.8573429160281,0.00025370340306410486,25.0,90.0
684.35669,0.12521606496062992,966.3171273053955,0.00025370340306410486,25.0,90.0
685.65796,0.12560291929133857,968.1821328541986,0.00025370340306410486,25.0,90.0
686.95923,0.12604584842519684,970.5741954235585,0.00025370340306410486,25.0,90.0
688.2605,0.1264531318897638,970.0818052105902,0.00025370340306410486,25.0,90.0
689.56177,0.12687585433070864,969.2649949796543,0.00025370340306410486,25.0,90.0
690.86304,0.12721560039370078,968.6946044496116,0.00025370340306410486,25.0,90.0
692.16431,0.12757728937007873,969.4280769434022,0.00025370340306410486,25.0,90.0
693.46558,0.1279783405511811,967.9059874227131,0.00025370340306410486,25.0,90.0
694.76685,0.1284401594488189,969.4365058394545,0.00025370340306410486,25.0,90.0
696.06812,0.1288764468503937,969.8597738202187,0.00025370340306410486,25.0,90.0
697.36938,0.12925499606299212,968.7980764149447,0.00025370340306410486,25.0,90.0
698.67065,0.1296327342519685,969.729139142842,0.00025370340306410486,25.0,90.0
699.97192,0.12996890157480315,968.8758125033029,0.00025370340306410486,25.0,90.0
701.27319,0.1303805846456693,971.3513977699096,0.00025370340306410486,25.0,90.0
702.57446,0.13081288188976378,970.4393066638481,0.00025370340306410486,25.0,90.0
703.87573,0.13113049999999998,968.4890080853986,0.00025370340306410486,25.0,90.0
705.177,0.13148040748031495,968.4341013581355,0.00025370340306410486,25.0,90.0
706.47827,0.13186183070866142,968.6543359932357,0.00025370340306410486,25.0,90.0
707.77954,0.1323001594488189,972.7722084236115,0.00025370340306410486,25.0,90.0
709.08081,0.1327603346456693,970.8984304814246,0.00025370340306410486,25.0,90.0
710.38208,0.13314526574803148,970.8395339005443,0.00025370340306410486,25.0,90.0
711.68335,0.1334626377952756,971.1406489457274,0.00025370340306410486,25.0,90.0
712.98462,0.13379607086614173,970.2226919621623,0.00025370340306410486,25.0,90.0
714.28589,0.13422799409448818,973.0901019922845,0.00025370340306410486,25.0,90.0
715.58716,0.13474824409448818,971.780188130846,0.00025370340306410486,25.0,90.0
716.88843,0.1351923346456693,970.7837816413887,0.00025370340306410486,25.0,90.0
718.1897,0.13555896062992126,971.0906040268455,0.00025370340306410486,25.0,90.0
719.49097,0.135934,970.3079057231939,0.00025370340306410486,25.0,90.0
720.79224,0.13634885236220473,972.3111557364053,0.00025370340306410486,25.0,90.0
722.09351,0.13676048818897638,973.9343920097235,0.00025370340306410486,25.0,90.0
723.39478,0.13718698818897637,971.4770649474184,0.00025370340306410486,25.0,90.0
724.69604,0.13765154133858268,970.8981662527084,0.00025370340306410486,25.0,90.0
725.99731,0.13802988976377953,970.1023093589811,0.00025370340306410486,25.0,90.0
727.29858,0.1383872834645669,971.2806901654071,0.00025370340306410486,25.0,90.0
728.59985,0.13885628346456694,973.2790519473656,0.00025370340306410486,25.0,90.0
729.90112,0.1392628503937008,971.3798552026634,0.00025370340306410486,25.0,90.0
731.20239,0.13972344881889764,974.5800877239337,0.00025370340306410486,25.0,90.0
732.50366,0.14014600787401574,972.6581673096232,0.00025370340306410486,25.0,90.0
733.80493,0.14061723622047242,972.5982402367489,0.00025370340306410486,25.0,90.0
735.1062,0.14106042322834644,971.316361042118,0.00025370340306410486,25.0,90.0
736.40747,0.14146640354330708,972.8169687681657,0.00025370340306410486,25.0,90.0
737.70874,0.14193652952755906,973.3340907889868,0.00025370340306410486,25.0,90.0
739.01001,0.14235995669291338,971.4932621677324,0.00025370340306410486,25.0,90.0
740.31128,0.14276361417322833,972.4838556254293,0.00025370340306410486,25.0,90.0
741.61255,0.14314128149606298,973.4534164773028,0.00025370340306410486,25.0,90.0
742.91382,0.14357958661417322,971.5689372721027,0.00025370340306410486,25.0,90.0
744.21509,0.14399814566929134,974.7594197537388,0.00025370340306410486,25.0,90.0
745.51636,0.14447817322834647,974.5739576177139,0.00025370340306410486,25.0,90.0
746.81763,0.14485483267716534,974.4144163187655,0.00025370340306410486,25.0,90.0
748.1189,0.1452894901574803,973.025154573799,0.00025370340306410486,25.0,90.0
749.42017,0.14574983070866143,973.5630978174707,0.00025370340306410486,25.0,90.0
750.72144,0.1462408405511811,973.2797653648998,0.00025370340306410486,25.0,90.0
752.02271,0.14669021062992127,972.3091740210326,0.00025370340306410486,25.0,90.0
753.32397,0.1471005433070866,973.4822702531311,0.00025370340306410486,25.0,90.0
754.62524,0.1475235374015748,972.3796702425619,0.00025370340306410486,25.0,90.0
755.92651,0.14795618700787402,974.215795592665,0.00025370340306410486,25.0,90.0
757.22778,0.14839811811023623,974.1667547429054,0.00025370340306410486,25.0,90.0
758.52905,0.14880865157480316,974.1975373883632,0.00025370340306410486,25.0,90.0
759.83032,0.14924870472440946,972.2907837023727,0.00025370340306410486,25.0,90.0
761.13159,0.1497258937007874,974.1062463668551,0.00025370340306410486,25.0,90.0
762.43286,0.1501665688976378,974.30235692015,0.00025370340306410486,25.0,90.0
763.73413,0.15061468307086615,974.648338001374,0.00025370340306410486,25.0,90.0
765.0354,0.15108887992125983,973.8415156159172,0.00025370340306410486,25.0,90.0
766.33667,0.15149800590551182,973.8631295249168,0.00025370340306410486,25.0,90.0
767.63794,0.1519468937007874,974.5138984304814,0.00025370340306410486,25.0,90.0
768.93921,0.1524418937007874,976.441288379221,0.00025370340306410486,25.0,90.0
770.24048,0.15294027362204726,974.4458331131427,0.00025370340306410486,25.0,90.0
771.54175,0.15343514566929134,975.8031760291708,0.00025370340306410486,25.0,90.0
772.84302,0.15386746653543307,973.3823917983406,0.00025370340306410486,25.0,90.0
774.14429,0.15429058858267716,973.4916767954342,0.00025370340306410486,25.0,90.0
775.44556,0.15468077559055118,973.0042540823337,0.00025370340306410486,25.0,90.0
776.74683,0.15511311023622046,974.3356497384135,0.00025370340306410486,25.0,90.0
778.0481,0.1556317165354331,974.981398298367,0.00025370340306410486,25.0,90.0
779.34937,0.15608960433070865,973.5576811287851,0.00025370340306410486,25.0,90.0
780.65063,0.15663208858267716,974.263779527559,0.00025370340306410486,25.0,90.0
781.9519,0.1571285098425197,974.7085821487078,0.00025370340306410486,25.0,90.0
783.25317,0.15765821653543308,975.3788247106695,0.00025370340306410486,25.0,90.0
784.55444,0.15819628937007874,976.4023146435554,0.00025370340306410486,25.0,90.0
785.45532,0.15857957677165355,977.0590815409818,0.00025370340306410486,25.0,90.0