File: datasets/am_bench_2022/csv/90-XY.07-1.csv
Time(s),Strain(%),Stress(MPa),SR(s-1),Temp(C),Angle(deg)
45.32373,3.4317706692913386e-05,11.368336197916667,0.00025370340306410486,25.0,90.0
47.125488,3.8840431102362204e-05,17.869808333333335,0.00025370340306410486,25.0,90.0
48.526855,5.901735433070866e-05,21.8548296875,0.00025370340306410486,25.0,90.0
49.928223,9.82396594488189e-05,28.194664062500003,0.00025370340306410486,25.0,90.0
51.229492,0.00010802924803149606,32.7964453125,0.00025370340306410486,25.0,90.0
52.530762,7.491313976377952e-05,37.297765625000004,0.00025370340306410486,25.0,90.0
53.832031,0.00011240698031496063,41.3054375,0.00025370340306410486,25.0,90.0
55.133301,0.0001231804960629921,47.53703385416667,0.00025370340306410486,25.0,90.0
56.43457,0.00020160190944881892,53.37155729166667,0.00025370340306410486,25.0,90.0
57.73584,0.00021101397637795277,61.93393489583334,0.00025370340306410486,25.0,90.0
59.037109,0.00019775496062992125,65.55986458333334,0.00025370340306410486,25.0,90.0
60.338379,0.000242451437007874,73.84767447916667,0.00025370340306410486,25.0,90.0
61.639648,0.00017597802952755906,81.32663541666668,0.00025370340306410486,25.0,90.0
62.940918,0.0001777962401574803,88.43017447916667,0.00025370340306410486,25.0,90.0
64.242188,0.00027489094488188976,95.77210677083333,0.00025370340306410486,25.0,90.0
65.543457,0.0002830896062992126,101.15790364583333,0.00025370340306410486,25.0,90.0
66.844727,0.0002719773031496063,108.04639583333334,0.00025370340306410486,25.0,90.0
68.145996,0.00029294435039370077,117.98687760416668,0.00025370340306410486,25.0,90.0
69.447266,0.0003201962598425197,122.92449479166667,0.00025370340306410486,25.0,90.0
70.748535,0.00033192082677165356,133.71880729166668,0.00025370340306410486,25.0,90.0
72.049805,0.00033661234251968505,140.78705989583332,0.00025370340306410486,25.0,90.0
73.351074,0.00038197734251968507,149.03848958333336,0.00025370340306410486,25.0,90.0
74.652344,0.0004021000393700788,157.56487760416667,0.00025370340306410486,25.0,90.0
75.953613,0.00041205153543307085,167.67980208333336,0.00025370340306410486,25.0,90.0
77.254883,0.00043103543307086614,172.3930364583333,0.00025370340306410486,25.0,90.0
78.556152,0.00048190746062992126,183.80177864583334,0.00025370340306410486,25.0,90.0
79.857422,0.0005205691141732284,195.43280729166668,0.00025370340306410486,25.0,90.0
81.158691,0.0005321228937007874,201.77183072916665,0.00025370340306410486,25.0,90.0
82.459961,0.0005677660433070867,211.07362239583333,0.00025370340306410486,25.0,90.0
83.76123,0.0005953567519685039,219.6671796875,0.00025370340306410486,25.0,90.0
85.0625,0.0006200118307086614,230.1559765625,0.00025370340306410486,25.0,90.0
86.36377,0.0006669233858267716,240.46808854166667,0.00025370340306410486,25.0,90.0
87.665039,0.0006747493897637795,247.05436979166666,0.00025370340306410486,25.0,90.0
88.966309,0.0007019440157480315,257.68179947916667,0.00025370340306410486,25.0,90.0
90.267578,0.0007513779921259842,266.9786979166667,0.00025370340306410486,25.0,90.0
91.568848,0.0007882537401574803,277.86953125,0.00025370340306410486,25.0,90.0
92.870117,0.0008239777559055117,286.1877083333334,0.00025370340306410486,25.0,90.0
94.171387,0.0008500051968503938,296.58458333333334,0.00025370340306410486,25.0,90.0
95.472656,0.0008768309448818897,306.1694791666667,0.00025370340306410486,25.0,90.0
96.773926,0.0009202391929133859,316.70393229166666,0.00025370340306410486,25.0,90.0
98.075195,0.0009572192125984251,326.08276041666664,0.00025370340306410486,25.0,90.0
99.376465,0.0009836175196850394,334.33924479166666,0.00025370340306410486,25.0,90.0
100.67773,0.0010127933070866143,344.18697916666673,0.00025370340306410486,25.0,90.0
101.979,0.00102641344488189,353.97924479166664,0.00025370340306410486,25.0,90.0
103.28027,0.001054700905511811,360.33111979166665,0.00025370340306410486,25.0,90.0
104.58154,0.0010842411614173228,370.1614322916667,0.00025370340306410486,25.0,90.0
105.88281,0.0011230264370078742,380.3318229166667,0.00025370340306410486,25.0,90.0
107.18408,0.0011600088385826772,388.7951822916667,0.00025370340306410486,25.0,90.0
108.48535,0.0011941397047244093,398.31721354166666,0.00025370340306410486,25.0,90.0
109.78662,0.0012226694291338582,408.91497395833335,0.00025370340306410486,25.0,90.0
111.08789,0.001259436220472441,416.77067708333334,0.00025370340306410486,25.0,90.0
112.38916,0.0012807753346456693,426.79833333333335,0.00025370340306410486,25.0,90.0
113.69043,0.0013375892322834645,435.4293489583334,0.00025370340306410486,25.0,90.0
114.9917,0.0013459075196850393,443.4354427083333,0.00025370340306410486,25.0,90.0
116.29297,0.0014115943503937008,454.243125,0.00025370340306410486,25.0,90.0
117.59424,0.0014285500984251968,462.4020572916667,0.00025370340306410486,25.0,90.0
118.89551,0.0014680918897637795,472.7355729166667,0.00025370340306410486,25.0,90.0
120.19678,0.0014973838188976378,482.09265625,0.00025370340306410486,25.0,90.0
121.49805,0.0015408766732283464,491.1743489583334,0.00025370340306410486,25.0,90.0
122.79932,0.0015582649212598427,499.762578125,0.00025370340306410486,25.0,90.0
124.10059,0.0015983882283464566,510.5880729166667,0.00025370340306410486,25.0,90.0
125.40186,0.001646749350393701,517.8043489583333,0.00025370340306410486,25.0,90.0
126.70313,0.0016799169094488188,527.3069791666667,0.00025370340306410486,25.0,90.0
128.00439,0.0017143835433070867,535.5562239583334,0.00025370340306410486,25.0,90.0
129.30566,0.0017403340748031496,541.5994010416667,0.00025370340306410486,25.0,90.0
130.60693,0.001764665807086614,548.9002864583333,0.00025370340306410486,25.0,90.0
131.9082,0.0017784361811023623,554.9069791666667,0.00025370340306410486,25.0,90.0
133.20947,0.00182414468503937,562.705546875,0.00025370340306410486,25.0,90.0
134.51074,0.0018420257086614175,568.7491666666666,0.00025370340306410486,25.0,90.0
135.81201,0.0018713038779527558,577.6390104166667,0.00025370340306410486,25.0,90.0
137.11328,0.0019130900196850393,583.29640625,0.00025370340306410486,25.0,90.0
138.41455,0.0019103957874015748,587.7591406250001,0.00025370340306410486,25.0,90.0
139.71582,0.0019599230708661416,594.212734375,0.00025370340306410486,25.0,90.0
141.01709,0.0019793149606299213,602.09859375,0.00025370340306410486,25.0,90.0
142.31836,0.002026364960629921,606.5338802083334,0.00025370340306410486,25.0,90.0
143.61963,0.002030381496062992,612.37984375,0.00025370340306410486,25.0,90.0
144.9209,0.0020754738188976376,616.8164583333335,0.00025370340306410486,25.0,90.0
146.22217,0.002104108070866142,623.2234375,0.00025370340306410486,25.0,90.0
147.52344,0.002139176377952756,628.6797916666667,0.00025370340306410486,25.0,90.0
148.82471,0.002160517125984252,633.341484375,0.00025370340306410486,25.0,90.0
150.12598,0.0021906220472440946,638.589609375,0.00025370340306410486,25.0,90.0
151.42725,0.0022018062992125984,640.9207552083333,0.00025370340306410486,25.0,90.0
152.72852,0.002243053346456693,646.3056510416667,0.00025370340306410486,25.0,90.0
154.02979,0.002271394881889764,648.9604427083334,0.00025370340306410486,25.0,90.0
155.33105,0.002298810433070866,652.0647656250001,0.00025370340306410486,25.0,90.0
156.63232,0.0023425777559055116,660.0182812500001,0.00025370340306410486,25.0,90.0
157.93359,0.0023773698818897637,663.0554166666667,0.00025370340306410486,25.0,90.0
159.23486,0.002387503937007874,667.2846354166667,0.00025370340306410486,25.0,90.0
160.53613,0.0024348848425196847,670.5191406250001,0.00025370340306410486,25.0,90.0
161.8374,0.0024643903543307088,673.8759895833333,0.00025370340306410486,25.0,90.0
163.13867,0.0024994803149606297,678.8450781250001,0.00025370340306410486,25.0,90.0
164.43994,0.002536575,681.448046875,0.00025370340306410486,25.0,90.0
165.74121,0.002590519488188976,686.5450000000001,0.00025370340306410486,25.0,90.0
167.04248,0.0026180350393700787,688.3807552083333,0.00025370340306410486,25.0,90.0
168.34375,0.002650566338582677,691.7771614583334,0.00025370340306410486,25.0,90.0
169.64502,0.002698474015748031,694.2237760416667,0.00025370340306410486,25.0,90.0
170.94629,0.0027280956692913388,699.7430729166666,0.00025370340306410486,25.0,90.0
172.24756,0.0027853838582677162,701.5322916666667,0.00025370340306410486,25.0,90.0
173.54883,0.0028214822834645666,706.2627083333334,0.00025370340306410486,25.0,90.0
174.8501,0.0028822057086614174,708.1306510416667,0.00025370340306410486,25.0,90.0
176.15137,0.0029180452755905514,709.4101041666667,0.00025370340306410486,25.0,90.0
177.45264,0.002994081496062992,714.3641145833333,0.00025370340306410486,25.0,90.0
178.75391,0.0030461005905511812,716.2239583333334,0.00025370340306410486,25.0,90.0
180.05518,0.0031069870078740155,718.8791927083333,0.00025370340306410486,25.0,90.0
181.35645,0.00316873779527559,721.9057031250001,0.00025370340306410486,25.0,90.0
182.65771,0.003243738188976378,724.258671875,0.00025370340306410486,25.0,90.0
183.95898,0.0033185000000000003,728.1224479166667,0.00025370340306410486,25.0,90.0
185.26025,0.0033806700787401577,729.70359375,0.00025370340306410486,25.0,90.0
186.56152,0.0034727805118110236,732.568359375,0.00025370340306410486,25.0,90.0
187.86279,0.0035543929133858266,736.6355208333334,0.00025370340306410486,25.0,90.0
189.16406,0.0036811624015748033,739.3177604166667,0.00025370340306410486,25.0,90.0
190.46533,0.003776801181102362,741.6005989583333,0.00025370340306410486,25.0,90.0
191.7666,0.003889967519685039,743.2238802083333,0.00025370340306410486,25.0,90.0
193.06787,0.004005858464566929,745.1788020833334,0.00025370340306410486,25.0,90.0
194.36914,0.0041121899606299216,748.6633854166668,0.00025370340306410486,25.0,90.0
195.67041,0.004242555708661417,750.4341666666667,0.00025370340306410486,25.0,90.0
196.97168,0.0043695206692913385,751.6513281250001,0.00025370340306410486,25.0,90.0
198.27295,0.004523266929133858,754.4274739583333,0.00025370340306410486,25.0,90.0
199.57422,0.004679419291338582,757.8245833333334,0.00025370340306410486,25.0,90.0
200.87549,0.004836989960629921,759.2140104166667,0.00025370340306410486,25.0,90.0
202.17676,0.004983637992125984,758.7428385416667,0.00025370340306410486,25.0,90.0
203.47803,0.0051543188976377954,762.603515625,0.00025370340306410486,25.0,90.0
204.7793,0.005306818307086614,764.35,0.00025370340306410486,25.0,90.0
206.08057,0.005443846653543307,762.1638541666666,0.00025370340306410486,25.0,90.0
207.38184,0.005627202755905512,767.9812239583333,0.00025370340306410486,25.0,90.0
208.68311,0.00581554842519685,770.9205729166667,0.00025370340306410486,25.0,90.0
209.98438,0.005970202952755905,769.1264583333334,0.00025370340306410486,25.0,90.0
211.28564,0.0061602045275590545,772.7390885416667,0.00025370340306410486,25.0,90.0
212.58691,0.006350785433070866,775.38,0.00025370340306410486,25.0,90.0
213.88818,0.006565534448818897,774.1054427083333,0.00025370340306410486,25.0,90.0
215.18945,0.006764272047244095,776.3574479166666,0.00025370340306410486,25.0,90.0
216.49072,0.007010752952755905,779.0403906250001,0.00025370340306410486,25.0,90.0
217.79199,0.007257243897637795,779.3125781250001,0.00025370340306410486,25.0,90.0
219.09326,0.0074771533464566935,781.8477083333333,0.00025370340306410486,25.0,90.0
220.39453,0.00770665905511811,782.55125,0.00025370340306410486,25.0,90.0
221.6958,0.007949979133858268,784.0335156250001,0.00025370340306410486,25.0,90.0
222.99707,0.008233503937007874,785.4992447916668,0.00025370340306410486,25.0,90.0
224.29834,0.008406352165354332,784.5725260416667,0.00025370340306410486,25.0,90.0
225.59961,0.008630826574803149,785.8798958333334,0.00025370340306410486,25.0,90.0
226.90088,0.008905694291338582,788.9554947916668,0.00025370340306410486,25.0,90.0
228.20215,0.00914168562992126,789.1578125,0.00025370340306410486,25.0,90.0
229.50342,0.009389076377952756,790.3997395833334,0.00025370340306410486,25.0,90.0
230.80469,0.009655393700787402,792.8132291666667,0.00025370340306410486,25.0,90.0
232.10596,0.009903237598425197,793.5059895833334,0.00025370340306410486,25.0,90.0
233.40723,0.010153415157480314,795.6719791666667,0.00025370340306410486,25.0,90.0
234.7085,0.010432041929133858,795.031171875,0.00025370340306410486,25.0,90.0
236.00977,0.010675529921259842,796.5290625,0.00025370340306410486,25.0,90.0
237.31104,0.010963668700787401,797.6949739583334,0.00025370340306410486,25.0,90.0
238.6123,0.011224210236220472,797.1694270833334,0.00025370340306410486,25.0,90.0
239.91357,0.011425911220472441,799.69609375,0.00025370340306410486,25.0,90.0
241.21484,0.011669246062992127,800.0729947916667,0.00025370340306410486,25.0,90.0
242.51611,0.011944061614173229,801.1051822916667,0.00025370340306410486,25.0,90.0
243.81738,0.012207524015748032,802.6709114583334,0.00025370340306410486,25.0,90.0
245.11865,0.012461849999999998,803.1530989583333,0.00025370340306410486,25.0,90.0
246.41992,0.012709091929133857,806.3116145833334,0.00025370340306410486,25.0,90.0
247.72119,0.012921128346456692,804.3008072916667,0.00025370340306410486,25.0,90.0
249.02246,0.013175128543307088,806.1778385416668,0.00025370340306410486,25.0,90.0
250.32373,0.013439110826771654,806.9470833333335,0.00025370340306410486,25.0,90.0
251.625,0.013749678346456691,809.4428385416667,0.00025370340306410486,25.0,90.0
252.92627,0.01401691653543307,810.3497916666666,0.00025370340306410486,25.0,90.0
254.22754,0.014250437992125985,809.6694270833334,0.00025370340306410486,25.0,90.0
255.52881,0.014574403346456691,812.0030208333334,0.00025370340306410486,25.0,90.0
256.83008,0.014872734645669291,812.530078125,0.00025370340306410486,25.0,90.0
258.13135,0.015192360039370077,814.3416666666667,0.00025370340306410486,25.0,90.0
259.43262,0.015471058661417321,814.2065625,0.00025370340306410486,25.0,90.0
260.73389,0.015768064173228347,815.5073697916666,0.00025370340306410486,25.0,90.0
262.03516,0.016034275787401575,814.5058854166667,0.00025370340306410486,25.0,90.0
263.33643,0.016292970669291338,816.3744531250001,0.00025370340306410486,25.0,90.0
264.6377,0.016590652165354332,818.5386718750001,0.00025370340306410486,25.0,90.0
265.93896,0.01686392283464567,818.6747135416667,0.00025370340306410486,25.0,90.0
267.24023,0.017139224606299214,818.0639322916667,0.00025370340306410486,25.0,90.0
268.5415,0.0173977905511811,821.1470833333334,0.00025370340306410486,25.0,90.0
269.84277,0.017688291338582678,821.07359375,0.00025370340306410486,25.0,90.0
271.14404,0.017957191338582677,820.225390625,0.00025370340306410486,25.0,90.0
272.44531,0.018237625,823.6197135416668,0.00025370340306410486,25.0,90.0
273.74658,0.018547922637795276,824.4223958333334,0.00025370340306410486,25.0,90.0
275.04785,0.018863215748031497,824.6649479166667,0.00025370340306410486,25.0,90.0
276.34912,0.01915627283464567,825.4440885416667,0.00025370340306410486,25.0,90.0
277.65039,0.019462214566929134,827.09546875,0.00025370340306410486,25.0,90.0
278.95166,0.019739273622047245,825.90828125,0.00025370340306410486,25.0,90.0
280.25293,0.020009793307086614,825.4958593750001,0.00025370340306410486,25.0,90.0
281.5542,0.020249198818897637,826.9865625,0.00025370340306410486,25.0,90.0
282.85547,0.020537653543307086,829.4809375,0.00025370340306410486,25.0,90.0
284.15674,0.02080604724409449,829.1194270833333,0.00025370340306410486,25.0,90.0
285.45801,0.021081212598425197,829.5345312500001,0.00025370340306410486,25.0,90.0
286.75928,0.021357944881889763,829.8299739583333,0.00025370340306410486,25.0,90.0
288.06055,0.021636096456692913,831.838984375,0.00025370340306410486,25.0,90.0
289.36182,0.021941527559055117,833.1797916666668,0.00025370340306410486,25.0,90.0
290.66309,0.022242692913385827,834.411875,0.00025370340306410486,25.0,90.0
291.96436,0.022541307086614174,834.3319010416667,0.00025370340306410486,25.0,90.0
293.26563,0.022836588582677165,834.46203125,0.00025370340306410486,25.0,90.0
294.56689,0.023149482283464567,836.2745833333335,0.00025370340306410486,25.0,90.0
295.86816,0.02342907874015748,836.0943489583334,0.00025370340306410486,25.0,90.0
297.16943,0.02369888779527559,836.372578125,0.00025370340306410486,25.0,90.0
298.4707,0.02402434251968504,837.2700260416667,0.00025370340306410486,25.0,90.0
299.77197,0.024316905511811024,839.8044010416667,0.00025370340306410486,25.0,90.0
301.07324,0.024600037401574803,838.8998697916667,0.00025370340306410486,25.0,90.0
302.37451,0.024879909448818897,839.2522916666667,0.00025370340306410486,25.0,90.0
303.67578,0.025161990157480316,841.83984375,0.00025370340306410486,25.0,90.0
304.97705,0.025460409448818895,840.4239062500001,0.00025370340306410486,25.0,90.0
306.27832,0.025735370078740157,842.0094270833334,0.00025370340306410486,25.0,90.0
307.57959,0.026015374015748032,841.8513020833333,0.00025370340306410486,25.0,90.0
308.88086,0.02632523228346457,844.3819010416667,0.00025370340306410486,25.0,90.0
310.18213,0.02665444094488189,845.9676822916666,0.00025370340306410486,25.0,90.0
311.4834,0.0269993937007874,844.174453125,0.00025370340306410486,25.0,90.0
312.78467,0.02728914763779527,846.0725260416667,0.00025370340306410486,25.0,90.0
314.08594,0.027576253937007873,847.0336979166666,0.00025370340306410486,25.0,90.0
315.38721,0.027867468503937006,845.4656510416667,0.00025370340306410486,25.0,90.0
316.68848,0.028127578740157477,847.5240625,0.00025370340306410486,25.0,90.0
317.98975,0.028310633858267716,845.5063541666667,0.00025370340306410486,25.0,90.0
319.29102,0.028528389763779527,848.7068229166667,0.00025370340306410486,25.0,90.0
320.59229,0.02878072244094488,849.0391406250001,0.00025370340306410486,25.0,90.0
321.89355,0.02906401181102362,849.4115885416667,0.00025370340306410486,25.0,90.0
323.19482,0.029354293307086613,849.738046875,0.00025370340306410486,25.0,90.0
324.49609,0.029666572834645667,851.1673697916667,0.00025370340306410486,25.0,90.0
325.79736,0.030031311023622047,849.4137499999999,0.00025370340306410486,25.0,90.0
327.09863,0.030351799212598424,852.8971875,0.00025370340306410486,25.0,90.0
328.3999,0.03066781496062992,851.495625,0.00025370340306410486,25.0,90.0
329.70117,0.030979872047244096,853.6322916666667,0.00025370340306410486,25.0,90.0
331.00244,0.03127277952755905,853.2775260416668,0.00025370340306410486,25.0,90.0
332.30371,0.03158157677165354,854.2071614583333,0.00025370340306410486,25.0,90.0
333.60498,0.03187245669291339,854.4115104166667,0.00025370340306410486,25.0,90.0
334.90625,0.03214143503937008,855.473125,0.00025370340306410486,25.0,90.0
336.20752,0.032445647637795276,856.9335416666667,0.00025370340306410486,25.0,90.0
337.50879,0.03276676377952756,857.7969791666667,0.00025370340306410486,25.0,90.0
338.81006,0.03304730905511811,858.2893489583333,0.00025370340306410486,25.0,90.0
340.11133,0.033336338582677164,857.6795052083335,0.00025370340306410486,25.0,90.0
341.4126,0.033602564960629924,858.3106250000001,0.00025370340306410486,25.0,90.0
342.71387,0.03390591535433071,859.5596875,0.00025370340306410486,25.0,90.0
344.01514,0.034216874015748036,860.5945572916668,0.00025370340306410486,25.0,90.0
345.31641,0.034511998031496065,860.4266406250001,0.00025370340306410486,25.0,90.0
346.61768,0.03477074803149606,859.8110156250001,0.00025370340306410486,25.0,90.0
347.91895,0.03506697047244094,861.2855989583334,0.00025370340306410486,25.0,90.0
349.22021,0.03538044291338582,861.8368229166666,0.00025370340306410486,25.0,90.0
350.52148,0.035713490157480314,863.5292708333334,0.00025370340306410486,25.0,90.0
351.82275,0.035988844488188974,862.4907812499999,0.00025370340306410486,25.0,90.0
353.12402,0.03627081102362205,862.5757812500001,0.00025370340306410486,25.0,90.0
354.42529,0.036592194881889764,863.8640104166667,0.00025370340306410486,25.0,90.0
355.72656,0.036819692913385826,864.2080989583334,0.00025370340306410486,25.0,90.0
357.02783,0.03713547637795275,865.81140625,0.00025370340306410486,25.0,90.0
358.3291,0.03741016535433071,865.0878385416667,0.00025370340306410486,25.0,90.0
359.63037,0.03766346259842519,864.1670833333334,0.00025370340306410486,25.0,90.0
360.93164,0.03792556692913386,866.3627083333334,0.00025370340306410486,25.0,90.0
362.23291,0.03825257677165354,868.7668489583333,0.00025370340306410486,25.0,90.0
363.53418,0.03853509251968504,865.9820572916667,0.00025370340306410486,25.0,90.0
364.83545,0.03881544881889763,868.6317447916667,0.00025370340306410486,25.0,90.0
366.13672,0.03908673425196851,870.2554166666667,0.00025370340306410486,25.0,90.0
367.43799,0.03935671850393701,868.947421875,0.00025370340306410486,25.0,90.0
368.73926,0.039646533464566924,868.6575,0.00025370340306410486,25.0,90.0
370.04053,0.03995136614173228,873.53953125,0.00025370340306410486,25.0,90.0
371.3418,0.040261372047244094,874.4390364583334,0.00025370340306410486,25.0,90.0
372.64307,0.04057950196850394,871.4663802083334,0.00025370340306410486,25.0,90.0
373.94434,0.040880622047244096,871.4453906250001,0.00025370340306410486,25.0,90.0
375.24561,0.041194127952755906,873.442578125,0.00025370340306410486,25.0,90.0
376.54688,0.04149741338582677,873.954765625,0.00025370340306410486,25.0,90.0
377.84814,0.04177130118110236,873.46953125,0.00025370340306410486,25.0,90.0
379.14941,0.04200536811023622,874.2809895833334,0.00025370340306410486,25.0,90.0
380.45068,0.04233005708661417,875.784296875,0.00025370340306410486,25.0,90.0
381.75195,0.04265255511811023,876.5128385416667,0.00025370340306410486,25.0,90.0
383.05322,0.042912108267716534,876.1437760416667,0.00025370340306410486,25.0,90.0
384.35449,0.04322505118110236,878.1838020833334,0.00025370340306410486,25.0,90.0
385.65576,0.04358524015748031,878.621484375,0.00025370340306410486,25.0,90.0
386.95703,0.04385955511811024,877.2099739583334,0.00025370340306410486,25.0,90.0
388.2583,0.044105175196850394,878.3541927083334,0.00025370340306410486,25.0,90.0
389.55957,0.04438666338582677,877.5133854166668,0.00025370340306410486,25.0,90.0
390.86084,0.0447164842519685,880.4889583333334,0.00025370340306410486,25.0,90.0
392.16211,0.045053279527559054,881.11375,0.00025370340306410486,25.0,90.0
393.46338,0.04532850590551181,878.2408333333334,0.00025370340306410486,25.0,90.0
394.76465,0.045569824803149604,878.3859375000001,0.00025370340306410486,25.0,90.0
396.06592,0.04582723031496063,882.7452864583333,0.00025370340306410486,25.0,90.0
397.36719,0.04615511220472441,882.5791666666667,0.00025370340306410486,25.0,90.0
398.66846,0.04645943897637795,882.0002864583333,0.00025370340306410486,25.0,90.0
399.96973,0.046822543307086614,883.6545312500001,0.00025370340306410486,25.0,90.0
401.271,0.04706988779527559,881.6200781250001,0.00025370340306410486,25.0,90.0
402.57227,0.04732710629921259,882.871640625,0.00025370340306410486,25.0,90.0
403.87354,0.04764544881889764,882.2432291666667,0.00025370340306410486,25.0,90.0
405.1748,0.0479289625984252,884.296875,0.00025370340306410486,25.0,90.0
406.47607,0.0482682874015748,886.1091666666667,0.00025370340306410486,25.0,90.0
407.77734,0.048632230314960626,886.0415104166666,0.00025370340306410486,25.0,90.0
409.07861,0.04895057283464567,884.9892187500001,0.00025370340306410486,25.0,90.0
410.37988,0.049216775590551175,884.9894791666667,0.00025370340306410486,25.0,90.0
411.68115,0.049497092519685044,886.9140104166667,0.00025370340306410486,25.0,90.0
412.98242,0.049751462598425195,887.4101562500001,0.00025370340306410486,25.0,90.0
414.28369,0.05009135039370079,887.6255729166667,0.00025370340306410486,25.0,90.0
415.58496,0.05039322834645669,888.9704947916666,0.00025370340306410486,25.0,90.0
416.88623,0.0506865688976378,888.6812239583334,0.00025370340306410486,25.0,90.0
418.1875,0.05096108464566929,889.7473697916666,0.00025370340306410486,25.0,90.0
419.48877,0.05123088976377953,890.541640625,0.00025370340306410486,25.0,90.0
420.79004,0.05152829133858267,890.7122916666667,0.00025370340306410486,25.0,90.0
422.09131,0.051828051181102355,891.2492708333333,0.00025370340306410486,25.0,90.0
423.39258,0.05215650984251969,892.7715885416668,0.00025370340306410486,25.0,90.0
424.69385,0.05244894291338583,891.1560677083334,0.00025370340306410486,25.0,90.0
425.99512,0.05272660236220472,893.9965625000001,0.00025370340306410486,25.0,90.0
427.29639,0.05302257874015748,892.3330989583334,0.00025370340306410486,25.0,90.0
428.59766,0.05326811417322835,892.4563020833334,0.00025370340306410486,25.0,90.0
429.89893,0.053573657480314965,892.9940625,0.00025370340306410486,25.0,90.0
431.2002,0.05393258858267717,895.1057552083333,0.00025370340306410486,25.0,90.0
432.50146,0.05424523622047245,895.048203125,0.00025370340306410486,25.0,90.0
433.80273,0.05450623031496063,895.1698177083333,0.00025370340306410486,25.0,90.0
435.104,0.054745523622047244,894.7556250000001,0.00025370340306410486,25.0,90.0
436.40527,0.05500559448818898,895.4691666666666,0.00025370340306410486,25.0,90.0
437.70654,0.055314330708661416,896.956328125,0.00025370340306410486,25.0,90.0
439.00781,0.055615809055118114,897.2201041666667,0.00025370340306410486,25.0,90.0
440.30908,0.05591999803149606,897.1849479166667,0.00025370340306410486,25.0,90.0
441.61035,0.056210096456692914,898.7527083333333,0.00025370340306410486,25.0,90.0
442.91162,0.0565095748031496,898.2672395833333,0.00025370340306410486,25.0,90.0
444.21289,0.056826200787401575,899.0568229166668,0.00025370340306410486,25.0,90.0
445.51416,0.057135814960629916,899.3976041666667,0.00025370340306410486,25.0,90.0
446.81543,0.05745375590551181,900.4651302083333,0.00025370340306410486,25.0,90.0
448.1167,0.05780722440944882,901.9547135416667,0.00025370340306410486,25.0,90.0
449.41797,0.058125746062992124,903.3968489583334,0.00025370340306410486,25.0,90.0
450.71924,0.05843598228346456,901.8126822916668,0.00025370340306410486,25.0,90.0
452.02051,0.058768641732283466,904.2711197916667,0.00025370340306410486,25.0,90.0
453.32178,0.05907549015748031,900.9285677083334,0.00025370340306410486,25.0,90.0
454.62305,0.05931313385826771,901.8278124999999,0.00025370340306410486,25.0,90.0
455.92432,0.059587261811023626,904.3308333333333,0.00025370340306410486,25.0,90.0
457.22559,0.05987946062992126,902.0402343750001,0.00025370340306410486,25.0,90.0
458.52686,0.060157037401574805,901.4137239583333,0.00025370340306410486,25.0,90.0
459.82813,0.06043716732283464,904.4361197916668,0.00025370340306410486,25.0,90.0
461.12939,0.06070654527559055,904.4742708333333,0.00025370340306410486,25.0,90.0
462.43066,0.06097477165354331,903.2875,0.00025370340306410486,25.0,90.0
463.73193,0.06126203543307086,905.1960677083334,0.00025370340306410486,25.0,90.0
465.0332,0.061530080708661415,905.4648177083334,0.00025370340306410486,25.0,90.0
466.33447,0.06181859448818898,906.2908072916667,0.00025370340306410486,25.0,90.0
467.63574,0.062160188976377956,908.5025260416667,0.00025370340306410486,25.0,90.0
468.93701,0.06247801181102362,907.612421875,0.00025370340306410486,25.0,90.0
470.23828,0.06280548425196851,908.8190625000001,0.00025370340306410486,25.0,90.0
471.53955,0.06310977362204724,907.332109375,0.00025370340306410486,25.0,90.0
472.84082,0.06340666929133858,908.2431250000001,0.00025370340306410486,25.0,90.0
474.14209,0.06370593110236221,908.0953645833334,0.00025370340306410486,25.0,90.0
475.44336,0.06401511220472442,908.9960677083334,0.00025370340306410486,25.0,90.0
476.74463,0.06433700787401575,910.2046875000001,0.00025370340306410486,25.0,90.0
478.0459,0.06463129921259841,908.962890625,0.00025370340306410486,25.0,90.0
479.34717,0.0649499901574803,912.6045833333334,0.00025370340306410486,25.0,90.0
480.64844,0.06527979330708661,912.3632552083334,0.00025370340306410486,25.0,90.0
481.94971,0.06561399606299212,912.3974479166667,0.00025370340306410486,25.0,90.0
483.25098,0.06590093700787401,911.32296875,0.00025370340306410486,25.0,90.0
484.55225,0.06615261417322835,913.0193750000001,0.00025370340306410486,25.0,90.0
485.85352,0.06641694488188976,913.1696614583334,0.00025370340306410486,25.0,90.0
487.15479,0.06671675787401575,913.101953125,0.00025370340306410486,25.0,90.0
488.45605,0.06699034645669291,911.5503385416667,0.00025370340306410486,25.0,90.0
489.75732,0.06729542716535433,911.9269010416667,0.00025370340306410486,25.0,90.0
491.05859,0.06755073031496063,912.5881770833333,0.00025370340306410486,25.0,90.0
492.35986,0.06790608070866141,915.6330729166667,0.00025370340306410486,25.0,90.0
493.66113,0.06822692519685039,916.6609375,0.00025370340306410486,25.0,90.0
494.9624,0.06858143897637796,915.9766406250001,0.00025370340306410486,25.0,90.0
496.26367,0.06886674803149606,915.8997135416668,0.00025370340306410486,25.0,90.0
497.56494,0.0691832342519685,916.591328125,0.00025370340306410486,25.0,90.0
498.86621,0.06943567913385827,915.2067708333333,0.00025370340306410486,25.0,90.0
500.16748,0.06973339763779528,916.2290624999999,0.00025370340306410486,25.0,90.0
501.46875,0.07005205511811023,917.304609375,0.00025370340306410486,25.0,90.0
502.77002,0.07033800984251969,916.5839583333334,0.00025370340306410486,25.0,90.0
504.07129,0.07060732283464566,916.4867447916666,0.00025370340306410486,25.0,90.0
505.37256,0.0709400748031496,918.3190625000001,0.00025370340306410486,25.0,90.0
506.67383,0.0712797283464567,919.65171875,0.00025370340306410486,25.0,90.0
507.9751,0.0716416437007874,918.332421875,0.00025370340306410486,25.0,90.0
509.27637,0.07188520866141732,917.4170833333334,0.00025370340306410486,25.0,90.0
510.57764,0.07215850393700787,919.3373958333334,0.00025370340306410486,25.0,90.0
511.87891,0.07243259645669291,920.8898437500001,0.00025370340306410486,25.0,90.0
513.18018,0.07272477165354331,920.1533072916667,0.00025370340306410486,25.0,90.0
514.48145,0.07304809645669291,922.2841145833333,0.00025370340306410486,25.0,90.0
515.78271,0.07338215354330709,920.6724739583334,0.00025370340306410486,25.0,90.0
517.08398,0.07368918110236221,922.7860677083335,0.00025370340306410486,25.0,90.0
518.38525,0.0740401279527559,921.155859375,0.00025370340306410486,25.0,90.0
519.68652,0.0743140688976378,920.0660677083333,0.00025370340306410486,25.0,90.0
520.98779,0.07459366338582676,921.1394010416667,0.00025370340306410486,25.0,90.0
522.28906,0.07489471456692913,923.087578125,0.00025370340306410486,25.0,90.0
523.59033,0.0752479311023622,925.6198177083334,0.00025370340306410486,25.0,90.0
524.8916,0.07559191338582677,924.033671875,0.00025370340306410486,25.0,90.0
526.19287,0.07595786023622048,925.3288281250001,0.00025370340306410486,25.0,90.0
527.49414,0.07626183661417323,923.367109375,0.00025370340306410486,25.0,90.0
528.79541,0.07657699606299212,924.808125,0.00025370340306410486,25.0,90.0
530.09668,0.07690903543307086,923.5251822916666,0.00025370340306410486,25.0,90.0
531.39795,0.07713533267716535,923.4640104166667,0.00025370340306410486,25.0,90.0
532.69922,0.07745816535433071,926.091953125,0.00025370340306410486,25.0,90.0
534.00049,0.07774227952755905,925.5143489583334,0.00025370340306410486,25.0,90.0
535.30176,0.07801092913385826,924.5217708333333,0.00025370340306410486,25.0,90.0
536.60303,0.07835466535433071,928.7291145833334,0.00025370340306410486,25.0,90.0
537.9043,0.0786558562992126,927.9790364583333,0.00025370340306410486,25.0,90.0
539.20557,0.07896539566929134,925.0937239583334,0.00025370340306410486,25.0,90.0
540.50684,0.07927656496062993,927.4626302083333,0.00025370340306410486,25.0,90.0
541.80811,0.07955641338582677,927.3855208333334,0.00025370340306410486,25.0,90.0
543.10938,0.07985465354330708,930.0642708333335,0.00025370340306410486,25.0,90.0
544.41064,0.08016138385826771,929.6181250000001,0.00025370340306410486,25.0,90.0
545.71191,0.08049098622047243,928.0032552083334,0.00025370340306410486,25.0,90.0
547.01318,0.08082109448818897,928.7831510416668,0.00025370340306410486,25.0,90.0
548.31445,0.08112406889763779,930.81640625,0.00025370340306410486,25.0,90.0
549.61572,0.08144500196850393,931.6879947916667,0.00025370340306410486,25.0,90.0
550.91699,0.08178857283464566,931.1777083333334,0.00025370340306410486,25.0,90.0
552.21826,0.0821068405511811,930.7040625000001,0.00025370340306410486,25.0,90.0
553.51953,0.08238422637795276,930.9366927083333,0.00025370340306410486,25.0,90.0
554.8208,0.08268931299212598,932.5012760416668,0.00025370340306410486,25.0,90.0
556.12207,0.08306522047244094,933.9075,0.00025370340306410486,25.0,90.0
557.42334,0.08341548031496063,932.489765625,0.00025370340306410486,25.0,90.0
558.72461,0.08373427755905512,934.4097135416667,0.00025370340306410486,25.0,90.0
560.02588,0.08407871653543307,933.9640885416667,0.00025370340306410486,25.0,90.0
561.32715,0.08437397637795276,931.1433854166667,0.00025370340306410486,25.0,90.0
562.62842,0.08469048031496064,934.8347916666668,0.00025370340306410486,25.0,90.0
563.92969,0.08501170472440944,932.4371874999999,0.00025370340306410486,25.0,90.0
565.23096,0.08527516338582677,933.5340625,0.00025370340306410486,25.0,90.0
566.53223,0.0855943996062992,934.6948697916667,0.00025370340306410486,25.0,90.0
567.8335,0.08589974409448818,934.4738020833333,0.00025370340306410486,25.0,90.0
569.13477,0.08623546062992125,935.90640625,0.00025370340306410486,25.0,90.0
570.43604,0.08653086614173228,935.0884635416667,0.00025370340306410486,25.0,90.0
571.7373,0.08681503937007873,934.3232552083334,0.00025370340306410486,25.0,90.0
573.03857,0.08712722440944883,935.9972656250001,0.00025370340306410486,25.0,90.0
574.33984,0.08746033070866141,937.3781250000001,0.00025370340306410486,25.0,90.0
575.64111,0.08780909251968504,936.76453125,0.00025370340306410486,25.0,90.0
576.94238,0.08814250984251969,937.598671875,0.00025370340306410486,25.0,90.0
578.24365,0.08850576377952755,937.9058072916667,0.00025370340306410486,25.0,90.0
579.54492,0.08880839763779527,937.8133854166666,0.00025370340306410486,25.0,90.0
580.84619,0.0891315059055118,937.5732552083334,0.00025370340306410486,25.0,90.0
582.14746,0.08943778346456693,939.4669270833333,0.00025370340306410486,25.0,90.0
583.44873,0.0897765157480315,939.1329427083334,0.00025370340306410486,25.0,90.0
584.75,0.09016963582677165,939.4809114583334,0.00025370340306410486,25.0,90.0
586.05127,0.09048688976377953,938.0242708333334,0.00025370340306410486,25.0,90.0
587.35254,0.09078375196850394,938.7726562500001,0.00025370340306410486,25.0,90.0
588.65381,0.09112234251968504,939.2834895833333,0.00025370340306410486,25.0,90.0
589.95508,0.09140611023622047,939.5611458333334,0.00025370340306410486,25.0,90.0
591.25635,0.09169252952755906,940.9789322916668,0.00025370340306410486,25.0,90.0
592.55762,0.09203082677165354,939.7212239583334,0.00025370340306410486,25.0,90.0
593.85889,0.09237466338582677,941.4620833333333,0.00025370340306410486,25.0,90.0
595.16016,0.09263791929133859,940.1062760416667,0.00025370340306410486,25.0,90.0
596.46143,0.09291162598425197,940.580546875,0.00025370340306410486,25.0,90.0
597.7627,0.09322143503937008,942.1393750000001,0.00025370340306410486,25.0,90.0
599.06396,0.09354616338582676,942.7734895833333,0.00025370340306410486,25.0,90.0
600.36523,0.0938758720472441,942.4915885416667,0.00025370340306410486,25.0,90.0
601.6665,0.09423293110236221,942.8605468750001,0.00025370340306410486,25.0,90.0
602.96777,0.09457566338582678,943.507890625,0.00025370340306410486,25.0,90.0
604.26904,0.09489287007874016,942.0457291666667,0.00025370340306410486,25.0,90.0
605.57031,0.09517126377952756,941.677421875,0.00025370340306410486,25.0,90.0
606.87158,0.09547771259842519,943.2308854166668,0.00025370340306410486,25.0,90.0
608.17285,0.09580617125984252,943.1552343750001,0.00025370340306410486,25.0,90.0
609.47412,0.09613792716535434,944.8284895833334,0.00025370340306410486,25.0,90.0
610.77539,0.09645611417322834,943.3694791666667,0.00025370340306410486,25.0,90.0
612.07666,0.09679997834645669,943.7420572916667,0.00025370340306410486,25.0,90.0
613.37793,0.09714485826771653,945.1696354166667,0.00025370340306410486,25.0,90.0
614.6792,0.09747892125984252,944.8638281249999,0.00025370340306410486,25.0,90.0
615.98047,0.09779657283464567,945.370234375,0.00025370340306410486,25.0,90.0
617.28174,0.09811083464566929,945.6759114583334,0.00025370340306410486,25.0,90.0
618.58301,0.09846647440944882,946.77046875,0.00025370340306410486,25.0,90.0
619.88428,0.09878339960629923,944.480390625,0.00025370340306410486,25.0,90.0
621.18555,0.09911121259842519,946.21875,0.00025370340306410486,25.0,90.0
622.48682,0.09942392716535432,946.2700000000001,0.00025370340306410486,25.0,90.0
623.78809,0.09973077362204724,946.2782552083335,0.00025370340306410486,25.0,90.0
625.08936,0.10009443110236221,949.811171875,0.00025370340306410486,25.0,90.0
626.39063,0.10044181692913386,947.5919010416667,0.00025370340306410486,25.0,90.0
627.69189,0.10083677952755905,946.6464322916667,0.00025370340306410486,25.0,90.0
628.99316,0.10116354921259843,945.6786458333333,0.00025370340306410486,25.0,90.0
630.29443,0.10147605118110237,946.5450260416667,0.00025370340306410486,25.0,90.0
631.5957,0.10184675,949.0533072916667,0.00025370340306410486,25.0,90.0
632.89697,0.10216667913385825,948.6747135416666,0.00025370340306410486,25.0,90.0
634.19824,0.10246517125984252,947.575703125,0.00025370340306410486,25.0,90.0
635.49951,0.10282047637795276,947.9629427083335,0.00025370340306410486,25.0,90.0
636.80078,0.10315044881889764,949.61421875,0.00025370340306410486,25.0,90.0
638.10205,0.10347432086614174,949.5796875,0.00025370340306410486,25.0,90.0
639.40332,0.10381723425196851,948.840703125,0.00025370340306410486,25.0,90.0
640.70459,0.10417624803149607,950.923671875,0.00025370340306410486,25.0,90.0
642.00586,0.10450211417322834,948.6991927083334,0.00025370340306410486,25.0,90.0
643.30713,0.10480714173228346,949.0154947916667,0.00025370340306410486,25.0,90.0
644.6084,0.10518845866141734,952.5926041666667,0.00025370340306410486,25.0,90.0
645.90967,0.10555060433070867,952.9015104166667,0.00025370340306410486,25.0,90.0
647.21094,0.10591481299212598,951.2476562500001,0.00025370340306410486,25.0,90.0
648.51221,0.10623992913385827,952.7545833333334,0.00025370340306410486,25.0,90.0
649.81348,0.1065948346456693,950.6219791666666,0.00025370340306410486,25.0,90.0
651.11475,0.10690168110236221,950.5291666666667,0.00025370340306410486,25.0,90.0
652.41602,0.10721681102362204,953.2112760416667,0.00025370340306410486,25.0,90.0
653.71729,0.10754525984251968,952.2349739583334,0.00025370340306410486,25.0,90.0
655.01855,0.10788857283464567,951.8985677083334,0.00025370340306410486,25.0,90.0
656.31982,0.10822975,952.579765625,0.00025370340306410486,25.0,90.0
657.62109,0.10858439763779529,953.4606249999999,0.00025370340306410486,25.0,90.0
658.92236,0.10898063976377952,952.4595833333334,0.00025370340306410486,25.0,90.0
660.22363,0.10932786023622047,954.4220052083334,0.00025370340306410486,25.0,90.0
661.5249,0.10970335826771653,952.1988541666667,0.00025370340306410486,25.0,90.0
662.82617,0.11001544881889763,951.6344010416667,0.00025370340306410486,25.0,90.0
664.12744,0.11037888582677166,954.4511718750001,0.00025370340306410486,25.0,90.0
665.42871,0.11076082480314961,955.183671875,0.00025370340306410486,25.0,90.0
666.72998,0.11112137401574804,953.2477083333333,0.00025370340306410486,25.0,90.0
668.03125,0.11141890354330708,952.4460416666667,0.00025370340306410486,25.0,90.0
669.33252,0.1117349842519685,953.3948177083333,0.00025370340306410486,25.0,90.0
670.63379,0.11209309251968504,953.4386979166667,0.00025370340306410486,25.0,90.0
671.93506,0.11243391929133859,954.3561979166667,0.00025370340306410486,25.0,90.0
673.23633,0.11276366929133858,954.77453125,0.00025370340306410486,25.0,90.0
674.5376,0.11310848425196851,954.588828125,0.00025370340306410486,25.0,90.0
675.83887,0.11350877362204724,956.2890364583334,0.00025370340306410486,25.0,90.0
677.14014,0.11386769291338583,956.8729427083334,0.00025370340306410486,25.0,90.0
678.44141,0.1142321496062992,955.0735416666666,0.00025370340306410486,25.0,90.0
679.74268,0.11456974803149605,956.6383333333333,0.00025370340306410486,25.0,90.0
681.04395,0.114912968503937,955.0903906249999,0.00025370340306410486,25.0,90.0
682.34521,0.11532035629921261,957.5609114583333,0.00025370340306410486,25.0,90.0
683.64648,0.11571954330708661,957.9373697916667,0.00025370340306410486,25.0,90.0
684.94775,0.11609770472440945,955.9080729166667,0.00025370340306410486,25.0,90.0
686.24902,0.11636801377952756,956.0720572916666,0.00025370340306410486,25.0,90.0
687.55029,0.11670402952755905,957.3985416666668,0.00025370340306410486,25.0,90.0
688.85156,0.11702685629921258,955.1554427083333,0.00025370340306410486,25.0,90.0
690.15283,0.11740695275590551,957.638671875,0.00025370340306410486,25.0,90.0
691.4541,0.11776466338582678,957.7750000000001,0.00025370340306410486,25.0,90.0
692.75537,0.1181745748031496,959.0979947916667,0.00025370340306410486,25.0,90.0
694.05664,0.11857465354330708,957.3973958333333,0.00025370340306410486,25.0,90.0
695.35791,0.11895547637795276,956.821640625,0.00025370340306410486,25.0,90.0
696.65918,0.11935087401574802,957.4740625000001,0.00025370340306410486,25.0,90.0
697.96045,0.11968377952755906,959.0918229166667,0.00025370340306410486,25.0,90.0
699.26172,0.12009582677165355,958.4777864583334,0.00025370340306410486,25.0,90.0
700.56299,0.12044226181102363,958.415546875,0.00025370340306410486,25.0,90.0
701.86426,0.12078795669291338,958.2701302083334,0.00025370340306410486,25.0,90.0
703.16553,0.1211736377952756,959.7134374999999,0.00025370340306410486,25.0,90.0
704.4668,0.12147758661417322,956.8986197916666,0.00025370340306410486,25.0,90.0
705.76807,0.12179068700787403,957.0404687500001,0.00025370340306410486,25.0,90.0
707.06934,0.12207416141732283,959.1467447916667,0.00025370340306410486,25.0,90.0
708.37061,0.12245663976377953,958.4630208333334,0.00025370340306410486,25.0,90.0
709.67188,0.12280820078740157,960.02984375,0.00025370340306410486,25.0,90.0
710.97314,0.12314718503937007,959.8477604166667,0.00025370340306410486,25.0,90.0
712.27441,0.1235720688976378,960.2195833333334,0.00025370340306410486,25.0,90.0
713.57568,0.12395115551181103,960.003671875,0.00025370340306410486,25.0,90.0
714.87695,0.12427527362204724,959.6970833333334,0.00025370340306410486,25.0,90.0
716.17822,0.12461266141732283,959.6680208333333,0.00025370340306410486,25.0,90.0
717.47949,0.12502044881889762,960.738125,0.00025370340306410486,25.0,90.0
718.78076,0.12539472637795276,960.0676822916668,0.00025370340306410486,25.0,90.0
720.08203,0.12572807874015748,961.3703385416667,0.00025370340306410486,25.0,90.0
721.3833,0.12607493503937006,960.4169791666667,0.00025370340306410486,25.0,90.0
722.68457,0.12642372834645668,960.9551041666666,0.00025370340306410486,25.0,90.0
723.98584,0.12674348031496063,959.74921875,0.00025370340306410486,25.0,90.0
725.28711,0.12713364566929133,961.1352864583334,0.00025370340306410486,25.0,90.0
726.58838,0.12753165944881892,961.9923958333334,0.00025370340306410486,25.0,90.0
727.88965,0.12792869881889765,961.1046354166667,0.00025370340306410486,25.0,90.0
729.19092,0.1283052165354331,960.8811718750001,0.00025370340306410486,25.0,90.0
730.49219,0.12871881102362207,962.4261197916667,0.00025370340306410486,25.0,90.0
731.79346,0.12912314960629923,960.7031510416667,0.00025370340306410486,25.0,90.0
733.09473,0.12957842125984254,962.6381510416667,0.00025370340306410486,25.0,90.0
734.396,0.12992582874015748,962.1885416666668,0.00025370340306410486,25.0,90.0
735.69727,0.1303256968503937,962.0298958333334,0.00025370340306410486,25.0,90.0
736.99854,0.13071019291338584,961.85703125,0.00025370340306410486,25.0,90.0
738.2998,0.1310842834645669,962.92921875,0.00025370340306410486,25.0,90.0
739.60107,0.1314131062992126,962.1887239583334,0.00025370340306410486,25.0,90.0
740.90234,0.13181711417322833,962.0688020833334,0.00025370340306410486,25.0,90.0
742.20361,0.1322079940944882,961.7483854166667,0.00025370340306410486,25.0,90.0
743.50488,0.13260116338582678,963.5653125,0.00025370340306410486,25.0,90.0
744.80615,0.13299544488188975,962.6474479166668,0.00025370340306410486,25.0,90.0
746.10742,0.13333622440944884,962.5872395833334,0.00025370340306410486,25.0,90.0
747.40869,0.13372618897637797,962.2697135416666,0.00025370340306410486,25.0,90.0
748.70996,0.13402322637795275,963.6728385416668,0.00025370340306410486,25.0,90.0
750.01123,0.13433035433070864,962.1804427083333,0.00025370340306410486,25.0,90.0
751.3125,0.13471045078740157,963.478203125,0.00025370340306410486,25.0,90.0
752.61377,0.1350511122047244,961.3484635416668,0.00025370340306410486,25.0,90.0
753.91504,0.13538537992125982,962.3417447916667,0.00025370340306410486,25.0,90.0
755.21631,0.1358342342519685,964.2006510416667,0.00025370340306410486,25.0,90.0
756.51758,0.13622774212598424,963.0414322916666,0.00025370340306410486,25.0,90.0
757.81885,0.13657742519685037,963.5712239583333,0.00025370340306410486,25.0,90.0
759.12012,0.13700431496062992,963.0675,0.00025370340306410486,25.0,90.0
760.42139,0.13738492716535433,963.03640625,0.00025370340306410486,25.0,90.0
761.72266,0.137767218503937,964.6183072916667,0.00025370340306410486,25.0,90.0
763.02393,0.1381428346456693,963.5036979166667,0.00025370340306410486,25.0,90.0
764.3252,0.1385430531496063,964.2950000000001,0.00025370340306410486,25.0,90.0
765.62646,0.1389520374015748,964.1529166666668,0.00025370340306410486,25.0,90.0
766.92773,0.13937821062992126,964.00546875,0.00025370340306410486,25.0,90.0
768.229,0.13975512795275588,962.7099479166667,0.00025370340306410486,25.0,90.0
769.53027,0.14014328543307086,964.4184635416667,0.00025370340306410486,25.0,90.0
770.83154,0.14059215157480315,964.4607031250001,0.00025370340306410486,25.0,90.0
772.13281,0.14096501968503936,962.7822135416667,0.00025370340306410486,25.0,90.0
773.43408,0.1413058346456693,964.0559635416668,0.00025370340306410486,25.0,90.0
774.73535,0.1417303405511811,966.1291145833334,0.00025370340306410486,25.0,90.0
776.03662,0.14214992125984252,964.56484375,0.00025370340306410486,25.0,90.0
777.33789,0.14248831692913386,964.3771614583333,0.00025370340306410486,25.0,90.0
778.63916,0.14288818503937006,963.8844270833334,0.00025370340306410486,25.0,90.0
779.94043,0.1432873720472441,964.832890625,0.00025370340306410486,25.0,90.0
781.2417,0.143667562992126,963.9005729166668,0.00025370340306410486,25.0,90.0
782.54297,0.14401683661417322,963.8534635416667,0.00025370340306410486,25.0,90.0
783.84424,0.1443789940944882,963.7785677083334,0.00025370340306410486,25.0,90.0
785.14551,0.14473022637795274,965.6059895833334,0.00025370340306410486,25.0,90.0
786.44678,0.145105031496063,965.5383333333333,0.00025370340306410486,25.0,90.0
787.74805,0.14554225787401576,966.07875,0.00025370340306410486,25.0,90.0
789.04932,0.14590103543307084,964.4221614583333,0.00025370340306410486,25.0,90.0
790.35059,0.14630232283464567,963.6993489583334,0.00025370340306410486,25.0,90.0
791.65186,0.14682260826771654,965.8287760416666,0.00025370340306410486,25.0,90.0
792.95313,0.14727774999999999,965.6084114583333,0.00025370340306410486,25.0,90.0
794.25439,0.1476642657480315,964.00546875,0.00025370340306410486,25.0,90.0
795.55566,0.14802841732283464,963.9567708333334,0.00025370340306410486,25.0,90.0
796.85693,0.1483739586614173,964.7708333333334,0.00025370340306410486,25.0,90.0
798.1582,0.14874210039370078,964.61125,0.00025370340306410486,25.0,90.0
799.45947,0.14919308858267719,966.2404947916667,0.00025370340306410486,25.0,90.0
800.76074,0.14952487992125982,964.7739322916667,0.00025370340306410486,25.0,90.0
802.06201,0.14992235433070866,964.32546875,0.00025370340306410486,25.0,90.0
803.36328,0.15033846062992126,965.5877343750001,0.00025370340306410486,25.0,90.0
804.66455,0.15080291929133857,965.2210156250001,0.00025370340306410486,25.0,90.0
805.96582,0.15126037401574802,966.0040625,0.00025370340306410486,25.0,90.0
807.26709,0.15162091141732284,963.4064322916668,0.00025370340306410486,25.0,90.0
808.56836,0.15202266732283465,965.2300520833334,0.00025370340306410486,25.0,90.0
809.86963,0.15240691732283465,964.7363541666666,0.00025370340306410486,25.0,90.0
811.1709,0.15279269291338582,965.0201822916666,0.00025370340306410486,25.0,90.0
812.47217,0.1531667716535433,964.9767447916666,0.00025370340306410486,25.0,90.0
813.77344,0.15352809448818897,964.7060416666667,0.00025370340306410486,25.0,90.0
815.07471,0.15397772244094488,966.5211458333334,0.00025370340306410486,25.0,90.0
816.37598,0.1543749035433071,965.1883333333333,0.00025370340306410486,25.0,90.0
817.67725,0.15480810433070866,964.1170572916667,0.00025370340306410486,25.0,90.0
818.97852,0.15523516929133857,965.3047656250001,0.00025370340306410486,25.0,90.0
820.27979,0.15564045866141732,967.6153125000001,0.00025370340306410486,25.0,90.0