File: datasets/am_bench_2022/raw_data/30-XY.01-1/specimen.dat
MTS793|MPT|ENU|1|2|.|/|:|1|0|0|A

Operator Information						Time:	12.281738	Sec	10/14/2021 3:17:06 PM
Operator	Nick Derimow
Project	AM Bench 2022 mini-tensile challenge
Specimen ID	30-XY.01-1
Material	PBF-L Inconel 625
Specimen Width	2.56	mm
Specimen Thickness	1.51	mm
Notes
Operator Information End

Data Acquisition						Time:	1013.2756	Sec	10/14/2021 3:33:47 PM
Time	Axial Displacement	Axial Extensometer	Axial Force
Sec	mm	mm	N
12.395508	-0.00085369137	5.7170632e-06	79.324776
13.496582	0.0044076014	-7.9082187e-05	98.680161
14.597656	0.0034672029	-0.00012711273	112.75365
15.69873	0.010718397	6.3766769e-05	132.04234
16.799805	0.014287341	0.00016355483	151.66431
17.900879	0.017851163	0.00012705657	173.0957
19.001953	0.01882419	9.1581744e-05	192.97537
20.103027	0.021299632	0.00021872274	214.23322
21.204102	0.025567716	0.00043398733	240.78474
22.305176	0.027285727	0.00020290515	262.4949
23.40625	0.032271236	0.00043908911	294.55048
24.507324	0.031848341	0.0005482909	310.4425
25.608398	0.036531482	0.00068366848	340.05194
26.709473	0.041814953	0.00056085887	360.65665
27.810547	0.043725766	0.00083872484	386.11005
28.911621	0.046251614	0.0009155866	407.20068
30.012695	0.052045263	0.00088318926	441.47018
31.11377	0.054465793	0.001054931	462.95706
32.214844	0.056931861	0.0010524804	485.40909
33.315918	0.059309773	0.00121165	510.76334
34.416992	0.065988965	0.001212699	540.05298
35.518066	0.067224249	0.0012563817	570.00677
36.619141	0.069392562	0.0014597708	586.3573
37.720215	0.071924552	0.0015194464	616.04846
38.821289	0.076550737	0.001626882	647.07953
39.922363	0.078876249	0.0016407408	665.46674
41.023438	0.084160745	0.0016638853	698.20148
42.124512	0.085795514	0.001843002	725.11926
43.225586	0.090893567	0.0019158408	761.18262
44.32666	0.091761075	0.0019681526	784.94928
45.427734	0.096986972	0.0021100293	818.96637
46.528809	0.099851087	0.0022797149	853.81323
47.629883	0.10369336	0.0023577516	880.71918
48.730957	0.10759182	0.002374647	913.54584
49.832031	0.10691977	0.0023624846	941.82697
50.933105	0.11276071	0.002565718	980.06287
52.03418	0.11620466	0.00273969	1011.5414
53.135254	0.11864021	0.002774385	1032.629
54.236328	0.12297975	0.0028780752	1071.8271
55.337402	0.1255732	0.0029105414	1096.2051
56.438477	0.12878522	0.0031848913	1130.9957
57.539551	0.13036473	0.0030550458	1167.621
58.640625	0.13524006	0.0032003648	1196.8397
59.741699	0.13942942	0.0033814125	1230.4104
60.842773	0.14525564	0.0033792858	1266.7086
61.943848	0.1436573	0.0034729855	1281.9736
63.044922	0.14636903	0.0036864511	1315.192
64.145996	0.15254883	0.0037146062	1348.8286
65.24707	0.15398759	0.0039035587	1374.9355
66.348145	0.16127858	0.0040660198	1418.0551
67.449219	0.16026641	0.0041682953	1438.9562
68.550293	0.1651856	0.0042442107	1470.8287
69.651367	0.1664073	0.0043808757	1500.5845
70.752441	0.17208356	0.0045469133	1532.5427
71.853516	0.17308773	0.0047356486	1563.1741
72.95459	0.17924604	0.0048162639	1590.6979
74.055664	0.17915854	0.0049628299	1618.9519
75.156738	0.1870808	0.005189776	1647.1941
76.257813	0.18889321	0.0052081547	1680.5912
77.358887	0.19026394	0.0053357095	1706.2863
78.459961	0.1964118	0.0056375111	1738.9939
79.561035	0.19855024	0.0055710003	1753.8199
80.662109	0.20007853	0.0058151535	1788.8376
81.763184	0.20534131	0.0059088492	1812.5239
82.864258	0.20540994	0.0059145982	1839.9702
83.965332	0.21208088	0.0061531663	1862.0652
85.066406	0.21499504	0.0061552031	1891.9539
86.16748	0.21876213	0.0064467886	1920.0555
87.268555	0.22530255	0.006659491	1945.1089
88.369629	0.22503251	0.0065833051	1962.401
89.470703	0.23109415	0.0069054319	1988.0494
90.571777	0.22916366	0.0067901569	2017.6136
91.672852	0.23506755	0.0069750445	2033.3762
92.773926	0.23918396	0.0071357833	2060.9568
93.875	0.24287318	0.0072310609	2082.7393
94.976074	0.24461536	0.0074331961	2101.1794
96.077148	0.24838613	0.0073938323	2120.4568
97.178223	0.25095439	0.0076744398	2145.1704
98.279297	0.2556138	0.0077369795	2167.7749
99.380371	0.2589334	0.0077776178	2174.2605
100.48145	0.26153177	0.0079639722	2189.113
101.58252	0.26238802	0.0080064656	2211.8916
102.68359	0.2687152	0.0082031135	2231.2278
103.78467	0.27198973	0.0083001042	2244.6543
104.88574	0.27493417	0.0084673343	2262.708
105.98682	0.27845475	0.0085721267	2283.0659
107.08789	0.28234747	0.0086710341	2292.2209
108.18896	0.28562894	0.0088018877	2305.7744
109.29004	0.28876659	0.0088371253	2321.2466
110.39111	0.29207391	0.0090359533	2337.6597
111.49219	0.29617599	0.0091380617	2347.604
112.59326	0.29785648	0.0093169333	2367.3079
113.69434	0.3034825	0.009491019	2381.3909
114.79541	0.30468479	0.0095416186	2394.6724
115.89648	0.30763236	0.0095925089	2413.3528
116.99756	0.31152728	0.009844034	2418.3704
118.09863	0.31624198	0.0099123027	2437.2031
119.19971	0.31791997	0.010058467	2444.6184
120.30078	0.32155353	0.010207388	2460.8145
121.40186	0.32452357	0.010261856	2469.1846
122.50293	0.3288959	0.010581433	2486.5564
123.604	0.32971129	0.010499428	2492.0232
124.70508	0.33365136	0.010905217	2503.8367
125.80615	0.33713198	0.011010285	2510.4087
126.90723	0.34142214	0.011024553	2522.5046
128.0083	0.34377116	0.011268805	2532.7351
129.10938	0.34758481	0.011405659	2548.6003
130.21045	0.34866193	0.011438526	2551.4922
131.31152	0.35220832	0.011751227	2565.0361
132.4126	0.35871822	0.011865339	2574.5664
133.51367	0.36044914	0.012016018	2581.3779
134.61475	0.36550498	0.012203389	2599.7344
135.71582	0.3677454	0.012461643	2603.5327
136.81689	0.37264615	0.01280922	2620.4302
137.91797	0.37393144	0.012890793	2618.7375
139.01904	0.37458441	0.01317177	2632.7405
140.12012	0.38072941	0.013335779	2636.0496
141.22119	0.38587907	0.013510758	2649.0264
142.32227	0.38994288	0.013853131	2665.2224
143.42334	0.39145514	0.014214398	2676.3047
144.52441	0.39742598	0.01441303	2679.5356
145.62549	0.40150943	0.014753063	2688.0864
146.72656	0.40352988	0.014971581	2692.5332
147.82764	0.40768701	0.015387378	2707.3018
148.92871	0.40782326	0.015810357	2713.519
150.02979	0.40921488	0.01612287	2718.9734
151.13086	0.41568589	0.016568007	2737.2229
152.23193	0.41640815	0.017155161	2732.8655
153.33301	0.42224374	0.017566204	2743.8525
154.43408	0.42875102	0.017954329	2751.8237
155.53516	0.43168339	0.018536437	2756.6348
156.63623	0.42967385	0.01896904	2764.2749
157.7373	0.43609321	0.019583942	2768.2671
158.83838	0.43716922	0.020222815	2779.3374
159.93945	0.43891081	0.020947387	2783.1582
161.04053	0.44487882	0.021633886	2784.4517
162.1416	0.44606945	0.022129156	2789.0232
163.24268	0.44759235	0.023059933	2798.9463
164.34375	0.45503005	0.023875557	2803.2559
165.44482	0.45954722	0.024605963	2811.418
166.5459	0.46124592	0.025424855	2811.7234
167.64697	0.46526337	0.026166324	2820.5999
168.74805	0.4698894	0.027044123	2827.9165
169.84912	0.47304508	0.027794369	2823.1897
170.9502	0.47236484	0.028493386	2830.1597
172.05127	0.47787222	0.029610455	2839.3618
173.15234	0.48215976	0.030506523	2843.1245
174.25342	0.48635608	0.031267609	2842.9072
175.35449	0.49053848	0.032324225	2851.9624
176.45557	0.49001661	0.033332109	2852.2212
177.55664	0.49390087	0.034258407	2859.2588
178.65771	0.49662429	0.035288066	2855.5681
179.75879	0.50175893	0.036725856	2870.2471
180.85986	0.50439912	0.037880138	2870.6919
181.96094	0.50773412	0.039044481	2874.6516
183.06201	0.51240355	0.040092498	2868.7861
184.16309	0.5155189	0.041068066	2881.3135
185.26416	0.51411688	0.042484943	2883.499
186.36523	0.51904666	0.043595672	2886.4409
187.46631	0.52496755	0.044857118	2892.5732
188.56738	0.53021389	0.046172585	2892.1421
189.66846	0.52975208	0.047111347	2897.0378
190.76953	0.5309388	0.04843184	2895.9578
191.87061	0.53864551	0.049369078	2905.6101
192.97168	0.53918415	0.05067515	2906.4448
194.07275	0.54695922	0.051867902	2913.0764
195.17383	0.5488801	0.05291554	2912.0571
196.2749	0.54760647	0.054249309	2910.3643
197.37598	0.55378616	0.055587634	2918.0789
198.47705	0.5577606	0.056805268	2919.3193
199.57813	0.56128424	0.058334526	2926.4021
200.6792	0.56587458	0.059494372	2927.4314
201.78027	0.56460673	0.060707152	2924.356
202.88135	0.56984103	0.061922416	2923.4387
203.98242	0.57286102	0.062980652	2927.271
205.0835	0.5762282	0.064389735	2929.7676
206.18457	0.58021247	0.065537944	2933.1721
207.28564	0.5819425	0.066988036	2939.5178
208.38672	0.58804125	0.068319693	2942.5222
209.48779	0.59016186	0.069594666	2942.6699
210.58887	0.59410048	0.070709601	2938.7012
211.68994	0.59970105	0.071780041	2951.4248
212.79102	0.6008181	0.073161796	2954.438
213.89209	0.60246009	0.074696757	2954.6235
214.99316	0.60672075	0.076094732	2960.8835
216.09424	0.60999346	0.077735469	2958.3635
217.19531	0.61343616	0.079264224	2965.0374
218.29639	0.61860901	0.080496445	2958.9565
219.39746	0.61875057	0.081430264	2955.543
220.49854	0.62112445	0.082455963	2961.4937
221.59961	0.62617368	0.083994076	2969.6125
222.70068	0.63177991	0.085244857	2974.3215
223.80176	0.63281351	0.086732075	2975.5764
224.90283	0.63799495	0.088354379	2976.8088
226.00391	0.63939184	0.089710601	2976.531
227.10498	0.64324403	0.091078609	2977.0183
228.20605	0.64627695	0.092204027	2977.3938
229.30713	0.64879727	0.093766056	2978.8711
230.4082	0.65286452	0.09503857	2982.4377
231.50928	0.656739	0.096392319	2987.6697
232.61035	0.65827423	0.098025002	2988.4424
233.71143	0.66157109	0.099366181	2989.3762
234.8125	0.66517407	0.10098569	2998.8567
235.91357	0.66856414	0.10236939	2995.186
237.01465	0.67281842	0.10380579	3002.1724
238.11572	0.67331076	0.1050528	2993.5129
239.2168	0.67804104	0.1061728	2997.1802
240.31787	0.67968774	0.10776047	3000.2788
241.41895	0.68566084	0.10936727	3006.4072
242.52002	0.6896078	0.11064038	3007.1624
243.62109	0.6941461	0.11201313	3007.207
244.72217	0.69479787	0.11359226	3016.7903
245.82324	0.69543731	0.11483671	3008.7507
246.92432	0.70228904	0.1160769	3006.6865
248.02539	0.70462841	0.11725958	3014.5945
249.12646	0.70924848	0.11857735	3010.1086
250.22754	0.71390229	0.11980285	3023.5774
251.32861	0.71626729	0.12122707	3019.8896
252.42969	0.71878725	0.122642	3022.093
253.53076	0.72089165	0.12409166	3024.938
254.63184	0.72389597	0.12552063	3023.5344
255.73291	0.72957546	0.1266908	3023.8098
256.83398	0.73253775	0.12795781	3027.9697
257.93506	0.73350292	0.12964734	3030.333
259.03613	0.74073327	0.13116801	3032.0347
260.13721	0.74073738	0.13244604	3033.3311
261.23828	0.7440629	0.13385443	3038.2129
262.33936	0.74836683	0.13551781	3045.3833
263.44043	0.75160182	0.13691014	3044.749
264.5415	0.75584549	0.13846351	3044.9915
265.64258	0.75735629	0.13978583	3036.5261
266.74365	0.76137823	0.1409142	3033.551
267.84473	0.76381767	0.1421234	3048.3518
268.9458	0.76889217	0.14362544	3050.7249
270.04688	0.77342629	0.14506853	3046.2832
271.14795	0.77391827	0.1464607	3050.3447
272.24902	0.7781595	0.14795163	3056.3057
273.3501	0.78276557	0.14937131	3059.2195
274.45117	0.78550678	0.15051547	3055.1401
275.55225	0.78516668	0.15200533	3057.9885
276.65332	0.79129881	0.15348978	3062.4688
277.75439	0.79358244	0.15470904	3058.4084
278.85547	0.79933125	0.15630551	3064.4609
279.95654	0.80131167	0.15771247	3063.8645
281.05762	0.80395228	0.15885872	3065.4502
282.15869	0.80713481	0.16010711	3056.1379
283.25977	0.81336462	0.16126549	3069.094
284.36084	0.81331605	0.16242647	3068.0583
285.46191	0.81830513	0.16398396	3076.5398
286.56299	0.82327163	0.16530827	3077.9939
287.66406	0.82849568	0.16689485	3086.4717
288.76514	0.8281703	0.16834311	3079.3447
289.86621	0.83158523	0.1697116	3078.0083
290.96729	0.8343938	0.17100504	3078.6152
292.06836	0.84045929	0.17233966	3079.9978
293.16943	0.84332633	0.17378128	3082.4478
294.27051	0.8430196	0.1750619	3083.7554
295.37158	0.84772938	0.17648014	3086.8513
296.47266	0.84968835	0.17770766	3085.0969
297.57373	0.85293686	0.17921165	3088.8457
298.6748	0.85929865	0.1805985	3097.0859
299.77588	0.85922861	0.18210173	3090.5613
300.87695	0.86534774	0.18358448	3091.7556
301.97803	0.86714238	0.18495102	3097.9575
303.0791	0.868653	0.18648006	3097.5217
304.18018	0.87457019	0.18778549	3097.9714
305.28125	0.87674862	0.18917425	3103.8806
306.38232	0.88088953	0.19095382	3103.2
307.4834	0.88348657	0.1920387	3099.3291
308.58447	0.88742286	0.19338866	3101.9402
309.68555	0.89086866	0.19504957	3101.0112
310.78662	0.89422065	0.19614957	3107.1309
311.8877	0.89706475	0.19777688	3111.9463
312.98877	0.90410978	0.19911544	3114.7515
314.08984	0.90490234	0.20038906	3113.4419
315.19092	0.90439624	0.20180196	3112.4521
316.29199	0.91032392	0.20293199	3113.7219
317.39307	0.9139961	0.20413542	3116.2295
318.49414	0.9198494	0.20556636	3122.7148
319.59521	0.92063981	0.20686446	3116.9338
320.69629	0.92637753	0.20844451	3124.9019
321.79736	0.92787689	0.2097044	3120.0051
322.89844	0.93007004	0.21110396	3126.2104
323.99951	0.93303233	0.21241309	3127.1182
325.10059	0.93613863	0.21381707	3124.8721
326.20166	0.94060421	0.21499732	3133.0608
327.30273	0.94415694	0.21622194	3130.7368
328.40381	0.94772774	0.21759035	3129.3203
329.50488	0.95147413	0.21911782	3139.4258
330.60596	0.95273012	0.2205188	3133.594
331.70703	0.95662075	0.22215918	3130.7698
332.80811	0.96005201	0.22324081	3133.7957
333.90918	0.96147531	0.22485125	3140.4521
335.01025	0.96511215	0.22636886	3144.4092
336.11133	0.96816146	0.22781786	3137.2576
337.2124	0.97341895	0.22911441	3140.4539
338.31348	0.97669363	0.23042944	3145.3193
339.41455	0.97920805	0.23195788	3152.5815
340.51563	0.98242915	0.2336724	3145.5981
341.6167	0.98660517	0.2351404	3151.0723
342.71777	0.99028927	0.23653643	3153.2083
343.81885	0.99397463	0.23766534	3152.2881
344.91992	0.9942283	0.23918907	3153.3
346.021	1.0010659	0.24037895	3152.874
347.12207	1.0042034	0.24164854	3156.4084
348.22314	1.0088419	0.24340673	3162.0427
349.32422	1.0091519	0.24480274	3161.5266
350.42529	1.0124725	0.24626888	3158.249
351.52637	1.0202143	0.24750336	3158.5437
352.62744	1.0205499	0.24868087	3158.0408
353.72852	1.02188	0.24992146	3163.0796
354.82959	1.0268129	0.25103277	3163.6868
355.93066	1.0282545	0.25249401	3164.4243
357.03174	1.0331739	0.25387272	3169.1877
358.13281	1.0353562	0.25494128	3163.7161
359.23389	1.0399809	0.25640014	3170.8333
360.33496	1.0448322	0.25789234	3175.1858
361.43604	1.0460218	0.259128	3171.5869
362.53711	1.0507046	0.26041174	3168.7061
363.63818	1.0542819	0.26177222	3178.9817
364.73926	1.0564916	0.26325476	3176.9783
365.84033	1.0587565	0.2647287	3178.2837
366.94141	1.0636027	0.26614466	3189.8262
368.04248	1.0656785	0.26765755	3180.3623
369.14355	1.0662597	0.26906911	3181.5437
370.24463	1.0721755	0.27045593	3183.1743
371.3457	1.0770599	0.27202925	3187.5864
372.44678	1.077252	0.27345318	3182.0515
373.54785	1.0841346	0.2747272	3190.3472
374.64893	1.0851791	0.27605566	3183.0491
375.75	1.0886538	0.27727458	3188.668
376.85107	1.0933666	0.27853546	3189.3418
377.95215	1.0945286	0.27997512	3191.8667
379.05322	1.0991185	0.28148559	3189.8452
380.1543	1.1041992	0.28294018	3202.9673
381.25537	1.1044446	0.28430748	3194.0381
382.35645	1.1078877	0.28559607	3193.8745
383.45752	1.1124175	0.28703687	3200.29
384.55859	1.1155022	0.28839806	3196.6194
385.65967	1.1191939	0.28975633	3200.3501
386.76074	1.1218083	0.29122251	3200.9736
387.86182	1.1258976	0.29254887	3202.0227
388.96289	1.1280524	0.29394126	3205.1404
390.06396	1.1325098	0.29525337	3201.3767
391.16504	1.136382	0.29673028	3207.6011
392.26611	1.1375165	0.29818651	3205.3525
393.36719	1.1436269	0.29938546	3211.9724
394.46826	1.1463763	0.30075032	3213.1692
395.56934	1.1478666	0.30213886	3206.4827
396.67041	1.1509039	0.30342391	3212.97
397.77148	1.155188	0.30470023	3213.8484
398.87256	1.1584951	0.30619749	3215.3945
399.97363	1.1616417	0.3075594	3216.6284
401.07471	1.1647995	0.30883935	3222.4585
402.17578	1.1697859	0.31026193	3219.7717
403.27686	1.1726683	0.31177008	3220.5725
404.37793	1.1742806	0.31338376	3223.4883
405.479	1.178383	0.31473592	3227.165
406.58008	1.1783379	0.31621656	3219.0061
407.68115	1.1818267	0.31760216	3226.2935
408.78223	1.1900182	0.31897223	3230.042
409.8833	1.19111	0.32039133	3227.2217
410.98438	1.1939063	0.32195434	3228.3181
412.08545	1.1976618	0.32324323	3232.2686
413.18652	1.2015427	0.32457975	3230.3845
414.2876	1.2041247	0.32572696	3232.9177
415.38867	1.2073401	0.32683343	3227.7527
416.48975	1.2103679	0.32817075	3240.1423
417.59082	1.2142692	0.32934031	3232.551
418.69189	1.2167014	0.33086643	3242.0933
419.79297	1.221078	0.33216324	3239.5522
420.89404	1.223465	0.33372718	3245.6921
421.99512	1.2297872	0.33552817	3245.2297
423.09619	1.2301604	0.33691877	3241.2085
424.19727	1.2336867	0.33800206	3237.8567
425.29834	1.2356131	0.33938634	3241.1694
426.39941	1.2386874	0.34057283	3239.3625
427.50049	1.2455482	0.34167618	3243.0732
428.60156	1.2450681	0.34288523	3242.2329
429.70264	1.2482934	0.34413734	3247.0454
430.80371	1.2535363	0.34550992	3252.908
431.90479	1.2601452	0.34697962	3253.2141
433.00586	1.2638326	0.34838468	3257.6611
434.10693	1.2644364	0.34970677	3245.917
435.20801	1.2661843	0.35086221	3248.9717
436.30908	1.2728118	0.35234466	3259.1736
437.41016	1.2756473	0.35370046	3264.7437
438.51123	1.2775059	0.35492018	3258.585
439.6123	1.2807939	0.35630226	3261.4934
440.71338	1.2861205	0.35763955	3263.2803
441.81445	1.28608	0.35917577	3265.5989
442.91553	1.2909778	0.36068934	3266.49
444.0166	1.2931321	0.36217555	3267.8916
445.11768	1.2964083	0.36367685	3266.0947
446.21875	1.3017033	0.36495891	3266.6113
447.31982	1.3043345	0.36623508	3264.2292
448.4209	1.3087767	0.36750615	3268.6323
449.52197	1.3092417	0.36871615	3272.3086
450.62305	1.3118894	0.37034029	3276.2339
451.72412	1.3151737	0.37185246	3273.0315
452.8252	1.316985	0.37329093	3269.7065
453.92627	1.3240317	0.37455371	3275.5977
455.02734	1.3271629	0.37582263	3276.6204
456.12842	1.3296692	0.37715966	3279.3901
457.22949	1.3327751	0.37857792	3275.7759
458.33057	1.3356104	0.37989971	3270.5884
459.43164	1.3382548	0.38116807	3280.2283
460.53271	1.3428383	0.38280457	3285.2041
461.63379	1.349398	0.38425806	3281.2705
462.73486	1.3512363	0.38536125	3285.217
463.83594	1.3552722	0.386805	3288.3569
464.93701	1.3540156	0.38825306	3283.9133
466.03809	1.3608453	0.38977751	3287.6738
467.13916	1.3596709	0.39090931	3283.0991
468.24023	1.3667102	0.39216739	3288.4546
469.34131	1.3686799	0.39376727	3292.1187
470.44238	1.3747494	0.39497763	3293.624
471.54346	1.3761442	0.39627329	3290.479
472.64453	1.3788208	0.39770904	3291.7021
473.74561	1.3828018	0.39913419	3295.4585
474.84668	1.3857334	0.40063965	3294.7942
475.94775	1.3894351	0.40185627	3293.1067
477.04883	1.3931977	0.40311885	3297.7544
478.1499	1.3968375	0.40466255	3300.3364
479.25098	1.4002954	0.40606877	3302.7014
480.35205	1.4048414	0.40765965	3299.501
481.45313	1.4043386	0.40885592	3298.1255
482.5542	1.4091231	0.41028935	3303.8418
483.65527	1.4125928	0.41168159	3303.5415
484.75635	1.4169078	0.41281813	3303.7759
485.85742	1.4165416	0.41400862	3302.5813
486.9585	1.4213827	0.41550726	3305.8965
488.05957	1.4258265	0.41693428	3306.3655
489.16064	1.4270571	0.41818398	3310.4424
490.26172	1.4331304	0.4194755	3307.5
491.36279	1.436946	0.42101243	3315.8752
492.46387	1.4390699	0.42236727	3313.4897
493.56494	1.4427842	0.42379472	3317.7627
494.66602	1.4492787	0.42523235	3321.1895
495.76709	1.451143	0.42659226	3314.5544
496.86816	1.454187	0.42773411	3311.1707
497.96924	1.4562666	0.42885143	3313.1611
499.07031	1.458974	0.43029702	3323.7043
500.17139	1.4617357	0.43169966	3319.449
501.27246	1.4642785	0.43307248	3320.5793
502.37354	1.468857	0.4346315	3320.6643
503.47461	1.4725074	0.43590969	3318.3901
504.57568	1.4743797	0.43723404	3323.5391
505.67676	1.4799743	0.43872902	3332.8101
506.77783	1.4843595	0.44017994	3323.5664
507.87891	1.4872156	0.44160306	3321.6504
508.97998	1.4901222	0.44291309	3327.3257
510.08105	1.4924436	0.44430184	3334.7527
511.18213	1.4974515	0.44558188	3322.6248
512.2832	1.5003232	0.4469642	3341.1311
513.38428	1.5028534	0.44837204	3330.0349
514.48535	1.5070798	0.44981113	3337.9458
515.58643	1.5085936	0.45126763	3333.9534
516.6875	1.5133805	0.45276049	3335.4009
517.78857	1.5167599	0.45410258	3334.2051
518.88965	1.519626	0.45553619	3336.2644
519.99072	1.5221848	0.45696041	3334.7686
521.0918	1.5231929	0.4580901	3336.8306
522.19287	1.5267774	0.45963785	3341.5107
523.29395	1.5336908	0.46109477	3342.3901
524.39502	1.5373018	0.46247107	3339.2268
525.49609	1.5382112	0.46378651	3339.3513
526.59717	1.5407412	0.46532834	3344.6665
527.69824	1.5463551	0.4665598	3346.1577
528.79932	1.5481718	0.46774888	3345.0278
529.90039	1.5482707	0.46929094	3346.4797
531.00146	1.5512161	0.47048438	3342.9224
532.10254	1.5580113	0.47173613	3346.053
533.20361	1.5612907	0.47317103	3353.8311
534.30469	1.5627335	0.47451136	3350.429
535.40576	1.5676234	0.47603488	3351.1755
536.50684	1.5708765	0.47727674	3351.2983
537.60791	1.5738943	0.47864002	3349.3513
538.70898	1.5782708	0.48021424	3352.6252
539.81006	1.5790709	0.48137558	3351.8521
540.91113	1.5849574	0.4831562	3362.1177
542.01221	1.5907832	0.4846569	3359.7117
543.11328	1.5904179	0.48607436	3354.5305
544.21436	1.5948442	0.48720241	3353.4592
545.31543	1.5971409	0.48842907	3351.0615
546.4165	1.60197	0.48959479	3357.1155
547.51758	1.6049898	0.49086311	3359.0564
548.61865	1.6063615	0.49235538	3358.9431
549.71973	1.6118251	0.49402997	3369.1416
550.8208	1.6139076	0.49568549	3369.2524
551.92188	1.6185267	0.49739057	3367.0291
553.02295	1.6198462	0.49863806	3361.064
554.12402	1.623926	0.49987367	3363.334
555.2251	1.627582	0.50142491	3366.9104
556.32617	1.6309631	0.50275326	3365.8494
557.42725	1.6345009	0.504076	3364.197
558.52832	1.6353073	0.50552934	3369.5754
559.62939	1.6404195	0.50703126	3372.4282
560.73047	1.6439323	0.50840867	3363.395
561.83154	1.6479014	0.50975549	3369.8787
562.93262	1.6499987	0.51103401	3376.6055
564.03369	1.6531396	0.5124985	3378.6611
565.13477	1.6553569	0.51400715	3370.9727
566.23584	1.6599394	0.5153212	3374.8496
567.33691	1.6623992	0.5165143	3367.5667
568.43799	1.6657729	0.51782995	3377.1567
569.53906	1.6730744	0.51893574	3371.4797
570.64014	1.678262	0.52024108	3384.2881
571.74121	1.6787679	0.52158022	3381.3604
572.84229	1.6791553	0.52316439	3386.3909
573.94336	1.6827415	0.52457756	3376.387
575.04443	1.6866313	0.52561778	3372.7915
576.14551	1.6887594	0.52701867	3384.979
577.24658	1.6952778	0.52849418	3389.1343
578.34766	1.6941882	0.52988172	3384.116
579.44873	1.7005705	0.53161156	3384.3816
580.5498	1.7032332	0.53295583	3385.0979
581.65088	1.7082752	0.53433228	3386.3076
582.75195	1.7095199	0.53578633	3390.6726
583.85303	1.7169392	0.5372659	3391.2505
584.9541	1.716491	0.53874725	3385.0303
586.05518	1.7180686	0.53995687	3390.4031
587.15625	1.7262284	0.54139555	3391.312
588.25732	1.7282534	0.54269099	3388.6589
589.3584	1.7283454	0.5441674	3386.4509
590.45947	1.7326616	0.54530108	3398.3523
591.56055	1.7363088	0.54673123	3392.6069
592.66162	1.7396384	0.54818022	3397.1357
593.7627	1.7442936	0.54975861	3396.2686
594.86377	1.7434992	0.55109179	3394.1682
595.96484	1.7508249	0.55248433	3392.2207
597.06592	1.7504227	0.553837	3394.1914
598.16699	1.7571462	0.55539691	3404.4526
599.26807	1.759725	0.55673915	3398.2163
600.36914	1.7641931	0.55831313	3406.7769
601.47021	1.765758	0.55986434	3398.4302
602.57129	1.7684739	0.56149	3410.0801
603.67236	1.771137	0.56323785	3405.1172
604.77344	1.7719879	0.56448716	3399.2429
605.87451	1.7793772	0.56571573	3407.6885
606.97559	1.7829691	0.56723887	3405.0051
608.07666	1.7888623	0.56845993	3409.9036
609.17773	1.7894077	0.56967837	3407.2317
610.27881	1.7932801	0.57089263	3403.9841
611.37988	1.7975867	0.57257724	3422.2771
612.48096	1.8021535	0.5743469	3415.821
613.58203	1.8032724	0.57570744	3407.9692
614.68311	1.8075076	0.57700074	3413.6006
615.78418	1.8088472	0.57865405	3411.2371
616.88525	1.8125465	0.57995903	3410.5649
617.98633	1.8154452	0.58133835	3406.7783
619.0874	1.8176844	0.58265305	3409.1943
620.18848	1.8208498	0.58402336	3412.009
621.28955	1.8267477	0.58563107	3416.0051
622.39063	1.8294076	0.58707255	3421.5149
623.4917	1.8328929	0.58886355	3415.5935
624.59277	1.8382975	0.5901612	3418.2886
625.69385	1.8387316	0.5915938	3416.9937
626.79492	1.8440259	0.59307939	3419.4963
627.896	1.8460523	0.59440857	3426.1956
628.99707	1.8493389	0.59570038	3419.0833
630.09814	1.8525274	0.59728771	3424.3618
631.19922	1.8555671	0.59901434	3427.616
632.30029	1.8603714	0.60019398	3425.4153
633.40137	1.8624599	0.60157341	3420.9285
634.50244	1.8653367	0.60300004	3420.5237
635.60352	1.8667872	0.60441196	3423.5991
636.70459	1.8724827	0.60567248	3428.3835
637.80566	1.8738893	0.60720289	3429.0808
638.90674	1.8809618	0.60852355	3424.603
640.00781	1.8829359	0.61011183	3431.9836
641.10889	1.8836348	0.61138666	3425.6157
642.20996	1.8879184	0.61283153	3427.9382
643.31104	1.8936291	0.61417902	3436.0161
644.41211	1.8951882	0.61555195	3433.4124
645.51318	1.8988795	0.61704493	3426.7813
646.61426	1.9014167	0.61826915	3428.6736
647.71533	1.9036694	0.6197086	3429.948
648.81641	1.9120748	0.62135464	3440.6628
649.91748	1.9122263	0.62273556	3432.9727
651.01855	1.9166044	0.62452871	3439.1252
652.11963	1.9188766	0.62598318	3437.1873
653.2207	1.9203752	0.62776774	3438.1147
654.32178	1.9270991	0.62919408	3437.554
655.42285	1.9249883	0.63051653	3435.0105
656.52393	1.9322658	0.63207865	3437.0205
657.625	1.933776	0.63334996	3439.6072
658.72607	1.9408143	0.63476789	3443.5425
659.82715	1.942077	0.63618737	3436.5657
660.92822	1.9437071	0.63757241	3442.5437
662.0293	1.9488868	0.63947743	3441.9585
663.13037	1.9502714	0.64101851	3442.5967
664.23145	1.9520235	0.64231819	3442.5554
665.33252	1.9605348	0.64405018	3447.6692
666.43359	1.9614978	0.64557421	3451.9604
667.53467	1.9635246	0.64702773	3442.7129
668.63574	1.9661304	0.64845765	3444.6013
669.73682	1.968356	0.64990968	3442.4734
670.83789	1.974154	0.65138012	3446.7144
671.93896	1.9773085	0.65289205	3444.0251
673.04004	1.9815263	0.65449536	3450.1252
674.14111	1.983111	0.65592444	3444.5117
675.24219	1.9879192	0.65758318	3450.332
676.34326	1.9908611	0.65895706	3451.0957
677.44434	1.9933158	0.66051716	3454.4109
678.54541	2.0001636	0.66208375	3456.5583
679.64648	1.9987224	0.66376024	3452.6184
680.74756	2.0051422	0.66523182	3447.1538
681.84863	2.0099831	0.66641581	3449.1438
682.94971	2.0107789	0.66784793	3454.4429
684.05078	2.0123324	0.66935927	3453.3416
685.15186	2.0162842	0.67093325	3460.4543
686.25293	2.0228796	0.6724714	3455.1482
687.354	2.0262179	0.67379385	3454.1328
688.45508	2.0249765	0.67502272	3452.7756
689.55615	2.0320094	0.67656368	3450.4897
690.65723	2.030983	0.67775351	3455.9761
691.7583	2.0355129	0.67935103	3456.3767
692.85938	2.040904	0.6808272	3464.4768
693.96045	2.0457306	0.68244076	3465.8396
695.06152	2.0471146	0.68406796	3460.2183
696.1626	2.0523207	0.68577909	3465.7488
697.26367	2.0547757	0.68733197	3459.0181
698.36475	2.0574508	0.68911397	3464.5991
699.46582	2.0590158	0.69049633	3460.2769
700.56689	2.0619359	0.69230938	3462.9487
701.66797	2.0716944	0.69382221	3471.3315
702.76904	2.0684807	0.69527888	3464.6721
703.87012	2.071588	0.69695455	3463.3242
704.97119	2.0804341	0.69845289	3465.2939
706.07227	2.0816936	0.69980174	3467.283
707.17334	2.0820227	0.70110816	3466.4805
708.27441	2.0834901	0.7028107	3469.4788
709.37549	2.0874424	0.70434701	3472.3416
710.47656	2.0942156	0.70592207	3469.1931
711.57764	2.0983026	0.70737451	3472.2922
712.67871	2.0984786	0.70858729	3465.856
713.77979	2.1029322	0.7096917	3468.1431
714.88086	2.1082087	0.71127123	3474.1064
715.98193	2.1087372	0.71267295	3478.7383
717.08301	2.1150048	0.71410149	3475.5886
718.18408	2.1182511	0.71562034	3480.5879
719.28516	2.117594	0.71725559	3468.9297
720.38623	2.1241896	0.7185905	3473.7729
721.4873	2.1257696	0.72023726	3480.0698
722.58838	2.1299818	0.72198969	3471.6633
723.68945	2.1342332	0.7236194	3475.48
724.79053	2.1371086	0.72515857	3475.6602
725.8916	2.1392553	0.72658366	3475.9502
726.99268	2.1424942	0.72821981	3469.8252
728.09375	2.1449115	0.72974968	3478.5454
729.19482	2.1514897	0.73127979	3483.9468
730.2959	2.155314	0.73288822	3484.146
731.39697	2.1539257	0.73467487	3478.0486
732.49805	2.1571598	0.73581284	3478.2046
733.59912	2.1635611	0.7372992	3475.7729
734.7002	2.1670716	0.7389515	3485.3567
735.80127	2.1679032	0.74055797	3477.9668
736.90234	2.170876	0.74219465	3483.0928
738.00342	2.1782153	0.74377131	3487.4131
739.10449	2.1778769	0.74571157	3482.8955
740.20557	2.1834359	0.74730766	3488.8259
741.30664	2.1862638	0.74876088	3486.5032
742.40771	2.1867576	0.75036287	3483.5503
743.50879	2.1917202	0.75178164	3488.1174
744.60986	2.1945581	0.75334871	3485.8145
745.71094	2.1980431	0.7549631	3486.4756
746.81201	2.2018437	0.75658083	3486.9817
747.91309	2.2082498	0.75828612	3492.1943
749.01416	2.2077422	0.75971878	3485.2634
750.11523	2.2130938	0.76111668	3481.6047
751.21631	2.2175417	0.76262569	3490.2239
752.31738	2.2195971	0.76381093	3482.0579
753.41846	2.2195208	0.76511317	3482.6914
754.51953	2.2288413	0.76645726	3490.7
755.62061	2.230113	0.76821566	3499.8198
756.72168	2.233098	0.76986766	3495.1401
757.82275	2.2348959	0.77168906	3489.6882
758.92383	2.2371781	0.77329987	3492.7026
760.0249	2.2415352	0.77487481	3495.5837
761.12598	2.2429991	0.77673972	3491.3394
762.22705	2.2526793	0.77874529	3500.5554
763.32813	2.2526395	0.78010982	3491.0657
764.4292	2.2543027	0.78173649	3491.1145
765.53027	2.2585812	0.78389752	3498.2903
766.63135	2.2626467	0.78569514	3491.9844
767.73242	2.26616	0.78732657	3496.4387
768.8335	2.268904	0.78869712	3491.8303
769.93457	2.2722173	0.79065704	3495.0291
771.03564	2.2757406	0.79228252	3498.5994
772.13672	2.278949	0.79377425	3496.8813
773.23779	2.2829347	0.79540634	3495.4131
774.33887	2.2855752	0.79676366	3494.1653
775.43994	2.2887211	0.79847491	3496.72
776.54102	2.2887032	0.79997212	3501.5535
777.64209	2.294112	0.80185199	3501.0098
778.74316	2.2986779	0.80349898	3495.2056
779.84424	2.3027911	0.80498159	3494.0173
780.94531	2.301765	0.80659395	3496.5293
782.04639	2.3075576	0.80799168	3497.249
783.14746	2.3094764	0.80936801	3494.3152
784.24854	2.3129566	0.81076723	3497.3276
785.34961	2.3205082	0.81261986	3503.6223
786.45068	2.3211792	0.8141821	3503.9084
787.55176	2.3227735	0.81596339	3502.5085
788.65283	2.3286052	0.81755388	3502.6941
789.75391	2.3326631	0.81914413	3499.4607
790.85498	2.3354104	0.82076657	3502.9355
791.95605	2.33566	0.82235861	3501.4915
793.05713	2.3417141	0.82388955	3500.2808
794.1582	2.3450305	0.82541043	3501.2444
795.25928	2.3476865	0.8267318	3503.6172
796.36035	2.3530998	0.82870072	3511.665
797.46143	2.3548319	0.83075881	3509.0686
798.5625	2.3547499	0.83203328	3497.0186
799.66357	2.3619087	0.83368242	3502.3494
800.76465	2.3625968	0.83545721	3508.7007
801.86572	2.3672197	0.83735728	3509.7905
802.9668	2.3715799	0.8390342	3504.9111
804.06787	2.3771141	0.84040672	3503.8335
805.16895	2.3750079	0.84199303	3501.1475
806.27002	2.3785622	0.84340948	3505.9082
807.37109	2.3811014	0.84502167	3507.127
808.47217	2.3873236	0.84697306	3512.6321
809.57324	2.3902974	0.84837306	3507.3599
810.67432	2.3930438	0.85002589	3512.3721
811.77539	2.400481	0.85190618	3514.9775
812.87646	2.3975797	0.85364455	3507.8511
813.97754	2.3992672	0.85557163	3508.8679
815.07861	2.4069905	0.85744858	3509.1584
816.17969	2.4103732	0.85929686	3517.4229
817.28076	2.4111602	0.86077994	3506.5854
818.38184	2.416281	0.86230302	3510.3665
819.48291	2.4213624	0.86417329	3515.1072
820.58398	2.427099	0.86577183	3518.571
821.68506	2.4272861	0.86753917	3513.6714
822.78613	2.4327395	0.86917239	3511.8418
823.88721	2.4320321	0.87099326	3508.687
824.98828	2.4363294	0.87256569	3509.894
826.08936	2.4401846	0.87412524	3515.186
827.19043	2.4448161	0.87597537	3515.3738
828.2915	2.4462674	0.8776843	3520.8923
829.39258	2.4510932	0.87959021	3518.9626
830.49365	2.4530299	0.88123018	3514.0679
831.59473	2.4585342	0.88322008	3521.6523
832.6958	2.4648104	0.88497174	3518.9919
833.79688	2.4635336	0.88633323	3513.354
834.89795	2.4682848	0.88824785	3524.6064
835.99902	2.4709094	0.89002579	3516.5747
837.1001	2.4734273	0.89166594	3519.6414
838.20117	2.4748104	0.89370823	3514.8325
839.30225	2.4806886	0.89538288	3514.4314
840.40332	2.4823818	0.89698499	3518.3188
841.50439	2.4873781	0.8985557	3516.9651
842.60547	2.4892554	0.90017068	3518.5061
843.70654	2.4930077	0.90202647	3518.3223
844.80762	2.4931695	0.90357137	3518.9724
845.90869	2.5014992	0.90533268	3519.5942
847.00977	2.5019782	0.90696448	3514.2671
848.11084	2.5028973	0.90860373	3518.79
849.21191	2.5121922	0.91068107	3524.7729
850.31299	2.5133634	0.91270059	3521.4592
851.41406	2.5157859	0.91439724	3511.646
852.51514	2.5217748	0.91624564	3521.6938
853.61621	2.5266178	0.91809857	3524.2319
854.71729	2.5249364	0.91969353	3515.3123
855.81836	2.527384	0.92130959	3513.3762
856.91943	2.5312822	0.92292726	3520.2803
858.02051	2.5332978	0.92460543	3514.2258
859.12158	2.5386565	0.92625397	3522.1265
860.22266	2.544776	0.92829597	3521.3318
861.32373	2.5461845	0.92988235	3521.4495
862.4248	2.5515449	0.93134892	3516.1677
863.52588	2.5532541	0.93286091	3522.9937
864.62695	2.5552576	0.93446636	3520.5645
865.72803	2.5591669	0.9363749	3526.5486
866.8291	2.560133	0.93847358	3520.1301
867.93018	2.5672555	0.94071811	3528.374
869.03125	2.5681663	0.94263685	3524.3479
870.13232	2.5731776	0.94402701	3514.2827
871.2334	2.5751128	0.9457047	3517.7385
872.33447	2.5788059	0.94725597	3523.6135
873.43555	2.5813439	0.94927162	3528.6873
874.53662	2.5851083	0.95117325	3525.3379
875.6377	2.5883057	0.9531945	3529.1694
876.73877	2.5927916	0.95542496	3525.53
877.83984	2.596261	0.95752501	3527.5999
878.94092	2.5989873	0.95938545	3525.0156
880.04199	2.6022491	0.96112484	3517.0439
881.14307	2.6073613	0.96272725	3524.7346
882.24414	2.6080406	0.96455294	3525.9568
883.34521	2.6126568	0.96632683	3524.7119
884.44629	2.616961	0.96841609	3530.4963
885.54736	2.6205637	0.97026432	3525.9553
886.64844	2.6201942	0.97161394	3519.4438
887.74951	2.6245434	0.97325283	3526.9058
888.85059	2.6284945	0.97520709	3530.4067
889.95166	2.631829	0.977274	3530.4116
891.05273	2.6336241	0.97890759	3523.0283
892.15381	2.6399302	0.98057723	3524.1384
893.25488	2.639535	0.98234302	3523.238
894.35596	2.6435974	0.98415607	3526.2263
895.45703	2.6480742	0.9859615	3524.0923
896.55811	2.6490099	0.98789263	3530.4661
897.65918	2.653645	0.98981583	3525.302
898.76025	2.6582487	0.99169725	3524.4885
899.86133	2.6608675	0.99349535	3528.1643
900.9624	2.6661673	0.99535394	3528.9949
902.06348	2.6694868	0.9973954	3529.0991
903.16455	2.6721361	0.99944788	3535.0007
904.26563	2.672586	1.0016739	3527.0305
905.3667	2.6771765	1.0033641	3526.7683
906.46777	2.6809011	1.0049013	3520.343
907.56885	2.685215	1.0066749	3527.8569
908.66992	2.6865835	1.0084095	3527.6033
909.771	2.6930366	1.0102924	3529.9436
910.87207	2.6930244	1.0121673	3530.738
911.97314	2.6968601	1.0142244	3526.5049
913.07422	2.7029779	1.0161413	3527.0732
914.17529	2.7020874	1.0179844	3530.7451
915.27637	2.7081084	1.0201821	3528.9548
916.37744	2.7125237	1.0218496	3532.2437
917.47852	2.7137094	1.0238807	3524.9231
918.57959	2.7164071	1.0258312	3529.0706
919.68066	2.7210684	1.027769	3530.7856
920.78174	2.7261715	1.0297892	3528.7446
921.88281	2.7263038	1.0316281	3531.0305
922.98389	2.7317145	1.0338216	3531.9756
924.08496	2.7345469	1.0360471	3525.5266
925.18604	2.7403963	1.0377135	3527.2576
926.28711	2.7425134	1.039377	3525.0588
927.38818	2.7448552	1.0409749	3527.0212
928.48926	2.7456617	1.0428705	3530.5854
929.59033	2.7484565	1.0446658	3523.6011
930.69141	2.7520833	1.04663	3526.2971
931.79248	2.7579198	1.048861	3535.2317
932.89355	2.7612212	1.0506773	3523.6873
933.99463	2.7635214	1.0524156	3525.9177
935.0957	2.7650042	1.054493	3532.2668
936.19678	2.7692163	1.0564957	3525.9451
937.29785	2.7730041	1.0582819	3527.2183
938.39893	2.7787459	1.0601711	3530.0054
939.5	2.7817979	1.0620949	3525.5603
940.60107	2.7842426	1.0640951	3525.4431
941.70215	2.7848744	1.0660708	3531.0261
942.80322	2.7880704	1.0684719	3530.562
943.9043	2.7917356	1.0706887	3529.958
945.00537	2.7949042	1.0732497	3528.6118
946.10645	2.8028679	1.0752909	3531.2813
947.20752	2.8030002	1.0768993	3524.541
948.30859	2.8045003	1.0788943	3524.3728
949.40967	2.8108604	1.0809364	3535.1704
950.51074	2.8143003	1.0829688	3529.7566
951.61182	2.8158145	1.0849462	3528.5813
952.71289	2.8197041	1.0868684	3527.7319
953.81396	2.8205507	1.0889795	3522.4805
954.91504	2.8270977	1.0907744	3526.1836
956.01611	2.8297484	1.092759	3533.1245
957.11719	2.8342679	1.0947888	3531.4065
958.21826	2.8371546	1.0966169	3525.3823
959.31934	2.8415854	1.0986657	3529.2039
960.42041	2.8427587	1.1004938	3528.072
961.52148	2.8467586	1.1021607	3522.4272
962.62256	2.8498335	1.1043719	3526.8916
963.72363	2.8555944	1.1062849	3533.2598
964.82471	2.8561535	1.1083481	3531.3037
965.92578	2.8600705	1.110239	3530.4905
967.02686	2.8636689	1.1122824	3527.0879
968.12793	2.864933	1.1143316	3524.4387
969.229	2.8689935	1.1161596	3528.4072
970.33008	2.8745751	1.1183134	3527.7964
971.43115	2.8763239	1.1201918	3524.6436
972.53223	2.8797572	1.1221375	3529.2542
973.6333	2.8856964	1.1243305	3535.2329
974.73438	2.8856833	1.1263808	3525.281
975.83545	2.8889396	1.1281809	3518.8464
976.93652	2.8921497	1.1301954	3526.4341
978.0376	2.8944597	1.1327212	3527.1421
979.13867	2.8991244	1.1351837	3531.72
980.23975	2.9055557	1.1374353	3528.4792
981.34082	2.9065325	1.1396643	3521.7344
982.44189	2.9119389	1.1416756	3526.0408
983.54297	2.9122365	1.1433891	3525.4705
984.64404	2.914396	1.145236	3523.3298
985.74512	2.9200425	1.1472949	3531.3289
986.84619	2.9233978	1.1495093	3527.9348
987.94727	2.9243665	1.1516443	3527.499
989.04834	2.9345672	1.1538472	3529.4026
990.14941	2.9320793	1.1560997	3525.79
991.25049	2.935925	1.1578469	3523.4092
992.35156	2.9389162	1.1596845	3519.1538
993.45264	2.9417224	1.1616504	3524.7739
994.55371	2.9459939	1.1634464	3518.0427
995.65479	2.949425	1.165341	3522.0388
996.75586	2.9534764	1.1674072	3523.0388
997.85693	2.9538846	1.1693197	3517.7905
998.95801	2.960633	1.1709825	3523.1475
1000.0591	2.9606614	1.1729138	3525.6514
1001.1602	2.9637895	1.1750427	3524.8
1002.2612	2.9729102	1.1770066	3526.2141
1003.3623	2.972611	1.1791779	3525.8145
1004.4634	2.9748852	1.1813085	3518.4363
1005.5645	2.9817228	1.1835879	3529.8008
1006.6655	2.9812016	1.1859413	3524.9912
1007.7666	2.9855771	1.187959	3518.5161
1008.8677	2.9891663	1.1897407	3513.0579
1009.9688	2.9934692	1.1913503	3515.5513
1011.0698	2.99733	1.1926119	3513.8049
1012.1709	2.9990268	1.1942188	3520.7354
1013.272	3.000937	1.1964698	3522.2559
1014.373	3.0020344	1.1986158	3527.075
1015.4741	3.0108883	1.2009135	3523.6602
1016.5752	3.0113585	1.2028693	3517.8577
1017.6763	3.0136023	1.2051233	3518.6033
1018.7773	3.0159886	1.2071942	3519.2351
1019.8784	3.0164852	1.2091484	3513.3601
1020.9795	3.0238886	1.2112619	3515.1423
1022.0806	3.0271757	1.2131203	3517.5283
1023.1816	3.0319841	1.2150921	3520.4792
1024.2827	3.0354331	1.2169861	3516.7288
1025.3838	3.0367839	1.2191117	3516.1489
1026.4849	3.0442986	1.2211535	3514.0098
1027.5859	3.0443873	1.223285	3514.2239
1028.687	3.047401	1.2252841	3515.8289
1029.7881	3.0507772	1.2271966	3520.2498
1030.8892	3.053514	1.2291952	3518.3149
1031.9902	3.0578048	1.2313305	3513.0413
1033.0913	3.0636773	1.2334765	3516.8491
1034.1924	3.066848	1.2353665	3514.7446
1035.2935	3.0709183	1.2373617	3516.4985
1036.3945	3.0715997	1.2396456	3516.8535
1037.4956	3.0737207	1.2421602	3510.4114
1038.5967	3.0763848	1.2440985	3510.7971
1039.6978	3.0816512	1.2462723	3511.9595
1040.7988	3.0885243	1.2480488	3518.4048
1041.8999	3.0882421	1.2499835	3512.363
1043.001	3.0927153	1.2522062	3517.7271
1044.1021	3.0906734	1.2541649	3505.5676
1045.2031	3.0965853	1.256181	3511.5967
1046.3042	3.1008794	1.2579623	3510.9734
1047.4053	3.1046412	1.2600344	3508.8025
1048.5063	3.1085274	1.2620111	3510.2612
1049.6074	3.1093082	1.2640507	3510.6396
1050.7085	3.1133146	1.2662911	3513.1128
1051.8096	3.1173575	1.2682914	3510.7788
1052.9106	3.1181939	1.270627	3505.0735
1054.0117	3.1238174	1.2725486	3507.1775
1055.1128	3.1266136	1.2748103	3512.6313
1056.2139	3.1305063	1.2769785	3502.9556
1057.3149	3.1332583	1.2792126	3499.3071
1058.416	3.1381409	1.2811996	3503.7505
1059.5171	3.1414495	1.283101	3502.1375
1060.6182	3.1445422	1.2848752	3500.876
1061.7192	3.1480708	1.2867876	3500.5244
1062.8203	3.1500711	1.2888113	3501.2615
1063.9214	3.1537967	1.2905942	3503.0571
1065.0225	3.1580141	1.2925234	3501.1702
1066.1235	3.1608021	1.2945324	3501.731
1067.2246	3.1641109	1.296643	3499.4692
1068.3257	3.1662803	1.2984302	3495.3228
1069.4268	3.1683018	1.3004947	3500.5583
1070.5278	3.1769788	1.3023645	3499.9033
1071.6289	3.1775374	1.3041615	3491.6677
1072.73	3.1763315	1.3061948	3496.5144
1073.8311	3.1851349	1.3080933	3498.9941
1074.9321	3.1861057	1.3102052	3493.2192
1076.0332	3.1919594	1.3121346	3491.437
1077.1343	3.1962523	1.3143848	3498.8723
1078.2354	3.1979957	1.3163346	3489.7861
1079.3364	3.2022581	1.3182505	3495.2964
1080.4375	3.2029021	1.320107	3485.2051
1081.5386	3.2070587	1.3218553	3488.3772
1082.6396	3.2082188	1.3236713	3487.1289
1083.7407	3.2114778	1.3256199	3481.323
1084.8418	3.218049	1.3274566	3488.8574
1085.9429	3.2186892	1.3292804	3481.2349
1087.0439	3.2236555	1.3311909	3487.543
1088.145	3.2247553	1.3330902	3479.832
1089.2461	3.2286825	1.3350146	3475.0999
1090.3472	3.2342763	1.3366785	3479.2026
1091.4482	3.2357011	1.3386291	3478.0793
1092.5493	3.2429378	1.3406539	3480.6248
1093.6504	3.2432885	1.3424599	3472.7183
1094.7515	3.2453573	1.3440419	3478.6689
1095.8525	3.2520185	1.3458711	3478.3257
1096.9536	3.2550213	1.3478687	3475.4365
1098.0547	3.2539523	1.3494952	3470.9209
1099.1558	3.2594135	1.3512144	3464.4773
1100.2568	3.2635524	1.3528588	3468.6013
1101.3579	3.2646086	1.3547853	3468.7871
1102.459	3.2685142	1.356771	3467.0491
1103.5601	3.2723508	1.358556	3462.1848
1104.6611	3.2771611	1.3604721	3464.1072
1105.7622	3.2812545	1.3622782	3456.8186
1106.8633	3.281451	1.363598	3453.5845
1107.9644	3.2889316	1.3651427	3461.001
1109.0654	3.2891529	1.3673515	3462.5708
1110.1665	3.2946444	1.3692392	3452.8926
1111.2676	3.2975585	1.3711764	3459.7402
1112.3687	3.2989171	1.3726906	3452.8503
1113.4697	3.3040271	1.3746802	3450.3894
1114.5708	3.3053584	1.3762884	3445.2502
1115.6719	3.3066728	1.3774656	3438.5991
1116.7729	3.3142416	1.3791288	3445.8408
1117.874	3.3136218	1.3808777	3443.4448
1118.9751	3.3200817	1.3826886	3447.717
1120.0762	3.3254721	1.3844361	3439.0596
1121.1772	3.3232014	1.386202	3440.4746
1122.2783	3.3298128	1.3882402	3436.5168
1123.3794	3.3314631	1.390031	3430.0168
1124.4805	3.3368964	1.3918303	3429.5439
1125.5815	3.3402455	1.3935171	3435.7205
1126.6826	3.3417594	1.3951411	3423.9084
1127.7837	3.3431623	1.3968867	3424.0352
1128.8848	3.3472881	1.3987733	3426.2681
1129.9858	3.3535576	1.4006413	3418.8081
1131.0869	3.3538463	1.4022382	3414.9878
1132.188	3.3582828	1.4038868	3415.2498
1133.2891	3.3637762	1.4055727	3415.0762
1134.3901	3.3668203	1.4072859	3420.0491
1135.4912	3.367557	1.4089708	3412.3167
1136.5923	3.3744965	1.410587	3412.677
1137.6934	3.3735311	1.4118716	3403.4814
1138.7944	3.3785756	1.4133339	3400.04
1139.8955	3.3832266	1.4146677	3407.5713
1140.9966	3.3856063	1.4161987	3394.615
1142.0977	3.3881288	1.4176364	3400.2627
1143.1987	3.3908517	1.4193085	3396.3867
1144.2998	3.397613	1.4210482	3396.7336
1145.4009	3.4012818	1.4225091	3395.6047
1146.502	3.4023826	1.4241036	3391.5886
1147.603	3.4025042	1.4256918	3381.3098
1148.7041	3.4045937	1.4272643	3382.9133
1149.8052	3.4124537	1.4291195	3383.0979
1150.9063	3.4165237	1.4305366	3377.1125
1152.0073	3.42097	1.4322207	3375.1763
1153.1084	3.4229059	1.4335386	3373.3584
1154.2095	3.4227247	1.4348121	3367.6116
1155.3105	3.4260716	1.4366308	3368.292
1156.4116	3.4311602	1.4380969	3363.4199
1157.5127	3.4321575	1.4394426	3353.5251
1158.6138	3.4397674	1.4412433	3362.8838
1159.7148	3.4429669	1.4429052	3357.9905
1160.8159	3.4418502	1.4444401	3350.666
1161.917	3.4471834	1.4460441	3354.2551
1163.0181	3.4500337	1.4476491	3341.1594
1164.1191	3.4553077	1.4490124	3339.5293
1165.2202	3.4572334	1.4504796	3339.6797
1166.3213	3.4624236	1.4521039	3334.729
1167.4224	3.4658036	1.4538317	3336.804
1168.5234	3.4698279	1.455381	3329.6611
1169.6245	3.4713542	1.4569801	3330.6462
1170.7256	3.4748724	1.4587567	3319.9089
1171.8267	3.4793036	1.4601945	3313.7622
1172.9277	3.4824219	1.4614983	3314.4507
1174.0288	3.4850726	1.4631063	3318.4592
1175.1299	3.4895971	1.4645466	3307.9204
1176.231	3.4924157	1.4660616	3311.5056
1177.332	3.4948683	1.4676042	3301.4775
1178.4331	3.4982259	1.4691014	3299.2673
1179.5342	3.5007298	1.4709266	3293.4312
1180.6353	3.5031879	1.4722685	3286.9954
1181.7363	3.5076251	1.4736167	3285.1958
1182.8374	3.5090253	1.4750711	3279.3374
1183.9385	3.5128162	1.476424	3281.2771
1185.0396	3.5212152	1.4779638	3275.499
1186.1406	3.5192738	1.4799196	3273.6938
1187.2417	3.5274582	1.4817047	3270.8386
1188.3428	3.5288827	1.483904	3262.0706
1189.4438	3.5308387	1.4854958	3255.3403
1190.5449	3.5326893	1.4872401	3253.75
1191.646	3.5377681	1.4891452	3250.4277
1192.7471	3.541827	1.4912614	3243.5259
1193.8481	3.5439556	1.4930612	3237.9487
1194.9492	3.5494349	1.4948056	3239.4023
1196.0503	3.5500746	1.497202	3234.0142
1197.1514	3.5541654	1.499267	3225.9744
1198.2524	3.5564671	1.5014844	3221.9441
1199.3535	3.5615337	1.5032772	3215.0818
1200.4546	3.5662231	1.5047884	3207.8477
1201.5557	3.5664079	1.506483	3204.7605
1202.6567	3.5701826	1.5086826	3207.8394
1203.7578	3.5714924	1.5112875	3197.502
1204.8589	3.5771813	1.5135052	3188.4612
1205.96	3.581141	1.515318	3186.7974
1207.061	3.582628	1.5170052	3179.3706
1208.1621	3.585938	1.5190675	3174.9929
1209.2632	3.5907934	1.5212737	3168.7725
1210.3643	3.5948446	1.5231018	3159.0605
1211.4653	3.5977721	1.5247725	3154.6057
1212.5664	3.6024351	1.5265998	3153.8215
1213.6675	3.6049545	1.5282278	3144.0378
1214.7686	3.6082211	1.5297992	3140.8042
1215.8696	3.6111686	1.5316054	3133.6877
1216.9707	3.612674	1.5334711	3128.3391
1218.0718	3.6167743	1.5354919	3124.0693
1219.1729	3.6187067	1.5373442	3108.731
1220.2739	3.6214879	1.5391378	3100.5183
1221.375	3.6304674	1.5412	3100.4592
1222.4761	3.6301618	1.5426779	3089.189
1223.5771	3.6325312	1.5446507	3085.6948
1224.6782	3.638941	1.5467335	3084.8098
1225.7793	3.6384645	1.5490549	3065.8938
1226.8804	3.6418719	1.5510678	3058.0286
1227.9814	3.6464496	1.5530366	3039.417
1229.0825	3.6524434	1.5549955	3030.6006
1230.1836	3.6534557	1.5567929	3018.7585
1231.2847	3.660032	1.5582794	3016.5056
1232.3857	3.6611683	1.5607345	3002.0547
1233.4868	3.6620843	1.5623281	2985.7661
1234.5879	3.6684484	1.5639271	2983.377
1235.689	3.6677926	1.5655037	2964.8386
1236.79	3.6719515	1.567175	2941.2981
1237.8911	3.6813793	1.5707285	2862.9395
1237.9912	3.6810818	1.571371	2843.7625