File: datasets/am_bench_2022/raw_data/60-X.14-3/specimen.dat
MTS793|MPT|ENU|1|2|.|/|:|1|0|0|A

Operator Information						Time:	15.697998	Sec	11/1/2021 12:27:22 PM
Operator	Nick Derimow
Project	AM Bench 2022 mini-tensile challenge
Specimen ID	60-X.14-3
Material	PBF-L Inconel 625
Specimen Width	2.55	mm
Specimen Thickness	1.52	mm
Notes
Operator Information End

Data Acquisition						Time:	1016.6919	Sec	11/1/2021 12:44:03 PM
Time	Axial Displacement	Axial Extensometer	Axial Force
Sec	mm	mm	N
15.811768	-0.00055900321	3.9306145e-05	30.399139
16.712646	-0.00051187829	-3.6452289e-05	40.79636
17.613525	0.00088071439	7.4694915e-05	52.971306
18.514404	0.0063115032	1.0294608e-05	67.24939
19.415283	0.0088701816	0.000111312	80.05555
20.316162	0.0093926536	0.00010525133	86.951836
21.217041	0.013487502	0.00019406337	103.03694
22.11792	0.017211804	0.00027327728	111.39653
23.018799	0.018162088	0.00031804905	121.38884
23.919678	0.01890195	0.00036977889	133.67247
24.820557	0.023568034	0.00026974906	145.95076
25.721436	0.028350139	0.00039974623	154.41383
26.622314	0.028503602	0.00047442489	164.13225
27.523193	0.031777348	0.00055867911	176.06517
28.424072	0.036072429	0.00061512558	194.85515
29.324951	0.037882589	0.00061366265	207.68172
30.22583	0.041481856	0.00070884579	222.73947
31.126709	0.046138413	0.00069733092	246.49783
32.027588	0.045851156	0.00074430008	254.56381
32.928467	0.048260212	0.00081411772	272.59995
33.829346	0.053157467	0.00091410655	294.91318
34.730225	0.052952781	0.00095001166	307.07217
35.631104	0.05452916	0.00099843973	320.18243
36.531982	0.060097225	0.0010517226	342.64264
37.432861	0.061587192	0.0011640838	360.57352
38.33374	0.063980475	0.0013289616	385.41028
39.234619	0.066470511	0.0013143447	405.26666
40.135498	0.069628648	0.0014641302	425.15958
41.036377	0.073639952	0.0015520202	448.12524
41.937256	0.075589903	0.0016597663	471.09506
42.838135	0.077851027	0.0017395662	491.83408
43.739014	0.080385476	0.0019081412	507.68198
44.639893	0.080160715	0.0017627844	522.4845
45.540771	0.085453868	0.002003053	550.41699
46.44165	0.089381777	0.0019971847	569.9621
47.342529	0.091246031	0.0021956484	589.67175
48.243408	0.094234928	0.0022725102	615.15375
49.144287	0.095616922	0.0023315966	638.28064
50.045166	0.098986559	0.002425075	665.09821
50.946045	0.10272659	0.0024675357	684.17853
51.846924	0.10298249	0.0025314647	706.9613
52.747803	0.10749962	0.0026342666	735.47003
53.648682	0.10911867	0.0027551583	755.24298
54.549561	0.11211151	0.0028770799	784.52313
55.450439	0.11588719	0.0030463259	809.79718
56.351318	0.11655452	0.0029982298	829.04858
57.252197	0.12037732	0.0032852872	866.61426
58.153076	0.12364569	0.0032546406	881.20306
59.053955	0.12801187	0.0034524363	912.50873
59.954834	0.13084014	0.0035201802	932.13165
60.855713	0.13086882	0.0036694044	959.20947
61.756592	0.13155951	0.0037607274	984.97607
62.657471	0.13638259	0.0038954085	1009.1748
63.55835	0.13730009	0.0039344523	1030.3696
64.459229	0.13888758	0.0039971401	1058.3094
65.360107	0.1434187	0.0040898891	1078.7969
66.260986	0.14860255	0.0042697359	1106.3923
67.161865	0.15057933	0.0043139802	1138.5995
68.062744	0.15378977	0.0045321207	1169.4351
68.963623	0.15259874	0.0045370501	1189.9958
69.864502	0.15817331	0.0047180285	1213.2347
70.765381	0.15910023	0.004718184	1238.3864
71.66626	0.15910822	0.0048519317	1255.5006
72.567139	0.1648818	0.0048740632	1278.8379
73.468018	0.17019375	0.0050231814	1299.0005
74.368896	0.17331479	0.0052273688	1334.0677
75.269775	0.17354509	0.005217317	1350.4263
76.170654	0.17758735	0.0053244582	1383.1085
77.071533	0.17983253	0.0054291845	1402.4849
77.972412	0.18487562	0.005595821	1427.8621
78.873291	0.18617812	0.005717217	1457.7698
79.77417	0.18679298	0.0057954844	1475.3053
80.675049	0.18907318	0.0058919908	1495.6224
81.575928	0.1923631	0.0060264384	1532.5072
82.476807	0.19487748	0.0061078416	1553.9991
83.377686	0.19707493	0.0061380467	1575.7766
84.278564	0.20203954	0.006325494	1604.8687
85.179443	0.20326439	0.0064365398	1623.356
86.080322	0.20409583	0.0065419227	1655.2548
86.981201	0.208378	0.0065775234	1671.7013
87.88208	0.21249154	0.0067705573	1700.8739
88.782959	0.2103222	0.0068246066	1721.1257
89.683838	0.21714477	0.0069213519	1745.5338
90.584717	0.21758324	0.0070644254	1769.7225
91.485596	0.22290953	0.0071642348	1789.0444
92.386475	0.22683662	0.0072414861	1808.999
93.287354	0.2298497	0.0074156164	1832.8569
94.188232	0.23278067	0.0074718511	1848.171
95.089111	0.23541796	0.0075451639	1871.8969
95.98999	0.23575789	0.007683197	1886.2156
96.890869	0.23856525	0.0077427505	1908.2251
97.791748	0.24203052	0.0078731449	1926.8768
98.692627	0.24629696	0.0079713603	1944.109
99.593506	0.24877855	0.0080533288	1961.0531
100.49438	0.24943523	0.0081693232	1982.2438
101.39526	0.25087398	0.0082244677	1997.0122
102.29614	0.25532514	0.0083188396	2013.4105
103.19702	0.2582235	0.0084463125	2034.6442
104.0979	0.26140055	0.008493077	2046.7682
104.99878	0.2624481	0.0086070811	2065.7097
105.89966	0.26721832	0.0087195886	2077.2227
106.80054	0.27110425	0.0088449977	2087.9233
107.70142	0.2716845	0.0087823924	2095.4873
108.60229	0.27220267	0.0089412825	2109.4976
109.50317	0.27732304	0.0090100346	2123.3447
110.40405	0.28029943	0.0092119323	2137.9229
111.30493	0.282763	0.0092449514	2153.7473
112.20581	0.28537801	0.0092035159	2152.6187
113.10669	0.28495654	0.0092732841	2162.2693
114.00757	0.29161507	0.0093923202	2174.0183
114.90845	0.29490042	0.0093859155	2184.8794
115.80933	0.29599348	0.0094962241	2196.5349
116.71021	0.29853106	0.0096207717	2210.7327
117.61108	0.30234587	0.009673276	2219.8108
118.51196	0.3035244	0.0097729946	2235.658
119.41284	0.30735293	0.0097398609	2238.8865
120.31372	0.31085202	0.0098619051	2248.7471
121.2146	0.31587118	0.0099322107	2262.8225
122.11548	0.31582958	0.0098957615	2269.8052
123.01636	0.31607464	0.0098826932	2276.2891
123.91724	0.31937578	0.0099472981	2279.1794
124.81812	0.3257671	0.010102952	2296.9221
125.71899	0.32508644	0.01020436	2303.7278
126.61987	0.33073831	0.010251062	2317.3848
127.52075	0.33290294	0.010259422	2325.9421
128.42163	0.33755925	0.010388079	2335.2102
129.32251	0.33897504	0.010433312	2345.0386
130.22339	0.34416181	0.010564459	2354.3
131.12427	0.34524956	0.01063649	2360.1514
132.02515	0.34674564	0.010695626	2373.7168
132.92603	0.34566605	0.010644276	2367.5154
133.8269	0.35085672	0.010810752	2386.3335
134.72778	0.35487974	0.01081185	2392.5225
135.62866	0.35707265	0.010904792	2400.6792
136.52954	0.35896578	0.01090367	2408.6563
137.43042	0.36361799	0.010981973	2417.731
138.3313	0.36643791	0.011108214	2422.7532
139.23218	0.36813769	0.011179126	2424.0808
140.13306	0.37123045	0.011214936	2433.8906
141.03394	0.37455148	0.011358677	2446.9031
141.93481	0.37617663	0.011343602	2450.6355
142.83569	0.37932354	0.011499871	2456.3567
143.73657	0.38249829	0.011608047	2470.5264
144.63745	0.38258556	0.011592529	2470.8257
145.53833	0.3856276	0.011611006	2476.4014
146.43921	0.38664728	0.011730862	2481.7542
147.34009	0.39144516	0.011894052	2489.4255
148.24097	0.39461747	0.011979855	2498.9749
149.14185	0.39783955	0.012076472	2503.9097
150.04272	0.4003152	0.012188029	2506.665
150.9436	0.4033094	0.012340389	2516.5588
151.84448	0.40863371	0.012440596	2525.6104
152.74536	0.40890765	0.012568517	2536.01
153.64624	0.41082352	0.012699218	2541.1936
154.54712	0.41164207	0.012753879	2542.1199
155.448	0.41562122	0.013060475	2562.366
156.34888	0.41764918	0.01310131	2563.0166
157.24976	0.42108643	0.013272948	2563.3145
158.15063	0.42717937	0.013506361	2576.5896
159.05151	0.42717916	0.013659074	2580.2012
159.95239	0.43133083	0.013963173	2583.9888
160.85327	0.434154	0.014196008	2590.9529
161.75415	0.43426526	0.014470313	2596.9045
162.65503	0.43559131	0.014643386	2598.5393
163.55591	0.43802086	0.014934869	2611.4824
164.45679	0.44532102	0.01524505	2620.0691
165.35767	0.44537348	0.015535272	2624.8203
166.25854	0.45088479	0.015773674	2636.967
167.15942	0.45250958	0.015992176	2630.052
168.0603	0.45587692	0.016296547	2637.7847
168.96118	0.45637065	0.016752541	2646.8411
169.86206	0.4590039	0.016894186	2643.793
170.76294	0.46272984	0.017304307	2648.3223
171.66382	0.46506596	0.017684713	2661.5779
172.5647	0.46765041	0.018103655	2663.1619
173.46558	0.46924037	0.018562775	2668.7747
174.36646	0.47241613	0.019010384	2670.0701
175.26733	0.47667247	0.019285716	2675.3535
176.16821	0.47623733	0.019829269	2680.6174
177.06909	0.48242351	0.020291775	2688.4153
177.96997	0.4837997	0.02080833	2685.6621
178.87085	0.48826653	0.021159751	2697.1199
179.77173	0.48670527	0.021726968	2694.1626
180.67261	0.49072662	0.022188585	2703.3789
181.57349	0.4945322	0.022864062	2706.8975
182.47437	0.49825788	0.023244565	2705.6821
183.37524	0.501773	0.023779828	2713.6924
184.27612	0.5035764	0.024340695	2720.0657
185.177	0.50890779	0.024865657	2724.2517
186.07788	0.50756001	0.025348427	2720.6792
186.97876	0.50818843	0.026012087	2728.7529
187.87964	0.51273203	0.026599789	2735.7737
188.78052	0.51750165	0.027364897	2737.0967
189.6814	0.51925427	0.027875807	2739.7954
190.58228	0.52115971	0.028579418	2743.2854
191.48315	0.52681017	0.029197585	2752.2893
192.38403	0.52902341	0.029918874	2750.0149
193.28491	0.53005105	0.030499421	2760.8391
194.18579	0.53562772	0.031292886	2767.5784
195.08667	0.53552693	0.031953733	2763.7737
195.98755	0.5385353	0.032710284	2763.552
196.88843	0.53964275	0.033341628	2768.2148
197.78931	0.54368788	0.034040783	2779.7439
198.69019	0.54631478	0.035015561	2781.9956
199.59106	0.54715925	0.035828508	2786.2856
200.49194	0.55445802	0.036590356	2786.7896
201.39282	0.55420852	0.037419122	2785.7498
202.2937	0.5566557	0.03813858	2791.0718
203.19458	0.55906868	0.038998667	2792.3228
204.09546	0.55988842	0.039654583	2796.1851
204.99634	0.56778502	0.040524568	2808.5417
205.89722	0.57059115	0.041154332	2807.2869
206.7981	0.57081836	0.041982703	2804.5134
207.69897	0.5770638	0.042737674	2811.0764
208.59985	0.57814741	0.043560296	2809.9336
209.50073	0.57889962	0.044271626	2811.0371
210.40161	0.57999492	0.044978287	2810.2937
211.30249	0.58467275	0.045766469	2814.6868
212.20337	0.58921862	0.04645545	2823.8618
213.10425	0.58784133	0.047300681	2828.3569
214.00513	0.58987737	0.048350293	2825.0088
214.90601	0.59277773	0.049149219	2824.7278
215.80688	0.59645611	0.049962085	2829.8762
216.70776	0.60220402	0.050960165	2836.749
217.60864	0.60043508	0.051713992	2831.1313
218.50952	0.60490549	0.052600358	2836.8821
219.4104	0.60710335	0.053577442	2846.0603
220.31128	0.61113167	0.054415062	2845.3367
221.21216	0.61538148	0.055429459	2848.958
222.11304	0.61519974	0.056394041	2851.5552
223.01392	0.62085444	0.057533775	2856.2166
223.91479	0.62589985	0.058521602	2854.8306
224.81567	0.62804502	0.059320755	2855.7236
225.71655	0.62952882	0.060070619	2856.7017
226.61743	0.62827939	0.061002888	2866.4392
227.51831	0.63564044	0.061961044	2866.6838
228.41919	0.63848776	0.062846482	2866.1055
229.32007	0.63833493	0.063672036	2866.4004
230.22095	0.64064282	0.064780347	2875.9265
231.12183	0.64516836	0.065823689	2874.3958
232.02271	0.64745557	0.066753075	2873.0046
232.92358	0.64852428	0.067667544	2874.9536
233.82446	0.6521014	0.068731546	2882.9053
234.72534	0.65709722	0.069715261	2879.5193
235.62622	0.65567833	0.070641048	2880.3032
236.5271	0.66222125	0.071697094	2886.3496
237.42798	0.66236246	0.072702229	2891.8972
238.32886	0.6661846	0.07378681	2887.0063
239.22974	0.66646308	0.074653752	2889.3445
240.13062	0.67039961	0.075658768	2895.0557
241.03149	0.6722542	0.076766975	2897.9917
241.93237	0.6772691	0.077672467	2894.2852
242.83325	0.67803967	0.078737281	2899.2339
243.73413	0.68311107	0.079668231	2903.1055
244.63501	0.68427694	0.080770105	2903.1118
245.53589	0.68733054	0.08174777	2905.324
246.43677	0.69025129	0.082746111	2909.9917
247.33765	0.68881971	0.08365459	2910.8206
248.23853	0.69412696	0.084751762	2907.9319
249.1394	0.69714963	0.085856147	2911.9285
250.04028	0.70062846	0.086860068	2912.5857
250.94116	0.70653087	0.08790341	2915.6003
251.84204	0.7063967	0.088633299	2917.1392
252.74292	0.7091924	0.089778237	2923.6616
253.6438	0.71150613	0.09076523	2925.1516
254.54468	0.71483749	0.091908954	2920.0256
255.44556	0.71832854	0.092959121	2924.6165
256.34644	0.71976179	0.09401574	2927.1738
257.24731	0.72290516	0.095153578	2934.8821
258.14819	0.72361612	0.096239425	2933.2419
259.04907	0.73002017	0.097326785	2934.1235
259.94995	0.7309233	0.098193318	2932.5415
260.85083	0.73216677	0.099185482	2940.8633
261.75171	0.73484915	0.10017798	2937.7126
262.65259	0.74069279	0.10141318	2940.7805
263.55347	0.74206638	0.10241864	2945.9929
264.45435	0.74283165	0.10367706	2938.6245
265.35522	0.74605858	0.10454992	2943.5334
266.2561	0.75022399	0.10566777	2943.1077
267.15698	0.75379193	0.1066563	2948.9829
268.05786	0.754641	0.10768606	2947.8745
268.95874	0.75905323	0.10874521	2955.5151
269.85962	0.760912	0.10993937	2958.7629
270.7605	0.76461786	0.11122108	2956.9771
271.66138	0.76638621	0.11246695	2960.5803
272.56226	0.7701568	0.11352071	2956.2424
273.46313	0.7694813	0.11462337	2958.0398
274.36401	0.77380872	0.11573248	2964.1721
275.26489	0.7762844	0.11677407	2965.0935
276.16577	0.77915835	0.11771408	2964.4917
277.06665	0.77844477	0.11867065	2964.7544
277.96753	0.78579593	0.11974069	2968.2805
278.86841	0.78648126	0.12106205	2973.8438
279.76929	0.7913931	0.122219	2973.9866
280.67017	0.79122776	0.1233178	2971.0991
281.57104	0.79707241	0.12423491	2973.9077
282.47192	0.8002125	0.12529336	2976.7075
283.3728	0.80246013	0.12638311	2982.8762
284.27368	0.80527121	0.12768157	2986.1216
285.17456	0.80607289	0.12878717	2983.29
286.07544	0.80843323	0.12984286	2977.2019
286.97632	0.81067866	0.13089773	2983.9143
287.8772	0.81507498	0.13178806	2979.2178
288.77808	0.81712133	0.13262244	2987.7295
289.67896	0.8203969	0.13377669	2993.6064
290.57983	0.82217413	0.13510518	2993.3052
291.48071	0.82611471	0.13621825	2992.2485
292.38159	0.82649869	0.13733014	2988.1338
293.28247	0.82980621	0.13848878	2993.4944
294.18335	0.83140171	0.13960215	2995.6404
295.08423	0.8386609	0.14060971	2998.6133
295.98511	0.8375324	0.14149939	2997.9934
296.88599	0.84296292	0.14260589	3003.0061
297.78687	0.84449345	0.14362709	3000.0603
298.68774	0.84744096	0.14466412	3001.1946
299.58862	0.84731293	0.14579087	2997.397
300.4895	0.85162032	0.14693126	3007.219
301.39038	0.85714555	0.14816989	3011.1492
302.29126	0.85860908	0.14923741	3002.4299
303.19214	0.86134613	0.15025279	3008.6309
304.09302	0.86185491	0.15150166	3014.2058
304.9939	0.86823845	0.15260065	3020.2947
305.89478	0.86701238	0.15373559	3012.8047
306.79565	0.86913496	0.15476079	3011.6064
307.69653	0.87260699	0.15589279	3015.082
308.59741	0.8750487	0.15692307	3014.7749
309.49829	0.87904632	0.15794313	3019.6001
310.39917	0.87880576	0.15889649	3018.885
311.30005	0.88407648	0.15999065	3021.2324
312.20093	0.8866753	0.16105272	3026.0388
313.10181	0.8924073	0.16246428	3031.4968
314.00269	0.89489543	0.16363238	3031.3911
314.90356	0.89427114	0.16478352	3026.5276
315.80444	0.89670295	0.1658704	3026.4106
316.70532	0.90134448	0.16697046	3030.082
317.6062	0.90188825	0.16806905	3027.5203
318.50708	0.90495467	0.16915174	3031.7825
319.40796	0.90975887	0.17025414	3034.7024
320.30884	0.91131765	0.17128095	3035.2681
321.20972	0.91300839	0.172291	3034.8711
322.1106	0.91687506	0.1733072	3037.2424
323.01147	0.92062598	0.17422855	3043.5686
323.91235	0.92220181	0.17517672	3036.4656
324.81323	0.92350399	0.17630768	3042.5723
325.71411	0.92807096	0.1774698	3045.5767
326.61499	0.92786241	0.17855917	3043.7156
327.51587	0.93406439	0.17994618	3052.9524
328.41675	0.93672669	0.18102692	3048.8604
329.31763	0.937383	0.18235788	3049.9902
330.21851	0.94086647	0.18342838	3052.6724
331.11938	0.94562382	0.18435912	3049.2556
332.02026	0.94436723	0.18520465	3050.4373
332.92114	0.94907027	0.18618298	3057.1265
333.82202	0.95165348	0.18711331	3052.5403
334.7229	0.95488602	0.1881582	3054.3259
335.62378	0.95784402	0.18949336	3071.2437
336.52466	0.96315265	0.19076967	3065.2866
337.42554	0.96086919	0.19191633	3065.3438
338.32642	0.96322411	0.19304991	3057.8711
339.22729	0.96675044	0.19412842	3061.0691
340.12817	0.97092634	0.19522125	3070.6738
341.02905	0.97252184	0.19628432	3064.4744
341.92993	0.97811753	0.19723755	3069.4631
342.83081	0.98005694	0.1984915	3069.759
343.73169	0.97849143	0.19933599	3068.229
344.63257	0.98391014	0.20034428	3068.2822
345.53345	0.98821568	0.20157237	3080.0635
346.43433	0.99129677	0.20275006	3079.061
347.33521	0.99247754	0.20385642	3080.2314
348.23608	0.99402523	0.20515376	3078.8638
349.13696	0.99573135	0.20612894	3073.5103
350.03784	0.99943209	0.20714936	3071.9487
350.93872	1.0026585	0.20809659	3081.3396
351.8396	1.008124	0.20909561	3075.8962
352.74048	1.0114324	0.21022251	3090.7271
353.64136	1.0111114	0.2112754	3080.793
354.54224	1.0115359	0.21253809	3089.3757
355.44312	1.0166595	0.21368231	3081.0701
356.34399	1.0221118	0.21471234	3084.0762
357.24487	1.0219079	0.21569917	3090.1375
358.14575	1.0268942	0.21675882	3088.7166
359.04663	1.0239866	0.21765144	3085.1526
359.94751	1.0289297	0.2187248	3096.7051
360.84839	1.030702	0.21987903	3093.9751
361.74927	1.0353097	0.22092853	3093.7366
362.65015	1.0391569	0.22209805	3096.9792
363.55103	1.0409564	0.22294171	3098.6458
364.4519	1.0411205	0.2238732	3094.4172
365.35278	1.0419993	0.22502984	3098.8008
366.25366	1.0478468	0.22624971	3102.9585
367.15454	1.0503342	0.22742489	3104.9241
368.05542	1.0549515	0.22837515	3102.1482
368.9563	1.0555937	0.22933494	3102.5659
369.85718	1.0617909	0.23054832	3109.9634
370.75806	1.0651647	0.23160321	3107.1423
371.65894	1.0653703	0.23265381	3112.741
372.55981	1.0672162	0.23366012	3113.5571
373.46069	1.0719286	0.23486143	3113.7339
374.36157	1.070857	0.2357198	3106.9402
375.26245	1.0758475	0.23704281	3122.6208
376.16333	1.0796409	0.23820457	3121.6914
377.06421	1.0840191	0.23924123	3118.7139
377.96509	1.0819215	0.24025789	3114.3169
378.86597	1.0877142	0.24128862	3123.5081
379.76685	1.0891093	0.24245295	3118.0935
380.66772	1.09473	0.24372248	3127.7109
381.5686	1.0955609	0.24483408	3117.9519
382.46948	1.0987885	0.24585868	3120.5874
383.37036	1.1005788	0.24687198	3125.9731
384.27124	1.1053624	0.24800076	3129.5754
385.17212	1.1055726	0.24893709	3130.2463
386.073	1.1085602	0.24992566	3131.4734
386.97388	1.1118208	0.25093687	3130.5574
387.87476	1.1126044	0.25211126	3130.5437
388.77563	1.1182282	0.25310367	3129.9568
389.67651	1.1191636	0.25412107	3131.5986
390.57739	1.1248308	0.25533906	3138.2234
391.47827	1.1237712	0.25646821	3135.2952
392.37915	1.1295189	0.25742388	3139.8567
393.28003	1.1313409	0.25863114	3141.6741
394.18091	1.133841	0.25971234	3138.449
395.08179	1.1367142	0.26085398	3145.3987
395.98267	1.1385295	0.26203674	3138.3928
396.88354	1.1440651	0.26294544	3137.5564
397.78442	1.142987	0.26418832	3142.2388
398.6853	1.1469499	0.26509136	3144.9792
399.58618	1.1492376	0.26628616	3151.0061
400.48706	1.1515359	0.26726183	3150.4023
401.38794	1.1551896	0.26837954	3146.832
402.28882	1.1569906	0.2694636	3151.2593
403.1897	1.1604526	0.27033499	3143.0874
404.09058	1.1614318	0.27125546	3153.885
404.99146	1.1661446	0.27234799	3152.8513
405.89233	1.1657341	0.27348045	3152.7229
406.79321	1.1698875	0.2745198	3148.5884
407.69409	1.1756551	0.27551976	3158.311
408.59497	1.1735276	0.27645478	3156.1741
409.49585	1.1806147	0.27752015	3158.1453
410.39673	1.1782901	0.27848846	3155.1904
411.29761	1.1837335	0.27929416	3154.2959
412.19849	1.1854947	0.28050086	3168.1597
413.09937	1.191584	0.28178075	3165.5195
414.00024	1.1906087	0.28282407	3161.364
414.90112	1.1971387	0.28387606	3168.9009
415.802	1.1977495	0.28508818	3168.8052
416.70288	1.2028707	0.28622714	3167.4583
417.60376	1.2072153	0.28732514	3169.8425
418.50464	1.203728	0.28827778	3165.9834
419.40552	1.2077845	0.28931662	3167.7368
420.3064	1.2110808	0.29032388	3172.5859
421.20728	1.2142798	0.29153523	3174.8342
422.10815	1.2169369	0.29263908	3174.3713
423.00903	1.2201985	0.29381484	3175.6289
423.90991	1.2237283	0.2948744	3179.1135
424.81079	1.2257105	0.29563707	3174.4553
425.71167	1.2247155	0.29667482	3180.1943
426.61255	1.2308439	0.29767236	3178.7693
427.51343	1.2352077	0.29890537	3181.9072
428.41431	1.2358344	0.29994631	3183.6956
429.31519	1.2379982	0.30095914	3180.7141
430.21606	1.2420522	0.30173787	3179.9739
431.11694	1.2429109	0.30278692	3185.3433
432.01782	1.247744	0.30378962	3185.3257
432.9187	1.2497619	0.3046768	3183.6729
433.81958	1.2524159	0.30538282	3182.6396
434.72046	1.2553984	0.30636075	3184.6104
435.62134	1.2602043	0.30703342	3186.77
436.52222	1.2606091	0.30830526	3197.3318
437.4231	1.2649589	0.30945441	3191.9915
438.32397	1.2634143	0.31054002	3186.7134
439.22485	1.2692223	0.31160378	3195.4211
440.12573	1.2729559	0.31274778	3193.7703
441.02661	1.2758787	0.31380883	3198.1655
441.92749	1.279474	0.31481364	3200.0342
442.82837	1.2777983	0.31566674	3198.9797
443.72925	1.2813234	0.31651735	3197.072
444.63013	1.2846895	0.31756431	3199.5696
445.53101	1.2882627	0.31866989	3203.7761
446.43188	1.290724	0.31997851	3204.7517
447.33276	1.2944412	0.3210963	3203.9692
448.23364	1.2954159	0.32209632	3206.6453
449.13452	1.295248	0.32330102	3205.0852
450.0354	1.3028336	0.32449621	3207.2214
450.93628	1.3029946	0.32559437	3207.2371
451.83716	1.3059556	0.32681453	3210.2856
452.73804	1.3100563	0.32773784	3206.3752
453.63892	1.3112978	0.32866624	3212.0317
454.53979	1.3124578	0.32981098	3209.7871
455.44067	1.3157506	0.33071601	3210.0457
456.34155	1.3190417	0.33174226	3214.125
457.24243	1.3236302	0.33296129	3221.364
458.14331	1.3246444	0.33401513	3215.3645
459.04419	1.3298482	0.33508429	3223.0095
459.94507	1.3290913	0.33617955	3221.7122
460.84595	1.3329797	0.33726841	3211.5686
461.74683	1.3371092	0.3386074	3221.3474
462.64771	1.3392023	0.33973387	3225.4331
463.54858	1.3421324	0.34089527	3225.7358
464.44946	1.3415428	0.34197077	3219.6096
465.35034	1.3478571	0.34298182	3219.0774
466.25122	1.3495687	0.34377196	3223.4414
467.1521	1.3533728	0.34478194	3230.2534
468.05298	1.3526832	0.34588513	3223.6887
468.95386	1.3578382	0.34700969	3227.3655
469.85474	1.3606448	0.34809244	3229.0618
470.75562	1.3637291	0.34905547	3228.8157
471.65649	1.3629969	0.35004494	3227.7837
472.55737	1.370997	0.3509239	3230.3486
473.45825	1.369041	0.3520253	3233.1458
474.35913	1.3751909	0.35297057	3231.9512
475.26001	1.3773391	0.35388088	3234.2244
476.16089	1.3786011	0.35475445	3232.4968
477.06177	1.3813442	0.35583618	3238.9827
477.96265	1.3853242	0.35689837	3235.2195
478.86353	1.3866757	0.35801482	3242.2412
479.7644	1.3926021	0.35902721	3240.9851
480.66528	1.3915075	0.35990688	3240.0051
481.56616	1.3925148	0.36105323	3242.3032
482.46704	1.3991331	0.36231866	3250.2131
483.36792	1.400687	0.36345723	3245.4912
484.2688	1.4013584	0.36474147	3247.7034
485.16968	1.4060563	0.36615944	3244.3293
486.07056	1.4123501	0.36727607	3245.8521
486.97144	1.4096752	0.36837187	3244.9287
487.87231	1.4154441	0.3693381	3250.6375
488.77319	1.4170334	0.37048304	3249.2407
489.67407	1.4174962	0.37155738	3248.7651
490.57495	1.4253858	0.37262926	3249.2375
491.47583	1.4265386	0.37358266	3254.3218
492.37671	1.4270953	0.37477347	3252.614
493.27759	1.4346443	0.37604579	3264.5237
494.17847	1.4335859	0.37722608	3254.959
495.07935	1.4346284	0.37813517	3254.5576
495.98022	1.439828	0.37906528	3260.4756
496.8811	1.4426476	0.38006622	3262.3291
497.78198	1.4435595	0.38129723	3262.4475
498.68286	1.4459099	0.38227752	3257.8926
499.58374	1.4499204	0.38316166	3256.4785
500.48462	1.455196	0.38402984	3257.9714
501.3855	1.4556339	0.38505751	3265.1199
502.28638	1.457142	0.38602954	3268.8369
503.18726	1.4601855	0.38712674	3266.3525
504.08813	1.4634222	0.38797078	3261.0354
504.98901	1.4689279	0.38879532	3262.9075
505.88989	1.4665377	0.38980404	3261.5239
506.79077	1.4697204	0.39083806	3267.8782
507.69165	1.4737029	0.39189163	3273.9021
508.59253	1.4769695	0.39309463	3281.7153
509.49341	1.4790214	0.39412314	3272.4312
510.39429	1.4818935	0.39507604	3272.5791
511.29517	1.4848486	0.39602679	3272.3091
512.19604	1.4873469	0.39709005	3274.0361
513.09692	1.4901648	0.39821333	3275.7749
513.9978	1.4922935	0.39913943	3274.7876
514.89868	1.4956689	0.40039858	3279.2327
515.79956	1.4966604	0.40152445	3270.7937
516.70044	1.5005249	0.40261096	3276.1304
517.60132	1.5029702	0.40376821	3277.8086
518.5022	1.5042317	0.40513808	3282.062
519.40308	1.5102725	0.40625116	3283.8413
520.30396	1.5117253	0.40728125	3278.4475
521.20483	1.5154161	0.40839151	3287.939
522.10571	1.5162573	0.40946889	3281.1038
523.00659	1.5183553	0.4105508	3282.2024
523.90747	1.5247482	0.41139552	3284.5649
524.80835	1.5248561	0.41236988	3285.5369
525.70923	1.5281476	0.4133614	3286.5527
526.61011	1.528193	0.41434929	3290.324
527.51099	1.5323538	0.41556117	3290.01
528.41187	1.5384312	0.41629359	3288.9436
529.31274	1.5418292	0.41750634	3301.7852
530.21362	1.5371161	0.41873252	3290.187
531.1145	1.5405005	0.41955858	3287.2122
532.01538	1.5469711	0.42056635	3294.5247
532.91626	1.5504172	0.42148095	3288.7808
533.81714	1.5523746	0.42250255	3297.3794
534.71802	1.5541598	0.42344561	3293.5894
535.6189	1.5575218	0.4243238	3295.3923
536.51978	1.5612884	0.42515299	3299.0266
537.42065	1.5642467	0.42587322	3294.9783
538.32153	1.564441	0.42685741	3292.5122
539.22241	1.5660098	0.42754698	3294.0073
540.12329	1.5689237	0.4285239	3306.8374
541.02417	1.5729604	0.42956665	3297.8201
541.92505	1.5756785	0.43054983	3307.6672
542.82593	1.578205	0.43164477	3310.3899
543.72681	1.5833032	0.43262008	3306.0774
544.62769	1.5822744	0.43344474	3297.4473
545.52856	1.5867959	0.43417516	3300.0649
546.42944	1.5914961	0.43487963	3303.3455
547.33032	1.5919945	0.43584791	3310.6436
548.2312	1.5928967	0.43657184	3304.2976
549.13208	1.6005025	0.43749449	3314.2854
550.03296	1.6003699	0.43842757	3313.8684
550.93384	1.6067586	0.43967855	3322.4097
551.83472	1.6096424	0.44066575	3318.5037
552.7356	1.6090523	0.44149137	3312.4773
553.63647	1.6119236	0.44245523	3310.0645
554.53735	1.6148726	0.44348124	3312.9866
555.43823	1.6167998	0.44457027	3317.4612
556.33911	1.6172388	0.44577205	3320.4309
557.23999	1.6206443	0.44680443	3311.9331
558.14087	1.6259704	0.44766277	3318.7561
559.04175	1.6266484	0.44847271	3311.9561
559.94263	1.6301032	0.44945297	3323.9448
560.84351	1.6347888	0.45056173	3323.3875
561.74438	1.6361827	0.45154268	3324.5554
562.64526	1.6389544	0.45239183	3325.5503
563.54614	1.6416124	0.45339197	3324.2166
564.44702	1.642936	0.4542211	3318.3367
565.3479	1.6445073	0.45491156	3322.3142
566.24878	1.6498071	0.45559716	3324.6001
567.14966	1.6544691	0.45638597	3325.9863
568.05054	1.6579595	0.45730171	3331.9683
568.95142	1.6594287	0.45824772	3328.6138
569.85229	1.6609293	0.45926681	3327.5198
570.75317	1.6646569	0.46035784	3327.1599
571.65405	1.663825	0.46138901	3330.8621
572.55493	1.6660535	0.46219671	3325.394
573.45581	1.6722007	0.46297547	3331.491
574.35669	1.6707611	0.46355698	3325.4524
575.25757	1.6797836	0.46427765	3332.5176
576.15845	1.6818484	0.46488881	3334.2971
577.05933	1.6844506	0.46575192	3336.5605
577.96021	1.6874126	0.46677902	3348.7637
578.86108	1.6869426	0.46788561	3342.4429
579.76196	1.6929561	0.46875751	3338.291
580.66284	1.693782	0.46970007	3337.1106
581.56372	1.6949632	0.47075391	3337.0688
582.4646	1.6986672	0.47152096	3337.4746
583.36548	1.7001696	0.47234914	3334.4067
584.26636	1.7058681	0.47335094	3338.4238
585.16724	1.7066423	0.47418317	3339.8171
586.06812	1.706701	0.47534889	3340.5691
586.96899	1.7145009	0.47616336	3345.8276
587.86987	1.7163472	0.47717533	3339.8877
588.77075	1.7158579	0.4782691	3349.519
589.67163	1.7200272	0.47930241	3349.8416
590.57251	1.7211951	0.4805294	3349.2766
591.47339	1.7248876	0.48167956	3349.9309
592.37427	1.7267904	0.48269442	3340.3953
593.27515	1.7293595	0.48359969	3349.0149
594.17603	1.7344487	0.48466817	3347.7275
595.0769	1.7353144	0.48545632	3356.0452
595.97778	1.7396537	0.48639554	3342.967
596.87866	1.7429227	0.48740572	3342.9097
597.77954	1.7437119	0.48843393	3349.5618
598.68042	1.7492213	0.48960656	3358.8167
599.5813	1.748274	0.49076891	3355.3123
600.48218	1.7498127	0.49189284	3359.856
601.38306	1.7545339	0.49305603	3355.718
602.28394	1.7589035	0.49397823	3355.7915
603.18481	1.7608693	0.49469894	3350.9028
604.08569	1.7633219	0.49580514	3353.05
604.98657	1.7662824	0.49648789	3359.3027
605.88745	1.7683101	0.49780622	3356.8254
606.78833	1.7697691	0.4988302	3355.4226
607.68921	1.7727233	0.50009525	3362.2388
608.59009	1.7757128	0.5010947	3359.2781
609.49097	1.7794197	0.50208801	3358.1348
610.39185	1.7804911	0.50295591	3360.4409
611.29272	1.7847724	0.50415975	3355.4009
612.1936	1.7877785	0.50506216	3361.2661
613.09448	1.7891175	0.50673616	3367.4333
613.99536	1.7932749	0.50791156	3366.3799
614.89624	1.7966201	0.50933927	3369.7512
615.79712	1.7960144	0.51047206	3362.2012
616.698	1.8018535	0.51162779	3365.3511
617.59888	1.8032826	0.51305211	3374.946
618.49976	1.8081062	0.51450759	3368.1755
619.40063	1.8081771	0.51595581	3363.1082
620.30151	1.8096725	0.51724106	3366.979
621.20239	1.8138666	0.51852697	3369.2346
622.10327	1.8195151	0.52001238	3374.4048
623.00415	1.8205435	0.52149975	3376.3228
623.90503	1.8227857	0.5230009	3373.4546
624.80591	1.8252013	0.5248825	3367.4739
625.70679	1.826838	0.52654761	3371.3809
626.60767	1.829489	0.52794385	3368.3237
627.50854	1.8339056	0.52966058	3376.2249
628.40942	1.8348358	0.53147292	3374.3589
629.3103	1.8384271	0.53274274	3372.9607
630.21118	1.8419783	0.53417975	3375.9604
631.11206	1.8439931	0.53562987	3377.5002
632.01294	1.8439316	0.53734082	3378.2627
632.91382	1.852399	0.53881401	3379.6045
633.8147	1.8506351	0.54027086	3372.8701
634.71558	1.8580784	0.54192203	3388.5823
635.61646	1.8588518	0.5437867	3383.3135
636.51733	1.8600683	0.54510182	3383.0901
637.41821	1.8654637	0.54722512	3387.2114
638.31909	1.8628494	0.54868203	3378.3987
639.21997	1.8699981	0.54976833	3386.321
640.12085	1.8707755	0.55126601	3376.8611
641.02173	1.8736641	0.5525744	3390.6086
641.92261	1.8786486	0.55446702	3386.6021
642.82349	1.8795594	0.55572081	3389.5615
643.72437	1.8835256	0.55737251	3388.4629
644.62524	1.8846741	0.55854899	3387.9329
645.52612	1.8875605	0.56014079	3390.2776
646.427	1.8895119	0.56138688	3384.5652
647.32788	1.8942249	0.56296194	3385.6394
648.22876	1.8943286	0.56445503	3392.8984
649.12964	1.8965458	0.56550676	3381.2886
650.03052	1.9007443	0.56699598	3390.4944
650.9314	1.9054357	0.56835794	3386.2363
651.83228	1.9062531	0.56944931	3388.9595
652.73315	1.9101793	0.57120204	3393.9917
653.63403	1.9138836	0.57293844	3394.8486
654.53491	1.9144428	0.57456517	3394.0947
655.43579	1.9170547	0.57664496	3399.6323
656.33667	1.9184788	0.57814276	3391.6162
657.23755	1.9236215	0.57969517	3395.4365
658.13843	1.9240758	0.58127844	3393.6536
659.03931	1.9273204	0.5826596	3396.7241
659.94019	1.9321275	0.58426338	3399.5642
660.84106	1.9324578	0.58564979	3398.2058
661.74194	1.9366373	0.58672673	3398.5586
662.64282	1.939407	0.58807176	3401.3777
663.5437	1.9389288	0.58952653	3396.8269
664.44458	1.9458889	0.59105915	3401.1533
665.34546	1.9471393	0.59274727	3403.4714
666.24634	1.9485333	0.59428668	3397.199
667.14722	1.9519985	0.59547186	3397.1294
668.0481	1.957221	0.59667617	3401.8276
668.94897	1.9591601	0.5977667	3411.0198
669.84985	1.9587684	0.59915543	3403.178
670.75073	1.9630921	0.60038471	3404.1426
671.65161	1.9669313	0.60113782	3397.4561
672.55249	1.968897	0.60246599	3403.614
673.45337	1.9699081	0.6038093	3407.3159
674.35425	1.9737161	0.60495943	3407.2041
675.25513	1.9760206	0.60654432	3407.4839
676.15601	1.978211	0.60774398	3405.5227
677.05688	1.980072	0.60894972	3405.1265
677.95776	1.9833308	0.61028498	3403.4736
678.85864	1.9890552	0.61113173	3405.8594
679.75952	1.9908201	0.61234134	3411.5471
680.6604	1.993843	0.61343044	3409.5745
681.56128	1.9975021	0.61457705	3409.6228
682.46216	1.9971703	0.61582637	3409.7766
683.36304	2.0012903	0.61701906	3415.8333
684.26392	2.0054579	0.61853963	3412.9414
685.16479	2.004827	0.62000334	3410.1226
686.06567	2.0068188	0.62142199	3411.1416
686.96655	2.011179	0.6228261	3413.9309
687.86743	2.0144172	0.62399763	3411.4121
688.76831	2.0180225	0.62546206	3408.949
689.66919	2.0216835	0.62715518	3417.7539
690.57007	2.0220282	0.6288439	3411.2278
691.47095	2.0277469	0.630678	3421.1924
692.37183	2.0275598	0.63244051	3413.0083
693.27271	2.0287418	0.63450193	3416.0317
694.17358	2.0358899	0.63601631	3417.624
695.07446	2.0363708	0.63760227	3416.2866
695.97534	2.0416141	0.63929379	3415.5642
696.87622	2.0418136	0.64073777	3416.677
697.7771	2.0415668	0.64226627	3414.0164
698.67798	2.0444775	0.64388329	3417.1292
699.57886	2.0515714	0.64620626	3423.0896
700.47974	2.0528216	0.64761901	3415.9744
701.38062	2.0546904	0.6493063	3419.4814
702.28149	2.0594068	0.65102589	3420.1096
703.18237	2.0606563	0.65283871	3419.1138
704.08325	2.0646551	0.65446138	3420.3271
704.98413	2.0628433	0.656156	3419.6223
705.88501	2.069479	0.65767318	3420.8765
706.78589	2.0698972	0.65937084	3420.731
707.68677	2.0738683	0.66131622	3428.1001
708.58765	2.0760028	0.66346967	3429.6489
709.48853	2.0781937	0.66553724	3428.2788
710.3894	2.083328	0.66727495	3425.3989
711.29028	2.0861034	0.66878313	3426.5798
712.19116	2.0860882	0.66996396	3414.4531
713.09204	2.0913513	0.67145175	3425.1726
713.99292	2.0916104	0.6730094	3426.2224
714.8938	2.0996368	0.67465115	3430.8889
715.79468	2.098094	0.67622983	3425.5483
716.69556	2.0989916	0.67826849	3423.2346
717.59644	2.1044724	0.67962676	3422.0959
718.49731	2.1054859	0.68104357	3422.4268
719.39819	2.1066546	0.68221521	3421.4236
720.29907	2.1133831	0.68357188	3426.2205
721.19995	2.1146991	0.68503422	3428.9973
722.10083	2.1164348	0.68669838	3432.0291
723.00171	2.1205904	0.68854719	3432.9834
723.90259	2.1254821	0.69035536	3438.1963
724.80347	2.1256618	0.69273388	3433.6797
725.70435	2.1268439	0.69461793	3433.5518
726.60522	2.1300588	0.6960876	3424.3215
727.5061	2.1343582	0.69738203	3435.2405
728.40698	2.1362586	0.69902086	3434.8867
729.30786	2.1371257	0.7007829	3429.3906
730.20874	2.1402838	0.70212084	3434.3706
731.10962	2.1421916	0.70346349	3430.8198
732.0105	2.1462753	0.70468819	3435.5081
732.91138	2.1475132	0.70619756	3440.5488
733.81226	2.1485424	0.7074874	3427.7119
734.71313	2.156878	0.70869428	3439.5327
735.61401	2.1568508	0.70984775	3441.321
736.51489	2.1619587	0.71129024	3434.9712
737.41577	2.1645331	0.71228456	3439.4656
738.31665	2.1694007	0.71363175	3441.771
739.21753	2.1696925	0.71478701	3441.9839
740.11841	2.1700263	0.71607977	3436.2065
741.01929	2.1711652	0.71738553	3437.6228
741.92017	2.1773734	0.71859479	3443.4194
742.82104	2.1760862	0.72022563	3439.7112
743.72192	2.181896	0.72147137	3438.2861
744.6228	2.185971	0.72300905	3442.5537
745.52368	2.186218	0.72444612	3438.6267
746.42456	2.1916904	0.72580791	3442.9585
747.32544	2.1941352	0.72721809	3440.8989
748.22632	2.1961958	0.72859609	3439.4409
749.1272	2.1985488	0.72982252	3441.2158
750.02808	2.200192	0.73143315	3443.7283
750.92896	2.204061	0.73277372	3440.9089
751.82983	2.2055371	0.73386085	3439.8699
752.73071	2.2077353	0.73561084	3439.7275
753.63159	2.2123122	0.73678297	3441.3748
754.53247	2.2160635	0.73805416	3444.7908
755.43335	2.2174938	0.73934001	3439.897
756.33423	2.2207739	0.74057233	3447.5156
757.23511	2.2229936	0.74209857	3447.5107
758.13599	2.2262137	0.74339187	3441.1853
759.03687	2.2271395	0.74517417	3446.1021
759.93774	2.2313612	0.74670947	3444.687
760.83862	2.2337086	0.74827248	3448.74
761.7395	2.2370558	0.7497732	3450.0083
762.64038	2.2354081	0.75158405	3442.9629
763.54126	2.2411268	0.75303626	3447.7869
764.44214	2.2458861	0.75492042	3453.408
765.34302	2.2487357	0.756688	3448.166
766.2439	2.249455	0.75866574	3448.7668
767.14478	2.2533751	0.76039034	3446.7249
768.04565	2.2535229	0.76158524	3442.6082
768.94653	2.2566054	0.76287562	3443.8191
769.84741	2.261899	0.7644906	3455.7346
770.74829	2.2644334	0.76658773	3456.5173
771.64917	2.2653933	0.76854479	3452.0251
772.55005	2.2677603	0.77058142	3453.4375
773.45093	2.2699587	0.7723012	3446.4446
774.35181	2.2725852	0.77431417	3448.7764
775.25269	2.2751882	0.77568555	3443.2214
776.15356	2.2805912	0.77780181	3456.4133
777.05444	2.2801838	0.77994877	3449.8567
777.95532	2.2832139	0.78179634	3453.9717
778.8562	2.2858894	0.78345203	3447.0112
779.75708	2.2907355	0.78541428	3447.9458
780.65796	2.2910011	0.78734332	3448.6553
781.55884	2.297354	0.78936571	3453.2917
782.45972	2.2985666	0.79141164	3451.1758
783.3606	2.3023312	0.79330099	3442.9995
784.26147	2.3043065	0.79516685	3450.3809
785.16235	2.3068378	0.7967819	3456.7449
786.06323	2.3086205	0.79859495	3455.9661
786.96411	2.3145828	0.80008543	3453.9019
787.86499	2.3153822	0.80128551	3446.0964
788.76587	2.3178418	0.80224818	3449.3643
789.66675	2.3231044	0.80303705	3450.3188
790.56763	2.3206577	0.80440849	3453.1604
791.46851	2.3247185	0.80560511	3459.343
792.36938	2.3278623	0.80724514	3460.8384
793.27026	2.3295083	0.80870628	3454.3318
794.17114	2.3338265	0.81029189	3457.8667
795.07202	2.3356838	0.81165045	3457.8396
795.9729	2.3403049	0.8133775	3457.967
796.87378	2.3425033	0.81494176	3456.8352
797.77466	2.3450818	0.81648117	3459.6094
798.67554	2.3467436	0.81778872	3456.1563
799.57642	2.347599	0.81979942	3458.228
800.47729	2.3502712	0.82182443	3460.8792
801.37817	2.3549845	0.82428485	3458.8257
802.27905	2.3597362	0.82589597	3455.1267
803.17993	2.3594038	0.82745337	3454.2544
804.08081	2.3621366	0.82962078	3451.6855
804.98169	2.3651316	0.83147711	3458.8359
805.88257	2.3672585	0.83361512	3460.8413
806.78345	2.3709769	0.83609813	3460.7085
807.68433	2.37661	0.83783007	3462.9268
808.58521	2.3787243	0.84013915	3456.0562
809.48608	2.3777571	0.84214157	3453.9456
810.38696	2.3795307	0.8441928	3457.8601
811.28784	2.3848994	0.8458271	3458.6956
812.18872	2.3860695	0.84796149	3465.7678
813.0896	2.3900955	0.8504144	3466.7483
813.99048	2.3959086	0.85255951	3461.5596
814.89136	2.3976567	0.8548699	3465.3455
815.79224	2.3978353	0.85638559	3461.8828
816.69312	2.4007568	0.85843796	3456.6077
817.59399	2.4044452	0.86006474	3460.2412
818.49487	2.4057283	0.86174345	3458.9414
819.39575	2.4072895	0.86365265	3462.1938
820.29663	2.4123991	0.86556512	3462.8887
821.19751	2.4139183	0.86733645	3457.7998
822.09839	2.4166861	0.86920774	3462.2092
822.99927	2.4186201	0.87092727	3453.8525
823.90015	2.4225035	0.87306666	3459.3328
824.80103	2.4271557	0.87476301	3458.6255
825.7019	2.4290082	0.8768248	3464.6902
826.60278	2.4302509	0.8791787	3459.2415
827.50366	2.4334254	0.8817091	3464.6138
828.40454	2.4343758	0.88405854	3456.7383
829.30542	2.4391258	0.88625669	3459.3823
830.2063	2.4436677	0.88833517	3471.0613
831.10718	2.4440646	0.89062911	3461.8379
832.00806	2.4446378	0.89265841	3462.4019
832.90894	2.4460475	0.89473408	3459.5444
833.80981	2.4542084	0.89661944	3466.4521
834.71069	2.4535351	0.89888966	3460.9343
835.61157	2.4585824	0.90070552	3468.262
836.51245	2.4635928	0.90309411	3465.2878
837.41333	2.4599135	0.90532863	3459.0383
838.31421	2.4649026	0.90755689	3469.3433
839.21509	2.4670978	0.90923691	3461.5115
840.11597	2.4719067	0.91133088	3464.2224
841.01685	2.4758012	0.91326237	3461.5273
841.91772	2.4784589	0.91546011	3462.5991
842.8186	2.4783635	0.91789275	3463.8848
843.71948	2.4804096	0.92001277	3462.1606
844.62036	2.484417	0.92231548	3462.9807
845.52124	2.4872148	0.92448854	3467.9312
846.42212	2.4903529	0.92632711	3462.418
847.323	2.4927764	0.92869264	3463.4099
848.22388	2.4929247	0.93120342	3460.8921
849.12476	2.4985788	0.93328696	3463.374
850.02563	2.5020096	0.9351449	3464.9482
850.92651	2.503125	0.93712312	3470.7678
851.82739	2.5038855	0.93985999	3467.8687
852.72827	2.5112662	0.94241816	3466.9248
853.62915	2.514396	0.94443333	3460.9177
854.53003	2.5144155	0.94671756	3463.085
855.43091	2.5189197	0.94864142	3463.1262
856.33179	2.5210116	0.95027155	3454.9316
857.23267	2.5218239	0.95212919	3461.6843
858.13354	2.5240448	0.95381969	3460.2251
859.03442	2.5302291	0.95574433	3467.689
859.9353	2.5298562	0.95853645	3465.5093
860.83618	2.5348458	0.96028715	3456.3477
861.73706	2.5379508	0.96178293	3458.0371
862.63794	2.5343559	0.96342129	3460.2332
863.53882	2.5385158	0.96582288	3463.8303
864.4397	2.5430083	0.96837664	3461.0378
865.34058	2.5485182	0.97031146	3464.4043
866.24146	2.5480142	0.9727661	3458.6187
867.14233	2.5521417	0.97462445	3467.7097
868.04321	2.556412	0.97649205	3462.2444
868.94409	2.558429	0.97864538	3466.9392
869.84497	2.5614836	0.98078221	3461.7476
870.74585	2.5616441	0.98321182	3463.0325
871.64673	2.5686619	0.98557371	3472.2241
872.54761	2.5700617	0.98785084	3461.6755
873.44849	2.5722055	0.99011171	3462.5999
874.34937	2.5734973	0.99203932	3456.0791
875.25024	2.5772302	0.99388671	3461.3291
876.15112	2.5807657	0.99626863	3466.8105
877.052	2.5805814	0.99867654	3462.9189
877.95288	2.5869465	1.0010519	3467.1001
878.85376	2.5882063	1.0031821	3459.499
879.75464	2.5877118	1.0050837	3450.3777
880.65552	2.5911801	1.0069063	3460.2825
881.5564	2.5949893	1.0087699	3460.646
882.45728	2.5990853	1.011265	3469.2773
883.35815	2.6010451	1.0136104	3462.5767
884.25903	2.6024425	1.0161089	3466.8457
885.15991	2.6064346	1.0186833	3460.5388
886.06079	2.6075146	1.0209833	3456.5388
886.96167	2.6111374	1.0236764	3465.2683
887.86255	2.6156569	1.025836	3461.1636
888.76343	2.6164873	1.0278573	3460.0942
889.66431	2.6170347	1.0299871	3453.6533
890.56519	2.6228817	1.0323859	3461.981
891.46606	2.6266234	1.0344149	3464.3152
892.36694	2.6275368	1.0369135	3461.3042
893.26782	2.6294205	1.0392834	3462.1897
894.1687	2.636441	1.0414784	3460.0779
895.06958	2.6383724	1.0435535	3462.0229
895.97046	2.6399496	1.0456735	3462.5022
896.87134	2.6407566	1.0477321	3454.9302
897.77222	2.6412632	1.0501758	3451.7888
898.6731	2.6448405	1.0522832	3456.9592
899.57397	2.6495271	1.0548484	3455.3311
900.47485	2.6514986	1.0569867	3456.9048
901.37573	2.6564507	1.0590957	3458.1011
902.27661	2.6587865	1.0616663	3457.022
903.17749	2.6580284	1.0644248	3456.5049
904.07837	2.6636775	1.0664725	3454.0303
904.97925	2.6657269	1.0691655	3460.271
905.88013	2.6687682	1.0724109	3455.8367
906.78101	2.66992	1.0748035	3457.7866
907.68188	2.6732659	1.0775478	3458.5415
908.58276	2.6759448	1.0803883	3452.47
909.48364	2.6792071	1.0829628	3458.6626
910.38452	2.6784148	1.0851418	3449.5083
911.2854	2.6842167	1.0869988	3451.9707
912.18628	2.6866491	1.0894984	3459.2197
913.08716	2.6873269	1.0922219	3452.9524
913.98804	2.6918325	1.0949947	3453.156
914.88892	2.6952541	1.0971007	3450.4033
915.78979	2.7014658	1.0996536	3456.2949
916.69067	2.7018194	1.1015695	3448.0879
917.59155	2.7027991	1.1034334	3450.4417
918.49243	2.7067289	1.1056819	3455.3203
919.39331	2.71033	1.1076466	3454.9631
920.29419	2.7104044	1.1106454	3453.4895
921.19507	2.7162948	1.1130207	3454.7117
922.09595	2.716244	1.1152112	3446.7944
922.99683	2.7214425	1.1177899	3452.7258
923.89771	2.7212014	1.1204453	3457.2493
924.79858	2.7249129	1.1227163	3447.4407
925.69946	2.7284904	1.1249017	3448.8552
926.60034	2.7277687	1.1266075	3441.2151
927.50122	2.7327766	1.1280673	3446.7737
928.4021	2.7363434	1.1303169	3454.5134
929.30298	2.7401199	1.1324501	3456.3508
930.20386	2.7421398	1.1348524	3452.6821
931.10474	2.7452939	1.1371996	3448.2051
932.00562	2.7463276	1.1388912	3443.062
932.90649	2.7509475	1.1409643	3452.2109
933.80737	2.7533827	1.1437422	3453.8184
934.70825	2.7573092	1.1462733	3449.7595
935.60913	2.7595527	1.1489948	3448.1599
936.51001	2.7592235	1.1517509	3449.9131
937.41089	2.7630405	1.1544185	3445.9763
938.31177	2.7654557	1.1569571	3440.627
939.21265	2.7685421	1.159385	3445.689
940.11353	2.7719731	1.1619287	3446.1028
941.0144	2.7705991	1.164896	3444.356
941.91528	2.7751658	1.1674337	3438.2397
942.81616	2.7801933	1.1697328	3440.3262
943.71704	2.7829888	1.1716787	3437.9148
944.61792	2.7866488	1.1742613	3443.854
945.5188	2.7900491	1.1768734	3439.5305
946.41968	2.7911699	1.1797134	3444.834
947.32056	2.7916636	1.18214	3435.1843
948.22144	2.7946212	1.1846579	3438.7305
949.12231	2.799793	1.1875094	3440.8459
950.02319	2.8012776	1.1912374	3445.0505
950.92407	2.8064361	1.1947967	3436.7373
951.82495	2.8080025	1.1973931	3436.0703
952.72583	2.8093505	1.2007692	3438.9075
953.62671	2.8129935	1.2037559	3435.0769
954.52759	2.815037	1.2070028	3436.9041
955.42847	2.8211493	1.2097673	3434.8315
956.32935	2.8203144	1.2122412	3428.4465
957.23022	2.8229866	1.214614	3428.9148
958.1311	2.8250525	1.2168641	3427.6125
959.03198	2.8283229	1.2192446	3435.1714
959.93286	2.8308201	1.2221558	3432.8208
960.83374	2.83284	1.2246825	3427.6067
961.73462	2.8367443	1.2269553	3428.041
962.6355	2.8365414	1.2289482	3422.0593
963.53638	2.8418088	1.2309327	3424.2742
964.43726	2.8417604	1.2339377	3430.9558
965.33813	2.8473401	1.2364243	3424.9631
966.23901	2.8469436	1.2387068	3422.0769
967.13989	2.8535395	1.2408215	3419.6821
968.04077	2.8560419	1.2427456	3419.7444
968.94165	2.8554022	1.2451272	3417.1492
969.84253	2.8573821	1.2472292	3417.3535
970.74341	2.8633828	1.2493454	3419.5837
971.64429	2.8663418	1.2519851	3418.665
972.54517	2.868129	1.2541513	3413.9851
973.44604	2.872649	1.256403	3421.9946
974.34692	2.8725533	1.2593122	3420.7632
975.2478	2.8763988	1.2622795	3416.2898
976.14868	2.8811643	1.2657087	3419.1323
977.04956	2.8808393	1.2689446	3409.0908
977.95044	2.8850844	1.2717687	3414.2004
978.85132	2.8882172	1.2745947	3411.9111
979.7522	2.8903193	1.2772005	3411.8672
980.65308	2.8911769	1.280552	3412.2686
981.55396	2.8975778	1.2835958	3404.1858
982.45483	2.8972216	1.2864536	3403.7078
983.35571	2.9047692	1.28985	3411.209
984.25659	2.9033461	1.2925593	3398.0918
985.15747	2.9067154	1.2953976	3408.72
986.05835	2.9102104	1.2981601	3405.7888
986.95923	2.9132478	1.3013316	3406.2395
987.86011	2.9119799	1.3049749	3397.7158
988.76099	2.9170566	1.3082521	3391.6313
989.66187	2.9210994	1.311568	3396.0515
990.56274	2.9226246	1.3140879	3393.4658
991.46362	2.9239802	1.316555	3387.1406
992.3645	2.9280102	1.318983	3392.6387
993.26538	2.9282608	1.3217869	3388.7813
994.16626	2.9333963	1.3247902	3395.031
995.06714	2.93575	1.3279451	3388.8757
995.96802	2.9385655	1.3308423	3386.4561
996.8689	2.9432783	1.3333236	3385.2715
997.76978	2.9432721	1.3359287	3384.5322
998.67065	2.9469385	1.3385459	3376.4492
999.57153	2.9503613	1.3412296	3385.439
1000.4724	2.9518406	1.3439009	3376.8081
1001.3733	2.9546771	1.3465633	3378.5911
1002.2742	2.9555979	1.3491603	3375.5908
1003.175	2.9610379	1.3519168	3374.4011
1004.0759	2.9618247	1.3543868	3372.7327
1004.9768	2.9649992	1.3570317	3372.1235
1005.8777	2.9697692	1.3592317	3364.8142
1006.7786	2.9747775	1.3614744	3375.1416
1007.6794	2.975245	1.3639249	3369.063
1008.5803	2.9752135	1.3663522	3361.019
1009.4812	2.978519	1.3688523	3362.0132
1010.3821	2.9811828	1.3713821	3365.0503
1011.283	2.9840245	1.3739461	3360.7034
1012.1838	2.9873977	1.3763731	3359.9629
1013.0847	2.989912	1.37927	3355.3699
1013.9856	2.9949553	1.3818792	3352.0784
1014.8865	2.9935317	1.3839447	3352.2454
1015.7874	2.995821	1.3855028	3348.1257
1016.6882	3.0019326	1.387615	3348.2986
1017.5891	3.0029252	1.3896858	3348.8032
1018.49	3.0063763	1.3922654	3346.8105
1019.3909	3.0110714	1.3948489	3347.907
1020.2917	3.0136917	1.397472	3347.8799
1021.1926	3.0185204	1.4002687	3344.0198
1022.0935	3.016252	1.4031798	3343.1472
1022.9944	3.0196335	1.4064341	3343.4536
1023.8953	3.0224724	1.4095318	3340.2183
1024.7961	3.0261769	1.411701	3330.4805
1025.697	3.0263126	1.4141357	3337.9988
1026.5979	3.0287566	1.4171374	3330.6377
1027.4988	3.0328376	1.4196309	3329.6536
1028.3997	3.0353374	1.4224961	3328.4216
1029.3005	3.0376408	1.4251468	3325.2808
1030.2014	3.0400734	1.4282842	3323.3115
1031.1023	3.0424089	1.4311014	3320.7566
1032.0032	3.0464559	1.4335067	3317.0156
1032.9041	3.0485818	1.4361241	3322.1416
1033.8049	3.0513425	1.4390712	3316.3235
1034.7058	3.0554817	1.4418004	3311.7551
1035.6067	3.0560665	1.4445384	3311.2126
1036.5076	3.0598679	1.4470941	3308.2815
1037.4084	3.0621526	1.4497079	3310.9888
1038.3093	3.0649912	1.4524379	3300.4851
1039.2102	3.0691361	1.4553648	3296.3176
1040.1111	3.0715499	1.4578763	3302.3855
1041.012	3.0757053	1.4606045	3301.5061
1041.9128	3.0750229	1.4633626	3297.2747
1042.8137	3.0788999	1.4663589	3293.9812
1043.7146	3.0807486	1.4692816	3291.9529
1044.6155	3.0838954	1.4718077	3280.4207
1045.5164	3.0869508	1.474486	3295.2942
1046.4172	3.0914888	1.4775488	3282.2493
1047.3181	3.0948091	1.4799685	3280.0933
1048.219	3.0949233	1.4832088	3278.2649
1049.1199	3.0998712	1.4861783	3283.9507
1050.0208	3.1026709	1.4901413	3273.9021
1050.9216	3.1071229	1.492999	3274.0012
1051.8225	3.1070759	1.4954542	3265.6934
1052.7234	3.108186	1.498086	3264.6372
1053.6243	3.1119256	1.5009208	3257.9685
1054.5251	3.1144891	1.50375	3266.6294
1055.426	3.1192365	1.5069872	3258.6851
1056.3269	3.1206617	1.5094851	3256.5137
1057.2278	3.1239564	1.512686	3253.7495
1058.1287	3.1252162	1.5159873	3250.3167
1059.0295	3.1263404	1.5189521	3244.9946
1059.9304	3.1305156	1.5219359	3240.6707
1060.8313	3.1350701	1.5248702	3236.4177
1061.7322	3.1394665	1.5275867	3242.8708
1062.6331	3.1375647	1.5307134	3232.7368
1063.5339	3.1423326	1.5337249	3240.4414
1064.4348	3.1447916	1.5371335	3228.6343
1065.3357	3.1488569	1.5405829	3224.2825
1066.2366	3.1519735	1.543223	3218.887
1067.1375	3.1534183	1.5462667	3218.7473
1068.0383	3.1541307	1.5493979	3214.3901
1068.9392	3.1562719	1.5526152	3205.4812
1069.8401	3.1610916	1.5556858	3202.2776
1070.741	3.161921	1.5582669	3201.0305
1071.6418	3.1691706	1.5605888	3199.4412
1072.5427	3.1702785	1.5632697	3198.374
1073.4436	3.1708782	1.5661294	3190.0195
1074.3445	3.1748986	1.5686589	3184.3132
1075.2454	3.177592	1.571564	3184.502
1076.1462	3.1794171	1.5745611	3176.8193
1077.0471	3.1813247	1.5771233	3177.012
1077.948	3.1829166	1.5806614	3165.063
1078.8489	3.190062	1.5833819	3170.5698
1079.7498	3.1910346	1.5860368	3159.5356
1080.6506	3.1951036	1.5888038	3157.4414
1081.5515	3.1962852	1.5918872	3154.9446
1082.4524	3.1986222	1.5956261	3149.3584
1083.3533	3.2041874	1.5992764	3152.5181
1084.2542	3.2061207	1.6032819	3147.1099
1085.155	3.2041383	1.6070018	3125.6797
1086.0559	3.2077687	1.610525	3128.1213
1086.9568	3.2128263	1.6139547	3113.3562
1087.8577	3.2138419	1.6165284	3105.7563
1088.7585	3.2172949	1.6197606	3107.2607
1089.6594	3.2204499	1.6233065	3095.3979
1090.5603	3.2241263	1.6263899	3099.0332
1091.4612	3.2253277	1.6309565	3079.5227
1092.3621	3.2302766	1.634335	3072.1628
1093.2629	3.2319226	1.6394026	3048.8667
1094.1638	3.2352598	1.6457433	3014.2156
1095.0647	3.2385714	1.6504569	2987.563
1095.9656	3.2391732	1.6595548	2925.7715
1096.4661	3.2459645	1.6671035	2866.6995