File: datasets/am_bench_2022/raw_data/TH2-C/specimen.dat
MTS793|MPT|ENU|1|2|.|/|:|1|0|0|A

Operator Information						Time:	10.197998	Sec	11/3/2021 12:00:14 PM
Operator	Nick Derimow
Project	AM Bench 2022 mini-tensile challenge
Specimen ID	TH2-C
Material	PBF-L Inconel 625
Specimen Width	2.56	mm
Specimen Thickness	1.52	mm
Notes
Operator Information End

Data Acquisition						Time:	1011.1924	Sec	11/3/2021 12:16:55 PM
Time	Axial Displacement	Axial Extensometer	Axial Force
Sec	mm	mm	N
10.312256	0.0033984582	-5.7906422e-05	13.873678
11.213135	0.0073630987	8.7428889e-05	25.397896
12.114014	0.0079384325	0.00016169265	33.580879
13.014893	0.0083465753	0.00023249477	46.243134
13.915771	0.012387179	0.00031499105	58.030346
14.81665	0.015161761	0.00034917402	68.175789
15.717529	0.017424731	0.00042213878	75.895195
16.618408	0.020460395	0.00056602858	87.125061
17.519287	0.023105538	0.00053007121	95.874298
18.420166	0.024696054	0.00068379374	106.99674
19.321045	0.02718297	0.00074045837	120.31771
20.221924	0.029585522	0.00075487862	129.53461
21.122803	0.033208761	0.00089634152	142.28891
22.023682	0.037384797	0.00094464555	148.6806
22.924561	0.03903171	0.0010634577	161.0108
23.825439	0.042432237	0.0011395368	175.66833
24.726318	0.042055238	0.0012718001	191.17645
25.627197	0.049372047	0.0013449042	206.20081
26.528076	0.049566694	0.001376736	218.66241
27.428955	0.049574684	0.0016468776	237.61809
28.329834	0.056629181	0.0016883793	257.31314
29.230713	0.057899661	0.001851828	276.25659
30.131592	0.060986344	0.0018854905	294.78671
31.032471	0.063473925	0.0020538268	310.62842
31.93335	0.06485381	0.0022048347	333.58563
32.834229	0.067717113	0.0022963451	351.49292
33.735107	0.067948028	0.0023454288	363.58325
34.635986	0.076282732	0.0025694617	390.11133
35.536865	0.074204728	0.002802015	407.28427
36.437744	0.078155182	0.0028438403	426.27704
37.338623	0.083267979	0.0030670876	448.97678
38.239502	0.084588863	0.0031378928	470.37729
39.140381	0.084703803	0.0033537268	485.23734
40.04126	0.086492911	0.0033868158	509.0524
40.942139	0.091129541	0.0036880311	530.15125
41.843018	0.092604965	0.0036767868	552.20795
42.743896	0.097072765	0.0039699418	572.28882
43.644775	0.098303288	0.0040326742	592.29541
44.545654	0.10127482	0.0041905367	621.71002
45.446533	0.10462228	0.0043535181	645.42517
46.347412	0.10717563	0.0045910696	671.10834
47.248291	0.10916732	0.0046264664	682.72723
48.14917	0.11347285	0.004827946	710.55658
49.050049	0.11886369	0.004981386	736.35986
49.950928	0.11709778	0.005024327	751.85144
50.851807	0.12166695	0.0053071184	777.88599
51.752686	0.1239982	0.0054427092	799.67877
52.653564	0.12767164	0.0055964296	826.0061
53.554443	0.1292405	0.0057661021	854.16187
54.455322	0.13061367	0.005930746	882.01605
55.356201	0.13566925	0.0061595296	906.41443
56.25708	0.13669616	0.0062963497	933.84698
57.157959	0.13836332	0.0065264101	965.81677
58.058838	0.14580654	0.006598318	987.96588
58.959717	0.14424737	0.0068255644	1002.3576
59.860596	0.14897595	0.0069538006	1030.4014
60.761475	0.14982685	0.0072236964	1062.1763
61.662354	0.15400106	0.0072853263	1070.1704
62.563232	0.15456164	0.0074370462	1100.5605
63.464111	0.15718178	0.0075791082	1126.1876
64.36499	0.16146657	0.0078650005	1147.5708
65.265869	0.16644536	0.0079415962	1178.7738
66.166748	0.16435553	0.0081269136	1194.7882
67.067627	0.16931629	0.0083368719	1229.7391
67.968506	0.17263363	0.0084981071	1250.1744
68.869385	0.17253283	0.00860871	1275.1108
69.770264	0.17661789	0.0087575158	1299.1843
70.671143	0.17895953	0.0089511322	1321.364
71.572021	0.17977071	0.0090635093	1343.6497
72.4729	0.18382591	0.0093957288	1375.3429
73.373779	0.1887522	0.0094397506	1398.8553
74.274658	0.19080807	0.009712413	1425.0853
75.175537	0.19442415	0.0098534701	1451.4956
76.076416	0.19681932	0.0099803451	1472.3483
76.977295	0.19690312	0.010139151	1499.2634
77.878174	0.19947958	0.010448402	1521.4585
78.779053	0.20525534	0.010593548	1544.5126
79.679932	0.2066146	0.010680867	1560.1733
80.580811	0.21258056	0.010883944	1593.3719
81.481689	0.21352573	0.011030174	1622.6272
82.382568	0.21474278	0.011229744	1646.2599
83.283447	0.2180054	0.011345428	1670.4147
84.184326	0.21865956	0.011585012	1691.3462
85.085205	0.22251931	0.011677749	1716.7476
85.986084	0.22802447	0.011836378	1736.689
86.886963	0.22687586	0.012002748	1763.7507
87.787842	0.2322228	0.01221947	1790.262
88.688721	0.23403361	0.012340995	1808.7717
89.5896	0.23956275	0.012526184	1834.5587
90.490479	0.23967381	0.012690148	1854.9855
91.391357	0.24353246	0.01281697	1879.8235
92.292236	0.24375457	0.013089214	1907.5981
93.193115	0.25002193	0.013072651	1919.0221
94.093994	0.24977769	0.013274692	1940.828
94.994873	0.25083515	0.013367847	1964.6742
95.895752	0.25639924	0.013533696	1988.062
96.796631	0.25564343	0.013691068	2004.6404
97.69751	0.26058593	0.013803231	2017.3109
98.598389	0.26273197	0.013981902	2043.6132
99.499268	0.26757494	0.014168363	2059.887
100.40015	0.27002394	0.014189405	2077.4075
101.30103	0.27238443	0.014320767	2101.4031
102.2019	0.27368858	0.014408935	2116.3333
103.10278	0.27849162	0.014634489	2134.5657
104.00366	0.27969652	0.014710018	2155.0981
104.90454	0.28453705	0.014916332	2176.063
105.80542	0.28661889	0.014995593	2192.5278
106.7063	0.2900047	0.01513113	2209.2122
107.60718	0.29041389	0.015242803	2221.4236
108.50806	0.28954616	0.015276655	2238.553
109.40894	0.29811153	0.015533872	2260.9849
110.30981	0.30264571	0.015634386	2274.7493
111.21069	0.30415598	0.01578752	2296.6194
112.11157	0.30489829	0.015945632	2309.2686
113.01245	0.30702868	0.016031329	2321.9961
113.91333	0.3117311	0.016178321	2343.377
114.81421	0.31492364	0.016299643	2348.8757
115.71509	0.31451181	0.016437139	2364.5464
116.61597	0.31901321	0.016493058	2382.2141
117.51685	0.32313395	0.016681965	2398.6506
118.41772	0.32539779	0.016836213	2410.842
119.3186	0.3278144	0.017010823	2424.2954
120.21948	0.32866985	0.017248781	2435.8267
121.12036	0.3329387	0.017305171	2443.3481
122.02124	0.33620542	0.017494475	2453.0417
122.92212	0.33850184	0.017645704	2472.9783
123.823	0.34234616	0.017792024	2483.4319
124.72388	0.34608433	0.017990462	2486.7488
125.62476	0.34630767	0.01811092	2495.3152
126.52563	0.34699816	0.018199969	2505.7305
127.42651	0.3495785	0.018428456	2524.8618
128.32739	0.35407969	0.018521862	2529.283
129.22827	0.35659084	0.018708391	2545.7231
130.12915	0.36058247	0.018955175	2554.5586
131.03003	0.36103159	0.019130966	2557.7319
131.93091	0.36651704	0.019236717	2575.6301
132.83179	0.36931503	0.019484403	2580.4353
133.73267	0.37338698	0.019711042	2588.7317
134.63354	0.37324828	0.019815793	2590.5996
135.53442	0.37632465	0.02001849	2597.3958
136.4353	0.38082421	0.020257792	2612.4365
137.33618	0.3798348	0.020426387	2616.7935
138.23706	0.38443029	0.020770665	2629.7393
139.13794	0.3865777	0.021023091	2638.6833
140.03882	0.39088979	0.021248182	2647.7141
140.9397	0.39404917	0.021468544	2656.5378
141.84058	0.39524797	0.021881526	2665.542
142.74146	0.39666253	0.022001386	2668.4653
143.64233	0.40204722	0.022328069	2680.1284
144.54321	0.40472901	0.02261702	2689.1816
145.44409	0.40700999	0.022924654	2703.2385
146.34497	0.41095456	0.02342229	2706.8606
147.24585	0.4102813	0.02360948	2707.4973
148.14673	0.41664982	0.024000229	2719.0718
149.04761	0.41479212	0.024296537	2727.4629
149.94849	0.42091292	0.024606241	2727.1545
150.84937	0.42010996	0.024957594	2728.7092
151.75024	0.42274833	0.025336981	2745.1006
152.65112	0.42804819	0.025846753	2760.2017
153.552	0.43318698	0.026413973	2768.054
154.45288	0.43532562	0.026682148	2768.1528
155.35376	0.43653774	0.027265573	2774.1809
156.25464	0.43690205	0.027794654	2783.9949
157.15552	0.44188926	0.028237175	2786.2715
158.0564	0.44278359	0.028629454	2792.5095
158.95728	0.44333062	0.0291229	2792.7742
159.85815	0.45000467	0.029642941	2804.4563
160.75903	0.45391598	0.030086501	2805.6409
161.65991	0.45819017	0.030512344	2814.1118
162.56079	0.45865855	0.030983597	2815.0598
163.46167	0.45988253	0.031589378	2822.1221
164.36255	0.46210414	0.032098494	2828.9475
165.26343	0.46445793	0.032677133	2830.3533
166.16431	0.46858358	0.033411026	2846.8416
167.06519	0.47379938	0.034153696	2853.2285
167.96606	0.47295016	0.034778312	2851.6216
168.86694	0.47754991	0.035403546	2856.8931
169.76782	0.47897187	0.036079712	2854.8699
170.6687	0.48245227	0.03672386	2864.1787
171.56958	0.48727348	0.037437577	2875.176
172.47046	0.49139443	0.038117107	2873.5811
173.37134	0.48897469	0.038840301	2878.3013
174.27222	0.49370944	0.039555747	2884.9861
175.1731	0.49738842	0.040256642	2894.3823
176.07397	0.4965978	0.041014537	2891.8633
176.97485	0.49985614	0.041740533	2893.8064
177.87573	0.50490665	0.04253329	2901.6013
178.77661	0.5069766	0.043261901	2908.446
179.67749	0.50779128	0.044200543	2908.4023
180.57837	0.513161	0.044872962	2910.4155
181.47925	0.51532805	0.045528784	2911.3396
182.38013	0.51677519	0.046196971	2916.3879
183.28101	0.52062094	0.046972755	2920.9004
184.18188	0.51980823	0.047646325	2922.4651
185.08276	0.52412558	0.048508722	2930.4392
185.98364	0.52703685	0.049495492	2932.7439
186.88452	0.53358555	0.050557006	2942.4946
187.7854	0.53372139	0.05160496	2942.1887
188.68628	0.53687483	0.052362479	2943.0137
189.58716	0.53943956	0.053359933	2953.4783
190.48804	0.54374677	0.054376841	2954.9307
191.38892	0.5467701	0.055203345	2956.8633
192.28979	0.54902059	0.056171358	2962.3755
193.19067	0.55224532	0.057136141	2966.0242
194.09155	0.55019093	0.058104184	2961.9976
194.99243	0.55444968	0.059036475	2964.6775
195.89331	0.55680883	0.059821237	2970.3647
196.79419	0.5587616	0.060583159	2974.1641
197.69507	0.56107563	0.061816998	2978.9241
198.59595	0.56567287	0.062769279	2978.2188
199.49683	0.56736505	0.063528486	2977.689
200.39771	0.57176572	0.064601779	2995.3384
201.29858	0.57243627	0.065496638	2986.3215
202.19946	0.57657135	0.066355184	2985.916
203.10034	0.58091086	0.067307375	3000.2666
204.00122	0.58189368	0.068264179	2988.2954
204.9021	0.58464313	0.069076814	3000.1394
205.80298	0.58688486	0.069963351	3003.1733
206.70386	0.59055048	0.070764519	3004.2666
207.60474	0.58939737	0.071522363	3003.4944
208.50562	0.59478897	0.072481237	3014.0837
209.40649	0.59681594	0.073468141	3015.7693
210.30737	0.60154355	0.074671991	3019.1147
211.20825	0.60400391	0.075632557	3014.4473
212.10913	0.60601693	0.076537654	3027.0037
213.01001	0.60936171	0.07749068	3022.7832
213.91089	0.61145854	0.078427143	3030.104
214.81177	0.61278111	0.079492554	3028.3621
215.71265	0.61896259	0.080440663	3031.5122
216.61353	0.61825365	0.081228167	3031.4209
217.5144	0.62213689	0.082348421	3041.2861
218.41528	0.62615484	0.08333642	3039.4805
219.31616	0.62720549	0.084376574	3040.7759
220.21704	0.63152903	0.085400403	3049.3918
221.11792	0.63415384	0.08649835	3043.9375
222.0188	0.63646024	0.087536074	3051.2839
222.91968	0.63536227	0.088546239	3046.3447
223.82056	0.64079595	0.08948385	3052.9036
224.72144	0.64557636	0.090650938	3063.5828
225.62231	0.64499468	0.091511227	3054.6108
226.52319	0.64960694	0.092333958	3053.9529
227.42407	0.64950264	0.093372606	3062.2502
228.32495	0.65510225	0.094458073	3066.7627
229.22583	0.6554969	0.095534489	3069.5117
230.12671	0.65890992	0.096387252	3065.6929
231.02759	0.66154516	0.097382419	3067.9529
231.92847	0.66882634	0.098313615	3075.4385
232.82935	0.66904742	0.099398442	3076.7737
233.73022	0.67158127	0.10036401	3077.825
234.6311	0.67687315	0.10128846	3072.9751
235.53198	0.6770016	0.10229589	3087.9319
236.43286	0.6791603	0.10322163	3084.2004
237.33374	0.68338776	0.10424887	3096.6096
238.23462	0.68357873	0.10524363	3083.2747
239.1355	0.68576223	0.1061206	3087.364
240.03638	0.6890769	0.10703139	3084.0842
240.93726	0.69373691	0.10792843	3094.4917
241.83813	0.69413787	0.10891072	3093.1104
242.73901	0.695099	0.1099843	3099.9392
243.63989	0.70360863	0.11119749	3103.0789
244.54077	0.70509613	0.11242512	3110.5862
245.44165	0.7081871	0.1134561	3108.6289
246.34253	0.70937073	0.11456546	3110.104
247.24341	0.7107091	0.11554246	3105.366
248.14429	0.71614122	0.11654842	3109.6045
249.04517	0.719926	0.11755589	3119.3542
249.94604	0.72006756	0.11855727	3118.9431
250.84692	0.72294748	0.11948983	3121.8428
251.7478	0.72434217	0.12068512	3125.2957
252.64868	0.72535408	0.12161019	3121.4705
253.54956	0.72981656	0.12258758	3126.1206
254.45044	0.73496813	0.12367342	3126.5339
255.35132	0.73636907	0.12450714	3123.488
256.2522	0.73755664	0.12557176	3128.2964
257.15308	0.7422666	0.12660018	3127.5962
258.05396	0.74492872	0.12766002	3138.2239
258.95483	0.7476005	0.12875058	3137.6628
259.85571	0.75061524	0.12965922	3132.6421
260.75659	0.75004953	0.13049473	3137.3035
261.65747	0.75329471	0.13174745	3142.2166
262.55835	0.75689483	0.13289946	3150.0808
263.45923	0.75985342	0.13379122	3140.2952
264.36011	0.76147068	0.13485806	3146.8491
265.26099	0.76684034	0.13603973	3154.1172
266.16187	0.76823562	0.13706279	3150.3755
267.06274	0.77382606	0.137988	3157.8894
267.96362	0.77406353	0.13895479	3152.2559
268.8645	0.77904761	0.13998671	3161.8049
269.76538	0.77781296	0.1410699	3155.3704
270.66626	0.78562742	0.14216654	3168.5625
271.56714	0.78463411	0.14306623	3163.3513
272.46802	0.78881139	0.14432326	3164.0964
273.3689	0.79134256	0.14532381	3166.1467
274.26978	0.79296732	0.14639741	3168.5574
275.17065	0.79474884	0.1475732	3170.7976
276.07153	0.80047363	0.14851446	3167.146
276.97241	0.80219722	0.14936426	3165.5342
277.87329	0.80415714	0.1502907	3176.2485
278.77417	0.80639225	0.1512356	3176.7808
279.67505	0.80903554	0.15200064	3170.343
280.57593	0.81023693	0.15296762	3174.6462
281.47681	0.81368732	0.15389086	3179.2332
282.37769	0.81786108	0.1549089	3180.1863
283.27856	0.82047343	0.15602671	3190.2925
284.17944	0.82373071	0.1568516	3184.5938
285.08032	0.8228718	0.15792075	3181.9956
285.9812	0.82970732	0.15874708	3190.5591
286.88208	0.8330636	0.15981434	3192.1274
287.78296	0.83211911	0.160909	3194.4221
288.68384	0.83548766	0.16207643	3202.2524
289.58472	0.83973539	0.16326723	3198.8164
290.4856	0.84286755	0.16432579	3199.3438
291.38647	0.84544444	0.16555755	3199.0156
292.28735	0.84791315	0.16637339	3202.0239
293.18823	0.85353059	0.16731714	3201.5281
294.08911	0.8522045	0.16821402	3203.6646
294.98999	0.8564254	0.1690001	3205.5815
295.89087	0.85495704	0.16977125	3195.9792
296.79175	0.86043632	0.17080458	3213.9238
297.69263	0.86280626	0.17200811	3210.0413
298.59351	0.86586034	0.17297411	3212.3359
299.49438	0.86904639	0.17404769	3216.1875
300.39526	0.8703683	0.17505008	3210.0339
301.29614	0.87439787	0.17597069	3216.3442
302.19702	0.8778615	0.17702642	3219.9338
303.0979	0.88150299	0.17814156	3224.2405
303.99878	0.88271248	0.17898157	3213.7913
304.89966	0.88571346	0.1800878	3220.6494
305.80054	0.88922256	0.18116289	3226.4299
306.70142	0.89173329	0.18234086	3233.6702
307.60229	0.89264625	0.18359137	3231.8191
308.50317	0.89465851	0.18453313	3230.2344
309.40405	0.89917302	0.18562448	3236.2278
310.30493	0.90305746	0.18657874	3226.3618
311.20581	0.90372044	0.18743165	3226.2664
312.10669	0.90593266	0.18822862	3236.637
313.00757	0.90804511	0.1894999	3236.52
313.90845	0.91356415	0.19023713	3236.1294
314.80933	0.91456729	0.19113778	3239.3215
315.71021	0.91653234	0.19205934	3234.5227
316.61108	0.92130506	0.19279599	3238.6965
317.51196	0.92563272	0.19378243	3242.6531
318.41284	0.92540139	0.19473869	3238.4692
319.31372	0.93049389	0.1956007	3247.2793
320.2146	0.93000376	0.196613	3246.8313
321.11548	0.93443435	0.19780013	3256.6628
322.01636	0.93705833	0.19901234	3256.9026
322.91724	0.94142079	0.19979915	3252.5935
323.81812	0.94082642	0.20089082	3251.686
324.71899	0.94377148	0.20175594	3257.303
325.61987	0.9488132	0.20295724	3260.8301
326.52075	0.95039368	0.20389432	3256.9434
327.42163	0.95478219	0.20465162	3254.9111
328.32251	0.9534117	0.20566562	3264.0305
329.22339	0.95751113	0.20671153	3263.0793
330.12427	0.95927662	0.2077615	3265.4573
331.02515	0.96216112	0.20882313	3268.5396
331.92603	0.96698618	0.21001931	3271.8389
332.8269	0.96718371	0.21101014	3269.4758
333.72778	0.97407168	0.21210539	3272.4907
334.62866	0.97464412	0.21303898	3273.2388
335.52954	0.97653222	0.21405095	3270.0862
336.43042	0.98009211	0.21514249	3278.3367
337.3313	0.98186564	0.21620989	3277.199
338.23218	0.98368394	0.21711113	3272.71
339.13306	0.98836225	0.21813802	3274.4954
340.03394	0.99190211	0.2189867	3284.6262
340.93481	0.99217379	0.21995144	3283.0635
341.83569	0.9974283	0.22102141	3282.7888
342.73657	0.99783421	0.22198482	3281.4077
343.63745	1.0022545	0.22293071	3286.4924
344.53833	1.0051926	0.2239563	3289.1331
345.43921	1.0050662	0.22491601	3282.9338
346.34009	1.0121318	0.22595093	3292.5989
347.24097	1.0116402	0.22708456	3301.5872
348.14185	1.0134584	0.22812012	3298.9199
349.04272	1.0204282	0.22920881	3300.8672
349.9436	1.0226977	0.22999911	3299.064
350.84448	1.0216147	0.23105183	3295.6338
351.74536	1.0280377	0.2319221	3297.1436
352.64624	1.0279521	0.23281811	3295.9907
353.54712	1.0281348	0.23377478	3299.7278
354.448	1.0325702	0.23467556	3295.3923
355.34888	1.0375035	0.23559839	3305.3936
356.24976	1.0409819	0.23671542	3304.4658
357.15063	1.043044	0.23771226	3310.8323
358.05151	1.0435183	0.23866311	3303.2031
358.95239	1.0478233	0.23950939	3302.9343
359.85327	1.0503361	0.2404986	3314.373
360.75415	1.0490572	0.24172135	3314.4033
361.65503	1.0553963	0.24260892	3310.2876
362.55591	1.0583749	0.24351436	3313.6643
363.45679	1.0591732	0.24461687	3312.0708
364.35767	1.0625887	0.24560747	3319.4683
365.25854	1.0681792	0.24665014	3321.7175
366.15942	1.0703586	0.24777585	3325.6758
367.0603	1.072075	0.24870989	3319.9814
367.96118	1.0733293	0.24974997	3320.6694
368.86206	1.0758487	0.25084352	3324.4001
369.76294	1.0802244	0.25182775	3327.8147
370.66382	1.0807811	0.25290489	3324.9387
371.5647	1.0866364	0.2537424	3330.522
372.46558	1.0883719	0.25485837	3334.4351
373.36646	1.0906186	0.2559939	3334.387
374.26733	1.0944276	0.25688854	3328.8994
375.16821	1.0966423	0.25764674	3333.5027
376.06909	1.0982581	0.25875264	3333.7468
376.96997	1.1005515	0.25977218	3335.3174
377.87085	1.1045206	0.26057148	3337.968
378.77173	1.1067128	0.26154858	3339.5901
379.67261	1.1094015	0.26242861	3337.1116
380.57349	1.1110899	0.26334155	3340.8269
381.47437	1.1159089	0.26413289	3343.4524
382.37524	1.1161562	0.26505789	3339.2983
383.27612	1.1207246	0.26609191	3343.9636
384.177	1.1223725	0.26715457	3345.8154
385.07788	1.1245911	0.26827511	3350.9629
385.97876	1.1304195	0.26922855	3350.3909
386.87964	1.1333256	0.27018878	3348.0146
387.78052	1.1326989	0.27107	3343.1121
388.6814	1.1388217	0.27193943	3351.853
389.58228	1.1379242	0.27278063	3350.2485
390.48315	1.1412184	0.27381301	3352.9688
391.38403	1.1438568	0.27485007	3356.8271
392.28491	1.1469715	0.27581948	3351.3552
393.18579	1.1539457	0.27688316	3360.9111
394.08667	1.1523674	0.27775094	3357.2607
394.98755	1.1567084	0.27878675	3367.4092
395.88843	1.1598732	0.27970022	3359.0374
396.78931	1.1641942	0.28064534	3365.7712
397.69019	1.1651964	0.28161442	3365.8955
398.59106	1.1634955	0.28264171	3370.5923
399.49194	1.1679746	0.2836096	3366.7378
400.39282	1.1719289	0.28458193	3364.4133
401.2937	1.1745788	0.28544778	3367.5183
402.19458	1.1766438	0.28650516	3370.6084
403.09546	1.1812865	0.28760934	3378.4258
403.99634	1.1829169	0.28891933	3378.5327
404.89722	1.1863563	0.28997555	3373.5442
405.7981	1.1859822	0.29075962	3369.0342
406.69897	1.1927228	0.29164171	3373.5146
407.59985	1.1888216	0.29245985	3370.3887
408.50073	1.195779	0.29340446	3376.9456
409.40161	1.1961972	0.29455441	3380.9087
410.30249	1.201672	0.29555011	3383.4727
411.20337	1.2045485	0.29664886	3388.2971
412.10425	1.2045006	0.29759386	3380.8396
413.00513	1.2068801	0.29847941	3377.7109
413.90601	1.2127817	0.29946488	3389.5938
414.80688	1.2158521	0.30048373	3390.4407
415.70776	1.2174349	0.30151737	3390.2688
416.60864	1.2208444	0.30258101	3392.1812
417.50952	1.2209764	0.30324537	3377.2678
418.4104	1.2262353	0.30413204	3385.2275
419.31128	1.2279153	0.30497825	3389.0659
420.21216	1.2310512	0.3059423	3394.9128
421.11304	1.2328755	0.30687755	3394.0891
422.01392	1.2376668	0.3076643	3392.1787
422.91479	1.2403541	0.3084549	3390.5991
423.81567	1.2427546	0.30931473	3397.4321
424.71655	1.245715	0.31015846	3397.4026
425.61743	1.2502369	0.31125587	3406.4568
426.51831	1.2494602	0.31238857	3407.4822
427.41919	1.2513534	0.31338242	3401.7539
428.32007	1.2544185	0.31434095	3401.6445
429.22095	1.2566146	0.31534851	3402.0435
430.12183	1.2608348	0.31629449	3402.8865
431.02271	1.2623791	0.31727907	3406.2537
431.92358	1.2686728	0.31837732	3412.1067
432.82446	1.2684661	0.31937146	3409.188
433.72534	1.2738055	0.32029611	3414.0588
434.62622	1.2735187	0.3213065	3409.7659
435.5271	1.2782158	0.32232323	3411.4683
436.42798	1.2789236	0.32329094	3407.8369
437.32886	1.2832456	0.32436877	3417.2871
438.22974	1.2842875	0.32531464	3418.6379
439.13062	1.2899548	0.32627678	3420.4084
440.03149	1.2934717	0.32731792	3420.0291
440.93237	1.2922413	0.32836273	3418.4612
441.83325	1.2963619	0.3295922	3422.2629
442.73413	1.2985904	0.33043668	3419.4604
443.63501	1.2997942	0.33146983	3421.8159
444.53589	1.3045683	0.33236688	3426.4851
445.43677	1.3066587	0.3334215	3424.2939
446.33765	1.3103408	0.33454612	3425.4451
447.23853	1.3122264	0.33549008	3430.2107
448.1394	1.3138	0.33653876	3431.0859
449.04028	1.3175029	0.33760142	3426.187
449.94116	1.3185552	0.33851826	3425.2822
450.84204	1.321528	0.33946609	3431.3621
451.74292	1.3257093	0.34055525	3437.9646
452.6438	1.328302	0.34161258	3433.0464
453.54468	1.3330731	0.34266952	3438.7292
454.44556	1.3356333	0.34357387	3435.0918
455.34644	1.3368583	0.34450349	3431.7842
456.24731	1.339726	0.3454785	3439.1709
457.14819	1.3421539	0.34635055	3437.1052
458.04907	1.3449904	0.34726965	3439.5537
458.94995	1.3477123	0.34822825	3441.8906
459.85083	1.3515888	0.3491886	3445.3411
460.75171	1.3551834	0.35014251	3443.2478
461.65259	1.3561147	0.35089132	3443.6431
462.55347	1.357332	0.35184002	3443.218
463.45435	1.359134	0.35289317	3443.386
464.35522	1.363695	0.35382822	3445.3591
465.2561	1.3660634	0.35484904	3447.3616
466.15698	1.3675019	0.35574669	3443.3025
467.05786	1.3747429	0.3566874	3451.5452
467.95874	1.3745311	0.35781735	3455.0149
468.85962	1.3789787	0.35904229	3453.3044
469.7605	1.3826259	0.36011639	3451.7681
470.66138	1.3827286	0.36101642	3451.7959
471.56226	1.3830214	0.36202201	3455.5315
472.46313	1.3864805	0.36284336	3458.3564
473.36401	1.3922102	0.36375892	3454.3047
474.26489	1.3946084	0.36468694	3458.8076
475.16577	1.39449	0.36565745	3458.2461
476.06665	1.4014717	0.36665717	3461.2444
476.96753	1.3985337	0.36763301	3459.3794
477.86841	1.4024113	0.36891243	3468.5225
478.76929	1.4059275	0.37007126	3465.1199
479.67017	1.4089006	0.37102851	3461.4907
480.57104	1.4109114	0.37219098	3468.1426
481.47192	1.4170468	0.37302551	3462.3914
482.3728	1.4158449	0.37403062	3465.877
483.27368	1.4205848	0.37519228	3473.5042
484.17456	1.4236667	0.37623364	3466.3257
485.07544	1.428735	0.37726742	3478.0566
485.97632	1.4298173	0.37844709	3476.6194
486.8772	1.430585	0.37945196	3476.8171
487.77808	1.4352875	0.38036203	3471.2917
488.67896	1.4367722	0.38141209	3471.3528
489.57983	1.4394284	0.38217241	3471.4585
490.48071	1.4389281	0.38318101	3477.0034
491.38159	1.4456533	0.38417971	3476.1487
492.28247	1.4486464	0.38503799	3477.3845
493.18335	1.4485474	0.38585484	3474.8894
494.08423	1.4524161	0.38681722	3482.0374
494.98511	1.4557964	0.38786602	3481.0957
495.88599	1.4593291	0.38884783	3481.5413
496.78687	1.4615984	0.38980636	3485.9841
497.68774	1.4632504	0.39088458	3484.9766
498.58862	1.4665281	0.39178523	3480.9058
499.4895	1.4683024	0.39257473	3482.283
500.39038	1.4709564	0.39354807	3486.2151
501.29126	1.4756866	0.39459911	3492.1943
502.19214	1.4751706	0.39546531	3484.2095
503.09302	1.4782026	0.39643183	3487.5454
503.9939	1.4837098	0.39748463	3494.4072
504.89478	1.484206	0.39850923	3493.011
505.79565	1.4882482	0.39964667	3493.7964
506.69653	1.4900067	0.40077773	3491.7051
507.59741	1.492435	0.40169558	3488.2866
508.49829	1.4958773	0.40290299	3497.0129
509.39917	1.4998868	0.40404403	3501.2346
510.30005	1.5012332	0.40508196	3496.7078
511.20093	1.5023528	0.40628505	3505.103
512.10181	1.5085125	0.4071992	3495.3333
513.00269	1.5095567	0.40810221	3492.5181
513.90356	1.513334	0.40898564	3497.8657
514.80444	1.5150477	0.40998244	3499.8257
515.70532	1.5196329	0.41111708	3509.4731
516.6062	1.5216727	0.41238701	3511.5564
517.50708	1.5245656	0.41327101	3501.0337
518.40796	1.5253284	0.41441721	3504.0713
519.30884	1.5294026	0.41548803	3508.6433
520.20972	1.5333455	0.41650048	3505.4695
521.1106	1.534935	0.41734457	3505.7271
522.01147	1.5352018	0.41832459	3509.7681
522.91235	1.5403974	0.41943392	3512.3479
523.81323	1.5424144	0.42047897	3510.0979
524.71411	1.5465351	0.4212648	3512.1443
525.61499	1.5493587	0.42234954	3513.1799
526.51587	1.5492786	0.42342171	3511.5222
527.41675	1.5557648	0.42431766	3512.3074
528.31763	1.5552659	0.42520854	3518.3594
529.21851	1.5590072	0.42617035	3514.0193
530.11938	1.5645076	0.4274058	3519.8691
531.02026	1.562686	0.42841285	3513.3704
531.92114	1.5651553	0.42926678	3512.6882
532.82202	1.5657617	0.43033922	3521.2056
533.7229	1.5702062	0.43140224	3517.123
534.62378	1.5743616	0.4323267	3519.2512
535.52466	1.5797238	0.43351093	3522.4265
536.42554	1.5788035	0.43455952	3518.6079
537.32642	1.5825192	0.4356361	3523.2649
538.22729	1.5849968	0.43673444	3524.4104
539.12817	1.5874996	0.43778983	3524.8872
540.02905	1.5902625	0.43887731	3525.3296
540.92993	1.5910225	0.43997213	3524.3489
541.83081	1.5983173	0.44111553	3530.9426
542.73169	1.5982243	0.44210789	3530.3794
543.63257	1.6015825	0.44313633	3523.4294
544.53345	1.6038316	0.4439126	3522.0859
545.43433	1.6055814	0.44490948	3530.0774
546.33521	1.6088072	0.44602063	3533.2017
547.23608	1.6138417	0.44716471	3533.5703
548.13696	1.6156056	0.44816893	3529.387
549.03784	1.6163329	0.44897306	3530.0488
549.93872	1.6205291	0.44997036	3534.1135
550.8396	1.622864	0.45107269	3533.2493
551.74048	1.6254956	0.45202303	3538.8816
552.64136	1.6263108	0.45299408	3538.7507
553.54224	1.629541	0.45410758	3542.6802
554.44312	1.6321577	0.45525467	3536.3618
555.34399	1.6373373	0.45640627	3540.5967
556.24487	1.6408463	0.45742261	3543.908
557.14575	1.6444712	0.45841259	3543.3445
558.04663	1.6472133	0.45955536	3544.6052
558.94751	1.6460648	0.46050557	3540.2329
559.84839	1.6487781	0.461568	3540.3831
560.74927	1.6522844	0.46263599	3544.3518
561.65015	1.653771	0.46375698	3544.5974
562.55103	1.6584078	0.46489429	3548.5476
563.4519	1.66107	0.46595883	3548.0557
564.35278	1.6628414	0.46703798	3544.6865
565.25366	1.6657088	0.46803477	3544.4155
566.15454	1.6675168	0.46896273	3543.4753
567.05542	1.6721073	0.4699167	3547.4551
567.9563	1.6735404	0.47083792	3549.4546
568.85718	1.6770558	0.4718996	3551.0349
569.75806	1.6820714	0.47312525	3555.7837
570.65894	1.6845254	0.47410443	3547.3467
571.55981	1.68414	0.47526067	3555.5266
572.46069	1.6878201	0.4761174	3555.3328
573.36157	1.6913003	0.47721091	3554.0552
574.26245	1.6922388	0.47831532	3548.0891
575.16333	1.698228	0.47939444	3559.8655
576.06421	1.7006881	0.48040244	3557.145
576.96509	1.7009687	0.48135984	3553.8213
577.86597	1.7049448	0.48247841	3559.9131
578.76685	1.7089927	0.48355824	3562.7402
579.66772	1.7080137	0.48456278	3555.6382
580.5686	1.7121127	0.48570454	3562.7834
581.46948	1.7160994	0.4868319	3560.4119
582.37036	1.7175606	0.48816311	3565.3708
583.27124	1.720857	0.48923686	3563.009
584.17212	1.72378	0.49030992	3563.8936
585.073	1.7242881	0.4913829	3560.0078
585.97388	1.7281784	0.49250165	3570.2783
586.87476	1.7289355	0.49368054	3565.0542
587.77563	1.7346401	0.49482429	3568.8137
588.67651	1.7376196	0.49583879	3565.8533
589.57739	1.7368919	0.49683189	3569.5864
590.47827	1.7413925	0.49792281	3566.2065
591.37915	1.74391	0.49905783	3570.7292
592.28003	1.7486029	0.50010383	3567.7637
593.18091	1.7515565	0.50109398	3568.8513
594.08179	1.7536831	0.5021885	3575.1902
594.98267	1.7564383	0.50325936	3571.7131
595.88354	1.7591995	0.50445348	3573.0691
596.78442	1.7603554	0.50545526	3573.2561
597.6853	1.7644295	0.50654423	3576.8804
598.58618	1.7678345	0.50763726	3577.0313
599.48706	1.7685711	0.50871783	3574.4932
600.38794	1.7725452	0.50980669	3575.9214
601.28882	1.7727709	0.51085132	3575.7351
602.1897	1.7772527	0.51207751	3583.8923
603.09058	1.7776798	0.51326716	3575.7908
603.99146	1.7845856	0.51445317	3580.0986
604.89233	1.7870451	0.51551133	3576.4897
605.79321	1.7886218	0.51664209	3579.4949
606.69409	1.7936157	0.51769763	3573.8164
607.59497	1.7931838	0.51882142	3579.9409
608.49585	1.7964884	0.5200004	3584.135
609.39673	1.7994841	0.52105606	3581.9583
610.29761	1.801717	0.52216005	3584.1602
611.19849	1.8053817	0.52323568	3588.4988
612.09937	1.806124	0.52427328	3576.8916
613.00024	1.8100059	0.5253551	3583.0947
613.90112	1.8096706	0.52658254	3585.9043
614.802	1.8144082	0.52757013	3582.7383
615.70288	1.816918	0.52884078	3590.9128
616.60376	1.818222	0.52998042	3590.2241
617.50464	1.8246995	0.53132832	3592.5715
618.40552	1.8262562	0.53235453	3582.4417
619.3064	1.830162	0.53332758	3590.6921
620.20728	1.8301131	0.53425944	3590.1033
621.10815	1.8315153	0.5355711	3596.854
622.00903	1.8363727	0.53688985	3592.4099
622.90991	1.8377733	0.53814781	3593.8064
623.81079	1.8430517	0.53928149	3596.6692
624.71167	1.8455871	0.54046577	3593.9651
625.61255	1.8482298	0.54163855	3589.4893
626.51343	1.8509517	0.54253292	3592.085
627.41431	1.8528419	0.54357672	3588.8967
628.31519	1.8529048	0.54469854	3597.0159
629.21606	1.8603398	0.54566872	3590.6831
630.11694	1.860364	0.54676706	3596.5452
631.01782	1.8624698	0.54788661	3595.7632
631.9187	1.8645355	0.54918057	3600.418
632.81958	1.8657392	0.55036741	3595.7002
633.72046	1.8719773	0.55162859	3599.7878
634.62134	1.8751194	0.55267209	3599.6563
635.52222	1.8778589	0.55384362	3602.7986
636.4231	1.881097	0.55491525	3598.7559
637.32397	1.8819616	0.55586243	3594.5911
638.22485	1.8814486	0.55680639	3598.1521
639.12573	1.8878664	0.55790573	3605.4719
640.02661	1.8928246	0.55921465	3609.9971
640.92749	1.8923239	0.56051356	3608.2319
641.82837	1.8966218	0.56147736	3603.373
642.72925	1.9007622	0.56282258	3605.1365
643.63013	1.8991712	0.56386513	3603.76
644.53101	1.9051267	0.56518304	3607.2849
645.43188	1.9070152	0.56646693	3607.3667
646.33276	1.9106833	0.56756502	3602.093
647.23364	1.9114809	0.56864339	3606.3662
648.13452	1.9135721	0.56974947	3603.2034
649.0354	1.9189328	0.57083887	3606.9915
649.93628	1.9206753	0.57215112	3605.604
650.83716	1.9262378	0.57335043	3611.4736
651.73804	1.9244637	0.5744794	3608.6772
652.63892	1.9298013	0.57561731	3613.7593
653.53979	1.9301577	0.57712698	3616.8628
654.44067	1.9365613	0.578403	3613.8308
655.34155	1.9354675	0.57951301	3614.2202
656.24243	1.9394118	0.58073831	3614.7007
657.14331	1.9387063	0.58209896	3611.5774
658.04419	1.9465538	0.58329505	3612.6709
658.94507	1.9471396	0.58453637	3620.5996
659.84595	1.94953	0.58566523	3611.6069
660.74683	1.9542625	0.58688682	3615.592
661.64771	1.957131	0.58792871	3613.3623
662.54858	1.956108	0.58907193	3615.6497
663.44946	1.9644661	0.59023446	3617.5513
664.35034	1.9598931	0.5913204	3613.0273
665.25122	1.9689877	0.59245974	3616.3555
666.1521	1.9693147	0.5936957	3615.407
667.05298	1.97296	0.59496945	3622.9102
667.95386	1.9750818	0.59627616	3618.5649
668.85474	1.9781739	0.59748393	3625.2158
669.75562	1.9812652	0.59879971	3622.9976
670.65649	1.9814937	0.60014027	3620.9978
671.55737	1.9845027	0.60094589	3614.9067
672.45825	1.9854136	0.60198867	3613.7136
673.35913	1.9905183	0.6031394	3623.2524
674.26001	1.9953793	0.60460222	3625.5271
675.16089	1.9961293	0.60585058	3625.9397
676.06177	1.9953138	0.60689062	3617.041
676.96265	2.0034988	0.60796815	3623.3818
677.86353	2.004745	0.60937488	3625.3562
678.7644	2.0061316	0.61071998	3628.3989
679.66528	2.0077803	0.61200511	3624.0449
680.56616	2.011373	0.61330402	3625.4731
681.46704	2.014559	0.61479062	3632.7322
682.36792	2.0182774	0.61586332	3624.1792
683.2688	2.0194354	0.61700284	3625.416
684.16968	2.0224314	0.61820871	3627.5452
685.07056	2.0265226	0.61942774	3632.2666
685.97144	2.0279582	0.62060946	3624.5471
686.87231	2.0305197	0.62165666	3626.5034
687.77319	2.0358987	0.62294811	3628.5781
688.67407	2.032474	0.62433332	3630.7532
689.57495	2.0400906	0.62569761	3628.4314
690.47583	2.0430994	0.62682253	3629.2563
691.37671	2.0443082	0.6283049	3631.2422
692.27759	2.0486317	0.62959981	3631.0591
693.17847	2.0482695	0.63072431	3629.9695
694.07935	2.0530889	0.63176388	3631.0962
694.98022	2.0565143	0.63301063	3634.0054
695.8811	2.0583255	0.63434249	3634.4282
696.78198	2.0581534	0.63575721	3634.8235
697.68286	2.0646768	0.63724357	3642.2842
698.58374	2.0655589	0.63853866	3636.2813
699.48462	2.0684743	0.63983071	3636.249
700.3855	2.0704687	0.64104509	3632.3059
701.28638	2.0723355	0.64218676	3626.6392
702.18726	2.0768435	0.64358228	3642.3022
703.08813	2.0774498	0.64489168	3637.9429
703.98901	2.084568	0.6462872	3634.5596
704.88989	2.0841916	0.64739311	3632.4358
705.79077	2.0880935	0.64878958	3639.0393
706.69165	2.0914593	0.65005213	3641.4729
707.59253	2.0943415	0.65139693	3639.6968
708.49341	2.0950353	0.65232807	3630.8909
709.39429	2.0997257	0.65374321	3641.9731
710.29517	2.1006768	0.65502954	3639.2581
711.19604	2.1059008	0.65640062	3641.5564
712.09692	2.1066806	0.65772295	3638.6199
712.9978	2.1101768	0.65880507	3637.8203
713.89868	2.1127212	0.66013169	3637.8228
714.79956	2.1151788	0.66142613	3641.1055
715.70044	2.1163521	0.66291076	3641.6411
716.60132	2.1212921	0.66431189	3639.1912
717.5022	2.1255212	0.66537553	3639.7754
718.40308	2.1255665	0.66686875	3646.4187
719.30396	2.128329	0.66825056	3645.1655
720.20483	2.1295116	0.66965419	3639.7554
721.10571	2.1353757	0.67102307	3644.7715
722.00659	2.1366498	0.67218345	3637.3394
722.90747	2.1410213	0.67340761	3639.9482
723.80835	2.1428483	0.6746664	3645.7815
724.70923	2.1457038	0.67594248	3646.3157
725.61011	2.1472347	0.67732507	3641.3406
726.51099	2.1511512	0.67882371	3648.3672
727.41187	2.1524804	0.68014181	3642.5967
728.31274	2.1556194	0.68158585	3644.916
729.21362	2.1580861	0.6831094	3647.9873
730.1145	2.1599331	0.68476725	3649.3015
731.01538	2.1637475	0.6863547	3649.5156
731.91626	2.1659808	0.68775648	3639.1536
732.81714	2.1674175	0.6890834	3641.8223
733.71802	2.1717305	0.69044721	3650.4072
734.6189	2.1749012	0.69173044	3644.116
735.51978	2.176544	0.69292438	3644.3682
736.42065	2.1766586	0.69409376	3643.0708
737.32153	2.1818066	0.69541556	3645.791
738.22241	2.1852162	0.69702035	3649.5652
739.12329	2.1898685	0.69839543	3647.855
740.02417	2.1917825	0.69980496	3648.9089
740.92505	2.192374	0.70142704	3650.1357
741.82593	2.1969025	0.70272994	3646.9792
742.72681	2.1988482	0.70420796	3648.6604
743.62769	2.2023311	0.70561534	3653.248
744.52856	2.2047541	0.70693076	3649.4861
745.42944	2.2067037	0.70828497	3652.3923
746.33032	2.2109468	0.70972127	3649.6506
747.2312	2.2147002	0.7110101	3650.1321
748.13208	2.2158089	0.71235943	3651.4705
749.03296	2.216855	0.71384591	3650.2454
749.93384	2.2202871	0.71524286	3649.9702
750.83472	2.2238786	0.71667218	3646.7795
751.7356	2.2280571	0.71797681	3656.8508
752.63647	2.2254639	0.71939427	3651.8911
753.53735	2.2320518	0.72090328	3652.6948
754.43823	2.2322657	0.72232962	3652.4915
755.33911	2.2364342	0.72378743	3651.6069
756.23999	2.2414415	0.72536999	3656.9409
757.14087	2.2439592	0.72695661	3652.9226
758.04175	2.2478862	0.72841305	3649.1035
758.94263	2.2468824	0.72961473	3654.2087
759.84351	2.2486336	0.73097944	3647.9131
760.74438	2.2559478	0.73271471	3661.9946
761.64526	2.2539303	0.73452473	3656.4583
762.54614	2.258615	0.73641032	3657.1536
763.44702	2.2610798	0.73779994	3650.8779
764.3479	2.2645855	0.73935074	3650.978
765.24878	2.26826	0.74070174	3655.0413
766.14966	2.2702498	0.74208224	3649.9658
767.05054	2.2718358	0.7435652	3659.4985
767.95142	2.2724802	0.74512899	3651.5168
768.85229	2.2776375	0.74667567	3659.178
769.75317	2.2792091	0.74809086	3648.4663
770.65405	2.2809155	0.74962682	3653.812
771.55493	2.2855515	0.75111103	3659.666
772.45581	2.2894304	0.75248426	3653.043
773.35669	2.2928736	0.7540288	3660.2554
774.25757	2.2936795	0.75525671	3651.3145
775.15845	2.2977748	0.75667065	3656.2004
776.05933	2.2955251	0.75832981	3656.9138
776.96021	2.3010373	0.75987679	3655.092
777.86108	2.3029594	0.76151991	3657.7493
778.76196	2.3070905	0.76299965	3655.4111
779.66284	2.3079302	0.76438987	3651.7092
780.56372	2.3136799	0.76553267	3649.9988
781.4646	2.3151996	0.76700652	3655.9036
782.36548	2.3172431	0.76858592	3658.6077
783.26636	2.3213112	0.77022594	3661.2373
784.16724	2.3234401	0.77181178	3656.3005
785.06812	2.3247669	0.77334344	3653.4834
785.96899	2.3296204	0.77477121	3657.3804
786.86987	2.3313513	0.77635252	3658.4204
787.77075	2.3349259	0.77807748	3654.8347
788.67163	2.3377655	0.77963954	3657.3379
789.57251	2.3379028	0.78112745	3653.9155
790.47339	2.3433611	0.78261423	3658.5134
791.37427	2.346534	0.7843985	3662.7839
792.27515	2.3487642	0.78604335	3661.3726
793.17603	2.3537879	0.78766	3659.1277
794.0769	2.3535366	0.78917414	3660.2727
794.97778	2.3517339	0.79090577	3657.408
795.87866	2.3597701	0.79271209	3660.6245
796.77954	2.3595788	0.79465121	3663.0391
797.68042	2.3662233	0.79657698	3658.0232
798.5813	2.3673573	0.79825568	3656.074
799.48218	2.3695574	0.79986495	3652.6326
800.38306	2.3745635	0.80149108	3654.3948
801.28394	2.3754852	0.80304444	3657.8777
802.18481	2.3760481	0.80441844	3653.3811
803.08569	2.3779252	0.80575848	3650.8762
803.98657	2.3828702	0.80744189	3658.4382
804.88745	2.3858416	0.80918175	3659.3208
805.78833	2.3887823	0.81091774	3658.3755
806.68921	2.390635	0.81271321	3660.7517
807.59009	2.3926048	0.81476331	3662.126
808.49097	2.3958986	0.81673831	3660.3789
809.39185	2.3977423	0.81832021	3654.8953
810.29272	2.4004805	0.81992036	3652.7529
811.1936	2.4063802	0.82164669	3657.2163
812.09448	2.4084322	0.82362413	3657.9766
812.99536	2.4098141	0.8255235	3656.7683
813.89624	2.4126992	0.82740474	3661.9758
814.79712	2.4147062	0.82914543	3657.7625
815.698	2.4193168	0.83087218	3658.24
816.59888	2.4179657	0.83250791	3651.7012
817.49976	2.4211314	0.8344872	3657.5811
818.40063	2.4240954	0.83627898	3652.0195
819.30151	2.429044	0.83780682	3655.5928
820.20239	2.430182	0.83927691	3653.9519
821.10327	2.4350147	0.84126693	3660.7861
822.00415	2.4388177	0.84317291	3657.7734
822.90503	2.4399059	0.84502041	3655.1494
823.80591	2.4417212	0.84655237	3656.8369
824.70679	2.4469681	0.84813905	3655.0601
825.60767	2.4459145	0.8500703	3654.9211
826.50854	2.4486427	0.85191351	3652.3608
827.40942	2.4505925	0.85373741	3651.5249
828.3103	2.456454	0.85553849	3653.0474
829.21118	2.4556334	0.85754883	3657.9019
830.11206	2.4619994	0.85945922	3657.5269
831.01294	2.4634705	0.86134076	3654.4487
831.91382	2.4651394	0.86333144	3655.5469
832.8147	2.4676948	0.86566901	3662.4932
833.71558	2.4722519	0.86842489	3657.0217
834.61646	2.4756753	0.87090409	3659.7808
835.51733	2.4779441	0.87262201	3638.751
836.41821	2.4809535	0.87421644	3648.3408
837.31909	2.4838455	0.87547237	3647.9312
838.21997	2.4824233	0.87726605	3650.6021
839.12085	2.4899769	0.87897325	3654.0776
840.02173	2.491648	0.88078654	3657.365
840.92261	2.493412	0.88280696	3656.1621
841.82349	2.4971018	0.88500559	3654.4636
842.72437	2.4975386	0.88699025	3647.0808
843.62524	2.5036345	0.8888061	3653.2637
844.52612	2.5061104	0.89053416	3650.9478
845.427	2.510138	0.89237428	3655.8711
846.32788	2.5103271	0.89465725	3655.8005
847.22876	2.5127933	0.8967368	3652.9492
848.12964	2.5171363	0.89864439	3646.7002
849.03052	2.5177839	0.90013957	3643.1243
849.9314	2.5230489	0.90208107	3652.0713
850.83228	2.5220125	0.90388101	3646.5405
851.73315	2.5264423	0.90575618	3645.8806
852.63403	2.5276513	0.90793699	3650.9333
853.53491	2.5288997	0.90993351	3649.6331
854.43579	2.5337799	0.91199982	3648.7966
855.33667	2.53477	0.91435349	3651.3232
856.23755	2.5422003	0.9168002	3648.7102
857.13843	2.5420897	0.91888666	3648.3872
858.03931	2.5437012	0.92102122	3647.1499
858.94019	2.5474873	0.92331797	3650.3079
859.84106	2.5470979	0.9255318	3640.7192
860.74194	2.5521195	0.9274078	3641.5374
861.64282	2.5563059	0.9295935	3648.8645
862.5437	2.5578017	0.93142062	3643.5315
863.44458	2.5608892	0.9333362	3638.9558
864.34546	2.5648117	0.93531066	3649.1331
865.24634	2.56617	0.93769187	3646.7527
866.14722	2.5728924	0.93997175	3639.7876
867.0481	2.5737305	0.94197851	3640.1687
867.94897	2.5729949	0.94397926	3645.7883
868.84985	2.5797899	0.94671577	3650.5552
869.75073	2.5794392	0.94915181	3640.53
870.65161	2.5832167	0.95128143	3639.9534
871.55249	2.585151	0.95361811	3643.249
872.45337	2.5863326	0.95578223	3637.0857
873.35425	2.5894294	0.95815998	3638.4937
874.25513	2.5949075	0.96032721	3641.4744
875.15601	2.5961087	0.9629091	3642.7822
876.05688	2.5988383	0.96577013	3639.5168
876.95776	2.6049736	0.96809459	3639.3127
877.85864	2.6034358	0.97054398	3639.2783
878.75952	2.6074781	0.97310388	3638.9995
879.6604	2.611083	0.9755013	3632.5923
880.56128	2.6123972	0.97784692	3635.5313
881.46216	2.6155479	0.98010391	3627.6875
882.36304	2.6191969	0.9817946	3627.8589
883.26392	2.6202414	0.98382258	3632.2986
884.16479	2.6225212	0.9860338	3634.7969
885.06567	2.6272259	0.98854119	3630.4541
885.96655	2.6280868	0.99090558	3627.6428
886.86743	2.6310256	0.99295461	3623.0474
887.76831	2.6359317	0.99522012	3627.2717
888.66919	2.6359105	0.99750972	3628.0803
889.57007	2.6384668	0.9998163	3628.3176
890.47095	2.6390035	1.002645	3627.0859
891.37183	2.6446981	1.0052062	3628.5801
892.27271	2.6488519	1.0076189	3627.7122
893.17358	2.6500607	1.0102032	3629.3318
894.07446	2.6539538	1.0128314	3625.3086
894.97534	2.6555302	1.0152254	3621.7151
895.87622	2.6576703	1.017445	3625.3203
896.7771	2.6631827	1.0199294	3621.1345
897.67798	2.6630714	1.0223901	3616.8474
898.57886	2.6670637	1.0249403	3622.2319
899.47974	2.6700897	1.0274979	3619.1541
900.38062	2.6701403	1.0300983	3624.8726
901.28149	2.6758103	1.0328214	3617.5698
902.18237	2.6777942	1.0352192	3619.4927
903.08325	2.679261	1.0379354	3612.2783
903.98413	2.6846852	1.0405684	3615.7629
904.88501	2.6846869	1.0435501	3614.2705
905.78589	2.6882269	1.0466934	3614.8979
906.68677	2.691005	1.0494546	3603.5354
907.58765	2.6931219	1.0522161	3616.5762
908.48853	2.6967251	1.0550283	3611.0664
909.3894	2.697875	1.0579076	3608.2251
910.29028	2.699914	1.060424	3608.0442
911.19116	2.7075686	1.0629231	3608.6575
912.09204	2.7086484	1.0653911	3603.9004
912.99292	2.7099199	1.0677822	3602.9429
913.8938	2.7122536	1.0702945	3603.4099
914.79468	2.7142029	1.0728335	3599.2356
915.69556	2.7216022	1.0757804	3603.199
916.59644	2.7198751	1.0785633	3595.8665
917.49731	2.7261405	1.0813625	3601.822
918.39819	2.7237642	1.0837094	3593.1135
919.29907	2.7300775	1.0863782	3594.8135
920.19995	2.7336237	1.0891665	3592.2825
921.10083	2.7332666	1.0917282	3594.343
922.00171	2.7374353	1.0945557	3595.0781
922.90259	2.741528	1.0974926	3587.533
923.80347	2.7425485	1.1002167	3587.4092
924.70435	2.7458055	1.1028199	3586.3408
925.60522	2.7473099	1.1054219	3583.6211
926.5061	2.7495859	1.1083711	3585.5938
927.40698	2.7521448	1.1112896	3582.498
928.30786	2.7545862	1.113973	3577.0454
929.20874	2.7584202	1.1163898	3576.2571
930.10962	2.7625458	1.1187874	3581.6099
931.0105	2.7610147	1.121533	3577.3936
931.91138	2.7665577	1.1243925	3576.3701
932.81226	2.7714291	1.1274381	3575.1543
933.71313	2.7728248	1.1300797	3574.8772
934.61401	2.7754514	1.1331509	3573.6831
935.51489	2.7749619	1.1363161	3568.0847
936.41577	2.7827063	1.1390392	3568.1843
937.31665	2.7831631	1.1416447	3558.8281
938.21753	2.7866509	1.1441748	3558.4543
939.11841	2.787044	1.1466717	3560.9866
940.01929	2.7890227	1.1496563	3565.8276
940.92017	2.7938144	1.152442	3555.1663
941.82104	2.7960136	1.1550316	3553.2563
942.72192	2.7984431	1.1576524	3552.9319
943.6228	2.800174	1.160385	3549.479
944.52368	2.8028207	1.1633937	3551.8394
945.42456	2.8046873	1.1664026	3549.2649
946.32544	2.8073227	1.1694106	3546.5417
947.22632	2.8134751	1.1723133	3546.49
948.1272	2.815779	1.1749475	3541.8855
949.02808	2.8165224	1.177691	3538.4836
949.92896	2.8227346	1.1805668	3541.0386
950.82983	2.8221512	1.1832914	3537.366
951.73071	2.8262904	1.1862221	3536.3784
952.63159	2.8283939	1.1895472	3536.4749
953.53247	2.8315489	1.1926248	3527.2688
954.43335	2.8336892	1.1954014	3528.3044
955.33423	2.8355315	1.1981654	3526.2537
956.23511	2.839438	1.2012533	3529.98
957.13599	2.8426023	1.2043786	3523.9688
958.03687	2.8450723	1.2073545	3522.2375
958.93774	2.8486516	1.2099912	3510.0725
959.83862	2.851233	1.2123126	3512.6089
960.7395	2.8528278	1.2147224	3510.739
961.64038	2.8553357	1.2175212	3510.6975
962.54126	2.8622055	1.2204717	3512.6631
963.44214	2.8602118	1.2233486	3509.6406
964.34302	2.8656754	1.2264709	3506.9529
965.2439	2.8660178	1.2293035	3499.4863
966.14478	2.8693993	1.2322873	3502.2551
967.04565	2.8707685	1.2351893	3497.7922
967.94653	2.8730471	1.2379103	3493.5918
968.84741	2.8779228	1.240535	3491.3174
969.74829	2.8800638	1.2429961	3493.532
970.64917	2.883311	1.246196	3490.2537
971.55005	2.885494	1.2495121	3483.9224
972.45093	2.8891881	1.2526292	3485.7178
973.35181	2.8921599	1.2557395	3476.2476
974.25269	2.8936894	1.2590119	3480.7542
975.15356	2.8944836	1.2623811	3472.8149
976.05444	2.8983891	1.265581	3473.7915
976.95532	2.9022031	1.2684672	3464.5085
977.8562	2.9046719	1.2712805	3467.7319
978.75708	2.9070883	1.2743274	3461.3015
979.65796	2.9113827	1.2773275	3458.1851
980.55884	2.9138474	1.2805369	3456.2529
981.45972	2.9135096	1.2835367	3450.2478
982.3606	2.9169128	1.286118	3448.0786
983.26147	2.9222035	1.2889839	3447.3191
984.16235	2.9219966	1.291823	3445.0396
985.06323	2.9273605	1.2946993	3445.3643
985.96411	2.9289455	1.2974331	3441.4373
986.86499	2.930721	1.3003181	3434.865
987.76587	2.9362407	1.3034008	3439.8145
988.66675	2.9373136	1.3067547	3429.427
989.56763	2.9392607	1.3099648	3427.7598
990.46851	2.9419057	1.3131016	3425.6541
991.36938	2.9455183	1.3159944	3421.0962
992.27026	2.9482968	1.3186047	3415.0823
993.17114	2.9522369	1.3213812	3413.5161
994.07202	2.9521623	1.3241719	3408.7026
994.9729	2.9562755	1.32686	3407.5852
995.87378	2.9573908	1.3297251	3405.4021
996.77466	2.9603512	1.3323077	3401.7324
997.67554	2.9624615	1.3351458	3398.0469
998.57642	2.9653859	1.3384252	3398.3257
999.47729	2.9716125	1.3414826	3393.0137
1000.3782	2.9736407	1.3443532	3385.6565
1001.2791	2.975704	1.3470995	3384.9917
1002.1799	2.9778802	1.3498812	3385.1428
1003.0808	2.9801691	1.353079	3378.9553
1003.9817	2.9825888	1.356317	3372.793
1004.8826	2.9839387	1.3588482	3367.4653
1005.7834	2.9895322	1.3612374	3364.5657
1006.6843	2.990653	1.3633926	3359.2478
1007.5852	2.996496	1.3656482	3364.6292
1008.4861	2.9959993	1.3679787	3361.1975
1009.387	3.0003719	1.3707922	3358.6685
1010.2878	3.0035307	1.3737283	3353.8325
1011.1887	3.001879	1.3762871	3345.6123
1012.0896	3.0066173	1.3790877	3346.9146
1012.9905	3.009202	1.3819555	3347.45
1013.8914	3.0114186	1.3855006	3338.1367
1014.7922	3.0159695	1.3891751	3337.9172
1015.6931	3.0202096	1.3929869	3330.292
1016.594	3.019814	1.3962108	3323.6951
1017.4949	3.0236418	1.3993865	3317.6858
1018.3958	3.0255182	1.4018557	3309.9724
1019.2966	3.0319095	1.4045985	3314.5076
1020.1975	3.0314057	1.4076166	3310.3481
1021.0984	3.0329401	1.410941	3303.5366
1021.9993	3.0390315	1.4137192	3298.5889
1022.9001	3.0389988	1.4163409	3289.8149
1023.801	3.0421433	1.4191442	3291.0933
1024.7019	3.0457897	1.4225317	3288.2334
1025.6028	3.0462687	1.4264425	3287.9836
1026.5037	3.0513375	1.4298769	3273.3572
1027.4045	3.0520062	1.4326051	3268.7637
1028.3054	3.0556076	1.4352593	3269.7703
1029.2063	3.058548	1.4383334	3265.4941
1030.1072	3.0610409	1.4412496	3262.2791
1031.0081	3.0640609	1.4443989	3255.1228
1031.9089	3.0692081	1.4474632	3251.3713
1032.8098	3.0697005	1.4503374	3245.887
1033.7107	3.0734558	1.4532902	3243.5649
1034.6116	3.077673	1.4560583	3242.4167
1035.5125	3.0773573	1.4592355	3235.959
1036.4133	3.0796957	1.4622996	3230.4243
1037.3142	3.0842388	1.4653553	3227.7339
1038.2151	3.0864096	1.4683443	3220.8606
1039.116	3.0888941	1.4716333	3217.2205
1040.0168	3.0919507	1.4746277	3207.2954
1040.9177	3.0940793	1.4775041	3204.8308
1041.8186	3.0959818	1.4808509	3201.9189
1042.7195	3.0991433	1.4839782	3194.7715
1043.6204	3.1025796	1.4873221	3189.2664
1044.5212	3.103806	1.4904002	3185.7849
1045.4221	3.1096876	1.4937969	3179.116
1046.323	3.1095841	1.4969175	3172.4072
1047.2239	3.1136682	1.5001636	3173.2546
1048.1248	3.1164284	1.5034491	3166.3154
1049.0256	3.1186092	1.5069902	3156.147
1049.9265	3.1197009	1.5100442	3152.0867
1050.8274	3.1244075	1.5134254	3141.9146
1051.7283	3.1279294	1.5170383	3145.6941
1052.6292	3.1297367	1.5203995	3134.7893
1053.53	3.1324222	1.5233326	3125.9333
1054.4309	3.1346827	1.5262749	3123.0056
1055.3318	3.1365247	1.5284845	3113.7756
1056.2327	3.1391044	1.5312432	3118.8225
1057.1335	3.1431408	1.5347084	3105.0637
1058.0344	3.1465769	1.5382168	3108.2588
1058.9353	3.1494551	1.5416689	3100.7866
1059.8362	3.1511633	1.545078	3096.1138
1060.7371	3.1532528	1.5484973	3084.7776
1061.6379	3.1582251	1.5516456	3077.3787
1062.5388	3.1589956	1.5551792	3078.3252
1063.4397	3.1627305	1.5589038	3066.4365
1064.3406	3.162868	1.5618583	3055.1238
1065.2415	3.1689432	1.5650814	3053.1421
1066.1423	3.1704519	1.5682012	3045.9526
1067.0432	3.1753771	1.5712961	3044.4121
1067.9441	3.1742682	1.5742	3031.3586
1068.845	3.1769071	1.5768634	3023.5962
1069.7458	3.180347	1.5796831	3021.8586
1070.6467	3.1847048	1.5826958	3018.6536
1071.5476	3.1864076	1.5857328	3009.2317
1072.4485	3.1864123	1.5889456	2998.6536
1073.3494	3.1916995	1.5921954	3001.8457
1074.2502	3.1950073	1.5954813	2987.1621
1075.1511	3.1973262	1.598561	2988.3704
1076.052	3.2003253	1.6022183	2979.8813
1076.9529	3.2036684	1.6058809	2965.7349
1077.8538	3.207906	1.6092601	2960.6543
1078.7546	3.2067261	1.6122509	2950.6848
1079.6555	3.2104466	1.6155915	2950.1919
1080.5564	3.2124441	1.6192565	2941.3079
1081.4573	3.2148674	1.6224693	2928.3845
1082.3582	3.2189987	1.6258146	2921.001
1083.259	3.2195768	1.6289163	2919.1121
1084.1599	3.2238615	1.6325419	2907.5361
1085.0608	3.2260659	1.6370559	2904.4265
1085.9617	3.2293932	1.6408067	2887.3359
1086.8625	3.2311075	1.6438631	2873.4241
1087.7634	3.236299	1.6469815	2875.2866
1088.6643	3.2369976	1.6503175	2865.9858
1089.5652	3.2385249	1.6544361	2856.4397
1090.4661	3.2442536	1.6578503	2843.8796
1091.3669	3.2447007	1.6613803	2840.4001
1092.2678	3.2491119	1.6645658	2826.2678
1093.1687	3.2492254	1.6677736	2817.8916
1094.0696	3.2553411	1.6713157	2815.5496
1094.9705	3.2551785	1.6751181	2797.6008
1095.8713	3.2615027	1.6786467	2795.0034
1096.7722	3.2609513	1.6821519	2777.0718
1097.6731	3.2646453	1.6863503	2770.9026
1098.574	3.2697408	1.6905603	2751.4561
1099.4749	3.2713017	1.6943549	2734.2192
1100.3757	3.2747223	1.6990392	2717.4302
1100.676	3.2753019	1.7019012	2694.1892