File: datasets/am_bench_2022/raw_data/TH1-I/specimen.dat
MTS793|MPT|ENU|1|2|.|/|:|1|0|0|A

Operator Information						Time:	13.239502	Sec	11/3/2021 11:37:47 AM
Operator	Nick Derimow
Project	AM Bench 2022 mini-tensile challenge
Specimen ID	TH1-I
Material	PBF-L Inconel 625
Specimen Width	2.56	mm
Specimen Thickness	1.52	mm
Notes
Operator Information End

Data Acquisition						Time:	1014.2334	Sec	11/3/2021 11:54:28 AM
Time	Axial Displacement	Axial Extensometer	Axial Force
Sec	mm	mm	N
13.353271	-0.0012929385	0.00018157192	61.555744
14.25415	0.0046988418	0.00012153988	70.353127
15.155029	0.0051274737	0.0002253151	77.161034
16.055908	0.0099065043	0.00032264958	87.029007
16.956787	0.01189533	0.00038550195	97.051956
17.857666	0.014689223	0.00048666686	108.39226
18.758545	0.018134004	0.00046340455	116.11664
19.659424	0.02042366	0.0006400923	128.53108
20.560303	0.021984262	0.00056883122	136.39697
21.461182	0.019867381	0.00072047819	149.62469
22.362061	0.027351536	0.0007402614	161.52667
23.262939	0.030262217	0.00090230454	173.20706
24.163818	0.032529693	0.00093914295	190.51787
25.064697	0.034132145	0.0010573517	205.97638
25.965576	0.038514048	0.0011176296	217.5932
26.866455	0.041435793	0.0013094547	236.51755
27.767334	0.041345026	0.0014285608	253.48303
28.668213	0.044168014	0.0014330643	270.60217
29.569092	0.047862913	0.0016035889	287.5975
30.469971	0.04966411	0.0016039906	298.34915
31.37085	0.052575149	0.0017596975	314.39655
32.271729	0.055144072	0.0018932885	333.28375
33.172607	0.058880825	0.0019238335	353.93829
34.073486	0.061870541	0.0020593884	378.02563
34.974365	0.061631843	0.0023010953	397.7359
35.875244	0.067064889	0.0024421688	422.33408
36.776123	0.069594882	0.0025751626	445.87106
37.677002	0.070154846	0.0027805062	473.31342
38.577881	0.074565224	0.0027618939	485.73209
39.47876	0.075994343	0.0028893054	501.72507
40.379639	0.080070592	0.0029314391	528.58441
41.280518	0.082284853	0.0032042074	548.81097
42.181396	0.082520068	0.0032708985	569.21484
43.082275	0.087141536	0.0034368376	592.29553
43.983154	0.088535152	0.0034737999	609.05023
44.884033	0.094781816	0.0037160066	640.84387
45.784912	0.094201565	0.0039242068	659.42688
46.685791	0.10129238	0.0040620551	680.58203
47.58667	0.10209858	0.004098739	702.15253
48.487549	0.10440729	0.0043309592	724.44403
49.388428	0.10691982	0.0044988287	751.27563
50.289307	0.1104048	0.0046873232	776.36066
51.190186	0.11057527	0.0047970605	804.87177
52.091064	0.11345866	0.0049340948	826.26538
52.991943	0.11597753	0.005173183	856.07141
53.892822	0.119652	0.0051087365	874.80292
54.793701	0.12179168	0.0053490512	898.97662
55.69458	0.12708211	0.0055065816	922.85822
56.595459	0.12817597	0.0056307898	946.62805
57.496338	0.12982023	0.0058212215	967.71191
58.397217	0.13444968	0.0059411298	993.82672
59.298096	0.13976143	0.0060760248	1017.6061
60.198975	0.13952069	0.0061969738	1041.5588
61.099854	0.14250672	0.0063043451	1061.0532
62.000732	0.1475226	0.006492231	1091.554
62.901611	0.14818439	0.0066897278	1112.6552
63.80249	0.15087092	0.0068055801	1140.0831
64.703369	0.15254585	0.0069328113	1155.8909
65.604248	0.15654631	0.0070350589	1181.9486
66.505127	0.15588184	0.0072244378	1210.2023
67.406006	0.15921025	0.0074334857	1237.8645
68.306885	0.16318677	0.0075967941	1263.1777
69.207764	0.16363056	0.0077067581	1286.3566
70.108643	0.16855624	0.0079058157	1313.2897
71.009521	0.17343055	0.0080322484	1339.8011
71.9104	0.17526042	0.0082386322	1375.5729
72.811279	0.17408763	0.0085020661	1397.955
73.712158	0.17918712	0.0085048974	1417.1194
74.613037	0.18164846	0.0087210434	1436.078
75.513916	0.18968153	0.0089173177	1474.8232
76.414795	0.18833108	0.0089969328	1495.9729
77.315674	0.1877619	0.0091285612	1513.6348
78.216553	0.19188042	0.0094011202	1543.6493
79.117432	0.19700177	0.0094700661	1563.9144
80.018311	0.19890045	0.0097212754	1597.8203
80.919189	0.20081003	0.0097497888	1612.1902
81.820068	0.20315295	0.0099006556	1636.7025
82.720947	0.20626232	0.0099995434	1664.3798
83.621826	0.20654938	0.010344949	1696.9061
84.522705	0.21022733	0.010497074	1718.0317
85.423584	0.21645042	0.010558054	1739.0989
86.324463	0.21775927	0.010801055	1760.4509
87.225342	0.22033183	0.010869144	1784.1965
88.126221	0.22446054	0.011120666	1813.2134
89.0271	0.22285727	0.011193041	1835.1924
89.927979	0.22785348	0.011382644	1859.0098
90.828857	0.22821409	0.011474402	1878.0969
91.729736	0.23422083	0.011696803	1900.0139
92.630615	0.23629488	0.011887412	1926.2401
93.531494	0.23854828	0.011975826	1945.9188
94.432373	0.24298637	0.012098873	1965.0537
95.333252	0.24578923	0.012144154	1986.9521
96.234131	0.24956982	0.012405505	2009.3615
97.13501	0.25220677	0.012527009	2033.0925
98.035889	0.25127575	0.012527615	2045.0723
98.936768	0.25606009	0.012744167	2064.592
99.837646	0.26246962	0.012883626	2082.2974
100.73853	0.25899312	0.013004035	2103.9436
101.6394	0.26111656	0.013285281	2131.5283
102.54028	0.26803973	0.013292825	2142.2441
103.44116	0.27163514	0.013387168	2167.9988
104.34204	0.27100837	0.013572982	2187.457
105.24292	0.27701262	0.013727603	2206.8125
106.1438	0.27876258	0.013893518	2228.5698
107.04468	0.28021604	0.014010369	2248.5098
107.94556	0.28114727	0.014194642	2253.8882
108.84644	0.28521803	0.014272811	2270.6272
109.74731	0.28770906	0.014411906	2282.3091
110.64819	0.29014575	0.014442307	2300.7854
111.54907	0.29262188	0.01454755	2314.8567
112.44995	0.29524115	0.014684277	2324.1802
113.35083	0.30153126	0.014887682	2348.5967
114.25171	0.29966345	0.015003321	2365.2007
115.15259	0.30488712	0.015267656	2379.1221
116.05347	0.30512992	0.015325705	2385.144
116.95435	0.30998883	0.015474053	2410.2302
117.85522	0.31265202	0.01565678	2414.9585
118.7561	0.31735539	0.015780242	2430.3611
119.65698	0.32078686	0.015960179	2445.1873
120.55786	0.32183591	0.016141916	2458.009
121.45874	0.32445747	0.016215356	2469.199
122.35962	0.32504612	0.016354028	2483.2285
123.2605	0.32863024	0.016533514	2491.1538
124.16138	0.33014473	0.016627977	2500.2493
125.06226	0.33254871	0.016799871	2512.4424
125.96313	0.33768037	0.016921971	2522.4248
126.86401	0.33824012	0.01719413	2535.4773
127.76489	0.33954898	0.017279863	2546.0261
128.66577	0.34515736	0.017567974	2562.6577
129.56665	0.34662536	0.017666521	2564.4604
130.46753	0.35017836	0.017801948	2569.9233
131.36841	0.35440376	0.01796951	2578.8167
132.26929	0.35578391	0.0180603	2589.6208
133.17017	0.36234382	0.018319016	2613.1252
134.07104	0.36240813	0.018455965	2610.8022
134.97192	0.36655489	0.018698597	2623.394
135.8728	0.36901748	0.018915284	2630.3247
136.77368	0.36727959	0.019080112	2635.5676
137.67456	0.3723475	0.019348647	2648.835
138.57544	0.37879989	0.019603217	2660.3401
139.47632	0.37784877	0.019774059	2660.6484
140.3772	0.38044694	0.020066636	2674.2361
141.27808	0.38423881	0.020354951	2683.6135
142.17896	0.38465884	0.020465545	2685.4688
143.07983	0.39099464	0.020868255	2696.3618
143.98071	0.3909221	0.021000039	2700.8799
144.88159	0.39243296	0.02135071	2708.542
145.78247	0.39805281	0.02162371	2712.6292
146.68335	0.40143204	0.022055903	2724.9868
147.58423	0.40472484	0.022323905	2732.1033
148.48511	0.40548027	0.022652835	2741.4731
149.38599	0.40852246	0.023071995	2757.2026
150.28687	0.41025004	0.023444019	2759.1489
151.18774	0.41232538	0.023886133	2762.9148
152.08862	0.41598386	0.02429877	2775.2644
152.9895	0.42093417	0.024696106	2781.1096
153.89038	0.42162445	0.024962904	2783.1411
154.79126	0.42442116	0.025494028	2795.5352
155.69214	0.42326072	0.025953811	2795.269
156.59302	0.42893589	0.026488049	2805.0488
157.4939	0.43203855	0.026991017	2806.3616
158.39478	0.43702021	0.027501052	2811.1558
159.29565	0.43414354	0.028053023	2823.7185
160.19653	0.44308263	0.028625652	2830.0459
161.09741	0.44348195	0.029110219	2828.823
161.99829	0.4468928	0.029793603	2833.4238
162.89917	0.45056167	0.030301433	2840.1003
163.80005	0.44876155	0.03096539	2846.9368
164.70093	0.45423183	0.031631414	2852.2288
165.60181	0.46214795	0.032340158	2863.5508
166.50269	0.46193179	0.032986108	2869.0249
167.40356	0.46442381	0.033619467	2870.9758
168.30444	0.46241677	0.034445703	2876.3696
169.20532	0.46763462	0.035064928	2876.6384
170.1062	0.46988246	0.035759706	2881.2856
171.00708	0.47148043	0.036396369	2883.7634
171.90796	0.47736561	0.037017886	2890.3523
172.80884	0.47827736	0.03761429	2893.8398
173.70972	0.48054284	0.038589839	2902.854
174.6106	0.48081264	0.039439302	2899.48
175.51147	0.48409355	0.040094282	2901.5125
176.41235	0.49159655	0.040761247	2914.6763
177.31323	0.49408332	0.04165807	2920.8362
178.21411	0.49429718	0.042255003	2917.4063
179.11499	0.49535996	0.043220121	2925.2886
180.01587	0.49968848	0.044033017	2922.8708
180.91675	0.50376636	0.044832811	2930.4341
181.81763	0.50735044	0.045529515	2929.6575
182.71851	0.50820667	0.046403963	2934.792
183.61938	0.5112958	0.047222946	2941.7446
184.52026	0.51458836	0.048150357	2949.7422
185.42114	0.51872855	0.049030416	2949.2083
186.32202	0.51769322	0.050011929	2952.5984
187.2229	0.52321106	0.050924227	2954.1028
188.12378	0.52329737	0.051727455	2953.8472
189.02466	0.52579147	0.052710053	2966.0916
189.92554	0.53138328	0.053503763	2965.833
190.82642	0.53244543	0.054441683	2964.2437
191.72729	0.53478974	0.055258207	2976.0447
192.62817	0.53909016	0.056238197	2975.0342
193.52905	0.5427044	0.057159852	2974.2114
194.42993	0.54359078	0.05810966	2980.8354
195.33081	0.54752237	0.059080273	2985.9495
196.23169	0.54825765	0.059836209	2985.3313
197.13257	0.55345023	0.060778163	2990.0361
198.03345	0.5548088	0.06157745	2996.0906
198.93433	0.55724251	0.06243882	2995.6914
199.83521	0.5612933	0.063411891	2997.0295
200.73608	0.56320554	0.064373575	2999.761
201.63696	0.56633013	0.065275848	3004.5654
202.53784	0.56864536	0.066276141	3003.8545
203.43872	0.56895578	0.06716264	3010.762
204.3396	0.57499748	0.067885093	3013.1472
205.24048	0.5768292	0.068735823	3007.8926
206.14136	0.57762909	0.069599472	3010.0566
207.04224	0.5819084	0.0704915	3022.7341
207.94312	0.58452791	0.071401343	3021.084
208.84399	0.58492249	0.072346725	3022.8157
209.74487	0.58816999	0.073424183	3024.4866
210.64575	0.59014755	0.074247248	3027.979
211.54663	0.59502804	0.075277381	3034.821
212.44751	0.59853226	0.076296955	3030.3091
213.34839	0.6011737	0.07733044	3041.2683
214.24927	0.60162908	0.078462094	3045.9421
215.15015	0.60558248	0.079530351	3045.8345
216.05103	0.60833043	0.08043173	3042.9758
216.9519	0.60955608	0.081400909	3043.5374
217.85278	0.61573732	0.082304925	3052.4465
218.75366	0.61687899	0.083327584	3054.479
219.65454	0.62161708	0.084206901	3059.7766
220.55542	0.62304205	0.084996611	3050.8005
221.4563	0.6251694	0.08609587	3065.2036
222.35718	0.62776518	0.087148406	3064.2349
223.25806	0.6293366	0.088116206	3063.4756
224.15894	0.63302219	0.088992767	3058.5029
225.05981	0.63767767	0.090028666	3069.76
225.96069	0.64074522	0.090900771	3072.4116
226.86157	0.63986546	0.091895729	3075.6177
227.76245	0.64291948	0.092846081	3072.7551
228.66333	0.64725828	0.093963273	3076.0566
229.56421	0.65181482	0.094879396	3081.4912
230.46509	0.65086043	0.096035331	3083.4934
231.36597	0.65253019	0.096895732	3083.0066
232.26685	0.65748608	0.097850449	3087.7881
233.16772	0.66050065	0.098779477	3086.8594
234.0686	0.66219687	0.099752948	3083.8164
234.96948	0.66666633	0.10067727	3091.2861
235.87036	0.66780919	0.10166007	3099.7788
236.77124	0.6687324	0.10276472	3102.408
237.67212	0.67119372	0.10385603	3095.3181
238.573	0.67549068	0.10484829	3100.896
239.47388	0.67727464	0.10577354	3103.6267
240.37476	0.68028098	0.10667457	3106.8779
241.27563	0.68304652	0.10760157	3106.782
242.17651	0.68739879	0.10852782	3107.3418
243.07739	0.69131589	0.10940347	3104.3433
243.97827	0.69023877	0.11036419	3108.8687
244.87915	0.69705254	0.11125728	3115.8762
245.78003	0.69848591	0.11229488	3113.2107
246.68091	0.70086819	0.11332903	3119.531
247.58179	0.7008059	0.11430785	3115.2295
248.48267	0.70425969	0.11517745	3123.8447
249.38354	0.71212149	0.11622959	3127.3293
250.28442	0.71316415	0.11718333	3130.812
251.1853	0.71093822	0.11822756	3124.9382
252.08618	0.71432751	0.11918548	3124.7063
252.98706	0.7180528	0.12017166	3130.7415
253.88794	0.72343194	0.12099197	3130.7881
254.78882	0.72423202	0.12197873	3132.2629
255.6897	0.72846669	0.12297199	3138.9321
256.59058	0.73059118	0.1240667	3140.5532
257.49146	0.73067188	0.12513384	3141.176
258.39233	0.73506695	0.12630533	3144.1426
259.29321	0.73925632	0.12738898	3147.4324
260.19409	0.74113578	0.12842523	3146.8406
261.09497	0.74256277	0.12934078	3150.4993
261.99585	0.745529	0.13033445	3149.5359
262.89673	0.74860275	0.13135335	3155.603
263.79761	0.74892294	0.13230111	3152.7791
264.69849	0.75480473	0.13334981	3161.3962
265.59937	0.75498933	0.13440494	3161.2046
266.50024	0.75952798	0.13550024	3159.5503
267.40112	0.7607733	0.13633785	3155.0137
268.302	0.76425475	0.13721876	3157.2954
269.20288	0.76689458	0.13826631	3167.978
270.10376	0.77064055	0.13909957	3164.312
271.00464	0.77443898	0.13999072	3167.8188
271.90552	0.77523023	0.14092882	3172.3298
272.8064	0.77958864	0.1417148	3169.9719
273.70728	0.78085917	0.14269505	3175.2141
274.60815	0.7816394	0.1436685	3175.9529
275.50903	0.78823537	0.1446863	3179.7603
276.40991	0.78951758	0.14572746	3185.1248
277.31079	0.79329407	0.14649564	3174.4043
278.21167	0.79471087	0.1474628	3181.1277
279.11255	0.79929769	0.14837725	3187.7551
280.01343	0.79814255	0.14942099	3185.9351
280.91431	0.80086815	0.15044758	3190.6404
281.81519	0.80392796	0.15148179	3190.8721
282.71606	0.80805832	0.1523495	3181.4138
283.61694	0.81145126	0.15323475	3190.5476
284.51782	0.81422669	0.1541412	3187.2849
285.4187	0.81906414	0.15522279	3197.7693
286.31958	0.82047969	0.15616006	3198.7356
287.22046	0.82228601	0.15719953	3196.8269
288.12134	0.82247573	0.15810794	3196.9001
289.02222	0.82924342	0.15907182	3205.5781
289.9231	0.83034217	0.16020913	3206.948
290.82397	0.83304656	0.16122673	3204.7983
291.72485	0.83683288	0.16214061	3208.7019
292.62573	0.83996028	0.16327956	3209.5818
293.52661	0.8422817	0.16428018	3222.7634
294.42749	0.84474486	0.16530445	3214.7166
295.32837	0.84318405	0.1664906	3214.4871
296.22925	0.84915286	0.16735886	3218.2317
297.13013	0.85051167	0.16862857	3220.5674
298.03101	0.85440516	0.16956092	3215.1394
298.93188	0.85489196	0.17057355	3219.6982
299.83276	0.86222452	0.17151964	3216.3748
300.73364	0.86385709	0.17255759	3221.2502
301.63452	0.86442298	0.17347962	3221.0588
302.5354	0.87108654	0.17451118	3230.7278
303.43628	0.86940831	0.17535338	3223.6311
304.33716	0.8719424	0.17614891	3226.1304
305.23804	0.87698531	0.17694062	3230.5286
306.13892	0.88024998	0.17801203	3234.1599
307.03979	0.87992918	0.17893314	3229.8267
307.94067	0.8853476	0.17984866	3237.1838
308.84155	0.88929689	0.18071134	3232.5896
309.74243	0.89156866	0.18167385	3241.0403
310.64331	0.89015865	0.18254678	3237.9644
311.54419	0.89417833	0.18357508	3242.7229
312.44507	0.90137732	0.18464214	3245.864
313.34595	0.90256202	0.18559851	3249.5051
314.24683	0.90425104	0.18645132	3242.313
315.14771	0.90624571	0.18746515	3252.3745
316.04858	0.9073047	0.18852842	3248.1594
316.94946	0.90949297	0.18939376	3247.9597
317.85034	0.91595948	0.19036712	3252.5659
318.75122	0.91786367	0.19119358	3254.127
319.6521	0.91637313	0.19204536	3252.0535
320.55298	0.92081058	0.19300285	3257.0276
321.45386	0.92498559	0.19398992	3258.0603
322.35474	0.93137974	0.19490969	3259.0698
323.25562	0.92890799	0.19582435	3256.8108
324.15649	0.9330771	0.19693691	3263.2617
325.05737	0.9364866	0.1978946	3265.043
325.95825	0.93479645	0.19880864	3263.1138
326.85913	0.94160271	0.19975989	3265.3716
327.76001	0.94359463	0.20069818	3267.6902
328.66089	0.94482434	0.2016639	3271.2739
329.56177	0.95032728	0.20269799	3273.0713
330.46265	0.95200568	0.20369849	3270.2383
331.36353	0.95545745	0.20487045	3277.4546
332.2644	0.95579225	0.20571509	3274.6069
333.16528	0.95751309	0.20672365	3266.2029
334.06616	0.96259862	0.20747186	3274.6306
334.96704	0.96581352	0.20834728	3279.2683
335.86792	0.97056329	0.20937136	3284.676
336.7688	0.97148877	0.21038541	3278.7437
337.66968	0.97262406	0.21140802	3287.7473
338.57056	0.97596228	0.21236287	3285.8796
339.47144	0.97555721	0.21309508	3281.4146
340.37231	0.98518127	0.21401198	3292.0688
341.27319	0.98334426	0.21497539	3288.9148
342.17407	0.98694146	0.21584687	3288.8835
343.07495	0.99068213	0.21688277	3289.6025
343.97583	0.99091649	0.217876	3292.1599
344.87671	0.99527717	0.21892147	3298.5747
345.77759	0.99832261	0.21988666	3296.8828
346.67847	1.0012293	0.22076665	3299.9849
347.57935	1.005192	0.22184964	3301.6567
348.48022	1.0060061	0.22268057	3296.1533
349.3811	1.0099109	0.22347872	3300.3906
350.28198	1.0123469	0.22455917	3313.1904
351.18286	1.0117729	0.22564051	3305.2502
352.08374	1.0168083	0.22663507	3303.9846
352.98462	1.0174072	0.22759919	3303.7456
353.8855	1.0223819	0.22870544	3310.4976
354.78638	1.0255599	0.22964621	3309.7585
355.68726	1.0266954	0.23038292	3305.5474
356.58813	1.0293978	0.23118064	3307.4443
357.48901	1.0310235	0.23210232	3315.0483
358.38989	1.0367304	0.23325734	3318.4297
359.29077	1.0362166	0.23424532	3313.4124
360.19165	1.0431131	0.23528618	3320.6387
361.09253	1.0441699	0.23641996	3320.144
361.99341	1.044515	0.2374105	3315.7805
362.89429	1.0511327	0.23841333	3327.8108
363.79517	1.0524759	0.23940067	3328.0063
364.69604	1.0535412	0.24050921	3323.9055
365.59692	1.0575145	0.24149805	3322.2737
366.4978	1.0601951	0.24246094	3327.3328
367.39868	1.0623976	0.24328281	3322.1467
368.29956	1.0670995	0.24406107	3329.4622
369.20044	1.0671711	0.24512884	3331.2834
370.10132	1.0683464	0.24589637	3327.3386
371.0022	1.071744	0.24668689	3330.5066
371.90308	1.0768749	0.24757573	3335.5681
372.80396	1.0778135	0.24839889	3335.7009
373.70483	1.0814499	0.24962211	3339.1343
374.60571	1.0866827	0.25054824	3336.2512
375.50659	1.0854888	0.25132707	3338.6062
376.40747	1.0893039	0.2524386	3340.9138
377.30835	1.0953177	0.25360185	3348.283
378.20923	1.0941232	0.2546562	3339.8789
379.11011	1.0980048	0.2556234	3347.3542
380.01099	1.0983484	0.25638327	3345.5479
380.91187	1.1038532	0.25725293	3346.6658
381.81274	1.1051295	0.25825748	3355.2908
382.71362	1.1114564	0.25934991	3354.1296
383.6145	1.1154124	0.26042113	3353.8887
384.51538	1.1152077	0.26135311	3355.4006
385.41626	1.1176267	0.2623587	3356.0544
386.31714	1.1237388	0.26328647	3357.6973
387.21802	1.1247053	0.26411816	3360.2258
388.1189	1.1224419	0.26493955	3348.0806
389.01978	1.1242193	0.2658295	3354.6152
389.92065	1.1289899	0.26684552	3359.0957
390.82153	1.1330402	0.26776749	3360.196
391.72241	1.1354123	0.2687971	3360.9822
392.62329	1.1366849	0.2696107	3357.0405
393.52417	1.1399449	0.27054489	3361.3696
394.42505	1.1449239	0.27145144	3369.5708
395.32593	1.1440411	0.27251935	3368.3313
396.22681	1.1506788	0.27357635	3376.2375
397.12769	1.1515428	0.27461863	3374.0522
398.02856	1.1548901	0.27554655	3370.0964
398.92944	1.1592767	0.2763654	3364.5425
399.83032	1.1591655	0.27741507	3375.7144
400.7312	1.1640333	0.2784808	3374.0266
401.63208	1.1640157	0.27959293	3380.4946
402.53296	1.1696177	0.28037998	3374.7485
403.43384	1.1733977	0.28130791	3380.7759
404.33472	1.1707803	0.2823565	3381.6704
405.2356	1.1782519	0.28326064	3383.8655
406.13647	1.1782606	0.28394595	3372.9109
407.03735	1.1811792	0.28494087	3384.4917
407.93823	1.1820452	0.28614295	3384.3354
408.83911	1.1863503	0.2871283	3384.262
409.73999	1.1890622	0.28805745	3385.6274
410.64087	1.1953954	0.28916281	3392.2732
411.54175	1.1930053	0.29006973	3387.7371
412.44263	1.197203	0.29093829	3378.1995
413.34351	1.2028543	0.29179028	3387.0745
414.24438	1.2031	0.29270959	3389.8696
415.14526	1.2091997	0.29368418	3390.9453
416.04614	1.209142	0.29447496	3394.6848
416.94702	1.2115375	0.29552966	3397.2571
417.8479	1.2155612	0.29653609	3399.5061
418.74878	1.2203302	0.29740992	3401.5884
419.64966	1.2188615	0.29817146	3396.1897
420.55054	1.2230619	0.2990616	3388.0925
421.45142	1.2250777	0.29993317	3402.8372
422.35229	1.230108	0.30094877	3407.4888
423.25317	1.2307667	0.30205905	3402.6465
424.15405	1.2335495	0.30295312	3402.835
425.05493	1.2373095	0.3039324	3405.696
425.95581	1.2388297	0.30487442	3404.614
426.85669	1.2429479	0.30575562	3406.8613
427.75757	1.2463443	0.30675781	3407.8701
428.65845	1.2456259	0.30752122	3401.5845
429.55933	1.248626	0.3083975	3406.7454
430.46021	1.2546908	0.30929589	3413.5955
431.36108	1.2563245	0.31039098	3418.8625
432.26196	1.2582494	0.311362	3408.8076
433.16284	1.2606186	0.31229928	3417.5952
434.06372	1.263662	0.31323698	3412.8521
434.9646	1.2662921	0.31408304	3413.1985
435.86548	1.26844	0.31519064	3424.5266
436.76636	1.2718655	0.31625193	3422.2534
437.66724	1.2764169	0.31715074	3420.804
438.56812	1.275507	0.31826133	3418.4666
439.46899	1.2780329	0.31941453	3427.8523
440.36987	1.2782558	0.32035685	3421.0269
441.27075	1.2837236	0.32138282	3427.7651
442.17163	1.284994	0.32240504	3423.6646
443.07251	1.2894868	0.32338867	3426.821
443.97339	1.2925199	0.32427147	3426.821
444.87427	1.2955912	0.32538837	3430.1079
445.77515	1.299104	0.32621142	3430.6633
446.67603	1.3018851	0.32717025	3432.8081
447.5769	1.3059322	0.32810977	3434.105
448.47778	1.3046846	0.32914868	3433.3191
449.37866	1.3079237	0.33001232	3434.2578
450.27954	1.30995	0.33103222	3436.6982
451.18042	1.3133723	0.33205178	3436.8689
452.0813	1.3169217	0.33285716	3432.9622
452.98218	1.3192215	0.33393252	3443.5286
453.88306	1.320346	0.3348434	3435.8044
454.78394	1.3250496	0.33566335	3433.7017
455.68481	1.3275149	0.33641478	3433.5405
456.58569	1.3295767	0.3372795	3442.2319
457.48657	1.3346647	0.3384541	3456.3516
458.38745	1.3331413	0.33938226	3443.9692
459.28833	1.3423223	0.34058237	3447.9438
460.18921	1.3431629	0.34145901	3445.8945
461.09009	1.3422474	0.34223038	3441.1355
461.99097	1.3437097	0.34316167	3447.5745
462.89185	1.347146	0.34414762	3447.0361
463.79272	1.3516024	0.34508511	3446.522
464.6936	1.3554084	0.34613645	3460.752
465.59448	1.3576001	0.34726727	3456.0334
466.49536	1.35788	0.34815401	3451.0288
467.39624	1.3594501	0.34930685	3456.1035
468.29712	1.3647251	0.35020521	3450.6414
469.198	1.3682535	0.35108018	3452.1853
470.09888	1.3702461	0.35187522	3455.6392
470.99976	1.3724656	0.35282272	3459.5967
471.90063	1.374885	0.35380605	3457.989
472.80151	1.3803589	0.35488552	3466.8145
473.70239	1.3832084	0.35595968	3464.1162
474.60327	1.3847387	0.35725918	3468.4495
475.50415	1.3867364	0.35823423	3468.043
476.40503	1.3901784	0.3592495	3462.9158
477.30591	1.3946247	0.36009532	3464.4336
478.20679	1.3953354	0.361101	3469.874
479.10767	1.3985279	0.36201543	3465.5317
480.00854	1.3991761	0.36304426	3473.3462
480.90942	1.4011068	0.36419418	3468.3547
481.8103	1.4064077	0.36508974	3469.9614
482.71118	1.4081596	0.36605111	3472.3552
483.61206	1.4152259	0.36695129	3472.5972
484.51294	1.4157399	0.36791047	3472.832
485.41382	1.4144137	0.3688466	3473.2942
486.3147	1.4177501	0.36983183	3470.9216
487.21558	1.4220519	0.37077934	3479.0725
488.11646	1.4256217	0.37172332	3476.1804
489.01733	1.4300438	0.3726418	3482.887
489.91821	1.4310988	0.37351632	3479.5703
490.81909	1.4325914	0.37439367	3480.9436
491.71997	1.4363518	0.37542754	3483.3501
492.62085	1.4360998	0.37638694	3484.2021
493.52173	1.4421484	0.37738544	3486.6545
494.42261	1.4471291	0.37836316	3484.6775
495.32349	1.4459664	0.37923154	3482.7974
496.22437	1.4503516	0.38020381	3484.3755
497.12524	1.4494154	0.38115606	3486.0642
498.02612	1.4565597	0.38208699	3491.3845
498.927	1.4583373	0.38302827	3490.8813
499.82788	1.4588069	0.38410082	3491.7866
500.72876	1.4611992	0.38497484	3493.4336
501.62964	1.4661373	0.38605779	3498.9299
502.53052	1.4708183	0.38715297	3493.593
503.4314	1.4728158	0.38810942	3493.1101
504.33228	1.473222	0.38908115	3495.999
505.23315	1.4764205	0.39003536	3494.2673
506.13403	1.4792606	0.3909961	3496.3979
507.03491	1.4827297	0.39217383	3499.5471
507.93579	1.4855201	0.39319947	3500.4226
508.83667	1.4880594	0.39431211	3503.5063
509.73755	1.4916748	0.39544511	3502.6558
510.63843	1.4916991	0.39660233	3506.927
511.53931	1.4971002	0.39729485	3493.5464
512.44019	1.4953805	0.39823881	3498.1248
513.34106	1.4994744	0.39903259	3498.3201
514.24194	1.5037171	0.40008399	3503.8325
515.14282	1.5058428	0.40108538	3501.7068
516.0437	1.510264	0.40222803	3508.3799
516.94458	1.5136775	0.40330094	3506.7666
517.84546	1.5125135	0.40411299	3502.5369
518.74634	1.5164933	0.40515187	3513.4124
519.64722	1.5186396	0.40605399	3506.8354
520.5481	1.5232255	0.40707245	3512.1724
521.44897	1.5234325	0.40797505	3511.9812
522.34985	1.5259922	0.40892693	3510.2451
523.25073	1.5299114	0.40974104	3512.0125
524.15161	1.5343877	0.41074345	3515.6709
525.05249	1.5384449	0.41174331	3518.4456
525.95337	1.5394275	0.41275755	3521.459
526.85425	1.5428141	0.41385797	3522.4092
527.75513	1.5447456	0.41480264	3516.8486
528.65601	1.5471494	0.41579488	3519.0215
529.55688	1.5496256	0.41678306	3519.2581
530.45776	1.5540953	0.41778144	3515.7642
531.35864	1.553709	0.41885191	3522.7712
532.25952	1.5592197	0.42011681	3526.7456
533.1604	1.5581148	0.42132136	3520.5459
534.06128	1.5623058	0.42227355	3525.7832
534.96216	1.5680677	0.42319673	3524.4424
535.86304	1.5664676	0.42422584	3527.8262
536.76392	1.5710524	0.42523399	3525.4111
537.66479	1.5702362	0.42607108	3518.3108
538.56567	1.5754791	0.42716429	3528.1035
539.46655	1.5790259	0.42827964	3529.2139
540.36743	1.5791714	0.42938703	3536.0149
541.26831	1.5843358	0.4304218	3529.3025
542.16919	1.5861918	0.43133777	3527.9338
543.07007	1.5906113	0.43243909	3537.5
543.97095	1.5940293	0.43351966	3529.5476
544.87183	1.5976129	0.43439245	3532.5229
545.77271	1.597788	0.43526521	3532.7881
546.67358	1.6018621	0.43640107	3542.458
547.57446	1.6035447	0.43750131	3539.5686
548.47534	1.607035	0.43862137	3537.8145
549.37622	1.6099139	0.4395974	3539.7949
550.2771	1.6100796	0.44057983	3538.1238
551.17798	1.615968	0.44145268	3544.4739
552.07886	1.6213558	0.44263989	3549.2227
552.97974	1.6194099	0.44368121	3544.0291
553.88062	1.6204233	0.44470528	3539.8472
554.78149	1.6250321	0.44562039	3537.9019
555.68237	1.63115	0.44665024	3546.6145
556.58325	1.6308849	0.44760272	3541.8188
557.48413	1.63317	0.44860047	3541.916
558.38501	1.6348003	0.44982687	3550.7046
559.28589	1.6386268	0.45069149	3536.1765
560.18677	1.6426215	0.45160583	3539.27
561.08765	1.6442442	0.45264971	3547.8972
561.98853	1.6499143	0.45349485	3550.6899
562.8894	1.6501788	0.45446664	3549.3064
563.79028	1.6510419	0.45547289	3556.0081
564.69116	1.6547914	0.45652047	3550.0725
565.59204	1.6557108	0.45743504	3548.8086
566.49292	1.6577473	0.45849788	3551.4551
567.3938	1.6628498	0.45953029	3553.9351
568.29468	1.6650617	0.46067649	3556.4434
569.19556	1.6666994	0.46171626	3550.1589
570.09644	1.669266	0.46282443	3557.9404
570.99731	1.6708241	0.46383277	3550.5315
571.89819	1.6731763	0.46489528	3556.8833
572.79907	1.6784301	0.46587026	3558.0698
573.69995	1.6833481	0.46700746	3564.2708
574.60083	1.683992	0.46799302	3559.3938
575.50171	1.6849604	0.46887803	3558.2292
576.40259	1.6924269	0.46981019	3558.9241
577.30347	1.6899931	0.47086957	3561.1401
578.20435	1.6942183	0.47204179	3565.0679
579.10522	1.6980411	0.47325528	3565.0986
580.0061	1.7008673	0.47464696	3565.3123
580.90698	1.7007705	0.47570825	3561.251
581.80786	1.7064584	0.47686452	3560.7542
582.70874	1.7090925	0.47777614	3565.4224
583.60962	1.711738	0.47889999	3571.3982
584.5105	1.7148618	0.47971815	3564.03
585.41138	1.7180109	0.48052454	3561.3225
586.31226	1.7187694	0.48148999	3572.5552
587.21313	1.7221723	0.48272565	3569.1223
588.11401	1.7216991	0.483785	3571.051
589.01489	1.7289954	0.48493177	3569.21
589.91577	1.7299206	0.48593968	3567.8738
590.81665	1.7310603	0.48712155	3569.8787
591.71753	1.7370555	0.48813105	3574.4385
592.61841	1.7385467	0.48904213	3571.2129
593.51929	1.7418501	0.49023899	3578.7607
594.42017	1.7433861	0.4913404	3576.6023
595.32104	1.7454703	0.49236098	3573.8442
596.22192	1.7489969	0.49345911	3577.5945
597.1228	1.7522292	0.49455395	3576.1653
598.02368	1.7545521	0.49558228	3579.1626
598.92456	1.7559617	0.49658975	3575.5837
599.82544	1.7574489	0.49768716	3575.9089
600.72632	1.7616895	0.4986501	3576.241
601.6272	1.7663571	0.49979982	3580.791
602.52808	1.7668725	0.50072902	3577.7871
603.42896	1.7705671	0.50183302	3583.1821
604.32983	1.7736497	0.50303322	3584.7017
605.23071	1.7799606	0.50411201	3586.1069
606.13159	1.7806462	0.50535542	3587.7617
607.03247	1.7807883	0.50630218	3580.5325
607.93335	1.7873641	0.50739437	3593.2969
608.83423	1.7858196	0.50847548	3585.2334
609.73511	1.7897799	0.5096401	3585.7085
610.63599	1.7928526	0.51093882	3586.8003
611.53687	1.7924436	0.51202023	3584.5388
612.43774	1.7981453	0.51300299	3587.6052
613.33862	1.8000616	0.51401931	3584.314
614.2395	1.8025419	0.51512891	3591.9536
615.14038	1.8076714	0.51651847	3600.5793
616.04126	1.807375	0.51762009	3594.3972
616.94214	1.8132101	0.51886362	3593.6958
617.84302	1.8139769	0.5200339	3592.4033
618.7439	1.8167546	0.52102572	3591.7698
619.64478	1.8224908	0.52207166	3591.6008
620.54565	1.8219521	0.52303511	3594.3865
621.44653	1.827302	0.52415258	3596.2581
622.34741	1.8286617	0.52527779	3598.8862
623.24829	1.8311889	0.52632517	3596.7388
624.14917	1.8347019	0.52744496	3594.8413
625.05005	1.8353438	0.52840221	3596.9902
625.95093	1.8387079	0.5297175	3604.8613
626.85181	1.8402593	0.53088105	3602.4285
627.75269	1.8432696	0.53189117	3597.2573
628.65356	1.8465064	0.53322113	3603.178
629.55444	1.8507588	0.53432691	3603.115
630.45532	1.8528993	0.53544283	3604.804
631.3562	1.8542815	0.53658968	3599.0598
632.25708	1.8576218	0.53763258	3602.657
633.15796	1.8579274	0.53860563	3602.1138
634.05884	1.8625557	0.53969079	3601.1528
634.95972	1.8643233	0.5406211	3594.5437
635.8606	1.867449	0.54159957	3600.8125
636.76147	1.8702848	0.54275817	3606.6172
637.66235	1.8726826	0.54381931	3603.7129
638.56323	1.8756995	0.54498076	3607.488
639.46411	1.8815469	0.54614079	3606.7771
640.36499	1.880841	0.54713893	3601.9639
641.26587	1.8845825	0.54832298	3606.5825
642.16675	1.8866638	0.54953814	3612.9331
643.06763	1.8892694	0.55066764	3608.136
643.96851	1.8909388	0.55177456	3607.4448
644.86938	1.8950518	0.55288428	3608.1794
645.77026	1.8995476	0.55402625	3611.6392
646.67114	1.9017841	0.55523121	3617.3689
647.57202	1.9020337	0.55632746	3615.3191
648.4729	1.9055917	0.55758333	3616.4702
649.37378	1.9115098	0.5589065	3617.7349
650.27466	1.9118056	0.5602476	3617.7351
651.17554	1.9146892	0.56150246	3618.3462
652.07642	1.9209738	0.56288052	3623.9812
652.97729	1.920193	0.5639506	3612.4839
653.87817	1.9242805	0.56496173	3611.6277
654.77905	1.9212266	0.56621897	3612.9253
655.67993	1.926474	0.56726283	3612.5977
656.58081	1.9316323	0.56839985	3618.8684
657.48169	1.9319829	0.56962335	3618.8701
658.38257	1.9381319	0.5707671	3622.2197
659.28345	1.940291	0.57200092	3619.9927
660.18433	1.943134	0.57343972	3623.8503
661.08521	1.942525	0.57466871	3613.2561
661.98608	1.945879	0.57585895	3620.4778
662.88696	1.9497635	0.57689774	3617.114
663.78784	1.9541556	0.57796675	3615.4941
664.68872	1.9546826	0.57884699	3619.3923
665.5896	1.9568884	0.57992458	3620.0825
666.49048	1.9595276	0.5809195	3614.4546
667.39136	1.9588691	0.58225185	3627.4653
668.29224	1.9636861	0.58352083	3622.2046
669.19312	1.9666787	0.58479327	3622.8928
670.09399	1.9710261	0.58578813	3619.3374
670.99487	1.976473	0.58701485	3623.6721
671.89575	1.9766549	0.58801585	3624.8818
672.79663	1.9794955	0.58914518	3623.8552
673.69751	1.9822676	0.59039742	3628.0798
674.59839	1.9840418	0.59155738	3631.5852
675.49927	1.9881719	0.59276986	3624.0996
676.40015	1.9917368	0.59394795	3630.9626
677.30103	1.9959527	0.59501255	3627.4414
678.2019	1.9941428	0.59625661	3629.7563
679.10278	1.9976289	0.59734887	3628.8767
680.00366	2.0012226	0.59850985	3631.3574
680.90454	2.0024989	0.59987873	3634.8196
681.80542	2.0073602	0.60116792	3631.75
682.7063	2.0071132	0.60259837	3633.5962
683.60718	2.0132096	0.60368085	3624.52
684.50806	2.0129864	0.60485327	3633.9827
685.40894	2.0172429	0.60617369	3638.1833
686.30981	2.0186479	0.60747963	3633.1838
687.21069	2.0198629	0.60879087	3635.1328
688.11157	2.0253611	0.61017269	3632.3281
689.01245	2.0268397	0.6112693	3628.2898
689.91333	2.0286622	0.61259693	3634.7627
690.81421	2.0311837	0.61373961	3630.5015
691.71509	2.0364945	0.61494571	3633.6416
692.61597	2.0374317	0.61626023	3633.3992
693.51685	2.0422564	0.61754167	3637.689
694.41772	2.044735	0.61903369	3640.9834
695.3186	2.0467193	0.62035573	3638.7693
696.21948	2.0518141	0.62148041	3633.8865
697.12036	2.0511012	0.62264705	3637.1396
698.02124	2.0541918	0.62390226	3637.9778
698.92212	2.0571897	0.62524056	3645.7588
699.823	2.0600693	0.62659782	3640.73
700.72388	2.0632985	0.62778425	3637.6052
701.62476	2.0656471	0.62901455	3640.8787
702.52563	2.0689168	0.6300534	3641.5107
703.42651	2.0683393	0.63135046	3635.0908
704.32739	2.076998	0.63228542	3634.5349
705.22827	2.074584	0.63322753	3627.1826
706.12915	2.0789752	0.63420868	3641.2271
707.03003	2.0813634	0.63532329	3637.4163
707.93091	2.0825663	0.63644832	3634.2278
708.83179	2.088706	0.6377188	3642.5659
709.73267	2.0887465	0.63877428	3639.8821
710.63354	2.0920923	0.64000636	3642.4072
711.53442	2.0963833	0.64138579	3644.333
712.4353	2.0962915	0.6426723	3643.2493
713.33618	2.100805	0.64414686	3646.8906
714.23706	2.1052692	0.64561516	3649.865
715.13794	2.1058612	0.6469534	3644.3245
716.03882	2.1091545	0.64826804	3645.6545
716.9397	2.1123347	0.64954638	3639.0137
717.84058	2.1116457	0.65089601	3648.4036
718.74146	2.1173697	0.65234244	3650.856
719.64233	2.1172311	0.65355182	3646.4558
720.54321	2.1224627	0.65480691	3644.864
721.44409	2.1260819	0.65592039	3640.3091
722.34497	2.1299863	0.65727925	3652.1406
723.24585	2.1306264	0.65845478	3647.7065
724.14673	2.1345739	0.6596294	3651.4211
725.04761	2.1362567	0.6607936	3645.5305
725.94849	2.1403224	0.66205388	3649.834
726.84937	2.1406071	0.66338247	3651.6306
727.75024	2.1425331	0.66490161	3656.2732
728.65112	2.1490383	0.6664722	3652.2866
729.552	2.1512723	0.66765356	3650.9224
730.45288	2.1509435	0.66937995	3652.3269
731.35376	2.1532974	0.67075092	3647.3618
732.25464	2.1587226	0.67223001	3652.7852
733.15552	2.1604147	0.67361957	3648.6943
734.0564	2.1623592	0.67503822	3644.1226
734.95728	2.1668952	0.67643178	3654.1462
735.85815	2.1650288	0.6773926	3645.1594
736.75903	2.1699529	0.67883486	3650.7666
737.65991	2.1773217	0.68025261	3656.8162
738.56079	2.1776412	0.68156272	3653.0591
739.46167	2.17804	0.68271947	3650.7297
740.36255	2.1856444	0.68386233	3651.7209
741.26343	2.1846268	0.68485957	3647.6755
742.16431	2.1892495	0.68614376	3655.5354
743.06519	2.190567	0.68755978	3656.3547
743.96606	2.1923094	0.68903357	3656.4744
744.86694	2.1956508	0.69042808	3652.1147
745.76782	2.1962976	0.69182605	3655.9338
746.6687	2.2023869	0.69338483	3660.938
747.56958	2.2047906	0.69474232	3654.739
748.47046	2.2087131	0.69588721	3650.6799
749.37134	2.2102048	0.6972363	3659.8057
750.27222	2.2107487	0.69876313	3654.9265
751.1731	2.2129633	0.70039737	3658.8091
752.07397	2.2164931	0.70187652	3655.1907
752.97485	2.2195907	0.70341152	3656.5627
753.87573	2.2221789	0.70490038	3654.3113
754.77661	2.2244589	0.70616126	3651.4431
755.67749	2.2270379	0.70732456	3653.5186
756.57837	2.2327504	0.70837402	3657.552
757.47925	2.2310479	0.70966482	3657.2104
758.38013	2.2324142	0.71132386	3662.7446
759.28101	2.2368727	0.71336126	3661.2854
760.18188	2.2403073	0.71501064	3658.5022
761.08276	2.2459307	0.71624762	3649.4075
761.98364	2.2454591	0.7174179	3653.0469
762.88452	2.2518995	0.71890342	3663.0808
763.7854	2.2503538	0.7206102	3662.9104
764.68628	2.2540834	0.72207946	3653.8687
765.58716	2.2560961	0.72336954	3655.5652
766.48804	2.2607477	0.72459948	3657.9216
767.38892	2.2641387	0.72582054	3653.8645
768.28979	2.2689774	0.72715527	3661.2905
769.19067	2.268194	0.72827917	3659.6453
770.09155	2.2713966	0.72974885	3658.7993
770.99243	2.2724192	0.73121178	3664.7268
771.89331	2.2754862	0.73280394	3659.8904
772.79419	2.2798934	0.73431182	3661.3413
773.69507	2.2828643	0.7355864	3660.562
774.59595	2.2856977	0.73713499	3660.8152
775.49683	2.2890141	0.73873115	3665.0203
776.39771	2.2907867	0.74013543	3660.4214
777.29858	2.2941213	0.74173105	3662.1855
778.19946	2.2958412	0.74319559	3660.6873
779.10034	2.2969525	0.74462992	3657.5706
780.00122	2.3002024	0.74606937	3658.9265
780.9021	2.3019278	0.74739754	3658.7651
781.80298	2.3034387	0.74888402	3659.7766
782.70386	2.3090277	0.75037962	3660.1094
783.60474	2.3110967	0.7518518	3661.6233
784.50562	2.3156974	0.75376225	3663.5811
785.40649	2.3189898	0.75524396	3661.1379
786.30737	2.318017	0.75688368	3652.8367
787.20825	2.3223794	0.75845855	3660.1619
788.10913	2.3252475	0.75968361	3656.4094
789.01001	2.3287854	0.76095957	3657.4878
789.91089	2.3307798	0.76227522	3659.4563
790.81177	2.334547	0.76370418	3662.3462
791.71265	2.3322041	0.76517975	3657.7336
792.61353	2.339663	0.7666505	3663.709
793.5144	2.341511	0.76816785	3659.4961
794.41528	2.3405864	0.76976931	3661.2307
795.31616	2.345999	0.77153146	3661.9685
796.21704	2.3496697	0.77318805	3661.9153
797.11792	2.3517923	0.77511567	3663.9111
798.0188	2.3533888	0.77671862	3661.4395
798.91968	2.3588955	0.77806479	3658.3296
799.82056	2.3634605	0.7794255	3662.386
800.72144	2.3642588	0.78079051	3660.5291
801.62231	2.3653839	0.78242558	3662.4084
802.52319	2.3675478	0.78420711	3663.5918
803.42407	2.3711634	0.7857666	3660.574
804.32495	2.3739045	0.78751791	3659.6187
805.22583	2.3756626	0.78888434	3655.812
806.12671	2.3797724	0.790263	3658.3706
807.02759	2.3846288	0.79176348	3661.4214
807.92847	2.3865986	0.79347646	3661.9375
808.82935	2.3879681	0.79527617	3660.564
809.73022	2.392529	0.79676485	3659.728
810.6311	2.3907647	0.79808009	3658.9783
811.53198	2.3970406	0.79994971	3667.7883
812.43286	2.3976905	0.80133212	3662.5161
813.33374	2.4001424	0.80301929	3665.2314
814.23462	2.4063079	0.80454481	3662.2903
815.1355	2.4066076	0.80625099	3659.8125
816.03638	2.4045913	0.80806488	3661.2173
816.93726	2.4130762	0.8096891	3659.6731
817.83813	2.4149294	0.81133825	3660.2524
818.73901	2.4186721	0.81294495	3663.6572
819.63989	2.4181991	0.81452692	3658.1104
820.54077	2.4209263	0.81627035	3657.3911
821.44165	2.4269974	0.81793976	3660.9509
822.34253	2.4252348	0.81968302	3663.5725
823.24341	2.4288776	0.821603	3661.2349
824.14429	2.430675	0.82346123	3659.676
825.04517	2.4385028	0.82518399	3655.8406
825.94604	2.4385707	0.8267777	3655.2593
826.84692	2.441308	0.82852501	3661.1631
827.7478	2.4433064	0.83032888	3665.4009
828.64868	2.4458148	0.83230835	3662.2466
829.54956	2.4486911	0.83432966	3662.1702
830.45044	2.4496353	0.83630776	3663.9822
831.35132	2.4537053	0.83805245	3657.5913
832.2522	2.4544153	0.83981287	3657.8899
833.15308	2.4604609	0.84151644	3654.2529
834.05396	2.4601645	0.84337103	3658.6855
834.95483	2.4640822	0.84515995	3652.4734
835.85571	2.4670367	0.84704024	3654.73
836.75659	2.4729512	0.84901071	3660.7244
837.65747	2.4730654	0.85065007	3654.3474
838.55835	2.4768345	0.85249633	3657.6985
839.45923	2.4778903	0.85416806	3656.6575
840.36011	2.481215	0.85621637	3662.5417
841.26099	2.4858048	0.85826868	3662.5061
842.16187	2.4843826	0.86013937	3652.6458
843.06274	2.4922652	0.8619312	3659.8159
843.96362	2.493659	0.86360496	3648.5527
844.8645	2.4975314	0.86517113	3653.0942
845.76538	2.4969306	0.86687315	3651.4902
846.66626	2.502368	0.86822397	3653.1316
847.56714	2.5040765	0.86968631	3644.8926
848.46802	2.5061076	0.87108243	3650.7017
849.3689	2.5089877	0.8728177	3661.6362
850.26978	2.5148687	0.87479907	3659.0967
851.17065	2.5111115	0.87666923	3653.665
852.07153	2.5161428	0.8782981	3648.0701
852.97241	2.5204508	0.88008481	3650.8347
853.87329	2.5244141	0.88179696	3654.3735
854.77417	2.5249002	0.883533	3650.6228
855.67505	2.5269363	0.88552052	3653.894
856.57593	2.5319469	0.88788682	3655.1682
857.47681	2.5324147	0.88969868	3650.1006
858.37769	2.5380714	0.89167094	3653.1003
859.27856	2.537966	0.89343429	3651.04
860.17944	2.5406215	0.8954711	3645.8938
861.08032	2.5431542	0.89729202	3646.9536
861.9812	2.5446985	0.8993364	3650.9385
862.88208	2.5495775	0.90154564	3647.9302
863.78296	2.5519848	0.90336823	3650.5793
864.68384	2.55514	0.90531862	3649.1721
865.58472	2.5579083	0.90752488	3648.1587
866.4856	2.5598576	0.90959078	3649.7158
867.38647	2.5660069	0.91176826	3650.24
868.28735	2.5658209	0.91379273	3643.9077
869.18823	2.5669088	0.91592187	3642.7913
870.08911	2.5686889	0.91784424	3642.7666
870.98999	2.5738306	0.9198758	3647.8577
871.89087	2.5768523	0.92208022	3643.0654
872.79175	2.5794508	0.92410165	3643.0293
873.69263	2.5807934	0.92626214	3641.9023
874.59351	2.5849812	0.92836833	3638.5103
875.49438	2.5842881	0.93048066	3640.1553
876.39526	2.5889108	0.93252504	3640.9292
877.29614	2.5931933	0.93441933	3634.9104
878.19702	2.5932803	0.93635702	3635.1304
879.0979	2.5959852	0.93829191	3637.8516
879.99878	2.6000319	0.94034243	3637.7397
880.89966	2.5997541	0.94254088	3638.3616
881.80054	2.6075296	0.9447313	3641.1111
882.70142	2.6099246	0.94677919	3631.5979
883.60229	2.613714	0.94883317	3632.928
884.50317	2.6139865	0.95076853	3631.3103
885.40405	2.6151462	0.95262146	3636.2751
886.30493	2.6182611	0.95465797	3636.8076
887.20581	2.6232462	0.95684522	3638.0913
888.10669	2.625222	0.9586333	3628.2969
889.00757	2.6257606	0.96073657	3626.0496
889.90845	2.6297688	0.96254116	3628.3162
890.80933	2.6342869	0.96480614	3631.3362
891.71021	2.6363702	0.96753466	3633.7593
892.61108	2.6364415	0.96992093	3625.7429
893.51196	2.6421516	0.97207218	3624.9097
894.41284	2.6422472	0.9738645	3621.0725
895.31372	2.6446187	0.97563672	3617.252
896.2146	2.6513903	0.97780263	3626.4326
897.11548	2.6505349	0.9797942	3624.1421
898.01636	2.6598918	0.98189634	3619.4421
898.91724	2.6572263	0.98381919	3625.0405
899.81812	2.6594906	0.98634279	3620.1594
900.71899	2.663981	0.98879993	3620.3311
901.61987	2.665283	0.99093348	3612.0076
902.52075	2.6692247	0.99307245	3613.9121
903.42163	2.6685882	0.99556983	3620.3945
904.32251	2.6719253	0.99852836	3618.4651
905.22339	2.675983	1.0010732	3606.6924
906.12427	2.6806514	1.0031806	3611.895
907.02515	2.6806164	1.0055487	3610.0127
907.92603	2.6899226	1.0076618	3606.5486
908.8269	2.6874652	1.0101526	3605.6299
909.72778	2.6882844	1.0124559	3605.6855
910.62866	2.694175	1.0146962	3606.3149
911.52954	2.6963542	1.0165906	3605.0752
912.43042	2.6950202	1.0183887	3598.7617
913.3313	2.7000601	1.0205593	3601.3225
914.23218	2.7021036	1.0227664	3596.4915
915.13306	2.7076676	1.0253973	3607.9834
916.03394	2.7112789	1.027517	3591.6189
916.93481	2.7114155	1.0296335	3591.9824
917.83569	2.7173028	1.031601	3587.1694
918.73657	2.7164142	1.0336367	3589.7646
919.63745	2.7191186	1.0359507	3593.4028
920.53833	2.7220719	1.0385486	3595.0552
921.43921	2.7249939	1.0408489	3584.3342
922.34009	2.7287772	1.0430471	3584.1331
923.24097	2.7322316	1.0450056	3583.6472
924.14185	2.7329738	1.0471551	3581.4524
925.04272	2.735888	1.0495206	3581.8726
925.9436	2.7387364	1.0520236	3581.5737
926.84448	2.7449722	1.0546763	3583.5081
927.74536	2.7460747	1.0573658	3575.8467
928.64624	2.7495692	1.0595037	3573.7849
929.54712	2.7511053	1.0614886	3572.2971
930.448	2.7522395	1.0640383	3570.1123
931.34888	2.7555125	1.0666158	3568.894
932.24976	2.7565329	1.0689903	3564.0205
933.15063	2.7626114	1.0715007	3569.197
934.05151	2.7604542	1.0741458	3555.8027
934.95239	2.7661033	1.0761727	3555.7881
935.85327	2.7691288	1.0784148	3559.2202
936.75415	2.7700331	1.0808754	3552.1052
937.65503	2.7748096	1.0828136	3552.5308
938.55591	2.7764549	1.0853126	3561.7319
939.45679	2.7779434	1.0882441	3551.9761
940.35767	2.7817488	1.0908933	3548.1196
941.25854	2.784704	1.0935537	3551.1218
942.15942	2.7868018	1.0962354	3544.1035
943.0603	2.7904148	1.0988758	3543.853
943.96118	2.7946577	1.1014764	3541.0991
944.86206	2.7923315	1.1037054	3536.3032
945.76294	2.7962592	1.1059135	3533.1482
946.66382	2.8002164	1.1081134	3527.478
947.5647	2.8049583	1.1104606	3531.4397
948.46558	2.8053436	1.1126668	3527.7742
949.36646	2.8113563	1.1154566	3530.2573
950.26733	2.8133721	1.1183045	3525.9868
951.16821	2.8137579	1.1207443	3518.5352
952.06909	2.817136	1.1236423	3517.344
952.96997	2.820832	1.1261277	3515.5188
953.87085	2.8216395	1.1281317	3505.0735
954.77173	2.8240538	1.1305844	3508.3064
955.67261	2.8294139	1.132967	3508.4341
956.57349	2.8298249	1.1352181	3502.0967
957.47437	2.8300569	1.137356	3504.2661
958.37524	2.8360803	1.1403227	3497.823
959.27612	2.838629	1.1430343	3495.3538
960.177	2.8424346	1.1457397	3498.7268
961.07788	2.8433001	1.1482091	3490.0073
961.97876	2.8502452	1.1506793	3492.1636
962.87964	2.8511171	1.1530334	3488.582
963.78052	2.8535349	1.1552994	3486.0518
964.6814	2.8571489	1.158034	3482.842
965.58228	2.857821	1.1608135	3478.0583
966.48315	2.8565972	1.1629035	3469.5833
967.38403	2.862808	1.1653314	3468.395
968.28491	2.8675337	1.1675168	3472.4282
969.18579	2.8694255	1.170084	3469.5161
970.08667	2.8687611	1.1727667	3467.4937
970.98755	2.874126	1.175896	3460.2866
971.88843	2.8764322	1.1787108	3459.5889
972.78931	2.8792791	1.1815922	3457.6929
973.69019	2.8847978	1.1845109	3454.8386
974.59106	2.8869288	1.1871063	3445.2095
975.49194	2.8881857	1.1895417	3444.5198
976.39282	2.8891544	1.1922379	3443.9849
977.2937	2.8908703	1.1949142	3430.5129
978.19458	2.8937924	1.1971827	3426.9512
979.09546	2.8989379	1.1996927	3438.0964
979.99634	2.9015739	1.2025539	3425.678
980.89722	2.901195	1.2045653	3417.8418
981.7981	2.9078178	1.2066952	3420.9297
982.69897	2.9076281	1.2094214	3421.9756
983.59985	2.9118507	1.211795	3413.1113
984.50073	2.9125743	1.2143705	3412.7708
985.40161	2.9148519	1.2176241	3410.2625
986.30249	2.9201758	1.2205434	3407.6624
987.20337	2.9227238	1.2231997	3405.7759
988.10425	2.9235189	1.22572	3399.5588
989.00513	2.9275258	1.2280923	3392.1079
989.90601	2.9291179	1.2307259	3393.2007
990.80688	2.9336686	1.2336434	3389.4038
991.70776	2.9369664	1.236912	3387.6621
992.60864	2.9400737	1.2395178	3379.1731
993.50952	2.9439752	1.2420714	3380.3413
994.4104	2.9454079	1.2448312	3377.8865
995.31128	2.9509802	1.2474387	3366.2368
996.21216	2.9511678	1.2498822	3365.7786
997.11304	2.9511335	1.2527485	3363.8323
998.01392	2.9571435	1.2559161	3369.563
998.91479	2.9578588	1.2589594	3354.9995
999.81567	2.9570632	1.2618072	3341.2114
1000.7166	2.9612253	1.2642695	3338.7881
1001.6174	2.9689863	1.266698	3345.9805
1002.5183	2.9673791	1.2689792	3331.9976
1003.4192	2.9683704	1.2704519	3326.4126
1004.3201	2.9730759	1.2723001	3327.5535
1005.2209	2.9771643	1.2744974	3331.6003
1006.1218	2.9778891	1.2768586	3331.5081
1007.0227	2.979553	1.2796956	3319.4087
1007.9236	2.9844649	1.2825752	3322.7256
1008.8245	2.9878767	1.2854662	3317.3579
1009.7253	2.9899876	1.2883338	3309.188
1010.6262	2.9902346	1.2912544	3303.0476
1011.5271	2.9952712	1.2943199	3299.2104
1012.428	2.99915	1.2977445	3299.0308
1013.3289	3.0038433	1.300869	3292.1228
1014.2297	3.002965	1.3041321	3291.2437
1015.1306	3.0075204	1.3068038	3280.3213
1016.0315	3.0072813	1.3101425	3282.5903
1016.9324	3.0130897	1.3134006	3267.7842
1017.8333	3.0129778	1.315818	3259.7656
1018.7341	3.015862	1.3184457	3261.3838
1019.635	3.0230327	1.3216116	3260.533
1020.5359	3.0271065	1.3247987	3253.0059
1021.4368	3.0253203	1.3276502	3244.4922
1022.3376	3.0306251	1.3306313	3246.0112
1023.2385	3.0328491	1.3339751	3237.6257
1024.1394	3.0344865	1.3369758	3232.1826
1025.0403	3.0361042	1.3396676	3221.1567
1025.9412	3.0405233	1.3421112	3221.6934
1026.842	3.0431645	1.3447684	3221.5171
1027.7429	3.0440145	1.3477058	3211.5696
1028.6438	3.0444274	1.3506073	3205.4941
1029.5447	3.0532312	1.3537298	3209.5889
1030.4456	3.0507081	1.3569294	3197.0127
1031.3464	3.0550516	1.3600882	3191.822
1032.2473	3.0612514	1.3629051	3182.373
1033.1482	3.0606294	1.3660202	3184.5083
1034.0491	3.0609221	1.3694535	3174.3093
1034.95	3.0673335	1.3728194	3170.2092
1035.8508	3.0681219	1.3760552	3166.5347
1036.7517	3.0720956	1.3788275	3154.4648
1037.6526	3.0741773	1.3817341	3155.8584
1038.5535	3.0770717	1.3848081	3148.6353
1039.4543	3.0804977	1.3877294	3142.4905
1040.3552	3.0828297	1.3908741	3135.6328
1041.2561	3.0844507	1.3941971	3129.6597
1042.157	3.0878534	1.3974721	3124.6216
1043.0579	3.0909917	1.4004309	3113.8025
1043.9587	3.0918796	1.4036659	3115.5071
1044.8596	3.0959387	1.4067056	3105.0037
1045.7605	3.0977676	1.4099574	3099.5222
1046.6614	3.1031642	1.4133896	3098.4211
1047.5623	3.1028559	1.4165517	3079.4192
1048.4631	3.10779	1.4196585	3084.6187
1049.364	3.106636	1.4231194	3072.6931
1050.2649	3.1125417	1.4269019	3067.9258
1051.1658	3.1120186	1.4302485	3056.3982
1052.0667	3.1185055	1.4335049	3049.7432
1052.9675	3.1230593	1.4361821	3039.9595
1053.8684	3.1224971	1.438947	3040.2612
1054.7693	3.1283009	1.4426817	3032.5466
1055.6702	3.130882	1.4465144	3026.3538
1056.571	3.1301575	1.4503397	3011.4919
1057.4719	3.1322541	1.4538161	3003.3264
1058.3728	3.1380713	1.4572355	3005.4214
1059.2737	3.1401286	1.460588	2986.1167
1060.1746	3.1427836	1.4633842	2985.1064
1061.0754	3.1458859	1.4668441	2975.9873
1061.9763	3.1485479	1.4698454	2971.2993
1062.8772	3.1543126	1.473478	2959.5186
1063.7781	3.1531491	1.4766074	2949.0752
1064.679	3.1556847	1.4797077	2940.8582
1065.5798	3.1565073	1.4824636	2929.4824
1066.4807	3.1605587	1.4857295	2925.8481
1067.3816	3.1640072	1.4895992	2920.1047
1068.2825	3.1695049	1.4933114	2906.3545
1069.1833	3.1678069	1.4974924	2894.8875
1070.0842	3.1738305	1.5017319	2879.7278
1070.9851	3.17413	1.505599	2862.804
1071.886	3.179538	1.5088389	2855.9182
1072.7869	3.1840324	1.512421	2849.781
1073.6877	3.1870351	1.5166271	2826.0955
1074.5886	3.1867976	1.5209284	2815.1123
1075.4895	3.1896589	1.5248562	2796.3389
1076.3904	3.1912594	1.5291518	2777.5884
1077.2913	3.1948225	1.5346487	2749.8577
1077.7917	3.195329	1.5427058	2669.6638