File: datasets/am_bench_2022/raw_data/90-XY.07-2/specimen.dat
MTS793|MPT|ENU|1|2|.|/|:|1|0|0|A

Operator Information						Time:	22.875	Sec	11/2/2021 2:41:36 PM
Operator	Nick Derimow
Project	AM Bench 2022 mini-tensile challenge
Specimen ID	90-XY.07-2
Material	PBF-L Inconel 625
Specimen Width	2.54	mm
Specimen Thickness	1.51	mm
Notes
Operator Information End

Data Acquisition						Time:	986.61987	Sec	11/2/2021 2:57:39 PM
Time	Axial Displacement	Axial Extensometer	Axial Force
Sec	mm	mm	N
22.987793	0.00047030288	6.0978673e-05	58.022675
23.788574	0.0033760665	8.8290639e-05	67.905632
24.589355	0.0028572825	0.00020466666	80.436844
25.390137	0.0063885273	0.00021691504	82.477493
26.190918	0.010397987	0.00038390426	95.130798
26.991699	0.011691669	0.00038821515	105.3488
27.79248	0.013515608	0.00040776894	116.88725
28.593262	0.016395504	0.000472788	124.89772
29.394043	0.01820546	0.00049477688	138.66498
30.194824	0.022034205	0.00057828944	151.23766
30.995605	0.022484146	0.00059462746	162.44737
31.796387	0.027338168	0.00073748769	174.71013
32.597168	0.030246185	0.0007853625	186.78175
33.397949	0.034415409	0.000827151	198.48697
34.19873	0.034594689	0.00090637006	213.02866
34.999512	0.033578072	0.00097181124	225.09613
35.800293	0.03600147	0.0011498103	242.32545
36.601074	0.042596243	0.0011629848	258.63663
37.401855	0.043330573	0.0012482717	273.36273
38.202637	0.047520082	0.0013025667	292.04324
39.003418	0.046653032	0.0014527016	300.41507
39.804199	0.048822369	0.0015466051	320.80396
40.60498	0.055465497	0.0016218442	342.50577
41.405762	0.053912271	0.0016438208	355.60147
42.206543	0.055145867	0.0017446139	373.18347
43.007324	0.057409655	0.001874988	393.09772
43.808105	0.062706649	0.0019926939	412.43808
44.608887	0.063151471	0.0020614951	426.09546
45.409668	0.064961679	0.0021333739	443.69421
46.210449	0.069766529	0.0021984053	459.7728
47.01123	0.071161985	0.0022462965	473.51715
47.812012	0.073449798	0.0023975449	491.97565
48.612793	0.074394502	0.0024034828	514.78741
49.413574	0.078985699	0.0026289253	534.07227
50.214355	0.081998162	0.0027050986	559.25397
51.015137	0.083212756	0.0028076302	576.92688
51.815918	0.084594078	0.0029712284	589.87738
52.616699	0.089320041	0.0030158374	606.51978
53.41748	0.088263623	0.0030824463	626.37915
54.218262	0.092282966	0.0032468857	654.66656
55.019043	0.095530443	0.0033463684	671.80029
55.819824	0.09576463	0.0034544587	695.43665
56.620605	0.09816508	0.0035795148	709.16486
57.421387	0.098322026	0.003618476	728.99786
58.222168	0.10364771	0.0038055107	753.09961
59.022949	0.10851382	0.0039049187	778.35638
59.82373	0.1081069	0.0040563229	802.8902
60.624512	0.11182747	0.0040664896	826.0578
61.425293	0.11362661	0.0042119818	842.07318
62.226074	0.11924795	0.0043067704	870.7171
63.026855	0.11878039	0.0045332015	889.02808
63.827637	0.12044226	0.0046352525	918.21808
64.628418	0.12206659	0.0047020297	934.80463
65.429199	0.12729433	0.0048751398	959.44489
66.22998	0.12769796	0.0049213674	975.11578
67.030762	0.12999494	0.0050165998	1004.4892
67.831543	0.13513643	0.0051324223	1028.8992
68.632324	0.1347539	0.0052927239	1048.8177
69.433105	0.13821466	0.0053703841	1063.0608
70.233887	0.1373263	0.0054155216	1092.332
71.034668	0.14119132	0.0055644219	1108.9772
71.835449	0.14630431	0.0056909001	1132.459
72.63623	0.14734045	0.0058069248	1154.6296
73.437012	0.15023838	0.0058387187	1171.7604
74.237793	0.15333034	0.0060827746	1201.0553
75.038574	0.15303427	0.006222303	1221.1768
75.839355	0.15733303	0.0061773625	1242.2811
76.640137	0.15794279	0.0064052441	1264.6232
77.440918	0.16033715	0.0064861956	1290.8571
78.241699	0.16375385	0.0066049248	1309.1661
79.04248	0.16675156	0.0067083188	1325.4199
79.843262	0.16777848	0.0068693007	1344.6957
80.644043	0.17302015	0.0068374821	1372.7217
81.444824	0.16998859	0.0070532784	1395.8873
82.245605	0.17712264	0.0070950026	1412.7203
83.046387	0.1770038	0.007304484	1445.8857
83.847168	0.17938682	0.0074479668	1468.0331
84.647949	0.18323915	0.0075875744	1495.6139
85.44873	0.18669832	0.0078153731	1517.2274
86.249512	0.18870251	0.0077715279	1532.5801
87.050293	0.18836813	0.0078903064	1548.1266
87.851074	0.19383948	0.0079491949	1574.0427
88.651855	0.19535583	0.0080364197	1594.6361
89.452637	0.19685645	0.0082920063	1619.4705
90.253418	0.19863491	0.0082993163	1643.7168
91.054199	0.20140113	0.0084573263	1666.5653
91.85498	0.20530318	0.008625159	1695.2617
92.655762	0.20674254	0.0087683722	1724.2302
93.456543	0.20629629	0.0089125643	1741.9132
94.257324	0.20980848	0.0089491867	1757.1273
95.058105	0.21501087	0.0091887377	1779.4288
95.858887	0.21770881	0.0092077767	1796.3093
96.659668	0.21657699	0.0092733614	1817.7072
97.460449	0.21897869	0.0094107464	1835.6124
98.26123	0.22562672	0.0094659729	1856.7446
99.062012	0.22729331	0.0097206244	1877.647
99.862793	0.22736461	0.0097525632	1894.9185
100.66357	0.23177238	0.0099201454	1924.4336
101.46436	0.23337212	0.010078979	1943.785
102.26514	0.23610716	0.010134622	1964.9523
103.06592	0.23817287	0.010162635	1986.5786
103.8667	0.23909079	0.010330656	2007.9296
104.66748	0.24384727	0.01035927	2025.3882
105.46826	0.24676958	0.010519628	2049.7639
106.26904	0.2483706	0.010632445	2063.9529
107.06982	0.24845788	0.010761701	2085.1089
107.87061	0.25033033	0.010816509	2095.8403
108.67139	0.25611025	0.010877361	2113.9219
109.47217	0.25725457	0.010967729	2127.6396
110.27295	0.25818908	0.011162225	2150.3501
111.07373	0.26158449	0.011124555	2167.6487
111.87451	0.26447687	0.011254671	2178.3904
112.67529	0.26536813	0.011421311	2195.8657
113.47607	0.27186292	0.011492731	2215.9092
114.27686	0.2717531	0.0117283	2238.124
115.07764	0.27274659	0.01175112	2253.7241
115.87842	0.27856439	0.011806014	2267.1282
116.6792	0.27946305	0.011895468	2284.8403
117.47998	0.28002405	0.011985894	2300.2668
118.28076	0.28329775	0.012071623	2308.8547
119.08154	0.28599119	0.012242804	2330.8726
119.88232	0.29103965	0.012338438	2348.4717
120.68311	0.29226407	0.012439087	2356.1494
121.48389	0.29379258	0.012522641	2369.9399
122.28467	0.29592258	0.012581657	2381.2744
123.08545	0.29827061	0.012701082	2391.8418
123.88623	0.30305573	0.012762778	2402.7612
124.68701	0.30264658	0.012844889	2418.1814
125.48779	0.30480531	0.012961787	2436.4324
126.28857	0.30934504	0.013189545	2448.7454
127.08936	0.31062478	0.01326683	2456.1934
127.89014	0.31395912	0.013363175	2466.8333
128.69092	0.31396812	0.013490334	2482.4443
129.4917	0.32051373	0.01347057	2491.0967
130.29248	0.32182053	0.013578505	2503.1501
131.09326	0.32280642	0.01377749	2513.2158
131.89404	0.32630855	0.013813169	2521.4893
132.69482	0.32723528	0.013990914	2541.1062
133.49561	0.33275253	0.014090117	2543.8733
134.29639	0.3319293	0.014172662	2547.8655
135.09717	0.33629137	0.014309671	2558.0142
135.89795	0.33677572	0.014358554	2566.1743
136.69873	0.33970705	0.014498688	2576.6587
137.49951	0.34182727	0.014631764	2589.7292
138.30029	0.34555867	0.014761447	2598.6128
139.10107	0.34623542	0.014821622	2606.4397
139.90186	0.35076839	0.014938917	2612.5598
140.70264	0.35208112	0.015077106	2628.1819
141.50342	0.35435352	0.015296087	2636.1609
142.3042	0.35388616	0.015392094	2640.772
143.10498	0.36335757	0.015566011	2652.4424
143.90576	0.36283904	0.015591831	2656.6211
144.70654	0.36577529	0.015783442	2670.0037
145.50732	0.36685213	0.015875835	2668.9988
146.30811	0.3702082	0.01599608	2679.6025
147.10889	0.37115294	0.016278438	2692.5784
147.90967	0.37228414	0.016389785	2694.6731
148.71045	0.38014427	0.016615225	2713.0398
149.51123	0.37671918	0.016736152	2705.9973
150.31201	0.38039649	0.016927755	2716.9189
151.11279	0.38461885	0.017096238	2729.6912
151.91357	0.38352063	0.017299403	2727.1924
152.71436	0.38886726	0.017403813	2743.2659
153.51514	0.39110523	0.01764627	2748.1421
154.31592	0.39327559	0.017864546	2754.5422
155.1167	0.39578551	0.018092858	2768.9985
155.91748	0.39525566	0.018368715	2772.6877
156.71826	0.40101343	0.018564556	2780.7698
157.51904	0.40332478	0.018713403	2783.7515
158.31982	0.40565562	0.018998489	2791.6819
159.12061	0.40853283	0.019189212	2797.6794
159.92139	0.41051716	0.019453036	2801.3979
160.72217	0.4129779	0.019701451	2809.5454
161.52295	0.4154458	0.020047721	2820.7437
162.32373	0.41547737	0.020351894	2827.397
163.12451	0.4208872	0.020633951	2829.8369
163.92529	0.42441434	0.020995235	2842.7681
164.72607	0.42310843	0.02135043	2838.6306
165.52686	0.42786124	0.021659026	2847.7368
166.32764	0.42923748	0.021944383	2853.063
167.12842	0.43194261	0.022249011	2861.6724
167.9292	0.43500444	0.022698799	2863.5127
168.72998	0.43790156	0.023058297	2871.0127
169.53076	0.43794459	0.023411725	2872.9788
170.33154	0.4427841	0.023857173	2881.1921
171.13232	0.4435907	0.024274094	2887.6738
171.93311	0.44707811	0.024811111	2898.1958
172.73389	0.45105806	0.025217187	2902.7197
173.53467	0.45228535	0.025693508	2901.9351
174.33545	0.45192209	0.026066512	2900.6255
175.13623	0.45651329	0.026577398	2912.9473
175.93701	0.46173093	0.027027547	2923.9968
176.73779	0.4617838	0.027438844	2920.1704
177.53857	0.46093351	0.027937206	2927.8015
178.33936	0.46789646	0.028518012	2932.9858
179.14014	0.46757111	0.029036056	2935.1433
179.94092	0.4721024	0.029624952	2940.7705
180.7417	0.47237	0.030241672	2948.2249
181.54248	0.47591805	0.030982528	2948.8564
182.34326	0.4778198	0.031358607	2941.0471
183.14404	0.47926101	0.031857256	2955.9402
183.94482	0.48272428	0.032356922	2960.7019
184.74561	0.48599756	0.033046398	2961.8452
185.54639	0.48673844	0.033731349	2968.4016
186.34717	0.49041986	0.034344014	2977.4729
187.14795	0.49348459	0.035122175	2982.2742
187.94873	0.49685484	0.035810675	2986.1907
188.74951	0.49586725	0.036412779	2981.3416
189.55029	0.50167745	0.037189338	2989.4053
190.35107	0.50201428	0.037778229	2993.6584
191.15186	0.50531727	0.038585048	2991.918
191.95264	0.50670505	0.039084557	2991.1311
192.75342	0.50916451	0.039729271	2999.1101
193.5542	0.51371467	0.040482465	3009.0806
194.35498	0.5149315	0.041300874	3009.1074
195.15576	0.51695317	0.041935176	3006.1506
195.95654	0.51882476	0.042535812	3012.2615
196.75732	0.51939768	0.0431979	3014.7344
197.55811	0.5235883	0.044098306	3015.219
198.35889	0.52460819	0.044721272	3018.7793
199.15967	0.53146821	0.045335997	3031.9641
199.96045	0.53119761	0.046249144	3025.8374
200.76123	0.53344685	0.046927366	3028.6028
201.56201	0.53549087	0.047581173	3028.5625
202.36279	0.53986013	0.048362046	3040.3169
203.16357	0.5396632	0.049203809	3041.0444
203.96436	0.54349011	0.049903862	3042.4033
204.76514	0.54694819	0.050718836	3043.6736
205.56592	0.54876131	0.051435202	3046.8806
206.3667	0.54698837	0.052250471	3049.6494
207.16748	0.55138141	0.053088456	3057.9504
207.96826	0.55749589	0.05400091	3059.6572
208.76904	0.55634439	0.054815635	3057.9836
209.56982	0.55938065	0.055514012	3060.6995
210.37061	0.56072718	0.056360703	3065.2627
211.17139	0.56761843	0.057197656	3071.228
211.97217	0.56696588	0.057937507	3070.2952
212.77295	0.56992239	0.058784347	3064.8542
213.57373	0.57287049	0.059311748	3069.4185
214.37451	0.57202899	0.060113698	3074.2993
215.17529	0.57487601	0.060815223	3075.7676
215.97607	0.58009881	0.061483085	3071.0249
216.77686	0.5802986	0.062075432	3078.6484
217.57764	0.5847829	0.062882341	3079.4751
218.37842	0.58666569	0.063819483	3098.0305
219.1792	0.58599812	0.064833008	3084.9487
219.97998	0.59132588	0.065557942	3089.803
220.78076	0.59508431	0.066446595	3093.1694
221.58154	0.59681153	0.067268513	3101.1838
222.38232	0.59414905	0.068062924	3096.99
223.18311	0.60214359	0.068920024	3102.4072
223.98389	0.6002717	0.069713145	3096.6262
224.78467	0.60489541	0.070477225	3100.0061
225.58545	0.61101854	0.071102388	3110.3706
226.38623	0.60852689	0.071920827	3104.4751
227.18701	0.61442113	0.072711572	3113.0117
227.98779	0.61520362	0.07355956	3108.9626
228.78857	0.61647743	0.074366771	3121.8506
229.58936	0.62230688	0.075269461	3115.4705
230.39014	0.62374169	0.076113686	3115.9351
231.19092	0.62470859	0.077293962	3128.1177
231.9917	0.62982774	0.078171819	3123.5146
232.79248	0.63136911	0.079128891	3129.5139
233.59326	0.62972426	0.080011696	3128.2754
234.39404	0.63583732	0.080802493	3127.2917
235.19482	0.63790381	0.081523553	3130.3625
235.99561	0.63869709	0.082295477	3129.6311
236.79639	0.64110458	0.083099119	3140.887
237.59717	0.64350301	0.08393468	3138.728
238.39795	0.64731395	0.08479438	3141.3892
239.19873	0.65052313	0.085575491	3141.6118
239.99951	0.6518696	0.086290337	3144.4275
240.80029	0.65425205	0.087178513	3143.0957
241.60107	0.65745616	0.088028096	3148.7791
242.40186	0.66193581	0.088873491	3156.5806
243.20264	0.66036415	0.089854091	3159.5115
244.00342	0.66546172	0.090696372	3162.6765
244.8042	0.663571	0.091597728	3155.082
245.60498	0.66437584	0.092485651	3159.6155
246.40576	0.67398757	0.09335807	3161.8997
247.20654	0.67503476	0.094084419	3161.4626
248.00732	0.67410439	0.094977528	3165.3306
248.80811	0.67666197	0.095674857	3163.7681
249.60889	0.67803824	0.096546151	3166.5298
250.40967	0.68329811	0.097353473	3173.6089
251.21045	0.68491983	0.098171584	3168.1882
252.01123	0.68769896	0.099128403	3173.1335
252.81201	0.69012499	0.1000901	3172.7205
253.61279	0.6936546	0.10091852	3177.6733
254.41357	0.69335157	0.101761	3178.8049
255.21436	0.69809359	0.10271559	3184.3911
256.01514	0.70109618	0.10354912	3183.3962
256.81592	0.70195836	0.10465751	3182.8357
257.6167	0.70281249	0.10568593	3188.5208
258.41748	0.70658821	0.10660063	3181.668
259.21826	0.71068847	0.10726814	3184.1301
260.01904	0.7119807	0.10807102	3192.749
260.81982	0.7129336	0.10893606	3192.6296
261.62061	0.71550924	0.10972124	3191.6809
262.42139	0.71908987	0.11070451	3197.6758
263.22217	0.72233349	0.11144001	3197.7061
264.02295	0.72546875	0.11230539	3198.6658
264.82373	0.72564346	0.11330789	3198.1846
265.62451	0.73015141	0.11400914	3201.1809
266.42529	0.7303735	0.11480214	3203.3689
267.22607	0.73310816	0.11581061	3212.0303
268.02686	0.7346403	0.11675157	3207.1899
268.82764	0.73683697	0.11775465	3207.4529
269.62842	0.73888177	0.11865788	3211.0593
270.4292	0.74403346	0.11942612	3212.8657
271.22998	0.74440473	0.12040144	3209.1563
272.03076	0.74804437	0.12129588	3221.0569
272.83154	0.75116444	0.12210473	3216.6697
273.63232	0.75343478	0.1229481	3224.0908
274.43311	0.75649107	0.12382589	3224.2183
275.23389	0.75804889	0.12466712	3224.2542
276.03467	0.76053923	0.12548481	3226.1338
276.83545	0.76294243	0.12637562	3229.8284
277.63623	0.76626652	0.12722574	3226.8296
278.43701	0.76630974	0.12807049	3231.7634
279.23779	0.77050221	0.12907775	3234.384
280.03857	0.77112728	0.12994666	3229.1206
280.83936	0.77565086	0.13073447	3233.3489
281.64014	0.7766583	0.13169515	3240.1987
282.44092	0.77846891	0.13277669	3238.917
283.2417	0.77928144	0.13366988	3237.6497
284.04248	0.78615689	0.13471214	3249.3506
284.84326	0.7872799	0.13562644	3242.9922
285.64404	0.78958166	0.1365184	3244.5688
286.44482	0.79232186	0.13738766	3248.0283
287.24561	0.79159898	0.13814788	3243.3113
288.04639	0.7967093	0.13896027	3245.7139
288.84717	0.79856664	0.13957404	3242.5476
289.64795	0.80098057	0.14040868	3249.9438
290.44873	0.80185014	0.14129227	3251.3718
291.24951	0.80409801	0.14214	3254.7898
292.05029	0.80616593	0.14295842	3257.6868
292.85107	0.81080049	0.14396162	3259.9297
293.65186	0.81326038	0.14489526	3257.9055
294.45264	0.81148034	0.14581247	3255.2974
295.25342	0.81825292	0.14667064	3255.6611
296.0542	0.81859022	0.14756657	3260.2432
296.85498	0.82451636	0.14864218	3275.1414
297.65576	0.82631958	0.14983554	3274.3501
298.45654	0.82644904	0.15060182	3262.0974
299.25732	0.82864714	0.15149379	3269.6938
300.05811	0.82965106	0.15226664	3265.7158
300.85889	0.833444	0.15310074	3272.2661
301.65967	0.83504027	0.15391369	3271.2551
302.46045	0.84101623	0.15484677	3278.5076
303.26123	0.84126312	0.15566194	3274.4233
304.06201	0.84413898	0.1565402	3276.4268
304.86279	0.84330571	0.15749994	3280.665
305.66357	0.84738153	0.15845425	3282.8716
306.46436	0.84968412	0.15940942	3281.4382
307.26514	0.8546899	0.16034266	3285.4763
308.06592	0.85636628	0.16107681	3284.478
308.8667	0.85849023	0.16196422	3292.3413
309.66748	0.8609966	0.16287164	3285.9375
310.46826	0.86187088	0.16394168	3288.7356
311.26904	0.86733049	0.16498101	3294.8154
312.06982	0.86665517	0.16586882	3289.7529
312.87061	0.86970681	0.16664068	3292.5815
313.67139	0.87240314	0.16756202	3297.8145
314.47217	0.87608826	0.16832361	3295.6675
315.27295	0.87733114	0.16910617	3292.353
316.07373	0.87945831	0.1699682	3300.2825
316.87451	0.87985742	0.17084374	3298.6975
317.67529	0.88456553	0.17170581	3306.3318
318.47607	0.88974988	0.1728303	3311.5759
319.27686	0.88969517	0.17367665	3302.8914
320.07764	0.88922739	0.17455141	3301.7297
320.87842	0.8919524	0.17546646	3312.843
321.6792	0.89582968	0.17642033	3305.345
322.47998	0.9001416	0.17717406	3307.749
323.28076	0.90001172	0.17796159	3308.9814
324.08154	0.90194893	0.17893519	3306.8513
324.88232	0.90572256	0.17987056	3319.5283
325.68311	0.90933186	0.1808307	3319.1626
326.48389	0.91020018	0.1815716	3312.5881
327.28467	0.91538286	0.18251301	3321.3091
328.08545	0.91525704	0.18344113	3321.0349
328.88623	0.91982603	0.18431588	3324.6252
329.68701	0.92277503	0.18543273	3329.6162
330.48779	0.92505687	0.18631217	3328.1213
331.28857	0.92545581	0.1871786	3320.4661
332.08936	0.92699182	0.18804958	3330.5225
332.89014	0.93009901	0.18890697	3326.2454
333.69092	0.9339785	0.18968484	3322.0286
334.4917	0.9355787	0.19048783	3327.5288
335.29248	0.93786281	0.19132198	3334.6833
336.09326	0.94090766	0.19221509	3331.2239
336.89404	0.94034362	0.19307195	3331.8616
337.69482	0.9430635	0.19394284	3337.4155
338.49561	0.94376028	0.19513454	3336.2058
339.29639	0.9515115	0.1958085	3334.3364
340.09717	0.9521569	0.19669089	3339.2952
340.89795	0.95446372	0.19757617	3343.3279
341.69873	0.95582497	0.19846787	3342.4663
342.49951	0.9600715	0.19945242	3350.3481
343.30029	0.95802814	0.20041861	3346.3103
344.10107	0.9622767	0.20146324	3343.2178
344.90186	0.96698672	0.2023046	3343.4192
345.70264	0.96776652	0.2030858	3343.0215
346.50342	0.97333521	0.20397533	3351.3923
347.3042	0.97506154	0.20504838	3353.9971
348.10498	0.9750939	0.20586297	3345.2874
348.90576	0.97569734	0.2066261	3350.4368
349.70654	0.98225808	0.20769882	3359.0786
350.50732	0.98253614	0.20876467	3360.8862
351.30811	0.98586863	0.20964517	3355.2742
352.10889	0.98764211	0.21045388	3359.5447
352.90967	0.98942137	0.21152902	3357.3481
353.71045	0.99354398	0.2123193	3359.5073
354.51123	0.99402857	0.21322428	3357.8398
355.31201	0.99744296	0.21427727	3367.5935
356.11279	0.99794924	0.21504664	3361.3169
356.91357	1.0024912	0.21606112	3370.3276
357.71436	1.0062701	0.21698211	3367.8887
358.51514	1.0061159	0.217793	3368.8989
359.31592	1.0107292	0.21884723	3373.1824
360.1167	1.014066	0.21961655	3373.7654
360.91748	1.0139188	0.22045758	3370.1763
361.71826	1.0158075	0.22124878	3365.9492
362.51904	1.0195541	0.22200637	3373.8616
363.31982	1.0226126	0.22280487	3378.9463
364.12061	1.0225471	0.2238813	3380.4888
364.92139	1.0256449	0.22487052	3375.9963
365.72217	1.0284805	0.22565304	3378.0249
366.52295	1.0317611	0.22647926	3380.27
367.32373	1.0325105	0.22740483	3378.5332
368.12451	1.0363798	0.22847196	3384.1785
368.92529	1.0390341	0.22932008	3389.2717
369.72607	1.0414917	0.23020579	3380.1997
370.52686	1.0409683	0.2309404	3381.2844
371.32764	1.0462084	0.23191024	3390.8257
372.12842	1.0472209	0.23289141	3390.7664
372.9292	1.0517241	0.23379637	3395.6062
373.72998	1.0522337	0.23480795	3396.9617
374.53076	1.0548048	0.23563288	3392.6431
375.33154	1.0564122	0.23649532	3393.97
376.13232	1.0608804	0.23733707	3393.0034
376.93311	1.0619557	0.23825705	3398.2422
377.73389	1.0628461	0.23917738	3397.3152
378.53467	1.0660471	0.24024254	3393.9792
379.33545	1.0691831	0.24104749	3402.0459
380.13623	1.0729141	0.24181271	3401.717
380.93701	1.075762	0.24275102	3402.1216
381.73779	1.0754005	0.24361381	3400.678
382.53857	1.0785246	0.24448359	3404.615
383.33936	1.0805138	0.24554524	3409.3362
384.14014	1.0825723	0.24656717	3408.2793
384.94092	1.0862542	0.24762261	3407.6055
385.7417	1.0886481	0.24863191	3407.8442
386.54248	1.0902426	0.24959575	3414.033
387.34326	1.0922003	0.25059456	3411.2407
388.14404	1.0960371	0.25159144	3415.4763
388.94482	1.0985117	0.25246686	3412.9536
389.74561	1.1024209	0.25325778	3405.6995
390.54639	1.1043066	0.25400579	3418.3591
391.34717	1.1073223	0.25484133	3416.8601
392.14795	1.1109405	0.2557379	3415.9202
392.94873	1.110859	0.25659773	3426.5334
393.74951	1.1128094	0.25759405	3418.7693
394.55029	1.1152619	0.25850171	3424.6963
395.35107	1.1161499	0.25947458	3419.7935
396.15186	1.1187748	0.26047763	3418.9224
396.95264	1.1211236	0.26149043	3423.3547
397.75342	1.1239517	0.26233289	3425.4119
398.5542	1.1328826	0.26318994	3428.7012
399.35498	1.1313726	0.26411325	3428.3149
400.15576	1.1295394	0.26511875	3430.4048
400.95654	1.1374702	0.26604858	3428.7402
401.75732	1.1377763	0.26698127	3430.8315
402.55811	1.1392573	0.26773968	3425.9185
403.35889	1.1431395	0.26862943	3430.4026
404.15967	1.142812	0.26946297	3435.896
404.96045	1.1463195	0.27040809	3434.5747
405.76123	1.1498809	0.2713024	3435.105
406.56201	1.1506138	0.27240494	3442.2505
407.36279	1.1547837	0.27327558	3440.1343
408.16357	1.1552244	0.2743597	3440.1506
408.96436	1.1600567	0.27517375	3441.4976
409.76514	1.1612693	0.27605209	3439.488
410.56592	1.1620691	0.2767154	3437.3877
411.3667	1.1662577	0.27747115	3446.0203
412.16748	1.1682492	0.27844846	3447.3672
412.96826	1.1716667	0.27944914	3453.699
413.76904	1.1729422	0.28040478	3445.0481
414.56982	1.1770084	0.28145713	3450.8816
415.37061	1.1780902	0.28254461	3451.1443
416.17139	1.1793734	0.283362	3453.3315
416.97217	1.1831038	0.28451192	3454.9478
417.77295	1.1826248	0.28542164	3449.0886
418.57373	1.1868448	0.28639567	3456.5686
419.37451	1.189358	0.28717831	3451.3022
420.17529	1.1926559	0.28811035	3456.7209
420.97607	1.1925752	0.2889885	3459.0007
421.77686	1.1973783	0.28999829	3461.7112
422.57764	1.1989183	0.29107657	3467.8184
423.37842	1.2015871	0.29190776	3457.1699
424.1792	1.2048882	0.29275993	3459.1284
424.97998	1.2070465	0.29362631	3464.6604
425.78076	1.2087529	0.29455277	3460.9958
426.58154	1.2102801	0.29532143	3463.1213
427.38232	1.2150599	0.29620668	3465.0376
428.18311	1.2142067	0.29706058	3462.407
428.98389	1.2176394	0.29793248	3461.6926
429.78467	1.2221327	0.29887119	3468.6279
430.58545	1.2223408	0.29964679	3460.8413
431.38623	1.2271152	0.30055526	3470.9006
432.18701	1.2276593	0.30126044	3464.6943
432.98779	1.2299089	0.30205053	3471.6501
433.78857	1.2339007	0.30301455	3477.1013
434.58936	1.2351954	0.30415386	3473.4136
435.39014	1.2351636	0.30505273	3472.7427
436.19092	1.2407945	0.30612779	3478.4912
436.9917	1.2443018	0.30703154	3472.6558
437.79248	1.2447075	0.3077831	3476.9473
438.59326	1.2475265	0.30855069	3480.9385
439.39404	1.2480986	0.30947897	3483.322
440.19482	1.2489352	0.31042391	3478.7131
440.99561	1.2544512	0.31135347	3479.908
441.79639	1.2585274	0.3122555	3480.6563
442.59717	1.2583123	0.31327537	3482.427
443.39795	1.26333	0.31410608	3486.2852
444.19873	1.2622614	0.31492689	3480.2598
444.99951	1.2665955	0.31585377	3491.2429
445.80029	1.26896	0.31685951	3488.6301
446.60107	1.2723814	0.31775826	3488.6021
447.40186	1.2720798	0.31851685	3482.0876
448.20264	1.2759145	0.3195594	3490.0579
449.00342	1.2776693	0.32055283	3493.5774
449.8042	1.2787577	0.32170406	3498.6069
450.60498	1.2868015	0.32269597	3494.6362
451.40576	1.2857131	0.3236053	3489.376
452.20654	1.2889061	0.32452664	3492.0063
453.00732	1.2912854	0.32543612	3492.7346
453.80811	1.2950668	0.32641181	3500.3179
454.60889	1.2959625	0.32721955	3492.3933
455.40967	1.2963105	0.32802755	3498.2305
456.21045	1.2975507	0.32917756	3504.0552
457.01123	1.3036884	0.33020177	3500.1243
457.81201	1.3050311	0.33107603	3502.749
458.61279	1.3075056	0.3321884	3500.3228
459.41357	1.3084754	0.33288759	3498.3484
460.21436	1.3100294	0.3338238	3508.3516
461.01514	1.3132671	0.33478516	3510.3867
461.81592	1.3149124	0.33578101	3501.842
462.6167	1.3206886	0.33667305	3508.4189
463.41748	1.3227246	0.33763853	3511.6377
464.21826	1.3246055	0.3385289	3513.3857
465.01904	1.3264011	0.33943382	3507.6147
465.81982	1.327548	0.34037581	3510.4043
466.62061	1.3309691	0.34141302	3511.615
467.42139	1.3338834	0.34230226	3511.8247
468.22217	1.3384625	0.34320283	3514.2896
469.02295	1.3368979	0.34400988	3510.478
469.82373	1.3399451	0.34505847	3517.2029
470.62451	1.3456682	0.34607962	3515.5818
471.42529	1.3437902	0.34696829	3515.4204
472.22607	1.347229	0.34799951	3513.4277
473.02686	1.348266	0.34891611	3515.8132
473.82764	1.3520906	0.3497749	3514.0947
474.62842	1.3572634	0.35066071	3515.8286
475.4292	1.359286	0.35174987	3526.0708
476.22998	1.3621976	0.35274932	3524.8809
477.03076	1.3625495	0.3537274	3522.2913
477.83154	1.3634592	0.35458058	3519.6428
478.63232	1.3698159	0.35546675	3524.7737
479.43311	1.3717028	0.35626659	3523.3008
480.23389	1.3727282	0.35713661	3531.1086
481.03467	1.3748827	0.35803908	3525.4128
481.83545	1.3774036	0.35884979	3529.668
482.63623	1.3784461	0.35988548	3540.0342
483.43701	1.3838109	0.36103845	3534.3574
484.23779	1.3852003	0.36198577	3531.1577
485.03857	1.388337	0.36300567	3533.0078
485.83936	1.3879051	0.36396974	3528.488
486.64014	1.3938057	0.36503446	3541.772
487.44092	1.3930526	0.36592835	3532.3425
488.2417	1.3979117	0.36683318	3532.2114
489.04248	1.4003912	0.36789063	3539.9336
489.84326	1.4015642	0.3687951	3533.8391
490.64404	1.4033718	0.36978394	3540.7874
491.44482	1.4043682	0.37073988	3539.9412
492.24561	1.408281	0.37184173	3543.365
493.04639	1.4101381	0.37279782	3535.2637
493.84717	1.4132657	0.37373799	3538.2324
494.64795	1.4179832	0.37461293	3543.2019
495.44873	1.4172497	0.37550259	3542.6116
496.24951	1.4199616	0.37649876	3547.2354
497.05029	1.4250215	0.3773149	3544.4985
497.85107	1.4221727	0.37812623	3541.9409
498.65186	1.4303329	0.37909821	3548.2793
499.45264	1.4307432	0.3800514	3546.5879
500.25342	1.4322475	0.38099563	3549.488
501.0542	1.432969	0.38177535	3549.8291
501.85498	1.4346216	0.38258356	3543.604
502.65576	1.4372883	0.38353083	3542.4878
503.45654	1.4419245	0.38431093	3549.9778
504.25732	1.4452327	0.38520005	3547.5381
505.05811	1.4465431	0.38612595	3550.4587
505.85889	1.4482042	0.38714421	3552.0879
506.65967	1.4531585	0.38792768	3550.8523
507.46045	1.4545218	0.38888347	3558.2285
508.26123	1.4538267	0.3898856	3559.1965
509.06201	1.4586509	0.39091662	3554.0366
509.86279	1.4601017	0.39182302	3553.8518
510.66357	1.4626635	0.39286542	3562.5276
511.46436	1.4650271	0.39375949	3558.574
512.26514	1.46913	0.39494488	3569.1458
513.06592	1.4705099	0.39602926	3559.8625
513.8667	1.4736781	0.39717665	3566.6838
514.66748	1.4731673	0.39800817	3556.1655
515.46826	1.4782848	0.39898935	3560.2922
516.26904	1.4808944	0.39985961	3558.3909
517.06982	1.4839306	0.40087298	3563.9661
517.87061	1.4861376	0.40183294	3563.5054
518.67139	1.4885782	0.40279493	3572.9814
519.47217	1.4914192	0.40390557	3570.3445
520.27295	1.4926111	0.40492213	3571.335
521.07373	1.4924548	0.406012	3568.8882
521.87451	1.4981965	0.40711313	3570.8521
522.67529	1.5001776	0.40811214	3567.4741
523.47607	1.5030341	0.40901574	3572.3384
524.27686	1.5055201	0.40989876	3572.9626
525.07764	1.5061773	0.4107573	3569.6768
525.87842	1.5113132	0.41165096	3570.4866
526.6792	1.5125457	0.41264883	3579.7336
527.47998	1.5137972	0.41371596	3576.1199
528.28076	1.5147892	0.41469142	3571.2021
529.08154	1.5209713	0.41582543	3582.1626
529.88232	1.5202454	0.41679239	3580.0237
530.68311	1.52244	0.41761327	3568.2742
531.48389	1.52908	0.4184463	3575.905
532.28467	1.5301454	0.41948512	3584.7224
533.08545	1.5313991	0.4206143	3581.5012
533.88623	1.5314612	0.42160287	3578.2275
534.68701	1.5362025	0.42248109	3577.5793
535.48779	1.5354574	0.42348596	3582.4126
536.28857	1.5407002	0.42442313	3582.3545
537.08936	1.5404422	0.42530689	3580.3489
537.89014	1.543561	0.42628473	3580.6682
538.69092	1.5449277	0.42736122	3583.771
539.4917	1.5491523	0.42815951	3587.3113
540.29248	1.5502682	0.42917481	3581.8562
541.09326	1.5562017	0.43012318	3595.3796
541.89404	1.557161	0.43116894	3587.55
542.69482	1.5600932	0.43228	3590.6655
543.49561	1.5606675	0.43322167	3585.1199
544.29639	1.5627173	0.43420988	3585.1758
545.09717	1.5671073	0.43502918	3585.9971
545.89795	1.5698653	0.43584314	3591.5371
546.69873	1.5703822	0.43703282	3592.9597
547.49951	1.5742042	0.43796161	3593.5093
548.30029	1.5762228	0.43890721	3593.7036
549.10107	1.5807664	0.43975356	3592.7708
549.90186	1.5766135	0.44071341	3595.3291
550.70264	1.5847231	0.44177714	3597.821
551.50342	1.584736	0.44296831	3603.1326
552.3042	1.5888191	0.44387823	3594.8962
553.10498	1.5896469	0.44485134	3598.3835
553.90576	1.5937719	0.44582704	3594.1213
554.70654	1.596388	0.44677055	3598.8689
555.50732	1.5981622	0.44787252	3601.8765
556.30811	1.6037242	0.44890383	3604.8018
557.10889	1.602031	0.44991055	3598.2686
557.90967	1.6055757	0.45086366	3598.8174
558.71045	1.6075294	0.45173451	3601.9512
559.51123	1.6097407	0.45279026	3603.7969
560.31201	1.6119796	0.45378777	3604.0833
561.11279	1.61766	0.45490316	3606.2571
561.91357	1.6159593	0.45586404	3605.5938
562.71436	1.621901	0.45688024	3602.825
563.51514	1.6227955	0.45781082	3606.1396
564.31592	1.6247827	0.45885536	3607.5278
565.1167	1.6242684	0.45969564	3607.989
565.91748	1.6313872	0.46074814	3611.5254
566.71826	1.6322237	0.46177047	3610.4126
567.51904	1.6305033	0.46276009	3605.5466
568.31982	1.6373506	0.46355966	3602.573
569.12061	1.6374929	0.46450952	3609.2742
569.92139	1.6420201	0.46535948	3605.2676
570.72217	1.6428393	0.46640092	3613.0398
571.52295	1.6456634	0.46751249	3612.8782
572.32373	1.6488934	0.46872079	3623.8228
573.12451	1.6495354	0.46962768	3607.8188
573.92529	1.6526333	0.47064534	3609.2722
574.72607	1.6559279	0.47148106	3613.594
575.52686	1.6580535	0.47256598	3620.6125
576.32764	1.6606736	0.47356561	3618.0232
577.12842	1.6636574	0.47451159	3619.3362
577.9292	1.6660048	0.4754065	3614.8538
578.72998	1.6673491	0.47634214	3616.3584
579.53076	1.6706756	0.47717449	3616.6943
580.33154	1.6707147	0.47818241	3618.217
581.13232	1.6761957	0.47917098	3623.3574
581.93311	1.6766396	0.48015428	3618.9253
582.73389	1.6791939	0.48117122	3625.2532
583.53467	1.6820778	0.48230231	3631.2043
584.33545	1.6849902	0.48320886	3618.3833
585.13623	1.686389	0.48426881	3621.8633
585.93701	1.6898619	0.48541987	3624.7954
586.73779	1.6904401	0.4865019	3623.1667
587.53857	1.6944149	0.487501	3623.6594
588.33936	1.6956027	0.48847225	3624.0535
589.14014	1.6972595	0.48936549	3623.1921
589.94092	1.7000562	0.4903585	3629.4639
590.7417	1.7039133	0.49132565	3625.553
591.54248	1.706804	0.49241933	3629.6946
592.34326	1.708209	0.49351627	3631.8684
593.14404	1.7078861	0.49457037	3626.053
593.94482	1.7149742	0.49570778	3630.8081
594.74561	1.7147441	0.49681196	3632.2361
595.54639	1.7170553	0.49794623	3630.5308
596.34717	1.7210726	0.49899882	3632.8887
597.14795	1.7219695	0.50000465	3630.4878
597.94873	1.7245376	0.5012005	3637.3784
598.74951	1.7273664	0.50226253	3633.998
599.55029	1.7315224	0.5032419	3637.5083
600.35107	1.731426	0.50449657	3636.9082
601.15186	1.7365158	0.50544357	3636.0442
601.95264	1.7346328	0.50649875	3633.627
602.75342	1.7395655	0.50756156	3636.2068
603.5542	1.7389902	0.50864124	3633.6824
604.35498	1.7440695	0.50962752	3638.3423
605.15576	1.7492466	0.51063085	3639.511
605.95654	1.7489798	0.51147443	3641.9331
606.75732	1.7525858	0.5126341	3639.2712
607.55811	1.7543575	0.51367265	3642.9919
608.35889	1.7580535	0.51471138	3629.9761
609.15967	1.7588524	0.51574612	3644.7251
609.96045	1.7586901	0.51669598	3637.481
610.76123	1.7629167	0.51758838	3636.1658
611.56201	1.7652807	0.51847464	3635.6226
612.36279	1.769628	0.51928991	3644.1521
613.16357	1.7713784	0.52043086	3650.1772
613.96436	1.7730911	0.52146685	3644.9558
614.76514	1.7760156	0.52248055	3641.3411
615.56592	1.7793607	0.52343649	3642.3684
616.3667	1.779835	0.52440757	3642.8267
617.16748	1.7824516	0.52549273	3646.9705
617.96826	1.7851064	0.5265702	3649.9414
618.76904	1.7877426	0.52759755	3639.72
619.56982	1.7899408	0.52854091	3642.9563
620.37061	1.7892799	0.5296005	3647.582
621.17139	1.7985914	0.53064764	3649.7715
621.97217	1.7963445	0.53175247	3648.5222
622.77295	1.8005816	0.53274751	3653.5886
623.57373	1.8040754	0.53371835	3644.9929
624.37451	1.8044138	0.53471291	3647.6602
625.17529	1.8068831	0.53571707	3650.6687
625.97607	1.8070921	0.5366295	3652.155
626.77686	1.8119649	0.53771579	3653.4551
627.57764	1.8169366	0.53895134	3658.2915
628.37842	1.8170036	0.54022956	3653.7974
629.1792	1.817556	0.54136068	3653.8982
629.97998	1.8252506	0.54262227	3659.188
630.78076	1.8246931	0.54352951	3652.1672
631.58154	1.8243057	0.54443854	3645.1553
632.38232	1.830097	0.54540032	3652.8506
633.18311	1.83059	0.54634207	3651.123
633.98389	1.8340352	0.54750878	3660.6497
634.78467	1.8335583	0.5485611	3655.4944
635.58545	1.8392689	0.54957223	3655.7744
636.38623	1.8416237	0.55057001	3652.5781
637.18701	1.8419296	0.55158019	3655.5349
637.98779	1.8455536	0.55259472	3660.2524
638.78857	1.8466082	0.55363894	3659.0779
639.58936	1.8501277	0.55481559	3655.3694
640.39014	1.850769	0.5561536	3661.801
641.19092	1.8550768	0.55728012	3659.9783
641.9917	1.8547503	0.55832916	3661.2373
642.79248	1.8601093	0.55943608	3658.0371
643.59326	1.8641348	0.56065148	3660.4351
644.39404	1.8642651	0.56148505	3658.7927
645.19482	1.8687667	0.56241524	3655.7051
645.99561	1.8703363	0.56335771	3660.6536
646.79639	1.8724771	0.56429827	3660.4141
647.59717	1.8751596	0.56538546	3666.0249
648.39795	1.8760217	0.56643146	3664.0361
649.19873	1.8764228	0.56732053	3661.8652
649.99951	1.883267	0.56836706	3666.4836
650.80029	1.8814019	0.56919038	3655.8997
651.60107	1.8851973	0.57023978	3659.6895
652.40186	1.8863865	0.57155162	3677.1604
653.20264	1.8903552	0.57268435	3669.7832
654.00342	1.8932474	0.5739271	3667.094
654.8042	1.8948404	0.57507306	3670.0588
655.60498	1.8987269	0.57625449	3671.1675
656.40576	1.9013283	0.57744658	3672.2463
657.20654	1.9018211	0.57874823	3672.157
658.00732	1.9064484	0.58009863	3677.5542
658.80811	1.9079043	0.58145404	3667.0361
659.60889	1.9094439	0.58259767	3672.5671
660.40967	1.9127971	0.58364171	3664.3159
661.21045	1.9148211	0.58491641	3666.2864
662.01123	1.9161316	0.58591062	3672.0112
662.81201	1.9207435	0.58691913	3672.3899
663.61279	1.9235002	0.58794224	3671.7854
664.41357	1.9258657	0.58918452	3672.364
665.21436	1.9298372	0.59011251	3674.3477
666.01514	1.927236	0.59130466	3669.2578
666.81592	1.9321582	0.5923242	3672.6182
667.6167	1.9339995	0.59352136	3681.05
668.41748	1.9368368	0.59469908	3674.3652
669.21826	1.9403136	0.59577417	3671.9009
670.01904	1.9439591	0.59681821	3671.0857
670.81982	1.9460484	0.5977903	3673.1938
671.62061	1.9467148	0.59889823	3679.9956
672.42139	1.9507654	0.60000437	3678.4983
673.22217	1.9538034	0.60111016	3675.4019
674.02295	1.9509137	0.6020723	3671.4153
674.82373	1.9590204	0.60303479	3677.2456
675.62451	1.9589605	0.60418004	3680.4917
676.42529	1.9612272	0.60505217	3675.5161
677.22607	1.9642376	0.60594529	3673.4968
678.02686	1.9636543	0.60699916	3677.082
678.82764	1.9676284	0.60826421	3682.6758
679.62842	1.9705787	0.6093449	3679.8474
680.4292	1.9712192	0.61071295	3682.2307
681.22998	1.9768199	0.61182481	3683.9385
682.03076	1.9768672	0.61284041	3674.115
682.83154	1.9809971	0.61416525	3685.2566
683.63232	1.9813745	0.61522257	3678.5474
684.43311	1.9852346	0.61634809	3683.0208
685.23389	1.9861317	0.61755073	3678.7056
686.03467	1.9886401	0.61887896	3684.3486
686.83545	1.9945445	0.62001264	3682.0315
687.63623	1.9973589	0.62096363	3683.2546
688.43701	1.9975097	0.62208962	3688.303
689.23779	2.0001829	0.62312138	3681.9478
690.03857	1.9996879	0.6240111	3681.0911
690.83936	2.0044978	0.62505549	3681.7336
691.64014	2.0058806	0.6262818	3682.4761
692.44092	2.0089545	0.6275335	3684.5559
693.2417	2.0119333	0.6284675	3678.7888
694.04248	2.0156527	0.62974465	3694.3274
694.84326	2.0173728	0.63092917	3689.6372
695.64404	2.0174401	0.63221538	3687.3269
696.44482	2.0216913	0.63351423	3686.8672
697.24561	2.0245945	0.63471192	3684.7344
698.04639	2.0247943	0.63576365	3686.2178
698.84717	2.0260139	0.6370272	3687.1453
699.64795	2.0287015	0.63831019	3688.5034
700.44873	2.0359275	0.63956428	3695.3137
701.24951	2.0370982	0.64062315	3684.3154
702.05029	2.0384629	0.64171416	3686.2817
702.85107	2.0432205	0.64291054	3693.2954
703.65186	2.0416331	0.64404708	3689.991
704.45264	2.0462122	0.64518595	3689.408
705.25342	2.0482147	0.64633965	3690.9788
706.0542	2.0495753	0.64762926	3691.7803
706.85498	2.0515654	0.64880413	3689.6157
707.65576	2.0524318	0.65000981	3689.5188
708.45654	2.0594234	0.6511125	3690.5303
709.25732	2.0615218	0.65229946	3686.5996
710.05811	2.0632839	0.65325826	3693.0964
710.85889	2.065028	0.65431058	3687.9031
711.65967	2.0640719	0.65537047	3685.3628
712.46045	2.0696626	0.65668237	3694.1455
713.26123	2.071847	0.65783542	3693.0342
714.06201	2.0738966	0.65909183	3689.9763
714.86279	2.076545	0.66027123	3690.2595
715.66357	2.0794668	0.66143382	3693.9509
716.46436	2.0850027	0.66247404	3691.0671
717.26514	2.0843987	0.66348499	3686.9131
718.06592	2.0859158	0.6642648	3684.9941
718.8667	2.0872693	0.66524965	3693.7197
719.66748	2.0887487	0.6661948	3693.271
720.46826	2.0960469	0.66749537	3699.0718
721.26904	2.0956035	0.66857064	3690.8357
722.06982	2.0959272	0.66979641	3692.449
722.87061	2.0993011	0.67085916	3691.2705
723.67139	2.1033585	0.67202449	3691.5
724.47217	2.1081977	0.67327338	3700.7539
725.27295	2.1079211	0.67448086	3699.0718
726.07373	2.1123762	0.6757561	3693.4832
726.87451	2.1121521	0.67698985	3693.8264
727.67529	2.1132967	0.67827719	3696.5679
728.47607	2.1174746	0.67925388	3693.5935
729.27686	2.1207716	0.68049234	3694.8845
730.07764	2.1211841	0.6815902	3692.7671
730.87842	2.1254363	0.6826117	3692.5381
731.6792	2.1261966	0.68374294	3695.2505
732.47998	2.1311574	0.68498874	3700.4631
733.28076	2.1296494	0.68616641	3697.0298
734.08154	2.1359642	0.68758297	3704.5596
734.88232	2.13518	0.68890816	3696.8625
735.68311	2.1391511	0.69025236	3698.0757
736.48389	2.1403155	0.69166988	3699.8442
737.28467	2.1439934	0.69284815	3696.6216
738.08545	2.1468489	0.69381183	3692.7322
738.88623	2.1491163	0.69504893	3695.6235
739.68701	2.1528068	0.69612372	3694.0107
740.48779	2.1529257	0.69713384	3695.8867
741.28857	2.1566722	0.69819635	3697.2021
742.08936	2.1580176	0.69962555	3702.4883
742.89014	2.1602836	0.70096558	3704.1538
743.69092	2.1639857	0.70219415	3697.4155
744.4917	2.1671236	0.70322675	3697.3696
745.29248	2.1720383	0.7044093	3703.3787
746.09326	2.1690483	0.70547605	3699.0117
746.89404	2.173454	0.70678729	3701.0657
747.69482	2.1728876	0.70798755	3699.4158
748.49561	2.1779356	0.70925468	3698.6926
749.29639	2.1768084	0.71036649	3699.3586
750.09717	2.1829617	0.71161962	3696.7012
750.89795	2.1873801	0.71278936	3699.2332
751.69873	2.1853526	0.71402752	3695.749
752.49951	2.1890831	0.71518904	3695.7751
753.30029	2.192693	0.71610641	3694.2405
754.10107	2.1946907	0.71733451	3699.6292
754.90186	2.194746	0.71867722	3699.2998
755.70264	2.1968753	0.71982437	3697.3203
756.50342	2.2046497	0.72095132	3695.1206
757.3042	2.2055938	0.72204965	3699.7229
758.10498	2.2045424	0.72337615	3699.783
758.90576	2.2095926	0.72441643	3697.241
759.70654	2.2132447	0.72560966	3705.8523
760.50732	2.2132797	0.72696292	3703.8992
761.30811	2.2129385	0.72817838	3700.4099
762.10889	2.2176268	0.72943348	3704.2229
762.90967	2.2226477	0.73074532	3702.0083
763.71045	2.222389	0.73193467	3696.5439
764.51123	2.2239397	0.73308343	3697.2781
765.31201	2.2254992	0.73440146	3701.4707
766.11279	2.23122	0.73562235	3701.311
766.91357	2.2315176	0.73708057	3707.8315
767.71436	2.2351573	0.7384606	3703.5723
768.51514	2.2378259	0.73982477	3705.5576
769.31592	2.2416983	0.74126935	3699.9314
770.1167	2.2397492	0.74253559	3700.2556
770.91748	2.2463002	0.7440294	3708.1838
771.71826	2.2501428	0.74556834	3704.9143
772.51904	2.2512798	0.74676758	3703.9165
773.31982	2.2510738	0.74798346	3693.7319
774.12061	2.2548289	0.74913168	3698.8308
774.92139	2.2572422	0.75019717	3701.7852
775.72217	2.2563195	0.75126851	3703.4563
776.52295	2.2627234	0.7525416	3705.9248
777.32373	2.2651584	0.75360978	3701.7983
778.12451	2.2659872	0.75494939	3706.5352
778.92529	2.2691	0.75620884	3704.7095
779.72607	2.2717805	0.75767565	3708.595
780.52686	2.2740819	0.75889188	3698.9338
781.32764	2.275316	0.76000214	3696.8796
782.12842	2.2780814	0.76130807	3703.8623
782.9292	2.2790935	0.76240265	3701.2822
783.72998	2.2836523	0.76359779	3700.7395
784.53076	2.2855837	0.76491499	3704.3245
785.33154	2.2859485	0.76626384	3704.6003
786.13232	2.2887805	0.76748133	3701.7847
786.93311	2.2919841	0.76909012	3704.5344
787.73389	2.2945063	0.77052379	3705.9348
788.53467	2.296227	0.77172679	3696.7385
789.33545	2.3015003	0.77292061	3703.4585
790.13623	2.3003466	0.77421516	3700.7192
790.93701	2.3056204	0.77559602	3703.8708
791.73779	2.3080685	0.77693486	3699.7439
792.53857	2.309427	0.77806199	3691.2891
793.33936	2.3117385	0.77904177	3699.0549
794.14014	2.3153992	0.78008819	3699.9941
794.94092	2.314744	0.78105885	3697.387
795.7417	2.320509	0.78230774	3702.2524
796.54248	2.3206558	0.78351736	3702.0718
797.34326	2.3224843	0.78477079	3701.4749
798.14404	2.3262579	0.78594875	3700.0754
798.94482	2.3297665	0.78716785	3695.8369
799.74561	2.3281937	0.78840828	3699.8867
800.54639	2.3321548	0.78967655	3700.1592
801.34717	2.3362267	0.7911194	3703.3435
802.14795	2.3393867	0.7927599	3705.698
802.94873	2.3415489	0.79414117	3699.5535
803.74951	2.3436623	0.79531693	3695.9514
804.55029	2.3455637	0.79631609	3697.1519
805.35107	2.3465998	0.79758626	3702.3022
806.15186	2.350652	0.7989437	3706.5938
806.95264	2.3552306	0.80042511	3713.6687
807.75342	2.3563626	0.8021062	3704.6785
808.5542	2.3575473	0.80337775	3699.1577
809.35498	2.3593178	0.80480915	3700.3291
810.15576	2.3632813	0.80613804	3700.5112
810.95654	2.364341	0.80761248	3707.1436
811.75732	2.3668051	0.80893153	3701.0579
812.55811	2.3713679	0.81019896	3695.6204
813.35889	2.3716209	0.81158352	3698.6926
814.15967	2.3728335	0.81255597	3691.5942
814.96045	2.3771231	0.81368077	3694.6594
815.76123	2.3767564	0.81497633	3702.0813
816.56201	2.3800311	0.81638014	3702.8074
817.36279	2.3821397	0.81770629	3698.4312
818.16357	2.3893492	0.81909686	3700.8845
818.96436	2.3883429	0.82025397	3697.4045
819.76514	2.3938899	0.82155997	3697.2332
820.56592	2.3953879	0.8229233	3697.6877
821.3667	2.394824	0.82436281	3697.2043
822.16748	2.3994906	0.82620823	3707.2041
822.96826	2.4005949	0.82766461	3696.1252
823.76904	2.402873	0.82893836	3689.6621
824.56982	2.4040022	0.83000529	3691.7786
825.37061	2.4084749	0.83124191	3694.5645
826.17139	2.4111693	0.83268154	3698.457
826.97217	2.4113588	0.83377695	3696.7529
827.77295	2.4144809	0.83494776	3694.4385
828.57373	2.4195955	0.83610219	3692.9258
829.37451	2.4184692	0.83732456	3697.5813
830.17529	2.424057	0.83887053	3702.3208
830.97607	2.4235318	0.84044737	3700.0591
831.77686	2.4295349	0.84236604	3702.5222
832.57764	2.4290643	0.84391612	3692.0767
833.37842	2.4300382	0.8453027	3692.2092
834.1792	2.4317701	0.84644085	3685.9277
834.97998	2.4372728	0.84752429	3688.4175
835.78076	2.4402969	0.8485775	3693.49
836.58154	2.4418817	0.84982264	3694.5376
837.38232	2.4445417	0.85111159	3695.5415
838.18311	2.4450777	0.85263503	3691.6797
838.98389	2.4473383	0.85397691	3693.6404
839.78467	2.4500036	0.85537136	3691.8367
840.58545	2.4545805	0.85689145	3699.6665
841.38623	2.4574599	0.85835254	3694.4182
842.18701	2.4597533	0.85985011	3693.4141
842.98779	2.4597802	0.8614257	3688.0112
843.78857	2.465539	0.86281353	3688.2219
844.58936	2.4649167	0.86385667	3681.7085
845.39014	2.4685619	0.86509591	3690.4529
846.19092	2.4699695	0.8664425	3692.1826
846.9917	2.4721267	0.86796111	3687.3223
847.79248	2.4763532	0.86964047	3690.3293
848.59326	2.4770396	0.87104982	3687.6316
849.39404	2.4811172	0.87239856	3684.5396
850.19482	2.4816792	0.87370741	3682.9553
850.99561	2.4837918	0.87488538	3680.0447
851.79639	2.4884398	0.87615603	3688.6545
852.59717	2.4902627	0.87752372	3685.7656
853.39795	2.4886787	0.87897074	3682.6426
854.19873	2.4945056	0.88027191	3679.7117
854.99951	2.5004818	0.88165706	3683.0132
855.80029	2.4990525	0.88311565	3681.5195
856.60107	2.5007961	0.88454765	3680.4871
857.40186	2.5061054	0.8861984	3683.8455
858.20264	2.5042031	0.88783735	3682.5813
859.00342	2.5082662	0.88915515	3676.1543
859.8042	2.5132794	0.89036739	3675.8647
860.60498	2.5135386	0.89126313	3670.3679
861.40576	2.5153337	0.89252114	3675.5371
862.20654	2.5194907	0.89363247	3676.3672
863.00732	2.5201507	0.89498729	3678.0054
863.80811	2.5231729	0.89641148	3678.0413
864.60889	2.5267582	0.89783376	3678.5977
865.40967	2.5269747	0.89941901	3674.2078
866.21045	2.5308032	0.90067166	3668.4287
867.01123	2.5321586	0.90188342	3669.0718
867.81201	2.5363567	0.90328598	3672.3306
868.61279	2.5374811	0.90447825	3671.0076
869.41357	2.5416842	0.90594369	3674.8293
870.21436	2.5435562	0.90747273	3670.1099
871.01514	2.54339	0.90883476	3664.6965
871.81592	2.548099	0.91040134	3668.5342
872.6167	2.5485821	0.91208369	3666.8721
873.41748	2.5524387	0.91357452	3663.8438
874.21826	2.5577769	0.91499186	3664.6091
875.01904	2.5553844	0.91610205	3657.2124
875.81982	2.5573938	0.91749752	3652.8245
876.62061	2.5615435	0.91882139	3660.8369
877.42139	2.5636101	0.920075	3662.5254
878.22217	2.5685196	0.92148465	3658.2278
879.02295	2.5692632	0.9229843	3656.272
879.82373	2.5700445	0.92438084	3653.9624
880.62451	2.5739391	0.92614824	3660.7275
881.42529	2.5744441	0.92778236	3652.2793
882.22607	2.5780437	0.92921191	3648.0208
883.02686	2.5812399	0.93050992	3646.2458
883.82764	2.583168	0.93171483	3643.9097
884.62842	2.5856378	0.93310869	3649.8386
885.4292	2.5895202	0.93429208	3645.6018
886.22998	2.5920618	0.93549228	3646.8384
887.03076	2.5912137	0.93681026	3644.4995
887.83154	2.5950723	0.93841475	3652.9241
888.63232	2.5969009	0.9400903	3640.988
889.43311	2.6022696	0.94160086	3632.5845
890.23389	2.6022828	0.94286269	3633.5222
891.03467	2.6049235	0.94409394	3637.5012
891.83545	2.6069102	0.94544536	3636.9683
892.63623	2.6096942	0.9469521	3639.8005
893.43701	2.6123183	0.94840205	3638.8201
894.23779	2.6144636	0.94987178	3630.5718
895.03857	2.6168437	0.95139033	3631.1272
895.83936	2.6209641	0.95283639	3625.29
896.64014	2.6231275	0.9541145	3626.2656
897.44092	2.6258352	0.95526236	3618.1282
898.2417	2.6285858	0.95643407	3619.502
899.04248	2.6292703	0.95774943	3622.6592
899.84326	2.6317253	0.95931417	3624.5239
900.64404	2.6338072	0.96094984	3620.4712
901.44482	2.6358602	0.96235597	3614.5359
902.24561	2.6403205	0.96381831	3614.8179
903.04639	2.6404405	0.965253	3606.3674
903.84717	2.6460886	0.96667159	3613.2634
904.64795	2.6482723	0.96816236	3611.3315
905.44873	2.6490867	0.96964478	3606.7834
906.24951	2.6486883	0.97105366	3604.9421
907.05029	2.6514442	0.97214943	3596.532
907.85107	2.6536438	0.97342515	3593.6943
908.65186	2.6580446	0.97490197	3600.134
909.45264	2.6611447	0.97636592	3599.5972
910.25342	2.6638877	0.97771162	3594.3918
911.0542	2.6637065	0.97900248	3583.8469
911.85498	2.6707897	0.98038805	3593.2693
912.65576	2.6693804	0.98195964	3597.1843
913.45654	2.6723773	0.98367399	3587.8108
914.25732	2.6751831	0.98522705	3586.606
915.05811	2.6755254	0.98672324	3583.6301
915.85889	2.6790376	0.98820329	3578.7285
916.65967	2.6805828	0.9899081	3573.5928
917.46045	2.6858122	0.99126834	3573.1162
918.26123	2.6878085	0.99245316	3565.0999
919.06201	2.6880193	0.99378306	3567.4714
919.86279	2.6897705	0.99530447	3565.5408
920.66357	2.6925716	0.99681884	3564.6201
921.46436	2.6969602	0.99844557	3566.9719
922.26514	2.6973708	0.99982041	3554.6365
923.06592	2.7004182	1.001112	3556.1143
923.8667	2.7016933	1.0025334	3552.3352
924.66748	2.7060304	1.0040963	3553.4844
925.46826	2.7071519	1.0056399	3550.0627
926.26904	2.7117243	1.0070463	3542.1714
927.06982	2.7129359	1.0084034	3544.1067
927.87061	2.714021	1.0100816	3544.6096
928.67139	2.7175834	1.0117205	3540.2029
929.47217	2.7199287	1.0131698	3536.0308
930.27295	2.7220972	1.0146041	3530.3647
931.07373	2.729403	1.0160332	3530.6799
931.87451	2.7277422	1.0173658	3523.0151
932.67529	2.7284739	1.0184443	3514.1321
933.47607	2.7312365	1.0197724	3520.2832
934.27686	2.7336919	1.021275	3518.2896
935.07764	2.7363112	1.022893	3517.3269
935.87842	2.7389205	1.0242219	3509.9275
936.6792	2.7434862	1.025721	3515.0969
937.47998	2.7439282	1.0274854	3510.1902
938.28076	2.7456417	1.0291796	3502.4929
939.08154	2.7487991	1.0307018	3499.3706
939.88232	2.7493019	1.0321418	3495.5042
940.68311	2.7540255	1.0337385	3495.6963
941.48389	2.7562146	1.035382	3492.6216
942.28467	2.7600381	1.0370568	3495.5088
943.08545	2.7642293	1.0388412	3490.5283
943.88623	2.7646072	1.0402901	3476.9771
944.68701	2.766571	1.0415967	3477.4211
945.48779	2.7714794	1.0431118	3478.1807
946.28857	2.7716525	1.0449495	3473.9429
947.08936	2.7724445	1.046694	3469.5444
947.89014	2.777117	1.0482762	3468.3538
948.69092	2.7803068	1.0498451	3465.9043
949.4917	2.7785664	1.0514766	3458.9128
950.29248	2.7847939	1.0531343	3452.1211
951.09326	2.7828035	1.0546548	3449.1387
951.89404	2.7887135	1.0563904	3450.0349
952.69482	2.7912722	1.0581601	3439.5505
953.49561	2.7937024	1.0599303	3441.0461
954.29639	2.7959018	1.0616015	3433.8738
955.09717	2.7980206	1.0635098	3431.7029
955.89795	2.7988458	1.0653948	3418.6514
956.69873	2.8027871	1.0668281	3411.5879
957.49951	2.8044138	1.0682706	3414.2729
958.30029	2.8083405	1.0699016	3407.5083
959.10107	2.8098736	1.071429	3404.9058
959.90186	2.8121173	1.0731975	3396.4985
960.70264	2.8153155	1.0750175	3397.8574
961.50342	2.8193035	1.0773768	3397.1013
962.3042	2.8209536	1.0790563	3382.1743
963.10498	2.820065	1.0806842	3376.4507
963.90576	2.8230476	1.0824047	3371.5891
964.70654	2.8281376	1.0840424	3366.709
965.50732	2.8290131	1.0855267	3353.9058
966.30811	2.8331814	1.0864714	3352.8713
967.10889	2.834924	1.0877444	3356.2495
967.90967	2.8362296	1.0894735	3355.6555
968.71045	2.8406608	1.0914812	3352.4834
969.51123	2.8397846	1.0931491	3335.9592
970.31201	2.8455243	1.0949968	3329.0764
971.11279	2.8451719	1.0970268	3325.5093
971.91357	2.849613	1.0992107	3309.7959
972.71436	2.8522999	1.1012373	3289.7329
973.51514	2.8567986	1.1031169	3282.2009
974.31592	2.858938	1.1052339	3267.2346
975.1167	2.8585594	1.1074842	3253.0786
975.91748	2.8625271	1.1094257	3243.3054
976.71826	2.8626781	1.1115198	3224.8723
977.51904	2.868355	1.1133344	3210.6096
978.31982	2.8653743	1.1149567	3207.4868
979.12061	2.8711848	1.116596	3196.0737
979.92139	2.8723857	1.118094	3177.6482
980.72217	2.8757594	1.1197487	3176.853
981.52295	2.876642	1.1215999	3165.407
982.32373	2.8796666	1.1235543	3156.1406
983.12451	2.8833127	1.1253806	3145.0112
983.92529	2.8848422	1.1275092	3125.3274
984.72607	2.8879728	1.1301941	3103.4001
985.52686	2.890734	1.1332586	3061.4463
986.32764	2.8939383	1.1374041	3013.2964
986.52783	2.8970232	1.1396406	2961.1089