File: datasets/am_bench_2022/raw_data/90-X.13-2/specimen.dat
MTS793|MPT|ENU|1|2|.|/|:|1|0|0|A

Operator Information						Time:	10.381348	Sec	11/2/2021 12:12:12 PM
Operator	Nick Derimow
Project	AM Bench 2022 mini-tensile challenge
Specimen ID	90-X.13-2
Material	PBF-L Inconel 625
Specimen Width	2.54	mm
Specimen Thickness	1.51	mm
Notes
Operator Information End

Data Acquisition						Time:	1011.376	Sec	11/2/2021 12:28:53 PM
Time	Axial Displacement	Axial Extensometer	Axial Force
Sec	mm	mm	N
10.49585	-0.0046418207	0.00018935199	18.662212
11.396729	0.00026034922	0.00013624015	28.203619
12.297607	0.002352081	0.00025953021	38.865326
13.198486	0.0049691023	0.00036856704	50.692982
14.099365	0.0076820124	0.00050868274	64.752167
15.000244	0.0075590778	0.00050194596	69.525909
15.901123	0.011477771	0.00048730956	78.331459
16.802002	0.01624128	0.0006813464	91.037476
17.702881	0.017579578	0.00068126858	101.21612
18.60376	0.019134905	0.00076455571	113.08228
19.504639	0.023497391	0.00079915771	123.70357
20.405518	0.025494413	0.00092302455	133.46394
21.306396	0.027960481	0.00098494673	146.25421
22.207275	0.033060782	0.001041721	160.17314
23.108154	0.032869823	0.0011018144	165.68246
24.009033	0.035828602	0.0012532442	176.16153
24.909912	0.03761315	0.0013223324	191.91501
25.810791	0.043759469	0.0014062794	208.12546
26.71167	0.044489034	0.0014355583	223.01442
27.612549	0.045077685	0.0016649839	237.73372
28.513428	0.045204718	0.0018075214	256.35425
29.414307	0.051689621	0.0018790642	272.05524
30.315186	0.057530448	0.0019832656	287.10873
31.216064	0.055724539	0.0019899902	308.91644
32.116943	0.059328519	0.00225805	330.85092
33.017822	0.063556805	0.0023479972	346.81937
33.918701	0.065075405	0.0024383327	361.33765
34.81958	0.065915659	0.0025846146	379.73755
35.720459	0.069881119	0.0027097855	398.07468
36.621338	0.072254114	0.0029983702	423.17221
37.522217	0.077949367	0.0030205394	443.8541
38.423096	0.080882587	0.0031726453	461.508
39.323975	0.081518978	0.003223113	479.66852
40.224854	0.083367504	0.0033547452	494.52139
41.125732	0.088505864	0.0035629494	522.19055
42.026611	0.088683091	0.0036872721	538.79321
42.92749	0.091175541	0.0038328941	565.15369
43.828369	0.096810862	0.0039949776	581.37628
44.729248	0.098914221	0.0040710689	602.17548
45.630127	0.1015755	0.0042658197	622.73035
46.531006	0.10201848	0.0043185297	635.30969
47.431885	0.10294335	0.0044223624	658.70483
48.332764	0.10963914	0.0046539283	687.66406
49.233643	0.1115288	0.0047815251	713.55054
50.134521	0.11188797	0.004891648	730.62311
51.0354	0.1168135	0.0051633343	764.7959
51.936279	0.12027077	0.0052983197	786.33533
52.837158	0.12312388	0.0055394033	818.24261
53.738037	0.12553868	0.005587229	830.85071
54.638916	0.12673873	0.0057586459	852.55774
55.539795	0.12736917	0.0058281287	874.84479
56.440674	0.13180844	0.006065377	895.77942
57.341553	0.13531166	0.0061798566	925.30219
58.242432	0.1338131	0.0064019649	951.53662
59.143311	0.13832802	0.0064877053	970.82495
60.044189	0.1412551	0.0066668326	1001.9067
60.945068	0.14699809	0.0067792051	1026.1333
61.845947	0.15143685	0.006952594	1051.5013
62.746826	0.15284131	0.0071297283	1079.7035
63.647705	0.15222521	0.0073508066	1099.0227
64.548584	0.15218566	0.0074327136	1119.5829
65.449463	0.15836057	0.0075904164	1143.421
66.350342	0.16132985	0.0076216818	1164.6381
67.251221	0.16329168	0.0079226103	1198.528
68.1521	0.16568066	0.0081396159	1233.0275
69.052979	0.17045702	0.0081180576	1242.796
69.953857	0.17458655	0.0084643764	1276.1455
70.854736	0.17534137	0.0085643055	1292.6014
71.755615	0.17770848	0.0086608119	1320.2048
72.656494	0.18097807	0.0087719476	1341.3535
73.557373	0.17991264	0.0090292962	1370.6342
74.458252	0.18386924	0.0091976523	1392.3467
75.359131	0.18965757	0.0092185801	1413.4897
76.26001	0.19166405	0.0093739638	1439.1587
77.160889	0.19424953	0.0096084718	1464.6191
78.061768	0.19345844	0.0097898422	1493.27
78.962646	0.19828071	0.0098526245	1512.5894
79.863525	0.20239548	0.01005998	1538.2246
80.764404	0.2041305	0.010120307	1561.78
81.665283	0.20589723	0.010388302	1586.947
82.566162	0.21097949	0.010563035	1613.5519
83.467041	0.21359876	0.010628672	1639.0057
84.36792	0.21364425	0.010847501	1663.4109
85.268799	0.21825655	0.010957818	1687.098
86.169678	0.22050478	0.011041404	1706.7612
87.070557	0.2223012	0.011288198	1736.2529
87.971436	0.22667372	0.011442544	1764.3015
88.872314	0.23162431	0.011532793	1789.1481
89.773193	0.22949672	0.011711841	1808.3296
90.674072	0.2343868	0.011827669	1825.1217
91.574951	0.23858783	0.011959842	1853.5193
92.47583	0.23910943	0.012062311	1869.5635
93.376709	0.24207133	0.012228623	1893.0941
94.277588	0.24557368	0.012204983	1903.4618
95.178467	0.25017548	0.012354364	1920.3109
96.079346	0.24859092	0.012635864	1944.3348
96.980225	0.25358811	0.012611064	1960.7285
97.881104	0.25271404	0.012737751	1986.0216
98.781982	0.2585946	0.012910088	2007.1844
99.682861	0.2609885	0.013037979	2034.8301
100.58374	0.26070207	0.013319881	2059.5117
101.48462	0.26708984	0.013244486	2075.2922
102.3855	0.26681304	0.013396246	2085.2813
103.28638	0.2714321	0.013537476	2101.1096
104.18726	0.27429029	0.013616138	2120.7847
105.08813	0.28007036	0.013869195	2145.8042
105.98901	0.28233463	0.013935099	2163.4229
106.88989	0.28083172	0.014094212	2182.0723
107.79077	0.28640145	0.01432765	2199.4526
108.69165	0.29093114	0.014418907	2221.3931
109.59253	0.28999129	0.014693897	2233.6638
110.49341	0.29431319	0.014591157	2249.3308
111.39429	0.29821229	0.014929666	2267.739
112.29517	0.29958826	0.015039491	2287.5229
113.19604	0.30219325	0.015131363	2300.7766
114.09692	0.30634075	0.015243048	2308.9165
114.9978	0.30874044	0.015391124	2320.9099
115.89868	0.31018165	0.015515381	2338.9314
116.79956	0.31314555	0.01575065	2349.8872
117.70044	0.31673089	0.015863623	2366.2122
118.60132	0.31794262	0.016159907	2384.4832
119.5022	0.3187882	0.016152643	2386.1899
120.40308	0.32583866	0.016441703	2408.1147
121.30396	0.32568336	0.016625024	2416.6951
122.20483	0.32833931	0.016764563	2428.0559
123.10571	0.3312524	0.016958928	2436.4805
124.00659	0.33767322	0.017064724	2449.5154
124.90747	0.33599126	0.017295215	2461.6606
125.80835	0.34085387	0.017564656	2471.99
126.70923	0.34484798	0.017624205	2474.5618
127.61011	0.34515327	0.017872145	2487.5071
128.51099	0.34873021	0.018107209	2501.5579
129.41187	0.35404584	0.018273031	2514.6821
130.31274	0.35628077	0.018509444	2520.6226
131.21362	0.35731524	0.018768644	2534.8154
132.1145	0.36258599	0.01900888	2539.7771
133.01538	0.36010006	0.019221943	2546.1851
133.91626	0.36023775	0.019463539	2552.1875
134.81714	0.3680217	0.019803779	2566.8928
135.71802	0.37079671	0.020050338	2584.9988
136.6189	0.37391999	0.020290971	2579.406
137.51978	0.37854972	0.020534849	2587.8948
138.42065	0.37823644	0.020667503	2582.8386
139.32153	0.37957662	0.020823324	2590.2866
140.22241	0.38705972	0.021339234	2609.2725
141.12329	0.38686344	0.021478714	2613.0835
142.02417	0.38962474	0.021858303	2622.8743
142.92505	0.39115712	0.02225684	2629.2393
143.82593	0.39408252	0.022609048	2634.8914
144.72681	0.39655453	0.022828652	2637.5435
145.62769	0.40170476	0.023170508	2643.2356
146.52856	0.40410465	0.02354829	2655.3826
147.42944	0.40642217	0.023986908	2665.5271
148.33032	0.40874252	0.02445461	2665.366
149.2312	0.4125143	0.024927305	2677.9204
150.13208	0.41778731	0.02538923	2674.8435
151.03296	0.41746625	0.025775503	2681.0938
151.93384	0.4201071	0.026171016	2682.8733
152.83472	0.42212787	0.026746707	2698.9731
153.7356	0.425529	0.027319252	2703.7153
154.63647	0.4272525	0.027985534	2710.075
155.53735	0.42997736	0.028791005	2713.928
156.43823	0.43467751	0.029415198	2726.8652
157.33911	0.43703288	0.030122846	2725.1677
158.23999	0.43881953	0.030648148	2731.0278
159.14087	0.44092697	0.031407967	2735.5276
160.04175	0.44494224	0.031818289	2732.5835
160.94263	0.44609925	0.032556113	2742.0833
161.84351	0.45139804	0.033239432	2747.1252
162.74438	0.45292017	0.033924632	2750.9197
163.64526	0.45627111	0.034449976	2745.3206
164.54614	0.45890766	0.035107117	2762.4233
165.44702	0.46247822	0.035835162	2761.4187
166.3479	0.46568063	0.036574733	2769.7148
167.24878	0.46458098	0.037480544	2772.9702
168.14966	0.47144538	0.038337674	2774.8193
169.05054	0.47120076	0.039168548	2779.6401
169.95142	0.47389644	0.0400187	2781.3811
170.85229	0.47570091	0.040900409	2791.4888
171.75317	0.48178157	0.041679535	2793.7788
172.65405	0.48364505	0.042489246	2794.8464
173.55493	0.48085916	0.04333872	2798.5691
174.45581	0.48819563	0.044166997	2800.5005
175.35669	0.49068439	0.04505495	2805.6594
176.25757	0.49188772	0.045921434	2814.438
177.15845	0.49796516	0.046647996	2811.7839
178.05933	0.49787951	0.047496911	2813.7905
178.96021	0.50059533	0.048268013	2821.2307
179.86108	0.50316811	0.049160354	2819.1978
180.76196	0.50667268	0.049982544	2826.0232
181.66284	0.50871539	0.050852761	2834.2808
182.56372	0.51188856	0.051806081	2834.9341
183.4646	0.51610494	0.052513197	2833.1775
184.36548	0.51689541	0.053540237	2843.4182
185.26636	0.51905721	0.054211851	2839.8496
186.16724	0.52105689	0.055141024	2846.2603
187.06812	0.52448857	0.055867109	2846.832
187.96899	0.52618223	0.056850847	2853.8098
188.86987	0.53120357	0.057739325	2853.5818
189.77075	0.53501022	0.058700778	2863.2415
190.67163	0.53567261	0.059646051	2861.6995
191.57251	0.53896356	0.060845129	2865.7649
192.47339	0.54368645	0.061841182	2870.3621
193.37427	0.54525405	0.06298098	2873.8762
194.27515	0.54904079	0.063854843	2874.291
195.17603	0.5485636	0.064684995	2879.7922
196.0769	0.55353159	0.065362409	2878.3921
196.97778	0.55862689	0.066268452	2886.4558
197.87866	0.56039673	0.067138948	2887.2922
198.77954	0.56141114	0.06826181	2895.5037
199.68042	0.56340796	0.069306001	2895.3201
200.5813	0.5674876	0.070220627	2895.6921
201.48218	0.56939507	0.071178079	2895.8882
202.38306	0.57311767	0.072240733	2896.9871
203.28394	0.57595187	0.073041394	2897.3503
204.18481	0.57695174	0.073975898	2902.8105
205.08569	0.57878202	0.074750274	2907.4858
205.98657	0.58433205	0.075722352	2913.2754
206.88745	0.58661735	0.076590858	2908.8464
207.78833	0.58929956	0.077494472	2916.5295
208.68921	0.59117633	0.078375652	2915.7095
209.59009	0.59304637	0.079303481	2919.3655
210.49097	0.59532124	0.07998535	2913.2371
211.39185	0.59761518	0.081014618	2921.9055
212.29272	0.60470062	0.08200065	2926.9155
213.1936	0.60615969	0.082935974	2927.8193
214.09448	0.60491353	0.083793141	2930.1526
214.99536	0.61040741	0.084739566	2933.4036
215.89624	0.61231673	0.08568421	2932.5608
216.79712	0.6137315	0.086559229	2931.0962
217.698	0.61752522	0.087491348	2940.769
218.59888	0.62151569	0.088284574	2943.5127
219.49976	0.62518764	0.089467771	2951.8611
220.40063	0.62617522	0.090357341	2946.3398
221.30151	0.6290549	0.091301747	2948.1638
222.20239	0.63051558	0.092380978	2954.5261
223.10327	0.63353974	0.093283027	2954.9553
224.00415	0.63818377	0.094383061	2964.6646
224.90503	0.63939321	0.095283672	2959.2996
225.80591	0.64207083	0.096341245	2960.1257
226.70679	0.64844131	0.097326763	2968.0486
227.60767	0.64830858	0.098254167	2967.073
228.50854	0.65225238	0.099232361	2976.4309
229.40942	0.65201473	0.10029519	2969.437
230.3103	0.65407878	0.10116921	2964.6672
231.21118	0.65791494	0.10210281	2969.668
232.11206	0.66180539	0.10315587	2977.2725
233.01294	0.66244155	0.10428842	2982.6675
233.91382	0.66880965	0.10542969	2982.5593
234.8147	0.67046845	0.10629023	2980.7004
235.71558	0.6741159	0.10730267	2991.075
236.61646	0.67181623	0.10820325	2985.7588
237.51733	0.67690194	0.10917775	2988.272
238.41821	0.68032295	0.11016134	2993.5276
239.31909	0.68443549	0.11100146	2991.9612
240.21997	0.68496799	0.11208216	3001.6733
241.12085	0.68938029	0.1131058	2999.488
242.02173	0.69136077	0.11404625	2998.8853
242.92261	0.69397902	0.11505496	3002.6189
243.82349	0.69780469	0.11617993	3009.1426
244.72437	0.69648767	0.1169821	2997.8591
245.62524	0.70171809	0.11789841	3005.5879
246.52612	0.70393515	0.11873627	3007.8057
247.427	0.70654196	0.11946253	3008.5056
248.32788	0.71041393	0.12036627	3015.1401
249.22876	0.7121473	0.12142134	3019.6902
250.12964	0.71640837	0.12245464	3015.155
251.03052	0.71704721	0.12342188	3018.064
251.9314	0.7190004	0.12445076	3020.6863
252.83228	0.7260195	0.12549156	3028.5974
253.73315	0.72657907	0.12641211	3026.2705
254.63403	0.72951204	0.12753354	3028.8113
255.53491	0.73328668	0.12842688	3033.1611
256.43579	0.73698264	0.12935235	3038.8428
257.33667	0.73689741	0.13027175	3033.2185
258.23755	0.74117064	0.13119899	3032.9915
259.13843	0.74221432	0.13213499	3040.7678
260.03931	0.74142593	0.13305213	3036.3628
260.94019	0.75034487	0.13427956	3049.7881
261.84106	0.75106442	0.13544774	3045.229
262.74194	0.75227886	0.13665107	3050.4785
263.64282	0.75556141	0.13765436	3049.9907
264.5437	0.75762153	0.13856727	3049.5356
265.44458	0.75938374	0.13955402	3049.8589
266.34546	0.76341408	0.14033234	3049.0879
267.24634	0.76503211	0.14134759	3054.1785
268.14722	0.76727772	0.14221723	3055.4827
269.0481	0.77223438	0.14309825	3060.364
269.94897	0.77574432	0.14415039	3066.9685
270.84985	0.77701008	0.14507748	3065.7322
271.75073	0.778974	0.14618704	3068.4106
272.65161	0.78397304	0.14709063	3065.1536
273.55249	0.78642577	0.14793399	3066.425
274.45337	0.7882995	0.14873196	3070.1567
275.35425	0.7897591	0.14953782	3072.9119
276.25513	0.79339486	0.15061888	3076.1167
277.15601	0.79553741	0.15174595	3079.4646
278.05688	0.80017644	0.15261269	3078.4861
278.95776	0.79876524	0.15353823	3073.3032
279.85864	0.80454385	0.15453947	3080.9219
280.75952	0.81015003	0.15575282	3091.1648
281.6604	0.81266505	0.15656717	3082.2517
282.56128	0.81332499	0.1572783	3077.5447
283.46216	0.81466311	0.15797181	3082.0933
284.36304	0.81926304	0.15879625	3087.8804
285.26392	0.81823367	0.15975386	3087.147
286.16479	0.82191336	0.16075522	3099.1743
287.06567	0.82637727	0.16184169	3091.3125
287.96655	0.82772642	0.16260667	3088.8386
288.86743	0.8336131	0.16356692	3097.1914
289.76831	0.83267653	0.16464995	3097.3313
290.66919	0.83667862	0.16555443	3098.3979
291.57007	0.83712852	0.16664599	3101.4092
292.47095	0.84262758	0.16756165	3102.313
293.37183	0.84579182	0.16843855	3103.7661
294.27271	0.84581047	0.16942404	3105.5876
295.17358	0.85054564	0.17028715	3106.4832
296.07446	0.85202581	0.17121859	3110.6658
296.97534	0.85827816	0.17228207	3118.1589
297.87622	0.85903686	0.1731893	3113.9116
298.7771	0.86280113	0.17432152	3117.4976
299.67798	0.86450779	0.17509411	3114.5237
300.57886	0.86570275	0.17603037	3116.8
301.47974	0.87122339	0.1771484	3129.8589
302.38062	0.87049031	0.17816734	3120.5313
303.28149	0.87175941	0.17914324	3120.3491
304.18237	0.87763155	0.18000549	3124.1338
305.08325	0.88169366	0.18105769	3126.6262
305.98413	0.8819555	0.18199944	3134.7058
306.88501	0.88292974	0.18303078	3129.2822
307.78589	0.8855232	0.18409567	3134.4255
308.68677	0.89008063	0.18507163	3130.1196
309.58765	0.89556092	0.18617921	3140.0242
310.48853	0.89756596	0.1871075	3137.0105
311.3894	0.89952469	0.18789519	3135.5107
312.29028	0.90063846	0.18871906	3137.8804
313.19116	0.90557611	0.18972301	3146.1406
314.09204	0.90543759	0.19069193	3144.3086
314.99292	0.90999496	0.19164923	3146.2864
315.8938	0.91279799	0.19249703	3143.4124
316.79468	0.9144451	0.19342813	3146.8269
317.69556	0.91713303	0.19436219	3143.6733
318.59644	0.91995174	0.19514675	3146.5344
319.49731	0.92269146	0.19620697	3155.7349
320.39819	0.9248448	0.19721876	3160.3323
321.29907	0.92915779	0.19818316	3152.4419
322.19995	0.93334198	0.19914679	3161.447
323.10083	0.93461353	0.19987556	3154.0125
324.00171	0.93675935	0.20085861	3166.0005
324.90259	0.93989021	0.20191683	3166.3108
325.80347	0.94484359	0.20281743	3166.2158
326.70435	0.94492435	0.20373939	3166.5676
327.60522	0.94600677	0.20471811	3164.6521
328.5061	0.95111972	0.20566519	3165.6399
329.40698	0.9534772	0.20653106	3171.1609
330.30786	0.95653683	0.20769195	3173.918
331.20874	0.95881253	0.20865794	3170.4626
332.10962	0.96065426	0.20950818	3173.9746
333.0105	0.96441251	0.21039791	3173.3884
333.91138	0.96761841	0.21130696	3178.6443
334.81226	0.96777761	0.21236518	3181.5808
335.71313	0.97071779	0.21339002	3180.0366
336.61401	0.97677159	0.21442869	3185.863
337.51489	0.97602642	0.21535866	3185.905
338.41577	0.97832912	0.2163389	3186.2361
339.31665	0.98511916	0.21731335	3188.5156
340.21753	0.98369116	0.21827516	3186.9221
341.11841	0.9849444	0.21918902	3187.4128
342.01929	0.9933508	0.22000445	3192.0051
342.92017	0.99460429	0.22096473	3191.6897
343.82104	0.99586743	0.22202492	3202.4185
344.72192	1.0004113	0.22293277	3196.866
345.6228	1.0025296	0.22383748	3199.7087
346.52368	1.0049548	0.22468297	3197.2517
347.42456	1.0085794	0.22554292	3196.0447
348.32544	1.010749	0.22651586	3202.2996
349.22632	1.009853	0.2273809	3200.0295
350.1272	1.0136999	0.22834119	3203.5574
351.02808	1.0185119	0.22927955	3206.6221
351.92896	1.0179796	0.23015054	3198.5667
352.82983	1.0267925	0.23102358	3208.1709
353.73071	1.0249616	0.23174882	3206.665
354.63159	1.0313836	0.23264544	3208.9675
355.53247	1.03061	0.23353881	3212.54
356.43335	1.0326767	0.23440745	3206.9756
357.33423	1.0383157	0.23541725	3219.22
358.23511	1.038355	0.23634604	3219.2742
359.13599	1.0409719	0.23742205	3224.3743
360.03687	1.0470243	0.23806414	3213.2542
360.93774	1.0506363	0.23885654	3213.5393
361.83862	1.0483738	0.23972778	3219.0186
362.7395	1.0548464	0.24082197	3227.6921
363.64038	1.0573225	0.24192201	3226.9724
364.54126	1.0575223	0.2430269	3226.2178
365.44214	1.0592862	0.24396038	3225.3931
366.34302	1.0654664	0.24480511	3229.1106
367.2439	1.0700389	0.24575041	3228.6995
368.14478	1.0693431	0.2467137	3231.5601
369.04565	1.0744869	0.24755628	3231.9028
369.94653	1.076268	0.24846989	3237.7837
370.84741	1.0778178	0.24931258	3233.7146
371.74829	1.0793194	0.25027293	3239.853
372.64917	1.0816193	0.25132921	3243.4641
373.55005	1.0849456	0.25251272	3245.7673
374.45093	1.0874985	0.25346833	3243.9333
375.35181	1.0895474	0.25414878	3234.9678
376.25269	1.0933213	0.2550078	3240.6375
377.15356	1.0939502	0.25590253	3242.6819
378.05444	1.1007378	0.25691432	3244.5078
378.95532	1.1004432	0.25780562	3243.7488
379.8562	1.1022478	0.25858462	3244.8535
380.75708	1.1104008	0.25949398	3254.5532
381.65796	1.1107417	0.26063162	3252.686
382.55884	1.1080313	0.26162693	3257.4307
383.45972	1.1155996	0.26247692	3259.3103
384.3606	1.1205575	0.26326409	3255.3811
385.26147	1.1191715	0.26420048	3256.386
386.16235	1.1248809	0.26528239	3260.9885
387.06323	1.1250477	0.26602128	3257.6792
387.96411	1.1287439	0.26719865	3267.0784
388.86499	1.1298537	0.26806509	3256.9287
389.76587	1.1374702	0.26909134	3265.2666
390.66675	1.1340286	0.26988128	3256.7234
391.56763	1.1393005	0.27079347	3261.979
392.46851	1.14324	0.2718038	3269.6914
393.36938	1.1462401	0.27255705	3269.843
394.27026	1.1462108	0.27342758	3272.3289
395.17114	1.1504705	0.27446747	3274.3982
396.07202	1.1537358	0.27544177	3277.6504
396.9729	1.1518637	0.27640364	3274.4675
397.87378	1.1578903	0.27719	3270.0886
398.77466	1.1594782	0.27793869	3272.3979
399.67554	1.1636724	0.27877203	3273.845
400.57642	1.1635661	0.27954504	3274.782
401.47729	1.1677499	0.28044879	3275.5244
402.37817	1.1745356	0.28143045	3285.4094
403.27905	1.1749467	0.28241345	3287.6736
404.17993	1.1782079	0.2832562	3285.1858
405.08081	1.1797806	0.28429478	3288.8704
405.98169	1.1847821	0.28510934	3283.3811
406.88257	1.1857104	0.28613359	3284.886
407.78345	1.1894382	0.2871055	3299.9919
408.68433	1.1917182	0.28816557	3285.6946
409.58521	1.1957074	0.28918034	3292.074
410.48608	1.1951808	0.29006273	3290.5691
411.38696	1.1977038	0.29095924	3293.0264
412.28784	1.2014199	0.29186589	3292.3889
413.18872	1.2050829	0.29282936	3300.3127
414.0896	1.207805	0.29390261	3300.3674
414.99048	1.2083484	0.29474458	3297.3799
415.89136	1.2113036	0.2955887	3296.1677
416.79224	1.2166644	0.29648033	3299.4749
417.69312	1.2178791	0.29734212	3304.4175
418.59399	1.221826	0.29841909	3309.04
419.49487	1.2240697	0.29926315	3298.9395
420.39575	1.2243617	0.30027199	3307.0146
421.29663	1.2326843	0.30134401	3314.1721
422.19751	1.2325624	0.30229732	3309.3391
423.09839	1.2336016	0.3031649	3305.3748
423.99927	1.2360967	0.30394232	3305.1152
424.90015	1.2394294	0.30464682	3303.6865
425.80103	1.2414894	0.30531752	3298.5803
426.7019	1.2460512	0.3060928	3316.4292
427.60278	1.2448519	0.30700991	3314.5696
428.50366	1.2522948	0.30785027	3307.9968
429.40454	1.2526537	0.30876893	3319.9141
430.30542	1.2579572	0.30978277	3326.626
431.2063	1.26002	0.31066212	3326.1404
432.10718	1.2601889	0.31177449	3328.1897
433.00806	1.2635585	0.31292316	3322.5588
433.90894	1.2669554	0.31402284	3327.396
434.80981	1.273176	0.31487158	3320.7319
435.71069	1.268364	0.31571609	3327.3105
436.61157	1.278013	0.31675828	3323.3591
437.51245	1.2761133	0.31754878	3324.1226
438.41333	1.2812089	0.31845707	3335.0981
439.31421	1.2820274	0.31922197	3322.2754
440.21509	1.284392	0.31994534	3327.2383
441.11597	1.2888315	0.32101056	3333.8411
442.01685	1.2910669	0.32195145	3342.7417
442.91772	1.2917265	0.32302955	3334.6086
443.8186	1.2953871	0.32425565	3343.0115
444.71948	1.2971196	0.32519516	3338.8997
445.62036	1.3017613	0.32629478	3338.0256
446.52124	1.3043047	0.32721955	3336.7217
447.42212	1.307186	0.32801247	3338.0432
448.323	1.3116168	0.32901663	3344.5906
449.22388	1.3109152	0.3298685	3342.554
450.12476	1.3142719	0.33069524	3339.7185
451.02563	1.3174553	0.33175093	3346.0786
451.92651	1.323462	0.3327336	3354.4792
452.82739	1.3234208	0.33371353	3347.8213
453.72827	1.3238978	0.33451834	3348.6782
454.62915	1.3303909	0.33558628	3359.3328
455.53003	1.3323038	0.33661407	3354.2053
456.43091	1.3356419	0.33746174	3348.7957
457.33179	1.3379542	0.33826035	3349.4048
458.23267	1.3423617	0.33908209	3354.1824
459.13354	1.3442054	0.34009829	3362.7871
460.03442	1.3483737	0.34101406	3359.5386
460.9353	1.3461559	0.34191316	3354.7869
461.83618	1.3499277	0.34284234	3361.0479
462.73706	1.3532721	0.34375599	3362.2429
463.63794	1.3554004	0.34462816	3355.9927
464.53882	1.357435	0.34543717	3364.0115
465.4397	1.3582947	0.3465676	3360.9272
466.34058	1.3651525	0.34742713	3364.6189
467.24146	1.3667142	0.34819618	3368.0032
468.14233	1.3675174	0.34921241	3369.1262
469.04321	1.3752071	0.35015398	3373.7205
469.94409	1.3737054	0.35106915	3367.1414
470.84497	1.3780117	0.35195735	3369.6604
471.74585	1.3811694	0.35280856	3373.717
472.64673	1.383847	0.35389078	3377.8225
473.54761	1.3859992	0.35484442	3367.1504
474.44849	1.3882031	0.35562187	3370.8789
475.34937	1.3896888	0.3565796	3379.9189
476.25024	1.3930314	0.3574245	3371.8008
477.15112	1.3965759	0.3584519	3373.3933
478.052	1.4008195	0.35940063	3378.1438
478.95288	1.4019382	0.36021298	3380.3984
479.85376	1.405184	0.36117327	3383.0981
480.75464	1.4083942	0.36227208	3385.3638
481.65552	1.4084247	0.36311567	3377.2039
482.5564	1.4121299	0.36428636	3390.0527
483.45728	1.4159949	0.36545682	3390.9292
484.35815	1.4177153	0.36642474	3389.8838
485.25903	1.4241494	0.36733869	3380.8323
486.15991	1.4215434	0.36808631	3385.0076
487.06079	1.427713	0.36893725	3391.0371
487.96167	1.4291815	0.36992976	3390.322
488.86255	1.4323694	0.37093878	3386.6487
489.76343	1.4343903	0.37187469	3396.4624
490.66431	1.4364105	0.37288585	3387.8042
491.56519	1.4381025	0.37366802	3390.0471
492.46606	1.4449677	0.37484026	3400.3806
493.36694	1.4434544	0.37572166	3392.6646
494.26782	1.4488425	0.37669104	3400.1956
495.1687	1.4535387	0.37764126	3402.4072
496.06958	1.4525898	0.37864622	3404.0435
496.97046	1.4573059	0.37959087	3400.2947
497.87134	1.4583442	0.38046691	3399.2234
498.77222	1.4616686	0.38134217	3398.9026
499.6731	1.4654096	0.38232991	3405.2319
500.57397	1.466938	0.38312349	3401.9968
501.47485	1.4691303	0.38416243	3406.967
502.37573	1.4714776	0.38514572	3407.7122
503.27661	1.4704556	0.3861846	3403.5642
504.17749	1.4777437	0.38704449	3402.5266
505.07837	1.4792674	0.38809156	3410.3516
505.97925	1.4846796	0.38899824	3406.2747
506.88013	1.4866633	0.38992336	3403.9519
507.78101	1.4865071	0.39087695	3411.0603
508.68188	1.4902426	0.39179099	3419.8953
509.58276	1.4935377	0.39294276	3420.9915
510.48364	1.4931631	0.39366755	3406.9258
511.38452	1.4999543	0.39457214	3410.7622
512.2854	1.5031372	0.39543602	3418.8186
513.18628	1.5054677	0.39652604	3419.1172
514.08716	1.5062026	0.39740291	3419.6328
514.98804	1.5097824	0.39844137	3417.7097
515.88892	1.5128547	0.39947429	3421.915
516.78979	1.5135212	0.40042368	3416.0103
517.69067	1.5183707	0.40141284	3427.4456
518.59155	1.5199344	0.4024733	3418.959
519.49243	1.5219821	0.40341648	3425.8127
520.39331	1.5242865	0.40447915	3422.0781
521.29419	1.5305197	0.40530786	3426.4834
522.19507	1.5298418	0.40632778	3428.9861
523.09595	1.534855	0.40754476	3436.6357
523.99683	1.5398847	0.40856522	3432.179
524.89771	1.5391736	0.40965915	3430.5439
525.79858	1.5429547	0.41068694	3433.9202
526.69946	1.547266	0.41165808	3431.5923
527.60034	1.5496019	0.41256377	3434.7395
528.50122	1.5503072	0.41354981	3433.179
529.4021	1.5530608	0.41442636	3437.0146
530.30298	1.5556147	0.41553596	3443.6177
531.20386	1.5594417	0.41648316	3437.0105
532.10474	1.5602342	0.41743168	3433.563
533.00562	1.5636337	0.41839647	3438.8887
533.90649	1.5653079	0.41935155	3438.28
534.80737	1.5715438	0.42031631	3447.7961
535.70825	1.5705843	0.4212223	3437.2617
536.60913	1.5742542	0.42218417	3442.2842
537.51001	1.5743998	0.42312875	3439.1589
538.41089	1.5819367	0.423904	3440.6462
539.31177	1.5842671	0.42470735	3439.3743
540.21265	1.5847355	0.42556545	3448.9888
541.11353	1.5882993	0.42667925	3450.4185
542.0144	1.5888009	0.42780888	3448.6274
542.91528	1.5942066	0.42874649	3449.0898
543.81616	1.5968359	0.42982018	3450.6514
544.71704	1.6008544	0.43092391	3450.1096
545.61792	1.6004291	0.43188897	3452.7041
546.5188	1.6058358	0.43300217	3454.0889
547.41968	1.6072315	0.43385226	3450.2766
548.32056	1.6111469	0.43488586	3456.1204
549.22144	1.6159338	0.43588051	3456.5242
550.12231	1.6167953	0.43675995	3455.6655
551.02319	1.6164483	0.43783963	3457.7478
551.92407	1.6198895	0.43881735	3458.7595
552.82495	1.6210308	0.43997943	3463.5767
553.72583	1.626399	0.44102421	3459.7158
554.62671	1.6297854	0.44191942	3457.1006
555.52759	1.6305416	0.44306624	3464.5571
556.42847	1.6345907	0.44395569	3456.1531
557.32935	1.6372889	0.44498199	3463.5674
558.23022	1.638024	0.44603175	3460.7229
559.1311	1.6423042	0.44710067	3467.3501
560.03198	1.6447105	0.44804758	3461.7124
560.93286	1.6469443	0.44896725	3462.228
561.83374	1.6533786	0.44998485	3465.8274
562.73462	1.6547749	0.45092595	3467.3486
563.6355	1.6564409	0.45184496	3468.6755
564.53638	1.6570065	0.4528096	3467.7441
565.43726	1.6614809	0.45391503	3472.7888
566.33813	1.6639127	0.45504954	3468.917
567.23901	1.6676452	0.45606714	3472.7041
568.13989	1.6660217	0.45689917	3468.1797
569.04077	1.6757084	0.45803449	3474.9106
569.94165	1.6739709	0.45897338	3473.0554
570.84253	1.6779292	0.45990342	3474.6794
571.74341	1.6799158	0.46073213	3473.6904
572.64429	1.6825057	0.46171364	3477.3203
573.54517	1.6888407	0.46285963	3478.4841
574.44604	1.6874878	0.4636367	3475.6848
575.34692	1.6915424	0.46482286	3482.925
576.2478	1.6949208	0.46609506	3482.3013
577.14868	1.6939293	0.46722442	3480.7485
578.04956	1.6978581	0.46817973	3474.8811
578.95044	1.6994617	0.46928748	3480.5374
579.85132	1.7076266	0.47038254	3485.363
580.7522	1.7088251	0.47137848	3486.5791
581.65308	1.7089636	0.47222281	3482.7688
582.55396	1.7130769	0.473061	3483.2212
583.45483	1.7172258	0.47415772	3495.1921
584.35571	1.718493	0.47541046	3485.7717
585.25659	1.7228329	0.47661844	3491.8298
586.15747	1.7249534	0.47780991	3495.5723
587.05835	1.7251858	0.47886914	3489.0039
587.95923	1.7303249	0.47967198	3483.9426
588.86011	1.7333417	0.48068842	3493.0447
589.76099	1.7364304	0.48160258	3486.9207
590.66187	1.7402689	0.48255798	3490.9846
591.56274	1.7360313	0.48351637	3491.6331
592.46362	1.7431191	0.48438564	3489.6777
593.3645	1.7486008	0.48539102	3496.437
594.26538	1.7469646	0.4863804	3493.9636
595.16626	1.7518519	0.48752594	3494.4023
596.06714	1.7507923	0.48835334	3490.6899
596.96802	1.752372	0.48942912	3495.658
597.8689	1.7579783	0.49064946	3501.8569
598.76978	1.7598654	0.49182427	3500.2698
599.67065	1.7632468	0.49279481	3492.2874
600.57153	1.7689804	0.49381939	3499.4268
601.47241	1.7691525	0.49510908	3508.6968
602.37329	1.775447	0.49626726	3504.1985
603.27417	1.7753099	0.49719828	3502.2329
604.17505	1.7779623	0.49826285	3507.1917
605.07593	1.780298	0.49947158	3500.0278
605.97681	1.7834719	0.50038737	3499.3945
606.87769	1.7866721	0.50155175	3504.4927
607.77856	1.7890151	0.50257283	3506.3425
608.67944	1.7897521	0.50349861	3503.165
609.58032	1.7953231	0.50480098	3511.325
610.4812	1.7974331	0.50594646	3507.4304
611.38208	1.7993007	0.50692695	3501.48
612.28296	1.8021151	0.50770664	3509.6016
613.18384	1.8047104	0.50865728	3507.5884
614.08472	1.8082715	0.50955701	3505.5713
614.9856	1.8109168	0.51062387	3517.844
615.88647	1.8130479	0.51188648	3519.5723
616.78735	1.8153675	0.51303959	3511.6223
617.68823	1.8170817	0.51438755	3514.9253
618.58911	1.8204737	0.51582003	3519.9451
619.48999	1.8283402	0.51687324	3518.6826
620.39087	1.827723	0.51775706	3513.9207
621.29175	1.8295103	0.51866001	3511.0598
622.19263	1.8335737	0.51973706	3516.7202
623.09351	1.8347925	0.52089059	3520.999
623.99438	1.837824	0.52190405	3519.2737
624.89526	1.8368763	0.52313834	3524.1768
625.79614	1.8435972	0.52408707	3523.574
626.69702	1.8472341	0.52523124	3518.5002
627.5979	1.8461249	0.52609497	3516.9492
628.49878	1.8531057	0.52711028	3520.7766
629.39966	1.8549075	0.5282262	3525.7871
630.30054	1.853734	0.52926636	3526.0781
631.20142	1.8601631	0.53068805	3530.01
632.10229	1.8633708	0.53187937	3529.1194
633.00317	1.8649852	0.53297514	3529.4934
633.90405	1.8664273	0.53413886	3525.0713
634.80493	1.8702086	0.53534377	3533.0793
635.70581	1.8723752	0.53643483	3525.0789
636.60669	1.8751886	0.53750104	3527.9409
637.50757	1.879793	0.53873354	3531.0371
638.40845	1.8798543	0.54004341	3532.5581
639.30933	1.8823769	0.54111695	3530.8484
640.21021	1.8858021	0.5421471	3524.6206
641.11108	1.888333	0.54296595	3527.3223
642.01196	1.8904216	0.54392725	3528.5356
642.91284	1.8948876	0.54499465	3533.2559
643.81372	1.8977134	0.54630059	3538.1445
644.7146	1.8990148	0.5474838	3535.0144
645.61548	1.902492	0.54854393	3529.9768
646.51636	1.9039619	0.54977155	3531.5698
647.41724	1.904965	0.55071068	3531.4854
648.31812	1.9093589	0.55198228	3535.6492
649.21899	1.9123584	0.55312061	3532.4873
650.11987	1.9151418	0.55441874	3539.4668
651.02075	1.917913	0.55552304	3537.03
651.92163	1.9226289	0.55686855	3542.9639
652.82251	1.9255015	0.55809146	3539.1682
653.72339	1.9262589	0.55923927	3536.6936
654.62427	1.9288511	0.56015545	3533.427
655.52515	1.9299235	0.56120336	3537.073
656.42603	1.9334197	0.56228447	3542.8579
657.3269	1.9346352	0.56356156	3539.7869
658.22778	1.9389694	0.56483388	3540.3613
659.12866	1.9427764	0.56590062	3542.4377
660.02954	1.9467638	0.56718975	3547.9797
660.93042	1.9480525	0.56833273	3546.5549
661.8313	1.9476398	0.56948167	3541.1921
662.73218	1.9551073	0.57052159	3540.0781
663.63306	1.9571942	0.57143176	3545.3091
664.53394	1.9577701	0.57292944	3549.8894
665.43481	1.963055	0.57418185	3552.7478
666.33569	1.9632171	0.57550704	3552.8018
667.23657	1.9704654	0.5768311	3548.3982
668.13745	1.9694833	0.57789516	3544.8677
669.03833	1.9718535	0.57898492	3546.2095
669.93921	1.9744581	0.58032387	3547.9204
670.84009	1.9774989	0.58174902	3547.0664
671.74097	1.9792073	0.58293629	3546.2539
672.64185	1.9845829	0.58413255	3547.8835
673.54272	1.9862036	0.58540422	3551.3206
674.4436	1.9863541	0.5866158	3553.6206
675.34448	1.991182	0.58766061	3551.7522
676.24536	1.9917587	0.58877176	3547.9583
677.14624	1.9981891	0.58972895	3547.9045
678.04712	2.0010579	0.59082806	3552.4272
678.948	2.0030887	0.59186983	3554.23
679.84888	2.0040083	0.59314364	3551.4343
680.74976	2.0043685	0.59421033	3553.8552
681.65063	2.0115969	0.59548956	3560.4065
682.55151	2.0147047	0.59690803	3562.2227
683.45239	2.0152078	0.59826392	3555.1499
684.35327	2.0166416	0.5995912	3554.5637
685.25415	2.0217242	0.60073125	3554.2793
686.15503	2.0227332	0.60186958	3553.5393
687.05591	2.0239849	0.60294002	3552.5586
687.95679	2.0258975	0.60419953	3558.2756
688.85767	2.0330081	0.60528809	3557.2114
689.75854	2.0358307	0.60652816	3566.1487
690.65942	2.037246	0.60788411	3564.6072
691.5603	2.0414326	0.60905564	3562.5164
692.46118	2.0412462	0.61024249	3562.1594
693.36206	2.0456054	0.61153519	3564.8171
694.26294	2.0462942	0.61294997	3559.72
695.16382	2.0481286	0.61420101	3561.9216
696.0647	2.0541275	0.61538106	3561.0461
696.96558	2.0564961	0.61639553	3558.0327
697.86646	2.0582423	0.61771518	3561.8958
698.76733	2.0614572	0.61887449	3560.1487
699.66821	2.0644984	0.62012345	3565.8601
700.56909	2.0655038	0.62132984	3563.6917
701.46997	2.068114	0.6225931	3564.8542
702.37085	2.0737293	0.62395376	3565.4407
703.27173	2.0740716	0.62531936	3564.7451
704.17261	2.0782657	0.62661147	3560.5391
705.07349	2.0806956	0.62767631	3567.0669
705.97437	2.0865984	0.62911355	3571.9697
706.87524	2.0872269	0.63050699	3574.5042
707.77612	2.0877495	0.63153636	3564.9744
708.677	2.0917268	0.63296664	3569.5264
709.57788	2.0960026	0.63430363	3571.4929
710.47876	2.0974004	0.63536924	3567.6553
711.37964	2.1000001	0.63680565	3576.5977
712.28052	2.1011217	0.63815755	3569.3491
713.1814	2.1054306	0.63947564	3571.9648
714.08228	2.1049843	0.64082396	3568.0637
714.98315	2.1082551	0.6420297	3568.3223
715.88403	2.1138828	0.64334667	3573.0701
716.78491	2.1170416	0.644481	3574.0408
717.68579	2.1186528	0.64559114	3566.4126
718.58667	2.1223905	0.64681929	3574.3489
719.48755	2.1239369	0.64807045	3571.1199
720.38843	2.1230459	0.64933091	3570.5044
721.28931	2.1275861	0.65084082	3576.1609
722.19019	2.1309438	0.65230811	3578.4082
723.09106	2.1338489	0.65347391	3568.4663
723.99194	2.1343293	0.65456682	3568.7861
724.89282	2.1418331	0.65593368	3571.8235
725.7937	2.1441739	0.65717524	3577.5842
726.69458	2.1434829	0.6583249	3573.0479
727.59546	2.1476903	0.66001904	3578.7256
728.49634	2.1496537	0.66151863	3575.7292
729.39722	2.1522789	0.66301864	3581.3411
730.2981	2.1567187	0.66460907	3573.999
731.19897	2.1587658	0.66613579	3577.4797
732.09985	2.1599486	0.66754293	3570.7507
733.00073	2.1622047	0.66852814	3566.3218
733.90161	2.1656063	0.66981089	3574.0139
734.80249	2.1691911	0.6711458	3582.6448
735.70337	2.1716716	0.6725561	3573.3442
736.60425	2.1745143	0.6740123	3579.344
737.50513	2.1778715	0.67558581	3576.5952
738.40601	2.1796107	0.67723852	3582.1521
739.30688	2.1817994	0.67861187	3574.0603
740.20776	2.1874793	0.67996013	3577.2649
741.10864	2.1862812	0.68123049	3582.7478
742.00952	2.1902943	0.68259645	3579.9539
742.9104	2.1911755	0.68385708	3573.1179
743.81128	2.1978998	0.68537933	3583.0085
744.71216	2.2013464	0.68682683	3582.6638
745.61304	2.2005301	0.68801785	3575.1748
746.51392	2.2042716	0.68957978	3583.7405
747.41479	2.2096434	0.69116551	3587.6509
748.31567	2.2093604	0.69265372	3580.6375
749.21655	2.2119031	0.69405109	3580.7661
750.11743	2.2168782	0.69561213	3582.8638
751.01831	2.2180679	0.6967954	3571.73
751.91919	2.2190416	0.69787425	3576.8772
752.82007	2.2225816	0.69922698	3579.3501
753.72095	2.2278407	0.70055079	3580.1729
754.62183	2.2300103	0.7021637	3591.6941
755.52271	2.2310112	0.70368689	3582.8462
756.42358	2.2343888	0.70527834	3587.3721
757.32446	2.2364712	0.70680535	3580.5264
758.22534	2.2419376	0.70830542	3584.217
759.12622	2.2437878	0.70993727	3587.8601
760.0271	2.2445726	0.71139556	3584.072
760.92798	2.2504165	0.71288091	3586.6489
761.82886	2.2506025	0.71431363	3584.8721
762.72974	2.2512767	0.71580178	3581.9504
763.63062	2.2577984	0.71732998	3584.8955
764.53149	2.2603161	0.71866322	3583.593
765.43237	2.2608979	0.72043723	3587.2476
766.33325	2.2661288	0.72186548	3584.905
767.23413	2.2678311	0.723445	3580.3525
768.13501	2.2713244	0.7247963	3584.7886
769.03589	2.2710133	0.72622347	3586.1045
769.93677	2.2769079	0.72773862	3587.1697
770.83765	2.2790723	0.72918409	3589.4558
771.73853	2.2815969	0.73093176	3587.6091
772.6394	2.2847176	0.73280412	3592.2461
773.54028	2.2859154	0.73471856	3589.2258
774.44116	2.2871478	0.73632592	3585.519
775.34204	2.2895141	0.73788649	3583.2351
776.24292	2.2930229	0.73931068	3589.1946
777.1438	2.2964654	0.74088711	3588.1882
778.04468	2.2996562	0.74241066	3583.208
778.94556	2.3025696	0.74403173	3591.8557
779.84644	2.3044622	0.74550831	3587.1799
780.74731	2.3076713	0.74702388	3585.9619
781.64819	2.3106081	0.74837339	3589.3066
782.54907	2.3146889	0.7497887	3586.9475
783.44995	2.316323	0.75128895	3592.0146
784.35083	2.3184044	0.75300008	3586.1472
785.25171	2.3199637	0.75437593	3586.2251
786.15259	2.323988	0.75597692	3589.8206
787.05347	2.3265641	0.75751722	3585.0491
787.95435	2.32687	0.75910264	3592.8687
788.85522	2.3312912	0.76101577	3588.01
789.7561	2.3356116	0.76265162	3585.874
790.65698	2.3383749	0.76424652	3586.7256
791.55786	2.3398089	0.76571035	3589.2996
792.45874	2.3453584	0.76728874	3586.2886
793.35962	2.3458979	0.76878053	3587.2847
794.2605	2.3499396	0.77023619	3584.3474
795.16138	2.3514271	0.77186984	3590.3406
796.06226	2.3526449	0.77343464	3590.0757
796.96313	2.3563745	0.77518946	3589.0999
797.86401	2.357507	0.77709222	3595.1077
798.76489	2.3590121	0.77895141	3587.9419
799.66577	2.3642948	0.78073096	3583.4597
800.56665	2.3665903	0.78233731	3586.2434
801.46753	2.3676441	0.78406781	3589.4243
802.36841	2.3722215	0.78621197	3588.8958
803.26929	2.3770983	0.78803366	3589.2031
804.17017	2.3782759	0.78968889	3587.5295
805.07104	2.3790894	0.79158026	3587.8755
805.97192	2.3835487	0.79335332	3592.7329
806.8728	2.3875296	0.79533678	3588.9617
807.77368	2.3912392	0.79706299	3585.1108
808.67456	2.3920565	0.79886448	3590.2625
809.57544	2.3933384	0.80052751	3584.9116
810.47632	2.3946612	0.80223757	3585.0178
811.3772	2.396179	0.80364829	3589.3916
812.27808	2.4020836	0.80555403	3590.3765
813.17896	2.4027686	0.80728102	3582.6262
814.07983	2.4078279	0.80901712	3581.5403
814.98071	2.40713	0.81077152	3588.0793
815.88159	2.414556	0.81236523	3585.1521
816.78247	2.4171016	0.81424761	3590.5107
817.68335	2.4174078	0.81605291	3587.5471
818.58423	2.4207301	0.81796652	3587.0142
819.48511	2.4245207	0.81976527	3584.8032
820.38599	2.4271894	0.8216024	3589.0156
821.28687	2.4303298	0.82331783	3586.9817
822.18774	2.4317853	0.82504988	3581.3608
823.08862	2.4359827	0.82685792	3590.9966
823.9895	2.4351375	0.82866842	3587.8181
824.89038	2.436069	0.83104771	3587.0112
825.79126	2.4432538	0.83349538	3593.1069
826.69214	2.4439495	0.83548576	3581.8748
827.59302	2.4479325	0.83731043	3584.2717
828.4939	2.4490051	0.83930027	3584.4429
829.39478	2.452409	0.84132755	3586.7981
830.29565	2.4560513	0.84310603	3581.4856
831.19653	2.4579368	0.84485948	3589.0676
832.09741	2.4621501	0.84692079	3585.2959
832.99829	2.46452	0.84898311	3587.2048
833.89917	2.4642787	0.85115004	3587.9204
834.80005	2.4711714	0.8531757	3584.5618
835.70093	2.4751921	0.85535634	3590.5588
836.60181	2.4737186	0.85765254	3584.2483
837.50269	2.4766321	0.85961223	3580.9854
838.40356	2.4808517	0.86164612	3583.6169
839.30444	2.4821022	0.86332953	3579.1357
840.20532	2.4848719	0.86540473	3583.2681
841.1062	2.4855738	0.86761189	3581.6221
842.00708	2.4897294	0.86986923	3587.5383
842.90796	2.4929035	0.87162173	3579.4336
843.80884	2.4955812	0.87363917	3582.344
844.70972	2.4990208	0.87585014	3577.0603
845.6106	2.5016077	0.87767828	3579.9021
846.51147	2.5043664	0.87991256	3581.9038
847.41235	2.5049303	0.88233924	3582.0435
848.31323	2.5126483	0.88455576	3582.6716
849.21411	2.5137696	0.88651031	3576.8274
850.11499	2.5166752	0.88876241	3581.3416
851.01587	2.519706	0.89130884	3586.8088
851.91675	2.5190852	0.89353991	3575.4385
852.81763	2.5246162	0.89552712	3576.5605
853.71851	2.5225325	0.89758384	3580.7148
854.61938	2.5292749	0.89987814	3574.3513
855.52026	2.5313888	0.90196365	3574.0117
856.42114	2.5325201	0.90415061	3570.3152
857.32202	2.5392308	0.90590692	3570.7834
858.2229	2.5402341	0.90774119	3574.9209
859.12378	2.5421183	0.90978575	3573.0991
860.02466	2.5450115	0.91185826	3576.8716
860.92554	2.5517724	0.9139359	3577.0723
861.82642	2.552851	0.91625369	3578.3083
862.72729	2.5541587	0.91820842	3574.552
863.62817	2.5550284	0.92072427	3573.8293
864.52905	2.5611608	0.92357856	3585.4343
865.42993	2.5614166	0.9265998	3571.9531
866.33081	2.5634315	0.92912513	3569.6445
867.23169	2.5673912	0.93161345	3570.5935
868.13257	2.570163	0.93380231	3565.2998
869.03345	2.5709848	0.93585432	3563.3042
869.93433	2.5764022	0.9380523	3569.511
870.83521	2.5766213	0.94031942	3566.8044
871.73608	2.5799861	0.94246751	3567.2771
872.63696	2.5846386	0.94490159	3567.9077
873.53784	2.5836394	0.94763207	3566.4539
874.43872	2.589077	0.9505018	3563.2097
875.3396	2.5892408	0.95294058	3564.0659
876.24048	2.5954609	0.95515198	3560.0771
877.14136	2.5983953	0.95816314	3567.3174
878.04224	2.6002145	0.96044379	3558.3555
878.94312	2.6020064	0.96277547	3562.135
879.84399	2.6033132	0.96499902	3558.5181
880.74487	2.6055613	0.96702462	3554.51
881.64575	2.6084487	0.96914369	3553.866
882.54663	2.613831	0.97167712	3556.2285
883.44751	2.6144495	0.97435987	3560.1755
884.34839	2.6189728	0.97744846	3559.605
885.24927	2.6224382	0.98053628	3555.1108
886.15015	2.6223435	0.98285294	3550.1934
887.05103	2.6264246	0.9855476	3550.4495
887.9519	2.629674	0.98771423	3545.929
888.85278	2.631732	0.9899227	3545.8223
889.75366	2.6353846	0.9923256	3546.6519
890.65454	2.6376026	0.99534529	3554.5571
891.55542	2.6414979	0.99827814	3548.4753
892.4563	2.6434398	1.0009156	3545.8293
893.35718	2.6443825	1.0035167	3541.9648
894.25806	2.6487875	1.0059772	3544.2788
895.15894	2.6510904	1.0084978	3548.6812
896.05981	2.651149	1.0109698	3542.9634
896.96069	2.6563308	1.0133121	3543.6123
897.86157	2.6608915	1.0157063	3541.03
898.76245	2.6635859	1.0181009	3539.7566
899.66333	2.6638606	1.0204314	3535.2
900.56421	2.6656275	1.0229825	3537.427
901.46509	2.6690855	1.0259439	3537.7412
902.36597	2.6706958	1.0287771	3533.208
903.26685	2.6772859	1.0312099	3532.551
904.16772	2.6807334	1.0339899	3536.2278
905.0686	2.6794562	1.0369771	3528.8503
905.96948	2.6825991	1.0395092	3532.0181
906.87036	2.6848452	1.0429825	3534.8274
907.77124	2.688905	1.0460613	3527.3474
908.67212	2.6915331	1.048929	3523.1113
909.573	2.6932986	1.0516936	3517.9905
910.47388	2.6973989	1.054706	3523.8691
911.37476	2.7003987	1.0572135	3516.4851
912.27563	2.7029164	1.0594274	3515.5615
913.17651	2.7065871	1.0618727	3518.3125
914.07739	2.7093978	1.0644382	3520.0002
914.97827	2.7100766	1.0667821	3511.8662
915.87915	2.7111855	1.0695781	3516.6755
916.78003	2.7152932	1.0726197	3511.0042
917.68091	2.7170968	1.0753162	3508.6626
918.58179	2.7216384	1.078241	3505.437
919.48267	2.7246902	1.0812945	3506.4326
920.38354	2.7272315	1.0838215	3503.5352
921.28442	2.7313726	1.0863082	3502.3989
922.1853	2.7315755	1.0891806	3504.1287
923.08618	2.7353935	1.0923589	3503.6162
923.98706	2.7376466	1.0955732	3502.9063
924.88794	2.7387185	1.0987328	3498.4873
925.78882	2.7444139	1.1014656	3493.5481
926.6897	2.7454586	1.1040256	3489.967
927.59058	2.7483163	1.1069911	3492.8921
928.49146	2.7505736	1.1096674	3490.0979
929.39233	2.7540247	1.1122628	3489.0496
930.29321	2.7574654	1.1152036	3486.5725
931.19409	2.7595036	1.1179788	3485.8018
932.09497	2.7602122	1.1210123	3482.4136
932.99585	2.7639647	1.1237218	3478.5928
933.89673	2.767339	1.1263064	3477.0605
934.79761	2.7704806	1.1289809	3475.0754
935.69849	2.7736046	1.131809	3476.3767
936.59937	2.7772999	1.1345174	3474.5032
937.50024	2.7794011	1.1372447	3470.345
938.40112	2.7812674	1.1398737	3472.0439
939.302	2.7834232	1.1427964	3474.7813
940.20288	2.7850211	1.1456224	3466.8376
941.10376	2.7911077	1.1486549	3462.0713
942.00464	2.7886512	1.1516751	3460.5146
942.90552	2.7949016	1.1552404	3465.0408
943.8064	2.7976089	1.1582671	3456.6626
944.70728	2.8007071	1.1613572	3453.2766
945.60815	2.8007882	1.1638421	3444.7466
946.50903	2.8059556	1.1661484	3444.8706
947.40991	2.80687	1.1689587	3443.2891
948.31079	2.8091013	1.171968	3446.0911
949.21167	2.8109281	1.1749052	3436.3665
950.11255	2.8175611	1.1777805	3440.3669
951.01343	2.8182759	1.1802484	3434.1428
951.91431	2.8226783	1.1828012	3442.9563
952.81519	2.8242369	1.1857878	3430.2859
953.71606	2.8268187	1.188854	3434.5317
954.61694	2.8300619	1.1916207	3421.7485
955.51782	2.8304358	1.1942501	3426.7275
956.4187	2.8348651	1.1975963	3430.6052
957.31958	2.8381608	1.2008618	3424.4827
958.22046	2.8407001	1.2037448	3414.4504
959.12134	2.8417544	1.2065312	3417.8081
960.02222	2.8465991	1.2096734	3414.5767
960.9231	2.8475089	1.2122239	3408.4548
961.82397	2.8506265	1.2149844	3404.4246
962.72485	2.8498669	1.2177539	3403.5493
963.62573	2.8562639	1.2206109	3402.8203
964.52661	2.859565	1.2236456	3402.4822
965.42749	2.8604496	1.2264999	3401.969
966.32837	2.8645787	1.2292325	3394.0742
967.22925	2.8659387	1.2317988	3392.5491
968.13013	2.872438	1.2346052	3395.1606
969.03101	2.8731799	1.2374636	3387.334
969.93188	2.874913	1.2401659	3382.7834
970.83276	2.8761573	1.2430186	3387.1399
971.73364	2.8786767	1.2461786	3380.0525
972.63452	2.8812954	1.24919	3377.7559
973.5354	2.8865347	1.2528566	3379.552
974.43628	2.8886895	1.2557374	3370.1335
975.33716	2.8903043	1.2586187	3369.9321
976.23804	2.8967052	1.2616203	3367.0498
977.13892	2.8968551	1.265228	3365.376
978.03979	2.8987579	1.2684366	3356.2437
978.94067	2.9023545	1.2715943	3352.2148
979.84155	2.9061909	1.2750269	3353.6799
980.74243	2.9059448	1.2780634	3345.2021
981.64331	2.9110863	1.281249	3341.7913
982.54419	2.9150414	1.2839787	3340.9312
983.44507	2.9186165	1.2868733	3337.5928
984.34595	2.9177196	1.2893448	3335.8176
985.24683	2.9215989	1.2923112	3334.1353
986.14771	2.9262323	1.2956474	3334.2068
987.04858	2.9269931	1.2988368	3325.2156
987.94946	2.9281328	1.301948	3318.1731
988.85034	2.9316354	1.3047332	3313.4919
989.75122	2.9342654	1.3076307	3313.5286
990.6521	2.9396586	1.3104105	3313.8843
991.55298	2.9393499	1.3132594	3305.7732
992.45386	2.942431	1.3160832	3303.0796
993.35474	2.9438806	1.3191845	3301.2783
994.25562	2.9499147	1.3223162	3298.0073
995.15649	2.9508164	1.3249277	3293.9502
996.05737	2.9552121	1.3280237	3299.4944
996.95825	2.9553192	1.3308949	3286.0464
997.85913	2.9592712	1.3334978	3282.9812
998.76001	2.9599352	1.3362573	3281.3406
999.66089	2.9644947	1.3395841	3280.5317
1000.5618	2.9680054	1.3422167	3268.5552
1001.4626	2.971971	1.3451728	3270.2373
1002.3635	2.972894	1.3479047	3262.2151
1003.2644	2.979511	1.3511125	3267.5786
1004.1653	2.9788821	1.3542694	3261.6133
1005.0662	2.9815261	1.3573654	3256.7427
1005.967	2.9826803	1.3600112	3245.415
1006.8679	2.9884379	1.3626816	3245.0293
1007.7688	2.9870377	1.3655766	3243.8831
1008.6697	2.9895566	1.368504	3239.3252
1009.5706	2.9980752	1.3709135	3228.1321
1010.4714	2.9969192	1.3726861	3222.5728
1011.3723	3.0011129	1.3750576	3230.5825
1012.2732	3.0040138	1.3777443	3227.8301
1013.1741	3.0081239	1.3809193	3227.9949
1014.075	3.0062692	1.3836383	3215.4397
1014.9758	3.0132587	1.3868313	3219.0103
1015.8767	3.0161068	1.3901249	3209.8262
1016.7776	3.0160205	1.3936747	3206.3235
1017.6785	3.0223496	1.3968554	3200.7217
1018.5793	3.0238945	1.3998604	3203.3247
1019.4802	3.0259101	1.4032873	3193.7834
1020.3811	3.0290556	1.4064754	3189.5881
1021.282	3.0311353	1.4095075	3182.6809
1022.1829	3.030977	1.4124556	3173.4353
1023.0837	3.0344913	1.4152251	3171.3652
1023.9846	3.0365365	1.4178749	3163.822
1024.8855	3.0414171	1.4207646	3167.3564
1025.7864	3.0441737	1.4243983	3164.6304
1026.6873	3.0465157	1.4275444	3153.0286
1027.5881	3.0471592	1.4306561	3149.7549
1028.489	3.0542331	1.4340073	3154.5769
1029.3899	3.0540733	1.4370186	3136.4592
1030.2908	3.0551739	1.4397938	3134.7952
1031.1917	3.0614386	1.4423325	3124.2666
1032.0925	3.061681	1.4453731	3131.0164
1032.9934	3.0655324	1.4491204	3127.6602
1033.8943	3.0715094	1.452427	3119.05
1034.7952	3.0680606	1.4553373	3108.5732
1035.696	3.0733893	1.4584819	3101.6106
1036.5969	3.0767617	1.461283	3102.3186
1037.4978	3.0771391	1.4640713	3093.9768
1038.3987	3.0810676	1.4672666	3094.7004
1039.2996	3.0833914	1.4709549	3084.9089
1040.2004	3.0866747	1.4746156	3085.3938
1041.1013	3.0886581	1.4780377	3068.7021
1042.0022	3.0907402	1.4811172	3067.0195
1042.9031	3.098654	1.4846816	3059.6138
1043.804	3.0946386	1.4882215	3055.1589
1044.7048	3.0990763	1.4915723	3044.1069
1045.6057	3.1036947	1.4944215	3041.5776
1046.5066	3.1086223	1.4974428	3038.2849
1047.4075	3.107748	1.5003599	3034.5422
1048.3083	3.1111202	1.5038437	3021.364
1049.2092	3.1127014	1.5070388	3020.8108
1050.1101	3.1159503	1.5093957	3006.7749
1051.011	3.1202452	1.5120233	3011.0759
1051.9119	3.1184993	1.515344	3008.6848
1052.8127	3.1235044	1.5191785	3000.5698
1053.7136	3.1280746	1.5226648	2992.5298
1054.6145	3.1316569	1.5263236	2982.2375
1055.5154	3.1323609	1.5295106	2979.4502
1056.4163	3.1346359	1.532673	2969.157
1057.3171	3.1409879	1.5366683	2961.6431
1058.218	3.1418612	1.5398449	2952.6299
1059.1189	3.1450422	1.542922	2954.9751
1060.0198	3.1453097	1.5462028	2940.0381
1060.9207	3.1467018	1.5497544	2930.438
1061.8215	3.151299	1.552873	2923.0898
1062.7224	3.1536803	1.5556988	2920.4104
1063.6233	3.1556401	1.5587571	2914.6431
1064.5242	3.1586485	1.5624003	2909.8938
1065.425	3.1622846	1.5663559	2897.5862
1066.3259	3.1673579	1.570189	2892.5254
1067.2268	3.1673803	1.5737157	2883.5786
1068.1277	3.1715746	1.576861	2875.0959
1069.0286	3.1724532	1.5797518	2862.9692
1069.9294	3.1751006	1.5825994	2854.679
1070.8303	3.1785843	1.5857322	2845.1563
1071.7312	3.1827013	1.5889028	2837.0549
1072.6321	3.1833231	1.5922812	2828.3569
1073.533	3.189141	1.5958282	2825.8645
1074.4338	3.1904147	1.5994481	2810.5371
1075.3347	3.1935565	1.6031433	2799.8225
1076.2356	3.1978626	1.6073366	2775.9102
1077.1365	3.2005289	1.6144361	2739.7976
1078.0374	3.2015729	1.6227826	2680.939
1078.738	3.2053721	1.6353413	2581.0637