File: datasets/am_bench_2022/raw_data/60-XY.04-2/specimen.dat
MTS793|MPT|ENU|1|2|.|/|:|1|0|0|A

Operator Information						Time:	11.743652	Sec	11/1/2021 1:08:53 PM
Operator	Nick Derimow
Project	AM Bench 2022 mini-tensile challenge
Specimen ID	60-XY.04-2
Material	PBF-L Inconel 625
Specimen Width	2.55	mm
Specimen Thickness	1.5	mm
Notes
Operator Information End

Data Acquisition						Time:	1012.7388	Sec	11/1/2021 1:25:34 PM
Time	Axial Displacement	Axial Extensometer	Axial Force
Sec	mm	mm	N
11.858643	0.0021550951	4.4507862e-05	41.780762
12.759521	0.0032983355	3.0430531e-06	55.076702
13.6604	0.0059020901	0.00015123967	64.704399
14.561279	0.012120019	0.00017846865	83.782875
15.462158	0.014752253	0.00024061106	98.613937
16.363037	0.015047706	0.0002760572	105.57645
17.263916	0.01926513	0.00021046853	117.22203
18.164795	0.019309182	0.00035814368	126.62853
19.065674	0.022980725	0.00033696616	138.64093
19.966553	0.025483264	0.00044495906	151.47287
20.867432	0.029865215	0.0005279266	162.47096
21.768311	0.032209169	0.00056865381	174.84514
22.669189	0.032680828	0.00079550699	192.78407
23.570068	0.036125608	0.00070031162	203.85109
24.470947	0.037991293	0.00088868628	223.61308
25.371826	0.041687936	0.00091932568	240.38466
26.272705	0.043866284	0.00095325563	258.32233
27.173584	0.048094571	0.0011048104	266.55106
28.074463	0.049236018	0.001080032	286.16486
28.975342	0.05247099	0.0012824007	308.94498
29.876221	0.052193977	0.0012992745	318.17456
30.7771	0.060577191	0.0014066158	343.61182
31.677979	0.061172809	0.0014789423	355.46475
32.578857	0.063924856	0.0015235051	373.27335
33.479736	0.062943682	0.0016977874	393.03329
34.380615	0.0660045	0.0017924624	414.01498
35.281494	0.073070318	0.0019525826	439.89182
36.182373	0.07171271	0.0020015065	457.20834
37.083252	0.077534586	0.00204777	481.48563
37.984131	0.079215713	0.0022975134	503.2261
38.88501	0.081596136	0.0023602911	531.18671
39.785889	0.083206378	0.0024578418	542.65063
40.686768	0.087275408	0.0025681551	568.59503
41.587646	0.091583192	0.0026468721	590.82324
42.488525	0.094656967	0.0027548445	615.98718
43.389404	0.096186884	0.0027970029	632.61182
44.290283	0.097180553	0.0029457107	658.38989
45.191162	0.10230728	0.003174158	693.13312
46.092041	0.10374597	0.0032480764	713.63702
46.99292	0.10532568	0.0032679508	729.40106
47.893799	0.10921288	0.0034407468	755.17279
48.794678	0.1118172	0.0036283715	786.34155
49.695557	0.11506794	0.0035999983	808.75439
50.596436	0.11670236	0.0038437375	834.96436
51.497314	0.12107509	0.0038372467	859.34625
52.398193	0.12228374	0.0040636808	883.22729
53.299072	0.12491634	0.0040964922	912.51166
54.199951	0.12803145	0.0042411932	943.81049
55.10083	0.13224846	0.0043659369	957.71307
56.001709	0.13342044	0.0044192127	982.18793
56.902588	0.13430065	0.0046615424	1014.4249
57.803467	0.13515361	0.0046062097	1036.8368
58.704346	0.14092569	0.0048774001	1066.8013
59.605225	0.14735758	0.0049705189	1090.0607
60.506104	0.1474881	0.0050430698	1121.1799
61.406982	0.14909834	0.0052138036	1144.4918
62.307861	0.15256238	0.0053245667	1162.988
63.20874	0.15617926	0.0053979154	1188.6858
64.109619	0.15664232	0.0055543403	1214.1523
65.010498	0.15918353	0.0056179459	1238.1088
65.911377	0.16118142	0.0057228734	1263.3324
66.812256	0.16397567	0.0058479132	1287.6052
67.713135	0.16718529	0.005899549	1302.0657
68.614014	0.17055979	0.0059597734	1330.4036
69.514893	0.17337392	0.0061129616	1355.4198
70.415771	0.17539312	0.0063256319	1388.1293
71.31665	0.18071936	0.0064435899	1414.4081
72.217529	0.18220319	0.0065268278	1436.255
73.118408	0.1858418	0.0066575883	1461.6
74.019287	0.18558793	0.0068284282	1489.14
74.920166	0.18868323	0.0068820799	1514.861
75.821045	0.19118878	0.0070388401	1541.7048
76.721924	0.1963065	0.0071377205	1572.8032
77.622803	0.19711213	0.0072557111	1581.8536
78.523682	0.2011013	0.0073714815	1619.7062
79.424561	0.20552342	0.007583553	1643.3645
80.325439	0.20455469	0.0076074065	1666.207
81.226318	0.20997031	0.0077014915	1687.5298
82.127197	0.21016435	0.0079657603	1709.7941
83.028076	0.21092178	0.0079553314	1737.6233
83.928955	0.21515995	0.0081090024	1761.2476
84.829834	0.22042395	0.0082694879	1785.1584
85.730713	0.21849778	0.0084046768	1811.163
86.631592	0.22601266	0.0083978502	1827.7964
87.532471	0.22641528	0.0085514626	1853.3383
88.43335	0.22964804	0.0086100129	1877.906
89.334229	0.23308565	0.0087673916	1896.9338
90.235107	0.23231792	0.0087823486	1917.9856
91.135986	0.23794986	0.0090727089	1938.02
92.036865	0.24108511	0.0091515332	1960.4274
92.937744	0.24407837	0.0092502898	1983.9181
93.838623	0.24298465	0.0092851706	1997.1958
94.739502	0.24817526	0.0094511826	2022.0725
95.640381	0.25298667	0.0094806664	2042.8047
96.54126	0.25348026	0.0096140495	2062.6516
97.442139	0.25818634	0.0098002767	2081.2708
98.343018	0.26167312	0.0098814946	2105.4968
99.243896	0.26045385	0.010078474	2125.6816
100.14478	0.26468351	0.010072368	2132.7168
101.04565	0.26752886	0.010166625	2150.6716
101.94653	0.27281049	0.010207512	2168.5559
102.84741	0.27139303	0.010334245	2183.7148
103.74829	0.27706969	0.010486431	2199.3755
104.64917	0.28040403	0.010579607	2219.9539
105.55005	0.28354606	0.010567199	2234.3464
106.45093	0.28303504	0.010682392	2251.3457
107.35181	0.2869859	0.010830943	2267.261
108.25269	0.28751063	0.010910707	2269.2053
109.15356	0.29632351	0.011042253	2290.4751
110.05444	0.29512161	0.011081313	2300.7139
110.95532	0.29716888	0.011178582	2317.8064
111.8562	0.30350503	0.011262353	2331.7849
112.75708	0.3058635	0.011334338	2344.686
113.65796	0.30446392	0.011450301	2349.4053
114.55884	0.30756101	0.011490099	2365.9915
115.45972	0.31079358	0.01154603	2370.7678
116.3606	0.31263775	0.011699791	2388.3516
117.26147	0.31744158	0.011700406	2397.489
118.16235	0.32175243	0.011815913	2416.8167
119.06323	0.3233481	0.01188226	2423.7864
119.96411	0.32387081	0.012035288	2436.9375
120.86499	0.32660666	0.012027866	2438.4341
121.76587	0.32874218	0.012200854	2451.4839
122.66675	0.33092016	0.012298536	2461.2437
123.56763	0.33417708	0.012304155	2466.3103
124.46851	0.33771902	0.012506031	2485.5579
125.36938	0.34157953	0.012603115	2502.8481
126.27026	0.34458849	0.012681166	2504.2271
127.17114	0.34833017	0.012743952	2521.5405
128.07202	0.35015145	0.012857615	2526.7537
128.9729	0.35302559	0.012995072	2536.1633
129.87378	0.35463932	0.013083285	2537.5874
130.77466	0.35802755	0.013237008	2552.0898
131.67554	0.36121723	0.013337359	2564.6077
132.57642	0.36543489	0.013455554	2575.7202
133.47729	0.36700147	0.01358398	2582.9519
134.37817	0.36855987	0.013663107	2585.5854
135.27905	0.36937138	0.013793195	2592.2549
136.17993	0.37402463	0.013860021	2601.6733
137.08081	0.37924355	0.014185081	2618.1824
137.98169	0.3811093	0.014235808	2620.7119
138.88257	0.38238284	0.014365626	2627.7031
139.78345	0.38667545	0.0144236	2633.6084
140.68433	0.3862288	0.014523143	2638.6963
141.58521	0.39280698	0.014840864	2652.7703
142.48608	0.39244309	0.014956269	2648.0767
143.38696	0.39679512	0.015099457	2667.3335
144.28784	0.40220562	0.015295709	2677.8108
145.18872	0.401676	0.0155302	2680.3501
146.0896	0.40355545	0.01566752	2681.8059
146.99048	0.40539044	0.015898043	2694.0986
147.89136	0.41083819	0.016177574	2705.6428
148.79224	0.41528919	0.016466644	2710.9177
149.69312	0.4134841	0.016799944	2722.3059
150.59399	0.41919109	0.016959276	2722.988
151.49487	0.41944125	0.017293882	2726.8276
152.39575	0.42470589	0.017525125	2738.8521
153.29663	0.42750588	0.017874897	2748.8127
154.19751	0.42982176	0.018151527	2758.4646
155.09839	0.43212596	0.018500961	2755.5632
155.99927	0.43437642	0.018821951	2772.1763
156.90015	0.43615851	0.019301146	2771.2632
157.80103	0.43721721	0.019629123	2775.9185
158.7019	0.44117644	0.020140268	2784.1094
159.60278	0.44492328	0.020536063	2789.7686
160.50366	0.44909975	0.02109652	2799.688
161.40454	0.45267764	0.021488037	2803.4431
162.30542	0.45265326	0.021908542	2802.8093
163.2063	0.4576436	0.022445958	2811.9902
164.10718	0.45963937	0.022868466	2815.6609
165.00806	0.46225891	0.023496117	2826.8123
165.90894	0.46484417	0.024004249	2825.2742
166.80981	0.46568096	0.02455331	2825.0339
167.71069	0.4695015	0.024999024	2835.0901
168.61157	0.47259372	0.025515474	2832.6541
169.51245	0.47411579	0.026069297	2843.0261
170.41333	0.47796482	0.026626589	2848.198
171.31421	0.48243675	0.027430322	2856.7461
172.21509	0.48447621	0.028034236	2853.2554
173.11597	0.48572215	0.028757505	2856.7224
174.01685	0.48763865	0.029391283	2859.1501
174.91772	0.4929356	0.030097125	2867.8291
175.8186	0.49666256	0.030877054	2874.1899
176.71948	0.49756408	0.031511214	2879.9944
177.62036	0.50115639	0.03240953	2884.6013
178.52124	0.50292605	0.033105548	2889.6326
179.42212	0.50577009	0.033936605	2892.2361
180.323	0.51132482	0.034809485	2888.1172
181.22388	0.510611	0.035414781	2891.6609
182.12476	0.5094263	0.036011588	2893.571
183.02563	0.51430696	0.036808554	2896.0085
183.92651	0.51956624	0.037769787	2913.6091
184.82739	0.51954556	0.038533792	2905.0876
185.72827	0.52448994	0.039298743	2911.3772
186.62915	0.52824861	0.040184114	2924.3965
187.53003	0.52739793	0.041015606	2917.6265
188.43091	0.53190219	0.041899189	2923.1626
189.33179	0.53254694	0.042876501	2926.9673
190.23267	0.53667384	0.043859765	2930.7139
191.13354	0.53954476	0.044792105	2928.1895
192.03442	0.5409103	0.045745455	2932.2266
192.9353	0.54274487	0.046512246	2931.5366
193.83618	0.54820698	0.047346611	2941.9248
194.73706	0.55126619	0.048432223	2943.2578
195.63794	0.55466533	0.049424462	2949.0647
196.53882	0.55880362	0.050271884	2948.9482
197.4397	0.55975127	0.051125418	2951.7747
198.34058	0.56028414	0.051945351	2952.6472
199.24146	0.56264937	0.052960776	2959.2632
200.14233	0.56875098	0.054029558	2967.5837
201.04321	0.57442904	0.055087615	2972.8669
201.94409	0.57492137	0.055976294	2967.8484
202.84497	0.57865983	0.056981716	2974.0876
203.74585	0.57640314	0.057791915	2967.2483
204.64673	0.58232445	0.058728475	2972.9519
205.54761	0.58225375	0.059523448	2970.2915
206.44849	0.58581597	0.060558628	2975.1804
207.34937	0.59049338	0.061602041	2986.6699
208.25024	0.59169322	0.062720478	2977.0701
209.15112	0.59324342	0.063565552	2982.6919
210.052	0.59704119	0.064503685	2984.7317
210.95288	0.59959453	0.065374561	2990.2131
211.85376	0.60092914	0.066457547	2991.7473
212.75464	0.60653085	0.067617111	2999.1262
213.65552	0.60761505	0.068483777	2995.7163
214.5564	0.61019546	0.069573686	2998.2078
215.45728	0.61109304	0.07055936	2998.4678
216.35815	0.61611468	0.071525015	3003.2603
217.25903	0.62109631	0.072479568	3015.8635
218.15991	0.61936527	0.073589131	3006.5706
219.06079	0.62440509	0.074663296	3010.8918
219.96167	0.62827539	0.075647123	3014.0505
220.86255	0.62937403	0.076850154	3019.3381
221.76343	0.63550431	0.077804737	3013.6001
222.66431	0.63310879	0.078654565	3013.7893
223.56519	0.637429	0.079670347	3018.543
224.46606	0.64444733	0.080618642	3021.2146
225.36694	0.64256477	0.081654899	3028.2583
226.26782	0.64647716	0.082577676	3028.8765
227.1687	0.65055424	0.083590485	3030.7576
228.06958	0.64939785	0.084652774	3035.2234
228.97046	0.65585053	0.085644178	3034.8193
229.87134	0.65897739	0.086723424	3041.9282
230.77222	0.66045344	0.087740429	3043.6968
231.6731	0.65907019	0.088637941	3038.0024
232.57397	0.66549444	0.089845784	3046.188
233.47485	0.66814613	0.090998054	3043.4573
234.37573	0.67219865	0.092005894	3052.1956
235.27661	0.67374289	0.093113512	3052.5376
236.17749	0.67447656	0.094196156	3055.7898
237.07837	0.67823303	0.095184125	3053.6516
237.97925	0.67977911	0.096451767	3058.6516
238.88013	0.68406045	0.097623445	3062.6997
239.78101	0.68500441	0.098618045	3054.0508
240.68188	0.68931216	0.099736825	3063.2756
241.58276	0.69439071	0.10063323	3064.8479
242.48364	0.69629109	0.10176534	3071.8845
243.38452	0.69761425	0.10292572	3068.1128
244.2854	0.70046943	0.10402308	3070.2686
245.18628	0.70092404	0.10504162	3072.3347
246.08716	0.70516461	0.10592235	3072.8064
246.98804	0.71061134	0.10698614	3081.2781
247.88892	0.71120268	0.10797339	3071.6438
248.78979	0.71305424	0.10892034	3079.6768
249.69067	0.7135421	0.10986877	3086.2346
250.59155	0.72144806	0.1110457	3084.438
251.49243	0.71875769	0.11207081	3081.0767
252.39331	0.72430694	0.1129593	3080.5024
253.29419	0.72678447	0.11408707	3092.0237
254.19507	0.72754788	0.11517286	3089.0237
255.09595	0.73360932	0.11629763	3092.479
255.99683	0.73608738	0.11729243	3095.4851
256.89771	0.74075401	0.11833104	3088.7461
257.79858	0.73948836	0.11911916	3094.3049
258.69946	0.74253976	0.12015009	3095.3943
259.60034	0.74908841	0.12121616	3103.7502
260.50122	0.74682462	0.12226649	3103.6318
261.4021	0.75308108	0.12341605	3107.8259
262.30298	0.75235766	0.12462125	3105.481
263.20386	0.75589442	0.12582748	3103.7332
264.10474	0.76258135	0.12682211	3110.4756
265.00562	0.75870979	0.12794665	3111.7622
265.90649	0.76450628	0.12908073	3116.886
266.80737	0.76690394	0.13044806	3118.2302
267.70825	0.7724967	0.13127123	3114.4507
268.60913	0.77350396	0.13223654	3112.6414
269.51001	0.77893764	0.13328509	3126.1536
270.41089	0.77835512	0.13433501	3117.8269
271.31177	0.7791208	0.13525023	3120.2422
272.21265	0.78640705	0.13633999	3129.8364
273.11353	0.78947747	0.13739502	3131.2441
274.0144	0.79135448	0.13841131	3135.0237
274.91528	0.7941193	0.13938887	3128.8687
275.81616	0.7969287	0.14039026	3130.8936
276.71704	0.79646254	0.14147851	3136.2026
277.61792	0.80039561	0.14253119	3136.8843
278.5188	0.80337691	0.14362755	3134.6763
279.41968	0.80460829	0.1445663	3137.4099
280.32056	0.80616796	0.14559528	3140.3254
281.22144	0.81140327	0.14666332	3136.3755
282.12231	0.8146776	0.14783698	3147.3882
283.02319	0.81508738	0.14887546	3141.9658
283.92407	0.81580383	0.14981779	3143.0225
284.82495	0.82151514	0.15100159	3150.134
285.72583	0.82174176	0.15206008	3145.5374
286.62671	0.82484907	0.15310688	3151.0876
287.52759	0.82629287	0.15396503	3147.5022
288.42847	0.83275509	0.15494956	3156.3853
289.32935	0.83358306	0.1562033	3159.0974
290.23022	0.83932441	0.15741144	3163.9639
291.1311	0.83858192	0.15871345	3161.4785
292.03198	0.84076399	0.15971464	3151.856
292.93286	0.8492136	0.16080213	3167.4634
293.83374	0.85175955	0.16166201	3163.645
294.73462	0.84931606	0.16269818	3161.3596
295.6355	0.85699934	0.16357504	3166.5596
296.53638	0.85432923	0.1645827	3167.9094
297.43726	0.85739928	0.16551837	3160.7104
298.33813	0.86404508	0.16659419	3177.6946
299.23901	0.8632372	0.16762918	3177.0767
300.13989	0.86650783	0.16878566	3180.4775
301.04077	0.87252909	0.1700772	3179.5315
301.94165	0.87255776	0.1712046	3178.9014
302.84253	0.87689447	0.1722165	3181.1831
303.74341	0.88128233	0.17343947	3194.7322
304.64429	0.88238418	0.17432363	3184.0491
305.54517	0.88002574	0.17553636	3185.3896
306.44604	0.88827378	0.17673297	3186.7087
307.34692	0.88918304	0.17772216	3188.7947
308.2478	0.88813281	0.17866385	3182.7224
309.14868	0.89661783	0.17977266	3197.071
310.04956	0.89849567	0.18082629	3196.5408
310.95044	0.90047348	0.18193799	3192.0935
311.85132	0.90331566	0.18286717	3192.4553
312.7522	0.90303743	0.1837637	3200.1685
313.65308	0.90535349	0.18485062	3199.5891
314.55396	0.91080701	0.18590792	3195.1558
315.45483	0.91541684	0.18709926	3213.2466
316.35571	0.91400695	0.18826765	3209.5972
317.25659	0.91860527	0.18929422	3207.1958
318.15747	0.92324412	0.19019333	3203.1169
319.05835	0.92265427	0.191109	3202.6396
319.95923	0.9264636	0.1921061	3208.7725
320.86011	0.93064022	0.19316217	3216.552
321.76099	0.93387562	0.19413483	3213.1938
322.66187	0.93503284	0.19527687	3213.2603
323.56274	0.93805021	0.19620474	3215.7131
324.46362	0.93955123	0.19731778	3219.2866
325.3645	0.94422823	0.19826908	3215.4426
326.26538	0.94768554	0.19918253	3221.0425
327.16626	0.94920087	0.20027792	3221.4683
328.06714	0.95171261	0.20137472	3231.6135
328.96802	0.95764536	0.20245311	3225.8562
329.8689	0.95716614	0.20333137	3225.3179
330.76978	0.95870119	0.20428106	3221.3081
331.67065	0.96160525	0.2054377	3222.7488
332.57153	0.96294415	0.20635973	3232.6235
333.47241	0.96643305	0.20748587	3237.3562
334.37329	0.96851104	0.20845996	3224.6917
335.27417	0.97351867	0.20959793	3239.6543
336.17505	0.97806537	0.21071558	3236.2764
337.07593	0.9770745	0.21173956	3231.4934
337.97681	0.98016036	0.21279724	3239.2385
338.87769	0.98327118	0.21390185	3234.4597
339.77856	0.98547113	0.21501908	3238.9866
340.67944	0.99161422	0.2160712	3240.6174
341.58032	0.99285179	0.21706553	3242.7471
342.4812	0.99576575	0.21812265	3242.2258
343.38208	0.99645704	0.21921545	3245.4446
344.28296	1.0004761	0.22033702	3249.1357
345.18384	1.0034312	0.22138011	3244.0203
346.08472	1.0043517	0.2222393	3247.4314
346.9856	1.0073885	0.22338662	3255.9138
347.88647	1.0102112	0.22452088	3253.2908
348.78735	1.0141934	0.22568524	3257.9314
349.68823	1.0171907	0.22683205	3257.937
350.58911	1.0192109	0.22799914	3261.3982
351.48999	1.0225223	0.22893479	3253.6514
352.39087	1.0242411	0.22978237	3257.0645
353.29175	1.0286667	0.23068261	3261.6636
354.19263	1.0280482	0.23173253	3259.0195
355.09351	1.0302286	0.23278841	3262.9224
355.99438	1.0378236	0.23382597	3272.2168
356.89526	1.0391327	0.23502849	3274.2854
357.79614	1.0446638	0.23604165	3272.897
358.69702	1.042343	0.2370625	3267.8855
359.5979	1.0435708	0.23799051	3272.3281
360.49878	1.0474628	0.2389461	3275.8398
361.39966	1.0524697	0.23993987	3277.4097
362.30054	1.0540223	0.24092248	3279.7659
363.20142	1.056349	0.24196067	3272.5176
364.10229	1.0596522	0.24319783	3283.6809
365.00317	1.0607822	0.24431419	3276.24
365.90405	1.0656309	0.24550901	3286.0439
366.80493	1.0667396	0.24656589	3280.7368
367.70581	1.0678411	0.24742362	3275.7612
368.60669	1.0712516	0.24839555	3285.7683
369.50757	1.0771512	0.24947891	3284.9568
370.40845	1.08033	0.25069275	3292
371.30933	1.0789925	0.25192362	3291.1724
372.21021	1.0860974	0.25314438	3295.0505
373.11108	1.0868587	0.25409937	3291.9167
374.01196	1.0886165	0.25529122	3298.1675
374.91284	1.0895435	0.25632113	3291.3833
375.81372	1.0975685	0.25718132	3291.918
376.7146	1.0962082	0.25822702	3292.7207
377.61548	1.1017538	0.25934616	3308.2896
378.51636	1.1017559	0.26027808	3296.813
379.41724	1.1020644	0.26150158	3298.4265
380.31812	1.1072081	0.2626341	3303.2834
381.21899	1.1109779	0.26353392	3297.5261
382.11987	1.1158665	0.26439452	3305.5005
383.02075	1.1182778	0.26529953	3307.1689
383.92163	1.1184213	0.26646486	3311.9392
384.82251	1.1214805	0.26763374	3310.1826
385.72339	1.1236188	0.26870471	3310.8047
386.62427	1.12701	0.26993248	3317.8516
387.52515	1.1289279	0.27076328	3304.9485
388.42603	1.1327921	0.27165452	3309.2209
389.3269	1.133554	0.27264756	3311.687
390.22778	1.1352617	0.27373055	3311.6108
391.12866	1.1403946	0.27476856	3319.8528
392.02954	1.1449275	0.2757673	3316.3164
392.93042	1.1459974	0.27654982	3317.7283
393.8313	1.1495861	0.27752826	3317.4961
394.73218	1.1522464	0.27851284	3325.4309
395.63306	1.1548107	0.27956301	3327.1433
396.53394	1.1585759	0.28039441	3324.9182
397.43481	1.1567018	0.28155896	3323.7024
398.33569	1.1631572	0.28242615	3325.448
399.23657	1.1639891	0.28361905	3327.3394
400.13745	1.1664081	0.28466526	3325.6848
401.03833	1.1689982	0.28590649	3335.3145
401.93921	1.1734177	0.28706771	3335.739
402.84009	1.1753483	0.28828788	3333.0654
403.74097	1.1761932	0.28930628	3334.8284
404.64185	1.1817663	0.29045466	3332.9219
405.54272	1.1827531	0.29135293	3332.6787
406.4436	1.1853166	0.29244003	3338.6963
407.34448	1.192871	0.29350564	3343.0679
408.24536	1.1944342	0.29454255	3341.8928
409.14624	1.1953231	0.29539064	3338.0088
410.04712	1.1982154	0.29656556	3341.9629
410.948	1.1995258	0.29759866	3343.2649
411.84888	1.200431	0.29871646	3341.2666
412.74976	1.2043712	0.29965058	3345.7288
413.65063	1.2099528	0.30062237	3351.624
414.55151	1.2109847	0.30165359	3344.4946
415.45239	1.2165147	0.30265549	3355.0979
416.35327	1.2155659	0.30382779	3354.6172
417.25415	1.2210208	0.30472505	3353.304
418.15503	1.2232152	0.30558112	3344.8281
419.05591	1.2249267	0.3064073	3354.8811
419.95679	1.2270231	0.30761096	3358.4597
420.85767	1.2317742	0.30880305	3362.0408
421.75854	1.2331593	0.3097035	3355.699
422.65942	1.2368953	0.31076387	3360.8816
423.5603	1.2365226	0.3117829	3358.0615
424.46118	1.2406027	0.31280518	3365.179
425.36206	1.2452167	0.31374228	3361.1621
426.26294	1.2477857	0.31453323	3365.1978
427.16382	1.2499526	0.31562716	3370.4282
428.0647	1.2525684	0.31661397	3363.9548
428.96558	1.2557251	0.31769496	3369.646
429.86646	1.2555516	0.31865224	3366.3252
430.76733	1.2619183	0.31974098	3372.0198
431.66821	1.2603974	0.32073632	3362.5481
432.56909	1.2634183	0.32178017	3372.248
433.46997	1.2668887	0.32295132	3370.8843
434.37085	1.2690908	0.32388666	3372.051
435.27173	1.2729235	0.32491294	3370.4863
436.17261	1.2758784	0.3259165	3380.7607
437.07349	1.2783397	0.32684207	3377.3835
437.97437	1.2842861	0.3279939	3372.1851
438.87524	1.2825965	0.32896698	3377.1838
439.77612	1.286427	0.32995057	3377.2834
440.677	1.2885362	0.33103737	3379.8511
441.57788	1.2916123	0.33207089	3384.0896
442.47876	1.2939659	0.33304369	3387.6165
443.37964	1.2984005	0.33434305	3392.457
444.28052	1.3013895	0.33530858	3384.1357
445.1814	1.3048787	0.33623692	3385.0364
446.08228	1.3059716	0.33729091	3389.8975
446.98315	1.3080865	0.33836222	3394.2615
447.88403	1.3131906	0.33935323	3391.3872
448.78491	1.312664	0.34037748	3388.2698
449.68579	1.3153141	0.34133497	3391.3564
450.58667	1.3193976	0.34252653	3393.7798
451.48755	1.3196448	0.34347287	3396.1609
452.38843	1.3245212	0.34467986	3393.2209
453.28931	1.3259078	0.34568548	3394.5977
454.19019	1.3284862	0.3467795	3396.7556
455.09106	1.3349373	0.34772307	3400.446
455.99194	1.3382059	0.34872711	3396.6331
456.89282	1.3347687	0.34969962	3395.9705
457.7937	1.3414136	0.35085711	3409.9998
458.69458	1.3416728	0.35177898	3399.3101
459.59546	1.3461146	0.35286546	3405.3296
460.49634	1.3502238	0.35379058	3411.4338
461.39722	1.3505359	0.3548508	3408.1836
462.2981	1.3517238	0.35605088	3407.6555
463.19897	1.3576263	0.35744274	3416.5383
464.09985	1.3590552	0.35873941	3409.6729
465.00073	1.3642374	0.35961291	3405.4788
465.90161	1.3643101	0.36056265	3411.9692
466.80249	1.3694226	0.36174092	3414.9272
467.70337	1.3692718	0.36283761	3411.0149
468.60425	1.373306	0.36387181	3411.8516
469.50513	1.3739108	0.36495736	3414.5469
470.40601	1.3792784	0.36595476	3416.8701
471.30688	1.3813109	0.36682636	3420.2966
472.20776	1.3834897	0.36772817	3420.7078
473.10864	1.3836045	0.36886495	3419.1931
474.00952	1.3899374	0.36989063	3422.6736
474.9104	1.3936473	0.37086385	3425.8235
475.81128	1.3954608	0.37206668	3428.2231
476.71216	1.3971249	0.37301996	3424.8606
477.61304	1.3995918	0.37408066	3428.5813
478.51392	1.4035695	0.37522638	3425.2454
479.41479	1.4055048	0.37635979	3423.666
480.31567	1.4121326	0.37759826	3435.8977
481.21655	1.4091799	0.37868512	3429.96
482.11743	1.4138927	0.37982723	3429.7788
483.01831	1.4203414	0.38073474	3431.1257
483.91919	1.4180641	0.38157639	3436.4949
484.82007	1.4206096	0.38264179	3434.7979
485.72095	1.4239115	0.3837105	3434.1194
486.62183	1.4272624	0.38480344	3437.9783
487.52271	1.4284235	0.3860302	3441.8972
488.42358	1.4325448	0.38711271	3435.3003
489.32446	1.435068	0.38790774	3431.3948
490.22534	1.4367102	0.388998	3440.2317
491.12622	1.4398968	0.39008257	3439.3416
492.0271	1.4435803	0.39106664	3442.5479
492.92798	1.447951	0.3923527	3449.3042
493.82886	1.4495569	0.39333105	3441.6875
494.72974	1.4526209	0.39420655	3446.3105
495.63062	1.4509062	0.39524689	3443.7639
496.53149	1.4563023	0.39626831	3446.1392
497.43237	1.459419	0.39734676	3444.1436
498.33325	1.4636725	0.39838096	3445.8884
499.23413	1.4626745	0.39937085	3449.5203
500.13501	1.4666932	0.40053129	3447.2407
501.03589	1.4706367	0.4015843	3451.6604
501.93677	1.471079	0.40261018	3452.3291
502.83765	1.4743342	0.40348759	3451.0308
503.73853	1.4776404	0.40455675	3449.8945
504.6394	1.479954	0.40565145	3456.1863
505.54028	1.4851227	0.40691963	3460.6807
506.44116	1.486335	0.40787587	3454.8486
507.34204	1.4890894	0.40879759	3454.6294
508.24292	1.4931576	0.40978706	3458.1641
509.1438	1.4949892	0.41080827	3456.4958
510.04468	1.49575	0.41182187	3462.0364
510.94556	1.5012614	0.41298163	3460.9817
511.84644	1.5017246	0.41400924	3460.334
512.74731	1.5072894	0.41500244	3469.1123
513.64819	1.5072871	0.41633567	3467.1663
514.54907	1.5084679	0.41763031	3472.1746
515.44995	1.5124241	0.41876113	3464.113
516.35083	1.5132422	0.4196924	3469.7512
517.25171	1.5188606	0.4208366	3470.3286
518.15259	1.5193355	0.42176512	3467.5615
519.05347	1.5227051	0.42276904	3465.5801
519.95435	1.5269941	0.42373019	3471.6506
520.85522	1.5284029	0.42485732	3469.6672
521.7561	1.5331087	0.42613974	3483.0801
522.65698	1.5353075	0.42740431	3480.718
523.55786	1.5375346	0.42852423	3480.4998
524.45874	1.5414203	0.4295955	3473.1096
525.35962	1.5417852	0.43078563	3473.5632
526.2605	1.5471195	0.43181586	3476.9395
527.16138	1.5460116	0.43268603	3469.4063
528.06226	1.5491539	0.43371975	3470.449
528.96313	1.5547323	0.43474069	3482.7837
529.86401	1.557693	0.43583128	3483.1274
530.76489	1.5572354	0.43683907	3480.5076
531.66577	1.5627635	0.43788174	3486.6316
532.56665	1.5677428	0.43907589	3479.7068
533.46753	1.5680237	0.44002816	3483.0149
534.36841	1.5696174	0.44105038	3490.5957
535.26929	1.5722597	0.44214922	3483.6223
536.17017	1.5753037	0.44331029	3491.6797
537.07104	1.5788351	0.44433433	3483.2109
537.97192	1.5799214	0.44537932	3490.5474
538.8728	1.5843624	0.44634956	3487.1604
539.77368	1.5857111	0.44732878	3490.3005
540.67456	1.5885835	0.44839308	3491.1125
541.57544	1.5914305	0.44948956	3488.156
542.47632	1.5954792	0.45043394	3500.6069
543.3772	1.5991217	0.45162773	3504.866
544.27808	1.6017053	0.45286369	3497.5481
545.17896	1.6000016	0.45396915	3496.3364
546.07983	1.6058855	0.45519212	3503.384
546.98071	1.6091282	0.45619404	3501.0286
547.88159	1.6109991	0.45723823	3492.4033
548.78247	1.6136351	0.45830068	3501.9824
549.68335	1.6191254	0.45926523	3503.6064
550.58423	1.6201473	0.46054736	3508.9834
551.48511	1.6221969	0.46171516	3508.4526
552.38599	1.6232191	0.46277094	3501.8411
553.28687	1.6268573	0.46393129	3503.2644
554.18774	1.6312888	0.46508038	3509.7422
555.08862	1.6338651	0.46630642	3508.0896
555.9895	1.6350853	0.46742189	3514.3254
556.89038	1.6367549	0.46855545	3507.8579
557.79126	1.6403749	0.46953622	3507.8455
558.69214	1.6408924	0.470689	3508.7532
559.59302	1.6503687	0.47186482	3516.9165
560.4939	1.6463336	0.47294676	3506.6855
561.39478	1.6521721	0.47405902	3515.8831
562.29565	1.6530122	0.47511858	3508.6392
563.19653	1.6554942	0.4762345	3514.0933
564.09741	1.6588898	0.47734264	3516.1301
564.99829	1.6626753	0.47839698	3521.3948
565.89917	1.6660322	0.47951442	3517.4534
566.80005	1.6674153	0.48047641	3513.323
567.70093	1.6709149	0.48143435	3514.2419
568.60181	1.6728482	0.48257551	3516.3115
569.50269	1.6771499	0.48368567	3517.1321
570.40356	1.6765738	0.48447922	3510.8152
571.30444	1.6822031	0.48545766	3523.2917
572.20532	1.6847079	0.48643813	3521.4512
573.1062	1.6836563	0.48748964	3519.0852
574.00708	1.6905098	0.48854378	3526.5898
574.90796	1.6890742	0.48972324	3526.002
575.80884	1.6943855	0.49082851	3526.0127
576.70972	1.6991701	0.49194703	3528.1353
577.6106	1.6998075	0.49320596	3530.3477
578.51147	1.704891	0.49442056	3533.1184
579.41235	1.7045925	0.49555987	3528.7673
580.31323	1.7076416	0.4967252	3527.5583
581.21411	1.7082382	0.49779013	3527.7542
582.11499	1.7123992	0.49895298	3531.0957
583.01587	1.7164044	0.500063	3531.9673
583.91675	1.7177756	0.50116169	3527.8242
584.81763	1.7223892	0.50240266	3540.2896
585.71851	1.7270979	0.50367332	3534.4692
586.61938	1.7294227	0.50474161	3533.1738
587.52026	1.7305441	0.50590575	3543.3391
588.42114	1.7334661	0.50700295	3540.2339
589.32202	1.7368821	0.50794184	3537.5024
590.2229	1.7376658	0.50899214	3535.0398
591.12378	1.7429187	0.51026243	3542.8721
592.02466	1.7415	0.51123488	3530.9553
592.92554	1.7459539	0.51241022	3543.8274
593.82642	1.7481384	0.51378131	3543.0747
594.72729	1.7535819	0.51495111	3546.5137
595.62817	1.7516247	0.51598978	3540.5684
596.52905	1.7580452	0.51706338	3540.8552
597.42993	1.7588277	0.51799399	3536.7312
598.33081	1.7589252	0.51911694	3542.3855
599.23169	1.7648857	0.52017087	3545.9568
600.13257	1.7696917	0.52121896	3544.394
601.03345	1.7697484	0.52241272	3551.8289
601.93433	1.773065	0.52371538	3552.6902
602.83521	1.7740167	0.52490723	3549.7107
603.73608	1.7780565	0.52600586	3544.2996
604.63696	1.7821219	0.52702051	3551.4973
605.53784	1.7839731	0.52803892	3552.3074
606.43872	1.788553	0.52916968	3547.9619
607.3396	1.7873734	0.53043467	3563.0229
608.24048	1.7890934	0.5316422	3553.6584
609.14136	1.7963387	0.53280967	3553.6958
610.04224	1.7984132	0.53391051	3554.4807
610.94312	1.8025634	0.5350709	3556.3916
611.84399	1.8017185	0.53636312	3554.6553
612.74487	1.8045517	0.53741199	3556.1631
613.64575	1.8088318	0.53870094	3561.7654
614.54663	1.8121923	0.53990221	3565.3745
615.44751	1.813436	0.54109681	3559.8528
616.34839	1.814857	0.54217255	3557.9441
617.24927	1.8184563	0.54334301	3561.165
618.15015	1.8203133	0.54462957	3562.478
619.05103	1.8228021	0.54576963	3560.2871
619.9519	1.8282446	0.54685473	3559.241
620.85278	1.8280201	0.54816031	3565.1921
621.75366	1.8311694	0.54913545	3557.4661
622.65454	1.8361528	0.55046618	3571.2866
623.55542	1.8394492	0.55168432	3569.6692
624.4563	1.8389268	0.5527606	3569.2725
625.35718	1.8427081	0.55389297	3562.561
626.25806	1.8433185	0.55502731	3567.7441
627.15894	1.8496206	0.55617607	3567.5439
628.05981	1.8509766	0.5571751	3570.2476
628.96069	1.8576838	0.55843997	3568.0159
629.86157	1.856526	0.55952835	3569.0103
630.76245	1.8587185	0.56068712	3572.3123
631.66333	1.8629236	0.56207323	3569.3508
632.56421	1.8665049	0.56327409	3575.1453
633.46509	1.8677986	0.56441432	3571.4165
634.36597	1.8711112	0.56563139	3578.0938
635.26685	1.8722686	0.56677502	3577.6709
636.16772	1.8743523	0.5677343	3569.1179
637.0686	1.8782108	0.56899035	3574.021
637.96948	1.8823278	0.56998587	3574.5933
638.87036	1.879789	0.5712229	3572.1902
639.77124	1.8885492	0.57238984	3582.2747
640.67212	1.8856931	0.57361257	3578.303
641.573	1.8926145	0.57463825	3579.0798
642.47388	1.8942761	0.57570767	3576.9971
643.37476	1.8978513	0.57666332	3576.9358
644.27563	1.9005483	0.57762849	3580.0071
645.17651	1.9013164	0.5788452	3585.8887
646.07739	1.9055896	0.5804019	3588.1946
646.97827	1.9045748	0.58173633	3582.7854
647.87915	1.9076512	0.5828408	3582.5149
648.78003	1.912991	0.58419126	3581.0171
649.68091	1.9123394	0.58511037	3574.1255
650.58179	1.9197929	0.58617532	3583.8037
651.48267	1.9212068	0.587192	3586.0447
652.38354	1.9234393	0.58829981	3588.4714
653.28442	1.9264612	0.58975005	3593.2969
654.1853	1.9289149	0.59119982	3591.4136
655.08618	1.9318593	0.59241337	3585.1279
655.98706	1.9347471	0.59352857	3588.2732
656.88794	1.9404465	0.59472322	3590.9297
657.78882	1.9438075	0.59589976	3597.6753
658.6897	1.9438325	0.59723645	3595.5291
659.59058	1.9474105	0.59857959	3595.3459
660.49146	1.9504054	0.59999353	3596.6604
661.39233	1.9519137	0.6012845	3596.2144
662.29321	1.9524544	0.60230547	3591.05
663.19409	1.9592874	0.60347944	3594.344
664.09497	1.958994	0.60477012	3594.1619
664.99585	1.9642011	0.60608625	3596.7534
665.89673	1.965458	0.60721612	3597.0908
666.79761	1.9672359	0.60837024	3595.9041
667.69849	1.9734228	0.6093654	3596.644
668.59937	1.9729947	0.6104809	3603.4775
669.50024	1.9739286	0.61178643	3600.9473
670.40112	1.9790293	0.61294276	3597.325
671.302	1.9789313	0.61424154	3599.5588
672.20288	1.9840463	0.61540627	3600.1689
673.10376	1.9859037	0.61647433	3601.4873
674.00464	1.9902343	0.61759412	3591.7642
674.90552	1.9906018	0.61854714	3597.4656
675.8064	1.9939728	0.61965585	3601.2363
676.70728	1.9994802	0.62087673	3607.1433
677.60815	1.9984136	0.62196797	3603.1062
678.50903	2.0024393	0.6232003	3600.3447
679.40991	2.0050344	0.6244328	3610.4392
680.31079	2.0106533	0.62590319	3609.1023
681.21167	2.0121441	0.62699622	3606.3088
682.11255	2.0124292	0.62826866	3608.7397
683.01343	2.0161636	0.629614	3608.3918
683.91431	2.0174828	0.63077891	3604.5996
684.81519	2.0222321	0.63206887	3603.418
685.71606	2.0252123	0.63337767	3609.2087
686.61694	2.0246236	0.63471591	3609.8027
687.51782	2.0295796	0.63599199	3609.644
688.4187	2.0334594	0.63704938	3606.0007
689.31958	2.0347447	0.63826549	3610.1733
690.22046	2.037329	0.63945001	3618.5317
691.12134	2.0423703	0.64085871	3620.0781
692.02222	2.0456972	0.64234191	3622.116
692.9231	2.0456674	0.64354485	3616.6794
693.82397	2.0503016	0.64497215	3617.1904
694.72485	2.0535204	0.64602619	3613.2744
695.62573	2.0527954	0.6472705	3609.1455
696.52661	2.0571206	0.64841878	3612.8445
697.42749	2.0627251	0.64967662	3619.2256
698.32837	2.0602565	0.65102774	3618.075
699.22925	2.0649428	0.65228218	3612.2966
700.13013	2.0680664	0.65354675	3617.2117
701.03101	2.0706196	0.65479058	3621.0154
701.93188	2.0714252	0.65605587	3614.5955
702.83276	2.075417	0.65740216	3621.6787
703.73364	2.0795727	0.65890634	3624.3821
704.63452	2.0844064	0.66013104	3623.916
705.5354	2.0849469	0.66119081	3620.073
706.43628	2.0904412	0.66243798	3624.2991
707.33716	2.0876338	0.66363603	3615.584
708.23804	2.0905597	0.66501027	3632.7139
709.13892	2.093004	0.66594166	3614.8716
710.03979	2.0969002	0.66701198	3615.3762
710.94067	2.0978773	0.66806942	3619.459
711.84155	2.1038804	0.66928792	3625.3608
712.74243	2.1046202	0.67041922	3618.749
713.64331	2.1088119	0.6716696	3623.9456
714.54419	2.1086483	0.67282528	3621.6589
715.44507	2.1146357	0.67442101	3633.364
716.34595	2.1174653	0.67591596	3627.2412
717.24683	2.119096	0.67723924	3626.9905
718.14771	2.12306	0.67858768	3626.2302
719.04858	2.1229768	0.67995566	3629.2747
719.94946	2.1248748	0.68130052	3627.0613
720.85034	2.1281204	0.68248928	3626.7817
721.75122	2.1320732	0.68369311	3629.1885
722.6521	2.1341283	0.68486029	3630.0166
723.55298	2.1383622	0.68628776	3636.5793
724.45386	2.1411767	0.68759841	3628.2439
725.35474	2.1411788	0.68907624	3628.5837
726.25562	2.1490014	0.69021267	3628.1045
727.15649	2.1478317	0.69132954	3624.6855
728.05737	2.1514583	0.6925711	3635.1504
728.95825	2.1510777	0.69397742	3632.5161
729.85913	2.1572576	0.69575036	3639.3606
730.76001	2.1607885	0.69717419	3636.2776
731.66089	2.1613591	0.69849694	3633.6084
732.56177	2.166888	0.69966394	3631.2036
733.46265	2.1712852	0.70087701	3635.2664
734.36353	2.1684942	0.70207804	3633.8313
735.2644	2.1734107	0.70316589	3630.2048
736.16528	2.1764786	0.7044667	3638.27
737.06616	2.1795208	0.70587897	3638.7439
737.96704	2.1804814	0.7071718	3640.7832
738.86792	2.1844735	0.70847917	3639.0139
739.7688	2.1859763	0.70982724	3636.5159
740.66968	2.1914306	0.71108776	3638.1685
741.57056	2.1919515	0.71255034	3646.2202
742.47144	2.1938133	0.71420288	3644.4109
743.37231	2.1980848	0.71562737	3639.8533
744.27319	2.1976564	0.71676892	3635.7788
745.17407	2.2021353	0.71802968	3637.2542
746.07495	2.2037327	0.7192477	3639.4939
746.97583	2.2061875	0.72046822	3635.3506
747.87671	2.2119882	0.72161055	3644.5933
748.77759	2.2129569	0.72276139	3641.8232
749.67847	2.2180061	0.72397369	3639.2588
750.57935	2.2185609	0.72528392	3646.1135
751.48022	2.2217348	0.72696692	3645.6018
752.3811	2.2230747	0.7282784	3640.3191
753.28198	2.2267504	0.72961795	3646.9431
754.18286	2.2280161	0.73097217	3645.9622
755.08374	2.2313652	0.73225588	3648.873
755.98462	2.2367158	0.73377615	3645.1287
756.8855	2.2392247	0.73520017	3649.3977
757.78638	2.2420349	0.73662823	3650.9214
758.68726	2.2420156	0.73802316	3645.2891
759.58813	2.2461548	0.73934442	3648.8909
760.48901	2.2478516	0.74098289	3640.7883
761.38989	2.2525969	0.74222988	3644.1643
762.29077	2.2553566	0.74360287	3649.2666
763.19165	2.2541933	0.74479449	3643.6514
764.09253	2.2620378	0.74602759	3648.1899
764.99341	2.2619207	0.74715787	3643.5391
765.89429	2.2638035	0.74835098	3641.3623
766.79517	2.2662728	0.74960369	3646.4587
767.69604	2.2722092	0.75098968	3654.5359
768.59692	2.2729428	0.75259489	3656.7859
769.4978	2.2752919	0.75427669	3650.6401
770.39868	2.2781017	0.75577915	3651.3835
771.29956	2.2828889	0.75741702	3653.3708
772.20044	2.2828505	0.75872296	3648.7627
773.10132	2.285651	0.76001078	3651.8059
774.0022	2.2898135	0.76113707	3647.105
774.90308	2.2936535	0.76254606	3652.7434
775.80396	2.2970021	0.76399261	3653.8335
776.70483	2.2963116	0.76532978	3647.8772
777.60571	2.3008289	0.76669657	3650.9707
778.50659	2.3038998	0.76807547	3653.4272
779.40747	2.3049407	0.76944613	3654.5188
780.30835	2.307303	0.77070433	3649.0525
781.20923	2.3120229	0.77187061	3648.957
782.11011	2.3137658	0.7731812	3650.4221
783.01099	2.3154843	0.7745108	3653.1902
783.91187	2.319288	0.77594054	3657.4382
784.81274	2.3223169	0.77736574	3659.4626
785.71362	2.3251748	0.7787376	3658.584
786.6145	2.3261201	0.78023583	3659.0117
787.51538	2.3277781	0.78188688	3661.8054
788.41626	2.3349173	0.78346938	3659.0859
789.31714	2.337858	0.78494596	3658.1931
790.21802	2.3360183	0.78641009	3661.6162
791.1189	2.3369241	0.78800631	3655.2026
792.01978	2.3434846	0.78943294	3653.7944
792.92065	2.3470385	0.79040879	3647.6655
793.82153	2.3508129	0.79176825	3660.1021
794.72241	2.352921	0.79306751	3657.6453
795.62329	2.3540254	0.79446912	3662.1536
796.52417	2.3604238	0.79601312	3663.6716
797.42505	2.3578169	0.79756248	3656.6365
798.32593	2.3608212	0.79917377	3666.5254
799.22681	2.364161	0.80091465	3665.0269
800.12769	2.3663855	0.80235213	3660.502
801.02856	2.3699164	0.80392879	3659.9519
801.92944	2.3740504	0.80542338	3660.6733
802.83032	2.3758707	0.80694014	3660.3479
803.7312	2.3773704	0.80819762	3661.5247
804.63208	2.3817692	0.80968386	3666.627
805.53296	2.3848009	0.81105596	3656.8755
806.43384	2.3855987	0.81218755	3660.063
807.33472	2.3883107	0.81372839	3665.6729
808.2356	2.3937373	0.81534868	3669.918
809.13647	2.392915	0.8170296	3662.8723
810.03735	2.3947971	0.81863475	3663.2268
810.93823	2.4000244	0.82017624	3664.21
811.83911	2.3999736	0.82177371	3663.8333
812.73999	2.409133	0.82289046	3659.2209
813.64087	2.4101102	0.8241666	3661.6404
814.54175	2.4108949	0.82551295	3668.4504
815.44263	2.4145129	0.8270095	3668.8931
816.34351	2.4183671	0.82847285	3664.2083
817.24438	2.4199378	0.82998133	3669.5784
818.14526	2.4235437	0.83159435	3671.9573
819.04614	2.4226329	0.83312267	3668.1624
819.94702	2.4289806	0.83475369	3669.1414
820.8479	2.4285467	0.83613777	3662.8706
821.74878	2.4318874	0.8376261	3665.8174
822.64966	2.4346061	0.83912259	3668.3572
823.55054	2.4394033	0.84064502	3666.2263
824.45142	2.4395149	0.8422541	3667.7661
825.35229	2.4433119	0.84396052	3676.5461
826.25317	2.4480584	0.84546775	3674.8506
827.15405	2.4495251	0.84708971	3669.1279
828.05493	2.4511223	0.84864724	3669.5967
828.95581	2.4541614	0.85029566	3672.8125
829.85669	2.4547517	0.85188258	3666.6216
830.75757	2.4592636	0.85368842	3674.5867
831.65845	2.4651933	0.85531706	3664.1895
832.55933	2.4639816	0.85679144	3669.2559
833.46021	2.4684319	0.8583926	3672.7629
834.36108	2.4699895	0.85979605	3668.0034
835.26196	2.4732609	0.86132538	3671.1802
836.16284	2.4769223	0.86283463	3674.8965
837.06372	2.4801328	0.86431956	3670.6235
837.9646	2.479929	0.86588162	3668.6121
838.86548	2.4849131	0.86727792	3669.7849
839.76636	2.4883602	0.86869788	3674.1182
840.66724	2.4898465	0.8704887	3669.4187
841.56812	2.4912353	0.87209266	3669.946
842.46899	2.4979002	0.87341124	3666.6851
843.36987	2.4977505	0.87499887	3673.0872
844.27075	2.4989109	0.87675267	3671.762
845.17163	2.5035572	0.87848115	3676.2458
846.07251	2.504185	0.88009328	3671.2148
846.97339	2.5079627	0.88190269	3670.3193
847.87427	2.5121603	0.88353705	3672.3213
848.77515	2.5149243	0.88507909	3671.1396
849.67603	2.5166652	0.88665956	3671.5552
850.5769	2.5186296	0.88822979	3670.897
851.47778	2.5228548	0.89001358	3674.7056
852.37866	2.5252357	0.89156842	3665.1426
853.27954	2.5278974	0.89288485	3665.6277
854.18042	2.5277052	0.89425904	3669.9902
855.0813	2.5317898	0.89579725	3675.1272
855.98218	2.5361164	0.89731717	3672.8596
856.88306	2.5388482	0.89877397	3671.8352
857.78394	2.5390713	0.90040731	3678.9102
858.68481	2.5423989	0.90202802	3672.3662
859.58569	2.5474424	0.90361547	3671.5256
860.48657	2.5502224	0.90521091	3675.1565
861.38745	2.5479729	0.90668237	3667.9639
862.28833	2.5523264	0.90835911	3673.3247
863.18921	2.5546608	0.91015142	3678.9412
864.09009	2.5598962	0.91201878	3677.666
864.99097	2.5644608	0.91374415	3676.4968
865.89185	2.5653374	0.9154312	3673.2515
866.79272	2.5675485	0.91720468	3676.4595
867.6936	2.5691881	0.91897911	3675.0122
868.59448	2.5713038	0.92032927	3668.8496
869.49536	2.5740323	0.92185849	3666.4883
870.39624	2.5782497	0.92338693	3674.4907
871.29712	2.5813818	0.92517519	3676.1489
872.198	2.584204	0.92686665	3676.4128
873.09888	2.5864284	0.92884898	3677.1416
873.99976	2.5906684	0.93088096	3677.5261
874.90063	2.5906789	0.9327271	3671.1228
875.80151	2.5931914	0.93477231	3675.4185
876.70239	2.5980036	0.93653893	3673.4434
877.60327	2.6020489	0.93798918	3673.9446
878.50415	2.6054077	0.93966544	3673.0752
879.40503	2.6036737	0.94166464	3671.4175
880.30591	2.6073139	0.94346654	3673.157
881.20679	2.6121647	0.94517648	3673.8086
882.10767	2.6131158	0.94691151	3673.0879
883.00854	2.6187749	0.94893968	3680.2993
883.90942	2.620343	0.95096391	3672.8743
884.8103	2.6221087	0.95284176	3673.6135
885.71118	2.627212	0.95468235	3677.3564
886.61206	2.6272731	0.95676762	3677.1699
887.51294	2.63009	0.95852429	3670.5867
888.41382	2.6343558	0.96004546	3672.6123
889.3147	2.6350305	0.96159953	3666.0693
890.21558	2.6391597	0.96307707	3671.2456
891.11646	2.6423168	0.96455401	3670.772
892.01733	2.6418021	0.96620679	3673.085
892.91821	2.6450341	0.96784443	3670.9202
893.81909	2.6456397	0.96939182	3672.7068
894.71997	2.6518033	0.97113925	3673.2327
895.62085	2.6553202	0.97305715	3675.855
896.52173	2.661046	0.97493476	3677.3147
897.42261	2.6581056	0.97674364	3671.4436
898.32349	2.664952	0.97834736	3677.1267
899.22437	2.6660423	0.98021197	3676.2593
900.12524	2.6673534	0.98218602	3670.9487
901.02612	2.6686332	0.9840017	3666.5056
901.927	2.6725128	0.98583877	3673.8928
902.82788	2.6768744	0.9879148	3674.0349
903.72876	2.6764703	0.98985374	3675.7771
904.62964	2.6820211	0.99176908	3675.124
905.53052	2.6850004	0.99337041	3670.4368
906.4314	2.6872325	0.99549711	3677.3362
907.33228	2.6877961	0.99756694	3675.1606
908.23315	2.6916699	0.9996078	3668.759
909.13403	2.6953506	1.001588	3670.1697
910.03491	2.696826	1.0035396	3668.4114
910.93579	2.7003593	1.0054959	3669.2634
911.83667	2.7019432	1.007121	3668.5554
912.73755	2.7040749	1.009225	3678.4148
913.63843	2.7101679	1.0115684	3680.1399
914.53931	2.7085581	1.0137097	3667.1814
915.44019	2.7172849	1.0157754	3672.7375
916.34106	2.7184765	1.0174441	3667.8577
917.24194	2.7195616	1.0191053	3669.0112
918.14282	2.7218118	1.0208399	3674.5046
919.0437	2.7228765	1.0226128	3672.5627
919.94458	2.726866	1.0247169	3672.4216
920.84546	2.7323022	1.0267935	3677.9509
921.74634	2.7324977	1.0289328	3671.5107
922.64722	2.7350388	1.0312461	3673.0498
923.5481	2.7406855	1.0331349	3664.9731
924.44897	2.7389493	1.0347869	3668.6023
925.34985	2.7405298	1.0366064	3659.1479
926.25073	2.7477014	1.0384008	3669.1292
927.15161	2.7462838	1.0401849	3666.5308
928.05249	2.7532413	1.0422026	3670.6882
928.95337	2.7545369	1.0443125	3664.9263
929.85425	2.7563217	1.0462397	3669.2141
930.75513	2.7600329	1.0480453	3664.584
931.65601	2.7629738	1.0499878	3666.4729
932.55688	2.7655182	1.0516135	3664.2527
933.45776	2.7675974	1.0536561	3666.1294
934.35864	2.7715096	1.055807	3666.3958
935.25952	2.7747445	1.0581313	3668.7122
936.1604	2.7770371	1.0603846	3663.7312
937.06128	2.7785037	1.0626235	3669.7617
937.96216	2.7827196	1.064698	3666.7126
938.86304	2.7844949	1.0667276	3668.7117
939.76392	2.7871203	1.0687497	3666.1079
940.66479	2.7862985	1.0709586	3662.3213
941.56567	2.7930501	1.0729569	3660.7717
942.46655	2.7945888	1.0750005	3661.6292
943.36743	2.7981122	1.0770193	3660.4641
944.26831	2.7985468	1.0791796	3661.0271
945.16919	2.8033471	1.0816429	3664.5066
946.07007	2.8076422	1.0839415	3662.2866
946.97095	2.8086634	1.0859981	3658.0649
947.87183	2.8146105	1.0877489	3660.6191
948.77271	2.8164895	1.089507	3658.9121
949.67358	2.8164835	1.0917192	3667.1565
950.57446	2.8220861	1.0938653	3662.9258
951.47534	2.8220215	1.0960416	3659.2603
952.37622	2.8252487	1.0982492	3658.6909
953.2771	2.8258889	1.1003633	3654.3481
954.17798	2.8299124	1.1026932	3656.0132
955.07886	2.8327689	1.1046189	3657.1826
955.97974	2.8354378	1.1068074	3655.5989
956.88062	2.8398066	1.1088458	3661.1565
957.78149	2.8395495	1.1111834	3654.7244
958.68237	2.8437333	1.1134506	3658.3811
959.58325	2.8462195	1.1159104	3655.9395
960.48413	2.8467169	1.1180588	3652.6921
961.38501	2.8485997	1.1200877	3646.2529
962.28589	2.8515482	1.1222872	3646.8643
963.18677	2.8604577	1.1243991	3659.051
964.08765	2.8619847	1.1262424	3655.1116
964.98853	2.8624153	1.12831	3649.1558
965.8894	2.8670726	1.1309167	3662.0085
966.79028	2.8632123	1.1333532	3647.8225
967.69116	2.8692451	1.1355244	3646.8252
968.59204	2.8757615	1.1375959	3647.4739
969.49292	2.8754854	1.1395297	3649.9941
970.3938	2.8753276	1.1412997	3645.0134
971.29468	2.8804183	1.1437904	3651.8699
972.19556	2.8813109	1.1463826	3644.6482
973.09644	2.8857484	1.1484013	3641.9277
973.99731	2.8870995	1.1504356	3637.8159
974.89819	2.8893034	1.1528848	3648.564
975.79907	2.8926282	1.1552298	3643.176
976.69995	2.8971543	1.1574715	3644.1587
977.60083	2.898262	1.1598873	3640.8735
978.50171	2.9039989	1.1622618	3641.9141
979.40259	2.905937	1.1647288	3645.3953
980.30347	2.906431	1.1668656	3635.6658
981.20435	2.9122343	1.1690152	3643.7646
982.10522	2.9152422	1.1713663	3637.626
983.0061	2.9155703	1.1737905	3636.5066
983.90698	2.9197199	1.1761239	3636.042
984.80786	2.9220805	1.1781653	3630.9924
985.70874	2.9245453	1.180446	3630.0007
986.60962	2.9295297	1.182897	3635.9734
987.5105	2.9299741	1.1851662	3635.354
988.41138	2.9309893	1.187832	3633.6704
989.31226	2.9330893	1.1902567	3626.0574
990.21313	2.9379382	1.1924036	3628.5815
991.11401	2.9428787	1.1946205	3629.427
992.01489	2.9445369	1.1965605	3627.5967
992.91577	2.9481528	1.1989379	3630.9866
993.81665	2.9491112	1.2012906	3621.2363
994.71753	2.9522958	1.2036994	3624.1897
995.61841	2.9564288	1.2058731	3618.3218
996.51929	2.9568715	1.2078484	3618.8
997.42017	2.956562	1.2097676	3612.0669
998.32104	2.9594417	1.2119349	3621.5024
999.22192	2.9668336	1.2143043	3621.5625
1000.1228	2.9686449	1.2167466	3618.6511
1001.0237	2.9696858	1.2191484	3612.261
1001.9246	2.9719245	1.2212669	3610.4363
1002.8254	2.9756856	1.2232888	3617
1003.7263	2.9804666	1.2252933	3611.2063
1004.6272	2.9819014	1.2273921	3609.8479
1005.5281	2.9830678	1.2297108	3611.6624
1006.429	2.987319	1.2323527	3610.2527
1007.3298	2.9881361	1.2348188	3602.2664
1008.2307	2.9970472	1.2370389	3602.1653
1009.1316	2.9958746	1.2392683	3602.1606
1010.0325	3.0007534	1.2407535	3589.9409
1010.9333	2.9976227	1.2425083	3601.7546
1011.8342	3.0044913	1.2444992	3605.0156
1012.7351	3.006151	1.2464911	3592.2505
1013.636	3.0049086	1.2485498	3604.3589
1014.5369	3.0112445	1.250918	3594.2249
1015.4377	3.0111952	1.2537072	3598.2358
1016.3386	3.0151858	1.2562058	3596.3125
1017.2395	3.0190775	1.2585974	3594.9546
1018.1404	3.0190003	1.2613385	3589.4521
1019.0413	3.0236259	1.2640015	3588.4795
1019.9421	3.0256398	1.266175	3582.3201
1020.843	3.0296779	1.2683934	3587.9912
1021.7439	3.0316434	1.2711366	3589.3479
1022.6448	3.033406	1.2738247	3582.7712
1023.5457	3.0396187	1.2764809	3581.6824
1024.4465	3.044131	1.2792093	3578.6738
1025.3474	3.0440133	1.2815999	3580.7212
1026.2483	3.0461805	1.2837869	3574.6047
1027.1492	3.0482736	1.2856369	3570.8296
1028.05	3.0504656	1.2882006	3570.3425
1028.9509	3.0531025	1.2907724	3573.1719
1029.8518	3.0544803	1.29344	3569.4954
1030.7527	3.061681	1.2957902	3560.4041
1031.6536	3.0620959	1.2977767	3563.7808
1032.5544	3.0669754	1.2999673	3568.5654
1033.4553	3.069263	1.302613	3563.0989
1034.3562	3.0702541	1.3048968	3569.0952
1035.2571	3.0725965	1.3075507	3559.3425
1036.158	3.0790291	1.310048	3557.7913
1037.0588	3.0772898	1.3121446	3547.4724
1037.9597	3.0811782	1.3142474	3550.1069
1038.8606	3.0843132	1.3166667	3549.5959
1039.7615	3.0861194	1.3197169	3549.3291
1040.6624	3.088371	1.3226595	3545.0647
1041.5632	3.0913837	1.3253309	3539.9263
1042.4641	3.0943789	1.3280292	3539.3743
1043.365	3.0984614	1.3302798	3532.1853
1044.2659	3.0985548	1.3332374	3537.5969
1045.1667	3.1014955	1.3359512	3535.0352
1046.0676	3.1067026	1.3384681	3526.8301
1046.9685	3.1099489	1.3407258	3525.2
1047.8694	3.109782	1.3427246	3522.5125
1048.7703	3.1142387	1.3451829	3521.6079
1049.6711	3.1154783	1.3477892	3520.6553
1050.572	3.1182299	1.3504894	3517.4336
1051.4729	3.1221182	1.3532207	3513.667
1052.3738	3.1218393	1.3559282	3515.8389
1053.2747	3.1269727	1.358743	3509.0835
1054.1755	3.1321828	1.3613572	3511.0974
1055.0764	3.1316643	1.3637885	3509.4248
1055.9773	3.1344023	1.3665382	3502.9114
1056.8782	3.1399748	1.3690177	3499.8518
1057.7791	3.1433096	1.3712332	3497.0056
1058.6799	3.143199	1.3735625	3490.7864
1059.5808	3.146951	1.3759129	3492.6716
1060.4817	3.147856	1.3785365	3492.8289
1061.3826	3.1524863	1.3813061	3485.9651
1062.2834	3.1546345	1.3837819	3484.9746
1063.1843	3.1573696	1.3869045	3480.8745
1064.0852	3.1620667	1.3894086	3475.7834
1064.9861	3.1647496	1.3918772	3470.0767
1065.887	3.1650743	1.3939005	3468.0002
1066.7878	3.1642025	1.3962487	3470.9443
1067.6887	3.1698833	1.3991334	3461.8887
1068.5896	3.1729338	1.4011611	3454.1504
1069.4905	3.1752849	1.4033923	3459.8193
1070.3914	3.1817491	1.4061897	3461.8774
1071.2922	3.1793797	1.4093417	3455.2695
1072.1931	3.1861174	1.4127526	3447.8701
1073.094	3.1834838	1.4154559	3443.5337
1073.9949	3.1892655	1.4185418	3440.7871
1074.8958	3.1947267	1.4219987	3445.2368
1075.7966	3.1940882	1.42551	3427.5276
1076.6975	3.1991911	1.4282334	3425.3486
1077.5984	3.2023172	1.4309045	3416.6692
1078.4993	3.2023585	1.4336096	3413.2185
1079.4001	3.2070236	1.4362277	3410.5364
1080.301	3.2095068	1.4391853	3405.9753
1081.2019	3.2096694	1.4422623	3392.9702
1082.1028	3.2156472	1.4448457	3387.5737
1083.0037	3.2167277	1.4480472	3381.7273
1083.9045	3.2177055	1.4507138	3370.5562
1084.8054	3.2221673	1.453436	3364.6765
1085.7063	3.2277138	1.4561322	3364.9136
1086.6072	3.2275655	1.459384	3353.4268
1087.5081	3.2337596	1.4625241	3355.9941
1088.4089	3.2315753	1.4654925	3337.9873
1089.3098	3.2337966	1.4689914	3332.1177
1090.2107	3.2394865	1.4727932	3316.3005
1091.1116	3.2427859	1.4773684	3298.6892
1092.0125	3.2471519	1.4826871	3264.8062
1092.9133	3.2470527	1.4864471	3249.4158
1093.8142	3.2524636	1.4895381	3235.4138
1094.7151	3.2541957	1.4926169	3229.0327
1095.616	3.2561789	1.4967973	3200.5891
1096.5168	3.2610738	1.5048543	3137.8372
1097.4177	3.2634552	1.5130371	3063.6499
1097.718	3.2698681	1.5220554	2963.4778