File: datasets/am_bench_2022/raw_data/45-XY.13-3/specimen.dat
MTS793|MPT|ENU|1|2|.|/|:|1|0|0|A

Operator Information						Time:	26.82251	Sec	10/20/2021 10:08:06 AM
Operator	Newell Moser
Project	AM Bench 2022 mini-tensile challenge
Specimen ID	45-XY.13-3
Material	PBF-L Inconel 625
Specimen Width	2.54	mm
Specimen Thickness	1.52	mm
Notes
Operator Information End

Data Acquisition						Time:	1027.8186	Sec	10/20/2021 10:24:47 AM
Time	Axial Displacement	Axial Extensometer	Axial Force
Sec	mm	mm	N
26.938477	-0.0020546338	-0.0001225499	86.161469
27.939453	0.0019642513	5.7667072e-05	108.59279
28.94043	0.0056776442	4.8451075e-05	118.52372
29.941406	0.0067383647	7.9790174e-05	131.25446
30.942383	0.011663687	0.00011372831	146.41499
31.943359	0.010693324	0.00024384432	159.16936
32.944336	0.019014867	0.00027779475	181.06758
33.945313	0.018633975	0.00042275718	200.62003
34.946289	0.023298062	0.00055269798	218.75473
35.947266	0.026632663	0.00055618933	242.99586
36.948242	0.031356115	0.0006192046	260.13757
37.949219	0.032411508	0.00075109903	275.07086
38.950195	0.032900993	0.00091213413	299.32977
39.951172	0.038230363	0.00095352519	316.58987
40.952148	0.041068461	0.0010442007	336.45685
41.953125	0.043288659	0.0011400445	358.73264
42.954102	0.044285811	0.0012992623	384.58505
43.955078	0.04912303	0.0014292564	405.51068
44.956055	0.054973643	0.0014760576	429.19016
45.957031	0.057557933	0.0015746695	455.37671
46.958008	0.061009832	0.0017418596	478.13263
47.958984	0.062902004	0.0018857811	502.63965
48.959961	0.065449409	0.0019252226	527.27386
49.960938	0.065852843	0.0020515195	548.9386
50.961914	0.073246844	0.0021298237	578.29956
51.962891	0.075694621	0.0022992664	607.24261
52.963867	0.077642724	0.0023379826	629.51471
53.964844	0.081105381	0.0025309224	658.56317
54.96582	0.083075769	0.0025929173	683.48499
55.966797	0.086605787	0.0027534238	709.42615
56.967773	0.087572053	0.002852679	734.84637
57.96875	0.092755944	0.0030289663	762.48145
58.969727	0.095303506	0.0031390234	789.74249
59.970703	0.096399061	0.0032719187	817.57935
60.97168	0.099988289	0.0033737556	850.88416
61.972656	0.1035683	0.0035759932	889.81958
62.973633	0.10583603	0.0036274332	907.9079
63.974609	0.10996372	0.0037794888	935.51801
64.975586	0.10859688	0.0038468479	955.52692
65.976563	0.11693072	0.0039686956	978.62207
66.977539	0.11892944	0.0040632393	1013.2432
67.978516	0.1208507	0.0042458349	1040.9415
68.979492	0.12363204	0.004408366	1078.3674
69.980469	0.1294533	0.0044803349	1107.0544
70.981445	0.12863004	0.0046666525	1131.755
71.982422	0.13405351	0.0047103832	1160.5321
72.983398	0.13581511	0.0049164402	1188.5217
73.984375	0.13910869	0.0050167046	1218.1205
74.985352	0.14518632	0.005169421	1251.7053
75.986328	0.1479927	0.0051905527	1279.9292
76.987305	0.15002435	0.0054901862	1308.6803
77.988281	0.15205456	0.0056272889	1345.7992
78.989258	0.15312676	0.0057144128	1365.6284
79.990234	0.15756424	0.0058344561	1401.2673
80.991211	0.16327101	0.005935831	1427.7955
81.992188	0.16505454	0.005992163	1452.0463
82.993164	0.16533995	0.0062250029	1484.3253
83.994141	0.16855013	0.0062686643	1507.0215
84.995117	0.17531149	0.0064454381	1537.2054
85.996094	0.17553236	0.0066355094	1570.1594
86.99707	0.1799434	0.006711117	1588.0458
87.998047	0.18311875	0.0067540542	1619.3557
88.999023	0.18442494	0.0069501195	1644.3232
90	0.18697542	0.0070844856	1676.3572
91.000977	0.18982929	0.0071952641	1706.9856
92.001953	0.19432865	0.0072922064	1737.6188
93.00293	0.19529814	0.0074156797	1758.4689
94.003906	0.20058125	0.0075767557	1786.4318
95.004883	0.20267703	0.0076258588	1804.3574
96.005859	0.2056147	0.0077508283	1837.6514
97.006836	0.209148	0.0078766998	1863.6024
98.007813	0.21263668	0.0079339081	1889.3394
99.008789	0.21634884	0.0080682216	1909.2703
100.00977	0.21949878	0.0081538856	1932.4432
101.01074	0.22391085	0.0082704872	1962.616
102.01172	0.22455339	0.0084031746	1983.9152
103.0127	0.22594871	0.008516456	2012.4319
104.01367	0.23133934	0.0086771501	2031.7202
105.01465	0.23412293	0.0087741613	2054.5208
106.01563	0.23636827	0.0088460231	2071.6008
107.0166	0.23689833	0.0089988466	2098.1458
108.01758	0.24172126	0.0089569297	2109.613
109.01855	0.24415654	0.0091446247	2125.7449
110.01953	0.24798405	0.0091882255	2135.123
111.02051	0.25256148	0.0093089612	2164.6604
112.02148	0.25522485	0.0094155893	2186.8401
113.02246	0.25722885	0.0095367078	2202.1638
114.02344	0.26129484	0.0096263494	2228.7312
115.02441	0.26165032	0.0097421827	2236.624
116.02539	0.2658774	0.0097719692	2254.9473
117.02637	0.26959407	0.0098812636	2272.3206
118.02734	0.27135736	0.0099733463	2286.9282
119.02832	0.27333122	0.0100559	2306.6235
120.0293	0.28042695	0.010167186	2318.0681
121.03027	0.28182882	0.010303331	2332.7266
122.03125	0.28457245	0.010329119	2345.814
123.03223	0.28457758	0.010426886	2361.6055
124.0332	0.29057729	0.010552098	2371.5242
125.03418	0.29380208	0.010595241	2378.7341
126.03516	0.29408482	0.010598068	2393.405
127.03613	0.30012655	0.010793081	2416.5479
128.03711	0.30283454	0.010947501	2429.7869
129.03809	0.30596671	0.010996149	2442.4463
130.03906	0.30730999	0.011069537	2446.3984
131.04004	0.31285852	0.011226051	2459.8418
132.04102	0.31518486	0.011229607	2466.1377
133.04199	0.3155717	0.011338478	2485.1943
134.04297	0.32358468	0.011449428	2496.1294
135.04395	0.32353529	0.011614762	2513.3928
136.04492	0.32571656	0.011799575	2514.2053
137.0459	0.32896855	0.011833128	2527.4355
138.04688	0.33318207	0.011950415	2538.6917
139.04785	0.33628306	0.01214501	2553.7534
140.04883	0.33892369	0.012264033	2562.9873
141.0498	0.34087461	0.012409976	2573.1895
142.05078	0.34357828	0.012512759	2578.6406
143.05176	0.34599847	0.012578336	2585.4963
144.05273	0.34789187	0.012670123	2599.4067
145.05371	0.35293519	0.012903314	2609.6934
146.05469	0.35882181	0.013022884	2615.3958
147.05566	0.36209947	0.013217405	2631.0464
148.05664	0.36200932	0.013321098	2639.7483
149.05762	0.36492792	0.013467471	2643.1528
150.05859	0.36543095	0.013685497	2652.2156
151.05957	0.37289318	0.013836349	2671.1494
152.06055	0.37526172	0.014028871	2674.4407
153.06152	0.37612265	0.014148976	2676.6965
154.0625	0.38163558	0.014358426	2696.9976
155.06348	0.38507357	0.014635828	2701.5662
156.06445	0.38547906	0.014704606	2707.5771
157.06543	0.38732409	0.014975935	2716.9819
158.06641	0.39159235	0.015224551	2723.6357
159.06738	0.39733759	0.015496442	2734.6753
160.06836	0.39987516	0.01565616	2741.4214
161.06934	0.40028453	0.01595806	2747.583
162.07031	0.40674919	0.016181972	2751.4812
163.07129	0.40787545	0.016470999	2761.4854
164.07227	0.4125475	0.01674493	2776.4709
165.07324	0.41183573	0.01706332	2779.1028
166.07422	0.41757837	0.017372463	2782.4412
167.0752	0.41893288	0.017786004	2796.5322
168.07617	0.42561552	0.01803614	2802.8604
169.07715	0.42907447	0.018370779	2812.9568
170.07813	0.42873558	0.018704044	2818.4141
171.0791	0.43089631	0.019134842	2819.6282
172.08008	0.43443352	0.019545747	2829.8333
173.08105	0.43930474	0.020047497	2837.1948
174.08203	0.43809608	0.020344062	2834.6943
175.08301	0.44435996	0.020873433	2848.5059
176.08398	0.44781417	0.021319143	2855.9373
177.08496	0.44909883	0.021673677	2847.1807
178.08594	0.45264852	0.022113578	2861.7698
179.08691	0.45623308	0.022593379	2869.7056
180.08789	0.45644554	0.023046566	2875.5178
181.08887	0.46041015	0.023385167	2872.2471
182.08984	0.46789083	0.024033844	2889.3115
183.09082	0.46931338	0.02449622	2889.6892
184.0918	0.46979344	0.025016457	2894.5298
185.09277	0.47342405	0.025698384	2894.77
186.09375	0.47818664	0.02635828	2906.3921
187.09473	0.47890559	0.027068436	2911.9841
188.0957	0.48414052	0.027704699	2915.0022
189.09668	0.48543912	0.028427392	2924.1609
190.09766	0.48920864	0.029089564	2927.7566
191.09863	0.49600074	0.029867474	2930.488
192.09961	0.49132183	0.030560022	2927.0425
193.10059	0.49534857	0.031228386	2935.5801
194.10156	0.50361067	0.032076191	2947.8188
195.10254	0.50300074	0.032895748	2949.6768
196.10352	0.5080238	0.033585411	2944.5132
197.10449	0.51035422	0.034394659	2957.1304
198.10547	0.51447529	0.035242047	2961.9436
199.10645	0.51544809	0.036148589	2960.9177
200.10742	0.52221543	0.037098512	2968.5491
201.1084	0.52265429	0.037882164	2966.312
202.10938	0.52496439	0.038558889	2970.2603
203.11035	0.52767545	0.039467011	2980.123
204.11133	0.52956742	0.040306035	2977.2468
205.1123	0.533692	0.04131202	2981.3145
206.11328	0.53682375	0.042167835	2982.4824
207.11426	0.5396834	0.043098588	2979.7373
208.11523	0.54496145	0.043999366	2989.3811
209.11621	0.54437965	0.045008756	2990.782
210.11719	0.54654777	0.045969684	2996.5781
211.11816	0.55106086	0.046922319	2998.061
212.11914	0.55453962	0.047908168	3002.9512
213.12012	0.55775845	0.048928361	2998.312
214.12109	0.55861998	0.049942102	3002.377
215.12207	0.56459886	0.050914232	3010.4507
216.12305	0.56580812	0.051964849	3011.4238
217.12402	0.57188958	0.052913096	3019.0569
218.125	0.57660699	0.053787906	3016.9221
219.12598	0.57585174	0.054704461	3018.3972
220.12695	0.57857597	0.055552039	3009.1292
221.12793	0.58437634	0.056620292	3033.8362
222.12891	0.58698946	0.057785053	3028.7886
223.12988	0.59004605	0.058826778	3027.4873
224.13086	0.59324616	0.059778962	3031.5232
225.13184	0.59475666	0.060744993	3035.9695
226.13281	0.59844273	0.061928317	3046.0571
227.13379	0.59821653	0.063206919	3043.5234
228.13477	0.60182405	0.064435467	3045.4258
229.13574	0.60748696	0.065489642	3041.8574
230.13672	0.61034924	0.066579655	3053.8264
231.1377	0.61075085	0.067767553	3049.6892
232.13867	0.61525857	0.069094054	3059.106
233.13965	0.61712515	0.070039973	3054.7754
234.14063	0.62267327	0.071217082	3052.5884
235.1416	0.62535995	0.07242129	3069.8892
236.14258	0.62796599	0.073447824	3059.4324
237.14355	0.63206905	0.07458815	3068.5593
238.14453	0.63355803	0.076005749	3071.0532
239.14551	0.63409323	0.076939106	3061.4651
240.14648	0.6378293	0.07819505	3073.4028
241.14746	0.64338756	0.079405889	3069.2881
242.14844	0.64446896	0.080378324	3064.8015
243.14941	0.64686203	0.08159145	3078.2566
244.15039	0.65225589	0.082717873	3080.5767
245.15137	0.651932	0.083688743	3080.509
246.15234	0.65807217	0.084881239	3084.7798
247.15332	0.66125935	0.08597967	3084.9451
248.1543	0.66273785	0.087104745	3084.8679
249.15527	0.66721404	0.088321574	3096.9182
250.15625	0.67084247	0.089651942	3092.2058
251.15723	0.67496252	0.090733096	3090.8403
252.1582	0.67781848	0.09179429	3094.0928
253.15918	0.67798424	0.092957161	3089.5952
254.16016	0.68145216	0.094345324	3106.5818
255.16113	0.68491709	0.0954592	3099.8232
256.16211	0.68597198	0.096625574	3104.0796
257.16309	0.69017428	0.097795829	3102.9209
258.16406	0.69419891	0.099057361	3109.1609
259.16504	0.69695508	0.099966988	3109.2554
260.16602	0.69926351	0.10113425	3106.7241
261.16699	0.70314616	0.10223991	3110.3472
262.16797	0.70703822	0.1034717	3115.4429
263.16895	0.70846695	0.10463479	3117.3503
264.16992	0.7095719	0.10569298	3114.6289
265.1709	0.7144509	0.10700305	3120.9448
266.17188	0.71887386	0.10817976	3123.2378
267.17285	0.71965092	0.10921214	3118.728
268.17383	0.72286999	0.11055384	3129.1799
269.1748	0.72464538	0.11209599	3132.0386
270.17578	0.72974461	0.11346761	3129.1399
271.17676	0.7332201	0.11477371	3129.1997
272.17773	0.73466891	0.11594176	3129.6443
273.17871	0.73937911	0.11707097	3135.3792
274.17969	0.74231333	0.11824378	3132.5444
275.18066	0.7448312	0.11932264	3132.3196
276.18164	0.7483741	0.12049212	3143.6357
277.18262	0.75027239	0.12177248	3137.3196
278.18359	0.75515473	0.1230483	3139.3735
279.18457	0.75733018	0.12452493	3153.8196
280.18555	0.75889641	0.12576798	3146.1572
281.18652	0.76271939	0.12713124	3145.8994
282.1875	0.76382685	0.12817	3149.0081
283.18848	0.76978719	0.12936869	3147.5547
284.18945	0.77188408	0.13070798	3148.6812
285.19043	0.77285868	0.1317737	3146.8574
286.19141	0.77711058	0.13306808	3156.0981
287.19238	0.78226453	0.13427648	3165.3
288.19336	0.78434926	0.13540454	3157.3538
289.19434	0.78677881	0.13655771	3158.979
290.19531	0.78768712	0.13762948	3158.4758
291.19629	0.79254669	0.13884655	3157.9819
292.19727	0.79816222	0.14002031	3169.2603
293.19824	0.80066639	0.14130446	3172.7227
294.19922	0.79865831	0.14259258	3165.5986
295.2002	0.80546677	0.14385346	3169.3564
296.20117	0.80810589	0.14487676	3174.4443
297.20215	0.811782	0.14623098	3174.5503
298.20313	0.81360447	0.14730872	3172.4277
299.2041	0.81833744	0.14842285	3182.3218
300.20508	0.82086742	0.14966506	3178.7346
301.20605	0.82123023	0.15108143	3182.5085
302.20703	0.82515407	0.15248096	3178.8525
303.20801	0.82990193	0.15399252	3185.2378
304.20898	0.83311772	0.15508054	3185.1726
305.20996	0.83466667	0.15619951	3181.2896
306.21094	0.83787519	0.15751372	3191.2922
307.21191	0.84566426	0.15870532	3192.6062
308.21289	0.84180743	0.15997966	3187.6597
309.21387	0.84588635	0.16120227	3183.8513
310.21484	0.85036087	0.16232562	3193.3809
311.21582	0.8538565	0.16345672	3192.0806
312.2168	0.8555966	0.16483475	3198.6636
313.21777	0.85907221	0.16622896	3196.5239
314.21875	0.8611241	0.16736135	3193.9043
315.21973	0.865152	0.16849127	3198.9832
316.2207	0.86488277	0.1697934	3199.1787
317.22168	0.87130708	0.17107555	3204.9768
318.22266	0.8749969	0.17240977	3203.7319
319.22363	0.87783009	0.17348625	3206.2312
320.22461	0.87848496	0.17473203	3204.0742
321.22559	0.88051802	0.17579995	3214.312
322.22656	0.88282347	0.17705446	3208.679
323.22754	0.88640618	0.1783386	3206.1787
324.22852	0.88984603	0.1793883	3205.0884
325.22949	0.89578283	0.18056996	3217.1201
326.23047	0.89435273	0.18174121	3216.2288
327.23145	0.90182239	0.18298993	3216.9268
328.23242	0.90542984	0.18404107	3217.3521
329.2334	0.90716481	0.18522991	3225.9465
330.23438	0.90859228	0.18630995	3217.8203
331.23535	0.91152364	0.18757528	3224.0996
332.23633	0.91453838	0.18890038	3226.9595
333.2373	0.91925716	0.19015136	3226.1287
334.23828	0.92160022	0.19167575	3228.6304
335.23926	0.9269051	0.19287491	3223.5125
336.24023	0.92561305	0.19391125	3219.7859
337.24121	0.93156523	0.1949753	3235.3967
338.24219	0.93335247	0.19607452	3224.4138
339.24316	0.93693227	0.19721927	3233.6938
340.24414	0.93885356	0.19848692	3236.5632
341.24512	0.94398516	0.19998451	3239.3582
342.24609	0.94622809	0.20129304	3236.1023
343.24707	0.94688314	0.20259622	3242.6392
344.24805	0.95296651	0.20397834	3247.3025
345.24902	0.95515817	0.20507699	3235.7615
346.25	0.95618731	0.20628566	3246.7397
347.25098	0.95695913	0.2075863	3245.6316
348.25195	0.96453446	0.20893814	3250.2617
349.25293	0.96468341	0.21003281	3244.8411
350.25391	0.96828622	0.21133713	3248.6387
351.25488	0.97363502	0.21242887	3251.3643
352.25586	0.97682208	0.21373875	3251.4019
353.25684	0.97778153	0.21479045	3246.7158
354.25781	0.98257267	0.21577735	3258.2334
355.25879	0.98413908	0.21698108	3255.2185
356.25977	0.98956549	0.21814115	3254.3186
357.26074	0.98930979	0.21923149	3260.7981
358.26172	0.99210125	0.22064151	3260.6938
359.2627	0.99841666	0.22172357	3260.5613
360.26367	0.99892479	0.22296035	3263.7417
361.26465	1.0018916	0.2242891	3265.0513
362.26563	1.0045664	0.22548065	3259.8552
363.2666	1.0076593	0.22655305	3257.4136
364.26758	1.0107228	0.22773376	3266.905
365.26855	1.0150833	0.2287959	3267.5496
366.26953	1.015128	0.23005091	3271.4028
367.27051	1.0181772	0.23164791	3270.0647
368.27148	1.0258605	0.23300435	3276.1909
369.27246	1.0250088	0.23405664	3272.7815
370.27344	1.0299095	0.23506445	3272.8535
371.27441	1.0322772	0.23635188	3282.3271
372.27539	1.0348967	0.2377561	3282.6221
373.27637	1.0389818	0.23889025	3278.7532
374.27734	1.0428007	0.2399378	3275.0801
375.27832	1.0430005	0.24102969	3278.9563
376.2793	1.0475937	0.24240679	3283.8115
377.28027	1.0510223	0.24377631	3287.5608
378.28125	1.0536903	0.2448274	3286.554
379.28223	1.0570154	0.24605344	3293.1299
380.2832	1.059323	0.24740076	3293.8103
381.28418	1.061882	0.24872716	3286.4006
382.28516	1.0656259	0.24976754	3293.9717
383.28613	1.069191	0.25080708	3284.0081
384.28711	1.0711368	0.25198409	3292.7607
385.28809	1.0759346	0.25300607	3291.9727
386.28906	1.077572	0.25421628	3298.3965
387.29004	1.0811169	0.25548559	3293.4771
388.29102	1.0868046	0.25669768	3303.2424
389.29199	1.0868059	0.25790423	3288.8728
390.29297	1.0917726	0.25934628	3303.7678
391.29395	1.0922033	0.26049265	3303.584
392.29492	1.0968648	0.26206321	3309.3381
393.2959	1.0991592	0.26320538	3296.812
394.29688	1.1018444	0.26425141	3297.8491
395.29785	1.1015302	0.26558352	3303.8528
396.29883	1.1082752	0.26671606	3303.3845
397.2998	1.1128908	0.26780877	3307.5618
398.30078	1.1169919	0.26886863	3311.8882
399.30176	1.1198143	0.27009508	3307.9548
400.30273	1.1199232	0.27138215	3317.7622
401.30371	1.1189888	0.27279958	3311.6567
402.30469	1.1238376	0.2737242	3313.3481
403.30566	1.1305258	0.27486289	3316.1902
404.30664	1.1302222	0.27622953	3313.3623
405.30762	1.1366862	0.27755821	3325.6482
406.30859	1.1356642	0.27859905	3315.1113
407.30957	1.1412427	0.27975121	3324.2275
408.31055	1.1455345	0.28093678	3322.0405
409.31152	1.1479214	0.28229982	3329.6179
410.3125	1.1501533	0.28350839	3327.8293
411.31348	1.1531793	0.28475904	3322.8745
412.31445	1.1565151	0.2859706	3329.6223
413.31543	1.1566131	0.28715828	3327.7896
414.31641	1.1612034	0.28828213	3328.0076
415.31738	1.1647859	0.28956217	3327.1509
416.31836	1.1696769	0.29092062	3335.7896
417.31934	1.1711726	0.29231015	3331.5544
418.32031	1.1745189	0.29337943	3334.855
419.32129	1.1765776	0.29447159	3332.865
420.32227	1.1816534	0.29565448	3340.2576
421.32324	1.1847252	0.29687065	3335.5562
422.32422	1.1874748	0.2981163	3343.9734
423.3252	1.1888446	0.29924104	3333.4189
424.32617	1.1892215	0.30037093	3337.47
425.32715	1.1955411	0.30152521	3349.2661
426.32813	1.1962842	0.30273083	3336.3933
427.3291	1.199544	0.30399504	3350.5273
428.33008	1.2051411	0.30521452	3346.6323
429.33105	1.2071909	0.30649811	3342.78
430.33203	1.2108102	0.30765557	3351.6501
431.33301	1.212473	0.30888337	3354.8552
432.33398	1.2163078	0.31018904	3342.634
433.33496	1.2173394	0.31137604	3341.937
434.33594	1.2213446	0.31251031	3350.1577
435.33691	1.2224207	0.31377697	3354.2288
436.33789	1.2259121	0.31488544	3341.6216
437.33887	1.229131	0.31606865	3354.8865
438.33984	1.2350702	0.31729388	3357.9211
439.34082	1.2337987	0.31854966	3358.8254
440.3418	1.2388965	0.31963429	3354.2834
441.34277	1.2429593	0.32082602	3360.3564
442.34375	1.2475734	0.3218438	3355.2947
443.34473	1.2495863	0.32322299	3368.0134
444.3457	1.2477019	0.3243477	3358.1492
445.34668	1.2528945	0.32559651	3360.5293
446.34766	1.2583722	0.32667309	3368.0383
447.34863	1.2596335	0.32807449	3363.3789
448.34961	1.2642956	0.32958454	3368.8528
449.35059	1.2657743	0.33093515	3365.6677
450.35156	1.2692333	0.3320426	3366.4231
451.35254	1.2722576	0.33340406	3370.8267
452.35352	1.2776107	0.33465195	3371.3831
453.35449	1.2770725	0.33591914	3374.6177
454.35547	1.2825811	0.33686134	3369.6284
455.35645	1.2847446	0.33790654	3363.5444
456.35742	1.286756	0.33916128	3377.2717
457.3584	1.2931373	0.34047672	3378.4155
458.35938	1.2953122	0.34163725	3377.573
459.36035	1.2965525	0.34279841	3382.3835
460.36133	1.3001617	0.34416738	3382.8357
461.3623	1.3042964	0.34545714	3379.312
462.36328	1.3036792	0.34646493	3376.292
463.36426	1.3095145	0.34760207	3385.4529
464.36523	1.3131287	0.34863356	3380.3252
465.36621	1.3134944	0.34982318	3382.9478
466.36719	1.3185937	0.3509694	3389.3269
467.36816	1.3218499	0.35210526	3388.2617
468.36914	1.3210446	0.35322952	3381.0432
469.37012	1.3269241	0.35450929	3394.3674
470.37109	1.3305489	0.35565534	3388.0652
471.37207	1.3334434	0.35698116	3389.552
472.37305	1.3348494	0.35803425	3383.5537
473.37402	1.3371607	0.3591775	3390.9243
474.375	1.3427104	0.36056188	3398.3081
475.37598	1.3448265	0.36169058	3390.801
476.37695	1.349353	0.36293501	3399.613
477.37793	1.3516483	0.36414394	3400.1636
478.37891	1.3554596	0.36571863	3408.5747
479.37988	1.3581692	0.36719584	3403.7166
480.38086	1.3593397	0.36852261	3397.8547
481.38184	1.362766	0.36959592	3393.0354
482.38281	1.3666118	0.37081349	3398.7356
483.38379	1.3685476	0.37202951	3404.1228
484.38477	1.3712837	0.37332013	3407.8821
485.38574	1.3760248	0.37449136	3404.3113
486.38672	1.3797251	0.37568235	3402.7839
487.3877	1.3797255	0.3768751	3405.1221
488.38867	1.3824501	0.37814936	3407.9094
489.38965	1.3867102	0.37942249	3408.8889
490.39063	1.3911542	0.38058773	3406.6599
491.3916	1.3915619	0.38176024	3410.0186
492.39258	1.3937019	0.38297087	3412.1829
493.39355	1.3988431	0.38416573	3412.5042
494.39453	1.403265	0.38551593	3422.7542
495.39551	1.4060369	0.38688147	3418.9563
496.39648	1.4076123	0.3879981	3409.9268
497.39746	1.4123944	0.38907236	3415.5232
498.39844	1.4142789	0.39034489	3417.9763
499.39941	1.4168937	0.39147997	3417.9473
500.40039	1.4171098	0.39277762	3421.4929
501.40137	1.4229486	0.39405638	3427.7693
502.40234	1.4252697	0.39530683	3420.0105
503.40332	1.4303405	0.39638761	3417.5815
504.4043	1.4308078	0.39736146	3420.0176
505.40527	1.4343506	0.39844319	3421.4944
506.40625	1.4393325	0.39981565	3428.1282
507.40723	1.4415182	0.40116382	3420.8242
508.4082	1.4453056	0.40213656	3426.5134
509.40918	1.4452451	0.40335268	3428.7339
510.41016	1.4490525	0.40469614	3428.448
511.41113	1.4530694	0.40602493	3436.762
512.41211	1.4564002	0.40719575	3433.3804
513.41309	1.4594496	0.4082824	3420.8035
514.41406	1.462666	0.40951529	3437.3362
515.41504	1.4652544	0.41074237	3431.2192
516.41602	1.4681907	0.41198543	3438.0837
517.41699	1.4714898	0.41318312	3437.5229
518.41797	1.4746544	0.41458324	3443.0027
519.41895	1.4778409	0.41592231	3440.0251
520.41992	1.4785256	0.41721994	3432.5415
521.4209	1.4827144	0.41862026	3442.7908
522.42188	1.4838917	0.41999885	3435.3845
523.42285	1.4890211	0.42100474	3437.7012
524.42383	1.4923644	0.42207214	3439.1035
525.4248	1.4955115	0.42336741	3446.3325
526.42578	1.496009	0.42457938	3443.644
527.42676	1.5029984	0.42581072	3445.1897
528.42773	1.5048159	0.42692795	3445.8845
529.42871	1.5080343	0.42818415	3445.7598
530.42969	1.5113652	0.42940181	3451.0513
531.43066	1.5135751	0.43062818	3452.4695
532.43164	1.5154179	0.43203548	3451.0896
533.43262	1.5201586	0.43350074	3458.0386
534.43359	1.5213593	0.43469197	3446.6846
535.43457	1.5284317	0.43575943	3445.2839
536.43555	1.5295835	0.43668208	3447.9246
537.43652	1.5312476	0.43790007	3455.3044
538.4375	1.5341085	0.43901119	3455.9348
539.43848	1.5346416	0.44021419	3450.719
540.43945	1.5414788	0.44146329	3460.5991
541.44043	1.544065	0.44279423	3460.7881
542.44141	1.5462526	0.44401491	3458.8022
543.44238	1.5486641	0.44544879	3462.457
544.44336	1.5506495	0.44659805	3453.373
545.44434	1.5541863	0.44785064	3461.0505
546.44531	1.5591735	0.44909298	3468.9766
547.44629	1.5623494	0.45038763	3463.2361
548.44727	1.5640978	0.4517228	3458.8982
549.44824	1.567101	0.45293733	3458.7805
550.44922	1.5712737	0.45439702	3470.104
551.4502	1.5744599	0.45554155	3475.6086
552.45117	1.5746148	0.45684671	3462.5159
553.45215	1.5798947	0.45792875	3463.6311
554.45313	1.5825812	0.45928085	3474.4346
555.4541	1.5834342	0.46068156	3472.4014
556.45508	1.5879595	0.46204358	3466.5798
557.45605	1.5910962	0.46322203	3473.3164
558.45703	1.5938798	0.4644466	3467.9653
559.45801	1.59522	0.46573874	3472.7969
560.45898	1.603279	0.46699867	3468.5754
561.45996	1.6049961	0.46811062	3472.8357
562.46094	1.6079296	0.4694165	3474.3364
563.46191	1.6089467	0.47064066	3475.2371
564.46289	1.6113883	0.47195506	3476.5479
565.46387	1.6136618	0.47311175	3473.2358
566.46484	1.6170748	0.47430989	3475.1313
567.46582	1.6201634	0.47550917	3481.104
568.4668	1.624697	0.47658563	3473.8816
569.46777	1.6251705	0.47789642	3480.3152
570.46875	1.6279233	0.47924003	3479.9629
571.46973	1.6328869	0.48056173	3487.8621
572.4707	1.6367105	0.48196268	3484.3794
573.47168	1.6399299	0.48338023	3490.0051
574.47266	1.6410931	0.48454529	3479.8508
575.47363	1.6447341	0.48596805	3487.0046
576.47461	1.6493554	0.48710024	3479.7612
577.47559	1.6517251	0.48848063	3490.1167
578.47656	1.6541879	0.48976222	3487.8794
579.47754	1.6558805	0.49097836	3484.8872
580.47852	1.6605724	0.49233204	3493.1128
581.47949	1.6623138	0.49375945	3489.8594
582.48047	1.6675569	0.49488625	3494.5588
583.48145	1.670141	0.49600029	3486.8865
584.48242	1.6702108	0.4972761	3494.0872
585.4834	1.6737318	0.49861965	3497.6392
586.48438	1.6775417	0.49993899	3490.02
587.48535	1.6812468	0.50116605	3494.365
588.48633	1.6830578	0.50244671	3491.4751
589.4873	1.6862586	0.50377202	3503.9607
590.48828	1.691115	0.50512761	3498.6033
591.48926	1.6915072	0.50652635	3501.7656
592.49023	1.6956451	0.50802135	3498.3979
593.49121	1.6992717	0.50932693	3499.6094
594.49219	1.7041396	0.51074427	3503.8809
595.49316	1.7070211	0.51220888	3511.7053
596.49414	1.7063073	0.51331103	3494.4429
597.49512	1.7099944	0.5144217	3499.6147
598.49609	1.711908	0.51565599	3504.8879
599.49707	1.7163782	0.51702362	3504.5789
600.49805	1.7215847	0.51801509	3506.6155
601.49902	1.7248679	0.51940072	3509.7676
602.5	1.728601	0.52053821	3502.3943
603.50098	1.7325095	0.52192229	3509.168
604.50195	1.7309562	0.52306169	3498.7324
605.50293	1.7349569	0.52425086	3507.4978
606.50391	1.7384498	0.525397	3507.8289
607.50488	1.7424551	0.52675712	3514.5085
608.50586	1.7444043	0.52803564	3509.7815
609.50684	1.747635	0.52917612	3513.7068
610.50781	1.7527597	0.53048682	3516.1138
611.50879	1.7526691	0.53167802	3510.4651
612.50977	1.7563813	0.53261679	3507.769
613.51074	1.7590982	0.53363734	3510.125
614.51172	1.7627811	0.53497899	3518.7263
615.5127	1.7663847	0.53616112	3523.0769
616.51367	1.768307	0.53765112	3521.0022
617.51465	1.7718371	0.53900391	3519.8708
618.51563	1.7735175	0.54043812	3515.918
619.5166	1.7782384	0.54179549	3516.0056
620.51758	1.7800709	0.54318756	3521.4346
621.51855	1.7846891	0.5444721	3519.3301
622.51953	1.7875044	0.54581141	3523.9688
623.52051	1.7888008	0.54715192	3520.3054
624.52148	1.7922726	0.54855037	3529.3806
625.52246	1.7944075	0.54975986	3515.5283
626.52344	1.7997216	0.55108654	3526.0654
627.52441	1.8043092	0.55250126	3530.554
628.52539	1.8007277	0.55395752	3523.5635
629.52637	1.8064079	0.55536509	3522.1831
630.52734	1.8118186	0.55690551	3527.9966
631.52832	1.813758	0.55837303	3526.6101
632.5293	1.8179764	0.55972111	3531.9172
633.53027	1.8178564	0.56096244	3523.8496
634.53125	1.8229209	0.5620569	3525.9651
635.53223	1.8252989	0.56331092	3532.772
636.5332	1.827469	0.5646078	3523.0105
637.53418	1.8309619	0.56580794	3529.3281
638.53516	1.835618	0.56703162	3533.8374
639.53613	1.8380772	0.56842482	3533.0042
640.53711	1.844655	0.56968057	3536.7961
641.53809	1.8434055	0.57099444	3532.7512
642.53906	1.8483291	0.57249922	3537.9702
643.54004	1.8512558	0.5738529	3534.2319
644.54102	1.8539025	0.57495594	3535.6233
645.54199	1.8551431	0.57626301	3539.0891
646.54297	1.8554877	0.57758129	3535.604
647.54395	1.8623351	0.57894641	3539.113
648.54492	1.8657929	0.58021563	3532.9194
649.5459	1.8636322	0.58126509	3536.7537
650.54688	1.8698649	0.58274102	3545.2502
651.54785	1.8727787	0.58420897	3539.1138
652.54883	1.8755457	0.58547258	3538.083
653.5498	1.8799326	0.58675927	3539.7363
654.55078	1.8827095	0.58811003	3546.0496
655.55176	1.8866649	0.58921385	3538.1685
656.55273	1.8890368	0.59048295	3540.3347
657.55371	1.8909444	0.5918107	3542.3071
658.55469	1.8943647	0.59312797	3544.4529
659.55566	1.8955646	0.59450799	3543.0186
660.55664	1.8987721	0.5959785	3546.7397
661.55762	1.9017161	0.59744459	3542.8445
662.55859	1.9055326	0.59876055	3544.4302
663.55957	1.9104249	0.60006416	3547.7617
664.56055	1.9127685	0.60134971	3542.9612
665.56152	1.9149179	0.60273105	3541.2961
666.5625	1.9164639	0.60392833	3545.7476
667.56348	1.921435	0.60533011	3554.5522
668.56445	1.9231453	0.60666001	3546.2339
669.56543	1.9266826	0.60798281	3550.0825
670.56641	1.932261	0.60938942	3558.1189
671.56738	1.932332	0.61057371	3549.7012
672.56836	1.9366026	0.61217922	3559.5608
673.56934	1.9380158	0.61373568	3557.2046
674.57031	1.9392843	0.61507612	3547.7578
675.57129	1.9425211	0.61629879	3547.2742
676.57227	1.9490007	0.61768526	3553.4736
677.57324	1.9515114	0.61923981	3559.2256
678.57422	1.9549587	0.62076116	3555.0398
679.5752	1.955584	0.62194198	3546.2842
680.57617	1.958552	0.6232717	3552.99
681.57715	1.9616643	0.62455684	3557.6909
682.57813	1.9663198	0.62617427	3558.5549
683.5791	1.9696361	0.62724394	3551.2341
684.58008	1.9736497	0.6286332	3561.6475
685.58105	1.9754568	0.62988323	3554.1133
686.58203	1.9813678	0.63122833	3563.5085
687.58301	1.9831823	0.63263965	3558.6841
688.58398	1.9834198	0.63424635	3563.3682
689.58496	1.9869685	0.63574958	3561.7368
690.58594	1.9902546	0.63716263	3563.6724
691.58691	1.9928559	0.63842267	3565.0422
692.58789	1.9969715	0.63982368	3565.2205
693.58887	2.0008297	0.64123285	3568.0186
694.58984	2.0066192	0.64263684	3567.6714
695.59082	2.0072877	0.64400184	3569.2849
696.5918	2.0085957	0.64535552	3562.7517
697.59277	2.0119114	0.64686459	3576.8503
698.59375	2.0162442	0.64845514	3569.6328
699.59473	2.0167615	0.64995289	3563.4177
700.5957	2.0202885	0.6511817	3564.2346
701.59668	2.0229406	0.65264469	3565.1606
702.59766	2.0253868	0.65410858	3568.9529
703.59863	2.0291283	0.65560848	3565.5154
704.59961	2.0323935	0.65686077	3566.8618
705.60059	2.0325105	0.65829617	3569.7947
706.60156	2.0366971	0.65968418	3565.0933
707.60254	2.0416646	0.66124207	3573.7249
708.60352	2.0456054	0.66250008	3575.7979
709.60449	2.0446122	0.6638819	3567.2959
710.60547	2.0525928	0.66529536	3568.1345
711.60645	2.0534492	0.66660899	3570.3721
712.60742	2.0549355	0.6683023	3577.5598
713.6084	2.0596395	0.66965044	3567.3398
714.60938	2.0649714	0.67104799	3576.8438
715.61035	2.065119	0.67233765	3573.2837
716.61133	2.0707965	0.67365235	3580.4646
717.6123	2.0751803	0.6749661	3580.1035
718.61328	2.0758257	0.6764226	3578.7739
719.61426	2.0783329	0.67769575	3567.7378
720.61523	2.0768204	0.67901075	3572.5313
721.61621	2.0842915	0.68046492	3578.3054
722.61719	2.0864031	0.68192214	3580.377
723.61816	2.0909977	0.68338656	3578.2642
724.61914	2.0890374	0.68481058	3576.1511
725.62012	2.0944855	0.68643093	3580.1904
726.62109	2.0985093	0.68802875	3580.821
727.62207	2.1009672	0.68934554	3580.2642
728.62305	2.1054659	0.69073492	3577.0898
729.62402	2.1104286	0.69205141	3584.1519
730.625	2.1092548	0.69340587	3580.4009
731.62598	2.1129551	0.69493037	3586.5173
732.62695	2.1151834	0.69624841	3575.4102
733.62793	2.119307	0.6977061	3586.1116
734.62891	2.1235785	0.6993683	3584.175
735.62988	2.1259875	0.70074731	3583.1187
736.63086	2.1296906	0.70241517	3585.5864
737.63184	2.1286833	0.70382959	3583.563
738.63281	2.1356313	0.70519853	3579.8611
739.63379	2.1367075	0.70645452	3580.1379
740.63477	2.1411512	0.70780188	3581.5957
741.63574	2.1445005	0.70926684	3586.6809
742.63672	2.1492648	0.71094304	3593.4263
743.6377	2.1493123	0.71256322	3596.8376
744.63867	2.1545892	0.71430367	3586.9285
745.63965	2.1571298	0.71597821	3597.4099
746.64063	2.1593471	0.71741992	3583.9392
747.6416	2.1599722	0.71892798	3586.4988
748.64258	2.1650138	0.72047389	3589.0371
749.64355	2.1668251	0.72192627	3591.8457
750.64453	2.1718097	0.72343987	3596.4438
751.64551	2.1762986	0.72471166	3582.5444
752.64648	2.1761031	0.72576612	3584.2988
753.64746	2.1818719	0.72704226	3584.3909
754.64844	2.1845701	0.72880268	3599.1873
755.64941	2.186547	0.73027742	3589.5081
756.65039	2.1899912	0.73187393	3595.1284
757.65137	2.1923997	0.7332595	3595.9719
758.65234	2.1957054	0.73477185	3598.6306
759.65332	2.199228	0.73657405	3596.4116
760.6543	2.2009974	0.73796934	3593.1831
761.65527	2.2027135	0.73947114	3588.219
762.65625	2.2061172	0.74091828	3588.4253
763.65723	2.2116969	0.74225992	3594.9487
764.6582	2.212832	0.74366987	3595.2473
765.65918	2.2151682	0.74533099	3596.1182
766.66016	2.2202361	0.74667507	3595.6956
767.66113	2.220823	0.74805617	3594.343
768.66211	2.2245078	0.74965507	3597.175
769.66309	2.2282376	0.7509383	3595.5273
770.66406	2.2301207	0.75261497	3599.8525
771.66504	2.2336991	0.7541191	3599.7488
772.66602	2.2373064	0.75573999	3599.5129
773.66699	2.239269	0.75709236	3594.7046
774.66797	2.2400415	0.75864738	3603.4185
775.66895	2.2453926	0.76033628	3601.9448
776.66992	2.2508056	0.76163167	3590.3318
777.6709	2.2517452	0.76286435	3601.0574
778.67188	2.2543476	0.76446331	3599.1499
779.67285	2.2591333	0.76627678	3608.5598
780.67383	2.2597194	0.76796991	3597.6455
781.6748	2.2671885	0.76958358	3603.7529
782.67578	2.2658846	0.77098691	3597.0889
783.67676	2.2700019	0.77262914	3601.5364
784.67773	2.2725382	0.77452993	3606.2759
785.67871	2.2743528	0.77617502	3599.0415
786.67969	2.2784982	0.77761775	3599.9683
787.68066	2.2805936	0.77908766	3598.9719
788.68164	2.2816565	0.78060305	3595.9111
789.68262	2.2890739	0.78197867	3601.593
790.68359	2.2899427	0.78334653	3607.9224
791.68457	2.2942574	0.78519243	3611.7007
792.68555	2.2990396	0.78666615	3608.7366
793.68652	2.2994428	0.7879827	3604.3286
794.6875	2.3026333	0.78946954	3598.9448
795.68848	2.3069954	0.79098642	3602.916
796.68945	2.3080311	0.79262435	3607.4272
797.69043	2.3116014	0.79427665	3608.4209
798.69141	2.3139567	0.7959677	3609.7126
799.69238	2.3182464	0.79769802	3602.6477
800.69336	2.3203208	0.79928595	3607.4338
801.69434	2.3248384	0.80075747	3606.4028
802.69531	2.3252516	0.80215234	3613.2729
803.69629	2.3284664	0.80369461	3612.9695
804.69727	2.3331804	0.80539846	3610.1663
805.69824	2.3380136	0.80707598	3607.908
806.69922	2.3388355	0.80871969	3611.0745
807.7002	2.3419182	0.810812	3613.9812
808.70117	2.3446033	0.81257117	3613.5176
809.70215	2.3513923	0.81411546	3606.2764
810.70313	2.3511801	0.81553268	3607.2881
811.7041	2.353673	0.81702584	3611.689
812.70508	2.3563206	0.8187272	3613.8091
813.70605	2.3614535	0.82036138	3611.5884
814.70703	2.3616836	0.82199365	3609.2566
815.70801	2.3670487	0.82357424	3607.769
816.70898	2.3682926	0.82511359	3609.1238
817.70996	2.3733912	0.82687575	3614.9194
818.71094	2.3752501	0.82843143	3607.8423
819.71191	2.3738	0.83015853	3613.9409
820.71289	2.3805401	0.83199942	3608.0989
821.71387	2.3836911	0.83374512	3609.6318
822.71484	2.3848372	0.83521444	3605.521
823.71582	2.3880947	0.83682996	3607.1116
824.7168	2.3932841	0.83880109	3608.5977
825.71777	2.3970344	0.84039915	3609.6179
826.71875	2.3982928	0.8418926	3611.2224
827.71973	2.4018774	0.84339535	3612.6384
828.7207	2.4056742	0.8450951	3614.0942
829.72168	2.4094357	0.84646618	3612.917
830.72266	2.4113312	0.8480469	3615.2356
831.72363	2.4139695	0.84965527	3613.4893
832.72461	2.4169199	0.8513189	3616.8857
833.72559	2.4195671	0.85292798	3616.5894
834.72656	2.4245381	0.85470504	3613.4106
835.72754	2.4271352	0.85645336	3616.0364
836.72852	2.4286706	0.85801178	3615.0447
837.72949	2.4304154	0.85971075	3614.4207
838.73047	2.4353189	0.86142755	3615.6819
839.73145	2.4377506	0.86318141	3616.8616
840.73242	2.4406817	0.86462861	3612.6296
841.7334	2.4429157	0.86633158	3615.292
842.73438	2.4445586	0.86827397	3615.6304
843.73535	2.4527988	0.8699764	3619.6309
844.73633	2.4514227	0.8718906	3617.8643
845.7373	2.4575403	0.87382209	3618.8015
846.73828	2.4584723	0.87560433	3614.0442
847.73926	2.4617984	0.87706155	3614.7495
848.74023	2.4643812	0.87852204	3615.2397
849.74121	2.4656479	0.8805626	3618.5413
850.74219	2.4711943	0.8826862	3618.9822
851.74316	2.4735608	0.88478726	3620.5161
852.74414	2.4785724	0.88670343	3619.2834
853.74512	2.4786451	0.88842076	3616.7651
854.74609	2.4833145	0.89003927	3617.4666
855.74707	2.4862397	0.89173228	3622.3389
856.74805	2.4879308	0.89334148	3616.8811
857.74902	2.4947808	0.89516556	3619.0781
858.75	2.494071	0.89690256	3621.4907
859.75098	2.4991491	0.89896351	3620.2444
860.75195	2.5027876	0.90084898	3622.7961
861.75293	2.5028226	0.90250176	3616.2083
862.75391	2.506799	0.90412039	3614.2832
863.75488	2.5090747	0.9057169	3617.2612
864.75586	2.5106463	0.90745938	3614.2439
865.75684	2.516777	0.90900236	3619.5623
866.75781	2.5187416	0.91068149	3618.709
867.75879	2.5213091	0.91277754	3621.8997
868.75977	2.5235305	0.91477948	3624.5435
869.76074	2.5297403	0.91683877	3621.6428
870.76172	2.5332336	0.91875887	3624.123
871.7627	2.5332556	0.92052931	3616.6042
872.76367	2.5369	0.92233205	3614.1128
873.76465	2.5408661	0.92411745	3618.3652
874.76563	2.5407915	0.92597443	3618.1555
875.7666	2.5464776	0.92776257	3615.8396
876.76758	2.548367	0.92956203	3616.2842
877.76855	2.5528371	0.93160999	3626.2185
878.76953	2.5533054	0.93374133	3622.2568
879.77051	2.5588305	0.9355098	3612.4016
880.77148	2.5622914	0.9371351	3615.6313
881.77246	2.565727	0.93890178	3611.9167
882.77344	2.5664046	0.94057876	3616.8616
883.77441	2.5721498	0.9423272	3625.1169
884.77539	2.5708578	0.94417024	3617.4741
885.77637	2.5767097	0.94598043	3620.8191
886.77734	2.5765581	0.94818348	3617.2732
887.77832	2.5837083	0.94981748	3608.1477
888.7793	2.585947	0.9516573	3626.093
889.78027	2.5867329	0.9536525	3625.0051
890.78125	2.591496	0.95571995	3617.6699
891.78223	2.5942039	0.95747602	3618.9355
892.7832	2.5986524	0.9594506	3624.3528
893.78418	2.5992224	0.96157843	3614.6946
894.78516	2.600148	0.96327871	3614.4016
895.78613	2.6058428	0.96517712	3617.0605
896.78711	2.6097617	0.9669708	3607.957
897.78809	2.6112151	0.96861905	3613.6406
898.78906	2.6130319	0.97036457	3612.6929
899.79004	2.6158748	0.97224617	3625.2241
900.79102	2.6208146	0.97450358	3621.989
901.79199	2.6239212	0.9767189	3620.8176
902.79297	2.6244733	0.97860664	3612.6182
903.79395	2.629148	0.98037636	3617.5674
904.79492	2.6331608	0.98204648	3615.9463
905.7959	2.6358101	0.98426002	3620.9048
906.79688	2.6396801	0.98625594	3625.2087
907.79785	2.6429901	0.98860514	3621.491
908.79883	2.6442604	0.9907217	3622.6567
909.7998	2.6480536	0.99279988	3617.3298
910.80078	2.6519928	0.99475694	3620.1394
911.80176	2.6530776	0.99640954	3613.6648
912.80273	2.6549268	0.99852574	3618.8887
913.80371	2.6621752	1.0006869	3620.863
914.80469	2.6630566	1.0028141	3619.6035
915.80566	2.6632531	1.0047661	3618.7876
916.80664	2.6712084	1.0071205	3623.7327
917.80762	2.672771	1.0092605	3619.2969
918.80859	2.6724403	1.0113831	3614.7351
919.80957	2.6770105	1.013586	3619.1687
920.81055	2.6822517	1.0155208	3618.8391
921.81152	2.684947	1.0178446	3615.8899
922.8125	2.6882229	1.0200156	3616.9011
923.81348	2.6919734	1.022115	3609.05
924.81445	2.6926339	1.0237316	3609.1895
925.81543	2.6953552	1.0257459	3615.8167
926.81641	2.696388	1.027998	3615.8396
927.81738	2.7010515	1.0305729	3618.7456
928.81836	2.7040789	1.0327837	3607.2239
929.81934	2.7063277	1.0345221	3607.9038
930.82031	2.7108216	1.0362763	3607.512
931.82129	2.713516	1.0378168	3610.9756
932.82227	2.7168908	1.0398901	3623.1299
933.82324	2.7229769	1.0420375	3618.9336
934.82422	2.7254996	1.0442963	3612.4922
935.8252	2.7253494	1.0463886	3612.5288
936.82617	2.72802	1.0486828	3619.1484
937.82715	2.7328835	1.0510213	3612.3286
938.82813	2.7343562	1.0532776	3612.9526
939.8291	2.7403569	1.0555738	3613.7239
940.83008	2.7410688	1.0575805	3608.2141
941.83105	2.7464767	1.0597377	3615.156
942.83203	2.7517731	1.0619788	3609.1545
943.83301	2.7503946	1.0646173	3612.6865
944.83398	2.7540386	1.0670526	3607.8638
945.83496	2.7569263	1.0692265	3613.5991
946.83594	2.7592154	1.0712898	3614.2974
947.83691	2.7630014	1.0737752	3615.3574
948.83789	2.7640924	1.0760036	3605.5251
949.83887	2.770746	1.078514	3611.2607
950.83984	2.7707584	1.0808187	3606.77
951.84082	2.774924	1.0831181	3608.28
952.8418	2.7790592	1.0851882	3609.0481
953.84277	2.7824669	1.0873678	3605.8501
954.84375	2.7820544	1.0897378	3605.7241
955.84473	2.7850378	1.0919688	3603.3284
956.8457	2.7893548	1.0940092	3604.4211
957.84668	2.7927103	1.0962287	3605.5979
958.84766	2.7944796	1.0987062	3601.6567
959.84863	2.7978144	1.1010191	3599.8059
960.84961	2.802135	1.1031457	3608.6042
961.85059	2.803653	1.1057886	3606.3943
962.85156	2.8070536	1.1084098	3603.1772
963.85254	2.8080163	1.1108285	3601.9275
964.85352	2.8136053	1.1130011	3601.8745
965.85449	2.8162379	1.1151701	3603.3755
966.85547	2.8175712	1.1176734	3601.7385
967.85645	2.820637	1.1199476	3592.6145
968.85742	2.8264616	1.1224264	3605.5703
969.8584	2.8303227	1.1247653	3598.6335
970.85938	2.8312993	1.1272048	3602.4512
971.86035	2.834095	1.1297944	3596.7581
972.86133	2.8397999	1.1321119	3599.0066
973.8623	2.8403347	1.1345294	3593.542
974.86328	2.8462815	1.1371744	3598.9048
975.86426	2.845464	1.1396824	3590.8855
976.86523	2.8470259	1.1420428	3591.2407
977.86621	2.8520033	1.1445704	3589.2751
978.86719	2.855073	1.147103	3596.2266
979.86816	2.8573532	1.1498803	3586.6792
980.86914	2.8624516	1.1525205	3594.5068
981.87012	2.8653517	1.1546828	3590.6572
982.87109	2.8641765	1.1569085	3587.3811
983.87207	2.8721752	1.159609	3586.1787
984.87305	2.8752747	1.162174	3585.6331
985.87402	2.8785548	1.1644652	3585.8459
986.875	2.8791132	1.1670719	3591.8445
987.87598	2.884305	1.169722	3584.2136
988.87695	2.886157	1.172563	3582.749
989.87793	2.8877802	1.175536	3582.7395
990.87891	2.8903439	1.1778911	3575.5349
991.87988	2.8937492	1.1801586	3574.1536
992.88086	2.898031	1.1825823	3585.3811
993.88184	2.9018252	1.1857725	3587.3943
994.88281	2.904314	1.1881896	3579.8379
995.88379	2.9084661	1.1905476	3579.2449
996.88477	2.9108205	1.1930559	3571.6301
997.88574	2.9127314	1.1956946	3573.1501
998.88672	2.9155707	1.198274	3574.3503
999.8877	2.9158709	1.2003558	3568.3091
1000.8887	2.9203331	1.2026602	3568.6892
1001.8896	2.9277947	1.2051283	3577.8445
1002.8906	2.9266782	1.2081662	3573.428
1003.8916	2.9324396	1.2112458	3570.3628
1004.8926	2.9334838	1.2138157	3558.2202
1005.8936	2.9385109	1.2162714	3567.1628
1006.8945	2.9386475	1.2187796	3567.2854
1007.8955	2.9433882	1.2218462	3561.5002
1008.8965	2.9449339	1.2241384	3556.4163
1009.8975	2.9500635	1.2267461	3562.9382
1010.8984	2.9515822	1.2296997	3559.3577
1011.8994	2.953232	1.2323194	3553.9299
1012.9004	2.9568212	1.2348665	3553.2458
1013.9014	2.9593699	1.2375004	3556.5745
1014.9023	2.9611135	1.2404721	3550.9578
1015.9033	2.9671643	1.2430103	3547.9282
1016.9043	2.9722166	1.2452416	3550.8794
1017.9053	2.9716868	1.2479247	3552.4487
1018.9063	2.9782205	1.2504202	3545.5225
1019.9072	2.9786894	1.2523565	3538.0251
1020.9082	2.9817235	1.2545518	3550.5671
1021.9092	2.9824901	1.2576597	3546.1079
1022.9102	2.9884081	1.2606465	3541.6533
1023.9111	2.9905281	1.26354	3544.9944
1024.9121	2.9965246	1.2664412	3540.4041
1025.9131	2.996196	1.2697576	3532.4089
1026.9141	2.9995103	1.2726299	3530.5571
1027.915	3.0042865	1.2752393	3528.5398
1028.916	3.0057824	1.2779138	3526.0354
1029.917	3.007606	1.2805687	3530.0837
1030.918	3.0090821	1.2833405	3524.8381
1031.9189	3.0172899	1.2858607	3522.2258
1032.9199	3.0175292	1.2881422	3519.9312
1033.9209	3.0214686	1.2905273	3526.7063
1034.9219	3.0249739	1.2932447	3522.731
1035.9229	3.0241413	1.2959739	3520.2083
1036.9238	3.0316114	1.2992964	3523.5593
1037.9248	3.0309086	1.302254	3511.3376
1038.9258	3.0325422	1.3048762	3507.3184
1039.9268	3.0406191	1.3073866	3512.6743
1040.9277	3.040802	1.3099208	3509.9526
1041.9287	3.0440931	1.3129593	3513.9641
1042.9297	3.0485725	1.3154175	3511.2322
1043.9307	3.0530217	1.3178254	3504.5481
1044.9316	3.0524285	1.3205378	3500.4524
1045.9326	3.0560396	1.3236053	3501.3301
1046.9336	3.0605834	1.3264151	3499.2944
1047.9346	3.0631814	1.3290112	3494.1606
1048.9355	3.0668674	1.331563	3488.2354
1049.9365	3.0710299	1.3338361	3491.5293
1050.9375	3.073909	1.3362157	3487.7302
1051.9385	3.0754561	1.3385583	3482.6064
1052.9395	3.0784941	1.3407787	3482.135
1053.9404	3.0814188	1.3430766	3486.9084
1054.9414	3.0830698	1.3453954	3479.4521
1055.9424	3.0849202	1.3480004	3479.8596
1056.9434	3.0900452	1.3511091	3485.7725
1057.9443	3.0908122	1.3542267	3473.5437
1058.9453	3.0950799	1.3576217	3475.4619
1059.9463	3.1000195	1.3606017	3468.2236
1060.9473	3.1009052	1.3633654	3474.052
1061.9482	3.1061583	1.3662884	3461.1072
1062.9492	3.1093481	1.3692293	3472.7725
1063.9502	3.1113188	1.3719538	3461.2126
1064.9512	3.1165762	1.3750303	3464.1191
1065.9521	3.1149919	1.3782429	3453.1814
1066.9531	3.1210923	1.3810775	3455.9949
1067.9541	3.1226854	1.3841803	3454.3259
1068.9551	3.1245632	1.3871121	3450.6934
1069.9561	3.1294487	1.3902792	3447.0378
1070.957	3.1335378	1.3933316	3447.8572
1071.958	3.1353691	1.3963803	3438.8975
1072.959	3.1391182	1.3993194	3438.2646
1073.96	3.1408572	1.4022108	3437.7405
1074.9609	3.1439929	1.4047743	3430.4102
1075.9619	3.1476448	1.4073739	3433.2949
1076.9629	3.1504118	1.4105617	3432.4863
1077.9639	3.1535044	1.4139156	3425.429
1078.9648	3.1567678	1.4166945	3418.8123
1079.9658	3.1595616	1.4195617	3421.3464
1080.9668	3.1621709	1.4226063	3417.9111
1081.9678	3.1617167	1.4259435	3411.2742
1082.9688	3.1684747	1.4288511	3407.1536
1083.9697	3.172523	1.4318749	3404.2922
1084.9707	3.175334	1.4350126	3397.8367
1085.9717	3.1745911	1.4383172	3402.4436
1086.9727	3.1787667	1.4415973	3388.5767
1087.9736	3.1855268	1.444597	3399.457
1088.9746	3.1862669	1.4476647	3390.9351
1089.9756	3.1888962	1.4502608	3383.9373
1090.9766	3.1900914	1.453163	3384.0247
1091.9775	3.1945295	1.456248	3384.6821
1092.9785	3.1942663	1.4596044	3375.3916
1093.9795	3.2015631	1.4629512	3372.2388
1094.9805	3.2056201	1.4660648	3369.103
1095.9814	3.2046072	1.4690521	3369.8406
1096.9824	3.21122	1.472113	3359.5732
1097.9834	3.211957	1.4753171	3359.9421
1098.9844	3.2142491	1.4783723	3351.3086
1099.9854	3.2183647	1.4814198	3350.0183
1100.9863	3.2219234	1.4844768	3340.2725
1101.9873	3.2256582	1.4871472	3341.2195
1102.9883	3.2260866	1.4900985	3334.7063
1103.9893	3.231041	1.4933444	3340.0972
1104.9902	3.2305214	1.4968464	3326.0759
1105.9912	3.2392566	1.4999229	3331.6621
1106.9922	3.2392297	1.5032264	3321.1782
1107.9932	3.2408342	1.507094	3323.3979
1108.9941	3.2453768	1.5104905	3310.0886
1109.9951	3.2478671	1.5135351	3307.9961
1110.9961	3.2497151	1.5168992	3302.0916
1111.9971	3.2575843	1.5194372	3299.0415
1112.998	3.2574565	1.5218527	3298.2107
1113.999	3.2599087	1.5254024	3293.4055
1115	3.2650635	1.5283651	3295.2224
1116.001	3.2670481	1.5314918	3285.4514
1117.002	3.2701716	1.5351244	3284.2073
1118.0029	3.2726181	1.5385464	3272.0559
1119.0039	3.274385	1.5415424	3268.8901
1120.0049	3.2797427	1.5454191	3269.7468
1121.0059	3.2827284	1.5487692	3256.425
1122.0068	3.284246	1.552088	3250.6287
1123.0078	3.2869492	1.5554671	3246.2888
1124.0088	3.2901399	1.5587344	3237.8079
1125.0098	3.295099	1.56346	3233.2341
1126.0107	3.2979043	1.5676353	3221.0811
1127.0117	3.299073	1.5712175	3206.2104
1128.0127	3.3049488	1.5748035	3197.834
1129.0137	3.3046432	1.5790743	3186.1396
1130.0146	3.307765	1.5842955	3161.876
1131.0156	3.3134773	1.590693	3140.2576
1131.3159	3.3143406	1.5960891	3089.3657