File: datasets/am_bench_2022/raw_data/60-X.05-3/specimen.dat
MTS793|MPT|ENU|1|2|.|/|:|1|0|0|A

Operator Information						Time:	27.059326	Sec	11/1/2021 8:27:30 AM
Operator	Nick Derimow
Project	AM Bench 2022 mini-tensile challenge
Specimen ID	60-X.05-3
Material	PBF-L Inconel 625
Specimen Width	2.54	mm
Specimen Thickness	1.53	mm
Notes
Operator Information End

Data Acquisition						Time:	1028.0527	Sec	11/1/2021 8:44:11 AM
Time	Axial Displacement	Axial Extensometer	Axial Force
Sec	mm	mm	N
27.172607	0.003866337	5.6784927e-05	49.724911
28.173584	0.0035385115	4.6630532e-05	62.258839
29.174561	0.0053245462	0.00023538634	70.490768
30.175537	0.011244563	0.00025746948	86.77784
31.176514	0.012526566	0.00028605075	97.636147
32.17749	0.014981109	0.00029057474	104.82129
33.178467	0.018299932	0.0003599918	120.25756
34.179443	0.022307958	0.00046945582	135.31673
35.18042	0.025557682	0.00047927728	145.64093
36.181396	0.027152708	0.00056629343	157.54152
37.182373	0.030487923	0.00062409317	174.28358
38.18335	0.03374318	0.00076942029	189.04427
39.184326	0.037754074	0.00074594386	205.14664
40.185303	0.038579375	0.00093576615	224.83121
41.186279	0.041169964	0.0010818216	244.2984
42.187256	0.04520775	0.0010994463	267.82764
43.188232	0.04713019	0.0011353022	291.29193
44.189209	0.050174206	0.0012477331	301.64246
45.190186	0.057110328	0.0014180528	331.12167
46.191162	0.056251016	0.0014729185	355.85263
47.192139	0.061440852	0.0016159673	378.76993
48.193115	0.063495651	0.0017564385	401.92154
49.194092	0.064378321	0.0018142915	422.5166
50.195068	0.068277553	0.0019803864	444.34122
51.196045	0.071090497	0.0020505646	467.47815
52.197021	0.076113552	0.0020794829	482.34872
53.197998	0.074749187	0.0022441926	503.35175
54.198975	0.079479456	0.0023696946	535.17865
55.199951	0.082870141	0.0024621568	561.3761
56.200928	0.085056737	0.0026395246	584.31238
57.201904	0.089121521	0.0027221111	610.5484
58.202881	0.093841285	0.0027540987	630.85413
59.203857	0.095694117	0.0028529821	654.67963
60.204834	0.09852653	0.0029661742	680.6413
61.205811	0.10198565	0.0030531627	710.56238
62.206787	0.10344053	0.0031936748	732.2287
63.207764	0.10654996	0.0033716781	756.16187
64.20874	0.1109233	0.0034867479	780.94891
65.209717	0.1167188	0.0035499556	806.73279
66.210693	0.11362474	0.0037206442	832.45087
67.21167	0.11941736	0.0037996697	861.99152
68.212646	0.12416361	0.0039955885	890.84393
69.213623	0.12257202	0.0040658158	917.45349
70.2146	0.12952802	0.0041980022	953.92981
71.215576	0.13019371	0.0044020144	975.45294
72.216553	0.13324571	0.0044827159	1000.6335
73.217529	0.1382241	0.0046097706	1026.2017
74.218506	0.14167687	0.0047870441	1061.7219
75.219482	0.14265728	0.0048813997	1094.844
76.220459	0.14497556	0.0049428302	1115.3375
77.221436	0.14687552	0.0050847931	1148.9315
78.222412	0.15370387	0.0052573951	1183.861
79.223389	0.15433796	0.0054047056	1202.1917
80.224365	0.15737684	0.0054999432	1224.118
81.225342	0.15957308	0.0056003868	1265.54
82.226318	0.16628832	0.0057262504	1289.9008
83.227295	0.16657209	0.0059245201	1318.0385
84.228271	0.16918522	0.0060064681	1346.5516
85.229248	0.17093433	0.0061428663	1370.5042
86.230225	0.179142	0.0062820967	1407.2131
87.231201	0.18026562	0.0064300587	1438.7119
88.232178	0.18134616	0.0064815017	1455.5703
89.233154	0.18385997	0.0065485789	1484.2826
90.234131	0.18529806	0.0067967768	1508.9792
91.235107	0.1932361	0.0068414961	1542.2439
92.236084	0.19577013	0.0069478122	1568.6498
93.237061	0.19543268	0.0071482221	1590.6082
94.238037	0.19900347	0.0072136959	1616.7726
95.239014	0.20471148	0.0074052713	1650.5123
96.23999	0.20497702	0.0075716283	1672.3719
97.240967	0.20841053	0.0075137969	1687.6572
98.241943	0.21200283	0.0076521793	1718.6901
99.24292	0.21494706	0.0076930826	1752.1073
100.2439	0.21684353	0.0079113832	1771.1172
101.24487	0.22253084	0.0079694856	1795.3507
102.24585	0.22580044	0.0080846408	1817.2877
103.24683	0.22820418	0.0083035277	1840.524
104.2478	0.23335083	0.0083384849	1873.2063
105.24878	0.23414519	0.0084889149	1895.9327
106.24976	0.23656121	0.0085695591	1903.1439
107.25073	0.23910017	0.0086312592	1924.5494
108.25171	0.2416674	0.0087321308	1945.3602
109.25269	0.24479465	0.0087962812	1961.514
110.25366	0.2499136	0.0088999169	1980.613
111.25464	0.25327376	0.0090919137	2006.8732
112.25562	0.25449854	0.0091113662	2019.985
113.25659	0.25932333	0.0092762569	2035.1088
114.25757	0.2600517	0.0093671493	2044.2882
115.25854	0.26696154	0.0093758609	2064.9202
116.25952	0.26481143	0.0094143096	2068.8035
117.2605	0.27408186	0.0095539466	2085.1497
118.26147	0.27791533	0.0096741589	2101.9265
119.26245	0.274676	0.0096722823	2115.0354
120.26343	0.27983981	0.0098254727	2119.6365
121.2644	0.280518	0.0099443318	2133.9675
122.26538	0.28761026	0.0099348016	2150.7864
123.26636	0.28695011	0.01005849	2157.3342
124.26733	0.29226118	0.010139609	2176.7678
125.26831	0.29484051	0.010172484	2186.5208
126.26929	0.29992652	0.01033577	2198.5977
127.27026	0.29888424	0.010431636	2211.1006
128.27124	0.30139741	0.01047236	2227.1484
129.27222	0.30892783	0.010511944	2238.0522
130.27319	0.31050324	0.010601903	2248.8
131.27417	0.31324878	0.010743571	2254.479
132.27515	0.3126542	0.010716902	2259.9985
133.27612	0.31808886	0.010805025	2276.4185
134.2771	0.32156253	0.010725704	2281.0403
135.27808	0.32413918	0.010986376	2294.7822
136.27905	0.32636943	0.011051186	2306.5576
137.28003	0.33153653	0.01107549	2314.7139
138.28101	0.33527711	0.01112602	2321.9553
139.28198	0.33699575	0.011262869	2334.3423
140.28296	0.34132507	0.011340678	2347.9727
141.28394	0.3425681	0.01145662	2355.7429
142.28491	0.34705639	0.01139095	2360.9998
143.28589	0.34902248	0.011648388	2374.491
144.28687	0.35379481	0.011614515	2385.4006
145.28784	0.35365465	0.011728069	2394.0437
146.28882	0.35972118	0.011818126	2403.176
147.28979	0.36306474	0.011879109	2405.6589
148.29077	0.36467171	0.012001591	2421.4629
149.29175	0.36573282	0.012158863	2430.085
150.29272	0.36982793	0.012219921	2437.5212
151.2937	0.37428221	0.012306067	2448.5066
152.29468	0.37463421	0.012380372	2448.4609
153.29565	0.37924013	0.012418683	2454.7502
154.29663	0.38086921	0.012598587	2474.1814
155.29761	0.38238883	0.012721803	2478.4595
156.29858	0.38814929	0.012849112	2483.2927
157.29956	0.39057678	0.012905531	2490.3655
158.30054	0.39687857	0.013142702	2504.1399
159.30151	0.39689025	0.013193149	2509.25
160.30249	0.3973738	0.01331966	2520.3091
161.30347	0.40258673	0.01344644	2527.2737
162.30444	0.40373677	0.013649838	2529.3567
163.30542	0.40781286	0.013786962	2541.499
164.3064	0.41233841	0.013848207	2541.5034
165.30737	0.4170703	0.013997193	2557.3794
166.30835	0.41929787	0.014173987	2567.1228
167.30933	0.41900468	0.014284058	2569.5747
168.3103	0.42329955	0.01457627	2580.0681
169.31128	0.4273164	0.014636078	2576.6741
170.31226	0.43109986	0.014860746	2594.6558
171.31323	0.43467233	0.014987801	2599.6584
172.31421	0.43549517	0.015155983	2599.8704
173.31519	0.43686625	0.015384089	2607.0071
174.31616	0.44151765	0.015506675	2612.9438
175.31714	0.44641879	0.015821317	2626.6345
176.31812	0.44719902	0.016022453	2634.7368
177.31909	0.45342022	0.016334763	2646.4126
178.32007	0.45501202	0.016521927	2652.7742
179.32104	0.45656687	0.016764989	2654.3469
180.32202	0.45876577	0.017066633	2663.4526
181.323	0.46218029	0.017414039	2669.0894
182.32397	0.46677813	0.01767133	2677.9309
183.32495	0.46926859	0.017971074	2682.2358
184.32593	0.4721739	0.018325143	2690.5037
185.3269	0.47606885	0.01857364	2687.8145
186.32788	0.47473666	0.018886741	2688.2485
187.32886	0.47895533	0.0192813	2704.8892
188.32983	0.48450181	0.019601878	2710.8945
189.33081	0.48811936	0.01999826	2715.8064
190.33179	0.49101526	0.020353364	2719.3928
191.33276	0.49178278	0.020776356	2720.6423
192.33374	0.49871802	0.021166803	2737.0515
193.33472	0.49846497	0.021593362	2733.4375
194.33569	0.50134045	0.02216984	2744.4116
195.33667	0.50369477	0.022606827	2749.3096
196.33765	0.51131499	0.023132697	2750.1047
197.33862	0.5082314	0.023625709	2749.7202
198.3396	0.51229131	0.024066929	2758.9255
199.34058	0.51592177	0.024676509	2762.2708
200.34155	0.51781654	0.025220435	2770.6846
201.34253	0.52329457	0.025650399	2772.915
202.34351	0.52536643	0.026409743	2782.3113
203.34448	0.52907413	0.027019529	2780.8516
204.34546	0.53066695	0.02765191	2784.6277
205.34644	0.53431433	0.028108062	2780.4648
206.34741	0.53913766	0.028664896	2795.6196
207.34839	0.54302382	0.029282404	2791.6838
208.34937	0.54524148	0.029949872	2807.9941
209.35034	0.5447014	0.030553736	2806.0945
210.35132	0.5487119	0.031142738	2806.5398
211.35229	0.55771655	0.031837642	2823.3452
212.35327	0.55856645	0.032815672	2828.1687
213.35425	0.56023461	0.033397663	2828.9131
214.35522	0.5616014	0.034333415	2827.3892
215.3562	0.56626344	0.035102144	2836.3582
216.35718	0.56688446	0.035621975	2831.8169
217.35815	0.57102835	0.036502637	2839.532
218.35913	0.57335651	0.037188359	2844.2468
219.36011	0.57974166	0.037960291	2850.0422
220.36108	0.57864016	0.038915299	2848.8967
221.36206	0.58327091	0.039642673	2854.1946
222.36304	0.58503067	0.040516242	2853.7034
223.36401	0.58872008	0.041325267	2861.6233
224.36499	0.589405	0.042077471	2857.5413
225.36597	0.59604508	0.043024011	2865.261
226.36694	0.59707648	0.04379848	2860.4441
227.36792	0.60136127	0.044458378	2869.7107
228.3689	0.60357434	0.045416608	2871.6523
229.36987	0.60780215	0.04617732	2873.2908
230.37085	0.61095828	0.047077298	2879.5911
231.37183	0.61433935	0.048038136	2882.8916
232.3728	0.61678326	0.048901953	2882.3311
233.37378	0.61930174	0.049745739	2879.7117
234.37476	0.62434715	0.050887339	2894.1973
235.37573	0.62405723	0.051855247	2893.4211
236.37671	0.62741017	0.05273113	2894.5994
237.37769	0.62994593	0.053759802	2896.1938
238.37866	0.63719839	0.054903939	2905.1755
239.37964	0.6353814	0.055625364	2901.2595
240.38062	0.64130986	0.056664769	2906.7522
241.38159	0.6472916	0.0576621	2908.7917
242.38257	0.6452437	0.058446072	2908.5986
243.38354	0.65274632	0.059328478	2922.2883
244.38452	0.65168154	0.060592279	2921.0376
245.3855	0.65533322	0.061448805	2919.9119
246.38647	0.6617102	0.0623587	2924.0928
247.38745	0.66113263	0.063301168	2917.5771
248.38843	0.66242057	0.064455055	2922.4648
249.3894	0.66985291	0.065490231	2937.3328
250.39038	0.6694929	0.066639833	2930.1606
251.39136	0.67336655	0.067504838	2923.9688
252.39233	0.67654461	0.068346649	2933.8711
253.39331	0.68074811	0.069450088	2947.3604
254.39429	0.68274367	0.070470557	2942.7185
255.39526	0.68381381	0.07161843	2943.5044
256.39624	0.68880779	0.072707422	2947.0222
257.39722	0.69158745	0.0737551	2950.8928
258.39819	0.69762331	0.075016983	2951.6892
259.39917	0.69686049	0.075934187	2946.6851
260.40015	0.70122588	0.076885641	2948.438
261.40112	0.70320368	0.078135706	2953.2627
262.4021	0.70790416	0.079358295	2957.1831
263.40308	0.71237957	0.080272675	2962.0859
264.40405	0.71346468	0.081272624	2963.5569
265.40503	0.71595305	0.082623787	2965.9136
266.40601	0.72080892	0.08362443	2958.7861
267.40698	0.71906716	0.084639624	2964.7971
268.40796	0.72098535	0.085635334	2963.1929
269.40894	0.72885531	0.086693421	2970.0083
270.40991	0.72821707	0.087824851	2972.7432
271.41089	0.73434323	0.088746011	2975.8008
272.41187	0.73585385	0.090046719	2981.4026
273.41284	0.73982048	0.091418378	2982.3433
274.41382	0.74472553	0.092665821	2983.4529
275.41479	0.74559426	0.093739629	2981.9917
276.41577	0.75097936	0.095002249	2984.8367
277.41675	0.75244099	0.095770203	2980.0393
278.41772	0.75264591	0.09681242	2983.3921
279.4187	0.75815642	0.097838722	2989.8354
280.41968	0.76089823	0.098746039	2982.9768
281.42065	0.76646936	0.099820435	2994.8494
282.42163	0.76852542	0.10102469	2999.043
283.42261	0.76770359	0.1022528	3001.9248
284.42358	0.7740615	0.10337047	2997.3872
285.42456	0.77487713	0.10467187	3003.646
286.42554	0.77901816	0.10573167	2999.238
287.42651	0.78317231	0.10686182	3006.9341
288.42749	0.78266931	0.10827622	3011.4468
289.42847	0.78617656	0.10956935	3006.8176
290.42944	0.79275101	0.11059512	3009.0071
291.43042	0.79079068	0.11180245	3009.7393
292.4314	0.79869628	0.11284217	3010.499
293.43237	0.80040097	0.11384182	3007.4243
294.43335	0.80324215	0.11495298	3010.8169
295.43433	0.8059116	0.11593417	3013.3384
296.4353	0.81089741	0.11705731	3020.3037
297.43628	0.81179303	0.11830369	3025.8735
298.43726	0.81544363	0.11959282	3035.6829
299.43823	0.81912571	0.12115125	3031.1501
300.43921	0.82091725	0.12257735	3024.845
301.44019	0.82827115	0.12372855	3033.1575
302.44116	0.82839555	0.12477005	3030.7214
303.44214	0.8323521	0.12597081	3034.6079
304.44312	0.83253133	0.12706709	3030.4585
305.44409	0.83440918	0.12822129	3032.9822
306.44507	0.8392095	0.12935123	3034.5281
307.44604	0.842475	0.13061003	3040.1838
308.44702	0.84637588	0.13172057	3044.1003
309.448	0.84953922	0.13290335	3036.5178
310.44897	0.85340464	0.13410275	3050.51
311.44995	0.85673177	0.13542061	3053.1433
312.45093	0.85680658	0.13653286	3038.2791
313.4519	0.85856003	0.13763292	3051.3408
314.45288	0.86479729	0.13900846	3054.9275
315.45386	0.86566615	0.13981059	3042.3855
316.45483	0.87042779	0.14086829	3055.6858
317.45581	0.86952752	0.14194795	3046.0144
318.45679	0.87457389	0.14295337	3053.7114
319.45776	0.87749362	0.14387777	3054.1689
320.45874	0.88354617	0.14521457	3069.2241
321.45972	0.88616174	0.14661135	3064.0896
322.46069	0.88772917	0.14781411	3063.271
323.46167	0.88903618	0.14902633	3065.5298
324.46265	0.89609742	0.15021852	3068.1211
325.46362	0.89641136	0.15135241	3065.1973
326.4646	0.90004259	0.15245402	3065.0337
327.46558	0.90088117	0.15373959	3069.5715
328.46655	0.90592945	0.15501627	3070.4126
329.46753	0.90792835	0.15621571	3068.1506
330.46851	0.90897864	0.15747634	3068.8516
331.46948	0.91247195	0.15864392	3066.9136
332.47046	0.91857028	0.15969813	3078.158
333.47144	0.92208576	0.16077223	3085.1404
334.47241	0.92318803	0.16213414	3077.7844
335.47339	0.92493862	0.16342361	3082.9009
336.47437	0.92895752	0.1644408	3080.1611
337.47534	0.93164384	0.16551648	3081.0066
338.47632	0.93422908	0.16677533	3083.7214
339.47729	0.93923491	0.16794974	3091.0466
340.47827	0.93913436	0.16907607	3086.863
341.47925	0.94557977	0.17014401	3088.6101
342.48022	0.9477548	0.17111309	3095.2988
343.4812	0.95183825	0.17222898	3090.9456
344.48218	0.95315176	0.17335677	3089.6111
345.48315	0.95292413	0.17456341	3094.282
346.48413	0.95752597	0.17580469	3099.1736
347.48511	0.96091872	0.17708582	3095.8403
348.48608	0.9692601	0.17847455	3107.4634
349.48706	0.97097158	0.1798337	3106.9336
350.48804	0.97223389	0.18086374	3105.4087
351.48901	0.97397685	0.18202385	3093.4414
352.48999	0.97505993	0.18327971	3106.5208
353.49097	0.97789598	0.18434227	3100.8335
354.49194	0.98244858	0.18545587	3103.7813
355.49292	0.98585039	0.18656699	3106.9065
356.4939	0.99125183	0.18803148	3113.5918
357.49487	0.99383754	0.1893388	3120.9294
358.49585	0.99562025	0.19063583	3112.4265
359.49683	0.99924809	0.19167787	3118.8396
360.4978	1.00448	0.19287525	3117.9165
361.49878	1.0069133	0.19391949	3114.4111
362.49976	1.0089583	0.19502464	3120.3306
363.50073	1.0089439	0.19619857	3123.6523
364.50171	1.013714	0.19742355	3120.5056
365.50269	1.0168502	0.19860521	3125.9341
366.50366	1.0164874	0.19968179	3123.9207
367.50464	1.0205705	0.20091382	3122.5742
368.50562	1.0246698	0.20214343	3131.751
369.50659	1.0303829	0.2034144	3133.0398
370.50757	1.0345848	0.20471756	3140.5642
371.50854	1.0353833	0.2059869	3128.5725
372.50952	1.0359879	0.20702353	3127.6912
373.5105	1.0395992	0.2079751	3129.7888
374.51147	1.0416024	0.2091842	3136.8525
375.51245	1.0459533	0.21026868	3132.0071
376.51343	1.0500145	0.21138494	3133.5139
377.5144	1.0504407	0.21253964	3137.3564
378.51538	1.0572889	0.2135842	3138.1125
379.51636	1.0581139	0.21487489	3141.2979
380.51733	1.0613217	0.21606997	3142.8328
381.51831	1.0651488	0.21711239	3142.9824
382.51929	1.0656614	0.21827646	3145.9971
383.52026	1.0734825	0.2196466	3149.2593
384.52124	1.0751973	0.22104852	3154.54
385.52222	1.0746974	0.22230874	3146.1094
386.52319	1.0792261	0.22343355	3149.9092
387.52417	1.082521	0.22449188	3153.3738
388.52515	1.0850832	0.22574702	3153.2385
389.52612	1.0851326	0.22665736	3146.0012
390.5271	1.0915902	0.22782183	3159.5898
391.52808	1.0925267	0.22904088	3157.3542
392.52905	1.0956098	0.23031273	3165.4827
393.53003	1.102218	0.23134367	3156.9106
394.53101	1.1033559	0.23257576	3162.75
395.53198	1.1063886	0.23368138	3154.9651
396.53296	1.1076194	0.23483704	3161.1118
397.53394	1.1087159	0.23612519	3166.0254
398.53491	1.1158406	0.2372153	3164.7537
399.53589	1.1200559	0.23823503	3167.4395
400.53687	1.1216815	0.23941626	3166.125
401.53784	1.1235338	0.24046026	3168.3386
402.53882	1.1270385	0.24173626	3176.3325
403.53979	1.1309474	0.24289575	3178.1812
404.54077	1.1340503	0.24403021	3173.1333
405.54175	1.1352531	0.24505198	3177.4832
406.54272	1.137908	0.24637316	3179.1406
407.5437	1.1430606	0.24754386	3176.6665
408.54468	1.1436723	0.24866962	3172.7139
409.54565	1.1513108	0.24986267	3185.0889
410.54663	1.1499361	0.25111374	3182.5046
411.54761	1.1556407	0.25227228	3183.5427
412.54858	1.15695	0.25333232	3175.9634
413.54956	1.1600631	0.25458106	3188.8992
414.55054	1.1637278	0.25592929	3189.6558
415.55151	1.166371	0.25724378	3191.9563
416.55249	1.1698159	0.25844952	3184.4744
417.55347	1.1728866	0.25944245	3192.9651
418.55444	1.1750959	0.2606675	3195.5295
419.55542	1.1791322	0.26188555	3198.7678
420.5564	1.1832423	0.26282457	3190.875
421.55737	1.1841207	0.26399747	3195.6938
422.55835	1.1870039	0.26510161	3189.7358
423.55933	1.1934584	0.26614818	3198.4407
424.5603	1.1952444	0.2674329	3196.0076
425.56128	1.1978476	0.26845697	3199.7905
426.56226	1.2023388	0.26949635	3199.4111
427.56323	1.2008792	0.27078959	3204.2495
428.56421	1.2044905	0.27194163	3202.3616
429.56519	1.2093887	0.2731643	3211.3325
430.56616	1.2077664	0.27419996	3202.8191
431.56714	1.2153099	0.27541995	3209.9192
432.56812	1.2207545	0.2767784	3211.9529
433.56909	1.2186809	0.27794942	3206.7188
434.57007	1.2234435	0.27910823	3215.2834
435.57104	1.2286974	0.28029504	3212.2485
436.57202	1.2284057	0.28140917	3212.6306
437.573	1.231706	0.28239805	3210.9387
438.57397	1.2354194	0.28346252	3216.3818
439.57495	1.2370602	0.28452322	3214.3789
440.57593	1.2417761	0.28592184	3230.2732
441.5769	1.2460034	0.2872811	3224.3008
442.57788	1.2461517	0.28835481	3218.7036
443.57886	1.2521312	0.28956679	3220.7693
444.57983	1.2554612	0.29078931	3227.3704
445.58081	1.2555071	0.29176912	3219.2
446.58179	1.2588941	0.29283288	3222.125
447.58276	1.2654506	0.29387099	3224.3813
448.58374	1.266238	0.29507184	3238.2419
449.58472	1.2687469	0.29643369	3234.6069
450.58569	1.2705482	0.29770681	3235.2329
451.58667	1.27685	0.29902279	3231.627
452.58765	1.2780789	0.30017564	3232.5825
453.58862	1.2770401	0.30116069	3227.1887
454.5896	1.2835722	0.3022458	3237.8242
455.59058	1.2865834	0.3034983	3243.8743
456.59155	1.290709	0.30479914	3231.2998
457.59253	1.2917309	0.30585161	3238.802
458.59351	1.2963697	0.30694631	3237.7798
459.59448	1.2977501	0.30770394	3230.4583
460.59546	1.3018298	0.30873856	3238.1963
461.59644	1.3030699	0.309659	3238.2791
462.59741	1.3071516	0.31083554	3246.2549
463.59839	1.3103864	0.31182492	3249.5378
464.59937	1.3131136	0.31298196	3247.8716
465.60034	1.3172787	0.3144412	3253.5483
466.60132	1.3181863	0.3153958	3247.9028
467.60229	1.3199682	0.31657225	3246.6023
468.60327	1.323065	0.31760606	3242.6702
469.60425	1.3283935	0.31856567	3251.3596
470.60522	1.3350407	0.31998694	3258.0833
471.6062	1.3322887	0.32109487	3252.4812
472.60718	1.3376281	0.32218397	3252.6938
473.60815	1.3405504	0.32348761	3254.7305
474.60913	1.3419874	0.32449481	3254.7441
475.61011	1.3469368	0.32557592	3263.1023
476.61108	1.3476768	0.32673234	3261.4529
477.61206	1.3504058	0.32792327	3262.8086
478.61304	1.3545454	0.32921603	3261.9824
479.61401	1.3586158	0.33071133	3263.2837
480.61499	1.3610831	0.33198178	3266.4888
481.61597	1.3685166	0.33296767	3261.696
482.61694	1.3678404	0.33413431	3262.3901
483.61792	1.3723375	0.33515608	3269.199
484.6189	1.3725971	0.3363151	3271.7473
485.61987	1.3754705	0.33762124	3267.4302
486.62085	1.3800648	0.33878869	3277.2737
487.62183	1.3836176	0.3400442	3275.2585
488.6228	1.3842278	0.3413547	3276.0149
489.62378	1.3876473	0.34241742	3268.9272
490.62476	1.3896794	0.34342116	3270.228
491.62573	1.3953439	0.34440669	3268.6572
492.62671	1.3969159	0.34552461	3271.4983
493.62769	1.4008021	0.34665218	3279.8884
494.62866	1.4056222	0.34787402	3282.9292
495.62964	1.4079546	0.34909901	3276.7649
496.63062	1.4102255	0.35003954	3278.2192
497.63159	1.4122252	0.35114288	3278.877
498.63257	1.4133664	0.35230663	3280.219
499.63354	1.4197261	0.35325643	3288.614
500.63452	1.4217005	0.35455942	3284.6919
501.6355	1.4222451	0.35561669	3284.4724
502.63647	1.4258653	0.35660979	3285.3069
503.63745	1.43203	0.3579551	3289.1653
504.63843	1.433611	0.359299	3290.9924
505.6394	1.4366907	0.360304	3289.1865
506.64038	1.4404169	0.36145887	3292.2336
507.64136	1.4420925	0.36258486	3294.96
508.64233	1.4480225	0.36362854	3293.3716
509.64331	1.4482323	0.3647815	3291.3994
510.64429	1.4494092	0.36600441	3298.2708
511.64526	1.4551238	0.3673057	3294.7815
512.64624	1.4566931	0.36858445	3304.175
513.64722	1.4591985	0.36966264	3299.3904
514.64819	1.4633486	0.37063253	3302.7385
515.64917	1.4646599	0.37190256	3298.8352
516.65015	1.4706382	0.37310722	3306.501
517.65112	1.475522	0.37415606	3305.7158
518.6521	1.4768541	0.37527916	3307.5459
519.65308	1.4799536	0.37637207	3310.7009
520.65405	1.4803239	0.37741616	3302.7542
521.65503	1.4822695	0.37874258	3306.7771
522.65601	1.4882438	0.38002467	3312.2783
523.65698	1.4891344	0.38112548	3309.1919
524.65796	1.4929694	0.38236791	3309.7668
525.65894	1.495056	0.38348785	3309.2534
526.65991	1.5001056	0.38468859	3310.9463
527.66089	1.5037965	0.38596186	3317.9773
528.66187	1.5059433	0.38700798	3314.1392
529.66284	1.504941	0.38783914	3312.1055
530.66382	1.5126852	0.38903841	3315.6738
531.66479	1.513742	0.38997698	3317.145
532.66577	1.516585	0.39097047	3315.4338
533.66675	1.5230751	0.39206353	3320.9712
534.66772	1.5234288	0.39325643	3324.292
535.6687	1.5270693	0.39442873	3331.3584
536.66968	1.5275226	0.39586964	3322.8977
537.67065	1.5308444	0.39709559	3324.5552
538.67163	1.5349317	0.39821944	3322.9832
539.67261	1.5391912	0.39929438	3322.4028
540.67358	1.542385	0.40046927	3332.092
541.67456	1.5428454	0.40147227	3326.3909
542.67554	1.5484792	0.4025616	3325.918
543.67651	1.5515419	0.40379333	3326.5422
544.67749	1.5570085	0.404782	3332.5579
545.67847	1.5532774	0.40587264	3334.5388
546.67944	1.5632364	0.40737924	3342.7959
547.68042	1.5623386	0.40863696	3330.5334
548.6814	1.5662302	0.40965053	3334.9102
549.68237	1.570086	0.41091174	3334.2019
550.68335	1.5699352	0.41193673	3332.4937
551.68433	1.573642	0.41304323	3338.1648
552.6853	1.5785244	0.4142628	3337.2261
553.68628	1.5805222	0.41537601	3342.0283
554.68726	1.5864625	0.41665751	3342.8979
555.68823	1.5867647	0.41776872	3345.2642
556.68921	1.5901409	0.41912133	3349.1648
557.69019	1.591673	0.4203679	3339.1204
558.69116	1.5950243	0.42141816	3344.8047
559.69214	1.5999511	0.42268366	3343.3145
560.69312	1.6032858	0.42376766	3350.3723
561.69409	1.6026182	0.42483413	3342.3855
562.69507	1.6092752	0.42587948	3348.6716
563.69604	1.6128501	0.42692822	3353.7366
564.69702	1.6137209	0.42802146	3344.9534
565.698	1.6181056	0.42906103	3349.0552
566.69897	1.6173925	0.43022484	3344.5513
567.69995	1.6238235	0.43140206	3359.6746
568.70093	1.6256428	0.43245628	3358.949
569.7019	1.6282686	0.43375036	3350.6697
570.70288	1.6293119	0.43475807	3356.196
571.70386	1.6308703	0.43616429	3359.7666
572.70483	1.6368959	0.43744022	3356.4741
573.70581	1.6436801	0.43867165	3366.0784
574.70679	1.6431675	0.43987882	3359.6704
575.70776	1.6461779	0.44112137	3356.6045
576.70874	1.6482643	0.44231269	3358.4358
577.70972	1.6541901	0.44346267	3365.0574
578.71069	1.6573349	0.4446241	3364.0786
579.71167	1.6572083	0.44554108	3358.9629
580.71265	1.659979	0.44656992	3359.6709
581.71362	1.6662334	0.44802004	3369.6516
582.7146	1.6650302	0.44924045	3368.6587
583.71558	1.6696219	0.45037389	3368.084
584.71655	1.6730573	0.45163831	3370.0374
585.71753	1.6765153	0.45284635	3374.009
586.71851	1.6786323	0.45396742	3375.7073
587.71948	1.6860832	0.45529482	3372.5247
588.72046	1.6882118	0.45632437	3374.4795
589.72144	1.6885196	0.45749226	3373.6484
590.72241	1.6920086	0.45862848	3378.6243
591.72339	1.6961128	0.45980603	3373.8645
592.72437	1.6980902	0.46104684	3375.7815
593.72534	1.7008529	0.46218437	3374.1799
594.72632	1.7055136	0.46320459	3373.189
595.72729	1.7060312	0.46424663	3375.8818
596.72827	1.7110988	0.46512812	3385.5911
597.72925	1.7142463	0.46645531	3382.4819
598.73022	1.7182732	0.46768591	3383.5171
599.7312	1.717806	0.46881902	3377.2014
600.73218	1.7223357	0.47020322	3388.1018
601.73315	1.7265893	0.47108805	3375.7813
602.73413	1.7297387	0.4720355	3378.6045
603.73511	1.732258	0.47297367	3386.0291
604.73608	1.7369986	0.47425851	3388.915
605.73706	1.7386839	0.47537071	3388.573
606.73804	1.7385849	0.47666198	3388.5339
607.73901	1.7429068	0.47801602	3392.9307
608.73999	1.7467968	0.47924617	3395.7639
609.74097	1.7467513	0.48071161	3394.9724
610.74194	1.7488747	0.48201388	3391.5063
611.74292	1.7524195	0.48315829	3384.3733
612.7439	1.7597171	0.48434022	3387.1458
613.74487	1.7591988	0.48535275	3381.9441
614.74585	1.7623819	0.48656574	3398.3318
615.74683	1.7686837	0.48788372	3393.8337
616.7478	1.7677363	0.48898956	3395.9028
617.74878	1.775455	0.49025545	3399.967
618.74976	1.7787951	0.49137264	3400.8091
619.75073	1.7815261	0.49261054	3402.449
620.75171	1.7833961	0.49378416	3405.5046
621.75269	1.783771	0.49490994	3398.5503
622.75366	1.7889152	0.49604526	3407.9575
623.75464	1.7895889	0.49724635	3401.1465
624.75562	1.7930132	0.49847871	3401.9065
625.75659	1.7931416	0.49966285	3406.7231
626.75757	1.8004448	0.50094855	3409.8391
627.75854	1.8001156	0.50231373	3405.8411
628.75952	1.8072748	0.50331974	3406.4905
629.7605	1.8097386	0.50439608	3399.2166
630.76147	1.8113971	0.50555694	3403.6504
631.76245	1.8173908	0.50676352	3414.7485
632.76343	1.8186319	0.50799751	3409.946
633.7644	1.8205055	0.50932974	3419.5779
634.76538	1.8238348	0.51053935	3415.6865
635.76636	1.8296213	0.51192921	3419.6104
636.76733	1.8338513	0.51301575	3418.5435
637.76831	1.8325939	0.51414412	3414.7732
638.76929	1.833989	0.51529586	3406.2244
639.77026	1.8385082	0.51629549	3408.5889
640.77124	1.8424493	0.51743948	3418.8438
641.77222	1.8451307	0.51872867	3420.7288
642.77319	1.8458122	0.52006501	3410.8455
643.77417	1.8513585	0.521276	3413.8611
644.77515	1.8533139	0.52203625	3409.0623
645.77612	1.8556243	0.52319068	3415.7522
646.7771	1.8608549	0.52448708	3424.2773
647.77808	1.8632447	0.52555084	3419.0586
648.77905	1.8648931	0.52680498	3421.4265
649.78003	1.8674785	0.52805167	3427.6052
650.78101	1.8720689	0.52914953	3426.7842
651.78198	1.8759321	0.53029132	3425.6802
652.78296	1.8769516	0.53139186	3426.178
653.78394	1.8793545	0.53272742	3426.3557
654.78491	1.8846527	0.53380316	3423.3958
655.78589	1.8851422	0.53509951	3432.2412
656.78687	1.8912661	0.53670281	3429.1411
657.78784	1.89182	0.53796458	3427.3259
658.78882	1.896199	0.53940231	3425.7717
659.78979	1.8974094	0.54035932	3429.2505
660.79077	1.9050951	0.54147202	3438.0222
661.79175	1.9032214	0.54280555	3432.2686
662.79272	1.907568	0.54391509	3429.9536
663.7937	1.9107383	0.54527164	3433.8462
664.79468	1.9129657	0.54664218	3436.2312
665.79565	1.9171231	0.54760385	3432.7822
666.79663	1.9179404	0.54873264	3433.1853
667.79761	1.9233721	0.54975271	3428.6604
668.79858	1.9244223	0.55068016	3436.666
669.79956	1.9295185	0.55207318	3443.7175
670.80054	1.9324471	0.55316412	3441.5449
671.80151	1.9341015	0.55458331	3439.8516
672.80249	1.9374025	0.5559448	3439.4705
673.80347	1.9414214	0.55727303	3440.4287
674.80444	1.9425377	0.55846572	3440.1895
675.80542	1.9457821	0.55964571	3436.7043
676.8064	1.9494438	0.5609827	3443.6372
677.80737	1.9541301	0.56237251	3445.96
678.80835	1.9575601	0.56338406	3443.7036
679.80933	1.9582907	0.56487811	3452.0505
680.8103	1.9592969	0.56592339	3443.6028
681.81128	1.9662917	0.56725806	3446.9048
682.81226	1.9688898	0.56839061	3454.0022
683.81323	1.969155	0.56963462	3445.1907
684.81421	1.97372	0.57106501	3441.3547
685.81519	1.9776133	0.57213795	3450.3398
686.81616	1.9792439	0.57340491	3449.9541
687.81714	1.9823289	0.57455635	3446.7148
688.81812	1.9870008	0.57540774	3448.4045
689.81909	1.9932433	0.57653219	3458.23
690.82007	1.9907899	0.57772189	3451.2871
691.82104	1.9956303	0.57914507	3454.6021
692.82202	2.0005457	0.58037972	3459.9312
693.823	2.0022271	0.58144051	3455.0496
694.82397	2.0015292	0.58265597	3451.8098
695.82495	2.0069232	0.58370066	3455.479
696.82593	2.0095999	0.58483696	3453.7109
697.8269	2.0117028	0.58606344	3458.6404
698.82788	2.015836	0.58717906	3452.4929
699.82886	2.0189621	0.58838409	3454.6863
700.82983	2.0226648	0.58944458	3459.2571
701.83081	2.0241661	0.59085894	3465.8123
702.83179	2.0299416	0.59214896	3464.0132
703.83276	2.032815	0.59333396	3468.3535
704.83374	2.035861	0.59456879	3466.3215
705.83472	2.0360847	0.59570032	3460.9646
706.83569	2.04211	0.59710962	3470.1992
707.83667	2.0454166	0.59823138	3470.1755
708.83765	2.0450361	0.59932715	3464.0518
709.83862	2.0472288	0.60023451	3461.3145
710.8396	2.0532503	0.60135686	3469.157
711.84058	2.0555615	0.60253066	3464.0095
712.84155	2.0589542	0.60356623	3467.1628
713.84253	2.0607796	0.60505295	3469.6963
714.84351	2.0633204	0.60610092	3467.0024
715.84448	2.06934	0.60733229	3473.5361
716.84546	2.0669954	0.60866928	3469.8655
717.84644	2.0733368	0.60992384	3464.0613
718.84741	2.0771768	0.61105776	3473.9797
719.84839	2.0829237	0.61204791	3474.0544
720.84937	2.0811455	0.61323994	3466.9639
721.85034	2.0828512	0.61430454	3474.2832
722.85132	2.0870569	0.61557299	3476.1414
723.85229	2.0914624	0.61681712	3476.3416
724.85327	2.0964611	0.61781609	3479.6973
725.85425	2.0971491	0.61916822	3477.8792
726.85522	2.0991945	0.62045068	3477.5811
727.8562	2.1028471	0.62182248	3472.2231
728.85718	2.1048367	0.62305176	3476.6104
729.85815	2.1067557	0.62458313	3473.458
730.85913	2.1142874	0.62586558	3483.8242
731.86011	2.1157534	0.62745392	3478.1692
732.86108	2.1178017	0.62893558	3491.0972
733.86206	2.1201115	0.63076103	3482.7539
734.86304	2.1223972	0.63219398	3477.7424
735.86401	2.1268971	0.63356727	3478.6753
736.86499	2.1306796	0.63517493	3484.4072
737.86597	2.1339669	0.63682914	3488.8386
738.86694	2.138293	0.63842231	3481.6289
739.86792	2.1356764	0.63982016	3478.2246
740.8689	2.1421788	0.64117467	3486.3193
741.86987	2.1447389	0.64265412	3491.2488
742.87085	2.1460888	0.6441046	3482.3101
743.87183	2.1508703	0.64525664	3481.7864
744.8728	2.1557171	0.64639521	3485.1135
745.87378	2.1607072	0.647677	3491.0801
746.87476	2.1639662	0.64903957	3493.2671
747.87573	2.166297	0.65024924	3486.156
748.87671	2.1630731	0.65152633	3484.7405
749.87769	2.1678114	0.65288466	3485.8655
750.87866	2.1735709	0.65396714	3496.9324
751.87964	2.1744165	0.65542549	3498.116
752.88062	2.1803942	0.65678632	3494.6426
753.88159	2.1839874	0.65813708	3496.1208
754.88257	2.1841791	0.65970796	3495.3242
755.88354	2.1882091	0.66104066	3495.9058
756.88452	2.1897862	0.66205567	3491.6123
757.8855	2.1937811	0.66340536	3495.9702
758.88647	2.194818	0.664653	3497.489
759.88745	2.1989598	0.66591352	3494.874
760.88843	2.2013147	0.66716939	3493.2693
761.8894	2.2080944	0.66834033	3496.9351
762.89038	2.2098334	0.66973138	3502.8525
763.89136	2.2109621	0.6713112	3500.4451
764.89233	2.2144809	0.67291015	3502.6091
765.89331	2.2175696	0.67448711	3498.7073
766.89429	2.2205653	0.67580968	3498.5159
767.89526	2.2236741	0.67756003	3496.8923
768.89624	2.2275395	0.67890906	3500.7656
769.89722	2.2298522	0.6802901	3507.2676
770.89819	2.234031	0.68195629	3501.05
771.89917	2.2355142	0.68339014	3505.9866
772.90015	2.2384772	0.68463922	3496.4253
773.90112	2.2430058	0.6858716	3506.6887
774.9021	2.2442658	0.68720913	3507.5493
775.90308	2.2469475	0.68879926	3503.8494
776.90405	2.2514203	0.69026273	3503.9927
777.90503	2.251725	0.69174522	3508.387
778.90601	2.2562509	0.69308621	3501.2666
779.90698	2.2589939	0.69433665	3503.0784
780.90796	2.2623138	0.69561327	3500.906
781.90894	2.2637527	0.6968928	3508.5994
782.90991	2.2671957	0.69842273	3507.2881
783.91089	2.2736402	0.69980335	3507.6477
784.91187	2.2753818	0.70123917	3506.0325
785.91284	2.2763839	0.70272958	3507.615
786.91382	2.2825811	0.70426798	3511.8171
787.91479	2.2835987	0.70593297	3510.5803
788.91577	2.2851942	0.70756948	3511.1262
789.91675	2.2872934	0.70911556	3502.3838
790.91772	2.2908216	0.71077591	3512.6028
791.9187	2.2945678	0.71229666	3507.7446
792.91968	2.2998474	0.71397424	3515.1023
793.92065	2.3003528	0.71560287	3510.0264
794.92163	2.3030541	0.717417	3514.978
795.92261	2.3060315	0.71917063	3517.613
796.92358	2.3112781	0.72068584	3516.2373
797.92456	2.3147404	0.72206599	3510.6636
798.92554	2.3158231	0.7237047	3516.5215
799.92651	2.3190548	0.72532439	3521.2725
800.92749	2.3263857	0.72712564	3516.1667
801.92847	2.3270659	0.7284224	3507.7954
802.92944	2.3307135	0.72986954	3519.0376
803.93042	2.3305695	0.73142302	3514.0132
804.9314	2.3333125	0.7329793	3517.5527
805.93237	2.3366308	0.73442596	3516.5957
806.93335	2.3400173	0.73601097	3516.5703
807.93433	2.3435788	0.73743057	3525.1597
808.9353	2.3451316	0.73909736	3516.5859
809.93628	2.3488185	0.74048787	3516.8179
810.93726	2.3523262	0.7420032	3523.6946
811.93823	2.3571577	0.74368751	3523.9583
812.93921	2.3602638	0.74520594	3523.5791
813.94019	2.3629987	0.74676311	3519.5552
814.94116	2.3619363	0.74811298	3520.4612
815.94214	2.3681192	0.7493915	3518.1426
816.94312	2.3717563	0.75064558	3516.813
817.94409	2.3749239	0.75189835	3519.4058
818.94507	2.3760238	0.75324923	3523.0764
819.94604	2.3789597	0.75471622	3528.0974
820.94702	2.3838191	0.75647694	3524.6128
821.948	2.3869216	0.75804877	3528.4624
822.94897	2.3919551	0.75964284	3526.0081
823.94995	2.3903327	0.76101667	3520.749
824.95093	2.3957911	0.76260698	3527.6814
825.9519	2.398191	0.76431239	3524.6147
826.95288	2.4001458	0.7658515	3526.6956
827.95386	2.4027536	0.76737338	3524.1736
828.95483	2.4059083	0.76880366	3526.3621
829.95581	2.4112518	0.77013528	3524.8264
830.95679	2.4138086	0.7718153	3520.781
831.95776	2.4171097	0.77348077	3534.7544
832.95874	2.421155	0.77514756	3533.5442
833.95972	2.4230053	0.77708566	3532.3511
834.96069	2.4238946	0.77887231	3526.0144
835.96167	2.4301155	0.78060615	3532.5515
836.96265	2.4306471	0.78198934	3530.7842
837.96362	2.4334505	0.78354853	3526.3562
838.9646	2.4359069	0.78515738	3527.1174
839.96558	2.4403954	0.78680182	3534.947
840.96655	2.4433877	0.78860492	3539.3342
841.96753	2.4445755	0.7904073	3529.6748
842.96851	2.4518924	0.79214334	3534.0491
843.96948	2.4501314	0.79388869	3533.4556
844.97046	2.4557135	0.79589486	3537.5327
845.97144	2.4575806	0.79791951	3532.5369
846.97241	2.4616368	0.79953384	3526.884
847.97339	2.4653742	0.80094409	3533.2666
848.97437	2.4673166	0.80232006	3526.7366
849.97534	2.4703679	0.8039493	3535.0769
850.97632	2.4735775	0.80561739	3540.5237
851.97729	2.4756336	0.80748737	3532.4236
852.97827	2.4771509	0.80893791	3528.4883
853.97925	2.4822569	0.81045049	3536.6165
854.98022	2.4834771	0.81201816	3533.957
855.9812	2.4868917	0.81375742	3541.2517
856.98218	2.4884624	0.81556654	3528.5361
857.98315	2.4949079	0.81708688	3542.3208
858.98413	2.4953024	0.81877303	3533.658
859.98511	2.502243	0.82014745	3530.9084
860.98608	2.5038762	0.82173198	3545.7175
861.98706	2.507339	0.82324785	3538.7148
862.98804	2.508219	0.82509547	3546.7246
863.98901	2.5126946	0.82691395	3536.7373
864.98999	2.5147429	0.82831085	3531.2322
865.99097	2.5163784	0.82995385	3542.4492
866.99194	2.5210986	0.83177263	3548.5144
867.99292	2.5249243	0.83328295	3544.2036
868.9939	2.5265179	0.83500147	3538.0103
869.99487	2.5267637	0.83688337	3543.3572
870.99585	2.5346825	0.83867282	3540.7786
871.99683	2.5357962	0.84063828	3545.3794
872.9978	2.5414732	0.84234118	3536.1489
873.99878	2.5434599	0.84402466	3535.4019
874.99976	2.5467768	0.8454591	3542.022
876.00073	2.5479126	0.84701312	3533.8877
877.00171	2.5486987	0.84859455	3540.29
878.00269	2.5544591	0.8501007	3544.6714
879.00366	2.5562346	0.85178691	3549.938
880.00464	2.5609598	0.85362953	3545.7813
881.00562	2.5618508	0.85556686	3543.1792
882.00659	2.5660808	0.85722464	3547.6975
883.00757	2.5685153	0.85901761	3545.3943
884.00854	2.5714169	0.86091524	3543.1497
885.00952	2.5754011	0.86245692	3539.2434
886.0105	2.5765164	0.8638494	3533.3411
887.01147	2.5824611	0.86537433	3550.2732
888.01245	2.5822642	0.86712861	3539.5906
889.01343	2.5888784	0.86875439	3544.9827
890.0144	2.5861213	0.87022156	3542.0083
891.01538	2.5922704	0.87182021	3542.5547
892.01636	2.5961218	0.87330741	3543.0642
893.01733	2.5990005	0.87483579	3546.4963
894.01831	2.6037369	0.876737	3549.3735
895.01929	2.6056583	0.87846714	3544.0525
896.02026	2.6105294	0.88012558	3546.7756
897.02124	2.6099608	0.88201171	3553.5103
898.02222	2.6135182	0.88400817	3544.4563
899.02319	2.61624	0.88557374	3544.1716
900.02417	2.6190705	0.88701379	3547.5754
901.02515	2.6234477	0.88896102	3550.3589
902.02612	2.6249681	0.89061534	3546.5579
903.0271	2.6285942	0.89229399	3548.7673
904.02808	2.6318405	0.893664	3536.4502
905.02905	2.6343329	0.89536685	3552.7358
906.03003	2.6378152	0.89721209	3548.7771
907.03101	2.6436424	0.89925021	3553.5808
908.03198	2.6439202	0.90101832	3546.7029
909.03296	2.6461704	0.90271258	3546.707
910.03394	2.6500092	0.90443742	3548.95
911.03491	2.6522076	0.90600944	3544.4385
912.03589	2.655421	0.90788895	3548.0552
913.03687	2.659719	0.90965539	3550.6587
914.03784	2.6575935	0.91158545	3542.7971
915.03882	2.663564	0.91358483	3549.0671
916.03979	2.6676388	0.91530508	3551.1201
917.04077	2.6680288	0.91703975	3543.2241
918.04175	2.6763594	0.91854787	3550.5977
919.04272	2.6756763	0.92035401	3552.1189
920.0437	2.6808009	0.92221206	3548.4341
921.04468	2.6826324	0.92426223	3553.6819
922.04565	2.6855159	0.92615306	3551.3005
923.04663	2.6910751	0.92767495	3552.6294
924.04761	2.6932013	0.9296211	3552.511
925.04858	2.6971796	0.93141204	3550.6619
926.04956	2.6968868	0.93344951	3556.8569
927.05054	2.7015808	0.93529487	3545.3252
928.05151	2.7049301	0.93704236	3548.0264
929.05249	2.7070017	0.93895555	3553.0662
930.05347	2.7110376	0.94078273	3551.8906
931.05444	2.7099361	0.94280529	3545.752
932.05542	2.715405	0.94471502	3552.593
933.0564	2.717876	0.94681531	3548.9097
934.05737	2.7205119	0.94918054	3556.4519
935.05835	2.7258162	0.95123196	3545.9497
936.05933	2.7299979	0.95321232	3547.3457
937.0603	2.7301674	0.95471191	3543.8296
938.06128	2.7363725	0.95636368	3546.0022
939.06226	2.7376084	0.95810145	3557.9895
940.06323	2.7412317	0.96047896	3555.9312
941.06421	2.743958	0.9623307	3551.3921
942.06519	2.7466967	0.96415091	3555.3606
943.06616	2.7473929	0.96645641	3540.7495
944.06714	2.752023	0.96830273	3550.5078
945.06812	2.7552342	0.97035849	3546.9106
946.06909	2.7577302	0.97237796	3547.6348
947.07007	2.7585564	0.97412455	3553.3
948.07104	2.7645984	0.97612971	3546.3838
949.07202	2.7680354	0.97793937	3558.6377
950.073	2.7727237	0.98007733	3552.7522
951.07397	2.7746012	0.98223644	3559.075
952.07495	2.7765884	0.98418468	3549.429
953.07593	2.780056	0.98611808	3556.449
954.0769	2.779927	0.9879359	3548.2681
955.07788	2.7872193	0.98976207	3558.7012
956.07886	2.7863567	0.99218422	3552.9001
957.07983	2.7932889	0.99429858	3554.0898
958.08081	2.7945113	0.99652255	3549.2925
959.08179	2.798974	0.99841529	3559.3279
960.08276	2.8001311	1.0005257	3555.9163
961.08374	2.8061383	1.0029179	3556.7834
962.08472	2.8075068	1.004778	3550.2302
963.08569	2.8086088	1.0071505	3551.7021
964.08667	2.8126938	1.0091472	3551.4058
965.08765	2.8152161	1.011137	3545.7764
966.08862	2.8180912	1.0133404	3544.1201
967.0896	2.821666	1.0150325	3549.5039
968.09058	2.8237205	1.0169234	3546.3752
969.09155	2.8245525	1.0190157	3553.7034
970.09253	2.8280418	1.0214115	3545.6924
971.09351	2.8336823	1.0237603	3554.7815
972.09448	2.837379	1.0258369	3551.1365
973.09546	2.8353	1.0280353	3548.926
974.09644	2.8452051	1.0302496	3550.0562
975.09741	2.8441904	1.0322392	3547.6831
976.09839	2.8493695	1.0339473	3546.0249
977.09937	2.8505545	1.0362606	3546.6702
978.10034	2.8581977	1.0382603	3549.1416
979.10132	2.8581598	1.0405908	3548.3694
980.10229	2.8597412	1.0430367	3546.3425
981.10327	2.8607998	1.0456736	3551.2986
982.10425	2.8646336	1.047892	3543.0442
983.10522	2.8706524	1.049994	3546.2175
984.1062	2.8718421	1.0523945	3545.6035
985.10718	2.876574	1.0549072	3556.1897
986.10815	2.8765564	1.0579057	3544.8489
987.10913	2.8795817	1.0603359	3542.2456
988.11011	2.8871017	1.062732	3546.8577
989.11108	2.8896327	1.0653512	3549.7268
990.11206	2.8918338	1.0675398	3545.7026
991.11304	2.8913279	1.0699265	3549.6592
992.11401	2.8952203	1.0723677	3545.7327
993.11499	2.8994057	1.0743313	3542.04
994.11597	2.9031096	1.0766608	3546.3809
995.11694	2.9056818	1.0787476	3544.7927
996.11792	2.9066236	1.081159	3546.99
997.1189	2.913533	1.0832708	3542.0283
998.11987	2.9160051	1.085429	3548.4185
999.12085	2.9144523	1.0879768	3541.8254
1000.1218	2.920259	1.0901834	3536.5242
1001.1228	2.9237392	1.0921422	3543.6807
1002.1238	2.9287231	1.0942513	3546.0078
1003.1248	2.9287059	1.0965434	3540.9456
1004.1257	2.9322424	1.0994428	3548.4021
1005.1267	2.9359062	1.102191	3541.8604
1006.1277	2.9364665	1.1045017	3543.741
1007.1287	2.9417684	1.1069188	3541.8203
1008.1296	2.945646	1.1089596	3542.3435
1009.1306	2.9466395	1.1110126	3543.3757
1010.1316	2.9474113	1.1135241	3538.605
1011.1326	2.9531562	1.1160868	3544.6362
1012.1335	2.9565179	1.1188142	3544.8833
1013.1345	2.9585216	1.1211405	3532.7539
1014.1355	2.9622843	1.1230545	3535.1536
1015.1365	2.964469	1.1253426	3535.634
1016.1375	2.9696293	1.1282358	3545.0901
1017.1384	2.9716084	1.1308542	3537.0527
1018.1394	2.9719415	1.1334124	3542.4114
1019.1404	2.9765277	1.1361718	3536.7637
1020.1414	2.9808195	1.1395043	3540.8267
1021.1423	2.9848418	1.1424161	3534.5542
1022.1433	2.9857752	1.1452087	3531.1777
1023.1443	2.9923897	1.1482066	3539.2285
1024.1453	2.9932356	1.1512088	3537.3103
1025.1462	2.9975836	1.1538736	3534.6147
1026.1472	2.9967232	1.1559199	3525.8052
1027.1482	2.9996698	1.1583408	3536.1436
1028.1492	3.0048757	1.1613704	3535.1436
1029.1501	3.007915	1.1635674	3526.0337
1030.1511	3.0087969	1.1658984	3525.8298
1031.1521	3.0127437	1.1682279	3529.363
1032.1531	3.0173042	1.1708289	3527.6482
1033.1541	3.01566	1.1735895	3531.0024
1034.155	3.0223956	1.1763923	3529.8118
1035.156	3.024859	1.1789113	3531.5457
1036.157	3.0278065	1.1815542	3526.0806
1037.158	3.0312274	1.184365	3524.9451
1038.1589	3.0325704	1.187326	3522.7976
1039.1599	3.0375707	1.1897166	3523.2266
1040.1609	3.0437441	1.1924757	3529.3206
1041.1619	3.0409882	1.196038	3525.0964
1042.1628	3.0437694	1.1988899	3514.5552
1043.1638	3.051105	1.2005981	3513.4727
1044.1648	3.0483427	1.202238	3508.5881
1045.1658	3.0558109	1.2038267	3519.5955
1046.1667	3.0606034	1.206203	3521.3398
1047.1677	3.0596957	1.2089027	3520.9595
1048.1687	3.0642033	1.2112972	3524.5239
1049.1697	3.0634758	1.21444	3521.5906
1050.1707	3.0704963	1.2171841	3525.6248
1051.1716	3.0755384	1.2204316	3521.9883
1052.1726	3.0769262	1.2232496	3517.6548
1053.1736	3.0779762	1.2258414	3519.3875
1054.1746	3.0823188	1.228426	3515.9961
1055.1755	3.0852666	1.2308428	3511.9553
1056.1765	3.0881083	1.2329876	3513.1528
1057.1775	3.0913646	1.2361282	3518.927
1058.1785	3.0935919	1.2393789	3515.5432
1059.1794	3.0955274	1.2425859	3517.637
1060.1804	3.1005983	1.2456645	3506.1016
1061.1814	3.1032419	1.2480699	3512.0112
1062.1824	3.1054063	1.2507964	3505.0171
1063.1833	3.1072373	1.2538451	3506.4465
1064.1843	3.1135335	1.2567873	3499.8872
1065.1853	3.1167424	1.2595927	3506.3103
1066.1863	3.1162279	1.2622813	3499.5723
1067.1873	3.1205447	1.2648704	3498.5955
1068.1882	3.1228805	1.2672154	3499.866
1069.1892	3.1244674	1.2696183	3494.5503
1070.1902	3.128947	1.272159	3500.9541
1071.1912	3.1322222	1.2754385	3503.9656
1072.1921	3.1375263	1.2783046	3489.3926
1073.1931	3.136764	1.2807343	3490.0996
1074.1941	3.141567	1.2832025	3494.0928
1075.1951	3.1453197	1.2861559	3491.313
1076.196	3.1490688	1.2890092	3490.2864
1077.197	3.1518643	1.2916857	3494.0466
1078.198	3.1537738	1.2949246	3484.2651
1079.199	3.1602418	1.2977793	3492.7932
1080.2	3.1597645	1.3007176	3483.8726
1081.2009	3.161798	1.3032743	3481.019
1082.2019	3.167645	1.3058213	3483.573
1083.2029	3.1673338	1.3085315	3482.9895
1084.2039	3.1721413	1.3113793	3479.8508
1085.2048	3.1739464	1.3142331	3479.5869
1086.2058	3.1764979	1.3177476	3481.5925
1087.2068	3.1797671	1.3206855	3480.2156
1088.2078	3.1841743	1.3238955	3472.2744
1089.2087	3.1868141	1.3266804	3471.4287
1090.2097	3.191994	1.3291944	3469.1152
1091.2107	3.1948004	1.331943	3467.1223
1092.2117	3.1972966	1.3346386	3471.9094
1093.2126	3.1981857	1.3380382	3473.1379
1094.2136	3.2020464	1.3405057	3467.5796
1095.2146	3.205354	1.3436961	3472.0535
1096.2156	3.2081866	1.3472472	3469.4302
1097.2166	3.2129419	1.3501965	3466.1213
1098.2175	3.215158	1.3523847	3456.3545
1099.2185	3.2168403	1.3547652	3462.1201
1100.2195	3.2171097	1.3577068	3462.9512
1101.2205	3.2219367	1.3611507	3450.7307
1102.2214	3.2248795	1.363971	3454.6252
1103.2224	3.2291183	1.3667084	3447.8589
1104.2234	3.2335913	1.3690293	3449.2744
1105.2244	3.2363019	1.3716019	3451.0244
1106.2253	3.2395492	1.3743149	3452.3691
1107.2263	3.2395473	1.3772846	3448.0544
1108.2273	3.2437763	1.3801855	3445.5339
1109.2283	3.2455306	1.3829002	3439.4321
1110.2292	3.2509427	1.3862534	3444.6519
1111.2302	3.25296	1.3895177	3437.9761
1112.2312	3.2576413	1.3923612	3437.2126
1113.2322	3.258471	1.3951266	3434.8093
1114.2332	3.2641315	1.3980664	3433.623
1115.2341	3.266439	1.4007868	3431.9795
1116.2351	3.2680957	1.4033517	3426.1682
1117.2361	3.2734036	1.4058479	3420.5071
1118.2371	3.2751913	1.4079412	3415.5222
1119.238	3.2779391	1.409987	3423.5891
1120.239	3.2803636	1.4124583	3424.5647
1121.24	3.2816324	1.4150584	3416.418
1122.241	3.2878246	1.4178027	3418.574
1123.2419	3.2908409	1.4209807	3427.9023
1124.2429	3.291636	1.4242793	3413.8462
1125.2439	3.2963877	1.4269925	3403.2026
1126.2449	3.2989461	1.4294255	3405.6252
1127.2458	3.2994688	1.4318649	3401.8481
1128.2468	3.3063293	1.4346396	3403.3269
1129.2478	3.3096604	1.4374163	3406.2637
1130.2488	3.310385	1.4402187	3391.1423
1131.2498	3.3117135	1.4426183	3390.1357
1132.2507	3.317008	1.445137	3393.3315
1133.2517	3.3186467	1.4475229	3386.6333
1134.2527	3.3209348	1.4505782	3384.4771
1135.2537	3.3259983	1.4528447	3384.7554
1136.2546	3.3307621	1.4556495	3384.6201
1137.2556	3.3319588	1.4588114	3379.2759
1138.2566	3.3364992	1.4615953	3372.1077
1139.2576	3.339036	1.4637147	3369.8149
1140.2585	3.3390694	1.4660033	3365.7043
1141.2595	3.3447742	1.4687644	3373.1064
1142.2605	3.3469076	1.4717115	3367.4387
1143.2615	3.3507686	1.4747717	3365.9915
1144.2625	3.3535511	1.4778695	3361.5586
1145.2634	3.35554	1.4811094	3360.5696
1146.2644	3.3566315	1.4845349	3351.9368
1147.2654	3.3617094	1.4874763	3344.9702
1148.2664	3.368494	1.4900838	3346.9915
1149.2673	3.3672657	1.493369	3338.811
1150.2683	3.3686881	1.4961227	3335.0769
1151.2693	3.372745	1.4989464	3335.4995
1152.2703	3.3741121	1.5023533	3324.5322
1153.2712	3.3795166	1.5050087	3323.9932
1154.2722	3.3809702	1.508288	3318.1519
1155.2732	3.3851266	1.5112308	3318.0298
1156.2742	3.3903201	1.5136899	3312.144
1157.2751	3.3931496	1.5173868	3316.3445
1158.2761	3.3974109	1.5208292	3303.9438
1159.2771	3.3996198	1.5236278	3293.9663
1160.2781	3.4029472	1.5266706	3290.5476
1161.2791	3.4017608	1.5292994	3283.1736
1162.28	3.4105725	1.5319201	3289.7861
1163.281	3.4118249	1.5352532	3285.2717
1164.282	3.4141912	1.5387872	3273.7375
1165.283	3.4171748	1.5422882	3268.679
1166.2839	3.4191651	1.5462767	3272.6501
1167.2849	3.4227757	1.5498286	3255.2478
1168.2859	3.4255097	1.5538163	3255.0464
1169.2869	3.4287755	1.5572209	3248.9299
1170.2878	3.4327095	1.5608797	3242.3047
1171.2888	3.4331701	1.5648862	3233.7634
1172.2898	3.4378009	1.5678958	3225.2595
1173.2908	3.4401681	1.5719116	3227.1409
1174.2917	3.4434135	1.5756699	3210.353
1175.2927	3.4454222	1.5786184	3208.0457
1176.2937	3.450568	1.5851496	3171.4475
1177.2947	3.4543548	1.5929489	3114.1201
1177.8953	3.4554939	1.5978994	3088.4285