File: datasets/am_bench_2022/raw_data/0-XY.10-2/specimen.dat
MTS793|MPT|ENU|1|2|.|/|:|1|0|0|A

Operator Information						Time:	16.155273	Sec	10/13/2021 2:32:15 PM
Operator	Nick Derimow
Project	AM Bench 2022 mini-tensile challenge
Specimen ID	0-XY.10-2
Material	PBF-L Inconel 625
Specimen Width	2.56	mm
Specimen Thickness	1.54	mm
Notes
Operator Information End

Data Acquisition						Time:	1017.1489	Sec	10/13/2021 2:48:56 PM
Time	Axial Displacement	Axial Extensometer	Axial Force
Sec	mm	mm	N
16.268799	0.0015264124	2.2088689e-05	95.961777
17.169678	0.0045124423	6.2301274e-06	110.71414
18.070557	0.0090703955	0.00015648385	123.12025
18.971436	0.010701737	0.00013040531	135.38663
19.872314	0.01372055	9.7524418e-05	144.30962
20.773193	0.018478066	0.00015693869	153.27599
21.674072	0.01776566	0.00017083441	167.76259
22.574951	0.019889509	0.000423466	183.99974
23.47583	0.024715306	0.00046700533	198.56757
24.376709	0.024576595	0.0007023933	217.04405
25.277588	0.028850568	0.00055598741	228.66199
26.178467	0.032833342	0.00065398164	250.13411
27.079346	0.032914273	0.00074353436	267.37027
27.980225	0.037908491	0.00077489088	289.66492
28.881104	0.040399708	0.00086149725	307.82053
29.781982	0.040725689	0.0010761502	323.88431
30.682861	0.040936522	0.0011301308	338.6059
31.58374	0.049418498	0.0013662113	362.60223
32.484619	0.04774208	0.0012689065	374.19513
33.385498	0.051513918	0.0014919027	396.52585
34.286377	0.052975558	0.0015070974	417.38391
35.187256	0.055821441	0.0015969943	435.99857
36.088135	0.060245398	0.0017380515	464.59143
36.989014	0.063096866	0.0017027038	479.71149
37.889893	0.065518878	0.0018216255	502.68286
38.790771	0.067400344	0.002029428	528.8717
39.69165	0.070997976	0.0020656774	545.28809
40.592529	0.07258378	0.0021384496	569.60254
41.493408	0.078647733	0.002403731	591.71063
42.394287	0.081547298	0.0024961308	614.00085
43.295166	0.080372453	0.0026428029	637.79987
44.196045	0.089436933	0.0025947078	665.96033
45.096924	0.08715342	0.0027119608	680.85913
45.997803	0.087818496	0.0028854809	698.21515
46.898682	0.091160476	0.0030180854	720.82336
47.799561	0.092365235	0.0033568356	741.55853
48.700439	0.096486509	0.003293934	765.9054
49.601318	0.099082887	0.0034109557	793.15015
50.502197	0.10187448	0.0035581912	821.16187
51.403076	0.10552051	0.00346212	846.45367
52.303955	0.10659634	0.0036584812	862.91119
53.204834	0.11333367	0.0037053346	897.26593
54.105713	0.11531107	0.0040864977	925.96216
55.006592	0.11365883	0.0041044489	944.16461
55.907471	0.12059024	0.0044451961	975.40015
56.80835	0.12073059	0.0043917769	990.79132
57.709229	0.126709	0.0046020583	1028.3198
58.610107	0.1284387	0.0046280059	1046.9497
59.510986	0.12847352	0.0048803915	1066.8549
60.411865	0.13073961	0.004935957	1091.1282
61.312744	0.13477387	0.0052029802	1117.1376
62.213623	0.1359901	0.0051218937	1139.0048
63.114502	0.14177325	0.0053937766	1174.5494
64.015381	0.14276165	0.0053958911	1195.1145
64.91626	0.14629582	0.0056487727	1219.403
65.817139	0.14727084	0.0057017249	1242.7716
66.718018	0.15245841	0.0058127213	1270.6768
67.618896	0.15256332	0.0060474169	1296.3145
68.519775	0.15507995	0.0061558974	1323.9952
69.420654	0.16360126	0.0061626588	1355.712
70.321533	0.16218245	0.0063947602	1378.2463
71.222412	0.16278113	0.0063924408	1395.6593
72.123291	0.16771071	0.0067400425	1430.0118
73.02417	0.16926931	0.0067589497	1449.6969
73.925049	0.17253999	0.0070380615	1477.7659
74.825928	0.17497364	0.0070365537	1494.8038
75.726807	0.18044761	0.0070802844	1527.235
76.627686	0.18552029	0.0071952846	1548.5598
77.528564	0.18472183	0.0074779452	1582.271
78.429443	0.18689178	0.0076201907	1603.485
79.330322	0.18751813	0.0076673976	1625.718
80.231201	0.19040643	0.0078243092	1646.4138
81.13208	0.19328003	0.0081862202	1678.5321
82.032959	0.19619475	0.0082201334	1699.8738
82.933838	0.20362318	0.0083199758	1724.5814
83.834717	0.20303744	0.0085077323	1742.3042
84.735596	0.20546003	0.0085947514	1769.2031
85.636475	0.20636503	0.0089196684	1799.1368
86.537354	0.21256191	0.0089065311	1821.4739
87.438232	0.21331754	0.0090754777	1843.8895
88.339111	0.21257542	0.0091931047	1863.5543
89.23999	0.21919289	0.0093419719	1885.1713
90.140869	0.2223205	0.0096082333	1914.135
91.041748	0.22637488	0.0096790921	1923.6853
91.942627	0.2268908	0.0098429909	1953.4026
92.843506	0.22758062	0.010106859	1974.7313
93.744385	0.23277619	0.0098881973	1995.0303
94.645264	0.23189947	0.010396642	2012.182
95.546143	0.23924127	0.010438586	2035.6321
96.447021	0.2405097	0.010605099	2057.3931
97.3479	0.24082831	0.010940612	2078.3696
98.248779	0.24426858	0.011135604	2100.6052
99.149658	0.24941128	0.011319726	2107.6169
100.05054	0.24940883	0.011331671	2120.3193
100.95142	0.25336772	0.011552949	2149.1074
101.85229	0.25859132	0.011741514	2163.9236
102.75317	0.26015833	0.011771037	2176.115
103.65405	0.2637912	0.011980869	2198.2122
104.55493	0.26329413	0.012229959	2213.564
105.45581	0.26970205	0.012497503	2230.0708
106.35669	0.26961824	0.012595572	2241.8162
107.25757	0.27616033	0.012809864	2264.9753
108.15845	0.27567738	0.01302149	2268.9919
109.05933	0.27783531	0.013066176	2278.9973
109.96021	0.28425729	0.013453046	2304.8723
110.86108	0.28798687	0.013582901	2325.5657
111.76196	0.28457427	0.01380659	2334.7861
112.66284	0.29197571	0.014070547	2349.9399
113.56372	0.29292557	0.014258729	2366.5024
114.4646	0.295082	0.014432829	2371.2197
115.36548	0.29827824	0.014609929	2386.0789
116.26636	0.30235961	0.014744542	2392.9307
117.16724	0.30571473	0.015150114	2407.9534
118.06812	0.31001779	0.015306993	2424.9275
118.96899	0.3118726	0.015477261	2430.4756
119.86987	0.31246904	0.015830906	2440.0508
120.77075	0.3161394	0.016063003	2460.2803
121.67163	0.31884807	0.016298048	2466.8599
122.57251	0.32045606	0.016594509	2477.8975
123.47339	0.3211301	0.016929802	2484.5471
124.37427	0.32629433	0.017230393	2501.2258
125.27515	0.33137453	0.017470153	2512.3955
126.17603	0.32934019	0.017740151	2516.2253
127.0769	0.33417171	0.017993836	2530.2937
127.97778	0.33467999	0.018448772	2535.1597
128.87866	0.3393527	0.018782174	2554.9832
129.77954	0.34325007	0.01907419	2555.5564
130.68042	0.3439967	0.019463709	2566.6714
131.5813	0.34888205	0.019857181	2574.0725
132.48218	0.35104552	0.020538254	2584.1357
133.38306	0.35306036	0.020662254	2594.1155
134.28394	0.35764781	0.020896539	2594.3206
135.18481	0.35993233	0.021589587	2612.5095
136.08569	0.35968339	0.021922257	2607.3669
136.98657	0.36279094	0.022502124	2618.1423
137.88745	0.36795312	0.022961555	2626.0735
138.78833	0.37195623	0.023303935	2637.7446
139.68921	0.36934713	0.023849599	2635.4963
140.59009	0.37294009	0.024216959	2646.7134
141.49097	0.37634391	0.024845812	2650.459
142.39185	0.37951863	0.025334697	2657.2083
143.29272	0.38051277	0.025951223	2661.8501
144.1936	0.38277391	0.026571164	2672.8604
145.09448	0.38932544	0.027170291	2675.655
145.99536	0.38827375	0.027686626	2670.7656
146.89624	0.3936494	0.028279848	2683.2373
147.79712	0.39284623	0.028891515	2687.3982
148.698	0.39834547	0.029659338	2690.4268
149.59888	0.40093344	0.030470194	2706.3323
150.49976	0.40381905	0.03143049	2707.0947
151.40063	0.40786028	0.032021951	2710.199
152.30151	0.40695283	0.032661688	2709.8044
153.20239	0.41075003	0.033495899	2718.0945
154.10327	0.41270119	0.034320638	2726.8088
155.00415	0.41644636	0.035310011	2732.4319
155.90503	0.41889864	0.036174491	2727.6892
156.80591	0.42305112	0.036775246	2737.0129
157.70679	0.42273313	0.037818812	2738.2632
158.60767	0.43081069	0.038797814	2755.5618
159.50854	0.43215555	0.039777707	2750.344
160.40942	0.43551961	0.040690765	2754.8975
161.3103	0.43835384	0.041666262	2762.4312
162.21118	0.44020402	0.042642795	2765.0452
163.11206	0.44245592	0.043716591	2763.3857
164.01294	0.44567573	0.044733778	2771.1611
164.91382	0.44475645	0.04550143	2768.1323
165.8147	0.4512569	0.04645073	2771.4358
166.71558	0.455282	0.047476858	2780.9795
167.61646	0.45809796	0.048601236	2784.4487
168.51733	0.46045518	0.049947321	2789.0049
169.41821	0.46022019	0.050954763	2784.9297
170.31909	0.46142697	0.051789574	2790.0383
171.21997	0.46894208	0.052871004	2795.9819
172.12085	0.47083014	0.053865321	2800.99
173.02173	0.47195214	0.055138644	2803.8677
173.92261	0.47213259	0.056169406	2802.7502
174.82349	0.47566876	0.057397489	2802.6211
175.72437	0.48076028	0.058341328	2805.4041
176.62524	0.48479906	0.059441064	2812.6892
177.52612	0.48338285	0.060476568	2807.895
178.427	0.48869726	0.061575469	2811.4067
179.32788	0.49084568	0.063059941	2824.8276
180.22876	0.49251902	0.064098954	2816.4851
181.12964	0.49405324	0.065302923	2820.1821
182.03052	0.49989274	0.066738337	2827.0171
182.9314	0.50129503	0.067696847	2821.5396
183.83228	0.50731713	0.068941332	2832.1797
184.73315	0.50784552	0.070151567	2837.3718
185.63403	0.51172614	0.071549393	2837.1282
186.53491	0.51337236	0.072962664	2841.3877
187.43579	0.51467097	0.074165665	2840.2542
188.33667	0.51985854	0.075226158	2835.2683
189.23755	0.52255976	0.076394342	2846.2554
190.13843	0.52315784	0.077566989	2843.4692
191.03931	0.53052956	0.078938983	2849.2363
191.94019	0.52986425	0.080097288	2853.0667
192.84106	0.52958047	0.081328258	2845.3296
193.74194	0.53418827	0.082714632	2859.9314
194.64282	0.53860646	0.08413174	2862.3281
195.5437	0.53944999	0.085452534	2856.7524
196.44458	0.54259068	0.08665508	2858.1616
197.34546	0.54580766	0.088042863	2864.4695
198.24634	0.54591894	0.089704216	2863.1985
199.14722	0.54891729	0.090855479	2859.9922
200.0481	0.55444336	0.092190087	2865.6846
200.94897	0.55519897	0.093466073	2867.4229
201.84985	0.55887443	0.094669551	2870.2107
202.75073	0.5628196	0.096244454	2874.2312
203.65161	0.56597573	0.097333089	2872.6199
204.55249	0.56847066	0.098461159	2870.6121
205.45337	0.57072234	0.099746875	2878.7073
206.35425	0.57518035	0.10113403	2886.3867
207.25513	0.57358098	0.10238195	2876.7949
208.15601	0.5769946	0.10369188	2884.2959
209.05688	0.58083934	0.10491967	2883.2959
209.95776	0.58605558	0.10625494	2889.1177
210.85864	0.58779514	0.10752728	2887.0889
211.75952	0.58821023	0.10875354	2882.8379
212.6604	0.59469616	0.10990118	2893.9939
213.56128	0.59503686	0.1114856	2896.3638
214.46216	0.59531331	0.1126963	2890.9797
215.36304	0.60058957	0.11396241	2893.9524
216.26392	0.60467875	0.11531258	2891.8118
217.16479	0.60808361	0.11663915	2890.7644
218.06567	0.60876298	0.1176409	2892.4011
218.96655	0.61118966	0.11898785	2900.7334
219.86743	0.61518979	0.12039034	2905.3496
220.76831	0.6145075	0.12188998	2902.646
221.66919	0.62143415	0.12314427	2905.7009
222.57007	0.6250264	0.12463275	2903.5947
223.47095	0.62453246	0.12574922	2906.4434
224.37183	0.62902653	0.12717573	2913.3892
225.27271	0.62917936	0.12882386	2913.4263
226.17358	0.63205677	0.13009267	2912.1287
227.07446	0.63407105	0.13173455	2912.3782
227.97534	0.63996446	0.13298178	2917.5142
228.87622	0.63934612	0.13431907	2919.686
229.7771	0.64428353	0.13572189	2916.6943
230.67798	0.64577079	0.13701957	2918.2041
231.57886	0.64454412	0.13844472	2915.0442
232.47974	0.65377951	0.13962953	2917.0461
233.38062	0.65261674	0.14090744	2923.2458
234.28149	0.65903836	0.14254667	2926.5991
235.18237	0.66074508	0.14362623	2924.1353
236.08325	0.6624608	0.14476873	2919.2454
236.98413	0.66316628	0.14606076	2932.1467
237.88501	0.66761726	0.14747271	2923.7134
238.78589	0.67035455	0.14876451	2931.3496
239.68677	0.67142636	0.15011178	2926.7166
240.58765	0.67612278	0.15157287	2939.2322
241.48853	0.67684239	0.15320061	2934.062
242.3894	0.68256432	0.15455541	2932.2705
243.29028	0.68647361	0.15613458	2946.4092
244.19116	0.68692559	0.15747182	2941.1226
245.09204	0.69026363	0.15896903	2939.1111
245.99292	0.69105482	0.16014539	2933.5498
246.8938	0.6926288	0.1614351	2934.1455
247.79468	0.69653422	0.16271885	2940.1099
248.69556	0.69844401	0.16411951	2940.4031
249.59644	0.702627	0.16531095	2942.085
250.49731	0.7033183	0.16661231	2940.5723
251.39819	0.7059021	0.16775802	2940.1973
252.29907	0.71057051	0.16927594	2946.2417
253.19995	0.7125389	0.17059851	2950.0679
254.10083	0.71835524	0.17211564	2949.071
255.00171	0.7191844	0.17350395	2945.6018
255.90259	0.72078812	0.17479093	2948.8386
256.80347	0.72420955	0.17597057	2950.1516
257.70435	0.72595745	0.17721114	2953.6174
258.60522	0.72909552	0.17871049	2954.1465
259.5061	0.73183852	0.17983884	2956.2803
260.40698	0.7346046	0.18092002	2952.8735
261.30786	0.73454392	0.18241346	2960.2427
262.20874	0.74116796	0.18411534	2969.1343
263.10962	0.73999172	0.18581301	2961.2258
264.0105	0.74589187	0.18719916	2963.6802
264.91138	0.75077927	0.18854098	2971.9453
265.81226	0.75076801	0.19007803	2960.8545
266.71313	0.75520551	0.19134313	2966.1699
267.61401	0.75645512	0.19253393	2962.8684
268.51489	0.76099813	0.19354796	2964.4812
269.41577	0.76147532	0.19483685	2968.5874
270.31665	0.76289171	0.1963485	2970.9883
271.21753	0.76647359	0.19785245	2969.8721
272.11841	0.76975423	0.1991355	2975.8245
273.01929	0.77489758	0.20084599	2979.5342
273.92017	0.77378768	0.20227729	2972.8528
274.82104	0.77426589	0.2041111	2979.5564
275.72192	0.77972066	0.20560387	2979.0276
276.6228	0.78415793	0.20680669	2966.5085
277.52368	0.78550237	0.20792255	2977.0654
278.42456	0.79028141	0.20935011	2984.8601
279.32544	0.79384691	0.21074325	2982.0798
280.22632	0.79452401	0.21197145	2979.623
281.1272	0.79852426	0.21347873	2987.3555
282.02808	0.7996155	0.21502921	2987.6042
282.92896	0.8008641	0.21620899	2986.1587
283.82983	0.80412579	0.21746276	2983.2148
284.73071	0.8071382	0.21861358	2986.0747
285.63159	0.81005335	0.21988781	2987.9441
286.53247	0.81586748	0.22138892	2997.2378
287.43335	0.81625473	0.22263157	2987.3345
288.33423	0.81898546	0.22399168	2985.9365
289.23511	0.8218748	0.22517839	2994.1841
290.13599	0.82261527	0.22639491	2990.9641
291.03687	0.82764673	0.22741424	2987.9512
291.93774	0.82969749	0.22876722	2998.5076
292.83862	0.83136874	0.23006921	2992.4719
293.7395	0.83401775	0.23131672	2994.5156
294.64038	0.84160602	0.23252918	2997.2239
295.54126	0.84070593	0.23377612	2998.3374
296.44214	0.84172159	0.23508389	3001.3958
297.34302	0.84653193	0.23672898	3007.7686
298.2439	0.85134274	0.23809782	3010.7068
299.14478	0.85098213	0.23954643	2999.1372
300.04565	0.85528088	0.24093877	3004.8938
300.94653	0.85631639	0.24224298	3002.4363
301.84741	0.85757649	0.2434026	3010.1553
302.74829	0.86404335	0.24518548	3007.2024
303.64917	0.86244911	0.24636409	3007.3157
304.55005	0.86820298	0.2479547	3015.2554
305.45093	0.87067294	0.24916641	3010.1057
306.35181	0.87326437	0.25089872	3013.2683
307.25269	0.87853795	0.25205231	3011.9326
308.15356	0.87810898	0.25333437	3010.137
309.05444	0.88099706	0.25472125	3019.5659
309.95532	0.88348299	0.25629681	3017.3303
310.8562	0.88698107	0.25769305	3010.5342
311.75708	0.88938415	0.25921765	3023.0767
312.65796	0.88863224	0.26048267	3009.6006
313.55884	0.89307934	0.26173386	3009.8528
314.45972	0.89937538	0.26303938	3034.5029
315.3606	0.90152222	0.26448318	3026.7468
316.26147	0.90214545	0.26567665	3020.8276
317.16235	0.90667492	0.26693311	3023.9668
318.06323	0.90582299	0.26828855	3025.7793
318.96411	0.91125566	0.26957941	3025.9089
319.86499	0.91338998	0.27103901	3025.2124
320.76587	0.91426015	0.27240327	3027.7393
321.66675	0.91802555	0.27385592	3032.5422
322.56763	0.9224354	0.27490148	3020.2275
323.46851	0.92481256	0.27606827	3027.3232
324.36938	0.92691982	0.27736902	3034.9099
325.27026	0.92759204	0.27870956	3022.4402
326.17114	0.93071246	0.28004462	3035.7236
327.07202	0.93203169	0.28159589	3035.3762
327.9729	0.93691367	0.28279617	3035.4355
328.87378	0.94290131	0.28412029	3035.8286
329.77466	0.9402445	0.28549242	3032.8198
330.67554	0.94777989	0.28692243	3045.7129
331.57642	0.95086598	0.28847688	3045.1589
332.47729	0.9517265	0.28994906	3042.1133
333.37817	0.95562488	0.29125819	3043.7312
334.27905	0.95621598	0.29256159	3039.7224
335.17993	0.95894611	0.29384762	3040.9963
336.08081	0.96079993	0.29512969	3042.7446
336.98169	0.96452141	0.29659677	3042.7649
337.88257	0.96875912	0.2981585	3047.9016
338.78345	0.9698292	0.29925674	3042.3401
339.68433	0.96936142	0.30069077	3041.4167
340.58521	0.97455555	0.3020629	3045.3281
341.48608	0.97849768	0.3033258	3048.8638
342.38696	0.9827683	0.30464476	3054.7844
343.28784	0.9814626	0.30594596	3049.0251
344.18872	0.98640549	0.30724895	3045.4863
345.0896	0.98801881	0.30880889	3056.3804
345.99048	0.99197972	0.31022072	3056.6255
346.89136	0.99266851	0.31167337	3052.7825
347.79224	0.99680382	0.31301969	3059.4363
348.69312	1.0058548	0.31430921	3059.6157
349.59399	0.99739695	0.31551984	3056.6191
350.49487	1.0059308	0.31673148	3049.0903
351.39575	1.009866	0.31801039	3061.8545
352.29663	1.009537	0.31923717	3061.3284
353.19751	1.0147822	0.32080355	3067.3889
354.09839	1.0142937	0.32196766	3056.8145
354.99927	1.0194055	0.3232204	3066.4124
355.90015	1.0197183	0.32468817	3061.1216
356.80103	1.0249045	0.3260439	3062.8892
357.7019	1.0289701	0.32715884	3066.2927
358.60278	1.0315235	0.32861915	3072.5742
359.50366	1.0314628	0.32995901	3065.8086
360.40454	1.0359925	0.33139279	3064.4873
361.30542	1.0380459	0.33261657	3066.5852
362.2063	1.0398464	0.33404022	3074.4365
363.10718	1.0433024	0.33528414	3069.5569
364.00806	1.0455688	0.33645511	3065.1714
364.90894	1.0492018	0.33766919	3067.9028
365.80981	1.050595	0.33868882	3076.165
366.71069	1.0503789	0.33996105	3068.5815
367.61157	1.0551034	0.34136099	3079.125
368.51245	1.0627359	0.34267268	3079.4338
369.41333	1.0640413	0.34425062	3082.6265
370.31421	1.0632012	0.3455722	3077.8132
371.21509	1.0659215	0.34695348	3079.2791
372.11597	1.066204	0.34823239	3078.9009
373.01685	1.0728239	0.34955215	3080.3252
373.91772	1.0767343	0.35111454	3082.2859
374.8186	1.0784218	0.35234049	3079.2712
375.71948	1.0829245	0.35373759	3084.5977
376.62036	1.08634	0.35516116	3091.1782
377.52124	1.0854151	0.35643321	3076.5828
378.42212	1.0878625	0.35764569	3077.8894
379.323	1.0897579	0.35872531	3080.9109
380.22388	1.0941663	0.36010298	3083.0273
381.12476	1.096921	0.36160102	3093.0774
382.02563	1.1001779	0.36313993	3089.9988
382.92651	1.1000109	0.364719	3089.324
383.82739	1.1023033	0.3661212	3090.998
384.72827	1.1059619	0.36742079	3089.7695
385.62915	1.1109577	0.36881948	3093.0781
386.53003	1.1144849	0.37010142	3091.7471
387.43091	1.1136785	0.37146708	3094.7603
388.33179	1.1168365	0.37272605	3090.2769
389.23267	1.1231906	0.37415439	3094.9731
390.13354	1.1263992	0.37538701	3099.5596
391.03442	1.1243957	0.37638617	3090.2715
391.9353	1.1314492	0.37776887	3097.4282
392.83618	1.1310544	0.37886602	3102.8345
393.73706	1.1334375	0.38014388	3097.5754
394.63794	1.1367698	0.38125697	3094.9985
395.53882	1.1380905	0.38263908	3099.5137
396.4397	1.1407975	0.38391566	3099.7397
397.34058	1.1441238	0.38514832	3104.1411
398.24146	1.148407	0.38623592	3100.054
399.14233	1.1522491	0.3876116	3103.3708
400.04321	1.1536518	0.38881958	3109.5178
400.94409	1.1587133	0.39038813	3110.5378
401.84497	1.1595774	0.39153132	3106.9192
402.74585	1.1617836	0.39280152	3100.9775
403.64673	1.1629905	0.39416069	3110.5513
404.54761	1.1661924	0.39542413	3110.9463
405.44849	1.1709944	0.39686951	3113.7615
406.34937	1.1738403	0.39796191	3109.4004
407.25024	1.1757637	0.39928842	3109.5845
408.15112	1.1785647	0.40068465	3111.7539
409.052	1.183936	0.40190953	3117.6621
409.95288	1.1833194	0.40358505	3125.542
410.85376	1.1861584	0.40501508	3117.9209
411.75464	1.189597	0.40646183	3117.3298
412.65552	1.1922681	0.4078801	3119.2419
413.5564	1.1983345	0.40928346	3124.7505
414.45728	1.1959031	0.4105643	3119.4797
415.35815	1.1992639	0.41160786	3113.3474
416.25903	1.2041285	0.4131892	3127.2239
417.15991	1.204253	0.41441515	3118.2786
418.06079	1.2049787	0.41573393	3121.1013
418.96167	1.2122018	0.41733053	3126.4841
419.86255	1.2129021	0.41875657	3120.0325
420.76343	1.2162759	0.42013782	3133.3091
421.66431	1.219577	0.42147598	3123.553
422.56519	1.2242669	0.4225072	3124.5874
423.46606	1.2257144	0.42379424	3123.1875
424.36694	1.226369	0.42469853	3124.7878
425.26782	1.230106	0.42619234	3127.4133
426.1687	1.231263	0.42745703	3126.4944
427.06958	1.2370124	0.42872208	3133.2791
427.97046	1.2399865	0.42981061	3131.6875
428.87134	1.2409605	0.43078348	3130.8054
429.77222	1.2411853	0.43187571	3129.5181
430.6731	1.2477188	0.4333038	3133.8074
431.57397	1.2484585	0.43449125	3132.4155
432.47485	1.2510006	0.43561748	3137.3264
433.37573	1.2547244	0.43706253	3140.5906
434.27661	1.2575229	0.43853074	3139.4519
435.17749	1.2570834	0.43974343	3131.3835
436.07837	1.2624279	0.4411906	3143.6797
436.97925	1.2638748	0.4424324	3133.9119
437.88013	1.2668626	0.44376275	3137.8682
438.78101	1.2704232	0.44514629	3137.0391
439.68188	1.273878	0.44662577	3142.0625
440.58276	1.2749695	0.44785184	3139.1985
441.48364	1.2794679	0.44927126	3141.3894
442.38452	1.2803571	0.45026845	3132.9702
443.2854	1.2846967	0.4514398	3141.5457
444.18628	1.2859644	0.45265305	3143.1797
445.08716	1.2886235	0.45389399	3147.1077
445.98804	1.2938024	0.45556009	3150.2048
446.88892	1.2961969	0.4568755	3148.6287
447.78979	1.296728	0.45813173	3147.9595
448.69067	1.3009825	0.45954233	3151.5725
449.59155	1.3009907	0.46074355	3145.3518
450.49243	1.3068181	0.4622491	3147.2307
451.39331	1.3052557	0.46358591	3150.636
452.29419	1.3125951	0.46487221	3149.3662
453.19507	1.3114628	0.46620673	3145.9038
454.09595	1.3151277	0.46733063	3148.4788
454.99683	1.3172418	0.46859464	3146.3064
455.89771	1.3212849	0.46988556	3150.0156
456.79858	1.3236063	0.47123829	3153.8911
457.69946	1.3247674	0.47246298	3153.002
458.60034	1.3287338	0.47386876	3157.0183
459.50122	1.3315891	0.47530314	3155.2485
460.4021	1.3379381	0.47659582	3157.3149
461.30298	1.337693	0.47788426	3155.3176
462.20386	1.340063	0.47923496	3155.1626
463.10474	1.3432305	0.4803881	3158.9685
464.00562	1.3466561	0.48166898	3160.1292
464.90649	1.3518355	0.48291889	3164.1897
465.80737	1.3517967	0.48423207	3162.1653
466.70825	1.3516519	0.48528042	3157.4932
467.60913	1.3566946	0.48646668	3163.5896
468.51001	1.3605003	0.48785192	3162.0935
469.41089	1.3599566	0.48914778	3165.7769
470.31177	1.3660682	0.49059251	3165.7131
471.21265	1.367586	0.49192905	3164.3193
472.11353	1.3691211	0.49325061	3165.9036
473.0144	1.3719271	0.49470419	3163.334
473.91528	1.3758889	0.49623534	3172.8745
474.81616	1.3771148	0.49748343	3166.7087
475.71704	1.3808323	0.49891806	3166.5085
476.61792	1.3849918	0.50021338	3174.3191
477.5188	1.3887861	0.50150895	3171.2002
478.41968	1.3899859	0.50300038	3173.0876
479.32056	1.3913027	0.50454462	3173.1765
480.22144	1.3937044	0.50584245	3172.3308
481.12231	1.3979836	0.50751889	3177.1299
482.02319	1.4011482	0.50875348	3169.7466
482.92407	1.4029168	0.51033175	3179.3823
483.82495	1.4042039	0.51179534	3174.6548
484.72583	1.4056066	0.51312429	3176.3201
485.62671	1.4122887	0.51464099	3176.27
486.52759	1.412641	0.51566416	3176.6777
487.42847	1.4167749	0.51683766	3175.9634
488.32935	1.4179524	0.51806349	3177.407
489.23022	1.4241949	0.51953995	3181.6807
490.1311	1.4245669	0.52074164	3176.7346
491.03198	1.4246998	0.52205652	3179.0696
491.93286	1.4303157	0.52327257	3177.4468
492.83374	1.4316723	0.52440703	3181.5981
493.73462	1.4371283	0.52573341	3186.4153
494.6355	1.4393598	0.52717972	3189.7903
495.53638	1.4418285	0.52882886	3191.4487
496.43726	1.4422191	0.53010714	3181.2661
497.33813	1.4466673	0.53149384	3181.1255
498.23901	1.450243	0.53297263	3188.5774
499.13989	1.45217	0.53417218	3184.7981
500.04077	1.4547126	0.53535795	3183.2195
500.94165	1.4579227	0.53625137	3183.7163
501.84253	1.4615117	0.53733218	3181.1602
502.74341	1.4624214	0.53840786	3188.4509
503.64429	1.4657342	0.53981179	3193.7205
504.54517	1.4662118	0.54131544	3185.2698
505.44604	1.469582	0.54273123	3191.8699
506.34692	1.4715234	0.54406953	3190.749
507.2478	1.4744873	0.54531443	3187.4932
508.14868	1.479915	0.54651022	3196.8804
509.04956	1.4825146	0.54808724	3195.7019
509.95044	1.4844023	0.54907513	3186.3464
510.85132	1.4822628	0.55031222	3189.8142
511.7522	1.4877768	0.55137324	3188.3867
512.65308	1.4915562	0.55262285	3199.1853
513.55396	1.4926294	0.55396068	3197.5574
514.45483	1.4971727	0.55563104	3199.0239
515.35571	1.5019994	0.55710083	3196.3281
516.25659	1.5043324	0.5584892	3197.1335
517.15747	1.5046998	0.55993062	3198.5491
518.05835	1.5089606	0.56135994	3197.8535
518.95923	1.5142093	0.56271195	3200.644
519.86011	1.5146172	0.56417042	3204.094
520.76099	1.5138003	0.56549007	3196.9143
521.66187	1.5186219	0.5668084	3196.4231
522.56274	1.5196419	0.56812441	3202.8586
523.46362	1.5242435	0.5694108	3201.5886
524.3645	1.5274932	0.57074243	3206.9429
525.26538	1.5282423	0.57236272	3211.509
526.16626	1.5312685	0.57378751	3205.7825
527.06714	1.5362176	0.57518119	3203.5557
527.96802	1.5368268	0.57627869	3201.1714
528.8689	1.5404307	0.57781857	3205.5803
529.76978	1.5435128	0.57905686	3208.8604
530.67065	1.5456513	0.5803439	3206.7688
531.57153	1.5488303	0.58165574	3203.5508
532.47241	1.5473456	0.58284986	3205.5178
533.37329	1.5538317	0.58441508	3211.1899
534.27417	1.5537833	0.58566594	3209.8816
535.17505	1.5589809	0.58700645	3207.5654
536.07593	1.5610923	0.5882749	3206.8228
536.97681	1.565089	0.5895806	3211.8318
537.87769	1.5647255	0.59066433	3206.8486
538.77856	1.5675508	0.59206498	3211.9961
539.67944	1.5733203	0.59351909	3213.9309
540.58032	1.5754222	0.59498799	3216.2129
541.4812	1.5777286	0.59595633	3206.1741
542.38208	1.582182	0.59748489	3216.3352
543.28296	1.5828019	0.59874105	3214.3611
544.18384	1.5858397	0.60003871	3213.4749
545.08472	1.5883318	0.60129571	3216.1987
545.9856	1.5918118	0.60266048	3218.8855
546.88647	1.5928353	0.60407418	3215.6597
547.78735	1.5946715	0.60561985	3220.272
548.68823	1.5990903	0.60709566	3221.4253
549.58911	1.6041664	0.60844916	3218.7554
550.48999	1.6060168	0.60964853	3219.3015
551.39087	1.6072268	0.61118793	3218.4497
552.29175	1.60901	0.61282134	3219.7114
553.19263	1.6125929	0.61408627	3224.2952
554.09351	1.6157115	0.61534894	3219.5139
554.99438	1.6197982	0.61663365	3215.6934
555.89526	1.6231605	0.61805576	3230.1023
556.79614	1.6239034	0.61949283	3226.6929
557.69702	1.625936	0.62088889	3224.7939
558.5979	1.6309308	0.62234235	3231.8418
559.49878	1.6316437	0.62377506	3226.6174
560.39966	1.6346189	0.62531245	3224.0044
561.30054	1.6378134	0.62674022	3222.9536
562.20142	1.6419104	0.62787932	3220.6785
563.10229	1.6424345	0.62910205	3222.1365
564.00317	1.6482548	0.6304335	3232.0332
564.90405	1.6495894	0.63193071	3228.8391
565.80493	1.6498624	0.63314879	3230.2705
566.70581	1.6534225	0.63467956	3227.8823
567.60669	1.6573639	0.63608581	3231.5544
568.50757	1.6593645	0.63721919	3225.0964
569.40845	1.6619344	0.63828993	3227.2266
570.30933	1.6657065	0.63951457	3230.5532
571.21021	1.6698568	0.64066941	3229.3748
572.11108	1.6700569	0.64206785	3228.3374
573.01196	1.6727722	0.64319545	3235.6904
573.91284	1.6754318	0.64467931	3235.7019
574.81372	1.6760972	0.64580542	3232.2332
575.7146	1.6809433	0.64710832	3236.7251
576.61548	1.6801466	0.64845228	3234.4026
577.51636	1.685341	0.64989418	3235.9709
578.41724	1.6906923	0.65142316	3240.9412
579.31812	1.6926482	0.65298277	3233.3342
580.21899	1.6949425	0.65420842	3234.0347
581.11987	1.6956987	0.65570128	3240.9377
582.02075	1.6986541	0.65687293	3234.0254
582.92163	1.7031703	0.6582725	3243.2957
583.82251	1.7057152	0.65986586	3245.5198
584.72339	1.7093345	0.66132504	3243.7869
585.62427	1.7096429	0.66267031	3237.1145
586.52515	1.7111861	0.66417193	3240.3218
587.42603	1.7165191	0.66582775	3242.551
588.3269	1.716494	0.66706407	3239.3601
589.22778	1.7205008	0.66842502	3243.1599
590.12866	1.726868	0.6699357	3246.1526
591.02954	1.7244436	0.67162627	3244.6851
591.93042	1.7284381	0.67318565	3243.5959
592.8313	1.7329265	0.67474782	3242.1177
593.73218	1.7374369	0.67617565	3240.9597
594.63306	1.7382685	0.67759883	3240.4065
595.53394	1.7386993	0.67860776	3239.8569
596.43481	1.7406141	0.68003267	3243.9033
597.33569	1.7474284	0.68137074	3249.1382
598.23657	1.747005	0.68265688	3242.0535
599.13745	1.7537427	0.68407732	3256.6738
600.03833	1.7549169	0.68528324	3245.8152
600.93921	1.7553915	0.68644392	3249.3511
601.84009	1.7600361	0.68770474	3250.9609
602.74097	1.7633067	0.68915123	3254.5093
603.64185	1.7677809	0.69072175	3251.0898
604.54272	1.765779	0.6918385	3247.9673
605.4436	1.772679	0.69325376	3247.3472
606.34448	1.7706374	0.69445324	3248.4202
607.24536	1.7761151	0.69586366	3256.719
608.14624	1.779856	0.69735008	3257.2275
609.04712	1.7833461	0.69884294	3254.709
609.948	1.7856549	0.70037425	3257.2922
610.84888	1.7864727	0.70179236	3250.4207
611.74976	1.7900637	0.70303661	3253.3621
612.65063	1.7913038	0.70453644	3253.6147
613.55151	1.7949073	0.70567334	3251.6013
614.45239	1.7979327	0.70722193	3255.5747
615.35327	1.7972785	0.70892221	3255.2405
616.25415	1.8009572	0.71054447	3254.8777
617.15503	1.8039107	0.71213275	3251.3435
618.05591	1.8070648	0.71352541	3255.3625
618.95679	1.8098522	0.71497411	3254.1875
619.85767	1.8096817	0.7161895	3254.3828
620.75854	1.8181748	0.71746016	3256.5024
621.65942	1.8195896	0.7189554	3254.553
622.5603	1.8215005	0.72024238	3256.8127
623.46118	1.8243767	0.72177696	3262.4553
624.36206	1.8275946	0.72335559	3262.3201
625.26294	1.8325646	0.72469419	3261.7058
626.16382	1.8300161	0.72638869	3257.5771
627.0647	1.8351681	0.72802579	3263.272
627.96558	1.8370521	0.72954142	3258.9021
628.86646	1.8412523	0.73081928	3259.9448
629.76733	1.8424873	0.73218477	3257.5857
630.66821	1.8485906	0.73380131	3266.9817
631.56909	1.8519096	0.73522723	3269.2871
632.46997	1.8486451	0.73680127	3263.356
633.37085	1.8555166	0.73847383	3266.9075
634.27173	1.8563383	0.73989958	3270.8772
635.17261	1.8577645	0.74132681	3262.7412
636.07349	1.8607632	0.74245882	3257.1907
636.97437	1.8649032	0.74385494	3264.1653
637.87524	1.8668722	0.74512672	3268.9663
638.77612	1.8707708	0.74697721	3270.3584
639.677	1.875761	0.748429	3270.2996
640.57788	1.8767202	0.74992919	3262.9241
641.47876	1.877425	0.75129986	3259.2397
642.37964	1.8803475	0.75270694	3264.8069
643.28052	1.8830079	0.75373894	3257.9922
644.1814	1.8856856	0.75516921	3265.8684
645.08228	1.8890526	0.75649136	3266.7627
645.98315	1.8907073	0.75829512	3276.7244
646.88403	1.895353	0.75963718	3265.5974
647.78491	1.8997703	0.76116025	3266.7549
648.68579	1.9005046	0.76253855	3274.6511
649.58667	1.9032034	0.76423073	3268.8242
650.48755	1.9058497	0.76580995	3273.2249
651.38843	1.9080025	0.76733416	3270.1855
652.28931	1.9116979	0.768682	3272.6592
653.19019	1.9154223	0.77030373	3277.9504
654.09106	1.915258	0.7717852	3275.5852
654.99194	1.9161389	0.7733472	3273.625
655.89282	1.9228561	0.77497888	3269.606
656.7937	1.9262025	0.77654392	3271.9836
657.69458	1.9288323	0.77807271	3271.4692
658.59546	1.9273413	0.77927607	3273.4902
659.49634	1.9309571	0.78126556	3280.3086
660.39722	1.9365734	0.78317839	3280.4255
661.2981	1.9377395	0.7845394	3268.9373
662.19897	1.9428897	0.78608805	3271.5571
663.09985	1.9411254	0.78744674	3270.5669
664.00073	1.9452571	0.78902799	3271.8955
664.90161	1.9497887	0.79039663	3273.3499
665.80249	1.9520823	0.7917999	3279.7805
666.70337	1.9556938	0.79339272	3278.344
667.60425	1.957203	0.79473794	3277.6555
668.50513	1.9607474	0.79639089	3280.6729
669.40601	1.9637437	0.79793274	3285.9915
670.30688	1.9641885	0.79950064	3278.2698
671.20776	1.9696007	0.80099982	3277.127
672.10864	1.970698	0.80227321	3272.4111
673.00952	1.9742665	0.80368936	3276.8765
673.9104	1.9737114	0.80502796	3274.0393
674.81128	1.9766134	0.80676001	3281.9675
675.71216	1.9806575	0.80860692	3288.2561
676.61304	1.9842895	0.80984819	3276.0022
677.51392	1.9859945	0.81129467	3274.0767
678.41479	1.9880062	0.81231338	3276.1914
679.31567	1.9883384	0.81381023	3282.5146
680.21655	1.9958897	0.81535035	3279.3635
681.11743	1.996555	0.81719333	3288.9607
682.01831	2.0011456	0.81911314	3284.6375
682.91919	2.0012565	0.82050449	3286.679
683.82007	2.0059683	0.82199663	3285.1108
684.72095	2.0092852	0.82355195	3282.3689
685.62183	2.0089996	0.82504833	3285.4021
686.52271	2.0135374	0.82662952	3284.1162
687.42358	2.0172851	0.82826459	3284.8425
688.32446	2.0199146	0.82961947	3279.9907
689.22534	2.0222676	0.83141893	3287.7966
690.12622	2.0245039	0.83261514	3283.5081
691.0271	2.0248632	0.83402282	3283.4473
691.92798	2.0306628	0.83557838	3289.8877
692.82886	2.0315654	0.83727407	3286.7251
693.72974	2.036226	0.83881104	3286.6787
694.63062	2.0369456	0.84053743	3283.0405
695.53149	2.0381944	0.84202862	3287.248
696.43237	2.0398576	0.84381592	3284.3965
697.33325	2.043889	0.84532458	3284.3711
698.23413	2.0466931	0.8470118	3286.1331
699.13501	2.0501645	0.84842741	3286.7314
700.03589	2.0519109	0.84998995	3284.0405
700.93677	2.0554233	0.85168731	3290.9287
701.83765	2.0583277	0.85360575	3290.677
702.73853	2.0593662	0.8555811	3287.3962
703.6394	2.0663316	0.8570106	3284.1213
704.54028	2.0658653	0.85853434	3283.1023
705.44116	2.0675216	0.86022896	3286.6807
706.34204	2.0740893	0.8614822	3285.1423
707.24292	2.074666	0.86316288	3290.9031
708.1438	2.0775807	0.86467755	3288.2957
709.04468	2.0784991	0.86632848	3284.8218
709.94556	2.0855262	0.86792868	3284.5625
710.84644	2.0836408	0.86939329	3283.2102
711.74731	2.092227	0.8710106	3292.7085
712.64819	2.0915051	0.87229908	3293.803
713.54907	2.0947111	0.87354958	3286.374
714.44995	2.0988317	0.87495846	3292.1589
715.35083	2.102217	0.87636584	3295.4207
716.25171	2.1011612	0.87795186	3288.5696
717.15259	2.1034129	0.87942386	3291.7698
718.05347	2.1103492	0.8811819	3302.7783
718.95435	2.1112423	0.88319337	3303.3547
719.85522	2.1145318	0.88482016	3293.5779
720.7561	2.1152947	0.88678312	3289.1963
721.65698	2.121098	0.88830155	3292.5359
722.55786	2.1221859	0.88987446	3295.0078
723.45874	2.1256883	0.89142901	3293.6101
724.35962	2.1262724	0.89295995	3299.8621
725.2605	2.1296077	0.8944062	3294.4629
726.16138	2.1331637	0.89598346	3295.6655
727.06226	2.13868	0.89775199	3302.8777
727.96313	2.1395464	0.8994841	3296.0928
728.86401	2.141643	0.9009878	3292.0928
729.76489	2.1422355	0.90259135	3296.1462
730.66577	2.1468914	0.90428537	3299.2205
731.56665	2.1478901	0.90632313	3300.9482
732.46753	2.1515357	0.90818089	3300.0947
733.36841	2.1515119	0.91004759	3294.1558
734.26929	2.1569967	0.91189289	3291.4314
735.17017	2.1598816	0.91357923	3295.9939
736.07104	2.1618633	0.91527641	3296.7422
736.97192	2.1692085	0.91717112	3300.594
737.8728	2.1669972	0.91879809	3296.9485
738.77368	2.1705852	0.92053968	3293.2505
739.67456	2.1739955	0.92170388	3293.1401
740.57544	2.1768012	0.92334729	3299.666
741.47632	2.1775351	0.92508477	3296.9319
742.3772	2.1801414	0.92667729	3296.7566
743.27808	2.1832888	0.92849165	3293.1282
744.17896	2.1863325	0.93024224	3302.1282
745.07983	2.1898489	0.93212092	3299.3198
745.98071	2.1881206	0.93388647	3296.5686
746.88159	2.195415	0.93561846	3296.4241
747.78247	2.1979213	0.93730479	3302.4397
748.68335	2.1987386	0.93885744	3295.8896
749.58423	2.2036681	0.94055146	3298.6011
750.48511	2.2068942	0.94228977	3303.6133
751.38599	2.2084596	0.94374794	3301.5239
752.28687	2.2087173	0.9455502	3298.6509
753.18774	2.2155428	0.94715768	3305.7947
754.08862	2.2156014	0.94922769	3300.0559
754.9895	2.2178705	0.95093423	3303.9692
755.89038	2.2230046	0.95263726	3296.9058
756.79126	2.2239749	0.95411843	3290.147
757.69214	2.2255259	0.95575607	3299.9036
758.59302	2.2307353	0.9572826	3301.9353
759.4939	2.2319088	0.95911509	3300.5015
760.39478	2.2345779	0.96091545	3297.2581
761.29565	2.2359874	0.96263921	3295.1919
762.19653	2.2409086	0.96404332	3300.7761
763.09741	2.2423532	0.96560782	3292.0481
763.99829	2.2465718	0.96753466	3305.7722
764.89917	2.2495193	0.9695577	3308.4985
765.80005	2.250653	0.97139025	3297.7559
766.70093	2.2533207	0.97317046	3294.3726
767.60181	2.2571914	0.97494292	3302.3899
768.50269	2.2582898	0.97675937	3299.908
769.40356	2.2593863	0.97845602	3300.7998
770.30444	2.2655995	0.98032445	3302.2126
771.20532	2.2687414	0.98189533	3303.9063
772.1062	2.2709403	0.98370856	3305.0293
773.00708	2.2743816	0.98558939	3304.0371
773.90796	2.277004	0.9875319	3309.1973
774.80884	2.27719	0.98968953	3300.5242
775.70972	2.2801216	0.99168336	3307.0586
776.6106	2.2822857	0.99384385	3301.1897
777.51147	2.2885382	0.99573886	3302.333
778.41235	2.2881567	0.99755752	3304.521
779.31323	2.2917089	0.99957687	3296.9434
780.21411	2.2940567	1.0013593	3302.5623
781.11499	2.29409	1.0032439	3304.7441
782.01587	2.2988501	1.0052017	3299.9941
782.91675	2.3019996	1.0069046	3297.7061
783.81763	2.3060427	1.0085152	3302.9954
784.71851	2.3092086	1.0101051	3302.8286
785.61938	2.3139911	1.0118836	3310.3672
786.52026	2.3115265	1.0136026	3296.0283
787.42114	2.3155673	1.0153134	3297.9126
788.32202	2.3153403	1.0168062	3297.7019
789.2229	2.3194277	1.0184178	3298.4104
790.12378	2.3255849	1.0205327	3311.7407
791.02466	2.3267934	1.0222915	3300.571
791.92554	2.3264709	1.0242357	3304.9878
792.82642	2.3307812	1.0262902	3304.4077
793.72729	2.3362255	1.0282195	3306.4475
794.62817	2.3367906	1.0303805	3304.9324
795.52905	2.3381307	1.0320385	3297.1736
796.42993	2.3419375	1.0339965	3301.5007
797.33081	2.344559	1.0361214	3304.1633
798.23169	2.350538	1.037794	3300.9211
799.13257	2.3511417	1.0397525	3299.2075
800.03345	2.3547196	1.0419388	3303.3691
800.93433	2.3593667	1.0436118	3301.9023
801.83521	2.3583477	1.0457963	3305.5125
802.73608	2.3626776	1.0477797	3304.3784
803.63696	2.3667314	1.0496029	3304.5488
804.53784	2.3692245	1.0516322	3298.8923
805.43872	2.3702765	1.0535883	3301.0137
806.3396	2.3732941	1.0552855	3296.6069
807.24048	2.3778131	1.0571479	3300.2017
808.14136	2.3769517	1.0591928	3304.5852
809.04224	2.3793161	1.0613441	3299.2268
809.94312	2.3827348	1.0631614	3302.5376
810.84399	2.3862817	1.0652237	3310.2061
811.74487	2.3891714	1.0671544	3297.4448
812.64575	2.3928592	1.0689926	3300.5696
813.54663	2.3928578	1.0710421	3299.8542
814.44751	2.3994455	1.0727867	3302.2544
815.34839	2.4000671	1.0748574	3307.6521
816.24927	2.4014678	1.0768192	3298.5566
817.15015	2.4051449	1.0790308	3302.5093
818.05103	2.4081604	1.0810635	3298.0801
818.9519	2.4109387	1.0834223	3301.177
819.85278	2.4129183	1.0856701	3298.8369
820.75366	2.4159243	1.0875446	3300.8647
821.65454	2.4205954	1.089329	3301.4219
822.55542	2.4232829	1.09139	3302.2104
823.4563	2.4276543	1.0929534	3296.8872
824.35718	2.427016	1.0950506	3302.252
825.25806	2.431088	1.0971019	3301.4705
826.15894	2.4306016	1.0994471	3302.6912
827.05981	2.4377337	1.1013548	3295.6614
827.96069	2.4384909	1.1032466	3305.6406
828.86157	2.4408119	1.1053492	3304.3
829.76245	2.4433296	1.1073352	3300.5139
830.66333	2.4475107	1.1094557	3301.8904
831.56421	2.4488652	1.1116161	3301.2817
832.46509	2.4533858	1.1137792	3303.3994
833.36597	2.453511	1.1157289	3299.2922
834.26685	2.4565604	1.1178436	3300.5364
835.16772	2.4599683	1.119903	3295.0789
836.0686	2.4633451	1.1216725	3298.6558
836.96948	2.465169	1.1237841	3300.9529
837.87036	2.4687481	1.1262282	3301.0103
838.77124	2.4692893	1.1283721	3301.1526
839.67212	2.4708529	1.1306077	3293.8552
840.573	2.4762189	1.132814	3302.1736
841.47388	2.4791906	1.1348035	3296.7588
842.37476	2.4792268	1.1366558	3298.6074
843.27563	2.4810965	1.1390923	3300.8728
844.17651	2.4876225	1.1416752	3299.7688
845.07739	2.4880607	1.1440588	3300.2859
845.97827	2.4921548	1.1461273	3300.1304
846.87915	2.4956117	1.1484689	3301.1306
847.78003	2.497777	1.1504158	3293.5098
848.68091	2.5004184	1.1522197	3290.3647
849.58179	2.504998	1.1542073	3291.9534
850.48267	2.5077224	1.1561837	3297.3181
851.38354	2.5081253	1.1582422	3294.4268
852.28442	2.5087738	1.1602495	3294.9006
853.1853	2.51612	1.1626345	3302.7029
854.08618	2.5170131	1.1648742	3290.0664
854.98706	2.516166	1.1668429	3295.0364
855.88794	2.5240541	1.1692419	3293.3103
856.78882	2.5255694	1.1713377	3297.5796
857.6897	2.5284662	1.1734196	3292.6206
858.59058	2.5319371	1.1752323	3293.4045
859.49146	2.5328772	1.1774368	3294.5222
860.39233	2.5352714	1.1797376	3297.4946
861.29321	2.5374126	1.1820923	3296.6809
862.19409	2.5421007	1.1842464	3293.5151
863.09497	2.5434976	1.1863586	3294.3196
863.99585	2.5475311	1.1895365	3299.5784
864.89673	2.548717	1.1918838	3290.7544
865.79761	2.5504425	1.1942312	3293.5742
866.69849	2.5508864	1.1965618	3289.4368
867.59937	2.5557022	1.198781	3290.334
868.50024	2.5584865	1.2015649	3299.3193
869.40112	2.5618434	1.20444	3291.3608
870.302	2.5656207	1.2066833	3291.0596
871.20288	2.5670924	1.209106	3288.543
872.10376	2.5719311	1.2113738	3293.1079
873.00464	2.5734699	1.2133334	3287.2419
873.90552	2.5752301	1.2154739	3289.7322
874.8064	2.5768104	1.2180067	3285.353
875.70728	2.5806978	1.220305	3288.1089
876.60815	2.5828795	1.2224343	3284.7041
877.50903	2.5847707	1.2243298	3282.4524
878.40991	2.5929348	1.2266937	3288.446
879.31079	2.5924428	1.2286272	3286.7109
880.21167	2.5964301	1.2308849	3290.2729
881.11255	2.5963922	1.2331588	3285.2732
882.01343	2.5998878	1.235914	3291.1506
882.91431	2.6039789	1.2384913	3287.8508
883.81519	2.6033154	1.2409581	3284.0366
884.71606	2.607372	1.2435977	3284.8757
885.61694	2.6126137	1.2461309	3289.4463
886.51782	2.6147261	1.2485315	3285.8806
887.4187	2.617306	1.2511555	3283.8362
888.31958	2.6178184	1.2537363	3284.189
889.22046	2.6204803	1.2560556	3276.1746
890.12134	2.6222975	1.2586001	3277.0461
891.02222	2.6273892	1.2606758	3280.5222
891.9231	2.6300757	1.2630491	3285.269
892.82397	2.635359	1.2654364	3281.2815
893.72485	2.6374016	1.2679759	3280.0593
894.62573	2.6352649	1.2703272	3283.7441
895.52661	2.6385067	1.2724866	3276.1711
896.42749	2.6418736	1.2749842	3274.9792
897.32837	2.6433313	1.2776862	3284.3613
898.22925	2.6484573	1.2805442	3278.1118
899.13013	2.6498902	1.2835149	3278.4612
900.03101	2.6542985	1.2861937	3277.0471
900.93188	2.6562569	1.2885542	3276.3933
901.83276	2.6581466	1.2907839	3275.4363
902.73364	2.6623554	1.2933303	3274.668
903.63452	2.6652451	1.2956905	3271.4233
904.5354	2.6651721	1.2985095	3278.4675
905.43628	2.6726882	1.3009671	3275.2905
906.33716	2.6737206	1.3031446	3266.3645
907.23804	2.6763806	1.3055758	3268.9175
908.13892	2.6791923	1.3078924	3270.8252
909.03979	2.6814818	1.310725	3275.7324
909.94067	2.6840427	1.3134638	3274.8406
910.84155	2.6865335	1.315936	3270.9182
911.74243	2.6885004	1.3185862	3271.5159
912.64331	2.689821	1.3208661	3265.6106
913.54419	2.6935277	1.3237805	3268.55
914.44507	2.6961408	1.3263407	3268.8357
915.34595	2.7019517	1.3290737	3271.6426
916.24683	2.7005224	1.3318123	3261.314
917.14771	2.704736	1.3346208	3267.6919
918.04858	2.704963	1.3371594	3260.7847
918.94946	2.7103496	1.3397	3263.2939
919.85034	2.7124822	1.3421468	3262.7246
920.75122	2.715148	1.3450847	3260.4351
921.6521	2.7205567	1.347484	3263.8079
922.55298	2.7225916	1.3499844	3262.3389
923.45386	2.725208	1.3530588	3259.7478
924.35474	2.7288702	1.3553885	3258.875
925.25562	2.7301631	1.357895	3254.4404
926.15649	2.7337308	1.3602462	3259.1948
927.05737	2.7366695	1.3632849	3261.7014
927.95825	2.736104	1.3661221	3256.593
928.85913	2.7391582	1.3688928	3257.6111
929.76001	2.7408333	1.3717263	3253.1877
930.66089	2.7450185	1.3745619	3256.6333
931.56177	2.7497811	1.3772609	3248.3494
932.46265	2.7509615	1.3802959	3255.6658
933.36353	2.7535298	1.3826828	3253.5176
934.2644	2.7568219	1.3856417	3252.512
935.16528	2.7595994	1.3880919	3248.9563
936.06616	2.7615471	1.3908166	3248.7822
936.96704	2.7648046	1.3933095	3242.8777
937.86792	2.766408	1.39584	3248.1306
938.7688	2.7685866	1.3987166	3249.2449
939.66968	2.7718296	1.4019117	3244.5513
940.57056	2.7761378	1.4045578	3244.7224
941.47144	2.7783659	1.4074371	3246.1628
942.37231	2.7825801	1.4100112	3238.5903
943.27319	2.783483	1.4124379	3242.6838
944.17407	2.7882533	1.4147122	3238.5632
945.07495	2.7893283	1.4174452	3242.8152
945.97583	2.7925506	1.4202621	3242.9939
946.87671	2.7934039	1.4233546	3239.9932
947.77759	2.7957242	1.4264766	3235.8208
948.67847	2.8010385	1.4292287	3235.937
949.57935	2.8031971	1.4320551	3233.2915
950.48022	2.8029945	1.4349688	3230.6946
951.3811	2.8065882	1.4376043	3227.8074
952.28198	2.8136275	1.4398705	3230.6152
953.18286	2.8114331	1.442696	3229.6731
954.08374	2.8146369	1.4460894	3229.7478
954.98462	2.8187611	1.4495312	3230.8638
955.8855	2.8190289	1.4523207	3220.6682
956.78638	2.8225734	1.4548843	3218.6821
957.68726	2.8290949	1.4576797	3229.7791
958.58813	2.8292756	1.4603581	3217.3367
959.48901	2.8325155	1.46278	3220.6919
960.38989	2.8332865	1.4650954	3212.7593
961.29077	2.8394325	1.4677697	3222.5938
962.19165	2.8409677	1.4709148	3223.5991
963.09253	2.8430345	1.4737818	3215.854
963.99341	2.846801	1.4764273	3217.4304
964.89429	2.8495641	1.4790819	3218.4417
965.79517	2.8509569	1.481649	3209.7151
966.69604	2.8545327	1.4839817	3207.6545
967.59692	2.859704	1.4867665	3215.5398
968.4978	2.860549	1.4896445	3210.6807
969.39868	2.8580205	1.4926035	3205.5251
970.29956	2.8670478	1.4958987	3211.8816
971.20044	2.86589	1.498794	3199.6489
972.10132	2.8685739	1.5013287	3196.0559
973.0022	2.8733938	1.5039166	3198.4688
973.90308	2.8759475	1.506688	3201.8337
974.80396	2.8775342	1.5096917	3199.1082
975.70483	2.8833771	1.5127182	3200.4514
976.60571	2.8868575	1.5151632	3194.2478
977.50659	2.8852746	1.5175335	3191.312
978.40747	2.8908858	1.5205605	3202.4771
979.30835	2.8921094	1.5234511	3186.9822
980.20923	2.8927214	1.5257534	3188.5198
981.11011	2.8985717	1.5291016	3198.002
982.01099	2.8992631	1.5327585	3194.3538
982.91187	2.9029818	1.5359836	3182.3633
983.81274	2.9025457	1.5390686	3180.4478
984.71362	2.908659	1.5413299	3177.4358
985.6145	2.9136283	1.5438362	3184.7073
986.51538	2.9151344	1.5468642	3183.5779
987.41626	2.9165916	1.5492589	3173.2009
988.31714	2.9201231	1.5520861	3178.3328
989.21802	2.9215055	1.5548589	3174.9768
990.1189	2.9229176	1.5578996	3172.2661
991.01978	2.9260674	1.5614463	3176.6528
991.92065	2.9305286	1.5642784	3171.9456
992.82153	2.9333577	1.5668364	3171.1956
993.72241	2.9323781	1.5698171	3172.0906
994.62329	2.9375587	1.5726317	3167.5654
995.52417	2.941426	1.5758007	3166.4043
996.42505	2.9432158	1.5782216	3155.0208
997.32593	2.9474833	1.58134	3165.448
998.22681	2.9520309	1.584118	3159.5742
999.12769	2.9540508	1.5867325	3156.5596
1000.0286	2.9553339	1.5892148	3152.5388
1000.9294	2.9556782	1.5914229	3149.2947
1001.8303	2.9606595	1.5940143	3151.4854
1002.7312	2.9623249	1.5967954	3151.7568
1003.6321	2.9665627	1.5996597	3153.4346
1004.533	2.9673822	1.6027954	3147.9822
1005.4338	2.9717703	1.6060195	3143.907
1006.3347	2.9729681	1.609001	3141.1553
1007.2356	2.9758129	1.6119351	3139.5525
1008.1365	2.9777668	1.6149049	3140.8677
1009.0374	2.983073	1.6179557	3137.5815
1009.9382	2.9841206	1.620092	3129.6003
1010.8391	2.9886703	1.6228673	3133.2117
1011.74	2.9896514	1.6248821	3126.0789
1012.6409	2.9933162	1.6266316	3122.4985
1013.5417	2.9951239	1.6286581	3124.4329
1014.4426	2.9974418	1.6308991	3127.4978
1015.3435	3.0012598	1.6333953	3126.6211
1016.2444	3.0037506	1.6365256	3129.2085
1017.1453	3.0045862	1.6395433	3122.7654
1018.0461	3.0069478	1.6427743	3118.3645
1018.947	3.0100322	1.646266	3118.262
1019.8479	3.0158234	1.649364	3113.4158
1020.7488	3.0187416	1.6516504	3106.9829
1021.6497	3.0189891	1.6544924	3112.0381
1022.5505	3.0221226	1.6571556	3103.1348
1023.4514	3.0232284	1.6601291	3111.7493
1024.3523	3.025322	1.6629455	3106.0808
1025.2532	3.0294135	1.6655456	3096.7839
1026.1541	3.033061	1.6682737	3100.2534
1027.0549	3.0344279	1.6713916	3099.9001
1027.9558	3.0352821	1.6745908	3094.2161
1028.8567	3.0401487	1.677916	3093.5125
1029.7576	3.0454891	1.6811227	3090.0618
1030.6584	3.0492771	1.6843169	3090.0193
1031.5593	3.0519321	1.6872438	3086.335
1032.4602	3.0523937	1.6899453	3081.3879
1033.3611	3.055321	1.6929888	3083.2576
1034.262	3.0548971	1.6960151	3080.8865
1035.1628	3.0605316	1.6988798	3074.4229
1036.0637	3.0618143	1.7017481	3076.4072
1036.9646	3.0637348	1.7044932	3063.9983
1037.8655	3.0701149	1.7070794	3069.3818
1038.7664	3.0663917	1.7095784	3060.8313
1039.6672	3.0732589	1.7124027	3064.8862
1040.5681	3.0740151	1.7151313	3065.3103
1041.469	3.0770895	1.7180434	3058.8755
1042.3699	3.0808182	1.7213384	3054.1836
1043.2708	3.0854986	1.7246536	3062.1335
1044.1716	3.0870278	1.7272875	3050.2544
1045.0725	3.0891035	1.7299415	3044.1082
1045.9734	3.0934618	1.7328809	3050.4048
1046.8743	3.0923059	1.7355886	3039.7058
1047.7751	3.0986168	1.738583	3044.918
1048.676	3.1014521	1.7412471	3037.6396
1049.5769	3.1030726	1.7445763	3035.2466
1050.4778	3.1068912	1.7472656	3033.5439
1051.3787	3.1086586	1.7499834	3030.9817
1052.2795	3.1131277	1.7529817	3028.7649
1053.1804	3.1125667	1.7558993	3023.9846
1054.0813	3.1175611	1.7586722	3017.1299
1054.9822	3.1192148	1.7613204	3018.0916
1055.8831	3.1225994	1.7644811	3017.3286
1056.7839	3.1231151	1.7680669	3012.459
1057.6848	3.1289959	1.771394	3014.8472
1058.5857	3.1306336	1.7751411	3013.5066
1059.4866	3.1337318	1.7779925	2998.7185
1060.3875	3.1353016	1.7810652	2997.7847
1061.2883	3.137768	1.7835827	2993.8923
1062.1892	3.1408107	1.7861964	2987.9812
1063.0901	3.1414113	1.7889762	2992.158
1063.991	3.1464515	1.7922754	2991.5691
1064.8918	3.148689	1.7957463	2985.1909
1065.7927	3.1543851	1.7983215	2985.3796
1066.6936	3.1528828	1.8014433	2980.0623
1067.5945	3.1563206	1.8048866	2977.1235
1068.4954	3.1617093	1.8078251	2976.5454
1069.3962	3.1611943	1.8112409	2963.9033
1070.2971	3.165122	1.8138653	2962.4438
1071.198	3.1681633	1.8167207	2960.4014
1072.0989	3.1716497	1.8196243	2960.0073
1072.9998	3.1762152	1.8223076	2954.0557
1073.9006	3.1785753	1.824893	2955.9338
1074.8015	3.1774013	1.8275406	2943.9656
1075.7024	3.1821408	1.830188	2942.2878
1076.6033	3.1835742	1.8327233	2944.895
1077.5042	3.1897757	1.8362126	2941.5625
1078.405	3.1895008	1.8395021	2935.2087
1079.3059	3.1930249	1.8428031	2938.3088
1080.2068	3.1965151	1.8458645	2925.0598
1081.1077	3.1971009	1.8489263	2927.8872
1082.0085	3.1987939	1.8517615	2919.3945
1082.9094	3.2039561	1.8547682	2917.6526
1083.8103	3.2058036	1.8570545	2909.666
1084.7112	3.2084334	1.8602091	2913.9109
1085.6121	3.2099798	1.8631693	2907.5095
1086.5129	3.2126179	1.8662622	2907.8047
1087.4138	3.2142813	1.8695465	2900.6089
1088.3147	3.2218914	1.8725644	2899.1243
1089.2156	3.2242746	1.875591	2896.126
1090.1165	3.2245955	1.8785338	2886.1719
1091.0173	3.2271509	1.880942	2884.6284
1091.9182	3.2275856	1.8846574	2881.9812
1092.8191	3.2343702	1.8885782	2876.4661
1093.72	3.2377996	1.8920574	2870.6794
1094.6208	3.2388608	1.8951794	2867.4648
1095.5217	3.2391171	1.8981314	2855.0796
1096.4226	3.2474525	1.9012343	2860.0715
1097.3235	3.2433345	1.9042431	2848.0718
1098.2244	3.2509208	1.9070201	2850.6738
1099.1252	3.253547	1.9100378	2842.863
1100.0261	3.2549493	1.9131691	2842.1116
1100.927	3.2602563	1.9166104	2829.4451
1101.8279	3.2598155	1.9200612	2826.2507
1102.7288	3.2627416	1.9238302	2818.531
1103.6296	3.2670658	1.9271272	2807.4722
1104.5305	3.2662687	1.929945	2798.825
1105.4314	3.2701383	1.933388	2799.0203
1106.3323	3.2756133	1.9365849	2787.5271
1107.2332	3.2805147	1.9398227	2780.3157
1108.134	3.2806268	1.9428952	2764.5754
1109.0349	3.281853	1.9458042	2760.2429
1109.9358	3.2844696	1.9488474	2753.1704
1110.8367	3.2866571	1.9522481	2744.4856
1111.7375	3.290777	1.9570552	2730.6785
1112.6384	3.2940233	1.9605782	2714.4878
1113.5393	3.2965434	1.9637065	2703.8147
1114.4402	3.2982607	1.9682357	2692.7859
1115.3411	3.3039925	1.9842517	2555.3936
1116.1418	3.3075373	1.9926447	2496.002