File: datasets/am_bench_2022/raw_data/45-XY.13-2/specimen.dat
MTS793|MPT|ENU|1|2|.|/|:|1|0|0|A

Operator Information						Time:	35.703125	Sec	10/19/2021 3:22:25 PM
Operator	Newell Moser
Project	AM Bench 2022 mini-tensile challenge
Specimen ID	45-XY.13-2
Material	PBF-L Inconel 625
Specimen Width	2.55	mm
Specimen Thickness	1.51	mm
Notes
Operator Information End

Data Acquisition						Time:	1036.6973	Sec	10/19/2021 3:39:06 PM
Time	Axial Displacement	Axial Extensometer	Axial Force
Sec	mm	mm	N
35.817139	-0.0022233326	-7.4537704e-05	60.521103
36.818115	0.00080879766	-2.8613445e-05	74.542191
37.819092	0.003342889	9.4283227e-05	88.30748
38.820068	0.010489384	0.00010828958	101.52129
39.821045	0.013783365	9.5438816e-05	112.35847
40.822021	0.014320794	0.00014003026	125.73342
41.822998	0.017683053	0.0001482177	138.79572
42.823975	0.023545906	0.00022660386	149.12216
43.824951	0.024614412	0.00021697399	162.0582
44.825928	0.02878123	0.00030160934	180.40714
45.826904	0.027646543	0.0003809841	195.26521
46.827881	0.031878974	0.00046947034	215.22141
47.828857	0.035248358	0.00060066918	238.08116
48.829834	0.037814155	0.0005157839	250.89505
49.830811	0.039283019	0.00068667729	280.22412
50.831787	0.043116681	0.00078028277	292.79538
51.832764	0.047120403	0.00081054412	319.39371
52.83374	0.051788386	0.0008818995	338.26401
53.834717	0.051964387	0.0010494655	356.84088
54.835693	0.056233853	0.0010932497	380.41766
55.83667	0.056737475	0.0012048896	398.73907
56.837646	0.064477131	0.001225641	420.99344
57.838623	0.061136842	0.0013095345	442.54205
58.8396	0.06772501	0.0014101842	466.72208
59.840576	0.067213193	0.0015016998	487.94791
60.841553	0.073896475	0.0016782522	516.95178
61.842529	0.074421816	0.0017849503	533.06116
62.843506	0.078878969	0.0017863722	555.50238
63.844482	0.08229465	0.0019113782	583.05444
64.845459	0.084577754	0.0019686904	604.54883
65.846436	0.089234054	0.0021348498	635.32684
66.847412	0.093377508	0.0022941474	658.83417
67.848389	0.097356036	0.0024252632	688.91949
68.849365	0.097243756	0.0024788054	714.24146
69.850342	0.099121578	0.0026073805	741.53522
70.851318	0.10215678	0.0026544235	765.74487
71.852295	0.10533909	0.002782213	791.9278
72.853271	0.10826816	0.0029377467	822.40912
73.854248	0.11163698	0.0029818597	848.33209
74.855225	0.11274831	0.0031770205	878.91418
75.856201	0.11778566	0.0033567653	909.80811
76.857178	0.12011117	0.0034224768	939.93274
77.858154	0.1248107	0.0035924001	973.79608
78.859131	0.12676947	0.0037624768	1003.3784
79.860107	0.13094483	0.0038308327	1031.9886
80.861084	0.13017757	0.0038275297	1044.7625
81.862061	0.13694358	0.0039814338	1081.3042
82.863037	0.13737118	0.0041412967	1105.2018
83.864014	0.14329167	0.0043032272	1140.441
84.86499	0.14573453	0.0044384133	1165.1445
85.865967	0.1455491	0.0045246263	1191.6846
86.866943	0.15016648	0.0045979354	1214.1447
87.86792	0.15156485	0.0047368831	1253.7045
88.868896	0.161137	0.0048568896	1279.5045
89.869873	0.16162279	0.0050187311	1303.3239
90.87085	0.16382681	0.0050692488	1331.3075
91.871826	0.1646267	0.0052628196	1370.2675
92.872803	0.17084572	0.0054166415	1401.1681
93.873779	0.17273045	0.0054744496	1418.0089
94.874756	0.1741862	0.0055279168	1451.8068
95.875732	0.17982844	0.0057160705	1477.6692
96.876709	0.17990999	0.0058719004	1503.2046
97.877686	0.18415506	0.0059381197	1526.3007
98.878662	0.1901761	0.0061623333	1559.4636
99.879639	0.18929343	0.0061833672	1582.5278
100.88062	0.18879718	0.0063979272	1612.5549
101.88159	0.19422004	0.0064920243	1640.0266
102.88257	0.19746177	0.0066325977	1664.0637
103.88354	0.20023736	0.0067271255	1690.4497
104.88452	0.20282018	0.0067584775	1707.4832
105.8855	0.20634286	0.0069335634	1737.5071
106.88647	0.2107494	0.0071272282	1774.0242
107.88745	0.21419275	0.0071631866	1796.0858
108.88843	0.21556363	0.0073595028	1825.5828
109.8894	0.22006938	0.0074170516	1851.74
110.89038	0.22255896	0.0074886642	1877.3259
111.89136	0.22668807	0.0076776166	1901.5409
112.89233	0.22826241	0.0077475202	1925.4498
113.89331	0.23084322	0.007896102	1944.9497
114.89429	0.23354368	0.0079587074	1971.3119
115.89526	0.23632358	0.0080764601	1989.8119
116.89624	0.2384544	0.0081771221	2006.7725
117.89722	0.24445786	0.0082517872	2034.8744
118.89819	0.24909572	0.0084443539	2057.5713
119.89917	0.25021565	0.008535591	2079.7998
120.90015	0.25250506	0.0084954873	2093.1125
121.90112	0.25141448	0.0087297559	2118.1824
122.9021	0.25893366	0.0088106627	2138.5276
123.90308	0.26161918	0.0088791726	2154.8447
124.90405	0.26520631	0.0090573933	2179.7803
125.90503	0.26852939	0.0090470631	2191.177
126.90601	0.26987365	0.0091462331	2210.4636
127.90698	0.27100056	0.0092983432	2226.0918
128.90796	0.2765463	0.0092928149	2242.8357
129.90894	0.27774	0.0093713198	2253.2815
130.90991	0.28344712	0.0094971135	2276.8159
131.91089	0.28644058	0.0096371183	2290.0015
132.91187	0.28995523	0.0096692722	2300.208
133.91284	0.29307178	0.0097939149	2328.218
134.91382	0.2954036	0.0097277155	2329.2859
135.91479	0.2990357	0.0099418443	2355.4551
136.91577	0.30022037	0.010028144	2363.0376
137.91675	0.30152041	0.0101143	2370.7041
138.91772	0.30746397	0.010215059	2390.8743
139.9187	0.30990684	0.010299421	2397.6152
140.91968	0.31226167	0.010321467	2405.2275
141.92065	0.31752566	0.01053303	2426.0742
142.92163	0.32039449	0.01055079	2442.2205
143.92261	0.32137573	0.01056403	2444.7117
144.92358	0.32734659	0.010821673	2465.7458
145.92456	0.33070821	0.010885279	2478.5095
146.92554	0.33040661	0.010887529	2486.5593
147.92651	0.33532372	0.011072703	2499.6697
148.92749	0.33858287	0.011130362	2500.4832
149.92847	0.33954033	0.011231032	2520.3447
150.92944	0.34562179	0.011367653	2533.2314
151.93042	0.34881952	0.011492253	2546.5913
152.9314	0.34915039	0.011542331	2540.636
153.93237	0.35433638	0.011705444	2562.4575
154.93335	0.35483181	0.011733083	2571.7124
155.93433	0.36084014	0.01188364	2574.1184
156.9353	0.36206189	0.011968173	2586.8999
157.93628	0.36582261	0.012115135	2591.3767
158.93726	0.36882856	0.012260733	2608.052
159.93823	0.37018695	0.012258443	2610.7354
160.93921	0.37448797	0.012589928	2625.5945
161.94019	0.37783134	0.012743294	2636.7485
162.94116	0.37682921	0.012814186	2638.6514
163.94214	0.3800298	0.013010305	2641.8035
164.94312	0.38696057	0.013131145	2659.1116
165.94409	0.38839439	0.013326043	2668.7898
166.94507	0.3928546	0.013382481	2670.7573
167.94604	0.39472178	0.013582019	2680.8984
168.94702	0.39580092	0.013807684	2684.6567
169.948	0.40212378	0.013963307	2697.5674
170.94897	0.40548125	0.014246173	2707.2573
171.94995	0.40651226	0.014257397	2711.5959
172.95093	0.4074136	0.014512327	2715.7617
173.9519	0.4141126	0.014821529	2730.322
174.95288	0.41541305	0.014962058	2732.522
175.95386	0.42316028	0.01522078	2739.5286
176.95483	0.4235715	0.015416387	2752.4565
177.95581	0.4244853	0.015783707	2756.6033
178.95679	0.42842039	0.015929883	2761.2073
179.95776	0.4316189	0.016203705	2771.1963
180.95874	0.43552268	0.016644046	2786.3726
181.95972	0.43743652	0.017016182	2789.385
182.96069	0.44037357	0.017321084	2800.2295
183.96167	0.4414759	0.017671891	2803.8926
184.96265	0.44742423	0.018138958	2820.3242
185.96362	0.4492195	0.018564954	2817.043
186.9646	0.454615	0.01884827	2819.5066
187.96558	0.45686197	0.019192114	2823.4272
188.96655	0.45921391	0.01968788	2837.8145
189.96753	0.46221638	0.020069342	2840.2361
190.96851	0.46588838	0.020647705	2848.9998
191.96948	0.46753874	0.021166882	2847.4023
192.97046	0.46739164	0.021613427	2858.0046
193.97144	0.47486785	0.022103181	2863.6433
194.97241	0.47824809	0.022687655	2869.3213
195.97339	0.48193321	0.023334971	2879.6741
196.97437	0.48236287	0.023996631	2879.561
197.97534	0.48590866	0.024571516	2883.6641
198.97632	0.48967147	0.025085783	2883.3821
199.97729	0.49067867	0.025546858	2888.5581
200.97827	0.49182564	0.026187032	2895.7947
201.97925	0.49885926	0.026927911	2908.7217
202.98022	0.5008018	0.027664006	2905.6824
203.9812	0.50471497	0.028159341	2915.1489
204.98218	0.50794768	0.029094649	2915.3025
205.98315	0.50896108	0.029791545	2917.4163
206.98413	0.51245075	0.030609295	2927.6526
207.98511	0.51479059	0.031444367	2928.1123
208.98608	0.51952022	0.032205991	2931.8508
209.98706	0.52431011	0.033116795	2949.1208
210.98804	0.5245617	0.034132749	2944.3982
211.98901	0.52950692	0.03509609	2946.4871
212.98999	0.53273559	0.035910808	2950.6814
213.99097	0.53369212	0.036738031	2952.2095
214.99194	0.53874183	0.037625194	2953.8782
215.99292	0.53936613	0.038369223	2958.6675
216.9939	0.54468977	0.039204583	2964.0659
217.99487	0.54409927	0.040257942	2966.6907
218.99585	0.54951304	0.041305747	2976.208
219.99683	0.55363214	0.042295404	2977.0498
220.9978	0.55360711	0.043380249	2981.3894
221.99878	0.55734205	0.04456801	2988.8245
222.99976	0.55894881	0.045626324	2984.2427
224.00073	0.56634015	0.046531741	2989.6792
225.00171	0.5675531	0.047546986	2988.2861
226.00269	0.56797802	0.048574008	2990.0857
227.00366	0.5742982	0.049627017	3001.6458
228.00464	0.57778746	0.050516248	2997.7017
229.00562	0.58154637	0.051695906	3010.0813
230.00659	0.58063501	0.052959472	3007.457
231.00757	0.5863744	0.054390505	3012.061
232.00854	0.58624631	0.05554992	3012.3389
233.00952	0.58683968	0.056550685	3009.533
234.0105	0.59335202	0.057704423	3018.1741
235.01147	0.59932494	0.058680337	3021.1545
236.01245	0.59921312	0.059596151	3015.8765
237.01343	0.6013763	0.060552996	3023.4573
238.0144	0.60372186	0.061416499	3020.0381
239.01538	0.61058217	0.062662773	3033.188
240.01636	0.61404479	0.063935019	3035.054
241.01733	0.61603546	0.064887434	3029.49
242.01831	0.61963922	0.065988578	3038.7891
243.01929	0.6207397	0.067195334	3043.4451
244.02026	0.62209529	0.068405688	3036.0652
245.02124	0.6259734	0.069626324	3046.052
246.02222	0.62960809	0.070584327	3042.7549
247.02319	0.63149816	0.07155893	3039.9209
248.02417	0.63940161	0.072700836	3047.001
249.02515	0.63928562	0.073963702	3060.7681
250.02612	0.64123368	0.075351052	3059.0862
251.0271	0.64522469	0.076540507	3061.864
252.02808	0.64966655	0.07795798	3064.7029
253.02905	0.65067726	0.079226829	3059.4702
254.03003	0.65371984	0.080572292	3070.2703
255.03101	0.65591747	0.081791349	3064.5488
256.03198	0.65854555	0.082934074	3070.8342
257.03296	0.66469383	0.084080063	3074.7043
258.03394	0.66541648	0.085177533	3072.3738
259.03491	0.6665858	0.086267389	3075.2449
260.03589	0.67218637	0.087409571	3079.6436
261.03687	0.67354792	0.088632658	3074.3701
262.03784	0.67842853	0.089985572	3087.2026
263.03882	0.68070102	0.091373406	3087.5671
264.03979	0.68266976	0.092568837	3082.0574
265.04077	0.6854974	0.093759015	3085.2942
266.04175	0.69208419	0.09485992	3093.2146
267.04272	0.69377369	0.096004352	3090.5654
268.0437	0.69510096	0.097208522	3094.7046
269.04468	0.7019375	0.098259456	3096.3958
270.04565	0.70103967	0.099489912	3099.2419
271.04663	0.70824617	0.10094023	3102.0444
272.04761	0.70657861	0.1022833	3101.8452
273.04858	0.71107042	0.10337438	3101.2537
274.04956	0.71534681	0.10447234	3102.3418
275.05054	0.71682042	0.10567084	3103.3699
276.05151	0.72068995	0.10673562	3103.9705
277.05249	0.72276586	0.10792838	3115.4631
278.05347	0.72450596	0.10915206	3116.0054
279.05444	0.72907603	0.11039199	3108.3525
280.05542	0.73364174	0.11152372	3119.3528
281.0564	0.73760223	0.11264712	3120.8057
282.05737	0.73807168	0.11389701	3116.9058
283.05835	0.7405858	0.11508563	3115.1699
284.05933	0.74546176	0.11624455	3124.8718
285.0603	0.74890816	0.11757712	3125.8372
286.06128	0.74870634	0.11877405	3129.7837
287.06226	0.75549108	0.12007914	3132.9663
288.06323	0.75704002	0.12140568	3136.6121
289.06421	0.75745416	0.12284003	3134.2585
290.06519	0.76045674	0.12415262	3131.1877
291.06616	0.76532835	0.12527123	3134.7764
292.06714	0.76871639	0.12651247	3136.1328
293.06812	0.77113247	0.12762167	3133.1348
294.06909	0.77678597	0.12895837	3144.938
295.07007	0.77704638	0.13022283	3139.3738
296.07104	0.77804625	0.13138203	3143.3235
297.07202	0.78273898	0.13275912	3145.6995
298.073	0.78967285	0.13401908	3151.6472
299.07397	0.78729779	0.13528313	3151.6328
300.07495	0.79378986	0.13648115	3156.2402
301.07593	0.79696053	0.13776226	3154.5608
302.0769	0.79685462	0.13895939	3155.2175
303.07788	0.8032428	0.1401495	3155.0015
304.07886	0.80269778	0.14137894	3158.2371
305.07983	0.80736166	0.14230166	3163.3191
306.08081	0.80986583	0.14347973	3155.9839
307.08179	0.81319076	0.14427729	3153.3118
308.08276	0.81708223	0.14523131	3157.6689
309.08374	0.81894773	0.14647485	3165.043
310.08472	0.82227021	0.14760721	3165.3145
311.08569	0.82432795	0.14868101	3161.4084
312.08667	0.82743627	0.14989428	3169.4084
313.08765	0.82999861	0.15140122	3175.7375
314.08862	0.8353591	0.1527068	3176.8325
315.0896	0.8384214	0.1539056	3174.8784
316.09058	0.83788049	0.15524173	3177.5203
317.09155	0.84333068	0.15632762	3173.8755
318.09253	0.8476522	0.15747343	3179.5298
319.09351	0.84814721	0.15878533	3182.8345
320.09448	0.85293651	0.15993667	3184.1428
321.09546	0.85780776	0.16118738	3183.9011
322.09644	0.86004281	0.16240889	3186.697
323.09741	0.86175901	0.16371056	3190.0337
324.09839	0.86491573	0.16504516	3189.5527
325.09937	0.86734569	0.16621746	3193.6553
326.10034	0.8700633	0.16749443	3194.8218
327.10132	0.87510729	0.16868158	3190.8733
328.10229	0.87646592	0.16977304	3194.9797
329.10327	0.8799234	0.17081869	3195.5723
330.10425	0.88107979	0.171958	3197.7168
331.10522	0.88432401	0.17308658	3197.8064
332.1062	0.8863374	0.17426525	3206.6047
333.10718	0.8930285	0.17550297	3208.3589
334.10815	0.89607847	0.17686823	3206.9846
335.10913	0.89815152	0.17797662	3201.0935
336.11011	0.90249658	0.17933905	3210.9783
337.11108	0.90294534	0.18033496	3206.0637
338.11206	0.90498316	0.18150885	3208.5044
339.11304	0.90843654	0.18282518	3214.8555
340.11401	0.91182989	0.18416636	3217.4905
341.11499	0.91391563	0.18529889	3215.1672
342.11597	0.91882789	0.18652202	3215.9363
343.11694	0.9207319	0.18777731	3219.0789
344.11792	0.92211264	0.18887429	3213.3108
345.1189	0.92675126	0.19016846	3227.1609
346.11987	0.93106997	0.19142318	3228.001
347.12085	0.93523002	0.19271225	3227.9329
348.12183	0.93654126	0.19384637	3223.5908
349.1228	0.93812245	0.19516715	3230.9731
350.12378	0.94433856	0.19633295	3229.603
351.12476	0.94640774	0.19742334	3230.167
352.12573	0.9505018	0.1986564	3230.1233
353.12671	0.95164692	0.19972606	3228.2671
354.12769	0.95325404	0.20078321	3229.6035
355.12866	0.95906329	0.20202047	3238.2195
356.12964	0.96077144	0.2033135	3239.3567
357.13062	0.96410125	0.20473906	3237.291
358.13159	0.96558839	0.20597497	3234.5349
359.13257	0.96904647	0.20720255	3242.0442
360.13354	0.97306418	0.20849374	3241.8499
361.13452	0.97734547	0.20963879	3248.2051
362.1355	0.97967261	0.21074396	3238.4092
363.13647	0.98332125	0.21173999	3245.8479
364.13745	0.98496163	0.21281242	3246.6995
365.13843	0.98908007	0.21399462	3250.1372
366.1394	0.99273056	0.21506986	3253.2588
367.14038	0.99295515	0.21633227	3249.9236
368.14136	0.99662757	0.21754797	3250.6594
369.14233	0.99954683	0.21843663	3252.2932
370.14331	1.0038781	0.21950126	3259.1863
371.14429	1.0060998	0.22068802	3258.1189
372.14526	1.0044388	0.22202104	3257.2632
373.14624	1.0090042	0.22329684	3262.4565
374.14722	1.0139923	0.22435889	3255.4719
375.14819	1.0170949	0.22564223	3261.1528
376.14917	1.0206699	0.2268797	3263.8665
377.15015	1.0241878	0.22824058	3269.2605
378.15112	1.0257394	0.22963421	3271.7405
379.1521	1.0295333	0.23075795	3261.4797
380.15308	1.0317161	0.23174997	3266.4065
381.15405	1.0371552	0.23282909	3274.1797
382.15503	1.0406544	0.23390089	3271.5164
383.15601	1.0386306	0.23488423	3265.5923
384.15698	1.0460953	0.23592639	3274.9358
385.15796	1.0477037	0.23726584	3279.041
386.15894	1.0509208	0.23835322	3274.6792
387.15991	1.0546967	0.23968324	3280.9202
388.16089	1.0579933	0.24075851	3283.1152
389.16187	1.0606674	0.24207598	3288.3557
390.16284	1.0618386	0.2434943	3284.5054
391.16382	1.0646188	0.24469836	3284.9111
392.16479	1.0673894	0.24592899	3284.512
393.16577	1.0728033	0.247153	3286.4583
394.16675	1.074407	0.24810402	3282.4922
395.16772	1.0782851	0.24938984	3292.6008
396.1687	1.079795	0.25073689	3291.0466
397.16968	1.0854343	0.25195238	3294.0188
398.17065	1.0875688	0.2531966	3290.8745
399.17163	1.0904682	0.25434488	3295.7546
400.17261	1.0921993	0.25553638	3295.8523
401.17358	1.0969636	0.25669524	3300.9097
402.17456	1.0976382	0.2578539	3296.3643
403.17554	1.1012282	0.25890282	3296.4185
404.17651	1.1030602	0.26012063	3300.3909
405.17749	1.1101352	0.26124039	3303.8872
406.17847	1.1118746	0.26247838	3303.2129
407.17944	1.1121786	0.26370987	3304.8267
408.18042	1.1148993	0.26481065	3308.8088
409.1814	1.1174763	0.2659266	3308.5867
410.18237	1.1236135	0.26716474	3303.4983
411.18335	1.1234516	0.2682699	3309.99
412.18433	1.1252171	0.26962766	3313.0798
413.1853	1.132616	0.27066231	3312.498
414.18628	1.1350657	0.2719104	3314.1577
415.18726	1.1366855	0.27322629	3319.1672
416.18823	1.1384541	0.27429792	3310.6191
417.18921	1.1434219	0.27553713	3314.8318
418.19019	1.1467253	0.27682564	3319.782
419.19116	1.151853	0.27776411	3313.0667
420.19214	1.149804	0.27901173	3321.3689
421.19312	1.1554996	0.27993149	3313.0337
422.19409	1.160452	0.28099298	3317.7561
423.19507	1.1633688	0.28210765	3323.6135
424.19604	1.1663946	0.28301305	3317.7278
425.19702	1.1689919	0.28408235	3330.0635
426.198	1.1696407	0.28536242	3330.6782
427.19897	1.1752253	0.28657982	3328.5688
428.19995	1.17756	0.28774381	3322.1423
429.20093	1.1790218	0.28897285	3331.3167
430.2019	1.1837982	0.29020438	3335.1387
431.20288	1.1848167	0.29147336	3332.7437
432.20386	1.1881614	0.29281062	3337.4409
433.20483	1.1935225	0.29413202	3333.1638
434.20581	1.1972082	0.29540458	3338.1697
435.20679	1.1987737	0.29660165	3338.3813
436.20776	1.20068	0.29768953	3340.0073
437.20874	1.2028906	0.29875761	3333.9141
438.20972	1.2096685	0.29992929	3350.5127
439.21069	1.2095652	0.30117339	3341.5874
440.21167	1.2150575	0.30249494	3348.7903
441.21265	1.2153962	0.30371967	3346.7092
442.21362	1.2189399	0.30492306	3344.4519
443.2146	1.2215586	0.3060315	3347.5918
444.21558	1.2257084	0.30730766	3354.593
445.21655	1.2277573	0.30844107	3346.4539
446.21753	1.2300653	0.30966341	3348.3215
447.21851	1.2370507	0.31093356	3351.2363
448.21948	1.2378021	0.31207281	3353.082
449.22046	1.2400572	0.31322998	3353.9819
450.22144	1.2442735	0.31433886	3350.8281
451.22241	1.2455227	0.31537494	3347.9104
452.22339	1.2465817	0.31640792	3351.4473
453.22437	1.251335	0.31760082	3358.0251
454.22534	1.2523755	0.31850171	3348.834
455.22632	1.2574502	0.31949705	3355.5288
456.22729	1.2594076	0.32065463	3359.7852
457.22827	1.2631954	0.32173038	3359.2695
458.22925	1.2663046	0.32291001	3360.6543
459.23022	1.2682729	0.32398251	3366.3396
460.2312	1.2729598	0.32520437	3369.8247
461.23218	1.2785385	0.32672209	3373.8123
462.23315	1.2822161	0.32786292	3367.3806
463.23413	1.2807488	0.32926226	3367.9802
464.23511	1.2850262	0.33034983	3368.4443
465.23608	1.2861344	0.33145696	3365.9048
466.23706	1.2907779	0.3325091	3369.9856
467.23804	1.2933477	0.33370072	3378.4065
468.23901	1.296898	0.33508268	3376.0759
469.23999	1.3014705	0.33627307	3375.531
470.24097	1.3047551	0.33743829	3377.3694
471.24194	1.3045624	0.33849499	3372.9265
472.24292	1.3108226	0.33968997	3381.9053
473.2439	1.3144792	0.3409265	3382.6304
474.24487	1.3142009	0.34228978	3382.376
475.24585	1.317534	0.3434824	3383.9331
476.24683	1.320241	0.34479952	3381.6172
477.2478	1.3205788	0.34616235	3381.8752
478.24878	1.3295656	0.34716326	3384.366
479.24976	1.3303286	0.34826225	3389.7803
480.25073	1.3321576	0.34936282	3388.2561
481.25171	1.3360194	0.35027966	3387.8123
482.25269	1.3376471	0.3514387	3390.1338
483.25366	1.3406943	0.35268345	3388.9131
484.25464	1.3433357	0.35398778	3396.5752
485.25562	1.3471445	0.35531527	3395.0127
486.25659	1.3513995	0.35635582	3390.0774
487.25757	1.3555053	0.35731626	3390.52
488.25854	1.3567059	0.3585529	3398.9939
489.25952	1.3593105	0.35998103	3402.7974
490.2605	1.360394	0.36128432	3395.3555
491.26147	1.363633	0.36222258	3399.3047
492.26245	1.3674768	0.3634814	3394.439
493.26343	1.3714588	0.36458746	3402.3948
494.2644	1.3754288	0.36587745	3400.9514
495.26538	1.3761786	0.36716601	3404.124
496.26636	1.3822361	0.36873165	3411.0276
497.26733	1.386874	0.36991927	3400.2256
498.26831	1.3877174	0.37111825	3406.6685
499.26929	1.3888879	0.37228152	3407.1145
500.27026	1.3964942	0.37338158	3407.7292
501.27124	1.3978157	0.3746601	3409.8574
502.27222	1.3993497	0.37576425	3407.2424
503.27319	1.4019455	0.37698105	3409.7266
504.27417	1.4042298	0.37837949	3415.3713
505.27515	1.4084722	0.37974983	3420.176
506.27612	1.4120425	0.38095012	3413.2051
507.2771	1.4151947	0.38208163	3414.4023
508.27808	1.4163601	0.38313603	3412.8369
509.27905	1.421803	0.38425535	3414.3884
510.28003	1.4248444	0.38549876	3420.7039
511.28101	1.428221	0.38673952	3422.054
512.28198	1.4250576	0.38796049	3413.2874
513.28296	1.4319637	0.388991	3421.1829
514.28394	1.4359419	0.39010274	3426.8567
515.28491	1.441548	0.39127746	3429.0786
516.28589	1.4424982	0.39258194	3430.0542
517.28687	1.4466531	0.39409894	3429.1975
518.28784	1.4451804	0.39532569	3419.8049
519.28882	1.4487914	0.39655465	3428.2388
520.28979	1.4537507	0.39764631	3423.4517
521.29077	1.4595636	0.39862916	3424.2957
522.29175	1.4605492	0.39960876	3423.7896
523.29272	1.4632468	0.40070191	3430.262
524.2937	1.4671904	0.40190834	3431.551
525.29468	1.4675764	0.40310577	3433.1531
526.29565	1.4700346	0.40436646	3435.5347
527.29663	1.4762626	0.40556636	3438.9316
528.29761	1.4762514	0.40664911	3430.676
529.29858	1.4800292	0.4076564	3428.8816
530.29956	1.4829183	0.4087607	3438.6453
531.30054	1.4863437	0.40993628	3437.9727
532.30151	1.4882033	0.41127819	3437.6072
533.30249	1.4905674	0.41247013	3436.0635
534.30347	1.4945791	0.41394341	3441.3057
535.30444	1.4980786	0.41535121	3444.5979
536.30542	1.502243	0.41652185	3447.3757
537.3064	1.5054535	0.41786423	3442.7156
538.30737	1.5095066	0.4189584	3443.9907
539.30835	1.5111027	0.4200995	3447.8555
540.30933	1.5147707	0.4215689	3454.6382
541.3103	1.5159827	0.42287543	3448
542.31128	1.5207597	0.42410943	3446.7356
543.31226	1.521852	0.42521659	3450.6436
544.31323	1.5229325	0.42633572	3447.231
545.31421	1.5261689	0.42748776	3445.1143
546.31519	1.53099	0.42862532	3457.854
547.31616	1.5344819	0.43010062	3452.7241
548.31714	1.5379877	0.43121943	3454.5625
549.31812	1.5399631	0.43247589	3452.1406
550.31909	1.542601	0.43365484	3455.3989
551.32007	1.5485116	0.43480393	3456.7993
552.32104	1.5504414	0.43600598	3454.9812
553.32202	1.5526265	0.43716908	3464.1274
554.323	1.5565083	0.43868166	3461.9934
555.32397	1.5589135	0.43996325	3459.6636
556.32495	1.5643361	0.44117618	3463.9302
557.32593	1.5636618	0.44241998	3457.9453
558.3269	1.5663501	0.44338164	3459.177
559.32788	1.5677946	0.44445911	3461.0857
560.32886	1.5744549	0.44570524	3465.3
561.32983	1.5792857	0.4471336	3474.8384
562.33081	1.5790782	0.44856414	3468.219
563.33179	1.5809714	0.44982386	3469.9265
564.33276	1.5840535	0.45118892	3466.395
565.33374	1.5885482	0.45220473	3461.0125
566.33472	1.5912502	0.45334542	3470.0435
567.33569	1.5925099	0.45441079	3466.7646
568.33667	1.5951405	0.45546123	3466.8918
569.33765	1.6000079	0.45678699	3470.4839
570.33862	1.6011013	0.45795551	3467.5618
571.3396	1.6065587	0.45927039	3475.0391
572.34058	1.6091212	0.46044213	3469.7949
573.34155	1.6134644	0.46170989	3474.0388
574.34253	1.6150886	0.46306965	3476.3354
575.34351	1.6191688	0.46440399	3481.0525
576.34448	1.6218485	0.46576583	3477.6643
577.34546	1.6226537	0.46692359	3476.7502
578.34644	1.6264824	0.46827099	3478.4524
579.34741	1.6291747	0.46966484	3482.5408
580.34839	1.6355624	0.47104716	3482.5112
581.34937	1.6328846	0.47224617	3478.123
582.35034	1.6413296	0.47351289	3481.0288
583.35132	1.6412276	0.47478652	3480.5654
584.35229	1.6445506	0.47596651	3483.4658
585.35327	1.6470244	0.47726351	3485
586.35425	1.6521974	0.47831494	3484.0974
587.35522	1.654101	0.47948918	3485.8044
588.3562	1.6571697	0.48068097	3486.3994
589.35718	1.6612941	0.48198497	3492.6611
590.35815	1.6636264	0.48310071	3485.1104
591.35913	1.6647389	0.48449451	3498.0488
592.36011	1.670478	0.48578191	3491.6895
593.36108	1.6753465	0.48690644	3496.114
594.36206	1.6731087	0.48802593	3491.4248
595.36304	1.677745	0.48932695	3493.8167
596.36401	1.6808703	0.49048522	3495.0391
597.36499	1.6824455	0.49172559	3490.5823
598.36597	1.6863308	0.492717	3488.6687
599.36694	1.6914756	0.49393862	3493.8806
600.36792	1.6935682	0.49494722	3492.8586
601.3689	1.6968236	0.49635258	3502.1316
602.36987	1.7014979	0.49762559	3494.04
603.37085	1.701643	0.49880555	3496.4692
604.37183	1.7055178	0.50021732	3503.7791
605.3728	1.7101974	0.50140262	3497.123
606.37378	1.7123166	0.5026989	3497.2185
607.37476	1.7148857	0.5038085	3503.2344
608.37573	1.7153207	0.50511146	3502.3604
609.37671	1.7185702	0.50650477	3502.0579
610.37769	1.7230937	0.50795358	3511.8999
611.37866	1.7288918	0.50947678	3504.1738
612.37964	1.7304741	0.51076239	3508.187
613.38062	1.7343557	0.51194829	3509.8494
614.38159	1.7337046	0.51325363	3506.7375
615.38257	1.7397735	0.5145908	3511.6323
616.38354	1.7425666	0.51589584	3510.7976
617.38452	1.7453694	0.51702249	3506.9236
618.3855	1.7515973	0.51823986	3514.6926
619.38647	1.7517923	0.51965266	3513.5693
620.38745	1.7531126	0.52080113	3513.1252
621.38843	1.7585789	0.5219413	3515.7419
622.3894	1.7583742	0.52316296	3512.0247
623.39038	1.7611654	0.52442491	3509.5828
624.39136	1.7667879	0.52568775	3516.3064
625.39233	1.7673278	0.5272482	3518.1243
626.39331	1.7704904	0.52857369	3507.7307
627.39429	1.7735038	0.52978766	3513.8159
628.39526	1.779417	0.53125453	3524.5059
629.39624	1.7819308	0.53263289	3524.084
630.39722	1.7824014	0.53398716	3519.7957
631.39819	1.7864968	0.53532726	3521.2881
632.39917	1.7903682	0.53657466	3519.6711
633.40015	1.7924451	0.53788412	3517.5647
634.40112	1.7951994	0.53895009	3513.9546
635.4021	1.8015262	0.54012632	3521.0933
636.40308	1.8017431	0.54105556	3519.446
637.40405	1.8061039	0.5424093	3526.6108
638.40503	1.8082818	0.54376727	3523.2595
639.40601	1.8123052	0.54519159	3532.0286
640.40698	1.8134513	0.54638177	3520.9233
641.40796	1.8170227	0.54775727	3527.9709
642.40894	1.8198659	0.54918706	3527.2698
643.40991	1.8203186	0.55054122	3527.7761
644.41089	1.8271557	0.55172926	3525.5715
645.41187	1.8276398	0.55292392	3529.9192
646.41284	1.8309845	0.55411768	3525.5977
647.41382	1.8352395	0.55545384	3537.332
648.41479	1.838599	0.55697453	3533.1069
649.41577	1.8392279	0.55832851	3525.1416
650.41675	1.8435576	0.55948561	3522.5833
651.41772	1.8457043	0.56076628	3531.9409
652.4187	1.8513319	0.56219792	3540.1301
653.41968	1.8527875	0.56369352	3533.1968
654.42065	1.8554193	0.56488615	3531.3496
655.42163	1.8569672	0.56609881	3531.3015
656.42261	1.8583604	0.56735754	3533.449
657.42358	1.8655353	0.56874764	3541.9558
658.42456	1.8672761	0.57023889	3542.6548
659.42554	1.8691666	0.57158846	3541.5696
660.42651	1.8750746	0.57306993	3542.8455
661.42749	1.8763368	0.57444537	3537.5786
662.42847	1.8794498	0.57560998	3533.8323
663.42944	1.8820988	0.57703596	3536.4822
664.43042	1.8867908	0.57826149	3534.2693
665.4314	1.8882922	0.57966036	3546.3042
666.43237	1.8915642	0.58095491	3544.1201
667.43335	1.8954778	0.58254313	3549.0537
668.43433	1.8980473	0.58374	3536.6079
669.4353	1.8991839	0.58527166	3546.272
670.43628	1.9047759	0.58649844	3546.198
671.43726	1.9068846	0.58773345	3543.1821
672.43823	1.9111748	0.58895522	3545.3145
673.43921	1.911028	0.59028512	3548.4204
674.44019	1.9173477	0.59164429	3547.436
675.44116	1.9160383	0.59301841	3546.6018
676.44214	1.9208025	0.59416252	3541.094
677.44312	1.924831	0.59526646	3544.8167
678.44409	1.9271339	0.59663522	3551.3909
679.44507	1.9295937	0.59817553	3554.7388
680.44604	1.9312606	0.5995968	3553.0151
681.44702	1.937663	0.60091603	3555.3171
682.448	1.9389477	0.60258472	3554.1738
683.44897	1.94249	0.60393268	3548.5222
684.44995	1.9490556	0.60528708	3557.2068
685.45093	1.9500046	0.60663462	3555.7532
686.4519	1.9497217	0.6077776	3552.7773
687.45288	1.9552815	0.60909045	3555.1245
688.45386	1.9572616	0.61045945	3554.4565
689.45483	1.9614114	0.61180699	3553.3435
690.45581	1.9648945	0.61315989	3556.636
691.45679	1.9667891	0.61473274	3558.3955
692.45776	1.9699559	0.61618704	3562.2651
693.45874	1.9746605	0.61764544	3560.4778
694.45972	1.9768391	0.61909282	3564.2156
695.46069	1.9791527	0.62049699	3563.5681
696.46167	1.9827793	0.62171656	3560.2527
697.46265	1.9844636	0.62312579	3560.1589
698.46362	1.9880971	0.62441599	3556.334
699.4646	1.9917692	0.6257	3562.563
700.46558	1.9941816	0.62705868	3566.6228
701.46655	1.9976058	0.62833786	3564.4001
702.46753	1.9990129	0.62964499	3567.2622
703.46851	2.0030785	0.63114357	3561.7864
704.46948	2.0043199	0.63260418	3567.6248
705.47046	2.0076709	0.63408881	3564.3135
706.47144	2.0132596	0.63557041	3568.9658
707.47241	2.014678	0.63692075	3562.4829
708.47339	2.0196302	0.63852113	3569.7021
709.47437	2.0199294	0.63985217	3565.4915
710.47534	2.0239952	0.64115816	3566.4722
711.47632	2.0272961	0.64218384	3565.5439
712.47729	2.0287819	0.64353019	3568.8767
713.47827	2.0319068	0.64472729	3568.6597
714.47925	2.0392563	0.64622796	3571.6672
715.48022	2.0382338	0.64759058	3571.6563
716.4812	2.0411234	0.6490981	3564.8914
717.48218	2.0425148	0.65047055	3571.1978
718.48315	2.0497434	0.65196669	3575.2869
719.48413	2.0495207	0.65360534	3576.5107
720.48511	2.0512273	0.6554637	3576.6052
721.48608	2.0566204	0.65711629	3574.9963
722.48706	2.0616484	0.65852934	3569.3086
723.48804	2.0646422	0.65970182	3572.2217
724.48901	2.0645387	0.66066432	3564.8826
725.48999	2.0678527	0.66203487	3577.9905
726.49097	2.0718098	0.66346639	3579.3489
727.49194	2.0740912	0.6649732	3578.8333
728.49292	2.0807741	0.66630197	3581.0122
729.4939	2.0784197	0.66786855	3583.5825
730.49487	2.0826368	0.66953671	3579.7053
731.49585	2.0877678	0.67098993	3577.8433
732.49683	2.0907359	0.67229748	3578.9807
733.4978	2.0925186	0.67378193	3574.4604
734.49878	2.0930514	0.67508781	3572.845
735.49976	2.1017385	0.67644292	3580.5408
736.50073	2.1026552	0.67772526	3576.7283
737.50171	2.1036637	0.6791966	3585.2458
738.50269	2.1086984	0.68043029	3583.8557
739.50366	2.1131237	0.68178123	3584.0391
740.50464	2.1113303	0.68308306	3577.7725
741.50562	2.1183856	0.68445718	3579.2388
742.50659	2.1200874	0.68598497	3588.7334
743.50757	2.1226614	0.68751603	3591.1013
744.50854	2.1272192	0.68925345	3587.0845
745.50952	2.1269133	0.69060373	3579.0117
746.5105	2.132334	0.69212395	3586.825
747.51147	2.1364229	0.69355017	3585.1401
748.51245	2.138422	0.69476664	3585.9548
749.51343	2.1416278	0.69627887	3589.5767
750.5144	2.1413975	0.69761574	3586.625
751.51538	2.1487463	0.69915724	3589.0698
752.51636	2.1527636	0.70076197	3588.252
753.51733	2.1552441	0.7022754	3584.9712
754.51831	2.1574404	0.70389301	3588.6443
755.51929	2.1607974	0.7052387	3585.6138
756.52026	2.1604192	0.70665663	3587.2141
757.52124	2.1648772	0.70810115	3589.595
758.52222	2.168205	0.70956457	3593.3831
759.52319	2.1672494	0.71125448	3588.5857
760.52417	2.172456	0.71294087	3590.6494
761.52515	2.1774948	0.71450323	3589.3147
762.52612	2.1774948	0.71585608	3589.939
763.5271	2.183497	0.71714395	3588.1675
764.52808	2.1883001	0.71867126	3591.5513
765.52905	2.1884091	0.71987468	3589.4553
766.53003	2.1911647	0.72133684	3591.9036
767.53101	2.1974194	0.72263086	3596.1365
768.53198	2.1985838	0.72441691	3598.9043
769.53296	2.2032351	0.72594911	3595.0168
770.53394	2.2021117	0.72748572	3590.3342
771.53491	2.2074161	0.72907513	3594.3804
772.53589	2.2106071	0.73046911	3591.0024
773.53687	2.2123358	0.73180407	3594.1504
774.53784	2.2160594	0.73320895	3598.2903
775.53882	2.2190218	0.73459977	3591.2319
776.53979	2.2235849	0.73598748	3597.8708
777.54077	2.2238917	0.73755938	3599.7017
778.54175	2.2293799	0.73913896	3599.9509
779.54272	2.2309098	0.74051076	3596.5488
780.5437	2.2346351	0.74204248	3601.5442
781.54468	2.2371345	0.74361312	3597.7578
782.54565	2.2384484	0.74528515	3599.9351
783.54663	2.2423418	0.74694353	3604.8743
784.54761	2.2449543	0.74850404	3602.248
785.54858	2.2510254	0.75024784	3602.3884
786.54956	2.2524996	0.7518279	3603.8711
787.55054	2.2542131	0.75346559	3600.0664
788.55151	2.2581637	0.75537461	3606.875
789.55249	2.2642887	0.7569589	3606.4504
790.55347	2.2646687	0.75876462	3601.8098
791.55444	2.2682476	0.76013923	3599.2803
792.55542	2.2680995	0.76163846	3603.144
793.5564	2.272517	0.76332742	3596.0339
794.55737	2.2758079	0.76480252	3602.3225
795.55835	2.2798641	0.76641011	3602.0461
796.55933	2.2811699	0.76801258	3600.019
797.5603	2.2859716	0.76948452	3604.9795
798.56128	2.2886167	0.77117169	3607.2996
799.56226	2.2922289	0.77288556	3603.657
800.56323	2.2940519	0.77447635	3603.5276
801.56421	2.2988095	0.77604347	3602.9885
802.56519	2.2989342	0.77771467	3605.5195
803.56616	2.3062882	0.77927995	3602.8521
804.56714	2.3065012	0.78075659	3603.2014
805.56812	2.3084013	0.78222889	3605.906
806.56909	2.3088658	0.78365481	3604.5171
807.57007	2.3160014	0.78521514	3607.3345
808.57104	2.3201396	0.78668803	3603.6848
809.57202	2.3225191	0.78807443	3605.2927
810.573	2.3266582	0.78981119	3615.9312
811.57397	2.325393	0.79148793	3609.7805
812.57495	2.3254313	0.79291856	3602.1704
813.57593	2.3317094	0.79453599	3606.3113
814.5769	2.3353438	0.79609895	3605.4836
815.57788	2.3372104	0.79762924	3605.5693
816.57886	2.3429801	0.79913169	3607.2788
817.57983	2.3460166	0.80054802	3610.6443
818.58081	2.3479152	0.80203629	3605.8523
819.58179	2.3509192	0.80377162	3608.7021
820.58276	2.3520169	0.80550051	3607.8491
821.58374	2.3564012	0.807235	3609.0002
822.58472	2.3600948	0.80893773	3613.8679
823.58569	2.3624148	0.81050092	3610.4192
824.58667	2.3672311	0.81220776	3614.207
825.58765	2.3695745	0.81386828	3611.498
826.58862	2.3726048	0.81567794	3608.5959
827.5896	2.3762183	0.81752151	3617.8445
828.59058	2.3808293	0.81917071	3610.7136
829.59155	2.3821816	0.82060868	3606.3967
830.59253	2.3837037	0.82229763	3616.6799
831.59351	2.3866522	0.8243016	3622.6255
832.59448	2.3917193	0.82591033	3614.5417
833.59546	2.3912673	0.82743257	3608.2759
834.59644	2.3982732	0.82913327	3614.708
835.59741	2.3991554	0.83100486	3616.9326
836.59839	2.4016187	0.83275962	3609.5535
837.59937	2.4057698	0.83440065	3610.697
838.60034	2.4088495	0.83585793	3607.3811
839.60132	2.4103885	0.83745492	3610.6118
840.60229	2.4101105	0.83920527	3611.155
841.60327	2.4181604	0.84102225	3613.6677
842.60425	2.4202952	0.84282571	3615.5295
843.60522	2.4243188	0.84446603	3614.1228
844.6062	2.4293301	0.84611672	3613.7568
845.60718	2.4295495	0.84789002	3612.2678
846.60815	2.4312301	0.84946531	3611.4922
847.60913	2.4364045	0.85103875	3619.8691
848.61011	2.4354134	0.85285121	3615.9722
849.61108	2.4385018	0.85464185	3607.1309
850.61206	2.4450459	0.85635126	3617.144
851.61304	2.448276	0.85806465	3612.6868
852.61401	2.449228	0.85988986	3615.4539
853.61499	2.4539864	0.86163867	3611.3467
854.61597	2.457454	0.86347276	3611.7815
855.61694	2.4607623	0.86495358	3616.7188
856.61792	2.463805	0.86670935	3617.5088
857.6189	2.4652455	0.86853945	3617.2783
858.61987	2.4679849	0.87029123	3614.3208
859.62085	2.4725342	0.87207299	3621.7358
860.62183	2.4703476	0.87395966	3615.2292
861.6228	2.4753551	0.87570351	3617.7727
862.62378	2.4803913	0.87761492	3617.6028
863.62476	2.4861741	0.87928975	3617.4841
864.62573	2.4848349	0.88106346	3611.7498
865.62671	2.4896266	0.88301384	3616.5508
866.62769	2.4915779	0.88487923	3616.1353
867.62866	2.496103	0.88670146	3618.7795
868.62964	2.497802	0.88837218	3616.4897
869.63062	2.5003719	0.89005458	3618.3218
870.63159	2.5055792	0.89207774	3622.5339
871.63257	2.5074885	0.89386851	3617.4465
872.63354	2.5108318	0.89574194	3616.1821
873.63452	2.5145676	0.89770424	3617.7363
874.6355	2.5155537	0.89968055	3614.481
875.63647	2.5180728	0.90146017	3618.6289
876.63745	2.5207329	0.90304071	3613.282
877.63843	2.5269578	0.90500182	3623.5701
878.6394	2.5282426	0.90655375	3614.5322
879.64038	2.5323646	0.90827924	3614.5591
880.64136	2.5361216	0.90959269	3611.5508
881.64233	2.5368376	0.91093653	3614.0493
882.64331	2.5397866	0.91258991	3622.1145
883.64429	2.5458932	0.9143936	3620.5144
884.64526	2.5454297	0.91609108	3616.2734
885.64624	2.5493345	0.91790879	3618.509
886.64722	2.5496163	0.91977322	3619.7961
887.64819	2.5538208	0.92196697	3615.354
888.64917	2.5578763	0.92369843	3623.7847
889.65015	2.5615108	0.92561275	3619.9028
890.65112	2.5652008	0.92733306	3619.6187
891.6521	2.5661275	0.92934	3622.7771
892.65308	2.5703833	0.93113583	3614.4775
893.65405	2.5742278	0.93291318	3621.0889
894.65503	2.5770566	0.93480301	3625.178
895.65601	2.5807593	0.93696433	3621.6848
896.65698	2.5808802	0.93888694	3616.3145
897.65796	2.5842867	0.94088066	3621.0562
898.65894	2.5904613	0.94304299	3628.2742
899.65991	2.5874989	0.94515193	3616.5398
900.66089	2.5957687	0.94724739	3617.9888
901.66187	2.5984309	0.94909912	3622.748
902.66284	2.5991254	0.95116597	3615.9231
903.66382	2.6047962	0.95315945	3621.7568
904.66479	2.6083913	0.95519853	3617.0938
905.66577	2.6110742	0.95701826	3612.5066
906.66675	2.6128471	0.95901352	3620.5271
907.66772	2.6130476	0.9609673	3611.2559
908.6687	2.6166873	0.9628033	3613.3032
909.66968	2.6188695	0.96436721	3608.7578
910.67065	2.6257377	0.96617872	3615.95
911.67163	2.6300073	0.96833754	3626.5259
912.67261	2.6303139	0.97060955	3616.905
913.67358	2.6360233	0.97232777	3619.3223
914.67456	2.6369047	0.97429639	3613.5408
915.67554	2.6397676	0.97627497	3616.8931
916.67651	2.6418042	0.97800642	3622.0078
917.67749	2.6458275	0.97967726	3615.5388
918.67847	2.6491835	0.98159397	3620.7766
919.67944	2.6491275	0.98357207	3610.3196
920.68042	2.6552732	0.98534787	3613.2524
921.6814	2.6564341	0.98721892	3615.4431
922.68237	2.6618092	0.98909783	3614.3577
923.68335	2.6654856	0.99091941	3619.3789
924.68433	2.6680908	0.99298251	3624.05
925.6853	2.6676407	0.99508572	3617.2651
926.68628	2.6710083	0.99761534	3621.6855
927.68726	2.677428	0.99968892	3621.4644
928.68823	2.6782343	1.001905	3620.2705
929.68921	2.6819763	1.0041568	3620.0574
930.69019	2.6826775	1.0062495	3612.7754
931.69116	2.688056	1.0082251	3616.6738
932.69214	2.6895204	1.0106518	3624.0088
933.69312	2.6935682	1.0128829	3612.8313
934.69409	2.6962061	1.0148479	3613.5725
935.69507	2.7016549	1.016874	3611.2195
936.69604	2.7031841	1.0191008	3618.6587
937.69702	2.7042108	1.0214142	3619.8511
938.698	2.7104018	1.023828	3619.98
939.69897	2.7131519	1.0259342	3610.7373
940.69995	2.7147758	1.0278186	3609.739
941.70093	2.7191105	1.0299315	3612.052
942.7019	2.7220578	1.0319028	3614.6426
943.70288	2.7247803	1.0338566	3610.8081
944.70386	2.7259567	1.0358845	3614.585
945.70483	2.7285397	1.0379671	3609.1963
946.70581	2.7307792	1.0399318	3610.9202
947.70679	2.7354763	1.0419509	3610.4275
948.70776	2.7390001	1.0439565	3605.0747
949.70874	2.740767	1.0457997	3610.8462
950.70972	2.7471924	1.048023	3610.4292
951.71069	2.7467167	1.0504093	3609.9885
952.71167	2.7520533	1.0527809	3613.3174
953.71265	2.7545662	1.0550971	3608.2234
954.71362	2.7577965	1.0575221	3605.6802
955.7146	2.7593906	1.0595139	3608.668
956.71558	2.7601132	1.0614691	3604.2502
957.71655	2.7686827	1.0640311	3613.5332
958.71753	2.7696011	1.0662714	3606.8777
959.71851	2.7690682	1.0685858	3605.366
960.71948	2.7761302	1.0711586	3609.3433
961.72046	2.7776566	1.0731736	3597.2773
962.72144	2.7811186	1.0752763	3597.3755
963.72241	2.7833369	1.0771867	3602.4954
964.72339	2.7886319	1.079151	3602.3879
965.72437	2.7876492	1.0812978	3605.6619
966.72534	2.7922845	1.0836	3607.2751
967.72632	2.7963607	1.0860021	3610.0205
968.72729	2.79896	1.088569	3607.3716
969.72827	2.8028038	1.0911435	3607.4636
970.72925	2.8041549	1.0933619	3596.4246
971.73022	2.8072996	1.0954449	3596.4241
972.7312	2.8092968	1.0978169	3596.979
973.73218	2.8134949	1.1002078	3598.9756
974.73315	2.8142707	1.1023183	3596.4592
975.73413	2.8201387	1.1047463	3605.2031
976.73511	2.8226194	1.1070422	3596.915
977.73608	2.8264735	1.1094222	3599.2395
978.73706	2.8290422	1.1115749	3593.2478
979.73804	2.8314426	1.1139128	3600.3386
980.73901	2.836535	1.116387	3597.0386
981.73999	2.8378255	1.1190858	3604.4526
982.74097	2.8427219	1.1215904	3596.4194
983.74194	2.8416674	1.1238341	3589.0244
984.74292	2.8477337	1.1258236	3591.6746
985.7439	2.8482859	1.1281997	3590.5203
986.74487	2.8533778	1.1301548	3584.4543
987.74585	2.8546102	1.1319153	3587.4678
988.74683	2.8600359	1.13381	3595.3303
989.7478	2.8640828	1.1364155	3596.8176
990.74878	2.8630154	1.1390225	3594.3569
991.74976	2.8688755	1.1414973	3588.5952
992.75073	2.8690069	1.1440158	3587.5688
993.75171	2.874054	1.1465085	3586.5134
994.75269	2.8769715	1.1490673	3585.2891
995.75366	2.8794048	1.1515434	3583.5596
996.75464	2.8843961	1.1542177	3585.9207
997.75562	2.886791	1.1566671	3581.2937
998.75659	2.888942	1.1590918	3584.7798
999.75757	2.8924067	1.1615269	3580.6885
1000.7585	2.8949513	1.1639339	3581.8027
1001.7595	2.8990679	1.1663595	3582.0901
1002.7605	2.9000545	1.1688081	3580.0813
1003.7615	2.9030793	1.1716375	3580.4141
1004.7625	2.9068139	1.1748444	3578.9475
1005.7634	2.908746	1.1777866	3573.303
1006.7644	2.91377	1.1801034	3562.9165
1007.7654	2.9141774	1.1823512	3571.8438
1008.7664	2.9210086	1.1847556	3574.5259
1009.7673	2.9191644	1.187149	3571.9182
1010.7683	2.9241168	1.1896049	3570.8313
1011.7693	2.9263844	1.1925666	3569.9714
1012.7703	2.9300747	1.1950718	3567.6348
1013.7712	2.9328723	1.1974365	3566.1011
1014.7722	2.9396002	1.1998805	3570.4673
1015.7732	2.9409702	1.2020108	3558.8787
1016.7742	2.9431286	1.2039087	3559.8503
1017.7751	2.9472528	1.2062893	3568.124
1018.7761	2.9486685	1.2088841	3558.7886
1019.7771	2.9543827	1.2115413	3557.7393
1020.7781	2.9532709	1.2142431	3557.3896
1021.7791	2.9560399	1.2168921	3558.1785
1022.78	2.9617043	1.2194451	3551.7407
1023.781	2.9616742	1.2216668	3550.5476
1024.782	2.9676194	1.2238325	3548.9351
1025.783	2.9710481	1.2258017	3545.9141
1026.7839	2.9728987	1.2282306	3554.6458
1027.7849	2.9803345	1.2307914	3554.9578
1028.7859	2.9805112	1.2337373	3551.7161
1029.7869	2.9810758	1.2363091	3544.4246
1030.7878	2.9856422	1.2387856	3542.344
1031.7888	2.9863462	1.2416214	3546.6831
1032.7898	2.9896472	1.2442143	3542.8765
1033.7908	2.9902408	1.2463466	3533.7822
1034.7917	2.9980373	1.2484511	3536.5569
1035.7927	2.9980197	1.2504767	3527.9885
1036.7937	3.0018604	1.252591	3534.1184
1037.7947	3.0061486	1.254932	3534.7598
1038.7957	3.005425	1.2576543	3538.678
1039.7966	3.0104537	1.2609468	3539.1724
1040.7976	3.0167842	1.2638897	3527.231
1041.7986	3.0183036	1.2662117	3524.1855
1042.7996	3.0205512	1.2688915	3530.3342
1043.8005	3.0225818	1.2714865	3527.0991
1044.8015	3.0282514	1.273582	3522.9045
1045.8025	3.0309303	1.2757454	3522.6863
1046.8035	3.0308332	1.2784086	3523.978
1047.8044	3.037564	1.2811021	3518.1853
1048.8054	3.0410264	1.2840086	3520.877
1049.8064	3.044445	1.2873769	3519.7371
1050.8074	3.0446317	1.2905504	3512.7554
1051.8083	3.0486946	1.2933234	3510.4783
1052.8093	3.0547698	1.2960008	3512.9497
1053.8103	3.0511665	1.298543	3505.8184
1054.8113	3.0561769	1.3009686	3501.502
1055.8123	3.0613017	1.3033137	3499.0332
1056.8132	3.0628822	1.305827	3499.7285
1057.8142	3.0672011	1.3085265	3502.3899
1058.8152	3.0700891	1.3111992	3499.1799
1059.8162	3.0705233	1.3140072	3496.1399
1060.8171	3.0755947	1.3169715	3493.7588
1061.8181	3.0765164	1.3197926	3490.542
1062.8191	3.0813789	1.3228422	3491.25
1063.8201	3.0831504	1.3255129	3483.884
1064.821	3.0894563	1.3281194	3486.5867
1065.822	3.0908265	1.330798	3482.9817
1066.823	3.0928307	1.3335644	3480.8049
1067.824	3.0938151	1.3367977	3486.6816
1068.825	3.1009893	1.3401752	3474.1619
1069.8259	3.1027913	1.3429915	3471.187
1070.8269	3.1083457	1.3456002	3467.4155
1071.8279	3.1090996	1.3480731	3468.8704
1072.8289	3.1123767	1.3510405	3471.7529
1073.8298	3.1135926	1.3540474	3464.2617
1074.8308	3.1202667	1.3571268	3467.1633
1075.8318	3.1181436	1.3602308	3459.0071
1076.8328	3.1224287	1.3633323	3451.6995
1077.8337	3.1269321	1.3663393	3452.5498
1078.8347	3.1303511	1.3695667	3454.5142
1079.8357	3.1343009	1.3729545	3446.4194
1080.8367	3.1363657	1.3754796	3444.6863
1081.8376	3.1395869	1.3782363	3445.3235
1082.8386	3.1435502	1.3811294	3440.0671
1083.8396	3.1452823	1.3839028	3434.5549
1084.8406	3.1484153	1.3866595	3437.4636
1085.8416	3.1509106	1.3893793	3434.123
1086.8425	3.1528809	1.3921144	3426.7632
1087.8435	3.1581416	1.3952022	3428.3738
1088.8445	3.1611791	1.3982862	3422.2651
1089.8455	3.1639769	1.4011072	3419.7651
1090.8464	3.1645546	1.404079	3417.7449
1091.8474	3.170171	1.4076986	3419.5313
1092.8484	3.1706486	1.4109218	3410.7385
1093.8494	3.1752386	1.4137021	3407.1694
1094.8503	3.1780279	1.4165587	3404.9587
1095.8513	3.1823843	1.4194417	3400.3208
1096.8523	3.1827133	1.4225011	3401.3367
1097.8533	3.1859808	1.4254903	3394.9507
1098.8542	3.1864536	1.4285179	3391.1331
1099.8552	3.1920838	1.4318777	3391.5659
1100.8562	3.1954231	1.4348652	3385.2737
1101.8572	3.1988423	1.4375633	3377.7615
1102.8582	3.2018073	1.4404843	3378.4309
1103.8591	3.2043915	1.4432288	3372.1157
1104.8601	3.2068012	1.4462581	3371.864
1105.8611	3.2081764	1.4492905	3364.561
1106.8621	3.2147782	1.4525599	3364.3767
1107.863	3.2156343	1.4560617	3362.2261
1108.864	3.2191727	1.4595139	3357.3884
1109.865	3.2195718	1.4625806	3345.187
1110.866	3.2257636	1.4654927	3346.7444
1111.8669	3.2305951	1.4683932	3343.3745
1112.8679	3.2324343	1.4717011	3344.9165
1113.8689	3.2354202	1.4752346	3336.6501
1114.8699	3.2394466	1.4787904	3336.3398
1115.8708	3.243355	1.4817617	3320.8015
1116.8718	3.2444897	1.4840908	3318.3516
1117.8728	3.2465663	1.4870713	3322.1772
1118.8738	3.2494819	1.4905509	3315.1643
1119.8748	3.2544458	1.4940079	3312.6248
1120.8757	3.2538238	1.4974	3304.9192
1121.8767	3.2586389	1.5007095	3298.7813
1122.8777	3.2607102	1.5042958	3292.5823
1123.8787	3.2649789	1.5086693	3296.5723
1124.8796	3.2682731	1.5117223	3280.467
1125.8806	3.272032	1.5147737	3279.5442
1126.8816	3.2740102	1.5180166	3273.4998
1127.8826	3.2769344	1.5214571	3270.7373
1128.8835	3.2785337	1.5244393	3263.834
1129.8845	3.280092	1.5272999	3255.2881
1130.8855	3.2863269	1.5307941	3252.9839
1131.8865	3.2897909	1.5338095	3248.6978
1132.8875	3.29143	1.5369194	3239.4412
1133.8884	3.2941046	1.5400616	3236.364
1134.8894	3.3006995	1.544032	3235.9722
1135.8904	3.2985196	1.5483552	3223.4402
1136.8914	3.3055944	1.5521955	3211.5801
1137.8923	3.3064294	1.5554727	3211.7842
1138.8933	3.3092129	1.5586257	3201.8442
1139.8943	3.3125625	1.5618905	3195.572
1140.8953	3.3144071	1.5658284	3191.0688
1141.8962	3.319649	1.5701174	3179.6519
1142.8972	3.3216035	1.5748008	3159.8223
1143.8982	3.3242424	1.5787181	3149.4976
1144.8992	3.3285165	1.5829911	3134.0137
1145.4998	3.3318212	1.592973	3050.012