File: datasets/am_bench_2022/raw_data/90-XY.07-1/specimen.dat
MTS793|MPT|ENU|1|2|.|/|:|1|0|0|A

Operator Information						Time:	45.110107	Sec	10/15/2021 1:48:13 PM
Operator	Nick Derimow
Project	AM Bench 2022 mini-tensile challenge
Specimen ID	90-XY.07-1
Material	PBF-L Inconel 625
Specimen Width	2.56	mm
Specimen Thickness	1.5	mm
Notes
Operator Information End

Data Acquisition						Time:	998.36768	Sec	10/15/2021 2:04:06 PM
Time	Axial Displacement	Axial Extensometer	Axial Force
Sec	mm	mm	N
45.223633	0.0005194199	-0.00010337219	42.948341
46.024414	-0.00012906002	0.00030313147	54.567184
46.825195	0.0038256941	0.0001081347	62.247608
47.625977	0.0042823963	-5.7026882e-05	73.300377
48.426758	0.0068447627	0.00010863873	83.351814
49.227539	0.0099606933	0.00041385251	95.638802
50.02832	0.010084652	0.00035899604	106.19939
50.829102	0.015035177	0.00038978705	123.51678
51.629883	0.015059764	0.00029707901	129.30089
52.430664	0.022640627	0.00054393266	142.41933
53.231445	0.021974577	0.00040758695	152.87816
54.032227	0.020977987	0.00055164477	161.17476
54.833008	0.025373872	0.00040384562	180.54881
55.633789	0.027504481	0.00067842106	189.17395
56.43457	0.030176619	0.0010241377	204.94678
57.235352	0.031756327	0.00087306951	216.30455
58.036133	0.035955362	0.00066280121	236.13962
58.836914	0.04065628	0.001146895	252.47997
59.637695	0.039538395	0.00082675699	267.1207
60.438477	0.042258527	0.00072485756	285.3837
61.239258	0.042864747	0.0011613317	303.4613
62.040039	0.047572322	0.0012184666	317.79239
62.84082	0.048768681	0.00062508485	338.14532
63.641602	0.053164311	0.0012561828	351.3898
64.442383	0.055722374	0.0014689682	368.00894
65.243164	0.057156149	0.0012132295	384.73297
66.043945	0.058711272	0.0012699341	397.80533
66.844727	0.062545396	0.0013816447	414.89816
67.645508	0.064256802	0.0014815188	433.87552
68.446289	0.065114886	0.0015180223	456.83041
69.24707	0.066094674	0.0015204358	468.26389
70.047852	0.071662277	0.0016433776	495.56256
70.848633	0.075817876	0.0017559836	513.51392
71.649414	0.079223931	0.0018371767	532.57855
72.450195	0.078537747	0.0017434238	544.51855
73.250977	0.077893369	0.0018895715	564.99878
74.051758	0.083091758	0.0018879365	588.13916
74.852539	0.081720069	0.0020762037	610.51099
75.65332	0.088370569	0.0020708528	629.12701
76.454102	0.088781379	0.002169261	652.19989
77.254883	0.089146085	0.00218966	661.98926
78.055664	0.094593823	0.0023295861	689.87415
78.856445	0.099103019	0.0025072983	712.0979
79.657227	0.099674866	0.002557561	735.87469
80.458008	0.099983022	0.0026015677	753.07202
81.258789	0.10538431	0.0027268368	777.17706
82.05957	0.10798084	0.0028046453	805.24994
82.860352	0.11081402	0.0028858988	822.72015
83.661133	0.11175221	0.0030263425	844.80676
84.461914	0.11256973	0.0031379864	864.47784
85.262695	0.11741596	0.0032525319	893.49884
86.063477	0.1187328	0.0033511561	912.99188
86.864258	0.12407953	0.0033990226	939.01819
87.665039	0.12416887	0.0034277269	948.68878
88.46582	0.12540251	0.003534172	970.78589
89.266602	0.13063866	0.0036611857	997.48053
90.067383	0.13210587	0.0038479296	1023.0939
90.868164	0.13450572	0.0038562769	1048.1472
91.668945	0.1374647	0.0039979937	1070.5266
92.469727	0.13587828	0.00402113	1087.4049
93.270508	0.14186576	0.0041739889	1111.3918
94.071289	0.14402218	0.0042371354	1134.0665
94.87207	0.14501938	0.0043971175	1157.3665
95.672852	0.14732088	0.0044740695	1178.817
96.473633	0.14985968	0.0045325318	1209.8784
97.274414	0.15216814	0.0047912486	1231.3003
98.075195	0.15277483	0.0048626736	1252.1578
98.875977	0.16017953	0.0049711452	1277.0746
99.676758	0.15972427	0.0050316276	1297.8359
100.47754	0.16324505	0.0051216814	1319.5607
101.27832	0.16486979	0.0052201878	1340.2097
102.0791	0.16513839	0.0052431715	1356.5502
102.87988	0.16876189	0.0053711166	1375.608
103.68066	0.17237243	0.0054021575	1388.7593
104.48145	0.17236751	0.005535183	1418.452
105.28223	0.17663433	0.0056303702	1444.2783
106.08301	0.17790541	0.0057072649	1461.7382
106.88379	0.18059564	0.0058147823	1485.2598
107.68457	0.18249579	0.0060010348	1509.1179
108.48535	0.18422686	0.0060662297	1529.5381
109.28613	0.18850043	0.0061216312	1554.8031
110.08691	0.18886165	0.0062088696	1574.4424
110.8877	0.19371219	0.0063641998	1592.8424
111.68848	0.1929922	0.0064261784	1616.9803
112.48926	0.20106931	0.0066343988	1641.5704
113.29004	0.19855228	0.0066136802	1662.8618
114.09082	0.20275003	0.0068158726	1684.9696
114.8916	0.20172742	0.0068381974	1703.7067
115.69238	0.20732069	0.0069806604	1724.1593
116.49316	0.20526789	0.0071284627	1752.443
117.29395	0.21453561	0.0071875313	1775.0496
118.09473	0.21637225	0.0073601468	1790.7158
118.89551	0.21649233	0.0074579068	1815.3046
119.69629	0.22043191	0.0075740716	1840.4382
120.49707	0.22191307	0.0076787975	1856.6118
121.29785	0.22456288	0.007801895	1881.0898
122.09863	0.22754112	0.0079066958	1903.1707
122.89941	0.22825229	0.008019953	1922.9117
123.7002	0.23099615	0.0081637409	1955.8689
124.50098	0.23309444	0.008169773	1966.416
125.30176	0.23681463	0.0082622869	1985.067
126.10254	0.23985784	0.0084557673	2016.2241
126.90332	0.24013197	0.0084745148	2026.8665
127.7041	0.24324033	0.0085890936	2042.3608
128.50488	0.24384823	0.0087111872	2062.4885
129.30566	0.24926059	0.0088408971	2079.7417
130.10645	0.25029814	0.0087987138	2090.3599
130.90723	0.25169587	0.0089534838	2112.0706
131.70801	0.25602168	0.0091514392	2131.5063
132.50879	0.26000512	0.0091956621	2147.4993
133.30957	0.26182845	0.0092552518	2163.5559
134.11035	0.26093063	0.0092269201	2180.9739
134.91113	0.2652089	0.0094984425	2202.0618
135.71191	0.26970497	0.00953783	2219.5608
136.5127	0.26953387	0.0095853275	2234.5725
137.31348	0.27346671	0.0097210091	2245.7561
138.11426	0.27564654	0.0097878845	2264.3423
138.91504	0.27797079	0.0097895693	2274.1995
139.71582	0.27760509	0.0099564092	2281.7769
140.5166	0.28051329	0.0099969124	2296.1323
141.31738	0.28669024	0.010136222	2316.2761
142.11816	0.2870039	0.010196674	2323.6943
142.91895	0.28902844	0.010313247	2341.0254
143.71973	0.29301637	0.010416285	2353.469
144.52051	0.29553199	0.010532647	2368.2849
145.32129	0.29871491	0.010644392	2380.1514
146.12207	0.29705739	0.010609774	2388.6514
146.92285	0.3005532	0.010818646	2401.5674
147.72363	0.30630198	0.010831575	2417.604
148.52441	0.30885753	0.010978824	2430.1401
149.3252	0.30849078	0.011038964	2437.4807
150.12598	0.31231174	0.01112836	2452.1841
150.92676	0.3103393	0.011186139	2452.7749
151.72754	0.31538817	0.011324615	2470.4568
152.52832	0.31867704	0.011331479	2472.2378
153.3291	0.321435	0.011398117	2485.2214
154.12988	0.32476854	0.011547111	2497.2839
154.93066	0.32502159	0.011690389	2507.3103
155.73145	0.32840946	0.011801726	2517.5244
156.53223	0.3296589	0.011804009	2533.7852
157.33301	0.33019528	0.011859116	2532.7693
158.13379	0.33469012	0.012055202	2546.9729
158.93457	0.34033272	0.012159478	2558.6919
159.73535	0.34317169	0.012249785	2573.2483
160.53613	0.34299508	0.012369215	2574.7935
161.33691	0.34319669	0.012479052	2583.3516
162.1377	0.34762412	0.012507579	2592.1919
162.93848	0.35259345	0.012754622	2608.8252
163.73926	0.35169622	0.012709538	2606.7859
164.54004	0.35641712	0.012892992	2620.9768
165.34082	0.35847029	0.013078436	2631.3022
166.1416	0.36031041	0.013198166	2641.8679
166.94238	0.36032128	0.013247536	2639.9834
167.74316	0.36386052	0.013364788	2649.0503
168.54395	0.36599872	0.013462456	2657.2351
169.34473	0.37057063	0.013631893	2663.9888
170.14551	0.37018543	0.013724152	2669.2029
170.94629	0.3742457	0.013858726	2687.0134
171.74707	0.37860242	0.014037516	2695.605
172.54785	0.37958547	0.0141785	2696.2957
173.34863	0.38071033	0.01434332	2709.9377
174.14941	0.38557953	0.014537863	2713.9653
174.9502	0.38660601	0.014686833	2715.2766
175.75098	0.3875266	0.014816278	2726.4441
176.55176	0.3925035	0.014959196	2726.2839
177.35254	0.39349189	0.015133228	2739.0933
178.15332	0.39233857	0.015325893	2742.7383
178.9541	0.399506	0.015420724	2746.4541
179.75488	0.40481529	0.015635107	2758.272
180.55566	0.40162191	0.015846286	2765.3433
181.35645	0.40435225	0.016097188	2772.1179
182.15723	0.41059726	0.016398173	2787.1431
182.95801	0.41329378	0.016497336	2786.7737
183.75879	0.41589749	0.016796133	2791.3926
184.55957	0.41390148	0.017015088	2797.8367
185.36035	0.41540268	0.01727079	2803.207
186.16113	0.41634211	0.017475411	2808.4678
186.96191	0.42101932	0.017626148	2813.6216
187.7627	0.42505851	0.018031862	2825.6257
188.56348	0.42559999	0.018388031	2832.8906
189.36426	0.43123978	0.018670268	2837.4641
190.16504	0.43412316	0.01902627	2846.4761
190.96582	0.43423235	0.019462524	2853.6763
191.7666	0.43776795	0.019761035	2853.9797
192.56738	0.4405233	0.020164186	2858.6482
193.36816	0.44152296	0.020448551	2869.1575
194.16895	0.44470567	0.020843776	2874.8762
194.96973	0.44667402	0.021176958	2869.6833
195.77051	0.44887865	0.021595104	2882.8477
196.57129	0.45097837	0.022023289	2889.2761
197.37207	0.4533278	0.022457751	2890.3057
198.17285	0.45518658	0.022873228	2900.4641
198.97363	0.45817444	0.023295941	2898.3108
199.77441	0.4614338	0.023885524	2914.4712
200.5752	0.46254736	0.024331387	2908.9209
201.37598	0.46468276	0.02491088	2916.967
202.17676	0.4658682	0.025316881	2913.5725
202.97754	0.47193557	0.025827672	2924.0862
203.77832	0.47374737	0.026274566	2928.8254
204.5791	0.47771183	0.026764764	2930.425
205.37988	0.47718689	0.027236024	2938.0979
206.18066	0.48027188	0.027732743	2933.2612
206.98145	0.48161247	0.02827337	2944.293
207.78223	0.48649329	0.028891556	2950.1045
208.58301	0.48575062	0.029334292	2949.2988
209.38379	0.48995963	0.030077927	2958.196
210.18457	0.49474746	0.030402705	2959.532
210.98535	0.4962548	0.031073416	2963.8945
211.78613	0.49599603	0.031588454	2965.7698
212.58691	0.49821848	0.03226199	2977.4592
213.3877	0.50081974	0.032918729	2973.877
214.18848	0.50612694	0.033573464	2976.6506
214.98926	0.50533777	0.034183647	2985.821
215.79004	0.51055133	0.034971327	2993.6309
216.59082	0.51030958	0.035672974	2988.8447
217.3916	0.51559079	0.036512565	2997.6001
218.19238	0.51498777	0.037147019	2992.9861
218.99316	0.51946276	0.037796654	2998.5435
219.79395	0.51893848	0.03867285	3000.5579
220.59473	0.52395123	0.039325137	3007.2551
221.39551	0.5286721	0.040097386	3014.4392
222.19629	0.53009403	0.041007787	3018.793
222.99707	0.53170937	0.0418262	3016.3171
223.79785	0.53406602	0.042417943	3016.676
224.59863	0.53771627	0.043035779	3018.272
225.39941	0.53957546	0.043668561	3022.9165
226.2002	0.5405972	0.04450047	3026.4585
227.00098	0.54098076	0.04528749	3022.1433
227.80176	0.54325157	0.04607413	3031.3003
228.60254	0.54953879	0.046811394	3034.2957
229.40332	0.54844755	0.047648542	3034.5535
230.2041	0.55466551	0.048373569	3046.9819
231.00488	0.55195403	0.049216188	3041.2249
231.80566	0.55931383	0.050037641	3050.5334
232.60645	0.55889237	0.050783925	3043.5789
233.40723	0.56056345	0.051579349	3055.3804
234.20801	0.56320298	0.052530009	3057.9951
235.00879	0.56760257	0.053284861	3055.916
235.80957	0.56728643	0.054012064	3059.8328
236.61035	0.57099247	0.054990478	3066.9937
237.41113	0.57650971	0.055921204	3071.8657
238.21191	0.58184826	0.05662341	3063.6179
239.0127	0.5789063	0.057169087	3059.03
239.81348	0.58095717	0.057895634	3067.0383
240.61426	0.58156222	0.058765978	3068.7739
241.41504	0.58697271	0.059550755	3076.7532
242.21582	0.59030443	0.06032778	3078.9019
243.0166	0.5893718	0.061234884	3078.6575
243.81738	0.59158969	0.062014222	3082.2563
244.61816	0.59873033	0.062880568	3088.3003
245.41895	0.59868318	0.06359794	3086.1868
246.21973	0.60359675	0.064427823	3091.5847
247.02051	0.60387319	0.065224744	3093.9468
247.82129	0.60178822	0.065677427	3081.9226
248.62207	0.60834467	0.06656789	3097.5022
249.42285	0.61022168	0.067247033	3092.217
250.22363	0.6120339	0.068138584	3098.7791
251.02441	0.6147747	0.069092132	3105.4788
251.8252	0.61837476	0.07005693	3106.7898
252.62598	0.62021631	0.070853621	3111.6909
253.42676	0.6214686	0.071681924	3110.1431
254.22754	0.62581062	0.072392225	3109.1306
255.02832	0.62903762	0.073372252	3118.2056
255.8291	0.63097668	0.074353077	3118.8762
256.62988	0.63119566	0.075367279	3122.3665
257.43066	0.63775152	0.07637094	3131.061
258.23145	0.63982278	0.077279978	3125.366
259.03223	0.63952261	0.078176133	3127.7703
259.83301	0.64061606	0.079073943	3127.3271
260.63379	0.64651382	0.080032527	3130.1863
261.43457	0.64613432	0.080760129	3127.9397
262.23535	0.64766133	0.081603713	3131.8596
263.03613	0.64944738	0.082478784	3134.521
263.83691	0.6545366	0.083329014	3138.4473
264.6377	0.65946072	0.084280513	3143.1885
265.43848	0.66022003	0.085122265	3144.0076
266.23926	0.66008091	0.085965313	3144.3367
267.04004	0.666462	0.086879373	3151.6841
267.84082	0.66539162	0.08762762	3143.9692
268.6416	0.66524106	0.088418618	3150.0896
269.44238	0.66921175	0.089602418	3153.4268
270.24316	0.67100388	0.090282008	3146.5432
271.04395	0.67340481	0.09109699	3150.4939
271.84473	0.67988753	0.091918014	3159.3782
272.64551	0.6789403	0.092863396	3162.1458
273.44629	0.6847347	0.093918666	3167.325
274.24707	0.68720937	0.094785213	3163.5386
275.04785	0.686993	0.095825136	3166.7134
275.84863	0.68728048	0.096724182	3159.2239
276.64941	0.68904191	0.097659044	3168.1633
277.4502	0.69326919	0.098507732	3171.8882
278.25098	0.69589299	0.099619277	3167.8745
279.05176	0.6997031	0.10035075	3175.804
279.85254	0.70305568	0.10119968	3175.7837
280.65332	0.70373529	0.10201763	3169.4268
281.4541	0.70465606	0.10278879	3175.7922
282.25488	0.70866531	0.1035158	3178.5459
283.05566	0.71220845	0.1045247	3182.6848
283.85645	0.71335626	0.10537765	3182.4856
284.65723	0.71748334	0.10620122	3185.2578
285.45801	0.71664017	0.10709256	3185.4126
286.25879	0.72083223	0.10795618	3192.1626
287.05957	0.72280979	0.10880601	3194.031
287.86035	0.7276988	0.10962687	3194.8513
288.66113	0.72626424	0.11054024	3192.2766
289.46191	0.72905725	0.11145734	3195.1006
290.2627	0.73289096	0.11246949	3203.9922
291.06348	0.73245454	0.11353438	3195.5034
291.86426	0.73751897	0.11442871	3202.1128
292.66504	0.73975223	0.11533377	3208.4592
293.46582	0.74341542	0.11629099	3216.333
294.2666	0.74790847	0.11714617	3205.5801
295.06738	0.74836123	0.1181538	3210.1519
295.86816	0.75103855	0.11901972	3210.6023
296.66895	0.7506001	0.11989649	3212.8467
297.46973	0.75781542	0.12080959	3222.8748
298.27051	0.75773185	0.12181896	3222.76
299.07129	0.75719255	0.12275244	3218.0442
299.87207	0.76059639	0.12364952	3223.0989
300.67285	0.76380414	0.12453729	3221.2883
301.47363	0.76664841	0.12550884	3218.572
302.27441	0.77166426	0.12629616	3225.719
303.0752	0.7724365	0.12714253	3222.9929
303.87598	0.77379942	0.1280701	3232.2612
304.67676	0.7769168	0.12910551	3227.9014
305.47754	0.78009051	0.12991044	3227.522
306.27832	0.78030276	0.13073568	3233.3162
307.0791	0.78321463	0.13164312	3230.9387
307.87988	0.7860868	0.13254783	3235.6865
308.68066	0.78789043	0.13350144	3237.8691
309.48145	0.79377174	0.13440047	3245.2537
310.28223	0.79207176	0.13559482	3238.1997
311.08301	0.79534405	0.13668482	3246.5972
311.88379	0.79838461	0.13758342	3248.0857
312.68457	0.80110985	0.13853553	3247.3906
313.48535	0.80628204	0.13946429	3251.4048
314.28613	0.8051613	0.14031342	3244.8875
315.08691	0.80850691	0.14115404	3245.509
315.8877	0.81021816	0.14206576	3245.7791
316.68848	0.8153252	0.1428881	3254.4924
317.48926	0.81812811	0.14345275	3246.75
318.29004	0.81592226	0.14406027	3243.5767
319.09082	0.8184467	0.14465891	3248.9775
319.8916	0.822133	0.14552478	3255.7947
320.69238	0.82624048	0.146281	3254.3794
321.49316	0.82713419	0.14721882	3261.4736
322.29395	0.82996553	0.14807631	3266.7715
323.09473	0.82836676	0.14904384	3264.0032
323.89551	0.83529729	0.14999996	3265.4492
324.69629	0.83669525	0.15101241	3269.1628
325.49707	0.83797175	0.15216665	3272.5449
326.29785	0.8426131	0.15310974	3274.843
327.09863	0.84585178	0.15418714	3275.1252
327.89941	0.84368485	0.15530266	3276.2881
328.7002	0.84804469	0.15610874	3275.3801
329.50098	0.85095453	0.15709676	3273.1606
330.30176	0.85332775	0.15802369	3276.5767
331.10254	0.85410452	0.15899542	3280.4324
331.90332	0.85708094	0.15988566	3279.646
332.7041	0.86251062	0.16088749	3281.8401
333.50488	0.86320788	0.161688	3274.3792
334.30566	0.86362112	0.16252346	3281.624
335.10645	0.86906278	0.16330168	3285.8789
335.90723	0.87127888	0.1644116	3291.8823
336.70801	0.87377852	0.16549172	3293.1223
337.50879	0.87459189	0.16645516	3293.9404
338.30957	0.87513977	0.16720298	3288.9431
339.11035	0.87989485	0.16816615	3296.1191
339.91113	0.88295835	0.16907783	3297.5317
340.71191	0.88372093	0.17000675	3288.9993
341.5127	0.88703829	0.17078696	3297.0945
342.31348	0.88730687	0.17174041	3299.5984
343.11426	0.8904689	0.17277938	3300.1042
343.91504	0.8916868	0.17369862	3300.0334
344.71582	0.89790457	0.17466514	3300.6685
345.5166	0.8987987	0.17545559	3301.8975
346.31738	0.90194517	0.17638615	3307.1038
347.11816	0.90353036	0.17720403	3307.0557
347.91895	0.90282822	0.17814021	3307.3367
348.71973	0.90605623	0.17919093	3310.4343
349.52051	0.90955162	0.18014905	3310.3357
350.32129	0.91557765	0.18114583	3315.5085
351.12207	0.91348469	0.18202773	3309.071
351.92285	0.91878003	0.18292134	3309.6428
352.72363	0.92036116	0.1837443	3314.9675
353.52441	0.91958135	0.18477452	3312.9839
354.3252	0.92654836	0.18568161	3324.3589
355.12598	0.9256469	0.18646139	3308.894
355.92676	0.93115467	0.18729773	3322.5676
356.72754	0.93272251	0.18822572	3328.5962
357.52832	0.93554324	0.18914762	3321.5818
358.3291	0.93649673	0.19004364	3321.9373
359.12988	0.93926048	0.19086745	3329.7429
359.93066	0.94250673	0.19168456	3326.5276
360.73145	0.94539404	0.19251703	3330.0186
361.53223	0.94632691	0.19337055	3331.2549
362.33301	0.95248258	0.19445392	3333.5427
363.13379	0.95395201	0.19536395	3336.2437
363.93457	0.95812112	0.19626777	3335.7493
364.73535	0.958125	0.19700119	3338.4141
365.53613	0.95765495	0.19791333	3333.5742
366.33691	0.96104652	0.19887555	3338.4001
367.1377	0.96477997	0.19964585	3342.1685
367.93848	0.96381497	0.2004173	3337.9731
368.73926	0.96933931	0.20140439	3335.6448
369.54004	0.96921581	0.20215945	3340.9419
370.34082	0.97345948	0.20314917	3345.7715
371.1416	0.97659367	0.20416367	3353.3684
371.94238	0.97852802	0.20536467	3350.9233
372.74316	0.98266721	0.2062692	3347.2471
373.54395	0.98270446	0.20721687	3348.8276
374.34473	0.98978579	0.2080728	3357.3621
375.14551	0.98737675	0.20904063	3352.1904
375.94629	0.9912262	0.21007007	3357.0581
376.74707	0.99359673	0.21105927	3356.5337
377.54785	0.99281412	0.21189857	3353.7461
378.34863	0.99842328	0.2128094	3361.1255
379.14941	1.0001745	0.21338727	3357.239
379.9502	1.000079	0.21432614	3357.4832
380.75098	1.0023761	0.21541066	3361.7722
381.55176	1.0061148	0.21637124	3361.5093
382.35254	1.0095146	0.21730158	3361.8809
383.15332	1.0119466	0.21811888	3368.5364
383.9541	1.0125198	0.2190225	3365.1384
384.75488	1.0162069	0.22019373	3373.0269
385.55566	1.0192797	0.22123393	3370.8552
386.35645	1.0231205	0.22223696	3373.7319
387.15723	1.0227635	0.22301088	3373.9341
387.95801	1.028248	0.22377083	3370.7615
388.75879	1.0294156	0.22457451	3375.6729
389.55957	1.0303679	0.22548425	3369.6514
390.36035	1.0299103	0.22644199	3373.8823
391.16113	1.0355512	0.22754291	3379.542
391.96191	1.0410748	0.22865489	3383.1899
392.7627	1.0408707	0.22949693	3379.9951
393.56348	1.0422066	0.23048088	3380.769
394.36426	1.0440075	0.2310542	3376.8398
395.16504	1.0491724	0.23188169	3379.8926
395.96582	1.0504131	0.23265572	3383.9917
396.7666	1.0533929	0.23366271	3388.2922
397.56738	1.0557121	0.23475266	3391.522
398.36816	1.0572944	0.23575737	3385.5444
399.16895	1.0621169	0.23675165	3394.4072
399.96973	1.0607785	0.23785852	3393.2334
400.77051	1.0651785	0.2386557	3390.1321
401.57129	1.0658153	0.23939718	3386.3105
402.37207	1.0721457	0.24025908	3398.3977
403.17285	1.0702517	0.24116179	3395.8589
403.97363	1.0731556	0.2421433	3396.9075
404.77441	1.0782118	0.24311154	3396.9546
405.5752	1.0794626	0.24393527	3396.0176
406.37598	1.0796193	0.24497397	3399.6226
407.17676	1.0840243	0.24616659	3403.0627
407.97754	1.0867883	0.24737927	3410.5796
408.77832	1.0892836	0.24832666	3401.5747
409.5791	1.089277	0.24910906	3398.1719
410.37988	1.0928783	0.25002122	3398.3596
411.18066	1.0979913	0.25094643	3407.6243
411.98145	1.0974748	0.25167349	3403.658
412.78223	1.099021	0.25260997	3406.0591
413.58301	1.104211	0.2536093	3419.9863
414.38379	1.1070625	0.25460672	3414.3687
415.18457	1.1084249	0.25554368	3411.5259
415.98535	1.1104418	0.25648677	3415.7458
416.78613	1.1143854	0.25742391	3410.9868
417.58691	1.112342	0.25832909	3414.8118
418.3877	1.1193521	0.25914949	3413.1741
419.18848	1.1211261	0.25996089	3416.8032
419.98926	1.1198393	0.2608242	3417.0015
420.79004	1.1216811	0.26176372	3420.3352
421.59082	1.1273365	0.2627058	3427.8638
422.3916	1.1294929	0.26361543	3420.793
423.19238	1.1308385	0.26465032	3429.5461
423.99316	1.1326612	0.26555684	3421.9502
424.79395	1.1373649	0.26660851	3421.5081
425.59473	1.1383151	0.26736179	3424.7959
426.39551	1.1381639	0.26836127	3427.4121
427.19629	1.1444464	0.26925266	3427.1094
427.99707	1.1442847	0.27006701	3424.7034
428.79785	1.150449	0.27088252	3431.2109
429.59863	1.1480461	0.27181661	3434.1157
430.39941	1.1541866	0.27282906	3437.4509
431.2002	1.1587366	0.27397755	3437.2061
432.00098	1.1587249	0.27497694	3438.8479
432.80176	1.1604849	0.2758368	3432.2451
433.60254	1.1622994	0.27664417	3436.4133
434.40332	1.166576	0.27736625	3430.3884
435.2041	1.167665	0.27821305	3436.9504
436.00488	1.1717701	0.27899334	3437.3132
436.80566	1.1735344	0.27991217	3448.8213
437.60645	1.1761324	0.28095451	3448.1262
438.40723	1.177574	0.28178254	3445.2893
439.20801	1.1810038	0.28280243	3451.1455
440.00879	1.1811007	0.28366548	3445.3494
440.80957	1.1839764	0.28450948	3445.3999
441.61035	1.1869692	0.28554729	3451.2104
442.41113	1.1891898	0.28643116	3447.0254
443.21191	1.1916224	0.28746328	3453.0549
444.0127	1.1906499	0.28846785	3452.5818
444.81348	1.1972804	0.2893475	3452.6362
445.61426	1.1997305	0.29039538	3452.2942
446.41504	1.2025639	0.29148412	3463.0168
447.21582	1.2065203	0.29249597	3466.011
448.0166	1.2074448	0.29356781	3463.6418
448.81738	1.2094233	0.29450953	3461.0039
449.61816	1.2136329	0.2953845	3462.1941
450.41895	1.2148592	0.29643923	3463.3638
451.21973	1.2175552	0.29752821	3472.605
452.02051	1.2209766	0.2985447	3472.4011
452.82129	1.2206213	0.29958358	3463.5706
453.62207	1.2225649	0.30036032	3461.76
454.42285	1.2240684	0.30096242	3453.1204
455.22363	1.2274839	0.30178657	3462.4602
456.02441	1.2311535	0.30285412	3469.605
456.8252	1.2338926	0.30382881	3467.1016
457.62598	1.2338244	0.30463225	3472.0359
458.42676	1.2401755	0.30549687	3466.9773
459.22754	1.2419814	0.30628482	3476.7056
460.02832	1.2433075	0.3072049	3469.1836
460.8291	1.2463897	0.30807856	3481.0869
461.62988	1.2477951	0.30897275	3472.7378
462.43066	1.2488855	0.30975184	3468.624
463.23145	1.2551017	0.3105973	3479.1311
464.03223	1.2567463	0.31155387	3480.6211
464.83301	1.2572856	0.31244105	3474.2854
465.63379	1.2601731	0.3133055	3478.1299
466.43457	1.2616285	0.31422329	3480.4512
467.23535	1.2650034	0.31519389	3485.7996
468.03613	1.2654527	0.31622812	3484.4363
468.83691	1.2680115	0.31724095	3486.4683
469.6377	1.2737442	0.31828082	3487.1843
470.43848	1.2728488	0.31924054	3488.0867
471.23926	1.2738694	0.32019663	3483.5864
472.04004	1.2775912	0.32116866	3484.802
472.84082	1.2801273	0.32210588	3487.6536
473.6416	1.2829092	0.32318237	3492.2952
474.44238	1.285826	0.32410282	3488.7173
475.24316	1.2875276	0.32501784	3487.2061
476.04395	1.2897332	0.32603973	3492.0085
476.84473	1.2937533	0.32698146	3495.6768
477.64551	1.29407	0.32797512	3493.0322
478.44629	1.2989613	0.32883129	3495.3018
479.24707	1.3008547	0.32980394	3500.0562
480.04785	1.3060555	0.33092946	3501.6328
480.84863	1.3052667	0.33175081	3496.2036
481.64941	1.3088632	0.33289489	3511.5217
482.4502	1.3082948	0.33389759	3496.5361
483.25098	1.3131634	0.33477676	3499.4802
484.05176	1.3139383	0.33552971	3495.0598
484.85254	1.3195055	0.33634606	3499.6594
485.65332	1.3204275	0.33709759	3507.1672
486.4541	1.3237361	0.33812088	3505.0798
487.25488	1.3235611	0.33899	3504.2566
488.05566	1.3274506	0.33998418	3505.293
488.85645	1.3321189	0.34087977	3511.3652
489.65723	1.331793	0.34175891	3510.8093
490.45801	1.3353149	0.34267798	3507.2783
491.25879	1.3369197	0.34343815	3513.0251
492.05957	1.336993	0.34445614	3513.5791
492.86035	1.3398212	0.34547994	3513.491
493.66113	1.3450627	0.34659278	3519.978
494.46191	1.3463588	0.3476809	3519.2393
495.2627	1.3495814	0.34872508	3520.5571
496.06348	1.3511434	0.34962967	3518.4705
496.86426	1.354218	0.35073188	3520.1196
497.66504	1.3593408	0.35162544	3517.2559
498.46582	1.3582178	0.3523578	3508.282
499.2666	1.3592426	0.35314414	3515.437
500.06738	1.3642567	0.35425481	3526.938
500.86816	1.3642471	0.35509565	3516.9607
501.66895	1.3678855	0.35613573	3522.2634
502.46973	1.371326	0.35704336	3520.5273
503.27051	1.3710296	0.3579267	3524.2908
504.07129	1.3737913	0.3586852	3519.3091
504.87207	1.3783461	0.35970014	3527.8765
505.67285	1.3789462	0.36068061	3524.6909
506.47363	1.3826669	0.36194953	3534.2769
507.27441	1.3829302	0.3629916	3535.3237
508.0752	1.3895139	0.36397457	3527.2625
508.87598	1.3880867	0.36483145	3523.1794
509.67676	1.3873253	0.36556357	3525.2078
510.47754	1.393104	0.36636865	3528.2639
511.27832	1.3973144	0.36728081	3530.355
512.0791	1.4000204	0.36824846	3540.656
512.87988	1.4011929	0.36909291	3532.021
513.68066	1.4039141	0.37004188	3533.7363
514.48145	1.4066842	0.37108433	3541.571
515.28223	1.408872	0.37220216	3541.9023
516.08301	1.4121102	0.37321323	3540.7727
516.88379	1.4120847	0.37406915	3538.7297
517.68457	1.4184108	0.37521267	3545.0679
518.48535	1.4169346	0.37628585	3539.8608
519.28613	1.4200245	0.37717566	3541.4211
520.08691	1.4236706	0.3780098	3541.7263
520.8877	1.4233584	0.37885329	3539.9133
521.68848	1.4282616	0.37978002	3541.8586
522.48926	1.4282537	0.38073114	3547.3506
523.29004	1.432794	0.38183656	3552.4634
524.09082	1.4313757	0.38305444	3549.397
524.8916	1.4389691	0.38400692	3548.2893
525.69238	1.4375861	0.3851099	3553.8982
526.49316	1.4430224	0.38625288	3549.9866
527.29395	1.4457738	0.38720873	3547.4133
528.09473	1.4441042	0.38801441	3549.5413
528.89551	1.4519625	0.38912997	3554.5923
529.69629	1.4500122	0.39014938	3552.9602
530.49707	1.4514017	0.39099076	3544.4873
531.29785	1.4554741	0.39185074	3548.5305
532.09863	1.4588935	0.39281747	3556.5764
532.89941	1.4610852	0.39359629	3553.1602
533.7002	1.4640968	0.39470613	3555.7588
534.50098	1.4645435	0.39553583	3554.6882
535.30176	1.4680651	0.39629552	3550.1636
536.10254	1.471027	0.39732742	3564.908
536.90332	1.4718229	0.3983734	3557.2361
537.7041	1.4741831	0.39939412	3559.447
538.50488	1.4769278	0.40033865	3557.0657
539.30566	1.4803027	0.40120351	3552.2952
540.10645	1.4814308	0.4022935	3564.2229
540.90723	1.4838406	0.40315014	3559.7813
541.70801	1.4869813	0.40401092	3557.4016
542.50879	1.4902025	0.40498954	3565.8911
543.30957	1.494217	0.40592733	3566.3958
544.11035	1.4911913	0.40677261	3564.7131
544.91113	1.4961716	0.40783024	3566.731
545.71191	1.4991109	0.40889421	3563.5325
546.5127	1.5058153	0.40992442	3576.6528
547.31348	1.5021471	0.41099289	3568.1421
548.11426	1.5055046	0.41186896	3568.989
548.91504	1.5083991	0.41276199	3568.5549
549.71582	1.5082878	0.41379088	3574.9321
550.5166	1.5141323	0.41508856	3580.6091
551.31738	1.5156713	0.41600594	3572.3838
552.11816	1.5192239	0.41700977	3571.7234
552.91895	1.5186611	0.417824	3570.3435
553.71973	1.5228144	0.41870621	3570.4233
554.52051	1.5264885	0.41973388	3578.0095
555.32129	1.5287708	0.42075565	3588.3823
556.12207	1.5308303	0.42197132	3586.2048
556.92285	1.5335521	0.42299309	3579.9358
557.72363	1.5372976	0.42405236	3581.9626
558.52441	1.5374134	0.42508009	3576.2947
559.3252	1.5403972	0.42623612	3587.9636
560.12598	1.543478	0.42732587	3589.1829
560.92676	1.5469966	0.42826131	3582.2898
561.72754	1.5474504	0.42898595	3575.9143
562.52832	1.549377	0.43013376	3587.0059
563.3291	1.5530907	0.43112814	3586.894
564.12988	1.5567213	0.43200719	3583.6086
564.93066	1.5594807	0.43291315	3586.2009
565.73145	1.5618362	0.43381572	3595.0808
566.53223	1.5640868	0.43481955	3589.2283
567.33301	1.5627861	0.43578109	3586.2197
568.13379	1.5664899	0.43686426	3589.2043
568.93457	1.5691003	0.43781403	3593.1567
569.73535	1.5713831	0.43879491	3587.866
570.53613	1.5727841	0.4396576	3590.084
571.33691	1.5759424	0.44054967	3593.3662
572.1377	1.579576	0.44149423	3587.9221
572.93848	1.5816097	0.44244862	3590.7854
573.73926	1.582073	0.44350359	3600.2532
574.54004	1.5852504	0.44459856	3598.9585
575.34082	1.5893235	0.44567835	3601.3999
576.1416	1.5903994	0.44672334	3602.2671
576.94238	1.5929493	0.44776395	3600.3789
577.74316	1.596267	0.44884497	3598.8748
578.54395	1.5965459	0.44987077	3597.0645
579.34473	1.6003562	0.4508405	3597.0386
580.14551	1.6022321	0.45192879	3598.3291
580.94629	1.6047429	0.45283321	3601.2471
581.74707	1.6061226	0.45381203	3604.2214
582.54785	1.6091522	0.45480809	3605.262
583.34863	1.6096989	0.45593053	3606.7905
584.14941	1.6136038	0.45720181	3604.6833
584.9502	1.6163983	0.45839244	3605.064
585.75098	1.6202054	0.45927933	3601.1177
586.55176	1.6226882	0.4602322	3604.8721
587.35254	1.6228739	0.46118146	3604.887
588.15332	1.6282111	0.46222997	3603.1448
588.9541	1.62941	0.46319476	3604.4111
589.75488	1.6308309	0.46410197	3609.3784
590.55566	1.6335655	0.46510583	3607.0159
591.35645	1.6341056	0.46605301	3604.8525
592.15723	1.6361183	0.46708477	3606.5779
592.95801	1.639895	0.46804976	3614.0337
593.75879	1.6434108	0.46919417	3613.7476
594.55957	1.6447377	0.46997845	3601.3652
595.36035	1.6500136	0.47086972	3614.1799
596.16113	1.6511562	0.47169188	3611.1826
596.96191	1.6514243	0.47262779	3614.7783
597.7627	1.6560724	0.47356489	3617.8152
598.56348	1.6610221	0.47455785	3619.8613
599.36426	1.6592401	0.47566989	3616.009
600.16504	1.6620692	0.47670096	3622.4985
600.96582	1.6664324	0.47782084	3624.5671
601.7666	1.6673971	0.47886959	3615.3643
602.56738	1.6680636	0.47990468	3614.2668
603.36816	1.6699246	0.48093963	3621.4216
604.16895	1.6722031	0.48191586	3611.6567
604.96973	1.6791064	0.48281822	3616.1772
605.77051	1.6803863	0.48369661	3618.0078
606.57129	1.6844161	0.4846203	3616.7483
607.37207	1.6856837	0.48570502	3624.4785
608.17285	1.6860341	0.48669535	3621.7161
608.97363	1.6875464	0.48774794	3623.0215
609.77441	1.690944	0.4887546	3628.4368
610.5752	1.6941532	0.48969224	3618.2407
611.37598	1.6995618	0.49084219	3631.022
612.17676	1.6961006	0.49187589	3620.5505
612.97754	1.7012438	0.49285978	3627.4478
613.77832	1.7035679	0.49392849	3629.8784
614.5791	1.7038356	0.49494755	3623.6387
615.37988	1.7095542	0.4959884	3631.5664
616.18066	1.7109177	0.49705249	3628.4563
616.98145	1.7136725	0.49798259	3630.6794
617.78223	1.71635	0.49917269	3634.8577
618.58301	1.7196356	0.50020969	3635.5986
619.38379	1.7211556	0.50116086	3630.4707
620.18457	1.7216372	0.50224066	3627.9812
620.98535	1.7277182	0.50324821	3633.188
621.78613	1.7268219	0.5041095	3630.4185
622.58691	1.7305881	0.50516993	3633.4438
623.3877	1.7345995	0.50622129	3635.1628
624.18848	1.7337726	0.50714016	3636.9048
624.98926	1.7347172	0.50819373	3637.9597
625.79004	1.7413493	0.50945926	3636.5337
626.59082	1.7409846	0.51064491	3642.7957
627.3916	1.7485396	0.51193893	3643.4612
628.19238	1.7457623	0.51299441	3639.209
628.99316	1.749915	0.51391083	3631.406
629.79395	1.754734	0.51486546	3640.0095
630.59473	1.7536047	0.51590437	3638.9902
631.39551	1.7558458	0.5171032	3642.301
632.19629	1.7601492	0.51805598	3636.6094
632.99707	1.7606915	0.51910228	3639.5337
633.79785	1.7652563	0.52014774	3639.6548
634.59863	1.7644384	0.5210973	3643.9858
635.39941	1.770524	0.52218938	3646.177
636.2002	1.7731565	0.52329296	3648.3965
637.00098	1.7723759	0.52421665	3646.3538
637.80176	1.7767375	0.52535421	3646.5217
638.60254	1.7804728	0.52633339	3653.2058
639.40332	1.7802453	0.52739155	3643.5483
640.2041	1.7843546	0.52847147	3648.5081
641.00488	1.787164	0.52972227	3650.0801
641.80566	1.789987	0.53060085	3644.7581
642.60645	1.7896327	0.53166789	3643.0872
643.40723	1.7889408	0.53261977	3647.7676
644.20801	1.7962965	0.53379226	3650.9417
645.00879	1.7973986	0.53489161	3655.4077
645.80957	1.8007698	0.53600466	3650.2339
646.61035	1.801851	0.5372234	3653.7524
647.41113	1.8063338	0.5382092	3649.3252
648.21191	1.810243	0.53929907	3655.9639
649.0127	1.8113955	0.54043514	3658.5425
649.81348	1.8109559	0.54150176	3650.3884
650.61426	1.8168817	0.5425275	3651.8992
651.41504	1.8158386	0.543441	3650.5325
652.21582	1.8201455	0.54442209	3649.894
653.0166	1.8214692	0.54536474	3653.4341
653.81738	1.8233653	0.54644716	3654.7739
654.61816	1.8238422	0.54757661	3650.7083
655.41895	1.8302182	0.54875642	3662.4434
656.21973	1.8313966	0.54962194	3656.293
657.02051	1.8355817	0.55083245	3659.8833
657.82129	1.8371881	0.55203432	3662.2537
658.62207	1.8369571	0.55319083	3657.6155
659.42285	1.8411753	0.55433673	3657.729
660.22363	1.8447608	0.55538553	3664.9805
661.02441	1.8476951	0.55665094	3661.1143
661.8252	1.8464246	0.55776983	3657.1501
662.62598	1.8511525	0.55874783	3658.4946
663.42676	1.8534434	0.55968863	3659.6946
664.22754	1.8537569	0.56091189	3667.0452
665.02832	1.8567588	0.56206423	3657.9517
665.8291	1.8632674	0.56300157	3661.1038
666.62988	1.8625015	0.56426382	3662.7402
667.43066	1.8677915	0.56527948	3663.5388
668.23145	1.8645884	0.5662027	3655.812
669.03223	1.8664764	0.56710267	3661.7441
669.83301	1.8724533	0.5682444	3666.8418
670.63379	1.8724279	0.56943291	3661.2046
671.43457	1.8779619	0.5705806	3664.24
672.23535	1.8814484	0.57163936	3666.4143
673.03613	1.883154	0.57255739	3666.4539
673.83691	1.8858459	0.57366961	3671.697
674.6377	1.88833	0.57476932	3671.7007
675.43848	1.8872036	0.57589632	3671.8145
676.23926	1.8917248	0.57706326	3666.3142
677.04004	1.8955745	0.57822442	3673.2112
677.84082	1.8920008	0.57950538	3673.5354
678.6416	1.8993496	0.58062249	3662.2007
679.44238	1.9001576	0.58163053	3671.1521
680.24316	1.9013294	0.58277172	3665.8499
681.04395	1.9073319	0.58375788	3667.5471
681.84473	1.9097625	0.58512825	3679.0444
682.64551	1.9107568	0.58627057	3673.6619
683.44629	1.9097185	0.58752847	3674.2551
684.24707	1.9135295	0.58871061	3671.5413
685.04785	1.9176911	0.58984667	3666.9197
685.84863	1.9200298	0.59076405	3666.4614
686.64941	1.9209733	0.59170723	3666.5325
687.4502	1.9237463	0.59279287	3671.0012
688.25098	1.927331	0.59374803	3673.1633
689.05176	1.9303399	0.59488493	3673.8494
689.85254	1.9346955	0.59598821	3684.3491
690.65332	1.9314392	0.59701365	3669.5471
691.4541	1.9373624	0.59824449	3677.856
692.25488	1.9381796	0.59938711	3678.7769
693.05566	1.9413853	0.60081303	3685.1899
693.85645	1.9443756	0.60207039	3674.6306
694.65723	1.9469746	0.60329258	3682.7454
695.45801	1.9503376	0.6045242	3677.3086
696.25879	1.9530213	0.6056723	3682.2805
697.05957	1.954465	0.60670799	3678.0317
697.86035	1.9553665	0.60783297	3682.4146
698.66113	1.9568666	0.60923052	3681.0322
699.46191	1.9592264	0.61024582	3676.4321
700.2627	1.9632913	0.61138332	3675.0088
701.06348	1.9674808	0.61267334	3683.8638
701.86426	1.9689008	0.61360282	3679.7573
702.66504	1.9709812	0.61480635	3681.301
703.46582	1.9752073	0.61598271	3687.0283
704.2666	1.9752511	0.61703062	3678.5557
705.06738	1.975906	0.61791676	3681.73
705.86816	1.9800445	0.61882776	3678.5603
706.66895	1.9829048	0.61972827	3681.2463
707.46973	1.9863402	0.62078017	3688.8845
708.27051	1.9886267	0.62186551	3682.6094
709.07129	1.9896419	0.62295109	3682.9568
709.87207	1.991926	0.62408793	3683.7151
710.67285	1.9946631	0.62524033	3685.2822
711.47363	1.9941753	0.6263895	3686.5847
712.27441	1.9986914	0.62774611	3687.2432
713.0752	2.0017865	0.62885177	3684.2314
713.87598	2.0042992	0.63004816	3684.8303
714.67676	2.0066254	0.63103485	3683.1189
715.47754	2.008065	0.63212425	3687.6409
716.27832	2.0103359	0.6333099	3686.2346
717.0791	2.0137539	0.63452822	3692.0767
717.87988	2.0152423	0.6356979	3693.2122
718.68066	2.0212584	0.63677126	3686.0696
719.48145	2.0213225	0.63783878	3683.3625
720.28223	2.0227249	0.63906986	3688.4668
721.08301	2.026032	0.64011848	3689.9326
721.88379	2.0270853	0.64116639	3683.3813
722.68457	2.0306664	0.64223254	3690.0676
723.48535	2.0320039	0.64323449	3688.2087
724.28613	2.0355132	0.6443994	3686.2683
725.08691	2.0389192	0.64556992	3693.0974
725.8877	2.0397608	0.64667863	3689.95
726.68848	2.0437696	0.64810574	3698.7983
727.48926	2.0441101	0.64923489	3686.178
728.29004	2.0478134	0.65053266	3694.3044
729.09082	2.0502677	0.65166968	3693.5837
729.8916	2.0542226	0.65287578	3693.679
730.69238	2.0540526	0.65423387	3693.0017
731.49316	2.0544314	0.65543491	3691.334
732.29395	2.0564022	0.65690786	3696.3865
733.09473	2.0627909	0.65825838	3696.5305
733.89551	2.066725	0.65948153	3694.7708
734.69629	2.0676966	0.66049433	3692.178
735.49707	2.0679224	0.6617865	3697.1184
736.29785	2.0714831	0.66298389	3695.0203
737.09863	2.070287	0.6641199	3688.8586
737.89941	2.079397	0.66537017	3700.9075
738.7002	2.0768664	0.66634589	3687.6938
739.50098	2.0816257	0.66743058	3693.7837
740.30176	2.0827098	0.66857916	3698.8232
741.10254	2.0849066	0.66991746	3702.8257
741.90332	2.0864897	0.67115474	3697.7297
742.7041	2.0888693	0.67224896	3689.5737
743.50488	2.0935965	0.67361391	3700.0908
744.30566	2.0954368	0.67481059	3697.7324
745.10645	2.1000433	0.67602009	3698.4019
745.90723	2.0993454	0.6770795	3692.7883
746.70801	2.1042585	0.67828995	3697.0815
747.50879	2.105304	0.67935389	3693.5591
748.30957	2.1093299	0.68040544	3692.8721
749.11035	2.1088912	0.68135929	3690.5911
749.91113	2.1131694	0.68228573	3694.7998
750.71191	2.1150527	0.68326467	3694.0081
751.5127	2.1190624	0.68453908	3702.696
752.31348	2.1183615	0.68575734	3695.2629
753.11426	2.1210701	0.68675715	3693.4785
753.91504	2.1232626	0.68775773	3695.3923
754.71582	2.1245556	0.68915254	3705.7759
755.5166	2.1314356	0.69052058	3705.9761
756.31738	2.131263	0.69169855	3696.6389
757.11816	2.1369095	0.69279611	3698.6584
757.91895	2.1378818	0.69394803	3700.2925
758.71973	2.1372988	0.69542831	3700.2883
759.52051	2.1434677	0.6966266	3700.8789
760.32129	2.1413999	0.6976611	3692.168
761.12207	2.1451576	0.69876605	3695.1604
761.92285	2.1469295	0.70007479	3703.752
762.72363	2.1544988	0.70144141	3708.4556
763.52441	2.1522784	0.70262676	3700.8745
764.3252	2.1535509	0.70379871	3702.8928
765.12598	2.1590004	0.70510942	3705.2659
765.92676	2.1614256	0.70626712	3706.3174
766.72754	2.1649492	0.70766121	3706.3628
767.52832	2.163527	0.70890784	3701.6714
768.3291	2.1673508	0.71006966	3701.0056
769.12988	2.1685278	0.7113356	3703.1899
769.93066	2.1717069	0.71262848	3702.4644
770.73145	2.1723373	0.71399307	3702.7466
771.53223	2.176441	0.71518987	3692.4531
772.33301	2.1809835	0.7163083	3698.4307
773.13379	2.1803248	0.71742904	3702.1738
773.93457	2.1859226	0.7185955	3706.8564
774.73535	2.1881375	0.71999013	3709.9358
775.53613	2.1863372	0.72135299	3701.1287
776.33691	2.1904144	0.7225523	3699.7517
777.1377	2.1952162	0.72361898	3705.9822
777.93848	2.1943676	0.7247507	3702.4082
778.73926	2.2003784	0.72596973	3702.9297
779.54004	2.199497	0.72726494	3701.0313
780.34082	2.2023461	0.72838771	3700.0208
781.1416	2.2053163	0.72984082	3704.8184
781.94238	2.2079098	0.73079789	3701.6462
782.74316	2.2117429	0.7318998	3705.5518
783.54395	2.2118626	0.73298836	3705.4185
784.34473	2.2137942	0.73403805	3698.5525
785.14551	2.2183928	0.73522955	3707.927
785.94629	2.2214241	0.73639357	3702.4783
786.74707	2.223304	0.73774135	3708.376
787.54785	2.2268243	0.73892939	3708.3911
788.34863	2.2279727	0.74031943	3706.3296
789.14941	2.2290843	0.74142915	3705.3794
789.9502	2.2319479	0.74265581	3707.0874
790.75098	2.2367287	0.7441346	3706.5361
791.55176	2.2368088	0.74565941	3705.7795
792.35254	2.2394166	0.74710125	3708.3296
793.15332	2.2410989	0.74846953	3701.5259
793.9541	2.248307	0.74966413	3699.9517
794.75488	2.244945	0.75086349	3703.3621
795.55566	2.2525249	0.75198436	3701.594
796.35645	2.2492414	0.75305152	3701.1267
797.15723	2.2532692	0.75415123	3700.5342
797.95801	2.2546046	0.75537407	3701.8657
798.75879	2.2585394	0.75658137	3706.2234
799.55957	2.2625537	0.75793821	3705.4761
800.36035	2.2652254	0.75902182	3700.6387
801.16113	2.2685862	0.76020241	3706.7634
801.96191	2.267982	0.761482	3706.7275
802.7627	2.2708895	0.76267922	3704.3174
803.56348	2.2718439	0.76415503	3708.5554
804.36426	2.2730396	0.765396	3701.0342
805.16504	2.2796221	0.76692641	3715.2168
805.96582	2.2810483	0.7684027	3709.4556
806.7666	2.284343	0.76949835	3699.6265
807.56738	2.2851064	0.77055424	3701.8252
808.36816	2.2876737	0.77188313	3702.9512
809.16895	2.2936022	0.77324641	3708.0378
809.96973	2.2943034	0.77428943	3701.4651
810.77051	2.2949274	0.7755729	3703.8323
811.57129	2.2986019	0.77684438	3709.0098
812.37207	2.299798	0.77786642	3702.6904
813.17285	2.3017857	0.77908134	3709.418
813.97363	2.3051145	0.7803238	3709.1873
814.77441	2.307606	0.7816878	3707.1467
815.5752	2.3077738	0.78306204	3705.6248
816.37598	2.3108542	0.78422451	3706.3232
817.17676	2.314858	0.78570873	3709.6423
817.97754	2.3188274	0.78698063	3702.8064
818.77832	2.3193228	0.78825033	3704.2307
819.5791	2.3193164	0.7893973	3703.0591
820.37988	2.3247104	0.79070389	3706.564
821.18066	2.3247273	0.79194331	3699.9485
821.98145	2.3286846	0.79311401	3702.1262
822.78223	2.330344	0.79426837	3701.5144
823.58301	2.3325212	0.79523516	3700.8232
824.38379	2.3334613	0.79638815	3701.5967
825.18457	2.3370805	0.79737884	3698.9636
825.98535	2.3398015	0.79841363	3698.5884
826.78613	2.3434854	0.79958475	3709.2131
827.58691	2.3451686	0.80093259	3702.2114
828.3877	2.3462923	0.80229366	3703.0774
829.18848	2.3487928	0.80341047	3701.7532
829.98926	2.3520045	0.80501229	3701.7993
830.79004	2.3547959	0.80629432	3700.9504
831.59082	2.3567963	0.8074519	3697.3318
832.3916	2.3620377	0.80857849	3700.7505
833.19238	2.3599153	0.80979633	3703.9282
833.99316	2.3639858	0.81110406	3706.9768
834.79395	2.3646619	0.81215131	3695.0437
835.59473	2.3715212	0.81317466	3695.6355
836.39551	2.3728671	0.81428325	3704.0273
837.19629	2.375499	0.81545353	3698.8433
837.99707	2.3780034	0.81661874	3702.8562
838.79785	2.3802469	0.8177579	3697.915
839.59863	2.3818634	0.81901199	3706.6304
840.39941	2.3856368	0.82037234	3706.4348
841.2002	2.3857074	0.82171029	3700.46
842.00098	2.3869832	0.82288009	3695.9783
842.80176	2.3927464	0.82410121	3698.0728
843.60254	2.3940976	0.82520455	3700.636
844.40332	2.3955908	0.82651657	3701.2957
845.2041	2.3979576	0.82767403	3695.2158
846.00488	2.4014485	0.82893527	3697.7405
846.80566	2.4050052	0.83005571	3697.2981
847.60645	2.4069576	0.83114994	3692.4739
848.40723	2.4095414	0.83228618	3692.9353
849.20801	2.4112213	0.83337408	3695.5347
850.00879	2.4122024	0.83461612	3698.0681
850.80957	2.4121382	0.83587241	3696.1892
851.61035	2.4170885	0.83730131	3695.447
852.41113	2.4179459	0.83846575	3689.7468
853.21191	2.4217863	0.83980268	3697.676
854.0127	2.4243889	0.84080291	3688.2805
854.81348	2.4266965	0.84180826	3687.0586
855.61426	2.4266386	0.84290051	3689.8098
856.41504	2.4348993	0.84415823	3690.5962
857.21582	2.4348509	0.84522676	3690.2363
858.0166	2.4360712	0.84622753	3684.1125
858.81738	2.4401343	0.8472088	3685.5801
859.61816	2.4401352	0.84824187	3686.4617
860.41895	2.4429114	0.84907293	3684.0583
861.21973	2.44613	0.8502202	3693.8315
862.02051	2.4513175	0.85143352	3697.3018
862.82129	2.4512069	0.85246992	3685.9583
863.62207	2.45333	0.85349554	3684.8296
864.42285	2.4562745	0.85484415	3692.4841
865.22363	2.4553456	0.85593718	3678.3711
866.02441	2.4616344	0.85714167	3687.4673
866.8252	2.4621685	0.85825205	3683.5684
867.62598	2.4670458	0.85931718	3677.9299
868.42676	2.4669483	0.8603881	3687.3008
869.22754	2.4684179	0.86147583	3685.3225
870.02832	2.4749942	0.86268955	3684.8831
870.8291	2.475631	0.86382639	3679.4939
871.62988	2.4777434	0.86479741	3678.9092
872.43066	2.4812267	0.8660208	3682.0852
873.23145	2.4833817	0.86693019	3674.9827
874.03223	2.483506	0.86790746	3674.4282
874.83301	2.4861529	0.86883765	3676.3303
875.63379	2.4903216	0.86981672	3672.3662
876.43457	2.4897537	0.87094408	3676.4744
877.23535	2.4922109	0.87205005	3671.1021
878.03613	2.4957886	0.87314004	3668.5789
878.83691	2.5024316	0.87424958	3675.2483
879.6377	2.4998605	0.87526488	3674.8374
880.43848	2.5057855	0.87643683	3673.281
881.23926	2.5062685	0.87735897	3664.032
882.04004	2.5059369	0.87829977	3660.3835
882.84082	2.5104606	0.87938809	3664.3013
883.6416	2.5139935	0.88019609	3662.1453
884.44238	2.5155177	0.88134754	3665.8772
885.24316	2.5165107	0.88246268	3663.0906
886.04395	2.522712	0.88332343	3659.4749
886.84473	2.5207777	0.88423705	3660.2974
887.64551	2.5261261	0.88545734	3659.0371
888.44629	2.5284402	0.88643354	3657.1235
889.24707	2.5296373	0.88740349	3648.8826
890.04785	2.5330179	0.8882494	3650.0352
890.84863	2.5350361	0.88903213	3648.3628
891.64941	2.5377829	0.88976938	3641.2629
892.4502	2.5405166	0.89052838	3643.5105
893.25098	2.5428445	0.89128029	3645.2527
894.05176	2.5449665	0.89238042	3653.751
894.85254	2.546555	0.89324909	3643.6128
895.65332	2.5501812	0.89440757	3645.2346
896.4541	2.5491753	0.89532608	3642.8835
897.25488	2.5510967	0.89626902	3638.2749
898.05566	2.5578685	0.8971135	3639.8464
898.85645	2.5568128	0.89817125	3638.7036
899.65723	2.5617712	0.89935106	3643.3401
900.45801	2.5628343	0.90041053	3633.1116
901.25879	2.5664895	0.90131032	3634.5261
902.05957	2.5707266	0.90213138	3627.8923
902.86035	2.5708954	0.90284896	3625.0032
903.66113	2.5742931	0.90357059	3624.1409
904.46191	2.5770125	0.90436959	3626.9058
905.2627	2.5785182	0.90538472	3628.7302
906.06348	2.5803885	0.9063741	3620.1614
906.86426	2.5842817	0.9071092	3617.5146
907.66504	2.5849524	0.90821511	3621.9214
908.46582	2.58741	0.9093163	3612.1482
909.2666	2.5920901	0.91030586	3613.6538
910.06738	2.5951571	0.9112184	3615.9084
910.86816	2.5924442	0.91223067	3608.2878
911.66895	2.5983758	0.91330528	3606.1543
912.46973	2.6024854	0.91412115	3601.9031
913.27051	2.6022086	0.9149316	3601.4441
914.07129	2.6081874	0.91580153	3603.1948
914.87207	2.6089711	0.91658664	3596.9011
915.67285	2.6061475	0.91739148	3596.0938
916.47363	2.6138039	0.91843325	3595.6831
917.27441	2.6176329	0.91953999	3594.7722
918.0752	2.6172655	0.92040747	3587.5229
918.87598	2.6199737	0.92125279	3583.4541
919.67676	2.6223295	0.92208207	3583.4595
920.47754	2.6254048	0.92294937	3584.604
921.27832	2.6261561	0.92379761	3578.7009
922.0791	2.6291666	0.92463511	3578.1328
922.87988	2.6325293	0.92564374	3573.5017
923.68066	2.6335876	0.92636847	3573.3311
924.48145	2.6376173	0.92718041	3572.1853
925.28223	2.6393807	0.92799836	3565.7813
926.08301	2.6382225	0.92883754	3567.7878
926.88379	2.6433549	0.92974252	3565.6416
927.68457	2.6469493	0.93054128	3560.2859
928.48535	2.6461883	0.93152273	3552.9836
929.28613	2.6487088	0.93244946	3550.9771
930.08691	2.6519051	0.93352455	3549.9312
930.8877	2.6561122	0.93434304	3545.6821
931.68848	2.657949	0.935265	3546.0898
932.48926	2.6619885	0.93623388	3539.7466
933.29004	2.6606822	0.93714219	3537.9146
934.09082	2.6656137	0.93796039	3539.1267
934.8916	2.668854	0.9387933	3536.9854
935.69238	2.6710505	0.93962789	3532.6082
936.49316	2.6720412	0.94063359	3527.0657
937.29395	2.6785915	0.94163167	3526.5134
938.09473	2.6801162	0.94238788	3515.1414
938.89551	2.6793449	0.94309264	3510.4016
939.69629	2.6808379	0.94370896	3511.5071
940.49707	2.6827488	0.94464266	3513.4426
941.29785	2.6860523	0.94556624	3512.2461
942.09863	2.6878562	0.94636273	3501.4626
942.89941	2.6919181	0.94705975	3498.7539
943.7002	2.6926868	0.94792503	3500.3137
944.50098	2.6956873	0.9489792	3498.3801
945.30176	2.69994	0.95014286	3496.0422
946.10254	2.7010171	0.9511885	3486.4792
946.90332	2.7047143	0.95198828	3479.783
947.7041	2.7062945	0.95274985	3479.5933
948.50488	2.7091119	0.95334738	3476.9751
949.30566	2.7092271	0.95407218	3471.7354
950.10645	2.7122815	0.95490903	3469.9912
950.90723	2.716799	0.9557572	3461.5745
951.70801	2.7178729	0.95660532	3461.9475
952.50879	2.7213371	0.95743245	3461.7766
953.30957	2.7217662	0.95810384	3451.3872
954.11035	2.7256455	0.95894462	3456.7036
954.91113	2.7250383	0.95973825	3441.7734
955.71191	2.7311978	0.96063656	3447.7783
956.5127	2.7307408	0.96150881	3439.6162
957.31348	2.7384019	0.96235156	3442.1604
958.11426	2.7390978	0.96332449	3430.926
958.91504	2.7420237	0.96414155	3427.7957
959.71582	2.7440448	0.96496695	3424.3569
960.5166	2.746645	0.96578717	3419.7886
961.31738	2.7458007	0.9664892	3413.6177
962.11816	2.7485738	0.96732086	3415.4504
962.91895	2.7504716	0.96814305	3404.9905
963.71973	2.7528791	0.96880198	3400.7751
964.52051	2.7549882	0.96945757	3395.5342
965.32129	2.7589941	0.97009057	3397.22
966.12207	2.7616372	0.9710567	3396.1221
966.92285	2.7614028	0.97184658	3386.2732
967.72363	2.7681878	0.97270018	3380.8098
968.52441	2.7710767	0.97338378	3378.418
969.3252	2.7726223	0.97422439	3371.8547
970.12598	2.7730041	0.97498536	3362.9263
970.92676	2.7747116	0.97578889	3361.085
971.72754	2.7761133	0.97648019	3358.1985
972.52832	2.7792656	0.97739601	3349.2866
973.3291	2.7824981	0.97824872	3343.5232
974.12988	2.7871399	0.97889781	3334.6882
974.93066	2.7888401	0.97955239	3338.0256
975.73145	2.7908721	0.98036307	3336.9658
976.53223	2.7921512	0.98115522	3323.8
977.33301	2.7946796	0.98192078	3319.9788
978.13379	2.8007278	0.98270786	3319.1284
978.93457	2.8014715	0.98336858	3309.6018
979.73535	2.8026347	0.9839682	3306.7085
980.53613	2.8052218	0.98464882	3292.064
981.33691	2.8095329	0.98537302	3294.0024
982.1377	2.8099513	0.98599249	3288.3608
982.93848	2.8100989	0.98672485	3283.562
983.73926	2.8152313	0.98726481	3270.4585
984.54004	2.8141418	0.98794228	3273.186
985.34082	2.8192794	0.98859328	3269.8149
986.1416	2.8211746	0.98931777	3262.2932
986.94238	2.8253102	0.99000508	3263.0496
987.74316	2.8264329	0.99094927	3247.7
988.54395	2.8320062	0.99162811	3242.7974
989.34473	2.8307278	0.99247307	3229.7053
990.14551	2.8320315	0.9932192	3224.4863
990.94629	2.833914	0.99391371	3212.5071
991.74707	2.835387	0.99456847	3210.5183
992.54785	2.8409922	0.99544674	3201.7195
993.34863	2.8446267	0.99624604	3198.5854
994.14941	2.8450308	0.99712318	3185.2847
994.9502	2.8476553	0.99795437	3181.5732
995.75098	2.8502765	0.99891013	3165.6589
996.55176	2.8517616	0.99996799	3149.6719
997.35254	2.8561828	1.0008076	3135.7017
998.15332	2.8606098	1.0027204	3090.3159
998.35352	3.0519235	0.64820808	-26.396309