File: datasets/am_bench_2022/raw_data/0-X.20-2/specimen.dat
MTS793|MPT|ENU|1|2|.|/|:|1|0|0|A

Operator Information						Time:	14.632568	Sec	10/13/2021 9:59:12 AM
Operator	Jake Benzing
Project	AM Bench 2022 mini-tensile challenge
Specimen ID	O-X.20-2
Material	PBF-L Inconel 625
Specimen Width	2.55	mm
Specimen Thickness	1.53	mm
Notes
Operator Information End

Data Acquisition						Time:	1015.6262	Sec	10/13/2021 10:15:53 AM
Time	Axial Displacement	Axial Extensometer	Axial Force
Sec	mm	mm	N
14.746094	-0.0013859385	0.0025297664	55.229969
15.74707	0.0030326887	0.0024614558	66.920563
16.748047	0.0043554651	0.0026895904	77.310471
17.749023	0.0093078334	0.0026975854	94.176659
18.75	0.011546216	0.0027653961	103.11082
19.750977	0.013291016	0.0026572517	114.83241
20.751953	0.015584156	0.0028615503	126.09604
21.75293	0.020346794	0.0028797479	136.4994
22.753906	0.022153933	0.0030139054	153.18265
23.754883	0.025242614	0.0031267048	171.38194
24.755859	0.025904207	0.0031473364	190.97627
25.756836	0.031928975	0.0031510654	209.61116
26.757813	0.033648778	0.0033365891	227.34135
27.758789	0.037551489	0.0034407373	243.82462
28.759766	0.039077517	0.0033646582	261.81815
29.760742	0.043778688	0.0035845204	283.83826
30.761719	0.04488305	0.0037215659	300.1333
31.762695	0.049944833	0.0036901152	321.21481
32.763672	0.051230472	0.0038469909	338.28214
33.764648	0.053414814	0.003942342	362.88446
34.765625	0.058497902	0.0040856614	380.59998
35.766602	0.059994835	0.0041465373	409.63138
36.767578	0.063665971	0.0042724828	430.73935
37.768555	0.066554725	0.0043207626	445.06448
38.769531	0.072536878	0.0044797119	469.69104
39.770508	0.073175319	0.0045167306	494.59335
40.771484	0.077074699	0.0046455977	524.81024
41.772461	0.076750204	0.0047071907	540.46057
42.773438	0.081139483	0.0048284433	564.17609
43.774414	0.084811129	0.0049537206	591.78961
44.775391	0.088778377	0.0051930398	615.82599
45.776367	0.090270191	0.0051500411	645.75397
46.777344	0.093616009	0.0053713531	677.76611
47.77832	0.093694687	0.005487768	701.20227
48.779297	0.097297028	0.0056436746	726.79431
49.780273	0.10206151	0.0056277467	743.11163
50.78125	0.10605683	0.0057363594	781.93768
51.782227	0.10750557	0.0059376289	800.39929
52.783203	0.11042793	0.0059616216	830.49677
53.78418	0.11107211	0.0061195167	852.50446
54.785156	0.1184573	0.0059602694	888.65704
55.786133	0.12095322	0.0063838311	918.99817
56.787109	0.12467404	0.0064367699	945.16205
57.788086	0.12552352	0.0064833579	966.03357
58.789063	0.12992986	0.0067701284	1000.7477
59.790039	0.13348323	0.006805595	1039.1243
60.791016	0.13275976	0.0069642891	1062.6853
61.791992	0.1398309	0.0071516559	1095.7129
62.792969	0.14093214	0.0072398596	1117.8188
63.793945	0.14373812	0.007312227	1142.7092
64.794922	0.14856321	0.0074478257	1175.2079
65.795898	0.14733821	0.0076413061	1203.2292
66.796875	0.15469247	0.0076302062	1228.0419
67.797852	0.15340847	0.007794911	1255.7058
68.798828	0.15900046	0.0079484796	1294.9189
69.799805	0.16236226	0.0080720512	1318.5709
70.800781	0.16219589	0.008194387	1347.7916
71.801758	0.16479164	0.0083587775	1372.7083
72.802734	0.17135093	0.0085093379	1410.131
73.803711	0.17520815	0.0086205546	1435.0575
74.804688	0.17517659	0.0086673684	1459.9263
75.805664	0.18233667	0.0089129601	1490.8176
76.806641	0.18367685	0.0090105571	1515.9919
77.807617	0.18777135	0.0091400454	1545.1392
78.808594	0.18888406	0.0092070652	1570.4742
79.80957	0.1938041	0.0094006965	1600.8481
80.810547	0.19498709	0.0094608935	1629.0508
81.811523	0.20103931	0.0096099991	1662.0688
82.8125	0.20255116	0.0097427676	1681.9127
83.813477	0.20310068	0.0098990519	1696.4336
84.814453	0.20740646	0.0099470653	1728.3895
85.81543	0.21363094	0.010110945	1761.1777
86.816406	0.21249482	0.010310493	1780.5342
87.817383	0.214555	0.010343308	1800.5435
88.818359	0.21884967	0.01052059	1835.6627
89.819336	0.22174166	0.010724577	1857.4995
90.820313	0.22495389	0.010776615	1879.7946
91.821289	0.22743614	0.010922693	1899.2953
92.822266	0.22864474	0.011050403	1922.437
93.823242	0.23443024	0.011323823	1959.7565
94.824219	0.23797624	0.011369202	1988.4364
95.825195	0.23948316	0.011527991	2000.6528
96.826172	0.24231327	0.011752499	2030.1133
97.827148	0.24336846	0.011847444	2048.1958
98.828125	0.24734457	0.012035134	2070.8181
99.829102	0.25225878	0.012126118	2092.6406
100.83008	0.25686181	0.012446154	2118.2488
101.83105	0.25812024	0.012445978	2130.8477
102.83203	0.26268905	0.012782409	2163.9573
103.83301	0.26398703	0.012926256	2178.4343
104.83398	0.2678912	0.013154043	2196.4622
105.83496	0.27022895	0.013229164	2215.687
106.83594	0.27463573	0.013544554	2227.845
107.83691	0.27956593	0.013815059	2251.709
108.83789	0.27982593	0.013909603	2266.4424
109.83887	0.28149766	0.014271539	2281.3655
110.83984	0.28768224	0.014506386	2298.9985
111.84082	0.29079631	0.014758317	2318.5225
112.8418	0.29134172	0.015001951	2327.2449
113.84277	0.29201496	0.015234069	2338.9211
114.84375	0.29887998	0.015695142	2357.7241
115.84473	0.29942846	0.015979324	2372.4766
116.8457	0.30201948	0.016375003	2381.3049
117.84668	0.30422717	0.016786838	2391.1472
118.84766	0.30742589	0.017272925	2404.8611
119.84863	0.31444335	0.017661933	2426.2026
120.84961	0.31819013	0.01816199	2441.0791
121.85059	0.31951839	0.01862124	2439.8748
122.85156	0.32047585	0.018949619	2450.4756
123.85254	0.32514894	0.019604973	2466.8596
124.85352	0.32809302	0.020370504	2472.9077
125.85449	0.33047953	0.020921519	2483.8357
126.85547	0.33479142	0.021627741	2492.6179
127.85645	0.3393043	0.022290412	2501.7168
128.85742	0.34098727	0.023037052	2509.6882
129.8584	0.34147656	0.02390084	2521.199
130.85938	0.34696138	0.024745282	2524.5547
131.86035	0.34981117	0.025738573	2527.5811
132.86133	0.35342872	0.026728727	2536.6958
133.8623	0.35619181	0.027310254	2535.051
134.86328	0.35744166	0.028173143	2546.3606
135.86426	0.36179698	0.02943554	2553.1174
136.86523	0.36410913	0.03035802	2547.5229
137.86621	0.3674224	0.031352673	2563.853
138.86719	0.37158656	0.032408394	2566.9185
139.86816	0.37354854	0.033800352	2565.6096
140.86914	0.37842163	0.034847211	2571.2236
141.87012	0.38036215	0.035969872	2572.9023
142.87109	0.38508156	0.037320249	2588.561
143.87207	0.38433841	0.038672559	2584.2791
144.87305	0.39012957	0.040059272	2592.7913
145.87402	0.39453429	0.0412082	2592.2825
146.875	0.39259994	0.042085066	2587.9099
147.87598	0.39778832	0.043255132	2596.4238
148.87695	0.40202296	0.044414334	2592.9714
149.87793	0.4059763	0.045726534	2602.959
150.87891	0.40531039	0.047268562	2611.1394
151.87988	0.41238564	0.048766159	2614.5566
152.88086	0.41505161	0.050209314	2617.9167
153.88184	0.41787189	0.051885732	2620.2419
154.88281	0.42020601	0.053011347	2615.9685
155.88379	0.42188406	0.054493133	2624.2827
156.88477	0.4279514	0.055730347	2617.8367
157.88574	0.42575768	0.057185512	2625.0476
158.88672	0.43101263	0.058793336	2624.2737
159.8877	0.43228376	0.060299251	2625.6108
160.88867	0.43598655	0.06165136	2632.4438
161.88965	0.44166973	0.063188203	2635.417
162.89063	0.44281527	0.064972177	2637.8784
163.8916	0.44487047	0.06662035	2634.1934
164.89258	0.44763303	0.068023652	2633.1238
165.89355	0.45132592	0.069362901	2633.509
166.89453	0.455587	0.071050793	2640.0464
167.89551	0.45763627	0.072560161	2648.0569
168.89648	0.45786512	0.074628823	2648.2703
169.89746	0.46448448	0.076546982	2651.4468
170.89844	0.46708348	0.078392468	2649.834
171.89941	0.47193524	0.079963267	2648.7454
172.90039	0.47034836	0.081189945	2641.842
173.90137	0.47500533	0.082659416	2655.2878
174.90234	0.47672635	0.084402822	2658.9995
175.90332	0.48081839	0.086225905	2656.1008
176.9043	0.48749411	0.088014431	2665.8926
177.90527	0.49001113	0.089753367	2655.3208
178.90625	0.49240467	0.091023527	2658.7593
179.90723	0.49375466	0.092615783	2662.0779
180.9082	0.4968214	0.094401844	2661.2803
181.90918	0.50300032	0.096058972	2666.2019
182.91016	0.50111979	0.097508639	2660.7327
183.91113	0.50548518	0.099288426	2668.238
184.91211	0.51007056	0.10129179	2673.2913
185.91309	0.51541877	0.10275207	2671.4001
186.91406	0.51719451	0.10451051	2676.5479
187.91504	0.51886785	0.10636087	2669.6199
188.91602	0.52183795	0.10792388	2673.7524
189.91699	0.52510816	0.10974127	2677.5708
190.91797	0.53125668	0.11148179	2683.3403
191.91895	0.52981716	0.11343592	2671.3748
192.91992	0.5318898	0.11496376	2681.9321
193.9209	0.53496903	0.1166506	2678.5566
194.92188	0.54127592	0.11847126	2688.0435
195.92285	0.54378331	0.1199633	2677.0117
196.92383	0.54575747	0.12166037	2686.1675
197.9248	0.54951489	0.12343552	2686.7097
198.92578	0.54961365	0.12546919	2686.5552
199.92676	0.55346763	0.12695096	2684.0483
200.92773	0.55770063	0.1286153	2690.6831
201.92871	0.56120646	0.13056228	2693.3999
202.92969	0.55790633	0.13227898	2688.1094
203.93066	0.56498152	0.13424681	2693.1616
204.93164	0.56963211	0.13590671	2691.6514
205.93262	0.57169574	0.13770433	2692.9404
206.93359	0.57614774	0.13923007	2688.4355
207.93457	0.57907581	0.14088869	2698.761
208.93555	0.58462274	0.14249159	2699.1138
209.93652	0.58486044	0.14424486	2703.2229
210.9375	0.58757436	0.14611547	2699.0142
211.93848	0.5898214	0.14814319	2699.6038
212.93945	0.5933252	0.14988345	2696.7317
213.94043	0.5988521	0.15148294	2701.2349
214.94141	0.59768665	0.15323719	2702.2349
215.94238	0.60371655	0.1549046	2702.5198
216.94336	0.60735846	0.15639444	2707.2285
217.94434	0.60977715	0.15810964	2704.3005
218.94531	0.6145035	0.15974998	2703.4722
219.94629	0.61373848	0.16144413	2709.9456
220.94727	0.62249172	0.1631107	2714.4153
221.94824	0.62005681	0.16479261	2717.9253
222.94922	0.62223381	0.16656649	2710.3042
223.9502	0.62657905	0.16834164	2711.1619
224.95117	0.63077313	0.17014673	2714.1384
225.95215	0.63153487	0.17187209	2713.9604
226.95313	0.63632911	0.17364675	2717.8137
227.9541	0.63779092	0.1752225	2716.1655
228.95508	0.64584637	0.17693706	2722.9932
229.95605	0.64571172	0.1787754	2717.3687
230.95703	0.6500501	0.18033998	2718.9338
231.95801	0.65254664	0.18204762	2724.0217
232.95898	0.65184897	0.18396023	2719.4651
233.95996	0.65384054	0.1859902	2719.6975
234.96094	0.65698618	0.18814167	2727.0737
235.96191	0.66019225	0.18987419	2721.2983
236.96289	0.66743588	0.19181252	2729.3572
237.96387	0.66776496	0.19352151	2725.7734
238.96484	0.67239189	0.1954671	2728.8625
239.96582	0.67477769	0.19728556	2729.6511
240.9668	0.6800468	0.19896333	2730.9685
241.96777	0.68023509	0.20065825	2730.751
242.96875	0.68394518	0.2024765	2729.6584
243.96973	0.68776983	0.20417708	2732.1282
244.9707	0.6876725	0.20582689	2728.9268
245.97168	0.69361061	0.20731337	2730.3435
246.97266	0.69448489	0.20922865	2735.595
247.97363	0.69794506	0.21125889	2743.062
248.97461	0.70002586	0.21325445	2741.55
249.97559	0.70416796	0.21518348	2735.1223
250.97656	0.71001071	0.21674621	2739.0667
251.97754	0.71004963	0.21850251	2740.0847
252.97852	0.71463156	0.22012164	2746.0112
253.97949	0.71930856	0.22159399	2743.2366
254.98047	0.72115916	0.22300573	2744.5676
255.98145	0.72330308	0.2246872	2742.915
256.98242	0.72689188	0.22666131	2752.0291
257.9834	0.7276383	0.22859067	2745.0002
258.98438	0.73102677	0.23055983	2747.0498
259.98535	0.73201084	0.23261985	2745.5681
260.98633	0.73754919	0.23425153	2743.5095
261.9873	0.74067783	0.23633483	2745.7512
262.98828	0.74237496	0.23780888	2745.4021
263.98926	0.74429721	0.23946552	2743.3521
264.99023	0.74791986	0.24107797	2748.8491
265.99121	0.74972326	0.24283157	2748.1577
266.99219	0.75809157	0.24475186	2752.8765
267.99316	0.75702488	0.24656142	2752.4155
268.99414	0.76499957	0.24884382	2757.2993
269.99512	0.76359177	0.25059667	2752.771
270.99609	0.76893973	0.25218332	2756.0166
271.99707	0.77079302	0.25406888	2757.6643
272.99805	0.7773332	0.25582767	2762.593
273.99902	0.77643704	0.25766832	2759.8967
275	0.7787807	0.25956374	2764.6782
276.00098	0.78170902	0.26162317	2769.0825
277.00195	0.78380895	0.26364025	2758.3188
278.00293	0.78940547	0.26537263	2759.7031
279.00391	0.79179388	0.2672658	2767.3079
280.00488	0.79242879	0.26903769	2768.7957
281.00586	0.79959661	0.27080289	2770.084
282.00684	0.80105543	0.27265975	2769.2461
283.00781	0.80224723	0.27457625	2762.9033
284.00879	0.80792207	0.27626395	2765.1265
285.00977	0.80914319	0.2778962	2765.8191
286.01074	0.81172645	0.2796818	2772.8018
287.01172	0.81427753	0.28159142	2777.1487
288.0127	0.81750655	0.28394866	2774.8872
289.01367	0.82189161	0.28538716	2764.957
290.01465	0.8223294	0.28700122	2773.5415
291.01563	0.82890701	0.28827459	2773.543
292.0166	0.83175451	0.28966382	2776.9573
293.01758	0.8346262	0.29139614	2777.2551
294.01855	0.83792496	0.29306701	2778.6965
295.01953	0.84113044	0.2948561	2783.4272
296.02051	0.84248888	0.29672691	2780.6721
297.02148	0.84651423	0.29865301	2778.6736
298.02246	0.85047662	0.30044657	2785.2786
299.02344	0.85387284	0.30214739	2782.0347
300.02441	0.85275966	0.30417064	2785.1794
301.02539	0.85939127	0.30605802	2786.4941
302.02637	0.8635717	0.30797634	2796.4033
303.02734	0.86463445	0.31001598	2792.6086
304.02832	0.86855501	0.31189099	2782.3064
305.0293	0.86827594	0.31382129	2789.2993
306.03027	0.87376893	0.31565896	2791.2673
307.03125	0.8757894	0.3176612	2791.3323
308.03223	0.87856567	0.31966016	2789.3552
309.0332	0.88185984	0.32164586	2792.5874
310.03418	0.88505095	0.32343864	2791.8096
311.03516	0.88822961	0.32530454	2791.949
312.03613	0.88916183	0.32735345	2794.6938
313.03711	0.89440536	0.32943732	2799.0754
314.03809	0.89611495	0.33129963	2790.4624
315.03906	0.90165943	0.33282283	2800.6519
316.04004	0.90202904	0.33445081	2800.2563
317.04102	0.90822589	0.33617508	2796.3809
318.04199	0.91095197	0.33811554	2802.9204
319.04297	0.9117713	0.34002742	2800.5071
320.04395	0.91536403	0.34191841	2797.6921
321.04492	0.91949296	0.34361088	2804.9534
322.0459	0.92323726	0.34524307	2807.3936
323.04688	0.92475814	0.34718838	2807.0571
324.04785	0.92877477	0.34919024	2807.8967
325.04883	0.92833716	0.35079306	2801.0671
326.0498	0.93538696	0.3523944	2812.2383
327.05078	0.93786448	0.35433069	2814.7681
328.05176	0.93948638	0.35616744	2808.2908
329.05273	0.94381177	0.35809365	2809.3828
330.05371	0.94457334	0.35983908	2813.5999
331.05469	0.94846833	0.36222371	2812.3867
332.05566	0.94814456	0.36395973	2809.425
333.05664	0.94992834	0.36553869	2808.1941
334.05762	0.95623457	0.36730596	2814.1069
335.05859	0.96288794	0.36936849	2816.8975
336.05957	0.96414471	0.37125903	2818.2075
337.06055	0.96788538	0.37308136	2815.3843
338.06152	0.96499175	0.37480113	2808.4038
339.0625	0.97186738	0.37659645	2818.7849
340.06348	0.97645587	0.37800038	2814.2344
341.06445	0.97729856	0.37984642	2820.1208
342.06543	0.97735739	0.381789	2815.3582
343.06641	0.98697937	0.38358	2819.239
344.06738	0.99103796	0.38533127	2827.3066
345.06836	0.98922068	0.387407	2827.8655
346.06934	0.99632144	0.38934359	2823.2856
347.07031	0.99362344	0.39095169	2821.1621
348.07129	1.0016844	0.39287356	2828.0146
349.07227	1.0019541	0.39479861	2831.9521
350.07324	1.0088606	0.3966119	2831.1438
351.07422	1.0064642	0.3987512	2831.9038
352.0752	1.009939	0.40069515	2819.9807
353.07617	1.0134668	0.40253851	2826.1602
354.07715	1.0154001	0.40437335	2831.3098
355.07813	1.0199478	0.40625441	2828.2083
356.0791	1.0205206	0.4081836	2829.29
357.08008	1.0232651	0.4097462	2827.3875
358.08105	1.0309794	0.41149649	2828.219
359.08203	1.0315738	0.41320091	2832.626
360.08301	1.0357473	0.41525128	2833.2083
361.08398	1.0389662	0.41734594	2837.7046
362.08496	1.0407243	0.4192189	2832.0261
363.08594	1.045526	0.42078054	2831.2314
364.08691	1.0475078	0.42242247	2842.8074
365.08789	1.0522876	0.42424974	2837.5344
366.08887	1.0562443	0.42594895	2842.3987
367.08984	1.0555636	0.42784154	2840.1799
368.09082	1.0578618	0.42983565	2843.0674
369.0918	1.0614073	0.43178689	2846.7925
370.09277	1.0657747	0.43403184	2847.2747
371.09375	1.0687159	0.43592885	2843.9585
372.09473	1.0699103	0.43778303	2844.9236
373.0957	1.0726482	0.43921316	2836.885
374.09668	1.0780063	0.44098741	2848.6597
375.09766	1.0811241	0.44255373	2846.1858
376.09863	1.0857745	0.44412559	2848.1848
377.09961	1.0867271	0.44591907	2853.5852
378.10059	1.0893298	0.44798669	2853.3359
379.10156	1.0902709	0.44999233	2848.3198
380.10254	1.0950378	0.45212889	2854.3154
381.10352	1.0973816	0.45424938	2857.0081
382.10449	1.1005149	0.45599276	2850.2563
383.10547	1.1050187	0.4576768	2847.7603
384.10645	1.111133	0.45931399	2855.7756
385.10742	1.1110262	0.46091223	2850.9944
386.1084	1.1132885	0.46296352	2855.4414
387.10938	1.1181619	0.46520406	2857.7847
388.11035	1.1210083	0.46721259	2860.4485
389.11133	1.1252553	0.46899992	2855.2131
390.1123	1.1234468	0.47074983	2852.3923
391.11328	1.1300259	0.47261745	2866.9116
392.11426	1.1324972	0.47470838	2863.1753
393.11523	1.1302418	0.47653878	2858.2622
394.11621	1.1378958	0.47828037	2859.2007
395.11719	1.14	0.48030174	2872.2161
396.11816	1.1438218	0.48199889	2860.762
397.11914	1.1463556	0.48360536	2863.7043
398.12012	1.1466669	0.48554829	2861.043
399.12109	1.1521448	0.4873428	2862.3313
400.12207	1.1551247	0.48931843	2866.7239
401.12305	1.1563243	0.49106652	2863.6929
402.12402	1.1625593	0.49316788	2873.9709
403.125	1.1630766	0.49489558	2865.0413
404.12598	1.165922	0.49682406	2867.5483
405.12695	1.1689786	0.49877182	2871.1016
406.12793	1.1744224	0.50061542	2870.6406
407.12891	1.1727662	0.50232261	2868.5342
408.12988	1.179493	0.50434023	2870.9883
409.13086	1.1815794	0.50626558	2872.5361
410.13184	1.1874301	0.5079686	2874.353
411.13281	1.1873492	0.50972992	2872.9036
412.13379	1.189944	0.51177657	2880.0215
413.13477	1.1949153	0.51349378	2878.908
414.13574	1.1985027	0.51554644	2880.7454
415.13672	1.1991551	0.51765853	2879.3523
416.1377	1.2046264	0.51988363	2882.1677
417.13867	1.2038009	0.52140975	2866.2473
418.13965	1.2093673	0.52332723	2880.9063
419.14063	1.2116096	0.52530301	2874.9949
420.1416	1.2141073	0.52686924	2878.7185
421.14258	1.218317	0.52893215	2877.5339
422.14355	1.21968	0.53058118	2878.4114
423.14453	1.2230221	0.53222126	2878.4275
424.14551	1.2270941	0.5343647	2888.2769
425.14648	1.2308948	0.5364207	2886.3718
426.14746	1.2326598	0.53840107	2881.9932
427.14844	1.2362596	0.5398972	2881.4482
428.14941	1.2388281	0.54174995	2889.4602
429.15039	1.2446495	0.54367131	2890.0852
430.15137	1.2436244	0.54556811	2887.2568
431.15234	1.2481855	0.54746401	2885.9963
432.15332	1.2508912	0.54929072	2898.3953
433.1543	1.2572279	0.55112034	2886.6025
434.15527	1.2575202	0.5526619	2887.177
435.15625	1.2582989	0.55416775	2884.6855
436.15723	1.2654158	0.55608946	2889.5989
437.1582	1.2649835	0.55812895	2896.7502
438.15918	1.2696916	0.55991393	2896.1228
439.16016	1.2706647	0.56193817	2898.0679
440.16113	1.2725687	0.56397134	2892.5974
441.16211	1.2800857	0.5659408	2896.1743
442.16309	1.282668	0.56781149	2892.2732
443.16406	1.2844012	0.56977415	2895.4226
444.16504	1.2876441	0.57101816	2891.5417
445.16602	1.2902323	0.5726589	2895.415
446.16699	1.2964276	0.57442141	2901.9243
447.16797	1.296018	0.57606226	2905.2151
448.16895	1.2979722	0.57795793	2895.2151
449.16992	1.3029841	0.5798499	2898.6958
450.1709	1.304378	0.58154827	2899.418
451.17188	1.3080657	0.58362168	2904.1497
452.17285	1.3132774	0.58564138	2907.2012
453.17383	1.3127306	0.58758241	2899.8889
454.1748	1.3159436	0.58960736	2900.0166
455.17578	1.320017	0.59155262	2905.769
456.17676	1.3240187	0.59341675	2906.366
457.17773	1.3258867	0.59556192	2910.1406
458.17871	1.3279405	0.59761488	2907.521
459.17969	1.3337046	0.59958553	2906.1799
460.18066	1.3362722	0.6014365	2909.8518
461.18164	1.3388059	0.60323799	2912.5198
462.18262	1.3411068	0.60490739	2912.7124
463.18359	1.3440506	0.60688818	2909.4485
464.18457	1.348817	0.60875618	2911.6348
465.18555	1.3492643	0.61053258	2906.6755
466.18652	1.3524048	0.61230433	2907.7124
467.1875	1.3585531	0.61416215	2915.3022
468.18848	1.3602968	0.61618197	2922.1855
469.18945	1.3645363	0.61796695	2913.5771
470.19043	1.3655586	0.61974317	2916.49
471.19141	1.3661709	0.62127453	2912.2725
472.19238	1.3718547	0.62312859	2918.7925
473.19336	1.3734046	0.62468004	2914.0828
474.19434	1.3790114	0.62654859	2925.2837
475.19531	1.3780581	0.62850761	2923.1951
476.19629	1.3818917	0.6306954	2930.7295
477.19727	1.3856552	0.63241118	2918.8918
478.19824	1.3899333	0.63446146	2924.6345
479.19922	1.3915178	0.63632423	2917.4692
480.2002	1.3949556	0.63804787	2918.0808
481.20117	1.4001459	0.64018494	2926.5728
482.20215	1.4034288	0.64205223	2927.4712
483.20313	1.4056697	0.6437999	2926.2761
484.2041	1.404845	0.64573085	2926.1443
485.20508	1.4128661	0.64763522	2928.9124
486.20605	1.4143213	0.64960802	2924.8464
487.20703	1.416235	0.65145648	2926.0906
488.20801	1.4204891	0.6535089	2934.5037
489.20898	1.4233278	0.65550864	2933.9004
490.20996	1.4252598	0.65768176	2933.3599
491.21094	1.4262977	0.6596148	2927.2158
492.21191	1.4322085	0.66159546	2935.0017
493.21289	1.43321	0.66347235	2923.1748
494.21387	1.4380549	0.66502845	2932.6885
495.21484	1.4388795	0.66691303	2932.8667
496.21582	1.4433209	0.66882813	2936.7344
497.2168	1.4464829	0.67097682	2933.8938
498.21777	1.4490129	0.67298412	2935.3733
499.21875	1.4508417	0.67506468	2935.9712
500.21973	1.4528596	0.67706341	2934.6887
501.2207	1.4589009	0.67881429	2937.4741
502.22168	1.4619808	0.68060273	2941.6003
503.22266	1.4654416	0.68250501	2945.0513
504.22363	1.4698476	0.68421417	2934.8154
505.22461	1.4703598	0.68582577	2937.0471
506.22559	1.4755063	0.68706131	2926.79
507.22656	1.4749376	0.68850517	2932.9707
508.22754	1.478012	0.68996549	2941.0486
509.22852	1.4808242	0.69179457	2950.052
510.22949	1.4843104	0.69395387	2945.1953
511.23047	1.4906095	0.69581372	2939.0857
512.23145	1.4921722	0.69788998	2944.447
513.23242	1.4948493	0.69989675	2937.8293
514.2334	1.4976263	0.70192659	2943.4045
515.23438	1.4996328	0.70389044	2949.1621
516.23535	1.5037462	0.70605803	2950.8608
517.23633	1.5047747	0.70811129	2943.9888
518.2373	1.5103312	0.70995295	2949.8896
519.23828	1.5110765	0.71168292	2945.3904
520.23926	1.5165663	0.71346486	2947.043
521.24023	1.5173323	0.71521312	2943.9517
522.24121	1.5200627	0.71684653	2943.7051
523.24219	1.5260834	0.7187143	2957.4927
524.24316	1.5286059	0.72091824	2952.8088
525.24414	1.5299633	0.72282308	2946.2849
526.24512	1.535375	0.72477514	2954.4607
527.24609	1.5351229	0.72652078	2948.0762
528.24707	1.5385139	0.72809815	2950.5122
529.24805	1.5441084	0.72993785	2952.9722
530.24902	1.5445315	0.73208147	2958.0271
531.25	1.5475571	0.73393577	2949.1245
532.25098	1.5536865	0.73552835	2958.1453
533.25195	1.5540019	0.73764586	2964.3735
534.25293	1.5565857	0.73958814	2954.1445
535.25391	1.5602417	0.7411949	2953.1042
536.25488	1.5640706	0.74309963	2959.9331
537.25586	1.5652808	0.74503207	2957.1333
538.25684	1.5695125	0.74699897	2957.3442
539.25781	1.5696332	0.74874508	2952.4475
540.25879	1.5731143	0.75036299	2951.054
541.25977	1.5791786	0.75198197	2951.9683
542.26074	1.5806016	0.75376046	2962.3074
543.26172	1.5860853	0.7556445	2966.3735
544.2627	1.5908861	0.75780827	2967.8953
545.26367	1.5895449	0.75993353	2965.6606
546.26465	1.5930885	0.76163	2966.8062
547.26563	1.5967246	0.76367235	2965.0623
548.2666	1.5981537	0.76533777	2961.0845
549.26758	1.6053183	0.76737422	2966.6375
550.26855	1.6034421	0.76908547	2965.0403
551.26953	1.6065087	0.77101505	2964.9636
552.27051	1.6147286	0.77309513	2969.7651
553.27148	1.6122576	0.77525121	2971.5
554.27246	1.6181058	0.77732331	2967.3677
555.27344	1.6233079	0.77906865	2971.8235
556.27441	1.6226532	0.78072107	2968.6467
557.27539	1.6280156	0.7825411	2969.3853
558.27637	1.631416	0.78454357	2972.5437
559.27734	1.6326532	0.78638452	2970.8411
560.27832	1.6364304	0.7884596	2980.5327
561.2793	1.63798	0.79057568	2972.7429
562.28027	1.64373	0.79244745	2971.6536
563.28125	1.6443621	0.79372549	2969.4404
564.28223	1.6467035	0.795726	2969.6455
565.2832	1.6481156	0.79748619	2975.9536
566.28418	1.6533824	0.79931068	2972.7681
567.28516	1.6563622	0.80134505	2976.0371
568.28613	1.6587554	0.80345005	2978.1299
569.28711	1.662855	0.80568409	2975.8972
570.28809	1.6660851	0.80748063	2975.7053
571.28906	1.6682314	0.80928928	2981.0435
572.29004	1.6742175	0.81146598	2982.8013
573.29102	1.6730657	0.81318128	2972.0898
574.29199	1.6814224	0.81500989	2984.772
575.29297	1.6799905	0.81682473	2979.1367
576.29395	1.6833136	0.81844312	2975.5273
577.29492	1.6844555	0.8199681	2973.0688
578.2959	1.6910647	0.82131976	2972.0964
579.29688	1.6905726	0.82294703	2976.6487
580.29785	1.6968824	0.82447189	2984.3296
581.29883	1.6960342	0.82618243	2978.9792
582.2998	1.7001182	0.82835764	2985.8376
583.30078	1.7038748	0.83033323	2983.5229
584.30176	1.7078216	0.83273536	2987.7332
585.30273	1.7089961	0.83471197	2985.9065
586.30371	1.7130975	0.83661008	2984.9385
587.30469	1.718075	0.83831656	2986.6528
588.30566	1.7205991	0.83995861	2986.7393
589.30664	1.7218354	0.84167767	2988.8623
590.30762	1.7255696	0.84367776	2988.114
591.30859	1.7296436	0.84544778	2988.0227
592.30957	1.7341262	0.8472873	2988.7041
593.31055	1.7378896	0.84934855	2998.2124
594.31152	1.7382953	0.85156184	2994.6204
595.3125	1.7414086	0.85348874	2988.8918
596.31348	1.7425119	0.85571897	2989.9141
597.31445	1.7465739	0.85774237	2985.6438
598.31543	1.7507095	0.85968477	2995.2661
599.31641	1.7526715	0.86154795	2990.5286
600.31738	1.7585231	0.8637237	2997.3848
601.31836	1.7574782	0.8655709	2992.3044
602.31934	1.7613316	0.86741805	2999.8296
603.32031	1.7641264	0.86901665	2991.4844
604.32129	1.7686747	0.87094915	2998.4534
605.32227	1.772475	0.87272632	2999.9773
606.32324	1.7731167	0.87445974	2989.8516
607.32422	1.780588	0.87643111	2996.8494
608.3252	1.7791784	0.87839371	2992.3677
609.32617	1.7795419	0.8801958	2993.6736
610.32715	1.7834958	0.88204396	2994.8379
611.32813	1.7878271	0.88399523	2992.158
612.3291	1.7917124	0.88573837	2997.2495
613.33008	1.7943456	0.88768762	2996.1558
614.33105	1.8006717	0.88950276	3006.1995
615.33203	1.8033165	0.89124954	2997.0613
616.33301	1.8048632	0.89314938	3003.0313
617.33398	1.8084613	0.89513797	3002.6377
618.33496	1.8108318	0.89680928	2997.2598
619.33594	1.8137224	0.89875519	3006.9688
620.33691	1.8157507	0.9006865	3006.646
621.33789	1.8177627	0.90259171	3006.6304
622.33887	1.8221838	0.90472049	3007.5859
623.33984	1.8229935	0.906654	2998.6152
624.34082	1.8254248	0.90863192	2998.9307
625.3418	1.8302736	0.91034371	3003.0657
626.34277	1.835939	0.91213477	3010.2209
627.34375	1.8358418	0.91436917	3004.7068
628.34473	1.8406525	0.91596735	2997.4529
629.3457	1.8417583	0.9176181	3001.2886
630.34668	1.8461483	0.91962749	3009.7126
631.34766	1.8503169	0.92158854	3016.5686
632.34863	1.852702	0.92366099	3012.2385
633.34961	1.8559219	0.92536187	3005.4363
634.35059	1.8601503	0.9272626	3011.429
635.35156	1.8607453	0.92910469	3011.6938
636.35254	1.8638346	0.93106735	3008.3721
637.35352	1.8669909	0.93296081	3015.4529
638.35449	1.8706443	0.9349038	3013.1101
639.35547	1.8740426	0.93674219	3014.5928
640.35645	1.8790206	0.93874794	3020.0049
641.35742	1.8793359	0.94074726	3010.6577
642.3584	1.8831817	0.94259799	3008.5093
643.35938	1.8865118	0.94464713	3014.8127
644.36035	1.8871088	0.94633037	3009.2983
645.36133	1.8893301	0.94829696	3016.8716
646.3623	1.8933996	0.95021003	3011.9353
647.36328	1.8984059	0.9518677	3015.2634
648.36426	1.8986912	0.9536314	3011.5271
649.36523	1.9008502	0.9555968	3012.3772
650.36621	1.9064509	0.95765865	3015.8374
651.36719	1.909225	0.95955133	3014.0608
652.36816	1.9133487	0.96153355	3021.3079
653.36914	1.9139671	0.96370631	3017.594
654.37012	1.9150025	0.96566719	3017.7358
655.37109	1.9209983	0.96769762	3016.6763
656.37207	1.922833	0.96939367	3014.9138
657.37305	1.9274243	0.97130823	3021.8984
658.37402	1.9288814	0.97324467	3019.811
659.375	1.9321898	0.97538221	3019.0872
660.37598	1.9332081	0.97723621	3018.0088
661.37695	1.9403138	0.97928989	3024.3196
662.37793	1.9419171	0.98121649	3021.0518
663.37891	1.9465367	0.98326588	3023.5151
664.37988	1.947868	0.98523819	3018.4656
665.38086	1.9506878	0.9870041	3022.7271
666.38184	1.9538516	0.98906928	3022.3169
667.38281	1.9568421	0.99091709	3019.9446
668.38379	1.9607882	0.99268878	3024.0818
669.38477	1.9622096	0.99441189	3019.5444
670.38574	1.966099	0.99627388	3024.2041
671.38672	1.9712037	0.99845088	3029.7224
672.3877	1.9696125	1.0003375	3027.6382
673.38867	1.9778975	1.0024654	3029.365
674.38965	1.9774536	1.00451	3019.5881
675.39063	1.9799242	1.0062555	3019.7153
676.3916	1.983421	1.0080899	3026.4265
677.39258	1.9848598	1.0098618	3022.2156
678.39355	1.9939326	1.0119063	3038.4775
679.39453	1.9938805	1.0136678	3026.386
680.39551	1.9933257	1.0159262	3030.2122
681.39648	1.9979259	1.017845	3028.0581
682.39746	2.0028396	1.0199758	3032.2195
683.39844	2.0034225	1.0216514	3021.5676
684.39941	2.0102143	1.0235261	3034.5037
685.40039	2.0116951	1.0253341	3025.5684
686.40137	2.0153251	1.0267484	3027.6624
687.40234	2.0137177	1.0287368	3031.8013
688.40332	2.0200665	1.0305525	3030.4302
689.4043	2.0229146	1.0325505	3032.2341
690.40527	2.0255971	1.0345379	3036.0618
691.40625	2.0276215	1.0365167	3030.2927
692.40723	2.0334032	1.0382597	3027.6541
693.4082	2.0346541	1.0400143	3033.1379
694.40918	2.0399799	1.0420018	3035.324
695.41016	2.0415015	1.0442736	3034.2463
696.41113	2.0448644	1.0462297	3034.6736
697.41211	2.0472326	1.0480502	3034.1021
698.41309	2.0494525	1.0499411	3040.8193
699.41406	2.0537789	1.0519259	3035.9109
700.41504	2.0558598	1.0539514	3034.0598
701.41602	2.0591149	1.0560904	3037.9583
702.41699	2.0609224	1.0584172	3039.3823
703.41797	2.0648086	1.0608807	3043.2356
704.41895	2.069524	1.0630594	3042.356
705.41992	2.0734346	1.0650656	3035.5068
706.4209	2.0743711	1.0673511	3045.7141
707.42188	2.0802979	1.0691147	3040.468
708.42285	2.0820487	1.0707595	3036.5864
709.42383	2.0845222	1.0725709	3038.7769
710.4248	2.0874422	1.0742505	3039.6311
711.42578	2.0874066	1.0760372	3034.877
712.42676	2.0924549	1.077885	3039.5227
713.42773	2.0933456	1.0796853	3034.0627
714.42871	2.0970302	1.0816163	3041.3228
715.42969	2.1008153	1.0834002	3037.6316
716.43066	2.1081221	1.0854242	3044.5288
717.43164	2.107805	1.0871764	3037.9568
718.43262	2.114233	1.0891658	3046.3259
719.43359	2.1144879	1.0911744	3046.4685
720.43457	2.1176207	1.0929761	3038.8672
721.43555	2.1188264	1.0946769	3038.9399
722.43652	2.1227081	1.0967389	3042.7124
723.4375	2.1249819	1.0988324	3045.2327
724.43848	2.1269307	1.1007463	3039.282
725.43945	2.1303892	1.1026559	3041.8162
726.44043	2.1336238	1.1043612	3043.4727
727.44141	2.1379266	1.1063339	3040.6626
728.44238	2.1394393	1.1080317	3039.6782
729.44336	2.143012	1.1100847	3045.0825
730.44434	2.1456454	1.1120555	3043.1838
731.44531	2.1517069	1.1139237	3052.9385
732.44629	2.152601	1.1159427	3045.9849
733.44727	2.1549895	1.1179861	3048.0959
734.44824	2.1634152	1.1201606	3053.3025
735.44922	2.1605034	1.1220173	3043.8621
736.4502	2.1648362	1.1239748	3046.448
737.45117	2.1679854	1.1257428	3041.9092
738.45215	2.1705837	1.1274997	3047.6453
739.45313	2.1733975	1.1298244	3049.1458
740.4541	2.175	1.1320179	3045.7419
741.45508	2.1795011	1.1342015	3047.3796
742.45605	2.1819191	1.136236	3050.052
743.45703	2.1816235	1.138342	3046.9033
744.45801	2.1849418	1.1404122	3045.271
745.45898	2.1893744	1.1423638	3043.884
746.45996	2.1950819	1.1440686	3043.6079
747.46094	2.1938894	1.1457978	3047.6758
748.46191	2.1995234	1.1479973	3053.1897
749.46289	2.2020338	1.1498766	3050.0972
750.46387	2.2050471	1.1517459	3044.3384
751.46484	2.2088478	1.1538464	3050.9878
752.46582	2.2140076	1.1556078	3055.5264
753.4668	2.2135091	1.1578351	3055.5752
754.46777	2.2172797	1.1599271	3050.2571
755.46875	2.2221637	1.1624434	3054.8875
756.46973	2.2261152	1.1640234	3044.3142
757.4707	2.2283683	1.1659657	3053.0439
758.47168	2.230063	1.1676399	3046.0308
759.47266	2.2306077	1.169706	3058.4568
760.47363	2.2368426	1.1717675	3052.9583
761.47461	2.2408698	1.1737585	3055.3901
762.47559	2.2437353	1.176049	3057.5474
763.47656	2.2476628	1.178072	3058.6975
764.47754	2.2466555	1.1801575	3050.2568
765.47852	2.2523923	1.182356	3057.45
766.47949	2.2550774	1.1841478	3057.2856
767.48047	2.2603438	1.1860652	3057.1189
768.48145	2.2571342	1.1879802	3053.6499
769.48242	2.261627	1.1901546	3056.0605
770.4834	2.2656529	1.192057	3057.5811
771.48438	2.2695642	1.1941546	3061.3423
772.48535	2.2745249	1.1967105	3062.8601
773.48633	2.2746542	1.1988417	3055.5366
774.4873	2.2801239	1.2010076	3062.0549
775.48828	2.2820096	1.2030685	3056.1746
776.48926	2.2849097	1.2052733	3061.2698
777.49023	2.2867227	1.2075971	3058.4868
778.49121	2.2921448	1.2097652	3056.3376
779.49219	2.292927	1.2116185	3053.0281
780.49316	2.2976892	1.2135003	3056.1431
781.49414	2.3016012	1.2156212	3062.3093
782.49512	2.3010759	1.2173357	3051.2717
783.49609	2.3066013	1.2196414	3063.9709
784.49707	2.3092434	1.2215662	3061.3743
785.49805	2.3124413	1.2236696	3062.2666
786.49902	2.3156917	1.2256594	3057.8931
787.5	2.3181443	1.2276067	3056.7703
788.50098	2.3224523	1.2295517	3058.8328
789.50195	2.3215992	1.2314191	3054.6375
790.50293	2.3232586	1.2333906	3057.135
791.50391	2.329989	1.2351727	3056.854
792.50488	2.3316004	1.2368704	3061.8193
793.50586	2.335417	1.2390949	3060.6477
794.50684	2.3381464	1.2411922	3062.8127
795.50781	2.3432591	1.2433207	3062.457
796.50879	2.3451493	1.2455083	3065.7476
797.50977	2.3477905	1.2477266	3067.1917
798.51074	2.3523104	1.2495013	3062.0989
799.51172	2.3520985	1.2516587	3058.6284
800.5127	2.3568833	1.253601	3061.8235
801.51367	2.360605	1.2556015	3066.0923
802.51465	2.3626785	1.2575957	3059.8711
803.51563	2.3633871	1.2595346	3062.3606
804.5166	2.3684418	1.2614462	3056.2644
805.51758	2.3735373	1.2635566	3070.7354
806.51855	2.3734086	1.2654854	3063.1345
807.51953	2.3802073	1.267857	3073.418
808.52051	2.3827059	1.2697872	3063.7429
809.52148	2.3836172	1.2721735	3067.9377
810.52246	2.3840091	1.2742221	3058.2253
811.52344	2.3900304	1.2763715	3072.8508
812.52441	2.394187	1.2789634	3072.1582
813.52539	2.395175	1.2814626	3069.1936
814.52637	2.4001305	1.2839427	3069.2988
815.52734	2.401216	1.2863616	3064.873
816.52832	2.4058297	1.2884605	3066.198
817.5293	2.4070394	1.2903601	3066.0151
818.53027	2.4120989	1.2921737	3062.332
819.53125	2.4126205	1.2941052	3064.4756
820.53223	2.4172747	1.2960081	3067.7542
821.5332	2.4207199	1.2982092	3067.866
822.53418	2.4213209	1.3001786	3069.8403
823.53516	2.4227965	1.3022777	3065.2446
824.53613	2.4261434	1.3045542	3067.8276
825.53711	2.4323075	1.3066337	3067.2964
826.53809	2.4350929	1.3084691	3066.085
827.53906	2.4361343	1.3103975	3063.3616
828.54004	2.4422591	1.3122455	3065.2937
829.54102	2.4412529	1.3140984	3068.8779
830.54199	2.4449353	1.3165662	3074.4324
831.54297	2.452529	1.3186492	3073.2205
832.54395	2.4507055	1.3208438	3066.8027
833.54492	2.4551642	1.3229001	3066.9504
834.5459	2.4576833	1.3251064	3066.7119
835.54688	2.4645832	1.3273441	3069.8555
836.54785	2.4613104	1.329083	3063.521
837.54883	2.4674227	1.331144	3070.9697
838.5498	2.4726636	1.3335406	3073.1628
839.55078	2.4717462	1.3358114	3064.4021
840.55176	2.4751048	1.3378646	3070.2825
841.55273	2.4819391	1.3401121	3071.9485
842.55371	2.4829998	1.3420879	3069.793
843.55469	2.4848492	1.3440044	3067.5369
844.55566	2.4916184	1.3464656	3071.6296
845.55664	2.4901588	1.3487476	3070.5125
846.55762	2.4954641	1.3510122	3068.1917
847.55859	2.4989579	1.3530933	3071.5471
848.55957	2.4990046	1.3557086	3077.0415
849.56055	2.5019166	1.3579189	3066.7622
850.56152	2.506943	1.3601785	3073.3806
851.5625	2.5114257	1.3626248	3072.8333
852.56348	2.5102937	1.364677	3074.8953
853.56445	2.5141315	1.3672844	3069.4224
854.56543	2.5204706	1.3692811	3069.7219
855.56641	2.521354	1.3714585	3068.0515
856.56738	2.5251529	1.3736564	3069.7903
857.56836	2.5286186	1.3753263	3069.7786
858.56934	2.5326922	1.3777316	3077.2024
859.57031	2.53318	1.380015	3072.4138
860.57129	2.5382283	1.3827533	3075.1587
861.57227	2.5402441	1.3846738	3065.3005
862.57324	2.5447245	1.3864001	3065.6626
863.57422	2.547302	1.3886383	3077.5981
864.5752	2.5445123	1.3905081	3066.7214
865.57617	2.549926	1.3925006	3073.1353
866.57715	2.5524557	1.3944709	3064.6021
867.57813	2.5590532	1.396534	3073.2996
868.5791	2.5618212	1.3986462	3070.7041
869.58008	2.5629823	1.4007682	3069.4199
870.58105	2.5686338	1.4030827	3077.2441
871.58203	2.5685318	1.4053206	3072.5581
872.58301	2.5708518	1.4079095	3072.1577
873.58398	2.5763276	1.4104204	3073.0222
874.58496	2.5807292	1.4125839	3069.9292
875.58594	2.5808165	1.4145137	3070.9451
876.58691	2.5820539	1.4173989	3079.4021
877.58789	2.5898039	1.4199907	3071.7671
878.58887	2.5911067	1.4220188	3068.356
879.58984	2.5941174	1.4246331	3078.2405
880.59082	2.5959635	1.4269772	3077.4243
881.5918	2.5968668	1.4295398	3070.2266
882.59277	2.6016879	1.4318094	3071.6804
883.59375	2.6041176	1.4341924	3065.4126
884.59473	2.6101685	1.4360752	3068.6016
885.5957	2.6115091	1.4381152	3074.0225
886.59668	2.616472	1.4402355	3068.2625
887.59766	2.6182349	1.4422848	3073.2817
888.59863	2.6219034	1.4446487	3070.5884
889.59961	2.6228192	1.4470507	3076.4424
890.60059	2.6233921	1.4494036	3074.8628
891.60156	2.6310956	1.4517815	3074.0178
892.60254	2.634377	1.4540056	3074.6326
893.60352	2.6352053	1.4561825	3074.0737
894.60449	2.636718	1.4584235	3076.6179
895.60547	2.643018	1.460889	3077.0505
896.60645	2.6455438	1.4628775	3073.1921
897.60742	2.645879	1.4647022	3067.5803
898.6084	2.6510355	1.4665592	3068.6169
899.60938	2.6539705	1.4686093	3080.083
900.61035	2.658078	1.470909	3075.1482
901.61133	2.6590779	1.4730293	3072.698
902.6123	2.6627908	1.4755477	3073.8589
903.61328	2.6653926	1.4780321	3071.1904
904.61426	2.66752	1.4801223	3068.4016
905.61523	2.6704576	1.4822391	3072.0068
906.61621	2.6740055	1.4843779	3080.2395
907.61719	2.6790304	1.4872602	3070.0791
908.61816	2.6789582	1.4896781	3076.7363
909.61914	2.6836159	1.4919878	3072.9648
910.62012	2.6871946	1.4941938	3079.7781
911.62109	2.6891325	1.4966052	3076.2683
912.62207	2.6935167	1.4990575	3075.6316
913.62305	2.6981523	1.5015306	3075.9131
914.62402	2.6979601	1.5036741	3066.7251
915.625	2.6996064	1.506007	3072.7043
916.62598	2.7053194	1.5083423	3075.79
917.62695	2.7099535	1.5103846	3071.47
918.62793	2.7128751	1.5130833	3078.0212
919.62891	2.7139733	1.5158588	3077.4727
920.62988	2.7182558	1.518232	3073.9224
921.63086	2.7212107	1.5204318	3071.8335
922.63184	2.7236469	1.5230559	3074.7944
923.63281	2.7284882	1.5259377	3080.7903
924.63379	2.7274091	1.5286947	3073.6477
925.63477	2.7337458	1.5314575	3076.908
926.63574	2.734602	1.5338464	3071.5461
927.63672	2.7386847	1.5360826	3070.7896
928.6377	2.7397285	1.5382494	3070.0459
929.63867	2.7430227	1.5406432	3072.0876
930.63965	2.7473578	1.5430603	3067.3123
931.64063	2.748915	1.5454158	3076.0142
932.6416	2.7508941	1.5481913	3069.9614
933.64258	2.7531581	1.550523	3066.9692
934.64355	2.7587805	1.5529109	3067.8584
935.64453	2.7620232	1.5550148	3070.1667
936.64551	2.7650552	1.5570341	3068.6697
937.64648	2.7646132	1.5590883	3067.637
938.64746	2.7701528	1.5612102	3073.2068
939.64844	2.7736316	1.56385	3075.9016
940.64941	2.7780247	1.5664182	3075.5112
941.65039	2.7774282	1.5686151	3069.7009
942.65137	2.7827682	1.5710353	3075.0203
943.65234	2.7859921	1.5736384	3074.905
944.65332	2.7899432	1.5763711	3076.2749
945.6543	2.7897246	1.5788159	3070.6934
946.65527	2.7966928	1.5817006	3072.1953
947.65625	2.7983377	1.5842395	3074.2649
948.65723	2.8010495	1.5870403	3079.3608
949.6582	2.8083501	1.5898174	3072.6191
950.65918	2.8064375	1.5918978	3062.6121
951.66016	2.8099	1.5940808	3070.365
952.66113	2.8118572	1.5961406	3071.718
953.66211	2.817663	1.5989609	3075.0151
954.66309	2.8173087	1.6017611	3076.812
955.66406	2.8202739	1.6041802	3060.613
956.66504	2.8251317	1.6066345	3069.7
957.66602	2.829262	1.6092155	3077.0417
958.66699	2.8339114	1.6122104	3080.3542
959.66797	2.8341343	1.6153617	3075.3972
960.66895	2.8371999	1.6184288	3071.9202
961.66992	2.8393555	1.6211951	3066.3708
962.6709	2.8405154	1.6237724	3069.0295
963.67188	2.8451645	1.626179	3071.5862
964.67285	2.8508382	1.6285833	3071.6941
965.67383	2.8515494	1.6306986	3064.344
966.6748	2.8542671	1.6330674	3068.7048
967.67578	2.8570054	1.6355197	3070.4331
968.67676	2.8597147	1.6378155	3068.1143
969.67773	2.8651536	1.6401275	3066.9209
970.67871	2.8681402	1.6425591	3067.6338
971.67969	2.8689957	1.6452131	3067.2097
972.68066	2.8749599	1.6475798	3065.9294
973.68164	2.8748012	1.6497971	3064.311
974.68262	2.8805583	1.6526825	3076.6958
975.68359	2.8818517	1.6553739	3072.1187
976.68457	2.8838615	1.6580027	3066.6936
977.68555	2.8880463	1.6605786	3067.7766
978.68652	2.8906603	1.6630828	3075.7742
979.6875	2.8938131	1.6658028	3073.4507
980.68848	2.8985875	1.6682256	3070.6807
981.68945	2.8996727	1.6712183	3068.9224
982.69043	2.905514	1.6737832	3070.7742
983.69141	2.9072318	1.6766096	3066.6445
984.69238	2.9061751	1.6794399	3062.6519
985.69336	2.9148061	1.6818051	3065.3867
986.69434	2.9144154	1.6840086	3069.0862
987.69531	2.91922	1.6865402	3071.4099
988.69629	2.9220169	1.68905	3068.3684
989.69727	2.9257834	1.6924351	3073.1265
990.69824	2.9258602	1.6956246	3067.1367
991.69922	2.9306118	1.6984386	3068.3518
992.7002	2.9362187	1.7008513	3069.5959
993.70117	2.9339197	1.703227	3062.9172
994.70215	2.9405944	1.7059735	3068.0146
995.70313	2.9430804	1.7090114	3065.7214
996.7041	2.9431112	1.7116579	3062.0901
997.70508	2.9469619	1.7139195	3061.4177
998.70605	2.9502289	1.7168262	3066.9526
999.70703	2.9569101	1.7198616	3070.4805
1000.708	2.9546978	1.7230341	3063.0168
1001.709	2.957761	1.7261344	3059.9897
1002.71	2.962857	1.7290072	3063.4495
1003.7109	2.9691844	1.731673	3061.9524
1004.7119	2.9683478	1.7340451	3063.3962
1005.7129	2.9724047	1.7362478	3055.9219
1006.7139	2.976459	1.7386497	3057.3691
1007.7148	2.9757953	1.7409127	3052.5344
1008.7158	2.9817235	1.7434359	3060.1438
1009.7168	2.9826071	1.7458156	3055.302
1010.7178	2.9864976	1.7482977	3059.1841
1011.7188	2.9900351	1.7508912	3055.168
1012.7197	2.9923735	1.7537905	3058.5046
1013.7207	2.9939568	1.7568785	3059.25
1014.7217	2.9995575	1.7597852	3060.6177
1015.7227	3.005971	1.7626793	3060.7031
1016.7236	3.0057588	1.7656605	3063.0298
1017.7246	3.0071659	1.7680594	3053.6145
1018.7256	3.0121481	1.7699126	3046.6516
1019.7266	3.0163019	1.7715474	3046.8811
1020.7275	3.0175142	1.7734298	3061.7554
1021.7285	3.0197315	1.7758696	3062.6785
1022.7295	3.0245323	1.7786127	3057.8337
1023.7305	3.027477	1.7812586	3055.7461
1024.7314	3.0314596	1.7837161	3057.3235
1025.7324	3.0331678	1.78698	3061.0867
1026.7334	3.0366137	1.7904795	3056.8625
1027.7344	3.0379667	1.7936583	3046.854
1028.7354	3.0402546	1.796315	3050.1948
1029.7363	3.0472918	1.7993666	3051.6194
1030.7373	3.0483422	1.8023819	3052.3794
1031.7383	3.0480769	1.8052775	3049.6936
1032.7393	3.0515256	1.8078015	3042.2117
1033.7402	3.0575547	1.8103582	3051.3647
1034.7412	3.0605311	1.8129699	3053.3958
1035.7422	3.0618596	1.8162051	3050.8872
1036.7432	3.0628405	1.8191453	3045.0125
1037.7441	3.0708332	1.8219815	3047.8669
1038.7451	3.0710759	1.8248514	3044.4316
1039.7461	3.0734718	1.8277957	3045.481
1040.7471	3.0760162	1.8305423	3048.7734
1041.748	3.0803559	1.8329931	3042.5212
1042.749	3.0840187	1.8354372	3044.4995
1043.75	3.0855346	1.8385251	3048.5474
1044.751	3.0906453	1.8418003	3050.2529
1045.752	3.0921259	1.8449922	3051.4019
1046.7529	3.0958879	1.8479253	3043.3198
1047.7539	3.1014473	1.8514905	3045.6704
1048.7549	3.1026304	1.8546959	3043.3867
1049.7559	3.1063893	1.8573658	3043.1438
1050.7568	3.1054416	1.8601947	3036.5708
1051.7578	3.1097324	1.8632567	3042.6372
1052.7588	3.1148763	1.8665882	3039.8853
1053.7598	3.1156828	1.869508	3036.1038
1054.7607	3.1183839	1.8726386	3036.5876
1055.7617	3.1226523	1.8757124	3035.0964
1056.7627	3.124917	1.87825	3027.6316
1057.7637	3.1301146	1.8809296	3033.9607
1058.7646	3.1304231	1.8838751	3033.627
1059.7656	3.1346197	1.8867383	3030.3586
1060.7666	3.1385145	1.8894725	3033.6709
1061.7676	3.1397812	1.8924148	3031.4958
1062.7686	3.1420898	1.8955666	3032.9202
1063.7695	3.1483018	1.8986279	3031.1858
1064.7705	3.1467965	1.9018555	3031.2314
1065.7715	3.1533458	1.9054474	3028.6721
1066.7725	3.1566525	1.9086413	3024.6243
1067.7734	3.1586411	1.911581	3022.7869
1068.7744	3.1620328	1.9142966	3023.9414
1069.7754	3.1672745	1.917281	3031.928
1070.7764	3.16752	1.9198772	3025.1204
1071.7773	3.1717703	1.9226567	3027.3672
1072.7783	3.1726918	1.9254345	3024.3235
1073.7793	3.1753321	1.9283181	3025.6411
1074.7803	3.1807361	1.9316473	3024.3408
1075.7813	3.1827447	1.9346889	3014.7468
1076.7822	3.1868184	1.9375286	3019.2307
1077.7832	3.1872134	1.9405313	3015.3362
1078.7842	3.1921699	1.9436547	3026.4724
1079.7852	3.1962829	1.9469981	3022.0535
1080.7861	3.1968324	1.9498017	3019.752
1081.7871	3.2013979	1.952516	3009.8447
1082.7881	3.2017229	1.9553229	3013.6321
1083.7891	3.2056048	1.9583133	3014.512
1084.79	3.2085178	1.9612724	3011.5122
1085.791	3.2106731	1.9642178	3009.031
1086.792	3.2138319	1.9672573	3013.2949
1087.793	3.2187879	1.9699792	3012.8645
1088.7939	3.2217255	1.972566	3009.4822
1089.7949	3.2252362	1.9758661	3007.5295
1090.7959	3.2268817	1.9789613	3005.7817
1091.7969	3.2294972	1.982111	3003.2974
1092.7979	3.2372971	1.9853705	3006.2136
1093.7988	3.2373636	1.9887363	3002.2969
1094.7998	3.2383423	1.9916619	2998.717
1095.8008	3.2420089	1.9947989	2997.7751
1096.8018	3.2454188	1.9979913	3002.5437
1097.8027	3.2491813	2.0017295	3003.3521
1098.8037	3.2519104	2.0051181	2996.4199
1099.8047	3.254123	2.0081851	2994.1777
1100.8057	3.257901	2.0115182	2996.874
1101.8066	3.2593067	2.0141604	2986.7346
1102.8076	3.2655509	2.0168872	2991.9602
1103.8086	3.2675474	2.0199931	2997.498
1104.8096	3.2682757	2.0233936	2988.7278
1105.8105	3.2699177	2.0263431	2986.3401
1106.8115	3.2741866	2.0291591	2980.115
1107.8125	3.2778261	2.0322509	2983.4031
1108.8135	3.2807117	2.03546	2983.7998
1109.8145	3.2838459	2.0388916	2983.0347
1110.8154	3.2874408	2.0417545	2981.4226
1111.8164	3.2938285	2.0444598	2985.5183
1112.8174	3.2909396	2.0472929	2978.9265
1113.8184	3.2967217	2.0490499	2971.2576
1114.8193	3.30146	2.0505085	2981.481
1115.8203	3.302115	2.0515151	2980.8403
1116.8213	3.3038626	2.0519764	2970.5659
1117.8223	3.3109	2.0524631	2972.0649
1118.8232	3.3109219	2.0526524	2970.2402
1119.8242	3.3142662	2.0530798	2974.5288
1120.8252	3.3176405	2.0531621	2970.5803
1121.8262	3.3177314	2.0533381	2967.2949
1122.8271	3.3230906	2.0536859	2966.6714
1123.8281	3.3273282	2.0535409	2964.3975
1124.8291	3.3298666	2.0536907	2962.5728
1125.8301	3.332978	2.0538545	2959.6704
1126.8311	3.3334987	2.0537782	2964.1624
1127.832	3.3365662	2.0538623	2960.5115
1128.833	3.3451493	2.0542307	2959.7117
1129.834	3.3441153	2.0541294	2955.5249
1130.835	3.3479049	2.0541277	2955.5613
1131.8359	3.3482311	2.0544341	2947.5186
1132.8369	3.3532348	2.0544333	2953.1641
1133.8379	3.3597121	2.0541558	2954.5586
1134.8389	3.3571918	2.0544822	2939.5308
1135.8398	3.3656497	2.0543156	2942.2566
1136.8408	3.368001	2.0541213	2953.5039
1137.8418	3.3665268	2.0541949	2943.5759
1138.8428	3.3685081	2.0541267	2941.7141
1139.8438	3.3755546	2.0541751	2942.7085
1140.8447	3.37854	2.0540576	2934.9314
1141.8457	3.3814931	2.0537736	2939.5093
1142.8467	3.3818698	2.0542073	2935.2236
1143.8477	3.3847318	2.054112	2930.4187
1144.8486	3.3882091	2.05373	2927.1643
1145.8496	3.3928909	2.0541227	2927.7202
1146.8506	3.3944418	2.0537837	2926.1353
1147.8516	3.3993082	2.0537839	2924.2302
1148.8525	3.4027855	2.053818	2914.2954
1149.8535	3.4077549	2.0537279	2922.9619
1150.8545	3.407136	2.0540595	2915.7373
1151.8555	3.4085531	2.053699	2914.4626
1152.8564	3.4141886	2.0538306	2913.5457
1153.8574	3.4186063	2.0540335	2913.259
1154.8584	3.4223373	2.0541239	2907.552
1155.8594	3.4234071	2.0540907	2904.7209
1156.8604	3.4259868	2.05406	2909.7458
1157.8613	3.4277699	2.0543351	2900.8228
1158.8623	3.4327059	2.0540714	2905.5964
1159.8633	3.43645	2.054353	2896.1274
1160.8643	3.43787	2.0540292	2900.9507
1161.8652	3.4404471	2.0540259	2894.502
1162.8662	3.4439743	2.0541701	2891.7231
1163.8672	3.4463227	2.0541008	2884.7358
1164.8682	3.4514256	2.0543215	2884.0488
1165.8691	3.4520285	2.0541174	2884.5063
1166.8701	3.457087	2.0540924	2876.9307
1167.8711	3.4582088	2.0542669	2879.8044
1168.8721	3.4637437	2.0538707	2880.0847
1169.873	3.4637508	2.0543334	2878.9048
1170.874	3.4697623	2.0540149	2870.5247
1171.875	3.4710293	2.0540178	2866.2986
1172.876	3.4737296	2.0540044	2870.1821
1173.877	3.4775674	2.0540321	2862.3599
1174.8779	3.4805706	2.0539892	2860.7822
1175.8789	3.4834731	2.0541387	2863.4375
1176.8799	3.4858704	2.0542762	2859.9465
1177.8809	3.4897876	2.0543039	2859.6208
1178.8818	3.4905934	2.0540915	2850.76
1179.8828	3.4944587	2.0541062	2845.9866
1180.8838	3.4966154	2.0540524	2849.9893
1181.8848	3.4986577	2.0537193	2842.491
1182.8857	3.5015836	2.0538836	2842.0659
1183.8867	3.5068145	2.0536397	2840.2407
1184.8877	3.5093191	2.0539355	2838.4827
1185.8887	3.5127628	2.0540497	2833.374
1186.8896	3.5150194	2.0539756	2830.25
1187.8906	3.5175741	2.054039	2826.9126
1188.8916	3.5217173	2.0537262	2823.1863
1189.8926	3.5243628	2.0538731	2828.2351
1190.8936	3.5266657	2.0539508	2816.8882
1191.8945	3.5319715	2.0539408	2820.5779
1192.8955	3.5333602	2.0539768	2808.7822
1193.8965	3.5372694	2.0538831	2804.7563
1194.8975	3.5384016	2.053992	2799.6658
1195.8984	3.5467405	2.0539494	2807.1523
1196.8994	3.5472968	2.0540984	2796.8765
1197.9004	3.5505111	2.0538423	2797.7739
1198.9014	3.5518172	2.0540648	2788.551
1199.9023	3.5551658	2.0537891	2793.2424
1200.9033	3.5566559	2.0538626	2789.2095
1201.9043	3.5615776	2.0541198	2772.6848
1202.9053	3.562957	2.0537963	2775.5281
1203.9063	3.5677066	2.0539875	2771.5686
1204.9072	3.5716255	2.0539353	2771.1448
1205.9082	3.5712144	2.054018	2773.0789
1206.9092	3.5771461	2.053721	2765.3528
1207.9102	3.5789475	2.0539029	2761.3628
1208.9111	3.5836811	2.053834	2754.792
1209.9121	3.5840664	2.0538926	2748.3823
1210.9131	3.5869124	2.0540774	2745.5791
1211.9141	3.592783	2.0539682	2744.9524
1212.915	3.5967627	2.0539551	2750.5159
1213.916	3.5968709	2.0542965	2742.6611
1214.917	3.6014843	2.0538514	2737.1313
1215.918	3.6055083	2.0540867	2737.3472
1216.9189	3.6084981	2.0540602	2730.3313
1217.9199	3.6088679	2.05392	2716.8804
1218.9209	3.6107726	2.0540535	2713.9131
1219.9219	3.6198995	2.0536449	2715.1392
1220.9229	3.6178112	2.0539019	2712.7732
1221.9238	3.6179268	2.05407	2700.908
1222.9248	3.6232371	2.0540092	2693.9792
1223.9258	3.6251335	2.0541794	2688.0774
1224.9268	3.6297517	2.0538692	2677.8965
1225.9277	3.6326289	2.0539467	2670.4373
1226.9287	3.6364822	2.0540612	2668.9736
1227.9297	3.6388974	2.0539544	2663.9233
1228.9307	3.6408374	2.0535438	2643.874
1229.9316	3.6456571	2.0534585	2636.7085
1230.9326	3.6474154	2.0536609	2625.0408
1231.9336	3.6511021	2.0537648	2612.0735
1232.9346	3.6550608	2.0536945	2601.5488
1233.9355	3.6594696	2.0537174	2585.2988
1234.9365	3.6623824	2.0537698	2560.3826
1235.9375	3.6677549	2.0537572	2504.948