File: datasets/am_bench_2022/raw_data/30-XY.18-1/specimen.dat
MTS793|MPT|ENU|1|2|.|/|:|1|0|0|A

Operator Information						Time:	23.451172	Sec	10/18/2021 2:34:36 PM
Operator	Nick Derimow
Project	AM Bench 2022 mini-tensile challenge
Specimen ID	30-XY.18-1
Material	PBF-L Inconel 625
Specimen Width	2.54	mm
Specimen Thickness	1.5	mm
Notes
Operator Information End

Data Acquisition						Time:	1024.4446	Sec	10/18/2021 2:51:17 PM
Time	Axial Displacement	Axial Extensometer	Axial Force
Sec	mm	mm	N
23.564453	-0.00072817516	6.2993866e-05	70.850922
24.56543	0.0062189605	5.6002984e-05	87.76754
25.566406	0.0049318355	0.00016232705	100.3542
26.567383	0.0076597026	0.00025522051	115.04445
27.568359	0.01308665	0.00026357188	125.81853
28.569336	0.01221115	0.00021773367	133.71097
29.570313	0.018297743	0.00027751265	146.67174
30.571289	0.022283232	0.00042868225	158.66721
31.572266	0.022387112	0.00037851365	169.52995
32.573242	0.027985705	0.00050731527	189.15837
33.574219	0.027039723	0.00069492677	205.96046
34.575195	0.033847738	0.0006342883	225.26137
35.576172	0.036112193	0.00080153567	243.93585
36.577148	0.03804329	0.00089518924	265.12289
37.578125	0.043083761	0.00093461439	288.09314
38.579102	0.04635746	0.0010159919	303.9838
39.580078	0.047678955	0.0010666	319.6152
40.581055	0.051021136	0.0010896493	340.97369
41.582031	0.051986787	0.0012592559	357.95029
42.583008	0.055414971	0.0013919915	380.09128
43.583984	0.059285104	0.0014881007	392.38635
44.584961	0.061655439	0.0014324359	411.35245
45.585938	0.065476038	0.0015858982	446.33069
46.586914	0.06789083	0.0016606373	459.74423
47.587891	0.07098525	0.0018527779	491.55151
48.588867	0.073974356	0.0019007623	516.30914
49.589844	0.077984683	0.0020978367	548.08704
50.59082	0.080098338	0.0021907291	566.43304
51.591797	0.079501696	0.0022656487	593.71185
52.592773	0.08258833	0.0023498824	615.20111
53.59375	0.090307698	0.0024576867	640.4549
54.594727	0.091833726	0.0025849629	666.06335
55.595703	0.095564537	0.0026865767	691.76074
56.59668	0.097787961	0.0027498091	714.63654
57.597656	0.09769883	0.0028197414	733.43665
58.598633	0.10232931	0.0030625137	763.41479
59.599609	0.10696641	0.0032035145	790.69269
60.600586	0.10922815	0.003224774	818.18823
61.601563	0.11069394	0.0033724972	843.82263
62.602539	0.1173028	0.0035055862	872.32245
63.603516	0.1181701	0.0036308586	902.34943
64.604492	0.12272334	0.0037599839	934.20062
65.605469	0.12312923	0.0038049647	953.16718
66.606445	0.12657073	0.0039637121	980.4541
67.607422	0.13134547	0.0041644131	1007.3105
68.608398	0.13251559	0.0043220008	1039.5211
69.609375	0.13668896	0.0044417465	1064.1747
70.610352	0.14022902	0.0046175327	1092.5055
71.611328	0.14243831	0.0047180336	1127.5176
72.612305	0.14593887	0.0048169345	1163.3391
73.613281	0.14832641	0.0049984199	1186.7098
74.614258	0.15318905	0.0050425902	1212.3369
75.615234	0.15442941	0.0052157864	1242.343
76.616211	0.15628673	0.0053653764	1270.9187
77.617188	0.1617417	0.0055231065	1307.5571
78.618164	0.16552968	0.0057183993	1342.7765
79.619141	0.16768596	0.0057602902	1354.9519
80.620117	0.16855524	0.0059422194	1385.6002
81.621094	0.17230681	0.0060316818	1414.4547
82.62207	0.17565733	0.0061096912	1434.192
83.623047	0.17778698	0.0063300235	1462.719
84.624023	0.17913142	0.0064450824	1492.1598
85.625	0.18288231	0.0065702479	1524.6907
86.625977	0.18742843	0.0066830148	1548.653
87.626953	0.19032963	0.0068209004	1582.7572
88.62793	0.19126189	0.0069850376	1604.8571
89.628906	0.19437413	0.007175169	1637.438
90.629883	0.19979712	0.0072515607	1663.4681
91.630859	0.20109777	0.0073499144	1679.5743
92.631836	0.20622773	0.0074738641	1708.5426
93.632813	0.20767283	0.0075327009	1730.8136
94.633789	0.21396866	0.0077932943	1761.9791
95.634766	0.21468456	0.0079020523	1784.3641
96.635742	0.21883513	0.0079955393	1807.2156
97.636719	0.22276632	0.0080715418	1831.9938
98.637695	0.2228657	0.008273663	1859.3047
99.638672	0.22539139	0.0083047375	1872.2386
100.63965	0.22850077	0.0085306959	1896.1614
101.64063	0.23369838	0.0086947298	1929.0287
102.6416	0.23548253	0.0088408403	1948.1337
103.64258	0.23646621	0.0088946354	1967.2897
104.64355	0.24293129	0.009019969	1991.7352
105.64453	0.2466961	0.0091148131	2009.866
106.64551	0.24454603	0.0092809359	2029.0902
107.64648	0.24876709	0.0093953181	2053.1316
108.64746	0.25471139	0.0095672561	2070.6433
109.64844	0.25768	0.0097949822	2093.2805
110.64941	0.25730506	0.0097476486	2110.7427
111.65039	0.2626102	0.0099323848	2123.3638
112.65137	0.2647011	0.010053002	2144.6895
113.65234	0.26867083	0.010275724	2162.3855
114.65332	0.27050418	0.010296184	2178.8889
115.6543	0.27491829	0.010495717	2201.6072
116.65527	0.27919289	0.010570849	2209.3706
117.65625	0.28233442	0.010706384	2227.0188
118.65723	0.28479558	0.010796584	2240.5198
119.6582	0.28990567	0.010931334	2259.3452
120.65918	0.28914592	0.011116021	2270.8943
121.66016	0.29539403	0.011169821	2289.0337
122.66113	0.29603022	0.01133604	2295.8696
123.66211	0.29925025	0.01143393	2308.3877
124.66309	0.29969832	0.011580443	2326.2981
125.66406	0.30379793	0.011636209	2338.9524
126.66504	0.30680636	0.011777038	2347.3105
127.66602	0.30964938	0.011913944	2359.2825
128.66699	0.31446773	0.012032107	2380.8623
129.66797	0.3167811	0.012245523	2386.5178
130.66895	0.32219127	0.012263635	2398.9111
131.66992	0.32411104	0.012446838	2407.9883
132.6709	0.32730728	0.012590823	2424.8953
133.67188	0.32980075	0.012763851	2432.7471
134.67285	0.33387807	0.01288703	2443.3201
135.67383	0.33418378	0.013039267	2455.4033
136.6748	0.33764249	0.01321729	2466.4402
137.67578	0.341277	0.013367637	2478.9949
138.67676	0.34592	0.013455248	2485.0447
139.67773	0.34914511	0.013616171	2501.4065
140.67871	0.350824	0.013772379	2509.2671
141.67969	0.35524201	0.013963773	2510.4502
142.68066	0.35453227	0.014119156	2528.4404
143.68164	0.36171448	0.01424332	2529.7332
144.68262	0.36240494	0.014424489	2540.8259
145.68359	0.36622873	0.014635275	2550.2263
146.68457	0.37103215	0.014651162	2561.533
147.68555	0.37191892	0.014898269	2564.22
148.68652	0.37401721	0.015100995	2573.1797
149.6875	0.37499166	0.015272602	2585.4197
150.68848	0.38415423	0.015421502	2592.9324
151.68945	0.38909683	0.01563595	2606.6035
152.69043	0.38685122	0.015830431	2609.5146
153.69141	0.39043674	0.01601713	2620.0061
154.69238	0.39114895	0.016331187	2636.3032
155.69336	0.39815736	0.016702821	2643.2141
156.69434	0.39869642	0.016795112	2650.8032
157.69531	0.40401062	0.017156221	2656.5884
158.69629	0.40507135	0.017312791	2656.9426
159.69727	0.40964603	0.017598752	2669.7935
160.69824	0.41316813	0.017842904	2682.2698
161.69922	0.41115713	0.018142816	2678.8413
162.7002	0.41775721	0.018446621	2695.7678
163.70117	0.41738433	0.018745894	2699.0847
164.70215	0.42339858	0.019070864	2708.501
165.70313	0.4267754	0.019342776	2710.2307
166.7041	0.42826617	0.019668987	2721.1128
167.70508	0.43123767	0.020098675	2732.2056
168.70605	0.4340145	0.020471986	2735.5339
169.70703	0.43795368	0.020884296	2735.926
170.70801	0.44096538	0.021407176	2755.4905
171.70898	0.44583088	0.02180713	2760.1504
172.70996	0.44506231	0.022273688	2762.3979
173.71094	0.44802213	0.022688201	2760.7573
174.71191	0.45429173	0.023260335	2779.8066
175.71289	0.45568806	0.023677628	2779.7363
176.71387	0.46039185	0.024155322	2793.3167
177.71484	0.4612895	0.024821399	2795.8801
178.71582	0.46739683	0.025257841	2800.2178
179.7168	0.46859235	0.02579408	2804.2029
180.71777	0.47071335	0.026518987	2813.1099
181.71875	0.47671613	0.027179996	2813.7073
182.71973	0.47790408	0.027776994	2821.4722
183.7207	0.47826469	0.028477972	2825.4941
184.72168	0.48410323	0.029024435	2830.6584
185.72266	0.48849827	0.029735005	2840.4402
186.72363	0.48903081	0.030341381	2835.96
187.72461	0.49476829	0.031111827	2847.2087
188.72559	0.49300787	0.031721499	2845.7563
189.72656	0.49713311	0.032458931	2860.6636
190.72754	0.50245202	0.033216629	2855.5667
191.72852	0.50486499	0.033835124	2861.3792
192.72949	0.50768876	0.034702651	2869.0627
193.73047	0.51308352	0.035394415	2868.436
194.73145	0.51445907	0.036116585	2870.8728
195.73242	0.51694584	0.036989439	2880.5217
196.7334	0.51799709	0.037943367	2884.6843
197.73438	0.52199352	0.038943172	2887.3687
198.73535	0.52589005	0.0398435	2891.9863
199.73633	0.52846122	0.040798213	2890.2197
200.7373	0.53068054	0.041655742	2899.887
201.73828	0.53521353	0.042555027	2905.5825
202.73926	0.53597206	0.043674652	2900.6458
203.74023	0.54021937	0.04466971	2914.4661
204.74121	0.54513949	0.045724314	2907.2437
205.74219	0.54845077	0.046672527	2917.7048
206.74316	0.54997432	0.047746792	2917.7021
207.74414	0.55282676	0.048765529	2925.3726
208.74512	0.5545091	0.049824644	2924.3848
209.74609	0.5594393	0.050729088	2927.511
210.74707	0.56067175	0.051927023	2933.2842
211.74805	0.56877548	0.053057902	2938.4519
212.74902	0.57060128	0.054009926	2935.2322
213.75	0.57155418	0.054965928	2936.752
214.75098	0.57472384	0.055990335	2944.6414
215.75195	0.57531083	0.05705611	2944.4329
216.75293	0.58037382	0.058187928	2945.627
217.75391	0.58170336	0.059495177	2952.7949
218.75488	0.58263844	0.060618713	2950.137
219.75586	0.5847922	0.061604492	2949.4204
220.75684	0.59435028	0.062757485	2959.3301
221.75781	0.59758031	0.063850701	2966.3303
222.75879	0.59783584	0.064870514	2962.8535
223.75977	0.60218364	0.066125214	2972.7285
224.76074	0.60409158	0.067049742	2972.0112
225.76172	0.60769182	0.068240851	2972.9839
226.7627	0.61001116	0.069343001	2973.3711
227.76367	0.61307079	0.070403889	2972.3447
228.76465	0.6172415	0.071551166	2979.6104
229.76563	0.61661988	0.072626464	2976.7441
230.7666	0.62083036	0.073822528	2981.6934
231.76758	0.62584823	0.075123407	2983.6357
232.76855	0.62931824	0.076144308	2981.8186
233.76953	0.62823153	0.077247813	2991.2268
234.77051	0.63279378	0.078565583	2991.0862
235.77148	0.638044	0.079684652	2996.0044
236.77246	0.64202505	0.080977134	2997.54
237.77344	0.64111573	0.08216653	2999.2007
238.77441	0.6457634	0.083692096	3011.2578
239.77539	0.64731628	0.085155204	3002.1797
240.77637	0.6525321	0.086303979	3001.501
241.77734	0.65708476	0.087475516	3009.2087
242.77832	0.6602636	0.08872392	3013.2764
243.7793	0.66093588	0.089837581	3015.9971
244.78027	0.6646632	0.091034055	3010.9685
245.78125	0.666659	0.092148453	3012.2844
246.78223	0.67156976	0.093154028	3017.7573
247.7832	0.67491698	0.094210878	3022.0271
248.78418	0.67553538	0.09554483	3025.0889
249.78516	0.68134481	0.096853532	3027.3367
250.78613	0.68236148	0.098229259	3027.6145
251.78711	0.68525529	0.099565081	3026.9753
252.78809	0.68866771	0.10065961	3028.9565
253.78906	0.68970954	0.10168753	3026.2646
254.79004	0.69508135	0.10275991	3027.5422
255.79102	0.70138681	0.10385751	3038.0049
256.79199	0.70109934	0.10498632	3036.7268
257.79297	0.70589757	0.10617599	3034.1055
258.79395	0.70636517	0.10728221	3037.0823
259.79492	0.708269	0.10864964	3040.9421
260.7959	0.71162081	0.10995335	3045.718
261.79688	0.71342832	0.11118686	3042.5115
262.79785	0.71700853	0.11250208	3043.5659
263.79883	0.72367913	0.11361369	3048.272
264.7998	0.72573799	0.11480163	3047.0583
265.80078	0.72782749	0.11614154	3056.3989
266.80176	0.72881359	0.11736566	3048.1941
267.80273	0.73117906	0.11857761	3049.4055
268.80371	0.73438513	0.11969412	3057.6238
269.80469	0.73836535	0.12096738	3060.4216
270.80566	0.73883921	0.12218192	3057.1611
271.80664	0.74726874	0.12316567	3062.8916
272.80762	0.74755287	0.12444673	3064.2068
273.80859	0.75160503	0.12586048	3074.9111
274.80957	0.75454575	0.12734742	3064.4333
275.81055	0.75895572	0.12858984	3066.8313
276.81152	0.75830954	0.12999912	3069.5554
277.8125	0.76227146	0.13106178	3070.3894
278.81348	0.76818031	0.13231769	3074.2053
279.81445	0.77080655	0.13369739	3085.7097
280.81543	0.7704863	0.13501942	3075.5857
281.81641	0.77498567	0.13643056	3079.3396
282.81738	0.77884632	0.13767481	3084.0168
283.81836	0.77889735	0.13886549	3081.1892
284.81934	0.78121322	0.14007403	3079.1575
285.82031	0.7866407	0.14119315	3086.844
286.82129	0.79033816	0.14265001	3095.5088
287.82227	0.79326522	0.14412759	3088.7979
288.82324	0.79725194	0.14508536	3081.5999
289.82422	0.79720682	0.1460568	3083.3862
290.8252	0.80204839	0.14703369	3093.2617
291.82617	0.80397862	0.14823943	3090.5339
292.82715	0.80741501	0.14950496	3097.0129
293.82813	0.81197727	0.15067494	3092.3252
294.8291	0.81042397	0.15188305	3094.8394
295.83008	0.81654835	0.15319251	3102.1802
296.83105	0.81909531	0.15440412	3095.9888
297.83203	0.82288063	0.15556511	3100.0281
298.83301	0.82945037	0.15676446	3108.7183
299.83398	0.82882154	0.15803896	3106.4248
300.83496	0.83037585	0.15921874	3105.5728
301.83594	0.83640939	0.16063301	3105.5322
302.83691	0.84023178	0.16189274	3114.498
303.83789	0.84123164	0.16309616	3109.4758
304.83887	0.84222662	0.16426647	3108.3235
305.83984	0.84504324	0.16553293	3119.0869
306.84082	0.84942901	0.16681729	3120.6843
307.8418	0.85327989	0.16789426	3113.7749
308.84277	0.85807639	0.16913657	3122.2024
309.84375	0.86007547	0.17058887	3130.2139
310.84473	0.86297667	0.17211899	3124.093
311.8457	0.86538702	0.17337592	3122.0344
312.84668	0.87044185	0.17464279	3128.4063
313.84766	0.87049836	0.17579608	3127.4243
314.84863	0.8730951	0.17688417	3123.853
315.84961	0.87602794	0.17817427	3128.0864
316.85059	0.88042009	0.17950514	3133.7761
317.85156	0.88357109	0.18075296	3128.4473
318.85254	0.88661897	0.18204689	3131.4443
319.85352	0.89132327	0.18324585	3134.8672
320.85449	0.89204878	0.18440028	3140.3457
321.85547	0.89532471	0.18572484	3140.5195
322.85645	0.89769405	0.18708307	3136.0366
323.85742	0.90466458	0.18850343	3147.8784
324.8584	0.90559971	0.18958622	3137.7935
325.85938	0.90678102	0.19089811	3146.4866
326.86035	0.90821546	0.19210841	3141.1755
327.86133	0.91383785	0.19324423	3146.5364
328.8623	0.91614717	0.19434689	3147.3071
329.86328	0.91903424	0.19554004	3154.9153
330.86426	0.92120498	0.1966251	3151.261
331.86523	0.92456627	0.19798711	3151.321
332.86621	0.9299888	0.19906825	3155.4954
333.86719	0.92822987	0.20035587	3155.8975
334.86816	0.93617564	0.20188108	3163.3152
335.86914	0.93745863	0.20304845	3154.4138
336.87012	0.93846714	0.20432302	3156.9185
337.87109	0.94161195	0.20550303	3157.7104
338.87207	0.94469959	0.20685613	3160.1143
339.87305	0.94894511	0.20822132	3165.1411
340.87402	0.95137101	0.20936126	3165.0591
341.875	0.95472747	0.21039522	3161.5151
342.87598	0.95883977	0.21166116	3167.9497
343.87695	0.96247822	0.21285181	3170.906
344.87793	0.96483749	0.21397018	3165.3801
345.87891	0.96853739	0.21537903	3181.7524
346.87988	0.96944523	0.21678786	3173.1218
347.88086	0.97315329	0.21800135	3170.0344
348.88184	0.97740167	0.21906354	3174.6829
349.88281	0.98297977	0.22034964	3180.7939
350.88379	0.98720354	0.22169556	3184.3899
351.88477	0.98655856	0.22278126	3178.5979
352.88574	0.98813349	0.22390701	3179.2815
353.88672	0.99267185	0.22501862	3183.626
354.8877	0.99506164	0.22623847	3188.0894
355.88867	0.99783009	0.22785538	3191.0117
356.88965	1.0021453	0.2290619	3183.0068
357.89063	1.0019552	0.23026007	3185.4907
358.8916	1.0031619	0.23122717	3180.9429
359.89258	1.0100048	0.23251911	3190.9111
360.89355	1.0125592	0.23369217	3184.3564
361.89453	1.013726	0.23477209	3184.2485
362.89551	1.0141106	0.23562756	3180.8057
363.89648	1.0189691	0.23658641	3189.105
364.89746	1.0240265	0.2378706	3196.6643
365.89844	1.0294385	0.23917946	3198.7922
366.89941	1.0303793	0.24063261	3206.3799
367.90039	1.0347617	0.2421633	3200.2207
368.90137	1.0375617	0.24328999	3200.1331
369.90234	1.0387247	0.24456471	3202.2251
370.90332	1.0409368	0.2457082	3200.4976
371.9043	1.0472224	0.24690394	3207.2534
372.90527	1.0479145	0.24792331	3202.1919
373.90625	1.0485981	0.24929126	3204.2563
374.90723	1.053618	0.25045356	3205.5542
375.9082	1.056461	0.25143403	3206.1177
376.90918	1.0580864	0.25275055	3213.7007
377.91016	1.0614429	0.25406161	3207.6494
378.91113	1.0676862	0.25516182	3210.655
379.91211	1.0683634	0.25628513	3218.0928
380.91309	1.0722344	0.25753871	3220.5681
381.91406	1.0752481	0.25887039	3219.5933
382.91504	1.077363	0.26024508	3223.697
383.91602	1.0840135	0.2615439	3223.4792
384.91699	1.0838357	0.26286116	3217.9917
385.91797	1.0891713	0.26414651	3218.4561
386.91895	1.0902967	0.2652759	3219.1074
387.91992	1.0928324	0.26638392	3224.3445
388.9209	1.0975752	0.26790172	3232.0732
389.92188	1.0977436	0.26928326	3223.8784
390.92285	1.1040993	0.27038777	3227.7207
391.92383	1.1067311	0.27145055	3225.7573
392.9248	1.1107517	0.27265871	3230.135
393.92578	1.1124518	0.27376765	3225.7085
394.92676	1.117198	0.27478245	3230.126
395.92773	1.1167405	0.27614847	3236.7102
396.92871	1.1195198	0.27750769	3228.3203
397.92969	1.1246634	0.27870038	3238.7173
398.93066	1.1271152	0.28008935	3238.657
399.93164	1.1283425	0.28136632	3234.8792
400.93262	1.131439	0.28260696	3242.0442
401.93359	1.1356277	0.28368512	3239.9578
402.93457	1.1396561	0.28497615	3241.1194
403.93555	1.1417345	0.28601822	3245.0513
404.93652	1.143551	0.287173	3243.4114
405.9375	1.1459973	0.28849077	3239.842
406.93848	1.1518126	0.28953585	3250.2783
407.93945	1.1529855	0.29065087	3247.0132
408.94043	1.1553683	0.29181066	3247.322
409.94141	1.1582484	0.29291093	3248.3916
410.94238	1.1627742	0.29410395	3245.304
411.94336	1.1640886	0.29523712	3251.3501
412.94434	1.1734545	0.29645598	3257.0815
413.94531	1.171479	0.29782039	3254.9854
414.94629	1.1755271	0.29911998	3256.9802
415.94727	1.1758672	0.30033907	3256.3142
416.94824	1.1837401	0.30151284	3260.2661
417.94922	1.1841829	0.30264577	3256.418
418.9502	1.1831276	0.30391583	3259.9336
419.95117	1.1887131	0.30515411	3256.5063
420.95215	1.1903892	0.30631083	3255.6313
421.95313	1.196324	0.30745217	3263.0422
422.9541	1.1998066	0.30847356	3266.7947
423.95508	1.1993372	0.30973363	3264.8621
424.95605	1.2045518	0.31102261	3269.6172
425.95703	1.2071445	0.312363	3271.0605
426.95801	1.211311	0.31352675	3267.0793
427.95898	1.2130184	0.31484798	3268.8147
428.95996	1.2174346	0.31603196	3272.7922
429.96094	1.2176106	0.31731814	3271.113
430.96191	1.2242999	0.31844631	3273.1582
431.96289	1.2267724	0.31978783	3280.8428
432.96387	1.2280366	0.32095996	3275.1868
433.96484	1.2329319	0.32230204	3278.9636
434.96582	1.2345449	0.32316458	3275.4663
435.9668	1.2366854	0.32420012	3278.7537
436.96777	1.2417881	0.32518548	3275.2634
437.96875	1.2443769	0.32606629	3277.6167
438.96973	1.2470925	0.32709622	3276.1707
439.9707	1.2501353	0.32821068	3280.9253
440.97168	1.2521482	0.32959995	3285.2793
441.97266	1.258891	0.33063558	3286.2007
442.97363	1.2584919	0.3318859	3286.2141
443.97461	1.2641214	0.33305365	3288.3796
444.97559	1.2664393	0.33428174	3287.4436
445.97656	1.2683562	0.33552432	3291.4299
446.97754	1.2738167	0.33664119	3299.6411
447.97852	1.2746861	0.3378422	3293.949
448.97949	1.2778698	0.33897704	3294.5798
449.98047	1.2806405	0.3402977	3294.5889
450.98145	1.2845718	0.34146821	3292.6785
451.98242	1.2865565	0.34279546	3298.6506
452.9834	1.2882392	0.34410536	3299.0833
453.98438	1.2909647	0.34533384	3300.8403
454.98535	1.2957115	0.34657201	3299.5303
455.98633	1.2946533	0.34778789	3297.8999
456.9873	1.29984	0.34906045	3297.9241
457.98828	1.3023545	0.35019648	3297.4177
458.98926	1.3076332	0.35126084	3305.7275
459.99023	1.3116385	0.35253069	3304.647
460.99121	1.3135757	0.35365677	3298.9595
461.99219	1.3178179	0.35460132	3304.009
462.99316	1.3187392	0.35564822	3303.7793
463.99414	1.3223348	0.35701486	3308.1245
464.99512	1.3246325	0.35828507	3306.0552
465.99609	1.327566	0.35956466	3308.0798
466.99707	1.3305815	0.36094773	3318.1135
467.99805	1.3362321	0.36221382	3312.3835
468.99902	1.3359779	0.36322856	3304.7998
470	1.342478	0.36427474	3316.8147
471.00098	1.3446136	0.36530769	3318.5295
472.00195	1.3432239	0.36648038	3314.3601
473.00293	1.3509929	0.36779928	3320.9253
474.00391	1.3515263	0.36894578	3321.1755
475.00488	1.353497	0.37014848	3321.2744
476.00586	1.3590211	0.37142146	3319.8174
477.00684	1.3608323	0.37270021	3312.752
478.00781	1.3638669	0.37380368	3315.9414
479.00879	1.3680828	0.37507597	3326.7532
480.00977	1.3713638	0.37645125	3332.3169
481.01074	1.3734328	0.37778032	3330.1458
482.01172	1.3765863	0.37879682	3322.9944
483.0127	1.3776522	0.38000971	3327.1016
484.01367	1.382655	0.3810471	3320.5647
485.01465	1.383689	0.38216126	3326.978
486.01563	1.3891487	0.38332736	3329.2617
487.0166	1.3898466	0.38445571	3328.1675
488.01758	1.3944908	0.38566604	3332.6885
489.01855	1.397361	0.38675979	3334.8672
490.01953	1.4033883	0.38800588	3342.0769
491.02051	1.4014968	0.38919947	3335.1909
492.02148	1.4059713	0.39048839	3335.7996
493.02246	1.4090508	0.39175132	3333.3057
494.02344	1.4103502	0.39283174	3337.675
495.02441	1.4157873	0.39398751	3341.0427
496.02539	1.4176487	0.39494234	3337.2905
497.02637	1.4179282	0.3962087	3333.9602
498.02734	1.4233067	0.39733446	3344.7566
499.02832	1.4282976	0.39870802	3344.9277
500.0293	1.4288057	0.40013072	3343.4583
501.03027	1.435431	0.40140072	3352.7073
502.03125	1.4355202	0.40275919	3349.3442
503.03223	1.4420139	0.40397924	3343.4434
504.0332	1.4398627	0.40514722	3342.2224
505.03418	1.4463575	0.40629736	3348.2227
506.03516	1.4451476	0.40743616	3345.0881
507.03613	1.4535065	0.40863207	3352.5181
508.03711	1.4533231	0.41005877	3348.5432
509.03809	1.4582732	0.4111053	3350.0854
510.03906	1.4626381	0.41218719	3356.2571
511.04004	1.4601197	0.41336662	3351.3623
512.04102	1.4679083	0.41454715	3350.9688
513.04199	1.4667859	0.415674	3347.9299
514.04297	1.4734466	0.41677231	3357.4431
515.04395	1.4754927	0.41802299	3362.3101
516.04492	1.4789352	0.41931596	3360.5002
517.0459	1.4820668	0.42055222	3363.3801
518.04688	1.4846025	0.4217585	3362.8999
519.04785	1.489175	0.4228864	3364.1016
520.04883	1.490821	0.42393634	3361.7427
521.0498	1.4928467	0.42499861	3360.5842
522.05078	1.4945823	0.42603016	3355.8018
523.05176	1.4987255	0.42698854	3365.0415
524.05273	1.5020628	0.42833468	3365.8044
525.05371	1.5056615	0.42968646	3371.032
526.05469	1.5097049	0.43095133	3372.5176
527.05566	1.513105	0.43233976	3372.0916
528.05664	1.5167339	0.43344614	3369.9189
529.05762	1.5177336	0.43464664	3370.0847
530.05859	1.5195988	0.43588182	3370.8906
531.05957	1.5212352	0.43716541	3370.3687
532.06055	1.526956	0.43827951	3371.8618
533.06152	1.5271939	0.43943834	3378.1238
534.0625	1.5309298	0.44070002	3371.0981
535.06348	1.5351722	0.4418503	3376.2188
536.06445	1.5377898	0.44310278	3376.3123
537.06543	1.5415785	0.44429564	3374.1272
538.06641	1.5446414	0.44538325	3380.5815
539.06738	1.5488977	0.44676325	3380.8076
540.06836	1.5508208	0.44788164	3381.2686
541.06934	1.5545644	0.44899219	3380.74
542.07031	1.5576662	0.45004109	3379.5298
543.07129	1.556703	0.45097086	3374.9819
544.07227	1.5625322	0.45214987	3385.4907
545.07324	1.5656676	0.45350787	3390.2068
546.07422	1.5701953	0.45493674	3391.2322
547.0752	1.5700483	0.45612347	3383.1919
548.07617	1.5728029	0.4572311	3382.2329
549.07715	1.5773147	0.45841175	3391.2419
550.07813	1.5814797	0.45971894	3389.4131
551.0791	1.5833434	0.46102417	3390.5952
552.08008	1.5883801	0.46241459	3397.1228
553.08105	1.5894778	0.46365598	3387.6279
554.08203	1.5917592	0.46467483	3396.8774
555.08301	1.5973084	0.4661971	3394.3428
556.08398	1.5993811	0.46727213	3395.6206
557.08496	1.6020558	0.46848252	3394.5959
558.08594	1.6042875	0.46979329	3397.3513
559.08691	1.6074772	0.47104022	3398.9966
560.08789	1.6097646	0.47235301	3403.917
561.08887	1.6129205	0.47368494	3392.1799
562.08984	1.6173813	0.47477633	3399.8586
563.09082	1.6175361	0.47597483	3397.5313
564.0918	1.6215371	0.47701395	3395.9629
565.09277	1.6273381	0.47816041	3400.2334
566.09375	1.6285381	0.47925961	3399.5706
567.09473	1.6317863	0.4801631	3399.4617
568.0957	1.6359816	0.48136997	3404.585
569.09668	1.6346289	0.48274454	3406.9084
570.09766	1.6399072	0.484216	3407.6804
571.09863	1.6452655	0.48537108	3409.8608
572.09961	1.6474041	0.48674861	3411.5881
573.10059	1.6475571	0.48773041	3396.95
574.10156	1.6517279	0.48883674	3406.0449
575.10254	1.6574428	0.49000391	3410.2009
576.10352	1.6551554	0.49120706	3407.5393
577.10449	1.6636206	0.49237448	3410.9016
578.10547	1.6642947	0.49360952	3412.8777
579.10645	1.6651043	0.49478906	3413.7397
580.10742	1.6686442	0.49608135	3413.5952
581.1084	1.6715215	0.49726129	3410.5378
582.10938	1.6766913	0.49833226	3410.0186
583.11035	1.6786746	0.49927109	3414.0715
584.11133	1.6837252	0.50024498	3416.0132
585.1123	1.6853311	0.50125682	3417.8157
586.11328	1.6896724	0.50215006	3414.249
587.11426	1.695376	0.50299215	3423.1174
588.11523	1.6923019	0.50388414	3418.1597
589.11621	1.6965818	0.50489861	3416.3127
590.11719	1.6964419	0.5058127	3416.6489
591.11816	1.7046866	0.50677407	3422.1191
592.11914	1.7092837	0.50785542	3425.3923
593.12012	1.7113066	0.50886029	3429.2378
594.12109	1.7148343	0.50999886	3428.0928
595.12207	1.7177702	0.51106119	3425.5979
596.12305	1.7173039	0.51214123	3425.2368
597.12402	1.7200252	0.51341397	3428.8501
598.125	1.7234725	0.51475233	3433.2021
599.12598	1.7275504	0.51586962	3431.8489
600.12695	1.7311674	0.51682997	3431.3752
601.12793	1.7326173	0.51788342	3426.1375
602.12891	1.7371842	0.51871222	3432.8723
603.12988	1.7368059	0.51966423	3428.5281
604.13086	1.7450602	0.5205999	3427.8777
605.13184	1.7451878	0.52162248	3438.3354
606.13281	1.7494787	0.52280337	3430.0461
607.13379	1.7503971	0.52367485	3431.8396
608.13477	1.751794	0.52489918	3433.9209
609.13574	1.7591149	0.52581918	3430.3562
610.13672	1.7607543	0.52699798	3436.5732
611.1377	1.7653193	0.52835828	3444.3894
612.13867	1.7672491	0.52959758	3431.96
613.13965	1.7712187	0.53073239	3435.0518
614.14063	1.7722756	0.53185958	3437.7598
615.1416	1.7761946	0.53304332	3438.989
616.14258	1.7771522	0.53427458	3439.7549
617.14355	1.7806705	0.53544462	3441.1687
618.14453	1.7854445	0.53698152	3441.147
619.14551	1.7882652	0.53828967	3444.2405
620.14648	1.7896799	0.53950298	3440.1038
621.14746	1.7900869	0.54064858	3440.906
622.14844	1.7949274	0.54180205	3444.5444
623.14941	1.7978454	0.54300362	3440.7014
624.15039	1.8026545	0.54419678	3444.9124
625.15137	1.807861	0.54551667	3453.071
626.15234	1.8079103	0.54675901	3450.2651
627.15332	1.8095033	0.54805106	3445.7219
628.1543	1.8155152	0.54937667	3455.2803
629.15527	1.8167305	0.55086714	3451.0076
630.15625	1.818063	0.5523386	3449.8696
631.15723	1.8219378	0.5540877	3457.5588
632.1582	1.82414	0.55594176	3453.8459
633.15918	1.8300834	0.55743325	3452.2976
634.16016	1.8311707	0.55861473	3450.4233
635.16113	1.8370519	0.56021643	3453.0762
636.16211	1.839431	0.56150305	3455.2903
637.16309	1.8421905	0.56329823	3457.0598
638.16406	1.8421433	0.56466043	3452.3813
639.16504	1.8516822	0.56586152	3454.2832
640.16602	1.8515098	0.56707883	3454.4426
641.16699	1.8539355	0.56843555	3465.3115
642.16797	1.8590075	0.56982023	3457.7126
643.16895	1.859054	0.57105273	3458.2783
644.16992	1.86374	0.57262713	3456.3345
645.1709	1.8637236	0.57375848	3456.8396
646.17188	1.8688526	0.5752309	3468.6709
647.17285	1.8711854	0.57657027	3463.1587
648.17383	1.8724674	0.57790595	3465.2031
649.1748	1.8765521	0.57923114	3461.5361
650.17578	1.8820736	0.58046639	3464.3901
651.17676	1.8808316	0.58175582	3461.4749
652.17773	1.8867939	0.58281434	3464.2834
653.17871	1.8891562	0.58397013	3466.4092
654.17969	1.8922058	0.58517087	3464.5481
655.18066	1.8952787	0.58625704	3470.437
656.18164	1.8976792	0.58731663	3463.1482
657.18262	1.9027407	0.58849686	3474.7969
658.18359	1.9046723	0.5898307	3474.8772
659.18457	1.9105368	0.59116191	3470.438
660.18555	1.9114136	0.59220672	3464.0557
661.18652	1.9131508	0.59341985	3475.2612
662.1875	1.9157025	0.59456336	3468.208
663.18848	1.9203123	0.59572399	3473.575
664.18945	1.9239031	0.59691048	3472.7908
665.19043	1.9252301	0.59823215	3474.0359
666.19141	1.9277208	0.59951574	3472.5181
667.19238	1.9315717	0.60079402	3475.571
668.19336	1.9334487	0.60233331	3479.1787
669.19434	1.9377548	0.60394716	3472.3855
670.19531	1.9406632	0.60563636	3479.3286
671.19629	1.9432514	0.60694927	3478.3926
672.19727	1.9467765	0.60824341	3470.5657
673.19824	1.9490916	0.60943025	3474.4407
674.19922	1.9518964	0.61072963	3474.8914
675.2002	1.9550813	0.61214572	3479.4805
676.20117	1.9577646	0.61353809	3474.2085
677.20215	1.9621105	0.61497921	3476.9158
678.20313	1.9644448	0.61634862	3483.4443
679.2041	1.9656664	0.61774802	3478.438
680.20508	1.9676435	0.61908734	3477.3179
681.20605	1.9752465	0.6202746	3483.2026
682.20703	1.9771516	0.62143868	3481.8921
683.20801	1.9789933	0.62282097	3484.5071
684.20898	1.9812921	0.6243301	3484.3323
685.20996	1.9854072	0.62554806	3479.29
686.21094	1.9867734	0.62670296	3483.1377
687.21191	1.9907435	0.62790227	3481.3027
688.21289	1.9961314	0.62906653	3483.4111
689.21387	1.9976283	0.63019574	3488.1335
690.21484	1.9990833	0.63153833	3482.9668
691.21582	2.0034037	0.63289648	3488.8979
692.2168	2.0073335	0.6342448	3490.2886
693.21777	2.009711	0.6355235	3489.6001
694.21875	2.0087955	0.63700593	3488.2778
695.21973	2.0178928	0.6384964	3491.3149
696.2207	2.0167468	0.63995743	3486.373
697.22168	2.0203559	0.64139491	3488.7422
698.22266	2.0264542	0.64299667	3499.5623
699.22363	2.0243506	0.64411837	3485.4165
700.22461	2.0317791	0.64520216	3491.9368
701.22559	2.0321798	0.64632952	3484.7744
702.22656	2.0364985	0.64740312	3488.2461
703.22754	2.0366616	0.64869034	3491.467
704.22852	2.0399747	0.65017968	3493.8481
705.22949	2.0439761	0.65195864	3500.1387
706.23047	2.0466063	0.65377861	3495.0725
707.23145	2.0482767	0.65504146	3487.9807
708.23242	2.0545843	0.65651983	3502.905
709.2334	2.05808	0.657987	3496.105
710.23438	2.0605388	0.65912259	3496.7239
711.23535	2.0659132	0.66046441	3499.9341
712.23633	2.0665627	0.6617431	3496.907
713.2373	2.0691326	0.66333163	3503.4739
714.23828	2.0720968	0.66481131	3504.6978
715.23926	2.0755162	0.66641927	3504.0376
716.24023	2.0796919	0.66778278	3503.4529
717.24121	2.0843813	0.66913766	3503.8083
718.24219	2.0857058	0.67042965	3505.4038
719.24316	2.0884173	0.67192507	3503.4917
720.24414	2.0913532	0.67324716	3501.3616
721.24512	2.0930777	0.67465228	3505.9692
722.24609	2.0965161	0.67568415	3498.8342
723.24707	2.097815	0.6768893	3502.7026
724.24805	2.1038544	0.67832392	3512.8213
725.24902	2.1059191	0.67986012	3505.106
726.25	2.1094062	0.68103588	3508.709
727.25098	2.1135468	0.68234748	3515.6274
728.25195	2.1146154	0.68370092	3507.7346
729.25293	2.1171832	0.68517745	3505.0742
730.25391	2.1200972	0.68649203	3507.6411
731.25488	2.1210654	0.68789369	3509.1367
732.25586	2.1263151	0.68929315	3506.7402
733.25684	2.1294503	0.69069904	3507.1396
734.25781	2.1321428	0.69206548	3519.1204
735.25879	2.1352127	0.69367605	3507.2515
736.25977	2.1411519	0.69505811	3512.7417
737.26074	2.1411798	0.69656533	3511.4343
738.26172	2.1460159	0.69793516	3511.4626
739.2627	2.1483254	0.69930792	3513.0845
740.26367	2.1514218	0.70076644	3513.7395
741.26465	2.1527486	0.70201308	3513.2625
742.26563	2.160778	0.70335907	3515.2461
743.2666	2.1599891	0.70462829	3518.877
744.26758	2.1626394	0.70601672	3515.1348
745.26855	2.1680758	0.70758533	3518.9441
746.26953	2.1677628	0.70904303	3512.6309
747.27051	2.1713769	0.71031356	3511.6646
748.27148	2.1737478	0.71155196	3512.5449
749.27246	2.1780398	0.71284443	3515.0063
750.27344	2.1817963	0.71430165	3519.644
751.27441	2.1828966	0.71565509	3517.3616
752.27539	2.187202	0.71694332	3510.8672
753.27637	2.1882985	0.71799296	3517.4453
754.27734	2.1936202	0.71925336	3518.8044
755.27832	2.1974435	0.72048861	3522.3796
756.2793	2.1968737	0.72179973	3523.5166
757.28027	2.2039735	0.72333914	3527.6731
758.28125	2.2049005	0.72493708	3518.1245
759.28223	2.2092175	0.72625303	3520.8801
760.2832	2.2082105	0.72776353	3516.9172
761.28418	2.2153518	0.72911584	3523.9856
762.28516	2.2162397	0.73035467	3520.2053
763.28613	2.2201676	0.73159301	3520.3872
764.28711	2.2209549	0.73279715	3521.4556
765.28809	2.2267549	0.73431242	3528.8271
766.28906	2.2265885	0.7359035	3525.4556
767.29004	2.2311294	0.7374807	3527.4243
768.29102	2.2324352	0.73903531	3525.6018
769.29199	2.2418962	0.74056101	3530.2795
770.29297	2.2385859	0.74208921	3523.4956
771.29395	2.2480316	0.74366337	3524.4858
772.29492	2.2446747	0.74491602	3521.2549
773.2959	2.2475972	0.74653852	3523.2332
774.29688	2.250716	0.74777853	3527.3474
775.29785	2.2566013	0.74944168	3532.0288
776.29883	2.2584553	0.75110608	3529.4531
777.2998	2.2600546	0.75264704	3529.0708
778.30078	2.2644875	0.75400954	3526.0481
779.30176	2.2672441	0.75559908	3527.4792
780.30273	2.2709105	0.75698477	3526.3516
781.30371	2.2766376	0.75816625	3528.5442
782.30469	2.2764862	0.75951993	3523.1477
783.30566	2.2794604	0.76095754	3531.1531
784.30664	2.2798765	0.76267159	3535.7651
785.30762	2.2846081	0.76429021	3534.3601
786.30859	2.2904108	0.76588786	3537.0688
787.30957	2.2907152	0.76762748	3533.0967
788.31055	2.2992473	0.76931173	3536.4063
789.31152	2.2984295	0.77101678	3530.9109
790.3125	2.3009217	0.7725904	3531.6245
791.31348	2.3023736	0.77386749	3526.5327
792.31445	2.3085203	0.77537608	3532.2351
793.31543	2.3105826	0.77657562	3528.366
794.31641	2.3138497	0.77780128	3524.9375
795.31738	2.3138664	0.77912998	3524.4495
796.31836	2.3195181	0.78034389	3538.8257
797.31934	2.3214352	0.78171271	3535.5891
798.32031	2.3253977	0.78337312	3533.8689
799.32129	2.3286145	0.78472739	3534.4185
800.32227	2.3314822	0.7863608	3537.8167
801.32324	2.3329701	0.78814834	3533.1721
802.32422	2.3332496	0.78960127	3534.0713
803.3252	2.3409288	0.79139161	3537.6836
804.32617	2.3440576	0.79268366	3536.2278
805.32715	2.3478141	0.79397249	3538.9573
806.32813	2.346741	0.7955386	3532.0171
807.3291	2.3499937	0.79706442	3538.5349
808.33008	2.3556535	0.79872197	3542.4045
809.33105	2.3585923	0.80028218	3533.0698
810.33203	2.3607385	0.80167419	3532.4702
811.33301	2.3633349	0.8029896	3538.8723
812.33398	2.3662372	0.80454642	3536.0491
813.33496	2.3666136	0.8061142	3538.1731
814.33594	2.3735995	0.80757868	3537.0107
815.33691	2.3762069	0.80916369	3546.2642
816.33789	2.381417	0.81095499	3542.134
817.33887	2.3841178	0.81240529	3541.0007
818.33984	2.3826365	0.81392074	3533.4741
819.34082	2.3877692	0.81531912	3537.3799
820.3418	2.3905473	0.81664044	3536.7813
821.34277	2.3944292	0.81818891	3542.5916
822.34375	2.3974726	0.81995797	3540.7566
823.34473	2.3998482	0.82145661	3541.8857
824.3457	2.4032128	0.82291669	3543.3406
825.34668	2.4070454	0.82448494	3545.2776
826.34766	2.4049044	0.82628673	3544.5505
827.34863	2.4136856	0.82778567	3545.2332
828.34961	2.4121454	0.82924086	3535.8254
829.35059	2.4175277	0.83073157	3541.9973
830.35156	2.4206707	0.83198422	3540.7983
831.35254	2.4223306	0.83352119	3540.4556
832.35352	2.4265461	0.83504653	3546.0701
833.35449	2.4326828	0.83653361	3548.6255
834.35547	2.4312551	0.83828592	3549.5771
835.35645	2.436589	0.83978754	3540.2244
836.35742	2.4391167	0.84132135	3541.739
837.3584	2.4410794	0.84283966	3543.9619
838.35938	2.4454479	0.84448385	3550.7739
839.36035	2.4491801	0.84569734	3539.844
840.36133	2.4530301	0.84714407	3547.2209
841.3623	2.4534655	0.84868085	3549.3555
842.36328	2.4545746	0.85015678	3541.5618
843.36426	2.4596844	0.85156339	3548.7659
844.36523	2.4616027	0.85313106	3546.0208
845.36621	2.4649541	0.8547383	3550.7354
846.36719	2.4697502	0.85644591	3552.0071
847.36816	2.471086	0.85825402	3548.3843
848.36914	2.4751823	0.86010611	3549.6382
849.37012	2.4807982	0.86178577	3548.5051
850.37109	2.4804139	0.86332047	3549.0027
851.37207	2.4827616	0.86497456	3550.4182
852.37305	2.4841888	0.86670518	3544.948
853.37402	2.4912329	0.86815721	3547.9895
854.375	2.4914629	0.86988765	3550.4314
855.37598	2.4957495	0.87148494	3546.2019
856.37695	2.5001943	0.87288356	3553.9004
857.37793	2.5017605	0.8745209	3544.1345
858.37891	2.5064807	0.87612957	3544.7979
859.37988	2.5063586	0.87756574	3543.7395
860.38086	2.5111325	0.87910473	3550.605
861.38184	2.5167482	0.88096619	3557.0029
862.38281	2.5175455	0.8827132	3545.3923
863.38379	2.5210662	0.88451779	3548.7915
864.38477	2.5223005	0.88608849	3544.7798
865.38574	2.5268674	0.88747585	3548.9741
866.38672	2.5313518	0.88918102	3551.2185
867.3877	2.533093	0.89095134	3548.6873
868.38867	2.5347509	0.89250922	3555.9451
869.38965	2.5387692	0.89415491	3546.1121
870.39063	2.5430405	0.89551562	3547.4497
871.3916	2.5452116	0.89710832	3550.4253
872.39258	2.5480261	0.89854181	3555.2217
873.39355	2.5520084	0.90045434	3554.6782
874.39453	2.5530119	0.90218121	3547.7688
875.39551	2.5574672	0.90369314	3549.2803
876.39648	2.5602946	0.90509516	3551.6802
877.39746	2.5600426	0.90665281	3547.991
878.39844	2.5628443	0.9082315	3543.6245
879.39941	2.5670629	0.90953571	3550.1858
880.40039	2.5708656	0.91108871	3547.4866
881.40137	2.5731952	0.91266572	3557.6292
882.40234	2.5767579	0.91434211	3553.6943
883.40332	2.5767126	0.91617209	3552.1304
884.4043	2.5837033	0.91806483	3556.3015
885.40527	2.5840034	0.92002189	3551.2825
886.40625	2.5878413	0.92187834	3545.1433
887.40723	2.5926642	0.9234004	3551.5688
888.4082	2.5936389	0.9247033	3544.6741
889.40918	2.6005268	0.92592013	3554.2429
890.41016	2.5982437	0.92755765	3548.7629
891.41113	2.6021695	0.92929578	3549.459
892.41211	2.6085687	0.93101096	3557.0889
893.41309	2.6102035	0.93288344	3553.7222
894.41406	2.611459	0.93431669	3551.1128
895.41504	2.6201859	0.93586987	3558.9082
896.41602	2.6196015	0.93760473	3555.9351
897.41699	2.6216896	0.93911266	3556.0229
898.41797	2.6242259	0.94062769	3548.0298
899.41895	2.6277564	0.94207299	3548.094
900.41992	2.6308069	0.94346559	3554.9175
901.4209	2.6319091	0.94513446	3553.9387
902.42188	2.6392419	0.94651318	3556.3567
903.42285	2.6434283	0.94820654	3552.4875
904.42383	2.6448219	0.94981658	3552.2278
905.4248	2.6463454	0.95147705	3557.8564
906.42578	2.6500919	0.95332831	3553.4785
907.42676	2.6525791	0.95500296	3548.5703
908.42773	2.6543689	0.95674801	3550.8186
909.42871	2.6583927	0.95795512	3548.0186
910.42969	2.6609409	0.95982623	3555.771
911.43066	2.66541	0.96149981	3554.2827
912.43164	2.6680329	0.96306241	3554.73
913.43262	2.6698961	0.96489382	3560.3286
914.43359	2.6717103	0.96678799	3555.6392
915.43457	2.6764934	0.96872121	3556.4243
916.43555	2.6766541	0.9707492	3553.1641
917.43652	2.6814554	0.97238421	3552.853
918.4375	2.6823123	0.97445351	3557.3076
919.43848	2.6887615	0.97642499	3554.3213
920.43945	2.6896994	0.97808808	3545.2947
921.44043	2.6953568	0.97977483	3555.957
922.44141	2.6956978	0.98162442	3552.3494
923.44238	2.6985586	0.98337758	3553.8799
924.44336	2.7008393	0.98567379	3554.3159
925.44434	2.708981	0.98771507	3554.9749
926.44531	2.709522	0.98985785	3551.7358
927.44629	2.7123046	0.99178064	3547.426
928.44727	2.7145541	0.99329597	3550.6658
929.44824	2.7184684	0.99504811	3552.915
930.44922	2.7187688	0.99701178	3552.4165
931.4502	2.7234621	0.99880564	3546.3381
932.45117	2.7310991	1.0003152	3555.6899
933.45215	2.7270987	1.0018178	3547.6755
934.45313	2.7321987	1.0036391	3554.2593
935.4541	2.7365849	1.0051166	3550.0974
936.45508	2.739634	1.0068491	3552.8589
937.45605	2.741977	1.0086304	3554.1077
938.45703	2.743639	1.0103333	3553.782
939.45801	2.7490959	1.0119113	3558.6587
940.45898	2.7509639	1.0136256	3548.1875
941.45996	2.7517912	1.0153197	3553.127
942.46094	2.7596476	1.0169637	3553.5774
943.46191	2.7616038	1.0186783	3547.8723
944.46289	2.7611101	1.0203075	3553.345
945.46387	2.7665195	1.0220271	3551.7998
946.46484	2.7731087	1.0236959	3556.0125
947.46582	2.771982	1.0258311	3554.1252
948.4668	2.7758679	1.0275428	3550.7185
949.46777	2.7806566	1.0292587	3544.9197
950.46875	2.7810538	1.0309271	3548.1431
951.46973	2.7855041	1.0327806	3551.8569
952.4707	2.7877738	1.0344883	3546.1301
953.47168	2.7904859	1.0362968	3553.3779
954.47266	2.7930295	1.0382113	3551.761
955.47363	2.7970157	1.0404423	3557.8259
956.47461	2.8000648	1.042502	3554.1724
957.47559	2.8007653	1.0448464	3549.123
958.47656	2.8030157	1.0467249	3546.595
959.47754	2.8100536	1.0483615	3547.4939
960.47852	2.8125942	1.0498784	3549.5378
961.47949	2.8150394	1.0517386	3554.1143
962.48047	2.8176246	1.0538663	3551.4287
963.48145	2.8174996	1.0557897	3547.2007
964.48242	2.8233924	1.0574279	3550.5437
965.4834	2.8283246	1.059358	3551.321
966.48438	2.8300195	1.0613604	3554.3076
967.48535	2.8335352	1.0632826	3547.3008
968.48633	2.8361063	1.0652435	3551.3447
969.4873	2.8385158	1.0672991	3551.5442
970.48828	2.8411276	1.0692985	3544.0305
971.48926	2.8459289	1.0713105	3541.5288
972.49023	2.8472304	1.0728067	3536.4985
973.49121	2.8546596	1.074279	3543.696
974.49219	2.8529899	1.0757707	3541.2529
975.49316	2.8555813	1.0776618	3546.7271
976.49414	2.8597181	1.079414	3547.8813
977.49512	2.8641961	1.0813178	3547.7122
978.49609	2.8655424	1.0832549	3544.3296
979.49707	2.8702323	1.0848649	3541.3726
980.49805	2.8742557	1.0867882	3544.6628
981.49902	2.873107	1.0884488	3542.1946
982.5	2.876344	1.0902033	3541.9963
983.50098	2.8821568	1.092397	3546.3479
984.50195	2.8834739	1.094188	3544.2639
985.50293	2.8852038	1.0961622	3538.791
986.50391	2.8878131	1.0980734	3539.0593
987.50488	2.892489	1.1000885	3543.6724
988.50586	2.89463	1.1020105	3543.686
989.50684	2.8993616	1.1039529	3543.05
990.50781	2.902492	1.1059159	3547.2546
991.50879	2.9055049	1.1077855	3540.5688
992.50977	2.9057479	1.1099602	3546.3354
993.51074	2.9099574	1.1118138	3531.0469
994.51172	2.9145839	1.1137292	3540.3357
995.5127	2.919245	1.1154522	3541.0776
996.51367	2.9181089	1.1171052	3527.7673
997.51465	2.9185474	1.118679	3530.4734
998.51563	2.9273944	1.1202952	3533.9434
999.5166	2.9303842	1.1221683	3540.364
1000.5176	2.931123	1.1242028	3540.2288
1001.5186	2.9293811	1.1258587	3527.5105
1002.5195	2.9400566	1.1274258	3531.8372
1003.5205	2.9404337	1.1293303	3533.9917
1004.5215	2.9435723	1.1312615	3536.5525
1005.5225	2.9462798	1.1333382	3531.6621
1006.5234	2.9483721	1.1352762	3525.7563
1007.5244	2.9502044	1.1368934	3525.7385
1008.5254	2.9580889	1.1383168	3528.8296
1009.5264	2.9582341	1.1398189	3524.3127
1010.5273	2.9603274	1.1413399	3526.1831
1011.5283	2.9651833	1.1430223	3530.4973
1012.5293	2.9673219	1.1444526	3526.1499
1013.5303	2.9705758	1.1463212	3526.4783
1014.5313	2.9751916	1.1481161	3529.1702
1015.5322	2.9763172	1.1503938	3525.8164
1016.5332	2.9782395	1.1520206	3517.6467
1017.5342	2.9817905	1.1535959	3522.8523
1018.5352	2.9867926	1.1553215	3519.2058
1019.5361	2.9868622	1.1567609	3508.6501
1020.5371	2.9927738	1.1580075	3518.2996
1021.5381	2.9957633	1.1593498	3518.856
1022.5391	2.9972935	1.1609185	3519.3333
1023.54	3.0006495	1.1623303	3520.0615
1024.541	3.0037217	1.1637548	3514.0955
1025.542	3.0070677	1.1654525	3520.8403
1026.543	3.0093596	1.167194	3515.8389
1027.5439	3.0127037	1.1691233	3522.0586
1028.5449	3.0148785	1.171329	3517.5503
1029.5459	3.0203578	1.1734374	3515.157
1030.5469	3.020236	1.1755128	3510.0627
1031.5479	3.0283813	1.1774036	3512.6604
1032.5488	3.0295875	1.1789314	3512.3179
1033.5498	3.030823	1.180625	3510.7539
1034.5508	3.0351472	1.1825258	3509.2488
1035.5518	3.0354123	1.1843092	3503.1521
1036.5527	3.0388463	1.1861221	3499.3914
1037.5537	3.0410569	1.1879209	3500.4653
1038.5547	3.0430572	1.1898011	3497.8867
1039.5557	3.0478265	1.1914263	3498.6333
1040.5566	3.051137	1.1929433	3493.8296
1041.5576	3.0531518	1.1945834	3495.8604
1042.5586	3.0563228	1.196404	3496.9333
1043.5596	3.0605054	1.1981212	3493.8892
1044.5605	3.0659471	1.1997156	3493.6914
1045.5615	3.0684264	1.2014254	3495.9194
1046.5625	3.06845	1.2033788	3493.2952
1047.5635	3.0714128	1.205034	3483.8408
1048.5645	3.0752709	1.2067164	3485.9363
1049.5654	3.0799077	1.2084559	3487.7646
1050.5664	3.0800292	1.2101483	3481.7266
1051.5674	3.0837634	1.2117937	3475.9209
1052.5684	3.0862024	1.2132251	3475.1025
1053.5693	3.0907407	1.2145669	3475.9077
1054.5703	3.0944166	1.2164669	3482.5859
1055.5713	3.0941525	1.2182764	3474.7751
1056.5723	3.1021476	1.220295	3472.0662
1057.5732	3.1045721	1.2217255	3468.6482
1058.5742	3.1061211	1.2231755	3469.2991
1059.5752	3.1083658	1.224758	3472.2505
1060.5762	3.1106038	1.226594	3467.7764
1061.5771	3.1152921	1.2283005	3459.2627
1062.5781	3.1197989	1.2299801	3466.9634
1063.5791	3.1226747	1.2318432	3464.0115
1064.5801	3.122885	1.2336317	3457.8569
1065.5811	3.1291029	1.2355058	3462.0723
1066.582	3.1301541	1.2373639	3448.5657
1067.583	3.1311295	1.2391081	3456.6675
1068.584	3.1355717	1.2407197	3450.7622
1069.585	3.1381412	1.2425109	3445.6843
1070.5859	3.1423337	1.2443029	3450.4817
1071.5869	3.1440871	1.2461081	3444.6318
1072.5879	3.1472576	1.2478729	3435.6584
1073.5889	3.1525114	1.2495449	3442.552
1074.5898	3.1541848	1.2513139	3437.8096
1075.5908	3.1565931	1.2531533	3433.3555
1076.5918	3.1586182	1.2547004	3432.1428
1077.5928	3.1627622	1.2559932	3422.1411
1078.5938	3.1662288	1.2571738	3424.6318
1079.5947	3.1675742	1.2586511	3424.9897
1080.5957	3.1697609	1.2602344	3421.2114
1081.5967	3.1741295	1.2617768	3416.0308
1082.5977	3.1787214	1.2634418	3421.3428
1083.5986	3.1794384	1.2650653	3414.426
1084.5996	3.1843891	1.266964	3420.2842
1085.6006	3.1847453	1.2688015	3403.0969
1086.6016	3.1897047	1.2703862	3405.7209
1087.6025	3.1940749	1.2716376	3400.4063
1088.6035	3.1942813	1.2730404	3399.6711
1089.6045	3.1999466	1.2746412	3401.0515
1090.6055	3.20066	1.2762306	3402.8606
1091.6064	3.2035801	1.2781409	3398.6187
1092.6074	3.2066276	1.2797863	3394.6824
1093.6084	3.2093523	1.2816292	3391.5334
1094.6094	3.2116067	1.2833701	3388.043
1095.6104	3.2179754	1.284941	3388.7729
1096.6113	3.2220957	1.286432	3384.2722
1097.6123	3.2226915	1.2879113	3374.6655
1098.6133	3.2280891	1.2895298	3385.7905
1099.6143	3.2283628	1.2915424	3370.7788
1100.6152	3.2293568	1.2932966	3372.7104
1101.6162	3.2359219	1.2950791	3369.3142
1102.6172	3.2403002	1.2969141	3369.7537
1103.6182	3.2394559	1.2986454	3363.0117
1104.6191	3.2427313	1.3002191	3356.7461
1105.6201	3.2449465	1.3018019	3349.48
1106.6211	3.2499428	1.3036188	3355.2957
1107.6221	3.2560923	1.3051805	3352.8936
1108.623	3.2550058	1.3068706	3345.5303
1109.624	3.2603478	1.3084731	3342.8875
1110.625	3.262008	1.3101765	3339.9661
1111.626	3.2664385	1.3118123	3337.1079
1112.627	3.2717378	1.313277	3332.2231
1113.6279	3.275152	1.3148531	3329.4922
1114.6289	3.2734022	1.3166077	3331.3967
1115.6299	3.2780814	1.3184046	3321.1426
1116.6309	3.2798026	1.3197981	3311.8142
1117.6318	3.2817874	1.3213135	3314.2026
1118.6328	3.2854545	1.3229241	3311.7844
1119.6338	3.2897668	1.3244303	3310.4529
1120.6348	3.292469	1.3261337	3308.2358
1121.6357	3.297667	1.3276817	3300.8545
1122.6367	3.2998188	1.3293577	3304.5581
1123.6377	3.3023906	1.3309083	3294.8296
1124.6387	3.302304	1.3324915	3289.8848
1125.6396	3.3097732	1.3340093	3283.9153
1126.6406	3.3129706	1.3356317	3284.2993
1127.6416	3.3124936	1.3373655	3284.4238
1128.6426	3.3177874	1.3393617	3280.7488
1129.6436	3.3212941	1.341184	3272.3706
1130.6445	3.3192184	1.342942	3268.1807
1131.6455	3.3246148	1.3443501	3258.0955
1132.6465	3.3278413	1.3461953	3258.5889
1133.6475	3.3302319	1.3480073	3252.0134
1134.6484	3.3349977	1.3498499	3249.8203
1135.6494	3.3366468	1.3518109	3242.9438
1136.6504	3.3415484	1.3538452	3237.3533
1137.6514	3.3415916	1.3554533	3230.2393
1138.6523	3.3448734	1.3570087	3226.5474
1139.6533	3.3497028	1.3586578	3222.6077
1140.6543	3.3531969	1.3601441	3218.4998
1141.6553	3.3558607	1.3615755	3216.6484
1142.6563	3.3589482	1.3629179	3210.1941
1143.6572	3.3621068	1.3644342	3211.5735
1144.6582	3.3637731	1.366276	3203.0095
1145.6592	3.3665111	1.3679394	3196.114
1146.6602	3.3723762	1.3698695	3201.1096
1147.6611	3.3736844	1.3718921	3183.6968
1148.6621	3.374346	1.3735996	3180.0181
1149.6631	3.3799956	1.3752666	3179.5767
1150.6641	3.3832808	1.3768553	3164.7512
1151.665	3.3837626	1.3783405	3166.458
1152.666	3.3854165	1.3799127	3157.1138
1153.667	3.3915648	1.3815824	3149.459
1154.668	3.3936241	1.3829684	3147.0669
1155.6689	3.3971605	1.384612	3147.6599
1156.6699	3.4004393	1.3865968	3144.646
1157.6709	3.4023616	1.3885454	3129.3213
1158.6719	3.4069991	1.3902659	3129.1548
1159.6729	3.4106123	1.3917185	3118.3423
1160.6738	3.41432	1.3932699	3116.072
1161.6748	3.4157298	1.39498	3107.7419
1162.6758	3.4198813	1.3968419	3099.8079
1163.6768	3.4200659	1.3982975	3092.3401
1164.6777	3.4231744	1.400259	3086.4282
1165.6787	3.4292448	1.4023924	3077.033
1166.6797	3.4329331	1.4042345	3068.4417
1167.6807	3.4371619	1.4060589	3055.0061
1168.6816	3.4373541	1.4076623	3044.1968
1169.6826	3.4409173	1.4102428	3017.844
1170.5835	3.443469	1.413994	2950.2944