File: datasets/am_bench_2022/raw_data/0-X.11-2/specimen.dat
MTS793|MPT|ENU|1|2|.|/|:|1|0|0|A

Operator Information						Time:	24.308594	Sec	10/13/2021 7:58:46 AM
Operator	Jake Benzing
Project	AM Bench 2022 mini-tensile challenge
Specimen ID	O-X.11-2
Material	PBF-L Inconel 625
Specimen Width	2.56	mm
Specimen Thickness	1.53	mm
Notes
Operator Information End

Data Acquisition						Time:	1025.3015	Sec	10/13/2021 8:15:27 AM
Time	Axial Displacement	Axial Extensometer	Axial Force
Sec	mm	mm	N
24.421631	-0.0019676082	6.0089813e-05	65.15451
25.422607	0.0022750178	0.0002726939	84.572807
26.423584	0.0036828236	0.00023310998	93.765762
27.424561	0.0085255755	0.00027576726	114.57357
28.425537	0.011660766	0.00037748742	123.6894
29.426514	0.016503926	0.000487602	140.19461
30.42749	0.018322743	0.00073149393	155.34358
31.428467	0.020991603	0.00065835298	167.67928
32.429443	0.021708312	0.00070180523	188.3116
33.43042	0.027615421	0.00079076376	206.06807
34.431396	0.028968111	0.0009530313	231.22421
35.432373	0.030120622	0.0010413136	251.63644
36.43335	0.036781318	0.0010550946	271.34763
37.434326	0.038106143	0.0011535847	291.12677
38.435303	0.04213671	0.001234446	316.74188
39.436279	0.045429103	0.001203238	329.09607
40.437256	0.048103902	0.0015131069	351.94006
41.438232	0.050600242	0.0015162991	374.11795
42.439209	0.052009687	0.0016515045	395.57495
43.440186	0.057304222	0.0015971275	414.41367
44.441162	0.059105214	0.0019207528	441.77829
45.442139	0.059615802	0.0019313907	457.17007
46.443115	0.065421693	0.0019159912	481.44382
47.444092	0.067819282	0.0020141287	506.34103
48.445068	0.075454488	0.0021430205	527.30011
49.446045	0.077684879	0.0022708715	560.80701
50.447021	0.075782932	0.0023644145	587.71753
51.447998	0.079431988	0.0025319364	608.73041
52.448975	0.084475733	0.0026941088	638.87189
53.449951	0.08747939	0.0027144665	661.75122
54.450928	0.088445857	0.0028877736	692.99219
55.451904	0.093324825	0.0030528165	722.96973
56.452881	0.094113447	0.0031548173	751.35602
57.453857	0.09594968	0.0031914355	776.86469
58.454834	0.099832773	0.0033616608	801.1767
59.455811	0.10381965	0.0035069881	832.10394
60.456787	0.10677597	0.0034964157	855.63721
61.457764	0.11224615	0.0037922955	892.54126
62.45874	0.11102049	0.0038810133	914.48535
63.459717	0.1158321	0.0040025115	945.81738
64.460693	0.12061968	0.0040436075	972.02563
65.46167	0.12153903	0.0042319493	1004.148
66.462646	0.12340046	0.0043439092	1029.3407
67.463623	0.127849	0.004420694	1048.6873
68.4646	0.12801209	0.0046585491	1072.7227
69.465576	0.13427387	0.0047439015	1106.77
70.466553	0.13626644	0.0048570526	1131.1064
71.467529	0.14121409	0.0049293954	1162.2795
72.468506	0.14402637	0.0051651397	1187.3374
73.469482	0.14644654	0.00524848	1220.3196
74.470459	0.15109977	0.0053641973	1251.0603
75.471436	0.15195847	0.0056060147	1277.4756
76.472412	0.15474576	0.0056367023	1310.6138
77.473389	0.16030379	0.0057997867	1341.8105
78.474365	0.16266489	0.0058444026	1370.7628
79.475342	0.16489227	0.006115335	1398.5366
80.476318	0.16601957	0.0062160296	1424.2615
81.477295	0.17073053	0.0062495908	1455.6592
82.478271	0.17378013	0.0064807991	1484.5552
83.479248	0.17523009	0.0066965963	1518.429
84.480225	0.17911482	0.0067706797	1545.7384
85.481201	0.18498567	0.0069383606	1573.5308
86.482178	0.18440706	0.0070404606	1589.1091
87.483154	0.18936823	0.0071696928	1616.1676
88.484131	0.19026566	0.0072523886	1644.5898
89.485107	0.19386415	0.0075187972	1677.6427
90.486084	0.19684444	0.0077369097	1718.5221
91.487061	0.20331828	0.0078423498	1743.2827
92.488037	0.20341356	0.0078696571	1761.49
93.489014	0.20497832	0.0080539249	1776.2172
94.48999	0.20896851	0.008242514	1809.5065
95.490967	0.21077785	0.0083582634	1838.4215
96.491943	0.21673214	0.0086801806	1871.1508
97.49292	0.21674772	0.0087556085	1890.6599
98.493896	0.21906605	0.0089612836	1927.5541
99.494873	0.22514322	0.009105226	1954.3895
100.49585	0.22624409	0.009366598	1961.499
101.49683	0.22841877	0.0094970884	1991.478
102.4978	0.2328272	0.0096807536	2017.3928
103.49878	0.23481438	0.0098388586	2039.9783
104.49976	0.23664364	0.0099733267	2064.7983
105.50073	0.24241327	0.010157853	2079.4922
106.50171	0.24436671	0.010251426	2097.3535
107.50269	0.24513115	0.010512589	2119.8669
108.50366	0.25321114	0.010814255	2149.7947
109.50464	0.2538133	0.010974273	2169.9932
110.50562	0.25697902	0.011304172	2195.0352
111.50659	0.26279479	0.011523985	2216.2402
112.50757	0.26400694	0.011669814	2230.197
113.50854	0.26844969	0.011883946	2245.1868
114.50952	0.27001607	0.012183612	2262.7678
115.5105	0.27391639	0.012549703	2288.3811
116.51147	0.27492091	0.012796606	2297.2051
117.51245	0.27920699	0.013123645	2315.0342
118.51343	0.27992287	0.013488101	2333.5544
119.5144	0.28306195	0.013738897	2344.415
120.51538	0.28847471	0.014047275	2368.2346
121.51636	0.2889556	0.014396229	2369.3784
122.51733	0.29651597	0.014803301	2387.6504
123.51831	0.29943055	0.015119728	2400.4009
124.51929	0.29986143	0.015589803	2415.979
125.52026	0.3007105	0.016111165	2429.3015
126.52124	0.30305213	0.016540138	2437.1824
127.52222	0.30686367	0.017139031	2454.1104
128.52319	0.31457776	0.017810186	2467.8091
129.52417	0.31117144	0.018451754	2473.0886
130.52515	0.3195602	0.018822527	2491.0913
131.52612	0.31915	0.019469632	2484.9587
132.5271	0.32346782	0.019953534	2500.2668
133.52808	0.3247529	0.020635013	2514.0164
134.52905	0.33013412	0.021127997	2519.3306
135.53003	0.33159554	0.022022104	2523.6152
136.53101	0.33550584	0.022729648	2537.5286
137.53198	0.33651105	0.023599518	2542.4009
138.53296	0.33922073	0.024428809	2549.4526
139.53394	0.34479287	0.025517296	2561.9536
140.53491	0.34980276	0.026152484	2561.981
141.53589	0.35052624	0.027215073	2575.8779
142.53687	0.35310888	0.028125657	2573.605
143.53784	0.36011443	0.029109789	2582.4839
144.53882	0.35904655	0.029866852	2588.0137
145.53979	0.36502275	0.030913578	2587.8618
146.54077	0.36752138	0.031906776	2594.6304
147.54175	0.36774328	0.032832112	2593.2798
148.54272	0.37172344	0.033732317	2595.0747
149.5437	0.3748734	0.035098631	2617.2974
150.54468	0.38079777	0.036550112	2616.2649
151.54565	0.37786517	0.037785921	2613.3779
152.54663	0.38630596	0.039210368	2626.5647
153.54761	0.38555726	0.040475402	2622.5193
154.54858	0.38960811	0.041507151	2627.6191
155.54956	0.39116776	0.042707153	2623.0671
156.55054	0.39486808	0.043929182	2628.5757
157.55151	0.40049839	0.045046031	2637.6699
158.55249	0.40022936	0.046469647	2637.9116
159.55347	0.40249294	0.047988582	2640.78
160.55444	0.40817684	0.049014006	2644.6836
161.55542	0.41184267	0.050420694	2650.5461
162.5564	0.41415912	0.051873159	2655.8679
163.55737	0.41616005	0.053368863	2652.5515
164.55835	0.42197794	0.054941364	2659.5586
165.55933	0.42400712	0.056466971	2662.312
166.5603	0.42641577	0.057978265	2657.8804
167.56128	0.43014267	0.059440926	2664.8789
168.56226	0.43380675	0.060782373	2666.8496
169.56323	0.43150234	0.062137224	2660.0234
170.56421	0.43764511	0.063533172	2667.7336
171.56519	0.44279188	0.065252602	2678.2212
172.56616	0.44239193	0.066549242	2674.5713
173.56714	0.44623119	0.067662925	2678.6992
174.56812	0.45031399	0.069077514	2677.6904
175.56909	0.45276791	0.070645668	2670.2251
176.57007	0.45538601	0.072449841	2676.8003
177.57104	0.45834377	0.073548526	2679.8159
178.57202	0.46065167	0.075041533	2685.6655
179.573	0.4656657	0.076366484	2681.8713
180.57397	0.4685044	0.077943243	2681.009
181.57495	0.47150192	0.079426937	2688.0791
182.57593	0.47269827	0.080836631	2684.4934
183.5769	0.47646165	0.082441621	2683.6636
184.57788	0.48310411	0.08400166	2692.6255
185.57886	0.48088726	0.085652433	2697.7185
186.57983	0.48737529	0.087540314	2699.1099
187.58081	0.48753941	0.089343756	2693.8374
188.58179	0.49294925	0.090581909	2694.5886
189.58276	0.49708492	0.091983318	2701.929
190.58374	0.49924651	0.093551971	2699.9746
191.58472	0.4994055	0.095017686	2702.2671
192.58569	0.50189328	0.096584916	2700.9766
193.58667	0.50600171	0.097973295	2702.6108
194.58765	0.50813949	0.099430107	2698.9187
195.58862	0.51498425	0.10088216	2711.085
196.5896	0.51617813	0.10268818	2707.7842
197.59058	0.51867938	0.10443052	2706.1025
198.59155	0.52333295	0.10604102	2711.969
199.59253	0.52563596	0.10796617	2714.2317
200.59351	0.52844071	0.10959426	2719.7148
201.59448	0.53407532	0.11152984	2727.7065
202.59546	0.53315204	0.11350565	2719.656
203.59644	0.53430051	0.11498196	2717.0708
204.59741	0.54145503	0.11669271	2723.6079
205.59839	0.54362828	0.11863377	2718.9746
206.59937	0.54750657	0.12022536	2726.1604
207.60034	0.54937989	0.12182377	2719.7361
208.60132	0.55501598	0.1235753	2729.2769
209.60229	0.55605686	0.12533616	2730.2917
210.60327	0.56286895	0.12682445	2731.3301
211.60425	0.56102818	0.12886542	2730.3125
212.60522	0.56357497	0.1303833	2727.2979
213.6062	0.57083112	0.13179597	2722.9182
214.60718	0.57160169	0.13311327	2734.0449
215.60815	0.57179141	0.13490017	2733.7285
216.60913	0.57684433	0.13639946	2725.0889
217.61011	0.57876951	0.13773088	2729.1208
218.61108	0.57965708	0.13973711	2741.0723
219.61206	0.58600783	0.1413914	2738.3755
220.61304	0.5878768	0.14298782	2741.8489
221.61401	0.59281278	0.14457016	2743.8098
222.61499	0.59554565	0.14651963	2746.8394
223.61597	0.59723574	0.1482396	2740.4858
224.61694	0.59956366	0.14973901	2739.3564
225.61792	0.60256916	0.15175819	2742.4583
226.6189	0.6069001	0.15375407	2746.6179
227.61987	0.60880005	0.15527374	2739.0913
228.62085	0.61222684	0.15698388	2745.6089
229.62183	0.61637723	0.15872262	2750.115
230.6228	0.61811548	0.16026834	2743.1738
231.62378	0.62046766	0.16189134	2748.7205
232.62476	0.62278146	0.16389252	2754.2039
233.62573	0.62937289	0.16574602	2755.082
234.62671	0.62895614	0.16756222	2756.2769
235.62769	0.63481909	0.16919881	2761.4165
236.62866	0.6362918	0.17111491	2757.3066
237.62964	0.64009905	0.17296994	2757.5479
238.63062	0.64115155	0.17477581	2755.7639
239.63159	0.64489752	0.17642553	2757.6597
240.63257	0.64945632	0.17773944	2763.6296
241.63354	0.65208644	0.17937028	2759.1582
242.63452	0.65478957	0.18093434	2767.3411
243.6355	0.65821201	0.18229894	2761.5491
244.63647	0.65954357	0.18416212	2765.7283
245.63745	0.66092128	0.18578573	2762.3657
246.63843	0.66460514	0.18749155	2767.5874
247.6394	0.66689807	0.18928953	2757.738
248.64038	0.67352951	0.19121027	2769.8118
249.64136	0.67553616	0.19278412	2759.5054
250.64233	0.67907399	0.19459246	2766.3018
251.64331	0.6834293	0.19610897	2771.843
252.64429	0.68514478	0.19781843	2771.9592
253.64526	0.68796718	0.19987424	2772.6494
254.64624	0.69055271	0.20140947	2772.5161
255.64722	0.69144309	0.2030647	2771.103
256.64819	0.69478667	0.20470585	2769.7444
257.64917	0.70048136	0.20660619	2779.468
258.65015	0.70250261	0.20837709	2775.4824
259.65112	0.70717281	0.21034883	2777.2439
260.6521	0.70751029	0.21225446	2783.9641
261.65308	0.71195447	0.21390957	2784.26
262.65405	0.7141788	0.21576333	2781.1926
263.65503	0.71531981	0.21742576	2778.7793
264.65601	0.71724129	0.21941446	2784.2002
265.65698	0.72260869	0.22112729	2779.7053
266.65796	0.72730249	0.22265419	2784.0073
267.65894	0.72874451	0.22440781	2785.6521
268.65991	0.73260766	0.22621177	2792.4617
269.66089	0.73742133	0.22812149	2791.6096
270.66187	0.73538351	0.22993165	2788.0671
271.66284	0.7427929	0.23159534	2789.7207
272.66382	0.74360919	0.23337638	2797.1621
273.66479	0.7471118	0.23520748	2793.7246
274.66577	0.74853039	0.23699051	2790.4756
275.66675	0.75460595	0.23864593	2797.8428
276.66772	0.7552399	0.24068637	2794.729
277.6687	0.75743467	0.2427299	2793.2542
278.66968	0.76296049	0.24447472	2796.6584
279.67065	0.76604855	0.24646717	2797.9082
280.67163	0.76875848	0.24824804	2799.804
281.67261	0.77227902	0.24988881	2801.4973
282.67358	0.7765913	0.25178152	2804.856
283.67456	0.77604651	0.25328657	2792.1948
284.67554	0.78206801	0.25489813	2802.9443
285.67651	0.78648293	0.25674605	2808.1814
286.67749	0.78831255	0.25832233	2803.9817
287.67847	0.79141444	0.2599512	2802.9966
288.67944	0.79234803	0.26201773	2810.1958
289.68042	0.79469651	0.26382169	2804.3689
290.6814	0.79858696	0.26550063	2802.4275
291.68237	0.80105138	0.26702663	2799.8127
292.68335	0.80509394	0.26865527	2807.646
293.68433	0.80624342	0.27028593	2811.1101
294.6853	0.81178051	0.27201575	2809.3691
295.68628	0.81184673	0.27399293	2816.0295
296.68726	0.82016516	0.27556467	2817.6965
297.68823	0.82320881	0.27768889	2818.2727
298.68921	0.82455188	0.27954659	2809.4331
299.69019	0.82676899	0.28152892	2816.6826
300.69116	0.82720703	0.28324291	2817.2825
301.69214	0.83133984	0.2850832	2823.7688
302.69312	0.83386177	0.28719562	2816.0715
303.69409	0.83880413	0.28899288	2815.5842
304.69507	0.83948171	0.29044425	2816.0583
305.69604	0.84495568	0.29234979	2825.9211
306.69702	0.84652305	0.29394326	2813.0317
307.698	0.85056269	0.29566345	2823.2114
308.69897	0.85331923	0.29744783	2823.5723
309.69995	0.85469609	0.29925463	2824.4836
310.70093	0.85825849	0.3010326	2822.6223
311.7019	0.86060959	0.30307567	2827.2273
312.70288	0.86541092	0.30499551	2825.5496
313.70386	0.86837983	0.30695757	2835.9976
314.70483	0.86968613	0.30871877	2832.0339
315.70581	0.87581891	0.3105998	2835.3608
316.70679	0.87585968	0.31242645	2829.6147
317.70776	0.87848574	0.31431857	2833.9595
318.70874	0.88090795	0.31615114	2832.4692
319.70972	0.88777864	0.31777695	2828.9827
320.71069	0.89125729	0.31977603	2840.2068
321.71167	0.8893348	0.32143843	2830.4858
322.71265	0.89505243	0.32285666	2839.9148
323.71362	0.89918822	0.32444784	2835.6433
324.7146	0.90222824	0.32615846	2841.5032
325.71558	0.90545875	0.32787675	2842.2908
326.71655	0.90506756	0.32960713	2840.2634
327.71753	0.90933269	0.33153123	2835.1277
328.71851	0.91288978	0.33328125	2841.5356
329.71948	0.91549003	0.33513421	2840.8521
330.72046	0.91794217	0.33730197	2842.9573
331.72144	0.9195798	0.33908916	2841.9165
332.72241	0.92425168	0.34080383	2845.7297
333.72339	0.92982465	0.34266213	2852.0432
334.72437	0.93183279	0.34434596	2844.8667
335.72534	0.93385834	0.34614718	2850.8638
336.72632	0.93853348	0.34800684	2852.9009
337.72729	0.93943226	0.34988809	2847.543
338.72827	0.94125515	0.35169527	2851.0547
339.72925	0.94389665	0.35331714	2857.073
340.73022	0.95172912	0.35530472	2854.3018
341.7312	0.95173872	0.35739505	2853.3987
342.73218	0.95254517	0.35899398	2849.7942
343.73315	0.95795238	0.36065823	2858.7798
344.73413	0.96179736	0.3624098	2853.9077
345.73511	0.96219134	0.36422464	2856.7881
346.73608	0.96677506	0.36617658	2854.8892
347.73706	0.96922678	0.36830223	2864.9883
348.73804	0.97329915	0.37015176	2856.9971
349.73901	0.9768011	0.37157175	2860.5374
350.73999	0.97971481	0.37301621	2866.0845
351.74097	0.98287833	0.37508056	2862.7109
352.74194	0.98783726	0.37675312	2863.6108
353.74292	0.98769873	0.3786715	2862.9053
354.7439	0.99048847	0.380382	2865.1738
355.74487	0.99353349	0.3823145	2865.3035
356.74585	0.99726993	0.38449955	2880.6621
357.74683	1.0002793	0.3863771	2865.9417
358.7478	1.0016425	0.38826662	2868.4316
359.74878	1.0068097	0.39010322	2866.5613
360.74976	1.0111448	0.3917143	2858.4507
361.75073	1.0130779	0.39320168	2869.3208
362.75171	1.0128657	0.39505604	2871.2563
363.75269	1.0140967	0.39679632	2870.1367
364.75366	1.0223857	0.39858246	2874.4102
365.75464	1.0271962	0.40061018	2876.916
366.75562	1.0290734	0.40228644	2876.6736
367.75659	1.0277706	0.40380627	2872.2385
368.75757	1.0336063	0.40553066	2874.2825
369.75854	1.0368099	0.40745071	2876.9421
370.75952	1.0359048	0.40928698	2876.5625
371.7605	1.0395688	0.41125017	2879.2034
372.76147	1.0459963	0.41344902	2878.1167
373.76245	1.0464473	0.41521204	2875.6318
374.76343	1.0531042	0.41708016	2884.8081
375.7644	1.057302	0.41894531	2894.9775
376.76538	1.0579562	0.42108706	2884.6694
377.76636	1.0583496	0.42298824	2882.6536
378.76733	1.0624201	0.42468929	2883.2002
379.76831	1.0649278	0.42678598	2886.3589
380.76929	1.0689071	0.42831343	2882.9131
381.77026	1.0737784	0.43003878	2884.8801
382.77124	1.0750635	0.43195376	2889.0864
383.77222	1.0781145	0.43403777	2886.8218
384.77319	1.0833637	0.43563309	2889.4954
385.77417	1.0849377	0.4373599	2890.7388
386.77515	1.0856624	0.43932745	2892.8328
387.77612	1.0903778	0.44125751	2889.8333
388.7771	1.0922682	0.4429934	2892.0808
389.77808	1.0944899	0.44483069	2894.9868
390.77905	1.0976268	0.44675738	2888.4934
391.78003	1.1033105	0.44849557	2895.6123
392.78101	1.1058306	0.44994351	2893.8252
393.78198	1.1069845	0.45171812	2894.2847
394.78296	1.1102861	0.45373493	2902.1489
395.78394	1.111517	0.45554838	2898.1624
396.78491	1.1157339	0.45745906	2897.168
397.78589	1.1204805	0.45934108	2899.1672
398.78687	1.1205852	0.46115601	2900.5991
399.78784	1.1260306	0.46305466	2902.4346
400.78882	1.1294138	0.46471161	2898.3848
401.78979	1.133299	0.46646509	2906.7825
402.79077	1.1343484	0.46808076	2902.5991
403.79175	1.1363989	0.4697521	2904.2896
404.79272	1.1399424	0.47198233	2905.7737
405.7937	1.1434792	0.47370374	2902.1357
406.79468	1.1465747	0.4754048	2903.8911
407.79565	1.1480452	0.47735649	2901.842
408.79663	1.1538419	0.47891223	2905.6956
409.79761	1.1556728	0.48086509	2909.5515
410.79858	1.158408	0.48274922	2907.1714
411.79956	1.1615684	0.48486131	2912.6152
412.80054	1.1609585	0.4866018	2910.8916
413.80151	1.1701615	0.48844483	2915.957
414.80249	1.1727642	0.49064532	2918.4109
415.80347	1.1763979	0.49241447	2912.7705
416.80444	1.1760156	0.49442977	2917.1096
417.80542	1.1818109	0.49640787	2915.2805
418.8064	1.1834786	0.49821699	2914.9368
419.80737	1.1863846	0.5001635	2915.2966
420.80835	1.1874906	0.50194693	2911.4634
421.80933	1.188851	0.50395823	2913.5933
422.8103	1.1970077	0.50530905	2914.5356
423.81128	1.1972539	0.5070712	2913.9131
424.81226	1.1998541	0.50893402	2919.042
425.81323	1.2044845	0.51093471	2920.1787
426.81421	1.203452	0.51285046	2922.6006
427.81519	1.2068552	0.5147016	2919.9067
428.81616	1.2110831	0.51664299	2929.7813
429.81714	1.2152539	0.51841909	2925.9219
430.81812	1.2198527	0.52006406	2919.6965
431.81909	1.2200537	0.52169359	2923.9763
432.82007	1.2228426	0.52363425	2926.5706
433.82104	1.2263306	0.5253377	2925.6921
434.82202	1.2301143	0.52694404	2924.5352
435.823	1.2327341	0.52863139	2925.0652
436.82397	1.2355506	0.53025192	2926.3987
437.82495	1.2405834	0.53218311	2940.5164
438.82593	1.2417438	0.53425986	2936.7141
439.8269	1.2439382	0.53636843	2926.821
440.82788	1.2473422	0.53812563	2928.6018
441.82886	1.2530884	0.53956133	2927.3145
442.82983	1.2524732	0.54138428	2926.5811
443.83081	1.2591909	0.54336745	2937.6116
444.83179	1.260886	0.54528719	2934.4072
445.83276	1.2635026	0.54710722	2937.4434
446.83374	1.2690222	0.54923558	2944.4995
447.83472	1.269294	0.55118054	2936.6375
448.83569	1.2713505	0.55326164	2938.6787
449.83667	1.2747101	0.55541444	2943.6167
450.83765	1.2756521	0.55705905	2930.1394
451.83862	1.2801449	0.55889362	2934.4651
452.8396	1.2832434	0.56028801	2932.4971
453.84058	1.2865562	0.561966	2942.2056
454.84155	1.2942711	0.56380713	2945.1658
455.84253	1.2934614	0.56525314	2944.1619
456.84351	1.2983806	0.5676505	2951.0393
457.84448	1.3037457	0.56942922	2948.929
458.84546	1.3033258	0.57138771	2950.7319
459.84644	1.3065263	0.57314271	2948.3938
460.84741	1.3108534	0.57522303	2949.301
461.84839	1.3122209	0.57683295	2940.499
462.84937	1.3148038	0.57875687	2950.2095
463.85034	1.3180058	0.5811671	2951.9482
464.85132	1.3185381	0.58277071	2939.7471
465.85229	1.3209981	0.58422369	2941.5454
466.85327	1.3269838	0.58560687	2945.2986
467.85425	1.3280987	0.58759159	2954.3918
468.85522	1.3326466	0.58952594	2954.9355
469.8562	1.33649	0.59137243	2951.8633
470.85718	1.3396968	0.59345424	2957.8877
471.85815	1.3415385	0.59548467	2950.6138
472.85913	1.3470201	0.59736502	2954.8582
473.86011	1.3496141	0.5989629	2956.0342
474.86108	1.3532264	0.60081798	2962.0264
475.86206	1.3555574	0.60267305	2958.9219
476.86304	1.3569276	0.6044113	2959.0977
477.86401	1.3594949	0.60616618	2958.3201
478.86499	1.3644081	0.60793406	2964.0891
479.86597	1.3672862	0.60957938	2959.7981
480.86694	1.368449	0.61131567	2955.1079
481.86792	1.3713843	0.61311162	2964.2356
482.8689	1.3759012	0.61519653	2966.0986
483.86987	1.3781062	0.61710966	2968.0415
484.87085	1.3807312	0.61934656	2964.3928
485.87183	1.3859895	0.62097824	2968.4128
486.8728	1.3838689	0.62276453	2959.9812
487.87378	1.3894718	0.624672	2963.3
488.87476	1.3917235	0.62658602	2969.8691
489.87573	1.3974848	0.62859559	2970.6931
490.87671	1.4018309	0.63043296	2970.9878
491.87769	1.4021416	0.63212925	2969.843
492.87866	1.403565	0.63389671	2972.0601
493.87964	1.4090366	0.63566172	2969.9309
494.88062	1.4137739	0.63749641	2975.6453
495.88159	1.4153337	0.63940585	2972.3135
496.88257	1.4159892	0.64100814	2968.2859
497.88354	1.4201418	0.64256358	2970.8572
498.88452	1.4242977	0.64466566	2980.4536
499.8855	1.4266908	0.64670438	2968.2864
500.88647	1.4312733	0.64853096	2976.0923
501.88745	1.4316846	0.65010661	2974.5537
502.88843	1.4363402	0.65230215	2984.2944
503.8894	1.4390686	0.65432912	2980.9534
504.89038	1.4421932	0.65590912	2971.6145
505.89136	1.4479159	0.65797716	2977.5078
506.89233	1.4494493	0.65955204	2978.4788
507.89331	1.4537328	0.66110682	2982.3208
508.89429	1.4535751	0.66282022	2975.9678
509.89526	1.4586215	0.6646834	2991.7778
510.89624	1.4623755	0.66661823	2984.6177
511.89722	1.460453	0.66869539	2988.9285
512.89819	1.4639244	0.67069066	2980.5249
513.89917	1.4694971	0.67239076	2984.6501
514.90015	1.4742533	0.67407709	2985.646
515.90112	1.4714258	0.6760149	2984.5811
516.9021	1.4769313	0.67807519	2984.4067
517.90308	1.4791398	0.6800276	2980.7813
518.90405	1.4815664	0.68205172	2995.6357
519.90503	1.485214	0.68425614	2987.0381
520.90601	1.4884872	0.68620288	2985.8171
521.90698	1.4929262	0.68826699	2992.5522
522.90796	1.4971668	0.68959445	2984.9888
523.90894	1.498655	0.69141585	2991.3008
524.90991	1.5009738	0.69327241	2989.4622
525.91089	1.5038166	0.6949569	2984.9465
526.91187	1.5081103	0.69686282	2986.2395
527.91284	1.5084853	0.69858849	2988.1978
528.91382	1.5142578	0.70051199	2993.3643
529.91479	1.5151128	0.7024709	2989.5637
530.91577	1.5202719	0.70442158	2996.6206
531.91675	1.5218948	0.70604801	2985.5886
532.91772	1.5235668	0.70792717	2997.9814
533.9187	1.5264966	0.71006316	2997.7603
534.91968	1.5300807	0.71197021	2993.6526
535.92065	1.5328164	0.71381325	2991.5112
536.92163	1.5381314	0.71520418	2993.2363
537.92261	1.5412959	0.71711177	3002.5071
538.92358	1.543705	0.71906066	2997.1921
539.92456	1.5480005	0.72062778	2995.196
540.92554	1.5496615	0.72228724	3001.8667
541.92651	1.5522536	0.72416192	3002.3149
542.92749	1.5567935	0.72581804	3000.425
543.92847	1.55688	0.7276209	3005.6152
544.92944	1.5600379	0.72947699	3001.6714
545.93042	1.5639567	0.73130226	2999.1951
546.9314	1.5686828	0.73320878	3013.9741
547.93237	1.572657	0.7350657	2999.4121
548.93335	1.5720499	0.73674297	3000.9763
549.93433	1.5761508	0.73884249	3005.6382
550.9353	1.5777644	0.74078697	3006.5723
551.93628	1.5775958	0.74260598	3000.6128
552.93726	1.5830479	0.74440509	3004.0066
553.93823	1.587175	0.7460736	3002.1777
554.93921	1.5914249	0.74814743	3010.0452
555.94019	1.595659	0.75017029	3013.2932
556.94116	1.5971895	0.75211221	3009.4961
557.94214	1.5982248	0.75410026	3009.5283
558.94312	1.6017598	0.75613225	3012.2971
559.94409	1.6079361	0.75794899	3007.1638
560.94507	1.6097127	0.75996536	3015.4978
561.94604	1.6134763	0.76238561	3015.804
562.94702	1.6162688	0.76430255	3014.7874
563.948	1.6189942	0.7663849	3019.0591
564.94897	1.6230135	0.76816958	3014.9675
565.94995	1.6238126	0.77038717	3014.0093
566.95093	1.6290374	0.77206123	3013.5085
567.9519	1.6302918	0.77352649	3017.1458
568.95288	1.6340129	0.77529228	3012.8721
569.95386	1.6387093	0.77662951	3017.1021
570.95483	1.6416175	0.77846676	3017.9172
571.95581	1.6419524	0.78059918	3020.8545
572.95679	1.6463867	0.78247184	3017.6475
573.95776	1.6493132	0.78430051	3017
574.95874	1.6518431	0.78634983	3023.0549
575.95972	1.6553231	0.7882396	3020.4824
576.96069	1.6571395	0.78998888	3018.6604
577.96167	1.6597322	0.79159284	3014.7192
578.96265	1.6627443	0.79384911	3016.6982
579.96362	1.6665258	0.79513341	3018.6155
580.9646	1.6695253	0.79689419	3024.6963
581.96558	1.67363	0.79892039	3029.2012
582.96655	1.6754906	0.80058593	3022.1194
583.96753	1.6804444	0.80239236	3023.9631
584.96851	1.6836932	0.80449468	3032.5166
585.96948	1.6844108	0.80614114	3025.4011
586.97046	1.6868484	0.8083387	3026.0857
587.97144	1.6919088	0.81041449	3029.2368
588.97241	1.6925408	0.81214905	3020.4248
589.97339	1.6968197	0.81420767	3025.8479
590.97437	1.7002063	0.81612295	3032.4377
591.97534	1.7020495	0.81824553	3027.9929
592.97632	1.7068863	0.82083923	3030.6021
593.97729	1.7070106	0.8225596	3024.9758
594.97827	1.7123021	0.82456207	3028.9751
595.97925	1.7131014	0.82609481	3030.8665
596.98022	1.7173657	0.82787025	3029.7786
597.9812	1.7206643	0.8297742	3040.2788
598.98218	1.7255239	0.83156794	3039.9343
599.98315	1.7268977	0.83343196	3033.6245
600.98413	1.730647	0.83526963	3032.8184
601.98511	1.7326373	0.83691013	3031.5293
602.98608	1.7340735	0.83834368	3031.0698
603.98706	1.7400372	0.84066695	3043.4834
604.98804	1.7417279	0.84280771	3039.1018
605.98901	1.7470733	0.84481597	3035.9651
606.98999	1.7476925	0.84703815	3038.1714
607.99097	1.749848	0.84845716	3034.468
608.99194	1.7548867	0.85006392	3028.5391
609.99292	1.7571745	0.85176283	3038.7798
610.9939	1.7628365	0.85360545	3041.1948
611.99487	1.7625459	0.85520387	3039.0659
612.99585	1.7653549	0.85694033	3030.8318
613.99683	1.7681484	0.85893631	3041.198
614.9978	1.7713428	0.86073267	3038.1038
615.99878	1.7729526	0.86249012	3036.8765
616.99976	1.7761536	0.86445427	3042.0757
618.00073	1.7818013	0.8662852	3040.436
619.00171	1.7834326	0.86843157	3046.4548
620.00269	1.7877849	0.87051302	3045.7751
621.00366	1.7890167	0.87284565	3050.6008
622.00464	1.7923145	0.8747884	3043.6394
623.00562	1.7947036	0.87657005	3043.4431
624.00659	1.8008152	0.87842327	3049.1838
625.00757	1.8009791	0.88026762	3036.2588
626.00854	1.8057419	0.88219804	3050.4949
627.00952	1.8054399	0.88405371	3037.6228
628.0105	1.8112981	0.88613236	3046.8318
629.01147	1.8151941	0.8879956	3051.2434
630.01245	1.8172932	0.8900221	3044.6719
631.01343	1.8180519	0.8919068	3051.2913
632.0144	1.8231647	0.89380693	3048.1157
633.01538	1.824715	0.8953703	3042.813
634.01636	1.8287131	0.89677858	3049.332
635.01733	1.8312268	0.89876378	3053.0901
636.01831	1.8319571	0.90094167	3055.8584
637.01929	1.8380517	0.90287805	3052.5911
638.02026	1.8408209	0.90477175	3049.5344
639.02124	1.8441586	0.90649176	3052.5974
640.02222	1.8468285	0.90849453	3052.6619
641.02319	1.8488393	0.91050059	3054.6277
642.02417	1.8502183	0.91245466	3053.7058
643.02515	1.8529897	0.91416496	3047.0728
644.02612	1.8591617	0.9159326	3050.7292
645.0271	1.8610409	0.91807353	3062.2798
646.02808	1.8664336	0.92004681	3055.9661
647.02905	1.8679558	0.92172426	3052.0051
648.03003	1.8709944	0.92352438	3059.8545
649.03101	1.8721535	0.92549855	3061.4622
650.03198	1.8784028	0.92751557	3057.9805
651.03296	1.8793596	0.92924327	3056.0811
652.03394	1.8818436	0.93100083	3060.8162
653.03491	1.8854848	0.93311572	3061.8438
654.03589	1.8874302	0.93524259	3053.967
655.03687	1.8897443	0.93705779	3063.4006
656.03784	1.892785	0.9392091	3057.4448
657.03882	1.8955404	0.94107717	3059.9932
658.03979	1.8994843	0.94331348	3062.6587
659.04077	1.90443	0.94516271	3063.4434
660.04175	1.9069908	0.94721514	3064.3118
661.04272	1.9104661	0.94905531	3059.803
662.0437	1.9121807	0.95087367	3062.5359
663.04468	1.9157661	0.95304894	3062.2563
664.04565	1.918946	0.95521051	3063.3687
665.04663	1.9204447	0.95693982	3057.3716
666.04761	1.9225068	0.95896983	3060.9775
667.04858	1.9300964	0.9609552	3065.3245
668.04956	1.9313674	0.96276665	3065.5999
669.05054	1.9339198	0.9646647	3068.3064
670.05151	1.9370203	0.96661592	3061.0295
671.05249	1.9399675	0.96802199	3060.3179
672.05347	1.9402651	0.97007579	3064.5271
673.05444	1.9474648	0.97229463	3069.3982
674.05542	1.9478018	0.97424632	3062.6392
675.0564	1.9511524	0.9760536	3068.4185
676.05737	1.9570129	0.97816759	3072.2305
677.05835	1.9584211	0.98019981	3066.2161
678.05933	1.9595823	0.98189026	3070.1221
679.0603	1.9596721	0.98366785	3066.9326
680.06128	1.9677714	0.98556906	3075.9927
681.06226	1.9697479	0.98783547	3066.2363
682.06323	1.9715184	0.98952168	3068.8179
683.06421	1.9753903	0.99120659	3064.6941
684.06519	1.9796215	0.99344093	3073.5288
685.06616	1.9844358	0.9955709	3072.6274
686.06714	1.9838837	0.9970203	3068.0029
687.06812	1.9858133	0.99885637	3068.5386
688.06909	1.98877	1.0007937	3072.8203
689.07007	1.9918602	1.0029682	3075.3604
690.07104	1.9971642	1.0051545	3073.3755
691.07202	2.0001609	1.0071169	3075.0835
692.073	2.003185	1.0089202	3075.7007
693.07397	2.0055223	1.0108253	3070.6274
694.07495	2.0091124	1.0126321	3073.4771
695.07593	2.0097229	1.0150802	3073.0605
696.0769	2.0148394	1.01692	3073.1963
697.07788	2.0190108	1.0186979	3072.0303
698.07886	2.0234594	1.0209545	3079.8953
699.07983	2.0233521	1.0230238	3079.4055
700.08081	2.0273376	1.025084	3073.885
701.08179	2.0306892	1.0270512	3070.2515
702.08276	2.0313754	1.0290533	3078.3447
703.08374	2.0341687	1.030977	3073.4949
704.08472	2.0396399	1.0331843	3079.4846
705.08569	2.0435607	1.0348715	3076.6936
706.08667	2.0454712	1.0367584	3078.2654
707.08765	2.0462718	1.0386517	3084.218
708.08862	2.0492706	1.0406852	3083.5984
709.0896	2.0531328	1.0428569	3084.3855
710.09058	2.058759	1.0447248	3085.4214
711.09155	2.0597477	1.0467594	3077.8965
712.09253	2.0589538	1.0486487	3078.6489
713.09351	2.063894	1.0504045	3069.7021
714.09448	2.0700245	1.0519811	3076.8079
715.09546	2.072464	1.0537508	3082.5391
716.09644	2.0740263	1.0555881	3080.6223
717.09741	2.0790071	1.0575675	3084.5413
718.09839	2.0815084	1.0598875	3087.6616
719.09937	2.0851009	1.0622611	3087.9905
720.10034	2.0850604	1.0644766	3085.3542
721.10132	2.0883083	1.0670063	3084.2612
722.10229	2.0928175	1.0689861	3083.4302
723.10327	2.0957351	1.0711349	3087.8774
724.10425	2.1008074	1.0729252	3082.5347
725.10522	2.1013095	1.0745946	3076.1018
726.1062	2.1037607	1.0765151	3076.019
727.10718	2.1082323	1.078458	3089.3997
728.10815	2.1125114	1.0806017	3079.7876
729.10913	2.1143439	1.0826858	3085.9099
730.11011	2.1165452	1.0848323	3086.9849
731.11108	2.1201866	1.0864896	3089.2
732.11206	2.1232204	1.0883315	3089.8318
733.11304	2.1259246	1.0900133	3080.4607
734.11401	2.1300588	1.0919249	3093.2759
735.11499	2.1307893	1.094101	3091.9697
736.11597	2.1355546	1.0968312	3092.571
737.11694	2.1363018	1.098884	3083.3315
738.11792	2.1401372	1.1009514	3089.9023
739.1189	2.1442404	1.1027592	3087.4045
740.11987	2.1485875	1.1045831	3091.8782
741.12085	2.148495	1.1063912	3088.082
742.12183	2.1539211	1.1084478	3088.8748
743.1228	2.1548882	1.1107417	3090.7598
744.12378	2.1585371	1.1128967	3090.8787
745.12476	2.1632245	1.1150913	3097.1431
746.12573	2.1647036	1.1170099	3088.7817
747.12671	2.1677752	1.1195872	3095.5901
748.12769	2.1730208	1.1216238	3092.6951
749.12866	2.1735971	1.1234388	3091.9265
750.12964	2.1752193	1.1253706	3093.1782
751.13062	2.1800442	1.1273663	3088.0347
752.13159	2.1844726	1.1294241	3102.0962
753.13257	2.1853297	1.1312332	3089.165
754.13354	2.188308	1.1330229	3090.032
755.13452	2.1900203	1.1348472	3094.5415
756.1355	2.1936696	1.1368821	3090.7266
757.13647	2.1983433	1.1384679	3083.9202
758.13745	2.2012694	1.1400614	3087.7332
759.13843	2.203615	1.1416794	3089.2163
760.1394	2.2073822	1.1434972	3103.0837
761.14038	2.2093654	1.1457196	3099.9551
762.14136	2.2123013	1.1476443	3096.6602
763.14233	2.2145736	1.1501861	3100.2756
764.14331	2.2201269	1.1523015	3098.2451
765.14429	2.2238169	1.1547434	3099.5232
766.14526	2.2267604	1.1570733	3100.3408
767.14624	2.2264874	1.1593363	3095.4431
768.14722	2.2288859	1.1614778	3095.5994
769.14819	2.2338579	1.1637375	3096.0974
770.14917	2.237828	1.1659243	3098.0723
771.15015	2.2414031	1.1679823	3092.4875
772.15112	2.2435391	1.1698221	3090.5391
773.1521	2.245008	1.17168	3094.5598
774.15308	2.250675	1.1735766	3099.8391
775.15405	2.2514019	1.1757594	3101.2651
776.15503	2.2552867	1.1783173	3106.6543
777.15601	2.2608342	1.1805207	3102.6719
778.15698	2.2577665	1.1827683	3104.1204
779.15796	2.2650976	1.1849967	3095.4487
780.15894	2.2652364	1.1867305	3093.9207
781.15991	2.2704957	1.1889057	3098.7375
782.16089	2.2745154	1.1907969	3098.2043
783.16187	2.2734501	1.1929121	3103.1228
784.16284	2.2804646	1.1952355	3100.4919
785.16382	2.2827246	1.1969912	3099.1135
786.16479	2.2854781	1.1988933	3099.6663
787.16577	2.288254	1.2009833	3098.5876
788.16675	2.2893555	1.2032087	3103.4224
789.16772	2.295068	1.2054356	3096.3281
790.1687	2.2943854	1.2073001	3093.2153
791.16968	2.2991738	1.2090315	3099.5916
792.17065	2.3015347	1.2109952	3095.283
793.17163	2.3063595	1.2131946	3106.9014
794.17261	2.3093367	1.2152615	3105.3157
795.17358	2.3131189	1.2178537	3111.5593
796.17456	2.3130705	1.2199641	3098.4009
797.17554	2.3182654	1.2218415	3100.3687
798.17651	2.3215163	1.2238206	3106.9233
799.17749	2.3249471	1.2263422	3113.4404
800.17847	2.3283451	1.2283947	3099.2451
801.17944	2.3309147	1.2303914	3104.9246
802.18042	2.3334358	1.2324837	3101.9375
803.1814	2.3355775	1.2343667	3102.0444
804.18237	2.3384299	1.2361946	3107.0784
805.18335	2.3432994	1.2383939	3103.7393
806.18433	2.3423231	1.2411896	3107.3284
807.1853	2.3486929	1.2436993	3109.7725
808.18628	2.3514285	1.2461637	3108.5632
809.18726	2.3564224	1.2480718	3099.2644
810.18823	2.3557119	1.2502556	3101.3489
811.18921	2.3606308	1.2522229	3100.032
812.19019	2.362298	1.2541916	3100.166
813.19116	2.3636572	1.2560067	3097.1689
814.19214	2.3699021	1.2582122	3107.5498
815.19312	2.3723679	1.2602383	3105.1829
816.19409	2.3752146	1.2625587	3112.6411
817.19507	2.3761468	1.2647144	3103.0928
818.19604	2.3792014	1.2666976	3101.168
819.19702	2.3845685	1.269099	3110.1133
820.198	2.3842101	1.2713565	3107.4678
821.19897	2.3891454	1.2736045	3110.147
822.19995	2.3910322	1.2759478	3105.2605
823.20093	2.3982425	1.2780296	3107.4011
824.2019	2.4000905	1.2804798	3108.6592
825.20288	2.4029288	1.2821248	3099.7017
826.20386	2.4062378	1.2837813	3104.1433
827.20483	2.4106495	1.2857352	3113.3557
828.20581	2.4105427	1.2877803	3102.363
829.20679	2.4154875	1.2901034	3114.5508
830.20776	2.4188638	1.2924246	3115.1257
831.20874	2.4168966	1.2947251	3108.0779
832.20972	2.4237285	1.2971377	3103.8623
833.21069	2.4244258	1.2995509	3109.5415
834.21167	2.4267175	1.3016032	3097.843
835.21265	2.4324903	1.3037544	3102.5715
836.21362	2.4352269	1.3061017	3118.2129
837.2146	2.4363766	1.308502	3108.0303
838.21558	2.4426205	1.3109367	3107.7273
839.21655	2.4433532	1.3129271	3110.4409
840.21753	2.4469955	1.3153132	3114.8081
841.21851	2.4512208	1.3175982	3112.0293
842.21948	2.4557717	1.3196478	3109.4585
843.22046	2.4561067	1.322053	3111.9978
844.22144	2.4600294	1.3241237	3109.9668
845.22241	2.4632854	1.3264821	3107.6306
846.22339	2.4635382	1.3286934	3108.481
847.22437	2.4659171	1.3311039	3108.2764
848.22534	2.4711363	1.333421	3112.7595
849.22632	2.4735482	1.3358023	3106.4036
850.22729	2.4789379	1.3381726	3116.3608
851.22827	2.4778831	1.3402328	3104.5396
852.22925	2.483078	1.3427598	3106.3145
853.23022	2.4862034	1.3449166	3106.5996
854.2312	2.4900162	1.3469514	3104.1362
855.23218	2.4921739	1.3489834	3105.8987
856.23315	2.496233	1.351355	3105.6826
857.23413	2.4998729	1.3533926	3111.2915
858.23511	2.5001209	1.355625	3109.0054
859.23608	2.5041566	1.3579992	3111.9314
860.23706	2.5103228	1.36009	3115.3906
861.23804	2.5077257	1.3623271	3107.3511
862.23901	2.5158429	1.3644958	3110.3157
863.23999	2.51404	1.3671739	3109.2644
864.24097	2.5220089	1.3694338	3114.6697
865.24194	2.5234098	1.3718197	3115.1626
866.24292	2.5235527	1.3739494	3102.9922
867.2439	2.5287185	1.3762792	3114.936
868.24487	2.5330963	1.3785923	3112.9609
869.24585	2.5342939	1.3809129	3114.0918
870.24683	2.5333109	1.3832469	3105.4456
871.2478	2.5386405	1.3854342	3106.1074
872.24878	2.5452499	1.3879997	3116.481
873.24976	2.5461516	1.3904638	3109.5427
874.25073	2.5490444	1.3924944	3111.3201
875.25171	2.5512383	1.3950046	3115.7422
876.25269	2.5545783	1.3975773	3114.1804
877.25366	2.5584502	1.4000371	3112.3604
878.25464	2.5602722	1.4022019	3104.8691
879.25562	2.5637469	1.4041864	3106.125
880.25659	2.5671761	1.406835	3114.2478
881.25757	2.5694222	1.4092695	3110.8733
882.25854	2.5721943	1.4116267	3112.0715
883.25952	2.5781732	1.4136313	3115.6943
884.2605	2.5788746	1.4161818	3111.7493
885.26147	2.5824931	1.418465	3118.5852
886.26245	2.584486	1.421055	3109.4885
887.26343	2.5881641	1.4234819	3109.4663
888.2644	2.5911233	1.4255925	3114.5071
889.26538	2.5947235	1.4276748	3110.0842
890.26636	2.5962079	1.4299817	3117.4939
891.26733	2.6003907	1.4325825	3107.9766
892.26831	2.6031017	1.4351349	3108.8853
893.26929	2.6093714	1.4377977	3116.4087
894.27026	2.6078658	1.4403201	3105.5166
895.27124	2.6146407	1.4423871	3105.1421
896.27222	2.6119606	1.4442785	3105.3384
897.27319	2.6185563	1.4464514	3108.9187
898.27417	2.6206918	1.448969	3115.0605
899.27515	2.6232276	1.4512179	3108.9355
900.27612	2.6280897	1.4537511	3116.0161
901.2771	2.6296713	1.4560528	3104.6616
902.27808	2.6335981	1.458349	3112.9392
903.27905	2.6351001	1.4608313	3110.5808
904.28003	2.6387639	1.4632133	3106.041
905.28101	2.6436107	1.4653387	3110.2791
906.28198	2.6431227	1.4679811	3110.6746
907.28296	2.6495419	1.4705504	3108.5708
908.28394	2.6510227	1.4730251	3104.5217
909.28491	2.6548333	1.4752302	3112.5723
910.28589	2.6566312	1.4778337	3113.9309
911.28687	2.659595	1.480165	3105.2974
912.28784	2.6656148	1.4826205	3110.8147
913.28882	2.6663065	1.4852059	3111.7483
914.28979	2.6710322	1.4877738	3110.0146
915.29077	2.6731021	1.4902202	3111.76
916.29175	2.6765387	1.4926661	3113.9995
917.29272	2.6783614	1.4953908	3110.6187
918.2937	2.6798859	1.4978704	3107.0518
919.29468	2.6851034	1.5009015	3112.5935
920.29565	2.6870377	1.5039028	3111.5964
921.29663	2.6896229	1.5063424	3107.6094
922.29761	2.6944478	1.508852	3105.9551
923.29858	2.6968672	1.5109091	3104.1035
924.29956	2.7030122	1.5132103	3108.8899
925.30054	2.7033875	1.5155673	3111.2822
926.30151	2.7053571	1.5180111	3109.3904
927.30249	2.7066913	1.5208824	3111.0483
928.30347	2.7103305	1.5236567	3098.1472
929.30444	2.7115374	1.526388	3112.1685
930.30542	2.717833	1.5287555	3104.9495
931.3064	2.7221222	1.5312774	3105.823
932.30737	2.7227805	1.5335788	3106.5747
933.30835	2.7251966	1.53618	3109.6338
934.30933	2.728658	1.5389202	3111.3079
935.3103	2.733834	1.541615	3107.8413
936.31128	2.7379601	1.5437783	3104.3552
937.31226	2.7373016	1.5460638	3106.5396
938.31323	2.7401409	1.5487026	3103.8306
939.31421	2.743057	1.5509716	3101.9604
940.31519	2.7464612	1.5535169	3102.6611
941.31616	2.7531791	1.5558612	3106.0405
942.31714	2.7527792	1.5583918	3105.7996
943.31812	2.7555504	1.5610944	3102.988
944.31909	2.7598426	1.5639995	3118.6785
945.32007	2.7647905	1.5667256	3105.8516
946.32104	2.7666912	1.5691994	3110.1816
947.32202	2.7702267	1.5718565	3104.6033
948.323	2.7719479	1.5742218	3103.9863
949.32397	2.7739942	1.5769488	3103.3992
950.32495	2.774776	1.5797518	3102.1169
951.32593	2.7834904	1.5820181	3106.26
952.3269	2.7834303	1.5844811	3100.5735
953.32788	2.7868485	1.587271	3107.3862
954.32886	2.7907817	1.5903041	3112.637
955.32983	2.7923219	1.5932285	3104.2681
956.33081	2.7946794	1.5958384	3097.3359
957.33179	2.8000131	1.5987152	3104.9036
958.33276	2.802717	1.6012897	3105.4619
959.33374	2.8063793	1.6039414	3108.9441
960.33472	2.8059561	1.6068851	3104.3904
961.33569	2.8127017	1.6098194	3104.8689
962.33667	2.8110986	1.6121814	3099.0667
963.33765	2.8167717	1.6148533	3098.8516
964.33862	2.8173683	1.617118	3099.0657
965.3396	2.820461	1.6196312	3106.5732
966.34058	2.8250761	1.6227126	3104.9724
967.34155	2.8261025	1.6256599	3103.4678
968.34253	2.827981	1.6286443	3091.5933
969.34351	2.8363042	1.6311101	3095.6362
970.34448	2.8384538	1.6335889	3102.5244
971.34546	2.8398812	1.6365579	3101.3176
972.34644	2.8409443	1.6394111	3098.606
973.34741	2.8482363	1.6426067	3095.9419
974.34839	2.8486724	1.6454358	3093.8738
975.34937	2.8529844	1.6475948	3100.6348
976.35034	2.8570817	1.6499796	3097.4133
977.35132	2.8565116	1.6526771	3101.7268
978.35229	2.8624384	1.6557455	3100.9041
979.35327	2.8650923	1.6584165	3097.5667
980.35425	2.8698635	1.6612309	3093.1511
981.35522	2.8711572	1.664005	3095.2659
982.3562	2.8722777	1.6670063	3094.0098
983.35718	2.876193	1.6698427	3092.5459
984.35815	2.8810806	1.6723034	3100.5657
985.35913	2.8810959	1.6753523	3096.1582
986.36011	2.8871412	1.6782373	3095.6858
987.36108	2.8870244	1.6811135	3093.5164
988.36206	2.8908584	1.6835947	3086.8691
989.36304	2.8924265	1.6863025	3087.874
990.36401	2.8991611	1.6889042	3095.1079
991.36499	2.9023602	1.6913933	3092.2927
992.36597	2.9032502	1.6942155	3092.4534
993.36694	2.904423	1.6972175	3091.2397
994.36792	2.9106259	1.7003677	3092.6055
995.3689	2.9137855	1.7034152	3089.269
996.36987	2.9186554	1.7065666	3094.9487
997.37085	2.9181876	1.7094973	3091.9753
998.37183	2.9238102	1.7124133	3093.0449
999.3728	2.9296548	1.7153322	3092.3198
1000.3738	2.9252045	1.7175702	3081.73
1001.3748	2.9300289	1.7198863	3086.6152
1002.3757	2.9359105	1.7227405	3091.6836
1003.3767	2.9371924	1.7257565	3088.791
1004.3777	2.939714	1.7287773	3087.9771
1005.3787	2.9403715	1.7317656	3079.5291
1006.3796	2.9476235	1.7348968	3088.5251
1007.3806	2.949676	1.7379527	3087.321
1008.3816	2.9500835	1.7406652	3078.7505
1009.3826	2.952399	1.7437249	3080.0513
1010.3835	2.958473	1.7470294	3084.467
1011.3845	2.9592278	1.7493932	3079.9319
1012.3855	2.9637671	1.751701	3077.436
1013.3865	2.9672945	1.7545782	3081.0769
1014.3875	2.9700961	1.7569494	3076.2651
1015.3884	2.9721467	1.7599443	3084.3093
1016.3894	2.9748683	1.7630028	3074.8789
1017.3904	2.9808657	1.7663043	3083.9409
1018.3914	2.9818101	1.7696639	3081.3792
1019.3923	2.9851472	1.7723509	3080.5984
1020.3933	2.9879436	1.775915	3078.9536
1021.3943	2.9906249	1.779557	3080.5244
1022.3953	2.9942715	1.783132	3076.3813
1023.3962	2.9980564	1.7863292	3070.2312
1024.3972	3.0017753	1.7891333	3081.9604
1025.3982	3.001967	1.7914886	3067.594
1026.3992	3.0035405	1.7936835	3069.9895
1027.4001	3.0097907	1.7961589	3067.6545
1028.4011	3.0138869	1.7989047	3074.6531
1029.4021	3.0153053	1.8022716	3070.6475
1030.4031	3.018276	1.8056424	3071.9358
1031.4041	3.0217838	1.8090088	3070.0806
1032.405	3.023586	1.8121369	3067.2444
1033.406	3.0284929	1.8160539	3074.2153
1034.407	3.0322983	1.8191223	3064.4734
1035.408	3.0320826	1.8226168	3062.032
1036.4089	3.0338881	1.8256551	3058.4663
1037.4099	3.0400512	1.8285428	3061.1682
1038.4109	3.0423014	1.831162	3062.7915
1039.4119	3.0487208	1.8336461	3068.4932
1040.4128	3.0447731	1.8360491	3057.771
1041.4138	3.0507729	1.8388112	3058.502
1042.4148	3.0559032	1.8413804	3058.6423
1043.4158	3.0589688	1.844065	3060.553
1044.4167	3.0624888	1.8466032	3060.7942
1045.4177	3.0631888	1.8495588	3056.6667
1046.4187	3.0632181	1.8520606	3053.7974
1047.4197	3.0709865	1.8552353	3062.4324
1048.4207	3.0729294	1.8585021	3059.521
1049.4216	3.0757575	1.860974	3046.1899
1050.4226	3.0782287	1.8632544	3042.4688
1051.4236	3.079602	1.8656806	3046.1484
1052.4246	3.083708	1.8683547	3053.8506
1053.4255	3.0849211	1.8714972	3052.1575
1054.4265	3.0891097	1.8743834	3046.2148
1055.4275	3.093056	1.8771497	3050.5845
1056.4285	3.0955224	1.880136	3046.4463
1057.4294	3.0978503	1.8836075	3045.7273
1058.4304	3.1028278	1.8870658	3048.687
1059.4314	3.1053762	1.8904914	3039.5635
1060.4324	3.1090276	1.8932585	3041.4043
1061.4333	3.1102581	1.8958089	3034.7014
1062.4343	3.1127162	1.8987917	3041.0439
1063.4353	3.1170585	1.9017252	3035.5637
1064.4363	3.1210475	1.904599	3041.1047
1065.4373	3.1249061	1.9075642	3038.8987
1066.4382	3.1276431	1.9110937	3036.4639
1067.4392	3.128711	1.9143382	3037.4976
1068.4402	3.1326168	1.9170964	3026.1018
1069.4412	3.1364286	1.9197415	3033.6438
1070.4421	3.1389019	1.922817	3028.3457
1071.4431	3.142401	1.9257555	3026.6321
1072.4441	3.1434507	1.9289647	3025.6553
1073.4451	3.1458836	1.9322288	3023.9932
1074.446	3.1507099	1.9348359	3020.6345
1075.447	3.1528924	1.9374774	3025.1484
1076.448	3.1562686	1.9406986	3026.8164
1077.449	3.1593215	1.9438467	3025.1475
1078.45	3.1655698	1.9470018	3018.3296
1079.4509	3.1646259	1.9504259	3015.0049
1080.4519	3.1687093	1.9535409	3020.4377
1081.4529	3.1697395	1.9565822	3018.3689
1082.4539	3.1726494	1.9598321	3012.9519
1083.4548	3.1786284	1.962907	3011.7646
1084.4558	3.1780965	1.9656725	3006.0557
1085.4568	3.1832244	1.9684522	3001.3579
1086.4578	3.1880112	1.9714212	3009.8015
1087.4587	3.1888916	1.9744974	3008.0872
1088.4597	3.1938765	1.9778	3007.2559
1089.4607	3.1962359	1.9808284	3005.6438
1090.4617	3.199533	1.9844061	3002.9695
1091.4626	3.1996608	1.9876018	2998.6038
1092.4636	3.2036681	1.9907932	2999.8674
1093.4646	3.2061644	1.9946142	3001.9741
1094.4656	3.2075517	1.9974954	2993.7996
1095.4666	3.2111263	2.000865	2995.6357
1096.4675	3.2176793	2.0040443	2993.3538
1097.4685	3.2202847	2.0076001	2992.6707
1098.4695	3.2236052	2.0104685	2987.8674
1099.4705	3.2261229	2.0132992	2989.3298
1100.4714	3.2296712	2.0165701	2988.4382
1101.4724	3.2301755	2.0204694	2987.1033
1102.4734	3.2327089	2.0237627	2976.7341
1103.4744	3.2389934	2.0263171	2977.241
1104.4753	3.2420194	2.0289083	2978.9429
1105.4763	3.2426901	2.0315733	2975.6177
1106.4773	3.2453074	2.0342898	2972.3093
1107.4783	3.2489476	2.0371022	2972.269
1108.4792	3.2525861	2.0399673	2969.7344
1109.4802	3.2540128	2.0432985	2971.2515
1110.4812	3.2588806	2.0464411	2966.7793
1111.4822	3.2609799	2.0486915	2963.7087
1112.4832	3.2621963	2.0500891	2964.4072
1113.4841	3.2655306	2.0515902	2963.2231
1114.4851	3.2717748	2.0530436	2962.7576
1115.4861	3.2715359	2.0544281	2960.3232
1116.4871	3.2767971	2.0556064	2956.9255
1117.488	3.2765758	2.0564334	2956.4438
1118.489	3.2824273	2.0569282	2951.9116
1119.49	3.2847061	2.0573699	2945.5515
1120.491	3.290359	2.0577505	2950.9373
1121.4919	3.2908108	2.0581713	2950.9116
1122.4929	3.2941895	2.0580721	2955.5066
1123.4939	3.2972257	2.0585396	2944.0215
1124.4949	3.298589	2.0588481	2939.0417
1125.4958	3.3025243	2.0588701	2942.9663
1126.4968	3.3046532	2.0591626	2936.9294
1127.4978	3.3083112	2.0595224	2932.2314
1128.4988	3.3130915	2.0595393	2940.354
1129.4998	3.3160748	2.0596929	2932.2117
1130.5007	3.3176017	2.0598109	2921.2539
1131.5017	3.3203268	2.0597503	2924.4128
1132.5027	3.3206933	2.0597005	2933.1008
1133.5037	3.3266866	2.0599568	2922.0906
1134.5046	3.3312201	2.0599844	2927.5803
1135.5056	3.3326144	2.0600274	2919.3784
1136.5066	3.3358431	2.0601215	2920.6084
1137.5076	3.3380928	2.0602584	2911.749
1138.5085	3.3450665	2.0601752	2908.3013
1139.5095	3.3461549	2.0605721	2904.4319
1140.5105	3.3461747	2.0607455	2906.2305
1141.5115	3.3520021	2.060585	2899.6143
1142.5125	3.3549917	2.0606086	2906.4382
1143.5134	3.3573771	2.0609031	2905.009
1144.5144	3.3600967	2.0607364	2892.0994
1145.5154	3.3640401	2.0606992	2890.594
1146.5164	3.3675125	2.0609066	2888.991
1147.5173	3.3730559	2.0608447	2893.78
1148.5183	3.3744586	2.0606847	2886.5198
1149.5193	3.377151	2.0609	2883.9624
1150.5203	3.376173	2.0610693	2877.5278
1151.5212	3.3796937	2.0607123	2878.5884
1152.5222	3.3819351	2.060801	2872.4275
1153.5232	3.3857932	2.0610433	2872.1746
1154.5242	3.3865967	2.0604537	2859.9524
1155.5251	3.3935664	2.0604389	2861.946
1156.5261	3.3942149	2.0607922	2865.6221
1157.5271	3.3998234	2.0605567	2865.6018
1158.5281	3.402488	2.0605772	2859.6262
1159.5291	3.403347	2.0607405	2857.9976
1160.53	3.4107139	2.0608292	2859.4482
1161.531	3.4121408	2.0607173	2856.4358
1162.532	3.4156823	2.0608115	2847.8767
1163.533	3.4177284	2.0609734	2847.0906
1164.5339	3.4199529	2.0609164	2841.2271
1165.5349	3.4205928	2.0609741	2835.7046
1166.5359	3.423887	2.0610397	2836.3977
1167.5369	3.4274321	2.0612116	2827.947
1168.5378	3.4311991	2.0609355	2829.9253
1169.5388	3.433126	2.0612283	2819.511
1170.5398	3.4364107	2.0612898	2827.9409
1171.5408	3.4393606	2.0611815	2815.9788
1172.5417	3.4420233	2.061204	2807.9741
1173.5427	3.4488323	2.0608785	2808.7139
1174.5437	3.4507618	2.0610189	2810.1375
1175.5447	3.4528403	2.0608938	2798.7773
1176.5457	3.4546623	2.0609326	2804.4719
1177.5466	3.4582741	2.0609202	2794.8884
1178.5476	3.4612398	2.0607989	2791.6418
1179.5486	3.4654701	2.0604689	2789.5713
1180.5496	3.4668565	2.0606296	2788.8049
1181.5505	3.4695034	2.0606179	2785.5396
1182.5515	3.4743071	2.0602713	2781.394
1183.5525	3.47895	2.0604668	2770.0417
1184.5535	3.4821634	2.0606668	2768.5037
1185.5544	3.483542	2.0605464	2766.3289
1186.5554	3.4869297	2.0604861	2770.645
1187.5564	3.4902833	2.0602627	2767.8804
1188.5574	3.4894528	2.0600412	2759.1084
1189.5583	3.494514	2.0602417	2756.3965
1190.5593	3.5012531	2.0599928	2754.4697
1191.5603	3.5025589	2.0601039	2742.9458
1192.5613	3.5034101	2.0600541	2741.6853
1193.5623	3.5067677	2.0599828	2733.9243
1194.5632	3.5090954	2.0598125	2737.9314
1195.5642	3.513041	2.0600214	2726.9023
1196.5652	3.5146101	2.0598412	2730.739
1197.5662	3.5197124	2.0597878	2715.446
1198.5671	3.5235534	2.0595431	2714.4802
1199.5681	3.5244575	2.0598075	2709.7625
1200.5691	3.5300503	2.0597177	2715.9954
1201.5701	3.5330021	2.0593634	2707.9729
1202.571	3.5308573	2.0596886	2696.8867
1203.572	3.5363367	2.0594063	2694.3208
1204.573	3.5403924	2.0592647	2685.1492
1205.574	3.5442889	2.0596864	2681.6682
1206.575	3.5492935	2.059777	2680.2698
1207.5759	3.5493805	2.0598099	2676.7344
1208.5769	3.5525081	2.0598083	2668.5332
1209.5779	3.556205	2.0599301	2664.0088
1210.5789	3.5568709	2.0599723	2650.1685
1211.5798	3.5611269	2.0598741	2653.1484
1212.5808	3.5655267	2.0597291	2647.8716
1213.5818	3.5689025	2.0597847	2641.2837
1214.5828	3.5703163	2.0598414	2639.6733
1215.5837	3.5746667	2.0598066	2638.6812
1216.5847	3.5780418	2.060179	2628.5015
1217.5857	3.5784571	2.0599983	2620.575
1218.5867	3.5828614	2.0598147	2612.6833
1219.5876	3.5844359	2.0600162	2596.5439
1220.5886	3.5881269	2.0595922	2600.7649
1221.5896	3.5941358	2.0595396	2597.8323
1222.5906	3.5965984	2.0595813	2594.1226
1223.5916	3.6016879	2.0597763	2590.1863
1224.5925	3.6003518	2.0598092	2570.9851
1225.5935	3.6018209	2.0594616	2556.0237
1226.5945	3.6054876	2.0596564	2548.9541
1227.5955	3.6100254	2.059763	2546.8198
1228.5964	3.6120396	2.0597053	2524.8372
1229.5974	3.6173654	2.059797	2500.2651
1230.5984	3.6195278	2.0600908	2482.1257
1231.5994	3.6230235	2.0600133	2452.5208
1232.6003	3.6267114	2.0600603	2430.3806
1233.6013	3.6246905	2.0603571	2415.4519
1234.6023	3.6297469	2.0604093	2386.7788
1234.9026	3.6340578	2.0601461	2363.344