File: datasets/am_bench_2022/raw_data/60-X.12-2/specimen.dat
MTS793|MPT|ENU|1|2|.|/|:|1|0|0|A

Operator Information						Time:	23.110107	Sec	11/1/2021 9:36:13 AM
Operator	Nick Derimow
Project	AM Bench 2022 mini-tensile challenge
Specimen ID	60-X.12-2
Material	PBF-L Inconel 625
Specimen Width	2.54	mm
Specimen Thickness	1.52	mm
Notes
Operator Information End

Data Acquisition						Time:	1024.1038	Sec	11/1/2021 9:52:54 AM
Time	Axial Displacement	Axial Extensometer	Axial Force
Sec	mm	mm	N
23.223633	0.0035649322	-6.7848227e-06	47.092968
24.124512	0.0062938239	0.00015488849	54.761951
25.025391	0.0095894439	0.00028965654	68.718079
25.92627	0.0087901643	0.00017608958	82.03862
26.827148	0.016092017	0.00036278932	94.074646
27.728027	0.017354708	0.00036567828	108.67202
28.628906	0.019790042	0.0004655073	120.86189
29.529785	0.024519028	0.00056037179	128.83469
30.430664	0.022275319	0.00052338897	142.62637
31.331543	0.028964547	0.00076845603	159.96294
32.232422	0.032034788	0.00069043867	168.43945
33.133301	0.033145092	0.00085803738	182.49751
34.03418	0.034251247	0.00071034173	191.43434
34.935059	0.03799824	0.0008577219	214.66428
35.835938	0.041930508	0.0010526859	227.8746
36.736816	0.042572841	0.00090168329	243.10864
37.637695	0.046094663	0.0012470024	258.57288
38.538574	0.047807705	0.001110961	273.60114
39.439453	0.054167673	0.0014659991	296.38852
40.340332	0.051524989	0.0012755181	311.00531
41.241211	0.05399413	0.0015577646	329.69693
42.14209	0.05909279	0.0015657758	350.6048
43.042969	0.061593641	0.0016841486	371.75858
43.943848	0.065528311	0.0018915454	399.12531
44.844727	0.068901435	0.0017098255	407.64359
45.745605	0.07129164	0.0020512803	432.43579
46.646484	0.069995344	0.0019269781	445.05478
47.547363	0.07626839	0.0023043791	465.97604
48.448242	0.07699924	0.0020391589	484.04514
49.349121	0.081439786	0.002406291	513.61755
50.25	0.087265402	0.0023096611	532.97327
51.150879	0.084569238	0.002558199	549.76648
52.051758	0.088217072	0.0025547652	567.74677
52.952637	0.092159532	0.0027125056	593.7605
53.853516	0.095053002	0.0026944096	614.96979
54.754395	0.097640365	0.0029860565	640.60675
55.655273	0.098598994	0.0029890807	659.54572
56.556152	0.10231648	0.0031820522	674.71442
57.457031	0.10310511	0.0031470649	712.37592
58.35791	0.10598788	0.0033767046	730.07275
59.258789	0.11114227	0.0034022781	753.9281
60.159668	0.11114186	0.0035960549	776.12671
61.060547	0.11609586	0.0035724514	809.17377
61.961426	0.11609996	0.0038312583	826.88928
62.862305	0.11884668	0.0038544151	848.61731
63.763184	0.12632842	0.0041017034	882.20929
64.664063	0.12614793	0.00407928	906.63037
65.564941	0.12917247	0.0041521136	932.83673
66.46582	0.13022316	0.0043483521	952.34827
67.366699	0.13504356	0.0045019528	976.9527
68.267578	0.1361801	0.004547664	1004.5428
69.168457	0.13769506	0.0046533453	1023.4145
70.069336	0.1430127	0.0046650325	1053.4346
70.970215	0.14210545	0.0049088662	1074.1429
71.871094	0.14646506	0.0049590059	1101.8811
72.771973	0.15006377	0.0052602827	1131.186
73.672852	0.15578033	0.0053219334	1165.6853
74.57373	0.15655747	0.00562103	1188.8474
75.474609	0.15720677	0.0054697571	1216.3252
76.375488	0.16220218	0.0058461204	1234.4906
77.276367	0.16466005	0.0057626609	1254.3071
78.177246	0.16598359	0.0060450961	1282.0934
79.078125	0.16937551	0.0060713137	1314.2034
79.979004	0.17319974	0.006203148	1339.9172
80.879883	0.1723347	0.0063986559	1357.4602
81.780762	0.17640465	0.0064439042	1383.178
82.681641	0.17850986	0.0066419528	1400.9922
83.58252	0.18329605	0.0066110971	1429.7639
84.483398	0.18525025	0.0069737867	1459.0239
85.384277	0.19088885	0.0068385517	1481.7659
86.285156	0.19271152	0.0071364767	1498.8022
87.186035	0.19557932	0.0071454057	1525.5396
88.086914	0.19568996	0.0074136253	1550.7209
88.987793	0.19809334	0.0074709202	1573.5284
89.888672	0.20206428	0.007586367	1591.8219
90.789551	0.2027355	0.007658836	1621.8743
91.69043	0.2063321	0.0079115005	1647.7662
92.591309	0.21089701	0.008033135	1665.696
93.492188	0.21487246	0.0081287436	1690.1895
94.393066	0.21567933	0.0081882225	1711.7087
95.293945	0.2154308	0.0083696069	1734.3494
96.194824	0.21867232	0.0083878869	1758.3387
97.095703	0.22623597	0.0085828882	1785.7426
97.996582	0.2255879	0.0087244781	1813.8292
98.897461	0.22805111	0.0086945072	1825.6196
99.79834	0.2311634	0.0088472757	1848.2761
100.69922	0.2331844	0.0089836819	1867.0541
101.6001	0.23869468	0.0091507202	1895.2753
102.50098	0.23991659	0.0091912551	1915.5634
103.40186	0.24383207	0.0093960948	1935.2346
104.30273	0.24574365	0.0094299959	1952.9722
105.20361	0.24687669	0.0094421655	1965.353
106.10449	0.25205752	0.0096934419	1994.2047
107.00537	0.25505564	0.0097837439	2008.4672
107.90625	0.25622618	0.0097641163	2024.9586
108.80713	0.26050547	0.0098219803	2034.7858
109.70801	0.25850478	0.010006147	2058.24
110.60889	0.26466656	0.010067002	2069.759
111.50977	0.2651538	0.010088073	2077.6882
112.41064	0.26836991	0.010205282	2097.407
113.31152	0.27204198	0.010287164	2112.9783
114.2124	0.2769824	0.010359735	2126.6223
115.11328	0.28014198	0.010331595	2145.4883
116.01416	0.27741554	0.010486267	2154.4255
116.91504	0.28282398	0.01051954	2164.2681
117.81592	0.28617802	0.010646182	2184.5605
118.7168	0.28698426	0.010725789	2187.4949
119.61768	0.29066056	0.010805176	2190.033
120.51855	0.2912066	0.010761161	2202.3579
121.41943	0.29750162	0.010924018	2215.6409
122.32031	0.29891148	0.010898194	2222.4458
123.22119	0.30441168	0.01116632	2241.7388
124.12207	0.308332	0.011140508	2250.155
125.02295	0.30582091	0.011222902	2259.0835
125.92383	0.30958349	0.011258561	2268.7708
126.82471	0.31381461	0.011363161	2271.8779
127.72559	0.31835598	0.01141276	2287.8069
128.62646	0.31847975	0.011434368	2290.3311
129.52734	0.31915238	0.011546914	2299.7507
130.42822	0.32323909	0.011634601	2307.114
131.3291	0.32488561	0.011606417	2317.6006
132.22998	0.33326691	0.011857918	2335.7532
133.13086	0.3333126	0.011830361	2342.0876
134.03174	0.33599257	0.011891351	2347.7813
134.93262	0.33800071	0.012023668	2365.2581
135.8335	0.34104946	0.01211407	2367.4458
136.73438	0.3452054	0.01210315	2375.9443
137.63525	0.34415412	0.012249693	2375.5254
138.53613	0.34912553	0.012358354	2384.8455
139.43701	0.35081261	0.01233959	2392.1992
140.33789	0.35595942	0.012480635	2406.8088
141.23877	0.35455653	0.012642085	2413.4861
142.13965	0.35785091	0.012666277	2421.3447
143.04053	0.3598049	0.012788551	2422.7151
143.94141	0.36713341	0.012861478	2437.4927
144.84229	0.36937696	0.012948081	2448.1611
145.74316	0.37068984	0.013042592	2455.3276
146.64404	0.37128896	0.013121482	2462.4243
147.54492	0.37807366	0.013231844	2469.5295
148.4458	0.37993237	0.013337754	2474.8857
149.34668	0.38241503	0.01348927	2482.0098
150.24756	0.38597229	0.013530649	2492.7996
151.14844	0.38889953	0.013771397	2498.8867
152.04932	0.38975945	0.01379355	2505.9553
152.9502	0.39084619	0.013758062	2498.5576
153.85107	0.39422378	0.013977913	2509.1521
154.75195	0.39861271	0.014101567	2523.7825
155.65283	0.4029133	0.014214883	2529.4124
156.55371	0.40452704	0.014347068	2536.1897
157.45459	0.40666112	0.014466166	2540.0447
158.35547	0.41116971	0.014719326	2554.6519
159.25635	0.40818408	0.014725452	2556.4854
160.15723	0.41491464	0.014931206	2565.5076
161.05811	0.41743746	0.015073797	2570.8198
161.95898	0.42047471	0.015282942	2578.116
162.85986	0.42366993	0.01536961	2585.5425
163.76074	0.42559099	0.015628371	2591.8203
164.66162	0.42708707	0.015672566	2591.8074
165.5625	0.43265721	0.01585741	2599.6958
166.46338	0.4328199	0.016112881	2611.6287
167.36426	0.43629029	0.016393468	2616.4529
168.26514	0.43760687	0.01650632	2616.5767
169.16602	0.43813589	0.016871743	2629.6304
170.06689	0.44004896	0.017020911	2631.7102
170.96777	0.44918907	0.017320359	2641.7954
171.86865	0.44809741	0.017532529	2645.2034
172.76953	0.45096377	0.017834218	2655.7329
173.67041	0.45536047	0.018061683	2663.4316
174.57129	0.45630032	0.018449679	2663.2913
175.47217	0.46122175	0.018782698	2671.9309
176.37305	0.46437538	0.018990155	2674.5986
177.27393	0.4657543	0.019340057	2686.9026
178.1748	0.46910113	0.019523764	2675.3474
179.07568	0.4723466	0.019810218	2684.9485
179.97656	0.47087857	0.020269616	2698.3345
180.87744	0.4755201	0.020718073	2699.698
181.77832	0.47877681	0.021110151	2711.5811
182.6792	0.47905853	0.02149415	2706.0603
183.58008	0.48602334	0.021915155	2713.0854
184.48096	0.4890866	0.022253539	2719.6699
185.38184	0.49071625	0.022590214	2729.0034
186.28271	0.49135593	0.022993896	2723.2249
187.18359	0.4936884	0.023485454	2731.2283
188.08447	0.49820006	0.023940774	2740.1628
188.98535	0.49532604	0.024478352	2740.3513
189.88623	0.50006765	0.02487121	2744.7993
190.78711	0.50864834	0.025375953	2752.6602
191.68799	0.50470459	0.025863022	2752.3174
192.58887	0.51104063	0.026326312	2751.438
193.48975	0.5171209	0.02684439	2766.0974
194.39063	0.51263303	0.027398933	2765.366
195.2915	0.52043641	0.028006362	2771.7363
196.19238	0.52097338	0.028499108	2774.574
197.09326	0.52296042	0.029084126	2775.0005
197.99414	0.5260762	0.029609153	2783.8936
198.89502	0.53309155	0.030305691	2785.1868
199.7959	0.53164995	0.030777903	2785.6006
200.69678	0.53784847	0.031437848	2798.8704
201.59766	0.53654903	0.03191011	2795.3215
202.49854	0.54059911	0.032587919	2801.7771
203.39941	0.54392034	0.033259455	2810.5276
204.30029	0.54751736	0.034013774	2811.0088
205.20117	0.54953098	0.034696519	2812.1814
206.10205	0.55241197	0.035384253	2810.0742
207.00293	0.55504149	0.035964847	2818.4485
207.90381	0.55882412	0.036727164	2834.0601
208.80469	0.56239122	0.037421145	2827.0256
209.70557	0.56165564	0.038099721	2821.4954
210.60645	0.56712192	0.038752649	2826.8831
211.50732	0.56891918	0.039473746	2836.8079
212.4082	0.57168704	0.040219784	2837.4885
213.30908	0.57197815	0.040866133	2833.2766
214.20996	0.57569832	0.041530453	2845.0791
215.11084	0.57981807	0.042339493	2842.4016
216.01172	0.58348697	0.043137711	2851.3938
216.9126	0.5863384	0.043943793	2853.3403
217.81348	0.5867101	0.044815671	2852.8098
218.71436	0.59091336	0.045581829	2860.9341
219.61523	0.58963442	0.046256762	2855.7708
220.51611	0.59717107	0.047098469	2857.7102
221.41699	0.59825474	0.047895614	2858.3037
222.31787	0.59918553	0.048525855	2865.3174
223.21875	0.60125595	0.049137998	2863.2896
224.11963	0.60962152	0.050109606	2879.0613
225.02051	0.60613024	0.050745349	2871.7209
225.92139	0.61330318	0.051645555	2878.1748
226.82227	0.61359227	0.052428521	2873.5891
227.72314	0.61593312	0.053325903	2885.7979
228.62402	0.61936873	0.054129377	2889.5891
229.5249	0.62425286	0.055009156	2887.4119
230.42578	0.62442249	0.055825885	2887.9385
231.32666	0.62838989	0.05680865	2895.4182
232.22754	0.63144892	0.057467613	2891.8108
233.12842	0.63475239	0.058342852	2898.7236
234.0293	0.63576126	0.059154812	2897.3691
234.93018	0.63884681	0.059760131	2898.6646
235.83105	0.6389333	0.060742162	2903.2573
236.73193	0.64571291	0.061695673	2905.2856
237.63281	0.64787287	0.062567174	2912.7981
238.53369	0.65214431	0.063363343	2917.1672
239.43457	0.65361315	0.064430237	2918.4666
240.33545	0.6551168	0.065279961	2910.6926
241.23633	0.65740669	0.066147216	2917.1565
242.13721	0.66065586	0.067194372	2924.8689
243.03809	0.66231257	0.068267204	2921.866
243.93896	0.66502017	0.069055215	2922.6833
244.83984	0.66884542	0.070034847	2930.9753
245.74072	0.67012352	0.070878215	2928.8447
246.6416	0.67476696	0.071957335	2933.9604
247.54248	0.67638797	0.072952799	2935.3762
248.44336	0.68049991	0.073858254	2938.8218
249.34424	0.68060601	0.074843995	2936.9075
250.24512	0.68385309	0.075780228	2939.5879
251.146	0.68884128	0.076742768	2939.1143
252.04688	0.69134879	0.07784915	2954.1006
252.94775	0.69182086	0.078861296	2940.8779
253.84863	0.69830555	0.079699717	2943.6431
254.74951	0.69795907	0.080648594	2951.3938
255.65039	0.70262069	0.081560649	2955.2253
256.55127	0.70424896	0.082591668	2954.3906
257.45215	0.70700979	0.083652519	2960.957
258.35303	0.70885319	0.0844981	2949.7976
259.25391	0.71170729	0.085511953	2956.5352
260.15479	0.71597838	0.086360909	2960.4631
261.05566	0.71680188	0.08717373	2953.4941
261.95654	0.71961558	0.088009901	2966.8
262.85742	0.72285503	0.08884266	2964.7456
263.7583	0.72658819	0.089816473	2969.1211
264.65918	0.72926176	0.090635918	2971.9238
265.56006	0.73047185	0.091652669	2970.052
266.46094	0.73382336	0.092692129	2970.7839
267.36182	0.73559427	0.093782812	2979.8228
268.2627	0.73939532	0.094773427	2979.6807
269.16357	0.741023	0.095750466	2978.3557
270.06445	0.7462427	0.096692689	2981.3181
270.96533	0.74671704	0.097779088	2987.1675
271.86621	0.75007248	0.098632663	2985.9597
272.76709	0.75079346	0.099592455	2984.4702
273.66797	0.75380331	0.10048681	2984.8191
274.56885	0.75918162	0.10154714	2994.4553
275.46973	0.76334906	0.10278914	3000.2207
276.37061	0.76440978	0.10378661	2998.1079
277.27148	0.76463187	0.10488714	2995.4128
278.17236	0.76954347	0.10602386	2994.145
279.07324	0.77263027	0.10722172	2998.9172
279.97412	0.77312714	0.10823572	3000.3147
280.875	0.77754229	0.10924992	2996.8232
281.77588	0.77957648	0.11018424	3001.4668
282.67676	0.78244352	0.11134075	3000.9468
283.57764	0.78301978	0.11233913	2997.8096
284.47852	0.78888702	0.11334243	3010.7908
285.37939	0.79024357	0.11439862	3009.2336
286.28027	0.79358059	0.11552735	3017.2329
287.18115	0.79878151	0.11651737	3011.8813
288.08203	0.79983318	0.11738979	3015.0005
288.98291	0.79894626	0.11829644	3011.6443
289.88379	0.80422515	0.1194066	3021.4402
290.78467	0.8082189	0.1205128	3022.9304
291.68555	0.80996674	0.12179702	3023.145
292.58643	0.81262684	0.12277152	3023.7493
293.4873	0.81412309	0.12387282	3020.9949
294.38818	0.81343919	0.12482622	3022.5916
295.28906	0.81444257	0.12599868	3030.2698
296.18994	0.82053924	0.12697391	3024.4211
297.09082	0.82520396	0.12801307	3027.6694
297.9917	0.82831866	0.12886225	3031.6301
298.89258	0.83043939	0.1297998	3034.7986
299.79346	0.83461326	0.13070624	3039.5391
300.69434	0.83410144	0.13185203	3033.4358
301.59521	0.84093034	0.13287507	3041.4939
302.49609	0.84033638	0.13399814	3041.7759
303.39697	0.84231949	0.13492163	3033.4341
304.29785	0.84525102	0.1357868	3038.593
305.19873	0.84779191	0.13678767	3041.9861
306.09961	0.85248405	0.13797078	3050.1926
307.00049	0.85727185	0.13917592	3054.7979
307.90137	0.85854173	0.14032774	3055.6853
308.80225	0.85825574	0.1413641	3041.2185
309.70313	0.86328614	0.1422593	3048.2849
310.604	0.8667537	0.14321612	3057.7903
311.50488	0.87158722	0.14422548	3054.7605
312.40576	0.87079531	0.14543638	3056.0381
313.30664	0.87414837	0.14638886	3054.8022
314.20752	0.87801456	0.14745928	3056.2532
315.1084	0.88104755	0.14853737	3055.0803
316.00928	0.88227439	0.14950195	3058.873
316.91016	0.88253033	0.150475	3060.6523
317.81104	0.88916421	0.15159197	3071.8833
318.71191	0.88971704	0.15272006	3060.5161
319.61279	0.89375269	0.15367667	3065.999
320.51367	0.89922792	0.15475938	3076.05
321.41455	0.8980844	0.15574118	3069.4463
322.31543	0.89869112	0.15668842	3069.0332
323.21631	0.90492421	0.15792866	3080.5146
324.11719	0.90556204	0.15907151	3077.9817
325.01807	0.91111904	0.16000363	3077.3335
325.91895	0.90961617	0.16092737	3072.5854
326.81982	0.91499126	0.16193978	3086.4763
327.7207	0.92056113	0.16309851	3083.303
328.62158	0.91964614	0.16409057	3080.095
329.52246	0.92146778	0.16519292	3086.3499
330.42334	0.92421061	0.16640422	3085.1252
331.32422	0.92617548	0.16750981	3084.9438
332.2251	0.9325428	0.16848722	3087.8206
333.12598	0.93478513	0.16950119	3089.6042
334.02686	0.93827575	0.17046472	3096.6636
334.92773	0.94037676	0.17156076	3096.9148
335.82861	0.94030768	0.17256278	3087.896
336.72949	0.94257212	0.17360628	3093.4568
337.63037	0.94611037	0.17480005	3096.2551
338.53125	0.95172817	0.1758239	3097.2397
339.43213	0.95248336	0.17669214	3092.5569
340.33301	0.95352876	0.17762329	3091.8342
341.23389	0.95970058	0.17862533	3108.7183
342.13477	0.95827127	0.17971522	3100.7351
343.03564	0.96450251	0.1811398	3108.1831
343.93652	0.9633202	0.18204722	3100.8855
344.8374	0.96729338	0.18303582	3104.9961
345.73828	0.96878988	0.18411429	3102.5701
346.63916	0.97133458	0.1852894	3107.2886
347.54004	0.98010194	0.1863791	3108.7876
348.44092	0.97979504	0.18764722	3119.8411
349.3418	0.98034745	0.18878734	3107.1697
350.24268	0.9808318	0.1898969	3117.6797
351.14355	0.98749369	0.19088764	3111.1697
352.04443	0.99120426	0.19202931	3120.8525
352.94531	0.99399751	0.19312024	3120.7422
353.84619	0.99671006	0.19403023	3120.7927
354.74707	0.99713647	0.19496648	3116.7988
355.64795	1.0001067	0.19609436	3122.4395
356.54883	1.0022795	0.1970918	3126.822
357.44971	1.0072157	0.1982758	3126.8667
358.35059	1.0124657	0.19926694	3124.771
359.25146	1.0137572	0.20021009	3133.1357
360.15234	1.0123336	0.20128083	3126.7085
361.05322	1.0185118	0.20238855	3135.4263
361.9541	1.0208945	0.20357727	3136.6333
362.85498	1.0222062	0.20468166	3137.4307
363.75586	1.0270139	0.20568307	3127.5771
364.65674	1.0293754	0.20671789	3143.0146
365.55762	1.029557	0.20769769	3140.5872
366.4585	1.0314499	0.20865983	3133.6672
367.35938	1.0374589	0.20978056	3147.4973
368.26025	1.0383182	0.21074381	3135.8472
369.16113	1.0415472	0.21177177	3143.0994
370.06201	1.0431266	0.21287355	3146.2708
370.96289	1.0491197	0.21385853	3147.895
371.86377	1.0506949	0.21500783	3146.4336
372.76465	1.0530286	0.21596362	3143.0674
373.66553	1.0528914	0.21689369	3142.8953
374.56641	1.0581592	0.21780828	3148.5466
375.46729	1.0614256	0.21888082	3152.991
376.36816	1.0646919	0.2199786	3159.4602
377.26904	1.0623742	0.22101967	3145.5862
378.16992	1.069474	0.22200349	3154.1189
379.0708	1.0703366	0.22305125	3154.7764
379.97168	1.0727317	0.22404505	3160.0437
380.87256	1.0737187	0.22511801	3154.4146
381.77344	1.0775177	0.22617278	3158.7915
382.67432	1.0832802	0.22725981	3161.9011
383.5752	1.0857059	0.22848065	3164.7278
384.47607	1.0866334	0.22944154	3160.2563
385.37695	1.0902759	0.23061599	3168.9741
386.27783	1.0929917	0.23191245	3167.2205
387.17871	1.0929204	0.23301859	3167.7197
388.07959	1.1007026	0.23425522	3170.2063
388.98047	1.1028289	0.23523396	3168.1265
389.88135	1.1034141	0.23609579	3163.2244
390.78223	1.1043756	0.2372719	3174.7864
391.68311	1.1078678	0.23846859	3174.5837
392.58398	1.1144242	0.23945463	3167.5
393.48486	1.113636	0.24024175	3168.8318
394.38574	1.1175196	0.24118081	3178.9124
395.28662	1.117386	0.24246162	3178.0273
396.1875	1.1244555	0.24351664	3180.0361
397.08838	1.1259036	0.24448746	3177.032
397.98926	1.1263524	0.24541736	3174.292
398.89014	1.1300516	0.24646878	3184.9102
399.79102	1.1334993	0.24750294	3183.0352
400.69189	1.1351422	0.24854076	3181.2119
401.59277	1.1367414	0.2496338	3183.7107
402.49365	1.1385913	0.25060436	3183.5005
403.39453	1.1439446	0.25168732	3186.7488
404.29541	1.1474016	0.25267556	3191.3923
405.19629	1.15405	0.25360951	3195.2974
406.09717	1.1529609	0.25455528	3193.7078
406.99805	1.1546677	0.25561607	3191.0332
407.89893	1.1603107	0.25682649	3197.207
408.7998	1.1625004	0.25786141	3192.917
409.70068	1.1620996	0.25886768	3191.0176
410.60156	1.1681913	0.25992453	3202.5193
411.50244	1.168354	0.26106831	3206.2751
412.40332	1.1685176	0.26207015	3193.8391
413.3042	1.174682	0.26309478	3199.7151
414.20508	1.1747065	0.26398885	3196.8728
415.10596	1.180014	0.26483071	3197.9014
416.00684	1.1819093	0.26595193	3205.9817
416.90771	1.18527	0.267111	3210.3601
417.80859	1.1893634	0.26817834	3205.7678
418.70947	1.1906879	0.26901215	3196.3303
419.61035	1.1921234	0.26985678	3202.6914
420.51123	1.1946599	0.27093974	3205.2061
421.41211	1.2008082	0.27190605	3212.5825
422.31299	1.1997895	0.2730189	3210.4927
423.21387	1.2019577	0.27422571	3215.821
424.11475	1.2076113	0.27513939	3217.071
425.01563	1.2095555	0.27616423	3212.3857
425.9165	1.2102189	0.27732396	3214.0793
426.81738	1.2157544	0.278485	3221.3367
427.71826	1.2202255	0.27964926	3226.03
428.61914	1.2222135	0.28068259	3219.3162
429.52002	1.2213708	0.28161192	3217.4526
430.4209	1.2241403	0.28250611	3219.3525
431.32178	1.2281352	0.28374091	3225.5488
432.22266	1.2295684	0.28493115	3224.8965
433.12354	1.2348379	0.28594464	3224.834
434.02441	1.2332329	0.28693712	3220.9648
434.92529	1.2383398	0.28794852	3231.9497
435.82617	1.2411339	0.28918713	3230.7061
436.72705	1.2451928	0.29019544	3231.7593
437.62793	1.2475537	0.29108649	3229.2329
438.52881	1.2484651	0.29204455	3231.5298
439.42969	1.2488037	0.29292607	3230.8738
440.33057	1.2568907	0.29394498	3232.8459
441.23145	1.2586719	0.2947717	3231.3306
442.13232	1.2598305	0.2956427	3232.2285
443.0332	1.2621658	0.29659057	3236.8135
443.93408	1.2641907	0.29770881	3239.8645
444.83496	1.2703339	0.29865125	3238.9741
445.73584	1.2728112	0.2997902	3247.7043
446.63672	1.2756568	0.3008405	3244.697
447.5376	1.2745889	0.30189073	3241.6506
448.43848	1.280095	0.30297896	3246.8413
449.33936	1.2813091	0.30411494	3243.582
450.24023	1.2828625	0.30513623	3243.4368
451.14111	1.2871536	0.30608544	3234.2595
452.04199	1.2923931	0.30703798	3249.3052
452.94287	1.2925605	0.30792746	3247.604
453.84375	1.2924373	0.30888206	3243.7771
454.74463	1.3001019	0.30980098	3245.5698
455.64551	1.3022139	0.31091306	3254.2444
456.54639	1.304076	0.31199625	3258.1606
457.44727	1.3045646	0.31301099	3258.5293
458.34814	1.3097303	0.31427497	3261.6021
459.24902	1.3128313	0.31538403	3255.2556
460.1499	1.3142958	0.3164902	3257.3513
461.05078	1.3191516	0.31746742	3257.3828
461.95166	1.319098	0.31828663	3257.6636
462.85254	1.3245753	0.31955993	3265.0295
463.75342	1.3240354	0.32072261	3260.6724
464.6543	1.3284761	0.32193148	3264.8086
465.55518	1.332013	0.32317287	3267.3818
466.45605	1.3324096	0.32413998	3256.542
467.35693	1.3383684	0.32505089	3269.0166
468.25781	1.3388745	0.32608518	3271.5378
469.15869	1.3392886	0.32723102	3264.6123
470.05957	1.3420457	0.32832983	3266.7151
470.96045	1.34892	0.32928586	3269.2217
471.86133	1.3495982	0.33030242	3277.8987
472.76221	1.3515786	0.33142403	3275.0674
473.66309	1.3520627	0.33251128	3274.9832
474.56396	1.3581643	0.33354139	3270.9519
475.46484	1.3615193	0.33476478	3280.8743
476.36572	1.3632302	0.33577126	3276.4055
477.2666	1.3685591	0.33676881	3276.4561
478.16748	1.3682704	0.33772644	3278.8276
479.06836	1.372242	0.3387675	3283.9963
479.96924	1.3747228	0.33973873	3280.4463
480.87012	1.3770312	0.34075779	3278.7415
481.771	1.3771671	0.34157208	3277.1465
482.67188	1.3826169	0.34261775	3288.813
483.57275	1.3841317	0.34365106	3283.1875
484.47363	1.3853598	0.34467772	3284.8125
485.37451	1.3936787	0.34556526	3290.791
486.27539	1.3913727	0.34669274	3282.5791
487.17627	1.3951215	0.34805629	3298.4771
488.07715	1.3981787	0.349188	3293.781
488.97803	1.402535	0.35028332	3287.0276
489.87891	1.4033525	0.35115883	3286.5103
490.77979	1.4073094	0.3520059	3288.5308
491.68066	1.4096676	0.35293996	3294.3687
492.58154	1.411134	0.35386854	3291.4463
493.48242	1.4145538	0.35496455	3298.8298
494.3833	1.4207251	0.3560032	3300.322
495.28418	1.4197959	0.35713094	3301.9829
496.18506	1.4222362	0.35837135	3298.5625
497.08594	1.4243217	0.3595064	3298.6912
497.98682	1.4304564	0.36072719	3302.9219
498.8877	1.4331957	0.36169618	3298.6414
499.78857	1.4334164	0.362542	3300.6306
500.68945	1.4350988	0.36351743	3304.7791
501.59033	1.4408906	0.36448961	3307.2722
502.49121	1.4436375	0.36569163	3307.2405
503.39209	1.4425873	0.36678302	3299.5601
504.29297	1.4478768	0.36762023	3297.5176
505.19385	1.4505855	0.36860159	3312.4607
506.09473	1.4507961	0.36961162	3303.1013
506.99561	1.4549476	0.37076059	3312.5291
507.89648	1.4552567	0.37201926	3312.4426
508.79736	1.4621881	0.37310651	3312.6272
509.69824	1.4631619	0.37422258	3307.8569
510.59912	1.4625311	0.37521669	3310.5657
511.5	1.4708463	0.37619972	3314.4678
512.40088	1.469956	0.37698698	3308.3474
513.30176	1.4722825	0.37794781	3316.7278
514.20264	1.4753034	0.37892783	3319.3582
515.10352	1.4809617	0.37972936	3315.3098
516.00439	1.4804338	0.38080668	3317.9246
516.90527	1.4833677	0.38186312	3322.5408
517.80615	1.490281	0.38296649	3328.8579
518.70703	1.4882724	0.38397914	3318.4072
519.60791	1.4929415	0.3851158	3322.6333
520.50879	1.4927893	0.38614723	3320.2371
521.40967	1.4968715	0.38711742	3321.345
522.31055	1.5003303	0.38814771	3323.1021
523.21143	1.5019346	0.38908756	3322.1882
524.1123	1.5074826	0.39024803	3328.2568
525.01318	1.5103453	0.39129934	3329.0486
525.91406	1.5094366	0.3924627	3336.8372
526.81494	1.5144373	0.39373854	3326.6042
527.71582	1.5191894	0.3947759	3332.5286
528.6167	1.519249	0.39579496	3323.1924
529.51758	1.5240082	0.39681444	3337.5005
530.41846	1.5238864	0.39789376	3329.5073
531.31934	1.5276383	0.39917669	3335.2744
532.22021	1.5303097	0.40030062	3333.8179
533.12109	1.5327126	0.40125605	3333.5313
534.02197	1.5366801	0.40259191	3340.1709
534.92285	1.5412698	0.40371153	3337.3335
535.82373	1.5420811	0.40468237	3336.2939
536.72461	1.5473204	0.40598655	3342.6428
537.62549	1.5500659	0.40690759	3343.7207
538.52637	1.5510012	0.40811133	3346.7256
539.42725	1.5503117	0.40913996	3344.9155
540.32813	1.5548371	0.41012093	3335.9707
541.229	1.55686	0.4110716	3336.2769
542.12988	1.5611942	0.41218799	3354.1733
543.03076	1.5675284	0.41311014	3350.4695
543.93164	1.5684547	0.41417122	3349.8965
544.83252	1.5689129	0.41511551	3345.4124
545.7334	1.5735534	0.4160912	3352.8157
546.63428	1.5729368	0.41705441	3350.1624
547.53516	1.5765147	0.41823566	3352.1519
548.43604	1.5794717	0.41920695	3341.9631
549.33691	1.5797566	0.42004654	3345.9763
550.23779	1.5868533	0.42118219	3360.635
551.13867	1.5895362	0.42247221	3353.3296
552.03955	1.5887291	0.42357507	3351.22
552.94043	1.5949302	0.42465034	3351.3276
553.84131	1.596694	0.42570508	3355.8845
554.74219	1.5993979	0.42678192	3356.7773
555.64307	1.6048336	0.42792726	3367.2651
556.54395	1.6033818	0.42908233	3361.1023
557.44482	1.6047438	0.43003002	3352.4644
558.3457	1.6082439	0.43097836	3360.6387
559.24658	1.6098984	0.43192998	3356.103
560.14746	1.6122845	0.43293628	3359.2358
561.04834	1.6177922	0.43404868	3359.0205
561.94922	1.6217048	0.43504697	3361.9724
562.8501	1.6224818	0.43610591	3368.5767
563.75098	1.6261075	0.43733272	3372.1042
564.65186	1.6285563	0.43841523	3367.7271
565.55273	1.6305238	0.43950784	3367.3857
566.45361	1.6334734	0.44079581	3375.9626
567.35449	1.6342565	0.44195399	3368.8987
568.25537	1.6388545	0.44303393	3363.5161
569.15625	1.6409295	0.44420084	3374.3352
570.05713	1.6454954	0.44550425	3372.6653
570.95801	1.6460439	0.44657028	3368.1392
571.85889	1.6489227	0.44769078	3375.4712
572.75977	1.6526672	0.44857311	3371.6504
573.66064	1.658756	0.44974461	3372.9063
574.56152	1.6599696	0.45083931	3377.0872
575.4624	1.6618915	0.45177963	3374.405
576.36328	1.6616999	0.45271915	3380.0691
577.26416	1.6647913	0.45380521	3373.8291
578.16504	1.6692624	0.45480514	3379.7344
579.06592	1.6729004	0.45591453	3378.3879
579.9668	1.6713243	0.4568544	3373.2676
580.86768	1.6771693	0.4579466	3379.0271
581.76855	1.6776454	0.45883229	3377.5095
582.66943	1.6836193	0.45976052	3379.1787
583.57031	1.6839364	0.4607195	3376.3096
584.47119	1.6868207	0.46172753	3384.1628
585.37207	1.6894394	0.46292618	3387.4666
586.27295	1.6937485	0.46393028	3386.3184
587.17383	1.6927034	0.46501026	3392.0527
588.07471	1.6986417	0.46622747	3394.4185
588.97559	1.7027253	0.46733755	3389.0193
589.87646	1.7024766	0.46857676	3391.5168
590.77734	1.7100656	0.46971563	3391.6521
591.67822	1.7109202	0.47089481	3392.5952
592.5791	1.710718	0.47216105	3395.1638
593.47998	1.71522	0.47320092	3395.0005
594.38086	1.7165427	0.47411603	3385.2034
595.28174	1.7191784	0.47493127	3387.1658
596.18262	1.724339	0.47621924	3398.3997
597.0835	1.7220441	0.47749403	3403.2744
597.98438	1.7304484	0.47883302	3402.3621
598.88525	1.7315724	0.47979105	3393.4504
599.78613	1.7320975	0.48091766	3391.2087
600.68701	1.7389476	0.48188815	3398.8738
601.58789	1.7428259	0.48310974	3404.5095
602.48877	1.7437173	0.48425367	3399.9648
603.38965	1.7418178	0.48526788	3394.7864
604.29053	1.7464015	0.48649248	3401.7502
605.19141	1.750964	0.48768592	3400.2432
606.09229	1.7532207	0.48876843	3395.6743
606.99316	1.7543613	0.48977906	3405.7168
607.89404	1.7598246	0.4907712	3396.668
608.79492	1.7595187	0.49178851	3401.5024
609.6958	1.7638876	0.49291179	3403.0503
610.59668	1.7634732	0.49390212	3400.3083
611.49756	1.7714109	0.49510005	3410.3574
612.39844	1.7713726	0.49608347	3403.8799
613.29932	1.7761443	0.49710196	3408.4209
614.2002	1.7771486	0.49825761	3412.0444
615.10107	1.7785072	0.49946222	3414.0752
616.00195	1.7844031	0.50064629	3410.1807
616.90283	1.7847934	0.50173408	3409.0957
617.80371	1.7896663	0.50279725	3416.3066
618.70459	1.7936832	0.50408876	3421.4333
619.60547	1.7919707	0.50499928	3408.2432
620.50635	1.7968045	0.50608981	3416.3887
621.40723	1.8015568	0.5070613	3411.9971
622.30811	1.8034936	0.50823855	3421.584
623.20898	1.804023	0.5093497	3422.4363
624.10986	1.80797	0.51076514	3422.4297
625.01074	1.8074456	0.51177597	3411.2888
625.91162	1.8136997	0.51312125	3419.0701
626.8125	1.8130146	0.5141741	3413.0688
627.71338	1.8196597	0.51515788	3421.781
628.61426	1.8211247	0.51642489	3419.991
629.51514	1.8244694	0.51727271	3415.856
630.41602	1.8264158	0.51823944	3422.9763
631.31689	1.8281866	0.51927274	3419.0718
632.21777	1.8318996	0.52032596	3417.6941
633.11865	1.8320459	0.5212127	3425.6316
634.01953	1.8355714	0.52242845	3426.7937
634.92041	1.8395132	0.52359396	3430.0364
635.82129	1.8407981	0.52479607	3429.6182
636.72217	1.8448594	0.52624935	3430.0601
637.62305	1.844895	0.52753937	3423.7554
638.52393	1.8494958	0.52863955	3424.6543
639.4248	1.8524859	0.52981633	3425.1543
640.32568	1.8548809	0.53101945	3429.8694
641.22656	1.858683	0.53230315	3434.5767
642.12744	1.8584825	0.53362381	3433.2227
643.02832	1.8619034	0.53496611	3430.04
643.9292	1.8675879	0.53627998	3433.0908
644.83008	1.8678776	0.53725964	3427.2983
645.73096	1.8726654	0.53824824	3429.0894
646.63184	1.8756558	0.53915507	3431.0176
647.53271	1.8751047	0.54024655	3436.4956
648.43359	1.8809007	0.54132593	3435.2598
649.33447	1.8821961	0.54241979	3435.3408
650.23535	1.8839362	0.5434804	3431.9465
651.13623	1.8877134	0.54469305	3438.9233
652.03711	1.8928511	0.54556775	3433.4731
652.93799	1.8920282	0.54662776	3440.1292
653.83887	1.8945136	0.54780966	3443.196
654.73975	1.8945943	0.54917687	3441.8794
655.64063	1.9018387	0.55028462	3436.8296
656.5415	1.9038745	0.55128968	3435.5676
657.44238	1.9056334	0.55236256	3444.0952
658.34326	1.9073211	0.55353183	3437.0239
659.24414	1.9132513	0.5547269	3444.1045
660.14502	1.9174819	0.55573916	3444.0637
661.0459	1.9151663	0.55683726	3438.5122
661.94678	1.9201145	0.55795413	3441.2739
662.84766	1.9219301	0.55901319	3440.874
663.74854	1.9256622	0.56046885	3456.2153
664.64941	1.9276916	0.56177473	3451.8008
665.55029	1.9318992	0.56304473	3448.2271
666.45117	1.9343269	0.5643782	3446.9968
667.35205	1.9379057	0.56559938	3450.0623
668.25293	1.9381831	0.5667547	3446.6653
669.15381	1.9417652	0.56790906	3445.0823
670.05469	1.9476234	0.56889832	3447.7793
670.95557	1.9461197	0.56998122	3442.6946
671.85645	1.9534431	0.57123017	3451.4648
672.75732	1.9534016	0.57237595	3449.7993
673.6582	1.9554634	0.57367837	3454.4995
674.55908	1.9588754	0.57492125	3455.2112
675.45996	1.9628561	0.57613349	3452.6135
676.36084	1.9631457	0.57713169	3448.979
677.26172	1.967523	0.57830596	3456.8625
678.1626	1.9674426	0.57957357	3455.0283
679.06348	1.9714992	0.58064622	3447.1895
679.96436	1.9747376	0.58184052	3452.7437
680.86523	1.9779634	0.5831148	3461.9656
681.76611	1.9832666	0.58432174	3460.4019
682.66699	1.9809732	0.58551729	3459.1089
683.56787	1.985213	0.58667868	3451.4697
684.46875	1.9866188	0.58780324	3455.1323
685.36963	1.9900544	0.58905864	3459.2888
686.27051	1.9941243	0.59014732	3454.8188
687.17139	1.9955583	0.59112805	3456.0532
688.07227	1.9995729	0.59237051	3461.6011
688.97314	2.0000229	0.5936895	3464.8652
689.87402	2.0023355	0.59506547	3462.6531
690.7749	2.0092263	0.596358	3463.1433
691.67578	2.0088251	0.59748119	3460.7998
692.57666	2.0138316	0.59858543	3461.6304
693.47754	2.0133662	0.59976816	3469.9863
694.37842	2.016279	0.60088724	3461.8337
695.2793	2.0207896	0.60193342	3461.7876
696.18018	2.0216479	0.60312241	3466.7656
697.08105	2.0260119	0.60421801	3466.7021
697.98193	2.0276165	0.60536605	3462.0581
698.88281	2.0331554	0.60660321	3471.4858
699.78369	2.0330319	0.60775346	3467.196
700.68457	2.0385268	0.60903764	3471.2361
701.58545	2.0392339	0.61023492	3462.2517
702.48633	2.0438752	0.61151123	3474.8604
703.38721	2.0451162	0.61264741	3470.7957
704.28809	2.0449083	0.61411691	3471.5337
705.18896	2.0508742	0.61551803	3472.1599
706.08984	2.0515091	0.61658227	3461.3162
706.99072	2.056339	0.61768162	3474.4712
707.8916	2.0580077	0.619039	3476.7529
708.79248	2.0621088	0.62048584	3476.3003
709.69336	2.063957	0.621813	3471.5425
710.59424	2.0701051	0.62303036	3477.1936
711.49512	2.0706611	0.62410343	3469.7854
712.396	2.0707362	0.62533641	3473.9893
713.29688	2.0736682	0.62647903	3466.2271
714.19775	2.0770652	0.62766707	3469.98
715.09863	2.0788031	0.62898326	3475.1611
715.99951	2.0820925	0.63014108	3471.2861
716.90039	2.0835905	0.63116664	3478.645
717.80127	2.0880644	0.6326077	3481.074
718.70215	2.0915484	0.63380474	3471.4915
719.60303	2.0938249	0.63486362	3480.6958
720.50391	2.0969391	0.63613677	3488.2646
721.40479	2.0967836	0.63737381	3480.1672
722.30566	2.1021018	0.63885915	3483.0752
723.20654	2.1046486	0.64012408	3480.4995
724.10742	2.1083822	0.64144117	3476.5781
725.0083	2.1092737	0.64261574	3476.7075
725.90918	2.1125495	0.64374286	3479.5786
726.81006	2.1138482	0.64491153	3479.9998
727.71094	2.1200957	0.64627022	3480.5371
728.61182	2.1199257	0.64764905	3485.8037
729.5127	2.1242411	0.6486792	3480.5161
730.41357	2.1281097	0.64986539	3486.9426
731.31445	2.1266961	0.6510855	3478.5525
732.21533	2.1300321	0.6522122	3475.5601
733.11621	2.1316161	0.65348411	3478.6223
734.01709	2.135895	0.6547668	3483.6848
734.91797	2.1400561	0.65622222	3487.0801
735.81885	2.1398942	0.65749705	3483.7217
736.71973	2.1433868	0.65862823	3479.7607
737.62061	2.1458886	0.65977663	3480.679
738.52148	2.1480873	0.66101575	3482.1475
739.42236	2.1533916	0.66236383	3487.8933
740.32324	2.1553137	0.66366857	3488.748
741.22412	2.1590376	0.66481084	3487.5837
742.125	2.1603231	0.66606617	3492.2039
743.02588	2.1637769	0.66731834	3490.3606
743.92676	2.1662304	0.66885018	3490.6973
744.82764	2.1667554	0.67023879	3494.8232
745.72852	2.1699672	0.67175388	3493.0283
746.62939	2.1747842	0.67301106	3491.7551
747.53027	2.1786761	0.67423445	3492.3564
748.43115	2.1785932	0.67560059	3485.4224
749.33203	2.1808922	0.67696178	3490.4834
750.23291	2.1820295	0.6782192	3484.113
751.13379	2.1877873	0.67957324	3489.7249
752.03467	2.1917953	0.68076992	3491.7573
752.93555	2.1932509	0.68216205	3498.5352
753.83643	2.1961198	0.68337041	3490.7585
754.7373	2.1988313	0.68456739	3489.6726
755.63818	2.2026608	0.68572325	3495.688
756.53906	2.2044296	0.68697989	3495.0278
757.43994	2.2084937	0.68839449	3503.3867
758.34082	2.2092662	0.69001794	3499.3938
759.2417	2.2138932	0.69133633	3494.2666
760.14258	2.2147603	0.69278133	3500.3318
761.04346	2.2190142	0.69413131	3492.6267
761.94434	2.2208078	0.69523603	3484.1101
762.84521	2.2227571	0.69644529	3496.6519
763.74609	2.228334	0.69756055	3500.2637
764.64697	2.2272303	0.6989314	3494.7246
765.54785	2.2302146	0.70020604	3495.2935
766.44873	2.2335174	0.70144171	3494.5913
767.34961	2.237118	0.70271409	3500.2664
768.25049	2.23928	0.70392072	3495.1792
769.15137	2.2399838	0.70514184	3503.9858
770.05225	2.2429492	0.70634365	3493.188
770.95313	2.24771	0.70767897	3499.9431
771.854	2.2464428	0.70880312	3495.7375
772.75488	2.2523713	0.71009248	3500.49
773.65576	2.2554791	0.71130967	3500.5369
774.55664	2.2581894	0.71273899	3503.4856
775.45752	2.2593942	0.71418208	3496.9705
776.3584	2.2667036	0.7153905	3499.9568
777.25928	2.2643974	0.71659195	3497.6152
778.16016	2.2683411	0.7179175	3499.9854
779.06104	2.2703261	0.71913552	3509.2927
779.96191	2.2759159	0.72084391	3508.7771
780.86279	2.2759809	0.72252387	3502.2849
781.76367	2.2779918	0.72397691	3504.22
782.66455	2.282156	0.72540742	3506.0476
783.56543	2.2876811	0.7265619	3511.1321
784.46631	2.2867129	0.72812259	3502.1013
785.36719	2.2907996	0.72920585	3503.1252
786.26807	2.2945473	0.73029959	3499.4761
787.16895	2.2961409	0.73141968	3502.0916
788.06982	2.298105	0.73235393	3505.7549
788.9707	2.3011837	0.73363847	3510.1306
789.87158	2.300945	0.73485434	3504.3621
790.77246	2.3069098	0.73595613	3503.7263
791.67334	2.3092473	0.73725957	3507.0503
792.57422	2.3122511	0.73849165	3505.8093
793.4751	2.3134501	0.73997056	3507.4229
794.37598	2.3182936	0.74101174	3508.1741
795.27686	2.3220727	0.74248582	3507.5923
796.17773	2.3220537	0.74371952	3514.6138
797.07861	2.3281467	0.74513638	3511.783
797.97949	2.3257108	0.74654585	3511.9468
798.88037	2.3291731	0.74800825	3511.876
799.78125	2.3327405	0.74934465	3505.5537
800.68213	2.3358407	0.75087464	3516.0862
801.58301	2.3381264	0.75231045	3511.1235
802.48389	2.3403757	0.75360566	3508.1912
803.38477	2.3444705	0.75485837	3513.6284
804.28564	2.3462903	0.75614113	3513.635
805.18652	2.349566	0.75751323	3509.0554
806.0874	2.352016	0.75902915	3507.6814
806.98828	2.3556273	0.76034224	3510.9053
807.88916	2.3585629	0.76177472	3517.9553
808.79004	2.3601027	0.76336741	3516.1687
809.69092	2.3633835	0.76513529	3515.8472
810.5918	2.3659608	0.76663399	3516.7043
811.49268	2.3670878	0.76806915	3506.0322
812.39355	2.3705344	0.7694416	3510.8547
813.29443	2.3746233	0.77090645	3514.0437
814.19531	2.3771591	0.77241099	3512.7974
815.09619	2.3793628	0.77373922	3518.7952
815.99707	2.3830237	0.77579379	3518.1931
816.89795	2.385452	0.77724797	3515.6926
817.79883	2.386472	0.77881163	3518.6145
818.69971	2.3911424	0.78013623	3509.7166
819.60059	2.393307	0.781636	3517.1724
820.50146	2.3959229	0.78320211	3516.804
821.40234	2.3974614	0.7847985	3515.5647
822.30322	2.4011085	0.78642654	3514.1494
823.2041	2.40504	0.78774899	3517.9536
824.10498	2.4055583	0.78957325	3514.8865
825.00586	2.4074247	0.7911672	3515.2764
825.90674	2.4126308	0.79302621	3525.7061
826.80762	2.4139156	0.79449064	3516.6548
827.7085	2.4188941	0.79604667	3519.2891
828.60938	2.4192195	0.79741871	3517.3279
829.51025	2.4200749	0.79881883	3513.7705
830.41113	2.4241612	0.80004287	3511.1555
831.31201	2.4277515	0.80132771	3518.4473
832.21289	2.4322848	0.8026368	3516.6008
833.11377	2.4349372	0.8039903	3515.6008
834.01465	2.4360178	0.80556893	3515.4954
834.91553	2.4395621	0.80690658	3521.3184
835.81641	2.4405198	0.80873394	3517.4629
836.71729	2.4413047	0.81012213	3514.1675
837.61816	2.4471214	0.81176639	3516.0679
838.51904	2.4483409	0.81327462	3518.7625
839.41992	2.4523823	0.81486166	3518.739
840.3208	2.453985	0.81653243	3517.1057
841.22168	2.4576449	0.81873494	3523.1326
842.12256	2.4617865	0.82028782	3523.8442
843.02344	2.4654055	0.82236642	3522.9849
843.92432	2.4632566	0.82414472	3513.7766
844.8252	2.4680705	0.82589173	3517.9749
845.72607	2.4702306	0.82764781	3515.4851
846.62695	2.4735239	0.82943857	3517.9194
847.52783	2.4762194	0.83106768	3520.2852
848.42871	2.4824286	0.83278185	3524.2876
849.32959	2.4809339	0.83428562	3517.1951
850.23047	2.4838364	0.83595401	3518.8074
851.13135	2.4869471	0.83740836	3517.1804
852.03223	2.4922748	0.83932608	3524.0081
852.93311	2.49505	0.84085256	3522.5979
853.83398	2.4963932	0.84228623	3518.3679
854.73486	2.4973075	0.84393281	3522.1218
855.63574	2.496469	0.84539944	3522.3518
856.53662	2.5028944	0.84673905	3518.8674
857.4375	2.5097325	0.84808558	3530.6558
858.33838	2.5099649	0.84977293	3519.0784
859.23926	2.5105898	0.85119033	3518.8508
860.14014	2.5159364	0.85254139	3524.9592
861.04102	2.5179391	0.85420024	3528.4114
861.94189	2.5206678	0.85582179	3524.0627
862.84277	2.5241191	0.85743934	3528.1338
863.74365	2.5261216	0.85889733	3526.3208
864.64453	2.5290082	0.86067671	3525.6733
865.54541	2.5336218	0.862225	3533.1394
866.44629	2.534622	0.86341035	3522.7
867.34717	2.5360591	0.86503547	3518.3142
868.24805	2.5404565	0.86599839	3520.1814
869.14893	2.5394757	0.86765146	3519.9368
870.0498	2.5443249	0.86884475	3515.0505
870.95068	2.5478387	0.870462	3521.6362
871.85156	2.5482745	0.87179106	3518.8674
872.75244	2.5515058	0.87338823	3524.3511
873.65332	2.5580509	0.87500101	3521.8203
874.5542	2.5593064	0.87665325	3530.4124
875.45508	2.5609975	0.87849736	3524.6206
876.35596	2.5624821	0.88013434	3518.0012
877.25684	2.5669634	0.88198942	3524.3813
878.15771	2.5687373	0.88388312	3531.1157
879.05859	2.5709858	0.88632965	3522.6304
879.95947	2.5731175	0.88790715	3525.1855
880.86035	2.5808778	0.88963699	3519.5432
881.76123	2.5787537	0.89139187	3521.0566
882.66211	2.5826774	0.89321852	3525.5637
883.56299	2.5858839	0.89504069	3520.5503
884.46387	2.5900824	0.89675921	3526.1882
885.36475	2.5930328	0.89835745	3525.896
886.26563	2.5927055	0.90050602	3523.6904
887.1665	2.5955086	0.90222079	3525.4963
888.06738	2.5985897	0.9044013	3528.4785
888.96826	2.6039243	0.90613526	3526.1604
889.86914	2.6015577	0.90802002	3520.6436
890.77002	2.6062677	0.91007078	3521.7339
891.6709	2.6096613	0.91233832	3521.6238
892.57178	2.6103637	0.91398412	3521.1021
893.47266	2.6147008	0.9161464	3519.876
894.37354	2.6178901	0.91799212	3516.7952
895.27441	2.6209855	0.91975302	3525.2705
896.17529	2.6237514	0.92185205	3526.1653
897.07617	2.6247299	0.92372185	3515.6926
897.97705	2.6306818	0.92541575	3527.249
898.87793	2.6319978	0.92754394	3528.7642
899.77881	2.6338222	0.92960215	3524.6956
900.67969	2.6358752	0.93152183	3519.7705
901.58057	2.6413703	0.9330653	3522.0073
902.48145	2.6413767	0.93468338	3519.7322
903.38232	2.6454194	0.93652815	3527.4314
904.2832	2.6458566	0.93854356	3526.5728
905.18408	2.6501496	0.94060278	3515.1204
906.08496	2.6533918	0.94249159	3521.2053
906.98584	2.6568928	0.94432408	3526.5374
907.88672	2.6575727	0.94657928	3526.0674
908.7876	2.6632209	0.94869816	3526.698
909.68848	2.6653295	0.95081031	3521.1301
910.58936	2.6668746	0.95252591	3521.8491
911.49023	2.6681235	0.95445836	3522.4888
912.39111	2.6718779	0.95626944	3531.9067
913.29199	2.6722097	0.9581759	3514.106
914.19287	2.6783514	0.95955998	3514.9253
915.09375	2.6787188	0.96117032	3514.9407
915.99463	2.6838214	0.96303982	3521.3372
916.89551	2.6842968	0.96509796	3523.292
917.79639	2.6873701	0.96742827	3527.4666
918.69727	2.6894047	0.96968192	3518.7786
919.59814	2.6933382	0.97162175	3518.3091
920.49902	2.6948638	0.97366077	3519.1531
921.3999	2.6971695	0.97588289	3522.345
922.30078	2.6974864	0.9781518	3516.0603
923.20166	2.7029493	0.98019278	3523.2837
924.10254	2.7063463	0.98301488	3522.4934
925.00342	2.7095017	0.98541796	3526.2273
925.9043	2.7133226	0.98779535	3520.1445
926.80518	2.7110813	0.98995805	3514.8208
927.70605	2.7173433	0.99186665	3516.5076
928.60693	2.7186651	0.99380344	3518.0193
929.50781	2.7231586	0.9957692	3521.2356
930.40869	2.7270339	0.99818569	3525.2866
931.30957	2.7283351	1.0003089	3519.7166
932.21045	2.7325802	1.0022333	3510.5908
933.11133	2.7320867	1.003889	3520.9739
934.01221	2.7359657	1.0059257	3522.9924
934.91309	2.7381427	1.0073956	3518.6033
935.81396	2.7429392	1.0090911	3515.9976
936.71484	2.7438178	1.0107783	3516.7185
937.61572	2.7470231	1.0129901	3516.0532
938.5166	2.7526028	1.0146683	3516.5901
939.41748	2.7550695	1.0165459	3515.9595
940.31836	2.7559028	1.0182894	3516.5376
941.21924	2.757133	1.0200304	3513.4563
942.12012	2.7607303	1.0214922	3511.8982
943.021	2.7650838	1.0231954	3514.4121
943.92188	2.7662528	1.0246891	3514.3945
944.82275	2.7700729	1.0264602	3513.5344
945.72363	2.7709579	1.0281873	3515.8804
946.62451	2.7745764	1.0300378	3517.0144
947.52539	2.7739668	1.0320421	3508.0957
948.42627	2.7806284	1.0339549	3512.9016
949.32715	2.7828932	1.0361291	3516.6611
950.22803	2.7840929	1.0381303	3513.0144
951.12891	2.7868927	1.0406181	3516.1216
952.02979	2.791147	1.0428679	3512.4058
952.93066	2.7924111	1.0459074	3506.2544
953.83154	2.7970285	1.0478258	3508.863
954.73242	2.7968853	1.0499871	3502.7881
955.6333	2.8010044	1.0515959	3506.7009
956.53418	2.8032589	1.0536302	3506.072
957.43506	2.8090014	1.0553823	3511.9292
958.33594	2.8099153	1.0577265	3511.2158
959.23682	2.8117018	1.0595514	3505.3474
960.1377	2.8146572	1.0622613	3514.7249
961.03857	2.8172848	1.0643655	3501.9622
961.93945	2.8192914	1.0668206	3506.5435
962.84033	2.8206725	1.0696218	3501.416
963.74121	2.8270464	1.0721989	3507.5649
964.64209	2.8279824	1.0746785	3506.1045
965.54297	2.8321075	1.0766457	3499.814
966.44385	2.8361719	1.0787888	3503.7046
967.34473	2.8352509	1.081485	3501.4634
968.24561	2.8392272	1.0839547	3498.5461
969.14648	2.8446581	1.0862826	3509.5264
970.04736	2.8427191	1.0888859	3505.3303
970.94824	2.8480167	1.0913087	3503.4265
971.84912	2.8527563	1.0939573	3508.2112
972.75	2.8535216	1.0961555	3504.9482
973.65088	2.8554173	1.0984762	3501.8484
974.55176	2.8563483	1.1006308	3502.5732
975.45264	2.8625085	1.1031812	3503.9985
976.35352	2.8633075	1.1052713	3496.0818
977.25439	2.8665183	1.1073927	3501.7297
978.15527	2.8684974	1.1093088	3493.1375
979.05615	2.8704636	1.1114202	3497.8982
979.95703	2.8743279	1.1134152	3494.9023
980.85791	2.8790672	1.1153252	3494.5769
981.75879	2.8820529	1.1178864	3499.6536
982.65967	2.8809247	1.1199365	3487.4097
983.56055	2.88608	1.1220146	3492.1465
984.46143	2.8868124	1.1239173	3491.9031
985.3623	2.8919778	1.1258571	3491.9653
986.26318	2.8944414	1.1276654	3496.314
987.16406	2.8950448	1.129884	3488.946
988.06494	2.8991313	1.1317824	3486.7876
988.96582	2.9021485	1.1334028	3486.8076
989.8667	2.9045947	1.1351433	3483.3977
990.76758	2.9063659	1.1368662	3492.0105
991.66846	2.9101577	1.1391116	3494.0076
992.56934	2.9115248	1.1408371	3483.6943
993.47021	2.9128709	1.1428463	3481.5127
994.37109	2.9164045	1.1451631	3483.3293
995.27197	2.9189744	1.1477511	3481.2471
996.17285	2.9266887	1.1497571	3479.2007
997.07373	2.9274406	1.1517255	3478.5137
997.97461	2.9286792	1.153224	3476.3728
998.87549	2.9326677	1.1550254	3473.0955
999.77637	2.9332004	1.1567045	3475.2715
1000.6772	2.9335074	1.1588298	3472.7324
1001.5781	2.9381039	1.1607935	3476.052
1002.479	2.9398873	1.1628393	3473.9133
1003.3799	2.9450231	1.1649383	3476.5647
1004.2808	2.9467304	1.1672308	3465.2988
1005.1816	2.9498692	1.1692536	3467.7688
1006.0825	2.9534471	1.1718116	3481.2368
1006.9834	2.9549706	1.1744004	3471.6038
1007.8843	2.9571798	1.1768053	3469.4924
1008.7852	2.9614749	1.1791204	3462.6599
1009.686	2.9636059	1.1811339	3464.5244
1010.5869	2.9638407	1.1836236	3457.1079
1011.4878	2.9691088	1.1856821	3461.762
1012.3887	2.975775	1.1877773	3457.4382
1013.2896	2.9755757	1.1894891	3457.4417
1014.1904	2.9787552	1.1914815	3450.864
1015.0913	2.9812033	1.1930772	3453.9077
1015.9922	2.9811745	1.1953859	3456.8176
1016.8931	2.9843104	1.1978774	3458.4937
1017.7939	2.9887931	1.2003758	3456.1719
1018.6948	2.9921536	1.2029294	3455.6465
1019.5957	2.9920938	1.2051593	3455.3044
1020.4966	2.995044	1.207532	3452.8279
1021.3975	3.0024545	1.2094935	3445.6174
1022.2983	3.0013697	1.2116936	3446.8506
1023.1992	3.003088	1.2136608	3443.9131
1024.1001	3.0077066	1.2156214	3439.7295
1025.001	3.0131032	1.2175746	3435.9573
1025.9019	3.0146368	1.2188965	3441.646
1026.8027	3.0173924	1.2209165	3441.8599
1027.7036	3.0184453	1.2228826	3438.2925
1028.6045	3.0208094	1.2248437	3435.2874
1029.5054	3.0235565	1.2268291	3437.1326
1030.4063	3.022377	1.229157	3434.2737
1031.3071	3.0268273	1.2319976	3431.2996
1032.208	3.0319872	1.2346706	3428.384
1033.1089	3.0346627	1.2367905	3425.3628
1034.0098	3.0344846	1.2389467	3431.1621
1034.9106	3.0372939	1.241671	3422.5674
1035.8115	3.0430157	1.2442973	3429.4382
1036.7124	3.0432606	1.2468545	3420.1741
1037.6133	3.048743	1.2490867	3415.8528
1038.5142	3.0508888	1.2512579	3427.0632
1039.415	3.0529881	1.2539501	3418.9148
1040.3159	3.0562053	1.2565643	3416.0552
1041.2168	3.0570233	1.2586706	3400.7644
1042.1177	3.0613148	1.260933	3409.8552
1043.0186	3.0626504	1.263065	3404.3333
1043.9194	3.0675917	1.2652087	3407.6414
1044.8203	3.0683298	1.267423	3404.6614
1045.7212	3.0716996	1.2698666	3405.3345
1046.6221	3.0769961	1.2720554	3403.4233
1047.5229	3.0783486	1.2745684	3396.5344
1048.4238	3.0821099	1.2768621	3391.6887
1049.3247	3.0817134	1.2793633	3393.9214
1050.2256	3.0900614	1.2810677	3390.9421
1051.1265	3.0859699	1.2840338	3391.5981
1052.0273	3.0884757	1.2865446	3387.3157
1052.9282	3.092885	1.2891099	3376.7097
1053.8291	3.0955486	1.2909746	3379.9443
1054.73	3.098665	1.292866	3368.7507
1055.6309	3.1050363	1.2947921	3382.4077
1056.5317	3.1037228	1.2973459	3380.3059
1057.4326	3.1072659	1.2996079	3375.1169
1058.3335	3.1085856	1.3021686	3374.9446
1059.2344	3.110904	1.3051418	3366.1938
1060.1353	3.1147881	1.3077236	3368.9617
1061.0361	3.1185834	1.3097179	3360.3076
1061.937	3.1202481	1.3115178	3358.2498
1062.8379	3.1213269	1.3138289	3355.9412
1063.7388	3.1224139	1.3164539	3357.6467
1064.6396	3.1287904	1.318952	3348.0515
1065.5405	3.1309283	1.3211963	3347.1943
1066.4414	3.1339412	1.3236836	3345.186
1067.3423	3.1399267	1.3260798	3346.3623
1068.2432	3.1393161	1.3283941	3338.0227
1069.144	3.1433663	1.3305402	3341.0688
1070.0449	3.1446135	1.3325721	3336.8621
1070.9458	3.1470678	1.3349086	3336.1721
1071.8467	3.1501608	1.3372605	3332.2576
1072.7476	3.15329	1.3398812	3330.7129
1073.6484	3.1533461	1.3422101	3320.9016
1074.5493	3.1577804	1.3447623	3326.4836
1075.4502	3.1619117	1.3471504	3324.0728
1076.3511	3.1631644	1.349489	3317.8994
1077.252	3.1664331	1.351604	3317.5334
1078.1528	3.1686332	1.353985	3310.4856
1079.0537	3.1721528	1.3559031	3305.9126
1079.9546	3.1725786	1.3582537	3305.0688
1080.8555	3.1783252	1.3604577	3303.6248
1081.7563	3.1786437	1.3633289	3297.0466
1082.6572	3.1865528	1.3656044	3300.0435
1083.5581	3.1839788	1.3679734	3288.6506
1084.459	3.1882312	1.3699288	3286.1641
1085.3599	3.1912658	1.3725722	3288.5327
1086.2607	3.1949959	1.3747523	3279.312
1087.1616	3.1982937	1.3772026	3281.6289
1088.0625	3.1971281	1.379375	3273.957
1088.9634	3.2011459	1.3818781	3269.6946
1089.8643	3.2040091	1.3840168	3266.6382
1090.7651	3.2051961	1.3864342	3260.342
1091.666	3.2121332	1.3889406	3262.0017
1092.5669	3.2141979	1.3918391	3258.0378
1093.4678	3.2168212	1.3943776	3245.6182
1094.3687	3.2194858	1.3969692	3252.2329
1095.2695	3.2236156	1.3991115	3245.8403
1096.1704	3.2214792	1.401244	3235.9709
1097.0713	3.2294724	1.4038351	3241.6404
1097.9722	3.2265284	1.406787	3225.0708
1098.873	3.2318892	1.4091135	3219.2131
1099.7739	3.2326488	1.4116558	3210.4521
1100.6748	3.2349894	1.4144266	3208.0054
1101.5757	3.2374353	1.4171181	3201.6206
1102.4766	3.2434356	1.4200407	3195.7656
1103.3774	3.2427742	1.4225565	3180.3169
1104.2783	3.2497687	1.4255028	3177.6885
1105.1792	3.2510488	1.4292328	3161.5527
1105.6797	3.253422	1.4331152	3119.9832