File: datasets/am_bench_2022/raw_data/60-XY.09-1/specimen.dat
MTS793|MPT|ENU|1|2|.|/|:|1|0|0|A

Operator Information						Time:	15.741455	Sec	11/1/2021 2:11:58 PM
Operator	Nick Derimow
Project	AM Bench 2022 mini-tensile challenge
Specimen ID	60-XY.09-1
Material	PBF-L Inconel 625
Specimen Width	2.55	mm
Specimen Thickness	1.51	mm
Notes
Operator Information End

Data Acquisition						Time:	1016.7544	Sec	11/1/2021 2:28:39 PM
Time	Axial Displacement	Axial Extensometer	Axial Force
Sec	mm	mm	N
15.874268	0.0019271149	-2.7800397e-05	60.396782
16.775146	0.0025444513	1.4337479e-05	70.542274
17.676025	0.0062372014	9.4607611e-05	82.578453
18.576904	0.0071501955	7.8778765e-05	96.5532
19.477783	0.010333125	0.00019794641	104.16658
20.378662	0.013038864	0.00019239797	114.40274
21.279541	0.017179864	0.00022022934	128.88138
22.18042	0.021156592	0.00024109133	138.26817
23.081299	0.020287445	0.0003913891	147.63969
23.982178	0.023080878	0.00057668635	156.84947
24.883057	0.030447016	0.00048489723	168.80162
25.783936	0.027894534	0.00057485461	178.87433
26.684814	0.029505542	0.0006694108	197.12862
27.585693	0.03555879	0.00080587121	211.13504
28.486572	0.03662955	0.0008014497	227.6736
29.387451	0.040558692	0.00093563483	250.09721
30.28833	0.043042738	0.0010480779	257.38962
31.189209	0.046807814	0.0010780044	278.98532
32.090088	0.047405891	0.0011537105	296.1257
32.990967	0.052503683	0.001186656	312.48428
33.891846	0.054913968	0.0014742051	333.59763
34.792725	0.056488965	0.0013288206	355.25113
35.693604	0.056948535	0.0015466464	366.142
36.594482	0.061303083	0.0015209407	387.65173
37.495361	0.065893151	0.0019267385	407.54205
38.39624	0.066833191	0.001746961	421.65659
39.297119	0.068511195	0.0019778905	444.01126
40.197998	0.071048774	0.0020487008	470.50894
41.098877	0.073923595	0.0022260647	483.36749
41.999756	0.076806568	0.0021702608	511.55154
42.900635	0.077764839	0.0024698901	526.75806
43.801514	0.081632107	0.0023802349	543.896
44.702393	0.085430533	0.0025972945	567.19696
45.603271	0.084970757	0.0025959953	584.56946
46.50415	0.091790296	0.0029824555	616.66205
47.405029	0.094394609	0.0027863935	635.67981
48.305908	0.097004667	0.0030381072	660.96741
49.206787	0.097311392	0.0030104436	678.54761
50.107666	0.10139979	0.0033165754	704.95624
51.008545	0.1043307	0.0033499973	730.42712
51.909424	0.10679466	0.003451237	750.82904
52.810303	0.11003906	0.0035492312	771.79889
53.711182	0.11067422	0.0038304531	796.46716
54.612061	0.11698563	0.0038647878	825.66541
55.512939	0.11633224	0.0040035597	849.32666
56.413818	0.12151265	0.0042024818	875.84656
57.314697	0.12202959	0.0042240652	895.26306
58.215576	0.12572393	0.0044779424	925.32886
59.116455	0.1262839	0.0045350529	946.79895
60.017334	0.13101232	0.0047705113	968.19946
60.918213	0.13414484	0.0046976726	996.77612
61.819092	0.133858	0.0049489029	1022.8734
62.719971	0.1404583	0.0049245046	1042.4769
63.62085	0.14088939	0.0051468173	1076.6882
64.521729	0.14436901	0.005253294	1102.3325
65.422607	0.14731713	0.0053942939	1120.171
66.323486	0.1507068	0.0055992524	1144.6738
67.224365	0.15086477	0.0056659556	1171.1309
68.125244	0.15553239	0.0058232658	1199.6359
69.026123	0.15936702	0.0058662468	1223.5099
69.927002	0.15910456	0.0061287172	1244.3417
70.827881	0.16114691	0.0061741909	1269.4468
71.72876	0.16884646	0.006264484	1296.7018
72.629639	0.16797894	0.0064282566	1320.7318
73.530518	0.17109488	0.0065299543	1340.1351
74.431396	0.1712461	0.0066577243	1365.426
75.332275	0.17617075	0.0068328087	1393.4713
76.233154	0.18129303	0.0069093518	1420.907
77.134033	0.18122971	0.0070129675	1439.1664
78.034912	0.18382502	0.0071989009	1468.5454
78.935791	0.18962066	0.0072838422	1497.1353
79.83667	0.19102129	0.0073581347	1521.4209
80.737549	0.19451366	0.0075369696	1544.6504
81.638428	0.19433828	0.007643254	1562.6414
82.539307	0.19638652	0.0077068028	1584.579
83.440186	0.20312241	0.007812947	1616.9365
84.341064	0.2035951	0.0079950364	1646.9265
85.241943	0.20790027	0.0081031881	1662.8616
86.142822	0.21013762	0.0082055423	1688.3064
87.043701	0.20839037	0.0083215013	1715.5454
87.94458	0.21418601	0.0084333988	1743.2057
88.845459	0.21570221	0.0085387817	1762.5602
89.746338	0.22029929	0.0086679393	1781.4476
90.647217	0.22325745	0.008838566	1812.7194
91.548096	0.22468473	0.0088772541	1835.0198
92.448975	0.22668339	0.0090800161	1863.6476
93.349854	0.23221375	0.0092264563	1883.1482
94.250732	0.23397848	0.0092478674	1907.749
95.151611	0.23333634	0.0093702972	1924.4037
96.05249	0.24103072	0.0094881486	1958.4327
96.953369	0.23961636	0.0095659746	1965.5697
97.854248	0.24631441	0.0097050276	1996.4799
98.755127	0.24630108	0.0097940639	2012.6963
99.656006	0.248928	0.009870681	2034.7626
100.55688	0.25139195	0.00998432	2051.2512
101.45776	0.25522479	0.010060698	2068.7263
102.35864	0.2580215	0.010197277	2088.4939
103.25952	0.26046258	0.010412882	2103.1257
104.1604	0.26265472	0.010461792	2127.4326
105.06128	0.26619232	0.010524193	2134.8325
105.96216	0.26923838	0.010665276	2153.6445
106.86304	0.27051088	0.010637034	2171.1362
107.76392	0.2737242	0.010739474	2189.4854
108.66479	0.27601549	0.010927292	2205.7505
109.56567	0.279641	0.010996609	2220.6406
110.46655	0.28499714	0.011161978	2239.3762
111.36743	0.28359589	0.011142571	2242.8689
112.26831	0.29038799	0.01131864	2258.97
113.16919	0.28967705	0.01142803	2278.8599
114.07007	0.28948161	0.011415839	2287.6174
114.97095	0.29573148	0.011586708	2309.6819
115.87183	0.29925269	0.011676745	2323.5718
116.77271	0.29914165	0.011773809	2329.3389
117.67358	0.30732673	0.01193011	2350.292
118.57446	0.30620787	0.011911535	2352.3889
119.47534	0.31076434	0.012053789	2364.4978
120.37622	0.31470215	0.012152476	2380.7864
121.2771	0.3147552	0.012301865	2392.5447
122.17798	0.31747857	0.012369941	2399.3245
123.07886	0.31997576	0.012478965	2413.886
123.97974	0.3213532	0.012596015	2420.6931
124.88062	0.32863232	0.012728479	2430.9624
125.78149	0.32975718	0.012862009	2444.4919
126.68237	0.3311803	0.013085055	2457.1194
127.58325	0.33453104	0.013222335	2472.7004
128.48413	0.33731973	0.013346309	2482.8875
129.38501	0.33933896	0.013464394	2489.8362
130.28589	0.34120879	0.013632329	2499.2107
131.18677	0.3434757	0.013760536	2507.9163
132.08765	0.3514663	0.013884162	2521.3198
132.98853	0.35186276	0.014260029	2522.5513
133.8894	0.3528952	0.014293259	2537.2732
134.79028	0.35655394	0.014425338	2552.3928
135.69116	0.35938588	0.014522779	2551.7476
136.59204	0.3598645	0.014720211	2557.8809
137.49292	0.36297593	0.014892505	2565.5439
138.3938	0.36799735	0.015191867	2579.1694
139.29468	0.37077725	0.015365264	2589.3113
140.19556	0.37488303	0.015560864	2602.4402
141.09644	0.37380269	0.015814196	2605.2605
141.99731	0.37983048	0.01610563	2618.1372
142.89819	0.38325974	0.016227551	2620.5576
143.79907	0.38239959	0.016513772	2629.168
144.69995	0.38543111	0.01675293	2637.146
145.60083	0.39192545	0.016948972	2645.7405
146.50171	0.39337894	0.017288053	2647.9768
147.40259	0.39524364	0.017538408	2659.429
148.30347	0.39715979	0.017750995	2660.4263
149.20435	0.39887345	0.0181203	2665.7256
150.10522	0.40095201	0.018435808	2675.0669
151.0061	0.40504548	0.018840397	2684.3928
151.90698	0.411387	0.019218167	2699.1265
152.80786	0.40769595	0.019673225	2697.7778
153.70874	0.41371989	0.020047428	2705.478
154.60962	0.41570216	0.020372218	2708.3203
155.5105	0.41745788	0.020790083	2713.2976
156.41138	0.42094281	0.021254361	2723.4226
157.31226	0.42602202	0.021629468	2728.7505
158.21313	0.42722821	0.022101004	2732.4844
159.11401	0.42862839	0.022610269	2743.8025
160.01489	0.43172771	0.023120077	2749.5952
160.91577	0.43634	0.023714755	2751.5908
161.81665	0.43822578	0.024103498	2754.427
162.71753	0.44335744	0.024781404	2765.6836
163.61841	0.4435955	0.025339197	2767.3589
164.51929	0.4437789	0.026066754	2778.0969
165.42017	0.45080927	0.026676906	2785.5422
166.32104	0.45256799	0.027363772	2785.5723
167.22192	0.45183694	0.027884282	2781.4189
168.1228	0.46000114	0.028534539	2790.3677
169.02368	0.4629907	0.029081095	2802.3584
169.92456	0.46195865	0.029637547	2799.0444
170.82544	0.46522847	0.030516475	2806.4548
171.72632	0.47025213	0.031163612	2804.9297
172.6272	0.46733883	0.031890228	2817.0637
173.52808	0.47664469	0.032658458	2819.4033
174.42896	0.47579071	0.033323161	2818.5813
175.32983	0.47692907	0.034030713	2822.0112
176.23071	0.48159412	0.034655079	2824.9753
177.13159	0.48374876	0.035559963	2833.5178
178.03247	0.48636517	0.036411732	2837.9817
178.93335	0.49122027	0.037330456	2843.2998
179.83423	0.49031341	0.038040049	2839.386
180.73511	0.49277124	0.038950887	2847.408
181.63599	0.49807844	0.039809324	2845.1777
182.53687	0.49918851	0.040592905	2852.3865
183.43774	0.50268292	0.041412257	2856.3521
184.33862	0.50534749	0.042303607	2857.2007
185.2395	0.50784796	0.043088388	2855.6389
186.14038	0.50871688	0.043946829	2864.8318
187.04126	0.51142573	0.044793133	2867.356
187.94214	0.51828498	0.045699745	2870.0205
188.84302	0.52062422	0.046616044	2875.5811
189.7439	0.52191663	0.047616165	2879.7686
190.64478	0.52421409	0.048486024	2877.6304
191.54565	0.52733284	0.049400453	2883.8013
192.44653	0.52783936	0.050372865	2881.9702
193.34741	0.5312258	0.051269144	2889.0869
194.24829	0.53605497	0.052174922	2894.3042
195.14917	0.54084468	0.053251542	2895.4058
196.05005	0.53996176	0.053886522	2892.1475
196.95093	0.5435859	0.054889288	2895.9197
197.85181	0.54776973	0.055811297	2901.8809
198.75269	0.55264807	0.056921478	2908.6748
199.65356	0.55127227	0.05791723	2908.8152
200.55444	0.55508608	0.058749296	2906.1543
201.45532	0.5543384	0.059806816	2912.6963
202.3562	0.55946225	0.06084498	2916.4058
203.25708	0.56324083	0.061830774	2920.5403
204.15796	0.56385058	0.062938116	2918.5061
205.05884	0.56720519	0.064046487	2923.4504
205.95972	0.57095838	0.065221809	2930.6714
206.8606	0.57227498	0.066359937	2929.9731
207.76147	0.57919693	0.06736885	2931.3167
208.66235	0.5794012	0.068214498	2932.1179
209.56323	0.58068341	0.069247037	2936.717
210.46411	0.58290708	0.07022661	2936.0217
211.36499	0.58583307	0.071070306	2937.8147
212.26587	0.59014678	0.072055809	2934.6394
213.16675	0.59326375	0.072998114	2944.605
214.06763	0.5954448	0.074095085	2946.2903
214.96851	0.59867144	0.075165674	2942.2244
215.86938	0.59768057	0.076042794	2944.666
216.77026	0.60385835	0.076854862	2944.6704
217.67114	0.60700458	0.077673547	2947.678
218.57202	0.60669625	0.078610376	2954.3325
219.4729	0.61357909	0.079868212	2963.3186
220.37378	0.61656922	0.081150524	2960.3123
221.27466	0.61663175	0.082182765	2958.8228
222.17554	0.61913234	0.083039418	2956.6399
223.07642	0.62459129	0.084084608	2965.8738
223.97729	0.62537825	0.085011557	2967.2109
224.87817	0.62757462	0.086120486	2967.6882
225.77905	0.62810779	0.087033495	2968.4565
226.67993	0.6329509	0.088025808	2974.4092
227.58081	0.63457155	0.089123949	2977.0984
228.48169	0.63923341	0.090231031	2975.4077
229.38257	0.64054984	0.091284372	2977.7903
230.28345	0.6471591	0.092384085	2980.0088
231.18433	0.64680666	0.093575694	2994.2688
232.08521	0.64923257	0.094613634	2980.9316
232.98608	0.65097517	0.095497571	2983.4551
233.88696	0.6551789	0.096764244	2995.8738
234.78784	0.65753198	0.09799321	2988.4377
235.68872	0.65893859	0.099073492	2988.9749
236.5896	0.66165131	0.099950321	2988.1694
237.49048	0.66347831	0.10105138	2994.6885
238.39136	0.66907465	0.10211466	2996.8567
239.29224	0.66984516	0.10302111	3000.563
240.19312	0.67235816	0.104073	2998.6362
241.09399	0.67763138	0.10523047	3002.613
241.99487	0.6773892	0.10638843	3002.437
242.89575	0.68243831	0.10738757	3007.2241
243.79663	0.68536329	0.1085097	3011.384
244.69751	0.68716013	0.1095815	3009.2427
245.59839	0.69234383	0.11067314	3014.2034
246.49927	0.69276303	0.11177712	3011.7947
247.40015	0.69521207	0.11269125	3013.5371
248.30103	0.69781518	0.11382522	3014.1128
249.2019	0.70134497	0.11474687	3015.7417
250.10278	0.70181251	0.1156706	3015.4951
251.00366	0.70510739	0.11677436	3027.376
251.90454	0.71123272	0.11762225	3022.6079
252.80542	0.71152055	0.11856256	3024.1355
253.7063	0.71347761	0.11959562	3021.52
254.60718	0.71805876	0.12059388	3024.8589
255.50806	0.72281367	0.12187091	3034.6021
256.40894	0.72106349	0.12310279	3027.4282
257.30981	0.72634983	0.12410115	3034.8027
258.21069	0.72972453	0.12535128	3038.1465
259.11157	0.73000419	0.12619251	3029.1809
260.01245	0.73513091	0.12716423	3039.9326
260.91333	0.73609352	0.12822293	3041.7041
261.81421	0.73938686	0.1292841	3040.208
262.71509	0.74096143	0.13029552	3041.8345
263.61597	0.74321806	0.13123211	3048.0176
264.51685	0.74607652	0.13241117	3042.1714
265.41772	0.75110567	0.13355674	3051.2166
266.3186	0.75100547	0.13471253	3047.8311
267.21948	0.75350815	0.13578723	3049.4492
268.12036	0.75689685	0.13680154	3047.7334
269.02124	0.75902569	0.13777131	3050.6252
269.92212	0.76423246	0.13891429	3052.5317
270.823	0.76248091	0.13995476	3058.0474
271.72388	0.767802	0.14089864	3061.6008
272.62476	0.76934731	0.14202985	3058.2153
273.52563	0.77256817	0.1432783	3066.0759
274.42651	0.77851135	0.14438036	3065.9429
275.32739	0.77808988	0.14524758	3052.8953
276.22827	0.78300434	0.14617439	3061.2429
277.12915	0.78262818	0.1472038	3064.7251
278.03003	0.78826612	0.14846757	3078.5872
278.93091	0.79182094	0.14961252	3071.7996
279.83179	0.79092145	0.15084879	3070.4026
280.73267	0.79467869	0.15193494	3072.6357
281.63354	0.79676425	0.15293685	3074.0513
282.53442	0.80276978	0.15404928	3078.1213
283.4353	0.80419844	0.15501834	3072.6428
284.33618	0.80743217	0.15591078	3077.8591
285.23706	0.80784583	0.15691277	3077.9971
286.13794	0.80930305	0.15795878	3081.4817
287.03882	0.81178778	0.15893131	3077.5283
287.9397	0.81740391	0.15984581	3078.4248
288.84058	0.81891435	0.16074663	3085.425
289.74146	0.82424843	0.16169083	3085.0845
290.64233	0.82765818	0.16287874	3096.6936
291.54321	0.82863224	0.16400725	3094.8821
292.44409	0.83174366	0.16521916	3092.5129
293.34497	0.83238047	0.16636194	3096.0476
294.24585	0.83371532	0.16737755	3097.3567
295.14673	0.83677596	0.16839719	3088.9983
296.04761	0.84153038	0.16950648	3094.7224
296.94849	0.8420096	0.17056064	3091.0325
297.84937	0.8463707	0.17157374	3102.0093
298.75024	0.85306913	0.17250641	3103.958
299.65112	0.85279292	0.17354907	3101.3682
300.552	0.85670859	0.17454892	3099.8135
301.45288	0.85585868	0.17560509	3099.6248
302.35376	0.85897338	0.17673671	3102.563
303.25464	0.8639788	0.17768958	3102.8616
304.15552	0.86312342	0.17868666	3108.4768
305.0564	0.86731011	0.17968152	3118.1289
305.95728	0.87223274	0.18079603	3116.8596
306.85815	0.87186784	0.18184939	3113.575
307.75903	0.8776502	0.18311618	3116.8027
308.65991	0.87779504	0.18425371	3113.3406
309.56079	0.88273209	0.18522558	3114.6523
310.46167	0.88531137	0.18638657	3121.6753
311.36255	0.88703698	0.18764372	3120.0537
312.26343	0.88549787	0.18858702	3114.3936
313.16431	0.89190286	0.18973935	3120.0728
314.06519	0.89505589	0.19065662	3121.4895
314.96606	0.89581072	0.19182283	3121.1453
315.86694	0.9003576	0.19274521	3126.1624
316.76782	0.90575969	0.19378662	3128.0784
317.6687	0.90553677	0.19487867	3125.6025
318.56958	0.90803313	0.19592851	3133.5947
319.47046	0.91070145	0.19689368	3130.4739
320.37134	0.91808683	0.19796534	3138.6494
321.27222	0.91704232	0.19908765	3137.1792
322.1731	0.9208914	0.20006457	3128.8469
323.07397	0.92265463	0.20095044	3133.8069
323.97485	0.92487925	0.20195952	3137.9927
324.87573	0.92517126	0.20292693	3135.322
325.77661	0.92865473	0.20411742	3142.0923
326.67749	0.93220532	0.2052044	3140.0056
327.57837	0.93305188	0.20644812	3148.3665
328.47925	0.93577445	0.20775619	3147.6899
329.38013	0.94318402	0.20882457	3150.9634
330.28101	0.94511819	0.20990954	3144.6465
331.18188	0.94668931	0.21081719	3145.8362
332.08276	0.94989723	0.21175115	3150.7314
332.98364	0.94922024	0.21291637	3150.2505
333.88452	0.95435274	0.21405159	3157.5227
334.7854	0.95933765	0.21516998	3161.9431
335.68628	0.96179163	0.21628527	3158.9736
336.58716	0.96286136	0.21716432	3152.75
337.48804	0.96510893	0.21813637	3161.0244
338.38892	0.97009575	0.21922624	3163.2722
339.28979	0.9727245	0.22015363	3163.9619
340.19067	0.97350556	0.22136854	3169.1228
341.09155	0.97858387	0.22253034	3170.259
341.99243	0.97764939	0.22355421	3166.4902
342.89331	0.98108619	0.22483282	3170.0452
343.79419	0.98355079	0.22594009	3171.418
344.69507	0.98768467	0.22715612	3168.6045
345.59595	0.99058747	0.2281504	3166.2036
346.49683	0.99146914	0.22909282	3167.1702
347.39771	0.99138921	0.23002054	3165.1685
348.29858	0.99859595	0.23103178	3172.4841
349.19946	0.99775118	0.23217753	3179.3245
350.10034	1.0046074	0.23333897	3177.7654
351.00122	1.0050901	0.23441704	3178.1533
351.9021	1.0087113	0.23550329	3179.5776
352.80298	1.0145462	0.23657128	3185.3555
353.70386	1.0125827	0.23769133	3180.364
354.60474	1.0169247	0.23874143	3183.9858
355.50562	1.0208911	0.23981687	3180.1873
356.40649	1.0203375	0.24088337	3181.1533
357.30737	1.0265533	0.24186602	3189.7463
358.20825	1.0289664	0.24297006	3192.7651
359.10913	1.0317621	0.24392349	3186.4558
360.01001	1.0329912	0.24488871	3186.2637
360.91089	1.0369844	0.24584298	3190.4204
361.81177	1.0355576	0.24677248	3187.0085
362.71265	1.039235	0.24767274	3190.0378
363.61353	1.0422627	0.24884038	3193.8816
364.5144	1.0489987	0.24979082	3196.7358
365.41528	1.0490432	0.25063333	3197.1316
366.31616	1.0494893	0.25171804	3195.5315
367.21704	1.0561855	0.25272024	3194.8091
368.11792	1.0596021	0.25391805	3204.0435
369.0188	1.059963	0.25493032	3203.5798
369.91968	1.062681	0.25632411	3209.3865
370.82056	1.062999	0.25730065	3199.9641
371.72144	1.0680776	0.25842419	3207.9055
372.62231	1.0712163	0.25975609	3206.0442
373.52319	1.075076	0.26088735	3207.4373
374.42407	1.0754116	0.26168674	3202.8289
375.32495	1.0770478	0.26276606	3208.0508
376.22583	1.0832675	0.26399204	3214.3416
377.12671	1.0844802	0.26498583	3213.1851
378.02759	1.0841364	0.26599118	3206.9055
378.92847	1.0937783	0.26706231	3212.6116
379.82935	1.0936749	0.26806596	3209.8289
380.73022	1.0973006	0.26908016	3219.3403
381.6311	1.0969929	0.27002382	3210.8191
382.53198	1.1005952	0.27106947	3218.2749
383.43286	1.1030277	0.27229127	3223.1692
384.33374	1.1045477	0.27351695	3217.0837
385.23462	1.107564	0.27450189	3216.4014
386.1355	1.1117992	0.27554831	3222.6665
387.03638	1.1127791	0.27651408	3221.51
387.93726	1.1167165	0.27770719	3227.0569
388.83813	1.1200452	0.27894661	3230.5552
389.73901	1.1227585	0.28026009	3229.6611
390.63989	1.1263059	0.28115609	3227.3965
391.54077	1.1256874	0.28219718	3230.6619
392.44165	1.1310773	0.28302637	3226.7314
393.34253	1.1338686	0.28399003	3231.2661
394.24341	1.1365374	0.2849943	3236.0127
395.14429	1.1387504	0.28616101	3234.9653
396.04517	1.1417516	0.28720474	3229.6267
396.94604	1.1428435	0.28824443	3235.3086
397.84692	1.1478367	0.28946546	3237.9868
398.7478	1.1492467	0.29058218	3236.3516
399.64868	1.1534988	0.29161561	3241.1218
400.54956	1.1529934	0.29271859	3238.6858
401.45044	1.1575047	0.29361823	3233.8308
402.35132	1.1632248	0.29442841	3245.0205
403.2522	1.162917	0.29549846	3246.4187
404.15308	1.1643529	0.29666674	3246.1328
405.05396	1.1702222	0.29773992	3246.0498
405.95483	1.1712904	0.29868942	3246.3442
406.85571	1.1733416	0.29988718	3247.3254
407.75659	1.1764299	0.30089372	3251.1123
408.65747	1.1785636	0.30197203	3249.2734
409.55835	1.1834202	0.30309346	3251.0942
410.45923	1.1864684	0.30399251	3249.9382
411.36011	1.1853725	0.30514061	3258.3064
412.26099	1.1885517	0.30646607	3257.5168
413.16187	1.1908875	0.30767858	3251.6702
414.06274	1.1930674	0.30877042	3261.4885
414.96362	1.1970787	0.30987954	3254.1389
415.8645	1.1988783	0.31112731	3259.103
416.76538	1.2012751	0.3121939	3263.1619
417.66626	1.2076674	0.31324318	3263.4565
418.56714	1.2084972	0.31449723	3268.1836
419.46802	1.2133111	0.31538415	3258.6641
420.3689	1.2162668	0.31630939	3264.22
421.26978	1.2166305	0.31713203	3263.3313
422.17065	1.2179344	0.31829554	3267.5996
423.07153	1.2258734	0.31971321	3274.4985
423.97241	1.224645	0.32082555	3272.3486
424.87329	1.2274357	0.3218402	3273.5347
425.77417	1.2310693	0.322768	3268.0798
426.67505	1.2322626	0.32364485	3265.8425
427.57593	1.2354531	0.32461289	3270.9844
428.47681	1.2389843	0.32583067	3278.0352
429.37769	1.2376682	0.326749	3268.1501
430.27856	1.2465546	0.32772022	3273.9907
431.17944	1.2473563	0.32857689	3271.0737
432.08032	1.2477425	0.32958412	3274.9414
432.9812	1.2508247	0.33048666	3279.8923
433.88208	1.2535043	0.3314082	3282.8601
434.78296	1.2588084	0.33242679	3280.2402
435.68384	1.2624466	0.33362001	3285.3765
436.58472	1.2624638	0.33467042	3288.8579
437.4856	1.2635679	0.3357732	3279.7004
438.38647	1.2662812	0.33670101	3279.9802
439.28735	1.2698681	0.33766812	3281.9641
440.18823	1.2730088	0.33891702	3286.6001
441.08911	1.2760465	0.34027791	3289.0466
441.98999	1.278725	0.34145752	3287.6084
442.89087	1.2810286	0.34262073	3292.3608
443.79175	1.2860787	0.3439326	3298.9392
444.69263	1.2860026	0.34503281	3296.4785
445.59351	1.2896626	0.34644461	3294.311
446.49438	1.2915945	0.34751353	3296.1248
447.39526	1.2963567	0.34871691	3299.3723
448.29614	1.2984551	0.34979254	3290.5925
449.19702	1.3002267	0.35070798	3297.5027
450.0979	1.3046086	0.35178405	3302.6733
450.99878	1.306672	0.35302094	3302.1479
451.89966	1.3110046	0.3539407	3295.9187
452.80054	1.3114471	0.35492295	3297.7456
453.70142	1.3124315	0.35577506	3298.9351
454.60229	1.3153957	0.35677418	3299.8682
455.50317	1.3224052	0.35781026	3308.4448
456.40405	1.3243238	0.35888967	3305.0007
457.30493	1.3246949	0.35999185	3305.8228
458.20581	1.3297786	0.36121562	3310.2725
459.10669	1.329953	0.36227345	3308.8523
460.00757	1.3333037	0.36335611	3304.5352
460.90845	1.3354161	0.36444664	3311.8613
461.80933	1.3337632	0.36553383	3309.0491
462.71021	1.3404689	0.36663762	3309.4675
463.61108	1.3483431	0.36764109	3317.8774
464.51196	1.3451452	0.36869222	3311.5427
465.41284	1.3479831	0.3698054	3318.1646
466.31372	1.3519698	0.37090075	3317.2522
467.2146	1.3543426	0.37186727	3310.7046
468.11548	1.3547028	0.37293121	3316.271
469.01636	1.3626515	0.37411281	3322.3013
469.91724	1.3638128	0.37530562	3317.4097
470.81812	1.3667171	0.37644136	3322.1038
471.71899	1.3661848	0.37764189	3325.1177
472.61987	1.373859	0.37861663	3317.5701
473.52075	1.3750283	0.37977889	3327.2485
474.42163	1.3733442	0.38088772	3325.0754
475.32251	1.3782202	0.38195312	3325.5195
476.22339	1.3834573	0.3832719	3328.3132
477.12427	1.3849372	0.38433155	3326.7693
478.02515	1.38618	0.38549048	3322.4998
478.92603	1.3925978	0.38642406	3325.2036
479.8269	1.3913662	0.3873668	3326.2366
480.72778	1.3950551	0.38852122	3331.5417
481.62866	1.3998148	0.38953388	3331.8782
482.52954	1.399549	0.39046398	3327.0957
483.43042	1.4066851	0.39169499	3340.2883
484.3313	1.4067526	0.39290461	3339.9426
485.23218	1.409259	0.3941963	3345.8818
486.13306	1.4109759	0.39554888	3340.8564
487.03394	1.4138538	0.39656669	3327.0828
487.93481	1.4149479	0.3975161	3333.001
488.83569	1.4188601	0.39857915	3333.1748
489.73657	1.4239321	0.39948392	3335.802
490.63745	1.4254818	0.40048215	3336.7212
491.53833	1.4268039	0.40150464	3342.6929
492.43921	1.4307446	0.40251952	3342.6509
493.34009	1.4334409	0.40368482	3348.7671
494.24097	1.4339802	0.40486291	3341.6624
495.14185	1.4371076	0.40602592	3351.9773
496.04272	1.440995	0.40728393	3347.6021
496.9436	1.4433885	0.40842763	3349.7979
497.84448	1.4448973	0.40969661	3351.0269
498.74536	1.4488493	0.41082773	3346.2563
499.64624	1.4532694	0.41178885	3345.6621
500.54712	1.4556873	0.41302887	3356.5176
501.448	1.4569548	0.41400698	3349.269
502.34888	1.4579923	0.41501442	3348.8264
503.24976	1.4632447	0.41601157	3347.6074
504.15063	1.4650367	0.41690898	3352.7896
505.05151	1.47071	0.41789621	3353.3074
505.95239	1.4690022	0.41917184	3352.4792
506.85327	1.4726424	0.42024711	3357.0447
507.75415	1.475368	0.42149013	3358.0027
508.65503	1.4808578	0.42271712	3359.7651
509.55591	1.4805095	0.42378694	3362.0752
510.45679	1.4851841	0.42497385	3362.4055
511.35767	1.4880829	0.42617616	3362.7756
512.25854	1.4913771	0.42732447	3363.144
513.15942	1.4927205	0.42861253	3365.6831
514.0603	1.4962864	0.42980269	3366.3616
514.96118	1.498593	0.43074429	3360.3662
515.86206	1.5007728	0.43184987	3361.8467
516.76294	1.5040855	0.43296847	3363.9089
517.66382	1.5044641	0.43404609	3363.8394
518.5647	1.5110193	0.43517527	3371.0725
519.46558	1.509891	0.43641886	3371.2283
520.36646	1.5130711	0.43763387	3368.7251
521.26733	1.5201283	0.43887603	3370.7224
522.16821	1.5225445	0.43990931	3369.467
523.06909	1.5253242	0.44111386	3372.7163
523.96997	1.524441	0.442278	3371.467
524.87085	1.5273029	0.44313815	3368.9053
525.77173	1.5313771	0.44420534	3372.5042
526.67261	1.5312089	0.44534934	3373.936
527.57349	1.5368679	0.44668278	3382.6604
528.47437	1.5393155	0.44773403	3374.2512
529.37524	1.5422124	0.44873589	3379.0984
530.27612	1.5452847	0.44986409	3381.0073
531.177	1.5458043	0.45115173	3382.5339
532.07788	1.5506048	0.45234722	3378.9653
532.97876	1.5538404	0.4535898	3386.6682
533.87964	1.5554007	0.45460746	3381.6572
534.78052	1.5569652	0.45570624	3379.6245
535.6814	1.5580032	0.45678383	3384.3884
536.58228	1.5630655	0.45808703	3388.501
537.48315	1.564513	0.45926005	3386.5896
538.38403	1.5685058	0.46046689	3382.0808
539.28491	1.5693568	0.46147141	3382.9504
540.18579	1.574445	0.46263605	3388.6475
541.08667	1.5747086	0.46377811	3388.488
541.98755	1.5791259	0.46486139	3388.4678
542.88843	1.5788977	0.4658097	3380.4036
543.78931	1.5863417	0.46677643	3384.9651
544.69019	1.5879575	0.46765399	3384.0254
545.59106	1.5890856	0.46854228	3388.751
546.49194	1.5917174	0.46975908	3395.1265
547.39282	1.5931696	0.47113162	3398.1765
548.2937	1.6004924	0.47237706	3395.2139
549.19458	1.6023206	0.47355354	3395.0103
550.09546	1.6023691	0.47487345	3396.8015
550.99634	1.6046942	0.47598574	3396.0425
551.89722	1.6094587	0.47704124	3398.1228
552.7981	1.6136159	0.47820562	3401.4087
553.69897	1.6129284	0.47933871	3403.8269
554.59985	1.6190886	0.48078248	3408.4871
555.50073	1.620772	0.48196158	3399.3157
556.40161	1.6224194	0.48331165	3398.4065
557.30249	1.6257447	0.48450908	3401.2734
558.20337	1.629179	0.48565197	3403.8413
559.10425	1.6296037	0.48692155	3402.6516
560.00513	1.6318805	0.48809722	3405.6118
560.90601	1.634894	0.48931471	3404.396
561.80688	1.640455	0.49069527	3406.1182
562.70776	1.6423438	0.49184006	3406.9944
563.60864	1.6452883	0.49306044	3408.7949
564.50952	1.6476265	0.49416375	3406.5789
565.4104	1.6486322	0.49529088	3402.2009
566.31128	1.6527796	0.49619883	3405.8076
567.21216	1.654461	0.49737129	3411.2522
568.11304	1.6598572	0.49837032	3414.688
569.01392	1.6615034	0.49956813	3410.4419
569.91479	1.6646451	0.50064719	3411.1375
570.81567	1.6643213	0.50172281	3413.8181
571.71655	1.6666384	0.5028581	3407.5303
572.61743	1.6731188	0.50389957	3413.072
573.51831	1.6741674	0.50505275	3419.4333
574.41919	1.6764071	0.50604266	3411.2432
575.32007	1.6775318	0.50708485	3409.3325
576.22095	1.6817708	0.50801069	3417.5037
577.12183	1.6831126	0.5092653	3420.1919
578.02271	1.6892313	0.51036173	3421.6504
578.92358	1.6899626	0.511666	3420.7646
579.82446	1.6925489	0.51299119	3426.9026
580.72534	1.6985023	0.51435935	3427.1047
581.62622	1.695266	0.51567024	3418.0955
582.5271	1.6995722	0.51673847	3421.0625
583.42798	1.7041068	0.51772207	3425.155
584.32886	1.7056057	0.51876718	3420.6821
585.22974	1.7116743	0.52001387	3429.1787
586.13062	1.7103516	0.52118677	3418.2273
587.03149	1.7153685	0.52232748	3428.4158
587.93237	1.7171335	0.52368903	3427.2471
588.83325	1.7199039	0.5249092	3426.5781
589.73413	1.7233446	0.52612472	3432.0581
590.63501	1.7242582	0.52752721	3427.9028
591.53589	1.7278521	0.52856958	3429.9116
592.43677	1.7305913	0.5299049	3435.2329
593.33765	1.7341684	0.5313257	3433.7046
594.23853	1.734789	0.53242379	3429.5759
595.1394	1.7408453	0.53360486	3436.6721
596.04028	1.7407515	0.53474033	3430.6768
596.94116	1.7440838	0.53579509	3434.0657
597.84204	1.7478849	0.53696811	3435.4744
598.74292	1.7494253	0.53811991	3431.8118
599.6438	1.7534981	0.53951555	3444.2922
600.54468	1.7554666	0.54069346	3437.9717
601.44556	1.7563204	0.54185981	3438.5813
602.34644	1.7617946	0.54293513	3438.8872
603.24731	1.7633579	0.54411817	3437.21
604.14819	1.7645959	0.5453369	3438.2004
605.04907	1.7685053	0.54669046	3440.7559
605.94995	1.7705793	0.54806322	3438.2512
606.85083	1.7750689	0.5493511	3440.7727
607.75171	1.7759714	0.55043256	3439.3486
608.65259	1.7805955	0.5515976	3443.376
609.55347	1.7839864	0.55269808	3440.4163
610.45435	1.7860749	0.55370909	3440.6753
611.35522	1.7858026	0.55491465	3439.3804
612.2561	1.7918417	0.5561741	3448.1882
613.15698	1.7957239	0.55749899	3447.6235
614.05786	1.7927914	0.55875754	3443.0876
614.95874	1.798645	0.55989283	3444.5955
615.85962	1.8007913	0.56089199	3443.0784
616.7605	1.8026856	0.56191492	3448.3557
617.66138	1.8054459	0.56310391	3446.4426
618.56226	1.8084089	0.56436872	3454.2063
619.46313	1.8125291	0.56571239	3453.4338
620.36401	1.815227	0.5668996	3451.5737
621.26489	1.8142056	0.56801957	3447.8291
622.16577	1.820411	0.56934518	3454.8342
623.06665	1.8222638	0.57049239	3452.5657
623.96753	1.8248868	0.57175434	3451.8047
624.86841	1.8272823	0.57279992	3449.3665
625.76929	1.8271352	0.57389212	3450.282
626.67017	1.8332598	0.57528359	3459.9038
627.57104	1.8356736	0.57653308	3455.1924
628.47192	1.8378394	0.57783443	3455.458
629.3728	1.8421472	0.57905531	3456.075
630.27368	1.8446114	0.58035845	3455.3408
631.17456	1.8463871	0.58166361	3464.855
632.07544	1.8501301	0.58287966	3455.5056
632.97632	1.8520429	0.58409727	3454.4319
633.8772	1.8556821	0.58521897	3462.1812
634.77808	1.8587244	0.58648336	3463.3696
635.67896	1.8626775	0.58780587	3465.5527
636.57983	1.862875	0.589194	3464.4902
637.48071	1.8682566	0.59067011	3463.0596
638.38159	1.8712975	0.59202093	3468.4839
639.28247	1.8695685	0.59315783	3462.3074
640.18335	1.8733613	0.59465373	3466.6489
641.08423	1.8741982	0.59574145	3455.7498
641.98511	1.8802363	0.59695667	3469.2798
642.88599	1.880699	0.59807533	3463.8215
643.78687	1.8817677	0.59945399	3466.0088
644.68774	1.8873041	0.60060799	3469.3423
645.58862	1.8899114	0.6018092	3470.2515
646.4895	1.8925648	0.60292	3468.7688
647.39038	1.8939601	0.60406363	3471.6765
648.29126	1.8972665	0.60535097	3466.4968
649.19214	1.9039377	0.60656017	3468.6335
650.09302	1.9050742	0.60776359	3472.2566
650.9939	1.9078767	0.60878849	3467.4292
651.89478	1.9086804	0.61013132	3472.8452
652.79565	1.9116764	0.61148423	3472.7126
653.69653	1.9146371	0.61260623	3469.4194
654.59741	1.9173139	0.61381477	3477.1541
655.49829	1.9216905	0.61518806	3476.4397
656.39917	1.9218255	0.6163373	3466.6765
657.30005	1.9254473	0.6175856	3474.6838
658.20093	1.9274206	0.61878735	3473.1323
659.10181	1.9289603	0.620368	3479.959
660.00269	1.9343219	0.62189126	3477.6587
660.90356	1.9359993	0.62301499	3472.3989
661.80444	1.9370166	0.62416846	3471.2046
662.70532	1.9381537	0.62533522	3478.0452
663.6062	1.9461718	0.62682205	3484.2529
664.50708	1.9465797	0.62814218	3482.4153
665.40796	1.9504927	0.62939364	3485.2537
666.30884	1.9517682	0.63066411	3478.3682
667.20972	1.9568154	0.6319055	3480.7239
668.1106	1.955652	0.63317275	3479.0234
669.01147	1.9591709	0.63435733	3478.2231
669.91235	1.9631186	0.63559318	3479.96
670.81323	1.9651232	0.63693005	3478.582
671.71411	1.9671203	0.63824707	3484.8562
672.61499	1.9723417	0.63949686	3483.125
673.51587	1.9732605	0.64076924	3481.7959
674.41675	1.9781431	0.64214426	3485.8279
675.31763	1.9802309	0.64352918	3489.1436
676.21851	1.9791434	0.64477438	3480.9346
677.11938	1.985545	0.64593464	3486.7148
678.02026	1.9883336	0.64721304	3491.2793
678.92114	1.9905589	0.64849222	3488.0383
679.82202	1.9922439	0.64984447	3486.2271
680.7229	1.9960188	0.65100187	3484.562
681.62378	1.9991308	0.65230739	3487.812
682.52466	2.0011518	0.65357202	3491.5615
683.42554	2.0046456	0.65481001	3488.7927
684.32642	2.0066144	0.65609777	3493.1282
685.22729	2.0096705	0.65726775	3490.5313
686.12817	2.014025	0.658696	3492.2507
687.02905	2.0146103	0.66002399	3487.2324
687.92993	2.0198431	0.66108495	3491.729
688.83081	2.0156047	0.66231167	3491.2202
689.73169	2.0207286	0.66339767	3490.7817
690.63257	2.0243027	0.66493255	3498.0859
691.53345	2.0293767	0.6663208	3496.0566
692.43433	2.0358233	0.66777486	3501.0618
693.33521	2.0326624	0.66888434	3493.5515
694.23608	2.036315	0.67019278	3492.896
695.13696	2.0388732	0.67137915	3494.2024
696.03784	2.0432742	0.67265034	3494.781
696.93872	2.0449443	0.6740731	3494.0366
697.8396	2.0440204	0.67544216	3497.99
698.74048	2.0489933	0.6768328	3498.1843
699.64136	2.0539434	0.67818969	3500.7944
700.54224	2.0550497	0.67948723	3502.9377
701.44312	2.0543685	0.68075675	3496.7573
702.34399	2.0594974	0.68226856	3501.4363
703.24487	2.0622737	0.68339425	3494.6484
704.14575	2.0659189	0.68470639	3495.8577
705.04663	2.0696394	0.68591517	3501.7095
705.94751	2.0710909	0.68715417	3501.5437
706.84839	2.0741725	0.68863231	3503.7739
707.74927	2.0785723	0.69000262	3507.1631
708.65015	2.0797055	0.69141102	3504.9863
709.55103	2.0839555	0.69287288	3501.4885
710.4519	2.0849521	0.6942293	3503.843
711.35278	2.0864668	0.69573361	3504.4392
712.25366	2.0935555	0.69714248	3510.5759
713.15454	2.0929539	0.69866467	3504.4644
714.05542	2.0917697	0.69983053	3499.1868
714.9563	2.0976856	0.70122153	3501.7061
715.85718	2.0999222	0.7025187	3505.5662
716.75806	2.1046519	0.70379907	3509.6443
717.65894	2.1051967	0.70499021	3502.1658
718.55981	2.1103039	0.70636475	3506.1074
719.46069	2.1126211	0.70744234	3511.4492
720.36157	2.1154273	0.70870972	3513.957
721.26245	2.116637	0.71000147	3506.1414
722.16333	2.1196525	0.71131295	3513.3855
723.06421	2.1219673	0.71277481	3506.8235
723.96509	2.1242418	0.71405375	3508.2349
724.86597	2.1268733	0.71534812	3504.0564
725.76685	2.1293056	0.71681434	3506.5776
726.66772	2.1322403	0.71812636	3508.6934
727.5686	2.1362486	0.71944445	3511.3079
728.46948	2.1368537	0.72087306	3510.8127
729.37036	2.1443179	0.72246158	3512.6282
730.27124	2.1424918	0.72372705	3513.8479
731.17212	2.147944	0.72519791	3515.7412
732.073	2.1489954	0.72653991	3512.6865
732.97388	2.1508634	0.72790998	3510.6558
733.87476	2.1543982	0.72935128	3511.8567
734.77563	2.1580446	0.73080963	3511.7512
735.67651	2.1601744	0.73228896	3517.9839
736.57739	2.1621907	0.73379403	3517.2478
737.47827	2.1667597	0.73510188	3513.7798
738.37915	2.16645	0.73634863	3512.1946
739.28003	2.1724169	0.73765975	3513.3892
740.18091	2.1768718	0.73887414	3518.8696
741.08179	2.1759686	0.74028248	3518.0439
741.98267	2.1758208	0.74159789	3512.7405
742.88354	2.1816552	0.74309796	3517.1504
743.78442	2.1832421	0.74465179	3519.4617
744.6853	2.1874137	0.74610311	3521.376
745.58618	2.1905622	0.74779189	3524.488
746.48706	2.191412	0.74897355	3510.2241
747.38794	2.1959965	0.75030011	3521.2456
748.28882	2.1986969	0.75172818	3520.1387
749.1897	2.2005816	0.75305814	3516.925
750.09058	2.2012503	0.7546947	3526.3718
750.99146	2.2062857	0.75613499	3513.9736
751.89233	2.2085063	0.75764459	3516.7039
752.79321	2.2107635	0.75899369	3519.1462
753.69409	2.2182751	0.76041085	3524.8804
754.59497	2.2170112	0.76156914	3516.2051
755.49585	2.2216203	0.76291472	3525.3179
756.39673	2.2255487	0.76439613	3529.3416
757.29761	2.2250016	0.7660858	3527.9758
758.19849	2.2286899	0.76766956	3522.6399
759.09937	2.2324593	0.76909548	3524.9617
760.00024	2.2358983	0.77032167	3520.8083
760.90112	2.2359371	0.77149999	3522.0918
761.802	2.2396848	0.77287757	3526.9666
762.70288	2.2370381	0.77445555	3521.4434
763.60376	2.2437513	0.77593642	3520.9272
764.50464	2.2484212	0.77725691	3524.9238
765.40552	2.2472723	0.77874386	3523.4758
766.3064	2.2535403	0.78019857	3526.6079
767.20728	2.2548225	0.78157222	3523.5271
768.10815	2.2589695	0.78298211	3530.6479
769.00903	2.2613401	0.78455728	3526.7952
769.90991	2.262078	0.78618819	3533.8816
770.81079	2.2633088	0.78802145	3528.6277
771.71167	2.268214	0.78964907	3526.4043
772.61255	2.2729468	0.79107481	3523.8911
773.51343	2.2722948	0.79223716	3522.9746
774.41431	2.2767696	0.7935999	3532.1062
775.31519	2.2800777	0.79515404	3528.6675
776.21606	2.2818987	0.79658252	3531.8003
777.11694	2.2891953	0.79810369	3532.2969
778.01782	2.2891595	0.79940122	3528.3091
778.9187	2.292093	0.80079579	3524.7844
779.81958	2.2910187	0.802118	3528.3442
780.72046	2.296603	0.80369067	3530.1848
781.62134	2.2974188	0.8052184	3523.7307
782.52222	2.3002801	0.80691975	3530.4187
783.4231	2.304642	0.80853099	3532.4719
784.32397	2.3069096	0.8100999	3534.9912
785.22485	2.3087244	0.81174034	3527.4526
786.12573	2.3121331	0.81320935	3530.3188
787.02661	2.3147752	0.81470788	3526.2297
787.92749	2.3178365	0.81605947	3532.2275
788.82837	2.3196714	0.81753016	3531.0481
789.72925	2.3219788	0.81895149	3528.3721
790.63013	2.3267066	0.82014507	3531.8369
791.53101	2.3270888	0.8215158	3528.1724
792.43188	2.3319325	0.82307482	3534.3474
793.33276	2.333071	0.82448298	3536.0564
794.23364	2.336555	0.82597995	3530.4236
795.13452	2.3384216	0.82734078	3532.0688
796.0354	2.3408718	0.82884437	3531.7234
796.93628	2.3425505	0.83045137	3535.0815
797.83716	2.3475766	0.83188558	3537.981
798.73804	2.3505263	0.83359504	3537.5735
799.63892	2.3512704	0.83528668	3535.7744
800.53979	2.354959	0.83671534	3537.6609
801.44067	2.3595233	0.83806801	3536.437
802.34155	2.3589952	0.83951801	3534.5
803.24243	2.3634706	0.84114587	3537.0107
804.14331	2.3647444	0.84253633	3527.8794
805.04419	2.3669701	0.84432173	3536.3511
805.94507	2.3726778	0.84611243	3545.988
806.84595	2.3744743	0.84779167	3536.363
807.74683	2.3768685	0.84939122	3541.4954
808.64771	2.3805082	0.85096526	3536.6514
809.54858	2.3805957	0.85229677	3532.0608
810.44946	2.3884821	0.85363406	3535.3687
811.35034	2.3875477	0.85515863	3541.646
812.25122	2.3889291	0.8567493	3543.5586
813.1521	2.3928573	0.85830969	3533.6577
814.05298	2.3939166	0.8599025	3537.562
814.95386	2.3960009	0.86168104	3533.9912
815.85474	2.4014511	0.86316985	3539.637
816.75562	2.4056311	0.86479503	3535.0393
817.65649	2.4069903	0.86599582	3536.0571
818.55737	2.4074488	0.86753339	3535.0771
819.45825	2.4105403	0.86901706	3533.7983
820.35913	2.4123716	0.87051082	3534.6919
821.26001	2.418509	0.87193245	3539.49
822.16089	2.4188221	0.87372684	3543.5422
823.06177	2.4246917	0.87531585	3536.8418
823.96265	2.4263089	0.87686408	3540.6633
824.86353	2.4260633	0.87858629	3535.4619
825.7644	2.4286773	0.88022447	3542.9448
826.66528	2.4324744	0.88184965	3538.4929
827.56616	2.4331398	0.88364255	3537.7388
828.46704	2.4357784	0.88544065	3545.3354
829.36792	2.4416947	0.88711691	3537.9067
830.2688	2.4441967	0.88863468	3537.7864
831.16968	2.4463053	0.89023435	3539.8462
832.07056	2.4527664	0.89179116	3542.5959
832.97144	2.4496939	0.89325672	3537.7556
833.87231	2.4522748	0.89507055	3538.1328
834.77319	2.4591668	0.8967098	3542.8218
835.67407	2.4603217	0.89835298	3536.2385
836.57495	2.4628742	0.8999815	3541.729
837.47583	2.4650927	0.90151167	3537.8911
838.37671	2.4724019	0.90321416	3550.3694
839.27759	2.4728394	0.90492272	3545.9695
840.17847	2.4744442	0.90673953	3540.1511
841.07935	2.4743536	0.90856856	3547.2192
841.98022	2.478276	0.91011059	3536.8628
842.8811	2.4821506	0.91195691	3539.344
843.78198	2.4856656	0.91352671	3539.3542
844.68286	2.489593	0.91512352	3537.2363
845.58374	2.4915025	0.9165135	3538.0525
846.48462	2.4937427	0.91816646	3546.2676
847.3855	2.4972618	0.91966009	3540.5542
848.28638	2.4972386	0.92103761	3534.5178
849.18726	2.4996722	0.92288971	3543.5469
850.08813	2.5035546	0.92472667	3544.4971
850.98901	2.5054817	0.92648977	3537.6755
851.88989	2.511466	0.92826718	3542.7651
852.79077	2.5140038	0.93006235	3543.6125
853.69165	2.5124176	0.93169808	3538.5742
854.59253	2.5171988	0.9332965	3535.2175
855.49341	2.5194271	0.93524116	3547.3975
856.39429	2.5228682	0.93685102	3539.0049
857.29517	2.5249484	0.93860894	3539.5217
858.19604	2.5304832	0.94049191	3548.9795
859.09692	2.5296323	0.94214493	3538.4263
859.9978	2.5337863	0.94412911	3546.8755
860.89868	2.5368671	0.94592124	3539.6953
861.79956	2.5398273	0.94734854	3537.281
862.70044	2.5400522	0.94865155	3535.4568
863.60132	2.5424814	0.950293	3541.3933
864.5022	2.5451071	0.95203269	3538.252
865.40308	2.5511935	0.9538973	3544.1921
866.30396	2.5487573	0.95562708	3535.5959
867.20483	2.5560231	0.95766109	3547.9766
868.10571	2.5581346	0.95926613	3534.8823
869.00659	2.5633745	0.96060359	3541.7263
869.90747	2.5636971	0.9623605	3545.2351
870.80835	2.5651569	0.96438748	3545.0383
871.70923	2.5677428	0.96617305	3537.1069
872.61011	2.5693367	0.96782953	3542.0601
873.51099	2.5765886	0.9697997	3543.9258
874.41187	2.5760748	0.97159672	3540.7722
875.31274	2.5815027	0.97330046	3543.9624
876.21362	2.5827522	0.97514749	3538.9004
877.1145	2.5846176	0.9767127	3538.8826
878.01538	2.5872221	0.97861868	3543.0005
878.91626	2.5869896	0.98063934	3545.1355
879.81714	2.5908437	0.98289281	3539.6255
880.71802	2.596267	0.98481846	3542.3623
881.6189	2.5990436	0.98648685	3534.9495
882.51978	2.6005175	0.98798698	3530.4758
883.42065	2.604027	0.98934472	3538.7395
884.32153	2.6066015	0.99093473	3538.8008
885.22241	2.6100235	0.9929682	3547.1057
886.12329	2.6119251	0.99480444	3542.4814
887.02417	2.6153855	0.99659675	3544.6733
887.92505	2.6161892	0.99870819	3537.2771
888.82593	2.6188877	1.0007284	3540.9956
889.72681	2.623337	1.0030397	3545.1125
890.62769	2.6242263	1.0048995	3532.3604
891.52856	2.6277158	1.0067648	3536.7576
892.42944	2.6297526	1.0086247	3537.3816
893.33032	2.6340637	1.0105284	3534.1802
894.2312	2.63568	1.0121733	3535.2173
895.13208	2.6396511	1.0139673	3533.802
896.03296	2.6401422	1.0155455	3534.1375
896.93384	2.6438138	1.0173763	3540.5317
897.83472	2.6439512	1.0191792	3533.2788
898.7356	2.6490128	1.0212259	3538.2778
899.63647	2.6513379	1.0232055	3537.7488
900.53735	2.6540229	1.0251664	3541.5916
901.43823	2.6577234	1.0272471	3542.0833
902.33911	2.6612842	1.0294561	3532.9656
903.23999	2.6636653	1.0314113	3533.9272
904.14087	2.6662884	1.0334219	3533.5596
905.04175	2.6693313	1.0355049	3535.6077
905.94263	2.6697218	1.0373322	3534.6221
906.84351	2.6721141	1.0393674	3531.7026
907.74438	2.679646	1.0415149	3535.1582
908.64526	2.6782112	1.0431571	3533.3621
909.54614	2.6819723	1.0450915	3533.7778
910.44702	2.6845734	1.0470676	3540.3425
911.3479	2.6872873	1.0493686	3536.4241
912.24878	2.6901133	1.0514138	3536.3499
913.14966	2.693495	1.0534917	3532.2979
914.05054	2.693388	1.0553619	3531.415
914.95142	2.698868	1.0575398	3536.2202
915.85229	2.7010026	1.0598177	3529.8508
916.75317	2.7057962	1.0618939	3532.7891
917.65405	2.7036741	1.0637408	3525.6416
918.55493	2.7101338	1.0655408	3527.7175
919.45581	2.7098677	1.0673406	3526.3345
920.35669	2.7131364	1.0694097	3534.8254
921.25757	2.7159889	1.0715709	3534.4385
922.15845	2.7200155	1.0736328	3528.999
923.05933	2.7216432	1.0758814	3528.4348
923.96021	2.7263851	1.0782015	3531.3589
924.86108	2.7321239	1.0801511	3528.2803
925.76196	2.7322321	1.0818591	3522.9124
926.66284	2.7336829	1.0840927	3531.2715
927.56372	2.7357883	1.0861359	3523.5703
928.4646	2.7379012	1.0880033	3523.3157
929.36548	2.7406001	1.0901794	3526.9749
930.26636	2.7443688	1.0924004	3523.145
931.16724	2.747287	1.0940574	3516.7673
932.06812	2.7521822	1.0959495	3528.3257
932.96899	2.7513945	1.0979626	3518.8699
933.86987	2.7568717	1.0997893	3521.7473
934.77075	2.7562048	1.1020428	3527.7161
935.67163	2.762794	1.1037644	3516.3057
936.57251	2.7641275	1.1058291	3522.7104
937.47339	2.7652042	1.1077988	3521.3748
938.37427	2.7692401	1.1103015	3525.1812
939.27515	2.76985	1.1131165	3518.3252
940.17603	2.7744131	1.1153003	3512.8945
941.0769	2.77545	1.1170139	3512.5059
941.97778	2.7777677	1.1186494	3518.8831
942.87866	2.7825959	1.1208745	3518.6655
943.77954	2.7838564	1.1230345	3515.6707
944.68042	2.7886834	1.1253041	3515.29
945.5813	2.7911026	1.1273154	3513.9143
946.48218	2.7919989	1.1293384	3515.1807
947.38306	2.7971334	1.1315033	3520.4009
948.28394	2.8004711	1.1338574	3513.3315
949.18481	2.8016551	1.1362709	3509.0952
950.08569	2.8070145	1.1386303	3510.6836
950.98657	2.8057835	1.1408715	3509.6848
951.88745	2.8086188	1.1425276	3505.8198
952.78833	2.8108313	1.1445209	3505.7561
953.68921	2.8160863	1.1468704	3511.0393
954.59009	2.816335	1.1492447	3507.5007
955.49097	2.8231485	1.1514091	3508.8623
956.39185	2.8267162	1.1538569	3509.2417
957.29272	2.8278766	1.1562619	3502.0652
958.1936	2.8275747	1.1582958	3494.8733
959.09448	2.8325863	1.1602737	3498.1606
959.99536	2.8309193	1.1623647	3497.6069
960.89624	2.8353772	1.1646639	3501.1826
961.79712	2.8386259	1.1671597	3498.7527
962.698	2.8429725	1.1694452	3496.7026
963.59888	2.8426845	1.1719972	3491.0996
964.49976	2.8483548	1.1741029	3490.5447
965.40063	2.8456113	1.1761599	3493.0076
966.30151	2.8502765	1.1787846	3491.5359
967.20239	2.8547711	1.1810672	3489.6228
968.10327	2.8610194	1.1831956	3491.0288
969.00415	2.8601258	1.1852411	3486.5618
969.90503	2.8644495	1.1871504	3486.1133
970.80591	2.8639245	1.1890584	3480.606
971.70679	2.8701856	1.1908604	3482.0894
972.60767	2.8705969	1.1924893	3479.7585
973.50854	2.8743408	1.1943985	3483.575
974.40942	2.8765929	1.1968709	3484.8259
975.3103	2.8797514	1.1996367	3485.0369
976.21118	2.88153	1.2023304	3484.7188
977.11206	2.8863065	1.2047751	3474.1716
978.01294	2.8858793	1.2069577	3468.7678
978.91382	2.890065	1.2089283	3471.6882
979.8147	2.8918014	1.2108624	3468.2798
980.71558	2.8972859	1.2128015	3470.0339
981.61646	2.8952744	1.2147093	3465.2495
982.51733	2.9034972	1.2167572	3474.4041
983.41821	2.9041231	1.2194847	3470.1987
984.31909	2.9085748	1.2219958	3470.4016
985.21997	2.9104035	1.2246249	3467.3672
986.12085	2.9133215	1.2270608	3464.7854
987.02173	2.9110119	1.229409	3461.4011
987.92261	2.9149046	1.2314656	3455.238
988.82349	2.9220695	1.233737	3459.7046
989.72437	2.9215822	1.2361398	3453.292
990.62524	2.9272554	1.2386143	3455.9058
991.52612	2.9268477	1.2413548	3454.5051
992.427	2.9316163	1.2435297	3446.0054
993.32788	2.9338326	1.2456192	3447.4409
994.22876	2.9344847	1.2478291	3447.6025
995.12964	2.9384456	1.2503233	3445.3469
996.03052	2.9418738	1.2528884	3444.0427
996.9314	2.9436116	1.255464	3443.7927
997.83228	2.9508002	1.2578291	3444.0618
998.73315	2.950048	1.2605371	3440.2007
999.63403	2.9521742	1.262771	3433.3218
1000.5349	2.9548125	1.2652091	3434.4424
1001.4358	2.959703	1.2674404	3432.7385
1002.3367	2.9635699	1.2695343	3429.5503
1003.2375	2.9616642	1.2721671	3426.988
1004.1384	2.9656951	1.2744122	3422.5403
1005.0393	2.9689679	1.2761565	3416.52
1005.9402	2.9734275	1.2782302	3422.2058
1006.8411	2.976068	1.2805961	3423.8855
1007.7419	2.9749999	1.2829546	3417.6694
1008.6428	2.9778216	1.2849193	3413.5034
1009.5437	2.98279	1.2869374	3412.6155
1010.4446	2.9856706	1.2890664	3417.9478
1011.3455	2.9880619	1.2915788	3413.0874
1012.2463	2.9873827	1.2943161	3405.1187
1013.1472	2.9928262	1.2970704	3402.1707
1014.0481	2.9976685	1.2993823	3398.3796
1014.949	2.9990616	1.3009727	3385.303
1015.8499	3.005512	1.3025815	3395.2769
1016.7507	3.0062654	1.3041627	3397.0916
1017.6516	3.0072536	1.306361	3400.8091
1018.5525	3.0065906	1.3099061	3392.6877
1019.4534	3.0134742	1.3128712	3386.2175
1020.3542	3.014035	1.3156304	3385.23
1021.2551	3.0141127	1.3181494	3381.3186
1022.156	3.0205638	1.3206314	3377.707
1023.0569	3.0238152	1.3230368	3366.3623
1023.9578	3.0269668	1.3252552	3366.637
1024.8586	3.0311797	1.3277625	3368.7778
1025.7595	3.0320716	1.3303528	3361.9417
1026.6604	3.0327559	1.3326883	3357.2708
1027.5613	3.0380197	1.334969	3357.5063
1028.4622	3.0378273	1.3372151	3350.4026
1029.363	3.041693	1.3395898	3355.9282
1030.2639	3.0443535	1.3424344	3348.4102
1031.1648	3.0485122	1.3454112	3346.0278
1032.0657	3.0510542	1.3479167	3338.863
1032.9666	3.0547626	1.3504796	3341.344
1033.8674	3.0578406	1.3531584	3333.1567
1034.7683	3.0589964	1.3558701	3328.2148
1035.6692	3.0612996	1.3587832	3328.0664
1036.5701	3.064358	1.3615674	3314.592
1037.4709	3.0673246	1.3641582	3305.3662
1038.3718	3.0695481	1.3667927	3296.9941
1039.2727	3.0723641	1.3703882	3290.312
1040.1736	3.0742135	1.3738718	3281.981
1041.0745	3.078615	1.3774717	3266.8616
1041.9753	3.0820434	1.380219	3255.9866
1042.8762	3.0820477	1.3829396	3253.3369
1043.7771	3.0865943	1.3856745	3244.7642
1044.678	3.0890024	1.3885664	3234.9668
1045.5789	3.0911796	1.3908483	3225.9739
1046.4797	3.0945759	1.3933541	3230.094
1047.3806	3.0971403	1.3967078	3216.5608
1048.2815	3.1016872	1.4008244	3199.084
1049.1824	3.1015975	1.4044312	3177.9668
1050.0833	3.1061394	1.4076791	3170.6506
1050.9841	3.1086979	1.412408	3153.814
1051.885	3.1125374	1.4218764	3066.0249
1052.7859	3.1187487	1.4405012	2882.2717