File: datasets/am_bench_2022/raw_data/60-X.05-4/specimen.dat
MTS793|MPT|ENU|1|2|.|/|:|1|0|0|A

Operator Information						Time:	20.085205	Sec	11/1/2021 8:50:19 AM
Operator	Nick Derimow
Project	AM Bench 2022 mini-tensile challenge
Specimen ID	60-X.05-4
Material	PBF-L Inconel 625
Specimen Width	2.54	mm
Specimen Thickness	1.52	mm
Notes
Operator Information End

Data Acquisition						Time:	1021.0935	Sec	11/1/2021 9:07:00 AM
Time	Axial Displacement	Axial Extensometer	Axial Force
Sec	mm	mm	N
20.213379	0.002905959	0.00010224865	39.584995
21.214355	0.0014895479	0.00010880106	54.021523
22.215332	0.0077447668	0.00011433312	65.70578
23.216309	0.010353182	0.00020019063	77.237251
24.217285	0.013679382	0.00021396237	92.223595
25.218262	0.017912174	0.00030623196	104.94992
26.219238	0.021712029	0.00033737434	117.20837
27.220215	0.021818778	0.00039488723	131.23283
28.221191	0.023726057	0.00037895903	142.29199
29.222168	0.028905496	0.00045723555	155.41592
30.223145	0.02920812	0.00042141654	167.57632
31.224121	0.034657296	0.00053656014	186.66678
32.225098	0.036111612	0.00058018451	204.53439
33.226074	0.039591637	0.00069354556	225.79861
34.227051	0.042752694	0.00087296241	247.13292
35.228027	0.044588875	0.00086085335	260.61096
36.229004	0.049487356	0.00093128975	284.79739
37.22998	0.051366359	0.0010010715	299.16461
38.230957	0.053585328	0.0010975936	318.70187
39.231934	0.058974527	0.0011717344	341.01691
40.23291	0.058324818	0.0013225741	360.905
41.233887	0.065631129	0.001446777	382.21494
42.234863	0.065225646	0.0014649795	409.06952
43.23584	0.066915177	0.0015747795	429.52789
44.236816	0.071989864	0.0017238234	458.5798
45.237793	0.074807063	0.0018033539	476.14246
46.23877	0.076494344	0.001872024	500.71423
47.239746	0.080941036	0.0019082805	518.37567
48.240723	0.085191451	0.0020818631	543.96844
49.241699	0.085356392	0.0022072257	568.48303
50.242676	0.087918706	0.0022206861	596.18457
51.243652	0.094847247	0.0023693088	621.52069
52.244629	0.093830168	0.0024667948	641.15692
53.245605	0.096029259	0.0024984248	666.6615
54.246582	0.10156327	0.0026180854	686.20544
55.247559	0.1024947	0.0027121815	714.42511
56.248535	0.10770646	0.0027280934	739.81226
57.249512	0.10872293	0.0028708153	768.58929
58.250488	0.11310815	0.0030250296	806.74335
59.251465	0.1160868	0.003119468	825.33392
60.252441	0.12124796	0.0033513072	859.77673
61.253418	0.12496955	0.0034513215	888.81427
62.254395	0.1273618	0.0035078542	915.23157
63.255371	0.12820534	0.0035613624	938.52997
64.256348	0.13291328	0.0036882022	973.60626
65.257324	0.13428031	0.0037753361	992.65747
66.258301	0.13749766	0.0039927769	1031.5645
67.259277	0.14275286	0.004119467	1061.0785
68.260254	0.14568233	0.004288333	1086.5349
69.26123	0.14635253	0.0042667538	1113.2368
70.262207	0.15118831	0.0044253455	1140.005
71.263184	0.15057799	0.0045108539	1162.3741
72.26416	0.15452839	0.0046480671	1198.2214
73.265137	0.15750889	0.0046605822	1222.7209
74.266113	0.16271538	0.0048594596	1250.7539
75.26709	0.16216955	0.0049028797	1270.012
76.268066	0.16622204	0.0051186639	1307.0912
77.269043	0.17050216	0.0051343627	1320.641
78.27002	0.17426494	0.0053168815	1355.4772
79.270996	0.17540433	0.0054124868	1386.5264
80.271973	0.18183494	0.0055801021	1425.9299
81.272949	0.18179129	0.0056985812	1450.6498
82.273926	0.18634412	0.0058148392	1477.7931
83.274902	0.18957812	0.0059719561	1507.4523
84.275879	0.1882492	0.0060161827	1528.127
85.276855	0.19291431	0.0061192131	1548.7496
86.277832	0.19827867	0.0061758696	1577.2729
87.278809	0.20332041	0.0062939012	1611.8531
88.279785	0.20343126	0.0063961735	1616.8097
89.280762	0.20650581	0.0065925675	1654.1823
90.281738	0.21267416	0.0066303206	1679.4434
91.282715	0.2132128	0.0067864158	1701.5023
92.283691	0.21541005	0.0069608917	1732.8735
93.284668	0.21925458	0.0069634859	1749.3844
94.285645	0.22097033	0.0070979372	1782.1263
95.286621	0.22098038	0.0071495986	1788.5366
96.287598	0.22699936	0.0073617273	1820.6046
97.288574	0.23248075	0.0074591395	1845.3591
98.289551	0.23122293	0.0074888035	1862.1561
99.290527	0.23567188	0.007670749	1880.7283
100.2915	0.23989545	0.0077558802	1906.389
101.29248	0.24209905	0.0077807619	1922.9116
102.29346	0.24763761	0.007893716	1941.4767
103.29443	0.25086051	0.0080727236	1965.0966
104.29541	0.25145647	0.0080530178	1977.9003
105.29639	0.25397664	0.0083185211	1994.3844
106.29736	0.26200354	0.0083194142	2017.3547
107.29834	0.2638115	0.0083984388	2041.4551
108.29932	0.26415715	0.0084536318	2044.4174
109.30029	0.26702559	0.0084635327	2058.7581
110.30127	0.27024522	0.0086236447	2073.1301
111.30225	0.27298272	0.0086692646	2089.677
112.30322	0.27932525	0.0088223908	2113.1831
113.3042	0.28106046	0.0088838981	2117.3452
114.30518	0.2811918	0.0089342427	2131.2173
115.30615	0.28429466	0.00897625	2142.2327
116.30713	0.28978974	0.0090005416	2155.9038
117.30811	0.29281017	0.0089955665	2169.2229
118.30908	0.29576942	0.0091253147	2177.0925
119.31006	0.30008683	0.0091979355	2189.4619
120.31104	0.30053309	0.0092171738	2202.9797
121.31201	0.30520573	0.0093743652	2212.6316
122.31299	0.30390143	0.0093506714	2217.0989
123.31396	0.30711162	0.0094216736	2227.667
124.31494	0.3129186	0.00945439	2234.2373
125.31592	0.31532231	0.0094889337	2243.9333
126.31689	0.31685942	0.0094931135	2248.5403
127.31787	0.32227668	0.0097329775	2272.7998
128.31885	0.32451224	0.0097363992	2274.8069
129.31982	0.329927	0.0097917309	2287.2849
130.3208	0.33253932	0.0098830825	2300.0029
131.32178	0.33402908	0.0098696509	2309.7861
132.32275	0.33411902	0.0099674147	2312.8113
133.32373	0.34063244	0.010092503	2328.7874
134.32471	0.34176961	0.010218957	2333.6924
135.32568	0.34626153	0.01028847	2348.5535
136.32666	0.35114819	0.010232647	2355.1685
137.32764	0.34968424	0.010201013	2362.9006
138.32861	0.35552391	0.010373669	2372.3777
139.32959	0.35611218	0.010386126	2382.3767
140.33057	0.35967454	0.010474879	2385.2817
141.33154	0.3643094	0.010534141	2397.8254
142.33252	0.36764967	0.010623964	2413.7676
143.3335	0.36914554	0.010721774	2410.3967
144.33447	0.37368485	0.010833769	2422.6226
145.33545	0.37503999	0.010857086	2430.6785
146.33643	0.37517747	0.010907588	2442.3848
147.3374	0.38014644	0.010957449	2445.7144
148.33838	0.38286427	0.011039196	2450.7432
149.33936	0.38765067	0.011027754	2461.6184
150.34033	0.39128995	0.01117464	2470.009
151.34131	0.39320275	0.011203975	2479.1667
152.34229	0.39684176	0.011329588	2482.8982
153.34326	0.39856184	0.011397529	2495.1497
154.34424	0.39975324	0.011466241	2500.6941
155.34521	0.40833503	0.011582917	2508.4734
156.34619	0.40918487	0.011659065	2515.5095
157.34717	0.41041136	0.011728011	2522.103
158.34814	0.41422698	0.011848817	2533.3401
159.34912	0.41802239	0.011916442	2541.438
160.3501	0.4186596	0.012068171	2551.6948
161.35107	0.4222984	0.012003029	2549.575
162.35205	0.42953894	0.012189948	2568.2222
163.35303	0.43033433	0.01227749	2563.1953
164.354	0.43266144	0.012452964	2572.415
165.35498	0.43615702	0.012516808	2581.8005
166.35596	0.44146815	0.012753241	2596.5483
167.35693	0.44238135	0.012830348	2597.9985
168.35791	0.44613472	0.012945225	2606.2866
169.35889	0.44917896	0.013157175	2610.7671
170.35986	0.45083773	0.013145369	2614.4077
171.36084	0.45413682	0.013266986	2615.1865
172.36182	0.45370144	0.013375995	2628.23
173.36279	0.4604556	0.013705104	2640.7874
174.36377	0.46272579	0.013767783	2646.5198
175.36475	0.46731997	0.014000209	2654.1365
176.36572	0.46978277	0.01414039	2659.3289
177.3667	0.47325274	0.014359125	2666.1633
178.36768	0.47579646	0.01446318	2666.0017
179.36865	0.47733331	0.014773766	2674.9983
180.36963	0.48186952	0.015021723	2686.2461
181.37061	0.48650759	0.01530889	2688.6948
182.37158	0.48718271	0.015502756	2700.7798
183.37256	0.49045005	0.01576083	2697.7336
184.37354	0.49758166	0.016151084	2713.6287
185.37451	0.49667254	0.016400954	2712.7671
186.37549	0.49979264	0.01659094	2714.0417
187.37646	0.50443804	0.017002748	2724.7485
188.37744	0.5053041	0.017227614	2730.0923
189.37842	0.50957644	0.017644489	2737.5327
190.37939	0.51134133	0.018078983	2741.6965
191.38037	0.5144577	0.018515155	2743.7151
192.38135	0.51626956	0.018728707	2749.5515
193.38232	0.52255201	0.019311942	2757.6523
194.3833	0.5230155	0.019657426	2753.8528
195.38428	0.52509636	0.020092035	2761.8464
196.38525	0.53195375	0.020635182	2776.0791
197.38623	0.53407127	0.021015026	2776.082
198.38721	0.5374667	0.021545786	2778.3936
199.38818	0.54071009	0.022041488	2783.3442
200.38916	0.54032999	0.022530915	2791.1353
201.39014	0.54349858	0.023047898	2794.1846
202.39111	0.54762852	0.023561325	2796.0825
203.39209	0.55396432	0.024140442	2801.231
204.39307	0.55529916	0.024670636	2805.0747
205.39404	0.55434585	0.025364995	2807.0005
206.39502	0.56097168	0.025834851	2808.5066
207.396	0.56172055	0.026301635	2810.9319
208.39697	0.56730092	0.026858069	2823.7695
209.39795	0.56750417	0.027503418	2813.9824
210.39893	0.57198447	0.02819879	2828.4641
211.3999	0.57269341	0.029056851	2831.8567
212.40088	0.57506251	0.029854773	2835.2659
213.40186	0.57928568	0.030580714	2837.4783
214.40283	0.58382928	0.031404871	2848.6001
215.40381	0.58721852	0.032028858	2843.3477
216.40479	0.59227359	0.032889817	2852.8677
217.40576	0.59542024	0.033703737	2858.3235
218.40674	0.59548092	0.034481481	2855.7263
219.40771	0.59955162	0.035190616	2857.2253
220.40869	0.59990937	0.036070548	2861.9043
221.40967	0.6062519	0.036648396	2861.8928
222.41064	0.6105988	0.037440069	2870.8999
223.41162	0.61137593	0.038297206	2873.6323
224.4126	0.61318904	0.039136477	2875.8843
225.41357	0.61673462	0.039930686	2868.281
226.41455	0.62079591	0.040853452	2883.1094
227.41553	0.62314582	0.041579708	2884.9536
228.4165	0.62629616	0.042440027	2888.4922
229.41748	0.62900579	0.043309622	2891.2883
230.41846	0.63322365	0.044209279	2893.5044
231.41943	0.63439107	0.045113258	2893.8113
232.42041	0.63800532	0.045989513	2897.8948
233.42139	0.64131099	0.046727482	2896.2849
234.42236	0.64456874	0.047840729	2902.3381
235.42334	0.64876872	0.048840154	2912.5735
236.42432	0.65153331	0.049823858	2911.6204
237.42529	0.6519773	0.050610147	2904.574
238.42627	0.6562289	0.051745672	2915.6289
239.42725	0.66109341	0.052796841	2911.082
240.42822	0.66088754	0.053742122	2918.542
241.4292	0.66590828	0.054757614	2920.6855
242.43018	0.66820878	0.055619817	2922.9426
243.43115	0.67134726	0.056495998	2923.9802
244.43213	0.67574602	0.057345424	2927.593
245.43311	0.67677271	0.058342148	2935.8633
246.43408	0.67855603	0.059523083	2932.5789
247.43506	0.68108296	0.06067498	2932.5562
248.43604	0.68366885	0.061581381	2934.2939
249.43701	0.68918282	0.062534526	2939.7031
250.43799	0.69145644	0.063640937	2938.2124
251.43896	0.69286162	0.064783417	2941.8489
252.43994	0.69829792	0.065660134	2940.2131
253.44092	0.70033658	0.066616289	2948.6619
254.44189	0.70136321	0.067859359	2948.3386
255.44287	0.70563906	0.068917379	2951.8901
256.44385	0.70893753	0.070112057	2958.3511
257.44482	0.71388912	0.07115943	2958.7922
258.4458	0.71836096	0.072319157	2960.2112
259.44678	0.71829194	0.073566116	2959.9548
260.44775	0.72037894	0.074664488	2964.2729
261.44873	0.72401059	0.075689033	2960.624
262.44971	0.72813725	0.076767698	2959.4038
263.45068	0.7291978	0.07763011	2968.5859
264.45166	0.73342359	0.078732237	2969.948
265.45264	0.73500139	0.079865322	2968.0166
266.45361	0.7390523	0.080869913	2970.2141
267.45459	0.74386269	0.081908606	2974.7883
268.45557	0.74782503	0.082794078	2974.2847
269.45654	0.74656558	0.083875395	2976.2207
270.45752	0.75324333	0.085002407	2979.9055
271.4585	0.75768572	0.086037949	2982.5728
272.45947	0.75710648	0.087318256	2988.3457
273.46045	0.76287735	0.088512026	2992.5686
274.46143	0.76447445	0.08959505	2987.0256
275.4624	0.77098054	0.090643466	2995.9265
276.46338	0.76875359	0.091877207	2993.845
277.46436	0.77265215	0.092912257	2992.9592
278.46533	0.77764636	0.094006412	2990.8796
279.46631	0.77819669	0.095077969	3000.7278
280.46729	0.78235817	0.096468106	3007.1938
281.46826	0.78521574	0.097639062	2998.3054
282.46924	0.78842598	0.09887366	3004.5432
283.47021	0.79224384	0.1000738	3006.7688
284.47119	0.79747283	0.10148805	3014.6482
285.47217	0.79654628	0.10270103	3007.1233
286.47314	0.79714912	0.1038151	3008.1868
287.47412	0.8029564	0.10484278	3012.2654
288.4751	0.8057071	0.1058965	3016.5952
289.47607	0.80957967	0.1070225	3015.6399
290.47705	0.81362051	0.10846405	3024.0703
291.47803	0.81482649	0.10969933	3023.7839
292.479	0.81679606	0.11091729	3019.9399
293.47998	0.8207041	0.11187503	3023.991
294.48096	0.82360494	0.11300515	3025.5889
295.48193	0.82824236	0.11426897	3035.1621
296.48291	0.83255774	0.11534683	3029.6514
297.48389	0.83068788	0.1165522	3029.6211
298.48486	0.83526599	0.11747251	3026.2659
299.48584	0.83923197	0.11831614	3022.1501
300.48682	0.83945632	0.11939797	3025.1533
301.48779	0.84676862	0.12060058	3039.2192
302.48877	0.84832376	0.12192328	3040.2085
303.48975	0.84983784	0.12312683	3036.5151
304.49072	0.85394889	0.12429	3039.9197
305.4917	0.85582936	0.12537944	3041.9768
306.49268	0.85996592	0.12639627	3045.1758
307.49365	0.86198676	0.12762888	3043.5657
308.49463	0.867172	0.12899333	3047.8882
309.49561	0.86654526	0.13024348	3042.7417
310.49658	0.87372625	0.13128805	3052.4939
311.49756	0.87724537	0.13247959	3057.4126
312.49854	0.87803483	0.13347819	3050.074
313.49951	0.8809846	0.13467655	3056.5
314.50049	0.88476884	0.13583344	3057.4563
315.50146	0.88873553	0.13702263	3059.1216
316.50244	0.8893258	0.13816863	3056.3606
317.50342	0.89100116	0.13939735	3055.9995
318.50439	0.8938477	0.14063101	3059.5889
319.50537	0.90063238	0.14187658	3069.4121
320.50635	0.90422678	0.1430092	3065.332
321.50732	0.9050715	0.14424393	3066.3799
322.5083	0.90862286	0.14530566	3065.3003
323.50928	0.90974641	0.14653701	3066.8184
324.51025	0.91347134	0.14759654	3071.3289
325.51123	0.9192459	0.1487828	3074.946
326.51221	0.92130852	0.14994624	3071.2312
327.51318	0.92436892	0.1510988	3077.0376
328.51416	0.92374951	0.15214421	3074.5305
329.51514	0.92712021	0.15319321	3076.1592
330.51611	0.93268806	0.15440431	3077.0083
331.51709	0.93564868	0.15573491	3085.3748
332.51807	0.94093871	0.15691842	3088.6379
333.51904	0.93918526	0.1580255	3083.0447
334.52002	0.9447369	0.15917042	3083.9214
335.521	0.94829297	0.16022448	3083.6721
336.52197	0.95082247	0.16154847	3089.5662
337.52295	0.95397455	0.16264811	3091.3918
338.52393	0.95571178	0.16376992	3088.8057
339.5249	0.95715255	0.16486265	3094.3606
340.52588	0.96116203	0.16614518	3095.7715
341.52686	0.96382433	0.16760615	3093.1514
342.52783	0.96946824	0.1686344	3097.218
343.52881	0.97034574	0.16968596	3096.9412
344.52979	0.97121692	0.17077744	3098.1609
345.53076	0.97935855	0.17200059	3108.5483
346.53174	0.97820443	0.17309287	3095.9368
347.53271	0.98368275	0.17424597	3105.9924
348.53369	0.98605639	0.17537294	3107.9673
349.53467	0.98737317	0.17656176	3106.8208
350.53564	0.99198318	0.17773411	3104.9348
351.53662	0.99560404	0.17881207	3108.9729
352.5376	1.0017201	0.18005887	3117.0972
353.53857	1.0003629	0.18152228	3117.4988
354.53955	1.0021092	0.18268478	3109.5479
355.54053	1.005264	0.18380885	3105.1865
356.5415	1.0091007	0.18491216	3116.1133
357.54248	1.0137106	0.18612306	3117.1946
358.54346	1.0152876	0.18723305	3117.1653
359.54443	1.0182097	0.18852122	3125.9634
360.54541	1.021353	0.18972635	3124.5378
361.54639	1.0237377	0.19080198	3120.9949
362.54736	1.0273019	0.19195874	3124.4827
363.54834	1.0335088	0.1931513	3131.2344
364.54932	1.0335346	0.19433886	3125.3916
365.55029	1.0392736	0.19546309	3130.6147
366.55127	1.0405523	0.19660345	3125.6873
367.55225	1.0420977	0.19773166	3129.115
368.55322	1.0472194	0.19893941	3139.1003
369.5542	1.0487845	0.20031177	3133.9375
370.55518	1.0527008	0.20148173	3141.0879
371.55615	1.0562906	0.20280077	3139.8276
372.55713	1.0578544	0.20383927	3132.574
373.55811	1.0620396	0.20480052	3138.1013
374.55908	1.0613452	0.20583123	3143.9692
375.56006	1.0682399	0.20696992	3136.8872
376.56104	1.070104	0.20817545	3146.7495
377.56201	1.0749828	0.20934977	3146.9666
378.56299	1.0761709	0.21037769	3142.0854
379.56396	1.0783267	0.21143435	3147.7
380.56494	1.0825782	0.212409	3143.2395
381.56592	1.0833641	0.21352088	3153.3198
382.56689	1.0870286	0.21467349	3147.0703
383.56787	1.0926294	0.2159126	3158.7261
384.56885	1.0950717	0.21717404	3153.95
385.56982	1.0973616	0.21826884	3147.925
386.5708	1.0997765	0.21931307	3158.0229
387.57178	1.1059959	0.22041215	3156.5608
388.57275	1.1039057	0.22163713	3157.5564
389.57373	1.1085931	0.22301137	3157.8491
390.57471	1.1130959	0.22397712	3150.8032
391.57568	1.114004	0.22508159	3169.5745
392.57666	1.1204141	0.22636075	3166.4043
393.57764	1.1196997	0.22761041	3166.5298
394.57861	1.1239721	0.22873253	3162.5969
395.57959	1.128745	0.22992755	3165.2559
396.58057	1.130229	0.23095304	3172.8611
397.58154	1.1361403	0.23205021	3173.9805
398.58252	1.1344783	0.23323056	3171.2454
399.5835	1.1416427	0.23449039	3176.6855
400.58447	1.1404904	0.23550704	3171.1172
401.58545	1.1451545	0.23650616	3170.8003
402.58643	1.1485468	0.23774344	3179.1433
403.5874	1.1546257	0.23878427	3177.8359
404.58838	1.1518686	0.23966476	3178.0266
405.58936	1.155287	0.2407092	3180.5825
406.59033	1.159193	0.2419678	3178.5708
407.59131	1.1638311	0.24315482	3186.4661
408.59229	1.1675256	0.24423492	3182.762
409.59326	1.1695172	0.24530177	3183.9619
410.59424	1.1707022	0.24634975	3184.7175
411.59521	1.1759287	0.24729998	3187.9929
412.59619	1.1773107	0.248717	3197.3271
413.59717	1.1817259	0.25002947	3193.0046
414.59814	1.187775	0.25121492	3191.5146
415.59912	1.1860654	0.25241128	3192.4614
416.6001	1.1903498	0.25356811	3197.9507
417.60107	1.1943226	0.25467452	3193.8528
418.60205	1.1967665	0.25572842	3195.8594
419.60303	1.2011437	0.25666535	3202.5518
420.604	1.2032332	0.25792265	3201.2993
421.60498	1.2033938	0.25896496	3197.7996
422.60596	1.2054501	0.26022595	3200.5259
423.60693	1.2128079	0.26146182	3202.2454
424.60791	1.2164016	0.26293021	3207.2229
425.60889	1.2183714	0.26390991	3206.8333
426.60986	1.2185318	0.26499245	3207.3232
427.61084	1.2253354	0.26598001	3204.5891
428.61182	1.2275455	0.26711902	3211.8904
429.61279	1.2271888	0.26820073	3201.542
430.61377	1.231366	0.26930869	3212.137
431.61475	1.2339579	0.27039582	3211.625
432.61572	1.2403238	0.2716468	3217.5344
433.6167	1.2412189	0.27272511	3211.4553
434.61768	1.2474774	0.27385858	3222.01
435.61865	1.2476068	0.27487904	3210.6301
436.61963	1.2493753	0.27582321	3212.0688
437.62061	1.2521551	0.27698606	3221.5193
438.62158	1.2608594	0.27818012	3225.885
439.62256	1.2573966	0.27931184	3221.7971
440.62354	1.2631605	0.28040689	3219.8726
441.62451	1.2643353	0.28146198	3219.624
442.62549	1.267725	0.28258678	3227.3787
443.62646	1.2717807	0.28358409	3228.1748
444.62744	1.2713646	0.28474212	3223.3262
445.62842	1.2782056	0.28584704	3227.7827
446.62939	1.2810571	0.286863	3233.4175
447.63037	1.2832437	0.28789082	3227.4048
448.63135	1.2872164	0.28895038	3235.8054
449.63232	1.290548	0.29011449	3233.5278
450.6333	1.2931898	0.2910662	3232.2476
451.63428	1.295831	0.29212466	3230.9253
452.63525	1.2984214	0.29311332	3231.7478
453.63623	1.3009921	0.29427665	3236.1572
454.63721	1.3032259	0.29536372	3238.0413
455.63818	1.3098775	0.2965579	3246.8674
456.63916	1.3102695	0.29754269	3245.2441
457.64014	1.3141159	0.29882371	3245.3889
458.64111	1.3147445	0.29993668	3241.0503
459.64209	1.3180104	0.30102506	3241.0559
460.64307	1.3233621	0.30214891	3249.3882
461.64404	1.326656	0.30334631	3248.8149
462.64502	1.3294353	0.30452004	3254.9192
463.646	1.3306848	0.30566132	3245.9221
464.64697	1.3336675	0.30689937	3245.2354
465.64795	1.3361076	0.30784869	3251.542
466.64893	1.3422272	0.30912828	3259.7534
467.6499	1.3444471	0.31033379	3256.1582
468.65088	1.3461438	0.31123742	3251.6287
469.65186	1.3507653	0.31237289	3261.8083
470.65283	1.3540201	0.31360987	3259.1909
471.65381	1.3590142	0.31466553	3265.2195
472.65479	1.3583915	0.31568903	3260.418
473.65576	1.3626537	0.31684747	3263.3564
474.65674	1.3651413	0.31804407	3259.084
475.65771	1.3700467	0.31909627	3261.9822
476.65869	1.3729174	0.32016894	3266.5459
477.65967	1.3735559	0.32114735	3262.8748
478.66064	1.3744915	0.32226205	3264.0288
479.66162	1.3760583	0.32337457	3266.7288
480.6626	1.3816046	0.32447362	3277.3447
481.66357	1.3861264	0.32562765	3271.7185
482.66455	1.3910575	0.32670265	3270.4724
483.66553	1.3926727	0.32760426	3270.3391
484.6665	1.3955191	0.32858554	3273.5095
485.66748	1.3937597	0.32961577	3274.4685
486.66846	1.4022772	0.33084169	3279.5164
487.66943	1.4019364	0.33190134	3276.1377
488.67041	1.4048786	0.33309057	3274.4856
489.67139	1.4113929	0.33427882	3282.4128
490.67236	1.4119445	0.33532637	3273.5742
491.67334	1.4156071	0.33631915	3272.4478
492.67432	1.4165443	0.33734065	3275.3569
493.67529	1.4225184	0.33858627	3284.968
494.67627	1.4246863	0.33976462	3284.5957
495.67725	1.4288824	0.34109914	3285.8967
496.67822	1.4300976	0.34208098	3283.0779
497.6792	1.4352808	0.34302944	3281.0793
498.68018	1.4364963	0.34392127	3286.0667
499.68115	1.4378084	0.3449572	3291.7756
500.68213	1.4430475	0.34615672	3292.3091
501.68311	1.4462522	0.34705809	3286.353
502.68408	1.4483427	0.3482894	3303.7791
503.68506	1.4533608	0.34945601	3300.271
504.68604	1.4507098	0.35058665	3294.8765
505.68701	1.4583218	0.35182163	3301.0247
506.68799	1.4621667	0.35295698	3300.6914
507.68896	1.4649379	0.35406303	3303.4229
508.68994	1.4679327	0.35513911	3299.0779
509.69092	1.4702481	0.35622188	3307.3135
510.69189	1.4746193	0.35731706	3304.3647
511.69287	1.4768192	0.35837474	3303.146
512.69385	1.4786131	0.35940582	3303.7349
513.69482	1.4835118	0.36037153	3306.7534
514.6958	1.4840962	0.36135504	3301.9443
515.69678	1.4864545	0.36244002	3306.936
516.69775	1.4919151	0.36348721	3312.834
517.69873	1.4902381	0.36461869	3306.7532
518.69971	1.4972644	0.3656868	3308.4646
519.70068	1.5003746	0.36687273	3314.8748
520.70166	1.5033	0.36791968	3312.7642
521.70264	1.5069798	0.36884141	3307.8362
522.70361	1.5091991	0.36985409	3317.571
523.70459	1.5128831	0.37130806	3319.1755
524.70557	1.5164677	0.37248644	3312.5569
525.70654	1.5165876	0.37354136	3313.5332
526.70752	1.5195202	0.37467998	3318.563
527.7085	1.5241455	0.37578234	3325.2107
528.70947	1.5257082	0.37685126	3319.8926
529.71045	1.5336684	0.37779629	3323.4692
530.71143	1.5332345	0.37898692	3322.6646
531.7124	1.5365816	0.38008907	3320.3555
532.71338	1.5370417	0.38124776	3324.1865
533.71436	1.5398359	0.38226509	3319.7471
534.71533	1.542366	0.38347298	3327.5098
535.71631	1.5493491	0.38482311	3326.1995
536.71729	1.5521458	0.38580233	3326.6265
537.71826	1.554404	0.38677815	3326.0693
538.71924	1.5560588	0.38765821	3326.5447
539.72021	1.5595151	0.38891685	3336.3489
540.72119	1.5628828	0.39006609	3333.3088
541.72217	1.5642197	0.39109734	3330.0271
542.72314	1.5659945	0.39234838	3331.1238
543.72412	1.5722114	0.39339402	3334.1111
544.7251	1.5731646	0.39453551	3339.4453
545.72607	1.5783376	0.39558178	3336.2419
546.72705	1.581255	0.39666042	3337.1099
547.72803	1.5801555	0.39786515	3343.2742
548.729	1.5856615	0.39917827	3345.7188
549.72998	1.5872012	0.40020579	3335.5383
550.73096	1.5938575	0.40138513	3340.3584
551.73193	1.5976895	0.40244117	3342.8694
552.73291	1.5992913	0.40352288	3343.7808
553.73389	1.5993326	0.40458372	3342.6372
554.73486	1.6048819	0.40568247	3346.5898
555.73584	1.6080728	0.40681097	3346.8574
556.73682	1.6138512	0.40791801	3354.5798
557.73779	1.6150478	0.40883687	3351.491
558.73877	1.6179694	0.40989274	3351.1418
559.73975	1.6174309	0.41101271	3348.748
560.74072	1.6220087	0.41211727	3347.8167
561.7417	1.6263807	0.41313332	3356.6299
562.74268	1.6291745	0.41427079	3354.6558
563.74365	1.633233	0.41524801	3353.5159
564.74463	1.6350665	0.41628399	3352.2214
565.74561	1.6406704	0.41745582	3361.5688
566.74658	1.6425277	0.41887578	3365.7808
567.74756	1.6441941	0.42014599	3365.3506
568.74854	1.6481638	0.42137372	3359.6245
569.74951	1.6476649	0.42250636	3361.9497
570.75049	1.6527029	0.42348945	3357.0054
571.75146	1.6562886	0.42438269	3358.4756
572.75244	1.6569818	0.42546222	3360.4583
573.75342	1.662146	0.42655763	3362.615
574.75439	1.6628705	0.42755672	3362.9333
575.75537	1.6730258	0.42868695	3366.1079
576.75635	1.6690289	0.42972749	3363.2922
577.75732	1.6724329	0.43078634	3367.5698
578.7583	1.6763321	0.43193233	3366.564
579.75928	1.6830336	0.43291077	3372.9531
580.76025	1.6827078	0.43422681	3376.6443
581.76123	1.6889774	0.43536302	3381.5571
582.76221	1.6892436	0.43662256	3375.2656
583.76318	1.6889622	0.43762633	3368.0537
584.76416	1.6964324	0.43860763	3375.8799
585.76514	1.6981075	0.43953317	3365.2004
586.76611	1.7004905	0.44042626	3374.376
587.76709	1.7050747	0.44136974	3371.6472
588.76807	1.7091266	0.44226268	3379.5
589.76904	1.7086554	0.44329494	3373
590.77002	1.7118896	0.44437677	3380.5371
591.771	1.7128229	0.44554371	3382.4695
592.77197	1.7168785	0.44662988	3382.77
593.77295	1.7223353	0.44788119	3382.9814
594.77393	1.7239656	0.4491348	3385.6494
595.7749	1.7286876	0.45015073	3384.2576
596.77588	1.7312957	0.45116073	3387.9854
597.77686	1.7343824	0.45215124	3389.6514
598.77783	1.7380667	0.45336619	3392.8447
599.77881	1.7396297	0.45441416	3386.0488
600.77979	1.7428895	0.45541403	3393.2866
601.78076	1.7459172	0.45653176	3389.9873
602.78174	1.7489595	0.45744058	3387.2043
603.78271	1.7533133	0.45873448	3396.9231
604.78369	1.7564571	0.46012416	3395.7773
605.78467	1.7577778	0.46137545	3392.8123
606.78564	1.7616265	0.46273932	3393.2759
607.78662	1.7638974	0.46372867	3393.0613
608.7876	1.7672186	0.46490481	3399.9785
609.78857	1.7697066	0.46615246	3398.593
610.78955	1.7752001	0.46706805	3399.3843
611.79053	1.7767525	0.46805996	3396.5271
612.7915	1.7765206	0.46900877	3395.1204
613.79248	1.7775064	0.46998513	3390.8364
614.79346	1.7871161	0.47104362	3399.0176
615.79443	1.7886572	0.47200811	3404.7244
616.79541	1.7907867	0.47298509	3404.8916
617.79639	1.791926	0.4742417	3401.4666
618.79736	1.7967451	0.47520119	3407.7488
619.79834	1.800167	0.47627777	3409.3196
620.79932	1.8003811	0.47740477	3401.9944
621.80029	1.8053509	0.47839114	3403.4773
622.80127	1.8095444	0.47936195	3405.3284
623.80225	1.8125752	0.48026958	3408.0754
624.80322	1.8177689	0.48122767	3416.3506
625.8042	1.8166505	0.48251924	3410.0947
626.80518	1.818953	0.48350984	3411.3047
627.80615	1.8230469	0.48483232	3412.9385
628.80713	1.8265721	0.4860208	3408.9807
629.80811	1.8306872	0.48706308	3406.9932
630.80908	1.8322943	0.48800644	3412.9663
631.81006	1.8353574	0.48918009	3414.3081
632.81104	1.8390551	0.49057811	3426.5278
633.81201	1.8443046	0.49194425	3417.1965
634.81299	1.844937	0.49309647	3421.4531
635.81396	1.8485163	0.49436435	3422.5132
636.81494	1.8498331	0.49540094	3418.6157
637.81592	1.8512396	0.4964675	3417.1899
638.81689	1.8575507	0.49755251	3426.2673
639.81787	1.8584301	0.49875677	3421.292
640.81885	1.8609769	0.4999685	3426.5725
641.81982	1.8660426	0.50105739	3422.8997
642.8208	1.8690201	0.50220519	3421.4946
643.82178	1.8703557	0.50325787	3425.8374
644.82275	1.8773102	0.50436407	3432.6155
645.82373	1.8798386	0.50526196	3425.6069
646.82471	1.8823646	0.50633401	3428.6401
647.82568	1.8853148	0.50729191	3423.6824
648.82666	1.8876847	0.50824344	3433.4675
649.82764	1.8894498	0.50922841	3427.6865
650.82861	1.8933336	0.510189	3433.1978
651.82959	1.8988856	0.51131308	3432.1082
652.83057	1.9012611	0.51248509	3433.645
653.83154	1.9008845	0.51361066	3423.8801
654.83252	1.90478	0.51440191	3432.0024
655.8335	1.9101716	0.51534969	3441.0332
656.83447	1.9117768	0.51651061	3435.7476
657.83545	1.9143279	0.51755232	3434.9863
658.83643	1.9180105	0.51871639	3446.8784
659.8374	1.9193865	0.51984298	3438.4424
660.83838	1.9223177	0.52105635	3432.115
661.83936	1.9248503	0.52195609	3441.3267
662.84033	1.928331	0.5228942	3434.5747
663.84131	1.9317776	0.52417153	3442.9541
664.84229	1.9343754	0.5252803	3447.9421
665.84326	1.9388268	0.52632791	3443.1096
666.84424	1.9404391	0.52749038	3445.0718
667.84521	1.9447327	0.52844113	3445.113
668.84619	1.9482119	0.52959085	3446.4358
669.84717	1.9499764	0.53056908	3448.9861
670.84814	1.952901	0.53163791	3446.177
671.84912	1.9561237	0.53297114	3450.3833
672.8501	1.9604393	0.5340308	3455.103
673.85107	1.9620221	0.53533703	3453.4915
674.85205	1.9666246	0.53654563	3449.6865
675.85303	1.9684228	0.5375883	3451.4475
676.854	1.9749765	0.53867579	3451.1755
677.85498	1.9739096	0.53940254	3454.5251
678.85596	1.9761764	0.54061604	3454.7568
679.85693	1.9776961	0.54186761	3454.3105
680.85791	1.9832344	0.54297137	3453.9966
681.85889	1.9889493	0.54425174	3458.5374
682.85986	1.9906104	0.54532808	3452.8704
683.86084	1.9917989	0.54645717	3453.7375
684.86182	1.9928867	0.54739147	3453.9033
685.86279	1.9990693	0.54830718	3458.0461
686.86377	2.0003822	0.54939538	3457.9006
687.86475	2.0008574	0.55060077	3457.6606
688.86572	2.0091825	0.55141968	3457.4167
689.8667	2.0120227	0.55264366	3465.2053
690.86768	2.0143626	0.55371183	3467.0615
691.86865	2.0165813	0.55464065	3465.1914
692.86963	2.0195892	0.55559635	3461.8972
693.87061	2.0215805	0.55667764	3461.5107
694.87158	2.0268738	0.55755877	3468.1841
695.87256	2.0279882	0.55854642	3471.2419
696.87354	2.0319409	0.55975366	3468.9404
697.87451	2.0358427	0.56068707	3464.5349
698.87549	2.0356355	0.56164825	3461.189
699.87646	2.0408895	0.56248635	3468.3357
700.87744	2.0408459	0.56343061	3464.6213
701.87842	2.0456114	0.56459856	3463.7363
702.87939	2.0489051	0.56581408	3476.3682
703.88037	2.0525153	0.56670105	3464.2822
704.88135	2.0573137	0.56786966	3476.0181
705.88232	2.0580034	0.56931645	3474.0073
706.8833	2.0602522	0.57049799	3469.4133
707.88428	2.0625553	0.5716083	3466.8767
708.88525	2.0675108	0.572914	3477.9749
709.88623	2.0704348	0.57471693	3479.7195
710.88721	2.0763268	0.57629555	3474.7444
711.88818	2.0748312	0.57733446	3475.5071
712.88916	2.0801933	0.57850629	3475.9202
713.89014	2.0820339	0.57979161	3471.2954
714.89111	2.0870228	0.58099514	3483.0645
715.89209	2.0882194	0.58257151	3478.3989
716.89307	2.0921228	0.58397692	3480.2803
717.89404	2.0938411	0.58527362	3477.5657
718.89502	2.1005578	0.58664614	3483.5747
719.896	2.1009455	0.58796799	3483.3823
720.89697	2.1036937	0.58946222	3484.8284
721.89795	2.1084685	0.59085935	3488.0244
722.89893	2.1100845	0.59229237	3486.8071
723.8999	2.1102507	0.59341908	3480.7041
724.90088	2.1155396	0.59466952	3485.1045
725.90186	2.1181784	0.59592253	3489.7646
726.90283	2.122251	0.59707409	3488.2153
727.90381	2.1241798	0.59836036	3484.7253
728.90479	2.1291988	0.59946084	3487.9153
729.90576	2.1310279	0.6005162	3487.999
730.90674	2.1339791	0.60142285	3489.125
731.90771	2.1367979	0.60224354	3498.0945
732.90869	2.1392307	0.60315382	3488.4348
733.90967	2.1410315	0.60398704	3484.5332
734.91064	2.1471486	0.60493851	3500.2773
735.91162	2.1494107	0.60575294	3502.4541
736.9126	2.1520913	0.60664666	3491.7515
737.91357	2.1548257	0.60748446	3492.7185
738.91455	2.1549644	0.60821098	3488.6118
739.91553	2.1607571	0.60901523	3499.5537
740.9165	2.1622753	0.60969228	3493.6702
741.91748	2.1657917	0.6105746	3498.5083
742.91846	2.1718645	0.61115122	3493.7764
743.91943	2.1712663	0.61189646	3498.811
744.92041	2.173934	0.61291659	3496.8179
745.92139	2.1790533	0.61355573	3496.3418
746.92236	2.1797149	0.61450475	3497.5474
747.92334	2.1833551	0.61534035	3497.3027
748.92432	2.1893854	0.61614984	3500.6345
749.92529	2.1877713	0.61745381	3501.5796
750.92627	2.1943519	0.61838871	3499.2339
751.92725	2.1963007	0.61953992	3501.9185
752.92822	2.2003422	0.62051535	3507.7322
753.9292	2.2043128	0.62160081	3503.0251
754.93018	2.2029917	0.62275451	3507.345
755.93115	2.2090776	0.62381357	3502.5869
756.93213	2.2129705	0.62477595	3502.6245
757.93311	2.2157066	0.62564391	3503.5352
758.93408	2.2190802	0.626504	3500.0857
759.93506	2.2211237	0.62736851	3507.907
760.93604	2.2248557	0.62837011	3508.5125
761.93701	2.2265522	0.62940025	3504.5737
762.93799	2.2307224	0.63021815	3512.0718
763.93896	2.2343462	0.63126725	3511.0459
764.93994	2.2339742	0.63256347	3512.8503
765.94092	2.2385943	0.63362676	3513.5667
766.94189	2.2418232	0.63497132	3508.4832
767.94287	2.2444391	0.63617855	3519.699
768.94385	2.2484822	0.63771862	3510.7625
769.94482	2.2467182	0.63892388	3508.6128
770.9458	2.2530236	0.64015138	3515.22
771.94678	2.2563989	0.64165306	3513.7456
772.94775	2.2601695	0.6428616	3513.8921
773.94873	2.2620549	0.64406168	3514.7385
774.94971	2.269381	0.64530629	3518.7061
775.95068	2.269908	0.64660716	3519.8994
776.95166	2.2743843	0.6482808	3517.5789
777.95264	2.2746277	0.64978695	3520.2063
778.95361	2.2738891	0.65145731	3520.915
779.95459	2.2807541	0.6534645	3517.2778
780.95557	2.2843251	0.65461999	3516.8843
781.95654	2.2849805	0.65620232	3513.6914
782.95752	2.2897108	0.65799677	3516.4004
783.9585	2.2897623	0.65945911	3518.0745
784.95947	2.2935641	0.66104269	3522.2974
785.96045	2.2996023	0.66275513	3518.696
786.96143	2.3035059	0.66401643	3524.04
787.9624	2.3051393	0.66571003	3525.4749
788.96338	2.307904	0.66721928	3521.0525
789.96436	2.3121519	0.66891873	3524.1455
790.96533	2.3147137	0.67054278	3527.1035
791.96631	2.3166947	0.67193025	3528.9128
792.96729	2.3187718	0.67361462	3525.7246
793.96826	2.3237014	0.67510337	3527.2332
794.96924	2.3255947	0.67662859	3523.0022
795.97021	2.3275735	0.67824441	3524.0039
796.97119	2.3317001	0.67985278	3533.3506
797.97217	2.3363421	0.68149531	3533.7998
798.97314	2.3373034	0.68311495	3525.354
799.97412	2.3384967	0.68441832	3516.4688
800.9751	2.3451233	0.68568224	3529.5957
801.97607	2.3481827	0.68687141	3526.1992
802.97705	2.3463352	0.68820924	3526.9849
803.97803	2.3518789	0.68972743	3533.2158
804.979	2.3560102	0.69123584	3531.5334
805.97998	2.3577135	0.69282156	3528.5264
806.98096	2.360307	0.69411772	3529.1257
807.98193	2.3639348	0.69537789	3531.4475
808.98291	2.3667967	0.69668823	3524.8547
809.98389	2.3723888	0.69804424	3537.2244
810.98486	2.3707721	0.69927919	3533.303
811.98584	2.3752065	0.70063055	3531.6345
812.98682	2.3794413	0.70190287	3532.9878
813.98779	2.3856452	0.70324969	3536.5579
814.98877	2.3843019	0.70455748	3531.0269
815.98975	2.3877597	0.70603299	3536.4192
816.99072	2.3918533	0.70754558	3536.0229
817.9917	2.392704	0.70891601	3541.6543
818.99268	2.3976648	0.71045011	3534.3774
819.99365	2.3992484	0.71171254	3541.0654
820.99463	2.4058897	0.71283859	3540.8191
821.99561	2.4031301	0.71423793	3535.6526
822.99658	2.4107802	0.71544176	3538.2036
823.99756	2.4118924	0.71676147	3534.5386
824.99854	2.4144158	0.71824944	3539.1021
825.99951	2.4194362	0.71948838	3539.9473
827.00049	2.4211786	0.72087896	3545.0203
828.00146	2.4241397	0.72219658	3532.2778
829.00244	2.4275861	0.72292006	3543.1829
830.00342	2.4293694	0.72413439	3542.5229
831.00439	2.4349892	0.7253961	3553.3779
832.00537	2.4351332	0.72653568	3545.9902
833.00635	2.4382298	0.72786415	3541.363
834.00732	2.4427595	0.72903347	3545.6694
835.0083	2.4441471	0.73019779	3544.4407
836.00928	2.4498956	0.7312631	3542.8938
837.01025	2.4519341	0.73229736	3545.6709
838.01123	2.455164	0.73348677	3547.0764
839.01221	2.4566705	0.73466921	3540.657
840.01318	2.4613132	0.73597628	3547.8389
841.01416	2.4666011	0.73748809	3550.2144
842.01514	2.4684062	0.73920989	3545.7151
843.01611	2.4705234	0.74070942	3552.1118
844.01709	2.4738505	0.74231017	3551.6367
845.01807	2.4751806	0.74403745	3547.3247
846.01904	2.4780905	0.74574947	3550.9048
847.02002	2.4818721	0.74742281	3546.4446
848.021	2.4846447	0.74874169	3547.7256
849.02197	2.4885857	0.7498489	3541.6123
850.02295	2.4893191	0.7509442	3551.0403
851.02393	2.492002	0.75276649	3553.5737
852.0249	2.4961896	0.75437397	3558.2417
853.02588	2.4962859	0.75638455	3553.1743
854.02686	2.5041981	0.75828028	3550.627
855.02783	2.504895	0.75976193	3555.3708
856.02881	2.5079081	0.76159811	3551.4719
857.02979	2.51174	0.76344609	3550.4202
858.03076	2.5129259	0.76502705	3555.0493
859.03174	2.5197377	0.76655799	3552.6428
860.03271	2.5223763	0.76817024	3558.5847
861.03369	2.5252206	0.76989537	3556.6707
862.03467	2.5270536	0.77153665	3555.6243
863.03564	2.5306592	0.77321672	3559.2695
864.03662	2.5339067	0.77535427	3555.5134
865.0376	2.5350044	0.7774545	3554.2395
866.03857	2.5387306	0.77879047	3553.3779
867.03955	2.5386522	0.78052324	3560.7698
868.04053	2.5429087	0.78242528	3565.0278
869.0415	2.5467808	0.78426045	3562.9368
870.04248	2.5486965	0.78592694	3558.8018
871.04346	2.5569479	0.78774756	3563.1509
872.04443	2.5551693	0.78954232	3555.9121
873.04541	2.5602288	0.79097474	3552.5732
874.04639	2.5621586	0.79228258	3558.1111
875.04736	2.5637844	0.79383421	3561.8828
876.04834	2.5680294	0.79557246	3556.636
877.04932	2.5693436	0.79723018	3566.4189
878.05029	2.5734885	0.79868782	3556.959
879.05127	2.5786159	0.80018878	3557.5881
880.05225	2.5840983	0.80161095	3563.5769
881.05322	2.5838745	0.803096	3565.2415
882.0542	2.5861256	0.80487442	3560.95
883.05518	2.5905004	0.80670577	3564.281
884.05615	2.5913737	0.80836731	3562.5273
885.05713	2.5971129	0.8099218	3567.0042
886.05811	2.5965767	0.81151497	3557.2764
887.05908	2.6013408	0.81324351	3565.6396
888.06006	2.6064751	0.8150292	3568.1423
889.06104	2.6085155	0.81663436	3564.6165
890.06201	2.6115785	0.81838286	3569.3259
891.06299	2.6141543	0.82010728	3564.6577
892.06396	2.6165838	0.82160252	3561.8811
893.06494	2.6243036	0.82314807	3572.3284
894.06592	2.6252162	0.82477826	3577.2
895.06689	2.6261842	0.82656962	3571.9399
896.06787	2.6317537	0.82810253	3567.0845
897.06885	2.6324546	0.82956111	3568.6606
898.06982	2.6345458	0.8313033	3566.554
899.0708	2.6368699	0.8328743	3567.7002
900.07178	2.6432245	0.83405322	3564.1987
901.07275	2.6427782	0.83539712	3567.6296
902.07373	2.646529	0.83696955	3567.906
903.07471	2.6493421	0.83873367	3576.9424
904.07568	2.6511958	0.84048206	3567.793
905.07666	2.6571376	0.84204435	3570.666
906.07764	2.6587963	0.84393156	3576.1768
907.07861	2.6616855	0.84578967	3567.6709
908.07959	2.6635113	0.84743023	3569.2163
909.08057	2.6682432	0.84925026	3574.6179
910.08154	2.6703928	0.85084242	3572.0537
911.08252	2.6739008	0.85238487	3566.9294
912.0835	2.6781261	0.85424143	3573.5762
913.08447	2.6788485	0.85598153	3570.7451
914.08545	2.6848247	0.85755283	3574
915.08643	2.6862631	0.85958618	3574.2549
916.0874	2.6876528	0.86158806	3569.5032
917.08838	2.6910987	0.86338854	3575.3687
918.08936	2.6968195	0.86493516	3578.1162
919.09033	2.6987791	0.86668932	3572.394
920.09131	2.7012115	0.8681258	3573.4143
921.09229	2.7058737	0.86992562	3577.0496
922.09326	2.7071667	0.87190622	3569.2908
923.09424	2.7110255	0.87352198	3577.8018
924.09521	2.7142651	0.87536776	3580.1025
925.09619	2.7156394	0.87751907	3588.3723
926.09717	2.7172651	0.87945688	3575.0007
927.09814	2.7228959	0.88123643	3565.9668
928.09912	2.7251534	0.88281107	3574.7258
929.1001	2.7259302	0.88424993	3572.0425
930.10107	2.7293096	0.88602895	3577.7595
931.10205	2.7326269	0.88820863	3575.9553
932.10303	2.7398746	0.88976544	3572.1724
933.104	2.740644	0.89137936	3576.4536
934.10498	2.7415359	0.89304435	3572.3557
935.10596	2.7470222	0.89462811	3578.6733
936.10693	2.7495949	0.89640176	3582.4973
937.10791	2.752532	0.89834911	3583.2205
938.10889	2.7547436	0.89993036	3575.1245
939.10986	2.7588952	0.90151238	3580.4111
940.11084	2.7600513	0.90308613	3573.9377
941.11182	2.7669122	0.90456516	3586.9373
942.11279	2.7690773	0.90618634	3582.7593
943.11377	2.7658737	0.90782231	3573.0452
944.11475	2.7709274	0.9095698	3579.3835
945.11572	2.7784851	0.91143805	3580.637
946.1167	2.7809212	0.91343015	3580.7754
947.11768	2.7820964	0.91532999	3572.8091
948.11865	2.7841637	0.91718173	3583.5486
949.11963	2.7881465	0.91917086	3583.3027
950.12061	2.792685	0.92085642	3582.3237
951.12158	2.7921143	0.92280656	3577.3726
952.12256	2.7965541	0.92483079	3581.6575
953.12354	2.8001094	0.92667443	3582.0139
954.12451	2.8026869	0.92856985	3581.833
955.12549	2.8047054	0.93064356	3587.2332
956.12646	2.8099611	0.93249071	3582.3623
957.12744	2.8109641	0.9343425	3582.085
958.12842	2.8162651	0.9364599	3585.073
959.12939	2.818475	0.93852985	3579.6919
960.13037	2.820437	0.94026405	3578.949
961.13135	2.8228097	0.9425568	3582.5186
962.13232	2.8254328	0.94443256	3578.5142
963.1333	2.8296945	0.94649804	3579.0095
964.13428	2.8301609	0.94882864	3579.7556
965.13525	2.8365872	0.95070362	3580.373
966.13623	2.840229	0.95258522	3584.123
967.13721	2.844027	0.95466357	3578.134
968.13818	2.8452766	0.95670485	3580.0527
969.13916	2.8501127	0.958727	3582.7986
970.14014	2.8531871	0.96053344	3584.2791
971.14111	2.8515027	0.96259314	3573.8699
972.14209	2.8572085	0.96454149	3587.363
973.14307	2.8617618	0.96657485	3584.8174
974.14404	2.8662469	0.96892679	3585.4004
975.14502	2.8653054	0.9706583	3582.1445
976.146	2.8676169	0.97230905	3576.7988
977.14697	2.8734322	0.97409683	3582.3621
978.14795	2.8758018	0.9759047	3589.7344
979.14893	2.8776834	0.97779834	3585.9187
980.1499	2.8784122	0.98001361	3580.5364
981.15088	2.885201	0.9816196	3579.8796
982.15186	2.8875933	0.98376596	3583.5532
983.15283	2.8893514	0.98581398	3585.1899
984.15381	2.8947301	0.9880231	3587.0256
985.15479	2.8959002	0.99064583	3587.5029
986.15576	2.899482	0.99286175	3586.2402
987.15674	2.899791	0.99538428	3587.0632
988.15771	2.9044793	0.99774939	3582.8203
989.15869	2.9099696	0.99979609	3584.6316
990.15967	2.9106274	1.001856	3590.9656
991.16064	2.915416	1.0044006	3596.5427
992.16162	2.9167147	1.0072683	3585.3142
993.1626	2.9211702	1.0095856	3586.6072
994.16357	2.923496	1.0115778	3576.5544
995.16455	2.9250035	1.0133821	3582.833
996.16553	2.9289896	1.0150437	3587.3801
997.1665	2.9317667	1.0174128	3588.7749
998.16748	2.9329257	1.0193795	3579.3611
999.16846	2.9368303	1.021394	3589.3809
1000.1694	2.9445524	1.0231605	3586.5759
1001.1704	2.9444768	1.0246177	3584.5107
1002.1714	2.9483254	1.0266203	3588.7107
1003.1724	2.9495132	1.0284075	3589.1638
1004.1733	2.9523149	1.03061	3595.0029
1005.1743	2.9577982	1.0329934	3598.0078
1006.1753	2.9592712	1.0350943	3581.7061
1007.1763	2.9632852	1.036816	3581.7961
1008.1772	2.9637539	1.0387454	3578.4861
1009.1782	2.9709592	1.0404829	3587.3523
1010.1792	2.9713886	1.0424663	3584.2017
1011.1802	2.9737918	1.0442481	3582.4097
1012.1812	2.9734681	1.0462222	3581.1563
1013.1821	2.9821095	1.0482733	3586.002
1014.1831	2.9823921	1.0501732	3587.8003
1015.1841	2.9881053	1.0522026	3590.5701
1016.1851	2.9882209	1.0545044	3579.061
1017.186	2.9931438	1.056276	3587.2656
1018.187	2.9964616	1.0584418	3590.26
1019.188	3.0002794	1.0608898	3590.3442
1020.189	3.0030024	1.0631092	3582.1555
1021.1899	3.0041354	1.0652772	3583.481
1022.1909	3.0107927	1.0675926	3587.4961
1023.1919	3.0093436	1.0696628	3582.885
1024.1929	3.0138271	1.0718764	3580.9348
1025.1938	3.0195432	1.0740197	3590.77
1026.1948	3.0206296	1.0760368	3586.3081
1027.1958	3.0244138	1.0781484	3586.7349
1028.1968	3.0247064	1.0799909	3582.5842
1029.1978	3.0290945	1.0819504	3584.6943
1030.1987	3.0327902	1.0843183	3586.4517
1031.1997	3.0334992	1.0865614	3580.7991
1032.2007	3.0362911	1.0887426	3583.6089
1033.2017	3.0435591	1.0911222	3592.5417
1034.2026	3.0447814	1.0937579	3591.5647
1035.2036	3.0459564	1.0958537	3586.6775
1036.2046	3.0508981	1.098682	3587.1982
1037.2056	3.0504694	1.1012727	3582.5146
1038.2065	3.0574079	1.103474	3586.0208
1039.2075	3.057483	1.1059812	3581.7397
1040.2085	3.0600085	1.108139	3582.2676
1041.2095	3.0628068	1.1105745	3583.4639
1042.2104	3.0676775	1.1131446	3585.7383
1043.2114	3.0720367	1.1157888	3587.8354
1044.2124	3.077224	1.1182808	3587.1958
1045.2134	3.0746953	1.1209294	3580.1794
1046.2144	3.0806994	1.1235068	3588.062
1047.2153	3.0828216	1.1261442	3584.0811
1048.2163	3.086277	1.1282983	3579.9949
1049.2173	3.090111	1.1305287	3585.9282
1050.2183	3.0916841	1.1327345	3581.4124
1051.2192	3.0959251	1.134964	3583.0146
1052.2202	3.1000123	1.137506	3590.3528
1053.2212	3.1008551	1.1400868	3579.2522
1054.2222	3.1049352	1.1420338	3581.6902
1055.2231	3.1061826	1.1438059	3582.0864
1056.2241	3.1115386	1.1461869	3587.0652
1057.2251	3.1095314	1.148478	3577.1775
1058.2261	3.1167097	1.1506321	3584.9253
1059.2271	3.1186659	1.1528153	3588.2068
1060.228	3.1198626	1.1548506	3582.0518
1061.229	3.1228945	1.1568785	3585.1479
1062.23	3.1278472	1.1592722	3582.7249
1063.231	3.1308639	1.1609287	3576.4216
1064.2319	3.1318152	1.1630235	3583.6975
1065.2329	3.1386433	1.1653172	3581.7153
1066.2339	3.1403356	1.1680276	3584.7473
1067.2349	3.1427684	1.1712209	3583.3794
1068.2358	3.1481798	1.1735345	3579.0801
1069.2368	3.1466026	1.175992	3575.8096
1070.2378	3.1523423	1.1791288	3584.0457
1071.2388	3.1562011	1.1819983	3579.803
1072.2397	3.1588998	1.1847117	3575.9153
1073.2407	3.159796	1.1874639	3576.1904
1074.2417	3.162708	1.1903267	3575.7065
1075.2427	3.1646383	1.1924373	3578.6077
1076.2437	3.1679461	1.1951345	3579.7058
1077.2446	3.1733904	1.1975168	3575.0471
1078.2456	3.1730468	1.1996481	3576.0813
1079.2466	3.1789052	1.2021433	3579.4736
1080.2476	3.1810002	1.2052052	3585.5107
1081.2485	3.1840005	1.2078362	3572.8896
1082.2495	3.1881726	1.2100167	3577.1172
1083.2505	3.1894252	1.212445	3573.2412
1084.2515	3.1908944	1.2146468	3570.23
1085.2524	3.1986725	1.2170167	3580.7439
1086.2534	3.1995916	1.2195086	3577.0581
1087.2544	3.2040496	1.2219976	3568.2339
1088.2554	3.20684	1.2242327	3573.2981
1089.2563	3.2083309	1.2272193	3573.9985
1090.2573	3.2139044	1.2301759	3575.4253
1091.2583	3.2130206	1.2327565	3571.9355
1092.2593	3.2179906	1.2354239	3568.4551
1093.2603	3.2215712	1.2378531	3571.1743
1094.2612	3.2240064	1.2403052	3572.4031
1095.2622	3.2267854	1.2431159	3577.6011
1096.2632	3.2287371	1.2462447	3576.1702
1097.2642	3.2351065	1.2487372	3571.95
1098.2651	3.2380264	1.2510689	3568.7053
1099.2661	3.2371137	1.2536358	3564.6621
1100.2671	3.2407887	1.2562884	3567.4775
1101.2681	3.2443354	1.258944	3568.0295
1102.269	3.2483504	1.2618099	3564.9717
1103.27	3.2511787	1.264338	3569.9514
1104.271	3.2544975	1.2678609	3573.79
1105.272	3.2565603	1.2710901	3562.7981
1106.2729	3.259464	1.274036	3562.4385
1107.2739	3.2618737	1.2769862	3565.4167
1108.2749	3.2654483	1.2800261	3561.646
1109.2759	3.2693896	1.2826475	3564.5376
1110.2769	3.2695394	1.2855006	3563.2285
1111.2778	3.2762995	1.2878985	3563.4407
1112.2788	3.2769711	1.290364	3561.4841
1113.2798	3.2803979	1.2935395	3564.1851
1114.2808	3.2832887	1.2964529	3567.249
1115.2817	3.289048	1.2990507	3562.9636
1116.2827	3.2899749	1.3021539	3558.686
1117.2837	3.2949138	1.3049978	3561.9702
1118.2847	3.2976937	1.3078433	3557.9277
1119.2856	3.3002121	1.3110224	3559.2957
1120.2866	3.3008769	1.3140969	3553.7922
1121.2876	3.3037827	1.3171334	3556.3425
1122.2886	3.3088069	1.3202047	3554.5818
1123.2896	3.3114316	1.3230418	3552.7625
1124.2905	3.3123159	1.3250971	3545.8135
1125.2915	3.3154817	1.3274091	3551.1348
1126.2925	3.3201795	1.3299916	3550.0244
1127.2935	3.3218198	1.333424	3556.6145
1128.2944	3.3278117	1.3368697	3554.3564
1129.2954	3.3283677	1.3403054	3548.5952
1130.2964	3.3335958	1.3425728	3542.5095
1131.2974	3.337502	1.3446661	3551.6096
1132.2983	3.3383219	1.3471354	3551.2383
1133.2993	3.3431194	1.3496916	3550.8308
1134.3003	3.3446681	1.3523231	3546.9128
1135.3013	3.3465285	1.3551916	3539.0642
1136.3022	3.3499274	1.3571899	3536.803
1137.3032	3.352838	1.3595959	3541.8572
1138.3042	3.3557038	1.3621116	3544.5149
1139.3052	3.3594892	1.3646868	3541.9419
1140.3062	3.3635051	1.3677245	3545.501
1141.3071	3.3644278	1.370685	3539.604
1142.3081	3.3675632	1.3736297	3535.8782
1143.3091	3.3694625	1.3767049	3537.8538
1144.3101	3.3746727	1.3795387	3530.9961
1145.311	3.3796003	1.3821275	3537.9663
1146.312	3.3794022	1.3850068	3531.2041
1147.313	3.3847799	1.3876636	3533.4292
1148.314	3.3838787	1.3907648	3528.1172
1149.3149	3.3886859	1.3929905	3524.7219
1150.3159	3.3919525	1.3951521	3522.5908
1151.3169	3.3922431	1.397912	3526.3286
1152.3179	3.396069	1.4007126	3523.1038
1153.3188	3.4020109	1.4041543	3525.1318
1154.3198	3.4026437	1.407281	3518.4553
1155.3208	3.4055448	1.409933	3515.0813
1156.3218	3.4098427	1.4124178	3510.6082
1157.3228	3.4120381	1.4150459	3519.645
1158.3237	3.4159808	1.4179095	3518.8103
1159.3247	3.419209	1.4205115	3514.3264
1160.3257	3.4204497	1.4237605	3520.644
1161.3267	3.4250736	1.4265001	3510.073
1162.3276	3.4281781	1.4289067	3506.9597
1163.3286	3.4286714	1.4320611	3515.1296
1164.3296	3.4345429	1.4349139	3507.501
1165.3306	3.4372079	1.4383023	3503.3872
1166.3315	3.4387405	1.4410117	3497.8799
1167.3325	3.4413152	1.4431497	3500.8635
1168.3335	3.4480784	1.4458247	3508.1768
1169.3345	3.4470541	1.4487451	3501.051
1170.3354	3.4527912	1.4513023	3494.4028
1171.3364	3.4561541	1.4538107	3496.9063
1172.3374	3.4592543	1.4564288	3496.5129
1173.3384	3.4602365	1.4594418	3495.1548
1174.3394	3.4626784	1.4624957	3485.0869
1175.3403	3.4675994	1.4652349	3490.3115
1176.3413	3.4721627	1.4680423	3493.2419
1177.3423	3.4711254	1.4709793	3484.2693
1178.3433	3.4767191	1.4741411	3488.1958
1179.3442	3.4793735	1.477337	3479.6958
1180.3452	3.4832871	1.4811423	3487.967
1181.3462	3.4865143	1.4851812	3475.988
1182.3472	3.4891584	1.4878753	3465.8169
1183.3481	3.4888482	1.4906549	3471.3638
1184.3491	3.4935434	1.4942787	3474.9368
1185.3501	3.4962711	1.4977775	3462.2529
1186.3511	3.4972773	1.5008847	3461.1929
1187.3521	3.5053251	1.5037378	3465.3567
1188.353	3.5041711	1.5062462	3456.1025
1189.354	3.5101857	1.5095621	3462.9375
1190.355	3.5133526	1.5136207	3463.9844
1191.356	3.515537	1.5171158	3460.0269
1192.3569	3.5179629	1.5205625	3448.4619
1193.3579	3.5209529	1.5236026	3450.6711
1194.3589	3.5256014	1.5266222	3442.9827
1195.3599	3.5228407	1.5296005	3439.9771
1196.3608	3.5312867	1.5321136	3442.9563
1197.3618	3.5320466	1.5355605	3443.9629
1198.3628	3.5366106	1.5389065	3432.113
1199.3638	3.5405643	1.541721	3434.001
1200.3647	3.5405533	1.5441729	3425.7832
1201.3657	3.5434921	1.546569	3431.1697
1202.3667	3.5501394	1.549381	3426.4543
1203.3677	3.5542741	1.5526464	3430.8401
1204.3687	3.5536451	1.5558758	3422.2097
1205.3696	3.5585883	1.5590914	3420.5637
1206.3706	3.5609326	1.5622624	3414.6431
1207.3716	3.5639944	1.5646387	3409.4153
1208.3726	3.5632327	1.5674287	3403.2644
1209.3735	3.5697424	1.5707277	3407.739
1210.3745	3.5717053	1.5733731	3400.3308
1211.3755	3.5765195	1.5765973	3402.8696
1212.3765	3.5762193	1.5802135	3396.3604
1213.3774	3.5815825	1.5840958	3391.1313
1214.3784	3.586503	1.5877198	3381.0334
1215.3794	3.5903833	1.591637	3379.2349
1216.3804	3.5878198	1.5952709	3373.699
1217.3813	3.5932243	1.5991135	3365.7888
1218.3823	3.5971131	1.6033242	3351.7556
1219.3833	3.5982604	1.6064341	3347.0784
1220.3843	3.6003978	1.609983	3348.6072
1221.3853	3.6066444	1.614481	3336.6096
1222.3862	3.6097715	1.6181842	3326.4512
1223.3872	3.6105921	1.6213549	3311.3442
1224.3882	3.61657	1.6257871	3311.0813
1225.3892	3.6207616	1.6305162	3300.6956
1226.3901	3.6215737	1.6374682	3256.6677
1227.3911	3.6277194	1.6622216	3023.24
1228.3921	3.6354923	1.6709098	2962.8147
1228.6924	3.6330318	1.6764281	2908.8655