File: datasets/am_bench_2022/raw_data/90-XY.16-2/specimen.dat
MTS793|MPT|ENU|1|2|.|/|:|1|0|0|A

Operator Information						Time:	12.687744	Sec	11/3/2021 7:34:48 AM
Operator	Nick Derimow
Project	AM Bench 2022 mini-tensile challenge
Specimen ID	90-XY.16-2
Material	PBF-L Inconel 625
Specimen Width	2.54	mm
Specimen Thickness	1.49	mm
Notes
Operator Information End

Data Acquisition						Time:	986.87476	Sec	11/3/2021 7:51:02 AM
Time	Axial Displacement	Axial Extensometer	Axial Force
Sec	mm	mm	N
12.801514	0.00077954383	0.0001849542	89.393456
13.702393	0.0036141591	0.00011657081	99.927406
14.603271	0.0044468362	0.0002711713	112.75961
15.50415	0.0061675105	0.00028551367	125.08578
16.405029	0.0088668978	0.00026104148	133.63983
17.305908	0.014312848	0.00024400685	140.00972
18.206787	0.016155995	0.00044927685	157.56483
19.107666	0.020066544	0.00045634969	163.59251
20.008545	0.019765969	0.00055329897	176.46028
20.909424	0.025546661	0.00054621795	192.27248
21.810303	0.027387401	0.00064881402	211.104
22.711182	0.028726364	0.00074562401	222.50169
23.612061	0.033117332	0.00075674546	235.69365
24.512939	0.036654722	0.00080322189	249.57423
25.413818	0.0372026	0.00091757462	267.47412
26.314697	0.040098272	0.00096561748	281.349
27.215576	0.042248145	0.0010490634	300.15408
28.116455	0.045880657	0.0010929141	316.49722
29.017334	0.051442575	0.0013128298	344.82599
29.918213	0.051281735	0.0013755499	359.37473
30.819092	0.055556938	0.001367506	371.91443
31.719971	0.055813204	0.0014729787	396.0368
32.62085	0.056862246	0.0014928818	419.09976
33.521729	0.062057257	0.001738457	443.22241
34.422607	0.065957665	0.0017784517	461.82419
35.323486	0.065393038	0.0018447042	472.1853
36.224365	0.069617786	0.0019781855	497.75333
37.125244	0.072052918	0.0020644672	518.39777
38.026123	0.076371558	0.0021776767	536.76904
38.927002	0.077177189	0.0023095189	560.63751
39.827881	0.079722494	0.0023915919	580.49274
40.72876	0.085591339	0.0024268127	604.50439
41.629639	0.087049551	0.002605238	628.36853
42.530518	0.089152344	0.0026834232	657.27319
43.431396	0.089412302	0.0028402417	672.62042
44.332275	0.093335301	0.0028936353	704.58386
45.233154	0.098818541	0.003117915	720.69
46.134033	0.09737549	0.0031705915	748.92114
47.034912	0.10232934	0.0032227845	774.60547
47.935791	0.1050107	0.0034168141	796.77679
48.83667	0.10983414	0.0034914589	818.54047
49.737549	0.1114327	0.0036796166	853.46283
50.638428	0.11390799	0.003878752	873.96356
51.539307	0.11675961	0.0038799117	898.69171
52.440186	0.12052013	0.0040459041	921.19177
53.341064	0.12187979	0.0040550423	946.85883
54.241943	0.12270632	0.0042411918	960.20789
55.142822	0.12752408	0.0043607531	995.04163
56.043701	0.13052465	0.0045701442	1024.2399
56.94458	0.13224512	0.0046472857	1044.6244
57.845459	0.13984381	0.0047739269	1065.3519
58.746338	0.13548276	0.0048610987	1091.1587
59.647217	0.13844521	0.0049785865	1124.5503
60.548096	0.14125161	0.00510835	1145.2501
61.448975	0.14528094	0.0052172402	1169.281
62.349854	0.14713536	0.0052436301	1181.2523
63.250732	0.15039492	0.0054523586	1213.705
64.151611	0.151848	0.0054314598	1239.0542
65.05249	0.15623063	0.0057076169	1272.6178
65.953369	0.15890153	0.0058494569	1293.2841
66.854248	0.16170563	0.0060021901	1323.6293
67.755127	0.16507889	0.0060865576	1346.4373
68.656006	0.16759107	0.0061485209	1366.6814
69.556885	0.17001118	0.0062558008	1393.2202
70.457764	0.1726926	0.0064653642	1419.2001
71.358643	0.17345043	0.0065799505	1444.4132
72.259521	0.17903838	0.0067039402	1478.2957
73.1604	0.17961474	0.0068391222	1505.276
74.061279	0.1841442	0.0069685047	1522.451
74.962158	0.18725398	0.0071476726	1552.8268
75.863037	0.19017179	0.0072281887	1577.663
76.763916	0.19176379	0.0072477721	1596.7429
77.664795	0.1949521	0.007420613	1622.1213
78.565674	0.19517933	0.007555298	1652.593
79.466553	0.19871446	0.0077947555	1679.3403
80.367432	0.20215535	0.0077981646	1698.7755
81.268311	0.20675899	0.007971976	1721.8076
82.169189	0.20805657	0.0080325278	1734.4312
83.070068	0.21285158	0.008140346	1770.9764
83.970947	0.21367478	0.008326048	1798.1415
84.871826	0.21502952	0.0083960304	1817.2678
85.772705	0.21835054	0.00859062	1840.3705
86.673584	0.22329047	0.0087132016	1862.7278
87.574463	0.22540981	0.0088465586	1887.1921
88.475342	0.22686489	0.0089592822	1903.8292
89.376221	0.22840546	0.0089714592	1929.3829
90.2771	0.23420158	0.0090597095	1946.3224
91.177979	0.23790759	0.0092585459	1968.7302
92.078857	0.23736709	0.0094709788	1994.3739
92.979736	0.23859255	0.0094363969	2014.5917
93.880615	0.24228996	0.0095532369	2030.0696
94.781494	0.24852207	0.0098129828	2048.9697
95.682373	0.24746053	0.0098703308	2070.1128
96.583252	0.25114933	0.009980835	2087.4487
97.484131	0.25485617	0.010021453	2103.3335
98.38501	0.25619924	0.010154606	2120.3796
99.285889	0.26000279	0.010217092	2147.5422
100.18677	0.25930041	0.010299209	2161.4861
101.08765	0.26513976	0.010515857	2180.7734
101.98853	0.26877856	0.010644511	2206.5874
102.8894	0.26990506	0.010701904	2219.7729
103.79028	0.27375203	0.010787474	2231.2949
104.69116	0.27611464	0.010941931	2252.0208
105.59204	0.27668157	0.011041257	2261.323
106.49292	0.28119993	0.011125843	2284.8257
107.3938	0.28267679	0.011250329	2296.2791
108.29468	0.28758284	0.011368854	2314.5442
109.19556	0.29008025	0.011445396	2322.1797
110.09644	0.29156178	0.011585196	2334.6096
110.99731	0.29558989	0.011678764	2349.7314
111.89819	0.29605007	0.011734833	2361.9131
112.79907	0.29972741	0.011904228	2377.697
113.69995	0.30249301	0.011929235	2389.1655
114.60083	0.30344453	0.0121036	2405.6602
115.50171	0.30808479	0.012256525	2419.7886
116.40259	0.31150255	0.012253095	2427.061
117.30347	0.3105402	0.01240111	2440.1023
118.20435	0.31647995	0.012510419	2451.7075
119.10522	0.31876934	0.012695172	2467.842
120.0061	0.31998006	0.012816403	2476.3083
120.90698	0.32435623	0.012925167	2494.0195
121.80786	0.32661474	0.013047219	2501.1863
122.70874	0.33003271	0.013045519	2514.8823
123.60962	0.33120772	0.013263594	2526.4822
124.5105	0.33694872	0.013344463	2532.7437
125.41138	0.3390699	0.013446969	2535.4456
126.31226	0.34147593	0.013640248	2547.9136
127.21313	0.34581056	0.013673202	2557.3579
128.11401	0.34624144	0.013758756	2569.9604
129.01489	0.34836242	0.01386963	2577.5269
129.91577	0.35341498	0.014049047	2590.8662
130.81665	0.3532775	0.014221501	2601.4475
131.71753	0.35395446	0.014334515	2605.3684
132.61841	0.35762405	0.014407516	2609.3586
133.51929	0.3646068	0.014612666	2622.4114
134.42017	0.36267287	0.014648244	2628.1865
135.32104	0.36827761	0.014824415	2638.5955
136.22192	0.37305665	0.014971377	2648.4331
137.1228	0.37461397	0.015123577	2653.6921
138.02368	0.37712103	0.015143419	2660.4282
138.92456	0.37981284	0.015478518	2671.9861
139.82544	0.38039061	0.015532461	2675.4631
140.72632	0.38368446	0.015731489	2692.385
141.6272	0.38770106	0.01591482	2695.8611
142.52808	0.38761625	0.016147032	2703.9578
143.42896	0.39305353	0.016382121	2718.1807
144.32983	0.3971827	0.016523356	2726.9587
145.23071	0.39870396	0.016744722	2731.1907
146.13159	0.40026832	0.016998537	2738.7048
147.03247	0.40168282	0.017198762	2739.1975
147.93335	0.40717262	0.017394541	2757.8652
148.83423	0.40641084	0.017706566	2762.0537
149.73511	0.41097724	0.017835654	2769.875
150.63599	0.41543782	0.018260568	2782.1892
151.53687	0.41703886	0.018591251	2785.8591
152.43774	0.41914588	0.018822119	2789.748
153.33862	0.42347175	0.019141106	2799.6587
154.2395	0.4238885	0.019387743	2801.3721
155.14038	0.42834908	0.019717433	2818.4883
156.04126	0.43209156	0.020123841	2822.1665
156.94214	0.43291318	0.020421423	2826.6309
157.84302	0.43836486	0.020716073	2823.9124
158.7439	0.43720892	0.021083111	2839.5913
159.64478	0.44206351	0.021366157	2839.6973
160.54565	0.4459236	0.021808211	2848.5696
161.44653	0.44586501	0.022173077	2853.8245
162.34741	0.44829646	0.02272738	2858.5833
163.24829	0.45385489	0.023052799	2864.8997
164.14917	0.45267123	0.023542397	2867.4788
165.05005	0.45732835	0.023850245	2875.0088
165.95093	0.45770884	0.024343614	2875.8604
166.85181	0.46530446	0.02479532	2879.1733
167.75269	0.4653565	0.025275398	2893.2666
168.65356	0.46844831	0.02571518	2887.3569
169.55444	0.47173142	0.026269935	2897.5491
170.45532	0.47718045	0.026933976	2910.5186
171.3562	0.47743061	0.027567279	2910.9546
172.25708	0.47864044	0.028231908	2918.4194
173.15796	0.48020253	0.028895814	2919.4004
174.05884	0.48132062	0.029487392	2923.7354
174.95972	0.48776168	0.030052204	2922.6565
175.8606	0.48835525	0.030758832	2929.6829
176.76147	0.49211493	0.031350654	2935.3408
177.66235	0.49688005	0.031987634	2943.4043
178.56323	0.5018484	0.032622717	2947.3247
179.46411	0.49921227	0.033391766	2945.6931
180.36499	0.50404567	0.033993538	2951.6477
181.26587	0.50371313	0.034697808	2960.1577
182.16675	0.51043344	0.035540894	2964.1499
183.06763	0.51555443	0.036478236	2966.1938
183.96851	0.51407737	0.037182853	2970.8613
184.86938	0.51779306	0.037946694	2973.968
185.77026	0.51898998	0.038619574	2979.79
186.67114	0.5231396	0.039456185	2985.6816
187.57202	0.52549726	0.040348317	2981.5698
188.4729	0.52590907	0.041247778	2984.0996
189.37378	0.52995235	0.042047083	2993.7197
190.27466	0.53337991	0.042830706	2993.4695
191.17554	0.53624511	0.043797679	2997.3057
192.07642	0.53775269	0.044615909	3004.6936
192.97729	0.54100835	0.045399815	3001.1199
193.87817	0.54436857	0.046143834	3008.5271
194.77905	0.54481375	0.047056232	3013.636
195.67993	0.54802275	0.04802173	3009.7349
196.58081	0.55056536	0.048885264	3012.0459
197.48169	0.55420828	0.049642421	3019.675
198.38257	0.55739641	0.050370201	3018.1394
199.28345	0.56063932	0.051268287	3028.5906
200.18433	0.56376529	0.052117709	3032.2449
201.08521	0.56503379	0.053290229	3039.3784
201.98608	0.56831855	0.054191642	3032.2102
202.88696	0.56899571	0.055145331	3040.4204
203.78784	0.57452363	0.056059983	3041.5176
204.68872	0.57450706	0.056867428	3036.1165
205.5896	0.57923484	0.057671145	3037.3569
206.49048	0.58107471	0.058487982	3044.7229
207.39136	0.58362865	0.059414595	3051.9846
208.29224	0.58576608	0.060411233	3053.5825
209.19312	0.58819687	0.061268885	3055.5085
210.09399	0.59279984	0.062281419	3060.374
210.99487	0.59446847	0.063291274	3066.0359
211.89575	0.59795123	0.064230144	3061.3962
212.79663	0.60191005	0.06509766	3073.6506
213.69751	0.60248113	0.06616421	3072.552
214.59839	0.60511678	0.067174874	3078.0154
215.49927	0.60870212	0.068195954	3074.782
216.40015	0.61342192	0.069084354	3076.9514
217.30103	0.61442304	0.070079871	3078.7876
218.2019	0.61565053	0.070945948	3076.6912
219.10278	0.61772746	0.071827419	3087.4453
220.00366	0.62560487	0.072631538	3086.4324
220.90454	0.62736565	0.073641427	3093.0833
221.80542	0.63133186	0.074567989	3093.5979
222.7063	0.63020927	0.075521737	3091.165
223.60718	0.63242763	0.076466747	3092.9255
224.50806	0.63548309	0.07745567	3099.7661
225.40894	0.63869846	0.078496113	3099.1628
226.30981	0.63924038	0.079460144	3107.0552
227.21069	0.6457808	0.080544017	3103.9453
228.11157	0.64525056	0.081447668	3100.7981
229.01245	0.6487236	0.082188889	3103.2322
229.91333	0.65372497	0.083219938	3114.5737
230.81421	0.65333217	0.084240198	3118.5574
231.71509	0.65815914	0.085316427	3117.7117
232.61597	0.66025966	0.086327262	3120.502
233.51685	0.66279376	0.087159827	3123.9077
234.41772	0.66600788	0.08825922	3128.1245
235.3186	0.67070836	0.089466318	3130.0295
236.21948	0.67218029	0.090407416	3124.072
237.12036	0.67418426	0.091683865	3136.821
238.02124	0.67704618	0.092763424	3131.1238
238.92212	0.67912602	0.093747154	3131.0193
239.823	0.68355632	0.094633497	3135.0962
240.72388	0.68692446	0.095317632	3129.6206
241.62476	0.68779135	0.096282542	3137.6467
242.52563	0.68993163	0.097173735	3144.7488
243.42651	0.69350225	0.09833277	3147.0005
244.32739	0.6952526	0.099327996	3148.2041
245.22827	0.69818068	0.10019582	3146.4758
246.12915	0.69990051	0.10115527	3147.8767
247.03003	0.70510328	0.10220286	3155.4744
247.93091	0.70542783	0.10301879	3148.5068
248.83179	0.70777148	0.104155	3155.8958
249.73267	0.7136178	0.10529929	3164.7585
250.63354	0.71271956	0.10635652	3154.916
251.53442	0.71767437	0.10721356	3162.3586
252.4353	0.72151381	0.10823273	3162.6689
253.33618	0.71916026	0.10906944	3163.6555
254.23706	0.72640491	0.11011496	3167.5664
255.13794	0.72716254	0.11108168	3170.0076
256.03882	0.72943193	0.11199018	3169.739
256.9397	0.73450089	0.1131836	3173.5452
257.84058	0.73538518	0.11431655	3174.593
258.74146	0.73757476	0.11528115	3169.7871
259.64233	0.74129516	0.11621188	3178.7344
260.54321	0.7443921	0.11710324	3183.3865
261.44409	0.74946696	0.11815573	3187.4043
262.34497	0.75002921	0.11905399	3185.8943
263.24585	0.75398797	0.11990893	3184.5649
264.14673	0.7537092	0.12073962	3185.0178
265.04761	0.756091	0.12179185	3188.0784
265.94849	0.75951654	0.12294614	3196.2683
266.84937	0.76143575	0.12408084	3198.1936
267.75024	0.76548636	0.12529644	3198.2156
268.65112	0.76846993	0.12627226	3199.8037
269.552	0.77160662	0.12730122	3198.8821
270.45288	0.773323	0.12846655	3202.0872
271.35376	0.77845192	0.12926674	3203.9863
272.25464	0.77846789	0.13024062	3205.1775
273.15552	0.78415644	0.13121629	3207.1531
274.0564	0.78490204	0.13211785	3216.8892
274.95728	0.78439474	0.13318868	3210.1147
275.85815	0.7908293	0.13415638	3210.7197
276.75903	0.79492331	0.1350935	3212.4077
277.65991	0.79850256	0.13608237	3222.6782
278.56079	0.79657984	0.13696034	3212.5066
279.46167	0.80379194	0.1380128	3221.7317
280.36255	0.80144227	0.13899584	3221.854
281.26343	0.80781835	0.14018871	3220.6707
282.16431	0.80489814	0.14117277	3220.0903
283.06519	0.81471616	0.14206298	3224.1782
283.96606	0.81663865	0.14316246	3230.9023
284.86694	0.81548351	0.14432037	3230.2222
285.76782	0.81770408	0.14533378	3234.0942
286.6687	0.82201678	0.14651096	3227.3735
287.56958	0.8254444	0.14753377	3229.2744
288.47046	0.82537305	0.14837952	3232.3533
289.37134	0.8292219	0.14934243	3228.4954
290.27222	0.83270723	0.15030739	3242.4963
291.1731	0.83777905	0.15142342	3244.8467
292.07397	0.83924955	0.15256327	3246.6072
292.97485	0.8413263	0.15370935	3248.0486
293.87573	0.84452403	0.15475383	3246.5337
294.77661	0.84122854	0.15575576	3242.3928
295.67749	0.85063583	0.15669756	3246.3081
296.57837	0.85563862	0.15776159	3248.5388
297.47925	0.85672104	0.15870477	3250.1858
298.38013	0.86081779	0.15971972	3257.5364
299.28101	0.86131197	0.16065259	3255.0615
300.18188	0.86398083	0.16175357	3261.323
301.08276	0.86733532	0.16269214	3259.2881
301.98364	0.8678717	0.1636699	3267.3984
302.88452	0.87016213	0.16473348	3260.7571
303.7854	0.87294757	0.16578765	3267.8667
304.68628	0.87593317	0.16687509	3263.7405
305.58716	0.87840378	0.16788946	3266.7515
306.48804	0.88418925	0.16902301	3274.387
307.38892	0.88517326	0.16996433	3268.5349
308.28979	0.88880306	0.17098109	3263.5349
309.19067	0.88974231	0.17177692	3270.7461
310.09155	0.89261013	0.17270464	3272.2454
310.99243	0.89588976	0.17354824	3274.9307
311.89331	0.89957571	0.17449729	3278.1626
312.79419	0.89969105	0.17530824	3276.2551
313.69507	0.90230072	0.17648582	3278.9236
314.59595	0.9064098	0.17740177	3278.8271
315.49683	0.90719002	0.17847857	3281.5891
316.39771	0.91399151	0.17953439	3278.7456
317.29858	0.91256338	0.18062183	3290.709
318.19946	0.91696525	0.18162501	3289.9583
319.10034	0.9204967	0.18269287	3289.5281
320.00122	0.92289162	0.18380764	3291.1245
320.9021	0.92574161	0.184799	3292.6375
321.80298	0.92634463	0.18583894	3289.6843
322.70386	0.93208826	0.18678638	3304.2686
323.60474	0.934816	0.18786851	3298.844
324.50562	0.93587726	0.1889635	3297.2305
325.40649	0.94029158	0.19004072	3300.3042
326.30737	0.94385666	0.19092888	3301.8665
327.20825	0.94472808	0.19182655	3301.4937
328.10913	0.94399822	0.19293724	3303.7834
329.01001	0.94623542	0.19403213	3297.1514
329.91089	0.95220953	0.19516078	3307.2961
330.81177	0.95563424	0.19612195	3312.574
331.71265	0.95761943	0.19717129	3310.3896
332.61353	0.96001053	0.1981177	3304.6921
333.5144	0.96604526	0.19912294	3314.7588
334.41528	0.96724141	0.20043404	3325.2847
335.31616	0.96951216	0.2014223	3319.5786
336.21704	0.97199446	0.20235743	3313.6021
337.11792	0.97303772	0.20322004	3312.5259
338.0188	0.97647578	0.20411491	3317.7947
338.91968	0.97885776	0.2051166	3320.7388
339.82056	0.98157567	0.2061466	3323.302
340.72144	0.98440123	0.20719051	3327.4543
341.62231	0.98409516	0.20812392	3318.1145
342.52319	0.99124068	0.20899989	3323.4531
343.42407	0.99303031	0.20975241	3323.7808
344.32495	0.99622554	0.21070829	3331.3335
345.22583	0.99747252	0.2118599	3330.1936
346.12671	0.99769974	0.21296428	3328.5269
347.02759	1.0018246	0.21389753	3333.738
347.92847	1.0067093	0.2151157	3342.2051
348.82935	1.0079026	0.21621186	3334.8162
349.73022	1.0130947	0.21728256	3340.8718
350.6311	1.0168267	0.21833007	3335.322
351.53198	1.0186977	0.21934484	3341.262
352.43286	1.0212507	0.22046617	3345.165
353.33374	1.0254579	0.22138207	3345.1875
354.23462	1.0248866	0.2224817	3341.6897
355.1355	1.0250386	0.22344498	3343.7173
356.03638	1.0311154	0.22450523	3348.1287
356.93726	1.0340984	0.22526066	3342.3296
357.83813	1.0378407	0.22634031	3351.5186
358.73901	1.0382919	0.22721942	3344.2375
359.63989	1.0402619	0.22829083	3355.7849
360.54077	1.0454054	0.2294236	3359.7258
361.44165	1.0485015	0.23051381	3352.6511
362.34253	1.0485185	0.23143026	3354.8071
363.24341	1.0511154	0.23241532	3357.1001
364.14429	1.0545031	0.23363961	3358.8911
365.04517	1.0560918	0.2347385	3359.6113
365.94604	1.0609348	0.23599944	3362.1304
366.84692	1.0607687	0.23702358	3358.6475
367.7478	1.0662637	0.2378792	3361.6855
368.64868	1.0675418	0.23878609	3365.644
369.54956	1.0701224	0.23975633	3358.0688
370.45044	1.0764712	0.24070461	3368.8289
371.35132	1.0788059	0.24169001	3368.8015
372.2522	1.0816358	0.24274077	3374.4343
373.15308	1.0811896	0.24368842	3367.8154
374.05396	1.0813769	0.24473599	3368.6538
374.95483	1.0861783	0.24571504	3370.3416
375.85571	1.09057	0.24690761	3378.2236
376.75659	1.0928559	0.24789727	3378.0569
377.65747	1.0931119	0.24916959	3378.3926
378.55835	1.0969353	0.25012878	3379.21
379.45923	1.1033489	0.25126842	3384.6553
380.36011	1.101402	0.25228801	3384.0483
381.26099	1.1070601	0.25325301	3378.1475
382.16187	1.1101328	0.2542704	3386.7837
383.06274	1.1112558	0.25536874	3390.4587
383.96362	1.1132538	0.25620353	3383.7869
384.8645	1.115772	0.25722679	3388.3169
385.76538	1.1194897	0.25801912	3389.1855
386.66626	1.1228812	0.25908196	3393.7451
387.56714	1.1252851	0.25992405	3385.9607
388.46802	1.1256351	0.26101875	3398.9978
389.3689	1.1298255	0.26194039	3392.1262
390.26978	1.1342611	0.26302776	3395.3264
391.17065	1.1336647	0.26425341	3398.7722
392.07153	1.1412117	0.26537871	3402.8989
392.97241	1.1421241	0.26649618	3397.5151
393.87329	1.1473252	0.26759744	3408.5566
394.77417	1.144788	0.26856437	3400.2185
395.67505	1.150216	0.26967424	3406.9954
396.57593	1.1539325	0.27047241	3400.4094
397.47681	1.1537081	0.27145612	3404.9495
398.37769	1.1589195	0.27234766	3412.7959
399.27856	1.1587809	0.27338448	3412.4907
400.17944	1.1643078	0.27457091	3413.9319
401.08032	1.1671953	0.2756066	3413.9846
401.9812	1.1702425	0.27684346	3417.7493
402.88208	1.1717132	0.27772149	3405.2617
403.78296	1.1751556	0.27866986	3412.2373
404.68384	1.1735792	0.27954367	3411.1665
405.58472	1.177382	0.2806471	3415.2131
406.4856	1.1806087	0.28186327	3419.9309
407.38647	1.1848968	0.28312376	3421.7563
408.28735	1.1893948	0.28417328	3422.3638
409.18823	1.1900003	0.28516063	3428.6125
410.08911	1.1921099	0.28635749	3417.7029
410.98999	1.1922444	0.28731686	3422.7695
411.89087	1.1990018	0.28836069	3421.189
412.79175	1.1987643	0.2891618	3418.6565
413.69263	1.2052939	0.29014146	3428.8
414.59351	1.2057528	0.2911306	3436.127
415.49438	1.2073655	0.2922124	3426.3657
416.39526	1.2118858	0.29351258	3435.6265
417.29614	1.2149665	0.29443976	3427.1262
418.19702	1.2176154	0.29549846	3431.3586
419.0979	1.2173438	0.29655853	3437.6631
419.99878	1.2228638	0.29754105	3433.9822
420.89966	1.2239398	0.29838634	3432.2913
421.80054	1.2287709	0.29946211	3443.5103
422.70142	1.2299381	0.30053085	3438.9746
423.60229	1.2347122	0.30151576	3442.4348
424.50317	1.2359557	0.30251685	3441.8572
425.40405	1.2392195	0.30347866	3443.1816
426.30493	1.2394518	0.30454636	3442.7429
427.20581	1.2455505	0.30548772	3437.7085
428.10669	1.2440951	0.30644563	3442.5208
429.00757	1.2493318	0.3074998	3450.522
429.90845	1.2497101	0.30856583	3443.251
430.80933	1.2572576	0.30963656	3452.2949
431.71021	1.2600969	0.3107163	3448.5618
432.61108	1.2629573	0.31160265	3455.145
433.51196	1.262338	0.31260088	3453.1052
434.41284	1.2647145	0.31359911	3452.7253
435.31372	1.267395	0.31483391	3455.708
436.2146	1.2724962	0.31599542	3456.5564
437.11548	1.2736633	0.31708556	3461.7407
438.01636	1.2766501	0.31806377	3461.418
438.91724	1.2801231	0.31916472	3461.1465
439.81812	1.2831331	0.32029071	3461.8286
440.71899	1.2844203	0.32140192	3461.8689
441.61987	1.2840827	0.3225584	3463.8293
442.52075	1.2880121	0.32360896	3461.5884
443.42163	1.2913275	0.32474694	3460.9146
444.32251	1.2940152	0.32590339	3468.4612
445.22339	1.2967118	0.32683155	3463.439
446.12427	1.2982504	0.32803854	3465.1133
447.02515	1.306447	0.32931447	3475.4949
447.92603	1.3054314	0.33043277	3475.2053
448.8269	1.3085525	0.33141351	3474.3032
449.72778	1.3135755	0.33238554	3473.4028
450.62866	1.313058	0.33340967	3472.3911
451.52954	1.3167775	0.33428094	3472.6531
452.43042	1.3213106	0.33526567	3476.6243
453.3313	1.3228474	0.33619073	3472.5427
454.23218	1.3223044	0.33718693	3467.1743
455.13306	1.3283412	0.33819029	3478.4465
456.03394	1.3293663	0.33910388	3476.843
456.93481	1.3350593	0.34003749	3480.731
457.83569	1.3391064	0.34113103	3482.5024
458.73657	1.3395419	0.34206003	3481.491
459.63745	1.3444418	0.34317449	3487.2161
460.53833	1.3437117	0.34417847	3480.085
461.43921	1.349577	0.34513009	3485.8738
462.34009	1.3476171	0.34617716	3485.5254
463.24097	1.3518088	0.34727392	3486.947
464.14185	1.3552085	0.34824678	3490.8284
465.04272	1.3576707	0.34954587	3494.7671
465.9436	1.3624194	0.35079879	3498.0156
466.84448	1.3619188	0.35193512	3492.0005
467.74536	1.3657707	0.35315996	3489.7571
468.64624	1.3693783	0.3540498	3490.4888
469.54712	1.3690048	0.35511211	3496.0249
470.448	1.3727561	0.35610849	3495.0742
471.34888	1.377751	0.35709819	3498.0769
472.24976	1.3795248	0.35838678	3499.9238
473.15063	1.3781308	0.35958174	3497.2395
474.05151	1.3839283	0.3608191	3497.417
474.95239	1.384058	0.36180869	3500.0566
475.85327	1.390276	0.36272052	3489.4429
476.75415	1.3910687	0.36348763	3491.917
477.65503	1.393266	0.36447775	3505.7891
478.55591	1.3957391	0.36546648	3501.3049
479.45679	1.4039658	0.36651048	3506.9026
480.35767	1.4023957	0.36763191	3509.0732
481.25854	1.4081498	0.36877993	3506.1223
482.15942	1.4107628	0.36978289	3499.7393
483.0603	1.4131616	0.37079003	3512.2822
483.96118	1.4145881	0.37204081	3511.9368
484.86206	1.4192057	0.37350324	3519.9033
485.76294	1.4172612	0.37464926	3505.8398
486.66382	1.4213924	0.37581542	3510.0876
487.5647	1.4248745	0.37704605	3519.1711
488.46558	1.4292198	0.37815076	3512.75
489.36646	1.430383	0.37901974	3509.3247
490.26733	1.4301082	0.37997752	3514.1074
491.16821	1.436429	0.38084447	3512.7332
492.06909	1.4376856	0.38159689	3509.7361
492.96997	1.4412664	0.38273329	3526.4673
493.87085	1.4441009	0.38364604	3520.3965
494.77173	1.4460402	0.38478258	3521.7576
495.67261	1.4491754	0.38594851	3523.8472
496.57349	1.4516211	0.38709316	3521.7
497.47437	1.4566534	0.38806474	3521.0105
498.37524	1.4569216	0.38913849	3521.3293
499.27612	1.4616677	0.39039013	3531.4485
500.177	1.4625238	0.39152691	3529.3574
501.07788	1.4642186	0.39253259	3527.2368
501.97876	1.468677	0.39348495	3521.5566
502.87964	1.4721485	0.39443499	3527.6494
503.78052	1.4725189	0.3954004	3530.7515
504.6814	1.4778979	0.39655915	3532.0132
505.58228	1.4817991	0.39757612	3530.5142
506.48315	1.4839565	0.39864516	3530.22
507.38403	1.4860823	0.3998273	3533.781
508.28491	1.4869349	0.4010253	3537.7009
509.18579	1.4909353	0.4022156	3531.7954
510.08667	1.4930224	0.4033711	3543.457
510.98755	1.4940877	0.40454265	3539.5151
511.88843	1.4994744	0.4057532	3532.3018
512.78931	1.5000641	0.40689954	3540.6057
513.69019	1.5041125	0.40797052	3540.8904
514.59106	1.5071818	0.40924719	3545.0757
515.49194	1.5087254	0.410202	3540.5259
516.39282	1.5139312	0.41132638	3548.7549
517.2937	1.5130401	0.41251844	3541.5627
518.19458	1.5190817	0.41360974	3546.9182
519.09546	1.5187539	0.41485056	3551.0088
519.99634	1.523526	0.41580278	3546.5354
520.89722	1.5247483	0.41693342	3548.1563
521.7981	1.5293363	0.41792324	3549.1187
522.69897	1.5318307	0.41901159	3550.3188
523.59985	1.5350472	0.42015779	3548.5774
524.50073	1.5371774	0.42128897	3551.6985
525.40161	1.5380366	0.42238876	3549.865
526.30249	1.5404472	0.42347008	3545.0688
527.20337	1.5415612	0.42440432	3552.1938
528.10425	1.5470198	0.42555952	3561.7053
529.00513	1.5497209	0.42656475	3547.4875
529.90601	1.5529135	0.42742613	3545.1719
530.80688	1.5538476	0.42846054	3560.3083
531.70776	1.5565534	0.42973158	3557.9094
532.60864	1.5607744	0.43089557	3558.4055
533.50952	1.5626519	0.43196246	3559.0081
534.4104	1.5645065	0.43293178	3554.9504
535.31128	1.5691406	0.43412486	3559.6538
536.21216	1.5728912	0.4352777	3561.1406
537.11304	1.5729398	0.43625817	3561.2373
538.01392	1.5784984	0.43758976	3572.2932
538.91479	1.577538	0.43853956	3550.7954
539.81567	1.5769935	0.43971637	3568.1536
540.71655	1.5833917	0.44095513	3561.3125
541.61743	1.5871497	0.44200748	3563.5889
542.51831	1.5897036	0.44300041	3565.0874
543.41919	1.5910197	0.44435716	3571.6704
544.32007	1.5961833	0.44588056	3574.127
545.22095	1.5981086	0.44713271	3577.0498
546.12183	1.6010443	0.44836691	3569.7744
547.02271	1.6029135	0.44948465	3573.1062
547.92358	1.6053754	0.45061907	3573.8438
548.82446	1.6087497	0.45158011	3572.1194
549.72534	1.6100606	0.45279765	3574.2705
550.62622	1.613525	0.45382318	3574.8232
551.5271	1.6179421	0.45491967	3576.9526
552.42798	1.6187557	0.45611435	3578.1804
553.32886	1.6225132	0.4571763	3576.8315
554.22974	1.6255674	0.45827135	3579.1121
555.13062	1.6274028	0.45929992	3575.2947
556.03149	1.6321055	0.46027091	3579.9026
556.93237	1.6331868	0.46152994	3583.6409
557.83325	1.6363226	0.46295145	3586.9868
558.73413	1.6384494	0.4642148	3582.7153
559.63501	1.6431401	0.46550438	3582.0601
560.53589	1.6415668	0.46660006	3577.2495
561.43677	1.6458527	0.46755314	3577.6533
562.33765	1.6488725	0.46866751	3583.5264
563.23853	1.6544081	0.47006518	3588.0596
564.1394	1.6545719	0.4710823	3581.9846
565.04028	1.6583374	0.47214928	3582.1604
565.94116	1.6615601	0.47314203	3586.293
566.84204	1.6617038	0.47421166	3582.2803
567.74292	1.6647493	0.47542375	3588.271
568.6438	1.6697906	0.47649518	3588.5596
569.54468	1.6721174	0.47770166	3593.6816
570.44556	1.6743829	0.47890785	3589.9861
571.34644	1.6744018	0.4798969	3583.7034
572.24731	1.6778744	0.4811483	3596.9993
573.14819	1.6806511	0.48216638	3590.7034
574.04907	1.6833119	0.48342824	3593.8979
574.94995	1.6877952	0.48479339	3599.3477
575.85083	1.6892248	0.48597068	3597.6235
576.75171	1.6943094	0.48715246	3602.5439
577.65259	1.6972911	0.48818222	3592.8533
578.55347	1.6977218	0.48928583	3591.7305
579.45435	1.6996373	0.49043939	3606.8735
580.35522	1.7035036	0.49189606	3600.8484
581.2561	1.7066303	0.49321592	3604.7937
582.15698	1.7089503	0.49430931	3602.5493
583.05786	1.7111341	0.49550223	3601.7659
583.95874	1.7124825	0.49670988	3604.4287
584.85962	1.7170148	0.49794397	3606.9758
585.7605	1.7192376	0.49919292	3604.1663
586.66138	1.7233329	0.50038326	3606.7913
587.56226	1.7271732	0.50153989	3610.8103
588.46313	1.727226	0.50284028	3612.8799
589.36401	1.7308893	0.50390977	3603.1709
590.26489	1.7345561	0.50511718	3614.207
591.16577	1.7381699	0.50620908	3608.4836
592.06665	1.7381109	0.50720495	3602.8
592.96753	1.7412559	0.50835705	3607.6943
593.86841	1.7445446	0.50940472	3611.7388
594.76929	1.7477697	0.51070046	3617.9043
595.67017	1.7498231	0.51207888	3610.4712
596.57104	1.7541349	0.51322562	3609.2471
597.47192	1.7552316	0.51409823	3606.1545
598.3728	1.7570412	0.51520777	3615.6057
599.27368	1.762987	0.51638508	3616.8027
600.17456	1.7636278	0.51735842	3612.2524
601.07544	1.7685143	0.51849806	3617.0508
601.97632	1.7683403	0.51981139	3619.8918
602.8772	1.7718869	0.52106917	3612.9338
603.77808	1.7755951	0.52214503	3616.9531
604.67896	1.7779802	0.52336007	3622.3594
605.57983	1.7816417	0.52459544	3621.2363
606.48071	1.7813544	0.52567232	3618.1021
607.38159	1.7847128	0.52665234	3614.8501
608.28247	1.7876817	0.52769786	3615.9194
609.18335	1.7890151	0.52889442	3621.7915
610.08423	1.7947176	0.53039795	3629.938
610.98511	1.7965796	0.53171426	3626.0278
611.88599	1.7991384	0.53295046	3622.6404
612.78687	1.7988847	0.53412175	3625.2764
613.68774	1.8040928	0.53528565	3625.5896
614.58862	1.8070375	0.53657812	3625.6343
615.4895	1.8101624	0.5380801	3634.5962
616.39038	1.8123808	0.53959268	3635.5549
617.29126	1.8123691	0.54097778	3620.2212
618.19214	1.8184502	0.54227245	3622.6016
619.09302	1.8189093	0.54338515	3620.9097
619.9939	1.8238147	0.54452759	3617.7539
620.89478	1.8249753	0.54544932	3617.7571
621.79565	1.8267801	0.54649502	3630.3496
622.69653	1.8288728	0.547961	3626.8459
623.59741	1.8318107	0.54909784	3627.1804
624.49829	1.8366884	0.55036801	3637.6023
625.39917	1.8404878	0.55158448	3629.9958
626.30005	1.8403571	0.55275369	3631.3516
627.20093	1.8442739	0.55409896	3630.2451
628.10181	1.8457301	0.55536449	3631.6467
629.00269	1.8486985	0.55659246	3628.4607
629.90356	1.852797	0.55774826	3631.2002
630.80444	1.8570698	0.55866599	3628.7964
631.70532	1.8599049	0.5600782	3640.2263
632.6062	1.8594456	0.56128877	3635.6558
633.50708	1.8646636	0.56243193	3626.9155
634.40796	1.8650687	0.56372577	3640.7217
635.30884	1.8693624	0.56495947	3640.3298
636.20972	1.8713567	0.56617588	3635.9397
637.1106	1.873706	0.56733191	3638.499
638.01147	1.8768933	0.56879252	3645.0757
638.91235	1.8806101	0.57024395	3646.4885
639.81323	1.8801231	0.57161456	3637.0176
640.71411	1.8830284	0.5728541	3630.1941
641.61499	1.8914416	0.57396013	3635.593
642.51587	1.8911266	0.57501698	3642.6248
643.41675	1.8952972	0.5762977	3641.5789
644.31763	1.8962507	0.57760793	3644.45
645.21851	1.8984801	0.57885689	3642.5503
646.11938	1.899931	0.58037019	3642.6577
647.02026	1.9025697	0.58172345	3646.4402
647.92114	1.9062494	0.58327788	3646.6802
648.82202	1.9109875	0.58458978	3651.3347
649.7229	1.9134393	0.58589423	3652.4487
650.62378	1.9134656	0.5872106	3646.9065
651.52466	1.9178302	0.58877754	3648.2065
652.42554	1.917946	0.59010249	3646.0962
653.32642	1.9233561	0.59112841	3647.052
654.22729	1.9244263	0.59227335	3643.2961
655.12817	1.9262789	0.59346294	3651.7532
656.02905	1.9327557	0.59488863	3655.4106
656.92993	1.9324498	0.59588414	3640.6008
657.83081	1.9359956	0.59701788	3651.0332
658.73169	1.9362496	0.5982511	3649.7969
659.63257	1.938816	0.59970582	3648.0256
660.53345	1.9466307	0.60123366	3657.1719
661.43433	1.945745	0.60252076	3653.2859
662.33521	1.9460753	0.6037811	3651.3315
663.23608	1.9543252	0.60526472	3658.1724
664.13696	1.9550296	0.60631579	3646.2073
665.03784	1.9578327	0.60768205	3653.8816
665.93872	1.9602149	0.60921794	3659.5063
666.8396	1.9595777	0.61035699	3650.0051
667.74048	1.9643726	0.61180949	3660.3877
668.64136	1.9690913	0.61338443	3660.2881
669.54224	1.9730753	0.61477596	3655.9053
670.44312	1.9722719	0.61585152	3651.967
671.34399	1.97869	0.61696815	3649.8469
672.24487	1.9810024	0.61815196	3654.6658
673.14575	1.9843729	0.61942548	3658.1765
674.04663	1.9823568	0.62102556	3658.1638
674.94751	1.9865468	0.62213254	3657.0791
675.84839	1.9879558	0.62351853	3658.0869
676.74927	1.9913192	0.62474155	3657.2644
677.65015	1.9946821	0.62604469	3661.5327
678.55103	1.9974313	0.62754983	3668.0039
679.4519	2.0015774	0.62880147	3659.1882
680.35278	2.0047336	0.63018692	3661.6968
681.25366	2.0084336	0.63167715	3663.7463
682.15454	2.0072367	0.6329118	3658.5417
683.05542	2.0111706	0.63427323	3666.7375
683.9563	2.0121655	0.63549286	3655.4792
684.85718	2.0153916	0.63687229	3664.1624
685.75806	2.0194407	0.63822466	3665.5662
686.65894	2.0231428	0.63973898	3673.0605
687.55981	2.0272162	0.64113927	3662.8521
688.46069	2.0278966	0.64264345	3665.6829
689.36157	2.0314279	0.64421636	3662.5432
690.26245	2.0343378	0.64548212	3663.1658
691.16333	2.0340731	0.64669365	3663.6621
692.06421	2.0402174	0.6479581	3665.2134
692.96509	2.0393512	0.64939117	3667.105
693.86597	2.0460362	0.65068245	3665.6418
694.76685	2.0443816	0.65247601	3668.9294
695.66772	2.0509796	0.65395886	3675.6636
696.5686	2.0547163	0.65530056	3659.9126
697.46948	2.0545738	0.65665716	3661.376
698.37036	2.0541327	0.65796387	3666.6111
699.27124	2.0621271	0.65937829	3666.564
700.17212	2.0636361	0.66055077	3670.9219
701.073	2.0647519	0.66189909	3671.0063
701.97388	2.0703204	0.66355807	3675.3914
702.87476	2.0704222	0.66494441	3665.1243
703.77563	2.0788732	0.6660772	3671.0764
704.67651	2.0781493	0.66723949	3670.0176
705.57739	2.0766544	0.66844976	3670.5581
706.47827	2.0830994	0.6698581	3665.9692
707.37915	2.0838912	0.67131209	3674.9106
708.28003	2.0859263	0.67296332	3673.6523
709.18091	2.0888824	0.6745941	3672.1755
710.08179	2.0925441	0.67580473	3666.7344
710.98267	2.0930481	0.67702192	3664.1167
711.88354	2.0995884	0.67825687	3671.6785
712.78442	2.0989733	0.67945474	3671.0576
713.6853	2.1048849	0.68078637	3679.1809
714.58618	2.1045876	0.6824612	3677.1638
715.48706	2.1096826	0.68427187	3678.6785
716.38794	2.1117518	0.68588006	3675.0491
717.28882	2.1148357	0.68733227	3671.0908
718.1897	2.1165266	0.68863952	3675.1895
719.09058	2.1182671	0.68992186	3674.8123
719.99146	2.1204712	0.69129092	3673.3347
720.89233	2.1252391	0.69279885	3681.3108
721.79321	2.1283767	0.69413775	3674.4666
722.69409	2.1294894	0.69569451	3680.3364
723.59497	2.1322503	0.69721437	3679.9397
724.49585	2.1326191	0.69892526	3680.9771
725.39673	2.141001	0.70036614	3675.3794
726.29761	2.1410358	0.70156503	3672.7434
727.19849	2.1429024	0.70284438	3676.9104
728.09937	2.1477759	0.70442313	3678.7971
729.00024	2.1485019	0.70599288	3678.4561
729.90112	2.1545827	0.70745528	3676.2842
730.802	2.1532786	0.70905149	3681.5852
731.70288	2.157588	0.71072203	3682.9294
732.60376	2.15885	0.71222496	3684.3235
733.50464	2.1639688	0.7138418	3685.7095
734.40552	2.164767	0.7154538	3677.2439
735.3064	2.165971	0.71683741	3676.1765
736.20728	2.1688533	0.71839786	3677.7312
737.10815	2.1740441	0.71992898	3679.8965
738.00903	2.1767859	0.72165674	3682.8125
738.90991	2.1810255	0.72312421	3684.0784
739.81079	2.1850758	0.72457802	3685.9368
740.71167	2.1856198	0.72576094	3674.0308
741.61255	2.1867642	0.72715771	3684.1318
742.51343	2.1887615	0.72872949	3688.3401
743.41431	2.1909144	0.73018187	3674.8357
744.31519	2.1942186	0.73163581	3684.3308
745.21606	2.1984651	0.73328471	3689.0913
746.11694	2.2007577	0.73485994	3682.0261
747.01782	2.2025917	0.7361784	3678.4812
747.9187	2.2054677	0.73768771	3686.4475
748.81958	2.2103198	0.7392875	3685.7363
749.72046	2.2108903	0.74116957	3689.7041
750.62134	2.2143879	0.74282587	3684.4102
751.52222	2.218533	0.74431115	3687.4983
752.4231	2.2201896	0.74587202	3689.3396
753.32397	2.222779	0.74727076	3684.241
754.22485	2.2255704	0.74870884	3686.7495
755.12573	2.226975	0.75034553	3679.5652
756.02661	2.2297261	0.75183702	3685.2649
756.92749	2.2335126	0.75332195	3680.5586
757.82837	2.2379887	0.75482309	3687.6421
758.72925	2.2385304	0.75627512	3688.644
759.63013	2.2440948	0.75794274	3685.0779
760.53101	2.2454784	0.75934434	3683.8938
761.43188	2.2459259	0.76101875	3692.1331
762.33276	2.2515047	0.76265693	3685.1719
763.23364	2.2518561	0.76422906	3690.5359
764.13452	2.2540121	0.76596463	3686.0759
765.0354	2.258364	0.76753151	3685.6006
765.93628	2.2619045	0.76908308	3688.0601
766.83716	2.2647662	0.77047193	3685.5999
767.73804	2.2662783	0.77204806	3684.3062
768.63892	2.2671943	0.77374262	3690.9893
769.53979	2.2704215	0.77549028	3692.4426
770.44067	2.2754688	0.77726442	3684.8096
771.34155	2.2749989	0.77894068	3688.8491
772.24243	2.2822905	0.78068256	3690.5957
773.14331	2.2830558	0.78213477	3681.124
774.04419	2.2833626	0.78355497	3682.1235
774.94507	2.2889879	0.78502941	3686.437
775.84595	2.2880194	0.78640008	3686.4219
776.74683	2.2916081	0.7879746	3687.4707
777.64771	2.2967508	0.78980052	3688.259
778.54858	2.2978151	0.79155189	3687.248
779.44946	2.3004971	0.79320997	3691.042
780.35034	2.3044436	0.79503775	3695.1536
781.25122	2.3061326	0.79681462	3683.4868
782.1521	2.3097889	0.79867917	3694.0864
783.05298	2.3111279	0.80054808	3689.2402
783.95386	2.3158944	0.8023656	3693.4248
784.85474	2.3182175	0.80413973	3688.3933
785.75562	2.3181636	0.80613029	3685.0874
786.65649	2.3202684	0.80780315	3680.5842
787.55737	2.3254254	0.80948216	3686.8396
788.45825	2.3288953	0.81108892	3688.1448
789.35913	2.3284678	0.81254154	3684.5083
790.26001	2.3313997	0.81391793	3683.4651
791.16089	2.3346801	0.8150835	3682.0369
792.06177	2.3401339	0.81686139	3696.3154
792.96265	2.3433795	0.8188656	3694.4224
793.86353	2.3414953	0.82064325	3686.4314
794.7644	2.3454611	0.8226521	3687.1323
795.66528	2.3516285	0.82460278	3689.9468
796.56616	2.354399	0.82645154	3688.4392
797.46704	2.3559945	0.82816541	3686.5164
798.36792	2.3573809	0.82989615	3691.9497
799.2688	2.3580308	0.83185577	3686.2639
800.16968	2.3611612	0.83381569	3684.4417
801.07056	2.3656547	0.83564097	3684.5356
801.97144	2.3682632	0.83745176	3685.2126
802.87231	2.3687034	0.83929765	3690.1809
803.77319	2.3718927	0.8411842	3686.4573
804.67407	2.3775887	0.84310591	3687.8474
805.57495	2.3800933	0.84471893	3682.9819
806.47583	2.3831789	0.84646404	3688.2405
807.37671	2.3851643	0.84832323	3686.1272
808.27759	2.3887799	0.85025799	3688.3081
809.17847	2.3917332	0.85159796	3680.9167
810.07935	2.3926561	0.85321236	3685.7883
810.98022	2.3986423	0.85504454	3689.8508
811.8811	2.399111	0.8566466	3687.8547
812.78198	2.4009273	0.85819691	3684.5073
813.68286	2.4026439	0.86020541	3695.498
814.58374	2.4070868	0.86231345	3687.8108
815.48462	2.409019	0.86395025	3687.8511
816.3855	2.4088798	0.86569047	3682.6265
817.28638	2.4135602	0.86794025	3692.7935
818.18726	2.4137979	0.86979496	3682.3306
819.08813	2.4214175	0.87152928	3684.7212
819.98901	2.4245636	0.87329394	3680.6653
820.88989	2.4227331	0.87491232	3676.4309
821.79077	2.4303257	0.87682229	3689.3274
822.69165	2.4289308	0.87859964	3679.6323
823.59253	2.4340065	0.88054132	3684.8022
824.49341	2.4358711	0.88250959	3685.3767
825.39429	2.4421268	0.8844732	3683.9443
826.29517	2.4421983	0.88626313	3681.5198
827.19604	2.4456155	0.88826621	3687.5454
828.09692	2.4467077	0.8906911	3685.7908
828.9978	2.4497666	0.89281875	3685.0674
829.89868	2.4528041	0.89469314	3684.4609
830.79956	2.4555595	0.89671862	3689.4404
831.70044	2.4561057	0.89846522	3680.2903
832.60132	2.4608316	0.90038759	3678.9495
833.5022	2.4610758	0.90218586	3682.7139
834.40308	2.4665127	0.90434957	3684.418
835.30396	2.4674773	0.90607119	3680.96
836.20483	2.4706459	0.907996	3687.7168
837.10571	2.4757128	0.91032314	3694.1843
838.00659	2.4762342	0.91270161	3685.2917
838.90747	2.4781208	0.91493613	3682.6389
839.80835	2.4821491	0.91702867	3683.0728
840.70923	2.4831882	0.91874629	3673.3894
841.61011	2.4876571	0.920452	3677.6316
842.51099	2.4905927	0.92236161	3682.99
843.41187	2.4929745	0.92444617	3683.7112
844.31274	2.4976909	0.92631263	3677.7854
845.21362	2.4955664	0.92827284	3681.0376
846.1145	2.4998429	0.93037879	3675.2932
847.01538	2.5050526	0.9322688	3679.2583
847.91626	2.504811	0.93407094	3677.9558
848.81714	2.5086098	0.93610901	3679.0056
849.71802	2.5117781	0.93869239	3681.811
850.6189	2.5123727	0.94087714	3678.9568
851.51978	2.5199046	0.94308925	3678.9097
852.42065	2.520951	0.94521117	3676.1387
853.32153	2.5233796	0.94740218	3673.1467
854.22241	2.5283322	0.94947404	3680.0269
855.12329	2.527272	0.95144635	3673.8491
856.02417	2.5306516	0.9534384	3672.7493
856.92505	2.5325208	0.95554274	3673.3943
857.82593	2.5375819	0.95773143	3674.3357
858.72681	2.540132	0.9602502	3681.1492
859.62769	2.5448189	0.96235484	3667.4399
860.52856	2.5427172	0.96400481	3662.3145
861.42944	2.5460825	0.96584594	3665.8391
862.33032	2.5472829	0.96794575	3672.9719
863.2312	2.5507162	0.97016847	3671.5452
864.13208	2.5537632	0.97269249	3669.1458
865.03296	2.5564935	0.9752475	3662.2498
865.93384	2.5571325	0.97770476	3669.8796
866.83472	2.5634987	0.98037177	3667.8457
867.7356	2.5681124	0.98237604	3665.5034
868.63647	2.5666378	0.98413342	3656.8782
869.53735	2.571074	0.98627359	3667.3413
870.43823	2.5767474	0.98849189	3667.1721
871.33911	2.5734978	0.99078703	3662.6812
872.23999	2.5786698	0.99275959	3661.115
873.14087	2.5837498	0.99473983	3665.323
874.04175	2.584471	0.99688756	3666.5227
874.94263	2.5858986	0.99920988	3658.5393
875.84351	2.5912604	1.0012031	3668.4836
876.74438	2.5951004	1.0043135	3666.4023
877.64526	2.5957193	1.0070592	3661.3506
878.54614	2.5980949	1.0094174	3653.782
879.44702	2.6004596	1.0115004	3653.616
880.3479	2.6055236	1.0133876	3655.073
881.24878	2.6043975	1.0155584	3659.7449
882.14966	2.6100967	1.0179387	3661.4216
883.05054	2.6101115	1.0204924	3656.0603
883.95142	2.6152294	1.0229588	3656.134
884.85229	2.621459	1.0250897	3654.0808
885.75317	2.6195128	1.0269771	3649.4902
886.65405	2.6223848	1.0290313	3653.8489
887.55493	2.6231997	1.0310487	3649.3872
888.45581	2.6276395	1.0333755	3649.4983
889.35669	2.6296961	1.0354564	3646.2324
890.25757	2.6334586	1.0378336	3645.5715
891.15845	2.6362607	1.0401927	3643.1633
892.05933	2.6379893	1.0429593	3650.323
892.96021	2.6407664	1.0456597	3645.3337
893.86108	2.6460962	1.0482823	3642.7786
894.76196	2.6464779	1.0506383	3641.2446
895.66284	2.6513844	1.053367	3649.3625
896.56372	2.6499519	1.055887	3632.6646
897.4646	2.6548994	1.0584056	3637.4858
898.36548	2.6599905	1.0610414	3635.0461
899.26636	2.6625326	1.0634481	3639.1938
900.16724	2.661695	1.0655758	3631.4592
901.06812	2.6674101	1.068584	3638.4294
901.96899	2.6685934	1.0714564	3635.5974
902.86987	2.6691477	1.0738	3626.5903
903.77075	2.6744959	1.0764863	3631.0884
904.67163	2.6759634	1.0789082	3627.377
905.57251	2.6771045	1.0812919	3624.9128
906.47339	2.683193	1.0834241	3621.4211
907.37427	2.6856432	1.0855583	3623.0215
908.27515	2.685936	1.087711	3617.9353
909.17603	2.6929805	1.090084	3623.4702
910.0769	2.6913087	1.0924586	3620.7236
910.97778	2.6986203	1.0948815	3623.2502
911.87866	2.700454	1.0975927	3622.6335
912.77954	2.7015622	1.1002815	3613.5239
913.68042	2.7045319	1.1028842	3618.7612
914.5813	2.708477	1.1055219	3612.6621
915.48218	2.7096717	1.1083065	3604.9724
916.38306	2.7103508	1.1108319	3606.7942
917.28394	2.7137465	1.1134595	3606.3711
918.18481	2.718919	1.1158056	3607.4011
919.08569	2.722358	1.1181036	3599.8662
919.98657	2.7237382	1.1201421	3598.563
920.88745	2.7268245	1.1224585	3607.4631
921.78833	2.729825	1.1249709	3605.1936
922.68921	2.7316127	1.1278226	3595.5308
923.59009	2.7360423	1.1299636	3590.8865
924.49097	2.7355721	1.1321508	3593.1179
925.39185	2.7404158	1.1349511	3598.4648
926.29272	2.741266	1.1377698	3587.5083
927.1936	2.7437906	1.140515	3582.3398
928.09448	2.7468722	1.1432792	3580.1814
928.99536	2.7536476	1.1458298	3585.1331
929.89624	2.7543683	1.1484501	3584.5786
930.79712	2.7540188	1.1509099	3579.2805
931.698	2.7590585	1.1535624	3573.7517
932.59888	2.7601252	1.1559514	3566.5767
933.49976	2.7605636	1.1583984	3566.3743
934.40063	2.7640276	1.1612437	3571.2798
935.30151	2.7675965	1.1643081	3567.8716
936.20239	2.7716279	1.16681	3561.7903
937.10327	2.7740748	1.1693807	3561.7947
938.00415	2.7761755	1.1720381	3559.7561
938.90503	2.7785728	1.1745807	3553.2124
939.80591	2.7821128	1.1768216	3552.0781
940.70679	2.784812	1.1790681	3551.0015
941.60767	2.7904434	1.1816639	3554.9187
942.50854	2.7889102	1.1841884	3541.9773
943.40942	2.7914007	1.1867261	3547.1138
944.3103	2.7975254	1.1903843	3550.0234
945.21118	2.7982593	1.1935487	3531.9265
946.11206	2.8022959	1.1962285	3538.3135
947.01294	2.8054194	1.1992742	3527.854
947.91382	2.8060789	1.2015266	3526.137
948.8147	2.8067892	1.2039291	3524.7644
949.71558	2.810478	1.2063044	3530.1243
950.61646	2.8143847	1.2091705	3519.9524
951.51733	2.8150787	1.2117931	3519.5461
952.41821	2.8163669	1.2145524	3511.4094
953.31909	2.8228369	1.2173343	3511.1907
954.21997	2.8249214	1.2199062	3512.3562
955.12085	2.8286934	1.2223947	3502.9866
956.02173	2.830924	1.22515	3512.5459
956.92261	2.8360178	1.2279463	3504.7886
957.82349	2.8356538	1.2309922	3502.6362
958.72437	2.8373435	1.2337965	3488.8301
959.62524	2.8429716	1.2367077	3490.5144
960.52612	2.8451784	1.2393458	3483.425
961.427	2.8457227	1.2420316	3481.3772
962.32788	2.8506653	1.2452648	3476.752
963.22876	2.8519988	1.2484413	3471.625
964.12964	2.8563006	1.2524648	3448.3494
965.03052	2.8581061	1.2557287	3440.4048
965.9314	2.8598194	1.2589877	3419.1726
966.83228	2.8664327	1.2612162	3416.8127
967.73315	2.8641436	1.2641897	3414.7036
968.63403	2.8672857	1.267038	3412.6924
969.53491	2.8730402	1.2700354	3408.6509
970.43579	2.8756285	1.2730713	3401.7583
971.33667	2.8792167	1.2760019	3394.271
972.23755	2.8813746	1.2790533	3388.9292
973.13843	2.8807154	1.2823595	3374.2144
974.03931	2.8865709	1.2863539	3362.7146
974.94019	2.8896084	1.2910159	3331.8733
975.84106	2.8918147	1.2967731	3270.675
976.74194	2.8951755	1.3006291	3254.439
977.64282	2.8977408	1.3035313	3242.7463
978.5437	2.9000137	1.305892	3229.095
979.44458	2.9028466	1.3088909	3228.5688
980.34546	2.9051673	1.3137846	3191.7354
981.24634	2.9120932	1.3204806	3135.8342
982.14722	2.9102695	1.3260014	3095.1052
983.0481	2.9176257	1.3292367	3079.1428
983.94897	2.9166934	1.3337147	3043.6707
984.84985	2.9176002	1.3378068	3022.1792
985.75073	2.924727	1.3429813	2995.4102
986.65161	2.9253521	1.3488188	2953.3384
986.85181	2.9294209	1.3581173	2844.5671