File: datasets/am_bench_2022/raw_data/TH3-F/specimen.dat
MTS793|MPT|ENU|1|2|.|/|:|1|0|0|A

Operator Information						Time:	11.897949	Sec	11/3/2021 1:26:02 PM
Operator	Nick Derimow
Project	AM Bench 2022 mini-tensile challenge
Specimen ID	TH3-F
Material	PBF-L Inconel 625
Specimen Width	2.56	mm
Specimen Thickness	1.51	mm
Notes
Operator Information End

Data Acquisition						Time:	1012.8928	Sec	11/3/2021 1:42:43 PM
Time	Axial Displacement	Axial Extensometer	Axial Force
Sec	mm	mm	N
12.012695	-0.00037245278	-3.3279368e-05	36.529266
12.913574	0.0018425722	-5.1719555e-05	46.9161
13.814453	0.0039937226	0.00013544629	58.426102
14.715332	0.004545494	0.00030359416	66.918724
15.616211	0.011790746	0.00010100412	77.913391
16.51709	0.013776959	0.00030346712	86.193962
17.417969	0.014842751	0.00039832242	94.705215
18.318848	0.019309374	0.00040194491	108.47174
19.219727	0.020394681	0.00053485151	116.95905
20.120605	0.023616539	0.00054894801	130.2683
21.021484	0.027491387	0.00063449715	140.11441
21.922363	0.028133053	0.00070861034	152.12013
22.823242	0.030195076	0.00076501991	163.08455
23.724121	0.035881773	0.0010044032	180.71022
24.625	0.03913027	0.00096646661	191.47919
25.525879	0.038161341	0.0010362883	203.87502
26.426758	0.045030463	0.0011928967	226.58846
27.327637	0.04712322	0.0012303549	239.4225
28.228516	0.046660371	0.0013729447	256.11649
29.129395	0.051075719	0.0014004319	272.79517
30.030273	0.051871873	0.0015050082	286.9303
30.931152	0.05689903	0.0015836279	301.38821
31.832031	0.058784027	0.00170034	323.47528
32.73291	0.060021978	0.0017458831	339.48315
33.633789	0.065602697	0.001956471	367.03931
34.534668	0.063545637	0.0020069317	382.03445
35.435547	0.065783612	0.0021225547	395.9079
36.336426	0.071890749	0.0022118522	412.46533
37.237305	0.075264022	0.0023372578	435.6188
38.138184	0.078790754	0.0025566316	458.89905
39.039063	0.081663072	0.0026033591	482.01651
39.939941	0.082755961	0.0026918862	507.15869
40.84082	0.084271334	0.0027284839	525.71527
41.741699	0.090406947	0.0029049995	549.35199
42.642578	0.091968372	0.0031004143	570.40546
43.543457	0.095169127	0.0032001049	589.78497
44.444336	0.096583076	0.0033035155	609.71075
45.345215	0.099724464	0.0035500987	638.75922
46.246094	0.1005514	0.0035931217	651.26898
47.146973	0.10607168	0.003787094	679.6308
48.047852	0.10693243	0.0039320248	705.84143
48.94873	0.10843858	0.0039364956	727.04028
49.849609	0.10888171	0.0042450326	755.91406
50.750488	0.11428346	0.0042799171	776.62653
51.651367	0.1138831	0.0043988544	799.11188
52.552246	0.11865102	0.0045143832	822.81671
53.453125	0.12196753	0.0046906448	841.75348
54.354004	0.12623501	0.0048220977	868.33759
55.254883	0.12521403	0.0049904096	893.13019
56.155762	0.13208842	0.0051628673	923.73792
57.056641	0.13778067	0.0053765704	956.06946
57.95752	0.13834964	0.005542228	975.81439
58.858398	0.14012256	0.0055798246	996.84833
59.759277	0.14051411	0.0057022446	1022.4891
60.660156	0.14527306	0.0059916954	1050.5002
61.561035	0.14489524	0.0061092977	1076.6713
62.461914	0.14838715	0.0062659183	1099.7255
63.362793	0.15157212	0.0064198929	1118.4934
64.263672	0.15506019	0.0063912407	1144.5566
65.164551	0.15724325	0.0066448557	1168.5449
66.06543	0.1576221	0.0068016076	1185.5425
66.966309	0.16084887	0.0069772135	1214.9481
67.867188	0.16178727	0.0070741302	1237.6879
68.768066	0.16629237	0.007257944	1264.7986
69.668945	0.17098656	0.0073709278	1288.3234
70.569824	0.17306924	0.0075632529	1324.1167
71.470703	0.17743438	0.0077711414	1354.5061
72.371582	0.17826194	0.0079184147	1372.4167
73.272461	0.18045591	0.008040648	1394.4258
74.17334	0.18326636	0.0082182083	1424.7367
75.074219	0.18590222	0.0083558932	1445.6351
75.975098	0.18954964	0.0085182218	1475.1151
76.875977	0.19153441	0.0086678686	1493.295
77.776855	0.1966673	0.008855042	1518.1149
78.677734	0.19703999	0.0089897076	1542.6504
79.578613	0.19834371	0.0092081968	1572.399
80.479492	0.20264694	0.0093657691	1594.2611
81.380371	0.20678696	0.0095185339	1620.2339
82.28125	0.20776285	0.009575149	1639.0813
83.182129	0.20990475	0.0098470859	1670.2039
84.083008	0.21606858	0.00985472	1689.9059
84.983887	0.2165931	0.010131466	1714.7458
85.884766	0.2184992	0.01021797	1736.7136
86.785645	0.22372776	0.010411024	1769.8995
87.686523	0.22587256	0.010544497	1790.532
88.587402	0.22644046	0.010757995	1821.6089
89.488281	0.23011513	0.010832771	1843.6494
90.38916	0.23193353	0.010970837	1857.759
91.290039	0.23595944	0.011122586	1884.3262
92.190918	0.23480549	0.011259842	1905.6575
93.091797	0.24268611	0.011461509	1932.5775
93.992676	0.24502879	0.011721058	1957.0077
94.893555	0.24604136	0.011655583	1972.0989
95.794434	0.24980393	0.011833685	1997.9943
96.695313	0.25138977	0.012106912	2022.3176
97.596191	0.25624087	0.012219314	2045.9852
98.49707	0.25690821	0.012326287	2064.9302
99.397949	0.25846988	0.012487378	2088.0083
100.29883	0.26179773	0.012625288	2099.8569
101.19971	0.26509541	0.012677527	2117.5757
102.10059	0.26924685	0.012901957	2137.4919
103.00146	0.27297744	0.013049942	2155.9119
103.90234	0.27541319	0.013116403	2167.9927
104.80322	0.27467498	0.013251141	2187.3914
105.7041	0.27778456	0.01334846	2203.783
106.60498	0.2806792	0.013507522	2231.9563
107.50586	0.28596821	0.0135557	2247.7454
108.40674	0.28753379	0.013751091	2260.2136
109.30762	0.28880143	0.013972533	2284.9812
110.2085	0.29575226	0.014077482	2299.4512
111.10938	0.29687747	0.014204997	2315.3235
112.01025	0.29766506	0.014317975	2326.3193
112.91113	0.30469891	0.014605353	2344.0859
113.81201	0.30518657	0.014661337	2353.7815
114.71289	0.30855143	0.014736781	2373.0308
115.61377	0.30806503	0.014861262	2391.2227
116.51465	0.31225705	0.015067745	2401.4133
117.41553	0.31281108	0.015070921	2414.4377
118.31641	0.31738523	0.015333802	2434.6365
119.21729	0.32088348	0.015507616	2443.2234
120.11816	0.32324627	0.015670253	2460.6287
121.01904	0.32536581	0.015784757	2471.2559
121.91992	0.32557994	0.015933899	2475.2327
122.8208	0.33086178	0.016034206	2491.8975
123.72168	0.33367959	0.016182384	2503.5051
124.62256	0.33823588	0.016311506	2511.0156
125.52344	0.33886161	0.016432414	2526.1226
126.42432	0.34306395	0.016546426	2531.7615
127.3252	0.34579447	0.016762359	2541.7664
128.22607	0.3484959	0.01686543	2556.8943
129.12695	0.35027903	0.016997734	2561.2144
130.02783	0.35236421	0.017146725	2578.3511
130.92871	0.35693446	0.01745401	2588.1313
131.82959	0.3595759	0.017664937	2606.1958
132.73047	0.36141187	0.017853599	2614.1377
133.63135	0.36821645	0.017949946	2624.4226
134.53223	0.36895838	0.018241126	2633.084
135.43311	0.36793536	0.018332202	2627.8892
136.33398	0.37231997	0.018681793	2652.8613
137.23486	0.37737513	0.018697392	2644.8997
138.13574	0.37855345	0.018899519	2659.6038
139.03662	0.3816092	0.019060066	2661.6377
139.9375	0.38420472	0.019342832	2678.2087
140.83838	0.38751653	0.019592592	2685.6936
141.73926	0.38823014	0.019896088	2703.0654
142.64014	0.39228427	0.020085787	2710.4309
143.54102	0.39270985	0.020421481	2712.1226
144.44189	0.39452025	0.020727105	2712.6995
145.34277	0.39914051	0.020888636	2725.4099
146.24365	0.40342206	0.02125648	2736.0889
147.14453	0.40484232	0.021683946	2745.8916
148.04541	0.40905958	0.02191098	2754.064
148.94629	0.40733194	0.022287942	2751.6191
149.84717	0.41183907	0.022630163	2761.251
150.74805	0.41826785	0.022949848	2765.6509
151.64893	0.41841802	0.023431461	2774.6628
152.5498	0.4216139	0.02375295	2782.2087
153.45068	0.42390233	0.024236526	2791.6809
154.35156	0.42558569	0.024738848	2796.6106
155.25244	0.42752942	0.02517138	2801.2188
156.15332	0.43187141	0.025678456	2804.6489
157.0542	0.43233693	0.026054135	2814.6816
157.95508	0.43659723	0.026613334	2817.3467
158.85596	0.440561	0.027124625	2824.1443
159.75684	0.44254777	0.027701722	2832.4268
160.65771	0.44808102	0.028369427	2833.1392
161.55859	0.44642979	0.028996233	2838.3152
162.45947	0.44628698	0.029692018	2838.124
163.36035	0.45309874	0.030199552	2855.4497
164.26123	0.45730263	0.030831205	2859.3496
165.16211	0.46061239	0.031522151	2863.884
166.06299	0.45976722	0.032276399	2861.7578
166.96387	0.46451369	0.032921635	2873.7141
167.86475	0.46765712	0.033565376	2880.6023
168.76563	0.46837071	0.034136713	2875.1558
169.6665	0.47108731	0.034917921	2886.5691
170.56738	0.47454789	0.03563362	2886.7683
171.46826	0.48042494	0.036415678	2891.0679
172.36914	0.4781689	0.037105702	2896.3577
173.27002	0.48331714	0.037811801	2897.1667
174.1709	0.48518959	0.038613398	2904.1201
175.07178	0.48899442	0.039382521	2903.199
175.97266	0.49148378	0.040220875	2912.1116
176.87354	0.49504554	0.0409697	2917.0828
177.77441	0.49760935	0.041744046	2915.4883
178.67529	0.50137538	0.04244063	2925.0667
179.57617	0.50267869	0.043372486	2931.7268
180.47705	0.50522751	0.044268101	2931.8035
181.37793	0.50835514	0.045117497	2933.5706
182.27881	0.51299971	0.045945738	2940.033
183.17969	0.51111293	0.046906747	2944.6777
184.08057	0.51615447	0.047743481	2945.5947
184.98145	0.51741517	0.048733775	2952.0984
185.88232	0.5206573	0.0494483	2947.3147
186.7832	0.52191526	0.050284002	2955.4941
187.68408	0.52959228	0.051099584	2957.645
188.58496	0.52958286	0.051935051	2961.7834
189.48584	0.53450245	0.052683864	2965.4016
190.38672	0.53286165	0.053595815	2966.9795
191.2876	0.53753638	0.054725941	2972.6582
192.18848	0.54516011	0.055836722	2981.4504
193.08936	0.54448646	0.056686386	2982.4468
193.99023	0.5425697	0.057593107	2979.7026
194.89111	0.55063844	0.058388032	2982.6609
195.79199	0.55202281	0.059210423	2989.1599
196.69287	0.5533427	0.060102824	2988.2339
197.59375	0.55759603	0.060920265	2992.4573
198.49463	0.55890036	0.061836794	2994.241
199.39551	0.56328821	0.062825821	3005.5913
200.29639	0.56536555	0.063760832	3002.96
201.19727	0.56730115	0.064777739	3008.3052
202.09814	0.56962585	0.065734737	2999.4236
202.99902	0.57036	0.066569507	3004.5859
203.8999	0.57393038	0.067552947	3010.3608
204.80078	0.58043188	0.068514027	3018.3142
205.70166	0.58533114	0.069284238	3018.3813
206.60254	0.58323437	0.070164353	3013.9451
207.50342	0.58245331	0.070967473	3016.4438
208.4043	0.58617616	0.072059602	3022.6116
209.30518	0.59259361	0.072993435	3029.7014
210.20605	0.59589893	0.074060626	3024.9756
211.10693	0.5975067	0.07502085	3035.4888
212.00781	0.5974862	0.075791225	3028.0007
212.90869	0.60173994	0.076661319	3035.4143
213.80957	0.60735959	0.077601157	3041.2681
214.71045	0.6046192	0.078492068	3040.8394
215.61133	0.61128938	0.079454817	3044.0112
216.51221	0.61418319	0.080450185	3048.9702
217.41309	0.61722416	0.081396282	3051.4009
218.31396	0.61829001	0.082376942	3054.7273
219.21484	0.62099165	0.083348855	3053.574
220.11572	0.62340117	0.084370174	3059.0586
221.0166	0.62753147	0.085470721	3064.5879
221.91748	0.6289677	0.086577184	3062.4893
222.81836	0.63115758	0.087579042	3067.1311
223.71924	0.63683611	0.088409133	3067.3757
224.62012	0.63751185	0.089509331	3065.7366
225.521	0.64175344	0.090613507	3076.2976
226.42188	0.64075375	0.091721736	3075.8337
227.32275	0.64496297	0.092695802	3081.2734
228.22363	0.64915991	0.093816303	3075.7107
229.12451	0.65251434	0.094741352	3082.0159
230.02539	0.65494663	0.095813163	3085.3738
230.92627	0.65541047	0.096721306	3084.2603
231.82715	0.6600284	0.097634986	3090.3733
232.72803	0.66318458	0.098729827	3096.1042
233.62891	0.66475856	0.099679172	3086.8369
234.52979	0.66875589	0.10052898	3094.1084
235.43066	0.67246437	0.10150815	3100.2078
236.33154	0.6733638	0.10241617	3100.7793
237.23242	0.6728493	0.10345783	3105.7871
238.1333	0.67721802	0.10448981	3098.2283
239.03418	0.67915463	0.10532319	3101.0417
239.93506	0.68605703	0.10624871	3105.2017
240.83594	0.68651539	0.10731778	3110.1274
241.73682	0.68924272	0.10812519	3104.6575
242.6377	0.69109696	0.10892224	3104.6118
243.53857	0.69719952	0.10978381	3115.731
244.43945	0.70007449	0.11093532	3122.5017
245.34033	0.70105183	0.11173188	3120.2932
246.24121	0.7008453	0.11270206	3115.9395
247.14209	0.70226872	0.11360959	3117.9805
248.04297	0.70739049	0.1145644	3123.2173
248.94385	0.71129876	0.11565883	3117.5078
249.84473	0.71239698	0.11652061	3121.7495
250.74561	0.71556348	0.11743805	3126.7996
251.64648	0.7167539	0.11843438	3126.3335
252.54736	0.7230581	0.11935517	3137.7793
253.44824	0.7221427	0.12026583	3129.7507
254.34912	0.7282303	0.12121043	3138.4771
255.25	0.7298221	0.12213539	3140.1416
256.15088	0.73423499	0.12307714	3141.6987
257.05176	0.73673689	0.12413344	3145.4426
257.95264	0.73784697	0.1251086	3144.9238
258.85352	0.74072647	0.12602919	3150.6423
259.75439	0.74151057	0.12698905	3146.8586
260.65527	0.74371314	0.12807654	3152.2769
261.55615	0.74720037	0.12914565	3153.981
262.45703	0.75058508	0.13041116	3157.6301
263.35791	0.7538957	0.13144125	3167.5129
264.25879	0.75632733	0.13243902	3151.6311
265.15967	0.75766587	0.13334392	3156.2822
266.06055	0.76169235	0.13446073	3163.4299
266.96143	0.7634986	0.13546801	3159.312
267.8623	0.76749068	0.13630663	3164.5991
268.76318	0.76982665	0.13702486	3160.1672
269.66406	0.77242094	0.13782609	3166.4988
270.56494	0.77764678	0.13881814	3170.6023
271.46582	0.77645272	0.13981013	3167.2097
272.3667	0.7832337	0.14091028	3181.4626
273.26758	0.78393525	0.14185482	3171.7109
274.16846	0.78638041	0.14284681	3174.3633
275.06934	0.79261619	0.14387222	3181.9004
275.97021	0.79155833	0.14481543	3177.8125
276.87109	0.7963171	0.14583066	3183.9875
277.77197	0.79827195	0.14674927	3182.1453
278.67285	0.80048001	0.14752436	3180.3777
279.57373	0.80094123	0.14832185	3179.1821
280.47461	0.80727714	0.14898166	3181.9072
281.37549	0.81009358	0.14970122	3188.4402
282.27637	0.80960327	0.150518	3192.9485
283.17725	0.81096888	0.15164946	3194.2495
284.07813	0.81293482	0.15272148	3195.5977
284.979	0.81857574	0.15381566	3196.9707
285.87988	0.82021552	0.15480521	3195.5869
286.78076	0.82360786	0.15603806	3198.0942
287.68164	0.82758534	0.15691888	3197.8057
288.58252	0.83084202	0.15779704	3202.8325
289.4834	0.83562267	0.15886343	3211.0251
290.38428	0.83550447	0.15968196	3203.6296
291.28516	0.83858114	0.1605943	3209.1353
292.18604	0.84066278	0.1616351	3209.7659
293.08691	0.84391677	0.16262084	3212.728
293.98779	0.84765786	0.16354659	3218.0676
294.88867	0.84890091	0.16442047	3219.0024
295.78955	0.85023457	0.16549326	3214.4417
296.69043	0.85429215	0.16637611	3219.2134
297.59131	0.85756093	0.16747952	3224.4167
298.49219	0.85811269	0.16832864	3220.8318
299.39307	0.86306489	0.16933301	3219.9644
300.29395	0.86669022	0.17022571	3224.4104
301.19482	0.87023085	0.17127497	3230.5151
302.0957	0.87395936	0.17245099	3232.6128
302.99658	0.87643284	0.17336713	3232.7544
303.89746	0.87307453	0.17422654	3220.5396
304.79834	0.8776415	0.17517948	3230.0251
305.69922	0.88058656	0.17603116	3228.8413
306.6001	0.88191217	0.17682496	3233.2327
307.50098	0.88647014	0.17794541	3235.135
308.40186	0.88869542	0.17888443	3231.4209
309.30273	0.89412171	0.17964713	3237.124
310.20361	0.89632505	0.18059851	3243.3867
311.10449	0.89717764	0.18148267	3236.0007
312.00537	0.901972	0.18234387	3247.9849
312.90625	0.90379244	0.18340617	3248.3022
313.80713	0.90611976	0.1842404	3244.3086
314.70801	0.90580505	0.18500124	3244.4331
315.60889	0.91121411	0.18588275	3247.2251
316.50977	0.91314459	0.18673186	3251.8535
317.41064	0.91636646	0.18769236	3256.2871
318.31152	0.91935438	0.18863411	3257.2825
319.2124	0.92134792	0.18967044	3260.6162
320.11328	0.92179704	0.19059239	3255.7705
321.01416	0.92619103	0.19162652	3255.5015
321.91504	0.92881709	0.19247955	3255.1003
322.81592	0.9308244	0.19355689	3259.2651
323.7168	0.93444067	0.19451751	3261.9785
324.61768	0.93823767	0.19541188	3261.2283
325.51855	0.93864071	0.19639701	3264.2871
326.41943	0.94219589	0.19742633	3264.3027
327.32031	0.94770622	0.19847822	3276.6213
328.22119	0.9506759	0.19938633	3266.8704
329.12207	0.95121324	0.20022379	3269.7031
330.02295	0.95493627	0.20115761	3274.9597
330.92383	0.95535302	0.20189589	3265.1365
331.82471	0.95861161	0.2028708	3271.2585
332.72559	0.96484822	0.20368294	3278.5991
333.62646	0.96547949	0.20465004	3274.9827
334.52734	0.96879476	0.20545509	3277.8398
335.42822	0.96928525	0.20646951	3283.261
336.3291	0.96984565	0.20746417	3277.9592
337.22998	0.97560608	0.20856003	3288.6482
338.13086	0.9789353	0.20951508	3286.5476
339.03174	0.98425734	0.21056989	3289.8167
339.93262	0.98440707	0.21149698	3288.9268
340.8335	0.98654407	0.21250769	3288.8806
341.73438	0.98856819	0.21349508	3292.5747
342.63525	0.9949742	0.21441123	3293.2493
343.53613	0.99272227	0.21522267	3290.9128
344.43701	0.9980002	0.21635772	3297.0427
345.33789	1.000546	0.21721549	3290.6184
346.23877	1.0031599	0.2181737	3299.2485
347.13965	1.004017	0.21919087	3301.4705
348.04053	1.0120178	0.22015458	3301.1079
348.94141	1.0127492	0.22110778	3308.7722
349.84229	1.0100634	0.22187012	3299.5295
350.74316	1.0153037	0.22287109	3305.9358
351.64404	1.0191003	0.22372039	3305.9214
352.54492	1.019276	0.22450314	3304.6953
353.4458	1.0240313	0.2252948	3302.8186
354.34668	1.0271282	0.2261962	3308.0095
355.24756	1.0280824	0.22715372	3307.1316
356.14844	1.0344377	0.22824739	3316.27
357.04932	1.0347321	0.22911893	3312.0886
357.9502	1.0365361	0.23013605	3320.0222
358.85107	1.0402719	0.23090644	3309.4692
359.75195	1.0419476	0.23172486	3312.8831
360.65283	1.0447464	0.23243828	3311.6106
361.55371	1.0488831	0.23339166	3322.2627
362.45459	1.0532615	0.23434152	3326.8882
363.35547	1.0511879	0.2352792	3319.6079
364.25635	1.0576621	0.23607907	3316.8679
365.15723	1.0588839	0.23694004	3325.1033
366.05811	1.0593309	0.23801485	3324.1865
366.95898	1.062888	0.23887825	3323.0671
367.85986	1.0665908	0.23985818	3328.5769
368.76074	1.0698568	0.24083422	3333.8381
369.66162	1.0747657	0.24192066	3336.4053
370.5625	1.0776205	0.24310483	3335.261
371.46338	1.0820239	0.24403839	3334.6936
372.36426	1.0825539	0.24519731	3340.8215
373.26514	1.0816681	0.24610263	3335.3984
374.16602	1.0862699	0.24696505	3336.8938
375.06689	1.0883359	0.24788968	3338.4314
375.96777	1.0900609	0.24880013	3334.2207
376.86865	1.0939838	0.24953493	3341.2764
377.76953	1.0969002	0.25053972	3343.6238
378.67041	1.1005722	0.25147152	3342.4795
379.57129	1.1042235	0.25244623	3345.0239
380.47217	1.1041737	0.25319144	3345.5708
381.37305	1.110163	0.2541154	3350.0862
382.27393	1.1122476	0.2549282	3349.979
383.1748	1.1135713	0.25581414	3353.5681
384.07568	1.1175941	0.25667357	3349.2197
384.97656	1.1184973	0.25756514	3350.0894
385.87744	1.1224815	0.25833622	3347.5303
386.77832	1.1254196	0.25920141	3353.9148
387.6792	1.1275388	0.26021472	3360.0381
388.58008	1.1306564	0.26112428	3361.3477
389.48096	1.1330251	0.26215842	3362.8508
390.38184	1.1333271	0.2633394	3356.4507
391.28271	1.1396141	0.26433662	3363.3096
392.18359	1.1425536	0.26522091	3363.0535
393.08447	1.1421994	0.2659775	3357.8345
393.98535	1.1453049	0.26688263	3366.9102
394.88623	1.1501048	0.26814556	3371.0508
395.78711	1.1536185	0.26912382	3366.6152
396.68799	1.1559085	0.27018473	3372.4722
397.58887	1.1580967	0.2710008	3370.1826
398.48975	1.1603683	0.27191228	3371.6655
399.39063	1.1625936	0.27280518	3372.4856
400.2915	1.1627878	0.27388388	3374.7778
401.19238	1.170195	0.2749491	3375.7847
402.09326	1.1709584	0.27561167	3367.0173
402.99414	1.1743475	0.27654064	3375.499
403.89502	1.1749046	0.27733269	3377.51
404.7959	1.1791277	0.27847487	3379.876
405.69678	1.1793615	0.27926552	3375.1086
406.59766	1.1858714	0.28017786	3382.5522
407.49854	1.1854448	0.28117913	3381.9321
408.39941	1.1900952	0.28223944	3388.5615
409.30029	1.1931785	0.28299925	3385.7837
410.20117	1.1936654	0.28378505	3382.6633
411.10205	1.1973099	0.28478566	3382.6243
412.00293	1.202289	0.28578678	3394.9602
412.90381	1.2032626	0.28678143	3393.7927
413.80469	1.2031717	0.28776881	3394.0793
414.70557	1.2062715	0.28863367	3388.8159
415.60645	1.2129031	0.28956756	3390.9792
416.50732	1.2139623	0.29036778	3393.8464
417.4082	1.2186646	0.29138598	3401.8569
418.30908	1.2194277	0.29218665	3396.668
419.20996	1.2209449	0.29309404	3395.7
420.11084	1.2252101	0.29407886	3397.457
421.01172	1.22489	0.29514661	3400.4385
421.9126	1.2271215	0.29590854	3399.5286
422.81348	1.2335627	0.29690316	3406.2078
423.71436	1.2353016	0.29771203	3400.7834
424.61523	1.2397686	0.29854289	3403.2742
425.51611	1.2409158	0.29926753	3404.3157
426.41699	1.243279	0.30035469	3414.9915
427.31787	1.2464367	0.30125645	3404.8325
428.21875	1.2502137	0.30218962	3411.1538
429.11963	1.2524571	0.30323857	3417.7058
430.02051	1.2562959	0.30409443	3411.1221
430.92139	1.256183	0.30479702	3402.8767
431.82227	1.2618459	0.30563256	3409.5544
432.72314	1.2616199	0.30650103	3412.4146
433.62402	1.2659431	0.30754524	3414.4392
434.5249	1.2675554	0.30847657	3414.03
435.42578	1.2681416	0.30946141	3420.0964
436.32666	1.2723799	0.31034672	3418.136
437.22754	1.2759601	0.3112596	3415.3972
438.12842	1.2799911	0.31229311	3425.177
439.0293	1.2813512	0.31326443	3419.2554
439.93018	1.2829417	0.31422648	3423.813
440.83105	1.285821	0.31528848	3421.0625
441.73193	1.292143	0.3162311	3428.9158
442.63281	1.2900155	0.31714189	3428.0549
443.53369	1.2941934	0.31822935	3429.9138
444.43457	1.298345	0.31928653	3428.7898
445.33545	1.2990154	0.32008716	3426.8191
446.23633	1.304336	0.32117367	3437.4353
447.13721	1.306389	0.32206678	3427.176
448.03809	1.3052188	0.32322082	3434.6375
448.93896	1.3115405	0.32410061	3430.21
449.83984	1.3140038	0.32500458	3437.0647
450.74072	1.3149209	0.3257674	3432.9805
451.6416	1.3180563	0.32657474	3437.002
452.54248	1.3240143	0.32770333	3437.9041
453.44336	1.3244277	0.32843712	3434.5823
454.34424	1.32428	0.3295939	3439.8401
455.24512	1.3304074	0.33054689	3443.7866
456.146	1.3343267	0.33151683	3442.4519
457.04688	1.3338033	0.33229637	3439.1272
457.94775	1.3404839	0.33321193	3443.2498
458.84863	1.3429898	0.33397469	3443.7166
459.74951	1.3412997	0.33491197	3443.3945
460.65039	1.3441263	0.3357977	3443.353
461.55127	1.3463596	0.33672601	3446.3516
462.45215	1.3515806	0.33779764	3447.4561
463.35303	1.3559108	0.33874661	3453.8218
464.25391	1.3560033	0.33972165	3451.6704
465.15479	1.3615638	0.34071067	3456.1819
466.05566	1.3614056	0.34166384	3456.033
466.95654	1.3648566	0.342601	3454.4509
467.85742	1.3656303	0.34363264	3458.5574
468.7583	1.3692789	0.34468335	3461.3618
469.65918	1.3739065	0.34572306	3456.8508
470.56006	1.3764766	0.34642926	3450.3259
471.46094	1.377012	0.34729537	3462.5168
472.36182	1.3854724	0.34824872	3465.4976
473.2627	1.3841083	0.34926793	3463.4319
474.16357	1.3864781	0.35038552	3463.5469
475.06445	1.3891228	0.3514502	3466.9983
475.96533	1.3927532	0.35254368	3468.5229
476.86621	1.3960046	0.35344681	3463.0869
477.76709	1.3976328	0.35423544	3462.5852
478.66797	1.3988377	0.35505149	3463.4097
479.56885	1.4021877	0.35604048	3468.5393
480.46973	1.4065031	0.35696355	3472.5281
481.37061	1.4091169	0.35780868	3472.5042
482.27148	1.4101179	0.35865694	3472.8447
483.17236	1.4132746	0.35980183	3475.0972
484.07324	1.4151689	0.36079866	3472.2561
484.97412	1.4203136	0.36180165	3478.0984
485.875	1.422201	0.3627893	3474.7258
486.77588	1.4263797	0.36372912	3475.7761
487.67676	1.427724	0.36461428	3481.2031
488.57764	1.4318473	0.36559871	3477.0703
489.47852	1.432906	0.36647314	3479.0928
490.37939	1.4382241	0.36744189	3483.6384
491.28027	1.4367784	0.36831221	3483.3809
492.18115	1.4419849	0.36947918	3483.3289
493.08203	1.440968	0.37038684	3477.3755
493.98291	1.4442874	0.3715179	3483.2483
494.88379	1.448873	0.37247902	3483.8784
495.78467	1.4506756	0.37331074	3481.0361
496.68555	1.4549426	0.37413156	3484.5361
497.58643	1.4556441	0.37510857	3489.2874
498.4873	1.4586052	0.37585905	3485.4478
499.38818	1.4628053	0.37674975	3488.0955
500.28906	1.4661564	0.37763003	3493.4268
501.18994	1.4705971	0.37858891	3493.3274
502.09082	1.4710168	0.37966704	3494.4521
502.9917	1.4749577	0.38063815	3495.9961
503.89258	1.4758427	0.38155875	3493.2234
504.79346	1.4804969	0.38246629	3490.095
505.69434	1.4812366	0.38327092	3497.2012
506.59521	1.4838612	0.38418111	3496.2913
507.49609	1.483348	0.38524085	3490.0728
508.39697	1.4873747	0.38607833	3495.6428
509.29785	1.4908873	0.38704589	3500.1023
510.19873	1.4919432	0.38815773	3497.1138
511.09961	1.4973241	0.3894276	3504.3899
512.00049	1.5001515	0.39051858	3505.9255
512.90137	1.5049797	0.39164603	3504.7673
513.80225	1.5045753	0.3925347	3499.9519
514.70313	1.5078696	0.39351979	3501.5095
515.604	1.5085574	0.39430791	3501.5029
516.50488	1.5168325	0.39537737	3504.6909
517.40576	1.5176291	0.39619377	3503.4753
518.30664	1.5177627	0.39703369	3502.4019
519.20752	1.5221057	0.39815256	3514.9805
520.1084	1.5258039	0.39910099	3510.5806
521.00928	1.5278062	0.40031049	3510.4172
521.91016	1.5292077	0.40111974	3509.2969
522.81104	1.5329138	0.40210783	3511.7241
523.71191	1.5328972	0.40311828	3509.5305
524.61279	1.5372682	0.40401703	3515.8289
525.51367	1.5432801	0.40515906	3520.718
526.41455	1.5456653	0.4062579	3521.2969
527.31543	1.5451772	0.40743598	3514.1509
528.21631	1.548857	0.40825263	3515.7104
529.11719	1.5519847	0.40928775	3520.8569
530.01807	1.5549177	0.41014272	3516.1099
530.91895	1.5554724	0.41114959	3521.4351
531.81982	1.5579289	0.41200781	3514.8445
532.7207	1.5603627	0.41287196	3517.543
533.62158	1.568435	0.41385043	3525.4771
534.52246	1.5653745	0.41479397	3524.04
535.42334	1.5708303	0.41594154	3527.5625
536.32422	1.5726038	0.41680166	3522.375
537.2251	1.5771456	0.41793713	3526.3303
538.12598	1.5763286	0.41890782	3522.8408
539.02686	1.5781629	0.42002994	3528.4597
539.92773	1.5833457	0.42105964	3525.0803
540.82861	1.587086	0.4220401	3523.719
541.72949	1.5911613	0.4228394	3530.8469
542.63037	1.5953881	0.42383555	3534.5007
543.53125	1.5944501	0.42465571	3526.8572
544.43213	1.595782	0.42567465	3533.5166
545.33301	1.5979881	0.42671585	3535.0334
546.23389	1.601882	0.42780843	3536.167
547.13477	1.6032896	0.42906728	3533.2485
548.03564	1.6077502	0.43000686	3532.6929
548.93652	1.6081878	0.4312222	3535.9482
549.8374	1.6136147	0.43219179	3534.2844
550.73828	1.6154282	0.43298915	3535.0337
551.63916	1.6214315	0.43394503	3540.4292
552.54004	1.6228533	0.43510219	3544.3369
553.44092	1.625615	0.43596923	3540.8467
554.3418	1.6281296	0.43680272	3537.6865
555.24268	1.6303785	0.43790135	3539.4661
556.14355	1.6334424	0.43901911	3539.9224
557.04443	1.6377561	0.43994927	3542.6609
557.94531	1.63867	0.44092026	3542.8557
558.84619	1.6408563	0.44208959	3548.8257
559.74707	1.6432368	0.44323778	3557.6133
560.64795	1.6470984	0.44425961	3548.7393
561.54883	1.6481395	0.44535941	3546.4141
562.44971	1.6523817	0.44630268	3547.2927
563.35059	1.6540219	0.44727087	3548.3682
564.25146	1.6581868	0.44816631	3548.8408
565.15234	1.6575742	0.44904077	3544.4009
566.05322	1.6638954	0.45009756	3557.6182
566.9541	1.6635838	0.45097929	3551.1365
567.85498	1.668081	0.45194185	3555.1665
568.75586	1.670603	0.45283377	3551.2432
569.65674	1.669638	0.45396382	3555.7446
570.55762	1.6756878	0.45500022	3557.7163
571.4585	1.6784954	0.45594633	3554.2048
572.35938	1.6792926	0.45704338	3557.7371
573.26025	1.6861888	0.45810047	3558.7527
574.16113	1.685501	0.45918137	3559.8171
575.06201	1.6898746	0.46012604	3554.9841
575.96289	1.6921877	0.46127117	3558.5459
576.86377	1.6957465	0.46232969	3563.1899
577.76465	1.6964617	0.46336073	3560.928
578.66553	1.700097	0.46432245	3562.782
579.56641	1.7009727	0.46541628	3562.9211
580.46729	1.7034565	0.46646717	3562.2
581.36816	1.708884	0.46756399	3564.5247
582.26904	1.7091379	0.46859097	3561.6851
583.16992	1.7128292	0.46961734	3566.9634
584.0708	1.7193196	0.47061384	3565.6367
584.97168	1.7193589	0.47165406	3565.2517
585.87256	1.7249112	0.47262838	3572.5315
586.77344	1.7239782	0.47375891	3568.4946
587.67432	1.7281338	0.47477624	3568.4868
588.5752	1.7291952	0.47591835	3567.7993
589.47607	1.7299181	0.47694111	3571.6138
590.37695	1.7332441	0.47800365	3565.9841
591.27783	1.7379582	0.47925842	3574.6333
592.17871	1.7413489	0.48013464	3564.5532
593.07959	1.7435561	0.4810605	3575.8391
593.98047	1.7473463	0.4821693	3576.4683
594.88135	1.7468711	0.48318368	3573.0427
595.78223	1.7485008	0.48434517	3576.6846
596.68311	1.7508692	0.48558772	3575.8042
597.58398	1.7554419	0.48653433	3572.375
598.48486	1.7596612	0.4875927	3574.3579
599.38574	1.7609364	0.48861688	3579.7151
600.28662	1.7668347	0.48980016	3579.0906
601.1875	1.7663674	0.49075571	3574.0305
602.08838	1.7728206	0.49179429	3580.2432
602.98926	1.7736028	0.49289155	3581.925
603.89014	1.7742814	0.49381852	3579.8228
604.79102	1.7799861	0.49496958	3585.0603
605.69189	1.7814047	0.49586692	3581.4116
606.59277	1.7835159	0.49695066	3582.2666
607.49365	1.7887666	0.49809107	3585.116
608.39453	1.7905449	0.49935922	3590.6436
609.29541	1.7898641	0.50045294	3579.5205
610.19629	1.7942306	0.50158393	3591.7429
611.09717	1.7969882	0.50264996	3585.8223
611.99805	1.79915	0.50368464	3586.699
612.89893	1.8052927	0.50455618	3589.575
613.7998	1.8073367	0.50567067	3594.3755
614.70068	1.8108693	0.50659883	3592.1604
615.60156	1.8105869	0.50756967	3588.2795
616.50244	1.8113986	0.50866526	3588.8682
617.40332	1.8157263	0.5098809	3595.9971
618.3042	1.8201106	0.51095712	3588.3281
619.20508	1.8206694	0.51219374	3598.7227
620.10596	1.8259301	0.51338023	3597.0732
621.00684	1.8275819	0.51455307	3599.054
621.90771	1.8283315	0.51554352	3596.3506
622.80859	1.8314618	0.51663655	3595.1943
623.70947	1.8357282	0.51775002	3592.6538
624.61035	1.841952	0.51871914	3593.6533
625.51123	1.8406795	0.51976568	3594.7407
626.41211	1.8441911	0.52102751	3608.7512
627.31299	1.8461832	0.5221163	3601.5598
628.21387	1.8500125	0.52335954	3605.3521
629.11475	1.8522655	0.52448893	3597.5815
630.01563	1.8557333	0.52581805	3601.5076
630.9165	1.8564458	0.52706867	3601.2341
631.81738	1.8611753	0.52789992	3595.7166
632.71826	1.8608905	0.52889562	3600.0928
633.61914	1.8642255	0.52989632	3598.7046
634.52002	1.8660233	0.53070021	3596.9426
635.4209	1.8685822	0.53167593	3601.1362
636.32178	1.8699535	0.53287512	3608.4771
637.22266	1.8795493	0.53410578	3608.0706
638.12354	1.8768724	0.53506076	3599.97
639.02441	1.8816314	0.53637528	3606.876
639.92529	1.8836291	0.53744167	3609.1931
640.82617	1.8877971	0.53862262	3603.0144
641.72705	1.8901578	0.5395869	3603.7725
642.62793	1.8933531	0.5408259	3602.8748
643.52881	1.8950585	0.5420332	3607.0715
644.42969	1.9017801	0.54302919	3607.0388
645.33057	1.9007535	0.54416007	3607.0115
646.23145	1.9034828	0.545196	3611.8965
647.13232	1.9060884	0.54626137	3604.9739
648.0332	1.9089774	0.5473451	3611.2043
648.93408	1.9134121	0.54841459	3607.9958
649.83496	1.9134461	0.54964441	3613.3103
650.73584	1.9174914	0.55077499	3612.8386
651.63672	1.9192162	0.55183017	3613.3975
652.5376	1.924526	0.55315447	3620.6772
653.43848	1.924382	0.55427092	3619.8325
654.33936	1.9272382	0.55567867	3615.1736
655.24023	1.9304115	0.55682391	3617.196
656.14111	1.9342468	0.55809039	3616.6985
657.04199	1.936108	0.55942255	3617.283
657.94287	1.9377671	0.5606522	3612.948
658.84375	1.9405673	0.5617522	3615.7244
659.74463	1.9442422	0.562819	3612.1792
660.64551	1.9448195	0.56395751	3615.6196
661.54639	1.9482751	0.56497854	3615.6416
662.44727	1.9513444	0.56594652	3616.843
663.34814	1.9567724	0.56718326	3622.1401
664.24902	1.9601933	0.56852978	3623.7727
665.1499	1.9586853	0.56980032	3619.8137
666.05078	1.9619993	0.57092357	3622.3206
666.95166	1.9628097	0.57209569	3616.9734
667.85254	1.9690733	0.57314777	3621.4387
668.75342	1.9695929	0.57426858	3619.4412
669.6543	1.9731239	0.57555598	3624.5276
670.55518	1.975253	0.57654881	3614.2151
671.45605	1.9774435	0.57779145	3621.3401
672.35693	1.9827068	0.57903206	3626.0691
673.25781	1.9800675	0.58024925	3622.635
674.15869	1.9848676	0.58139032	3619.6575
675.05957	1.9867226	0.58278507	3625.1492
675.96045	1.9910927	0.58400244	3623.2769
676.86133	1.9952674	0.58514118	3622.6045
677.76221	1.9999381	0.58627999	3627.6267
678.66309	2.0018528	0.58731073	3628.0266
679.56396	2.0033588	0.58841085	3624.5847
680.46484	2.0057037	0.5894897	3628.7217
681.36572	2.0072358	0.590765	3630.1567
682.2666	2.0107427	0.59198034	3629.6665
683.16748	2.013351	0.59331423	3631.3567
684.06836	2.01565	0.59441179	3625.6829
684.96924	2.019886	0.59544396	3629.5876
685.87012	2.0210998	0.59655321	3629.7437
686.771	2.0249329	0.59785777	3631.2432
687.67188	2.0259807	0.59892017	3627.3545
688.57275	2.0309072	0.60005903	3633.6799
689.47363	2.0326099	0.60133696	3632.9194
690.37451	2.0349784	0.60287756	3635.8494
691.27539	2.0364046	0.60409284	3640.2681
692.17627	2.0414722	0.60515511	3633.8345
693.07715	2.0444548	0.60658884	3639.6943
693.97803	2.0476916	0.60781223	3633.0452
694.87891	2.0488262	0.60903585	3633.9705
695.77979	2.0506248	0.61019927	3631.668
696.68066	2.0550637	0.61113399	3633.8328
697.58154	2.0564084	0.6122359	3634.1272
698.48242	2.058718	0.61331594	3634.2649
699.3833	2.0634549	0.61453503	3636.1936
700.28418	2.0623987	0.61571366	3630.811
701.18506	2.0671027	0.61694729	3632.77
702.08594	2.0691397	0.61832684	3639.7986
702.98682	2.0720599	0.6197921	3642.7092
703.8877	2.0753975	0.62126625	3638.1812
704.78857	2.0783319	0.62270761	3641.8904
705.68945	2.0790036	0.62397623	3640.8389
706.59033	2.0833724	0.6252138	3642.3848
707.49121	2.0840538	0.62629116	3634.1941
708.39209	2.0873258	0.62737244	3640.2102
709.29297	2.0926576	0.62847757	3632.5093
710.19385	2.094065	0.62959224	3638.0576
711.09473	2.1005218	0.63057518	3636.0769
711.99561	2.0997946	0.63174039	3641.7183
712.89648	2.1027129	0.63299519	3639.8716
713.79736	2.1071017	0.63412195	3643.248
714.69824	2.1087637	0.63530236	3648.9202
715.59912	2.1106629	0.63666958	3646.0112
716.5	2.1117175	0.63798231	3641.1226
717.40088	2.1165121	0.6393559	3642.4148
718.30176	2.1204119	0.64053613	3641.5884
719.20264	2.1194601	0.64185971	3647.4519
720.10352	2.1212826	0.64343095	3647.9385
721.00439	2.1290929	0.64480454	3645.4041
721.90527	2.1305981	0.64640713	3651.3887
722.80615	2.1344879	0.64785522	3642.2336
723.70703	2.1360404	0.64911795	3643.1274
724.60791	2.1377594	0.65021122	3644.7112
725.50879	2.140806	0.65153265	3651.4536
726.40967	2.1429377	0.65275866	3648.5645
727.31055	2.1462076	0.65411729	3652.1311
728.21143	2.1503193	0.65541112	3650.3052
729.1123	2.1529067	0.65682256	3646.5305
730.01318	2.1543553	0.65829724	3647.4446
730.91406	2.1575291	0.65936661	3642.0161
731.81494	2.1615112	0.66050482	3647.1282
732.71582	2.1639736	0.66166985	3645.5283
733.6167	2.1677482	0.66292596	3649.9363
734.51758	2.1669941	0.66421962	3651.1951
735.41846	2.1689336	0.66590255	3655.521
736.31934	2.1726246	0.66715676	3649.8337
737.22021	2.1762621	0.66862524	3657.2715
738.12109	2.175247	0.66990411	3651.6309
739.02197	2.1847465	0.67122054	3652.0393
739.92285	2.1838999	0.67245901	3649.3425
740.82373	2.1861384	0.67385364	3654.5012
741.72461	2.1881881	0.67527902	3656.1519
742.62549	2.1881907	0.67642534	3646.1826
743.52637	2.1972692	0.67783827	3654.8191
744.42725	2.1993918	0.67910701	3653.1338
745.32813	2.2015145	0.68063569	3654.4141
746.229	2.2033768	0.68173957	3652.2227
747.12988	2.2052591	0.68307489	3653.2317
748.03076	2.2103841	0.6844793	3659.1091
748.93164	2.2114415	0.68591821	3651.1377
749.83252	2.2122297	0.68733323	3651.5969
750.7334	2.2144876	0.68889439	3655.7104
751.63428	2.2179768	0.69007224	3644.5017
752.53516	2.2205353	0.69117975	3643.397
753.43604	2.2264082	0.6924696	3655.4631
754.33691	2.227699	0.69382668	3657.7124
755.23779	2.2304618	0.69519949	3655.9329
756.13867	2.232008	0.69666564	3653.1602
757.03955	2.2355196	0.69808728	3653.6575
757.94043	2.2352018	0.6994679	3654.9885
758.84131	2.240093	0.70071542	3655.0862
759.74219	2.245506	0.70230544	3658.9536
760.64307	2.246376	0.70400453	3657.4929
761.54395	2.2457292	0.705661	3655.5298
762.44482	2.2486584	0.70728183	3653.4028
763.3457	2.2522607	0.7086097	3653.614
764.24658	2.2588255	0.71029967	3664.1367
765.14746	2.2606969	0.71185112	3660.8481
766.04834	2.2636337	0.71340233	3657.3523
766.94922	2.2644851	0.71473747	3654.7776
767.8501	2.2704673	0.71629208	3657.4792
768.75098	2.2689621	0.7174567	3649.209
769.65186	2.2745249	0.71858352	3651.8567
770.55273	2.2747834	0.71996379	3654.582
771.45361	2.2766185	0.7210564	3650.8215
772.35449	2.2819235	0.72254026	3660.0398
773.25537	2.2849102	0.72412962	3659.4802
774.15625	2.2885807	0.72569859	3659.6157
775.05713	2.2891455	0.72739804	3657.429
775.95801	2.2942181	0.72897804	3656.5093
776.85889	2.2939281	0.73058021	3656.5603
777.75977	2.2945828	0.73214352	3658.8706
778.66064	2.2995698	0.73389214	3665.9246
779.56152	2.3046558	0.7350539	3653.7922
780.4624	2.3046167	0.73641485	3651.7869
781.36328	2.3101413	0.7376141	3657.7512
782.26416	2.3113854	0.73908055	3657.4871
783.16504	2.3148315	0.74038935	3661.6965
784.06592	2.3178494	0.74208117	3660.6035
784.9668	2.3191309	0.74341482	3655.1047
785.86768	2.3235283	0.74479103	3661.2556
786.76855	2.3273065	0.74643052	3662.9785
787.66943	2.3288691	0.74799502	3659.0066
788.57031	2.3323636	0.74934405	3660.5154
789.47119	2.332006	0.75094163	3662.0444
790.37207	2.334739	0.75255841	3661.2271
791.27295	2.3344676	0.75407094	3654.8733
792.17383	2.3405027	0.75540614	3656.3894
793.07471	2.3418515	0.75697309	3663.9004
793.97559	2.3467257	0.7587291	3662.1907
794.87646	2.3500407	0.76088518	3664.229
795.77734	2.350399	0.76261288	3660.0315
796.67822	2.3525522	0.7641173	3658.6045
797.5791	2.3575203	0.76581198	3658.9971
798.47998	2.3583994	0.76731253	3659.1743
799.38086	2.3615191	0.76867384	3655.7588
800.28174	2.3667481	0.77020311	3666.6228
801.18262	2.3682871	0.77169156	3663.3889
802.0835	2.366394	0.7733534	3658.3506
802.98438	2.3715575	0.77505338	3664.5432
803.88525	2.3761332	0.77678698	3662.0896
804.78613	2.3778512	0.77838874	3658.9131
805.68701	2.3819733	0.77986503	3655.7114
806.58789	2.3834479	0.78140897	3664.1309
807.48877	2.3864427	0.7831313	3657.1902
808.38965	2.3890486	0.7844581	3659.0901
809.29053	2.3894846	0.78610915	3663.4949
810.19141	2.3925266	0.78795511	3661.6194
811.09229	2.3960471	0.79000562	3666.3694
811.99316	2.399322	0.79178357	3655.6753
812.89404	2.4038513	0.79323888	3656.7419
813.79492	2.4059803	0.79473644	3660.2629
814.6958	2.4085021	0.79628247	3658.5479
815.59668	2.4100008	0.7978394	3658.6448
816.49756	2.4141889	0.79935074	3656.1797
817.39844	2.4185095	0.80101675	3662.7397
818.29932	2.4184361	0.80269408	3658.2966
819.2002	2.42066	0.80426586	3658.2136
820.10107	2.425513	0.8057695	3658.2273
821.00195	2.4227743	0.80751348	3660.9504
821.90283	2.430474	0.80920911	3663.8384
822.80371	2.4336903	0.81103206	3662.9421
823.70459	2.4346654	0.81297415	3661.0964
824.60547	2.4406703	0.81479698	3660.2178
825.50635	2.4421749	0.81635553	3655.3696
826.40723	2.4468958	0.81819546	3660.9851
827.30811	2.4453878	0.81999135	3658.2173
828.20898	2.4483414	0.82159626	3655.3445
829.10986	2.452184	0.82354504	3658.5911
830.01074	2.4531081	0.82529163	3656.9995
830.91162	2.4565024	0.82686847	3658.3735
831.8125	2.4606485	0.82880759	3658.0486
832.71338	2.4638658	0.83082837	3668.6787
833.61426	2.4649947	0.83271527	3658.6641
834.51514	2.4657674	0.83457041	3656.4646
835.41602	2.4696906	0.83677012	3655.1816
836.31689	2.4718571	0.83869308	3657.1099
837.21777	2.4773679	0.84031558	3655.6641
838.11865	2.4768085	0.84145319	3649.8718
839.01953	2.482882	0.84318566	3659.7646
839.92041	2.4849846	0.84511942	3663.5093
840.82129	2.4886665	0.84700507	3657.9146
841.72217	2.4907837	0.84904194	3653.7678
842.62305	2.4971161	0.85097837	3660.4673
843.52393	2.4959879	0.85299009	3657.8831
844.4248	2.4996436	0.85519361	3660.0547
845.32568	2.500324	0.8573274	3659.1736
846.22656	2.5055723	0.85910302	3652.8792
847.12744	2.5053031	0.86077744	3654.5068
848.02832	2.5060894	0.86285043	3654.9868
848.9292	2.5130031	0.86545199	3662.1997
849.83008	2.5152326	0.86770862	3656.2012
850.73096	2.5158098	0.86963409	3652.7222
851.63184	2.520035	0.87125468	3644.8196
852.53271	2.5186985	0.87288916	3650.2725
853.43359	2.5257561	0.87451023	3651.637
854.33447	2.5258207	0.87616307	3648.3564
855.23535	2.5271742	0.87800443	3651.1277
856.13623	2.5345895	0.88012302	3653.1824
857.03711	2.5357804	0.88206214	3657.3037
857.93799	2.538173	0.8839677	3653.1367
858.83887	2.5408044	0.886123	3652.1003
859.73975	2.544672	0.88803321	3647.5215
860.64063	2.5480044	0.88993406	3648.3733
861.5415	2.5487366	0.89168763	3648.2905
862.44238	2.551784	0.89344543	3650.5635
863.34326	2.5529566	0.89558476	3651.4609
864.24414	2.555979	0.89804947	3650.6787
865.14502	2.5610211	0.90011024	3647.3196
866.0459	2.5630109	0.90210503	3647.24
866.94678	2.5676572	0.9044894	3649.1152
867.84766	2.5683522	0.90645754	3644.4993
868.74854	2.5708365	0.90841973	3652.1865
869.64941	2.5724049	0.91052407	3650.3962
870.55029	2.5751624	0.9132877	3653.178
871.45117	2.581481	0.91584724	3645.1233
872.35205	2.5794821	0.91780955	3642.5657
873.25293	2.5832133	0.91995573	3641.0171
874.15381	2.5846403	0.92184967	3643.6748
875.05469	2.588299	0.92410588	3646.2485
875.95557	2.5941415	0.92652833	3650.6802
876.85645	2.5945668	0.92883533	3642.6687
877.75732	2.5965254	0.93122274	3646.2637
878.6582	2.6001303	0.93391567	3648.4038
879.55908	2.6031914	0.93603188	3632.6692
880.45996	2.6044383	0.93809938	3636.6958
881.36084	2.6112244	0.94002444	3640.1863
882.26172	2.6111481	0.94210434	3642.915
883.1626	2.6116889	0.94459474	3640.8899
884.06348	2.617382	0.94706935	3643.4648
884.96436	2.6168981	0.94939059	3630.9641
885.86523	2.6219041	0.95143491	3638.0308
886.76611	2.6275733	0.95383573	3643.2747
887.66699	2.6293328	0.95629269	3645.5652
888.56787	2.6285081	0.95892686	3640.0371
889.46875	2.6346626	0.96127963	3634.8711
890.36963	2.6377587	0.96326888	3632.6206
891.27051	2.6374857	0.96521902	3628.5212
892.17139	2.6407185	0.96766967	3636.155
893.07227	2.6429789	0.97024828	3633.4058
893.97314	2.6446605	0.97266632	3628.6499
894.87402	2.6495366	0.97500259	3630.4526
895.7749	2.6517	0.97750735	3635.6917
896.67578	2.6541855	0.9799121	3633.1531
897.57666	2.6540239	0.98192358	3621.2996
898.47754	2.6601789	0.98425615	3628.0239
899.37842	2.6621308	0.98661	3633.0232
900.2793	2.6655271	0.98939228	3637.5017
901.18018	2.6674521	0.99223542	3628.0374
902.08105	2.6681318	0.99504948	3624.4856
902.98193	2.6735678	0.99770236	3623.6052
903.88281	2.6749511	1.0003443	3622.4209
904.78369	2.6794021	1.003141	3629.5042
905.68457	2.6796186	1.0057173	3623.2112
906.58545	2.6860008	1.0086255	3626.0303
907.48633	2.6889849	1.0112113	3617.9712
908.38721	2.6894727	1.0137844	3619.771
909.28809	2.6929624	1.0163536	3615.9319
910.18896	2.6959977	1.0187099	3612.3711
911.08984	2.6965387	1.0211327	3614.2515
911.99072	2.7023339	1.0237696	3619.6633
912.8916	2.7046504	1.0263252	3615.0806
913.79248	2.7049677	1.0286627	3612.0564
914.69336	2.7079532	1.0316583	3618.0125
915.59424	2.7122998	1.0342606	3610.5413
916.49512	2.7148662	1.0368923	3608.5264
917.396	2.7179992	1.0393181	3608.407
918.29688	2.7184331	1.0420003	3608.7227
919.19775	2.7225373	1.0445482	3608.1663
920.09863	2.7254229	1.0474154	3610.6521
920.99951	2.7259533	1.049866	3600.1235
921.90039	2.7288747	1.0520483	3597.3577
922.80127	2.7326069	1.0550152	3609.3982
923.70215	2.7350583	1.0579623	3602.4797
924.60303	2.7364032	1.0606749	3598.5203
925.50391	2.7416821	1.0634577	3599.3958
926.40479	2.7464299	1.06626	3596.9209
927.30566	2.7473893	1.0689521	3592.7283
928.20654	2.7489996	1.0716009	3592.0994
929.10742	2.7516727	1.074293	3592.7485
930.0083	2.755028	1.0771005	3592.1677
930.90918	2.7570233	1.0802218	3592.6443
931.81006	2.7588511	1.083616	3587.2031
932.71094	2.7637873	1.0864648	3583.8323
933.61182	2.7637658	1.0896147	3585.2563
934.5127	2.7658067	1.0925391	3583.3479
935.41357	2.770874	1.0950817	3580.2366
936.31445	2.7716274	1.0977149	3575.7354
937.21533	2.7748196	1.0999058	3569.3086
938.11621	2.7782371	1.1025041	3576.0645
939.01709	2.7823999	1.1054341	3574.7583
939.91797	2.7826624	1.1084914	3573.7332
940.81885	2.7849948	1.1119453	3570.6206
941.71973	2.7915444	1.1148636	3565.6487
942.62061	2.7906806	1.1175486	3566.1538
943.52148	2.7935252	1.1201016	3562.0747
944.42236	2.8000677	1.1229337	3566.3403
945.32324	2.8024952	1.1252573	3561.6765
946.22412	2.80373	1.1276901	3567.8237
947.125	2.8040073	1.1305864	3559.0452
948.02588	2.8075175	1.1334738	3555.4507
948.92676	2.8105767	1.1364238	3552.9873
949.82764	2.8146701	1.1390172	3551.6987
950.72852	2.8150039	1.1416318	3552.6436
951.62939	2.8202453	1.1445048	3546.582
952.53027	2.8216734	1.1467537	3546.4316
953.43115	2.8247066	1.1494935	3545.3027
954.33203	2.8272264	1.1526918	3542.9873
955.23291	2.8281798	1.155827	3540.2058
956.13379	2.8310413	1.1587725	3533.0532
957.03467	2.8367307	1.1615281	3529.7188
957.93555	2.84003	1.1643448	3533.0208
958.83643	2.8390546	1.1669756	3528.114
959.7373	2.8426237	1.169974	3529.0388
960.63818	2.846447	1.1728086	3522.8337
961.53906	2.8467443	1.1759236	3525.7786
962.43994	2.8517613	1.1791363	3523.9644
963.34082	2.855876	1.1821178	3517.7729
964.2417	2.8568826	1.1847554	3512.6711
965.14258	2.8571062	1.1874043	3510.8364
966.04346	2.8624821	1.1903144	3512.3867
966.94434	2.8651454	1.1934718	3512.4277
967.84521	2.8698452	1.1963609	3503.2095
968.74609	2.8720274	1.1993202	3510.8079
969.64697	2.8723791	1.202323	3501.5996
970.54785	2.8769624	1.2057158	3505.0764
971.44873	2.8780537	1.2087642	3494.5835
972.34961	2.8816938	1.2119458	3497.658
973.25049	2.882648	1.2152456	3492.4106
974.15137	2.8866727	1.2178655	3489.2898
975.05225	2.8897388	1.2206112	3479.4536
975.95313	2.8937044	1.2229536	3482.384
976.854	2.8954902	1.2255473	3486.7969
977.75488	2.896946	1.2288543	3483.4539
978.65576	2.9010611	1.2320516	3478.4331
979.55664	2.903317	1.2352679	3469.6116
980.45752	2.9058273	1.2377875	3470.7625
981.3584	2.9111392	1.2405188	3470.6829
982.25928	2.9117696	1.2436533	3464.2488
983.16016	2.9158273	1.2466258	3458.7192
984.06104	2.9157221	1.2497392	3463.3303
984.96191	2.9197984	1.2528967	3455.6772
985.86279	2.9221792	1.2560494	3447.354
986.76367	2.926764	1.2595875	3450.7949
987.66455	2.9307554	1.2627493	3446.1533
988.56543	2.9314277	1.26546	3440.2332
989.46631	2.9310853	1.268108	3434.3523
990.36719	2.9366667	1.2706263	3433.0425
991.26807	2.9375231	1.2735486	3433.8301
992.16895	2.9407775	1.2762643	3430.4753
993.06982	2.9437602	1.2791175	3426.5298
993.9707	2.948307	1.2819359	3424.1997
994.87158	2.9486063	1.2851486	3422.8584
995.77246	2.9507978	1.288141	3414.1902
996.67334	2.9548755	1.2906677	3407.5054
997.57422	2.95855	1.2931556	3407.9063
998.4751	2.9607387	1.2964619	3413.6687
999.37598	2.9613709	1.2994536	3404.5476
1000.2769	2.9686692	1.3022951	3402.6111
1001.1777	2.9671049	1.305539	3400.0405
1002.0786	2.9707742	1.3087068	3388.4275
1002.9795	2.9770181	1.3112521	3389.1143
1003.8804	2.9785883	1.3139442	3387.2437
1004.7813	2.9789186	1.3166666	3382.3037
1005.6821	2.9824271	1.3194563	3383.3804
1006.583	2.9848633	1.3217655	3374.3069
1007.4839	2.9886544	1.3238029	3369.9214
1008.3848	2.9845264	1.3262564	3369.8904
1009.2856	2.9947138	1.3290037	3369.3364
1010.1865	2.9950588	1.33206	3362.0564
1011.0874	2.9975605	1.3344526	3354.8005
1011.9883	3.0027387	1.3370234	3360.2998
1012.8892	3.0039136	1.3399706	3354.2319
1013.79	3.0040445	1.3435481	3352.48
1014.6909	3.0101767	1.3470647	3344.4248
1015.5918	3.0092287	1.3501247	3336.1104
1016.4927	3.0137725	1.3535699	3333.9614
1017.3936	3.0164397	1.3566389	3330.2952
1018.2944	3.0200064	1.3595909	3328.8975
1019.1953	3.0240996	1.3624915	3325.2104
1020.0962	3.0265052	1.3655883	3322.2439
1020.9971	3.0238595	1.3680238	3307.2954
1021.8979	3.0289557	1.3709959	3312.9744
1022.7988	3.0322957	1.3744773	3311.8442
1023.6997	3.036809	1.3781031	3302.1069
1024.6006	3.035203	1.3810732	3293.2368
1025.5015	3.0430908	1.3840629	3293.1238
1026.4023	3.0414419	1.3867508	3288.2922
1027.3032	3.046916	1.3899795	3291.4365
1028.2041	3.050854	1.3931224	3281.6794
1029.105	3.0503547	1.3963836	3275.3135
1030.0059	3.0554988	1.3999941	3277.0754
1030.9067	3.0563257	1.4027886	3260.8059
1031.8076	3.0597138	1.4058032	3257.9507
1032.7085	3.0650938	1.4087706	3257.0938
1033.6094	3.0647066	1.4114206	3256.658
1034.5103	3.0692635	1.4145095	3252.125
1035.4111	3.0693452	1.4177387	3241.3435
1036.312	3.0765023	1.4209219	3239.2031
1037.2129	3.0774899	1.4236594	3233.5569
1038.1138	3.0800829	1.4268824	3230.0913
1039.0146	3.084126	1.4301282	3229.3804
1039.9155	3.0846794	1.4333512	3220.6035
1040.8164	3.0879457	1.4364566	3211.7312
1041.7173	3.0913391	1.4394817	3212.2576
1042.6182	3.0934641	1.4425757	3202.0618
1043.519	3.09619	1.4460703	3204.762
1044.4199	3.0973911	1.4495004	3192.666
1045.3208	3.1002626	1.4528378	3183.8696
1046.2217	3.104497	1.4560987	3179.3176
1047.1226	3.1067045	1.4591433	3172.6536
1048.0234	3.1089087	1.4618158	3172.9456
1048.9243	3.1125782	1.4648529	3164.2502
1049.8252	3.1127477	1.4683301	3160.2859
1050.7261	3.1175785	1.4722517	3156.9265
1051.627	3.1184144	1.475656	3147.4456
1052.5278	3.1229367	1.4786608	3135.9524
1053.4287	3.1255746	1.4818521	3130.9514
1054.3296	3.1303654	1.4849597	3132.6448
1055.2305	3.1298392	1.4879233	3120.4761
1056.1313	3.1362557	1.4909512	3120.3779
1057.0322	3.1341822	1.4940441	3105.7783
1057.9331	3.1386001	1.496941	3100.1677
1058.834	3.1442494	1.5003575	3100.2319
1059.7349	3.1441472	1.5037173	3099.4246
1060.6357	3.1462295	1.5072446	3084.1633
1061.5366	3.1478176	1.5107043	3083.9302
1062.4375	3.1537135	1.5140061	3074.0842
1063.3384	3.1558564	1.5170512	3066.5071
1064.2393	3.1576154	1.5198311	3065.8901
1065.1401	3.1578243	1.5232649	3060.0613
1066.041	3.1606076	1.5269487	3042.3049
1066.9419	3.1647844	1.5300782	3036.1548
1067.8428	3.1702909	1.5331253	3033.8391
1068.7437	3.1730804	1.5360637	3024
1069.6445	3.1735654	1.5387386	3021.2412
1070.5454	3.1771533	1.5416307	3016.1135
1071.4463	3.1802945	1.5454012	3008.3782
1072.3472	3.181895	1.5485849	3001.7893
1073.248	3.185755	1.5515431	2996.7627
1074.1489	3.1859725	1.5544441	2989.168
1075.0498	3.1916649	1.5579482	2980.9685
1075.9507	3.1952159	1.5612702	2972.958
1076.8516	3.1946218	1.5644116	2966.8374
1077.7524	3.1980591	1.5684644	2960.853
1078.6533	3.1983416	1.5720925	2943.8091
1079.5542	3.2067351	1.5761126	2938.8889
1080.4551	3.2089615	1.5792432	2930.5186
1081.356	3.2114162	1.5826502	2915.9934
1082.2568	3.210788	1.5859102	2906.5298
1083.1577	3.2124312	1.589586	2896.2261
1084.0586	3.2180479	1.5929981	2893.6487
1084.9595	3.2175999	1.5971379	2881.4094
1085.8604	3.219753	1.6010242	2861.6025
1086.7612	3.2258551	1.6047521	2858.7532
1087.6621	3.2312427	1.6080854	2852.3311
1088.563	3.2296546	1.6116312	2836.8567
1089.4639	3.2356553	1.6157085	2831.1213
1090.3647	3.2383113	1.6202472	2812.3987
1091.2656	3.2407379	1.624018	2797.2173
1092.1665	3.2405531	1.6278708	2791.9976
1093.0674	3.2497051	1.6322961	2778.2993
1093.9683	3.2477014	1.63597	2760.5745
1094.8691	3.2500775	1.6410835	2725.9773
1095.77	3.2536798	1.6483833	2666.7607
1095.9702	3.2571797	1.652018	2640.8159