File: datasets/am_bench_2022/raw_data/30-XY.01-3/specimen.dat
MTS793|MPT|ENU|1|2|.|/|:|1|0|0|A

Operator Information						Time:	38.017334	Sec	10/18/2021 11:02:02 AM
Operator	Nick Derimow
Project	AM Bench 2022 mini-tensile challenge
Specimen ID	30-XY.01-3
Material	PBF-L Inconel 625
Specimen Width	2.55	mm
Specimen Thickness	1.52	mm
Notes
Operator Information End

Data Acquisition						Time:	1039.0117	Sec	10/18/2021 11:18:43 AM
Time	Axial Displacement	Axial Extensometer	Axial Force
Sec	mm	mm	N
38.131592	-0.0021653783	-2.8825887e-05	47.199844
39.132568	0.0022300964	5.0215924e-05	64.035248
40.133545	0.0023124625	0.00020858743	74.887558
41.134521	0.0066999467	0.00012127621	86.851021
42.135498	0.012538468	0.00023504601	100.04523
43.136475	0.013182185	0.00026189082	117.18014
44.137451	0.017157683	0.00047424188	131.88768
45.138428	0.020510059	0.00043802534	147.73117
46.139404	0.019563718	0.00053501973	160.30893
47.140381	0.028972568	0.00061804871	180.19928
48.141357	0.02960691	0.00059558445	190.78596
49.142334	0.033068951	0.00077787391	216.93961
50.143311	0.030525027	0.00077570614	235.60895
51.144287	0.037169334	0.00094661285	254.9651
52.145264	0.038406875	0.00099937536	276.91562
53.14624	0.042544186	0.001040246	290.37268
54.147217	0.047444716	0.0011774563	311.56705
55.148193	0.050062764	0.0013633642	336.63263
56.14917	0.05306913	0.0014342186	352.69467
57.150146	0.054878879	0.0014378943	374.78009
58.151123	0.056856487	0.0015284796	394.57513
59.1521	0.062375173	0.0017294142	421.508
60.153076	0.061705999	0.0017695677	442.73547
61.154053	0.069004729	0.0018238884	469.0192
62.155029	0.069848672	0.0019127025	491.02689
63.156006	0.074424043	0.0020350469	518.61108
64.156982	0.075460993	0.0022424508	542.71167
65.157959	0.081042536	0.0022961488	568.16638
66.158936	0.077810638	0.0023942075	589.30048
67.159912	0.08389359	0.0025128261	617.68195
68.160889	0.088531859	0.0025891878	644.98871
69.161865	0.091803096	0.0027691866	669.31067
70.162842	0.092451371	0.0028090216	699.98279
71.163818	0.09571667	0.0029828153	722.55042
72.164795	0.098795772	0.0030411477	749.05267
73.165771	0.10114275	0.0031986577	776.61047
74.166748	0.10281322	0.0032930211	800.86707
75.167725	0.10409374	0.0033529231	831.10266
76.168701	0.11201436	0.0035096544	860.71387
77.169678	0.11511001	0.0036180653	887.47156
78.170654	0.1186095	0.0038362753	912.9353
79.171631	0.12318569	0.0038927677	945.89856
80.172607	0.12074216	0.0040864646	971.32593
81.173584	0.12643977	0.004173154	1000.6473
82.174561	0.12709275	0.0042563537	1017.1115
83.175537	0.13365674	0.0043037576	1051.7789
84.176514	0.1358775	0.0045015039	1084.2758
85.17749	0.13758405	0.0046442123	1109.8927
86.178467	0.14059466	0.0047952808	1138.2777
87.179443	0.14333957	0.004939273	1171.5571
88.18042	0.14893608	0.0050371895	1199.7897
89.181396	0.15141915	0.0050598695	1218.7661
90.182373	0.15630288	0.0052277562	1246.1158
91.18335	0.15585642	0.0053137438	1275.3137
92.184326	0.16094683	0.0054935133	1307.6079
93.185303	0.16144697	0.0055381702	1329.0521
94.186279	0.16213131	0.0055948757	1347.0681
95.187256	0.1683833	0.0057860781	1384.4702
96.188232	0.17004395	0.0060294773	1419.1931
97.189209	0.17177789	0.0060669468	1433.0012
98.190186	0.17803192	0.0061550406	1472.2269
99.191162	0.17961019	0.0064080656	1493.376
100.19214	0.18308243	0.0064788382	1524.3472
101.19312	0.18850437	0.0066102459	1557.9148
102.19409	0.19003408	0.0067228363	1575.896
103.19507	0.19205594	0.0068402747	1593.0411
104.19604	0.19756049	0.0069359294	1632.0883
105.19702	0.20028651	0.0071354788	1660.0942
106.198	0.20257448	0.007296856	1685.8463
107.19897	0.20697534	0.0073964205	1715.6364
108.19995	0.20720091	0.0074693197	1733.0242
109.20093	0.20946737	0.007668722	1765.5533
110.2019	0.21530379	0.0078021367	1794.4998
111.20288	0.21699968	0.0077802828	1811.8195
112.20386	0.22201802	0.0079928348	1837.796
113.20483	0.22394563	0.0080747493	1858.0552
114.20581	0.22678065	0.0080636069	1871.6403
115.20679	0.23050492	0.0082205925	1898.5757
116.20776	0.23417	0.0084053325	1918.7731
117.20874	0.23652947	0.0084317392	1945.2806
118.20972	0.2383966	0.0086610457	1971.4589
119.21069	0.24032359	0.0086562755	1987.7823
120.21167	0.24339794	0.0087714521	2014.9366
121.21265	0.2418133	0.0088709136	2030.0391
122.21362	0.24850786	0.008955704	2053.8945
123.2146	0.25286257	0.0091893431	2079.6194
124.21558	0.25393414	0.009196301	2087.1912
125.21655	0.25607827	0.0094077997	2117.5022
126.21753	0.2619383	0.0095253931	2137.1279
127.21851	0.26303837	0.0095454315	2140.655
128.21948	0.2700021	0.009659132	2163.9814
129.22046	0.26865944	0.0097253518	2179.9988
130.22144	0.27549067	0.009872471	2201.8633
131.22241	0.27682841	0.0099251801	2214.6602
132.22339	0.27931163	0.01006114	2231.7202
133.22437	0.28262404	0.010117341	2240.2463
134.22534	0.28878078	0.010267884	2262.7544
135.22632	0.28579515	0.010404611	2280.6548
136.22729	0.29234049	0.010517193	2291.1467
137.22827	0.29558918	0.010564432	2308.145
138.22925	0.30112064	0.010669397	2321.5344
139.23022	0.30100775	0.010807414	2331.8564
140.2312	0.30272242	0.010927868	2342.3931
141.23218	0.30837429	0.010995391	2354.9712
142.23315	0.31172767	0.011102597	2370.8599
143.23413	0.31114107	0.011187015	2380.02
144.23511	0.31229955	0.01124674	2395.4756
145.23608	0.32016909	0.011516189	2409.698
146.23706	0.32098579	0.011561793	2416.8357
147.23804	0.32526734	0.011661304	2427.5901
148.23901	0.33000705	0.011845096	2440.166
149.23999	0.33090201	0.011839967	2451.1799
150.24097	0.3326138	0.011920311	2457.4956
151.24194	0.33529049	0.012093799	2468.0342
152.24292	0.33924627	0.012230514	2487.3601
153.2439	0.34258965	0.012391371	2489.4189
154.24487	0.34634769	0.012449941	2506.3032
155.24585	0.34693798	0.012637991	2521.2356
156.24683	0.35329202	0.012665495	2524.322
157.2478	0.35385936	0.012839196	2532.0508
158.24878	0.35768074	0.012899999	2539.3862
159.24976	0.36276254	0.013133576	2551.9163
160.25073	0.3633596	0.013263967	2559.5435
161.25171	0.37051004	0.013409057	2577.4282
162.25269	0.37297112	0.01352847	2586.8096
163.25366	0.37468728	0.013744373	2593.03
164.25464	0.37584263	0.013908641	2593.2021
165.25562	0.377727	0.013927547	2610.718
166.25659	0.38419661	0.014196464	2622.1836
167.25757	0.38603339	0.014338059	2633.4919
168.25854	0.38958657	0.014633337	2638.7456
169.25952	0.39279023	0.014876326	2646.7917
170.2605	0.39432609	0.014930941	2648.8745
171.26147	0.39738384	0.015137854	2657.7363
172.26245	0.4001365	0.015318476	2662.2241
173.26343	0.40354624	0.01548357	2675.2124
174.2644	0.4076834	0.015896367	2692.0007
175.26538	0.40872979	0.015959855	2695.2974
176.26636	0.41331923	0.016201714	2701.8486
177.26733	0.41690293	0.016545057	2707.1333
178.26831	0.41930526	0.016795145	2715.4043
179.26929	0.42252985	0.017071566	2721.0903
180.27026	0.42544991	0.01724687	2726.3508
181.27124	0.42950541	0.017578663	2745.3333
182.27222	0.43244907	0.017932929	2747.6963
183.27319	0.43446684	0.01832556	2748.1904
184.27417	0.43403557	0.018600857	2750.7649
185.27515	0.4389914	0.019012069	2759.4888
186.27612	0.44353762	0.019270593	2767.511
187.2771	0.44735146	0.019772697	2779.9087
188.27808	0.450468	0.020141935	2779.3828
189.27905	0.4526841	0.020483386	2780.689
190.28003	0.4559449	0.021035036	2794.3704
191.28101	0.46010271	0.021494061	2797.8579
192.28198	0.45976874	0.022014178	2802.8279
193.28296	0.46363723	0.022518219	2817.2771
194.28394	0.46725065	0.023066843	2814.8601
195.28491	0.47076303	0.023552027	2818.3977
196.28589	0.47357905	0.024252918	2823.2671
197.28687	0.47502947	0.024727555	2834.1624
198.28784	0.47697219	0.025383253	2837.0483
199.28882	0.48278183	0.026133219	2838.6516
200.28979	0.48582217	0.026658442	2846.9998
201.29077	0.49040389	0.027576424	2857.8853
202.29175	0.49230301	0.028338833	2860.9663
203.29272	0.49315265	0.029141614	2867.386
204.2937	0.49844635	0.030048557	2872.2842
205.29468	0.50098866	0.030878898	2872.562
206.29565	0.50060225	0.031817764	2873.6956
207.29663	0.50519991	0.032699194	2879.6396
208.29761	0.50949073	0.033463035	2886.2161
209.29858	0.51509339	0.03440132	2885.9617
210.29956	0.51557058	0.035345584	2891.7993
211.30054	0.51756823	0.036317993	2898.2637
212.30151	0.52142072	0.037180658	2895.2549
213.30249	0.52211821	0.038144916	2906.4104
214.30347	0.52765656	0.039187618	2906.6963
215.30444	0.52683884	0.040192835	2905.4185
216.30542	0.53273326	0.041134208	2910.3745
217.3064	0.53581929	0.042021602	2908.6086
218.30737	0.53566808	0.043126106	2918.4011
219.30835	0.5422008	0.044241872	2915.1704
220.30933	0.54458404	0.045314226	2920.3123
221.3103	0.54893297	0.046164621	2927.3911
222.31128	0.54929727	0.047161419	2925.0447
223.31226	0.5552913	0.048189007	2932.7222
224.31323	0.55901206	0.049323481	2936.6594
225.31421	0.56046653	0.050239529	2943.0303
226.31519	0.56450737	0.051263127	2944.2361
227.31616	0.56761372	0.052407883	2949.3594
228.31714	0.56813145	0.053646445	2946.3237
229.31812	0.57134759	0.054774307	2950.251
230.31909	0.5723294	0.056088291	2952.0474
231.32007	0.57701546	0.057242319	2956.0969
232.32104	0.57967341	0.058279015	2959.0613
233.32202	0.58713037	0.059359971	2960.5906
234.323	0.58429694	0.060427196	2958.8445
235.32397	0.58966917	0.061426137	2969.8359
236.32495	0.59118754	0.062615439	2971.8574
237.32593	0.59495938	0.063867681	2973.4731
238.3269	0.59829456	0.065017462	2976.3945
239.32788	0.60102898	0.066176564	2975.969
240.32886	0.60672468	0.06727545	2977.0339
241.32983	0.60765368	0.068335518	2973.8188
242.33081	0.61280066	0.069360875	2987.2485
243.33179	0.61680502	0.070565835	2991.2188
244.33276	0.61544943	0.071788155	2986.1804
245.33374	0.62089765	0.07308545	2990.3586
246.33472	0.6233328	0.074339703	2994.0417
247.33569	0.62720191	0.075389251	2979.3462
248.33667	0.62928003	0.076562002	2997.9895
249.33765	0.6324634	0.077749334	2999.135
250.33862	0.63297212	0.079024822	3000.3977
251.3396	0.63798064	0.080431499	3004.5935
252.34058	0.63948435	0.081711389	3002.1819
253.34155	0.64577603	0.082744472	3002.5847
254.34253	0.64544183	0.083734617	3003.25
255.34351	0.65018201	0.084883608	3008.0854
256.34448	0.65325367	0.085924655	3007.5681
257.34546	0.65301538	0.087173797	3011.0591
258.34644	0.66008854	0.088415377	3013.0984
259.34741	0.66306847	0.089397907	3012.6973
260.34839	0.66578609	0.090457842	3018.7068
261.34937	0.66804802	0.091632113	3017.5059
262.35034	0.67199171	0.092721201	3026.2065
263.35132	0.67284	0.09403006	3026.2754
264.35229	0.67880023	0.095364869	3030.1013
265.35327	0.68245333	0.096493244	3027.9509
266.35425	0.6824919	0.09777192	3036.4265
267.35522	0.68577743	0.099097028	3033.4641
268.3562	0.68975705	0.10031205	3033.6863
269.35718	0.69518882	0.10160506	3035.2898
270.35815	0.69746906	0.10292078	3044.6216
271.35913	0.69787598	0.10407118	3036.9592
272.36011	0.69926608	0.10531854	3045.0559
273.36108	0.70181328	0.10640791	3037.8625
274.36206	0.70600122	0.10785703	3048.5413
275.36304	0.71006966	0.10934599	3049.8274
276.36401	0.71267176	0.11050587	3042.5405
277.36499	0.71435469	0.11176917	3050.0991
278.36597	0.71986216	0.11285949	3057.4978
279.36694	0.72157437	0.11415964	3050.9897
280.36792	0.72569364	0.11527705	3051.4067
281.3689	0.72462255	0.11644688	3053.408
282.36987	0.73131317	0.11776579	3057.1707
283.37085	0.73205835	0.11873613	3058.5562
284.37183	0.73961914	0.11998251	3062.2209
285.3728	0.74243778	0.12112589	3068.2961
286.37378	0.7453593	0.12225891	3065.3867
287.37476	0.74706662	0.12351491	3071.2681
288.37573	0.7480948	0.12490153	3071.9243
289.37671	0.75700271	0.12600307	3072.1389
290.37769	0.75691074	0.12705579	3066.2419
291.37866	0.75717402	0.12817712	3069.6001
292.37964	0.76017952	0.12939325	3077.6375
293.38062	0.7649399	0.13060847	3080.6243
294.38159	0.76660395	0.13172448	3077.0493
295.38257	0.77049565	0.13280949	3077.2573
296.38354	0.77169549	0.13389726	3074.9028
297.38452	0.77573442	0.13508335	3086.6077
298.3855	0.77939945	0.13647795	3089.7998
299.38647	0.78131664	0.13771822	3085.9189
300.38745	0.78746289	0.13911757	3087.9424
301.38843	0.78759217	0.14029802	3091.6667
302.3894	0.79259467	0.14161156	3093.1951
303.39038	0.79758525	0.14295577	3098.4827
304.39136	0.79733342	0.14392823	3093.4905
305.39233	0.7981624	0.14499618	3088.656
306.39331	0.79950786	0.14623496	3094.4265
307.39429	0.80834699	0.14751433	3101.5659
308.39526	0.80921143	0.14859602	3101.3792
309.39624	0.81019795	0.15001115	3104.2297
310.39722	0.81663412	0.15136749	3107.1851
311.39819	0.8202346	0.1526185	3107.4277
312.39917	0.82173544	0.15395515	3112.0693
313.40015	0.82589197	0.15537637	3109.7339
314.40112	0.82897532	0.15653427	3106.0535
315.4021	0.83302063	0.15760398	3113.0803
316.40308	0.83544779	0.1587587	3114.1594
317.40405	0.83765918	0.15999715	3119.4839
318.40503	0.83794397	0.161107	3115.9185
319.40601	0.84175247	0.16221404	3114.7864
320.40698	0.84373248	0.16349556	3119.6272
321.40796	0.84444445	0.16454111	3113.0378
322.40894	0.84968919	0.16575977	3121.7786
323.40991	0.85385621	0.16720624	3131.6826
324.41089	0.85982478	0.1685359	3129.6167
325.41187	0.86062837	0.16999739	3126.3682
326.41284	0.86344033	0.17122553	3124.2478
327.41382	0.86676747	0.17217436	3124.1973
328.41479	0.86817014	0.17294642	3118.7786
329.41577	0.8705743	0.17398813	3126.3459
330.41675	0.87630588	0.17536548	3141.1582
331.41772	0.87897885	0.17678934	3134.1614
332.4187	0.8819344	0.17803706	3139.8142
333.41968	0.88462579	0.17925604	3140.9944
334.42065	0.8927111	0.18053168	3148.9998
335.42163	0.88864589	0.18156739	3137.0703
336.42261	0.89433974	0.18271758	3144.1292
337.42358	0.89658636	0.18393511	3141.3276
338.42456	0.8984285	0.18516989	3139.9033
339.42554	0.90229475	0.18629605	3145.6721
340.42651	0.90615708	0.18753934	3147.0161
341.42749	0.90657854	0.18872346	3147.0935
342.42847	0.91386604	0.18995772	3156.8401
343.42944	0.91672999	0.19128871	3153.6104
344.43042	0.91742516	0.19234721	3150.1362
345.4314	0.92039442	0.19353409	3152.3989
346.43237	0.92493802	0.19475652	3153.8794
347.43335	0.92577541	0.19614513	3160.0552
348.43433	0.92806089	0.1975778	3161.8704
349.4353	0.93230194	0.19869456	3159.1543
350.43628	0.93647444	0.20000324	3164.0037
351.43726	0.93856227	0.20125584	3163.0308
352.43823	0.94150037	0.20244393	3167.5181
353.43921	0.94460696	0.20348057	3158.9612
354.44019	0.94613069	0.2046435	3168.396
355.44116	0.95142031	0.20608677	3168.6936
356.44214	0.95194846	0.20759015	3169.5674
357.44312	0.95757371	0.208921	3169.2058
358.44409	0.96273285	0.21015742	3173.0154
359.44507	0.96287668	0.21138133	3179.4458
360.44604	0.96696723	0.21235663	3169.5068
361.44702	0.96719319	0.21351324	3175.3999
362.448	0.9722411	0.21469459	3176.3013
363.44897	0.97617495	0.21576938	3177.3972
364.44995	0.97546071	0.21677448	3172.7651
365.45093	0.97989714	0.21780798	3179.1001
366.4519	0.98174316	0.21897084	3180.678
367.45288	0.98669839	0.22018676	3181.8
368.45386	0.99200791	0.22118677	3183.5515
369.45483	0.99387974	0.22230956	3190.7275
370.45581	0.9970625	0.22357251	3187.5596
371.45679	0.99919438	0.2249157	3189.3735
372.45776	0.99880368	0.22623023	3193.0286
373.45874	1.003952	0.22751851	3193.3059
374.45972	1.0083358	0.22871824	3193.9141
375.46069	1.0092968	0.22985633	3188.2036
376.46167	1.0123065	0.23108588	3194.3879
377.46265	1.0158846	0.23240237	3196.5549
378.46362	1.019102	0.23352554	3194.2991
379.4646	1.0241402	0.23469351	3203.8491
380.46558	1.025347	0.23592827	3199.5574
381.46655	1.0274278	0.23732655	3204.9138
382.46753	1.0307271	0.23858996	3206.4668
383.46851	1.0345659	0.23988797	3206.0815
384.46948	1.0359511	0.24094719	3205.4238
385.47046	1.0389057	0.2420518	3203.447
386.47144	1.0440326	0.24326657	3206.8621
387.47241	1.0459487	0.24432379	3211.8708
388.47339	1.0509301	0.24553558	3215.3989
389.47437	1.0482504	0.24684864	3206.8154
390.47534	1.053862	0.2480209	3211.7358
391.47632	1.0568519	0.24933425	3213.6504
392.47729	1.0629084	0.25046876	3211.6494
393.47827	1.0646074	0.2515212	3214.1128
394.47925	1.0671579	0.25284818	3218.2778
395.48022	1.0728043	0.25396821	3222.2661
396.4812	1.0730975	0.25539887	3220.9041
397.48218	1.0777872	0.2564452	3220.6926
398.48315	1.078694	0.25762081	3219.7996
399.48413	1.0814463	0.2586363	3218.0632
400.48511	1.0862186	0.25999102	3224.9734
401.48608	1.0872891	0.26119158	3227.7544
402.48706	1.0915532	0.26238406	3223.4785
403.48804	1.0919902	0.26350698	3224.792
404.48901	1.096959	0.26469719	3224.8672
405.48999	1.0998027	0.26597562	3229.2083
406.49097	1.1012973	0.26712617	3228.2368
407.49194	1.1071727	0.26822612	3232.4087
408.49292	1.1105103	0.26924804	3234.6716
409.4939	1.1147813	0.27047357	3235.7202
410.49487	1.1171682	0.27165964	3235.8413
411.49585	1.1193688	0.27288234	3241.7231
412.49683	1.1202583	0.274064	3244.6797
413.4978	1.1229141	0.27532759	3236.7168
414.49878	1.1287833	0.27669731	3242.9614
415.49976	1.1302774	0.27786201	3242.7378
416.50073	1.136202	0.2790795	3246.1069
417.50171	1.1357676	0.28028268	3245.5972
418.50269	1.1386274	0.28157687	3246.082
419.50366	1.1440221	0.28304639	3244.2422
420.50464	1.1466937	0.28422204	3246.9128
421.50562	1.1487719	0.28540522	3246.3508
422.50659	1.1525875	0.28641415	3250.8535
423.50757	1.1556299	0.28759521	3254.4812
424.50854	1.1559101	0.28878754	3246.6997
425.50952	1.1608303	0.29009262	3254.0708
426.5105	1.1637914	0.29140538	3255.1565
427.51147	1.1647415	0.29272532	3258.4448
428.51245	1.1711433	0.293825	3255.6101
429.51343	1.171232	0.29487595	3254.5049
430.5144	1.1774983	0.2958788	3263.9961
431.51538	1.179291	0.29706341	3260.2434
432.51636	1.1834062	0.29811656	3265.7583
433.51733	1.1851286	0.29930097	3262.4316
434.51831	1.1873624	0.30052325	3263.4236
435.51929	1.1917765	0.30175197	3259.8252
436.52026	1.1942285	0.30292085	3262.7192
437.52124	1.1959299	0.30406278	3268.1086
438.52222	1.1994271	0.3054781	3269.5017
439.52319	1.2014699	0.30666247	3269.9937
440.52417	1.2064013	0.30774331	3270.4426
441.52515	1.2089192	0.3089222	3275.6819
442.52612	1.2105265	0.31020686	3273.8901
443.5271	1.2133764	0.31140986	3270.8118
444.52808	1.2164941	0.31267536	3279.7756
445.52905	1.2202878	0.31399181	3278.8005
446.53003	1.2243979	0.31520659	3276.29
447.53101	1.2272238	0.3163653	3281.3137
448.53198	1.2307138	0.3174409	3279.562
449.53296	1.2333089	0.31852591	3275.1968
450.53394	1.2381725	0.319536	3285.5562
451.53491	1.2381908	0.32073003	3283.437
452.53589	1.2416619	0.3218261	3286.446
453.53687	1.2456243	0.32334784	3285.5242
454.53784	1.2488253	0.32447806	3284.9961
455.53882	1.2524101	0.32552749	3284.8721
456.53979	1.2541939	0.32654312	3286.5347
457.54077	1.2553269	0.32791311	3297.0647
458.54175	1.2594908	0.329142	3289.082
459.54272	1.2651213	0.33029863	3290.1714
460.5437	1.2676265	0.33126026	3286.9663
461.54468	1.2672812	0.33246124	3292.6223
462.54565	1.2723974	0.33380622	3302.4446
463.54663	1.2755053	0.3350682	3297.0076
464.54761	1.2790675	0.3362	3297.239
465.54858	1.2821913	0.33738232	3305.2061
466.54956	1.2824609	0.33852279	3296.9751
467.55054	1.290956	0.33974302	3302.1338
468.55151	1.2899379	0.34092668	3299.8179
469.55249	1.2937732	0.34212139	3303.9543
470.55347	1.2925721	0.34330007	3298.2493
471.55444	1.2975383	0.34432375	3296.7202
472.55542	1.3040856	0.34540975	3310.0264
473.5564	1.3051825	0.34665453	3311.104
474.55737	1.3083152	0.34778267	3306.8679
475.55835	1.3076988	0.34904489	3310.8403
476.55933	1.3126831	0.35022417	3302.7844
477.5603	1.3185797	0.35125217	3308.5764
478.56128	1.319688	0.35237893	3312.8687
479.56226	1.3210158	0.35365072	3315.8599
480.56323	1.3247774	0.35503924	3319.1348
481.56421	1.3291051	0.35624003	3315.8843
482.56519	1.3326479	0.35741317	3322.3914
483.56616	1.3374308	0.3587614	3324.1851
484.56714	1.3369129	0.35981971	3320.8625
485.56812	1.343207	0.36106434	3318.8843
486.56909	1.3436263	0.36210257	3317.0762
487.57007	1.3491606	0.36315218	3324.8181
488.57104	1.3493226	0.36458308	3326.6101
489.57202	1.3520886	0.3658694	3330.1016
490.573	1.3560497	0.36726558	3327.6797
491.57397	1.3604268	0.3684293	3327.561
492.57495	1.3635091	0.36956674	3325.3933
493.57593	1.366356	0.37070209	3325.2278
494.5769	1.3664111	0.37168634	3324.2908
495.57788	1.3715098	0.37287191	3335.5632
496.57886	1.3749982	0.3740283	3333.3093
497.57983	1.3764771	0.3752436	3332.7009
498.58081	1.379676	0.37653679	3336.759
499.58179	1.3840262	0.37766051	3334.78
500.58276	1.3857065	0.37893519	3333.3372
501.58374	1.3903227	0.38022044	3338.155
502.58472	1.3920574	0.38149506	3334.9104
503.58569	1.3961145	0.38270611	3334.762
504.58667	1.3997793	0.38386109	3339.2373
505.58765	1.401392	0.38490874	3337.0908
506.58862	1.4025413	0.38602057	3337.9893
507.5896	1.4047509	0.38721222	3341.9263
508.59058	1.4134429	0.38849968	3344.1543
509.59155	1.4127389	0.38961226	3333.1729
510.59253	1.418952	0.39054072	3343.2859
511.59351	1.4191211	0.39176238	3350.9099
512.59448	1.422839	0.39300442	3342.6282
513.59546	1.428478	0.39417118	3347.4595
514.59644	1.4269987	0.39549536	3348.0964
515.59741	1.4325519	0.39689696	3353.6099
516.59839	1.4320792	0.39801857	3346.988
517.59937	1.4382738	0.39921957	3348.7673
518.60034	1.4399606	0.40019068	3344.8464
519.60132	1.4465939	0.40124473	3353.8538
520.60229	1.4458612	0.402468	3352.697
521.60327	1.4509777	0.40381879	3360.2327
522.60425	1.4506963	0.40493497	3353.3323
523.60522	1.4563241	0.40620175	3355.4866
524.6062	1.4589155	0.40740651	3358.9028
525.60718	1.4618831	0.40864557	3361.136
526.60815	1.465221	0.40991825	3360.0066
527.60913	1.4665506	0.41125041	3360.3506
528.61011	1.4710119	0.4124108	3360.2009
529.61108	1.472616	0.41368812	3361.0991
530.61206	1.4760941	0.41479847	3358.1692
531.61304	1.4808347	0.41596735	3358.6936
532.61401	1.482417	0.41685244	3358.3586
533.61499	1.4837289	0.41815862	3364.5032
534.61597	1.4892863	0.41926467	3368.542
535.61694	1.4906228	0.42058063	3370.1401
536.61792	1.492655	0.42190081	3364.2341
537.6189	1.497963	0.42296717	3369.8569
538.61987	1.5004574	0.42409366	3370.8125
539.62085	1.5018351	0.42534381	3371.0635
540.62183	1.5046887	0.42629787	3364.9277
541.6228	1.5123601	0.42722043	3372.2051
542.62378	1.5107529	0.42825824	3365.0515
543.62476	1.513787	0.42957404	3372.4758
544.62573	1.5183028	0.43090326	3380.5068
545.62671	1.5210662	0.43215317	3382.1912
546.62769	1.524743	0.43357483	3380.0425
547.62866	1.5270168	0.43480071	3377.5151
548.62964	1.5286263	0.43606707	3376.4417
549.63062	1.5336971	0.43722755	3377.175
550.63159	1.536213	0.43831617	3379.5422
551.63257	1.54001	0.4397653	3386.6008
552.63354	1.5408506	0.44100827	3383.6375
553.63452	1.5436691	0.44209373	3379.4763
554.6355	1.5453125	0.44331574	3383.4014
555.63647	1.5533034	0.44471467	3387.1873
556.63745	1.5526457	0.44580334	3384.9556
557.63843	1.5554161	0.44709381	3389.0396
558.6394	1.562045	0.44830346	3391.0581
559.64038	1.5634381	0.44960773	3390.866
560.64136	1.5658835	0.45075858	3383.3157
561.64233	1.5689574	0.45198128	3390.5208
562.64331	1.5728219	0.45331502	3389.7993
563.64429	1.574688	0.45463032	3398.5762
564.64526	1.5767084	0.45592302	3389.7593
565.64624	1.5825074	0.45694351	3389.9614
566.64722	1.5847728	0.45792845	3388.0657
567.64819	1.5859021	0.45896372	3399.6802
568.64917	1.5903507	0.46012825	3395.894
569.65015	1.5958126	0.461193	3404.0552
570.65112	1.5974501	0.46258375	3402.2688
571.6521	1.6016051	0.46384323	3404.2119
572.65308	1.6007633	0.46501097	3396.8916
573.65405	1.6051041	0.46607992	3393.5901
574.65503	1.6076577	0.4671703	3402.1086
575.65601	1.6102622	0.46844435	3401.8611
576.65698	1.617433	0.46955439	3405.1233
577.65796	1.6171768	0.47061169	3403.6082
578.65894	1.6187036	0.47187763	3402.4563
579.65991	1.6230772	0.47327495	3415.4443
580.66089	1.627453	0.47438735	3403.5154
581.66187	1.6274579	0.4755275	3406.7119
582.66284	1.6334209	0.47678691	3404.363
583.66382	1.6345736	0.47793403	3405.9421
584.66479	1.6361607	0.47893384	3405.812
585.66577	1.6436986	0.48025513	3418.7705
586.66675	1.6442666	0.48152354	3409.5166
587.66772	1.6465806	0.48266309	3408.0027
588.6687	1.6516193	0.48408589	3415.4204
589.66968	1.6527305	0.48520216	3415.5117
590.67065	1.6553591	0.48672175	3419.427
591.67163	1.6586485	0.48794264	3415.8027
592.67261	1.6637886	0.48914859	3423.407
593.67358	1.6666703	0.4902879	3416.2231
594.67456	1.6683588	0.49141014	3416.042
595.67554	1.6717532	0.49276146	3428.415
596.67651	1.6736242	0.49407992	3422.1294
597.67749	1.6760048	0.49528781	3417.2986
598.67847	1.6810213	0.49673778	3425.1938
599.67944	1.680837	0.49797705	3416.8384
600.68042	1.6852604	0.4991996	3418.615
601.6814	1.6916579	0.50058031	3428.8926
602.68237	1.6918492	0.5016095	3421.0007
603.68335	1.6953918	0.5028978	3428.2622
604.68433	1.7018064	0.504215	3428.79
605.6853	1.7019234	0.5056091	3427.7034
606.68628	1.70516	0.50684839	3430.5332
607.68726	1.7035847	0.50809419	3422.312
608.68823	1.7115159	0.50904953	3427.6243
609.68921	1.7146331	0.51001704	3424.1919
610.69019	1.7152629	0.51107806	3427.4058
611.69116	1.7192271	0.51224917	3430.8208
612.69214	1.7212425	0.5134874	3427.7368
613.69312	1.7247226	0.51475579	3434.5173
614.69409	1.7267115	0.5158146	3426.897
615.69507	1.731783	0.5169214	3432.4966
616.69604	1.7356126	0.51790822	3432.2161
617.69702	1.7382406	0.51916027	3443.5728
618.698	1.7407225	0.5206027	3441.4631
619.69897	1.7399021	0.52178788	3433.0801
620.69995	1.7458347	0.52295673	3438.2927
621.70093	1.7511033	0.52423209	3437.981
622.7019	1.748998	0.52543026	3439.7795
623.70288	1.7548038	0.52676672	3440.5657
624.70386	1.7596629	0.52792311	3442.4707
625.70483	1.7609266	0.52913004	3436.373
626.70581	1.7644733	0.53037918	3441.3074
627.70679	1.7675521	0.53163469	3448.6118
628.70776	1.7695066	0.53278011	3441.856
629.70874	1.7752645	0.53425378	3450.8501
630.70972	1.777523	0.53562886	3449.2991
631.71069	1.7763472	0.53697705	3443.8779
632.71167	1.7832587	0.53827184	3450.9729
633.71265	1.7839198	0.53978562	3450.1936
634.71362	1.7916286	0.54104197	3444.0764
635.7146	1.7900575	0.54229248	3449.0996
636.71558	1.7958742	0.54357588	3449.8726
637.71655	1.7969879	0.54474682	3448.2903
638.71753	1.8019289	0.54598922	3452.5874
639.71851	1.8054322	0.54716253	3452.9226
640.71948	1.8095192	0.54833108	3450.4827
641.72046	1.8106498	0.54930985	3452.6379
642.72144	1.8078611	0.55054808	3456.5664
643.72241	1.8182929	0.55176878	3458.9353
644.72339	1.817487	0.55301297	3453.4553
645.72437	1.8221947	0.55429959	3457.7222
646.72534	1.8247496	0.55550897	3454.8535
647.72632	1.8225905	0.55690151	3454.9521
648.72729	1.8307904	0.5580706	3454.3357
649.72827	1.8336289	0.55917364	3462.7024
650.72925	1.8387259	0.56068647	3462.6211
651.73022	1.8375269	0.56196713	3460.2273
652.7312	1.8433084	0.56318092	3463.99
653.73218	1.8483131	0.56457102	3463.1272
654.73315	1.8484864	0.56580615	3464.8401
655.73413	1.8525741	0.56686699	3464.6006
656.73511	1.8556577	0.56804484	3464.1858
657.73608	1.855987	0.56939685	3465.126
658.73706	1.8641087	0.57052463	3468.1716
659.73804	1.8620728	0.57172024	3459.2961
660.73901	1.8654819	0.57297403	3462.2515
661.73999	1.8703756	0.57442302	3476.2629
662.74097	1.8718656	0.57563192	3468.614
663.74194	1.8743762	0.5771805	3471.1912
664.74292	1.8781779	0.57860172	3467.0413
665.7439	1.8810267	0.58002943	3473.2764
666.74487	1.8818564	0.58127165	3468.1699
667.74585	1.8850344	0.58233523	3466.7312
668.74683	1.8891748	0.58376753	3473.8372
669.7478	1.8911583	0.58506882	3470.1716
670.74878	1.8931596	0.58651304	3473.1487
671.74976	1.9030509	0.58777809	3476.082
672.75073	1.900473	0.58895439	3472.0186
673.75171	1.9075713	0.59020782	3467.6787
674.75269	1.9067749	0.59133732	3474.196
675.75366	1.9104785	0.59268695	3478.8647
676.75464	1.9149985	0.59404594	3481.5181
677.75562	1.9164172	0.5952366	3474.6707
678.75659	1.9193714	0.59636468	3480.897
679.75757	1.9204681	0.59766656	3481.8376
680.75854	1.9260255	0.59886211	3480.1279
681.75952	1.9294734	0.60031432	3486.7646
682.7605	1.9325072	0.60166824	3485.2874
683.76147	1.9346744	0.60275245	3481.6367
684.76245	1.9398264	0.60402942	3480.8293
685.76343	1.9408338	0.60539722	3487.176
686.7644	1.9436942	0.60691941	3489.407
687.76538	1.9471718	0.60825479	3487.9451
688.76636	1.9494381	0.60945028	3479.9363
689.76733	1.9528055	0.61083233	3486.6226
690.76831	1.9547808	0.61202776	3484.9675
691.76929	1.9585658	0.61323881	3483.3425
692.77026	1.9637424	0.61480784	3489.1218
693.77124	1.9659327	0.61602581	3483.0901
694.77222	1.9670856	0.61713737	3486.6235
695.77319	1.9753485	0.6183427	3486.3677
696.77417	1.9752803	0.61950296	3489.7856
697.77515	1.9764853	0.62077349	3489.6721
698.77612	1.9811149	0.62195045	3487.0679
699.7771	1.9843396	0.62309712	3490.5095
700.77808	1.9871161	0.62447697	3491.7771
701.77905	1.9882542	0.6259222	3494.8579
702.78003	1.9936994	0.62739211	3501.2419
703.78101	1.9960558	0.62880319	3494.4509
704.78198	1.9980522	0.63024968	3493.0217
705.78296	2.0017118	0.63175738	3497.2844
706.78394	2.0028696	0.63309538	3495.647
707.78491	2.0074687	0.63442284	3494.5334
708.78589	2.0115395	0.63576514	3496.345
709.78687	2.0145438	0.63697886	3497.0208
710.78784	2.0168636	0.63803428	3491.9072
711.78882	2.0226111	0.63933003	3501.7961
712.78979	2.0218937	0.64069545	3495.6362
713.79077	2.0258613	0.64173543	3496.7109
714.79175	2.0279067	0.6428715	3499.6169
715.79272	2.0315387	0.64438027	3503.26
716.7937	2.0379634	0.64568496	3505.6069
717.79468	2.0390298	0.64708465	3503.675
718.79565	2.0405376	0.64835411	3508.2915
719.79663	2.0416095	0.64977932	3508.219
720.79761	2.0448225	0.65133369	3504.9363
721.79858	2.0503135	0.65251136	3499.5566
722.79956	2.0580072	0.65362734	3507.1987
723.80054	2.0570893	0.65467215	3501.0269
724.80151	2.0591722	0.65566009	3496.1294
725.80249	2.0613344	0.65672117	3502.9165
726.80347	2.0662997	0.65792471	3514
727.80444	2.0668712	0.65905398	3505.3262
728.80542	2.0704098	0.66029632	3514.248
729.8064	2.0755379	0.66169226	3510.9624
730.80737	2.0780056	0.66305822	3516.6143
731.80835	2.0803006	0.66441113	3505.1558
732.80933	2.0836635	0.66594017	3517.3674
733.8103	2.0876355	0.6675182	3517.0137
734.81128	2.0911195	0.6691969	3513.4768
735.81226	2.0940361	0.67063951	3517.0637
736.81323	2.0937033	0.6721893	3508.3215
737.81421	2.0986664	0.67339659	3510.7161
738.81519	2.1022305	0.67481941	3521.6843
739.81616	2.1029568	0.6764046	3515.604
740.81714	2.1077735	0.67787045	3515.8511
741.81812	2.113652	0.67935967	3520.29
742.81909	2.1096356	0.68101555	3516.8779
743.82007	2.1149576	0.68263173	3516.1248
744.82104	2.1185277	0.68410248	3508.885
745.82202	2.123246	0.68542641	3516.1255
746.823	2.1272998	0.68667585	3518.0645
747.82397	2.128834	0.68791699	3515.425
748.82495	2.1305258	0.68906331	3519.3223
749.82593	2.1334982	0.69058245	3523.3186
750.8269	2.1348372	0.6920284	3518.009
751.82788	2.1388497	0.69340312	3522.7549
752.82886	2.1411211	0.69502014	3517.8447
753.82983	2.1437871	0.69642264	3524.7346
754.83081	2.145278	0.6982336	3521.9102
755.83179	2.1522286	0.69976109	3522.2971
756.83276	2.1561146	0.70095527	3519.1367
757.83374	2.1561949	0.70223057	3515.0764
758.83472	2.1613286	0.70317489	3522.7754
759.83569	2.1643627	0.70427406	3518.5752
760.83667	2.1670442	0.70541352	3526.8672
761.83765	2.1704116	0.70660073	3523.2754
762.83862	2.1704023	0.70799518	3524.3523
763.8396	2.1776979	0.70943749	3531.7078
764.84058	2.1774931	0.71073037	3521.9426
765.84155	2.1840432	0.71192598	3527.8601
766.84253	2.1857269	0.71337813	3534.1472
767.84351	2.1883955	0.71468914	3538.2749
768.84448	2.1911895	0.71594787	3528.321
769.84546	2.193161	0.71727598	3529.3208
770.84644	2.1936462	0.71870977	3529.5881
771.84741	2.2013865	0.72024947	3539.0264
772.84839	2.2043507	0.72194797	3542.822
773.84937	2.2071695	0.72362024	3533.5144
774.85034	2.2079868	0.72507995	3527.115
775.85132	2.2117317	0.72649866	3537.0332
776.85229	2.2167132	0.72801697	3535.1301
777.85327	2.2199211	0.72943717	3537.7222
778.85425	2.2189014	0.73072273	3528.9482
779.85522	2.2247324	0.73201758	3533.5967
780.8562	2.2259824	0.73331457	3524.9277
781.85718	2.2300243	0.73466003	3534.1711
782.85815	2.2324729	0.73610592	3535.396
783.85913	2.2373757	0.73727727	3538.2468
784.86011	2.2398481	0.73897594	3535.0442
785.86108	2.2397115	0.74041075	3536.3398
786.86206	2.244925	0.74190485	3534.8804
787.86304	2.2476957	0.74353725	3541.5188
788.86401	2.252686	0.74513537	3537.1997
789.86499	2.2541428	0.74641752	3534.5173
790.86597	2.2565322	0.74765611	3537.1892
791.86694	2.2613134	0.74911529	3534.9934
792.86792	2.2678568	0.75048256	3542.7122
793.8689	2.2645104	0.75187498	3539.7571
794.86987	2.2687857	0.7532078	3534.1619
795.87085	2.2696865	0.75460577	3544.4199
796.87183	2.2785285	0.75611752	3545.7874
797.8728	2.2775638	0.75768244	3543.0239
798.87378	2.2795572	0.75916684	3542.696
799.87476	2.2861116	0.76071471	3546.6094
800.87573	2.2863796	0.76221395	3544.0134
801.87671	2.2894711	0.76388139	3541.7078
802.87769	2.2925527	0.76542956	3541.9106
803.87866	2.2952051	0.76688415	3540.6958
804.87964	2.29703	0.76826197	3540.4338
805.88062	2.3017001	0.7697466	3540.8052
806.88159	2.3049929	0.77128297	3548.3792
807.88257	2.3083327	0.77280813	3548.3416
808.88354	2.3094797	0.77408874	3543.9792
809.88452	2.311408	0.7758444	3547.8945
810.8855	2.3186612	0.77741355	3552.1685
811.88647	2.321717	0.77893925	3547.0408
812.88745	2.3217661	0.78044343	3548.084
813.88843	2.3273358	0.78177536	3544.9666
814.8894	2.3283653	0.78331578	3549.3557
815.89038	2.3322558	0.78487939	3551.4868
816.89136	2.3368328	0.78658575	3553.8379
817.89233	2.3392572	0.78814524	3548.1614
818.89331	2.3421035	0.78950506	3552.124
819.89429	2.3442407	0.79106069	3547.1599
820.89526	2.3447015	0.79240423	3543.906
821.89624	2.3514497	0.79382676	3547.9812
822.89722	2.3524997	0.79559094	3557.7461
823.89819	2.3559082	0.79723281	3549.0164
824.89917	2.3595152	0.79862517	3547.3154
825.90015	2.3611555	0.80033344	3554.6145
826.90112	2.3646467	0.80177748	3553.0303
827.9021	2.367573	0.80317914	3549.6699
828.90308	2.3695915	0.80476379	3550.3989
829.90405	2.3749938	0.80623466	3549.5244
830.90503	2.3760371	0.80745167	3552.5901
831.90601	2.3812332	0.80926222	3557.7029
832.90698	2.3836644	0.81076473	3550.554
833.90796	2.3865325	0.81248617	3554.4028
834.90894	2.3894906	0.81385368	3555.7595
835.90991	2.3907475	0.8154068	3553.0833
836.91089	2.3951347	0.8172307	3558.6064
837.91187	2.3980148	0.8189801	3555.2883
838.91284	2.4032385	0.820476	3554.3184
839.91382	2.4018061	0.82198238	3551.4829
840.91479	2.4096425	0.82358783	3560.0413
841.91577	2.411299	0.82510012	3556.5769
842.91675	2.4139476	0.82640976	3554.5056
843.91772	2.4179151	0.82809818	3558.2654
844.9187	2.4204974	0.82960987	3560.3208
845.91968	2.4230115	0.83130735	3559.5569
846.92065	2.4257233	0.83289772	3558.571
847.92163	2.4281189	0.83461016	3558.3088
848.92261	2.4307673	0.83622342	3557.5579
849.92358	2.433918	0.8380754	3557.302
850.92456	2.4377809	0.83968467	3561.3472
851.92554	2.4380805	0.84148633	3558.1716
852.92651	2.4433439	0.84329981	3559.7366
853.92749	2.4454889	0.84496981	3560.0261
854.92847	2.4513128	0.84647936	3555.283
855.92944	2.4530425	0.84784055	3556.2163
856.93042	2.4551709	0.84934032	3559.8977
857.9314	2.4584706	0.85100228	3565.5142
858.93237	2.4613719	0.85280269	3564.3018
859.93335	2.4632771	0.85444939	3561.3142
860.93433	2.4668415	0.85598022	3563.3237
861.9353	2.4690626	0.85768735	3563.0393
862.93628	2.475162	0.85937673	3562.6255
863.93726	2.4753032	0.86081189	3558.4158
864.93823	2.4802532	0.86219144	3561.0659
865.93921	2.4806437	0.86368006	3558.2344
866.94019	2.4865298	0.86508298	3563.7292
867.94116	2.4867678	0.86690485	3565.4929
868.94214	2.4922745	0.86882526	3565.5271
869.94312	2.4957743	0.87046301	3567.9656
870.94409	2.4968193	0.87211865	3565.4441
871.94507	2.5018148	0.87372994	3561.5901
872.94604	2.5013626	0.87533963	3566.5264
873.94702	2.5066416	0.8772006	3564.3452
874.948	2.5089498	0.87875915	3566.4353
875.94897	2.5144768	0.88026053	3566.1694
876.94995	2.5171015	0.88213402	3565.5159
877.95093	2.5178611	0.88388282	3566.2854
878.9519	2.5214021	0.88558203	3560.4788
879.95288	2.5241473	0.8871749	3564.3296
880.95386	2.528578	0.88888758	3560.8909
881.95483	2.5300975	0.89056265	3562.7512
882.95581	2.5350201	0.89203811	3567.3936
883.95679	2.5385661	0.89387721	3569.0215
884.95776	2.5431645	0.89575452	3573.8328
885.95874	2.5417116	0.89771646	3566.6787
886.95972	2.5450857	0.89965278	3574.6187
887.96069	2.5499086	0.90172464	3566.4111
888.96167	2.5530231	0.90333593	3565.9355
889.96265	2.5555735	0.90505499	3569.2273
890.96362	2.5570951	0.9068523	3566.3506
891.9646	2.558007	0.90862316	3566.178
892.96558	2.5631082	0.91067988	3568.99
893.96655	2.5642514	0.91246086	3562.6482
894.96753	2.5684991	0.91399902	3566.7615
895.96851	2.5723722	0.91617203	3571.8408
896.96948	2.5781491	0.91813308	3574.55
897.97046	2.5756001	0.91999435	3566.7966
898.97144	2.5813098	0.9217273	3569.8738
899.97241	2.5863709	0.92366701	3568.5315
900.97339	2.5876007	0.92533892	3566.3931
901.97437	2.5890255	0.9268288	3571.5005
902.97534	2.5945625	0.92851794	3571.436
903.97632	2.5945346	0.93009657	3573.115
904.97729	2.5984032	0.93229228	3576.5703
905.97827	2.6005144	0.9342292	3575.2341
906.97925	2.6043222	0.93606383	3568.0947
907.98022	2.6080594	0.93804729	3568.9583
908.9812	2.6107984	0.94011456	3568.7151
909.98218	2.6145632	0.94193953	3565.113
910.98315	2.6171591	0.9436152	3571.5264
911.98413	2.6229973	0.94554299	3576.9832
912.98511	2.6230335	0.94726622	3565.772
913.98608	2.6276867	0.9491272	3563.7358
914.98706	2.6288958	0.95105755	3570.5708
915.98804	2.6343107	0.95306993	3577.5398
916.98901	2.6358254	0.95528156	3573.6401
917.98999	2.6352055	0.95750272	3575.0178
918.99097	2.6394303	0.95972574	3571.9146
919.99194	2.645175	0.96154743	3567.3616
920.99292	2.6500313	0.96338624	3573.7764
921.9939	2.6520717	0.96510166	3573.4978
922.99487	2.654501	0.96712583	3579.1741
923.99585	2.6549661	0.96928275	3571.9773
924.99683	2.656769	0.97116387	3572.1968
925.9978	2.660841	0.97303897	3570.6423
926.99878	2.6629536	0.97512728	3571.1392
927.99976	2.6671112	0.97715378	3566.8169
929.00073	2.6699476	0.97931695	3571.886
930.00171	2.6720324	0.98140687	3575.5278
931.00269	2.6762056	0.98360801	3568.5837
932.00366	2.6778247	0.98559386	3569.6365
933.00464	2.6842999	0.98730439	3567.5032
934.00562	2.6877108	0.98906255	3572.6929
935.00659	2.6898055	0.99105799	3574.8633
936.00757	2.6933391	0.99296647	3576.2708
937.00854	2.6960773	0.99490368	3570.3655
938.00952	2.6970074	0.99699789	3572.1628
939.0105	2.703866	0.9988364	3572.334
940.01147	2.7053025	1.000878	3578.7891
941.01245	2.7052174	1.0030767	3567.2363
942.01343	2.7112014	1.0050639	3576.6912
943.0144	2.7138474	1.0070646	3573.646
944.01538	2.7166946	1.0092183	3569.4412
945.01636	2.7177827	1.0113915	3575.1709
946.01733	2.7223172	1.0138324	3579.8743
947.01831	2.7278636	1.0162327	3577.3447
948.01929	2.7301824	1.0186992	3575.3464
949.02026	2.7322927	1.020538	3572.4634
950.02124	2.7313545	1.0224047	3573.0535
951.02222	2.7366972	1.0243737	3574.9436
952.02319	2.7425668	1.026117	3578.4407
953.02417	2.7464056	1.0282615	3576.7429
954.02515	2.7474325	1.0305398	3581.9231
955.02612	2.7473714	1.0327508	3574.2686
956.0271	2.7545929	1.0349098	3572.1213
957.02808	2.7549946	1.0371245	3571.7314
958.02905	2.7597733	1.0391495	3573.6204
959.03003	2.7609754	1.0413953	3574.2317
960.03101	2.7650876	1.0434263	3569.23
961.03198	2.7680941	1.0455073	3573.4001
962.03296	2.7699015	1.0479451	3574.9868
963.03394	2.774179	1.0498711	3575.3562
964.03491	2.7765326	1.0516508	3575.0525
965.03589	2.7795243	1.053386	3572.6379
966.03687	2.7827039	1.0549566	3573.4551
967.03784	2.7862852	1.0561496	3570.5405
968.03882	2.7861547	1.0578541	3573.0564
969.03979	2.7919645	1.0597806	3572.6021
970.04077	2.7959888	1.0617056	3575.2542
971.04175	2.7966168	1.0638801	3567.5154
972.04272	2.7996995	1.0660776	3572.2517
973.0437	2.8056903	1.0681643	3561.188
974.04468	2.8072164	1.070773	3577.1174
975.04565	2.8083673	1.0732938	3572.2861
976.04663	2.8103127	1.0756514	3569.2786
977.04761	2.8189988	1.0779222	3572.3711
978.04858	2.8154292	1.0804036	3567.1248
979.04956	2.8202105	1.08279	3568.0615
980.05054	2.8243032	1.0855808	3569.5232
981.05151	2.8263557	1.0877606	3562.3848
982.05249	2.8300188	1.0900792	3567.6167
983.05347	2.8321328	1.0922519	3562.1631
984.05444	2.8370147	1.0945092	3573.3027
985.05542	2.8381906	1.0973084	3568.5337
986.0564	2.8426573	1.0997567	3565.6545
987.05737	2.8458295	1.1021509	3570.2046
988.05835	2.8500884	1.1046536	3571.085
989.05933	2.8534591	1.1074879	3569.2349
990.0603	2.853498	1.1101384	3567.0505
991.06128	2.8584187	1.1131746	3569.8784
992.06226	2.8629384	1.1159842	3571.2107
993.06323	2.8619273	1.1188397	3565.9639
994.06421	2.8670955	1.1211318	3566.2661
995.06519	2.8703241	1.1237159	3571.7322
996.06616	2.8730083	1.1265051	3568.6289
997.06714	2.875308	1.1288944	3564.9668
998.06812	2.8798296	1.1311347	3562.4377
999.06909	2.8833945	1.1334	3566.2026
1000.0701	2.8860543	1.1361123	3573.3979
1001.071	2.8895328	1.1386456	3563.5007
1002.072	2.892206	1.1412935	3568.9529
1003.073	2.8920257	1.1440161	3563.5181
1004.074	2.8972809	1.1465114	3568.3362
1005.075	2.9019976	1.1489269	3565.7268
1006.0759	2.9045422	1.1515244	3565.5942
1007.0769	2.904279	1.1538939	3566.1809
1008.0779	2.9063518	1.156624	3562.1355
1009.0789	2.9129283	1.158962	3560.0972
1010.0798	2.9137025	1.1612061	3558.158
1011.0808	2.917052	1.1634914	3564.0376
1012.0818	2.919687	1.1660701	3557.6926
1013.0828	2.925241	1.1683496	3566.7029
1014.0837	2.9247894	1.1711117	3563.0203
1015.0847	2.9295979	1.1739603	3565.1394
1016.0857	2.9318101	1.1769181	3558.9558
1017.0867	2.9360013	1.179336	3558.0476
1018.0876	2.9359684	1.1817851	3556.8491
1019.0886	2.9413826	1.1842148	3556.1228
1020.0896	2.9435532	1.1867698	3555.6902
1021.0906	2.9476182	1.1893822	3559.5303
1022.0916	2.9501221	1.192341	3556.9895
1023.0925	2.9585392	1.1951975	3559.3567
1024.0935	2.9578798	1.1981997	3554.2712
1025.0945	2.9617648	1.2015413	3555.1978
1026.0955	2.9629197	1.2046129	3552.6147
1027.0964	2.9654481	1.2078812	3553.2676
1028.0974	2.9688265	1.2107553	3559.1343
1029.0984	2.970901	1.2140502	3554.2939
1030.0994	2.9751484	1.2165529	3546.9775
1031.1003	2.9773366	1.2189243	3549.8911
1032.1013	2.978446	1.2217082	3550.8682
1033.1023	2.9878855	1.2242738	3552.175
1034.1033	2.9869709	1.2270689	3551.1472
1035.1042	2.9863992	1.2299558	3548.6362
1036.1052	2.9898314	1.2332122	3547.4053
1037.1062	2.9970896	1.2360336	3539.8381
1038.1072	2.9982493	1.2385972	3546.8784
1039.1082	3.0018842	1.2411296	3537.7307
1040.1091	3.0048766	1.2437232	3539.73
1041.1101	3.0069456	1.2465997	3548.9827
1042.1111	3.0103981	1.2499903	3541.0981
1043.1121	3.0157406	1.252459	3539.3069
1044.113	3.0146236	1.255367	3540.8958
1045.114	3.0177979	1.2580168	3534.9629
1046.115	3.0205886	1.2607605	3539.7756
1047.116	3.0270262	1.2636501	3539.4163
1048.1169	3.0298638	1.2662091	3535.4866
1049.1179	3.0325737	1.269085	3539.354
1050.1189	3.0339398	1.2718345	3537.6367
1051.1199	3.0374241	1.2751603	3537.7507
1052.1208	3.0447075	1.2784353	3537.4197
1053.1218	3.0475006	1.2814398	3534.7224
1054.1228	3.046737	1.2839793	3531.4504
1055.1238	3.0519969	1.2865142	3526.4646
1056.1248	3.0520883	1.2883148	3521.5708
1057.1257	3.0538015	1.2900343	3522.6587
1058.1267	3.0609453	1.2917658	3525.2212
1059.1277	3.0611823	1.2943619	3534.3254
1060.1287	3.0625238	1.2971927	3527.8579
1061.1296	3.0676732	1.300243	3527.6721
1062.1306	3.071903	1.3034815	3527.1121
1063.1316	3.0714705	1.3074784	3531.2214
1064.1326	3.0783081	1.3109305	3517.6882
1065.1335	3.0802329	1.3133286	3514.8201
1066.1345	3.0810595	1.3160625	3516.5806
1067.1355	3.0859408	1.3188586	3514.1035
1068.1365	3.0885794	1.3218977	3521.3577
1069.1375	3.0899	1.3249547	3517.7505
1070.1384	3.0920298	1.3283303	3512.7791
1071.1394	3.098866	1.3310182	3511.4807
1072.1404	3.1018667	1.3341994	3509.8936
1073.1414	3.1053853	1.3371645	3514.2395
1074.1423	3.1075139	1.3402063	3504.125
1075.1433	3.1112542	1.3427713	3501.731
1076.1443	3.1131546	1.3452284	3502.5183
1077.1453	3.1162951	1.348067	3507.3997
1078.1462	3.1192427	1.3511997	3513.1987
1079.1472	3.1221499	1.3546019	3503.7129
1080.1482	3.1277163	1.3575765	3500.125
1081.1492	3.1277485	1.3604574	3499.5842
1082.1501	3.1320808	1.3639505	3504.6501
1083.1511	3.1346633	1.3671787	3487.7961
1084.1521	3.1359305	1.3699979	3495.4197
1085.1531	3.1386433	1.3730603	3491.3652
1086.1541	3.1431117	1.3764188	3491.5583
1087.155	3.1444602	1.379704	3488.9485
1088.156	3.1498821	1.3826916	3486.5659
1089.157	3.1532402	1.3858875	3484.127
1090.158	3.1554418	1.3894104	3489.4319
1091.1589	3.1569381	1.3926691	3481.114
1092.1599	3.1588149	1.3956078	3474.7822
1093.1609	3.1655974	1.3987098	3479.5054
1094.1619	3.1666572	1.4020001	3478.4495
1095.1628	3.1711483	1.4050194	3471.4509
1096.1638	3.1726165	1.4077553	3470.1792
1097.1648	3.1778524	1.4106845	3469.9387
1098.1658	3.1791768	1.4137489	3472.3916
1099.1667	3.1813827	1.4166225	3473.4968
1100.1677	3.186996	1.419782	3465.3413
1101.1687	3.1886659	1.4224077	3462.6267
1102.1697	3.1909115	1.4254972	3462.3037
1103.1707	3.1945539	1.428636	3457.4734
1104.1716	3.197031	1.4310242	3452.4587
1105.1726	3.1990297	1.4334775	3451.5266
1106.1736	3.2034438	1.4365618	3457.6724
1107.1746	3.2090888	1.4402983	3465.0508
1108.1755	3.2094522	1.4443463	3447.1074
1109.1765	3.21152	1.4475437	3447.6479
1110.1775	3.2168837	1.4510956	3452.1333
1111.1785	3.2166224	1.4538027	3438.1423
1112.1794	3.2217848	1.4566108	3443.1794
1113.1804	3.2214744	1.4592412	3439.5181
1114.1814	3.2291512	1.4620705	3433.5325
1115.1824	3.2296863	1.4648235	3436.6074
1116.1833	3.2322881	1.4673996	3432.2881
1117.1843	3.234215	1.4699961	3427.2156
1118.1853	3.2410324	1.4728661	3428.3765
1119.1863	3.242696	1.4759862	3429.8584
1120.1873	3.2445538	1.479018	3427.5342
1121.1882	3.2504177	1.4823925	3428.4536
1122.1892	3.2526388	1.4861556	3424.0918
1123.1902	3.2530191	1.4896268	3413.8518
1124.1912	3.256146	1.492853	3415.4514
1125.1921	3.2599847	1.4959153	3408.5159
1126.1931	3.2630963	1.4986451	3402.3152
1127.1941	3.2667692	1.5012741	3408.1201
1128.1951	3.2696233	1.504186	3413.4226
1129.196	3.2721465	1.5081539	3408.6311
1130.197	3.2746322	1.5118984	3395.1653
1131.198	3.2802587	1.5149702	3393.5759
1132.199	3.281342	1.5179141	3395.5442
1133.2	3.2849526	1.5212468	3390.7881
1134.2009	3.2884462	1.5252377	3396.4165
1135.2019	3.2894199	1.5288286	3377.6609
1136.2029	3.2920489	1.5317569	3379.7891
1137.2039	3.2958095	1.5348842	3384.6133
1138.2048	3.2995784	1.5385101	3377.1255
1139.2058	3.3019223	1.5421543	3371.0349
1140.2068	3.3031406	1.5453619	3366.0698
1141.2078	3.3081467	1.5487746	3369.4482
1142.2087	3.3141198	1.5521829	3371.2632
1143.2097	3.3151064	1.555637	3363.5168
1144.2107	3.3179433	1.5589274	3358.854
1145.2117	3.3226016	1.5618367	3352.6865
1146.2126	3.32515	1.5647721	3350.1892
1147.2136	3.3278403	1.5678774	3355.7322
1148.2146	3.3279903	1.5713086	3346.1221
1149.2156	3.3320813	1.5749207	3344.4675
1150.2166	3.3341365	1.5784855	3337.7285
1151.2175	3.335536	1.581632	3333.6992
1152.2185	3.3393443	1.5848666	3335.8506
1153.2195	3.344918	1.5878016	3332.9724
1154.2205	3.3497827	1.5907172	3325.1235
1155.2214	3.3504288	1.5937501	3321.5532
1156.2224	3.3526337	1.5969316	3320.2847
1157.2234	3.3577669	1.6001478	3317.1204
1158.2244	3.3588557	1.6030165	3307.5928
1159.2253	3.3653235	1.6056416	3311.1089
1160.2263	3.3650551	1.6092986	3308.8269
1161.2273	3.3670597	1.6131004	3300.9634
1162.2283	3.3725019	1.6162149	3295.0383
1163.2292	3.3737209	1.619146	3296.7847
1164.2302	3.3749082	1.6226673	3292.4902
1165.2312	3.3815126	1.6267015	3294.9741
1166.2322	3.3838441	1.6301173	3282.5251
1167.2332	3.3862538	1.6334494	3278.3198
1168.2341	3.3908525	1.6369638	3278.2241
1169.2351	3.3943002	1.640685	3274.9187
1170.2361	3.3941183	1.6441901	3266.0581
1171.2371	3.3991809	1.6476312	3257.5876
1172.238	3.4001033	1.6506041	3252.542
1173.239	3.4039848	1.6541451	3260.3694
1174.24	3.407068	1.6576549	3248.752
1175.241	3.4090188	1.6615869	3244.8723
1176.2419	3.4147351	1.6651028	3237.2773
1177.2429	3.4158511	1.6688265	3237.6707
1178.2439	3.4203568	1.6719904	3230.2803
1179.2449	3.421735	1.6749995	3228.0891
1180.2458	3.4289317	1.6781906	3228.3547
1181.2468	3.427655	1.6818267	3212.6074
1182.2478	3.4280624	1.6850054	3210.1663
1183.2488	3.4372077	1.688037	3209.116
1184.2498	3.437794	1.6909691	3205.4836
1185.2507	3.4402754	1.694298	3197.2932
1186.2517	3.4439037	1.6974835	3185.7686
1187.2527	3.4486854	1.7006453	3194.3396
1188.2537	3.4480653	1.7041847	3177.8306
1189.2546	3.4522023	1.7071553	3180.5349
1190.2556	3.4545252	1.7108674	3173.1587
1191.2566	3.4574933	1.7139176	3161.1072
1192.2576	3.4642754	1.7172397	3164.7388
1193.2585	3.4641531	1.7209219	3154.8826
1194.2595	3.4658475	1.7246889	3143.8962
1195.2605	3.4699848	1.7280121	3142.7974
1196.2615	3.474946	1.7316192	3135.9617
1197.2625	3.4766815	1.7358694	3121.3711
1198.2634	3.479264	1.7447536	3058.2427
1199.2644	3.4843082	1.7508061	3019.269
1200.0652	3.4858952	1.7578309	2978.8374