File: datasets/am_bench_2022/raw_data/45-XY.08-1/specimen.dat
MTS793|MPT|ENU|1|2|.|/|:|1|0|0|A

Operator Information						Time:	26.448242	Sec	10/19/2021 12:07:46 PM
Operator	Newell Moser
Project	AM Bench 2022 mini-tensile challenge
Specimen ID	45-XY.08-1
Material	PBF-L Inconel 625
Specimen Width	2.55	mm
Specimen Thickness	1.53	mm
Notes
Operator Information End

Data Acquisition						Time:	1027.4434	Sec	10/19/2021 12:24:27 PM
Time	Axial Displacement	Axial Extensometer	Axial Force
Sec	mm	mm	N
26.5625	-0.0021778338	3.8681039e-05	90.12606
27.463379	9.4970557e-05	0.00015380005	105.78147
28.364258	0.0013144816	0.00013672034	111.71034
29.265137	0.0046492359	0.00020809923	125.43632
30.166016	0.0070470748	0.00025644532	136.04958
31.066895	0.010111578	0.00031761243	152.95448
31.967773	0.014992234	0.00037977635	163.93379
32.868652	0.017122844	0.00048608813	171.60657
33.769531	0.015799658	0.00049519347	193.53891
34.67041	0.021300981	0.00063420279	209.48222
35.571289	0.023937056	0.00061080011	216.86586
36.472168	0.026993159	0.00073417934	233.92125
37.373047	0.028339498	0.00081897038	256.33539
38.273926	0.031937331	0.00087219285	266.72913
39.174805	0.034012876	0.00096906431	283.49945
40.075684	0.038326394	0.0010764046	301.45392
40.976563	0.040659849	0.0010555437	316.30893
41.877441	0.044024106	0.0011548368	330.12659
42.77832	0.046195745	0.0012964227	361.74591
43.679199	0.046002943	0.0013504187	377.44162
44.580078	0.050456811	0.0015301602	402.41006
45.480957	0.054044399	0.0015587866	420.48026
46.381836	0.057255607	0.0016691112	446.13373
47.282715	0.056034662	0.0016649765	463.88535
48.183594	0.062943943	0.0018650545	488.77209
49.084473	0.065004528	0.0018397792	508.80063
49.985352	0.06765946	0.0020379189	531.25848
50.88623	0.069335826	0.0021393381	549.0799
51.787109	0.072794177	0.0021727269	575.17072
52.687988	0.073629722	0.0022137666	594.36041
53.588867	0.078019053	0.0023969454	627.81281
54.489746	0.078652166	0.0024409795	641.98627
55.390625	0.081027821	0.0025734405	664.34247
56.291504	0.088225797	0.0027919218	700.54236
57.192383	0.088082172	0.0028671159	719.91693
58.093262	0.087513596	0.0028184296	729.2594
58.994141	0.093315184	0.0029406911	756.92615
59.89502	0.096358791	0.0030918289	787.33142
60.795898	0.095626563	0.0031352905	806.36926
61.696777	0.10253891	0.0032423481	832.94891
62.597656	0.10133784	0.0033261729	858.95526
63.498535	0.1068741	0.0034445405	886.17328
64.399414	0.1053346	0.0035473416	912.85437
65.300293	0.11432163	0.0037047982	939.25214
66.201172	0.11357378	0.003742367	950.27203
67.102051	0.11834605	0.0040218057	987.31165
68.00293	0.11911521	0.0039890814	1004.5425
68.903809	0.12383784	0.0040822197	1033.5959
69.804688	0.12487767	0.0042013503	1064.9139
70.705566	0.12782544	0.004388459	1089.6877
71.606445	0.13189308	0.0043846644	1107.9468
72.507324	0.13593574	0.0045476202	1140.7979
73.408203	0.1354192	0.0046285265	1163.9185
74.309082	0.13743939	0.0047384785	1195.1565
75.209961	0.14327626	0.0049511041	1224.9777
76.11084	0.14227603	0.0050602471	1253.1886
77.011719	0.14796349	0.0051695881	1284.3433
77.912598	0.14986381	0.0052086608	1306.2704
78.813477	0.15420443	0.0053029209	1328.8215
79.714355	0.157498	0.0054346281	1359.3665
80.615234	0.15632033	0.0055166571	1373.4935
81.516113	0.15782644	0.0055887983	1398.0188
82.416992	0.16166994	0.0057396833	1423.8604
83.317871	0.16632563	0.0057775499	1443.6597
84.21875	0.17004946	0.0058144387	1467.3219
85.119629	0.17495717	0.0059286468	1501.9976
86.020508	0.17153636	0.006112928	1533.4446
86.921387	0.17780982	0.0062336731	1561.1046
87.822266	0.1789279	0.0063021467	1573.6917
88.723145	0.18035312	0.0063712187	1604.6641
89.624023	0.18659092	0.0065104985	1629.0513
90.524902	0.1864453	0.0065733413	1642.4943
91.425781	0.18931393	0.0066356529	1673.9344
92.32666	0.19547863	0.0067357812	1704.774
93.227539	0.19536513	0.006828031	1727.0194
94.128418	0.1975193	0.0069062482	1753.3065
95.029297	0.20085754	0.0070125284	1772.1892
95.930176	0.20281772	0.0070583541	1792.6268
96.831055	0.20484753	0.0071927155	1819.1157
97.731934	0.21048445	0.0072828503	1836.2148
98.632813	0.211421	0.0074096275	1870.2689
99.533691	0.2166139	0.007412463	1897.1597
100.43457	0.21745186	0.0075224754	1916.281
101.33545	0.22103786	0.0076251337	1934.7891
102.23633	0.22366942	0.0077208816	1959.8568
103.13721	0.22658503	0.0077955797	1983.7207
104.03809	0.2300003	0.0078763841	1998.8616
104.93896	0.22907215	0.0078638652	2013.8104
105.83984	0.23253107	0.0080766585	2043.2139
106.74072	0.23424703	0.0080932789	2054.3582
107.6416	0.23680571	0.0081341378	2071.7153
108.54248	0.24320066	0.0082379477	2088.5798
109.44336	0.24537656	0.008313858	2110.0923
110.34424	0.24733143	0.0083759185	2127.0798
111.24512	0.24950859	0.0084579317	2151.3445
112.146	0.25119644	0.0085160881	2165.0281
113.04688	0.25590539	0.0085322773	2184.8875
113.94775	0.2577053	0.0085921744	2199.9031
114.84863	0.25887522	0.0086653158	2214.1638
115.74951	0.26327917	0.0086936159	2227.7898
116.65039	0.26903054	0.0088201705	2251.2747
117.55127	0.26763463	0.0087546641	2254.7515
118.45215	0.27302197	0.0089774113	2271.8914
119.35303	0.27294126	0.0089684576	2287.6655
120.25391	0.27955261	0.0091105802	2308.5862
121.15479	0.27935612	0.0091271624	2315.6685
122.05566	0.28358215	0.0091688661	2328.6199
122.95654	0.28399557	0.009166481	2341.7104
123.85742	0.28613034	0.0091880728	2350.0588
124.7583	0.29043716	0.0093692234	2360.2791
125.65918	0.29296893	0.009477892	2377.9084
126.56006	0.29686385	0.0095898267	2387.7742
127.46094	0.29918522	0.0095982719	2395.8318
128.36182	0.30107841	0.0097098378	2417.8762
129.2627	0.30613509	0.0098452736	2426.2935
130.16357	0.3075045	0.0098036854	2435.9792
131.06445	0.31016624	0.009873962	2451.5039
131.96533	0.31363869	0.010007033	2458.967
132.86621	0.31517825	0.0099843638	2469.8193
133.76709	0.31983003	0.010045037	2484.6814
134.66797	0.32030499	0.010169006	2493.9063
135.56885	0.3236219	0.010225161	2499.0881
136.46973	0.3264012	0.010336637	2516.3252
137.37061	0.3284165	0.010440872	2522.666
138.27148	0.33033019	0.010501105	2524.3762
139.17236	0.33516243	0.0105902	2540.47
140.07324	0.33995417	0.010616236	2550.78
140.97412	0.33833307	0.010699151	2554.9507
141.875	0.34252352	0.010901807	2574.8708
142.77588	0.34756479	0.010889022	2576.1467
143.67676	0.34917951	0.01099926	2587.3606
144.57764	0.3507551	0.011134899	2594.1487
145.47852	0.35012281	0.01125528	2603.0815
146.37939	0.35603899	0.011367264	2611.1389
147.28027	0.35901293	0.011476715	2616.4709
148.18115	0.35989684	0.011582008	2621.0603
149.08203	0.36482313	0.011783487	2638.8704
149.98291	0.36918321	0.01192339	2642.1663
150.88379	0.37308407	0.011948247	2645.5625
151.78467	0.37502638	0.012119275	2653.614
152.68555	0.37452015	0.012284878	2663.7698
153.58643	0.3783091	0.012369988	2671.7104
154.4873	0.38033548	0.01255284	2681.2051
155.38818	0.38524809	0.012602136	2687.4629
156.28906	0.3841444	0.012814765	2687.7817
157.18994	0.39045802	0.013045204	2699.3374
158.09082	0.39187682	0.013184904	2711.4561
158.9917	0.39232942	0.013390167	2706.5642
159.89258	0.39943805	0.013563178	2719.9167
160.79346	0.40055144	0.013797629	2727.6321
161.69434	0.4003025	0.01395708	2733.6245
162.59521	0.404448	0.014542898	2738.6902
163.49609	0.40863818	0.014729388	2746.5798
164.39697	0.41299596	0.015015876	2759.2207
165.29785	0.41307014	0.01525877	2758.1194
166.19873	0.41579184	0.015455042	2768.2854
167.09961	0.41790858	0.015705232	2766.9363
168.00049	0.42407	0.016185351	2782.0344
168.90137	0.4256888	0.016442662	2789.3323
169.80225	0.42698556	0.016861545	2795.3801
170.70313	0.42825156	0.017194035	2803.1941
171.604	0.43314448	0.017585438	2806.2341
172.50488	0.434297	0.017909937	2806.5261
173.40576	0.43618342	0.018248806	2811.0486
174.30664	0.44153124	0.018745081	2822.2083
175.20752	0.44475922	0.018968521	2828.0198
176.1084	0.44806224	0.019412072	2829.5049
177.00928	0.44848779	0.019956449	2843.1411
177.91016	0.45461029	0.020386875	2844.082
178.81104	0.45326641	0.020977147	2847.2612
179.71191	0.45803049	0.021478582	2854.6506
180.61279	0.46213174	0.021999512	2852.6296
181.51367	0.46071306	0.022445243	2859.8831
182.41455	0.46641144	0.023167828	2866.5386
183.31543	0.46540952	0.023817092	2869.103
184.21631	0.47201654	0.024340762	2873.5408
185.11719	0.47086716	0.024934947	2876.7393
186.01807	0.47619262	0.025471207	2877.3088
186.91895	0.47799054	0.026067846	2882.5432
187.81982	0.48147509	0.026688574	2890.9282
188.7207	0.48621553	0.027251303	2892.3076
189.62158	0.48869985	0.028076537	2899.7705
190.52246	0.4853968	0.028823206	2897.8779
191.42334	0.48969254	0.029605441	2903.3599
192.32422	0.49591047	0.030535411	2916.9019
193.2251	0.49765697	0.031340022	2910.5867
194.12598	0.50060898	0.032187957	2920.8621
195.02686	0.50319386	0.032982722	2920.748
195.92773	0.50585538	0.033683743	2919.5098
196.82861	0.50771576	0.034361497	2918.593
197.72949	0.51142281	0.03510157	2923.4609
198.63037	0.5144406	0.035960309	2929.3308
199.53125	0.51603222	0.036699269	2931.3928
200.43213	0.51611847	0.037235577	2927.0552
201.33301	0.52252859	0.038205218	2937.6895
202.23389	0.52189445	0.039016567	2941.7578
203.13477	0.53121489	0.04009416	2949.9688
204.03564	0.52910471	0.040937662	2946.3635
204.93652	0.53247595	0.04193728	2950.1274
205.8374	0.53447586	0.043153048	2956.4812
206.73828	0.53908253	0.044030186	2957.9197
207.63916	0.53780305	0.045061234	2958.2917
208.54004	0.54406261	0.045756582	2959.3098
209.44092	0.54675072	0.046700634	2961.1772
210.3418	0.54876912	0.047566224	2965.1768
211.24268	0.55131215	0.04862972	2968.4951
212.14355	0.55519909	0.049631182	2972.626
213.04443	0.55754304	0.050652318	2977.0117
213.94531	0.5602836	0.05180157	2979.3669
214.84619	0.56195307	0.052928865	2978.1162
215.74707	0.56483829	0.054084782	2982.6372
216.64795	0.56945115	0.055128451	2983.5276
217.54883	0.56986773	0.055999856	2983.3323
218.44971	0.57383806	0.05707347	2989.4395
219.35059	0.57794893	0.05801075	2989.3015
220.25146	0.58159119	0.058774628	2990.5293
221.15234	0.58102715	0.059672046	2988.7532
222.05322	0.58266503	0.060709104	2996.6023
222.9541	0.58827001	0.061806895	2999.6587
223.85498	0.59113926	0.06267643	2992.9292
224.75586	0.59347045	0.063637167	3006.4844
225.65674	0.59465206	0.064864472	3008.4141
226.55762	0.6010288	0.066026233	3009.7012
227.4585	0.59883404	0.066921502	3003.3821
228.35938	0.60071409	0.06783703	3003.0264
229.26025	0.60674435	0.068958834	3015.1519
230.16113	0.61108249	0.070103064	3013.8953
231.06201	0.61258805	0.071103446	3016.1533
231.96289	0.61538374	0.072333418	3023.6851
232.86377	0.61469221	0.073483586	3017.4795
233.76465	0.61962861	0.074592866	3022.2402
234.66553	0.62305719	0.07563249	3022.0229
235.56641	0.62306869	0.076502174	3019.5293
236.46729	0.63014305	0.077679522	3027.0603
237.36816	0.63394433	0.078769937	3031.7959
238.26904	0.63437748	0.079959452	3034.1445
239.16992	0.63627887	0.081043169	3034.6682
240.0708	0.63667494	0.082243986	3036.4834
240.97168	0.64096469	0.083423473	3035.5513
241.87256	0.64388967	0.084549628	3036.1628
242.77344	0.64512491	0.085550569	3037.1233
243.67432	0.64872396	0.086594969	3037.71
244.5752	0.6517939	0.087477528	3037.584
245.47607	0.65370423	0.088423401	3039.2227
246.37695	0.65607053	0.08952456	3045.6011
247.27783	0.65974969	0.090704821	3050.9968
248.17871	0.66170162	0.091984756	3054.6641
249.07959	0.66286993	0.09325368	3049.5261
249.98047	0.66828245	0.094310857	3053.5361
250.88135	0.67035347	0.095357463	3053.9216
251.78223	0.67268962	0.096350193	3054.137
252.68311	0.67625552	0.09729173	3059.9751
253.58398	0.67645097	0.098370433	3064.6245
254.48486	0.68152237	0.099507421	3062.2786
255.38574	0.68454301	0.10054157	3054.96
256.28662	0.68670094	0.10160692	3064.3765
257.1875	0.6872322	0.10268939	3060.8606
258.08838	0.69280726	0.10350868	3063.0535
258.98926	0.69441766	0.10458086	3067.2241
259.89014	0.69690377	0.10562854	3071.6211
260.79102	0.69941938	0.1067616	3070.7654
261.69189	0.70077324	0.10793166	3074.1748
262.59277	0.70421934	0.10899622	3077.6677
263.49365	0.70950812	0.11004916	3079.0593
264.39453	0.71133018	0.11122141	3075.3728
265.29541	0.71492863	0.11239292	3082.3542
266.19629	0.71428216	0.11347819	3077.7253
267.09717	0.7185654	0.11461164	3079.8398
267.99805	0.72242081	0.11582645	3081.6516
268.89893	0.72526753	0.11687329	3088.96
269.7998	0.72922248	0.11796387	3091.8357
270.70068	0.72966236	0.11925319	3095.0203
271.60156	0.73093414	0.12029461	3085.7664
272.50244	0.7336719	0.12138232	3085.0686
273.40332	0.73966074	0.12269534	3092.6323
274.3042	0.74069887	0.12357835	3088.061
275.20508	0.74247855	0.1245776	3094.8101
276.10596	0.74533743	0.12562741	3104.4976
277.00684	0.75079316	0.12689723	3104.3069
277.90771	0.75020206	0.1281486	3100.2756
278.80859	0.75399655	0.1293353	3105.0122
279.70947	0.75745207	0.13035478	3098.7148
280.61035	0.75813842	0.13175444	3105.1787
281.51123	0.76401949	0.13276605	3107.8381
282.41211	0.76410437	0.13370974	3104.6099
283.31299	0.76738542	0.13478167	3106.3296
284.21387	0.77062249	0.13602223	3112.5288
285.11475	0.77415311	0.1372405	3111.2261
286.01563	0.77655774	0.13838258	3114.5823
286.9165	0.78076142	0.13954286	3116.9768
287.81738	0.78316885	0.1405755	3119.0117
288.71826	0.78394026	0.14165454	3121.0703
289.61914	0.78746271	0.14279425	3121.2693
290.52002	0.78974944	0.14404345	3117.5596
291.4209	0.79387468	0.14525397	3127.2957
292.32178	0.79801345	0.14632504	3125.7205
293.22266	0.79648024	0.14744218	3123.4048
294.12354	0.79738504	0.1482895	3121.3967
295.02441	0.80353665	0.14912558	3121.1235
295.92529	0.80697525	0.15009126	3128.6685
296.82617	0.8085748	0.15111622	3131.3313
297.72705	0.80814946	0.15223092	3131.8855
298.62793	0.81542075	0.15327123	3126.6624
299.52881	0.81607276	0.1545258	3143.6626
300.42969	0.8212117	0.15553702	3134.7615
301.33057	0.81979126	0.15653288	3134.6182
302.23145	0.82525361	0.15804966	3144.9927
303.13232	0.82619959	0.1593722	3134.3545
304.0332	0.82982075	0.16052687	3139.2732
304.93408	0.83558708	0.16158757	3148.6714
305.83496	0.83679616	0.16265072	3143.7844
306.73584	0.83612001	0.16402881	3141.7566
307.63672	0.84247714	0.16508448	3144.5122
308.5376	0.84223086	0.16610235	3149.2048
309.43848	0.84412074	0.16710258	3139.0732
310.33936	0.84960723	0.16807957	3150.1611
311.24023	0.8526724	0.16933812	3154.8445
312.14111	0.85223556	0.17052369	3145.3479
313.04199	0.85773522	0.17162627	3152.6541
313.94287	0.86232549	0.17287211	3157.4241
314.84375	0.86431766	0.17392936	3149.9827
315.74463	0.86550212	0.17503595	3159.8413
316.64551	0.86672163	0.17612922	3164.6504
317.54639	0.86895961	0.17719105	3160.4504
318.44727	0.8726263	0.17830813	3163.4534
319.34814	0.87430227	0.17931925	3159.6228
320.24902	0.87878096	0.18041645	3160.1919
321.1499	0.88429612	0.18163387	3164.8933
322.05078	0.88431907	0.18273833	3167.6038
322.95166	0.88771307	0.18397269	3166.531
323.85254	0.89068472	0.18500471	3163.7236
324.75342	0.89207619	0.18596892	3171.9978
325.6543	0.89502305	0.18713707	3174.6677
326.55518	0.89643228	0.18823721	3173.5144
327.45605	0.90136951	0.18954778	3179.5615
328.35693	0.90449202	0.19086187	3183.0093
329.25781	0.90889323	0.19215024	3186.1499
330.15869	0.90713942	0.19322284	3172.3481
331.05957	0.91046041	0.19414662	3174.0688
331.96045	0.91289222	0.19505951	3171.9214
332.86133	0.91845578	0.19586468	3177.8005
333.76221	0.91690046	0.19677496	3176.627
334.66309	0.92195362	0.19775644	3179.6282
335.56396	0.92443341	0.19879839	3179.2468
336.46484	0.92847443	0.19982354	3183.7524
337.36572	0.93266422	0.20097163	3195.4294
338.2666	0.92914522	0.2021206	3184.4226
339.16748	0.93517739	0.20313178	3189.2368
340.06836	0.93901879	0.20421506	3192.2122
340.96924	0.93953615	0.20559619	3195.2715
341.87012	0.94221544	0.206595	3184.1375
342.771	0.94518352	0.2075863	3192.6758
343.67188	0.9459002	0.20864797	3196.6699
344.57275	0.95478559	0.20985903	3201.4424
345.47363	0.9562782	0.21111503	3194.4119
346.37451	0.95873094	0.21229343	3200.3701
347.27539	0.95927572	0.21341661	3197.655
348.17627	0.9631682	0.21457103	3206.4119
349.07715	0.9645049	0.21569701	3201.9258
349.97803	0.97090399	0.21670538	3208.0095
350.87891	0.96920115	0.21793918	3203.4385
351.77979	0.97409248	0.21916306	3209.554
352.68066	0.97461659	0.22031304	3207.6072
353.58154	0.97594565	0.22139169	3204.1382
354.48242	0.98336899	0.22252078	3209.9749
355.3833	0.984083	0.2234576	3208.8677
356.28418	0.98524988	0.22439213	3205.9067
357.18506	0.99057311	0.22548914	3213.3872
358.08594	0.99409842	0.22646928	3214.8635
358.98682	0.99459362	0.22750132	3216.3035
359.8877	0.99814779	0.22861737	3224.0017
360.78857	0.99770588	0.22987224	3213.3042
361.68945	1.0028629	0.2310787	3219.1731
362.59033	1.007066	0.23239388	3226.9985
363.49121	1.0096949	0.23357129	3228.6711
364.39209	1.0118084	0.23467527	3220.0398
365.29297	1.012329	0.23557833	3212.6123
366.19385	1.016381	0.2365488	3219.978
367.09473	1.0192397	0.23759225	3223.3628
367.99561	1.0225965	0.23856914	3230.5742
368.89648	1.0243815	0.23966849	3228.9424
369.79736	1.029246	0.24067236	3227.8721
370.69824	1.0303209	0.24171433	3229.8105
371.59912	1.0333623	0.24294326	3231.7214
372.5	1.0349604	0.24392924	3231.0667
373.40088	1.0384049	0.24500638	3236.3333
374.30176	1.0393636	0.24620806	3235.395
375.20264	1.0432307	0.24719846	3239.3291
376.10352	1.0452759	0.24840261	3239.7661
377.00439	1.0490284	0.24963759	3241.8933
377.90527	1.0511593	0.25060666	3236.2346
378.80615	1.0553907	0.25161338	3241.373
379.70703	1.0565363	0.25254485	3238.5684
380.60791	1.0596043	0.25366554	3243.2427
381.50879	1.0611744	0.25467175	3243.1563
382.40967	1.0655746	0.25577152	3250.4031
383.31055	1.0679162	0.25696927	3248.9136
384.21143	1.0735723	0.25812665	3253.4558
385.1123	1.0734278	0.25933883	3245.9792
386.01318	1.0764747	0.26032421	3251.6836
386.91406	1.0779115	0.26148036	3247.0925
387.81494	1.0822934	0.26265192	3257.2673
388.71582	1.0835917	0.26392415	3257.8799
389.6167	1.0887121	0.2652719	3256.3054
390.51758	1.0892651	0.26634952	3249.4709
391.41846	1.0943425	0.26733464	3259.718
392.31934	1.0988494	0.26849732	3262.8882
393.22021	1.0980226	0.26939145	3251.3679
394.12109	1.0994133	0.2703872	3254.2249
395.02197	1.1023151	0.27135149	3252.7312
395.92285	1.1062024	0.27239287	3259.875
396.82373	1.1059153	0.27337685	3262.0437
397.72461	1.1125106	0.27474925	3268.9709
398.62549	1.1169379	0.27575639	3267.6326
399.52637	1.1161063	0.27664801	3262.1458
400.42725	1.1198124	0.27770302	3268.061
401.32813	1.1244149	0.27888346	3274.7346
402.229	1.1259403	0.28000498	3268.3901
403.12988	1.1261264	0.28115106	3271.1042
404.03076	1.1293267	0.28211635	3264.9087
404.93164	1.1339949	0.28287497	3267.4534
405.83252	1.1338253	0.28389555	3268.8245
406.7334	1.1407198	0.28494951	3277.2468
407.63428	1.142794	0.28607726	3281.6177
408.53516	1.1455896	0.28715128	3277.0479
409.43604	1.1448108	0.28819767	3275.7222
410.33691	1.1478263	0.28928116	3279.6638
411.23779	1.1507639	0.2904985	3283.53
412.13867	1.1538216	0.29160115	3276.9106
413.03955	1.1581033	0.29268447	3284.6165
413.94043	1.1589055	0.2936562	3279.4084
414.84131	1.1612206	0.29477894	3284.1738
415.74219	1.1684591	0.29584444	3286.1494
416.64307	1.1681259	0.29703888	3289.6008
417.54395	1.1714973	0.29812768	3286.9119
418.44482	1.1732602	0.29941753	3290.0945
419.3457	1.1743906	0.30044711	3285.3457
420.24658	1.1780425	0.30162218	3290.6042
421.14746	1.1861622	0.30272534	3287.0056
422.04834	1.1868304	0.30376664	3297.5798
422.94922	1.1869485	0.30476958	3291.8613
423.8501	1.1912682	0.30596238	3304.0381
424.75098	1.1928127	0.30721942	3294.769
425.65186	1.1942027	0.30838141	3297.4604
426.55273	1.1970918	0.30945861	3303.4812
427.45361	1.1993052	0.31039709	3293.9573
428.35449	1.204511	0.31146294	3299.5081
429.25537	1.2044994	0.31236368	3297.4802
430.15625	1.2095515	0.31349406	3301.0024
431.05713	1.2081398	0.31455541	3300.3784
431.95801	1.2143075	0.31568944	3300.7253
432.85889	1.2150003	0.31659093	3295.3184
433.75977	1.2187127	0.31771526	3310.3408
434.66064	1.2221869	0.31908673	3309.5552
435.56152	1.2262508	0.32022771	3311.3809
436.4624	1.2290411	0.321408	3311.1782
437.36328	1.2286043	0.32247365	3307.4641
438.26416	1.2319531	0.32357427	3310.8057
439.16504	1.2366567	0.32464671	3305.2483
440.06592	1.2392144	0.3255921	3312.1406
440.9668	1.2436121	0.32659903	3315.7583
441.86768	1.2462946	0.32747066	3313.27
442.76855	1.2471867	0.32857662	3318.4229
443.66943	1.2481685	0.32974699	3315.4392
444.57031	1.2500576	0.33110279	3321.6479
445.47119	1.254343	0.33209768	3312.9365
446.37207	1.2574047	0.33327109	3325.7297
447.27295	1.2606989	0.33427227	3319.0107
448.17383	1.263061	0.33525488	3320.8557
449.07471	1.2633134	0.33615342	3318.7529
449.97559	1.2664135	0.3372106	3318.5303
450.87646	1.2702229	0.33816275	3318.9385
451.77734	1.2740878	0.33944917	3329.4211
452.67822	1.2776256	0.34040517	3324.7097
453.5791	1.2782787	0.34140581	3329.9233
454.47998	1.282541	0.34238267	3322.907
455.38086	1.2852014	0.34351474	3333.9099
456.28174	1.2876805	0.34470719	3332.7063
457.18262	1.2891282	0.34580749	3333.2236
458.0835	1.2938533	0.34700939	3333.1565
458.98438	1.2955645	0.34813526	3340.8677
459.88525	1.299989	0.34926668	3334.0168
460.78613	1.2995826	0.35037649	3339.1621
461.68701	1.3037788	0.35156596	3334.2256
462.58789	1.3042899	0.35275501	3340.3335
463.48877	1.3081372	0.35392907	3341.4177
464.38965	1.3113563	0.35514227	3345.1548
465.29053	1.3120313	0.35623205	3335.3542
466.19141	1.3168619	0.35743195	3344.991
467.09229	1.3205557	0.35868889	3343.1775
467.99316	1.3216559	0.35979605	3339.9463
468.89404	1.3242576	0.36086929	3343.6436
469.79492	1.3261728	0.36177501	3338.9688
470.6958	1.3308214	0.36290208	3347.4109
471.59668	1.3297197	0.36379474	3339.6084
472.49756	1.3357033	0.36466596	3341.9695
473.39844	1.339802	0.36569625	3352.6743
474.29932	1.3434349	0.36682659	3349.9409
475.2002	1.3440242	0.36785632	3345.7349
476.10107	1.3473324	0.36893842	3348.3638
477.00195	1.3493752	0.36980954	3351.249
477.90283	1.3525203	0.37091401	3355.7998
478.80371	1.3551091	0.37198842	3353.5105
479.70459	1.3589861	0.37320048	3357.9438
480.60547	1.3600012	0.37425977	3357.1794
481.50635	1.3644497	0.37538269	3361.7917
482.40723	1.3671194	0.37663817	3354.5486
483.30811	1.3685811	0.37759688	3360.0513
484.20898	1.3706882	0.37872192	3359.3462
485.10986	1.3737818	0.37993884	3361.876
486.01074	1.3748106	0.3810856	3366.3899
486.91162	1.3802974	0.38233775	3367.5293
487.8125	1.3793191	0.38354611	3359.9956
488.71338	1.3847665	0.38476294	3364.1345
489.61426	1.3867379	0.38592386	3368.1091
490.51514	1.3907247	0.38716042	3366.7463
491.41602	1.3935603	0.38832924	3365.8242
492.31689	1.3922544	0.3893953	3367.2471
493.21777	1.3955085	0.39049843	3363.5642
494.11865	1.4023302	0.39145955	3368.364
495.01953	1.4040935	0.39266515	3376.0415
495.92041	1.4040123	0.39382768	3367.8599
496.82129	1.4080882	0.39494321	3366.7688
497.72217	1.4087126	0.395913	3374.7986
498.62305	1.4144453	0.39715359	3371.1418
499.52393	1.4170246	0.3981182	3374.8831
500.4248	1.4204208	0.39933819	3380.8735
501.32568	1.422392	0.40030193	3373.0598
502.22656	1.4245032	0.40154839	3372.8662
503.12744	1.428097	0.40262076	3381.907
504.02832	1.4319514	0.40359917	3380.0413
504.9292	1.4328799	0.4047288	3379.8206
505.83008	1.4374362	0.40580902	3381.1416
506.73096	1.4366059	0.40671691	3381.2207
507.63184	1.4415573	0.40796524	3379.896
508.53271	1.4421684	0.4090316	3380.9226
509.43359	1.4436494	0.41006818	3381.1968
510.33447	1.4465292	0.41121867	3384.4961
511.23535	1.450826	0.4122867	3388.9543
512.13623	1.4545802	0.41333506	3382.5847
513.03711	1.4579984	0.41447395	3384.8467
513.93799	1.4618542	0.41539827	3386.6021
514.83887	1.4628081	0.41637889	3393.313
515.73975	1.4636967	0.41738597	3392.5938
516.64063	1.4679136	0.41847986	3390.3723
517.5415	1.4720018	0.41966528	3397.7607
518.44238	1.4740627	0.42093498	3394.9131
519.34326	1.4770621	0.42220402	3394.0776
520.24414	1.4780143	0.42324391	3385.887
521.14502	1.4807676	0.42418873	3389.1287
522.0459	1.484911	0.42509627	3390.1833
522.94678	1.484822	0.42610162	3398.0437
523.84766	1.4891845	0.42720297	3397.3511
524.74854	1.491757	0.4282831	3394.7769
525.64941	1.4958662	0.42958039	3405.0791
526.55029	1.4970022	0.43074661	3406.833
527.45117	1.5016106	0.43200156	3400.897
528.35205	1.5025363	0.43294343	3406.959
529.25293	1.5067352	0.43425786	3407.8152
530.15381	1.5083272	0.4355115	3406.5171
531.05469	1.5128055	0.43668535	3402.9905
531.95557	1.5160421	0.43762636	3403.0579
532.85645	1.5140369	0.43865925	3405.9258
533.75732	1.5208582	0.43979904	3406.0186
534.6582	1.5228572	0.4410646	3415.0681
535.55908	1.525625	0.44226497	3411.0037
536.45996	1.529829	0.44327262	3414.626
537.36084	1.5328875	0.44454646	3416.4614
538.26172	1.5299222	0.44564191	3413.4795
539.1626	1.5362073	0.44690421	3412.2205
540.06348	1.5393901	0.44787896	3414.4009
540.96436	1.5397569	0.44896927	3413.6023
541.86523	1.5424373	0.44996837	3414.1931
542.76611	1.5470581	0.45114195	3417.3779
543.66699	1.5505267	0.4523651	3422.165
544.56787	1.5502112	0.45346937	3417.7573
545.46875	1.5545788	0.45461327	3419.7256
546.36963	1.5587	0.4558202	3417.0139
547.27051	1.5588309	0.45677644	3416.3787
548.17139	1.5635761	0.45776245	3420.6929
549.07227	1.5672396	0.45880738	3423.093
549.97314	1.5671567	0.45988584	3423.5835
550.87402	1.5722668	0.46098885	3425.0186
551.7749	1.5726148	0.46185344	3418.9519
552.67578	1.5745522	0.46295202	3422.4465
553.57666	1.5811547	0.46407762	3431.4365
554.47754	1.5767826	0.46513796	3426.0337
555.37842	1.5857016	0.46643451	3431.811
556.2793	1.5857596	0.46770564	3423.4868
557.18018	1.5891423	0.46901077	3427.2041
558.08105	1.5910894	0.47002855	3420.936
558.98193	1.5957868	0.47100842	3428.2356
559.88281	1.5971901	0.47226015	3430.7729
560.78369	1.6008075	0.47373921	3432.488
561.68457	1.6033853	0.47499651	3435.4468
562.58545	1.6044216	0.47625309	3437.418
563.48633	1.6124697	0.4774566	3439.688
564.38721	1.6143888	0.47861686	3436.3062
565.28809	1.6136416	0.47999001	3436.4785
566.18896	1.6165826	0.48124453	3435.6975
567.08984	1.6202462	0.48221773	3435.1563
567.99072	1.621853	0.48333538	3440.9846
568.8916	1.6256328	0.48422518	3435.6353
569.79248	1.6276338	0.48529184	3443.8557
570.69336	1.633117	0.48638505	3440.5176
571.59424	1.6339124	0.48750043	3445.0156
572.49512	1.6355064	0.48870954	3444.771
573.396	1.6366478	0.48974326	3440.3057
574.29688	1.6426786	0.49091366	3442.9312
575.19775	1.6452028	0.49222684	3447.1514
576.09863	1.6458852	0.49340326	3442.8818
576.99951	1.6516069	0.49467638	3446.7185
577.90039	1.6518493	0.49584123	3444.4106
578.80127	1.6529938	0.49692848	3439.6003
579.70215	1.6574374	0.4981128	3444.5471
580.60303	1.6614927	0.49900758	3440.6731
581.50391	1.662917	0.5001055	3448.6611
582.40479	1.665125	0.50105292	3447.9226
583.30566	1.6670706	0.50212163	3446.0891
584.20654	1.6700481	0.50322247	3449.1875
585.10742	1.6717157	0.50426787	3454.4607
586.0083	1.6774552	0.50548446	3453.1138
586.90918	1.6784883	0.50665128	3447.8901
587.81006	1.6818455	0.50767672	3454.8406
588.71094	1.6851757	0.50883752	3463.4539
589.61182	1.6871432	0.50989825	3454.946
590.5127	1.6905107	0.51119542	3461.5605
591.41357	1.6912059	0.51263368	3462.1567
592.31445	1.6932905	0.51395237	3456.4768
593.21533	1.698082	0.51521891	3461.9143
594.11621	1.7001672	0.5163458	3461.2324
595.01709	1.7020544	0.51735383	3448.0762
595.91797	1.7060423	0.51840806	3457.2317
596.81885	1.7114192	0.5195055	3464.2395
597.71973	1.7108622	0.52059066	3460.2693
598.62061	1.7147775	0.52179456	3466.5449
599.52148	1.7176752	0.52286005	3470.677
600.42236	1.7210493	0.52408487	3460.1426
601.32324	1.724328	0.52507496	3462.1809
602.22412	1.7252038	0.52612537	3464.7622
603.125	1.7309678	0.52748263	3469.9097
604.02588	1.729877	0.52886844	3470.7622
604.92676	1.7317913	0.53014088	3470.375
605.82764	1.7369624	0.53133965	3475.1921
606.72852	1.7395531	0.53266329	3471.9592
607.62939	1.7400627	0.53375077	3466.3835
608.53027	1.7440752	0.53487808	3466.241
609.43115	1.7455957	0.53590369	3469.2461
610.33203	1.7482678	0.5370788	3469.8528
611.23291	1.7485733	0.53828865	3474.2783
612.13379	1.7534163	0.53927559	3472.1221
613.03467	1.7561126	0.54031849	3472.6631
613.93555	1.7621144	0.54165775	3475.9993
614.83643	1.7636578	0.54243737	3475.061
615.7373	1.7629632	0.54363221	3472.0496
616.63818	1.7692722	0.54462647	3478.7837
617.53906	1.7692432	0.54575962	3474.2615
618.43994	1.7730485	0.54687077	3480.6545
619.34082	1.777136	0.54815274	3482.6274
620.2417	1.7782668	0.54927355	3472.7651
621.14258	1.7837954	0.55041677	3483.5129
622.04346	1.7840127	0.55148739	3477.5752
622.94434	1.7871941	0.55263525	3479.5955
623.84521	1.7907246	0.55379355	3478.8276
624.74609	1.7939034	0.55490398	3484.1899
625.64697	1.7957458	0.55601072	3482.3647
626.54785	1.7986482	0.55713874	3485.0886
627.44873	1.8012549	0.55837709	3490.1533
628.34961	1.80316	0.55966884	3486.0032
629.25049	1.8058989	0.56098449	3486.4019
630.15137	1.8089802	0.5622915	3486.8357
631.05225	1.8119814	0.56347442	3487.9363
631.95313	1.8148584	0.56469136	3493.6677
632.854	1.8160648	0.56614995	3490.2314
633.75488	1.8204172	0.56724757	3485.469
634.65576	1.8206416	0.56851536	3490.8772
635.55664	1.8263223	0.56963241	3490.135
636.45752	1.8273679	0.57075644	3490.115
637.3584	1.8312117	0.57199329	3489.5691
638.25928	1.8337086	0.57319289	3491.2102
639.16016	1.8364511	0.57434827	3491.4309
640.06104	1.8382281	0.57569391	3495.6367
640.96191	1.8407328	0.57686096	3491.3789
641.86279	1.8455416	0.57795084	3494.2078
642.76367	1.8476369	0.57907081	3497.6633
643.66455	1.8491287	0.58039963	3496.7139
644.56543	1.8512701	0.5817048	3495.1494
645.46631	1.8536944	0.58296233	3496.6375
646.36719	1.8593208	0.58405417	3497.8171
647.26807	1.8615546	0.58524412	3495.9578
648.16895	1.8618861	0.58644158	3497.9819
649.06982	1.8650894	0.58745891	3496.0378
649.9707	1.869911	0.58876777	3504.9392
650.87158	1.8721185	0.58981407	3503.9324
651.77246	1.8757163	0.59104359	3502.2397
652.67334	1.8730958	0.59211266	3497.8169
653.57422	1.8784901	0.59321779	3496.7429
654.4751	1.8811729	0.59426123	3500.7542
655.37598	1.8848127	0.5955556	3510.636
656.27686	1.8867999	0.59685057	3510.3352
657.17773	1.8913783	0.59823281	3507.0254
658.07861	1.8953811	0.5994423	3508.4033
658.97949	1.8940078	0.60049999	3504.4197
659.88037	1.9003814	0.60174775	3512.2876
660.78125	1.8984584	0.6030004	3509.1921
661.68213	1.9037145	0.60430986	3509.3354
662.58301	1.9053055	0.60550636	3503.7458
663.48389	1.9080615	0.60668766	3507.9705
664.38477	1.9098454	0.60787725	3509.4385
665.28564	1.9152188	0.60920352	3505.375
666.18652	1.9152507	0.61035568	3505.4895
667.0874	1.9216337	0.61146742	3514.459
667.98828	1.9222015	0.61272544	3516.4812
668.88916	1.924574	0.61383909	3516.2456
669.79004	1.928804	0.61525154	3519.6003
670.69092	1.930859	0.61662602	3516.6814
671.5918	1.9340073	0.61789399	3519.2314
672.49268	1.9354602	0.61932558	3515.8879
673.39355	1.9393697	0.62052381	3516.2688
674.29443	1.9414421	0.62177932	3513.2632
675.19531	1.942729	0.62287235	3510.5229
676.09619	1.9473952	0.62394947	3520.2324
676.99707	1.9478295	0.62515765	3518.4026
677.89795	1.952224	0.62655061	3524.3618
678.79883	1.9568584	0.62803513	3526.3069
679.69971	1.9553043	0.62915915	3513.6497
680.60059	1.9595701	0.63042051	3516.5583
681.50146	1.96064	0.6316607	3519.7302
682.40234	1.9652741	0.63276911	3520.0938
683.30322	1.9662849	0.63411689	3522.3618
684.2041	1.9719834	0.6355896	3529.7104
685.10498	1.9719375	0.63666552	3515.6826
686.00586	1.9778385	0.6377418	3522.9592
686.90674	1.9764534	0.63877386	3521.2041
687.80762	1.9834033	0.6399622	3525.9417
688.7085	1.985992	0.6411165	3525.635
689.60938	1.9878254	0.64239693	3520.3662
690.51025	1.9895786	0.64354724	3527.2075
691.41113	1.9910136	0.64496171	3532.3862
692.31201	1.9944507	0.64623886	3525.1047
693.21289	1.9982182	0.64748639	3525.844
694.11377	1.9987535	0.64850926	3522.4714
695.01465	2.0020976	0.64960319	3529.4597
695.91553	2.0066783	0.65088159	3532.3198
696.81641	2.0079675	0.65241641	3539.4175
697.71729	2.0094616	0.65395135	3530.7305
698.61816	2.0184069	0.65540069	3533.7664
699.51904	2.0164719	0.65641284	3526.9897
700.41992	2.0196993	0.65770364	3532.2009
701.3208	2.0223918	0.65889913	3541.1057
702.22168	2.0223417	0.66019857	3533.4287
703.12256	2.0287073	0.66153085	3528.9656
704.02344	2.0274696	0.66297317	3534.8979
704.92432	2.0373526	0.6641472	3529.3604
705.8252	2.0354576	0.66548753	3540.4487
706.72607	2.0381496	0.66698819	3539.3621
707.62695	2.042722	0.66832894	3537.5349
708.52783	2.0459156	0.66982663	3541.3137
709.42871	2.0467613	0.6710912	3540.0686
710.32959	2.0485485	0.67210776	3534.355
711.23047	2.0532343	0.67324275	3531.7637
712.13135	2.0520217	0.67455435	3536.5293
713.03223	2.0583255	0.67597067	3544.1531
713.93311	2.0613568	0.67690641	3532.8782
714.83398	2.0649765	0.67818463	3540.6511
715.73486	2.0644672	0.67936641	3541.4031
716.63574	2.0681868	0.68057901	3544.2236
717.53662	2.0670319	0.68197978	3538.7356
718.4375	2.0748098	0.68332994	3547.2642
719.33838	2.0790253	0.68464136	3540.8264
720.23926	2.0792818	0.68580258	3542.283
721.14014	2.0804722	0.68691778	3536.0701
722.04102	2.0822659	0.68814695	3541.3916
722.94189	2.0865364	0.68930203	3538.9529
723.84277	2.0884995	0.6904549	3543.2019
724.74365	2.0947759	0.69161433	3543.8794
725.64453	2.0913818	0.69280976	3543.4214
726.54541	2.0962811	0.69416726	3545.6465
727.44629	2.1010089	0.6954208	3546.4431
728.34717	2.1029139	0.69677651	3547.4922
729.24805	2.1050153	0.69838643	3551.9294
730.14893	2.1080287	0.69968158	3544.6616
731.0498	2.1136093	0.70090717	3546.1013
731.95068	2.1141415	0.70210409	3554.7456
732.85156	2.1152468	0.70344186	3552.7302
733.75244	2.1181755	0.7049613	3550.5466
734.65332	2.1231608	0.70628059	3552.3081
735.5542	2.1237838	0.707681	3554.7517
736.45508	2.1267958	0.70915389	3554.3169
737.35596	2.1303318	0.71051109	3555.8672
738.25684	2.1300848	0.7117821	3547.2209
739.15771	2.1364734	0.7129823	3552.3328
740.05859	2.1382277	0.71418607	3550.5735
740.95947	2.1406703	0.71535391	3550.834
741.86035	2.143127	0.71673661	3556.969
742.76123	2.147393	0.71826851	3553.2849
743.66211	2.1501148	0.7194916	3549.1248
744.56299	2.1522789	0.72055286	3551.8511
745.46387	2.1558077	0.72191024	3553.1738
746.36475	2.1547282	0.72323334	3554.4099
747.26563	2.1589925	0.72474897	3562.8633
748.1665	2.1628549	0.72634137	3563.9761
749.06738	2.1667554	0.72778875	3561.6138
749.96826	2.165638	0.728993	3551.2903
750.86914	2.1695397	0.73047644	3553.803
751.77002	2.1732879	0.73159522	3557.8147
752.6709	2.1762605	0.73303491	3557.0376
753.57178	2.1776133	0.73429	3554.5242
754.47266	2.1826162	0.7355724	3562.0171
755.37354	2.1835885	0.7369628	3562.7739
756.27441	2.1870947	0.73841357	3560.3621
757.17529	2.1900687	0.73980337	3562.46
758.07617	2.1911221	0.74130791	3566.4209
758.97705	2.1958435	0.74257642	3561.8491
759.87793	2.2004063	0.74386549	3553.783
760.77881	2.1992407	0.74514174	3559.6392
761.67969	2.2053084	0.74638498	3567.3379
762.58057	2.2063668	0.7476958	3565.6062
763.48145	2.2065923	0.74908018	3559.8918
764.38232	2.2130659	0.75042504	3570.657
765.2832	2.212641	0.75206214	3573.241
766.18408	2.2190206	0.75372511	3569.7595
767.08496	2.2198217	0.75497007	3561.8625
767.98584	2.2213504	0.75634825	3566.262
768.88672	2.2290072	0.75774938	3572.7485
769.7876	2.2293007	0.75896752	3566.4543
770.68848	2.2298179	0.76019675	3570.5544
771.58936	2.231915	0.7616154	3560.5439
772.49023	2.2362244	0.76299709	3568.6855
773.39111	2.2408941	0.76429391	3571.2036
774.29199	2.2418454	0.76579708	3577.0601
775.19287	2.2431879	0.76728684	3576.0923
776.09375	2.2496474	0.76884097	3575.6548
776.99463	2.2494435	0.77029526	3568.429
777.89551	2.2510185	0.77171832	3572.3013
778.79639	2.2548833	0.77337027	3572.2021
779.69727	2.2578266	0.77510601	3578.4429
780.59814	2.2598774	0.77639538	3569.9514
781.49902	2.2646666	0.77772123	3573.9084
782.3999	2.2677124	0.77899861	3568.6453
783.30078	2.266187	0.78047919	3570.6899
784.20166	2.2704411	0.78191262	3573.2366
785.10254	2.2711093	0.78335339	3573.3779
786.00342	2.2737601	0.7847271	3571.3853
786.9043	2.2784367	0.78620279	3573.0508
787.80518	2.2815256	0.78732133	3571.7412
788.70605	2.284636	0.7886548	3576.675
789.60693	2.2890882	0.78981012	3575.155
790.50781	2.2907701	0.79125315	3580.0112
791.40869	2.291106	0.79250813	3572.429
792.30957	2.2935081	0.79406565	3577.0688
793.21045	2.2965465	0.79567665	3576.7302
794.11133	2.3011079	0.79706663	3576.0051
795.01221	2.3015785	0.7983492	3576.7202
795.91309	2.3049159	0.79976773	3570.9944
796.81396	2.3109705	0.80111426	3579.7944
797.71484	2.3131986	0.80229491	3577.0417
798.61572	2.3118315	0.80371302	3571.4395
799.5166	2.317404	0.80503732	3579.3359
800.41748	2.3184857	0.80651605	3581.624
801.31836	2.3206959	0.80808866	3581.1494
802.21924	2.3259332	0.80957013	3579.4976
803.12012	2.3278718	0.81084633	3575.2253
804.021	2.3326869	0.81223029	3586.9949
804.92188	2.3340943	0.81385255	3583.2683
805.82275	2.332612	0.81538564	3583.4036
806.72363	2.3407629	0.81727314	3586.072
807.62451	2.340903	0.81887901	3577.5674
808.52539	2.3436248	0.82044965	3583.7869
809.42627	2.3481865	0.82189918	3578.8198
810.32715	2.3493123	0.82340419	3581.2727
811.22803	2.3524389	0.82472789	3577.0518
812.12891	2.3536463	0.82609028	3582.2554
813.02979	2.3596172	0.82758838	3588.0798
813.93066	2.3602717	0.82932997	3589.8584
814.83154	2.3626158	0.8310464	3579.8916
815.73242	2.3644366	0.83276629	3585.0398
816.6333	2.3657446	0.83447838	3586.9778
817.53418	2.369827	0.83598042	3581.281
818.43506	2.3738661	0.83737499	3579.4568
819.33594	2.3739719	0.83857507	3576.4155
820.23682	2.377403	0.84006023	3581.5234
821.1377	2.3814385	0.8415848	3587.9587
822.03857	2.3826504	0.84312016	3587.8887
822.93945	2.3851771	0.84457779	3586.7385
823.84033	2.3902788	0.84601611	3586.0981
824.74121	2.3923748	0.84748542	3591.123
825.64209	2.3975513	0.84881318	3586.7314
826.54297	2.3965244	0.85026956	3581.0459
827.44385	2.4027996	0.85168469	3588.8982
828.34473	2.4055443	0.85317343	3592.3062
829.24561	2.4031637	0.85483778	3588.1086
830.14648	2.4091589	0.85657084	3594.5769
831.04736	2.4083281	0.85819691	3589.8831
831.94824	2.4146342	0.85997027	3594.2556
832.84912	2.4156468	0.86139071	3582.2493
833.75	2.423244	0.8629784	3586.7019
834.65088	2.4245594	0.86442518	3591.4016
835.55176	2.4245512	0.86615014	3594.1973
836.45264	2.4294455	0.86787081	3598.1797
837.35352	2.4308283	0.86965042	3592.7493
838.25439	2.4335239	0.87134147	3586.2937
839.15527	2.4361351	0.87282628	3588.6924
840.05615	2.4368334	0.87409836	3586.4155
840.95703	2.4394665	0.87553549	3589.9783
841.85791	2.4458089	0.87721056	3598.5396
842.75879	2.4445701	0.8786031	3592.4626
843.65967	2.4513874	0.88026512	3594.9451
844.56055	2.4522128	0.88177943	3593.8223
845.46143	2.4552236	0.88316667	3584.3044
846.3623	2.4547429	0.88453132	3587.8347
847.26318	2.4610662	0.88616705	3596.491
848.16406	2.4631248	0.88784701	3600.5652
849.06494	2.4633682	0.88976002	3594.1172
849.96582	2.4706595	0.89172077	3594.8906
850.8667	2.4720862	0.89353013	3599.6079
851.76758	2.4717405	0.89517975	3591.8416
852.66846	2.476871	0.89693123	3592.3882
853.56934	2.4788594	0.89846474	3594.5579
854.47021	2.4820714	0.89983571	3589.656
855.37109	2.4826562	0.90118688	3597.7124
856.27197	2.4870822	0.90283459	3597.1719
857.17285	2.4933724	0.90463817	3601.7827
858.07373	2.4948542	0.90619469	3595.9053
858.97461	2.4971442	0.9077186	3593.3013
859.87549	2.4996414	0.90926272	3599.5837
860.77637	2.497849	0.91085428	3590.3137
861.67725	2.5033398	0.91259807	3595.5376
862.57813	2.5080502	0.91437715	3593.6819
863.479	2.5087478	0.91592079	3591.2856
864.37988	2.5113738	0.91755795	3596.9363
865.28076	2.5161846	0.91915864	3600.697
866.18164	2.5164411	0.92078632	3595.1284
867.08252	2.5203338	0.92240286	3592.1289
867.9834	2.5239005	0.92389059	3595.6008
868.88428	2.5231895	0.9254005	3591.438
869.78516	2.5307169	0.92688733	3601.0825
870.68604	2.5304344	0.92862141	3601.0715
871.58691	2.532968	0.93018889	3597.7781
872.48779	2.5369205	0.93187362	3602.1609
873.38867	2.5374546	0.93368232	3597.9714
874.28955	2.5429888	0.93515271	3594.5242
875.19043	2.5402846	0.93667853	3598.6318
876.09131	2.5490935	0.93851918	3606.436
876.99219	2.5503829	0.94066113	3605.1079
877.89307	2.5532479	0.9429931	3603.4485
878.79395	2.5559192	0.94483685	3596.8254
879.69482	2.5600317	0.94650662	3601.9324
880.5957	2.5617628	0.94844115	3602.9092
881.49658	2.5655551	0.95020252	3601.6296
882.39746	2.5680859	0.95203775	3603.896
883.29834	2.5682642	0.9534058	3592.4036
884.19922	2.5690315	0.95482969	3594.0322
885.1001	2.5756834	0.95644838	3604.6396
886.00098	2.5768349	0.95828944	3603.9351
886.90186	2.5778768	0.96023196	3599.3745
887.80273	2.581578	0.96182442	3595.3718
888.70361	2.5834737	0.96348387	3602.1538
889.60449	2.5880742	0.96550149	3598.1294
890.50537	2.5897665	0.96744055	3599.1863
891.40625	2.593411	0.96921009	3601.7666
892.30713	2.5949688	0.97101313	3599.2312
893.20801	2.598963	0.97274739	3605.5879
894.10889	2.6032734	0.97453898	3602.3035
895.00977	2.6056457	0.97620499	3601.2581
895.91064	2.6038713	0.97783124	3599.8191
896.81152	2.6093488	0.97937524	3597.0879
897.7124	2.6111293	0.98109472	3603.8518
898.61328	2.6137457	0.98298818	3599.2378
899.51416	2.6206007	0.98480767	3602.9995
900.41504	2.6204338	0.98668814	3603.2915
901.31592	2.6228645	0.98883253	3604.563
902.2168	2.6255045	0.99091697	3602.1794
903.11768	2.6262913	0.99301469	3604.3047
904.01855	2.6291006	0.99504262	3599.6802
904.91943	2.6336954	0.99689102	3600.1108
905.82031	2.6369431	0.99891478	3600.3228
906.72119	2.6359169	1.0005809	3595.0569
907.62207	2.6435549	1.0026381	3602.7131
908.52295	2.6473446	1.0042871	3596.0403
909.42383	2.6481996	1.0061574	3606.7212
910.32471	2.6523685	1.0079067	3605.2014
911.22559	2.6531951	1.0099183	3598.3254
912.12646	2.6551356	1.011626	3594.7498
913.02734	2.6551614	1.0136732	3601.4304
913.92822	2.663167	1.0156116	3600.656
914.8291	2.6650305	1.0174266	3602.054
915.72998	2.6639047	1.0190976	3598.5491
916.63086	2.668107	1.0210326	3602.6614
917.53174	2.6704972	1.0229968	3595.0381
918.43262	2.6708672	1.0246977	3592.9922
919.3335	2.6751385	1.02636	3596.1021
920.23438	2.6783576	1.0284082	3603.4309
921.13525	2.6828122	1.0307455	3606.1306
922.03613	2.6836221	1.0329534	3606.0044
922.93701	2.6868188	1.0356448	3603.217
923.83789	2.6895244	1.0379435	3600.281
924.73877	2.6928959	1.0400748	3602.8557
925.63965	2.6954699	1.0420423	3600.5081
926.54053	2.6961844	1.0441356	3601.592
927.44141	2.7026477	1.0462596	3603.4136
928.34229	2.7030859	1.0484463	3600.5474
929.24316	2.7065916	1.0507673	3602.1311
930.14404	2.7080586	1.0529642	3599.0398
931.04492	2.7125897	1.0552881	3604.6328
931.9458	2.7142527	1.0573602	3593.564
932.84668	2.7196958	1.0591314	3597.2434
933.74756	2.7170808	1.0608592	3593.2842
934.64844	2.7225602	1.0629305	3597.7717
935.54932	2.725908	1.0646073	3594.1621
936.4502	2.7272778	1.0662224	3598.8516
937.35107	2.7293289	1.0682421	3602.5149
938.25195	2.7328806	1.0702821	3597.5273
939.15283	2.736937	1.0723029	3595.0564
940.05371	2.7380853	1.0745254	3595.3379
940.95459	2.7407498	1.0769557	3599.8975
941.85547	2.7418432	1.0789599	3592.127
942.75635	2.7476411	1.0808046	3594.5513
943.65723	2.7516723	1.0829605	3600.23
944.55811	2.7526836	1.0853485	3601.3743
945.45898	2.7568285	1.0875996	3593.6487
946.35986	2.7538865	1.0894251	3589.1711
947.26074	2.7589421	1.091159	3596.3186
948.16162	2.7640185	1.0932839	3601.3091
949.0625	2.764128	1.0955836	3592.9045
949.96338	2.7681246	1.0977879	3595.1243
950.86426	2.7705359	1.1003094	3601.2266
951.76514	2.7718368	1.1026864	3593.7075
952.66602	2.7784684	1.1049591	3597.8552
953.56689	2.776376	1.1072488	3591.2283
954.46777	2.7832162	1.1096145	3599.3687
955.36865	2.7860074	1.1115807	3591.9636
956.26953	2.7841754	1.1136922	3595.7878
957.17041	2.7898626	1.116107	3600.7734
958.07129	2.7938926	1.1185396	3595.4592
958.97217	2.7952168	1.1213136	3594.2778
959.87305	2.8009753	1.1238954	3589.1553
960.77393	2.7988853	1.126279	3590.6799
961.6748	2.8030527	1.1287857	3596.8076
962.57568	2.809041	1.1313109	3591.054
963.47656	2.8075173	1.1335053	3583.7415
964.37744	2.8126147	1.1356649	3590.4756
965.27832	2.8146968	1.1377726	3585.8235
966.1792	2.8157632	1.14022	3593.0515
967.08008	2.8184822	1.1429902	3595.1157
967.98096	2.8248525	1.1455243	3594.7825
968.88184	2.8243282	1.1475716	3584.3508
969.78271	2.8285942	1.1497145	3588.9409
970.68359	2.8287425	1.1522241	3589.062
971.58447	2.8329811	1.1545259	3584.2393
972.48535	2.8371739	1.1566792	3589.3818
973.38623	2.8376262	1.1589925	3584.1504
974.28711	2.8419368	1.1613392	3586.7231
975.18799	2.8454738	1.1636528	3587.7163
976.08887	2.8466108	1.1661793	3587.4802
976.98975	2.8500314	1.1685848	3586.6086
977.89063	2.8530593	1.1711	3586.2166
978.7915	2.8542981	1.173337	3580.1111
979.69238	2.8587365	1.1755476	3582.6719
980.59326	2.8597226	1.1777768	3582.4126
981.49414	2.86446	1.1801162	3587.7732
982.39502	2.8640728	1.1827772	3590.3203
983.2959	2.8708351	1.1851521	3582.2285
984.19678	2.8736212	1.1875596	3582.8901
985.09766	2.8738739	1.1900486	3581.9016
985.99854	2.8767185	1.1931225	3580.0811
986.89941	2.8781514	1.1957699	3576.7356
987.80029	2.8829746	1.198372	3573.7896
988.70117	2.8834329	1.2009075	3576.8059
989.60205	2.8861802	1.2034554	3575.0422
990.50293	2.8888214	1.2059622	3574.2192
991.40381	2.8925061	1.2082117	3578.9675
992.30469	2.8938363	1.2109548	3576.4001
993.20557	2.9015193	1.2139249	3577.7849
994.10645	2.8987982	1.2168118	3570.9773
995.00732	2.9047799	1.2198654	3582.5098
995.9082	2.907325	1.222694	3570.2708
996.80908	2.9096148	1.2252033	3569.2578
997.70996	2.9124534	1.2275101	3568.8906
998.61084	2.9149237	1.2301414	3568.127
999.51172	2.9194613	1.2325895	3567.2688
1000.4126	2.9216177	1.2346021	3567.7358
1001.3135	2.9197199	1.2370342	3563.7214
1002.2144	2.9248912	1.2396609	3566.8992
1003.1152	2.9285626	1.2422019	3564.3149
1004.0161	2.9291904	1.2445859	3560.7307
1004.917	2.9332597	1.2472391	3563.4258
1005.8179	2.9375803	1.2500048	3562.1611
1006.7188	2.9391432	1.2526646	3562.0171
1007.6196	2.9419031	1.2554857	3566.7253
1008.5205	2.9427888	1.2583841	3559.4402
1009.4214	2.9474025	1.2610714	3564.5503
1010.3223	2.948101	1.2636738	3552.7327
1011.2231	2.9533916	1.2662008	3556.3186
1012.124	2.9563189	1.2687023	3555.2283
1013.0249	2.9580221	1.2712917	3551.593
1013.9258	2.9616232	1.2741148	3554.1023
1014.8267	2.9627013	1.2765651	3545.5029
1015.7275	2.9635215	1.2792187	3554.0845
1016.6284	2.968322	1.2821321	3552.7417
1017.5293	2.9705768	1.2844799	3548.9622
1018.4302	2.9742672	1.287097	3554.5508
1019.3311	2.9783881	1.2901255	3548.4417
1020.2319	2.9806082	1.2930901	3544.7644
1021.1328	2.9820642	1.2957332	3540.9727
1022.0337	2.9877396	1.2977898	3542.5986
1022.9346	2.9859464	1.2996058	3530.8147
1023.8354	2.9870741	1.3010331	3524.3359
1024.7363	2.9923179	1.3026601	3539.4014
1025.6372	2.995682	1.3049184	3547.542
1026.5381	2.9967909	1.3079135	3539.6538
1027.439	3.0006936	1.3108652	3542.0334
1028.3398	3.0037763	1.3139367	3536.7009
1029.2407	3.006248	1.3169137	3534.6079
1030.1416	3.0073133	1.319631	3538.0376
1031.0425	3.0118008	1.3221993	3534.4929
1031.9434	3.0156872	1.3251495	3531.8179
1032.8442	3.0163486	1.3277559	3530.1553
1033.7451	3.0184641	1.3305174	3529.5049
1034.646	3.0231886	1.3337946	3530.3064
1035.5469	3.0236039	1.3367369	3516.969
1036.4478	3.0281618	1.3391095	3521.0886
1037.3486	3.0312383	1.3415787	3525.051
1038.2495	3.0348055	1.3443322	3525.8997
1039.1504	3.034678	1.3469557	3518.4126
1040.0513	3.0355005	1.3497375	3521.2737
1040.9521	3.0423591	1.3526293	3516.3843
1041.853	3.0448253	1.3551053	3511.6372
1042.7539	3.0478511	1.3579122	3508.3176
1043.6548	3.05019	1.3604954	3508.6824
1044.5557	3.0534451	1.3633751	3516.1021
1045.4565	3.0574389	1.3660824	3509.5237
1046.3574	3.0568635	1.3687663	3504.302
1047.2583	3.0609128	1.3715538	3511.4856
1048.1592	3.0622954	1.3744967	3504.8845
1049.0601	3.0634573	1.3773324	3499.6355
1049.9609	3.0697341	1.3804773	3502.8403
1050.8618	3.0704386	1.3833085	3493.5059
1051.7627	3.0745702	1.3863083	3497.0552
1052.6636	3.0750639	1.3894564	3496.2336
1053.5645	3.0781054	1.3925651	3489.8054
1054.4653	3.0825562	1.395548	3489.2715
1055.3662	3.0823162	1.3986191	3485.823
1056.2671	3.0877509	1.4013457	3492.9783
1057.168	3.0904946	1.4040412	3483.5686
1058.0688	3.0926723	1.406647	3482.2749
1058.9697	3.0955951	1.4095681	3478.8345
1059.8706	3.0984921	1.4127042	3478.1238
1060.7715	3.1015952	1.415452	3471.2864
1061.6724	3.1040771	1.4179848	3471.4104
1062.5732	3.1075649	1.4208201	3470.2998
1063.4741	3.1082342	1.4237304	3470.7776
1064.375	3.1126347	1.4267751	3461.8843
1065.2759	3.1156375	1.4297829	3464.1814
1066.1768	3.1172175	1.4332311	3463.6206
1067.0776	3.1221404	1.4364851	3452.8843
1067.9785	3.124126	1.4395033	3456.7107
1068.8794	3.1248617	1.4422317	3450.989
1069.7803	3.1288557	1.4454751	3452.1169
1070.6812	3.1295226	1.448792	3442.7871
1071.582	3.1354744	1.4513807	3444.6094
1072.4829	3.1353018	1.4541423	3438.2583
1073.3838	3.137795	1.4569389	3433.6506
1074.2847	3.1437292	1.4597299	3437.0557
1075.1855	3.1434164	1.462853	3434.2686
1076.0864	3.1456089	1.4662563	3426.6245
1076.9873	3.1517141	1.4688878	3422.0801
1077.8882	3.1515472	1.4717572	3422.9578
1078.7891	3.1584554	1.4750818	3422.7463
1079.6899	3.159416	1.478327	3417.2754
1080.5908	3.1645668	1.4813992	3414.7444
1081.4917	3.1635625	1.4843678	3409.8096
1082.3926	3.1645806	1.4870028	3408.4377
1083.2935	3.1725035	1.489611	3401.2544
1084.1943	3.17066	1.4924252	3398.6921
1085.0952	3.1720014	1.4953752	3392.5027
1085.9961	3.1757023	1.4982127	3388.657
1086.897	3.1794648	1.5009743	3385.4233
1087.7979	3.1821713	1.5040991	3379.7957
1088.6987	3.1828566	1.507495	3376.2791
1089.5996	3.1854188	1.5108216	3371.0222
1090.5005	3.1904967	1.5140383	3359.2593
1091.4014	3.192625	1.5170869	3352.3726
1092.3022	3.195823	1.5205356	3348.165
1093.2031	3.2012558	1.5240514	3345.2007
1094.104	3.204179	1.5270722	3337.478
1095.0049	3.203305	1.5299163	3326.1846
1095.9058	3.2064695	1.5324159	3320.908
1096.8066	3.2115567	1.5354102	3325.8032
1097.7075	3.2125804	1.5388123	3308.8772
1098.6084	3.2134073	1.5419716	3302.9788
1099.5093	3.2176881	1.5461218	3293.6099
1100.4102	3.2216709	1.5506895	3271.7476
1101.311	3.2262106	1.556114	3246.5793
1102.2119	3.2263989	1.5612645	3224.4541
1103.1128	3.2289593	1.5658309	3199.645
1104.0137	3.2370467	1.5872699	2995.9138