File: datasets/am_bench_2022/raw_data/90-XY.17-4/specimen.dat
MTS793|MPT|ENU|1|2|.|/|:|1|0|0|A

Operator Information						Time:	11.340332	Sec	11/3/2021 10:33:33 AM
Operator	Nick Derimow
Project	AM Bench 2022 mini-tensile challenge
Specimen ID	90-XY.17-4
Material	PBF-L Inconel 625
Specimen Width	2.54	mm
Specimen Thickness	1.51	mm
Notes
Operator Information End

Data Acquisition						Time:	973.16431	Sec	11/3/2021 10:49:35 AM
Time	Axial Displacement	Axial Extensometer	Axial Force
Sec	mm	mm	N
11.453857	0.00072669692	-6.384556e-05	45.652412
12.254639	0.001267814	7.2593386e-05	54.233467
13.05542	0.0056979153	2.4895793e-05	63.39159
13.856201	0.0066852849	0.00019467152	72.058319
14.656982	0.0081930775	0.00012191883	86.226181
15.457764	0.010899226	0.00028202269	97.548889
16.258545	0.011411249	0.00027315502	106.28558
17.059326	0.015524589	0.00035573734	117.83807
17.860107	0.018401463	0.00037279245	122.88345
18.660889	0.0196619	0.00040721006	141.55856
19.46167	0.024317177	0.000452409	150.98416
20.262451	0.026987059	0.00050045899	160.9286
21.063232	0.028902994	0.00064643763	172.77986
21.864014	0.031948701	0.00062579697	182.74669
22.664795	0.035278741	0.00073919899	194.75797
23.465576	0.035364386	0.00079253211	210.82025
24.266357	0.040098287	0.00087943248	225.49431
25.067139	0.038205966	0.00094855041	235.82443
25.86792	0.041844163	0.00096926896	249.9231
26.668701	0.045245968	0.0010457989	270.87219
27.469482	0.048731524	0.0010839198	282.25754
28.270264	0.048569251	0.0012153769	294.46698
29.071045	0.050750263	0.0012020343	305.41162
29.871826	0.055872075	0.0012510401	325.55392
30.672607	0.057980198	0.0015153177	339.29037
31.473389	0.06085702	0.0013513118	353.22849
32.27417	0.058649577	0.0015183255	368.49786
33.074951	0.064132355	0.0016541498	397.84073
33.875732	0.063028403	0.0017319869	413.91959
34.676514	0.068370268	0.0016922954	430.46616
35.477295	0.068714485	0.001823314	445.93027
36.278076	0.07386601	0.0018832763	464.94528
37.078857	0.077213056	0.0020309526	480.41403
37.879639	0.078428678	0.0021122932	506.74808
38.68042	0.082945034	0.0021678135	521.15118
39.481201	0.084077671	0.0022720487	539.78534
40.281982	0.082207017	0.0023277667	552.85773
41.082764	0.089592211	0.002373731	573.56317
41.883545	0.088428684	0.0025122967	593.1405
42.684326	0.093340233	0.002636394	610.35132
43.485107	0.093614988	0.0026702296	625.33405
44.285889	0.098348588	0.0028108854	652.98895
45.08667	0.097825706	0.0028819374	671.91217
45.887451	0.10283155	0.0030129878	694.94806
46.688232	0.10459499	0.0030827071	714.52771
47.489014	0.10537706	0.003199707	729.4541
48.289795	0.10667684	0.0032555715	755.73346
49.090576	0.11200503	0.0033471812	779.24152
49.891357	0.11337139	0.0035100512	801.71771
50.692139	0.11361194	0.0035908509	820.91907
51.49292	0.11695939	0.0036585878	840.21179
52.293701	0.12258545	0.003786274	866.13501
53.094482	0.1221019	0.0039583682	889.55164
53.895264	0.12425572	0.0039923717	915.65833
54.696045	0.12701944	0.0041780542	943.17847
55.496826	0.13094305	0.0042871619	968.91864
56.297607	0.13332035	0.0043301224	983.41455
57.098389	0.13311735	0.0043682512	1001.494
57.89917	0.13562599	0.0044641076	1025.0061
58.699951	0.13999708	0.004594957	1048.3397
59.500732	0.14080147	0.0047476902	1069.3588
60.301514	0.14711407	0.0048316033	1093.2415
61.102295	0.14895092	0.0049746898	1114.9734
61.903076	0.14930804	0.0050553787	1137.016
62.703857	0.15012966	0.0051739183	1161.0945
63.504639	0.15482202	0.005257186	1185.7079
64.30542	0.15620503	0.0054553291	1212.7826
65.106201	0.15666577	0.0053849583	1224.854
65.906982	0.16078445	0.0055391663	1250.7883
66.707764	0.16000442	0.00565778	1271.4065
67.508545	0.16554448	0.0058957953	1297.6367
68.309326	0.16707844	0.0060491832	1317.7744
69.110107	0.16828279	0.0059496397	1333.6628
69.910889	0.17364837	0.006127778	1362.7568
70.71167	0.17766854	0.0062812478	1395.8768
71.512451	0.17801234	0.0063061379	1409.59
72.313232	0.17955291	0.0064880173	1429.564
73.114014	0.18334745	0.0064673522	1445.8185
73.914795	0.18730052	0.0065772505	1467.4471
74.715576	0.18625213	0.0067833965	1495.7904
75.516357	0.18732551	0.0068303864	1512.1627
76.317139	0.19435342	0.0069299005	1538.3491
77.11792	0.19287723	0.0069216765	1552.8434
77.918701	0.19781296	0.0072557838	1581.614
78.719482	0.20163187	0.0073056626	1600.5544
79.520264	0.20346871	0.0073853107	1628.2402
80.321045	0.20447125	0.0074231541	1644.7615
81.121826	0.20567498	0.0076420442	1677.472
81.922607	0.20955496	0.0077892565	1696.3109
82.723389	0.21003808	0.0078931265	1710.6637
83.52417	0.21322347	0.0079148905	1736.2921
84.324951	0.21770336	0.0080209821	1752.7214
85.125732	0.21796849	0.0081941457	1776.2091
85.926514	0.22136082	0.0082089957	1789.8612
86.727295	0.22620255	0.0083782664	1813.9592
87.528076	0.22672051	0.008315932	1840.1289
88.328857	0.22649267	0.0085266838	1855.1676
89.129639	0.23016672	0.0086295949	1878.5737
89.93042	0.23276883	0.0087290322	1900.3589
90.731201	0.23486073	0.00884338	1924.4348
91.531982	0.23703523	0.0088939136	1939.05
92.332764	0.24168411	0.009116427	1959.3434
93.133545	0.24532337	0.0091574006	1975.0953
93.934326	0.24349104	0.0091712549	1988.7914
94.735107	0.24888802	0.0093424153	2013.7007
95.535889	0.25138047	0.0094158426	2033.874
96.33667	0.25418723	0.0095552905	2056.3352
97.137451	0.25383383	0.009667634	2062.8184
97.938232	0.26055565	0.0097063016	2086.0798
98.739014	0.2598758	0.0097609041	2104.0649
99.539795	0.26416263	0.0099506062	2122.7258
100.34058	0.26367587	0.0099405628	2129.189
101.14136	0.26866159	0.010027004	2149.2483
101.94214	0.26830673	0.010211925	2177.0884
102.74292	0.27259201	0.010175751	2184.9631
103.5437	0.27425486	0.010339363	2202.6348
104.34448	0.27455318	0.01046586	2215.5549
105.14526	0.27897775	0.010575603	2244.7939
105.94604	0.28035811	0.010549753	2250.991
106.74683	0.28580528	0.010710473	2265.0007
107.54761	0.28455135	0.010761023	2279.9211
108.34839	0.28842741	0.010916763	2298.2671
109.14917	0.29143128	0.010918825	2308.4341
109.94995	0.29660943	0.011016883	2315.6528
110.75073	0.29296139	0.011075276	2323.2314
111.55151	0.29719788	0.01117843	2342.7346
112.35229	0.30201706	0.011303617	2351.4597
113.15308	0.30668402	0.011293548	2368.387
113.95386	0.30872345	0.011411516	2378.8401
114.75464	0.31140733	0.011568562	2397.8955
115.55542	0.31293744	0.011760445	2407.521
116.3562	0.31276554	0.011627136	2418.1892
117.15698	0.31355664	0.011644506	2419.4968
117.95776	0.31852841	0.011855583	2438.0461
118.75854	0.32147101	0.011891856	2451.9832
119.55933	0.32340395	0.011914996	2459.9668
120.36011	0.32366273	0.012013623	2470.0789
121.16089	0.32518363	0.012091664	2478.1982
121.96167	0.32756957	0.0122288	2488.6201
122.76245	0.333808	0.01225848	2503.0488
123.56323	0.33646518	0.012291897	2512.7048
124.36401	0.34071586	0.012476994	2523.2874
125.16479	0.34183061	0.012542178	2532.0217
125.96558	0.34225413	0.0126694	2544.1719
126.76636	0.34430897	0.0126142	2555.387
127.56714	0.34719685	0.012804353	2566.0308
128.36792	0.3504101	0.012914693	2574.1619
129.1687	0.35168371	0.012988362	2579.2451
129.96948	0.3571817	0.013001209	2592.1399
130.77026	0.35495701	0.013125688	2602.1499
131.57104	0.35986328	0.01327056	2617.5796
132.37183	0.35974401	0.0133522	2617.4126
133.17261	0.36590731	0.013509484	2624.6724
133.97339	0.36244115	0.013480042	2630.2249
134.77417	0.36964959	0.013684952	2639.4629
135.57495	0.37166667	0.013772553	2655.2014
136.37573	0.37348202	0.013892644	2660.9558
137.17651	0.37653342	0.013986638	2672.4961
137.97729	0.37715423	0.013934047	2674.2246
138.77808	0.38049743	0.014126196	2678.1011
139.57886	0.38756853	0.014269581	2695.5112
140.37964	0.38964668	0.014426108	2709.9026
141.18042	0.38807502	0.014550909	2710.4236
141.9812	0.38707924	0.014609478	2716.761
142.78198	0.39453313	0.014843883	2717.8555
143.58276	0.39935881	0.014917295	2724.812
144.38354	0.39309582	0.014910923	2730.1465
145.18433	0.40045151	0.015244822	2747.47
145.98511	0.40203935	0.015332817	2749.8064
146.78589	0.40338078	0.015401701	2763.7195
147.58667	0.40941763	0.015608191	2769.5247
148.38745	0.40974998	0.01569467	2767.2354
149.18823	0.41169581	0.015899425	2777.9922
149.98901	0.41432062	0.016058611	2787.3196
150.78979	0.41721651	0.016263999	2790.7205
151.59058	0.42026693	0.016309973	2799.7
152.39136	0.42143911	0.016532548	2804.9827
153.19214	0.42576569	0.016796591	2817.0676
153.99292	0.42879701	0.016924199	2820.6292
154.7937	0.43123069	0.017239463	2833.9448
155.59448	0.43178061	0.017364226	2831.9175
156.39526	0.43491852	0.017571807	2838.7073
157.19604	0.43586218	0.017802291	2845.7979
157.99683	0.4410176	0.018057741	2848.7117
158.79761	0.44462281	0.018305104	2854.0791
159.59839	0.44485044	0.018498953	2862.4941
160.39917	0.44606012	0.018755347	2869.1477
161.19995	0.44672561	0.019146856	2876.801
162.00073	0.45000505	0.019380936	2879.9443
162.80151	0.45535615	0.019647406	2888.4685
163.60229	0.45476258	0.02000895	2896.5605
164.40308	0.45905313	0.02034534	2891.9453
165.20386	0.46212322	0.020618707	2904.1338
166.00464	0.46365494	0.020962754	2906.4014
166.80542	0.4689863	0.021337816	2916.4983
167.6062	0.46674895	0.021806564	2921.7561
168.40698	0.46941268	0.022087581	2921.5095
169.20776	0.47101474	0.022471117	2923.1809
170.00854	0.47488552	0.022674505	2926.637
170.80933	0.47413951	0.023176515	2936.4714
171.61011	0.47942355	0.02359616	2948.8521
172.41089	0.48044309	0.024123954	2948.7021
173.21167	0.48620108	0.024537288	2947.5305
174.01245	0.48790005	0.024994615	2958.4255
174.81323	0.49023369	0.02543802	2958.9834
175.61401	0.4921816	0.025913127	2962.865
176.41479	0.49040458	0.026291814	2965.1362
177.21558	0.49602547	0.026772724	2973.115
178.01636	0.49775535	0.027333841	2978.3003
178.81714	0.50465727	0.027848545	2979.1506
179.61792	0.50011837	0.0282834	2986.1384
180.4187	0.5041815	0.028997373	2996.0054
181.21948	0.50948954	0.029478241	2990.3892
182.02026	0.51100695	0.030142732	2997.3022
182.82104	0.51179558	0.030629363	2998.4314
183.62183	0.51468307	0.03126834	2999.0781
184.42261	0.5192256	0.031712994	3003.416
185.22339	0.52151179	0.03235935	3010.0688
186.02417	0.52407801	0.03289517	3012.0999
186.82495	0.52536553	0.033491161	3014.2573
187.62573	0.52464306	0.034071974	3019.749
188.42651	0.53124607	0.034783445	3022.1047
189.22729	0.53181791	0.03536284	3027.8062
190.02808	0.53547597	0.035924476	3033.553
190.82886	0.53817248	0.036719803	3034.4438
191.62964	0.53852105	0.037396409	3035.3647
192.43042	0.5421564	0.038051583	3042.0044
193.2312	0.54489124	0.038778763	3042.9229
194.03198	0.54820347	0.039387736	3047.4294
194.83276	0.55255055	0.040040512	3047.5901
195.63354	0.55456096	0.040690336	3048.4678
196.43433	0.55285174	0.041415025	3051.0625
197.23511	0.55548626	0.042228412	3065.3423
198.03589	0.55755478	0.043147162	3060.0728
198.83667	0.56271672	0.043754384	3060.8271
199.63745	0.56459451	0.044446658	3070.8027
200.43823	0.56905806	0.045263849	3070.5815
201.23901	0.56662971	0.046030488	3072.4568
202.03979	0.56943977	0.046751428	3075.0259
202.84058	0.57351929	0.0474387	3070.5405
203.64136	0.57686204	0.048099622	3079.1145
204.44214	0.57727998	0.04865158	3079.3547
205.24292	0.57859111	0.049539153	3083.6855
206.0437	0.58235782	0.050357867	3087.6187
206.84448	0.58711755	0.051070195	3092.2073
207.64526	0.58591753	0.051745411	3087.8989
208.44604	0.59068894	0.052611187	3091.1821
209.24683	0.59215474	0.053194769	3097.2556
210.04761	0.59482139	0.054125197	3101.5413
210.84839	0.59898186	0.054840267	3105.0073
211.64917	0.60056335	0.055747569	3107.4351
212.44995	0.60001218	0.056577273	3106.9707
213.25073	0.60694915	0.057344016	3112.4221
214.05151	0.60829014	0.058063447	3108.8201
214.85229	0.60828972	0.058877587	3116.2036
215.65308	0.61386514	0.059523433	3121.1465
216.45386	0.61255652	0.060187645	3112.3936
217.25464	0.61762398	0.060922105	3120.5313
218.05542	0.61678028	0.061556682	3113.0408
218.8562	0.62341911	0.062356088	3122.0359
219.65698	0.62326646	0.063139021	3129.9883
220.45776	0.62697428	0.063973553	3137.4055
221.25854	0.62749678	0.064705871	3130.3975
222.05933	0.6320588	0.065660946	3135.0852
222.86011	0.63462281	0.066788584	3142.3035
223.66089	0.63541001	0.067399904	3141.3442
224.46167	0.64059347	0.068108022	3138.4309
225.26245	0.64227623	0.068848833	3143.1462
226.06323	0.64145583	0.069569275	3139.5498
226.86401	0.64666331	0.070303679	3153.835
227.66479	0.64796662	0.071190767	3150.6492
228.46558	0.65088522	0.071880922	3148.1182
229.26636	0.65346646	0.0727432	3152.8408
230.06714	0.65565789	0.073535778	3158.8438
230.86792	0.6559087	0.0743552	3157.9995
231.6687	0.65854311	0.075194538	3162.5479
232.46948	0.6617595	0.07590805	3158.3291
233.27026	0.66640538	0.07667271	3167.6206
234.07104	0.66365141	0.077551119	3163.0269
234.87183	0.66978931	0.078501314	3169.6382
235.67261	0.67124373	0.07930281	3174.4636
236.47339	0.67570525	0.080261938	3170.7078
237.27417	0.67626357	0.081134789	3178.3455
238.07495	0.67928177	0.082022369	3183.0667
238.87573	0.68384135	0.082749359	3172.9968
239.67651	0.68800306	0.083525665	3178.0254
240.47729	0.68358815	0.084319793	3176.687
241.27808	0.69103312	0.085142791	3188.7673
242.07886	0.693775	0.086053796	3190.6206
242.87964	0.69293267	0.08686053	3191.2566
243.68042	0.69796449	0.08773838	3196.8752
244.4812	0.69691962	0.088624127	3195.3818
245.28198	0.69966531	0.089604348	3198.4102
246.08276	0.70460373	0.090305001	3197.6782
246.88354	0.70471376	0.091213249	3198.8499
247.68433	0.70737034	0.09207838	3195.6868
248.48511	0.71222538	0.092872635	3199.3459
249.28589	0.71164739	0.093553439	3197.6072
250.08667	0.71531373	0.094347455	3201.7888
250.88745	0.71779531	0.095021136	3207.7341
251.68823	0.71972007	0.095874071	3208.592
252.48901	0.72617745	0.09672448	3213.1401
253.28979	0.72533292	0.097552732	3215.731
254.09058	0.7281723	0.098432772	3210.9775
254.89136	0.73171604	0.099381492	3221.553
255.69214	0.73466969	0.10018254	3218.5364
256.49292	0.73705071	0.10115357	3224.1724
257.2937	0.73732507	0.10198093	3218.3257
258.09448	0.74155706	0.10266724	3221.5078
258.89526	0.74353856	0.10345517	3225.3237
259.69604	0.7437402	0.10434541	3227.4724
260.49683	0.74890292	0.10523784	3236.3289
261.29761	0.74916291	0.10614111	3231.0281
262.09839	0.75032443	0.10686579	3226.8262
262.89917	0.75518626	0.10769908	3235.5916
263.69995	0.75566137	0.1084018	3228.4292
264.50073	0.7591449	0.10928278	3236.3384
265.30151	0.75996464	0.11010539	3236.5005
266.10229	0.76523602	0.11081792	3236.1658
266.90308	0.76561505	0.11170211	3244.1018
267.70386	0.7673763	0.11258183	3243.9629
268.50464	0.7712872	0.1136672	3249.0784
269.30542	0.7729007	0.11462793	3252.5303
270.1062	0.77264339	0.11547009	3251.1045
270.90698	0.77548599	0.11642423	3245.9387
271.70776	0.77901435	0.11718885	3245.3064
272.50854	0.78514385	0.11806618	3252.9033
273.30933	0.7867983	0.11886211	3256.8289
274.11011	0.78874701	0.11977662	3256.0315
274.91089	0.79029369	0.12070673	3261.6335
275.71167	0.79327196	0.12160674	3262.0842
276.51245	0.79544771	0.12241492	3272.9849
277.31323	0.79828233	0.12336489	3261.5674
278.11401	0.79917359	0.12421387	3261.1746
278.91479	0.80278701	0.12508471	3269.0771
279.71558	0.80296749	0.12611875	3269.5867
280.51636	0.80556649	0.12696752	3268.938
281.31714	0.80976391	0.1277632	3268.3481
282.11792	0.81349552	0.12853116	3271.5449
282.9187	0.81700301	0.12927312	3272.2295
283.71948	0.81705379	0.13003168	3274.1606
284.52026	0.81888914	0.13082455	3274.3616
285.32104	0.82286566	0.13155673	3275.0962
286.12183	0.82397598	0.13219918	3277.8374
286.92261	0.8255356	0.13325818	3288.8623
287.72339	0.82934546	0.13392676	3279.9763
288.52417	0.82812554	0.1347888	3280.3396
289.32495	0.83393252	0.13546909	3282.2495
290.12573	0.83700281	0.1365466	3298.6697
290.92651	0.84001344	0.13739814	3293.8538
291.72729	0.84150136	0.1380962	3288.6111
292.52808	0.84289473	0.13891716	3294.6814
293.32886	0.84372294	0.13981138	3294.1809
294.12964	0.84629649	0.14071447	3299.4651
294.93042	0.85286158	0.14157547	3295.1812
295.7312	0.85315824	0.14246064	3300.6741
296.53198	0.8542214	0.14334586	3297.3657
297.33276	0.85359979	0.14417091	3301.6768
298.13354	0.86054957	0.14502965	3300.022
298.93433	0.86149371	0.14591877	3303.8635
299.73511	0.86421573	0.14681232	3305.9182
300.53589	0.86686713	0.14751537	3300.0574
301.33667	0.87281811	0.14840537	3313.2615
302.13745	0.87131262	0.1495142	3318.1863
302.93823	0.8700062	0.15024661	3309.2612
303.73901	0.8765049	0.15118867	3311.9263
304.53979	0.88013166	0.15193081	3317.8213
305.34058	0.87936473	0.15270701	3314.9375
306.14136	0.88344693	0.15359312	3322.2849
306.94214	0.88588715	0.15460515	3319.4902
307.74292	0.88951617	0.15561123	3326.9832
308.5437	0.89137411	0.15670151	3327.9268
309.34448	0.89165419	0.15752611	3320.938
310.14526	0.89487809	0.15832147	3324.666
310.94604	0.89939749	0.15917864	3327.3599
311.74683	0.90084809	0.1602132	3327.7498
312.54761	0.90035433	0.16109912	3330.4214
313.34839	0.90604573	0.16204095	3333.084
314.14917	0.90831757	0.16282932	3331.124
314.94995	0.91249704	0.1636257	3331.6191
315.75073	0.91140914	0.16459644	3338.751
316.55151	0.91674423	0.16537733	3335.1519
317.35229	0.91859889	0.16630247	3338.4622
318.15308	0.91876769	0.16707459	3340.0488
318.95386	0.92487478	0.16802152	3346.2646
319.75464	0.92821711	0.16869147	3343.1099
320.55542	0.92810857	0.16942778	3342.3337
321.3562	0.93241799	0.17027585	3344.8892
322.15698	0.93171215	0.17098989	3341.114
322.95776	0.93558371	0.17197339	3354.3345
323.75854	0.93555337	0.17287657	3353.2874
324.55933	0.93918461	0.17383319	3351.7146
325.36011	0.94173115	0.1747276	3349.3389
326.16089	0.94409645	0.17551899	3355.1318
326.96167	0.94839805	0.1763749	3355.3767
327.76245	0.948897	0.17713952	3353.4639
328.56323	0.95167792	0.17805579	3359.1396
329.36401	0.95267344	0.1789566	3354.3225
330.16479	0.95485288	0.17991379	3365.4019
330.96558	0.95906496	0.18113951	3369.6956
331.76636	0.95943993	0.18209149	3361.9434
332.56714	0.96201724	0.18293476	3358.1328
333.36792	0.965051	0.18381631	3367.511
334.1687	0.96663433	0.18464804	3363.6599
334.96948	0.96850646	0.18553004	3367.7427
335.77026	0.97295129	0.18627666	3366.3887
336.57104	0.97505492	0.18701831	3370.8477
337.37183	0.97874063	0.18789479	3370.71
338.17261	0.97956443	0.18868667	3371.4658
338.97339	0.98373461	0.1896026	3375.1108
339.77417	0.98445868	0.19051611	3377.0601
340.57495	0.98659772	0.19147746	3378.5725
341.37573	0.99115747	0.19251664	3382.0491
342.17651	0.99242389	0.19337876	3381.7861
342.97729	0.99275887	0.19434036	3382.5437
343.77808	0.99817801	0.19521959	3382.189
344.57886	0.99889123	0.19610094	3379.311
345.37964	1.0021471	0.19706556	3382.0039
346.18042	1.0027636	0.19801447	3388.0889
346.9812	1.0055801	0.19892123	3385.1348
347.78198	1.0096231	0.19974804	3391.8887
348.58276	1.0117152	0.20063637	3393.0059
349.38354	1.0112673	0.2015319	3391.0435
350.18433	1.0171595	0.20252821	3395.1929
350.98511	1.0184488	0.20339435	3396.9707
351.78589	1.0221692	0.20420304	3394.2468
352.58667	1.0217516	0.20505686	3394.8066
353.38745	1.0234324	0.20591703	3392.675
354.18823	1.0289938	0.20674413	3401.793
354.98901	1.0297978	0.20743711	3397.1982
355.78979	1.0330652	0.20841262	3399.6831
356.59058	1.0384241	0.20924582	3403.5779
357.39136	1.0400776	0.21016023	3410.9617
358.19214	1.0407184	0.21096444	3401.8408
358.99292	1.0430441	0.21179104	3410.1277
359.7937	1.044275	0.21263994	3406.8735
360.59448	1.0458366	0.21354069	3406.9417
361.39526	1.0508424	0.21440108	3410.7371
362.19604	1.0523983	0.21533337	3417.2014
362.99683	1.0550244	0.21613209	3412.5068
363.79761	1.058162	0.21701856	3411.032
364.59839	1.0627978	0.21797986	3422.0715
365.39917	1.0578831	0.21895014	3421.1079
366.19995	1.0638905	0.21981706	3422.0784
367.00073	1.0667657	0.2208437	3421.2598
367.80151	1.0689154	0.22169442	3412.0313
368.60229	1.0712891	0.22254878	3423.9634
369.40308	1.0749381	0.22342739	3427.2104
370.20386	1.0782502	0.22433665	3427.6843
371.00464	1.0783428	0.22526056	3421.6917
371.80542	1.0809952	0.22616595	3422.5396
372.6062	1.0826839	0.22719961	3425.1267
373.40698	1.085062	0.22796872	3425.7249
374.20776	1.0891215	0.22881788	3429.9426
375.00854	1.0901781	0.22973463	3432.3357
375.80933	1.0928112	0.23064961	3430.8909
376.61011	1.0942154	0.2317113	3434.6873
377.41089	1.099931	0.23294508	3439.6038
378.21167	1.0999917	0.23388474	3432.3496
379.01245	1.1028855	0.23478189	3438.4641
379.81323	1.1072886	0.23574512	3445.7815
380.61401	1.1056269	0.23666655	3439.4861
381.41479	1.1134191	0.23758447	3441.3616
382.21558	1.1107116	0.23842305	3438.1313
383.01636	1.1153411	0.239199	3440.2134
383.81714	1.1156574	0.24007697	3445.012
384.61792	1.1195424	0.24105568	3447.9277
385.4187	1.1239305	0.24186158	3445.8352
386.21948	1.1242265	0.24265055	3444.7898
387.02026	1.1249328	0.24354751	3450.9951
387.82104	1.130686	0.24445476	3451.3223
388.62183	1.1308757	0.24530937	3448.396
389.42261	1.1344752	0.24614307	3453.8535
390.22339	1.1349251	0.24687703	3447.6567
391.02417	1.1392952	0.24772435	3459.2246
391.82495	1.1396171	0.248759	3455.647
392.62573	1.1419792	0.24958712	3453.5046
393.42651	1.146547	0.25049689	3460.2742
394.22729	1.1482898	0.25119928	3456.0732
395.02808	1.1501806	0.25211036	3457.2119
395.82886	1.1528788	0.25302413	3460.3191
396.62964	1.1542023	0.25390878	3468.3225
397.43042	1.1579223	0.25498933	3469.9253
398.2312	1.1597708	0.25600883	3470.7014
399.03198	1.1626923	0.25688934	3470.9812
399.83276	1.1647853	0.25763044	3462.9238
400.63354	1.1687726	0.25847965	3468.8499
401.43433	1.169436	0.2593303	3469.8564
402.23511	1.1734209	0.26022956	3473.5327
403.03589	1.1737781	0.26107541	3474.2837
403.83667	1.1775779	0.26205188	3478.4856
404.63745	1.1795462	0.26299974	3471.0916
405.43823	1.1820176	0.26389754	3474.7671
406.23901	1.1839198	0.26483789	3484.7834
407.03979	1.1872544	0.26569256	3478.9126
407.84058	1.1881975	0.26656863	3480.2329
408.64136	1.1894491	0.2676307	3481.3245
409.44214	1.1937037	0.26843533	3481.4424
410.24292	1.1977379	0.26931247	3481.7651
411.0437	1.1978714	0.27025354	3486.9148
411.84448	1.2011899	0.27122518	3488.8513
412.64526	1.2012212	0.27232614	3491.0566
413.44604	1.2062254	0.27338538	3486.4819
414.24683	1.2066815	0.27431408	3483.9888
415.04761	1.2111286	0.27527449	3491.2346
415.84839	1.2130018	0.27618113	3489.7996
416.64917	1.2126888	0.27688023	3486.7766
417.44995	1.2172003	0.27784091	3495.321
418.25073	1.2179127	0.27872208	3487.8254
419.05151	1.2234286	0.27965617	3495.3142
419.85229	1.2258066	0.28069243	3497.4412
420.65308	1.2272148	0.28148541	3493.0684
421.45386	1.2299042	0.28232989	3497.2048
422.25464	1.2334582	0.28326309	3501.373
423.05542	1.2327563	0.2841877	3497.3765
423.8562	1.2397138	0.28488347	3504.0571
424.65698	1.239318	0.28557724	3499.5359
425.45776	1.2414513	0.28655457	3504.7832
426.25854	1.2470067	0.28758675	3506.8481
427.05933	1.2491641	0.28845412	3505.3328
427.86011	1.2509524	0.28924504	3504.3406
428.66089	1.2523956	0.29013377	3502.5896
429.46167	1.2564481	0.29097068	3507.1018
430.26245	1.2532263	0.29184821	3512.5486
431.06323	1.2602293	0.29267502	3510.1035
431.86401	1.2621688	0.29357094	3516.8179
432.66479	1.2653193	0.29427412	3509.6599
433.46558	1.26738	0.29526195	3511.0054
434.26636	1.2689101	0.29631191	3521.7832
435.06714	1.2720094	0.29730868	3520.6152
435.86792	1.2738208	0.29836252	3519.3806
436.6687	1.2769992	0.29928616	3521.3882
437.46948	1.2765579	0.30021757	3518.9878
438.27026	1.2783955	0.30120623	3522.3899
439.07104	1.2847477	0.30220109	3518.9961
439.87183	1.2829839	0.30289799	3512.6167
440.67261	1.2869976	0.30385378	3524.6257
441.47339	1.2878016	0.30470014	3519.3359
442.27417	1.2918884	0.30555335	3520.072
443.07495	1.2962075	0.30643669	3523.604
443.87573	1.2955521	0.3073619	3530.6204
444.67651	1.2991489	0.30826312	3532.3772
445.47729	1.3030635	0.30931848	3535.1914
446.27808	1.3047094	0.31022617	3530.2881
447.07886	1.3059324	0.31130907	3539.6992
447.87964	1.3119938	0.31237355	3536.6191
448.68042	1.3141224	0.31335378	3537.5278
449.4812	1.3167762	0.31426135	3536.115
450.28198	1.3163061	0.31517318	3539.207
451.08276	1.3177181	0.31602353	3531.7217
451.88354	1.3199364	0.31688884	3531.46
452.68433	1.3216105	0.31787845	3540.2004
453.48511	1.3257972	0.31868502	3539.238
454.28589	1.3306698	0.3196567	3541.7205
455.08667	1.3316489	0.32050669	3535.8076
455.88745	1.3339975	0.32152355	3544.3711
456.68823	1.3372157	0.322478	3545.5413
457.48901	1.3411819	0.32337725	3546.4609
458.28979	1.3403381	0.3243306	3540.6528
459.09058	1.3461481	0.32538745	3554.2961
459.89136	1.3461421	0.32619375	3545.7664
460.69214	1.3485197	0.32702196	3544.0144
461.49292	1.3477108	0.32795757	3545.9275
462.2937	1.3520848	0.32897291	3557.9456
463.09448	1.3532071	0.32986665	3549.7581
463.89526	1.3579732	0.33085236	3555.6858
464.69604	1.3599052	0.33166575	3555.8674
465.49683	1.3623577	0.33253628	3548.4067
466.29761	1.363843	0.3333104	3551.0493
467.09839	1.3673824	0.33424959	3557.137
467.89917	1.3683251	0.33537215	3556.6929
468.69995	1.3724878	0.33644199	3561.5623
469.50073	1.3730084	0.33742836	3560.3477
470.30151	1.3758119	0.33819193	3553.5439
471.10229	1.3762732	0.33907783	3558.5378
471.90308	1.3807163	0.33993772	3562.2764
472.70386	1.3841728	0.34082186	3563.3801
473.50464	1.3855113	0.341822	3562.926
474.30542	1.3890983	0.34271616	3562.6184
475.1062	1.3882569	0.34361452	3564.7429
475.90698	1.3924023	0.34470603	3562.9199
476.70776	1.3975158	0.34559822	3567.2185
477.50854	1.3975036	0.34641027	3560.6934
478.30933	1.4012667	0.34741989	3570.2869
479.11011	1.4040684	0.34836417	3566.1372
479.91089	1.405145	0.34942761	3575.3962
480.71167	1.4088922	0.3503857	3568.4055
481.51245	1.4093888	0.35152906	3571.1641
482.31323	1.4125245	0.35249662	3571.1299
483.11401	1.413133	0.35357711	3577.3093
483.91479	1.4199352	0.35471657	3578.1477
484.71558	1.4188598	0.35559595	3570.5046
485.51636	1.4234384	0.35642627	3574.3535
486.31714	1.4236859	0.35751417	3580.8936
487.11792	1.4262391	0.35852274	3576.877
487.9187	1.4296255	0.35934073	3575.2817
488.71948	1.4324337	0.36023739	3577.2793
489.52026	1.433216	0.36125997	3582.8584
490.32104	1.4367242	0.36238754	3585.6619
491.12183	1.4399613	0.36338249	3583.6741
491.92261	1.4432039	0.36433467	3582.3904
492.72339	1.4432191	0.36517975	3584.4138
493.52417	1.4432017	0.3661871	3581.0002
494.32495	1.4471996	0.36709243	3583.9421
495.12573	1.452917	0.3679179	3588.0715
495.92651	1.45362	0.3689152	3592.4326
496.72729	1.4566277	0.37007886	3587.2041
497.52808	1.4614531	0.37121215	3599.2065
498.32886	1.4605356	0.37220815	3589.3975
499.12964	1.4636036	0.37301594	3584.7815
499.93042	1.4684403	0.37378445	3593.0598
500.7312	1.465994	0.37464687	3592.8503
501.53198	1.4745626	0.3755894	3593.335
502.33276	1.4715132	0.37627116	3591.5083
503.13354	1.4758593	0.37732932	3593.7488
503.93433	1.4768078	0.37801179	3592.2495
504.73511	1.4768797	0.3788394	3594.449
505.53589	1.4814572	0.3798027	3595.5986
506.33667	1.4870142	0.38063619	3601.176
507.13745	1.4867544	0.3816106	3602.8965
507.93823	1.4911448	0.38274673	3606.2068
508.73901	1.4940813	0.38395089	3609.4663
509.53979	1.4957269	0.38514024	3611.3257
510.34058	1.4985336	0.38611025	3598.9966
511.14136	1.5014775	0.38695481	3606.0918
511.94214	1.5034046	0.38800082	3609.9631
512.74292	1.5025855	0.38894477	3599.9851
513.5437	1.5073271	0.38979605	3607.22
514.34448	1.5110986	0.39072961	3606.9375
515.14526	1.5091336	0.39156872	3602.8501
515.94604	1.5142189	0.39250502	3613.5603
516.74683	1.5156562	0.3933664	3607.6309
517.54761	1.5178725	0.39419287	3610.8706
518.34839	1.520677	0.39515999	3616.3679
519.14917	1.5235708	0.39641023	3615.7446
519.94995	1.527861	0.39752054	3616.2932
520.75073	1.5268193	0.39849102	3618.1555
521.55151	1.5284551	0.3996149	3618.2847
522.35229	1.53134	0.40070489	3624.397
523.15308	1.534524	0.40180412	3617.321
523.95386	1.5362012	0.40289885	3616.2061
524.75464	1.5374879	0.40389895	3619.1543
525.55542	1.5441645	0.4049364	3621.6045
526.3562	1.5449194	0.4059886	3622.198
527.15698	1.5466857	0.40684262	3613.9001
527.95776	1.5484632	0.40778753	3620.689
528.75854	1.5510848	0.40863222	3618.6379
529.55933	1.5544744	0.40949535	3617.481
530.36011	1.5576512	0.41034099	3625.1003
531.16089	1.5588921	0.41135749	3625.0376
531.96167	1.5625358	0.41268957	3632.8433
532.76245	1.5641453	0.4138408	3633.9177
533.56323	1.5650489	0.41490462	3626.8074
534.36401	1.568239	0.41582218	3629.5955
535.16479	1.5735433	0.41682431	3629.0435
535.96558	1.5719851	0.41781035	3627.5056
536.76636	1.5752745	0.41868985	3630.5796
537.56714	1.5762774	0.41959003	3631.4773
538.36792	1.5781261	0.42059696	3628.8638
539.1687	1.5849224	0.42177102	3641.0071
539.96948	1.5833598	0.42281517	3634.2344
540.77026	1.5906763	0.42393747	3636.7913
541.57104	1.5915985	0.4249312	3634.7244
542.37183	1.5930047	0.42573783	3628.9746
543.17261	1.5934881	0.42652443	3633.2949
543.97339	1.5978724	0.42746654	3639.6387
544.77417	1.5972731	0.4286319	3637.0134
545.57495	1.6016256	0.42967761	3638.4392
546.37573	1.6054943	0.43061247	3638.5125
547.17651	1.6026609	0.43159974	3638.2451
547.97729	1.6109642	0.43250152	3639.2532
548.77808	1.6145415	0.43342173	3646.8679
549.57886	1.6146158	0.4342722	3645.9224
550.37964	1.6143672	0.43547097	3646.4434
551.18042	1.6202642	0.43649417	3650.0686
551.9812	1.6210922	0.43748793	3646.8647
552.78198	1.6246848	0.43860736	3650.5667
553.58276	1.626712	0.43977717	3644.0439
554.38354	1.6295928	0.44086182	3652.2375
555.18433	1.6298717	0.44174924	3650.4099
555.98511	1.6343772	0.44283092	3648.9985
556.78589	1.6339169	0.44385177	3650.9287
557.58667	1.6410191	0.44496745	3656.9133
558.38745	1.6382793	0.44593245	3648.4092
559.18823	1.6429418	0.44699344	3645.7932
559.98901	1.6457193	0.44791314	3644.6807
560.78979	1.6499555	0.44887662	3656.6111
561.59058	1.6509168	0.44981435	3653.7529
562.39136	1.6532395	0.45059013	3651.7981
563.19214	1.6548265	0.45144528	3650.7991
563.99292	1.6589422	0.4525649	3661.667
564.7937	1.6580099	0.45339385	3656.2402
565.59448	1.6628277	0.45446873	3659.6892
566.39526	1.6632665	0.45550594	3657.8682
567.19604	1.6686267	0.45654941	3659.8691
567.99683	1.6712768	0.45756882	3659.4277
568.79761	1.6732394	0.45870739	3667.3823
569.59839	1.6724834	0.45969963	3662.446
570.39917	1.6776235	0.46078137	3661.8506
571.19995	1.680487	0.46168381	3655.9165
572.00073	1.6818817	0.46277562	3665.0725
572.80151	1.6834317	0.46377909	3661.9785
573.60229	1.6880753	0.46471798	3662.0715
574.40308	1.6891121	0.46577212	3666.2156
575.20386	1.6927896	0.46681482	3667.1587
576.00464	1.6938046	0.46773335	3668.9543
576.80542	1.695029	0.46885616	3670.6758
577.6062	1.6954474	0.46983796	3667.8513
578.40698	1.7005688	0.47100762	3665.3574
579.20776	1.7038915	0.4720394	3672.5674
580.00854	1.708248	0.47296876	3670.8901
580.80933	1.7095523	0.47396573	3665.0757
581.61011	1.7095078	0.47488514	3662.5784
582.41089	1.716352	0.47577229	3669.3601
583.21167	1.7139235	0.47686648	3671.1375
584.01245	1.7172388	0.47808397	3674.5833
584.81323	1.7196357	0.47906366	3675.166
585.61401	1.7203649	0.48010722	3671.0508
586.41479	1.7254714	0.48111814	3672.4983
587.21558	1.7271693	0.48214245	3673.2761
588.01636	1.7268003	0.48324963	3673.1643
588.81714	1.7328373	0.48420846	3674.7485
589.61792	1.7325797	0.48539254	3679.0332
590.4187	1.7381238	0.48643067	3678.4746
591.21948	1.738902	0.48747286	3685.2598
592.02026	1.742489	0.48859102	3679.3025
592.82104	1.7461897	0.48987374	3680.4866
593.62183	1.7468904	0.49101737	3677.2034
594.42261	1.7501744	0.49203512	3679.3362
595.22339	1.7499017	0.4930549	3681.0662
596.02417	1.7509595	0.49387941	3674.155
596.82495	1.7540531	0.49480316	3678.0981
597.62573	1.7566724	0.49562341	3679.7339
598.42651	1.7616063	0.49667764	3686.9978
599.22729	1.7609181	0.49786121	3689.7734
600.02808	1.7643672	0.49901894	3687.1438
600.82886	1.7687705	0.50010663	3689.8892
601.62964	1.7688475	0.50128651	3684.6011
602.43042	1.7745483	0.50211364	3687.8455
603.2312	1.774071	0.50332952	3693.6836
604.03198	1.7784469	0.50433326	3683.0352
604.83276	1.7809671	0.50527161	3684.679
605.63354	1.7827905	0.50624067	3683.9814
606.43433	1.7851285	0.50708991	3684.4482
607.23511	1.7850232	0.50802469	3690.2185
608.03589	1.7880429	0.5091697	3693.5081
608.83667	1.7905829	0.51030636	3690.3267
609.63745	1.7946584	0.51134443	3692.0166
610.43823	1.7944698	0.51246059	3696.0547
611.23901	1.7981361	0.51352829	3694.4626
612.03979	1.8034455	0.51458925	3697.406
612.84058	1.8036491	0.51576102	3693.2239
613.64136	1.807024	0.51693028	3693.3848
614.44214	1.809834	0.51799446	3702.1853
615.24292	1.8110152	0.51920098	3696.3411
616.0437	1.8162311	0.52028894	3702.8164
616.84448	1.8167782	0.52134532	3695.1096
617.64526	1.8206751	0.52260995	3702.8267
618.44604	1.8215204	0.5238235	3703.0581
619.24683	1.8191829	0.52508986	3699.7363
620.04761	1.8264159	0.5262866	3700.1526
620.84839	1.8270491	0.52724385	3694.4526
621.64917	1.8327225	0.52809411	3698.9612
622.44995	1.8339642	0.52914244	3697.3752
623.25073	1.8353256	0.53022534	3700.8398
624.05151	1.836352	0.53120255	3698.7754
624.85229	1.8419942	0.53224832	3700.7437
625.65308	1.8440045	0.53340083	3706.814
626.45386	1.8452151	0.53452885	3708.853
627.25464	1.8497649	0.53592277	3712.3862
628.05542	1.8503895	0.53729355	3704.8301
628.8562	1.8514981	0.53832257	3703.3169
629.65698	1.8564628	0.53950948	3706.6509
630.45776	1.8571299	0.54051775	3705.6013
631.25854	1.8562821	0.5415886	3703.6133
632.05933	1.8610013	0.54258263	3706.8767
632.86011	1.86529	0.54372609	3710.157
633.66089	1.8667628	0.54472196	3703.5698
634.46167	1.866148	0.54583508	3707.0808
635.26245	1.8729737	0.5469777	3714.3643
636.06323	1.8734702	0.54835981	3712.1506
636.86401	1.8762779	0.54959184	3710.3284
637.66479	1.8811539	0.55075014	3710.1982
638.46558	1.8802264	0.55183077	3712.6479
639.26636	1.8853233	0.55284566	3716.1152
640.06714	1.883835	0.55387056	3708.5901
640.86792	1.8892925	0.55490774	3709.8313
641.6687	1.8894552	0.55622756	3717.2083
642.46948	1.8935306	0.55724037	3717.959
643.27026	1.8931524	0.55816638	3712.6477
644.07104	1.8961635	0.55930519	3716.3074
644.87183	1.9008389	0.56036615	3715.7817
645.67261	1.9017403	0.56145388	3715.1831
646.47339	1.9069022	0.56233853	3716.9795
647.27417	1.9078782	0.56366658	3725.0935
648.07495	1.9078056	0.56476909	3719.4866
648.87573	1.9141021	0.56585574	3721.1741
649.67651	1.9141634	0.56704658	3721.8254
650.47729	1.917177	0.56811583	3715.4216
651.27808	1.9199731	0.56911325	3716.5969
652.07886	1.9228965	0.57028514	3717.8965
652.87964	1.9229422	0.57144922	3718.5178
653.68042	1.9279246	0.57252306	3720.4539
654.4812	1.927545	0.57360017	3720.5347
655.28198	1.9305077	0.57492036	3723.5833
656.08276	1.9337016	0.57600117	3722.7439
656.88354	1.9393337	0.57714432	3724.5291
657.68433	1.9375696	0.57802093	3717.9111
658.48511	1.9407111	0.57913494	3716.3633
659.28589	1.9454302	0.58005589	3719.8303
660.08667	1.9463567	0.58110166	3723.6118
660.88745	1.9482096	0.58211356	3723.1597
661.68823	1.9528956	0.58320546	3728.2085
662.48901	1.9517717	0.58461672	3733.8982
663.28979	1.9558508	0.58619946	3736.5879
664.09058	1.9604722	0.58744955	3732.3228
664.89136	1.9579835	0.58878338	3730.8623
665.69214	1.9640951	0.59011197	3727.7974
666.49292	1.9652982	0.59122962	3729.9221
667.2937	1.9673028	0.59241271	3729.802
668.09448	1.9715916	0.59366459	3731.5503
668.89526	1.9742844	0.59470612	3734.1833
669.69604	1.9759932	0.59596139	3728.3237
670.49683	1.979623	0.59706181	3733.6807
671.29761	1.980027	0.59813887	3727.0664
672.09839	1.9818915	0.59914225	3730.3953
672.89917	1.9848737	0.60016078	3727.8943
673.69995	1.9895773	0.60118353	3735.5303
674.50073	1.9888501	0.60232544	3731.3979
675.30151	1.9917663	0.60349911	3741.0547
676.10229	1.995064	0.60475266	3735.6719
676.90308	1.9950615	0.6061902	3735.4617
677.70386	1.9972175	0.60747385	3732.2412
678.50464	2.0010276	0.60848427	3731.1628
679.30542	2.0048847	0.60966241	3736.01
680.1062	2.0056708	0.61077482	3731.438
680.90698	2.0084803	0.61176205	3729.3596
681.70776	2.011657	0.61277717	3733.0366
682.50854	2.0127456	0.61395168	3737.9299
683.30933	2.0145075	0.61504334	3737.9609
684.11011	2.0198851	0.6161741	3736.8076
684.91089	2.0191493	0.61747676	3739.6541
685.71167	2.0212736	0.61892492	3744.6013
686.51245	2.0249472	0.62016213	3731.3232
687.31323	2.0284712	0.62135965	3737.5134
688.11401	2.0287628	0.62255168	3742.113
688.91479	2.0325248	0.62377536	3742.8511
689.71558	2.0354791	0.62492383	3741.7966
690.51636	2.0375319	0.62599039	3737.7566
691.31714	2.0380952	0.62714785	3739.1587
692.11792	2.0401652	0.62837398	3740.447
692.9187	2.0460958	0.62970817	3740.0728
693.71948	2.0478442	0.63082635	3739.228
694.52026	2.0498815	0.6318748	3741.5366
695.32104	2.0534694	0.63310885	3748.6438
696.12183	2.0532293	0.63444465	3739.7534
696.92261	2.0562568	0.63558167	3741.3413
697.72339	2.0599697	0.63684428	3747.4707
698.52417	2.0640767	0.63802302	3746.1658
699.32495	2.064173	0.6395095	3750.4761
700.12573	2.0640254	0.64069426	3744.5757
700.92651	2.0668349	0.64193642	3744.0186
701.72729	2.069932	0.64336437	3743.8689
702.52808	2.0738971	0.64442527	3746.8645
703.32886	2.0774877	0.64584106	3749.3003
704.12964	2.0773215	0.64705408	3741.0476
704.93042	2.0800061	0.64827561	3752.5452
705.7312	2.0840147	0.64968544	3750.2207
706.53198	2.085393	0.65087146	3745.2327
707.33276	2.0875533	0.65226626	3751.8994
708.13354	2.0899785	0.65327495	3738.7021
708.93433	2.0941815	0.65439028	3746.5371
709.73511	2.0973523	0.65581721	3751.1848
710.53589	2.0982337	0.65680152	3746.3416
711.33667	2.0993447	0.65794665	3747.231
712.13745	2.1027176	0.65897894	3747.6682
712.93823	2.1016831	0.66006428	3749.2229
713.73901	2.1065862	0.66145319	3760.5063
714.53979	2.1122513	0.66289175	3752.5347
715.34058	2.1103339	0.66427809	3749.501
716.14136	2.1153913	0.66533506	3742.0974
716.94214	2.113373	0.66606897	3741.7747
717.74292	2.119283	0.66715431	3749.4099
718.5437	2.120152	0.66845536	3753.8538
719.34448	2.123626	0.66991132	3759.2173
720.14526	2.1256597	0.67144847	3754.1919
720.94604	2.1294947	0.6725688	3750.3601
721.74683	2.1287963	0.67364681	3749.2175
722.54761	2.1318774	0.67510837	3755.4429
723.34839	2.1359732	0.67660582	3757.2537
724.14917	2.1401353	0.67813706	3761.9287
724.94995	2.1403284	0.67953897	3750.1392
725.75073	2.1433654	0.68073297	3751.4136
726.55151	2.147572	0.68195897	3753.6541
727.35229	2.149941	0.68314463	3753.6226
728.15308	2.1481802	0.68420488	3748.5088
728.95386	2.1538067	0.68532431	3751.9795
729.75464	2.1523657	0.68640161	3748.8403
730.55542	2.155911	0.68759787	3752.6589
731.3562	2.1592772	0.68892294	3757.5828
732.15698	2.1631322	0.69040495	3767.9675
732.95776	2.1655693	0.69182456	3760.4988
733.75854	2.1679916	0.69324064	3760.2576
734.55933	2.1665256	0.69456035	3753.8965
735.36011	2.1720278	0.69579482	3755.9897
736.16089	2.1765106	0.69705153	3757.6169
736.96167	2.1762338	0.69831824	3757.3594
737.76245	2.1817429	0.69974566	3755.8237
738.56323	2.1832228	0.70106769	3754.5662
739.36401	2.1815228	0.70227212	3757.927
740.16479	2.185812	0.70360833	3757.2007
740.96558	2.1879764	0.70492589	3761.4956
741.76636	2.1928818	0.70616698	3765.231
742.56714	2.1940665	0.7076813	3762.3892
743.36792	2.1969512	0.70907581	3759.6218
744.1687	2.1978185	0.71029001	3763.261
744.96948	2.2014301	0.71147287	3758.3159
745.77026	2.2026331	0.71264333	3752.7778
746.57104	2.2051852	0.71393144	3759.1692
747.37183	2.2103074	0.7151475	3758.7197
748.17261	2.2101784	0.71681148	3764.4395
748.97339	2.2135623	0.71835142	3765.0757
749.77417	2.2160256	0.71964824	3760.3032
750.57495	2.2164881	0.72094297	3764.7759
751.37573	2.2219069	0.72210836	3759.3074
752.17651	2.2204754	0.72352225	3760.5095
752.97729	2.2249362	0.72481734	3761.1423
753.77808	2.2269032	0.72596222	3758.3181
754.57886	2.2284596	0.72727776	3759.3638
755.37964	2.2300391	0.72864306	3762.6643
756.18042	2.2344804	0.73021996	3765.2603
756.9812	2.2356498	0.73170435	3767.0271
757.78198	2.2392228	0.7331813	3765.0815
758.58276	2.2439163	0.73456317	3763.9548
759.38354	2.2459943	0.73587161	3765.189
760.18433	2.2469089	0.73707128	3765.1401
760.98511	2.2497909	0.73842573	3758.5876
761.78589	2.2546403	0.73957062	3763.3359
762.58667	2.2533586	0.74079835	3763.47
763.38745	2.2533207	0.74217898	3759.0273
764.18823	2.2571502	0.74354458	3762.0022
764.98901	2.26057	0.74494624	3766.8474
765.78979	2.2617865	0.74651659	3761.7651
766.59058	2.2656705	0.74806768	3761.2332
767.39136	2.2672267	0.74938387	3760.5864
768.19214	2.269659	0.75069767	3765.855
768.99292	2.2718146	0.75204843	3764.1465
769.7937	2.2746124	0.75340718	3761.6936
770.59448	2.2730322	0.75480485	3762.0288
771.39526	2.2791374	0.75609607	3757.2998
772.19604	2.2836187	0.75772142	3768.0671
772.99683	2.2852688	0.75927848	3769.238
773.79761	2.2867911	0.76078123	3758.1575
774.59839	2.2882614	0.76244748	3767.5801
775.39917	2.2901566	0.76391596	3764.6462
776.19995	2.2917323	0.76522338	3757.8657
777.00073	2.2974002	0.76644665	3760.7898
777.80151	2.2969944	0.76778537	3765.3035
778.60229	2.3021951	0.76905799	3767.8215
779.40308	2.3040626	0.77066857	3762.2512
780.20386	2.3071358	0.77218693	3768.9268
781.00464	2.3063612	0.77356529	3767.3325
781.80542	2.3094563	0.77499336	3764.7112
782.6062	2.3128474	0.77637464	3764.8333
783.40698	2.315567	0.77774429	3766.2341
784.20776	2.3187711	0.77930546	3766.8127
785.00854	2.3210239	0.78071707	3762.1599
785.80933	2.3216739	0.78215712	3762.0698
786.61011	2.327316	0.7838245	3767.8298
787.41089	2.3282893	0.78517586	3765.1433
788.21167	2.3315613	0.78653204	3769.3899
789.01245	2.3344412	0.78812015	3768.8604
789.81323	2.334796	0.78937268	3761.5676
790.61401	2.3391635	0.79093874	3764.2065
791.41479	2.3415675	0.7924661	3767.437
792.21558	2.3433197	0.79350948	3761.6965
793.01636	2.3452756	0.79486352	3765.4241
793.81714	2.3451962	0.79624021	3761.2202
794.61792	2.3507569	0.79768586	3769.2292
795.4187	2.3538208	0.79914796	3766.1655
796.21948	2.3534319	0.80057514	3766.1948
797.02026	2.3574684	0.80231494	3771.2363
797.82104	2.3560658	0.80366004	3762.1819
798.62183	2.363925	0.80503368	3763.8379
799.42261	2.3645012	0.80641168	3761.0657
800.22339	2.3663974	0.80791867	3770.967
801.02417	2.3688288	0.80977535	3768.8079
801.82495	2.370929	0.81142527	3771.1819
802.62573	2.3756695	0.8129831	3768.6785
803.42651	2.3774455	0.814372	3763.3105
804.22729	2.3816862	0.8159802	3773.6116
805.02808	2.3809094	0.81744319	3763.6729
805.82886	2.3827765	0.81893349	3764.6516
806.62964	2.3852608	0.82051384	3772.5503
807.43042	2.3850453	0.82196116	3757.8176
808.2312	2.3904173	0.8234365	3766.0166
809.03198	2.3922868	0.82483721	3762.8513
809.83276	2.3940732	0.82639277	3769.8926
810.63354	2.3974416	0.8282938	3774.7693
811.43433	2.4012172	0.83015257	3767.4233
812.23511	2.4018166	0.83168882	3768.5669
813.03589	2.4054503	0.83336216	3763.5576
813.83667	2.4053509	0.83483118	3762.1716
814.63745	2.4118176	0.83632487	3768.2559
815.43823	2.4138279	0.83797568	3764.1221
816.23901	2.4152989	0.83929008	3761.4631
817.03979	2.4176776	0.84071577	3768.0994
817.84058	2.4197721	0.84232622	3766.3113
818.64136	2.4219615	0.84409463	3767.4673
819.44214	2.4235718	0.84591925	3764.3799
820.24292	2.425504	0.84777737	3769.416
821.0437	2.43083	0.84963417	3768.8813
821.84448	2.4307508	0.85129845	3765.3235
822.64526	2.4324498	0.85312778	3763.0898
823.44604	2.4379497	0.85455054	3760.8442
824.24683	2.4391642	0.85620856	3764.4399
825.04761	2.4395576	0.85758281	3761.0366
825.84839	2.4439931	0.85902959	3758.033
826.64917	2.4460263	0.8606469	3769.1321
827.44995	2.4483902	0.86217344	3764.3555
828.25073	2.4486701	0.86379683	3765.7488
829.05151	2.4513714	0.86568046	3763.3853
829.85229	2.4551802	0.86715722	3760.4324
830.65308	2.4596224	0.86860609	3761.5894
831.45386	2.4589612	0.87013113	3764.0771
832.25464	2.4643123	0.87171173	3767.4385
833.05542	2.4641438	0.87341124	3764.397
833.8562	2.4666886	0.87517601	3765.8362
834.65698	2.4713838	0.87687445	3760.748
835.45776	2.470567	0.87849784	3764.3372
836.25854	2.4757617	0.87997013	3762.6987
837.05933	2.4777331	0.88185883	3766.2661
837.86011	2.4786217	0.88359541	3761.3062
838.66089	2.4808042	0.88532448	3762.2468
839.46167	2.4839916	0.88691711	3759.3059
840.26245	2.4858174	0.88854885	3764.7087
841.06323	2.4888432	0.89015806	3761.5762
841.86401	2.4894445	0.89181697	3758.0432
842.66479	2.4982255	0.89401728	3768.7566
843.46558	2.4971023	0.89574915	3764.1169
844.26636	2.4979761	0.897587	3761.4785
845.06714	2.5026529	0.89942187	3760.741
845.86792	2.5064509	0.90101331	3761.9534
846.6687	2.5075295	0.90286374	3764.9568
847.46948	2.5094135	0.90454608	3756.4648
848.27026	2.5119309	0.90634072	3760.2463
849.07104	2.5156326	0.90800333	3751.5527
849.87183	2.5192423	0.90964431	3756.1873
850.67261	2.5161331	0.91150129	3762.4761
851.47339	2.5194833	0.91341519	3758.7595
852.27417	2.522481	0.9150238	3757.9678
853.07495	2.5253093	0.91662902	3754.0837
853.87573	2.526489	0.91851711	3766.1477
854.67651	2.5309272	0.92042381	3752.1855
855.47729	2.5326214	0.92234105	3759.6545
856.27808	2.5319576	0.92405701	3754.9773
857.07886	2.5371253	0.9258793	3756.5366
857.87964	2.5402684	0.92796171	3762.4194
858.68042	2.541868	0.92983603	3748.6956
859.4812	2.543225	0.93154871	3755.699
860.28198	2.5479312	0.93311793	3756.8831
861.08276	2.5491669	0.93444288	3749.7654
861.88354	2.5482886	0.93610269	3754.4155
862.68433	2.5537519	0.93780911	3756.2009
863.48511	2.5575128	0.93964207	3761.2571
864.28589	2.5580456	0.94144124	3755.6528
865.08667	2.559407	0.94327426	3749.697
865.88745	2.5634418	0.94511467	3757.6597
866.68823	2.5665739	0.94716239	3754.5476
867.48901	2.5678051	0.94902653	3750.9563
868.28979	2.5699785	0.95084268	3752.5879
869.09058	2.5724213	0.95271802	3750.3428
869.89136	2.5734618	0.95462918	3750.5999
870.69214	2.5785427	0.95655358	3753.7664
871.49292	2.5817504	0.95844692	3754.885
872.2937	2.5828645	0.96003342	3746.9001
873.09448	2.5835609	0.96184117	3748.1709
873.89526	2.589123	0.96374017	3746.7795
874.69604	2.5867283	0.96569383	3747.4639
875.49683	2.5909765	0.96773601	3747.1729
876.29761	2.5951428	0.96967119	3746.9331
877.09839	2.597101	0.9715988	3749.9136
877.89917	2.5999789	0.97392994	3750.8206
878.69995	2.6019428	0.97610956	3749.3882
879.50073	2.6031141	0.97811353	3745.8745
880.30151	2.6068327	0.98012471	3747.6172
881.10229	2.6080115	0.98209733	3742.3113
881.90308	2.6117463	0.98406887	3746.4011
882.70386	2.6155074	0.98620445	3745.6355
883.50464	2.6150343	0.98804641	3740.1384
884.30542	2.6179245	0.98994005	3741.895
885.1062	2.6209276	0.99198574	3746.6384
885.90698	2.6241434	0.99441105	3749.0286
886.70776	2.6253376	0.99666333	3739.0222
887.50854	2.627259	0.99868697	3737.6895
888.30933	2.6303055	1.0006102	3738.1826
889.11011	2.6342783	1.002423	3737.4158
889.91089	2.633553	1.0045238	3737.8867
890.71167	2.6399488	1.0065221	3740.2141
891.51245	2.6407645	1.0085624	3741.3416
892.31323	2.6451187	1.0109266	3744.4319
893.11401	2.6452713	1.012876	3729.7407
893.91479	2.6491456	1.0147631	3737.8811
894.71558	2.6495731	1.016692	3732.0249
895.51636	2.6520619	1.0184405	3726.8813
896.31714	2.6562757	1.0200044	3727.7942
897.11792	2.6535792	1.0216725	3728.5593
897.9187	2.6608009	1.0236621	3732.4907
898.71948	2.6594927	1.0258801	3730.835
899.52026	2.6647069	1.0280322	3729.9707
900.32104	2.6703155	1.0302054	3730.7791
901.12183	2.6677008	1.0319985	3723.7559
901.92261	2.6718423	1.033813	3723.1816
902.72339	2.6732056	1.0354599	3721.5044
903.52417	2.6754742	1.0374364	3727.9976
904.32495	2.6798427	1.0395104	3724.6853
905.12573	2.6829283	1.0416791	3725.9956
905.92651	2.6862791	1.0441756	3732.052
906.72729	2.6836622	1.0469655	3720.8545
907.52808	2.6882324	1.0494418	3719.4158
908.32886	2.69016	1.0516464	3719.7971
909.12964	2.6934159	1.0539749	3715.3638
909.93042	2.6950274	1.056134	3711.6716
910.7312	2.6993484	1.0579522	3711.9653
911.53198	2.7014489	1.0597544	3711.4187
912.33276	2.7031338	1.0616159	3714.2454
913.13354	2.7061999	1.0639246	3717.2563
913.93433	2.7071781	1.0660307	3711.9529
914.73511	2.7099755	1.0680983	3704.9231
915.53589	2.7131121	1.0701848	3711.3262
916.33667	2.7161057	1.0721427	3707.635
917.13745	2.7174788	1.0742095	3706.4224
917.93823	2.7195802	1.0763766	3706.1497
918.73901	2.7220221	1.0787781	3701.2112
919.53979	2.7243521	1.0810441	3699.1733
920.34058	2.726918	1.0833206	3702.6255
921.14136	2.7309029	1.0854161	3698.8857
921.94214	2.7308984	1.0873321	3693.3464
922.74292	2.7331059	1.0895582	3698.9504
923.5437	2.7358742	1.0918727	3700.7844
924.34448	2.7392073	1.0943165	3691.0366
925.14526	2.7414248	1.0967027	3687.8997
925.94604	2.7431951	1.0989172	3686.3926
926.74683	2.7465744	1.1012549	3692.7834
927.54761	2.7467349	1.1034671	3681.2634
928.34839	2.7503972	1.105173	3678.3792
929.14917	2.7529588	1.1067336	3678.6213
929.94995	2.7568648	1.1086229	3678.6563
930.75073	2.7604492	1.1106797	3680.5198
931.55151	2.7626333	1.1127018	3679.9229
932.35229	2.7645133	1.1144849	3677.0544
933.15308	2.7680597	1.1165999	3680.7026
933.95386	2.7669668	1.1191193	3667.9004
934.75464	2.7696972	1.1213706	3667.1379
935.55542	2.7708526	1.1235601	3667.916
936.3562	2.7741697	1.125913	3666.5723
937.15698	2.7758989	1.1282785	3664.749
937.95776	2.7808075	1.1306429	3656.7837
938.75854	2.7824988	1.1327374	3656.2664
939.55933	2.7854433	1.1343461	3650.8125
940.36011	2.7873394	1.1363404	3654.7114
941.16089	2.7894261	1.1385748	3655.5051
941.96167	2.7930245	1.1414683	3651.1025
942.76245	2.7953079	1.1440872	3644.0701
943.56323	2.7971098	1.1463724	3637.1882
944.36401	2.7977059	1.1484345	3636.8821
945.16479	2.8022201	1.1506001	3636.1011
945.96558	2.8019576	1.1528525	3630.3738
946.76636	2.8086972	1.1551468	3628.7166
947.56714	2.8054531	1.1575873	3623.9526
948.36792	2.810179	1.1604161	3619.8174
949.1687	2.8140922	1.1632866	3610.7617
949.96948	2.8155279	1.1658827	3607.1824
950.77026	2.8190138	1.1683199	3601.7068
951.57104	2.819808	1.1706742	3592.4531
952.37183	2.8253462	1.1728629	3595.385
953.17261	2.8254175	1.17498	3583.5933
953.97339	2.8271039	1.1769928	3583.7815
954.77417	2.8313189	1.1793733	3580.2041
955.57495	2.8332844	1.1818962	3575.9424
956.37573	2.8350542	1.1849409	3579.3394
957.17651	2.8337512	1.1877639	3566.0554
957.97729	2.8407929	1.1906624	3553.3303
958.77808	2.8421459	1.1931733	3542.9592
959.57886	2.8459923	1.1958611	3542.1755
960.37964	2.8476563	1.1979668	3533.4082
961.18042	2.8494368	1.2003702	3530.929
961.9812	2.8537545	1.2026517	3529.0054
962.78198	2.8550253	1.2050334	3519.6819
963.58276	2.8578291	1.207679	3511.9707
964.38354	2.8613098	1.210223	3510.3975
965.18433	2.8612175	1.2127088	3497.5754
965.98511	2.865169	1.2150626	3493.8833
966.78589	2.8672602	1.2176061	3484.6133
967.58667	2.870743	1.2203063	3479.665
968.38745	2.8733439	1.2228601	3470.7954
969.18823	2.8737659	1.2258	3455.1062
969.98901	2.8782465	1.2283922	3453.6309
970.78979	2.8780737	1.2310143	3444.7839
971.59058	2.8840704	1.2343202	3425.8132
972.39136	2.8852658	1.2377225	3410.0002
973.09204	2.8906989	1.2496107	3296.1914