File: datasets/am_bench_2022/raw_data/90-X.08-2/specimen.dat
MTS793|MPT|ENU|1|2|.|/|:|1|0|0|A

Operator Information						Time:	33.137451	Sec	11/2/2021 10:47:10 AM
Operator	Nick Derimow
Project	AM Bench 2022 mini-tensile challenge
Specimen ID	90-X.08-2a
Material	PBF-L Inconel 625
Specimen Width	2.55	mm
Specimen Thickness	1.51	mm
Notes	USE THIS ONE, not sure how the other one got in the system
Operator Information End

Data Acquisition						Time:	1034.1304	Sec	11/2/2021 11:03:51 AM
Time	Axial Displacement	Axial Extensometer	Axial Force
Sec	mm	mm	N
33.250244	-0.00092383672	8.7268418e-05	54.147488
34.151123	0.0042301444	0.0002779041	66.809067
35.052002	0.0059583997	0.0001749935	76.932869
35.952881	0.0088225193	0.00031743167	90.986427
36.85376	0.010487873	0.00048035072	101.72762
37.754639	0.01295225	0.00038994668	112.97047
38.655518	0.015294513	0.00051959144	122.26082
39.556396	0.018153561	0.00042662522	131.31584
40.457275	0.021096205	0.00069194369	142.01183
41.358154	0.026029672	0.00064490584	152.57336
42.259033	0.023384171	0.00071863277	167.92899
43.159912	0.027650975	0.00083166495	181.38223
44.060791	0.029686514	0.00075166428	193.85941
44.96167	0.037751585	0.0010319315	214.61575
45.862549	0.03815604	0.00090535195	224.10002
46.763428	0.038818404	0.0011061421	245.07344
47.664307	0.045164645	0.0013215418	261.73871
48.565186	0.044721261	0.0012075999	274.28827
49.466064	0.046816271	0.0014275104	298.99094
50.366943	0.050212082	0.0014724799	314.55505
51.267822	0.054321323	0.0015561758	330.93549
52.168701	0.055163424	0.001905728	355.0939
53.06958	0.057659768	0.0017115354	363.98322
53.970459	0.063182138	0.0019446081	390.59494
54.871338	0.061748162	0.0022555066	402.61295
55.772217	0.064884782	0.0021291103	422.5361
56.673096	0.068844609	0.002374124	442.39926
57.573975	0.072218142	0.0024824941	465.52841
58.474854	0.073355079	0.0025268693	481.49365
59.375732	0.077944793	0.0027652078	509.17303
60.276611	0.080532104	0.0027880857	522.1687
61.17749	0.081325643	0.0028668491	545.64209
62.078369	0.083205268	0.0029501731	561.15588
62.979248	0.087636031	0.003091431	588.28766
63.880127	0.090740487	0.0033461002	619.71356
64.781006	0.091244519	0.0034075009	639.20801
65.681885	0.093875065	0.0035676416	662.57257
66.582764	0.098734818	0.0037576391	684.81989
67.483643	0.10149655	0.003775984	706.18652
68.384521	0.10417914	0.0042584441	732.19269
69.2854	0.10436579	0.0039584138	755.97662
70.186279	0.10806894	0.004363765	780.73334
71.087158	0.10977297	0.0046677585	798.72736
71.988037	0.1168271	0.0044155493	825.64954
72.888916	0.11583359	0.0050768224	854.1051
73.789795	0.11817918	0.0047618682	874.41852
74.690674	0.12279138	0.0051068012	904.51056
75.591553	0.12556519	0.0052091931	926.49432
76.492432	0.12715986	0.0052604969	944.27637
77.393311	0.1298029	0.0055579753	967.95129
78.294189	0.133228	0.0057206606	991.20099
79.195068	0.13478723	0.0059278966	1017.2151
80.095947	0.13925381	0.0060842107	1043.5421
80.996826	0.14187948	0.006129548	1072.2434
81.897705	0.144291	0.0063781608	1102.0854
82.798584	0.14614706	0.0063860319	1122.5797
83.699463	0.14792509	0.0066033616	1145.2668
84.600342	0.14842053	0.0067600356	1174.2592
85.501221	0.1556312	0.0069236797	1194.7036
86.4021	0.15652345	0.0071331463	1215.0156
87.302979	0.15995635	0.0071858685	1232.54
88.203857	0.16281985	0.0074575092	1265.887
89.104736	0.16611224	0.0075439923	1297.0227
90.005615	0.16765302	0.0077235126	1327.028
90.906494	0.16903891	0.0077858232	1347.1984
91.807373	0.17427827	0.0079796519	1367.6393
92.708252	0.17522323	0.0081387768	1398.7196
93.609131	0.17914663	0.0083652642	1419.1233
94.51001	0.17935993	0.0083575109	1441.5538
95.410889	0.18337308	0.008601795	1472.8668
96.311768	0.18703975	0.0086981105	1493.7947
97.212646	0.18906407	0.0087514669	1519.8065
98.113525	0.18945767	0.0089972522	1543.1606
99.014404	0.19636096	0.009164473	1572.0125
99.915283	0.19769706	0.0092317183	1593.5245
100.81616	0.20315956	0.0094057908	1622.618
101.71704	0.20363961	0.0094827721	1642.6326
102.61792	0.20786835	0.0097530363	1665.0446
103.5188	0.20854901	0.0097684851	1682.1182
104.41968	0.20924665	0.009886099	1709.4692
105.32056	0.21420102	0.010033164	1728.6708
106.22144	0.21503596	0.010228086	1755.7274
107.12231	0.2204354	0.010328196	1778.0437
108.02319	0.22351404	0.010402746	1803.0743
108.92407	0.22786689	0.01060628	1824.097
109.82495	0.22872825	0.010714078	1849.0099
110.72583	0.23256089	0.010905974	1868.3867
111.62671	0.23310079	0.011011643	1883.9623
112.52759	0.23730387	0.011203833	1916.0671
113.42847	0.23881042	0.011271868	1937.293
114.32935	0.24215952	0.011367391	1961.3198
115.23022	0.24304792	0.011468323	1977.6511
116.1311	0.24689861	0.011651994	2001.9741
117.03198	0.24832875	0.011756404	2024.316
117.93286	0.25216568	0.011928278	2043.7775
118.83374	0.25438991	0.01201847	2062.3677
119.73462	0.25694016	0.012074662	2087.0564
120.6355	0.26151538	0.012268942	2104.7117
121.53638	0.26149118	0.012432918	2130.8286
122.43726	0.26507488	0.012518758	2134.2158
123.33813	0.26694384	0.012665265	2154.5098
124.23901	0.27110186	0.012763682	2172.3447
125.13989	0.27392012	0.012852858	2183.7646
126.04077	0.27589181	0.01306007	2206.4128
126.94165	0.27874035	0.01315468	2230.1338
127.84253	0.28287601	0.013251272	2243.2104
128.74341	0.28581348	0.01339612	2267.7444
129.64429	0.28822505	0.013429194	2274.1511
130.54517	0.28788126	0.013568291	2290.3042
131.44604	0.29295513	0.013735534	2300.5173
132.34692	0.29210871	0.013773152	2310.5085
133.2478	0.29833648	0.013899454	2325.21
134.14868	0.29949433	0.013940128	2342.3132
135.04956	0.30460423	0.014141071	2361.3789
135.95044	0.30701375	0.01424019	2373.7593
136.85132	0.31045809	0.014327614	2374.564
137.7522	0.30969799	0.014296552	2383.1104
138.65308	0.31128132	0.014667741	2404.4531
139.55396	0.31895792	0.014747074	2418.1709
140.45483	0.32095045	0.014848829	2434.1785
141.35571	0.32356116	0.01502669	2440.2161
142.25659	0.32611322	0.015103666	2452.9548
143.15747	0.32914808	0.015268117	2459.2205
144.05835	0.33102566	0.015322868	2472.9485
144.95923	0.33412498	0.015622112	2491.229
145.86011	0.33618209	0.015759043	2500.1204
146.76099	0.34083471	0.015963908	2506.0334
147.66187	0.34071362	0.016032845	2509.9336
148.56274	0.34645072	0.01618647	2523.2468
149.46362	0.34650746	0.016208487	2531.5979
150.3645	0.35040075	0.016517017	2541.3997
151.26538	0.35546213	0.016688835	2552.9966
152.16626	0.357402	0.016728979	2557.0459
153.06714	0.35794473	0.016975267	2559.9727
153.96802	0.36008319	0.017113939	2573.7412
154.8689	0.36059931	0.017374251	2581.0579
155.76978	0.36624929	0.017556606	2583.0994
156.67065	0.36851293	0.017796136	2598.3684
157.57153	0.37088549	0.017976282	2602.4036
158.47241	0.37612391	0.018178713	2606.8228
159.37329	0.37856039	0.018490184	2619.7043
160.27417	0.38275433	0.018736202	2622.3772
161.17505	0.38293341	0.019102121	2629.8328
162.07593	0.3857764	0.019376822	2638.9712
162.97681	0.38853666	0.019662216	2645.8237
163.87769	0.39214802	0.020095605	2657.7832
164.77856	0.39272991	0.020325929	2652.1462
165.67944	0.39799881	0.020658696	2665.7373
166.58032	0.3987987	0.02106064	2672.6038
167.4812	0.40304503	0.021558767	2676.3203
168.38208	0.40358657	0.021964069	2684.0195
169.28296	0.40524673	0.022386288	2687.9141
170.18384	0.41086978	0.022895314	2695.6987
171.08472	0.41393569	0.02347694	2701.9902
171.9856	0.41271004	0.023792472	2702.3079
172.88647	0.41835204	0.024327412	2713.6318
173.78735	0.42003399	0.024826471	2717.4854
174.68823	0.42314178	0.025365058	2723.2085
175.58911	0.42759481	0.026022669	2728.1987
176.48999	0.4292976	0.026784768	2741.2976
177.39087	0.43096685	0.027248219	2734.948
178.29175	0.43552789	0.027925653	2734.6301
179.19263	0.43873316	0.028546384	2747.7471
180.09351	0.44130903	0.029176395	2753.9768
180.99438	0.4444975	0.029862233	2761.9136
181.89526	0.444401	0.030653618	2766.78
182.79614	0.44910729	0.031387515	2763.4189
183.69702	0.45164174	0.031995438	2772.7915
184.5979	0.4545432	0.032619182	2772.4314
185.49878	0.45679224	0.033435579	2780.1228
186.39966	0.4621388	0.033989914	2783.0234
187.30054	0.4616518	0.034679011	2788.6709
188.20142	0.46484661	0.035331585	2783.1375
189.10229	0.46840283	0.035969932	2792.5017
190.00317	0.47201788	0.036727633	2795.9089
190.90405	0.47177345	0.037394758	2801.5125
191.80493	0.47544593	0.038247652	2811.5452
192.70581	0.47838175	0.039119806	2808.5017
193.60669	0.48142132	0.039828468	2815.1196
194.50757	0.48395002	0.040714875	2820.4282
195.40845	0.48531863	0.041462164	2819.4077
196.30933	0.48881286	0.042405281	2830.8608
197.21021	0.49327964	0.043521151	2837.9463
198.11108	0.49558848	0.044336386	2830.6572
199.01196	0.49569485	0.045101698	2832.717
199.91284	0.49956906	0.045880068	2837.0537
200.81372	0.50238407	0.046689421	2840.1335
201.7146	0.50488412	0.047580447	2852.2825
202.61548	0.50757122	0.048489403	2852.219
203.51636	0.5100975	0.049440835	2848.5896
204.41724	0.51221478	0.050347406	2852.2852
205.31812	0.51749259	0.051358901	2868.1133
206.21899	0.52045053	0.052285332	2867.5608
207.11987	0.52343965	0.053100925	2869.761
208.02075	0.52217466	0.053787224	2863.9448
208.92163	0.52684754	0.054750256	2872.2129
209.82251	0.52663749	0.05567643	2881.2048
210.72339	0.53167617	0.056630552	2877.1453
211.62427	0.53393692	0.057586994	2877.342
212.52515	0.5381062	0.058593538	2881.4336
213.42603	0.54111826	0.05954197	2891.0303
214.3269	0.54333395	0.060343042	2890.2708
215.22778	0.54385394	0.06120972	2899.9006
216.12866	0.54934859	0.062165633	2898.3901
217.02954	0.55094695	0.063196696	2904.3123
217.93042	0.55774415	0.064220503	2908.2427
218.8313	0.55611813	0.065155931	2905.6758
219.73218	0.55872357	0.066256337	2909.707
220.63306	0.5625549	0.067288324	2915.8518
221.53394	0.56535083	0.068334758	2921.8071
222.43481	0.56626028	0.069302998	2917.3792
223.33569	0.56836432	0.070442818	2921.8831
224.23657	0.57271475	0.071391404	2925.9626
225.13745	0.57671475	0.07230261	2929.5686
226.03833	0.57889974	0.073186293	2932.7163
226.93921	0.57906663	0.073969305	2930.4807
227.84009	0.58522445	0.074906491	2932.6636
228.74097	0.58478087	0.07569281	2936.689
229.64185	0.58997679	0.076508336	2940.2266
230.54272	0.58782756	0.077357002	2938.8704
231.4436	0.59329331	0.078127757	2944.0659
232.34448	0.59799558	0.079243012	2952.7664
233.24536	0.59889483	0.080326527	2951.7678
234.14624	0.60108423	0.081259698	2949.2305
235.04712	0.60739315	0.082118288	2953.5654
235.948	0.60795003	0.083022654	2954.4375
236.84888	0.61285853	0.084074974	2965.9468
237.74976	0.61129427	0.08510077	2963.4385
238.65063	0.61549509	0.086159602	2964.2319
239.55151	0.61759192	0.087212026	2973.3142
240.45239	0.6187194	0.088095687	2965.9128
241.35327	0.62426984	0.089110784	2974.8008
242.25415	0.62453622	0.090166844	2979.2573
243.15503	0.62903309	0.091370508	2989.2192
244.05591	0.6315034	0.092518315	2983.3796
244.95679	0.6332767	0.093535691	2976.4617
245.85767	0.63618433	0.094483882	2984.085
246.75854	0.63936567	0.095458888	2989.783
247.65942	0.64331359	0.096450113	2999.6401
248.5603	0.64546227	0.097693339	2999.5217
249.46118	0.64888579	0.098599665	3001.5964
250.36206	0.65039051	0.099694282	2999.2747
251.26294	0.65410656	0.10068836	3004.0042
252.16382	0.66053468	0.10175803	3013.5293
253.0647	0.65902001	0.10271465	3003.2896
253.96558	0.65941501	0.10348505	3007.697
254.86646	0.66301692	0.10446122	3014.2429
255.76733	0.66726369	0.10558602	3016.8684
256.66821	0.6711967	0.10655839	3021.1943
257.56909	0.67282003	0.10775433	3025.4834
258.46997	0.67602104	0.10872942	3023.5022
259.37085	0.68085575	0.10973129	3022.6042
260.27173	0.68274671	0.11063226	3026.4734
261.17261	0.68036509	0.11170166	3029.6746
262.07349	0.68836802	0.11293548	3036.3735
262.97437	0.68889743	0.11379908	3028.4294
263.87524	0.69470316	0.114663	3033.9609
264.77612	0.69620931	0.11579213	3041.9644
265.677	0.69570673	0.11661111	3040.5898
266.57788	0.70126694	0.11757895	3039.7253
267.47876	0.70042837	0.11845274	3040.8481
268.37964	0.70307428	0.11958314	3053.8965
269.28052	0.70492345	0.12068883	3052.0054
270.1814	0.70937979	0.1217909	3053.5173
271.08228	0.71199536	0.12287499	3049.7368
271.98315	0.71620214	0.12400902	3054.6951
272.88403	0.71741182	0.12520428	3057.8716
273.78491	0.72243917	0.12620011	3060.7512
274.68579	0.721636	0.12712555	3063.5557
275.58667	0.7263689	0.12825735	3069.8699
276.48755	0.72857511	0.12931	3064.5535
277.38843	0.73464972	0.13038389	3072.9392
278.28931	0.7347669	0.13130371	3068.9199
279.19019	0.73819363	0.13254702	3076.3721
280.09106	0.74163169	0.13368042	3078.0261
280.99194	0.74278581	0.13453946	3074.9082
281.89282	0.74684507	0.13535617	3080.113
282.7937	0.74809241	0.13643077	3082.1743
283.69458	0.75181687	0.13725045	3084.8284
284.59546	0.75390261	0.13825123	3093.3247
285.49634	0.75428206	0.13934693	3090.447
286.39722	0.76313412	0.14060602	3100.3699
287.2981	0.76009095	0.14177765	3095.9434
288.19897	0.76646376	0.14301835	3095.4663
289.09985	0.76630294	0.14405552	3099.2437
290.00073	0.77059555	0.1450101	3095.5881
290.90161	0.77636892	0.14611349	3102.897
291.80249	0.77841514	0.14699845	3104.688
292.70337	0.77782935	0.14807275	3107.9487
293.60425	0.78148824	0.1491154	3113.9382
294.50513	0.78082931	0.15006706	3108.8901
295.40601	0.78453517	0.15123332	3112.8901
296.30688	0.79158372	0.15219754	3120.7119
297.20776	0.79439557	0.15344702	3122.0071
298.10864	0.79592943	0.15434361	3114.3096
299.00952	0.79749417	0.15531483	3121.3564
299.9104	0.80091417	0.15600842	3117.0642
300.81128	0.80159277	0.15698169	3123.0024
301.71216	0.80620748	0.15784413	3127.1594
302.61304	0.80775189	0.15865245	3129.5195
303.51392	0.81131428	0.15978473	3130.2852
304.41479	0.81324357	0.1606499	3127.249
305.31567	0.81509918	0.16166115	3136.8352
306.21655	0.82019991	0.16298443	3139.4077
307.11743	0.82444292	0.16405417	3142.1541
308.01831	0.8268885	0.16513093	3141.0613
308.91919	0.82563543	0.16601086	3135.03
309.82007	0.82911277	0.16699016	3143.4548
310.72095	0.83379406	0.16810593	3146.4553
311.62183	0.83505285	0.16919065	3152.8696
312.52271	0.83593124	0.17019822	3148.0002
313.42358	0.84130752	0.17126401	3153.3875
314.32446	0.84058064	0.17239472	3154.6123
315.22534	0.84606218	0.17346825	3158.6716
316.12622	0.85008639	0.17430484	3156.4634
317.0271	0.85213691	0.17539228	3162.084
317.92798	0.85544157	0.17634267	3166.6873
318.82886	0.85520351	0.17755342	3165.8613
319.72974	0.86071295	0.1785285	3167.1099
320.63062	0.86228627	0.17959009	3174.4021
321.53149	0.86818337	0.18050808	3169.9304
322.43237	0.86643225	0.18169026	3174.3799
323.33325	0.87028271	0.18263382	3171.5242
324.23413	0.87328142	0.18358667	3178.6648
325.13501	0.87896937	0.18459319	3174.949
326.03589	0.8777945	0.18563327	3183.4233
326.93677	0.88287163	0.18648078	3179.4873
327.83765	0.88186193	0.18771885	3183.1204
328.73853	0.88790387	0.18869177	3180.072
329.6394	0.88696694	0.18972872	3188.8269
330.54028	0.89212364	0.19079338	3187.6978
331.44116	0.89590645	0.19192535	3192.8721
332.34204	0.89886832	0.19320481	3192.5803
333.24292	0.90134603	0.19420296	3200.2283
334.1438	0.90083098	0.19512907	3197.3086
335.04468	0.9040432	0.19620971	3197.7449
335.94556	0.90975326	0.19725226	3205.4546
336.84644	0.91327548	0.19812736	3199.4438
337.74731	0.91478366	0.19892842	3203.9529
338.64819	0.91444522	0.19987583	3208.624
339.54907	0.91850996	0.20110582	3212.4502
340.44995	0.91823339	0.20193991	3203.8164
341.35083	0.92410815	0.20297922	3213.3972
342.25171	0.92667437	0.2040792	3217.1582
343.15259	0.92937046	0.20527783	3209.4087
344.05347	0.92985219	0.2062255	3211.9622
344.95435	0.93629247	0.20735344	3222.8445
345.85522	0.93770927	0.20861466	3222.5706
346.7561	0.94066519	0.2096846	3223.9583
347.65698	0.94129419	0.21077619	3215.8254
348.55786	0.94770867	0.21167812	3223.4761
349.45874	0.94830525	0.21266243	3227.9441
350.35962	0.94992393	0.21357688	3224.8701
351.2605	0.95299745	0.2145942	3233.2498
352.16138	0.95717984	0.21542983	3230.1553
353.06226	0.95845014	0.21622813	3227.6057
353.96313	0.96030134	0.21736744	3239.7759
354.86401	0.96629018	0.21850602	3235.7886
355.76489	0.96588534	0.21971527	3241.5598
356.66577	0.97166198	0.22074455	3244.2095
357.56665	0.97170991	0.22173677	3245.5605
358.46753	0.97728354	0.22288273	3245.5288
359.36841	0.97949034	0.22383185	3250.5029
360.26929	0.98150176	0.22485642	3248.9529
361.17017	0.98430276	0.22587784	3247.052
362.07104	0.98699194	0.22706376	3251.0889
362.97192	0.98924387	0.22822368	3253.7302
363.8728	0.99117357	0.22908139	3252.1643
364.77368	0.99480253	0.22993414	3255.7917
365.67456	0.9977994	0.2309953	3258.3826
366.57544	1.0011803	0.23192129	3258.2605
367.47632	1.0007732	0.23286586	3260.8713
368.3772	1.0058988	0.23397979	3266.8621
369.27808	1.0104398	0.23515458	3269.9229
370.17896	1.0091794	0.23625271	3265.4407
371.07983	1.0133508	0.2371332	3263.8713
371.98071	1.0143838	0.23821139	3264.6062
372.88159	1.0204333	0.23910554	3265.1868
373.78247	1.022015	0.24000721	3272.575
374.68335	1.0242468	0.24117087	3269.1289
375.58423	1.0276698	0.24196155	3273.468
376.48511	1.0305223	0.24313511	3284.4346
377.38599	1.0310526	0.24417783	3284.8359
378.28687	1.0337182	0.24519834	3280.4788
379.18774	1.0386046	0.24626788	3279.0896
380.08862	1.0392671	0.24703161	3282.4026
380.9895	1.0443707	0.24806972	3283.3081
381.89038	1.0466182	0.24911293	3290.6497
382.79126	1.0489628	0.25027969	3289.0127
383.69214	1.0515329	0.25158635	3291.5835
384.59302	1.0537469	0.25252268	3288.3831
385.4939	1.0560017	0.25355068	3292.4395
386.39478	1.061443	0.25443727	3288.814
387.29565	1.0606214	0.25523639	3290.9519
388.19653	1.0641378	0.25624743	3303.113
389.09741	1.0680832	0.25740889	3302.1294
389.99829	1.074205	0.25857985	3309.1311
390.89917	1.074914	0.25991938	3315.2913
391.80005	1.0762439	0.26105461	3306.2312
392.70093	1.0794455	0.26197729	3304.3364
393.60181	1.0777578	0.26269838	3301.8555
394.50269	1.0820476	0.26361999	3307.1084
395.40356	1.0837669	0.26462701	3312.8579
396.30444	1.0916855	0.26575872	3313.1855
397.20532	1.0922723	0.26673234	3317.4529
398.1062	1.0925678	0.2677711	3311.7229
399.00708	1.0975318	0.26873872	3317.5557
399.90796	1.1001327	0.26947147	3321.0479
400.80884	1.1022426	0.27044615	3316.1992
401.70972	1.107681	0.27135348	3323.7559
402.6106	1.1066266	0.27242795	3323.1196
403.51147	1.1102417	0.27339309	3328.4426
404.41235	1.1147215	0.2743977	3329.9209
405.31323	1.1197675	0.27528277	3327.8918
406.21411	1.1194927	0.27628261	3335.1292
407.11499	1.1207291	0.27742848	3330.3467
408.01587	1.1241297	0.27842736	3333.0349
408.91675	1.1263275	0.27930668	3331.5193
409.81763	1.1303564	0.28020641	3333.3892
410.71851	1.1316031	0.28118888	3335.6736
411.61938	1.137014	0.28222662	3339.1875
412.52026	1.1387691	0.2831206	3339.0566
413.42114	1.1400893	0.28402394	3343.304
414.32202	1.143586	0.28499141	3350.8933
415.2229	1.1438497	0.28604388	3339.5359
416.12378	1.1477381	0.28723919	3350.7158
417.02466	1.1498673	0.28843254	3344.6631
417.92554	1.1537352	0.28965372	3357.7349
418.82642	1.1585394	0.29065701	3349.4758
419.72729	1.1622322	0.29163471	3352.2988
420.62817	1.1595334	0.29261473	3349.7102
421.52905	1.1647111	0.29348883	3349.6802
422.42993	1.1659449	0.29450396	3357.3071
423.33081	1.1719331	0.29533732	3351.0564
424.23169	1.1724203	0.29629123	3359.219
425.13257	1.176582	0.29738981	3364.9844
426.03345	1.1819541	0.29844043	3365.2966
426.93433	1.1796389	0.29954293	3367.0725
427.83521	1.1833633	0.30079648	3371.5361
428.73608	1.1870198	0.30179462	3365.9141
429.63696	1.1896048	0.30263677	3361.7478
430.53784	1.1917968	0.30354428	3362.1394
431.43872	1.1934998	0.30440959	3367.8801
432.3396	1.1965398	0.30543116	3373.1975
433.24048	1.2015262	0.30634096	3376.8918
434.14136	1.2034062	0.30733943	3377.3137
435.04224	1.2044384	0.30829087	3376.6252
435.94312	1.2084799	0.30956593	3382.8464
436.84399	1.2094674	0.31045189	3374.4001
437.74487	1.2135342	0.31145993	3386.6062
438.64575	1.2169431	0.31245643	3384.3586
439.54663	1.2170312	0.31335294	3381.2881
440.44751	1.2239368	0.3145147	3390.5923
441.34839	1.2281333	0.31563398	3388.8416
442.24927	1.2272245	0.31651223	3382.9604
443.15015	1.2318386	0.31744358	3381.5276
444.05103	1.2318808	0.31814596	3382.6775
444.9519	1.2371017	0.31905884	3390.6084
445.85278	1.2436914	0.31986779	3392.4512
446.75366	1.2377565	0.32075289	3391.0984
447.65454	1.2419963	0.32169795	3398.3413
448.55542	1.2429798	0.32290217	3396.7378
449.4563	1.2486765	0.32401836	3396.6294
450.35718	1.2530062	0.32492357	3401.1699
451.25806	1.2544048	0.32610345	3407.5188
452.15894	1.2555681	0.32706678	3399.4736
453.05981	1.2593746	0.32814974	3404.499
453.96069	1.2622408	0.32912311	3403.3521
454.86157	1.2632465	0.33025888	3401.4031
455.76245	1.2678977	0.33130315	3408.9021
456.66333	1.2719804	0.3323479	3407.6682
457.56421	1.2728063	0.33316356	3404.499
458.46509	1.2757263	0.33412662	3409.7314
459.36597	1.2786885	0.33503482	3415.011
460.26685	1.282143	0.33602443	3414.1831
461.16772	1.2829001	0.33697793	3414.7097
462.0686	1.2849852	0.33803818	3412.1306
462.96948	1.2884812	0.33899546	3414.6794
463.87036	1.2897381	0.3400037	3413.7839
464.77124	1.2953967	0.34097666	3418.2349
465.67212	1.2979287	0.34185264	3419.3052
466.573	1.2992498	0.34296247	3424.4231
467.47388	1.3000653	0.34394467	3424.6482
468.37476	1.3020703	0.34486839	3419.3462
469.27563	1.3055986	0.34590423	3424.7971
470.17651	1.3109032	0.34694445	3429.0044
471.07739	1.3144826	0.34816322	3428.7244
471.97827	1.3157892	0.34910461	3428.8779
472.87915	1.3183184	0.35016727	3427.6455
473.78003	1.322543	0.35127154	3431.8677
474.68091	1.3263445	0.35226199	3439.6284
475.58179	1.3284665	0.3535735	3442.1235
476.48267	1.330231	0.3545132	3434.6089
477.38354	1.3313234	0.35544112	3436.2996
478.28442	1.3370649	0.35645953	3435.6311
479.1853	1.3389617	0.35727414	3440.2827
480.08618	1.3396798	0.35833627	3446.2698
480.98706	1.3426429	0.35926366	3444.1802
481.88794	1.3446172	0.36001348	3442.7632
482.78882	1.3497274	0.36102647	3444.3967
483.6897	1.3523035	0.36193073	3448.1323
484.59058	1.3519968	0.36303011	3447.2402
485.49146	1.3572923	0.36418334	3455.9712
486.39233	1.3618591	0.36527726	3455.4167
487.29321	1.3603494	0.366099	3447.1104
488.19409	1.3662441	0.36708385	3451.4924
489.09497	1.368531	0.36812955	3455.5247
489.99585	1.371078	0.36918771	3456.4805
490.89673	1.3748378	0.37027624	3462.9973
491.79761	1.3737041	0.3713356	3450.1563
492.69849	1.3801737	0.37221265	3457.5977
493.59937	1.3817281	0.37301698	3459.1177
494.50024	1.3818671	0.37402645	3457.313
495.40112	1.3876572	0.3749142	3465.0591
496.302	1.3865722	0.37598079	3458.7742
497.20288	1.3924677	0.37713388	3468.6816
498.10376	1.3950869	0.3781203	3465.5842
499.00464	1.399016	0.37903512	3468.7183
499.90552	1.4002867	0.37996379	3463.5193
500.8064	1.4064273	0.38085195	3466.6052
501.70728	1.4065111	0.38185799	3467.2319
502.60815	1.405763	0.38289061	3472.6057
503.50903	1.4112749	0.38392761	3473.2415
504.40991	1.4143711	0.38509241	3470.874
505.31079	1.4168785	0.38616151	3479.9492
506.21167	1.4171243	0.38709679	3472.1477
507.11255	1.4202592	0.38825899	3475.5723
508.01343	1.4237927	0.38913473	3476.9934
508.91431	1.4249811	0.39030325	3479.1792
509.81519	1.4301656	0.39114448	3476.8179
510.71606	1.4343094	0.39225286	3492.1199
511.61694	1.436311	0.39313316	3484.0664
512.51782	1.4394233	0.39405617	3483.8447
513.4187	1.4368933	0.39499259	3483.0139
514.31958	1.4448478	0.39612761	3480.6106
515.22046	1.4451215	0.39697433	3480.7651
516.12134	1.4478947	0.39784339	3490.677
517.02222	1.4503946	0.39893153	3487.4902
517.9231	1.4531883	0.40001231	3490.9736
518.82397	1.456485	0.40117323	3496.6943
519.72485	1.4604406	0.40211052	3489.0742
520.62573	1.4648604	0.40314236	3494.8225
521.52661	1.4642694	0.40401563	3488.8577
522.42749	1.4687588	0.40498167	3498.2456
523.32837	1.4687397	0.40604159	3496.1348
524.22925	1.4720299	0.40715206	3497.6404
525.13013	1.4745685	0.40849099	3505.5801
526.03101	1.4774272	0.40940601	3495.1785
526.93188	1.4816405	0.41031921	3499.8372
527.83276	1.4838778	0.41137332	3509.3828
528.73364	1.4883736	0.41232663	3506.7007
529.63452	1.4908341	0.41337061	3503.3372
530.5354	1.4929256	0.41417778	3499.019
531.43628	1.4957862	0.41511539	3507.8152
532.33716	1.4977726	0.41609773	3510.9338
533.23804	1.4992884	0.41715047	3505.6421
534.13892	1.5010618	0.41824135	3509.9417
535.03979	1.5033253	0.41944048	3513.3599
535.94067	1.5093952	0.42053202	3513.0754
536.84155	1.5103095	0.42154923	3511.4766
537.74243	1.5140716	0.42259669	3509.6736
538.64331	1.5155393	0.42365488	3514.7896
539.54419	1.5200161	0.42453256	3509.8999
540.44507	1.5233369	0.42530498	3512.2666
541.34595	1.5218238	0.42627114	3516.6736
542.24683	1.5284038	0.42734289	3523.4314
543.14771	1.5299773	0.4285405	3522.0693
544.04858	1.5313851	0.42964035	3520.4468
544.94946	1.5352854	0.43066582	3523.9016
545.85034	1.5381668	0.43184996	3524.3401
546.75122	1.5408268	0.43292901	3521.9004
547.6521	1.5438753	0.43400022	3525.8652
548.55298	1.5435362	0.4349542	3522.8809
549.45386	1.5509735	0.4359673	3525.8567
550.35474	1.5495825	0.43696135	3523.4902
551.25562	1.5551784	0.43809956	3530.1272
552.15649	1.5598224	0.43889892	3529.7905
553.05737	1.5591599	0.43991208	3531.4194
553.95825	1.5595996	0.44111669	3537.9573
554.85913	1.5654956	0.44197559	3528.9575
555.76001	1.56689	0.44290373	3531.228
556.66089	1.571515	0.44385219	3535.3906
557.56177	1.5750655	0.44516441	3543.074
558.46265	1.5744015	0.44614899	3540.8582
559.36353	1.5762357	0.44724914	3538.0669
560.2644	1.5813935	0.44820657	3534.1033
561.16528	1.5866109	0.44915533	3544.429
562.06616	1.5867494	0.45009196	3534.8247
562.96704	1.5918037	0.45111522	3545.1621
563.86792	1.5911953	0.45212573	3542.2644
564.7688	1.595237	0.45326042	3547.7173
565.66968	1.5954407	0.45429882	3542.1667
566.57056	1.599913	0.45557123	3546.2769
567.47144	1.6015254	0.45668533	3545.7234
568.37231	1.6037852	0.45774502	3546.114
569.27319	1.6059232	0.45898518	3550.0161
570.17407	1.6091541	0.46018425	3549.603
571.07495	1.6141347	0.46121183	3553.55
571.97583	1.6145705	0.46221778	3545.8533
572.87671	1.6177049	0.46341923	3551.5042
573.77759	1.6200418	0.46444458	3555.7905
574.67847	1.6236016	0.46553916	3556.6313
575.57935	1.6259471	0.46653056	3555.3774
576.48022	1.6310657	0.46757814	3553.207
577.3811	1.6341081	0.46850768	3554.3694
578.28198	1.6351072	0.46953619	3562.1016
579.18286	1.6359156	0.47044232	3554.0645
580.08374	1.6414903	0.47152156	3562.1838
580.98462	1.6444271	0.47257966	3558.7026
581.8855	1.6449606	0.47350904	3558.7004
582.78638	1.6490523	0.47468147	3560.9272
583.68726	1.6528087	0.47575581	3563.0701
584.58813	1.6570933	0.47670114	3563.7302
585.48901	1.6562985	0.47760642	3567.3091
586.38989	1.6559478	0.47860286	3561.8728
587.29077	1.6631835	0.47954831	3563.7341
588.19165	1.664767	0.48063222	3567.877
589.09253	1.6693227	0.48168784	3571.1987
589.99341	1.669534	0.48277119	3566.4114
590.89429	1.673223	0.48378828	3568.7915
591.79517	1.6768001	0.48488891	3570.3132
592.69604	1.6802391	0.48586851	3575.2539
593.59692	1.6808749	0.48701698	3574.3652
594.4978	1.6833711	0.48816761	3577.3425
595.39868	1.6859826	0.48927113	3570.7615
596.29956	1.6880792	0.49031553	3574.6826
597.20044	1.6922153	0.49150628	3579.0596
598.10132	1.6936518	0.49281755	3578.0271
599.0022	1.6980616	0.49399236	3581.6917
599.90308	1.7012614	0.4952808	3583.2998
600.80396	1.7032418	0.49619567	3576.7109
601.70483	1.7041458	0.49726921	3578.4385
602.60571	1.708012	0.49840051	3581.228
603.50659	1.7070118	0.49943873	3578.946
604.40747	1.7163018	0.50071639	3584.844
605.30835	1.7136879	0.50211072	3585.4165
606.20923	1.7181202	0.50315452	3576.8633
607.11011	1.7238761	0.50405246	3580.4529
608.01099	1.7213697	0.50521451	3587.1953
608.91187	1.7277944	0.50635636	3587.5066
609.81274	1.7293338	0.50758189	3587.8274
610.71362	1.729669	0.50860292	3584.259
611.6145	1.7354369	0.50988048	3587.2041
612.51538	1.7375983	0.51087797	3594.0688
613.41626	1.7426751	0.51213288	3595.1365
614.31714	1.7425495	0.51326203	3590.7935
615.21802	1.7444043	0.51434696	3590.9446
616.1189	1.7476616	0.51557469	3591.5977
617.01978	1.7538836	0.51652253	3595.791
617.92065	1.7561817	0.51758909	3597.3032
618.82153	1.7569402	0.51863825	3597.7075
619.72241	1.7592642	0.51995635	3603.8108
620.62329	1.7640297	0.52108765	3595.8218
621.52417	1.7646432	0.52221727	3596.8262
622.42505	1.768375	0.52319682	3596.8962
623.32593	1.770619	0.52414483	3593.1086
624.22681	1.773972	0.52514952	3596.0618
625.12769	1.7760147	0.52618986	3604.3345
626.02856	1.7772903	0.52731496	3606.3254
626.92944	1.7799171	0.52877712	3607.1328
627.83032	1.7839538	0.52983028	3601.9587
628.7312	1.7867243	0.53103155	3603.7976
629.63208	1.7908483	0.5322569	3610.7312
630.53296	1.7926022	0.53341097	3606.9788
631.43384	1.795336	0.53478193	3618.1191
632.33472	1.7956245	0.53584015	3607.5557
633.2356	1.7998136	0.53699684	3606.8093
634.13647	1.8041704	0.5378266	3602.8938
635.03735	1.8087766	0.53867894	3607.7744
635.93823	1.8045213	0.53976172	3608.8154
636.83911	1.8113565	0.54095012	3609.4734
637.73999	1.8127048	0.5422253	3612.7358
638.64087	1.815891	0.54340029	3615.0168
639.54175	1.820685	0.5446682	3611.1689
640.44263	1.8219573	0.54583973	3617.751
641.34351	1.8256724	0.54688519	3613.332
642.24438	1.8275313	0.548011	3618.2473
643.14526	1.8307837	0.54938495	3621.4597
644.04614	1.8309909	0.55071676	3621.7275
644.94702	1.8327641	0.55207258	3619.3027
645.8479	1.8394234	0.55316132	3617.6816
646.74878	1.8440549	0.55437547	3623.356
647.64966	1.8440366	0.55530924	3618.1152
648.55054	1.8471533	0.55651188	3618.6592
649.45142	1.8480986	0.55769533	3618.7888
650.35229	1.8500029	0.55889463	3620.5237
651.25317	1.856941	0.56025326	3629.2195
652.15405	1.8561096	0.56156462	3623.7537
653.05493	1.8599008	0.56269848	3623.4316
653.95581	1.8612843	0.56384999	3624.4216
654.85669	1.8642786	0.56484878	3623.0798
655.75757	1.8694909	0.56581372	3624.7253
656.65845	1.8708193	0.56692207	3624.6323
657.55933	1.8727152	0.56817156	3629.2063
658.46021	1.8752103	0.5694418	3624.729
659.36108	1.8778228	0.57065803	3626.8601
660.26196	1.8782482	0.57158506	3625.1313
661.16284	1.8824236	0.57270515	3623.9006
662.06372	1.8869165	0.57398593	3626.353
662.9646	1.887542	0.57520372	3629.6968
663.86548	1.8916174	0.57638854	3632.1294
664.76636	1.8959057	0.57774961	3636.1489
665.66724	1.8978649	0.57901478	3627.0132
666.56812	1.8987951	0.58029157	3631.1833
667.46899	1.9063216	0.58148092	3637.3267
668.36987	1.9029102	0.58249646	3631.437
669.27075	1.911097	0.58374631	3637.8406
670.17163	1.9097464	0.58499038	3636.3337
671.07251	1.9154168	0.58621019	3639.9688
671.97339	1.911944	0.58743596	3636.2871
672.87427	1.9170873	0.5886122	3633.8196
673.77515	1.9220265	0.58972275	3636.5803
674.67603	1.9233412	0.59089595	3638.0835
675.5769	1.9259356	0.59256387	3645.197
676.47778	1.9299998	0.59409922	3642.9658
677.37866	1.9312863	0.59573025	3644.8262
678.27954	1.9367632	0.59705967	3641.9021
679.18042	1.9383422	0.59829003	3637.7212
680.0813	1.9396222	0.59952992	3643.4551
680.98218	1.9426978	0.60074741	3643.2844
681.88306	1.9473897	0.60190809	3646.7317
682.78394	1.9515189	0.60333675	3651.9761
683.68481	1.9524024	0.60465026	3643.061
684.58569	1.9566553	0.60591382	3643.6289
685.48657	1.9569144	0.60709399	3644.6443
686.38745	1.9586316	0.60820919	3646.4065
687.28833	1.9627385	0.60942298	3644.6101
688.18921	1.9678589	0.61057061	3649.0522
689.09009	1.9666034	0.61160523	3643.7063
689.99097	1.9719477	0.61292928	3653.6953
690.89185	1.9737591	0.61418921	3649.4067
691.79272	1.973883	0.61558801	3649.6758
692.6936	1.9763033	0.61684805	3647.9231
693.59448	1.9828287	0.61826205	3651.6155
694.49536	1.9836962	0.61954355	3651.2151
695.39624	1.9881607	0.62082237	3652.3145
696.29712	1.9880198	0.62213105	3650.0229
697.198	1.9948022	0.62332124	3652.3364
698.09888	1.9955947	0.62457407	3655.0298
698.99976	1.9981985	0.62609637	3654.0645
699.90063	2.0009232	0.62716728	3649.9065
700.80151	2.0035934	0.62815207	3649.7336
701.70239	2.0054793	0.62940437	3655.4006
702.60327	2.00611	0.63071537	3653.6719
703.50415	2.0076711	0.63213807	3652.2195
704.40503	2.0115068	0.6332674	3656.5364
705.30591	2.0151649	0.6347695	3660.4758
706.20679	2.0195298	0.63600731	3659.0388
707.10767	2.021754	0.63727695	3658.4207
708.00854	2.0258012	0.6385386	3660.5859
708.90942	2.0266235	0.63998556	3658.9619
709.8103	2.0313752	0.64144933	3661.7168
710.71118	2.0339394	0.64281934	3659.0762
711.61206	2.0351887	0.64431679	3665.3132
712.51294	2.0375214	0.645805	3661.6763
713.41382	2.040731	0.64700705	3659.6218
714.3147	2.0420942	0.64840114	3663.6616
715.21558	2.0485389	0.64990366	3665.6223
716.11646	2.0458157	0.65128481	3662.7085
717.01733	2.0535696	0.65261334	3665.9834
717.91821	2.0532901	0.65398651	3668.6082
718.81909	2.0588911	0.65557349	3670.3889
719.71997	2.0596304	0.65685165	3666.6021
720.62085	2.0648999	0.65817863	3668.5173
721.52173	2.0668736	0.65969527	3665.9639
722.42261	2.0696604	0.66092092	3667.585
723.32349	2.0695984	0.66262996	3671.4036
724.22437	2.06973	0.66398919	3663.0261
725.12524	2.0771918	0.66513604	3662.9417
726.02612	2.0797451	0.6663419	3668.4873
726.927	2.0787055	0.66762453	3666.2263
727.82788	2.0840299	0.66898501	3672.3618
728.72876	2.0854514	0.67047626	3669.6172
729.62964	2.0862629	0.67186022	3667.2954
730.53052	2.0896804	0.67321306	3667.7668
731.4314	2.0990164	0.67436641	3671.3142
732.33228	2.0950935	0.67562944	3668.832
733.23315	2.1015303	0.67696846	3673.6995
734.13403	2.1057632	0.67813796	3668.3159
735.03491	2.1017959	0.67957383	3668.8899
735.93579	2.1060219	0.68095624	3667.7219
736.83667	2.1101761	0.68252039	3675.2737
737.73755	2.1127329	0.68389153	3670.2417
738.63843	2.1169086	0.68521553	3672.9299
739.53931	2.1197584	0.68667293	3673.7073
740.44019	2.122782	0.68823701	3673.8171
741.34106	2.1262574	0.68988174	3674.2266
742.24194	2.1254871	0.69129485	3676.9395
743.14282	2.1273112	0.69314986	3675.8845
744.0437	2.1338174	0.69474792	3680.3079
744.94458	2.1355934	0.69644839	3677.3345
745.84546	2.1387339	0.69804287	3676.3291
746.74634	2.1418192	0.69969165	3675.3967
747.64722	2.1431167	0.7010861	3675.4709
748.5481	2.1480684	0.70280057	3680.2502
749.44897	2.1498942	0.70440799	3680.699
750.34985	2.1521056	0.7057665	3671.7502
751.25073	2.1558867	0.70735109	3677.4846
752.15161	2.1541882	0.70860982	3673.6323
753.05249	2.1596856	0.70987207	3674.22
753.95337	2.1609504	0.71107394	3675.0171
754.85425	2.1663229	0.71229625	3677.2717
755.75513	2.1681039	0.71370947	3677.397
756.65601	2.1699307	0.71527892	3682.2395
757.55688	2.173121	0.71683133	3682.2258
758.45776	2.1740758	0.71839577	3678.9988
759.35864	2.1803641	0.71980858	3683.2407
760.25952	2.1821427	0.72142035	3680.3892
761.1604	2.1864145	0.72290504	3684.3738
762.06128	2.1860178	0.72462869	3684.8508
762.96216	2.1845274	0.72637701	3680.9287
763.86304	2.1906426	0.72796172	3680.4043
764.76392	2.1927571	0.72961748	3679.0181
765.66479	2.1984284	0.73098207	3680.0869
766.56567	2.2001593	0.7324661	3683.1218
767.46655	2.2026668	0.73393399	3683.6262
768.36743	2.2047379	0.73517191	3678.6484
769.26831	2.209461	0.73619711	3674.8708
770.16919	2.2112596	0.73764491	3684.6135
771.07007	2.2137623	0.73898423	3683.4158
771.97095	2.2142363	0.74047011	3686.6968
772.87183	2.2202909	0.7421065	3687.9021
773.77271	2.220962	0.74404764	3690.9214
774.67358	2.2249613	0.7461068	3691.0525
775.57446	2.2264662	0.74764436	3680.3748
776.47534	2.2301452	0.74933249	3679.5713
777.37622	2.2346873	0.75062412	3679.5676
778.2771	2.2358592	0.7523154	3686.1899
779.17798	2.2359865	0.7540319	3687.1575
780.07886	2.2401755	0.75564784	3692.8462
780.97974	2.2426207	0.75748628	3689.2996
781.88062	2.2467101	0.75909907	3688.2256
782.78149	2.2478728	0.76092279	3687.0188
783.68237	2.2505352	0.762447	3686.9297
784.58325	2.2549927	0.76420605	3690.584
785.48413	2.2560029	0.76577139	3685.3669
786.38501	2.2581768	0.76730406	3680.4146
787.28589	2.2624881	0.76875538	3683.0242
788.18677	2.2635624	0.77028316	3683.9907
789.08765	2.269984	0.77213115	3686.8655
789.98853	2.2716689	0.77392393	3691.0688
790.8894	2.2744997	0.77558982	3683.6331
791.79028	2.2750182	0.77727276	3687.8997
792.69116	2.2790668	0.77877146	3686.1782
793.59204	2.2794256	0.78045422	3682.8118
794.49292	2.2854145	0.78220129	3688.126
795.3938	2.2858648	0.78400797	3686.6301
796.29468	2.2895977	0.78564721	3685.469
797.19556	2.2936652	0.78738177	3689.3691
798.09644	2.2937038	0.78904831	3685.9297
798.99731	2.2951493	0.79109746	3687.9246
799.89819	2.2996264	0.79287457	3686.4294
800.79907	2.3015599	0.79435182	3682.7942
801.69995	2.3075433	0.79592204	3686.1357
802.60083	2.3083267	0.79737401	3687.198
803.50171	2.3125858	0.79961538	3688.3892
804.40259	2.312073	0.80154461	3689.3486
805.30347	2.3146019	0.80323911	3683.5151
806.20435	2.3197479	0.80505288	3686.8796
807.10522	2.3190219	0.80663389	3686.8484
808.0061	2.3262682	0.80817002	3687.6809
808.90698	2.3291495	0.80977947	3692.8687
809.80786	2.3311336	0.81146204	3688.647
810.70874	2.33183	0.81364369	3690.9475
811.60962	2.3351226	0.81521034	3681.8286
812.5105	2.3394094	0.81705582	3689.7183
813.41138	2.3415005	0.81882197	3690.426
814.31226	2.3428762	0.82074499	3690.5078
815.21313	2.3466561	0.82277328	3688.981
816.11401	2.349664	0.82434422	3682.8721
817.01489	2.3522747	0.826325	3689.7781
817.91577	2.354284	0.8281576	3690.0352
818.81665	2.355689	0.83010948	3687.7964
819.71753	2.3564184	0.83230042	3692.8916
820.61841	2.3617544	0.83454263	3693.4771
821.51929	2.3666897	0.83655053	3690.8945
822.42017	2.3675354	0.83834213	3682.7468
823.32104	2.3722563	0.84019482	3691.2151
824.22192	2.3743489	0.84242105	3686.7356
825.1228	2.3781636	0.84458232	3685.0356
826.02368	2.3765864	0.84634662	3686.4812
826.92456	2.3809297	0.84820116	3681.9207
827.82544	2.3822944	0.8501302	3690.6934
828.72632	2.3862422	0.8520332	3685.8054
829.6272	2.3926685	0.85366082	3683.8552
830.52808	2.3910799	0.85501182	3681.0828
831.42896	2.3950284	0.85660738	3687.4116
832.32983	2.3960912	0.85833704	3690.5125
833.23071	2.3988864	0.86024284	3685.5088
834.13159	2.4036126	0.861974	3690.6902
835.03247	2.4046226	0.86417055	3689.4412
835.93335	2.4087284	0.86595684	3685.113
836.83423	2.4105363	0.86815733	3691.7104
837.73511	2.4126894	0.87020206	3684.3743
838.63599	2.4163275	0.87199605	3686.7576
839.53687	2.4180515	0.87409729	3693.3093
840.43774	2.4236045	0.87622195	3687.1152
841.33862	2.4238083	0.87828755	3683.6567
842.2395	2.4251783	0.88015866	3685.6079
843.14038	2.4282146	0.88248241	3688.946
844.04126	2.4340169	0.88449609	3680.3711
844.94214	2.4398909	0.88641524	3684.1804
845.84302	2.4353688	0.88845456	3683.634
846.7439	2.4408638	0.89041114	3687.0967
847.64478	2.4431014	0.89270079	3684.3628
848.54565	2.4419324	0.89483726	3678.3318
849.44653	2.4501069	0.89708281	3683.5713
850.34741	2.45013	0.89920521	3680.0898
851.24829	2.453402	0.90138471	3683.8062
852.14917	2.4560297	0.90331125	3673.6191
853.05005	2.4567068	0.90521455	3679.6184
853.95093	2.4650028	0.90736145	3686.1377
854.85181	2.4630325	0.90952945	3681.1667
855.75269	2.4682233	0.91175842	3686.8552
856.65356	2.4688389	0.91399443	3679.967
857.55444	2.4731848	0.9163245	3677.6853
858.45532	2.4772232	0.91842693	3683.3206
859.3562	2.479722	0.92055523	3677.8372
860.25708	2.4813766	0.92255801	3678.8564
861.15796	2.4862108	0.92443103	3680.4033
862.05884	2.4838605	0.92655367	3678.5159
862.95972	2.4883518	0.92880625	3678.1912
863.8606	2.4947913	0.93109936	3681.7068
864.76147	2.4942191	0.93349224	3675.8799
865.66235	2.4986813	0.93577045	3682.3625
866.56323	2.499871	0.93791437	3675.6843
867.46411	2.5039761	0.93991905	3674.6155
868.36499	2.5078263	0.94228959	3679.489
869.26587	2.5084841	0.94443238	3672.0364
870.16675	2.5091352	0.94639409	3670.4924
871.06763	2.5123453	0.94849801	3676.1606
871.96851	2.5174079	0.95072341	3679.0325
872.86938	2.5197499	0.9529255	3672.5608
873.77026	2.5254099	0.95519412	3679.7859
874.67114	2.5240138	0.95774502	3672.8
875.57202	2.5255218	0.96035624	3675.676
876.4729	2.527019	0.96315777	3673.1379
877.37378	2.5349188	0.96578294	3668.2017
878.27466	2.5360835	0.96823716	3671.1882
879.17554	2.5382493	0.97042865	3673.093
880.07642	2.5404565	0.97261381	3672.354
880.97729	2.5437224	0.97456157	3665.822
881.87817	2.5462172	0.97685885	3667.9226
882.77905	2.5485468	0.97891843	3675.0752
883.67993	2.552134	0.98119444	3669.0435
884.58081	2.5548334	0.98362041	3675.3926
885.48169	2.5601232	0.98620367	3668.1724
886.38257	2.5596611	0.98859239	3662.0857
887.28345	2.5635304	0.9907124	3667.6484
888.18433	2.5649958	0.99297041	3664.6228
889.08521	2.5675881	0.99493438	3662.6323
889.98608	2.571373	0.99725562	3664.5933
890.88696	2.5725949	0.9999159	3665.1118
891.78784	2.5743866	1.002337	3657.5894
892.68872	2.5797796	1.0045406	3660.8818
893.5896	2.5838938	1.0070055	3665.9529
894.49048	2.5840816	1.0096183	3662.8357
895.39136	2.5854697	1.0125265	3659.9937
896.29224	2.5902522	1.0151333	3660.1379
897.19312	2.5918059	1.0178931	3658.6284
898.09399	2.593956	1.0202509	3653.6863
898.99487	2.5979676	1.0226594	3656.0178
899.89575	2.6003065	1.0253547	3659.259
900.79663	2.606324	1.0284758	3655.7678
901.69751	2.6057515	1.0312694	3652.5625
902.59839	2.6091399	1.0339804	3652.3728
903.49927	2.609587	1.0358642	3651.3975
904.40015	2.6140862	1.0383787	3651.9036
905.30103	2.6165717	1.0407861	3648.3931
906.2019	2.6188974	1.0435157	3646.9927
907.10278	2.6237972	1.0455799	3645.0911
908.00366	2.6249225	1.0476445	3649.3713
908.90454	2.6260972	1.0500536	3647.0254
909.80542	2.6308925	1.0530308	3648.9529
910.7063	2.6349661	1.0554805	3642.7813
911.60718	2.635227	1.0577347	3641.6855
912.50806	2.6385345	1.0599697	3644.822
913.40894	2.6403337	1.0625528	3644.3457
914.30981	2.6435108	1.0652212	3641.4492
915.21069	2.6471007	1.0678946	3644.2744
916.11157	2.6489697	1.0706366	3640.2908
917.01245	2.6508729	1.0734546	3635.5188
917.91333	2.6529293	1.076111	3642.6223
918.81421	2.6580436	1.0784589	3629.6191
919.71509	2.6592181	1.0808209	3632.8184
920.61597	2.663554	1.0830833	3636.043
921.51685	2.6653581	1.0859022	3635.4036
922.41772	2.6708784	1.0885543	3633.6172
923.3186	2.6684089	1.0911206	3626.5664
924.21948	2.6715183	1.0940577	3631.1794
925.12036	2.6766922	1.0975935	3634.6306
926.02124	2.6804671	1.1005956	3622.8147
926.92212	2.6798928	1.1031686	3624.7212
927.823	2.6831601	1.1058403	3623.5327
928.72388	2.6880918	1.1090997	3622.3733
929.62476	2.6897638	1.1117333	3620.4692
930.52563	2.6933589	1.1143681	3616.4058
931.42651	2.6948061	1.1170104	3612.9255
932.32739	2.6973531	1.1192752	3611.593
933.22827	2.7009499	1.1221961	3617.0342
934.12915	2.7061868	1.1247283	3621.1067
935.03003	2.7035503	1.127618	3610.406
935.93091	2.7099435	1.1308261	3620.147
936.83179	2.7111113	1.1344035	3607.5969
937.73267	2.7136433	1.1370643	3607.6917
938.63354	2.7171564	1.1397876	3605.1794
939.53442	2.7185032	1.1421704	3601.5276
940.4353	2.7240365	1.1443841	3602.3799
941.33618	2.7240264	1.1469434	3600.875
942.23706	2.7248867	1.149611	3597.5837
943.13794	2.7307613	1.152131	3599.8508
944.03882	2.7321715	1.154838	3597.239
944.9397	2.7365096	1.157897	3597.6458
945.84058	2.7389307	1.1606332	3595.7856
946.74146	2.7409232	1.1631773	3588.9236
947.64233	2.7446423	1.1656717	3593.6501
948.54321	2.7434952	1.16811	3588.5803
949.44409	2.7494442	1.1706665	3589.2261
950.34497	2.751291	1.1732026	3587.3115
951.24585	2.7556894	1.1757051	3584.2087
952.14673	2.7594697	1.1786357	3585.1226
953.04761	2.7605398	1.1818181	3585.0881
953.94849	2.7619569	1.184687	3578.0615
954.84937	2.7632091	1.1875557	3573.6689
955.75024	2.7674818	1.1902852	3578.4768
956.65112	2.7713568	1.1929547	3576.7925
957.552	2.7755125	1.1959499	3573.2278
958.45288	2.7745345	1.199152	3570.7617
959.35376	2.7782929	1.2018956	3568.5876
960.25464	2.7797034	1.2049977	3568.0918
961.15552	2.7850449	1.2083066	3569.6047
962.0564	2.7848916	1.2114393	3559.8093
962.95728	2.7890096	1.2138941	3557.478
963.85815	2.7905383	1.2167817	3559.644
964.75903	2.7939003	1.2196363	3551.7195
965.65991	2.7967429	1.2222548	3553.0447
966.56079	2.8028562	1.2252471	3556.8789
967.46167	2.8021705	1.2284353	3555.876
968.36255	2.8054345	1.2308797	3550.5715
969.26343	2.8119729	1.2338651	3547.2234
970.16431	2.8101554	1.2366484	3547.0427
971.06519	2.810874	1.2397352	3546.8206
971.96606	2.8163667	1.2427222	3538.2485
972.86694	2.8194222	1.2453636	3542.655
973.76782	2.8207643	1.2478575	3532.8196
974.6687	2.8281035	1.2503245	3533.8999
975.56958	2.8285716	1.2531765	3540.5457
976.47046	2.8291686	1.2567863	3530.7043
977.37134	2.8352187	1.2599887	3530.7676
978.27222	2.8360929	1.2631205	3528.5874
979.1731	2.8394547	1.2660121	3518.5442
980.07397	2.8430583	1.2683495	3516.5925
980.97485	2.8410947	1.2710335	3517.2886
981.87573	2.8457739	1.273746	3514.1702
982.77661	2.8481345	1.2767709	3518.4893
983.67749	2.8505287	1.2799716	3515.5588
984.57837	2.8506534	1.2830219	3511.5339
985.47925	2.8548682	1.2864163	3505.8115
986.38013	2.8596845	1.2893034	3504.6641
987.28101	2.863493	1.292575	3503.8748
988.18188	2.8643012	1.2957602	3506.1936
989.08276	2.8698101	1.2987767	3496.6323
989.98364	2.8738885	1.3015506	3493.6743
990.88452	2.8773892	1.3040456	3487.3022
991.7854	2.8773406	1.3064859	3487.9216
992.68628	2.8781078	1.3090628	3485.7307
993.58716	2.8807969	1.3117054	3483.3289
994.48804	2.8856168	1.3146781	3480.7498
995.38892	2.8857133	1.317618	3475.5933
996.28979	2.8896632	1.32014	3470.4482
997.19067	2.8928285	1.3230964	3482.499
998.09155	2.8970258	1.3264418	3471.2009
998.99243	2.8972645	1.3295796	3463.8557
999.89331	2.9023883	1.33251	3469.8059
1000.7942	2.9030442	1.3356982	3458.343
1001.6951	2.9051349	1.3393188	3461.8389
1002.5959	2.9077051	1.3421056	3453.2527
1003.4968	2.9136806	1.344646	3455.7007
1004.3977	2.9103091	1.3474903	3446.4778
1005.2986	2.9155915	1.3506033	3449.3604
1006.1995	2.921366	1.3533031	3444.3342
1007.1003	2.9223382	1.3557919	3439.2881
1008.0012	2.9259048	1.3583792	3440.488
1008.9021	2.9255891	1.3613183	3432.8494
1009.803	2.9315028	1.3642614	3435.0352
1010.7039	2.9347756	1.3676344	3433.1431
1011.6047	2.9355953	1.3707601	3426.9253
1012.5056	2.9407289	1.3740995	3425.0422
1013.4065	2.9382138	1.3771571	3414.3682
1014.3074	2.9448626	1.379699	3411.4724
1015.2083	2.943327	1.3825338	3407.5044
1016.1091	2.9508903	1.385114	3409.1719
1017.01	2.9567444	1.387852	3409.0896
1017.9109	2.9548185	1.390723	3406.322
1018.8118	2.9546897	1.3936487	3400.8264
1019.7126	2.9602721	1.3964077	3398.8755
1020.6135	2.9644051	1.3994437	3397.0098
1021.5144	2.9646649	1.4022399	3393.0703
1022.4153	2.9678082	1.405347	3390.6938
1023.3162	2.9717023	1.4086399	3382.4875
1024.217	2.9724813	1.4112215	3376.1152
1025.1179	2.9770563	1.4140611	3376.5217
1026.0188	2.978507	1.4163877	3366.9363
1026.9197	2.9818082	1.4193519	3377.304
1027.8206	2.9858999	1.4218385	3363.9744
1028.7214	2.9875302	1.4239395	3365.0134
1029.6223	2.9909823	1.4257743	3358.5078
1030.5232	2.9939175	1.4278489	3361.5012
1031.4241	2.9948404	1.4307421	3358.9016
1032.325	2.9974637	1.4338573	3350.4246
1033.2258	3.0015779	1.4370509	3353.3425
1034.1267	3.0001104	1.4401546	3343.7622
1035.0276	3.0084977	1.443345	3344.323
1035.9285	3.0092132	1.4468691	3333.6736
1036.8293	3.0102022	1.4501182	3330.6257
1037.7302	3.0141602	1.4524883	3323.0828
1038.6311	3.0162733	1.4553138	3322.3264
1039.532	3.0196347	1.4580218	3323.3694
1040.4329	3.0189745	1.4611632	3315.1934
1041.3337	3.0236695	1.464599	3313.2983
1042.2346	3.0294774	1.4676056	3306.6147
1043.1355	3.0312674	1.4706818	3308.0256
1044.0364	3.0338671	1.4736975	3301.7358
1044.9373	3.0359483	1.4767232	3293.0935
1045.8381	3.0437007	1.479656	3291.6445
1046.739	3.0415666	1.4826895	3290.3223
1047.6399	3.0415337	1.4860334	3278.095
1048.5408	3.04829	1.4892085	3277.5569
1049.4417	3.0500581	1.4923735	3273.1106
1050.3425	3.0521169	1.4949327	3268.5388
1051.2434	3.0537124	1.4976108	3267.6089
1052.1443	3.0568457	1.5008087	3265.1221
1053.0452	3.0582318	1.5044724	3259.4131
1053.946	3.0632467	1.5078638	3247.3108
1054.8469	3.0653808	1.511034	3241.7742
1055.7478	3.0698521	1.5138656	3239.3855
1056.6487	3.0701766	1.5169042	3241.1548
1057.5496	3.0729592	1.520349	3234.3074
1058.4504	3.0796297	1.5235111	3223.8381
1059.3513	3.0772526	1.5265114	3221.1626
1060.2522	3.0806596	1.529353	3212.5598
1061.1531	3.082422	1.5325001	3215.0547
1062.054	3.0862625	1.5360494	3213.012
1062.9548	3.0886097	1.5395739	3197.5608
1063.8557	3.0947096	1.5424151	3195.4482
1064.7566	3.0909605	1.5451633	3191.5073
1065.6575	3.0992424	1.5481074	3190.8037
1066.5583	3.102443	1.5513544	3182.2192
1067.4592	3.103019	1.5543971	3177.551
1068.3601	3.1076379	1.5581203	3171.4668
1069.261	3.1074653	1.5608165	3164.0286
1070.1619	3.111933	1.5635506	3162.3428
1071.0627	3.1147478	1.5668064	3155.9136
1071.9636	3.1174078	1.5701137	3150.1028
1072.8645	3.1221049	1.5726985	3141.8479
1073.7654	3.1230681	1.5760355	3145.0156
1074.6663	3.1254046	1.5792742	3135.9863
1075.5671	3.1275604	1.583214	3127.8005
1076.468	3.1308331	1.586386	3115.2178
1077.3689	3.1330748	1.5896462	3116.2151
1078.2698	3.1355665	1.5930837	3112.0107
1079.1707	3.1414258	1.5960197	3103.7512
1080.0715	3.1440163	1.5988158	3100.7168
1080.9724	3.1430748	1.6017156	3083.8054
1081.8733	3.1454651	1.6042027	3085.0371
1082.7742	3.1506767	1.6072308	3076.5879
1083.675	3.1552739	1.6105063	3075.8018
1084.5759	3.1540177	1.6138883	3072.4822
1085.4768	3.1597683	1.6179841	3065.8535
1086.3777	3.1622567	1.6215552	3048.9063
1087.2786	3.1647372	1.6243463	3044.3157
1088.1794	3.1655374	1.6275777	3039.0437
1089.0803	3.1688519	1.6307745	3029.1062
1089.9812	3.1723182	1.6333804	3023.3508
1090.8821	3.1745379	1.6365535	3020.1123
1091.783	3.1784766	1.6401536	3008.1621
1092.6838	3.1836736	1.6431116	3007.8706
1093.5847	3.181637	1.6459396	2995.689
1094.4856	3.186753	1.6491045	2993.5679
1095.3865	3.1842024	1.6525711	2986.033
1096.2874	3.1896727	1.6563381	2978.6528
1097.1882	3.1937308	1.6598696	2964.0813
1098.0891	3.193965	1.6632949	2950.8015
1098.99	3.1966615	1.6665775	2940.7944
1099.8909	3.2033765	1.669831	2939.8181
1100.7917	3.2051101	1.6735734	2927.5361
1101.6926	3.2083199	1.6787943	2907.5859
1102.5935	3.2123868	1.6828943	2887.843
1103.4944	3.2116621	1.6865638	2868.0186
1104.3953	3.2146909	1.6905726	2855.8625
1105.2961	3.2190444	1.6945665	2829.127
1106.197	3.2236223	1.6991662	2813.3652
1107.0979	3.22434	1.7081609	2740.8384
1107.4983	3.2296634	1.7145286	2681.7583