File: datasets/am_bench_2022/raw_data/TH2-F/specimen.dat
MTS793|MPT|ENU|1|2|.|/|:|1|0|0|A

Operator Information						Time:	20.205811	Sec	11/3/2021 12:21:56 PM
Operator	Nick Derimow
Project	AM Bench 2022 mini-tensile challenge
Specimen ID	TH2-F
Material	PBF-L Inconel 625
Specimen Width	2.56	mm
Specimen Thickness	1.51	mm
Notes
Operator Information End

Data Acquisition						Time:	1021.1997	Sec	11/3/2021 12:38:37 PM
Time	Axial Displacement	Axial Extensometer	Axial Force
Sec	mm	mm	N
20.31958	0.0015654758	7.365807e-05	61.947048
21.220459	0.0034014524	0.00018613297	69.262817
22.121338	0.0068025915	0.00021373895	81.004814
23.022217	0.0077561541	0.00021193181	91.886284
23.923096	0.0091817854	0.0003750076	102.52283
24.823975	0.013837267	0.00046807626	112.52164
25.724854	0.017598398	0.00044528418	119.62392
26.625732	0.020005817	0.00053268147	132.5088
27.526611	0.022259003	0.00062378315	143.78491
28.42749	0.024652949	0.0007742694	153.02995
29.328369	0.024978725	0.00082061574	165.38531
30.229248	0.032698095	0.00078948872	172.64166
31.130127	0.031348683	0.00095912407	180.32108
32.031006	0.03312606	0.0010517584	196.01523
32.931885	0.036738083	0.0012227583	215.68689
33.832764	0.04014926	0.0012992923	229.13626
34.733643	0.041426755	0.0014309869	251.74797
35.634521	0.04655569	0.0015551653	268.23514
36.5354	0.04990197	0.0016690805	286.71576
37.436279	0.052759379	0.0018108138	302.64505
38.337158	0.055330504	0.0018932855	317.84308
39.238037	0.055534165	0.0019842847	333.5239
40.138916	0.056859758	0.0020774805	352.68735
41.039795	0.063128754	0.0021589522	369.0968
41.940674	0.063582383	0.0024191034	393.37579
42.841553	0.064266309	0.0025193677	411.89371
43.742432	0.070146583	0.0026181652	429.91116
44.643311	0.073014028	0.0027275104	451.83487
45.544189	0.074204601	0.0029970619	477.17206
46.445068	0.079481363	0.0029704219	491.86261
47.345947	0.080162369	0.0031289358	506.80356
48.246826	0.082523532	0.0032050477	520.5462
49.147705	0.084726468	0.0034301265	546.63226
50.048584	0.089868769	0.0035692905	573.19403
50.949463	0.091326773	0.0036416324	588.29974
51.850342	0.092582144	0.0037841084	613.45624
52.751221	0.097613752	0.0039928318	635.90826
53.6521	0.099516369	0.0040673506	654.17401
54.552979	0.10037645	0.0042415336	679.68982
55.453857	0.10537661	0.0043729139	706.7226
56.354736	0.10735724	0.0045802114	736.5155
57.255615	0.1071417	0.0046729483	760.18927
58.156494	0.11200063	0.0048691374	775.07147
59.057373	0.1142091	0.004927014	796.47644
59.958252	0.11748715	0.0051332223	827.14642
60.859131	0.12202584	0.0053464207	850.40039
61.76001	0.12367947	0.0054696654	872.15594
62.660889	0.12301977	0.005639215	896.61804
63.561768	0.12810527	0.0058560437	933.31555
64.462646	0.13268211	0.0060399938	954.6156
65.363525	0.13386346	0.0061199688	973.62109
66.264404	0.13421035	0.0062470916	998.28815
67.165283	0.13977861	0.0063876323	1012.9611
68.066162	0.14127284	0.0065402044	1050.1791
68.967041	0.14351025	0.0067714341	1070.1366
69.86792	0.14947088	0.006798577	1091.2955
70.768799	0.15203853	0.0070525622	1123.7552
71.669678	0.15444677	0.0071496372	1148.7321
72.570557	0.15267615	0.0072703212	1176.3406
73.471436	0.15775146	0.007505619	1200.9528
74.372314	0.15874681	0.0076288967	1222.3601
75.273193	0.16478157	0.0077442359	1244.3788
76.174072	0.16621663	0.007916946	1269.7881
77.074951	0.16794053	0.0081912093	1296.2617
77.97583	0.17060268	0.0083023198	1317.4698
78.876709	0.17286016	0.0083804941	1346.6067
79.777588	0.17696059	0.0084870765	1366.9076
80.678467	0.17887177	0.0086877402	1389.286
81.579346	0.18119641	0.0088454718	1414.2462
82.480225	0.181749	0.008896051	1430.6366
83.381104	0.18900168	0.009215923	1466.4995
84.281982	0.19154145	0.0093361968	1490.8696
85.182861	0.19573101	0.0095023774	1519.9944
86.08374	0.19575396	0.0096327318	1541.1587
86.984619	0.20089605	0.0097593246	1559.4077
87.885498	0.19903816	0.0099235177	1586.7286
88.786377	0.20451111	0.010075394	1613.599
89.687256	0.20660488	0.010188857	1635.5552
90.588135	0.2099167	0.010326985	1655.6765
91.489014	0.21117698	0.010515642	1679.4575
92.389893	0.21349163	0.010681012	1698.3956
93.290771	0.21596584	0.010816718	1727.8439
94.19165	0.21854578	0.011017299	1753.1304
95.092529	0.2251215	0.011083266	1778.3196
95.993408	0.22540076	0.011380129	1803.6956
96.894287	0.22825463	0.011538004	1830.3048
97.795166	0.23167032	0.011679594	1849.9772
98.696045	0.23495284	0.011708532	1866.8867
99.596924	0.23658766	0.011893605	1892.1903
100.4978	0.24103989	0.012062235	1919.9562
101.39868	0.23993783	0.012182948	1945.1707
102.29956	0.24524173	0.012394635	1968.1798
103.20044	0.24743161	0.012478976	1979.7014
104.10132	0.24890985	0.012595736	1998.8123
105.0022	0.25103313	0.012705258	2019.7721
105.90308	0.25623444	0.012928042	2046.2554
106.80396	0.25953764	0.01294349	2060.8201
107.70483	0.26169756	0.013135856	2079.1052
108.60571	0.2638104	0.013289052	2098.1218
109.50659	0.26807392	0.013357804	2114.2568
110.40747	0.26979828	0.01352035	2137.5276
111.30835	0.27130273	0.013629875	2155.7727
112.20923	0.2742376	0.01380776	2177.7156
113.11011	0.27532449	0.013960733	2193.3035
114.01099	0.28012285	0.014066464	2210.3003
114.91187	0.28394133	0.014173666	2232.0283
115.81274	0.28519747	0.014368028	2246.7871
116.71362	0.29010087	0.014530197	2263.4502
117.6145	0.29337996	0.014641452	2281.6599
118.51538	0.28973535	0.014744211	2300.1631
119.41626	0.29521632	0.014910327	2311.3198
120.31714	0.301918	0.014935999	2329.7544
121.21802	0.30254436	0.015167831	2343.3713
122.1189	0.30325145	0.015252846	2354.0293
123.01978	0.30641291	0.015436875	2371.2771
123.92065	0.31162092	0.01558062	2387.4189
124.82153	0.31396756	0.015698172	2398.5188
125.72241	0.31543964	0.015752476	2408.4226
126.62329	0.31570497	0.015923759	2415.4573
127.52417	0.31984767	0.016096255	2430.676
128.42505	0.32463139	0.016299451	2449.1853
129.32593	0.32598075	0.0164234	2463.668
130.22681	0.3276453	0.016641894	2475.5647
131.12769	0.32953373	0.016814139	2486.6355
132.02856	0.33620781	0.01701396	2503.9985
132.92944	0.33589616	0.017230092	2509.1716
133.83032	0.34205261	0.01735271	2526.3896
134.7312	0.3437272	0.017610062	2540.3518
135.63208	0.34497559	0.017607931	2543.4932
136.53296	0.34817415	0.017826589	2555.457
137.43384	0.34910962	0.018009268	2561.272
138.33472	0.35244787	0.018206328	2569.8887
139.2356	0.35851526	0.01835832	2584.5715
140.13647	0.35980564	0.018643016	2591.8918
141.03735	0.36123109	0.018915633	2611.1492
141.93823	0.36672309	0.019157274	2619.5452
142.83911	0.36830649	0.019253986	2614.594
143.73999	0.37301543	0.01951549	2626.1721
144.64087	0.37417021	0.019702401	2634.7974
145.54175	0.37491232	0.019890165	2638.6929
146.44263	0.37581953	0.020129425	2647.1443
147.34351	0.38128063	0.020395186	2660.092
148.24438	0.38314325	0.020562897	2663.05
149.14526	0.38646966	0.020836975	2674.1204
150.04614	0.38963905	0.021132277	2684.1807
150.94702	0.39373335	0.021614628	2698.6897
151.8479	0.39589551	0.021914739	2703.6604
152.74878	0.39908135	0.022101905	2707.7224
153.64966	0.39944381	0.02249823	2718.9697
154.55054	0.40225589	0.022899345	2727.9282
155.45142	0.40255031	0.023162512	2731.3628
156.35229	0.40762663	0.023613537	2736.7693
157.25317	0.41265953	0.023883197	2743.1609
158.15405	0.41529894	0.024357134	2752.947
159.05493	0.41737279	0.024732994	2767.1379
159.95581	0.4224126	0.025011327	2767.8726
160.85669	0.42084563	0.025420953	2773.3801
161.75757	0.42317581	0.025836136	2775.3313
162.65845	0.42650408	0.026233792	2787.2375
163.55933	0.43069834	0.026893709	2796.886
164.46021	0.43133861	0.027360821	2798.0684
165.36108	0.4353663	0.02787751	2806.2432
166.26196	0.43956611	0.028329425	2811.3262
167.16284	0.43921226	0.028782168	2814.6208
168.06372	0.44454861	0.029413799	2822.3364
168.9646	0.44534031	0.029821325	2823.7732
169.86548	0.45127693	0.030431537	2837.6201
170.76636	0.4489072	0.031068303	2832.5298
171.66724	0.45400852	0.031603198	2841.1016
172.56812	0.45755842	0.032172311	2849.5461
173.46899	0.46269003	0.03308212	2861.584
174.36987	0.46397182	0.033739567	2863.0413
175.27075	0.46789137	0.034505807	2868.8572
176.17163	0.46735352	0.035080872	2868.4124
177.07251	0.47012401	0.035730138	2874.0117
177.97339	0.47249851	0.036280788	2866.7615
178.87427	0.47557324	0.03701508	2879.5601
179.77515	0.47717318	0.037687	2887.0403
180.67603	0.48074874	0.038192693	2879.4961
181.5769	0.48152262	0.038861487	2887.4236
182.47778	0.48861974	0.039563686	2897.011
183.37866	0.49081898	0.040167969	2898.3284
184.27954	0.49355325	0.040850766	2901.9978
185.18042	0.49541631	0.041729536	2912.1072
186.0813	0.4981952	0.042640097	2917.0752
186.98218	0.4994165	0.043316927	2915.3831
187.88306	0.50481945	0.044129059	2921.1729
188.78394	0.50444508	0.044918984	2926.4172
189.68481	0.50703859	0.04561412	2922.219
190.58569	0.51449919	0.046449363	2934.3979
191.48657	0.51279086	0.047387023	2935.5847
192.38745	0.5199638	0.048112802	2938.6924
193.28833	0.52084035	0.048992872	2940.822
194.18921	0.52253067	0.049784187	2942.1597
195.09009	0.52315718	0.050548889	2943.3054
195.99097	0.5268845	0.051498629	2950.7024
196.89185	0.53015572	0.052221	2954.0989
197.79272	0.5344314	0.053167086	2965.283
198.6936	0.53570503	0.054097049	2962.0781
199.59448	0.53738463	0.05508773	2966.3125
200.49536	0.54171294	0.056013282	2966.4688
201.39624	0.5452913	0.056856282	2967.6274
202.29712	0.54629505	0.05786518	2981.2327
203.198	0.54825872	0.058697034	2973.261
204.09888	0.55241734	0.059466358	2975.1365
204.99976	0.55692238	0.06044146	2987.8054
205.90063	0.55985624	0.06130195	2992.0979
206.80151	0.56079215	0.062244095	2992.0122
207.70239	0.56200039	0.063097805	2988.2312
208.60327	0.566679	0.064093493	2997.9734
209.50415	0.57010162	0.065110542	2995.1963
210.40503	0.57165062	0.066103935	3001.2363
211.30591	0.57486677	0.066891409	2996.3628
212.20679	0.57708609	0.068006568	3011.0508
213.10767	0.58053827	0.068927407	3011.1682
214.00854	0.58086079	0.06997633	3016.4785
214.90942	0.58587152	0.071233168	3024.4329
215.8103	0.58904815	0.072140068	3013.7019
216.71118	0.59095258	0.07292217	3018.5347
217.61206	0.59045118	0.0736719	3018.0344
218.51294	0.59337991	0.074496932	3015.8933
219.41382	0.5995028	0.075457618	3025.7671
220.3147	0.59789604	0.076550543	3028.5366
221.21558	0.60470307	0.077442653	3035.8943
222.11646	0.60474157	0.078350417	3035.281
223.01733	0.61133403	0.079309009	3038.5356
223.91821	0.61617422	0.080412701	3043.092
224.81909	0.61505777	0.081405297	3042.5354
225.71997	0.61698508	0.082486317	3048.636
226.62085	0.61963332	0.083362974	3044.4373
227.52173	0.62341106	0.084148087	3040.1868
228.42261	0.62490958	0.085166827	3050.7307
229.32349	0.62734979	0.086041451	3051.145
230.22437	0.62708223	0.086937554	3054.1162
231.12524	0.63258368	0.088067479	3059.8572
232.02612	0.63502902	0.089000702	3061.9949
232.927	0.63921326	0.090059176	3062.4526
233.82788	0.64168876	0.090926208	3059.1042
234.72876	0.64613605	0.091895081	3068.1167
235.62964	0.6469788	0.092834704	3070.2839
236.53052	0.64665401	0.093826361	3069.1033
237.4314	0.65170079	0.094998576	3078.0579
238.33228	0.65486348	0.096152633	3073.2
239.23315	0.66059893	0.097137764	3079.7405
240.13403	0.66014433	0.098200083	3082.9465
241.03491	0.66416311	0.099107444	3082.9856
241.93579	0.66558301	0.099977762	3081.7993
242.83667	0.66886294	0.10081421	3082.0039
243.73755	0.67083949	0.10175036	3088.4021
244.63843	0.67314982	0.10287521	3093.8276
245.53931	0.67422587	0.10380504	3091.6934
246.44019	0.67759955	0.10487477	3089.0439
247.34106	0.67929929	0.10583594	3094.8726
248.24194	0.68650937	0.10675007	3099.7454
249.14282	0.68580413	0.10780869	3104.7188
250.0437	0.69104266	0.10870953	3097.4199
250.94458	0.69378167	0.10955735	3101.6453
251.84546	0.69576544	0.11047758	3102.6995
252.74634	0.69748408	0.11147007	3111.6392
253.64722	0.70011663	0.1124455	3108.1252
254.5481	0.70341879	0.11336866	3108.3574
255.44897	0.70540661	0.11448154	3117.0608
256.34985	0.70949459	0.11548179	3115.7041
257.25073	0.71308732	0.11658099	3124.9502
258.15161	0.71431577	0.11762749	3121.0237
259.05249	0.71549475	0.11856332	3122.7043
259.95337	0.71585166	0.11947042	3118.6689
260.85425	0.72186595	0.1203673	3123.6624
261.75513	0.72517222	0.12137458	3131.6848
262.65601	0.72762519	0.12226268	3127.6738
263.55688	0.7286002	0.12302241	3125.155
264.45776	0.73413938	0.124065	3132.0276
265.35864	0.73906922	0.12507993	3135.8694
266.25952	0.73795319	0.12613221	3133.865
267.1604	0.74220091	0.12698998	3135.8857
268.06128	0.74494028	0.12820061	3151.1763
268.96216	0.7462737	0.12926611	3142.9426
269.86304	0.74855417	0.13041221	3149.2197
270.76392	0.75352782	0.13157439	3150.135
271.66479	0.752002	0.13259326	3145.1821
272.56567	0.75787455	0.13368474	3153.9648
273.46655	0.76139164	0.13475427	3154.0449
274.36743	0.76355445	0.13564029	3159.5505
275.26831	0.76352906	0.13653928	3150.9226
276.16919	0.76737523	0.13754813	3160.4116
277.07007	0.7681396	0.1383954	3149.9124
277.97095	0.77424592	0.13938172	3157.7605
278.87183	0.776344	0.14021	3159.9939
279.77271	0.78038812	0.14139962	3166.9924
280.67358	0.78244966	0.14220484	3160.2588
281.57446	0.78231221	0.14314932	3166.1738
282.47534	0.7863577	0.14406914	3171.8198
283.37622	0.78939253	0.14509623	3172.5981
284.2771	0.79418039	0.14627735	3175.4595
285.17798	0.79568321	0.14733116	3174.0515
286.07886	0.79609793	0.14812313	3169.1543
286.97974	0.80204403	0.14914106	3183.9038
287.88062	0.80164117	0.15019761	3175.887
288.78149	0.80570948	0.15098813	3182.2371
289.68237	0.80638272	0.15179071	3176.415
290.58325	0.81319976	0.15284577	3183.9973
291.48413	0.81262732	0.15380885	3186.3506
292.38501	0.81469405	0.1548726	3182.0771
293.28589	0.82197946	0.15578133	3186.3689
294.18677	0.82329935	0.15679671	3189.1702
295.08765	0.8261745	0.15792586	3197.2634
295.98853	0.8283695	0.15887418	3192.8333
296.8894	0.82840252	0.15952373	3189.8728
297.79028	0.83119702	0.16051382	3196.8665
298.69116	0.83536381	0.16156127	3200.6702
299.59204	0.83861148	0.1627396	3201.4558
300.49292	0.84064335	0.16376704	3203.3674
301.3938	0.84659213	0.16479328	3205.9895
302.29468	0.84869611	0.16585627	3206.9038
303.19556	0.85065156	0.16667925	3195.636
304.09644	0.85179424	0.16760904	3205.7446
304.99731	0.85272914	0.16859259	3208.1785
305.89819	0.85744834	0.16956565	3209.8591
306.79907	0.86363065	0.17052825	3211.5159
307.69995	0.86427009	0.17150131	3219.3174
308.60083	0.86585999	0.17243962	3221.2075
309.50171	0.87099189	0.17338775	3222.23
310.40259	0.86899483	0.17442666	3221.5447
311.30347	0.87552911	0.17553726	3222.0386
312.20435	0.87709898	0.17658579	3214.9475
313.10522	0.8789475	0.1775762	3232.4626
314.0061	0.88115025	0.17840806	3222.7827
314.90698	0.88440067	0.17935288	3221.8862
315.80786	0.88542348	0.1803886	3235.9509
316.70874	0.89070153	0.18137069	3231.582
317.60962	0.89347124	0.18229322	3235.845
318.5105	0.89760429	0.18326813	3234.0203
319.41138	0.89592069	0.18418714	3227.5852
320.31226	0.90106362	0.1852186	3235.4924
321.21313	0.90506303	0.18601617	3231.9082
322.11401	0.90690023	0.18675713	3231.5901
323.01489	0.91273588	0.18778606	3238.8
323.91577	0.91515893	0.18857525	3239.9343
324.81665	0.91204405	0.18961479	3241.8884
325.71753	0.91352123	0.19064204	3242.8909
326.61841	0.92159688	0.19174181	3250.0388
327.51929	0.92269433	0.19271132	3246.5452
328.42017	0.92317784	0.19355369	3244.8108
329.32104	0.92474467	0.19450161	3245.7915
330.22192	0.93203497	0.19561608	3258.5713
331.1228	0.93260127	0.19661465	3253.0432
332.02368	0.93794233	0.19784562	3260.9709
332.92456	0.94073719	0.19889057	3257.7051
333.82544	0.9401139	0.19991764	3250.0046
334.72632	0.94258177	0.20087729	3262.5942
335.6272	0.94772351	0.2019114	3261.6265
336.52808	0.94774723	0.20281184	3256.6003
337.42896	0.95442379	0.20414028	3271.1597
338.32983	0.95604277	0.20522052	3264.939
339.23071	0.95911962	0.20626047	3268.791
340.13159	0.96060073	0.20709658	3265.3174
341.03247	0.96139711	0.20801486	3268.2788
341.93335	0.96471679	0.20904158	3276.3445
342.83423	0.96738213	0.2098659	3269.1704
343.73511	0.96998465	0.21076603	3267.77
344.63599	0.97575617	0.21170354	3275.5442
345.53687	0.97819495	0.21264391	3275.6069
346.43774	0.9811222	0.21369706	3275.7554
347.33862	0.98255605	0.21458544	3279.3237
348.2395	0.98473209	0.21547094	3274.6094
349.14038	0.98496795	0.21648894	3280.364
350.04126	0.99194318	0.2174916	3281.281
350.94214	0.99299628	0.21841891	3287.8804
351.84302	0.99504846	0.21933305	3284.2874
352.7439	0.99737722	0.22056144	3291.2795
353.64478	1.0013458	0.22133951	3286.5652
354.54565	1.0043807	0.22209693	3285.9844
355.44653	1.0049582	0.22300117	3282.856
356.34741	1.0081185	0.22376087	3286.8022
357.24829	1.0121982	0.22468588	3292.2813
358.14917	1.0146688	0.22563452	3300.061
359.05005	1.0178223	0.22647956	3295.2932
359.95093	1.021651	0.2275514	3296.5603
360.85181	1.0234402	0.22858331	3295.2627
361.75269	1.02428	0.22978522	3304.7751
362.65356	1.0274378	0.23060229	3296.5017
363.55444	1.0304931	0.23157966	3295.5466
364.45532	1.0324199	0.23260188	3306.394
365.3562	1.0349299	0.23345982	3301.658
366.25708	1.0366808	0.2343685	3300.1829
367.15796	1.0436429	0.23543468	3306.9697
368.05884	1.0443099	0.23646186	3313.2578
368.95972	1.0466709	0.23744836	3307.2563
369.8606	1.0500909	0.23858312	3311.3562
370.76147	1.051757	0.23956439	3307.1409
371.66235	1.0562849	0.24043278	3312.0571
372.56323	1.0555873	0.24131621	3314.6194
373.46411	1.0604155	0.24243823	3318.3074
374.36499	1.0604669	0.24335563	3313.0505
375.26587	1.0684075	0.24433011	3319.0044
376.16675	1.0667683	0.24523799	3321.3364
377.06763	1.0705457	0.24619693	3312.5605
377.96851	1.072222	0.24716544	3317.5391
378.86938	1.077292	0.24820711	3325.6702
379.77026	1.0814426	0.24938664	3330.0779
380.67114	1.0820569	0.25021672	3323.4131
381.57202	1.0845872	0.2513102	3327.2083
382.4729	1.0865704	0.25249043	3331.4075
383.37378	1.0919218	0.2533704	3328.7498
384.27466	1.0931638	0.25435823	3326.0791
385.17554	1.0955629	0.255187	3330.5408
386.07642	1.0964499	0.2561478	3328.9651
386.97729	1.0972468	0.2570605	3329.8323
387.87817	1.1049523	0.25795716	3336.7375
388.77905	1.1051925	0.25890714	3330.136
389.67993	1.10991	0.25989571	3335.7986
390.58081	1.1131889	0.26080716	3345.5608
391.48169	1.1154017	0.2618961	3345.8401
392.38257	1.1179415	0.26264429	3336.1682
393.28345	1.1206384	0.26352298	3341.4253
394.18433	1.1231064	0.26441109	3338.906
395.08521	1.1262864	0.2653451	3345.7605
395.98608	1.1254879	0.2662476	3343.7354
396.88696	1.1296134	0.26720846	3344.1511
397.78784	1.134127	0.26816851	3350.3232
398.68872	1.1359711	0.2690576	3350.8057
399.5896	1.1382231	0.26994461	3348.4956
400.49048	1.1402658	0.27100328	3354.8882
401.39136	1.1460552	0.2721127	3357.8105
402.29224	1.1482805	0.27325755	3363.3262
403.19312	1.1496941	0.27436793	3357.9436
404.09399	1.152212	0.27537253	3356.6079
404.99487	1.1563606	0.27628157	3357.542
405.89575	1.1588998	0.27734482	3359.3083
406.79663	1.1601465	0.27817199	3361.3364
407.69751	1.1613654	0.27907214	3359.3679
408.59839	1.1647645	0.28000131	3362.134
409.49927	1.1692829	0.28094402	3367.5635
410.40015	1.1706198	0.28192174	3365.2651
411.30103	1.1738905	0.28299707	3364.0029
412.2019	1.1744248	0.28382522	3364.6902
413.10278	1.1785045	0.28468102	3361.6165
414.00366	1.1831468	0.28575712	3373.8823
414.90454	1.182709	0.28670555	3373.7373
415.80542	1.1881433	0.28779244	3374.7507
416.7063	1.1913593	0.28877577	3375.8123
417.60718	1.191556	0.28965551	3372.4172
418.50806	1.1929631	0.29066619	3372.5522
419.40894	1.1965131	0.29157075	3372.7517
420.30981	1.2013237	0.29265958	3380.918
421.21069	1.2026867	0.29367346	3378.0347
422.11157	1.2082795	0.29460391	3387.4529
423.01245	1.2082443	0.29551139	3384.8911
423.91333	1.2109537	0.29654613	3379.3035
424.81421	1.2122624	0.29763982	3389.7451
425.71509	1.2163175	0.29859945	3389.2651
426.61597	1.2224069	0.29962757	3379.9541
427.51685	1.2244633	0.30072588	3393.7239
428.41772	1.2247596	0.30153495	3389.5398
429.3186	1.225988	0.3025969	3391.4512
430.21948	1.2291743	0.30336055	3382.2192
431.12036	1.2324224	0.30415115	3385.6372
432.02124	1.2342113	0.30508441	3396.2546
432.92212	1.2382429	0.30597216	3397.311
433.823	1.2404108	0.30684841	3397.2668
434.72388	1.2440649	0.30779809	3397.3706
435.62476	1.2474592	0.30880314	3396.7625
436.52563	1.2483777	0.30987003	3399.5369
437.42651	1.253974	0.31089297	3398.0706
438.32739	1.2552406	0.31184214	3400.9541
439.22827	1.2576177	0.3127754	3401.2625
440.12915	1.2598588	0.31381908	3404.7673
441.03003	1.2636036	0.31475809	3402.4504
441.93091	1.2682334	0.31572416	3407.0352
442.83179	1.2680504	0.3167733	3411.3384
443.73267	1.2723564	0.31767642	3406.7822
444.63354	1.272103	0.31857371	3407.9534
445.53442	1.274937	0.31969741	3411.27
446.4353	1.2785774	0.32071045	3405.3796
447.33618	1.2825944	0.32162568	3412.8977
448.23706	1.2842706	0.32256922	3407.7119
449.13794	1.2861608	0.32362756	3419.4365
450.03882	1.2915795	0.32474658	3419.3064
450.9397	1.296428	0.32587069	3418.5591
451.84058	1.2968744	0.32674491	3412.6143
452.74146	1.2963582	0.32765108	3415.1106
453.64233	1.2994509	0.32846388	3417.5847
454.54321	1.3041879	0.32932919	3421.0144
455.44409	1.3055437	0.33029622	3426.3469
456.34497	1.30803	0.33123159	3421.0637
457.24585	1.314351	0.33214316	3424.479
458.14673	1.3149188	0.33305681	3424.2844
459.04761	1.3194708	0.33414117	3433.3938
459.94849	1.3201522	0.33519757	3425.9304
460.84937	1.3218217	0.3362782	3429.05
461.75024	1.3249656	0.33734748	3431.0295
462.65112	1.3281537	0.33848789	3436.4702
463.552	1.3280476	0.33944944	3426.0432
464.45288	1.3328506	0.34019822	3427.3972
465.35376	1.3366152	0.34097195	3430.2151
466.25464	1.3404493	0.34192887	3435.6108
467.15552	1.340768	0.34287149	3434.4622
468.0564	1.3429946	0.34380046	3438.061
468.95728	1.3472996	0.34475482	3435.3433
469.85815	1.3480507	0.34571058	3437.5859
470.75903	1.3516557	0.34674099	3438.5881
471.65991	1.353227	0.34758955	3431.2305
472.56079	1.3559245	0.34858447	3436.4814
473.46167	1.3616434	0.34942067	3434.259
474.36255	1.3600596	0.3503876	3444.2959
475.26343	1.3684795	0.35159579	3450.1914
476.16431	1.3694904	0.35269317	3444.2014
477.06519	1.3717721	0.35354555	3441.1709
477.96606	1.3738955	0.35447475	3442.2375
478.86694	1.3759534	0.3557933	3453.5801
479.76782	1.3819935	0.35682505	3455.1951
480.6687	1.3825121	0.35762355	3451.7344
481.56958	1.3865305	0.35866287	3457.7891
482.47046	1.3887225	0.3597436	3450.8713
483.37134	1.3900131	0.36062351	3446.8413
484.27222	1.3917187	0.36146727	3452.5183
485.1731	1.3925916	0.36246437	3446.8477
486.07397	1.3968314	0.36337769	3455.0532
486.97485	1.3981045	0.36447847	3457.7268
487.87573	1.4027416	0.36551982	3459.1707
488.77661	1.4046487	0.3664867	3457.343
489.67749	1.4062591	0.36757103	3459.3401
490.57837	1.4115608	0.36859581	3462.4084
491.47925	1.4178679	0.36976439	3465.4495
492.38013	1.4176111	0.37062147	3460.5063
493.28101	1.4222714	0.37162957	3466.771
494.18188	1.4230139	0.37269592	3463.1914
495.08276	1.4249189	0.37351146	3462.895
495.98364	1.4283417	0.37457347	3469.2563
496.88452	1.4305624	0.3757208	3476.4307
497.7854	1.4352435	0.37681517	3465.2136
498.68628	1.4321821	0.37779117	3466.7495
499.58716	1.4410509	0.37888223	3474.9832
500.48804	1.4426574	0.37977183	3468.3733
501.38892	1.443768	0.38063848	3469.4893
502.28979	1.4484699	0.3815912	3473.5388
503.19067	1.4500449	0.3824912	3467.4812
504.09155	1.4550099	0.38350767	3476.4116
504.99243	1.456745	0.38454482	3475.4407
505.89331	1.4550552	0.38533711	3475.0417
506.79419	1.458621	0.3862744	3473.7971
507.69507	1.4613334	0.38729137	3478.8594
508.59595	1.4682167	0.38835874	3483.1746
509.49683	1.4680197	0.38937825	3481.2214
510.39771	1.4694027	0.39047575	3479.3523
511.29858	1.4726174	0.39150521	3482.707
512.19946	1.4771559	0.39241341	3483.2451
513.10034	1.479455	0.39355886	3487.3921
514.00122	1.4802889	0.39452469	3477.3506
514.9021	1.48218	0.39540103	3482.9502
515.80298	1.4900737	0.39635232	3487.5425
516.70386	1.4883996	0.39715546	3483.6177
517.60474	1.4928131	0.39804527	3488.5334
518.50562	1.4944725	0.39906791	3493.4385
519.40649	1.4982024	0.40016487	3492.8174
520.30737	1.5004838	0.40131095	3495.8586
521.20825	1.5025072	0.40227371	3488.3323
522.10913	1.5062673	0.40336078	3498.8694
523.01001	1.509128	0.40443999	3491.165
523.91089	1.5109491	0.40535784	3491.5293
524.81177	1.5126483	0.40631449	3494.9209
525.71265	1.5172135	0.40739146	3495.6877
526.61353	1.5168301	0.40838584	3495.7524
527.5144	1.5247929	0.40940019	3496.6384
528.41528	1.5238956	0.41045982	3502.134
529.31616	1.5297043	0.41150361	3501.7434
530.21704	1.531518	0.41247204	3500.8018
531.11792	1.533505	0.4133265	3501.3684
532.0188	1.5365971	0.41449338	3509.3181
532.91968	1.5366304	0.41535276	3495.1382
533.82056	1.5432335	0.416491	3503.3167
534.72144	1.5454047	0.41775981	3511.6548
535.62231	1.5462763	0.41882914	3501.9724
536.52319	1.5464751	0.41981664	3503.0879
537.42407	1.5509901	0.42076296	3502.4209
538.32495	1.5535901	0.42153606	3506.717
539.22583	1.5564716	0.42264223	3516.7573
540.12671	1.5582781	0.42357183	3509.4385
541.02759	1.5623558	0.42440784	3509.0847
541.92847	1.5670742	0.42543539	3520.2988
542.82935	1.5676899	0.42646945	3508.7798
543.73022	1.5703071	0.42746925	3515.8474
544.6311	1.5768054	0.42837635	3514.8281
545.53198	1.5762632	0.42944878	3521.979
546.43286	1.5817428	0.43048924	3516.8701
547.33374	1.5832661	0.43155584	3518.29
548.23462	1.5865334	0.43261421	3515.7173
549.1355	1.5901215	0.43351671	3511.6831
550.03638	1.59097	0.43443328	3517.2874
550.93726	1.5920744	0.4354178	3520.3093
551.83813	1.596449	0.43645418	3521.248
552.73901	1.6029227	0.43741947	3523.5906
553.63989	1.6006989	0.43851885	3523.0894
554.54077	1.6049019	0.43950287	3527.645
555.44165	1.6092398	0.44057789	3526.936
556.34253	1.6073673	0.44187951	3532.5527
557.24341	1.610368	0.44318822	3528.4307
558.14429	1.6141514	0.4440428	3521.0967
559.04517	1.6161491	0.44526657	3532.8369
559.94604	1.6208764	0.44643191	3531.8621
560.84692	1.6202751	0.44745314	3522.5073
561.7478	1.6265955	0.44847849	3527.0369
562.64868	1.6267761	0.44928846	3523.8767
563.54956	1.6298153	0.45032063	3532.2507
564.45044	1.6340703	0.45128819	3531.1555
565.35132	1.6340723	0.45245084	3531.6541
566.2522	1.6383963	0.45339552	3531.9434
567.15308	1.643163	0.45442766	3532.2991
568.05396	1.6459095	0.45548275	3533.3174
568.95483	1.6485094	0.45653027	3539.4771
569.85571	1.647	0.45760265	3533.6018
570.75659	1.6523672	0.4587658	3544.2998
571.65747	1.6570381	0.45985329	3532.7515
572.55835	1.6550726	0.46064571	3535.7058
573.45923	1.6602181	0.46183774	3541.7383
574.36011	1.6624287	0.46272948	3530.5342
575.26099	1.6654459	0.46351376	3532.3933
576.16187	1.6688921	0.46436	3537.1064
577.06274	1.6732533	0.4656314	3549.0242
577.96362	1.6731207	0.46662182	3544.1941
578.8645	1.674422	0.46770594	3541.0876
579.76538	1.6822971	0.46882421	3549.906
580.66626	1.6829259	0.46983695	3544.8008
581.56714	1.6840984	0.47101155	3544.0649
582.46802	1.6872932	0.47183949	3541.5984
583.3689	1.6903976	0.47288805	3548.5559
584.26978	1.695109	0.47383681	3550.6687
585.17065	1.6941029	0.47508591	3546.9836
586.07153	1.6993885	0.47617772	3551.5552
586.97241	1.700834	0.47712159	3550.1575
587.87329	1.7032851	0.47830206	3550.894
588.77417	1.7072726	0.47944775	3554.7195
589.67505	1.7108257	0.48040369	3551.22
590.57593	1.7124559	0.48146114	3554.0146
591.47681	1.7129456	0.48246634	3548.7515
592.37769	1.7159855	0.48343039	3557.8352
593.27856	1.7205052	0.48440287	3559.3684
594.17944	1.7251867	0.48552051	3564.0313
595.08032	1.7239037	0.48678827	3552.8994
595.9812	1.7304975	0.48793355	3561.0244
596.88208	1.7317095	0.48904213	3557.417
597.78296	1.7333486	0.49009383	3562.2136
598.68384	1.7369584	0.49109766	3560.4395
599.58472	1.7419107	0.49221462	3563.9316
600.4856	1.7413288	0.49331927	3562.175
601.38647	1.7433249	0.49449408	3565.1536
602.28735	1.7487308	0.49548769	3558.2651
603.18823	1.7504601	0.49645051	3563.5049
604.08911	1.7515209	0.49752361	3564.5977
604.98999	1.7581259	0.498752	3569.6565
605.89087	1.7586061	0.49975964	3568.5222
606.79175	1.7589872	0.50074929	3561.4309
607.69263	1.7609357	0.50179124	3563.1904
608.59351	1.7670599	0.50296903	3566.7908
609.49438	1.7694621	0.50392103	3569.3923
610.39526	1.7722219	0.50501168	3571.3074
611.29614	1.7759951	0.50611681	3571.415
612.19702	1.7762077	0.50709015	3566.0449
613.0979	1.7828096	0.5082112	3573.0642
613.99878	1.7802794	0.50925672	3569.4482
614.89966	1.7847071	0.51026565	3569.3547
615.80054	1.7876673	0.51122707	3572.6833
616.70142	1.7884309	0.51255286	3575.0654
617.60229	1.7917112	0.51357764	3572.03
618.50317	1.7975358	0.51474458	3574.8281
619.40405	1.7995455	0.51597512	3578.5188
620.30493	1.8039819	0.51696378	3576.864
621.20581	1.8056184	0.51791739	3572.2402
622.10669	1.805737	0.51908678	3576.4785
623.00757	1.8085083	0.52005935	3579.8699
623.90845	1.8113444	0.52140969	3585.3782
624.80933	1.8127221	0.52277082	3587.1382
625.71021	1.8162339	0.52405435	3579.7761
626.61108	1.8187243	0.52527523	3580.6663
627.51196	1.8229558	0.52636898	3581.0032
628.41284	1.8242232	0.52752858	3582.1516
629.31372	1.8248196	0.52861553	3574.2043
630.2146	1.8304948	0.5297209	3583.7234
631.11548	1.833306	0.5307821	3582.9807
632.01636	1.8362308	0.53155273	3579.5305
632.91724	1.8382674	0.53281438	3582.426
633.81812	1.8411762	0.53396344	3587.2268
634.71899	1.8426682	0.5350948	3582.6951
635.61987	1.8475671	0.53624219	3587.8586
636.52075	1.8510689	0.53745008	3586.5837
637.42163	1.8537993	0.53859371	3591.2095
638.32251	1.8553053	0.53979665	3585.3516
639.22339	1.8567792	0.54089212	3585.426
640.12427	1.8600603	0.54181802	3587.9128
641.02515	1.8610399	0.54303032	3586.1245
641.92603	1.8640994	0.54402256	3590.2393
642.8269	1.8686777	0.54506689	3592.2703
643.72778	1.8716607	0.54613984	3588.937
644.62866	1.8735807	0.54718065	3589.7688
645.52954	1.8793881	0.54829139	3592.1299
646.43042	1.8828522	0.54929274	3599.0903
647.3313	1.8789837	0.55043292	3594.1079
648.23218	1.8881685	0.55152798	3600.1504
649.13306	1.8853722	0.55262899	3594.5588
650.03394	1.8887392	0.55394095	3597.3376
650.93481	1.8911344	0.55507183	3596.7546
651.83569	1.8977566	0.55621833	3597.2327
652.73657	1.8990995	0.55721229	3595.811
653.63745	1.9035648	0.55836987	3597.6792
654.53833	1.9061482	0.55936253	3594.6672
655.43921	1.9071667	0.56054902	3604.3774
656.34009	1.9080276	0.56168675	3599.7874
657.24097	1.912501	0.56272215	3601.251
658.14185	1.9159843	0.56378114	3596.6194
659.04272	1.92026	0.56489229	3598.4714
659.9436	1.919403	0.56640893	3604.6882
660.84448	1.9203624	0.56770313	3602.1067
661.74536	1.9250695	0.56890625	3604.8694
662.64624	1.9273335	0.57029772	3605.6013
663.54712	1.9319247	0.57140988	3598.4397
664.448	1.932525	0.57232904	3599.0876
665.34888	1.9362495	0.57362002	3602.4622
666.24976	1.9389828	0.57496172	3607.2134
667.15063	1.9428458	0.57626384	3609.9221
668.05151	1.9406662	0.5773918	3601.3816
668.95239	1.9470829	0.57855582	3605.3694
669.85327	1.9463764	0.57966131	3604.6223
670.75415	1.950543	0.58095884	3604.0598
671.65503	1.9533097	0.58200842	3605.7222
672.55591	1.9570395	0.58318865	3602.9758
673.45679	1.9618113	0.58445328	3607.9651
674.35767	1.9607924	0.58547419	3604.552
675.25854	1.9634051	0.58673406	3613.0674
676.15942	1.9669563	0.58790839	3610.3423
677.0603	1.97023	0.58896345	3611.3782
677.96118	1.9732277	0.59006399	3609.9246
678.86206	1.9759206	0.59127218	3610.0071
679.76294	1.9805174	0.59234512	3616.2859
680.66382	1.9834781	0.59373796	3618.3235
681.5647	1.9839863	0.59498006	3618.1204
682.46558	1.988593	0.59642416	3617.5229
683.36646	1.9901795	0.59747213	3613.083
684.26733	1.9915997	0.5985691	3607.488
685.16821	1.9956552	0.59966403	3616.9553
686.06909	1.9987181	0.60076255	3617.0115
686.96997	2.0028348	0.60194737	3622.3279
687.87085	2.0014598	0.60310215	3618.5442
688.77173	2.0049331	0.60407734	3609.751
689.67261	2.0068429	0.60517526	3621.0664
690.57349	2.0139432	0.60646647	3618.3701
691.47437	2.0161643	0.60769689	3619.0422
692.37524	2.0169103	0.60909271	3620.5208
693.27612	2.0204427	0.61039329	3623.6895
694.177	2.0211174	0.61133051	3608.6975
695.07788	2.0255971	0.6125164	3616.3115
695.97876	2.0295885	0.61352479	3617.7905
696.87964	2.0327418	0.61476588	3623.3896
697.78052	2.0310345	0.61590648	3622.7813
698.6814	2.0347891	0.61716622	3622.9265
699.58228	2.0374241	0.61850822	3621.1775
700.48315	2.0419164	0.61997706	3621.2507
701.38403	2.0448062	0.62142789	3626.2488
702.28491	2.0469036	0.62282616	3626.5645
703.18579	2.0512064	0.62414289	3624.8997
704.08667	2.0540056	0.62552267	3624.6035
704.98755	2.056443	0.62677187	3625.8235
705.88843	2.0593107	0.62809044	3623.3911
706.78931	2.0580904	0.62923771	3623.1885
707.69019	2.0620086	0.63063025	3627.1768
708.59106	2.0676911	0.63177419	3625.4939
709.49194	2.0698969	0.63292968	3625.9973
710.39282	2.0713758	0.63429314	3621.1189
711.2937	2.0764844	0.63542962	3629.9094
712.19458	2.0770867	0.63658011	3629.3745
713.09546	2.0773606	0.63760972	3624.0652
713.99634	2.0836768	0.63883078	3630.3052
714.89722	2.0851843	0.6401965	3630.4771
715.7981	2.0891018	0.64156109	3627.3457
716.69897	2.089628	0.64266795	3623.9475
717.59985	2.0905685	0.64357626	3618.2502
718.50073	2.0952444	0.6446768	3626.9341
719.40161	2.0996957	0.64563638	3630.6121
720.30249	2.1002164	0.64680797	3629.6543
721.20337	2.1042066	0.64796269	3633.5996
722.10425	2.105824	0.64946353	3637.4094
723.00513	2.1107347	0.65067917	3633.0103
723.90601	2.1118274	0.65189093	3634.7957
724.80688	2.1125972	0.65339416	3634.8135
725.70776	2.1150908	0.65477979	3631.5388
726.60864	2.1197779	0.65593523	3631.2993
727.50952	2.1236174	0.65721744	3634.3364
728.4104	2.1245341	0.6583904	3631.2771
729.31128	2.126621	0.65967143	3635.2803
730.21216	2.1305835	0.66100746	3634.7024
731.11304	2.1352346	0.66244924	3638.4138
732.01392	2.1373379	0.66390967	3635.9888
732.91479	2.1380942	0.66530496	3632.9893
733.81567	2.140089	0.66648382	3628.3574
734.71655	2.1447327	0.66773373	3631.5771
735.61743	2.1469162	0.66898799	3636.0659
736.51831	2.1470702	0.67044902	3636.5186
737.41919	2.1530051	0.67180479	3638.8198
738.32007	2.1544962	0.67326146	3641.1885
739.22095	2.1583343	0.67470455	3636.093
740.12183	2.159827	0.67584044	3632.3784
741.02271	2.1611018	0.6771028	3633.7537
741.92358	2.1651793	0.67865711	3642.6482
742.82446	2.1667471	0.68006837	3638.103
743.72534	2.1719797	0.68138099	3640.2612
744.62622	2.1724572	0.68271112	3639.5149
745.5271	2.1757348	0.68406707	3638.3232
746.42798	2.179934	0.68537146	3636.8987
747.32886	2.1816294	0.68668932	3638.7334
748.22974	2.1872482	0.68812823	3642.9897
749.13062	2.1880891	0.68969595	3642.8289
750.03149	2.1895034	0.69101214	3637.521
750.93237	2.1942234	0.69238758	3638.137
751.83325	2.1966505	0.69370097	3639.5801
752.73413	2.199055	0.69502854	3639.6829
753.63501	2.1986737	0.69631517	3638.3606
754.53589	2.2031903	0.69756848	3633.3057
755.43677	2.2060616	0.69892853	3642.5303
756.33765	2.2086034	0.70026249	3644.4485
757.23853	2.2113707	0.70155478	3642.0015
758.1394	2.2138009	0.70292002	3639.7043
759.04028	2.2189813	0.7041297	3638.4487
759.94116	2.2195857	0.70535898	3642.4075
760.84204	2.222172	0.70665437	3642.7859
761.74292	2.2252941	0.70820367	3643.4834
762.6438	2.2299538	0.70976353	3649.1882
763.54468	2.2300589	0.71128976	3642.3865
764.44556	2.2330739	0.71264029	3641.4155
765.34644	2.2370005	0.71384889	3641.502
766.24731	2.2405784	0.7152217	3648.9165
767.14819	2.2413194	0.71671426	3643.0315
768.04907	2.2437985	0.71820104	3645.9207
768.94995	2.2449563	0.71974212	3649.844
769.85083	2.2463844	0.72124916	3645.1838
770.75171	2.2530131	0.72279328	3642.6453
771.65259	2.2550681	0.72410041	3638.9849
772.55347	2.2605681	0.7255187	3646.9067
773.45435	2.26191	0.72694272	3649.002
774.35522	2.2631383	0.72842628	3645.1345
775.2561	2.2654774	0.73004836	3651.874
776.15698	2.2659984	0.73131543	3640.606
777.05786	2.2722034	0.73273379	3648.9268
777.95874	2.2729988	0.73426133	3647.0002
778.85962	2.2759802	0.7358427	3640.1836
779.7605	2.28039	0.73741406	3651.3647
780.66138	2.2822771	0.73883629	3647.2219
781.56226	2.2856956	0.74029565	3648.9377
782.46313	2.2873392	0.74184614	3644.5991
783.36401	2.2917316	0.74320871	3646.5508
784.26489	2.2916265	0.74465108	3647.3962
785.16577	2.2973504	0.74610245	3644.8308
786.06665	2.3016655	0.74747944	3654.9592
786.96753	2.3011191	0.74889559	3647.4792
787.86841	2.304647	0.75018829	3651.019
788.76929	2.30724	0.75168318	3650.5535
789.67017	2.3098748	0.75309986	3651.3989
790.57104	2.3112488	0.75441206	3643.1243
791.47192	2.3126926	0.75577992	3649.1179
792.3728	2.3178685	0.75718784	3647.2007
793.27368	2.3184772	0.75836617	3644.0757
794.17456	2.3223562	0.75984031	3647.6318
795.07544	2.324049	0.7613126	3649.0974
795.97632	2.325592	0.76302975	3652.8748
796.8772	2.3289926	0.76472294	3648.6133
797.77808	2.3346889	0.76624697	3647.199
798.67896	2.3362417	0.76788104	3650.2283
799.57983	2.3382852	0.76930344	3646.2388
800.48071	2.3428826	0.7708146	3651.0449
801.38159	2.3430631	0.77245998	3650.5776
802.28247	2.3476112	0.77398729	3647.1184
803.18335	2.3509502	0.77534252	3647.1157
804.08423	2.3505526	0.77692682	3649.7366
804.98511	2.3552492	0.77851987	3650.2737
805.88599	2.3597491	0.77993751	3651.343
806.78687	2.3616934	0.78168893	3651.4075
807.68774	2.360218	0.78334779	3650.241
808.58862	2.3662279	0.78507394	3652.2964
809.4895	2.3662932	0.7865026	3644.9727
810.39038	2.3702042	0.7879476	3648.0674
811.29126	2.3765321	0.78988701	3657.9397
812.19214	2.3788469	0.79162395	3655.8711
813.09302	2.3781741	0.79335088	3648.6663
813.9939	2.3827062	0.79505259	3652.1057
814.89478	2.3836455	0.79660714	3649.9392
815.79565	2.3865438	0.7978884	3646.1965
816.69653	2.3902836	0.79958647	3646.1296
817.59741	2.3919857	0.8011809	3649.7515
818.49829	2.3971086	0.80256993	3645.4597
819.39917	2.3982253	0.80437958	3651.6606
820.30005	2.4015446	0.8061263	3652.6045
821.20093	2.4053786	0.80783647	3649.761
822.10181	2.4083114	0.80929947	3646.834
823.00269	2.4090481	0.81070346	3647.4192
823.90356	2.4104812	0.8121469	3648.0889
824.80444	2.4133298	0.81369495	3650.4104
825.70532	2.4199202	0.81540108	3652.2852
826.6062	2.4186392	0.81697452	3651.3748
827.50708	2.425019	0.81881231	3656.9006
828.40796	2.4260547	0.82105613	3656.4673
829.30884	2.4275272	0.82259417	3648.4709
830.20972	2.4324193	0.82438362	3654.5471
831.1106	2.43363	0.82602262	3645.4287
832.01147	2.4335401	0.82755661	3646.835
832.91235	2.4396379	0.82923687	3649.7498
833.81323	2.442641	0.83084804	3646.9756
834.71411	2.4467213	0.83259642	3650.7002
835.61499	2.4429288	0.83409625	3639.6992
836.51587	2.4511108	0.83557266	3646.8423
837.41675	2.4526231	0.83715194	3652.5771
838.31763	2.4547033	0.83922046	3655.9905
839.21851	2.4577389	0.84108585	3646.2146
840.11938	2.4597898	0.8428731	3649.5918
841.02026	2.4616337	0.84456205	3646.3564
841.92114	2.4685135	0.84618312	3650.4133
842.82202	2.4661419	0.8482427	3650.1467
843.7229	2.4718513	0.85050005	3653.623
844.62378	2.4731712	0.85264707	3651.0435
845.52466	2.4772575	0.85432643	3645.8457
846.42554	2.4786727	0.85605341	3646.0669
847.32642	2.4803956	0.85788739	3644.9268
848.22729	2.4860344	0.8599087	3651.4583
849.12817	2.4870532	0.86162525	3643.8245
850.02905	2.4877536	0.86319721	3641.1282
850.92993	2.492063	0.86486691	3648.9304
851.83081	2.4977276	0.86682898	3652.9897
852.73169	2.4967384	0.86878747	3647.4675
853.63257	2.5018175	0.87075597	3646.1584
854.53345	2.5032766	0.87294126	3648.9104
855.43433	2.5044949	0.87486112	3644.7747
856.33521	2.5083783	0.87646574	3639.0081
857.23608	2.515419	0.87822932	3650.4895
858.13696	2.5161421	0.88006341	3649.2622
859.03784	2.5179875	0.88202524	3649.5762
859.93872	2.5190322	0.8840152	3645.0933
860.8396	2.5226691	0.88566309	3642.168
861.74048	2.5244577	0.88734341	3639.6567
862.64136	2.5274615	0.8887198	3640.1736
863.54224	2.5311792	0.89011437	3639.5095
864.44312	2.5348816	0.89181709	3647.9783
865.34399	2.5395319	0.89380044	3647.4778
866.24487	2.5383825	0.8959465	3649.4373
867.14575	2.5423026	0.89814341	3645.916
868.04663	2.5425305	0.90034515	3646.085
868.94751	2.5482361	0.90246934	3642.4619
869.84839	2.5513301	0.90455788	3648.9348
870.74927	2.5536141	0.90649211	3636.9324
871.65015	2.5575325	0.90812182	3640.2515
872.55103	2.5603478	0.9098146	3643.5325
873.4519	2.5631361	0.9116686	3639.6504
874.35278	2.5598247	0.91372991	3640.332
875.25366	2.5695899	0.91614413	3644.325
876.15454	2.5664086	0.91811317	3638.8926
877.05542	2.5718296	0.91997761	3640.3799
877.9563	2.5750997	0.92188746	3639.2146
878.85718	2.5757079	0.92406064	3644.4028
879.75806	2.579958	0.92634422	3641.9333
880.65894	2.5834513	0.92871803	3645.5247
881.55981	2.5845308	0.93127644	3644.4363
882.46069	2.5873647	0.93373376	3636.0491
883.36157	2.5904293	0.93605852	3636.9583
884.26245	2.5913062	0.93792695	3635.4275
885.16333	2.5917923	0.93994117	3631.4604
886.06421	2.5990052	0.94166952	3630.7996
886.96509	2.600579	0.94336832	3636.9712
887.86597	2.6040385	0.94508702	3632.7056
888.76685	2.6059489	0.94707054	3639.5767
889.66772	2.6083791	0.94923151	3636.6392
890.5686	2.6120112	0.95139891	3634.7307
891.46948	2.6152079	0.95381594	3637.8721
892.37036	2.6178646	0.95594472	3635.7666
893.27124	2.6220212	0.95830935	3635.9883
894.17212	2.6234219	0.96085602	3635.7148
895.073	2.6251984	0.96309316	3627.5764
895.97388	2.6290605	0.96496326	3628.6597
896.87476	2.6298733	0.966865	3625.4646
897.77563	2.6326313	0.96899164	3630.968
898.67651	2.6356101	0.97090453	3627.0178
899.57739	2.6381795	0.97286785	3626.3914
900.47827	2.6402566	0.97497356	3632.1831
901.37915	2.6430311	0.97743094	3631.4841
902.28003	2.647774	0.98028499	3631.2869
903.18091	2.6468654	0.98255229	3627.021
904.08179	2.6510522	0.98458862	3621.5928
904.98267	2.6569643	0.98687625	3632.0215
905.88354	2.6560786	0.98950446	3627.9216
906.78442	2.6606388	0.99190778	3624.0359
907.6853	2.6610408	0.99417317	3628.0916
908.58618	2.6658201	0.99708718	3632.4431
909.48706	2.6703794	0.99937016	3621.738
910.38794	2.6702573	1.0015659	3620.9136
911.28882	2.674515	1.0038741	3628.3997
912.1897	2.6752448	1.0061162	3619.3428
913.09058	2.6800804	1.0087237	3624.5059
913.99146	2.6832569	1.0112584	3616.7847
914.89233	2.6845257	1.0137695	3621.0552
915.79321	2.6856933	1.017159	3623.7227
916.69409	2.6892555	1.0193039	3612.3337
917.59497	2.6921134	1.0214922	3617.4001
918.49585	2.6959629	1.0238242	3618.7141
919.39673	2.6991341	1.026535	3612.5544
920.29761	2.6999416	1.0291834	3616.4624
921.19849	2.6997905	1.0320926	3614.9524
922.09937	2.7046885	1.0347111	3611.584
923.00024	2.7064366	1.0371308	3611.095
923.90112	2.7115495	1.0396769	3612.7878
924.802	2.7118225	1.0421654	3611.0288
925.70288	2.718076	1.0446018	3606.9792
926.60376	2.7209082	1.0470036	3606.7371
927.50464	2.7229142	1.0495754	3609.9412
928.40552	2.7236285	1.0522214	3599.0532
929.3064	2.7267108	1.0544788	3600.1548
930.20728	2.7306898	1.0566466	3601.6423
931.10815	2.7338326	1.0593424	3610.7725
932.00903	2.73791	1.0620415	3605.5339
932.90991	2.7367871	1.0646366	3596.6812
933.81079	2.7412529	1.0670496	3602.3491
934.71167	2.745625	1.0697324	3603.9766
935.61255	2.7450294	1.0724324	3602.5042
936.51343	2.7500637	1.0751791	3596.7498
937.41431	2.7540708	1.0779488	3596.7827
938.31519	2.7526624	1.08048	3596.5903
939.21606	2.7594647	1.0827827	3596.3518
940.11694	2.7587228	1.0852121	3598.5759
941.01782	2.7626979	1.0879313	3594.0894
941.9187	2.7675154	1.0908833	3592.5828
942.81958	2.7707214	1.0938087	3588.1875
943.72046	2.7688241	1.0962385	3584.0332
944.62134	2.7745185	1.0987436	3584.7158
945.52222	2.7772048	1.1007855	3585.5728
946.4231	2.7784958	1.1036415	3587.2898
947.32397	2.7821667	1.106611	3587.7808
948.22485	2.7853882	1.1092817	3585.4033
949.12573	2.7872019	1.1120535	3580.7961
950.02661	2.7908607	1.1151705	3584.5234
950.92749	2.7907798	1.1180477	3578.7246
951.82837	2.7977183	1.1208222	3574.2415
952.72925	2.7997437	1.12333	3575.1958
953.63013	2.8015552	1.1264724	3575.252
954.53101	2.8044517	1.1297253	3576.7231
955.43188	2.8047235	1.1323901	3569.394
956.33276	2.8088562	1.1352924	3570.8621
957.23364	2.8119063	1.1380159	3562.4048
958.13452	2.8131759	1.1405259	3568.9133
959.0354	2.815676	1.1430213	3561.2183
959.93628	2.8201272	1.1457844	3564.7532
960.83716	2.8237786	1.1483978	3562.3872
961.73804	2.8243213	1.1507174	3558.1614
962.63892	2.8287735	1.1530976	3556.8484
963.53979	2.8299384	1.1557506	3559.8372
964.44067	2.8331909	1.1587151	3559.3533
965.34155	2.8348796	1.1617951	3555.7979
966.24243	2.8394618	1.1645138	3547.7773
967.14331	2.8402388	1.167199	3548.6694
968.04419	2.8430228	1.1697978	3546.5527
968.94507	2.8471546	1.1725327	3549.0332
969.84595	2.8497727	1.1752625	3546.1636
970.74683	2.8527155	1.1780571	3549.2822
971.64771	2.8553312	1.1810807	3543.4082
972.54858	2.8605866	1.1841261	3544.2358
973.44946	2.8585079	1.187258	3539.4893
974.35034	2.8654447	1.1900365	3536.5276
975.25122	2.8658524	1.1927418	3536.7832
976.1521	2.8704095	1.1951015	3533.5701
977.05298	2.8704822	1.1978989	3534.2996
977.95386	2.8738973	1.2006552	3529.2441
978.85474	2.8777404	1.203354	3531.0266
979.75562	2.8825216	1.2064031	3527.4509
980.65649	2.8845196	1.2093021	3530.1548
981.55737	2.8850167	1.2119381	3523.3132
982.45825	2.888762	1.2145429	3520.2083
983.35913	2.8906901	1.2171625	3520.3186
984.26001	2.8924227	1.2200035	3517.8286
985.16089	2.8977299	1.2227882	3515.8464
986.06177	2.9006448	1.2257546	3517.5781
986.96265	2.900166	1.2288834	3511.6809
987.86353	2.9042509	1.2319194	3504.9412
988.7644	2.9050708	1.235027	3505.562
989.66528	2.9089587	1.2380738	3503.3389
990.56616	2.9140882	1.2406533	3497.0051
991.46704	2.9133611	1.2434274	3497.3716
992.36792	2.9208605	1.2464128	3501.4792
993.2688	2.9206443	1.2497878	3500.5188
994.16968	2.9221287	1.2530301	3492.4753
995.07056	2.927001	1.2558777	3495.6072
995.97144	2.9306138	1.2595757	3491.8914
996.87231	2.93115	1.2624414	3482.6804
997.77319	2.9327135	1.2649826	3475.2432
998.67407	2.9354908	1.2671026	3477.9409
999.57495	2.9384625	1.2702447	3484.3174
1000.4758	2.9417057	1.2734114	3472.8564
1001.3767	2.9467666	1.2762562	3466.0972
1002.2776	2.9469278	1.2786505	3469.1003
1003.1785	2.9487121	1.2818813	3471.1506
1004.0793	2.9525664	1.2851762	3468.885
1004.9802	2.9569273	1.2878424	3455.2634
1005.8811	2.9606912	1.2902683	3461.3779
1006.782	2.9589574	1.2932713	3454.655
1007.6829	2.9637904	1.2962716	3455.7493
1008.5837	2.9641237	1.2991599	3447.4919
1009.4846	2.9687932	1.3017902	3451.8181
1010.3855	2.9720578	1.3044739	3449.114
1011.2864	2.9742153	1.3073645	3446.2654
1012.1873	2.9766057	1.3101587	3438.45
1013.0881	2.9811845	1.3129928	3441.5181
1013.989	2.9833186	1.3156635	3433.1055
1014.8899	2.982527	1.3185245	3428.4316
1015.7908	2.9875388	1.3214035	3427.6069
1016.6917	2.9933169	1.3236641	3418.3721
1017.5925	2.993962	1.3258356	3423.9111
1018.4934	2.9964101	1.3278204	3414.2566
1019.3943	2.9991314	1.3304489	3422.4817
1020.2952	3.0006926	1.3331378	3417.6611
1021.196	3.0038939	1.3363305	3413.5535
1022.0969	3.0078423	1.3392683	3410.8606
1022.9978	3.008517	1.3421041	3406.5264
1023.8987	3.0111194	1.3452766	3405.9133
1024.7996	3.0171244	1.3491216	3400.8569
1025.7004	3.0169165	1.3521079	3388.5422
1026.6013	3.0196383	1.3550948	3394.8811
1027.5022	3.0252569	1.3585929	3390.7815
1028.4031	3.0260174	1.3614401	3380.6792
1029.304	3.0317843	1.3645186	3386.7317
1030.2048	3.0311875	1.3673455	3378.7783
1031.1057	3.0328929	1.3705239	3378.9497
1032.0066	3.0392714	1.3733608	3375.5518
1032.9075	3.0381792	1.3762559	3371.0034
1033.8083	3.0440793	1.3793763	3366.5952
1034.7092	3.0471342	1.3823133	3368.7793
1035.6101	3.0472567	1.3854188	3359.6504
1036.511	3.049525	1.3881432	3355.2473
1037.4119	3.0563216	1.3912945	3352.7798
1038.3127	3.0545382	1.3939942	3345.2673
1039.2136	3.0589092	1.3968099	3348.3674
1040.1145	3.0604849	1.4002454	3344.3831
1041.0154	3.0639622	1.4034555	3331.4844
1041.9163	3.0671616	1.4061619	3326.6565
1042.8171	3.0709271	1.4088798	3326.6228
1043.718	3.0724225	1.4117591	3328.6504
1044.6189	3.0732388	1.4153037	3322.3728
1045.5198	3.0792501	1.4191303	3317.2117
1046.4207	3.0793805	1.4221689	3306.5854
1047.3215	3.0823946	1.4250364	3310.7007
1048.2224	3.0832021	1.4279296	3296.5115
1049.1233	3.0872579	1.4311992	3298.8733
1050.0242	3.0898235	1.4341475	3298.0691
1050.925	3.0928571	1.4373363	3287.4368
1051.8259	3.0973492	1.4402257	3286.6714
1052.7268	3.0987506	1.4428687	3281.293
1053.6277	3.1000032	1.4457252	3281.4355
1054.5286	3.1012833	1.448895	3274.3811
1055.4294	3.1064153	1.4520289	3272.1162
1056.3303	3.1094828	1.4549605	3271.4773
1057.2312	3.1132445	1.4581447	3269.0979
1058.1321	3.1125178	1.4615222	3258.1997
1059.033	3.117676	1.4647636	3255.6692
1059.9338	3.1194303	1.468466	3250.9998
1060.8347	3.1236773	1.4719517	3242.1223
1061.7356	3.1277442	1.4745363	3231.52
1062.6365	3.1278949	1.4769144	3234.3899
1063.5374	3.1311564	1.4798685	3234.5833
1064.4382	3.1355534	1.4833053	3226.2166
1065.3391	3.1349742	1.4866178	3221.3616
1066.24	3.1418471	1.4897206	3218.5886
1067.1409	3.1431026	1.4929609	3209.6069
1068.0417	3.1430774	1.4960477	3203.5474
1068.9426	3.1483028	1.4992514	3204.0928
1069.8435	3.1470194	1.5020787	3192.439
1070.7444	3.1536176	1.5046456	3191.2715
1071.6453	3.1557932	1.5071511	3184.7551
1072.5461	3.1577508	1.510445	3180.9858
1073.447	3.1613977	1.5135777	3178.0581
1074.3479	3.161278	1.5170631	3168.4312
1075.2488	3.16711	1.5203522	3166.0796
1076.1497	3.1690812	1.5234948	3161.1597
1077.0505	3.1719394	1.5264974	3153.4585
1077.9514	3.173656	1.529609	3148.8928
1078.8523	3.1779697	1.5323492	3141.0942
1079.7532	3.1821978	1.5353101	3141.2529
1080.6541	3.1847563	1.538588	3142.7898
1081.5549	3.1887763	1.5424172	3133.5059
1082.4558	3.1881318	1.5457969	3119.1277
1083.3567	3.1915591	1.5490218	3115.0056
1084.2576	3.1922476	1.5522097	3103.4695
1085.1584	3.1962049	1.5554761	3104.6082
1086.0593	3.2003551	1.5587963	3098.0178
1086.9602	3.201823	1.5616114	3088.7231
1087.8611	3.2061222	1.5650259	3085.738
1088.762	3.209846	1.5681847	3079.9685
1089.6628	3.2104809	1.5710752	3072.7192
1090.5637	3.2095046	1.5742686	3067.4602
1091.4646	3.2151699	1.5776743	3063.4099
1092.3655	3.2179646	1.5808809	3054.0149
1093.2664	3.2194016	1.5844171	3048.2825
1094.1672	3.2223074	1.5874083	3038.741
1095.0681	3.226135	1.5903071	3031.4004
1095.969	3.2280221	1.593191	3026.3774
1096.8699	3.2315021	1.596235	3027.7627
1097.7708	3.2338767	1.5996599	3020.7874
1098.6716	3.2357333	1.6030266	3005.4014
1099.5725	3.2393961	1.6063048	3007.7668
1100.4734	3.2449961	1.6098706	2998.9578
1101.3743	3.24578	1.6135558	2987.8713
1102.2751	3.2466195	1.6174278	2978.1689
1103.176	3.2502153	1.6207039	2964.25
1104.0769	3.2506216	1.6240929	2957.4448
1104.9778	3.2557378	1.6274904	2943.7522
1105.8787	3.2561207	1.6301883	2938.49
1106.7795	3.2612562	1.6333065	2934.2183
1107.6804	3.2658727	1.6369791	2931.9666
1108.5813	3.2676966	1.6406375	2922.3374
1109.4822	3.2679741	1.6448327	2908.6733
1110.3831	3.2728612	1.6489248	2895.6738
1111.2839	3.276876	1.6524633	2888.3162
1112.1848	3.2792618	1.6555867	2874.5422
1113.0857	3.2797933	1.6589993	2866.2734
1113.9866	3.282254	1.6621929	2854.8855
1114.8875	3.2862601	1.6653156	2847.9656
1115.7883	3.2881148	1.6697186	2831.2839
1116.6892	3.2939885	1.6752458	2813.334
1117.1897	3.2940226	1.6805652	2773.5884