File: datasets/am_bench_2022/raw_data/0-X.20-1/specimen.dat
MTS793|MPT|ENU|1|2|.|/|:|1|0|0|A

Operator Information						Time:	20.286377	Sec	10/13/2021 9:28:43 AM
Operator	Jake Benzing
Project	AM Bench 2022 mini-tensile challenge
Specimen ID	O-X.20-1
Material	PBF-L Inconel 625
Specimen Width	2.55	mm
Specimen Thickness	1.54	mm
Notes
Operator Information End

Data Acquisition						Time:	1021.2861	Sec	10/13/2021 9:45:24 AM
Time	Axial Displacement	Axial Extensometer	Axial Force
Sec	mm	mm	N
20.406006	-0.00091468927	2.3412005e-05	75.907036
21.406982	0.0069101993	2.4379089e-05	92.919815
22.407959	0.009916923	0.00013556829	108.58266
23.408936	0.010903883	0.00010379073	118.25475
24.409912	0.013957117	0.000254235	128.91368
25.410889	0.017301142	0.00027212198	143.93799
26.411865	0.020315241	0.00035540605	160.73199
27.412842	0.021395016	0.00052321691	178.02812
28.413818	0.026770433	0.00060801307	191.95331
29.414795	0.029761022	0.00078080787	218.17514
30.415771	0.032048427	0.00079207175	236.54335
31.416748	0.032803655	0.00093893247	261.02954
32.417725	0.039586261	0.0010048654	284.13968
33.418701	0.040432818	0.0010896646	304.28143
34.419678	0.040600829	0.001274548	317.92072
35.420654	0.046600241	0.0012988071	344.75369
36.421631	0.050523803	0.001374128	371.97656
37.422607	0.054701068	0.0014192245	394.17487
38.423584	0.053517669	0.0016424953	414.34323
39.424561	0.060341049	0.0017413665	437.5043
40.425537	0.058795813	0.0017706699	458.35526
41.426514	0.062290996	0.0020249037	485.14243
42.42749	0.067390017	0.0019979894	505.36365
43.428467	0.071009621	0.0020503185	536.64783
44.429443	0.074161611	0.0022035872	555.66772
45.43042	0.078041375	0.0023093016	576.55896
46.431396	0.07878042	0.0024684221	602.54004
47.432373	0.081242949	0.0025424932	623.77496
48.43335	0.084092982	0.0026915574	657.15344
49.434326	0.088723466	0.002747755	670.89636
50.435303	0.088332742	0.0027974779	694.5907
51.436279	0.092432357	0.0029216234	720.62122
52.437256	0.096284866	0.0030847555	744.17041
53.438232	0.10054553	0.0032570546	775.7403
54.439209	0.10303023	0.0034013705	805.88403
55.440186	0.10458305	0.0034905698	829.64832
56.441162	0.10608695	0.0037039493	851.05829
57.442139	0.11275672	0.0037356992	884.49658
58.443115	0.11518483	0.0039097359	911.80988
59.444092	0.11953297	0.0041040196	940.03265
60.445068	0.12121057	0.0041671209	973.15149
61.446045	0.12224322	0.004314804	1008.3651
62.447021	0.12444662	0.0045247865	1032.6007
63.447998	0.12946005	0.0045527164	1060.9741
64.448975	0.13358875	0.0047923382	1094.7137
65.449951	0.13332649	0.0049248077	1127.4391
66.450928	0.13638157	0.0050214897	1150.0289
67.451904	0.14258602	0.0052059479	1185.7786
68.452881	0.1434187	0.0053055389	1205.9656
69.453857	0.1456534	0.0054335049	1236.4709
70.454834	0.15210229	0.0055646081	1258.2555
71.455811	0.15323432	0.0057843314	1297.1146
72.456787	0.15513258	0.0058658361	1324.8451
73.457764	0.15781455	0.0061498447	1353.8687
74.45874	0.16163468	0.0061072926	1375.1929
75.459717	0.16785288	0.0062556081	1407.5939
76.460693	0.17101762	0.0065505127	1436.0089
77.46167	0.17197789	0.0065919901	1467.4084
78.462646	0.17425567	0.0068003088	1499.6771
79.463623	0.17644712	0.0068862266	1530.2434
80.4646	0.17850238	0.0070083686	1540.7485
81.465576	0.18189287	0.0072237807	1572.6514
82.466553	0.18568924	0.0073016463	1603.9355
83.467529	0.18906191	0.0075886464	1624.9132
84.468506	0.1925889	0.0076541817	1650.4376
85.469482	0.19758777	0.0078125279	1685.3617
86.470459	0.19478999	0.0078484612	1707.7446
87.471436	0.20068444	0.008086849	1732.9731
88.472412	0.2028714	0.0083754426	1761.7791
89.473389	0.2045933	0.0084094135	1789.9095
90.474365	0.21171911	0.0087262411	1823.0289
91.475342	0.21359161	0.0087983487	1842.9438
92.476318	0.21462712	0.0089629162	1867.2292
93.477295	0.21934448	0.0090905614	1896.5013
94.478271	0.22157857	0.0094329221	1925.7197
95.479248	0.22302878	0.0095909322	1945.0533
96.480225	0.22909181	0.0097552575	1974.1128
97.481201	0.23028898	0.010030652	1991.5638
98.482178	0.23205842	0.010164313	2015.2178
99.483154	0.23653053	0.010414839	2037.8893
100.48413	0.23946431	0.010564432	2063.3108
101.48511	0.2453471	0.01084279	2083.4084
102.48608	0.24659549	0.011109207	2104.4668
103.48706	0.24957763	0.011284173	2124.2598
104.48804	0.2537469	0.011594419	2150.5427
105.48901	0.25406018	0.011871306	2169.0825
106.48999	0.25678599	0.012147746	2182.4954
107.49097	0.26118234	0.012478702	2205.3298
108.49194	0.26545689	0.01278247	2220.8308
109.49292	0.26715338	0.013081669	2239.8665
110.4939	0.27174145	0.01320638	2259.5691
111.49487	0.27100939	0.013820354	2274.0598
112.49585	0.27678519	0.014155117	2297.4924
113.49683	0.27790144	0.014555805	2311.8896
114.4978	0.28269026	0.014921512	2332.0659
115.49878	0.285151	0.015452005	2343.6211
116.49976	0.29145831	0.01588132	2363.0454
117.50073	0.29173431	0.016209224	2367.5525
118.50171	0.29631105	0.016873449	2392.9963
119.50269	0.29567999	0.017256467	2397.9373
120.50366	0.29982761	0.017716246	2404.386
121.50464	0.30520287	0.018239276	2423.0249
122.50562	0.30915532	0.018740775	2427.1406
123.50659	0.31025374	0.019400934	2448.3806
124.50757	0.31270832	0.020118261	2467.2686
125.50854	0.31704745	0.020957144	2468.7295
126.50952	0.31942126	0.021524034	2479.271
127.5105	0.3220492	0.022250956	2487.1548
128.51147	0.32320434	0.022907341	2497.0913
129.51245	0.32770866	0.023896804	2504.8604
130.51343	0.33150032	0.024706472	2509.394
131.5144	0.3349666	0.025549047	2515.8359
132.51538	0.33764222	0.026463067	2528.4766
133.51636	0.34366146	0.027258137	2530.0559
134.51733	0.34352788	0.028215833	2536.9272
135.51831	0.34870869	0.029455388	2550.5479
136.51929	0.34894064	0.030399486	2559.1389
137.52026	0.35449803	0.031535495	2560.4924
138.52124	0.35859212	0.032542642	2565.2236
139.52222	0.35851529	0.033778802	2572.9221
140.52319	0.36144742	0.034970377	2571.9998
141.52417	0.36205882	0.036283549	2581.9028
142.52515	0.36783138	0.037340589	2590.074
143.52612	0.36884969	0.038673289	2584.4536
144.5271	0.37466788	0.039739508	2590.5933
145.52808	0.37985545	0.040914059	2594.666
146.52905	0.38121879	0.04245377	2606.075
147.53003	0.38326213	0.043589909	2603.1143
148.53101	0.38507459	0.044827417	2610.5361
149.53198	0.38929462	0.04622785	2611.0081
150.53296	0.39250097	0.04729047	2611.5449
151.53394	0.39275584	0.048316378	2605.6558
152.53491	0.39783606	0.049460869	2615.3135
153.53589	0.39916274	0.05072818	2615.9546
154.53687	0.40427652	0.051938325	2621.9202
155.53784	0.40847105	0.053334456	2635.1895
156.53882	0.40725952	0.054940499	2630.7622
157.53979	0.41344035	0.056362644	2631.561
158.54077	0.41533336	0.057799332	2630.1489
159.54175	0.42100918	0.059141576	2636.428
160.54272	0.42146078	0.060634624	2641.7458
161.5437	0.4266063	0.062001433	2643.4346
162.54468	0.42690584	0.063367784	2645.8276
163.54565	0.43174654	0.065052703	2647.4888
164.54663	0.43359876	0.066479132	2642.665
165.54761	0.43709332	0.067944072	2646.9165
166.54858	0.44065899	0.069534138	2661.0476
167.54956	0.44235161	0.071508273	2650.2322
168.55054	0.44761172	0.073291391	2663.7141
169.55151	0.44699499	0.074991547	2657.1128
170.55249	0.44995397	0.076734148	2656.9805
171.55347	0.45650935	0.078079358	2658.9302
172.55444	0.4585554	0.079297483	2658.0906
173.55542	0.4595606	0.080997288	2666.4656
174.5564	0.4629499	0.082623444	2661.4468
175.55737	0.46927765	0.084159963	2670.2927
176.55835	0.46909305	0.085543446	2666.4167
177.55933	0.47279865	0.087249488	2676.8525
178.5603	0.47756007	0.089141563	2680.4756
179.56128	0.48176807	0.09076111	2673.667
180.56226	0.4817445	0.092211023	2674.6226
181.56323	0.48308858	0.093709566	2672.3794
182.56421	0.48825917	0.095088832	2671.8298
183.56519	0.49223831	0.096548781	2678.4263
184.56616	0.4961068	0.098394111	2683.0088
185.56714	0.49671772	0.10001726	2679.5342
186.56812	0.49938214	0.10162158	2681.9414
187.56909	0.50308454	0.10326129	2684.0901
188.57007	0.50588673	0.10479154	2683.2222
189.57104	0.51070547	0.10654405	2690.8909
190.57202	0.51495677	0.10833031	2697.637
191.573	0.51676756	0.10985573	2693.0491
192.57397	0.5185169	0.11128441	2685.3176
193.57495	0.52446496	0.11303564	2691.5378
194.57593	0.52212191	0.11460001	2690.4939
195.5769	0.52779752	0.11641154	2695.6938
196.57788	0.53109396	0.11772418	2687.217
197.57886	0.53381282	0.11934299	2702.4858
198.57983	0.53464407	0.12127648	2701.3669
199.58081	0.53959644	0.12297036	2700.3264
200.58179	0.53958148	0.1244313	2696.7278
201.58276	0.54339939	0.12628196	2707.7087
202.58374	0.54842877	0.12803471	2699.7339
203.58472	0.55391061	0.12973124	2707.7429
204.58569	0.55444169	0.13152368	2703.6313
205.58667	0.55992365	0.13371454	2717.0061
206.58765	0.56058621	0.13550717	2708.4409
207.58862	0.56573325	0.1373799	2714.4089
208.5896	0.56614614	0.13895352	2706.9983
209.59058	0.57258642	0.14079404	2710.2153
210.59155	0.57205594	0.14200763	2707.5933
211.59253	0.57425743	0.14378402	2716.6001
212.59351	0.57754016	0.1456899	2713.7947
213.59448	0.58000684	0.14752202	2715.9517
214.59546	0.58597219	0.14926672	2714.0776
215.59644	0.58884549	0.15099484	2714.7607
216.59741	0.59241772	0.15292394	2725.4238
217.59839	0.59532863	0.15456243	2719.3306
218.59937	0.59845501	0.15643318	2725.7979
219.60034	0.5999136	0.1582932	2722.9958
220.60132	0.60428303	0.16030136	2726.1614
221.60229	0.60598528	0.16157991	2717.5503
222.60327	0.607122	0.1629663	2722.9331
223.60425	0.61320293	0.16461736	2729.3154
224.60522	0.61434633	0.16610804	2720.0864
225.6062	0.61780852	0.16776527	2730.384
226.60718	0.6193471	0.16951655	2726.4346
227.60815	0.62393171	0.17109117	2725.4351
228.60913	0.62576789	0.17276339	2733.0811
229.61011	0.63064998	0.17451046	2732.0317
230.61108	0.63278079	0.17648992	2732.0742
231.61206	0.63861442	0.17821242	2734.3845
232.61304	0.6371454	0.1802603	2735.7576
233.61401	0.64247042	0.182005	2731.4739
234.61499	0.6461457	0.18346956	2736.835
235.61597	0.64721727	0.18512113	2737.0195
236.61694	0.65018308	0.18694162	2742.0352
237.61792	0.6552946	0.18892965	2742.9658
238.6189	0.65577072	0.19049519	2730.8752
239.61987	0.66000295	0.19181262	2735.4207
240.62085	0.66301829	0.19367068	2745.2129
241.62183	0.66732156	0.19570929	2746.6807
242.6228	0.66749227	0.19728507	2746.7874
243.62378	0.67274678	0.19919609	2743.6123
244.62476	0.67214483	0.20098767	2747.4521
245.62573	0.67639589	0.20314789	2749.7285
246.62671	0.68261379	0.20478953	2744.8179
247.62769	0.68496102	0.20641725	2742.2056
248.62866	0.68569368	0.20782249	2747.7681
249.62964	0.6886304	0.20964637	2753.5046
250.63062	0.6921227	0.21179616	2754.8372
251.63159	0.69569904	0.21385929	2758.1091
252.63257	0.70036191	0.21569127	2756.8784
253.63354	0.70471889	0.21727592	2754.5906
254.63452	0.7034719	0.21897849	2759.47
255.6355	0.70697594	0.22078362	2754.8994
256.63647	0.7088533	0.22230051	2753.3562
257.63745	0.71723449	0.22416601	2765.1211
258.63843	0.7180928	0.22605793	2755.8523
259.6394	0.72277731	0.22767755	2761.2876
260.64038	0.72199076	0.22914758	2755.6292
261.64136	0.728297	0.23117998	2765.8569
262.64233	0.72873527	0.23265602	2759.863
263.64331	0.73401427	0.23437238	2768.2468
264.64429	0.73670828	0.23628876	2769.8533
265.64526	0.73981851	0.23807961	2767.0371
266.64624	0.73906839	0.23977064	2763.9155
267.64722	0.74523842	0.24136455	2766.2808
268.64819	0.74622172	0.2431321	2771.2659
269.64917	0.74907517	0.24491437	2770.1599
270.65015	0.75473911	0.24668151	2775.5959
271.65112	0.7546674	0.24862103	2778.0911
272.6521	0.75721669	0.2507669	2778.1812
273.65308	0.76141155	0.25256652	2769.6196
274.65405	0.7649309	0.25429267	2776.9976
275.65503	0.76587933	0.25633788	2783.5994
276.65601	0.77129334	0.25871068	2779.8579
277.65698	0.77196479	0.26064742	2772.8711
278.65796	0.77622801	0.2622641	2779.0391
279.65894	0.77802575	0.26435727	2775.8108
280.65991	0.78534889	0.2659032	2775.9119
281.66089	0.78806531	0.26745859	2782.5151
282.66187	0.78790897	0.26907024	2780.1638
283.66284	0.79132324	0.27079552	2783.9463
284.66382	0.79685009	0.27282944	2789.8887
285.66479	0.79891312	0.2745716	2784.2461
286.66577	0.80048174	0.27682993	2791.667
287.66675	0.80306292	0.27867699	2788.1121
288.66772	0.80636591	0.28019866	2783.3628
289.6687	0.81045473	0.28162923	2784.0024
290.66968	0.81586599	0.28318429	2788.2527
291.67065	0.82046163	0.28497624	2790.3206
292.67163	0.81877625	0.28672504	2788.7813
293.67261	0.82303345	0.28848147	2790.8306
294.67358	0.82179159	0.29009917	2795.6824
295.67456	0.82677472	0.29226425	2797.9226
296.67554	0.83352429	0.29388231	2790.9133
297.67651	0.83294183	0.29530388	2789.6831
298.67749	0.83766782	0.29694176	2793.9927
299.67847	0.83675194	0.29853311	2797.7786
300.67944	0.84248251	0.30025986	2796.0728
301.68042	0.84431231	0.30230582	2804.5913
302.6814	0.85007524	0.30420005	2801.1636
303.68237	0.8512181	0.30619842	2803.1841
304.68335	0.85651875	0.30804941	2800.5933
305.68433	0.85595554	0.30997512	2798.2
306.6853	0.85964721	0.31191859	2804.1492
307.68628	0.86149508	0.31370941	2802.3799
308.68726	0.86847121	0.31566355	2810.2073
309.68823	0.86955994	0.31753251	2802.4727
310.68921	0.87521648	0.31921667	2809.5505
311.69019	0.87651777	0.32107982	2811.0283
312.69116	0.8799777	0.3229048	2806.6262
313.69214	0.88378328	0.32462946	2809.9683
314.69312	0.88631201	0.32673845	2815.0127
315.69409	0.88835454	0.32833368	2802.1226
316.69507	0.89113903	0.33009693	2813.0405
317.69604	0.89033097	0.33208105	2810.8508
318.69702	0.89506119	0.33373147	2809.1929
319.698	0.90117198	0.33558545	2817.093
320.69897	0.90146744	0.337571	2815.8271
321.69995	0.90744382	0.33915228	2817.7439
322.70093	0.90904838	0.34102312	2817.3665
323.7019	0.91469175	0.34286046	2823.2561
324.70288	0.91348702	0.34460476	2817.6318
325.70386	0.91866606	0.34693539	2823.5498
326.70483	0.91769528	0.34886327	2819.4946
327.70581	0.9253208	0.35029829	2820.8152
328.70679	0.92982876	0.3521131	2821.3074
329.70776	0.93001562	0.35398814	2822.2944
330.70874	0.93438321	0.35581738	2828.3511
331.70972	0.9387818	0.35752782	2823.584
332.71069	0.93818307	0.35910159	2820.9473
333.71167	0.94092613	0.36097082	2827.7983
334.71265	0.94376713	0.36269987	2823.4141
335.71362	0.94906271	0.36508524	2831.8926
336.7146	0.94992715	0.36685303	2832.8394
337.71558	0.95362204	0.36864623	2828.8623
338.71655	0.9572773	0.37044308	2833.5254
339.71753	0.96109331	0.37202519	2834.4126
340.71851	0.96513557	0.37385508	2834.3081
341.71948	0.9677456	0.37573314	2832.564
342.72046	0.97057986	0.3774299	2826.3523
343.72144	0.96971667	0.37923303	2838.9949
344.72241	0.97350401	0.3812061	2833.8269
345.72339	0.977175	0.38310716	2829.7468
346.72437	0.97809333	0.38484472	2828.8943
347.72534	0.98354584	0.386453	2832.9758
348.72632	0.98605943	0.38812366	2844.2942
349.72729	0.99127173	0.39031085	2843.8494
350.72827	0.99364722	0.39223519	2844.2908
351.72925	0.99693161	0.394299	2845.8738
352.73022	0.99835908	0.39636651	2836.6013
353.7312	1.002933	0.39808446	2848.0593
354.73218	1.0081481	0.39989379	2843.4534
355.73315	1.0063182	0.4017193	2849.5989
356.73413	1.0118539	0.40352011	2849.2859
357.73511	1.0159453	0.40551916	2846.7339
358.73608	1.0168875	0.40742192	2846.6228
359.73706	1.0210832	0.40954763	2844.3232
360.73804	1.0241936	0.41139758	2853.6614
361.73901	1.0251423	0.41301718	2845.7229
362.73999	1.0302171	0.414561	2850.7214
363.74097	1.0295466	0.41630182	2849.9675
364.74194	1.036829	0.41800389	2852.9211
365.74292	1.0383188	0.4199976	2857.5371
366.7439	1.0402005	0.42158759	2848.8091
367.74487	1.0414304	0.42311978	2847.304
368.74585	1.0471166	0.4247027	2851.8826
369.74683	1.0525991	0.42660668	2862.9778
370.7478	1.053476	0.42886201	2862.3315
371.74878	1.0569851	0.43072668	2865.5188
372.74976	1.0592295	0.43269336	2856.7349
373.75073	1.0616766	0.43438494	2851.4954
374.75171	1.066831	0.43617955	2862.5879
375.75269	1.0683441	0.43817168	2861.4705
376.75366	1.0720865	0.44000331	2859.5198
377.75464	1.0719266	0.44172955	2855.8284
378.75562	1.0769991	0.44319212	2860.2188
379.75659	1.0834802	0.444915	2868.8372
380.75757	1.0828303	0.44687107	2868.5627
381.75854	1.0850532	0.4489404	2865.3994
382.75952	1.0917432	0.45088443	2872.0317
383.7605	1.0893416	0.45259598	2866.4885
384.76147	1.095306	0.45463175	2868.3069
385.76245	1.098183	0.4566603	2869.3774
386.76343	1.1024476	0.4584952	2870.8689
387.7644	1.1025474	0.46045735	2868.5552
388.76538	1.1087697	0.46226677	2870.9702
389.76636	1.1099734	0.46417138	2873.1472
390.76733	1.1150854	0.46576306	2874.7361
391.76831	1.1173332	0.4676432	2869.9966
392.76929	1.121636	0.46921444	2877.4521
393.77026	1.1231	0.47152475	2876.7654
394.77124	1.1242478	0.47344461	2870.5237
395.77222	1.1289481	0.47533369	2880.2014
396.77319	1.1287785	0.47705761	2872.6384
397.77417	1.1353288	0.47877973	2878.4099
398.77515	1.1409843	0.48065412	2878.7209
399.77612	1.1403209	0.48206562	2879.8318
400.7771	1.1442361	0.48406619	2882.7451
401.77808	1.1460773	0.48595271	2886.6934
402.77905	1.1506034	0.48784757	2887.0706
403.78003	1.1524743	0.48975739	2880.0024
404.78101	1.1548321	0.49143007	2879.3696
405.78198	1.1603789	0.49345759	2887.1104
406.78296	1.1598457	0.4950228	2880.2974
407.78394	1.1630918	0.49691573	2879.6501
408.78491	1.1672113	0.49917546	2886.5476
409.78589	1.1717149	0.50130951	2885.0623
410.78687	1.1724298	0.50299662	2878.9956
411.78784	1.1771884	0.50458479	2886.7617
412.78882	1.1822466	0.50632817	2884.0435
413.78979	1.1826359	0.50794089	2888.5244
414.79077	1.1847337	0.51007134	2888.697
415.79175	1.187485	0.51160562	2884.272
416.79272	1.1911917	0.51309144	2886.0339
417.7937	1.1930043	0.51490545	2894.2517
418.79468	1.2003316	0.51647437	2893.8716
419.79565	1.197542	0.51852041	2896.5811
420.79663	1.2016078	0.52051413	2899.9072
421.79761	1.2071029	0.52305454	2901.7261
422.79858	1.2087862	0.52517909	2893.5908
423.79956	1.2147866	0.52688795	2895.5396
424.80054	1.2164481	0.52840519	2892.9958
425.80151	1.2169358	0.53019255	2892.3313
426.80249	1.2225515	0.53226525	2899.2551
427.80347	1.2247362	0.53405654	2904.311
428.80444	1.2262551	0.53589821	2895.717
429.80542	1.2301235	0.5375495	2895.9551
430.8064	1.234983	0.53955203	2901.7327
431.80737	1.2364253	0.54151994	2910.0923
432.80835	1.2409167	0.54349643	2903.3442
433.80933	1.2386533	0.54551774	2900.3594
434.8103	1.2464468	0.54720217	2906.729
435.81128	1.2460614	0.54876477	2899.6921
436.81226	1.2558593	0.55067718	2910.6248
437.81323	1.2538664	0.55232126	2905.168
438.81421	1.258123	0.55376965	2902.136
439.81519	1.26063	0.5552516	2908.8586
440.81616	1.2630408	0.55701828	2909.9004
441.81714	1.2681113	0.55887741	2907.0647
442.81812	1.2669855	0.56046402	2901.7148
443.81909	1.2743618	0.56241071	2912.2021
444.82007	1.2741289	0.56409466	2903.9038
445.82104	1.2778587	0.56571507	2909.5918
446.82202	1.2831352	0.567442	2916.8308
447.823	1.2830029	0.56963098	2920.4617
448.82397	1.2885321	0.5718649	2918.8396
449.82495	1.2893423	0.57373875	2917.2141
450.82593	1.2939687	0.57562625	2916.2095
451.8269	1.2956259	0.57755971	2915.3401
452.82788	1.2988114	0.57966012	2918.634
453.82886	1.3021561	0.58138502	2916.1519
454.82983	1.3053175	0.58305246	2917.7898
455.83081	1.3100814	0.58470351	2921.2354
456.83179	1.3091798	0.5867492	2925.1912
457.83276	1.3150781	0.58877045	2921.8191
458.83374	1.3173465	0.59044504	2923.0842
459.83472	1.3233064	0.59217829	2918.4502
460.83569	1.3253158	0.59382182	2925.9028
461.83667	1.3249999	0.59575784	2921.7136
462.83765	1.3314893	0.59774935	2920.1812
463.83862	1.3356943	0.599823	2929.7324
464.8396	1.3328764	0.60222536	2923.2813
465.84058	1.3360909	0.60406518	2918.689
466.84155	1.3417336	0.60559475	2925.6362
467.84253	1.3449202	0.60768342	2929.6616
468.84351	1.3473942	0.6096276	2923.2981
469.84448	1.3497102	0.61157525	2931.0125
470.84546	1.3523322	0.6135388	2930.771
471.84644	1.3558018	0.61550421	2928.9207
472.84741	1.3603649	0.61710447	2933.0791
473.84839	1.3638701	0.61906391	2934.7549
474.84937	1.3661057	0.62079215	2930.4265
475.85034	1.367503	0.62253237	2928.4307
476.85132	1.3699613	0.62417459	2935.9897
477.85229	1.3748949	0.62600327	2933.8774
478.85327	1.378736	0.62787485	2937.2964
479.85425	1.3794173	0.62991232	2939.0615
480.85522	1.3851324	0.63166595	2939.512
481.8562	1.3863771	0.63334495	2929.8364
482.85718	1.391216	0.63517386	2936.2556
483.85815	1.3913215	0.63679206	2930.8599
484.85913	1.3946879	0.6383754	2933.6223
485.86011	1.4003471	0.64018166	2937.885
486.86108	1.4020447	0.64194083	2946.1924
487.86206	1.4026992	0.64395785	2942.6667
488.86304	1.4056334	0.6457637	2940.2429
489.86401	1.4098946	0.64763093	2937.8496
490.86499	1.4128336	0.64970028	2944.5452
491.86597	1.4163522	0.65186161	2947.7781
492.86694	1.4178069	0.65368789	2935.7029
493.86792	1.4217514	0.65539062	2937.7019
494.8689	1.4273381	0.65697044	2945.7856
495.86987	1.4291013	0.65883285	2949.3181
496.87085	1.4304842	0.66071182	2946.9351
497.87183	1.4324956	0.66265672	2951.978
498.8728	1.4375829	0.66481471	2952.314
499.87378	1.4409645	0.66671389	2948.2756
500.87476	1.4403182	0.66834313	2949.2666
501.87573	1.4481525	0.67046189	2953.0093
502.87671	1.4500908	0.67247975	2957.0129
503.87769	1.4539574	0.67445976	2953.9438
504.87866	1.4564794	0.676162	2946.4976
505.87964	1.4610232	0.67808801	2958.9299
506.88062	1.4602944	0.67993468	2955.8555
507.88159	1.4633737	0.68204236	2953.5374
508.88257	1.4677252	0.6836952	2949.1174
509.88354	1.470266	0.68522727	2952.7366
510.88452	1.4753286	0.68689674	2953.2581
511.8855	1.476573	0.68858415	2961.0444
512.88647	1.4789739	0.69053012	2960.2712
513.88745	1.4839962	0.69263488	2958.2598
514.88843	1.4852245	0.69424766	2955.4807
515.8894	1.487712	0.69585311	2956.1431
516.89038	1.4940269	0.69787198	2964.9517
517.89136	1.4928071	0.70013523	2960.7739
518.89233	1.4966897	0.70182151	2961.3826
519.89331	1.5002064	0.70358437	2963.5847
520.89429	1.5030874	0.70555395	2963.0552
521.89526	1.5048457	0.70770073	2965.1057
522.89624	1.5100274	0.70944184	2961.5181
523.89722	1.5126389	0.71122456	2960.3716
524.89819	1.5172602	0.71317077	2967.2834
525.89917	1.5189352	0.71518081	2968.7637
526.90015	1.5200499	0.71699744	2968.9417
527.90112	1.5254272	0.71929175	2969.0559
528.9021	1.5257295	0.72148877	2970.0088
529.90308	1.5326862	0.72344679	2967.9561
530.90405	1.5321513	0.72551405	2964.6179
531.90503	1.5348316	0.72711933	2966.2397
532.90601	1.5382963	0.72883302	2960.417
533.90698	1.5429723	0.73039478	2966.3936
534.90796	1.5443759	0.73243928	2970.8992
535.90894	1.5476558	0.73437303	2978.1184
536.90991	1.5498674	0.73667657	2974.5161
537.91089	1.5565841	0.73828667	2970.24
538.91187	1.5571369	0.73991662	2966.7483
539.91284	1.5601354	0.74187881	2976.8157
540.91382	1.5632254	0.74346673	2967.9514
541.91479	1.5699391	0.74544924	2983.1897
542.91577	1.5681078	0.74729127	2975.4478
543.91675	1.5733204	0.74937576	2973.4856
544.91772	1.576479	0.75131738	2980.8054
545.9187	1.5814059	0.75305116	2973.6636
546.91968	1.581986	0.75468075	2970.9377
547.92065	1.5858862	0.75634569	2975.2161
548.92163	1.5852685	0.75800842	2974.3142
549.92261	1.5921715	0.75986022	2980.5959
550.92358	1.5934232	0.76172107	2983.3083
551.92456	1.5966185	0.76377803	2982.2615
552.92554	1.5990953	0.76573515	2987.2109
553.92651	1.6006569	0.76729035	2974.3638
554.92749	1.6067001	0.76905453	2979.9939
555.92847	1.610328	0.77074867	2984.542
556.92944	1.6136005	0.77286583	2990.814
557.93042	1.6140851	0.77494282	2983.0435
558.9314	1.6189002	0.77688211	2984.8589
559.93237	1.6202661	0.77879053	2984.094
560.93335	1.6222521	0.78072292	2988.3218
561.93433	1.6256764	0.78289646	2980.168
562.9353	1.6265035	0.78509074	2987.3015
563.93628	1.6338421	0.78708202	2987.8088
564.93726	1.637077	0.78896099	2991.9697
565.93823	1.6381371	0.79069173	2982.542
566.93921	1.6405648	0.79216486	2979.4905
567.94019	1.6465629	0.79362816	2986.8372
568.94116	1.6458731	0.79547703	2992.2021
569.94214	1.6504214	0.79753089	2989.5552
570.94312	1.6545295	0.79920381	2997.0623
571.94409	1.6597694	0.80130184	3000.0718
572.94507	1.6609402	0.80376995	2998.0295
573.94604	1.6616291	0.80588782	2996.803
574.94702	1.6674573	0.80800688	2996.012
575.948	1.6699969	0.80988705	2994.7354
576.94897	1.6733358	0.81163639	2994.1716
577.94995	1.6777906	0.81342018	2992.9592
578.95093	1.6760712	0.81502497	2990.6277
579.9519	1.6816468	0.81670362	2988.9177
580.95288	1.6848854	0.81816965	2993.1802
581.95386	1.6855764	0.81973118	2994.55
582.95483	1.688552	0.82128102	2993.6814
583.95581	1.6928926	0.82342494	3002.2871
584.95679	1.6948062	0.82551455	3003.8848
585.95776	1.6983755	0.82757068	2999.9414
586.95874	1.7033849	0.82974732	3006.8604
587.95972	1.7035131	0.83161396	2999.4512
588.96069	1.7075509	0.83349514	2999.845
589.96167	1.7122101	0.83559692	3000.6606
590.96265	1.7159872	0.83761507	2999.8494
591.96362	1.7181773	0.83913642	2995.5906
592.9646	1.7203015	0.84084022	3003.094
593.96558	1.7227995	0.84293199	3004.1196
594.96655	1.72908	0.84476107	3006.6526
595.96753	1.7275313	0.84675902	3000.9287
596.96851	1.732236	0.84823233	2993.2014
597.96948	1.7337605	0.84987324	3001.3816
598.97046	1.735448	0.85162503	3007.2029
599.97144	1.7393837	0.85366029	3009.2332
600.97241	1.7444552	0.85601693	3013.2996
601.97339	1.7479396	0.85800219	3008.7295
602.97437	1.7520659	0.86033082	3011.7656
603.97534	1.7527149	0.86218858	3005.5659
604.97632	1.7576038	0.86401153	3006.9998
605.97729	1.7586921	0.86558121	3000.6667
606.97827	1.7611988	0.86742347	3010.8643
607.97925	1.7664694	0.86945057	3011.3408
608.98022	1.7657324	0.87153715	3012.344
609.9812	1.7741477	0.87345934	3013.2793
610.98218	1.7757103	0.87509179	3004.7737
611.98315	1.7758839	0.87691712	3010.4634
612.98413	1.7831646	0.87878042	3016.6982
613.98511	1.7837895	0.8806386	3008.896
614.98608	1.7873474	0.88272327	3018.1721
615.98706	1.7883066	0.88475519	3013.571
616.98804	1.7918819	0.88644934	3008.7449
617.98901	1.7912592	0.88870388	3011.3606
618.98999	1.7968887	0.89060152	3011.0884
619.99097	1.8037543	0.89257449	3019.9116
620.99194	1.8006514	0.89444005	3015.2737
621.99292	1.8048003	0.89648813	3014.4983
622.9939	1.813634	0.89845043	3015.8999
623.99487	1.8131769	0.90026081	3017.0347
624.99585	1.8169014	0.90198874	3009.7532
625.99683	1.819245	0.90394592	3017.8906
626.9978	1.8192331	0.90565616	3009.4719
627.99878	1.8256141	0.9073773	3017.1238
628.99976	1.8254346	0.90933895	3017.8103
630.00073	1.8303745	0.91122955	3016.3926
631.00171	1.8346294	0.9133839	3027.7576
632.00269	1.8388422	0.91527617	3020.3191
633.00366	1.8406435	0.9175052	3025.7554
634.00464	1.8434862	0.91915536	3019.73
635.00562	1.8460584	0.92092633	3018.8616
636.00659	1.8487817	0.92294627	3024.5715
637.00757	1.8516629	0.92491275	3021.0488
638.00854	1.8539264	0.9267931	3023.6619
639.00952	1.8575579	0.9286235	3023.6946
640.0105	1.8592726	0.93072194	3023.6575
641.01147	1.8650843	0.93260533	3024.0105
642.01245	1.8673062	0.93462801	3023.2688
643.01343	1.8687606	0.93641561	3019.4236
644.0144	1.8725455	0.93825257	3021.8838
645.01538	1.874557	0.94040513	3030.2097
646.01636	1.8777454	0.94246405	3025.4045
647.01733	1.8836635	0.94443566	3029.3862
648.01831	1.8874387	0.94626647	3029.1089
649.01929	1.8879051	0.94802982	3025.9429
650.02026	1.8891491	0.94967115	3028.1208
651.02124	1.8936535	0.95136005	3036.9783
652.02222	1.8969122	0.95376801	3030.1785
653.02319	1.8987437	0.95564419	3022.9397
654.02417	1.9049714	0.95761812	3031.3713
655.02515	1.9063492	0.95966208	3032.9587
656.02612	1.9112645	0.96170527	3035.3923
657.0271	1.910289	0.9639771	3030.001
658.02808	1.9143975	0.96580809	3029.9866
659.02905	1.9184563	0.96776277	3032.6467
660.03003	1.9217403	0.96993065	3035.8533
661.03101	1.9244108	0.97192812	3029.6885
662.03198	1.9284014	0.97368747	3032.6226
663.03296	1.9306605	0.97557539	3038.2573
664.03394	1.9345309	0.97740066	3030.5535
665.03491	1.9362547	0.979141	3031.7031
666.03589	1.937834	0.98098814	3036.989
667.03687	1.9421095	0.98296005	3037.3516
668.03784	1.9474112	0.9852286	3032.2822
669.03882	1.9458256	0.98702401	3031.4146
670.03979	1.9529951	0.98898953	3041.3242
671.04077	1.9550314	0.99094981	3038.0337
672.04175	1.9588938	0.99307984	3038.5759
673.04272	1.9598919	0.99500692	3038.0747
674.0437	1.9616907	0.99710351	3035.5537
675.04468	1.96758	0.99906921	3039.0469
676.04565	1.9674286	1.0008969	3037.5354
677.04663	1.9714999	1.0028478	3039.3323
678.04761	1.977389	1.0049245	3041.9309
679.04858	1.9785309	1.0065867	3033.5044
680.04956	1.9819418	1.0085143	3039.6094
681.05054	1.9846793	1.0102105	3038.7241
682.05151	1.9877697	1.0123069	3041.6912
683.05249	1.9906818	1.0143445	3043.0457
684.05347	1.9943161	1.0163838	3045.0183
685.05444	1.99523	1.0183244	3039.0437
686.05542	1.9986181	1.0201166	3046.6536
687.0564	2.0035336	1.0221218	3050.248
688.05737	2.0017543	1.0239683	3042.2588
689.05835	2.0070317	1.0257869	3037.9136
690.05933	2.0122082	1.0274607	3042.9163
691.0603	2.014739	1.0292968	3046.469
692.06128	2.0176342	1.0317357	3045.3723
693.06226	2.0198915	1.0337191	3044.7817
694.06323	2.0242872	1.0356991	3045.8103
695.06421	2.0242748	1.0376431	3044.2976
696.06519	2.030515	1.0394944	3042.5535
697.06616	2.0314429	1.0414129	3045.5625
698.06714	2.0339687	1.0433534	3048.063
699.06812	2.0376928	1.0453364	3050.6196
700.06909	2.0413692	1.0473654	3046.2781
701.07007	2.04339	1.0497621	3052.0471
702.07104	2.0472939	1.0516148	3051.0532
703.07202	2.0516357	1.0540279	3058.0059
704.073	2.0544379	1.0562147	3049.5586
705.07397	2.0560651	1.0581276	3046.0632
706.07495	2.0589867	1.0602274	3051.5408
707.07593	2.0631211	1.0622269	3050.1382
708.0769	2.0662637	1.0645683	3047.4187
709.07788	2.0689034	1.0664678	3044.7681
710.07886	2.0721595	1.0683937	3051.6765
711.07983	2.0744898	1.0703114	3055.8374
712.08081	2.0767765	1.0721802	3052.532
713.08179	2.0759072	1.0741948	3046.0581
714.08276	2.0850189	1.0761075	3051.105
715.08374	2.0866821	1.0782449	3060.5547
716.08472	2.0916176	1.0803403	3048.5168
717.08569	2.0951796	1.0821117	3050.3408
718.08667	2.0965679	1.0843222	3058.0171
719.08765	2.0971975	1.0863917	3053.8638
720.08862	2.0998318	1.0887589	3052.5771
721.0896	2.1038253	1.0906364	3048.8625
722.09058	2.1076412	1.0925927	3052.8909
723.09155	2.1094494	1.0944239	3049.6389
724.09253	2.1098897	1.0967411	3058.4609
725.09351	2.1150634	1.0988151	3055.5098
726.09448	2.119874	1.1008174	3050.8206
727.09546	2.1200533	1.1027848	3051.8469
728.09644	2.1268504	1.1046911	3055.033
729.09741	2.127279	1.1064942	3051.0225
730.09839	2.1308696	1.1082535	3054.9297
731.09937	2.1341085	1.1102569	3052.8738
732.10034	2.1363163	1.1121324	3061.4924
733.10132	2.1417575	1.1143079	3057.7654
734.10229	2.1419346	1.1163037	3054.0225
735.10327	2.1437671	1.1180155	3052.4863
736.10425	2.1500797	1.1197731	3055.8213
737.10522	2.1537192	1.1217402	3059.1604
738.1062	2.1569979	1.123717	3057.6226
739.10718	2.1589205	1.1259221	3064.3135
740.10815	2.1627064	1.1279371	3060.6921
741.10913	2.1663206	1.1297486	3059.9399
742.11011	2.1681511	1.1317389	3068.9438
743.11108	2.171515	1.1339042	3061.9336
744.11206	2.175658	1.1362461	3056.4163
745.11304	2.1781354	1.1382284	3061.6531
746.11401	2.1773965	1.1404268	3069.9714
747.11499	2.1826425	1.1423379	3061.3323
748.11597	2.1868074	1.1443967	3057.5032
749.11694	2.1884713	1.1465214	3058.7891
750.11792	2.1900961	1.148622	3065.7861
751.1189	2.190855	1.1510999	3062.3215
752.11987	2.1978257	1.1535828	3065.6919
753.12085	2.2026837	1.1558526	3063.9202
754.12183	2.2031481	1.1579554	3057.0994
755.1228	2.2074001	1.1598512	3063.9819
756.12378	2.2111027	1.1617119	3064.8909
757.12476	2.2139685	1.1637346	3061.2437
758.12573	2.2160718	1.1653626	3065.137
759.12671	2.2205129	1.1674938	3067.5806
760.12769	2.2225862	1.1692482	3064.8335
761.12866	2.2241249	1.1714804	3060.8909
762.12964	2.2254174	1.1736996	3066.1423
763.13062	2.2310443	1.1755418	3064.0896
764.13159	2.2335548	1.1777178	3072.3054
765.13257	2.2343037	1.1800542	3068.2778
766.13354	2.2379372	1.1826328	3068.1001
767.13452	2.2428081	1.1848093	3059.9607
768.1355	2.2448769	1.1865535	3065.9675
769.13647	2.2478752	1.1888468	3067.3213
770.13745	2.2529228	1.1908933	3065.0742
771.13843	2.2549214	1.1929154	3061.1301
772.1394	2.2570305	1.1948378	3070.5752
773.14038	2.2612069	1.1968093	3064.8108
774.14136	2.265449	1.1986256	3072.8857
775.14233	2.2673719	1.2006743	3066.1768
776.14331	2.2714386	1.2026983	3069.3384
777.14429	2.2735269	1.2045052	3068.1077
778.14526	2.2767806	1.2065458	3068.8311
779.14624	2.2790167	1.2088432	3072.3123
780.14722	2.2813478	1.2112874	3067.8938
781.14819	2.2853086	1.2133816	3068.9224
782.14917	2.2864125	1.2153879	3068.2273
783.15015	2.2913947	1.2178985	3070.2666
784.15112	2.2922606	1.2200634	3066.7822
785.1521	2.2947495	1.2224042	3072.2031
786.15308	2.2968469	1.2246215	3066.5156
787.15405	2.3021214	1.2269502	3072.5249
788.15503	2.3068414	1.2294267	3076.2363
789.15601	2.308969	1.2312701	3066.738
790.15698	2.3127711	1.23353	3074.656
791.15796	2.3129199	1.2355325	3071.9939
792.15894	2.3175082	1.2376264	3065.1243
793.15991	2.321727	1.2394499	3066.1672
794.16089	2.3239923	1.2414583	3068.5996
795.16187	2.3267274	1.243346	3071.6235
796.16284	2.3296707	1.2455984	3069.9246
797.16382	2.3323767	1.2480541	3071.7561
798.16479	2.333879	1.2499318	3067.9043
799.16577	2.3387098	1.2518234	3069.0266
800.16675	2.342886	1.2536316	3071.0732
801.16772	2.3449368	1.2559837	3073.717
802.1687	2.3491542	1.2580984	3070.2126
803.16968	2.3509119	1.2605504	3077.5674
804.17065	2.3541965	1.2628496	3071.7007
805.17163	2.3525019	1.264773	3067.103
806.17261	2.3602245	1.2671264	3077.6199
807.17358	2.3627188	1.2696927	3072.3704
808.17456	2.3649621	1.2721472	3070.7837
809.17554	2.3653471	1.2740721	3066.5637
810.17651	2.3725169	1.2759849	3068.7566
811.17749	2.3738606	1.2779399	3073.5256
812.17847	2.376842	1.2798073	3069.5354
813.17944	2.3787086	1.281991	3075.0769
814.18042	2.3824484	1.2841173	3074.6143
815.1814	2.3864155	1.2866229	3078.6672
816.18237	2.3901517	1.2891725	3075.4741
817.18335	2.3927839	1.2914926	3071.7346
818.18433	2.3945105	1.2937011	3070.3201
819.1853	2.4008048	1.2956359	3076.9487
820.18628	2.4006734	1.2979146	3080.7429
821.18726	2.4008808	1.3003659	3076.9221
822.18823	2.4096601	1.3031303	3081.1267
823.18921	2.4103107	1.3050408	3069.1072
824.19019	2.4169571	1.3071743	3069.9778
825.19116	2.4173234	1.309293	3078.3643
826.19214	2.4213314	1.3112803	3078.907
827.19312	2.4226885	1.3134665	3076.0161
828.19409	2.4259534	1.3154454	3073.4763
829.19507	2.4285791	1.3178262	3080.062
830.19604	2.4318178	1.320233	3078.0098
831.19702	2.4352241	1.3224915	3076.311
832.198	2.4391727	1.32459	3076.2786
833.19897	2.4389799	1.3265162	3074.8069
834.19995	2.4452012	1.3286943	3073.27
835.20093	2.447062	1.3308669	3078.3438
836.2019	2.4514685	1.3331859	3076.5186
837.20288	2.4562485	1.3351017	3078.3223
838.20386	2.4579124	1.33723	3081.9185
839.20483	2.4592435	1.3397052	3079.5959
840.20581	2.4642146	1.3419758	3080.6719
841.20679	2.4662595	1.3446075	3080.3914
842.20776	2.4671276	1.3467245	3070.0588
843.20874	2.4718904	1.3493658	3078.1763
844.20972	2.4745705	1.3515767	3075.6121
845.21069	2.4747059	1.3535346	3072.0391
846.21167	2.4781132	1.3561502	3083.865
847.21265	2.4837568	1.3588581	3080.5308
848.21362	2.4865303	1.3615257	3078.0723
849.2146	2.4872944	1.3639164	3074.5388
850.21558	2.4924974	1.3665229	3078.7271
851.21655	2.4947402	1.3690012	3082.4597
852.21753	2.5002606	1.3712854	3076.844
853.21851	2.5021091	1.373316	3076.168
854.21948	2.506716	1.3754553	3081.1548
855.22046	2.503983	1.3777629	3073.832
856.22144	2.5117357	1.3796227	3073.374
857.22241	2.5154421	1.3817801	3079.0208
858.22339	2.5142579	1.3836377	3073.8286
859.22437	2.5198121	1.3860949	3085.7095
860.22534	2.5235593	1.3887786	3087.1821
861.22632	2.52665	1.3912896	3079.6147
862.22729	2.5288982	1.3937602	3079.2446
863.22827	2.5329008	1.3961332	3079.0593
864.22925	2.5344181	1.3986847	3082.832
865.23022	2.53702	1.4004827	3073.166
866.2312	2.5384438	1.4025862	3074.033
867.23218	2.5404859	1.4047885	3075.8977
868.23315	2.5449424	1.4066201	3078.446
869.23413	2.5473456	1.4088598	3079.9971
870.23511	2.5510974	1.4110539	3078.8386
871.23608	2.5521352	1.4131826	3077.0771
872.23706	2.5597737	1.4156342	3084.3037
873.23804	2.5598738	1.4181657	3081.7332
874.23901	2.5663147	1.4207605	3080.8909
875.23999	2.5648842	1.4229639	3079.0659
876.24097	2.5699065	1.4254929	3080.1973
877.24194	2.5715721	1.4281025	3078.728
878.24292	2.5753355	1.4307303	3074.5627
879.2439	2.5807214	1.4326841	3074.5298
880.24487	2.5832171	1.4348543	3078.2585
881.24585	2.5836236	1.4371243	3076.4929
882.24683	2.5903268	1.4397906	3083.1685
883.2478	2.5904791	1.4422661	3075.0608
884.24878	2.5930872	1.4448317	3080.0601
885.24976	2.5965345	1.4475331	3083.0093
886.25073	2.599184	1.4499608	3081.2761
887.25171	2.6012168	1.4522157	3077.2153
888.25269	2.6043532	1.4544461	3073.2959
889.25366	2.6088006	1.4566169	3074.7041
890.25464	2.6122446	1.4589318	3074.6272
891.25562	2.6122503	1.4611685	3070.0154
892.25659	2.6199696	1.463712	3078.4717
893.25757	2.6219831	1.4662018	3079.6541
894.25854	2.6247931	1.4685192	3079.7432
895.25952	2.6262136	1.4713539	3080.1396
896.2605	2.628026	1.4741738	3077.896
897.26147	2.6332653	1.4768916	3077.6265
898.26245	2.6404717	1.4790183	3074.9573
899.26343	2.6390374	1.4813526	3074.1309
900.2644	2.6421363	1.4836789	3077.9292
901.26538	2.643445	1.4864894	3080.9976
902.26636	2.6484072	1.4887226	3073.7246
903.26733	2.650696	1.4910053	3074.7366
904.26831	2.6564088	1.4934145	3080.9326
905.26929	2.6575546	1.4955995	3071.6404
906.27026	2.6636007	1.4979634	3087.1494
907.27124	2.6625547	1.5002545	3078.6343
908.27222	2.6682625	1.5025263	3077.8813
909.27319	2.6689458	1.5050037	3076.6101
910.27417	2.6708899	1.5074041	3076.6692
911.27515	2.677449	1.5098947	3084.4001
912.27612	2.6792016	1.5123638	3073.895
913.2771	2.6803737	1.5150354	3077.6963
914.27808	2.6838765	1.5177615	3079.5928
915.27905	2.6844227	1.5204308	3078.9387
916.28003	2.6892395	1.5229105	3073.4912
917.28101	2.6904891	1.5251526	3071.0283
918.28198	2.6939545	1.52742	3071.3948
919.28296	2.70123	1.5298542	3081.7507
920.28394	2.6988893	1.5323987	3080.0876
921.28491	2.7038684	1.5351099	3079.7231
922.28589	2.7063925	1.5383582	3085.7795
923.28687	2.7130516	1.5416869	3079.5444
924.28784	2.7151465	1.5444698	3075.9624
925.28882	2.7165205	1.5471216	3073.4993
926.28979	2.7194333	1.5494211	3073.3115
927.29077	2.7215812	1.5517488	3075.501
928.29175	2.7294548	1.5544972	3076.635
929.29272	2.728888	1.5571468	3075.4524
930.2937	2.7332442	1.5597929	3073.6064
931.29468	2.7341461	1.5619502	3069.5886
932.29565	2.74259	1.5643187	3072.262
933.29663	2.739877	1.5667108	3075.8083
934.29761	2.74371	1.569742	3079.0073
935.29858	2.7467871	1.5719993	3069.8098
936.29956	2.7516398	1.5743873	3077.3184
937.30054	2.7523603	1.5771519	3078.0664
938.30151	2.7545133	1.5797747	3073.4749
939.30249	2.7590647	1.5823991	3071.8657
940.30347	2.7622578	1.5845768	3071.4102
941.30444	2.7650697	1.587486	3074.7383
942.30542	2.7696865	1.5902964	3082.1135
943.3064	2.7727795	1.5932853	3079.1179
944.30737	2.7754264	1.5964015	3076.9836
945.30835	2.778641	1.5988803	3067.113
946.30933	2.7796063	1.6014969	3070.6023
947.3103	2.7832942	1.6038507	3068.686
948.31128	2.7860126	1.6065043	3067.5771
949.31226	2.7893066	1.608821	3071.5251
950.31323	2.7908325	1.6114545	3072.4441
951.31421	2.7955718	1.6139945	3068.6484
952.31519	2.7989895	1.6166584	3074.8594
953.31616	2.8034518	1.6194645	3072.6741
954.31714	2.8043222	1.6220053	3072.6431
955.31812	2.8086071	1.6247059	3070.2693
956.31909	2.8103795	1.6273854	3074.7815
957.32007	2.8144722	1.630295	3070.7546
958.32104	2.8150058	1.633233	3069.1248
959.32202	2.8204069	1.6363339	3069.8435
960.323	2.8193462	1.6390562	3063.2231
961.32397	2.8246927	1.6415912	3065.3345
962.32495	2.8287768	1.6446019	3070.4644
963.32593	2.8307166	1.6474043	3068.5474
964.3269	2.8368993	1.6500525	3064.4468
965.32788	2.835407	1.6526148	3064.4644
966.32886	2.8380616	1.6551564	3067.4463
967.32983	2.8412385	1.6580087	3061.6516
968.33081	2.8474069	1.6603863	3060.0332
969.33179	2.8518739	1.6627742	3067.1409
970.33276	2.8536375	1.6656373	3069.5188
971.33374	2.855588	1.6687599	3071.8848
972.33472	2.8554642	1.6716232	3065.293
973.33569	2.8608675	1.6746862	3068.2483
974.33667	2.8640857	1.6774629	3060.6492
975.33765	2.865679	1.6801319	3057.5757
976.33862	2.8703015	1.6831293	3066.7793
977.3396	2.8688927	1.6856627	3064.6785
978.34058	2.8784688	1.6882889	3064.5825
979.34155	2.8778427	1.6910362	3064.2629
980.34253	2.882354	1.6939162	3059.6809
981.34351	2.8864291	1.696484	3054.0894
982.34448	2.8864558	1.6988919	3062.4719
983.34546	2.8910396	1.7013664	3062.6567
984.34644	2.8911667	1.7043734	3062.2239
985.34741	2.8961308	1.7068841	3055.8623
986.34839	2.8985479	1.7095497	3065.6077
987.34937	2.9024613	1.7123455	3059.2043
988.35034	2.9053905	1.7149307	3055.5764
989.35132	2.910634	1.7179941	3065.4365
990.35229	2.9120493	1.7215252	3062.8518
991.35327	2.9165847	1.7247362	3059.6523
992.35425	2.9181266	1.7278018	3060.0159
993.35522	2.9213696	1.7310243	3059.3015
994.3562	2.9262352	1.7339242	3056.7991
995.35718	2.9277403	1.7365282	3056.429
996.35815	2.9289651	1.739643	3059.7034
997.35913	2.9351845	1.7431571	3059.575
998.36011	2.9336369	1.7459842	3052.1028
999.36108	2.9390781	1.7485406	3052.5645
1000.3621	2.9419186	1.7515087	3056.78
1001.363	2.9438694	1.7544625	3049.1343
1002.364	2.9481754	1.7577363	3053.325
1003.365	2.9525979	1.7604903	3054.6628
1004.366	2.9532561	1.763254	3054.5686
1005.3669	2.9568491	1.7662632	3051.998
1006.3679	2.9607513	1.7692808	3050.7908
1007.3689	2.9624636	1.7722963	3050.5828
1008.3699	2.9690626	1.775202	3048.6665
1009.3708	2.9667828	1.7782012	3049.2898
1010.3718	2.9723938	1.7812037	3045.291
1011.3728	2.9753087	1.7840189	3046.0137
1012.3738	2.9785323	1.7865281	3044.9138
1013.3748	2.9812126	1.7889023	3043.2468
1014.3757	2.98246	1.7916403	3045.9924
1015.3767	2.9864755	1.7945091	3045.6255
1016.3777	2.9914041	1.7972071	3045.3594
1017.3787	2.9917693	1.7996907	3039.3787
1018.3796	2.9977949	1.8022808	3048.1052
1019.3806	2.999661	1.805921	3050.605
1020.3816	2.9990797	1.8099415	3047.4104
1021.3826	3.0026722	1.8132452	3037.2329
1022.3835	3.0078301	1.8152052	3027.854
1023.3845	3.0120082	1.8170847	3031.9106
1024.3855	3.0142877	1.8188406	3035.7061
1025.3865	3.0163412	1.8209119	3036.0688
1026.3875	3.0195456	1.8233341	3039.3772
1027.3884	3.0213683	1.8259394	3038.292
1028.3894	3.0266082	1.8293097	3045.2549
1029.3904	3.0295391	1.8329859	3041.4568
1030.3914	3.0348303	1.8365062	3039.6663
1031.3923	3.0366049	1.8396914	3036.7122
1032.3933	3.0389698	1.8431513	3036.9866
1033.3943	3.0400438	1.8458768	3033.7046
1034.3953	3.0445607	1.8489684	3030.3843
1035.3962	3.0489318	1.851607	3035.645
1036.3972	3.0515702	1.8543378	3031.6255
1037.3982	3.0527654	1.8577417	3034.2407
1038.3992	3.0574172	1.8603182	3028.436
1039.4001	3.0604558	1.863378	3028.2073
1040.4011	3.0624986	1.8658711	3028.1453
1041.4021	3.0640273	1.868977	3025.7961
1042.4031	3.0697036	1.8720936	3028.1565
1043.4041	3.0721538	1.8752	3027.4712
1044.405	3.0775428	1.8785124	3022.324
1045.406	3.0774095	1.8815911	3021.3579
1046.407	3.079402	1.8842496	3018.175
1047.408	3.0821335	1.8866466	3019.4033
1048.4089	3.0854397	1.8896344	3020.7712
1049.4099	3.0895102	1.8928971	3024.6018
1050.4109	3.0923705	1.8956248	3018.3364
1051.4119	3.0959811	1.8984216	3024.272
1052.4128	3.0987871	1.9017519	3014.7896
1053.4138	3.1013496	1.9052186	3021.6504
1054.4148	3.1029036	1.9084709	3011.6567
1055.4158	3.1086605	1.9121572	3018.9709
1056.4167	3.1112533	1.9157379	3017.4292
1057.4177	3.1119101	1.9190806	3010.5837
1058.4187	3.1161687	1.9221711	3008.5151
1059.4197	3.1212025	1.9249498	3004.96
1060.4207	3.1212087	1.9276	3004.915
1061.4216	3.1276138	1.9304442	2999.343
1062.4226	3.1285975	1.933095	3007.1899
1063.4236	3.1299145	1.9359921	3003.926
1064.4246	3.1325448	1.9389971	3006.4407
1065.4255	3.1381199	1.9417931	2998.2917
1066.4265	3.1411264	1.9447292	3000.3582
1067.4275	3.143096	1.9477853	3005.4844
1068.4285	3.1474357	1.9510984	3001.0051
1069.4294	3.1486304	1.9543501	2999.093
1070.4304	3.1528969	1.9573162	2998.134
1071.4314	3.1543431	1.9607363	2999.3367
1072.4324	3.1573911	1.9644436	2999.2537
1073.4333	3.1611764	1.9681461	2986.9099
1074.4343	3.1626933	1.9712347	2986.7434
1075.4353	3.1684859	1.9740077	2989.7671
1076.4363	3.1729405	1.9770141	2990.1724
1077.4373	3.173121	1.9797441	2987.5427
1078.4382	3.1778066	1.9827383	2991.1636
1079.4392	3.1804621	1.9864188	2989.2986
1080.4402	3.182097	1.9897048	2982.0574
1081.4412	3.1857092	1.9922003	2977.5645
1082.4421	3.187891	1.9951764	2984.8894
1083.4431	3.1905541	1.998137	2983.0488
1084.4441	3.1959321	2.0012436	2980.6782
1085.4451	3.1976345	2.0047274	2976.4568
1086.446	3.2014542	2.0076282	2968.8113
1087.447	3.202754	2.0103748	2973.283
1088.448	3.2069979	2.0134032	2976.4993
1089.449	3.2114518	2.017101	2969.2827
1090.45	3.213371	2.0201299	2966.7646
1091.4509	3.2178164	2.023221	2971.2673
1092.4519	3.2192092	2.0263774	2966.574
1093.4529	3.2214882	2.0290742	2958.9695
1094.4539	3.2251582	2.0318689	2961.4329
1095.4548	3.2285945	2.0344875	2960.7554
1096.4558	3.2297199	2.0372562	2965.3223
1097.4568	3.2331793	2.0396366	2956.0464
1098.4578	3.2399032	2.0418124	2957.5928
1099.4587	3.2387583	2.0437248	2956.3906
1100.4597	3.2426918	2.0456171	2952.1819
1101.4607	3.2444661	2.0472431	2956.4792
1102.4617	3.2501082	2.0484304	2948.7273
1103.4626	3.2507989	2.0489681	2948.1057
1104.4636	3.2548923	2.0494649	2947.6321
1105.4646	3.2555554	2.050338	2938.2878
1106.4656	3.2586017	2.0506759	2935.1206
1107.4666	3.2608016	2.0506845	2938.7661
1108.4675	3.2654631	2.0509167	2942.467
1109.4685	3.2709005	2.0509069	2939.0332
1110.4695	3.2729208	2.0510292	2935.519
1111.4705	3.2738075	2.0511503	2929.4844
1112.4714	3.2786739	2.0512023	2928.6626
1113.4724	3.2824137	2.051065	2936.2891
1114.4734	3.2845216	2.0512745	2929.0081
1115.4744	3.289602	2.051245	2927.8574
1116.4753	3.2905531	2.0511529	2932.5298
1117.4763	3.2941339	2.0513732	2922.3823
1118.4773	3.297668	2.0511301	2921.2224
1119.4783	3.299206	2.0512135	2917.4094
1120.4792	3.3025959	2.0515845	2920.1062
1121.4802	3.3032672	2.0517006	2921.9578
1122.4812	3.3098686	2.0518527	2913.3789
1123.4822	3.3134959	2.0517063	2918.5862
1124.4832	3.3145232	2.0516808	2912.9133
1125.4841	3.3188121	2.0517097	2904.4907
1126.4851	3.3219459	2.0519345	2906.6157
1127.4861	3.3247595	2.0517864	2902.8604
1128.4871	3.3274555	2.0519834	2905.2175
1129.488	3.3297288	2.0521617	2898.4028
1130.489	3.332583	2.0520122	2897.5396
1131.49	3.3346453	2.0518749	2892.6541
1132.491	3.3401442	2.0518041	2891.5322
1133.4919	3.34287	2.0517609	2888.5288
1134.4929	3.3465137	2.0519907	2881.3682
1135.4939	3.3473141	2.0520947	2879.865
1136.4949	3.3548524	2.052	2885.625
1137.4958	3.3528054	2.0520897	2880.4734
1138.4968	3.3557367	2.0521479	2875.9502
1139.4978	3.3596079	2.0517769	2878.4163
1140.4988	3.364238	2.0520794	2868.9595
1141.4998	3.3654859	2.051929	2866.8621
1142.5007	3.3701606	2.0519311	2864.5544
1143.5017	3.3689768	2.0523937	2860.155
1144.5027	3.3741002	2.051805	2859.9717
1145.5037	3.3770278	2.0519817	2856.0747
1146.5046	3.3808947	2.0519347	2853.1682
1147.5056	3.3851924	2.052108	2850.6331
1148.5066	3.3857274	2.0523279	2848.8684
1149.5076	3.3915546	2.0520637	2845.5513
1150.5085	3.3903551	2.0521102	2836.0308
1151.5095	3.3927188	2.0520494	2840.1194
1152.5105	3.3972476	2.0520201	2834.552
1153.5115	3.4027314	2.051836	2842.3953
1154.5125	3.4046795	2.0521903	2833.7974
1155.5134	3.4085984	2.052458	2825.7341
1156.5144	3.4095874	2.0522823	2822.2556
1157.5154	3.4149487	2.0525305	2821.8645
1158.5164	3.414273	2.0525355	2822.6489
1159.5173	3.4168613	2.0523853	2816.417
1160.5183	3.4235713	2.0524142	2812.5715
1161.5193	3.4249251	2.0526974	2808.8528
1162.5203	3.4309185	2.0523212	2810.228
1163.5212	3.4295235	2.0524139	2801.865
1164.5222	3.433156	2.0523567	2803.5872
1165.5232	3.4400818	2.0522578	2796.1729
1166.5242	3.4398065	2.052438	2797.6262
1167.5251	3.4452755	2.0522947	2794.8687
1168.5261	3.4457061	2.0524073	2785.9407
1169.5271	3.4500656	2.0523798	2779.0566
1170.5281	3.4533865	2.0523882	2778.7815
1171.5291	3.4554477	2.0522294	2777.9551
1172.53	3.4588377	2.0523236	2778.8857
1173.531	3.4615927	2.0524595	2770.8372
1174.532	3.4656808	2.0522387	2764.814
1175.533	3.4683878	2.0523694	2758.8494
1176.5339	3.472333	2.0523546	2757.2244
1177.5349	3.4733608	2.0522494	2755.825
1178.5359	3.4782856	2.0522461	2753.4724
1179.5369	3.4832184	2.0522342	2748.6733
1180.5378	3.4816306	2.0524721	2736.3105
1181.5388	3.4876566	2.0522892	2739.0752
1182.5398	3.4891393	2.0523336	2740.2002
1183.5408	3.491787	2.0523014	2728.05
1184.5417	3.4946404	2.0523331	2722.5598
1185.5427	3.4961817	2.0523312	2711.3738
1186.5437	3.5050159	2.052259	2718.446
1187.5447	3.5055792	2.0523381	2710.9695
1188.5457	3.5073659	2.0521827	2709.3611
1189.5466	3.509527	2.0523534	2698.8306
1190.5476	3.5139627	2.0524533	2694.8972
1191.5486	3.5184309	2.0523744	2687.0676
1192.5496	3.5219831	2.0522161	2688.4146
1193.5505	3.524034	2.0523286	2684.5671
1194.5515	3.5246363	2.0524523	2673.8201
1195.5525	3.5267882	2.052495	2664.8525
1196.5535	3.5314736	2.0525925	2663.6331
1197.5544	3.5356901	2.0526342	2648.0896
1198.5554	3.5348182	2.0526299	2632.6038
1199.5564	3.5413246	2.0528455	2625.3296
1200.5574	3.5442228	2.0527554	2616.9106
1201.5583	3.5472589	2.0527112	2610.2561
1202.5593	3.5490806	2.052685	2592.615
1203.5603	3.5531974	2.0528116	2584.1604
1204.5613	3.5560663	2.0526779	2566.6799
1205.5623	3.5596402	2.0523305	2525.1599
1206.5632	3.5645843	2.0525019	2476.0381
1206.8635	3.5624213	2.0525122	2460.4355