File: datasets/am_bench_2022/raw_data/0-XY.20-3/specimen.dat
MTS793|MPT|ENU|1|2|.|/|:|1|0|0|A

Operator Information						Time:	13.411133	Sec	10/13/2021 4:37:26 PM
Operator	Jake Benzing
Project	AM Bench 2022 mini-tensile challenge
Specimen ID	0-XY.20-3
Material	PBF-L Inconel 625
Specimen Width	2.55	mm
Specimen Thickness	1.53	mm
Notes
Operator Information End

Data Acquisition						Time:	1014.4043	Sec	10/13/2021 4:54:07 PM
Time	Axial Displacement	Axial Extensometer	Axial Force
Sec	mm	mm	N
13.52417	-0.0026876547	-1.0576048e-05	56.974136
14.525146	0.00050372712	6.9675647e-05	68.788078
15.526123	0.0042117927	6.8306974e-05	83.435745
16.5271	0.01107185	0.00016087056	100.84248
17.528076	0.011402749	0.0002334665	112.67841
18.529053	0.010058459	0.0002259593	123.16245
19.530029	0.015418407	0.00041594138	136.05966
20.531006	0.018481884	0.00052829331	148.45483
21.531982	0.021978298	0.00064579316	164.07066
22.532959	0.021804346	0.00049543293	176.44414
23.533936	0.026478061	0.00066416373	197.76904
24.534912	0.027803706	0.00077440939	215.65189
25.535889	0.032703418	0.00082659512	236.54161
26.536865	0.033498548	0.00092865439	253.85278
27.537842	0.03716379	0.00096379215	277.72546
28.538818	0.042054947	0.0012560579	300.15781
29.539795	0.04574601	0.00118849	316.48517
30.540771	0.045414496	0.0012760265	327.69446
31.541748	0.048969712	0.0014803704	352.05597
32.542725	0.05402514	0.0013641655	372.15036
33.543701	0.057297811	0.0015198806	392.36334
34.544678	0.061146434	0.001754659	416.03864
35.545654	0.061184749	0.0017786466	437.45676
36.546631	0.066643812	0.0018808944	461.96573
37.547607	0.06986101	0.0019828593	482.5751
38.548584	0.070001766	0.0022451496	498.38446
39.549561	0.07432548	0.0022329625	528.80298
40.550537	0.077844843	0.0025116235	557.54761
41.551514	0.078756399	0.0026059379	578.7066
42.55249	0.085104279	0.0027453692	605.42767
43.553467	0.084527925	0.0027034446	621.88354
44.554443	0.088393144	0.0029925837	649.20673
45.55542	0.093028545	0.0032088922	682.97888
46.556396	0.098779783	0.0031546503	709.46411
47.557373	0.096441001	0.0033211713	739.28394
48.55835	0.10181703	0.0035382186	761.96808
49.559326	0.10485101	0.003680804	788.89294
50.560303	0.10732794	0.0037074483	817.30652
51.561279	0.10880131	0.0038495299	841.95178
52.562256	0.11321501	0.0040820953	875.30566
53.563232	0.11577897	0.0041047893	896.19562
54.564209	0.11858244	0.0043327641	926.15295
55.565186	0.1208678	0.0045302762	955.01343
56.566162	0.12556979	0.0047662552	985.43988
57.567139	0.1261484	0.0047407132	1009.7238
58.568115	0.12938789	0.0049562361	1037.8593
59.569092	0.13488443	0.0050164978	1062.4243
60.570068	0.13551448	0.0051937262	1095.9034
61.571045	0.14008063	0.0054067331	1123.0449
62.572021	0.14460616	0.0056310077	1156.4318
63.572998	0.1434875	0.0057097636	1188.7878
64.573975	0.14982882	0.0058419858	1219.5422
65.574951	0.15228686	0.0060668834	1246.8107
66.575928	0.15366864	0.0062267384	1268.8486
67.576904	0.15924321	0.0063807694	1297.6648
68.577881	0.16017054	0.0064606755	1318.6144
69.578857	0.16525814	0.0066303113	1347.5704
70.579834	0.16460659	0.0068149525	1373.1163
71.580811	0.17133224	0.0068726572	1405.9801
72.581787	0.17649856	0.0071406923	1430.8823
73.582764	0.17437425	0.0072908644	1457.9912
74.58374	0.17924917	0.0073275603	1488.2432
75.584717	0.18238764	0.0075289565	1518.3105
76.585693	0.18559085	0.007843297	1545.5493
77.58667	0.18781577	0.0079815229	1567.3999
78.587646	0.18940695	0.008125077	1599.6998
79.588623	0.19288267	0.0082130218	1615.9437
80.5896	0.19995499	0.0084956866	1650.1549
81.590576	0.20104358	0.0085446667	1675.1011
82.591553	0.20347974	0.0087283058	1706.3767
83.592529	0.20526183	0.0090646297	1735.1674
84.593506	0.2073683	0.0091593089	1757.4836
85.594482	0.21219072	0.0093736667	1790.9691
86.595459	0.21784449	0.0095972503	1814.5859
87.596436	0.21893384	0.0097159585	1832.1923
88.597412	0.22124706	0.0097947875	1860.1617
89.598389	0.2250485	0.010028319	1876.5389
90.599365	0.22382884	0.010199795	1903.0934
91.600342	0.23196536	0.010510013	1928.7419
92.601318	0.23257144	0.010577269	1950.9207
93.602295	0.23639424	0.010848993	1978.4043
94.603271	0.24061945	0.011222287	2010.9878
95.604248	0.24396573	0.011224824	2023.5836
96.605225	0.24319799	0.011451364	2043.3492
97.606201	0.25243288	0.011787968	2077.8174
98.607178	0.25026724	0.011958809	2091.3096
99.608154	0.25376162	0.012154797	2117.6116
100.60913	0.2562201	0.012386186	2134.9495
101.61011	0.26157585	0.012581161	2156.2859
102.61108	0.26102719	0.012806039	2172.2017
103.61206	0.26719433	0.012977854	2194.2751
104.61304	0.26709473	0.013192713	2207.0828
105.61401	0.27209669	0.013580088	2229.0713
106.61499	0.27649853	0.01368384	2250.0391
107.61597	0.27901801	0.013991185	2268.8953
108.61694	0.28215244	0.014238026	2287.6248
109.61792	0.28455049	0.014425402	2306.2002
110.6189	0.28642437	0.014828663	2322.4729
111.61987	0.29091325	0.015014292	2337.3127
112.62085	0.29050267	0.015382838	2353.303
113.62183	0.29742998	0.015630566	2369.1152
114.6228	0.29886642	0.015980298	2389.5317
115.62378	0.30214974	0.016188042	2400.8987
116.62476	0.30406895	0.016437227	2413.5608
117.62573	0.30711237	0.016706742	2423.8098
118.62671	0.30931023	0.017105713	2440.1489
119.62769	0.31424785	0.017419061	2455.1628
120.62866	0.31700993	0.017698606	2468.8943
121.62964	0.32109109	0.01807151	2483.0051
122.63062	0.32488793	0.018344093	2483.1165
123.63159	0.3257181	0.018512966	2499.2112
124.63257	0.32899487	0.019014493	2514.6223
125.63354	0.33305123	0.019429998	2530.1807
126.63452	0.33797988	0.019818489	2539.1926
127.6355	0.34051251	0.020183923	2547.9146
128.63647	0.34383926	0.020623405	2564.4414
129.63745	0.34576866	0.021210808	2576.9417
130.63843	0.34879142	0.021548277	2585.9434
131.6394	0.35186991	0.02211454	2590.3633
132.64038	0.35266319	0.022590106	2597.9182
133.64136	0.35677284	0.023088731	2606.9504
134.64233	0.35925055	0.023457831	2612.6387
135.64331	0.36319	0.024051622	2623.5251
136.64429	0.36698842	0.024724931	2634.6304
137.64526	0.3700693	0.025265308	2647.6096
138.64624	0.37369376	0.026020475	2653.5073
139.64722	0.37455556	0.026601534	2661.6169
140.64819	0.38025126	0.027152529	2666.3828
141.64917	0.38159391	0.027851904	2674.1907
142.65015	0.38288119	0.028645331	2675.3628
143.65112	0.38971958	0.0293367	2690.1499
144.6521	0.38965136	0.029982287	2701.5703
145.65308	0.38875228	0.030854272	2693.4951
146.65405	0.39824006	0.031515848	2705.0474
147.65503	0.39630958	0.03203259	2702.2947
148.65601	0.40512395	0.032756984	2710.7041
149.65698	0.40291953	0.033586241	2718.8162
150.65796	0.40898097	0.034410071	2722.5081
151.65894	0.41004184	0.035234489	2729.7698
152.65991	0.41609591	0.036189817	2738.5686
153.66089	0.41753486	0.037111096	2744.9534
154.66187	0.42341962	0.037968416	2747.4211
155.66284	0.42429164	0.039014254	2752.8447
156.66382	0.42647821	0.04005412	2748.5645
157.66479	0.42897478	0.040970698	2753.8403
158.66577	0.43357885	0.041890316	2763.5947
159.66675	0.43401894	0.042997964	2767.9495
160.66772	0.43706214	0.044180483	2774.9705
161.6687	0.44198522	0.045118928	2778.6458
162.66968	0.44446501	0.046241824	2788.9973
163.67065	0.44687426	0.047475316	2785.1921
164.67163	0.45606557	0.048641477	2797.7437
165.67261	0.45396218	0.049617324	2794.1313
166.67358	0.45554903	0.0506576	2795.479
167.67456	0.45669356	0.051912539	2799.1609
168.67554	0.46311966	0.053151384	2805.5171
169.67651	0.46392652	0.05442911	2804.8086
170.67749	0.47004533	0.05557926	2807.6079
171.67847	0.47208133	0.056878034	2814.6343
172.67944	0.47638398	0.058012586	2817.1443
173.68042	0.47983918	0.059579726	2823.4934
174.6814	0.47997278	0.060689237	2814.7983
175.68237	0.48569128	0.06162674	2821.551
176.68335	0.48593467	0.062623322	2820.8516
177.68433	0.4896448	0.063869856	2832.9182
178.6853	0.49428895	0.065193526	2828.8628
179.68628	0.49332678	0.066227116	2829.417
180.68726	0.49706706	0.067297995	2833.1694
181.68823	0.5031535	0.068439059	2839.4675
182.68921	0.50482273	0.069766991	2840.8806
183.69019	0.51150888	0.071071684	2847.9468
184.69116	0.51221818	0.072203927	2843.5002
185.69214	0.51371425	0.073394425	2847.5583
186.69312	0.51984394	0.074717999	2857.2864
187.69409	0.517946	0.076005645	2849.4636
188.69507	0.52242881	0.077461556	2853.7532
189.69604	0.52931756	0.078643449	2859.5569
190.69702	0.52646762	0.080050707	2857.9238
191.698	0.53130496	0.081586629	2871.3413
192.69897	0.53505933	0.082878329	2862.0259
193.69995	0.53682327	0.084006667	2862.4448
194.70093	0.54082084	0.085284017	2866.4883
195.7019	0.54482657	0.086604662	2869.6584
196.70288	0.54743212	0.087854393	2878.2473
197.70386	0.54948986	0.089382969	2880.6125
198.70483	0.55263227	0.091004804	2879.1299
199.70581	0.55363846	0.092671134	2879.5657
200.70679	0.56089681	0.09399391	2880.9297
201.70776	0.55938947	0.09556096	2877.6892
202.70874	0.56547737	0.097124927	2886.6636
203.70972	0.56783682	0.098473154	2888.0884
204.71069	0.57213742	0.09997651	2887.7422
205.71167	0.5742324	0.10158175	2893.6018
206.71265	0.57675421	0.10300979	2894.0378
207.71362	0.57985258	0.10427949	2893.667
208.7146	0.58349568	0.1056298	2895.3181
209.71558	0.59029692	0.10723754	2903.7078
210.71655	0.59102654	0.1083552	2898.429
211.71753	0.59507573	0.10966629	2900.6885
212.71851	0.59630078	0.11091495	2902.8884
213.71948	0.5981921	0.1123327	2907.3315
214.72046	0.60053504	0.11361441	2906.405
215.72144	0.60241646	0.11534518	2908.0154
216.72241	0.60745347	0.11664473	2908.9355
217.72339	0.6105082	0.11770182	2903.3042
218.72437	0.61390215	0.11904389	2909.4331
219.72534	0.61549264	0.12059785	2916.3228
220.72632	0.61696112	0.12229226	2910.4131
221.72729	0.6227513	0.12360483	2915.5237
222.72827	0.6276077	0.12506877	2919.5879
223.72925	0.62893564	0.1264164	2920.2771
224.73022	0.63366348	0.12775505	2919.2834
225.7312	0.63544065	0.12939686	2924.7466
226.73218	0.63842994	0.13092729	2929.2605
227.73315	0.63932246	0.13241164	2924.1125
228.73413	0.6443224	0.13357174	2926.5327
229.73511	0.64341265	0.13495959	2933.1414
230.73608	0.64997667	0.13655522	2928.7407
231.73706	0.65307564	0.13811573	2939.0759
232.73804	0.65304756	0.13968018	2939.7588
233.73901	0.65761167	0.14125477	2935.6079
234.73999	0.66343111	0.14287636	2939.0916
235.74097	0.66447639	0.14436762	2934.3586
236.74194	0.66953307	0.14602417	2944.3669
237.74292	0.67063069	0.14780082	2942.8489
238.7439	0.67346227	0.14937489	2942.6899
239.74487	0.67965132	0.15074658	2944.728
240.74585	0.67978162	0.15197863	2943.771
241.74683	0.68417299	0.15338613	2951.4731
242.7478	0.68313807	0.15475072	2947.0815
243.74878	0.6893698	0.15646526	2954.5315
244.74976	0.69070649	0.1578723	2949.1245
245.75073	0.69603723	0.15909438	2949.5466
246.75171	0.69748503	0.16026372	2950.3311
247.75269	0.70002425	0.16196947	2959.3245
248.75366	0.70295554	0.16345796	2957.3167
249.75464	0.70524681	0.16492905	2958.8987
250.75562	0.71105498	0.16681354	2966.2065
251.75659	0.71448898	0.16828759	2958.2354
252.75757	0.7146998	0.16981395	2968.3479
253.75854	0.71580434	0.17167005	2964.9497
254.75952	0.72101915	0.17326142	2960.0432
255.7605	0.72382528	0.17498562	2967.7158
256.76147	0.72789216	0.17625806	2964.0139
257.76245	0.73037332	0.17748192	2959.6963
258.76343	0.73419654	0.17887466	2975.2134
259.7644	0.73830336	0.18048295	2978.6106
260.76538	0.74257606	0.18183272	2976.9253
261.76636	0.74294287	0.18336602	2977.1948
262.76733	0.74613273	0.1852186	2979.4458
263.76831	0.75069809	0.18641809	2972.6211
264.76929	0.75074703	0.18797576	2978.4011
265.77026	0.75432074	0.18955538	2981.6179
266.77124	0.75975084	0.19090037	2979.0266
267.77222	0.75922185	0.19239655	2983.3601
268.77319	0.76295573	0.19400401	2986.0188
269.77417	0.76477206	0.19572344	2980.8184
270.77515	0.76936853	0.19723058	2987.2161
271.77612	0.7709552	0.19907735	2984.6045
272.7771	0.77597189	0.20056249	2989.8208
273.77808	0.77664411	0.20215526	2990.0464
274.77905	0.78488994	0.2039614	2994.446
275.78003	0.78543037	0.2054687	2996.8518
276.78101	0.78559405	0.20733507	2993.4756
277.78198	0.79266196	0.20895924	2998.542
278.78296	0.79372227	0.21059462	2996.1851
279.78394	0.79666996	0.21211518	2993.926
280.78491	0.79882354	0.21329376	2994.5449
281.78589	0.80324113	0.2148311	2998.3376
282.78687	0.80654764	0.21615034	3002.0093
283.78784	0.80571455	0.21774986	3001.762
284.78882	0.80975598	0.21926418	3000.3115
285.78979	0.81799823	0.22065888	3003.8022
286.79077	0.81748235	0.22223216	3003.603
287.79175	0.82239497	0.22383521	3005.9775
288.79272	0.82393944	0.22521585	3007.8481
289.7937	0.82666749	0.2266385	3008.9312
290.79468	0.82905442	0.22786878	3005.0393
291.79565	0.8316682	0.2292905	3012.6541
292.79663	0.83733261	0.23088656	3015.3049
293.79761	0.83987808	0.23249607	3013.0825
294.79858	0.84290695	0.23385228	3017.4292
295.79956	0.8425377	0.2352605	3014.9001
296.80054	0.84830356	0.23681013	3023.3149
297.80151	0.8517217	0.23869811	3025.4895
298.80249	0.85184652	0.24014167	3019.124
299.80347	0.85813838	0.24184097	3021.8384
300.80444	0.85878789	0.24325508	3024.2776
301.80542	0.86256456	0.24469104	3022.7827
302.8064	0.86391646	0.24621333	3026.146
303.80737	0.86943305	0.24777177	3023.6611
304.80835	0.87086135	0.2493577	3027.1992
305.80933	0.87619913	0.25098523	3032.261
306.8103	0.87990308	0.25282243	3036.9365
307.81128	0.87956399	0.2542606	3030.8374
308.81226	0.88295281	0.25571561	3029.332
309.81323	0.88559103	0.25722465	3033.0144
310.81421	0.88832039	0.25855577	3032.2813
311.81519	0.8925212	0.26009828	3033.5691
312.81616	0.89589179	0.26133651	3036.3015
313.81714	0.89931381	0.26272658	3038.5674
314.81812	0.89844346	0.2646513	3044.0674
315.81909	0.9029727	0.26630509	3040.5188
316.82007	0.90750015	0.26810488	3046.2708
317.82104	0.91032696	0.26955712	3045.6328
318.82202	0.91518331	0.27095178	3042.8083
319.823	0.91979015	0.27245665	3049.6746
320.82397	0.92377466	0.27391058	3051.1221
321.82495	0.92342675	0.27536902	3047.9746
322.82593	0.9259004	0.27685016	3046.7832
323.8269	0.92979389	0.27850398	3051.3733
324.82788	0.93112671	0.2801486	3051.0122
325.82886	0.93773782	0.28153455	3052.4585
326.82983	0.9373309	0.28287962	3050.6755
327.83081	0.93925852	0.28439832	3052.5176
328.83179	0.94243556	0.28567895	3045.884
329.83276	0.94681787	0.28691301	3053.5916
330.83374	0.94995326	0.28834727	3056.8276
331.83472	0.95387423	0.28991076	3062.1104
332.83569	0.9545123	0.29187009	3061.511
333.83667	0.95851886	0.29343468	3060.0388
334.83765	0.96168542	0.29503301	3057.0627
335.83862	0.96527606	0.29661465	3065.0642
336.8396	0.96804291	0.29823747	3065.2317
337.84058	0.96999937	0.29982692	3059.3613
338.84155	0.9721632	0.30145442	3064.5735
339.84253	0.97511363	0.3032977	3061.3628
340.84351	0.97816825	0.30455226	3059.7974
341.84448	0.98318398	0.30609202	3074.3984
342.84546	0.98240912	0.3077302	3062.564
343.84644	0.99055606	0.30922422	3072.3096
344.84741	0.99307555	0.31073993	3075.1956
345.84839	0.99532342	0.31231365	3065.9839
346.84937	0.99821806	0.31370738	3067.7754
347.85034	0.99917656	0.31494612	3072.7954
348.85132	1.0023146	0.31659254	3074.6663
349.85229	1.0067616	0.31812167	3074.8269
350.85327	1.0081667	0.31951696	3079.8928
351.85425	1.0113124	0.32137761	3080.4836
352.85522	1.019807	0.32306111	3086.6836
353.8562	1.0182357	0.32462448	3083.9104
354.85718	1.0193634	0.32608426	3082.8088
355.85815	1.022724	0.32760677	3077.6833
356.85913	1.0265529	0.32897049	3080.8491
357.86011	1.0295484	0.33028933	3083.2715
358.86108	1.0346723	0.33182997	3087.9285
359.86206	1.0359507	0.33332941	3086.3337
360.86304	1.0411353	0.33482301	3086.1006
361.86401	1.0420589	0.33613899	3092.2358
362.86499	1.0452857	0.33780843	3095.6609
363.86597	1.0493776	0.33942622	3088.459
364.86694	1.0538112	0.34073827	3093.8848
365.86792	1.0529746	0.34252352	3091.9023
366.8689	1.0550576	0.34401557	3094.5542
367.86987	1.0602973	0.3455416	3092.6487
368.87085	1.0630327	0.34709814	3097.9453
369.87183	1.0671562	0.34875697	3100.0852
370.8728	1.0724344	0.3503966	3101.4758
371.87378	1.0736116	0.35176578	3096.3154
372.87476	1.0752026	0.35321674	3096.9775
373.87573	1.0799205	0.35483676	3101.5879
374.87671	1.0797544	0.35634574	3094.8479
375.87769	1.0865251	0.35772067	3103.8604
376.87866	1.0878327	0.35925859	3103.1167
377.87964	1.092616	0.36110902	3112.2771
378.88062	1.0948392	0.36255243	3102.158
379.88159	1.0953811	0.36398336	3107.3276
380.88257	1.1011084	0.36549714	3107.1724
381.88354	1.1025591	0.36699349	3105.1182
382.88452	1.1039605	0.36834154	3104.033
383.8855	1.1095673	0.36995098	3110.019
384.88647	1.1114955	0.37156802	3109.9131
385.88745	1.1167259	0.37297294	3111.6216
386.88843	1.1154361	0.37439629	3114.0681
387.8894	1.1196882	0.37595123	3116.3125
388.89038	1.1215121	0.3777867	3119.7966
389.89136	1.1263046	0.37944376	3119.8726
390.89233	1.1291046	0.38083905	3114.6135
391.89331	1.1317968	0.38226315	3118.3428
392.89429	1.1359093	0.38358173	3116.9688
393.89526	1.1407776	0.38493565	3120.6868
394.89624	1.1404409	0.3864201	3118.8552
395.89722	1.1457419	0.3879815	3122.2268
396.89819	1.1475346	0.38927078	3125.2671
397.89917	1.1496747	0.39072478	3122.4041
398.90015	1.1544542	0.39203066	3120.8108
399.90112	1.1560067	0.39346939	3127.4727
400.9021	1.1610292	0.39502853	3126.6272
401.90308	1.1628741	0.39667866	3131.7546
402.90405	1.1654117	0.39851919	3134.1528
403.90503	1.1681306	0.39992008	3125.8013
404.90601	1.1691447	0.40152517	3130.3623
405.90698	1.1733915	0.40302765	3125.7117
406.90796	1.1796117	0.40450871	3138.3174
407.90894	1.1834376	0.40611511	3140.7786
408.90991	1.1815168	0.40783599	3132.325
409.91089	1.1883265	0.40924734	3132.0286
410.91187	1.1889384	0.41052195	3135.5854
411.91284	1.1906452	0.4118138	3132.1702
412.91382	1.1958133	0.41340736	3143.0566
413.91479	1.1986821	0.41517368	3139.0667
414.91577	1.199924	0.41683829	3139.4197
415.91675	1.2077804	0.41872814	3152.9043
416.91772	1.2087067	0.42028552	3144.8328
417.9187	1.2108022	0.42167675	3142.4299
418.91968	1.2126234	0.42321783	3136.814
419.92065	1.2154248	0.42482615	3141.1934
420.92163	1.2197485	0.42640877	3148.4744
421.92261	1.2246772	0.42783695	3147.5
422.92358	1.223772	0.42940935	3146.7151
423.92456	1.2270006	0.43099993	3151.179
424.92554	1.230019	0.43232903	3148.5181
425.92651	1.2347134	0.43373555	3145.3228
426.92749	1.2362124	0.43517023	3150.5298
427.92847	1.2431161	0.43643305	3150.3306
428.92944	1.2461057	0.43808001	3158.0171
429.93042	1.2500156	0.43980205	3158.1499
430.9314	1.2508855	0.44146544	3153.0457
431.93237	1.2545304	0.44294664	3158.0002
432.93335	1.2571987	0.44426692	3154.322
433.93433	1.2621361	0.44549426	3156.3054
434.9353	1.2645605	0.44702169	3158.2039
435.93628	1.2652992	0.44845882	3153.9353
436.93726	1.267885	0.44992456	3156.6196
437.93823	1.2718134	0.45129794	3157.7698
438.93921	1.2732199	0.45263222	3164.8528
439.94019	1.2770203	0.4542492	3164.7349
440.94116	1.2782627	0.45587212	3158.395
441.94214	1.2853615	0.45721388	3163.167
442.94312	1.2875319	0.45868617	3160.7234
443.94409	1.2867963	0.46016788	3161.0371
444.94507	1.2909529	0.46178854	3165.5457
445.94604	1.2964724	0.4631997	3164.0059
446.94702	1.2989028	0.46436685	3163.323
447.948	1.3015832	0.46576837	3167.1621
448.94897	1.3035079	0.46728334	3169.9998
449.94995	1.3055462	0.46916541	3174.1079
450.95093	1.3086289	0.47080159	3174.0286
451.9519	1.3131232	0.4725014	3172.739
452.95288	1.3151782	0.47422919	3172.4963
453.95386	1.3212069	0.47603545	3170.6511
454.95483	1.3232628	0.47762376	3174.0718
455.95581	1.3246081	0.47895959	3174.7107
456.95679	1.3266168	0.48048335	3175.4246
457.95776	1.3287526	0.48196447	3182.459
458.95874	1.3349671	0.48356467	3177.9302
459.95972	1.339517	0.48463833	3175.2141
460.96069	1.3388718	0.48623466	3181.2781
461.96167	1.3450843	0.48755339	3179.7007
462.96265	1.3493171	0.48883468	3179.8606
463.96362	1.3490255	0.4906334	3186.0359
464.9646	1.352879	0.49227995	3177.488
465.96558	1.3525521	0.49384564	3178.96
466.96655	1.3590268	0.49514273	3183.9768
467.96753	1.3612213	0.49638712	3182.2605
468.96851	1.3649822	0.4979659	3189.1379
469.96948	1.3655387	0.49925837	3183.3115
470.97046	1.3706372	0.50096124	3187.6594
471.97144	1.3734269	0.50260597	3188.1953
472.97241	1.3766674	0.50419426	3185.5061
473.97339	1.3780406	0.50561923	3188.178
474.97437	1.3824054	0.5072245	3187.9189
475.97534	1.3857504	0.50858414	3184.5898
476.97632	1.3883307	0.50999957	3192.845
477.97729	1.3929515	0.51194686	3199.1589
478.97827	1.3965926	0.51344013	3190.387
479.97925	1.395318	0.51496118	3192.145
480.98022	1.4022404	0.51675344	3199.5742
481.9812	1.4038291	0.51839262	3199.6643
482.98218	1.4043875	0.5200156	3194.8818
483.98315	1.4079379	0.52153826	3195.2236
484.98413	1.4142638	0.52346087	3202.7847
485.98511	1.4134268	0.52520508	3196.4807
486.98608	1.420756	0.526658	3196.6338
487.98706	1.4219604	0.52808666	3199.7517
488.98804	1.4237549	0.52979892	3201.1941
489.98901	1.4286301	0.53104699	3204.9724
490.98999	1.42968	0.53241521	3202.8433
491.99097	1.4347343	0.53407723	3207.322
492.99194	1.4352108	0.53564656	3204.9763
493.99292	1.4405293	0.53714663	3206.0554
494.9939	1.4436576	0.53838152	3209.8445
495.99487	1.4440514	0.53995287	3203.2322
496.99585	1.4492325	0.54142064	3213.5491
497.99683	1.4509155	0.54280823	3208.1938
498.9978	1.4540114	0.54435551	3211.2234
499.99878	1.4580897	0.54579967	3205.9097
500.99976	1.4605831	0.54740173	3205.1172
502.00073	1.4643543	0.54879576	3211.2727
503.00171	1.465271	0.55020052	3209.9626
504.00269	1.47042	0.55175722	3207.8774
505.00366	1.4730481	0.5532797	3213.1919
506.00464	1.473878	0.55487037	3209.8662
507.00562	1.4783909	0.55641633	3217.9922
508.00659	1.4803247	0.55814499	3214.0095
509.00757	1.4846249	0.55980229	3217.9602
510.00854	1.4868187	0.56137991	3218.1458
511.00952	1.4901412	0.56286901	3213.7686
512.0105	1.4955322	0.56421322	3223.1252
513.01147	1.4958032	0.56575418	3211.8872
514.01245	1.5007207	0.5671013	3220.0947
515.01343	1.5011595	0.56873894	3217.6677
516.0144	1.5063726	0.56998527	3218.5837
517.01538	1.5092663	0.57173079	3226.197
518.01636	1.5088353	0.57327068	3220.3833
519.01733	1.5132806	0.57468051	3220.2424
520.01831	1.519628	0.57625097	3220.947
521.01929	1.5204655	0.5778929	3228.5491
522.02026	1.5266715	0.57980371	3235.7922
523.02124	1.5261267	0.58129978	3221.1028
524.02222	1.5283797	0.5827567	3219.7339
525.02319	1.5317911	0.58399993	3216.9941
526.02417	1.5340189	0.58539081	3227.4863
527.02515	1.5359751	0.58727038	3233.1038
528.02612	1.5390011	0.58915287	3228.2495
529.0271	1.5443083	0.59074956	3231.1465
530.02808	1.5476441	0.59229565	3231.9006
531.02905	1.550993	0.5941208	3235.0015
532.03003	1.5550263	0.59556991	3230.719
533.03101	1.5576042	0.59684741	3235.6609
534.03198	1.5573691	0.59848237	3231.9653
535.03296	1.5634569	0.60007817	3238.6414
536.03394	1.5647632	0.60140222	3234.8516
537.03491	1.5687517	0.6028446	3234.7654
538.03589	1.5724355	0.60436195	3237.0198
539.03687	1.5747869	0.60605407	3237.9102
540.03784	1.5803491	0.60753047	3238.6841
541.03882	1.5818146	0.60909814	3238.1521
542.03979	1.5835884	0.6104635	3237.2266
543.04077	1.5911055	0.61194611	3244.9048
544.04175	1.5900754	0.61330032	3244.3291
545.04272	1.5944003	0.61474252	3234.615
546.0437	1.5937324	0.61639893	3235.3799
547.04468	1.5974079	0.618137	3242.9534
548.04565	1.6039774	0.62006003	3243.4692
549.04663	1.6038563	0.62172014	3240.2495
550.04761	1.6114397	0.62316716	3243.4827
551.04858	1.6096119	0.62470734	3242.2324
552.04956	1.6143919	0.62621784	3240.2937
553.05054	1.620119	0.62793547	3247.0161
554.05151	1.6187358	0.6293292	3249.9063
555.05249	1.6235632	0.63099861	3250.5051
556.05347	1.6271986	0.63260931	3253.1704
557.05444	1.6277272	0.63413286	3247.3225
558.05542	1.6325227	0.63581502	3248.8601
559.0564	1.6369501	0.63768375	3249.9631
560.05737	1.6415118	0.63944352	3255.1638
561.05835	1.6380775	0.64089692	3248.4944
562.05933	1.6453184	0.64263517	3252.2009
563.0603	1.6474282	0.64425194	3253.2627
564.06128	1.6517003	0.64576769	3249.5088
565.06226	1.6524256	0.64723676	3252.8733
566.06323	1.6541013	0.64868867	3249.9551
567.06421	1.6560698	0.65028358	3255.9841
568.06519	1.6641055	0.65189725	3258.9204
569.06616	1.6634617	0.65376025	3252.9333
570.06714	1.6643336	0.65560687	3254.8545
571.06812	1.6703372	0.65724111	3256.2844
572.06909	1.6728653	0.65886563	3260.6975
573.07007	1.6767046	0.66031188	3255.6121
574.07104	1.6767635	0.66172278	3252.7395
575.07202	1.6799315	0.66297269	3246.2126
576.073	1.6860458	0.66448563	3252.6196
577.07397	1.6874768	0.66589445	3257.0166
578.07495	1.6911881	0.66736215	3258.8149
579.07593	1.6971041	0.6689449	3262.0891
580.0769	1.6966854	0.67045099	3262.2378
581.07788	1.7017978	0.67203528	3260.1807
582.07886	1.7035453	0.6736781	3260.583
583.07983	1.7059433	0.67531639	3258.0247
584.08081	1.7108611	0.67719036	3264.5105
585.08179	1.7127632	0.67869282	3269.3818
586.08276	1.7156498	0.68068904	3265.729
587.08374	1.7182789	0.68258405	3265.9492
588.08472	1.7223899	0.68392718	3259.7627
589.08569	1.7248287	0.68535125	3266.7937
590.08667	1.7246784	0.68687844	3262.3379
591.08765	1.7291701	0.68829572	3261.6687
592.08862	1.7335815	0.68964463	3271.1169
593.0896	1.738097	0.69138259	3270.5896
594.09058	1.739395	0.69296253	3269.0349
595.09155	1.741135	0.69465768	3261.2129
596.09253	1.7449903	0.69615775	3265.0342
597.09351	1.7492088	0.69797343	3271.71
598.09448	1.7505331	0.69937301	3268.8713
599.09546	1.753768	0.70101929	3273.396
600.09644	1.7570211	0.70290834	3272.353
601.09741	1.7584448	0.70476389	3267.8877
602.09839	1.7643913	0.70673901	3271.2891
603.09937	1.7685651	0.7084161	3275.7227
604.10034	1.7698727	0.71012306	3277.4836
605.10132	1.7711672	0.71165419	3271.7454
606.10229	1.7755684	0.71329778	3269.9561
607.10327	1.7768575	0.71476638	3266.2686
608.10425	1.7826161	0.7160036	3270.2666
609.10522	1.7833556	0.7175355	3279.8496
610.1062	1.7862371	0.71901351	3274.5723
611.10718	1.7907606	0.72071779	3279.8625
612.10815	1.793401	0.72211373	3274.3853
613.10913	1.7945411	0.72366822	3276.1721
614.11011	1.7997272	0.72555035	3279.3198
615.11108	1.8030602	0.72744185	3279.6228
616.11206	1.8031554	0.72917068	3277.7639
617.11304	1.8083874	0.73061836	3279.8787
618.11401	1.8104699	0.73223978	3276.4597
619.11499	1.8164502	0.73358971	3278.0671
620.11597	1.8156657	0.73490977	3276.2124
621.11694	1.8248795	0.73683417	3289.2268
622.11792	1.8259152	0.73852205	3282.0886
623.1189	1.827763	0.74030167	3284.103
624.11987	1.8328393	0.74201053	3286.1008
625.12085	1.835696	0.74362451	3284.3342
626.12183	1.8362281	0.74529642	3284.0205
627.1228	1.8374203	0.74678826	3279.5027
628.12378	1.8436918	0.74854964	3291.8008
629.12476	1.8445246	0.7503289	3289.6729
630.12573	1.8457854	0.75212586	3285.1187
631.12671	1.8524604	0.75372398	3285.3909
632.12769	1.8557166	0.75579661	3291.1631
633.12866	1.8565189	0.75739372	3287.979
634.12964	1.8598397	0.75900882	3283.6497
635.13062	1.8599999	0.76047719	3283.2488
636.13159	1.8656981	0.76193416	3287.418
637.13257	1.8689802	0.76364052	3288.1213
638.13354	1.8706601	0.76518863	3284.4465
639.13452	1.8763233	0.76707596	3292.2383
640.1355	1.8759022	0.7688843	3294.3145
641.13647	1.8816983	0.77055693	3288.2861
642.13745	1.8850797	0.77224773	3288.4551
643.13843	1.8897743	0.77395058	3286.3848
644.1394	1.8910534	0.77568972	3300.6563
645.14038	1.8899368	0.77708733	3287.7722
646.14136	1.8987833	0.77926087	3300.5911
647.14233	1.900914	0.78123981	3294.8884
648.14331	1.9040527	0.78318924	3295.6709
649.14429	1.9042263	0.78507775	3291.8159
650.14526	1.9056849	0.78668004	3291.2842
651.14624	1.9090239	0.78824335	3286.9966
652.14722	1.9149503	0.78989369	3297.5793
653.14819	1.9150726	0.79159367	3292.8779
654.14917	1.92345	0.79311395	3293.3208
655.15015	1.9217089	0.7945624	3293.1235
656.15112	1.927279	0.79628944	3288.6892
657.1521	1.9290388	0.79807866	3296.6013
658.15308	1.9301207	0.80003858	3295.7573
659.15405	1.9344773	0.80154788	3299.5535
660.15503	1.9388298	0.80306685	3293.6138
661.15601	1.9420367	0.80452889	3293.6704
662.15698	1.9429014	0.80636609	3294.8748
663.15796	1.9487559	0.80820245	3299.7021
664.15894	1.952059	0.81007147	3303.8977
665.15991	1.9508358	0.81193286	3299.116
666.16089	1.956401	0.813564	3300.7036
667.16187	1.9603943	0.81518054	3296.686
668.16284	1.960198	0.81712991	3299.9675
669.16382	1.9650033	0.81891125	3298.8687
670.16479	1.9657683	0.82055598	3296.2656
671.16577	1.9702964	0.82243359	3302.4756
672.16675	1.9753131	0.82413912	3299.7617
673.16772	1.979147	0.82598591	3301.4578
674.1687	1.9793063	0.82770574	3296.2175
675.16968	1.9828155	0.82945156	3303.0244
676.17065	1.9845115	0.83143908	3305.5571
677.17163	1.9867864	0.83329624	3295.1641
678.17261	1.9921209	0.83498555	3302.4502
679.17358	1.9949718	0.83659166	3297.3762
680.17456	1.9993813	0.83832008	3308.5535
681.17554	2.0016091	0.84007257	3302.7542
682.17651	2.0040743	0.84164888	3305.7942
683.17749	2.0071645	0.84361386	3309.2175
684.17847	2.0116045	0.84520388	3302.3389
685.17944	2.0130417	0.84675431	3301.8406
686.18042	2.0177288	0.84862822	3309.0608
687.1814	2.018424	0.85040778	3303.1423
688.18237	2.0220523	0.85202479	3298.4893
689.18335	2.0249629	0.85407668	3308.0381
690.18433	2.0264726	0.85593432	3302.365
691.1853	2.0273602	0.85781574	3301.3376
692.18628	2.0334828	0.8594774	3301.0437
693.18726	2.0393326	0.86130214	3310.3796
694.18823	2.0385072	0.86321056	3309.8687
695.18921	2.0429111	0.86529833	3306.0098
696.19019	2.0451503	0.86714858	3302.8413
697.19116	2.0506363	0.86883885	3304.9253
698.19214	2.051816	0.87056118	3309.1973
699.19312	2.0573912	0.87237823	3309.4075
700.19409	2.058419	0.87412316	3310.3196
701.19507	2.060504	0.87596369	3310.501
702.19604	2.0642743	0.87813807	3311.8608
703.19702	2.0667987	0.88018304	3308.5359
704.198	2.0664513	0.88187081	3305.6602
705.19897	2.0715692	0.88384843	3312.1663
706.19995	2.0779791	0.88559145	3310.5283
707.20093	2.0782132	0.88723385	3312.5149
708.2019	2.0830784	0.88935018	3311.5256
709.20288	2.0830545	0.89136904	3311.0354
710.20386	2.0888128	0.89320838	3312.0593
711.20483	2.0896668	0.89477777	3309.1221
712.20581	2.0940006	0.89636785	3311.6975
713.20679	2.098068	0.8980723	3310.0571
714.20776	2.1020689	0.90010285	3319.2102
715.20874	2.1059999	0.90162688	3308.5061
716.20972	2.1064315	0.90319705	3314.5579
717.21069	2.1108327	0.90506816	3316.5708
718.21167	2.1071634	0.90671426	3307.043
719.21265	2.1139805	0.9088735	3311.8359
720.21362	2.1207085	0.9108659	3314.2349
721.2146	2.1213496	0.91274923	3312.4546
722.21558	2.1245916	0.91465068	3311.1707
723.21655	2.1294279	0.91672504	3314.0776
724.21753	2.1311545	0.91836655	3312.8333
725.21851	2.1325133	0.91997969	3313.1628
726.21948	2.1347032	0.92205977	3315.8167
727.22046	2.1378036	0.923989	3314.0605
728.22144	2.1427441	0.92582411	3315.1599
729.22241	2.1447051	0.92807752	3316.9097
730.22339	2.1469529	0.93005598	3311.7898
731.22437	2.1491673	0.93201071	3311.6819
732.22534	2.1561399	0.93378127	3315.0496
733.22632	2.1548588	0.93536317	3314.3723
734.22729	2.1617253	0.93727219	3315.6128
735.22827	2.1646392	0.93899798	3310.5212
736.22925	2.1672955	0.94058692	3312.9937
737.23022	2.1679146	0.9427377	3317.9958
738.2312	2.1724229	0.94496369	3318.5503
739.23218	2.1760685	0.94719297	3317.1758
740.23315	2.1786878	0.94919819	3316.5725
741.23413	2.1821246	0.95148909	3317.6765
742.23511	2.1855018	0.95336747	3318.2581
743.23608	2.1866603	0.95503217	3310.7151
744.23706	2.1891465	0.95682931	3316.5891
745.23804	2.192811	0.95889932	3322.416
746.23901	2.1951027	0.9609158	3318.6055
747.23999	2.1980166	0.96296233	3314.6101
748.24097	2.2028193	0.96508551	3314.3506
749.24194	2.2039275	0.96715295	3318.0176
750.24292	2.2095172	0.96918106	3314.2183
751.2439	2.2101867	0.97123897	3316.1375
752.24487	2.2118883	0.97311449	3312.6687
753.24585	2.2180607	0.9751175	3318.3962
754.24683	2.2194092	0.97706032	3318.5339
755.2478	2.2226262	0.97907048	3319.6133
756.24878	2.2272677	0.98111326	3319.3132
757.24976	2.2297218	0.98281473	3316.7361
758.25073	2.2332146	0.9851895	3320.9836
759.25171	2.2358384	0.98741376	3321.3367
760.25269	2.240927	0.98923457	3317.1714
761.25366	2.2411957	0.99128681	3320.1262
762.25464	2.2430303	0.99314374	3312.0696
763.25562	2.2498233	0.99496013	3316.1921
764.25659	2.2485464	0.99676532	3315.9434
765.25757	2.2541606	0.99906343	3317.9976
766.25854	2.256144	1.0011495	3318.8938
767.25952	2.2625821	1.0032246	3324.6606
768.2605	2.2620881	1.0055619	3318.9875
769.26147	2.2643745	1.0079066	3319.1924
770.26245	2.2673028	1.0103219	3319.0427
771.26343	2.2726014	1.0128511	3326.0476
772.2644	2.27545	1.01533	3320.8372
773.26538	2.2759974	1.0176172	3320.4509
774.26636	2.2818334	1.0197687	3319.5676
775.26733	2.2826962	1.021549	3312.5771
776.26831	2.2860255	1.0233649	3314.6797
777.26929	2.2906251	1.0255728	3324.6733
778.27026	2.2928946	1.0275706	3313.886
779.27124	2.2971957	1.0294625	3320.4341
780.27222	2.2994518	1.031505	3320.0559
781.27319	2.3011928	1.0336031	3319.8496
782.27417	2.3066978	1.0354519	3315.9592
783.27515	2.3093731	1.0377051	3325.7454
784.27612	2.3098385	1.0399649	3323.27
785.2771	2.3126876	1.0419095	3311.2258
786.27808	2.3156457	1.0439347	3321.4478
787.27905	2.3214421	1.0459042	3321.1445
788.28003	2.3190742	1.0481546	3318.0288
789.28101	2.3253191	1.0503	3317.4287
790.28198	2.3295486	1.0523989	3318.9143
791.28296	2.3308418	1.0545071	3316.8264
792.28394	2.3349488	1.0563691	3312.2327
793.28491	2.3360031	1.0583986	3323.0037
794.28589	2.3373055	1.0607082	3320.5645
795.28687	2.3450692	1.0626955	3318.3975
796.28784	2.3478804	1.065135	3321.0498
797.28882	2.3523393	1.067536	3323.2561
798.28979	2.3520291	1.0699874	3314.3408
799.29077	2.3562417	1.0723891	3318.3013
800.29175	2.3590941	1.0747222	3313.2844
801.29272	2.3609154	1.076666	3312.501
802.2937	2.3636134	1.0789107	3317.7092
803.29468	2.3639646	1.0809478	3310.3623
804.29565	2.3710458	1.0830255	3319.8335
805.29663	2.3743708	1.0853003	3321.0144
806.29761	2.3748779	1.0875485	3317.1096
807.29858	2.3789222	1.0899934	3316.678
808.29956	2.3824971	1.0925452	3321.7205
809.30054	2.385628	1.0949563	3314.543
810.30151	2.3899174	1.0972919	3319.6133
811.30249	2.393131	1.0997663	3317.1062
812.30347	2.3922763	1.1023251	3316.2329
813.30444	2.3972044	1.1048051	3313.8994
814.30542	2.3999944	1.1071	3310.3142
815.3064	2.4035096	1.1092211	3315.5342
816.30737	2.4072742	1.1112982	3318.8157
817.30835	2.4094501	1.1137247	3313.668
818.30933	2.4129169	1.1160699	3306.4597
819.3103	2.4162753	1.1186037	3322.8323
820.31128	2.4216383	1.1207795	3314.6973
821.31226	2.4214292	1.1231394	3314.2285
822.31323	2.4240856	1.1254449	3314.509
823.31421	2.4267344	1.1276034	3309.8018
824.31519	2.4304125	1.1301236	3315.812
825.31616	2.4346073	1.1324676	3307.9534
826.31714	2.4346595	1.1348137	3314.3015
827.31812	2.4409659	1.1372112	3314.4849
828.31909	2.4402096	1.1393874	3311.4419
829.32007	2.4455221	1.1419307	3318.9758
830.32104	2.4490821	1.1443982	3311.1875
831.32202	2.4528544	1.146531	3313.2773
832.323	2.4579964	1.149125	3321.3975
833.32397	2.4575241	1.1515167	3314.27
834.32495	2.4593368	1.1537848	3309.488
835.32593	2.4650054	1.1565385	3316.1165
836.3269	2.4670496	1.1594049	3312.1079
837.32788	2.4685621	1.1614512	3301.5762
838.32886	2.4720743	1.1635193	3305.5496
839.32983	2.4751327	1.1658769	3313.7563
840.33081	2.4795854	1.1686654	3312.3276
841.33179	2.4811547	1.1712031	3308.4607
842.33276	2.4823194	1.1738999	3311.3484
843.33374	2.4863443	1.1763711	3304.7373
844.33472	2.4909739	1.1790329	3308.6531
845.33569	2.4950902	1.1817157	3310.6436
846.33667	2.4970405	1.1840371	3300.4392
847.33765	2.4988487	1.186377	3310.6079
848.33862	2.5014217	1.1886882	3305.2285
849.3396	2.5031357	1.1910237	3309.0188
850.34058	2.5066562	1.1936877	3307.5779
851.34155	2.5118301	1.1963636	3307.8103
852.34253	2.5153048	1.199065	3306.4443
853.34351	2.5164366	1.2015769	3299.6182
854.34448	2.5197074	1.2040048	3300.7939
855.34546	2.524482	1.2063125	3306.0022
856.34644	2.525542	1.2091236	3301.5837
857.34741	2.5330648	1.2119794	3312.6221
858.34839	2.5344329	1.2148156	3305.7439
859.34937	2.5350869	1.2175746	3300.2803
860.35034	2.5389204	1.2200205	3296.3438
861.35132	2.5437691	1.2221999	3305.5557
862.35229	2.546087	1.2244674	3302.8379
863.35327	2.5474524	1.2266482	3304.1741
864.35425	2.5492887	1.2292758	3301.6147
865.35522	2.5549603	1.2319961	3299.301
866.3562	2.5559242	1.2348331	3296.7188
867.35718	2.5607109	1.2372054	3302.2566
868.35815	2.560586	1.2399826	3297.5813
869.35913	2.5658929	1.2425523	3303.165
870.36011	2.5672772	1.245405	3294.7283
871.36108	2.5713153	1.2479763	3295.3152
872.36206	2.576324	1.2505615	3292.8574
873.36304	2.5774212	1.2527652	3289.502
874.36401	2.5810871	1.2557323	3302.8433
875.36499	2.5814538	1.2587377	3296.3689
876.36597	2.5866525	1.2616704	3295.751
877.36694	2.5883842	1.2641521	3293.0403
878.36792	2.5944285	1.266978	3290.0474
879.3689	2.5963504	1.2695007	3293.0947
880.36987	2.6011748	1.2724828	3295.4131
881.37085	2.60274	1.2753583	3290.7393
882.37183	2.6052735	1.2782102	3290.8
883.3728	2.6098335	1.2806211	3289.7793
884.37378	2.6111033	1.2831147	3284.4414
885.37476	2.6121345	1.2858716	3283.5935
886.37573	2.6200297	1.2886351	3288.071
887.37671	2.6189196	1.2917845	3283.4407
888.37769	2.6233642	1.2945747	3288.219
889.37866	2.6266096	1.2972009	3280.9773
890.37964	2.6322293	1.299598	3282.8174
891.38062	2.6326077	1.3020935	3283.5171
892.38159	2.63486	1.3050852	3289.335
893.38257	2.6370351	1.3080605	3278.561
894.38354	2.6396606	1.3108497	3281.9319
895.38452	2.6442938	1.3134927	3279.7415
896.3855	2.6461608	1.3160272	3277.825
897.38647	2.6498995	1.3190769	3276.6318
898.38745	2.6513338	1.322129	3275.5669
899.38843	2.6560669	1.3249222	3272.2366
900.3894	2.6576445	1.3280276	3275.9421
901.39038	2.6625171	1.3313577	3274.6121
902.39136	2.6636581	1.3341379	3271.3
903.39233	2.666476	1.3370986	3269.6091
904.39331	2.6683631	1.3394903	3269.6021
905.39429	2.6723425	1.342581	3272.5974
906.39526	2.6776185	1.3451371	3272.666
907.39624	2.6792893	1.3482168	3271.6995
908.39722	2.6812694	1.3514301	3264.6282
909.39819	2.6868494	1.3538704	3268.4612
910.39917	2.6873188	1.3567283	3264.6499
911.40015	2.6969559	1.3597641	3269.6104
912.40112	2.6937091	1.3623363	3262.7229
913.4021	2.6958587	1.3652925	3262.5042
914.40308	2.7021251	1.3681874	3257.2949
915.40405	2.7026565	1.3715371	3259.7634
916.40503	2.7057602	1.3745986	3261.2229
917.40601	2.7093723	1.3778559	3255.3557
918.40698	2.7150433	1.3805878	3256.9004
919.40796	2.7142212	1.3836626	3258.1208
920.40894	2.7205918	1.3868129	3255.1907
921.40991	2.7211549	1.3892279	3244.658
922.41089	2.726675	1.3923135	3255.5005
923.41187	2.7303405	1.3954186	3247.1697
924.41284	2.7275786	1.3988544	3245.1121
925.41382	2.7318242	1.4012227	3241.7759
926.41479	2.7360418	1.4041662	3244.6421
927.41577	2.7399135	1.4069209	3242.8472
928.41675	2.7417948	1.4091842	3241.3359
929.41772	2.7453637	1.4122012	3240.1221
930.4187	2.7476702	1.4152441	3241.5996
931.41968	2.7530758	1.4180211	3234.6355
932.42065	2.7547233	1.4206946	3245.6489
933.42163	2.7570004	1.4235679	3230.1343
934.42261	2.7634168	1.4259747	3237.1572
935.42358	2.763823	1.4285002	3236.345
936.42456	2.7643311	1.4322551	3237.0232
937.42554	2.7714252	1.4353614	3238.1279
938.42651	2.7724233	1.4381636	3234.5798
939.42749	2.7761185	1.4412932	3229.7495
940.42847	2.7800012	1.4449772	3234.4263
941.42944	2.7804456	1.4486314	3227.8101
942.43042	2.7844446	1.4515704	3216.707
943.4314	2.7881644	1.454625	3220.6523
944.43237	2.7900615	1.457629	3216.665
945.43335	2.7942173	1.4604871	3217.1838
946.43433	2.7960606	1.463071	3211.2654
947.4353	2.8007214	1.4658771	3217.1143
948.43628	2.8035467	1.4692677	3211.7478
949.43726	2.8045657	1.4718591	3207.9536
950.43823	2.8079872	1.4750813	3218.4026
951.43921	2.8139508	1.4783955	3211.0298
952.44019	2.8128307	1.482042	3205.4568
953.44116	2.8224587	1.4852123	3208.7209
954.44214	2.8204224	1.48842	3202.3191
955.44312	2.8233252	1.4913313	3194.2808
956.44409	2.8264472	1.4941308	3199.03
957.44507	2.8313396	1.4971802	3202.0698
958.44604	2.8327229	1.5002669	3199.449
959.44702	2.8359406	1.5035146	3191.8391
960.448	2.8395476	1.5066758	3192.512
961.44897	2.8438587	1.510342	3192.3008
962.44995	2.8470843	1.5136213	3194.8123
963.45093	2.8513823	1.5166326	3185.0356
964.4519	2.8499715	1.5194172	3182.4709
965.45288	2.8556364	1.5223798	3185.291
966.45386	2.8546171	1.5253817	3182.5027
967.45483	2.8589671	1.5286552	3173.8528
968.45581	2.8612266	1.5314653	3173.5034
969.45679	2.8639674	1.5340217	3169.1421
970.45776	2.8665521	1.5366521	3169.4866
971.45874	2.8726585	1.539765	3170.0391
972.45972	2.875643	1.5425978	3171.5083
973.46069	2.8783312	1.5456959	3169.6973
974.46167	2.8834224	1.5489651	3172.1807
975.46265	2.8851078	1.5521569	3165.5784
976.46362	2.8818622	1.5555701	3159.1094
977.4646	2.8916373	1.5587845	3158.6667
978.46558	2.8938911	1.5617945	3153.0076
979.46655	2.8955026	1.5646793	3155.1382
980.46753	2.8972154	1.5680234	3152.5142
981.46851	2.9009249	1.5711139	3145.554
982.46948	2.9043133	1.5747502	3150.8992
983.47046	2.9094565	1.5779589	3146.4275
984.47144	2.9130085	1.5815254	3149.4805
985.47241	2.915122	1.5850838	3137.3433
986.47339	2.915077	1.5880609	3136.4534
987.47437	2.9189408	1.5912282	3132.0747
988.47534	2.9257925	1.5945866	3133.5701
989.47632	2.9256182	1.5974336	3127.2507
990.47729	2.9297686	1.6010238	3132.4167
991.47827	2.9333827	1.6040791	3126.9285
992.47925	2.9350121	1.6073054	3119.2253
993.48022	2.9397655	1.6106116	3119.3936
994.4812	2.9420376	1.6141119	3117.9417
995.48218	2.9448268	1.6169138	3113.4399
996.48315	2.9455609	1.6196418	3106.1431
997.48413	2.9493265	1.6226052	3114.5259
998.48511	2.9527586	1.6259807	3110.0269
999.48608	2.9527056	1.6292137	3101.7012
1000.4871	2.9593117	1.6324617	3103.2065
1001.488	2.9650009	1.6355064	3098.874
1002.489	2.9679325	1.6384575	3096.3672
1003.49	2.9700768	1.641041	3091.4211
1004.491	2.970273	1.6439127	3086.7546
1005.4919	2.9722164	1.6466053	3089.2571
1006.4929	2.9801776	1.649773	3083.2251
1007.4939	2.9825227	1.6526781	3092.1064
1008.4949	2.9815462	1.6559812	3080.1157
1009.4958	2.9879503	1.6597351	3085.1099
1010.4968	2.9888813	1.6637387	3079.8091
1011.4978	2.9909382	1.6671739	3071.335
1012.4988	2.994494	1.6701213	3060.6938
1013.4998	2.999542	1.6733972	3066.2148
1014.5007	3.0009203	1.6767993	3073.1133
1015.5017	2.9995492	1.6795794	3051.9453
1016.5027	3.0073402	1.6818451	3048.6167
1017.5037	3.0094104	1.6841079	3052.3218
1018.5046	3.016937	1.6868542	3058.054
1019.5056	3.0173535	1.6896474	3056.9041
1020.5066	3.0166266	1.6935261	3049.5281
1021.5076	3.0205517	1.6962645	3038.7559
1022.5085	3.0259035	1.6992713	3042.2305
1023.5095	3.0272164	1.7025721	3040.2717
1024.5105	3.0302594	1.7061815	3032.2009
1025.5115	3.0339766	1.7096636	3032.1667
1026.5125	3.0389888	1.7124441	3027.0234
1027.5134	3.0437028	1.7154967	3028.8188
1028.5144	3.0414004	1.7189437	3025.3655
1029.5154	3.0442057	1.7226591	3022.6472
1030.5164	3.0481229	1.7258091	3012.3127
1031.5173	3.0522702	1.7295334	3012.4124
1032.5183	3.0556796	1.7325466	3011.407
1033.5193	3.0576158	1.7357664	3000.4036
1034.5203	3.0594151	1.7389371	2997.77
1035.5212	3.0654504	1.7422301	2999.7642
1036.5222	3.0665772	1.7454996	2995.489
1037.5232	3.0715771	1.7490727	2992.2458
1038.5242	3.0723815	1.7521155	2981.9607
1039.5251	3.076936	1.7554181	2985.8604
1040.5261	3.0769122	1.7587531	2979.3491
1041.5271	3.0811236	1.7625113	2976.3635
1042.5281	3.0851068	1.7656617	2973.5613
1043.5291	3.0911295	1.7686411	2968.8154
1044.53	3.0906012	1.771415	2972.311
1045.531	3.0916865	1.7751321	2961.7358
1046.532	3.0968304	1.7784246	2956.3655
1047.533	3.0994039	1.7814162	2953.2427
1048.5339	3.100877	1.7849126	2952.3293
1049.5349	3.1057985	1.7880334	2944.6755
1050.5359	3.1071217	1.7912395	2942.1819
1051.5369	3.1109335	1.7952026	2940.2085
1052.5378	3.1137958	1.7980059	2930.8933
1053.5388	3.1200364	1.8010257	2932.6208
1054.5398	3.123848	1.8044655	2931.6875
1055.5408	3.1241598	1.808084	2929.123
1056.5417	3.1279347	1.8117807	2919.0725
1057.5427	3.1303897	1.8149	2918.3799
1058.5437	3.1325326	1.8181717	2910.1897
1059.5447	3.1349554	1.8213667	2901.2163
1060.5457	3.1390302	1.8243086	2902.6475
1061.5466	3.1435087	1.8283156	2909.4956
1062.5476	3.1446981	1.8323994	2894.3015
1063.5486	3.1475103	1.8360425	2889.3484
1064.5496	3.1488585	1.8394125	2887.5549
1065.5505	3.1554191	1.8424687	2877.4893
1066.5515	3.1616204	1.8460515	2875.3796
1067.5525	3.1584585	1.849061	2873.353
1068.5535	3.1640406	1.8521249	2873.9265
1069.5544	3.1658258	1.8549482	2864.4431
1070.5554	3.1714551	1.8579432	2866.834
1071.5564	3.1738298	1.8607956	2860.2319
1072.5574	3.1768379	1.8639233	2852.2551
1073.5583	3.1787384	1.8674145	2850.3411
1074.5593	3.1797323	1.8708957	2838.5737
1075.5603	3.1852398	1.8739355	2836.1519
1076.5613	3.1893697	1.8775305	2838.5684
1077.5623	3.1921585	1.8807105	2831.8147
1078.5632	3.1943672	1.884106	2826.9602
1079.5642	3.1940622	1.8875411	2816.676
1080.5652	3.203124	1.8906554	2818.262
1081.5662	3.2030256	1.8943859	2813.4778
1082.5671	3.2059476	1.8977369	2807.8552
1083.5681	3.2094812	1.9017663	2802.7869
1084.5691	3.2089794	1.9054971	2796.8203
1085.5701	3.2143736	1.9097266	2790.1113
1086.571	3.2194414	1.9137397	2786.1531
1087.572	3.2206254	1.9170675	2771.23
1088.573	3.2241325	1.9200968	2775.0303
1089.574	3.2298584	1.923261	2772.6812
1090.575	3.2285995	1.9267019	2759.6516
1091.5759	3.2314246	1.9296484	2754.9492
1092.5769	3.23792	1.9324452	2753.8074
1093.5779	3.2407184	1.9358069	2749.9194
1094.5789	3.2428226	1.939925	2744.636
1095.5798	3.2460093	1.9434234	2735.666
1096.5808	3.2481189	1.9470069	2729.0813
1097.5818	3.2537222	1.9509648	2732.1177
1098.5828	3.2511351	1.9544085	2714.2407
1099.5837	3.2592022	1.9581572	2715.6013
1100.5847	3.2606337	1.961908	2700.0657
1101.5857	3.2648065	1.9654721	2696.8806
1102.5867	3.2665668	1.9687343	2689.8511
1103.5876	3.2703574	1.9712347	2689.7417
1104.5886	3.2731357	1.9746109	2687.7246
1105.5896	3.2757416	1.9787759	2682.2444
1106.5906	3.2783716	1.982675	2669.061
1107.5916	3.2802818	1.9861581	2661.7339
1108.5925	3.2839918	1.9894531	2661.0872
1109.5935	3.2874627	1.9930053	2654.5022
1110.5945	3.2878764	1.9968678	2642.1616
1111.5955	3.2943261	2.000526	2634.6096
1112.5964	3.2973523	2.0035369	2628.8406
1113.5974	3.2992418	2.0072248	2621.4087
1114.5984	3.3013101	2.0111549	2613.1152
1115.5994	3.3034108	2.014868	2600.5317
1116.6003	3.308053	2.0182202	2596.1147
1117.6013	3.3138108	2.0216005	2590.405
1118.6023	3.3146093	2.0252736	2578.6587
1119.6033	3.3202658	2.0292616	2583.4556
1120.6042	3.3196366	2.0333726	2557.1208
1121.6052	3.3240893	2.0369792	2552.2344
1122.6062	3.3290324	2.0398693	2544.0396
1123.6072	3.3288012	2.0420451	2532.4314
1124.6082	3.3345349	2.0428498	2526.0242
1125.6091	3.3325536	2.0439043	2503.4468
1126.6101	3.3374281	2.0448165	2481.4431
1127.6111	3.3424037	2.0453737	2460.7419
1128.6121	3.3470538	2.0462351	2441.5029
1128.8123	3.3454502	2.046381	2435.3794