File: datasets/steel_spring/csv/BS2V-1150-0.1.csv
Time(s),Strain(%),Stress(MPa),Temp(C),SR(%/s)
0.0,1.969e-05,1.2811497110705816,1150.0,0.1
0.00010719999999999998,3.041e-05,0.49374567190775465,1150.0,0.1
0.00021429999999999998,4.112e-05,-0.04373575811076913,1150.0,0.1
0.00042769999999999993,6.246e-05,-0.33656130271770013,1150.0,0.1
0.0004818,6.787e-05,-0.38999768564574744,1150.0,0.1
0.0005349,7.318e-05,-0.2093116306276217,1150.0,0.1
0.0006961000000000001,8.93e-05,0.20023013860396666,1150.0,0.1
0.0008023,9.992e-05,0.8333608983163092,1150.0,0.1
0.0008563,0.00010532,1.684813924776694,1150.0,0.1
0.0011237999999999999,0.00013207,2.7493224942524117,1150.0,0.1
0.0018188999999999998,0.00020158,4.710493165439411,1150.0,0.1
0.0020864,0.00022833,6.389521689250024,1150.0,0.1
0.0028366,0.00030335,8.288837372090942,1150.0,0.1
0.0032643999999999998,0.00034613,10.415104768825797,1150.0,0.1
0.0040129,0.00042098,12.72033112092808,1150.0,0.1
0.0054056,0.00056025,15.150186234106119,1150.0,0.1
0.006422699999999999,0.00066196,17.600814728174313,1150.0,0.1
0.007439899999999999,0.00076368,19.958605832496293,1150.0,0.1
0.008135499999999999,0.00083324,22.075386163090997,1150.0,0.1
0.0096351,0.0009832,24.0267244456554,1150.0,0.1
0.0112953,0.00114922,25.77937647992434,1150.0,0.1
0.012313,0.00125099,27.28857370218193,1150.0,0.1
0.014081,0.00142779,28.56183974667435,1150.0,0.1
0.0162776,0.00164745,29.506975496246326,1150.0,0.1
0.019064699999999997,0.00192616,30.224813365939514,1150.0,0.1
0.022067299999999998,0.00222642,30.75765967998497,1150.0,0.1
0.023086100000000002,0.0023283,31.14462137467057,1150.0,0.1
0.0254463,0.00256432,31.30482652853422,1150.0,0.1
0.0279678,0.00281647,31.37805421319709,1150.0,0.1
0.030864700000000002,0.00310616,31.437938780484973,1150.0,0.1
0.0318844,0.00320813,31.51971574832967,1150.0,0.1
0.0346758,0.00348727,31.564585860163007,1150.0,0.1
0.037467999999999994,0.00376649,31.6659845940077,1150.0,0.1
0.0399925,0.00401894,31.831760921216038,1150.0,0.1
0.042893799999999996,0.00430907,32.03587764693573,1150.0,0.1
0.0447749,0.00449718,32.260871542700876,1150.0,0.1
0.0464409,0.00466378,32.494018577738764,1150.0,0.1
0.04902109999999999,0.0049218,32.72359907121604,1150.0,0.1
0.051495099999999995,0.0051692,32.95250468582967,1150.0,0.1
0.0527314,0.00529283,33.170839077038,1150.0,0.1
0.0553141,0.0055511,33.377977442079676,1150.0,0.1
0.0584345,0.00586314,33.57374923340544,1150.0,0.1
0.060534,0.00607309,33.77351912406452,1150.0,0.1
0.06187929999999999,0.00620762,33.962606812697096,1150.0,0.1
0.0643565,0.00645534,34.142202206159226,1150.0,0.1
0.0664563,0.00666532,34.3138585412918,1150.0,0.1
0.0692574,0.00694543,34.487330925102405,1150.0,0.1
0.0722207,0.00724176,34.665043699541805,1150.0,0.1
0.0731912,0.00733881,34.83917481969332,1150.0,0.1
0.07567019999999999,0.00758671,34.991669712484985,1150.0,0.1
0.0780974,0.00782943,35.1427357638865,1150.0,0.1
0.08117039999999999,0.00813673,35.29453281264408,1150.0,0.1
0.08235780000000001,0.00825547,35.44447442132591,1150.0,0.1
0.0848936,0.00850905,35.57987932840165,1150.0,0.1
0.08737559999999998,0.00875725,35.71202092387136,1150.0,0.1
0.0895348,0.00897317,35.843123981015296,1150.0,0.1
0.092018,0.00922149,35.971265638337265,1150.0,0.1
0.09293679999999999,0.00931337,36.100423770731204,1150.0,0.1
0.0966625,0.00968594,36.22363578787135,1150.0,0.1
0.09833819999999999,0.00985351,36.33648721019711,1150.0,0.1
0.10103999999999999,0.01012369,36.445769939515294,1150.0,0.1
0.1023907,0.01025876,36.554974137072115,1150.0,0.1
0.104716,0.01049129,36.65184340049257,1150.0,0.1
0.1070409,0.01072378,36.75664560716681,1150.0,0.1
0.1096904,0.01098873,36.86850614743955,1150.0,0.1
0.11190909999999998,0.0112106,36.969592408985,1150.0,0.1
0.11282879999999999,0.01130257,37.07265173687893,1150.0,0.1
0.11558919999999999,0.01157861,37.17110220254559,1150.0,0.1
0.1175914,0.01177883,37.268332005163025,1150.0,0.1
0.12029839999999999,0.01204953,37.37664716571606,1150.0,0.1
0.12138199999999999,0.01215789,37.484229009973625,1150.0,0.1
0.12338529999999999,0.01235822,37.58611421612135,1150.0,0.1
0.1259316,0.01261285,37.687000675333486,1150.0,0.1
0.12858709999999998,0.0128784,37.79911297590167,1150.0,0.1
0.1294545,0.01296514,37.90477654449257,1150.0,0.1
0.13232709999999998,0.0132524,38.005127592212276,1150.0,0.1
0.13471329999999998,0.01349102,38.10772248614029,1150.0,0.1
0.1370452,0.01372421,38.21605158904182,1150.0,0.1
0.13943149999999999,0.01396284,38.309580609041824,1150.0,0.1
0.1406797,0.01408766,38.41161523512515,1150.0,0.1
0.14317649999999998,0.01433734,38.51048882721227,1150.0,0.1
0.1457269,0.01459238,38.608289532617576,1150.0,0.1
0.1480075,0.01482044,38.70661612786379,1150.0,0.1
0.1494743,0.01496712,38.80382959991303,1150.0,0.1
0.1521899,0.01523868,38.89592980775774,1150.0,0.1
0.1536563,0.01538532,38.99922184510243,1150.0,0.1
0.15604759999999998,0.01562445,39.10020585806076,1150.0,0.1
0.1573518,0.01575487,39.19584409161378,1150.0,0.1
0.1600146,0.01602115,39.29506119758728,1150.0,0.1
0.16191779999999997,0.01621147,39.3966097143903,1150.0,0.1
0.1642571,0.0164454,39.494050636269094,1150.0,0.1
0.1665959,0.01667928,39.595804507128946,1150.0,0.1
0.1676296,0.01678265,39.69657516721986,1150.0,0.1
0.17035009999999998,0.0170547,39.79027212883727,1150.0,0.1
0.1725273,0.01727242,39.88298380955697,1150.0,0.1
0.1751952,0.01753921,39.983032930875154,1150.0,0.1
0.1763378,0.01765347,40.08194205637137,1150.0,0.1
0.1790618,0.01792587,40.164842902155456,1150.0,0.1
0.181349,0.01815459,40.25449202299258,1150.0,0.1
0.18412839999999997,0.01843253,40.34277618795091,1150.0,0.1
0.18592699999999998,0.01861239,40.43210071582212,1150.0,0.1
0.18756169999999997,0.01877586,40.51663722642061,1150.0,0.1
0.1896334,0.01898303,40.61208401934864,1150.0,0.1
0.19236099999999998,0.01925579,40.70320833122364,1150.0,0.1
0.1944879,0.01946848,40.796756670484996,1150.0,0.1
0.19601559999999998,0.01962125,40.88327856900017,1150.0,0.1
0.19808909999999996,0.0198286,40.97075641805319,1150.0,0.1
0.20021719999999998,0.02004141,41.06196842899637,1150.0,0.1
0.2028925,0.02030894,41.1551991240494,1150.0,0.1
0.2045852,0.02047821,41.24843641109106,1150.0,0.1
0.2067156,0.02069125,41.34515599124259,1150.0,0.1
0.20933739999999998,0.02095343,41.436651201492595,1150.0,0.1
0.21146790000000001,0.02116648,41.53017553900773,1150.0,0.1
0.2138188,0.02140157,41.625555076375164,1150.0,0.1
0.2149116,0.02151085,41.72059938043198,1150.0,0.1
0.2175356,0.02177325,41.80693358348881,1150.0,0.1
0.2193955,0.02195924,41.892688220897895,1150.0,0.1
0.22284089999999998,0.02230378,41.98902591351532,1150.0,0.1
0.2233887,0.02235856,42.08430504716684,1150.0,0.1
0.22585,0.02260469,42.17371659231835,1150.0,0.1
0.22820429999999997,0.02284012,42.26381059956835,1150.0,0.1
0.23116069999999997,0.02313576,42.359292436113805,1150.0,0.1
0.2334055,0.02336024,42.44755948334865,1150.0,0.1
0.23406269999999998,0.02342596,42.53069147686759,1150.0,0.1
0.23751409999999998,0.0237711,42.619332919818355,1150.0,0.1
0.2395409,0.02397378,42.707582944860015,1150.0,0.1
0.241569,0.02417659,42.794732034170615,1150.0,0.1
0.2430486,0.02432455,42.882887434753954,1150.0,0.1
0.2455712,0.02457681,42.96819283933729,1150.0,0.1
0.2483131,0.024851,43.052376589087295,1150.0,0.1
0.25056169999999994,0.02507586,43.13464071195093,1150.0,0.1
0.2522624,0.02524593,43.21832000952668,1150.0,0.1
0.2543486,0.02545455,43.30894730688274,1150.0,0.1
0.2564333,0.02566302,43.391547366280484,1150.0,0.1
0.25895919999999994,0.02591561,43.47098741277668,1150.0,0.1
0.2614303,0.02616272,43.56249265826532,1150.0,0.1
0.26230919999999996,0.02625061,43.65497856396608,1150.0,0.1
0.2647811,0.0264978,43.744583666753954,1150.0,0.1
0.26785749999999997,0.02680544,43.8296990865532,1150.0,0.1
0.2702762,0.02704731,43.922592950511536,1150.0,0.1
0.27093579999999995,0.02711327,44.013069077507744,1150.0,0.1
0.27373919999999996,0.02739361,44.09923969414411,1150.0,0.1
0.2759946,0.02761915,44.1858674736176,1150.0,0.1
0.2789096,0.02791065,44.28567381703426,1150.0,0.1
0.2812208,0.02814177,44.38255261491305,1150.0,0.1
0.28221169999999995,0.02824086,44.475994971038055,1150.0,0.1
0.2851286,0.02853255,44.56459814409487,1150.0,0.1
0.28749579999999997,0.02876927,44.644178967420636,1150.0,0.1
0.28986359999999994,0.02900605,44.7342540446479,1150.0,0.1
0.29069049999999996,0.02908874,44.82694041445093,1150.0,0.1
0.2938305,0.02940274,44.91045167997745,1150.0,0.1
0.2955933,0.02957902,44.99983977047745,1150.0,0.1
0.298515,0.02987119,45.08140019022745,1150.0,0.1
0.29961709999999997,0.0299814,45.164626993742594,1150.0,0.1
0.3023191,0.0302516,45.24943097230321,1150.0,0.1
0.30419379999999996,0.03043907,45.330365968841086,1150.0,0.1
0.3070633,0.03072602,45.411792587541846,1150.0,0.1
0.30904839999999995,0.03092453,45.4929090473979,1150.0,0.1
0.3104843,0.03106812,45.57910540902291,1150.0,0.1
0.31313349999999995,0.03133304,45.656282859091085,1150.0,0.1
0.31578329999999993,0.03159802,45.73328481373502,1150.0,0.1
0.318103,0.03182999,45.822520813447156,1150.0,0.1
0.31953919999999997,0.03197361,45.91211972771609,1150.0,0.1
0.3211959,0.03213928,45.99546012112519,1150.0,0.1
0.3241799,0.03243768,46.07722868413276,1150.0,0.1
0.3266123,0.03268092,46.15655590925397,1150.0,0.1
0.3288787,0.03290756,46.23472160700397,1150.0,0.1
0.33086909999999997,0.0331066,46.32353793757973,1150.0,0.1
0.33269529999999997,0.03328922,46.404056724784276,1150.0,0.1
0.335571,0.03357679,46.47919056796232,1150.0,0.1
0.3380062,0.03382031,46.567391990757756,1150.0,0.1
0.338836,0.03390329,46.64894418798503,1150.0,0.1
0.34143769999999996,0.03416346,46.72807060860625,1150.0,0.1
0.3456459,0.03458428,46.80157155267062,1150.0,0.1
0.3464764,0.03466733,46.88094719089791,1150.0,0.1
0.3488591999999999,0.03490561,46.965394001064574,1150.0,0.1
0.349634,0.03498309,47.04245387706836,1150.0,0.1
0.3525716,0.03527685,47.11794453821231,1150.0,0.1
0.3548998,0.03550967,47.188792612897906,1150.0,0.1
0.35761679999999996,0.03578137,47.265182580159276,1150.0,0.1
0.35878049999999995,0.03589774,47.34485039497746,1150.0,0.1
0.36144249999999994,0.03616394,47.416856213969886,1150.0,0.1
0.363939,0.03641359,47.487435007011555,1150.0,0.1
0.36660329999999997,0.03668002,47.56611397088655,1150.0,0.1
0.36821269999999995,0.03684096,47.63692894501155,1150.0,0.1
0.3699336,0.03701305,47.709379205617616,1150.0,0.1
0.3727659,0.03729628,47.77846978710246,1150.0,0.1
0.3749315,0.03751284,47.85121117025019,1150.0,0.1
0.3775427,0.03777396,47.93157226793579,1150.0,0.1
0.37865449999999995,0.03788514,48.01270716998125,1150.0,0.1
0.381044,0.03812409,48.08528685880701,1150.0,0.1
0.3835454,0.03837423,48.158086793469884,1150.0,0.1
0.38610269999999997,0.03862996,48.23405551723883,1150.0,0.1
0.38732579999999994,0.03875227,48.314491265708526,1150.0,0.1
0.38994019999999996,0.03901371,48.392810871553216,1150.0,0.1
0.39205529999999994,0.03922522,48.46449172957595,1150.0,0.1
0.39494809999999997,0.0395145,48.53653204012518,1150.0,0.1
0.3970081,0.0397205,48.61156304319337,1150.0,0.1
0.39834410000000003,0.0398541,48.685393029814584,1150.0,0.1
0.4007946,0.04009915,48.757344428663075,1150.0,0.1
0.40313309999999997,0.040333,48.82501533892822,1150.0,0.1
0.4054178,0.04056147,48.89916739851155,1150.0,0.1
0.4065318,0.04067287,48.97185824253428,1150.0,0.1
0.40987529999999994,0.04100722,49.04117797596611,1150.0,0.1
0.4116044,0.04118013,49.1136689050911,1150.0,0.1
0.4142241,0.0414421,49.18906945488277,1150.0,0.1
0.4166221,0.0416819,49.2706965237199,1150.0,0.1
0.4179053999999999,0.04181023,49.3516583913108,1150.0,0.1
0.4203053,0.04205022,49.42792759526156,1150.0,0.1
0.4227602,0.04229571,49.506421704250194,1150.0,0.1
0.4250485,0.04252454,49.58493233965171,1150.0,0.1
0.42655639999999995,0.04267533,49.660168550621414,1150.0,0.1
0.4290129,0.04292098,49.73822509513655,1150.0,0.1
0.4314709,0.04316678,49.808396239045656,1150.0,0.1
0.4336502,0.04338471,49.88117204636004,1150.0,0.1
0.4348792,0.04350761,49.95257834570474,1150.0,0.1
0.4373377,0.04375346,50.02800977384112,1150.0,0.1
0.4400217,0.04402186,50.09901170559489,1150.0,0.1
0.44253789999999993,0.04427348,50.16655841099261,1150.0,0.1
0.4448307,0.04450276,50.235881875909286,1150.0,0.1
0.445837,0.04460339,50.30778853819716,1150.0,0.1
0.4482991,0.0448496,50.37014139364793,1150.0,0.1
0.450874,0.04510709,50.436746305769134,1150.0,0.1
0.4537849,0.04539818,50.504611804932004,1150.0,0.1
0.4555761,0.0455773,50.57899881348505,1150.0,0.1
0.45736859999999996,0.04575655,50.649630405193385,1150.0,0.1
0.4592726,0.04594695,50.72177541917822,1150.0,0.1
0.4617371,0.0461934,50.787071682765344,1150.0,0.1
0.4642031999999999,0.04644001,50.85817450330701,1150.0,0.1
0.46560479999999993,0.04658017,50.92468494943202,1150.0,0.1
0.46807079999999995,0.04682677,50.99013004613657,1150.0,0.1
0.4704261,0.0470623,51.05840994022368,1150.0,0.1
0.4731179999999999,0.04733149,51.120601868447174,1150.0,0.1
0.4755312,0.04757281,51.189230404375195,1150.0,0.1
0.47676539999999995,0.04769623,51.25826122104564,1150.0,0.1
0.479459,0.04796559,51.325805673049445,1150.0,0.1
0.4818727,0.04820696,51.38921297561384,1150.0,0.1
0.4837257,0.04839226,51.45087842356838,1150.0,0.1
0.48580399999999996,0.04860009,51.51265596335626,1150.0,0.1
0.48827499999999996,0.04884719,51.57388089225399,1150.0,0.1
0.4899050999999999,0.0490102,51.63265401525399,1150.0,0.1
0.4925465,0.04927434,51.689510748670656,1150.0,0.1
0.49378269999999996,0.04939796,51.75379712638277,1150.0,0.1
0.4957505,0.04959474,51.81662710932976,1150.0,0.1
0.4988987,0.04990956,51.87621325720475,1150.0,0.1
0.5015424999999999,0.05017394,51.93844030136762,1150.0,0.1
0.5038499,0.05040468,51.99784869674263,1150.0,0.1
0.5052001999999999,0.05053971,52.06328809195854,1150.0,0.1
0.5075632999999999,0.05077602,52.12161977915172,1150.0,0.1
0.5103220999999999,0.0510519,52.18097047300021,1150.0,0.1
0.5125186999999999,0.05127156,52.24229578405324,1150.0,0.1
0.5134189999999998,0.05136159,52.30452132332976,1150.0,0.1
0.5159537999999999,0.05161507,52.363857238625215,1150.0,0.1
0.5188278,0.05190247,52.42569913173127,1150.0,0.1
0.5213068999999999,0.05215038,52.4859404220305,1150.0,0.1
0.5238446999999999,0.05240416,52.54852571371991,1150.0,0.1
0.5250279,0.05252248,52.611986868659294,1150.0,0.1
0.5273966,0.05275935,52.66811885726915,1150.0,0.1
0.5296529999999999,0.05298499,52.725016212954756,1150.0,0.1
0.5325308999999999,0.05327278,52.78034114554189,1150.0,0.1
0.5337150999999999,0.0533912,52.83165337554565,1150.0,0.1
0.5359168999999999,0.05361138,52.8857610207502,1150.0,0.1
0.5393039999999999,0.05395009,52.94217338515929,1150.0,0.1
0.5407721999999999,0.05409691,52.99682610315931,1150.0,0.1
0.5430886999999999,0.05432856,53.051262509583545,1150.0,0.1
0.5444442999999999,0.05446412,53.10876028956459,1150.0,0.1
0.5468737999999999,0.05470707,53.16776703420476,1150.0,0.1
0.5493608999999999,0.05495578,53.22523007345477,1150.0,0.1
0.5519048,0.05521017,53.286850064401726,1150.0,0.1
0.5542229,0.05544198,53.34900300225022,1150.0,0.1
0.5558626999999999,0.05560596,53.409404293492635,1150.0,0.1
0.5581254999999999,0.05583224,53.463403738598686,1150.0,0.1
0.5602754,0.05604723,53.524615829378995,1150.0,0.1
0.5626526,0.05628495,53.590258830553225,1150.0,0.1
0.5640670999999999,0.0564264,53.65287014640551,1150.0,0.1
0.5663316999999999,0.05665286,53.71161886587899,1150.0,0.1
0.5687674999999999,0.05689644,53.76532481565551,1150.0,0.1
0.5713153,0.05715122,53.82617950466308,1150.0,0.1
0.5725051999999999,0.05727021,53.88594390392066,1150.0,0.1
0.5747154999999999,0.05749124,53.936655347629,1150.0,0.1
0.5777761999999999,0.05779731,53.98297988072748,1150.0,0.1
0.5799865999999999,0.05801835,54.03810248364795,1150.0,0.1
0.5824248,0.05826217,54.08572360523128,1150.0,0.1
0.5840129999999999,0.05842099,54.137013146879,1150.0,0.1
0.5859422999999999,0.05861392,54.1952500350987,1150.0,0.1
0.5885518,0.05887487,54.2546974087843,1150.0,0.1
0.5908219999999998,0.05910189,54.31333357461763,1150.0,0.1
0.5922978999999999,0.05924948,54.36677551216689,1150.0,0.1
0.5942276999999999,0.05944246,54.42176171352295,1150.0,0.1
0.5970104999999999,0.05972074,54.478218529416885,1150.0,0.1
0.5997366999999999,0.05999336,54.5316487004737,1150.0,0.1
0.6017819,0.06019788,54.59165803796233,1150.0,0.1
0.6027486999999999,0.06029456,54.65307149625779,1150.0,0.1
0.6056466999999999,0.06058436,54.700841351784305,1150.0,0.1
0.6080910999999999,0.0608288,54.75981461348128,1150.0,0.1
0.6103656999999999,0.06105626,54.821179352034314,1150.0,0.1
0.6116740999999999,0.0611871,54.886053863060816,1150.0,0.1
0.6141199999999999,0.06143169,54.94492981387901,1150.0,0.1
0.6166803999999999,0.06168773,54.99157046696234,1150.0,0.1
0.6191273999999999,0.06193243,55.04405459319719,1150.0,0.1
0.6205509999999999,0.06207479,55.1023801918487,1150.0,0.1
0.6227708999999999,0.06229678,55.15468686243961,1150.0,0.1
0.6255051999999999,0.06257021,55.20879216038279,1150.0,0.1
0.6279543999999999,0.06281513,55.266505188920675,1150.0,0.1
0.6305748999999998,0.06307718,55.3208595124131,1150.0,0.1
0.6316575999999999,0.06318545,55.36968329367445,1150.0,0.1
0.6342802,0.06344771,55.41919002296613,1150.0,0.1
0.6368457999999998,0.06370427,55.47335075252295,1150.0,0.1
0.6390126999999999,0.06392096,55.51856130502673,1150.0,0.1
0.6413509999999999,0.06415479,55.55909600527295,1150.0,0.1
0.6428919999999998,0.06430889,55.60497827422749,1150.0,0.1
0.6451168999999999,0.06453138,55.64669569823127,1150.0,0.1
0.6477418999999999,0.06479388,55.686843921560815,1150.0,0.1
0.6497978999999999,0.06499948,55.74022687380704,1150.0,0.1
0.6513958,0.06515927,55.78668811195477,1150.0,0.1
0.653567,0.06537639,55.83328940476159,1150.0,0.1
0.6567652999999999,0.06569622,55.877668216163094,1150.0,0.1
0.6589365999999999,0.06591335,55.918712641901735,1150.0,0.1
0.6600224,0.06602193,55.972404027969915,1150.0,0.1
0.6621943999999998,0.06623913,56.023055768969904,1150.0,0.1
0.6651673999999999,0.06653643,56.07129715736386,1150.0,0.1
0.6675696999999999,0.06677666,56.12162892455324,1150.0,0.1
0.6702015999999998,0.06703985,56.1672178654472,1150.0,0.1
0.6712307999999999,0.06714277,56.21341828515931,1150.0,0.1
0.6738059,0.06740028,56.25775233843961,1150.0,0.1
0.6755800999999999,0.0675777,56.30264461077673,1150.0,0.1
0.678271,0.06784679,56.348752599450975,1150.0,0.1
0.6802174999999998,0.06804144,56.38305947114795,1150.0,0.1
0.6822224,0.06824193,56.42227180148129,1150.0,0.1
0.6847435,0.06849404,56.469800380276745,1150.0,0.1
0.6873788999999999,0.06875758,56.51500052575022,1150.0,0.1
0.6890986,0.06892955,56.55713026437144,1150.0,0.1
0.6899012,0.06900981,56.60573874383355,1150.0,0.1
0.6932270999999999,0.0693424,56.6507530587578,1150.0,0.1
0.6953482999999998,0.06955452,56.69819076581462,1150.0,0.1
0.6978147999999998,0.06980117,56.745613722450976,1150.0,0.1
0.6990766999999999,0.06992736,56.79475991692825,1150.0,0.1
0.7020036999999999,0.07022006,56.84406720279947,1150.0,0.1
0.7042428999999999,0.07044398,56.88822880626917,1150.0,0.1
0.7067113999999999,0.07069083,56.938024243587336,1150.0,0.1
0.7091806999999999,0.07093776,56.986738014477496,1150.0,0.1
0.7102149999999999,0.07104119,57.03303662126537,1150.0,0.1
0.7127420999999998,0.0712939,57.08370130353432,1150.0,0.1
0.7155009999999998,0.07156979,57.1330603425684,1150.0,0.1
0.7176839999999999,0.07178809,57.18157999702675,1150.0,0.1
0.7186621999999999,0.07188591,57.23747526007598,1150.0,0.1
0.7217661999999999,0.07219631,57.28087938993961,1150.0,0.1
0.7238374999999999,0.07240344,57.33577836493962,1150.0,0.1
0.7264832999999999,0.07266802,57.39389948433733,1150.0,0.1
0.7277486999999998,0.07279456,57.4469228294775,1150.0,0.1
0.7298212999999999,0.07300182,57.49120755287523,1150.0,0.1
0.7322379999999998,0.07324349,57.539469312325984,1150.0,0.1
0.7351748999999999,0.07353718,57.58673424077674,1150.0,0.1
0.7371324999999999,0.07373294,57.629875711004004,1150.0,0.1
0.7384575999999999,0.07386545,57.67469826259871,1150.0,0.1
0.7408774999999999,0.07410744,57.71636346445098,1150.0,0.1
0.7435276999999999,0.07437246,57.75704952309491,1150.0,0.1
0.7460060999999999,0.0746203,57.802111004897974,1150.0,0.1
0.7472167999999999,0.07474137,57.851791093504005,1150.0,0.1
0.7497542999999999,0.07499512,57.894041875795686,1150.0,0.1
0.7521758999999999,0.07523728,57.940684144950986,1150.0,0.1
0.7544262999999999,0.07546232,57.98892608985628,1150.0,0.1
0.7570802,0.07572771,58.04011306013659,1150.0,0.1
0.7585234999999999,0.07587204,58.089618765795684,1150.0,0.1
0.7607742999999999,0.07609712,58.135318190386585,1150.0,0.1
0.7633724999999999,0.07635694,58.17553612599645,1150.0,0.1
0.7653367999999998,0.07655337,58.229054490079776,1150.0,0.1
0.7671272999999998,0.07673242,58.27220081588281,1150.0,0.1
0.7699003,0.07700972,58.31219183757976,1150.0,0.1
0.772212,0.07724089,58.3448196482843,1150.0,0.1
0.7744669,0.07746638,58.388193647329764,1150.0,0.1
0.7754484999999999,0.07756454,58.43233093300781,1150.0,0.1
0.7786870999999999,0.0778884,58.47185698837523,1150.0,0.1
0.7801909999999999,0.07803879,58.51248626281841,1150.0,0.1
0.7830834999999999,0.07832804,58.55372035415175,1150.0,0.1
0.7852834,0.07854803,58.602158820924465,1150.0,0.1
0.7866137999999999,0.07868107,58.64959975266691,1150.0,0.1
0.7892187999999999,0.07894157,58.69447200011386,1150.0,0.1
0.7921138999999998,0.07923108,58.736781431439624,1150.0,0.1
0.7944307999999999,0.07946277,58.78153610517448,1150.0,0.1
0.7954163999999999,0.07956133,58.827651652367656,1150.0,0.1
0.7981972999999999,0.07983942,58.87028723410629,1150.0,0.1
0.8001096999999999,0.08003066,58.91098171186764,1150.0,0.1
0.8028344,0.08030313,58.945429969011585,1150.0,0.1
0.8055587,0.08057556,58.990538840977514,1150.0,0.1
0.8064868,0.08066837,59.03866864254567,1150.0,0.1
0.8087493999999998,0.08089463,59.077583846469935,1150.0,0.1
0.8115914999999999,0.08117884,59.11855404025023,1150.0,0.1
0.8143778999999999,0.08145748,59.160427651382804,1150.0,0.1
0.8151905999999999,0.08153875,59.207435690659324,1150.0,0.1
0.8176867999999999,0.08178837,59.24334720786765,1150.0,0.1
0.8204161999999999,0.08206131,59.276931857602506,1150.0,0.1
0.8227972999999998,0.08229942,59.309061642969915,1150.0,0.1
0.8240751,0.0824272,59.34860195403433,1150.0,0.1
0.8266897999999999,0.08268867,59.383184101022955,1150.0,0.1
0.8288405999999999,0.08290375,59.414650745257816,1150.0,0.1
0.8313988999999998,0.08315958,59.44381254775023,1150.0,0.1
0.8337238999999999,0.08339208,59.479634261723724,1150.0,0.1
0.8352946999999998,0.08354916,59.51202648992069,1150.0,0.1
0.8375628999999999,0.08377598,59.548469831841146,1150.0,0.1
0.8401234999999999,0.08403204,59.580661667462344,1150.0,0.1
0.8423926999999999,0.08425896,59.6216627592313,1150.0,0.1
0.8451287999999999,0.08453257,59.65693449239796,1150.0,0.1
0.8463516,0.08465485,59.69782770334115,1150.0,0.1
0.8483312,0.08485281,59.73448159707599,1150.0,0.1
0.8515934999999999,0.08517904,59.77446309220856,1150.0,0.1
0.8534573999999999,0.08536543,59.81366366967069,1150.0,0.1
0.8551481999999998,0.08553451,59.855229693977506,1150.0,0.1
0.8575375,0.08577344,59.89501837627296,1150.0,0.1
0.8596360999999999,0.0859833,59.92914215561386,1150.0,0.1
0.8624358999999999,0.08626328,59.963494511818425,1150.0,0.1
0.8636018999999999,0.08637988,59.99661119255706,1150.0,0.1
0.8658184999999999,0.08660154,60.034485331621454,1150.0,0.1
0.8685031999999999,0.08687001,60.06810419465555,1150.0,0.1
0.8707788999999998,0.08709758,60.103102715113856,1150.0,0.1
0.873114,0.08733109,60.140876591636605,1150.0,0.1
0.8740484999999999,0.08742454,60.179834836106295,1150.0,0.1
0.8769091999999998,0.08771061,60.21569305350781,1150.0,0.1
0.8792458999999999,0.08794428,60.25384050617069,1150.0,0.1
0.8819921,0.0882189,60.29578567213281,1150.0,0.1
0.8831614,0.08833583,60.33649199107599,1150.0,0.1
0.8861418999999999,0.08863388,60.3721685022275,1150.0,0.1
0.8881303999999999,0.08883273,60.41088968809114,1150.0,0.1
0.8900010999999999,0.0890198,60.447556886083575,1150.0,0.1
0.8927502999999999,0.08929472,60.493081038450995,1150.0,0.1
0.8939198999999999,0.08941168,60.5319646116063,1150.0,0.1
0.8959679999999999,0.08961649,60.57082919424267,1150.0,0.1
0.8990705,0.08992674,60.610708830966146,1150.0,0.1
0.9014703999999999,0.09016673,60.64798537927676,1150.0,0.1
0.9027001999999998,0.09028971,60.686247720621445,1150.0,0.1
0.9046327999999999,0.09048297,60.72419103306085,1150.0,0.1
0.9075614999999999,0.09077584,60.764274630522976,1150.0,0.1
0.9101389999999999,0.09103359,60.80007415720479,1150.0,0.1
0.9113697999999999,0.09115667,60.8347551393563,1150.0,0.1
0.9136563,0.09138532,60.870480046988874,1150.0,0.1
0.9167050999999999,0.0916902,60.89955747587146,1150.0,0.1
0.9189335,0.09191304,60.93430242473887,1150.0,0.1
0.9210449999999999,0.09212419,60.965704264212356,1150.0,0.1
0.9223947,0.09225916,61.00415377298509,1150.0,0.1
0.9249177999999999,0.09251147,61.035422856560835,1150.0,0.1
0.9262679999999999,0.09264649,61.07136073396616,1150.0,0.1
0.9296722999999999,0.09298692,61.10793934620099,1150.0,0.1
0.9310231999999999,0.09312201,61.14519988017069,1150.0,0.1
0.9334307,0.09336276,61.18475812021993,1150.0,0.1
0.9361918999999999,0.09363888,61.21784841383357,1150.0,0.1
0.937955,0.09381519,61.2505416569169,1150.0,0.1
0.9407756999999999,0.09409726,61.286378938348726,1150.0,0.1
0.9415988,0.09417957,61.32123336740555,1150.0,0.1
0.9447144999999999,0.09449114,61.35856330556464,1150.0,0.1
0.9473025999999999,0.09474995,61.39542596195478,1150.0,0.1
0.9495378999999999,0.09497348,61.42810590132599,1150.0,0.1
0.9510093,0.09512062,61.45698644696615,1150.0,0.1
0.9533037999999998,0.09535007,61.491103547685846,1150.0,0.1
0.9564826,0.09566795,61.52136018243206,1150.0,0.1
0.9584255999999999,0.09586225,61.54728752071995,1150.0,0.1
0.9596623999999999,0.09598593,61.57423531082979,1150.0,0.1
0.9621948999999999,0.09623918,61.60233350958357,1150.0,0.1
0.9650224999999999,0.09652194,61.63665671683358,1150.0,0.1
0.9664960999999999,0.0966693,61.66334379981843,1150.0,0.1
0.9696194999999999,0.09698164,61.69673476431084,1150.0,0.1
0.9708577999999999,0.09710547,61.72997474943205,1150.0,0.1
0.9730983,0.09732952,61.76239026540932,1150.0,0.1
0.9759885999999999,0.09761855,61.78648814438282,1150.0,0.1
0.9782888999999999,0.09784858,61.81425308429569,1150.0,0.1
0.9797048999999999,0.09799018,61.83949356693585,1150.0,0.1
0.9812988999999999,0.09814958,61.86351377943964,1150.0,0.1
0.9844865999999999,0.09846835,61.8905258351669,1150.0,0.1
0.9872607999999998,0.09874577,61.91885650937146,1150.0,0.1
0.9896830999999999,0.098988,61.94973089712524,1150.0,0.1
0.9906284999999999,0.09908254,61.97536049810631,1150.0,0.1
0.9922817999999999,0.09924787,62.00086178709494,1150.0,0.1
0.9951188999999998,0.09953158,62.0325971468563,1150.0,0.1
0.9979559,0.09981528,62.056698329144176,1150.0,0.1
0.9993159999999999,0.09995129,62.084960710026756,1150.0,0.1
1.0011489,0.10013458,62.10863977384114,1150.0,0.1
1.0048158,0.10050127,62.13286317218964,1150.0,0.1
1.0066498,0.10068467,62.16608765555327,1150.0,0.1
1.0093725,0.10095694,62.19866676230327,1150.0,0.1
1.010496,0.10106929,62.23237812387525,1150.0,0.1
1.0128641,0.1013061,62.256965462886605,1150.0,0.1
1.0154111000000001,0.1015608,62.2825441916063,1150.0,0.1
1.0173058,0.10175027,62.30502979495479,1150.0,0.1
1.0190244,0.10192213,62.334742793807074,1150.0,0.1
1.0214533,0.10216502,62.36067053821994,1150.0,0.1
1.0238828,0.10240797,62.380357867875254,1150.0,0.1
1.0257202,0.10259171,62.41461668396994,1150.0,0.1
1.0274992,0.10276961,62.44765303890933,1150.0,0.1
1.0301078,0.10303047,62.48411086222373,1150.0,0.1
1.0328958,0.10330927,62.51480598012903,1150.0,0.1
1.0349135999999999,0.10351105,62.54752165998508,1150.0,0.1
1.0365743,0.10367712,62.58423620840934,1150.0,0.1
1.0381774,0.10383743,62.61464377791312,1150.0,0.1
1.0406709,0.10408678,62.64665839209495,1150.0,0.1
1.0436397,0.10438366,62.67268953917071,1150.0,0.1
1.0458367,0.10460336,62.70117791792448,1150.0,0.1
1.0470842999999999,0.10472812,62.73644226832221,1150.0,0.1
1.049639,0.10498359,62.763424297701,1150.0,0.1
1.0525514999999999,0.10527484,62.78458043192449,1150.0,0.1
1.0540971000000001,0.1054294,62.80652989637904,1150.0,0.1
1.0568328,0.10570297,62.8335838552048,1150.0,0.1
1.0580807,0.10582776,62.86116515973889,1150.0,0.1
1.0609366,0.10611335,62.88309784309873,1150.0,0.1
1.0633156,0.10635125,62.903642535303284,1150.0,0.1
1.066232,0.10664289,62.92954317081085,1150.0,0.1
1.0670065,0.10672034,62.96656963189798,1150.0,0.1
1.0691494,0.10693463,62.99954243873887,1150.0,0.1
1.0717098,0.10719067,63.03289518376917,1150.0,0.1
1.073914,0.10741109,63.06647298145479,1150.0,0.1
1.076654,0.10768509,63.09972469892829,1150.0,0.1
1.0781441999999999,0.10783411,63.13776130081464,1150.0,0.1
1.0799916,0.10801885,63.16962378213281,1150.0,0.1
1.0826741,0.1082871,63.203191769799474,1150.0,0.1
1.0848807,0.10850776,63.23348714271236,1150.0,0.1
1.0866099999999999,0.10868069,63.26289447883737,1150.0,0.1
1.0888767,0.10890736,63.29385916202298,1150.0,0.1
1.0915013,0.10916982,63.31984862387903,1150.0,0.1
1.0934707,0.10936676,63.347574873784325,1150.0,0.1
1.0966943999999998,0.10968913,63.3781642121669,1150.0,0.1
1.0977093,0.10979062,63.402090151356305,1150.0,0.1
1.1001583,0.11003552,63.42859992358738,1150.0,0.1
1.1021295,0.11023264,63.449079624212374,1150.0,0.1
1.1052956999999999,0.11054926,63.47650243427675,1150.0,0.1
1.1060126,0.11062095,63.506640380769184,1150.0,0.1
1.1087626,0.11089595,63.526610710682085,1150.0,0.1
1.1112134,0.11114103,63.54690026599646,1150.0,0.1
1.1145021,0.1114699,63.57117830817451,1150.0,0.1
1.1158781999999998,0.11160751,63.595787183204784,1150.0,0.1
1.1178523999999999,0.11180493,63.62425191491692,1150.0,0.1
1.120246,0.11204429,63.648549871670696,1150.0,0.1
1.1226996,0.11228965,63.66756628490177,1150.0,0.1
1.1253342,0.11255311,63.68694076843208,1150.0,0.1
1.126232,0.11264289,63.70800757997374,1150.0,0.1
1.1286871,0.1128884,63.73249357179951,1150.0,0.1
1.1314433,0.11316402,63.75317734537903,1150.0,0.1
1.133959,0.11341559,63.77424257947372,1150.0,0.1
1.1352176999999999,0.11354146,63.804535745348744,1150.0,0.1
1.1379757,0.11381726,63.83283031765934,1150.0,0.1
1.1401339,0.11403308,63.85628104370478,1150.0,0.1
1.1424722999999999,0.11426692,63.88291920606843,1150.0,0.1
1.1448717,0.11450686,63.90849900544344,1150.0,0.1
1.1464923,0.11466892,63.933329257371476,1150.0,0.1
1.148712,0.11489089,63.95461257901161,1150.0,0.1
1.1516535,0.11518504,63.972698392064636,1150.0,0.1
1.1538753,0.11540722,64.00148117269343,1150.0,0.1
1.1554367,0.11556336,64.02797840354191,1150.0,0.1
1.1575379,0.11577348,64.05095192247374,1150.0,0.1
1.1594013,0.11595982,64.07261386007221,1150.0,0.1
1.1622255,0.11624224,64.0868159952389,1150.0,0.1
1.1637871,0.1163984,64.1048378197654,1150.0,0.1
1.1663728,0.11665697,64.1249114348942,1150.0,0.1
1.1684765,0.11686734,64.14337806068586,1150.0,0.1
1.1711829,0.11713798,64.162725550148,1150.0,0.1
1.1733493000000002,0.11735462,64.18064109093963,1150.0,0.1
1.1744317,0.11746286,64.20860569463284,1150.0,0.1
1.1772602,0.11774571,64.2337176356442,1150.0,0.1
1.1800298,0.11802267,64.25652471031465,1150.0,0.1
1.1821363,0.11823332,64.28013129600782,1150.0,0.1
1.1832207000000001,0.11834176,64.3051187537086,1150.0,0.1
1.1857495999999998,0.11859465,64.33354655949647,1150.0,0.1
1.1882203,0.11884172,64.35757500791313,1150.0,0.1
1.1901491,0.1190346,64.38154450192451,1150.0,0.1
1.1918358,0.11920327,64.4108131650154,1150.0,0.1
1.1943679,0.11945648,64.43882255080706,1150.0,0.1
1.1965384,0.11967353,64.457688818451,1150.0,0.1
1.1993133,0.11995102,64.48021895568587,1150.0,0.1
1.2014848,0.12016817,64.51038778130328,1150.0,0.1
1.2029328000000001,0.12031297,64.53344229122752,1150.0,0.1
1.2056485000000001,0.12058454,64.55779629276918,1150.0,0.1
1.2078824,0.12080793,64.57877749830328,1150.0,0.1
1.2105994,0.12107963,64.59673381570101,1150.0,0.1
1.2116859,0.12118828,64.62396697136766,1150.0,0.1
1.214042,0.12142389,64.65022216328056,1150.0,0.1
1.2165187,0.12167156,64.68028152110253,1150.0,0.1
1.2200245,0.12202214,64.70266463043207,1150.0,0.1
1.2210519,0.12212488,64.72978920837525,1150.0,0.1
1.2228048999999999,0.12230018,64.76116624892829,1150.0,0.1
1.2249815,0.12251784,64.7834567853904,1150.0,0.1
1.227462,0.12276589,64.80587784452679,1150.0,0.1
1.2298809,0.12300778,64.82474525050026,1150.0,0.1
1.2308493,0.12310462,64.84910960614418,1150.0,0.1
1.2333311999999998,0.12335281,64.8716476927048,1150.0,0.1
1.2359339999999999,0.12361309,64.89286806206086,1150.0,0.1
1.2385975,0.12387944,64.9142925576063,1150.0,0.1
1.2407174,0.12409143,64.94352296118585,1150.0,0.1
1.2424749,0.12426718,64.97548034730329,1150.0,0.1
1.2445945999999999,0.12447915,64.99473291602676,1150.0,0.1
1.2475645,0.12477614,65.02170106631466,1150.0,0.1
1.2501108,0.12503077,65.04665537348511,1150.0,0.1
1.2507168,0.12509137,65.07278160804192,1150.0,0.1
1.2533241,0.1253521,65.10340551268207,1150.0,0.1
1.2555687,0.12557656,65.12895906554192,1150.0,0.1
1.2587837,0.12589806,65.15031435945481,1150.0,0.1
1.2610897,0.12612866,65.16949930768207,1150.0,0.1
1.2626077,0.12628046,65.19024366626162,1150.0,0.1
1.2644281,0.1264625,65.20953787092449,1150.0,0.1
1.2669183999999998,0.12671153,65.21916170238282,1150.0,0.1
1.2701986,0.12703955,65.23261830734496,1150.0,0.1
1.2706841,0.1270881,65.24785584396994,1150.0,0.1
1.2737221,0.1273919,65.26845605619722,1150.0,0.1
1.2758494,0.12760463,65.28131887999649,1150.0,0.1
1.278098,0.12782949,65.30575046721616,1150.0,0.1
1.2798622,0.12800591,65.32769818020101,1150.0,0.1
1.2819908,0.12821877,65.35306764228434,1150.0,0.1
1.2846666,0.12848635,65.37533450970479,1150.0,0.1
1.2872224,0.12874193,65.39885972200783,1150.0,0.1
1.2896569,0.12898538,65.42280635726163,1150.0,0.1
1.2903873000000001,0.12905842,65.44649634053813,1150.0,0.1
1.2930652999999999,0.12932622,65.47228941359117,1150.0,0.1
1.2956231,0.129582,65.49636111547753,1150.0,0.1
1.2978772,0.12980741,65.51482542064801,1150.0,0.1
1.2991568,0.12993537,65.53464574662524,1150.0,0.1
1.3017767,0.13019736,65.55556870521237,1150.0,0.1
1.3042136,0.13044105,65.57530080778812,1150.0,0.1
1.3064696999999998,0.13066666,65.58154519252678,1150.0,0.1
1.3096406,0.13098375,65.58944175389419,1150.0,0.1
1.3101292999999998,0.13103262,65.59787864121616,1150.0,0.1
1.3129347,0.13131316,65.61085788272375,1150.0,0.1
1.315315,0.13155119,65.62748155602677,1150.0,0.1
1.3180614,0.13182583,65.63930491797754,1150.0,0.1
1.3192817,0.13194786,65.66210277416313,1150.0,0.1
1.3211137999999998,0.13213107,65.67481003638282,1150.0,0.1
1.3241669999999999,0.13243639,65.68625815062526,1150.0,0.1
1.3270381999999998,0.13272351,65.69830978490556,1150.0,0.1
1.3290545999999999,0.13292515,65.71576510582221,1150.0,0.1
1.3305212000000002,0.13307181,65.72850880412146,1150.0,0.1
1.332782,0.13329789,65.74242116668964,1150.0,0.1
1.3349837999999998,0.13351807,65.76337990594723,1150.0,0.1
1.3377356,0.13379325,65.78297673992827,1150.0,0.1
1.3392642000000001,0.13394611,65.800826235148,1150.0,0.1
1.3414056,0.13416025,65.81777042422374,1150.0,0.1
1.3437308,0.13439277,65.83076767353057,1150.0,0.1
1.3461172000000001,0.13463141,65.83965696769722,1150.0,0.1
1.3478933,0.13480902,65.84615789669346,1150.0,0.1
1.3499139,0.13501108,65.85928788523888,1150.0,0.1
1.3527925,0.13529894,65.87807861665556,1150.0,0.1
1.3549357,0.13551326,65.89873306994343,1150.0,0.1
1.3566514,0.13568483,65.92296045189798,1150.0,0.1
1.3584902,0.13586871,65.94638612038284,1150.0,0.1
1.3611878000000002,0.13613847,65.97175170396238,1150.0,0.1
1.3632111,0.1363408,65.9810849586101,1150.0,0.1
1.365725,0.13659219,65.99449894821619,1150.0,0.1
1.3674426999999998,0.13676396,66.01200620343205,1150.0,0.1
1.3695281,0.1369725,66.03153771350404,1150.0,0.1
1.371676,0.13718729,66.04627983611768,1150.0,0.1
1.3748057,0.13750026,66.06052185193965,1150.0,0.1
1.3769547,0.13771516,66.08467907541691,1150.0,0.1
1.3781823,0.13783792,66.1014402513639,1150.0,0.1
1.380455,0.13806519,66.11535418926921,1150.0,0.1
1.3830353999999998,0.13832323,66.13083738947753,1150.0,0.1
1.3854312,0.13856281,66.14854711899645,1150.0,0.1
1.3865988999999999,0.13867958,66.17116995859875,1150.0,0.1
1.3898575,0.13900544,66.18947684943205,1150.0,0.1
1.3919477,0.13921446,66.210933663326,1150.0,0.1
1.3943467,0.13945436,66.23706834481465,1150.0,0.1
1.3969917,0.13971886,66.26204078264041,1150.0,0.1
1.3980374999999998,0.13982344,66.28943920655708,1150.0,0.1
1.4005602,0.14007571,66.31116951982979,1150.0,0.1
1.4033301,0.1403527,66.32298809338283,1150.0,0.1
1.4056085999999999,0.14058055,66.3359012625154,1150.0,0.1
1.4067175,0.14069144,66.35140546653057,1150.0,0.1
1.4097347,0.14099316,66.36572797834495,1150.0,0.1
1.4113366,0.14115335,66.38217995268965,1150.0,0.1
1.4143563,0.14145532,66.3907413384321,1150.0,0.1
1.4154662,0.14156631,66.39653827927678,1150.0,0.1
1.4176229999999999,0.14178199,66.41220819750026,1150.0,0.1
1.4203363,0.14205332,66.41895489149647,1150.0,0.1
1.4225564,0.14227533,66.43228131448511,1150.0,0.1
1.4255173,0.14257142,66.44546901253057,1150.0,0.1
1.427184,0.14273809,66.46049479915177,1150.0,0.1
1.4289735,0.14291704,66.47629114837146,1150.0,0.1
1.4319986,0.14321955,66.48851354230707,1150.0,0.1
1.4343449,0.14345418,66.51087021117073,1150.0,0.1
1.4355795,0.14357764,66.52495016881845,1150.0,0.1
1.4379890999999998,0.1438186,66.54087391413663,1150.0,0.1
1.4404594,0.14406563,66.55970378000784,1150.0,0.1
1.4423137,0.14425106,66.57795166491692,1150.0,0.1
1.4454667,0.14456636,66.58923896352678,1150.0,0.1
1.4469504000000002,0.14471473,66.60913177379192,1150.0,0.1
1.4491151,0.1449312,66.6229621458033,1150.0,0.1
1.4512801,0.1451477,66.64044168984874,1150.0,0.1
1.4538162000000001,0.14540131,66.6553027939207,1150.0,0.1
1.4555491,0.1455746,66.66948004693585,1150.0,0.1
1.4566636000000002,0.14568605,66.6819704812048,1150.0,0.1
1.4596959,0.14598928,66.6958594096139,1150.0,0.1
1.4620487,0.14622456,66.70360440392072,1150.0,0.1
1.4640311,0.1464228,66.71030502439041,1150.0,0.1
1.4663222999999999,0.14665192,66.71872691093965,1150.0,0.1
1.468925,0.14691219,66.72943777180708,1150.0,0.1
1.47128,0.14714769,66.73503358627678,1150.0,0.1
1.473574,0.14737709,66.74794182553813,1150.0,0.1
1.4749377000000001,0.14751346,66.7604123025192,1150.0,0.1
1.4776041999999998,0.14778011,66.77063965068966,1150.0,0.1
1.4803339,0.14805308,66.78288408081467,1150.0,0.1
1.4824430000000002,0.14826399,66.7998811700495,1150.0,0.1
1.4841807999999999,0.14843777,66.80851529256087,1150.0,0.1
1.4862908000000001,0.14864877,66.81945794805709,1150.0,0.1
1.4885255,0.14887224,66.83302079204192,1150.0,0.1
1.4907618999999999,0.14909588,66.84923835906086,1150.0,0.1
1.4936813,0.14938782,66.86239636261769,1150.0,0.1
1.4946127999999999,0.14948097,66.87672912522375,1150.0,0.1
1.4968495,0.14970464,66.88879752615557,1150.0,0.1
1.4997707,0.14999676,66.8916664964283,1150.0,0.1
1.5018839999999998,0.15020809,66.90166952804192,1150.0,0.1
1.5032526,0.15034495,66.90977018156464,1150.0,0.1
1.5053665,0.15055634,66.91209484924269,1150.0,0.1
1.5081657,0.15083626,66.91937879973511,1150.0,0.1
1.5104681999999998,0.15106651,66.92918138052299,1150.0,0.1
1.5122109,0.15124078,66.93471548009497,1150.0,0.1
1.5143267,0.15145236,66.95134514084117,1150.0,0.1
1.5171283,0.15173252,66.9658639914548,1150.0,0.1
1.51937,0.15195669,66.98043657770481,1150.0,0.1
1.5219865000000001,0.15221834,66.99255745190938,1150.0,0.1
1.5226721,0.1522869,67.01016491270482,1150.0,0.1
1.5253502,0.15255471,67.02224224731845,1150.0,0.1
1.5280312,0.15282281,67.03970986492071,1150.0,0.1
1.5305868999999999,0.15307838,67.05305788982224,1150.0,0.1
1.5317717,0.15319686,67.06781591387147,1150.0,0.1
1.5345163,0.15347132,67.07907219276163,1150.0,0.1
1.5362632,0.15364601,67.09020552326919,1150.0,0.1
1.5391959000000002,0.15393928,67.09568549500027,1150.0,0.1
1.5404435,0.15406404,67.09872399744722,1150.0,0.1
1.5428773999999998,0.15430743,67.10846262552676,1150.0,0.1
1.5447507,0.15449476,67.11203214783359,1150.0,0.1
1.5481232999999999,0.15483202,67.1164324588639,1150.0,0.1
1.5498726,0.15500695,67.12385058873892,1150.0,0.1
1.5513719,0.15515688,67.13354540697374,1150.0,0.1
1.5539336,0.15541305,67.13900475584495,1150.0,0.1
1.556559,0.15567559,67.15245996459117,1150.0,0.1
1.5593093,0.15595062,67.16699310889041,1150.0,0.1
1.5603734,0.15605703,67.17898890979951,1150.0,0.1
1.5626878000000002,0.15628847,67.19614193543588,1150.0,0.1
1.5653146,0.15655115,67.21498008925406,1150.0,0.1
1.5670669,0.15672638,67.2273100256745,1150.0,0.1
1.5701961,0.1570393,67.24481664829193,1150.0,0.1
1.5711358999999998,0.15713328,67.26323889634496,1150.0,0.1
1.5740778000000002,0.15742747,67.27714843260254,1150.0,0.1
1.5763322,0.15765291,67.28903535493586,1150.0,0.1
1.5789636,0.15791605,67.30106315037906,1150.0,0.1
1.580092,0.15802889,67.31445272613664,1150.0,0.1
1.582411,0.15826079,67.31997322009875,1150.0,0.1
1.5852941,0.1585491,67.32946052584117,1150.0,0.1
1.5876133,0.15878102,67.33727123059874,1150.0,0.1
1.5884291999999998,0.15886261,67.34689878650025,1150.0,0.1
1.591126,0.15913229,67.35486892630331,1150.0,0.1
1.5945141999999999,0.15947111,67.35944379094724,1150.0,0.1
1.5960835999999998,0.15962805,67.36565482954951,1150.0,0.1
1.598719,0.15989159,67.37058822714421,1150.0,0.1
1.6000376,0.16002345,67.37731662195104,1150.0,0.1
1.6024871,0.1602684,67.38259472403057,1150.0,0.1
1.6051876999999999,0.16053846,67.39236560601162,1150.0,0.1
1.6073869,0.16075838,67.40260854237906,1150.0,0.1
1.6085807,0.16087776,67.40845895878056,1150.0,0.1
1.6112831,0.161148,67.41850855667072,1150.0,0.1
1.6135457999999998,0.16137427,67.42752407610632,1150.0,0.1
1.616439,0.16166359,67.43316456266693,1150.0,0.1
1.6186395,0.16188364,67.44547820607602,1150.0,0.1
1.6197086,0.16199055,67.45978769936393,1150.0,0.1
1.622415,0.16226119,67.46915682356466,1150.0,0.1
1.6253095,0.16255064,67.46887507345102,1150.0,0.1
1.6271986,0.16273955,67.47904648984496,1150.0,0.1
1.6282062,0.16284031,67.48668118356088,1150.0,0.1
1.6311024,0.16312993,67.49445003409873,1150.0,0.1
1.6334332999999999,0.16336302,67.49969326597754,1150.0,0.1
1.6361424,0.16363393,67.50448888891691,1150.0,0.1
1.6367097,0.16369066,67.51151470037527,1150.0,0.1
1.6399234,0.16401203,67.51502042967451,1150.0,0.1
1.6421303,0.16423272,67.5226204395495,1150.0,0.1
1.6448415,0.16450384,67.52539131181466,1150.0,0.1
1.6472384,0.16474353,67.52926891687525,1150.0,0.1
1.6487523,0.16489492,67.53616222275028,1150.0,0.1
1.6512139,0.16514108,67.53541678767073,1150.0,0.1
1.6536122,0.16538091,67.53834305919345,1150.0,0.1
1.6559472,0.16561441,67.54196023017451,1150.0,0.1
1.6575263,0.16577232,67.54465639743587,1150.0,0.1
1.6598635,0.16600604,67.55139086376921,1150.0,0.1
1.6619482,0.16621451,67.55166374482981,1150.0,0.1
1.6647275999999998,0.16649245,67.55374178925406,1150.0,0.1
1.6665613,0.16667582,67.55565498154571,1150.0,0.1
1.6682675,0.16684644,67.55991056240178,1150.0,0.1
1.6703538,0.16705507,67.5658038127692,1150.0,0.1
1.6729462,0.16731431,67.57152435629192,1150.0,0.1
1.6754765,0.16756734,67.57547496437904,1150.0,0.1
1.6765518,0.16767487,67.58068490787906,1150.0,0.1
1.6792097,0.16794066,67.58553934473511,1150.0,0.1
1.6812354999999999,0.16814324,67.58624126337905,1150.0,0.1
1.6842099000000001,0.16844068,67.5894543168336,1150.0,0.1
1.6852234000000001,0.16854203,67.58912251953815,1150.0,0.1
1.6878837,0.16880806,67.59477434320102,1150.0,0.1
1.6904176,0.16906145,67.60033349907224,1150.0,0.1
1.6928254,0.16930223,67.60139973009875,1150.0,0.1
1.6958033,0.16960002,67.60789804936769,1150.0,0.1
1.6967549,0.16969518,67.61852608773131,1150.0,0.1
1.6995451999999998,0.16997421,67.62073622465935,1150.0,0.1
1.7017011,0.1701898,67.62525243037148,1150.0,0.1
1.7039216,0.17041185,67.625934012576,1150.0,0.1
1.7054441,0.1705641,67.63047006867451,1150.0,0.1
1.7076012999999999,0.17077982,67.64049400673132,1150.0,0.1
1.7102674999999998,0.17104644,67.64710478457981,1150.0,0.1
1.7129343000000001,0.17131312,67.65956682481846,1150.0,0.1
1.7152203000000001,0.17154172,67.66401555405331,1150.0,0.1
1.7164902,0.17166871,67.67345789771996,1150.0,0.1
1.7185866,0.17187835,67.67935418580329,1150.0,0.1
1.720875,0.17210719,67.68751403392072,1150.0,0.1
1.7234805999999998,0.17236775,67.69352490092452,1150.0,0.1
1.7247514,0.17249483,67.70561069967071,1150.0,0.1
1.7274853,0.17276822,67.7164089195495,1150.0,0.1
1.7299662,0.17301631,67.7290245396139,1150.0,0.1
1.7321287,0.17323256,67.74022462119723,1150.0,0.1
1.7333375999999998,0.17335345,67.7461549145836,1150.0,0.1
1.7356926,0.17358895,67.75451901713662,1150.0,0.1
1.7386211999999999,0.17388181,67.76198195453813,1150.0,0.1
1.7412313,0.17414282,67.75640271713662,1150.0,0.1
1.7430779,0.17432748,67.75947791537148,1150.0,0.1
1.7445430999999998,0.174474,67.75843090521995,1150.0,0.1
1.7477917,0.17479886,67.76223401716693,1150.0,0.1
1.7497672,0.17499641,67.77027663634118,1150.0,0.1
1.7521892,0.17523861,67.77202680488662,1150.0,0.1
1.7534649,0.17536618,67.77458663949648,1150.0,0.1
1.7562067,0.17564036,67.77147097701541,1150.0,0.1
1.758567,0.17587639,67.77704603581465,1150.0,0.1
1.760928,0.17611249,67.778491768523,1150.0,0.1
1.7638627999999998,0.17640597,67.78595681037906,1150.0,0.1
1.7647565,0.17649534,67.78796464125027,1150.0,0.1
1.7674368,0.17676337,67.79234838124268,1150.0,0.1
1.7697364,0.17699333,67.79777783419343,1150.0,0.1
1.7720355,0.17722324,67.80113820447376,1150.0,0.1
1.773377,0.17735739,67.80546899265558,1150.0,0.1
1.7758049,0.17760018,67.80647776582222,1150.0,0.1
1.7782965999999998,0.17784935,67.81257024206084,1150.0,0.1
1.7811097999999999,0.17813067,67.81778485231465,1150.0,0.1
1.7832833,0.17834802,67.81492934390178,1150.0,0.1
1.784563,0.17847599,67.81723272973308,1150.0,0.1
1.7871217,0.17873186,67.82213240714678,1150.0,0.1
1.789681,0.17898779,67.8273572513536,1150.0,0.1
1.7918564,0.17920533,67.8328288133044,1150.0,0.1
1.7933923999999999,0.17935893,67.83846864395004,1150.0,0.1
1.7955051000000002,0.1795702,67.84419829424137,1150.0,0.1
1.7988985,0.17990954,67.84993931512925,1150.0,0.1
1.8003085,0.18005054,67.85561325756454,1150.0,0.1
1.8026780999999998,0.1802875,67.86114167249812,1150.0,0.1
1.8042156999999999,0.18044126,67.86644611088083,1150.0,0.1