File: datasets/steel_spring/csv/BS2V-1100-0.01.csv
Time(s),Strain(%),Stress(MPa),Temp(C),SR(%/s)
0.0,5.22e-06,0.43572736356239733,1100.0,0.01
0.001614,2.136e-05,0.2986263062495951,1100.0,0.01
0.002146,2.668e-05,0.15004496428000152,1100.0,0.01
0.0042910000000000005,4.813e-05,0.07924355995899551,1100.0,0.01
0.004823,5.345e-05,0.17548231559195598,1100.0,0.01
0.006698,7.219999999999999e-05,0.7249842562670511,1100.0,0.01
0.0072395,7.761500000000001e-05,1.6535080363409156,1100.0,0.01
0.009114500000000001,9.6365e-05,2.9816410185341007,1100.0,0.01
0.012594000000000001,0.00013116,4.638167981761377,1100.0,0.01
0.019022499999999998,0.00019544499999999998,6.538865880734868,1100.0,0.01
0.023841499999999995,0.00024363499999999997,8.490814710240555,1100.0,0.01
0.029733999999999997,0.00030256,10.358338268594727,1100.0,0.01
0.037773,0.00038294999999999996,12.282920411604207,1100.0,0.01
0.0444735,0.00044995500000000004,14.178086470736801,1100.0,0.01
0.054119,0.00054641,16.183186495437575,1100.0,0.01
0.067518,0.0006804000000000001,18.15143945918947,1100.0,0.01
0.07877600000000001,0.00079298,20.06564865844138,1100.0,0.01
0.09057300000000001,0.00091095,21.806273997623197,1100.0,0.01
0.105051,0.00105573,23.299329365950857,1100.0,0.01
0.12086649999999999,0.001213885,24.505978552956538,1100.0,0.01
0.139907,0.0014042899999999999,25.369442418001995,1100.0,0.01
0.15734399999999998,0.00157866,25.924524427553127,1100.0,0.01
0.17665799999999998,0.0017718,26.241674745195166,1100.0,0.01
0.19705050000000002,0.0019757250000000002,26.40461959035426,1100.0,0.01
0.217181,0.00217703,26.487765426329638,1100.0,0.01
0.23543549999999996,0.002359575,26.561625372172443,1100.0,0.01
0.2534225,0.002539445,26.64839850505882,1100.0,0.01
0.27221699999999993,0.00272739,26.774090284136477,1100.0,0.01
0.28725899999999993,0.0028778099999999997,26.943337309164896,1100.0,0.01
0.3014985,0.0030202049999999998,27.146130190119457,1100.0,0.01
0.31976899999999997,0.00320291,27.392318734615664,1100.0,0.01
0.3418055,0.003423275,27.66136656863079,1100.0,0.01
0.3603495,0.003608715,27.966702386625116,1100.0,0.01
0.37539999999999996,0.0037592199999999997,28.289666563822067,1100.0,0.01
0.3907244999999999,0.003912465,28.610388830473603,1100.0,0.01
0.4068615,0.004073835,28.934262857000114,1100.0,0.01
0.42756799999999995,0.004280900000000001,29.248814817882693,1100.0,0.01
0.450701,0.004512230000000001,29.541721234426266,1100.0,0.01
0.4695375,0.004700595,29.830349387566425,1100.0,0.01
0.4840655,0.0048458749999999995,30.120407509515285,1100.0,0.01
0.5020975,0.005026195,30.385759548246316,1100.0,0.01
0.5249805,0.005255025,30.63056946142434,1100.0,0.01
0.5465225,0.005470445,30.8528913029035,1100.0,0.01
0.5659164999999999,0.005664384999999999,31.05606979742625,1100.0,0.01
0.5842354999999999,0.005847575,31.239586552725484,1100.0,0.01
0.6017454999999999,0.006022675,31.40476295392437,1100.0,0.01
0.620338,0.0062086,31.561366387608093,1100.0,0.01
0.641366,0.00641888,31.709657753153557,1100.0,0.01
0.6613135,0.006618355,31.860310956793704,1100.0,0.01
0.6809925,0.006815145,32.00776297862512,1100.0,0.01
0.6993320000000001,0.00699854,32.14793604869897,1100.0,0.01
0.71255,0.00713072,32.278117897197035,1100.0,0.01
0.7338609999999999,0.00734383,32.41443775372924,1100.0,0.01
0.7589535,0.007594755,32.55388643780881,1100.0,0.01
0.7746095,0.007751315,32.696472356759564,1100.0,0.01
0.7905359999999999,0.00791058,32.83593468190543,1100.0,0.01
0.8110539999999999,0.00811576,32.966535925062644,1100.0,0.01
0.83239,0.008329119999999999,33.093931262543684,1100.0,0.01
0.8529164999999999,0.008534384999999999,33.234244866630796,1100.0,0.01
0.8720969999999999,0.00872619,33.37321804048876,1100.0,0.01
0.8918225,0.008923445,33.50599523832208,1100.0,0.01
0.9112784999999999,0.009118005,33.632438230403565,1100.0,0.01
0.931012,0.00931534,33.757554542316484,1100.0,0.01
0.9502074999999999,0.009507294999999999,33.87177117983925,1100.0,0.01
0.9702169999999999,0.00970739,33.97259964792831,1100.0,0.01
0.991045,0.00991567,34.07692536196998,1100.0,0.01
1.0105255,0.010110475,34.177437721935824,1100.0,0.01
1.02811,0.01028632,34.28235197114032,1100.0,0.01
1.0454295,0.010459514999999999,34.387953089358106,1100.0,0.01
1.065458,0.0106598,34.489098908235,1100.0,0.01
1.0863015,0.010868235,34.58411484286378,1100.0,0.01
1.107154,0.01107676,34.680703676716064,1100.0,0.01
1.1288225,0.011293445,34.767473650003964,1100.0,0.01
1.1485980000000002,0.0114912,34.86079725133161,1100.0,0.01
1.1683780000000001,0.011689,34.96103011410056,1100.0,0.01
1.1903285000000001,0.011908505,35.06095168625207,1100.0,0.01
1.207402,0.01207924,35.158734748587285,1100.0,0.01
1.226377,0.01226899,35.26101498471987,1100.0,0.01
1.248614,0.01249136,35.36089089866495,1100.0,0.01
1.266515,0.01267037,35.46374664305886,1100.0,0.01
1.2868575,0.012873795,35.56372199556453,1100.0,0.01
1.30829,0.01308812,35.65332668106068,1100.0,0.01
1.3234885000000003,0.013240105,35.742074701621284,1100.0,0.01
1.3416775,0.013421994999999999,35.82009087865919,1100.0,0.01
1.3674724999999999,0.013679944999999999,35.89078696547741,1100.0,0.01
1.388378,0.013888999999999999,35.960946043454705,1100.0,0.01
1.40576,0.01406282,36.02494340912902,1100.0,0.01
1.4250470000000002,0.01425569,36.08899021898511,1100.0,0.01
1.445966,0.01446488,36.15717025519908,1100.0,0.01
1.4658045,0.014663265,36.217513235119476,1100.0,0.01
1.4837445,0.014842665,36.272178869594875,1100.0,0.01
1.5027765,0.015032984999999999,36.327368343988695,1100.0,0.01
1.524531,0.01525053,36.39196890099246,1100.0,0.01
1.54384,0.01544362,36.47033069379543,1100.0,0.01
1.563969,0.015644909999999998,36.56437640521013,1100.0,0.01
1.584101,0.01584623,36.65924043558326,1100.0,0.01
1.600157,0.01600679,36.7623097884526,1100.0,0.01
1.6219325,0.016224545,36.84714537381807,1100.0,0.01
1.6453435,0.016458655000000003,36.909054952732866,1100.0,0.01
1.664406,0.016649280000000002,36.96594027087886,1100.0,0.01
1.6842885,0.016848105000000002,37.0169701070588,1100.0,0.01
1.7049905,0.017055125,37.067726919985034,1100.0,0.01
1.7221570000000002,0.01722679,37.11596629205135,1100.0,0.01
1.7401430000000002,0.017406650000000003,37.16849408650783,1100.0,0.01
1.7624905000000002,0.017630125,37.230114239937755,1100.0,0.01
1.7843005,0.017848225,37.30621714652865,1100.0,0.01
1.8036655000000001,0.018041875,37.383593298337345,1100.0,0.01
1.823024,0.01823546,37.46311607189787,1100.0,0.01
1.8434795,0.018440014999999997,37.535237675098664,1100.0,0.01
1.863944,0.01864466,37.59731285374634,1100.0,0.01
1.884684,0.01885206,37.65939496785053,1100.0,0.01
1.9057035,0.019062255,37.71323676666869,1100.0,0.01
1.9209930000000002,0.01921515,37.76674275219716,1100.0,0.01
1.93901,0.01939532,37.82944640999451,1100.0,0.01
1.961677,0.01962199,37.905447409134624,1100.0,0.01
1.9821654999999998,0.019826875,37.98824169014787,1100.0,0.01
2.0032055,0.020037275,38.064862883208335,1100.0,0.01
2.0247975,0.020253195,38.11947722647154,1100.0,0.01
2.043928,0.0204445,38.16866958511737,1100.0,0.01
2.061696,0.02062218,38.21693927861929,1100.0,0.01
2.0813865,0.020819085,38.269393953363654,1100.0,0.01
2.100256,0.02100778,38.325282560363824,1100.0,0.01
2.1218645,0.021223865,38.38656531024271,1100.0,0.01
2.143753,0.02144275,38.451715166771166,1100.0,0.01
2.1640024999999996,0.021645245,38.51490329067081,1100.0,0.01
2.1853524999999996,0.021858745,38.5773504668128,1100.0,0.01
2.2067075,0.022072295,38.64176197655895,1100.0,0.01
2.2253285,0.022258505,38.71059442297369,1100.0,0.01
2.2447749999999997,0.022452970000000003,38.768160522645985,1100.0,0.01
2.2655934999999996,0.022661155000000002,38.82413954461761,1100.0,0.01
2.2842259999999994,0.02284748,38.871676584354326,1100.0,0.01
2.3025849999999997,0.02303107,38.92004001004181,1100.0,0.01
2.321497,0.02322019,38.95458310465739,1100.0,0.01
2.3428804999999997,0.023434025,38.97739433345665,1100.0,0.01
2.360157,0.023606790000000002,39.022282702013484,1100.0,0.01
2.378808,0.0237933,39.09647510468381,1100.0,0.01
2.399654,0.024001759999999997,39.183432270375135,1100.0,0.01
2.4194059999999995,0.02419928,39.26431677182215,1100.0,0.01
2.4402609999999996,0.02440783,39.3425096139073,1100.0,0.01
2.46277,0.02463292,39.396614294638226,1100.0,0.01
2.4850060000000003,0.02485528,39.444215987793406,1100.0,0.01
2.5036795,0.025042015,39.47761506168555,1100.0,0.01
2.5223569999999995,0.02522879,39.50271890667606,1100.0,0.01
2.5437839999999996,0.02544306,39.544566921272754,1100.0,0.01
2.5616399999999997,0.02562162,39.600977387001855,1100.0,0.01
2.5792275,0.025797495,39.66620884761176,1100.0,0.01
2.6020405,0.026025625,39.722456656598574,1100.0,0.01
2.6223825,0.026229045,39.77627297343948,1100.0,0.01
2.6413599999999997,0.026418820000000003,39.812952390483055,1100.0,0.01
2.6617105,0.026622325000000002,39.85764909581445,1100.0,0.01
2.681241,0.026817630000000002,39.91822945865174,1100.0,0.01
2.6999515,0.027004735000000002,39.98174401961756,1100.0,0.01
2.722241,0.027227630000000003,40.0487959305058,1100.0,0.01
2.7439834999999997,0.027445055000000003,40.12175501204906,1100.0,0.01
2.761876,0.02762398,40.195450018193014,1100.0,0.01
2.7789465,0.027794685,40.261126276776544,1100.0,0.01
2.7968504999999997,0.027973725,40.32063613107773,1100.0,0.01
2.8169595,0.028174815,40.38733834728424,1100.0,0.01
2.8362419999999995,0.02836764,40.4464289571063,1100.0,0.01
2.8563589999999994,0.02856881,40.51112309322752,1100.0,0.01
2.8767579999999997,0.0287728,40.580149947528405,1100.0,0.01
2.8963305,0.028968525000000002,40.64332581642029,1100.0,0.01
2.915076,0.029155979999999998,40.68675281441834,1100.0,0.01
2.9343779999999997,0.029349,40.70849810486541,1100.0,0.01
2.9569979999999996,0.0295752,40.73294788008893,1100.0,0.01
2.976591,0.02977113,40.75538853738631,1100.0,0.01
2.9978375,0.029983595000000002,40.79426796564966,1100.0,0.01
3.018534,0.030190559999999998,40.844625269011566,1100.0,0.01
3.037861,0.03038383,40.91353470750596,1100.0,0.01
3.0569165,0.030574385000000003,40.99334983390367,1100.0,0.01
3.072104,0.03072626,41.06063314059124,1100.0,0.01
3.0911619999999997,0.03091684,41.10571657900799,1100.0,0.01
3.1149249999999995,0.03115447,41.126954238297586,1100.0,0.01
3.1367529999999997,0.031372750000000005,41.16154773821023,1100.0,0.01
3.1552695,0.031557915000000006,41.1879707018749,1100.0,0.01
3.1737895,0.031743115,41.24739607887851,1100.0,0.01
3.193695,0.031942170000000006,41.325755755406966,1100.0,0.01
3.2133295000000004,0.032138515000000006,41.39829018949997,1100.0,0.01
3.232694,0.03233216,41.45243862950196,1100.0,0.01
3.2517869999999998,0.032523090000000004,41.49677459346234,1100.0,0.01
3.2714334999999997,0.032719555,41.53526343595115,1100.0,0.01
3.2957884999999996,0.032963105,41.55995181600975,1100.0,0.01
3.3162719999999997,0.03316794,41.58836811532036,1100.0,0.01
3.333163,0.03333685,41.63482183522554,1100.0,0.01
3.3517159999999997,0.033522380000000004,41.70599961388261,1100.0,0.01
3.3708275,0.033713494999999996,41.78744758998478,1100.0,0.01
3.3885574999999992,0.033890795,41.85320316552457,1100.0,0.01
3.410171,0.03410693,41.89047212297147,1100.0,0.01
3.4356745,0.034361965,41.929385349729245,1100.0,0.01
3.456187,0.034567089999999995,41.96596364382988,1100.0,0.01
3.4728209999999997,0.034733429999999996,41.99520991820129,1100.0,0.01
3.4933419999999997,0.03493864,42.01540985618437,1100.0,0.01
3.513591,0.03514113,42.05036048360853,1100.0,0.01
3.53024,0.03530762,42.10345812423525,1100.0,0.01
3.5521594999999997,0.035526815,42.163498068521086,1100.0,0.01
3.572139999999999,0.03572662,42.21391596338272,1100.0,0.01
3.59185,0.03592372,42.25605605807578,1100.0,0.01
3.612675,0.03613197,42.31481942445283,1100.0,0.01
3.631004,0.03631526,42.373517166570416,1100.0,0.01
3.6523889999999994,0.036529110000000004,42.431334217761915,1100.0,0.01
3.6710009999999995,0.03671523,42.48058785264064,1100.0,0.01
3.690174,0.03690696,42.527209119178345,1100.0,0.01
3.710463,0.03710985,42.57322426413102,1100.0,0.01
3.7279774999999997,0.037284995,42.60720641752682,1100.0,0.01
3.7482744999999995,0.037487965,42.638664469784366,1100.0,0.01
3.7674609999999995,0.03767983,42.67853863464034,1100.0,0.01
3.7844284999999998,0.037849505,42.74093066423496,1100.0,0.01
3.8061279999999997,0.0380665,42.80667865163829,1100.0,0.01
3.8294984999999997,0.038300205000000004,42.874192951412816,1100.0,0.01
3.8498159999999997,0.038503380000000004,42.92069700656038,1100.0,0.01
3.8704139999999994,0.03870936,42.96824242972311,1100.0,0.01
3.8887899999999997,0.03889312,42.99224136666245,1100.0,0.01
3.9110699999999996,0.03911592,43.00891415804498,1100.0,0.01
3.9314035,0.039319255,43.02622331211896,1100.0,0.01
3.9472835,0.039478055,43.056316793749716,1100.0,0.01
3.9684595,0.039689815,43.11395322714194,1100.0,0.01
3.9899214999999995,0.039904435,43.183621397547405,1100.0,0.01
4.009713,0.040102349999999995,43.25608720993945,1100.0,0.01
4.026163,0.04026685,43.308353937295394,1100.0,0.01
4.043175,0.04043697,43.36663369134079,1100.0,0.01
4.065207,0.04065729,43.398658981469495,1100.0,0.01
4.0861255,0.040866475,43.41151269312122,1100.0,0.01
4.103147,0.04103669,43.42907349887507,1100.0,0.01
4.124916,0.04125438,43.4499947660192,1100.0,0.01
4.147807,0.041483290000000006,43.47976783884513,1100.0,0.01
4.166793499999999,0.041673155,43.52130598567102,1100.0,0.01
4.1852195,0.041857414999999995,43.58389042811047,1100.0,0.01
4.202535,0.04203057,43.647388929089566,1100.0,0.01
4.221532,0.04222054,43.705874791941696,1100.0,0.01
4.2427665,0.042432885000000004,43.755868822935945,1100.0,0.01
4.2656849999999995,0.042662069999999996,43.8010917813809,1100.0,0.01
4.2869285,0.042874505,43.857095169471485,1100.0,0.01
4.3023039999999995,0.04302826,43.902883184730776,1100.0,0.01
4.3210429999999995,0.043215649999999994,43.93680506753185,1100.0,0.01
4.341737999999999,0.0434226,43.966914490111236,1100.0,0.01
4.359641,0.04360163,44.00366485101291,1100.0,0.01
4.381748,0.0438227,44.0285753191626,1100.0,0.01
4.404693,0.04405215,44.04984694349991,1100.0,0.01
4.4223245,0.044228465,44.08414556458153,1100.0,0.01
4.4388425,0.044393644999999995,44.13851240812716,1100.0,0.01
4.461245,0.04461767,44.18915588578629,1100.0,0.01
4.479452,0.044799740000000005,44.24496536604937,1100.0,0.01
4.4976585,0.044981805,44.29536937810045,1100.0,0.01
4.5228745,0.045233965,44.34851397498469,1100.0,0.01
4.5408095,0.045413314999999996,44.39267270497138,1100.0,0.01
4.5581875,0.045587095,44.427673492553104,1100.0,0.01
4.576973499999999,0.045774955000000006,44.47238466663656,1100.0,0.01
4.598284,0.04598806,44.525812457263534,1100.0,0.01
4.6221235,0.046226455,44.573712883404035,1100.0,0.01
4.641479,0.04642001,44.61466597430565,1100.0,0.01
4.6608385000000006,0.046613605,44.65085160861048,1100.0,0.01
4.678236500000001,0.046787585000000007,44.67949860826207,1100.0,0.01
4.6950755,0.046955975,44.71603788172605,1100.0,0.01
4.716416,0.04716938,44.753239871055484,1100.0,0.01
4.737197999999999,0.0473772,44.78760080163489,1100.0,0.01
4.755451,0.04755973,44.8326344548525,1100.0,0.01
4.775674,0.047761960000000006,44.86559124828035,1100.0,0.01
4.796742,0.04797264,44.89908291585246,1100.0,0.01
4.8161309999999995,0.04816653,44.946127448164965,1100.0,0.01
4.8341195,0.048346415000000004,44.98542288722179,1100.0,0.01
4.85689,0.04857412,45.0200438993317,1100.0,0.01
4.8802330000000005,0.048807550000000005,45.06162100155114,1100.0,0.01
4.897674,0.048981960000000005,45.10558511101117,1100.0,0.01
4.917362499999999,0.049178845,45.14168400311323,1100.0,0.01
4.934805,0.049353270000000005,45.18096167979915,1100.0,0.01
4.9542265,0.049547485,45.21059474833902,1100.0,0.01
4.975896,0.04976418,45.25607937007236,1100.0,0.01
4.992500999999999,0.04993023,45.2992873012506,1100.0,0.01
5.011369499999999,0.050118915,45.34144142373187,1100.0,0.01
5.034464999999999,0.050349870000000005,45.38626987624907,1100.0,0.01
5.055872,0.05056394,45.43627323963704,1100.0,0.01
5.073339,0.05073861,45.481626653256,1100.0,0.01
5.0922175,0.050927395,45.52393764721425,1100.0,0.01
5.1125135,0.051130355,45.57311813096064,1100.0,0.01
5.1319645,0.051324865,45.61111589336786,1100.0,0.01
5.151979,0.051525009999999996,45.65548964008386,1100.0,0.01
5.1736965,0.051742184999999996,45.686091790780516,1100.0,0.01
5.192033499999999,0.051925555,45.71129704535795,1100.0,0.01
5.211785,0.05212307,45.74315806222921,1100.0,0.01
5.234076,0.05234598,45.77662927842418,1100.0,0.01
5.2541104999999995,0.052546325,45.8033808703463,1100.0,0.01
5.273873999999999,0.05274396,45.824840319387995,1100.0,0.01
5.29251,0.05293032,45.85088988797694,1100.0,0.01
5.31115,0.05311672,45.86529982067795,1100.0,0.01
5.3292275,0.053297495,45.88470748363072,1100.0,0.01
5.3495669999999995,0.053500889999999995,45.92180505489409,1100.0,0.01
5.3718935,0.053724154999999996,45.96926969814052,1100.0,0.01
5.391114,0.053916359999999997,46.03574111457243,1100.0,0.01
5.409772499999999,0.054102945,46.11273058194367,1100.0,0.01
5.429281,0.05429803,46.18661175421664,1100.0,0.01
5.447941,0.05448463,46.242956050962626,1100.0,0.01
5.468023499999999,0.054685454999999994,46.29945726795675,1100.0,0.01
5.490657499999999,0.054911795,46.32872520198144,1100.0,0.01
5.5110345,0.055115565000000005,46.34436208259501,1100.0,0.01
5.532264,0.05532786,46.37278776576186,1100.0,0.01
5.552643999999999,0.05553166,46.39878972310812,1100.0,0.01
5.568782499999999,0.055693045,46.424880363353715,1100.0,0.01
5.5891709999999994,0.05589693,46.44867280880591,1100.0,0.01
5.6106975,0.056112195000000004,46.468336444883846,1100.0,0.01
5.6282665,0.056287884999999996,46.481360899303674,1100.0,0.01
5.648953,0.056494749999999996,46.501232548387186,1100.0,0.01
5.6690755,0.056695975,46.51172663840242,1100.0,0.01
5.6874994999999995,0.056880215,46.53007596132682,1100.0,0.01
5.7042275,0.057047495000000004,46.58027675719082,1100.0,0.01
5.7218085,0.057223305,46.63846692660029,1100.0,0.01
5.741946,0.05742468,46.706398828585286,1100.0,0.01
5.760674999999999,0.05761197,46.76587717164804,1100.0,0.01
5.7828075,0.057833295,46.81391043793442,1100.0,0.01
5.8066445,0.058071665,46.86111461625059,1100.0,0.01
5.826798999999999,0.05827321,46.89881514072432,1100.0,0.01
5.847239999999999,0.058477619999999994,46.93565414535652,1100.0,0.01
5.867684499999999,0.058682065,46.966399849617645,1100.0,0.01
5.884442999999999,0.05884965,47.000385660426424,1100.0,0.01
5.9046135,0.059051355,47.03019114804394,1100.0,0.01
5.9267775,0.059272994999999995,47.05885545927645,1100.0,0.01
5.9452535,0.059457755,47.06870142909994,1100.0,0.01
5.9637335,0.059642555,47.07367335941984,1100.0,0.01
5.9836325,0.059841544999999996,47.08033341398057,1100.0,0.01
6.001262,0.06001784,47.10004685341087,1100.0,0.01
6.020887,0.06021409,47.14664747306407,1100.0,0.01
6.043929,0.06044451,47.20990968428984,1100.0,0.01
6.0644184999999995,0.060649405,47.28100971861979,1100.0,0.01
6.082632499999999,0.060831545,47.35418796731311,1100.0,0.01
6.1011325,0.061016545000000005,47.419699071091294,1100.0,0.01
6.119358500000001,0.061198805,47.45973062247936,1100.0,0.01
6.137582999999999,0.06138105,47.48585708722179,1100.0,0.01
6.1589405,0.061594625,47.49703424375043,1100.0,0.01
6.1834430000000005,0.061839649999999996,47.508699390443645,1100.0,0.01
6.202249,0.06202771,47.525294886436164,1100.0,0.01
6.219346999999999,0.06219869,47.55307207828654,1100.0,0.01
6.240727,0.06241249,47.60134478192472,1100.0,0.01
6.262682999999999,0.06263205,47.640528644738986,1100.0,0.01
6.282069999999999,0.06282592000000001,47.67314404895853,1100.0,0.01
6.298322000000001,0.06298844,47.694247873672445,1100.0,0.01
6.317722,0.06318244,47.71545775297529,1100.0,0.01
6.33713,0.06337652,47.73902598115518,1100.0,0.01
6.3568204999999995,0.063573425,47.76465171019845,1100.0,0.01
6.378513,0.06379035,47.781234312247804,1100.0,0.01
6.3970675,0.063975895,47.81135367336135,1100.0,0.01
6.4159095,0.064164315,47.869254120446726,1100.0,0.01
6.4367595,0.064372815,47.92215102050762,1100.0,0.01
6.457896999999999,0.06458419,47.96683662919526,1100.0,0.01
6.479044499999999,0.064795665,48.01283099505533,1100.0,0.01
6.5001964999999995,0.065007185,48.04725988812762,1100.0,0.01
6.519346,0.06519868000000001,48.075662865783194,1100.0,0.01
6.53736,0.06537882,48.09118732327348,1100.0,0.01
6.5579515,0.065584735,48.10024809436794,1100.0,0.01
6.577395999999999,0.06577917999999999,48.11646866132243,1100.0,0.01
6.595704,0.06596226,48.15093642593746,1100.0,0.01
6.615734499999999,0.066162565,48.17674215571225,1100.0,0.01
6.636910499999999,0.066374325,48.19890545620115,1100.0,0.01
6.6558019999999996,0.06656324,48.22693494265602,1100.0,0.01
6.677275999999999,0.06677798,48.24738561587775,1100.0,0.01
6.696175,0.06696697,48.28413534806525,1100.0,0.01
6.7150739999999995,0.06715596,48.33055305160843,1100.0,0.01
6.735980499999999,0.067365025,48.38445142414424,1100.0,0.01
6.752316499999999,0.067528385,48.443568346157406,1100.0,0.01
6.7746699999999995,0.06775192,48.50051893846976,1100.0,0.01
6.795878999999999,0.06796400999999999,48.534297610581795,1100.0,0.01
6.814226999999999,0.06814749,48.545492907903935,1100.0,0.01
6.835734499999999,0.068362565,48.54453136085858,1100.0,0.01
6.855528,0.0685605,48.53696490191309,1100.0,0.01
6.87589,0.06876412,48.54433525987312,1100.0,0.01
6.8933925,0.06893914500000001,48.56416171250707,1100.0,0.01
6.90918,0.06909702000000001,48.601350300544745,1100.0,0.01
6.9286935,0.069292155,48.65535420153528,1100.0,0.01
6.9510855,0.069516075,48.71158560304882,1100.0,0.01
6.971472,0.06971994000000001,48.751471892596314,1100.0,0.01
6.990428,0.0699095,48.77543894623286,1100.0,0.01
7.013984499999999,0.070145065,48.79489201507986,1100.0,0.01
7.034954000000001,0.07035476,48.81984758169323,1100.0,0.01
7.0536315,0.070541535,48.85078636160792,1100.0,0.01
7.073754,0.07074276,48.889280419867085,1100.0,0.01
7.094455999999999,0.07094977999999999,48.93136930090105,1100.0,0.01
7.113434499999999,0.07113956499999999,48.97793770542928,1100.0,0.01
7.130974499999999,0.071314965,49.024741252954165,1100.0,0.01
7.15226,0.07152781999999999,49.04085713572518,1100.0,0.01
7.17614,0.07176662,49.04473647512513,1100.0,0.01
7.193695,0.07194217,49.04959235692639,1100.0,0.01
7.2098154999999995,0.072103375,49.05719197346446,1100.0,0.01
7.2305405,0.07231062499999999,49.0717838163034,1100.0,0.01
7.251847,0.07252369,49.0825663804112,1100.0,0.01
7.271140999999999,0.07271663,49.098483116788366,1100.0,0.01
7.291593499999999,0.072921155,49.11487385286788,1100.0,0.01
7.3111865,0.073117085,49.14551934746652,1100.0,0.01
7.328479999999999,0.07329002,49.16185660909552,1100.0,0.01
7.3472170000000006,0.07347739,49.18849874715216,1100.0,0.01
7.366530000000001,0.07367052,49.229597409625754,1100.0,0.01
7.388729,0.07389251,49.290126976315115,1100.0,0.01
7.409496,0.07410018,49.33792049170457,1100.0,0.01
7.431996999999999,0.07432519,49.37569844975165,1100.0,0.01
7.453346,0.07453868,49.40995844289202,1100.0,0.01
7.4703725,0.074708945,49.44115881663642,1100.0,0.01
7.486245,0.07486767,49.45964418870471,1100.0,0.01
7.5070335,0.075075555,49.47152150580739,1100.0,0.01
7.530998499999999,0.075315205,49.49654224084131,1100.0,0.01
7.549768499999999,0.075502905,49.52806151885476,1100.0,0.01
7.567968499999999,0.075684905,49.56693269569164,1100.0,0.01
7.585013999999999,0.07585536,49.5764403260513,1100.0,0.01
7.605238999999999,0.07605761,49.57570343386915,1100.0,0.01
7.626625499999999,0.076271475,49.57293478375198,1100.0,0.01
7.646284999999999,0.07646807,49.58186268485635,1100.0,0.01
7.667972,0.07668494000000001,49.605367681022955,1100.0,0.01
7.688504999999999,0.07689027,49.64421214257287,1100.0,0.01
7.707017499999999,0.07707539499999999,49.70417792070161,1100.0,0.01
7.724087,0.07724609,49.77180175451806,1100.0,0.01
7.745504499999999,0.077460265,49.83310255785142,1100.0,0.01
7.765765999999999,0.07766287999999999,49.87701803815222,1100.0,0.01
7.7842875,0.077848095,49.91112401400034,1100.0,0.01
7.804838999999999,0.07805361,49.92766624604182,1100.0,0.01
7.825400999999999,0.07825923,49.93945754922913,1100.0,0.01
7.846259499999999,0.078467815,49.95294731165894,1100.0,0.01
7.8668295,0.078673515,49.95435886347014,1100.0,0.01
7.889139999999999,0.07889662,49.95439461366891,1100.0,0.01
7.906245999999999,0.07906768,49.96225196135892,1100.0,0.01
7.9245114999999995,0.079250335,49.9810714967111,1100.0,0.01
7.944510999999999,0.07945033,50.014357299449394,1100.0,0.01
7.962490000000001,0.07963012,50.0578821771105,1100.0,0.01
7.984534,0.07985056,50.09695582862741,1100.0,0.01
8.0060065,0.080065285,50.125819061381485,1100.0,0.01
8.0266095,0.08027131500000001,50.149968446218324,1100.0,0.01
8.047793,0.08048315,50.157671630714184,1100.0,0.01
8.065795999999999,0.08066318,50.165118340891816,1100.0,0.01
8.083509,0.08084031,50.17685468487099,1100.0,0.01
8.1041275,0.081046495,50.20532906708835,1100.0,0.01
8.124749999999999,0.08125272,50.25147118457829,1100.0,0.01
8.141886,0.08142408,50.30955970462571,1100.0,0.01
8.161065,0.08161587000000001,50.368798581139046,1100.0,0.01
8.183446499999999,0.081839685,50.422084922572694,1100.0,0.01
8.204957,0.08205479,50.47266569182491,1100.0,0.01
8.225018500000001,0.082255405,50.508640462464896,1100.0,0.01
8.243342,0.08243864000000001,50.5182564920529,1100.0,0.01
8.2645765,0.082650985,50.512168881256606,1100.0,0.01
8.284067,0.08284589,50.48917598935034,1100.0,0.01
8.303567,0.08304089,50.4670621340084,1100.0,0.01
8.322486999999999,0.08323009,50.46059858708846,1100.0,0.01
8.342279,0.08342801,50.460244649243634,1100.0,0.01
8.363823,0.08364345000000001,50.47193779126551,1100.0,0.01
8.382461,0.08382983,50.511080142144266,1100.0,0.01
8.4002295,0.084007515,50.56685282268696,1100.0,0.01
8.4182905,0.084188125,50.62604765780365,1100.0,0.01
8.438979,0.08439500999999999,50.680046788901635,1100.0,0.01
8.4564685,0.084569905,50.729235362427566,1100.0,0.01
8.478911499999999,0.084794335,50.77050726226835,1100.0,0.01
8.501652499999999,0.085021745,50.80582397425516,1100.0,0.01
8.517691,0.08518213,50.811196517963275,1100.0,0.01
8.5384,0.08538922,50.80480039603502,1100.0,0.01
8.558533,0.08559055,50.80002925997246,1100.0,0.01
8.577791999999999,0.08578314000000001,50.79410497610897,1100.0,0.01
8.598513,0.08599035,50.79151876535326,1100.0,0.01
8.614566,0.08615088,50.80609634014734,1100.0,0.01
8.633835999999999,0.08634358,50.840680117810045,1100.0,0.01
8.6560275,0.08656549499999999,50.88986328457558,1100.0,0.01
8.6764695,0.086769915,50.94407390694155,1100.0,0.01
8.6975065,0.086980285,50.98283177509697,1100.0,0.01
8.7165025,0.08717024500000001,51.02056479407062,1100.0,0.01
8.7357865,0.08736308500000001,51.0481385830665,1100.0,0.01
8.7536125,0.08754134499999999,51.059347038873575,1100.0,0.01
8.773494499999998,0.087740165,51.06906315332679,1100.0,0.01
8.795136999999999,0.08795659,51.093225679715445,1100.0,0.01
8.8118075,0.08812329499999999,51.11828397589105,1100.0,0.01
8.833454,0.08833975999999999,51.14416871777364,1100.0,0.01
8.856276,0.08856797999999999,51.17224099568675,1100.0,0.01
8.87442,0.08874942,51.192162601146975,1100.0,0.01
8.8949125,0.088954345,51.20511930056733,1100.0,0.01
8.914526500000001,0.089150485,51.210704402218134,1100.0,0.01
8.932976499999999,0.089334985,51.21071330529947,1100.0,0.01
8.951725499999998,0.08952247499999999,51.20940528997492,1100.0,0.01
8.971641499999999,0.089721635,51.21253424500319,1100.0,0.01
8.9930265,0.089935485,51.21792239193289,1100.0,0.01
9.012369,0.09012891,51.24111245976302,1100.0,0.01
9.031133,0.09031655,51.28869992515253,1100.0,0.01
9.0490175,0.090495395,51.34301447630442,1100.0,0.01
9.0721815,0.090727035,51.39948019021041,1100.0,0.01
9.096524,0.09097046,51.44504452229385,1100.0,0.01
9.1147115,0.091152335,51.475165580604234,1100.0,0.01
9.1355445,0.09136066500000001,51.493076878862325,1100.0,0.01
9.156672499999999,0.091571945,51.4925900981011,1100.0,0.01
9.174579000000001,0.09175101,51.49366951508899,1100.0,0.01
9.193077500000001,0.09193599499999999,51.50817363436343,1100.0,0.01
9.212458999999999,0.09212981,51.53423737497507,1100.0,0.01
9.232723499999999,0.09233245500000001,51.56584363501013,1100.0,0.01
9.254164,0.09254686000000001,51.59636267211478,1100.0,0.01
9.274733999999999,0.09275256000000001,51.62052541538792,1100.0,0.01
9.294131,0.09294653,51.62835714063562,1100.0,0.01
9.310588,0.0931111,51.64273827735268,1100.0,0.01
9.326464,0.09326986,51.65418702776584,1100.0,0.01
9.3488115,0.093493335,51.65993569168165,1100.0,0.01
9.372930499999999,0.093734525,51.679297152075286,1100.0,0.01
9.395585,0.09396107000000001,51.71951589814348,1100.0,0.01
9.4147075,0.094152295,51.760924361547346,1100.0,0.01
9.432071500000001,0.094325935,51.803693587177925,1100.0,0.01
9.451499,0.09452021,51.841784162257646,1100.0,0.01
9.4688685,0.094693905,51.86244275618867,1100.0,0.01
9.490365,0.09490887,51.87668664471092,1100.0,0.01
9.512456,0.09512978,51.874944874796235,1100.0,0.01
9.530422,0.09530944,51.862926408230145,1100.0,0.01
9.551336,0.09551857999999999,51.86654824478164,1100.0,0.01
9.572557499999998,0.09573079500000001,51.89282539374269,1100.0,0.01
9.5893635,0.095898855,51.91912709513991,1100.0,0.01
9.610002999999999,0.09610525,51.95797015075238,1100.0,0.01
9.6324125,0.096329345,52.00175162512163,1100.0,0.01
9.6524645,0.09652986499999999,52.050655810170895,1100.0,0.01
9.670753,0.09671275,52.09012060238619,1100.0,0.01
9.6875705,0.096880925,52.11441273709919,1100.0,0.01
9.707341,0.09707863,52.13565984662553,1100.0,0.01
9.727711499999998,0.097282335,52.15292189078674,1100.0,0.01
9.7451295,0.097456515,52.1570648642111,1100.0,0.01
9.7657965,0.097663185,52.151664999646556,1100.0,0.01
9.788241,0.09788763,52.11921604700959,1100.0,0.01
9.809805999999998,0.09810327999999999,52.09801696152172,1100.0,0.01
9.829898499999999,0.098304205,52.11352063789933,1100.0,0.01
9.846743,0.09847265,52.13675983422819,1100.0,0.01
9.866549499999998,0.09867071499999999,52.16454908852339,1100.0,0.01
9.886654,0.09887176,52.20855402322592,1100.0,0.01
9.905279499999999,0.099058015,52.25772787996571,1100.0,0.01
9.926870000000001,0.09927392,52.302113176885385,1100.0,0.01
9.9472795,0.099478015,52.34034095002345,1100.0,0.01
9.9650295,0.099655515,52.35682394262267,1100.0,0.01
9.98752,0.09988042,52.38017848871742,1100.0,0.01
10.0085355,0.100090575,52.40063948941826,1100.0,0.01
10.0313345,0.100318565,52.40805785677236,1100.0,0.01
10.051171499999999,0.100516935,52.408902412952905,1100.0,0.01
10.066572999999998,0.10067095,52.40975397979781,1100.0,0.01
10.08583,0.10086352,52.41981451422431,1100.0,0.01
10.104492,0.10105014,52.43746096943126,1100.0,0.01
10.126420499999998,0.101269425,52.470497382219094,1100.0,0.01
10.145688999999999,0.10146211,52.51029287453772,1100.0,0.01
10.164368,0.1016489,52.55027747308641,1100.0,0.01
10.186308499999999,0.10186830499999999,52.57156099034949,1100.0,0.01
10.204400499999998,0.102049225,52.583995215570326,1100.0,0.01
10.224868,0.10225390000000001,52.58943187436202,1100.0,0.01
10.244149499999999,0.102446715,52.579445238591624,1100.0,0.01
10.263735999999998,0.10264258,52.57465158888035,1100.0,0.01
10.285404,0.10285926000000001,52.576047540321404,1100.0,0.01
10.3008405,0.103013625,52.586677761605806,1100.0,0.01
10.3186535,0.103191755,52.60915638825387,1100.0,0.01
10.341818499999999,0.103423405,52.63788459879345,1100.0,0.01
10.3629085,0.10363430500000001,52.672229882696556,1100.0,0.01
10.3795475,0.103800695,52.704860727895394,1100.0,0.01
10.401836499999998,0.104023585,52.72715162845764,1100.0,0.01
10.425314,0.10425836,52.734445940531465,1100.0,0.01
10.444635,0.10445157,52.738776956167584,1100.0,0.01
10.462774,0.10463296,52.74790950318271,1100.0,0.01
10.480916999999998,0.10481439000000001,52.75793043721129,1100.0,0.01
10.4987615,0.104992835,52.78198250047397,1100.0,0.01
10.517206,0.10517728,52.8204328996442,1100.0,0.01
10.5413135,0.10541835499999999,52.85593325638071,1100.0,0.01
10.5618485,0.105623705,52.89343583128206,1100.0,0.01
10.580900999999999,0.10581423,52.917338878552336,1100.0,0.01
10.600552999999998,0.10601074999999999,52.93773815070976,1100.0,0.01
10.619612499999999,0.106201345,52.943565986835,1100.0,0.01
10.6407665,0.106412885,52.93947469480711,1100.0,0.01
10.660726,0.10661248000000001,52.92384545342629,1100.0,0.01
10.679195,0.10679717,52.90864405663674,1100.0,0.01
10.69529,0.10695812,52.901403358894186,1100.0,0.01
10.7131785,0.10713700500000001,52.896155687128996,1100.0,0.01
10.735837,0.10736359,52.91089269190067,1100.0,0.01
10.760589,0.10761111,52.940028674610005,1100.0,0.01
10.7796785,0.107802005,52.99050639624281,1100.0,0.01
10.7981755,0.107986975,53.03890586532433,1100.0,0.01
10.8184675,0.10818989500000001,53.07769565638929,1100.0,0.01
10.835780499999998,0.108363025,53.114893776973226,1100.0,0.01
10.8566735,0.108571955,53.13582777134549,1100.0,0.01
10.879364500000001,0.108798865,53.14473276602386,1100.0,0.01
10.901166,0.10901688000000001,53.14983255912858,1100.0,0.01
10.922072499999999,0.10922594499999999,53.15807000696541,1100.0,0.01
10.943582,0.10944103999999999,53.16825344777946,1100.0,0.01
10.9624095,0.109629315,53.19072535083642,1100.0,0.01
10.980643,0.10981165,53.214414855398964,1100.0,0.01
11.003665,0.11004187,53.22922861384413,1100.0,0.01
11.0213065,0.110218285,53.24524482647259,1100.0,0.01
11.039249,0.11039771,53.26280070932288,1100.0,0.01
11.058391499999999,0.110589135,53.26886442938769,1100.0,0.01
11.078737499999999,0.110792595,53.271846212495895,1100.0,0.01
11.1008795,0.111014015,53.26838678832942,1100.0,0.01
11.120332,0.11120854,53.27250793291203,1100.0,0.01
11.1382965,0.111388185,53.28488648415584,1100.0,0.01
11.1568595,0.11157381499999999,53.302919754354996,1100.0,0.01
11.180516,0.11181038,53.31142523088915,1100.0,0.01
11.201486,0.11202008,53.32164585497238,1100.0,0.01
11.2197625,0.112202845,53.34874374747405,1100.0,0.01
11.238042499999999,0.112385645,53.376565831449945,1100.0,0.01
11.255726,0.11256247999999999,53.39553569783272,1100.0,0.01
11.276707,0.11277229,53.41224222026027,1100.0,0.01
11.297096499999999,0.112976185,53.43089873366126,1100.0,0.01
11.317193499999998,0.113177155,53.44701979933136,1100.0,0.01
11.338186499999999,0.113387085,53.46061362823924,1100.0,0.01
11.358286,0.11358808000000001,53.467919048649904,1100.0,0.01
11.3774905,0.11378012500000001,53.47862216861562,1100.0,0.01
11.3963955,0.113969175,53.493600440289626,1100.0,0.01
11.418012,0.11418534,53.510616400672625,1100.0,0.01
11.438132499999998,0.114386545,53.52943421013268,1100.0,0.01
11.457352499999999,0.11457874500000001,53.54663000444234,1100.0,0.01
11.478375499999999,0.114788975,53.55545852965661,1100.0,0.01
11.499706499999998,0.115002285,53.558875945419715,1100.0,0.01
11.516834,0.11517356,53.56035580505864,1100.0,0.01
11.5357655,0.115362875,53.556950776588735,1100.0,0.01
11.5553075,0.115558295,53.548457612990106,1100.0,0.01
11.572748999999998,0.11573270999999999,53.55128510330439,1100.0,0.01
11.595305499999998,0.115958275,53.57854105890919,1100.0,0.01
11.616357,0.11616879,53.62941807109643,1100.0,0.01
11.6344055,0.116349275,53.67964644877629,1100.0,0.01
11.652463000000001,0.11652985,53.72152355753083,1100.0,0.01
11.6705185,0.116710405,53.75236011477145,1100.0,0.01
11.6909835,0.116915055,53.76952213088927,1100.0,0.01
11.713566499999999,0.117140885,53.76359561060291,1100.0,0.01
11.7343495,0.11734871499999999,53.73570402416242,1100.0,0.01
11.752419499999998,0.117529415,53.71603481929282,1100.0,0.01
11.7717005,0.117722225,53.711060810196656,1100.0,0.01
11.791288999999999,0.11791810999999999,53.71124987050706,1100.0,0.01
11.8096685,0.11810190500000001,53.71446925311406,1100.0,0.01
11.830766,0.11831288000000001,53.727019375378234,1100.0,0.01
11.85338,0.11853902,53.74318881991783,1100.0,0.01
11.873588,0.1187411,53.76162555891842,1100.0,0.01
11.89048,0.11891002,53.78099146530456,1100.0,0.01
11.9097875,0.11910309499999999,53.806387272188466,1100.0,0.01
11.933323,0.11933845,53.833351637745324,1100.0,0.01
11.9547515,0.119552735,53.859452567461,1100.0,0.01
11.9728615,0.11973383500000001,53.87898429613066,1100.0,0.01
11.9918795,0.119924015,53.892151172832826,1100.0,0.01
12.0136255,0.120141475,53.89605473190276,1100.0,0.01
12.031146,0.12031668,53.890301626588005,1100.0,0.01
12.0483655,0.120488875,53.87648332514357,1100.0,0.01
12.068913499999999,0.120694355,53.85090137307559,1100.0,0.01
12.0918815,0.120924035,53.81829983523915,1100.0,0.01
12.113038,0.12113560000000001,53.794797338856796,1100.0,0.01
12.131483,0.12132005000000001,53.78869554981417,1100.0,0.01
12.14993,0.12150452,53.820375038364816,1100.0,0.01
12.167769999999999,0.12168292,53.878957752504064,1100.0,0.01
12.188642999999999,0.12189164999999999,53.94594823774815,1100.0,0.01
12.209825499999999,0.12210347499999999,54.01444426821426,1100.0,0.01
12.2282875,0.122288095,54.093837783983446,1100.0,0.01
12.2482665,0.122487885,54.16537139389037,1100.0,0.01
12.270063,0.12270585,54.21683020306099,1100.0,0.01
12.288836499999999,0.122893585,54.25696495855336,1100.0,0.01
12.3076195,0.123081415,54.295476116486114,1100.0,0.01
12.3288275,0.123293495,54.321354170523335,1100.0,0.01
12.3491265,0.123496485,54.33455666896399,1100.0,0.01
12.368522500000001,0.12369044500000001,54.33041722591594,1100.0,0.01
12.3867075,0.123872295,54.328408390817145,1100.0,0.01
12.4061105,0.124066325,54.3261167383113,1100.0,0.01
12.4282475,0.124287695,54.336033008814404,1100.0,0.01
12.4503895,0.124509115,54.35147422123115,1100.0,0.01
12.47223,0.12472752,54.361929956340816,1100.0,0.01
12.492251499999998,0.12492773499999998,54.388775211864356,1100.0,0.01
12.5107655,0.125112875,54.40177674436884,1100.0,0.01
12.531409,0.12531931000000002,54.41573308388321,1100.0,0.01
12.551749,0.12552270999999998,54.42789126271874,1100.0,0.01
12.5681485,0.125686705,54.44595916114513,1100.0,0.01
12.588503,0.12589024999999998,54.4465212479863,1100.0,0.01
12.609162,0.12609684,54.44751264302747,1100.0,0.01
12.625872000000001,0.12626394000000002,54.44589878892149,1100.0,0.01
12.64836,0.12648882,54.43443695319919,1100.0,0.01
12.668724000000001,0.12669246,54.436795020582124,1100.0,0.01
12.686662,0.12687184,54.44674685814509,1100.0,0.01
12.7064305,0.127069525,54.448333652254775,1100.0,0.01
12.725594,0.12726115999999998,54.44784931925986,1100.0,0.01
12.747802,0.12748324,54.455546337449086,1100.0,0.01
12.7675765,0.12768098500000002,54.462876428840985,1100.0,0.01
12.784006000000002,0.12784528,54.473648991969505,1100.0,0.01
12.804399,0.12804921,54.4797145105155,1100.0,0.01
12.826019499999997,0.128265415,54.486517185333724,1100.0,0.01
12.847035499999999,0.128475575,54.49781527844976,1100.0,0.01
12.868352499999999,0.128688745,54.51931169504893,1100.0,0.01
12.8881515,0.128886735,54.52778786863325,1100.0,0.01
12.908262,0.12908784,54.53955001544337,1100.0,0.01
12.924109000000001,0.12924631,54.563831362331506,1100.0,0.01
12.943007,0.12943528999999998,54.59423724244917,1100.0,0.01
12.9661765,0.129666985,54.616535594110054,1100.0,0.01
12.986303499999998,0.129868255,54.61839355751968,1100.0,0.01
13.0070455,0.130075675,54.61189203420504,1100.0,0.01
13.028402499999999,0.130289245,54.60205896735328,1100.0,0.01
13.0494555,0.13049977499999998,54.59433623779876,1100.0,0.01
13.068067,0.13068589,54.57143370297381,1100.0,0.01
13.087299999999999,0.13087822,54.55870436374644,1100.0,0.01
13.1071475,0.131076695,54.54736936853168,1100.0,0.01
13.1279085,0.131284305,54.54788420130436,1100.0,0.01
13.145620000000001,0.13146142,54.55463398329285,1100.0,0.01
13.161505000000002,0.13162027,54.562418440717245,1100.0,0.01
13.18198,0.13182502000000001,54.58518514803236,1100.0,0.01
13.201538,0.1320206,54.62651302552352,1100.0,0.01
13.221712,0.13222234,54.67355472324136,1100.0,0.01
13.244946500000001,0.13245468500000002,54.70899039224871,1100.0,0.01
13.2642075,0.132647295,54.7332584714253,1100.0,0.01
13.2816455,0.132821675,54.73001499542278,1100.0,0.01
13.3021395,0.13302661500000001,54.72512140544583,1100.0,0.01
13.319882499999999,0.133204045,54.725143174537024,1100.0,0.01
13.339776999999998,0.13340299,54.71211629287012,1100.0,0.01
13.362426,0.13362948000000002,54.70125126315444,1100.0,0.01
13.379875,0.13380397,54.70751938303886,1100.0,0.01
13.3994715,0.13399993500000001,54.70352228443581,1100.0,0.01
13.422747000000001,0.13423269,54.68403520086028,1100.0,0.01
13.4441935,0.13444715499999998,54.646433925448974,1100.0,0.01
13.462885,0.13463407,54.611390366021176,1100.0,0.01
13.48158,0.13482102,54.59735752423561,1100.0,0.01
13.501196499999999,0.13501718499999998,54.60448581185108,1100.0,0.01
13.520506999999998,0.13521029,54.62059330996605,1100.0,0.01
13.541664,0.13542186,54.6565843594145,1100.0,0.01
13.560678000000001,0.135612,54.717155252767384,1100.0,0.01
13.5796955,0.13580217500000002,54.76592916700167,1100.0,0.01
13.603323499999998,0.136038455,54.796598949350575,1100.0,0.01
13.623578499999999,0.136241005,54.80900188556579,1100.0,0.01
13.641994,0.13642516,54.81169251995075,1100.0,0.01
13.661946499999999,0.136624685,54.81079687648001,1100.0,0.01
13.675763499999999,0.136762855,54.80982741355163,1100.0,0.01
13.695425,0.13695947,54.80753913868722,1100.0,0.01
13.719079,0.13719601,54.8085340201793,1100.0,0.01
13.740278,0.137408,54.807806928161995,1100.0,0.01
13.7599455,0.137604675,54.8009935457223,1100.0,0.01
13.779312,0.13779834,54.80250691435461,1100.0,0.01
13.802987,0.13803509,54.80027106185249,1100.0,0.01
13.82174,0.13822262000000002,54.78168381471492,1100.0,0.01
13.839886499999999,0.138404085,54.76017754313647,1100.0,0.01
13.8592675,0.138597895,54.748605359958304,1100.0,0.01
13.877415,0.13877937,54.73218972643144,1100.0,0.01
13.898647999999998,0.1389917,54.72030329403776,1100.0,0.01
13.918657,0.13919178999999998,54.70481656397168,1100.0,0.01
13.936204499999999,0.139367265,54.69921995647598,1100.0,0.01
13.9543715,0.13954893499999999,54.72202225767474,1100.0,0.01
13.973775,0.13974297000000002,54.7504057767025,1100.0,0.01
14.000265,0.14000787,54.7814688548234,1100.0,0.01
14.0233685,0.140238905,54.812565299334324,1100.0,0.01
14.039088499999998,0.140396105,54.84261527964651,1100.0,0.01
14.0585095,0.140590315,54.86655104613094,1100.0,0.01
14.08101,0.14081532,54.88683619935543,1100.0,0.01
14.102597,0.14103119,54.89109600282369,1100.0,0.01
14.120488,0.1412101,54.8895436755895,1100.0,0.01
14.139301,0.14139823,54.87259154273222,1100.0,0.01
14.159046499999999,0.141595685,54.843376047097465,1100.0,0.01
14.1803445,0.141808665,54.80225622851019,1100.0,0.01
14.201953499999998,0.142024755,54.756392752761066,1100.0,0.01
14.218931999999999,0.14219454,54.72016627680158,1100.0,0.01
14.2396195,0.142401415,54.70855448143621,1100.0,0.01
14.261854,0.14262376,54.723438598817296,1100.0,0.01
14.2757545,0.142762765,54.75517535978621,1100.0,0.01
14.294296,0.14294817999999998,54.79280850786414,1100.0,0.01
14.319324499999999,0.143198465,54.82504038334141,1100.0,0.01
14.3421965,0.143427185,54.852349200916116,1100.0,0.01
14.359511,0.14360033,54.8567199183624,1100.0,0.01
14.375278,0.143758,54.85541189920495,1100.0,0.01
14.399709,0.14400231,54.854408628493786,1100.0,0.01
14.422291,0.14422813,54.85813763111174,1100.0,0.01
14.438693,0.14439215,54.871617873433124,1100.0,0.01
14.4566445,0.14457166500000002,54.89986832183226,1100.0,0.01
14.466238,0.1446676,54.92110080030295,1100.0,0.01