File: datasets/steel_spring/csv/BS2V-1200-10.0.csv
Time(s),Strain(%),Stress(MPa),Temp(C),SR(%/s)
0.0,2.07e-05,0.19034261000000022,1200.0,10.0
2.67875e-07,2.3378749999999997e-05,0.19310858375000017,1200.0,10.0
5.3575e-07,2.60575e-05,0.19587455750000013,1200.0,10.0
8.036250000000001e-07,2.8736249999999998e-05,0.19864053125000009,1200.0,10.0
1.0715e-06,3.1414999999999997e-05,0.20140650500000007,1200.0,10.0
1.3393750000000002e-06,3.409375e-05,0.2048639721875007,1200.0,10.0
1.6072500000000002e-06,3.6772499999999994e-05,0.2076299459375007,1200.0,10.0
1.8751250000000001e-06,3.945124999999999e-05,0.21039591968750077,1200.0,10.0
2.143e-06,4.212999999999999e-05,0.2131618934375008,1200.0,10.0
2.410875e-06,4.4808749999999993e-05,0.21592786718750095,1200.0,10.0
2.6787500000000004e-06,4.7487499999999996e-05,0.2186938409375011,1200.0,10.0
2.9466250000000004e-06,5.016625e-05,0.22145981468750114,1200.0,10.0
3.2145000000000003e-06,5.284499999999999e-05,0.2240324201200291,1200.0,10.0
3.4823750000000003e-06,5.552374999999999e-05,0.2266354194886375,1200.0,10.0
3.7502500000000002e-06,5.820249999999999e-05,0.22954131015128065,1200.0,10.0
4.018125e-06,6.088124999999999e-05,0.2329387441250022,1200.0,10.0
4.286e-06,6.356e-05,0.23693252808593923,1200.0,10.0
4.3193125e-06,6.3893125e-05,0.2415436233693205,1200.0,10.0
4.352625e-06,6.422625e-05,0.24670914596946322,1200.0,10.0
4.3859375e-06,6.4559375e-05,0.25228236653977654,1200.0,10.0
4.41925e-06,6.48925e-05,0.2580327103927594,1200.0,10.0
4.4525625e-06,6.5225625e-05,0.2636457575000024,1200.0,10.0
4.4858750000000005e-06,6.555875e-05,0.2691786275000014,1200.0,10.0
4.5191875e-06,6.5891875e-05,0.2747114975000012,1200.0,10.0
4.5525e-06,6.6225e-05,0.28024436750000076,1200.0,10.0
4.5858125e-06,6.6558125e-05,0.2857772375000008,1200.0,10.0
4.619125e-06,6.689125e-05,0.2913101075000011,1200.0,10.0
4.6524375e-06,6.7224375e-05,0.29684297750000066,1200.0,10.0
4.68575e-06,6.75575e-05,0.3040127780181111,1200.0,10.0
4.7190625e-06,6.7890625e-05,0.3109252832244305,1200.0,10.0
4.752375e-06,6.822375e-05,0.31527370756498285,1200.0,10.0
4.7856875e-06,6.8556875e-05,0.3154610456562457,1200.0,10.0
4.819e-06,6.889e-05,0.31060007228515185,1200.0,10.0
4.8528124999999995e-06,6.9228125e-05,0.3005133424090876,1200.0,10.0
4.886625e-06,6.956625e-05,0.2857331911558937,1200.0,10.0
4.9204375000000004e-06,6.990437499999999e-05,0.26750173382386366,1200.0,10.0
4.95425e-06,7.02425e-05,0.24777086588174757,1200.0,10.0
4.9880625e-06,7.058062500000002e-05,0.22920226296875093,1200.0,10.0
5.021875e-06,7.091875000000001e-05,0.21131238734375055,1200.0,10.0
5.0556875000000005e-06,7.125687500000001e-05,0.19342251171875025,1200.0,10.0
5.0895e-06,7.159500000000001e-05,0.1755326360937504,1200.0,10.0
5.1233125e-06,7.1933125e-05,0.15764276046874995,1200.0,10.0
5.157125e-06,7.227125e-05,0.13975288484375004,1200.0,10.0
5.190937500000001e-06,7.2609375e-05,0.12186300921875036,1200.0,10.0
5.22475e-06,7.29475e-05,0.10301288054332462,1200.0,10.0
5.2585625e-06,7.3285625e-05,0.0843136859517054,1200.0,10.0
5.292375e-06,7.362375e-05,0.0671186275745747,1200.0,10.0
5.326187500000001e-06,7.396187499999999e-05,0.05236453765625066,1200.0,10.0
5.36e-06,7.43e-05,0.04057187855468792,1200.0,10.0
5.427125000000001e-06,7.497125000000002e-05,0.03184474274147748,1200.0,10.0
5.494250000000001e-06,7.564250000000001e-05,0.025870852801846648,1200.0,10.0
5.561375000000001e-06,7.631375000000001e-05,0.021921561434659096,1200.0,10.0
5.6285e-06,7.698500000000001e-05,-0.01946826422265635,1200.0,10.0
5.695625e-06,7.765625000000001e-05,-0.055516679554924356,1200.0,10.0
5.76275e-06,7.83275e-05,-0.031938785555279514,1200.0,10.0
5.829875e-06,7.899875e-05,0.08904905018750015,1200.0,10.0
5.8970000000000005e-06,7.967e-05,0.3282165380664072,1200.0,10.0
1.002075e-05,0.0001209075,0.6897176201600401,1200.0,10.0
1.41445e-05,0.000162145,1.161090470232603,1200.0,10.0
1.826825e-05,0.00020338249999999998,1.7132574937339073,1200.0,10.0
2.2392000000000002e-05,0.00024461999999999997,2.300235322496458,1200.0,10.0
2.6515750000000004e-05,0.0002858575,2.8600504141335343,1200.0,10.0
3.0639500000000004e-05,0.000327095,3.404430940368977,1200.0,10.0
3.476325e-05,0.00036833250000000003,3.949548661656266,1200.0,10.0
3.8887e-05,0.00040957,4.495560762441424,1200.0,10.0
4.294362500000001e-05,0.00045013625000000005,5.042498679613658,1200.0,10.0
4.700025000000001e-05,0.0004907025,5.590268102505347,1200.0,10.0
5.105687500000001e-05,0.00053126875,6.138648972892067,1200.0,10.0
5.511350000000001e-05,0.000571835,6.601426998597676,1200.0,10.0
5.9170125000000006e-05,0.00061240125,7.0774960563399825,1200.0,10.0
6.322675e-05,0.0006529675,7.687948892740552,1200.0,10.0
6.7283375e-05,0.00069353375,8.516679886968776,1200.0,10.0
7.134e-05,0.0007341,9.61023022406253,1200.0,10.0
0.0001187728125,0.001208428125,10.977908141029397,1200.0,10.0
0.000166205625,0.00168275625,12.591788926846641,1200.0,10.0
0.00021363843749999998,0.002157084375,14.386714922461238,1200.0,10.0
0.00026107124999999996,0.0026314125,16.26029552078984,1200.0,10.0
0.0003085040625,0.0031057406249999997,18.07290716671882,1200.0,10.0
0.000355936875,0.00358006875,19.849914806093828,1200.0,10.0
0.00040336968749999996,0.004054396875,21.62692244546884,1200.0,10.0
0.0004508025,0.004528725,23.403930084843847,1200.0,10.0
0.0004982353124999999,0.005003053125,25.180937724218854,1200.0,10.0
0.000545668125,0.00547738125,26.95794536359386,1200.0,10.0
0.0005931009375,0.005951709375,28.734953002968876,1200.0,10.0
0.00064053375,0.0064260375000000005,30.54775383418195,1200.0,10.0
0.0006879665625000001,0.006900365625,32.35492863524161,1200.0,10.0
0.0007353993750000001,0.00737469375,34.106037135806964,1200.0,10.0
0.0007828321875000001,0.007849021875,35.7661591487189,1200.0,10.0
0.0008302650000000001,0.00832335,37.315894570000154,1200.0,10.0
0.0009015669375000001,0.009036369375,38.75136337885525,1200.0,10.0
0.0009728688750000002,0.00974938875,40.08420563767061,1200.0,10.0
0.0010441708125,0.010462408125000001,41.34158149201438,1200.0,10.0
0.0011154727500000002,0.011175427500000001,42.566171170636544,1200.0,10.0
0.0011867746875000003,0.011888446875000002,43.816174985468955,1200.0,10.0
0.0012580766250000002,0.012601466250000002,45.08101987984395,1200.0,10.0
0.0013293785625000001,0.013314485625,46.34586477421897,1200.0,10.0
0.0014006805000000002,0.014027505000000001,47.61070966859398,1200.0,10.0
0.0014719824375000004,0.014740524375000001,48.875554562968986,1200.0,10.0
0.0015432843750000003,0.01545354375,50.14039945734396,1200.0,10.0
0.0016145863125000002,0.016166563125,51.40524435171897,1200.0,10.0
0.0016858882500000003,0.0168795825,52.70068384166534,1200.0,10.0
0.0017571901875000004,0.017592601875000002,53.99131442499074,1200.0,10.0
0.0018284921250000003,0.01830562125,55.23402176647262,1200.0,10.0
0.0018997940625000002,0.019018640625,56.398957480187704,1200.0,10.0
0.0019710960000000003,0.01973166,57.46953912951192,1200.0,10.0
0.0020440156250000003,0.02046085625,58.442450227120496,1200.0,10.0
0.00211693525,0.0211900525,59.327640234987804,1200.0,10.0
0.002189854875,0.021919248750000002,60.148324564387536,1200.0,10.0
0.0022627745,0.022648445000000003,60.94098457589263,1200.0,10.0
0.002335694125,0.023377641250000004,61.75536757937525,1200.0,10.0
0.00240861375,0.024106837500000002,62.58243614687527,1200.0,10.0
0.002481533375,0.02483603375,63.409504714375274,1200.0,10.0
0.002554453,0.02556523,64.23657328187531,1200.0,10.0
0.002627372625,0.026294426250000003,65.06364184937534,1200.0,10.0
0.00270029225,0.0270236225,65.89071041687531,1200.0,10.0
0.002773211875,0.027752818749999998,66.71777898437529,1200.0,10.0
0.0028461314999999997,0.028482015,67.5635431319019,1200.0,10.0
0.0029190511249999997,0.02921121125,68.40636867877397,1200.0,10.0
0.0029919707499999997,0.0299404075,69.2199095501572,1200.0,10.0
0.0030648903749999996,0.030669603749999996,69.98592615578167,1200.0,10.0
0.00313781,0.0313988,70.69428538994185,1200.0,10.0
0.0032135853125000004,0.032156553125,71.34296063149665,1200.0,10.0
0.0032893606250000004,0.03291430625,71.93803174386937,1200.0,10.0
0.0033651359375000004,0.033672059375,72.4936850750477,1200.0,10.0
0.0034409112500000004,0.034429812500000004,73.03221345758377,1200.0,10.0
0.0035166865625000003,0.035187565625,73.58401620859401,1200.0,10.0
0.0035924618750000003,0.035945318750000003,74.14357078546898,1200.0,10.0
0.0036682371875000003,0.03670307187500001,74.70312536234403,1200.0,10.0
0.0037440125000000003,0.037460825,75.2626799392191,1200.0,10.0
0.0038197878125000003,0.038218578125,75.82223451609407,1200.0,10.0
0.0038955631250000003,0.03897633125,76.38178909296899,1200.0,10.0
0.0039713384375,0.039734084375000006,76.94134366984396,1200.0,10.0
0.00404711375,0.0404918375,77.51276223836314,1200.0,10.0
0.0041228890625,0.041249590625,78.08231600602767,1200.0,10.0
0.004198664375,0.04200734375,78.63328606862352,1200.0,10.0
0.0042744396875,0.042765096875000005,79.15409780015636,1200.0,10.0
0.004350215,0.04352285,79.6383208528517,1200.0,10.0
0.004429968812500001,0.044320388125,80.08466915715466,1200.0,10.0
0.004509722625,0.04511792625,80.49700092172978,1200.0,10.0
0.0045894764375,0.045915464375000006,80.88431863346156,1200.0,10.0
0.00466923025,0.0467130025,81.26076905745434,1200.0,10.0
0.0047489840624999995,0.047510540625,81.6456432370319,1200.0,10.0
0.004828737875,0.048308078750000004,82.03543663265704,1200.0,10.0
0.004908491687500001,0.04910561687500001,82.42523002828207,1200.0,10.0
0.0049882455,0.049903155000000005,82.81502342390705,1200.0,10.0
0.0050679993125,0.050700693125,83.20481681953203,1200.0,10.0
0.0051477531250000005,0.051498231250000005,83.59461021515713,1200.0,10.0
0.005227506937500001,0.05229576937500001,83.98440361078215,1200.0,10.0
0.005307260750000001,0.053093307500000006,84.37946702933279,1200.0,10.0
0.0053870145625000004,0.053890845625,84.77370209739645,1200.0,10.0
0.005466768375,0.05468838375,85.15968222440026,1200.0,10.0
0.0055465221875,0.055485921875,85.53226592456294,1200.0,10.0
0.005626276,0.05628346,85.88859681689482,1200.0,10.0
0.00570242925,0.0570449925,86.22810362519812,1200.0,10.0
0.005778582500000001,0.057806525,86.55250017806667,1200.0,10.0
0.00585473575,0.0585680575,86.86578540888593,1200.0,10.0
0.005930889,0.05932959,87.17424335583259,1200.0,10.0
0.0060070422500000005,0.0600911225,87.48644316187546,1200.0,10.0
0.0060831955,0.060852655,87.80082809937552,1200.0,10.0
0.00615934875,0.0616141875,88.11521303687546,1200.0,10.0
0.006235502,0.062375719999999996,88.42959797437537,1200.0,10.0
0.00631165525,0.06313725249999999,88.74398291187534,1200.0,10.0
0.0063878085,0.063898785,89.0583678493754,1200.0,10.0
0.00646396175,0.06466031750000001,89.37275278687551,1200.0,10.0
0.006540115,0.06542185,89.69086416046116,1200.0,10.0
0.00661626825,0.0661833825,90.00838980696544,1200.0,10.0
0.0066924215,0.066944915,90.32007838014314,1200.0,10.0
0.00676857475,0.06770644749999999,90.62229433259398,1200.0,10.0
0.006844728,0.06846798,90.91301791576183,1200.0,10.0
0.006924728,0.06926798,91.19184517993564,1200.0,10.0
0.007004728,0.07006798,91.4599879742491,1200.0,10.0
0.007084728,0.07086798,91.72027394668025,1200.0,10.0
0.007164728,0.07166797999999999,91.977146544052,1200.0,10.0
0.007244728000000001,0.07246797999999999,92.23666501203192,1200.0,10.0
0.007324728000000001,0.07326798,92.49772858765694,1200.0,10.0
0.007404728000000001,0.07406798,92.75879216328197,1200.0,10.0
0.007484728,0.07486798,93.01985573890697,1200.0,10.0
0.007564728,0.07566798,93.28091931453186,1200.0,10.0
0.007644728,0.07646798,93.54198289015683,1200.0,10.0
0.007724728,0.07726798000000001,93.80304646578172,1200.0,10.0
0.007804728,0.07806798000000001,94.06723017305924,1200.0,10.0
0.007884728,0.07886798,94.33092345313935,1200.0,10.0
0.007964728,0.07966798,94.58972937252794,1200.0,10.0
0.008044728000000001,0.08046798,94.84060390034398,1200.0,10.0
0.008124728000000001,0.08126798,95.08185590832043,1200.0,10.0
0.0082078645625,0.08209934562500001,95.31314717080396,1200.0,10.0
0.008291001125000001,0.08293071125000001,95.53549236475499,1200.0,10.0
0.008374137687500002,0.08376207687500001,95.75125906974723,1200.0,10.0
0.00845727425,0.0845934425,95.9641677679682,1200.0,10.0
0.0085404108125,0.085424808125,96.17929184421898,1200.0,10.0
0.008623547375,0.08625617375,96.39570963359398,1200.0,10.0
0.008706683937500001,0.087087539375,96.612127422969,1200.0,10.0
0.0087898205,0.08791890499999999,96.82854521234387,1200.0,10.0
0.008872957062499999,0.08875027062499999,97.04496300171867,1200.0,10.0
0.008956093625,0.08958163624999999,97.26138079109381,1200.0,10.0
0.0090392301875,0.09041300187499998,97.47779858046884,1200.0,10.0
0.00912236675,0.09124436749999999,97.69686089543997,1200.0,10.0
0.009205503312499998,0.092075733125,97.91550753972145,1200.0,10.0
0.009288639874999999,0.09290709875,98.13001181057632,1200.0,10.0
0.0093717764375,0.093738464375,98.33779368303269,1200.0,10.0
0.009454912999999999,0.09456983,98.53741980988423,1200.0,10.0
0.00953767775,0.0953974775,98.72860352168988,1200.0,10.0
0.0096204425,0.096225125,98.91220482677338,1200.0,10.0
0.009703207249999998,0.0970527725,99.09023041122374,1200.0,10.0
0.009785971999999999,0.09788042,99.26583363889493,1200.0,10.0
0.009868736749999999,0.0987080675,99.44331455140652,1200.0,10.0
0.009951501499999998,0.099535715,99.62189197453125,1200.0,10.0
0.010034266249999998,0.1003633625,99.80046939765585,1200.0,10.0
0.010117030999999999,0.10119101,99.979046820781,1200.0,10.0
0.010199795749999999,0.1020186575,100.15762424390654,1200.0,10.0
0.0102825605,0.102846305,100.33620166703206,1200.0,10.0
0.01036532525,0.1036739525,100.51477909015748,1200.0,10.0
0.01044809,0.1045016,100.69449774117771,1200.0,10.0
0.01053085475,0.1053292475,100.87403701220346,1200.0,10.0
0.010613619500000001,0.106156895,101.05178866880297,1200.0,10.0
0.01069638425,0.1069845425,101.22663931790785,1200.0,10.0
0.010779149,0.10781219,101.3979704078138,1200.0,10.0
0.010862644875,0.10864714875,101.56565822818013,1200.0,10.0
0.01094614075,0.10948210750000001,101.73007391002942,1200.0,10.0
0.011029636625,0.11031706625000001,101.89208342574778,1200.0,10.0
0.011113132500000001,0.111152025,102.05304758908521,1200.0,10.0
0.011196628375,0.11198698374999999,102.21482205515588,1200.0,10.0
0.01128012425,0.1128219425,102.37706971328083,1200.0,10.0
0.011363620125000001,0.11365690125,102.53931737140607,1200.0,10.0
0.011447116,0.11449186,102.70156502953142,1200.0,10.0
0.011530611875,0.11532681875,102.86381268765666,1200.0,10.0
0.01161410775,0.11616177750000001,103.02606034578203,1200.0,10.0
0.011697603625,0.11699673625000001,103.18830800390732,1200.0,10.0
0.0117810995,0.117831695,103.35230286117698,1200.0,10.0
0.011864595375,0.11866665374999999,103.51602309093839,1200.0,10.0
0.01194809125,0.11950161249999999,103.67700651553564,1200.0,10.0
0.012031587125,0.12033657125,103.83354855043768,1200.0,10.0
0.012115083,0.12117153,103.98470220423842,1200.0,10.0
0.012199556562500002,0.122016265625,104.13027807865637,1200.0,10.0
0.012284030125000001,0.12286100124999999,104.27084436853495,1200.0,10.0
0.0123685036875,0.123705736875,104.40772686184316,1200.0,10.0
0.01245297725,0.1245504725,104.54300893967512,1200.0,10.0
0.0125374508125,0.125395208125,104.67953157624945,1200.0,10.0
0.012621924375000001,0.12623994375,104.81677866124949,1200.0,10.0
0.012706397937500002,0.127084679375,104.95402574624943,1200.0,10.0
0.012790871500000002,0.127929415,105.09127283124948,1200.0,10.0
0.012875345062500002,0.128774150625,105.22851991624985,1200.0,10.0
0.012959818625000001,0.12961888625,105.36576700125035,1200.0,10.0
0.0130442921875,0.130463621875,105.50301408625023,1200.0,10.0
0.013128765750000002,0.1313083575,105.64246001608649,1200.0,10.0
0.013213239312500003,0.132153093125,105.78156032803531,1200.0,10.0
0.013297712875000003,0.13299782875,105.91721637896671,1200.0,10.0
0.013382186437500002,0.133842564375,106.04728295440619,1200.0,10.0
0.013466660000000002,0.1346873,106.17056826853498,1200.0,10.0
0.013549998562500002,0.13552068562500003,106.28683396418936,1200.0,10.0
0.013633337125000002,0.13635407125000001,106.39679511286066,1200.0,10.0
0.013716675687500002,0.137187456875,106.5021202146958,1200.0,10.0
0.013800014250000001,0.13802084250000002,106.60543119849615,1200.0,10.0
0.0138833528125,0.138854228125,106.7103034217194,1200.0,10.0
0.013966691375,0.13968761375,106.81608736109442,1200.0,10.0
0.0140500299375,0.140520999375,106.92187130046909,1200.0,10.0
0.0141333685,0.141354385,107.02765523984371,1200.0,10.0
0.0142167070625,0.142187770625,107.13343917921887,1200.0,10.0
0.014300045625,0.14302115625,107.23922311859418,1200.0,10.0
0.0143833841875,0.143854541875,107.34500705796941,1200.0,10.0
0.01446672275,0.14468792749999998,107.45176833577662,1200.0,10.0
0.014550061312499998,0.145521313125,107.55837599399264,1200.0,10.0
0.014633399874999998,0.14635469874999998,107.66345275352649,1200.0,10.0
0.014716738437499998,0.14718808437499997,107.76604511346964,1200.0,10.0
0.014800076999999998,0.14802147,107.86562335109444,1200.0,10.0
0.014882886874999997,0.14884956875,107.96208152185523,1200.0,10.0
0.014965696749999998,0.1496776675,108.05573745938916,1200.0,10.0
0.015048506625,0.15050576625,108.14733277551447,1200.0,10.0
0.015131316499999999,0.15133386499999998,108.2380328602306,1200.0,10.0
0.015214126374999998,0.15216196374999996,108.32942688171964,1200.0,10.0
0.015296936249999999,0.15299006249999997,108.4212261410953,1200.0,10.0
0.015379746125,0.15381816124999997,108.51302540047114,1200.0,10.0
0.015462555999999999,0.15464625999999998,108.60482465984637,1200.0,10.0
0.015545365875,0.15547435874999999,108.69662391922117,1200.0,10.0
0.01562817575,0.1563024575,108.78842317859548,1200.0,10.0
0.015710985625,0.15713055625,108.8802224379697,1200.0,10.0
0.0157937955,0.157958655,108.97322997399779,1200.0,10.0
0.015876605375,0.15878675375,109.06604759120268,1200.0,10.0
0.015959415249999997,0.15961485250000002,109.15697256909692,1200.0,10.0
0.016042225124999997,0.16044295125000002,109.24482610118885,1200.0,10.0
0.016125035,0.16127105,109.32895329498254,1200.0,10.0
0.016207281312500002,0.16209351312499998,109.40922317197855,1200.0,10.0
0.016289527625,0.16291597624999998,109.48602866767428,1200.0,10.0
0.0163717739375,0.163738439375,109.56028663156386,1200.0,10.0
0.01645402025,0.1645609025,109.6334378271363,1200.0,10.0
0.0165362665625,0.165383365625,109.70744693187729,1200.0,10.0
0.016618512874999998,0.16620582875,109.78195702937717,1200.0,10.0
0.016700759187499997,0.167028291875,109.85646712687713,1200.0,10.0
0.0167830055,0.16785075500000002,109.93097722437705,1200.0,10.0
0.016865251812500003,0.16867321812500002,110.00548732187647,1200.0,10.0
0.016947498125000002,0.16949568125000003,110.07999741937542,1200.0,10.0
0.0170297444375,0.17031814437500004,110.15450751687453,1200.0,10.0
0.01711199075,0.1711406075,110.2296485455386,1200.0,10.0
0.0171942370625,0.171963070625,110.30469040345142,1200.0,10.0
0.017276483375,0.17278553375,110.37874397352384,1200.0,10.0
0.017358729687499998,0.173607996875,110.45119371315614,1200.0,10.0
0.017440976,0.17443046,110.521697654238,1200.0,10.0
0.017520640312500002,0.175227103125,110.59018740314764,1200.0,10.0
0.017600304625,0.17602374625,110.65686814075153,1200.0,10.0
0.0176799689375,0.176820389375,110.72221862240389,1200.0,10.0
0.01775963325,0.1776170325,110.78699117794869,1200.0,10.0
0.017839297562500002,0.178413675625,110.85221171171884,1200.0,10.0
0.017918961875,0.17921031874999999,110.91769385109362,1200.0,10.0
0.0179986261875,0.18000696187499998,110.98317599046814,1200.0,10.0
0.0180782905,0.180803605,111.04865812984248,1200.0,10.0
0.018157954812500002,0.18160024812500003,111.11414026921722,1200.0,10.0
0.018237619125,0.18239689125000003,111.1796224085929,1200.0,10.0
0.018317283437499998,0.18319353437500002,111.24510454796895,1200.0,10.0
0.01839694775,0.18399017750000002,111.31066100074756,1200.0,10.0
0.0184766120625,0.18478682062500001,111.37620577282789,1200.0,10.0
0.018556276375,0.18558346375,111.4416341407163,1200.0,10.0
0.018635940687499998,0.186380106875,111.50687360353226,1200.0,10.0
0.018715605,0.18717675,111.57188388300843,1200.0,10.0
0.0187974443125,0.18799514312499999,111.6366569234915,1200.0,10.0
0.018879283625,0.18881353625,111.70121689194178,1200.0,10.0
0.018961122937499998,0.189631929375,111.76562017793395,1200.0,10.0
0.01904296225,0.1904503225,111.8299553936555,1200.0,10.0
0.019124801562500002,0.191268715625,111.89434337390671,1200.0,10.0
0.019206640875,0.19208710875,111.95876216703199,1200.0,10.0
0.0192884801875,0.192905501875,112.02318096015695,1200.0,10.0
0.0193703195,0.193723895,112.08759975328212,1200.0,10.0
0.019452158812500002,0.19454228812500002,112.15201854640759,1200.0,10.0
0.019533998125,0.19536068125,112.2164373395326,1200.0,10.0
0.0196158374375,0.196179074375,112.28085613265705,1200.0,10.0
0.01969767675,0.19699746750000002,112.34630611650505,1200.0,10.0
0.019779516062500002,0.197815860625,112.41159401617413,1200.0,10.0
0.019861355375,0.19863425375000002,112.47526666316548,1200.0,10.0
0.0199431946875,0.19945264687500003,112.53631801774897,1200.0,10.0
0.020025034,0.20027104,112.59418916896345,1200.0,10.0
0.020104226875,0.20106296875000002,112.6487683346171,1200.0,10.0
0.02018341975,0.20185489750000002,112.70039086128658,1200.0,10.0
0.020262612625,0.20264682625000002,112.74983922431747,1200.0,10.0
0.020341805499999997,0.203438755,112.79834302782369,1200.0,10.0
0.020420998375,0.20423068374999997,112.84757900468895,1200.0,10.0
0.020500191249999997,0.20502261249999998,112.89724254843925,1200.0,10.0
0.020579384124999996,0.20581454124999998,112.946906092189,1200.0,10.0
0.020658576999999997,0.20660647,112.99656963593856,1200.0,10.0
0.020737769875,0.20739839875,113.04623317968833,1200.0,10.0
0.020816962749999997,0.2081903275,113.0958967234384,1200.0,10.0
0.020896155624999996,0.20898225625,113.14556026718819,1200.0,10.0
0.020975348499999998,0.209774185,113.19623850607736,1200.0,10.0
0.021054541375,0.21056611375,113.24675725358989,1200.0,10.0
0.021133734249999998,0.2113580425,113.29568658703633,1200.0,10.0
0.021212927124999996,0.21214997125,113.34203655993905,1200.0,10.0
0.021292119999999998,0.2129419,113.38525720203238,1200.0,10.0
0.021371320312499997,0.213733903125,113.4252385192637,1200.0,10.0
0.021450520624999997,0.21452590625,113.46231049379281,1200.0,10.0
0.021529720937499996,0.215317909375,113.49724308399074,1200.0,10.0
0.02160892125,0.2161099125,113.53124622443991,1200.0,10.0
0.021688121562500003,0.216901915625,113.56596982593665,1200.0,10.0
0.021767321875000002,0.21769391875,113.60111415468685,1200.0,10.0
0.021846522187500002,0.218485921875,113.63625848343705,1200.0,10.0
0.0219257225,0.21927792499999998,113.6714028121871,1200.0,10.0
0.0220049228125,0.22006992812499998,113.70654714093658,1200.0,10.0
0.022084123125,0.22086193124999998,113.7416914696867,1200.0,10.0
0.0221633234375,0.22165393437499997,113.77683579843719,1200.0,10.0
0.02224252375,0.2224459375,113.81169603649839,1200.0,10.0
0.0223217240625,0.22323794062500002,113.84660092838034,1200.0,10.0
0.022400924375,0.22402994375000002,113.88195081868622,1200.0,10.0
0.0224801246875,0.224821946875,113.91802286906383,1200.0,10.0
0.022559325,0.22561395,113.95497105820523,1200.0,10.0
0.022636395125,0.22638465125,113.99282618184874,1200.0,10.0
0.022713465250000002,0.22715535250000002,114.0314958527788,1200.0,10.0
0.022790535375,0.22792605375000002,114.0707645008254,1200.0,10.0
0.0228676055,0.228696755,114.11029337286334,1200.0,10.0
0.022944675625,0.22946745624999998,114.14962053281278,1200.0,10.0
0.02302174575,0.23023815749999998,114.18882989906233,1200.0,10.0
0.023098815874999998,0.23100885875,114.22803926531238,1200.0,10.0
0.023175886,0.23177956,114.26724863156242,1200.0,10.0
0.023252956125,0.23255026125,114.30645799781236,1200.0,10.0
0.02333002625,0.2333209625,114.34566736406224,1200.0,10.0
0.023407096375,0.23409166375,114.3848767303119,1200.0,10.0
0.0234841665,0.23486236500000002,114.42471542820182,1200.0,10.0
0.023561236625000002,0.23563306625000002,114.46445520675601,1200.0,10.0
0.02363830675,0.23640376750000003,114.50320920295802,1200.0,10.0
0.023715376875,0.23717446875000003,114.54036343471984,1200.0,10.0
0.023792447,0.23794517,114.57557680088082,1200.0,10.0
0.023869963187500003,0.23872033187500002,114.60878108120855,1200.0,10.0
0.023947479375,0.23949549375,114.64018093639969,1200.0,10.0
0.0240249955625,0.240270655625,114.6702539080781,1200.0,10.0
0.02410251175,0.24104581749999998,114.69975041879545,1200.0,10.0
0.0241800279375,0.24182097937499997,114.72969377203243,1200.0,10.0
0.024257544125,0.24259614124999998,114.75989806765769,1200.0,10.0
0.024335060312499997,0.243371303125,114.7901023632828,1200.0,10.0
0.024412576499999998,0.24414646499999998,114.8203066589074,1200.0,10.0
0.0244900926875,0.24492162687499996,114.85051095453252,1200.0,10.0
0.024567608874999997,0.24569678874999998,114.88071525015758,1200.0,10.0
0.024645125062499995,0.246471950625,114.9109195457821,1200.0,10.0
0.024722641249999996,0.24724711249999998,114.94059868189971,1200.0,10.0
0.024800157437499998,0.24802227437499996,114.97036036341375,1200.0,10.0
0.024877673625,0.24879743624999998,115.00094465250255,1200.0,10.0
0.0249551898125,0.249572598125,115.0328638999049,1200.0,10.0
0.025032706,0.25034776,115.06640274492041,1200.0,10.0
0.025109190499999996,0.251112605,115.10161811540901,1200.0,10.0
0.025185674999999998,0.25187744999999995,115.13833922779162,1200.0,10.0
0.0252621595,0.25264229499999996,115.17616758704814,1200.0,10.0
0.025338644,0.25340714,115.21447698671922,1200.0,10.0
0.025415128500000002,0.254171985,115.25241350890806,1200.0,10.0
0.025491613,0.25493683,115.29013228203237,1200.0,10.0
0.025568097499999998,0.25570167499999996,115.32785105515588,1200.0,10.0
0.025644582,0.25646652,115.36556982827938,1200.0,10.0
0.0257210665,0.257231365,115.40328860140329,1200.0,10.0
0.025797551,0.25799620999999995,115.44100737452838,1200.0,10.0
0.025874035499999996,0.25876105499999996,115.47872614765367,1200.0,10.0
0.025950519999999998,0.2595259,115.51717439224069,1200.0,10.0
0.0260270045,0.260290745,115.55550797735712,1200.0,10.0
0.026103488999999997,0.26105559,115.59269892153962,1200.0,10.0
0.026179973499999995,0.26182043499999996,115.62803554531327,1200.0,10.0
0.026256457999999996,0.26258528,115.6611224711926,1200.0,10.0
0.026333890624999995,0.26335960625,115.69188062368039,1200.0,10.0
0.026411323249999997,0.26413393249999995,115.7205472292678,1200.0,10.0
0.026488755875,0.26490825874999996,115.74767581643516,1200.0,10.0
0.026566188499999997,0.26568258499999997,115.77413621565101,1200.0,10.0
0.026643621124999996,0.26645691125,115.80111455937403,1200.0,10.0
0.026721053749999998,0.2672312375,115.82839536687443,1200.0,10.0
0.026798486375,0.26800556375,115.85567617437431,1200.0,10.0
0.026875918999999998,0.26877989,115.88295698187383,1200.0,10.0
0.026953351624999997,0.26955421625000003,115.91023778937355,1200.0,10.0
0.02703078425,0.27032854250000005,115.9375185968737,1200.0,10.0
0.027108216875,0.27110286875,115.964799404374,1200.0,10.0
0.0271856495,0.271877195,115.99209050910548,1200.0,10.0
0.027263082124999997,0.27265152125000003,116.01937999530165,1200.0,10.0
0.02734051475,0.2734258475,116.04665335195993,1200.0,10.0
0.027417947375,0.27420017375,116.07390053300027,1200.0,10.0
0.02749538,0.2749745,116.10111595726552,1200.0,10.0
0.0275732025625,0.27575272562500003,116.12829850852606,1200.0,10.0
0.027651025125,0.27653095125000005,116.15545153547613,1200.0,10.0
0.0277288476875,0.277309176875,116.18258285173283,1200.0,10.0
0.02780667025,0.2780874025,116.20970473583688,1200.0,10.0
0.027884492812499998,0.27886562812500004,116.23683393125229,1200.0,10.0
0.027962315374999998,0.27964385375,116.26396739625078,1200.0,10.0
0.0280401379375,0.280422079375,116.29110086125054,1200.0,10.0
0.0281179605,0.28120030500000004,116.31823432625045,1200.0,10.0
0.0281957830625,0.281978530625,116.34536779124872,1200.0,10.0
0.028273605625000003,0.28275675625,116.37250125624718,1200.0,10.0
0.028351428187500003,0.28353498187500004,116.3996347212482,1200.0,10.0
0.028429250750000003,0.2843132075,116.42691977903203,1200.0,10.0
0.028507073312500002,0.285091433125,116.45418100922302,1200.0,10.0
0.028584895875000002,0.28586965875000003,116.48120478513587,1200.0,10.0
0.0286627184375,0.286647884375,116.50784321137347,1200.0,10.0
0.028740541,0.28742611,116.53401412382777,1200.0,10.0
0.028819571375000002,0.28821641375,116.55970108967497,1200.0,10.0
0.028898601750000003,0.2890067175,116.58495340738061,1200.0,10.0
0.028977632125,0.28979702125,116.60988610669908,1200.0,10.0
0.0290566625,0.290587325,116.63467994867274,1200.0,10.0
0.029135692875,0.29137762875,116.6595814256294,1200.0,10.0
0.029214723249999998,0.2921679325,116.6845457581285,1200.0,10.0
0.029293753625,0.29295823625,116.70951009062692,1200.0,10.0
0.029372784,0.29374854,116.73447442312546,1200.0,10.0
0.029451814375,0.29453884375,116.75943875562521,1200.0,10.0
0.02953084475,0.2953291475,116.78440308812576,1200.0,10.0
0.029609875125,0.29611945125,116.80936742062575,1200.0,10.0
0.0296889055,0.296909755,116.83497271494942,1200.0,10.0
0.029767935875000002,0.29770005875,116.86047726188524,1200.0,10.0
0.029846966250000002,0.2984903625,116.88497780900092,1200.0,10.0
0.029925996625,0.29928066625,116.90784902768782,1200.0,10.0
0.030005027,0.30007097,116.92874351316321,1200.0,10.0
0.0300825955625,0.300846655625,116.94759178447265,1200.0,10.0
0.030160164125,0.30162234125,116.96460228448578,1200.0,10.0
0.0302377326875,0.302398026875,116.98026137989729,1200.0,10.0
0.030315301250000003,0.3031737125,116.99533336122532,1200.0,10.0
0.0303928698125,0.303949398125,117.01086044281591,1200.0,10.0
0.030470438375000002,0.30472508375,117.02665328906372,1200.0,10.0
0.030548006937500004,0.30550076937500004,117.0424461353114,1200.0,10.0
0.030625575500000002,0.306276455,117.05823898156017,1200.0,10.0
0.0307031440625,0.30705214062499997,117.07403182780916,1200.0,10.0
0.030780712625,0.30782782625,117.08982467405963,1200.0,10.0
0.030858281187500003,0.308603511875,117.10561752031052,1200.0,10.0
0.03093584975,0.3093791975,117.12198871173167,1200.0,10.0
0.0310134183125,0.310154883125,117.13826899795026,1200.0,10.0
0.031090986875,0.31093056875,117.1536433668004,1200.0,10.0
0.031168555437500002,0.311706254375,117.16754757909345,1200.0,10.0
0.031246124,0.31248194,117.17966816861293,1200.0,10.0
0.0313237860625,0.313258560625,117.18994244211613,1200.0,10.0
0.031401448125,0.31403518124999996,117.19855847933253,1200.0,10.0
0.031479110187500006,0.31481180187499996,117.20595513296551,1200.0,10.0
0.031556772250000004,0.31558842249999997,117.21282202869054,1200.0,10.0
0.0316344343125,0.31636504312499997,117.22009956515826,1200.0,10.0
0.031712096375,0.31714166374999997,117.22761690328177,1200.0,10.0
0.031789758437499996,0.31791828437499997,117.23513424140548,1200.0,10.0
0.0318674205,0.318694905,117.24265157952958,1200.0,10.0
0.031945082562500005,0.319471525625,117.25016891765377,1200.0,10.0
0.032022744625,0.32024814625,117.25768625577768,1200.0,10.0
0.0321004066875,0.321024766875,117.26520359390226,1200.0,10.0
0.03217806875,0.3218013875,117.27316737922257,1200.0,10.0
0.032255730812499994,0.322578008125,117.28106099127082,1200.0,10.0
0.032333392875,0.32335462875,117.28825529036968,1200.0,10.0
0.0324110549375,0.324131249375,117.29431471828048,1200.0,10.0
0.032488717,0.32490787,117.29899729820345,1200.0,10.0
0.032565665875,0.32567735875,117.30225463477915,1200.0,10.0
0.03264261475,0.32644684749999997,117.30423191408576,1200.0,10.0
0.032719563625,0.32721633625,117.30526790364264,1200.0,10.0
0.0327965125,0.327985825,117.30589495240923,1200.0,10.0
0.032873461374999996,0.32875531375,117.30683899078392,1200.0,10.0
0.03295041025,0.32952480250000005,117.30796814141023,1200.0,10.0
0.033027359125,0.33029429125000004,117.30909729203633,1200.0,10.0
0.033104308,0.33106378000000003,117.31022644266237,1200.0,10.0
0.033181256874999995,0.33183326875,117.31135559328699,1200.0,10.0
0.03325820575,0.3326027575,117.312484743911,1200.0,10.0
0.033335154625,0.33337224625,117.31361389453438,1200.0,10.0
0.0334121035,0.334141735,117.3144607575012,1200.0,10.0
0.033489052375,0.33491122375,117.31558990812437,1200.0,10.0
0.033566001250000005,0.3356807125,117.31671905874815,1200.0,10.0
0.033642950125,0.33645020125,117.31784820937295,1200.0,10.0
0.033719899000000005,0.33721969,117.31897735999921,1200.0,10.0