File: datasets/steel_spring/csv/BS2V-1000-10.0.csv
Time(s),Strain(%),Stress(MPa),Temp(C),SR(%/s)
0.0,2.284e-05,0.09955583000000014,1000.0,10.0
3.331249999999999e-08,2.3173125e-05,0.10831297375000026,1000.0,10.0
6.662499999999998e-08,2.350625e-05,0.11707011750000029,1000.0,10.0
9.993749999999996e-08,2.3839375e-05,0.12582726125000024,1000.0,10.0
1.3324999999999995e-07,2.41725e-05,0.13458440500000013,1000.0,10.0
1.6656249999999994e-07,2.4505625e-05,0.1455308346875006,1000.0,10.0
1.9987499999999993e-07,2.483875e-05,0.15428797843750053,1000.0,10.0
2.3318749999999992e-07,2.5171875e-05,0.16304512218750036,1000.0,10.0
2.664999999999999e-07,2.5505e-05,0.1718022659375003,1000.0,10.0
2.998124999999999e-07,2.5838125e-05,0.18055940968750045,1000.0,10.0
3.331249999999999e-07,2.617125e-05,0.1893165534375003,1000.0,10.0
3.6643749999999987e-07,2.6504375e-05,0.19807369718750037,1000.0,10.0
3.9974999999999986e-07,2.6837500000000002e-05,0.20737843602024192,1000.0,10.0
4.3306249999999985e-07,2.7170625000000002e-05,0.21659710299715967,1000.0,10.0
4.6637499999999983e-07,2.7503750000000002e-05,0.22495801941086732,1000.0,10.0
4.996874999999998e-07,2.7836875000000003e-05,0.23192694615625098,1000.0,10.0
5.329999999999998e-07,2.817e-05,0.23720708373046973,1000.0,10.0
6.001249999999998e-07,2.884125e-05,0.24073907223295582,1000.0,10.0
6.672499999999998e-07,2.95125e-05,0.24270099136541345,1000.0,10.0
7.343749999999999e-07,3.018375e-05,0.24350836043181978,1000.0,10.0
8.014999999999998e-07,3.0855e-05,0.24381413833842475,1000.0,10.0
8.686249999999997e-07,3.152625e-05,0.24450872359375106,1000.0,10.0
9.357499999999997e-07,3.21975e-05,0.24543036046875066,1000.0,10.0
1.0028749999999997e-06,3.2868749999999996e-05,0.2463519973437503,1000.0,10.0
1.0699999999999997e-06,3.354e-05,0.24727363421874987,1000.0,10.0
1.1371249999999997e-06,3.4211250000000006e-05,0.2481952710937495,1000.0,10.0
1.2042499999999995e-06,3.4882500000000004e-05,0.24911690796874944,1000.0,10.0
1.2713749999999995e-06,3.555375e-05,0.25003854484374943,1000.0,10.0
1.3384999999999996e-06,3.6225e-05,0.2519103844985794,1000.0,10.0
1.4056249999999996e-06,3.689625e-05,0.2536328697869323,1000.0,10.0
1.4727499999999996e-06,3.7567499999999996e-05,0.25386696156108024,1000.0,10.0
1.5398749999999996e-06,3.8238749999999994e-05,0.25168563271875083,1000.0,10.0
1.6069999999999996e-06,3.891e-05,0.24657386820312616,1000.0,10.0
1.6741249999999996e-06,3.958125e-05,0.23842866500284227,1000.0,10.0
1.7412499999999996e-06,4.02525e-05,0.22755903215198986,1000.0,10.0
1.8083749999999996e-06,4.092375e-05,0.2146859907301145,1000.0,10.0
1.8754999999999997e-06,4.1595e-05,0.20094257386221626,1000.0,10.0
1.942625e-06,4.2266249999999995e-05,0.18787382671875022,1000.0,10.0
2.0097499999999997e-06,4.29375e-05,0.1751990660937503,1000.0,10.0
2.0768749999999995e-06,4.3608750000000005e-05,0.1625243054687503,1000.0,10.0
2.1439999999999997e-06,4.428e-05,0.1498495448437503,1000.0,10.0
2.211125e-06,4.495125e-05,0.13717478421875054,1000.0,10.0
2.2782499999999997e-06,4.56225e-05,0.12450002359375084,1000.0,10.0
2.3453749999999995e-06,4.629375e-05,0.11182526296875095,1000.0,10.0
2.4124999999999998e-06,4.6965e-05,0.09832913424538446,1000.0,10.0
2.479625e-06,4.7636250000000007e-05,0.0849621094507584,1000.0,10.0
2.54675e-06,4.8307500000000005e-05,0.07288167208392586,1000.0,10.0
2.6138749999999996e-06,4.897875e-05,0.0628891568750006,1000.0,10.0
2.681e-06,4.965e-05,0.05542974978515673,1000.0,10.0
2.848625e-06,5.132625e-05,0.05059248800662904,1000.0,10.0
3.01625e-06,5.30025e-05,0.048110259962713224,1000.0,10.0
3.183875e-06,5.4678750000000006e-05,0.04735980530776528,1000.0,10.0
3.3515e-06,5.6355000000000005e-05,0.04736171492720181,1000.0,10.0
3.519125e-06,5.8031250000000004e-05,0.04678043093750009,1000.0,10.0
3.68675e-06,5.970750000000001e-05,0.045858579687500144,1000.0,10.0
3.854375e-06,6.138375000000002e-05,0.04493672843750018,1000.0,10.0
4.022e-06,6.306000000000001e-05,0.04401487718750019,1000.0,10.0
4.189625e-06,6.473625e-05,0.043093025937500175,1000.0,10.0
4.35725e-06,6.641250000000001e-05,0.04217117468750014,1000.0,10.0
4.524875e-06,6.808875000000001e-05,0.04124932343750017,1000.0,10.0
4.6924999999999995e-06,6.976500000000001e-05,0.021908782457741603,1000.0,10.0
4.8601249999999995e-06,7.144125e-05,0.005463320080492412,1000.0,10.0
5.027749999999999e-06,7.31175e-05,0.01786881343169988,1000.0,10.0
5.195374999999999e-06,7.479375000000001e-05,0.07709471590625033,1000.0,10.0
5.362999999999999e-06,7.647e-05,0.19312405716796963,1000.0,10.0
7.072875e-06,9.356875000000001e-05,0.36795344314962286,1000.0,10.0
8.78275e-06,0.00011066750000000001,0.5955930560529148,1000.0,10.0
1.0492625e-05,0.00012776625,0.8620666543484888,1000.0,10.0
1.2202499999999999e-05,0.00014486500000000002,1.1454115727759289,1000.0,10.0
1.3912374999999997e-05,0.00016196375000000003,1.4156787223437568,1000.0,10.0
1.5622249999999998e-05,0.00017906250000000002,1.6783088542187583,1000.0,10.0
1.7332124999999998e-05,0.00019616125,1.9409389860937591,1000.0,10.0
1.9041999999999998e-05,0.00021326000000000003,2.2035691179687604,1000.0,10.0
2.0751875e-05,0.00023035875000000004,2.4661992498437617,1000.0,10.0
2.246175e-05,0.00024745750000000003,2.728829381718764,1000.0,10.0
2.4171625e-05,0.00026455625,2.9914595135937643,1000.0,10.0
2.58815e-05,0.000281655,3.094580043756052,1000.0,10.0
2.7591375e-05,0.00029875375,3.2227725438352413,1000.0,10.0
2.930125e-05,0.0003158525,3.6008201923966774,1000.0,10.0
3.1011125e-05,0.00033295125000000004,4.3843421130625195,1000.0,10.0
3.2721e-05,0.00035005,5.659793374511743,1000.0,10.0
5.8666687499999994e-05,0.0006095068750000001,7.444464990480146,1000.0,10.0
8.461237499999999e-05,0.00086896375,9.686483919760343,1000.0,10.0
0.00011055806249999999,0.0011284206249999999,12.26481306620176,1000.0,10.0
0.00013650375,0.0013878775,14.989251278710649,1000.0,10.0
0.0001624494375,0.001647334375,17.600433351250086,1000.0,10.0
0.000188395125,0.00190679125,20.145477296250096,1000.0,10.0
0.0002143408125,0.002166248125,22.690521241250096,1000.0,10.0
0.0002402865,0.0024257050000000002,25.2355651862501,1000.0,10.0
0.0002662321875,0.002685161875,27.780609131250092,1000.0,10.0
0.000292177875,0.00294461875,30.32565307625011,1000.0,10.0
0.0003181235625,0.0032040756250000003,32.87069702125011,1000.0,10.0
0.00034406925,0.0034635325000000002,35.407596412533145,1000.0,10.0
0.0003700149375,0.003722989375,37.94577597757115,1000.0,10.0
0.000395960625,0.0039824462500000005,40.496713136236274,1000.0,10.0
0.0004219063125,0.004241903125,43.068353794593875,1000.0,10.0
0.000447852,0.00450136,45.66511234490246,1000.0,10.0
0.0004992183124999999,0.005015023125,48.28787166561378,1000.0,10.0
0.0005505846249999999,0.0055286862499999995,50.93398312137265,1000.0,10.0
0.0006019509374999999,0.006042349375,53.59726656301722,1000.0,10.0
0.0006533172499999999,0.0065560125,56.26801032757869,1000.0,10.0
0.0007046835624999999,0.007069675625,58.932971238281496,1000.0,10.0
0.0007560498749999999,0.00758333875,61.59455513890652,1000.0,10.0
0.0008074161874999999,0.008097001874999999,64.25613903953155,1000.0,10.0
0.0008587824999999999,0.008610665,66.91772294015652,1000.0,10.0
0.0009101488125,0.009124328125000001,69.57930684078154,1000.0,10.0
0.000961515125,0.00963799125,72.24089074140653,1000.0,10.0
0.0010128814375,0.010151654375,74.90247464203152,1000.0,10.0
0.00106424775,0.0106653175,77.62467635341687,1000.0,10.0
0.0011156140625,0.011178980625000001,80.33735006202684,1000.0,10.0
0.001166980375,0.01169264375,82.95507229470334,1000.0,10.0
0.0012183466875,0.012206306875,85.4187037238754,1000.0,10.0
0.001269713,0.01271997,87.69538916755899,1000.0,10.0
0.00134074275,0.0134302675,89.77855758935736,1000.0,10.0
0.0014117725000000001,0.014140565,91.68792209846093,1000.0,10.0
0.00148280225,0.0148508625,93.46947994964708,1000.0,10.0
0.001553832,0.01556116,95.19551254328046,1000.0,10.0
0.00162486175,0.0162714575,96.96458542531273,1000.0,10.0
0.0016958914999999999,0.016981754999999998,98.75879252156277,1000.0,10.0
0.00176692125,0.0176920525,100.55299961781274,1000.0,10.0
0.001837951,0.018402349999999998,102.3472067140628,1000.0,10.0
0.00190898075,0.019112647499999996,104.14141381031281,1000.0,10.0
0.0019800105,0.019822944999999998,105.93562090656285,1000.0,10.0
0.0020510402500000004,0.0205332425,107.72982800281285,1000.0,10.0
0.00212207,0.021243539999999998,109.56302726398124,1000.0,10.0
0.00219309975,0.021953837499999997,111.39009767537922,1000.0,10.0
0.0022641295,0.022664135,113.15609092872084,1000.0,10.0
0.0023351592499999997,0.0233744325,114.82296588750043,1000.0,10.0
0.002406189,0.02408473,116.36958858699262,1000.0,10.0
0.0024848828125000003,0.024871668125,117.79173223425242,1000.0,10.0
0.0025635766250000002,0.02565860625,119.10207720811489,1000.0,10.0
0.0026422704375,0.026445544374999998,120.33021105919562,1000.0,10.0
0.00272096425,0.0272324825,121.52262850989048,1000.0,10.0
0.0027996580625,0.028019420625,122.74273145437563,1000.0,10.0
0.002878351875,0.028806358749999997,123.97900188187575,1000.0,10.0
0.0029570456875,0.029593296874999998,125.2152723093757,1000.0,10.0
0.0030357394999999997,0.030380235,126.45154273687565,1000.0,10.0
0.0031144333124999996,0.031167173125,127.68781316437573,1000.0,10.0
0.0031931271249999995,0.03195411125,128.92408359187584,1000.0,10.0
0.0032718209374999994,0.032741049375,130.16035401937597,1000.0,10.0
0.00335051475,0.033527987499999995,131.4167752207712,1000.0,10.0
0.0034292085625,0.03431492562499999,132.67002909185214,1000.0,10.0
0.003507902375,0.03510186375,133.8917188780781,1000.0,10.0
0.0035865961875,0.035888801875,135.06218528784422,1000.0,10.0
0.00366529,0.03667574,136.1705064924808,1000.0,10.0
0.003735870875,0.03738154875,137.21449812625397,1000.0,10.0
0.00380645175,0.0380873575,138.20071328636558,1000.0,10.0
0.0038770326249999995,0.03879316625,139.14444253295304,1000.0,10.0
0.0039476135,0.039498975,140.069713889089,1000.0,10.0
0.004018194374999999,0.04020478375,141.00929284078197,1000.0,10.0
0.004088775249999999,0.040910592499999995,141.95722699140686,1000.0,10.0
0.004159356124999999,0.04161640125,142.90516114203191,1000.0,10.0
0.004229937,0.04232221,143.8530952926571,1000.0,10.0
0.004300517875,0.04302801875,144.80102944328212,1000.0,10.0
0.00437109875,0.0437338275,145.74896359390704,1000.0,10.0
0.004441679625,0.04443963625,146.6968977445319,1000.0,10.0
0.0045122605,0.045145445,147.66058307982436,1000.0,10.0
0.0045828413750000005,0.04585125375,148.6217926191529,1000.0,10.0
0.004653422250000001,0.046557062499999996,149.5583295711158,1000.0,10.0
0.004724003125000001,0.04726287125,150.4548269262813,1000.0,10.0
0.004794584,0.04796868,151.3027474571875,1000.0,10.0
0.0048711318125,0.048734158124999996,152.1003837183421,1000.0,10.0
0.004947679625,0.04949963625,152.85285804622185,1000.0,10.0
0.0050242274375,0.050265114375,153.5721225592739,1000.0,10.0
0.00510077525,0.0510305925,154.27695915791514,1000.0,10.0
0.0051773230625,0.051796070624999996,154.99297952453162,1000.0,10.0
0.005253870875,0.05256154875,155.71553087015656,1000.0,10.0
0.0053304186875000005,0.053327026875,156.4380822157815,1000.0,10.0
0.005406966500000001,0.054092505,157.1606335614064,1000.0,10.0
0.005483514312500001,0.054857983124999996,157.88318490703134,1000.0,10.0
0.005560062125000001,0.05562346125,158.60573625265656,1000.0,10.0
0.0056366099375,0.056388939375,159.3282875982819,1000.0,10.0
0.00571315775,0.0571544175,160.06136459364822,1000.0,10.0
0.005789705562500001,0.057919895624999995,160.79278715084394,1000.0,10.0
0.005866253375,0.05868537375,161.50772237592474,1000.0,10.0
0.0059428011875,0.059450851875,162.19590134231376,1000.0,10.0
0.006019349,0.06021633,162.8516190908017,1000.0,10.0
0.0060951516875,0.060974356874999996,163.47373462954698,1000.0,10.0
0.006170954375,0.06173238375,164.0656709340755,1000.0,10.0
0.0062467570625,0.062490410625000006,164.63541494728017,1000.0,10.0
0.00632255975,0.0632484375,165.19551757942108,1000.0,10.0
0.006398362437499999,0.064006464375,165.76309370812606,1000.0,10.0
0.0064741651249999995,0.06476449125,166.335034130626,1000.0,10.0
0.0065499678125,0.065522518125,166.9069745531259,1000.0,10.0
0.006625770499999999,0.066280545,167.4789149756257,1000.0,10.0
0.006701573187499999,0.067038571875,168.0508553981254,1000.0,10.0
0.006777375874999999,0.06779659874999999,168.62279582062516,1000.0,10.0
0.006853178562499999,0.06855462562499999,169.1947362431252,1000.0,10.0
0.006928981249999999,0.06931265249999999,169.7732599038607,1000.0,10.0
0.007004783937499999,0.07007067937499999,170.35074880086248,1000.0,10.0
0.0070805866249999995,0.07082870624999998,170.91792574203808,1000.0,10.0
0.007156389312499999,0.071586733125,171.46836805593853,1000.0,10.0
0.007232191999999999,0.07234476,171.99850759175882,1000.0,10.0
0.007309728624999999,0.07312012625,172.50763071933824,1000.0,10.0
0.007387265249999999,0.07389549249999999,172.99787832915976,1000.0,10.0
0.007464801874999999,0.07467085875,173.4742458323501,1000.0,10.0
0.007542338499999999,0.075446225,173.94458316067974,1000.0,10.0
0.007619875124999999,0.07622159125,174.41959476656376,1000.0,10.0
0.007697411749999999,0.0769969575,174.89733600781338,1000.0,10.0
0.007774948374999999,0.07777232375000001,175.37507724906288,1000.0,10.0
0.007852485,0.07854769,175.8528184903128,1000.0,10.0
0.007930021624999999,0.07932305625,176.33055973156274,1000.0,10.0
0.00800755825,0.0800984225,176.80830097281287,1000.0,10.0
0.008085094875,0.08087378875000001,177.28604221406312,1000.0,10.0
0.0081626315,0.081649155,177.76902165343054,1000.0,10.0
0.008240168124999999,0.08242452125,178.25117774458388,1000.0,10.0
0.00831770475,0.0831998875,178.72512874491943,1000.0,10.0
0.008395241375000001,0.08397525375,179.1857642172499,1000.0,10.0
0.008472778,0.08475062,179.63024502980423,1000.0,10.0
0.008551694625,0.08553978625,180.05800335622914,1000.0,10.0
0.00863061125,0.0863289525,180.47074267558654,1000.0,10.0
0.008709527875,0.08711811875,180.87243777235503,1000.0,10.0
0.0087884445,0.087907285,181.2693347364306,1000.0,10.0
0.008867361124999999,0.08869645125,181.66995096312579,1000.0,10.0
0.008946277749999999,0.0894856175,182.07273912562593,1000.0,10.0
0.009025194375,0.09027478375,182.475527288126,1000.0,10.0
0.009104111,0.09106395,182.878315450626,1000.0,10.0
0.009183027625,0.09185311625,183.28110361312542,1000.0,10.0
0.009261944250000001,0.0926422825,183.68389177562548,1000.0,10.0
0.009340860875,0.09343144875,184.08667993812546,1000.0,10.0
0.0094197775,0.09422061500000001,184.49286632457668,1000.0,10.0
0.009498694125,0.09500978125000001,184.8985185728456,1000.0,10.0
0.00957761075,0.09579894750000001,185.29884785785185,1000.0,10.0
0.009656527375,0.09658811375000001,185.69053883915583,1000.0,10.0
0.009735444,0.09737728,186.07174966095673,1000.0,10.0
0.0098134986875,0.09815782687499999,186.4421119520946,1000.0,10.0
0.009891553375,0.09893837375,186.80273082604944,1000.0,10.0
0.0099696080625,0.099718920625,187.15618488094196,1000.0,10.0
0.01004766275,0.1004994675,187.50652619953263,1000.0,10.0
0.0101257174375,0.101280014375,187.85928034922105,1000.0,10.0
0.010203772125,0.10206056125,188.21344351859642,1000.0,10.0
0.0102818268125,0.102841108125,188.5676066879708,1000.0,10.0
0.010359881500000001,0.10362165500000001,188.92176985734505,1000.0,10.0
0.0104379361875,0.104402201875,189.27593302671923,1000.0,10.0
0.010515990875,0.10518274875,189.63009619609323,1000.0,10.0
0.010594045562500001,0.10596329562500001,189.98425936546755,1000.0,10.0
0.01067210025,0.1067438425,190.34143059645962,1000.0,10.0
0.0107501549375,0.107524389375,190.69812901559922,1000.0,10.0
0.010828209625000002,0.10830493625000001,191.0501156200639,1000.0,10.0
0.0109062643125,0.10908548312500001,191.39445571559216,1000.0,10.0
0.010984319000000001,0.10986603,191.72951891648307,1000.0,10.0
0.011064156125000002,0.11066440125,192.05497914559666,1000.0,10.0
0.011143993250000001,0.1114627725,192.37181463435348,1000.0,10.0
0.011223830375,0.11226114375,192.6823079227344,1000.0,10.0
0.0113036675,0.113059515,192.99004585928077,1000.0,10.0
0.011383504624999999,0.11385788625,193.2999196010945,1000.0,10.0
0.01146334175,0.1146562575,193.6110405879695,1000.0,10.0
0.011543178875,0.11545462875,193.92216157484472,1000.0,10.0
0.011623016,0.116253,194.23328256171962,1000.0,10.0
0.011702853124999999,0.11705137125,194.54440354859483,1000.0,10.0
0.01178269025,0.1178497425,194.85552453546975,1000.0,10.0
0.011862527375000001,0.11864811374999999,195.16664552234482,1000.0,10.0
0.0119423645,0.11944648499999999,195.48058322206145,1000.0,10.0
0.012022201625,0.12024485624999999,195.79407818642608,1000.0,10.0
0.01210203875,0.12104322749999999,196.10316106400873,1000.0,10.0
0.012181875875000001,0.12184159875,196.4050838422818,1000.0,10.0
0.012261713,0.12263997,196.6983198476181,1000.0,10.0
0.012341893187500001,0.123441771875,196.98256374529166,1000.0,10.0
0.012422073375,0.12424357375,197.2587315394789,1000.0,10.0
0.0125022535625,0.125045375625,197.52896057325688,1000.0,10.0
0.01258243375,0.1258471775,197.79660952860567,1000.0,10.0
0.012662613937500001,0.12664897937499997,198.06625842640568,1000.0,10.0
0.012742794125,0.12745078124999998,198.3370752295307,1000.0,10.0
0.012822974312499999,0.12825258312499999,198.60789203265574,1000.0,10.0
0.0129031545,0.129054385,198.87870883578154,1000.0,10.0
0.0129833346875,0.129856186875,199.14952563890748,1000.0,10.0
0.013063514875,0.13065798875,199.42034244203285,1000.0,10.0
0.013143695062499999,0.13145979062500002,199.6911592451578,1000.0,10.0
0.01322387525,0.1322615925,199.9640862835431,1000.0,10.0
0.0133040554375,0.13306339437499998,200.23668163183325,1000.0,10.0
0.013384235625000001,0.13386519624999998,200.50597151676155,1000.0,10.0
0.013464415812500002,0.134666998125,200.76989717222017,1000.0,10.0
0.013544596,0.1354688,201.0273148392598,1000.0,10.0
0.0136266344375,0.13628918437499998,201.2779957660907,1000.0,10.0
0.013708672875000001,0.13710956875,201.52262620808182,1000.0,10.0
0.0137907113125,0.137929953125,201.76280742776052,1000.0,10.0
0.01387274975,0.1387503375,202.00105569481582,1000.0,10.0
0.0139547881875,0.139570721875,202.2408022860937,1000.0,10.0
0.014036826625,0.14039110625,202.48142385296757,1000.0,10.0
0.0141188650625,0.141211490625,202.72204541984206,1000.0,10.0
0.0142009035,0.142031875,202.96266698671715,1000.0,10.0
0.014282941937500002,0.142852259375,203.20328855359216,1000.0,10.0
0.014364980375000001,0.14367264375,203.44391012046754,1000.0,10.0
0.0144470188125,0.144493028125,203.68453168734337,1000.0,10.0
0.014529057250000001,0.14531341250000002,203.92672456703224,1000.0,10.0
0.0146110956875,0.146133796875,204.16867046530308,1000.0,10.0
0.014693134125,0.14695418125,204.40815506599623,1000.0,10.0
0.014775172562500001,0.14777456562500002,204.64364538100077,1000.0,10.0
0.014857211,0.14859495,204.8742897502549,1000.0,10.0
0.014940734562499999,0.149430185625,205.09991784174645,1000.0,10.0
0.015024258124999999,0.15026542125,205.32104065151216,1000.0,10.0
0.015107781687499999,0.15110065687500002,205.5388505036386,1000.0,10.0
0.015191305249999999,0.1519358925,205.75522105026153,1000.0,10.0
0.015274828812499999,0.152771128125,205.97270727156447,1000.0,10.0
0.015358352374999999,0.15360636375,206.19084501281486,1000.0,10.0
0.015441875937499999,0.15444159937500002,206.40898275406545,1000.0,10.0
0.015525399499999998,0.155276835,206.62712049531498,1000.0,10.0
0.015608923062499998,0.156112070625,206.84525823656432,1000.0,10.0
0.015692446625,0.15694730625,207.0633959778135,1000.0,10.0
0.0157759701875,0.15778254187500002,207.28153371906225,1000.0,10.0
0.01585949375,0.1586177775,207.50099943828482,1000.0,10.0
0.0159430173125,0.159453013125,207.72025642384187,1000.0,10.0
0.016026540875,0.16028824875,207.93743327045976,1000.0,10.0
0.0161100644375,0.16112348437500001,208.15123438987186,1000.0,10.0
0.016193588,0.16195872,208.36094001081872,1000.0,10.0
0.01627680475,0.1627908875,208.56640617904648,1000.0,10.0
0.016360021499999995,0.16362305500000002,208.76806475731146,1000.0,10.0
0.016443238249999995,0.1644552225,208.96692342537804,1000.0,10.0
0.016526454999999995,0.16528739,209.16456568001476,1000.0,10.0
0.016609671749999996,0.16611955750000001,209.36315083500088,1000.0,10.0
0.016692888499999996,0.166951725,209.56228661500015,1000.0,10.0
0.016776105249999996,0.1677838925,209.76142239499987,1000.0,10.0
0.016859321999999996,0.16861606,209.96055817500084,1000.0,10.0
0.016942538749999996,0.1694482275,210.15969395500107,1000.0,10.0
0.017025755499999996,0.170280395,210.35882973500156,1000.0,10.0
0.017108972249999996,0.1711125625,210.55796551500114,1000.0,10.0
0.017192188999999997,0.17194473,210.7592917754016,1000.0,10.0
0.017275405749999997,0.1727768975,210.96027373265002,1000.0,10.0
0.017358622499999997,0.173609065,211.1578245308965,1000.0,10.0
0.017441839249999997,0.1744412325,211.3498071160961,1000.0,10.0
0.017525055999999997,0.1752734,211.53503423599795,1000.0,10.0
0.01760976025,0.17612044249999997,211.71326844015235,1000.0,10.0
0.0176944645,0.17696748499999998,211.8852220799092,1000.0,10.0
0.017779168749999998,0.17781452749999999,212.05255730841782,1000.0,10.0
0.017863873,0.17866157,212.21788608062644,1000.0,10.0
0.01794857725,0.1795086125,212.3847701532813,1000.0,10.0
0.018033281499999998,0.180355655,212.55256247390747,1000.0,10.0
0.01811798575,0.1812026975,212.72035479453208,1000.0,10.0
0.01820269,0.18204974000000002,212.88814711515678,1000.0,10.0
0.01828739425,0.18289678250000002,213.05593943578134,1000.0,10.0
0.0183720985,0.18374382500000003,213.223731756406,1000.0,10.0
0.01845680275,0.18459086750000003,213.39152407703156,1000.0,10.0
0.018541507,0.18543791,213.56084652154485,1000.0,10.0
0.01862621125,0.1862849525,213.72992845878045,1000.0,10.0
0.0187109155,0.187131995,213.8966136165931,1000.0,10.0
0.01879561975,0.1879790375,214.05940919119024,1000.0,10.0
0.018880324,0.18882608,214.2174858471315,1000.0,10.0
0.018965165562499997,0.189674495625,214.37067771732757,1000.0,10.0
0.019050007124999997,0.19052291125,214.51948240304492,1000.0,10.0
0.019134848687499997,0.19137132687500003,214.6650609738991,1000.0,10.0
0.019219690249999997,0.1922197425,214.8092379678598,1000.0,10.0
0.019304531812499998,0.193068158125,214.95450139124742,1000.0,10.0
0.019389373374999998,0.19391657375000002,215.10039925624838,1000.0,10.0
0.019474214937499998,0.19476498937500003,215.24629712125048,1000.0,10.0
0.019559056499999998,0.19561340500000002,215.39219498625206,1000.0,10.0
0.019643898062499998,0.196461820625,215.53809285125274,1000.0,10.0
0.019728739625,0.19731023625000002,215.6839907162529,1000.0,10.0
0.0198135811875,0.19815865187500004,215.8298885812514,1000.0,10.0
0.01989842275,0.19900706750000002,215.97784816111138,1000.0,10.0
0.0199832643125,0.199855483125,216.12548367738896,1000.0,10.0
0.020068105875,0.20070389875,216.2698897324479,1000.0,10.0
0.0201529474375,0.20155231437499999,216.4090548971544,1000.0,10.0
0.020237789,0.20240073,216.54186171087866,1000.0,10.0
0.02032046975,0.2032275375,216.66808668149343,1000.0,10.0
0.020403150499999998,0.20405434500000003,216.78840028537667,1000.0,10.0
0.020485831249999996,0.20488115250000002,216.90436696741062,1000.0,10.0
0.020568511999999997,0.20570796000000002,217.01844514097883,1000.0,10.0
0.02065119275,0.20653476750000002,217.13398718797166,1000.0,10.0
0.0207338735,0.20736157500000002,217.25038409234688,1000.0,10.0
0.02081655425,0.20818838250000002,217.36678099672164,1000.0,10.0
0.020899235,0.20901519000000002,217.48317790109593,1000.0,10.0
0.020981915749999996,0.20984199750000002,217.59957480546956,1000.0,10.0
0.021064596499999998,0.21066880500000001,217.71597170984356,1000.0,10.0
0.02114727725,0.2114956125,217.83236861421904,1000.0,10.0
0.021229958,0.21232242,217.9498223024901,1000.0,10.0
0.02131263875,0.2131492275,218.06710988380675,1000.0,10.0
0.0213953195,0.213976035,218.18274212341123,1000.0,10.0
0.021478000249999997,0.2148028425,218.29568801262513,1000.0,10.0
0.021560680999999998,0.21562965,218.40537476884842,1000.0,10.0
0.0216426158125,0.21644899812500001,218.51168783555997,1000.0,10.0
0.021724550625,0.21726834625000002,218.61497088232036,1000.0,10.0
0.0218064854375,0.21808769437500003,218.7160258047694,1000.0,10.0
0.02188842025,0.2189070425,218.81611272462615,1000.0,10.0
0.0219703550625,0.219726390625,218.91694998968788,1000.0,10.0
0.022052289875,0.22054573875,219.01822543343746,1000.0,10.0
0.0221342246875,0.221365086875,219.11950087718773,1000.0,10.0
0.0222161595,0.222184435,219.22077632093746,1000.0,10.0
0.0222980943125,0.22300378312500002,219.32205176468787,1000.0,10.0
0.022380029125,0.22382313125,219.42332720843825,1000.0,10.0
0.0224619639375,0.22464247937499998,219.52460265218815,1000.0,10.0
0.02254389875,0.2254618275,219.62773413252364,1000.0,10.0
0.0226258335625,0.226281175625,219.73057387811093,1000.0,10.0
0.022707768375,0.22710052375,219.83050633603918,1000.0,10.0
0.022789703187499996,0.227919871875,219.92572073890685,1000.0,10.0
0.022871637999999996,0.22873922,220.01521110482554,1000.0,10.0
0.022951885874999994,0.22954169874999997,220.09877623741625,1000.0,10.0
0.023032133749999996,0.23034417749999997,220.1770197258128,1000.0,10.0
0.023112381624999997,0.23114665624999997,220.25134994466057,1000.0,10.0
0.0231926295,0.23194913499999997,220.3239800541148,1000.0,10.0
0.023272877375,0.23275161374999997,220.39792799984366,1000.0,10.0
0.02335312525,0.23355409249999998,220.47264552171808,1000.0,10.0
0.023433373124999997,0.23435657124999998,220.54736304359383,1000.0,10.0
0.023513621,0.23515904999999998,220.62208056546976,1000.0,10.0
0.023593868875,0.23596152874999998,220.69679808734512,1000.0,10.0
0.023674116749999998,0.23676400749999998,220.77151560922042,1000.0,10.0
0.023754364624999996,0.23756648625,220.84623313109518,1000.0,10.0
0.023834612499999998,0.238368965,220.92155435811043,1000.0,10.0
0.023914860375,0.23917144375,220.99678069380295,1000.0,10.0
0.023995108249999998,0.2399739225,221.07106138838125,1000.0,10.0
0.024075356124999996,0.24077640125,221.14380746121947,1000.0,10.0
0.024155603999999997,0.24157888,221.21469170086033,1000.0,10.0
0.024234819874999997,0.24237103875,221.28364866501082,1000.0,10.0
0.024314035749999997,0.24316319749999998,221.35087468054604,1000.0,10.0
0.024393251624999997,0.24395535624999998,221.41682784350948,1000.0,10.0
0.024472467499999997,0.244747515,221.48222801910947,1000.0,10.0
0.024551683374999998,0.24553967375000002,221.54805684171836,1000.0,10.0
0.024630899249999998,0.24633183250000001,221.61413598109326,1000.0,10.0
0.024710115124999998,0.24712399125,221.68021512047005,1000.0,10.0
0.024789330999999998,0.24791615,221.74629425984662,1000.0,10.0
0.024868546874999998,0.24870830875,221.812373399222,1000.0,10.0
0.024947762749999998,0.2495004675,221.87845253859726,1000.0,10.0
0.025026978624999998,0.25029262625,221.94453167797138,1000.0,10.0
0.025106194499999998,0.251084785,222.01150031259345,1000.0,10.0
0.025185410374999998,0.25187694374999997,222.07832913495366,1000.0,10.0
0.025264626249999998,0.25266910249999996,222.1437646558142,1000.0,10.0
0.025343842125,0.25346126125,222.20693907493563,1000.0,10.0
0.025423058,0.25425342,222.26737028107377,1000.0,10.0
0.0255019775,0.25504261500000003,222.3249618519775,1000.0,10.0
0.025580897,0.25583181,222.38000305439311,1000.0,10.0
0.025659816499999998,0.256621005,222.43316884406505,1000.0,10.0
0.025738735999999998,0.25741020000000003,222.4855198657313,1000.0,10.0
0.025817655499999998,0.258199395,222.53850245312734,1000.0,10.0
0.025896574999999998,0.25898859,222.59185385562702,1000.0,10.0
0.025975494499999998,0.25977778500000004,222.64520525812708,1000.0,10.0
0.026054413999999998,0.26056698,222.69855666062736,1000.0,10.0
0.026133333499999998,0.26135617499999997,222.75190806312833,1000.0,10.0
0.026212252999999998,0.26214537,222.80525946562923,1000.0,10.0
0.026291172499999998,0.262934565,222.8586108681301,1000.0,10.0
0.026370091999999998,0.26372376,222.91268041180916,1000.0,10.0
0.026449011499999998,0.264512955,222.9666370769282,1000.0,10.0
0.026527930999999998,0.26530215,223.01946884881798,1000.0,10.0
0.026606850499999998,0.266091345,223.070475101941,1000.0,10.0
0.026685769999999998,0.26688054,223.1192665998852,1000.0,10.0
0.026763969437499997,0.267662534375,223.16576549536796,1000.0,10.0
0.026842168874999996,0.26844452875,223.2102053302374,1000.0,10.0
0.026920368312499998,0.269226523125,223.253131035468,1000.0,10.0
0.026998567749999997,0.2700085175,223.29539893116473,1000.0,10.0
0.027076767187499996,0.27079051187500003,223.33817672656087,1000.0,10.0
0.027154966625,0.27157250625,223.38125228781186,1000.0,10.0
0.027233166062499998,0.272354500625,223.42432784906265,1000.0,10.0
0.027311365499999997,0.27313649500000003,223.46740341031236,1000.0,10.0
0.0273895649375,0.273918489375,223.5104789715623,1000.0,10.0
0.027467764375,0.27470048375,223.55355453281305,1000.0,10.0
0.027545963812499998,0.27548247812500004,223.59663009406452,1000.0,10.0
0.02762416325,0.2762644725,223.64115360109423,1000.0,10.0
0.0277023626875,0.277046466875,223.68544951773038,1000.0,10.0
0.027780562124999998,0.27782846125000005,223.72747737837636,1000.0,10.0
0.0278587615625,0.27861045562500003,223.7658245530033,1000.0,10.0
0.027936961,0.27939245,223.7997062471514,1000.0,10.0
0.0280146701875,0.280169541875,223.828965501928,1000.0,10.0
0.028092379374999997,0.28094663375,223.85407319400917,1000.0,10.0
0.028170088562499997,0.28172372562500003,223.87612803564224,1000.0,10.0
0.028247797749999998,0.2825008175,223.8968565746377,1000.0,10.0
0.028325506937499998,0.28327790937499997,223.91861319437388,1000.0,10.0
0.028403216125,0.28405500125,223.94097018187165,1000.0,10.0
0.0284809253125,0.284832093125,223.9633271693717,1000.0,10.0
0.0285586345,0.285609185,223.9856841568721,1000.0,10.0
0.0286363436875,0.28638627687499996,224.0080411443735,1000.0,10.0
0.028714052875,0.28716336875,224.03039813187436,1000.0,10.0
0.0287917620625,0.287940460625,224.05275511937313,1000.0,10.0
0.02886947125,0.2887175525,224.07504939036878,1000.0,10.0
0.0289471804375,0.289494644375,224.097353519243,1000.0,10.0
0.029024889625,0.29027173625,224.11975588697555,1000.0,10.0
0.029102598812499998,0.291048828125,224.1423176803982,1000.0,10.0
0.029180308,0.29182592,224.16507289219794,1000.0,10.0
0.029255813875,0.29258097875,224.18802832091149,1000.0,10.0
0.02933131975,0.29333603750000004,224.21116357092762,1000.0,10.0
0.029406825625,0.29409109625,224.23443105248865,1000.0,10.0
0.0294823315,0.294846155,224.25775598168556,1000.0,10.0
0.029557837375,0.29560121375000004,224.28103638046548,1000.0,10.0
0.02963334325,0.2963562725,224.3042907748426,1000.0,10.0
0.029708849125,0.29711133125,224.32754516921963,1000.0,10.0
0.029784355,0.29786639000000004,224.35079956359618,1000.0,10.0
0.029859860874999998,0.29862144875,224.37405395797003,1000.0,10.0
0.029935366749999998,0.2993765075,224.39730835234437,1000.0,10.0
0.030010872624999997,0.30013156625000004,224.420562746721,1000.0,10.0
0.030086378499999997,0.300886625,224.44427781781224,1000.0,10.0
0.030161884374999996,0.30164168375,224.46792047901195,1000.0,10.0
0.030237390249999996,0.30239674250000004,224.4908415382046,1000.0,10.0
0.030312896124999995,0.30315180125,224.5125915546947,1000.0,10.0
0.030388402,0.30390686,224.532920839204,1000.0,10.0
0.0304646476875,0.304669316875,224.55177945388016,1000.0,10.0
0.030540893374999996,0.30543177374999997,224.5693172122908,1000.0,10.0
0.030617139062499996,0.30619423062499995,224.58588367942113,1000.0,10.0
0.030693384749999997,0.3069566875,224.60202817167723,1000.0,10.0
0.030769630437499997,0.30771914437500003,224.61849975688202,1000.0,10.0
0.030845876124999998,0.30848160125,224.63516235437996,1000.0,10.0
0.030922121812499998,0.309244058125,224.65182495187778,1000.0,10.0
0.0309983675,0.310006515,224.66848754937655,1000.0,10.0
0.0310746131875,0.31076897187499997,224.68515014687452,1000.0,10.0
0.031150858875,0.31153142875,224.70181274437195,1000.0,10.0
0.0312271045625,0.31229388562500005,224.71847534187418,1000.0,10.0
0.03130335025,0.31305634250000003,224.73579616322107,1000.0,10.0
0.031379595937500004,0.313818799375,224.75301352390824,1000.0,10.0
0.031455841625,0.31458125625,224.76919984561908,1000.0,10.0
0.0315320873125,0.315343713125,224.78371295875095,1000.0,10.0
0.031608333,0.31610617,224.7961961024185,1000.0,10.0
0.0316823545,0.31684638500000006,224.80657792444728,1000.0,10.0
0.031756376,0.31758660000000005,224.8150724813682,1000.0,10.0
0.0318303975,0.31832681500000004,224.82217923842654,1000.0,10.0
0.031904419,0.31906703000000003,224.82868306958179,1000.0,10.0
0.031978440500000004,0.319807245,224.83565425750433,1000.0,10.0
0.032052462000000004,0.32054746,224.8428983675081,1000.0,10.0
0.032126483500000004,0.321287675,224.85014247750766,1000.0,10.0
0.032200505000000004,0.32202789,224.8573865875032,1000.0,10.0
0.032274526500000005,0.32276810499999997,224.86463069750033,1000.0,10.0
0.032348548000000005,0.32350831999999996,224.87187480750032,1000.0,10.0
0.032422569500000005,0.32424853499999995,224.8791189174989,1000.0,10.0
0.032496591000000005,0.32498875,224.88635456307816,1000.0,10.0
0.032570612500000005,0.32572896500000004,224.89359153910831,1000.0,10.0
0.032644634000000006,0.32646918,224.9008417737679,1000.0,10.0
0.0327186555,0.327209395,224.90811352502536,1000.0,10.0
0.032792677,0.32794961,224.91541138063994,1000.0,10.0
0.0328671619375,0.32869445937499997,224.92273625816466,1000.0,10.0
0.032941646874999994,0.32943930875,224.93008540494313,1000.0,10.0
0.033016131812499995,0.330184158125,224.93745239810852,1000.0,10.0
0.033090616749999996,0.3309290075,224.9448271445864,1000.0,10.0
0.0331651016875,0.33167385687499995,224.95219588109708,1000.0,10.0
0.033239586625,0.33241870625,224.95956110797087,1000.0,10.0
0.0333140715625,0.333163555625,224.96692633484426,1000.0,10.0
0.0333885565,0.33390840499999996,224.9742915617196,1000.0,10.0
0.0334630414375,0.33465325437499993,224.981656788594,1000.0,10.0
0.033537526375,0.33539810374999995,224.9890220154676,1000.0,10.0
0.0336120113125,0.336142953125,224.99638724234265,1000.0,10.0
0.03368649625,0.33688780249999994,225.00385230918155,1000.0,10.0
0.033760981187500004,0.33763265187499997,225.01130168301776,1000.0,10.0
0.033835466125000005,0.33837750125,225.0185946679658,1000.0,10.0
0.0339099510625,0.33912235062499996,225.0256338591844,1000.0,10.0
0.033984436,0.3398672,225.03236514286863,1000.0,10.0
0.0340623465625,0.340646305625,225.03877769626018,1000.0,10.0
0.034140257125000004,0.34142541125000003,225.04490398763875,1000.0,10.0
0.0342181676875,0.34220451687500003,225.05081977632412,1000.0,10.0
0.03429607825,0.34298362250000003,225.05664411268435,1000.0,10.0
0.0343739888125,0.343762728125,225.0625393381271,1000.0,10.0
0.034451899375,0.34454183375,225.0684759606259,1000.0,10.0
0.0345298099375,0.345320939375,225.07441258312357,1000.0,10.0
0.0346077205,0.346100045,225.08034920562224,1000.0,10.0
0.0346856310625,0.346879150625,225.08628582812287,1000.0,10.0
0.034763541625000005,0.34765825625,225.09222245062455,1000.0,10.0
0.034841452187500004,0.348437361875,225.0981590731281,1000.0,10.0
0.03491936275,0.3492164675,225.1043956820162,1000.0,10.0
0.0349972733125,0.349995573125,225.11058513857085,1000.0,10.0
0.035075183875,0.35077467875,225.11630469775238,1000.0,10.0
0.035153094437500004,0.351553784375,225.1212616899166,1000.0,10.0
0.035231005,0.35233289,225.1252935208101,1000.0,10.0
0.0353069538125,0.353092378125,225.12836767158805,1000.0,10.0
0.035382902625000004,0.35385186625,225.1305816987999,1000.0,10.0
0.0354588514375,0.354611354375,225.13216323438968,1000.0,10.0
0.03553480025,0.3553708425,225.1334699856995,1000.0,10.0
0.0356107490625,0.356130330625,225.13498973547163,1000.0,10.0
0.035686697875,0.35688981875000003,225.136633869842,1000.0,10.0
0.0357626466875,0.357649306875,225.13827800421578,1000.0,10.0
0.0358385955,0.358408795,225.1399221385936,1000.0,10.0
0.035914544312500005,0.359168283125,225.14156627297052,1000.0,10.0
0.035990493125,0.35992777125,225.14321040734595,1000.0,10.0
0.0360664419375,0.360687259375,225.14485454172345,1000.0,10.0
0.03614239075,0.3614467475,225.146417097923,1000.0,10.0
0.0362183395625,0.362206235625,225.14799247670618,1000.0,10.0
0.036294288375,0.36296572375,225.14969563919078,1000.0,10.0
0.0363702371875,0.363725211875,225.15160617384382,1000.0,10.0
0.036446186,0.3644847,225.15376829648187,1000.0,10.0
0.036523215312499996,0.365254993125,225.15619085026867,1000.0,10.0
0.036600244625,0.36602528624999997,225.15884730571423,1000.0,10.0
0.0366772739375,0.36679557937499996,225.16167576067755,1000.0,10.0
0.036754303249999995,0.3675658725,225.16457894036802,1000.0,10.0
0.0368313325625,0.36833616562500004,225.16742419734194,1000.0,10.0
0.036908361875,0.36910645875000003,225.17023562921804,1000.0,10.0
0.036985391187499994,0.369876751875,225.1730470610946,1000.0,10.0
0.0370624205,0.370647045,225.1758584929689,1000.0,10.0
0.0371394498125,0.371417338125,225.17866992484232,1000.0,10.0
0.037216479125,0.37218763125,225.18148135671686,1000.0,10.0
0.0372935084375,0.37295792437499997,225.1842927885923,1000.0,10.0
0.03737053775,0.3737282175,225.18716473760412,1000.0,10.0
0.037447567062500006,0.37449851062500006,225.1900271744356,1000.0,10.0
0.037524596375000004,0.37526880375000005,225.19279481748853,1000.0,10.0
0.0376016256875,0.37603909687500003,225.19540862565356,1000.0,10.0
0.037678655000000005,0.37680939,225.19783579831892,1000.0,10.0
0.037755656375,0.37757940375,225.2000697753587,1000.0,10.0
0.037832657750000005,0.3783494175,225.20213023714228,1000.0,10.0
0.03790965912500001,0.37911943125,225.20406310453185,1000.0,10.0
0.037986660500000005,0.379889445,225.20594053888132,1000.0,10.0
0.038063661875,0.38065945875,225.20786094203496,1000.0,10.0
0.038140663250000005,0.38142947250000003,225.20980643765833,1000.0,10.0
0.03821766462500001,0.38219948625,225.21175193327994,1000.0,10.0
0.038294666000000005,0.3829695,225.21369742890113,1000.0,10.0
0.038371667375,0.38373951375000004,225.21564292452337,1000.0,10.0
0.038448668750000005,0.3845095275,225.21758842015,1000.0,10.0
0.03852567012500001,0.38527954125,225.2195339157777,1000.0,10.0
0.038602671500000005,0.38604955500000004,225.22099303749857,1000.0,10.0
0.038679672875,0.38681956875,225.22293853312686,1000.0,10.0
0.038756674250000005,0.38758958250000003,225.224884028753,1000.0,10.0
0.03883367562500001,0.38835959625000005,225.22682952437557,1000.0,10.0
0.038910677000000005,0.38912961,225.22877501999324,1000.0,10.0