File: datasets/steel_spring/csv/BS2V-1000-0.01.csv
Time(s),Strain(%),Stress(MPa),Temp(C),SR(%/s)
0.016125,0.00021254,0.19068021708300056,1000.0,0.01
0.017201,0.0002233,1.1920764765935392,1000.0,0.01
0.020962999999999996,0.00026092,2.1634123885171244,1000.0,0.01
0.029022,0.00034151,3.128262735731504,1000.0,0.01
0.036548,0.00041677,4.110202301114428,1000.0,0.01
0.040845,0.00045974,5.386356943308734,1000.0,0.01
0.05805299999999999,0.00063182,6.510827794941316,1000.0,0.01
0.06558200000000002,0.00070711,7.746001747191322,1000.0,0.01
0.081174,0.00086303,9.080898195236783,1000.0,0.01
0.096234,0.00101363,10.507742989541708,1000.0,0.01
0.10322200000000001,0.00108351,12.011776139589069,1000.0,0.01
0.118286,0.00123415,13.598611562897785,1000.0,0.01
0.130119,0.00135248,15.24404649121408,1000.0,0.01
0.14518699999999998,0.00150316,16.924312073856132,1000.0,0.01
0.152722,0.00157851,18.627130227496288,1000.0,0.01
0.16725,0.00172379,20.3520537419944,1000.0,0.01
0.181789,0.00186918,22.111182848969793,1000.0,0.01
0.19363,0.00198759,23.87193917235428,1000.0,0.01
0.20547200000000002,0.00210601,25.625550464492548,1000.0,0.01
0.21893900000000002,0.00224068,27.392769376697103,1000.0,0.01
0.230249,0.00235378,29.148136846064535,1000.0,0.01
0.245867,0.00250996,30.86581445415166,1000.0,0.01
0.258795,0.00263924,32.545587091009615,1000.0,0.01
0.26903099999999996,0.0027416,34.17006890226716,1000.0,0.01
0.284664,0.00289793,35.71999014020278,1000.0,0.01
0.300825,0.00305954,37.189368129496344,1000.0,0.01
0.314304,0.00319433,38.58053705392248,1000.0,0.01
0.33155,0.00336679,39.9246926880115,1000.0,0.01
0.34719300000000003,0.00352322,41.25160507103044,1000.0,0.01
0.366605,0.00371734,42.52356956586568,1000.0,0.01
0.38116300000000003,0.00386292,43.760821525216066,1000.0,0.01
0.40112699999999996,0.00406256,44.9654299926725,1000.0,0.01
0.41137799999999997,0.00416507,46.08524839790357,1000.0,0.01
0.43458,0.00439709,47.099289063640335,1000.0,0.01
0.453472,0.00458601,48.00359350838846,1000.0,0.01
0.471287,0.00476416,48.80342046116875,1000.0,0.01
0.489642,0.00494771,49.5352214871138,1000.0,0.01
0.507999,0.00513128,50.203255428119476,1000.0,0.01
0.52637,0.00531499,50.80987435174449,1000.0,0.01
0.54257,0.00547699,51.368122894950936,1000.0,0.01
0.5620289999999999,0.00567158,51.90518299350776,1000.0,0.01
0.5787809999999999,0.0058391,52.42380937382024,1000.0,0.01
0.5982379999999999,0.00603367,52.93139047854186,1000.0,0.01
0.611211,0.0061634,53.43212039386763,1000.0,0.01
0.63122,0.00636349,53.93123659812142,1000.0,0.01
0.6485299999999999,0.00653659,54.43394578211195,1000.0,0.01
0.6615099999999999,0.00666639,54.93587991169341,1000.0,0.01
0.6836859999999999,0.00688815,55.43558117596045,1000.0,0.01
0.6988379999999998,0.00703967,55.92726909355515,1000.0,0.01
0.7177809999999999,0.0072291,56.4262003682938,1000.0,0.01
0.734012,0.00739141,56.932721153379,1000.0,0.01
0.75513,0.00760259,57.415875182649756,1000.0,0.01
0.7740829999999999,0.00779212,57.86163842958722,1000.0,0.01
0.7941149999999999,0.00799244,58.27027794778982,1000.0,0.01
0.8103689999999999,0.00815498,58.634626556303154,1000.0,0.01
0.833664,0.00838793,58.97016868866497,1000.0,0.01
0.8504609999999999,0.0085559,59.289276087833585,1000.0,0.01
0.869433,0.00874562,59.57148921825413,1000.0,0.01
0.8921939999999999,0.00897323,59.80962986735084,1000.0,0.01
0.906839,0.00911968,60.03211800640774,1000.0,0.01
0.931242,0.00936371,60.24726963116908,1000.0,0.01
0.944797,0.00949926,60.44496630264627,1000.0,0.01
0.9643349999999998,0.00969464,60.64114692829203,1000.0,0.01
0.9816929999999999,0.00986822,60.83354049019165,1000.0,0.01
1.0034020000000001,0.01008531,61.04078079439046,1000.0,0.01
1.0262030000000002,0.01031332,61.250097240854416,1000.0,0.01
1.043033,0.01048162,61.43834006812147,1000.0,0.01
1.060405,0.01065534,61.602096061740816,1000.0,0.01
1.0805040000000001,0.01085633,61.78124243892453,1000.0,0.01
1.09898,0.01104109,61.95986249185821,1000.0,0.01
1.11691,0.01122039,62.13349070558358,1000.0,0.01
1.135923,0.01141052,62.326325542227565,1000.0,0.01
1.155488,0.01160617,62.51794753527683,1000.0,0.01
1.1761460000000001,0.01181275,62.70453776942837,1000.0,0.01
1.193001,0.0119813,62.87395528513104,1000.0,0.01
1.214766,0.01219895,63.02152850745681,1000.0,0.01
1.2321680000000002,0.01237297,63.15586872411209,1000.0,0.01
1.251752,0.01256881,63.283525712844984,1000.0,0.01
1.26862,0.01273749,63.39186967127291,1000.0,0.01
1.2898509999999999,0.0129498,63.50856112291116,1000.0,0.01
1.310537,0.01315666,63.65094537953053,1000.0,0.01
1.331227,0.01336356,63.79233540598131,1000.0,0.01
1.352462,0.01357591,63.931153951227564,1000.0,0.01
1.370438,0.01375567,64.06334396250787,1000.0,0.01
1.388958,0.01394087,64.17841292301739,1000.0,0.01
1.4156620000000002,0.01420791,64.26978233396812,1000.0,0.01
1.429292,0.01434421,64.34765340678437,1000.0,0.01
1.450007,0.01455136,64.40950650406837,1000.0,0.01
1.465816,0.01470945,64.4720467441404,1000.0,0.01
1.493093,0.01498222,64.53653649575594,1000.0,0.01
1.5061820000000001,0.01511311,64.61559169144145,1000.0,0.01
1.5290890000000001,0.01534218,64.72747284785419,1000.0,0.01
1.54492,0.01550049,64.8765546149582,1000.0,0.01
1.5683870000000002,0.01573516,65.04739572744302,1000.0,0.01
1.580393,0.01585522,65.19677627156995,1000.0,0.01
1.602233,0.01607362,65.31298145974421,1000.0,0.01
1.6273490000000002,0.01632478,65.41979048867238,1000.0,0.01
1.647562,0.01652691,65.50375610783355,1000.0,0.01
1.6710530000000001,0.01676182,65.56962861817081,1000.0,0.01
1.686355,0.01691484,65.64345336678822,1000.0,0.01
1.705486,0.01710615,65.72514765652879,1000.0,0.01
1.7224300000000001,0.01727559,65.81933075293027,1000.0,0.01
1.7426530000000002,0.01747782,65.91661599489626,1000.0,0.01
1.770005,0.01775134,65.99571245986806,1000.0,0.01
1.7880559999999999,0.01793185,66.05579793012186,1000.0,0.01
1.807197,0.01812326,66.12417252511422,1000.0,0.01
1.8296390000000002,0.01834768,66.18005921473161,1000.0,0.01
1.843316,0.01848445,66.23237725444935,1000.0,0.01
1.8668630000000002,0.01871992,66.30182347726732,1000.0,0.01
1.888211,0.0189334,66.36125027324259,1000.0,0.01
1.906827,0.01911956,66.43054630203031,1000.0,0.01
1.931476,0.01936605,66.51388871254733,1000.0,0.01
1.9506539999999999,0.01955783,66.6217176809186,1000.0,0.01
1.969282,0.01974411,66.74018339028214,1000.0,0.01
1.990662,0.01995791,66.86874924621196,1000.0,0.01
2.0032639999999997,0.02008393,66.98458218735776,1000.0,0.01
2.0312309999999996,0.0203636,67.08857439463239,1000.0,0.01
2.047687,0.02052816,67.1781328564355,1000.0,0.01
2.0635909999999997,0.0206872,67.23891849420276,1000.0,0.01
2.0899219999999996,0.02095051,67.28455530222567,1000.0,0.01
2.108031,0.0211316,67.32104308665005,1000.0,0.01
2.1266979999999998,0.02131827,67.36686442397784,1000.0,0.01
2.1475569999999995,0.02152686,67.42326417151567,1000.0,0.01
2.1733659999999997,0.02178495,67.50191390750814,1000.0,0.01
2.1865449999999997,0.02191674,67.58394806761419,1000.0,0.01
2.2068619999999997,0.02211991,67.66845410050236,1000.0,0.01
2.229939,0.02235068,67.75077392368225,1000.0,0.01
2.2475279999999995,0.02252657,67.82058085262918,1000.0,0.01
2.269514,0.02274643,67.86361421455905,1000.0,0.01
2.285999,0.02291128,67.8850856101954,1000.0,0.01
2.311842,0.02316971,67.90037902408551,1000.0,0.01
2.3272429999999997,0.02332372,67.93196862446037,1000.0,0.01
2.34869,0.02353819,67.99560068722357,1000.0,0.01
2.3690499999999997,0.02374179,68.09867333112703,1000.0,0.01
2.3866639999999997,0.02391793,68.22071022243584,1000.0,0.01
2.4097829999999996,0.02414912,68.337819417292,1000.0,0.01
2.426291,0.0243142,68.44264895713104,1000.0,0.01
2.4466669999999997,0.02451796,68.52657463052313,1000.0,0.01
2.46649,0.02471619,68.58264577413689,1000.0,0.01
2.4857709999999997,0.024909,68.61549238824111,1000.0,0.01
2.5056019999999997,0.02510731,68.63970724866532,1000.0,0.01
2.521579,0.02526708,68.68655538898342,1000.0,0.01
2.545833,0.02550962,68.76966051606473,1000.0,0.01
2.5607219999999997,0.02565851,68.85788447523902,1000.0,0.01
2.5827669999999996,0.02587896,68.9482818633679,1000.0,0.01
2.605384,0.02610513,69.03735776541146,1000.0,0.01
2.62909,0.02634219,69.1189540061595,1000.0,0.01
2.649508,0.02654637,69.17104716175987,1000.0,0.01
2.663855,0.02668984,69.20093669193224,1000.0,0.01
2.687038,0.02692167,69.20074140781286,1000.0,0.01
2.7046969999999995,0.02709826,69.20360756167264,1000.0,0.01
2.72513,0.02730259,69.22011529936192,1000.0,0.01
2.7461149999999996,0.02751244,69.26099841059494,1000.0,0.01
2.765449,0.02770578,69.34230548811017,1000.0,0.01
2.783123,0.02788252,69.44403691434135,1000.0,0.01
2.8046779999999996,0.02809807,69.56474653453651,1000.0,0.01
2.826787,0.02831916,69.67896830471064,1000.0,0.01
2.844471,0.028496,69.75837722147756,1000.0,0.01
2.8671469999999997,0.02872276,69.81027813849646,1000.0,0.01
2.8804179999999997,0.02885547,69.85579563493019,1000.0,0.01
2.89922,0.02904349,69.90515439457596,1000.0,0.01
2.925223,0.02930352,69.9511564436611,1000.0,0.01
2.9456999999999995,0.02950829,70.01414668632391,1000.0,0.01
2.964514,0.02969643,70.09800642401896,1000.0,0.01
2.985,0.02990129,70.18617897632578,1000.0,0.01
3.0038219999999995,0.03008951,70.25565075416083,1000.0,0.01
3.0248649999999997,0.03029994,70.29330733140509,1000.0,0.01
3.048132,0.03053261,70.32250762126138,1000.0,0.01
3.0680749999999994,0.03073204,70.34946158282618,1000.0,0.01
3.084142,0.03089271,70.37282250516353,1000.0,0.01
3.1035419999999996,0.03108671,70.39112680883999,1000.0,0.01
3.124056,0.03129185,70.44035675967741,1000.0,0.01
3.146786,0.03151915,70.52077043053731,1000.0,0.01
3.1617549999999994,0.03166884,70.6182980258345,1000.0,0.01
3.1850539999999996,0.03190183,70.71694390242335,1000.0,0.01
3.205024,0.03210153,70.80925747060108,1000.0,0.01
3.225559,0.03230688,70.88216148841896,1000.0,0.01
3.246649,0.03251778,70.92892956687517,1000.0,0.01
3.26553,0.03270659,70.95732627717223,1000.0,0.01
3.289955,0.03295084,70.97277248049791,1000.0,0.01
3.3071699999999997,0.03312299,70.98752709275186,1000.0,0.01
3.3293899999999996,0.03334519,71.00456748767049,1000.0,0.01
3.3416099999999997,0.03346739,71.04762643052645,1000.0,0.01
3.3610599999999997,0.03366189,71.118979384998,1000.0,0.01
3.380514,0.03385643,71.20751376472742,1000.0,0.01
3.4038639999999996,0.03408993,71.3160263258373,1000.0,0.01
3.423316,0.03428445,71.42082762301176,1000.0,0.01
3.445562,0.03450691,71.51696890833956,1000.0,0.01
3.4644799999999996,0.03469609,71.5978065599645,1000.0,0.01
3.485058,0.03490187,71.6458008895403,1000.0,0.01
3.5028689999999996,0.03507998,71.66550174678102,1000.0,0.01
3.523466,0.03528595,71.66778575859344,1000.0,0.01
3.542389,0.03547518,71.67770453382802,1000.0,0.01
3.563546,0.03568675,71.70259623168782,1000.0,0.01
3.5847069999999994,0.03589836,71.74058799066714,1000.0,0.01
3.6075419999999996,0.03612671,71.7855497098603,1000.0,0.01
3.6248119999999995,0.03629941,71.84735902093412,1000.0,0.01
3.642648,0.03647777,71.91385387905326,1000.0,0.01
3.663826,0.03668955,71.97090325816303,1000.0,0.01
3.683339,0.03688468,72.02717769226167,1000.0,0.01
3.695602,0.03700731,72.07572628689805,1000.0,0.01
3.72293,0.03728059,72.12848817119162,1000.0,0.01
3.742454,0.03747583,72.18189704017661,1000.0,0.01
3.763654,0.03768783,72.23681766472788,1000.0,0.01
3.7815049999999997,0.03786634,72.29795021515791,1000.0,0.01
3.802148,0.03807277,72.36476691209891,1000.0,0.01
3.81779,0.03822919,72.43119322718015,1000.0,0.01
3.841232,0.03846361,72.49597140831071,1000.0,0.01
3.861334,0.03866463,72.56897018470278,1000.0,0.01
3.882558,0.03887687,72.63757334800401,1000.0,0.01
3.8998859999999995,0.03905015,72.69945487820497,1000.0,0.01
3.921119,0.03926248,72.7512473040234,1000.0,0.01
3.939563,0.03944692,72.7915490284517,1000.0,0.01
3.9608039999999995,0.03965933,72.83101802555585,1000.0,0.01
3.9792549999999998,0.03984384,72.86313467675807,1000.0,0.01
3.998264999999999,0.04003394,72.88565404649624,1000.0,0.01
4.023434999999999,0.04028564,72.89631741548659,1000.0,0.01
4.043018,0.04048147,72.9082603956286,1000.0,0.01
4.057001,0.0406213,72.91048000194691,1000.0,0.01
4.08163,0.04086759,72.91699805696798,1000.0,0.01
4.093386,0.04098515,72.95138074473367,1000.0,0.01
4.119702,0.04124831,73.0110847875126,1000.0,0.01
4.135382999999999,0.04140512,73.1205605220545,1000.0,0.01
4.1589,0.04164029,73.24501492256182,1000.0,0.01
4.179074999999999,0.04184204,73.36887930324706,1000.0,0.01
4.202045999999999,0.04207175,73.45860016978632,1000.0,0.01
4.218297,0.04223426,73.51615846910576,1000.0,0.01
4.24072,0.04245849,73.53904351954839,1000.0,0.01
4.254741,0.0425987,73.54435523439861,1000.0,0.01
4.284458,0.04289587,73.55034725689306,1000.0,0.01
4.300166,0.04305295,73.57258811804303,1000.0,0.01
4.320917,0.04326046,73.61707594771943,1000.0,0.01
4.345611,0.0435074,73.67508442984467,1000.0,0.01
4.357955,0.04363084,73.74694816448692,1000.0,0.01
4.379853,0.04384982,73.80077445103986,1000.0,0.01
4.398370999999999,0.044035,73.83570914989775,1000.0,0.01
4.418595,0.04423724,73.86783431635064,1000.0,0.01
4.442189,0.04447318,73.90862361989818,1000.0,0.01
4.4601619999999995,0.04465291,73.94883830004797,1000.0,0.01
4.480388,0.04485517,73.98963515014458,1000.0,0.01
4.496125999999999,0.04501255,74.03206351565193,1000.0,0.01
4.521422,0.04526551,74.07678726352455,1000.0,0.01
4.534924,0.04540053,74.12464041799566,1000.0,0.01
4.563598,0.04568727,74.18234065079449,1000.0,0.01
4.586657,0.04591786,74.23489833526214,1000.0,0.01
4.597346,0.04602475,74.29376212598763,1000.0,0.01
4.6159159999999995,0.04621045,74.36812161332311,1000.0,0.01
4.640123999999999,0.04645253,74.45479044138416,1000.0,0.01
4.660387,0.04665516,74.52530707902122,1000.0,0.01
4.672771,0.046779,74.58478146372617,1000.0,0.01
4.700367,0.04705496,74.63893545525846,1000.0,0.01
4.716129,0.04721258,74.68020606971665,1000.0,0.01
4.740921,0.0474605,74.71290173842674,1000.0,0.01
4.761774,0.04766903,74.7035888131273,1000.0,0.01
4.777557,0.04782686,74.69412948695641,1000.0,0.01
4.796717999999999,0.04801847,74.71008423492773,1000.0,0.01
4.816454,0.04821583,74.74602694400376,1000.0,0.01
4.837312,0.04842441,74.78659720223126,1000.0,0.01
4.858185,0.04863314,74.84740454020876,1000.0,0.01
4.874543,0.04879672,74.92887536019762,1000.0,0.01
4.901065,0.04906194,75.00954672372033,1000.0,0.01
4.921950999999999,0.0492708,75.07174642365032,1000.0,0.01
4.934366,0.04939495,75.10367803276955,1000.0,0.01
4.952427999999999,0.04957557,75.14151134161021,1000.0,0.01
4.977277999999999,0.04982407,75.19169530385084,1000.0,0.01
4.995918,0.05001047,75.23175142492684,1000.0,0.01
5.020779999999999,0.05025909,75.27340876218264,1000.0,0.01
5.041119999999999,0.05046249,75.32340014795534,1000.0,0.01
5.056946,0.05062075,75.35904676189104,1000.0,0.01
5.076722999999999,0.05081852,75.3933679980044,1000.0,0.01
5.099911,0.0510504,75.42090121029008,1000.0,0.01
5.118573,0.05123702,75.44326868280498,1000.0,0.01
5.136106999999999,0.05141236,75.47111616966275,1000.0,0.01
5.153643,0.05158772,75.51584713178221,1000.0,0.01
5.176277,0.05181406,75.56400983679967,1000.0,0.01
5.194953,0.05200082,75.61931634715809,1000.0,0.01
5.220988,0.05226117,75.67168222482321,1000.0,0.01
5.2351469999999996,0.05240276,75.71453603566796,1000.0,0.01
5.258934,0.05264063,75.76057161273162,1000.0,0.01
5.277054,0.05282183,75.79605651619882,1000.0,0.01
5.2968839999999995,0.05302013,75.82239877203399,1000.0,0.01
5.3189779999999995,0.05324107,75.84351036863796,1000.0,0.01
5.338254,0.05343383,75.870227137221,1000.0,0.01
5.356960999999999,0.0536209,75.90569054602763,1000.0,0.01
5.372838,0.05377967,75.94363135960327,1000.0,0.01
5.394386,0.05399515,75.9800954951845,1000.0,0.01
5.417637999999999,0.05422767,76.04142638981536,1000.0,0.01
5.43295,0.05438079,76.11754268471877,1000.0,0.01
5.453374999999999,0.05458504,76.19268188831562,1000.0,0.01
5.47324,0.05478369,76.26973762496024,1000.0,0.01
5.497656999999999,0.05502786,76.31851948730699,1000.0,0.01
5.512981999999999,0.05518111,76.33930354803438,1000.0,0.01
5.536262,0.05541391,76.34502033884159,1000.0,0.01
5.551029,0.05556158,76.34078825458225,1000.0,0.01
5.571477,0.05576606,76.34689637241753,1000.0,0.01
5.594781,0.0559991,76.375899710056,1000.0,0.01
5.612960999999999,0.0561809,76.41324284523401,1000.0,0.01
5.6357,0.05640829,76.47196100641999,1000.0,0.01
5.653898,0.05659027,76.54054577948652,1000.0,0.01
5.672654,0.05677783,76.59849343778139,1000.0,0.01
5.690859,0.05695988,76.63831375191542,1000.0,0.01
5.714754999999999,0.05719884,76.6547604843581,1000.0,0.01
5.732968,0.05738097,76.66546438010347,1000.0,0.01
5.752877999999999,0.05758007,76.68210305636256,1000.0,0.01
5.772238,0.05777367,76.69006117070303,1000.0,0.01
5.792732,0.05797861,76.69875709498695,1000.0,0.01
5.808678,0.05813807,76.72603397874717,1000.0,0.01
5.835438,0.05840567,76.76651732584845,1000.0,0.01
5.851965999999999,0.05857095,76.82683865391304,1000.0,0.01
5.87076,0.05875889,76.90568698417412,1000.0,0.01
5.891284,0.05896413,76.99835049403531,1000.0,0.01
5.911802,0.05916931,77.09703270789647,1000.0,0.01
5.931759,0.05936888,77.18347445460256,1000.0,0.01
5.951143,0.05956272,77.24776398493394,1000.0,0.01
5.9751009999999996,0.0598023,77.2786790369592,1000.0,0.01
5.993926999999999,0.05999056,77.28500966195448,1000.0,0.01
6.016176,0.06021305,77.27887305005937,1000.0,0.01
6.031014,0.06036143,77.27634460996104,1000.0,0.01
6.052138,0.06057267,77.29494197573527,1000.0,0.01
6.074977,0.06080106,77.33658342673537,1000.0,0.01
6.098387,0.06103516,77.38423544123783,1000.0,0.01
6.117236999999999,0.06122366,77.44549861863158,1000.0,0.01
6.135523,0.06140652,77.49704845672785,1000.0,0.01
6.156091,0.0616122,77.5251866640042,1000.0,0.01
6.17324,0.06178369,77.54050434217979,1000.0,0.01
6.194951,0.0620008,77.5531034692022,1000.0,0.01
6.215541999999999,0.06220671,77.57415653997843,1000.0,0.01
6.233268,0.06238397,77.60878717891906,1000.0,0.01
6.252143999999999,0.06257273,77.64515780759895,1000.0,0.01
6.272168,0.06277297,77.6901404759992,1000.0,0.01
6.292764999999999,0.06297894,77.7462724923104,1000.0,0.01
6.308212,0.06313341,77.80223273705892,1000.0,0.01
6.3316870000000005,0.06336816,77.85134456719894,1000.0,0.01
6.356305,0.06361434,77.89224700361883,1000.0,0.01
6.3723410000000005,0.0637747,77.91620894406422,1000.0,0.01
6.390085,0.06395214,77.93183941988494,1000.0,0.01
6.415874,0.06421003,77.94371874748747,1000.0,0.01
6.429624999999999,0.06434754,77.9495964030768,1000.0,0.01
6.452548999999999,0.06457678,77.97193448979846,1000.0,0.01
6.475479,0.06480608,78.00569063650704,1000.0,0.01
6.490386,0.06495515,78.05860306588406,1000.0,0.01
6.513894,0.06519023,78.11954689980747,1000.0,0.01
6.528807,0.06533936,78.1815986874185,1000.0,0.01
6.552892999999999,0.06558022,78.22926008086107,1000.0,0.01
6.569539999999999,0.06574669,78.25769418826427,1000.0,0.01
6.592496999999999,0.06597626,78.27901220817535,1000.0,0.01
6.610860999999999,0.0661599,78.28882422789378,1000.0,0.01
6.634976999999999,0.06640106,78.28868756370854,1000.0,0.01
6.653928,0.06659057,78.29299777484464,1000.0,0.01
6.670582,0.06675711,78.31115986300539,1000.0,0.01
6.6912709999999995,0.066964,78.34615374010552,1000.0,0.01
6.713675,0.06718804,78.39473899058072,1000.0,0.01
6.7349429999999995,0.06740072,78.44764342340655,1000.0,0.01
6.751611,0.0675674,78.49821163965109,1000.0,0.01
6.772888,0.06778017,78.54420622031806,1000.0,0.01
6.790713,0.06795842,78.59000389734098,1000.0,0.01
6.810834999999999,0.06815964,78.61628322261612,1000.0,0.01
6.830400999999999,0.0683553,78.6439044659701,1000.0,0.01
6.844207999999999,0.06849337,78.6769160458828,1000.0,0.01
6.864351999999999,0.06869481,78.71664576650788,1000.0,0.01
6.885071,0.068902,78.74771206150992,1000.0,0.01
6.9006099999999995,0.06905739,78.78467992162183,1000.0,0.01
6.927674999999999,0.06932804,78.82665843950713,1000.0,0.01
6.9420779999999995,0.06947207,78.86193963290116,1000.0,0.01
6.972604999999999,0.06977734,78.89748923941174,1000.0,0.01
6.986432,0.06991561,78.91958085079212,1000.0,0.01
7.004295,0.07009424,78.95114505262582,1000.0,0.01
7.029662,0.07034791,78.98153438093838,1000.0,0.01
7.048115,0.07053244,79.01888259388717,1000.0,0.01
7.067718,0.07072847,79.049420902603,1000.0,0.01
7.085023,0.07090152,79.09428950557441,1000.0,0.01
7.103477000000001,0.07108606,79.1465962107053,1000.0,0.01
7.130597,0.07135726,79.20244792402545,1000.0,0.01
7.147912999999999,0.07153042,79.24499757720842,1000.0,0.01
7.165223,0.07170352,79.2962254523366,1000.0,0.01
7.186013999999999,0.07191143,79.35855729851463,1000.0,0.01
7.203913,0.07209042,79.39956582645415,1000.0,0.01
7.2293199999999995,0.07234449,79.41608235408657,1000.0,0.01
7.252428999999999,0.07257558,79.41057675739168,1000.0,0.01
7.271496999999999,0.07276626,79.39268094466627,1000.0,0.01
7.28595,0.07291079,79.36501558930125,1000.0,0.01
7.309071999999999,0.07314201,79.3437112474743,1000.0,0.01
7.325251,0.0733038,79.32372974081541,1000.0,0.01
7.346649,0.07351778,79.32317510974714,1000.0,0.01
7.367468999999999,0.07372598,79.3449471481139,1000.0,0.01
7.386559,0.07391688,79.37264918752989,1000.0,0.01
7.405653999999999,0.07410783,79.40063761868305,1000.0,0.01
7.425336,0.07430465,79.44079293458465,1000.0,0.01
7.443268,0.07448397,79.5097870737423,1000.0,0.01
7.464117999999999,0.07469247,79.59500471418428,1000.0,0.01
7.487280999999999,0.0749241,79.68780508653701,1000.0,0.01
7.503489,0.07508618,79.76304638351768,1000.0,0.01
7.526085999999999,0.07531215,79.80651094335062,1000.0,0.01
7.555641999999999,0.07560771,79.8256466519904,1000.0,0.01
7.569548999999999,0.07574678,79.83463798266465,1000.0,0.01
7.586932,0.07592061,79.83129320884667,1000.0,0.01
7.607225,0.07612354,79.83039427850238,1000.0,0.01
7.626361999999999,0.07631491,79.85310073895187,1000.0,0.01
7.64434,0.07649469,79.89243792178566,1000.0,0.01
7.668120999999999,0.0767325,79.93256624336296,1000.0,0.01
7.690754999999999,0.07695884,79.9659902303128,1000.0,0.01
7.707007,0.07712136,79.98785024319645,1000.0,0.01
7.723837,0.07728966,80.00429704642185,1000.0,0.01
7.7482240000000004,0.07753353,80.02265958694511,1000.0,0.01
7.763322,0.07768451,80.04088490544343,1000.0,0.01
7.787717,0.07792846,80.06991486303836,1000.0,0.01
7.8074650000000005,0.07812594,80.11314461558432,1000.0,0.01
7.826639999999999,0.07831769,80.16362565673624,1000.0,0.01
7.8493,0.07854429,80.22067417746355,1000.0,0.01
7.8661639999999995,0.07871293,80.28675797029054,1000.0,0.01
7.887091,0.0789222,80.35037104360097,1000.0,0.01
7.908611,0.0791374,80.40948406276763,1000.0,0.01
7.928382999999999,0.07933512,80.45002881113855,1000.0,0.01
7.945250000000001,0.07950379,80.46610134616864,1000.0,0.01
7.967947,0.07973076,80.47926056631455,1000.0,0.01
7.986565000000001,0.07991694,80.482685535964,1000.0,0.01
8.005186,0.08010315,80.47425132752232,1000.0,0.01
8.026731,0.0803186,80.4617443549827,1000.0,0.01
8.047692,0.08052821,80.46333164419107,1000.0,0.01
8.068079,0.08073208,80.46907263038828,1000.0,0.01
8.082647999999999,0.08087777,80.48658406766509,1000.0,0.01
8.107699,0.08112828,80.51431900661542,1000.0,0.01
8.126353,0.08131482,80.55908216189367,1000.0,0.01
8.148503,0.08153632,80.61361964450566,1000.0,0.01
8.16424,0.08169369,80.67168019234268,1000.0,0.01
8.188145,0.08193274,80.71299831346757,1000.0,0.01
8.204476999999999,0.08209606,80.74998078345112,1000.0,0.01
8.224308,0.08229437,80.7885280867795,1000.0,0.01
8.245899999999999,0.08251029,80.80863665356743,1000.0,0.01
8.268075,0.08273204,80.82099695411615,1000.0,0.01
8.278585999999999,0.08283715,80.8302611363657,1000.0,0.01
8.301938999999999,0.08307068,80.83918250602478,1000.0,0.01
8.320618,0.08325747,80.83167632917069,1000.0,0.01
8.338721999999999,0.08343851,80.82871352024631,1000.0,0.01
8.365009,0.08370138,80.83509984139968,1000.0,0.01
8.38254,0.08387669,80.85833080356448,1000.0,0.01
8.399485,0.08404614,80.89138650832999,1000.0,0.01
8.421114999999999,0.08426244,80.91631631942883,1000.0,0.01
8.444500999999999,0.0844963,80.96111589765626,1000.0,0.01
8.462626,0.08467755,81.0043723330258,1000.0,0.01
8.484850999999999,0.0848998,81.04813432358088,1000.0,0.01
8.505328,0.08510457,81.07789874103713,1000.0,0.01
8.519369,0.08524498,81.1041036639039,1000.0,0.01
8.545111,0.0855024,81.1394977154089,1000.0,0.01
8.563847,0.08568976,81.1682656462284,1000.0,0.01
8.580241000000001,0.0858537,81.19165803817125,1000.0,0.01
8.599563999999999,0.08604693,81.20262838193153,1000.0,0.01
8.622992,0.08628121,81.2397303798225,1000.0,0.01
8.641151,0.0864628,81.27145780732077,1000.0,0.01
8.656965,0.08662094,81.30645803917467,1000.0,0.01
8.682162,0.08687291,81.34111413042434,1000.0,0.01
8.701505000000001,0.08706634,81.38266608220609,1000.0,0.01
8.725548999999999,0.08730678,81.41169277686633,1000.0,0.01
8.740202,0.08745331,81.44265881966896,1000.0,0.01
8.76015,0.08765279,81.46180986516318,1000.0,0.01
8.782428999999999,0.08787558,81.47509147552032,1000.0,0.01
8.801791999999999,0.08806921,81.49427662165434,1000.0,0.01
8.823509,0.08828638,81.50811088156226,1000.0,0.01
8.84288,0.08848009,81.51608326554917,1000.0,0.01
8.864605999999998,0.08869735,81.52419540219073,1000.0,0.01
8.883391,0.0888852,81.53751845617089,1000.0,0.01
8.904532,0.08909661,81.52385301635165,1000.0,0.01
8.922752999999998,0.08927882,81.5293570185612,1000.0,0.01
8.939789,0.08944918,81.54435036709701,1000.0,0.01
8.959764999999999,0.08964894,81.56960997632076,1000.0,0.01
8.978579,0.08983708,81.61276681012654,1000.0,0.01
9.001501999999999,0.09006631,81.6874300719076,1000.0,0.01
9.019729,0.09024858,81.76459819005413,1000.0,0.01
9.03796,0.09043089,81.82504703737777,1000.0,0.01
9.060312,0.09065441,81.86665322054056,1000.0,0.01
9.082086,0.09087215,81.87843386119798,1000.0,0.01
9.104448,0.09109577,81.88818909311455,1000.0,0.01
9.122694,0.09127823,81.87871074809219,1000.0,0.01
9.145065,0.09150194,81.86324238846379,1000.0,0.01
9.163912999999999,0.09169042,81.8527304116799,1000.0,0.01
9.182170999999999,0.091873,81.85873662624579,1000.0,0.01
9.208680000000001,0.09213809,81.87937821194463,1000.0,0.01
9.22282,0.09227949,81.90212025343465,1000.0,0.01
9.248159,0.09253288,81.92646077079593,1000.0,0.01
9.264666,0.09269795,81.96445762517486,1000.0,0.01
9.281175,0.09286304,82.00637487019954,1000.0,0.01
9.298867999999999,0.09303997,82.03081545317319,1000.0,0.01
9.320682999999999,0.09325812,82.04642814038756,1000.0,0.01
9.339564,0.09344693,82.05690745625637,1000.0,0.01
9.35549,0.09360619,82.05611376280483,1000.0,0.01
9.384409,0.09389538,82.0644803291946,1000.0,0.01
9.398573999999998,0.09403703,82.0907979189861,1000.0,0.01
9.419825,0.09424954,82.1121398780295,1000.0,0.01
9.440494,0.09445623,82.15762890387853,1000.0,0.01
9.462936000000001,0.09468065,82.20907015584494,1000.0,0.01
9.478295999999999,0.09483425,82.27166221667669,1000.0,0.01
9.498977,0.09504106,82.3291906033204,1000.0,0.01
9.522616,0.09527745,82.37782853789585,1000.0,0.01
9.543892999999999,0.09549022,82.401328277028,1000.0,0.01
9.56222,0.09567349,82.40690634451103,1000.0,0.01
9.584103,0.09589232,82.40871389142376,1000.0,0.01
9.600067000000001,0.09605196,82.39334937116631,1000.0,0.01
9.621361,0.0962649,82.37972731901509,1000.0,0.01
9.641473999999999,0.09646603,82.36562415606083,1000.0,0.01
9.658644,0.09663773,82.35832957886608,1000.0,0.01
9.678764,0.09683893,82.36541142694819,1000.0,0.01
9.703632,0.09708761,82.38231434504557,1000.0,0.01
9.724359,0.09729488,82.40265055517644,1000.0,0.01
9.742719000000001,0.09747848,82.43103436432618,1000.0,0.01
9.762267999999999,0.09767397,82.47970081136766,1000.0,0.01
9.780634999999998,0.09785764,82.53402132135425,1000.0,0.01
9.797229999999999,0.09802359,82.59020604288719,1000.0,0.01
9.823304,0.09828433,82.63859660160882,1000.0,0.01
9.835166,0.09840295,82.66178859609508,1000.0,0.01
9.85651,0.09861639,82.67535158685789,1000.0,0.01
9.877858,0.09882987,82.691371382498,1000.0,0.01
9.899211,0.0990434,82.69029762787432,1000.0,0.01
9.922355999999999,0.09927485,82.67855391664953,1000.0,0.01
9.936008999999999,0.09941138,82.66826864310553,1000.0,0.01
9.957962,0.09963091,82.66108186612435,1000.0,0.01
9.976965,0.09982094,82.65788587723307,1000.0,0.01
10.001907,0.10007036,82.6756823944621,1000.0,0.01
10.017938,0.10023067,82.70014555197105,1000.0,0.01
10.038131,0.1004326,82.74296911936757,1000.0,0.01
10.055368999999999,0.10060498,82.80176461110656,1000.0,0.01
10.07795,0.10083079,82.87288223892085,1000.0,0.01
10.097565,0.10102694,82.9268588613274,1000.0,0.01
10.118364999999999,0.10123494,82.9629878308939,1000.0,0.01
10.139178,0.10144307,82.98187270740902,1000.0,0.01
10.156423,0.10161552,82.99526821005382,1000.0,0.01
10.18141,0.10186539,83.00452611963271,1000.0,0.01
10.194496,0.10199625,83.01207279244262,1000.0,0.01
10.223068,0.10228197,83.02576867049993,1000.0,0.01
10.239135,0.10244264,83.03889221783882,1000.0,0.01
10.255806,0.10260935,83.0592051158262,1000.0,0.01
10.283192999999999,0.10288322,83.0674691286948,1000.0,0.01
10.294508,0.10299637,83.05836058173229,1000.0,0.01
10.320132,0.10325261,83.04885310807444,1000.0,0.01
10.342170999999999,0.103473,83.04334979474658,1000.0,0.01
10.355278,0.10360407,83.03467386833739,1000.0,0.01
10.378528999999999,0.10383658,83.02914468475817,1000.0,0.01
10.395223999999999,0.10400353,83.03787482043656,1000.0,0.01
10.419076,0.10424205,83.05932718411533,1000.0,0.01
10.433978999999999,0.10439108,83.08875411532681,1000.0,0.01
10.461426,0.10466555,83.14103065358269,1000.0,0.01
10.482311000000001,0.1048744,83.19026893735817,1000.0,0.01
10.49604,0.10501169,83.23845902966117,1000.0,0.01
10.520508999999999,0.10525638,83.28241691990948,1000.0,0.01
10.530655,0.10535784,83.31685586193474,1000.0,0.01
10.556328,0.10561457,83.33343037291624,1000.0,0.01
10.57663,0.10581759,83.35845155568532,1000.0,0.01
10.602315,0.10607444,83.37438450906296,1000.0,0.01
10.618454,0.10623583,83.38604776861794,1000.0,0.01
10.638176,0.10643305,83.40355264061353,1000.0,0.01
10.658494,0.10663623,83.41258350818536,1000.0,0.01
10.682409,0.10687538,83.413860226485,1000.0,0.01
10.705737,0.10710866,83.41978568368157,1000.0,0.01
10.715902999999999,0.10721032,83.4175810833923,1000.0,0.01
10.742228,0.10747357,83.40033036034147,1000.0,0.01
10.759576,0.10764705,83.3939874077289,1000.0,0.01
10.777522999999999,0.10782652,83.38121064012495,1000.0,0.01
10.799068,0.10804197,83.37758466994336,1000.0,0.01
10.818230999999999,0.1082336,83.38279970336669,1000.0,0.01
10.842184999999999,0.10847314,83.40282572077273,1000.0,0.01
10.856556999999999,0.10861686,83.44238481778227,1000.0,0.01
10.875731,0.1088086,83.49838869320394,1000.0,0.01
10.893102999999998,0.10898232,83.558348701232,1000.0,0.01
10.918869999999998,0.10923999,83.60594100553806,1000.0,0.01
10.934453,0.10939582,83.65236165731928,1000.0,0.01
10.959029999999998,0.10964159,83.69082041536578,1000.0,0.01
10.977022,0.10982151,83.72864447427752,1000.0,0.01
10.996208999999999,0.11001338,83.7621758787645,1000.0,0.01
11.020810999999998,0.1102594,83.79899438332897,1000.0,0.01
11.037612999999999,0.11042742,83.82685185387577,1000.0,0.01
11.058012,0.11063141,83.84464515526538,1000.0,0.01
11.074214,0.11079343,83.8398389594396,1000.0,0.01
11.097027,0.11102156,83.81068764366346,1000.0,0.01
11.121046999999999,0.11126176,83.7778882586252,1000.0,0.01
11.140867,0.11145996,83.74624113520679,1000.0,0.01
11.15589,0.11161019,83.71555916244387,1000.0,0.01
11.177517,0.11182646,83.69301154642208,1000.0,0.01
11.193738999999999,0.11198868,83.6818489306476,1000.0,0.01
11.219594,0.11224723,83.6915112473126,1000.0,0.01
11.23402,0.11239149,83.71658584105326,1000.0,0.01
11.252659999999999,0.11257789,83.73936203034964,1000.0,0.01
11.273103,0.11278232,83.76411739349234,1000.0,0.01
11.294766,0.11299895,83.80704230099582,1000.0,0.01
11.318226999999998,0.11323356,83.8466331360114,1000.0,0.01
11.329063,0.11334192,83.88067108303515,1000.0,0.01
11.353736,0.11358865,83.9073467600544,1000.0,0.01
11.366977,0.11372106,83.93776180469088,1000.0,0.01
11.398895999999999,0.11404025,83.98387089232536,1000.0,0.01
11.416956999999998,0.11422086,84.03322820674202,1000.0,0.01
11.439848,0.11444977,84.07746413275474,1000.0,0.01
11.457329,0.11462458,84.11413168766974,1000.0,0.01
11.473595,0.11478724,84.13580145644374,1000.0,0.01
11.500121,0.1150525,84.12489712379237,1000.0,0.01
11.519407,0.11524536,84.09400890919227,1000.0,0.01
11.536292999999999,0.11541422,84.05389001891089,1000.0,0.01
11.553780999999999,0.1155891,84.01246149985337,1000.0,0.01
11.573089,0.11578218,83.98243178433871,1000.0,0.01
11.60024,0.11605369,83.97206767139055,1000.0,0.01
11.611704999999999,0.11616834,83.98878054303022,1000.0,0.01
11.632833,0.11637962,84.01579531493456,1000.0,0.01
11.655162,0.11660291,84.06568819572864,1000.0,0.01
11.673281,0.1167841,84.12696625522227,1000.0,0.01
11.691403,0.11696532,84.19013907701554,1000.0,0.01
11.709515999999999,0.11714645,84.2492239380669,1000.0,0.01
11.735494,0.11740623,84.29055566034793,1000.0,0.01
11.753627,0.11758756,84.31547099249444,1000.0,0.01
11.775383999999999,0.11780513,84.3282245134119,1000.0,0.01
11.795333999999999,0.11800463,84.32576552309392,1000.0,0.01
11.814689999999999,0.11819819,84.30856082525438,1000.0,0.01
11.82678,0.11831909,84.2950650882405,1000.0,0.01
11.852787999999999,0.11857917,84.2839800749298,1000.0,0.01
11.875179,0.11880308,84.27765346631641,1000.0,0.01
11.893937,0.11899066,84.28004361433344,1000.0,0.01
11.913911,0.1191904,84.28194998693647,1000.0,0.01
11.938129,0.11943258,84.29429941947157,1000.0,0.01
11.9569,0.11962029,84.31197990743732,1000.0,0.01
11.975674,0.11980803,84.33548405503034,1000.0,0.01
11.996265,0.12001394,84.35739293228684,1000.0,0.01
12.014446,0.12019575,84.3812375009485,1000.0,0.01
12.037474,0.12042603,84.40873399095781,1000.0,0.01
12.050805,0.12055934,84.43834481091415,1000.0,0.01
12.072638,0.12077767,84.47521444059394,1000.0,0.01
12.092647999999999,0.12097777,84.50276482523144,1000.0,0.01
12.115694,0.12120823,84.52851452771444,1000.0,0.01
12.136916999999999,0.12142046,84.54274987837032,1000.0,0.01
12.158155,0.12163284,84.54776798427768,1000.0,0.01
12.177580999999998,0.1218271,84.53519514445317,1000.0,0.01
12.197612,0.12202741,84.51648947956708,1000.0,0.01
12.221898,0.12227027,84.49113976180627,1000.0,0.01
12.232821,0.1223795,84.47297355839368,1000.0,0.01
12.255297,0.12260426,84.46278123017062,1000.0,0.01
12.276561000000001,0.1228169,84.4470119911401,1000.0,0.01
12.295998,0.12301127,84.43857537958466,1000.0,0.01
12.314847,0.12319976,84.45211921291782,1000.0,0.01
12.33733,0.12342459,84.4812148802534,1000.0,0.01
12.354957,0.12360086,84.52312275560448,1000.0,0.01
12.372588,0.12377717,84.57752234890826,1000.0,0.01
12.393877,0.12399006,84.63364555146049,1000.0,0.01
12.417606999999999,0.12422736,84.69293811859129,1000.0,0.01
12.435249,0.12440378,84.73131674384723,1000.0,0.01
12.455332,0.12460461,84.7530767170252,1000.0,0.01
12.476639,0.12481768,84.76483589417765,1000.0,0.01
12.496115,0.12501244,84.76987683238991,1000.0,0.01
12.516209000000002,0.12521338,84.76684374874729,1000.0,0.01
12.529001,0.1253413,84.7682632096927,1000.0,0.01
12.557027999999999,0.12562157,84.76596136125545,1000.0,0.01
12.580181999999999,0.12585311,84.75656644572886,1000.0,0.01
12.598456,0.12603585,84.73998148874959,1000.0,0.01
12.612479999999998,0.12617609,84.71539055566856,1000.0,0.01
12.633202999999998,0.12638332,84.69912003157366,1000.0,0.01
12.652105,0.12657234,84.6869137557413,1000.0,0.01
12.674674,0.12679803,84.67915385195153,1000.0,0.01
12.700903,0.12706032,84.672188122207,1000.0,0.01
12.715546999999999,0.12720676,84.66194291557123,1000.0,0.01
12.727139999999999,0.12732269,84.66815742138556,1000.0,0.01
12.754000999999999,0.1275913,84.69539430390608,1000.0,0.01
12.774149,0.12779278,84.74919139532238,1000.0,0.01
12.797350999999999,0.1280248,84.81588458862726,1000.0,0.01
12.813231,0.1281836,84.89453672815056,1000.0,0.01
12.835218999999999,0.12840348,84.96868995417157,1000.0,0.01
12.854159999999998,0.12859289,85.01908155809916,1000.0,0.01
12.87189,0.12877019,85.02991757926965,1000.0,0.01
12.890217999999999,0.12895347,85.01003137121592,1000.0,0.01
12.91773,0.12922859,84.97339585868022,1000.0,0.01
12.934247,0.12939376,84.94721809318838,1000.0,0.01
12.957486,0.12962615,84.9327565243679,1000.0,0.01
12.977058,0.12982187,84.92006178387214,1000.0,0.01
12.995415999999999,0.13000545,84.92753643645568,1000.0,0.01
13.016219,0.13021348,84.9463789630199,1000.0,0.01
13.031526999999999,0.13036656,84.96534299955714,1000.0,0.01
13.057231999999999,0.13062361,84.97519409784957,1000.0,0.01
13.066423,0.13071552,84.98951218096076,1000.0,0.01
13.09521,0.13100339,84.98301017377179,1000.0,0.01
13.112970999999998,0.131181,84.98225842514617,1000.0,0.01
13.139924,0.13145053,84.97564339796736,1000.0,0.01
13.155249999999999,0.13160379,84.95238930980153,1000.0,0.01
13.173642999999998,0.13178772,84.93829839735638,1000.0,0.01
13.192646,0.13197775,84.94655597407122,1000.0,0.01
13.214719,0.13219848,84.96339273316813,1000.0,0.01
13.233122,0.13238251,85.00242620171846,1000.0,0.01
13.251527999999999,0.13256657,85.04813811578835,1000.0,0.01
13.270548,0.13275677,85.08676612990588,1000.0,0.01
13.290179,0.13295308,85.10924473416081,1000.0,0.01
13.311663,0.13316792,85.11933248509152,1000.0,0.01
13.337451000000001,0.1334258,85.12088125228082,1000.0,0.01
13.355256999999998,0.13360386,85.1206460583929,1000.0,0.01
13.373064999999999,0.13378194,85.12894600497987,1000.0,0.01
13.391497999999999,0.13396627,85.13801094050865,1000.0,0.01
13.413613999999999,0.13418743,85.1648651921978,1000.0,0.01
13.434516,0.13439645,85.1906384175903,1000.0,0.01
13.448644,0.13453773,85.20928252951174,1000.0,0.01
13.475078,0.13480207,85.2081422187988,1000.0,0.01
13.491066,0.13496195,85.20327995332688,1000.0,0.01
13.512592999999999,0.13517722,85.18659963612285,1000.0,0.01
13.537811999999999,0.13542941,85.17071890734456,1000.0,0.01
13.549502,0.13554631,85.14866978976872,1000.0,0.01
13.571042,0.13576171,85.12086640417215,1000.0,0.01
13.588888999999998,0.13594018,85.10582280389582,1000.0,0.01
13.613515999999999,0.13618645,85.1066432911122,1000.0,0.01
13.628301999999998,0.13633431,85.12283873593708,1000.0,0.01
13.64985,0.13654979,85.1489148056552,1000.0,0.01
13.673879000000001,0.13679008,85.18606472917578,1000.0,0.01
13.692357,0.13697486,85.22012308100977,1000.0,0.01
13.715786,0.13720915,85.25663732663749,1000.0,0.01
13.736115,0.13741244,85.2712311787334,1000.0,0.01
13.754614999999998,0.13759744,85.27333682379927,1000.0,0.01
13.776812,0.13781941,85.2644477571368,1000.0,0.01
13.798402,0.13803531,85.24548274795612,1000.0,0.01
13.815676999999999,0.13820806,85.22213669559554,1000.0,0.01
13.836651999999999,0.13841781,85.19032646836044,1000.0,0.01
13.854556999999998,0.13859686,85.16821315462144,1000.0,0.01
13.878623999999999,0.13883753,85.15265214174748,1000.0,0.01
13.895914,0.13901043,85.14537049145467,1000.0,0.01
13.916905,0.13922034,85.1556817297844,1000.0,0.01
13.934201,0.1393933,85.17730868230886,1000.0,0.01
13.952736999999999,0.13957866,85.21632982712066,1000.0,0.01
13.976215,0.13981344,85.26177031820126,1000.0,0.01
13.994747,0.13999876,85.30749882246927,1000.0,0.01
14.014532999999998,0.14019662,85.34064423048207,1000.0,0.01
14.03555,0.14040679,85.36366820543124,1000.0,0.01
14.049774,0.14054903,85.37011149374831,1000.0,0.01
14.076366999999998,0.14081496,85.3677325046061,1000.0,0.01
14.091213,0.14096342,85.370511950163,1000.0,0.01
14.119056,0.14124185,85.3620157330366,1000.0,0.01
14.137011999999999,0.14142141,85.3608078827235,1000.0,0.01
14.159908999999999,0.14165038,85.36326983883346,1000.0,0.01
14.177246,0.14182375,85.36323817447418,1000.0,0.01
14.195827,0.14200956,85.35961073378401,1000.0,0.01
14.217507999999999,0.14222637,85.34585836651372,1000.0,0.01
14.231759,0.14236888,85.32361143514656,1000.0,0.01
14.254677,0.14259806,85.30737602181209,1000.0,0.01
14.275743,0.14280872,85.2973727302865,1000.0,0.01
14.293101,0.1429823,85.2918930826876,1000.0,0.01
14.314803,0.14319932,85.30174637550908,1000.0,0.01
14.334023999999998,0.14339153,85.33162376597573,1000.0,0.01
14.356977999999998,0.14362107,85.37142049692392,1000.0,0.01
14.371863999999999,0.14376993,85.4058043189276,1000.0,0.01
14.391097,0.14396226,85.43673674762822,1000.0,0.01
14.414678,0.14419807,85.45480209780692,1000.0,0.01
14.43578,0.14440909,85.46743032956276,1000.0,0.01
14.45255,0.14457679,85.47892455690472,1000.0,0.01
14.474901999999998,0.14480031,85.49081968462568,1000.0,0.01
14.495397999999998,0.14500527,85.4903194754755,1000.0,0.01
14.514655,0.14519784,85.48427510483022,1000.0,0.01
14.533916,0.14539045,85.46814245472338,1000.0,0.01
14.551935,0.14557064,85.44395138306963,1000.0,0.01
14.569969,0.14575098,85.42345544083526,1000.0,0.01
14.591719000000001,0.14596848,85.40882769585062,1000.0,0.01
14.612867999999999,0.14617997,85.39942569111639,1000.0,0.01
14.638983,0.14644112,85.4153778877144,1000.0,0.01
14.652047999999999,0.14657177,85.43819427169365,1000.0,0.01
14.671964999999998,0.14677094,85.43855139774244,1000.0,0.01
14.692502,0.14697631,85.44521443939503,1000.0,0.01
14.707439,0.14712568,85.45493070808605,1000.0,0.01
14.729847999999999,0.14734977,85.4548846890935,1000.0,0.01
14.754139,0.14759268,85.45341003371867,1000.0,0.01
14.770332,0.14775461,85.45352084679898,1000.0,0.01
14.79587,0.14800999,85.45586177128587,1000.0,0.01
14.817052,0.14822181,85.47441639631151,1000.0,0.01
14.832636999999998,0.14837766,85.48763822652438,1000.0,0.01
14.855072999999999,0.14860202,85.49191293175166,1000.0,0.01
14.876898,0.14882027,85.51704487117892,1000.0,0.01
14.893112,0.14898241,85.54331361372223,1000.0,0.01
14.916192,0.14921321,85.5615532758748,1000.0,0.01
14.934280000000001,0.14939409,85.57606194660549,1000.0,0.01
14.955491999999998,0.14960621,85.59342848279998,1000.0,0.01
14.975466999999998,0.14980596,85.60681528396574,1000.0,0.01
14.994817999999999,0.14999947,85.60591493981974,1000.0,0.01
15.017922,0.15023051,85.59220360724758,1000.0,0.01
15.036648,0.15041777,85.56873352293707,1000.0,0.01
15.047264,0.15052393,85.53809044166279,1000.0,0.01
15.078498,0.15083627,85.50720552385073,1000.0,0.01
15.094743999999999,0.15099873,85.48485984646767,1000.0,0.01
15.114748,0.15119877,85.47085943248075,1000.0,0.01
15.133505,0.15138634,85.46796425592328,1000.0,0.01
15.150999999999998,0.15156129,85.46926285708354,1000.0,0.01
15.176646,0.15181775,85.46068530192268,1000.0,0.01
15.192276,0.15197405,85.46723087425406,1000.0,0.01
15.217301,0.1522243,85.46229431232273,1000.0,0.01
15.23733,0.15242459,85.4666112280928,1000.0,0.01
15.255476999999999,0.15260606,85.47812380744197,1000.0,0.01
15.276134,0.15281263,85.50956587106985,1000.0,0.01
15.296163,0.15301292,85.55016612803645,1000.0,0.01
15.312444000000001,0.15317573,85.58581876271326,1000.0,0.01
15.338132,0.15343261,85.63333606231897,1000.0,0.01
15.356296,0.15361425,85.6759730204453,1000.0,0.01
15.37572,0.15380849,85.70842999803068,1000.0,0.01
15.396403000000001,0.15401532,85.72540735601353,1000.0,0.01