File: datasets/steel_spring/csv/BS2V-1150-0.01.csv
Time(s),Strain(%),Stress(MPa),Temp(C),SR(%/s)
0.0,1.043e-05,0.27273076231338633,1150.0,0.01
0.0005319999999999999,1.575e-05,0.33177976099848583,1150.0,0.01
0.001604,2.647e-05,0.26861148679412034,1150.0,0.01
0.002677,3.72e-05,0.1734222399340173,1150.0,0.01
0.00374,4.783e-05,0.13640832065190434,1150.0,0.01
0.004281,5.324e-05,0.36337293150378924,1150.0,0.01
0.005353,6.396e-05,0.897625960984852,1150.0,0.01
0.012581,0.00013624,1.7391082105625069,1150.0,0.01
0.017403000000000002,0.00018446,2.8613830284924355,1150.0,0.01
0.0227565,0.00023799500000000001,4.198869458782213,1150.0,0.01
0.029715,0.00030758,5.6367469141875235,1150.0,0.01
0.045788999999999996,0.00046832000000000004,7.015370682198891,1150.0,0.01
0.060525499999999996,0.0006156849999999999,8.204431027054955,1150.0,0.01
0.07338499999999999,0.0007442799999999999,9.429410737585263,1150.0,0.01
0.088924,0.00089967,10.583623535414814,1150.0,0.01
0.1009835,0.001020265,11.65745606227656,1150.0,0.01
0.114118,0.00115161,12.665851250170503,1150.0,0.01
0.1288605,0.001299035,13.599663278852324,1150.0,0.01
0.14467950000000002,0.001457225,14.423336766880734,1150.0,0.01
0.164256,0.00165299,15.141661814681868,1150.0,0.01
0.1822235,0.001832665,15.762042502685656,1150.0,0.01
0.19590600000000002,0.00196949,16.30146414392429,1150.0,0.01
0.2120065,0.0021304949999999996,16.76755245819702,1150.0,0.01
0.22890850000000001,0.002299515,17.15508945153415,1150.0,0.01
0.243668,0.0024471099999999997,17.48774183919703,1150.0,0.01
0.2613845,0.002624275,17.776638902774685,1150.0,0.01
0.280174,0.00281217,18.058385973871275,1150.0,0.01
0.29843449999999994,0.002994775,18.314240607515213,1150.0,0.01
0.317774,0.0031881699999999997,18.56334259890726,1150.0,0.01
0.33362249999999993,0.0033466549999999996,18.81830595693567,1150.0,0.01
0.34893549999999995,0.003499785,19.077777986418617,1150.0,0.01
0.3655935,0.003666365,19.342999738812566,1150.0,0.01
0.3806445,0.003816875,19.60203150673682,1150.0,0.01
0.4005345,0.004015775,19.854991581341007,1150.0,0.01
0.42203749999999995,0.004230805000000001,20.103107833437587,1150.0,0.01
0.439785,0.0044082800000000005,20.35875511609288,1150.0,0.01
0.4578075,0.004588505,20.608991551036066,1150.0,0.01
0.475023,0.00476066,20.85884012938076,1150.0,0.01
0.49089649999999996,0.004919395,21.095185507147793,1150.0,0.01
0.512692,0.005137350000000001,21.316397743416726,1150.0,0.01
0.53503,0.00536073,21.53089688832771,1150.0,0.01
0.551185,0.00552228,21.73681229843188,1150.0,0.01
0.568144,0.00569187,21.941433614244406,1150.0,0.01
0.5856455,0.0058668850000000005,22.14024520873491,1150.0,0.01
0.6045015,0.006055445,22.344096092988696,1150.0,0.01
0.620935,0.006219779999999999,22.556133206411047,1150.0,0.01
0.6408725,0.006419154999999999,22.76825518597921,1150.0,0.01
0.6610849999999999,0.00662128,22.95957056721407,1150.0,0.01
0.6769879999999999,0.0067803099999999995,23.160904499183772,1150.0,0.01
0.696936,0.00697979,23.357742146397797,1150.0,0.01
0.71554,0.00716583,23.548233063822046,1150.0,0.01
0.7317195,0.007327625000000001,23.74000748450201,1150.0,0.01
0.748982,0.00750025,23.918406631454662,1150.0,0.01
0.76652,0.00767563,24.08922976663462,1150.0,0.01
0.7840615,0.007851045000000001,24.27123617439028,1150.0,0.01
0.8053805,0.008064235,24.443983768920567,1150.0,0.01
0.8237365000000001,0.008247795,24.59986169653041,1150.0,0.01
0.8426375,0.008436805,24.770965888969787,1150.0,0.01
0.860995,0.00862038,24.935229031257666,1150.0,0.01
0.8782805,0.008793235,25.077067458481142,1150.0,0.01
0.8996234999999999,0.009006665,25.208388682950858,1150.0,0.01
0.9182655,0.009193085,25.335502429079686,1150.0,0.01
0.9374525,0.009384955,25.46959847900393,1150.0,0.01
0.9561014999999999,0.009571445000000001,25.608815639047503,1150.0,0.01
0.9744809999999999,0.00975524,25.761025977928206,1150.0,0.01
0.9950300000000001,0.009960730000000001,25.905294211085394,1150.0,0.01
1.0128795,0.010139225,26.051003896087256,1150.0,0.01
1.0285704999999998,0.010296135,26.194600847770932,1150.0,0.01
1.0488625,0.010499055,26.32018593995085,1150.0,0.01
1.0688845000000002,0.010699275000000001,26.438250162534192,1150.0,0.01
1.0891795000000002,0.010902225,26.555286196068312,1150.0,0.01
1.108667,0.011097099999999999,26.681026424155437,1150.0,0.01
1.1254575,0.011265005,26.803480501075935,1150.0,0.01
1.146312,0.011473549999999999,26.926627271691476,1150.0,0.01
1.163646,0.01164689,27.042243454242577,1150.0,0.01
1.1807145000000001,0.011817575,27.154166978710336,1150.0,0.01
1.2015795,0.012026225,27.262170808513332,1150.0,0.01
1.2178375,0.012188805,27.376806420503865,1150.0,0.01
1.2365345,0.012375775,27.482034198003895,1150.0,0.01
1.2595785000000002,0.012606215,27.580057496636492,1150.0,0.01
1.2799165000000001,0.012809595,27.665752719958483,1150.0,0.01
1.2975430000000001,0.01298586,27.74852904180514,1150.0,0.01
1.3173465000000002,0.013183895000000001,27.826030027553276,1150.0,0.01
1.33824,0.01339283,27.903518349939574,1150.0,0.01
1.3566945000000001,0.013577375,27.995107753810753,1150.0,0.01
1.373796,0.01374839,28.09607226204936,1150.0,0.01
1.395241,0.01396284,28.207782040700856,1150.0,0.01
1.413431,0.01414474,28.317066166827736,1150.0,0.01
1.428641,0.01429684,28.424606719901576,1150.0,0.01
1.449009,0.01450052,28.510270466454628,1150.0,0.01
1.4699255,0.014709685,28.591526872530412,1150.0,0.01
1.489493,0.01490536,28.663424313714113,1150.0,0.01
1.5101490000000002,0.015111920000000001,28.72382429489775,1150.0,0.01
1.531892,0.01532935,28.789876111535975,1150.0,0.01
1.5482085,0.015492515,28.87395695756252,1150.0,0.01
1.5647985000000002,0.015658415000000002,28.949606862784115,1150.0,0.01
1.58275,0.01583793,29.03150083814212,1150.0,0.01
1.6034295,0.016044725,29.125428011837265,1150.0,0.01
1.626553,0.01627596,29.213299185441453,1150.0,0.01
1.6461465,0.016471895,29.305794809723587,1150.0,0.01
1.6638425000000001,0.016648855,29.39257187190727,1150.0,0.01
1.6850795,0.016861225,29.461241833295457,1150.0,0.01
1.7063200000000003,0.01707363,29.524060500869368,1150.0,0.01
1.7237515,0.017247945,29.591893068488748,1150.0,0.01
1.74391,0.017449529999999998,29.642983036460365,1150.0,0.01
1.7646175,0.017656605,29.69215463225777,1150.0,0.01
1.782605,0.017836480000000002,29.754772025513518,1150.0,0.01
1.8019585,0.018030015,29.820339718930192,1150.0,0.01
1.8256795000000001,0.018267224999999998,29.89410145771612,1150.0,0.01
1.846133,0.01847176,29.964552432742586,1150.0,0.01
1.86195,0.01862993,30.026847165113754,1150.0,0.01
1.8835005,0.018845435,30.090259620937672,1150.0,0.01
1.9042365,0.019052794999999997,30.142564186793745,1150.0,0.01
1.9238895,0.019249324999999998,30.196617394922423,1150.0,0.01
1.945733,0.01946776,30.25862307579744,1150.0,0.01
1.96293,0.01963973,30.33008621934475,1150.0,0.01
1.9828605000000001,0.019839034999999998,30.406448906606105,1150.0,0.01
2.0022525,0.020032954999999998,30.48258509412879,1150.0,0.01
2.021649,0.020226920000000002,30.544677567661008,1150.0,0.01
2.042961,0.02044004,30.605148599443275,1150.0,0.01
2.0629124999999995,0.020639554999999997,30.659722606958514,1150.0,0.01
2.0831389999999996,0.020841819999999997,30.698365827966278,1150.0,0.01
2.1047364999999996,0.021057794999999997,30.742296084884796,1150.0,0.01
2.1252475,0.021262905,30.79359799139241,1150.0,0.01
2.1430285,0.021440715,30.840058034356357,1150.0,0.01
2.161084,0.021621269999999998,30.894012363659343,1150.0,0.01
2.1788669999999994,0.021799100000000002,30.948869824642216,1150.0,0.01
2.2007614999999996,0.022018045,31.00070234891112,1150.0,0.01
2.225402,0.022264449999999998,31.058228233388363,1150.0,0.01
2.2481269999999998,0.0224917,31.121223357515344,1150.0,0.01
2.2640069999999994,0.022650499999999997,31.184430979449136,1150.0,0.01
2.2837259999999997,0.022847689999999997,31.246001121021077,1150.0,0.01
2.305366,0.02306409,31.308947248769126,1150.0,0.01
2.3231795,0.023242225,31.358396909473605,1150.0,0.01
2.3426425,0.023436855,31.421559610261426,1150.0,0.01
2.361556,0.02362599,31.47824915216666,1150.0,0.01
2.3804675,0.023815105000000003,31.528284227407138,1150.0,0.01
2.4007585,0.024018015,31.579810037500103,1150.0,0.01
2.4224289999999997,0.02423472,31.621177338019155,1150.0,0.01
2.4438274999999994,0.024448705,31.673165805409344,1150.0,0.01
2.4652304999999997,0.024662734999999998,31.724769932182106,1150.0,0.01
2.483894,0.024849370000000003,31.77924254697559,1150.0,0.01
2.5031109999999996,0.02504154,31.831279180111924,1150.0,0.01
2.520409,0.02521452,31.895391157532373,1150.0,0.01
2.5388059999999997,0.02539849,31.956642986289935,1150.0,0.01
2.5624249999999997,0.02563468,32.013795274738754,1150.0,0.01
2.583303,0.02584346,32.061394265390334,1150.0,0.01
2.602812,0.02603855,32.08814112966495,1150.0,0.01
2.6212235,0.026222665,32.106723417195234,1150.0,0.01
2.6401895,0.026412325,32.1368443271706,1150.0,0.01
2.66026,0.026613030000000003,32.175094823325914,1150.0,0.01
2.6781315,0.026791745,32.22013070451157,1150.0,0.01
2.697386,0.02698429,32.274568873354426,1150.0,0.01
2.7191215,0.027201645,32.34972145787906,1150.0,0.01
2.742232,0.02743275,32.42523395229,1150.0,0.01
2.7639715000000002,0.027650145,32.48864444394522,1150.0,0.01
2.7821395,0.027831825,32.538117647075964,1150.0,0.01
2.7981105,0.027991534999999998,32.57291466611,1150.0,0.01
2.817662,0.028187049999999998,32.614116334693485,1150.0,0.01
2.8413465,0.028423895,32.65676546220681,1150.0,0.01
2.8598015,0.028608445000000003,32.70418457559694,1150.0,0.01
2.879365,0.028804080000000003,32.75430685479578,1150.0,0.01
2.897832,0.02898875,32.81504439914798,1150.0,0.01
2.9151995,0.029162425,32.87357497309865,1150.0,0.01
2.9380815,0.029391245,32.9241363583296,1150.0,0.01
2.9590379999999996,0.029600809999999998,32.95874242425951,1150.0,0.01
2.9797205,0.029807635,32.98273337368752,1150.0,0.01
3.0001335,0.030011765000000003,32.992360546479176,1150.0,0.01
3.0183444999999995,0.030193875000000002,33.0062742738106,1150.0,0.01
3.0379385,0.030389815,33.02642879916477,1150.0,0.01
3.060022,0.030610650000000003,33.0550131542842,1150.0,0.01
3.078518,0.03079561,33.10529974286954,1150.0,0.01
3.097571,0.030986140000000002,33.178492933047465,1150.0,0.01
3.1196669999999997,0.0312071,33.25012341959673,1150.0,0.01
3.138727,0.0313977,33.32201922439788,1150.0,0.01
3.1572379999999995,0.03158281,33.38324011136936,1150.0,0.01
3.1768595,0.031779025,33.42810558846752,1150.0,0.01
3.1964894999999998,0.031975325,33.47257867028208,1150.0,0.01
3.2177795,0.032188225,33.50475309490721,1150.0,0.01
3.2385155,0.032395585000000005,33.54482346320297,1150.0,0.01
3.2584275,0.032594705,33.58542996840391,1150.0,0.01
3.2744739999999997,0.03275517,33.63242215849871,1150.0,0.01
3.2946735,0.032957165,33.67538264232639,1150.0,0.01
3.3184705,0.033195135,33.72795148672401,1150.0,0.01
3.335356,0.033363989999999996,33.76960265810817,1150.0,0.01
3.3566715,0.033577145,33.81563393227833,1150.0,0.01
3.378545,0.03379588,33.85735045242414,1150.0,0.01
3.3976604999999998,0.033987035,33.89056295257537,1150.0,0.01
3.417054,0.034180970000000005,33.92492927266069,1150.0,0.01
3.4356164999999996,0.034366595,33.95168365439938,1150.0,0.01
3.4547369999999997,0.0345578,33.98933330356241,1150.0,0.01
3.4724759999999995,0.03473519,34.02980402433899,1150.0,0.01
3.4918844999999994,0.034929274999999996,34.07179828298684,1150.0,0.01
3.5146235,0.035156665000000004,34.10949508334682,1150.0,0.01
3.534034,0.035350770000000004,34.151143085149954,1150.0,0.01
3.549009,0.03550052,34.19576454953618,1150.0,0.01
3.5712064999999997,0.035722495,34.23169182546215,1150.0,0.01
3.5931319999999998,0.03594175,34.27310983958539,1150.0,0.01
3.6120075,0.036130505,34.318584596199045,1150.0,0.01
3.6347739999999997,0.036358169999999995,34.367658621268944,1150.0,0.01
3.6564334999999994,0.036574764999999995,34.429006966257774,1150.0,0.01
3.6761524999999997,0.036771954999999995,34.47970738886601,1150.0,0.01
3.693926,0.03694969,34.52785186025241,1150.0,0.01
3.7147665,0.037158095,34.565095668845196,1150.0,0.01
3.7333885,0.037344315,34.60142619801555,1150.0,0.01
3.751729,0.03752772,34.64330989214606,1150.0,0.01
3.7734134999999998,0.037744565,34.68529534021228,1150.0,0.01
3.7967744999999997,0.037978175,34.728817717772785,1150.0,0.01
3.8162445,0.038172875,34.76246405356623,1150.0,0.01
3.83321,0.03834253,34.81000896921057,1150.0,0.01
3.8540739999999998,0.038551169999999996,34.84690847246081,1150.0,0.01
3.8729984999999996,0.038740415,34.87979369767097,1150.0,0.01
3.89471,0.038957530000000004,34.91555127877891,1150.0,0.01
3.91531,0.03916353,34.94533673811012,1150.0,0.01
3.9356385000000005,0.039366815,34.98385648390164,1150.0,0.01
3.9545785,0.039556215000000006,35.0212401986628,1150.0,0.01
3.9710145,0.039720575,35.05582887384835,1150.0,0.01
3.993305,0.03994348,35.08783922299415,1150.0,0.01
4.014765,0.04015808,35.129283417229324,1150.0,0.01
4.032322,0.04033365,35.15898944570492,1150.0,0.01
4.0501640000000005,0.04051207,35.1872436234228,1150.0,0.01
4.07136,0.04072403,35.224887357905715,1150.0,0.01
4.089762,0.04090805,35.26595743618391,1150.0,0.01
4.1084505,0.041094935,35.31187528451358,1150.0,0.01
4.13133,0.04132373,35.365543886922694,1150.0,0.01
4.153097,0.041541400000000006,35.415601503890436,1150.0,0.01
4.172914,0.041739570000000004,35.47356700916686,1150.0,0.01
4.193294999999999,0.04194338,35.532227896939645,1150.0,0.01
4.212560999999999,0.04213604,35.57066899218218,1150.0,0.01
4.232950499999999,0.042339934999999995,35.59253652670295,1150.0,0.01
4.256418,0.04257461,35.607570317810854,1150.0,0.01
4.275973499999999,0.042770165,35.609682038755906,1150.0,0.01
4.295256,0.04296299,35.617051327075956,1150.0,0.01
4.3111875,0.043122305,35.62267344014225,1150.0,0.01
4.32796,0.04329003,35.64493445328807,1150.0,0.01
4.3497699999999995,0.043508130000000006,35.6862112270172,1150.0,0.01
4.367951,0.04368994,35.745322018979174,1150.0,0.01
4.385852999999999,0.04386896,35.802098549233015,1150.0,0.01
4.4057115,0.044067545,35.85389847779758,1150.0,0.01
4.4253015,0.044263445,35.89121610491894,1150.0,0.01
4.445177999999999,0.04446221,35.92530021835831,1150.0,0.01
4.465614499999999,0.044666575,35.96880620111951,1150.0,0.01
4.4877325,0.044887755,36.00691368494328,1150.0,0.01
4.5067775,0.045078204999999996,36.0543768696667,1150.0,0.01
4.5252655,0.045263084999999995,36.10415878348297,1150.0,0.01
4.54908,0.045501230000000004,36.1509320596116,1150.0,0.01
4.569253999999999,0.045702969999999996,36.182033286914674,1150.0,0.01
4.5863475,0.045873905,36.20361644989774,1150.0,0.01
4.609899,0.04610942,36.22716130072163,1150.0,0.01
4.630647,0.0463169,36.254363556341076,1150.0,0.01
4.647194,0.04648237,36.28909611645291,1150.0,0.01
4.667393,0.04668436,36.32547214789406,1150.0,0.01
4.685910499999999,0.046869535000000004,36.3704158796175,1150.0,0.01
4.7047099999999995,0.04705753,36.410346903755986,1150.0,0.01
4.728845999999999,0.047298889999999996,36.447231672085444,1150.0,0.01
4.7504645,0.047515075000000004,36.47072397729943,1150.0,0.01
4.7661905,0.047672334999999996,36.48988931998493,1150.0,0.01
4.783322999999999,0.047843659999999996,36.52219551771026,1150.0,0.01
4.8032605,0.048043035,36.54270375834282,1150.0,0.01
4.8271365,0.048281795,36.56723031757564,1150.0,0.01
4.8493390000000005,0.04850382,36.59555852767023,1150.0,0.01
4.8673275,0.048683704999999994,36.63955099569301,1150.0,0.01
4.8861609999999995,0.04887204,36.697354864215896,1150.0,0.01
4.905003,0.04906046,36.75701288864403,1150.0,0.01
4.9246915,0.049257345,36.813085633894154,1150.0,0.01
4.942413999999999,0.04943457,36.8623210062805,1150.0,0.01
4.9626684999999995,0.049637114999999996,36.90547209164599,1150.0,0.01
4.9848965,0.049859395,36.91531085447341,1150.0,0.01
5.0046,0.05005643,36.91330504057386,1150.0,0.01
5.0248665,0.050259095000000004,36.90371267892057,1150.0,0.01
5.0473935,0.050484365,36.902295926941264,1150.0,0.01
5.0673885,0.050684315,36.91093294294871,1150.0,0.01
5.0834435,0.050844865,36.92687552134849,1150.0,0.01
5.102038499999999,0.051030815,36.96364455626702,1150.0,0.01
5.122609499999999,0.051236525000000005,37.01644287769318,1150.0,0.01
5.14262,0.05143663,37.076048802001786,1150.0,0.01
5.162915,0.051639580000000004,37.12917547356427,1150.0,0.01
5.1812439999999995,0.05182287,37.1755719562481,1150.0,0.01
5.2026765,0.052037194999999994,37.2157589662953,1150.0,0.01
5.226648,0.052276909999999996,37.25098006412648,1150.0,0.01
5.2461145,0.052471575,37.27076906815113,1150.0,0.01
5.264179,0.05265222,37.296363012655156,1150.0,0.01
5.2828075,0.052838505,37.32472004376473,1150.0,0.01
5.303976499999999,0.053050195,37.36048787476683,1150.0,0.01
5.326,0.05327043,37.39564085288608,1150.0,0.01
5.343508,0.05344551,37.428377702961896,1150.0,0.01
5.360174,0.05361217,37.460028785865035,1150.0,0.01
5.3785395000000005,0.053795825000000005,37.48714748424032,1150.0,0.01
5.4028445000000005,0.054038875,37.50869290840524,1150.0,0.01
5.425736,0.054267789999999996,37.52001067718584,1150.0,0.01
5.4438285,0.054448715,37.540578780902194,1150.0,0.01
5.4616430000000005,0.05462686,37.561674702814976,1150.0,0.01
5.4808699999999995,0.05481913,37.59321902397809,1150.0,0.01
5.503779999999999,0.055048230000000004,37.628177309663535,1150.0,0.01
5.5230195,0.055240625,37.6673342368603,1150.0,0.01
5.5428245,0.055438675,37.70751246176164,1150.0,0.01
5.5637669999999995,0.0556481,37.75435551846422,1150.0,0.01
5.583871499999999,0.055849145,37.797313601270524,1150.0,0.01
5.604260999999999,0.05605304,37.83525614982356,1150.0,0.01
5.625497999999999,0.05626541,37.87799082288437,1150.0,0.01
5.642491499999999,0.056435345,37.918899553700655,1150.0,0.01
5.660055999999999,0.05661099,37.95058381539009,1150.0,0.01
5.681309499999999,0.056823525,37.98550333774047,1150.0,0.01
5.700583,0.05701626,38.00066009991833,1150.0,0.01
5.7198605,0.057209035000000005,38.001692855339265,1150.0,0.01
5.7399915,0.057410345,38.01715992813832,1150.0,0.01
5.761261999999999,0.057623049999999995,38.033499914149395,1150.0,0.01
5.781969,0.05783012,38.05907087404504,1150.0,0.01
5.8001205,0.058011635,38.09180748768529,1150.0,0.01
5.8182805,0.058193234999999996,38.13644535578016,1150.0,0.01
5.836444,0.05837487,38.18217106532588,1150.0,0.01
5.8571670000000005,0.0585821,38.22785592353074,1150.0,0.01
5.877893499999999,0.058789364999999996,38.253046081792235,1150.0,0.01
5.8974874999999995,0.058985305,38.28409314371719,1150.0,0.01
5.9173715,0.059184145,38.30638387571352,1150.0,0.01
5.939531499999999,0.059405745,38.3192551645731,1150.0,0.01
5.9614080000000005,0.059624510000000006,38.33614755047231,1150.0,0.01
5.9778945,0.059789375000000006,38.34304642774124,1150.0,0.01
5.998365,0.059994080000000005,38.36158401122046,1150.0,0.01
6.0182645,0.060193075,38.38569927727159,1150.0,0.01
6.0350375,0.060360805000000003,38.4102665413983,1150.0,0.01
6.0572230000000005,0.060582659999999997,38.434773785503694,1150.0,0.01
6.0782785,0.060793215,38.471807714582916,1150.0,0.01
6.0970595,0.060981025,38.505502131832735,1150.0,0.01
6.116695999999999,0.06117739,38.53869021654288,1150.0,0.01
6.135484,0.06136527,38.57308492372121,1150.0,0.01
6.155415999999999,0.06156459,38.606590867500095,1150.0,0.01
6.1753465,0.061763895,38.644917952945725,1150.0,0.01
6.196705,0.06197748,38.67748149404245,1150.0,0.01
6.216931499999999,0.062179745,38.703375696064995,1150.0,0.01
6.234596499999999,0.062356394999999995,38.72608518679574,1150.0,0.01
6.256543999999999,0.06257586999999999,38.75019810782609,1150.0,0.01
6.2807794999999995,0.062818225,38.775290901638414,1150.0,0.01
6.3010235,0.063020665,38.79810724429538,1150.0,0.01
6.31927,0.06320313,38.81221096601503,1150.0,0.01
6.3380955,0.063391385,38.82473432049424,1150.0,0.01
6.3589225,0.063599655,38.84658185984091,1150.0,0.01
6.378327,0.0637937,38.87604379050756,1150.0,0.01
6.395448999999999,0.06396492,38.90872608005485,1150.0,0.01
6.416854999999999,0.06417898,38.95087091008702,1150.0,0.01
6.436558999999999,0.06437602,39.00504358501511,1150.0,0.01
6.453408,0.06454451,39.04845450187098,1150.0,0.01
6.4739705,0.064750135,39.08062758872867,1150.0,0.01
6.494825499999999,0.064958685,39.09426905617378,1150.0,0.01
6.5171135,0.065181565,39.102924172783844,1150.0,0.01
6.537405,0.06538448,39.118315694494505,1150.0,0.01
6.556844999999999,0.06557888,39.13908559018398,1150.0,0.01
6.576572,0.06577615,39.16135026862343,1150.0,0.01
6.595157499999999,0.06596200499999999,39.1823890834833,1150.0,0.01
6.6186135,0.066196565,39.20885400111174,1150.0,0.01
6.6383575,0.066394005,39.22305521442213,1150.0,0.01
6.65381,0.06654853,39.23720351816437,1150.0,0.01
6.674697500000001,0.066757405,39.25533581627051,1150.0,0.01
6.695305,0.06696348,39.27577265122311,1150.0,0.01
6.7130600000000005,0.06714103,39.30068215712861,1150.0,0.01
6.732533999999999,0.06733577,39.33192529233492,1150.0,0.01
6.7525805,0.067536235,39.37286833099065,1150.0,0.01
6.771772499999999,0.067728155,39.4137641101935,1150.0,0.01
6.792116,0.06793159,39.452106989365745,1150.0,0.01
6.813896,0.06814939,39.49021233476533,1150.0,0.01
6.835106499999998,0.068361495,39.531270971121565,1150.0,0.01
6.8511635,0.068522065,39.5648066480022,1150.0,0.01
6.8709495,0.068719925,39.57699371109108,1150.0,0.01
6.893889999999999,0.06894933,39.59322717311174,1150.0,0.01
6.913974,0.06915017,39.60838620282766,1150.0,0.01
6.9340615,0.069351045,39.61404859828459,1150.0,0.01
6.9524285,0.069534715,39.63293744211416,1150.0,0.01
6.9730989999999995,0.06974142,39.659445638905844,1150.0,0.01
6.995208999999999,0.06996252,39.69129182495676,1150.0,0.01
7.0147319999999995,0.07015774999999999,39.726156851407374,1150.0,0.01
7.0325385,0.070335815,39.760694402568085,1150.0,0.01
7.0500635,0.07051106500000001,39.79475351040675,1150.0,0.01
7.069312999999999,0.07070356,39.82925532727577,1150.0,0.01
7.092305,0.07093348,39.850366717889464,1150.0,0.01
7.1127135,0.071137565,39.86799333155847,1150.0,0.01
7.1296764999999995,0.07130719499999999,39.896913172721305,1150.0,0.01
7.150383999999999,0.07151426999999999,39.92333326614948,1150.0,0.01
7.1708039999999995,0.07171847,39.94116952441271,1150.0,0.01
7.189791,0.07190834,39.960349610145265,1150.0,0.01
7.207919499999999,0.07208962499999999,39.99015810691583,1150.0,0.01
7.228637999999999,0.07229680999999999,40.02324717774726,1150.0,0.01
7.251665999999999,0.07252708999999999,40.046801571194365,1150.0,0.01
7.2700914999999995,0.072711345,40.061033045622544,1150.0,0.01
7.289669,0.07290711999999999,40.078394967799156,1150.0,0.01
7.310118,0.07311161,40.075847973606095,1150.0,0.01
7.3291315,0.073301745,40.054273589384685,1150.0,0.01
7.348148499999999,0.07349191499999999,40.02876447166656,1150.0,0.01
7.367455,0.07368498,40.02139480936914,1150.0,0.01
7.387919999999999,0.07388963,40.03268533755079,1150.0,0.01
7.408389499999999,0.07409432499999999,40.073284736365466,1150.0,0.01
7.428863,0.07429906,40.13349205796207,1150.0,0.01
7.4458795,0.074469225,40.20173456903604,1150.0,0.01
7.4643415,0.074653845,40.26468239374475,1150.0,0.01
7.485117,0.0748616,40.32422812931645,1150.0,0.01
7.5076275,0.075086705,40.36413611802066,1150.0,0.01
7.5284075,0.07529450500000001,40.383430558685085,1150.0,0.01
7.5457275,0.075467705,40.3911154558576,1150.0,0.01
7.5644985,0.075655415,40.38857398987463,1150.0,0.01
7.5841389999999995,0.07585182,40.39038960080857,1150.0,0.01
7.606957999999999,0.07608001,40.394014415795326,1150.0,0.01
7.6271854999999995,0.076282285,40.39549846133335,1150.0,0.01
7.645393499999999,0.076464365,40.408730492212335,1150.0,0.01
7.665622999999999,0.07666666,40.44695620241844,1150.0,0.01
7.687015499999999,0.076880585,40.49264469725163,1150.0,0.01
7.7092839999999985,0.07710327,40.52452521257388,1150.0,0.01
7.729238999999999,0.07730282,40.54625815858508,1150.0,0.01
7.745434999999999,0.07746478,40.56455089457594,1150.0,0.01
7.764818999999999,0.07765862,40.5765736041613,1150.0,0.01
7.788263999999999,0.07789307,40.58439328150408,1150.0,0.01
7.808814999999999,0.07809858,40.594103868484986,1150.0,0.01
7.826471,0.07827513999999999,40.62726282308945,1150.0,0.01
7.8458755,0.078469185,40.671092950790204,1150.0,0.01
7.8644110000000005,0.07865454,40.72595302879947,1150.0,0.01
7.8829505,0.078839935,40.75998699010266,1150.0,0.01
7.903521,0.07904564,40.77886258729188,1150.0,0.01
7.9246765,0.079257195,40.78958357808952,1150.0,0.01
7.945549,0.07946592,40.789013764364235,1150.0,0.01
7.966127500000001,0.07967170500000001,40.778267743762235,1150.0,0.01
7.9858465,0.079868895,40.76510997627541,1150.0,0.01
8.004989,0.08006032,40.770942381540564,1150.0,0.01
8.025292,0.08026335000000001,40.79452310780932,1150.0,0.01
8.046766000000002,0.08047809,40.82504243337947,1150.0,0.01
8.068533,0.08069576,40.857267245305486,1150.0,0.01
8.087398,0.08088440999999999,40.89532665122189,1150.0,0.01
8.107723,0.08108766,40.92438446247566,1150.0,0.01
8.12921,0.08130253,40.9523469712276,1150.0,0.01
8.1475045,0.081485475,40.96814933321669,1150.0,0.01
8.1652255,0.081662685,40.97846769868218,1150.0,0.01
8.186143000000001,0.08187186,40.98848608948113,1150.0,0.01
8.205323000000002,0.08206366000000001,41.00953431421235,1150.0,0.01
8.2236375,0.082246805,41.02288063907446,1150.0,0.01
8.2468965,0.082479395,41.04836591747402,1150.0,0.01
8.264634000000001,0.08265676999999999,41.06874061442625,1150.0,0.01
8.281794,0.08282837,41.081181782640236,1150.0,0.01
8.302736,0.08303779,41.10037648793397,1150.0,0.01
8.322228500000001,0.083232715,41.11578819386954,1150.0,0.01
8.3434725,0.083445155,41.129438071198855,1150.0,0.01
8.363554500000001,0.08364597500000001,41.14976605970454,1150.0,0.01
8.3833525,0.083843955,41.17149229163844,1150.0,0.01
8.403737500000002,0.084047805,41.189477349943424,1150.0,0.01
8.4252885,0.084263315,41.22198283639614,1150.0,0.01
8.4480105,0.084490535,41.266754723892205,1150.0,0.01
8.466074,0.08467117,41.32283850254943,1150.0,0.01
8.484431,0.08485474000000001,41.377920581204656,1150.0,0.01
8.503963500000001,0.08505006500000001,41.405319715399244,1150.0,0.01
8.524084,0.08525126999999999,41.41143578793511,1150.0,0.01
8.5474075,0.08548450499999999,41.40814703803881,1150.0,0.01
8.5663625,0.085674055,41.39394830580583,1150.0,0.01
8.583284500000001,0.085843275,41.36890240796878,1150.0,0.01
8.601957,0.08603,41.358964009766275,1150.0,0.01
8.622092,0.08623135,41.372565814870576,1150.0,0.01
8.645149,0.08646192,41.396165535963426,1150.0,0.01
8.665581500000002,0.086666245,41.41695631169091,1150.0,0.01
8.6848545,0.086858975,41.429246695166384,1150.0,0.01
8.700041,0.08701084,41.45281836266844,1150.0,0.01
8.717571,0.08718614,41.47704696992038,1150.0,0.01
8.740365,0.08741408,41.51404107294504,1150.0,0.01
8.7602325,0.087612755,41.53317133286208,1150.0,0.01
8.781564500000002,0.087826075,41.552620849924416,1150.0,0.01
8.801740500000001,0.088027835,41.57204178789795,1150.0,0.01
8.82104,0.08822083,41.59444527172975,1150.0,0.01
8.842095,0.08843138,41.606395523834074,1150.0,0.01
8.860235,0.08861278,41.616930219831964,1150.0,0.01
8.877201500000002,0.088782445,41.63232665028076,1150.0,0.01
8.898855000000001,0.08899898,41.64675782685058,1150.0,0.01
8.9199315,0.08920974500000001,41.661802093992044,1150.0,0.01
8.9413035,0.08942346500000001,41.65057320126058,1150.0,0.01
8.9635565,0.089645995,41.64966570657269,1150.0,0.01
8.983764,0.08984807,41.653554570889405,1150.0,0.01
9.002802500000001,0.090038455,41.67552238853587,1150.0,0.01
9.020967,0.0902201,41.706152099415,1150.0,0.01
9.040017500000001,0.090410605,41.74690657539791,1150.0,0.01
9.060536500000001,0.090615795,41.79809455804217,1150.0,0.01
9.0822295,0.090832725,41.845531481547816,1150.0,0.01
9.103340000000001,0.09104382999999999,41.879309811697624,1150.0,0.01
9.122993500000002,0.091240365,41.89552511364428,1150.0,0.01
9.139713,0.09140756,41.90477270814409,1150.0,0.01
9.159369000000002,0.09160412000000001,41.90454438312308,1150.0,0.01
9.181967,0.0918301,41.9048521266307,1150.0,0.01
9.1995755,0.09200618499999999,41.909628783285804,1150.0,0.01
9.217188,0.09218231,41.921548485395526,1150.0,0.01
9.2389205,0.09239963500000001,41.93000134205467,1150.0,0.01
9.257127,0.09258169999999999,41.93050861243341,1150.0,0.01
9.2756295,0.092766725,41.93535802208144,1150.0,0.01
9.2970775,0.09298120500000001,41.93916388279916,1150.0,0.01
9.3194105,0.093204535,41.93766750760213,1150.0,0.01
9.3396895,0.093407325,41.95445081777467,1150.0,0.01
9.358504500000002,0.09359547500000001,41.98233984909524,1150.0,0.01
9.377619500000002,0.09378662500000001,42.0220813829044,1150.0,0.01
9.397619500000001,0.093986625,42.07033818052591,1150.0,0.01
9.4173255,0.094183685,42.10696822136478,1150.0,0.01
9.437333500000001,0.09438376500000001,42.13265699166562,1150.0,0.01
9.4599895,0.094610325,42.15064907544225,1150.0,0.01
9.4802975,0.094813405,42.13870076575123,1150.0,0.01
9.501789,0.09502832,42.12217987307541,1150.0,0.01
9.520926,0.09521969,42.113852270372654,1150.0,0.01
9.5394825,0.095405255,42.1106990852568,1150.0,0.01
9.560104500000001,0.095611475,42.11584402996503,1150.0,0.01
9.5795505,0.095805935,42.142056449301755,1150.0,0.01
9.599,0.09600043,42.1782331938636,1150.0,0.01
9.620518,0.09621561000000001,42.220918565611456,1150.0,0.01
9.6432155,0.096442585,42.25081297850736,1150.0,0.01
9.6623795,0.09663422499999999,42.25716913443237,1150.0,0.01
9.679781,0.09680823999999999,42.25619267527543,1150.0,0.01
9.701023,0.09702066,42.25762046244036,1150.0,0.01
9.721379500000001,0.097224225,42.252081569336326,1150.0,0.01
9.740266000000002,0.09741309000000001,42.24407357103361,1150.0,0.01
9.760637000000001,0.0976168,42.25136622169486,1150.0,0.01
9.7783485,0.09779391500000001,42.26661037167433,1150.0,0.01
9.798130500000001,0.097991735,42.287216308480595,1150.0,0.01
9.818507,0.09819549999999999,42.29602153554613,1150.0,0.01
9.835935000000001,0.09836978,42.31112491192232,1150.0,0.01
9.8566185,0.098576615,42.3415616560041,1150.0,0.01
9.8752365,0.09876279499999999,42.37891693146062,1150.0,0.01
9.8959235,0.098969665,42.4154721724894,1150.0,0.01
9.919569000000001,0.09920612000000001,42.45877200173176,1150.0,0.01
9.940563000000001,0.09941606,42.49806210812238,1150.0,0.01
9.9597895,0.099608325,42.52161039925594,1150.0,0.01
9.976356500000001,0.099773995,42.52942333036128,1150.0,0.01
9.996471,0.09997513999999999,42.52766134206744,1150.0,0.01
10.017481,0.10018524,42.52534400753261,1150.0,0.01
10.0367225,0.100377655,42.51584481381414,1150.0,0.01
10.055075500000001,0.100561185,42.486466824415515,1150.0,0.01
10.0769855,0.100780285,42.476328370673485,1150.0,0.01
10.099198999999999,0.10100242,42.493360860582385,1150.0,0.01
10.117269499999999,0.101183125,42.51913636381741,1150.0,0.01
10.1362305,0.10137273499999999,42.554943543003404,1150.0,0.01
10.158158499999999,0.101592015,42.5919119823651,1150.0,0.01
10.176833,0.10177876,42.627707788888046,1150.0,0.01
10.196994,0.10198037,42.650923008579575,1150.0,0.01
10.216858,0.10217901,42.65213535924805,1150.0,0.01
10.2334675,0.10234510499999999,42.63580424726717,1150.0,0.01
10.2521505,0.10253193499999999,42.640391027517154,1150.0,0.01
10.272321000000002,0.10273364,42.65259100179182,1150.0,0.01
10.294578000000001,0.10295620999999999,42.67087975031459,1150.0,0.01
10.3135725,0.10314615499999999,42.70122972437943,1150.0,0.01
10.33465,0.10335693,42.73008240540227,1150.0,0.01
10.355731,0.10356773999999999,42.75273407579813,1150.0,0.01
10.3759275,0.10376970499999999,42.76846377574325,1150.0,0.01
10.396723,0.10397766,42.77195982790441,1150.0,0.01
10.415737,0.1041678,42.771571124218376,1150.0,0.01
10.4347545,0.10435797499999999,42.771312395639406,1150.0,0.01
10.454666500000002,0.104557095,42.77444809496711,1150.0,0.01
10.473096000000002,0.10474139,42.78452385260501,1150.0,0.01
10.4906395,0.104916825,42.800294160661274,1150.0,0.01
10.514432500000002,0.105154755,42.8221821612,1150.0,0.01
10.535255500000002,0.10536298499999999,42.828963374362225,1150.0,0.01
10.5495345,0.105505775,42.82846899783772,1150.0,0.01
10.571849,0.10572892,42.819397754463125,1150.0,0.01
10.5959605,0.10597003499999999,42.81139833294566,1150.0,0.01
10.6162055,0.106172485,42.79690430400293,1150.0,0.01
10.637642,0.10638685,42.80476678470153,1150.0,0.01
10.654617000000002,0.1065566,42.82368257871067,1150.0,0.01
10.6739815,0.106750245,42.843451118261704,1150.0,0.01
10.697521000000002,0.10698563999999999,42.87733410742089,1150.0,0.01
10.717184500000002,0.107182275,42.90177315057316,1150.0,0.01
10.734173,0.10735216,42.93001301058934,1150.0,0.01
10.75266,0.10753703,42.95328048145146,1150.0,0.01
10.772339500000001,0.107733825,42.96679611568099,1150.0,0.01
10.792916,0.10793959,42.98353436629601,1150.0,0.01
10.81439,0.10815432999999999,42.99599602781832,1150.0,0.01
10.8337805,0.108348235,42.989417697620524,1150.0,0.01
10.85437,0.10855413,42.96951157660183,1150.0,0.01
10.874069,0.10875112,42.95346676078791,1150.0,0.01
10.8925765,0.108936195,42.94994701657565,1150.0,0.01
10.9140725,0.109151155,42.96754246631965,1150.0,0.01
10.933487,0.1093453,42.995747847761066,1150.0,0.01
10.950814000000001,0.10951857,43.026550843462275,1150.0,0.01
10.9687375,0.109697805,43.06401682278938,1150.0,0.01
10.9923425,0.109933855,43.08487560463052,1150.0,0.01
11.015956500000001,0.11016999499999999,43.09573513299946,1150.0,0.01
11.0341935,0.11035236500000001,43.096164167937765,1150.0,0.01
11.053923000000001,0.11054966,43.09853251886613,1150.0,0.01
11.074261,0.11075304,43.106745906405756,1150.0,0.01
11.093410500000001,0.11094453500000001,43.11663136711208,1150.0,0.01
11.1116615,0.11112704500000001,43.130140179189844,1150.0,0.01
11.1290135,0.11130056499999999,43.12988128039599,1150.0,0.01
11.1523595,0.111534025,43.1306135731689,1150.0,0.01
11.17511,0.11176153,43.13614436171058,1150.0,0.01
11.195770500000002,0.111968135,43.140612916928106,1150.0,0.01
11.217034000000002,0.11218077000000001,43.13276480601333,1150.0,0.01
11.2368,0.11237843,43.12584061427656,1150.0,0.01
11.2565745,0.112576175,43.10782484374151,1150.0,0.01
11.2754555,0.11276498500000001,43.09121798937841,1150.0,0.01
11.2916405,0.112926835,43.09346547192922,1150.0,0.01
11.3096255,0.113106685,43.103604984046605,1150.0,0.01
11.330015,0.11331058,43.12910426010802,1150.0,0.01
11.35041,0.11351453,43.166354964293255,1150.0,0.01
11.371403,0.11372446,43.209035304760896,1150.0,0.01
11.389407,0.11390449999999999,43.2327633547794,1150.0,0.01
11.413718,0.11414761,43.25732334989073,1150.0,0.01
11.435325500000001,0.11436368499999999,43.26740986379841,1150.0,0.01
11.453033000000001,0.11454075999999999,43.28200387994472,1150.0,0.01
11.474351,0.11475394,43.28898041603312,1150.0,0.01
11.4926715,0.114937145,43.279695859615195,1150.0,0.01
11.510996500000001,0.115120395,43.25616692687692,1150.0,0.01
11.533531,0.11534574,43.236226765561824,1150.0,0.01
11.553662500000002,0.115547055,43.22858984954211,1150.0,0.01
11.571092,0.11572135,43.219407213353385,1150.0,0.01
11.5906345,0.115916775,43.229511539643006,1150.0,0.01
11.609877000000001,0.1161092,43.24816466729248,1150.0,0.01
11.6312295,0.11632272499999999,43.27385166078696,1150.0,0.01
11.65289,0.11653933,43.299237707575045,1150.0,0.01
11.672443000000001,0.11673486,43.316306787996474,1150.0,0.01
11.690496,0.11691539000000001,43.33007658863654,1150.0,0.01
11.709156,0.11710198999999999,43.345257192477455,1150.0,0.01
11.728421,0.11729464,43.34668669220111,1150.0,0.01
11.7485975,0.117496405,43.343221606496414,1150.0,0.01
11.769680000000001,0.11770723,43.34153157971257,1150.0,0.01
11.7880495,0.11789092500000001,43.32577138968749,1150.0,0.01
11.807934,0.11808977000000001,43.31535632570064,1150.0,0.01
11.8281265,0.118291695,43.31597128524441,1150.0,0.01
11.850727500000001,0.118517705,43.329261711240065,1150.0,0.01
11.8727345,0.11873777499999999,43.34617491041759,1150.0,0.01
11.890824,0.11891867,43.35555833071719,1150.0,0.01
11.910423999999999,0.11911467,43.350199934572,1150.0,0.01
11.9306375,0.119316805,43.34385243968903,1150.0,0.01
11.946625000000001,0.11947668,43.33792171749355,1150.0,0.01
11.9662365,0.119672795,43.321762216501085,1150.0,0.01
11.988573500000001,0.119896165,43.32094692256536,1150.0,0.01
12.008498,0.12009541,43.32027160852405,1150.0,0.01
12.0287255,0.12029768499999999,43.333980848800934,1150.0,0.01
12.0495675,0.120506105,43.34280833418234,1150.0,0.01
12.0698035,0.120708465,43.3532567864778,1150.0,0.01
12.088834000000002,0.12089877,43.35397482489447,1150.0,0.01
12.109083000000002,0.12110126,43.34560264715701,1150.0,0.01
12.131753000000002,0.12132796000000001,43.352879568872666,1150.0,0.01
12.152005,0.12153048,43.35810483723825,1150.0,0.01
12.170145000000002,0.12171188,43.36398109295186,1150.0,0.01
12.187382000000001,0.12188425,43.375273967365345,1150.0,0.01
12.207647000000001,0.1220869,43.390576385822236,1150.0,0.01
12.230639,0.12231681999999999,43.410477278682265,1150.0,0.01
12.250311,0.12251354,43.43556557630514,1150.0,0.01
12.260904,0.12261947,43.450239042640064,1150.0,0.01