File: datasets/steel_spring/csv/BS2V-1100-0.1.csv
Time(s),Strain(%),Stress(MPa),Temp(C),SR(%/s)
0.0,1.276e-05,-0.141979022062117,1100.0,0.1
0.0001614,2.89e-05,0.6415092866634543,1100.0,0.1
0.0005356,6.632e-05,2.731100682754637,1100.0,0.1
0.0020371,0.00021647,5.884749238628373,1100.0,0.1
0.0027865,0.00029141,9.860409026701602,1100.0,0.1
0.004930499999999999,0.00050581,15.680371222200819,1100.0,0.1
0.006431699999999999,0.00065593,20.793376789162963,1100.0,0.1
0.0083617,0.00084893,25.695709467541768,1100.0,0.1
0.0106675,0.00107951,30.206044568931937,1100.0,0.1
0.0141549,0.00142825,33.86227545377287,1100.0,0.1
0.017804300000000002,0.00179319,36.44520906064408,1100.0,0.1
0.0221525,0.00222801,38.00657287175015,1100.0,0.1
0.0276843,0.00278119,38.701356557253945,1100.0,0.1
0.0319301,0.00320577,38.90983265192061,1100.0,0.1
0.0376293,0.00377569,38.95710977470849,1100.0,0.1
0.0413397,0.00414673,39.21188426119334,1100.0,0.1
0.047206500000000005,0.00473341,39.625418820151665,1100.0,0.1
0.0514062,0.00515338,40.14649310945849,1100.0,0.1
0.057062100000000004,0.00571897,40.65447285186758,1100.0,0.1
0.0602418,0.00603694,41.14539486308349,1100.0,0.1
0.06557969999999999,0.00657073,41.620499237587275,1100.0,0.1
0.0704345,0.00705621,42.07808180510622,1100.0,0.1
0.07442779999999999,0.00745554,42.5115811062085,1100.0,0.1
0.07928699999999998,0.00794146,42.90265718210244,1100.0,0.1
0.08328479999999999,0.00834124,43.25642497107594,1100.0,0.1
0.0884184,0.0088546,43.56951699450396,1100.0,0.1
0.0924726,0.00926002,43.87249861135244,1100.0,0.1
0.09734049999999998,0.00974681,44.13945065504183,1100.0,0.1
0.1009119,0.01010395,44.40846764048502,1100.0,0.1
0.10578399999999999,0.01059116,44.666853377011535,1100.0,0.1
0.11011689999999999,0.01102445,44.924468386488805,1100.0,0.1
0.11390899999999998,0.01140366,45.18809883829562,1100.0,0.1
0.11835399999999999,0.01184816,45.4489044048979,1100.0,0.1
0.1225299,0.01226575,45.715002354314564,1100.0,0.1
0.12676149999999997,0.01268891,45.98898427629942,1100.0,0.1
0.1303434,0.0130471,46.263171712723654,1100.0,0.1
0.1355552,0.01356828,46.525299393204726,1100.0,0.1
0.1379993,0.01381269,46.79489959739413,1100.0,0.1
0.14305229999999997,0.01431799,47.04725226788276,1100.0,0.1
0.14685789999999999,0.01469855,47.30457577585624,1100.0,0.1
0.1513176,0.01514452,47.553491154166856,1100.0,0.1
0.1561593,0.01562869,47.80984242621988,1100.0,0.1
0.15969769999999997,0.01598253,48.062131443875195,1100.0,0.1
0.1647076,0.01648352,48.30871955801913,1100.0,0.1
0.16819409999999999,0.01683217,48.547300325829745,1100.0,0.1
0.1726082,0.01727358,48.78707687557973,1100.0,0.1
0.17669769999999996,0.01768253,49.028098892572146,1100.0,0.1
0.18149749999999998,0.01816251,49.26434738066307,1100.0,0.1
0.18482539999999997,0.0184953,49.51016402017064,1100.0,0.1
0.18973949999999998,0.01898671,49.75480831073884,1100.0,0.1
0.19328889999999996,0.01934165,49.99459648623505,1100.0,0.1
0.1979873,0.01981149,50.23195957176914,1100.0,0.1
0.20301639999999999,0.0203144,50.4652262244396,1100.0,0.1
0.20640769999999997,0.02065353,50.69626312059868,1100.0,0.1
0.21165919999999996,0.02117868,50.91899557411004,1100.0,0.1
0.2149428,0.02150704,51.12911241572746,1100.0,0.1
0.22025409999999998,0.02203817,51.354558415761566,1100.0,0.1
0.223596,0.02237236,51.57946325356838,1100.0,0.1
0.2288031,0.02289307,51.80172256565928,1100.0,0.1
0.2325851,0.02327127,52.01071697269717,1100.0,0.1
0.2371931,0.02373207,52.227165566663096,1100.0,0.1
0.2420775,0.02422051,52.44705800458354,1100.0,0.1
0.24553559999999996,0.02456632,52.66012484767445,1100.0,0.1
0.2507542,0.02508818,52.873605912632776,1100.0,0.1
0.2546,0.02547276,53.087408489147926,1100.0,0.1
0.2592172,0.02593448,53.30458207167446,1100.0,0.1
0.2627367,0.02628643,53.52489436470098,1100.0,0.1
0.26757909999999996,0.02677067,53.731009689477474,1100.0,0.1
0.27165189999999995,0.02717795,53.940290853981274,1100.0,0.1
0.2761676,0.02762952,54.138607415469906,1100.0,0.1
0.28123519999999996,0.02813628,54.34371733992825,1100.0,0.1
0.2846531,0.02847807,54.552611955000216,1100.0,0.1
0.28972499999999995,0.02898526,54.77192874148506,1100.0,0.1
0.2932553,0.02933829,54.98095444112521,1100.0,0.1
0.2981115,0.02982391,55.184176289254005,1100.0,0.1
0.3020324,0.030216,55.39629119524264,1100.0,0.1
0.3072237,0.03073513,55.604414483557036,1100.0,0.1
0.31048499999999996,0.03106126,55.80666637930326,1100.0,0.1
0.31523879999999993,0.03153664,55.990086586386575,1100.0,0.1
0.3206586,0.03207862,56.182361252674475,1100.0,0.1
0.3244765,0.03246041,56.38133092228053,1100.0,0.1
0.3292929,0.03294205,56.568055084629016,1100.0,0.1
0.3330031,0.03331307,56.755794971568406,1100.0,0.1
0.3375466,0.03376742,56.934407644708564,1100.0,0.1
0.341537,0.03416646,57.119831222091136,1100.0,0.1
0.34630659999999996,0.03464342,57.295484863788104,1100.0,0.1
0.3500792,0.03502068,57.4836425255116,1100.0,0.1
0.35507419999999995,0.03552018,57.662690355219915,1100.0,0.1
0.35879399999999995,0.03589216,57.844395445394156,1100.0,0.1
0.3641272,0.03642548,58.02755874981463,1100.0,0.1
0.3683509,0.03684785,58.19449955128432,1100.0,0.1
0.3723536,0.03724812,58.373308214712345,1100.0,0.1
0.37769299999999995,0.03778206,58.52661000937903,1100.0,0.1
0.38069819999999993,0.03808258,58.682691552879014,1100.0,0.1
0.38604310000000003,0.03861707,58.83083900311386,1100.0,0.1
0.39099979999999995,0.03911274,59.00126162394342,1100.0,0.1
0.39434379999999997,0.03944714,59.170289975617656,1100.0,0.1
0.399361,0.03994886,59.327652521636594,1100.0,0.1
0.40298559999999994,0.04031132,59.48856473093204,1100.0,0.1
0.40756109999999995,0.04076887,59.6412360251063,1100.0,0.1
0.4116359,0.04117635,59.804341134401746,1100.0,0.1
0.4167171,0.04168447,59.94332899720857,1100.0,0.1
0.42029369999999994,0.04204213,60.09587850983736,1100.0,0.1
0.424764,0.04248916,60.23864385051539,1100.0,0.1
0.4289014,0.0429029,60.39078027378812,1100.0,0.1
0.43332109999999996,0.04334487,60.538564617147976,1100.0,0.1
0.43729429999999997,0.04374219,60.693438868504025,1100.0,0.1
0.4418289,0.04419565,60.84428305959872,1100.0,0.1
0.44658999999999993,0.04467176,60.982553262469935,1100.0,0.1
0.450344,0.04504716,61.1216301929169,1100.0,0.1
0.4552214,0.0455349,61.26359967992448,1100.0,0.1
0.45959609999999995,0.04597237,61.414941820833576,1100.0,0.1
0.4641975,0.04643251,61.55513664839796,1100.0,0.1
0.4680137999999999,0.04681414,61.693283113401755,1100.0,0.1
0.4726748,0.04728024,61.82982918673508,1100.0,0.1
0.4761021,0.04762297,61.974174445363886,1100.0,0.1
0.4816666,0.04817942,62.10253474850783,1100.0,0.1
0.48487169999999996,0.04849993,62.22147385486009,1100.0,0.1
0.4902157,0.04903433,62.33150934646994,1100.0,0.1
0.4947743,0.04949019,62.454856713969946,1100.0,0.1
0.4983778,0.04985054,62.58610917324646,1100.0,0.1
0.5035603,0.05036879,62.71250118592449,1100.0,0.1
0.5072798,0.05074074,62.84858044208357,1100.0,0.1
0.5122410999999999,0.05123687,62.98344856246994,1100.0,0.1
0.5160208,0.05161484,63.12000582538282,1100.0,0.1
0.5205352999999999,0.05206629,63.241674543132824,1100.0,0.1
0.5247683999999999,0.0524896,63.35530212782222,1100.0,0.1
0.5298515,0.05299791,63.46891535616691,1100.0,0.1
0.5330159,0.05331435,63.59476816675025,1100.0,0.1
0.5383297,0.05384573,63.71575854951919,1100.0,0.1
0.5428542,0.05429818,63.83514296903434,1100.0,0.1
0.5463617,0.05464893,63.956757007530534,1100.0,0.1
0.5516253,0.05517529,64.07971169534117,1100.0,0.1
0.5549662999999999,0.05550939,64.19286663200023,1100.0,0.1
0.5601782,0.05603058,64.30789906659494,1100.0,0.1
0.5636918,0.05638194,64.42541852043584,1100.0,0.1
0.5683976,0.05685252,64.55275847620858,1100.0,0.1
0.5724249,0.05725525,64.68364667346616,1100.0,0.1
0.5770212,0.05771488,64.80537206009117,1100.0,0.1
0.5809392999999999,0.05810669,64.92705131836011,1100.0,0.1
0.585028,0.05851556,65.05271507237146,1100.0,0.1
0.5906534999999999,0.05907811,65.16959718205706,1100.0,0.1
0.5950878,0.05952154,65.28297955501161,1100.0,0.1
0.599012,0.05991396,65.39974261096614,1100.0,0.1
0.6028237,0.06029513,65.5156955219245,1100.0,0.1
0.607776,0.06079036,65.63417146481844,1100.0,0.1
0.6110783,0.06112059,65.74743591352677,1100.0,0.1
0.6166619,0.06167895,65.86635590254193,1100.0,0.1
0.6199670999999999,0.06200947,65.97912391525405,1100.0,0.1
0.6250997999999999,0.06252274,66.09178622420478,1100.0,0.1
0.6288072,0.06289348,66.20083326042828,1100.0,0.1
0.6338857,0.06340133,66.32426952072754,1100.0,0.1
0.6394244,0.0639552,66.4383975805495,1100.0,0.1
0.6427948,0.06429224,66.54825059379573,1100.0,0.1
0.6475957999999999,0.06477234,66.66197535403813,1100.0,0.1
0.6507399999999999,0.06508676,66.76891693217829,1100.0,0.1
0.6563448,0.06564724,66.88196702340177,1100.0,0.1
0.6601794,0.0660307,66.97813084072375,1100.0,0.1
0.6646437,0.06647713,67.0885706158033,1100.0,0.1
0.6681951999999999,0.06683228,67.19641075180708,1100.0,0.1
0.6732948,0.06734224,67.31032204054193,1100.0,0.1
0.6770771,0.06772047,67.4090336554548,1100.0,0.1
0.6816646999999999,0.06817923,67.50025929442073,1100.0,0.1
0.6866563,0.06867839,67.5956718813033,1100.0,0.1
0.6903296,0.06904572,67.68072927509117,1100.0,0.1
0.6956125999999999,0.06957402,67.7798214293601,1100.0,0.1
0.6992310999999999,0.06993587,67.86397322283361,1100.0,0.1
0.703772,0.07038996,67.9709934297995,1100.0,0.1
0.7070489999999999,0.07071766,68.07561927814042,1100.0,0.1
0.7126855,0.07128131,68.1787349209283,1100.0,0.1
0.7160816999999999,0.07162093,68.2796997174245,1100.0,0.1
0.721262,0.07213896,68.37878670488664,1100.0,0.1
0.7258699999999999,0.07259976,68.4798966346177,1100.0,0.1
0.7293268999999999,0.07294545,68.572234043898,1100.0,0.1
0.7348614,0.0734989,68.67238890346238,1100.0,0.1
0.7383797999999999,0.07385074,68.76193775982223,1100.0,0.1
0.7433413999999999,0.0743469,68.86267098457225,1100.0,0.1
0.7464585999999999,0.07465862,68.95903306059118,1100.0,0.1
0.7516556,0.07517832,69.0550343499889,1100.0,0.1
0.7555842999999999,0.07557119,69.1520202854927,1100.0,0.1
0.7606702999999999,0.07607979,69.24946313809117,1100.0,0.1
0.7641977,0.07643253,69.3434570912465,1100.0,0.1
0.7694038999999999,0.07695315,69.4373732853336,1100.0,0.1
0.7742076,0.07743352,69.52629518777302,1100.0,0.1
0.7776812,0.07778088,69.61349052372755,1100.0,0.1
0.7818523,0.07819799,69.71012357022755,1100.0,0.1
0.7862560999999999,0.07863837,69.79713230962149,1100.0,0.1
0.7911255,0.07912531,69.87991347434875,1100.0,0.1
0.7954171999999999,0.07955448,69.9609652554586,1100.0,0.1
0.7999433,0.08000709,70.04549950451542,1100.0,0.1
0.8037171999999999,0.08038448,70.1128594492995,1100.0,0.1
0.8086537,0.08087813,70.19147327387147,1100.0,0.1
0.8133021999999999,0.08134298,70.26251335286013,1100.0,0.1
0.8171377999999999,0.08172654,70.34338447825026,1100.0,0.1
0.8224304,0.0822558,70.42415985218209,1100.0,0.1
0.8260373999999999,0.0826165,70.50438276221999,1100.0,0.1
0.8311593,0.08312869,70.57769283913287,1100.0,0.1
0.8346539,0.08347815,70.66135197782982,1100.0,0.1
0.8394301,0.08395577,70.73836313215558,1100.0,0.1
0.8432188999999999,0.08433465,70.80534282900787,1100.0,0.1
0.8482918,0.08484194,70.88462701361394,1100.0,0.1
0.8518492,0.08519768,70.96006402450028,1100.0,0.1
0.8569264999999999,0.08570541,71.03386619175406,1100.0,0.1
0.8617722999999999,0.08618999,71.10102222480332,1100.0,0.1
0.8653934999999999,0.08655211,71.16761357196619,1100.0,0.1
0.8701275999999999,0.08702552,71.24579705828435,1100.0,0.1
0.8742192,0.08743468,71.32417965388665,1100.0,0.1
0.8790154,0.0879143,71.40426902721997,1100.0,0.1
0.8825257,0.08826533,71.47845339251923,1100.0,0.1
0.8872086999999999,0.08873363,71.56386935423134,1100.0,0.1
0.8912491,0.08913767,71.64544415485256,1100.0,0.1
0.8961708999999999,0.08962985,71.72457622894345,1100.0,0.1
0.899335,0.08994626,71.80336748165182,1100.0,0.1
0.9040257999999999,0.09041534,71.87958363873894,1100.0,0.1
0.9094823,0.09096099,71.959343884023,1100.0,0.1
0.9133549,0.09134825,72.0397220866215,1100.0,0.1
0.9180522999999999,0.09181799,72.12534531129192,1100.0,0.1
0.9219875,0.09221151,72.20897608682603,1100.0,0.1
0.9262776,0.09264052,72.29032347451167,1100.0,0.1
0.9303338,0.09304614,72.36737376457602,1100.0,0.1
0.9356867999999999,0.09358144,72.44298522529952,1100.0,0.1
0.9389822999999999,0.09391099,72.51121959407604,1100.0,0.1
0.9445747,0.09447023,72.5757312019018,1100.0,0.1
0.94858,0.09487076,72.65697415967452,1100.0,0.1
0.9531749,0.09533025,72.72377045116316,1100.0,0.1
0.9568888999999999,0.09570165,72.80311325888285,1100.0,0.1
0.9615472999999999,0.09616749,72.8846606920344,1100.0,0.1
0.9667401999999999,0.09668678,72.95707878617452,1100.0,0.1
0.9704582,0.09705858,73.02720516104574,1100.0,0.1
0.974946,0.09750736,73.08764851873134,1100.0,0.1
0.9789048,0.09790324,73.14679377328815,1100.0,0.1
0.9841643,0.09842919,73.20169489724272,1100.0,0.1
0.9876529000000001,0.09877805,73.27511178951544,1100.0,0.1
0.9931552,0.09932828,73.33377707678817,1100.0,0.1
0.9975345999999999,0.09976622,73.39797152467455,1100.0,0.1
1.0017385,0.10018661,73.46274304066695,1100.0,0.1
1.0062404,0.1006368,73.53156838320105,1100.0,0.1
1.0094992999999999,0.10096269,73.60110216144724,1100.0,0.1
1.0147760000000001,0.10149036,73.66205394283364,1100.0,0.1
1.0180967,0.10182243,73.73063063700408,1100.0,0.1
1.0232002,0.10233278,73.79739761604952,1100.0,0.1
1.0271771,0.10273047,73.86856630728438,1100.0,0.1
1.0320472,0.10321748,73.9324871424624,1100.0,0.1
1.0351956,0.10353232,74.00778213932225,1100.0,0.1
1.0398316,0.10399592,74.0810001036821,1100.0,0.1
1.0448271,0.10449547,74.15553279190182,1100.0,0.1
1.0490509000000001,0.10491785,74.22533969768209,1100.0,0.1
1.0542283,0.10543559,74.29455906801165,1100.0,0.1
1.057504,0.10576316,74.35784995036016,1100.0,0.1
1.0625073,0.10626349,74.42331136114043,1100.0,0.1
1.065904,0.10660316,74.49112829770108,1100.0,0.1
1.0712698,0.10713974,74.55895821213286,1100.0,0.1
1.0751474,0.1075275,74.63547348770483,1100.0,0.1
1.0798019,0.10799295,74.70568753970863,1100.0,0.1
1.0838607,0.10839883,74.77209947998514,1100.0,0.1
1.0882207,0.10883483,74.84246038723892,1100.0,0.1
1.0938379,0.10939655,74.91511134016697,1100.0,0.1
1.0968267,0.10969543,74.98292152821242,1100.0,0.1
1.1023289,0.11024565,75.0499130545344,1100.0,0.1
1.1066365,0.11067641,75.12146780470484,1100.0,0.1
1.1113058,0.11114334,75.18576712483741,1100.0,0.1
1.1143603000000002,0.11144879,75.24793310062532,1100.0,0.1
1.1199922,0.11201198,75.31747162962148,1100.0,0.1
1.1229283,0.11230559,75.37852336777303,1100.0,0.1
1.128565,0.11286926,75.43824204364802,1100.0,0.1
1.1319842,0.11321118,75.49864616770107,1100.0,0.1
1.1370856,0.11372132,75.56174352026545,1100.0,0.1
1.1418892999999999,0.11420169,75.62752311196999,1100.0,0.1
1.1459744,0.1146102,75.69502601042073,1100.0,0.1
1.1502401,0.11503677,75.75878148208363,1100.0,0.1
1.1546292,0.11547568,75.81064331745104,1100.0,0.1
1.1587195000000001,0.11588471,75.86887694263287,1100.0,0.1
1.1632926000000001,0.11634202,75.91653992684121,1100.0,0.1
1.1681089,0.11682365,75.95984257781468,1100.0,0.1
1.1714210999999999,0.11715487,76.01236329472756,1100.0,0.1
1.176,0.11761276,76.07111058989803,1100.0,0.1
1.1799783,0.11801059,76.12992605596241,1100.0,0.1
1.1846818000000001,0.11848094,76.18534841991696,1100.0,0.1
1.189931,0.11900586,76.24053074048895,1100.0,0.1
1.1930696,0.11931972,76.30381323660258,1100.0,0.1
1.1983231,0.11984507,76.363403448398,1100.0,0.1
1.2020073,0.12021349,76.41787406792834,1100.0,0.1
1.2071444,0.1207272,76.47490348731851,1100.0,0.1
1.2105307,0.12106583,76.54516971583743,1100.0,0.1
1.2157934,0.1215921,76.61190186264803,1100.0,0.1
1.2195451000000002,0.12196727,76.67757213104575,1100.0,0.1
1.2243887,0.12245163,76.7330101961556,1100.0,0.1
1.229052,0.12291796,76.79555834292835,1100.0,0.1
1.2326271,0.12327547,76.86559801754954,1100.0,0.1
1.2375985,0.12377261,76.92171400351545,1100.0,0.1
1.2412982000000001,0.12414258,76.9794018726253,1100.0,0.1
1.2466374,0.1246765,77.0349116105003,1100.0,0.1
1.2505222,0.12506498,77.09818818354955,1100.0,0.1
1.2550158,0.12551434,77.15302901684501,1100.0,0.1
1.2584184,0.1258546,77.20678981630333,1100.0,0.1
1.2638281000000002,0.12639557,77.26491582060636,1100.0,0.1
1.268084,0.12682116,77.32215108490182,1100.0,0.1
1.2723429,0.12724705,77.38052805321242,1100.0,0.1
1.2764805000000001,0.12766081,77.43036798737151,1100.0,0.1
1.2815958,0.12817234,77.47951040067076,1100.0,0.1
1.2862858,0.12864134,77.52866780122001,1100.0,0.1
1.2901872,0.12903148,77.5758045130041,1100.0,0.1
1.2946371,0.12947647,77.62284025352682,1100.0,0.1
1.2983579,0.12984855,77.67395856827302,1100.0,0.1
1.3037277,0.13038553,77.7314963203715,1100.0,0.1
1.307452,0.13075796,77.78604968122,1100.0,0.1
1.3116054,0.1311733,77.83430558640939,1100.0,0.1
1.3160041,0.13161317,77.89237322856093,1100.0,0.1
1.3208945,0.13210221,77.93818809305711,1100.0,0.1
1.3259707,0.13260983,77.9814022325306,1100.0,0.1
1.3297031000000001,0.13298307,78.01715122081468,1100.0,0.1
1.3344159,0.13345435,78.05836836902304,1100.0,0.1
1.3379062,0.13380338,78.0973552939359,1100.0,0.1
1.3431149,0.13432425,78.1426391061253,1100.0,0.1
1.346302,0.13464296,78.17959059298137,1100.0,0.1
1.3513898,0.13515174,78.21976772970484,1100.0,0.1
1.3555006,0.13556282,78.27056780754198,1100.0,0.1
1.3602875,0.13604151,78.31350106116318,1100.0,0.1
1.3637869,0.13639145,78.35321034026545,1100.0,0.1
1.3682086,0.13683362,78.38766118109122,1100.0,0.1
1.3735549999999999,0.13736826,78.42125913050033,1100.0,0.1
1.3774895,0.13776171,78.46536079909121,1100.0,0.1
1.382226,0.13823536,78.51788088043214,1100.0,0.1
1.3858552,0.13859828,78.56879067689805,1100.0,0.1
1.3907800000000001,0.13909076,78.62174979536016,1100.0,0.1
1.394229,0.13943566,78.66725908535638,1100.0,0.1
1.4002665,0.14003941,78.70639126442454,1100.0,0.1
1.4031638,0.14032914,78.74627528522758,1100.0,0.1
1.40785,0.14079776,78.78203232108741,1100.0,0.1
1.4118604000000001,0.1411988,78.81804125952682,1100.0,0.1
1.416983,0.14171106,78.85738573120862,1100.0,0.1
1.4221693,0.14222969,78.90135574092832,1100.0,0.1
1.4256905,0.14258181,78.95086905175786,1100.0,0.1
1.4304497,0.14305773,79.00402370887909,1100.0,0.1
1.434592,0.14347196,79.04050845372,1100.0,0.1
1.4394170000000002,0.14395446,79.08448184507607,1100.0,0.1
1.4427588,0.14428864,79.12431328401925,1100.0,0.1
1.4483921,0.14485197,79.15679441089424,1100.0,0.1
1.4517995000000001,0.14519271,79.18909928379576,1100.0,0.1
1.4569427,0.14570703,79.21169083961772,1100.0,0.1
1.4615926000000001,0.14617202,79.2390943070079,1100.0,0.1
1.4651276999999998,0.14652553,79.2733768554435,1100.0,0.1
1.4700289,0.14701565,79.31101318492834,1100.0,0.1
1.473567,0.14736946,79.34743658228818,1100.0,0.1
1.4789700000000001,0.14790976,79.39154723028062,1100.0,0.1
1.4828845,0.14830121,79.42707478882605,1100.0,0.1
1.48767,0.14877976,79.46398066940561,1100.0,0.1
1.490779,0.14909066,79.5037268604662,1100.0,0.1
1.4956311,0.14957587,79.53233441682985,1100.0,0.1
1.4994275,0.14995551,79.56157848752306,1100.0,0.1
1.5045951,0.15047227,79.57933832261016,1100.0,0.1
1.5082072999999998,0.15083349,79.59816965648895,1100.0,0.1
1.5133174999999999,0.15134451,79.61316200160257,1100.0,0.1
1.5183055,0.15184331,79.63017126887154,1100.0,0.1
1.5218606000000001,0.15219882,79.6585645948147,1100.0,0.1
1.5267279,0.15268555,79.69438253579955,1100.0,0.1
1.530473,0.15306006,79.7288736619662,1100.0,0.1
1.5354065000000001,0.15355341,79.75600163520106,1100.0,0.1
1.5388438,0.15389714,79.78816427812531,1100.0,0.1
1.5433436,0.15434712,79.81496971677682,1100.0,0.1
1.5479718,0.15480994,79.85139381871622,1100.0,0.1
1.5529760000000001,0.15531036,79.88201129346999,1100.0,0.1
1.5561686,0.15562962,79.91873473383365,1100.0,0.1
1.5616163,0.15617439,79.95624473229198,1100.0,0.1
1.5661886999999999,0.15663163,79.99594069218591,1100.0,0.1
1.5703886,0.15705162,80.0222044237579,1100.0,0.1
1.5749661000000001,0.15750937,80.04388789307606,1100.0,0.1
1.5786670999999999,0.15787947,80.07079214928063,1100.0,0.1
1.5839381,0.15840657,80.09846651225789,1100.0,0.1
1.5877683,0.15878959,80.13289305627303,1100.0,0.1
1.5926041999999998,0.15927318,80.16389329831092,1100.0,0.1
1.5959976,0.15961252,80.1893382390761,1100.0,0.1
1.6013412999999999,0.16014689,80.20788056582987,1100.0,0.1
1.6050522,0.16051798,80.23616882339047,1100.0,0.1
1.6102746000000001,0.16104022,80.2655567226291,1100.0,0.1
1.6146817,0.16148093,80.28969265861394,1100.0,0.1
1.6185861,0.16187137,80.31473494998895,1100.0,0.1
1.6239419,0.16240695,80.34573061156092,1100.0,0.1
1.6269673000000002,0.16270949,80.36840900734123,1100.0,0.1
1.6323900999999998,0.16325177,80.38600677515943,1100.0,0.1
1.6364289,0.16365565,80.40472889860257,1100.0,0.1
1.6408465,0.16409741,80.42540765073515,1100.0,0.1
1.6446347000000001,0.16447623,80.45107150673516,1100.0,0.1
1.6495621,0.16496897,80.48457874736017,1100.0,0.1
1.6529749,0.16531025,80.50362631067077,1100.0,0.1
1.6580331000000001,0.16581607,80.52656769189048,1100.0,0.1
1.6632832,0.16634108,80.54815054652683,1100.0,0.1
1.6665740000000002,0.16667016,80.56585526943593,1100.0,0.1
1.6721452,0.16722728,80.57155967205335,1100.0,0.1
1.6755658000000002,0.16756934,80.58481229407606,1100.0,0.1
1.6803185,0.16804461,80.59921581043973,1100.0,0.1
1.6840589000000001,0.16841865,80.61958446501168,1100.0,0.1
1.6891956,0.16893232,80.63653000647759,1100.0,0.1
1.6929391999999999,0.16930668,80.65603837706094,1100.0,0.1
1.6978904000000001,0.1698018,80.67139451342454,1100.0,0.1
1.7015731,0.17017007,80.68576326499273,1100.0,0.1
1.7059576,0.17060852,80.70243476977303,1100.0,0.1
1.7111056999999998,0.17112333,80.71515979398136,1100.0,0.1
1.7150478999999998,0.17151755,80.7248428276897,1100.0,0.1
1.7196922000000001,0.17198198,80.73839476376925,1100.0,0.1
1.7235747000000001,0.17237023,80.75995604264423,1100.0,0.1
1.7287317999999998,0.17288594,80.7802112809776,1100.0,0.1
1.7324258000000001,0.17325534,80.8058306084094,1100.0,0.1
1.7373967000000001,0.17375243,80.81402148895108,1100.0,0.1
1.741286,0.17414136,80.82719925074656,1100.0,0.1
1.7465156000000002,0.17466432,80.84167870018592,1100.0,0.1
1.7510477999999998,0.17511754,80.85213375357229,1100.0,0.1
1.7551337,0.17552613,80.85141024207987,1100.0,0.1
1.7595406999999998,0.17596683,80.85195491884502,1100.0,0.1
1.7635020000000001,0.17636296,80.85526792592455,1100.0,0.1
1.7682968,0.17684244,80.85318111643592,1100.0,0.1
1.7723898,0.17725174,80.85524941948896,1100.0,0.1
1.7771877,0.17773153,80.84166045098516,1100.0,0.1
1.7808373,0.17809649,80.83500120651925,1100.0,0.1
1.785704,0.17858316,80.81919977117076,1100.0,0.1
1.7899961,0.17901237,80.8051901511026,1100.0,0.1
1.7944183,0.17945459,80.78827275308744,1100.0,0.1
1.7995485,0.17996761,80.76895958143213,1100.0,0.1
1.8032051,0.18033327,80.75433600026926,1100.0,0.1
1.8082113,0.18083389,80.74189080795487,1100.0,0.1
1.8116138000000002,0.18117414,80.73184133706091,1100.0,0.1
1.8164955,0.18166231,80.71443937545484,1100.0,0.1
1.8194522,0.18195798,80.70400459161394,1100.0,0.1
1.8253017999999999,0.18254294,80.68484463192455,1100.0,0.1
1.8290966,0.18292242,80.66687745683744,1100.0,0.1
1.8343086,0.18344362,80.63933651604957,1100.0,0.1
1.8379791,0.18381067,80.6186228142541,1100.0,0.1
1.8431305,0.18432581,80.60131747222,1100.0,0.1
1.846546,0.18466736,80.5841338623753,1100.0,0.1
1.8513157999999998,0.18514434,80.56921925479956,1100.0,0.1
1.8567976,0.18569252,80.55867859304577,1100.0,0.1
1.859765,0.18598926,80.5486765602541,1100.0,0.1
1.8647354,0.1864863,80.53545532129574,1100.0,0.1
1.8689322,0.18690598,80.52274241776927,1100.0,0.1
1.8733908,0.18735184,80.50909138218593,1100.0,0.1
1.877527,0.18776546,80.50577307896623,1100.0,0.1
1.8830221,0.18831497,80.5050461398829,1100.0,0.1
1.8867747,0.18869023,80.50683443844348,1100.0,0.1
1.890787,0.18909146,80.51344484116318,1100.0,0.1
1.8955135,0.18956411,80.51434823443594,1100.0,0.1
1.899335,0.18994626,80.51581021634502,1100.0,0.1
1.9041954,0.1904323,80.52164424921243,1100.0,0.1
1.9087329,0.19088605,80.53509617170866,1100.0,0.1
1.9134678999999999,0.19135955,80.55009823040184,1100.0,0.1
1.9169721000000002,0.19170997,80.56524923366321,1100.0,0.1
1.9210608000000002,0.19211884,80.57806350741699,1100.0,0.1
1.9259974,0.1926125,80.59095897557607,1100.0,0.1
1.9310653,0.19311929,80.60034168620106,1100.0,0.1
1.9355505000000002,0.19356781,80.60493112357607,1100.0,0.1
1.9393216999999998,0.19394493,80.61653884076547,1100.0,0.1
1.9443319000000001,0.19444595,80.62526986052683,1100.0,0.1
1.9476507,0.19477783,80.64900283209502,1100.0,0.1
1.9526651000000002,0.19527927,80.66190396658367,1100.0,0.1
1.9565732,0.19567008,80.68415613005337,1100.0,0.1
1.9618532,0.19619808,80.704575311417,1100.0,0.1
1.9650471999999999,0.19651748,80.72859999420866,1100.0,0.1
1.9705271,0.19706547,80.75914521104198,1100.0,0.1
1.9752254999999999,0.19753531,80.78831670647003,1100.0,0.1
1.9786866,0.19788142,80.82233544273518,1100.0,0.1
1.9839109,0.19840385,80.84401906348135,1100.0,0.1
1.9870483,0.19871759,80.86465273834881,1100.0,0.1
1.9923433,0.19924709,80.8838507357238,1100.0,0.1
1.9960062,0.19961338,80.89533821133367,1100.0,0.1
2.0012396,0.20013672,80.9049699440117,1100.0,0.1
2.0048408,0.20049684,80.91021312476926,1100.0,0.1
2.0095554,0.2009683,80.92633851172,1100.0,0.1
2.0130933,0.20132209,80.93305804276926,1100.0,0.1
2.0188611,0.20189887,80.94959083961776,1100.0,0.1
2.0236486,0.20237762,80.9601839588488,1100.0,0.1
2.0271252,0.20272528,80.97978363675789,1100.0,0.1
2.0325076,0.20326352,81.00212400907986,1100.0,0.1
2.0361189,0.20362465,81.01909251353061,1100.0,0.1
2.0411779,0.20413055,81.03736656067076,1100.0,0.1
2.0443974000000003,0.2044525,81.05281148103818,1100.0,0.1
2.0489348,0.20490624,81.06742237248515,1100.0,0.1
2.0522885,0.20524161,81.07495216251924,1100.0,0.1
2.0577498999999997,0.20578775,81.07914054376548,1100.0,0.1
2.0630824,0.206321,81.08254832498895,1100.0,0.1
2.0659807999999997,0.20661084,81.09221418161394,1100.0,0.1
2.0721085,0.20722361,81.10478524786018,1100.0,0.1
2.0754712,0.20755988,81.10854352240939,1100.0,0.1
2.0804834,0.2080611,81.11096262182608,1100.0,0.1
2.0839799,0.20841075,81.11858663828065,1100.0,0.1
2.0891286,0.20892562,81.12931173168971,1100.0,0.1
2.0927615999999998,0.20928892,81.13505532512154,1100.0,0.1
2.0975834,0.2097711,81.14534511530336,1100.0,0.1
2.1016155,0.21017431,81.14779473984123,1100.0,0.1
2.1065089,0.21066365,81.14817443521622,1100.0,0.1
2.1112723,0.21113999,81.15456350687911,1100.0,0.1
2.1151773,0.21153049,81.15047132817075,1100.0,0.1
2.1197457,0.21198733,81.15242436473895,1100.0,0.1
2.1238525,0.21239801,81.1534587921253,1100.0,0.1
2.1290881,0.21292157,81.15956818043593,1100.0,0.1
2.1324037000000002,0.21325313,81.15944843335039,1100.0,0.1
2.1373117,0.21374393,81.16767631733217,1100.0,0.1
2.1420232,0.21421508,81.17683349733275,1100.0,0.1
2.1460062,0.21461338,81.18599647056365,1100.0,0.1
2.1509879,0.21511155,81.19424173423636,1100.0,0.1
2.1518515999999996,0.21519792,81.19773163036699,1100.0,0.1