File: datasets/steel_spring/csv/BS2V-1050-0.01.csv
Time(s),Strain(%),Stress(MPa),Temp(C),SR(%/s)
0.0,5.81e-06,0.20489866750649355,1050.0,0.01
0.0005419999999999998,1.123e-05,0.23555591130918202,1050.0,0.01
0.0010739999999999999,1.655e-05,0.24284407439403316,1050.0,0.01
0.0037549999999999997,4.336e-05,0.231309751616099,1050.0,0.01
0.004297,4.878e-05,0.20549953783043165,1050.0,0.01
0.005371,5.952e-05,0.1592128919545461,1050.0,0.01
0.0069770000000000006,7.558e-05,0.09010096390151567,1050.0,0.01
0.007509999999999999,8.091e-05,-0.08245216452083359,1050.0,0.01
0.008042,8.623e-05,-0.11680963680303108,1050.0,0.01
0.009658,0.00010239,0.006263291104165486,1050.0,0.01
0.010732,0.00011313,0.5019175686136372,1050.0,0.01
0.012871,0.00013452,1.3846822647443238,1050.0,0.01
0.015019999999999999,0.00015601,2.605813500032208,1050.0,0.01
0.023605999999999995,0.00024187,4.08885242522729,1050.0,0.01
0.035406,0.00035987,5.7325702545265385,1050.0,0.01
0.037555000000000005,0.00038136,7.386842804200787,1050.0,0.01
0.051506,0.00052087,8.957615354926174,1050.0,0.01
0.062777,0.00063358,10.54906650294701,1050.0,0.01
0.068675,0.00069256,12.148668903107998,1050.0,0.01
0.076723,0.00077304,13.86951269060043,1050.0,0.01
0.089614,0.00090195,15.719068949081496,1050.0,0.01
0.097131,0.00097712,17.65569735302846,1050.0,0.01
0.100889,0.0010147,19.666286777888317,1050.0,0.01
0.112166,0.00112747,21.716044424045524,1050.0,0.01
0.12450900000000001,0.0012509,23.767891936473564,1050.0,0.01
0.13525500000000001,0.00135836,25.78141936150388,1050.0,0.01
0.146536,0.00147117,27.694143079020936,1050.0,0.01
0.162111,0.00162692,29.479629471662992,1050.0,0.01
0.172319,0.001729,31.074550115909208,1050.0,0.01
0.19166,0.00192241,32.448814691318304,1050.0,0.01
0.207786,0.00208367,33.59818733359104,1050.0,0.01
0.21853199999999998,0.00219113,34.518950559064514,1050.0,0.01
0.24218900000000002,0.0024277,35.23768321010238,1050.0,0.01
0.255626,0.00256207,35.79417283339027,1050.0,0.01
0.279826,0.00280407,36.2326619029755,1050.0,0.01
0.293821,0.00294402,36.58268402643385,1050.0,0.01
0.308876,0.00309457,36.89173971981263,1050.0,0.01
0.331477,0.00332058,37.17938328391682,1050.0,0.01
0.346004,0.00346585,37.46443020100962,1050.0,0.01
0.36162,0.00362201,37.76723817962138,1050.0,0.01
0.384768,0.00385349,38.09550517231646,1050.0,0.01
0.39983599999999997,0.00400417,38.467184887460384,1050.0,0.01
0.413848,0.00414429,38.882691646574024,1050.0,0.01
0.43485,0.00435431,39.328292265653566,1050.0,0.01
0.44832199999999994,0.00448903,39.79617680019524,1050.0,0.01
0.47472699999999995,0.00475308,40.27006387966303,1050.0,0.01
0.48766000000000004,0.00488241,40.750545178695226,1050.0,0.01
0.5065179999999999,0.00507099,41.225237313397905,1050.0,0.01
0.5253899999999999,0.00525971,41.688201625932,1050.0,0.01
0.5458799999999999,0.00546461,42.120144118102445,1050.0,0.01
0.5609829999999999,0.00561564,42.52782421131646,1050.0,0.01
0.578784,0.00579365,42.89598189682972,1050.0,0.01
0.6014459999999999,0.00602027,43.22657269428995,1050.0,0.01
0.6192449999999999,0.00619826,43.521916426913066,1050.0,0.01
0.6338229999999999,0.00634404,43.76667777320096,1050.0,0.01
0.6527179999999999,0.00653299,43.9817267775116,1050.0,0.01
0.674852,0.00675433,44.18137611505137,1050.0,0.01
0.692673,0.00693254,44.38165642642826,1050.0,0.01
0.716433,0.00717014,44.5798871896517,1050.0,0.01
0.735344,0.00735925,44.78867644197553,1050.0,0.01
0.754805,0.00755386,44.992283698545606,1050.0,0.01
0.7731769999999999,0.00773758,45.19900878360616,1050.0,0.01
0.7937179999999999,0.00794299,45.40783457432016,1050.0,0.01
0.8164289999999998,0.0081701,45.59559578090731,1050.0,0.01
0.833729,0.0083431,45.77386553901529,1050.0,0.01
0.8510419999999999,0.00851623,45.94739756828423,1050.0,0.01
0.8656439999999999,0.00866225,46.14034210727289,1050.0,0.01
0.887288,0.00887869,46.34133207737522,1050.0,0.01
0.9029799999999999,0.00903561,46.54401174114607,1050.0,0.01
0.9311269999999999,0.00931708,46.72589996889419,1050.0,0.01
0.9479089999999999,0.0094849,46.893064122081704,1050.0,0.01
0.961998,0.00962579,47.062948679362016,1050.0,0.01
0.9874449999999999,0.00988026,47.224365163433994,1050.0,0.01
1.0118230000000001,0.01012404,47.378188169447235,1050.0,0.01
1.025921,0.01026502,47.52300643083729,1050.0,0.01
1.041634,0.01042215,47.67344008074262,1050.0,0.01
1.064939,0.0106552,47.825482406530604,1050.0,0.01
1.084992,0.01085573,47.971271102975685,1050.0,0.01
1.102887,0.01103468,48.086663032024944,1050.0,0.01
1.130004,0.01130585,48.19478866723523,1050.0,0.01
1.138148,0.01138729,48.30230394411781,1050.0,0.01
1.164188,0.01164769,48.40636884101929,1050.0,0.01
1.1810090000000002,0.0118159,48.50102366908734,1050.0,0.01
1.201096,0.01201677,48.58512501443765,1050.0,0.01
1.224977,0.01225558,48.67257780576532,1050.0,0.01
1.241819,0.012424,48.777075320981325,1050.0,0.01
1.264083,0.01264664,48.88270935277111,1050.0,0.01
1.289617,0.01290198,48.98941253870107,1050.0,0.01
1.303195,0.01303776,49.10034279464432,1050.0,0.01
1.325473,0.01326054,49.213084767685984,1050.0,0.01
1.3417830000000002,0.01342364,49.3269360220287,1050.0,0.01
1.3586340000000001,0.01359215,49.444891913693304,1050.0,0.01
1.387999,0.0138858,49.54572656972164,1050.0,0.01
1.40377,0.01404351,49.65287810320651,1050.0,0.01
1.421182,0.01421763,49.775877711814445,1050.0,0.01
1.436957,0.01437538,49.883297199055015,1050.0,0.01
1.463085,0.01463666,49.97861861453612,1050.0,0.01
1.4804970000000002,0.01481078,50.07027061217065,1050.0,0.01
1.501184,0.01501765,50.14731597171241,1050.0,0.01
1.5213340000000002,0.01521915,50.222171362725746,1050.0,0.01
1.54203,0.01542611,50.29449120864804,1050.0,0.01
1.561097,0.01561678,50.35543699723889,1050.0,0.01
1.577986,0.01578567,50.42618936316886,1050.0,0.01
1.600866,0.01601447,50.51066802058549,1050.0,0.01
1.614497,0.01615078,50.60711622360245,1050.0,0.01
1.645029,0.0164561,50.704784498738796,1050.0,0.01
1.66084,0.01661421,50.82760708383354,1050.0,0.01
1.6733860000000003,0.01673967,50.946968038909446,1050.0,0.01
1.701209,0.0170179,51.06704839028078,1050.0,0.01
1.7219320000000002,0.01722513,51.17282906491335,1050.0,0.01
1.7350269999999999,0.01735608,51.272834951922746,1050.0,0.01
1.757953,0.01758534,51.35141948872761,1050.0,0.01
1.77652,0.01777101,51.413723328916944,1050.0,0.01
1.804363,0.01804944,51.47706699196419,1050.0,0.01
1.8152810000000001,0.01815862,51.52997853241116,1050.0,0.01
1.833317,0.01833898,51.57222094966116,1050.0,0.01
1.860633,0.01861214,51.62122493215925,1050.0,0.01
1.879752,0.01880333,51.674968312791925,1050.0,0.01
1.904901,0.01905482,51.74031702421239,1050.0,0.01
1.9212950000000002,0.01921876,51.836109106769136,1050.0,0.01
1.9431680000000002,0.01943749,51.93452125102855,1050.0,0.01
1.961217,0.01961798,52.03618059169528,1050.0,0.01
1.9836519999999997,0.01984233,52.134596851123305,1050.0,0.01
1.999517,0.02000098,52.2203660222956,1050.0,0.01
2.020864,0.02021445,52.29540192804927,1050.0,0.01
2.041653,0.02042234,52.37619416117989,1050.0,0.01
2.0580800000000004,0.02058661,52.43854575967805,1050.0,0.01
2.07615,0.02076731,52.49446021304557,1050.0,0.01
2.099697,0.02100278,52.5563557572311,1050.0,0.01
2.118328,0.02118909,52.61430123219896,1050.0,0.01
2.1413320000000002,0.02141913,52.67793432600014,1050.0,0.01
2.159971,0.02160552,52.734086676009575,1050.0,0.01
2.177505,0.02178086,52.78971149860235,1050.0,0.01
2.197792,0.02198373,52.852428335852494,1050.0,0.01
2.21753,0.02218111,52.92508761897006,1050.0,0.01
2.246594,0.02247175,52.99672882980543,1050.0,0.01
2.264707,0.02265288,53.07510720670331,1050.0,0.01
2.27732,0.02277901,53.15124837824687,1050.0,0.01
2.303658,0.02304239,53.22875250547022,1050.0,0.01
2.320128,0.02320709,53.31001994133363,1050.0,0.01
2.3366010000000004,0.02337182,53.376403607439485,1050.0,0.01
2.3629539999999998,0.02363535,53.43285335871408,1050.0,0.01
2.379989,0.0238057,53.490295392630784,1050.0,0.01
2.398662,0.02399243,53.54769741162515,1050.0,0.01
2.4200850000000003,0.02420666,53.61762992827862,1050.0,0.01
2.439867,0.02440448,53.68378966591126,1050.0,0.01
2.460753,0.02461334,53.75055680013849,1050.0,0.01
2.477249,0.0247783,53.81296999948868,1050.0,0.01
2.500345,0.02500926,53.85023908807764,1050.0,0.01
2.513543,0.02514124,53.88330161540343,1050.0,0.01
2.536648,0.02537229,53.932359642314374,1050.0,0.01
2.5564519999999997,0.02557033,54.0027662940056,1050.0,0.01
2.5713060000000003,0.02571887,54.08635736831248,1050.0,0.01
2.5927759999999997,0.02593357,54.18053679560043,1050.0,0.01
2.612591,0.02613172,54.270947145619466,1050.0,0.01
2.634616,0.02635197,54.36284775677488,1050.0,0.01
2.6566359999999998,0.02657217,54.42985948017653,1050.0,0.01
2.6753709999999997,0.02675952,54.464222334957086,1050.0,0.01
2.700164,0.02700745,54.495175106762204,1050.0,0.01
2.7161429999999998,0.02716724,54.54244328002723,1050.0,0.01
2.7337849999999997,0.02734366,54.593933561099036,1050.0,0.01
2.757488,0.02758069,54.65155487721633,1050.0,0.01
2.775127,0.02775708,54.71377751581085,1050.0,0.01
2.7955360000000002,0.02796117,54.77549621726345,1050.0,0.01
2.818707,0.02819288,54.83163216566136,1050.0,0.01
2.8358090000000002,0.0283639,54.88019294400432,1050.0,0.01
2.854568,0.02855149,54.93836943333959,1050.0,0.01
2.878309,0.0287889,55.00023893524863,1050.0,0.01
2.894864,0.02895445,55.07851378918976,1050.0,0.01
2.913086,0.02913667,55.1636940912502,1050.0,0.01
2.934071,0.02934652,55.2531561493107,1050.0,0.01
2.955061,0.02955642,55.33938248860977,1050.0,0.01
2.9744,0.02974981,55.414917049145814,1050.0,0.01
2.988767,0.02989348,55.48190470855886,1050.0,0.01
3.018615,0.03019196,55.52276353532593,1050.0,0.01
3.035203,0.03035784,55.56534969065351,1050.0,0.01
3.0528910000000002,0.03053472,55.591344661681966,1050.0,0.01
3.075562,0.03076143,55.62255769774263,1050.0,0.01
3.089944,0.03090525,55.66495613665372,1050.0,0.01
3.110417,0.03110998,55.70724595068598,1050.0,0.01
3.129787,0.03130368,55.752921370326064,1050.0,0.01
3.1508179999999997,0.03151399,55.80908351871232,1050.0,0.01
3.172961,0.03173542,55.888673005833475,1050.0,0.01
3.194001,0.03194582,55.98231175314576,1050.0,0.01
3.209509,0.0321009,56.08604482055855,1050.0,0.01
3.2322159999999998,0.03232797,56.18566697192221,1050.0,0.01
3.2510489999999996,0.0325163,56.26435047406044,1050.0,0.01
3.268786,0.03269367,56.32529145451122,1050.0,0.01
3.290956,0.03291537,56.35297757194312,1050.0,0.01
3.3048080000000004,0.03305389,56.3645282820796,1050.0,0.01
3.3303179999999997,0.03330899,56.37945425773133,1050.0,0.01
3.3486190000000002,0.033492,56.40784844544167,1050.0,0.01
3.373019,0.033736,56.461010980144465,1050.0,0.01
3.3918890000000004,0.0339247,56.52129033460103,1050.0,0.01
3.407978,0.03408559,56.58949130132834,1050.0,0.01
3.431291,0.03431872,56.653789501169165,1050.0,0.01
3.453497,0.03454078,56.71626990865005,1050.0,0.01
3.4695970000000003,0.03470178,56.77002497060437,1050.0,0.01
3.489586,0.03490167,56.82371594902854,1050.0,0.01
3.5112550000000002,0.03511836,56.89036572792439,1050.0,0.01
3.534581,0.03535162,56.951452091770854,1050.0,0.01
3.550142,0.03550723,57.0133931262027,1050.0,0.01
3.5684839999999998,0.03569065,57.07659372050785,1050.0,0.01
3.5912719999999996,0.03591853,57.134495435742856,1050.0,0.01
3.6079549999999996,0.03608536,57.19196837127334,1050.0,0.01
3.6274210000000005,0.03628002,57.24185213578471,1050.0,0.01
3.6446620000000003,0.03645243,57.28828122580543,1050.0,0.01
3.671926,0.03672507,57.3336393748506,1050.0,0.01
3.6869460000000003,0.03687527,57.38254014037879,1050.0,0.01
3.708647,0.03709228,57.429102318477156,1050.0,0.01
3.728694,0.03729275,57.473042558899486,1050.0,0.01
3.749852,0.03750433,57.5234744009678,1050.0,0.01
3.7643310000000003,0.03764912,57.57462268809107,1050.0,0.01
3.7888319999999998,0.03789413,57.62908619807242,1050.0,0.01
3.8072169999999996,0.03807798,57.68437226894185,1050.0,0.01
3.8317390000000002,0.0383232,57.744515530256095,1050.0,0.01
3.8467830000000003,0.03847364,57.80706210720452,1050.0,0.01
3.8662959999999997,0.03866877,57.874893008056475,1050.0,0.01
3.889152,0.03889733,57.94140613999967,1050.0,0.01
3.909236,0.03909817,58.00023714808484,1050.0,0.01
3.92708,0.03927661,58.04548629193705,1050.0,0.01
3.948843,0.03949424,58.085050247349734,1050.0,0.01
3.96614,0.03966721,58.11463614879473,1050.0,0.01
3.987347,0.03987928,58.13541489661095,1050.0,0.01
4.009677999999999,0.04010259,58.15321859426057,1050.0,0.01
4.024194,0.04024775,58.18252460571324,1050.0,0.01
4.042623,0.04043204,58.23343047343119,1050.0,0.01
4.06943,0.04070011,58.293555609433525,1050.0,0.01
4.083955,0.04084536,58.37113539397759,1050.0,0.01
4.102395,0.04102976,58.446171822568836,1050.0,0.01
4.116924999999999,0.04117506,58.51997591818789,1050.0,0.01
4.143752999999999,0.04144334,58.584058002683804,1050.0,0.01
4.161083,0.04161664,58.6430101812312,1050.0,0.01
4.182897,0.04183478,58.67668099248877,1050.0,0.01
4.201345,0.04201926,58.71574190344704,1050.0,0.01
4.223167999999999,0.04223749,58.74777075345814,1050.0,0.01
4.243309,0.0424389,58.78915993590125,1050.0,0.01
4.2640199999999995,0.04264601,58.84482804957746,1050.0,0.01
4.281370999999999,0.04281952,58.89846987401702,1050.0,0.01
4.303210999999999,0.04303792,58.94556005817223,1050.0,0.01
4.321126,0.04321707,58.992447664231115,1050.0,0.01
4.342963999999999,0.04343545,59.050556741869784,1050.0,0.01
4.364262,0.04364843,59.089590309676645,1050.0,0.01
4.385543999999999,0.04386125,59.12862997952537,1050.0,0.01
4.402359999999999,0.04402941,59.16776518595753,1050.0,0.01
4.4231039999999995,0.04423685,59.22396685844246,1050.0,0.01
4.443851999999999,0.04444433,59.276170007883806,1050.0,0.01
4.465161,0.04465742,59.327847141730444,1050.0,0.01
4.476940999999999,0.04477522,59.37666180735724,1050.0,0.01
4.502173999999999,0.04502755,59.425175519281304,1050.0,0.01
4.523505999999999,0.04524087,59.48160011172058,1050.0,0.01
4.540335999999999,0.04540917,59.52738900368222,1050.0,0.01
4.5594269999999995,0.04560008,59.56096809363452,1050.0,0.01
4.577954,0.04578535,59.59804892587331,1050.0,0.01
4.5942359999999995,0.04594817,59.64723379923494,1050.0,0.01
4.616143999999999,0.04616725,59.69555157508697,1050.0,0.01
4.642537999999999,0.04643119,59.757039162634605,1050.0,0.01
4.65883,0.04659411,59.81975125258571,1050.0,0.01
4.679059,0.0467964,59.89296975791951,1050.0,0.01
4.704921999999999,0.04705503,59.968529463433114,1050.0,0.01
4.724043999999999,0.04724625,60.04011647778552,1050.0,0.01
4.733034,0.04733615,60.09176398427977,1050.0,0.01
4.763407,0.04763988,60.13198787960349,1050.0,0.01
4.778034,0.04778615,60.16651238216197,1050.0,0.01
4.798286999999999,0.04798868,60.17303425376182,1050.0,0.01
4.820799,0.0482138,60.155083251257835,1050.0,0.01
4.837688999999999,0.0483827,60.14231588930154,1050.0,0.01
4.862454999999999,0.04863036,60.15747044023932,1050.0,0.01
4.876536999999999,0.04877118,60.19439018787779,1050.0,0.01
4.8996249999999995,0.04900206,60.25196334742507,1050.0,0.01
4.919344,0.04919925,60.319424800826575,1050.0,0.01
4.931737,0.04932318,60.38811687409358,1050.0,0.01
4.959352999999999,0.04959934,60.45920646961258,1050.0,0.01
4.976825999999999,0.04977407,60.50786034811837,1050.0,0.01
4.994871,0.04995452,60.531160310978194,1050.0,0.01
5.019676,0.05020257,60.56980909604637,1050.0,0.01
5.031521,0.05032102,60.6304877619062,1050.0,0.01
5.059724999999999,0.05060306,60.69385904306316,1050.0,0.01
5.0777849999999995,0.05078366,60.75702817117289,1050.0,0.01
5.0964089999999995,0.0509699,60.82079699802289,1050.0,0.01
5.118417999999999,0.05118999,60.87992261235791,1050.0,0.01
5.139870999999999,0.05140452,60.93252824964217,1050.0,0.01
5.156254,0.05156835,60.974717085503855,1050.0,0.01
5.178275999999999,0.05178857,61.00929889496783,1050.0,0.01
5.193524,0.05194105,61.052317282357905,1050.0,0.01
5.216696,0.05217277,61.08875169284658,1050.0,0.01
5.2381709999999995,0.05238752,61.10502614575186,1050.0,0.01
5.255121,0.05255702,61.105832237070025,1050.0,0.01
5.277174,0.05277755,61.10987128819902,1050.0,0.01
5.298100999999999,0.05298682,61.12314721214597,1050.0,0.01
5.319592999999999,0.05320174,61.14858779090758,1050.0,0.01
5.338260999999999,0.05338842,61.19660446220089,1050.0,0.01
5.354666999999999,0.05355248,61.255031580965955,1050.0,0.01
5.373341999999999,0.05373923,61.324463493661334,1050.0,0.01
5.392583,0.05393164,61.408106681903924,1050.0,0.01
5.407302,0.05407883,61.484596751383194,1050.0,0.01
5.4344779999999995,0.05435059,61.544772772339506,1050.0,0.01
5.448079,0.0544866,61.59229051171449,1050.0,0.01
5.472996,0.05473577,61.62788499517858,1050.0,0.01
5.488861999999999,0.05489443,61.662748462059085,1050.0,0.01
5.517757,0.05518338,61.691195829149976,1050.0,0.01
5.528537,0.05529118,61.70509526269721,1050.0,0.01
5.554047,0.05554628,61.7298477023355,1050.0,0.01
5.571051,0.05571632,61.778436084833764,1050.0,0.01
5.593175,0.05593756,61.834606412868006,1050.0,0.01
5.610759,0.0561134,61.88589973196475,1050.0,0.01
5.632318,0.05632899,61.93464346812781,1050.0,0.01
5.649908,0.05650489,61.974112577425274,1050.0,0.01
5.667502,0.05668083,61.99030269384386,1050.0,0.01
5.694748999999999,0.0569533,61.989690400343804,1050.0,0.01
5.708949,0.0570953,61.981930597451395,1050.0,0.01
5.733368,0.05733949,61.98364792044508,1050.0,0.01
5.752114,0.05752695,62.00701618038046,1050.0,0.01
5.768598,0.05769179,62.05358941450907,1050.0,0.01
5.790754999999999,0.05791336,62.11535638038008,1050.0,0.01
5.806671,0.05807252,62.19957220252798,1050.0,0.01
5.828272999999999,0.05828854,62.280475597997786,1050.0,0.01
5.851582,0.05852163,62.33997735015879,1050.0,0.01
5.868072,0.05868653,62.37922505461921,1050.0,0.01
5.888547999999999,0.05889129,62.40581413052653,1050.0,0.01
5.910176999999999,0.05910758,62.43553633955311,1050.0,0.01
5.930096,0.05930677,62.46933626715952,1050.0,0.01
5.950009,0.0595059,62.502642656032904,1050.0,0.01
5.971640999999999,0.05972222,62.553649857239265,1050.0,0.01
5.991573,0.05992154,62.61293230594575,1050.0,0.01
6.012072999999999,0.06012654,62.670252103718184,1050.0,0.01
6.034294999999999,0.06034876,62.72064881117033,1050.0,0.01
6.051956,0.06052537,62.74989987053753,1050.0,0.01
6.069055,0.06069636,62.76723732656601,1050.0,0.01
6.091279,0.0609186,62.78869782993362,1050.0,0.01
6.102676,0.06103257,62.81311743677473,1050.0,0.01
6.125482999999999,0.06126064,62.829944800911356,1050.0,0.01
6.152289,0.0615287,62.864652183099,1050.0,0.01
6.165412,0.06165993,62.90014402486037,1050.0,0.01
6.187091,0.06187672,62.946496793382806,1050.0,0.01
6.208774999999999,0.06209356,63.00268979837457,1050.0,0.01
6.227609999999999,0.06228191,63.04698519414712,1050.0,0.01
6.2515789999999996,0.0625216,63.083140042067264,1050.0,0.01
6.267002,0.06267583,63.132452639391175,1050.0,0.01
6.289847,0.06290428,63.184259830501716,1050.0,0.01
6.310408999999999,0.0631099,63.22925035058364,1050.0,0.01
6.328118999999999,0.063287,63.26614586034534,1050.0,0.01
6.349265999999999,0.06349847,63.3037204110422,1050.0,0.01
6.367551,0.06368132,63.34826000378801,1050.0,0.01
6.392142,0.06392723,63.3875136998297,1050.0,0.01
6.408143,0.06408724,63.42080823941144,1050.0,0.01
6.429307999999999,0.06429889,63.44060799113137,1050.0,0.01
6.45219,0.06452771,63.4471040106013,1050.0,0.01
6.468779,0.0646936,63.45309691610929,1050.0,0.01
6.483088999999999,0.0648367,63.453168046163995,1050.0,0.01
6.508845,0.06509426,63.45951492762202,1050.0,0.01
6.529452,0.06530033,63.486002059251945,1050.0,0.01
6.550642,0.06551223,63.54451826152592,1050.0,0.01
6.565531999999999,0.06566113,63.620367278062126,1050.0,0.01
6.5827089999999995,0.0658329,63.70649581749485,1050.0,0.01
6.606773,0.06607354,63.78085201505605,1050.0,0.01
6.625684,0.06626265,63.82698403976437,1050.0,0.01
6.646894999999999,0.06647476,63.85302086858589,1050.0,0.01
6.663515999999999,0.06664097,63.85461457137282,1050.0,0.01
6.693332999999999,0.06693914,63.84965530374699,1050.0,0.01
6.704229,0.0670481,63.849098500827594,1050.0,0.01
6.726025,0.06726606,63.86302064150304,1050.0,0.01
6.746097999999999,0.06746679,63.89820362592588,1050.0,0.01
6.761595999999999,0.06762177,63.951608410311124,1050.0,0.01
6.787423999999999,0.06788005,64.01486558536884,1050.0,0.01
6.8046489999999995,0.0680523,64.09725902362482,1050.0,0.01
6.825886999999999,0.06826468,64.15459153967797,1050.0,0.01
6.844848999999999,0.0684543,64.18735635417416,1050.0,0.01
6.864946,0.06865527,64.2025529228878,1050.0,0.01
6.886207,0.06886788,64.20841459370395,1050.0,0.01
6.9046,0.06905181,64.21227285866203,1050.0,0.01
6.927581,0.06928162,64.21757316791785,1050.0,0.01
6.939654,0.06940235,64.23369064991977,1050.0,0.01
6.964955999999999,0.06965537,64.25862470095568,1050.0,0.01
6.9833539999999985,0.06983935,64.2972817100828,1050.0,0.01
6.998889999999999,0.06999471,64.33390877775877,1050.0,0.01
7.023044999999999,0.07023626,64.35837640813581,1050.0,0.01
7.039738999999999,0.0704032,64.38867740116075,1050.0,0.01
7.0598849999999995,0.07060466,64.41971140175389,1050.0,0.01
7.076576,0.07077157,64.46662358451513,1050.0,0.01
7.104208999999999,0.0710479,64.52495435592962,1050.0,0.01
7.120334999999999,0.07120916,64.5902857913517,1050.0,0.01
7.143947999999999,0.07144529,64.64800580821101,1050.0,0.01
7.160080999999999,0.07160662,64.69691657676412,1050.0,0.01
7.181977,0.07182558,64.73416631163931,1050.0,0.01
7.198687999999999,0.07199269,64.74648909462628,1050.0,0.01
7.216556,0.07217137,64.75226744418181,1050.0,0.01
7.243084,0.07243665,64.74278229127484,1050.0,0.01
7.26096,0.07261541,64.73760623956487,1050.0,0.01
7.279412,0.07279993,64.7573881987921,1050.0,0.01
7.301334,0.07301915,64.78933502287549,1050.0,0.01
7.316336,0.07316917,64.83139850469932,1050.0,0.01
7.342318,0.07342899,64.87213508891516,1050.0,0.01
7.356742999999999,0.07357324,64.91163309788114,1050.0,0.01
7.379254999999999,0.07379836,64.94022726749853,1050.0,0.01
7.3971659999999995,0.07397747,64.9612926272233,1050.0,0.01
7.421417,0.07421998,64.97006660001273,1050.0,0.01
7.438178999999999,0.0743876,64.98534176816601,1050.0,0.01
7.456089999999999,0.07456671,65.0080026512797,1050.0,0.01
7.479197999999999,0.07479779,65.03759944216449,1050.0,0.01
7.494810999999999,0.07495392,65.06701614871048,1050.0,0.01
7.515622,0.07516203,65.09597888796607,1050.0,0.01
7.5370219999999994,0.07537603,65.13391733653069,1050.0,0.01
7.560159,0.0756074,65.17156227287408,1050.0,0.01
7.5798250000000005,0.07580406,65.22636817781168,1050.0,0.01
7.598920999999999,0.07599502,65.28473396277973,1050.0,0.01
7.623232,0.07623813,65.3575074559053,1050.0,0.01
7.636538,0.07637119,65.41566575917953,1050.0,0.01
7.658549,0.0765913,65.45738621125075,1050.0,0.01
7.681128999999999,0.0768171,65.4676653792119,1050.0,0.01
7.703138999999999,0.0770372,65.46894950577146,1050.0,0.01
7.724004,0.07724585,65.45633423413106,1050.0,0.01
7.736164,0.07736745,65.4466372591012,1050.0,0.01
7.762243999999999,0.07762825,65.46556634414328,1050.0,0.01
7.776739999999999,0.07777321,65.50098222303092,1050.0,0.01
7.795872999999999,0.07796454,65.54469449174985,1050.0,0.01
7.821382999999999,0.07821964,65.58437006319882,1050.0,0.01
7.842273,0.07842854,65.62192004788034,1050.0,0.01
7.857932,0.07858513,65.64673876904247,1050.0,0.01
7.874181,0.07874762,65.67183015241481,1050.0,0.01
7.893333,0.07893914,65.69246104164556,1050.0,0.01
7.915389999999999,0.07915971,65.71619167389949,1050.0,0.01
7.940354,0.07940935,65.74553761680134,1050.0,0.01
7.958354999999999,0.07958936,65.78050366137064,1050.0,0.01
7.98159,0.07982171,65.82067950415014,1050.0,0.01
8.000175,0.08000756,65.86327333625823,1050.0,0.01
8.018188,0.08018769,65.91541981310294,1050.0,0.01
8.039695,0.08040276,65.9638213504302,1050.0,0.01
8.054231999999999,0.08054813,66.00093921655215,1050.0,0.01
8.080972,0.08081553,66.02702920357936,1050.0,0.01
8.098422,0.08099003,66.04482120894431,1050.0,0.01
8.120524,0.08121105,66.04706519447251,1050.0,0.01
8.139145999999998,0.08139727,66.04788863341773,1050.0,0.01
8.160091,0.08160672,66.05815378711888,1050.0,0.01
8.175801,0.08176382,66.06916161390699,1050.0,0.01
8.19792,0.08198501,66.09576712540348,1050.0,0.01
8.214224,0.08214805,66.12164321187514,1050.0,0.01
8.231696999999999,0.08232278,66.14615141271075,1050.0,0.01
8.252663,0.08253244,66.15937712396416,1050.0,0.01
8.273052999999999,0.08273634,66.17366980128793,1050.0,0.01
8.300429999999999,0.08301011,66.18185341777846,1050.0,0.01
8.316173,0.08316754,66.20253096516277,1050.0,0.01
8.333073999999998,0.08333655,66.23482146339418,1050.0,0.01
8.348821999999998,0.08349403,66.27483418702911,1050.0,0.01
8.37622,0.08376801,66.32243834302972,1050.0,0.01
8.393142,0.08393723,66.36159201081246,1050.0,0.01
8.415887999999999,0.08416469,66.40959353153407,1050.0,0.01
8.431059,0.0843164,66.45677883562666,1050.0,0.01
8.452656,0.08453237,66.50512645651266,1050.0,0.01
8.472498,0.08473079,66.55831935347611,1050.0,0.01
8.490594999999999,0.08491176,66.6190976349032,1050.0,0.01
8.511035,0.08511616,66.66669072749377,1050.0,0.01
8.53148,0.08532061,66.691357403526,1050.0,0.01
8.552507,0.08553088,66.68052351720647,1050.0,0.01
8.572961,0.08573542,66.64511079948899,1050.0,0.01
8.592825999999999,0.08593407,66.61714934752857,1050.0,0.01
8.615039,0.0861562,66.59716484525195,1050.0,0.01
8.634924,0.08635505,66.5940141379394,1050.0,0.01
8.656554,0.08657135,66.60845536079879,1050.0,0.01
8.674104,0.08674685,66.64439725081338,1050.0,0.01
8.695753,0.08696334,66.68899552459749,1050.0,0.01
8.713892,0.08714473,66.72795309642548,1050.0,0.01
8.732612999999999,0.08733194,66.75552651663077,1050.0,0.01
8.753101999999998,0.08753683,66.76951525522435,1050.0,0.01
8.768906,0.08769487,66.78678929652192,1050.0,0.01
8.78823,0.08788811,66.80547934565672,1050.0,0.01
8.811658,0.08812239,66.84455678200327,1050.0,0.01
8.829234999999999,0.08829816,66.88903513096312,1050.0,0.01
8.852673,0.08853254,66.94507125660863,1050.0,0.01
8.876116999999999,0.08876698,67.019022667216,1050.0,0.01
8.893113999999999,0.08893695,67.09659528097146,1050.0,0.01
8.917149,0.0891773,67.15448524107342,1050.0,0.01
8.930639,0.0893122,67.1748234243821,1050.0,0.01
8.951751,0.08952332,67.1692774751667,1050.0,0.01
8.974043,0.08974624,67.14804059555902,1050.0,0.01
8.991055999999999,0.08991637,67.11905948251929,1050.0,0.01
9.009257999999999,0.09009839,67.09201805129429,1050.0,0.01
9.026869999999999,0.09027451,67.06932052137256,1050.0,0.01
9.052102999999999,0.09052684,67.07818300301086,1050.0,0.01
9.074416999999999,0.09074998,67.11407163095382,1050.0,0.01
9.092041,0.09092622,67.15649633144426,1050.0,0.01
9.107897999999999,0.09108479,67.19754447661273,1050.0,0.01
9.134348999999998,0.0913493,67.22625547605789,1050.0,0.01
9.147857,0.09148438,67.25232238139473,1050.0,0.01
9.173725,0.09174306,67.27050996627847,1050.0,0.01
9.191366,0.09191947,67.29017446410577,1050.0,0.01
9.214295,0.09214876,67.3105311049127,1050.0,0.01
9.233122,0.09233703,67.33549370893158,1050.0,0.01
9.250763,0.09251344,67.36954417369645,1050.0,0.01
9.271358999999999,0.0927194,67.40836230379895,1050.0,0.01
9.292542999999998,0.09293124,67.44594150207772,1050.0,0.01
9.308442,0.09309023,67.47334100802102,1050.0,0.01
9.330814,0.09331395,67.50050715845667,1050.0,0.01
9.348472,0.09349053,67.53364442624421,1050.0,0.01
9.368502999999999,0.09369084,67.55801730003726,1050.0,0.01
9.387944,0.09388525,67.58020292002956,1050.0,0.01
9.412683,0.09413264,67.5948403394859,1050.0,0.01
9.428004999999999,0.09428586,67.61222693941232,1050.0,0.01
9.448637999999999,0.09449219,67.63076711253002,1050.0,0.01
9.471635999999998,0.09472217,67.66368308372905,1050.0,0.01
9.492862999999998,0.09493444,67.69264021047326,1050.0,0.01
9.508784,0.09509365,67.73114237495584,1050.0,0.01
9.531794999999999,0.09532376,67.77058704099106,1050.0,0.01
9.545955,0.09546536,67.79876636146179,1050.0,0.01
9.569562,0.09570143,67.82579299426645,1050.0,0.01
9.587858999999998,0.0958844,67.8465979138195,1050.0,0.01
9.608524,0.09609105,67.85617450719703,1050.0,0.01
9.628597,0.09629178,67.85315945926259,1050.0,0.01
9.652223,0.09652804,67.84569454247169,1050.0,0.01
9.666997,0.09667578,67.83258889051767,1050.0,0.01
9.692402,0.09692983,67.82828275999874,1050.0,0.01
9.709537,0.09710118,67.83489599587917,1050.0,0.01
9.72786,0.09728441,67.84781167678634,1050.0,0.01
9.74737,0.09747951,67.86963954506102,1050.0,0.01
9.763341999999998,0.09763923,67.9025223185005,1050.0,0.01
9.788174,0.09788755,67.95149073720727,1050.0,0.01
9.808294,0.09808875,68.01500197862984,1050.0,0.01
9.826037,0.09826618,68.08292784116779,1050.0,0.01
9.841422999999999,0.09842004,68.14102659417323,1050.0,0.01
9.864511,0.09865092,68.1867268867995,1050.0,0.01
9.887595999999998,0.09888177,68.20892971446783,1050.0,0.01
9.909509,0.0991009,68.20142298805895,1050.0,0.01
9.925495999999999,0.09926077,68.16452012802336,1050.0,0.01
9.948604,0.09949185,68.12761642681359,1050.0,0.01
9.968746,0.09969327,68.11362905510364,1050.0,0.01
9.986528,0.09987109,68.1275281498915,1050.0,0.01
10.006676999999998,0.10007258,68.15623981947698,1050.0,0.01
10.021503,0.10022084,68.19167315213224,1050.0,0.01
10.045221999999999,0.10045803,68.24314393678486,1050.0,0.01
10.060042,0.10060623,68.28607538941509,1050.0,0.01
10.087335,0.10087916,68.31654310953203,1050.0,0.01
10.109281999999999,0.10109863,68.33459689629697,1050.0,0.01
10.121746,0.10122327,68.35222558692048,1050.0,0.01
10.142522,0.10143103,68.37283036625752,1050.0,0.01
10.160335,0.10160916,68.38873150300356,1050.0,0.01
10.186454999999999,0.10187036,68.39817536725954,1050.0,0.01
10.203686999999999,0.10204268,68.40906956693024,1050.0,0.01
10.22091,0.10221491,68.42122559557409,1050.0,0.01
10.242886,0.10243467,68.43107816064033,1050.0,0.01
10.263687999999998,0.10264269,68.4423171373903,1050.0,0.01
10.282713,0.10283294,68.45322957819171,1050.0,0.01
10.303512,0.10304093,68.46733751709183,1050.0,0.01
10.324926,0.10325507,68.4957572177617,1050.0,0.01
10.340978999999999,0.1034156,68.53890104474185,1050.0,0.01
10.360009,0.1036059,68.57590699441354,1050.0,0.01
10.383218,0.10383799,68.60920690311991,1050.0,0.01
10.403447,0.10404028,68.6407154963514,1050.0,0.01
10.422498999999998,0.1042308,68.66729003588806,1050.0,0.01
10.441543,0.10442124,68.69375942900061,1050.0,0.01
10.462385999999999,0.10462967,68.70601955814901,1050.0,0.01
10.482631,0.10483212,68.70002494793334,1050.0,0.01
10.499312,0.10499893,68.68678341856757,1050.0,0.01
10.520768,0.10521349,68.67530351087228,1050.0,0.01
10.540434,0.10541015,68.66030974338713,1050.0,0.01
10.563083,0.10563664,68.66111786330771,1050.0,0.01
10.583348999999998,0.1058393,68.68526252199186,1050.0,0.01
10.601239999999999,0.10601821,68.71920233824022,1050.0,0.01
10.619124,0.10619705,68.77097979795052,1050.0,0.01
10.645376,0.10645957,68.8157754167341,1050.0,0.01
10.664462,0.10665043,68.84479083222799,1050.0,0.01
10.678191,0.10678772,68.8576211566689,1050.0,0.01
10.708032999999999,0.10708614,68.86083709917783,1050.0,0.01
10.725354999999999,0.10725936,68.87280772423824,1050.0,0.01
10.745061,0.10745642,68.87895068970462,1050.0,0.01
10.763574,0.10764155,68.88845284822037,1050.0,0.01
10.78567,0.10786251,68.90662672256363,1050.0,0.01
10.801808,0.10802389,68.93814397278915,1050.0,0.01
10.817938,0.10818519,68.97067747218705,1050.0,0.01
10.838255,0.10838836,69.0083120076421,1050.0,0.01
10.866355,0.10866936,69.04151891244683,1050.0,0.01
10.8831,0.10883681,69.06247912982468,1050.0,0.01
10.905232,0.10905813,69.08147686722337,1050.0,0.01
10.923171,0.10923752,69.08298327897516,1050.0,0.01
10.939331,0.10939912,69.08046704483309,1050.0,0.01
10.960873,0.10961454,69.08182594198635,1050.0,0.01
10.974036,0.10974617,69.07970158033885,1050.0,0.01
11.005771,0.11006352,69.09187724749289,1050.0,0.01
11.020140999999999,0.11020722,69.11350164351458,1050.0,0.01
11.046486,0.11047067,69.14337849887109,1050.0,0.01
11.061466999999999,0.11062048,69.16921594634825,1050.0,0.01
11.07764,0.11078221,69.1901637230578,1050.0,0.01
11.098019999999998,0.11098601,69.20994945757431,1050.0,0.01
11.125587,0.11126168,69.2209508640248,1050.0,0.01
11.144170999999998,0.11144752,69.21067066532719,1050.0,0.01
11.160366999999999,0.11160948,69.19934220260899,1050.0,0.01
11.181348999999999,0.1118193,69.19875763053332,1050.0,0.01
11.205346,0.11205927,69.20694450369652,1050.0,0.01
11.223348999999999,0.1122393,69.23546209393359,1050.0,0.01
11.244950999999999,0.11245532,69.27185423065767,1050.0,0.01
11.264163,0.11264744,69.30563393383211,1050.0,0.01
11.283976,0.11284557,69.33987234844989,1050.0,0.01
11.30078,0.11301361,69.35990644396519,1050.0,0.01
11.324208,0.11324789,69.36757699973798,1050.0,0.01
11.33922,0.11339801,69.38109083140857,1050.0,0.01
11.360857999999999,0.11361439,69.3883618992742,1050.0,0.01
11.379486,0.11380067,69.3962504846457,1050.0,0.01
11.401121,0.11401702,69.40860568253937,1050.0,0.01
11.416154999999998,0.11416736,69.42655564437412,1050.0,0.01
11.441400999999999,0.11441982,69.44453881223265,1050.0,0.01
11.459446999999999,0.11460028,69.45704552959363,1050.0,0.01
11.475693999999999,0.11476275,69.47582016436309,1050.0,0.01
11.500955,0.11501536,69.51145234609703,1050.0,0.01
11.519012,0.11519593,69.54933948764784,1050.0,0.01
11.537071,0.11537652,69.57312064081854,1050.0,0.01
11.555124,0.11555705,69.59709092596411,1050.0,0.01
11.580416,0.11580997,69.62932055795206,1050.0,0.01
11.602095,0.11602676,69.65210639962123,1050.0,0.01
11.618364999999999,0.11618946,69.67760249516321,1050.0,0.01
11.635834999999998,0.11636416,69.68381039840997,1050.0,0.01
11.654513999999999,0.11655095,69.68774820125141,1050.0,0.01
11.675611,0.11676192,69.68519752772079,1050.0,0.01
11.691882999999999,0.11692464,69.66961822744057,1050.0,0.01
11.720820999999999,0.11721402,69.64272387504596,1050.0,0.01
11.733498999999998,0.1173408,69.6200341850602,1050.0,0.01
11.76184,0.11762421,69.61165861385534,1050.0,0.01
11.780542,0.11781123,69.60174737185218,1050.0,0.01
11.798649,0.1179923,69.61178781445236,1050.0,0.01
11.81676,0.11817341,69.61795669798684,1050.0,0.01
11.837280999999999,0.11837862,69.63179984309363,1050.0,0.01
11.857206999999999,0.11857788,69.65432416463013,1050.0,0.01
11.876539,0.1187712,69.6863224863279,1050.0,0.01
11.901901,0.11902482,69.73542991896004,1050.0,0.01
11.909149999999999,0.11909731,69.78599753976349,1050.0,0.01
11.938761999999999,0.11939343,69.8390436360735,1050.0,0.01
11.958708999999999,0.1195929,69.89098659135934,1050.0,0.01
11.976849,0.1197743,69.93706257069901,1050.0,0.01
11.995591,0.11996172,69.96461277262114,1050.0,0.01
12.014338,0.12014919,69.9687957881842,1050.0,0.01
12.036111,0.12036692,69.96215832194636,1050.0,0.01
12.060913999999999,0.12061495,69.93896627497848,1050.0,0.01
12.076657999999998,0.12077239,69.91680225004052,1050.0,0.01
12.095408999999998,0.1209599,69.8966916069108,1050.0,0.01
12.114184999999999,0.12114766,69.88554875709843,1050.0,0.01
12.14022,0.12140801,69.89745502256866,1050.0,0.01
12.160808,0.12161389,69.92040094565418,1050.0,0.01
12.17353,0.12174111,69.94744670122316,1050.0,0.01
12.202007,0.12202588,69.97480458132918,1050.0,0.01
12.215335,0.12215916,70.0003738098423,1050.0,0.01
12.231093999999999,0.12231675,70.0080966919307,1050.0,0.01
12.258986,0.12259567,70.01014321656552,1050.0,0.01
12.277781,0.12278362,70.00545676592787,1050.0,0.01
12.299612,0.12300193,69.99927604805094,1050.0,0.01
12.316598999999998,0.1231718,70.00309295378742,1050.0,0.01
12.33419,0.12334771,70.01967470909933,1050.0,0.01
12.356033,0.12356614,70.04934761169733,1050.0,0.01
12.373029999999998,0.12373611,70.10098322906643,1050.0,0.01
12.397915999999999,0.12398497,70.15358163579019,1050.0,0.01
12.415533,0.12416114,70.20269438224707,1050.0,0.01
12.436177,0.12436758,70.23649114418654,1050.0,0.01
12.456826,0.12457407,70.2450062786799,1050.0,0.01
12.477479,0.1247806,70.23628482138503,1050.0,0.01
12.497544,0.12498125,70.20970220534,1050.0,0.01
12.513346999999998,0.12513928,70.17728201600312,1050.0,0.01
12.537049999999999,0.12537631,70.16337225261982,1050.0,0.01
12.554075999999998,0.12554657,70.16786920050393,1050.0,0.01
12.582049,0.1258263,70.18667065651684,1050.0,0.01
12.596043,0.12596624,70.21423389591989,1050.0,0.01
12.613078999999997,0.1261366,70.2336130143935,1050.0,0.01
12.638641,0.12639222,70.23875439775982,1050.0,0.01
12.661769,0.1266235,70.22696636048039,1050.0,0.01
12.677598,0.12678179,70.2034271243827,1050.0,0.01
12.695253,0.12695834,70.17644021254388,1050.0,0.01
12.712307,0.12712888,70.17019489026154,1050.0,0.01
12.736673999999999,0.12737255,70.18832354052873,1050.0,0.01
12.755559999999997,0.12756141,70.22500857525415,1050.0,0.01
12.779319,0.127799,70.26868371309418,1050.0,0.01
12.795167000000001,0.12795748,70.31346813089488,1050.0,0.01
12.807970000000001,0.12808551,70.3595179295789,1050.0,0.01
12.831138,0.12831719,70.3950835291042,1050.0,0.01
12.855532999999998,0.12856114,70.41705703454981,1050.0,0.01
12.878713,0.12879294,70.42989029826012,1050.0,0.01
12.892749,0.1289333,70.44096518825408,1050.0,0.01
12.911664,0.12912245,70.44503007782043,1050.0,0.01
12.934249999999999,0.12934831,70.44574671459439,1050.0,0.01
12.953173,0.12953754,70.43671817456539,1050.0,0.01
12.974535,0.12975116,70.43289150765082,1050.0,0.01
12.991031,0.12991612,70.43088398821556,1050.0,0.01
13.012412,0.13012993,70.43333924576909,1050.0,0.01
13.032573999999999,0.13033155,70.4310092186626,1050.0,0.01
13.050897999999998,0.13051479,70.43859267687563,1050.0,0.01
13.076571,0.13077152,70.45040003324817,1050.0,0.01
13.094296999999997,0.13094878,70.4546101636107,1050.0,0.01
13.118149,0.1311873,70.45707794749444,1050.0,0.01
13.133431999999999,0.13134013,70.45877061627112,1050.0,0.01
13.152403999999999,0.13152985,70.47783606652779,1050.0,0.01
13.174426999999998,0.13175008,70.49317926134863,1050.0,0.01
13.192169999999999,0.13192751,70.52168467690933,1050.0,0.01
13.218486,0.13219067,70.56265131497734,1050.0,0.01
13.235022,0.13235603,70.60923114540687,1050.0,0.01
13.251551,0.13252132,70.65084073395468,1050.0,0.01
13.273594,0.13274175,70.67435253119659,1050.0,0.01
13.290128,0.13290709,70.6726565737938,1050.0,0.01
13.3128,0.13313381,70.66450737278645,1050.0,0.01
13.336694000000001,0.13337275,70.64197019306297,1050.0,0.01
13.352021999999998,0.13352603,70.60648281316294,1050.0,0.01
13.379608,0.13380189,70.5796060776987,1050.0,0.01
13.391878,0.13392459,70.56210051544726,1050.0,0.01
13.415790999999999,0.13416372,70.5529284269001,1050.0,0.01
13.434197,0.13434778,70.54926517027606,1050.0,0.01
13.455673,0.13456254,70.54682552790477,1050.0,0.01
13.472856999999998,0.13473438,70.5495482592748,1050.0,0.01
13.489423999999998,0.13490005,70.5551012114292,1050.0,0.01
13.513369999999998,0.13513951,70.55904017239224,1050.0,0.01
13.530553,0.13531134,70.57339431050691,1050.0,0.01
13.554510999999998,0.13555092,70.60446266278014,1050.0,0.01
13.576001,0.13576582,70.64471872347315,1050.0,0.01
13.590755,0.13591336,70.69366909335982,1050.0,0.01
13.611033999999998,0.13611615,70.7428423217347,1050.0,0.01
13.639912,0.13640493,70.78440565241293,1050.0,0.01
13.653445,0.13654026,70.80616905557814,1050.0,0.01
13.669431,0.13670012,70.80024392010907,1050.0,0.01
13.692801000000001,0.13693382,70.77746672103447,1050.0,0.01
13.710636,0.13711217,70.74622077573721,1050.0,0.01
13.738932,0.13739513,70.71712213396717,1050.0,0.01
13.758631000000001,0.13759212,70.68046969347496,1050.0,0.01
13.778322,0.13778903,70.65612059601847,1050.0,0.01
13.793107000000001,0.13793688,70.64196278574849,1050.0,0.01
13.814648,0.13815229,70.64196949176917,1050.0,0.01
13.837439,0.1383802,70.64656126691541,1050.0,0.01
13.852221,0.13852802,70.66625502295312,1050.0,0.01
13.876255,0.13876836,70.70245343376719,1050.0,0.01
13.895357999999998,0.13895939,70.74704052934995,1050.0,0.01
13.919391,0.13919972,70.80723630758206,1050.0,0.01
13.926175,0.13926756,70.8514047254418,1050.0,0.01
13.957004,0.13957585,70.8739255997441,1050.0,0.01
13.977969,0.1397855,70.87049782851842,1050.0,0.01
13.994631,0.13995212,70.85511789106725,1050.0,0.01
14.018688000000001,0.14019269,70.82698950755902,1050.0,0.01
14.0298,0.14030381,70.7977535868663,1050.0,0.01
14.05078,0.14051361,70.78060033174255,1050.0,0.01
14.076099,0.1407668,70.76875750310042,1050.0,0.01
14.099562,0.14100143,70.76705724727225,1050.0,0.01
14.117471,0.14118052,70.76255076458749,1050.0,0.01
14.134145,0.14134726,70.75656727617186,1050.0,0.01
14.151447,0.14152028,70.76146899027214,1050.0,0.01
14.169364,0.14169945,70.76939479215268,1050.0,0.01
14.190996999999998,0.14191578,70.77802059217339,1050.0,0.01
14.213875,0.14214456,70.79822894899614,1050.0,0.01
14.231804,0.14232385,70.82737773682972,1050.0,0.01
14.254691,0.14255272,70.85909010697395,1050.0,0.01
14.27324,0.14273821,70.88769912572438,1050.0,0.01
14.294896999999999,0.14295478,70.90630419692036,1050.0,0.01
14.313465999999998,0.14314047,70.92835112431366,1050.0,0.01
14.333891,0.14334472,70.95356945980592,1050.0,0.01
14.356175,0.14356756,70.95823598748741,1050.0,0.01
14.372274,0.14372855,70.94049471713154,1050.0,0.01
14.393327,0.14393908,70.90927365780817,1050.0,0.01
14.414396,0.14414977,70.86033508777777,1050.0,0.01
14.430503999999999,0.14431085,70.81720059868496,1050.0,0.01
14.452183,0.14452764,70.78630137365577,1050.0,0.01
14.466442,0.14467023,70.77773137166876,1050.0,0.01
14.491865,0.14492446,70.78556025122619,1050.0,0.01
14.508602,0.14509183,70.80909089059955,1050.0,0.01
14.525967999999999,0.14526549,70.84198611727325,1050.0,0.01
14.545194999999998,0.14545776,70.87952953441032,1050.0,0.01
14.576215,0.14576796,70.9004235703277,1050.0,0.01
14.589863,0.14590444,70.9103395369428,1050.0,0.01
14.610972999999998,0.14611554,70.92268119262022,1050.0,0.01
14.628972,0.14629553,70.93194022748243,1050.0,0.01
14.649463,0.14650044,70.95206823659952,1050.0,0.01
14.674923,0.14675504,70.96385778187822,1050.0,0.01
14.689829,0.1469041,70.97159937576274,1050.0,0.01
14.70847,0.14709051,70.99163439728792,1050.0,0.01
14.731455,0.14732036,71.01453332948684,1050.0,0.01
14.750732999999999,0.14751314,71.02768432496491,1050.0,0.01
14.772482,0.14773063,71.03304636205672,1050.0,0.01
14.783062,0.14783643,71.01358947304632,1050.0,0.01
14.812291999999998,0.14812873,70.972421782311,1050.0,0.01
14.8297,0.14830281,70.92427555953802,1050.0,0.01
14.851475999999998,0.14852057,70.87478432347896,1050.0,0.01
14.871395999999999,0.14871977,70.83157863155252,1050.0,0.01
14.895046999999998,0.14895628,70.80198905969077,1050.0,0.01
14.906874,0.14907455,70.8044029990087,1050.0,0.01
14.927422,0.14928003,70.8283193361838,1050.0,0.01
14.947973,0.14948554,70.86110197595924,1050.0,0.01
14.971642000000001,0.14972223,70.88498291874365,1050.0,0.01
14.978488,0.14979069,70.89914259383751,1050.0,0.01
15.007776,0.15008357,70.90769879213083,1050.0,0.01
15.032089000000001,0.1503267,70.90895025799001,1050.0,0.01
15.058894999999998,0.15059476,70.89810085461363,1050.0,0.01
15.075107000000001,0.15075688,70.88361011004073,1050.0,0.01
15.092573,0.15093154,70.87914095717025,1050.0,0.01
15.114406999999998,0.15114988,70.87847443849076,1050.0,0.01
15.131867,0.15132448,70.8717138365377,1050.0,0.01
15.151842,0.15152423,70.87134529431962,1050.0,0.01
15.17244,0.15173021,70.8613155111926,1050.0,0.01
15.195532,0.15196113,70.86324060600731,1050.0,0.01
15.214267999999999,0.15214849,70.86780289446467,1050.0,0.01
15.226764999999999,0.15227346,70.86144898503623,1050.0,0.01
15.254242999999999,0.15254824,70.86293269343709,1050.0,0.01
15.269235,0.15269816,70.87344652128796,1050.0,0.01
15.292362,0.15292943,70.88393854351055,1050.0,0.01
15.313608,0.15314189,70.90994985464302,1050.0,0.01
15.332366999999998,0.15332948,70.95405122469813,1050.0,0.01
15.354875,0.15355456,71.02098886049816,1050.0,0.01
15.373641000000001,0.15374222,71.11550896886537,1050.0,0.01