File: datasets/steel_spring/csv/BS2V-1000-1.0.csv
Time(s),Strain(%),Stress(MPa),Temp(C),SR(%/s)
0.0,8.233e-05,0.43342352948504304,1000.0,1.0
1.0754999999999994e-05,9.3085e-05,0.2172079008909244,1000.0,1.0
2.150999999999999e-05,0.00010384,-0.00778398328695451,1000.0,1.0
2.417499999999999e-05,0.000106505,-0.01927099966333523,1000.0,1.0
2.6839999999999994e-05,0.00010917,0.4050279751470406,1000.0,1.0
5.904999999999999e-05,0.00014138,1.9493639212272813,1000.0,1.0
9.125999999999999e-05,0.00017359,4.289044533025584,1000.0,1.0
0.00029265499999999996,0.000374985,7.834027445954571,1000.0,1.0
0.00049405,0.00057638,12.654919734080536,1000.0,1.0
0.0007411949999999999,0.000823525,18.576861448083402,1000.0,1.0
0.0009883399999999999,0.00107067,25.582705024667707,1000.0,1.0
0.00124633,0.00132866,33.154707490386485,1000.0,1.0
0.00150432,0.00158665,41.08598749284484,1000.0,1.0
0.001845875,0.0019282050000000001,48.73769068835625,1000.0,1.0
0.00218743,0.00226976,55.77974483667257,1000.0,1.0
0.002717665,0.002799995,61.78172141903055,1000.0,1.0
0.0032479,0.00333023,66.61984949206276,1000.0,1.0
0.003918955,0.004001285,70.3050073967806,1000.0,1.0
0.004590009999999999,0.00467234,72.98684532938289,1000.0,1.0
0.005288915,0.005371245,74.99008503816698,1000.0,1.0
0.00598782,0.00607015,76.4936578463393,1000.0,1.0
0.00661198,0.00669431,77.79049588738665,1000.0,1.0
0.007236139999999999,0.00731847,78.94678365648514,1000.0,1.0
0.007904455,0.007986785,80.0601055924624,1000.0,1.0
0.00857277,0.0086551,81.13733231481186,1000.0,1.0
0.00919855,0.00928088,82.18627862694726,1000.0,1.0
0.00982433,0.00990666,83.20391962214896,1000.0,1.0
0.010459069999999999,0.0105414,84.19495875390939,1000.0,1.0
0.011093809999999999,0.01117614,85.16502660873991,1000.0,1.0
0.011707579999999999,0.01178991,86.11468418778816,1000.0,1.0
0.01232135,0.01240368,87.04871077949839,1000.0,1.0
0.012938680000000001,0.01302101,87.96601774274278,1000.0,1.0
0.01355601,0.01363834,88.86064680662538,1000.0,1.0
0.014187665,0.014269995,89.73240140523525,1000.0,1.0
0.01481932,0.01490165,90.58338133262635,1000.0,1.0
0.01546812,0.01555045,91.4086072953867,1000.0,1.0
0.01611692,0.01619925,92.20800736131663,1000.0,1.0
0.016709245,0.016791575,92.98824930962908,1000.0,1.0
0.017301570000000002,0.0173839,93.75588069971806,1000.0,1.0
0.01795198,0.018034309999999998,94.51230803317456,1000.0,1.0
0.01860239,0.01868472,95.2513842365117,1000.0,1.0
0.01922633,0.01930866,95.97089409007609,1000.0,1.0
0.019850270000000003,0.0199326,96.68311113168694,1000.0,1.0
0.020491405000000004,0.020573735000000003,97.38630178493219,1000.0,1.0
0.021132540000000002,0.02121487,98.0672720667408,1000.0,1.0
0.021766235000000002,0.021848565,98.72044007799266,1000.0,1.0
0.022399930000000002,0.02248226,99.35068164099174,1000.0,1.0
0.023028965000000002,0.023111295,99.96211525905338,1000.0,1.0
0.023658000000000002,0.02374033,100.5537855174692,1000.0,1.0
0.024274080000000003,0.024356410000000002,101.12647364028841,1000.0,1.0
0.02489016,0.02497249,101.68540483623066,1000.0,1.0
0.025515250000000003,0.02559758,102.2439914134172,1000.0,1.0
0.02614034,0.02622267,102.80520622108473,1000.0,1.0
0.02678,0.02686233,103.36190081576545,1000.0,1.0
0.027419660000000002,0.02750199,103.91306149829099,1000.0,1.0
0.028038015,0.028120344999999998,104.45945040366699,1000.0,1.0
0.02865637,0.0287387,105.00153852587351,1000.0,1.0
0.02928936,0.02937169,105.53296010588679,1000.0,1.0
0.02992235,0.03000468,106.04616123075621,1000.0,1.0
0.030558890000000002,0.03064122,106.5386866045611,1000.0,1.0
0.031195430000000003,0.03127776,107.01630448945784,1000.0,1.0
0.031852195,0.031934525000000005,107.48688435056857,1000.0,1.0
0.03250896,0.03259129,107.95342003377405,1000.0,1.0
0.033108325,0.033190655,108.41392361726548,1000.0,1.0
0.03370769,0.03379002,108.86523482368584,1000.0,1.0
0.034371675000000004,0.034454004999999996,109.31299684014417,1000.0,1.0
0.03503566,0.03511799,109.76293097164233,1000.0,1.0
0.035664315,0.035746645,110.20843735889444,1000.0,1.0
0.03629297,0.0363753,110.64051017649602,1000.0,1.0
0.03692242,0.03700475,111.0634103481979,1000.0,1.0
0.03755187,0.0376342,111.48867073169339,1000.0,1.0
0.038193340000000006,0.03827567,111.9164771909482,1000.0,1.0
0.038834810000000004,0.03891714,112.33656221915646,1000.0,1.0
0.039471455,0.039553785,112.74589465518277,1000.0,1.0
0.0401081,0.04019043,113.15697967582746,1000.0,1.0
0.040717595,0.040799925,113.57187325834143,1000.0,1.0
0.041327090000000004,0.04140942,113.97841336331085,1000.0,1.0
0.041993375,0.042075705000000005,114.36548550253804,1000.0,1.0
0.04265966,0.04274199,114.73597804059683,1000.0,1.0
0.043273495,0.043355825,115.0992285409247,1000.0,1.0
0.04388733,0.04396966,115.45450798862468,1000.0,1.0
0.04453288,0.04461521,115.79930761956116,1000.0,1.0
0.04517843,0.04526076,116.14064226565303,1000.0,1.0
0.04582476,0.04590709,116.48794799330355,1000.0,1.0
0.04647109,0.04655342,116.84067561953543,1000.0,1.0
0.047056285,0.047138614999999995,117.19268833956849,1000.0,1.0
0.04764148,0.04772381,117.5408452260838,1000.0,1.0
0.04831484,0.04839717,117.8806072398644,1000.0,1.0
0.0489882,0.04907053,118.21060846049531,1000.0,1.0
0.049591825000000006,0.049674155,118.53145169206165,1000.0,1.0
0.05019545,0.05027778,118.84200281517128,1000.0,1.0
0.050828105,0.050910435000000004,119.144931333796,1000.0,1.0
0.05146076,0.05154309,119.44558735594163,1000.0,1.0
0.052082885,0.052165215,119.74851911437158,1000.0,1.0
0.052705010000000004,0.05278734,120.05579543957631,1000.0,1.0
0.053327910000000006,0.05341024,120.3652696026598,1000.0,1.0
0.05395081,0.05403314,120.66991591071198,1000.0,1.0
0.054543265,0.054625595,120.96999902973566,1000.0,1.0
0.05513572,0.05521805,121.27203841761923,1000.0,1.0
0.055751575,0.055833905,121.57262716012961,1000.0,1.0
0.05636743,0.05644976,121.86801425935091,1000.0,1.0
0.05698128,0.05706361,122.15908658622759,1000.0,1.0
0.05759513,0.05767746,122.44732114374185,1000.0,1.0
0.058221085000000006,0.058303415,122.7329964864325,1000.0,1.0
0.05884704,0.05892937,123.01121371856058,1000.0,1.0
0.0594567,0.05953903,123.28030415309941,1000.0,1.0
0.06006636,0.06014869,123.5471515156003,1000.0,1.0
0.060659569999999996,0.0607419,123.82072859160668,1000.0,1.0
0.06125278,0.06133511,124.10433442499004,1000.0,1.0
0.061895309999999995,0.06197764,124.38987068402298,1000.0,1.0
0.06253784,0.06262017,124.66858975790906,1000.0,1.0
0.063138295,0.063220625,124.94081254271198,1000.0,1.0
0.06373875,0.06382108,125.20897757121038,1000.0,1.0
0.06436283,0.06444516,125.470301913781,1000.0,1.0
0.06498691,0.06506924,125.72384335579083,1000.0,1.0
0.06557734999999999,0.06565968,125.97268265613734,1000.0,1.0
0.06616778999999999,0.06625012,126.21823569876226,1000.0,1.0
0.06679053499999998,0.066872865,126.47042703532665,1000.0,1.0
0.06741327999999999,0.06749561,126.7359695388039,1000.0,1.0
0.06803680499999999,0.068119135,127.0058605001597,1000.0,1.0
0.06866032999999999,0.06874266,127.27380563692074,1000.0,1.0
0.06926733499999999,0.069349665,127.54236687397002,1000.0,1.0
0.06987434,0.06995667,127.81201890587245,1000.0,1.0
0.07046190499999999,0.070544235,128.07716442934884,1000.0,1.0
0.07104946999999999,0.0711318,128.33418286680526,1000.0,1.0
0.07167526499999999,0.07175759500000001,128.58077414742445,1000.0,1.0
0.07230106,0.07238339,128.8228110134218,1000.0,1.0
0.07288427,0.07296659999999999,129.06908883962927,1000.0,1.0
0.07346747999999999,0.07354981,129.31186704123803,1000.0,1.0
0.074071615,0.074153945,129.54936203006082,1000.0,1.0
0.07467575,0.07475808,129.79443958550019,1000.0,1.0
0.07530382499999999,0.07538615500000001,130.05019394639407,1000.0,1.0
0.0759319,0.07601423,130.31529850097925,1000.0,1.0
0.076525965,0.07660829499999999,130.57957050049237,1000.0,1.0
0.07712002999999999,0.07720236,130.82643884463909,1000.0,1.0
0.077746705,0.07782903499999999,131.05689598650028,1000.0,1.0
0.07837337999999999,0.07845571,131.27801595654503,1000.0,1.0
0.07900083999999999,0.07908317000000001,131.4922629260535,1000.0,1.0
0.0796283,0.07971063,131.70972822458634,1000.0,1.0
0.08022457,0.0803069,131.93985747403056,1000.0,1.0
0.08082083999999999,0.08090317,132.18331398570874,1000.0,1.0
0.08142071499999999,0.081503045,132.4360319915234,1000.0,1.0
0.08202058999999999,0.08210292,132.68294629740112,1000.0,1.0
0.082632865,0.08271519499999999,132.9131193911673,1000.0,1.0
0.08324514,0.08332747,133.13557804898457,1000.0,1.0
0.083828925,0.08391125499999999,133.3571994533487,1000.0,1.0
0.08441270999999999,0.08449504,133.5794315715026,1000.0,1.0
0.08504107,0.08512339999999999,133.80195443122673,1000.0,1.0
0.08566942999999999,0.08575176,134.02063368118226,1000.0,1.0
0.08626049,0.08634282,134.23779683072692,1000.0,1.0
0.08685155,0.08693388,134.45548049481604,1000.0,1.0
0.08748732000000001,0.08756965,134.66999386752244,1000.0,1.0
0.08812309,0.08820542,134.88025238911996,1000.0,1.0
0.088703905,0.088786235,135.09272842064354,1000.0,1.0
0.08928472,0.08936705,135.31391147457433,1000.0,1.0
0.089933755,0.090016085,135.54138037581774,1000.0,1.0
0.09058279,0.09066512,135.7678524346692,1000.0,1.0
0.091173845,0.091256175,135.98819037626524,1000.0,1.0
0.0917649,0.09184723,136.20311284109653,1000.0,1.0
0.092383175,0.092465505,136.41682451253752,1000.0,1.0
0.09300145,0.09308378,136.63296708359715,1000.0,1.0
0.09363226,0.09371459,136.8448514061968,1000.0,1.0
0.09426306999999999,0.0943454,137.04816802992627,1000.0,1.0
0.09484746,0.09492979,137.24907069268232,1000.0,1.0
0.09543185,0.09551418,137.44937901201308,1000.0,1.0
0.09605533,0.09613766,137.6458992556143,1000.0,1.0
0.09667880999999999,0.09676114,137.8346874157145,1000.0,1.0
0.09727348499999999,0.097355815,138.0204296651746,1000.0,1.0
0.09786816,0.09795049,138.21644097819248,1000.0,1.0
0.09850798,0.09859031,138.42540735024284,1000.0,1.0
0.0991478,0.09923013,138.6346468543838,1000.0,1.0
0.09972317,0.09980549999999999,138.83718559988665,1000.0,1.0
0.10029853999999999,0.10038087,139.0358009217987,1000.0,1.0
0.10093396499999999,0.101016295,139.23569119884135,1000.0,1.0
0.10156939,0.10165172,139.4394874569142,1000.0,1.0
0.10218190499999999,0.10226423500000001,139.64188726100812,1000.0,1.0
0.10279442,0.10287675,139.84348999377806,1000.0,1.0
0.103404615,0.103486945,140.0501913471065,1000.0,1.0
0.10401481,0.10409714,140.25981474315935,1000.0,1.0
0.10462279499999999,0.10470512500000001,140.46282749710585,1000.0,1.0
0.10523078,0.10531311,140.65548536899578,1000.0,1.0
0.10585146499999999,0.105933795,140.83917806076482,1000.0,1.0
0.10647214999999999,0.10655448,141.01683055902808,1000.0,1.0
0.10710255999999999,0.10718489,141.19526088636374,1000.0,1.0
0.10773297,0.1078153,141.37703022762759,1000.0,1.0
0.1083672,0.10844953,141.55982409442495,1000.0,1.0
0.10900143,0.10908376,141.743082274861,1000.0,1.0
0.10957947,0.1096618,141.93109870685566,1000.0,1.0
0.11015751,0.11023984,142.12558053066167,1000.0,1.0
0.110772275,0.110854605,142.31996136287134,1000.0,1.0
0.11138703999999999,0.11146937,142.49684063001,1000.0,1.0
0.11199952999999999,0.11208186,142.66910838545544,1000.0,1.0
0.11261202,0.11269435,142.86827994772565,1000.0,1.0
0.11323432,0.11331664999999999,143.09518736653206,1000.0,1.0
0.11385661999999999,0.11393895,143.3404396754507,1000.0,1.0
0.11501905999999999,0.11510139,143.58985663708444,1000.0,1.0
0.1161815,0.11626383,143.8307954797726,1000.0,1.0
0.116790885,0.116873215,144.0588105739558,1000.0,1.0
0.11740027,0.1174826,144.2644064688799,1000.0,1.0
0.118010455,0.118092785,144.43530502491112,1000.0,1.0
0.11862064,0.11870297,144.59264828338982,1000.0,1.0
0.119231515,0.119313845,144.76165362548585,1000.0,1.0
0.11984239,0.11992472,144.93704667611516,1000.0,1.0
0.12044794,0.12053027,145.1148852275758,1000.0,1.0
0.12105349,0.12113582,145.29400959533822,1000.0,1.0
0.12166892,0.12175125,145.46796461257523,1000.0,1.0
0.12228435,0.12236668,145.6344095237947,1000.0,1.0
0.122903555,0.122985885,145.7974944726296,1000.0,1.0
0.12352276,0.12360509,145.96419275370056,1000.0,1.0
0.12414887,0.1242312,146.13309192151706,1000.0,1.0
0.12477498,0.12485731,146.29476588775862,1000.0,1.0
0.125374415,0.12545674499999998,146.4498584406456,1000.0,1.0
0.12597385,0.12605618,146.6070281415905,1000.0,1.0
0.126610575,0.126692905,146.76854558063783,1000.0,1.0
0.1272473,0.12732963,146.93004004566453,1000.0,1.0
0.12786347,0.1279458,147.08826231709233,1000.0,1.0
0.12847964,0.12856197,147.24498530499437,1000.0,1.0
0.12908439,0.12916672,147.40599220680343,1000.0,1.0
0.12968914,0.12977147,147.5705695017758,1000.0,1.0
0.13025481,0.13033714000000002,147.7311042059298,1000.0,1.0
0.13082048000000002,0.13090281,147.88907701535268,1000.0,1.0
0.13149098,0.13157331,148.0488947871265,1000.0,1.0
0.13216148,0.13224381,148.2076276092836,1000.0,1.0
0.132768405,0.132850735,148.36269533662806,1000.0,1.0
0.13337533000000001,0.13345766,148.5136091985704,1000.0,1.0
0.13397689000000002,0.13405922,148.66115891566892,1000.0,1.0
0.13457845000000002,0.13466078,148.80846731539012,1000.0,1.0
0.1351869,0.13526923000000002,148.96101086942087,1000.0,1.0
0.13579535,0.13587768,149.12107079857094,1000.0,1.0
0.13641376,0.13649609000000001,149.28497489976732,1000.0,1.0
0.13703217,0.1371145,149.44985775034988,1000.0,1.0
0.13763282500000001,0.137715155,149.61263703871913,1000.0,1.0
0.13823348000000002,0.13831581,149.77025387855016,1000.0,1.0
0.13889043,0.13897276,149.92176713578667,1000.0,1.0
0.13954738,0.13962971,150.0691798954661,1000.0,1.0
0.140137225,0.140219555,150.2123809467978,1000.0,1.0
0.14072707,0.1408094,150.34910654846664,1000.0,1.0
0.1413702,0.14145253000000002,150.48692583232966,1000.0,1.0
0.14201333000000002,0.14209566,150.634372068406,1000.0,1.0
0.14261698,0.14269931000000002,150.78913885584393,1000.0,1.0
0.14322063000000002,0.14330296,150.9462501003527,1000.0,1.0
0.14382815000000002,0.14391048,151.102218746738,1000.0,1.0
0.14443567000000002,0.144518,151.25422852445178,1000.0,1.0
0.145040795,0.14512312500000002,151.40350471309216,1000.0,1.0
0.14564592,0.14572825,151.5531914946877,1000.0,1.0
0.14627982,0.14636215,151.69642951072825,1000.0,1.0
0.14691372,0.14699605,151.83012824698775,1000.0,1.0
0.14753590500000002,0.147618235,151.96325759713042,1000.0,1.0
0.14815809000000002,0.14824042,152.0960052030057,1000.0,1.0
0.148774855,0.148857185,152.22906276697918,1000.0,1.0
0.14939162,0.14947395,152.36627341224616,1000.0,1.0
0.1499935,0.15007583,152.50878776728916,1000.0,1.0
0.15059538,0.15067771,152.66498539670505,1000.0,1.0
0.15121366,0.15129599,152.83295547064424,1000.0,1.0
0.15183194,0.15191427,152.99457878367687,1000.0,1.0
0.15241654999999998,0.15249888,153.14102815550157,1000.0,1.0
0.15300116,0.15308349,153.27660303918094,1000.0,1.0
0.15366478,0.15374711,153.4055754331381,1000.0,1.0
0.1543284,0.15441073,153.53448802603563,1000.0,1.0
0.15488624,0.15496857,153.66675843734282,1000.0,1.0
0.15544408,0.15552641,153.80341271634353,1000.0,1.0
0.15610927000000002,0.15619159999999999,153.94731780446517,1000.0,1.0
0.15677446,0.15685679,154.09267320314143,1000.0,1.0
0.15739969,0.15748202,154.22927118966294,1000.0,1.0
0.15802492,0.15810725,154.35721753547872,1000.0,1.0
0.158632075,0.158714405,154.47976224703442,1000.0,1.0
0.15923923,0.15932156,154.59678990290217,1000.0,1.0
0.15985657,0.1599389,154.7138957305864,1000.0,1.0
0.16047391,0.16055624,154.83668916516694,1000.0,1.0
0.16109201,0.16117434,154.96389124538007,1000.0,1.0
0.16171011000000002,0.16179244,155.09248799735818,1000.0,1.0
0.16231951,0.16240184000000002,155.2239222337661,1000.0,1.0
0.16292891,0.16301124,155.35998132371336,1000.0,1.0
0.16356114500000002,0.16364347499999998,155.496048644305,1000.0,1.0
0.16419338,0.16427571,155.626390178458,1000.0,1.0
0.16479475,0.16487708,155.74922945431337,1000.0,1.0
0.16539612,0.16547845,155.86747337390253,1000.0,1.0
0.166023625,0.166105955,155.98774336635813,1000.0,1.0
0.16665113,0.16673346,156.11171068149932,1000.0,1.0
0.16725077500000002,0.16733310499999998,156.2371278583949,1000.0,1.0
0.16785042,0.16793275,156.3665938753769,1000.0,1.0
0.16847309500000002,0.16855542499999998,156.50189113987045,1000.0,1.0
0.16909577,0.1691781,156.63672663461452,1000.0,1.0
0.169728815,0.169811145,156.7677017550666,1000.0,1.0
0.17036186,0.17044419,156.8977196600184,1000.0,1.0
0.170973335,0.171055665,157.0261383772259,1000.0,1.0
0.17158481,0.17166714,157.1537633812384,1000.0,1.0
0.17221938,0.17230171,157.28230615424187,1000.0,1.0
0.17285395,0.17293628,157.41157407993757,1000.0,1.0
0.17346696,0.17354929,157.53982723214418,1000.0,1.0
0.17407997,0.1741623,157.66298608879603,1000.0,1.0
0.17469055,0.17477288,157.78002828980433,1000.0,1.0
0.17530113,0.17538346,157.89534987940164,1000.0,1.0
0.175918815,0.176001145,158.01262703928052,1000.0,1.0
0.1765365,0.17661883,158.13189849294145,1000.0,1.0
0.17716779500000002,0.177250125,158.25219444461982,1000.0,1.0
0.17779909000000002,0.17788142,158.37556549464242,1000.0,1.0
0.17838629,0.17846862000000002,158.49892026820314,1000.0,1.0
0.17897349,0.17905582,158.61269868745873,1000.0,1.0
0.179593455,0.179675785,158.71736852544785,1000.0,1.0
0.18021342,0.18029575,158.82074255947572,1000.0,1.0
0.18085993,0.18094226000000002,158.9263670481167,1000.0,1.0
0.18150644000000002,0.18158877,159.0321164049387,1000.0,1.0
0.18211513000000001,0.18219746,159.14215925893424,1000.0,1.0
0.18272382,0.18280615,159.2653218560656,1000.0,1.0
0.183307455,0.183389785,159.3997256323887,1000.0,1.0
0.18389109,0.18397342,159.53450113020983,1000.0,1.0
0.18450443500000002,0.18458676499999999,159.66036695105547,1000.0,1.0
0.18511778,0.18520011,159.77727404885266,1000.0,1.0
0.18573835500000002,0.18582068499999999,159.8904377344727,1000.0,1.0
0.18635893,0.18644126,160.001647418721,1000.0,1.0
0.18696087500000003,0.187043205,160.10906693254793,1000.0,1.0
0.18756282000000002,0.18764515,160.21648348966758,1000.0,1.0
0.18823675,0.18831908,160.33148819746293,1000.0,1.0
0.18891068,0.18899301,160.45387558573512,1000.0,1.0
0.189491445,0.189573775,160.57714239118172,1000.0,1.0
0.19007221000000002,0.19015454,160.6952524856531,1000.0,1.0
0.19071211000000002,0.19079444,160.807352203788,1000.0,1.0
0.19135201000000002,0.19143434,160.91870024714106,1000.0,1.0
0.19195697500000003,0.192039305,161.0314598175617,1000.0,1.0
0.19256194000000001,0.19264427,161.1447764998077,1000.0,1.0
0.19317739500000003,0.193259725,161.25552958494868,1000.0,1.0
0.19379285000000002,0.19387518,161.3607710999698,1000.0,1.0
0.19441560000000002,0.19449792999999999,161.4647405091763,1000.0,1.0
0.19503835,0.19512068,161.56901711800637,1000.0,1.0
0.19566181500000002,0.19574414499999998,161.67167906317525,1000.0,1.0
0.19628528,0.19636761,161.77670831224796,1000.0,1.0
0.196870335,0.196952665,161.8864537318127,1000.0,1.0
0.19745539,0.19753772,161.9967064143294,1000.0,1.0
0.19809348,0.19817581,162.10772398373828,1000.0,1.0
0.19873157,0.1988139,162.22030424644694,1000.0,1.0
0.19935084,0.19943317,162.33024192255445,1000.0,1.0
0.19997011,0.20005244,162.4396218092143,1000.0,1.0
0.20055402,0.20063635000000002,162.54951476921124,1000.0,1.0
0.20113793000000002,0.20122026,162.65731851779788,1000.0,1.0
0.20177843500000003,0.201860765,162.76232758736117,1000.0,1.0
0.20241894000000002,0.20250127,162.86246010319226,1000.0,1.0
0.20301413000000001,0.20309646,162.95588903619992,1000.0,1.0
0.20360932,0.20369165,163.04577030223166,1000.0,1.0
0.20426128,0.20434361,163.1371747199876,1000.0,1.0
0.20491324,0.20499557,163.23168716733414,1000.0,1.0
0.20552974499999999,0.205612075,163.32957078112923,1000.0,1.0
0.20614625,0.20622858,163.42518159402678,1000.0,1.0
0.20672716000000002,0.20680948999999998,163.5213577628033,1000.0,1.0
0.20730807,0.2073904,163.62861087067338,1000.0,1.0
0.20796573000000002,0.20804806,163.74466350776535,1000.0,1.0
0.20862339000000002,0.20870572,163.86454397686398,1000.0,1.0
0.20922895000000002,0.20931128,163.9832166166973,1000.0,1.0
0.20983451,0.20991684,164.0959000969056,1000.0,1.0
0.21044745,0.21052978,164.20075450107586,1000.0,1.0
0.21106039000000001,0.21114272,164.29652623855364,1000.0,1.0
0.21169395500000002,0.211776285,164.3801234392558,1000.0,1.0
0.21232752000000002,0.21240985,164.45637522543387,1000.0,1.0
0.212945285,0.213027615,164.53693161177256,1000.0,1.0
0.21356305,0.21364538,164.62256681456788,1000.0,1.0
0.214164955,0.214247285,164.71241059822705,1000.0,1.0
0.21476686,0.21484919,164.80745974441632,1000.0,1.0
0.215366145,0.215448475,164.90541760957626,1000.0,1.0
0.21596543,0.21604776,165.00593614689728,1000.0,1.0
0.21659213,0.21667446,165.1076167594615,1000.0,1.0
0.21721883,0.21730116,165.20513352585127,1000.0,1.0
0.21781624,0.21789857,165.2961028584686,1000.0,1.0
0.21841365000000001,0.21849598,165.38350424481175,1000.0,1.0
0.21907869000000002,0.21916101999999998,165.47024541636128,1000.0,1.0
0.21974373,0.21982606,165.5576639792511,1000.0,1.0
0.220302455,0.220384785,165.64866027576724,1000.0,1.0
0.22086118000000002,0.22094351,165.7460435989257,1000.0,1.0
0.22149095500000002,0.221573285,165.84734219747313,1000.0,1.0
0.22212073000000002,0.22220306,165.94282265645072,1000.0,1.0
0.222747945,0.22283027500000002,166.034179921041,1000.0,1.0
0.22337516000000002,0.22345749,166.13540367140172,1000.0,1.0
0.22398972500000003,0.224072055,166.24349910997802,1000.0,1.0
0.22460429,0.22468662,166.34773860236933,1000.0,1.0
0.225206165,0.225288495,166.4459165993964,1000.0,1.0
0.22580804000000002,0.22589037,166.54027925745305,1000.0,1.0
0.22644765500000003,0.226529985,166.63232600101955,1000.0,1.0
0.22708727,0.2271696,166.71741388844077,1000.0,1.0
0.22774460000000002,0.22782692999999998,166.79265141465308,1000.0,1.0
0.22840193,0.22848426,166.8699690221916,1000.0,1.0
0.22899930000000002,0.22908162999999998,166.96001718489018,1000.0,1.0
0.22959667,0.229679,167.0542429924733,1000.0,1.0
0.23020492,0.23028725,167.14456730205458,1000.0,1.0
0.23081317,0.2308955,167.23357807264034,1000.0,1.0
0.23143233000000002,0.23151465999999998,167.32279709062567,1000.0,1.0
0.23205149,0.23213382,167.41014190207946,1000.0,1.0
0.232647685,0.232730015,167.49518946897567,1000.0,1.0
0.23324388000000001,0.23332621,167.58320090293282,1000.0,1.0
0.233878105,0.23396043500000002,167.67397561648386,1000.0,1.0
0.23451233000000002,0.23459466,167.759268917022,1000.0,1.0
0.235130355,0.235212685,167.83859707400174,1000.0,1.0
0.23574838,0.23583071,167.91710917914125,1000.0,1.0
0.23636722500000001,0.236449555,167.99764035678987,1000.0,1.0
0.23698607000000002,0.2370684,168.08250298656787,1000.0,1.0
0.23760903500000002,0.237691365,168.16917677104922,1000.0,1.0
0.238232,0.23831433,168.25369459906,1000.0,1.0
0.23884894,0.23893127,168.33925151082866,1000.0,1.0
0.23946588000000002,0.23954821,168.42624475625493,1000.0,1.0
0.240086965,0.240169295,168.50888610522367,1000.0,1.0
0.24070805,0.24079038,168.58675905615192,1000.0,1.0
0.24131286000000002,0.24139518999999998,168.6648047003366,1000.0,1.0
0.24191767,0.242,168.7477687018384,1000.0,1.0
0.24254375,0.24262608,168.83576692427653,1000.0,1.0
0.24316983,0.24325216,168.9235491912233,1000.0,1.0
0.243793225,0.243875555,169.0056676445687,1000.0,1.0
0.24441662,0.24449895,169.08225199591442,1000.0,1.0
0.24502026999999998,0.2451026,169.158359111901,1000.0,1.0
0.24562392,0.24570625,169.23558708448792,1000.0,1.0
0.24624885000000002,0.24633117999999998,169.31182244351507,1000.0,1.0
0.24687378000000001,0.24695611,169.3900328644842,1000.0,1.0
0.24748919000000003,0.24757152,169.47197196675958,1000.0,1.0
0.2481046,0.24818693,169.553699807536,1000.0,1.0
0.248707,0.24878933,169.63251244712376,1000.0,1.0
0.24930940000000001,0.24939173,169.7042740439487,1000.0,1.0
0.249922855,0.250005185,169.77108134663627,1000.0,1.0
0.25053631,0.25061864,169.84580025490206,1000.0,1.0
0.251181635,0.25126396500000003,169.92773410831023,1000.0,1.0
0.25182696,0.25190929,170.00477399865858,1000.0,1.0
0.25244542999999997,0.25252776,170.07832026498627,1000.0,1.0
0.2530639,0.25314623,170.15480064297586,1000.0,1.0
0.253624305,0.253706635,170.2310768792503,1000.0,1.0
0.25418471,0.25426704,170.30171774109726,1000.0,1.0
0.25482545999999995,0.25490778999999997,170.36598540347666,1000.0,1.0
0.25546620999999997,0.25554854,170.4314556765368,1000.0,1.0
0.256104275,0.256186605,170.50566462672865,1000.0,1.0
0.25674233999999996,0.25682467,170.57975161452003,1000.0,1.0
0.25733953499999995,0.25742186499999997,170.64638624407863,1000.0,1.0
0.25793673,0.25801906,170.71528982344557,1000.0,1.0
0.25853811,0.25862044,170.79253761929073,1000.0,1.0
0.25913949,0.25922182,170.8728515679001,1000.0,1.0
0.2597834,0.25986573,170.9501580553792,1000.0,1.0
0.26042730999999997,0.26050964,171.02172699964603,1000.0,1.0
0.26101975,0.26110208,171.090573605925,1000.0,1.0
0.26161218999999997,0.26169452,171.16092220139132,1000.0,1.0
0.26227166999999996,0.262354,171.23089637769766,1000.0,1.0
0.26293115,0.26301348,171.30004248825,1000.0,1.0
0.26351109,0.26359342,171.37209161521838,1000.0,1.0
0.26409103,0.26417336,171.44853694303498,1000.0,1.0
0.26472416499999996,0.264806495,171.5252477920416,1000.0,1.0
0.26535729999999996,0.26543963,171.59705365270386,1000.0,1.0
0.26595616499999997,0.266038495,171.6609069124192,1000.0,1.0
0.26655502999999997,0.26663736,171.7200420346316,1000.0,1.0
0.267158105,0.267240435,171.7786364466606,1000.0,1.0
0.26776118,0.26784351,171.83220548082144,1000.0,1.0
0.268379075,0.26846140500000004,171.88256259198866,1000.0,1.0
0.26899697,0.2690793,171.940532684076,1000.0,1.0
0.26962967,0.269712,172.0081450966254,1000.0,1.0
0.27026237,0.2703447,172.07777962458445,1000.0,1.0
0.27088881499999995,0.27097114499999997,172.1465053665958,1000.0,1.0
0.27151526,0.27159759,172.21683252744728,1000.0,1.0
0.27210376999999997,0.2721861,172.2866158662597,1000.0,1.0
0.27269227999999995,0.27277461,172.34966417652066,1000.0,1.0
0.273369685,0.273452015,172.40489960565168,1000.0,1.0
0.27404709,0.27412942,172.45894596529425,1000.0,1.0
0.27462643499999995,0.27470876499999997,172.5199724465046,1000.0,1.0
0.27520577999999996,0.27528811,172.58890450161854,1000.0,1.0
0.27580704,0.27588937,172.65962577366648,1000.0,1.0
0.2764083,0.27649063,172.7293969451407,1000.0,1.0
0.277049275,0.277131605,172.8001615453803,1000.0,1.0
0.27769024999999997,0.27777258,172.87100557801847,1000.0,1.0
0.278292985,0.278375315,172.93689592515295,1000.0,1.0
0.27889571999999996,0.27897805,172.99672903865903,1000.0,1.0
0.27952055499999995,0.27960288499999997,173.05290061522086,1000.0,1.0
0.28014539,0.28022772,173.1060510020835,1000.0,1.0
0.280760285,0.280842615,173.16301700761932,1000.0,1.0
0.28137518,0.28145751,173.23149091669114,1000.0,1.0
0.28199438499999996,0.282076715,173.30498038676302,1000.0,1.0
0.28261358999999997,0.28269592,173.37660093433269,1000.0,1.0
0.28322289999999994,0.28330522999999996,173.4459103881982,1000.0,1.0
0.28383221,0.28391454,173.50858471973623,1000.0,1.0
0.28444227499999997,0.284524605,173.56387206379043,1000.0,1.0
0.28505233999999996,0.28513467,173.6174319614196,1000.0,1.0
0.285670265,0.285752595,173.6683834067276,1000.0,1.0
0.28628819,0.28637052,173.71820482292625,1000.0,1.0
0.286931935,0.28701426500000005,173.77540675022973,1000.0,1.0
0.28757568,0.28765801,173.8387167520853,1000.0,1.0
0.2881701,0.28825243,173.90025616250404,1000.0,1.0
0.28876451999999997,0.28884685,173.95682981948144,1000.0,1.0
0.28936681,0.28944914,174.00789680471263,1000.0,1.0
0.2899691,0.29005143,174.056906850191,1000.0,1.0
0.290582925,0.290665255,174.10826861034977,1000.0,1.0
0.29119675,0.29127908,174.15973327390068,1000.0,1.0
0.29182929,0.29191162000000004,174.20804906990364,1000.0,1.0
0.29246183,0.29254416,174.25603679328614,1000.0,1.0
0.29309514,0.29317747,174.30703730968415,1000.0,1.0
0.29372845,0.29381078,174.3578453829853,1000.0,1.0
0.29433736,0.29441969,174.40744122868455,1000.0,1.0
0.29494626999999995,0.2950286,174.4576513427563,1000.0,1.0
0.29553427,0.2956166,174.51042559212274,1000.0,1.0
0.29612226999999997,0.2962046,174.56871010709557,1000.0,1.0
0.29674709,0.29682942,174.63100297068087,1000.0,1.0
0.29737190999999996,0.29745424,174.69395650627735,1000.0,1.0
0.29799388499999996,0.298076215,174.7557869656616,1000.0,1.0
0.29861585999999996,0.29869819,174.81506834773901,1000.0,1.0
0.29921326,0.29929559,174.86964309003363,1000.0,1.0
0.29981066,0.29989299,174.91972823524998,1000.0,1.0
0.30044865499999995,0.300530985,174.96721607436632,1000.0,1.0
0.30108664999999996,0.30116898,175.0139781925674,1000.0,1.0
0.30171461499999996,0.301796945,175.0637287368034,1000.0,1.0
0.30234257999999997,0.30242491,175.11914440167558,1000.0,1.0
0.302978545,0.303060875,175.17617591129394,1000.0,1.0
0.30361451,0.30369684,175.23091799517832,1000.0,1.0
0.304196715,0.304279045,175.2820467313552,1000.0,1.0
0.30477891999999995,0.30486125,175.3268726701443,1000.0,1.0
0.30536542999999994,0.30544775999999996,175.36623022256103,1000.0,1.0
0.30595194,0.30603427,175.40259599742905,1000.0,1.0
0.30659754499999997,0.306679875,175.43904093323562,1000.0,1.0
0.30724314999999996,0.30732548,175.48252447912031,1000.0,1.0
0.30787496,0.30795729,175.53461754778303,1000.0,1.0
0.30850677,0.3085891,175.58956193510258,1000.0,1.0
0.309113755,0.309196085,175.64145149533405,1000.0,1.0
0.30972074,0.30980307,175.68462119637894,1000.0,1.0
0.31033581499999996,0.310418145,175.7197589977561,1000.0,1.0
0.31095089,0.31103322,175.75358618253384,1000.0,1.0
0.311574055,0.31165638500000004,175.78874119745225,1000.0,1.0
0.31219722,0.31227955,175.82593246264923,1000.0,1.0
0.312824815,0.312907145,175.86936254604615,1000.0,1.0
0.31345240999999996,0.31353474,175.92051195883408,1000.0,1.0
0.31407712499999996,0.314159455,175.97433575550414,1000.0,1.0
0.31470183999999995,0.31478417,176.0226515539965,1000.0,1.0
0.31531261,0.31539494,176.0634283455715,1000.0,1.0
0.31592338,0.31600571,176.1022460500219,1000.0,1.0
0.316501735,0.316584065,176.1443792959583,1000.0,1.0
0.31708009,0.31716242,176.19162601694015,1000.0,1.0
0.31767386,0.31775619,176.2405783669853,1000.0,1.0
0.31826762999999997,0.31834996,176.28977247034533,1000.0,1.0
0.31891754499999997,0.318999875,176.3404221381734,1000.0,1.0
0.31956745999999997,0.31964979,176.38791722589758,1000.0,1.0
0.320184875,0.320267205,176.42822099018704,1000.0,1.0
0.32080229,0.32088462,176.46568912227877,1000.0,1.0
0.32140203,0.32148436,176.50295572872935,1000.0,1.0
0.32200176999999996,0.3220841,176.53997340639532,1000.0,1.0
0.322639255,0.32272158500000003,176.57929733530963,1000.0,1.0
0.32327674,0.32335907,176.6181625360124,1000.0,1.0
0.323885365,0.323967695,176.6566059352154,1000.0,1.0
0.32449398999999995,0.32457632,176.70041748015947,1000.0,1.0
0.325136795,0.325219125,176.7477681156734,1000.0,1.0
0.3257796,0.32586193,176.79521545736247,1000.0,1.0
0.32634878,0.32643111,176.84263011073324,1000.0,1.0
0.32691796,0.32700029,176.8880123219724,1000.0,1.0
0.32754743,0.32762976,176.92897133092407,1000.0,1.0
0.3281769,0.32825923,176.96637168730476,1000.0,1.0
0.328803435,0.328885765,176.99932063654757,1000.0,1.0
0.32942996999999996,0.3295123,177.0299292287531,1000.0,1.0
0.33007221,0.33015454,177.06275689115574,1000.0,1.0
0.33071445,0.33079678,177.09486951905242,1000.0,1.0
0.33129768,0.33138001,177.12432642973087,1000.0,1.0
0.33188091,0.33196324,177.1528918963411,1000.0,1.0
0.33251723499999997,0.332599565,177.18282903257682,1000.0,1.0
0.33315355999999996,0.33323589,177.21862295069042,1000.0,1.0
0.33378701,0.33386934,177.25853012650379,1000.0,1.0
0.33442046,0.33450279,177.29471312654624,1000.0,1.0
0.33499081499999994,0.33507314499999996,177.3262223336179,1000.0,1.0
0.33556116999999996,0.3356435,177.35466903655927,1000.0,1.0
0.33620740499999996,0.336289735,177.3816830260459,1000.0,1.0
0.33685363999999995,0.33693597,177.41068683855633,1000.0,1.0
0.33748182499999996,0.337564155,177.44356342745644,1000.0,1.0
0.33811000999999996,0.33819234,177.48285218699357,1000.0,1.0
0.338690025,0.338772355,177.52930825033465,1000.0,1.0
0.33927004,0.33935237,177.5746338206145,1000.0,1.0
0.33989981999999996,0.33998215,177.6143736863486,1000.0,1.0
0.3405296,0.34061193,177.6552361372748,1000.0,1.0
0.34114122,0.34122355000000004,177.69704000349935,1000.0,1.0
0.34175284,0.34183517,177.73642344673783,1000.0,1.0
0.342342555,0.342424885,177.77377600271015,1000.0,1.0
0.34293227,0.3430146,177.80981379735772,1000.0,1.0
0.34361356499999995,0.343695895,177.84422973869525,1000.0,1.0
0.34429486,0.34437719,177.87496007948826,1000.0,1.0
0.34488986499999996,0.344972195,177.89997654390083,1000.0,1.0
0.34548487,0.3455672,177.92248169222552,1000.0,1.0
0.346035035,0.346117365,177.94825130589626,1000.0,1.0
0.3465852,0.34666753,177.97623815179432,1000.0,1.0
0.347234755,0.347317085,178.00367068431166,1000.0,1.0
0.34788431,0.34796664,178.0300617453132,1000.0,1.0
0.34851570499999995,0.348598035,178.0580076252314,1000.0,1.0
0.3491471,0.34922943,178.09123830710382,1000.0,1.0
0.34973354999999995,0.34981587999999997,178.12740989185815,1000.0,1.0
0.35031999999999996,0.35040233,178.16367964563227,1000.0,1.0
0.35097585499999995,0.35105818499999997,178.19653860952002,1000.0,1.0
0.35163171,0.35171404,178.22098124961073,1000.0,1.0
0.35222345,0.35230578,178.23971992069764,1000.0,1.0
0.35281519,0.35289752,178.25639556554577,1000.0,1.0
0.35346119,0.35354352,178.27322710116624,1000.0,1.0
0.35410718999999996,0.35418952,178.29688101029654,1000.0,1.0
0.3546889,0.35477123,178.33004332949702,1000.0,1.0
0.35527061,0.35535294,178.36716859890618,1000.0,1.0
0.35586454,0.35594687,178.40540576000487,1000.0,1.0
0.35645846999999997,0.3565408,178.44227737502757,1000.0,1.0
0.35710679,0.35718912,178.47358595965713,1000.0,1.0
0.35775511,0.35783744,178.50437480891588,1000.0,1.0
0.35835819,0.35844052000000004,178.53470173250506,1000.0,1.0
0.35896127,0.3590436,178.55685146134408,1000.0,1.0
0.35958813,0.35967046,178.5764086157829,1000.0,1.0
0.36021498999999996,0.36029732,178.6018772180097,1000.0,1.0
0.360842675,0.360925005,178.63019527240823,1000.0,1.0
0.36147036,0.36155269,178.6589730395898,1000.0,1.0
0.36211811,0.36220044,178.68846952689117,1000.0,1.0
0.36276586,0.36284819,178.7156194559414,1000.0,1.0
0.363325625,0.363407955,178.7443332251036,1000.0,1.0
0.36388539,0.36396772,178.77645180325135,1000.0,1.0
0.36454241,0.36462474,178.80491571368154,1000.0,1.0
0.36519943,0.36528176,178.83425554827042,1000.0,1.0
0.3658109,0.36589323,178.87036587249597,1000.0,1.0
0.36642237,0.3665047,178.9102211179351,1000.0,1.0
0.367030665,0.367112995,178.94496041485115,1000.0,1.0
0.36763895999999996,0.36772129,178.96490237581352,1000.0,1.0
0.36827909999999997,0.36836143,178.96953188521084,1000.0,1.0
0.36891924,0.36900157,178.9677016309557,1000.0,1.0
0.369564055,0.369646385,178.96877036741554,1000.0,1.0
0.37020886999999997,0.3702912,178.9741352990266,1000.0,1.0
0.370745565,0.370827895,178.98557678087957,1000.0,1.0
0.37128226,0.37136459,179.0064942516876,1000.0,1.0
0.371889665,0.371971995,179.03654263875967,1000.0,1.0
0.37249707,0.3725794,179.0686739952959,1000.0,1.0
0.37312469,0.37320702,179.09523796374106,1000.0,1.0
0.37375231,0.37383464,179.11577037888907,1000.0,1.0
0.374380735,0.37446306500000004,179.1339263125726,1000.0,1.0
0.37500916,0.37509149,179.15208525580184,1000.0,1.0
0.37565399499999996,0.375736325,179.17164938063038,1000.0,1.0
0.37629883,0.37638116,179.1973155416581,1000.0,1.0
0.37689364,0.37697597,179.22835998875485,1000.0,1.0
0.37748845,0.37757078,179.2579366758416,1000.0,1.0
0.378103555,0.378185885,179.28347754342715,1000.0,1.0
0.37871866,0.37880099,179.3055381437191,1000.0,1.0
0.37932272,0.37940505,179.32253325622483,1000.0,1.0
0.37992677999999996,0.38000911,179.33489242493707,1000.0,1.0
0.38053549499999995,0.38061782499999997,179.34596152932926,1000.0,1.0
0.38114421,0.38122654,179.35752247817334,1000.0,1.0
0.381781265,0.381863595,179.37445790544658,1000.0,1.0
0.38241832,0.38250065,179.3990466621819,1000.0,1.0
0.383052215,0.383134545,179.42626706637495,1000.0,1.0
0.38368610999999997,0.38376844,179.45341120161982,1000.0,1.0
0.38429709999999995,0.38437942999999997,179.48087741865947,1000.0,1.0
0.38490809,0.38499042,179.50451506837874,1000.0,1.0
0.385515955,0.38559828500000004,179.52513607031588,1000.0,1.0
0.38612382,0.38620615,179.55252703587115,1000.0,1.0
0.386756105,0.38683843500000004,179.58231393429548,1000.0,1.0
0.38738838999999997,0.38747072,179.608642492393,1000.0,1.0
0.38797395999999995,0.38805628999999997,179.6316777928527,1000.0,1.0
0.38855953,0.38864186,179.6454073096448,1000.0,1.0
0.389189435,0.389271765,179.64858116619368,1000.0,1.0
0.38981933999999996,0.38990167,179.64672582437117,1000.0,1.0
0.390453935,0.390536265,179.6406466881184,1000.0,1.0
0.39108853,0.39117086,179.6335386026501,1000.0,1.0
0.39168821,0.39177054,179.63601591238347,1000.0,1.0
0.39228789,0.39237022,179.6465996005861,1000.0,1.0
0.39295199,0.39303432,179.65945778103634,1000.0,1.0
0.39361609,0.39369842,179.67371270710385,1000.0,1.0
0.39418538999999997,0.39426772,179.68713301514663,1000.0,1.0
0.39475468999999996,0.39483702,179.70188413639195,1000.0,1.0
0.39536456499999995,0.39544689499999996,179.71929354682132,1000.0,1.0
0.39597444,0.39605677,179.73173658909857,1000.0,1.0
0.39661699499999997,0.396699325,179.73793910523474,1000.0,1.0
0.39725954999999996,0.39734188,179.7486433356133,1000.0,1.0
0.39786290999999996,0.39794524,179.76396587234643,1000.0,1.0
0.39846626999999996,0.3985486,179.7746467885664,1000.0,1.0
0.39906639999999993,0.39914872999999995,179.78255696351357,1000.0,1.0
0.39966652999999996,0.39974886,179.79411427732646,1000.0,1.0
0.40027941499999997,0.400361745,179.8087330001184,1000.0,1.0
0.4008923,0.40097463,179.82227583019463,1000.0,1.0
0.40150587,0.4015882,179.83119057142,1000.0,1.0
0.40211944,0.40220177,179.8406188141533,1000.0,1.0
0.402733845,0.402816175,179.85235500862413,1000.0,1.0
0.40334824999999996,0.40343058,179.86209488238978,1000.0,1.0
0.40397543999999996,0.40405777,179.86870141546987,1000.0,1.0
0.40460262999999996,0.40468496,179.87103758788408,1000.0,1.0