File: datasets/steel_spring/csv/BS2V-1100-1.0.csv
Time(s),Strain(%),Stress(MPa),Temp(C),SR(%/s)
0.0,4.102e-05,-0.014642298578198445,1100.0,1.0
8.030000000000003e-06,4.905e-05,0.5286586257711596,1100.0,1.0
1.6060000000000005e-05,5.708e-05,0.661958158657999,1100.0,1.0
2.1430000000000003e-05,6.245e-05,0.5340476129517044,1100.0,1.0
2.68e-05,6.782e-05,0.29371830152166245,1100.0,1.0
3.217e-05,7.319e-05,0.06964964940909102,1100.0,1.0
3.7539999999999996e-05,7.856e-05,0.05146113336742389,1100.0,1.0
4.828e-05,8.93e-05,0.49062490163636485,1100.0,1.0
5.902e-05,0.00010004,1.5581683876392094,1100.0,1.0
0.00021453499999999996,0.000255555,3.5269924967878907,1100.0,1.0
0.00037004999999999997,0.00041107,6.522210688784116,1100.0,1.0
0.0006115,0.00065252,10.554103911871257,1100.0,1.0
0.00085295,0.00089397,15.585515676028475,1100.0,1.0
0.001054265,0.001095285,21.158172103894024,1100.0,1.0
0.00125558,0.0012966,27.165900176601433,1100.0,1.0
0.00158317,0.00162419,33.10213511271982,1100.0,1.0
0.00191076,0.00195178,38.66583521881077,1100.0,1.0
0.002378415,0.002419435,43.438888695795626,1100.0,1.0
0.00284607,0.00288709,47.25433971839983,1100.0,1.0
0.003467585,0.003508605,50.068539191841104,1100.0,1.0
0.0040891,0.00413012,52.00796359864227,1100.0,1.0
0.004719414999999999,0.004760435,53.35501028903809,1100.0,1.0
0.00534973,0.00539075,54.28326600775116,1100.0,1.0
0.006007914999999999,0.006048935,55.079835055727465,1100.0,1.0
0.0066660999999999995,0.00670712,55.810474276803205,1100.0,1.0
0.007265665,0.007306685,56.56463785352291,1100.0,1.0
0.00786523,0.00790625,57.33391811868865,1100.0,1.0
0.008535815,0.008576835,58.11277092067444,1100.0,1.0
0.0092064,0.00924742,58.90696806809205,1100.0,1.0
0.009804750000000001,0.00984577,59.71517926169718,1100.0,1.0
0.0104031,0.01044412,60.53236292718019,1100.0,1.0
0.011010345000000001,0.011051365,61.346444809856344,1100.0,1.0
0.01161759,0.01165861,62.15574578657131,1100.0,1.0
0.012220130000000001,0.01226115,62.95727784087906,1100.0,1.0
0.012822670000000001,0.01286369,63.750137037551404,1100.0,1.0
0.01342594,0.01346696,64.52371032962148,1100.0,1.0
0.01402921,0.01407023,65.27550002406844,1100.0,1.0
0.014649515,0.014690535,66.00580545953808,1100.0,1.0
0.01526982,0.01531084,66.72083471205795,1100.0,1.0
0.015885490000000002,0.015926509999999998,67.41371940971997,1100.0,1.0
0.01650116,0.01654218,68.07612387071147,1100.0,1.0
0.017123,0.017164020000000002,68.70451323065933,1100.0,1.0
0.01774484,0.01778586,69.30183606212333,1100.0,1.0
0.018372930000000003,0.01841395,69.87244194496233,1100.0,1.0
0.01900102,0.01904204,70.41686455028805,1100.0,1.0
0.019621705000000003,0.019662725,70.93649274885624,1100.0,1.0
0.020242390000000002,0.02028341,71.439723589753,1100.0,1.0
0.020852870000000003,0.02089389,71.9345473746593,1100.0,1.0
0.02146335,0.02150437,72.41567254411298,1100.0,1.0
0.02211026,0.02215128,72.87986613388671,1100.0,1.0
0.02275717,0.02279819,73.33255486220014,1100.0,1.0
0.02337747,0.02341849,73.77345943534118,1100.0,1.0
0.02399777,0.02403879,74.19424138039705,1100.0,1.0
0.0246298,0.024670820000000003,74.60073038803819,1100.0,1.0
0.025261830000000002,0.02530285,75.00455441776552,1100.0,1.0
0.025875385,0.025916405,75.40921963278083,1100.0,1.0
0.02648894,0.02652996,75.8105347882355,1100.0,1.0
0.027100515,0.027141535,76.2093482238265,1100.0,1.0
0.02771209,0.02775311,76.6152138279799,1100.0,1.0
0.028363060000000002,0.028404079999999998,77.02517330545518,1100.0,1.0
0.02901403,0.02905505,77.42467884275051,1100.0,1.0
0.02963538,0.0296764,77.80282998260644,1100.0,1.0
0.03025673,0.03029775,78.16431306302488,1100.0,1.0
0.030873409999999997,0.03091443,78.5163476812502,1100.0,1.0
0.03149009,0.03153111,78.85497547108734,1100.0,1.0
0.032140724999999995,0.032181745,79.18264714835627,1100.0,1.0
0.03279136,0.03283238,79.51272696746608,1100.0,1.0
0.033431779999999994,0.0334728,79.85402710428045,1100.0,1.0
0.0340722,0.03411322,80.20119447162796,1100.0,1.0
0.034699509999999996,0.03474053,80.54727671950768,1100.0,1.0
0.035326819999999995,0.03536784,80.8919872929357,1100.0,1.0
0.035949394999999995,0.035990415,81.23243332080311,1100.0,1.0
0.036571969999999995,0.03661299,81.56435470044516,1100.0,1.0
0.037195275,0.037236295,81.88380212557587,1100.0,1.0
0.03781858,0.0378596,82.19735637071322,1100.0,1.0
0.03847616499999999,0.038517184999999995,82.506243088591,1100.0,1.0
0.039133749999999995,0.03917477,82.80445296988078,1100.0,1.0
0.03978102,0.03982204,83.08993903790928,1100.0,1.0
0.04042829,0.04046931,83.36531691208451,1100.0,1.0
0.04104568,0.041086700000000004,83.63169008308358,1100.0,1.0
0.041663069999999996,0.04170409,83.88395561290174,1100.0,1.0
0.04229516,0.04233618,84.12820514218203,1100.0,1.0
0.04292725,0.04296827,84.37568196166978,1100.0,1.0
0.04356859,0.04360961,84.63319753056848,1100.0,1.0
0.044209929999999995,0.04425095,84.90115234181285,1100.0,1.0
0.04481558499999999,0.044856604999999994,85.17349649193987,1100.0,1.0
0.045421239999999995,0.04546226,85.44449981327513,1100.0,1.0
0.04606980499999999,0.046110824999999994,85.71332093630353,1100.0,1.0
0.046718369999999995,0.04675939,85.97628351552413,1100.0,1.0
0.04731992,0.047360940000000004,86.22872061236411,1100.0,1.0
0.04792147,0.04796249,86.48100154578356,1100.0,1.0
0.04857166,0.048612680000000005,86.73464855727302,1100.0,1.0
0.04922185,0.04926287,86.98040080988659,1100.0,1.0
0.04982775,0.04986877,87.22001345396984,1100.0,1.0
0.05043365,0.05047467,87.45820437350103,1100.0,1.0
0.051068514999999995,0.051109535,87.68918430434843,1100.0,1.0
0.05170338,0.0517444,87.90767965073952,1100.0,1.0
0.05233905,0.05238007,88.11807476427283,1100.0,1.0
0.052974719999999996,0.05301574,88.33025168767468,1100.0,1.0
0.053582905,0.053623925,88.54804265447049,1100.0,1.0
0.05419109,0.05423211,88.75920259250371,1100.0,1.0
0.054771635,0.054812655,88.96107040536462,1100.0,1.0
0.055352179999999994,0.0553932,89.16793382209377,1100.0,1.0
0.055970309999999995,0.05601133,89.38596698246286,1100.0,1.0
0.05658844,0.05662946,89.6057426977364,1100.0,1.0
0.05719596,0.05723698,89.8215995293111,1100.0,1.0
0.05780348,0.0578445,90.04025208111113,1100.0,1.0
0.058411784999999994,0.058452805,90.26350125155336,1100.0,1.0
0.05902009,0.05906111,90.48084603986781,1100.0,1.0
0.05962626,0.05966728,90.68750922200039,1100.0,1.0
0.060232429999999997,0.06027345,90.89309627944915,1100.0,1.0
0.06084787999999999,0.060888899999999996,91.10510171340162,1100.0,1.0
0.06146333,0.06150435,91.32127490751324,1100.0,1.0
0.062073865,0.062114885,91.53579048346978,1100.0,1.0
0.0626844,0.06272542,91.7484450195589,1100.0,1.0
0.06329847499999999,0.063339495,91.96107370277294,1100.0,1.0
0.06391255,0.06395357,92.16905115697386,1100.0,1.0
0.064524585,0.064565605,92.36882196205352,1100.0,1.0
0.06513661999999999,0.06517764,92.56670294537834,1100.0,1.0
0.06576372999999999,0.06580475,92.76571503602332,1100.0,1.0
0.06639083999999999,0.06643186,92.9627849952828,1100.0,1.0
0.06701009,0.06705111,93.15890444188692,1100.0,1.0
0.06762934,0.06767036,93.35567567189462,1100.0,1.0
0.06822065,0.06826167,93.55093263606892,1100.0,1.0
0.06881195999999999,0.06885298,93.74302140564924,1100.0,1.0
0.06942124499999999,0.069462265,93.93126671487168,1100.0,1.0
0.07003053,0.07007155,94.11673616791433,1100.0,1.0
0.07065204,0.07069306,94.30239083735665,1100.0,1.0
0.07127354999999999,0.07131457,94.48780189679715,1100.0,1.0
0.071864105,0.071905125,94.67042396176608,1100.0,1.0
0.07245466,0.07249568,94.84906917720915,1100.0,1.0
0.0730431,0.07308412,95.02915262480379,1100.0,1.0
0.07363154,0.07367256,95.21609189633497,1100.0,1.0
0.074255295,0.074296315,95.4077334531519,1100.0,1.0
0.07487905,0.07492007,95.60184852796606,1100.0,1.0
0.075460205,0.075501225,95.79495352586378,1100.0,1.0
0.07604136,0.07608238,95.98162145868764,1100.0,1.0
0.07669556999999999,0.07673659,96.16375063806834,1100.0,1.0
0.07734977999999999,0.0773908,96.34750064707885,1100.0,1.0
0.07792657,0.07796759,96.52791563862135,1100.0,1.0
0.07850336,0.07854438,96.70005749342819,1100.0,1.0
0.079121465,0.079162485,96.87117527040175,1100.0,1.0
0.07973957,0.07978059,97.04478530436381,1100.0,1.0
0.080343905,0.080384925,97.22140994194719,1100.0,1.0
0.08094823999999999,0.08098926,97.40111695130055,1100.0,1.0
0.08159406999999999,0.08163509,97.5806905159321,1100.0,1.0
0.08223989999999999,0.08228092,97.7665140668037,1100.0,1.0
0.082825345,0.082866365,97.95913632224328,1100.0,1.0
0.08341079,0.08345181,98.14524440713699,1100.0,1.0
0.084046525,0.084087545,98.31484605364456,1100.0,1.0
0.08468226,0.08472328,98.47112272009427,1100.0,1.0
0.08527789,0.08531891,98.61928606119739,1100.0,1.0
0.08587352,0.08591454,98.76136732986993,1100.0,1.0
0.08646696499999999,0.086507985,98.90259016584932,1100.0,1.0
0.08706040999999999,0.08710143,99.04912915556504,1100.0,1.0
0.08768678999999999,0.08772780999999999,99.20359341260635,1100.0,1.0
0.08831317,0.08835419,99.35687950797838,1100.0,1.0
0.0889315,0.08897252,99.50828814052272,1100.0,1.0
0.08954983,0.08959085,99.66520201822934,1100.0,1.0
0.09014248999999999,0.09018351,99.82908833474268,1100.0,1.0
0.09073515,0.09077617,100.0027542834132,1100.0,1.0
0.09135498,0.091396,100.17955547199314,1100.0,1.0
0.09197481,0.09201583,100.35001555857869,1100.0,1.0
0.092592485,0.092633505,100.51394253168283,1100.0,1.0
0.09321016,0.09325118,100.6689751434127,1100.0,1.0
0.093840355,0.093881375,100.81228178278855,1100.0,1.0
0.09447055,0.09451157,100.95293930027337,1100.0,1.0
0.095066185,0.095107205,101.09779444212937,1100.0,1.0
0.09566182,0.09570284,101.24557562562464,1100.0,1.0
0.096293565,0.096334585,101.39999997668222,1100.0,1.0
0.09692531,0.09696633,101.55959049902887,1100.0,1.0
0.09750758,0.0975486,101.71608489561405,1100.0,1.0
0.09808984999999999,0.09813087,101.8674540497183,1100.0,1.0
0.098717245,0.098758265,102.01606670187921,1100.0,1.0
0.09934464,0.09938566,102.16640791932704,1100.0,1.0
0.09997283,0.10001385,102.31885112431078,1100.0,1.0
0.10060102,0.10064204,102.47049907281828,1100.0,1.0
0.10117949,0.10122051,102.6156839063184,1100.0,1.0
0.10175796,0.10179898,102.75232630038577,1100.0,1.0
0.10238466499999999,0.10242568499999999,102.88415363977326,1100.0,1.0
0.10301136999999999,0.10305239,103.00964041714278,1100.0,1.0
0.103623985,0.103665005,103.13040503056865,1100.0,1.0
0.1042366,0.10427762,103.25500343874619,1100.0,1.0
0.104855935,0.104896955,103.38758280165102,1100.0,1.0
0.10547527,0.10551629,103.52428191668399,1100.0,1.0
0.10609833499999999,0.10613935499999999,103.66561653872651,1100.0,1.0
0.1067214,0.10676242,103.8114143183137,1100.0,1.0
0.1073453,0.10738632000000001,103.95770642164332,1100.0,1.0
0.1079692,0.10801022,104.10300626036731,1100.0,1.0
0.108551945,0.108592965,104.24700395858362,1100.0,1.0
0.10913468999999999,0.10917571,104.3937008316651,1100.0,1.0
0.10975707,0.10979809,104.54432779402276,1100.0,1.0
0.11037945,0.11042047,104.69324926482659,1100.0,1.0
0.11098459499999999,0.111025615,104.83675470365122,1100.0,1.0
0.11158973999999999,0.11163076,104.97759263307816,1100.0,1.0
0.11220168,0.1122427,105.11826342721933,1100.0,1.0
0.11281362,0.11285464,105.25984845079037,1100.0,1.0
0.11343526000000001,0.11347628000000001,105.40002552593165,1100.0,1.0
0.1140569,0.11409792,105.53536003101337,1100.0,1.0
0.11466731499999999,0.114708335,105.66904994493945,1100.0,1.0
0.11527773,0.11531875,105.80796725994783,1100.0,1.0
0.115879815,0.115920835,105.94587940451525,1100.0,1.0
0.1164819,0.11652292,106.07225001532227,1100.0,1.0
0.117105875,0.117146895,106.19019383694722,1100.0,1.0
0.11772985,0.11777087,106.3085289870477,1100.0,1.0
0.1183727,0.11841372,106.42807706488684,1100.0,1.0
0.11901555,0.11905657,106.54358911123637,1100.0,1.0
0.11959571999999999,0.11963673999999999,106.65323324215206,1100.0,1.0
0.12017589,0.12021691,106.76140668008938,1100.0,1.0
0.120802125,0.120843145,106.87701641521987,1100.0,1.0
0.12142836,0.12146938,106.99856613280409,1100.0,1.0
0.12204936,0.12209038,107.11651261630327,1100.0,1.0
0.12267035999999999,0.12271138,107.2309702151762,1100.0,1.0
0.123279985,0.123321005,107.34942927570475,1100.0,1.0
0.12388961,0.12393063,107.47178539369743,1100.0,1.0
0.12452732999999999,0.12456835,107.59426898464423,1100.0,1.0
0.12516505,0.12520607,107.71800621687123,1100.0,1.0
0.12577312000000002,0.12581414000000002,107.84066352407584,1100.0,1.0
0.12638119,0.12642221,107.96110156763086,1100.0,1.0
0.127020505,0.127061525,108.08162487709134,1100.0,1.0
0.12765982,0.12770084,108.1991005744666,1100.0,1.0
0.128266375,0.128307395,108.31032864895539,1100.0,1.0
0.12887293,0.12891395,108.41808318404573,1100.0,1.0
0.12943444999999998,0.12947546999999998,108.52717734586521,1100.0,1.0
0.12999597,0.13003699,108.64068039357497,1100.0,1.0
0.13063450999999998,0.13067552999999998,108.75965172165986,1100.0,1.0
0.13127305,0.13131407,108.88165925043705,1100.0,1.0
0.13189407,0.13193509,109.00323050440926,1100.0,1.0
0.13251509,0.13255611,109.12350397903027,1100.0,1.0
0.133152205,0.133193225,109.24161188657584,1100.0,1.0
0.13378932,0.13383034,109.36043937811166,1100.0,1.0
0.13441799,0.13445901,109.47575656740888,1100.0,1.0
0.13504665999999999,0.13508768,109.58088696062583,1100.0,1.0
0.13565467999999997,0.13569569999999997,109.6776866750832,1100.0,1.0
0.1362627,0.13630372,109.76605157181899,1100.0,1.0
0.13687450499999998,0.13691552499999998,109.85148093226513,1100.0,1.0
0.13748631,0.13752733,109.94308468407105,1100.0,1.0
0.138083475,0.138124495,110.04308348133348,1100.0,1.0
0.13868064,0.13872166,110.15304514617368,1100.0,1.0
0.139327865,0.139368885,110.27255514616769,1100.0,1.0
0.13997509,0.14001611,110.3908464968962,1100.0,1.0
0.14060149,0.14064251,110.50109837699397,1100.0,1.0
0.14122789,0.14126891,110.60617575402838,1100.0,1.0
0.1418428,0.14188382,110.70604144953948,1100.0,1.0
0.14245771,0.14249873,110.80437905840243,1100.0,1.0
0.14308259,0.14312361,110.90670580765949,1100.0,1.0
0.14370747,0.14374849,111.01077427276722,1100.0,1.0
0.14429595,0.14433697,111.11700597845295,1100.0,1.0
0.14488443,0.14492545,111.22812250398337,1100.0,1.0
0.14550775,0.14554877,111.33839164129391,1100.0,1.0
0.14613107,0.14617209,111.44424597312307,1100.0,1.0
0.14671167000000002,0.14675269000000002,111.54770590553836,1100.0,1.0
0.14729227,0.14733329,111.6475975729457,1100.0,1.0
0.147926415,0.147967435,111.74457447098689,1100.0,1.0
0.14856056,0.14860158,111.84212384137093,1100.0,1.0
0.14915505,0.14919607000000001,111.93963295870527,1100.0,1.0
0.14974954,0.14979056,112.03982137275791,1100.0,1.0
0.15041956,0.15046058,112.14471070271063,1100.0,1.0
0.15108958,0.1511306,112.24944422826196,1100.0,1.0
0.15169492499999998,0.15173594499999998,112.34699280497462,1100.0,1.0
0.15230027,0.15234129,112.43307846212878,1100.0,1.0
0.152900085,0.152941105,112.5105186412791,1100.0,1.0
0.1534999,0.15354092,112.58732482370553,1100.0,1.0
0.15411298,0.154154,112.66757379200638,1100.0,1.0
0.15472606,0.15476708,112.74784371035003,1100.0,1.0
0.15535865999999998,0.15539967999999998,112.830999139037,1100.0,1.0
0.15599126,0.15603228,112.92176431683474,1100.0,1.0
0.156624715,0.156665735,113.01918046740143,1100.0,1.0
0.15725817,0.15729919,113.11924799644508,1100.0,1.0
0.15783898000000002,0.15788000000000002,113.21693375543995,1100.0,1.0
0.15841979,0.15846081,113.31304930418905,1100.0,1.0
0.15906104,0.15910206,113.4096765658939,1100.0,1.0
0.15970229,0.15974331,113.50515602305758,1100.0,1.0
0.16030344,0.16034446,113.59405502317468,1100.0,1.0
0.16090459,0.16094561,113.67342355049891,1100.0,1.0
0.161537985,0.161579005,113.75137081965269,1100.0,1.0
0.16217138,0.1622124,113.8336662630096,1100.0,1.0
0.162767635,0.162808655,113.92236955382656,1100.0,1.0
0.16336388999999998,0.16340491,114.02180641150692,1100.0,1.0
0.16399884999999997,0.16403986999999998,114.12847619545381,1100.0,1.0
0.16463381,0.16467483,114.23917386826912,1100.0,1.0
0.165231595,0.165272615,114.34812822033138,1100.0,1.0
0.16582938,0.1658704,114.44256942473636,1100.0,1.0
0.16644692,0.16648794,114.51822731102214,1100.0,1.0
0.16706446,0.16710548,114.5832183321608,1100.0,1.0
0.167676355,0.167717375,114.64677506673537,1100.0,1.0
0.16828825,0.16832927,114.71716840304524,1100.0,1.0
0.16892319,0.16896421,114.79785833266777,1100.0,1.0
0.16955813,0.16959915,114.88272282916611,1100.0,1.0
0.170152505,0.170193525,114.97031856609198,1100.0,1.0
0.17074688,0.1707879,115.05783059119443,1100.0,1.0
0.17136741,0.17140843,115.14054218982554,1100.0,1.0
0.17198794,0.17202896,115.22381710209679,1100.0,1.0
0.17261884500000002,0.17265986500000002,115.30880197248389,1100.0,1.0
0.17324975,0.17329077,115.39336703628588,1100.0,1.0
0.17383676,0.17387778,115.47861710540852,1100.0,1.0
0.17442377,0.17446479,115.56130215273471,1100.0,1.0
0.17504342,0.17508444,115.63761491112946,1100.0,1.0
0.17566307,0.17570409,115.70800648353998,1100.0,1.0
0.176315475,0.176356495,115.77744636403952,1100.0,1.0
0.17696788,0.1770089,115.85085018032538,1100.0,1.0
0.177582685,0.177623705,115.9325341633942,1100.0,1.0
0.17819749,0.17823851,116.02456311874693,1100.0,1.0
0.17878417,0.17882519,116.12058533178002,1100.0,1.0
0.17937085,0.17941187,116.21465667866195,1100.0,1.0
0.17997433499999999,0.180015355,116.30368764637734,1100.0,1.0
0.18057782,0.18061884,116.38398903703121,1100.0,1.0
0.181207675,0.18124869500000002,116.45496590378062,1100.0,1.0
0.18183753,0.18187855,116.52163438471966,1100.0,1.0
0.18245534,0.18249636,116.58767998836478,1100.0,1.0
0.18307315,0.18311417,116.656273764034,1100.0,1.0
0.18363699,0.18367801,116.73078589589514,1100.0,1.0
0.18420083,0.18424185,116.80645216898164,1100.0,1.0
0.18485236500000002,0.18489338500000002,116.88057548705386,1100.0,1.0
0.1855039,0.18554492,116.95564015335302,1100.0,1.0
0.186136935,0.186177955,117.02997200599977,1100.0,1.0
0.18676997,0.18681099,117.10615936533188,1100.0,1.0
0.18736818,0.1874092,117.18190454059847,1100.0,1.0
0.18796639,0.18800741,117.24646948151934,1100.0,1.0
0.188588,0.18862902,117.30274855034095,1100.0,1.0
0.18920961,0.18925063,117.35618955185532,1100.0,1.0
0.18984171,0.18988273,117.41109698493966,1100.0,1.0
0.19047381,0.19051483,117.4802885090437,1100.0,1.0
0.19105802,0.19109904,117.56234133479539,1100.0,1.0
0.19164223,0.19168325,117.64374577225514,1100.0,1.0
0.192246655,0.192287675,117.723701913174,1100.0,1.0
0.19285108,0.1928921,117.79815931575152,1100.0,1.0
0.19348226000000002,0.19352328000000002,117.86176796671097,1100.0,1.0
0.19411344,0.19415446,117.92328902525185,1100.0,1.0
0.194716065,0.194757085,117.9892491391584,1100.0,1.0
0.19531869,0.19535971,118.06664892302973,1100.0,1.0
0.19591227,0.19595329,118.15713652636391,1100.0,1.0
0.19650585,0.19654687,118.24455113994873,1100.0,1.0
0.19717200499999998,0.197213025,118.3175925004325,1100.0,1.0
0.19783815999999999,0.19787918,118.38228780559336,1100.0,1.0
0.198469245,0.198510265,118.44132325164439,1100.0,1.0
0.19910033,0.19914135,118.49358387743473,1100.0,1.0
0.19968629,0.19972731,118.54523073914473,1100.0,1.0
0.20027224999999999,0.20031327,118.60094327606136,1100.0,1.0
0.200924525,0.200965545,118.66500414736534,1100.0,1.0
0.2015768,0.20161782,118.73889131069623,1100.0,1.0
0.202213515,0.202254535,118.81430547836396,1100.0,1.0
0.20285023,0.20289125,118.88592019663622,1100.0,1.0
0.203431865,0.203472885,118.95568616262037,1100.0,1.0
0.2040135,0.20405452,119.02399727485228,1100.0,1.0
0.20465508999999998,0.20469611,119.08497773912828,1100.0,1.0
0.20529668,0.2053377,119.13754733324768,1100.0,1.0
0.20587642,0.20591744,119.18453103381243,1100.0,1.0
0.20645616,0.20649718,119.22770155011798,1100.0,1.0
0.20707949,0.20712051,119.27376303469183,1100.0,1.0
0.20770282,0.20774384,119.32221822068986,1100.0,1.0
0.20831039,0.20835141000000001,119.37116732266128,1100.0,1.0
0.20891795999999999,0.20895898,119.42269438171112,1100.0,1.0
0.20956268499999997,0.20960370499999997,119.48433047312277,1100.0,1.0
0.21020740999999998,0.21024843,119.56154324853631,1100.0,1.0
0.2108099,0.21085092,119.64775048549306,1100.0,1.0
0.21141239,0.21145341,119.73403299923068,1100.0,1.0
0.212589655,0.212630675,119.8163690268423,1100.0,1.0
0.21376692,0.21380794,119.89716937628286,1100.0,1.0
0.214394805,0.214435825,119.97435247659965,1100.0,1.0
0.21502269,0.21506371,120.04592273598138,1100.0,1.0
0.215608115,0.215649135,120.10803405865282,1100.0,1.0
0.21619354,0.21623456,120.16149170851904,1100.0,1.0
0.216779655,0.216820675,120.21314090685686,1100.0,1.0
0.21736576999999999,0.21740679,120.2619241260322,1100.0,1.0
0.218022655,0.218063675,120.30464531046209,1100.0,1.0
0.21867954,0.21872056,120.3437611729212,1100.0,1.0
0.21929716,0.21933818,120.38522830765967,1100.0,1.0
0.21991478,0.2199558,120.43018710960396,1100.0,1.0
0.22055993499999998,0.220600955,120.47980934924249,1100.0,1.0
0.22120509,0.22124611,120.53548812080089,1100.0,1.0
0.22177742,0.22181844,120.5921875397439,1100.0,1.0
0.22234974999999998,0.22239077,120.64608931511015,1100.0,1.0
0.222986405,0.223027425,120.69737429932756,1100.0,1.0
0.22362305999999998,0.22366408,120.745433087549,1100.0,1.0
0.22423368999999999,0.22427471,120.78894101632612,1100.0,1.0
0.22484432,0.22488534,120.82822218422514,1100.0,1.0
0.22545903,0.22550005,120.86603403020354,1100.0,1.0
0.22607374,0.22611476,120.907040729303,1100.0,1.0
0.226692615,0.226733635,120.95394986435535,1100.0,1.0
0.22731149,0.22735251,121.00174472264109,1100.0,1.0
0.227924375,0.22796539500000002,121.04843403591741,1100.0,1.0
0.22853726,0.22857828,121.09806976225377,1100.0,1.0
0.22914749499999998,0.22918851499999998,121.15058766297072,1100.0,1.0
0.22975773,0.22979875,121.20629081358133,1100.0,1.0
0.23037889,0.23041991,121.26000845065418,1100.0,1.0
0.23100004999999998,0.23104107,121.30355998933777,1100.0,1.0
0.231605075,0.231646095,121.34023186452464,1100.0,1.0
0.2322101,0.23225112,121.37542399751781,1100.0,1.0
0.23284968,0.2328907,121.40884318948443,1100.0,1.0
0.23348926,0.23353028,121.44396713081859,1100.0,1.0
0.23409575999999999,0.23413678,121.48382672378631,1100.0,1.0
0.23470226,0.23474328,121.52616359872754,1100.0,1.0
0.235299335,0.235340355,121.57140832890154,1100.0,1.0
0.23589641,0.23593743,121.61711950717142,1100.0,1.0
0.23654859,0.23658961,121.65551735210776,1100.0,1.0
0.23720077,0.23724179,121.6864778373266,1100.0,1.0
0.23780953500000002,0.23785055500000002,121.71718710137321,1100.0,1.0
0.2384183,0.23845932,121.75347663515292,1100.0,1.0
0.23904142,0.23908244,121.79275552602519,1100.0,1.0
0.23966454,0.23970556,121.8288357096085,1100.0,1.0
0.24028502000000002,0.24032604000000002,121.85939108404862,1100.0,1.0
0.2409055,0.24094652,121.88418291218579,1100.0,1.0
0.24151314000000002,0.24155416000000002,121.90814964223698,1100.0,1.0
0.24212078,0.2421618,121.93259173654127,1100.0,1.0
0.24274281,0.24278383,121.9578178469476,1100.0,1.0
0.24336484,0.24340586,121.99264325144898,1100.0,1.0
0.243980805,0.244021825,122.03954243076524,1100.0,1.0
0.24459677,0.24463779,122.09101702298732,1100.0,1.0
0.24517234999999998,0.24521336999999999,122.13839846637812,1100.0,1.0
0.24574793,0.24578895,122.1746936475321,1100.0,1.0
0.246372225,0.246413245,122.19996832011421,1100.0,1.0
0.24699652,0.24703754,122.22101317148837,1100.0,1.0
0.24764563,0.24768665,122.24218847194808,1100.0,1.0
0.24829473999999999,0.24833576,122.26846308498014,1100.0,1.0
0.248924085,0.248965105,122.30246469982131,1100.0,1.0
0.24955343,0.24959445,122.33710980381328,1100.0,1.0
0.25014221999999997,0.25018324,122.37096984060928,1100.0,1.0
0.25073101,0.25077203,122.40569404883898,1100.0,1.0
0.25138945999999995,0.25143048,122.437991128184,1100.0,1.0
0.25204791,0.25208893,122.47141536245675,1100.0,1.0
0.25263472,0.25267574,122.50727762980365,1100.0,1.0
0.25322153,0.25326255,122.54163133429287,1100.0,1.0
0.253836665,0.25387768499999996,122.57396849125757,1100.0,1.0
0.2544518,0.25449282,122.60184150391294,1100.0,1.0
0.25510234,0.25514336000000004,122.62276563696985,1100.0,1.0
0.25575288,0.2557939,122.64347097000787,1100.0,1.0
0.25636612000000003,0.25640714,122.66660051012136,1100.0,1.0
0.25697936,0.25702038,122.68577526614412,1100.0,1.0
0.25756213,0.25760315,122.70418475308956,1100.0,1.0
0.2581449,0.25818592,122.72798648318941,1100.0,1.0
0.25879435500000003,0.258835375,122.75352897206068,1100.0,1.0
0.25944381,0.25948483,122.77671092853515,1100.0,1.0
0.260059345,0.260100365,122.79826211800982,1100.0,1.0
0.26067488,0.2607159,122.8226161268772,1100.0,1.0
0.26127022499999997,0.261311245,122.84922042270091,1100.0,1.0
0.26186557,0.26190659,122.8672975565899,1100.0,1.0
0.262482585,0.262523605,122.87472951574412,1100.0,1.0
0.2630996,0.26314062,122.8824269645028,1100.0,1.0
0.263717355,0.263758375,122.8991180362196,1100.0,1.0
0.26433511,0.26437613,122.92407920750426,1100.0,1.0
0.26491517,0.26495619,122.95219653663004,1100.0,1.0
0.26549522999999997,0.26553625,122.98366348290693,1100.0,1.0
0.2661565,0.26619751999999997,123.01759819166095,1100.0,1.0
0.26681777,0.26685879,123.04540469661039,1100.0,1.0
0.267409805,0.267450825,123.06134565890976,1100.0,1.0
0.26800184,0.26804286,123.0696156349977,1100.0,1.0
0.26864019,0.26868121,123.0774534851078,1100.0,1.0
0.26927854,0.26931956,123.08953717477654,1100.0,1.0
0.26989311,0.26993413,123.10779378526809,1100.0,1.0
0.27050768,0.2705487,123.1324202415699,1100.0,1.0
0.27111946499999995,0.271160485,123.16030786796398,1100.0,1.0
0.27173125,0.27177227,123.18351486709318,1100.0,1.0
0.272340275,0.27238129499999997,123.20054796307265,1100.0,1.0
0.2729493,0.27299032,123.21782899930678,1100.0,1.0
0.27358026,0.27362127999999997,123.23484532857844,1100.0,1.0
0.27421122,0.27425224,123.24851367655728,1100.0,1.0
0.274811185,0.27485220499999996,123.26233389949098,1100.0,1.0
0.27541115,0.27545217,123.28047509316129,1100.0,1.0
0.276068395,0.27610941499999997,123.30219493295493,1100.0,1.0
0.27672564,0.27676666,123.32265488932083,1100.0,1.0
0.27732003,0.27736105,123.3374785196595,1100.0,1.0
0.27791442,0.27795544,123.34959075002557,1100.0,1.0
0.27851306,0.27855408000000004,123.36373317252261,1100.0,1.0
0.2791117,0.27915272,123.37891146348763,1100.0,1.0
0.279778455,0.27981947500000004,123.38966108962912,1100.0,1.0
0.28044521,0.28048623,123.39520469319577,1100.0,1.0
0.28103829,0.28107930999999997,123.3996922546366,1100.0,1.0
0.28163137,0.28167239,123.40062361526482,1100.0,1.0
0.28226067499999996,0.282301695,123.40072504306887,1100.0,1.0
0.28288998,0.282931,123.40855268025267,1100.0,1.0
0.28349875,0.28353976999999997,123.42365824881294,1100.0,1.0
0.28410752,0.28414854,123.44338882448106,1100.0,1.0
0.284702735,0.28474375500000004,123.46673141358008,1100.0,1.0
0.28529795,0.28533897,123.48921007896988,1100.0,1.0
0.285933185,0.28597420500000004,123.5057964050635,1100.0,1.0
0.28656842,0.28660944,123.51409048401968,1100.0,1.0
0.287143665,0.287184685,123.51475893860818,1100.0,1.0
0.28771891,0.28775993,123.51550782060862,1100.0,1.0
0.28835564999999996,0.28839667,123.52306568422536,1100.0,1.0
0.28899239,0.28903341,123.5360542834417,1100.0,1.0
0.28964068,0.2896817,123.55010684191586,1100.0,1.0
0.29028897,0.29032999,123.56110078818612,1100.0,1.0
0.290869985,0.290911005,123.56929006371813,1100.0,1.0
0.291451,0.29149202,123.57725851220836,1100.0,1.0
0.292104505,0.292145525,123.58351122567527,1100.0,1.0
0.29275801,0.29279903,123.58844306441708,1100.0,1.0
0.29335121,0.29339223000000003,123.59362738669749,1100.0,1.0
0.29394441,0.29398543,123.59754170336159,1100.0,1.0
0.29457431,0.29461533,123.60123694013821,1100.0,1.0
0.29520421,0.29524523,123.60651486289497,1100.0,1.0
0.29584216,0.29588318,123.60978897239595,1100.0,1.0
0.29648011,0.29652113,123.60985280736475,1100.0,1.0
0.29712248500000005,0.297163505,123.60958139500904,1100.0,1.0
0.29776486,0.29780588,123.60727870363813,1100.0,1.0
0.298368265,0.298409285,123.60375268093496,1100.0,1.0
0.29897167,0.29901269,123.59925680205987,1100.0,1.0
0.299583035,0.299624055,123.59617129217624,1100.0,1.0
0.3001944,0.30023542,123.59914155623397,1100.0,1.0
0.30078478499999994,0.300825805,123.61114709376493,1100.0,1.0
0.30137516999999997,0.30141619,123.63516740430096,1100.0,1.0