File: datasets/steel_spring/csv/BS2V-1050-10.0.csv
Time(s),Strain(%),Stress(MPa),Temp(C),SR(%/s)
0.0,6.311e-05,0.3982199999999979,1050.0,10.0
3.325000000000001e-08,6.344249999999999e-05,0.3968371612499987,1050.0,10.0
6.650000000000002e-08,6.377499999999999e-05,0.3954543224999991,1050.0,10.0
9.975000000000003e-08,6.41075e-05,0.3940714837499994,1050.0,10.0
1.3300000000000004e-07,6.444e-05,0.3926886449999995,1050.0,10.0
1.6625000000000005e-07,6.47725e-05,0.39096009656250075,1050.0,10.0
1.9950000000000006e-07,6.5105e-05,0.3895772578125009,1050.0,10.0
2.3275000000000007e-07,6.543749999999998e-05,0.3881944190625017,1050.0,10.0
2.660000000000001e-07,6.576999999999999e-05,0.3868115803125015,1050.0,10.0
2.992500000000001e-07,6.610249999999999e-05,0.38542874156250057,1050.0,10.0
3.325000000000001e-07,6.6435e-05,0.3840459028125003,1050.0,10.0
3.657500000000001e-07,6.67675e-05,0.3826630640625005,1050.0,10.0
3.990000000000001e-07,6.709999999999999e-05,0.3806038276960234,1050.0,10.0
4.3225000000000013e-07,6.743249999999998e-05,0.3786509085700766,1050.0,10.0
4.6550000000000014e-07,6.776499999999999e-05,0.3777574957376905,1050.0,10.0
4.987500000000001e-07,6.809749999999999e-05,0.37858348931250185,1050.0,10.0
5.320000000000002e-07,6.843e-05,0.3814955004687523,1050.0,10.0
6.324375000000002e-07,6.943437499999999e-05,0.38656685144128994,1050.0,10.0
7.328750000000001e-07,7.043874999999999e-05,0.3935775755255696,1050.0,10.0
8.333125e-07,7.144312499999999e-05,0.40201441707765245,1050.0,10.0
9.3375e-07,7.244749999999999e-05,0.41107083151420487,1050.0,10.0
1.0341874999999997e-06,7.345187499999999e-05,0.4196469853124988,1050.0,10.0
1.1346249999999997e-06,7.445624999999998e-05,0.42794268156249793,1050.0,10.0
1.2350624999999997e-06,7.546062499999998e-05,0.4362383778124982,1050.0,10.0
1.3354999999999997e-06,7.6465e-05,0.4445340740624992,1050.0,10.0
1.4359374999999998e-06,7.7469375e-05,0.4528297703125002,1050.0,10.0
1.5363749999999998e-06,7.847375e-05,0.4611254665625016,1050.0,10.0
1.6368124999999998e-06,7.9478125e-05,0.46942116281250357,1050.0,10.0
1.7372499999999995e-06,8.04825e-05,0.4808412115458145,1050.0,10.0
1.8376874999999993e-06,8.1486875e-05,0.49177016964489095,1050.0,10.0
1.9381249999999993e-06,8.249125e-05,0.49780515556143845,1050.0,10.0
2.0385624999999993e-06,8.3495625e-05,0.49589802053125337,1050.0,10.0
2.1389999999999993e-06,8.45e-05,0.4843553485742216,1050.0,10.0
2.2061249999999996e-06,8.517124999999999e-05,0.4628384564943199,1050.0,10.0
2.27325e-06,8.584249999999999e-05,0.43236339387961703,1050.0,10.0
2.3403749999999996e-06,8.651374999999999e-05,0.39530094310227243,1050.0,10.0
2.4075e-06,8.7185e-05,0.16934150855859315,1050.0,10.0
2.474625e-06,8.785625000000001e-05,-0.025158259928977952,1050.0,10.0
2.54175e-06,8.852750000000001e-05,0.0730420256463061,1050.0,10.0
2.608875e-06,8.919875000000001e-05,0.644144571093751,1050.0,10.0
2.6760000000000003e-06,8.987e-05,1.7889814147656302,1050.0,10.0
2.0538062499999996e-05,0.000268490625,3.5277189643323994,1050.0,10.0
3.8400124999999993e-05,0.00044711125,5.799857996782692,1050.0,10.0
5.6262187499999994e-05,0.000625731875,8.464233658423328,1050.0,10.0
7.412424999999999e-05,0.0008043525000000001,11.296857392271706,1050.0,10.0
9.198631249999998e-05,0.0009829731250000002,13.997730365123168,1050.0,10.0
0.00010984837499999999,0.00116159375,16.624847224210185,1050.0,10.0
0.0001277104375,0.001340214375,19.257449915562585,1050.0,10.0
0.0001455725,0.001518835,21.896708126230557,1050.0,10.0
0.00016303231249999996,0.0016934331250000002,24.54285579362415,1050.0,10.0
0.00018049212499999997,0.0018680312500000001,27.195191105513235,1050.0,10.0
0.00019795193749999997,0.002042629375,29.852076500027554,1050.0,10.0
0.00021541174999999997,0.0022172275,32.53152112770748,1050.0,10.0
0.00023287156249999998,0.002391825625,35.2061982816147,1050.0,10.0
0.000250331375,0.00256642375,37.847740345618625,1050.0,10.0
0.0002677911875,0.002741021875,40.4369616795314,1050.0,10.0
0.000285251,0.00291562,42.96270647736344,1050.0,10.0
0.0003427075,0.003490185,45.42274357791684,1050.0,10.0
0.00040016400000000005,0.00406475,47.82376646478533,1050.0,10.0
0.00045762050000000006,0.004639315,50.181393266354334,1050.0,10.0
0.0005150770000000001,0.00521388,52.520166755800965,1050.0,10.0
0.0005725335,0.005788445,54.873554351093944,1050.0,10.0
0.0006299900000000001,0.00636301,57.23547613796896,1050.0,10.0
0.0006874465000000001,0.006937575,59.59739792484399,1050.0,10.0
0.0007449030000000001,0.00751214,61.959319711719004,1050.0,10.0
0.0008023595000000001,0.008086705,64.32124149859402,1050.0,10.0
0.0008598160000000001,0.00866127,66.68316328546905,1050.0,10.0
0.0009172725000000002,0.009235835000000001,69.04508507234407,1050.0,10.0
0.0009747290000000001,0.0098104,71.46412843892044,1050.0,10.0
0.0010321855,0.010384965,73.87419334581473,1050.0,10.0
0.001089642,0.01095953,76.1947832579465,1050.0,10.0
0.0011470985000000002,0.011534095000000001,78.37016980487533,1050.0,10.0
0.0012045550000000002,0.01210866,80.36939278080112,1050.0,10.0
0.001283952875,0.01290263875,82.18626014456379,1050.0,10.0
0.0013633507500000002,0.013696617500000001,83.83934801964345,1050.0,10.0
0.001442748625,0.014490596250000001,85.37200069416032,1050.0,10.0
0.0015221465,0.015284575,86.85233062087492,1050.0,10.0
0.0016015443750000001,0.01607855375,88.37321841718776,1050.0,10.0
0.00168094225,0.0168725325,89.91779077093773,1050.0,10.0
0.001760340125,0.01766651125,91.46236312468771,1050.0,10.0
0.001839738,0.01846049,93.00693547843774,1050.0,10.0
0.001919135875,0.019254468749999996,94.55150783218781,1050.0,10.0
0.00199853375,0.020048447499999997,96.09608018593784,1050.0,10.0
0.002077931625,0.020842426249999997,97.64065253968788,1050.0,10.0
0.0021573295,0.021636404999999997,99.2172393257504,1050.0,10.0
0.002236727375,0.022430383749999998,100.78879403302123,1050.0,10.0
0.00231612525,0.023224362499999998,102.31020147233376,1050.0,10.0
0.002395523125,0.02401834125,103.7502280511879,1050.0,10.0
0.0024749209999999997,0.02481232,105.09152177375034,1050.0,10.0
0.0025431333749999997,0.025494443749999998,106.33061224085458,1050.0,10.0
0.0026113457499999998,0.026176567499999998,107.47791065000042,1050.0,10.0
0.002679558125,0.026858691249999997,108.55770979535464,1050.0,10.0
0.0027477705,0.027540815,109.60818406775059,1050.0,10.0
0.002815982875,0.028222938750000003,110.6813894546881,1050.0,10.0
0.00288419525,0.028905062500000002,111.76786911843806,1050.0,10.0
0.002952407625,0.02958718625,112.85434878218804,1050.0,10.0
0.00302062,0.03026931,113.94082844593802,1050.0,10.0
0.003088832375,0.030951433750000003,115.0273081096879,1050.0,10.0
0.00315704475,0.031633557500000006,116.11378777343778,1050.0,10.0
0.003225257125,0.032315681250000006,117.20026743718789,1050.0,10.0
0.0032934695,0.032997805000000005,118.30791117032331,1050.0,10.0
0.003361681875,0.033679928750000004,119.41222830176672,1050.0,10.0
0.00342989425,0.034362052500000004,120.4833941266934,1050.0,10.0
0.003498106625,0.03504417625,121.50076077253209,1050.0,10.0
0.003566319,0.0357263,122.45285719896563,1050.0,10.0
0.0036397474375000002,0.036460584375,123.33738919793058,1050.0,10.0
0.003713175875,0.03719486875,124.16123939361724,1050.0,10.0
0.0037866043124999997,0.037929153125000004,124.94046724246985,1050.0,10.0
0.00386003275,0.0386634375,125.70030903318667,1050.0,10.0
0.003933461187499999,0.039397721875,126.47517788671914,1050.0,10.0
0.004006889624999999,0.040132006250000005,127.25882208609434,1050.0,10.0
0.004080318062499999,0.040866290625,128.04246628546971,1050.0,10.0
0.0041537464999999996,0.041600575,128.82611048484497,1050.0,10.0
0.0042271749375,0.042334859375,129.6097546842199,1050.0,10.0
0.004300603375,0.04306914375,130.39339888359464,1050.0,10.0
0.0043740318125,0.043803428125,131.17704308296942,1050.0,10.0
0.00444746025,0.0445377125,131.97324882061613,1050.0,10.0
0.0045208886875,0.045271996875,132.7674801159331,1050.0,10.0
0.0045943171250000005,0.04600628125,133.54203507216823,1050.0,10.0
0.004667745562500001,0.046740565625,134.28465853003172,1050.0,10.0
0.004741174,0.04747485,134.98854206769582,1050.0,10.0
0.0048185713125000005,0.048248823125,135.65232400079506,1050.0,10.0
0.004895968625,0.04902279625,136.2800893824259,1050.0,10.0
0.0049733659375,0.049796769375,136.88137000314703,1050.0,10.0
0.00505076325,0.0505707425,137.4711443909795,1050.0,10.0
0.005128160562499999,0.051344715625,138.06983781140633,1050.0,10.0
0.005205557875,0.05211868875,138.67373967453148,1050.0,10.0
0.0052829551875000005,0.052892661875000004,139.27764153765656,1050.0,10.0
0.0053603525,0.053666635000000004,139.88154340078148,1050.0,10.0
0.0054377498125,0.054440608125000005,140.48544526390643,1050.0,10.0
0.005515147125,0.055214581250000005,141.0893471270314,1050.0,10.0
0.005592544437499999,0.055988554375000006,141.69324899015646,1050.0,10.0
0.00566994175,0.05676252750000001,142.30598708854427,1050.0,10.0
0.005747339062500001,0.05753650062500001,142.91733629358467,1050.0,10.0
0.005824736375,0.05831047375000001,143.51484445802382,1050.0,10.0
0.0059021336875,0.059084446875,144.08989086453192,1050.0,10.0
0.005979531,0.05985842,144.63768622570376,1050.0,10.0
0.0060550153125,0.060613263125,145.1572726840584,1050.0,10.0
0.006130499625,0.06136810625,145.651523812039,1050.0,10.0
0.0062059839374999995,0.062122949375,146.1271446120128,1050.0,10.0
0.00628146825,0.0628777925,146.59467151627166,1050.0,10.0
0.0063569525625000005,0.063632635625,147.06847238703136,1050.0,10.0
0.006432436875,0.06438747875,147.54593706265632,1050.0,10.0
0.0065079211875,0.065142321875,148.0234017382812,1050.0,10.0
0.0065834055,0.06589716500000001,148.5008664139058,1050.0,10.0
0.006658889812500001,0.06665200812500001,148.97833108953057,1050.0,10.0
0.006734374125,0.06740685125000001,149.45579576515584,1050.0,10.0
0.0068098584375,0.06816169437500001,149.9332604407812,1050.0,10.0
0.0068853427500000005,0.06891653750000001,150.41582988359085,1050.0,10.0
0.006960827062500001,0.06967138062500002,150.8975969510706,1050.0,10.0
0.007036311375000001,0.07042622375000002,151.3713679333676,1050.0,10.0
0.0071117956875,0.071181066875,151.83216256981382,1050.0,10.0
0.007187280000000001,0.07193591,152.27721404892725,1050.0,10.0
0.0072649645,0.07271275500000002,152.70596900841153,1050.0,10.0
0.007342649000000001,0.07348960000000002,153.12008753515588,1050.0,10.0
0.007420333500000001,0.07426644500000001,153.5234431652354,1050.0,10.0
0.007498018,0.07504329000000001,153.92212288391045,1050.0,10.0
0.007575702500000001,0.07582013500000001,154.32442712562678,1050.0,10.0
0.007653387000000001,0.07659698000000001,154.72884797812665,1050.0,10.0
0.0077310715000000006,0.07737382500000001,155.13326883062663,1050.0,10.0
0.007808756000000001,0.07815067,155.53768968312636,1050.0,10.0
0.007886440500000001,0.078927515,155.94211053562583,1050.0,10.0
0.007964125,0.07970436,156.34653138812584,1050.0,10.0
0.0080418095,0.080481205,156.75095224062576,1050.0,10.0
0.008119494000000001,0.08125805,157.16032670073545,1050.0,10.0
0.008197178500000001,0.082034895,157.56892254501494,1050.0,10.0
0.008274863,0.08281174,157.96975907981374,1050.0,10.0
0.008352547500000002,0.08358858499999999,158.3580035172197,1050.0,10.0
0.008430232000000001,0.08436543,158.7309709750595,1050.0,10.0
0.008507674687500001,0.085139856875,159.08812447689857,1050.0,10.0
0.008585117375,0.08591428375000001,159.43107495204094,1050.0,10.0
0.0086625600625,0.08668871062500001,159.76358123552922,1050.0,10.0
0.00874000275,0.08746313750000001,160.0915500681445,1050.0,10.0
0.0088174454375,0.08823756437500001,160.42303609640675,1050.0,10.0
0.008894888125,0.08901199125,160.75657605953162,1050.0,10.0
0.0089723308125,0.089786418125,161.09011602265684,1050.0,10.0
0.0090497735,0.090560845,161.42365598578226,1050.0,10.0
0.0091272161875,0.091335271875,161.75719594890734,1050.0,10.0
0.009204658875,0.09210969875,162.0907359120325,1050.0,10.0
0.0092821015625,0.092884125625,162.4242758751575,1050.0,10.0
0.00935954425,0.09365855249999999,162.7607711140741,1050.0,10.0
0.009436986937500001,0.09443297937499999,163.096801838097,1050.0,10.0
0.009514429625000001,0.09520740624999999,163.42820343093297,1050.0,10.0
0.0095918723125,0.095981833125,163.752092696687,1050.0,10.0
0.009669315,0.09675626,164.06686785986278,1050.0,10.0
0.009750385812499998,0.09756696812499999,164.37220856536047,1050.0,10.0
0.009831456624999999,0.09837767624999999,164.6690758784781,1050.0,10.0
0.009912527437499999,0.099188384375,164.9597122849124,1050.0,10.0
0.00999359825,0.0999990925,165.24764169075624,1050.0,10.0
0.0100746690625,0.100809800625,165.53766942250078,1050.0,10.0
0.010155739875,0.10162050875,165.82892251250064,1050.0,10.0
0.0102368106875,0.10243121687500001,166.12017560250047,1050.0,10.0
0.0103178815,0.103241925,166.41142869249964,1050.0,10.0
0.010398952312500001,0.10405263312499999,166.70268178249881,1050.0,10.0
0.010480023125000001,0.10486334124999999,166.9939348724982,1050.0,10.0
0.010561093937500002,0.105674049375,167.2851879624979,1050.0,10.0
0.01064216475,0.1064847575,167.57920637912,1050.0,10.0
0.010723235562499999,0.107295465625,167.87279013735724,1050.0,10.0
0.010804306375,0.10810617375,168.16204229996524,1050.0,10.0
0.0108853771875,0.10891688187500001,168.44426498731306,1050.0,10.0
0.010966448,0.10972759,168.71795937738383,1050.0,10.0
0.0110478640625,0.11054175062499999,168.9828257057747,1050.0,10.0
0.011129280125,0.11135591125,169.2397632656945,1050.0,10.0
0.0112106961875,0.112170071875,169.49087040796732,1050.0,10.0
0.01129211225,0.1129842325,169.73944454103167,1050.0,10.0
0.011373528312499999,0.11379839312500001,169.98998213093864,1050.0,10.0
0.011454944375,0.11461255375,170.2416663196887,1050.0,10.0
0.0115363604375,0.11542671437499999,170.4933505084389,1050.0,10.0
0.0116177765,0.116240875,170.74503469718871,1050.0,10.0
0.011699192562499999,0.117055035625,170.99671888593807,1050.0,10.0
0.011780608625,0.11786919625,171.2484030746882,1050.0,10.0
0.0118620246875,0.118683356875,171.50008726343833,1050.0,10.0
0.01194344075,0.1194975175,171.75285869457025,1050.0,10.0
0.0120248568125,0.12031167812499999,172.00545923123647,1050.0,10.0
0.012106272875,0.12112583874999999,172.25635671614984,1050.0,10.0
0.0121876889375,0.121939999375,172.50449042503342,1050.0,10.0
0.012269105,0.12275416,172.7492710666238,1050.0,10.0
0.012348714812500002,0.123550258125,172.99058078266756,1050.0,10.0
0.012428324625,0.12434635625,173.2287731479229,1050.0,10.0
0.0125079344375,0.125142454375,173.4646731701607,1050.0,10.0
0.01258754425,0.1259385525,173.69957729016187,1050.0,10.0
0.012667154062500002,0.126734650625,173.93525338171892,1050.0,10.0
0.012746763875,0.12753074874999998,174.17138028109358,1050.0,10.0
0.0128263736875,0.12832684687499998,174.4075071804684,1050.0,10.0
0.0129059835,0.129122945,174.6436340798435,1050.0,10.0
0.012985593312500002,0.129919043125,174.87976097921901,1050.0,10.0
0.013065203125,0.13071514125,175.11588787859472,1050.0,10.0
0.0131448129375,0.131511239375,175.35201477797006,1050.0,10.0
0.013224422750000001,0.1323073375,175.59035541819784,1050.0,10.0
0.013304032562500002,0.13310343562500002,175.82834809915857,1050.0,10.0
0.013383642375000001,0.13389953375000002,176.06287318604623,1050.0,10.0
0.0134632521875,0.134695631875,176.2917709316881,1050.0,10.0
0.013542862000000001,0.13549173,176.51384147654318,1050.0,10.0
0.013626300562500002,0.13632611562500002,176.72884484870406,1050.0,10.0
0.013709739125000002,0.13716050125,176.93750096389473,1050.0,10.0
0.013793177687500002,0.137994886875,177.14148962547176,1050.0,10.0
0.013876616250000001,0.1388292725,177.343450524425,1050.0,10.0
0.0139600548125,0.13966365812499998,177.54698323937646,1050.0,10.0
0.014043493375,0.14049804375,177.75143384687624,1050.0,10.0
0.0141269319375,0.141332429375,177.95588445437525,1050.0,10.0
0.0142103705,0.142166815,178.16033506187443,1050.0,10.0
0.0142938090625,0.143001200625,178.36478566937419,1050.0,10.0
0.014377247624999999,0.14383558625,178.56923627687382,1050.0,10.0
0.014460686187499999,0.14466997187500003,178.77368688437323,1050.0,10.0
0.01454412475,0.14550435750000001,178.97968007907622,1050.0,10.0
0.014627563312500001,0.146338743125,179.1854308074986,1050.0,10.0
0.014711001875,0.14717312875,179.38876523401512,1050.0,10.0
0.0147944404375,0.14800751437499998,179.58817839550008,1050.0,10.0
0.014877879,0.1488419,179.7828342013284,1050.0,10.0
0.0149622879375,0.149685989375,179.97256543337554,1050.0,10.0
0.015046696875000001,0.15053007875000002,180.15787374601632,1050.0,10.0
0.0151311058125,0.151374168125,180.3399296661255,1050.0,10.0
0.01521551475,0.1522182575,180.52057259307793,1050.0,10.0
0.015299923687500001,0.153062346875,180.70231079874935,1050.0,10.0
0.015384332625,0.15390643625,180.8846886137492,1050.0,10.0
0.0154687415625,0.154750525625,181.06706642874957,1050.0,10.0
0.015553150500000001,0.155594615,181.2494442437503,1050.0,10.0
0.015637559437500004,0.156438704375,181.43182205875107,1050.0,10.0
0.015721968375000003,0.15728279374999998,181.61419987375174,1050.0,10.0
0.0158063773125,0.158126883125,181.7965776887523,1050.0,10.0
0.015890786250000004,0.1589709725,181.98061892522082,1050.0,10.0
0.015975195187500003,0.159815061875,182.1643987024875,1050.0,10.0
0.016059604125,0.16065915125000002,182.34557290357856,1050.0,10.0
0.016144013062500004,0.16150324062500002,182.52251867828159,1050.0,10.0
0.016228422000000003,0.16234733,182.69433444314475,1050.0,10.0
0.016312347937500006,0.16318658937500002,182.86083988147797,1050.0,10.0
0.016396273875000006,0.16402584875,183.02257594335146,1050.0,10.0
0.016480199812500006,0.164865108125,183.18080484559738,1050.0,10.0
0.016564125750000006,0.1657043675,183.33751007181033,1050.0,10.0
0.016648051687500005,0.16654362687500002,183.49539637234477,1050.0,10.0
0.016731977625000005,0.16738288625,183.65397238421923,1050.0,10.0
0.016815903562500005,0.16822214562499999,183.8125483960942,1050.0,10.0
0.016899829500000005,0.169061405,183.97112440796917,1050.0,10.0
0.016983755437500005,0.169900664375,184.12970041984414,1050.0,10.0
0.017067681375000004,0.17073992375,184.28827643171988,1050.0,10.0
0.017151607312500004,0.17157918312499998,184.44685244359553,1050.0,10.0
0.017235533250000004,0.1724184425,184.60763639793922,1050.0,10.0
0.017319459187500004,0.173257701875,184.76807330441514,1050.0,10.0
0.017403385125000004,0.17409696125000002,184.92505169938246,1050.0,10.0
0.017487311062500004,0.17493622062500003,185.07641749262748,1050.0,10.0
0.017571237000000003,0.17577548,185.2209739673649,1050.0,10.0
0.017656468187500003,0.176627791875,185.35848178023738,1050.0,10.0
0.017741699375000003,0.17748010375,185.4896589613176,1050.0,10.0
0.017826930562500003,0.17833241562500002,185.61618091410512,1050.0,10.0
0.017912161750000002,0.17918472750000003,185.74068041552607,1050.0,10.0
0.017997392937500002,0.18003703937500004,185.86674761593557,1050.0,10.0
0.018082624125000002,0.18088935125000002,185.99373030468624,1050.0,10.0
0.0181678553125,0.181741663125,186.12071299343793,1050.0,10.0
0.0182530865,0.18259397500000002,186.24769568218977,1050.0,10.0
0.0183383176875,0.18344628687500003,186.37467837094022,1050.0,10.0
0.018423548875,0.18429859875000001,186.5016610596894,1050.0,10.0
0.0185087800625,0.185150910625,186.6286437484385,1050.0,10.0
0.01859401125,0.1860032225,186.7565869134378,1050.0,10.0
0.0186792424375,0.18685553437500002,186.88437910927044,1050.0,10.0
0.018764473625,0.18770784625,187.01066681926875,1050.0,10.0
0.0188497048125,0.188560158125,187.13451299343458,1050.0,10.0
0.018934936000000003,0.18941247,187.25539704843501,1050.0,10.0
0.019018920812500003,0.190252318125,187.373214867603,1050.0,10.0
0.019102905625000003,0.19109216625,187.48827880093657,1050.0,10.0
0.019186890437500003,0.19193201437500002,187.6013176651029,1050.0,10.0
0.019270875250000003,0.1927718625,187.71347674343647,1050.0,10.0
0.019354860062500003,0.193611710625,187.82631778593753,1050.0,10.0
0.019438844875000003,0.19445155875,187.93955707468908,1050.0,10.0
0.019522829687500003,0.19529140687500002,188.05279636344008,1050.0,10.0
0.019606814500000003,0.196131255,188.16603565218995,1050.0,10.0
0.019690799312500003,0.196971103125,188.27927494093984,1050.0,10.0
0.019774784125000004,0.19781095125,188.39251422968886,1050.0,10.0
0.019858768937500004,0.19865079937500002,188.50575351843756,1050.0,10.0
0.019942753750000004,0.1994906475,188.6210090009971,1050.0,10.0
0.020026738562500004,0.200330495625,188.7359475750451,1050.0,10.0
0.020110723375000004,0.20117034375,188.84772799184992,1050.0,10.0
0.020194708187500004,0.20201019187500002,188.95438323306035,1050.0,10.0
0.020278693000000004,0.20285004,189.0548205107019,1050.0,10.0
0.020360327187500006,0.20366638187500002,189.14882126717882,1050.0,10.0
0.020441961375000005,0.20448272375,189.23704117527475,1050.0,10.0
0.020523595562500004,0.205299065625,189.32101013815463,1050.0,10.0
0.020605229750000002,0.20611540750000001,189.40313228935997,1050.0,10.0
0.0206868639375,0.20693174937500003,189.48668599281083,1050.0,10.0
0.020768498125000003,0.20774809125000002,189.57107567906144,1050.0,10.0
0.020850132312500005,0.208564433125,189.65546536531215,1050.0,10.0
0.020931766500000004,0.20938077500000002,189.7398550515635,1050.0,10.0
0.021013400687500003,0.21019711687500003,189.8242447378144,1050.0,10.0
0.021095034875,0.21101345875000002,189.9086344240645,1050.0,10.0
0.0211766690625,0.211829800625,189.99302411031377,1050.0,10.0
0.021258303250000003,0.21264614250000002,190.07849797303157,1050.0,10.0
0.021339937437500005,0.213462484375,190.16380142318826,1050.0,10.0
0.021421571625000004,0.21427882625,190.24740662402533,1050.0,10.0
0.021503205812500002,0.215095168125,190.3282558424065,1050.0,10.0
0.02158484,0.21591151,190.40576144880944,1050.0,10.0
0.021666458,0.21672769,190.47980591732846,1050.0,10.0
0.021748076,0.21754387,190.55074182567637,1050.0,10.0
0.021829694000000004,0.21836005,190.61939185518492,1050.0,10.0
0.021911312000000002,0.21917623,190.68704879080286,1050.0,10.0
0.02199293,0.21999241,190.755475521095,1050.0,10.0
0.022074548000000003,0.22080859,190.82435178797056,1050.0,10.0
0.022156166000000005,0.22162477,190.89322805484417,1050.0,10.0
0.022237784000000003,0.22244095,190.96210432171839,1050.0,10.0
0.022319402000000002,0.22325713,191.03098058859374,1050.0,10.0
0.022401020000000004,0.22407331,191.09985685546852,1050.0,10.0
0.022482638000000006,0.22488949,191.16873312234256,1050.0,10.0
0.022564256000000005,0.22570567,191.23913758026657,1050.0,10.0
0.022645874000000003,0.22652185,191.30930183472086,1050.0,10.0
0.022727492000000002,0.22733803,191.37707233734258,1050.0,10.0
0.02280911,0.22815421,191.44095817003384,1050.0,10.0
0.022890728000000003,0.22897039,191.500131044963,1050.0,10.0
0.022970266250000003,0.22976577250000002,191.55442530456503,1050.0,10.0
0.0230498045,0.23056115500000002,191.6043379215392,1050.0,10.0
0.02312934275,0.23135653750000001,191.65102849884983,1050.0,10.0
0.023208881,0.23215192,191.69631926972517,1050.0,10.0
0.02328841925,0.2329473025,191.74269509765904,1050.0,10.0
0.0233679575,0.233742685,191.78970456578435,1050.0,10.0
0.023447495750000002,0.2345380675,191.83671403390974,1050.0,10.0
0.023527034000000002,0.23533345,191.88372350203412,1050.0,10.0
0.023606572250000003,0.2361288325,191.93073297015692,1050.0,10.0
0.023686110500000003,0.236924215,191.97774243828076,1050.0,10.0
0.023765648750000003,0.2377195975,192.02475190640703,1050.0,10.0
0.023845187000000004,0.23851498,192.0721088148952,1050.0,10.0
0.023924725250000004,0.23931036249999998,192.11941111216092,1050.0,10.0
0.024004263500000005,0.24010574499999998,192.16616918034867,1050.0,10.0
0.02408380175,0.24090112749999998,192.21204405325165,1050.0,10.0
0.024163340000000002,0.24169651,192.2568474163103,1050.0,10.0
0.0242401416875,0.24246452687500003,192.30054160661126,1050.0,10.0
0.024316943375000004,0.24323254375000003,192.34323961289053,1050.0,10.0
0.024393745062500003,0.24400056062500003,192.38520507553397,1050.0,10.0
0.024470546750000002,0.24476857750000003,192.42685228657396,1050.0,10.0
0.0245473484375,0.24553659437500003,192.4687461896854,1050.0,10.0
0.024624150125,0.24630461125000003,192.51078415343375,1050.0,10.0
0.024700951812500004,0.24707262812500003,192.55282211718335,1050.0,10.0
0.024777753500000003,0.24784064500000003,192.59486008093316,1050.0,10.0
0.024854555187500002,0.24860866187500003,192.63689804468368,1050.0,10.0
0.024931356875000005,0.24937667875000002,192.67893600843428,1050.0,10.0
0.025008158562500004,0.250144695625,192.72097397218457,1050.0,10.0
0.025084960250000003,0.2509127125,192.7630381289515,1050.0,10.0
0.025161761937500002,0.251680729375,192.8050981686607,1050.0,10.0
0.025238563625,0.25244874625,192.84711717974199,1050.0,10.0
0.025315365312500004,0.253216763125,192.88906960803317,1050.0,10.0
0.025392167000000004,0.25398478,192.93094125677948,1050.0,10.0
0.025469531187500005,0.25475842187500003,192.97272928662912,1050.0,10.0
0.025546895375000003,0.25553206375000004,193.01444221563503,1050.0,10.0
0.0256242595625,0.256305705625,193.05609991925803,1050.0,10.0
0.025701623750000003,0.2570793475,193.0977336303623,1050.0,10.0
0.025778987937500004,0.257852989375,193.1393859392179,1050.0,10.0
0.025856352125000003,0.25862663124999996,193.18104910859407,1050.0,10.0
0.0259337163125,0.25940027312499997,193.22271227796946,1050.0,10.0
0.026011080500000002,0.260173915,193.2643754473449,1050.0,10.0
0.026088444687500004,0.260947556875,193.30603861672031,1050.0,10.0
0.026165808875000002,0.26172119875,193.3477017860947,1050.0,10.0
0.0262431730625,0.262494840625,193.38936495546926,1050.0,10.0
0.02632053725,0.2632684825,193.431711608545,1050.0,10.0
0.026397901437500003,0.264042124375,193.47395083057825,1050.0,10.0
0.026475265625,0.26481576625000003,193.515119446706,1050.0,10.0
0.0265526298125,0.265589408125,193.5545506435626,1050.0,10.0
0.026629994,0.26636305,193.59187396927803,1050.0,10.0
0.0267055365625,0.267118475625,193.62701533347794,1050.0,10.0
0.026781079125000003,0.26787390125,193.6601970072839,1050.0,10.0
0.026856621687500002,0.26862932687499996,193.691937623313,1050.0,10.0
0.02693216425,0.2693847525,193.7230521756826,1050.0,10.0
0.0270077068125,0.270140178125,193.75465202000308,1050.0,10.0
0.027083249375,0.27089560375,193.78653526000338,1050.0,10.0
0.0271587919375,0.27165102937499996,193.8184185000024,1050.0,10.0
0.0272343345,0.272406455,193.85030174000136,1050.0,10.0
0.027309877062499998,0.273161880625,193.88218498000057,1050.0,10.0
0.027385419624999997,0.27391730625,193.91406821999985,1050.0,10.0
0.0274609621875,0.27467273187499996,193.94595145999864,1050.0,10.0
0.02753650475,0.2754281575,193.978250855298,1050.0,10.0
0.0276120473125,0.276183583125,194.01048483865537,1050.0,10.0
0.027687589875,0.27693900875,194.042066958157,1050.0,10.0
0.0277631324375,0.27769443437499997,194.07259120862992,1050.0,10.0
0.027838675,0.27844986,194.10183203164553,1050.0,10.0
0.0279154556875,0.279217666875,194.1297443155186,1050.0,10.0
0.027992236375,0.27998547375,194.15646339530616,1050.0,10.0
0.0280690170625,0.280753280625,194.1823050528088,1050.0,10.0
0.02814579775,0.2815210875,194.2077655165693,1050.0,10.0
0.0282225784375,0.282288894375,194.2335214618718,1050.0,10.0
0.028299359125,0.28305670125,194.2594499593732,1050.0,10.0
0.0283761398125,0.283824508125,194.2853784568752,1050.0,10.0
0.0284529205,0.284592315,194.31130695437665,1050.0,10.0
0.0285297011875,0.285360121875,194.33723545187675,1050.0,10.0
0.028606481875,0.28612792875,194.36316394937592,1050.0,10.0
0.0286832625625,0.286895735625,194.38909244687412,1050.0,10.0
0.02876004325,0.2876635425,194.4154717570636,1050.0,10.0
0.0288368239375,0.288431349375,194.441780207808,1050.0,10.0
0.028913604625,0.28919915625,194.46738250750872,1050.0,10.0
0.0289903853125,0.289966963125,194.49183883890808,1050.0,10.0
0.029067166,0.29073477,194.51490485908542,1050.0,10.0
0.0291428590625,0.29149170062499996,194.53653169945522,1050.0,10.0
0.029218552124999998,0.29224863125,194.5568659657682,1050.0,10.0
0.029294245187499998,0.293005561875,194.57624973811642,1050.0,10.0
0.029369938249999998,0.29376249249999997,194.5952205709279,1050.0,10.0
0.029445631312499998,0.294519423125,194.61451149296641,1050.0,10.0
0.029521324374999998,0.29527635375,194.63398933734098,1050.0,10.0
0.029597017437499998,0.296033284375,194.65346718171622,1050.0,10.0
0.0296727105,0.296790215,194.67294502609244,1050.0,10.0
0.029748403562500005,0.297547145625,194.69242287046933,1050.0,10.0
0.029824096625000004,0.29830407625,194.7119007148456,1050.0,10.0
0.029899789687500004,0.29906100687500003,194.73137855922064,1050.0,10.0
0.029975482750000004,0.2998179375,194.7512031775041,1050.0,10.0
0.030051175812500004,0.300574868125,194.77097328932044,1050.0,10.0
0.030126868875000004,0.30133179875000005,194.79020021598777,1050.0,10.0
0.030202561937500004,0.30208872937500003,194.80854564150007,1050.0,10.0
0.030278255000000004,0.30284566,194.82582161251983,1050.0,10.0
0.030354830562500004,0.30361141562500005,194.8419905383788,1050.0,10.0
0.030431406125000005,0.30437717125,194.85716519107882,1050.0,10.0
0.030507981687500005,0.305142926875,194.87160870529357,1050.0,10.0
0.030584557250000005,0.30590868250000003,194.885734578367,1050.0,10.0
0.030661132812500005,0.30667443812500006,194.9001066703124,1050.0,10.0
0.030737708375000006,0.30744019375000003,194.91462254656162,1050.0,10.0
0.030814283937500006,0.308205949375,194.92913842280967,1050.0,10.0
0.030890859500000003,0.30897170500000004,194.94365429905875,1050.0,10.0
0.0309674350625,0.30973746062500007,194.95817017530982,1050.0,10.0
0.031044010625,0.31050321625000005,194.97268605156071,1050.0,10.0
0.0311205861875,0.311268971875,194.98720192781227,1050.0,10.0
0.03119716175,0.31203472750000005,195.0015163246042,1050.0,10.0
0.0312737373125,0.31280048312500003,195.01586239025465,1050.0,10.0
0.031350312875,0.31356623875,195.03052405245506,1050.0,10.0
0.0314268884375,0.31433199437500003,195.04569787653384,1050.0,10.0
0.031503464,0.31509775,195.06149306545157,1050.0,10.0
0.031578988687500004,0.315852996875,195.07793145979875,1050.0,10.0
0.031654513375,0.31660824374999996,195.0949475378007,1050.0,10.0
0.0317300380625,0.31736349062499997,195.11238841531397,1050.0,10.0
0.03180556275,0.31811873749999997,195.13001384582893,1050.0,10.0
0.031881087437500004,0.318873984375,195.1474962204679,1050.0,10.0
0.031956612125000006,0.31962923125,195.1648950548426,1050.0,10.0
0.0320321368125,0.320384478125,195.1822938892166,1050.0,10.0
0.0321076615,0.321139725,195.19969272359103,1050.0,10.0
0.032183186187500004,0.321894971875,195.21709155796708,1050.0,10.0
0.032258710875,0.32265021875,195.23449039234256,1050.0,10.0
0.0323342355625,0.323405465625,195.25188922671776,1050.0,10.0
0.03240976025,0.3241607125,195.26989763131783,1050.0,10.0
0.032485284937500004,0.324915959375,195.28781022271193,1050.0,10.0
0.032560809625000006,0.32567120625,195.3047679859498,1050.0,10.0
0.0326363343125,0.326426453125,195.3201762183785,1050.0,10.0
0.032711859,0.3271817,195.3337045296332,1050.0,10.0
0.0327882141875,0.327945251875,195.3452868416413,1050.0,10.0
0.032864569375,0.32870880375,195.35512138861964,1050.0,10.0
0.0329409245625,0.329472355625,195.36367071707724,1050.0,10.0
0.03301727975,0.3302359075,195.37166168581922,1050.0,10.0
0.033093634937500005,0.33099945937499997,195.38008546594108,1050.0,10.0
0.033169990125,0.33176301124999996,195.38876199469073,1050.0,10.0
0.033246345312499995,0.33252656312499995,195.39743852343642,1050.0,10.0
0.033322700499999997,0.333290115,195.40611505218328,1050.0,10.0
0.0333990556875,0.33405366687500004,195.41479158093443,1050.0,10.0
0.033475410875,0.33481721875000003,195.42346810968868,1050.0,10.0
0.0335517660625,0.335580770625,195.43214463844197,1050.0,10.0
0.03362812125,0.3363443225,195.44076991419414,1050.0,10.0
0.03370447643749999,0.337107874375,195.44940324597422,1050.0,10.0
0.033780831624999993,0.33787142625,195.4581168602306,1050.0,10.0
0.033857186812499995,0.338634978125,195.4669607598874,1050.0,10.0
0.033933542,0.33939853,195.47596272434672,1050.0,10.0
0.034010316874999995,0.34016627875,195.48512830949284,1050.0,10.0
0.03408709174999999,0.3409340275,195.49444084768552,1050.0,10.0
0.034163866625,0.34170177625,195.50386144775618,1050.0,10.0
0.034240641499999995,0.342469525,195.5133289950158,1050.0,10.0
0.03431741637499999,0.34323727375,195.52276015125486,1050.0,10.0
0.03439419125,0.3440050225,195.53217005625237,1050.0,10.0
0.034470966124999995,0.34477277125,195.54157996124937,1050.0,10.0
0.03454774099999999,0.34554052,195.55098986624694,1050.0,10.0
0.034624515875,0.34630826875,195.56039977124487,1050.0,10.0
0.034701290749999995,0.3470760175,195.5698096762462,1050.0,10.0
0.03477806562499999,0.34784376625,195.57921958125058,1050.0,10.0
0.0348548405,0.348611515,195.5862770100011,1050.0,10.0
0.034931615374999996,0.34937926375,195.59568691500255,1050.0,10.0
0.03500839024999999,0.3501470125,195.6050968200034,1050.0,10.0
0.035085165125,0.35091476125,195.61450672500354,1050.0,10.0
0.035161939999999996,0.35168251,195.62391663000273,1050.0,10.0