File: datasets/steel_spring/csv/BS2V-1150-1.0.csv
Time(s),Strain(%),Stress(MPa),Temp(C),SR(%/s)
0.0,5.456e-05,0.8279370720846853,1150.0,1.0
8.03e-06,6.259e-05,0.36062719390530273,1150.0,1.0
1.606e-05,7.062e-05,1.1428214430741388,1150.0,1.0
9.646000000000001e-05,0.00015102,3.0732835121819835,1150.0,1.0
0.00017686,0.00023142,6.050777093819628,1150.0,1.0
0.00038608999999999996,0.00044065,11.093056311893982,1150.0,1.0
0.00059532,0.00064988,16.34423089721218,1150.0,1.0
0.00083679,0.0008913500000000001,22.219709689840993,1150.0,1.0
0.0010782600000000002,0.00113282,28.443227622323974,1150.0,1.0
0.0013761900000000002,0.0014307500000000002,34.35622061449255,1150.0,1.0
0.00167412,0.00172868,39.549740966670605,1150.0,1.0
0.00226795,0.00232251,43.64181727303804,1150.0,1.0
0.00286178,0.00291634,46.57834811048314,1150.0,1.0
0.003572055,0.003626615,48.47951228307592,1150.0,1.0
0.00428233,0.00433689,49.601780172834474,1150.0,1.0
0.00491268,0.00496724,50.37714519256837,1150.0,1.0
0.00554303,0.00559759,50.95978338142918,1150.0,1.0
0.006171545,0.006226105,51.56787008775779,1150.0,1.0
0.006800059999999999,0.00685462,52.20290718973129,1150.0,1.0
0.007448234999999999,0.007502795,52.85692825569721,1150.0,1.0
0.00809641,0.00815097,53.51509624200879,1150.0,1.0
0.00874816,0.00880272,54.163013614038164,1150.0,1.0
0.00939991,0.00945447,54.79885459603912,1150.0,1.0
0.009987494999999999,0.010042055,55.42031904331848,1150.0,1.0
0.010575079999999999,0.01062964,56.03746456307795,1150.0,1.0
0.011201284999999998,0.011255845,56.64653197382605,1150.0,1.0
0.01182749,0.01188205,57.23834131570296,1150.0,1.0
0.01243277,0.01248733,57.81324272347756,1150.0,1.0
0.013038049999999999,0.01309261,58.3715910157531,1150.0,1.0
0.013657705,0.013712265,58.90872648600024,1150.0,1.0
0.01427736,0.01433192,59.4287990407351,1150.0,1.0
0.014900435,0.014954994999999999,59.93180596881842,1150.0,1.0
0.015523509999999999,0.01557807,60.41703034548982,1150.0,1.0
0.01615833,0.01621289,60.89251944404569,1150.0,1.0
0.01679315,0.01684771,61.35984140770386,1150.0,1.0
0.017417845,0.017472405,61.80992971472754,1150.0,1.0
0.018042540000000003,0.0180971,62.241803829148,1150.0,1.0
0.018684390000000002,0.01873895,62.65992406909875,1150.0,1.0
0.01932624,0.0193808,63.06528261506468,1150.0,1.0
0.019974395,0.020028955,63.46095588184119,1150.0,1.0
0.02062255,0.02067711,63.847954995095925,1150.0,1.0
0.021249645,0.021304205,64.22265654430326,1150.0,1.0
0.021876740000000002,0.0219313,64.58669810763466,1150.0,1.0
0.022496355000000003,0.022550915,64.94749264084108,1150.0,1.0
0.023115970000000003,0.02317053,65.30713044589321,1150.0,1.0
0.02375013,0.023804690000000003,65.65947907074263,1150.0,1.0
0.024384290000000003,0.02443885,65.99661615439888,1150.0,1.0
0.02500273,0.025057290000000003,66.32248304998508,1150.0,1.0
0.025621170000000002,0.02567573,66.64699457278817,1150.0,1.0
0.026245895,0.026300455,66.97370436452303,1150.0,1.0
0.02687062,0.02692518,67.30045954712998,1150.0,1.0
0.027523685,0.027578245,67.62399555524263,1150.0,1.0
0.02817675,0.02823131,67.94428331680989,1150.0,1.0
0.028797545,0.028852105,68.26463641165934,1150.0,1.0
0.02941834,0.0294729,68.58311996075592,1150.0,1.0
0.03007033,0.03012489,68.89124282230327,1150.0,1.0
0.03072232,0.03077688,69.19113380713752,1150.0,1.0
0.03135024,0.0314048,69.48781187695481,1150.0,1.0
0.03197816,0.03203272,69.77962441200887,1150.0,1.0
0.03255977,0.03261433,70.06531833911396,1150.0,1.0
0.03314138,0.03319594,70.34301308125697,1150.0,1.0
0.033820735,0.033875295,70.61444385955345,1150.0,1.0
0.03450009,0.03455465,70.88763244030167,1150.0,1.0
0.03514708,0.03520164,71.16502899551573,1150.0,1.0
0.03579407,0.03584863,71.44207219115296,1150.0,1.0
0.036414039999999995,0.036468600000000004,71.71573571600806,1150.0,1.0
0.03703401,0.03708857,71.98523200165954,1150.0,1.0
0.03767983,0.03773439,72.24953179314439,1150.0,1.0
0.038325649999999996,0.03838021,72.51006366692178,1150.0,1.0
0.038961134999999994,0.039015695,72.76382490562143,1150.0,1.0
0.03959662,0.03965118,73.01117812283641,1150.0,1.0
0.0402441,0.04029866,73.25454323854575,1150.0,1.0
0.04089158,0.04094614,73.48868787935638,1150.0,1.0
0.04150357,0.04155813,73.71426749472755,1150.0,1.0
0.042115559999999996,0.04217012,73.93837288926078,1150.0,1.0
0.04274785,0.04280241,74.16310397850796,1150.0,1.0
0.04338014,0.0434347,74.38709197979111,1150.0,1.0
0.04401328,0.04406784,74.6142987184928,1150.0,1.0
0.04464642,0.04470098,74.84855937753248,1150.0,1.0
0.045263504999999996,0.045318065000000005,75.08476516360628,1150.0,1.0
0.04588059,0.04593515,75.31222095730234,1150.0,1.0
0.046532149999999994,0.04658671,75.53063027901534,1150.0,1.0
0.04718371,0.04723827,75.75206244638645,1150.0,1.0
0.047819215,0.047873775,75.9784446892956,1150.0,1.0
0.04845472,0.04850928,76.20193967716966,1150.0,1.0
0.049068515,0.049123075,76.41885821089411,1150.0,1.0
0.04968231,0.04973687,76.63630431919053,1150.0,1.0
0.05030536,0.05035992,76.85428747119721,1150.0,1.0
0.05092841,0.05098297,77.06354313120205,1150.0,1.0
0.051552185,0.051606745,77.25511997952323,1150.0,1.0
0.05217596,0.05223052,77.4290729821644,1150.0,1.0
0.052780765,0.052835325,77.59792437918254,1150.0,1.0
0.05338557,0.05344013,77.76546866534747,1150.0,1.0
0.054010884999999995,0.054065445000000004,77.93366830343275,1150.0,1.0
0.054636199999999996,0.05469076,78.11048325520726,1150.0,1.0
0.05526228999999999,0.05531685,78.30212798210657,1150.0,1.0
0.055888379999999994,0.05594294,78.50716591401154,1150.0,1.0
0.056503939999999996,0.0565585,78.71753948605291,1150.0,1.0
0.0571195,0.05717406,78.92174479947802,1150.0,1.0
0.057718745,0.057773305,79.11424209058336,1150.0,1.0
0.05831799,0.05837255,79.30232975863663,1150.0,1.0
0.05892935,0.05898391,79.4882924684097,1150.0,1.0
0.05954071,0.05959527,79.66929309762959,1150.0,1.0
0.060147115,0.060201674999999996,79.84902782322814,1150.0,1.0
0.06075352,0.06080808,80.03465077362664,1150.0,1.0
0.06139488,0.06144944,80.22518668806885,1150.0,1.0
0.06203624,0.0620908,80.41262718833106,1150.0,1.0
0.06262417,0.06267873,80.59110708582631,1150.0,1.0
0.06321210000000001,0.06326666,80.76008221671752,1150.0,1.0
0.06383791500000001,0.063892475,80.92734762876584,1150.0,1.0
0.06446373000000001,0.06451829,81.09787240021939,1150.0,1.0
0.065090275,0.06514483500000001,81.2694852417125,1150.0,1.0
0.06571682000000001,0.06577138,81.44611974844999,1150.0,1.0
0.06629833000000002,0.06635289,81.63049468417435,1150.0,1.0
0.06687984000000001,0.0669344,81.8156143473543,1150.0,1.0
0.06752805,0.06758261,81.99562184311368,1150.0,1.0
0.06817626,0.06823082,82.16619630299247,1150.0,1.0
0.0687649,0.06881946,82.32784136009869,1150.0,1.0
0.06935354,0.0694081,82.49226789545668,1150.0,1.0
0.06996593000000001,0.07002048999999999,82.66373117004586,1150.0,1.0
0.07057832,0.07063288,82.84011227004302,1150.0,1.0
0.071174205,0.071228765,83.01622460634887,1150.0,1.0
0.07177009000000001,0.07182465,83.18299610866143,1150.0,1.0
0.07238968500000001,0.072444245,83.33805824712923,1150.0,1.0
0.07300928000000001,0.07306384,83.48220333620496,1150.0,1.0
0.07362104,0.07367560000000001,83.61849280343998,1150.0,1.0
0.0742328,0.07428736,83.75702152412957,1150.0,1.0
0.074830815,0.074885375,83.9053360340538,1150.0,1.0
0.07542883,0.07548339,84.05988843696775,1150.0,1.0
0.07603048500000001,0.07608504499999999,84.2201704444858,1150.0,1.0
0.07663214,0.0766867,84.38458141695526,1150.0,1.0
0.077269295,0.077323855,84.5477396775761,1150.0,1.0
0.07790645,0.07796101,84.7096723433391,1150.0,1.0
0.078498025,0.07855258500000001,84.87034048713625,1150.0,1.0
0.07908960000000001,0.07914416,85.03214894363147,1150.0,1.0
0.07971375,0.07976831000000001,85.19495496538633,1150.0,1.0
0.0803379,0.08039246,85.35332221614306,1150.0,1.0
0.08094834000000001,0.0810029,85.50438637088676,1150.0,1.0
0.08155878000000001,0.08161334,85.6524700321304,1150.0,1.0
0.08216997000000001,0.08222453,85.79866908225813,1150.0,1.0
0.08278116,0.08283572,85.93896832085656,1150.0,1.0
0.08340183000000001,0.08345638999999999,86.07541375761406,1150.0,1.0
0.0840225,0.08407706,86.21155577515084,1150.0,1.0
0.08467602,0.08473058,86.3510759960987,1150.0,1.0
0.08532954000000001,0.0853841,86.4979802034027,1150.0,1.0
0.08589921,0.08595377,86.64736181591684,1150.0,1.0
0.08646888,0.08652344,86.792053338844,1150.0,1.0
0.087056735,0.087111295,86.93455468937907,1150.0,1.0
0.08764459000000001,0.08769915,87.07629870343504,1150.0,1.0
0.08829467,0.08834923,87.21410903274294,1150.0,1.0
0.08894475,0.08899931,87.34677746520785,1150.0,1.0
0.089548665,0.08960322500000001,87.48024745086414,1150.0,1.0
0.09015258000000001,0.09020714,87.62532434112852,1150.0,1.0
0.09076910500000002,0.090823665,87.78290961951569,1150.0,1.0
0.09138563000000001,0.09144019,87.94398470431946,1150.0,1.0
0.091982215,0.092036775,88.09744117024265,1150.0,1.0
0.0925788,0.09263336,88.24522319328251,1150.0,1.0
0.093182045,0.093236605,88.38452081904583,1150.0,1.0
0.09378529000000001,0.09383985,88.4991588023051,1150.0,1.0
0.094365655,0.094420215,88.59427708215144,1150.0,1.0
0.09494602,0.09500058,88.69209406099127,1150.0,1.0
0.095609705,0.095664265,88.80370973781804,1150.0,1.0
0.09627339,0.09632795,88.92575173177703,1150.0,1.0
0.09688773,0.09694229,89.05738411796902,1150.0,1.0
0.09750207000000001,0.09755663,89.20062791053252,1150.0,1.0
0.09810829500000001,0.098162855,89.35188884292373,1150.0,1.0
0.09871452,0.09876908,89.49698256224416,1150.0,1.0
0.09934811,0.09940267,89.62438205968937,1150.0,1.0
0.0999817,0.10003626,89.74509240137792,1150.0,1.0
0.100580495,0.100635055,89.87063558588659,1150.0,1.0
0.10117929,0.10123385,90.00088649083158,1150.0,1.0
0.101784805,0.101839365,90.12906211832555,1150.0,1.0
0.10239032,0.10244488,90.24800609236758,1150.0,1.0
0.10300542000000001,0.10305998,90.36332389058234,1150.0,1.0
0.10362052000000001,0.10367508,90.48055788512383,1150.0,1.0
0.10422451,0.10427907,90.59789782324144,1150.0,1.0
0.1048285,0.10488306,90.71812901604969,1150.0,1.0
0.10543618,0.10549074,90.84262676198486,1150.0,1.0
0.10604386,0.10609842,90.96636462328578,1150.0,1.0
0.10665825500000001,0.106712815,91.09226973395558,1150.0,1.0
0.10727265000000001,0.10732721,91.2243802624631,1150.0,1.0
0.10789977,0.10795433,91.35201770559934,1150.0,1.0
0.10852689,0.10858145,91.47047216883229,1150.0,1.0
0.109148805,0.109203365,91.5857971896975,1150.0,1.0
0.10977072,0.10982528,91.7002376008958,1150.0,1.0
0.11037540500000001,0.11042996499999999,91.81338615803777,1150.0,1.0
0.11098009,0.11103465,91.92354013928622,1150.0,1.0
0.11160651,0.11166107,92.02782236178079,1150.0,1.0
0.11223293000000001,0.11228749,92.1291994467496,1150.0,1.0
0.112836135,0.112890695,92.23808658505362,1150.0,1.0
0.11343934,0.1134939,92.35304638961367,1150.0,1.0
0.114034265,0.114088825,92.46828071628912,1150.0,1.0
0.11462919,0.11468375,92.58259589049732,1150.0,1.0
0.11525491500000001,0.115309475,92.70344864178116,1150.0,1.0
0.11588064000000001,0.1159352,92.84172113715987,1150.0,1.0
0.116516175,0.11657073500000001,92.99198170428879,1150.0,1.0
0.11715171,0.11720627,93.14186309993454,1150.0,1.0
0.11834665,0.11840121,93.284631874743,1150.0,1.0
0.11954159,0.11959615,93.42503627798342,1150.0,1.0
0.12010686500000001,0.120161425,93.55912717093995,1150.0,1.0
0.12067214000000001,0.1207267,93.67587653982825,1150.0,1.0
0.12131073,0.12136529,93.77361393501576,1150.0,1.0
0.12194932,0.12200388,93.86443491187819,1150.0,1.0
0.1225524,0.12260696,93.95976691996958,1150.0,1.0
0.12315548000000001,0.12321004,94.05357332663499,1150.0,1.0
0.12378048500000001,0.123835045,94.14412324021907,1150.0,1.0
0.12440549000000001,0.12446005,94.24156812541588,1150.0,1.0
0.125013015,0.12506757500000001,94.35023735700703,1150.0,1.0
0.12562054,0.1256751,94.45998903381303,1150.0,1.0
0.12624406500000002,0.126298625,94.56485930554535,1150.0,1.0
0.12686759,0.12692215,94.66974938729936,1150.0,1.0
0.127504045,0.127558605,94.77782673753796,1150.0,1.0
0.1281405,0.12819506,94.88909976390428,1150.0,1.0
0.12874116,0.12879572,94.99801135744718,1150.0,1.0
0.12934182,0.12939638,95.10392789912552,1150.0,1.0
0.12997071,0.13002527,95.20850818632626,1150.0,1.0
0.13059959999999998,0.13065416,95.3045681532032,1150.0,1.0
0.13119257499999998,0.13124713500000001,95.39074314365952,1150.0,1.0
0.13178555,0.13184011,95.47635745843296,1150.0,1.0
0.1324099,0.13246446,95.56512431190134,1150.0,1.0
0.13303425,0.13308881,95.6560663703963,1150.0,1.0
0.13364704,0.1337016,95.75101275768915,1150.0,1.0
0.13425983,0.13431439,95.84756132571721,1150.0,1.0
0.134879525,0.134934085,95.94336394256915,1150.0,1.0
0.13549922,0.13555378,96.0397186070834,1150.0,1.0
0.13611046999999998,0.13616503000000002,96.13182151869022,1150.0,1.0
0.13672172,0.13677628,96.21676242047995,1150.0,1.0
0.13733989,0.13739445,96.30083376708367,1150.0,1.0
0.13795806,0.13801262,96.38628088953583,1150.0,1.0
0.13858933,0.13864389,96.47186913890143,1150.0,1.0
0.1392206,0.13927516,96.55524446359416,1150.0,1.0
0.139824895,0.13987945499999999,96.64131319450831,1150.0,1.0
0.14042918999999998,0.14048375,96.74256098344131,1150.0,1.0
0.141052715,0.14110727499999998,96.85672420337227,1150.0,1.0
0.14167623999999998,0.1417308,96.96968770248482,1150.0,1.0
0.14230060499999997,0.142355165,97.07324141482654,1150.0,1.0
0.14292496999999998,0.14297953,97.16864237667006,1150.0,1.0
0.14351290499999997,0.143567465,97.25886351825012,1150.0,1.0
0.14410083999999998,0.1441554,97.344008917487,1150.0,1.0
0.14474215499999998,0.144796715,97.42323800823553,1150.0,1.0
0.14538347,0.14543803,97.50609238343748,1150.0,1.0
0.14600080499999998,0.146055365,97.59910536097077,1150.0,1.0
0.14661813999999998,0.1466727,97.69102822712172,1150.0,1.0
0.14721761,0.14727216999999998,97.77528860420621,1150.0,1.0
0.14781708,0.14787164,97.85746083700712,1150.0,1.0
0.14845461499999998,0.148509175,97.93759240094832,1150.0,1.0
0.14909214999999998,0.14914671,98.01241214509872,1150.0,1.0
0.14970239,0.14975695,98.08463509422057,1150.0,1.0
0.15031263,0.15036719,98.15917063485784,1150.0,1.0
0.15091742,0.15097198,98.23781127703889,1150.0,1.0
0.15152221,0.15157677,98.31514596622472,1150.0,1.0
0.152155855,0.152210415,98.38873324633435,1150.0,1.0
0.1527895,0.15284406,98.46312060751306,1150.0,1.0
0.153405155,0.153459715,98.54368861129566,1150.0,1.0
0.15402080999999998,0.15407537,98.62841799558011,1150.0,1.0
0.15461847499999998,0.15467303500000001,98.71434316977962,1150.0,1.0
0.15521614,0.1552707,98.80702789368848,1150.0,1.0
0.15584585499999998,0.15590041500000001,98.90493976970325,1150.0,1.0
0.15647556999999998,0.15653013,98.99786588960049,1150.0,1.0
0.157099785,0.157154345,99.08295598009815,1150.0,1.0
0.157724,0.15777856,99.16485958247635,1150.0,1.0
0.158342705,0.158397265,99.2446428700159,1150.0,1.0
0.15896141,0.15901597,99.32146586823646,1150.0,1.0
0.159552615,0.159607175,99.39750598713059,1150.0,1.0
0.16014382,0.16019838,99.47720260968205,1150.0,1.0
0.16078289,0.16083745,99.56339288364431,1150.0,1.0
0.16142196,0.16147652,99.65147958160469,1150.0,1.0
0.16202725499999998,0.16208181500000002,99.73493494076422,1150.0,1.0
0.16263255,0.16268711,99.81412055628773,1150.0,1.0
0.16323532999999998,0.16328989,99.89329669904438,1150.0,1.0
0.16383810999999998,0.16389267,99.97522957910667,1150.0,1.0
0.164457475,0.164512035,100.05620019625827,1150.0,1.0
0.16507684,0.1651314,100.13389055624636,1150.0,1.0
0.16570011499999998,0.16575467500000002,100.20877465527407,1150.0,1.0
0.16632339,0.16637795,100.2788662527585,1150.0,1.0
0.16695385,0.16700841,100.34527252775985,1150.0,1.0
0.16758431,0.16763887,100.40775734475967,1150.0,1.0
0.16820594,0.16826049999999998,100.46939451137256,1150.0,1.0
0.16882756999999998,0.16888213,100.54038664518318,1150.0,1.0
0.169421425,0.169475985,100.62243285226464,1150.0,1.0
0.17001528,0.17006984,100.70712143284688,1150.0,1.0
0.170648015,0.170702575,100.78987144025668,1150.0,1.0
0.17128074999999998,0.17133531,100.86883470736507,1150.0,1.0
0.171898365,0.17195292499999998,100.94308831881908,1150.0,1.0
0.17251597999999999,0.17257054,101.01660038636145,1150.0,1.0
0.17314074999999998,0.17319531,101.0880012080545,1150.0,1.0
0.17376551999999998,0.17382008,101.15691170319931,1150.0,1.0
0.174365535,0.174420095,101.22834547923577,1150.0,1.0
0.17496555,0.17502011,101.29837145712509,1150.0,1.0
0.175607835,0.175662395,101.3647552536812,1150.0,1.0
0.17625011999999998,0.17630468,101.43270631069561,1150.0,1.0
0.17684199,0.17689654999999999,101.50332773696029,1150.0,1.0
0.17743386,0.17748842,101.57672230398873,1150.0,1.0
0.17810976499999998,0.178164325,101.6551193690231,1150.0,1.0
0.17878566999999998,0.17884023,101.73737498190839,1150.0,1.0
0.17934697,0.17940152999999998,101.81698656371383,1150.0,1.0
0.17990826999999998,0.17996283,101.88827961286094,1150.0,1.0
0.18052161499999997,0.180576175,101.9524749644634,1150.0,1.0
0.18113495999999998,0.18118952,102.01669882534195,1150.0,1.0
0.181781215,0.18183577499999998,102.08403917496175,1150.0,1.0
0.18242746999999998,0.18248203,102.15445328816794,1150.0,1.0
0.18301656,0.18307111999999998,102.22358791023485,1150.0,1.0
0.18360564999999998,0.18366021,102.28421452639957,1150.0,1.0
0.18426316999999998,0.18431773,102.34131278950875,1150.0,1.0
0.18492069,0.18497525,102.40026451835715,1150.0,1.0
0.185527445,0.185582005,102.45883085516033,1150.0,1.0
0.1861342,0.18618876,102.52027069371653,1150.0,1.0
0.18673194999999998,0.18678651000000002,102.58789182024393,1150.0,1.0
0.1873297,0.18738426,102.65968208394786,1150.0,1.0
0.18797022,0.18802478,102.73362935956366,1150.0,1.0
0.18861074,0.1886653,102.80389813099029,1150.0,1.0
0.18922624,0.1892808,102.86366044235969,1150.0,1.0
0.18984173999999998,0.1898963,102.9177690504662,1150.0,1.0
0.19044492999999998,0.19049949,102.97309298541893,1150.0,1.0
0.19104812,0.19110268,103.02701355949881,1150.0,1.0
0.19170405,0.19175861,103.0820278505239,1150.0,1.0
0.19235997999999999,0.19241454,103.14430465239906,1150.0,1.0
0.19297778,0.19303234,103.21252207238588,1150.0,1.0
0.19359558,0.19365014,103.28178823297121,1150.0,1.0
0.194194525,0.194249085,103.35186156605273,1150.0,1.0
0.19479347,0.19484803,103.42584200030863,1150.0,1.0
0.19541278499999998,0.19546734500000001,103.50049280496799,1150.0,1.0
0.1960321,0.19608666,103.57167329317875,1150.0,1.0
0.19665535499999998,0.196709915,103.63488095947515,1150.0,1.0
0.19727861,0.19733317,103.68913021596441,1150.0,1.0
0.19787982999999998,0.19793439000000002,103.7409626872347,1150.0,1.0
0.19848105,0.19853561,103.79446989563817,1150.0,1.0
0.19910265,0.19915721,103.84589612888806,1150.0,1.0
0.19972425,0.19977881,103.89329150625464,1150.0,1.0
0.20033674499999998,0.20039130500000002,103.94245977432087,1150.0,1.0
0.20094924,0.2010038,103.99422861103687,1150.0,1.0
0.20158541,0.20163997,104.04876148914465,1150.0,1.0
0.20222157999999998,0.20227614,104.10854636020585,1150.0,1.0
0.20282251499999998,0.202877075,104.16879413794479,1150.0,1.0
0.20342344999999998,0.20347801,104.22836141780788,1150.0,1.0
0.20405139,0.20410594999999998,104.28949935535313,1150.0,1.0
0.20467933,0.20473389,104.34674587606617,1150.0,1.0
0.205294875,0.205349435,104.39552205754335,1150.0,1.0
0.20591041999999998,0.20596498,104.43846530278871,1150.0,1.0
0.206526665,0.20658122499999998,104.47986298055226,1150.0,1.0
0.20714290999999999,0.20719747,104.52364351424467,1150.0,1.0
0.20776665,0.20782120999999998,104.57470145435613,1150.0,1.0
0.20839038999999998,0.20844495,104.63060851557384,1150.0,1.0
0.209014815,0.209069375,104.68963207171304,1150.0,1.0
0.20963924,0.2096938,104.7548245089127,1150.0,1.0
0.210254535,0.210309095,104.8231327322433,1150.0,1.0
0.21086982999999998,0.21092439,104.89171817480626,1150.0,1.0
0.211469315,0.211523875,104.95738683328165,1150.0,1.0
0.2120688,0.21212336,105.01430770565779,1150.0,1.0
0.21265242,0.21270698,105.06495605861411,1150.0,1.0
0.21323604,0.2132906,105.11483998648181,1150.0,1.0
0.213896745,0.21395130499999998,105.16658270388014,1150.0,1.0
0.21455744999999998,0.21461201,105.22519345458011,1150.0,1.0
0.215754915,0.215809475,105.29315584423395,1150.0,1.0
0.21695238,0.21700694,105.36886271411316,1150.0,1.0
0.21752216,0.21757672,105.44540736893029,1150.0,1.0
0.21809193999999998,0.2181465,105.51355859355834,1150.0,1.0
0.218692435,0.218746995,105.56776379265605,1150.0,1.0
0.21929293,0.21934749,105.61213633072576,1150.0,1.0
0.21993093,0.21998549,105.65149890055235,1150.0,1.0
0.22056893,0.22062349,105.68736672397321,1150.0,1.0
0.22122112,0.22127568,105.7234619407362,1150.0,1.0
0.22187331,0.22192787,105.7615225460135,1150.0,1.0
0.22247271999999998,0.22252728,105.80455242451622,1150.0,1.0
0.22307212999999998,0.22312669,105.85332395140674,1150.0,1.0
0.223699115,0.22375367499999999,105.90312399381051,1150.0,1.0
0.2243261,0.22438066,105.95175248969832,1150.0,1.0
0.22493035,0.22498491,105.99886413205289,1150.0,1.0
0.2255346,0.22558916,106.04008645405814,1150.0,1.0
0.22615305,0.22620761,106.0775871447972,1150.0,1.0
0.2267715,0.22682606,106.11832867257206,1150.0,1.0
0.22740080499999998,0.227455365,106.16346026937154,1150.0,1.0
0.22803010999999998,0.22808467,106.21574961300713,1150.0,1.0
0.228639975,0.22869453499999998,106.27395519485532,1150.0,1.0
0.22924983999999998,0.2293044,106.32838898992937,1150.0,1.0
0.22986380499999998,0.229918365,106.37677935981762,1150.0,1.0
0.23047777,0.23053233,106.42332136245913,1150.0,1.0
0.23108916499999999,0.23114372500000002,106.46446331619738,1150.0,1.0
0.23170056,0.23175512,106.50001925353837,1150.0,1.0
0.23232281,0.23237737,106.53583340586356,1150.0,1.0
0.23294505999999998,0.23299962,106.57204076913598,1150.0,1.0
0.23358505,0.23363961,106.61134322796913,1150.0,1.0
0.23422504,0.2342796,106.65625295292918,1150.0,1.0
0.23484207,0.23489663,106.70050629735532,1150.0,1.0
0.2354591,0.23551366,106.74167846800935,1150.0,1.0
0.23606334,0.2361179,106.78510805945344,1150.0,1.0
0.23666758,0.23672214,106.83270570971575,1150.0,1.0
0.237303145,0.237357705,106.8776461867941,1150.0,1.0
0.23793871,0.23799327,106.91470280679715,1150.0,1.0
0.23856148,0.23861604,106.9443423509839,1150.0,1.0
0.23918425,0.23923881,106.97066810442975,1150.0,1.0
0.239794165,0.23984872499999998,106.99950213289226,1150.0,1.0
0.24040408,0.24045864,107.02992632754054,1150.0,1.0
0.241042025,0.241096585,107.05849298377018,1150.0,1.0
0.24167997,0.24173453,107.08550261242826,1150.0,1.0
0.2422982,0.24235276,107.11906517620179,1150.0,1.0
0.24291643,0.24297099,107.16392929780937,1150.0,1.0
0.24351151999999998,0.24356608000000002,107.21332293974135,1150.0,1.0
0.24410661,0.24416117,107.26128495336938,1150.0,1.0
0.24471264999999998,0.24476721,107.30735977465264,1150.0,1.0
0.24531868999999998,0.24537325,107.35440802601455,1150.0,1.0
0.24594264,0.2459972,107.40033528147086,1150.0,1.0
0.24656659,0.24662115,107.43807474118576,1150.0,1.0
0.24722221,0.24727677,107.4664469572433,1150.0,1.0
0.24787783,0.24793239,107.49537054397474,1150.0,1.0
0.2484793,0.24853386,107.53084712899262,1150.0,1.0
0.24908076999999998,0.24913533,107.56703700316329,1150.0,1.0
0.249689865,0.249744425,107.59933815142615,1150.0,1.0
0.25029896,0.25035352,107.63122423960026,1150.0,1.0
0.250922525,0.250977085,107.66457256591279,1150.0,1.0
0.25154609,0.25160065,107.69359678606611,1150.0,1.0
0.25216361,0.25221817,107.71607347450336,1150.0,1.0
0.25278113,0.25283569,107.73830065805177,1150.0,1.0
0.25340975,0.25346431,107.76476179054646,1150.0,1.0
0.25403837,0.25409293,107.79284274174857,1150.0,1.0
0.25464355000000005,0.25469811,107.82084202063675,1150.0,1.0
0.25524873000000003,0.25530329,107.84919808130248,1150.0,1.0
0.25587197500000003,0.255926535,107.88010750950015,1150.0,1.0
0.25649522,0.25654978,107.91524617829221,1150.0,1.0
0.25714005,0.25719461,107.95038140118217,1150.0,1.0
0.25778488,0.25783944,107.98422524502743,1150.0,1.0
0.25837495,0.25842951000000003,108.01701806569663,1150.0,1.0
0.25896502000000005,0.25901958,108.04511039263114,1150.0,1.0
0.25959058500000004,0.259645145,108.06795438250742,1150.0,1.0
0.26021615000000003,0.26027071,108.08728370710294,1150.0,1.0
0.26083903500000005,0.260893595,108.10547365771407,1150.0,1.0
0.26146192,0.26151648,108.12786733140277,1150.0,1.0
0.26208555,0.26214011000000004,108.15722007675345,1150.0,1.0
0.26270918000000004,0.26276374,108.19102193517213,1150.0,1.0
0.26331965,0.26337421000000005,108.22502990285943,1150.0,1.0
0.26393012000000005,0.26398468,108.25276966694813,1150.0,1.0
0.26453083,0.26458539000000003,108.27498408645515,1150.0,1.0
0.26513154,0.2651861,108.30061112685156,1150.0,1.0
0.26575399,0.26580855,108.32913989373296,1150.0,1.0
0.26637644,0.266431,108.35649857750082,1150.0,1.0
0.267006655,0.267061215,108.38392405142284,1150.0,1.0
0.26763687,0.26769143,108.41301593018247,1150.0,1.0
0.26823633,0.26829089,108.44081520987972,1150.0,1.0
0.26883579,0.26889035,108.46049022461109,1150.0,1.0
0.269495645,0.269550205,108.47065033288125,1150.0,1.0
0.2701555,0.27021006,108.4811748963312,1150.0,1.0
0.27078461,0.27083917,108.49811425697294,1150.0,1.0
0.27141372,0.27146828,108.5142915325618,1150.0,1.0
0.27198726500000003,0.272041825,108.5271098154704,1150.0,1.0
0.27256081000000004,0.27261537,108.54186995868594,1150.0,1.0
0.27320551000000004,0.27326007,108.56143988215136,1150.0,1.0
0.27385021000000004,0.27390477,108.58310979074956,1150.0,1.0
0.27446750500000006,0.274522065,108.60279724013637,1150.0,1.0
0.2750848,0.27513936,108.6222268138143,1150.0,1.0
0.275695795,0.275750355,108.64394333900158,1150.0,1.0
0.27630679,0.27636135,108.66547436117928,1150.0,1.0
0.27690085500000006,0.276955415,108.6818731175019,1150.0,1.0
0.27749492000000003,0.27754948,108.69225655657033,1150.0,1.0
0.27814282,0.27819738,108.70095960997,1150.0,1.0
0.27879072,0.27884528,108.71024578887398,1150.0,1.0
0.279393325,0.27944788499999995,108.72164507862692,1150.0,1.0
0.27999593,0.28005049,108.73849433607212,1150.0,1.0
0.28063839,0.28069295,108.75874521833187,1150.0,1.0
0.28128085,0.28133541,108.77763937956638,1150.0,1.0
0.28188852000000003,0.28194308,108.79496014006025,1150.0,1.0
0.28249619000000004,0.28255075,108.80986311656646,1150.0,1.0
0.28312599000000005,0.28318055,108.8203694808715,1150.0,1.0
0.28375579,0.28381035,108.83008328083031,1150.0,1.0
0.28437563,0.28443019,108.8399684876508,1150.0,1.0
0.28499547000000003,0.28505003,108.84749543194853,1150.0,1.0
0.28559472,0.28564928,108.85629416036181,1150.0,1.0
0.28619397,0.28624853,108.86840209622989,1150.0,1.0
0.28683681000000005,0.28689137,108.87971222862723,1150.0,1.0
0.28747965000000003,0.28753421,108.88746625537169,1150.0,1.0
0.28808399500000004,0.288138555,108.89463922577289,1150.0,1.0
0.28868834000000004,0.2887429,108.90604139956017,1150.0,1.0
0.28930411500000003,0.289358675,108.92191939224335,1150.0,1.0
0.28991989,0.28997445,108.93894928057779,1150.0,1.0
0.290543625,0.290598185,108.95177376096265,1150.0,1.0
0.29116736000000004,0.29122192,108.95947842334081,1150.0,1.0
0.29178826,0.29184282,108.96569769341808,1150.0,1.0
0.29240916,0.29246372,108.97064782080105,1150.0,1.0
0.29302726,0.29308182,108.97102835159164,1150.0,1.0
0.29364536,0.29369992,108.96720944687141,1150.0,1.0
0.29424981000000006,0.29430437,108.96473972566659,1150.0,1.0
0.29485426000000003,0.29490882,108.9671719392379,1150.0,1.0
0.2955027,0.29555726000000004,108.9732265847093,1150.0,1.0
0.29615114000000003,0.2962057,108.97888004267226,1150.0,1.0
0.29674264000000006,0.2967972,108.98169896916266,1150.0,1.0
0.29733414,0.2973887,108.98174887359042,1150.0,1.0
0.29797337,0.29802793,108.98258801726843,1150.0,1.0
0.2986126,0.29866716,108.98224276822651,1150.0,1.0
0.299248985,0.299303545,108.98406043977593,1150.0,1.0
0.29988537000000004,0.29993993,108.99034712731432,1150.0,1.0
0.30048635,0.30054091000000005,109.00313801262116,1150.0,1.0
0.30108733000000004,0.30114189,109.02446827747593,1150.0,1.0