File: datasets/steel_spring/csv/BS2V-1000-0.1.csv
Time(s),Strain(%),Stress(MPa),Temp(C),SR(%/s)
0.0008548999999999999,0.00014951,0.5327352773037866,1000.0,0.1
0.0009619499999999998,0.000160215,1.1717381872335513,1000.0,0.1
0.0012291,0.00018693,1.7755468617613712,1000.0,0.1
0.00176335,0.00024035499999999998,2.372169219012203,1000.0,0.1
0.00248475,0.000312495,2.9896131771110044,1000.0,0.1
0.00342035,0.000406055,3.822679786732962,1000.0,0.1
0.00398175,0.000462195,4.643296963198875,1000.0,0.1
0.0046233,0.00052635,5.598564127276525,1000.0,0.1
0.006067100000000001,0.00067073,6.558491541750015,1000.0,0.1
0.007618150000000001,0.000825835,7.577308450304946,1000.0,0.1
0.008821550000000001,0.000946175,8.692095971183743,1000.0,0.1
0.00965065,0.001029085,9.915306843376928,1000.0,0.1
0.010346049999999999,0.001098625,11.095231089697005,1000.0,0.1
0.011549799999999999,0.001219,12.30402523262315,1000.0,0.1
0.013208949999999999,0.001384915,13.594135975350435,1000.0,0.1
0.014439549999999999,0.001507975,15.023531374776583,1000.0,0.1
0.01572395,0.001636415,16.477635745092876,1000.0,0.1
0.017115699999999998,0.00177559,17.89077670241484,1000.0,0.1
0.018079249999999998,0.0018719449999999999,19.363991215356133,1000.0,0.1
0.018855449999999996,0.001949565,20.96725986648682,1000.0,0.1
0.02022065,0.0020860849999999997,22.72161761337319,1000.0,0.1
0.021505749999999997,0.0022145949999999998,24.386381055397813,1000.0,0.1
0.022362899999999998,0.00230031,26.057706569541764,1000.0,0.1
0.0239968,0.0024637,27.807417616060714,1000.0,0.1
0.02568455,0.002632475,29.645296837447084,1000.0,0.1
0.026729649999999997,0.002736985,31.329827065502005,1000.0,0.1
0.028042249999999998,0.002868245,32.97413806186755,1000.0,0.1
0.029623299999999998,0.0030263499999999997,34.62937799185049,1000.0,0.1
0.030561449999999997,0.003120165,36.376743373538,1000.0,0.1
0.03190165,0.0032541849999999997,38.21129024930313,1000.0,0.1
0.0338587,0.0034498899999999997,39.895762905805064,1000.0,0.1
0.0353604,0.00360006,41.510235503288015,1000.0,0.1
0.03683525,0.003747545,43.11344032096984,1000.0,0.1
0.038363999999999995,0.00390042,44.7049617284699,1000.0,0.1
0.03994679999999999,0.0040587,46.06633950344909,1000.0,0.1
0.0416639,0.00423041,47.320252809074134,1000.0,0.1
0.043595800000000004,0.0044236,48.50268397463094,1000.0,0.1
0.04504514999999999,0.004568535,49.66006169667072,1000.0,0.1
0.046146049999999994,0.004678625,50.737163413026785,1000.0,0.1
0.0483744,0.00490146,51.64948931887338,1000.0,0.1
0.050871599999999996,0.00515118,52.49077111703625,1000.0,0.1
0.052670999999999996,0.00533112,53.29931100042071,1000.0,0.1
0.0545784,0.00552186,54.09260556879763,1000.0,0.1
0.05675474999999999,0.005739495,54.76861925169155,1000.0,0.1
0.0591198,0.005976,55.38061515543965,1000.0,0.1
0.06143145,0.006207165000000001,55.964268422932044,1000.0,0.1
0.06323325,0.006387345,56.53511073763092,1000.0,0.1
0.06538485,0.006602505,57.011959475714285,1000.0,0.1
0.06788585,0.0068526049999999995,57.44265172741129,1000.0,0.1
0.07030785,0.007094805,57.86915047600028,1000.0,0.1
0.07205729999999999,0.00726975,58.30626657915181,1000.0,0.1
0.07375280000000001,0.0074393,58.72986595494535,1000.0,0.1
0.07620295,0.007684315000000001,59.11981824350218,1000.0,0.1
0.07849185,0.007913205,59.477488121259675,1000.0,0.1
0.08037739999999999,0.00810176,59.857199993180224,1000.0,0.1
0.08242474999999999,0.008306495,60.259990479200944,1000.0,0.1
0.0847146,0.00853548,60.625959101812626,1000.0,0.1
0.0870595,0.008769969999999998,60.97533200352476,1000.0,0.1
0.08937814999999999,0.009001835,61.340464557841024,1000.0,0.1
0.09102245,0.009166265,61.70929069671035,1000.0,0.1
0.09301799999999999,0.00936582,62.03406905951527,1000.0,0.1
0.09571574999999999,0.009635595,62.335850660985024,1000.0,0.1
0.09819805000000001,0.009883824999999999,62.624116694689604,1000.0,0.1
0.1002217,0.01008619,62.91993718799837,1000.0,0.1
0.10192195,0.010256214999999999,63.2254979971366,1000.0,0.1
0.10400100000000001,0.01046412,63.50053890702116,1000.0,0.1
0.10637765,0.010701785,63.76116255645501,1000.0,0.1
0.10867345,0.010931364999999998,64.02595878157244,1000.0,0.1
0.11040235,0.011104255,64.30636379995119,1000.0,0.1
0.11194245,0.011258265,64.5691638449019,1000.0,0.1
0.11410455,0.011474475,64.8258449898185,1000.0,0.1
0.11661875,0.011725895,65.0886562828904,1000.0,0.1
0.1188086,0.01194488,65.35055040712705,1000.0,0.1
0.12051195,0.012115215,65.60871552554755,1000.0,0.1
0.12251335,0.012315355,65.8372444654776,1000.0,0.1
0.12478555,0.012542575,66.04884535761397,1000.0,0.1
0.1264904,0.012713060000000002,66.26388594967455,1000.0,0.1
0.12816824999999998,0.012880845,66.5555328551347,1000.0,0.1
0.1303607,0.01310009,66.87513604854192,1000.0,0.1
0.13266255,0.013330274999999999,67.209691252076,1000.0,0.1
0.13485594999999997,0.013549615,67.54998887104001,1000.0,0.1
0.13683279999999998,0.0137473,67.86065816693214,1000.0,0.1
0.13837689999999997,0.013901710000000001,68.10050222266135,1000.0,0.1
0.14062595,0.014126615,68.27311752856679,1000.0,0.1
0.14328219999999997,0.01439224,68.39857349219744,1000.0,0.1
0.14512575,0.014576595,68.51016009488302,1000.0,0.1
0.14680669999999998,0.01474469,68.68074668026163,1000.0,0.1
0.14873209999999998,0.01493723,68.8709998468998,1000.0,0.1
0.15076604999999998,0.015140625,69.08294248479183,1000.0,0.1
0.15328904999999998,0.015392925,69.31828448356842,1000.0,0.1
0.15507994999999997,0.015572015,69.56234187750023,1000.0,0.1
0.15630129999999998,0.01569415,69.78014450289415,1000.0,0.1
0.15866309999999997,0.01593033,69.98298891384485,1000.0,0.1
0.16110714999999998,0.016174735,70.18018479369326,1000.0,0.1
0.16268239999999998,0.01633226,70.37797316234295,1000.0,0.1
0.16423059999999998,0.01648708,70.58276106585039,1000.0,0.1
0.16648539999999998,0.01671256,70.7784165745247,1000.0,0.1
0.16863175,0.016927195,70.9824688307084,1000.0,0.1
0.17028915,0.017092935,71.19890256722731,1000.0,0.1
0.17221915,0.017285935,71.4137098115039,1000.0,0.1
0.17439424999999997,0.017503445,71.60864045477864,1000.0,0.1
0.17665134999999998,0.017729155,71.80027140012517,1000.0,0.1
0.17904484999999998,0.017968505,71.99996993367655,1000.0,0.1
0.18062244999999996,0.018126265,72.21137619414048,1000.0,0.1
0.18239144999999996,0.018303165,72.39995345261762,1000.0,0.1
0.18467779999999998,0.0185318,72.59032986520289,1000.0,0.1
0.18699174999999998,0.018763195,72.79102132325946,1000.0,0.1
0.1885981,0.018923830000000003,72.99716502613245,1000.0,0.1
0.1902049,0.01908451,73.20920043171198,1000.0,0.1
0.19281985000000001,0.019346005,73.4040671074431,1000.0,0.1
0.19502645,0.019566665,73.58328897228033,1000.0,0.1
0.1970699,0.01977101,73.77315514612351,1000.0,0.1
0.19897745,0.019961765,73.9656202826214,1000.0,0.1
0.20085835,0.020149855,74.13582706171816,1000.0,0.1
0.20298505,0.020362525,74.30389401891895,1000.0,0.1
0.20543954999999997,0.020607975,74.46634930542079,1000.0,0.1
0.2072945,0.02079347,74.65455772200023,1000.0,0.1
0.20874079999999998,0.0209381,74.8591249673279,1000.0,0.1
0.21103319999999998,0.02116734,75.04036002774455,1000.0,0.1
0.21351669999999998,0.02141569,75.2083427322711,1000.0,0.1
0.21616494999999997,0.021680514999999997,75.38979506452313,1000.0,0.1
0.218186,0.02188262,75.57449893923149,1000.0,0.1
0.2196881,0.02203283,75.73774623118811,1000.0,0.1
0.22198255,0.022262274999999998,75.90040855069185,1000.0,0.1
0.22446875,0.022510895000000003,76.06428229473735,1000.0,0.1
0.2262725,0.02269127,76.24329314235291,1000.0,0.1
0.22794005,0.022858025,76.40742468226028,1000.0,0.1
0.23009975,0.023073995,76.55864853549883,1000.0,0.1
0.23267044999999997,0.023331064999999998,76.70590389435671,1000.0,0.1
0.23496825,0.023560845,76.85687109585274,1000.0,0.1
0.23682874999999998,0.023746895,77.01436906381295,1000.0,0.1
0.23912715,0.023976735,77.15698909959124,1000.0,0.1
0.24145365000000002,0.024209385,77.31420213843585,1000.0,0.1
0.2435619,0.02442021,77.4803249478468,1000.0,0.1
0.24561519999999998,0.02462554,77.65647754176713,1000.0,0.1
0.24750484999999997,0.024814505,77.80186813689028,1000.0,0.1
0.24975134999999998,0.025039155,77.94511075796801,1000.0,0.1
0.25216245000000004,0.025280265000000003,78.09314524707426,1000.0,0.1
0.2538342,0.02544744,78.23839431696233,1000.0,0.1
0.25556124999999996,0.025620144999999997,78.38259708128822,1000.0,0.1
0.2578639,0.025850409999999997,78.53395840974461,1000.0,0.1
0.2603042,0.02609444,78.6810642884661,1000.0,0.1
0.2620872,0.026272740000000003,78.83859440713232,1000.0,0.1
0.2637335,0.02643737,79.01042288386317,1000.0,0.1
0.266093,0.02667332,79.15839596555081,1000.0,0.1
0.26864525,0.026928544999999998,79.2991559673258,1000.0,0.1
0.2710331,0.02716733,79.44100251463279,1000.0,0.1
0.27265304999999995,0.027329325,79.5825016569586,1000.0,0.1
0.27443839999999997,0.027507860000000002,79.7069740694552,1000.0,0.1
0.2771301,0.02777703,79.83658350582827,1000.0,0.1
0.2797401,0.02803803,79.96418200033553,1000.0,0.1
0.2814443,0.028208450000000003,80.09832441019674,1000.0,0.1
0.28314835,0.028378855,80.24503497503771,1000.0,0.1
0.285375,0.02860152,80.39034273665925,1000.0,0.1
0.28774015,0.028838034999999998,80.52916703008572,1000.0,0.1
0.2901604,0.02908006,80.675060237686,1000.0,0.1
0.29200335,0.029264355,80.82993268439273,1000.0,0.1
0.29373705,0.029437724999999998,80.96901497457489,1000.0,0.1
0.2961588,0.029679900000000002,81.10374935089294,1000.0,0.1
0.2986635,0.02993037,81.24177498376966,1000.0,0.1
0.30028790000000005,0.03009281,81.38299900748159,1000.0,0.1
0.30194005,0.030258025,81.52302451121456,1000.0,0.1
0.30441894999999997,0.030505915,81.65395114023369,1000.0,0.1
0.30681590000000003,0.03074561,81.77605084955378,1000.0,0.1
0.30893795,0.030957815,81.91203911507816,1000.0,0.1
0.3108948,0.0311535,82.04934852616356,1000.0,0.1
0.31332075000000004,0.031396095,82.16278136117906,1000.0,0.1
0.31574765000000005,0.031638785,82.28507294021729,1000.0,0.1
0.31814735,0.031878755,82.4082792491455,1000.0,0.1
0.32013335,0.032077355,82.53944639952981,1000.0,0.1
0.3217614,0.03224016,82.65404069964316,1000.0,0.1
0.32402405,0.032466425,82.76888983697049,1000.0,0.1
0.32661855000000006,0.032725875,82.8840736496215,1000.0,0.1
0.32860670000000003,0.03292469,83.0104483740923,1000.0,0.1
0.330098,0.033073820000000004,83.15033363588059,1000.0,0.1
0.3325286,0.03331688,83.27195733510258,1000.0,0.1
0.33518105,0.033582125000000004,83.39858269078667,1000.0,0.1
0.3376682,0.03383084,83.53329072921144,1000.0,0.1
0.33946455,0.034010475,83.65691015671128,1000.0,0.1
0.34095755,0.034159775,83.7654934421048,1000.0,0.1
0.34344620000000003,0.034408640000000004,83.87475961908162,1000.0,0.1
0.34590734999999995,0.034654754999999995,83.9769059902764,1000.0,0.1
0.34742865,0.034806884999999996,84.08657461809794,1000.0,0.1
0.34967035,0.035031055,84.2084788910131,1000.0,0.1
0.35257655,0.035321675,84.31485859046569,1000.0,0.1
0.35476325,0.035540345,84.42676189092421,1000.0,0.1
0.3565907,0.03572309,84.55181811098547,1000.0,0.1
0.35863995000000004,0.035928015,84.67262421494148,1000.0,0.1
0.36085595000000004,0.036149614999999996,84.7768460189907,1000.0,0.1
0.3629065,0.03635467,84.88007594414604,1000.0,0.1
0.36556665,0.036620685,84.98298293033584,1000.0,0.1
0.3679227,0.03685629,85.08816434341641,1000.0,0.1
0.36947545,0.037011564999999996,85.18361155706364,1000.0,0.1
0.3717215,0.03723617,85.28157276438915,1000.0,0.1
0.37430074999999996,0.037494095,85.3908618148608,1000.0,0.1
0.37588195,0.037652215,85.50116827923222,1000.0,0.1
0.37762975,0.037826995,85.60927224940654,1000.0,0.1
0.3802386,0.03808788,85.69728508458684,1000.0,0.1
0.38259869999999996,0.03832389,85.78188927090939,1000.0,0.1
0.38487525,0.038551545,85.87333827658968,1000.0,0.1
0.38687455,0.038751475,85.9647665213656,1000.0,0.1
0.3887079,0.03893481,86.0407130370114,1000.0,0.1
0.39104194999999997,0.039168215,86.13032488133346,1000.0,0.1
0.39357109999999995,0.03942113,86.22864131921422,1000.0,0.1
0.39534994999999995,0.039599015,86.33624654808368,1000.0,0.1
0.3972958,0.0397936,86.44390921737734,1000.0,0.1
0.3997427,0.04003829,86.53451836328644,1000.0,0.1
0.40185649999999995,0.04024967,86.63407599004596,1000.0,0.1
0.4035535,0.040419369999999996,86.74711002212526,1000.0,0.1
0.4053342,0.04059744,86.85096079203606,1000.0,0.1
0.40781075,0.040845095,86.93516896235805,1000.0,0.1
0.4101211,0.04107613,87.02777716493011,1000.0,0.1
0.4127104,0.04133506,87.13060598175399,1000.0,0.1
0.41485495,0.041549515,87.24188611722575,1000.0,0.1
0.41655425,0.041719445,87.33711119148354,1000.0,0.1
0.418755,0.041939519999999994,87.42683946849715,1000.0,0.1
0.42095625,0.042159644999999996,87.52096979914651,1000.0,0.1
0.42276815,0.042340835,87.61931376561988,1000.0,0.1
0.42485969999999995,0.042549989999999996,87.71102387223146,1000.0,0.1
0.42717395,0.042781415,87.79989009851941,1000.0,0.1
0.42957239999999997,0.04302126,87.90224641697586,1000.0,0.1
0.43197129999999995,0.04326115,88.01631444688103,1000.0,0.1
0.43372884999999994,0.043436905,88.1374346309079,1000.0,0.1
0.43568260000000003,0.043632279999999996,88.24481546084546,1000.0,0.1
0.43763675,0.043827695,88.35258238048164,1000.0,0.1
0.4399818,0.044062199999999996,88.45511073200956,1000.0,0.1
0.4420758,0.0442716,88.54894663914413,1000.0,0.1
0.44375200000000004,0.04443922,88.63996796836,1000.0,0.1
0.44587555,0.044651575,88.72766166444156,1000.0,0.1
0.44816649999999997,0.04488067,88.81589959585035,1000.0,0.1
0.4499551,0.04505953,88.90363767726336,1000.0,0.1
0.45185615,0.045249634999999996,89.00604823385285,1000.0,0.1
0.45426045000000004,0.045490064999999996,89.1013033814495,1000.0,0.1
0.45647005,0.045711025,89.20271435982424,1000.0,0.1
0.4592672,0.04599074,89.30696465202891,1000.0,0.1
0.46139295,0.046203315,89.41489542051177,1000.0,0.1
0.46304415,0.046368435,89.50619735412492,1000.0,0.1
0.46514349999999993,0.046578369999999994,89.59796360548617,1000.0,0.1
0.46738335,0.046802355,89.68173803357078,1000.0,0.1
0.46967970000000003,0.047031989999999996,89.77117746972185,1000.0,0.1
0.47155610000000003,0.04721963,89.87507900664383,1000.0,0.1
0.47399355000000004,0.047463375,89.97101848356681,1000.0,0.1
0.47665595,0.047729615,90.06945708083266,1000.0,0.1
0.47909409999999997,0.04797343,90.17197206770275,1000.0,0.1
0.48066359999999997,0.04813038,90.27369311175978,1000.0,0.1
0.48229015,0.048293035,90.35975349132556,1000.0,0.1
0.4846739,0.04853141,90.43518332316812,1000.0,0.1
0.4869176,0.04875578,90.51944377232653,1000.0,0.1
0.48876935,0.048940955,90.61570635855307,1000.0,0.1
0.49070610000000003,0.04913463,90.70093357812372,1000.0,0.1
0.4932884,0.04939286,90.79556663711382,1000.0,0.1
0.4953936,0.04960338,90.88282433602252,1000.0,0.1
0.49713450000000003,0.049777470000000004,90.97016187212468,1000.0,0.1
0.49932575,0.049996595000000005,91.05760973327239,1000.0,0.1
0.5017698500000001,0.050241005000000005,91.14102327002378,1000.0,0.1
0.50415835,0.050479855000000004,91.21388212442899,1000.0,0.1
0.5066037,0.05072439,91.29019983922697,1000.0,0.1
0.50826175,0.050890195,91.36607553701185,1000.0,0.1
0.5100049499999999,0.051064515,91.43581631829059,1000.0,0.1
0.51290185,0.051354205,91.52080343065434,1000.0,0.1
0.51529285,0.051593305,91.5985195756863,1000.0,0.1
0.51686815,0.051750834999999995,91.67325926673699,1000.0,0.1
0.51875345,0.051939365,91.75639524367661,1000.0,0.1
0.5210337,0.05216739,91.840355180207,1000.0,0.1
0.5235111,0.052415130000000004,91.92454504434721,1000.0,0.1
0.52590425,0.052654445,92.00889873136693,1000.0,0.1
0.5276504,0.05282906,92.09039671798098,1000.0,0.1
0.52936895,0.053000914999999996,92.16948024137862,1000.0,0.1
0.5318485,0.053248870000000004,92.24585080668744,1000.0,0.1
0.53435705,0.053499725,92.31259465896918,1000.0,0.1
0.5363305,0.05369707,92.36914769244923,1000.0,0.1
0.5383889,0.05390291,92.42176560095282,1000.0,0.1
0.54050415,0.054114435,92.46855512584465,1000.0,0.1
0.5424784,0.05431186,92.52761235958116,1000.0,0.1
0.544284,0.05449242,92.60617740554162,1000.0,0.1
0.54628805,0.054692825,92.68299236797206,1000.0,0.1
0.54854605,0.054918625,92.76192580916769,1000.0,0.1
0.5511149,0.05517551,92.84356332579712,1000.0,0.1
0.5536843,0.055432449999999994,92.9342542679008,1000.0,0.1
0.5555199,0.05561601,93.01986774425623,1000.0,0.1
0.5573564,0.05579966,93.10002420113311,1000.0,0.1
0.55981485,0.056045504999999995,93.17105417610988,1000.0,0.1
0.56216055,0.056280075,93.24529681111154,1000.0,0.1
0.5638569499999999,0.056449715,93.32228999651169,1000.0,0.1
0.5659771499999999,0.056661735,93.38498571959923,1000.0,0.1
0.5684657,0.05691059,93.44793125356321,1000.0,0.1
0.5708421,0.05714823,93.5083844827373,1000.0,0.1
0.5725675,0.05732077,93.58339572343549,1000.0,0.1
0.57423715,0.057487735,93.67205198952648,1000.0,0.1
0.57636,0.05770002,93.7615249997145,1000.0,0.1
0.57868105,0.057932125,93.85330859688477,1000.0,0.1
0.5818811,0.05825213,93.94225676125426,1000.0,0.1
0.5843454,0.058498560000000005,94.02552562098226,1000.0,0.1
0.58550675,0.058614695,94.1017594465671,1000.0,0.1
0.5873488,0.0587989,94.16949670378628,1000.0,0.1
0.58972965,0.059036985,94.23645258503792,1000.0,0.1
0.5920538,0.0592694,94.30358442419094,1000.0,0.1
0.5938678,0.0594508,94.38040945664379,1000.0,0.1
0.5956265000000001,0.05962667000000001,94.45079724559467,1000.0,0.1
0.59764025,0.059828044999999996,94.52074982048805,1000.0,0.1
0.60036365,0.060100385,94.59627405764977,1000.0,0.1
0.60246375,0.060310395,94.67907032486644,1000.0,0.1
0.6041384,0.060477859999999994,94.7658121475002,1000.0,0.1
0.60672145,0.060736164999999995,94.84046115807894,1000.0,0.1
0.6089932,0.06096334,94.92712783511865,1000.0,0.1
0.6112654499999999,0.061190565,95.01388033204591,1000.0,0.1
0.6131686,0.06138088,95.08868473227876,1000.0,0.1
0.615186,0.06158262,95.15348456959599,1000.0,0.1
0.61771555,0.061835575000000004,95.21786422252774,1000.0,0.1
0.6200749000000001,0.06207151,95.28529697181023,1000.0,0.1
0.6218376,0.06224778,95.3487960818791,1000.0,0.1
0.62377155,0.062441175,95.417967450667,1000.0,0.1
0.6261323,0.06267725,95.48915179435427,1000.0,0.1
0.62846545,0.062910565,95.56272282487049,1000.0,0.1
0.6306563999999999,0.06312966,95.6434968077352,1000.0,0.1
0.63267725,0.063331745,95.72266430012854,1000.0,0.1
0.63475555,0.063539575,95.7908407737338,1000.0,0.1
0.6372043,0.06378444999999999,95.86118237194098,1000.0,0.1
0.6397105999999999,0.06403508,95.9281168895249,1000.0,0.1
0.6414766999999999,0.06421169,95.99516152123127,1000.0,0.1
0.64295835,0.064359855,96.0640886257639,1000.0,0.1
0.64512425,0.064576445,96.13095741615258,1000.0,0.1
0.6478326999999999,0.06484729,96.19473712970058,1000.0,0.1
0.6496006999999999,0.06502409,96.26941824675168,1000.0,0.1
0.6514258,0.0652066,96.34161119087175,1000.0,0.1
0.6542779999999999,0.06549182,96.40077887364241,1000.0,0.1
0.656646,0.06572862,96.4594749244453,1000.0,0.1
0.65898585,0.06596260500000001,96.52366945232303,1000.0,0.1
0.6611267,0.06617669,96.59373032267689,1000.0,0.1
0.66281115,0.066345135,96.64866273075299,1000.0,0.1
0.66512405,0.066576425,96.69881691208856,1000.0,0.1
0.66758065,0.066822085,96.75918347880227,1000.0,0.1
0.66935175,0.06699919500000001,96.82722612356142,1000.0,0.1
0.6712377,0.06718779,96.88400008223407,1000.0,0.1
0.6737526,0.06743928,96.94840228601026,1000.0,0.1
0.67615355,0.067679375,97.01257057158585,1000.0,0.1
0.6780117999999999,0.0678652,97.07198776976438,1000.0,0.1
0.6797848,0.0680425,97.14483114302364,1000.0,0.1
0.6822162,0.06828564000000001,97.20684961631548,1000.0,0.1
0.6849346999999999,0.06855749,97.26273845816807,1000.0,0.1
0.68733885,0.06879790499999999,97.31842514344024,1000.0,0.1
0.6891417999999999,0.06897819999999999,97.37704322538274,1000.0,0.1
0.69074525,0.069138545,97.41798081139561,1000.0,0.1
0.6932077999999999,0.0693848,97.46293795484641,1000.0,0.1
0.696043,0.06966832,97.50816480362177,1000.0,0.1
0.6977621999999999,0.06984024,97.55093991273617,1000.0,0.1
0.69948185,0.070012205,97.60589416850529,1000.0,0.1
0.7021187,0.07027589,97.66241773803725,1000.0,0.1
0.70449805,0.070513825,97.71972869926032,1000.0,0.1
0.70661975,0.070725995,97.78134081803458,1000.0,0.1
0.7083693,0.07090095,97.85346159216398,1000.0,0.1
0.71014775,0.071078795,97.91176380411991,1000.0,0.1
0.7123280999999999,0.07129683,97.97728522479028,1000.0,0.1
0.71502585,0.071566605,98.04286005636538,1000.0,0.1
0.71686275,0.07175029499999999,98.10461161661186,1000.0,0.1
0.7185277,0.07191679000000001,98.15726850604587,1000.0,0.1
0.72105445,0.072169465,98.21617527364587,1000.0,0.1
0.7233238,0.0723964,98.27364716670799,1000.0,0.1
0.7253919999999999,0.07260322,98.33465811528174,1000.0,0.1
0.7271733999999999,0.07278135999999999,98.4094411569859,1000.0,0.1
0.7293004999999999,0.07299407,98.476919429878,1000.0,0.1
0.7318586,0.07324987999999999,98.54774496172868,1000.0,0.1
0.73415835,0.073479855,98.61427432711918,1000.0,0.1
0.73594175,0.073658195,98.67367853201962,1000.0,0.1
0.7378117499999999,0.073845195,98.7238169406618,1000.0,0.1
0.7402858999999999,0.07409261,98.77738234078484,1000.0,0.1
0.74293345,0.07435736500000001,98.84088325775264,1000.0,0.1
0.74445925,0.074509945,98.91444830746705,1000.0,0.1
0.7461001999999999,0.07467404,99.00658491680996,1000.0,0.1
0.74869115,0.074933135,99.0845620321908,1000.0,0.1
0.7512256,0.07518658,99.15883940554552,1000.0,0.1
0.75373205,0.075437225,99.2181942587675,1000.0,0.1
0.7554320999999999,0.07560723,99.27391112680114,1000.0,0.1
0.75724805,0.075788825,99.328734993082,1000.0,0.1
0.7597269499999999,0.076036715,99.36936387433828,1000.0,0.1
0.7620336999999999,0.07626738999999999,99.41736043427407,1000.0,0.1
0.76370655,0.07643467500000001,99.47619565834431,1000.0,0.1
0.7654657,0.07661059,99.5466850564306,1000.0,0.1
0.76806215,0.076870235,99.61158192722941,1000.0,0.1
0.7704864,0.07711266,99.68294173192994,1000.0,0.1
0.77302645,0.077366665,99.75225409972712,1000.0,0.1
0.7747298,0.077537,99.82392374813566,1000.0,0.1
0.77660715,0.07772473499999999,99.89481790936512,1000.0,0.1
0.77926425,0.07799044499999999,99.95434157851156,1000.0,0.1
0.7816329,0.07822731,100.00846753165581,1000.0,0.1
0.7836266000000001,0.07842668,100.06485149033122,1000.0,0.1
0.7853318,0.0785972,100.11575236238467,1000.0,0.1
0.7875574000000001,0.07881976,100.16867482679893,1000.0,0.1
0.7899571999999999,0.07905973999999999,100.22961804861137,1000.0,0.1
0.7918658999999999,0.07925061,100.28882907027284,1000.0,0.1
0.7938330499999999,0.079447325,100.34573195833897,1000.0,0.1
0.7963502499999999,0.079699045,100.39882873741277,1000.0,0.1
0.7988388499999999,0.079947905,100.45398344951028,1000.0,0.1
0.80132805,0.080196825,100.51113792879885,1000.0,0.1
0.80318095,0.080382115,100.56237202968728,1000.0,0.1
0.8048320499999999,0.080547225,100.60381017387749,1000.0,0.1
0.8070911999999999,0.08077314,100.64606932686812,1000.0,0.1
0.8096692999999999,0.08103094999999999,100.69126137612619,1000.0,0.1
0.8116978499999999,0.08123380499999999,100.73164299027748,1000.0,0.1
0.8135527499999999,0.081419295,100.79157490312866,1000.0,0.1
0.8160168999999999,0.08166571,100.85438667006379,1000.0,0.1
0.8185108999999999,0.08191511,100.91360950816032,1000.0,0.1
0.8210343499999999,0.082167455,100.97873152021191,1000.0,0.1
0.8227747000000001,0.08234149,101.04719835231809,1000.0,0.1
0.82448615,0.082512635,101.09835886338347,1000.0,0.1
0.82703985,0.082768005,101.14081347981181,1000.0,0.1
0.8295654,0.08302056,101.18274310999023,1000.0,0.1
0.8313946999999999,0.08320348999999999,101.22026046721821,1000.0,0.1
0.83313745,0.08337776499999999,101.26011896562898,1000.0,0.1
0.8356353000000001,0.08362755,101.30714473017099,1000.0,0.1
0.8382501,0.08388903,101.34693448192328,1000.0,0.1
0.840168,0.08408082,101.39921003665953,1000.0,0.1
0.8417953,0.08424355,101.45873816662247,1000.0,0.1
0.8442082000000001,0.08448484,101.51272209295097,1000.0,0.1
0.8467381,0.08473783,101.55693749291305,1000.0,0.1
0.8489484999999999,0.08495886999999999,101.60504466347378,1000.0,0.1
0.85075195,0.085139215,101.65350448237727,1000.0,0.1
0.8527307,0.08533709,101.69942709668103,1000.0,0.1
0.8550884,0.08557286,101.7479669994435,1000.0,0.1
0.8574461499999999,0.085808635,101.79114454242608,1000.0,0.1
0.85930895,0.085994915,101.83926862532341,1000.0,0.1
0.8610855,0.08617257,101.88148915390163,1000.0,0.1
0.8634741,0.08641143000000001,101.92986885870071,1000.0,0.1
0.8658049,0.08664451000000001,101.97445059825147,1000.0,0.1
0.8676992499999999,0.086833945,102.01972885917424,1000.0,0.1
0.8696224499999999,0.08702626499999999,102.07575843584843,1000.0,0.1
0.8719542,0.08725944,102.13471717966324,1000.0,0.1
0.8744912,0.08751314,102.18473584797893,1000.0,0.1
0.87691185,0.087755205,102.23601588132627,1000.0,0.1
0.8785456,0.08791858,102.29461478533685,1000.0,0.1
0.8801508,0.0880791,102.34915381468541,1000.0,0.1
0.88248555,0.088312575,102.41294090616977,1000.0,0.1
0.88520005,0.08858402500000001,102.4760081809505,1000.0,0.1
0.88730195,0.08879421500000001,102.54038934028078,1000.0,0.1
0.88899595,0.088963615,102.60055481959378,1000.0,0.1
0.8911571999999999,0.08917974,102.64401796963239,1000.0,0.1
0.8937571,0.08943973,102.68395017740039,1000.0,0.1
0.8957737499999999,0.089641395,102.73637439926881,1000.0,0.1
0.89767385,0.089831405,102.7867278657007,1000.0,0.1
0.9000997,0.09007398999999999,102.82874097311958,1000.0,0.1
0.90238,0.09030202,102.87126913153394,1000.0,0.1
0.9049251999999999,0.09055653999999999,102.92813471947302,1000.0,0.1
0.9066806999999999,0.09073209,102.99931909370568,1000.0,0.1
0.9084066,0.09090468,103.06428233258465,1000.0,0.1
0.91098185,0.091162205,103.1162744842359,1000.0,0.1
0.9132650999999999,0.09139053,103.17375207191989,1000.0,0.1
0.91499255,0.091563275,103.24005959317834,1000.0,0.1
0.916779,0.09174192,103.29636208919213,1000.0,0.1
0.9192977499999999,0.09199379499999999,103.34390769661384,1000.0,0.1
0.9218171,0.09224573,103.37973216271476,1000.0,0.1
0.9244254999999999,0.09250657,103.43238619957809,1000.0,0.1
0.9263891,0.09270292999999999,103.48790396422919,1000.0,0.1
0.9283532999999999,0.09289934999999999,103.54108426112192,1000.0,0.1
0.9308166999999999,0.09314569,103.58209039024436,1000.0,0.1
0.9327234,0.09333636000000001,103.63157581590144,1000.0,0.1
0.9346305,0.09352707,103.68706916551012,1000.0,0.1
0.9367429,0.09373830999999999,103.74448984704762,1000.0,0.1
0.93906125,0.093970145,103.79331776039328,1000.0,0.1
0.9413800999999999,0.09420202999999999,103.84210615427024,1000.0,0.1
0.9432003,0.09438405,103.90128064289522,1000.0,0.1
0.9450506,0.09456908,103.961843442242,1000.0,0.1
0.94742965,0.09480698500000001,104.01835289738904,1000.0,0.1
0.949839,0.09504792000000001,104.06503595024488,1000.0,0.1
0.9522489,0.09528891,104.11491312465172,1000.0,0.1
0.9542477,0.09548878999999999,104.1642812860213,1000.0,0.1
0.9563351,0.09569753,104.21235090906326,1000.0,0.1
0.9587459999999999,0.09593862,104.25653664665178,1000.0,0.1
0.96112835,0.096176855,104.30323281237898,1000.0,0.1
0.9631878999999999,0.09638281,104.3523675845401,1000.0,0.1
0.965454,0.09660942,104.40410712100213,1000.0,0.1
0.96763175,0.096827195,104.45048035220387,1000.0,0.1
0.9698399,0.09704801,104.48266110320651,1000.0,0.1
0.97249,0.09731302,104.50818095791416,1000.0,0.1
0.97402145,0.097466165,104.53850191827617,1000.0,0.1
0.9756415,0.09762817,104.58170528959144,1000.0,0.1
0.97829315,0.097893335,104.62720886093169,1000.0,0.1
0.98070985,0.098135005,104.6638323200383,1000.0,0.1
0.98247825,0.098311845,104.70786497550046,1000.0,0.1
0.98454225,0.098518245,104.76033234265255,1000.0,0.1
0.98701905,0.098765925,104.81285568623336,1000.0,0.1
0.9895258,0.0990166,104.84882442443902,1000.0,0.1
0.99197455,0.099261475,104.88026182402571,1000.0,0.1
0.9937156,0.09943558,104.91832947663706,1000.0,0.1
0.99545705,0.099609725,104.95990371236174,1000.0,0.1
0.99796645,0.09986066499999999,104.99254443533617,1000.0,0.1
1.0005946999999997,0.10012349,105.01762314927734,1000.0,0.1
1.0025440499999998,0.10031842499999999,105.05081327173616,1000.0,0.1
1.0039618499999998,0.100460205,105.09323727372879,1000.0,0.1
1.0060298499999998,0.100667005,105.14310168221799,1000.0,0.1
1.0088079999999997,0.10094481999999999,105.18489278668612,1000.0,0.1
1.0112619499999997,0.101190215,105.22831481399459,1000.0,0.1
1.0129471499999998,0.101358735,105.2779244299463,1000.0,0.1
1.0148989999999998,0.10155391999999999,105.32481219125727,1000.0,0.1
1.0174425999999999,0.10180828,105.35502662218207,1000.0,0.1
1.01998685,0.102062705,105.3851014514185,1000.0,0.1
1.0216141999999997,0.10222544,105.41940582957123,1000.0,0.1
1.0232719499999998,0.10239121500000001,105.45891305063293,1000.0,0.1
1.0259068999999998,0.10265471000000001,105.4943021340276,1000.0,0.1
1.0282164999999996,0.10288567,105.52420905729868,1000.0,0.1
1.0300231999999998,0.10306634,105.5627617099979,1000.0,0.1
1.0319484499999998,0.103258865,105.6088325642409,1000.0,0.1
1.0342301499999997,0.103487035,105.65293372009909,1000.0,0.1
1.0366898999999998,0.10373301,105.69725537825477,1000.0,0.1
1.0392090499999997,0.103984925,105.7486178957559,1000.0,0.1
1.0407213,0.10413615,105.79578757204241,1000.0,0.1
1.0427086499999998,0.10433488499999999,105.84292808281971,1000.0,0.1
1.0454669499999998,0.10461071499999999,105.88167849942842,1000.0,0.1
1.0475434,0.10481836,105.92351131563693,1000.0,0.1
1.0492347499999997,0.104987495,105.96877339852175,1000.0,0.1
1.0510453999999998,0.10516856,106.0198049507655,1000.0,0.1
1.0534203499999997,0.105406055,106.06648276524517,1000.0,0.1
1.0560037999999998,0.10566439999999999,106.11617923139548,1000.0,0.1
1.0584688999999998,0.10591091,106.15915574344436,1000.0,0.1
1.06028105,0.10609212500000001,106.19802281123415,1000.0,0.1
1.0622127,0.10628529,106.23543072224884,1000.0,0.1
1.0647088499999997,0.106534905,106.26947354747,1000.0,0.1
1.0671755499999998,0.10678157499999999,106.31106045809473,1000.0,0.1
1.0687215499999998,0.106936175,106.35759908698883,1000.0,0.1
1.0702383999999998,0.10708786,106.40806601845426,1000.0,0.1
1.0726178999999998,0.10732581,106.45309123745699,1000.0,0.1
1.0752358499999999,0.107587605,106.49717325834808,1000.0,0.1
1.0774081499999997,0.107804835,106.54639936521833,1000.0,0.1
1.0794026999999997,0.10800429,106.60103076371229,1000.0,0.1
1.0817247499999998,0.108236495,106.65111750188998,1000.0,0.1
1.08404685,0.108468705,106.69658792053585,1000.0,0.1
1.0863994999999997,0.10870397,106.74876491401753,1000.0,0.1
1.0883656499999999,0.108900585,106.80427543172271,1000.0,0.1
1.0906603499999998,0.109130055,106.85022874515187,1000.0,0.1
1.0930446999999999,0.10936849000000001,106.88484249086535,1000.0,0.1
1.0951015,0.10957417,106.92196112008831,1000.0,0.1
1.09694995,0.109759015,106.96459452453459,1000.0,0.1
1.0990372,0.10996774000000001,106.99895239582477,1000.0,0.1
1.1013939499999998,0.110203415,107.03737312640382,1000.0,0.1
1.1036021499999997,0.110424235,107.07885070871505,1000.0,0.1
1.1055414999999997,0.11061817,107.13445386829515,1000.0,0.1
1.10763115,0.110827135,107.1896877272996,1000.0,0.1
1.1103180499999998,0.111095825,107.23735399302576,1000.0,0.1
1.1127663499999998,0.111340655,107.27399532426617,1000.0,0.1
1.1148870499999997,0.11155272499999999,107.30968903326325,1000.0,0.1
1.1167693499999998,0.111740955,107.34789637174568,1000.0,0.1
1.1187118999999999,0.11193521000000001,107.37196843675584,1000.0,0.1
1.1212222499999998,0.11218624499999999,107.40962364257075,1000.0,0.1
1.1236435499999997,0.112428375,107.4522287125164,1000.0,0.1
1.1256171,0.11262573000000001,107.49545639567233,1000.0,0.1
1.1276207,0.11282609,107.53347419250163,1000.0,0.1
1.1296845999999998,0.11303247999999999,107.55891262080019,1000.0,0.1
1.1321382999999998,0.11327785,107.58229913855749,1000.0,0.1
1.1339335999999998,0.11345738,107.60889120354912,1000.0,0.1
1.1356099999999998,0.11362502,107.64188415301717,1000.0,0.1
1.1383043999999998,0.11389446,107.67117390719179,1000.0,0.1
1.1409395499999997,0.114157975,107.71494093896777,1000.0,0.1
1.1433062499999997,0.11439464499999999,107.75592256747603,1000.0,0.1
1.1450435999999997,0.11456838,107.79101737863324,1000.0,0.1
1.147201,0.11478411999999999,107.83453230621929,1000.0,0.1
1.1500483499999998,0.115068855,107.8675932365304,1000.0,0.1
1.1521471499999998,0.115278735,107.90187378614684,1000.0,0.1
1.1535862999999997,0.11542265,107.93342490909279,1000.0,0.1
1.1557157499999997,0.11563559500000001,107.97297750356753,1000.0,0.1
1.1583256499999997,0.115896585,108.01182780567572,1000.0,0.1
1.1606060499999997,0.116124625,108.04555621904824,1000.0,0.1
1.1628273499999997,0.116346755,108.06423769339985,1000.0,0.1
1.1644484,0.11650885999999999,108.09046265285228,1000.0,0.1
1.1663097999999998,0.116695,108.12272794563117,1000.0,0.1
1.1689821499999997,0.116962235,108.14820696986484,1000.0,0.1
1.17129525,0.117193545,108.17317648696562,1000.0,0.1
1.1730076499999997,0.117364785,108.19414969310769,1000.0,0.1
1.1750810499999997,0.117572125,108.21767614663703,1000.0,0.1
1.17760605,0.117824625,108.24756809975848,1000.0,0.1
1.1799808499999997,0.118062105,108.2767591532602,1000.0,0.1
1.1818151999999997,0.11824554,108.31017020701525,1000.0,0.1
1.1833492999999997,0.11839895,108.35662161901266,1000.0,0.1
1.1855149499999997,0.118615515,108.3977774368286,1000.0,0.1
1.1879817,0.11886219,108.43379810918944,1000.0,0.1
1.1903595499999997,0.119099975,108.46403161621443,1000.0,0.1
1.19261735,0.119325755,108.47857342227357,1000.0,0.1
1.1948147999999998,0.1195455,108.49342551286384,1000.0,0.1
1.1968926,0.11975327999999999,108.52177602722834,1000.0,0.1
1.1991519499999999,0.119979215,108.56313214312999,1000.0,0.1
1.2012611,0.12019013,108.60807695912621,1000.0,0.1
1.20294875,0.120358895,108.66702792572924,1000.0,0.1
1.20529975,0.12059399500000001,108.71827162603593,1000.0,0.1
1.2079825999999998,0.12086227999999999,108.76576507283403,1000.0,0.1
1.2102742999999998,0.12109144999999999,108.80990038256505,1000.0,0.1
1.211903,0.12125432,108.84199021460256,1000.0,0.1
1.2138031999999999,0.12144434,108.86967053975933,1000.0,0.1
1.21627755,0.121691775,108.9066330630276,1000.0,0.1
1.2188734499999998,0.121951365,108.94047571749228,1000.0,0.1
1.2208352999999998,0.12214755,108.97538819943584,1000.0,0.1
1.2222544499999999,0.122289465,109.01860668035967,1000.0,0.1
1.2244285499999998,0.122506875,109.05614174180404,1000.0,0.1
1.22735855,0.122799875,109.0890625045657,1000.0,0.1
1.2294735499999998,0.123011375,109.12503097920333,1000.0,0.1
1.231075,0.12317152,109.16112266450345,1000.0,0.1
1.23313035,0.123377055,109.18466467353082,1000.0,0.1
1.23530675,0.123594695,109.21541786922205,1000.0,0.1
1.2378464999999998,0.12384867,109.24923666185154,1000.0,0.1
1.2399938499999998,0.124063405,109.29320399946917,1000.0,0.1
1.2418093,0.12424494999999999,109.3327084838874,1000.0,0.1
1.2441694499999998,0.124480965,109.36976788769323,1000.0,0.1
1.2468626499999997,0.124750285,109.40437585448116,1000.0,0.1
1.2488305499999999,0.12494707499999999,109.44071198840311,1000.0,0.1
1.2507382999999999,0.12513785,109.47903587694296,1000.0,0.1
1.2530397999999998,0.12536799999999998,109.51594119327615,1000.0,0.1
1.25531185,0.125595205,109.55783818899445,1000.0,0.1
1.2577959499999998,0.12584361500000002,109.60394474558447,1000.0,0.1
1.2597960499999998,0.126043625,109.65887647486157,1000.0,0.1
1.2618273999999998,0.12624676,109.69860238468233,1000.0,0.1
1.2643437499999999,0.12649839499999999,109.74333452513206,1000.0,0.1
1.2668300499999998,0.126747025,109.77636734985627,1000.0,0.1
1.2688922499999997,0.126953245,109.80358696783338,1000.0,0.1
1.2708947499999999,0.127153495,109.82575514648852,1000.0,0.1
1.2733531999999999,0.12739934,109.84617263277367,1000.0,0.1
1.2755996499999998,0.127623985,109.87073231524322,1000.0,0.1
1.2770867999999997,0.12777270000000002,109.89722046976134,1000.0,0.1
1.2790909999999998,0.12797312,109.9334577029915,1000.0,0.1
1.2817639499999998,0.128240415,109.96472224397905,1000.0,0.1
1.2840726499999997,0.128471285,109.99975533815484,1000.0,0.1
1.2865337999999997,0.12871739999999998,110.02882056835425,1000.0,0.1
1.2883570499999997,0.128899725,110.06452917685235,1000.0,0.1
1.2897550999999998,0.12903953,110.08494100829746,1000.0,0.1
1.2921874499999997,0.129282765,110.10616220146917,1000.0,0.1
1.2950159499999998,0.129565615,110.13417787212842,1000.0,0.1
1.2970845499999997,0.129772475,110.1664615270317,1000.0,0.1
1.2987577999999997,0.1299398,110.19914294157718,1000.0,0.1
1.3010396999999998,0.13016799,110.2335329304227,1000.0,0.1
1.3035961499999997,0.13042363499999998,110.2587116343495,1000.0,0.1
1.3059708499999998,0.130661105,110.28721952744101,1000.0,0.1
1.3079196499999999,0.130855985,110.31179648824667,1000.0,0.1
1.3097777,0.13104179,110.31645229420529,1000.0,0.1
1.3120318499999999,0.131267205,110.32826265299768,1000.0,0.1
1.3144085499999998,0.131504875,110.34057536293413,1000.0,0.1
1.3164200499999996,0.131706025,110.36394773303681,1000.0,0.1
1.3183402499999999,0.131898045,110.39961105279578,1000.0,0.1
1.3205357999999998,0.1321176,110.43952205350183,1000.0,0.1
1.3229756999999998,0.13236159,110.47262087779103,1000.0,0.1
1.3249581,0.13255983,110.4998375313654,1000.0,0.1
1.3267278999999998,0.13273681,110.52089661753341,1000.0,0.1
1.32956635,0.133020655,110.5314065523992,1000.0,0.1
1.3321608999999999,0.13328011,110.54756308923092,1000.0,0.1
1.3342365999999997,0.13348768,110.55331076298236,1000.0,0.1
1.3360686,0.13367088,110.57974156165152,1000.0,0.1
1.33774895,0.133838915,110.61386014565545,1000.0,0.1
1.34007065,0.13407108499999998,110.6462750160025,1000.0,0.1
1.3425455,0.13431857,110.67651827563084,1000.0,0.1
1.3443796,0.13450198000000002,110.69834353872236,1000.0,0.1
1.3463051499999998,0.134694535,110.71951104858105,1000.0,0.1
1.3488428999999997,0.13494831000000002,110.73614163295267,1000.0,0.1
1.3513818,0.1352022,110.75579361401124,1000.0,0.1
1.3534924,0.13541325999999998,110.77529847300586,1000.0,0.1
1.3552053999999998,0.13558456,110.81216643584867,1000.0,0.1
1.3573168499999997,0.135795705,110.84800178829168,1000.0,0.1
1.3600103499999996,0.136065055,110.88446527596263,1000.0,0.1
1.3623984499999997,0.136303865,110.9190937588642,1000.0,0.1
1.3640831999999998,0.13647234,110.95158346089018,1000.0,0.1
1.3656758999999998,0.13663161000000001,110.97699028629948,1000.0,0.1
1.3678509499999998,0.13684911500000002,110.98872339076075,1000.0,0.1
1.3705472999999997,0.13711875,111.01245197075983,1000.0,0.1
1.3726005,0.13732407,111.04262677479821,1000.0,0.1
1.3742255499999998,0.137486575,111.08326627545331,1000.0,0.1
1.3764943499999998,0.13771345499999998,111.11219717178254,1000.0,0.1
1.3787635999999999,0.13794038,111.14091565272643,1000.0,0.1
1.3813405999999997,0.13819808,111.16715258980749,1000.0,0.1
1.3834878999999998,0.13841281,111.20154313732243,1000.0,0.1
1.3851445999999998,0.13857848,111.22723935097606,1000.0,0.1
1.3875698499999998,0.138821005,111.2489112550689,1000.0,0.1
1.3897806499999998,0.13904208499999998,111.28055000523705,1000.0,0.1
1.39128485,0.13919250500000002,111.31713406515742,1000.0,0.1
1.3933424999999997,0.13939827,111.35945270855765,1000.0,0.1
1.3959846999999999,0.13966249,111.39044323578854,1000.0,0.1
1.3984735499999998,0.139911375,111.41848088791137,1000.0,0.1
1.40093245,0.140157265,111.44671898363535,1000.0,0.1
1.4026235999999999,0.14032638,111.47957189978872,1000.0,0.1
1.4043451499999997,0.14049853499999998,111.51421716225741,1000.0,0.1
1.4066822999999997,0.14073225,111.54648508502638,1000.0,0.1
1.4092048999999998,0.14098451,111.5769825876234,1000.0,0.1
1.4112660499999998,0.14119062500000001,111.60385541365194,1000.0,0.1
1.41372825,0.141436845,111.64000787443842,1000.0,0.1
1.4159446999999998,0.14165849,111.67103104967457,1000.0,0.1
1.4180691499999996,0.14187093499999998,111.6945336748806,1000.0,0.1
1.4208406999999998,0.14214809,111.71484604856172,1000.0,0.1
1.4223189999999999,0.14229592,111.73579228079582,1000.0,0.1
1.4244754499999996,0.142511565,111.75639298853113,1000.0,0.1
1.427187,0.14278272,111.78159635397607,1000.0,0.1
1.42943715,0.14300773500000002,111.81221069030909,1000.0,0.1
1.4313795999999999,0.14320198,111.84849813103054,1000.0,0.1
1.4331989999999997,0.14338392,111.8901531066018,1000.0,0.1
1.4354193499999996,0.143605955,111.92904213901744,1000.0,0.1
1.4377944499999997,0.143843465,111.96352403878012,1000.0,0.1
1.4395841999999996,0.14402244,111.9885213265098,1000.0,0.1
1.4416523999999997,0.14422926,112.00611854091152,1000.0,0.1
1.4444612,0.14451014,112.02180343225362,1000.0,0.1
1.4466533999999998,0.14472936,112.04486808355186,1000.0,0.1
1.4491548499999998,0.144979505,112.06940673413388,1000.0,0.1
1.4509461,0.14515863,112.1031729299792,1000.0,0.1
1.4525840499999998,0.14532242499999998,112.13261095676154,1000.0,0.1
1.4553652,0.14560054,112.15923544717742,1000.0,0.1
1.45793075,0.145857095,112.1826309559707,1000.0,0.1
1.4596003499999999,0.14602405499999999,112.20454276745689,1000.0,0.1
1.4614867999999999,0.1462127,112.21671129449547,1000.0,0.1
1.46383735,0.146447755,112.23654228655897,1000.0,0.1
1.4661885,0.14668287,112.26010053901099,1000.0,0.1
1.4687880499999997,0.146942825,112.27605186237076,1000.0,0.1
1.4704281,0.14710683000000002,112.29777563676643,1000.0,0.1
1.4722853999999999,0.14729256000000002,112.32155085505838,1000.0,0.1
1.4747317999999998,0.14753719999999998,112.34271023115129,1000.0,0.1
1.4772403499999998,0.14778805499999997,112.36191809229562,1000.0,0.1
1.4792227999999996,0.1479863,112.38030908173462,1000.0,0.1
1.4808339499999996,0.148147415,112.40104896805472,1000.0,0.1
1.4832511499999996,0.148389135,112.42529745392852,1000.0,0.1
1.4859173499999998,0.148655755,112.45975931596244,1000.0,0.1
1.4884285999999998,0.14890688000000002,112.49540761713429,1000.0,0.1
1.4900098499999999,0.149065005,112.52717160013776,1000.0,0.1
1.4915298,0.149217,112.57402551976023,1000.0,0.1
1.49373235,0.149437255,112.6176323086943,1000.0,0.1
1.4960592,0.14966994,112.6534786220725,1000.0,0.1
1.4978281,0.14984683,112.67705111502731,1000.0,0.1
1.4984178,0.1499058,112.68282425857487,1000.0,0.1