File: datasets/steel_spring/csv/BS2V-1100-10.0.csv
Time(s),Strain(%),Stress(MPa),Temp(C),SR(%/s)
0.0,3.999e-05,0.2852371300000004,1100.0,10.0
6.7e-08,4.066e-05,0.2949356387499998,1100.0,10.0
1.34e-07,4.133e-05,0.3046341474999997,1100.0,10.0
2.01e-07,4.2000000000000004e-05,0.31433265624999984,1100.0,10.0
2.68e-07,4.267e-05,0.32403116500000007,1100.0,10.0
3.35e-07,4.334e-05,0.3361543009375013,1100.0,10.0
4.02e-07,4.401000000000001e-05,0.34585280968750065,1100.0,10.0
4.6900000000000003e-07,4.4680000000000006e-05,0.3555513184375011,1100.0,10.0
5.36e-07,4.5350000000000005e-05,0.36524982718750154,1100.0,10.0
6.03e-07,4.602e-05,0.3749483359375021,1100.0,10.0
6.7e-07,4.669e-05,0.38464684468750177,1100.0,10.0
7.370000000000001e-07,4.736e-05,0.39434535343750143,1100.0,10.0
8.04e-07,4.803e-05,0.4047539524129986,1100.0,10.0
8.71e-07,4.87e-05,0.415050938290722,1100.0,10.0
9.380000000000001e-07,4.9369999999999997e-05,0.42423564191820845,1100.0,10.0
1.0050000000000001e-06,5.004e-05,0.431615292343753,1100.0,10.0
1.072e-06,5.071e-05,0.43680501681640943,1100.0,10.0
1.139e-06,5.138e-05,0.43972784078598826,1100.0,10.0
1.206e-06,5.2050000000000005e-05,0.44061468790305724,1100.0,10.0
1.273e-06,5.2720000000000003e-05,0.4400043800189415,1100.0,10.0
1.34e-06,5.339e-05,0.4387436371857256,1100.0,10.0
1.4070000000000003e-06,5.406e-05,0.4379870776562512,1100.0,10.0
1.4740000000000002e-06,5.473e-05,0.43752494578125195,1100.0,10.0
1.5410000000000002e-06,5.54e-05,0.4370628139062527,1100.0,10.0
1.608e-06,5.607e-05,0.43660068203125296,1100.0,10.0
1.675e-06,5.6739999999999995e-05,0.4361385501562527,1100.0,10.0
1.742e-06,5.7409999999999994e-05,0.43567641828125286,1100.0,10.0
1.809e-06,5.808e-05,0.4352142864062531,1100.0,10.0
1.8760000000000001e-06,5.875e-05,0.43577206991974704,1100.0,10.0
1.9430000000000003e-06,5.942e-05,0.436169541529359,1100.0,10.0
2.0100000000000002e-06,6.009e-05,0.43496942209683076,1100.0,10.0
2.077e-06,6.076e-05,0.43117667221875317,1100.0,10.0
2.144e-06,6.143e-05,0.42423849222656584,1100.0,10.0
2.2104375e-06,6.2094375e-05,0.4140443221865558,1100.0,10.0
2.276875e-06,6.275875000000001e-05,0.4009258418998604,1100.0,10.0
2.3433125e-06,6.342312500000001e-05,0.38565697090246454,1100.0,10.0
2.40975e-06,6.40875e-05,0.369453868465201,1100.0,10.0
2.4761875e-06,6.4751875e-05,0.3539749335937508,1100.0,10.0
2.542625e-06,6.541625e-05,0.33891889046875023,1100.0,10.0
2.6090625e-06,6.6080625e-05,0.32386284734375004,1100.0,10.0
2.6755e-06,6.6745e-05,0.3088068042187501,1100.0,10.0
2.7419375e-06,6.7409375e-05,0.29375076109375065,1100.0,10.0
2.808375e-06,6.807375e-05,0.27869471796875056,1100.0,10.0
2.8748125e-06,6.8738125e-05,0.2636386748437504,1100.0,10.0
2.94125e-06,6.940249999999999e-05,0.2479177342528417,1100.0,10.0
3.0076875e-06,7.006687499999999e-05,0.23230130329072024,1100.0,10.0
3.074125e-06,7.073124999999999e-05,0.21772636483617416,1100.0,10.0
3.1405625e-06,7.1395625e-05,0.20484159934374987,1100.0,10.0
3.207e-06,7.206e-05,0.19400738484375038,1100.0,10.0
3.274e-06,7.272999999999999e-05,0.18529579694223566,1100.0,10.0
3.341e-06,7.34e-05,0.17849060882102433,1100.0,10.0
3.4080000000000002e-06,7.407e-05,0.173087291237691,1100.0,10.0
3.475e-06,7.474e-05,0.1682930125255696,1100.0,10.0
3.542e-06,7.541000000000001e-05,0.16302663859375138,1100.0,10.0
3.6090000000000005e-06,7.608e-05,0.1574845754687512,1100.0,10.0
3.6760000000000005e-06,7.675e-05,0.15194251234375097,1100.0,10.0
3.7430000000000004e-06,7.742e-05,0.14640044921875078,1100.0,10.0
3.8100000000000004e-06,7.809e-05,0.1408583860937506,1100.0,10.0
3.877e-06,7.876e-05,0.13531632296875065,1100.0,10.0
3.944000000000001e-06,7.942999999999999e-05,0.12977425984375052,1100.0,10.0
4.011000000000001e-06,8.01e-05,0.0632479974808236,1100.0,10.0
4.078000000000001e-06,8.077e-05,0.0063073274100370474,1100.0,10.0
4.145000000000001e-06,8.144e-05,0.04489204259540658,1100.0,10.0
4.212000000000001e-06,8.211000000000001e-05,0.23849892278125,1100.0,10.0
4.279000000000001e-06,8.278e-05,0.6201817344921892,1100.0,10.0
9.2665625e-06,0.00013265562500000002,1.196551231033148,1100.0,10.0
1.4254124999999998e-05,0.00018253125000000002,1.947775152489354,1100.0,10.0
1.9241687499999998e-05,0.00023240687500000002,2.827578225726338,1100.0,10.0
2.4229249999999995e-05,0.0002822825,3.76324216438993,1100.0,10.0
2.9216812499999992e-05,0.00033215812500000003,4.655605668906269,1100.0,10.0
3.420437499999999e-05,0.00038203375000000003,5.522683042031273,1100.0,10.0
3.919193749999999e-05,0.00043190937500000003,6.389760415156278,1100.0,10.0
4.417949999999999e-05,0.00048178500000000004,7.256837788281283,1100.0,10.0
4.916706249999999e-05,0.000531660625,8.123915161406286,1100.0,10.0
5.415462499999999e-05,0.00058153625,8.99099253453129,1100.0,10.0
5.914218749999999e-05,0.000631411875,9.858069907656295,1100.0,10.0
6.412975e-05,0.0006812875,10.634713580111555,1100.0,10.0
6.91173125e-05,0.000731163125,11.425571763783196,1100.0,10.0
7.4104875e-05,0.00078103875,12.358084904059476,1100.0,10.0
7.90924375e-05,0.000830914375,13.520481001593803,1100.0,10.0
8.408e-05,0.00088079,14.961775612304745,1100.0,10.0
0.00012371974999999998,0.0012771875000000001,16.69177184737601,1100.0,10.0
0.0001633595,0.001673585,18.68106037325646,1100.0,10.0
0.00020299925000000002,0.0020699825,20.86101941166011,1100.0,10.0
0.000242639,0.00246638,23.12381473956614,1100.0,10.0
0.00028227875,0.0028627775,25.322399689218855,1100.0,10.0
0.0003219185,0.003259175,27.48348773859386,1100.0,10.0
0.00036155825,0.0036555725,29.64457578796886,1100.0,10.0
0.000401198,0.00405197,31.805663837343864,1100.0,10.0
0.00044083775000000006,0.0044483675,33.966751886718875,1100.0,10.0
0.00048047750000000005,0.004844765,36.12783993609387,1100.0,10.0
0.00052011725,0.0052411625,38.28892798546888,1100.0,10.0
0.000559757,0.00563756,40.495372850573986,1100.0,10.0
0.0005993967500000001,0.0060339575,42.69468846009008,1100.0,10.0
0.0006390365000000001,0.0064303550000000004,44.822957350115644,1100.0,10.0
0.0006786762500000001,0.0068267525,46.835928968718875,1100.0,10.0
0.0007183160000000001,0.00722315,48.709019675937654,1100.0,10.0
0.000795628625,0.00799627625,50.43731274377954,1100.0,10.0
0.00087294125,0.0087694025,52.0355583562218,1100.0,10.0
0.0009502538749999999,0.009542528750000001,53.53817360921139,1100.0,10.0
0.0010275665,0.010315655,54.99924251066498,1100.0,10.0
0.001104879125,0.011088781249999999,56.492515980468966,1100.0,10.0
0.00118219175,0.0118619075,58.00459593484396,1100.0,10.0
0.001259504375,0.01263503375,59.51667588921896,1100.0,10.0
0.001336817,0.013408159999999999,61.028755843593956,1100.0,10.0
0.0014141296249999998,0.014181286249999998,62.540835797968974,1100.0,10.0
0.0014914422499999998,0.014954412499999998,64.052915752344,1100.0,10.0
0.0015687548749999999,0.01572753875,65.56499570671899,1100.0,10.0
0.0016460675,0.016500664999999998,67.10857924675776,1100.0,10.0
0.001723380125,0.017273791249999997,68.64721100368402,1100.0,10.0
0.0018006927499999998,0.0180469175,70.13649568062759,1100.0,10.0
0.0018780053749999997,0.01882004375,71.54569807206285,1100.0,10.0
0.0019553179999999997,0.01959317,72.85774306380888,1100.0,10.0
0.0020304211875,0.020344201875000002,74.06921563302963,1100.0,10.0
0.002105524375,0.02109523375,75.19036084823361,1100.0,10.0
0.0021806275625,0.021846265625,76.24508386927398,1100.0,10.0
0.0022557307499999997,0.022597297500000002,77.27094994734863,1100.0,10.0
0.0023308339374999995,0.023348329375,78.31918442500026,1100.0,10.0
0.002405937125,0.02409936125,79.38048136500021,1100.0,10.0
0.0024810403125,0.024850393125000002,80.44177830500011,1100.0,10.0
0.0025561435,0.025601425,81.50307524500003,1100.0,10.0
0.0026312466875,0.026352456875,82.56437218500002,1100.0,10.0
0.002706349875,0.02710348875,83.62566912500003,1100.0,10.0
0.0027814530624999997,0.027854520625,84.6869660650002,1100.0,10.0
0.00285655625,0.0286055525,85.76972709414243,1100.0,10.0
0.0029316594375000003,0.029356584375,86.8491143640156,1100.0,10.0
0.003006762625,0.03010761625,87.8948803777259,1100.0,10.0
0.0030818658125,0.030858648125,88.88608456050059,1100.0,10.0
0.003156969,0.03160968,89.81109325968808,1100.0,10.0
0.0032293854375,0.032333844375000004,90.66757974475803,1100.0,10.0
0.003301801875,0.03305800875,91.46252420730161,1100.0,10.0
0.0033742183125,0.033782173124999995,92.2122137610307,1100.0,10.0
0.00344663475,0.0345063375,92.94224244177879,1100.0,10.0
0.0035190511875,0.035230501875,93.68751120750036,1100.0,10.0
0.0035914676249999998,0.03595466625,94.44167971750028,1100.0,10.0
0.0036638840625,0.036678830625000006,95.19584822750029,1100.0,10.0
0.0037363005,0.037402995,95.95001673750033,1100.0,10.0
0.0038087169374999997,0.038127159375,96.70418524750029,1100.0,10.0
0.003881133375,0.03885132375,97.45835375750023,1100.0,10.0
0.0039535498125,0.039575488125,98.21252226750029,1100.0,10.0
0.00402596625,0.040299652500000005,98.98010265482596,1100.0,10.0
0.004098382687499999,0.04102381687500001,99.74557494219256,1100.0,10.0
0.004170799124999999,0.04174798125,100.49003892307086,1100.0,10.0
0.0042432155624999995,0.042472145625,101.2004098390941,1100.0,10.0
0.004315632,0.04319631,101.86941838005892,1100.0,10.0
0.004387838125,0.043918371250000005,102.49561068392461,1100.0,10.0
0.00446004425,0.0446404325,103.0833483368132,1100.0,10.0
0.004532250375,0.045362493749999996,103.64280837300984,1100.0,10.0
0.0046044564999999996,0.046084555,104.18998327496243,1100.0,10.0
0.0046766626249999995,0.04680661625,104.74668097328164,1100.0,10.0
0.0047488687499999994,0.0475286775,105.30893969390672,1100.0,10.0
0.004821074874999999,0.048250738749999994,105.87119841453192,1100.0,10.0
0.004893280999999999,0.0489728,106.433457135157,1100.0,10.0
0.004965487124999999,0.04969486125,106.99571585578197,1100.0,10.0
0.005037693249999999,0.050416922499999996,107.55797457640702,1100.0,10.0
0.005109899374999999,0.05113898374999999,108.12023329703217,1100.0,10.0
0.005182105499999999,0.051861044999999995,108.69162094124765,1100.0,10.0
0.005254311624999999,0.05258310625,109.26157368690411,1100.0,10.0
0.005326517749999999,0.0533051675,109.8172269262316,1100.0,10.0
0.005398723874999999,0.05402722875,110.34967439231268,1100.0,10.0
0.00547093,0.05474929,110.85396815908217,1100.0,10.0
0.005549882124999999,0.05553881125,111.32911864132667,1100.0,10.0
0.005628834249999999,0.056328332499999995,111.77809459468564,1100.0,10.0
0.005707786374999999,0.057117853749999996,112.20782311565038,1100.0,10.0
0.005786738499999999,0.057907375,112.62918964156486,1100.0,10.0
0.0058656906249999995,0.05869689625,113.05703795062513,1100.0,10.0
0.00594464275,0.0594864175,113.48867142312545,1100.0,10.0
0.006023594875,0.06027593875,113.92030489562566,1100.0,10.0
0.006102547,0.06106546,114.35193836812567,1100.0,10.0
0.006181499125,0.06185498125,114.78357184062568,1100.0,10.0
0.00626045125,0.0626445025,115.21520531312552,1100.0,10.0
0.006339403375,0.06343402375,115.64683878562543,1100.0,10.0
0.0064183555,0.06422354499999999,116.08375811018148,1100.0,10.0
0.0064973076250000004,0.06501306625,116.51984659620292,1100.0,10.0
0.006576259750000001,0.0658025875,116.94765534648364,1100.0,10.0
0.006655211875000001,0.06659210874999999,117.3620274321882,1100.0,10.0
0.006734164,0.06738163,117.76009789285223,1100.0,10.0
0.0068111907499999996,0.0681518975,118.14129373638299,1100.0,10.0
0.0068882175,0.06892216500000001,118.50733393905915,1100.0,10.0
0.0069652442500000005,0.06969243250000001,118.86222944553055,1100.0,10.0
0.007042271000000001,0.0704627,119.21228316881772,1100.0,10.0
0.0071192977500000015,0.0712329675,119.56608999031279,1100.0,10.0
0.007196324500000001,0.072003235,119.92208850656283,1100.0,10.0
0.007273351250000001,0.0727735025,120.27808702281281,1100.0,10.0
0.007350378000000001,0.07354377000000001,120.6340855390628,1100.0,10.0
0.007427404750000002,0.07431403750000001,120.99008405531275,1100.0,10.0
0.007504431500000001,0.075084305,121.34608257156279,1100.0,10.0
0.007581458250000001,0.0758545725,121.70208108781303,1100.0,10.0
0.007658485000000001,0.07662484,122.06187012301804,1100.0,10.0
0.007735511750000001,0.0773951075,122.42106335849554,1100.0,10.0
0.0078125385,0.07816537500000001,122.77431914151818,1100.0,10.0
0.007889565250000001,0.07893564250000001,123.11793940481347,1100.0,10.0
0.007966592000000002,0.07970591,123.44986966656313,1100.0,10.0
0.008048029750000001,0.08052028750000001,123.76969903040363,1100.0,10.0
0.008129467500000001,0.081334665,124.0786601854264,1100.0,10.0
0.00821090525,0.0821490425,124.37962940617686,1100.0,10.0
0.008292343,0.08296342000000001,124.6771265526547,1100.0,10.0
0.00837378075,0.0837777975,124.9773150703142,1100.0,10.0
0.0084552185,0.084592175,125.27907526656438,1100.0,10.0
0.00853665625,0.08540655250000001,125.58083546281426,1100.0,10.0
0.008618094,0.08622093,125.88259565906407,1100.0,10.0
0.00869953175,0.08703530749999999,126.184355855314,1100.0,10.0
0.0087809695,0.087849685,126.4861160515639,1100.0,10.0
0.008862407249999999,0.0886640625,126.78787624781376,1100.0,10.0
0.008943844999999999,0.08947843999999999,127.09332149117351,1100.0,10.0
0.009025282749999999,0.0902928175,127.39818751303648,1100.0,10.0
0.009106720499999998,0.091107195,127.69728129308494,1100.0,10.0
0.009188158249999998,0.09192157249999999,127.98700766340727,1100.0,10.0
0.009269596,0.09273595,128.26536930849687,1100.0,10.0
0.009351029187499998,0.093550281875,128.53196676525226,1100.0,10.0
0.009432462374999999,0.09436461374999999,128.78799842297778,1100.0,10.0
0.0095138955625,0.095178945625,129.03626052338277,1100.0,10.0
0.00959532875,0.0959932775,129.28114716058158,1100.0,10.0
0.0096767619375,0.09680760937499999,129.52865028109414,1100.0,10.0
0.009758195125,0.09762194125,129.77768134796935,1100.0,10.0
0.009839628312500001,0.098436273125,130.0267124148448,1100.0,10.0
0.0099210615,0.09925060499999999,130.27574348172004,1100.0,10.0
0.010002494687499999,0.100064936875,130.52477454859522,1100.0,10.0
0.010083927874999999,0.10087926875,130.77380561547005,1100.0,10.0
0.0101653610625,0.10169360062499999,131.02283668234472,1100.0,10.0
0.01024679425,0.1025079325,131.27435914911908,1100.0,10.0
0.0103282274375,0.103322264375,131.5254900137413,1100.0,10.0
0.010409660625,0.10413659624999999,131.7727183603637,1100.0,10.0
0.010491093812500001,0.104950928125,132.01361355493805,1100.0,10.0
0.010572527,0.10576526,132.24682524521538,1100.0,10.0
0.0106554506875,0.106594496875,132.47208336074593,1100.0,10.0
0.010738374375,0.10742373375,132.69019811287896,1100.0,10.0
0.0108212980625,0.108252970625,132.90305999476314,1100.0,10.0
0.01090422175,0.1090822075,133.11363978134634,1100.0,10.0
0.0109871454375,0.109911444375,133.32598852937573,1100.0,10.0
0.011070069125,0.11074068125,133.53937029687583,1100.0,10.0
0.0111529928125,0.111569918125,133.75275206437593,1100.0,10.0
0.0112359165,0.112399155,133.96613383187605,1100.0,10.0
0.0113188401875,0.113228391875,134.17951559937603,1100.0,10.0
0.011401763875,0.11405762875,134.39289736687596,1100.0,10.0
0.0114846875625,0.114886865625,134.60627913437597,1100.0,10.0
0.01156761125,0.1157161025,134.82173348057307,1100.0,10.0
0.0116505349375,0.116545339375,135.03686205559296,1100.0,10.0
0.011733458625,0.11737457625,135.24874415232821,1100.0,10.0
0.0118163823125,0.118203813125,135.45535774278233,1100.0,10.0
0.011899306,0.11903305,135.6555794780673,1100.0,10.0
0.011981015625,0.11985014625,135.84918468840573,1100.0,10.0
0.01206272525,0.1206672425,136.03684738313052,1100.0,10.0
0.012144434875,0.12148433875,136.22014025068387,1100.0,10.0
0.012226144500000001,0.122301435,136.40153465861795,1100.0,10.0
0.012307854125,0.12311853125,136.58440065359434,1100.0,10.0
0.01238956375,0.1239356275,136.7681260104695,1100.0,10.0
0.012471273375000001,0.12475272375,136.95185136734412,1100.0,10.0
0.012552983,0.12556982,137.13557672421885,1100.0,10.0
0.012634692624999999,0.12638691624999998,137.31930208109398,1100.0,10.0
0.01271640225,0.1272040125,137.50302743796908,1100.0,10.0
0.012798111875,0.12802110875,137.68675279484532,1100.0,10.0
0.0128798215,0.12883820499999998,137.87191836627795,1100.0,10.0
0.012961531125,0.12965530125,138.05685756252225,1100.0,10.0
0.01304324075,0.1304723975,138.23954081292942,1100.0,10.0
0.013124950375,0.13128949374999999,138.41856303012682,1100.0,10.0
0.01320666,0.13210659,138.59314361001938,1100.0,10.0
0.013290650875,0.13294649874999998,138.7631264317895,1100.0,10.0
0.01337464175,0.13378640749999998,138.92897985789438,1100.0,10.0
0.013458632625,0.13462631625,139.09179673406751,1100.0,10.0
0.0135426235,0.135466225,139.25329438931973,1100.0,10.0
0.013626614375,0.13630613375,139.4158146359375,1100.0,10.0
0.01371060525,0.1371460425,139.5789320446879,1100.0,10.0
0.013794596125000001,0.13798595125000002,139.74204945343809,1100.0,10.0
0.013878587000000001,0.13882586,139.9051668621875,1100.0,10.0
0.013962577875000002,0.13966576874999997,140.068284270937,1100.0,10.0
0.014046568750000002,0.14050567749999998,140.23140167968714,1100.0,10.0
0.014130559625,0.14134558625,140.39451908843773,1100.0,10.0
0.014214550500000001,0.142185495,140.55890295825753,1100.0,10.0
0.014298541375000001,0.14302540375,140.72308776373535,1100.0,10.0
0.01438253225,0.1438653125,140.88528879008499,1100.0,10.0
0.014466523125,0.14470522125000002,141.04427046553087,1100.0,10.0
0.014550514,0.14554513,141.19934636130841,1100.0,10.0
0.01463176625,0.1463576525,141.35037919166544,1100.0,10.0
0.014713018500000001,0.14717017500000001,141.4977808138597,1100.0,10.0
0.014794270750000001,0.1479826975,141.6425122281607,1100.0,10.0
0.014875523000000002,0.14879522,141.7860835778505,1100.0,10.0
0.014956775250000002,0.1496077425,141.93055414922125,1100.0,10.0
0.015038027500000002,0.150420265,142.075549838596,1100.0,10.0
0.015119279750000002,0.1512327875,142.22054552797124,1100.0,10.0
0.015200532000000001,0.15204531,142.3655412173464,1100.0,10.0
0.01528178425,0.15285783249999998,142.5105369067216,1100.0,10.0
0.0153630365,0.15367035499999998,142.65553259609683,1100.0,10.0
0.01544428875,0.1544828775,142.80052828547122,1100.0,10.0
0.015525541,0.1552954,142.94744899298428,1100.0,10.0
0.01560679325,0.1561079225,143.094067123121,1100.0,10.0
0.0156880455,0.15692044500000002,143.23766991319172,1100.0,10.0
0.01576929775,0.15773296750000002,143.37637929671885,1100.0,10.0
0.01585055,0.15854549,143.5091519034377,1100.0,10.0
0.015934581500000003,0.15938580500000002,143.63577905929472,1100.0,10.0
0.016018613,0.16022612000000003,143.7568867864492,1100.0,10.0
0.0161026445,0.161066435,143.87393580327222,1100.0,10.0
0.016186676,0.16190675000000002,143.989221524347,1100.0,10.0
0.016270707500000002,0.16274706500000002,144.10587406046912,1100.0,10.0
0.016354739,0.16358738,144.22332477484446,1100.0,10.0
0.016438770499999998,0.164427695,144.3407754892199,1100.0,10.0
0.016522802,0.16526801000000002,144.45822620359525,1100.0,10.0
0.0166068335,0.166108325,144.57567691796976,1100.0,10.0
0.016690865,0.16694864,144.69312763234424,1100.0,10.0
0.016774896499999997,0.16778895500000002,144.81057834671927,1100.0,10.0
0.016858928,0.16862927,144.93031098378194,1100.0,10.0
0.0169429595,0.169469585,145.04968494464944,1100.0,10.0
0.017026991,0.17030990000000001,145.1654845117136,1100.0,10.0
0.017111022499999996,0.171150215,145.27548341893691,1100.0,10.0
0.017195053999999998,0.17199053,145.3784448518554,1100.0,10.0
0.017278498249999996,0.1728249725,145.4741214475753,1100.0,10.0
0.017361942499999998,0.17365941499999998,145.56325529477496,1100.0,10.0
0.01744538675,0.1744938575,145.64757793370566,1100.0,10.0
0.017528830999999998,0.1753283,145.72981035619057,1100.0,10.0
0.017612275249999997,0.1761627425,145.81366300562473,1100.0,10.0
0.0176957195,0.176997185,145.89846181812442,1100.0,10.0
0.01777916375,0.1778316275,145.983260630624,1100.0,10.0
0.017862608,0.17866607,146.06805944312367,1100.0,10.0
0.017946052249999997,0.17950051250000001,146.15285825562404,1100.0,10.0
0.0180294965,0.18033495500000002,146.23765706812472,1100.0,10.0
0.01811294075,0.1811693975,146.32245588062523,1100.0,10.0
0.018196385,0.18200384,146.4079173824005,1100.0,10.0
0.018279829249999997,0.1828382825,146.493274721634,1100.0,10.0
0.0183632735,0.18367272499999998,146.5775940272603,1100.0,10.0
0.01844671775,0.18450716749999999,146.66022877315729,1100.0,10.0
0.018530162,0.18534161,146.7408197781455,1100.0,10.0
0.018610247375,0.18614246375,146.8192952059898,1100.0,10.0
0.018690332749999997,0.18694331749999998,146.89587056539747,1100.0,10.0
0.018770418124999997,0.18774417124999998,146.97104871001858,1100.0,10.0
0.018850503499999997,0.18854502499999998,147.0456198384472,1100.0,10.0
0.018930588874999998,0.18934587874999997,147.12066149422034,1100.0,10.0
0.019010674249999998,0.19014673249999997,147.1959779235952,1100.0,10.0
0.019090759625,0.19094758624999997,147.27129435297027,1100.0,10.0
0.019170845,0.19174844,147.3466107823452,1100.0,10.0
0.019250930375,0.19254929375000002,147.42192721172034,1100.0,10.0
0.01933101575,0.1933501475,147.49724364109522,1100.0,10.0
0.019411101125,0.19415100125,147.57256007047053,1100.0,10.0
0.0194911865,0.194951855,147.64835823760103,1100.0,10.0
0.019571271875,0.19575270875,147.72408068443332,1100.0,10.0
0.01965135725,0.1965535625,147.79904853933422,1100.0,10.0
0.019731442624999998,0.19735441625,147.87279181425004,1100.0,10.0
0.019811528,0.19815527,147.94504940470657,1100.0,10.0
0.0198921984375,0.198961974375,148.01576908980854,1100.0,10.0
0.019972868875,0.19976867874999998,148.08510753224124,1100.0,10.0
0.0200535393125,0.200575383125,148.15343027826856,1100.0,10.0
0.02013420975,0.2013820875,148.22131175773455,1100.0,10.0
0.0202148801875,0.202188791875,148.28953528406234,1100.0,10.0
0.020295550625,0.20299549625000002,148.3579585553125,1100.0,10.0
0.020376221062499998,0.203802200625,148.42638182656253,1100.0,10.0
0.020456891499999998,0.204608905,148.49480509781287,1100.0,10.0
0.020537561937499997,0.205415609375,148.56322836906276,1100.0,10.0
0.020618232374999997,0.20622231375,148.6316516403125,1100.0,10.0
0.020698902812499996,0.207029018125,148.7000749115628,1100.0,10.0
0.020779573249999995,0.2078357225,148.76928137321428,1100.0,10.0
0.020860243687499995,0.20864242687499998,148.83836473176743,1100.0,10.0
0.020940914124999994,0.20944913124999998,148.9062213042727,1100.0,10.0
0.021021584562499994,0.210255835625,148.972087002533,1100.0,10.0
0.021102254999999997,0.21106254,149.03553733310693,1100.0,10.0
0.021180087937499995,0.21184086937500002,149.09648739730588,1100.0,10.0
0.021257920874999996,0.21261919875000002,149.15519189119482,1100.0,10.0
0.021335753812499997,0.213397528125,149.21224510559423,1100.0,10.0
0.021413586749999998,0.2141758575,149.26858092607688,1100.0,10.0
0.0214914196875,0.214954186875,149.32547283296975,1100.0,10.0
0.021569252625,0.21573251625,149.38268947734554,1100.0,10.0
0.0216470855625,0.216510845625,149.43990612172178,1100.0,10.0
0.0217249185,0.217289175,149.49712276609728,1100.0,10.0
0.021802751437499997,0.218067504375,149.55433941047272,1100.0,10.0
0.021880584374999998,0.21884583375,149.61155605484834,1100.0,10.0
0.0219584173125,0.219624163125,149.66877269922347,1100.0,10.0
0.02203625025,0.2204024925,149.72663737019,1100.0,10.0
0.0221140831875,0.221180821875,149.7844001833176,1100.0,10.0
0.022191916125000002,0.22195915125,149.84114793040098,1100.0,10.0
0.022269749062500004,0.22273748062499998,149.89624839037552,1100.0,10.0
0.022347582,0.22351581,149.94935032931622,1100.0,10.0
0.022426778,0.22430777000000002,150.00038350043855,1100.0,10.0
0.022505973999999998,0.22509973,150.04955864409595,1100.0,10.0
0.022585169999999998,0.22589169,150.09736748778525,1100.0,10.0
0.022664366,0.22668365000000001,150.1445827461406,1100.0,10.0
0.022743562,0.22747561,150.19225812093688,1100.0,10.0
0.022822758,0.22826757,150.24020218968545,1100.0,10.0
0.022901954,0.22905953,150.2881462584336,1100.0,10.0
0.02298115,0.22985149,150.33609032718252,1100.0,10.0
0.023060346,0.23064345,150.38403439593378,1100.0,10.0
0.023139542,0.23143541,150.43197846468564,1100.0,10.0
0.023218738,0.23222737,150.47992253343716,1100.0,10.0
0.023297934,0.23301933,150.5276542590238,1100.0,10.0
0.02337713,0.23381129,150.57541936104252,1100.0,10.0
0.023456326,0.23460324999999999,150.62351707647247,1100.0,10.0
0.023535522,0.23539521,150.67215456937467,1100.0,10.0
0.023614718,0.23618717,150.72144693089615,1100.0,10.0
0.0236922698125,0.236962688125,150.77141717926798,1100.0,10.0
0.023769821625,0.23773820625,150.82199625980243,1100.0,10.0
0.0238473734375,0.238513724375,150.87302304489458,1100.0,10.0
0.02392492525,0.2392892425,150.92424433402235,1100.0,10.0
0.0240024770625,0.24006476062499998,150.9753148537487,1100.0,10.0
0.024080028875,0.24084027875,151.02629732874928,1100.0,10.0
0.0241575806875,0.241615796875,151.07727980375063,1100.0,10.0
0.0242351325,0.242391315,151.12826227875144,1100.0,10.0
0.0243126843125,0.24316683312499998,151.1792447537522,1100.0,10.0
0.024390236125,0.24394235125,151.2302272287532,1100.0,10.0
0.0244677879375,0.244717869375,151.28120970375323,1100.0,10.0
0.02454533975,0.2454933875,151.33298509982507,1100.0,10.0
0.0246228915625,0.24626890562499998,151.38463586331602,1100.0,10.0
0.024700443375,0.24704442375,151.43504459867705,1100.0,10.0
0.0247779951875,0.247819941875,151.48343772437585,1100.0,10.0
0.024855547,0.24859546,151.5293854728917,1100.0,10.0
0.02493481175,0.24938810749999998,151.5728018907212,1100.0,10.0
0.0250140765,0.250180755,151.61394483837555,1100.0,10.0
0.025093341249999998,0.2509734025,151.65341599037978,1100.0,10.0
0.025172606,0.25176604999999996,151.69216083527675,1100.0,10.0
0.02525187075,0.2525586975,151.73146867562474,1100.0,10.0
0.025331135499999997,0.253351345,151.77110528812523,1100.0,10.0
0.02541040025,0.25414399249999997,151.81074190062668,1100.0,10.0
0.025489664999999998,0.25493664,151.85037851312777,1100.0,10.0
0.025568929749999997,0.2557292875,151.89001512562706,1100.0,10.0
0.0256481945,0.256521935,151.92965173812647,1100.0,10.0
0.025727459249999998,0.2573145825,151.9692883506254,1100.0,10.0
0.025806723999999996,0.25810723,152.00920248890617,1100.0,10.0
0.02588598875,0.2588998775,152.0490730052488,1100.0,10.0
0.025965253499999997,0.259692525,152.08850880641103,1100.0,10.0
0.026044518249999996,0.26048517250000003,152.12723913553125,1100.0,10.0
0.026123782999999998,0.26127782,152.16511357213096,1100.0,10.0
0.026201249875,0.26205248875,152.2021020321135,1100.0,10.0
0.026278716749999997,0.26282715749999996,152.23829476776547,1100.0,10.0
0.026356183624999995,0.26360182624999995,152.27390236775705,1100.0,10.0
0.026433650499999996,0.264376495,152.30925575713982,1100.0,10.0
0.026511117374999997,0.26515116375000003,152.34480619734768,1100.0,10.0
0.02658858425,0.2659258325,152.38047170922172,1100.0,10.0
0.026666051125,0.26670050125,152.41613722109588,1100.0,10.0
0.026743517999999997,0.26747517,152.45180273297137,1100.0,10.0
0.026820984874999995,0.26824983874999997,152.4874682448472,1100.0,10.0
0.026898451749999996,0.26902450749999995,152.52313375672256,1100.0,10.0
0.026975918624999998,0.26979917624999994,152.5587992685981,1100.0,10.0
0.0270533855,0.270573845,152.5954351207907,1100.0,10.0
0.027130852375,0.27134851375,152.63191845336615,1100.0,10.0
0.027208319249999998,0.2721231825,152.66688184907474,1100.0,10.0
0.027285786124999996,0.27289785125,152.69937863443786,1100.0,10.0
0.027363252999999997,0.27367252,152.7288828797458,1100.0,10.0
0.027441247375,0.27445246375,152.7552893990566,1100.0,10.0
0.02751924175,0.2752324075,152.77891375019578,1100.0,10.0
0.027597236125,0.27601235125,152.80049223475643,1100.0,10.0
0.0276752305,0.27679229499999997,152.82118189810518,1100.0,10.0
0.027753224874999996,0.2775722387499999,152.84256052937585,1100.0,10.0
0.027831219249999997,0.27835218249999993,152.86434149687548,1100.0,10.0
0.027909213625,0.27913212624999995,152.88612246437395,1100.0,10.0
0.027987208,0.27991206999999996,152.90790343187203,1100.0,10.0
0.028065202375,0.28069201374999997,152.9296843993724,1100.0,10.0
0.02814319675,0.2814719575,152.9514653668735,1100.0,10.0
0.028221191124999996,0.28225190125,152.97324633437455,1100.0,10.0
0.028299185499999997,0.283031845,152.99547071652586,1100.0,10.0
0.028377179875,0.28381178875,153.01762540206502,1100.0,10.0
0.02845517425,0.2845917325,153.03908552481883,1100.0,10.0
0.028533168625,0.28537167625000004,153.0594184851268,1100.0,10.0
0.028611163,0.28615162,153.07838394984486,1100.0,10.0
0.028686173937499997,0.286901729375,153.09593385234473,1100.0,10.0
0.028761184874999998,0.28765183875,153.11221239251336,1100.0,10.0
0.0288361958125,0.288401948125,153.12755603675222,1100.0,10.0
0.028911206749999998,0.28915205749999995,153.14249351797812,1100.0,10.0
0.028986217687499996,0.2899021668749999,153.157745835623,1100.0,10.0
0.029061228624999998,0.29065227624999995,153.17318200812375,1100.0,10.0
0.0291362395625,0.291402385625,153.18861818062524,1100.0,10.0
0.029211250499999997,0.29215249499999996,153.20405435312594,1100.0,10.0
0.029286261437499995,0.29290260437499993,153.21949052562616,1100.0,10.0
0.029361272374999997,0.29365271374999996,153.23492669812586,1100.0,10.0
0.0294362833125,0.294402823125,153.25036287062557,1100.0,10.0
0.029511294249999997,0.29515293249999996,153.26551085355752,1100.0,10.0
0.029586305187499995,0.29590304187499994,153.28070413457894,1100.0,10.0
0.029661316124999997,0.29665315124999997,153.29634883448892,1100.0,10.0
0.029736327062499998,0.297403260625,153.31272611384273,1100.0,10.0
0.029811337999999996,0.29815337,153.32999217294903,1100.0,10.0
0.029887169624999994,0.29891168625,153.34817825186826,1100.0,10.0
0.029963001249999996,0.2996700025,153.36719063041556,1100.0,10.0
0.030038832874999997,0.30042831875,153.3868106281601,1100.0,10.0
0.0301146645,0.301186635,153.40669460442456,1100.0,10.0
0.030190496125,0.30194495125,153.42637395828453,1100.0,10.0
0.03026632775,0.3027032675,153.44593381890772,1100.0,10.0
0.030342159374999997,0.30346158375,153.4654936795312,1100.0,10.0
0.030417991,0.3042199,153.48505354015526,1100.0,10.0
0.030493822625,0.30497821625,153.50461340078095,1100.0,10.0
0.030569654249999998,0.3057365325,153.52417326140684,1100.0,10.0
0.030645485874999996,0.30649484875,153.54373312203163,1100.0,10.0
0.030721317499999998,0.307253165,153.56337242812043,1100.0,10.0
0.030797149125,0.30801148125,153.58299924684684,1100.0,10.0
0.03087298075,0.3087697975,153.6025016225414,1100.0,10.0
0.030948812375000002,0.30952811375,153.62180204743447,1100.0,10.0
0.031024644,0.31028643,153.64085746165662,1100.0,10.0
0.031100436000000002,0.31104434999999997,153.65965925323312,1100.0,10.0
0.031176228,0.31180227,153.6782332580873,1100.0,10.0
0.031252020000000005,0.31256019,153.69663976003835,1100.0,10.0
0.031327812000000003,0.31331811,153.7149734908051,1100.0,10.0
0.031403604,0.31407602999999995,153.7333636300046,1100.0,10.0
0.03147939600000001,0.31483395,153.751786710007,1100.0,10.0
0.031555188000000005,0.31559187,153.77020979000824,1100.0,10.0
0.03163098,0.31634978999999996,153.788632870008,1100.0,10.0
0.031706772,0.31710770999999993,153.80705595000722,1100.0,10.0
0.031782564,0.31786562999999995,153.8254790300054,1100.0,10.0
0.031858356000000004,0.31862355,153.8439021100029,1100.0,10.0
0.031934148,0.31938146999999995,153.8624281624033,1100.0,10.0
0.03200994,0.32013938999999997,153.88093802944041,1100.0,10.0
0.032085732000000006,0.32089731,153.89928660095313,1100.0,10.0
0.032161524000000004,0.32165522999999996,153.91737341606108,1100.0,10.0
0.032237316,0.32241315,153.93514266316458,1100.0,10.0
0.0323128700625,0.323168690625,153.95258317994208,1100.0,10.0
0.032388424125,0.32392423125,153.9697284533536,1100.0,10.0
0.032463978187500006,0.324679771875,153.98665661963824,1100.0,10.0
0.03253953225,0.3254353125,154.00349046431768,1100.0,10.0
0.0326150863125,0.326190853125,154.02039742219335,1100.0,10.0
0.032690640375,0.32694639375,154.03734707594197,1100.0,10.0
0.03276619443750001,0.327701934375,154.0542967296898,1100.0,10.0
0.032841748500000004,0.328457475,154.07124638343873,1100.0,10.0
0.0329173025625,0.329213015625,154.08819603719047,1100.0,10.0
0.032992856625000004,0.32996855625,154.10514569094138,1100.0,10.0
0.03306841068750001,0.330724096875,154.12209534469102,1100.0,10.0
0.033143964750000005,0.3314796375,154.1390882535139,1100.0,10.0
0.0332195188125,0.332235178125,154.15607436343726,1100.0,10.0
0.033295072875000005,0.33299071874999997,154.17299271880216,1100.0,10.0
0.03337062693750001,0.333746259375,154.1898011195353,1100.0,10.0
0.033446181000000005,0.3345018,154.20647612115357,1100.0,10.0
0.033523512062500004,0.33527511062500004,154.22301303476374,1100.0,10.0
0.033600843125,0.33604842125,154.23942592705527,1100.0,10.0
0.03367817418750001,0.33682173187500003,154.25574762030232,1100.0,10.0
0.033755505250000005,0.33759504250000005,154.27202969237112,1100.0,10.0
0.0338328363125,0.338368353125,154.28834247671585,1100.0,10.0
0.03391016737500001,0.33914166375000004,154.3046731960919,1100.0,10.0
0.033987498437500006,0.33991497437500007,154.3210039154672,1100.0,10.0
0.034064829500000005,0.34068828500000004,154.3373346348417,1100.0,10.0
0.0341421605625,0.341461595625,154.35366535421576,1100.0,10.0
0.034219491625,0.34223490625,154.3699960735901,1100.0,10.0
0.034296822687500006,0.34300821687500005,154.38632679296543,1100.0,10.0
0.034374153750000004,0.3437815275,154.40311252393326,1100.0,10.0
0.0344514848125,0.344554838125,154.41982673546434,1100.0,10.0
0.03452881587500001,0.34532814875,154.43582821880972,1100.0,10.0
0.034606146937500006,0.34610145937500003,154.45067306021693,1100.0,10.0
0.034683478000000004,0.34687477,154.46411464093575,1100.0,10.0
0.034761729250000005,0.3476572825,154.4761036372161,1100.0,10.0
0.034839980500000006,0.348439795,154.48678802030923,1100.0,10.0
0.03491823175,0.3492223075,154.4965130564657,1100.0,10.0
0.034996483,0.35000482,154.5058213069357,1100.0,10.0
0.03507473425,0.3507873325,154.51545262796864,1100.0,10.0
0.0351529855,0.351569845,154.5252726123449,1100.0,10.0
0.03523123675,0.3523523575,154.53509259672194,1100.0,10.0
0.035309488,0.35313487,154.54491258109812,1100.0,10.0
0.03538773925,0.3539173825,154.55473256547248,1100.0,10.0
0.0354659905,0.354699895,154.56455254984613,1100.0,10.0
0.035544241750000004,0.3554824075,154.57437253422094,1100.0,10.0
0.035622493000000005,0.35626492,154.58474950286768,1100.0,10.0
0.035700744250000006,0.3570474325,154.59503892385106,1100.0,10.0
0.03577899550000001,0.357829945,154.60445588708663,1100.0,10.0
0.03585724675,0.3586124575,154.6124569932835,1100.0,10.0
0.035935498,0.35939497,154.6187403539484,1100.0,10.0
0.0360138684375,0.36017867437499995,154.62324559138182,1100.0,10.0
0.036092238875,0.36096237875,154.62615383867964,1100.0,10.0
0.036170609312500004,0.361746083125,154.62788773973398,1100.0,10.0
0.03624897975000001,0.3625297875,154.6291114492323,1100.0,10.0
0.03632735018750001,0.36331349187499995,154.63073063265838,1100.0,10.0
0.036405720625000006,0.36409719625,154.63258076078225,1100.0,10.0
0.0364840910625,0.364880900625,154.6344308889078,1100.0,10.0
0.036562461500000004,0.365664605,154.63628101703324,1100.0,10.0
0.03664083193750001,0.36644830937499995,154.63813114515872,1100.0,10.0
0.036719202375,0.36723201375,154.63998127328446,1100.0,10.0
0.0367975728125,0.368015718125,154.64183140140904,1100.0,10.0
0.03687594325,0.3687994225,154.64321899750098,1100.0,10.0
0.036954313687500004,0.369583126875,154.64506912562447,1100.0,10.0
0.03703268412500001,0.37036683125000003,154.64691925374848,1100.0,10.0
0.03711105456250001,0.371150535625,154.6487693818735,1100.0,10.0
0.037189425000000005,0.37193424,154.6506195100001,1100.0,10.0