File: datasets/steel_spring/csv/BS2V-1200-1.0.csv
Time(s),Strain(%),Stress(MPa),Temp(C),SR(%/s)
0.0,3.252e-05,0.28206496898362987,1200.0,1.0
5.354999999999999e-06,3.7875e-05,0.5719808915143113,1200.0,1.0
1.0709999999999997e-05,4.323e-05,0.5293119589951166,1200.0,1.0
1.3364999999999998e-05,4.5885e-05,0.3250834890822415,1200.0,1.0
1.602e-05,4.854e-05,0.1303207994318809,1200.0,1.0
2.6734999999999997e-05,5.9255e-05,0.21572881855303133,1200.0,1.0
3.7449999999999995e-05,6.997e-05,0.7428445147253822,1200.0,1.0
0.000104335,0.00013685500000000002,1.8308708458333394,1200.0,1.0
0.00017122,0.00020374,3.604958416852285,1200.0,1.0
0.00041466500000000004,0.000447185,6.089570511757598,1200.0,1.0
0.00065811,0.00069063,9.234515321634504,1200.0,1.0
0.000998105,0.0010306249999999999,12.726921716257625,1200.0,1.0
0.0013380999999999998,0.00137062,16.459782582909153,1200.0,1.0
0.0017319050000000002,0.001764425,20.108620226787956,1200.0,1.0
0.0021257100000000003,0.00215823,23.500112734240624,1200.0,1.0
0.00262713,0.0026596500000000004,26.417150534598594,1200.0,1.0
0.0031285500000000003,0.00316107,28.806035482596705,1200.0,1.0
0.0037191000000000004,0.00375162,30.671547797363758,1200.0,1.0
0.00430965,0.00434217,32.08309612622646,1200.0,1.0
0.004930445,0.004962965,33.1917170962956,1200.0,1.0
0.00555124,0.00558376,34.085581780911134,1200.0,1.0
0.006156729999999999,0.00618925,34.89659310334863,1200.0,1.0
0.006762219999999999,0.00679474,35.642507662614726,1200.0,1.0
0.00741689,0.00744941,36.36025451263651,1200.0,1.0
0.00807156,0.00810408,37.05723461891587,1200.0,1.0
0.008667765000000001,0.008700284999999999,37.739804116575925,1200.0,1.0
0.00926397,0.00929649,38.40968842651341,1200.0,1.0
0.00988249,0.009915009999999998,39.06516699887893,1200.0,1.0
0.01050101,0.01053353,39.70546158936945,1200.0,1.0
0.01111751,0.01115003,40.33339292862135,1200.0,1.0
0.011734010000000001,0.01176653,40.954872444061685,1200.0,1.0
0.012348685000000002,0.012381205,41.557465435909236,1200.0,1.0
0.01296336,0.01299588,42.13312605254753,1200.0,1.0
0.013554315,0.013586834999999998,42.67935745844714,1200.0,1.0
0.01414527,0.01417779,43.19573931000016,1200.0,1.0
0.014772259999999999,0.01480478,43.68186675943197,1200.0,1.0
0.01539925,0.01543177,44.13566545989599,1200.0,1.0
0.016037865,0.016070385,44.5615711354547,1200.0,1.0
0.01667648,0.016709,44.97623700943105,1200.0,1.0
0.017288699999999997,0.01732122,45.388795050378995,1200.0,1.0
0.017900919999999997,0.01793344,45.790755921664044,1200.0,1.0
0.018535674999999998,0.018568195,46.17477729318959,1200.0,1.0
0.01917043,0.01920295,46.53967368693674,1200.0,1.0
0.019795109999999998,0.01982763,46.88727788476535,1200.0,1.0
0.02041979,0.02045231,47.21585657789985,1200.0,1.0
0.0210671,0.02109962,47.529154949863866,1200.0,1.0
0.02171441,0.02174693,47.841787150986946,1200.0,1.0
0.022346159999999997,0.022378679999999998,48.15923833592446,1200.0,1.0
0.022977909999999997,0.02301043,48.471944134218006,1200.0,1.0
0.023613185,0.023645705,48.77591034137138,1200.0,1.0
0.02424846,0.02428098,49.06961651350201,1200.0,1.0
0.024879045,0.024911565,49.35461814301525,1200.0,1.0
0.02550963,0.02554215,49.63776123918286,1200.0,1.0
0.026146509999999998,0.02617903,49.9167252943789,1200.0,1.0
0.026783389999999997,0.02681591,50.1887766304452,1200.0,1.0
0.02740183,0.02743435,50.46122607045466,1200.0,1.0
0.02802027,0.02805279,50.735047028105285,1200.0,1.0
0.028667005,0.028699525,51.003194852379,1200.0,1.0
0.029313739999999998,0.02934626,51.26280801215741,1200.0,1.0
0.02996136,0.02999388,51.51498780549265,1200.0,1.0
0.030608979999999997,0.0306415,51.76656303906842,1200.0,1.0
0.03126013,0.03129265,52.02058828154571,1200.0,1.0
0.03191128,0.0319438,52.27148426326255,1200.0,1.0
0.03253016,0.03256268,52.51059961418964,1200.0,1.0
0.03314904,0.03318156,52.737430462057056,1200.0,1.0
0.03381019,0.03384271,52.95747323571997,1200.0,1.0
0.034471339999999996,0.03450386,53.16886214722658,1200.0,1.0
0.035102855,0.035135374999999996,53.373646935924484,1200.0,1.0
0.03573437,0.03576689,53.57929670359876,1200.0,1.0
0.03637505,0.03640757,53.792463972659434,1200.0,1.0
0.03701573,0.03704825,54.01420898526931,1200.0,1.0
0.037654419999999994,0.03768694,54.243851028348864,1200.0,1.0
0.03829311,0.03832563,54.47862010052023,1200.0,1.0
0.038943765,0.038976285,54.712826121939784,1200.0,1.0
0.03959442,0.03962694,54.94361101688105,1200.0,1.0
0.040220839999999994,0.04025336,55.16834089900027,1200.0,1.0
0.040847259999999996,0.04087978,55.38944871789417,1200.0,1.0
0.041491175,0.041523695,55.60702930473509,1200.0,1.0
0.04213509,0.04216761,55.81957969751348,1200.0,1.0
0.04277152,0.04280404,56.02663372146234,1200.0,1.0
0.04340795,0.04344047,56.2289889028079,1200.0,1.0
0.044053565,0.044086085,56.42664736806073,1200.0,1.0
0.04469918,0.0447317,56.61949694582021,1200.0,1.0
0.045289605,0.045322125000000005,56.80657904331826,1200.0,1.0
0.04588003,0.04591255,56.985912909349494,1200.0,1.0
0.046549654999999995,0.046582175,57.1617250103335,1200.0,1.0
0.047219279999999995,0.0472518,57.340205012597806,1200.0,1.0
0.047844874999999995,0.047877395,57.519307119166996,1200.0,1.0
0.04847047,0.04850299,57.69252235783648,1200.0,1.0
0.04908843,0.04912095,57.86297296033364,1200.0,1.0
0.049706389999999996,0.04973891,58.03802845853353,1200.0,1.0
0.050364519999999996,0.05039704,58.215884397909505,1200.0,1.0
0.051022649999999996,0.05105517,58.38815881843697,1200.0,1.0
0.05163374999999999,0.05166627,58.55408135753832,1200.0,1.0
0.052244849999999995,0.05227737,58.72098316777412,1200.0,1.0
0.052839744999999994,0.052872265,58.89431507017455,1200.0,1.0
0.05343464,0.05346716,59.070817966857255,1200.0,1.0
0.05405848,0.054091,59.24398475771986,1200.0,1.0
0.05468232,0.05471484,59.41534275386182,1200.0,1.0
0.055321075,0.055353595000000005,59.59093994789405,1200.0,1.0
0.05595983,0.05599235,59.76901125781739,1200.0,1.0
0.056565475000000004,0.056597995,59.9429494800078,1200.0,1.0
0.05717112,0.05720364,60.11539311913012,1200.0,1.0
0.05779167,0.05782419,60.287124433917114,1200.0,1.0
0.05841222,0.05844474,60.45272513998243,1200.0,1.0
0.05903062,0.05906314,60.61382588586409,1200.0,1.0
0.05964902,0.05968154,60.77679986676559,1200.0,1.0
0.060259725,0.060292244999999994,60.93750441677315,1200.0,1.0
0.060870429999999996,0.06090295,61.091819770345175,1200.0,1.0
0.061493284999999995,0.061525805,61.24183819759147,1200.0,1.0
0.06211614,0.06214866,61.38662449095224,1200.0,1.0
0.062722645,0.062755165,61.52878827791705,1200.0,1.0
0.06332915,0.06336167,61.67012030461198,1200.0,1.0
0.06394782,0.06398034,61.80928455648493,1200.0,1.0
0.06456649,0.06459901,61.95235157723022,1200.0,1.0
0.06517732500000001,0.065209845,62.10440710406086,1200.0,1.0
0.06578816000000001,0.06582068,62.2563887850989,1200.0,1.0
0.066411195,0.066443715,62.40449135768241,1200.0,1.0
0.06703423,0.06706675,62.55396044935113,1200.0,1.0
0.06762084500000001,0.067653365,62.70379038104614,1200.0,1.0
0.06820746000000001,0.06823998,62.85242356940008,1200.0,1.0
0.06883485,0.06886737000000001,63.00266338735644,1200.0,1.0
0.06946224000000001,0.06949476,63.15723584950409,1200.0,1.0
0.070058875,0.070091395,63.314373150674534,1200.0,1.0
0.07065551,0.07068803,63.46925628175704,1200.0,1.0
0.071267225,0.071299745,63.61709387334123,1200.0,1.0
0.07187894,0.07191146,63.76107996758816,1200.0,1.0
0.072520165,0.072552685,63.90448282191671,1200.0,1.0
0.07316139,0.07319391,64.04348422256916,1200.0,1.0
0.07377464,0.07380716000000001,64.17621340801522,1200.0,1.0
0.07438789000000001,0.07442041,64.30698080056743,1200.0,1.0
0.074984615,0.07501713500000001,64.43922830575018,1200.0,1.0
0.07558134000000001,0.07561386,64.57203444422281,1200.0,1.0
0.07619029000000001,0.07622281,64.70409638063678,1200.0,1.0
0.07679924,0.07683176,64.833864537668,1200.0,1.0
0.077420515,0.077453035,64.96318369743962,1200.0,1.0
0.07804179,0.07807431,65.09635913157024,1200.0,1.0
0.07869565,0.07872817,65.22972884459861,1200.0,1.0
0.07934951000000001,0.07938203,65.35705836651435,1200.0,1.0
0.07994920500000001,0.079981725,65.48102882867444,1200.0,1.0
0.0805489,0.08058142,65.605161709824,1200.0,1.0
0.08115507500000001,0.081187595,65.73030008221237,1200.0,1.0
0.08176125000000001,0.08179377,65.85603055356376,1200.0,1.0
0.082379795,0.082412315,65.98244860100787,1200.0,1.0
0.08299834,0.08303086,66.11434757750213,1200.0,1.0
0.08360600500000001,0.08363852499999999,66.2537455944395,1200.0,1.0
0.08421367,0.08424619,66.39101657299143,1200.0,1.0
0.08483962,0.08487214,66.52176045665135,1200.0,1.0
0.08546557,0.08549809,66.65494382140433,1200.0,1.0
0.08604264,0.08607516,66.79170857728798,1200.0,1.0
0.08661971,0.08665223,66.9274094508469,1200.0,1.0
0.08727926,0.08731178,67.05992562437916,1200.0,1.0
0.08793881,0.08797133,67.18811048636312,1200.0,1.0
0.08851144500000001,0.088543965,67.31419492791714,1200.0,1.0
0.08908408000000001,0.0891166,67.43950656749483,1200.0,1.0
0.08972186000000001,0.08975438,67.56076133632641,1200.0,1.0
0.09035964,0.09039216,67.68235443354135,1200.0,1.0
0.09097179500000001,0.091004315,67.80768462576586,1200.0,1.0
0.09158395000000001,0.09161647,67.93113591352639,1200.0,1.0
0.0922174,0.09224992000000001,68.04778423141737,1200.0,1.0
0.09285085000000001,0.09288337,68.1530632667846,1200.0,1.0
0.09345281500000001,0.093485335,68.25101320062141,1200.0,1.0
0.09405478,0.0940873,68.35480729601706,1200.0,1.0
0.094680985,0.094713505,68.46672895139389,1200.0,1.0
0.09530719,0.09533971,68.58200775292813,1200.0,1.0
0.095901765,0.095934285,68.69812778981834,1200.0,1.0
0.09649634,0.09652886,68.80717769321039,1200.0,1.0
0.097135885,0.097168405,68.9103731242123,1200.0,1.0
0.09777543000000001,0.09780795,69.01442273637332,1200.0,1.0
0.09841281500000001,0.098445335,69.11803341128056,1200.0,1.0
0.0990502,0.09908272,69.22637417865468,1200.0,1.0
0.099626305,0.099658825,69.34559505467453,1200.0,1.0
0.10020241,0.10023493,69.46907150241714,1200.0,1.0
0.10081176,0.10084428000000001,69.5907220481066,1200.0,1.0
0.10142111000000001,0.10145363,69.70883888749474,1200.0,1.0
0.10204901000000001,0.10208153,69.81849645264424,1200.0,1.0
0.10267691000000001,0.10270943,69.92159655783459,1200.0,1.0
0.10326999,0.10330251,70.02609736928063,1200.0,1.0
0.10386307,0.10389559,70.13399938348422,1200.0,1.0
0.10450135,0.10453387,70.24472136249277,1200.0,1.0
0.10513963000000001,0.10517215,70.36190738444064,1200.0,1.0
0.10573117000000001,0.10576369,70.47913635534131,1200.0,1.0
0.10632271,0.10635523,70.58715950623063,1200.0,1.0
0.10692989,0.10696241000000001,70.6864453704398,1200.0,1.0
0.10753707000000001,0.10756959,70.77731504617087,1200.0,1.0
0.10815984000000001,0.10819236,70.85976824468995,1200.0,1.0
0.10878261,0.10881513,70.93818545599679,1200.0,1.0
0.10943901,0.10947153,71.0188019673261,1200.0,1.0
0.11009541,0.11012793,71.1042935036496,1200.0,1.0
0.11066896500000001,0.110701485,71.20145235425726,1200.0,1.0
0.11124252000000001,0.11127504,71.3128743984296,1200.0,1.0
0.111873595,0.111906115,71.42666047556042,1200.0,1.0
0.11250467,0.11253719,71.53324387192214,1200.0,1.0
0.113136595,0.113169115,71.63357731392412,1200.0,1.0
0.11376852000000001,0.11380104,71.73125833816272,1200.0,1.0
0.11435615000000002,0.11438867,71.82544509003759,1200.0,1.0
0.11494378000000001,0.1149763,71.91263312296074,1200.0,1.0
0.11559524500000001,0.115627765,71.99585154116602,1200.0,1.0
0.11624671,0.11627923,72.08658286676825,1200.0,1.0
0.11680878,0.11684130000000001,72.19011856448408,1200.0,1.0
0.11737085000000001,0.11740337,72.29704966505987,1200.0,1.0
0.11802389500000002,0.118056415,72.398260746219,1200.0,1.0
0.11867694000000001,0.11870946,72.48852585687233,1200.0,1.0
0.11929461000000001,0.11932713,72.57930688680221,1200.0,1.0
0.11991228000000001,0.1199448,72.68822090900109,1200.0,1.0
0.12054885000000001,0.12058137,72.80815350771168,1200.0,1.0
0.12118542,0.12121794,72.92953509221392,1200.0,1.0
0.12237025000000001,0.12240277,73.05353896746975,1200.0,1.0
0.12355508000000001,0.1235876,73.1788517217057,1200.0,1.0
0.12414855000000001,0.12418107,73.29689635475037,1200.0,1.0
0.12474202000000001,0.12477454,73.4009830919436,1200.0,1.0
0.12533619000000001,0.12536871,73.48444652946239,1200.0,1.0
0.12593036,0.12596288,73.55700051287894,1200.0,1.0
0.126573795,0.126606315,73.63507012214392,1200.0,1.0
0.12721723,0.12724975,73.7129269828155,1200.0,1.0
0.127834165,0.12786668499999998,73.78340896996242,1200.0,1.0
0.12845109999999998,0.12848362,73.85124073633837,1200.0,1.0
0.12906879999999998,0.12910132,73.9237976951218,1200.0,1.0
0.12968649999999998,0.12971902,74.00100962254344,1200.0,1.0
0.130304955,0.13033747499999998,74.08259162547812,1200.0,1.0
0.13092341,0.13095593,74.16866803686727,1200.0,1.0
0.13155178,0.1315843,74.25724409061448,1200.0,1.0
0.13218015,0.13221267,74.34684964446403,1200.0,1.0
0.13278483,0.13281735,74.43734329374362,1200.0,1.0
0.13338951,0.13342203,74.53033065788604,1200.0,1.0
0.13401027,0.13404279,74.62328083931207,1200.0,1.0
0.13463102999999998,0.13466355,74.71219263440011,1200.0,1.0
0.13524641999999998,0.13527894000000001,74.79783406753901,1200.0,1.0
0.13586181,0.13589433,74.88566634211332,1200.0,1.0
0.136499435,0.136531955,74.9742661093714,1200.0,1.0
0.13713706,0.13716958,75.05665376878503,1200.0,1.0
0.13770485,0.13773737000000003,75.13360094443946,1200.0,1.0
0.13827264,0.13830516,75.21280406395095,1200.0,1.0
0.13892102,0.13895354,75.29480077920483,1200.0,1.0
0.13956939999999998,0.13960192,75.37206919473908,1200.0,1.0
0.140209395,0.140241915,75.44350898947792,1200.0,1.0
0.14084939,0.14088191,75.51888291149801,1200.0,1.0
0.14147479,0.14150731,75.5990546640689,1200.0,1.0
0.14210019,0.14213271,75.67330362291993,1200.0,1.0
0.14270166499999998,0.142734185,75.73665838431063,1200.0,1.0
0.14330314,0.14333566,75.7927275429439,1200.0,1.0
0.14395791,0.14399043,75.8498439959238,1200.0,1.0
0.14461268,0.1446452,75.90734803632625,1200.0,1.0
0.14517233499999999,0.14520485500000002,75.96586901693126,1200.0,1.0
0.14573199,0.14576451,76.0389381428829,1200.0,1.0
0.146375945,0.146408465,76.1276732923479,1200.0,1.0
0.14701989999999998,0.14705242,76.21471451504483,1200.0,1.0
0.14762746499999999,0.147659985,76.29366876367357,1200.0,1.0
0.14823503,0.14826755,76.37010718242918,1200.0,1.0
0.14886507499999999,0.148897595,76.44285215800689,1200.0,1.0
0.14949511999999998,0.14952764,76.51012900283119,1200.0,1.0
0.15009796999999997,0.15013049,76.5743594859927,1200.0,1.0
0.15070081999999999,0.15073334,76.64045720213902,1200.0,1.0
0.151323045,0.151355565,76.7166728423646,1200.0,1.0
0.15194527,0.15197779,76.80181970017122,1200.0,1.0
0.15258080499999999,0.152613325,76.88433492797027,1200.0,1.0
0.15321633999999998,0.15324886,76.96353608321803,1200.0,1.0
0.15384638499999997,0.153878905,77.04265371547714,1200.0,1.0
0.15447643,0.15450895,77.1182934983763,1200.0,1.0
0.155091645,0.155124165,77.18607719046153,1200.0,1.0
0.15570686,0.15573938,77.24578031457136,1200.0,1.0
0.15633847499999998,0.156370995,77.2990916184769,1200.0,1.0
0.15697008999999998,0.15700261,77.34847501536447,1200.0,1.0
0.15757746499999997,0.157609985,77.40236253499216,1200.0,1.0
0.15818484,0.15821736,77.46420480669953,1200.0,1.0
0.15883376,0.15886628,77.53139002182564,1200.0,1.0
0.15948268,0.1595152,77.60283060207746,1200.0,1.0
0.16009157999999998,0.1601241,77.6772602845301,1200.0,1.0
0.16070047999999998,0.160733,77.75319723936458,1200.0,1.0
0.16131012499999997,0.161342645,77.82670609073513,1200.0,1.0
0.16191977,0.16195229,77.89284620128822,1200.0,1.0
0.16253958,0.1625721,77.9506778219099,1200.0,1.0
0.16315939,0.16319191,78.00464996390045,1200.0,1.0
0.1637611,0.16379362,78.06091857759918,1200.0,1.0
0.16436281,0.16439533,78.12403665425171,1200.0,1.0
0.164981015,0.165013535,78.19079093247042,1200.0,1.0
0.16559922,0.16563174,78.25510017181125,1200.0,1.0
0.16622446,0.16625698,78.31680226455404,1200.0,1.0
0.1668497,0.16688222,78.37410961491804,1200.0,1.0
0.16747578,0.1675083,78.42647306933442,1200.0,1.0
0.16810186,0.16813438,78.47658315572812,1200.0,1.0
0.16870654499999999,0.168739065,78.52903242066716,1200.0,1.0
0.16931122999999998,0.16934375,78.59065138221494,1200.0,1.0
0.16991979499999998,0.169952315,78.66392570781026,1200.0,1.0
0.17052836,0.17056088,78.74301458336899,1200.0,1.0
0.17114081999999997,0.17117334,78.82000358603007,1200.0,1.0
0.17175327999999998,0.1717858,78.89338793764591,1200.0,1.0
0.17239196499999998,0.172424485,78.96083083224302,1200.0,1.0
0.17303064999999998,0.17306317,79.01930588772807,1200.0,1.0
0.173654235,0.173686755,79.07068600333399,1200.0,1.0
0.17427782,0.17431034,79.1213860327525,1200.0,1.0
0.17489580999999998,0.17492833000000002,79.17499662456852,1200.0,1.0
0.1755138,0.17554632,79.23060885499821,1200.0,1.0
0.17615488499999998,0.17618740500000002,79.28687947323488,1200.0,1.0
0.17679597,0.17682849,79.33992568202089,1200.0,1.0
0.17740593999999998,0.17743846000000002,79.39200324680313,1200.0,1.0
0.17801591,0.17804843,79.44807673153936,1200.0,1.0
0.1786298,0.17866231999999999,79.50521805632673,1200.0,1.0
0.17924368999999998,0.17927621,79.56168214075203,1200.0,1.0
0.17986792999999998,0.17990045,79.61986646582676,1200.0,1.0
0.18049216999999998,0.18052469,79.68019932536635,1200.0,1.0
0.18108513499999998,0.181117655,79.73998572792487,1200.0,1.0
0.18167809999999998,0.18171062,79.79626811144763,1200.0,1.0
0.18232958999999999,0.18236211,79.84543802183423,1200.0,1.0
0.18298108,0.1830136,79.88916660984583,1200.0,1.0
0.18357552,0.18360804,79.9335496329326,1200.0,1.0
0.18416996,0.18420248,79.97662106750326,1200.0,1.0
0.18478125,0.18481377,80.01856228399247,1200.0,1.0
0.18539254,0.18542506,80.06416083707946,1200.0,1.0
0.186007725,0.186040245,80.11744407935623,1200.0,1.0
0.18662291,0.18665543,80.18112479042286,1200.0,1.0
0.18725503500000001,0.187287555,80.25118560625104,1200.0,1.0
0.18788716,0.18791968,80.32001613097025,1200.0,1.0
0.18855239000000001,0.18858491,80.38383714787268,1200.0,1.0
0.18921762,0.18925014,80.44367288657295,1200.0,1.0
0.189776965,0.189809485,80.4979834748186,1200.0,1.0
0.19033630999999998,0.19036883,80.54623014849895,1200.0,1.0
0.19096108499999997,0.190993605,80.59185978881015,1200.0,1.0
0.19158586,0.19161838,80.63935721126579,1200.0,1.0
0.19223085,0.19226337,80.6918301722424,1200.0,1.0
0.19287584,0.19290836,80.74976296443018,1200.0,1.0
0.193511935,0.193544455,80.8056240766899,1200.0,1.0
0.19414803,0.19418055,80.85187814026189,1200.0,1.0
0.194768625,0.194801145,80.89136821142493,1200.0,1.0
0.19538922,0.19542174,80.92632190628049,1200.0,1.0
0.19603673,0.19606925,80.95791167519884,1200.0,1.0
0.19668423999999998,0.19671676,80.99007098407819,1200.0,1.0
0.19727706,0.19730957999999998,81.02772983078991,1200.0,1.0
0.19786988,0.1979024,81.07470152876502,1200.0,1.0
0.19849609000000001,0.19852861,81.13226139222101,1200.0,1.0
0.1991223,0.19915482,81.19360769346733,1200.0,1.0
0.19972972,0.19976224,81.25017460640879,1200.0,1.0
0.20033714,0.20036966,81.30105212179562,1200.0,1.0
0.20093219499999998,0.20096471500000002,81.34970572313594,1200.0,1.0
0.20152725,0.20155977,81.40179568561945,1200.0,1.0
0.20216231499999998,0.20219483500000002,81.4550568696591,1200.0,1.0
0.20279738,0.2028299,81.50493349210636,1200.0,1.0
0.20340372,0.20343624,81.5520896708172,1200.0,1.0
0.20401006,0.20404258,81.59479393732161,1200.0,1.0
0.204633555,0.204666075,81.63472152165187,1200.0,1.0
0.20525705,0.20528957,81.67465616924834,1200.0,1.0
0.20589121999999999,0.20592374000000002,81.71599004450948,1200.0,1.0
0.20652539,0.20655791,81.76762228476842,1200.0,1.0
0.207130735,0.207163255,81.82922940075196,1200.0,1.0
0.20773608,0.2077686,81.88750414441955,1200.0,1.0
0.20835863,0.20839115,81.93608589591626,1200.0,1.0
0.20898118,0.2090137,81.97626418353323,1200.0,1.0
0.20960778,0.2096403,82.00835777531627,1200.0,1.0
0.21023438,0.2102669,82.03560434342505,1200.0,1.0
0.21085849499999998,0.21089101500000001,82.06238057073428,1200.0,1.0
0.21148261,0.21151513,82.0930738718954,1200.0,1.0
0.21209092499999999,0.212123445,82.13173290549216,1200.0,1.0
0.21269923999999998,0.21273176,82.17131252258719,1200.0,1.0
0.21334145,0.21337397,82.20644755461373,1200.0,1.0
0.21398366,0.21401618,82.24267885123396,1200.0,1.0
0.21460347,0.21463599,82.28101498959833,1200.0,1.0
0.21522328,0.2152558,82.3167894088085,1200.0,1.0
0.21580734499999998,0.215839865,82.35089125731797,1200.0,1.0
0.21639140999999998,0.21642393,82.38490817698793,1200.0,1.0
0.217065925,0.21709844499999997,82.4214103293927,1200.0,1.0
0.21774043999999998,0.21777296,82.46273191740966,1200.0,1.0
0.21832928,0.2183618,82.5074278007795,1200.0,1.0
0.21891812,0.21895064,82.55629111569446,1200.0,1.0
0.22014129,0.22017381,82.61062423861509,1200.0,1.0
0.22136445999999999,0.22139698,82.66707665535144,1200.0,1.0
0.22194208999999998,0.22197461000000002,82.71927200684435,1200.0,1.0
0.22251972,0.22255224,82.76596197575326,1200.0,1.0
0.223154895,0.223187415,82.8074497284951,1200.0,1.0
0.22379006999999998,0.22382259,82.84660169594305,1200.0,1.0
0.224402575,0.22443509499999997,82.88445104438004,1200.0,1.0
0.22501507999999998,0.2250476,82.91763587764306,1200.0,1.0
0.225645135,0.22567765499999998,82.94687876713782,1200.0,1.0
0.22627519,0.22630771,82.97606848411301,1200.0,1.0
0.22690602999999998,0.22693855000000002,83.00641771228166,1200.0,1.0
0.22753687,0.22756939,83.03648582652157,1200.0,1.0
0.22813826999999998,0.22817079,83.06556447325848,1200.0,1.0
0.22873966999999998,0.22877219,83.09407790348844,1200.0,1.0
0.22938552499999998,0.229418045,83.12342821873382,1200.0,1.0
0.23003137999999998,0.2300639,83.1527625005896,1200.0,1.0
0.23063088499999998,0.230663405,83.17974695196114,1200.0,1.0
0.23123038999999998,0.23126291,83.20508903106975,1200.0,1.0
0.23184747499999997,0.231879995,83.23184912124277,1200.0,1.0
0.23246456,0.23249708,83.2620509546268,1200.0,1.0
0.23308582,0.23311833999999998,83.29291669160042,1200.0,1.0
0.23370707999999998,0.2337396,83.32007544989794,1200.0,1.0
0.234335885,0.234368405,83.34379604907801,1200.0,1.0
0.23496469,0.23499721,83.36631887836792,1200.0,1.0
0.2355807,0.23561322,83.38914534974433,1200.0,1.0
0.23619671,0.23622923,83.41213033756993,1200.0,1.0
0.23680671,0.23683923,83.43559570258527,1200.0,1.0
0.23741671,0.23744923,83.46303357180385,1200.0,1.0
0.23804445,0.23807697,83.49537853986526,1200.0,1.0
0.23867218999999998,0.23870471,83.52876264854335,1200.0,1.0
0.23928030499999997,0.239312825,83.55788652891911,1200.0,1.0
0.23988842,0.23992094,83.5801590911138,1200.0,1.0
0.24050064999999998,0.24053317000000002,83.59854191362402,1200.0,1.0
0.24111288,0.2411454,83.61584387952307,1200.0,1.0
0.24176340000000002,0.24179592,83.63430371266001,1200.0,1.0
0.24241392,0.24244644,83.65811616994873,1200.0,1.0
0.243010675,0.243043195,83.68823511090908,1200.0,1.0
0.24360742999999999,0.24363995,83.72221337378268,1200.0,1.0
0.244218545,0.244251065,83.75697196172672,1200.0,1.0
0.24482966,0.24486218,83.78741816604052,1200.0,1.0
0.24544499,0.24547751,83.81125314240882,1200.0,1.0
0.24606032,0.24609284,83.83211529911945,1200.0,1.0
0.24670716999999998,0.24673969,83.8528395191122,1200.0,1.0
0.24735401999999998,0.24738654,83.87710205128863,1200.0,1.0
0.24796744499999998,0.247999965,83.9047245363709,1200.0,1.0
0.24858086999999998,0.24861339,83.9305777674181,1200.0,1.0
0.24921909999999997,0.24925162,83.9530193393022,1200.0,1.0
0.24985733,0.24988985,83.97225248302786,1200.0,1.0
0.25044822,0.25048074,83.98664088997651,1200.0,1.0
0.25103911,0.25107163,83.99484451166218,1200.0,1.0
0.25165824000000003,0.25169076,84.00239154320455,1200.0,1.0
0.25227737,0.25230989,84.01751880323427,1200.0,1.0
0.25292484000000004,0.25295736,84.0410448019553,1200.0,1.0
0.25357231,0.25360483,84.06736270257845,1200.0,1.0
0.25416195,0.25419447,84.09194735452307,1200.0,1.0
0.25475159,0.25478411,84.11448132051041,1200.0,1.0
0.255324655,0.255357175,84.13508444298516,1200.0,1.0
0.25589772,0.25593024,84.15231546818917,1200.0,1.0
0.25652679,0.25655931,84.16312142936462,1200.0,1.0
0.25715586,0.25718838,84.16788600683131,1200.0,1.0
0.257813435,0.25784595499999996,84.17519129887282,1200.0,1.0
0.25847101,0.25850353,84.19042507076405,1200.0,1.0
0.259067025,0.259099545,84.21039960497754,1200.0,1.0
0.25966304,0.25969556,84.23151533107469,1200.0,1.0
0.260284075,0.260316595,84.25302725431068,1200.0,1.0
0.26090511,0.26093763,84.27463057478411,1200.0,1.0
0.26155817000000003,0.26159069,84.295792246629,1200.0,1.0
0.26221123,0.26224375,84.31125096842453,1200.0,1.0
0.26280602500000005,0.26283854500000003,84.32183879291698,1200.0,1.0
0.26340082000000004,0.26343334,84.34210699961943,1200.0,1.0
0.264034625,0.264067145,84.37371532446176,1200.0,1.0
0.26466843,0.26470095,84.40553801102232,1200.0,1.0
0.265254165,0.26528668499999997,84.43141530406052,1200.0,1.0
0.2658399,0.26587242,84.44898433351628,1200.0,1.0
0.266492765,0.266525285,84.45962510066691,1200.0,1.0
0.26714563,0.26717815,84.46766863697987,1200.0,1.0
0.267774815,0.267807335,84.47114421328111,1200.0,1.0
0.26840400000000003,0.26843652,84.47346576677484,1200.0,1.0
0.26904449500000005,0.26907701500000003,84.48235397217556,1200.0,1.0
0.26968499,0.26971751,84.48921768045174,1200.0,1.0
0.27025967,0.27029219,84.49147956676566,1200.0,1.0
0.27083435,0.27086687,84.49734576910318,1200.0,1.0
0.27147289500000005,0.271505415,84.5071177573707,1200.0,1.0
0.27211144000000004,0.27214396,84.52029908116033,1200.0,1.0
0.272698055,0.272730575,84.54027678768095,1200.0,1.0
0.27328467,0.27331719,84.56749239874311,1200.0,1.0
0.273942375,0.273974895,84.59425233914217,1200.0,1.0
0.27460008,0.2746326,84.61030068849458,1200.0,1.0
0.27522339500000004,0.275255915,84.61422019859681,1200.0,1.0
0.27584671,0.27587923,84.61635992003085,1200.0,1.0
0.27646733,0.27649985,84.62284137965077,1200.0,1.0
0.27708795,0.27712047,84.6293528514941,1200.0,1.0
0.27770220500000004,0.277734725,84.63443481018908,1200.0,1.0
0.27831646000000004,0.27834898,84.6409608430589,1200.0,1.0
0.27890319500000005,0.27893571500000003,84.65372832957658,1200.0,1.0
0.27948993,0.27952245,84.67312237993539,1200.0,1.0
0.28016592,0.28019844,84.69075086184915,1200.0,1.0
0.28084191000000003,0.28087443,84.7032449089308,1200.0,1.0
0.28142302500000005,0.28145554500000003,84.71515461322099,1200.0,1.0
0.28200414,0.28203666,84.7267283459506,1200.0,1.0
0.282628605,0.28266112499999996,84.73565410323681,1200.0,1.0
0.28325307,0.28328559,84.74416894677407,1200.0,1.0
0.28386759500000003,0.283900115,84.75234520723531,1200.0,1.0
0.28448212,0.28451464,84.75874344690979,1200.0,1.0
0.28511519500000004,0.285147715,84.76849141703829,1200.0,1.0
0.28574827,0.28578079,84.78186941663749,1200.0,1.0
0.286378605,0.286411125,84.79437848638695,1200.0,1.0
0.28700894000000005,0.28704146,84.81086240138454,1200.0,1.0
0.287600795,0.287633315,84.82961348663747,1200.0,1.0
0.28819265,0.28822517,84.84220306110406,1200.0,1.0
0.288845935,0.288878455,84.84878918044754,1200.0,1.0
0.28949922,0.28953174,84.85134847728551,1200.0,1.0
0.29012477000000003,0.29015729,84.84690345910505,1200.0,1.0
0.29075032,0.29078284,84.83725860522561,1200.0,1.0
0.29136232500000003,0.291394845,84.82736356401463,1200.0,1.0
0.29197433,0.29200685,84.81752061365168,1200.0,1.0
0.29259425,0.29262677,84.8127865031215,1200.0,1.0
0.29321417,0.29324669,84.81162611284573,1200.0,1.0
0.29385283,0.29388535,84.81119582451333,1200.0,1.0
0.29449149,0.29452401,84.81807068527152,1200.0,1.0
0.29508059500000006,0.29511311500000004,84.83490615314909,1200.0,1.0
0.29566970000000004,0.29570222,84.85795792000319,1200.0,1.0
0.296288335,0.296320855,84.88142929409078,1200.0,1.0
0.29690697,0.29693949,84.8998390363062,1200.0,1.0
0.29756597500000004,0.297598495,84.91067623729786,1200.0,1.0
0.29822498000000003,0.2982575,84.91713771368131,1200.0,1.0
0.298819955,0.298852475,84.9209860186381,1200.0,1.0
0.29941493,0.29944745,84.92444073712345,1200.0,1.0
0.30007199500000004,0.300104515,84.92989677692526,1200.0,1.0
0.30072906,0.30076158,84.93540524610738,1200.0,1.0
0.301343555,0.30137607499999997,84.94057888358348,1200.0,1.0
0.30195805000000003,0.30199057,84.94485319811479,1200.0,1.0
0.30256247000000003,0.30259499,84.94706873148435,1200.0,1.0
0.30316689,0.30319941,84.94790302977515,1200.0,1.0
0.30380831,0.30384083,84.95018964430108,1200.0,1.0
0.30444973000000003,0.30448225,84.95505786453101,1200.0,1.0
0.305070155,0.305102675,84.96386002898328,1200.0,1.0
0.30569058000000005,0.3057231,84.97794847617618,1200.0,1.0