File: datasets/steel_spring/csv/BS2V-1150-10.0.csv
Time(s),Strain(%),Stress(MPa),Temp(C),SR(%/s)
0.0,1.904e-05,0.27109208999999984,1150.0,10.0
3.381250000000001e-08,1.9378125000000002e-05,0.28078699937500007,1150.0,10.0
6.762500000000002e-08,1.9716250000000003e-05,0.29048190875000013,1150.0,10.0
1.0143750000000004e-07,2.0054375e-05,0.3001768181250001,1150.0,10.0
1.3525000000000005e-07,2.03925e-05,0.3098717275,1150.0,10.0
1.6906250000000008e-07,2.0730625000000003e-05,0.3219903642187515,1150.0,10.0
2.0287500000000007e-07,2.106875e-05,0.3316852735937512,1150.0,10.0
2.3668750000000007e-07,2.1406875e-05,0.3413801829687511,1150.0,10.0
2.705000000000001e-07,2.1745000000000003e-05,0.3510750923437514,1150.0,10.0
3.043125000000001e-07,2.2083125e-05,0.36077000171875234,1150.0,10.0
3.3812500000000015e-07,2.242125e-05,0.37046491109375285,1150.0,10.0
3.719375000000002e-07,2.2759375000000003e-05,0.38015982046875274,1150.0,10.0
4.0575000000000015e-07,2.30975e-05,0.3923293913039797,1150.0,10.0
4.395625000000001e-07,2.3435625e-05,0.40410999096117656,1150.0,10.0
4.7337500000000015e-07,2.3773750000000003e-05,0.41201429163731296,1150.0,10.0
5.071875000000002e-07,2.4111875e-05,0.41362798946875196,1150.0,10.0
5.410000000000002e-07,2.445e-05,0.40760980453125134,1150.0,10.0
8.755625000000001e-07,2.7795625000000004e-05,0.3936914808399637,1150.0,10.0
1.210125e-06,3.114125e-05,0.3726777863494336,1150.0,10.0
1.5446874999999998e-06,3.4486875e-05,0.3464465129536001,1150.0,10.0
1.8792499999999996e-06,3.78325e-05,0.31794847648579666,1150.0,10.0
2.2138124999999995e-06,4.1178125000000006e-05,0.29120751671875106,1150.0,10.0
2.5483749999999996e-06,4.4523750000000005e-05,0.26549263609375096,1150.0,10.0
2.882937499999999e-06,4.7869375000000004e-05,0.23977775546875083,1150.0,10.0
3.2174999999999993e-06,5.1215000000000003e-05,0.21406287484375078,1150.0,10.0
3.5520624999999993e-06,5.4560625e-05,0.1883479942187507,1150.0,10.0
3.886624999999999e-06,5.790625e-05,0.16263311359375077,1150.0,10.0
4.2211874999999995e-06,6.1251875e-05,0.13691823296875089,1150.0,10.0
4.5557499999999995e-06,6.45975e-05,0.0891142306647736,1150.0,10.0
4.8903125e-06,6.7943125e-05,0.04478223122632634,1150.0,10.0
5.224875e-06,7.128875e-05,0.03505053620643999,1150.0,10.0
5.559437499999999e-06,7.4634375e-05,0.08146950821875137,1150.0,10.0
5.893999999999999e-06,7.798e-05,0.19601157093750257,1150.0,10.0
6.228624999999998e-06,8.132625e-05,0.3810712090975412,1150.0,10.0
6.5632499999999985e-06,8.46725e-05,0.6294649684943222,1150.0,10.0
6.897874999999999e-06,8.801875e-05,0.9244314559839063,1150.0,10.0
7.232499999999999e-06,9.136499999999999e-05,1.2396313394829612,1150.0,10.0
7.567124999999999e-06,9.471124999999999e-05,1.5391473479687563,1150.0,10.0
7.90175e-06,9.80575e-05,1.8295044523437558,1150.0,10.0
8.236375e-06,0.00010140375,2.119861556718757,1150.0,10.0
8.570999999999998e-06,0.00010475,2.410218661093759,1150.0,10.0
8.905624999999997e-06,0.00010809625,2.700575765468762,1150.0,10.0
9.240249999999997e-06,0.00011144249999999999,2.9909328698437636,1150.0,10.0
9.574874999999997e-06,0.00011478874999999998,3.2812899742187636,1150.0,10.0
9.909499999999997e-06,0.00011813499999999999,3.4518689080966034,1150.0,10.0
1.0244124999999997e-05,0.00012148125,3.641274763082397,1150.0,10.0
1.0578749999999998e-05,0.0001248275,4.018300624971602,1150.0,10.0
1.0913374999999998e-05,0.00012817375,4.699803245468763,1150.0,10.0
1.1247999999999998e-05,0.00013152,5.750703042187516,1150.0,10.0
3.781725e-05,0.00039721250000000004,7.183984098650589,1150.0,10.0
6.43865e-05,0.0006629050000000001,8.960694164289801,1150.0,10.0
9.095575e-05,0.0009285975000000001,10.989944654446061,1150.0,10.0
0.00011752500000000001,0.0011942900000000002,13.128910650369363,1150.0,10.0
0.00014409425000000002,0.0014599825000000002,15.182830899218803,1150.0,10.0
0.00017066350000000002,0.0017256750000000003,17.18708702859382,1150.0,10.0
0.00019723275000000002,0.0019913675000000006,19.191343157968834,1150.0,10.0
0.00022380200000000002,0.0022570600000000004,21.195599287343843,1150.0,10.0
0.00025037125,0.0025227525000000002,23.199855416718844,1150.0,10.0
0.00027694050000000005,0.0027884450000000005,25.20411154609386,1150.0,10.0
0.00030350975,0.0030541375000000003,27.208367675468864,1150.0,10.0
0.00033007900000000005,0.00331983,29.24524478313399,1150.0,10.0
0.0003566482500000001,0.0035855225000000004,31.276994474157316,1150.0,10.0
0.00038321750000000005,0.0038512150000000003,33.25764680623297,1150.0,10.0
0.00040978675,0.0041169075,35.15537643468764,1150.0,10.0
0.00043635600000000005,0.0043826,36.95250261248063,1150.0,10.0
0.0005020878125,0.005039918125000001,38.645489190203755,1150.0,10.0
0.0005678196250000001,0.00569723625,40.24494461608147,1150.0,10.0
0.0006335514375000001,0.006354554375,41.77562193597081,1150.0,10.0
0.0006992832500000001,0.0070118725,43.27641879336132,1150.0,10.0
0.0007650150625,0.007669190625,44.800377429375146,1150.0,10.0
0.000830746875,0.00832650875,46.33786183687514,1150.0,10.0
0.0008964786875000001,0.008983826875,47.87534624437515,1150.0,10.0
0.0009622105000000001,0.009641145,49.41283065187516,1150.0,10.0
0.0010279423125,0.010298463125,50.9503150593752,1150.0,10.0
0.0010936741250000001,0.010955781250000001,52.48779946687524,1150.0,10.0
0.0011594059375,0.011613099375000002,54.02528387437525,1150.0,10.0
0.00122513775,0.0122704175,55.59974165373392,1150.0,10.0
0.0012908695625000002,0.012927735624999999,57.168387900388524,1150.0,10.0
0.001356601375,0.01358505375,58.67911921768185,1150.0,10.0
0.0014223331875,0.014242371875,60.09586402331274,1150.0,10.0
0.001488065,0.01489969,61.39858254933619,1150.0,10.0
0.00156621525,0.0156811925,62.5832668421631,1150.0,10.0
0.0016443654999999998,0.016462695,63.66194076256055,1150.0,10.0
0.0017225157499999998,0.0172441975,64.66265998565173,1150.0,10.0
0.0018006659999999998,0.0180257,65.62951200091574,1150.0,10.0
0.0018788162499999998,0.0188072025,66.62261611218774,1150.0,10.0
0.0019569665,0.019588704999999998,67.63105064593779,1150.0,10.0
0.0020351167499999996,0.0203702075,68.63948517968782,1150.0,10.0
0.002113267,0.02115171,69.64791971343786,1150.0,10.0
0.00219141725,0.0219332125,70.65635424718786,1150.0,10.0
0.0022695675,0.022714715000000003,71.66478878093783,1150.0,10.0
0.0023477177499999996,0.023496217500000003,72.67322331468779,1150.0,10.0
0.002425868,0.024277720000000003,73.7047847758028,1150.0,10.0
0.00250401825,0.025059222500000002,74.73271111012338,1150.0,10.0
0.0025821685,0.025840725000000002,75.72441152569868,1150.0,10.0
0.0026603187499999997,0.0266222275,76.65732316656286,1150.0,10.0
0.002738469,0.02740373,77.51891111273478,1150.0,10.0
0.0028171901249999997,0.02819094125,78.30666838021824,1150.0,10.0
0.00289591125,0.0289781525,79.02811592100194,1150.0,10.0
0.002974632375,0.02976536375,79.70080262305922,1150.0,10.0
0.0030533534999999997,0.030552575,80.35230531034848,1150.0,10.0
0.003132074625,0.03133978625,81.02022874281292,1150.0,10.0
0.00321079575,0.0321269975,81.6977413890629,1150.0,10.0
0.0032895168749999997,0.03291420874999999,82.37525403531289,1150.0,10.0
0.003368238,0.033701419999999996,83.0527666815629,1150.0,10.0
0.0034469591250000002,0.03448863125,83.7302793278129,1150.0,10.0
0.00352568025,0.035275842499999994,84.40779197406285,1150.0,10.0
0.003604401375,0.03606305374999999,85.08530462031283,1150.0,10.0
0.0036831225,0.03685026499999999,85.7766897207518,1150.0,10.0
0.0037618436250000005,0.037637476249999996,86.46589432703637,1150.0,10.0
0.0038405647500000003,0.0384246875,87.13336918123093,1150.0,10.0
0.003919285875,0.03921189875,87.76558018168785,1150.0,10.0
0.0039980070000000005,0.03999911,88.35500838304718,1150.0,10.0
0.004075687125,0.04077591124999999,88.90014999623698,1150.0,10.0
0.00415336725,0.04155271249999999,89.40551638847317,1150.0,10.0
0.004231047375,0.04232951374999999,89.8816340832597,1150.0,10.0
0.0043087275,0.04310631499999999,90.34504476038805,1150.0,10.0
0.004386407625,0.04388311624999999,90.81830525593784,1150.0,10.0
0.00446408775,0.04465991749999999,91.29731774468796,1150.0,10.0
0.004541767875,0.045436718749999994,91.77633023343815,1150.0,10.0
0.004619448,0.046213519999999994,92.25534272218822,1150.0,10.0
0.004697128125,0.046990321249999994,92.73435521093829,1150.0,10.0
0.00477480825,0.047767122499999995,93.21336769968832,1150.0,10.0
0.004852488375,0.048543923749999995,93.69238018843828,1150.0,10.0
0.0049301685,0.049320724999999996,94.1781415710021,1150.0,10.0
0.005007848625,0.050097526249999996,94.66284215182822,1150.0,10.0
0.00508552875,0.0508743275,95.13697129464768,1150.0,10.0
0.005163208875,0.05165112875,95.59394471281294,1150.0,10.0
0.005240889,0.05242793,96.03010446929736,1150.0,10.0
0.00531640375,0.053183077499999995,96.44471897669553,1150.0,10.0
0.0053919185000000005,0.053938225,96.83998299722347,1150.0,10.0
0.005467433250000001,0.054693372500000004,97.22101764271845,1150.0,10.0
0.005542948000000001,0.05544852,97.59587037463851,1150.0,10.0
0.005618462750000001,0.0562036675,97.97551500406321,1150.0,10.0
0.005693977500000001,0.056958814999999996,98.3579579553132,1150.0,10.0
0.005769492250000001,0.05771396249999999,98.74040090656317,1150.0,10.0
0.005845007,0.05846911,99.12284385781302,1150.0,10.0
0.005920521749999999,0.0592242575,99.50528680906271,1150.0,10.0
0.0059960364999999995,0.059979405,99.88772976031228,1150.0,10.0
0.0060715512499999996,0.0607345525,100.27017271156208,1150.0,10.0
0.006147066,0.061489699999999994,100.65836782341796,1150.0,10.0
0.00622258075,0.0622448475,101.04565880162862,1150.0,10.0
0.0062980955,0.062999995,101.4239396204079,1150.0,10.0
0.00637361025,0.0637551425,101.7875984157502,1150.0,10.0
0.006449125,0.06451029,102.13351748543009,1150.0,10.0
0.0065306249375,0.065325289375,102.46107328900237,1150.0,10.0
0.006612124875,0.06614028875,102.77213644780225,1150.0,10.0
0.0066936248125,0.066955288125,103.07107174494544,1150.0,10.0
0.00677512475,0.0677702875,103.36473812532782,1150.0,10.0
0.0068566246875,0.068585286875,103.66248869562541,1150.0,10.0
0.006938124625,0.06940028625,103.96262430812534,1150.0,10.0
0.0070196245625,0.070215285625,104.2627599206254,1150.0,10.0
0.0071011245,0.071030285,104.56289553312544,1150.0,10.0
0.0071826244375,0.071845284375,104.8630311456254,1150.0,10.0
0.007264124375,0.07266028375,105.16316675812531,1150.0,10.0
0.0073456243125,0.073475283125,105.46330237062553,1150.0,10.0
0.00742712425,0.0742902825,105.76658604062698,1150.0,10.0
0.0075086241875,0.075105281875,106.06937489400212,1150.0,10.0
0.007590124125,0.07592028125,106.36723264375745,1150.0,10.0
0.0076716240625,0.076735280625,106.65708801428215,1150.0,10.0
0.007753124,0.07755028,106.9372347413484,1150.0,10.0
0.007829619749999999,0.0783152375,107.20733157211039,1150.0,10.0
0.0079061155,0.07908019499999999,107.46840226510488,1150.0,10.0
0.00798261125,0.07984515249999999,107.7228355902516,1150.0,10.0
0.008059107,0.08061011,107.9743853288528,1150.0,10.0
0.008135602749999998,0.08137506750000001,108.228170273593,1150.0,10.0
0.008212098499999999,0.082140025,108.48326051046803,1150.0,10.0
0.00828859425,0.0829049825,108.73835074734339,1150.0,10.0
0.008365089999999999,0.08366994,108.99344098421884,1150.0,10.0
0.008441585749999998,0.0844348975,109.2485312210941,1150.0,10.0
0.008518081499999998,0.08519985499999999,109.50362145796939,1150.0,10.0
0.008594577249999999,0.08596481249999999,109.75871169484473,1150.0,10.0
0.008671072999999998,0.08672977,110.0165425982826,1150.0,10.0
0.008747568749999999,0.08749472750000001,110.27394271944222,1150.0,10.0
0.0088240645,0.088259685,110.52704987238123,1150.0,10.0
0.008900560249999998,0.0890246425,110.77319023606324,1150.0,10.0
0.008977055999999999,0.0897896,111.0108783543565,1150.0,10.0
0.009056762187499998,0.090586661875,111.23981713603436,1150.0,10.0
0.009136468374999998,0.09138372375,111.46089785477581,1150.0,10.0
0.009216174562499999,0.09218078562500001,111.67620014916498,1150.0,10.0
0.009295880749999999,0.0929778475,111.88899202269175,1150.0,10.0
0.0093755869375,0.09377490937499999,112.10372984375078,1150.0,10.0
0.009455293125,0.09457197125,112.31960403875055,1150.0,10.0
0.0095349993125,0.095369033125,112.53547823375048,1150.0,10.0
0.0096147055,0.09616609500000001,112.75135242875042,1150.0,10.0
0.009694411687499998,0.09696315687500001,112.96722662375035,1150.0,10.0
0.009774117874999998,0.09776021875,113.18310081875023,1150.0,10.0
0.009853824062499999,0.098557280625,113.39897501375017,1150.0,10.0
0.00993353025,0.0993543425,113.61759843966843,1150.0,10.0
0.0100132364375,0.100151404375,113.83578973714958,1150.0,10.0
0.010092942625,0.10094846625000001,114.04967465124106,1150.0,10.0
0.0101726488125,0.10174552812500001,114.25657100543752,1150.0,10.0
0.010252355,0.10254259,114.45498870168001,1150.0,10.0
0.01033613375,0.10338037750000001,114.6446297203567,1150.0,10.0
0.0104199125,0.104218165,114.82638812030264,1150.0,10.0
0.010503691249999999,0.10505595250000001,115.00235003880003,1150.0,10.0
0.010587469999999998,0.10589374000000001,115.17579369157822,1150.0,10.0
0.010671248749999997,0.1067315275,115.35118937281305,1150.0,10.0
0.010755027499999998,0.10756931500000001,115.52772497906304,1150.0,10.0
0.01083880625,0.10840710250000002,115.70426058531298,1150.0,10.0
0.010922584999999999,0.10924489000000001,115.88079619156296,1150.0,10.0
0.011006363749999998,0.1100826775,116.05733179781319,1150.0,10.0
0.011090142499999999,0.11092046500000001,116.23386740406339,1150.0,10.0
0.01117392125,0.11175825250000002,116.41040301031335,1150.0,10.0
0.011257699999999999,0.11259604000000001,116.58812573219389,1150.0,10.0
0.011341478749999998,0.1134338275,116.7656618613737,1150.0,10.0
0.0114252575,0.114271615,116.94133849777684,1150.0,10.0
0.01150903625,0.11510940250000001,117.11399747981274,1150.0,10.0
0.011592815,0.11594719,117.28299538437518,1150.0,10.0
0.0116752934375,0.116771974375,117.4482035268429,1150.0,10.0
0.011757771875,0.11759675875,117.61000796107996,1150.0,10.0
0.0118402503125,0.118421543125,117.76930947943447,1150.0,10.0
0.01192272875,0.1192463275,117.92752361273952,1150.0,10.0
0.0120052071875,0.120071111875,118.08658063031329,1150.0,10.0
0.012087685625,0.12089589625,118.24612986656321,1150.0,10.0
0.0121701640625,0.121720680625,118.40567910281302,1150.0,10.0
0.0122526425,0.122545465,118.56522833906295,1150.0,10.0
0.012335120937500001,0.12337024937500002,118.72477757531269,1150.0,10.0
0.012417599375000001,0.12419503375000002,118.88432681156252,1150.0,10.0
0.012500077812500001,0.12501981812500002,119.04387604781246,1150.0,10.0
0.012582556250000002,0.1258446025,119.20468181445484,1150.0,10.0
0.012665034687500002,0.126669386875,119.3652900776751,1150.0,10.0
0.012747513125000002,0.12749417125,119.52393011713714,1150.0,10.0
0.0128299915625,0.128318955625,119.6793760495312,1150.0,10.0
0.01291247,0.12914374,119.83094682857403,1150.0,10.0
0.012997674375,0.12999578375,119.97850624500977,1150.0,10.0
0.01308287875,0.1308478275,120.12246292660743,1150.0,10.0
0.013168083125,0.13169987125000002,120.26377033816367,1150.0,10.0
0.0132532875,0.13255191500000002,120.40392678150162,1150.0,10.0
0.013338491875,0.13340395875000002,120.54497539547,1150.0,10.0
0.01342369625,0.13425600250000003,120.68654500984458,1150.0,10.0
0.013508900625,0.13510804625,120.82811462421913,1150.0,10.0
0.013594105,0.13596009,120.96968423859393,1150.0,10.0
0.013679309375,0.13681213375,121.1112538529688,1150.0,10.0
0.01376451375,0.13766417749999998,121.25282346734424,1150.0,10.0
0.013849718125,0.13851622125,121.39439308171954,1150.0,10.0
0.0139349225,0.139368265,121.5378073357431,1150.0,10.0
0.014020126875,0.14022030875,121.68093164640733,1150.0,10.0
0.01410533125,0.1410723525,121.82116652152408,1150.0,10.0
0.014190535625,0.14192439625,121.95671231265626,1150.0,10.0
0.01427574,0.14277644,122.08656921511692,1150.0,10.0
0.014358285875000001,0.14360189875,122.21053726796829,1150.0,10.0
0.01444083175,0.14442735750000002,122.3292163540231,1150.0,10.0
0.014523377625,0.14525281625000003,122.44400619984391,1150.0,10.0
0.0146059235,0.146078275,122.5571063757427,1150.0,10.0
0.014688469374999999,0.14690373375,122.67151629578193,1150.0,10.0
0.01477101525,0.1477291925,122.78669106640723,1150.0,10.0
0.014853561125000001,0.14855465125,122.90186583703233,1150.0,10.0
0.014936107,0.14938011,123.0170406076578,1150.0,10.0
0.015018652875,0.15020556875000002,123.13221537828264,1150.0,10.0
0.01510119875,0.1510310275,123.24739014890689,1150.0,10.0
0.015183744624999999,0.15185648624999998,123.36256491953168,1150.0,10.0
0.0152662905,0.15268194499999999,123.47948642272274,1150.0,10.0
0.015348836375000001,0.15350740375,123.59613337174368,1150.0,10.0
0.01543138225,0.1543328625,123.71004424644728,1150.0,10.0
0.015513928125,0.15515832125,123.81951491750146,1150.0,10.0
0.015596473999999999,0.15598378,123.92359864638829,1150.0,10.0
0.0156811955625,0.15683099562499997,124.02210608540395,1150.0,10.0
0.015765917125,0.15767821124999998,124.11560527765968,1150.0,10.0
0.0158506386875,0.158525426875,124.20542165707978,1150.0,10.0
0.01593536025,0.1593726425,124.29363804840496,1150.0,10.0
0.016020081812499996,0.160219858125,124.38309466718884,1150.0,10.0
0.016104803374999997,0.16106707375,124.47327554093913,1150.0,10.0
0.016189524937499998,0.16191428937500002,124.56345641468943,1150.0,10.0
0.0162742465,0.162761505,124.6536372884392,1150.0,10.0
0.0163589680625,0.16360872062499998,124.74381816218887,1150.0,10.0
0.016443689625,0.16445593625,124.8339990359387,1150.0,10.0
0.0165284111875,0.165303151875,124.92417990968922,1150.0,10.0
0.016613132750000002,0.1661503675,125.01577593801274,1150.0,10.0
0.016697854312500003,0.16699758312500002,125.1071495301156,1150.0,10.0
0.016782575875000004,0.16784479875000002,125.19630643023113,1150.0,10.0
0.016867297437500005,0.16869201437500003,125.28186599975155,1150.0,10.0
0.016952019000000002,0.16953923,125.36306121722822,1150.0,10.0
0.017033001562500004,0.17034905562500002,125.43973867837036,1150.0,10.0
0.017113984125000002,0.17115888125,125.51235859604762,1150.0,10.0
0.0171949666875,0.17196870687500002,125.5819948002892,1150.0,10.0
0.017275949250000002,0.17277853250000003,125.65033473828287,1150.0,10.0
0.017356931812500004,0.173588358125,125.71967947437464,1150.0,10.0
0.017437914375000002,0.17439818375000002,125.78961098187489,1150.0,10.0
0.0175188969375,0.17520800937500003,125.85954248937543,1150.0,10.0
0.017599879500000002,0.176017835,125.92947399687615,1150.0,10.0
0.017680862062500004,0.176827660625,125.99940550437645,1150.0,10.0
0.017761844625000002,0.17763748625,126.06933701187636,1150.0,10.0
0.0178428271875,0.17844731187500001,126.13926851937615,1150.0,10.0
0.017923809750000002,0.1792571375,126.20961818166816,1150.0,10.0
0.018004792312500004,0.180066963125,126.2799021177328,1150.0,10.0
0.018085774875000002,0.18087678875000002,126.3495310579438,1150.0,10.0
0.0181667574375,0.181686614375,126.41809704640642,1150.0,10.0
0.018247740000000002,0.18249644,126.48537344095743,1150.0,10.0
0.018326815750000003,0.1832871975,126.5513149131633,1150.0,10.0
0.0184058915,0.18407795500000002,126.61605744832217,1150.0,10.0
0.01848496725,0.1848687125,126.67991834546376,1150.0,10.0
0.018564043000000002,0.18565947,126.74339621734948,1150.0,10.0
0.01864311875,0.1864502275,126.80717099047006,1150.0,10.0
0.0187221945,0.187240985,126.87111914484538,1150.0,10.0
0.018801270250000002,0.1880317425,126.93506729922031,1150.0,10.0
0.018880346,0.1888225,126.99901545359526,1150.0,10.0
0.01895942175,0.18961325750000002,127.06296360796999,1150.0,10.0
0.0190384975,0.190404015,127.12691176234476,1150.0,10.0
0.01911757325,0.1911947725,127.19085991671936,1150.0,10.0
0.019196649,0.19198553000000002,127.25491280974364,1150.0,10.0
0.01927572475,0.1927762875,127.31894923978294,1150.0,10.0
0.019354800499999998,0.193567045,127.38282160765647,1150.0,10.0
0.01943387625,0.1943578025,127.44642772931468,1150.0,10.0
0.019512952,0.19514856,127.50971083584187,1150.0,10.0
0.0195918455,0.19593749500000002,127.57265957345528,1150.0,10.0
0.019670739,0.19672643,127.63530800350452,1150.0,10.0
0.0197496325,0.197515365,127.69773560247162,1150.0,10.0
0.019828526,0.1983043,127.76006726197161,1150.0,10.0
0.0199074195,0.19909323499999998,127.82247328875076,1150.0,10.0
0.019986313,0.19988217,127.88492274375086,1150.0,10.0
0.0200652065,0.20067110500000002,127.94737219875094,1150.0,10.0
0.020144099999999998,0.20146004,128.00982165375066,1150.0,10.0
0.020222993499999998,0.202248975,128.07227110875013,1150.0,10.0
0.020301886999999998,0.20303791,128.13472056374914,1150.0,10.0
0.020380780499999997,0.20382684499999998,128.1971700187486,1150.0,10.0
0.020459673999999997,0.20461578,128.2606625279009,1150.0,10.0
0.020538567499999997,0.20540471500000002,128.3239910881624,1150.0,10.0
0.020617460999999997,0.20619365,128.38568581292327,1150.0,10.0
0.0206963545,0.206982585,128.44472908837602,1150.0,10.0
0.020775248,0.20777152,128.50055557351703,1150.0,10.0
0.0208554840625,0.20857388062499999,128.5530522001457,1150.0,10.0
0.020935720125,0.20937624124999998,128.60255817286355,1150.0,10.0
0.0210159561875,0.21017860187499998,128.64986496907625,1150.0,10.0
0.02109619225,0.21098096249999998,128.69621633899308,1150.0,10.0
0.0211764283125,0.21178332312499998,128.74330830562494,1150.0,10.0
0.021256664374999998,0.21258568374999998,128.79083275812408,1150.0,10.0
0.0213369004375,0.21338804437499997,128.83835721062377,1150.0,10.0
0.0214171365,0.214190405,128.88588166312366,1150.0,10.0
0.0214973725625,0.21499276562500003,128.93340611562334,1150.0,10.0
0.021577608625,0.21579512625000002,128.98093056812402,1150.0,10.0
0.0216578446875,0.21659748687500002,129.0284550206248,1150.0,10.0
0.02173808075,0.21739984750000002,129.07624853448957,1150.0,10.0
0.0218183168125,0.21820220812500002,129.12399975686694,1150.0,10.0
0.021898552874999998,0.21900456875000002,129.17132952268895,1150.0,10.0
0.0219787889375,0.21980692937500002,129.2179753330638,1150.0,10.0
0.022059025,0.22060929,129.26379135527478,1150.0,10.0
0.022136627562499997,0.22138531562500002,129.30874842277794,1150.0,10.0
0.022214230124999998,0.22216134125,129.3529340352038,1150.0,10.0
0.0222918326875,0.222937366875,129.39655235835784,1150.0,10.0
0.02236943525,0.2237133925,129.4399242242184,1150.0,10.0
0.0224470378125,0.224489418125,129.4834871309389,1150.0,10.0
0.022524640375000002,0.22526544375000002,129.5271615996886,1150.0,10.0
0.022602242937500003,0.22604146937500003,129.57083606843827,1150.0,10.0
0.0226798455,0.226817495,129.6145105371876,1150.0,10.0
0.022757448062499998,0.227593520625,129.65818500593755,1150.0,10.0
0.022835050625,0.22836954625,129.70185947468747,1150.0,10.0
0.0229126531875,0.229145571875,129.74553394343747,1150.0,10.0
0.02299025575,0.22992159750000002,129.78947774008097,1150.0,10.0
0.0230678583125,0.23069762312500003,129.83337920334253,1150.0,10.0
0.023145460875000003,0.23147364875,129.87685879255983,1150.0,10.0
0.023223063437500004,0.232249674375,129.91965374881244,1150.0,10.0
0.023300666,0.2330257,129.96161809492216,1150.0,10.0
0.0233783455625,0.233802495625,130.00272263545307,1150.0,10.0
0.023456025125000002,0.23457929125,130.04305495671173,1150.0,10.0
0.0235337046875,0.23535608687499998,130.08281942674796,1150.0,10.0
0.02361138425,0.2361328825,130.1223371953532,1150.0,10.0
0.0236890638125,0.23690967812500002,130.1620461940615,1150.0,10.0
0.023766743375,0.23768647375000002,130.20186686531207,1150.0,10.0
0.0238444229375,0.238463269375,130.24168753656295,1150.0,10.0
0.0239221025,0.239240065,130.2815082078136,1150.0,10.0
0.023999782062500002,0.240016860625,130.32132887906377,1150.0,10.0
0.024077461625,0.24079365625,130.36114955031366,1150.0,10.0
0.0241551411875,0.24157045187499998,130.4009702215637,1150.0,10.0
0.024232820750000002,0.2423472475,130.4411298688021,1150.0,10.0
0.0243105003125,0.24312404312500002,130.48123623526118,1150.0,10.0
0.024388179875,0.24390083875000002,130.52081163120175,1150.0,10.0
0.0244658594375,0.244677634375,130.55952534834356,1150.0,10.0
0.024543539,0.24545443,130.5971936598638,1150.0,10.0
0.024621589625000002,0.24623493625,130.63377982039722,1150.0,10.0
0.024699640250000002,0.24701544250000002,130.66939406603743,1150.0,10.0
0.024777690875,0.24779594875,130.7042936143362,1150.0,10.0
0.0248557415,0.248576455,130.73888266430467,1150.0,10.0
0.024933792125,0.24935696125,130.77371239641096,1150.0,10.0
0.02501184275,0.2501374675,130.80868267953568,1150.0,10.0
0.025089893375,0.25091797375,130.84365296265983,1150.0,10.0
0.025167943999999998,0.25169848,130.87862324578404,1150.0,10.0
0.025245994624999997,0.25247898625,130.91359352890873,1150.0,10.0
0.025324045249999996,0.2532594925,130.94856381203405,1150.0,10.0
0.025402095874999996,0.25403999875,130.98353409515877,1150.0,10.0
0.0254801465,0.254820505,131.0185579639149,1150.0,10.0
0.025558197125,0.25560101125,131.05357340999726,1150.0,10.0
0.02563624775,0.2563815175,131.0885049197778,1150.0,10.0
0.025714298375,0.25716202374999997,131.12330021459312,1150.0,10.0
0.025792349,0.25794253,131.15793025074132,1150.0,10.0
0.025869368812499998,0.258712728125,131.19238921948076,1150.0,10.0
0.025946388624999997,0.25948292625,131.22669454703376,1150.0,10.0
0.0260234084375,0.26025312437500003,131.2608868945849,1150.0,10.0
0.02610042825,0.2610233225,131.29503015827814,1150.0,10.0
0.026177448062499997,0.26179352062499994,131.3292114692205,1150.0,10.0
0.026254467875,0.26256371874999995,131.36341499859563,1150.0,10.0
0.0263314876875,0.26333391687499996,131.39761852796997,1150.0,10.0
0.026408507499999997,0.264104115,131.43182205734433,1150.0,10.0
0.0264855273125,0.264874313125,131.46602558671898,1150.0,10.0
0.026562547125,0.26564451125,131.5002291160938,1150.0,10.0
0.026639566937499998,0.266414709375,131.53443264546863,1150.0,10.0
0.02671658675,0.2671849075,131.56959845062434,1150.0,10.0
0.0267936065625,0.267955105625,131.60461300375997,1150.0,10.0
0.026870626374999998,0.26872530375000003,131.63812025228438,1150.0,10.0
0.0269476461875,0.26949550187500004,131.66918139056057,1150.0,10.0
0.027024666,0.2702657,131.6972748598997,1150.0,10.0
0.027102114375,0.27104018375,131.72229634856396,1150.0,10.0
0.027179562749999997,0.2718146675,131.74455879176682,1150.0,10.0
0.027257011124999998,0.27258915125,131.7647923716725,1150.0,10.0
0.027334459499999998,0.273363635,131.7841445173949,1150.0,10.0
0.027411907875,0.27413811875,131.80417990499913,1150.0,10.0
0.02748935625,0.2749126025,131.82461428500062,1150.0,10.0
0.027566804625,0.27568708625,131.84504866500245,1150.0,10.0
0.027644253,0.27646157,131.86548304500351,1150.0,10.0
0.027721701375,0.27723605375,131.88591742500256,1150.0,10.0
0.027799149750000002,0.2780105375,131.90635180500124,1150.0,10.0
0.027876598125,0.27878502125,131.92678618500076,1150.0,10.0
0.0279540465,0.279559505,131.94749629125172,1150.0,10.0
0.028031494875,0.28033398875,131.96816305841682,1150.0,10.0
0.028108943249999997,0.2811084725,131.9883979291769,1150.0,10.0
0.028186391624999998,0.28188295625,132.0079319023106,1150.0,10.0
0.02826384,0.28265744,132.02661553269368,1150.0,10.0
0.028340865812499998,0.283427698125,132.04441893130132,1150.0,10.0
0.028417891624999997,0.28419795625,132.06143176520686,1150.0,10.0
0.028494917437499996,0.284968214375,132.07786325758548,1150.0,10.0
0.02857194325,0.28573847249999995,132.09404218770587,1150.0,10.0
0.0286489690625,0.28650873062499993,132.1104168909367,1150.0,10.0
0.028725994875,0.28727898874999996,132.1269059196865,1150.0,10.0
0.0288030206875,0.288049246875,132.14339494843725,1150.0,10.0
0.0288800465,0.288819505,132.15988397718795,1150.0,10.0
0.0289570723125,0.28958976312499995,132.17637300593785,1150.0,10.0
0.029034098125,0.29036002125,132.19286203468755,1150.0,10.0
0.029111123937500004,0.291130279375,132.20935106343842,1150.0,10.0
0.029188149750000003,0.2919005375,132.22581989756566,1150.0,10.0
0.029265175562500002,0.292670795625,132.24229190591495,1150.0,10.0
0.029342201375,0.29344105375,132.25879554703633,1150.0,10.0
0.0294192271875,0.29421131187500005,132.275350523005,1150.0,10.0
0.029496253000000004,0.29498157,132.29196777941812,1150.0,10.0
0.029571054750000006,0.2957295875,132.3086495053949,1150.0,10.0
0.029645856500000005,0.29647760500000003,132.32538913357644,1150.0,10.0
0.029720658250000004,0.29722562250000006,132.34217134012786,1150.0,10.0
0.029795460000000003,0.29797364000000004,132.3589720447389,1150.0,10.0
0.02987026175,0.2987216575,132.3757584106217,1150.0,10.0
0.0299450635,0.29946967500000005,132.39253640312367,1150.0,10.0
0.03001986525,0.3002176925000001,132.40931439562362,1150.0,10.0
0.030094667000000002,0.30096571000000005,132.42609238812355,1150.0,10.0
0.030169468750000004,0.30171372750000003,132.44287038062438,1150.0,10.0
0.030244270500000003,0.30246174500000006,132.45964837312556,1150.0,10.0
0.030319072250000002,0.3032097625000001,132.4764263656252,1150.0,10.0
0.030393874,0.30395778000000007,132.4932726732238,1150.0,10.0
0.03046867575,0.30470579750000004,132.51010824294795,1150.0,10.0
0.0305434775,0.305453815,132.52683680419736,1150.0,10.0
0.030618279249999998,0.3062018325,132.5433917080933,1150.0,10.0
0.030693081,0.30694985,132.55973592748032,1150.0,10.0
0.030770216500000003,0.307721205,132.57586205692817,1150.0,10.0
0.030847352,0.30849256,132.59179231273032,1150.0,10.0
0.0309244875,0.309263915,132.6075785329017,1150.0,10.0
0.031001623,0.31003527,132.62330217718136,1150.0,10.0
0.031078758499999998,0.310806625,132.6390743270325,1150.0,10.0
0.031155894,0.31157798,132.65487480265685,1150.0,10.0
0.031233029500000002,0.31234933499999995,132.67067527828135,1150.0,10.0
0.031310165,0.31312069,132.6864757539067,1150.0,10.0
0.0313873005,0.313892045,132.7022762295321,1150.0,10.0
0.031464436,0.3146634,132.7180767051571,1150.0,10.0
0.031541571500000004,0.31543475499999996,132.73387718078214,1150.0,10.0
0.031618707,0.31620611,132.74999323859018,1150.0,10.0
0.0316958425,0.316977465,132.76605969269528,1150.0,10.0
0.03177297800000001,0.31774882,132.78163182023627,1150.0,10.0
0.031850113500000006,0.31852017499999996,132.7964017361571,1150.0,10.0
0.031927249000000005,0.31929153,132.81019839320342,1150.0,10.0
0.032003809312500006,0.320057133125,132.8229875819246,1150.0,10.0
0.03208036962500001,0.32082273625,132.8348719306722,1150.0,10.0
0.03215692993750001,0.321588339375,132.84609090560227,1150.0,10.0
0.03223349025,0.3223539425,132.85702081067404,1150.0,10.0
0.0323100505625,0.323119545625,132.8681747876499,1150.0,10.0
0.032386610875,0.32388514874999996,132.87945961577702,1150.0,10.0
0.0324631711875,0.324650751875,132.89074444390494,1150.0,10.0
0.0325397315,0.325416355,132.90202927203194,1150.0,10.0
0.0326162918125,0.326181958125,132.91331410015877,1150.0,10.0
0.032692852125000005,0.32694756125,132.92459892828512,1150.0,10.0
0.032769412437500006,0.327713164375,132.93588375640982,1150.0,10.0
0.03284597275,0.3284787675,132.94717265008512,1150.0,10.0
0.032922533062499995,0.329244370625,132.95846090473123,1150.0,10.0
0.032999093374999997,0.33000997374999996,132.96974279111453,1150.0,10.0
0.0330756536875,0.330775576875,132.9810143428427,1150.0,10.0
0.033152214,0.33154118,132.99227335636553,1150.0,10.0
0.033231376625,0.33233280625,133.0035193909728,1150.0,10.0
0.03331053925,0.3331244325,133.0147537687947,1150.0,10.0
0.033389701875,0.33391605874999997,133.02597957480333,1150.0,10.0
0.0334688645,0.334707685,133.03720165680895,1150.0,10.0
0.033548027125000005,0.33549931125,133.04842662546676,1150.0,10.0
0.03362718975,0.33629093749999994,133.0596532798434,1150.0,10.0
0.033706352375,0.33708256374999995,133.07087993422005,1150.0,10.0
0.033785515,0.33787418999999996,133.0821065885954,1150.0,10.0
0.033864677625000006,0.33866581625,133.09333324297043,1150.0,10.0
0.03394384025,0.3394574425,133.10455989734672,1150.0,10.0
0.034023002875,0.34024906875,133.11578655172283,1150.0,10.0
0.0341021655,0.341040695,133.12741716469787,1150.0,10.0
0.03418132812500001,0.34183232125,133.1389842828241,1150.0,10.0
0.034260490750000004,0.3426239475,133.14991864195068,1150.0,10.0
0.034339653375,0.34341557375,133.15982613612636,1150.0,10.0
0.034418816000000005,0.3442072,133.168487817599,1150.0,10.0
0.0344965075,0.34498411500000004,133.1758598968184,1150.0,10.0
0.034574199,0.34576103,133.18207374243477,1150.0,10.0
0.034651890500000004,0.346537945,133.18743588130135,1150.0,10.0
0.034729582,0.34731486,133.19242799846853,1150.0,10.0
0.0348072735,0.348091775,133.19770693718837,1150.0,10.0
0.034884965000000004,0.34886869,133.20315337093797,1150.0,10.0
0.0349626565,0.34964560499999997,133.20859980468805,1150.0,10.0
0.035040348,0.35042251999999996,133.21404623843804,1150.0,10.0
0.0351180395,0.35119943499999995,133.2194926721881,1150.0,10.0
0.035195731,0.35197634999999994,133.2249391059385,1150.0,10.0
0.0352734225,0.3527532649999999,133.23038553968763,1150.0,10.0
0.035351114,0.35353017999999997,133.23615575342146,1150.0,10.0
0.0354288055,0.354307095,133.2418750749088,1150.0,10.0
0.035506497,0.35508401,133.24708722883182,1150.0,10.0
0.0355841885,0.355860925,133.25147633228073,1150.0,10.0
0.03566188,0.35663784,133.25486689474738,1150.0,10.0
0.035741275249999996,0.3574317925,133.25722381813122,1150.0,10.0
0.0358206705,0.358225745,133.25865239673502,1150.0,10.0
0.03590006575,0.35901969749999996,133.2593983172669,1150.0,10.0
0.035979461000000004,0.35981365,133.2598476588407,1150.0,10.0
0.03605885625000001,0.3606076025,133.2605268929767,1150.0,10.0
0.0361382515,0.361401555,133.2613403773493,1150.0,10.0
0.03621764675,0.36219550749999996,133.26215386172143,1150.0,10.0
0.036297042,0.36298946,133.26296734609411,1150.0,10.0
0.036376437250000004,0.3637834125,133.26378083046836,1150.0,10.0
0.0364558325,0.364577365,133.26459431484346,1150.0,10.0
0.036535227749999996,0.36537131749999996,133.26540779921888,1150.0,10.0
0.036614623,0.36616527,133.2660179125004,1150.0,10.0
0.03669401825,0.3669592225,133.26683139687623,1150.0,10.0
0.036773413500000005,0.367753175,133.26764488125147,1150.0,10.0
0.03685280875000001,0.36854712749999996,133.2684583656257,1150.0,10.0
0.036932204,0.36934108,133.26927184999846,1150.0,10.0