File: datasets/steel_spring/csv/BS2V-1200-0.01.csv
Time(s),Strain(%),Stress(MPa),Temp(C),SR(%/s)
0.0,3.993e-05,0.838110095705248,1200.0,0.01
0.0032109999999999994,7.204e-05,0.012648740160510097,1200.0,0.01
0.004282000000000001,8.275e-05,-0.3513894810143131,1200.0,0.01
0.004822,8.815e-05,-0.26592709989605334,1200.0,0.01
0.005351999999999999,9.345e-05,0.25711335143845726,1200.0,0.01
0.005882999999999999,9.876e-05,1.5506050958750042,1200.0,0.01
0.010161,0.00014154,3.1295330812310693,1200.0,0.01
0.0181815,0.00022174500000000003,5.04076073718941,1200.0,0.01
0.025931999999999997,0.00029925000000000004,7.09815445989207,1200.0,0.01
0.03529,0.00039283,9.064049720659126,1200.0,0.01
0.051331,0.00055324,10.650722315314432,1200.0,0.01
0.0641655,0.000681585,11.656487013314441,1200.0,0.01
0.07834350000000001,0.000823365,12.535058293460278,1200.0,0.01
0.094661,0.00098654,13.332020352337173,1200.0,0.01
0.11124700000000001,0.0011524,13.951368257801198,1200.0,0.01
0.13238450000000002,0.001363775,14.446073523200813,1200.0,0.01
0.150585,0.00154578,14.830889246051193,1200.0,0.01
0.172002,0.0017599500000000001,15.145137726632626,1200.0,0.01
0.1912765,0.001952695,15.431323011568233,1200.0,0.01
0.201718,0.00205711,15.702408347772783,1200.0,0.01
0.21885900000000003,0.0022285200000000003,15.958345904019001,1200.0,0.01
0.2392215,0.002432145,16.211507877352346,1200.0,0.01
0.256368,0.00260361,16.470958055945157,1200.0,0.01
0.27378349999999996,0.0027777649999999997,16.73425198877849,1200.0,0.01
0.2941525,0.002981455,16.993520216223555,1200.0,0.01
0.3115745,0.003155675,17.23894833044136,1200.0,0.01
0.3276644999999999,0.003316575,17.490230770437584,1200.0,0.01
0.34456,0.0034855299999999997,17.744954769689475,1200.0,0.01
0.36091699999999993,0.0036490999999999997,17.99436744956826,1200.0,0.01
0.38237849999999995,0.003863715,18.240250209575827,1200.0,0.01
0.4003575,0.004043505,18.488035264797418,1200.0,0.01
0.4172665,0.0042125949999999995,18.751342566825834,1200.0,0.01
0.4392729999999999,0.00443266,19.004319682882652,1200.0,0.01
0.4588709999999999,0.00462864,19.2351669683012,1200.0,0.01
0.47552199999999994,0.00479515,19.438752783994378,1200.0,0.01
0.494585,0.00498578,19.646557824668637,1200.0,0.01
0.5171465,0.005211395000000001,19.82102085876523,1200.0,0.01
0.5383745,0.005423675,19.9681940092046,1200.0,0.01
0.555844,0.00559837,20.10163390097355,1200.0,0.01
0.5730454999999999,0.005770384999999999,20.22949948278796,1200.0,0.01
0.59267,0.0059666300000000005,20.37133346353229,1200.0,0.01
0.6122985,0.006162915,20.508055228558817,1200.0,0.01
0.632198,0.00636191,20.642801472341002,1200.0,0.01
0.6510235,0.006550165,20.768894149833407,1200.0,0.01
0.667702,0.00671695,20.902724849255748,1200.0,0.01
0.6870784999999999,0.006910715,21.01392407119512,1200.0,0.01
0.7072645,0.0071125749999999995,21.112982084710264,1200.0,0.01
0.722607,0.007266,21.206822420265198,1200.0,0.01
0.7419894999999999,0.007459825,21.30239629799816,1200.0,0.01
0.7643389999999999,0.00768332,21.41411636286936,1200.0,0.01
0.7858874999999999,0.007898805,21.533572478015188,1200.0,0.01
0.8031275,0.008071205,21.64472346663261,1200.0,0.01
0.8206389999999999,0.00824632,21.739801372666722,1200.0,0.01
0.8400394999999998,0.008440324999999999,21.830157433486807,1200.0,0.01
0.8581024999999999,0.008620955,21.91583511753796,1200.0,0.01
0.8802104999999999,0.008842035,21.994271166486875,1200.0,0.01
0.9001629999999998,0.00904156,22.05514799462326,1200.0,0.01
0.9190394999999998,0.009230325,22.12346080642817,1200.0,0.01
0.9395399999999998,0.009435329999999999,22.19446158183153,1200.0,0.01
0.9592364999999999,0.009632294999999999,22.269162396322052,1200.0,0.01
0.979478,0.00983471,22.33404258167053,1200.0,0.01
1.001613,0.01005606,22.39645981715538,1200.0,0.01
1.020508,0.01024501,22.460514723079594,1200.0,0.01
1.0383305,0.010423235,22.533633962388304,1200.0,0.01
1.0569645,0.010609575,22.61726400555124,1200.0,0.01
1.0772210000000002,0.010812140000000001,22.69492223337322,1200.0,0.01
1.0966765,0.011006695,22.77761936537892,1200.0,0.01
1.115863,0.01119856,22.83807142980882,1200.0,0.01
1.1374870000000001,0.0114148,22.887538457640243,1200.0,0.01
1.156686,0.011606789999999999,22.93633751753039,1200.0,0.01
1.1739905,0.011779834999999999,22.983021627390208,1200.0,0.01
1.1934605,0.011974535,23.02504898538449,1200.0,0.01
1.212392,0.01216385,23.07265512518183,1200.0,0.01
1.2313325000000002,0.012353255,23.147594617255734,1200.0,0.01
1.25325,0.012572429999999999,23.227954509437602,1200.0,0.01
1.2765255,0.012805185,23.28967845621983,1200.0,0.01
1.2960195,0.013000125000000001,23.333327559267172,1200.0,0.01
1.311995,0.01315988,23.38055436114786,1200.0,0.01
1.3309540000000002,0.01334947,23.427209254753933,1200.0,0.01
1.3526250000000002,0.01356618,23.478774030170598,1200.0,0.01
1.3729405000000001,0.013769335,23.528527912751997,1200.0,0.01
1.3927180000000001,0.013967110000000001,23.5752117207368,1200.0,0.01
1.413316,0.01417309,23.63130024128604,1200.0,0.01
1.4339235000000001,0.014379165,23.682460672250123,1200.0,0.01
1.452093,0.01456086,23.716074062375093,1200.0,0.01
1.4718915,0.014758845,23.756429677096683,1200.0,0.01
1.4925055,0.014964985,23.808257843284217,1200.0,0.01
1.5117635000000003,0.015157565000000001,23.859384378062604,1200.0,0.01
1.531573,0.01535566,23.916614078352346,1200.0,0.01
1.550843,0.01554836,23.970149769503855,1200.0,0.01
1.573644,0.015776369999999998,24.016128568532217,1200.0,0.01
1.5940095,0.015980025000000002,24.045122808998165,1200.0,0.01
1.612478,0.01616471,24.07309174511755,1200.0,0.01
1.632038,0.01636031,24.105353344098642,1200.0,0.01
1.6532299999999998,0.01657223,24.144177368252095,1200.0,0.01
1.6703459999999999,0.016743389999999997,24.18308049076349,1200.0,0.01
1.687466,0.01691459,24.21743749742065,1200.0,0.01
1.7108474999999999,0.017148405,24.24829150232215,1200.0,0.01
1.729612,0.01733605,24.27204223785242,1200.0,0.01
1.748101,0.01752094,24.30211334218003,1200.0,0.01
1.770132,0.01774125,24.33976494175576,1200.0,0.01
1.791628,0.01795621,24.395325679655368,1200.0,0.01
1.8131235,0.018171165,24.466103208816385,1200.0,0.01
1.8313570000000001,0.018353500000000002,24.531307452642178,1200.0,0.01
1.8509555,0.018549484999999998,24.585008609873242,1200.0,0.01
1.872739,0.018767319999999997,24.627004432337284,1200.0,0.01
1.8907135,0.018947065,24.656776220841024,1200.0,0.01
1.9103235,0.019143165,24.664900124488714,1200.0,0.01
1.9304825,0.019344754999999998,24.664579376393952,1200.0,0.01
1.94983,0.019538229999999997,24.675332983583406,1200.0,0.01
1.9691855,0.019731785,24.705951749988788,1200.0,0.01
1.9882695000000004,0.019922625,24.75327067087707,1200.0,0.01
2.009537,0.020135300000000002,24.809456788286216,1200.0,0.01
2.0269895,0.020309825,24.869639230843028,1200.0,0.01
2.0474435,0.020514365,24.933118123994465,1200.0,0.01
2.0709039999999996,0.02074897,24.98666206519712,1200.0,0.01
2.092189,0.02096182,25.023731046759586,1200.0,0.01
2.109385,0.021133779999999998,25.042846024729208,1200.0,0.01
2.130955,0.02134948,25.05197657493197,1200.0,0.01
2.1522515,0.021562445,25.06997233739789,1200.0,0.01
2.1678180000000005,0.02171811,25.10270974913087,1200.0,0.01
2.1888475,0.021928404999999998,25.136594453036157,1200.0,0.01
2.2115235,0.022155164999999997,25.173994740096685,1200.0,0.01
2.231748,0.02235741,25.216920311509462,1200.0,0.01
2.2517009999999997,0.022556939999999998,25.26207604436743,1200.0,0.01
2.272205,0.02276198,25.30525238067987,1200.0,0.01
2.291342,0.02295335,25.33528477370262,1200.0,0.01
2.313217,0.0231721,25.358628685494338,1200.0,0.01
2.334282,0.02338275,25.393087827876965,1200.0,0.01
2.355623,0.023596159999999998,25.431394204460343,1200.0,0.01
2.3756005,0.023795934999999997,25.458117813174272,1200.0,0.01
2.3955830000000002,0.023995759999999998,25.485820413119274,1200.0,0.01
2.417757,0.0242175,25.520619337155313,1200.0,0.01
2.4344605,0.024384535,25.571617183909066,1200.0,0.01
2.450619,0.024546119999999998,25.622719434223434,1200.0,0.01
2.4714365000000003,0.024754295000000003,25.67557122248298,1200.0,0.01
2.4914370000000003,0.0249543,25.724628820367535,1200.0,0.01
2.511165,0.02515158,25.768698629159353,1200.0,0.01
2.532539,0.02536532,25.79636726312153,1200.0,0.01
2.5533729999999997,0.025573659999999998,25.81114344901739,1200.0,0.01
2.5725689999999997,0.02576562,25.815669100475706,1200.0,0.01
2.5914965,0.025954895,25.818775566903728,1200.0,0.01
2.6117935,0.026157865000000002,25.832307905418755,1200.0,0.01
2.6301734999999997,0.026341665,25.859210564814518,1200.0,0.01
2.649112,0.02653105,25.9014810812652,1200.0,0.01
2.670243,0.02674236,25.950546167386417,1200.0,0.01
2.692751,0.02696744,25.995819456577735,1200.0,0.01
2.7158185,0.027198115000000002,26.038771433172364,1200.0,0.01
2.735868,0.02739861,26.074191429524635,1200.0,0.01
2.754271,0.02758264,26.10793857078976,1200.0,0.01
2.7732280000000005,0.02777221,26.137855532990457,1200.0,0.01
2.7921885,0.027961815,26.166987755306764,1200.0,0.01
2.810607,0.028145999999999997,26.193382507962195,1200.0,0.01
2.830676,0.02834669,26.22026625885238,1200.0,0.01
2.8510215,0.028550145,26.245619016532412,1200.0,0.01
2.873297,0.028772899999999997,26.269326508187763,1200.0,0.01
2.893373,0.02897366,26.288387915428242,1200.0,0.01
2.910708,0.02914701,26.303773383619586,1200.0,0.01
2.929421,0.02933414,26.333461936623323,1200.0,0.01
2.949236,0.02953229,26.373906010142232,1200.0,0.01
2.969611,0.02973604,26.424199550716054,1200.0,0.01
2.987784,0.02991777,26.476450169049464,1200.0,0.01
3.0078885,0.030118815,26.53547287595663,1200.0,0.01
3.02827,0.030322630000000003,26.585560376377057,1200.0,0.01
3.0489295,0.030529225,26.622049783375132,1200.0,0.01
3.070975,0.03074968,26.653847807312562,1200.0,0.01
3.0908225,0.030948154999999998,26.681732308411032,1200.0,0.01
3.1084705,0.031124634999999998,26.697981991818242,1200.0,0.01
3.1308040000000004,0.03134797,26.71919729605875,1200.0,0.01
3.1514835000000003,0.031554765,26.749539261700686,1200.0,0.01
3.169137,0.031731300000000004,26.760989172554886,1200.0,0.01
3.1901045,0.031940974999999996,26.773783968102265,1200.0,0.01
3.207212,0.03211205,26.77695615883912,1200.0,0.01
3.226534,0.03230527,26.78190718260241,1200.0,0.01
3.248066,0.03252059,26.812433177835437,1200.0,0.01
3.267117,0.0327111,26.862182523361966,1200.0,0.01
3.2883794999999996,0.032923725,26.915339528176375,1200.0,0.01
3.3088179999999996,0.03312811,26.98839773925954,1200.0,0.01
3.3289869999999997,0.0333298,27.0567660817367,1200.0,0.01
3.3480529999999997,0.03352046,27.097481677348384,1200.0,0.01
3.3651929999999997,0.033691860000000004,27.132667798562526,1200.0,0.01
3.3878630000000003,0.03391856,27.157945165219814,1200.0,0.01
3.408596,0.03412589,27.166059762532402,1200.0,0.01
3.426295,0.03430288,27.17447564554581,1200.0,0.01
3.445659,0.03449652,27.195724379155703,1200.0,0.01
3.4683425,0.034723355,27.199921234485206,1200.0,0.01
3.4888174999999997,0.034928105,27.21560723208926,1200.0,0.01
3.508469,0.035124619999999995,27.22781431644152,1200.0,0.01
3.5295075,0.035335005,27.244153241416882,1200.0,0.01
3.5494465,0.035534394999999996,27.27021949671041,1200.0,0.01
3.569389,0.03573382,27.303818542395916,1200.0,0.01
3.5868415,0.035908344999999994,27.337782390651626,1200.0,0.01
3.6062365,0.036102295,27.39523781024822,1200.0,0.01
3.6259105,0.036299035,27.452342791151594,1200.0,0.01
3.6455835,0.036495765,27.49102242295649,1200.0,0.01
3.6658155,0.036698085,27.532782725537874,1200.0,0.01
3.686057,0.0369005,27.581614665041595,1200.0,0.01
3.704916,0.037089090000000005,27.615866071198955,1200.0,0.01
3.7251655,0.037291585,27.638776709929928,1200.0,0.01
3.7484725,0.037524655000000004,27.657464801346624,1200.0,0.01
3.7709485000000003,0.037749415,27.67918515380121,1200.0,0.01
3.7898235000000002,0.037938165,27.708473262401697,1200.0,0.01
3.804815,0.038088079999999996,27.72963126906281,1200.0,0.01
3.825085,0.038290779999999996,27.741547468610428,1200.0,0.01
3.8486905,0.038526835,27.76029502319767,1200.0,0.01
3.8670185000000004,0.038710115,27.782658107608512,1200.0,0.01
3.8878575,0.038918505,27.8086449728338,1200.0,0.01
3.9084190000000003,0.03912412,27.842671130954603,1200.0,0.01
3.92565,0.03929643,27.86935959734461,1200.0,0.01
3.9439975,0.039479904999999996,27.902563186886027,1200.0,0.01
3.963738,0.03967731,27.93347012956228,1200.0,0.01
3.986268,0.039902610000000005,27.975746268952445,1200.0,0.01
4.0054595,0.040094525000000006,28.008612205513458,1200.0,0.01
4.023540499999999,0.040275335,28.03779091338671,1200.0,0.01
4.0427395,0.040467325,28.063529254996567,1200.0,0.01
4.0638915,0.040678845000000005,28.093996993729682,1200.0,0.01
4.085046999999999,0.0408904,28.11022251938484,1200.0,0.01
4.104258,0.04108251,28.098497051104506,1200.0,0.01
4.125422,0.04129415,28.099005959165066,1200.0,0.01
4.145198,0.04149191,28.113851867816496,1200.0,0.01
4.163586,0.04167579,28.149296837202524,1200.0,0.01
4.185045,0.04189038,28.178637692670502,1200.0,0.01
4.205672999999999,0.042096659999999994,28.205291767992286,1200.0,0.01
4.224625499999999,0.042286185,28.24663685324991,1200.0,0.01
4.244698,0.04248691,28.291560408630847,1200.0,0.01
4.263104,0.04267097,28.319915365776485,1200.0,0.01
4.282631,0.04286624,28.33835145243562,1200.0,0.01
4.3035565,0.043075495000000005,28.373850855757716,1200.0,0.01
4.3230865,0.043270795,28.427227799109986,1200.0,0.01
4.343183999999999,0.04347177,28.47848955495105,1200.0,0.01
4.361048499999999,0.043650415,28.507578709233503,1200.0,0.01
4.381149499999999,0.043851425,28.528728318669096,1200.0,0.01
4.4037679999999995,0.04407761,28.548306221829954,1200.0,0.01
4.421644,0.04425637,28.562782581316633,1200.0,0.01
4.438686499999999,0.044426795000000005,28.56622667102263,1200.0,0.01
4.458525,0.04462518,28.577386494965577,1200.0,0.01
4.4792045,0.044831974999999996,28.596375412919897,1200.0,0.01
4.499051499999999,0.045030445,28.62624211275316,1200.0,0.01
4.5166664999999995,0.045206595,28.663300610760967,1200.0,0.01
4.537081,0.045410740000000005,28.692734975247898,1200.0,0.01
4.558897,0.0456289,28.727419061708183,1200.0,0.01
4.579597999999999,0.045835909999999994,28.755410379783957,1200.0,0.01
4.602822499999999,0.046068155,28.78293883581073,1200.0,0.01
4.622415499999999,0.046264084999999996,28.807778547242492,1200.0,0.01
4.642007499999999,0.046460005,28.835143416320232,1200.0,0.01
4.6638465,0.046678395,28.865003012111938,1200.0,0.01
4.684013,0.04688006,28.901894118504142,1200.0,0.01
4.7011,0.047050930000000005,28.93626741996846,1200.0,0.01
4.718468,0.04722461,28.970030579023444,1200.0,0.01
4.737800999999999,0.04741794,28.987081629191888,1200.0,0.01
4.756859499999999,0.047608525,28.995180748154056,1200.0,0.01
4.776477999999999,0.04780471,29.008942798341476,1200.0,0.01
4.798068499999999,0.048020615,29.027819027691557,1200.0,0.01
4.818818499999999,0.048228115,29.04428842057593,1200.0,0.01
4.836763999999999,0.04840757,29.06410355816657,1200.0,0.01
4.858645999999999,0.04862639,29.092471336092647,1200.0,0.01
4.88194,0.04885933,29.108042428641852,1200.0,0.01
4.9013045,0.049052975,29.141762304967617,1200.0,0.01
4.915900499999999,0.049198935,29.180244676283916,1200.0,0.01
4.9341525,0.049381455000000005,29.21758594324994,1200.0,0.01
4.956612999999999,0.04960606,29.264718378032157,1200.0,0.01
4.977958999999999,0.04981952,29.30851570519114,1200.0,0.01
4.999029999999999,0.050030229999999995,29.34027211707006,1200.0,0.01
5.019543,0.05023536,29.3626794643275,1200.0,0.01
5.040623,0.050446160000000004,29.374733811568234,1200.0,0.01
5.05805,0.05062043,29.373701056106274,1200.0,0.01
5.076043499999999,0.050800365,29.37753455189625,1200.0,0.01
5.098261999999999,0.05102255,29.38818178190579,1200.0,0.01
5.1154145,0.051194075000000006,29.400883391434185,1200.0,0.01
5.136794999999999,0.05140788,29.429995906534476,1200.0,0.01
5.162687,0.0516668,29.468520481842877,1200.0,0.01
5.18267,0.05186663,29.500369127710304,1200.0,0.01
5.198993999999999,0.05202987,29.538429984713968,1200.0,0.01
5.214477499999999,0.052184705,29.583790178535892,1200.0,0.01
5.236442499999999,0.052404355,29.613240174522623,1200.0,0.01
5.257567999999999,0.05261561,29.62906271359854,1200.0,0.01
5.2770055,0.052809985000000004,29.63534463755309,1200.0,0.01
5.2986995,0.053026925,29.641253776068403,1200.0,0.01
5.318144499999999,0.053221375,29.658841667392313,1200.0,0.01
5.337313999999999,0.05341307,29.688095368235203,1200.0,0.01
5.3573319999999995,0.05361325,29.70701437636811,1200.0,0.01
5.374814,0.05378807,29.728095857839794,1200.0,0.01
5.3956895,0.053996825,29.75688986676191,1200.0,0.01
5.4171285,0.054211215,29.787342302293915,1200.0,0.01
5.4343365,0.054383295,29.82264697700588,1200.0,0.01
5.454374,0.05458367,29.848811027626876,1200.0,0.01
5.473288999999999,0.05477282,29.870697728511352,1200.0,0.01
5.492488499999999,0.054964815,29.896722209221338,1200.0,0.01
5.5142285,0.055182215,29.912187829842743,1200.0,0.01
5.5342815,0.055382745,29.920298081026665,1200.0,0.01
5.5534925,0.055574855000000006,29.920419731746602,1200.0,0.01
5.5741195,0.055781125,29.913640268292067,1200.0,0.01
5.590793,0.05594786,29.926760629312913,1200.0,0.01
5.609164,0.05613157,29.957194853333796,1200.0,0.01
5.6326279999999995,0.05636621,29.99702093069346,1200.0,0.01
5.6546845,0.056586775000000006,30.0453463293753,1200.0,0.01
5.6764605,0.056804535,30.102933976522884,1200.0,0.01
5.6965465,0.057005395,30.139661063761558,1200.0,0.01
5.717203,0.05721196,30.166828830846665,1200.0,0.01
5.736167999999999,0.05740161,30.19221476862321,1200.0,0.01
5.753722,0.057577149999999994,30.198499759935878,1200.0,0.01
5.770987499999999,0.057749805,30.202141597918978,1200.0,0.01
5.7910875,0.057950804999999994,30.21555588126934,1200.0,0.01
5.8145945,0.058185875,30.222285953835677,1200.0,0.01
5.83414,0.058381329999999995,30.224584873767558,1200.0,0.01
5.8517065,0.058556995,30.221794834356558,1200.0,0.01
5.869562,0.05873555,30.238161443773112,1200.0,0.01
5.8879885,0.058919815,30.266416549536203,1200.0,0.01
5.9072675,0.059112605,30.310229916106167,1200.0,0.01
5.9291035,0.059330965,30.352008694494565,1200.0,0.01
5.9503755,0.059543685,30.393588924795733,1200.0,0.01
5.9685305,0.059725235,30.43079765916119,1200.0,0.01
5.988106999999999,0.059921,30.44981043821636,1200.0,0.01
6.007404999999999,0.06011398,30.445593616248434,1200.0,0.01
6.028975999999999,0.06032969,30.44419566432993,1200.0,0.01
6.050264499999999,0.060542575,30.459619415791924,1200.0,0.01
6.0695749999999995,0.06073568,30.48958968030324,1200.0,0.01
6.089739499999999,0.060937325,30.5202321097236,1200.0,0.01
6.1104775,0.061144705,30.550284959407428,1200.0,0.01
6.1275224999999995,0.061315154999999996,30.58238604384311,1200.0,0.01
6.145992,0.061499849999999995,30.614318746373407,1200.0,0.01
6.1701524999999995,0.061741455,30.648284268810965,1200.0,0.01
6.1903375,0.061943305000000004,30.668764623026842,1200.0,0.01
6.2093929999999995,0.06213386,30.698370333301323,1200.0,0.01
6.2273119999999995,0.062313049999999995,30.71555180154357,1200.0,0.01
6.247508999999999,0.06251502,30.71999189593744,1200.0,0.01
6.268278999999999,0.06272272,30.708755325217638,1200.0,0.01
6.2836415,0.062876345,30.70739407057755,1200.0,0.01
6.303845,0.06307838,30.72838931828216,1200.0,0.01
6.3257674999999995,0.063297605,30.760443506096554,1200.0,0.01
6.345701499999999,0.063496945,30.796095088395667,1200.0,0.01
6.366775,0.06370768,30.833570313407197,1200.0,0.01
6.387283,0.06391276000000001,30.862822009837018,1200.0,0.01
6.407229,0.06411222,30.882611151636002,1200.0,0.01
6.4277495,0.06431742500000001,30.883363874115627,1200.0,0.01
6.4476984999999996,0.06451691500000001,30.876261385863792,1200.0,0.01
6.469081999999999,0.06473075,30.880911365398017,1200.0,0.01
6.490752499999999,0.064947455,30.903299443633212,1200.0,0.01
6.507292,0.06511285,30.934680760977734,1200.0,0.01
6.525264999999999,0.06529257999999999,30.98219722784527,1200.0,0.01
6.545805,0.06549798,31.027144830767817,1200.0,0.01
6.5654945,0.065694875,31.059506904131183,1200.0,0.01
6.587762999999999,0.06591756,31.08726850818975,1200.0,0.01
6.608032499999999,0.06612025499999999,31.100578058013994,1200.0,0.01
6.626874,0.06630867,31.1002401626334,1200.0,0.01
6.648012,0.06652005,31.08936360132687,1200.0,0.01
6.66601,0.06670003,31.07784154599553,1200.0,0.01
6.686579,0.06690572,31.084585764623952,1200.0,0.01
6.707724,0.06711717,31.121644594015883,1200.0,0.01
6.725161,0.06729154000000001,31.158556841972345,1200.0,0.01
6.744318999999999,0.06748312000000001,31.185662837710602,1200.0,0.01
6.7614725,0.06765465500000001,31.218995725227323,1200.0,0.01
6.7817775000000005,0.067857705,31.237818642331558,1200.0,0.01
6.806665,0.06810658,31.240142238994565,1200.0,0.01
6.826973499999999,0.06830966499999999,31.236469568002022,1200.0,0.01
6.844141499999999,0.068481345,31.22746062236935,1200.0,0.01
6.865899499999999,0.068698925,31.23315623396388,1200.0,0.01
6.886225,0.06890218000000001,31.25919469860198,1200.0,0.01
6.904551,0.06908544,31.294067516255502,1200.0,0.01
6.926031999999999,0.06930025000000001,31.32331762885964,1200.0,0.01
6.9429324999999995,0.06946925500000001,31.370914573236618,1200.0,0.01
6.9618424999999995,0.069658355,31.413686659200895,1200.0,0.01
6.9836195,0.069876125,31.446482303280646,1200.0,0.01
7.003111,0.07007104,31.46578609267273,1200.0,0.01
7.022316999999999,0.0702631,31.467976254178495,1200.0,0.01
7.0423855,0.070463785,31.470712056998483,1200.0,0.01
7.0615985,0.070655915,31.47527310320086,1200.0,0.01
7.080245999999999,0.07084239,31.476018113852078,1200.0,0.01
7.102339499999999,0.07106332500000001,31.480226650620786,1200.0,0.01
7.123573,0.07127566,31.504692441535333,1200.0,0.01
7.1436615,0.071476545,31.530496434300215,1200.0,0.01
7.1614585,0.071654515,31.56014301496905,1200.0,0.01
7.18127,0.07185263,31.578705611832774,1200.0,0.01
7.2048214999999995,0.07208814499999999,31.591030559810275,1200.0,0.01
7.223495,0.07227488,31.602746533539683,1200.0,0.01
7.242452999999999,0.07246446000000001,31.605432743967732,1200.0,0.01
7.261419499999999,0.072654125,31.60552217047507,1200.0,0.01
7.281255999999999,0.07285248999999999,31.61226860699594,1200.0,0.01
7.3025275,0.073065205,31.622836728337045,1200.0,0.01
7.321505,0.07325498,31.637782064225345,1200.0,0.01
7.341638,0.07345631,31.66182830006852,1200.0,0.01
7.361193999999999,0.07365187000000001,31.680726771277328,1200.0,0.01
7.377878,0.07381871000000001,31.701807923211557,1200.0,0.01
7.3988855,0.074028785,31.729995583722708,1200.0,0.01
7.421048999999999,0.07425042,31.758058126832275,1200.0,0.01
7.440334999999999,0.07444328,31.786808791453215,1200.0,0.01
7.4610639999999995,0.07465057,31.81240039844972,1200.0,0.01
7.480648499999999,0.074846415,31.83504551986257,1200.0,0.01
7.49966,0.07503653,31.852499843226287,1200.0,0.01
7.518098500000001,0.075220915,31.847307793516162,1200.0,0.01
7.5371175,0.075411105,31.81471601663189,1200.0,0.01
7.5584489999999995,0.07562442,31.79180136199745,1200.0,0.01
7.5786299999999995,0.07582623,31.79623138712557,1200.0,0.01
7.597368999999999,0.07601362,31.816419321701105,1200.0,0.01
7.617844,0.07621837000000001,31.853087166875127,1200.0,0.01
7.637745499999999,0.076417385,31.903202094371363,1200.0,0.01
7.6573595,0.076613525,31.958623848579702,1200.0,0.01
7.678138499999999,0.076821315,32.0026916179871,1200.0,0.01
7.698922,0.07702914999999999,32.021375700574126,1200.0,0.01
7.717969499999999,0.077219625,32.016762335697166,1200.0,0.01
7.737604999999999,0.07741598,32.01962450936561,1200.0,0.01
7.758687499999999,0.077626805,32.03891855392597,1200.0,0.01
7.778039,0.07782032,32.05346503403198,1200.0,0.01
7.795376499999999,0.077993695,32.076731986255105,1200.0,0.01
7.812424499999999,0.078164175,32.10116360445962,1200.0,0.01
7.834676,0.07838669000000001,32.13018608114368,1200.0,0.01
7.8572235,0.07861216500000001,32.148088146045424,1200.0,0.01
7.8760195,0.078800125,32.15569792560449,1200.0,0.01
7.895680499999999,0.078996735,32.154571867901765,1200.0,0.01
7.915345499999999,0.079193385,32.15123497386753,1200.0,0.01
7.935312,0.07939304999999999,32.146164486337376,1200.0,0.01
7.956149,0.07960142,32.14403918611967,1200.0,0.01
7.974671000000001,0.07978664,32.1401811228603,1200.0,0.01
7.9937770000000015,0.07997770000000001,32.14618936557619,1200.0,0.01
8.014621000000002,0.08018614,32.167168941674696,1200.0,0.01
8.035468999999999,0.08039462,32.19631424159139,1200.0,0.01
8.054006000000001,0.08057998999999999,32.228233748650275,1200.0,0.01
8.072835000000001,0.08076828,32.25618364273722,1200.0,0.01
8.094856,0.08098849,32.284112258648406,1200.0,0.01
8.118043,0.08122036,32.29709557705961,1200.0,0.01
8.140367000000001,0.0814436,32.31089518494982,1200.0,0.01
8.157767,0.0816176,32.30996019676019,1200.0,0.01
8.17807,0.08182063,32.30992872719942,1200.0,0.01
8.199821,0.08203814000000001,32.31587966378024,1200.0,0.01
8.220415,0.08224408,32.32659005851837,1200.0,0.01
8.237541,0.08241534,32.342090900406454,1200.0,0.01
8.2546655,0.08258658499999999,32.36255009353516,1200.0,0.01
8.275269999999999,0.08279263,32.38585614771925,1200.0,0.01
8.2955965,0.082995895,32.393923132454056,1200.0,0.01
8.3141815,0.083181745,32.40819388523082,1200.0,0.01
8.333934500000002,0.083379275,32.41550892289203,1200.0,0.01
8.3568885,0.083608815,32.424169559824485,1200.0,0.01
8.3769375,0.083809305,32.436500830083894,1200.0,0.01
8.393791499999999,0.083977845,32.447844618772976,1200.0,0.01
8.410943,0.08414936,32.46486422115176,1200.0,0.01
8.4312975,0.084352905,32.4809520481535,1200.0,0.01
8.4536865,0.084576795,32.50022816054195,1200.0,0.01
8.473466,0.08477459,32.51987913418758,1200.0,0.01
8.491213,0.08495206,32.551210504717616,1200.0,0.01
8.513032500000001,0.085170255,32.580524468662844,1200.0,0.01
8.533407,0.085374,32.613016173865844,1200.0,0.01
8.555242,0.08559235000000001,32.64143973594689,1200.0,0.01
8.576492000000002,0.08580485,32.66719763303026,1200.0,0.01
8.593674,0.08597667,32.688317668668454,1200.0,0.01
8.6143545,0.086183475,32.685067975903664,1200.0,0.01
8.633877,0.0863787,32.672429392803764,1200.0,0.01
8.650485,0.08654478,32.66174528962602,1200.0,0.01
8.6735075,0.086775005,32.65511805454598,1200.0,0.01
8.694498,0.08698491,32.64932012522949,1200.0,0.01
8.71199,0.08715983,32.65694518258358,1200.0,0.01
8.735026000000001,0.08739019,32.66541151723464,1200.0,0.01
8.753693000000002,0.08757686,32.683846124122915,1200.0,0.01
8.771490500000002,0.087754835,32.70745834867982,1200.0,0.01
8.7887055,0.087926985,32.71352922541881,1200.0,0.01
8.808257999999999,0.08812250999999999,32.72033633389248,1200.0,0.01
8.8298565,0.08833849499999999,32.73225408844603,1200.0,0.01
8.847961999999999,0.08851955,32.747905891398474,1200.0,0.01
8.8695705,0.08873563500000001,32.75916091069166,1200.0,0.01
8.890887500000002,0.088948805,32.784332696988976,1200.0,0.01
8.909879,0.08913872,32.81265875156446,1200.0,0.01
8.9309205,0.089349135,32.851517208257384,1200.0,0.01
8.950209000000001,0.08954202,32.87521856251518,1200.0,0.01
8.969502,0.08973495000000001,32.888234172507154,1200.0,0.01
8.991431500000001,0.089954245,32.88599413563765,1200.0,0.01
9.006928000000002,0.09010921,32.88659390623606,1200.0,0.01
9.027695000000001,0.09031688,32.87745004924558,1200.0,0.01
9.0522705,0.090562635,32.84967928755826,1200.0,0.01
9.070120500000002,0.090741135,32.830488608185334,1200.0,0.01
9.087678,0.09091671,32.820891961730744,1200.0,0.01
9.107579000000001,0.09111572,32.83404357614403,1200.0,0.01
9.1274885,0.091314815,32.85433792477474,1200.0,0.01
9.147988999999999,0.09151982,32.89695653111698,1200.0,0.01
9.16556,0.09169553,32.93056832548793,1200.0,0.01
9.186947,0.0919094,32.97113851598201,1200.0,0.01
9.20804,0.09212033,32.990843866311735,1200.0,0.01
9.225326,0.09229319,33.0011367748137,1200.0,0.01
9.246142500000001,0.09250135500000001,32.999595647501124,1200.0,0.01
9.269011500000001,0.092730045,32.996363047862964,1200.0,0.01
9.289826,0.09293819,33.00038958819879,1200.0,0.01
9.3068405,0.093108335,33.0132022594262,1200.0,0.01
9.3273775,0.093313705,33.032602746392214,1200.0,0.01
9.3467435,0.09350736500000001,33.04930820465941,1200.0,0.01
9.3687565,0.093727495,33.07463209983183,1200.0,0.01
9.391064,0.09395057000000001,33.0825923393034,1200.0,0.01
9.411322,0.09415315,33.0923815148658,1200.0,0.01
9.430407500000001,0.09434400500000001,33.09567124234296,1200.0,0.01
9.447440499999999,0.094514335,33.091703582521,1200.0,0.01
9.467417999999999,0.09471410999999999,33.09468331728638,1200.0,0.01
9.487696,0.09491689,33.08462059874656,1200.0,0.01
9.5070935,0.09511086499999999,33.07786840164805,1200.0,0.01
9.526197,0.0953019,33.07614712274045,1200.0,0.01
9.548838,0.09552831,33.088012208056405,1200.0,0.01
9.5688355,0.095728285,33.09427644443119,1200.0,0.01
9.5876545,0.095916475,33.103809761690776,1200.0,0.01
9.60913,0.09613123,33.119587166902846,1200.0,0.01
9.627377,0.0963137,33.11967373730648,1200.0,0.01
9.6459145,0.096499075,33.12984901275562,1200.0,0.01
9.665932000000002,0.09669925,33.13607842299443,1200.0,0.01
9.687723000000002,0.09691716,33.15511129937316,1200.0,0.01
9.708333000000001,0.09712326,33.17504009987866,1200.0,0.01
9.726885,0.09730878,33.20081178795611,1200.0,0.01
9.746919,0.09750912,33.221102389003505,1200.0,0.01
9.768721500000002,0.097727145,33.23054765515712,1200.0,0.01
9.786992000000001,0.09790984999999999,33.24284529691472,1200.0,0.01
9.804974000000001,0.09808966999999999,33.23799954255306,1200.0,0.01
9.8256135,0.09829606499999999,33.22988683962525,1200.0,0.01
9.847434,0.09851426999999999,33.224447243733536,1200.0,0.01
9.867193499999999,0.098711865,33.221753673383134,1200.0,0.01
9.8866645,0.098906575,33.2114917757808,1200.0,0.01
9.9084975,0.099124905,33.20789201441317,1200.0,0.01
9.9288605,0.099328535,33.20621894268775,1200.0,0.01
9.9483435,0.099523365,33.20884273190565,1200.0,0.01
9.967244,0.09971237,33.24022613391706,1200.0,0.01
9.987033,0.09991026,33.278481801953156,1200.0,0.01
10.004752,0.10008745,33.31669119795717,1200.0,0.01
10.0251345,0.100291275,33.353298262650235,1200.0,0.01
10.045814,0.10049807,33.36392539047008,1200.0,0.01
10.067683,0.10071675999999999,33.353652243394365,1200.0,0.01
10.0898535,0.100938465,33.330508235435914,1200.0,0.01
10.108477,0.1011247,33.29858981698497,1200.0,0.01
10.128881,0.10132874,33.271101173949184,1200.0,0.01
10.146924000000002,0.10150917000000001,33.25940251324472,1200.0,0.01
10.167341,0.10171334,33.25594017180356,1200.0,0.01
10.1886485,0.10192641499999999,33.274918287290426,1200.0,0.01
10.205218,0.10209211,33.30008902328069,1200.0,0.01
10.222976,0.10226969,33.31606515372954,1200.0,0.01
10.242809999999999,0.10246802999999999,33.32756178304801,1200.0,0.01
10.2638345,0.102678275,33.33171827453827,1200.0,0.01
10.284868,0.10288861,33.332939415053104,1200.0,0.01
10.3020465,0.103060395,33.33179347655305,1200.0,0.01
10.321897,0.1032589,33.32303769235241,1200.0,0.01
10.3453125,0.103493055,33.31853204508503,1200.0,0.01
10.3633895,0.103673825,33.327022161380675,1200.0,0.01
10.379694,0.10383687,33.33079822426718,1200.0,0.01
10.4001585,0.104041515,33.323732280687956,1200.0,0.01
10.420327,0.10424320000000001,33.31995714229978,1200.0,0.01
10.4407945,0.104447875,33.31647571705147,1200.0,0.01
10.463043500000001,0.104670365,33.313935695975445,1200.0,0.01
10.4838195,0.104878125,33.313793543643925,1200.0,0.01
10.5028215,0.105068145,33.321264737439655,1200.0,0.01
10.521816000000001,0.10525809,33.32984821384262,1200.0,0.01
10.542004500000001,0.105459975,33.333379944410915,1200.0,0.01
10.561018,0.10565010999999999,33.33961484581999,1200.0,0.01
10.581814999999999,0.10585808,33.33876262108502,1200.0,0.01
10.6034995,0.106074925,33.33558307458317,1200.0,0.01
10.6216285,0.106256215,33.33594057640737,1200.0,0.01
10.641548,0.10645541,33.33496603405327,1200.0,0.01
10.663246000000001,0.10667239,33.33691859672406,1200.0,0.01
10.6804895,0.106844825,33.35104157514636,1200.0,0.01
10.701311500000001,0.10705304500000001,33.354958822998405,1200.0,0.01
10.722732,0.10726725000000001,33.357610661757896,1200.0,0.01
10.74207,0.10746063,33.359780354163306,1200.0,0.01
10.7626035,0.107665965,33.36255271087518,1200.0,0.01
10.7840385,0.107880315,33.36749945216816,1200.0,0.01
10.805176,0.10809168999999999,33.37615496938179,1200.0,0.01
10.8239385,0.108279315,33.390053653855574,1200.0,0.01
10.834363000000002,0.10838356,33.39944868110863,1200.0,0.01