File: datasets/steel_spring/csv/BS2V-1050-0.1.csv
Time(s),Strain(%),Stress(MPa),Temp(C),SR(%/s)
0.0,5.782e-05,0.023208567272733023,1050.0,0.1
0.0009618,0.000154,1.0324026696650739,1050.0,0.1
0.0019237,0.00025019,2.1126755319073083,1050.0,0.1
0.0034187999999999996,0.0003997,3.290844090349938,1050.0,0.1
0.0055562,0.00061344,4.593725281343464,1050.0,0.1
0.007106799999999999,0.0007685,6.461310049526542,1050.0,0.1
0.0093511,0.00099293,8.084497858818214,1050.0,0.1
0.012024300000000002,0.00126025,10.020620474670494,1050.0,0.1
0.013574899999999999,0.00141531,12.209781277598534,1050.0,0.1
0.0158757,0.00164539,14.68198478159854,1050.0,0.1
0.017587199999999997,0.00181654,17.389205312928095,1050.0,0.1
0.0198889,0.00204671,20.323839123882653,1050.0,0.1
0.021815499999999998,0.00223937,23.438167583511454,1050.0,0.1
0.024599299999999998,0.00251775,26.57297263199253,1050.0,0.1
0.027061999999999996,0.00276402,29.771686732621326,1050.0,0.1
0.030061899999999996,0.00306401,32.69815615046982,1050.0,0.1
0.03209769999999999,0.00326759,35.40684544193575,1050.0,0.1
0.0357421,0.00363203,37.73996496417439,1050.0,0.1
0.040137799999999994,0.0040716,39.66668993145091,1050.0,0.1
0.04303409999999999,0.00436123,41.19784820434486,1050.0,0.1
0.0487217,0.00492999,42.37138761218956,1050.0,0.1
0.05162049999999999,0.00521987,43.30887261137518,1050.0,0.1
0.0567752,0.00573534,44.06201014965547,1050.0,0.1
0.0610734,0.00616516,44.75519790006456,1050.0,0.1
0.06617959999999999,0.00667578,45.36030766681457,1050.0,0.1
0.06962099999999999,0.00701992,45.98276742786381,1050.0,0.1
0.0750005,0.00755787,46.56652790994336,1050.0,0.1
0.07925309999999999,0.00798313,47.15972189170094,1050.0,0.1
0.08399149999999998,0.00845697,47.721703996655485,1050.0,0.1
0.0890559,0.00896341,48.286085032405495,1050.0,0.1
0.0928292,0.00934074,48.83867155691307,1050.0,0.1
0.0976275,0.00982057,49.36105935109111,1050.0,0.1
0.1013495,0.01019277,49.85461884051535,1050.0,0.1
0.106261,0.01068392,50.32460870241687,1050.0,0.1
0.109878,0.01104562,50.774792582185796,1050.0,0.1
0.1147392,0.01153174,51.190964041678214,1050.0,0.1
0.1184139,0.01189921,51.58538975973884,1050.0,0.1
0.12300889999999999,0.01235871,51.95802399375019,1050.0,0.1
0.126794,0.01273722,52.325978574147925,1050.0,0.1
0.131555,0.01321332,52.66838676950399,1050.0,0.1
0.1347485,0.01353267,53.019678671034306,1050.0,0.1
0.1386474,0.01392256,53.3608097112199,1050.0,0.1
0.1435764,0.01441546,53.71051662847747,1050.0,0.1
0.14693599999999998,0.01475142,54.06116381376915,1050.0,0.1
0.151056,0.01516342,54.40103674379188,1050.0,0.1
0.15458159999999999,0.01551598,54.7501480196934,1050.0,0.1
0.15924709999999997,0.01598253,55.088206337538104,1050.0,0.1
0.1627756,0.01633538,55.432534555674465,1050.0,0.1
0.16684819999999997,0.01674264,55.74412049918961,1050.0,0.1
0.17037839999999999,0.01709566,56.083962130950965,1050.0,0.1
0.175323,0.01759012,56.397779966038094,1050.0,0.1
0.17967249999999998,0.01802507,56.72303250081461,1050.0,0.1
0.18369699999999997,0.01842752,57.03419080461006,1050.0,0.1
0.1878321,0.01884103,57.334451844371436,1050.0,0.1
0.1915338,0.0192112,57.6490231432919,1050.0,0.1
0.1959994,0.01965776,57.956587674049466,1050.0,0.1
0.19943079999999996,0.0200009,58.24773730084871,1050.0,0.1
0.20439069999999998,0.02049689,58.54175274589795,1050.0,0.1
0.2079893,0.02085675,58.836219082079786,1050.0,0.1
0.2121887,0.02127669,59.10517863011387,1050.0,0.1
0.21573589999999998,0.02163141,59.38552503493205,1050.0,0.1
0.2207581,0.02213363,59.65740941221615,1050.0,0.1
0.22452619999999998,0.02251044,59.947653222625235,1050.0,0.1
0.2294976,0.02300758,60.23679091294342,1050.0,0.1
0.2336518,0.023423,60.51764391306463,1050.0,0.1
0.23764380000000002,0.0238222,60.78463744876159,1050.0,0.1
0.24229389999999998,0.02428721,61.05936882043206,1050.0,0.1
0.2462351,0.02468133,61.3157620419813,1050.0,0.1
0.25034080000000003,0.0250919,61.567500993719946,1050.0,0.1
0.25444930000000004,0.02550275,61.81900271225782,1050.0,0.1
0.2599291,0.02605073,62.07365328832221,1050.0,0.1
0.263054,0.02636322,62.327761170784335,1050.0,0.1
0.2680447,0.02686229,62.56026938034116,1050.0,0.1
0.2731487,0.02737269,62.80046906073131,1050.0,0.1
0.27726649999999997,0.02778447,63.030901588621454,1050.0,0.1
0.281495,0.02820732,63.26049978418207,1050.0,0.1
0.2851215,0.02856997,63.48076646331086,1050.0,0.1
0.2895735,0.02901517,63.70985655068586,1050.0,0.1
0.293588,0.02941662,63.93612610484873,1050.0,0.1
0.2980994,0.02986776,64.16983022852676,1050.0,0.1
0.3022821,0.03028603,64.3885695927048,1050.0,0.1
0.3070727,0.03076509,64.60659165875404,1050.0,0.1
0.3107085,0.03112867,64.82481788954951,1050.0,0.1
0.3150615,0.03156397,65.03099378116691,1050.0,0.1
0.31936180000000003,0.031994,65.24230504703436,1050.0,0.1
0.32427110000000003,0.03248493,65.43858309520859,1050.0,0.1
0.32896179999999997,0.032954,65.64147668102298,1050.0,0.1
0.3331016,0.03336798,65.86622350601542,1050.0,0.1
0.33740960000000003,0.03379878,66.09014928972374,1050.0,0.1
0.3411671,0.03417453,66.3196676424586,1050.0,0.1
0.3464184,0.03469966,66.55013226920103,1050.0,0.1
0.3496263,0.03502045,66.77221931723511,1050.0,0.1
0.3547153,0.03552935,66.97368773909875,1050.0,0.1
0.35870100000000005,0.03592792,67.17122916156089,1050.0,0.1
0.3635737,0.03641519,67.34037680346997,1050.0,0.1
0.36711910000000003,0.03676973,67.51888422600027,1050.0,0.1
0.37266099999999996,0.03732392,67.71065476999269,1050.0,0.1
0.37715319999999997,0.03777314,67.89316992881845,1050.0,0.1
0.3805923,0.03811705,68.08716279781845,1050.0,0.1
0.38591939999999997,0.03864976,68.27657347353436,1050.0,0.1
0.3895288,0.0390107,68.4673445793298,1050.0,0.1
0.3939725,0.03945507,68.64455498237147,1050.0,0.1
0.3980842,0.03986624,68.84613948145102,1050.0,0.1
0.4029209,0.04034991,69.02598986376164,1050.0,0.1
0.4061461,0.04067243,69.21781880685255,1050.0,0.1
0.4109305,0.04115087,69.39484457223135,1050.0,0.1
0.41532840000000004,0.04159066,69.57362571143968,1050.0,0.1
0.4203957,0.04209739,69.7414051017427,1050.0,0.1
0.4248531,0.04254313,69.91135774562908,1050.0,0.1
0.42864359999999996,0.04292218,70.0747250628715,1050.0,0.1
0.4334951,0.04340733,70.23216692115179,1050.0,0.1
0.4372878,0.0437866,70.41872046437148,1050.0,0.1
0.4418092,0.04423874,70.59517200609497,1050.0,0.1
0.4452142,0.04457924,70.77272730119343,1050.0,0.1
0.4501292,0.04507074,70.93428300228057,1050.0,0.1
0.45370639999999995,0.04542846,71.10354098904952,1050.0,0.1
0.4590171,0.04595953,71.26457559380329,1050.0,0.1
0.4623169,0.04628951,71.43737686892453,1050.0,0.1
0.4673525,0.04679307,71.59305634052302,1050.0,0.1
0.4722784,0.04728566,71.75673452696998,1050.0,0.1
0.47597470000000003,0.04765529,71.93552909970103,1050.0,0.1
0.4805126,0.04810908,72.10971248319346,1050.0,0.1
0.4839318,0.048451,72.26981156548891,1050.0,0.1
0.48897820000000003,0.04895564,72.42253818606848,1050.0,0.1
0.49268069999999997,0.04932589,72.58076448735257,1050.0,0.1
0.4979554,0.04985336,72.7323014084662,1050.0,0.1
0.5013248,0.0501903,72.89409789512908,1050.0,0.1
0.5063801,0.05069583,73.04367987008364,1050.0,0.1
0.5113821,0.05119603,73.20809983949272,1050.0,0.1
0.5147539999999999,0.05153322,73.37622764256469,1050.0,0.1
0.5199855999999999,0.05205638,73.53176605419726,1050.0,0.1
0.5236427,0.05242209,73.68577051520484,1050.0,0.1
0.5282591,0.05288373,73.84347103893968,1050.0,0.1
0.5319762,0.05325544,73.99383463779952,1050.0,0.1
0.5370469,0.05376251,74.13039946996243,1050.0,0.1
0.5418385,0.05424167,74.27912540437529,1050.0,0.1
0.5455036,0.05460818,74.41772621810635,1050.0,0.1
0.5503562,0.05509344,74.56591726327304,1050.0,0.1
0.5541375,0.05547157,74.7025878810571,1050.0,0.1
0.558655,0.05592332,74.83228816863287,1050.0,0.1
0.5624965,0.05630747,74.96266843504576,1050.0,0.1
0.5673564,0.05679346,75.0933071703109,1050.0,0.1
0.5716532,0.05722314,75.21965447598137,1050.0,0.1
0.5757825,0.05763607,75.34835681001925,1050.0,0.1
0.5796868000000001,0.0580265,75.48179208539801,1050.0,0.1
0.5841586,0.05847368,75.60770406365181,1050.0,0.1
0.5878403,0.05884185,75.73437310651924,1050.0,0.1
0.5927125,0.05932907,75.85336260580331,1050.0,0.1
0.5965108,0.0597089,75.97695158142453,1050.0,0.1
0.6015008000000001,0.0602079,76.10153128897,1050.0,0.1
0.6063797,0.06069579,76.22804142932227,1050.0,0.1
0.6099559,0.06105341,76.36256692846243,1050.0,0.1
0.6147825,0.06153607,76.5050759728677,1050.0,0.1
0.6188722,0.06194504,76.63339629650031,1050.0,0.1
0.6237031,0.06242813,76.76433713449651,1050.0,0.1
0.6264893,0.06270675,76.8937810215988,1050.0,0.1
0.6318351,0.06324133,77.02815437418968,1050.0,0.1
0.6359328,0.0636511,77.15773336650028,1050.0,0.1
0.6406580000000001,0.06412362,77.2774886523412,1050.0,0.1
0.6457265,0.06463047,77.40981830750788,1050.0,0.1
0.6488613,0.06494395,77.54244706435259,1050.0,0.1
0.6539341,0.06545123,77.67250543401546,1050.0,0.1
0.6573565,0.06579347,77.78589126108743,1050.0,0.1
0.6630617,0.06636399,77.90052847978819,1050.0,0.1
0.6659722,0.06665504,78.01139375226924,1050.0,0.1
0.6715688999999999,0.06721471,78.12679733534878,1050.0,0.1
0.6752252,0.06758034,78.23643522834877,1050.0,0.1
0.6799122000000001,0.06804904,78.34898632806848,1050.0,0.1
0.6850586,0.06856368,78.46911679725409,1050.0,0.1
0.6885484,0.06891266,78.58795796368591,1050.0,0.1
0.6934121,0.06939903,78.70442182751545,1050.0,0.1
0.6972489,0.06978271,78.81172695462153,1050.0,0.1
0.7022316000000001,0.07028098,78.92216142001924,1050.0,0.1
0.7059569,0.07065351,79.0323010999132,1050.0,0.1
0.7107152,0.07112934,79.14817012443214,1050.0,0.1
0.7145007999999999,0.0715079,79.25539459968593,1050.0,0.1
0.7187464,0.07193246,79.36519960272001,1050.0,0.1
0.7225919999999999,0.07231702,79.4620460104776,1050.0,0.1
0.7275884,0.07281666,79.55976853361017,1050.0,0.1
0.7328743999999999,0.07334526,79.65485827579955,1050.0,0.1
0.7360936,0.07366718,79.7470485807579,1050.0,0.1
0.7412108000000001,0.0741789,79.85151886802684,1050.0,0.1
0.7451230999999999,0.07457013,79.96467650387532,1050.0,0.1
0.7494972,0.07500754,80.07231643665561,1050.0,0.1
0.7534699,0.07540481,80.175979569595,1050.0,0.1
0.7579629,0.07585411,80.2867082354397,1050.0,0.1
0.7630341,0.07636123,80.39004328707607,1050.0,0.1
0.7665513,0.07671295,80.4911242370988,1050.0,0.1
0.7722619,0.07728401,80.5832554933223,1050.0,0.1
0.7754355,0.07760137,80.68250692803441,1050.0,0.1
0.7803427000000001,0.07809209,80.783014148042,1050.0,0.1
0.7839816,0.07845598,80.89505724851169,1050.0,0.1
0.7889503999999999,0.07895286,80.9988396168185,1050.0,0.1
0.7924766,0.07930548,81.10706390860638,1050.0,0.1
0.7980863,0.07986645,81.2120874677882,1050.0,0.1
0.8013264999999999,0.08019047,81.3115673885079,1050.0,0.1
0.8063613,0.08069395,81.40450446737154,1050.0,0.1
0.8112837,0.08118619,81.48994755593972,1050.0,0.1
0.8147603999999999,0.08153386,81.59236126817837,1050.0,0.1
0.8196283,0.08202065,81.69042642207987,1050.0,0.1
0.8229917,0.08235699,81.78882321118216,1050.0,0.1
0.8284437,0.08290219,81.88473530423516,1050.0,0.1
0.8315199,0.08320981,81.9821722927238,1050.0,0.1
0.837558,0.08381362,82.07189400892456,1050.0,0.1
0.8406361,0.08412143,82.16342415864425,1050.0,0.1
0.8458082,0.08463864,82.25373839654577,1050.0,0.1
0.8490051999999999,0.08495834,82.34363474084502,1050.0,0.1
0.853192,0.08537702,82.4390507872617,1050.0,0.1
0.8590111,0.08595893,82.52667488361396,1050.0,0.1
0.8627364999999999,0.08633147,82.62018835831472,1050.0,0.1
0.8679768,0.0868555,82.70236671408746,1050.0,0.1
0.8708908,0.0871469,82.78298535898138,1050.0,0.1
0.8760775,0.08766557,82.86102071386395,1050.0,0.1
0.8795767999999999,0.0880155,82.94949332312534,1050.0,0.1
0.8845353,0.08851135,83.03276975433744,1050.0,0.1
0.888562,0.08891402,83.11134782693216,1050.0,0.1
0.8934081,0.08939863,83.18444434177684,1050.0,0.1
0.8983734999999999,0.08989517,83.26254950211016,1050.0,0.1
0.9021137,0.09026919,83.34989279352304,1050.0,0.1
0.9069071,0.09074853,83.42747380848895,1050.0,0.1
0.9104753,0.09110535,83.51105088424653,1050.0,0.1
0.9153319999999999,0.09159102,83.59828259218973,1050.0,0.1
0.9184351000000001,0.09190133,83.6771799096367,1050.0,0.1
0.9239404,0.09245186,83.74922820116701,1050.0,0.1
0.927689,0.09282672,83.83445832563669,1050.0,0.1
0.9325540999999999,0.09331323,83.91841068911395,1050.0,0.1
0.9367188,0.0937297,84.00616350275413,1050.0,0.1
0.9411181000000001,0.09416963,84.10067969336396,1050.0,0.1
0.9464007000000001,0.09469789,84.20205679324656,1050.0,0.1
0.9495135,0.09500917,84.28774423722004,1050.0,0.1
0.9545650999999999,0.09551433,84.37471338349654,1050.0,0.1
0.9580326,0.09586108,84.45177735732231,1050.0,0.1
0.9633825,0.09639607,84.53194916683364,1050.0,0.1
0.9665590000000001,0.09671372,84.61218596860638,1050.0,0.1
0.9719729,0.09725511,84.68973014152685,1050.0,0.1
0.9752689999999999,0.09758472,84.77280102135259,1050.0,0.1
0.9806887,0.09812669,84.85368216555334,1050.0,0.1
0.9841057,0.09846839,84.94603651858745,1050.0,0.1
0.9894706999999999,0.09900489,85.02035876937154,1050.0,0.1
0.9944243999999999,0.09950026,85.09754899226547,1050.0,0.1
0.997729,0.09983072,85.17908536652685,1050.0,0.1
1.0030414999999997,0.10036197,85.25339520270487,1050.0,0.1
1.0059941,0.10065723,85.32945563346246,1050.0,0.1
1.0112512999999999,0.10118295,85.40481224482987,1050.0,0.1
1.0152120999999998,0.10157903,85.491789044542,1050.0,0.1
1.0191734,0.10197516,85.57285101650032,1050.0,0.1
1.0237287,0.10243069,85.65111583395866,1050.0,0.1
1.0288777999999998,0.1029456,85.7268971560458,1050.0,0.1
1.0326660999999997,0.10332443,85.79717606039806,1050.0,0.1
1.0370500999999999,0.10376283,85.85939209359505,1050.0,0.1
1.0421460999999999,0.10427243,85.91778696148516,1050.0,0.1
1.0458216999999999,0.10463999,85.98506663843214,1050.0,0.1
1.0504480999999999,0.10510263,86.04376499807229,1050.0,0.1
1.0546021999999997,0.10551804,86.1101576333791,1050.0,0.1
1.0593503999999998,0.10599286,86.17220469538292,1050.0,0.1
1.0635081999999998,0.10640864,86.2387951288261,1050.0,0.1
1.0676077,0.10681859,86.30731220327306,1050.0,0.1
1.0715308,0.1072109,86.37462479336016,1050.0,0.1
1.0770019,0.10775801,86.44277728212535,1050.0,0.1
1.0801545,0.10807327,86.5213017854208,1050.0,0.1
1.0851544999999998,0.10857327,86.59362672309882,1050.0,0.1
1.0896206999999998,0.10901989,86.65798203086398,1050.0,0.1
1.0934331,0.10940113,86.7259949245647,1050.0,0.1
1.0978427999999998,0.1098421,86.78358475360642,1050.0,0.1
1.1025524999999998,0.11031307,86.84313516331473,1050.0,0.1
1.1073245999999999,0.11079028,86.90596729891321,1050.0,0.1
1.1113224999999998,0.11119007,86.96995227668972,1050.0,0.1
1.1155611999999997,0.11161394,87.03834326184882,1050.0,0.1
1.1191452999999998,0.11197235,87.11802570709884,1050.0,0.1
1.1246424999999998,0.11252207,87.18452221239049,1050.0,0.1
1.1288869,0.11294651,87.25633209118217,1050.0,0.1
1.1328341,0.11334123,87.32534543305336,1050.0,0.1
1.1377395,0.11383177,87.38746577595867,1050.0,0.1
1.1418694999999999,0.11424477,87.45461312645111,1050.0,0.1
1.1464812,0.11470594,87.52684265586399,1050.0,0.1
1.1500751999999999,0.11506534,87.59040303755337,1050.0,0.1
1.1553494,0.11559276,87.65657586550411,1050.0,0.1
1.1589478,0.1159526,87.72829313030337,1050.0,0.1
1.1638063999999997,0.11643846,87.79679364006095,1050.0,0.1
1.1673471999999998,0.11679254,87.86585473453445,1050.0,0.1
1.1719705999999999,0.11725488,87.93201277520869,1050.0,0.1
1.1776768999999998,0.11782551,87.99223052883369,1050.0,0.1
1.1810414999999999,0.11816197,88.05469362711018,1050.0,0.1
1.1860313999999998,0.11866096,88.11527935892838,1050.0,0.1
1.1900022999999997,0.11905805,88.15549349281473,1050.0,0.1
1.1942734,0.11948516,88.20955767132232,1050.0,0.1
1.1983073999999998,0.11988856,88.26266901318216,1050.0,0.1
1.2033059,0.12038841,88.32030973032612,1050.0,0.1
1.2069803,0.12075585,88.37952024233368,1050.0,0.1
1.2116828999999998,0.12122611,88.43771688584124,1050.0,0.1
1.2154213999999999,0.12159996,88.49279940163291,1050.0,0.1
1.2198253,0.12204035,88.55430518443595,1050.0,0.1
1.2251362999999997,0.12257145,88.61328231662156,1050.0,0.1
1.2290006999999998,0.12295789,88.65876386864049,1050.0,0.1
1.2340145999999999,0.12345928,88.7157704013943,1050.0,0.1
1.2381845999999999,0.12387628,88.7722738041746,1050.0,0.1
1.2425985999999998,0.12431768,88.83275743196246,1050.0,0.1
1.2463486,0.12469268,88.88618866514048,1050.0,0.1
1.2517349,0.12523131,88.93857358190564,1050.0,0.1
1.2550032,0.12555814,88.9878820499852,1050.0,0.1
1.2601514999999999,0.12607297,89.04835714409883,1050.0,0.1
1.2633021999999998,0.12638804,89.10717073289429,1050.0,0.1
1.2679701999999997,0.12685484,89.16308460693217,1050.0,0.1
1.2735498999999997,0.12741281,89.22755942222005,1050.0,0.1
1.2776147999999998,0.1278193,89.28436423321247,1050.0,0.1
1.2821677999999996,0.1282746,89.34431481353063,1050.0,0.1
1.2854473,0.12860255,89.40243092594731,1050.0,0.1
1.2904894999999998,0.12910677,89.46495856776927,1050.0,0.1
1.2943178,0.1294896,89.51056187782234,1050.0,0.1
1.2994863999999997,0.13000646,89.56638210796247,1050.0,0.1
1.3026495999999999,0.13032278,89.62217834914807,1050.0,0.1
1.3083705999999997,0.13089488,89.6830684979473,1050.0,0.1
1.3117190999999997,0.13122973,89.75794744797383,1050.0,0.1
1.3160435999999998,0.13166218,89.81848091112154,1050.0,0.1
1.3212837999999998,0.1321862,89.88255959472762,1050.0,0.1
1.3249424999999997,0.13255207,89.94108501200036,1050.0,0.1
1.3299430999999997,0.13305213,89.99682610549655,1050.0,0.1
1.3337271999999998,0.13343054,90.04460940887536,1050.0,0.1
1.3389767,0.13395549,90.09291310300415,1050.0,0.1
1.3418470999999998,0.13424253,90.13723055339429,1050.0,0.1
1.3474681999999998,0.13480464,90.18144650094732,1050.0,0.1
1.3509521999999998,0.13515304,90.23163516339051,1050.0,0.1
1.3559051999999998,0.13564834,90.27187823682611,1050.0,0.1
1.3604939999999999,0.13610722,90.3125410103299,1050.0,0.1
1.3644716999999997,0.13650499,90.35206118096626,1050.0,0.1
1.3693705999999999,0.13699488,90.3929474243337,1050.0,0.1
1.3729230999999997,0.13735013,90.44247177853445,1050.0,0.1
1.3784399,0.13790181,90.48441764385265,1050.0,0.1
1.3817499,0.13823281,90.52993666329958,1050.0,0.1
1.3866572999999998,0.13872355,90.57812272255337,1050.0,0.1
1.3908304999999999,0.13914087,90.62164758828824,1050.0,0.1
1.3943295999999998,0.13949078,90.65594506072385,1050.0,0.1
1.3987511,0.13993293,90.69763488082987,1050.0,0.1
1.4035436,0.14041218,90.7415595249208,1050.0,0.1
1.407908,0.14084862,90.79167950286778,1050.0,0.1
1.4122743999999998,0.14128526,90.8413065181708,1050.0,0.1
1.4168269999999998,0.14174052,90.88444936662914,1050.0,0.1
1.4211984,0.14217766,90.93502966243597,1050.0,0.1
1.4260005999999996,0.14265788,90.99137688812534,1050.0,0.1
1.4300667999999999,0.1430645,91.0461899400761,1050.0,0.1
1.4349979,0.14355761,91.08809852502688,1050.0,0.1
1.4383890999999998,0.14389673,91.13408955851173,1050.0,0.1
1.4433242,0.14439024,91.18527283207987,1050.0,0.1
1.4475823999999997,0.14481606,91.2398449695496,1050.0,0.1
1.4516574999999998,0.14522357,91.28790232622005,1050.0,0.1
1.4570941999999998,0.14576724,91.3345938098602,1050.0,0.1
1.4604304,0.14610086,91.38420278272763,1050.0,0.1
1.4655003,0.14660785,91.43303958072006,1050.0,0.1
1.4687778999999999,0.14693561,91.48467057167838,1050.0,0.1
1.4739134999999997,0.14744917,91.52706662597384,1050.0,0.1
1.4777523999999997,0.14783306,91.57231556259882,1050.0,0.1
1.4821493,0.14827275,91.61271395229203,1050.0,0.1
1.4864241999999999,0.14870024,91.66375352696248,1050.0,0.1
1.4908248999999998,0.14914031,91.70952613112534,1050.0,0.1
1.4951648999999998,0.14957431,91.75380100970492,1050.0,0.1
1.4998795999999996,0.15004578,91.80068507314049,1050.0,0.1
1.5047836999999997,0.15053619,91.83782270357234,1050.0,0.1
1.5085717999999997,0.150915,91.88317415785264,1050.0,0.1
1.5132927999999999,0.1513871,91.91944611993975,1050.0,0.1
1.5166477999999999,0.1517226,91.96208795343597,1050.0,0.1
1.5226169999999999,0.15231952,91.99809573536778,1050.0,0.1
1.5257269999999998,0.15263052,92.04043159739808,1050.0,0.1
1.5307057,0.15312839,92.07141102177312,1050.0,0.1
1.5342540999999998,0.15348323,92.11321565278445,1050.0,0.1
1.539112,0.15396902,92.15197490716325,1050.0,0.1
1.5433492999999998,0.15439275,92.18996229893975,1050.0,0.1
1.5482737,0.15488519,92.22571448607991,1050.0,0.1
1.5525148,0.1553093,92.26405160110642,1050.0,0.1
1.5568198,0.1557398,92.29677748790188,1050.0,0.1
1.5611266999999998,0.15617049,92.3263845617314,1050.0,0.1
1.5655603999999999,0.15661386,92.35212184111019,1050.0,0.1
1.5702464999999999,0.15708247,92.37923164067837,1050.0,0.1
1.5734965999999997,0.15740748,92.42203978375416,1050.0,0.1
1.5786862,0.15792644,92.45511520609885,1050.0,0.1
1.5828149999999999,0.15833932,92.49877788472384,1050.0,0.1
1.5875713,0.15881495,92.53438499360264,1050.0,0.1
1.5903253999999998,0.15909036,92.57656301728447,1050.0,0.1
1.5960878999999997,0.15966661,92.60972959382612,1050.0,0.1
1.6005371,0.16011153,92.65238533087536,1050.0,0.1
1.6044872999999997,0.16050655,92.68931892316323,1050.0,0.1
1.6091915999999997,0.16097698,92.72412729025035,1050.0,0.1
1.6130816999999997,0.16136599,92.76926968943975,1050.0,0.1
1.6179146,0.16184928,92.81283592493216,1050.0,0.1
1.6221854999999998,0.16227637,92.85600281986778,1050.0,0.1
1.6268981999999999,0.16274764,92.88442028525034,1050.0,0.1
1.6300408,0.1630619,92.91493228283748,1050.0,0.1
1.6352599999999997,0.16358382,92.95212844188293,1050.0,0.1
1.6390341,0.16396123,93.00002487301171,1050.0,0.1
1.6440069,0.16445851,93.03710016685643,1050.0,0.1
1.6489184999999997,0.16494967,93.06864423046628,1050.0,0.1
1.6529501999999998,0.16535284,93.10138181517839,1050.0,0.1
1.6576773999999999,0.16582556,93.14249441817083,1050.0,0.1
1.6615864,0.16621646,93.1764818922655,1050.0,0.1
1.6659385999999998,0.16665168,93.19981184180338,1050.0,0.1
1.6699770999999999,0.16705553,93.22569809478068,1050.0,0.1
1.6748376999999997,0.16754159,93.27173090580717,1050.0,0.1
1.6786906999999998,0.16792689,93.32111062400415,1050.0,0.1
1.6834928999999998,0.16840711,93.35861296407232,1050.0,0.1
1.6876024999999997,0.16881807,93.39673564059126,1050.0,0.1
1.6917764999999998,0.16923547,93.42761824456854,1050.0,0.1
1.6974710999999998,0.16980493,93.45860943662157,1050.0,0.1
1.7015852999999996,0.17021635,93.48649344303067,1050.0,0.1
1.7061457999999998,0.1706724,93.50936468559507,1050.0,0.1
1.7094403,0.17100185,93.52340158882615,1050.0,0.1
1.7150179999999997,0.17155962,93.55067859606474,1050.0,0.1
1.7184423999999998,0.17190206,93.57080470959507,1050.0,0.1
1.7233266,0.17239048,93.59678722500415,1050.0,0.1
1.7267539999999997,0.17273322,93.62792732187157,1050.0,0.1
1.7317693999999997,0.17323476,93.66610146662158,1050.0,0.1
1.7353268999999998,0.17359051,93.70544654344354,1050.0,0.1
1.7407286,0.17413068,93.73897325989051,1050.0,0.1
1.7449248999999998,0.17455031,93.76924654435645,1050.0,0.1
1.7486774999999999,0.17492557,93.78960577997384,1050.0,0.1
1.7541495999999999,0.17547278,93.80934704070113,1050.0,0.1
1.7574600999999999,0.17580383,93.8287063914511,1050.0,0.1
1.7620448,0.1762623,93.85133997850416,1050.0,0.1
1.7661869,0.17667651,93.87571580671626,1050.0,0.1
1.7707758999999998,0.17713541,93.91004823872007,1050.0,0.1
1.7743471999999998,0.17749254,93.94890034684884,1050.0,0.1
1.7796421999999998,0.17802204,93.98469228484507,1050.0,0.1
1.7847486999999997,0.17853269,94.02827510257234,1050.0,0.1
1.7879413999999998,0.17885196,94.07304929389431,1050.0,0.1
1.7929876999999999,0.17935659,94.11464565725795,1050.0,0.1
1.7970144,0.17975926,94.15808513221249,1050.0,0.1
1.8014893999999997,0.18020676,94.19124265689432,1050.0,0.1
1.8050082999999997,0.18055865,94.21937951950794,1050.0,0.1
1.8100631999999999,0.18106414,94.25034070593217,1050.0,0.1
1.8135838999999998,0.18141621,94.28241558797764,1050.0,0.1
1.8185794999999998,0.18191577,94.30304684059128,1050.0,0.1
1.8240911999999998,0.18246694,94.3273419511519,1050.0,0.1
1.8272964,0.18278746,94.36275958009126,1050.0,0.1
1.8322353,0.18328135,94.39669328929203,1050.0,0.1
1.8364053999999999,0.18369836,94.43416654114054,1050.0,0.1
1.8410914999999999,0.18416697,94.46476470831098,1050.0,0.1
1.8444306999999998,0.18450089,94.49037425701552,1050.0,0.1
1.8495055999999999,0.18500838,94.53654123729204,1050.0,0.1
1.8531689999999998,0.18537472,94.57135360926172,1050.0,0.1
1.8581845,0.18587627,94.59492453367085,1050.0,0.1
1.8621086999999996,0.18626869,94.62735784956477,1050.0,0.1
1.8666779999999998,0.18672562,94.65018294828826,1050.0,0.1
1.8718930999999999,0.18724713,94.66968437970114,1050.0,0.1
1.8757589,0.18763371,94.68461047227689,1050.0,0.1
1.8810426999999998,0.18816209,94.69800068190189,1050.0,0.1
1.8845245999999998,0.18851028,94.71063439614808,1050.0,0.1
1.8896850999999997,0.18902633,94.73487462423522,1050.0,0.1
1.8929765999999997,0.18935548,94.74751215034887,1050.0,0.1
1.8983976,0.18989758,94.7632449048337,1050.0,0.1
1.9020800999999998,0.19026583,94.78217429707993,1050.0,0.1
1.9071201999999998,0.19076984,94.79778474568977,1050.0,0.1
1.9105457999999997,0.1911124,94.82226833640188,1050.0,0.1
1.9153321999999997,0.19159104,94.83981302878826,1050.0,0.1
1.9187606999999998,0.19193389,94.8613083856746,1050.0,0.1
1.9232904999999998,0.19238687,94.88503585665947,1050.0,0.1
1.9284707999999997,0.1929049,94.91080354384506,1050.0,0.1
1.9326168999999997,0.19331951,94.93874269597767,1050.0,0.1
1.9374782999999998,0.19380565,94.97070605603066,1050.0,0.1
1.9410440999999998,0.19416223,94.99359077714054,1050.0,0.1
1.9463639,0.19469421,95.02665346831856,1050.0,0.1
1.9493483999999999,0.19499266,95.06014405411022,1050.0,0.1
1.9544123999999998,0.19549906,95.07830682533749,1050.0,0.1
1.9582445999999998,0.19588228,95.10714916231477,1050.0,0.1
1.9632485,0.19638267,95.13527704032614,1050.0,0.1
1.9667590999999998,0.19673373,95.16164951892081,1050.0,0.1
1.9717014999999998,0.19722797,95.1942425519284,1050.0,0.1
1.9769059999999998,0.19774842,95.21633343464053,1050.0,0.1
1.9800313999999999,0.19806096,95.24014712412537,1050.0,0.1
1.9850449999999997,0.19856232,95.26115311478446,1050.0,0.1
1.9892805,0.19898587,95.28707455560644,1050.0,0.1
1.9936471999999998,0.19942254,95.30350182132614,1050.0,0.1
1.9976249,0.19982031,95.33200676316324,1050.0,0.1
2.0026474999999997,0.20032257,95.35113767562538,1050.0,0.1
2.0061718999999996,0.20067501,95.37178919858748,1050.0,0.1
2.0110689999999996,0.20116472,95.39325085060264,1050.0,0.1
2.0162952999999995,0.20168735,95.40649740984887,1050.0,0.1
2.0197584999999996,0.20203367,95.42609091177688,1050.0,0.1
2.0245960999999997,0.20251743,95.44946633307234,1050.0,0.1
2.0285863999999996,0.20291646,95.47300061076174,1050.0,0.1
2.0338217999999997,0.20344,95.49913078054962,1050.0,0.1
2.0371599,0.20377381,95.53105306267084,1050.0,0.1
2.041876,0.20424542,95.55071366442083,1050.0,0.1
2.0462005999999997,0.20467788,95.57606781004965,1050.0,0.1
2.0507887,0.20513669,95.58601249136781,1050.0,0.1
2.0543964,0.20549746,95.597990984989,1050.0,0.1
2.0595136999999997,0.20600919,95.6027960481443,1050.0,0.1
2.0648305,0.20654087,95.61396474576175,1050.0,0.1
2.0682453999999995,0.20688236,95.6183054836443,1050.0,0.1
2.0732382,0.20738164,95.63189840842462,1050.0,0.1
2.0761956999999995,0.20767739,95.641371668436,1050.0,0.1
2.0815213999999997,0.20820996,95.65646075175793,1050.0,0.1
2.0847447999999997,0.2085323,95.6789842008943,1050.0,0.1
2.0905359,0.20911141,95.69837286829961,1050.0,0.1
2.0941567,0.20947349,95.71941806200039,1050.0,0.1
2.0987679999999997,0.20993462,95.7327123635534,1050.0,0.1
2.1025238999999996,0.21031021,95.7519144656178,1050.0,0.1
2.1070723,0.21076505,95.76930378834508,1050.0,0.1
2.1125464999999997,0.21131247,95.78345632987917,1050.0,0.1
2.1158455,0.21164237,95.79647765514052,1050.0,0.1
2.1211268,0.2121705,95.8149906057428,1050.0,0.1
2.1244286,0.21250068,95.84013623535266,1050.0,0.1
2.1299791,0.21305573,95.86444506226174,1050.0,0.1
2.1330851999999996,0.21336634,95.8851877391216,1050.0,0.1
2.1381767999999997,0.2138755,95.90380719613295,1050.0,0.1
2.1412861999999997,0.21418644,95.92198431260644,1050.0,0.1
2.1463819999999996,0.21469602,95.94305975999656,1050.0,0.1
2.1506857999999998,0.2151264,95.9565655372163,1050.0,0.1
2.1552561,0.21558343,95.97525190982235,1050.0,0.1
2.1604254,0.21610036,95.99628158943977,1050.0,0.1
2.1644037999999997,0.2164982,96.02151462076932,1050.0,0.1
2.1693121,0.21698903,96.04530441681477,1050.0,0.1
2.1728957999999996,0.2173474,96.064902366311,1050.0,0.1
2.1774104,0.21779886,96.07947590031856,1050.0,0.1
2.1815944999999997,0.21821727,96.10498848923903,1050.0,0.1
2.1863121999999997,0.21868904,96.11980038657613,1050.0,0.1
2.1901010999999997,0.21906793,96.1355061139322,1050.0,0.1
2.1946895,0.21952677,96.15266013679582,1050.0,0.1
2.1984157,0.21989939,96.16689918719734,1050.0,0.1
2.2034738999999997,0.22040521,96.17789493889053,1050.0,0.1
2.2086015,0.22091797,96.18835818526173,1050.0,0.1
2.2125323999999997,0.22131106,96.19770715235266,1050.0,0.1
2.2176644999999997,0.22182427,96.20633012287917,1050.0,0.1
2.2235331,0.22241113,96.2234792043072,1050.0,0.1
2.2274697999999997,0.2228048,96.2369149876519,1050.0,0.1
2.2322091,0.22327873,96.24882933935643,1050.0,0.1
2.2368838999999996,0.22374621,96.25242199450415,1050.0,0.1
2.2404249,0.22410031,96.25728894975417,1050.0,0.1
2.2460394999999997,0.22466177,96.25160573613674,1050.0,0.1
2.2493158999999996,0.22498941,96.24981028263294,1050.0,0.1
2.2543338,0.2254912,96.25195349262161,1050.0,0.1
2.2576129,0.22581911,96.26646947951932,1050.0,0.1
2.2637729999999996,0.22643512,96.27202772731478,1050.0,0.1
2.2664527,0.22670309,96.2807809000269,1050.0,0.1
2.2714114,0.22719896,96.28350240600797,1050.0,0.1
2.2752998,0.2275878,96.29521136470113,1050.0,0.1
2.2799948,0.2280573,96.31250752532233,1050.0,0.1
2.2836855,0.22842637,96.32669018578824,1050.0,0.1
2.2890561,0.22896343,96.33088565010644,1050.0,0.1
2.2930852999999995,0.22936635,96.33870957660643,1050.0,0.1
2.2981917999999997,0.229877,96.3509568897428,1050.0,0.1
2.3028307999999997,0.2303409,96.36744065931477,1050.0,0.1
2.3061931999999996,0.23067714,96.38217298279073,1050.0,0.1
2.3107678999999997,0.23113461,96.40983131469743,1050.0,0.1
2.3142004,0.23147786,96.44908861813617,1050.0,0.1
2.3200589,0.23206371,96.50260529766045,1050.0,0.1
2.3232928,0.2323871,96.57304175782377,1050.0,0.1