File: datasets/steel_spring/csv/BS2V-1200-0.1.csv
Time(s),Strain(%),Stress(MPa),Temp(C),SR(%/s)
0.0,6.08e-06,0.5112773898678679,1200.0,0.1
5.309999999999999e-05,1.139e-05,-0.03312420609139688,1200.0,0.1
0.0004277,4.885e-05,-0.054139797462512296,1200.0,0.1
0.0006421,7.029e-05,0.36626831362845613,1200.0,0.1
0.0006952,7.56e-05,1.1461378250554417,1200.0,0.1
0.0012840999999999998,0.00013449,2.458204115526524,1200.0,0.1
0.0023539999999999998,0.00024148,3.70533569993562,1200.0,0.1
0.0032105999999999997,0.00032714,5.15661327465343,1200.0,0.1
0.0045492,0.000461,6.587599871706468,1200.0,0.1
0.0050843,0.00051451,7.916115212009501,1200.0,0.1
0.006476299999999999,0.00065371,9.181018011541704,1200.0,0.1
0.0070114999999999995,0.00070723,10.626862696795493,1200.0,0.1
0.008082,0.00081428,12.077153924458377,1200.0,0.1
0.0095286,0.00095894,13.49672032773869,1200.0,0.1
0.010921199999999999,0.0010982,14.897922056161052,1200.0,0.1
0.011725300000000001,0.00117861,16.286203740644,1200.0,0.1
0.013011,0.00130718,17.585474251130737,1200.0,0.1
0.0143499,0.00144107,18.645311427988688,1200.0,0.1
0.0163331,0.00163939,19.472060962831492,1200.0,0.1
0.0192809,0.00193417,20.15243763014588,1200.0,0.1
0.0194415,0.00195023,20.77546035899626,1200.0,0.1
0.0220691,0.00221299,21.27028048561559,1200.0,0.1
0.0239454,0.00240062,21.69835906460046,1200.0,0.1
0.026789,0.00268498,22.1029188074092,1200.0,0.1
0.029096099999999996,0.00291569,22.52847438605883,1200.0,0.1
0.0302232,0.0030284,22.905452048308813,1200.0,0.1
0.0325311,0.00325919,23.2286849938126,1200.0,0.1
0.0345711,0.00346319,23.515189573193275,1200.0,0.1
0.0369342,0.0036995,23.789489588640247,1200.0,0.1
0.0381698,0.00382306,24.101422695702734,1200.0,0.1
0.040532799999999994,0.00405936,24.389199252428114,1200.0,0.1
0.043326899999999995,0.00433877,24.651427840494417,1200.0,0.1
0.04574539999999999,0.00458062,24.896537816430033,1200.0,0.1
0.048379899999999997,0.00484407,25.15676741118003,1200.0,0.1
0.04945479999999999,0.00495156,25.393569486356167,1200.0,0.1
0.051445,0.00515058,25.616790697645943,1200.0,0.1
0.0539732,0.0054034,25.832914601092924,1200.0,0.1
0.0561254,0.00561862,26.052738852138383,1200.0,0.1
0.057739099999999995,0.00577999,26.30445363029556,1200.0,0.1
0.060376799999999994,0.00604376,26.526813860206524,1200.0,0.1
0.063122,0.00631828,26.730064626388337,1200.0,0.1
0.06549189999999999,0.00655527,26.932365337153485,1200.0,0.1
0.06780879999999999,0.00678696,27.15285163175763,1200.0,0.1
0.0688859,0.00689467,27.354078745687566,1200.0,0.1
0.07136409999999999,0.00714249,27.53787646939022,1200.0,0.1
0.0736815,0.00737423,27.72514924331638,1200.0,0.1
0.0762163,0.00762771,27.91403680870844,1200.0,0.1
0.07740129999999999,0.00774621,28.110527013825852,1200.0,0.1
0.08004409999999999,0.00801049,28.284800565428135,1200.0,0.1
0.0827957,0.00828565,28.440256409750113,1200.0,0.1
0.084738,0.00847988,28.596226554161095,1200.0,0.1
0.08619469999999999,0.00862555,28.764706674458413,1200.0,0.1
0.0888398,0.00889006,28.91825447371596,1200.0,0.1
0.09110769999999999,0.00911685,29.05776342748868,1200.0,0.1
0.09353779999999999,0.00935986,29.203367475729213,1200.0,0.1
0.09575209999999999,0.00958129,29.35695933244324,1200.0,0.1
0.0973732,0.0097434,29.498358314358036,1200.0,0.1
0.09953479999999999,0.00995956,29.629516729903536,1200.0,0.1
0.10266919999999999,0.010273,29.75333598296226,1200.0,0.1
0.10499379999999998,0.01050546,29.872648395500136,1200.0,0.1
0.1066711,0.01067319,30.002976526002005,1200.0,0.1
0.10878,0.01088408,30.132327385081553,1200.0,0.1
0.111106,0.01111668,30.253185550960342,1200.0,0.1
0.1136494,0.01137102,30.36141677714595,1200.0,0.1
0.116085,0.01161458,30.476828426642147,1200.0,0.1
0.11760099999999998,0.01176618,30.594932641528494,1200.0,0.1
0.11971219999999999,0.0119773,30.704174345405367,1200.0,0.1
0.12252849999999998,0.01225893,30.812352057645857,1200.0,0.1
0.1246417,0.01247025,30.91689393489771,1200.0,0.1
0.1262127,0.01262735,31.029305712481044,1200.0,0.1
0.1280559,0.01281167,31.137386336882603,1200.0,0.1
0.130494,0.01305548,31.238256597960337,1200.0,0.1
0.1326627,0.01327235,31.326542999380848,1200.0,0.1
0.13461569999999998,0.01346765,31.426462935036195,1200.0,0.1
0.1366218,0.01366826,31.530819242221824,1200.0,0.1
0.1392265,0.01392873,31.62713619750211,1200.0,0.1
0.1415597,0.01416205,31.7309488647805,1200.0,0.1
0.1442734,0.01443342,31.8368985109661,1200.0,0.1
0.14530479999999998,0.01453656,31.94724136564412,1200.0,0.1
0.1483998,0.01484606,32.05098650453994,1200.0,0.1
0.15079,0.01508508,32.152065249617564,1200.0,0.1
0.1525278,0.01525886,32.24826810897548,1200.0,0.1
0.15519059999999998,0.01552514,32.35233199286938,1200.0,0.1
0.1564409,0.01565017,32.43452759281445,1200.0,0.1
0.1583975,0.01584583,32.504895108592855,1200.0,0.1
0.1610608,0.01611216,32.567468250382625,1200.0,0.1
0.16323619999999997,0.0163297,32.62656690908344,1200.0,0.1
0.1645414,0.01646022,32.67908757257968,1200.0,0.1
0.16704439999999998,0.01671052,32.72895063753614,1200.0,0.1
0.16933009999999998,0.01693909,32.77763518945853,1200.0,0.1
0.1717243,0.01717851,32.85093261828431,1200.0,0.1
0.17270449999999998,0.01727653,32.943642020199086,1200.0,0.1
0.1749365,0.01749973,33.03394743457787,1200.0,0.1
0.1770057,0.01770665,33.129449502909246,1200.0,0.1
0.1792387,0.01792995,33.217809055323954,1200.0,0.1
0.180601,0.01806618,33.32459302427092,1200.0,0.1
0.1829439,0.01830047,33.42017968058914,1200.0,0.1
0.1858872,0.0185948,33.503940659924346,1200.0,0.1
0.18806799999999999,0.01881288,33.58362535082965,1200.0,0.1
0.1904125,0.01904733,33.67924710246983,1200.0,0.1
0.19232169999999998,0.01923825,33.772274807028566,1200.0,0.1
0.19417700000000002,0.01942378,33.866074946899815,1200.0,0.1
0.1967406,0.01968014,33.960760056755895,1200.0,0.1
0.1987603,0.01988211,34.04916023602293,1200.0,0.1
0.2002337,0.02002945,34.16594462099836,1200.0,0.1
0.20241759999999998,0.02024784,34.27066201238667,1200.0,0.1
0.2040009,0.02040617,34.35879645747757,1200.0,0.1
0.20695039999999998,0.02070112,34.45398232241125,1200.0,0.1
0.2095735,0.02096343,34.54897661371049,1200.0,0.1
0.2105022,0.0210563,34.63248586958928,1200.0,0.1
0.21361739999999999,0.02136782,34.7199015574094,1200.0,0.1
0.2154757,0.02155365,34.801382745687874,1200.0,0.1
0.2184286,0.02184894,34.89720337248323,1200.0,0.1
0.2188658,0.02189266,34.99575984581077,1200.0,0.1
0.2217654,0.02218262,35.09417563731256,1200.0,0.1
0.2236253,0.02236861,35.18008040357005,1200.0,0.1
0.22592389999999998,0.02259847,35.267736694096534,1200.0,0.1
0.22669019999999998,0.0226751,35.358162602946884,1200.0,0.1
0.23139809999999997,0.02314589,35.44837282314194,1200.0,0.1
0.2328773,0.02329381,35.54192189453787,1200.0,0.1
0.2355062,0.0235567,35.63390696775393,1200.0,0.1
0.23736859999999999,0.02374294,35.729041982142206,1200.0,0.1
0.23890299999999998,0.02389638,35.827434841755796,1200.0,0.1
0.2412596,0.02413204,35.92387260755696,1200.0,0.1
0.24367209999999997,0.02437329,36.01201064600203,1200.0,0.1
0.246194,0.02462548,36.09250766431454,1200.0,0.1
0.24816819999999998,0.0248229,36.18856170669896,1200.0,0.1
0.2497043,0.02497651,36.27577096019319,1200.0,0.1
0.2521188999999999,0.02521797,36.357535068225346,1200.0,0.1
0.25436859999999994,0.02544294,36.43670441419887,1200.0,0.1
0.25738749999999994,0.02574483,36.521286531280346,1200.0,0.1
0.25843059999999995,0.02584914,36.622068852488695,1200.0,0.1
0.26095729999999995,0.02610181,36.716038399038055,1200.0,0.1
0.26326449999999996,0.02633253,36.810397022473715,1200.0,0.1
0.26595589999999997,0.02660167,36.914036818712255,1200.0,0.1
0.26831889999999997,0.02683797,37.02612443479547,1200.0,0.1
0.26952879999999996,0.02695896,37.119812576456404,1200.0,0.1
0.27205719999999994,0.0272118,37.21188417318555,1200.0,0.1
0.27420229999999995,0.02742631,37.2956024295832,1200.0,0.1
0.2768967,0.02769575,37.385530908075694,1200.0,0.1
0.27849279999999993,0.02785536,37.465698399348554,1200.0,0.1
0.28014279999999997,0.02802036,37.54254954399072,1200.0,0.1
0.28267489999999995,0.02827357,37.61330281319166,1200.0,0.1
0.28559209999999996,0.02856529,37.699261151761945,1200.0,0.1
0.28707939999999993,0.02871402,37.790506086582035,1200.0,0.1
0.28972259999999994,0.02897834,37.873521725547796,1200.0,0.1
0.2924768,0.02925376,37.97093198900029,1200.0,0.1
0.29457059999999996,0.02946314,38.064445695842885,1200.0,0.1
0.29749119999999996,0.0297552,38.159599162121076,1200.0,0.1
0.29820839999999993,0.02982692,38.24285764570427,1200.0,0.1
0.30013819999999997,0.0300199,38.31707123162271,1200.0,0.1
0.30333619999999994,0.0303397,38.38604212791247,1200.0,0.1
0.30570889999999995,0.03057697,38.462728505528226,1200.0,0.1
0.3067561,0.03068169,38.544959375994296,1200.0,0.1
0.3091844999999999,0.03092453,38.60710814440339,1200.0,0.1
0.3116134,0.03116742,38.69188125326707,1200.0,0.1
0.31437269999999995,0.03144335,38.79165969738079,1200.0,0.1
0.31536699999999995,0.03154278,38.897698913714166,1200.0,0.1
0.3181282999999999,0.03181891,38.98857061704748,1200.0,0.1
0.31995139999999994,0.03200122,39.066737752647875,1200.0,0.1
0.3227698,0.03228306,39.14160805206073,1200.0,0.1
0.32553309999999996,0.03255939,39.2128473520115,1200.0,0.1
0.3268597,0.03269205,39.27696394084117,1200.0,0.1
0.32912729999999996,0.03291881,39.32836226521242,1200.0,0.1
0.33178169999999996,0.03318425,39.39841651183549,1200.0,0.1
0.33404939999999994,0.03341102,39.48741967236003,1200.0,0.1
0.3363176,0.03363784,39.58105710570666,1200.0,0.1
0.33781239999999996,0.03378732,39.665182131267336,1200.0,0.1
0.3404690999999999,0.03405299,39.741249359812876,1200.0,0.1
0.3426837999999999,0.03427446,39.81872355123332,1200.0,0.1
0.34556359999999997,0.03456244,39.900686098066615,1200.0,0.1
0.34650499999999995,0.03465658,39.9805097448241,1200.0,0.1
0.3493859999999999,0.03494468,40.0539304208372,1200.0,0.1
0.35176869999999993,0.03518295,40.12230844874428,1200.0,0.1
0.35387589999999997,0.03539367,40.20600300846211,1200.0,0.1
0.35648079999999993,0.03565416,40.28746133919509,1200.0,0.1
0.3575903999999999,0.03576512,40.35922739821983,1200.0,0.1
0.3596417999999999,0.03597026,40.42459285121991,1200.0,0.1
0.3627486999999999,0.03628095,40.490074340674404,1200.0,0.1
0.3650795,0.03651403,40.57156440572742,1200.0,0.1
0.36624509999999993,0.03663059,40.661816336420536,1200.0,0.1
0.36890929999999994,0.03689701,40.736252683352326,1200.0,0.1
0.37146399999999996,0.03715248,40.80969580720089,1200.0,0.1
0.3736845999999999,0.03737454,40.889716354149975,1200.0,0.1
0.375185,0.03752458,40.964549013263536,1200.0,0.1
0.37790779999999996,0.03779686,41.02668550376714,1200.0,0.1
0.3798520999999999,0.03799129,41.08835952251695,1200.0,0.1
0.3830204,0.03830812,41.14670087856422,1200.0,0.1
0.3852997999999999,0.03853606,41.231980726497895,1200.0,0.1
0.38574529999999996,0.03858061,41.32471749192215,1200.0,0.1
0.38863759999999997,0.03886984,41.40525864579347,1200.0,0.1
0.39180869999999995,0.03918695,41.48228252090741,1200.0,0.1
0.39342229999999995,0.03934831,41.55411332770489,1200.0,0.1
0.39548209999999995,0.03955429,41.626113684769145,1200.0,0.1
0.3975975,0.03976583,41.68961095909464,1200.0,0.1
0.4001033,0.04001641,41.748570672317996,1200.0,0.1
0.40266489999999994,0.04027257,41.821386410785706,1200.0,0.1
0.40338969999999996,0.04034505,41.908185766876564,1200.0,0.1
0.4062307,0.04062915,41.98568332759618,1200.0,0.1
0.40851639999999995,0.04085772,42.04461725551485,1200.0,0.1
0.41108019999999995,0.0411141,42.09995261959644,1200.0,0.1
0.41342229999999996,0.04134831,42.157191687602214,1200.0,0.1
0.41470529999999994,0.04147661,42.216931480950635,1200.0,0.1
0.4174942,0.0417555,42.26227713730291,1200.0,0.1
0.41989309999999996,0.04199539,42.30329133254725,1200.0,0.1
0.422181,0.04222418,42.36760272179908,1200.0,0.1
0.42374409999999996,0.04238049,42.4405337826212,1200.0,0.1
0.42603369999999996,0.04260945,42.509014120644174,1200.0,0.1
0.42849019999999993,0.0428551,42.56331141186972,1200.0,0.1
0.4308354,0.04308962,42.62084127581678,1200.0,0.1
0.43368529999999994,0.04337461,42.68455368783958,1200.0,0.1
0.4346914999999999,0.04347523,42.74546440249492,1200.0,0.1
0.4370956,0.04371564,42.797437539008044,1200.0,0.1
0.43966679999999997,0.04397276,42.84959114718398,1200.0,0.1
0.44151209999999996,0.04415729,42.912293988267066,1200.0,0.1
0.4428541999999999,0.0442915,42.98852147905676,1200.0,0.1
0.44520279999999995,0.04452636,43.05568108414783,1200.0,0.1
0.44833639999999997,0.04483972,43.10346550600956,1200.0,0.1
0.4506316999999999,0.04506925,43.152693879517,1200.0,0.1
0.45348619999999995,0.0453547,43.204300564214165,1200.0,0.1
0.45432569999999994,0.04543865,43.247832693479744,1200.0,0.1
0.45690229999999993,0.04569631,43.28878991969408,1200.0,0.1
0.45897419999999994,0.0459035,43.333468785209334,1200.0,0.1
0.4622244,0.04622852,43.3818258937909,1200.0,0.1
0.4626167,0.04626775,43.45122500637029,1200.0,0.1
0.4653634,0.04654242,43.50654667982249,1200.0,0.1
0.46799749999999996,0.04680583,43.551917717683686,1200.0,0.1
0.47035299999999997,0.04704138,43.60016131213767,1200.0,0.1
0.47332539999999995,0.04733862,43.65441109349,1200.0,0.1
0.4744481,0.04745089,43.701792671539806,1200.0,0.1
0.4764121999999999,0.0476473,43.7420476089511,1200.0,0.1
0.47893779999999997,0.04789986,43.78770463697598,1200.0,0.1
0.4811835,0.04812443,43.83762613816176,1200.0,0.1
0.48281149999999995,0.04828723,43.898467701718424,1200.0,0.1
0.4847214999999999,0.04847823,43.955089806682025,1200.0,0.1
0.48758579999999996,0.04876466,44.01148020522507,1200.0,0.1
0.4900017,0.04900625,44.06273062895579,1200.0,0.1
0.4925307,0.04925915,44.11870424758284,1200.0,0.1
0.4932050999999999,0.04932659,44.17755497049619,1200.0,0.1
0.4961843999999999,0.04962452,44.22730880095674,1200.0,0.1
0.49854649999999995,0.04986073,44.27723005366127,1200.0,0.1
0.5007397,0.05008005,44.33335055794918,1200.0,0.1
0.5024847,0.05025455,44.39532571125609,1200.0,0.1
0.5040035,0.05040643,44.45673460144763,1200.0,0.1
0.5069302,0.0506991,44.51326112043075,1200.0,0.1
0.5098577,0.05099185,44.566470293820956,1200.0,0.1
0.5109275,0.05109883,44.61742926755579,1200.0,0.1
0.5132372000000001,0.0513298,44.68222483677174,1200.0,0.1
0.5154337,0.05154945,44.72632702620739,1200.0,0.1
0.5184196,0.05184804,44.77532740578854,1200.0,0.1
0.520731,0.05207918,44.833692043610405,1200.0,0.1
0.5228731,0.05229339,44.90232514351019,1200.0,0.1
0.5242262,0.0524287,44.970589202976186,1200.0,0.1
0.5266509,0.05267117,45.030770643302006,1200.0,0.1
0.5294152,0.0529476,45.088199733707135,1200.0,0.1
0.5321233,0.05321841,45.14810222869539,1200.0,0.1
0.5330824,0.05331432,45.204436917911075,1200.0,0.1
0.5351712,0.0535232,45.24053642176337,1200.0,0.1
0.5378248,0.05378856,45.28131893266479,1200.0,0.1
0.5396873,0.05397481,45.32914137608523,1200.0,0.1
0.5418345,0.05418953,45.37948715817811,1200.0,0.1
0.5438119,0.05438727,45.43597839124067,1200.0,0.1
0.5466930999999999,0.05467539,45.48915605058722,1200.0,0.1
0.5487847,0.05488455,45.54775132874064,1200.0,0.1
0.5504798999999999,0.05505407,45.61530718109856,1200.0,0.1
0.5529121,0.05529729,45.6702757843051,1200.0,0.1
0.5553437999999999,0.05554046,45.72100611554766,1200.0,0.1
0.55738,0.05574408,45.76925890563114,1200.0,0.1
0.5598128,0.05598736,45.82332824972974,1200.0,0.1
0.5615109,0.05615717,45.87246924500245,1200.0,0.1
0.5641143,0.05641751,45.92362946308206,1200.0,0.1
0.5667193,0.05667801,45.97655659319372,1200.0,0.1
0.5690982,0.0569159,46.03778596592851,1200.0,0.1
0.5701733999999999,0.05702342,46.09886975992668,1200.0,0.1
0.5725531,0.05726139,46.15384230096819,1200.0,0.1
0.5752728,0.05753336,46.20244516986777,1200.0,0.1
0.5774277,0.05774885,46.24404801507223,1200.0,0.1
0.5789579,0.05790187,46.29112079021216,1200.0,0.1
0.5807154999999999,0.05807763,46.33706681699038,1200.0,0.1
0.5831540000000001,0.05832148,46.37899492446576,1200.0,0.1
0.5864448,0.05865056,46.42946146262683,1200.0,0.1
0.5883738,0.05884346,46.487054785621446,1200.0,0.1
0.5901894,0.05902502,46.54555125319764,1200.0,0.1
0.5920063,0.05920671,46.60388427706904,1200.0,0.1
0.5948451,0.05949059,46.64371058265244,1200.0,0.1
0.5972307,0.05972915,46.680648065432734,1200.0,0.1
0.5985374,0.05985982,46.728701607559316,1200.0,0.1
0.6010367,0.06010975,46.77478085377488,1200.0,0.1
0.6034237,0.06034845,46.81575437180302,1200.0,0.1
0.6058677,0.06059285,46.85770418242606,1200.0,0.1
0.6083698,0.06084306,46.900127125289906,1200.0,0.1
0.6100187,0.06100795,46.943744532485205,1200.0,0.1
0.6119522,0.0612013,46.98197794779589,1200.0,0.1
0.6147402000000001,0.0614801,47.0027068708963,1200.0,0.1
0.6173585,0.06174193,47.04005120358967,1200.0,0.1
0.6183259,0.06183867,47.08813701851391,1200.0,0.1
0.6212286,0.06212894,47.1372472032862,1200.0,0.1
0.6228807,0.06229415,47.178890019927884,1200.0,0.1
0.6256706999999999,0.06257315,47.22355468460382,1200.0,0.1
0.6285191,0.06285799,47.2742908895244,1200.0,0.1
0.6296016000000001,0.06296624,47.32445904300758,1200.0,0.1
0.6312551,0.06313159,47.37134245181835,1200.0,0.1
0.6343333999999999,0.06343942,47.40636360563676,1200.0,0.1
0.6367273999999999,0.06367882,47.44627194370717,1200.0,0.1
0.6376966,0.06377574,47.48835392415428,1200.0,0.1
0.6403774999999999,0.06404383,47.530007024813074,1200.0,0.1
0.6428307,0.06428915,47.56045247843209,1200.0,0.1
0.6455706,0.06456314,47.592566493973386,1200.0,0.1
0.6482536,0.06483144,47.63399316195442,1200.0,0.1
0.6489953,0.06490561,47.67700745436376,1200.0,0.1
0.6516226,0.06516834,47.71059437962897,1200.0,0.1
0.6537929,0.06538537,47.733934637630924,1200.0,0.1
0.6568193999999999,0.06568802,47.76725129568244,1200.0,0.1
0.6577915999999999,0.06578524,47.816849483538526,1200.0,0.1
0.6601356,0.06601964,47.86494994486009,1200.0,0.1
0.6626502,0.0662711,47.90231435190701,1200.0,0.1
0.6651088,0.06651696,47.94166067671743,1200.0,0.1
0.6678548,0.06679156,47.99412071051853,1200.0,0.1
0.6683699000000001,0.06684307,48.04216972731787,1200.0,0.1
0.6718014,0.06718622,48.08618951401103,1200.0,0.1
0.6738625,0.06739233,48.1185458562006,1200.0,0.1
0.6761524,0.06762132,48.159977427643874,1200.0,0.1
0.6776409999999999,0.06777018,48.20841046802259,1200.0,0.1
0.679817,0.06798778,48.25084924574764,1200.0,0.1
0.6821081999999999,0.0682169,48.285292567414245,1200.0,0.1
0.6850295,0.06850903,48.317078009940765,1200.0,0.1
0.6864047,0.06864655,48.355266077641815,1200.0,0.1
0.6888701,0.06889309,48.401234175767314,1200.0,0.1
0.6908189,0.06908797,48.44626943080571,1200.0,0.1
0.6933992,0.069346,48.48020393460544,1200.0,0.1
0.6964387999999999,0.06964996,48.528569292576954,1200.0,0.1
0.6971851,0.06972459,48.580997785805636,1200.0,0.1
0.7000539,0.07001147,48.62902074536967,1200.0,0.1
0.7018899,0.07019507,48.66738048464206,1200.0,0.1
0.7050481000000001,0.07051089,48.69140181324396,1200.0,0.1
0.705909,0.07059698,48.7219677766187,1200.0,0.1
0.7088383,0.07088991,48.76136377392229,1200.0,0.1
0.7106188999999999,0.07106797,48.79403424283403,1200.0,0.1
0.7131462999999999,0.07132071,48.825801910881815,1200.0,0.1
0.7160778,0.07161386,48.864122460681195,1200.0,0.1
0.7180318,0.07180926,48.90357144701796,1200.0,0.1
0.7192393,0.07193001,48.9384025691254,1200.0,0.1
0.7218269999999999,0.07218878,48.97220774696404,1200.0,0.1
0.7244735,0.07245343,49.000088048084784,1200.0,0.1
0.7268321,0.07268929,49.03081614543292,1200.0,0.1
0.7280405999999999,0.07281014,49.0725465602134,1200.0,0.1
0.7306306,0.07306914,49.10882989994306,1200.0,0.1
0.7328182,0.0732879,49.14975115195467,1200.0,0.1
0.7358126,0.07358734,49.1842535379208,1200.0,0.1
0.7366761,0.07367369,49.22366485743782,1200.0,0.1
0.738865,0.07389258,49.26316858342435,1200.0,0.1
0.7415160000000001,0.07415768,49.295967183041626,1200.0,0.1
0.7439939999999999,0.07440548,49.331049821202754,1200.0,0.1
0.7466453,0.07467061,49.3697357413126,1200.0,0.1
0.7482027,0.07482635,49.40999895047539,1200.0,0.1
0.7501058999999999,0.07501667,49.43929872373859,1200.0,0.1
0.7531054,0.07531662,49.46198196623485,1200.0,0.1
0.7552969,0.07553577,49.49226810136151,1200.0,0.1
0.7563943,0.07564551,49.52799368470583,1200.0,0.1
0.7593375,0.07593983,49.564959586415895,1200.0,0.1
0.7618783,0.07619391,49.60298394498052,1200.0,0.1
0.76413,0.07641908,49.64507745792988,1200.0,0.1
0.7654586999999999,0.07655195,49.69332618034672,1200.0,0.1
0.7680584,0.07681192,49.73089345658489,1200.0,0.1
0.7703114999999999,0.07703723,49.75592020127992,1200.0,0.1
0.7729708,0.07730316,49.76944272978586,1200.0,0.1
0.7755141000000001,0.07755749,49.79749799996551,1200.0,0.1
0.7763821000000001,0.07764429,49.82298650313549,1200.0,0.1
0.779447,0.07795078,49.85033408538169,1200.0,0.1
0.7814719,0.07815327,49.871727805404525,1200.0,0.1
0.7843075999999999,0.07843684,49.89713544469086,1200.0,0.1
0.7848287,0.07848895,49.92296859756414,1200.0,0.1
0.7874334,0.07874942,49.94751311322695,1200.0,0.1
0.7902121999999999,0.0790273,49.965299164435535,1200.0,0.1
0.7925288,0.07925896,49.98761721543209,1200.0,0.1
0.7934559,0.07935167,50.024432563320104,1200.0,0.1
0.7960043,0.07960651,50.057150624616966,1200.0,0.1
0.7984959,0.07985567,50.09266513919033,1200.0,0.1
0.8012201999999999,0.0801281,50.12208034963473,1200.0,0.1
0.8035395,0.08036003,50.15807183715178,1200.0,0.1
0.8047572000000001,0.0804818,50.1898911780409,1200.0,0.1
0.8076570999999999,0.08077179,50.2150708451537,1200.0,0.1
0.8101515,0.08102123,50.23599023814503,1200.0,0.1
0.8124728,0.08125336,50.2672807080905,1200.0,0.1
0.8139819,0.08140427,50.30650013838617,1200.0,0.1
0.8160139,0.08160747,50.34434266585598,1200.0,0.1
0.8189746,0.08190354,50.38003037912665,1200.0,0.1
0.8210663,0.08211271,50.41852923123345,1200.0,0.1
0.8233900999999999,0.08234509,50.456567195765324,1200.0,0.1
0.8251325,0.08251933,50.49674091382652,1200.0,0.1
0.8273407999999999,0.08274016,50.530359669436955,1200.0,0.1
0.8301318,0.08301926,50.5574857847114,1200.0,0.1
0.8327483,0.08328091,50.586354917531025,1200.0,0.1
0.8336779999999999,0.08337388,50.61513633937382,1200.0,0.1
0.8360048,0.08360656,50.64573439157083,1200.0,0.1
0.8383908,0.08384516,50.671157878002276,1200.0,0.1
0.840369,0.08404298,50.69961443498397,1200.0,0.1
0.8419987999999999,0.08420596,50.731139301458825,1200.0,0.1
0.8449673,0.08450281,50.76127314327583,1200.0,0.1
0.8469477,0.08470085,50.79191525221596,1200.0,0.1
0.8492187,0.08492795,50.81364106387674,1200.0,0.1
0.8517823999999999,0.08518432,50.84013458186903,1200.0,0.1
0.8529473000000001,0.08530081,50.86532671131888,1200.0,0.1
0.8554531000000001,0.08555139,50.895823575028075,1200.0,0.1
0.8581352,0.0858196,50.91724575267413,1200.0,0.1
0.8605844,0.08606452,50.95477239586324,1200.0,0.1
0.8613999,0.08614607,50.998375445758775,1200.0,0.1
0.864433,0.08644938,51.03773865333445,1200.0,0.1
0.8671755,0.08672363,51.081022810415966,1200.0,0.1
0.8691014,0.08691622,51.11921719410117,1200.0,0.1
0.8712615,0.08713223,51.15469683919727,1200.0,0.1
0.8732461,0.08733069,51.17860127135692,1200.0,0.1
0.875816,0.08758768,51.20507265225858,1200.0,0.1
0.8776845999999999,0.08777454,51.21615529718109,1200.0,0.1
0.8801386,0.08801994,51.24357401779651,1200.0,0.1
0.8810148,0.08810756,51.276476810439924,1200.0,0.1
0.8839378,0.08839986,51.30271338822558,1200.0,0.1
0.8866265,0.08866873,51.33290933798705,1200.0,0.1
0.8883800000000001,0.08884408,51.355695985010136,1200.0,0.1
0.8901348,0.08901956,51.38153579518242,1200.0,0.1
0.8927090000000001,0.08927698,51.409183268233704,1200.0,0.1
0.895284,0.08953448,51.44095438606868,1200.0,0.1
0.8977412,0.0897802,51.46395774822946,1200.0,0.1
0.9000828999999999,0.09001437,51.49094368020845,1200.0,0.1
0.9016052999999999,0.09016661,51.51201322696735,1200.0,0.1
0.9041233000000001,0.09041841,51.52898603058108,1200.0,0.1
0.9063491,0.09064099,51.54664046992596,1200.0,0.1
0.9085173,0.09085781,51.56451515032382,1200.0,0.1
0.9102164,0.09102772,51.589478713962215,1200.0,0.1
0.9123855,0.09124463,51.624380178905,1200.0,0.1
0.9153749,0.09154357,51.66487802153696,1200.0,0.1
0.9177799,0.09178407,51.69134713371457,1200.0,0.1
0.9200088999999999,0.09200697,51.72002252357815,1200.0,0.1
0.9213585,0.09214193,51.754830114074466,1200.0,0.1
0.9238221,0.09238829,51.78735439748222,1200.0,0.1
0.9259358999999999,0.09259967,51.81772908986707,1200.0,0.1
0.9288118,0.09288726,51.84654396870512,1200.0,0.1
0.9300449,0.09301057,51.87768317007389,1200.0,0.1
0.9325702,0.0932631,51.910838306793806,1200.0,0.1
0.9350377000000001,0.09350985,51.934651275994426,1200.0,0.1
0.9376818,0.09377426,51.93916873244331,1200.0,0.1
0.9385629999999999,0.09386238,51.94799498761532,1200.0,0.1
0.9408559999999999,0.09409168,51.96579422859342,1200.0,0.1
0.9437955,0.09438563,51.97372777224964,1200.0,0.1
0.9463242,0.0946385,51.97684483765982,1200.0,0.1
0.9486773000000001,0.09487381,51.99493357857613,1200.0,0.1
0.9500892,0.095015,52.019602459154406,1200.0,0.1
0.9521489999999999,0.09522098,52.0466604164689,1200.0,0.1
0.9553861,0.09554469,52.06939477099573,1200.0,0.1
0.9572706,0.09573314,52.09239683427485,1200.0,0.1
0.9584479,0.09585087,52.1092781368228,1200.0,0.1
0.9610398,0.09611006,52.13359906991016,1200.0,0.1
0.9635133,0.09635741,52.1622502674484,1200.0,0.1
0.9661065,0.09661673,52.17916746206038,1200.0,0.1
0.9685227,0.09685835,52.20831224111715,1200.0,0.1
0.9698789,0.09699397,52.245245692212045,1200.0,0.1
0.9725323,0.09725931,52.268884611280235,1200.0,0.1
0.9753044999999999,0.09753653,52.29466157250454,1200.0,0.1
0.9770746,0.09771354,52.31964474666924,1200.0,0.1
0.9788441,0.09789049,52.34242312088569,1200.0,0.1
0.9807916,0.09808524,52.36708372028951,1200.0,0.1
0.9829760000000001,0.09830368,52.394190850553024,1200.0,0.1
0.9862230999999999,0.09862839,52.41290912166677,1200.0,0.1
0.9868731000000001,0.09869339,52.42630590455154,1200.0,0.1
0.9897079,0.09897687,52.44905808066763,1200.0,0.1
0.9918942000000001,0.0991955,52.467662776345925,1200.0,0.1
0.9944937,0.09945545,52.49477708653077,1200.0,0.1
0.9969178999999999,0.09969787,52.52993011185206,1200.0,0.1
0.9981596,0.09982204,52.56326752659125,1200.0,0.1
1.0002881,0.10003489,52.59555795901543,1200.0,0.1
1.0028896999999999,0.10029505,52.619953021324086,1200.0,0.1
1.0054932,0.1005554,52.643250884119425,1200.0,0.1
1.0070904,0.10071512,52.64687243551321,1200.0,0.1
1.0089846999999998,0.10090455,52.66995579126475,1200.0,0.1
1.0117072,0.1011768,52.69325904962628,1200.0,0.1
1.0144315,0.10144923,52.71577077742662,1200.0,0.1
1.0159114999999999,0.10159723,52.74039566351501,1200.0,0.1
1.0180448,0.10181056,52.76210118562148,1200.0,0.1
1.0207099,0.10207707,52.79234480666897,1200.0,0.1
1.0231405,0.10232013,52.813617616939844,1200.0,0.1
1.0255117,0.10255725,52.83816333290969,1200.0,0.1
1.0265194,0.10265802,52.854287589346924,1200.0,0.1
1.0295442,0.1029605,52.88123113420977,1200.0,0.1
1.0312629,0.10313237,52.91088327173946,1200.0,0.1
1.034468,0.10345288,52.9353602391826,1200.0,0.1
1.0355355,0.10355963,52.96073349279853,1200.0,0.1
1.0378507,0.10379115,52.98641137205532,1200.0,0.1
1.0401065999999999,0.10401674,53.007922081178755,1200.0,0.1
1.0423040000000001,0.10423648,53.016435584156234,1200.0,0.1
1.0443228,0.10443836,53.03201731260549,1200.0,0.1
1.0468171,0.10468779,53.046670221618925,1200.0,0.1
1.0489557999999999,0.10490166,53.06909410441224,1200.0,0.1
1.0513933,0.10514541,53.09016197157467,1200.0,0.1
1.0535932,0.1053654,53.11271397416242,1200.0,0.1
1.0549009,0.10549617,53.139131314343004,1200.0,0.1
1.0571004,0.10571612,53.16285284831831,1200.0,0.1
1.059659,0.10597198,53.18420264188243,1200.0,0.1
1.0623953,0.10624561,53.20457822587582,1200.0,0.1
1.0637642999999999,0.10638251,53.230644398752595,1200.0,0.1
1.0664427,0.10665035,53.2520646090863,1200.0,0.1
1.0683472999999999,0.10684081,53.275748359504995,1200.0,0.1
1.0712655,0.10713263,53.29107654540084,1200.0,0.1
1.0741242999999998,0.10741851,53.31003776594674,1200.0,0.1
1.0747799999999998,0.10748408,53.32958743034119,1200.0,0.1
1.0771635,0.10772243,53.34903590981261,1200.0,0.1
1.079667,0.10797278,53.36882789999042,1200.0,0.1
1.0822303,0.10822911,53.39251258556157,1200.0,0.1
1.0837806,0.10838414,53.40956374058359,1200.0,0.1
1.0859876,0.10860484,53.41879957084663,1200.0,0.1
1.0890885,0.10891493,53.427011002709854,1200.0,0.1
1.0909985,0.10910593,53.43156931473809,1200.0,0.1
1.0921916,0.10922524,53.444705368372766,1200.0,0.1
1.0950575,0.10951183,53.45661728034692,1200.0,0.1
1.0972066,0.10972674,53.47304958171505,1200.0,0.1
1.0995351,0.10995959,53.48764638089564,1200.0,0.1
1.1024032,0.1102464,53.50287351076905,1200.0,0.1
1.1039565999999998,0.11040174,53.520599869676005,1200.0,0.1
1.1057486,0.11058094,53.543501416796616,1200.0,0.1
1.1087382,0.1108799,53.56600360865028,1200.0,0.1
1.1109495999999999,0.11110104,53.587178613146314,1200.0,0.1
1.1135209,0.11135817,53.61040383632381,1200.0,0.1
1.1147771,0.11148379,53.62865501055267,1200.0,0.1
1.1169304999999998,0.11169913,53.64556031850646,1200.0,0.1
1.1198629,0.11199237,53.648997905214195,1200.0,0.1
1.1224365,0.11224973,53.65749619533138,1200.0,0.1
1.123454,0.11235148,53.67032709205891,1200.0,0.1
1.1260295999999999,0.11260904,53.68984086207853,1200.0,0.1
1.1281249,0.11281857,53.714069103183505,1200.0,0.1
1.1306412,0.1130702,53.737118311082526,1200.0,0.1
1.133038,0.11330988,53.75575508924943,1200.0,0.1
1.1344762,0.1134537,53.77625659628285,1200.0,0.1
1.1372342,0.1137295,53.79728297527626,1200.0,0.1
1.1393925,0.11394533,53.80854113972985,1200.0,0.1
1.1420306,0.11420914,53.81691178325587,1200.0,0.1
1.1432308999999998,0.11432917,53.819207086642265,1200.0,0.1
1.1455701,0.11456309,53.81916764759537,1200.0,0.1
1.1478503999999998,0.11479112,53.82098733647484,1200.0,0.1
1.1501310999999999,0.11501919,53.83668867757061,1200.0,0.1
1.151692,0.11517528,53.85070173901272,1200.0,0.1
1.1540344,0.11540952,53.87297876682895,1200.0,0.1
1.1567371,0.11567979,53.90298063154656,1200.0,0.1
1.1583584999999998,0.11584193,53.933606531686046,1200.0,0.1
1.1616035,0.11616643,53.957755391899454,1200.0,0.1
1.1626857,0.11627465,53.97434936229102,1200.0,0.1
1.1656912,0.1165752,53.99090960122216,1200.0,0.1
1.1671938,0.11672546,54.01457874752685,1200.0,0.1
1.1699001,0.11699609,54.03466784961827,1200.0,0.1
1.1715247999999998,0.11715856,54.039218281050786,1200.0,0.1
1.1741725,0.11742333,54.05006466785453,1200.0,0.1
1.1765788,0.11766396,54.07180788254949,1200.0,0.1
1.178626,0.11786868,54.0957141097633,1200.0,0.1
1.1798905,0.11799513,54.10696850924785,1200.0,0.1
1.1818776,0.11819384,54.1217575837173,1200.0,0.1
1.1850095,0.11850703,54.137777432891184,1200.0,0.1
1.1868161,0.11868769,54.15916370371451,1200.0,0.1
1.1899496,0.11900104,54.17034596257263,1200.0,0.1
1.1910349,0.11910957,54.173023868065314,1200.0,0.1
1.1939891,0.11940499,54.18939479298036,1200.0,0.1
1.1961595999999999,0.11962204,54.21261063305261,1200.0,0.1
1.1988727,0.11989335,54.22458666378379,1200.0,0.1
1.2001407,0.12002015,54.240940698831494,1200.0,0.1
1.202011,0.12020718,54.262859700583626,1200.0,0.1
1.2060543,0.12061151,54.285509837303884,1200.0,0.1
1.2070804,0.12071412,54.308170635423245,1200.0,0.1
1.2094358,0.12094966,54.329503893299695,1200.0,0.1
1.2111269,0.12111877,54.34516289890425,1200.0,0.1
1.213542,0.12136028,54.36108576149564,1200.0,0.1
1.2157778,0.12158386,54.37679372447857,1200.0,0.1
1.2184373,0.12184981,54.377796469999105,1200.0,0.1
1.2212174,0.12212782,54.38135989557459,1200.0,0.1
1.2217618,0.12218226,54.39118637940979,1200.0,0.1
1.224664,0.12247248,54.401177463396714,1200.0,0.1
1.227447,0.12275078,54.41605597732512,1200.0,0.1
1.2299272,0.1229988,54.43437732214998,1200.0,0.1
1.2310769,0.12311377,54.45837450114718,1200.0,0.1
1.233013,0.12330738,54.483567563556036,1200.0,0.1
1.2358585,0.12359193,54.5147110236975,1200.0,0.1
1.2385233,0.12385841,54.52673070787722,1200.0,0.1
1.2393713,0.12394321,54.531213795185906,1200.0,0.1
1.2417943,0.12418551,54.545156949384825,1200.0,0.1
1.2442781,0.12443389,54.557422228692104,1200.0,0.1
1.2468839,0.12469447,54.56940717416626,1200.0,0.1
1.249066,0.12491268,54.57971453006023,1200.0,0.1
1.2508251,0.12508859,54.58689922847833,1200.0,0.1
1.2534927999999999,0.12535536,54.59677620065625,1200.0,0.1
1.2561622,0.1256223,54.6148129451661,1200.0,0.1
1.2576786,0.12577394,54.6159580539333,1200.0,0.1
1.2590744999999999,0.12591353,54.61622402045374,1200.0,0.1
1.2619885999999998,0.12620494,54.62206005787985,1200.0,0.1
1.2642944999999999,0.12643553,54.6271205637188,1200.0,0.1
1.2670270999999997,0.12670879,54.635303589175415,1200.0,0.1
1.2681209,0.12681817,54.64873136759599,1200.0,0.1
1.2710979999999998,0.12711588,54.66848600131745,1200.0,0.1
1.2731034,0.12731642,54.696947301597845,1200.0,0.1
1.2758383,0.12758991,54.71369304854769,1200.0,0.1
1.2786345000000001,0.12786953,54.71688142472554,1200.0,0.1
1.2794256,0.12794864,54.71697355750983,1200.0,0.1
1.2818583999999997,0.12819192,54.717927270626674,1200.0,0.1
1.2844124,0.12844732,54.71875790988638,1200.0,0.1
1.2872725999999999,0.12873334,54.727108195994695,1200.0,0.1
1.2875779,0.12876387,54.742046967655746,1200.0,0.1
1.2909858,0.12910466,54.76008847108937,1200.0,0.1
1.2932994999999998,0.12933603,54.789320195222416,1200.0,0.1
1.295796,0.12958568,54.80520150297724,1200.0,0.1
1.2979284,0.12979892,54.80590550570674,1200.0,0.1
1.2989639,0.12990247,54.805035048476896,1200.0,0.1
1.3015236,0.13015844,54.8031936173503,1200.0,0.1
1.3040838000000001,0.13041446,54.80833771165587,1200.0,0.1
1.3068274,0.13068882,54.817118311707674,1200.0,0.1
1.3082302,0.1308291,54.82548284122687,1200.0,0.1
1.3098149,0.13098757,54.835614811630386,1200.0,0.1
1.3123772999999999,0.13124381,54.8581208997327,1200.0,0.1
1.3151848000000002,0.13152456,54.87210106094097,1200.0,0.1
1.3164048999999998,0.13164657,54.87597631206928,1200.0,0.1
1.3189073,0.13189681,54.87611267783329,1200.0,0.1
1.3212274,0.13212882,54.87949277620955,1200.0,0.1
1.3244649999999998,0.13245258,54.88196492748388,1200.0,0.1
1.3264811,0.13265419,54.88489651071263,1200.0,0.1
1.3276419,0.13277027,54.89285176920107,1200.0,0.1
1.3301471999999999,0.1330208,54.908681358634766,1200.0,0.1
1.3327755,0.13328363,54.931387962726035,1200.0,0.1
1.3349773999999999,0.13350382,54.95085472051794,1200.0,0.1
1.3363224,0.13363832,54.972837367516235,1200.0,0.1
1.3384016,0.13384624,54.99777433949154,1200.0,0.1
1.3412164,0.13412772,55.01430809838972,1200.0,0.1
1.3437249999999998,0.13437858,55.01426719913871,1200.0,0.1
1.3461127999999998,0.13461736,55.01917158252904,1200.0,0.1
1.3469081,0.13469689,55.027752635572575,1200.0,0.1
1.3497860999999998,0.13498469,55.039485356341636,1200.0,0.1
1.3523588,0.13524196,55.0507349432243,1200.0,0.1
1.3549927999999998,0.13550536,55.063414975583896,1200.0,0.1
1.3557888999999999,0.13558497,55.072578009172624,1200.0,0.1
1.3583021999999998,0.1358363,55.08567604068594,1200.0,0.1
1.3611834999999999,0.13612443,55.08128959106319,1200.0,0.1
1.3634514999999998,0.13635123,55.074696086739515,1200.0,0.1
1.3649232999999998,0.13649841,55.0732787078038,1200.0,0.1
1.3668865,0.13669473,55.07582046434313,1200.0,0.1
1.3700149999999998,0.13700758,55.083753818185876,1200.0,0.1
1.3714267,0.13714875,55.09170815059262,1200.0,0.1
1.3733902999999998,0.13734511,55.11041887925491,1200.0,0.1
1.3762149,0.13762757,55.12824592116165,1200.0,0.1
1.3782415,0.13783023,55.13988615145879,1200.0,0.1
1.3810055,0.13810663,55.14056550839299,1200.0,0.1
1.3829719999999999,0.13830328,55.14257228877597,1200.0,0.1
1.3847537,0.13848145,55.14371708602405,1200.0,0.1
1.3867819,0.13868427,55.142551504522714,1200.0,0.1
1.3898556,0.13899164,55.15016736283198,1200.0,0.1
1.3917616000000002,0.13918224,55.16408366788191,1200.0,0.1
1.3938524,0.13939132,55.18035916821684,1200.0,0.1
1.3954516999999997,0.13955125,55.192894753485334,1200.0,0.1
1.397974,0.13980348,55.1988237190494,1200.0,0.1
1.4010521999999999,0.1401113,55.20827699978176,1200.0,0.1
1.4037603,0.14038211,55.216902971548265,1200.0,0.1
1.4045612,0.1404622,55.22258787924282,1200.0,0.1
1.4062857999999998,0.14063466,55.2254015660651,1200.0,0.1
1.4097345,0.14097953,55.23247954067565,1200.0,0.1
1.4120757999999998,0.14121366,55.23396703786575,1200.0,0.1
1.4128773999999997,0.14129382,55.23636966684548,1200.0,0.1
1.4162061,0.14162669,55.227772690641075,1200.0,0.1
1.4181784,0.14182392,55.22473719871147,1200.0,0.1
1.421324,0.14213848,55.22961470932297,1200.0,0.1
1.4220017,0.14220625,55.22887700832852,1200.0,0.1
1.4245318,0.14245926,55.23050532101402,1200.0,0.1
1.4271226,0.14271834,55.238453905271534,1200.0,0.1
1.4296541,0.14297149,55.244155203038815,1200.0,0.1
1.4323086,0.14323694,55.2439674294894,1200.0,0.1
1.4335431,0.14336039,55.250560063335975,1200.0,0.1
1.4363225,0.14363833,55.24942829599667,1200.0,0.1
1.4383611,0.14384219,55.24778721995116,1200.0,0.1
1.441018,0.14410788,55.25217222114552,1200.0,0.1
1.4422548,0.14423156,55.246155304298554,1200.0,0.1
1.4443559999999998,0.14444168,55.24514585840717,1200.0,0.1
1.4470144999999999,0.14470753,55.25044617693408,1200.0,0.1
1.4497976,0.14498584,55.25526284389455,1200.0,0.1
1.4520255,0.14520863,55.26516443391309,1200.0,0.1
1.4531383999999998,0.14531992,55.27445888758899,1200.0,0.1
1.4557378,0.14557986,55.27667746959063,1200.0,0.1
1.4575325999999997,0.14575934,55.27412809559745,1200.0,0.1
1.4606906,0.14607514,55.28635342826923,1200.0,0.1
1.4622381,0.14622989,55.28504091016854,1200.0,0.1
1.4644062,0.1464467,55.28437330540079,1200.0,0.1
1.4666989,0.14667597,55.296311884996086,1200.0,0.1
1.4693633,0.14694241,55.29899768798627,1200.0,0.1
1.4705408999999998,0.14706017,55.30852289734819,1200.0,0.1
1.4732063,0.14732671,55.316238454381136,1200.0,0.1
1.4755011,0.14755619,55.31224487004851,1200.0,0.1
1.4781678,0.14782286,55.31029341628366,1200.0,0.1
1.4808351999999998,0.1480896,55.32051388163031,1200.0,0.1
1.4812695999999999,0.14813304,55.324568822702254,1200.0,0.1
1.4845594999999998,0.14846203,55.326244529478345,1200.0,0.1
1.4869183,0.14869791,55.329250327229694,1200.0,0.1
1.4890906,0.14891514,55.32157673821,1200.0,0.1
1.4901473,0.14902081,55.31434573961686,1200.0,0.1
1.4929423999999998,0.14930032,55.31112063256095,1200.0,0.1
1.4947438,0.14948046,55.30350902751425,1200.0,0.1
1.4975402,0.1497601,55.303331234733655,1200.0,0.1
1.4992808,0.14993416,55.30906154756076,1200.0,0.1
1.5007098,0.15007706,55.32022870102406,1200.0,0.1
1.5034461000000001,0.15035069,55.323975643782084,1200.0,0.1
1.5056847999999998,0.15057456,55.321427258330196,1200.0,0.1
1.5090446,0.15091054,55.3205758849152,1200.0,0.1
1.509854,0.15099148,55.3224112662861,1200.0,0.1
1.5127164,0.15127772,55.327052963826056,1200.0,0.1
1.5148325,0.15148933,55.33149948706866,1200.0,0.1
1.5171368,0.15171976,55.32678478596218,1200.0,0.1
1.5187559999999998,0.15188168,55.32353312284428,1200.0,0.1
1.521123,0.15211838,55.31944040425844,1200.0,0.1
1.5237401,0.15238009,55.318549680439396,1200.0,0.1
1.5260464,0.15261072,55.31778449166634,1200.0,0.1
1.5281653,0.15282261,55.325558422204196,1200.0,0.1
1.5302847,0.15303455,55.34427444701332,1200.0,0.1
1.5324047,0.15324655,55.36291824765847,1200.0,0.1
1.5349628,0.15350236,55.376215236045525,1200.0,0.1
1.5373336,0.15373944,55.37866394731387,1200.0,0.1
1.5384562,0.1538517,55.38325724636076,1200.0,0.1
1.5413898,0.15414506,55.384784739479755,1200.0,0.1
1.5436383,0.15436991,55.38589864174394,1200.0,0.1
1.5457608999999999,0.15458217,55.38544187355248,1200.0,0.1
1.5471977,0.15472585,55.39249374713032,1200.0,0.1
1.5495083,0.15495691,55.39421516830393,1200.0,0.1
1.5520707999999999,0.15521316,55.39511790913464,1200.0,0.1
1.5543206,0.15543814,55.396385440653795,1200.0,0.1
1.5575713,0.15576321,55.39838350893973,1200.0,0.1
1.5583215999999998,0.15583824,55.401829424238265,1200.0,0.1
1.5612611,0.15613219,55.407440496795225,1200.0,0.1