File: datasets/steel_spring/csv/BS2V-1050-1.0.csv
Time(s),Strain(%),Stress(MPa),Temp(C),SR(%/s)
0.0,1.356e-05,0.6166503089825034,1050.0,1.0
5.374999999999999e-06,1.8935e-05,0.02700005589627641,1050.0,1.0
1.0749999999999999e-05,2.431e-05,-0.2383599350100173,1050.0,1.0
4.2949999999999994e-05,5.651e-05,0.007417838693167256,1050.0,1.0
7.515e-05,8.871e-05,0.9511808794353754,1050.0,1.0
9.123e-05,0.00010479,3.448749990090922,1050.0,1.0
0.00010731,0.00012087,6.835483491735823,1050.0,1.0
0.00026032,0.00027388,11.581106740992468,1050.0,1.0
0.00041332999999999995,0.00042689,17.715123050445147,1050.0,1.0
0.0006416449999999999,0.0006552050000000001,24.747314091924334,1050.0,1.0
0.00086996,0.00088352,32.54231735738365,1050.0,1.0
0.00114396,0.00115752,40.374176198424394,1050.0,1.0
0.00141796,0.00143152,47.827040168636536,1050.0,1.0
0.0018669999999999997,0.0018805599999999999,54.283751035583535,1050.0,1.0
0.0023160399999999997,0.0023296,59.489154869528655,1050.0,1.0
0.00302132,0.00303488,63.32123373150026,1050.0,1.0
0.0037266,0.00374016,65.90381175800596,1050.0,1.0
0.00443015,0.00444371,67.59263947679572,1050.0,1.0
0.0051337,0.00514726,68.64610801348036,1050.0,1.0
0.005808555,0.005822115,69.4809101128184,1050.0,1.0
0.00648341,0.00649697,70.19773615707126,1050.0,1.0
0.007148345,0.007161905,70.94206409949267,1050.0,1.0
0.00781328,0.00782684,71.71820106364038,1050.0,1.0
0.008449295,0.008462855,72.52477811024265,1050.0,1.0
0.009085310000000001,0.00909887,73.35131880885913,1050.0,1.0
0.009689595,0.009703155,74.1792004756215,1050.0,1.0
0.01029388,0.01030744,75.00013114278154,1050.0,1.0
0.010926085,0.010939645,75.8125927933564,1050.0,1.0
0.01155829,0.01157185,76.6274227299691,1050.0,1.0
0.01220758,0.01222114,77.438991131417,1050.0,1.0
0.012856870000000001,0.01287043,78.2419009940344,1050.0,1.0
0.013501555000000002,0.013515115000000001,79.03193296086394,1050.0,1.0
0.014146240000000001,0.0141598,79.81200660232129,1050.0,1.0
0.01476997,0.01478353,80.57101913306848,1050.0,1.0
0.015393700000000001,0.01540726,81.29176633887535,1050.0,1.0
0.016012695,0.016026255,81.97118455015949,1050.0,1.0
0.01663169,0.01664525,82.62660535150896,1050.0,1.0
0.017246025,0.017259585,83.26870721003071,1050.0,1.0
0.017860360000000002,0.01787392,83.89482141180906,1050.0,1.0
0.018483700000000002,0.01849726,84.50230508135638,1050.0,1.0
0.019107040000000002,0.0191206,85.09321342216323,1050.0,1.0
0.019755765,0.019769325,85.67487586436401,1050.0,1.0
0.02040449,0.02041805,86.24679315128911,1050.0,1.0
0.02103763,0.02105119,86.79759076343964,1050.0,1.0
0.021670770000000002,0.02168433,87.32830200517536,1050.0,1.0
0.02230194,0.022315500000000002,87.8464501132653,1050.0,1.0
0.02293311,0.02294667,88.34865435814878,1050.0,1.0
0.023554065,0.023567625000000002,88.83626572665162,1050.0,1.0
0.024175020000000002,0.02418858,89.31484769897936,1050.0,1.0
0.024785765,0.024799325,89.78537818307603,1050.0,1.0
0.02539651,0.02541007,90.24915040816985,1050.0,1.0
0.026046600000000003,0.02606016,90.71411860206858,1050.0,1.0
0.026696690000000002,0.02671025,91.18172235248335,1050.0,1.0
0.02733657,0.02735013,91.64672202188683,1050.0,1.0
0.02797645,0.02799001,92.10710525138775,1050.0,1.0
0.02860608,0.028619640000000002,92.55917291186408,1050.0,1.0
0.02923571,0.02924927,93.00801089075794,1050.0,1.0
0.02984956,0.02986312,93.44956398960638,1050.0,1.0
0.03046341,0.03047697,93.86856309303907,1050.0,1.0
0.031113999999999996,0.03112756,94.26361052076543,1050.0,1.0
0.031764589999999995,0.03177815,94.64643953440756,1050.0,1.0
0.032379994999999995,0.032393555,95.02372841250806,1050.0,1.0
0.032995399999999994,0.03300896,95.39614922467948,1050.0,1.0
0.03362825,0.033641809999999994,95.76595801931863,1050.0,1.0
0.034261099999999996,0.03427466,96.13492288756574,1050.0,1.0
0.034930825,0.034944384999999994,96.50758427762919,1050.0,1.0
0.035600549999999995,0.03561411,96.88067773285731,1050.0,1.0
0.036201645,0.036215205,97.24406786752292,1050.0,1.0
0.03680274,0.0368163,97.59950951458255,1050.0,1.0
0.03744912,0.03746268,97.95295294975026,1050.0,1.0
0.0380955,0.03810906,98.30681065904768,1050.0,1.0
0.038725949999999995,0.038739510000000005,98.65520001005319,1050.0,1.0
0.0393564,0.03936996,98.9915500502907,1050.0,1.0
0.03999606,0.04000962,99.31452347143171,1050.0,1.0
0.04063572,0.04064928,99.62741247838818,1050.0,1.0
0.041262215,0.041275775,99.93426572134847,1050.0,1.0
0.041888709999999996,0.04190227,100.23584809335432,1050.0,1.0
0.042518774999999995,0.042532335,100.53161695672019,1050.0,1.0
0.043148839999999994,0.0431624,100.82431226963831,1050.0,1.0
0.04377969999999999,0.04379326,101.11850611177402,1050.0,1.0
0.044410559999999995,0.04442412,101.40803892225802,1050.0,1.0
0.04503096499999999,0.045044525,101.69278498820582,1050.0,1.0
0.04565137,0.04566493,101.98495528126517,1050.0,1.0
0.046264114999999995,0.046277675000000004,102.28204464285665,1050.0,1.0
0.04687686,0.04689042,102.57648893221334,1050.0,1.0
0.047510075,0.047523635,102.86451125603031,1050.0,1.0
0.04814329,0.04815685,103.14240484536072,1050.0,1.0
0.04879989999999999,0.04881346,103.40772774393932,1050.0,1.0
0.049456509999999995,0.04947007,103.66092808050763,1050.0,1.0
0.050054635,0.050068194999999996,103.90086457289406,1050.0,1.0
0.05065276,0.05066632,104.13264646923493,1050.0,1.0
0.051299695,0.051313255,104.368241975841,1050.0,1.0
0.05194663,0.05196019,104.605788060005,1050.0,1.0
0.05256039,0.05257395,104.8430370751897,1050.0,1.0
0.053174149999999996,0.05318771,105.08327431441512,1050.0,1.0
0.053760394999999996,0.053773955,105.32689768623517,1050.0,1.0
0.054346639999999995,0.0543602,105.57521623627031,1050.0,1.0
0.054964744999999995,0.054978305,105.82594444966716,1050.0,1.0
0.055582849999999996,0.05559641,106.07074170007243,1050.0,1.0
0.05619320999999999,0.05620677,106.30745225950032,1050.0,1.0
0.05680357,0.05681713,106.54117319567085,1050.0,1.0
0.057414675,0.057428235,106.77315608478095,1050.0,1.0
0.05802578,0.05803934,107.0045853951968,1050.0,1.0
0.058651869999999995,0.058665430000000005,107.23732976606128,1050.0,1.0
0.05927796,0.05929152,107.47108188990018,1050.0,1.0
0.059881989999999996,0.05989555,107.70578221292469,1050.0,1.0
0.060486019999999995,0.06049958,107.93856788735077,1050.0,1.0
0.06109938499999999,0.061112945,108.16510334959875,1050.0,1.0
0.06171275,0.06172631,108.38944607267997,1050.0,1.0
0.06232119,0.062334749999999994,108.61349328081823,1050.0,1.0
0.06292963,0.06294319,108.83193361613098,1050.0,1.0
0.063555905,0.06356946499999999,109.04532905131883,1050.0,1.0
0.06418218,0.06419574,109.2573721104429,1050.0,1.0
0.06479492,0.06480848,109.46922187272018,1050.0,1.0
0.06540766,0.06542122,109.68243872696254,1050.0,1.0
0.06601831,0.06603186999999999,109.89721472434903,1050.0,1.0
0.06662896,0.06664252,110.11052777385103,1050.0,1.0
0.067251855,0.067265415,110.32487977760687,1050.0,1.0
0.06787475,0.06788831,110.54203688486923,1050.0,1.0
0.06846963,0.06848319,110.75836096397812,1050.0,1.0
0.06906451000000001,0.06907807,110.97553959754634,1050.0,1.0
0.069660145,0.069673705,111.19456546629635,1050.0,1.0
0.07025578,0.07026934,111.4131591853216,1050.0,1.0
0.07086648000000001,0.07088004,111.62956029328066,1050.0,1.0
0.07147718,0.07149074,111.84237677552977,1050.0,1.0
0.07211467,0.07212823,112.04735324422033,1050.0,1.0
0.07275216000000001,0.07276572,112.24443279403877,1050.0,1.0
0.07334129,0.07335485,112.43849526637966,1050.0,1.0
0.07393042000000001,0.07394398,112.63122215531767,1050.0,1.0
0.074528915,0.074542475,112.82404063953798,1050.0,1.0
0.07512741,0.07514097,113.01742562947456,1050.0,1.0
0.07575562500000001,0.075769185,113.21216332928029,1050.0,1.0
0.07638384000000001,0.0763974,113.41286418216916,1050.0,1.0
0.07699254500000001,0.077006105,113.61703463296905,1050.0,1.0
0.07760125000000001,0.07761481,113.81530449846528,1050.0,1.0
0.07823972000000001,0.07825328000000001,114.0051001441361,1050.0,1.0
0.07887819,0.07889175,114.19050889506181,1050.0,1.0
0.07947388,0.07948743999999999,114.37306662361412,1050.0,1.0
0.08006957,0.08008313,114.55101597975259,1050.0,1.0
0.080689245,0.080702805,114.72805654757671,1050.0,1.0
0.08130892,0.08132248,114.91310998726065,1050.0,1.0
0.08194098,0.08195453999999999,115.10740180646356,1050.0,1.0
0.08257304,0.0825866,115.30252674440196,1050.0,1.0
0.08318842,0.08320198,115.49121641020582,1050.0,1.0
0.0838038,0.08381736,115.67200108726857,1050.0,1.0
0.08437613,0.08438968999999999,115.84963917590335,1050.0,1.0
0.08494846,0.08496202,116.03043684774251,1050.0,1.0
0.08556826000000001,0.08558182,116.21006914171409,1050.0,1.0
0.08618806000000001,0.08620162,116.38560477631334,1050.0,1.0
0.08680271,0.08681627,116.56177968711503,1050.0,1.0
0.08741736,0.08743092,116.73669008319311,1050.0,1.0
0.088027,0.08804055999999999,116.90804490937148,1050.0,1.0
0.08863664,0.0886502,117.07874131145448,1050.0,1.0
0.08922933,0.08924288999999999,117.24640617490914,1050.0,1.0
0.08982202,0.08983558,117.40848802252987,1050.0,1.0
0.09043896000000001,0.09045252000000001,117.57439492032678,1050.0,1.0
0.09105590000000001,0.09106946,117.74977487109331,1050.0,1.0
0.09167063,0.09168419,117.92723367368366,1050.0,1.0
0.09228536000000001,0.09229892,118.10024852750583,1050.0,1.0
0.092909675,0.09292323499999999,118.27103382247904,1050.0,1.0
0.09353399,0.09354755,118.44477793150882,1050.0,1.0
0.09411192,0.09412548,118.62299881322839,1050.0,1.0
0.09468985,0.09470341,118.80258722784654,1050.0,1.0
0.095300955,0.095314515,118.9755467970459,1050.0,1.0
0.09591206000000001,0.09592562,119.14523139122763,1050.0,1.0
0.09653571,0.09654926999999999,119.31595309218233,1050.0,1.0
0.09715936,0.09717292,119.48054973400426,1050.0,1.0
0.09779859,0.09781215,119.63178742255353,1050.0,1.0
0.09843782000000001,0.09845138,119.7685486647857,1050.0,1.0
0.09902453,0.09903809,119.90111975619766,1050.0,1.0
0.09961124,0.0996248,120.04188018576062,1050.0,1.0
0.10021047,0.10022402999999999,120.19286510277222,1050.0,1.0
0.1008097,0.10082326,120.34774611965148,1050.0,1.0
0.10144832000000001,0.10146188,120.50648967940862,1050.0,1.0
0.10208694,0.1021005,120.67246000934409,1050.0,1.0
0.102684705,0.102698265,120.84032196107621,1050.0,1.0
0.10328247,0.10329603,120.99942384642958,1050.0,1.0
0.10386606500000001,0.103879625,121.14744096633457,1050.0,1.0
0.10444966,0.10446322,121.29789657063505,1050.0,1.0
0.1051025,0.10511606,121.45541457919057,1050.0,1.0
0.10575534,0.1057689,121.60777417916735,1050.0,1.0
0.106373255,0.106386815,121.75184037493995,1050.0,1.0
0.10699117000000001,0.10700473,121.89553659299679,1050.0,1.0
0.107600835,0.107614395,122.04535856292476,1050.0,1.0
0.1082105,0.10822406,122.1987168132274,1050.0,1.0
0.10881491,0.10882847,122.3508962216134,1050.0,1.0
0.10941932,0.10943288,122.49882951622786,1050.0,1.0
0.110036475,0.11005003499999999,122.65656112316611,1050.0,1.0
0.11065363,0.11066719,122.83642502993224,1050.0,1.0
0.111274575,0.111288135,123.02818327840906,1050.0,1.0
0.11189552,0.11190908,123.22853246811198,1050.0,1.0
0.113091525,0.113105085,123.4316268585232,1050.0,1.0
0.11428753,0.11430109,123.62797265874414,1050.0,1.0
0.114871555,0.114885115,123.80980534472835,1050.0,1.0
0.11545558,0.11546914,123.96928942323581,1050.0,1.0
0.11608251,0.11609607,124.10163724504604,1050.0,1.0
0.11670944,0.116723,124.22057866424481,1050.0,1.0
0.11735224999999999,0.11736580999999999,124.34502198690967,1050.0,1.0
0.11799506,0.11800862,124.47736449603853,1050.0,1.0
0.118599365,0.118612925,124.61511933847011,1050.0,1.0
0.11920367,0.11921723,124.75214104466778,1050.0,1.0
0.119826895,0.119840455,124.88753348297723,1050.0,1.0
0.12045012000000001,0.12046368,125.02536147102927,1050.0,1.0
0.121074125,0.121087685,125.16292660911387,1050.0,1.0
0.12169813,0.12171169,125.29622770203257,1050.0,1.0
0.122271325,0.122284885,125.42654793867528,1050.0,1.0
0.12284452,0.12285808,125.55716342337556,1050.0,1.0
0.12349738,0.12351094,125.6904759081682,1050.0,1.0
0.12415024000000001,0.1241638,125.8239972879681,1050.0,1.0
0.12475223500000002,0.12476579500000001,125.95523363803134,1050.0,1.0
0.12535423,0.12536779,126.09102807566119,1050.0,1.0
0.125978225,0.12599178500000002,126.231978486295,1050.0,1.0
0.12660222000000002,0.12661578,126.36885142607616,1050.0,1.0
0.12720872500000002,0.127222285,126.49660227183958,1050.0,1.0
0.12781523,0.12782879,126.61666454332232,1050.0,1.0
0.12842253,0.12843609,126.73228517525654,1050.0,1.0
0.12902983,0.12904339,126.84777785807975,1050.0,1.0
0.129631685,0.12964524500000002,126.96287197850747,1050.0,1.0
0.13023354,0.1302471,127.07471885149108,1050.0,1.0
0.13088511000000003,0.13089867,127.18897273387971,1050.0,1.0
0.13153668000000002,0.13155024,127.30826358692067,1050.0,1.0
0.13215537,0.13216893000000002,127.42805366062254,1050.0,1.0
0.13277406,0.13278762,127.54560607447976,1050.0,1.0
0.13337512499999998,0.133388685,127.66265972053789,1050.0,1.0
0.13397619,0.13398975,127.78368007269005,1050.0,1.0
0.13462405,0.13463761,127.90957695175904,1050.0,1.0
0.13527191,0.13528547,128.03403829438517,1050.0,1.0
0.13584374,0.13585730000000001,128.15276161962294,1050.0,1.0
0.13641557,0.13642913,128.27234722261576,1050.0,1.0
0.137037285,0.137050845,128.39515778051035,1050.0,1.0
0.137659,0.13767256,128.5121188315515,1050.0,1.0
0.13826302000000001,0.13827657999999998,128.6231116276301,1050.0,1.0
0.13886704,0.1388806,128.7390571933851,1050.0,1.0
0.13950571,0.13951927,128.8610028686893,1050.0,1.0
0.14014438,0.14015794,128.98141348630043,1050.0,1.0
0.14077154000000003,0.1407851,129.09827322256666,1050.0,1.0
0.14139870000000002,0.14141226,129.2142476105452,1050.0,1.0
0.14198951,0.14200307,129.33256063716522,1050.0,1.0
0.14258032,0.14259388,129.45070044734322,1050.0,1.0
0.143202805,0.143216365,129.5645346569689,1050.0,1.0
0.14382529,0.14383885,129.68293519480585,1050.0,1.0
0.144429905,0.144443465,129.8088954942648,1050.0,1.0
0.14503452,0.14504808,129.92916327375534,1050.0,1.0
0.14565546000000001,0.14566901999999998,130.03957590130227,1050.0,1.0
0.1462764,0.14628996,130.1509422049611,1050.0,1.0
0.146898045,0.146911605,130.26093476132434,1050.0,1.0
0.14751969,0.14753325,130.3605079369783,1050.0,1.0
0.148135935,0.14814949500000002,130.45193345031063,1050.0,1.0
0.14875218,0.14876574,130.54058506607694,1050.0,1.0
0.14937228000000002,0.14938584,130.63181263182574,1050.0,1.0
0.14999238,0.15000594,130.7225278591882,1050.0,1.0
0.15059139,0.15060495000000002,130.81039216952342,1050.0,1.0
0.1511904,0.15120396,130.90524649105348,1050.0,1.0
0.15180891000000002,0.15182247,131.01475076214436,1050.0,1.0
0.15242742,0.15244098,131.13002139642515,1050.0,1.0
0.15303416,0.15304772,131.24135063622685,1050.0,1.0
0.1536409,0.15365446,131.34931471323446,1050.0,1.0
0.15426087,0.15427443,131.45651576989385,1050.0,1.0
0.15488084,0.1548944,131.56390970716208,1050.0,1.0
0.15552359999999998,0.15553716,131.67129194273545,1050.0,1.0
0.15616636,0.15617992,131.78238584944128,1050.0,1.0
0.15677849,0.15679205000000002,131.89688331269758,1050.0,1.0
0.15739062,0.15740418,132.0085724315372,1050.0,1.0
0.15799097,0.15800453,132.115264360454,1050.0,1.0
0.15859132,0.15860488,132.21967727297897,1050.0,1.0
0.15921754500000002,0.15923110499999998,132.3205128178021,1050.0,1.0
0.15984377,0.15985733,132.41541877944744,1050.0,1.0
0.16044559,0.16045915,132.50737608691674,1050.0,1.0
0.16104741,0.16106097,132.60034306721596,1050.0,1.0
0.161684695,0.161698255,132.69719952739536,1050.0,1.0
0.16232198,0.16233554,132.79601363476294,1050.0,1.0
0.16293789,0.16295145,132.8944473150072,1050.0,1.0
0.1635538,0.16356736,132.9945380201409,1050.0,1.0
0.16417681,0.16419037,133.09879247378734,1050.0,1.0
0.16479982,0.16481338,133.20666540798163,1050.0,1.0
0.165401435,0.165414995,133.3124519914253,1050.0,1.0
0.16600305,0.16601661,133.41369277515633,1050.0,1.0
0.166595875,0.166609435,133.51101692621322,1050.0,1.0
0.1671887,0.16720226,133.604772221827,1050.0,1.0
0.167848945,0.167862505,133.69439638507475,1050.0,1.0
0.16850919,0.16852275,133.77726339278425,1050.0,1.0
0.169097145,0.169110705,133.85776369833889,1050.0,1.0
0.1696851,0.16969866,133.94405549980132,1050.0,1.0
0.17033107,0.17034463,134.03884559665806,1050.0,1.0
0.17097704,0.1709906,134.13855603840156,1050.0,1.0
0.17156327999999998,0.17157684,134.2400850588248,1050.0,1.0
0.17214952,0.17216308,134.3447994166778,1050.0,1.0
0.172790705,0.172804265,134.44984104131683,1050.0,1.0
0.17343189,0.17344545,134.5486947534682,1050.0,1.0
0.174061085,0.174074645,134.63774018583982,1050.0,1.0
0.17469028,0.17470384,134.72111439355768,1050.0,1.0
0.17531069,0.17532425000000001,134.80430442366531,1050.0,1.0
0.1759311,0.17594466,134.88530028696727,1050.0,1.0
0.176510595,0.17652415500000002,134.96613241249037,1050.0,1.0
0.17709009,0.17710365,135.05335199585952,1050.0,1.0
0.177715235,0.177728795,135.14915719425613,1050.0,1.0
0.17834038,0.17835394,135.2519770424068,1050.0,1.0
0.17895981,0.17897337,135.3553211308261,1050.0,1.0
0.17957924,0.1795928,135.4529636099134,1050.0,1.0
0.180180185,0.18019374500000002,135.5446070332447,1050.0,1.0
0.18078113,0.18079469,135.6338885526842,1050.0,1.0
0.181421475,0.18143503500000002,135.71737895116198,1050.0,1.0
0.18206182,0.18207538,135.7918317532879,1050.0,1.0
0.18268037,0.18269393,135.8635195182221,1050.0,1.0
0.18329892,0.18331248,135.9389704904007,1050.0,1.0
0.18388597,0.18389953,136.0188743579938,1050.0,1.0
0.18447302000000002,0.18448658,136.09790676649723,1050.0,1.0
0.18510594000000002,0.1851195,136.17342413423603,1050.0,1.0
0.18573886,0.18575242,136.24621183793732,1050.0,1.0
0.1863371,0.18635066,136.32448970658544,1050.0,1.0
0.18693534,0.1869489,136.41373575110816,1050.0,1.0
0.18758929000000002,0.18760285,136.50702256860774,1050.0,1.0
0.18824324,0.1882568,136.60171508695018,1050.0,1.0
0.1888332,0.18884676,136.69993717382442,1050.0,1.0
0.18942316,0.18943672,136.8000975246233,1050.0,1.0
0.190056005,0.190069565,136.89516732381557,1050.0,1.0
0.19068885,0.19070241,136.97911550812185,1050.0,1.0
0.19129328,0.19130683999999998,137.05131723893027,1050.0,1.0
0.19189771,0.19191127,137.12086888824007,1050.0,1.0
0.192538645,0.192552205,137.19519046463617,1050.0,1.0
0.19317958000000002,0.19319314,137.26893316229797,1050.0,1.0
0.193759405,0.19377296500000002,137.34012692800704,1050.0,1.0
0.19433923,0.19435279,137.41320744607614,1050.0,1.0
0.19494587000000002,0.19495943,137.49166007871952,1050.0,1.0
0.19555251,0.19556607,137.5723475691935,1050.0,1.0
0.196189245,0.196202805,137.6530078445464,1050.0,1.0
0.19682598,0.19683954,137.7390489752737,1050.0,1.0
0.19744394,0.1974575,137.8303352944704,1050.0,1.0
0.1980619,0.19807546,137.9219467846064,1050.0,1.0
0.19865112000000001,0.19866468,138.00752787679522,1050.0,1.0
0.19924034000000002,0.1992539,138.0843486034372,1050.0,1.0
0.199872925,0.199886485,138.153799344001,1050.0,1.0
0.20050551,0.20051907,138.21590928834084,1050.0,1.0
0.20111584500000002,0.20112940499999998,138.27329022809988,1050.0,1.0
0.20172618,0.20173974,138.3312117495579,1050.0,1.0
0.20231431,0.20232787000000002,138.39619910471282,1050.0,1.0
0.20290244000000002,0.202916,138.47070478608526,1050.0,1.0
0.203514245,0.203527805,138.55212997865138,1050.0,1.0
0.20412605,0.20413961,138.63587190108933,1050.0,1.0
0.204765,0.20477856,138.71740586440853,1050.0,1.0
0.20540395,0.20541751,138.7944512880377,1050.0,1.0
0.206010735,0.206024295,138.86643940262965,1050.0,1.0
0.20661752,0.20663108,138.93405903205107,1050.0,1.0
0.20724156,0.20725512000000001,139.000236220878,1050.0,1.0
0.2078656,0.20787916,139.06818610270673,1050.0,1.0
0.20846063,0.20847419,139.14238655746956,1050.0,1.0
0.20905566,0.20906922,139.2271819093512,1050.0,1.0
0.20968783000000002,0.20970139,139.31681080587322,1050.0,1.0
0.21032,0.21033356,139.40188460807892,1050.0,1.0
0.210956315,0.210969875,139.48010182389788,1050.0,1.0
0.21159263,0.21160619,139.55378622141058,1050.0,1.0
0.21219983,0.21221339,139.6219635491399,1050.0,1.0
0.21280703,0.21282059,139.68455854030913,1050.0,1.0
0.213438275,0.213451835,139.7434258118425,1050.0,1.0
0.21406952,0.21408308,139.8026540208783,1050.0,1.0
0.21468492,0.21469848000000002,139.8669666428578,1050.0,1.0
0.21530032000000002,0.21531388,139.93027163553757,1050.0,1.0
0.215936445,0.215950005,139.9893546252293,1050.0,1.0
0.21657257,0.21658613,140.05159910988957,1050.0,1.0
0.217186145,0.217199705,140.1194846503874,1050.0,1.0
0.21779972,0.21781328,140.18893744557715,1050.0,1.0
0.21841073500000002,0.218424295,140.25786188010585,1050.0,1.0
0.21902175000000002,0.21903531,140.32671784550905,1050.0,1.0
0.21965693000000003,0.21967049,140.39455556987062,1050.0,1.0
0.22029211,0.22030567,140.45807136804586,1050.0,1.0
0.220871145,0.22088470500000001,140.517030241833,1050.0,1.0
0.22145018,0.22146374,140.57564859743871,1050.0,1.0
0.22209023,0.22210379,140.63959036260513,1050.0,1.0
0.22273028,0.22274384,140.7099275254998,1050.0,1.0
0.22335104,0.2233646,140.783722076053,1050.0,1.0
0.2239718,0.22398536,140.86200830139205,1050.0,1.0
0.22458656999999999,0.22460013,140.94153601108496,1050.0,1.0
0.22520134,0.2252149,141.01212470268612,1050.0,1.0
0.22584043,0.22585399,141.07405180872155,1050.0,1.0
0.22647952000000002,0.22649308,141.1363058769798,1050.0,1.0
0.227095865,0.227109425,141.2001064433745,1050.0,1.0
0.22771221,0.22772577,141.2653272840182,1050.0,1.0
0.22831921,0.22833277,141.33333068678238,1050.0,1.0
0.22892621,0.22893977,141.40394953762674,1050.0,1.0
0.22953727000000002,0.22955082999999998,141.4755364637861,1050.0,1.0
0.23014833,0.23016189,141.540034389403,1050.0,1.0
0.230733095,0.23074665500000002,141.59351097231539,1050.0,1.0
0.23131786000000001,0.23133142,141.64752710854896,1050.0,1.0
0.23197444500000003,0.231988005,141.70707469362767,1050.0,1.0
0.23263103000000002,0.23264459,141.76333167620646,1050.0,1.0
0.23325121000000001,0.23326477,141.81621709975113,1050.0,1.0
0.23387139,0.23388495,141.87398335161777,1050.0,1.0
0.23446511,0.23447867,141.93433854019244,1050.0,1.0
0.23505883,0.23507239,141.9885142260835,1050.0,1.0
0.235694075,0.235707635,142.03460847041953,1050.0,1.0
0.23632932,0.23634288,142.07694209919933,1050.0,1.0
0.23695177,0.23696533,142.12260973234436,1050.0,1.0
0.23757422,0.23758778,142.1721297180668,1050.0,1.0
0.238180385,0.23819394500000002,142.22004434676572,1050.0,1.0
0.23878655000000001,0.23880011,142.2692131087606,1050.0,1.0
0.23942758000000003,0.23944114,142.3252575709322,1050.0,1.0
0.24006861000000002,0.24008217,142.38097140448426,1050.0,1.0
0.24068313000000002,0.24069669,142.43169460864542,1050.0,1.0
0.24129765,0.24131121,142.48247745605954,1050.0,1.0
0.2419232,0.24193676,142.5344845285327,1050.0,1.0
0.24254875,0.24256231,142.58711832726524,1050.0,1.0
0.24314768,0.24316124,142.64403621535888,1050.0,1.0
0.24374661,0.24376017,142.70674159962684,1050.0,1.0
0.24437366500000002,0.24438722499999999,142.77148194428958,1050.0,1.0
0.24500072,0.24501428,142.83348524593754,1050.0,1.0
0.24562175,0.24563531,142.89133321548493,1050.0,1.0
0.24624278,0.24625634,142.95064369963015,1050.0,1.0
0.24684734,0.2468609,143.01216775395653,1050.0,1.0
0.2474519,0.24746546,143.07023495198163,1050.0,1.0
0.248064085,0.248077645,143.12201164973735,1050.0,1.0
0.24867627,0.24868983,143.17143695018336,1050.0,1.0
0.249309905,0.249323465,143.22037703872218,1050.0,1.0
0.24994354,0.2499571,143.26200597897417,1050.0,1.0
0.25057798,0.25059154,143.29830688845433,1050.0,1.0
0.25121242,0.25122598,143.34015839281173,1050.0,1.0
0.25180273,0.25181629,143.39142808676343,1050.0,1.0
0.25239303999999996,0.2524066,143.45184497115508,1050.0,1.0
0.25302554999999993,0.25303911,143.51280771852865,1050.0,1.0
0.25365805999999996,0.25367162,143.56360565905644,1050.0,1.0
0.25423599999999996,0.25424956,143.60556267165126,1050.0,1.0
0.25481393999999996,0.2548275,143.64152561249279,1050.0,1.0
0.25548958999999993,0.25550315,143.66833384959082,1050.0,1.0
0.25616523999999996,0.2561788,143.6902185831252,1050.0,1.0
0.25676893,0.25678249,143.7160153810019,1050.0,1.0
0.25737262,0.25738618,143.74593102488163,1050.0,1.0
0.25796657999999995,0.25798014,143.78391737519715,1050.0,1.0
0.25856053999999995,0.2585741,143.82929421443663,1050.0,1.0
0.259186535,0.25920009499999996,143.8743115415385,1050.0,1.0
0.25981253,0.25982609,143.92071428285223,1050.0,1.0
0.26040798,0.26042154,143.97191216735544,1050.0,1.0
0.26100343,0.26101699,144.02442604691103,1050.0,1.0
0.26165887499999996,0.26167243500000004,144.0743598735068,1050.0,1.0
0.26231432,0.26232788,144.12055057064677,1050.0,1.0
0.26292521,0.26293877,144.1623906144112,1050.0,1.0
0.2635361,0.26354966,144.20395320354226,1050.0,1.0
0.264109255,0.264122815,144.24850091965428,1050.0,1.0
0.26468241,0.26469597,144.29480709107864,1050.0,1.0
0.26528774,0.26530129999999996,144.34010304702588,1050.0,1.0
0.26589306999999995,0.26590663,144.38304792651346,1050.0,1.0
0.26655173,0.26656528999999995,144.42240251388532,1050.0,1.0
0.26721038999999996,0.26722395,144.45415662562982,1050.0,1.0
0.26779271499999996,0.267806275,144.48229966497527,1050.0,1.0
0.26837503999999995,0.2683886,144.51666929041966,1050.0,1.0
0.26901069499999997,0.269024255,144.55789464350667,1050.0,1.0
0.26964635,0.26965991,144.60192266365988,1050.0,1.0
0.27025119999999997,0.27026476,144.6472965496212,1050.0,1.0
0.27085604999999996,0.27086961,144.69210636258978,1050.0,1.0
0.27143694499999993,0.271450505,144.73438593771132,1050.0,1.0
0.27201783999999996,0.2720314,144.77134776353876,1050.0,1.0
0.27267348999999996,0.27268705,144.8011324332868,1050.0,1.0
0.27332913999999997,0.2733427,144.83138763188995,1050.0,1.0
0.27397505999999994,0.27398862,144.86798964862956,1050.0,1.0
0.27462097999999996,0.27463454,144.90688075227945,1050.0,1.0
0.27522883,0.27524239,144.94331433575834,1050.0,1.0
0.27583668,0.27585024,144.97480626695378,1050.0,1.0
0.276491315,0.276504875,145.0028354733046,1050.0,1.0
0.27714595,0.27715951,145.02943604941262,1050.0,1.0
0.27774822499999996,0.27776178500000004,145.05641693056197,1050.0,1.0
0.2783505,0.27836406,145.08824323026658,1050.0,1.0
0.2789855,0.27899906,145.125882984534,1050.0,1.0
0.2796205,0.27963406,145.1641412705455,1050.0,1.0
0.280213625,0.280227185,145.20205834035798,1050.0,1.0
0.28080675,0.28082031,145.24015153200952,1050.0,1.0
0.28142548999999994,0.28143905,145.27701142062872,1050.0,1.0
0.28204422999999995,0.28205779,145.31442355617708,1050.0,1.0
0.28265303499999994,0.282666595,145.35356447759628,1050.0,1.0
0.28326184,0.2832754,145.39553828086144,1050.0,1.0
0.28387852,0.28389208,145.44033048327358,1050.0,1.0
0.2844952,0.28450876,145.48426452040562,1050.0,1.0
0.285091265,0.285104825,145.522924261744,1050.0,1.0
0.28568732999999996,0.28570089,145.55650148647504,1050.0,1.0
0.286323385,0.28633694499999995,145.58737493439372,1050.0,1.0
0.28695943999999995,0.286973,145.61755411314294,1050.0,1.0
0.28758918,0.28760273999999997,145.6475957666455,1050.0,1.0
0.28821892,0.28823248,145.67971746957076,1050.0,1.0
0.288809985,0.288823545,145.7115117359859,1050.0,1.0
0.28940105,0.28941461,145.7358477842884,1050.0,1.0
0.29004666,0.29006022,145.7537025671233,1050.0,1.0
0.29069227,0.29070583,145.7693042670662,1050.0,1.0
0.29129923999999996,0.29131280000000004,145.78358755517866,1050.0,1.0
0.29190621,0.29191977,145.79759474530684,1050.0,1.0
0.29253182,0.29254538,145.81430668814622,1050.0,1.0
0.29315743,0.29317099,145.83567502754394,1050.0,1.0
0.29378390499999996,0.29379746500000004,145.86275255544243,1050.0,1.0
0.29441037999999997,0.29442394,145.89061305074262,1050.0,1.0
0.29503033999999995,0.2950439,145.91455334704543,1050.0,1.0
0.2956503,0.29566386,145.93992197862025,1050.0,1.0
0.29626387,0.29627743,145.9678944442911,1050.0,1.0
0.29687744,0.296891,145.9918713883505,1050.0,1.0
0.29749899999999996,0.29751256000000004,146.0117146914437,1050.0,1.0
0.29812056,0.29813412,146.03096816151373,1050.0,1.0
0.298750105,0.298763665,146.05198988260577,1050.0,1.0
0.29937965,0.29939321,146.0763552546495,1050.0,1.0
0.29995562499999995,0.299969185,146.1035234389912,1050.0,1.0
0.30053159999999995,0.30054516,146.1361544225628,1050.0,1.0
0.301144525,0.30115808499999996,146.17275062404389,1050.0,1.0
0.30175745,0.30177101,146.20424245683733,1050.0,1.0
0.30238930499999994,0.302402865,146.2254414413401,1050.0,1.0
0.30302115999999996,0.30303472,146.23880694171245,1050.0,1.0
0.303650155,0.303663715,146.24894699146103,1050.0,1.0
0.30427915,0.30429271,146.25882068647758,1050.0,1.0
0.30487619499999996,0.30488975500000004,146.2722082531358,1050.0,1.0
0.30547324,0.3054868,146.29307562177783,1050.0,1.0
0.306107435,0.306120995,146.32160787834738,1050.0,1.0
0.30674163,0.30675519,146.35168169495643,1050.0,1.0
0.30793565999999994,0.30794922,146.37876448314617,1050.0,1.0
0.30912968999999996,0.30914325,146.405498972929,1050.0,1.0
0.30973697,0.30975052999999997,146.4298322976761,1050.0,1.0
0.31034425,0.31035781,146.44689380612704,1050.0,1.0
0.310955855,0.31096941499999997,146.45865019505422,1050.0,1.0
0.31156745999999996,0.31158102,146.47132632277325,1050.0,1.0
0.31219087999999995,0.31220444,146.4867883734293,1050.0,1.0
0.3128143,0.31282786,146.50347330896963,1050.0,1.0
0.313416455,0.313430015,146.51787188014987,1050.0,1.0
0.31401861,0.31403217,146.5279130531123,1050.0,1.0
0.31459938,0.31461294,146.5365192897298,1050.0,1.0
0.31518015,0.31519371,146.54402186343611,1050.0,1.0
0.3158316,0.31584516,146.54659327021108,1050.0,1.0
0.31648305,0.31649661,146.5428459613384,1050.0,1.0
0.31709111999999995,0.31710468,146.54092923035364,1050.0,1.0
0.31769918999999996,0.31771275,146.54902018568538,1050.0,1.0
0.31832640999999995,0.31833997,146.56547504905535,1050.0,1.0
0.31895363,0.31896719,146.581336209025,1050.0,1.0
0.319581625,0.319595185,146.5954977771444,1050.0,1.0
0.32020962,0.32022318,146.61595821793125,1050.0,1.0
0.32080886999999997,0.32082243,146.64198676518276,1050.0,1.0
0.32140811999999996,0.32142168,146.66693503634883,1050.0,1.0
0.322008025,0.322021585,146.68353279582,1050.0,1.0
0.32260793,0.32262149,146.69213552562826,1050.0,1.0
0.32326056,0.32327412,146.69911093149676,1050.0,1.0
0.32391318999999996,0.32392675,146.70304235954305,1050.0,1.0
0.3245146,0.32452815999999995,146.7001602961495,1050.0,1.0
0.32511600999999996,0.32512957,146.69628083738772,1050.0,1.0
0.32574421,0.32575777,146.69874047882843,1050.0,1.0
0.32637241,0.32638597,146.704585869408,1050.0,1.0
0.32698278000000003,0.32699634,146.71253487709203,1050.0,1.0
0.32759315,0.32760671,146.7242653978877,1050.0,1.0
0.328207985,0.328221545,146.7360013220301,1050.0,1.0
0.32882281999999996,0.32883638,146.747008828944,1050.0,1.0
0.32944960999999995,0.32946317,146.7567563241797,1050.0,1.0
0.3300764,0.33008996,146.76203618439285,1050.0,1.0
0.330703975,0.330717535,146.76265722223098,1050.0,1.0
0.33133155,0.33134511,146.75805102945262,1050.0,1.0
0.331952465,0.331966025,146.75051017533013,1050.0,1.0
0.33257338,0.33258694,146.74785909150575,1050.0,1.0
0.333168805,0.333182365,146.7527656802459,1050.0,1.0
0.33376423,0.33377779,146.75979926253544,1050.0,1.0
0.33440912,0.33442267999999997,146.767932106708,1050.0,1.0
0.33505400999999996,0.33506757,146.7757324294769,1050.0,1.0
0.33564715,0.33566071,146.7857916197615,1050.0,1.0
0.33624029,0.33625385,146.79428815346574,1050.0,1.0
0.336860475,0.336874035,146.79994275649082,1050.0,1.0
0.33748066,0.33749422,146.80147615473805,1050.0,1.0