File: datasets/am_bench_2022/raw_data/TH3-I/specimen.dat
MTS793|MPT|ENU|1|2|.|/|:|1|0|0|A

Operator Information						Time:	9.4741211	Sec	11/3/2021 1:47:30 PM
Operator	Nick Derimow
Project	AM Bench 2022 mini-tensile challenge
Specimen ID	TH3-I
Material	PBF-L Inconel 625
Specimen Width	2.56	mm
Specimen Thickness	1.51	mm
Notes
Operator Information End

Data Acquisition						Time:	1010.4678	Sec	11/3/2021 2:04:11 PM
Time	Axial Displacement	Axial Extensometer	Axial Force
Sec	mm	mm	N
9.5876465	0.00094349578	0.00019651042	62.549889
10.588623	0.005565119	9.1123722e-05	73.743759
11.5896	0.008131993	0.00026912685	83.351265
12.590576	0.0079961503	0.0005216765	90.948235
13.591553	0.011604024	0.00038654884	101.65633
14.592529	0.015372174	0.00035287297	114.83442
15.593506	0.019554511	0.0005058056	124.46661
16.594482	0.022801161	0.00039333483	136.56831
17.595459	0.024847202	0.00042895717	149.40355
18.596436	0.026442483	0.00065471936	160.56262
19.597412	0.031531718	0.00083570566	170.0311
20.598389	0.034572456	0.0008775926	190.43808
21.599365	0.037180051	0.0011277368	209.83432
22.600342	0.040327176	0.00097736111	230.65921
23.601318	0.040144619	0.0012312518	241.52998
24.602295	0.046820886	0.0013339575	259.10898
25.603271	0.050281651	0.0012860222	282.33719
26.604248	0.052311301	0.0017476856	298.14923
27.605225	0.054020502	0.0018398035	320.21597
28.606201	0.058212928	0.0016532718	338.10794
29.607178	0.062413551	0.0024437904	353.78537
30.608154	0.060097259	0.0021612612	378.24014
31.609131	0.067455456	0.0022335455	405.80499
32.610107	0.06765154	0.0026705442	419.39542
33.611084	0.070676088	0.0028064803	448.13547
34.612061	0.076137148	0.0030552146	467.23648
35.613037	0.077459723	0.0030797238	491.55154
36.614014	0.083483666	0.0032015746	515.39655
37.61499	0.084466942	0.0036653811	547.38068
38.615967	0.088485003	0.0038262142	570.98651
39.616943	0.091558114	0.0038823134	599.1767
40.61792	0.091118619	0.0040396024	627.96436
41.618896	0.095953226	0.0041856882	646.19043
42.619873	0.09920726	0.0044878041	672.88647
43.62085	0.1011758	0.0046247309	703.47589
44.621826	0.10390326	0.004786151	727.36304
45.622803	0.10487628	0.0050648241	751.90588
46.623779	0.10751794	0.0052187731	776.64886
47.624756	0.10927775	0.0053584985	801.98743
48.625732	0.11566205	0.0055458858	835.85107
49.626709	0.11739476	0.0058219694	862.3111
50.627686	0.12230006	0.0060976758	893.09985
51.628662	0.12256478	0.0063096536	919.69354
52.629639	0.12747754	0.0065469309	949.37347
53.630615	0.12961292	0.006772771	977.77356
54.631592	0.13236435	0.0067123333	996.85596
55.632568	0.13899826	0.0070140935	1030.7526
56.633545	0.14049841	0.0071733245	1053.2722
57.634521	0.1446722	0.0074678236	1088.0507
58.635498	0.1456856	0.0080274353	1115.3987
59.636475	0.14897205	0.0083853956	1142.8381
60.637451	0.15306756	0.0080533167	1164.2955
61.638428	0.15472507	0.0080897054	1186.725
62.639404	0.15675221	0.0083227744	1210.2932
63.640381	0.15965061	0.0085104033	1241.9174
64.641357	0.16654186	0.0087148128	1275.525
65.642334	0.16668999	0.0089053744	1304.3907
66.643311	0.17090614	0.0091893254	1333.5494
67.644287	0.17230575	0.0093616825	1361.0521
68.645264	0.17340191	0.0094671017	1386.5909
69.64624	0.17983893	0.0097755948	1419.0155
70.647217	0.17995837	0.0099792778	1443.6077
71.648193	0.18917263	0.010142227	1478.1995
72.64917	0.18858111	0.010274112	1499.3566
73.650146	0.18949144	0.010366649	1520.9041
74.651123	0.19068897	0.010687529	1552.2181
75.6521	0.19965428	0.010799336	1577.8232
76.653076	0.20183104	0.01104506	1614.9794
77.654053	0.2020472	0.011263995	1630.924
78.655029	0.20602491	0.011449788	1669.2385
79.656006	0.21206601	0.011636552	1706.0778
80.656982	0.21282923	0.011848874	1721.5684
81.657959	0.21475418	0.012038077	1747.5439
82.658936	0.21782525	0.012130149	1768.9001
83.659912	0.22335233	0.012360977	1801.5474
84.660889	0.22498834	0.012496737	1823.6536
85.661865	0.22579847	0.012644048	1850.8363
86.662842	0.23123296	0.012851927	1876.5488
87.663818	0.2321693	0.012984904	1895.2172
88.664795	0.23715486	0.013214297	1923.6089
89.665771	0.2389138	0.013304748	1945.0638
90.666748	0.23961228	0.013488688	1968.9718
91.667725	0.24787994	0.013757526	2001.2645
92.668701	0.24626155	0.013849108	2015.3348
93.669678	0.25173387	0.014119959	2048.9324
94.670654	0.25577146	0.014157862	2064.9392
95.671631	0.25530368	0.014377631	2086.1162
96.672607	0.26316586	0.014520369	2110.1929
97.673584	0.26048636	0.014656165	2126.0581
98.674561	0.26509181	0.014786072	2145.678
99.675537	0.26917404	0.014942164	2167.0129
100.67651	0.2717675	0.015083459	2187.4868
101.67749	0.27262518	0.015149339	2203.0508
102.67847	0.27891934	0.015397451	2226.8484
103.67944	0.27989808	0.015581453	2243.9797
104.68042	0.28259569	0.015631881	2264.8958
105.6814	0.28790697	0.015913947	2284.1484
106.68237	0.29173982	0.016018944	2306.3425
107.68335	0.29266593	0.016238462	2321.4919
108.68433	0.29560775	0.016309312	2336.4719
109.6853	0.29850158	0.016408855	2346.6746
110.68628	0.30189759	0.016630983	2361.3374
111.68726	0.30779186	0.016830258	2388.1838
112.68823	0.30845281	0.01694731	2396.5962
113.68921	0.30915457	0.017145718	2415.0339
114.69019	0.31607711	0.017253824	2427.5037
115.69116	0.31669015	0.017460577	2443.2849
116.69214	0.32178617	0.01763517	2463.0044
117.69312	0.32260019	0.017756764	2464.6479
118.69409	0.32555139	0.017921863	2475.0977
119.69507	0.33237109	0.018223824	2500.4268
120.69604	0.33421406	0.01837166	2514.1865
121.69702	0.3395381	0.018566024	2526.6067
122.698	0.33898163	0.018742938	2530.8115
123.69897	0.34549972	0.018929714	2551.8687
124.69995	0.34709397	0.019085528	2555.8164
125.70093	0.35093486	0.019235959	2573.4519
126.7019	0.3509281	0.019461865	2583.4824
127.70288	0.35490063	0.019664731	2590.2844
128.70386	0.35803935	0.019836549	2596.1453
129.70483	0.35904819	0.020116949	2608.2151
130.70581	0.36121267	0.020288939	2620.4922
131.70679	0.36798528	0.02036055	2623.7144
132.70776	0.36946556	0.020738389	2641.7781
133.70874	0.37347913	0.020987926	2654.4216
134.70972	0.37564009	0.021324789	2659.6199
135.71069	0.37923446	0.021555394	2668.2466
136.71167	0.38107479	0.021740798	2671.9297
137.71265	0.38592711	0.022078017	2692.595
138.71362	0.38898984	0.022294313	2697.7791
139.7146	0.38987577	0.02245491	2701.543
140.71558	0.39375553	0.022899562	2711.1826
141.71655	0.39761871	0.023337491	2721.6348
142.71753	0.39948153	0.023623163	2727.7778
143.71851	0.40288129	0.023941953	2734.4414
144.71948	0.40369552	0.024309263	2740.7668
145.72046	0.41029844	0.02473502	2757.2307
146.72144	0.41167101	0.025088171	2761.4128
147.72241	0.41768777	0.02574395	2778.8325
148.72339	0.420975	0.026183506	2776.968
149.72437	0.4229548	0.026705492	2785.5217
150.72534	0.42328653	0.027276464	2791.022
151.72632	0.42873308	0.027859785	2806.1436
152.72729	0.43251801	0.028354088	2807.6233
153.72827	0.43384302	0.028765917	2808.2793
154.72925	0.43770251	0.029599069	2830.2983
155.73022	0.44070902	0.030052142	2826.5786
156.7312	0.44208813	0.030665403	2826.2195
157.73218	0.4462736	0.031367507	2845.72
158.73315	0.44878572	0.031951919	2844.8247
159.73413	0.45114586	0.032684945	2848.969
160.73511	0.45453677	0.033553362	2861.7134
161.73608	0.45915434	0.034144443	2859.2546
162.73706	0.46108624	0.034829214	2865.7163
163.73804	0.46372396	0.03534903	2868.1035
164.73901	0.46623996	0.036195505	2874.2107
165.73999	0.46718308	0.036940504	2882.6157
166.74097	0.47139299	0.037569936	2887.1765
167.74194	0.47549176	0.038356479	2889.5818
168.74292	0.4773339	0.038965732	2888.5449
169.7439	0.48246309	0.03976753	2898.4131
170.74487	0.48560387	0.040798485	2908.3147
171.74585	0.48842168	0.041727699	2910.0007
172.74683	0.49217623	0.042553946	2915.4438
173.7478	0.4911522	0.043575887	2916.4253
174.74878	0.49554604	0.044676345	2926.4958
175.74976	0.4979609	0.045463495	2921.8308
176.75073	0.50193119	0.046556294	2937.3799
177.75171	0.50217462	0.047428947	2936.9399
178.75269	0.50961351	0.048184197	2930.812
179.75366	0.51270115	0.049112402	2947.0093
180.75464	0.51613981	0.050032541	2942.7275
181.75562	0.51915145	0.050950624	2948.2617
182.75659	0.51859808	0.051933274	2948.3357
183.75757	0.52167815	0.052972738	2955.8508
184.75854	0.5285309	0.054104175	2966.4441
185.75952	0.53211004	0.055157639	2965.1726
186.7605	0.53125405	0.056134377	2968.3057
187.76147	0.53337932	0.057270076	2970.7405
188.76245	0.54065967	0.058140479	2978.2751
189.76343	0.54268724	0.058982797	2974.0962
190.7644	0.5444665	0.059918076	2980.0479
191.76538	0.54695666	0.06101222	2992.9473
192.76636	0.54837531	0.061950032	2986.3342
193.76733	0.55514508	0.062888376	2989.8008
194.76831	0.55557513	0.06402047	2993.3152
195.76929	0.55796164	0.065219618	3002.1563
196.77026	0.56391245	0.066355929	3006.5242
197.77124	0.56621873	0.067452773	3010.1638
198.77222	0.5666557	0.068325877	3005.3997
199.77319	0.57116389	0.069190077	3006.9102
200.77417	0.5727151	0.070209295	3007.9546
201.77515	0.57998496	0.071073137	3015.1313
202.77612	0.57958627	0.071909919	3013.2224
203.7771	0.58240652	0.072868049	3019.0874
204.77808	0.58525854	0.073951684	3022.4187
205.77905	0.58758032	0.074962854	3027.8076
206.78003	0.59355348	0.076059408	3035.738
207.78101	0.59498012	0.07711298	3028.1216
208.78198	0.59806287	0.078385405	3044.7224
209.78296	0.60064876	0.079275869	3038.8259
210.78394	0.60462117	0.080182113	3044.0627
211.78491	0.60750556	0.081309803	3044.2764
212.78589	0.61233503	0.082401276	3050.8027
213.78687	0.6140452	0.083518982	3046.5803
214.78784	0.61892587	0.084657684	3056.322
215.78882	0.61647171	0.085912086	3059.9009
216.78979	0.62380791	0.087140724	3060.1013
217.79077	0.62379193	0.088022605	3056.0286
218.79175	0.62596893	0.089049436	3058.7334
219.79272	0.6321125	0.090026408	3065.4854
220.7937	0.63453716	0.091156222	3077.3049
221.79468	0.63606954	0.092221878	3072.1086
222.79565	0.64160538	0.093366176	3074.158
223.79663	0.64607918	0.094552726	3077.0781
224.79761	0.64612341	0.095614061	3075.325
225.79858	0.65112656	0.096553855	3080.835
226.79956	0.65156358	0.09749119	3082.0496
227.80054	0.65716892	0.09863387	3086.2231
228.80151	0.65629506	0.099522375	3078.1873
229.80249	0.65862226	0.10052571	3094.3892
230.80347	0.66308326	0.10175092	3092.377
231.80444	0.66625988	0.1029225	3094.1792
232.80542	0.66807741	0.10392907	3094.4915
233.8064	0.67287964	0.10507911	3101.0972
234.80737	0.67786103	0.10618871	3104.7588
235.80835	0.67946798	0.10710308	3101.3679
236.80933	0.68434745	0.10829112	3113.1199
237.8103	0.68329716	0.10926376	3104.8933
238.81128	0.6868965	0.11045533	3112.489
239.81226	0.69420952	0.11147497	3110.0852
240.81323	0.69236535	0.11236635	3108.9705
241.81421	0.69870585	0.11348725	3117.5229
242.81519	0.69769716	0.11441226	3123.991
243.81616	0.70283514	0.11550272	3115.8542
244.81714	0.7066381	0.11652863	3126.5747
245.81812	0.71279091	0.11756326	3126.9124
246.81909	0.71378177	0.11868086	3133.2534
247.82007	0.71528149	0.11961017	3126.2373
248.82104	0.71735436	0.12080823	3131.8474
249.82202	0.72282058	0.12206534	3138.8708
250.823	0.72408575	0.1231971	3139.9028
251.82397	0.72650945	0.12432967	3137.7852
252.82495	0.73130888	0.12528317	3144.4946
253.82593	0.73346847	0.12631674	3142.0562
254.8269	0.73806596	0.12735167	3140.6917
255.82788	0.73953521	0.1282846	3144.1006
256.82886	0.74182111	0.12930433	3150.9539
257.82983	0.74762762	0.13043401	3154.5774
258.83081	0.74830729	0.13154311	3155.9802
259.83179	0.75126714	0.13250598	3152.106
260.83276	0.75400895	0.13353287	3160.7134
261.83374	0.75713432	0.13454007	3158.3777
262.83472	0.76451665	0.13573273	3169.4573
263.83569	0.76304901	0.13683438	3169.5283
264.83667	0.76331168	0.13810465	3165.7068
265.83765	0.76939589	0.13917854	3161.1802
266.83862	0.77351701	0.14026265	3172.252
267.8396	0.77635121	0.14123644	3172.334
268.84058	0.7757175	0.14227726	3168.9119
269.84155	0.78344858	0.14315924	3174.5686
270.84253	0.78436959	0.14419813	3181.0664
271.84351	0.78938603	0.1452487	3182.7522
272.84448	0.79288697	0.14624457	3174.6226
273.84546	0.79499668	0.14726309	3180.6018
274.84644	0.799142	0.14814657	3187.0342
275.84741	0.80068403	0.1491996	3190.2637
276.84839	0.80245608	0.15032604	3184.7747
277.84937	0.8051129	0.15145794	3190.093
278.85034	0.80851793	0.15240024	3191.981
279.85132	0.81203848	0.15350738	3192.0688
280.85229	0.81796491	0.15461263	3200.6123
281.85327	0.81752461	0.15563378	3194.3237
282.85425	0.82147139	0.1567679	3198.0222
283.85522	0.8230142	0.15761691	3194.2993
284.8562	0.82704663	0.15857188	3197.0374
285.85718	0.83336908	0.15963954	3205.1711
286.85815	0.83311176	0.16065124	3211.2363
287.85913	0.83651167	0.16165216	3208.958
288.86011	0.83945304	0.16285335	3212.4216
289.86108	0.84288794	0.16413063	3217.3423
290.86206	0.84494835	0.16501537	3210.1755
291.86304	0.84492338	0.16592512	3216.533
292.86401	0.85209095	0.16694377	3218.3296
293.86499	0.854514	0.16810799	3216.573
294.86597	0.85563982	0.16910748	3215.5984
295.86694	0.86241388	0.17022462	3227.7346
296.86792	0.86182564	0.17114541	3221.7419
297.8689	0.86717671	0.17222257	3228.4414
298.86987	0.86711729	0.1734083	3224.4097
299.87085	0.87154204	0.17442627	3227.5549
300.87183	0.87501556	0.17564231	3240.1433
301.8728	0.87575561	0.17656137	3229.5383
302.87378	0.8782354	0.1776417	3233.1504
303.87476	0.88517904	0.17874859	3234.4541
304.87573	0.88675243	0.17976931	3240.6707
305.87671	0.89045638	0.1807915	3239.0178
306.87769	0.89008451	0.18177283	3235.584
307.87866	0.89590496	0.18274587	3246.7859
308.87964	0.90058649	0.18384303	3243.2637
309.88062	0.90390956	0.18482466	3247.8672
310.88159	0.90569001	0.18572347	3246.3892
311.88257	0.90604776	0.18666293	3241.603
312.88354	0.91199547	0.18762797	3248.6707
313.88452	0.9131974	0.18850058	3249.4009
314.8855	0.91605967	0.18966629	3255.3704
315.88647	0.92180717	0.19061118	3257.7068
316.88745	0.92434347	0.1917195	3256.7554
317.88843	0.92612725	0.19275528	3257.5454
318.8894	0.92737341	0.19368668	3259.6746
319.89038	0.9333756	0.19469608	3261.9426
320.89136	0.93549418	0.19583061	3275.9946
321.89233	0.93679088	0.19697139	3264.2849
322.89331	0.94328707	0.19822139	3270.3662
323.89429	0.94610715	0.19931085	3270.9534
324.89526	0.94957983	0.20039959	3274.8684
325.89624	0.95211637	0.20149362	3280.1157
326.89722	0.95123696	0.20249647	3273.0325
327.89819	0.9562844	0.20353712	3277.3596
328.89917	0.95808357	0.20465763	3277.0354
329.90015	0.96035779	0.20572236	3275.1462
330.90112	0.9674986	0.2064725	3274.522
331.9021	0.96878821	0.20719047	3279.4207
332.90308	0.97389358	0.20830357	3287.1807
333.90405	0.97464859	0.20932485	3284.3035
334.90503	0.9784376	0.21034187	3281.259
335.90601	0.97965711	0.21139443	3286.5576
336.90698	0.98217332	0.21243331	3296.1189
337.90796	0.98755288	0.21354684	3289.7839
338.90894	0.98992425	0.21478836	3301.8584
339.90991	0.99190247	0.21582469	3293.4646
340.91089	0.9977721	0.21681423	3293.4653
341.91187	0.99813294	0.21797091	3297.4507
342.91284	1.0005237	0.21889015	3293.8445
343.91382	1.001181	0.21985923	3295.7185
344.91479	1.0084292	0.22091602	3301.354
345.91577	1.0086943	0.2219539	3303.6255
346.91675	1.0141206	0.22302864	3309.4556
347.91772	1.0156431	0.22409445	3308.3762
348.9187	1.0208519	0.22516726	3307.2654
349.91968	1.0203738	0.22601257	3303.645
350.92065	1.0258486	0.22695103	3311.0139
351.92163	1.0259672	0.22803789	3309.0513
352.92261	1.0302958	0.22905216	3315.7524
353.92358	1.0341542	0.23004581	3311.9768
354.92456	1.0386062	0.23101512	3317.697
355.92554	1.0409942	0.23208134	3319.0273
356.92651	1.0420434	0.23312218	3319.4634
357.92749	1.0459216	0.23418848	3319.5991
358.92847	1.0472155	0.23526588	3323.3296
359.92944	1.0538805	0.23629411	3326.3538
360.93042	1.0558087	0.23741208	3326.3416
361.9314	1.0608424	0.23851854	3330.9407
362.93237	1.0601668	0.23973933	3329.4146
363.93335	1.0622725	0.24092025	3328.834
364.93433	1.0683832	0.24205358	3332.2056
365.9353	1.0679069	0.24287629	3326.0779
366.93628	1.0743388	0.24394488	3335.1123
367.93726	1.0769746	0.24473171	3325.2166
368.93823	1.0780538	0.24565157	3338.0156
369.93921	1.082979	0.24678019	3341.4446
370.94019	1.0841869	0.24778639	3340.4495
371.94116	1.0891039	0.24907574	3348.6479
372.94214	1.0928695	0.2501598	3343.9763
373.94312	1.0935683	0.25087941	3335.7939
374.94409	1.0982158	0.25208178	3349.4619
375.94507	1.1003437	0.25289696	3345.532
376.94604	1.1029419	0.25394076	3341.3826
377.94702	1.1082522	0.25482446	3349.8892
378.948	1.1098275	0.25599688	3354.311
379.94897	1.1095585	0.25713584	3348.908
380.94995	1.1131027	0.2580885	3349.23
381.95093	1.1186008	0.25918588	3356.468
382.9519	1.1192037	0.25990477	3345.1006
383.95288	1.1226519	0.26065689	3348.8218
384.95386	1.127125	0.26160237	3356.4402
385.95483	1.1302543	0.26289153	3366.2866
386.95581	1.1355257	0.26397565	3366.9368
387.95679	1.1345541	0.26490611	3355.989
388.95776	1.1378163	0.26600328	3365.3259
389.95874	1.1414287	0.2671195	3360.981
390.95972	1.1480449	0.26808482	3369.0481
391.96069	1.1505672	0.26896963	3361.5466
392.96167	1.1532879	0.26995307	3372.0032
393.96265	1.1558275	0.27089578	3376.5132
394.96362	1.1577973	0.27205068	3374.8738
395.9646	1.1608081	0.2731677	3375.8064
396.96558	1.1655097	0.27420098	3379.7346
397.96655	1.1652412	0.27525809	3375.364
398.96753	1.1697761	0.27622464	3377.8218
399.96851	1.1723391	0.27736709	3381.5796
400.96948	1.1724725	0.27858761	3381.345
401.97046	1.1810927	0.27963036	3382.1914
402.97144	1.1838256	0.28066513	3385.6187
403.97241	1.1848298	0.28171518	3387.1755
404.97339	1.1876503	0.28279358	3385.1301
405.97437	1.1900465	0.28368527	3382.5283
406.97534	1.1909893	0.28458536	3385.0325
407.97632	1.1975578	0.28558022	3390.8315
408.97729	1.1998974	0.28658521	3392.7927
409.97827	1.2013419	0.28767389	3385.448
410.97925	1.2072506	0.28856945	3388.575
411.98022	1.2091103	0.28969577	3400.8989
412.9812	1.2109007	0.29086107	3392.0833
413.98218	1.2178507	0.29176235	3392.804
414.98315	1.2176913	0.29263237	3395.8059
415.98413	1.2202871	0.2937181	3401.0757
416.98511	1.2243488	0.29460111	3394.9414
417.98608	1.2261213	0.29541737	3394.8608
418.98706	1.2275732	0.29626173	3399.9785
419.98804	1.2326766	0.29713565	3395.7
420.98901	1.2357404	0.29805663	3404.9272
421.98999	1.235743	0.29896221	3400.4429
422.99097	1.2389851	0.3001211	3410.9209
423.99194	1.2457223	0.30116719	3411.4094
424.99292	1.2487539	0.30216408	3410.3323
425.9939	1.2492551	0.30354714	3420.5129
426.99487	1.2528607	0.30460778	3412.4175
427.99585	1.256229	0.30562019	3416.9507
428.99683	1.2568582	0.30675825	3414.021
429.9978	1.2643782	0.30780911	3416.2808
430.99878	1.2648516	0.3087942	3410.7461
431.99976	1.2684931	0.30995023	3422.3374
433.00073	1.2706838	0.31093022	3416.2334
434.00171	1.274233	0.31186938	3414.177
435.00269	1.2784457	0.31274122	3420.0078
436.00366	1.2814766	0.31386039	3425.9338
437.00464	1.2828648	0.31497279	3430.5295
438.00562	1.2881181	0.31617707	3428.9468
439.00659	1.2893345	0.31730646	3424.0916
440.00757	1.2898554	0.31810039	3426.9907
441.00854	1.2958282	0.31931213	3432.1221
442.00952	1.298416	0.32034689	3429.825
443.0105	1.3012867	0.32128033	3430.9336
444.01147	1.3060271	0.32225347	3431.7561
445.01245	1.3092681	0.32300833	3431.813
446.01343	1.3097459	0.32403618	3437.1174
447.0144	1.3107202	0.32496908	3437.4014
448.01538	1.3196056	0.32619354	3441.8572
449.01636	1.3183253	0.32750493	3442.8665
450.01733	1.3222812	0.32858709	3436.4998
451.01831	1.3260217	0.32954615	3443.0891
452.01929	1.3277221	0.33065125	3444.3091
453.02026	1.3312792	0.33153436	3435.9612
454.02124	1.3351456	0.33260068	3443.3884
455.02222	1.3370605	0.33356765	3440.5984
456.02319	1.3407352	0.33472836	3444.885
457.02417	1.3439466	0.3356477	3447.2361
458.02515	1.3485582	0.33669758	3451.1079
459.02612	1.3456361	0.33761987	3443.1602
460.0271	1.3544095	0.33849475	3447.3892
461.02808	1.3574953	0.33948779	3456.7043
462.02905	1.3578925	0.34063202	3461.4944
463.03003	1.361039	0.34175354	3455.5471
464.03101	1.3646108	0.34293276	3460.4346
465.03198	1.3677962	0.34398901	3452.8755
466.03296	1.368045	0.34483925	3451.4033
467.03394	1.3729336	0.3458803	3458.1575
468.03491	1.3788768	0.34697279	3456.8887
469.03589	1.3796006	0.34793052	3456.782
470.03687	1.3851639	0.34897429	3461.3472
471.03784	1.3853087	0.35014856	3470.6179
472.03882	1.388572	0.35130641	3457.4248
473.03979	1.3920002	0.35243145	3468.3281
474.04077	1.395571	0.35355282	3466.5781
475.04175	1.4005638	0.35442248	3465.428
476.04272	1.4021002	0.35555342	3473.4409
477.0437	1.404888	0.35654616	3471.3604
478.04468	1.4085695	0.35763621	3479.3611
479.04565	1.4100896	0.35864422	3474.5811
480.04663	1.4101666	0.3597165	3466.3586
481.04761	1.4196416	0.36078387	3478.0601
482.04858	1.4202183	0.36178476	3473.2163
483.04956	1.4215717	0.36278784	3479.9629
484.05054	1.4236892	0.36389971	3478.4902
485.05151	1.4277723	0.36511016	3477.5603
486.05249	1.4316567	0.36616746	3479.6565
487.05347	1.4330615	0.3672429	3477.812
488.05444	1.4348762	0.36824772	3480.0581
489.05542	1.4415351	0.36910328	3483.4741
490.0564	1.4452556	0.37000778	3478.6521
491.05737	1.4467494	0.37105599	3484.5215
492.05835	1.4487364	0.37195483	3483.0188
493.05933	1.4509853	0.37299755	3488.1487
494.0603	1.4523097	0.37432334	3493.6418
495.06128	1.4586719	0.37546787	3487.8015
496.06226	1.4606712	0.37652192	3491.2393
497.06323	1.4629434	0.37763092	3493.2478
498.06421	1.4665408	0.37846729	3489.8987
499.06519	1.4694268	0.3794108	3487.7004
500.06616	1.4706893	0.38040805	3494.6992
501.06714	1.4753517	0.38128635	3491.6912
502.06812	1.4791598	0.38238364	3498.0027
503.06909	1.4828032	0.38370544	3497.1978
504.07007	1.4849364	0.3847807	3502.6396
505.07104	1.4887967	0.38579223	3499.7097
506.07202	1.4897919	0.38699138	3499.0291
507.073	1.4944949	0.38818133	3502.1951
508.07397	1.4949075	0.38921693	3500.3137
509.07495	1.4994789	0.39024377	3500.9592
510.07593	1.5008601	0.39141279	3505.991
511.0769	1.5027996	0.3925373	3503.3274
512.07788	1.5097551	0.39357153	3506.324
513.07886	1.5104868	0.39465246	3502.2324
514.07983	1.5150193	0.39563873	3508.0842
515.08081	1.5208337	0.39674479	3512.4448
516.08179	1.5207516	0.39780977	3511.7083
517.08276	1.5222822	0.39900199	3510.9539
518.08374	1.5254539	0.40003598	3510.7261
519.08472	1.5277276	0.40110707	3514.5034
520.08569	1.5306231	0.4023706	3514.8604
521.08667	1.5348462	0.40344724	3510.2515
522.08765	1.5379312	0.40439102	3510.8523
523.08862	1.5410216	0.40543795	3514.0918
524.0896	1.5449749	0.40640214	3521.1221
525.09058	1.5467066	0.40736005	3517.7725
526.09155	1.5496709	0.40838394	3517.0085
527.09253	1.5541383	0.40935966	3521.2285
528.09351	1.5583982	0.41058549	3520.9905
529.09448	1.5567104	0.41155282	3520.0566
530.09546	1.5625541	0.41279098	3522.9504
531.09644	1.5660229	0.41379163	3522.7534
532.09741	1.5697347	0.41494235	3528.5044
533.09839	1.5709974	0.41607198	3528.8779
534.09937	1.5741918	0.41701666	3525.7932
535.10034	1.5773236	0.41801482	3524.1184
536.10132	1.5792061	0.41913936	3529.1135
537.10229	1.5867742	0.42017388	3529.7617
538.10327	1.586737	0.42137018	3533.386
539.10425	1.5911932	0.42251375	3534.7715
540.10522	1.5923094	0.42362544	3536.2185
541.1062	1.5959795	0.42468247	3536.032
542.10718	1.5984045	0.42593089	3538.3762
543.10815	1.6027949	0.42719537	3531.9331
544.10913	1.6048653	0.42817086	3533.5662
545.11011	1.6094136	0.42953533	3542.9607
546.11108	1.6118436	0.43061367	3539.3538
547.11206	1.6136814	0.43181348	3537.0906
548.11304	1.6161245	0.43269661	3533.217
549.11401	1.6206286	0.43386546	3542.7244
550.11499	1.6198398	0.43494985	3544.0081
551.11597	1.6236255	0.43610513	3538.4849
552.11694	1.6293566	0.43728426	3544.9319
553.11792	1.6321172	0.43827456	3543.3486
554.1189	1.6330494	0.43928334	3545.0083
555.11987	1.6378497	0.44042552	3545.032
556.12085	1.6426753	0.44174433	3551.3528
557.12183	1.6447715	0.44282466	3546.0488
558.1228	1.6475425	0.44372147	3545.147
559.12378	1.6496536	0.4448618	3551.1873
560.12476	1.652846	0.44603851	3547.7161
561.12573	1.6573076	0.44688669	3545.5718
562.12671	1.6593671	0.4478834	3550.9021
563.12769	1.6665603	0.44902724	3556.6611
564.12866	1.6642395	0.44994527	3549.0239
565.12964	1.6667607	0.45087063	3550.1904
566.13062	1.6682515	0.45200318	3553.4824
567.13159	1.6725137	0.45300105	3549.4609
568.13257	1.6778775	0.45404783	3560.302
569.13354	1.6784281	0.45524839	3560.5745
570.13452	1.6827703	0.45657814	3562.9302
571.1355	1.6856731	0.45759866	3560.5854
572.13647	1.6911373	0.45878652	3569.9749
573.13745	1.6912092	0.45987231	3559.7258
574.13843	1.6955761	0.46107963	3560.687
575.1394	1.6965575	0.46210942	3561.3142
576.14038	1.6988612	0.46319693	3570.6162
577.14136	1.7048401	0.4644818	3569.3691
578.14233	1.7054008	0.46576494	3565.4573
579.14331	1.71041	0.46692193	3564.313
580.14429	1.713219	0.46807325	3568.4995
581.14526	1.7181064	0.46923161	3571.8491
582.14624	1.7195867	0.47035375	3567.8835
583.14722	1.7217985	0.47147748	3567.9028
584.14819	1.7234124	0.47258437	3567.5059
585.14917	1.729504	0.47380656	3571.5693
586.15015	1.7314508	0.47508532	3576.6375
587.15112	1.7358303	0.47623333	3572.624
588.1521	1.7347097	0.47727326	3570.0317
589.15308	1.7407099	0.47849298	3576.3374
590.15405	1.7450534	0.47968036	3580.4568
591.15503	1.7453496	0.48061898	3566.6853
592.15601	1.7483549	0.48155218	3572.2053
593.15698	1.7555592	0.4826099	3580.2683
594.15796	1.7569381	0.4838413	3584.9592
595.15894	1.7561653	0.48485613	3574.5774
596.15991	1.7618743	0.4858861	3574.5676
597.16089	1.7640343	0.48721296	3577.6753
598.16187	1.7672776	0.4884901	3582.3972
599.16284	1.7707886	0.48962212	3586.8372
600.16382	1.7717395	0.4908053	3580.6516
601.16479	1.7792603	0.49205869	3587.2402
602.16577	1.7759782	0.49316445	3580.3972
603.16675	1.7801254	0.49436092	3582.0552
604.16772	1.784312	0.49541211	3587.8794
605.1687	1.7851521	0.49654305	3584.3044
606.16968	1.787836	0.49778783	3583.5166
607.17065	1.7934096	0.4988285	3581.3169
608.17163	1.800166	0.49989238	3586.3291
609.17261	1.7992901	0.50099224	3587.3362
610.17358	1.8026949	0.50220871	3593.2163
611.17456	1.8038261	0.50331575	3585.2239
612.17554	1.8091896	0.50450629	3589.8848
613.17651	1.8113592	0.50548291	3594.1018
614.17749	1.815568	0.50669307	3596.3428
615.17847	1.8183969	0.50802481	3595.426
616.17944	1.8228959	0.50953555	3598.0854
617.18042	1.8247999	0.51073968	3598.0837
618.1814	1.8271426	0.5118807	3596.915
619.18237	1.8293786	0.51308125	3595.2021
620.18335	1.8347057	0.51434535	3599.8198
621.18433	1.8377461	0.51548493	3596.5176
622.1853	1.8381289	0.51661074	3594.4802
623.18628	1.8450927	0.51785046	3600.5369
624.18726	1.8440475	0.51911002	3599.5974
625.18823	1.8445045	0.52026266	3593.2222
626.18921	1.8513921	0.52144784	3597.9167
627.19019	1.8537564	0.52268577	3604.8127
628.19116	1.8576585	0.52406347	3600.1392
629.19214	1.8591782	0.5250771	3600.3245
630.19312	1.862088	0.52622873	3600.7266
631.19409	1.8640459	0.52721739	3601.8845
632.19507	1.8677329	0.52843702	3604.2632
633.19604	1.8742713	0.52947676	3604.9641
634.19702	1.8736882	0.53076124	3609.0132
635.198	1.8778849	0.53205907	3607.8179
636.19897	1.88197	0.53325844	3608.7893
637.19995	1.8846774	0.53470773	3608.9302
638.20093	1.8879718	0.53568476	3606.1313
639.2019	1.8915845	0.53694344	3608.8982
640.20288	1.8927256	0.53800064	3603.1755
641.20386	1.896907	0.5392502	3610.4075
642.20483	1.9007732	0.540389	3612.3567
643.20581	1.9016362	0.54177225	3618.1433
644.20679	1.9047496	0.54289109	3615.4045
645.20776	1.9075027	0.5441581	3614.0408
646.20874	1.9108745	0.54545629	3612.625
647.20972	1.91198	0.54661119	3609.1492
648.21069	1.9202023	0.54784483	3618.9893
649.21167	1.9206131	0.54880971	3611.0383
650.21265	1.923197	0.54996723	3616.2922
651.21362	1.9259112	0.55130309	3618.082
652.2146	1.9318506	0.55277193	3621.8171
653.21558	1.9333276	0.55400026	3617.2451
654.21655	1.9353697	0.55518651	3615.5598
655.21753	1.9385554	0.5563547	3613.4165
656.21851	1.9425581	0.55775148	3621.5635
657.21948	1.9462144	0.55897152	3617.4294
658.22046	1.947395	0.56017691	3617.469
659.22144	1.9506932	0.56137627	3625.0476
660.22241	1.9530499	0.56267935	3619.2927
661.22339	1.956514	0.56389356	3627.166
662.22437	1.9569973	0.56545568	3622.7612
663.22534	1.9627091	0.56669551	3619.0652
664.22632	1.9628905	0.56797194	3622.3169
665.22729	1.9674788	0.56913376	3624.0298
666.22827	1.9708365	0.57032841	3620.6765
667.22925	1.9761608	0.57172984	3631.99
668.23022	1.9783301	0.57292932	3626.4348
669.2312	1.9800235	0.57427877	3627.0693
670.23218	1.9823041	0.57547772	3625.3757
671.23315	1.9862673	0.57657957	3624.198
672.23413	1.9896687	0.57777554	3625.6899
673.23511	1.9911423	0.57925463	3624.4253
674.23608	1.994813	0.58048439	3626.8879
675.23706	1.9998764	0.58161187	3629.5261
676.23804	2.0017715	0.58288717	3627.6843
677.23901	2.0023828	0.58397019	3629.2747
678.23999	2.0063653	0.58516037	3627.7449
679.24097	2.0095477	0.58646482	3630.1746
680.24194	2.0141571	0.58782834	3636.4619
681.24292	2.0162711	0.5891915	3635.5947
682.2439	2.0189109	0.59032536	3627.5452
683.24487	2.0231647	0.5914796	3630.9519
684.24585	2.0269701	0.59281307	3631.3049
685.24683	2.0306809	0.59408045	3633.1152
686.2478	2.0305791	0.59547907	3632.5015
687.24878	2.0320811	0.59709495	3636.5046
688.24976	2.0365486	0.59831405	3628.3723
689.25073	2.0431688	0.59961748	3632.3591
690.25171	2.0452318	0.60103786	3637.2354
691.25269	2.0459764	0.60236281	3639.8982
692.25366	2.0510736	0.60372299	3639.3716
693.25464	2.0541043	0.60499799	3637.1538
694.25562	2.0557613	0.60636985	3640.0903
695.25659	2.0603216	0.60763747	3635.0874
696.25757	2.0628347	0.60875076	3637.9478
697.25854	2.064642	0.61003363	3643.2546
698.25952	2.0697024	0.61159271	3641.3904
699.2605	2.0682096	0.61289459	3635.9734
700.26147	2.0722213	0.61398083	3630.676
701.26245	2.0777149	0.61537892	3638.2529
702.26343	2.0800283	0.61665511	3642.9692
703.2644	2.0819292	0.61805224	3645.7234
704.26538	2.0866129	0.61924577	3633.7373
705.26636	2.0897181	0.62045985	3633.7952
706.26733	2.0892396	0.62149471	3640.095
707.26831	2.093775	0.62277359	3642.71
708.26929	2.0960062	0.62388092	3636.7356
709.27026	2.1020701	0.62511712	3646.6697
710.27124	2.1063452	0.62657934	3649.677
711.27222	2.107955	0.62800819	3652.9197
712.27319	2.1095548	0.62959403	3647.6499
713.27417	2.1117113	0.63116431	3646.9851
714.27515	2.1157062	0.63288867	3650.6643
715.27612	2.1169081	0.63424182	3641.7419
716.2771	2.1212933	0.63539439	3638.0837
717.27808	2.1238465	0.63660342	3643.3623
718.27905	2.1276586	0.63802719	3650.0356
719.28003	2.1271217	0.63940966	3646.8628
720.28101	2.1342683	0.64088148	3650.968
721.28198	2.1370759	0.64225566	3649.5906
722.28296	2.1382663	0.64378178	3645.8948
723.28394	2.143177	0.6452831	3655.634
724.28491	2.1444213	0.64674377	3649.4905
725.28589	2.1514814	0.64797765	3651.4172
726.28687	2.1534739	0.64941353	3658.281
727.28784	2.154392	0.65113699	3654.9255
728.28882	2.1596396	0.65271693	3654.4932
729.28979	2.1624169	0.65415329	3648.708
730.29077	2.1624329	0.65542728	3649.8721
731.29175	2.1647723	0.65655392	3646.3562
732.29272	2.1709003	0.65813094	3656.4622
733.2937	2.1749649	0.65955555	3653.8738
734.29468	2.1762214	0.66093087	3654.8557
735.29565	2.180033	0.6621654	3651.2319
736.29663	2.1817155	0.66356534	3656.6121
737.29761	2.1848338	0.66505849	3654.4211
738.29858	2.1870177	0.66641974	3651.9451
739.29956	2.191659	0.66792399	3655.2424
740.30054	2.1929803	0.66918236	3647.5947
741.30151	2.1967614	0.6704855	3651.3521
742.30249	2.1977875	0.671736	3650.5862
743.30347	2.2042401	0.67300278	3651.7893
744.30444	2.2055774	0.67452705	3658.9255
745.30542	2.2056453	0.67601544	3656.1445
746.3064	2.2097743	0.67751807	3655.9773
747.30737	2.2164915	0.6790427	3657.9243
748.30835	2.217658	0.68039566	3654.9854
749.30933	2.2194016	0.68188471	3650.9966
750.3103	2.2215943	0.68323916	3654.7642
751.31128	2.2264149	0.68457979	3655.5464
752.31226	2.2293329	0.68601495	3665.9463
753.31323	2.2315118	0.68731475	3657.3679
754.31421	2.2344215	0.68896985	3658.8301
755.31519	2.2410347	0.69046116	3662.2319
756.31616	2.2443573	0.69199401	3656.6465
757.31714	2.2449026	0.6933412	3661.26
758.31812	2.2463961	0.69522643	3668.873
759.31909	2.2506413	0.69694543	3658.3335
760.32007	2.2513101	0.69847476	3657.0195
761.32104	2.2563708	0.69993389	3653.511
762.32202	2.2578948	0.7015456	3655.7893
763.323	2.262285	0.7030412	3657.979
764.32397	2.2649484	0.70454359	3659.2085
765.32495	2.2695243	0.70622921	3663.7004
766.32593	2.2712929	0.70776904	3660.2788
767.3269	2.2753098	0.70923346	3657.7461
768.32788	2.2798388	0.71064097	3658.2151
769.32886	2.2823505	0.71183836	3657.0183
770.32983	2.2830672	0.71315032	3658.4001
771.33081	2.2830076	0.71468055	3661.7341
772.33179	2.2888863	0.71634489	3663.8232
773.33276	2.2935529	0.71792954	3663.2539
774.33374	2.2974031	0.71940899	3657.6404
775.33472	2.2975059	0.721062	3661.0698
776.33569	2.3002934	0.72214121	3651.1125
777.33667	2.3038507	0.7232545	3656.8381
778.33765	2.3078172	0.72468174	3664.6943
779.33862	2.3107777	0.72638756	3667.1082
780.3396	2.3123877	0.72798121	3660.4731
781.34058	2.3157778	0.72955531	3662.8115
782.34155	2.3177378	0.73138183	3666.3914
783.34253	2.3219726	0.73302335	3663.4441
784.34351	2.3233254	0.73458964	3656.2454
785.34448	2.3285704	0.73610353	3663.6536
786.34546	2.3301802	0.73759794	3661.5149
787.34644	2.3370371	0.73941314	3670.4675
788.34741	2.3400016	0.74131542	3667.937
789.34839	2.339267	0.74303377	3661.4263
790.34937	2.3422122	0.74432939	3654.5266
791.35034	2.3482597	0.74585325	3664.4004
792.35132	2.3507447	0.74730396	3665.6475
793.35229	2.3525167	0.74904269	3668.7793
794.35327	2.3555467	0.75086826	3668.48
795.35425	2.3583429	0.75263679	3663.4282
796.35522	2.3613305	0.75444376	3662.5017
797.3562	2.365514	0.75603944	3663.1182
798.35718	2.364867	0.75754738	3663.0205
799.35815	2.3706796	0.75943059	3667.9292
800.35913	2.37289	0.76124084	3663.3447
801.36011	2.376148	0.7628051	3659.1643
802.36108	2.3795598	0.76416308	3665.7031
803.36206	2.3840022	0.76564562	3662.3135
804.36304	2.3845828	0.76723289	3662.2305
805.36401	2.3869383	0.76897401	3663.6775
806.36499	2.3945937	0.77084488	3669.071
807.36597	2.3932986	0.7726801	3667.7556
808.36694	2.3963232	0.77433461	3662.1187
809.36792	2.4026659	0.77610213	3662.6221
810.3689	2.4039414	0.77781516	3663.623
811.36987	2.4063907	0.7795313	3663.7156
812.37085	2.4115722	0.78124756	3665.3506
813.37183	2.4155271	0.78286213	3665.7134
814.3728	2.4137557	0.78454858	3663.1472
815.37378	2.4195876	0.78632128	3661.7229
816.37476	2.4216185	0.78806686	3658.6904
817.37573	2.4242289	0.78993326	3666.1799
818.37671	2.4295065	0.7917273	3664.8943
819.37769	2.4331021	0.79322767	3665.4714
820.37866	2.435009	0.79509872	3667.9082
821.37964	2.4371045	0.79692119	3662.3792
822.38062	2.439749	0.79889542	3666.3992
823.38159	2.4415193	0.80061007	3658.1782
824.38257	2.4442322	0.80229396	3661.2
825.38354	2.4479764	0.80387592	3659.7695
826.38452	2.4482687	0.80590826	3666.0618
827.3855	2.4538467	0.80768496	3661.7122
828.38647	2.4584157	0.80973852	3665.8884
829.38745	2.4604785	0.81167644	3663.9246
830.38843	2.4641016	0.81338429	3663.644
831.3894	2.4656782	0.81513464	3664.2434
832.39038	2.4700215	0.81702018	3661.7073
833.39136	2.4751897	0.81882519	3664.7639
834.39233	2.474509	0.82081753	3664.6887
835.39331	2.4787555	0.82288337	3667.323
836.39429	2.483355	0.82486123	3664.6016
837.39526	2.4852107	0.82703054	3666.3076
838.39624	2.4853811	0.82890958	3661.2422
839.39722	2.4908774	0.83106822	3664.8596
840.39819	2.497833	0.83308202	3666.9224
841.39917	2.4977968	0.83477622	3654.2944
842.40015	2.5002229	0.83640558	3663.8723
843.40112	2.5014293	0.83806503	3662.5996
844.4021	2.5039837	0.83983517	3659.4048
845.40308	2.5076258	0.84172201	3660.5403
846.40405	2.5112035	0.84364623	3659.6924
847.40503	2.5154228	0.84536928	3660.1218
848.40601	2.5156689	0.84730065	3659.7725
849.40698	2.5196855	0.8493554	3663.1138
850.40796	2.5225301	0.85138017	3657.8064
851.40894	2.5264189	0.85340977	3656.5227
852.40991	2.5310526	0.85551083	3661.1704
853.41089	2.5338504	0.85772413	3660.0625
854.41187	2.5357132	0.85981566	3657.812
855.41284	2.5373983	0.86192012	3654.9431
856.41382	2.5446754	0.86388981	3657.8677
857.41479	2.5466685	0.86574715	3657.6763
858.41577	2.548465	0.86735046	3659.323
859.41675	2.5513868	0.86957669	3659.1423
860.41772	2.551862	0.87160701	3657.0178
861.4187	2.5552819	0.87363076	3657.2251
862.41968	2.5610728	0.87536103	3654.1052
863.42065	2.5625882	0.87731308	3658.4333
864.42163	2.5660875	0.87942708	3657.8423
865.42261	2.5700464	0.8818779	3660.6399
866.42358	2.5696993	0.88448507	3652.6169
867.42456	2.5749373	0.88689244	3652.4443
868.42554	2.5790977	0.88921273	3651.251
869.42651	2.5804663	0.8917467	3657.7317
870.42749	2.5817783	0.89381498	3648.5747
871.42847	2.5865278	0.89567029	3650.5044
872.42944	2.5910761	0.89777017	3657.9111
873.43042	2.5983675	0.90055579	3657.0203
874.4314	2.5922792	0.90294975	3649.7061
875.43237	2.599798	0.90497291	3648.1714
876.43335	2.6033027	0.90702486	3651.2932
877.43433	2.6069446	0.90930223	3654.782
878.4353	2.6078305	0.91205728	3653.3965
879.43628	2.6086171	0.91461444	3649.0347
880.43726	2.6123734	0.91674387	3642.7256
881.43823	2.6159191	0.91876411	3646.4976
882.43921	2.6194448	0.9207893	3642.9041
883.44019	2.6230528	0.92291296	3647.9753
884.44116	2.6256607	0.92557549	3648.2512
885.44214	2.6280534	0.92818272	3645.0688
886.44312	2.6329064	0.93002725	3639.5798
887.44409	2.6339257	0.93220192	3650.6594
888.44507	2.6375501	0.93460226	3642.9399
889.44604	2.6395264	0.93695408	3647.4927
890.44702	2.6437376	0.93903643	3644.3569
891.448	2.6468379	0.94166404	3646.2473
892.44897	2.6504447	0.94461387	3647.5825
893.44995	2.6558008	0.94741428	3645.8804
894.45093	2.6552024	0.94992769	3641.1755
895.4519	2.6583116	0.95262688	3640.604
896.45288	2.6612091	0.95486635	3640.9082
897.45386	2.6679413	0.95751089	3639.4836
898.45483	2.6717138	0.95991236	3640.073
899.45581	2.6730702	0.9620778	3638.8088
900.45679	2.6745481	0.96412551	3638.7729
901.45776	2.6792588	0.96641231	3643.6201
902.45874	2.6808689	0.96907002	3636.0002
903.45972	2.6844285	0.97180587	3636.2388
904.46069	2.6849484	0.97415233	3631.8267
905.46167	2.6892202	0.97685617	3632.9607
906.46265	2.6895308	0.97934663	3628.7112
907.46362	2.6969721	0.98197442	3632.5527
908.4646	2.6981778	0.98423243	3629.6145
909.46558	2.6999342	0.98665977	3630.1592
910.46655	2.7040727	0.98893851	3625.4211
911.46753	2.7070751	0.99164414	3628.4387
912.46851	2.7108192	0.99455476	3632.0552
913.46948	2.7136378	0.99752796	3627.759
914.47046	2.716238	1.000394	3621.8586
915.47144	2.7202277	1.0026968	3624.6777
916.47241	2.7194211	1.0054098	3618.2917
917.47339	2.7262182	1.0082642	3623.4121
918.47437	2.7280924	1.0111297	3620.4504
919.47534	2.7266786	1.0136331	3614.1868
920.47632	2.7323475	1.0161498	3617.6594
921.47729	2.7349524	1.0191138	3620.6487
922.47827	2.7416928	1.0217317	3610.458
923.47925	2.7440655	1.0242357	3613.8975
924.48022	2.7472081	1.0268714	3607.1201
925.4812	2.7484426	1.0294709	3609.7881
926.48218	2.7536433	1.0326096	3611.3787
927.48315	2.7543344	1.0354124	3607.8049
928.48413	2.757159	1.0383444	3609.3542
929.48511	2.7590594	1.0410211	3605.3848
930.48608	2.7638257	1.0438762	3602.7805
931.48706	2.7670918	1.0471606	3608.2268
932.48804	2.7707553	1.0500071	3600.364
933.48901	2.7767408	1.0528928	3598.5972
934.48999	2.7764146	1.0562198	3602.0024
935.49097	2.7785149	1.0591252	3594.155
936.49194	2.7796471	1.062042	3596.3025
937.49292	2.785414	1.0647956	3587.4561
938.4939	2.7881906	1.0676185	3592.3943
939.49487	2.7894456	1.0704536	3587.9028
940.49585	2.7936993	1.0730747	3591.918
941.49683	2.7950552	1.0761114	3592.0684
942.4978	2.802058	1.0792789	3585.0378
943.49878	2.8015723	1.0820037	3577.571
944.49976	2.8071761	1.0842417	3577.2214
945.50073	2.8078878	1.0870054	3578.8057
946.50171	2.8106804	1.0898378	3578.2402
947.50269	2.8170893	1.0927504	3580.6216
948.50366	2.8182254	1.0957115	3577.4678
949.50464	2.8226709	1.0986974	3578.7346
950.50562	2.8243911	1.1017504	3574.4045
951.50659	2.8254533	1.1044633	3562.9033
952.50757	2.8300292	1.1072391	3564.9705
953.50854	2.8350458	1.1101789	3570.531
954.50952	2.8374164	1.112727	3560.5833
955.5105	2.8369288	1.115368	3558.4082
956.51147	2.8411865	1.1180979	3559.9114
957.51245	2.8461189	1.1209489	3561.0032
958.51343	2.8459127	1.1239856	3555.7034
959.5144	2.8525264	1.1273503	3558.9653
960.51538	2.8537285	1.1307844	3551.9814
961.51636	2.857528	1.1336799	3547.1345
962.51733	2.8609626	1.1363674	3541.7878
963.51831	2.8650575	1.1396185	3544.8464
964.51929	2.8665757	1.1426833	3545.7314
965.52026	2.8716884	1.1455572	3544.0974
966.52124	2.8743858	1.1484483	3542.8081
967.52222	2.8738308	1.1519032	3535.2314
968.52319	2.8816249	1.1554134	3536.644
969.52417	2.8808446	1.1584067	3525.1074
970.52515	2.8867598	1.1611618	3528.6418
971.52612	2.8874664	1.1641561	3524.8027
972.5271	2.8905416	1.1676528	3522.9751
973.52808	2.8909371	1.1709425	3521.5935
974.52905	2.8973382	1.1745307	3519.6802
975.53003	2.8998678	1.1778172	3521.52
976.53101	2.9042602	1.1807144	3511.4502
977.53198	2.9058321	1.1835146	3515.1653
978.53296	2.9054587	1.1864631	3504.3875
979.53394	2.9110548	1.1894153	3506.1282
980.53491	2.9141865	1.192046	3505.5696
981.53589	2.9157934	1.1952674	3498.7515
982.53687	2.9175518	1.1987292	3503.2581
983.53784	2.9220362	1.2025013	3494.7561
984.53882	2.9254694	1.2057335	3487.5461
985.53979	2.9297419	1.2094069	3492.6909
986.54077	2.9331059	1.2126895	3484.3738
987.54175	2.9340246	1.2152748	3476.4973
988.54272	2.9409173	1.2184229	3480.3779
989.5437	2.9411011	1.2213954	3473.9426
990.54468	2.9425302	1.223906	3467.8586
991.54565	2.9483778	1.2265663	3473.9758
992.54663	2.9491813	1.2294339	3464
993.54761	2.9496717	1.2324069	3467.0322
994.54858	2.9571936	1.2359076	3462.333
995.54956	2.9599369	1.2390227	3451.9575
996.55054	2.9625812	1.2416495	3450.1082
997.55151	2.9679351	1.2442417	3456.2937
998.55249	2.9668741	1.2470961	3446.7932
999.55347	2.9734783	1.2503746	3454.3997
1000.5544	2.9770579	1.2536415	3451.562
1001.5554	2.9781249	1.2564393	3439.5593
1002.5564	2.983958	1.2588384	3429.4995
1003.5574	2.9862406	1.2609782	3429.3513
1004.5583	2.9849982	1.2633175	3425.8777
1005.5593	2.9876418	1.2658577	3429.9478
1006.5603	2.9938188	1.2689852	3432.9285
1007.5613	2.9933169	1.2720664	3425.7751
1008.5623	2.9976859	1.2754846	3421.5913
1009.5632	3.0014288	1.2793077	3424.4133
1010.5642	3.0058308	1.2831665	3416.5049
1011.5652	3.0103891	1.2866794	3411.3921
1012.5662	3.0098038	1.2900958	3408.5688
1013.5671	3.013689	1.2931191	3399.145
1014.5681	3.0168223	1.296468	3392.9893
1015.5691	3.0205898	1.2995481	3391.5959
1016.5701	3.0206578	1.3027171	3391.7075
1017.571	3.0280318	1.3059547	3392.1829
1018.572	3.0277667	1.3096559	3387.1826
1019.573	3.0321875	1.3135604	3371.3831
1020.574	3.0365894	1.3166071	3373.2905
1021.575	3.0405009	1.3193712	3367.6514
1022.5759	3.0418527	1.3231771	3370.9941
1023.5769	3.0435741	1.3265008	3359.2781
1024.5779	3.0459268	1.3299855	3355.4653
1025.5789	3.0487008	1.3327624	3351.2505
1026.5798	3.0546978	1.3355067	3349.2388
1027.5808	3.0559673	1.3390652	3347.6111
1028.5818	3.0592985	1.3425404	3344.9092
1029.5828	3.0629897	1.3460194	3333.6082
1030.5837	3.0643723	1.3494837	3331.0664
1031.5847	3.0685039	1.353063	3324.4375
1032.5857	3.071928	1.3565898	3324.8887
1033.5867	3.0730801	1.360184	3318.7258
1034.5876	3.0747051	1.3627896	3307.2971
1035.5886	3.0807829	1.3654433	3302.7148
1036.5896	3.0832169	1.3683161	3307.2207
1037.5906	3.0877883	1.3714523	3301.5513
1038.5916	3.089133	1.3748053	3307.9258
1039.5925	3.0931122	1.3786758	3291.2661
1040.5935	3.0932732	1.3820316	3279.2437
1041.5945	3.0973685	1.3856359	3284.2202
1042.5955	3.0999231	1.3889621	3281.1116
1043.5964	3.1044946	1.3924882	3277.8855
1044.5974	3.1069515	1.3962069	3269.2771
1045.5984	3.1065989	1.4002099	3263.2749
1046.5994	3.1138399	1.403988	3256.863
1047.6003	3.1151659	1.4076046	3249.3313
1048.6013	3.1199555	1.4109799	3244.1169
1049.6023	3.1223662	1.4145306	3239.5334
1050.6033	3.1236908	1.4180869	3238.4546
1051.6042	3.1288359	1.4211818	3224.239
1052.6052	3.131911	1.4244962	3226.2417
1053.6062	3.1357105	1.4279288	3220.4668
1054.6072	3.1369033	1.4313326	3216.4297
1055.6082	3.1377251	1.4349383	3207.9973
1056.6091	3.1431005	1.4385246	3210.3142
1057.6101	3.1472983	1.4421735	3198.5657
1058.6111	3.1499262	1.4457377	3190.8638
1059.6121	3.1533704	1.449349	3181.9055
1060.613	3.1539638	1.4528043	3178.436
1061.614	3.1580014	1.4563448	3176.4858
1062.615	3.1598377	1.4595722	3167.4277
1063.616	3.1669672	1.4623603	3156.717
1064.6169	3.1669431	1.46529	3162.6907
1065.6179	3.1703932	1.4689788	3156.5298
1066.6189	3.1726727	1.4725116	3146.1748
1067.6199	3.1742282	1.4762433	3140.6106
1068.6208	3.1791573	1.4800361	3131.3218
1069.6218	3.1821775	1.4833943	3125.488
1070.6228	3.1841545	1.487147	3119.7639
1071.6238	3.1860259	1.4900049	3112.1926
1072.6248	3.1912487	1.4937494	3113.5085
1073.6257	3.1919346	1.4976106	3102.9192
1074.6267	3.1974638	1.5016419	3104.6221
1075.6277	3.2018936	1.5059797	3086.8428
1076.6287	3.2036459	1.5096099	3079.4226
1077.6296	3.2068133	1.5127701	3078.1235
1078.6306	3.2092345	1.515502	3064.6606
1079.6316	3.2123547	1.5189581	3065.1558
1080.6326	3.2150373	1.5220989	3053.5518
1081.6335	3.2201765	1.5257111	3051.9402
1082.6345	3.220505	1.5289538	3042.7339
1083.6355	3.2254655	1.5326632	3036.0869
1084.6365	3.2246883	1.5358919	3029.0889
1085.6375	3.2292335	1.5397147	3020.7974
1086.6384	3.232712	1.5431437	3010.2424
1087.6394	3.2354999	1.5477765	3009.1433
1088.6404	3.2397766	1.552259	2995.2144
1089.6414	3.2423742	1.5561427	2994.1455
1090.6423	3.2474329	1.5603694	2980.8096
1091.6433	3.2492023	1.5634749	2967.4253
1092.6443	3.2536731	1.5664201	2967.7529
1093.6453	3.2567229	1.5699553	2958.7554
1094.6462	3.2566311	1.5734884	2946.5349
1095.6472	3.258956	1.5767139	2938.2725
1096.6482	3.2625327	1.580189	2939.6821
1097.6492	3.2669842	1.5849732	2929.4858
1098.6501	3.2715502	1.5892625	2922.1316
1099.6511	3.2729938	1.5925324	2906.679
1100.6521	3.2751243	1.5956976	2900.3804
1101.6531	3.2789195	1.5995886	2898.5386
1102.6541	3.282095	1.6038768	2881.0479
1103.655	3.2865338	1.6071261	2871.8623
1104.656	3.2880678	1.610191	2866.085
1105.657	3.2903969	1.6134776	2856.0845
1106.658	3.2942743	1.6167442	2851.0935
1107.6589	3.2971077	1.620262	2844.1121
1108.6599	3.2998149	1.6251439	2834.697
1109.6609	3.3036709	1.6294349	2818.9648
1110.6619	3.304652	1.6335919	2806.4753
1111.6628	3.3068717	1.6375191	2795.884
1112.6638	3.311053	1.6415869	2785.9255
1113.6648	3.3185687	1.645483	2783.8962
1114.6658	3.3164759	1.6488466	2764.0549
1115.6667	3.3225839	1.6526061	2756.5938
1116.6677	3.3262944	1.657154	2748.1638
1117.6687	3.3264959	1.6626359	2724.6658
1118.6697	3.3326602	1.6678387	2698.5239
1119.6707	3.332725	1.6722239	2689.2422
1120.6716	3.3359385	1.6764007	2673.4346
1121.6726	3.3412485	1.6827571	2640.4441
1122.073	3.3406425	1.6884303	2596.3772