File: datasets/am_bench_2022/raw_data/0-X.01-2/specimen.dat
MTS793|MPT|ENU|1|2|.|/|:|1|0|0|A

Operator Information						Time:	34.057129	Sec	10/12/2021 3:10:14 PM
Operator	Nick Derimow
Project	AM Bench 2022 mini-tensile challenge
Specimen ID	0-X.01-2
Material	PBF-L Inconel 625
Specimen Width	2.55	mm
Specimen Thickness	1.52	mm
Notes
Operator Information End

Data Acquisition						Time:	1035.0542	Sec	10/12/2021 3:26:55 PM
Time	Axial Displacement	Axial Extensometer	Axial Force
Sec	mm	mm	N
34.174072	0.0043580821	-6.5986769e-06	57.302685
35.275146	0.0059369206	0.00017105203	70.501915
36.376221	0.010857172	0.0003492324	88.975441
37.477295	0.012547267	0.00023062101	106.91241
38.578369	0.013845456	0.00042296344	122.77752
39.679443	0.016557341	0.00049720565	141.48869
40.780518	0.021895519	0.00060239667	154.42628
41.881592	0.02342421	0.00063216634	167.83849
42.982666	0.029549323	0.00082662218	204.54294
44.08374	0.029867928	0.001081106	218.90735
45.184814	0.033031598	0.0011815589	243.62759
46.285889	0.036586866	0.0012432997	267.31693
47.386963	0.042116005	0.0015111547	291.15009
48.488037	0.043960791	0.0014960062	314.23801
49.589111	0.050210733	0.001699428	340.10944
50.690186	0.050637726	0.0017833124	367.37448
51.79126	0.056019086	0.0018839661	388.45721
52.892334	0.053333629	0.0019904019	410.83862
53.993408	0.060232822	0.0020730661	433.81128
55.094482	0.059476979	0.002196176	457.86032
56.195557	0.067181237	0.0023217925	482.4718
57.296631	0.071200535	0.0022988908	500.22281
58.397705	0.07321763	0.0025093108	530.65155
59.498779	0.071770951	0.0026824293	558.09937
60.599854	0.078997605	0.0028185209	590.31342
61.700928	0.082347728	0.0028974316	623.23779
62.802002	0.085169025	0.0030970795	649.58826
63.903076	0.090632595	0.0032722224	682.7489
65.00415	0.092993915	0.0033431544	709.17249
66.105225	0.097911656	0.0035819151	739.21771
67.206299	0.09824194	0.0036536914	764.88214
68.307373	0.10524978	0.0039659175	802.84088
69.408447	0.10371146	0.0040031574	822.50775
70.509521	0.10989742	0.0040885396	857.18878
71.610596	0.11267635	0.0043587429	889.6355
72.71167	0.11395339	0.0043755355	919.08557
73.812744	0.11769388	0.0046047233	945.69324
74.913818	0.1227196	0.0047265864	979.80322
76.014893	0.12210411	0.0046878592	1004.5867
77.115967	0.1306123	0.0049879514	1046.3386
78.217041	0.13157283	0.0050676642	1064.8311
79.318115	0.13477974	0.0052359118	1108.2266
80.419189	0.13809647	0.0054981401	1140.8323
81.520264	0.14212599	0.0055134417	1171.7126
82.621338	0.14310947	0.0057959985	1205.1431
83.722412	0.14817597	0.0059220381	1226.9233
84.823486	0.1506217	0.0059688804	1259.183
85.924561	0.15600024	0.0062103043	1289.0706
87.025635	0.16005683	0.0063320785	1328.991
88.126709	0.16142344	0.0064774421	1357.5446
89.227783	0.16420685	0.0065973024	1388.6936
90.328857	0.16690561	0.0067879763	1422.5819
91.429932	0.17166297	0.0069370405	1444.2081
92.531006	0.17451112	0.0071128719	1479.1357
93.63208	0.18035163	0.0071913274	1508.1001
94.733154	0.18238211	0.0074151596	1531.5883
95.834229	0.18375528	0.0074683782	1566.8887
96.935303	0.18591504	0.0075820587	1585.7192
98.036377	0.19043913	0.0077571757	1619.1091
99.137451	0.19702756	0.0079820501	1647.6985
100.23853	0.200148	0.0080345506	1679.9927
101.3396	0.20003188	0.0082849031	1702.0076
102.44067	0.20447995	0.0084460573	1733.8641
103.54175	0.20614858	0.0085233906	1761.6588
104.64282	0.20851421	0.0087383436	1786.2227
105.7439	0.21690418	0.0088740075	1824.423
106.84497	0.21503358	0.009047647	1841.3596
107.94604	0.22008778	0.0091377283	1867.9944
109.04712	0.22535773	0.0093847131	1894.119
110.14819	0.22647767	0.0096337013	1925.4063
111.24927	0.23293737	0.0096125128	1946.0411
112.35034	0.23531528	0.0098185576	1965.4752
113.45142	0.23828599	0.01019506	1995.8174
114.55249	0.24177912	0.010345723	2021.6084
115.65356	0.24478708	0.010490018	2041.0879
116.75464	0.24373046	0.010667107	2058.6028
117.85571	0.2512913	0.010874361	2081.3396
118.95679	0.25159985	0.01100755	2100.2061
120.05786	0.25919098	0.0112262	2130.9761
121.15894	0.26294124	0.011479072	2143.447
122.26001	0.26515898	0.011678577	2164.6033
123.36108	0.26616293	0.011708899	2173.844
124.46216	0.27177522	0.012109007	2198.467
125.56323	0.27636904	0.012238739	2216.6665
126.66431	0.27545071	0.012566322	2233.6326
127.76538	0.28245607	0.01272157	2242.0332
128.86646	0.2818996	0.012883026	2260.9609
129.96753	0.2865313	0.013223556	2276.103
131.0686	0.29238376	0.013456994	2290.4133
132.16968	0.29404092	0.013741535	2305.4639
133.27075	0.30166414	0.014162565	2324.1992
134.37183	0.30143261	0.014289571	2326.8733
135.4729	0.30593243	0.014687739	2349.6016
136.57397	0.30921206	0.014959827	2359.3279
137.67505	0.31048444	0.015336543	2367.0881
138.77612	0.31511569	0.015656278	2379.0491
139.8772	0.31806695	0.016054457	2389.1396
140.97827	0.31954974	0.016435083	2398.7043
142.07935	0.32612172	0.016777828	2408.6897
143.18042	0.32952675	0.017348135	2419.8477
144.28149	0.33274928	0.017837008	2433.1021
145.38257	0.33649403	0.018308863	2441.8135
146.48364	0.34097084	0.018897716	2454.1284
147.58472	0.34159428	0.019382525	2455.0938
148.68579	0.34210506	0.020132657	2464.7813
149.78687	0.35018426	0.020748189	2477.6965
150.88794	0.35151786	0.02143936	2481.5852
151.98901	0.35152176	0.022297749	2479.771
153.09009	0.35793725	0.022885248	2495.9841
154.19116	0.36183751	0.023896953	2503.46
155.29224	0.36181292	0.024657415	2505.2197
156.39331	0.36608812	0.025595723	2505.6389
157.49438	0.37042746	0.026555387	2516.2104
158.59546	0.37378705	0.027479211	2510.3115
159.69653	0.37842792	0.028675349	2531.2959
160.79761	0.37961772	0.029901903	2529.3655
161.89868	0.38272876	0.030814068	2534.5974
162.99976	0.38918543	0.032146245	2547.79
164.10083	0.3918848	0.033088289	2542.2048
165.2019	0.39694434	0.034258984	2549.3176
166.30298	0.39673966	0.035505518	2551.043
167.40405	0.39837283	0.036482483	2547.3337
168.50513	0.40424782	0.037682358	2561.7917
169.6062	0.40946239	0.039137326	2562.4834
170.70728	0.41407266	0.040697418	2569.4373
171.80835	0.41552815	0.042046074	2569.3682
172.90942	0.41809461	0.043348972	2574.9861
174.0105	0.42092103	0.044864304	2569.9651
175.11157	0.4223083	0.046109471	2575.4954
176.21265	0.42791966	0.047749445	2587.2192
177.31372	0.42974108	0.049128134	2585.4272
178.41479	0.43737602	0.050867926	2588.272
179.51587	0.43790364	0.052324031	2583.8638
180.61694	0.44188687	0.053853717	2592.1218
181.71802	0.44566891	0.055417676	2595.6912
182.81909	0.44830236	0.057415072	2609.0227
183.92017	0.45093781	0.059214119	2604.8313
185.02124	0.45429659	0.060809895	2598.8333
186.12231	0.4580856	0.062119003	2598.1636
187.22339	0.4623372	0.06369406	2611.7324
188.32446	0.46799874	0.065535277	2610.5083
189.42554	0.46722507	0.066962175	2604.375
190.52661	0.47037256	0.068612754	2606.3452
191.62769	0.47304222	0.070194662	2613.1665
192.72876	0.48078829	0.072096385	2621.6685
193.82983	0.48080981	0.073923916	2619.7585
194.93091	0.48651016	0.075515471	2620.6694
196.03198	0.48431441	0.077200577	2622.1416
197.13306	0.49172336	0.078964144	2627.655
198.23413	0.4928515	0.080735557	2620.7234
199.33521	0.49706933	0.082308494	2623.2593
200.43628	0.49974555	0.084024414	2622.4438
201.53735	0.50524622	0.085801102	2619.1726
202.63843	0.50590944	0.087494433	2631.7534
203.7395	0.5123204	0.089263625	2632.5647
204.84058	0.51453567	0.090845995	2632.8677
205.94165	0.51746023	0.092393264	2634.0825
207.04272	0.5221051	0.093967967	2643.991
208.1438	0.52307212	0.095763564	2634.4299
209.24487	0.52892828	0.097487576	2636.9036
210.34595	0.53172928	0.099463344	2640.0493
211.44702	0.53449982	0.10123911	2645.4009
212.5481	0.53633642	0.10299264	2636.9951
213.64917	0.5387103	0.10474329	2638.6042
214.75024	0.54535913	0.10678151	2642.7173
215.85132	0.54520422	0.10859726	2644.4377
216.95239	0.55153835	0.11062845	2651.5684
218.05347	0.55244666	0.11251088	2646.7649
219.15454	0.5539099	0.11438301	2650.7971
220.25562	0.5588389	0.11652207	2650.2615
221.35669	0.56193054	0.11831753	2650.0366
222.45776	0.56846195	0.12017819	2657.9053
223.55884	0.56854737	0.12177777	2650.8645
224.65991	0.57222986	0.12361491	2657.009
225.76099	0.57492721	0.12553425	2659.6782
226.86206	0.57749915	0.1272707	2659.3818
227.96313	0.5836665	0.12919965	2659.803
229.06421	0.58764547	0.13096422	2659.7778
230.16528	0.59047109	0.13244401	2661.8892
231.26636	0.59183854	0.13401324	2664.8564
232.36743	0.59807694	0.13613476	2663.6538
233.46851	0.59874117	0.1379969	2671.2881
234.56958	0.60267162	0.13976069	2663.4629
235.67065	0.6075713	0.14134015	2673.8574
236.77173	0.60952759	0.1436435	2670.6201
237.8728	0.61406976	0.14570466	2670.4299
238.97388	0.6159476	0.14734516	2667.876
240.07495	0.62231243	0.1490389	2677.1663
241.17603	0.62358594	0.15059958	2672.6084
242.2771	0.6243875	0.15218557	2670.7766
243.37817	0.62763053	0.15417531	2679.6799
244.47925	0.63285971	0.15595667	2686.5193
245.58032	0.63872093	0.15781495	2679.9663
246.6814	0.6379829	0.15956664	2678.5466
247.78247	0.64252776	0.16167979	2684.2437
248.88354	0.6456902	0.16375422	2684.5784
249.98462	0.64728117	0.16517293	2677.3733
251.08569	0.65189976	0.16705145	2685.6838
252.18677	0.65760058	0.16930062	2690.3975
253.28784	0.66181332	0.17156371	2693.6086
254.38892	0.66552156	0.17335556	2692.1201
255.48999	0.6663149	0.17534806	2690.3904
256.59106	0.66852444	0.17710403	2688.0359
257.69214	0.67610574	0.17860726	2697.3291
258.79321	0.67451841	0.18070784	2695.7285
259.89429	0.68066102	0.182349	2697.2327
260.99536	0.68442929	0.18402657	2693.5647
262.09644	0.68398654	0.18610847	2703.4363
263.19751	0.68890017	0.18791364	2704.4136
264.29858	0.69074684	0.18980549	2694.7107
265.39966	0.69486409	0.19130889	2698.3303
266.50073	0.70094496	0.19328576	2709.623
267.60181	0.70188624	0.19529995	2703.4812
268.70288	0.70422375	0.19740376	2708.6396
269.80396	0.71104211	0.19951256	2704.645
270.90503	0.71399266	0.20121445	2708.0991
272.0061	0.71611351	0.20285586	2704.6099
273.10718	0.71680683	0.20475687	2704.6052
274.20825	0.72238147	0.20688559	2721.5383
275.30933	0.72595757	0.20876491	2711.3167
276.4104	0.73205584	0.21065061	2717.8164
277.51147	0.73430145	0.21238424	2713.4001
278.61255	0.73383474	0.21423592	2717.6155
279.71362	0.74352348	0.21624258	2723.7349
280.8147	0.74320918	0.21818063	2719.2261
281.91577	0.74269062	0.21995097	2718.2688
283.01685	0.74611062	0.22203089	2713.448
284.11792	0.75241834	0.22361603	2714.0068
285.21899	0.75479192	0.22564825	2726.8369
286.32007	0.75612944	0.22747418	2718.6042
287.42114	0.76065016	0.22927803	2722.4719
288.52222	0.76147234	0.23130721	2722.0085
289.62329	0.76962632	0.23297505	2728.6072
290.72437	0.77266252	0.23485768	2721.6387
291.82544	0.77394986	0.23647603	2725.6458
292.92651	0.77702528	0.23796828	2723.6458
294.02759	0.78226197	0.23988891	2728.1904
295.12866	0.78553444	0.24159542	2733.0327
296.22974	0.78867686	0.2435313	2739.8474
297.33081	0.79431969	0.24579647	2742.6238
298.43188	0.79162991	0.2477563	2734.9873
299.53296	0.79650337	0.24971443	2732.7202
300.63403	0.80124021	0.25133497	2738.127
301.73511	0.80083758	0.25332457	2736.7229
302.83618	0.80647594	0.25535494	2737.77
303.93726	0.81267565	0.25702432	2743.1682
305.03833	0.81307578	0.25897264	2742.468
306.1394	0.81704414	0.26068005	2738.5332
307.24048	0.82048231	0.26222083	2739.1333
308.34155	0.82102162	0.2636829	2736.3892
309.44263	0.83029592	0.26552102	2746.6938
310.5437	0.82998306	0.26737362	2742.5906
311.64478	0.83498883	0.26949316	2751.8469
312.74585	0.83612657	0.27114654	2750.4626
313.84692	0.84271318	0.27326417	2749.5706
314.948	0.84319383	0.27513367	2753.563
316.04907	0.84847438	0.27708331	2756.562
317.15015	0.85315835	0.27908009	2754.7012
318.25122	0.85558259	0.28106281	2755.1064
319.35229	0.85607475	0.28291979	2748.4907
320.45337	0.86236769	0.28503355	2767.55
321.55444	0.86394596	0.28683147	2753.7073
322.65552	0.86762619	0.28894362	2758.7485
323.75659	0.86913747	0.29043081	2758.1443
324.85767	0.87041843	0.29257441	2761.8059
325.95874	0.87451929	0.29443839	2759.1345
327.05981	0.87792963	0.29602203	2755.6563
328.16089	0.88509637	0.29761755	2762.6262
329.26196	0.88794643	0.2992208	2769.9119
330.36304	0.89013153	0.30109867	2767.1594
331.46411	0.89304096	0.30301476	2766.9424
332.56519	0.89690435	0.30539501	2780.4639
333.66626	0.89950746	0.30773711	2772.5054
334.76733	0.90280551	0.30954424	2763.1248
335.86841	0.90859818	0.31134409	2772.0566
336.96948	0.91280842	0.31353632	2780.3357
338.07056	0.91573894	0.31560484	2777.8323
339.17163	0.91639459	0.31730556	2774.7224
340.27271	0.92025018	0.31903774	2773.9761
341.37378	0.92049521	0.32056934	2770.6421
342.47485	0.92674679	0.32209665	2777.6567
343.57593	0.92882288	0.323993	2780.3091
344.677	0.93371421	0.3261314	2783.2576
345.77808	0.93789274	0.32766512	2778.9375
346.87915	0.93840438	0.32962403	2785.582
347.98022	0.94436395	0.33146241	2790.106
349.0813	0.94644105	0.33333778	2792.0962
350.18237	0.94967115	0.33516821	2780.4426
351.28345	0.95377243	0.33684987	2786.854
352.38452	0.95725244	0.33874843	2788.9705
353.4856	0.96034479	0.34027281	2781.1987
354.58667	0.96297991	0.34176043	2786.0393
355.68774	0.96600139	0.34342369	2785.7964
356.78882	0.97083879	0.34530559	2793.9363
357.88989	0.96987522	0.34705257	2788.8301
358.99097	0.97456223	0.34901619	2796.8721
360.09204	0.97956258	0.35141915	2799.0183
361.19312	0.98303622	0.35388741	2797.7437
362.29419	0.98655128	0.35576531	2790.8379
363.39526	0.98792797	0.35735142	2795.7378
364.49634	0.99325484	0.3593275	2804.4028
365.59741	0.9990446	0.36116034	2801.824
366.69849	0.99799228	0.36289144	2794.4607
367.79956	1.0040021	0.36486581	2799.3572
368.90063	1.0094079	0.36674601	2806.0732
370.00171	1.0095881	0.36865407	2807.0396
371.10278	1.010653	0.37058142	2800.5186
372.20386	1.0169665	0.37261751	2816.4404
373.30493	1.0183175	0.37460598	2804.1497
374.40601	1.0219088	0.37645671	2805.0767
375.50708	1.0247974	0.37806779	2806.9312
376.60815	1.0314828	0.37972829	2806.2136
377.70923	1.0328467	0.38134262	2810.6753
378.8103	1.0358336	0.38272595	2809.8325
379.91138	1.0375959	0.38462803	2814.2358
381.01245	1.0426739	0.38669169	2818.7915
382.11353	1.0485674	0.38857394	2811.2661
383.2146	1.0505716	0.39052606	2814.2322
384.31567	1.053306	0.39212292	2816.3074
385.41675	1.0569482	0.39411843	2820.5276
386.51782	1.0606325	0.39626628	2823.188
387.6189	1.0630112	0.39818364	2812.1311
388.71997	1.0667965	0.4000296	2821.4133
389.82104	1.0667495	0.40186259	2827.7651
390.92212	1.0709218	0.40380442	2820.9519
392.02319	1.0758822	0.40555185	2826.4766
393.12427	1.0777868	0.40720198	2820.1995
394.22534	1.0807384	0.40899277	2821.3315
395.32642	1.0851641	0.41069576	2823.5894
396.42749	1.0886395	0.41253009	2831.9607
397.52856	1.0957496	0.41493517	2839.7988
398.62964	1.0953249	0.41676006	2827.8064
399.73071	1.0984324	0.41862205	2830.8513
400.83179	1.1028639	0.42042416	2833.5962
401.93286	1.1065307	0.42233878	2833.5374
403.03394	1.1083252	0.42419884	2837.5464
404.13501	1.1121149	0.42584234	2841.9063
405.23608	1.1111441	0.42744243	2830.3311
406.33716	1.1164962	0.42924309	2828.3203
407.43823	1.1221848	0.4310194	2841.1606
408.53931	1.1233153	0.43279788	2842.292
409.64038	1.1304485	0.43496493	2841.5613
410.74146	1.1316938	0.43692186	2838.0408
411.84253	1.1348958	0.43828985	2837.9961
412.9436	1.1359791	0.43992808	2840.946
414.04468	1.1400504	0.44201082	2846.6553
415.14575	1.1439682	0.44406712	2845.6074
416.24683	1.1479329	0.44600457	2849.1389
417.3479	1.1519114	0.44771159	2846.783
418.44897	1.1557493	0.44957811	2846.1611
419.55005	1.1591656	0.45128742	2849.0574
420.65112	1.1620585	0.45279381	2854.9246
421.7522	1.1640004	0.45475423	2847.5493
422.85327	1.1671522	0.45640191	2844.0242
423.95435	1.1727768	0.45820829	2857.3074
425.05542	1.1737084	0.45992392	2857.5122
426.15649	1.1765921	0.46175992	2856.6648
427.25757	1.1821179	0.46403623	2862.0256
428.35864	1.18538	0.46602151	2855.6943
429.45972	1.1866308	0.46790713	2857.7373
430.56079	1.1928884	0.46985212	2868.2126
431.66187	1.1911151	0.47186577	2852.5034
432.76294	1.1953948	0.47380254	2859.5857
433.86401	1.2017698	0.47559932	2859.2324
434.96509	1.2043819	0.47772342	2865.3745
436.06616	1.2054732	0.47920913	2853.9041
437.16724	1.2090517	0.48101434	2859.1694
438.26831	1.211502	0.48285335	2864.4573
439.36938	1.2181811	0.48462975	2870.8555
440.47046	1.2221044	0.48624048	2868.1169
441.57153	1.2240587	0.48787746	2873.8137
442.67261	1.2286047	0.48963112	2870.5271
443.77368	1.2320509	0.49141863	2872.9148
444.87476	1.2331704	0.49322495	2869.8828
445.97583	1.2363659	0.49519017	2872.1863
447.0769	1.2394351	0.49667388	2870.6736
448.17798	1.2464169	0.49824789	2869.4067
449.27905	1.2453939	0.49996606	2870.9275
450.38013	1.2510248	0.50151449	2876.6465
451.4812	1.2532598	0.50334537	2878.7566
452.58228	1.2576197	0.50532889	2880.2603
453.68335	1.2584592	0.50731993	2880.0994
454.78442	1.2643747	0.50939798	2886.0754
455.8855	1.2662821	0.51100856	2881.3196
456.98657	1.2719599	0.51281589	2885.2512
458.08765	1.2715832	0.51461756	2880.938
459.18872	1.2772619	0.51632309	2887.9417
460.28979	1.2816095	0.51840878	2889.7219
461.39087	1.2816982	0.52021438	2888.4412
462.49194	1.2892945	0.52201986	2890.8362
463.59302	1.2906853	0.52385539	2893.7742
464.69409	1.2972987	0.52576762	2895.3484
465.79517	1.2960927	0.52763587	2889.3105
466.89624	1.3008331	0.52917439	2889.3125
467.99731	1.3024871	0.53092527	2886.377
469.09839	1.3065312	0.53308868	2894.3948
470.19946	1.3112205	0.53467786	2892.301
471.30054	1.3139689	0.53646511	2892.4727
472.40161	1.3176078	0.53797585	2891.8528
473.50269	1.3162518	0.53938836	2891.4448
474.60376	1.3223578	0.54112929	2895.7734
475.70483	1.328485	0.54326659	2904.8428
476.80591	1.3295791	0.54543191	2898.675
477.90698	1.3334322	0.54720873	2902.2344
479.00806	1.3358731	0.54890823	2898.1948
480.10913	1.3379599	0.55060619	2897.6304
481.21021	1.3422617	0.55218643	2901.8228
482.31128	1.3451979	0.5539099	2901.0498
483.41235	1.347203	0.55562967	2898.9329
484.51343	1.3562201	0.55767697	2908.6809
485.6145	1.3550878	0.55969781	2912.6052
486.71558	1.3565681	0.56149739	2901.2598
487.81665	1.3625721	0.56339544	2913.627
488.91772	1.3623226	0.56485081	2904.1853
490.0188	1.3705531	0.56677502	2907.1326
491.11987	1.3713375	0.56844062	2909.5366
492.22095	1.3761443	0.5699755	2907.0525
493.32202	1.3782133	0.57183558	2910.7861
494.4231	1.3825922	0.5737384	2916.9014
495.52417	1.385797	0.57562578	2914.0735
496.62524	1.3904109	0.5773738	2916.3848
497.72632	1.3916814	0.57916152	2915.7678
498.82739	1.3959491	0.58122879	2915.9285
499.92847	1.397503	0.58311045	2914.738
501.02954	1.4018472	0.58509821	2922.5613
502.13062	1.4043715	0.58672756	2917.1282
503.23169	1.4098161	0.58857954	2923.4546
504.33276	1.4137452	0.59025246	2920.3035
505.43384	1.4163353	0.59207451	2920.3367
506.53491	1.4194087	0.59384626	2929.1902
507.63599	1.4230397	0.59594691	2931.1992
508.73706	1.4250619	0.59766012	2927.1692
509.83813	1.4310547	0.59952635	2928.2036
510.93921	1.4348079	0.60148907	2940.9561
512.04028	1.4361554	0.60350353	2930.0554
513.14136	1.4355491	0.60511708	2926.6514
514.24243	1.4417312	0.60660005	2922.6101
515.34351	1.4435416	0.60828084	2927.4038
516.44458	1.4475851	0.60996675	2926.1226
517.54565	1.4490236	0.61156964	2930.2991
518.64673	1.4589052	0.61331785	2936.8967
519.7478	1.4593006	0.61527646	2936.8733
520.84888	1.460924	0.61700964	2931.1265
521.94995	1.4637603	0.61836213	2928.2412
523.05103	1.4692533	0.62034667	2940.4534
524.1521	1.4710979	0.62196988	2934.7031
525.25317	1.4747167	0.62369233	2940.0981
526.35425	1.4776198	0.62579703	2940.8572
527.45532	1.4811082	0.62757403	2937.6917
528.5564	1.4863199	0.6295355	2946.8335
529.65747	1.4888244	0.63149875	2942.355
530.75854	1.4922847	0.63317227	2945.6509
531.85962	1.49913	0.63523257	2949.0002
532.96069	1.4979216	0.63665384	2943.0769
534.06177	1.5018675	0.63843489	2944.594
535.16284	1.5045093	0.64024436	2957.2493
536.26392	1.5086514	0.64193791	2947.5913
537.36499	1.5122746	0.64399171	2951.3481
538.46606	1.5165035	0.64570343	2954.3379
539.56714	1.5195026	0.64751399	2950.8784
540.66821	1.5199932	0.64929932	2946.0674
541.76929	1.5265524	0.65134156	2960.9409
542.87036	1.5277839	0.65350354	2957.3223
543.97144	1.5270493	0.6551069	2949.0427
545.07251	1.5354742	0.65671355	2948.6309
546.17358	1.5384661	0.65841985	2958.906
547.27466	1.5405755	0.65987056	2950.1699
548.37573	1.5441705	0.66190368	2955.5227
549.47681	1.5499282	0.66361755	2960.6084
550.57788	1.550346	0.66524786	2960.3083
551.67896	1.5538504	0.66695327	2954.5586
552.78003	1.5577351	0.66896802	2962.1172
553.8811	1.5599331	0.67081088	2964.9778
554.98218	1.5643876	0.67249757	2958.9568
556.08325	1.5656768	0.67433441	2960.0095
557.18433	1.5723286	0.67600155	2966.8127
558.2854	1.5719444	0.67769063	2959.6702
559.38647	1.5781422	0.67942089	2966.8604
560.48755	1.5792111	0.68131375	2969.0288
561.58862	1.5841006	0.68342733	2973.6553
562.6897	1.5903331	0.68503326	2964.7454
563.79077	1.591948	0.68635178	2965.5583
564.89185	1.5914946	0.68784481	2964.239
565.99292	1.5997895	0.6898647	2973.6609
567.09399	1.5993792	0.69169497	2966.8923
568.19507	1.6063031	0.69331741	2968.5229
569.29614	1.6093456	0.69528735	2972.7356
570.39722	1.6101495	0.69719279	2971.0049
571.49829	1.6131788	0.69851279	2973.7781
572.59937	1.6179863	0.70067513	2983.833
573.70044	1.6204288	0.70281184	2981.3845
574.80151	1.6255682	0.70475864	2984.5181
575.90259	1.6263589	0.70689815	2979.1826
577.00366	1.6305349	0.70869744	2979.4338
578.10474	1.6328309	0.71041739	2981.3484
579.20581	1.6374712	0.71245307	2978.2766
580.30688	1.6399872	0.7142489	2988.1169
581.40796	1.6433755	0.71617723	2979.7393
582.50903	1.6449256	0.71784085	2980.2109
583.61011	1.6497023	0.71952122	2983.1313
584.71118	1.6546447	0.72118288	2980.0986
585.81226	1.658002	0.72262388	2987.6558
586.91333	1.6580833	0.72451937	2983.9233
588.0144	1.6661046	0.72622293	2985.9768
589.11548	1.6656749	0.72774786	2984.4458
590.21655	1.6690148	0.72954887	2986.1841
591.31763	1.6700932	0.7312265	2981.52
592.4187	1.675325	0.73283261	2984.6858
593.51978	1.6822141	0.73427665	2991.4937
594.62085	1.6808227	0.73591506	2990.6235
595.72192	1.6873035	0.73756129	2994.2905
596.823	1.6885188	0.7394684	2988.5994
597.92407	1.6922076	0.74148291	2992.7058
599.02515	1.6979147	0.74322432	2998.3425
600.12622	1.6964924	0.74516445	2988.252
601.22729	1.7009926	0.74686289	2995.6128
602.32837	1.7020445	0.74881315	2996.6296
603.42944	1.7093554	0.7506907	2997.2405
604.53052	1.7120029	0.75219589	2993.0498
605.63159	1.7147722	0.7541129	2999.1106
606.73267	1.7177492	0.75583255	2994.3438
607.83374	1.7223477	0.75760126	2997.1238
608.93481	1.7246417	0.75944322	3001.981
610.03589	1.7292452	0.76127958	2997.5979
611.13696	1.7303568	0.76309156	2994.969
612.23804	1.7368934	0.76491046	3002.2603
613.33911	1.7396952	0.76663691	3005.5115
614.44019	1.7457491	0.76864988	3009.9863
615.54126	1.743816	0.77014548	3004.3853
616.64233	1.7463204	0.77193391	3008.9619
617.74341	1.7523592	0.77385283	3012.8682
618.84448	1.7571032	0.77563983	3005.71
619.94556	1.7594914	0.77745086	3011.0657
621.04663	1.7618781	0.77927202	3009.4712
622.14771	1.7635158	0.78119797	3007.2966
623.24878	1.7697537	0.78272152	3003.856
624.34985	1.7711203	0.78427815	3009.1716
625.45093	1.7748768	0.78614473	3013.4749
626.552	1.7802507	0.78753376	3005.9988
627.65308	1.7838852	0.78914791	3014.9541
628.75415	1.7848369	0.79077363	3018.3154
629.85522	1.7874571	0.79285103	3014.6577
630.9563	1.7917031	0.7948395	3014.9043
632.05737	1.7949178	0.79648942	3015.8276
633.15845	1.7992266	0.79840726	3016.8125
634.25952	1.8040377	0.79994667	3020.1509
635.3606	1.8063676	0.80160826	3021.2373
636.46167	1.810645	0.80363703	3016.5266
637.56274	1.8130491	0.80533504	3021.4758
638.66382	1.8153616	0.80710751	3020.2358
639.76489	1.8196299	0.80871511	3016.6575
640.86597	1.8203115	0.81048799	3019.3635
641.96704	1.8225448	0.8124091	3026.2883
643.06812	1.8283006	0.813999	3021.4873
644.16919	1.8325821	0.81579292	3026.3403
645.27026	1.836475	0.81755668	3025.9041
646.37134	1.8380919	0.81946456	3031.3716
647.47241	1.839426	0.82159847	3023.8281
648.57349	1.847178	0.82363486	3030.4883
649.67456	1.8477193	0.82574791	3024.5574
650.77563	1.8496495	0.8272801	3017.5903
651.87671	1.8552969	0.8290928	3028.3699
652.97778	1.8594629	0.83099437	3032.0078
654.07886	1.8634771	0.83272988	3032.3372
655.17993	1.8630413	0.83452207	3025.0249
656.28101	1.8652856	0.83623123	3029.5125
657.38208	1.8706087	0.83788162	3029.4775
658.48315	1.8753725	0.83950818	3032.728
659.58423	1.8768125	0.84128124	3035.1487
660.6853	1.8830322	0.84274781	3025.5085
661.78638	1.8848505	0.84426129	3035.1985
662.88745	1.887825	0.84597933	3033.8384
663.98853	1.8922524	0.84791559	3040.7305
665.0896	1.8931422	0.84994495	3040.9702
666.19067	1.9008787	0.85199952	3041.0081
667.29175	1.9003437	0.85358882	3031.0374
668.39282	1.9035326	0.85529447	3032.4756
669.4939	1.9085279	0.85689873	3038.3135
670.59497	1.9150418	0.85848385	3043.2622
671.69604	1.9112329	0.86067593	3043.0349
672.79712	1.9145074	0.86275005	3047.759
673.89819	1.9199824	0.86443329	3040.3579
674.99927	1.9229902	0.86614197	3038.0759
676.10034	1.925405	0.86792451	3046.8276
677.20142	1.931339	0.86985898	3045.5891
678.30249	1.9336746	0.8715989	3043.6187
679.40356	1.9375957	0.87348926	3048.7822
680.50464	1.9391354	0.87529397	3038.9199
681.60571	1.9462881	0.87679201	3050.0554
682.70679	1.9487739	0.87891436	3054.238
683.80786	1.9514986	0.88100648	3049.9766
684.90894	1.9507828	0.88269836	3045.9504
686.01001	1.9552481	0.88478762	3049.2563
687.11108	1.9611444	0.88638186	3054.3696
688.21216	1.9636779	0.88819855	3045.0413
689.31323	1.9664181	0.88978887	3048.2588
690.41431	1.9706228	0.89175272	3057.1543
691.51538	1.9749274	0.89348584	3046.3872
692.61646	1.9771663	0.89508194	3048.4514
693.71753	1.9823942	0.89663827	3051.2788
694.8186	1.9848378	0.89822024	3052.416
695.91968	1.9880109	0.89999902	3066.0813
697.02075	1.9881626	0.90191144	3054.1069
698.12183	1.992023	0.90378356	3057.0762
699.2229	1.9964029	0.90595824	3058.7056
700.32397	2.0006468	0.90788531	3064.3213
701.42505	2.0059044	0.90934986	3058.6543
702.52612	2.0060732	0.91087133	3056.5439
703.6272	2.0089102	0.91263765	3067.3821
704.72827	2.0144432	0.91487193	3071.0449
705.82935	2.0178549	0.91669214	3061.4143
706.93042	2.0196416	0.91843301	3062.5452
708.03149	2.0253544	0.9203136	3065.0496
709.13257	2.0252213	0.92207813	3058.4089
710.23364	2.0283027	0.92399132	3057.7742
711.33472	2.0311875	0.92541069	3059.9644
712.43579	2.0385568	0.92727971	3068.9854
713.53687	2.0396631	0.92937165	3065.8149
714.63794	2.0411739	0.93117547	3066.8281
715.73901	2.0471137	0.93341023	3067.9026
716.84009	2.0514834	0.93512702	3074.0762
717.94116	2.0534256	0.93691421	3069.4187
719.04224	2.0563867	0.93923956	3073.6223
720.14331	2.0602429	0.94101954	3069.7207
721.24438	2.0609958	0.9425106	3066.5979
722.34546	2.0656071	0.94431037	3069.7546
723.44653	2.066051	0.94624251	3070.2422
724.54761	2.0766189	0.94814557	3074.4297
725.64868	2.0752194	0.94990212	3073.5786
726.74976	2.0778422	0.9514733	3067.0752
727.85083	2.0853491	0.95330125	3072.1201
728.9519	2.0838902	0.95503747	3071.2241
730.05298	2.0884469	0.95680082	3074.5552
731.15405	2.0906296	0.95860803	3080.2388
732.25513	2.0970547	0.96059966	3080.75
733.3562	2.1009922	0.96256024	3079.03
734.45728	2.1016304	0.96420228	3071.0198
735.55835	2.1064873	0.96596813	3071.6616
736.65942	2.1100774	0.96755767	3082.1226
737.7605	2.110218	0.96928579	3071.3364
738.86157	2.1131113	0.97073501	3075.4836
739.96265	2.1177232	0.97257239	3075.0759
741.06372	2.122057	0.97442091	3081.0833
742.16479	2.1248314	0.97627157	3076.8804
743.26587	2.1297877	0.9781391	3079.2854
744.36694	2.1318166	0.97989607	3081.7136
745.46802	2.1357157	0.9818511	3084.1003
746.56909	2.1378422	0.9839021	3088.5259
747.67017	2.1415634	0.9859004	3075.1399
748.77124	2.1449399	0.98780447	3080.5432
749.87231	2.1479573	0.98960406	3080.8745
750.97339	2.1504323	0.99141276	3084.6367
752.07446	2.157855	0.9931671	3084.7917
753.17554	2.1600604	0.99483448	3087.2761
754.27661	2.1608868	0.99684823	3089.6289
755.37769	2.1657391	0.99873549	3089.335
756.47876	2.168366	1.0005876	3088.615
757.57983	2.170013	1.0025358	3086.8484
758.68091	2.1773038	1.0040935	3090.0334
759.78198	2.1791346	1.0060308	3088.7483
760.88306	2.1796913	1.0078497	3085.8115
761.98413	2.184891	1.0097599	3092.4155
763.08521	2.1889203	1.0118945	3091.7104
764.18628	2.1935606	1.0138388	3089.8228
765.28735	2.1931233	1.0159177	3090.8308
766.38843	2.1992202	1.017808	3087.6348
767.4895	2.201138	1.0195371	3093.6719
768.59058	2.2032044	1.0213953	3092.8389
769.69165	2.2116604	1.0236276	3102.0264
770.79272	2.2079439	1.0252501	3086.9819
771.8938	2.2139044	1.0269337	3089.311
772.99487	2.2224927	1.0288153	3097.7705
774.09595	2.2230365	1.0307078	3092.8538
775.19702	2.225816	1.0322886	3094.1726
776.2981	2.226938	1.0340316	3091.4692
777.39917	2.2344799	1.0360689	3101.0266
778.50024	2.2324705	1.0379045	3095.2087
779.60132	2.2374673	1.039777	3099.5093
780.70239	2.241643	1.0415627	3094.8037
781.80347	2.2479796	1.0435647	3096.2566
782.90454	2.2472744	1.0451928	3095.7925
784.00562	2.2528715	1.0470592	3096.4973
785.10669	2.2550583	1.0486996	3101.4287
786.20776	2.2570531	1.0504252	3101.8596
787.30884	2.2606461	1.0525534	3106.4309
788.40991	2.2665782	1.0545835	3107.2795
789.51099	2.2675681	1.0566654	3110.1567
790.61206	2.268537	1.0588981	3098.644
791.71313	2.2738731	1.0607734	3103.5244
792.81421	2.2764857	1.062753	3101.428
793.91528	2.282196	1.0643851	3103.7971
795.01636	2.2834034	1.0660805	3099.9497
796.11743	2.2862353	1.0680125	3101.5049
797.21851	2.2928851	1.0698647	3108.1323
798.31958	2.2964177	1.0718118	3107.0085
799.42065	2.2946725	1.0737348	3100.9316
800.52173	2.3036141	1.0756502	3106.8777
801.6228	2.3036997	1.0775446	3103.5037
802.72388	2.3060429	1.0793018	3104.0459
803.82495	2.3107746	1.0812846	3109.7563
804.92603	2.3136175	1.0833738	3115.8228
806.0271	2.3159838	1.0851038	3106.9541
807.12817	2.3180366	1.0872289	3110.9348
808.22925	2.3259561	1.0890281	3105.8315
809.33032	2.3264089	1.0905689	3102.7258
810.4314	2.3331251	1.0922058	3108.7617
811.53247	2.3324394	1.0942309	3114.4807
812.63354	2.336134	1.0965868	3113.0852
813.73462	2.3405845	1.0987338	3113.116
814.83569	2.3442221	1.1007515	3110.144
815.93677	2.3472347	1.1027217	3110.9841
817.03784	2.3525712	1.1045344	3112.5618
818.13892	2.3521883	1.1067441	3112.3994
819.23999	2.3549101	1.1084827	3115.0159
820.34106	2.3612766	1.1102281	3115.7449
821.44214	2.3642342	1.1120791	3118.0952
822.54321	2.3676445	1.1141386	3115.8777
823.64429	2.3712349	1.1161084	3119.2388
824.74536	2.3724074	1.11803	3113.8088
825.84644	2.3754396	1.1201578	3116.2249
826.94751	2.3825803	1.1223742	3116.248
828.04858	2.3828127	1.1242477	3111.2378
829.14966	2.3874426	1.1260033	3110.7312
830.25073	2.3905885	1.1276698	3117.2646
831.35181	2.3947425	1.130073	3125.011
832.45288	2.3992467	1.1319982	3124.1462
833.55396	2.3975823	1.1338385	3115.5762
834.65503	2.4027407	1.1358565	3118.0476
835.7561	2.4082885	1.1380124	3129.2195
836.85718	2.4074891	1.1399022	3115.7283
837.95825	2.4121401	1.1419796	3122.2207
839.05933	2.4159167	1.1436815	3117.0847
840.1604	2.4207058	1.1456521	3121.8877
841.26147	2.4257798	1.1472038	3121.6279
842.36255	2.4282613	1.1494576	3132.8362
843.46362	2.4288254	1.151737	3118.877
844.5647	2.4318388	1.1532041	3112.083
845.66577	2.4356191	1.1552298	3117.9014
846.76685	2.439266	1.157395	3125.5569
847.86792	2.4436119	1.1592535	3121.6072
848.96899	2.442713	1.1609449	3122.4114
850.07007	2.4487829	1.162645	3124.9768
851.17114	2.454881	1.1648171	3129.3931
852.27222	2.4556224	1.1667281	3129.0674
853.37329	2.457654	1.1690878	3125.2524
854.47437	2.4602077	1.1712283	3123.5972
855.57544	2.4684665	1.1731222	3126.8301
856.67651	2.4685311	1.1747638	3120.5696
857.77759	2.4718907	1.1768223	3129.0508
858.87866	2.4761281	1.1787344	3124.9485
859.97974	2.478281	1.1804265	3124.3772
861.08081	2.480762	1.182572	3129.2205
862.18188	2.4865611	1.1851097	3131.9729
863.28296	2.4893911	1.187037	3131.2373
864.38403	2.4932747	1.1893592	3137.7373
865.48511	2.4946401	1.1913821	3132.1563
866.58618	2.4998724	1.1936172	3135.6294
867.68726	2.499476	1.1959064	3130.3721
868.78833	2.5053635	1.1977645	3128.6743
869.8894	2.5080328	1.1998301	3129.177
870.99048	2.5144033	1.2016717	3129.1926
872.09155	2.5164657	1.2033863	3132.8669
873.19263	2.5178943	1.2056917	3129.7996
874.2937	2.5220032	1.2078041	3139.0752
875.39478	2.526104	1.2098753	3138.9485
876.49585	2.5287352	1.2120146	3132.7188
877.59692	2.5315876	1.2141349	3129.8833
878.698	2.5353856	1.2161819	3129.5845
879.79907	2.5376697	1.2179981	3139.4387
880.90015	2.5419414	1.2198099	3130.3511
882.00122	2.5467083	1.2219052	3137.0352
883.10229	2.5492353	1.2238325	3136.7585
884.20337	2.5523961	1.2257804	3133.2117
885.30444	2.5534062	1.2278913	3133.6208
886.40552	2.5603075	1.2299799	3146.0725
887.50659	2.5623839	1.2320125	3133.5105
888.60767	2.5640426	1.234197	3134.5125
889.70874	2.5665071	1.2364175	3133.0491
890.80981	2.5707059	1.2381403	3135.5107
891.91089	2.5739653	1.2401985	3136.4417
893.01196	2.5782435	1.2425001	3137.4209
894.11304	2.5829039	1.244688	3139.9167
895.21411	2.584039	1.2465122	3128.1821
896.31519	2.5895956	1.2486671	3140.1938
897.41626	2.5925286	1.2511483	3145.9375
898.51733	2.5962884	1.2535192	3140.6633
899.61841	2.5971134	1.2558117	3135.1995
900.71948	2.6020589	1.2579073	3136.5793
901.82056	2.6028867	1.2598201	3134.8152
902.92163	2.607394	1.2618001	3137.749
904.02271	2.608624	1.2637091	3138.197
905.12378	2.6134145	1.2657405	3136.3486
906.22485	2.6166379	1.2678365	3137.5979
907.32593	2.6232686	1.270015	3145.2329
908.427	2.6250455	1.2723908	3142.1252
909.52808	2.6294775	1.2743549	3143.3848
910.62915	2.6317213	1.2760514	3142.5566
911.73022	2.6356514	1.2782964	3144.3826
912.8313	2.6378574	1.2802414	3137.147
913.93237	2.639488	1.2821927	3137.1455
915.03345	2.64536	1.2842798	3145.7058
916.13452	2.6485021	1.286446	3145.5728
917.2356	2.6503134	1.2886856	3142.5461
918.33667	2.6517777	1.2908003	3142.1169
919.43774	2.65396	1.2927979	3138.5017
920.53882	2.6600606	1.2947851	3142.2036
921.63989	2.6639223	1.296804	3141.8926
922.74097	2.666029	1.2990307	3145.1877
923.84204	2.6701572	1.3014601	3143.3738
924.94312	2.6731989	1.3038344	3141.5901
926.04419	2.6780524	1.3062116	3149.6301
927.14526	2.6807911	1.3086672	3148.1396
928.24634	2.6833997	1.3109531	3147.2007
929.34741	2.688525	1.3131009	3147.8872
930.44849	2.6922033	1.3151523	3138.1282
931.54956	2.6920536	1.3174779	3149.1228
932.65063	2.6965945	1.3195819	3146.4993
933.75171	2.6969922	1.3214979	3134.3726
934.85278	2.7005062	1.3235143	3144.387
935.95386	2.7061744	1.3255852	3151.6062
937.05493	2.706666	1.327988	3149.5776
938.15601	2.7154944	1.330452	3144.271
939.25708	2.7191489	1.3324877	3144.6555
940.35815	2.7181859	1.3342046	3144.2048
941.45923	2.7228751	1.3364079	3150.1838
942.5603	2.7273672	1.3387728	3154.2671
943.66138	2.7295511	1.3412933	3145.116
944.76245	2.7328494	1.3436668	3150.5015
945.86353	2.7349803	1.3455327	3146.1929
946.9646	2.7391381	1.3476927	3146.6748
948.06567	2.7446251	1.3497913	3153.1421
949.16675	2.7470343	1.3517917	3147.114
950.26782	2.7511292	1.3542788	3151.6504
951.3689	2.7521334	1.3564733	3147.873
952.46997	2.7560337	1.3588011	3147.4824
953.57104	2.7581668	1.3612492	3151.5913
954.67212	2.7638347	1.3633279	3146.3481
955.77319	2.7705946	1.3656913	3154.6367
956.87427	2.7672837	1.3677953	3150.0632
957.97534	2.7736061	1.3700802	3150.3352
959.07642	2.7765799	1.3722099	3143.1733
960.17749	2.7807238	1.3742166	3153.9077
961.27856	2.7842321	1.3766233	3155.9512
962.37964	2.7874148	1.3789563	3148.5176
963.48071	2.7914186	1.3811741	3155.4526
964.58179	2.7940025	1.3831499	3156.8545
965.68286	2.7990351	1.3859367	3158.9199
966.78394	2.7980111	1.3882487	3150.5503
967.88501	2.8019454	1.3908478	3151.1824
968.98608	2.8045785	1.3931682	3151.4167
970.08716	2.8071945	1.395932	3159.1084
971.18823	2.8136942	1.3983693	3148.4482
972.28931	2.8157563	1.4005779	3152.1624
973.39038	2.819905	1.4027585	3150.1711
974.49146	2.8245184	1.4055153	3157.9329
975.59253	2.8239944	1.4077163	3153.2104
976.6936	2.827177	1.4096831	3145.0239
977.79468	2.8320227	1.4122815	3154.5479
978.89575	2.8383596	1.4147981	3155.2717
979.99683	2.8393128	1.4169636	3148.7273
981.0979	2.8416557	1.4191486	3154.8298
982.19897	2.847918	1.4215339	3150.6997
983.30005	2.8470376	1.42389	3150.9243
984.40112	2.8546526	1.4261566	3157.5315
985.5022	2.8562989	1.428635	3151.3689
986.60327	2.8575358	1.4308044	3149.7144
987.70435	2.8648736	1.4330105	3156.1138
988.80542	2.8672168	1.4354221	3154.3899
989.90649	2.8702648	1.4377	3151.7732
991.00757	2.8724475	1.4401896	3156.4297
992.10864	2.8752356	1.442557	3162.2188
993.20972	2.8792825	1.4449159	3156.6895
994.31079	2.8799179	1.4471552	3150.6477
995.41187	2.8814497	1.4491642	3154.3215
996.51294	2.8874509	1.4514579	3150.5461
997.61401	2.8904579	1.4537351	3156.3059
998.71509	2.8968158	1.4560456	3152.6389
999.81616	2.8970928	1.4588749	3157.6621
1000.9172	2.9025586	1.4615917	3160.3958
1002.0183	2.9081736	1.4642227	3155.5017
1003.1194	2.907439	1.4668504	3152.843
1004.2205	2.9142544	1.4693964	3153.9749
1005.3215	2.9170763	1.4719394	3157.8218
1006.4226	2.9181499	1.4747282	3159.5464
1007.5237	2.9249406	1.4773213	3152.7466
1008.6248	2.9245582	1.4792118	3143.3889
1009.7258	2.9279246	1.4813387	3153.7598
1010.8269	2.9304993	1.4837209	3153.7195
1011.928	2.9348655	1.4862945	3156.1941
1013.0291	2.9388497	1.4891403	3158.0437
1014.1301	2.9418609	1.4916341	3155.4143
1015.2312	2.9449906	1.4942889	3151.2966
1016.3323	2.9474676	1.4969144	3154.1897
1017.4333	2.9545293	1.4991757	3152.2717
1018.5344	2.9616189	1.5015852	3159.8801
1019.6355	2.9561141	1.5039454	3150.3596
1020.7366	2.9602206	1.5067689	3154.8538
1021.8376	2.9647677	1.5095155	3154.147
1022.9387	2.9702313	1.5114329	3156.4858
1024.0398	2.9678102	1.5135024	3145.8792
1025.1409	2.9751773	1.5157948	3157.3945
1026.2419	2.9792488	1.5179982	3156.3618
1027.343	2.9828701	1.5205152	3149.5923
1028.4441	2.9846282	1.5231152	3164.1348
1029.5452	2.9876568	1.5256393	3154.189
1030.6462	2.9898565	1.528632	3158.2419
1031.7473	2.9944239	1.5311283	3149.2402
1032.8484	2.9978557	1.5335793	3151.3369
1033.9495	3.0024605	1.535332	3143.7227
1035.0505	3.0068641	1.5374577	3149.6082
1036.1516	3.0111392	1.5392385	3156.8979
1037.2527	3.0133436	1.5413514	3153.7134
1038.3538	3.0158572	1.5436919	3155.2451
1039.4548	3.0168397	1.5463966	3160.6257
1040.5559	3.0215442	1.5492496	3154.3965
1041.657	3.0233476	1.5519127	3152.9768
1042.7581	3.0281758	1.5547494	3158.4312
1043.8591	3.0303674	1.5576165	3158.1682
1044.9602	3.0353551	1.5602759	3156.9219
1046.0613	3.0347066	1.5630071	3148.5859
1047.1624	3.0383646	1.5656921	3152.6934
1048.2634	3.0448422	1.5681355	3151.3137
1049.3645	3.0474	1.5705928	3149.4189
1050.4656	3.05024	1.5728172	3150.2817
1051.5667	3.0553715	1.5759251	3159.7209
1052.6677	3.0563645	1.5783303	3150.905
1053.7688	3.0593882	1.5812793	3151.123
1054.8699	3.0631163	1.5840406	3152.9729
1055.9709	3.0673287	1.5864837	3149.5706
1057.072	3.0700707	1.589358	3150.3958
1058.1731	3.0731187	1.5921278	3150.9065
1059.2742	3.074898	1.5947084	3151.3188
1060.3752	3.0821984	1.5972403	3149.0347
1061.4763	3.084456	1.5997823	3151.1584
1062.5774	3.0879455	1.6028572	3156.136
1063.6785	3.0897596	1.6055998	3145.4805
1064.7795	3.0944445	1.6079011	3149.8872
1065.8806	3.0952411	1.6103162	3151.2429
1066.9817	3.103498	1.6127013	3157.6521
1068.0828	3.1048346	1.6153281	3148.9487
1069.1838	3.1082013	1.618336	3155.0437
1070.2849	3.1099012	1.6215844	3150.0486
1071.386	3.1146264	1.6242833	3151.0374
1072.4871	3.1168165	1.626819	3150.0049
1073.5881	3.1201878	1.6294065	3150.0181
1074.6892	3.1216233	1.6325583	3149.2407
1075.7903	3.1259868	1.6354301	3148.7383
1076.8914	3.1302075	1.6385396	3153.8359
1077.9924	3.131654	1.6414685	3149.2251
1079.0935	3.1389759	1.6445909	3153.4622
1080.1946	3.1404898	1.6472421	3146.4363
1081.2957	3.1456699	1.6500679	3149.082
1082.3967	3.1473515	1.6527721	3146.2434
1083.4978	3.1519272	1.6556934	3154.4592
1084.5989	3.1516719	1.6591517	3153.0684
1085.7	3.1586208	1.662248	3146.2319
1086.801	3.1596866	1.6651256	3146.084
1087.9021	3.1613002	1.6681062	3148.04
1089.0032	3.1649592	1.6706007	3143.4431
1090.1042	3.1686769	1.6729722	3143.1729
1091.2053	3.1719582	1.6754047	3150.1089
1092.3064	3.1762979	1.678771	3149.0405
1093.4075	3.1805987	1.6823674	3149.1345
1094.5085	3.1833963	1.6851315	3148.7319
1095.6096	3.1840954	1.6880852	3146.1394
1096.7107	3.1893811	1.6905061	3139.9822
1097.8118	3.1944969	1.6930331	3148.4099
1098.9128	3.197505	1.6960341	3143.2734
1100.0139	3.2005513	1.698755	3150.3447
1101.115	3.2004697	1.702063	3137.301
1102.2161	3.2086046	1.7051288	3152.1824
1103.3171	3.2115581	1.7076614	3141.8816
1104.4182	3.2146821	1.7102576	3143.2617
1105.5193	3.2151103	1.7129581	3140.6006
1106.6204	3.2180159	1.7157254	3140.3013
1107.7214	3.222399	1.7186378	3145.6067
1108.8225	3.2277386	1.7219332	3144.7676
1109.9236	3.2281561	1.7246096	3140.4065
1111.0247	3.2308118	1.7277013	3143.4666
1112.1257	3.2376986	1.7309048	3145.7578
1113.2268	3.2371261	1.7342552	3136.5046
1114.3279	3.2428439	1.7376442	3138.7871
1115.429	3.2434514	1.7409213	3137.3408
1116.53	3.2477851	1.7441037	3138.4246
1117.6311	3.2512746	1.7474571	3140.2578
1118.7322	3.2554972	1.7500919	3134.5769
1119.8333	3.2608566	1.7527109	3130.8186
1120.9343	3.2619157	1.7556597	3131.9973
1122.0354	3.2662334	1.75894	3143.1563
1123.1365	3.2715201	1.7620021	3136.9819
1124.2375	3.2726829	1.7653244	3135.7666
1125.3386	3.2763116	1.7685311	3137.3667
1126.4397	3.2816877	1.771607	3132.8076
1127.5408	3.281945	1.774597	3133.2144
1128.6418	3.2852221	1.7779777	3132.6086
1129.7429	3.2912059	1.781006	3137.9814
1130.844	3.2910006	1.7840663	3129.2742
1131.9451	3.2973654	1.7872838	3133.0325
1133.0461	3.2963715	1.7904218	3131.884
1134.1472	3.3023307	1.7940587	3127.9441
1135.2483	3.3046517	1.7972224	3129.4043
1136.3494	3.3094237	1.8002397	3125.0933
1137.4504	3.3117332	1.803461	3129.9514
1138.5515	3.3129356	1.8061217	3121.2383
1139.6526	3.3192959	1.8091217	3127.2688
1140.7537	3.3191407	1.8126773	3129.8467
1141.8547	3.3232856	1.8157938	3122.0715
1142.9558	3.3281713	1.8190305	3123.2183
1144.0569	3.3291962	1.821926	3118.813
1145.158	3.3333817	1.8250955	3123.1812
1146.259	3.3397799	1.8284603	3122.6829
1147.3601	3.3417609	1.8316202	3125.9216
1148.4612	3.3450084	1.8354886	3119.9075
1149.5623	3.346508	1.8385178	3121.7009
1150.6633	3.3528202	1.8423767	3119.7791
1151.7644	3.3538826	1.8459841	3115.6414
1152.8655	3.3575871	1.8489732	3117.145
1153.9666	3.360301	1.8523628	3119.1016
1155.0676	3.3631608	1.8556356	3116.3916
1156.1687	3.3675263	1.8588818	3117.1838
1157.2698	3.3713744	1.8622608	3114.3459
1158.3708	3.3770928	1.8656662	3115.1448
1159.4719	3.3803334	1.8687038	3109.5491
1160.573	3.3781753	1.8718532	3107.9648
1161.6741	3.3866808	1.8751832	3114.9294
1162.7751	3.3882873	1.8781859	3106.8408
1163.8762	3.3905609	1.8808745	3106.6418
1164.9773	3.3943536	1.8840237	3108.7856
1166.0784	3.3941252	1.8871309	3100.5178
1167.1794	3.4019475	1.8904583	3110.0737
1168.2805	3.4008644	1.8937408	3102.1455
1169.3816	3.4095778	1.896906	3104.416
1170.4827	3.4117725	1.8999695	3104.7578
1171.5837	3.4105024	1.9030483	3099.7444
1172.6848	3.4151952	1.9060919	3104.4922
1173.7859	3.4190729	1.9094927	3102.3813
1174.887	3.4245515	1.9131941	3105.0068
1175.988	3.4299767	1.9166002	3100.613
1177.0891	3.4304445	1.920239	3098.6912
1178.1902	3.4325304	1.9237865	3101.0046
1179.2913	3.4375415	1.9275594	3093.7026
1180.3923	3.440588	1.931126	3092.1899
1181.4934	3.447289	1.9344712	3093.7805
1182.5945	3.4487195	1.9374093	3092.188
1183.6956	3.4525964	1.9406832	3088.8872
1184.7966	3.4521635	1.9443231	3091.7358
1185.8977	3.4537561	1.9481312	3083.7693
1186.9988	3.4614904	1.9516504	3084.1633
1188.0999	3.4652426	1.9551487	3090.6353
1189.2009	3.4664023	1.9582134	3078.5916
1190.302	3.4733593	1.9615802	3085.2097
1191.4031	3.4725008	1.964698	3070.5803
1192.5042	3.4780078	1.9680496	3077.7864
1193.6052	3.483325	1.9715632	3077.4199
1194.7063	3.4832532	1.9748418	3076.6489
1195.8074	3.4848204	1.9781604	3074.1096
1196.9084	3.4872086	1.9815741	3067.593
1198.0095	3.4944069	1.9849111	3070.8706
1199.1106	3.4976854	1.9886398	3075.6013
1200.2117	3.4981091	1.9919316	3062.6814
1201.3127	3.5018375	1.9955056	3071.4233
1202.4138	3.5070589	1.9991086	3069.0681
1203.5149	3.5078039	2.0023935	3057.9375
1204.616	3.513458	2.0055926	3063.9561
1205.717	3.5138056	2.0091994	3061.1189
1206.8181	3.5183818	2.0128131	3060.7368
1207.9192	3.5222008	2.0161924	3053.6406
1209.0203	3.5264299	2.0192966	3054.2949
1210.1213	3.5288157	2.0229299	3056.4631
1211.2224	3.5318363	2.0263269	3052.5498
1212.3235	3.5397644	2.0299327	3054.4854
1213.4246	3.5387456	2.0333035	3047.4958
1214.5256	3.5445645	2.0373061	3047.5601
1215.6267	3.5456622	2.0402155	3038.9058
1216.7278	3.548985	2.0434792	3038.8049
1217.8289	3.5526521	2.0467224	3036.5479
1218.9299	3.5574961	2.0498667	3037.8479
1220.031	3.5600722	2.0533764	3041.8198
1221.1321	3.5662291	2.0574088	3042.2214
1222.2332	3.565028	2.0611191	3030.3174
1223.3342	3.568347	2.0642681	3023.3809
1224.4353	3.5733953	2.0671	3031.9111
1225.5364	3.5770864	2.0702703	3025.2383
1226.6375	3.5806942	2.0734456	3024.8013
1227.7385	3.5835931	2.0763865	3023.7805
1228.8396	3.5855205	2.0797708	3023.2
1229.9407	3.58934	2.0826552	3018.7131
1231.0417	3.5934057	2.0850964	3015.2109
1232.1428	3.5952613	2.0871031	3010.9785
1233.2439	3.596072	2.0885181	3006.2268
1234.345	3.6047316	2.0891604	3017.6462
1235.446	3.6057911	2.0895913	3010.8733
1236.5471	3.6127362	2.0898025	3003.8804
1237.6482	3.6155653	2.0899363	3007.7874
1238.7493	3.6152017	2.0898488	2998.6707
1239.8503	3.6197233	2.0899143	3000.5552
1240.9514	3.6237085	2.0898421	3001.5891
1242.0525	3.6239057	2.0895431	2994.5791
1243.1536	3.6289017	2.0892951	2996.0442
1244.2546	3.6329291	2.0900433	2996.3408
1245.3557	3.6360426	2.0901046	2989.8577
1246.4568	3.6388021	2.0902007	2987.3633
1247.5579	3.6436932	2.0906091	2983.875
1248.6589	3.6445332	2.0905538	2976.2693
1249.76	3.6483498	2.0905075	2973.76
1250.8611	3.6527677	2.0901973	2985.6123
1251.9622	3.6563051	2.0899167	2967.9006
1253.0632	3.6577597	2.0903015	2969.6187
1254.1643	3.6609831	2.0903127	2960.8015
1255.2654	3.6671736	2.090678	2963.1477
1256.3665	3.666187	2.0906911	2956.4573
1257.4675	3.6717691	2.0901558	2962.5107
1258.5686	3.6740985	2.0901294	2952.7009
1259.6697	3.6820526	2.0902987	2956.4888
1260.7708	3.681354	2.0902832	2946.1465
1261.8718	3.6870427	2.0903237	2939.2595
1262.9729	3.6897995	2.0901868	2940.8242
1264.074	3.6902528	2.0903709	2939.4294
1265.175	3.6960793	2.0905976	2934.394
1266.2761	3.701371	2.0909333	2931.9199
1267.3772	3.7055664	2.0913539	2921.4678
1268.4783	3.7051656	2.0912437	2922.7063
1269.5793	3.7109361	2.0912259	2920.6641
1270.6804	3.7124124	2.091373	2917.1804
1271.7815	3.7158937	2.0914359	2913.1609
1272.8826	3.7212808	2.0908463	2909.3699
1273.9836	3.720927	2.0904298	2898.6472
1275.0847	3.7236991	2.0907772	2900.6333
1276.1858	3.725122	2.0905111	2900.0769
1277.2869	3.7308364	2.0906067	2886.7156
1278.3879	3.7354383	2.0903087	2888.2129
1279.489	3.7384586	2.0905004	2892.4695
1280.5901	3.7422493	2.0904443	2883.5544
1281.6912	3.7457721	2.0907106	2869.8027
1282.7922	3.7470858	2.0908279	2867.3037
1283.8933	3.7511902	2.0911224	2864.6672
1284.9944	3.7548926	2.0910587	2871.1565
1286.0955	3.7591269	2.0917919	2856.2256
1287.1965	3.7594087	2.0919814	2853.5276
1288.2976	3.7640085	2.0922086	2845.1143
1289.3987	3.7672424	2.0920124	2847.657
1290.4998	3.7707274	2.0917583	2843.0139
1291.6008	3.7729385	2.0917399	2834.5195
1292.7019	3.7748301	2.091712	2825.2175
1293.803	3.7822273	2.0915742	2823.4902
1294.9041	3.7839966	2.0917981	2815.6292
1296.0051	3.7859297	2.0918202	2813.8779
1297.1062	3.7930546	2.0916576	2814.5757
1298.2073	3.7937851	2.0918498	2806.1155
1299.3083	3.7987106	2.0917277	2792.3279
1300.4094	3.7983131	2.0916252	2783.0547
1301.5105	3.8043988	2.09166	2792.5188
1302.6116	3.8067551	2.0918705	2784.6799
1303.7126	3.8115828	2.0919926	2769.9417
1304.8137	3.8138833	2.0919361	2765.9277
1305.9148	3.8141191	2.0925603	2750.2766
1307.0159	3.8216662	2.0922344	2750.8892
1308.1169	3.8226542	2.091943	2735.9385
1309.218	3.8249588	2.0920258	2728.6685
1310.3191	3.8288369	2.0920792	2724.0872
1311.4202	3.8314455	2.0919642	2711.0364
1312.5212	3.8375502	2.0918405	2710.2578
1313.6223	3.8404715	2.0919881	2698.4758
1314.7234	3.8439364	2.0919735	2680.6226
1315.8245	3.8517413	2.0918548	2674.0093
1316.9255	3.854728	2.091563	2636.9832
1318.0266	3.8534942	2.0910761	2566.4556
1318.7273	3.8602734	2.0906022	2489.9504