File: datasets/am_bench_2022/raw_data/0-XY.10-1/specimen.dat
MTS793|MPT|ENU|1|2|.|/|:|1|0|0|A

Operator Information						Time:	41.44751	Sec	10/13/2021 2:09:08 PM
Operator	Nick Derimow
Project	AM Bench 2022 mini-tensile challenge
Specimen ID	0-XY.10-1
Material	PBF-L Inconel 625
Specimen Width	2.56	mm
Specimen Thickness	1.51	mm
Notes
Operator Information End

Data Acquisition						Time:	1042.4414	Sec	10/13/2021 2:25:49 PM
Time	Axial Displacement	Axial Extensometer	Axial Force
Sec	mm	mm	N
41.561279	0.0031055657	-0.00012573271	62.716103
42.562256	0.0041904636	-0.00032060654	80.618507
43.563232	0.0070150392	-8.4644889e-05	93.21022
44.564209	0.0071396129	0.00033710984	108.48957
45.565186	0.010045325	0.00017276066	121.13096
46.566162	0.017496543	0.00013047218	132.60028
47.567139	0.017313575	0.00049354305	148.8717
48.568115	0.018818449	0.00037362141	160.7025
49.569092	0.022240896	0.00060316588	182.04588
50.570068	0.028279802	0.00054585893	204.07585
51.571045	0.028682822	0.0007207641	214.80916
52.572021	0.03454081	0.00089313678	227.5778
53.572998	0.036363877	0.00080241618	251.3864
54.573975	0.038677659	0.00074482238	275.71515
55.574951	0.040278062	0.0011485713	295.29358
56.575928	0.042810105	0.00098183716	310.34903
57.576904	0.048459053	0.00099415937	328.82779
58.577881	0.050011717	0.001036121	348.63922
59.578857	0.052273456	0.0013015091	373.0116
60.579834	0.056684144	0.0014902198	398.53027
61.580811	0.060371105	0.0014826799	415.83212
62.581787	0.062097874	0.0015141541	434.72546
63.582764	0.065060548	0.0016409929	456.42856
64.58374	0.066632882	0.0017293983	478.90024
65.584717	0.070611455	0.0018051373	497.75922
66.585693	0.073089145	0.001968167	526.39594
67.58667	0.078684211	0.0020873591	551.05615
68.587646	0.079884253	0.0020475981	570.58685
69.588623	0.084448613	0.0022140124	597.51025
70.5896	0.083864674	0.0025366882	614.59875
71.590576	0.089333519	0.0024863956	645.10052
72.591553	0.090142019	0.0027912047	673.76385
73.592529	0.094735831	0.0029408182	694.45178
74.593506	0.094792172	0.0029021481	726.89508
75.594482	0.098445326	0.0028734633	747.2572
76.595459	0.10131421	0.0031303444	770.91211
77.596436	0.10993428	0.0033291809	806.00275
78.597412	0.10878074	0.0033217638	818.91583
79.598389	0.11138327	0.0036544134	849.96851
80.599365	0.11474589	0.0036238313	887.0379
81.600342	0.11828943	0.0038101152	914.32654
82.601318	0.12048458	0.0039930437	941.09863
83.602295	0.12528861	0.0040034931	968.0603
84.603271	0.12393105	0.0042829164	988.26959
85.604248	0.12852998	0.0042793555	1015.1912
86.605225	0.13191535	0.0045639006	1044.8756
87.606201	0.13353577	0.0045581637	1073.8768
88.607178	0.13805199	0.0048239534	1096.8387
89.608154	0.14258038	0.0049109492	1134.5703
90.609131	0.14412382	0.0050387266	1154.1406
91.610107	0.14754361	0.0050836662	1185.9425
92.611084	0.151364	0.005348071	1217.6279
93.612061	0.15508702	0.0054152207	1243.9689
94.613037	0.15624706	0.0056859567	1280.4631
95.614014	0.15710618	0.0059328848	1298.3766
96.61499	0.16170675	0.005882699	1332.9554
97.615967	0.16476782	0.0061515495	1362.1536
98.616943	0.1677479	0.0062776306	1378.6075
99.61792	0.17088699	0.00638582	1409.0348
100.6189	0.17464627	0.0066410252	1448.2628
101.61987	0.17840746	0.0066670994	1461.8278
102.62085	0.18133837	0.006822323	1496.7303
103.62183	0.18424696	0.0069928435	1523.434
104.6228	0.18786405	0.0071421298	1549.3375
105.62378	0.19225813	0.0073385024	1573.7695
106.62476	0.19120254	0.0073723667	1601.9415
107.62573	0.1963034	0.0076646162	1631.8602
108.62671	0.1976772	0.0077279923	1646.5872
109.62769	0.20066446	0.0079447236	1679.9028
110.62866	0.2007792	0.0080337226	1705.6735
111.62964	0.20456763	0.0081502469	1727.026
112.63062	0.20960252	0.0083659738	1752.9368
113.63159	0.21748933	0.0084291575	1792.0546
114.63257	0.21672837	0.0086514652	1809.4825
115.63354	0.21845499	0.0087652039	1834.9474
116.63452	0.22168545	0.009047552	1860.9429
117.6355	0.22877786	0.0091064982	1893.5078
118.63647	0.22857849	0.0092375251	1911.2209
119.63745	0.23494112	0.0094473884	1938.0015
120.63843	0.23372653	0.0094589647	1954.2269
121.6394	0.23897436	0.0097186444	1979.6298
122.64038	0.24142522	0.0099052116	2008.4954
123.64136	0.24390705	0.010100972	2026.7617
124.64233	0.24787554	0.010219659	2046.7959
125.64331	0.24919811	0.010360807	2064.8345
126.64429	0.25369373	0.010618217	2086.6416
127.64526	0.25865474	0.010695767	2105.822
128.64624	0.25651526	0.010896251	2123.8025
129.64722	0.26195917	0.01109632	2149.9858
130.64819	0.26378101	0.011220065	2164.082
131.64917	0.26699221	0.011400764	2185.7358
132.65015	0.26907533	0.011592736	2204.291
133.65112	0.2766847	0.011868197	2227.0598
134.6521	0.27833283	0.011918628	2241.6873
135.65308	0.28011021	0.012364334	2259.769
136.65405	0.2840732	0.012584488	2282.4861
137.65503	0.2869986	0.012794625	2291.0874
138.65601	0.29011616	0.01285828	2317.9597
139.65698	0.29053292	0.013115142	2325.6604
140.65796	0.29273653	0.013369027	2339.1775
141.65894	0.29838264	0.013523332	2359.0945
142.65991	0.30279511	0.013739518	2358.6738
143.66089	0.30435574	0.014071835	2379.4204
144.66187	0.3083615	0.014260415	2391.9919
145.66284	0.31311703	0.014440275	2406.9397
146.66382	0.31339973	0.014706675	2416.3713
147.66479	0.318257	0.014909212	2429.6868
148.66577	0.31674021	0.015081591	2440.2073
149.66675	0.32199642	0.015431743	2454.271
150.66772	0.32565722	0.01578681	2470.1938
151.6687	0.32612008	0.016125442	2478.9319
152.66968	0.33389449	0.016313722	2488.354
153.67065	0.33603498	0.016714955	2498.2476
154.67163	0.3378821	0.016980512	2507.6643
155.67261	0.34127504	0.017384659	2522.6494
156.67358	0.34204686	0.017849326	2536.2402
157.67456	0.34719035	0.018157279	2537.4875
158.67554	0.35200384	0.018646739	2553.8857
159.67651	0.35379905	0.018937495	2562.2725
160.67749	0.35592294	0.019449674	2572.8589
161.67847	0.35614136	0.019749776	2576.1787
162.67944	0.3615467	0.020137379	2585.9827
163.68042	0.36662942	0.020660754	2596.7524
164.6814	0.36750364	0.021144705	2596.491
165.68237	0.37096113	0.021641303	2610.7234
166.68335	0.37454543	0.022075608	2622.3699
167.68433	0.37820786	0.022734517	2622.0967
168.6853	0.38049543	0.023232123	2635.4197
169.68628	0.38311762	0.023714492	2645.5032
170.68726	0.38752288	0.024487754	2647.687
171.68823	0.39223412	0.025155257	2654.3372
172.68921	0.3936401	0.025820931	2667.8623
173.69019	0.39599282	0.026367128	2672.2102
174.69116	0.4010998	0.027101563	2677.811
175.69214	0.40106088	0.027902985	2677.2014
176.69312	0.40368164	0.02873946	2687.8289
177.69409	0.40920669	0.029570967	2690.3733
178.69507	0.41077548	0.030275805	2697.2417
179.69604	0.41518059	0.031152215	2700.9229
180.69702	0.41822302	0.031936824	2707.5342
181.698	0.41909811	0.032823611	2708.5867
182.69897	0.42630956	0.033933513	2725.0518
183.69995	0.42588666	0.034674894	2716.1064
184.70093	0.42663163	0.035634916	2722.1475
185.7019	0.43304223	0.036655139	2729.2764
186.70288	0.43261707	0.03749318	2738.5171
187.70386	0.44040099	0.038465612	2745.5725
188.70483	0.44025591	0.039610427	2747.8784
189.70581	0.44443604	0.04060398	2755.4431
190.70679	0.44776177	0.04163168	2754.4656
191.70776	0.45285267	0.042835969	2761.3801
192.70874	0.45311716	0.04414041	2767.5908
193.70972	0.45609644	0.045464236	2770.6182
194.71069	0.45932636	0.046530433	2769.9253
195.71167	0.46226627	0.04747637	2770.9612
196.71265	0.46503308	0.048645925	2775.2397
197.71362	0.46791419	0.049656156	2780.2322
198.7146	0.467426	0.050946288	2780.8691
199.71558	0.47194031	0.052112382	2780.1438
200.71655	0.47767127	0.053537384	2794.5264
201.71753	0.47974551	0.054516193	2787.2356
202.71851	0.48408383	0.05571821	2797.7468
203.71948	0.4864583	0.056961119	2796.7803
204.72046	0.48931548	0.058025885	2797.3662
205.72144	0.49427542	0.059307132	2810.8853
206.72241	0.4940154	0.060629349	2807.5276
207.72339	0.50071532	0.062118739	2812.7705
208.72437	0.50146496	0.0631833	2808.1089
209.72534	0.50713855	0.064626396	2816.397
210.72632	0.50681847	0.065887272	2817.873
211.72729	0.5117557	0.067322418	2826.6013
212.72827	0.51471555	0.068477981	2820.7529
213.72925	0.51383716	0.070032895	2826.7922
214.73022	0.52130699	0.071564205	2825.7393
215.7312	0.52372652	0.073175654	2842.9424
216.73218	0.52746803	0.074808359	2834.0142
217.73315	0.52835923	0.076037899	2832.3005
218.73413	0.53051406	0.077454157	2834.2454
219.73511	0.53557009	0.078814954	2839.6362
220.73608	0.53602904	0.080196984	2838.2976
221.73706	0.54073906	0.081286818	2835.1797
222.73804	0.54448462	0.082474306	2848.5371
223.73901	0.54876035	0.084195308	2851.2986
224.73999	0.54744053	0.085638769	2847.3545
225.74097	0.54846638	0.087135032	2844.771
226.74194	0.55694062	0.088718139	2854.9651
227.74292	0.55923265	0.089987814	2856.9697
228.7439	0.5631485	0.091435336	2860.917
229.74487	0.56217057	0.092687264	2853.1833
230.74585	0.57057899	0.09410543	2861.7078
231.74683	0.57048786	0.095438309	2865.3269
232.7478	0.57198572	0.096737921	2862.1299
233.74878	0.57428378	0.098248713	2864.656
234.74976	0.58073926	0.099735044	2872.3765
235.75073	0.58316308	0.1016415	2870.5811
236.75171	0.58540797	0.10306029	2871.7617
237.75269	0.58809066	0.1047045	2874.5984
238.75366	0.59069616	0.10633519	2873.2651
239.75464	0.59762061	0.10779783	2878.2559
240.75562	0.5992347	0.10926336	2876.1533
241.75659	0.59862357	0.1107005	2878.8054
242.75757	0.60213858	0.11221882	2876.4387
243.75854	0.60860062	0.11350711	2879.2859
244.75952	0.6066888	0.11465865	2883.3281
245.7605	0.61321014	0.11623506	2882.426
246.76147	0.61266106	0.11763525	2885.8643
247.76245	0.61527526	0.11938766	2887.0193
248.76343	0.62220931	0.12109116	2891.8296
249.7644	0.62527752	0.12245388	2888.8552
250.76538	0.62787485	0.12384895	2895.833
251.76636	0.62952173	0.12521425	2898.9358
252.76733	0.6353001	0.12681437	2894.6472
253.76831	0.63610178	0.12821883	2893.1936
254.76929	0.63708645	0.12993814	2895.3904
255.77026	0.64367342	0.13140586	2899.4299
256.77124	0.64615589	0.13317733	2902.1638
257.77222	0.64711189	0.1347173	2908.4446
258.77319	0.65186405	0.13648264	2907.457
259.77417	0.6580683	0.13811013	2911.6587
260.77515	0.65985495	0.13952203	2914.499
261.77612	0.66003358	0.14108299	2911.4839
262.7771	0.66463417	0.14268023	2912.5876
263.77808	0.66731411	0.14435101	2912.6497
264.77905	0.6700567	0.14582993	2915.0427
265.78003	0.67117727	0.14739098	2915.3152
266.78101	0.6761573	0.148856	2914.2842
267.78198	0.67917591	0.1501271	2916.6187
268.78296	0.67996573	0.15175709	2916.3474
269.78394	0.68491852	0.15310839	2919.6008
270.78491	0.68783063	0.15475248	2922.5364
271.78589	0.69240147	0.15661979	2927.8015
272.78687	0.69319397	0.1582382	2921.7842
273.78784	0.69909704	0.15951332	2925.6162
274.78882	0.70176226	0.16057895	2928.0295
275.78979	0.70355725	0.16218704	2931.9971
276.79077	0.70318002	0.16355652	2930.4395
277.79175	0.7091763	0.16528389	2939.2134
278.79272	0.70945269	0.16676562	2929.8044
279.7937	0.71294916	0.16841409	2936.3354
280.79468	0.7155773	0.17001973	2928.6392
281.79565	0.71869731	0.17116663	2928.3684
282.79663	0.72159237	0.17274931	2938.5981
283.79761	0.72922081	0.1744754	2942.6841
284.79858	0.72970551	0.17599021	2936.8259
285.79956	0.7273643	0.17770205	2938.4724
286.80054	0.73433685	0.17921081	2939.272
287.80151	0.74087405	0.18068273	2946.8591
288.80249	0.73925149	0.18236151	2946.9153
289.80347	0.74326998	0.18403563	2948.3728
290.80444	0.7490868	0.18569151	2950.4121
291.80542	0.7508437	0.18734235	2952.3118
292.8064	0.75307679	0.18869755	2949.2063
293.80737	0.7560938	0.19047649	2952.2468
294.80835	0.75881326	0.19211902	2950.2896
295.80933	0.75979984	0.19352864	2953.7935
296.8103	0.76448888	0.19503839	2951.8569
297.81128	0.76679099	0.19658689	2955.5442
298.81226	0.77130508	0.19796969	2955.6719
299.81323	0.77448702	0.19968493	2963.0845
300.81421	0.77936953	0.20143016	2960.3525
301.81519	0.78137952	0.20288505	2961.3115
302.81616	0.78357852	0.20412394	2962.677
303.81714	0.78674239	0.2057731	2963.8652
304.81812	0.79050618	0.20724784	2967.3525
305.81909	0.78986782	0.20881249	2965.6648
306.82007	0.79651177	0.21035059	2970.4104
307.82104	0.79911935	0.21201706	2970.021
308.82202	0.79894602	0.21355878	2968.6548
309.823	0.80544263	0.21514793	2968.6318
310.82397	0.80741614	0.21648206	2971.9175
311.82495	0.81057489	0.21781053	2969.9946
312.82593	0.81587863	0.2191748	2973.8579
313.8269	0.81940907	0.22044183	2976.9761
314.82788	0.81925189	0.22209966	2978.5408
315.82886	0.82318747	0.22352548	2973.364
316.82983	0.82744151	0.22498035	2979.5454
317.83081	0.82882452	0.22634232	2981.3169
318.83179	0.83177179	0.22801101	2984.0845
319.83276	0.83543652	0.22971411	2982.4692
320.83374	0.8373329	0.23108926	2983.698
321.83472	0.8418929	0.23269589	2982.032
322.83569	0.84482652	0.23401612	2978.8093
323.83667	0.84657258	0.23553097	2993.5913
324.83765	0.85009241	0.23707066	2983.3169
325.83862	0.85367793	0.23889107	2991.2771
326.8396	0.85306633	0.24058771	2989.771
327.84058	0.85938221	0.24205816	2989.7839
328.84155	0.86260945	0.24324399	2985.4722
329.84253	0.86524755	0.2448317	2985.6589
330.84351	0.86435425	0.24636877	2991.6904
331.84448	0.87329537	0.24808384	3005.2253
332.84546	0.87365907	0.24966265	2991.7048
333.84644	0.87379205	0.25106788	2998.0737
334.84741	0.87935418	0.25244614	2995.022
335.84839	0.88183594	0.25378752	2994.9597
336.84937	0.8874532	0.25535291	3005.1069
337.85034	0.89105308	0.25696948	2999.29
338.85132	0.8948009	0.25860274	3006.2856
339.85229	0.89308786	0.26036561	3006.6082
340.85327	0.89686763	0.2617957	3000.1284
341.85425	0.89970714	0.2633546	3005.1555
342.85522	0.90528566	0.26502287	3009.021
343.8562	0.90813297	0.26655978	3011.55
344.85718	0.90972292	0.26809892	3002.6697
345.85815	0.91288519	0.26961699	3010.8662
346.85913	0.91582394	0.27118665	3008.7593
347.86011	0.92005426	0.27255604	3007.4961
348.86108	0.92090988	0.27399489	3005.3589
349.86206	0.92295897	0.27530247	3007.5566
350.86304	0.92872453	0.27678308	3017.772
351.86401	0.92934209	0.27818483	3015.7988
352.86499	0.93787748	0.27997467	3019.1067
353.86597	0.93633324	0.28146547	3021.8879
354.86694	0.94011366	0.28296176	3017.6558
355.86792	0.94278914	0.28430685	3019.9421
356.8689	0.94850957	0.28598559	3022.1311
357.86987	0.94948733	0.28751817	3026.4775
358.87085	0.95372176	0.28899145	3022.3879
359.87183	0.954193	0.29030782	3018.5762
360.8728	0.9571473	0.2917529	3021.9126
361.87378	0.96282738	0.29326144	3026.5918
362.87476	0.96733701	0.29473141	3036.825
363.87573	0.96557558	0.29619911	3021.7737
364.87671	0.97013128	0.29759085	3025.9451
365.87769	0.9738248	0.29914463	3036.022
366.87866	0.97505248	0.30054265	3032.9526
367.87964	0.98039001	0.30233771	3036.3413
368.88062	0.98014152	0.30404684	3034.3684
369.88159	0.98664385	0.30573541	3038.4287
370.88257	0.9913004	0.30732667	3035.4255
371.88354	0.99189943	0.30866456	3037.2703
372.88452	0.99742675	0.30992952	3041.053
373.8855	0.99652034	0.31157368	3044.4653
374.88647	1.0007437	0.3131133	3045.0791
375.88745	1.0003647	0.31452864	3037.9082
376.88843	1.0071636	0.31605959	3042.7549
377.8894	1.0124463	0.3173236	3042.2786
378.89038	1.0126207	0.318515	3043.9333
379.89136	1.0147741	0.31998405	3044.8162
380.89233	1.0166453	0.32155907	3043.1362
381.89331	1.0239471	0.32312822	3056.8018
382.89429	1.0263398	0.32476345	3050.1755
383.89526	1.0255829	0.32627985	3050.7612
384.89624	1.0305175	0.32792127	3052.5886
385.89722	1.0309547	0.32940409	3047.5452
386.89819	1.0346153	0.33068702	3051.519
387.89917	1.0399053	0.33247051	3053.8206
388.90015	1.0418019	0.33376208	3050.2344
389.90112	1.0442723	0.3351225	3049.9617
390.9021	1.0479748	0.33623609	3056.8909
391.90308	1.0520391	0.33787274	3052.6563
392.90405	1.0502741	0.33941981	3059.1179
393.90503	1.0595162	0.34086224	3063.342
394.90601	1.0601503	0.34220859	3060.9106
395.90698	1.0627412	0.34378889	3065.3271
396.90796	1.0654285	0.34542605	3065.9341
397.90894	1.0680244	0.3474566	3062.9653
398.90991	1.0704601	0.34886697	3062.3599
399.91089	1.0733814	0.35024855	3064.604
400.91187	1.0770154	0.3516793	3067.677
401.91284	1.0779676	0.35312888	3060.3396
402.91382	1.0829766	0.3547855	3073.2017
403.91479	1.0868251	0.35641456	3070.2344
404.91577	1.0896989	0.35755381	3065.3652
405.91675	1.0932595	0.35913137	3067.053
406.91772	1.0988675	0.36055362	3069.1965
407.9187	1.1021887	0.36180368	3074.2954
408.91968	1.1039903	0.3634252	3075.6519
409.92065	1.1038234	0.36503199	3072.5842
410.92163	1.1070992	0.36631373	3069.5356
411.92261	1.1145015	0.36780629	3076.3958
412.92358	1.1119354	0.36920169	3073.5483
413.92456	1.1153201	0.3708986	3080.0027
414.92554	1.1218451	0.37230641	3079.5171
415.92651	1.1252819	0.37388477	3078.552
416.92749	1.1239229	0.37529913	3080.6252
417.92847	1.1275302	0.37672168	3077.1287
418.92944	1.1319335	0.37828436	3081.4937
419.93042	1.1379703	0.37994656	3086.4299
420.9314	1.135166	0.38143042	3082.6982
421.93237	1.1393867	0.38291314	3083.1006
422.93335	1.145401	0.38437939	3087.2578
423.93433	1.1481668	0.38581863	3091.8069
424.9353	1.1517444	0.38728753	3083.6245
425.93628	1.1543454	0.38876846	3088.0044
426.93726	1.153438	0.38988876	3080.3611
427.93823	1.1607045	0.39141029	3091.2583
428.93921	1.1657901	0.3927035	3094.6621
429.94019	1.1635797	0.39429095	3087.4978
430.94116	1.1675361	0.39571089	3093.4402
431.94214	1.1696795	0.39722615	3097.9709
432.94312	1.1716226	0.39880085	3096.7351
433.94409	1.1788499	0.40063542	3102.7297
434.94507	1.1789089	0.40206954	3094.8992
435.94604	1.1846472	0.40333384	3094.7642
436.94702	1.1884774	0.40508473	3103.467
437.948	1.1910616	0.40664339	3103.4653
438.94897	1.1972039	0.40807208	3100.9014
439.94995	1.1955825	0.40941393	3100.6887
440.95093	1.2008723	0.41063443	3102.2551
441.9519	1.1985668	0.41197112	3099.1531
442.95288	1.2038447	0.41319954	3102.502
443.95386	1.2067524	0.41490263	3109.3933
444.95483	1.2077128	0.41631675	3105.571
445.95581	1.2159542	0.41787437	3108.6611
446.95679	1.2138916	0.41953674	3105.3892
447.95776	1.2194719	0.42115143	3113.2373
448.95874	1.2214044	0.42285326	3108.1003
449.95972	1.225023	0.42413586	3106.1975
450.96069	1.2260669	0.42545804	3109.3818
451.96167	1.2299079	0.42706618	3118.3823
452.96265	1.2342186	0.42845297	3117.9355
453.96362	1.2410049	0.43006623	3118.2532
454.9646	1.2413958	0.43145931	3104.7791
455.96558	1.2405252	0.43271449	3112.2192
456.96655	1.24436	0.43400598	3111.8689
457.96753	1.2520732	0.43554398	3119.2175
458.96851	1.2534658	0.43668538	3114.2217
459.96948	1.2568544	0.43791991	3114.0586
460.97046	1.2573242	0.43921274	3113.0637
461.97144	1.2605261	0.44067502	3121.6572
462.97241	1.2607836	0.44211632	3121.5479
463.97339	1.267386	0.4435989	3123.9329
464.97437	1.2685993	0.44507292	3119.7246
465.97534	1.2752442	0.4465231	3125.6799
466.97632	1.2752317	0.44785401	3119.614
467.97729	1.2808961	0.44924393	3130.8152
468.97827	1.2806304	0.45082068	3122.7754
469.97925	1.2852664	0.45249248	3131.8743
470.98022	1.2891879	0.45411178	3128.2603
471.9812	1.2934197	0.45565096	3129.0132
472.98218	1.2943708	0.45701548	3126.4172
473.98315	1.2945158	0.45835352	3127.7458
474.98413	1.3001159	0.46006447	3136.2148
475.98511	1.3011099	0.46159968	3131.5708
476.98608	1.3058944	0.463092	3132.7451
477.98706	1.3098153	0.46425486	3127.4526
478.98804	1.3128452	0.46569529	3136.427
479.98901	1.3145295	0.46721208	3129.1643
480.98999	1.3199606	0.46892482	3142.2791
481.99097	1.3232902	0.4704046	3139.5964
482.99194	1.3239104	0.47181517	3138.5522
483.99292	1.326359	0.47345158	3140.8247
484.9939	1.3332794	0.47470894	3140.8342
485.99487	1.3321208	0.47640386	3142.1699
486.99585	1.3376406	0.47808331	3147.2183
487.99683	1.3380831	0.47947595	3136.2561
488.9978	1.344851	0.48103359	3144.189
489.99878	1.3445109	0.48235834	3144.4268
490.99976	1.3508414	0.4837091	3144.6067
492.00073	1.35271	0.48508978	3144.2598
493.00171	1.3532537	0.48646581	3136.1558
494.00269	1.3566692	0.48762846	3149.4534
495.00366	1.3624244	0.48896137	3148.5164
496.00464	1.3654555	0.49049783	3147.3486
497.00562	1.3671428	0.4918859	3147.136
498.00659	1.3691078	0.49331269	3145.3916
499.00757	1.3729857	0.49469501	3149.978
500.00854	1.3735898	0.496315	3151.4907
501.00952	1.3780811	0.49793738	3149.1929
502.0105	1.381139	0.49936086	3150.01
503.01147	1.3834558	0.50077993	3150.6675
504.01245	1.3861402	0.50246036	3152.0144
505.01343	1.3905103	0.50389487	3158.4983
506.0144	1.3931775	0.50531554	3157.845
507.01538	1.3963495	0.50690329	3159.0676
508.01636	1.4013653	0.50852221	3155.511
509.01733	1.4014357	0.51008654	3153.228
510.01831	1.4025093	0.51152945	3155.5859
511.01929	1.4074113	0.51282477	3157.1401
512.02026	1.4130669	0.51445204	3162.8767
513.02124	1.4129716	0.51580018	3155.4399
514.02222	1.4198478	0.51715368	3158.3809
515.02319	1.420518	0.51841813	3160.1855
516.02417	1.4233935	0.51973748	3159.562
517.02515	1.4254928	0.52123559	3166.043
518.02612	1.4326788	0.52293098	3163.4604
519.0271	1.4307004	0.52440113	3159.9036
520.02808	1.4354956	0.52579951	3165.4714
521.02905	1.4379677	0.52713239	3166.9915
522.03003	1.4406399	0.52841944	3169.4771
523.03101	1.44324	0.53010827	3174.6531
524.03198	1.4445508	0.53220022	3171.533
525.03296	1.4501631	0.53390014	3165.7351
526.03394	1.4536742	0.53516471	3163.95
527.03491	1.4544171	0.53625673	3161.8059
528.03589	1.4600341	0.53757727	3170.6382
529.03687	1.4620129	0.53910941	3174.9487
530.03784	1.4631374	0.54044789	3171.4038
531.03882	1.4709905	0.54202193	3177.8906
532.03979	1.472146	0.54358011	3173.6108
533.04077	1.4758599	0.54492903	3173.1816
534.04175	1.4750297	0.54625994	3175.4797
535.04272	1.4817609	0.54777038	3179.1982
536.0437	1.4835846	0.54918426	3180.2251
537.04468	1.4887967	0.55075103	3180.1748
538.04565	1.4875454	0.55217916	3173.1895
539.04663	1.4922038	0.55366248	3179.5303
540.04761	1.4963117	0.55497193	3175.9683
541.04858	1.4955196	0.55626744	3173.2827
542.04956	1.5026327	0.55764776	3179.782
543.05054	1.503716	0.55914599	3183.2302
544.05151	1.5097489	0.56071168	3183.9822
545.05249	1.5120835	0.56237376	3187.7214
546.05347	1.5122008	0.56407338	3191.7271
547.05444	1.5166563	0.56570864	3179.979
548.05542	1.5192612	0.56681126	3177.5605
549.0564	1.5214616	0.56828225	3187.6191
550.05737	1.5258869	0.56985587	3184.1541
551.05835	1.5306512	0.57099009	3187.4475
552.05933	1.5324041	0.5726192	3189.8904
553.0603	1.5331284	0.57423806	3188.2603
554.06128	1.5391293	0.57601124	3189.3589
555.06226	1.541741	0.57737577	3188.5093
556.06323	1.5439565	0.57879317	3193.8162
557.06421	1.5482576	0.58027524	3190.0991
558.06519	1.5511246	0.5817461	3193.7739
559.06616	1.551614	0.58362067	3191.7905
560.06714	1.5543998	0.58502787	3188.6509
561.06812	1.5608289	0.58641899	3194.6765
562.06909	1.5589318	0.58788538	3194.2698
563.07007	1.564455	0.58953577	3191.6726
564.07104	1.5655817	0.59055197	3183.8157
565.07202	1.5696714	0.59194303	3196.7959
566.073	1.5734504	0.59351832	3194.6753
567.07397	1.5781479	0.59509611	3198.3408
568.07495	1.5780538	0.59655029	3201.9514
569.07593	1.583093	0.5978682	3198.0649
570.0769	1.5836092	0.59932071	3195.3892
571.07788	1.5896955	0.60085458	3202.1685
572.07886	1.5885133	0.60242444	3198.9167
573.07983	1.5935289	0.60400587	3200.2695
574.08081	1.5986103	0.60562158	3204.8357
575.08179	1.600082	0.60722125	3205.3555
576.08276	1.6045476	0.60879946	3204.145
577.08374	1.607869	0.61035854	3206.9895
578.08472	1.6079708	0.61201239	3205.4346
579.08569	1.6134604	0.61361766	3206.5278
580.08667	1.6156765	0.61513692	3207.6768
581.08765	1.6188359	0.61683631	3215.1477
582.08862	1.6236463	0.61836559	3205.9019
583.0896	1.6236737	0.6196664	3206.9473
584.09058	1.6296409	0.62135935	3214.7551
585.09155	1.6316357	0.62263411	3210.6992
586.09253	1.6371862	0.62384135	3204.3047
587.09351	1.633829	0.6252014	3207.5537
588.09448	1.6400204	0.6265986	3213.0906
589.09546	1.6436635	0.6280818	3214.7559
590.09644	1.6427681	0.62971604	3212.9236
591.09741	1.6509309	0.63145208	3218.9448
592.09839	1.6509303	0.63300258	3217.8193
593.09937	1.6564108	0.63474262	3215.8301
594.10034	1.6593435	0.63646895	3217.6296
595.10132	1.6624575	0.63789231	3212.6855
596.10229	1.6636584	0.63930935	3218.2524
597.10327	1.6686417	0.64075166	3218.9275
598.10425	1.6690633	0.64223456	3212.811
599.10522	1.6716045	0.64353293	3208.8584
600.1062	1.6751733	0.64447618	3210.9465
601.10718	1.6799095	0.64577687	3213.1545
602.10815	1.6785291	0.64698505	3215.2056
603.10913	1.6882483	0.64871746	3227.9309
604.11011	1.6876451	0.65012777	3221.3223
605.11108	1.6882731	0.65184706	3218.6711
606.11206	1.6934637	0.65324497	3223.1809
607.11304	1.6980681	0.65478075	3228.8772
608.11401	1.700359	0.65644532	3224.2124
609.11499	1.7025859	0.65795058	3224.1995
610.11597	1.7086794	0.6595543	3228.5503
611.11694	1.7104598	0.66096151	3224.3088
612.11792	1.7114167	0.66249466	3229.2307
613.1189	1.7130243	0.66414046	3227.7373
614.11987	1.71817	0.66560316	3227.4004
615.12085	1.7169905	0.66711247	3223.4385
616.12183	1.7257376	0.66864151	3222.0483
617.1228	1.7265027	0.67026949	3229.5454
618.12378	1.7276713	0.67172116	3226.7676
619.12476	1.7333221	0.67297918	3222.4373
620.12573	1.7367487	0.67444289	3228.967
621.12671	1.738547	0.67583907	3226.9822
622.12769	1.741207	0.67740697	3236.573
623.12866	1.7445717	0.67913824	3234.4082
624.12964	1.7483401	0.6808632	3234.2468
625.13062	1.7509675	0.68280679	3231.2979
626.13159	1.7538273	0.6843133	3225.8298
627.13257	1.7578197	0.68576574	3228.5605
628.13354	1.7624953	0.6870153	3232.3687
629.13452	1.7659107	0.68849313	3234.7769
630.1355	1.7670913	0.68996745	3236.572
631.13647	1.770135	0.69176173	3237.4441
632.13745	1.7723722	0.69321811	3235.5635
633.13843	1.7784661	0.69491774	3236.2576
634.1394	1.7754971	0.6963433	3229.8459
635.14038	1.7812656	0.69770163	3233.4314
636.14136	1.7863088	0.69930297	3242.2307
637.14233	1.7857281	0.70087701	3238.7991
638.14331	1.7930849	0.70264399	3242.4993
639.14429	1.7919226	0.70400691	3233.9551
640.14526	1.7970468	0.70558286	3235.4907
641.14624	1.7988023	0.70713568	3234.6333
642.14722	1.8019776	0.70831746	3235.6301
643.14819	1.8028721	0.71001476	3238.228
644.14917	1.8091547	0.71135312	3241.4795
645.15015	1.8130701	0.71278703	3243.905
646.15112	1.8135566	0.71423376	3243.8308
647.1521	1.8148228	0.71594995	3237.4558
648.15308	1.8213744	0.71768981	3246.4023
649.15405	1.8218987	0.71920091	3239.0852
650.15503	1.8260559	0.72091132	3246.8271
651.15601	1.8288121	0.72258705	3247.0686
652.15698	1.8301915	0.72418594	3243.2556
653.15796	1.8367151	0.7258656	3249.1802
654.15894	1.837458	0.72758114	3243.5422
655.15991	1.8420191	0.72914714	3245.2708
656.16089	1.8400531	0.73057866	3244.9509
657.16187	1.8469101	0.73205656	3247.2776
658.16284	1.8506559	0.73349053	3247.0642
659.16382	1.851408	0.73502696	3244.6584
660.16479	1.8564932	0.73654234	3246.739
661.16577	1.8574209	0.73798376	3241.0313
662.16675	1.8642441	0.73962504	3257.0793
663.16772	1.8627526	0.74110633	3246.8167
664.1687	1.8687633	0.74259108	3248.1819
665.16968	1.8688947	0.74405998	3248.5945
666.17065	1.8709837	0.74598891	3260.5811
667.17163	1.8766614	0.74803376	3258.3577
668.17261	1.8786341	0.74964148	3247.7576
669.17358	1.8843805	0.75118756	3257.2563
670.17456	1.8860468	0.75269216	3249.417
671.17554	1.8885797	0.75425529	3251.4568
672.17651	1.8931229	0.75557101	3255.1614
673.17749	1.8946095	0.75713605	3254.436
674.17847	1.8978555	0.75867897	3258.3955
675.17944	1.8987615	0.7604214	3254.7429
676.18042	1.9060967	0.76192009	3251.6895
677.1814	1.9074074	0.76328838	3252.749
678.18237	1.9098505	0.76492774	3253.0999
679.18335	1.9134415	0.76670212	3259.374
680.18433	1.9149208	0.76856613	3260.4153
681.1853	1.9173787	0.77037066	3253.1477
682.18628	1.919715	0.77196527	3251.342
683.18726	1.9220836	0.77367389	3262.2554
684.18823	1.9252479	0.77495009	3250.2974
685.18921	1.9319706	0.77643061	3255.5532
686.19019	1.9349332	0.77757806	3252.1252
687.19116	1.9369917	0.77921569	3258.4841
688.19214	1.9423808	0.78055745	3267.6846
689.19312	1.9456987	0.78237909	3264.2012
690.19409	1.9481272	0.7841022	3266.1025
691.19507	1.9523249	0.7857703	3264.7231
692.19604	1.9550527	0.7874521	3261.9561
693.19702	1.9549893	0.78898805	3264.4971
694.198	1.9564235	0.79039091	3261.043
695.19897	1.9596295	0.79183954	3254.1411
696.19995	1.9630787	0.7936675	3267.3301
697.20093	1.9671425	0.79546493	3265.3113
698.2019	1.9695718	0.79695308	3259.2837
699.20288	1.972796	0.79855746	3261.3604
700.20386	1.9752647	0.79986399	3261.3865
701.20483	1.979732	0.80122	3266.5469
702.20581	1.9819614	0.80286926	3266.1487
703.20679	1.9862522	0.80492288	3266.9551
704.20776	1.9898899	0.80684203	3276.6428
705.20874	1.9930967	0.80858594	3273.8218
706.20972	1.9962147	0.81047302	3266.3477
707.21069	1.9980729	0.81203467	3268.4041
708.21167	1.9991678	0.81362218	3262.3921
709.21265	2.0053146	0.81512707	3267.1858
710.21362	2.0049844	0.81662327	3266.0149
711.2146	2.0077949	0.81814831	3267.4595
712.21558	2.0118923	0.81990623	3266.5249
713.21655	2.0152903	0.8218717	3272.0964
714.21753	2.0199523	0.82350707	3273.5935
715.21851	2.0216689	0.8251242	3269.6816
716.21948	2.0226333	0.82674438	3268.5583
717.22046	2.0243223	0.82843465	3267.75
718.22144	2.0289736	0.83024365	3270.9456
719.22241	2.0338833	0.83209002	3272.2278
720.22339	2.0340176	0.83373094	3267.8931
721.22437	2.0406361	0.83533543	3268.0535
722.22534	2.0441375	0.83662581	3271.387
723.22632	2.0440774	0.838144	3274.4563
724.22729	2.0505836	0.83994752	3275.1604
725.22827	2.0519831	0.84153903	3269.9451
726.22925	2.0513783	0.84330595	3274.8252
727.23022	2.0574822	0.84522474	3274.7695
728.2312	2.0597346	0.84683996	3272.1951
729.23218	2.0648165	0.84844548	3276.2043
730.23315	2.0659919	0.85002053	3271.3169
731.23413	2.0678961	0.85195982	3275.2461
732.23511	2.0733595	0.85356784	3278.7227
733.23608	2.0792887	0.85522223	3279.1028
734.23706	2.0779848	0.85717541	3273.0342
735.23804	2.0832438	0.85879666	3281.3262
736.23901	2.0844498	0.86033523	3271.1968
737.23999	2.085427	0.86194396	3269.1387
738.24097	2.0887156	0.86353052	3274.9465
739.24194	2.0899694	0.86524808	3275.5381
740.24292	2.0945737	0.86698747	3276.5679
741.2439	2.1014943	0.86873037	3276.4578
742.24487	2.1033733	0.8700096	3268.6697
743.24585	2.1032634	0.87170792	3279.51
744.24683	2.1083074	0.87356001	3273.0249
745.2478	2.1093853	0.87546462	3277.1296
746.24878	2.1158366	0.87717748	3279.0474
747.24976	2.1174059	0.87877572	3283.0161
748.25073	2.1207132	0.88060123	3280.0513
749.25171	2.1226301	0.88219762	3277.8345
750.25269	2.1257348	0.88396126	3275.7688
751.25366	2.1298764	0.88561398	3285.1772
752.25464	2.1286755	0.88750762	3280.4314
753.25562	2.1375918	0.88922679	3282.8723
754.25659	2.1381009	0.89085019	3279.8577
755.25757	2.1380701	0.89258301	3281.3442
756.25854	2.1437895	0.89432102	3281.4497
757.25952	2.1481695	0.8962338	3283.0457
758.2605	2.1506443	0.89824414	3286.6907
759.26147	2.1546898	0.9000392	3284.6118
760.26245	2.1558211	0.90215528	3286.9238
761.26343	2.1571856	0.90402681	3279.0564
762.2644	2.1652689	0.90577799	3283.116
763.26538	2.1628535	0.90725178	3272.5767
764.26636	2.1677084	0.90880358	3283.3105
765.26733	2.1697025	0.91020048	3277.2461
766.26831	2.1747584	0.9118703	3285.4443
767.26929	2.1753573	0.91346675	3282.9678
768.27026	2.1830652	0.91516846	3288.3064
769.27124	2.1818552	0.91730756	3286.9768
770.27222	2.1870463	0.91936827	3285.1953
771.27319	2.1880817	0.9211899	3283.2385
772.27417	2.1910067	0.92295486	3282.4097
773.27515	2.1959908	0.92492586	3286.1724
774.27612	2.1976593	0.92673934	3285.2808
775.2771	2.2004228	0.9284597	3282.8818
776.27808	2.2011218	0.93018758	3278.2563
777.27905	2.2051711	0.93176585	3280.656
778.28003	2.2096016	0.93360919	3289.0195
779.28101	2.2156093	0.93554431	3287.4849
780.28198	2.2185435	0.9374584	3287.1902
781.28296	2.2209256	0.93916529	3281.5493
782.28394	2.2215493	0.94047332	3276.6279
783.28491	2.22701	0.94230396	3291.2351
784.28589	2.2287078	0.94421971	3288.0637
785.28687	2.2309635	0.94591171	3283.5581
786.28784	2.2369268	0.94774264	3286.5955
787.28882	2.2366529	0.94967192	3286.8979
788.28979	2.2405684	0.95159322	3285.9199
789.29077	2.2430706	0.95310801	3283.7961
790.29175	2.2440455	0.9548915	3283.1006
791.29272	2.2495821	0.9566775	3284.7856
792.2937	2.2521734	0.95865285	3290.2771
793.29468	2.2543786	0.96089655	3285.3962
794.29565	2.2596118	0.96246552	3288.0037
795.29663	2.2626307	0.96464437	3289.4202
796.29761	2.2665393	0.96654946	3287.9895
797.29858	2.2662516	0.96857709	3284.593
798.29956	2.2728477	0.97045141	3296.3311
799.30054	2.2746396	0.97220945	3287.5471
800.30151	2.2794955	0.97423619	3294.3601
801.30249	2.2824826	0.97606695	3291.2073
802.30347	2.2825968	0.97762513	3286.5391
803.30444	2.2831686	0.97911596	3281.1089
804.30542	2.2899611	0.98111248	3292.2087
805.3064	2.2951858	0.98284179	3290.6699
806.30737	2.2954352	0.98465914	3292.7659
807.30835	2.298553	0.98639691	3288.0444
808.30933	2.299458	0.98845583	3292.3989
809.3103	2.3032136	0.99051839	3289.3357
810.31128	2.3030879	0.99230611	3284.7859
811.31226	2.3096893	0.99422735	3285.6541
812.31323	2.3152044	0.99595988	3291.5991
813.31421	2.3167632	0.99793184	3296.8708
814.31519	2.3192391	0.99994749	3289.5354
815.31616	2.3243792	1.0020623	3292.5811
816.31714	2.3270657	1.0038234	3292.2192
817.31812	2.3276227	1.0053489	3293.0313
818.31909	2.3325453	1.0072705	3287.218
819.32007	2.3336649	1.0088729	3286.6389
820.32104	2.3376079	1.0104748	3286.8093
821.32202	2.3374887	1.0126439	3294.426
822.323	2.3413839	1.0147568	3291.5215
823.32397	2.3478677	1.0168242	3292.6135
824.32495	2.3475146	1.0184354	3284.5452
825.32593	2.3502753	1.020301	3286.0864
826.3269	2.3531196	1.0221529	3293.1484
827.32788	2.3601665	1.0243137	3290.3979
828.32886	2.3602417	1.0264773	3292.3018
829.32983	2.3628175	1.0285496	3286.4436
830.33081	2.3656626	1.0305377	3290.4514
831.33179	2.3696289	1.0327096	3297.5618
832.33276	2.3724875	1.0348767	3293.0703
833.33374	2.3734064	1.0365791	3281.7515
834.33472	2.3781812	1.0383232	3289.6196
835.33569	2.3831289	1.0402321	3292.9568
836.33667	2.3837724	1.0419908	3284.2405
837.33765	2.3922513	1.0441251	3299.9082
838.33862	2.3923852	1.0460231	3291.3201
839.3396	2.3913312	1.0482899	3288.5974
840.34058	2.3986278	1.050236	3291.6458
841.34155	2.3992298	1.0519397	3295.1824
842.34253	2.4046409	1.0541548	3289.8457
843.34351	2.4059968	1.0562017	3290.7266
844.34448	2.4074345	1.0581474	3289.7302
845.34546	2.4097044	1.0602876	3290.6235
846.34644	2.4148426	1.06185	3276.5842
847.34741	2.414902	1.0633926	3288.5542
848.34839	2.4223406	1.0652523	3287.0483
849.34937	2.4260824	1.0671037	3288.1438
850.35034	2.4276195	1.0690938	3294.7656
851.35132	2.4274621	1.0708244	3289.6816
852.35229	2.4296317	1.0730373	3290.8005
853.35327	2.4364445	1.0752385	3290.4475
854.35425	2.4381881	1.0772924	3287.9404
855.35522	2.4422784	1.0792333	3289.6201
856.3562	2.4436176	1.0816299	3291.4651
857.35718	2.4477265	1.0840521	3295.7175
858.35815	2.4519396	1.0862828	3291.2295
859.35913	2.4524071	1.0882601	3286.2385
860.36011	2.4575481	1.0904485	3290.0327
861.36108	2.4567566	1.0925415	3288.5833
862.36206	2.4631314	1.0944695	3284.5308
863.36304	2.4665904	1.0965117	3291.3708
864.36401	2.4703646	1.0984328	3287.8506
865.36499	2.4710114	1.1002675	3285.0884
866.36597	2.4798782	1.1023059	3295.5234
867.36694	2.475359	1.1045336	3282.5181
868.36792	2.4793129	1.1067898	3285.8533
869.3689	2.483067	1.1088781	3285.2593
870.36987	2.4849334	1.1111585	3280.3613
871.37085	2.4875255	1.1132131	3288.7915
872.37183	2.491658	1.114888	3282.7405
873.3728	2.4941421	1.1167976	3285.926
874.37378	2.4962225	1.1186794	3284.1248
875.37476	2.5033953	1.1207992	3289.9517
876.37573	2.5032287	1.1230724	3286.3235
877.37671	2.5078845	1.1251867	3283.6587
878.37769	2.5112777	1.1273592	3289.9492
879.37866	2.5123718	1.1294166	3284.2219
880.37964	2.5183606	1.131467	3289.0742
881.38062	2.5172653	1.1335478	3279.3245
882.38159	2.5229645	1.1356775	3286.2617
883.38257	2.5275033	1.1377693	3288.605
884.38354	2.5304451	1.1397796	3284.8613
885.38452	2.5287449	1.1419089	3283.3989
886.3855	2.5377204	1.1439725	3282.5425
887.38647	2.5370615	1.1457685	3279.7424
888.38745	2.5387127	1.1475191	3279.0508
889.38843	2.5420897	1.1495253	3283.2402
890.3894	2.5486071	1.1515549	3291.7871
891.39038	2.5501082	1.1534853	3281.9927
892.39136	2.5556333	1.1554228	3284.8911
893.39233	2.5566957	1.157733	3286.7886
894.39331	2.556901	1.1598101	3278.4373
895.39429	2.5634437	1.161945	3278.0552
896.39526	2.5659578	1.1638479	3283.6816
897.39624	2.5680459	1.1660234	3283.6667
898.39722	2.5732951	1.1685213	3286.6375
899.39819	2.5745661	1.1705143	3281.6221
900.39917	2.5745108	1.172394	3278.4858
901.40015	2.5788403	1.1744808	3283.6592
902.40112	2.5845435	1.1771349	3289.4067
903.4021	2.5844417	1.1797206	3278.6418
904.40308	2.5904658	1.181819	3278.8982
905.40405	2.5925791	1.1841511	3284.2795
906.40503	2.5962734	1.1865318	3279.3757
907.40601	2.5978334	1.1887306	3278.9641
908.40698	2.6009912	1.1908684	3275.1702
909.40796	2.6024981	1.1929299	3271.0554
910.40894	2.6095846	1.1948655	3276.5007
911.40991	2.6078546	1.1969995	3276.6865
912.41089	2.6164615	1.1996384	3281.6118
913.41187	2.61252	1.2017119	3271.3193
914.41284	2.6193054	1.2038217	3274.8948
915.41382	2.6235185	1.2059933	3277.22
916.41479	2.6255434	1.2083493	3277.0522
917.41577	2.625843	1.2106082	3272.9241
918.41675	2.629302	1.2127106	3269.2842
919.41772	2.6340942	1.2151386	3278.105
920.4187	2.6352592	1.2174531	3267.4668
921.41968	2.6414471	1.2195249	3269.2424
922.42065	2.6411209	1.2214255	3268.1953
923.42163	2.6423573	1.2238295	3276.0034
924.42261	2.6504314	1.2259885	3271.2642
925.42358	2.6484501	1.2280644	3263.9001
926.42456	2.6543767	1.230336	3270.4502
927.42554	2.6577516	1.232374	3271.417
928.42651	2.6614056	1.2346097	3272.2222
929.42749	2.6626747	1.2368808	3269.28
930.42847	2.6683614	1.2392967	3262.5349
931.42944	2.6685951	1.2412815	3264.1372
932.43042	2.6713884	1.2434655	3266.324
933.4314	2.6728866	1.2457631	3260.6357
934.43237	2.6795239	1.2481049	3267.6614
935.43335	2.6809316	1.2505132	3265.8376
936.43433	2.6844687	1.2528267	3258.2502
937.4353	2.6873763	1.2550814	3259.4238
938.43628	2.6893475	1.2575436	3263.2881
939.43726	2.6955152	1.2599922	3267.5171
940.43823	2.6970906	1.2623929	3262.864
941.43921	2.6988585	1.26446	3252.9609
942.44019	2.7010436	1.2664882	3253.9297
943.44116	2.7069945	1.2689797	3260.4751
944.44214	2.7089045	1.2712837	3260.0806
945.44312	2.7143202	1.2736503	3260.6594
946.44409	2.7166018	1.276261	3258.9941
947.44507	2.7163215	1.2789478	3254.3545
948.44604	2.7200215	1.2810122	3246.5635
949.44702	2.7236416	1.2831696	3253.6052
950.448	2.7292979	1.2849855	3250.1223
951.44897	2.7308676	1.2869587	3253.5237
952.44995	2.733381	1.2893145	3249.8425
953.45093	2.7377551	1.29182	3255.2883
954.4519	2.7365332	1.2942667	3246.0984
955.45288	2.742439	1.296405	3248.8999
956.45386	2.7441318	1.2988185	3246.4014
957.45483	2.7500184	1.300962	3245.6809
958.45581	2.7523494	1.3031614	3249.397
959.45679	2.7532396	1.3052584	3241.6313
960.45776	2.758111	1.3077434	3246.8245
961.45874	2.7591383	1.3102734	3248.6445
962.45972	2.7650173	1.312634	3236.2427
963.46069	2.764575	1.3149362	3238.6179
964.46167	2.7671738	1.3172102	3242.4375
965.46265	2.7688789	1.3198786	3236.2302
966.46362	2.7765133	1.3220575	3233.4373
967.4646	2.7749798	1.3243314	3233.7751
968.46558	2.7785397	1.3269978	3234.6433
969.46655	2.7856843	1.3298177	3234.9402
970.46753	2.7878833	1.3319765	3233.8911
971.46851	2.7897625	1.3338189	3232.9685
972.46948	2.7921803	1.3362724	3235.6565
973.47046	2.7949548	1.3388467	3233.5637
974.47144	2.7965293	1.3412791	3224.7422
975.47241	2.7997558	1.3439488	3226.7197
976.47339	2.8007557	1.3465012	3223.1858
977.47437	2.8091891	1.3492548	3225.7153
978.47534	2.8149967	1.3518175	3228.8469
979.47632	2.8112609	1.3541974	3221.5608
980.47729	2.8149583	1.3565549	3217.3
981.47827	2.8195844	1.3592812	3218.7861
982.47925	2.8237429	1.3618804	3218.2747
983.48022	2.8276441	1.3643671	3219.1423
984.4812	2.8323102	1.3665128	3216.9651
985.48218	2.8320229	1.3686006	3212.6802
986.48315	2.8358855	1.3707509	3211.6238
987.48413	2.8397958	1.3727555	3213.4143
988.48511	2.8436649	1.3751378	3219.481
989.48608	2.8456564	1.3776808	3207.8523
990.48706	2.8479328	1.3799059	3208.3596
991.48804	2.8490472	1.3823469	3204.3513
992.48901	2.8536322	1.3846493	3201.8889
993.48999	2.8592944	1.3867198	3200.7407
994.49097	2.8605347	1.3888693	3207.5691
995.49194	2.8648026	1.3910036	3201.3162
996.49292	2.8641024	1.393093	3200.1072
997.4939	2.8699117	1.396022	3205.1729
998.49487	2.871419	1.3988168	3197.5742
999.49585	2.8754678	1.4014878	3190.7161
1000.4968	2.8780799	1.40399	3192.8857
1001.4978	2.8793926	1.4063449	3193.8115
1002.4988	2.8843939	1.4088963	3190.8979
1003.4998	2.8846741	1.4115658	3189.5149
1004.5007	2.8888109	1.4142447	3186.6421
1005.5017	2.8923583	1.4171622	3189.7083
1006.5027	2.8962064	1.4200722	3185.3369
1007.5037	2.8976407	1.4228824	3179.0769
1008.5046	2.8997314	1.4253262	3174.521
1009.5056	2.9028225	1.4276271	3170.7095
1010.5066	2.907347	1.4299569	3177.0496
1011.5076	2.9107273	1.4322155	3181.2368
1012.5085	2.916003	1.4349853	3176.8853
1013.5095	2.9154944	1.4371055	3167.7769
1014.5105	2.9165015	1.4397916	3169.1746
1015.5115	2.9231796	1.4424222	3168.7573
1016.5125	2.923661	1.4449261	3163.3723
1017.5134	2.9269803	1.4474388	3161.6892
1018.5144	2.9303811	1.4497427	3162.2507
1019.5154	2.9331982	1.4524081	3156.5952
1020.5164	2.9370883	1.4543524	3154.425
1021.5173	2.9376342	1.4567319	3155.5051
1022.5183	2.9423382	1.4590665	3153.1211
1023.5193	2.9482691	1.4614658	3158.3979
1024.5203	2.9496131	1.4650249	3152.9141
1025.5212	2.9513035	1.4678297	3144.5959
1026.5222	2.9549055	1.4703733	3144.8357
1027.5232	2.9593277	1.4726777	3141.532
1028.5242	2.9625893	1.4751209	3146.8069
1029.5251	2.9624395	1.477438	3139.95
1030.5261	2.9641461	1.4796208	3133.9844
1031.5271	2.9682934	1.4819344	3132.0657
1032.5281	2.971035	1.4846398	3135.991
1033.5291	2.9749339	1.4873439	3131.0493
1034.53	2.9808161	1.4902924	3130.4504
1035.531	2.9810846	1.4930065	3126.1946
1036.532	2.9859812	1.4954426	3121.1292
1037.533	2.9826233	1.4978731	3118.3486
1038.5339	2.9922957	1.499964	3113.3982
1039.5349	2.9960504	1.5017353	3118.3982
1040.5359	2.9943709	1.5036727	3109.55
1041.5369	2.9952836	1.5056447	3109.9531
1042.5378	3.002295	1.5079945	3116.1328
1043.5388	3.0085042	1.5104963	3113.2124
1044.5398	3.0098498	1.5132989	3114.0898
1045.5408	3.0134676	1.5159374	3106.062
1046.5417	3.0173039	1.5186406	3106.0232
1047.5427	3.0192873	1.5216022	3107.9214
1048.5437	3.0220971	1.5244248	3100.2529
1049.5447	3.026861	1.5274283	3097.0527
1050.5457	3.0246351	1.5300486	3091.0171
1051.5466	3.0303445	1.5324954	3087.9658
1052.5476	3.0334163	1.5358944	3088.8733
1053.5486	3.0354085	1.5381281	3085.8604
1054.5496	3.0399873	1.5410429	3088.6096
1055.5505	3.0414753	1.5438278	3081.8455
1056.5515	3.0476842	1.546647	3084.9331
1057.5525	3.0494468	1.5489744	3077.075
1058.5535	3.0533984	1.5518888	3076.8325
1059.5544	3.0574825	1.5554008	3079.5371
1060.5554	3.0565174	1.5581465	3063.0947
1061.5564	3.0601563	1.5607791	3066.2056
1062.5574	3.0648303	1.5632766	3057.1096
1063.5583	3.0652723	1.5658381	3060.3713
1064.5593	3.0673482	1.5685532	3060.3103
1065.5603	3.0715277	1.5717127	3050.5591
1066.5613	3.0756319	1.5746804	3050.9509
1067.5623	3.0780866	1.5769093	3045.9314
1068.5632	3.0801136	1.5798056	3042.9563
1069.5642	3.0837274	1.5824126	3043.2102
1070.5652	3.0873382	1.5855697	3042.1331
1071.5662	3.0917535	1.5882318	3035.2849
1072.5671	3.0915244	1.5908068	3030.2847
1073.5681	3.0938802	1.5934463	3029.5054
1074.5691	3.1023633	1.5964409	3030.1267
1075.5701	3.1017592	1.5995101	3022.936
1076.571	3.1056104	1.6023875	3017.5659
1077.572	3.1077015	1.6051705	3017.9292
1078.573	3.1117296	1.6079054	3013.1543
1079.574	3.1163735	1.6106662	3014.605
1080.575	3.1182473	1.6133283	3008.7332
1081.5759	3.1202598	1.6160074	3010.4961
1082.5769	3.1225054	1.6192032	3008.3372
1083.5779	3.1252673	1.6226174	3004.8477
1084.5789	3.1314483	1.6260371	3000.416
1085.5798	3.135396	1.6290728	2994.2158
1086.5808	3.1352613	1.632074	2985.4539
1087.5818	3.1400785	1.6350987	2986.2268
1088.5828	3.1412504	1.6379787	2974.1555
1089.5837	3.1421556	1.64073	2970.4551
1090.5847	3.1462889	1.6433657	2970.4946
1091.5857	3.1502719	1.645968	2969.3606
1092.5867	3.1545477	1.648814	2970.7412
1093.5876	3.1575377	1.651454	2963.5449
1094.5886	3.1611359	1.6543231	2955.9053
1095.5896	3.1623485	1.6571888	2956.5723
1096.5906	3.1628017	1.6603041	2953.0322
1097.5916	3.1679842	1.6634513	2947.2581
1098.5925	3.1715326	1.6669105	2943.3459
1099.5935	3.1715765	1.6697501	2934.5676
1100.5945	3.1785901	1.6727136	2938.9788
1101.5955	3.1803102	1.6757816	2932.0757
1102.5964	3.1837261	1.67866	2928.9639
1103.5974	3.1900713	1.6817192	2933.2244
1104.5984	3.1890514	1.6845694	2919.137
1105.5994	3.1931775	1.687423	2917.2151
1106.6003	3.1946259	1.6900026	2914.1335
1107.6013	3.1978686	1.6932521	2909.6523
1108.6023	3.2006691	1.696908	2904.9807
1109.6033	3.2066579	1.6997811	2903.5686
1110.6042	3.2077401	1.7024399	2889.708
1111.6052	3.2119296	1.7054545	2896.7751
1112.6062	3.2125888	1.7091155	2890.3452
1113.6072	3.2171514	1.712414	2885.6882
1114.6082	3.2190685	1.7161368	2879.0288
1115.6091	3.22102	1.7191806	2874.5366
1116.6101	3.2243278	1.7220525	2866.0703
1117.6111	3.2282	1.7256826	2861.0337
1118.6121	3.2324841	1.7288169	2859.239
1119.613	3.2342873	1.7315892	2850.2883
1120.614	3.2370136	1.7343975	2850.8394
1121.615	3.2405925	1.7375711	2850.6611
1122.616	3.2433858	1.7409798	2843.842
1123.6169	3.2519958	1.7442991	2841.7087
1124.6179	3.2503324	1.7479639	2837.4902
1125.6189	3.2524567	1.7513679	2825.2207
1126.6199	3.2576363	1.7538419	2824.5645
1127.6208	3.2583475	1.7574302	2825.8289
1128.6218	3.2637117	1.7615275	2817.5681
1129.6228	3.265048	1.7650025	2806.5842
1130.6238	3.2686257	1.7680573	2799.1726
1131.6248	3.2692444	1.7709939	2792.9036
1132.6257	3.2750542	1.7738503	2786.9375
1133.6267	3.2769573	1.7765331	2790.4924
1134.6277	3.2835391	1.7794092	2786.312
1135.6287	3.2835665	1.7828282	2776.5327
1136.6296	3.2870576	1.7858726	2768.6792
1137.6306	3.2909462	1.7886919	2769.2366
1138.6316	3.2911935	1.7919176	2765.4014
1139.6326	3.2954328	1.7960082	2759.9553
1140.6335	3.2970839	1.7997484	2744.9109
1141.6345	3.3037848	1.8033718	2750.4063
1142.6355	3.3059795	1.8062773	2734.8684
1143.6365	3.307292	1.8092207	2728.7346
1144.6375	3.3131633	1.8129929	2723.03
1145.6384	3.311105	1.8170142	2718.7048
1146.6394	3.317946	1.8215233	2708.3223
1147.6404	3.3203192	1.8258392	2693.4985
1148.6414	3.3209867	1.828849	2681.644
1149.6423	3.3253369	1.8324301	2677.2214
1150.6433	3.3289766	1.8359299	2665.282
1151.6443	3.3323822	1.8398918	2650.3823
1152.5452	3.3363607	1.8493345	2588.8374