File: datasets/am_bench_2022/raw_data/90-XY.07-3/specimen.dat
MTS793|MPT|ENU|1|2|.|/|:|1|0|0|A

Operator Information						Time:	17.544189	Sec	11/2/2021 3:00:09 PM
Operator	Nick Derimow
Project	AM Bench 2022 mini-tensile challenge
Specimen ID	90-XY.07-3
Material	PBF-L Inconel 625
Specimen Width	2.54	mm
Specimen Thickness	1.51	mm
Notes
Operator Information End

Data Acquisition						Time:	997.73096	Sec	11/2/2021 3:16:29 PM
Time	Axial Displacement	Axial Extensometer	Axial Force
Sec	mm	mm	N
17.658203	0.0053439168	0.00018372531	69.063927
18.559082	0.0058522513	0.00018686014	83.474457
19.459961	0.01007782	0.00030278641	93.879768
20.36084	0.0129696	0.00026487341	104.97591
21.261719	0.016278179	0.00046369346	116.03915
22.162598	0.016598219	0.00044871593	126.40134
23.063477	0.018306805	0.00054271065	141.00159
23.964355	0.024125606	0.00057701761	152.21054
24.865234	0.028706096	0.00073620357	167.08047
25.766113	0.027459949	0.0007699983	181.12415
26.666992	0.031674352	0.00092145981	195.78537
27.567871	0.032805759	0.00093257311	210.45891
28.46875	0.037085012	0.0010529404	223.53978
29.369629	0.041046936	0.001097037	241.53065
30.270508	0.040165905	0.0012927755	263.98749
31.171387	0.042388152	0.0013305563	280.4697
32.072266	0.045790367	0.0013883603	293.91998
32.973145	0.047282126	0.0014951443	312.90445
33.874023	0.052981116	0.0016090125	329.51291
34.774902	0.053284921	0.0016425777	347.72675
35.675781	0.057835549	0.0018456349	372.22906
36.57666	0.057613447	0.0018449218	381.55988
37.477539	0.064031348	0.0021241277	408.63437
38.378418	0.065971464	0.0022172527	428.27151
39.279297	0.069822133	0.0023270089	449.61346
40.180176	0.069204792	0.0023581882	465.55334
41.081055	0.072674826	0.0024931435	491.89694
41.981934	0.073893055	0.0026195152	505.18143
42.882813	0.079084329	0.0026261455	527.93323
43.783691	0.081517972	0.002882838	546.95715
44.68457	0.082941763	0.0028422091	567.0387
45.585449	0.087686777	0.0030613616	597.63202
46.486328	0.089509696	0.0031748866	614.90375
47.387207	0.092014231	0.003286382	638.49255
48.288086	0.090858236	0.0034727161	661.34851
49.188965	0.095808141	0.0035302534	679.21649
50.089844	0.097810335	0.0036463724	707.20422
50.990723	0.10204989	0.0037822581	733.7923
51.891602	0.10291474	0.0038617712	759.38519
52.79248	0.10779923	0.0040435935	791.04993
53.693359	0.1109855	0.0041325358	810.64752
54.594238	0.11205318	0.004280596	838.88892
55.495117	0.11684205	0.0044572768	865.20203
56.395996	0.11857619	0.0046215467	889.11334
57.296875	0.1202649	0.0046418477	906.28021
58.197754	0.1237648	0.0048308573	936.15228
59.098633	0.12820862	0.0049352441	961.16559
59.999512	0.12814204	0.0050351848	982.09515
60.900391	0.13179396	0.0051259464	1010.8986
61.80127	0.13537541	0.0053422353	1033.6251
62.702148	0.13965784	0.0054362947	1055.6146
63.603027	0.13922593	0.0055528809	1084.1318
64.503906	0.13892063	0.0057376781	1106.5491
65.404785	0.14397068	0.0058234446	1136.308
66.305664	0.14891219	0.005905957	1166.9331
67.206543	0.15071256	0.006069873	1189.9514
68.107422	0.15457655	0.0062433635	1214.3387
69.008301	0.15666276	0.006318206	1239.0032
69.90918	0.15898433	0.0065136524	1267.4825
70.810059	0.16321036	0.0066129998	1293.418
71.710938	0.16417518	0.0067078667	1310.7937
72.611816	0.1672795	0.0067673046	1331.7427
73.512695	0.17104611	0.0069013597	1359.046
74.413574	0.17424645	0.0071456856	1389.2933
75.314453	0.17482178	0.0072172247	1410.1399
76.215332	0.1764521	0.0074296207	1447.8812
77.116211	0.17967258	0.0074759494	1463.301
78.01709	0.18305793	0.0076578865	1486.2961
78.917969	0.18589337	0.007673942	1513.566
79.818848	0.18830161	0.0078149699	1532.635
80.719727	0.19223408	0.0080254367	1563.1204
81.620605	0.19633432	0.0082225436	1595.1749
82.521484	0.19495827	0.0083360756	1615.1897
83.422363	0.19939205	0.0083860969	1631.8778
84.323242	0.20448108	0.0085223606	1659.7374
85.224121	0.20215331	0.0085867401	1682.9774
86.125	0.20801418	0.0087259253	1707.3285
87.025879	0.21089084	0.0088416105	1733.4626
87.926758	0.21221049	0.009033747	1762.4934
88.827637	0.2132456	0.0092095649	1790.8734
89.728516	0.21733701	0.0093301423	1810.1216
90.629395	0.21966581	0.0094783539	1833.4978
91.530273	0.22551636	0.0095831873	1858.4868
92.431152	0.22765133	0.0096842842	1880.8193
93.332031	0.22852452	0.0098002264	1894.0682
94.23291	0.23003109	0.0099496264	1925.3419
95.133789	0.23337962	0.010082866	1950.3358
96.034668	0.23578048	0.010139707	1967.4052
96.935547	0.24181667	0.010314603	1998.1193
97.836426	0.24278848	0.010439861	2015.1467
98.737305	0.24460524	0.010626288	2037.7474
99.638184	0.24809879	0.010734166	2067.3071
100.53906	0.24827048	0.010838757	2078.3206
101.43994	0.25139236	0.010931543	2102.4688
102.34082	0.25473511	0.011011126	2119.1455
103.2417	0.25689894	0.011130888	2133.2444
104.14258	0.26054683	0.011278813	2152.6504
105.04346	0.26456696	0.01124538	2162.8142
105.94434	0.26860422	0.011445859	2183.6597
106.84521	0.26988459	0.011518911	2205.1265
107.74609	0.27581796	0.011714075	2231.8184
108.64697	0.27321529	0.011770333	2243.3438
109.54785	0.27992925	0.011919914	2262.4685
110.44873	0.27988991	0.012061119	2278.5771
111.34961	0.28246003	0.012108473	2290.9707
112.25049	0.28566802	0.012217375	2307.6243
113.15137	0.29120657	0.012390018	2331.7773
114.05225	0.29040667	0.012502289	2344.0479
114.95313	0.29280138	0.012541127	2355.969
115.854	0.29672357	0.012724385	2369.2141
116.75488	0.29947257	0.012736526	2389.2217
117.65576	0.30442187	0.013058824	2406.2856
118.55664	0.3083168	0.013123766	2412.6995
119.45752	0.30624965	0.013206241	2422.7019
120.3584	0.30804205	0.013265164	2438.0637
121.25928	0.31318456	0.013436278	2452.1609
122.16016	0.31600052	0.013668991	2464.9353
123.06104	0.32100022	0.013675765	2480.7722
123.96191	0.32221618	0.013820367	2488.7336
124.86279	0.3233982	0.014005353	2506.2493
125.76367	0.32723153	0.01414616	2516.6755
126.66455	0.33175793	0.01428173	2532.5647
127.56543	0.33484188	0.014369538	2539.7241
128.46631	0.33708724	0.014551928	2551.3938
129.36719	0.33656928	0.014686467	2560.9072
130.26807	0.34046301	0.014859484	2572.6895
131.16895	0.34686741	0.014915316	2582.7458
132.06982	0.34671086	0.015104042	2598.4297
132.9707	0.34818342	0.015247801	2602.0327
133.87158	0.35085922	0.015428423	2618.3533
134.77246	0.35505396	0.015654378	2632.1895
135.67334	0.35933179	0.01566356	2635.437
136.57422	0.3615104	0.015956178	2644.4321
137.4751	0.36291999	0.01596785	2644.6169
138.37598	0.3630712	0.016121725	2657.5029
139.27686	0.36871246	0.016342189	2665.5701
140.17773	0.37190688	0.016480021	2675.1096
141.07861	0.37256759	0.016608099	2677.2683
141.97949	0.3794699	0.016772438	2689.9324
142.88037	0.38075417	0.0170811	2710.9722
143.78125	0.37913981	0.017269829	2712
144.68213	0.38438314	0.017458778	2717.9636
145.58301	0.38604456	0.017660668	2725.3909
146.48389	0.39124626	0.017815076	2727.5435
147.38477	0.39179927	0.018050119	2748.8748
148.28564	0.39537072	0.018275222	2756.4355
149.18652	0.39912915	0.01853212	2765.3452
150.0874	0.40107396	0.018834138	2770.9502
150.98828	0.40454742	0.019042764	2785.5688
151.88916	0.4026491	0.01943581	2781.5784
152.79004	0.40874279	0.019632548	2792.1116
153.69092	0.41225147	0.019891741	2800.3513
154.5918	0.41468555	0.020178994	2807.9819
155.49268	0.41803813	0.020555671	2820.1216
156.39355	0.42015627	0.020755444	2819.7419
157.29443	0.42331463	0.021192841	2841.4199
158.19531	0.4251484	0.021625448	2842.3694
159.09619	0.42887285	0.021981686	2848.8953
159.99707	0.43310463	0.022362148	2853.0464
160.89795	0.43173042	0.022657594	2860.3318
161.79883	0.43720424	0.022964103	2860.9644
162.69971	0.43914393	0.023272378	2869.53
163.60059	0.44107682	0.023649087	2872.7366
164.50146	0.4451203	0.02412227	2881.5601
165.40234	0.44656825	0.024621688	2885.2065
166.30322	0.44785517	0.025034154	2892.5066
167.2041	0.45138255	0.025450811	2893.5867
168.10498	0.45419073	0.026014559	2906.4485
169.00586	0.4582639	0.026572663	2916.6213
169.90674	0.45991635	0.027053684	2911.7891
170.80762	0.46364245	0.027570873	2918.741
171.7085	0.46755582	0.028144393	2930.0525
172.60938	0.46693641	0.028738717	2933.8875
173.51025	0.47150216	0.029199172	2936.7131
174.41113	0.4758147	0.029860035	2945.7146
175.31201	0.47665572	0.030455949	2947.6433
176.21289	0.4812057	0.03090784	2942.8076
177.11377	0.4805271	0.03152895	2957.6384
178.01465	0.48499817	0.032164365	2962.7813
178.91553	0.48953816	0.032830335	2963.6794
179.81641	0.49153394	0.033429753	2961.2183
180.71729	0.49497914	0.034002215	2973.9446
181.61816	0.49511313	0.034587186	2978.5662
182.51904	0.49876484	0.035465218	2985.7703
183.41992	0.49988806	0.036303584	2986.1072
184.3208	0.50482631	0.037273716	2997.7434
185.22168	0.50922567	0.03795502	2995.4736
186.12256	0.51046664	0.038577177	2994.3384
187.02344	0.51209283	0.039181605	3002.311
187.92432	0.51405019	0.04014957	3000.7629
188.8252	0.51791662	0.040835783	3015.3662
189.72607	0.51983768	0.041773669	3012.676
190.62695	0.52350473	0.042414531	3008.2119
191.52783	0.52287865	0.04322309	3015.4604
192.42871	0.52817625	0.043968357	3020.8523
193.32959	0.53101701	0.045086715	3031.8176
194.23047	0.53547722	0.045966748	3034.501
195.13135	0.537615	0.046883024	3035.9656
196.03223	0.54036421	0.047803003	3034.5906
196.93311	0.54029948	0.048719969	3046.9241
197.83398	0.54475582	0.049522966	3041.7822
198.73486	0.54694766	0.050300166	3044.9438
199.63574	0.54957706	0.051236607	3048.0894
200.53662	0.55314457	0.052020542	3050.2754
201.4375	0.5573765	0.052823152	3057.9387
202.33838	0.5587253	0.053754069	3056.1394
203.23926	0.56091702	0.054715957	3063.0205
204.14014	0.56489676	0.055535745	3063.0205
205.04102	0.56571978	0.056370873	3065.9773
205.94189	0.57094181	0.057269666	3072.0181
206.84277	0.5734148	0.058136854	3071.4578
207.74365	0.57632852	0.05907172	3071.752
208.64453	0.57760882	0.059893571	3082.4487
209.54541	0.58291411	0.060787562	3085.6328
210.44629	0.58014148	0.06169337	3083.5481
211.34717	0.58532929	0.062672228	3089.3672
212.24805	0.58896112	0.063787572	3091.1665
213.14893	0.58972108	0.064763345	3089.2234
214.0498	0.5920943	0.065560058	3088.5684
214.95068	0.59334904	0.066267319	3088.9138
215.85156	0.59751278	0.067256957	3094.9463
216.75244	0.60326236	0.068144612	3096.4978
217.65332	0.6013456	0.068934426	3097.0811
218.5542	0.60784817	0.069862112	3107.9961
219.45508	0.61165953	0.070933402	3113.179
220.35596	0.61179495	0.071784288	3108.0918
221.25684	0.6167174	0.072879694	3118.8787
222.15771	0.61744022	0.074025013	3121.1804
223.05859	0.62106389	0.075082481	3118.5837
223.95947	0.6236822	0.076285921	3129.8372
224.86035	0.62452734	0.077118069	3119.6526
225.76123	0.6299811	0.078255221	3129.2078
226.66211	0.6305359	0.079278812	3134.1567
227.56299	0.63458371	0.080120139	3131.8474
228.46387	0.63751769	0.081367724	3141.1399
229.36475	0.63927627	0.082349315	3137.49
230.26563	0.64372826	0.083248757	3138.3552
231.1665	0.64435375	0.08417426	3136.9712
232.06738	0.64999092	0.08521831	3144.2656
232.96826	0.65136224	0.086253546	3152.0911
233.86914	0.65468365	0.087177522	3148.1511
234.77002	0.65885806	0.08804889	3149.1233
235.6709	0.65995711	0.088932946	3154.1904
236.57178	0.66032118	0.089945212	3156.0361
237.47266	0.6637609	0.091003589	3160.7852
238.37354	0.66810572	0.091894142	3159.9673
239.27441	0.66939241	0.093320072	3171.0867
240.17529	0.6735574	0.094282761	3165.6084
241.07617	0.67214632	0.095343642	3166.1743
241.97705	0.67786187	0.096562997	3173.3101
242.87793	0.68009335	0.097684488	3166.6304
243.77881	0.68359876	0.098602727	3166.4333
244.67969	0.68898284	0.099403985	3179.2234
245.58057	0.68781561	0.1003134	3176.5825
246.48145	0.69326258	0.10126584	3182.406
247.38232	0.69348449	0.10233456	3182.4102
248.2832	0.69824642	0.1033479	3184.1672
249.18408	0.69537187	0.10426436	3182.4631
250.08496	0.70189553	0.10511188	3184.4097
250.98584	0.70518994	0.10620398	3184.2471
251.88672	0.70656663	0.10702912	3188.6943
252.7876	0.7104097	0.10803848	3193.7983
253.68848	0.71339411	0.10919863	3197.7461
254.58936	0.71792156	0.11017376	3201.627
255.49023	0.71876425	0.1112678	3204.0159
256.39111	0.71972167	0.11227413	3200.6143
257.29199	0.72347319	0.11326194	3196.4719
258.19287	0.72611642	0.11439558	3210.6758
259.09375	0.7261039	0.11554407	3206.0896
259.99463	0.73449272	0.116445	3207.9939
260.89551	0.73468328	0.11745419	3211.7214
261.79639	0.73531473	0.11859011	3214.676
262.69727	0.74186707	0.11964688	3217.0442
263.59814	0.74337238	0.12090442	3222.103
264.49902	0.74390119	0.12202315	3222.2747
265.3999	0.74800146	0.12302206	3224.0774
266.30078	0.75209486	0.12435624	3228.6094
267.20166	0.75342155	0.12532271	3219.8743
268.10254	0.75193399	0.12632065	3223.9954
269.00342	0.75913775	0.12748691	3223.5566
269.9043	0.76039559	0.12843353	3230.2813
270.80518	0.76358831	0.12958767	3236.1216
271.70605	0.76576686	0.13052531	3225.6978
272.60693	0.76872367	0.13150607	3235.8665
273.50781	0.7704609	0.13267033	3242.4856
274.40869	0.77555972	0.13373305	3239.7563
275.30957	0.77844906	0.13493265	3243.458
276.21045	0.77657169	0.13580912	3239.8936
277.11133	0.78500843	0.13687497	3242.8738
278.01221	0.78687638	0.13806553	3250.5667
278.91309	0.7895844	0.13917804	3246.9895
279.81396	0.79187828	0.14009972	3253.981
280.71484	0.79033101	0.14122444	3253.0825
281.61572	0.7970311	0.14230302	3252.834
282.5166	0.80105835	0.14319839	3255.2644
283.41748	0.80289006	0.14425765	3263.9238
284.31836	0.8047052	0.14511682	3256.7585
285.21924	0.80875093	0.14617799	3262.1113
286.12012	0.80954134	0.14712395	3254.6162
287.021	0.81408972	0.14813969	3259.072
287.92188	0.81289357	0.14915405	3264.8982
288.82275	0.81816411	0.15021677	3266.8535
289.72363	0.82036722	0.15106648	3264.9543
290.62451	0.822285	0.15201713	3264.3291
291.52539	0.82664835	0.15312369	3278.1025
292.42627	0.82739168	0.15404978	3269.949
293.32715	0.83088094	0.15504444	3274.0696
294.22803	0.83243823	0.15621069	3277.4163
295.12891	0.83736426	0.15732647	3279.6365
296.02979	0.83897257	0.15839039	3280.7778
296.93066	0.83976531	0.15928496	3272.8909
297.83154	0.84349465	0.1603369	3286.676
298.73242	0.84797168	0.16150649	3284.478
299.6333	0.84800059	0.16254009	3285.25
300.53418	0.85252184	0.16354318	3284.853
301.43506	0.85509342	0.16458349	3289.5486
302.33594	0.86009288	0.16590354	3297.0378
303.23682	0.86134088	0.16680965	3288.0134
304.1377	0.86608797	0.16776918	3299.7827
305.03857	0.86837411	0.1688903	3301.2402
305.93945	0.87032115	0.16996014	3301.4138
306.84033	0.87101632	0.17119439	3306.0876
307.74121	0.87486559	0.17252424	3306.6201
308.64209	0.87785226	0.17358162	3306.5112
309.54297	0.88044965	0.1745688	3303.3293
310.44385	0.88367742	0.17555067	3303.5955
311.34473	0.88415915	0.17647055	3301.8025
312.24561	0.88631719	0.17762153	3310.5488
313.14648	0.89095777	0.17852107	3310.76
314.04736	0.8950963	0.17967016	3318.7354
314.94824	0.8952772	0.18063401	3310.1438
315.84912	0.89735949	0.18158381	3307.9089
316.75	0.90135074	0.18255518	3318.8647
317.65088	0.90445358	0.18344259	3318.0457
318.55176	0.91003305	0.18442991	3318.7598
319.45264	0.90972227	0.18533291	3318.7102
320.35352	0.91132569	0.18654126	3316.7454
321.25439	0.91498095	0.18786582	3329.1841
322.15527	0.91927481	0.18909478	3328.6526
323.05615	0.92041272	0.19026786	3328.5391
323.95703	0.92232049	0.19132039	3329.9155
324.85791	0.92696977	0.19236018	3330.6287
325.75879	0.92757541	0.1932295	3327.4622
326.65967	0.9299075	0.19421136	3330.2341
327.56055	0.9306035	0.1952928	3337.9639
328.46143	0.93513095	0.19628651	3335.3477
329.3623	0.93956	0.19747591	3337.6951
330.26318	0.94207394	0.19856179	3340.4441
331.16406	0.94333279	0.19953845	3339.6711
332.06494	0.94691694	0.20042662	3341.9106
332.96582	0.95294273	0.20146285	3343.614
333.8667	0.95362431	0.20254283	3344.2705
334.76758	0.95573676	0.2036255	3346.9468
335.66846	0.96039861	0.20481779	3350.3423
336.56934	0.96048605	0.20604289	3354.2676
337.47021	0.96280134	0.20715827	3350.9004
338.37109	0.96921557	0.20825595	3356.9917
339.27197	0.97011626	0.20939948	3357.6362
340.17285	0.97031808	0.21037105	3357.8022
341.07373	0.97324038	0.21144931	3361.9343
341.97461	0.97968173	0.21242933	3361.8774
342.87549	0.97988755	0.21327135	3354.8723
343.77637	0.98283654	0.2142189	3358.2207
344.67725	0.98638958	0.21516623	3364.9294
345.57813	0.9879514	0.21618141	3365.7095
346.479	0.99252492	0.21725167	3366.0906
347.37988	0.99137819	0.21836719	3370.9023
348.28076	0.99690747	0.21947715	3367.3613
349.18164	0.99698907	0.22047929	3373.0305
350.08252	1.0005364	0.2216244	3373.2185
350.9834	1.0024877	0.2227938	3373.3262
351.88428	1.0035883	0.22418748	3377.5125
352.78516	1.0086697	0.22522052	3379.5146
353.68604	1.0131356	0.22618768	3374.175
354.58691	1.0158789	0.2270478	3376.9424
355.48779	1.0166336	0.22804913	3384.4792
356.38867	1.0200186	0.22902098	3383.0085
357.28955	1.0238084	0.22997572	3381.719
358.19043	1.0273803	0.23099028	3383.2046
359.09131	1.0274705	0.23195753	3383.3267
359.99219	1.0325739	0.23297536	3389.1843
360.89307	1.0334992	0.23422752	3394.8291
361.79395	1.0352931	0.23536786	3387.0815
362.69482	1.0411389	0.23641478	3391.2913
363.5957	1.0439059	0.23758459	3396.2559
364.49658	1.0441735	0.23871723	3395.4788
365.39746	1.0467631	0.23968822	3389.1802
366.29834	1.0529989	0.24062949	3400.7676
367.19922	1.0518008	0.24163519	3402.0901
368.1001	1.0568335	0.24286427	3398.9712
369.00098	1.0595737	0.24398801	3398.5947
369.90186	1.0619949	0.24512577	3403.2454
370.80273	1.0641909	0.24627066	3402.5217
371.70361	1.0639477	0.24732856	3398.0698
372.60449	1.0670726	0.24841808	3411.7437
373.50537	1.0699749	0.24947515	3406.2559
374.40625	1.0744023	0.2507886	3415.1428
375.30713	1.0795267	0.25200015	3407.6396
376.20801	1.0785911	0.2528336	3407.0374
377.10889	1.0829052	0.25389159	3413.6372
378.00977	1.0846914	0.2547473	3413.1248
378.91064	1.0904752	0.25590739	3417.0383
379.81152	1.090475	0.25695315	3415.7192
380.7124	1.0952704	0.25795338	3420.4297
381.61328	1.0939327	0.2590428	3418.0027
382.51416	1.1017132	0.26005349	3423.0613
383.41504	1.0992326	0.26114833	3424.0168
384.31592	1.1036032	0.26211649	3425.8452
385.2168	1.1067303	0.26336274	3429.552
386.11768	1.1114538	0.26455608	3428.7332
387.01855	1.1096678	0.26561341	3429.0459
387.91943	1.1160688	0.26678708	3429.1445
388.82031	1.1191478	0.26783052	3430.4236
389.72119	1.1196276	0.2687428	3425.6772
390.62207	1.1214124	0.2698347	3430.6628
391.52295	1.1261867	0.27069685	3426.5737
392.42383	1.1322217	0.27180976	3437.813
393.32471	1.1317986	0.27279204	3433.2061
394.22559	1.1363668	0.27389583	3437.074
395.12646	1.1365553	0.27492425	3437.8801
396.02734	1.1386263	0.27593291	3438.4622
396.92822	1.1425345	0.27709982	3443.1914
397.8291	1.1450992	0.27819538	3444.6018
398.72998	1.1476169	0.27922502	3434.9011
399.63086	1.1498513	0.28014809	3441.0383
400.53174	1.1525892	0.28129265	3446.7217
401.43262	1.1538295	0.28238654	3452.8958
402.3335	1.1580606	0.28342846	3449.7681
403.23438	1.1596471	0.28477797	3449.7639
404.13525	1.1627693	0.28563365	3448.5913
405.03613	1.1669176	0.2867713	3448.2429
405.93701	1.1696907	0.28772753	3452.623
406.83789	1.17153	0.28884923	3457.3914
407.73877	1.1736022	0.29007804	3455.4919
408.63965	1.1765016	0.29122505	3461.6743
409.54053	1.1791979	0.29237798	3455.1128
410.44141	1.1870515	0.29335213	3461.9641
411.34229	1.1849371	0.29427087	3458.1499
412.24316	1.1893893	0.29537094	3469.1904
413.14404	1.189033	0.29661125	3465.5225
414.04492	1.1944623	0.29769045	3464.0649
414.9458	1.196494	0.29874501	3465.1333
415.84668	1.1980233	0.29993296	3469.8721
416.74756	1.1989553	0.3010056	3466.8513
417.64844	1.2026383	0.30204165	3466.5759
418.54932	1.2081119	0.30310783	3468.6548
419.4502	1.2099667	0.3043021	3472.4875
420.35107	1.2124985	0.30546322	3473.0132
421.25195	1.2147267	0.30646211	3469.7876
422.15283	1.2177539	0.30749184	3477.6331
423.05371	1.2212899	0.30877471	3479.8625
423.95459	1.2240763	0.30997431	3480.4189
424.85547	1.2242613	0.31105638	3477.6423
425.75635	1.2294846	0.31205863	3478.1858
426.65723	1.2310293	0.31304374	3479.5991
427.55811	1.2334229	0.3140313	3479.7241
428.45898	1.2379637	0.31498322	3478.7998
429.35986	1.2371806	0.31592146	3479.1465
430.26074	1.2429693	0.31696153	3481.7947
431.16162	1.2458085	0.31777534	3481.0637
432.0625	1.2494417	0.31898245	3489.6846
432.96338	1.2498076	0.32013518	3488.3181
433.86426	1.2521018	0.32115766	3485.9758
434.76514	1.255186	0.3222293	3487.2473
435.66602	1.2575018	0.32307151	3490.7183
436.56689	1.2609637	0.32450634	3493.9634
437.46777	1.2649179	0.32555026	3490.9443
438.36865	1.2662079	0.32644761	3494.2578
439.26953	1.2691211	0.3275862	3496.0205
440.17041	1.27539	0.32863972	3497.3359
441.07129	1.2751839	0.32952148	3496.2107
441.97217	1.280412	0.33045068	3491.918
442.87305	1.2835653	0.33139122	3503.9314
443.77393	1.2828397	0.33269936	3504.2368
444.6748	1.2844068	0.33398062	3501.9568
445.57568	1.2873218	0.33513519	3503.1563
446.47656	1.292779	0.33631128	3507.7361
447.37744	1.2925702	0.33743072	3509.9656
448.27832	1.2926755	0.33857042	3505.6382
449.1792	1.2996421	0.3398293	3508.197
450.08008	1.3031656	0.34104571	3513.3208
450.98096	1.3023077	0.34208384	3510.7556
451.88184	1.3084923	0.34305403	3501.7102
452.78271	1.3108194	0.3440614	3515.6196
453.68359	1.313247	0.34527147	3513.0989
454.58447	1.3136564	0.34634796	3513.2119
455.48535	1.3196298	0.34745061	3514.6873
456.38623	1.3209616	0.34844381	3515.8242
457.28711	1.3212055	0.34938723	3514.5815
458.18799	1.3235223	0.35035819	3514.5229
459.08887	1.3284661	0.35158357	3520.8086
459.98975	1.3334074	0.35280702	3528.741
460.89063	1.3357922	0.35379165	3520.8105
461.7915	1.3393033	0.35502505	3523.4368
462.69238	1.3402086	0.35601065	3519.2727
463.59326	1.3448151	0.3570607	3526.1821
464.49414	1.344107	0.3579697	3522.8596
465.39502	1.3480757	0.35905424	3526.5764
466.2959	1.3503129	0.36012113	3527.7783
467.19678	1.3524313	0.36146736	3532.4695
468.09766	1.3553206	0.36246151	3526.4768
468.99854	1.362471	0.3636122	3533.3164
469.89941	1.3641236	0.36455706	3528.0239
470.80029	1.3627039	0.36569861	3536.6775
471.70117	1.3652149	0.36706814	3542.4812
472.60205	1.3676034	0.36844915	3534.7266
473.50293	1.3720645	0.36954454	3530.8606
474.40381	1.374474	0.37063909	3536.8469
475.30469	1.3790811	0.37171158	3541.9734
476.20557	1.3812222	0.37282565	3540.2512
477.10645	1.3820887	0.37381667	3539.7205
478.00732	1.3846586	0.37488088	3542.0547
478.9082	1.3871273	0.37599552	3542.8416
479.80908	1.3939589	0.37715945	3543.8059
480.70996	1.3935419	0.37850344	3546.8728
481.61084	1.3987981	0.37979749	3551.709
482.51172	1.4004459	0.38094276	3540.7351
483.4126	1.4034821	0.38191172	3547.054
484.31348	1.4045354	0.38302979	3552.2742
485.21436	1.4059724	0.38423368	3547.3174
486.11523	1.4100817	0.38531801	3545.0405
487.01611	1.4116164	0.38641757	3551.5471
487.91699	1.4162164	0.38753903	3553.9519
488.81787	1.4198755	0.38876981	3559.2292
489.71875	1.4216369	0.39007774	3554.4487
490.61963	1.4218764	0.39115253	3552.7317
491.52051	1.4249274	0.39227766	3550.7097
492.42139	1.4268894	0.39317641	3550.7336
493.32227	1.4293293	0.39410448	3550.3511
494.22314	1.4351314	0.39525759	3561.2388
495.12402	1.4371555	0.3962954	3557.4473
496.0249	1.4391389	0.3975006	3561.0667
496.92578	1.4432986	0.3986384	3563.2434
497.82666	1.4462588	0.39989001	3564.3455
498.72754	1.4491868	0.40094736	3561.7146
499.62842	1.4528092	0.40193814	3560.0808
500.5293	1.4540986	0.40304345	3564.7097
501.43018	1.4568609	0.4041625	3569.8533
502.33105	1.4583783	0.40529129	3566.6707
503.23193	1.4626819	0.40664187	3570.5803
504.13281	1.4650544	0.4076601	3569.7603
505.03369	1.4668063	0.40847382	3564.1848
505.93457	1.4703205	0.40976664	3573.8088
506.83545	1.472231	0.41090894	3577.46
507.73633	1.4760754	0.41208389	3577.6204
508.63721	1.4764069	0.41307002	3571.3596
509.53809	1.4783523	0.41423404	3570.3342
510.43896	1.4845366	0.41522735	3575.6211
511.33984	1.4872904	0.41630858	3576.2358
512.24072	1.4888736	0.41740015	3574.5166
513.1416	1.4908298	0.41862807	3576.0303
514.04248	1.4936434	0.41968423	3571.8589
514.94336	1.4967335	0.42092466	3580.4199
515.84424	1.4973094	0.42221183	3584.5107
516.74512	1.5026898	0.42359155	3587.8672
517.646	1.5026337	0.42462033	3576.4287
518.54688	1.5058875	0.42577782	3580.1929
519.44775	1.5105846	0.4269768	3583.1528
520.34863	1.5142423	0.42801145	3583.8044
521.24951	1.5159812	0.42914736	3587.0107
522.15039	1.5188365	0.43015504	3588.2407
523.05127	1.5224324	0.43151262	3597.2949
523.95215	1.5214418	0.43285733	3589.1855
524.85303	1.5267771	0.43418413	3588.6079
525.75391	1.5300074	0.43529931	3589.7356
526.65479	1.532689	0.43651047	3590.8323
527.55566	1.53476	0.4375788	3592.0154
528.45654	1.5385586	0.4386867	3592.3459
529.35742	1.5394597	0.43985438	3595.0759
530.2583	1.5420629	0.44089204	3590.0156
531.15918	1.544223	0.44215304	3599.8552
532.06006	1.5460539	0.44341674	3595.1348
532.96094	1.5509073	0.44461745	3599.5032
533.86182	1.5545475	0.44588295	3600.2686
534.7627	1.5530963	0.44697049	3596.1682
535.66357	1.560594	0.44802135	3596.2192
536.56445	1.5633442	0.44922647	3600.8225
537.46533	1.5657738	0.45039096	3605.4258
538.36621	1.5666969	0.45144954	3597.426
539.26709	1.5700117	0.45237052	3601.3906
540.16797	1.5735513	0.45348272	3604.1687
541.06885	1.5743402	0.45463344	3605.3306
541.96973	1.5772545	0.45585328	3604.4607
542.87061	1.5800015	0.45716298	3613.0515
543.77148	1.5865653	0.45834339	3607.8594
544.67236	1.5878524	0.45946565	3611.7046
545.57324	1.5883991	0.46063378	3609.5166
546.47412	1.591802	0.4619742	3611.1096
547.375	1.5946946	0.46314058	3615.6975
548.27588	1.5961142	0.4643091	3611.3901
549.17676	1.5989639	0.46554863	3614.3535
550.07764	1.6005938	0.46674046	3612.3196
550.97852	1.6041597	0.46807727	3612.6687
551.87939	1.6061016	0.46954778	3617.9456
552.78027	1.61151	0.47068816	3614.5596
553.68115	1.6122855	0.47193667	3614.7532
554.58203	1.616062	0.47299024	3613.9377
555.48291	1.6183709	0.47408661	3619.5298
556.38379	1.6207038	0.47529143	3612.8083
557.28467	1.6239094	0.47656873	3618.6289
558.18555	1.6276128	0.47776729	3619.499
559.08643	1.6276433	0.47887057	3615.5059
559.9873	1.6288338	0.47997683	3621.7439
560.88818	1.6356937	0.48122117	3615.5459
561.78906	1.6394554	0.48233119	3621.2361
562.68994	1.6402758	0.48351866	3623.7273
563.59082	1.6420739	0.48469493	3624.2939
564.4917	1.6438438	0.48587394	3622.0591
565.39258	1.6455244	0.48709553	3623.6724
566.29346	1.6524903	0.48820817	3621.5027
567.19434	1.6556619	0.48924685	3624.6189
568.09521	1.6545647	0.49044991	3625.8291
568.99609	1.6578379	0.49143526	3621.3096
569.89697	1.6610831	0.49272865	3631.1951
570.79785	1.6625422	0.49384019	3625.1892
571.69873	1.6672966	0.494854	3624.0227
572.59961	1.6684805	0.49584675	3629.1267
573.50049	1.6715217	0.4969534	3625.0063
574.40137	1.6742924	0.4981142	3632.1907
575.30225	1.6779219	0.49933854	3639.7546
576.20313	1.6805362	0.50096947	3639.7925
577.104	1.6834319	0.50213617	3627.8789
578.00488	1.6875584	0.50338316	3635.0798
578.90576	1.6897449	0.50456667	3642.0505
579.80664	1.6916753	0.50586516	3637.2847
580.70752	1.6958717	0.50712222	3636.6509
581.6084	1.695883	0.50844836	3636.1167
582.50928	1.699219	0.50957549	3641.4089
583.41016	1.7054974	0.51080346	3641.7212
584.31104	1.7050775	0.51193386	3640.718
585.21191	1.7090584	0.51303178	3639.0972
586.11279	1.7070736	0.51440758	3642.8086
587.01367	1.7133776	0.51562893	3645.0906
587.91455	1.7163107	0.51700854	3645.6431
588.81543	1.7178762	0.51841825	3647.8328
589.71631	1.72025	0.51985037	3645.179
590.61719	1.7224704	0.52111548	3643.1677
591.51807	1.7229906	0.52231681	3640.4922
592.41895	1.7287008	0.52352881	3641.5632
593.31982	1.7312022	0.52455133	3642.2681
594.2207	1.7349153	0.52583414	3648.6563
595.12158	1.7391707	0.52703661	3646.2251
596.02246	1.7389216	0.5282023	3648.5107
596.92334	1.7431768	0.52935261	3648.2219
597.82422	1.7452319	0.53060454	3646.4531
598.7251	1.7492245	0.53182983	3655.27
599.62598	1.7519729	0.53306204	3652.4563
600.52686	1.7544109	0.53465098	3662.8162
601.42773	1.7567835	0.53611523	3656.0366
602.32861	1.760277	0.5375219	3652.9397
603.22949	1.7607224	0.53858888	3648.562
604.13037	1.7634954	0.53974599	3651.366
605.03125	1.7672445	0.54100633	3653.5537
605.93213	1.7684255	0.54204613	3650.9248
606.83301	1.7728274	0.54319125	3656.7512
607.73389	1.7772754	0.54425418	3660.2012
608.63477	1.7755446	0.54537976	3652.6023
609.53564	1.7825077	0.5466584	3657.9299
610.43652	1.7825724	0.5479393	3659.3179
611.3374	1.7816242	0.54934818	3657.9463
612.23828	1.7886276	0.55062544	3661.3672
613.13916	1.7898	0.55210191	3657.9648
614.04004	1.7938373	0.55354416	3661.8496
614.94092	1.7952828	0.55483246	3659.7708
615.8418	1.7989092	0.55612445	3661.613
616.74268	1.8017428	0.55735451	3659.3748
617.64355	1.808471	0.55853367	3660.3091
618.54443	1.8096937	0.55955744	3662.4885
619.44531	1.8094146	0.56075215	3666.0459
620.34619	1.8155574	0.561979	3665.3521
621.24707	1.8148323	0.56326318	3660.03
622.14795	1.8173723	0.56456977	3666.8718
623.04883	1.8193276	0.56598455	3663.7241
623.94971	1.823195	0.56751901	3668.2383
624.85059	1.8256819	0.56893176	3671.6975
625.75146	1.8255937	0.57042408	3665.9683
626.65234	1.8319371	0.57172114	3667.7371
627.55322	1.8349286	0.57312417	3676.0315
628.4541	1.8371505	0.5744791	3667.7515
629.35498	1.8397264	0.57575715	3670.9236
630.25586	1.840952	0.57694876	3664.7253
631.15674	1.8458873	0.57833433	3676.9866
632.05762	1.8472158	0.57975107	3673.6848
632.9585	1.8505669	0.5810954	3668.698
633.85938	1.852708	0.58217919	3666.5352
634.76025	1.8568833	0.58330196	3672.3633
635.66113	1.8592206	0.58450073	3666.0654
636.56201	1.8620489	0.58581483	3677.9705
637.46289	1.8640033	0.5871349	3674.9983
638.36377	1.86752	0.58863372	3683.4038
639.26465	1.8733782	0.58998221	3677.3933
640.16553	1.870953	0.59123307	3672.4102
641.06641	1.8746991	0.59237808	3670.0393
641.96729	1.876017	0.59369987	3677.9033
642.86816	1.8796203	0.59489429	3672.5574
643.76904	1.8830366	0.59621012	3681.856
644.66992	1.8860021	0.59762126	3680.6528
645.5708	1.8881162	0.59895021	3672.6636
646.47168	1.8908828	0.60046828	3687.4531
647.37256	1.8932462	0.60189402	3679.228
648.27344	1.8977458	0.60322213	3689.325
649.17432	1.8985543	0.60456812	3682.7769
650.0752	1.9028574	0.60592043	3681.0898
650.97607	1.9025505	0.60719353	3676.335
651.87695	1.9090444	0.60846174	3680.25
652.77783	1.9096128	0.6099177	3685.469
653.67871	1.9130436	0.61121547	3682.4702
654.57959	1.9159166	0.61263919	3684.6108
655.48047	1.9191167	0.61416483	3685.8982
656.38135	1.9210898	0.6154505	3678.2734
657.28223	1.9235467	0.61670864	3687.3452
658.18311	1.9256449	0.61829001	3690.9404
659.08398	1.9292926	0.61989945	3686.4355
659.98486	1.9333837	0.62124825	3677.991
660.88574	1.9351768	0.62266397	3685.0073
661.78662	1.9354371	0.62404722	3684.0557
662.6875	1.9421573	0.62544608	3691.1326
663.58838	1.9421532	0.62694943	3687.5054
664.48926	1.947245	0.62818873	3690.9299
665.39014	1.9502248	0.62945628	3688.4971
666.29102	1.9542291	0.63059849	3689.9761
667.19189	1.9503323	0.6319415	3690.7356
668.09277	1.9565505	0.63320392	3690.4575
668.99365	1.9592085	0.63462591	3692.4905
669.89453	1.962893	0.63610733	3693.135
670.79541	1.9620883	0.63742393	3690.2698
671.69629	1.968788	0.63895327	3696.387
672.59717	1.9679801	0.64047396	3691.3743
673.49805	1.9731168	0.64188826	3692.8745
674.39893	1.9771006	0.64341605	3694.5618
675.2998	1.9784678	0.64490026	3692.4922
676.20068	1.9807212	0.64597505	3688.7937
677.10156	1.9844276	0.647416	3698.3557
678.00244	1.9837849	0.64854908	3688.822
678.90332	1.9854732	0.64978135	3690.4646
679.8042	1.9893445	0.6512019	3693.6934
680.70508	1.9950013	0.65264893	3696.8359
681.60596	1.994844	0.65386021	3691.8059
682.50684	1.9968673	0.65508407	3697.21
683.40771	2.0000415	0.6566813	3698.3516
684.30859	2.005682	0.6583975	3704.2927
685.20947	2.0061049	0.66016704	3700.3103
686.11035	2.0087821	0.66175759	3703.1824
687.01123	2.0127523	0.66323322	3699.8098
687.91211	2.0138927	0.66471857	3700.6125
688.81299	2.0179853	0.66629988	3702.9478
689.71387	2.0213394	0.66763753	3698.2759
690.61475	2.021462	0.66895759	3694.9272
691.51563	2.0255246	0.67041528	3698.6995
692.4165	2.0299625	0.67151976	3695.3848
693.31738	2.0286872	0.6728493	3701.2271
694.21826	2.0359585	0.67453569	3709.9185
695.11914	2.0356462	0.67599243	3700.6045
696.02002	2.0420568	0.67736125	3699.6079
696.9209	2.044024	0.67891812	3702.269
697.82178	2.0455723	0.68047684	3711.9116
698.72266	2.0452757	0.68224573	3700.718
699.62354	2.050323	0.68398458	3702.7283
700.52441	2.0518749	0.68545794	3699.2603
701.42529	2.0568619	0.68688118	3701.6436
702.32617	2.0558968	0.68816757	3702.1436
703.22705	2.061044	0.68968421	3707.0027
704.12793	2.0624232	0.69095755	3698.9683
705.02881	2.0650134	0.69231957	3706.8865
705.92969	2.0705917	0.69411629	3710.0254
706.83057	2.0732121	0.69562912	3704.9636
707.73145	2.0735366	0.69696969	3704.6702
708.63232	2.075068	0.69835973	3701.6323
709.5332	2.0795505	0.70032865	3708.1682
710.43408	2.0804574	0.70194697	3701.7283
711.33496	2.081975	0.70313799	3698.8787
712.23584	2.0857379	0.70440722	3700.3311
713.13672	2.0925064	0.7055217	3700.8242
714.0376	2.0947094	0.7067486	3707.2087
714.93848	2.0973158	0.70793533	3699.5515
715.83936	2.1009963	0.70921767	3708.1692
716.74023	2.1027007	0.71079904	3712.532
717.64111	2.1037118	0.71240622	3708.8569
718.54199	2.1081877	0.7141239	3711.6228
719.44287	2.1086023	0.71573818	3709.761
720.34375	2.1131849	0.71731293	3705.6528
721.24463	2.1150539	0.71874559	3705.6072
722.14551	2.1172523	0.72032201	3706.9978
723.04639	2.1219697	0.72164243	3705.2207
723.94727	2.1242356	0.72321022	3706.3481
724.84814	2.1252494	0.7248444	3711.9226
725.74902	2.1302853	0.72669697	3714.8196
726.6499	2.1311877	0.72825694	3706.2148
727.55078	2.1335618	0.72986418	3705.6648
728.45166	2.1366718	0.73132801	3709.3264
729.35254	2.1408353	0.73290181	3713.6079
730.25342	2.1427321	0.73468024	3710.4656
731.1543	2.1456232	0.73641616	3713.3159
732.05518	2.1478024	0.7380572	3711.4993
732.95605	2.1530118	0.73974282	3711.9783
733.85693	2.1514339	0.7416085	3713.5623
734.75781	2.1579635	0.74338734	3715.9475
735.65869	2.1592734	0.74511188	3709.3127
736.55957	2.1594286	0.74671608	3704.8152
737.46045	2.1659937	0.74811649	3707.3984
738.36133	2.1674235	0.74961352	3712.325
739.26221	2.1709428	0.75108033	3715.9629
740.16309	2.1702936	0.75295031	3709.6123
741.06396	2.1737828	0.75437802	3706.844
741.96484	2.1760879	0.75600857	3710.1978
742.86572	2.1792085	0.75748944	3711.2871
743.7666	2.1813903	0.75908792	3709.5024
744.66748	2.1849689	0.76074934	3710.1707
745.56836	2.1880836	0.76242018	3712.3115
746.46924	2.1883974	0.76404327	3712.3215
747.37012	2.1922238	0.7656799	3707.5017
748.271	2.1968708	0.76720345	3716.2971
749.17188	2.1974463	0.7687782	3708.3774
750.07275	2.2007926	0.77018857	3713.9636
750.97363	2.2059155	0.77174097	3714.4797
751.87451	2.2069116	0.77358603	3712.6841
752.77539	2.2099016	0.77534807	3715.4146
753.67627	2.2150202	0.77716142	3711.074
754.57715	2.2147818	0.77839953	3710.8467
755.47803	2.218997	0.77972615	3712.0359
756.37891	2.2203169	0.78114873	3714.0859
757.27979	2.2216003	0.78313005	3719.3464
758.18066	2.2237527	0.78538829	3716.7661
759.08154	2.2293828	0.78712678	3714.5073
759.98242	2.2309341	0.78868389	3707.4004
760.8833	2.2329648	0.79035646	3711.7705
761.78418	2.2360075	0.79210246	3712.8137
762.68506	2.2389009	0.79382408	3713.282
763.58594	2.244797	0.79583311	3724.282
764.48682	2.2460639	0.7981351	3720.7766
765.3877	2.24733	0.80007899	3713.8931
766.28857	2.250705	0.80193156	3709.8752
767.18945	2.2517884	0.80362469	3711.1533
768.09033	2.2541518	0.8054626	3710.4468
768.99121	2.2583425	0.80721831	3710.1863
769.89209	2.2607298	0.80886191	3714.5427
770.79297	2.2628267	0.81056517	3712.8601
771.69385	2.2661011	0.81199163	3712.5566
772.59473	2.2695031	0.81359768	3706.8821
773.49561	2.2720833	0.81510067	3716.5278
774.39648	2.2745442	0.81704384	3719.9387
775.29736	2.277478	0.81876153	3715.5574
776.19824	2.2834713	0.82047474	3718.2175
777.09912	2.2838156	0.82230633	3710.2056
778	2.2852449	0.82413113	3717.7883
778.90088	2.287935	0.82615918	3717.1536
779.80176	2.2919166	0.82847333	3717.2881
780.70264	2.2920642	0.83046126	3712.9568
781.60352	2.2981052	0.83234566	3713.2585
782.50439	2.2971723	0.83410764	3712.353
783.40527	2.3020709	0.83570987	3707.0295
784.30615	2.3053744	0.83759552	3711.8279
785.20703	2.3087242	0.83932215	3714.9739
786.10791	2.3105924	0.84106916	3713.1382
787.00879	2.3124993	0.84263498	3711.9541
787.90967	2.315007	0.84442973	3713.3013
788.81055	2.315433	0.84619176	3711.7478
789.71143	2.3212647	0.84788197	3709.6057
790.6123	2.3242106	0.84995955	3718.4177
791.51318	2.3248575	0.85197353	3716.2539
792.41406	2.3311756	0.8540886	3711.364
793.31494	2.3306115	0.85595024	3711.7869
794.21582	2.3331263	0.85803306	3712.8589
795.1167	2.3386157	0.86010838	3711.9951
796.01758	2.3400018	0.86181986	3712.6477
796.91846	2.3428423	0.86344641	3710.3599
797.81934	2.3448157	0.86524189	3714.6318
798.72021	2.3497264	0.86734223	3716.8523
799.62109	2.3527627	0.86918294	3712.1455
800.52197	2.3530126	0.87116688	3709.9707
801.42285	2.3576748	0.87303984	3715.8018
802.32373	2.3584118	0.87516934	3716.4536
803.22461	2.3592746	0.87704527	3711.0161
804.12549	2.3641422	0.87904286	3707.8584
805.02637	2.3671541	0.88103366	3711.6577
805.92725	2.3675232	0.88303679	3713.9612
806.82813	2.3736365	0.88530833	3709.6819
807.729	2.3749316	0.88746685	3709.7214
808.62988	2.3778403	0.88943738	3708.9182
809.53076	2.3832073	0.89148092	3711.6792
810.43164	2.3845351	0.89357823	3711.7334
811.33252	2.3843722	0.89563978	3709.4099
812.2334	2.3876209	0.89777201	3710.1846
813.13428	2.3926129	0.90005636	3715.9158
814.03516	2.39518	0.90251768	3711.4519
814.93604	2.3981452	0.90468025	3708.3738
815.83691	2.397227	0.90668577	3706.3828
816.73779	2.4014904	0.90852475	3702.8284
817.63867	2.405555	0.91068769	3708.5261
818.53955	2.4072487	0.91301465	3710.7095
819.44043	2.4071119	0.91522807	3708.0942
820.34131	2.4129438	0.91728789	3710.9795
821.24219	2.4128664	0.9190768	3702.5005
822.14307	2.4164188	0.92119169	3705.7747
823.04395	2.4217494	0.92330408	3709.3728
823.94482	2.4232061	0.92544633	3704.9595
824.8457	2.4265313	0.92776597	3705.9551
825.74658	2.4300075	0.92978716	3701.2253
826.64746	2.4321947	0.9318791	3701.2349
827.54834	2.4371345	0.93343091	3693.7937
828.44922	2.4365637	0.93538165	3700.4089
829.3501	2.4387035	0.93747789	3701.0657
830.25098	2.4443965	0.93990052	3711.166
831.15186	2.4453154	0.94262928	3705.6851
832.05273	2.4470842	0.94497079	3705.2458
832.95361	2.4483635	0.94731426	3698.9927
833.85449	2.4522903	0.94961417	3701.0049
834.75537	2.459743	0.95178175	3701.8757
835.65625	2.4593055	0.95397025	3701.6506
836.55713	2.4643641	0.95625937	3701.502
837.45801	2.4613688	0.95841306	3700.6409
838.35889	2.4655945	0.96124679	3703.4917
839.25977	2.4688623	0.96440828	3700.3596
840.16064	2.4713051	0.96670568	3693.3259
841.06152	2.4765086	0.96897852	3692.6663
841.9624	2.4743621	0.97085392	3689.3833
842.86328	2.4782827	0.97289193	3695.7485
843.76416	2.4850144	0.97531611	3699.3728
844.66504	2.4844749	0.97772938	3695.3042
845.56592	2.4890821	0.98039359	3693.5337
846.4668	2.4894905	0.98300678	3690.8054
847.36768	2.4947882	0.98541743	3687.6873
848.26855	2.4935377	0.98742765	3686.9629
849.16943	2.4981377	0.989694	3691.1829
850.07031	2.5018375	0.99195915	3687.0498
850.97119	2.5051024	0.9941209	3686.8254
851.87207	2.5066924	0.9970693	3691.8899
852.77295	2.5074823	0.99986821	3689.1509
853.67383	2.5145431	1.0024804	3687.6814
854.57471	2.5148418	1.0045469	3682.4272
855.47559	2.5204816	1.0064555	3681.354
856.37646	2.5223787	1.0084738	3686.877
857.27734	2.5237417	1.0106374	3681.5671
858.17822	2.5269384	1.0125787	3683.7427
859.0791	2.5291989	1.0148996	3683.5083
859.97998	2.5335262	1.0175384	3685.2571
860.88086	2.5328879	1.0200944	3676.2173
861.78174	2.5369935	1.0228562	3682.1096
862.68262	2.5431502	1.0256968	3685.3943
863.5835	2.5450664	1.0284802	3678.7019
864.48438	2.5450566	1.0313617	3678.1172
865.38525	2.5480862	1.0339985	3675.3232
866.28613	2.5502808	1.0365	3667.6396
867.18701	2.5512347	1.0386537	3669.2009
868.08789	2.5577013	1.0406684	3673.6414
868.98877	2.5588605	1.043252	3679.6509
869.88965	2.5610385	1.045941	3672.259
870.79053	2.5648632	1.0484657	3678.2483
871.69141	2.5662434	1.0517117	3671.9939
872.59229	2.5683258	1.0547417	3670.4006
873.49316	2.5734951	1.0575984	3662.8694
874.39404	2.5760758	1.0597534	3663.384
875.29492	2.5791249	1.0622745	3664.5476
876.1958	2.5809324	1.0647805	3668.8545
877.09668	2.5843525	1.0673945	3662.7749
877.99756	2.5855005	1.069778	3658.8467
878.89844	2.5888512	1.0720576	3659.5774
879.79932	2.5916348	1.0742236	3648.073
880.7002	2.5939806	1.0772072	3663.625
881.60107	2.5957932	1.0810179	3660.7947
882.50195	2.5985892	1.0843216	3656.1084
883.40283	2.6026449	1.0877949	3654.845
884.30371	2.6052029	1.0905286	3643.4839
885.20459	2.6085944	1.0929574	3647.2781
886.10547	2.6088796	1.0952907	3646.717
887.00635	2.614228	1.098411	3652.8953
887.90723	2.6147923	1.1013498	3644.3384
888.80811	2.61992	1.1041951	3643.8989
889.70898	2.6210504	1.1068145	3641.7234
890.60986	2.6236746	1.1096749	3642.8936
891.51074	2.6255839	1.1125441	3633.5195
892.41162	2.6284897	1.1148502	3629.2561
893.3125	2.6316094	1.1174427	3639.9373
894.21338	2.6343865	1.1205215	3634.2534
895.11426	2.635529	1.1236205	3634.0115
896.01514	2.6411965	1.1269524	3632.8879
896.91602	2.6407449	1.1298764	3627.2317
897.81689	2.6447284	1.132275	3621.1516
898.71777	2.6483946	1.1347179	3624.9116
899.61865	2.6511979	1.1373155	3622.5728
900.51953	2.6528909	1.13994	3624.3982
901.42041	2.654886	1.1428709	3620.6804
902.32129	2.6600199	1.1455523	3618.2175
903.22217	2.6622825	1.1482776	3617.4492
904.12305	2.66467	1.15093	3617.9041
905.02393	2.6646369	1.1540946	3615.71
905.9248	2.6702089	1.1575322	3611.0229
906.82568	2.6719644	1.160771	3603.7773
907.72656	2.6757545	1.163729	3608.7524
908.62744	2.6787841	1.1670477	3603.7163
909.52832	2.6794028	1.1696553	3600.4556
910.4292	2.6836452	1.171821	3594.7893
911.33008	2.6881213	1.1742089	3602.2146
912.23096	2.6870368	1.1770891	3598.4827
913.13184	2.6905875	1.1799096	3593.3362
914.03271	2.6921937	1.1828066	3591.6799
914.93359	2.6984129	1.1856849	3586.2109
915.83447	2.699194	1.1886843	3585.3467
916.73535	2.7009459	1.1913997	3585.2898
917.63623	2.7047861	1.1943239	3581.9978
918.53711	2.7080023	1.1970426	3580.5056
919.43799	2.7121568	1.1999247	3577.5881
920.33887	2.7154028	1.2025123	3574.6853
921.23975	2.7158606	1.2050374	3574.124
922.14063	2.7178404	1.2081677	3571.1274
923.0415	2.7190785	1.2113053	3568.3088
923.94238	2.72246	1.2144719	3560.4885
924.84326	2.7264638	1.2172781	3564.2354
925.74414	2.7279	1.2208086	3565.2322
926.64502	2.7330616	1.2242674	3555.0254
927.5459	2.7330935	1.2272167	3549.0676
928.44678	2.7380323	1.2299365	3545.8926
929.34766	2.741401	1.2325339	3542.3408
930.24854	2.7410421	1.2351587	3540.3396
931.14941	2.7468705	1.2377747	3545.0957
932.05029	2.7485797	1.2408255	3543.6797
932.95117	2.7513413	1.2437432	3536.9458
933.85205	2.754971	1.2468141	3534.8875
934.75293	2.7562993	1.2496191	3531.5508
935.65381	2.7607291	1.2529546	3534.5535
936.55469	2.761533	1.2558039	3525.3711
937.45557	2.7657278	1.2586832	3523.677
938.35645	2.7684948	1.2614704	3518.0596
939.25732	2.7701724	1.2643784	3513.9243
940.1582	2.7725086	1.267275	3509.6826
941.05908	2.7772741	1.2705319	3515.9268
941.95996	2.7792876	1.2738826	3506.4561
942.86084	2.7809296	1.2767698	3504.7893
943.76172	2.7852807	1.2794626	3497.478
944.6626	2.786495	1.2824773	3498.3201
945.56348	2.7893801	1.2858443	3494.3711
946.46436	2.7932343	1.2890505	3490.3784
947.36523	2.7941477	1.2919617	3485.1802
948.26611	2.7959912	1.2953026	3485.3794
949.16699	2.8002667	1.2986739	3479.1907
950.06787	2.802186	1.301455	3470.4863
950.96875	2.8071177	1.3042197	3473.7012
951.86963	2.8069477	1.3068496	3467.5071
952.77051	2.8102424	1.3099444	3463.2886
953.67139	2.81441	1.3129849	3462.1636
954.57227	2.8160999	1.3160024	3457.0168
955.47314	2.8192012	1.3194634	3451.3994
956.37402	2.8217232	1.3226364	3446.553
957.2749	2.8245342	1.3252785	3443.0452
958.17578	2.8277333	1.3285742	3439.8423
959.07666	2.8290532	1.3314912	3434.7244
959.97754	2.8347278	1.3344213	3431.0383
960.87842	2.8358374	1.3370364	3426.3489
961.7793	2.8376098	1.3396915	3418.5952
962.68018	2.8402772	1.3423712	3425.125
963.58105	2.843642	1.3455867	3417.0308
964.48193	2.847568	1.3486272	3415.2632
965.38281	2.8494701	1.3517355	3415.4524
966.28369	2.8505657	1.3557448	3406.1926
967.18457	2.852581	1.3586079	3390.6523
968.08545	2.8584507	1.3619107	3393.9587
968.98633	2.8610988	1.3652116	3387.4578
969.88721	2.861845	1.36799	3379.9221
970.78809	2.866261	1.3706068	3382.333
971.68896	2.8689475	1.3736805	3374.4551
972.58984	2.8718565	1.3767655	3368.6902
973.49072	2.873951	1.3800678	3365.8899
974.3916	2.8753247	1.3836584	3360.2932
975.29248	2.876976	1.3874047	3345.7915
976.19336	2.8803778	1.3913686	3340.7014
977.09424	2.8860846	1.3944114	3330.0295
977.99512	2.8877237	1.3975879	3321.2632
978.896	2.8912508	1.4005982	3321.0061
979.79688	2.8916512	1.4033002	3306.5884
980.69775	2.8974454	1.406828	3308.7378
981.59863	2.8965783	1.4107615	3297.0955
982.49951	2.9004259	1.4140384	3284.2881
983.40039	2.9028549	1.4169523	3276.5317
984.30127	2.904711	1.420085	3269.4026
985.20215	2.9077256	1.4238743	3267.6521
986.10303	2.9112084	1.4281181	3258.1582
987.00391	2.9150076	1.4319192	3243.3442
987.90479	2.9153154	1.4357234	3237.1157
988.80566	2.9199588	1.4395145	3221.3264
989.70654	2.9221284	1.4428484	3210.7402
990.60742	2.9256878	1.4457861	3200.8745
991.5083	2.9279444	1.4485127	3192.4795
992.40918	2.9297605	1.451606	3186.4507
993.31006	2.9356229	1.4554076	3181.0242
994.21094	2.9357119	1.4591138	3161.3015
995.11182	2.9395096	1.4624842	3155.5129
996.0127	2.9350832	1.4677353	3126.6543
996.91357	2.9464531	1.4730375	3102.0054
997.71436	3.07901	-0.30152947	-1.3753419