File: datasets/am_bench_2022/raw_data/90-X.13-1/specimen.dat
MTS793|MPT|ENU|1|2|.|/|:|1|0|0|A

Operator Information						Time:	16.876709	Sec	11/2/2021 11:50:25 AM
Operator	Nick Derimow
Project	AM Bench 2022 mini-tensile challenge
Specimen ID	90-X.13-1
Material	PBF-L Inconel 625
Specimen Width	2.54	mm
Specimen Thickness	1.51	mm
Notes
Operator Information End

Data Acquisition						Time:	1017.8704	Sec	11/2/2021 12:07:06 PM
Time	Axial Displacement	Axial Extensometer	Axial Force
Sec	mm	mm	N
16.990234	-0.0024430158	2.357387e-05	29.983473
17.891113	0.00093066774	9.6653355e-05	43.084763
18.791992	0.0028382025	0.00011143419	52.925369
19.692871	0.0050417539	0.00021245671	65.416237
20.59375	0.0063128974	0.00041397312	77.830887
21.494629	0.010819423	0.00048430296	88.530792
22.395508	0.012566323	0.00048103291	93.016846
23.296387	0.015523873	0.00065316795	101.21458
24.197266	0.01550154	0.00064680405	109.71426
25.098145	0.020676419	0.00079452427	118.1872
25.999023	0.023913646	0.00098601333	136.26712
26.899902	0.027454315	0.00099570875	142.40439
27.800781	0.028082715	0.0010039699	151.44244
28.70166	0.032135613	0.0010668868	166.33765
29.602539	0.032935917	0.0013045163	187.20984
30.503418	0.038203407	0.0013242965	202.83704
31.404297	0.039870605	0.0013863047	215.41893
32.305176	0.041386541	0.0015000049	229.57283
33.206055	0.043993779	0.0015177771	245.98434
34.106934	0.045455217	0.0018291089	260.90561
35.007813	0.049414888	0.0016999068	275.45444
35.908691	0.053077109	0.0018190662	292.00925
36.80957	0.055008564	0.0018917851	308.02939
37.710449	0.058661513	0.002135721	326.46448
38.611328	0.061729502	0.0021640779	347.14441
39.512207	0.065196052	0.002322051	365.44104
40.413086	0.065420203	0.002399011	382.36356
41.313965	0.067259096	0.002519273	395.09143
42.214844	0.0699507	0.0026756518	422.32565
43.115723	0.071405992	0.0027711587	441.72095
44.016602	0.074186154	0.0028491679	459.42169
44.91748	0.079811387	0.00299441	483.9472
45.818359	0.083278701	0.0031923724	510.87415
46.719238	0.08520852	0.0032481807	528.4173
47.620117	0.08658272	0.0033977039	552.07324
48.520996	0.09106876	0.0034997019	570.19098
49.421875	0.092129074	0.0036990792	582.98761
50.322754	0.098192513	0.0037760145	607.88501
51.223633	0.096975714	0.0038078751	622.53442
52.124512	0.10016438	0.003929513	648.39484
53.025391	0.10303506	0.0042332769	676.34241
53.92627	0.105295	0.0043052295	695.74823
54.827148	0.11056045	0.0044892607	727.01813
55.728027	0.11187948	0.0045955982	742.70361
56.628906	0.11510646	0.0046370719	769.28259
57.529785	0.11622456	0.0048323381	788.18018
58.430664	0.11918953	0.0049317256	817.55127
59.331543	0.12368868	0.0051455768	841.21735
60.232422	0.12353788	0.0052267942	866.77899
61.133301	0.12867644	0.0054611294	891.37396
62.03418	0.12979802	0.0055508828	904.09619
62.935059	0.13340656	0.0057404214	930.96143
63.835938	0.13603321	0.0057801702	951.13562
64.736816	0.13680626	0.0059686597	975.38831
65.637695	0.1418051	0.0060821138	1005.7634
66.538574	0.14369377	0.0062333876	1027.0967
67.439453	0.14804648	0.0064426153	1058.1095
68.340332	0.14758322	0.0065544234	1080.007
69.241211	0.15333359	0.0066939807	1100.5999
70.14209	0.15424371	0.0068595191	1129.2891
71.042969	0.15629278	0.0069594099	1148.1074
71.943848	0.1620768	0.0071241492	1178.5107
72.844727	0.16162424	0.0073435311	1198.8206
73.745605	0.16410871	0.007517166	1228.9625
74.646484	0.16702978	0.0075518703	1248.9929
75.547363	0.169245	0.0078348052	1280.1044
76.448242	0.17469122	0.0079959463	1301.2655
77.349121	0.17485021	0.0080851261	1319.7019
78.25	0.17811899	0.0082398001	1347.5435
79.150879	0.17976074	0.0082491105	1362.4768
80.051758	0.18130787	0.0086013712	1391.7682
80.952637	0.1885505	0.0086504789	1416.129
81.853516	0.18856628	0.008746895	1438.6855
82.754395	0.19105566	0.0090605803	1471.8196
83.655273	0.19567339	0.0091507882	1495.2649
84.556152	0.19939503	0.0092517575	1524.6658
85.457031	0.20017566	0.0095106708	1544.7123
86.35791	0.20368375	0.0096878707	1567.2494
87.258789	0.2054556	0.0097074788	1586.4434
88.159668	0.21150474	0.0098988153	1615.3707
89.060547	0.21015143	0.010025133	1636.1838
89.961426	0.21141602	0.010142338	1656.0098
90.862305	0.21601045	0.010312577	1688.0925
91.763184	0.2198474	0.010536499	1709.1764
92.664063	0.2236786	0.01069466	1731.6521
93.564941	0.22657986	0.01075287	1752.2529
94.46582	0.22671959	0.010989401	1774.4336
95.366699	0.2289969	0.011156095	1798.2651
96.267578	0.23226507	0.011321067	1821.1796
97.168457	0.23618397	0.011462612	1845.5392
98.069336	0.23610038	0.011531901	1867.3967
98.970215	0.24200349	0.011751989	1898.0421
99.871094	0.24170905	0.011891321	1913.6055
100.77197	0.24721724	0.011907983	1938.6512
101.67285	0.24305165	0.012191336	1955.9746
102.57373	0.25228518	0.012382202	1986.0715
103.47461	0.254381	0.01244361	2001.4023
104.37549	0.25464019	0.012570838	2019.6118
105.27637	0.26052004	0.012844631	2049.8416
106.17725	0.26237595	0.012945007	2065.4353
107.07813	0.26280126	0.012998519	2083.4553
107.979	0.26876315	0.013182582	2104.7437
108.87988	0.27327457	0.01336774	2123.3887
109.78076	0.27159756	0.013519612	2140.4702
110.68164	0.27510935	0.013664017	2161.4939
111.58252	0.27944869	0.013806628	2183.2268
112.4834	0.28097391	0.013983664	2195.9546
113.38428	0.28435004	0.01411771	2218.9131
114.28516	0.28849781	0.014204857	2235.1213
115.18604	0.28781614	0.014215332	2246.0691
116.08691	0.2932381	0.01443939	2263.3035
116.98779	0.29438692	0.014556787	2279.5493
117.88867	0.29888895	0.014777182	2298.3018
118.78955	0.30270621	0.014949874	2312.8589
119.69043	0.30391851	0.01499928	2326.4509
120.59131	0.3052128	0.01525789	2340.5459
121.49219	0.31024098	0.015324881	2351.749
122.39307	0.31215322	0.015600452	2375.8708
123.29395	0.31395295	0.015737208	2387.2449
124.19482	0.31633413	0.015895657	2400.842
125.0957	0.32125664	0.016071057	2415.2183
125.99658	0.32316658	0.016164642	2422.5815
126.89746	0.32384682	0.016470376	2442.135
127.79834	0.32699737	0.016536936	2450.8406
128.69922	0.32918009	0.01681797	2464.8977
129.6001	0.33494812	0.01697485	2474.4097
130.50098	0.33575684	0.017138965	2486.5876
131.40186	0.33991951	0.017260876	2500.4106
132.30273	0.34214318	0.017465472	2503.9773
133.20361	0.3465448	0.017646963	2522.3264
134.10449	0.34473521	0.017857067	2520.4214
135.00537	0.34900963	0.017937232	2533.9744
135.90625	0.3521817	0.018195083	2544.4221
136.80713	0.35360423	0.018327098	2550.6626
137.70801	0.35798392	0.01855284	2559.1143
138.60889	0.35914195	0.018774673	2571.8491
139.50977	0.36414412	0.018985324	2582.4265
140.41064	0.36809558	0.019324917	2599.3801
141.31152	0.36842218	0.019581078	2600.51
142.2124	0.37169382	0.019813238	2608.3169
143.11328	0.37796468	0.0200893	2618.6479
144.01416	0.37472069	0.020306239	2622.29
144.91504	0.38034585	0.020518234	2625.0254
145.81592	0.38308483	0.020816229	2635.4138
146.7168	0.38777372	0.021075318	2646.1221
147.61768	0.38920242	0.021432484	2653.979
148.51855	0.38898832	0.021742169	2654.2483
149.41943	0.39105889	0.02207459	2662.9307
150.32031	0.39676684	0.022296458	2665.1646
151.22119	0.40004346	0.022889145	2683.4316
152.12207	0.40566254	0.023218118	2687.2681
153.02295	0.40643561	0.023622748	2693.6089
153.92383	0.40544906	0.024021359	2694.0725
154.82471	0.40992445	0.024481334	2702.9124
155.72559	0.40824884	0.025000455	2710.4517
156.62646	0.41573796	0.025483521	2715.1919
157.52734	0.42000887	0.026110768	2723.9548
158.42822	0.41913316	0.026605492	2726.5425
159.3291	0.4237892	0.027059123	2725.7668
160.22998	0.42722583	0.027604885	2740.2939
161.13086	0.43085933	0.028266365	2748.5156
162.03174	0.43202701	0.028999923	2749.2366
162.93262	0.43298957	0.029553749	2757.7212
163.8335	0.43709323	0.03020425	2762.5725
164.73438	0.44342294	0.030871814	2771.0186
165.63525	0.44333339	0.031566564	2767.03
166.53613	0.44454467	0.032033302	2772.4055
167.43701	0.44664767	0.032833595	2785.6052
168.33789	0.44773927	0.033394311	2782.9382
169.23877	0.454777	0.034329161	2793.396
170.13965	0.45298791	0.034996599	2787.9785
171.04053	0.46020615	0.035646085	2797.3396
171.94141	0.46062267	0.036233097	2801.1213
172.84229	0.46390843	0.037101686	2804.3359
173.74316	0.4675383	0.037685484	2808.5381
174.64404	0.46987978	0.038464583	2810.6982
175.54492	0.47231016	0.039195992	2813.6235
176.4458	0.47626695	0.040011887	2820.1035
177.34668	0.4764739	0.040781289	2827.8806
178.24756	0.47887251	0.041454066	2823.7173
179.14844	0.48326126	0.042126805	2829.3252
180.04932	0.48706502	0.043033537	2834.429
180.9502	0.4908812	0.04395711	2842.6643
181.85107	0.49091318	0.044544797	2841.6257
182.75195	0.49356404	0.045487635	2846.7339
183.65283	0.49940196	0.046274241	2849.2083
184.55371	0.4995921	0.047033083	2848.3738
185.45459	0.50236237	0.047966264	2852.1624
186.35547	0.50658327	0.04883847	2860.363
187.25635	0.50647509	0.049694318	2867.593
188.15723	0.51131028	0.050429128	2866.5962
189.05811	0.51125741	0.051184032	2866.2424
189.95898	0.5163188	0.052120566	2870.407
190.85986	0.52024198	0.052973047	2884.8357
191.76074	0.51808614	0.053957075	2879.1282
192.66162	0.5252462	0.054859117	2885.635
193.5625	0.52863383	0.055595137	2885.0996
194.46338	0.52854896	0.056320235	2882.7249
195.36426	0.53062576	0.057309587	2890.1458
196.26514	0.53719449	0.058001049	2896.8748
197.16602	0.53599179	0.059214398	2895.8083
198.06689	0.54084152	0.060063351	2904.113
198.96777	0.54045898	0.061052438	2909.1265
199.86865	0.54750878	0.06201461	2910.8542
200.76953	0.5478788	0.063066758	2914.1731
201.67041	0.54992831	0.063940316	2909.415
202.57129	0.55360585	0.064878777	2920.4199
203.47217	0.55559754	0.065919086	2920.874
204.37305	0.55841643	0.066652626	2914.8904
205.27393	0.55918902	0.067691043	2925.1558
206.1748	0.56297749	0.068599127	2927.1726
207.07568	0.56653678	0.06936051	2926.6523
207.97656	0.56953859	0.070259541	2931.1384
208.87744	0.5739302	0.071095534	2932.7339
209.77832	0.57451147	0.072124802	2938.2119
210.6792	0.57672614	0.073127963	2943.9583
211.58008	0.58106506	0.074122377	2944.968
212.48096	0.58041716	0.075092793	2943.0923
213.38184	0.58679634	0.075881422	2944.2764
214.28271	0.58878338	0.076952145	2954.251
215.18359	0.59233367	0.077826753	2952.4336
216.08447	0.59492326	0.078576423	2949.4197
216.98535	0.59512341	0.079275273	2954.0017
217.88623	0.59697545	0.080386929	2969.7156
218.78711	0.59993094	0.081331715	2964.8638
219.68799	0.60552973	0.082284816	2967.7202
220.58887	0.61037558	0.083173946	2968.3994
221.48975	0.61168087	0.083995916	2968.199
222.39063	0.61302561	0.084861405	2971.4424
223.2915	0.61398858	0.085639082	2969.0085
224.19238	0.61895365	0.086831383	2979.947
225.09326	0.62114024	0.087744817	2977.8696
225.99414	0.62461698	0.088734344	2981.1973
226.89502	0.62711596	0.089636877	2983.3123
227.7959	0.62965661	0.090615846	2986.407
228.69678	0.63268161	0.091627397	2988.3105
229.59766	0.63295287	0.092584528	2987.1672
230.49854	0.63723993	0.09341599	2990.0837
231.39941	0.63775444	0.094148166	2988.0352
232.30029	0.64090252	0.09505219	2995.4741
233.20117	0.64645135	0.09649229	3011.8938
234.10205	0.65001452	0.097486943	3007.8313
235.00293	0.64957917	0.098535411	3004.5212
235.90381	0.65358818	0.099455625	3008.2322
236.80469	0.65821159	0.10033948	3011.6514
237.70557	0.65953386	0.10147188	3017.5745
238.60645	0.66235644	0.10255571	3019.4094
239.50732	0.66295159	0.10358462	3017.5969
240.4082	0.6677534	0.10443478	3017.2761
241.30908	0.67014444	0.10536894	3022.136
242.20996	0.67310077	0.10609872	3022.8052
243.11084	0.67423177	0.10690809	3030.2747
244.01172	0.67966354	0.10797185	3031.0132
244.9126	0.68390071	0.109078	3037.5999
245.81348	0.68159097	0.11022696	3038.7837
246.71436	0.68407136	0.11137703	3036.5564
247.61523	0.68953735	0.11232672	3031.4509
248.51611	0.69096398	0.11345843	3038.1929
249.41699	0.69674969	0.11420415	3038.5383
250.31787	0.69861865	0.11496353	3036.9282
251.21875	0.70027477	0.11588322	3040.6414
252.11963	0.70328516	0.1164486	3043.5862
253.02051	0.70663077	0.11750351	3050.2329
253.92139	0.7085793	0.11849821	3055.9253
254.82227	0.7097494	0.11958906	3055.8726
255.72314	0.71135575	0.12061377	3052.0078
256.62402	0.71920806	0.12143981	3058.0994
257.5249	0.7177456	0.12267859	3060.5032
258.42578	0.72082406	0.12343579	3055.6721
259.32666	0.72361571	0.12462776	3065.6841
260.22754	0.7279126	0.12549523	3065.5718
261.12842	0.73063082	0.12655576	3069.3845
262.0293	0.72958857	0.12767005	3070.3364
262.93018	0.73255819	0.12865819	3072.6665
263.83105	0.73780769	0.12974595	3074.2432
264.73193	0.73863566	0.13070923	3075.4993
265.63281	0.7421903	0.13165364	3075.2346
266.53369	0.74419731	0.13251479	3074.3032
267.43457	0.74778777	0.13341288	3082.814
268.33545	0.75200814	0.13458234	3084.3892
269.23633	0.75395989	0.13532759	3082.9097
270.13721	0.75526607	0.13631476	3082.093
271.03809	0.7565521	0.13726074	3083.9028
271.93896	0.76243693	0.13819958	3088.4822
272.83984	0.76469219	0.1394874	3099.6938
273.74072	0.771927	0.14039926	3093.8379
274.6416	0.76861209	0.14130636	3096.7478
275.54248	0.77403033	0.14206576	3096.1077
276.44336	0.77302372	0.14284083	3092.3523
277.34424	0.77776629	0.14391805	3098.1306
278.24512	0.77932858	0.14478278	3100.7583
279.146	0.78529084	0.14595069	3109.5305
280.04688	0.78555065	0.146918	3109.0083
280.94775	0.79091567	0.14784417	3105.8291
281.84863	0.79267752	0.14889391	3111.261
282.74951	0.79413056	0.14955324	3109.3911
283.65039	0.79636383	0.15064545	3117.6047
284.55127	0.79986721	0.15145078	3116.9089
285.45215	0.80202061	0.15230429	3111.9509
286.35303	0.80667835	0.15320566	3117.6902
287.25391	0.81060892	0.15410182	3120.9861
288.15479	0.81192899	0.15493275	3124.2571
289.05566	0.81403911	0.15573175	3121.6001
289.95654	0.81727046	0.15685077	3132.7288
290.85742	0.82050568	0.15767632	3127.1255
291.7583	0.82199746	0.15870614	3132.7991
292.65918	0.82330173	0.1596919	3129.2146
293.56006	0.83005083	0.16050516	3131.7231
294.46094	0.83005857	0.16137877	3133.6594
295.36182	0.8322503	0.16242917	3136.3523
296.2627	0.83591455	0.16329804	3135.5994
297.16357	0.83647186	0.16418308	3141.0493
298.06445	0.84088469	0.16517375	3143.6755
298.96533	0.844401	0.16635929	3148.106
299.86621	0.84386647	0.16729051	3143.511
300.76709	0.84846556	0.1683698	3149.2646
301.66797	0.85077918	0.16937508	3147.7422
302.56885	0.85427827	0.17019297	3150.2024
303.46973	0.85563505	0.1712603	3149.678
304.37061	0.85769826	0.17208219	3150.1257
305.27148	0.86464155	0.17309901	3155.3042
306.17236	0.86650378	0.173904	3157.0195
307.07324	0.86642754	0.17476693	3154.3259
307.97412	0.87124449	0.17577003	3163.9785
308.875	0.87169522	0.17655386	3161.7024
309.77588	0.8753562	0.17771547	3170.4978
310.67676	0.87980312	0.17885621	3178.3716
311.57764	0.88535601	0.17964853	3165.9397
312.47852	0.88113791	0.18052654	3163.4194
313.37939	0.88645768	0.18155515	3171.4309
314.28027	0.89030093	0.18289892	3176.7542
315.18115	0.89187962	0.18351598	3167.4829
316.08203	0.89101148	0.1843196	3172.2876
316.98291	0.89657176	0.1851137	3171.9812
317.88379	0.89916325	0.18604496	3176.9053
318.78467	0.90373242	0.18708621	3183.7339
319.68555	0.90747696	0.1881972	3180.0098
320.58643	0.90747654	0.18929295	3180.6145
321.4873	0.90796113	0.1901038	3178.2178
322.38818	0.91317618	0.19110304	3188.9558
323.28906	0.91452289	0.19198082	3186.9998
324.18994	0.91784436	0.19269583	3180.4773
325.09082	0.92266619	0.19363521	3190.4497
325.9917	0.92463887	0.19452994	3189.7368
326.89258	0.9261778	0.19538374	3194.8298
327.79346	0.92855918	0.19640535	3194.3962
328.69434	0.93130553	0.19745484	3196.9697
329.59521	0.93290079	0.19830006	3192.2739
330.49609	0.93762428	0.19920775	3201.4272
331.39697	0.93915176	0.2000434	3198.231
332.29785	0.94442064	0.20112051	3200.3689
333.19873	0.94377464	0.20190515	3199.5188
334.09961	0.9486323	0.20287845	3209.4067
335.00049	0.95051652	0.20384057	3207.2229
335.90137	0.95684797	0.20470063	3211.9172
336.80225	0.95860714	0.20590343	3217.459
337.70313	0.95937669	0.20690431	3212.2905
338.604	0.96228671	0.20786183	3217.9102
339.50488	0.96177816	0.20870766	3210.0959
340.40576	0.96948487	0.20969321	3220.7407
341.30664	0.96782446	0.21075161	3219.877
342.20752	0.97398776	0.21144292	3215.7683
343.1084	0.97442043	0.21229751	3213.6797
344.00928	0.97828382	0.21311212	3220.821
344.91016	0.98046201	0.2140782	3225.8784
345.81104	0.98445505	0.21516441	3228.5977
346.71191	0.98647135	0.21615526	3233.6753
347.61279	0.98544568	0.21720749	3231.8362
348.51367	0.99091047	0.21815547	3231.2212
349.41455	0.99570692	0.21908072	3232.8501
350.31543	0.99790311	0.21991883	3227.0999
351.21631	1.0000151	0.22071692	3235.5093
352.11719	1.0045583	0.22155564	3231.0105
353.01807	1.0024582	0.22256556	3241.0325
353.91895	1.0087922	0.2235038	3236.5681
354.81982	1.009966	0.22436617	3241.218
355.7207	1.0140554	0.22517793	3241.8535
356.62158	1.014824	0.22622165	3241.9058
357.52246	1.0183711	0.22712798	3241.4309
358.42334	1.0204028	0.22793454	3244.9099
359.32422	1.0247895	0.22896393	3253.6233
360.2251	1.0277575	0.22979331	3248.8452
361.12598	1.0308453	0.23068714	3249.7246
362.02686	1.0308589	0.23156425	3248.6572
362.92773	1.034325	0.2324587	3253.9678
363.82861	1.0355831	0.23365238	3254.5244
364.72949	1.0412825	0.2345957	3255.7046
365.63037	1.0438404	0.23564194	3263.9797
366.53125	1.0449595	0.23654409	3254.1064
367.43213	1.0478194	0.23742804	3258.7397
368.33301	1.0536013	0.23827894	3257.4055
369.23389	1.0517288	0.23909695	3268.5911
370.13477	1.0581204	0.24002188	3270.6785
371.03564	1.0579804	0.24094611	3260.1504
371.93652	1.0610074	0.24176316	3265.6001
372.8374	1.0653039	0.24279226	3269.1953
373.73828	1.0651277	0.2435666	3269.748
374.63916	1.0715108	0.24448065	3272.313
375.54004	1.0731519	0.24543986	3273.8706
376.44092	1.0778567	0.24632753	3274.8235
377.3418	1.0768678	0.24723798	3271.3682
378.24268	1.080917	0.24826097	3283.1313
379.14355	1.0869943	0.24919954	3277.6167
380.04443	1.0876385	0.25018319	3276.7925
380.94531	1.0914041	0.25102231	3282.7708
381.84619	1.0913054	0.25209925	3281.2605
382.74707	1.0938883	0.25300461	3284.7585
383.64795	1.0953844	0.25383395	3283.8677
384.54883	1.0977235	0.25487694	3280.8582
385.44971	1.1049798	0.25583571	3289.5044
386.35059	1.1029209	0.25676996	3286.1899
387.25146	1.1112901	0.25785679	3291.6404
388.15234	1.109642	0.25861904	3287.792
389.05322	1.1142448	0.25944513	3283.2158
389.9541	1.1162733	0.26026842	3291.9502
390.85498	1.1192732	0.26108938	3297.2466
391.75586	1.1212318	0.26203737	3297.0466
392.65674	1.1250393	0.26294687	3297.9783
393.55762	1.1239477	0.26396614	3293.1184
394.4585	1.1317106	0.26475281	3303.3508
395.35938	1.128845	0.26563674	3298.6067
396.26025	1.1329734	0.26652032	3298.2573
397.16113	1.1365895	0.26733452	3302.2793
398.06201	1.1420097	0.26844242	3305.4722
398.96289	1.1438963	0.2693572	3312.5835
399.86377	1.1447912	0.27023411	3302.1797
400.76465	1.1494097	0.27115026	3310.623
401.66553	1.1492728	0.27197072	3311.3398
402.56641	1.1522392	0.27289405	3311.374
403.46729	1.1553998	0.27374762	3312.8833
404.36816	1.1607668	0.27464911	3315.5825
405.26904	1.1615286	0.27559593	3324.363
406.16992	1.1641352	0.27652866	3307.5337
407.0708	1.1681285	0.2773456	3315.5103
407.97168	1.1692748	0.2782208	3320.5623
408.87256	1.1736084	0.27930513	3324.968
409.77344	1.1754405	0.2800242	3317.127
410.67432	1.1768063	0.28082961	3317.219
411.5752	1.1792759	0.28192717	3328.0959
412.47607	1.1829002	0.28305659	3331.0466
413.37695	1.1878878	0.28420556	3329.8103
414.27783	1.1877605	0.28484985	3321.52
415.17871	1.1921422	0.28588885	3333.1702
416.07959	1.1943407	0.28658611	3330.8066
416.98047	1.1941967	0.28776196	3337.0779
417.88135	1.1967449	0.28848645	3328.7188
418.78223	1.2006712	0.28957224	3334.4492
419.68311	1.2053096	0.29065919	3339.2307
420.58398	1.2099807	0.29146147	3339.7512
421.48486	1.2134033	0.29248524	3341.6096
422.38574	1.2151554	0.29328436	3338.3713
423.28662	1.2173089	0.29414171	3342.3293
424.1875	1.2193391	0.29488927	3335.1074
425.08838	1.2222146	0.29590046	3344.4177
425.98926	1.2235421	0.29665005	3341.646
426.89014	1.2258945	0.29777294	3347.6951
427.79102	1.2293864	0.29868773	3346.5327
428.69189	1.2309746	0.29963434	3344.9236
429.59277	1.235393	0.30030578	3340.2954
430.49365	1.2382044	0.30107477	3345.6201
431.39453	1.2393562	0.30185157	3345.0249
432.29541	1.2427723	0.3027271	3352.928
433.19629	1.2436168	0.30369875	3355.1064
434.09717	1.2508744	0.30464205	3352.1316
434.99805	1.2502911	0.30557984	3355.2478
435.89893	1.2546866	0.30642775	3355.4153
436.7998	1.2577119	0.30732471	3360.1482
437.70068	1.2591392	0.3082878	3362.7349
438.60156	1.2605304	0.30931479	3365.2385
439.50244	1.2631567	0.31029543	3363.1465
440.40332	1.2680631	0.31130314	3359.7119
441.3042	1.2705351	0.31190401	3361.3784
442.20508	1.2710451	0.31284088	3362.7822
443.10596	1.274093	0.3135457	3363.4805
444.00684	1.2780174	0.31448376	3370.1675
444.90771	1.2843342	0.31533617	3370.0596
445.80859	1.2845891	0.31619364	3368.2991
446.70947	1.2844958	0.3169575	3368.0217
447.61035	1.2884783	0.31796739	3376.3174
448.51123	1.2917421	0.3190853	3374.2588
449.41211	1.2934988	0.32004738	3378.302
450.31299	1.2952749	0.32108966	3377.7146
451.21387	1.2994307	0.32203496	3379.4731
452.11475	1.3022207	0.32313716	3378.3181
453.01563	1.3068733	0.32413834	3376.9131
453.9165	1.308728	0.32509995	3379.6055
454.81738	1.310248	0.32594803	3383.1543
455.71826	1.3149544	0.32694271	3385.0413
456.61914	1.3211805	0.32806653	3387.8142
457.52002	1.3210251	0.32899609	3387.0767
458.4209	1.3203275	0.32977596	3387.8552
459.32178	1.3228989	0.33061197	3385.5654
460.22266	1.3250494	0.33168125	3388.5957
461.12354	1.3292572	0.33273768	3392.5659
462.02441	1.3300958	0.33367118	3389.4033
462.92529	1.3367523	0.33456117	3387.1208
463.82617	1.3389833	0.33544829	3398.6799
464.72705	1.3409897	0.33633429	3391.8972
465.62793	1.3469882	0.3370105	3392.6458
466.52881	1.3468616	0.33784476	3394.5706
467.42969	1.3494318	0.33883795	3400.053
468.33057	1.3512989	0.3397696	3400.2964
469.23145	1.3564373	0.34054279	3399.1599
470.13232	1.3541408	0.34155312	3400.001
471.0332	1.3598703	0.34241176	3398.4165
471.93408	1.3601794	0.34335539	3401.5156
472.83496	1.3655242	0.34435701	3404.5579
473.73584	1.3671917	0.34519532	3402.7849
474.63672	1.3698128	0.34603444	3402.8604
475.5376	1.3713992	0.34697035	3408.3909
476.43848	1.3761785	0.34817576	3411.9285
477.33936	1.376918	0.34911242	3408.3948
478.24023	1.378628	0.35020301	3411.6287
479.14111	1.3829465	0.35087094	3403.3831
480.04199	1.3835849	0.35193914	3408.7373
480.94287	1.3914194	0.35293138	3417.0269
481.84375	1.3909109	0.35369545	3412.144
482.74463	1.3921328	0.35449189	3417.74
483.64551	1.3976886	0.35533327	3416.0935
484.54639	1.4012667	0.35638568	3416.7532
485.44727	1.4017384	0.35729092	3414.2773
486.34814	1.4050865	0.35815999	3413.7988
487.24902	1.4049401	0.35922554	3422.9653
488.1499	1.4127858	0.36026356	3428.3928
489.05078	1.4115083	0.36131257	3425.4238
489.95166	1.417518	0.36246529	3429.7783
490.85254	1.4164722	0.36341682	3418.4514
491.75342	1.4220092	0.36441076	3428.0889
492.6543	1.4239799	0.3653267	3421.7036
493.55518	1.4278654	0.36612368	3424.3459
494.45605	1.431926	0.36706316	3433.6499
495.35693	1.433246	0.36796379	3426.4285
496.25781	1.4320418	0.36879045	3428.7446
497.15869	1.4357448	0.36982402	3431.8931
498.05957	1.4385749	0.37068284	3432.0999
498.96045	1.4435217	0.37174934	3436.1145
499.86133	1.4483795	0.37280828	3438.262
500.76221	1.4483891	0.37380943	3436.3027
501.66309	1.4505976	0.37474689	3435.6963
502.56396	1.4525907	0.3755354	3435.5923
503.46484	1.457324	0.37628031	3431.7222
504.36572	1.4591222	0.37717599	3444.8289
505.2666	1.4629352	0.37789419	3438.2778
506.16748	1.4660794	0.37895745	3446.4536
507.06836	1.4662118	0.37995464	3443.8679
507.96924	1.47137	0.38076478	3437.7666
508.87012	1.474502	0.38177228	3444.2083
509.771	1.4743272	0.38254052	3439.5388
510.67188	1.4769498	0.38354325	3446.5037
511.57275	1.4822046	0.38454658	3452.8757
512.47363	1.4843053	0.3854897	3446.8699
513.37451	1.4847162	0.3865442	3451.2603
514.27539	1.4892445	0.38731766	3452.198
515.17627	1.4895691	0.38837817	3451.9863
516.07715	1.490649	0.38942486	3450.3699
516.97803	1.4976794	0.39042976	3458.4028
517.87891	1.5024987	0.39147016	3455.0852
518.77979	1.5006204	0.39249435	3460.1553
519.68066	1.5040107	0.39362857	3459.1841
520.58154	1.5089025	0.39462531	3458.9192
521.48242	1.5075722	0.39575788	3455.7136
522.3833	1.5160227	0.39686978	3462.5022
523.28418	1.5182729	0.39785278	3458.3025
524.18506	1.5193144	0.39857244	3458.2002
525.08594	1.5195408	0.39942142	3455.3325
525.98682	1.5238904	0.40012041	3460.9075
526.8877	1.5270698	0.40096429	3462.1804
527.78857	1.5306115	0.40188608	3468.0532
528.68945	1.5326452	0.40293628	3464.1846
529.59033	1.5352824	0.40404296	3468.0178
530.49121	1.5369327	0.40510416	3470.1248
531.39209	1.5390388	0.40599704	3465.9021
532.29297	1.5417534	0.40702888	3472.6614
533.19385	1.5467924	0.4081091	3474.1812
534.09473	1.5487605	0.40932113	3473.5088
534.99561	1.5515984	0.41036144	3470.7705
535.89648	1.5525343	0.41143563	3477.4458
536.79736	1.5604823	0.41245678	3478.1187
537.69824	1.5601116	0.41323486	3473.7031
538.59912	1.5625979	0.41423965	3478.2288
539.5	1.5658634	0.41502029	3473.9082
540.40088	1.5670563	0.41592777	3480.0063
541.30176	1.5715026	0.41680908	3477.5779
542.20264	1.5724051	0.41761667	3477.3079
543.10352	1.5742974	0.41866666	3477.2627
544.00439	1.5782387	0.41958931	3484.2798
544.90527	1.5813659	0.42038298	3478.6992
545.80615	1.5853133	0.42142397	3489.5728
546.70703	1.5844989	0.42219651	3482.0266
547.60791	1.5876023	0.42328474	3484.2686
548.50879	1.5905806	0.42416951	3483.6331
549.40967	1.5959696	0.42523536	3491.6543
550.31055	1.5974559	0.42621773	3488.2661
551.21143	1.5974619	0.42719463	3485.3181
552.1123	1.6035353	0.42831379	3492.6174
553.01318	1.6061218	0.42937922	3491.2637
553.91406	1.6058593	0.43038088	3488.491
554.81494	1.6101367	0.43135828	3491.9734
555.71582	1.614403	0.43244979	3496.9331
556.6167	1.616074	0.43339899	3495.4639
557.51758	1.6159949	0.43453529	3495.7183
558.41846	1.6234683	0.43569931	3495.6697
559.31934	1.6224414	0.43653047	3490.4893
560.22021	1.6286896	0.43753394	3496.0049
561.12109	1.6281731	0.43825102	3487.2639
562.02197	1.6300563	0.43912032	3495.2039
562.92285	1.6368321	0.4402082	3507.3535
563.82373	1.636933	0.44137162	3510.7314
564.72461	1.6405255	0.44251093	3506.8381
565.62549	1.6414021	0.44348955	3499.616
566.52637	1.6469167	0.44452646	3505.8052
567.42725	1.6472185	0.44538668	3499.3931
568.32813	1.6513559	0.44662964	3505.0066
569.229	1.6537273	0.44742829	3499.3467
570.12988	1.6547382	0.44839966	3502.1633
571.03076	1.6590793	0.44921306	3503.9226
571.93164	1.6633818	0.45018977	3504.6426
572.83252	1.6634738	0.45114243	3509.6489
573.7334	1.6685011	0.45229924	3516.8191
574.63428	1.6706045	0.4531813	3507.6262
575.53516	1.6717569	0.45401791	3505.0491
576.43604	1.6739825	0.45488217	3510.1306
577.33691	1.6779444	0.45582473	3511.1948
578.23779	1.6816165	0.45669299	3513.4761
579.13867	1.6833113	0.45776579	3518.667
580.03955	1.689297	0.45897087	3518.4412
580.94043	1.6889051	0.45993587	3515.7441
581.84131	1.6902343	0.46083775	3519.2551
582.74219	1.6923138	0.46200582	3520.4497
583.64307	1.700298	0.46305299	3522.3984
584.54395	1.7007831	0.46416306	3521.7021
585.44482	1.7009687	0.46530044	3523.9121
586.3457	1.7055463	0.46655843	3520.4639
587.24658	1.7092025	0.46763945	3525.0847
588.14746	1.7072759	0.46878582	3524.5171
589.04834	1.7138134	0.4697009	3521.5962
589.94922	1.7150873	0.47074419	3521.8389
590.8501	1.7205982	0.47166753	3527.1343
591.75098	1.7220865	0.47272173	3526.5337
592.65186	1.7257472	0.47375873	3527.7456
593.55273	1.72703	0.47499424	3524.6008
594.45361	1.7287664	0.4758648	3520.2151
595.35449	1.7339213	0.47668308	3524.7178
596.25537	1.7347181	0.47752813	3526.0955
597.15625	1.7362474	0.47827345	3524.1553
598.05713	1.7404364	0.47917649	3529.5337
598.95801	1.7430114	0.48028773	3536.3054
599.85889	1.7467598	0.48162875	3539.866
600.75977	1.7476817	0.48272023	3535.4155
601.66064	1.7521733	0.48397803	3536.3101
602.56152	1.7514136	0.48499805	3528.9822
603.4624	1.7560984	0.48599246	3535.656
604.36328	1.7585819	0.48722237	3540.7295
605.26416	1.7636467	0.48833293	3535.7327
606.16504	1.7642474	0.48957819	3536.8142
607.06592	1.767373	0.49056816	3533.9136
607.9668	1.7701156	0.49152526	3539.0464
608.86768	1.7733994	0.49255103	3549.4126
609.76855	1.7767354	0.49376932	3541.054
610.66943	1.7787578	0.49470198	3538.7881
611.57031	1.7801152	0.49555841	3534.3005
612.47119	1.7848015	0.49666989	3543.5188
613.37207	1.7838264	0.49776167	3535.6682
614.27295	1.7888265	0.49876446	3542.9924
615.17383	1.7910582	0.49987605	3543.7778
616.07471	1.7903457	0.50074559	3540.6172
616.97559	1.7960376	0.50168926	3542.5222
617.87646	1.797693	0.50279653	3547.4666
618.77734	1.8007481	0.5038507	3551.3376
619.67822	1.8053459	0.50498343	3547.1514
620.5791	1.8066008	0.505876	3539.2292
621.47998	1.8099642	0.50670612	3540.9395
622.38086	1.8145894	0.50776452	3556.8118
623.28174	1.8171619	0.50890702	3551.7766
624.18262	1.8171707	0.51024508	3553.5745
625.0835	1.8219553	0.51145262	3551.4636
625.98438	1.8236203	0.51260394	3550.998
626.88525	1.8279375	0.51373607	3557.3921
627.78613	1.8326337	0.51490939	3557.0972
628.68701	1.8318007	0.5157845	3551.125
629.58789	1.8347254	0.51686537	3552.6396
630.48877	1.8383098	0.51801407	3554.1553
631.38965	1.8382336	0.51906675	3556.5493
632.29053	1.8423826	0.52026176	3559.5435
633.19141	1.8428067	0.52121115	3551.4124
634.09229	1.8474797	0.52237564	3553.771
634.99316	1.8510196	0.52339697	3551.4292
635.89404	1.8532118	0.52439332	3558.6523
636.79492	1.8540984	0.525397	3557.2712
637.6958	1.8621924	0.5265457	3558.5776
638.59668	1.8619217	0.52757466	3565.5188
639.49756	1.8629931	0.52877307	3560.7725
640.39844	1.8685215	0.52984333	3563.1138
641.29932	1.8697792	0.53104484	3560.5862
642.2002	1.8711796	0.53229725	3565.7317
643.10107	1.8720057	0.53347862	3562.6958
644.00195	1.8780029	0.53474295	3565.0115
644.90283	1.8830872	0.53596306	3567.5708
645.80371	1.8810295	0.53675711	3555.7703
646.70459	1.8859444	0.53788882	3562.4233
647.60547	1.8882382	0.53886586	3569.2212
648.50635	1.8920393	0.54000628	3567.2952
649.40723	1.8938838	0.54108548	3568.8315
650.30811	1.8966647	0.54246169	3571.5718
651.20898	1.8991563	0.54358858	3570.2378
652.10986	1.902606	0.54470873	3568.2341
653.01074	1.9040803	0.54588956	3571.1274
653.91162	1.9069583	0.54712141	3566.7515
654.8125	1.9102205	0.54820645	3575.0881
655.71338	1.9152032	0.54931724	3571.5637
656.61426	1.9149196	0.5501554	3566.0535
657.51514	1.9189572	0.55123729	3573.5029
658.41602	1.9206789	0.55245644	3579.1826
659.31689	1.9231629	0.5533132	3567.8604
660.21777	1.9277356	0.55460101	3577.0317
661.11865	1.9321967	0.55597663	3574.0676
662.01953	1.9300346	0.55706787	3574.9441
662.92041	1.935791	0.55838323	3576.3379
663.82129	1.9391875	0.55959845	3581.5212
664.72217	1.9397657	0.56080657	3574.8342
665.62305	1.941422	0.56210792	3581.167
666.52393	1.9474506	0.5633086	3583.9185
667.4248	1.9508281	0.5643785	3576.918
668.32568	1.9514279	0.5656144	3574.7952
669.22656	1.9569018	0.56702042	3590.6016
670.12744	1.9577223	0.56828785	3581.2126
671.02832	1.9611878	0.56932467	3579.3354
671.9292	1.9579865	0.5702098	3576.0654
672.83008	1.9645936	0.57133675	3582.9688
673.73096	1.9671384	0.57257634	3586.593
674.63184	1.9692838	0.57406908	3585.2844
675.53271	1.9712409	0.57504624	3582.2676
676.43359	1.977532	0.57626134	3587.5759
677.33447	1.9806277	0.57724983	3584.0469
678.23535	1.9835873	0.57851136	3585.783
679.13623	1.9807768	0.57955533	3582.6096
680.03711	1.9874333	0.5807358	3583.2278
680.93799	1.9873048	0.58170718	3581.3733
681.83887	1.9902422	0.58265615	3585.0781
682.73975	1.9947113	0.5837245	3586.4028
683.64063	1.9964858	0.58501858	3592.1702
684.5415	1.9984143	0.58607292	3587.7905
685.44238	2.0061729	0.58746928	3594.7244
686.34326	2.0051551	0.58870167	3592.9348
687.24414	2.0072446	0.59006006	3584.625
688.14502	2.0126112	0.59117049	3587.5244
689.0459	2.0119648	0.59233385	3590.438
689.94678	2.018369	0.59350604	3593.4055
690.84766	2.017698	0.59476042	3592.3374
691.74854	2.0188022	0.59593868	3587.5088
692.64941	2.0258305	0.59712738	3590.907
693.55029	2.0253394	0.59836054	3594.8645
694.45117	2.0295637	0.59979081	3598.1028
695.35205	2.0341809	0.60126519	3599.7395
696.25293	2.0343826	0.60243088	3590.7468
697.15381	2.0390861	0.60354865	3592.4771
698.05469	2.0405612	0.60482281	3598.2622
698.95557	2.0447631	0.60588598	3591.8049
699.85645	2.0454688	0.60723555	3595.4087
700.75732	2.0485303	0.608437	3597.5281
701.6582	2.05039	0.60975534	3599.3918
702.55908	2.0535185	0.61076075	3595.3184
703.45996	2.0558732	0.61185646	3593.521
704.36084	2.0606003	0.61306775	3595.7935
705.26172	2.0618098	0.6142804	3596.2888
706.1626	2.0640652	0.61549383	3601.4099
707.06348	2.0659058	0.61687493	3600.1924
707.96436	2.069494	0.61808908	3597.6147
708.86523	2.071305	0.61936086	3597.8362
709.76611	2.0757918	0.62068731	3597.374
710.66699	2.0759494	0.6219216	3599.4163
711.56787	2.0796556	0.6231696	3597.9121
712.46875	2.0844898	0.62443668	3600.1335
713.36963	2.0860913	0.62580389	3596.6523
714.27051	2.0914142	0.62708807	3599.9841
715.17139	2.0916636	0.62810969	3601.2148
716.07227	2.0942278	0.62929666	3603.3831
716.97314	2.0972919	0.63020116	3598.937
717.87402	2.100455	0.6312573	3600.7668
718.7749	2.101732	0.63254297	3602.6758
719.67578	2.1040766	0.63373882	3600.8975
720.57666	2.1064796	0.63498569	3607.8279
721.47754	2.1102347	0.63632929	3607.7271
722.37842	2.1153665	0.63791144	3608.7583
723.2793	2.1179717	0.63924658	3605.0313
724.18018	2.1183906	0.64084005	3615.1021
725.08105	2.1213346	0.64241743	3610.1294
725.98193	2.1272295	0.64365816	3606.2588
726.88281	2.1252394	0.6448341	3605.0442
727.78369	2.1290839	0.64607102	3605.0039
728.68457	2.1330688	0.64728236	3602.9592
729.58545	2.1345184	0.64865297	3609.7361
730.48633	2.1371024	0.64989311	3603.7095
731.38721	2.1389451	0.65143871	3609.8301
732.28809	2.143573	0.65258592	3603.553
733.18896	2.1464822	0.65398037	3610.2078
734.08984	2.1507597	0.65534723	3613.7114
734.99072	2.1523039	0.65687662	3615.7578
735.8916	2.1543643	0.65826094	3611.8723
736.79248	2.1565745	0.65996772	3612.0422
737.69336	2.1586192	0.66132617	3610.6252
738.59424	2.1603029	0.66269618	3608.7788
739.49512	2.164669	0.66407472	3613.5813
740.396	2.1661937	0.66524649	3613.5784
741.29688	2.1710682	0.66664338	3617.136
742.19775	2.174335	0.66804028	3613.457
743.09863	2.1757171	0.66946638	3612.4004
743.99951	2.1817791	0.67064714	3610.5498
744.90039	2.1814637	0.67188752	3614.3789
745.80127	2.1824195	0.67317361	3609.0693
746.70215	2.1857748	0.67458242	3613.3052
747.60303	2.186393	0.67585373	3614.2729
748.50391	2.192193	0.67741203	3614.4373
749.40479	2.1930656	0.67870873	3608.9634
750.30566	2.1982131	0.68027997	3622.9885
751.20654	2.198916	0.68180871	3612.6829
752.10742	2.2026775	0.68318731	3615.5881
753.0083	2.2025537	0.68452084	3610.6475
753.90918	2.2061758	0.68578726	3610.7556
754.81006	2.2074773	0.68686092	3607.2017
755.71094	2.2140508	0.68810421	3613.5732
756.61182	2.2170756	0.68961954	3625.1074
757.5127	2.2185326	0.69133461	3622.0415
758.41357	2.2248206	0.69266194	3616.3523
759.31445	2.2281444	0.69415015	3618.3181
760.21533	2.2250719	0.69558066	3613.3889
761.11621	2.2287357	0.69700122	3616.9775
762.01709	2.2320981	0.69831157	3616.395
762.91797	2.2336094	0.69984949	3617.2883
763.81885	2.2392671	0.70125043	3618.447
764.71973	2.238796	0.70283598	3622.4846
765.62061	2.2465854	0.70433128	3617.231
766.52148	2.2458127	0.70568341	3612.6946
767.42236	2.2469926	0.70718491	3620.6584
768.32324	2.2520258	0.70875573	3619.8904
769.22412	2.2542892	0.7103278	3616.2161
770.125	2.2569392	0.71204072	3626.3303
771.02588	2.2596638	0.71359026	3617.9268
771.92676	2.2625251	0.71505213	3618.6411
772.82764	2.2675395	0.71637958	3616.5703
773.72852	2.2684402	0.71771771	3619.1206
774.62939	2.2710495	0.71903008	3615.9712
775.53027	2.2703912	0.72057408	3620.5349
776.43115	2.2726014	0.72210115	3619.7715
777.33203	2.2765503	0.7236675	3622.6521
778.23291	2.2808735	0.72529584	3621.3113
779.13379	2.2839253	0.72698605	3624.4875
780.03467	2.2874022	0.72857511	3619.5979
780.93555	2.2898455	0.72988266	3616.0234
781.83643	2.2903242	0.73127979	3618.9675
782.7373	2.2949667	0.73276693	3617.2175
783.63818	2.2974942	0.73430765	3619.968
784.53906	2.2999616	0.73607606	3622.4158
785.43994	2.3049574	0.7376135	3625.3203
786.34082	2.3036826	0.73935169	3619.8503
787.2417	2.3042264	0.74073786	3611.8315
788.14258	2.3129902	0.74210632	3614.1448
789.04346	2.3114066	0.74330187	3611.6831
789.94434	2.315712	0.74478406	3619.9639
790.84521	2.3187644	0.74633926	3621.8235
791.74609	2.3220549	0.74852991	3633.3948
792.64697	2.3243661	0.75034845	3620.3481
793.54785	2.3276827	0.75206816	3618.5063
794.44873	2.3333755	0.75370586	3625.886
795.34961	2.3325813	0.75499123	3614.075
796.25049	2.3336551	0.75642949	3616.4814
797.15137	2.333919	0.75791156	3618.7302
798.05225	2.3378828	0.75948572	3624.7288
798.95313	2.3450487	0.76118439	3627.9556
799.854	2.3471403	0.76278019	3625.1326
800.75488	2.3459003	0.76453578	3622.5859
801.65576	2.3512559	0.76595557	3617.4165
802.55664	2.3519585	0.76777309	3621.1931
803.45752	2.3559816	0.76955414	3619.7102
804.3584	2.3606284	0.77093542	3620.301
805.25928	2.3638551	0.77256548	3620.9971
806.16016	2.3653057	0.77435327	3621.4404
807.06104	2.3676703	0.77633792	3623.6423
807.96191	2.3674753	0.77813888	3616.7078
808.86279	2.3716905	0.77990848	3615.917
809.76367	2.3750234	0.78156728	3613.6177
810.66455	2.3774726	0.78338045	3617.0012
811.56543	2.3792908	0.78506005	3620.2227
812.46631	2.3836844	0.78688818	3623.1372
813.36719	2.3874474	0.78860736	3624.563
814.26807	2.3891425	0.79080147	3625.21
815.16895	2.3928905	0.79230225	3612.5923
816.06982	2.3957829	0.79391807	3619.0957
816.9707	2.3993664	0.79551148	3620.0872
817.87158	2.4012854	0.79730272	3624.2515
818.77246	2.4030166	0.79918903	3618.1086
819.67334	2.4045677	0.80117488	3622.4543
820.57422	2.4046931	0.80278558	3617.3752
821.4751	2.4117315	0.80439913	3613.0024
822.37598	2.4141099	0.80592692	3618.1519
823.27686	2.4161603	0.80769283	3627.6023
824.17773	2.4185748	0.80944717	3624.2419
825.07861	2.4215717	0.81131244	3623.8613
825.97949	2.4225578	0.81339848	3620.7871
826.88037	2.4265325	0.81501675	3612.687
827.78125	2.4292803	0.8167119	3621.4487
828.68213	2.433347	0.81852502	3622.9524
829.58301	2.4351487	0.82061911	3618.9451
830.48389	2.4400835	0.82241577	3616.396
831.38477	2.440665	0.82398307	3613.7932
832.28564	2.4445875	0.82548785	3619.8254
833.18652	2.4483118	0.82746667	3622.1763
834.0874	2.4501333	0.82938403	3619.0452
834.98828	2.451966	0.8314485	3618.6311
835.88916	2.4562073	0.83340657	3622.6296
836.79004	2.4580717	0.83551145	3622.3877
837.69092	2.458864	0.8373127	3613.5891
838.5918	2.4614534	0.83922791	3614.4846
839.49268	2.4647031	0.84111428	3618.4553
840.39355	2.4672501	0.84321576	3617.4021
841.29443	2.4700441	0.84562212	3622.2729
842.19531	2.4730711	0.8477301	3615.1711
843.09619	2.4753416	0.84985119	3617.8916
843.99707	2.4777777	0.85185272	3611.6897
844.89795	2.480356	0.85404629	3613.6279
845.79883	2.4822049	0.85628688	3615.8816
846.69971	2.4860647	0.85818058	3609.3999
847.60059	2.4911315	0.86008054	3610.26
848.50146	2.4904511	0.86172307	3607.5886
849.40234	2.4949408	0.86369324	3614.2473
850.30322	2.4989288	0.86577249	3609.9932
851.2041	2.4982908	0.86763924	3609.2478
852.10498	2.5029025	0.86947465	3613.0071
853.00586	2.5068443	0.8710646	3602.6924
853.90674	2.5097106	0.87269181	3609.4668
854.80762	2.5115914	0.87475431	3615.0955
855.7085	2.5113907	0.87722933	3611.9473
856.60938	2.5150406	0.87980205	3611.311
857.51025	2.5161216	0.88232118	3611.0107
858.41113	2.5211537	0.88440967	3607.8452
859.31201	2.525717	0.88651997	3611.5422
860.21289	2.5287559	0.88804889	3603.2141
861.11377	2.5272243	0.88966018	3598.9976
862.01465	2.5325694	0.89138132	3602.4404
862.91553	2.5356135	0.8932516	3605.9453
863.81641	2.5378301	0.89542085	3604.7019
864.71729	2.5432615	0.897515	3605.4316
865.61816	2.5448	0.8996284	3606.1316
866.51904	2.5469022	0.90198576	3607.8506
867.41992	2.5478914	0.90412974	3598.6357
868.3208	2.5512688	0.90635502	3603.0872
869.22168	2.5537162	0.90868831	3605.2588
870.12256	2.5561202	0.91091275	3600.5222
871.02344	2.5606205	0.91344792	3599.4866
871.92432	2.5624835	0.91542298	3596.532
872.8252	2.5653923	0.91754782	3597.9641
873.72607	2.5658703	0.92015171	3603.28
874.62695	2.5695655	0.9228	3598.1021
875.52783	2.5730941	0.92519772	3594.5825
876.42871	2.574435	0.927616	3596.4211
877.32959	2.5776398	0.92999017	3595.5645
878.23047	2.5790534	0.93236989	3599.8762
879.13135	2.5828407	0.93498743	3597.3643
880.03223	2.5854874	0.93730599	3593.2222
880.93311	2.5901837	0.93952799	3589.1577
881.83398	2.5904512	0.94165242	3592.2141
882.73486	2.5946736	0.94386983	3592.8774
883.63574	2.5970361	0.94624984	3592.0088
884.53662	2.6015563	0.94859457	3589.4539
885.4375	2.6003275	0.95105553	3589.1047
886.33838	2.6059201	0.95351529	3589.7307
887.23926	2.6077061	0.95605469	3586.7109
888.14014	2.6108508	0.95829171	3585.97
889.04102	2.6168327	0.96069998	3586.6843
889.94189	2.6150806	0.96283001	3587.2385
890.84277	2.6193349	0.96500611	3588.5593
891.74365	2.6190712	0.96734667	3585.2053
892.64453	2.6257303	0.97001821	3584.5698
893.54541	2.6271589	0.97274989	3582.4456
894.44629	2.6303387	0.97540647	3586.0967
895.34717	2.6315579	0.97766757	3576.7866
896.24805	2.6363854	0.97994077	3579.2095
897.14893	2.6358831	0.9822219	3581.0884
898.0498	2.6396971	0.98437583	3573.5669
898.95068	2.6434405	0.98686802	3581.656
899.85156	2.6448147	0.98907357	3574.3057
900.75244	2.6483879	0.99160451	3575.9038
901.65332	2.6520224	0.99397165	3572.29
902.5542	2.6542559	0.99646455	3573.6013
903.45508	2.6582682	0.99886614	3575.2859
904.35596	2.6602349	1.0016415	3568.8633
905.25684	2.6617963	1.0038694	3564.2722
906.15771	2.6656787	1.0061207	3567.4519
907.05859	2.6654613	1.0085289	3568.3794
907.95947	2.6714108	1.011124	3567.7246
908.86035	2.6729214	1.0141833	3567.7666
909.76123	2.6741393	1.0171051	3565.5293
910.66211	2.6767318	1.0195819	3559.3611
911.56299	2.6845479	1.0218939	3558.8804
912.46387	2.6827226	1.0242816	3558.8484
913.36475	2.6873472	1.027071	3563.6899
914.26563	2.690975	1.0300626	3563.2993
915.1665	2.6918755	1.032866	3558.1885
916.06738	2.6929395	1.0358542	3551.9028
916.96826	2.696399	1.0383986	3549.8889
917.86914	2.7022836	1.0409794	3548.1111
918.77002	2.702486	1.0428506	3539.3057
919.6709	2.7064683	1.0451736	3550.147
920.57178	2.7070389	1.0481125	3550.542
921.47266	2.7114146	1.050965	3541.1743
922.37354	2.7130551	1.053244	3541.5095
923.27441	2.7161145	1.0558847	3542.5249
924.17529	2.7219522	1.0580914	3545.2664
925.07617	2.7211237	1.0605037	3539.7813
925.97705	2.7249551	1.0631479	3543.1135
926.87793	2.7275133	1.0655226	3536.447
927.77881	2.7298186	1.0682088	3537.6143
928.67969	2.7345066	1.0709105	3532.9727
929.58057	2.736099	1.0740354	3535.8972
930.48145	2.7390246	1.0765096	3524.2498
931.38232	2.7423494	1.0789441	3528.8357
932.2832	2.741122	1.0814972	3527.614
933.18408	2.7461693	1.0840694	3523.448
934.08496	2.7483449	1.08661	3520.3955
934.98584	2.7504218	1.0892831	3519.7405
935.88672	2.7530203	1.0923487	3518.1069
936.7876	2.7582767	1.0955329	3524.3037
937.68848	2.7606723	1.0983075	3518.9771
938.58936	2.7623739	1.1009446	3516.6057
939.49023	2.764703	1.1036407	3513.043
940.39111	2.7662518	1.106086	3504.0703
941.29199	2.7688179	1.1087168	3504.5847
942.19287	2.7695162	1.1115707	3512.1108
943.09375	2.7751827	1.1146547	3507.5796
943.99463	2.7774022	1.1178678	3510.947
944.89551	2.7802429	1.1212958	3494.7222
945.79639	2.7840347	1.1240026	3497.3665
946.69727	2.7860055	1.1265676	3500.7407
947.59814	2.7926502	1.1290241	3493.2871
948.49902	2.7907293	1.1311723	3491.5645
949.3999	2.7968771	1.1336496	3492.3179
950.30078	2.7957985	1.1366396	3490.5669
951.20166	2.8001406	1.13984	3488.7214
952.10254	2.8049006	1.1426319	3485.916
953.00342	2.8061359	1.1453718	3483.1182
953.9043	2.8074942	1.1478744	3482.4561
954.80518	2.8097394	1.1506647	3477.6267
955.70605	2.8136597	1.1531206	3480.6338
956.60693	2.8133759	1.1557058	3480.5959
957.50781	2.8173018	1.1590163	3478.6558
958.40869	2.8228538	1.1619891	3471.738
959.30957	2.8261228	1.1651279	3476.7861
960.21045	2.8277485	1.1678089	3462.7783
961.11133	2.8319812	1.1708833	3467.616
962.01221	2.8333507	1.1735952	3460.9966
962.91309	2.8340182	1.1760389	3458.7339
963.81396	2.8387415	1.1788359	3454.5466
964.71484	2.8391409	1.1817504	3456.071
965.61572	2.8422034	1.1848193	3453.2068
966.5166	2.845449	1.1877104	3452.8816
967.41748	2.8517897	1.1909417	3447.4255
968.31836	2.848995	1.1937531	3438.0015
969.21924	2.8556025	1.1962584	3437.3833
970.12012	2.8569734	1.1989889	3436.6226
971.021	2.8595526	1.2018582	3433.8992
971.92188	2.862422	1.2041843	3430.1543
972.82275	2.8656671	1.2068318	3427.2366
973.72363	2.8665135	1.209552	3432.6721
974.62451	2.8706098	1.2119277	3428.0596
975.52539	2.8710926	1.215253	3427.9092
976.42627	2.8763742	1.2185155	3421.3931
977.32715	2.8769393	1.2215334	3417.6572
978.22803	2.878562	1.2244155	3417.4485
979.12891	2.8832517	1.2274638	3410.2629
980.02979	2.8853748	1.2301015	3406.7219
980.93066	2.8901567	1.232626	3406.3691
981.83154	2.89256	1.2353308	3405.043
982.73242	2.8956604	1.2382876	3409.1033
983.6333	2.8972185	1.2417644	3399.6582
984.53418	2.9009268	1.2452487	3394.9468
985.43506	2.9026015	1.248477	3397.4663
986.33594	2.9067981	1.2520324	3390.0632
987.23682	2.9086893	1.2549828	3384.2197
988.1377	2.9090018	1.257673	3380.397
989.03857	2.9139383	1.260453	3383.7505
989.93945	2.9160435	1.2635273	3372.1738
990.84033	2.9183536	1.2661909	3371.2161
991.74121	2.9201868	1.2692462	3370.2949
992.64209	2.9230642	1.2720901	3372.3306
993.54297	2.9290767	1.2752258	3366.7129
994.44385	2.9292905	1.2780453	3357.8477
995.34473	2.9322951	1.2808355	3354.8962
996.24561	2.9352028	1.2835878	3354.6494
997.14648	2.9385786	1.2865996	3355.6243
998.04736	2.9423585	1.2897555	3352.0815
998.94824	2.942801	1.292678	3346.4744
999.84912	2.9470303	1.295709	3338.019
1000.75	2.9497106	1.2983335	3337.2249
1001.6509	2.9523604	1.301282	3337.4746
1002.5518	2.9545534	1.3040336	3334.689
1003.4526	2.9581165	1.3064971	3330.281
1004.3535	2.9598031	1.3093448	3326.9573
1005.2544	2.964215	1.3123939	3324.5901
1006.1553	2.9669065	1.3154994	3318.2314
1007.0562	2.96895	1.3183759	3312.8899
1007.957	2.9729836	1.3208435	3311.3726
1008.8579	2.9747651	1.3234527	3311.6304
1009.7588	2.9763584	1.326605	3304.8594
1010.6597	2.9801686	1.3300643	3302.1165
1011.5605	2.979913	1.333176	3296.0996
1012.4614	2.9846997	1.3364525	3291.2556
1013.3623	2.9839611	1.3387736	3281.6245
1014.2632	2.9892623	1.3407803	3275.7251
1015.1641	2.9938438	1.3428153	3281.646
1016.0649	2.9956493	1.3449707	3279.1274
1016.9658	3.0001063	1.3476532	3277.5688
1017.8667	2.9981518	1.3504611	3276.009
1018.7676	3.0033097	1.3530544	3267.2227
1019.6685	3.0060456	1.3558235	3270.8953
1020.5693	3.0081723	1.3588428	3261.6614
1021.4702	3.0115409	1.3621371	3261.9131
1022.3711	3.0165813	1.3652606	3257.3975
1023.272	3.0155253	1.3683194	3249.2532
1024.1729	3.0186603	1.3711956	3243.4087
1025.0737	3.0206723	1.3741003	3246.1775
1025.9746	3.0251231	1.3768439	3238.3704
1026.8755	3.0276642	1.3798559	3238.1155
1027.7764	3.0284967	1.3832066	3228.5564
1028.6772	3.0314922	1.3872348	3230.2266
1029.5781	3.0373251	1.3904679	3219.666
1030.479	3.0378199	1.3936675	3217.9832
1031.3799	3.0425355	1.3968025	3211.7134
1032.2808	3.0447614	1.3998479	3207.2456
1033.1816	3.0471871	1.4023709	3201.0764
1034.0825	3.0496442	1.4050701	3195.8838
1034.9834	3.0501404	1.4078379	3191.8196
1035.8843	3.0547903	1.4108696	3193.6912
1036.7852	3.0555837	1.4141096	3188.5791
1037.686	3.0606129	1.4171921	3187.396
1038.5869	3.0628107	1.4201725	3176.4966
1039.4878	3.064219	1.4235673	3174.6802
1040.3887	3.0693915	1.4270687	3169.1936
1041.2896	3.0727684	1.4296387	3161.04
1042.1904	3.0739694	1.4323566	3158.7751
1043.0913	3.0767798	1.4356018	3154.1624
1043.9922	3.0778842	1.4388063	3149.4946
1044.8931	3.0812225	1.4425102	3141.0591
1045.7939	3.0870326	1.4457827	3144.282
1046.6948	3.0845819	1.449219	3130.1736
1047.5957	3.0910003	1.4520763	3121.5083
1048.4966	3.0911577	1.4548081	3117.0454
1049.3975	3.0965035	1.4576186	3114.449
1050.2983	3.0973291	1.460647	3114.7229
1051.1992	3.098772	1.4638555	3107.9475
1052.1001	3.1049206	1.4670916	3105.8706
1053.001	3.1055505	1.4706131	3099.3342
1053.9019	3.1092095	1.4741359	3089.3237
1054.8027	3.1152024	1.4774569	3090.6519
1055.7036	3.1140683	1.4806194	3076.6963
1056.6045	3.116358	1.483834	3071.5881
1057.5054	3.1207092	1.4870636	3066.5452
1058.4063	3.1202126	1.4903617	3066.0701
1059.3071	3.1242347	1.494148	3051.1199
1060.208	3.1267841	1.4970887	3042.4626
1061.1089	3.1296735	1.4999546	3045.2976
1062.0098	3.1320703	1.5032071	3038.4412
1062.9106	3.134937	1.5060439	3028.9907
1063.8115	3.1393471	1.5088887	3029.0781
1064.7124	3.1405473	1.5122479	3023.2576
1065.6133	3.1447668	1.5151225	3016.4131
1066.5142	3.1491506	1.5178199	3010.6162
1067.415	3.1509175	1.5206615	3008.2942
1068.3159	3.1516082	1.5236253	3002.3049
1069.2168	3.155287	1.5267222	2999.9224
1070.1177	3.157934	1.5306864	2990.7625
1071.0186	3.1572628	1.5344782	2976.2268
1071.9194	3.1628773	1.5377954	2968.4663
1072.8203	3.1642613	1.541144	2963.5862
1073.7212	3.1667988	1.5440829	2956.1934
1074.6221	3.171298	1.5468444	2952.9436
1075.5229	3.1688023	1.5495687	2946.251
1076.4238	3.1759377	1.5527328	2944.9329
1077.3247	3.178385	1.5563014	2932.2019
1078.2256	3.1836333	1.5596573	2924.0884
1079.1265	3.183748	1.5631037	2919.7571
1080.0273	3.1884408	1.5666996	2915.1343
1080.9282	3.1888347	1.5708319	2913.9836
1081.8291	3.1928685	1.5745059	2895.4856
1082.73	3.1936443	1.5772576	2884.2893
1083.6309	3.1978498	1.5801371	2882.6838
1084.5317	3.1987677	1.5830643	2877.3652
1085.4326	3.2050204	1.5864826	2871.6543
1086.3335	3.2069154	1.5896914	2861.2656
1087.2344	3.2101157	1.5930105	2859.4868
1088.1353	3.2101965	1.5964464	2851.0508
1089.0361	3.2157199	1.5997205	2839.1538
1089.937	3.2197132	1.6027129	2834.1121
1090.8379	3.2227671	1.6058824	2828.2412
1091.7388	3.2225885	1.6090759	2819.0583
1092.6396	3.2269876	1.6125585	2813.4231
1093.5405	3.2266853	1.6163921	2802.5193
1094.4414	3.2289095	1.6200362	2791.4224
1095.3423	3.2334356	1.6233778	2776.8723
1096.2432	3.2363133	1.6271316	2778.8142
1097.144	3.2394867	1.6318501	2768.7598
1098.0449	3.24296	1.6355557	2752.6919
1098.9458	3.243047	1.6391203	2734.7449
1099.8467	3.2444706	1.6420096	2726.9609
1100.7476	3.2479057	1.6450522	2725.5891
1101.6484	3.2523329	1.6485128	2721.6978
1102.5493	3.2537937	1.6526903	2707.1938
1103.4502	3.2563026	1.6566855	2689.7153
1104.3511	3.2585456	1.6598185	2672.6851
1105.252	3.2661827	1.663541	2671.7175
1106.1528	3.2647388	1.6673508	2653.8225
1107.0537	3.2680061	1.67162	2650.9348
1107.9546	3.2707176	1.6756656	2627.8464
1108.8555	3.2715235	1.6790919	2614.4063
1109.7563	3.2764511	1.6826839	2600.7393
1110.6572	3.2772191	1.687521	2590.135
1111.5581	3.2836473	1.6914569	2570.05
1112.459	3.2874768	1.6979641	2543.8196
1113.3599	3.2886696	1.7039005	2508.4951
1114.2607	3.293124	1.7102821	2469.7871
1115.1616	3.2936676	1.7168511	2432.9302
1115.562	3.2992749	1.7215136	2398.8176