File: datasets/am_bench_2022/raw_data/60-X.12-3/specimen.dat
MTS793|MPT|ENU|1|2|.|/|:|1|0|0|A

Operator Information						Time:	26.494629	Sec	11/1/2021 9:58:00 AM
Operator	Nick Derimow
Project	AM Bench 2022 mini-tensile challenge
Specimen ID	60-X.12-3
Material	PBF-L Inconel 625
Specimen Width	2.55	mm
Specimen Thickness	1.52	mm
Notes
Operator Information End

Data Acquisition						Time:	1027.4888	Sec	11/1/2021 10:14:41 AM
Time	Axial Displacement	Axial Extensometer	Axial Force
Sec	mm	mm	N
26.608643	1.2953633e-05	0.00019720956	58.652481
27.509521	0.0023870252	0.00014963798	71.323669
28.4104	0.0079935594	0.00013092323	83.92025
29.311279	0.0070836386	0.00023262292	94.337723
30.212158	0.012224148	0.00027849289	109.85292
31.113037	0.011589396	0.00025709817	123.1439
32.013916	0.016983867	0.00035660449	137.90514
32.914795	0.01969268	0.00033096035	148.49963
33.815674	0.024966778	0.00040187206	161.40538
34.716553	0.024431193	0.00061339128	178.82262
35.617432	0.027508399	0.0005870146	187.94484
36.518311	0.029204281	0.00056123931	205.93204
37.419189	0.031087384	0.00070525927	222.45694
38.320068	0.034948912	0.00075807603	237.42636
39.220947	0.038233928	0.00083061872	252.79939
40.121826	0.042009607	0.00093993009	277.58087
41.022705	0.041720096	0.00092881272	292.02863
41.923584	0.048270974	0.0009936525	304.79626
42.824463	0.049683698	0.0011347302	333.53427
43.725342	0.051062614	0.0012118706	349.03528
44.626221	0.053496052	0.0011569363	365.16666
45.5271	0.057543211	0.0013155208	379.88074
46.427979	0.059628747	0.0013164264	401.60358
47.328857	0.06330654	0.0013811709	422.13068
48.229736	0.06467972	0.0014189641	441.08154
49.130615	0.068423025	0.0016247299	459.40231
50.031494	0.073074356	0.0017106808	480.34827
50.932373	0.074478678	0.0018731449	505.63501
51.833252	0.074584812	0.0019399342	528.14886
52.734131	0.076282538	0.0020242583	551.72211
53.63501	0.079344638	0.0020896101	568.35413
54.535889	0.080310442	0.0021930013	596.70227
55.436768	0.086360566	0.0023104672	613.06885
56.337646	0.088512123	0.0023652059	632.00958
57.238525	0.09078908	0.0024387403	662.66327
58.139404	0.093559563	0.0025269652	685.04724
59.040283	0.09666422	0.002686979	707.45923
59.941162	0.097134858	0.0027875181	731.83655
60.842041	0.10186041	0.0028351007	753.94055
61.74292	0.10499811	0.0029514206	778.55542
62.643799	0.10791551	0.0029336165	800.15302
63.544678	0.11167131	0.0032211358	835.72729
64.445557	0.11225341	0.0032649334	854.69647
65.346436	0.11695662	0.0034633519	887.88354
66.247314	0.12111443	0.0035067098	910.00568
67.148193	0.1236122	0.0035364765	930.66638
68.049072	0.12500976	0.0036524141	946.90857
68.949951	0.12827095	0.0037317888	975.10785
69.85083	0.1301326	0.0039698691	1006.9974
70.751709	0.13224851	0.004035179	1036.4036
71.652588	0.13009633	0.0041299034	1054.2384
72.553467	0.13625386	0.0042761862	1086.875
73.454346	0.13854326	0.0044254623	1109.5576
74.355225	0.14371692	0.0045252321	1142.5598
75.256104	0.14598793	0.0047043818	1175.8842
76.156982	0.14632334	0.0047615995	1190.0182
77.057861	0.14986093	0.0048367116	1218.9727
77.95874	0.15284799	0.0050709122	1242.4091
78.859619	0.15710168	0.0050963382	1268.9929
79.760498	0.15929279	0.0051967376	1291.2491
80.661377	0.16043377	0.005342836	1318.916
81.562256	0.16458707	0.0054105064	1341.191
82.463135	0.16896471	0.0054873643	1359.3594
83.364014	0.16709672	0.0055682664	1387.2012
84.264893	0.172353	0.0056418376	1410.8159
85.165771	0.17644666	0.0057255919	1433.4966
86.06665	0.17816503	0.0059433971	1461.3008
86.967529	0.1808843	0.0060632154	1489.25
87.868408	0.18083164	0.006105165	1500.9835
88.769287	0.1854634	0.0061690449	1525.0889
89.670166	0.18831851	0.0063093314	1552.4698
90.571045	0.19195937	0.0064609456	1575.5348
91.471924	0.19224642	0.0066643348	1604.3467
92.372803	0.19402237	0.006660528	1626.4423
93.273682	0.19811711	0.0068006138	1654.4098
94.174561	0.20407811	0.0068708411	1685.5325
95.075439	0.20918599	0.0069678696	1699.2877
95.976318	0.20801975	0.0071077128	1721.639
96.877197	0.20839019	0.0072062816	1747.391
97.778076	0.2147436	0.0073509901	1767.8801
98.678955	0.21230647	0.007445374	1786.2529
99.579834	0.22083491	0.007505653	1821.4104
100.48071	0.22299343	0.007632175	1842.6326
101.38159	0.22511242	0.0077518714	1863.2366
102.28247	0.22799128	0.0077932379	1880.0804
103.18335	0.23067372	0.0079027638	1896.6464
104.08423	0.23311105	0.0079309512	1913.0751
104.98511	0.23563567	0.0080935964	1937.6183
105.88599	0.23883668	0.0081965849	1953.0177
106.78687	0.23951754	0.0083160195	1971.358
107.68774	0.24377963	0.0082742469	1981.583
108.58862	0.24757615	0.0084353955	1999.6611
109.4895	0.24791975	0.0085821208	2016.9058
110.39038	0.25360772	0.0086110877	2039.0582
111.29126	0.25614935	0.0086748982	2041.8365
112.19214	0.2551626	0.0087902425	2058.4031
113.09302	0.25984022	0.0088469852	2077.7937
113.9939	0.26220459	0.0088719884	2084.4712
114.89478	0.26775709	0.0091085294	2110.4739
115.79565	0.26719207	0.009052258	2114.0762
116.69653	0.2707487	0.0091728475	2130.1279
117.59741	0.27245006	0.0092063993	2138.4426
118.49829	0.27507138	0.0093381228	2151.2224
119.39917	0.28119081	0.0094780372	2164.1799
120.30005	0.2807309	0.0095198918	2177.6248
121.20093	0.28590286	0.0096034622	2194.6851
122.10181	0.28804412	0.0096649406	2196.4148
123.00269	0.28754732	0.0097192898	2213.4688
123.90356	0.29146171	0.0097649386	2216.0217
124.80444	0.29669967	0.00984916	2227.2466
125.70532	0.30086282	0.0099193025	2232.9163
126.6062	0.30035654	0.0099794781	2248.3694
127.50708	0.30236667	0.010050008	2251.3721
128.40796	0.30480301	0.010070373	2265.1643
129.30884	0.30914748	0.010254037	2286.7046
130.20972	0.31091383	0.010121408	2283.9468
131.1106	0.31409615	0.010303131	2288.9939
132.01147	0.31779909	0.010334381	2300.7417
132.91235	0.31917208	0.010441047	2312.7966
133.81323	0.31980231	0.010532849	2316.5288
134.71411	0.32188109	0.010585719	2324.8489
135.61499	0.32527566	0.010711299	2335.3977
136.51587	0.32960987	0.010693744	2350.3228
137.41675	0.3326056	0.010850606	2350.5344
138.31763	0.33658618	0.010909078	2373.3755
139.21851	0.33961728	0.010973786	2375.1799
140.11938	0.34207878	0.010973913	2376.8582
141.02026	0.34503025	0.011173392	2381.1584
141.92114	0.34558159	0.011188017	2391.7329
142.82202	0.34993139	0.011219922	2406.0508
143.7229	0.35394984	0.011386968	2420.1223
144.62378	0.3567853	0.01144321	2423.9307
145.52466	0.35662609	0.011452311	2430.0752
146.42554	0.35907188	0.011595295	2438.7441
147.32642	0.36434573	0.011657408	2443.2114
148.22729	0.36561927	0.011763119	2455.5437
149.12817	0.36609358	0.011775158	2457.2302
150.02905	0.36975965	0.011881245	2461.3088
150.92993	0.37261993	0.01199107	2466.6836
151.83081	0.37463054	0.012119346	2480.7043
152.73169	0.38070852	0.01218162	2489.8665
153.63257	0.38248795	0.012318589	2497.4426
154.53345	0.38410124	0.012493243	2507.7297
155.43433	0.38778663	0.012518809	2508.0498
156.33521	0.3903217	0.01259884	2514.3647
157.23608	0.39162973	0.012790143	2519.759
158.13696	0.39565736	0.012911458	2528.7283
159.03784	0.39794886	0.01302163	2537.4387
159.93872	0.40276048	0.01315117	2544.8149
160.8396	0.40298706	0.013216442	2551.458
161.74048	0.40574262	0.013382046	2555.8357
162.64136	0.40676603	0.013499804	2552.3245
163.54224	0.41110167	0.013671792	2571.8645
164.44312	0.41211897	0.013819634	2576.0781
165.34399	0.41791958	0.014005949	2585.5991
166.24487	0.41791117	0.014158136	2591.9194
167.14575	0.42306757	0.014241504	2590.2451
168.04663	0.42546317	0.01442361	2602.0864
168.94751	0.42801815	0.014533459	2606.1101
169.84839	0.4322814	0.014729636	2620.3569
170.74927	0.43395558	0.015033223	2622.3438
171.65015	0.4369117	0.015260163	2623.5115
172.55103	0.43766138	0.015448618	2633.6211
173.4519	0.44109043	0.015745198	2640.2522
174.35278	0.44588396	0.016032211	2645.9355
175.25366	0.44797119	0.016268136	2650.0764
176.15454	0.44835413	0.016409699	2654.3027
177.05542	0.45138052	0.016812079	2659.4387
177.9563	0.45554516	0.017100455	2674.5898
178.85718	0.45618764	0.017350005	2678.5759
179.75806	0.45956069	0.017657757	2674.8074
180.65894	0.46351403	0.017839398	2678.6433
181.55981	0.46511647	0.018257059	2688.1426
182.46069	0.47203293	0.018796859	2705.9719
183.36157	0.47069579	0.019141072	2694.4121
184.26245	0.47521791	0.019465538	2707.0574
185.16333	0.4759618	0.019870529	2708.4521
186.06421	0.47950029	0.020284645	2711.1406
186.96509	0.48495546	0.020522887	2722.2817
187.86597	0.48538879	0.020984791	2717.4287
188.76685	0.48813325	0.021536622	2731.0742
189.66772	0.49090865	0.021844475	2731.2456
190.5686	0.49279755	0.022219962	2737.5911
191.46948	0.4952583	0.022706298	2737.4773
192.37036	0.49762535	0.023183057	2745.6653
193.27124	0.50370353	0.02353665	2750.2988
194.17212	0.50666767	0.024121538	2761.1033
195.073	0.50633967	0.024642238	2760.4165
195.97388	0.50839573	0.025089271	2766.1753
196.87476	0.50920939	0.025686562	2765.2681
197.77563	0.5168916	0.026316935	2773.8682
198.67651	0.51908845	0.026868083	2779.1243
199.57739	0.52141434	0.027357876	2780.3953
200.47827	0.52202433	0.027967736	2778.3677
201.37915	0.52493209	0.028673254	2790.3796
202.28003	0.52587968	0.029191388	2791.8809
203.18091	0.53233552	0.029878415	2792.8408
204.08179	0.53546625	0.030503027	2799.0295
204.98267	0.53675514	0.03114038	2802.9319
205.88354	0.53810251	0.031812456	2811.3889
206.78442	0.54276395	0.032502443	2808.2222
207.6853	0.5447157	0.033014067	2810.501
208.58618	0.54865676	0.033759579	2819.4409
209.48706	0.55134118	0.034379173	2816.8193
210.38794	0.5532034	0.035153471	2820.3416
211.28882	0.55189955	0.035842322	2823.7583
212.1897	0.55670923	0.036474492	2823.8191
213.09058	0.5614711	0.037192009	2832.1726
213.99146	0.56281316	0.038001474	2835.1953
214.89233	0.56823897	0.038813226	2839.2571
215.79321	0.56974554	0.039579719	2846.2314
216.69409	0.57298213	0.040362127	2848.8945
217.59497	0.57466412	0.041107159	2839.4646
218.49585	0.57591802	0.041985396	2852.8835
219.39673	0.5807429	0.042711727	2854.5945
220.29761	0.58239573	0.043589588	2857.4143
221.19849	0.58281744	0.044267047	2854.9087
222.09937	0.58464235	0.044959411	2862.1858
223.00024	0.593261	0.045604773	2864.7866
223.90112	0.59219044	0.0462064	2856.9058
224.802	0.59551376	0.046931371	2867.803
225.70288	0.59774107	0.047740519	2870.6819
226.60376	0.59983915	0.048674759	2873.4285
227.50464	0.60455424	0.049585223	2879.1133
228.40552	0.60438544	0.050477531	2875.093
229.3064	0.6075657	0.051340021	2878.5203
230.20728	0.61001128	0.052143309	2879.3167
231.10815	0.61609483	0.053085398	2888.7217
232.00903	0.61963427	0.054046895	2891.6006
232.90991	0.62007272	0.054977249	2890.4014
233.81079	0.62149668	0.055849362	2890.4114
234.71167	0.62821788	0.056538027	2896.7661
235.61255	0.62611467	0.057501756	2898.8181
236.51343	0.63116825	0.058257084	2898.7668
237.41431	0.63452655	0.058969337	2900.1799
238.31519	0.63442618	0.059785295	2901.6284
239.21606	0.63879663	0.060721684	2908.8513
240.11694	0.64176756	0.061624579	2910.9678
241.01782	0.64835495	0.062762432	2920.9968
241.9187	0.64753801	0.063757733	2919.8506
242.81958	0.65286982	0.065033674	2933.6191
243.72046	0.6554814	0.06603884	2926.8032
244.62134	0.65712517	0.066949673	2928.5386
245.52222	0.65801013	0.067788571	2922.5696
246.4231	0.66139877	0.068717912	2925.761
247.32397	0.66319644	0.069766723	2927.7087
248.22485	0.66381764	0.070547447	2932.9934
249.12573	0.67017108	0.071675003	2937.9172
250.02661	0.66981643	0.072462112	2933.145
250.92749	0.67538565	0.073510848	2945.4043
251.82837	0.67739582	0.074667484	2942.4285
252.72925	0.67903429	0.07562986	2940.1973
253.63013	0.68366486	0.076452471	2945.3828
254.53101	0.68611181	0.077339694	2944.0828
255.43188	0.68659472	0.078303821	2948.8899
256.33276	0.69219595	0.07929685	2949.5176
257.23364	0.69692445	0.080153815	2949.4692
258.13452	0.69453377	0.080906771	2944.8589
259.0354	0.70017827	0.082013294	2961.3794
259.93628	0.70321059	0.083019949	2963.7148
260.83716	0.70524877	0.08392635	2955.8982
261.73804	0.70707172	0.08485727	2960.251
262.63892	0.70984101	0.085845187	2969.2292
263.53979	0.71329623	0.086874396	2965.2915
264.44067	0.71596348	0.087930247	2974.7051
265.34155	0.71857107	0.088835627	2968.2871
266.24243	0.72037798	0.089805707	2966.3035
267.14331	0.7257973	0.090764351	2974.0334
268.04419	0.72267729	0.091756068	2974.4631
268.94507	0.72596633	0.092925377	2969.877
269.84595	0.73208427	0.094096974	2981.3291
270.74683	0.73417968	0.095243201	2979.614
271.64771	0.73822749	0.096375048	2990.8838
272.54858	0.74198449	0.097397022	2983.5095
273.44946	0.74014425	0.098392151	2983.7222
274.35034	0.74761569	0.099275865	2985.2507
275.25122	0.74611896	0.10027179	2985.3486
276.1521	0.7500248	0.10130878	2994.6726
277.05298	0.75289649	0.10260708	2998.1375
277.95386	0.75626135	0.10367043	2992.6702
278.85474	0.76053083	0.10476368	2999.7844
279.75562	0.75837272	0.10554247	2994.4336
280.65649	0.76297724	0.10647399	2995.554
281.55737	0.76579589	0.1074282	2993.1533
282.45825	0.77070707	0.10841871	3003.7009
283.35913	0.77283764	0.1094533	3006.5125
284.26001	0.77389938	0.11044606	3004.571
285.16089	0.77752864	0.11158486	3008.533
286.06177	0.77779192	0.11248609	3006.4666
286.96265	0.78114676	0.11339206	3005.999
287.86353	0.78513056	0.11450042	3013.519
288.7644	0.79167372	0.11557764	3019.3196
289.66528	0.79079002	0.11666136	3015.3459
290.56616	0.79644227	0.11762552	3019.1345
291.46704	0.79371071	0.11863042	3016.4319
292.36792	0.79868126	0.11978372	3012.4158
293.2688	0.79908919	0.12074002	3017.376
294.16968	0.8023929	0.12189413	3021.7493
295.07056	0.80627179	0.12295308	3017.8491
295.97144	0.81410652	0.12383613	3031.7632
296.87231	0.81229633	0.12458199	3021.9314
297.77319	0.81323367	0.12570412	3024.4897
298.67407	0.81577331	0.12676571	3034.9114
299.57495	0.81990367	0.128013	3030.1289
300.47583	0.8222453	0.12911175	3032.0315
301.37671	0.8258456	0.13028343	3037.6353
302.27759	0.82891572	0.13126782	3037.6067
303.17847	0.82909107	0.13221662	3039.7773
304.07935	0.83417559	0.13328548	3044.4573
304.98022	0.83671397	0.13433227	3036.2659
305.8811	0.83726877	0.13546681	3039.7073
306.78198	0.84264141	0.13639644	3045.7073
307.68286	0.84586573	0.13731761	3043.2686
308.58374	0.84650826	0.13868763	3051.6431
309.48462	0.84949958	0.13982444	3052.5283
310.3855	0.85008419	0.14072753	3038.1592
311.28638	0.85419321	0.14160582	3049.4951
312.18726	0.85960144	0.14282958	3051.613
313.08813	0.86089963	0.14401111	3055.377
313.98901	0.86404878	0.1450824	3053.8086
314.88989	0.86576015	0.14596073	3057.1809
315.79077	0.86862147	0.14712214	3056.6785
316.69165	0.86917305	0.14802006	3053.9204
317.59253	0.87623674	0.14916974	3066.2324
318.49341	0.87815189	0.15022323	3067.2537
319.39429	0.87858295	0.15131164	3060.385
320.29517	0.88191688	0.15222301	3065.2737
321.19604	0.88493431	0.1533602	3069.3662
322.09692	0.88804781	0.15453769	3073.5127
322.9978	0.8939594	0.15577225	3072.9592
323.89868	0.89139855	0.15672512	3065.1858
324.79956	0.89289725	0.15768811	3063.0366
325.70044	0.89945883	0.15849683	3067.6123
326.60132	0.90374184	0.15962118	3084.3237
327.5022	0.90178764	0.16060455	3076.2375
328.40308	0.90793693	0.16175365	3087.6667
329.30396	0.90974981	0.16289102	3082.8069
330.20483	0.91184378	0.16395862	3077.5393
331.10571	0.91599905	0.16500194	3085.6877
332.00659	0.91788286	0.16609092	3087.3428
332.90747	0.92123747	0.16711915	3086.3525
333.80835	0.92704016	0.16817956	3088.8372
334.70923	0.92558384	0.16924126	3090.6423
335.61011	0.92804551	0.17035051	3094.2788
336.51099	0.93123484	0.17145304	3095.6592
337.41187	0.93406433	0.17246056	3085.9243
338.31274	0.93844652	0.17341955	3091.5579
339.21362	0.94113648	0.17431004	3101.9458
340.1145	0.94253296	0.17541552	3097.793
341.01538	0.94687927	0.17643826	3099.2798
341.91626	0.94847167	0.17752624	3102.7957
342.81714	0.95051384	0.17877451	3106.0439
343.71802	0.95273644	0.17988582	3101.1851
344.6189	0.95255673	0.1807445	3090.6985
345.51978	0.95973092	0.18168318	3105.6575
346.42065	0.96043533	0.1827293	3107.7219
347.32153	0.96641213	0.18390588	3109.1658
348.22241	0.96465093	0.18501876	3108.717
349.12329	0.96849507	0.18605761	3109.2712
350.02417	0.9708482	0.18698955	3107.2981
350.92505	0.97347093	0.18813935	3108.0039
351.82593	0.97713357	0.1890139	3110.6272
352.72681	0.97776973	0.19015494	3115.1064
353.62769	0.98026323	0.19127415	3115.9348
354.52856	0.98525983	0.19237165	3117.5498
355.42944	0.99123502	0.1933331	3120.5371
356.33032	0.99013662	0.19422558	3113.6147
357.2312	0.99334759	0.19526678	3120.8423
358.13208	0.9965201	0.1964184	3123.4619
359.03296	1.0039423	0.19733715	3124.7397
359.93384	0.99803054	0.19836372	3124.7546
360.83472	1.002645	0.19944856	3129.2449
361.7356	1.0053605	0.20062914	3119.48
362.63647	1.0109979	0.20161739	3126.8762
363.53735	1.0120796	0.20283955	3131.3853
364.43823	1.0152009	0.20407577	3130.3308
365.33911	1.0168982	0.20507841	3129.1587
366.23999	1.019464	0.20603041	3129.6909
367.14087	1.0247487	0.20703055	3138.6394
368.04175	1.0259398	0.20801282	3134.6475
368.94263	1.0262431	0.20906687	3134.9182
369.84351	1.0290376	0.21000499	3130.2612
370.74438	1.0305998	0.21125434	3136.3835
371.64526	1.0348496	0.21229202	3129.6853
372.54614	1.0374671	0.21340451	3144.49
373.44702	1.0442107	0.21450497	3145.4995
374.3479	1.0475193	0.21558154	3152.6631
375.24878	1.0491056	0.21656066	3146.6411
376.14966	1.0522349	0.21753216	3153.4675
377.05054	1.051586	0.21865408	3150.5256
377.95142	1.0571632	0.21978635	3155.2598
378.85229	1.0599004	0.22093844	3153.531
379.75317	1.0609199	0.22192024	3156.2461
380.65405	1.0643388	0.22284308	3152.0742
381.55493	1.0675917	0.22387819	3159.5571
382.45581	1.0687028	0.22500752	3154.0759
383.35669	1.0719427	0.22612821	3157.5134
384.25757	1.0750557	0.2273287	3163.1858
385.15845	1.0774189	0.2284541	3163.8262
386.05933	1.0788429	0.2294137	3159.115
386.96021	1.0838377	0.23039776	3162.645
387.86108	1.0827603	0.23136893	3163.3042
388.76196	1.0897616	0.23257975	3164.4172
389.66284	1.0908417	0.23351321	3165.5745
390.56372	1.0948837	0.23478709	3171.6484
391.4646	1.0960513	0.23579818	3170.9629
392.36548	1.0986803	0.23671503	3171.1301
393.26636	1.1009959	0.23772855	3165.6104
394.16724	1.1060423	0.23876961	3173.2283
395.06812	1.1071798	0.23993461	3181.0244
395.96899	1.1086266	0.24104851	3173.4065
396.86987	1.1104945	0.24192396	3171.8823
397.77075	1.1143771	0.24289472	3175.9893
398.67163	1.1170319	0.24360117	3173.998
399.57251	1.1233033	0.24466667	3183.8169
400.47339	1.125962	0.24574751	3178.9192
401.37427	1.1272267	0.24669215	3178.8311
402.27515	1.1289749	0.24769637	3182.1804
403.17603	1.1333212	0.24881312	3190.5752
404.0769	1.1304485	0.2497773	3179.9761
404.97778	1.1386582	0.25071084	3186.4719
405.87866	1.1396061	0.25176209	3190.0747
406.77954	1.1414026	0.25279137	3189.1072
407.68042	1.146228	0.2538842	3187.759
408.5813	1.1507939	0.25510937	3196.6587
409.48218	1.151873	0.25613993	3193.6174
410.38306	1.1547093	0.25710917	3195.6772
411.28394	1.1545658	0.2581127	3193.7612
412.18481	1.1626116	0.25921106	3205.1858
413.08569	1.160079	0.26029575	3194.0325
413.98657	1.1626903	0.26114172	3191.7813
414.88745	1.164798	0.26221547	3196.969
415.78833	1.1661972	0.26320177	3199.8386
416.68921	1.1716899	0.26443407	3203.583
417.59009	1.174812	0.26533756	3198.7427
418.49097	1.1771108	0.26634943	3201.2241
419.39185	1.1777347	0.26745987	3208.427
420.29272	1.1838479	0.2686615	3210.0718
421.1936	1.1838863	0.26997012	3210.8945
422.09448	1.1886575	0.2709626	3203.6143
422.99536	1.1910455	0.27206349	3217.2805
423.89624	1.1934427	0.2730298	3213.3567
424.79712	1.1983801	0.27395162	3210.1489
425.698	1.199885	0.27492183	3216.6396
426.59888	1.2024217	0.27605709	3217.1887
427.49976	1.2035834	0.27714741	3217.0427
428.40063	1.2067422	0.27841303	3214.8953
429.30151	1.2080948	0.27944997	3212.918
430.20239	1.2097719	0.28029555	3209.5835
431.10327	1.2168629	0.28138918	3221.4355
432.00415	1.2192277	0.28222165	3212.7161
432.90503	1.2212845	0.28305697	3214.1711
433.80591	1.2200506	0.28396916	3225.3853
434.70679	1.2235713	0.28518209	3225.4409
435.60767	1.226069	0.28617102	3221.3953
436.50854	1.2272608	0.28700513	3223.0906
437.40942	1.2328643	0.28813925	3220.4609
438.3103	1.2373575	0.28920734	3231.2378
439.21118	1.239885	0.29018003	3226.0762
440.11206	1.2406787	0.29100022	3226.1748
441.01294	1.2473538	0.29194087	3229.7537
441.91382	1.2458423	0.29280505	3227.5481
442.8147	1.2519519	0.29379135	3240.8992
443.71558	1.2513523	0.29492447	3225.261
444.61646	1.2554256	0.2959089	3240.292
445.51733	1.2605269	0.29685071	3236.7273
446.41821	1.2620084	0.29805321	3246.1494
447.31909	1.2641778	0.29888937	3231.2703
448.21997	1.2661183	0.29989061	3238.469
449.12085	1.2688404	0.30082563	3234.7014
450.02173	1.2693222	0.3018958	3242.8152
450.92261	1.2734759	0.30288109	3245.0071
451.82349	1.2772624	0.30388355	3242.5386
452.72437	1.2799716	0.3050859	3245.584
453.62524	1.2797381	0.30612534	3247.0605
454.52612	1.2850201	0.30715397	3247.7083
455.427	1.2873913	0.30831096	3251.6675
456.32788	1.2912508	0.30939198	3252.0063
457.22876	1.2935525	0.31072223	3254.7456
458.12964	1.2953184	0.31161359	3249.915
459.03052	1.2987372	0.31255138	3244.095
459.9314	1.3022162	0.31352231	3254.7363
460.83228	1.3063294	0.31463602	3260.2351
461.73315	1.3064705	0.31565475	3252.6155
462.63403	1.3105252	0.31665653	3258.5771
463.53491	1.3136486	0.31792381	3266.4065
464.43579	1.3166842	0.31879979	3260.7693
465.33667	1.3155249	0.31991804	3259.5913
466.23755	1.3190171	0.32087663	3258.8469
467.13843	1.3245345	0.32175282	3260.2793
468.03931	1.3271229	0.32266253	3257.7368
468.94019	1.3286753	0.32374635	3270.3367
469.84106	1.3329102	0.32474929	3273.3713
470.74194	1.3327594	0.32579994	3269.501
471.64282	1.3345976	0.32686773	3262.687
472.5437	1.3427554	0.32792801	3274.5767
473.44458	1.3442882	0.32903415	3269.7886
474.34546	1.34553	0.33002955	3275.6162
475.24634	1.3467549	0.33123735	3272.7822
476.14722	1.3512212	0.33238554	3273.2876
477.0481	1.3554434	0.33332554	3268.9158
477.94897	1.3568251	0.33415809	3273.917
478.84985	1.3580317	0.33511305	3280.1675
479.75073	1.3627923	0.33619675	3276.7241
480.65161	1.3650516	0.33726552	3277.553
481.55249	1.3668215	0.33821705	3282.2913
482.45337	1.3717613	0.33952916	3285.3354
483.35425	1.3701493	0.34056234	3279.8682
484.25513	1.3739434	0.34154719	3286.3235
485.15601	1.3744946	0.34267083	3285.3655
486.05688	1.3799	0.3436788	3283.3586
486.95776	1.3826641	0.34470785	3287.9731
487.85864	1.3844295	0.34565017	3284.031
488.75952	1.3906691	0.34668308	3283.9492
489.6604	1.389572	0.34752649	3284.5779
490.56128	1.390727	0.34838474	3290.3088
491.46216	1.3962226	0.34954485	3289.501
492.36304	1.3969008	0.35056454	3288.9658
493.26392	1.4000351	0.35172009	3292.385
494.16479	1.4034244	0.35291037	3299.0225
495.06567	1.406098	0.35394463	3297.7114
495.96655	1.4091434	0.35488817	3289.9194
496.86743	1.4112282	0.35586563	3292.3105
497.76831	1.4178772	0.35678601	3302.6516
498.66919	1.4185966	0.35768268	3292.7312
499.57007	1.4205949	0.35870463	3303.7407
500.47095	1.4225405	0.3597253	3305.7358
501.37183	1.4263184	0.36081669	3304.1235
502.27271	1.4277865	0.36183915	3298.3171
503.17358	1.4293501	0.3629455	3303.5503
504.07446	1.4334841	0.36398941	3303.7847
504.97534	1.4377949	0.36497816	3306.9573
505.87622	1.4379584	0.36607754	3307.0022
506.7771	1.4440885	0.36704943	3304.9919
507.67798	1.4459552	0.36812809	3311.6218
508.57886	1.4502703	0.36919317	3312.4934
509.47974	1.4527825	0.37020192	3313.2717
510.38062	1.4550717	0.37110668	3311.1543
511.28149	1.4560421	0.37202245	3310.6377
512.18237	1.4566319	0.37301916	3312.8088
513.08325	1.4597114	0.37406078	3311.2048
513.98413	1.4640809	0.37495601	3313.9531
514.88501	1.466743	0.37607396	3322.4861
515.78589	1.4689406	0.37701342	3311.9944
516.68677	1.4757657	0.37814307	3325.8198
517.58765	1.4782221	0.37930417	3324.248
518.48853	1.4782803	0.38038081	3324.4573
519.3894	1.4764328	0.38155675	3322.3711
520.29028	1.4826337	0.38253134	3316.866
521.19116	1.4860674	0.38354442	3323.0613
522.09204	1.4884161	0.38443002	3321.863
522.99292	1.4901441	0.38540548	3327.3579
523.8938	1.4937518	0.38639852	3318.4768
524.79468	1.4968755	0.38727173	3327.7937
525.69556	1.5002741	0.38848916	3331.9773
526.59644	1.4991312	0.38967025	3326.8792
527.49731	1.5036807	0.39091364	3327.959
528.39819	1.5057657	0.39199722	3327.8816
529.29907	1.511497	0.39298019	3329.478
530.19995	1.514358	0.39399609	3335.1621
531.10083	1.516247	0.39514372	3330.2805
532.00171	1.5175574	0.39609838	3333.4407
532.90259	1.5225888	0.39724985	3336.5874
533.80347	1.5216396	0.39834711	3337.218
534.70435	1.5267711	0.39942691	3337.6567
535.60522	1.5295895	0.40063128	3337.6311
536.5061	1.5329741	0.4013426	3329.5796
537.40698	1.5316712	0.40222874	3339.6367
538.30786	1.535344	0.40310153	3336.2375
539.20874	1.5394396	0.40410534	3341.0686
540.10962	1.5404781	0.40532929	3343.6758
541.0105	1.5427173	0.4063758	3335.3137
541.91138	1.5461575	0.40737438	3336.8914
542.81226	1.5483634	0.40844414	3340.155
543.71313	1.5523359	0.409455	3344.6218
544.61401	1.5551815	0.41041443	3343.7388
545.51489	1.5593506	0.41139641	3354.0217
546.41577	1.5591502	0.41243318	3341.918
547.31665	1.5671197	0.4135091	3351.6711
548.21753	1.5660509	0.41461813	3351.6941
549.11841	1.5678514	0.41576761	3358.2771
550.01929	1.5712477	0.41687024	3352.9519
550.92017	1.5749782	0.41802132	3349.0415
551.82104	1.5754311	0.41883391	3350.7048
552.72192	1.580091	0.41985044	3349.3572
553.6228	1.5837655	0.42064294	3350.0818
554.52368	1.58506	0.42169976	3362.7351
555.42456	1.5874486	0.42277929	3363.8562
556.32544	1.5900747	0.42383695	3356.5491
557.22632	1.5966965	0.42490724	3360.4756
558.1272	1.5951834	0.42586514	3353.9556
559.02808	1.598385	0.42695484	3364.2461
559.92896	1.6005604	0.42805916	3359.6602
560.82983	1.6056854	0.42903978	3362.7793
561.73071	1.6085346	0.43013522	3363.302
562.63159	1.6107018	0.43155462	3365.3374
563.53247	1.613061	0.43258747	3358.8606
564.43335	1.6148793	0.4335399	3362.3396
565.33423	1.6166611	0.43448403	3364.7842
566.23511	1.6210552	0.43549463	3361.1758
567.13599	1.6239232	0.43640935	3364.3323
568.03687	1.6265944	0.43745971	3368.4978
568.93774	1.6321231	0.43849799	3373.4084
569.83862	1.6317614	0.4395605	3369.1172
570.7395	1.6331009	0.44070888	3369.5342
571.64038	1.6380868	0.44155988	3361.6548
572.54126	1.6391412	0.44256079	3374.7742
573.44214	1.6397589	0.44371238	3371.9924
574.34302	1.6465657	0.44483563	3377.5637
575.2439	1.6494077	0.44598988	3373.2874
576.14478	1.6497626	0.44692683	3377.7151
577.04565	1.6516045	0.44790402	3371.0327
577.94653	1.6571171	0.44897678	3375.342
578.84741	1.6585796	0.45010909	3377.907
579.74829	1.6624149	0.45090115	3376.7595
580.64917	1.6647545	0.45217228	3381.9424
581.55005	1.6626544	0.45305067	3370.2959
582.45093	1.670642	0.45413738	3378.6829
583.35181	1.6751065	0.45515054	3380.6897
584.25269	1.6748078	0.45602593	3382.0618
585.15356	1.6780491	0.45692477	3378.8843
586.05444	1.6815922	0.45809165	3388.1577
586.95532	1.6834186	0.45935693	3385.0513
587.8562	1.6826971	0.4606702	3384.3853
588.75708	1.6892418	0.46162868	3386.8518
589.65796	1.6937948	0.46275249	3385.2251
590.55884	1.6929916	0.46370333	3379.6924
591.45972	1.6967422	0.46482775	3391.998
592.3606	1.6977453	0.46571714	3384.9512
593.26147	1.6996911	0.46657732	3383.595
594.16235	1.7062228	0.46759975	3388.9529
595.06323	1.7063004	0.46877944	3389.5935
595.96411	1.7126526	0.46981168	3392.5144
596.86499	1.7119309	0.47088322	3397.1465
597.76587	1.7149588	0.47203141	3394.4688
598.66675	1.718305	0.47307223	3398.0994
599.56763	1.7183398	0.47435778	3394.1821
600.46851	1.7219684	0.47570774	3392.6055
601.36938	1.7248483	0.47680473	3395.8777
602.27026	1.7285432	0.47801045	3399.2803
603.17114	1.7296647	0.47909945	3401.5552
604.07202	1.7320428	0.48020712	3398.7363
604.9729	1.7348887	0.4813751	3394.1621
605.87378	1.7395567	0.48233238	3394.6069
606.77466	1.741964	0.48342749	3403.1902
607.67554	1.7448474	0.48429322	3401.2095
608.57642	1.7481557	0.48535678	3404.9592
609.47729	1.7504076	0.48638269	3406.4609
610.37817	1.7534254	0.48748592	3408.4031
611.27905	1.7550459	0.48851487	3405.4834
612.17993	1.7593468	0.48959634	3399.6753
613.08081	1.7589554	0.49078271	3403.6978
613.98169	1.7620502	0.49199191	3413.1064
614.88257	1.7649213	0.49312937	3401.9082
615.78345	1.7702236	0.49429029	3408.5505
616.68433	1.772839	0.49539775	3407.5647
617.58521	1.775031	0.49632269	3401.769
618.48608	1.7761879	0.49716267	3406.4663
619.38696	1.7784365	0.49822018	3409.0767
620.28784	1.7822676	0.49910986	3409.2986
621.18872	1.7849269	0.5001871	3415.0117
622.0896	1.7866948	0.50120246	3410.4324
622.99048	1.7888471	0.50231463	3417.0269
623.89136	1.7922159	0.50335205	3412.2986
624.79224	1.7968354	0.50432557	3416.677
625.69312	1.7991332	0.5054875	3419.376
626.59399	1.802592	0.50683296	3421.9209
627.49487	1.8029127	0.50786835	3418.1011
628.39575	1.8049524	0.50873661	3415.4294
629.29663	1.8121653	0.51003772	3423.4304
630.19751	1.8151147	0.51125503	3423.3452
631.09839	1.8149506	0.51220959	3414.6238
631.99927	1.8178842	0.51324844	3414.7974
632.90015	1.8215617	0.51439399	3424.5305
633.80103	1.8235029	0.5157913	3433.3298
634.7019	1.8272617	0.51709825	3431.1296
635.60278	1.8297193	0.51839489	3424.9644
636.50366	1.8297241	0.51944089	3422.071
637.40454	1.832436	0.52062684	3422.8154
638.30542	1.8354044	0.52164191	3420.1953
639.2063	1.8393266	0.5227744	3421.6631
640.10718	1.8446426	0.52401817	3431.5354
641.00806	1.8447758	0.52491075	3425.2375
641.90894	1.8484817	0.52599943	3433.3723
642.80981	1.8494776	0.52706057	3422.8262
643.71069	1.8528122	0.52801359	3424.6064
644.61157	1.8566622	0.52900398	3432.688
645.51245	1.8579249	0.52992398	3436.5588
646.41333	1.8604473	0.53111142	3429.6636
647.31421	1.8621262	0.53230417	3432.0405
648.21509	1.8650029	0.53329325	3432.6694
649.11597	1.8670298	0.53438777	3435.7737
650.01685	1.8715638	0.53571779	3433.5959
650.91772	1.8751646	0.53678429	3436.7966
651.8186	1.8802605	0.53783762	3440.2856
652.71948	1.8816572	0.53899181	3437.5024
653.62036	1.8855546	0.5401172	3436.562
654.52124	1.8857275	0.54113108	3439.1663
655.42212	1.8892163	0.54200757	3430.5115
656.323	1.8899175	0.5432083	3437.199
657.22388	1.8945814	0.54442078	3437.8274
658.12476	1.898012	0.54573768	3444.4753
659.02563	1.8983116	0.54703289	3442.0613
659.92651	1.9016719	0.54805708	3435.8914
660.82739	1.9035549	0.54906839	3439.3745
661.72827	1.9086608	0.55032027	3445.0908
662.62915	1.9079155	0.55131799	3438.6943
663.53003	1.9132289	0.55245042	3449.8525
664.43091	1.9162874	0.55347478	3445.1892
665.33179	1.9198915	0.55455524	3450.7158
666.23267	1.9211345	0.55580437	3450.7891
667.13354	1.9218336	0.5569644	3444.1445
668.03442	1.924969	0.5580613	3446.5918
668.9353	1.9306916	0.55935502	3451.9678
669.83618	1.9306341	0.56068462	3450.0012
670.73706	1.9308102	0.56183833	3445.6357
671.63794	1.9360937	0.56303942	3448.8594
672.53882	1.9406936	0.56411982	3449.7764
673.4397	1.9418325	0.56521386	3447.8694
674.34058	1.9487523	0.56635404	3453.9614
675.24146	1.9482731	0.56746715	3451.9199
676.14233	1.950317	0.56856382	3449.7505
677.04321	1.9555435	0.5697999	3460.4536
677.94409	1.9564358	0.5710668	3454.2227
678.84497	1.9582465	0.57200098	3448.2402
679.74585	1.9582394	0.57323402	3450.5886
680.64673	1.962449	0.57440966	3454.8091
681.54761	1.963739	0.57580841	3459.1675
682.44849	1.9705203	0.57698363	3461.2957
683.34937	1.9708856	0.57801139	3460.1851
684.25024	1.9745748	0.57926315	3460.4827
685.15112	1.9751942	0.5803085	3454.7832
686.052	1.9815208	0.58129847	3455.1367
686.95288	1.9851811	0.58233708	3457.8826
687.85376	1.9850096	0.58330357	3457.6746
688.75464	1.9889176	0.58430403	3459.6899
689.65552	1.9883925	0.5854755	3456.3936
690.5564	1.9928886	0.58673161	3467.6902
691.45728	1.9989891	0.58795774	3468.2917
692.35815	1.9979286	0.58922076	3460.6577
693.25903	2.0035338	0.59032369	3462.9692
694.15991	2.0065815	0.59177768	3466.9177
695.06079	2.0077393	0.59299171	3462.7432
695.96167	2.0116048	0.59419256	3472.8354
696.86255	2.0136132	0.59543335	3462.9155
697.76343	2.0152853	0.59660912	3471.1489
698.66431	2.0171399	0.59793967	3470.9285
699.56519	2.0214648	0.59925377	3472.5955
700.46606	2.0266623	0.6003623	3464.0706
701.36694	2.025099	0.60158598	3464.1167
702.26782	2.0283599	0.60268974	3470.5767
703.1687	2.0351403	0.60371554	3468.4417
704.06958	2.0339518	0.60484612	3464.8147
704.97046	2.0351653	0.60606414	3466.9678
705.87134	2.0435495	0.60721517	3474.3806
706.77222	2.040051	0.60857773	3475.624
707.6731	2.0433168	0.60975015	3461.1086
708.57397	2.0466802	0.61089551	3473.2969
709.47485	2.047502	0.6121707	3468.5891
710.37573	2.0520327	0.61347008	3472.0256
711.27661	2.0579872	0.6146518	3476.9382
712.17749	2.0591474	0.61605227	3477.7593
713.07837	2.0612426	0.6171605	3475.0371
713.97925	2.0651546	0.61816221	3471.4729
714.88013	2.0665326	0.61916	3475.6995
715.78101	2.068217	0.62046885	3476.3694
716.68188	2.070987	0.62171507	3481.0615
717.58276	2.079185	0.62315637	3485.9993
718.48364	2.0765679	0.62436986	3480.4155
719.38452	2.0799158	0.62562191	3479.3455
720.2854	2.0802329	0.62661362	3470.3513
721.18628	2.0849156	0.62762719	3475.7363
722.08716	2.0879118	0.62834507	3473.6799
722.98804	2.0933361	0.62950599	3479.7854
723.88892	2.0930533	0.63039768	3485.6704
724.78979	2.0965822	0.63153505	3480.9722
725.69067	2.1007133	0.63255179	3487.6248
726.59155	2.0992458	0.63362765	3478.658
727.49243	2.1052859	0.63506234	3486.0203
728.39331	2.1061773	0.6362322	3481.864
729.29419	2.108212	0.63756245	3484.0107
730.19507	2.1137671	0.63889056	3485.0774
731.09595	2.1152949	0.6401602	3490.2534
731.99683	2.1177862	0.64147472	3484.0791
732.89771	2.1194034	0.64268512	3480.5833
733.79858	2.1240182	0.64406073	3480.8342
734.69946	2.1256621	0.64542562	3484.1145
735.60034	2.1272323	0.64657748	3478.7444
736.50122	2.129576	0.64785457	3480.5422
737.4021	2.1336222	0.64917195	3484.7275
738.30298	2.1345384	0.65037155	3484.1467
739.20386	2.1391773	0.65172958	3484.4651
740.10474	2.1436846	0.65305442	3487.6936
741.00562	2.1447237	0.65436924	3491.2244
741.90649	2.1498575	0.65590751	3495.4534
742.80737	2.1494482	0.65753233	3489.3918
743.70825	2.1513088	0.65888178	3489.0195
744.60913	2.1540663	0.66028953	3491.0095
745.51001	2.1584635	0.66181827	3491.3096
746.41089	2.1616094	0.66329217	3491.6658
747.31177	2.1646235	0.66479117	3491.9817
748.21265	2.1619663	0.66634214	3492.7639
749.11353	2.1697619	0.66797924	3492.8298
750.0144	2.1741631	0.66934204	3497.0991
750.91528	2.1740434	0.67114824	3493.6895
751.81616	2.1774094	0.67249399	3491.4341
752.71704	2.1800532	0.67388517	3494.9097
753.61792	2.184283	0.6752364	3495.7285
754.5188	2.1856086	0.67653251	3490.4612
755.41968	2.1874363	0.67773885	3489.5386
756.32056	2.1918709	0.6785515	3492.5078
757.22144	2.1961005	0.67969054	3493.8838
758.12231	2.1996567	0.68043119	3496.3464
759.02319	2.1985364	0.6815536	3492.4863
759.92407	2.202843	0.68277186	3502.0332
760.82495	2.2036793	0.68375564	3498.1047
761.72583	2.2061017	0.68503851	3501.8455
762.62671	2.207798	0.68615562	3499.1025
763.52759	2.2111356	0.68734026	3495.2656
764.42847	2.2138364	0.68847525	3498.8748
765.32935	2.2200077	0.68981373	3505.3965
766.23022	2.2192662	0.69159096	3501.4519
767.1311	2.225107	0.69329572	3504.3086
768.03198	2.2267945	0.69529718	3500.5342
768.93286	2.2304714	0.6964736	3499.2935
769.83374	2.2296081	0.69798875	3504.6619
770.73462	2.2315269	0.69962245	3499.4644
771.6355	2.2375302	0.70127308	3506.5034
772.53638	2.2363672	0.70340276	3505.3938
773.43726	2.2424488	0.70507306	3506.7944
774.33813	2.2477119	0.70720935	3504.7566
775.23901	2.2499335	0.70865625	3503.8831
776.13989	2.2499321	0.71039897	3504.0605
777.04077	2.2517483	0.71179193	3498.6521
777.94165	2.2556365	0.71374351	3514.2441
778.84253	2.2581811	0.71537405	3508.168
779.74341	2.2605693	0.71713275	3503.0579
780.64429	2.2628276	0.71865988	3510.2871
781.54517	2.2648129	0.7201283	3502.0276
782.44604	2.2713213	0.72121042	3502.6335
783.34692	2.2726982	0.72263396	3500.5164
784.2478	2.2779279	0.72368032	3507.8738
785.14868	2.2784305	0.72518992	3506.0693
786.04956	2.2815356	0.72680062	3515.9202
786.95044	2.283139	0.7284534	3509.0525
787.85132	2.2842257	0.73033655	3517.5244
788.7522	2.2904692	0.73216629	3511.4402
789.65308	2.289885	0.73361111	3503.5828
790.55396	2.2917538	0.73502439	3507.3167
791.45483	2.2991436	0.7367695	3511.3735
792.35571	2.2982318	0.73843932	3511.9419
793.25659	2.3011022	0.7402187	3503.5076
794.15747	2.3039465	0.74192882	3509.6836
795.05835	2.3069532	0.74383467	3509.1267
795.95923	2.3106081	0.74527586	3505.4612
796.86011	2.3112957	0.74673831	3503.929
797.76099	2.3161178	0.74817437	3515.5879
798.66187	2.3159971	0.74995804	3520.7488
799.56274	2.3200877	0.75166249	3510.1704
800.46362	2.3254652	0.75348628	3522.7888
801.3645	2.3279529	0.75540727	3517.7197
802.26538	2.3281748	0.75704509	3518.2207
803.16626	2.3317134	0.75901538	3520.8279
804.06714	2.3343832	0.76070923	3517.8318
804.96802	2.3370347	0.76258141	3515.6074
805.8689	2.3383915	0.76392376	3509.3682
806.76978	2.3440783	0.76544231	3511.4714
807.67065	2.3437581	0.7668218	3514.3787
808.57153	2.3468618	0.76842964	3518.4126
809.47241	2.3480613	0.76995301	3511.6704
810.37329	2.3530412	0.77146769	3520.0869
811.27417	2.3576734	0.77319151	3520.3008
812.17505	2.3583984	0.77493644	3516.8367
813.07593	2.3597717	0.77700645	3520.665
813.97681	2.3621616	0.77896732	3519.8418
814.87769	2.3687842	0.7806505	3516.5254
815.77856	2.3658009	0.78219473	3515.718
816.67944	2.371146	0.78369075	3515.384
817.58032	2.3726466	0.78550571	3516.3462
818.4812	2.3787034	0.78685331	3516.6812
819.38208	2.3804734	0.78879899	3520.2573
820.28296	2.3837106	0.79030788	3520.9622
821.18384	2.3858664	0.79199964	3516.5762
822.08472	2.3864157	0.79344726	3510.9509
822.9856	2.3907206	0.79539341	3523.2732
823.88647	2.3937347	0.79713005	3517.6479
824.78735	2.3951871	0.7987479	3520.5435
825.68823	2.3993859	0.80060011	3521.6482
826.58911	2.4014902	0.80225247	3522.0908
827.48999	2.4044077	0.80380589	3524.1501
828.39087	2.4064283	0.8053273	3514.0608
829.29175	2.4114542	0.80674428	3523.5237
830.19263	2.4115503	0.80848223	3524.1758
831.09351	2.4154248	0.81044769	3524.5005
831.99438	2.4164133	0.81181282	3517.626
832.89526	2.4177179	0.81344825	3517.676
833.79614	2.4233265	0.8151598	3520.4111
834.69702	2.4266005	0.81695616	3522.6433
835.5979	2.4273133	0.81859833	3516.7075
836.49878	2.4336939	0.82029659	3522.4509
837.39966	2.4333138	0.82194066	3526.2622
838.30054	2.4382451	0.82332522	3523.0149
839.20142	2.4418097	0.82524401	3528.3723
840.10229	2.4396005	0.82689917	3522.5425
841.00317	2.4455991	0.8290931	3529.3398
841.90405	2.4457438	0.83096737	3522.4932
842.80493	2.4479239	0.83289623	3519.5767
843.70581	2.4526858	0.83489585	3524.0571
844.60669	2.4557276	0.83660108	3524.1204
845.50757	2.4595022	0.83826721	3530.3079
846.40845	2.4606667	0.83981603	3526.5789
847.30933	2.4643223	0.84170127	3526.0154
848.21021	2.4663503	0.84368229	3526.9436
849.11108	2.4663684	0.84534925	3525.4109
850.01196	2.474236	0.84711671	3523.0933
850.91284	2.4735918	0.84866333	3526.384
851.81372	2.475039	0.85037285	3524.3037
852.7146	2.4819107	0.85239381	3526.7395
853.61548	2.484875	0.85415077	3529.5317
854.51636	2.4831059	0.85604995	3528.0024
855.41724	2.4865839	0.85764515	3523.4841
856.31812	2.4933648	0.85911965	3528.5552
857.21899	2.4930892	0.8610127	3528.5205
858.11987	2.4945359	0.86259866	3523.8682
859.02075	2.4968343	0.8642199	3526.0339
859.92163	2.5018654	0.8658911	3529.1536
860.82251	2.5017986	0.86780053	3524.7759
861.72339	2.508543	0.86966312	3531.2842
862.62427	2.5081978	0.87130898	3523.7659
863.52515	2.5099843	0.87329817	3531.5488
864.42603	2.515275	0.87497324	3526.8191
865.3269	2.5178003	0.87671095	3526.3267
866.22778	2.5191135	0.87835908	3519.4958
867.12866	2.5233784	0.87976599	3520.416
868.02954	2.5276234	0.8812834	3523.0356
868.93042	2.526957	0.88278604	3522.0776
869.8313	2.5303738	0.88424796	3519.4026
870.73218	2.5359106	0.88605154	3528.7551
871.63306	2.5345759	0.88773465	3526.1345
872.53394	2.537982	0.88954109	3529.9597
873.43481	2.5408995	0.89149177	3525.1362
874.33569	2.5430937	0.89316589	3522.7239
875.23657	2.5501702	0.8952803	3532.2356
876.13745	2.5485427	0.89715499	3530.4109
877.03833	2.5519967	0.89925826	3525.4868
877.93921	2.5556467	0.90109789	3528.0659
878.84009	2.558955	0.90311933	3530.9221
879.74097	2.5604823	0.90517557	3526.459
880.64185	2.5648694	0.90682375	3525.1367
881.54272	2.5643852	0.90873885	3527.1172
882.4436	2.5691786	0.91061288	3533.6091
883.34448	2.5724065	0.91245186	3527.4202
884.24536	2.5752735	0.91453654	3524.752
885.14624	2.5785127	0.91679573	3529.5305
886.04712	2.5812113	0.91873479	3526.8003
886.948	2.579802	0.9201979	3523.8618
887.84888	2.5880766	0.92226374	3534.5928
888.74976	2.5866983	0.92413884	3522.7068
889.65063	2.5915785	0.92628956	3527.8101
890.55151	2.5949106	0.92861789	3529.4058
891.45239	2.5969858	0.93034613	3524.4692
892.35327	2.5994909	0.9322238	3523.0154
893.25415	2.6031034	0.93383086	3530.5569
894.15503	2.6037831	0.93611741	3531.4214
895.05591	2.6099336	0.93845493	3532.1848
895.95679	2.6125062	0.94054502	3526.5752
896.85767	2.6143484	0.94222522	3527.6211
897.75854	2.6137688	0.94398159	3534.6445
898.65942	2.6202488	0.94608778	3528.2356
899.5603	2.6212919	0.94776946	3527.9116
900.46118	2.6215544	0.94979089	3528.1016
901.36206	2.6293211	0.9517141	3533.8735
902.26294	2.6247811	0.95339864	3522.5771
903.16382	2.6318119	0.95529264	3530.8181
904.0647	2.6343699	0.95734632	3527.5583
904.96558	2.6357088	0.95948672	3526.7603
905.86646	2.6395013	0.961254	3524.3875
906.76733	2.6412754	0.96312529	3524.3787
907.66821	2.6423752	0.96525085	3526.0913
908.56909	2.6475036	0.96708614	3527.3418
909.46997	2.6482072	0.96915263	3525.1511
910.37085	2.6532061	0.97088224	3528.5247
911.27173	2.6550262	0.97299314	3530.8604
912.17261	2.6605897	0.9754433	3530.2375
913.07349	2.6589267	0.9776234	3523.439
913.97437	2.6632583	0.98005897	3524.8464
914.87524	2.6695883	0.98213756	3529.491
915.77612	2.6683729	0.98427331	3522.0891
916.677	2.6719213	0.98655635	3526.792
917.57788	2.6729114	0.98871177	3526.3499
918.47876	2.6778576	0.99079847	3530.386
919.37964	2.6821415	0.9931035	3527.012
920.28052	2.6827195	0.9950546	3528.9619
921.1814	2.6865861	0.99761671	3523.574
922.08228	2.6898751	0.99997252	3527.9558
922.98315	2.6925418	1.0021356	3527.3179
923.88403	2.6919122	1.0043445	3526.4304
924.78491	2.6940491	1.0060866	3522.686
925.68579	2.6989424	1.0079684	3523.8853
926.58667	2.7035782	1.0099665	3526.6201
927.48755	2.7041905	1.0120783	3525.2795
928.38843	2.7056332	1.0143291	3523.7388
929.28931	2.7089341	1.0166382	3524.2695
930.19019	2.7121418	1.0185469	3516.686
931.09106	2.7155848	1.0205448	3522.5325
931.99194	2.7202275	1.0226568	3521.1011
932.89282	2.7206626	1.0245354	3520.5181
933.7937	2.7222164	1.026983	3522.9712
934.69458	2.7251306	1.0290862	3523.3474
935.59546	2.7269788	1.0313632	3524.9917
936.49634	2.7296946	1.0341784	3521.5364
937.39722	2.7328537	1.0365653	3519.9189
938.2981	2.736253	1.0389309	3515.4211
939.19897	2.7372973	1.0418589	3519.196
940.09985	2.7423275	1.0438179	3508.6963
941.00073	2.7480409	1.0461562	3524.5608
941.90161	2.7483335	1.0480243	3514.4414
942.80249	2.7497125	1.0500942	3514.4041
943.70337	2.7525582	1.052493	3516.2014
944.60425	2.7533047	1.0552349	3517.3069
945.50513	2.7602055	1.0571265	3520.0164
946.40601	2.7592096	1.0595864	3517.6641
947.30688	2.7645321	1.0618496	3519.8308
948.20776	2.7674458	1.0644563	3524.6255
949.10864	2.7708788	1.0671445	3519.7385
950.00952	2.7714152	1.0692515	3512.8684
950.9104	2.7759681	1.0717144	3517.6128
951.81128	2.780875	1.0741764	3523.845
952.71216	2.7816212	1.0768892	3514.0403
953.61304	2.7840581	1.0794961	3513.8042
954.51392	2.7820523	1.0819364	3512.9636
955.41479	2.7871232	1.0845748	3509.3728
956.31567	2.7902331	1.0872349	3516.02
957.21655	2.7956114	1.0897154	3508.877
958.11743	2.7942927	1.092224	3508.136
959.01831	2.7989748	1.0948393	3511.6433
959.91919	2.8033636	1.0972252	3511.4407
960.82007	2.8050203	1.0992836	3505.1907
961.72095	2.8035805	1.1006001	3504.4016
962.62183	2.8134658	1.1020772	3515.345
963.52271	2.8139145	1.1037165	3507.686
964.42358	2.8169017	1.105306	3509.7913
965.32446	2.8162694	1.1070646	3510.8484
966.22534	2.818435	1.1087997	3502.7483
967.12622	2.8273678	1.1106817	3510.5732
968.0271	2.8267858	1.112545	3510.9351
968.92798	2.8280675	1.114866	3508.6252
969.82886	2.8309073	1.1172791	3507.9429
970.72974	2.8349373	1.119962	3509.3125
971.63062	2.8379369	1.1227547	3503.8367
972.53149	2.8379376	1.1254841	3499.9927
973.43237	2.8391688	1.1280963	3500.929
974.33325	2.8467929	1.1305015	3496.5603
975.23413	2.8451478	1.1329658	3499.7429
976.13501	2.8492086	1.1356876	3500.3506
977.03589	2.8552251	1.1386241	3508.8826
977.93677	2.8586433	1.1415035	3496.657
978.83765	2.8601992	1.1439034	3503.2644
979.73853	2.860291	1.1467383	3491.2727
980.6394	2.8645136	1.1492038	3499.5403
981.54028	2.8678668	1.1514521	3499.8374
982.44116	2.8712683	1.1539198	3501.7659
983.34204	2.869714	1.1563029	3497.0334
984.24292	2.8744333	1.1588601	3488.9595
985.1438	2.8760819	1.161196	3490.293
986.04468	2.8823867	1.1637771	3498.0825
986.94556	2.8832731	1.1667478	3486.9736
987.84644	2.8846612	1.1690588	3483.8508
988.74731	2.8890343	1.1716112	3490.8171
989.64819	2.8935945	1.1746259	3493.8145
990.54907	2.8929219	1.1776584	3480.7949
991.44995	2.8972821	1.1809506	3487.4497
992.35083	2.9006732	1.1842	3489.1272
993.25171	2.9017634	1.1871848	3477.8035
994.15259	2.9078109	1.1901312	3486.3315
995.05347	2.9091609	1.193379	3479.4346
995.95435	2.9107473	1.1955403	3477.5808
996.85522	2.9128764	1.1981959	3481.1426
997.7561	2.9161084	1.2009637	3480.8503
998.65698	2.9176571	1.2041918	3479.6577
999.55786	2.9192431	1.2069706	3472.8418
1000.4587	2.9252207	1.2094554	3474.7822
1001.3596	2.9276106	1.21199	3477.8125
1002.2605	2.9297783	1.214385	3472.2366
1003.1614	2.9349592	1.2167648	3471.9192
1004.0623	2.933105	1.2190555	3472.3997
1004.9631	2.9392359	1.2215043	3474.7561
1005.864	2.9393363	1.2244402	3473.751
1006.7649	2.9437201	1.227684	3474.8164
1007.6658	2.9480829	1.2313417	3472.6086
1008.5667	2.9470892	1.2343293	3459.9661
1009.4675	2.952004	1.2364014	3463.0498
1010.3684	2.9546599	1.2384176	3461.2786
1011.2693	2.9532402	1.2403988	3456.3877
1012.1702	2.9587798	1.2422473	3456.3804
1013.071	2.9595892	1.2451026	3462.8552
1013.9719	2.9647534	1.2483715	3460.8528
1014.8728	2.9657588	1.2504898	3454.1335
1015.7737	2.9689353	1.2526013	3454.6106
1016.6746	2.9730868	1.2555709	3454.2791
1017.5754	2.9762051	1.2585503	3455.9214
1018.4763	2.9775414	1.2620403	3447.6196
1019.3772	2.9781604	1.2656091	3449.6274
1020.2781	2.9830105	1.2683713	3444.8384
1021.179	2.9848888	1.2711238	3446.6953
1022.0798	2.9854212	1.273819	3442.6687
1022.9807	2.9865539	1.276026	3440.2126
1023.8816	2.9965053	1.2782866	3433.3906
1024.7825	2.9953377	1.2802508	3433.05
1025.6833	2.994781	1.2823431	3438.9185
1026.5842	3.0029404	1.2847223	3438.2549
1027.4851	3.0040832	1.2874713	3436.7627
1028.386	3.0067599	1.2901061	3438.158
1029.2869	3.0098152	1.2933717	3439.5293
1030.1877	3.015769	1.2970761	3442.2314
1031.0886	3.0148952	1.3002733	3428.9226
1031.9895	3.0170298	1.3035901	3427.7905
1032.8904	3.0209429	1.3067724	3426.1621
1033.7913	3.0257037	1.3091601	3427.9561
1034.6921	3.0251863	1.3119167	3426.0564
1035.593	3.0259466	1.3147898	3423.769
1036.4939	3.0296831	1.3173586	3414.5647
1037.3948	3.0341055	1.319765	3419.0344
1038.2957	3.0376096	1.3225645	3417.7849
1039.1965	3.0374982	1.3254136	3415.4009
1040.0974	3.0424907	1.3280721	3417.5349
1040.9983	3.0441747	1.3308765	3413.1929
1041.8992	3.0470958	1.3337101	3414.8997
1042.8	3.0503314	1.336724	3403.9863
1043.7009	3.0516579	1.3389082	3400.4822
1044.6018	3.0528042	1.3409449	3407.0574
1045.5027	3.0570416	1.3439366	3397.5635
1046.4036	3.0600836	1.3469139	3398.395
1047.3044	3.065506	1.349471	3395.6028
1048.2053	3.0688763	1.3516434	3399.7922
1049.1062	3.0700641	1.354059	3400.282
1050.0071	3.0728974	1.3573161	3397.8269
1050.908	3.0760746	1.3607267	3399.8047
1051.8088	3.0808051	1.363269	3389.1326
1052.7097	3.079803	1.3656737	3384.2188
1053.6106	3.0832627	1.3685204	3390.6477
1054.5115	3.086509	1.3714355	3385.3103
1055.4124	3.0866244	1.3740643	3381.6924
1056.3132	3.0931168	1.3767393	3378.9189
1057.2141	3.0929267	1.3790953	3380.3333
1058.115	3.0953128	1.3813564	3369.6609
1059.0159	3.0995479	1.3839533	3375.0645
1059.9167	3.0990417	1.3861817	3368.603
1060.8176	3.103559	1.3890816	3369.1533
1061.7185	3.1056724	1.3916118	3370.8433
1062.6194	3.1116364	1.3945436	3370.2419
1063.5203	3.1128294	1.3974333	3356.6931
1064.4211	3.1172202	1.4006119	3365.5447
1065.322	3.1178329	1.4038646	3357.2571
1066.2229	3.1198533	1.406865	3354.4578
1067.1238	3.1260591	1.409718	3353.897
1068.0247	3.1246965	1.4124866	3349.688
1068.9255	3.1284111	1.4157559	3344.2534
1069.8264	3.1342168	1.4186747	3348.9172
1070.7273	3.1352589	1.4219004	3340.3169
1071.6282	3.13762	1.424764	3333.2498
1072.5291	3.1379542	1.427192	3335.8538
1073.4299	3.1411653	1.4297286	3336.825
1074.3308	3.1465914	1.4326024	3333.9944
1075.2317	3.1481218	1.4351964	3326.2898
1076.1326	3.1475356	1.4383302	3326.6389
1077.0334	3.1526682	1.4407874	3321.3904
1077.9343	3.1567464	1.4430465	3318.592
1078.8352	3.1593468	1.4454967	3318.0115
1079.7361	3.1635559	1.4483321	3321.6877
1080.637	3.1624436	1.4515554	3314.7107
1081.5378	3.164649	1.4547557	3307.6296
1082.4387	3.172292	1.4578193	3309.8245
1083.3396	3.1715806	1.4604744	3304.238
1084.2405	3.177036	1.4629835	3303.9741
1085.1414	3.1773186	1.4660835	3299.3672
1086.0422	3.1811848	1.4687947	3292.5237
1086.9431	3.1841831	1.4718267	3293.0317
1087.844	3.1878917	1.4752002	3288.7603
1088.7449	3.1901817	1.4784633	3292.2625
1089.6458	3.189117	1.4819158	3286.4353
1090.5466	3.195725	1.4857842	3287.3059
1091.4475	3.1973808	1.489435	3274.4583
1092.3484	3.1997325	1.4915785	3266.1897
1093.2493	3.2022762	1.4946125	3274.3379
1094.1501	3.2067192	1.497997	3268.7473
1095.051	3.2071595	1.5006431	3260.3755
1095.9519	3.2074699	1.5037022	3254.0894
1096.8528	3.2154026	1.5069846	3253.5674
1097.7537	3.2172079	1.5101804	3245.3025
1098.6545	3.2204826	1.5128323	3237.8208
1099.5554	3.2223005	1.5162047	3239.0918
1100.4563	3.2220442	1.5194416	3232.3694
1101.3572	3.2272975	1.5225621	3230.5496
1102.2581	3.2305696	1.5262473	3215.3049
1103.1589	3.2317057	1.5289576	3202.4158
1104.0598	3.2339091	1.5312372	3202.8872
1104.9607	3.2380409	1.5342433	3199.4971
1105.8616	3.2421844	1.5375488	3182.0962
1106.7625	3.2453787	1.5407585	3170.4822
1107.6633	3.2456179	1.5444267	3150.113
1108.0637	3.248924	1.5476533	3130.2751