File: datasets/am_bench_2022/raw_data/60-X.14-2/specimen.dat
MTS793|MPT|ENU|1|2|.|/|:|1|0|0|A

Operator Information						Time:	20.696533	Sec	11/1/2021 12:06:59 PM
Operator	Nick Derimow
Project	AM Bench 2022 mini-tensile challenge
Specimen ID	60-X.14-2
Material	PBF-L Inconel 625
Specimen Width	2.55	mm
Specimen Thickness	1.52	mm
Notes
Operator Information End

Data Acquisition						Time:	1021.6895	Sec	11/1/2021 12:23:40 PM
Time	Axial Displacement	Axial Extensometer	Axial Force
Sec	mm	mm	N
20.809326	-0.0013116273	4.3276559e-05	42.838398
21.710205	0.0031799411	-5.4787331e-05	54.222977
22.611084	0.0050925985	7.3424213e-05	63.327454
23.511963	0.0096294479	0.00015701461	83.554047
24.412842	0.012139926	9.7507102e-05	95.935722
25.313721	0.011601882	0.00030757874	105.99524
26.2146	0.015413008	0.00038800255	117.92471
27.115479	0.018295618	0.00054399524	131.00928
28.016357	0.018605413	0.0005240317	142.1322
28.917236	0.024485067	0.0006792018	152.8535
29.818115	0.028671963	0.00063161482	166.28998
30.718994	0.029103259	0.00071041484	180.06453
31.619873	0.032654632	0.00061549398	191.25012
32.520752	0.034592032	0.00084643584	207.39607
33.421631	0.03925202	0.0010056597	226.68718
34.32251	0.041184705	0.00086157728	241.03896
35.223389	0.043027904	0.0011841259	257.29205
36.124268	0.046798103	0.0009809006	281.24359
37.025146	0.04716916	0.0012680973	294.45111
37.926025	0.048980549	0.0011559739	317.50604
38.826904	0.052916046	0.0015022723	334.12103
39.727783	0.053518631	0.0013957219	355.42419
40.628662	0.058531236	0.0014874833	375.97153
41.529541	0.062453616	0.0016798739	394.88779
42.43042	0.064315259	0.0016436861	414.02084
43.331299	0.067663945	0.0017652345	427.68695
44.232178	0.068617657	0.0018618519	445.30344
45.133057	0.07302507	0.0019911453	467.74396
46.033936	0.072874472	0.0019386358	488.97913
46.934814	0.074893214	0.0020116754	504.80151
47.835693	0.079497062	0.0021086482	528.03833
48.736572	0.082985692	0.0022217347	555.42102
49.637451	0.083529882	0.0022864055	572.38239
50.53833	0.087649211	0.0023666683	590.56873
51.439209	0.091438413	0.0024619827	615.42712
52.340088	0.092804372	0.0025681234	640.13159
53.240967	0.098116122	0.0027755243	668.96625
54.141846	0.099944979	0.0028466736	688.69269
55.042725	0.10003226	0.0028874879	701.60382
55.943604	0.10402308	0.0030297129	733.70117
56.844482	0.10660403	0.0031735566	759.25519
57.745361	0.10828266	0.0032560078	786.64948
58.64624	0.10948598	0.0033890507	801.97394
59.547119	0.11415052	0.0034637775	831.87915
60.447998	0.11604387	0.0036552993	862.17401
61.348877	0.11893955	0.0036834145	877.42981
62.249756	0.12434636	0.0038498987	910.54755
63.150635	0.12521428	0.0039184708	932.01233
64.051514	0.12766416	0.0041069766	959.88586
64.952393	0.13123803	0.00425734	994.13947
65.853271	0.13036191	0.0042673796	1019.4941
66.75415	0.13503543	0.0044977898	1045.5623
67.655029	0.14173838	0.004638474	1074.8636
68.555908	0.14394623	0.0047311452	1105.6919
69.456787	0.14264108	0.0048438576	1120.0183
70.357666	0.15106425	0.0049498025	1147.7822
71.258545	0.15232699	0.0050883316	1167.6697
72.159424	0.15332563	0.0051481626	1197.0333
73.060303	0.15699497	0.0052305451	1212.6238
73.961182	0.15764652	0.0053896196	1239.303
74.862061	0.16062927	0.0055802725	1269.2896
75.762939	0.15991113	0.0056186118	1292.1606
76.663818	0.16758855	0.00573612	1309.5538
77.564697	0.16771045	0.0058440831	1329.4053
78.465576	0.17265807	0.0059218709	1358.6414
79.366455	0.17591844	0.006043273	1382.8285
80.267334	0.17673248	0.0061351769	1408.1945
81.168213	0.18001114	0.0061948975	1430.8354
82.069092	0.18035577	0.0063750572	1455.0613
82.969971	0.18310003	0.0064503155	1479.4543
83.87085	0.18466458	0.006569054	1509.0244
84.771729	0.19005679	0.006761333	1536.3013
85.672607	0.19351637	0.0067842929	1560.2841
86.573486	0.19301726	0.0068669366	1578.3911
87.474365	0.19874801	0.0070539839	1602.3207
88.375244	0.2031842	0.0071463641	1628.6908
89.276123	0.20402324	0.0073122294	1654.5127
90.177002	0.20591499	0.0074159238	1680.1232
91.077881	0.20739943	0.0074973502	1695.8389
91.97876	0.21075201	0.0076531773	1725.8794
92.879639	0.21478605	0.0076815984	1745.9076
93.780518	0.21537389	0.0078741573	1765.8938
94.681396	0.2185812	0.0079465108	1789.9559
95.582275	0.22140624	0.0080289422	1808.8639
96.483154	0.22621657	0.0081029106	1837.0138
97.384033	0.22837652	0.0082339495	1866.2461
98.284912	0.22937635	0.0083981268	1881.7822
99.185791	0.23733118	0.008462389	1899.285
100.08667	0.23610879	0.0084820446	1911.392
100.98755	0.23837715	0.0085479161	1930.5795
101.88843	0.24407466	0.0087287808	1950.0349
102.78931	0.24313052	0.0087910378	1959.6582
103.69019	0.25072742	0.0088977264	1980.2526
104.59106	0.24982958	0.0089245019	2000.8875
105.49194	0.25265804	0.0090036588	2018.3821
106.39282	0.25606391	0.0091781905	2034.2793
107.2937	0.25721681	0.0092908265	2053.6387
108.19458	0.26190412	0.0093139382	2062.6755
109.09546	0.26479548	0.0094083212	2082.574
109.99634	0.26781759	0.0094851591	2093.6531
110.89722	0.26928562	0.0095574483	2100.2205
111.7981	0.27389029	0.009509935	2107.501
112.69897	0.27539727	0.0096450094	2123.636
113.59985	0.27697158	0.0097926939	2128.1404
114.50073	0.28128469	0.0098460745	2144.8694
115.40161	0.28184447	0.009840182	2156.3569
116.30249	0.28566521	0.0098632164	2169.24
117.20337	0.28978592	0.010112573	2181.3782
118.10425	0.29001355	0.010072134	2183.8745
119.00513	0.29644623	0.010137701	2202.8201
119.90601	0.29609817	0.010246488	2208.4314
120.80688	0.2993862	0.010303214	2218.1228
121.70776	0.30131894	0.010443686	2228.8635
122.60864	0.30554393	0.010426233	2242.7927
123.50952	0.30564597	0.01053405	2244.1445
124.4104	0.30708775	0.0105263	2252.7849
125.31128	0.31364974	0.010636686	2260.4512
126.21216	0.31535503	0.010694227	2272.1926
127.11304	0.31896353	0.010830983	2276.2351
128.01392	0.32100195	0.010835744	2286.1406
128.91479	0.32289287	0.01097547	2301.2839
129.81567	0.32464281	0.010945261	2305.5476
130.71655	0.33032519	0.011140451	2316.5574
131.61743	0.33194384	0.011253839	2330.3525
132.51831	0.3321057	0.011395963	2333.3418
133.41919	0.33662897	0.011448562	2344.4385
134.32007	0.33872071	0.011423504	2348.5667
135.22095	0.3443279	0.01160826	2366.8965
136.12183	0.34923685	0.01172449	2374.1609
137.02271	0.34651411	0.011779948	2375.4829
137.92358	0.34962755	0.011861596	2385.3394
138.82446	0.35336944	0.011964524	2389.3459
139.72534	0.35540748	0.012040907	2405.6445
140.62622	0.35879427	0.012094817	2406.4128
141.5271	0.36197272	0.012309786	2418.8279
142.42798	0.36323607	0.012362368	2423.1948
143.32886	0.36453441	0.012495386	2432.4485
144.22974	0.36987489	0.012566663	2436.6768
145.13062	0.37264496	0.012628523	2439.9336
146.03149	0.3751829	0.012888647	2451.6741
146.93237	0.37609076	0.01291876	2461.3354
147.83325	0.37906635	0.013033793	2461.334
148.73413	0.38419574	0.013155653	2482.8965
149.63501	0.3850815	0.013315408	2480.4929
150.53589	0.38942185	0.01346169	2488.3787
151.43677	0.39388308	0.013636013	2498.0476
152.33765	0.39404619	0.013736458	2503.4788
153.23853	0.39808023	0.013812997	2506.4648
154.1394	0.39753953	0.014103381	2517.8328
155.04028	0.4038347	0.014306865	2526.4131
155.94116	0.4061895	0.014570646	2531.8291
156.84204	0.40961385	0.014593078	2540.6167
157.74292	0.41101834	0.014792593	2537.8328
158.6438	0.41181555	0.014971052	2545.031
159.54468	0.41542754	0.015295153	2559.8894
160.44556	0.41938597	0.015456855	2560.4509
161.34644	0.41992915	0.015551637	2566.1169
162.24731	0.42508498	0.015813194	2578.8738
163.14819	0.42602602	0.016085273	2583.6504
164.04907	0.43125537	0.016355092	2591.5112
164.94995	0.43021333	0.016715642	2593.7307
165.85083	0.4329828	0.017070996	2596.0317
166.75171	0.43791735	0.017277168	2596.2769
167.65259	0.4426595	0.017430469	2609.3303
168.55347	0.44531605	0.017944818	2615.9414
169.45435	0.44656178	0.018289354	2622.593
170.35522	0.44902623	0.018674579	2624.2764
171.2561	0.45070264	0.019100705	2635.2095
172.15698	0.45696503	0.01948588	2645.8142
173.05786	0.45548305	0.019889886	2643.0081
173.95874	0.45745897	0.020153513	2647.9839
174.85962	0.46452603	0.020582002	2647.0945
175.7605	0.46471512	0.0209981	2659.7344
176.66138	0.4679378	0.021429535	2661.6323
177.56226	0.47115946	0.021857884	2665.4573
178.46313	0.47466248	0.022411944	2672.0781
179.36401	0.476569	0.022850662	2681.7666
180.26489	0.47565314	0.023219015	2675.2092
181.16577	0.48247015	0.023821512	2690.8071
182.06665	0.48404536	0.024315879	2692.0229
182.96753	0.48585409	0.024820836	2695.7598
183.86841	0.48808065	0.025315722	2691.7705
184.76929	0.49233207	0.025797863	2693.8657
185.67017	0.49555781	0.026210463	2701.3645
186.57104	0.50012994	0.026863948	2706.0903
187.47192	0.49885428	0.02729995	2712.7173
188.3728	0.50273162	0.027995965	2714.4597
189.27368	0.50669253	0.02850402	2719.1404
190.17456	0.50954252	0.02920378	2728.1748
191.07544	0.50777024	0.029857174	2730.1318
191.97632	0.51477104	0.030487111	2737.5286
192.8772	0.51866084	0.031237882	2735.1135
193.77808	0.52043623	0.031870827	2747.0493
194.67896	0.5177334	0.032499541	2736.4275
195.57983	0.52379763	0.032994345	2740.8457
196.48071	0.52663165	0.033706903	2752.856
197.38159	0.53084624	0.034481268	2761.5449
198.28247	0.53137255	0.035229784	2755.1521
199.18335	0.534702	0.035851598	2753.9507
200.08423	0.53981972	0.036411982	2766.2043
200.98511	0.53834492	0.037186693	2766.2034
201.88599	0.54299939	0.037917983	2767.8711
202.78687	0.54618257	0.038774215	2772.2856
203.68774	0.54680252	0.039590377	2772.1638
204.58862	0.54949784	0.040183909	2775.4932
205.4895	0.55445433	0.040856838	2782.3806
206.39038	0.55548632	0.041790418	2785.1321
207.29126	0.55899954	0.042574272	2788.5613
208.19214	0.55960274	0.043350175	2787.5515
209.09302	0.56580061	0.044103447	2795.0864
209.9939	0.56793922	0.044874828	2797.9509
210.89478	0.56882703	0.045592483	2796.4653
211.79565	0.57386631	0.046353634	2801.0847
212.69653	0.5795064	0.047169767	2809.7385
213.59741	0.57983935	0.048056316	2811.5986
214.49829	0.5803805	0.04879187	2811.4685
215.39917	0.58653373	0.049591891	2818.175
216.30005	0.58770567	0.050478894	2814.0417
217.20093	0.5890618	0.051293451	2815.0667
218.10181	0.59304303	0.052226279	2823.583
219.00269	0.59717625	0.053027183	2827.4414
219.90356	0.59968656	0.053843018	2825.0125
220.80444	0.60056758	0.054625295	2826.1536
221.70532	0.60413098	0.055422619	2827.3447
222.6062	0.60622019	0.056295004	2829.8188
223.50708	0.60954064	0.057288889	2836.1765
224.40796	0.60814536	0.058064505	2836.3325
225.30884	0.61451232	0.058943007	2841.1265
226.20972	0.61463726	0.059598178	2839.2175
227.1106	0.62041736	0.06039444	2839.3606
228.01147	0.62177372	0.061306126	2840.7437
228.91235	0.62447566	0.062137887	2842.7053
229.81323	0.62758523	0.062952347	2853.6367
230.71411	0.63177127	0.063937739	2852.6968
231.61499	0.63330668	0.064990789	2861.8193
232.51587	0.63222283	0.065841019	2855.813
233.41675	0.63814867	0.066770568	2863.521
234.31763	0.6409415	0.067765914	2858.2361
235.21851	0.64228714	0.068601079	2858.9568
236.11938	0.64811277	0.0694286	2864.1016
237.02026	0.64806712	0.070378989	2869.0159
237.92114	0.65034914	0.071399033	2869.3071
238.82202	0.65485835	0.072373971	2869.821
239.7229	0.65756124	0.073240921	2876.2439
240.62378	0.66243201	0.074255504	2879.2083
241.52466	0.66133094	0.075128652	2880.8428
242.42554	0.66461372	0.076276146	2885.7114
243.32642	0.66922039	0.077361897	2888.6108
244.22729	0.67065752	0.078332089	2890.1233
245.12817	0.67105889	0.079486221	2892.6675
246.02905	0.6768986	0.080434792	2887.6758
246.92993	0.67801529	0.08149498	2895.8381
247.83081	0.68154794	0.082473442	2896.0808
248.73169	0.68581331	0.083534978	2889.6172
249.63257	0.68777472	0.084392816	2900.4985
250.53345	0.69217062	0.085469663	2901.5898
251.43433	0.69429266	0.08635851	2895.4934
252.33521	0.69851148	0.087060727	2899.3281
253.23608	0.697218	0.088067926	2908.4077
254.13696	0.70070785	0.08899074	2902.7871
255.03784	0.70711172	0.089860588	2910.2224
255.93872	0.70683122	0.090925314	2907.6755
256.8396	0.70782965	0.0918082	2907.6055
257.74048	0.71215934	0.092657462	2913.3018
258.64136	0.71315318	0.093730979	2915.7961
259.54224	0.71371686	0.094697654	2911.0156
260.44312	0.72102177	0.095874853	2921.9346
261.34399	0.72129571	0.096820422	2926.3337
262.24487	0.72320896	0.098112531	2923.5381
263.14575	0.72803283	0.099253438	2924.6287
264.04663	0.73125559	0.10023689	2923.7305
264.94751	0.7326175	0.10117254	2922.3806
265.84839	0.7345137	0.10204567	2924.2698
266.74927	0.73739958	0.10301688	2932.5818
267.65015	0.74293238	0.10402746	2934.7122
268.55103	0.74444669	0.10502782	2930.6089
269.4519	0.74837995	0.1057544	2938.2188
270.35278	0.74714917	0.10698269	2941.6453
271.25366	0.74925035	0.10812208	2938.749
272.15454	0.75311488	0.10919928	2935.5911
273.05542	0.75657302	0.11026499	2946.9861
273.9563	0.7617051	0.11137502	2945.5352
274.85718	0.76176614	0.11243057	2944.9021
275.75806	0.76354969	0.11330764	2943.5635
276.65894	0.76966339	0.11428453	2948.2437
277.55981	0.77232182	0.11526152	2948.1592
278.46069	0.77306575	0.11651494	2953.3982
279.36157	0.77684242	0.11738871	2949.4006
280.26245	0.77880961	0.11840428	2954.835
281.16333	0.78097051	0.11958092	2963.1978
282.06421	0.78619874	0.12064461	2961.2859
282.96509	0.78683752	0.12173506	2962.6384
283.86597	0.78746104	0.1228748	2963.0601
284.76685	0.79331034	0.12392828	2962.6187
285.66772	0.79473841	0.12490903	2964.7666
286.5686	0.7971971	0.12578216	2966.2893
287.46948	0.80083925	0.12681611	2966.3123
288.37036	0.80167049	0.12762751	2963.6575
289.27124	0.80772346	0.12863393	2966.5244
290.17212	0.80848747	0.12935784	2972.8345
291.073	0.81069028	0.13038148	2972.833
291.97388	0.81501526	0.13147138	2968.9543
292.87476	0.8155396	0.13225535	2977.7415
293.77563	0.81991434	0.13370349	2987.4771
294.67651	0.82319522	0.13481063	2979.3794
295.57739	0.82691455	0.13568036	2979.2085
296.47827	0.82785356	0.13671476	2977.6067
297.37915	0.83145201	0.13770694	2985.77
298.28003	0.83073121	0.13865906	2981.0559
299.18091	0.83632243	0.13971415	2989.1821
300.08179	0.83713973	0.14070502	2983.6885
300.98267	0.84353596	0.14182952	2988.0791
301.88354	0.84432417	0.14271598	2988.5049
302.78442	0.84401536	0.14383121	2990.1128
303.6853	0.85010427	0.14493465	2993.343
304.58618	0.85269737	0.14622493	2999.5217
305.48706	0.85567379	0.14731289	2994.7744
306.38794	0.85631794	0.14833227	2998.8982
307.28882	0.86163008	0.14949982	3007.3367
308.1897	0.86131907	0.15064588	2994.5017
309.09058	0.86360502	0.15174353	3007.9885
309.99146	0.86796319	0.15297994	3001.1062
310.89233	0.86961889	0.15404636	3000.6663
311.79321	0.87352204	0.15514736	3002.21
312.69409	0.87434769	0.15612039	3003.3894
313.59497	0.88057226	0.15732871	3011.333
314.49585	0.87998444	0.15816289	3008.2405
315.39673	0.88553548	0.15919891	3007.3833
316.29761	0.88765889	0.16021082	3019.2957
317.19849	0.88972932	0.16153321	3014.4165
318.09937	0.89299285	0.16265973	3018.6516
319.00024	0.89386261	0.16383392	3010.9478
319.90112	0.89724034	0.16487855	3015.4053
320.802	0.90194333	0.16587774	3020.3198
321.70288	0.90174437	0.16692853	3016.7693
322.60376	0.90641218	0.16788813	3019.8311
323.50464	0.90982485	0.1690231	3027.2021
324.40552	0.90939701	0.17006584	3025.532
325.3064	0.91187412	0.170949	3025.6414
326.20728	0.91788101	0.17200591	3031.4009
327.10815	0.92086011	0.17303598	3032.801
328.00903	0.92070013	0.17392619	3020.7061
328.90991	0.92362344	0.175135	3032.1323
329.81079	0.92800021	0.17613021	3029.7065
330.71167	0.92620647	0.17723067	3034.4451
331.61255	0.93215972	0.17830186	3033.7485
332.51343	0.93650991	0.17944665	3046.8621
333.41431	0.93852782	0.18060842	3039.4548
334.31519	0.93772674	0.18156151	3031.3896
335.21606	0.94205296	0.18246663	3037.5496
336.11694	0.94473559	0.18350817	3036.396
337.01782	0.95156693	0.18448754	3047.4841
337.9187	0.95082384	0.18569657	3048.4529
338.81958	0.95523894	0.18679427	3044.9668
339.72046	0.95847028	0.1879617	3055.1748
340.62134	0.96078825	0.1889637	3044.6169
341.52222	0.96150017	0.18994561	3050.657
342.4231	0.96351874	0.19093828	3047.1843
343.32397	0.96809405	0.19196323	3047.0742
344.22485	0.97139567	0.19300187	3055.9082
345.12573	0.97164583	0.19399649	3055.7761
346.02661	0.97549486	0.19506843	3054.5334
346.92749	0.98042083	0.1961887	3066.2563
347.82837	0.98215991	0.19734749	3059.2917
348.72925	0.98440385	0.19832647	3056.5554
349.63013	0.98644847	0.199258	3065.9619
350.53101	0.98921877	0.20035912	3063.7742
351.43188	0.99348575	0.20142812	3066.1257
352.33276	0.99465626	0.20263113	3071.2026
353.23364	0.99531227	0.20379207	3068.2534
354.13452	1.0038126	0.20489106	3070.9556
355.0354	1.002305	0.20610665	3070.2822
355.93628	1.0038878	0.20728016	3069.3604
356.83716	1.0113395	0.20828849	3068.7981
357.73804	1.0130215	0.20915793	3077.2454
358.63892	1.0155746	0.2101133	3074.5515
359.53979	1.0168449	0.21115556	3078.6672
360.44067	1.0201092	0.21221702	3078.5276
361.34155	1.0210422	0.21322599	3075.803
362.24243	1.0222592	0.2141701	3077.8035
363.14331	1.0279493	0.21552329	3082.8762
364.04419	1.0309353	0.21649756	3077.6106
364.94507	1.0319474	0.21728933	3075.9563
365.84595	1.0350347	0.21823968	3080.6365
366.74683	1.0372453	0.21907224	3078.5603
367.64771	1.0434562	0.22018184	3091.0117
368.54858	1.0441759	0.22124647	3085.988
369.44946	1.0485672	0.22230582	3089.0408
370.35034	1.0498	0.22322087	3091.3354
371.25122	1.0520809	0.22420603	3086.2495
372.1521	1.0534651	0.22521992	3089.2224
373.05298	1.0583451	0.2262744	3096.9146
373.95386	1.0572125	0.22719032	3090.927
374.85474	1.0621828	0.22823425	3097.689
375.75562	1.0659376	0.2294897	3100.3401
376.65649	1.0697531	0.230655	3101.2451
377.55737	1.0693716	0.23184852	3102.4424
378.45825	1.0746596	0.2327546	3095.9509
379.35913	1.0751337	0.23376058	3104.0391
380.26001	1.0785084	0.23483992	3105.2654
381.16089	1.0808581	0.23613474	3110.3721
382.06177	1.0842297	0.23732394	3108.5984
382.96265	1.0864961	0.23839976	3111.8569
383.86353	1.0912049	0.23969327	3110.3037
384.7644	1.093781	0.24073018	3116.7527
385.66528	1.0948204	0.2417649	3106.7109
386.56616	1.0948263	0.24263196	3103.6309
387.46704	1.0979031	0.24374074	3117.658
388.36792	1.1053891	0.24481945	3115.6594
389.2688	1.1045666	0.24575073	3120.2727
390.16968	1.1100744	0.24684517	3116.252
391.07056	1.1093698	0.24754949	3112.4329
391.97144	1.111851	0.24865046	3117.1926
392.87231	1.1186483	0.24966064	3123.6267
393.77319	1.1226227	0.25054705	3122.5313
394.67407	1.1223062	0.25146067	3120.4036
395.57495	1.1241764	0.25244609	3124.5024
396.47583	1.1240845	0.25350377	3125.2744
397.37671	1.1308181	0.25461215	3124.2236
398.27759	1.1310203	0.25556946	3129.5146
399.17847	1.1344953	0.25655815	3124.1023
400.07935	1.1366719	0.25754347	3128.666
400.98022	1.1414784	0.25857922	3128.8479
401.8811	1.1445711	0.25969732	3133.9641
402.78198	1.1444517	0.26077935	3132.1943
403.68286	1.1497283	0.26176375	3131.2781
404.58374	1.1512275	0.26283082	3141.323
405.48462	1.1540639	0.26387924	3130.3936
406.3855	1.15888	0.26503357	3144.1777
407.28638	1.1606596	0.26603526	3139.3286
408.18726	1.1644716	0.2672517	3146.2227
409.08813	1.1682678	0.2684173	3143.8904
409.98901	1.167578	0.26948518	3146.0491
410.88989	1.1692463	0.27035049	3140.439
411.79077	1.1744193	0.27125269	3143.9717
412.69165	1.1750203	0.27248168	3151.8875
413.59253	1.1777683	0.27337626	3139.1538
414.49341	1.1818917	0.27428362	3153.2771
415.39429	1.1839674	0.27537984	3156.0601
416.29517	1.1869879	0.27643076	3154.1675
417.19604	1.1913412	0.2776387	3157.7373
418.09692	1.1936388	0.2787571	3155.8572
418.9978	1.1975689	0.27956754	3156.0144
419.89868	1.1986287	0.28069037	3153.8965
420.79956	1.19832	0.2816163	3150.6238
421.70044	1.2012864	0.28272271	3157.4507
422.60132	1.2081949	0.28383616	3162.1792
423.5022	1.2086571	0.28496608	3162.1851
424.40308	1.2114981	0.28618854	3162.4417
425.30396	1.2132208	0.28718999	3160.0984
426.20483	1.2159569	0.28836477	3164.2571
427.10571	1.2186983	0.2892682	3164.0195
428.00659	1.2224038	0.29031998	3163.3792
428.90747	1.2273872	0.29131112	3170.6638
429.80835	1.2284154	0.29247919	3173.0022
430.70923	1.2301842	0.29355404	3167.4143
431.61011	1.2333418	0.29457986	3168.6289
432.51099	1.2352867	0.29549721	3168.5068
433.41187	1.2360913	0.29663959	3168.6826
434.31274	1.2386292	0.29748362	3167.5935
435.21362	1.2446669	0.2984364	3171.2441
436.1145	1.2477722	0.29941148	3175.5593
437.01538	1.2479975	0.30027041	3165.9089
437.91626	1.2534628	0.30109406	3168.605
438.81714	1.2526264	0.3017455	3180.1409
439.71802	1.2575251	0.30274054	3175.0906
440.6189	1.2628644	0.30367199	3186.28
441.51978	1.2621318	0.30475345	3181.9976
442.42065	1.2647675	0.30577385	3180.0215
443.32153	1.2711688	0.30680111	3183.4976
444.22241	1.2708541	0.30801356	3185.6333
445.12329	1.2724544	0.30903393	3182.7827
446.02417	1.2769133	0.31013182	3187.4939
446.92505	1.2786106	0.31113532	3187.2449
447.82593	1.2823443	0.31235573	3190.1746
448.72681	1.2844094	0.31337827	3188.8069
449.62769	1.2912198	0.31440818	3188.5757
450.52856	1.2921927	0.31543407	3189.9497
451.42944	1.2896336	0.31662428	3185.2449
452.33032	1.2956713	0.31752658	3192.8689
453.2312	1.2988534	0.31852788	3191.1528
454.13208	1.2989001	0.31964356	3192.0837
455.03296	1.304471	0.32071418	3198.1387
455.93384	1.3084391	0.32187179	3196.3538
456.83472	1.3075147	0.32279396	3194.2119
457.7356	1.3103452	0.32381618	3200.4629
458.63647	1.3150038	0.32484499	3199.9543
459.53735	1.3151401	0.32574779	3198.0652
460.43823	1.3171036	0.32684666	3205.304
461.33911	1.3205413	0.32772189	3203.5825
462.23999	1.3242035	0.3289946	3210.0798
463.14087	1.3269645	0.33004504	3207.5122
464.04175	1.32945	0.33103853	3205.1072
464.94263	1.3320282	0.33208403	3206.0154
465.84351	1.3364196	0.33311322	3211.8413
466.74438	1.3412125	0.3343204	3218.271
467.64526	1.3396832	0.33540165	3202.3713
468.54614	1.3443134	0.33638382	3215.405
469.44702	1.3467857	0.3372528	3211.0664
470.3479	1.3479998	0.33842769	3211.9517
471.24878	1.3532305	0.33956751	3220.3264
472.14966	1.351891	0.34064457	3213.0991
473.05054	1.3561226	0.34153205	3214.7529
473.95142	1.3581458	0.34261686	3212.7078
474.85229	1.3631473	0.34365532	3214.449
475.75317	1.3627502	0.34462816	3216.2004
476.65405	1.3682096	0.34581411	3220.2671
477.55493	1.3705517	0.34693652	3222.5044
478.45581	1.3738037	0.34797725	3221.6624
479.35669	1.3768437	0.34890348	3221.906
480.25757	1.3807406	0.34965992	3217.9543
481.15845	1.382942	0.35045207	3222.9592
482.05933	1.3856889	0.35159838	3228.1616
482.96021	1.3862697	0.3527045	3225.7556
483.86108	1.3872266	0.35377496	3230.0103
484.76196	1.3940951	0.3547526	3223.2471
485.66284	1.393849	0.35575619	3223.9167
486.56372	1.3982893	0.35669935	3238.7339
487.4646	1.4008496	0.35778299	3235.7773
488.36548	1.4053862	0.35900632	3243.8843
489.26636	1.4084688	0.36001903	3234.322
490.16724	1.4037795	0.3610957	3230.7354
491.06812	1.4149594	0.36213461	3243.5403
491.96899	1.4125662	0.36326006	3239.7883
492.86987	1.415995	0.36438009	3237.8901
493.77075	1.421971	0.36539319	3240.4751
494.67163	1.4248736	0.36637169	3231.7378
495.57251	1.426432	0.36737061	3244.4504
496.47339	1.424898	0.36850742	3246.7581
497.37427	1.4307017	0.36962834	3242.1025
498.27515	1.4326451	0.37067831	3249.8633
499.17603	1.4382468	0.37161562	3243.6497
500.0769	1.4367914	0.37247771	3241.748
500.97778	1.4420701	0.37361294	3250.9907
501.87866	1.4452436	0.37446219	3238.4844
502.77954	1.4447752	0.37559423	3247.04
503.68042	1.4493603	0.37682912	3248.0056
504.5813	1.4526622	0.37803182	3254.71
505.48218	1.4531038	0.37898952	3242.9717
506.38306	1.4544934	0.38003963	3250.3396
507.28394	1.4609101	0.38107419	3251.1746
508.18481	1.4609009	0.38193515	3250.4614
509.08569	1.466005	0.38281971	3248.8904
509.98657	1.4709197	0.38368127	3251.5149
510.88745	1.4715948	0.38446793	3253.4744
511.78833	1.4729282	0.38549593	3258.8127
512.68921	1.475664	0.38628596	3257.8496
513.59009	1.4782612	0.38747019	3263.8091
514.49097	1.4829887	0.38862887	3260.7639
515.39185	1.4841645	0.38980755	3264.0601
516.29272	1.4869094	0.39091474	3266.1548
517.1936	1.4891261	0.39208794	3261.2039
518.09448	1.4903408	0.39307028	3263.3
518.99536	1.4938565	0.39413446	3257.7878
519.89624	1.499559	0.39543211	3266.8604
520.79712	1.5036173	0.39656052	3266.0313
521.698	1.5025281	0.3975513	3262.9353
522.59888	1.5056266	0.39855263	3264.6099
523.49976	1.5094646	0.39944842	3266.9341
524.40063	1.5108881	0.40050766	3271.1907
525.30151	1.514702	0.4016037	3272.3213
526.20239	1.5160401	0.40246901	3264.4307
527.10327	1.5208139	0.40364632	3273.4189
528.00415	1.5209775	0.40471354	3269.1504
528.90503	1.5250655	0.40573522	3273.168
529.80591	1.5272801	0.40685701	3273.1704
530.70679	1.5291349	0.40787566	3275.5686
531.60767	1.531893	0.40879288	3276.4021
532.50854	1.5352354	0.40998992	3283.55
533.40942	1.538267	0.41124889	3282.2717
534.3103	1.5428028	0.41233599	3281.2466
535.21118	1.5442221	0.41338366	3278.7214
536.11206	1.5474628	0.41446188	3282.2207
537.01294	1.5489563	0.41550475	3284.4019
537.91382	1.5529219	0.41645285	3282.3108
538.8147	1.5550195	0.41752389	3281.4478
539.71558	1.5584923	0.41859436	3285.0212
540.61646	1.5612093	0.41970888	3288.6736
541.51733	1.5610557	0.42092079	3292.8594
542.41821	1.5663536	0.42182404	3283.5027
543.31909	1.5682127	0.42289919	3288.9421
544.21997	1.5723834	0.42393064	3289.5557
545.12085	1.5761755	0.42492086	3288.0286
546.02173	1.5786442	0.42586592	3289.4292
546.92261	1.582689	0.4268679	3294.2476
547.82349	1.5844336	0.42772537	3293.2332
548.72437	1.5821443	0.42876604	3297.45
549.62524	1.5878263	0.43002343	3298.834
550.52612	1.5880035	0.43094733	3294.5046
551.427	1.5933777	0.43208212	3299.532
552.32788	1.5955075	0.43308505	3294.5217
553.22876	1.5994879	0.43407083	3297.4744
554.12964	1.5982652	0.43519154	3298.0181
555.03052	1.6030587	0.43615946	3295.4604
555.9314	1.6056559	0.43734306	3300.7798
556.83228	1.6056856	0.43830657	3296.0371
557.73315	1.6112114	0.43933231	3299.1165
558.63403	1.6115392	0.4404788	3299.0476
559.53491	1.6162865	0.44154498	3305.7517
560.43579	1.6207105	0.44284534	3310.3101
561.33667	1.6215612	0.44400355	3304.5115
562.23755	1.6258669	0.44504255	3305.665
563.13843	1.6270571	0.44602001	3300.3389
564.03931	1.6285266	0.4472236	3307.3455
564.94019	1.6339418	0.4483647	3310.7991
565.84106	1.6350224	0.44945404	3306.2234
566.74194	1.637427	0.45051995	3314.0847
567.64282	1.6445478	0.45164061	3314.4351
568.5437	1.6457987	0.45270929	3315.8872
569.44458	1.6468705	0.45353696	3309.5557
570.34546	1.6486967	0.45456752	3313.5122
571.24634	1.6487261	0.45562905	3311.9487
572.14722	1.6554852	0.45673719	3314.1584
573.0481	1.6593062	0.45771831	3317.0549
573.94897	1.660597	0.45876509	3314.0303
574.84985	1.6616343	0.4599663	3321.1797
575.75073	1.6670097	0.4609448	3312.2073
576.65161	1.6663067	0.46222076	3311.7617
577.55249	1.6682385	0.46326843	3312.9673
578.45337	1.6729972	0.46437144	3318.594
579.35425	1.6748092	0.46556094	3324.5396
580.25513	1.6797318	0.46661699	3320.8315
581.15601	1.6817492	0.46770969	3322.3672
582.05688	1.6856543	0.46881253	3320.9714
582.95776	1.6891398	0.46976793	3323.5518
583.85864	1.6899592	0.47069252	3323.083
584.75952	1.692538	0.47178131	3321.7144
585.6604	1.6960517	0.47273651	3323.2822
586.56128	1.6965386	0.47388849	3323.0344
587.46216	1.7004039	0.47484228	3330.2725
588.36304	1.7016122	0.47588927	3322.3782
589.26392	1.7060435	0.47696826	3329.969
590.16479	1.7092316	0.4780255	3327.3396
591.06567	1.7110887	0.47874963	3320.6836
591.96655	1.7156056	0.47994456	3333.2349
592.86743	1.7182676	0.48083419	3326.3728
593.76831	1.7201568	0.48205563	3334.7458
594.66919	1.7209694	0.48325667	3334.116
595.57007	1.7236012	0.48458809	3334.7964
596.47095	1.7276891	0.48574254	3335.2915
597.37183	1.7301265	0.4868919	3336.5564
598.27271	1.7342019	0.48787344	3339.0962
599.17358	1.7345377	0.48900265	3331.72
600.07446	1.7385395	0.49015263	3342.4326
600.97534	1.7436619	0.49127048	3344.6816
601.87622	1.742968	0.49260569	3340.5388
602.7771	1.7456868	0.4937624	3333.397
603.67798	1.748896	0.4948363	3335.1929
604.57886	1.7518392	0.49596435	3339.489
605.47974	1.7511352	0.49712124	3340.5601
606.38062	1.7588499	0.49810544	3341.1675
607.28149	1.7591548	0.49933273	3339.3909
608.18237	1.7623788	0.50032586	3339.9102
609.08325	1.7641165	0.50160432	3340.9727
609.98413	1.7689929	0.50282323	3346.3928
610.88501	1.7701732	0.50371438	3340.2771
611.78589	1.7743896	0.50490975	3344.5386
612.68677	1.775799	0.50596595	3345.5044
613.58765	1.7790211	0.50696182	3343.3328
614.48853	1.7808222	0.5077672	3340.5112
615.3894	1.7855051	0.50864792	3347.438
616.29028	1.7864823	0.50946438	3343.9285
617.19116	1.7856023	0.51066005	3350.7529
618.09204	1.7937936	0.51182461	3356.9409
618.99292	1.7931085	0.51300234	3347.3535
619.8938	1.7968489	0.51425618	3354.8552
620.79468	1.7996918	0.51572168	3360.8298
621.69556	1.8054117	0.51708227	3354.5691
622.59644	1.8035924	0.51824343	3347.4214
623.49731	1.8076599	0.51898354	3345.739
624.39819	1.8121619	0.52001101	3350.7029
625.29907	1.8114599	0.52117372	3355.1648
626.19995	1.8165295	0.52220213	3354.9766
627.10083	1.8169792	0.52340519	3356.8186
628.00171	1.8217757	0.52468872	3364.9536
628.90259	1.8239454	0.52612942	3358.2043
629.80347	1.8260968	0.52717501	3356.3589
630.70435	1.8284199	0.52828449	3361.4453
631.60522	1.8328069	0.52939641	3361.418
632.5061	1.8346349	0.53046674	3357.5867
633.40698	1.8412746	0.53166682	3365.7671
634.30786	1.8398229	0.53278846	3359.8237
635.20874	1.8437934	0.53392452	3359.9988
636.10962	1.8466842	0.53524441	3367.7332
637.0105	1.8489816	0.53628057	3361.3882
637.91138	1.8523561	0.5373081	3358.9968
638.81226	1.854583	0.53848046	3368.7874
639.71313	1.8565072	0.53931242	3366.0171
640.61401	1.8619353	0.54055148	3370.7183
641.51489	1.862571	0.5417425	3373.6204
642.41577	1.8638946	0.54281855	3362.5525
643.31665	1.8667911	0.54386353	3365.5183
644.21753	1.8699048	0.54491568	3368.2915
645.11841	1.8743972	0.54596359	3370.7314
646.01929	1.8757643	0.54719841	3376.9846
646.92017	1.8770106	0.54862183	3375.9004
647.82104	1.8808297	0.54993039	3372.4954
648.72192	1.8800206	0.5511536	3371.6855
649.6228	1.885514	0.55217171	3364.4375
650.52368	1.8895611	0.5533486	3369.7585
651.42456	1.892767	0.55414414	3365.6843
652.32544	1.8948102	0.55533385	3377.1194
653.22632	1.897366	0.5563814	3375.1931
654.1272	1.9027647	0.55757874	3375.8213
655.02808	1.9031898	0.55874389	3376.7017
655.92896	1.908046	0.5597744	3375.1289
656.82983	1.9094491	0.56101465	3379.9595
657.73071	1.9122777	0.56227952	3382.0676
658.63159	1.9119914	0.5635609	3378.844
659.53247	1.9151112	0.56492317	3382.3977
660.43335	1.9206854	0.56603205	3378.5852
661.33423	1.9232109	0.56703591	3376.6941
662.23511	1.9233127	0.5679484	3375.9292
663.13599	1.9302974	0.5692187	3385.1069
664.03687	1.9319437	0.57033974	3381.6316
664.93774	1.9346447	0.5711965	3382.0303
665.83862	1.9326038	0.57266569	3388.3362
666.7395	1.939083	0.57376111	3383.3325
667.64038	1.9424573	0.57514936	3383.72
668.54126	1.9474843	0.5761866	3390.9089
669.44214	1.9473703	0.57768852	3392.3735
670.34302	1.9470521	0.5788393	3383.7502
671.2439	1.9526603	0.5800066	3385.7598
672.14478	1.9558314	0.58135837	3391.7151
673.04565	1.9584997	0.58242184	3387.3452
673.94653	1.9617752	0.5837158	3389.0945
674.84741	1.9638764	0.58479297	3387.0205
675.74829	1.9661249	0.58595866	3388.9807
676.64917	1.9660084	0.58724564	3392.5413
677.55005	1.9687893	0.58846492	3391.9429
678.45093	1.9710535	0.58976078	3389.5254
679.35181	1.9746999	0.59088147	3390.6348
680.25269	1.9797997	0.59220588	3393.5957
681.15356	1.9819791	0.59340799	3394.1479
682.05444	1.9858159	0.59446996	3393.8052
682.95532	1.9849733	0.59582633	3398.3474
683.8562	1.991205	0.59728754	3393.665
684.75708	1.9920404	0.59815073	3385.6699
685.65796	1.9937063	0.59919024	3391.9063
686.55884	1.9952623	0.60030377	3394.0569
687.45972	2.0009558	0.60131902	3401.0398
688.3606	2.0039852	0.60242605	3393.0408
689.26147	2.0054748	0.60387689	3398.0176
690.16235	2.0067956	0.60500789	3394.4077
691.06323	2.0123293	0.60643059	3403.6201
691.96411	2.0143402	0.60739589	3387.48
692.86499	2.0151312	0.60843194	3391.9775
693.76587	2.0204253	0.60971588	3405.0815
694.66675	2.0208962	0.61077559	3399.8103
695.56763	2.0269394	0.61216128	3409.4675
696.46851	2.0256164	0.61338466	3400.9702
697.36938	2.0293794	0.6149503	3402.4404
698.27026	2.0329182	0.61599606	3393.2798
699.17114	2.0342255	0.61715299	3393.313
700.07202	2.0391688	0.61844426	3405.7688
700.9729	2.039851	0.61933839	3394.3823
701.87378	2.0407288	0.62049621	3405.2092
702.77466	2.0470154	0.62155622	3402.9739
703.67554	2.0496185	0.62290388	3411.9497
704.57642	2.0515728	0.62420899	3407.3169
705.47729	2.053725	0.62552375	3405.9441
706.37817	2.0590816	0.62691098	3409.6885
707.27905	2.0583615	0.62812185	3407.8291
708.17993	2.0627918	0.629619	3407.1975
709.08081	2.0656409	0.63108188	3411.9382
709.98169	2.068064	0.63218385	3402.2383
710.88257	2.071101	0.63329524	3410.3777
711.78345	2.0742061	0.63438398	3404.699
712.68433	2.0771966	0.63550735	3404.0779
713.58521	2.077142	0.63662809	3404.8174
714.48608	2.0831702	0.63799244	3411.7461
715.38696	2.080667	0.63923353	3405.9763
716.28784	2.0848398	0.64051449	3413.613
717.18872	2.0912836	0.64197385	3415.4526
718.0896	2.0893896	0.6435414	3418.647
718.99048	2.0971069	0.6449368	3418.2866
719.89136	2.0970464	0.64613748	3408.3804
720.79224	2.101012	0.64733946	3414.1736
721.69312	2.1012788	0.64829677	3407.9348
722.59399	2.1064775	0.6494363	3413.8394
723.49487	2.108242	0.65054524	3414.0935
724.39575	2.1115432	0.651752	3415.7104
725.29663	2.1139481	0.65294486	3412.7043
726.19751	2.120039	0.65385723	3413.6309
727.09839	2.1170111	0.6549409	3413.072
727.99927	2.1224303	0.65614456	3419.3831
728.90015	2.1230335	0.65758795	3426.3586
729.80103	2.1297004	0.65897536	3417.4407
730.7019	2.1316192	0.66033661	3421.4128
731.60278	2.1308806	0.66165704	3417.4668
732.50366	2.1362185	0.66310894	3416.8115
733.40454	2.1391687	0.66411012	3417.925
734.30542	2.1433864	0.66545969	3424.4131
735.2063	2.140717	0.66688967	3423.6902
736.10718	2.1451628	0.66819084	3420.6875
737.00806	2.1505229	0.66963875	3419.854
737.90894	2.1529217	0.67080063	3420.2808
738.80981	2.1543403	0.67218858	3427.2927
739.71069	2.1596255	0.6737203	3432.2952
740.61157	2.1609416	0.67506194	3418.8284
741.51245	2.1621192	0.67645288	3420.5295
742.41333	2.1687362	0.67741299	3418.5044
743.31421	2.169667	0.67876953	3424.7378
744.21509	2.1709211	0.68001735	3426.877
745.11597	2.1729343	0.68142688	3422.5151
746.01685	2.1749239	0.68280667	3427.0842
746.91772	2.1798024	0.6840772	3427.0491
747.8186	2.1780028	0.68524349	3423.7026
748.71948	2.1846337	0.68660766	3429.3792
749.62036	2.1877892	0.6879437	3428.1709
750.52124	2.1905978	0.68922848	3437.5364
751.42212	2.1925099	0.69032955	3419.228
752.323	2.1938493	0.69138962	3425.3032
753.22388	2.1958435	0.69255674	3425.6799
754.12476	2.198427	0.69361174	3420.2795
755.02563	2.2027268	0.6947369	3434.9121
755.92651	2.2053001	0.69632769	3431.6238
756.82739	2.2068691	0.69781882	3427.1589
757.72827	2.2131002	0.69919729	3432.6072
758.62915	2.2153189	0.70024854	3425.6543
759.53003	2.2154162	0.70139271	3428.3738
760.43091	2.2193244	0.70266801	3432.0408
761.33179	2.2234828	0.70401007	3430.8069
762.23267	2.2244561	0.70539051	3433.1838
763.13354	2.2294617	0.70681351	3438.8557
764.03442	2.2331388	0.70798492	3435.4019
764.9353	2.2308564	0.70943981	3429.4512
765.83618	2.2360597	0.71090442	3434.896
766.73706	2.2405307	0.71213955	3438.3137
767.63794	2.2407258	0.71326858	3424.1538
768.53882	2.2431705	0.7143805	3435.6497
769.4397	2.245775	0.71568477	3437.0146
770.34058	2.2519927	0.7170791	3437.6101
771.24146	2.2532268	0.71841586	3434.5532
772.14233	2.2524741	0.71985394	3434.7783
773.04321	2.2563837	0.72128791	3441.9856
773.94409	2.2607083	0.72285122	3431.0352
774.84497	2.2638545	0.7240591	3437.9246
775.74585	2.2652116	0.72550178	3440.1628
776.64673	2.2686977	0.72686714	3430.5017
777.54761	2.2687464	0.72821808	3438.2009
778.44849	2.2734029	0.72950518	3437.124
779.34937	2.2767723	0.73100054	3439.0735
780.25024	2.2807157	0.73234051	3439.1404
781.15112	2.2818646	0.73399353	3437.3611
782.052	2.2853458	0.73525709	3433.3611
782.95288	2.2853618	0.73667091	3436.9922
783.85376	2.2907531	0.73808289	3440.6167
784.75464	2.2906823	0.73953778	3443.1194
785.65552	2.2951138	0.7409972	3434.4534
786.5564	2.2931154	0.7424354	3438.3748
787.45728	2.3012118	0.74397439	3441.8218
788.35815	2.3041768	0.74570709	3444.8359
789.25903	2.3048306	0.74758744	3443.2351
790.15991	2.309109	0.74942863	3441.0127
791.06079	2.3104043	0.75087339	3437.5452
791.96167	2.3159821	0.75221008	3439.8459
792.86255	2.3150146	0.75371778	3434.1367
793.76343	2.3172467	0.75518757	3437.6616
794.66431	2.3219495	0.75642961	3436.3191
795.56519	2.3250921	0.75811708	3444.7759
796.46606	2.3270721	0.76003587	3445.5432
797.36694	2.3294563	0.76177847	3438.1333
798.26782	2.3342855	0.76342154	3439.5015
799.1687	2.3361335	0.764929	3442.1604
800.06958	2.3366101	0.76649457	3438.5901
800.97046	2.3386271	0.76826108	3443.1782
801.87134	2.3463197	0.76991034	3447.1023
802.77222	2.3457623	0.77142107	3441.2415
803.6731	2.3494477	0.77305907	3440.782
804.57397	2.3499637	0.77479297	3437.2158
805.47485	2.3554487	0.77651238	3448.7832
806.37573	2.3567455	0.77830118	3440.7056
807.27661	2.3636503	0.78001553	3451.6387
808.17749	2.3608556	0.78219098	3449.5591
809.07837	2.3628318	0.7838673	3441.0493
809.97925	2.3686259	0.78549206	3441.7773
810.88013	2.3717225	0.78735739	3450.7092
811.78101	2.3728423	0.78939629	3446.2463
812.68188	2.3778701	0.79126227	3446.6838
813.58276	2.3770137	0.79331017	3446.6648
814.48364	2.3822758	0.79529822	3446.0967
815.38452	2.3840849	0.79735726	3448.3694
816.2854	2.385174	0.79898077	3445.2012
817.18628	2.3907421	0.80088627	3442.7598
818.08716	2.3946755	0.80225587	3446.2871
818.98804	2.3958499	0.80418897	3447.8335
819.88892	2.3989019	0.80595541	3448.6653
820.78979	2.4005909	0.80801636	3445.6421
821.69067	2.4024675	0.80980933	3446.2495
822.59155	2.4077668	0.81166041	3445.104
823.49243	2.410219	0.81332314	3447.2429
824.39331	2.4105313	0.81519002	3448.9409
825.29419	2.415415	0.81684577	3451.4106
826.19507	2.4172659	0.81914353	3451.2996
827.09595	2.4188061	0.8208186	3442.498
827.99683	2.4207566	0.82227379	3440.4446
828.89771	2.4259636	0.82375193	3448.74
829.79858	2.4280717	0.82593864	3452.7781
830.69946	2.4305701	0.82788503	3446.1165
831.60034	2.4309309	0.82954758	3439.1638
832.50122	2.4358289	0.83139288	3449.2148
833.4021	2.4387684	0.8333894	3449.949
834.30298	2.4411237	0.83532786	3446.9854
835.20386	2.4421773	0.83730245	3452.0317
836.10474	2.4468672	0.83898109	3448.1787
837.00562	2.4497795	0.84091532	3455.7886
837.90649	2.4515948	0.84284598	3449.5129
838.80737	2.4521916	0.84507173	3447.4124
839.70825	2.4591994	0.84665859	3448.0947
840.60913	2.4609587	0.84816808	3446.4297
841.51001	2.4634748	0.84965372	3449.2949
842.41089	2.4653831	0.85139275	3447.2473
843.31177	2.4680209	0.85338944	3450.4971
844.21265	2.4683256	0.85521799	3447.946
845.11353	2.4718215	0.85706204	3451.7502
846.0144	2.4748292	0.85925388	3443.5879
846.91528	2.4795296	0.86100614	3453.9551
847.81616	2.4819496	0.86324775	3454.6938
848.71704	2.4884334	0.86532325	3455.1543
849.61792	2.4868245	0.86745161	3454.2122
850.5188	2.4888313	0.86960274	3451.2151
851.41968	2.4930012	0.87136471	3447.7917
852.32056	2.4959157	0.87295789	3447.4304
853.22144	2.4990845	0.8749181	3446.9668
854.12231	2.4999521	0.87637967	3445.2266
855.02319	2.5026121	0.87825966	3451.0227
855.92407	2.508213	0.88047826	3452.1301
856.82495	2.5105214	0.88248956	3457.709
857.72583	2.5119543	0.88456416	3445.7947
858.62671	2.515219	0.88644701	3451.4565
859.52759	2.5145235	0.88865018	3456.3088
860.42847	2.516474	0.89055705	3446.9802
861.32935	2.5226371	0.89238012	3449.2693
862.23022	2.5245516	0.89430285	3449.9485
863.1311	2.5314243	0.89619702	3456.5327
864.03198	2.5315967	0.89814109	3451.7422
864.93286	2.536036	0.89993328	3450.3542
865.83374	2.5359061	0.90142727	3445.9695
866.73462	2.5384247	0.90280759	3445.5513
867.6355	2.5415013	0.9046461	3447.1853
868.53638	2.5420268	0.90668708	3451.8113
869.43726	2.5475118	0.90872037	3456.6482
870.33813	2.5496099	0.91093409	3459.3838
871.23901	2.550329	0.91301662	3449.0291
872.13989	2.5567133	0.91524148	3451.3564
873.04077	2.5569959	0.91768646	3454.8291
873.94165	2.5608797	0.92006522	3450.5398
874.84253	2.5613484	0.92219162	3449.623
875.74341	2.5660861	0.92382228	3446.8594
876.64429	2.5695565	0.92585003	3450.6665
877.54517	2.57183	0.92821759	3453.1748
878.44604	2.5734718	0.93061018	3458.343
879.34692	2.5742226	0.93294847	3445.3977
880.2478	2.5783715	0.93455416	3444.1533
881.14868	2.5802906	0.93634713	3450.7427
882.04956	2.5862908	0.93865627	3452.9321
882.95044	2.5877621	0.94109613	3449.9529
883.85132	2.5904019	0.94307119	3452.1426
884.7522	2.5948265	0.94544852	3452.5029
885.65308	2.5928507	0.94753557	3446.9692
886.55396	2.6013224	0.94926417	3450.0764
887.45483	2.6008763	0.95131147	3452.1338
888.35571	2.6020963	0.95341069	3448.3484
889.25659	2.6045394	0.95579529	3449.407
890.15747	2.6104558	0.95786351	3453.8347
891.05835	2.6125748	0.95990586	3447.7126
891.95923	2.6145284	0.96198148	3450.0164
892.86011	2.6169362	0.96430022	3449.5559
893.76099	2.620882	0.96637106	3444.1987
894.66187	2.6217616	0.96839714	3453.0481
895.56274	2.6247599	0.97100019	3454.0447
896.46362	2.6284442	0.97301877	3442.5598
897.3645	2.6298838	0.97509956	3446.8416
898.26538	2.6328506	0.97714305	3451.2346
899.16626	2.6354828	0.97936881	3448.0466
900.06714	2.6394715	0.98179066	3446.6975
900.96802	2.640878	0.98370528	3442.8413
901.8689	2.6437001	0.98538768	3441.9534
902.76978	2.6464753	0.98701918	3446.533
903.67065	2.6490247	0.98879439	3446.6628
904.57153	2.6499348	0.99072802	3447.9644
905.47241	2.6538513	0.99318302	3452.7205
906.37329	2.6578393	0.99524462	3446.572
907.27417	2.6615937	0.99716192	3447.6238
908.17505	2.6618199	0.99905527	3440.7051
909.07593	2.6680357	1.001045	3443.0527
909.97681	2.6690586	1.0031822	3451.9727
910.87769	2.6704049	1.0055395	3446.0823
911.77856	2.6766746	1.0083193	3450.1497
912.67944	2.6774976	1.010769	3447.8792
913.58032	2.6795011	1.0133753	3445.3696
914.4812	2.6820562	1.0158223	3442.7754
915.38208	2.6846232	1.0180622	3448.3894
916.28296	2.6873472	1.0206707	3443.0439
917.18384	2.6905119	1.0234895	3445.4873
918.08472	2.6922121	1.0262928	3448.2473
918.9856	2.6930306	1.0290675	3439.8628
919.88647	2.697475	1.0317701	3445.9707
920.78735	2.7008214	1.0343434	3436.7874
921.68823	2.7041693	1.0363854	3442.0337
922.58911	2.7046237	1.0390459	3441.6936
923.48999	2.7078211	1.0420194	3441.3486
924.39087	2.711539	1.0445149	3438.7935
925.29175	2.7128227	1.0470266	3438.7136
926.19263	2.715106	1.0497035	3443.7991
927.09351	2.7187233	1.0526229	3438.6931
927.99438	2.7228236	1.0559024	3443.4045
928.89526	2.7273006	1.0586698	3440.2986
929.79614	2.7277081	1.0612582	3440.4551
930.69702	2.7323928	1.0632907	3425.8914
931.5979	2.734128	1.0654954	3440.9297
932.49878	2.7350988	1.0681094	3438.8887
933.39966	2.7393615	1.0713887	3445.0413
934.30054	2.739186	1.0741636	3442.6545
935.20142	2.745286	1.0770028	3440.5078
936.10229	2.7466152	1.0795746	3434.7642
937.00317	2.7503531	1.0820298	3434.4971
937.90405	2.7516108	1.0842127	3429.4497
938.80493	2.7558212	1.0863085	3431.5977
939.70581	2.7570484	1.0886345	3435.5894
940.60669	2.7607431	1.0907522	3439.2695
941.50757	2.7635722	1.0932121	3434.2939
942.40845	2.7691729	1.0959418	3437.4238
943.30933	2.7666192	1.0984695	3436.9856
944.21021	2.7714336	1.1007298	3431.2043
945.11108	2.7742271	1.1025929	3430.1892
946.01196	2.7761304	1.1051364	3428.0757
946.91284	2.7784076	1.1075109	3428.9773
947.81372	2.7829473	1.1097196	3428.7224
948.7146	2.7838125	1.1117592	3426.9849
949.61548	2.7868235	1.1141361	3433.3823
950.51636	2.78829	1.1163267	3419.8508
951.41724	2.7893178	1.1181175	3425.2859
952.31812	2.7965069	1.1202073	3420.5647
953.21899	2.7988937	1.1222796	3426.4321
954.11987	2.802238	1.1249735	3428.4482
955.02075	2.8022852	1.1276547	3429.0105
955.92163	2.8039036	1.1310052	3423.9045
956.82251	2.8092899	1.1348658	3424.8354
957.72339	2.8109548	1.1380841	3423.7087
958.62427	2.8121049	1.1408356	3421.6316
959.52515	2.8170438	1.14396	3424.0042
960.42603	2.817982	1.1466404	3416.5544
961.3269	2.8248494	1.1496967	3420.1492
962.22778	2.8230822	1.1525539	3420.7915
963.12866	2.8243067	1.1557494	3417.2139
964.02954	2.8295453	1.1584973	3414.5508
964.93042	2.8359189	1.1609401	3416.918
965.8313	2.8362815	1.163548	3417.1658
966.73218	2.8376403	1.1661839	3415.127
967.63306	2.8434536	1.1691014	3415.197
968.53394	2.8444171	1.1714798	3416.877
969.43481	2.8470881	1.1740637	3415.6428
970.33569	2.8514333	1.1772171	3419.4041
971.23657	2.8523514	1.1802641	3408.5676
972.13745	2.8551631	1.1826758	3408.2788
973.03833	2.8570938	1.185425	3410.3921
973.93921	2.8606269	1.1882516	3409.3054
974.84009	2.863996	1.1912611	3403.6345
975.74097	2.865803	1.1938874	3405.9094
976.64185	2.8677282	1.1968262	3405.6411
977.54272	2.8687823	1.1990048	3396.5881
978.4436	2.8758659	1.2020299	3412.0308
979.34448	2.8778849	1.2053679	3407.9421
980.24536	2.8783174	1.2079775	3397.3271
981.14624	2.8833466	1.2106439	3396.7864
982.04712	2.8833761	1.2131339	3397.7822
982.948	2.8906248	1.2157747	3396.8384
983.84888	2.8898861	1.2183414	3400.6765
984.74976	2.8929579	1.2212234	3388.9241
985.65063	2.8983378	1.2235506	3391.1467
986.55151	2.897501	1.2260613	3393.1633
987.45239	2.9005613	1.2288842	3397.7939
988.35327	2.9045746	1.2311909	3392.3511
989.25415	2.9053252	1.2339407	3388.1125
990.15503	2.9081984	1.2371826	3393.2146
991.05591	2.9167788	1.2400758	3394.9692
991.95679	2.9148157	1.2425381	3387.46
992.85767	2.9196522	1.2452761	3389.2012
993.75854	2.91993	1.2484578	3385.9656
994.65942	2.9216526	1.2509655	3381.2727
995.5603	2.9262478	1.2534775	3380.3992
996.46118	2.9289801	1.2565308	3388.2793
997.36206	2.9328563	1.2593217	3377.2646
998.26294	2.9326365	1.2622728	3372.7993
999.16382	2.935221	1.2650169	3376.3906
1000.0647	2.9403489	1.2675372	3375.5503
1000.9656	2.9425862	1.2700139	3375.679
1001.8665	2.9424751	1.2723039	3364.4194
1002.7673	2.9468901	1.2744223	3365.636
1003.6682	2.9500458	1.2766938	3369.8743
1004.5691	2.9543624	1.2797315	3371.7473
1005.47	2.9554102	1.2825341	3364.7983
1006.3708	2.9558132	1.2851679	3365.0327
1007.2717	2.9591184	1.2879382	3360.1138
1008.1726	2.9642477	1.290828	3359.0278
1009.0735	2.9651604	1.2932682	3355.6589
1009.9744	2.9671991	1.2957609	3356.6284
1010.8752	2.972966	1.2980521	3356.1792
1011.7761	2.9740396	1.3005259	3356.1104
1012.677	2.9744587	1.3028857	3351.5813
1013.5779	2.9824953	1.3053082	3355.4119
1014.4788	2.9838741	1.3084532	3354.2588
1015.3796	2.983187	1.3114878	3345.915
1016.2805	2.9868796	1.3141631	3345.127
1017.1814	2.9910655	1.3166616	3346.9175
1018.0823	2.9908605	1.3195742	3342.6323
1018.9832	2.9927132	1.3219963	3342.2175
1019.884	2.9975216	1.3244698	3332.9402
1020.7849	3.002871	1.3260759	3318.075
1021.6858	3.0040026	1.3274264	3328.9978
1022.5867	3.0044096	1.3292246	3339.9426
1023.4875	3.0091584	1.3322374	3336.9446
1024.3884	3.0112181	1.3348507	3336.6855
1025.2893	3.0150468	1.3378369	3334.2852
1026.1902	3.015698	1.3409518	3330.146
1027.0911	3.0186095	1.3435402	3323.4185
1027.9919	3.0211182	1.3466818	3321.7603
1028.8928	3.0242903	1.349394	3318.824
1029.7937	3.0287969	1.3520433	3322.5742
1030.6946	3.0309772	1.354568	3313.6223
1031.5955	3.0332353	1.3569531	3310.9207
1032.4963	3.0350647	1.3596232	3315.7036
1033.3972	3.0404727	1.3630152	3315.8704
1034.2981	3.038506	1.3661373	3308.3401
1035.199	3.0432045	1.369392	3304.7861
1036.0999	3.0457339	1.372036	3302.1489
1037.0007	3.0481513	1.3752599	3302.7449
1037.9016	3.0533183	1.3779907	3295.4963
1038.8025	3.0542142	1.3808845	3297.2383
1039.7034	3.0583017	1.3833375	3293.2864
1040.6042	3.0590339	1.3854275	3283.0425
1041.5051	3.0626907	1.3878793	3290.7676
1042.406	3.0659502	1.3905272	3290.7329
1043.3069	3.0674186	1.3936106	3286.9055
1044.2078	3.0734398	1.3958012	3285.104
1045.1086	3.0712945	1.3984829	3278.6201
1046.0095	3.079828	1.4010477	3279.7815
1046.9104	3.0793941	1.4035578	3277.0916
1047.8113	3.0823538	1.4061944	3274.5662
1048.7122	3.0859337	1.4084667	3270.0166
1049.613	3.0877602	1.4108257	3272.8962
1050.5139	3.0903797	1.412909	3262.0466
1051.4148	3.0914605	1.4153433	3266.8215
1052.3157	3.0960462	1.4188896	3264.7224
1053.2166	3.0982223	1.422429	3249.8174
1054.1174	3.1024389	1.4251026	3257.2686
1055.0183	3.1026013	1.4277717	3254.582
1055.9192	3.105895	1.431185	3245.3872
1056.8201	3.1098568	1.4335365	3244.7783
1057.7209	3.1111882	1.4362528	3243.4241
1058.6218	3.115123	1.4389811	3237.9224
1059.5227	3.1151545	1.4417372	3239.4929
1060.4236	3.1191866	1.4447341	3236.0916
1061.3245	3.1222756	1.4477351	3232.344
1062.2253	3.1260383	1.4506313	3231.0696
1063.1262	3.1306126	1.4537781	3227.7715
1064.0271	3.1286736	1.4569505	3214.9707
1064.928	3.1330981	1.459541	3212.1194
1065.8289	3.135479	1.462146	3213.1042
1066.7297	3.1396008	1.464779	3208.2122
1067.6306	3.1423302	1.4671469	3210.3396
1068.5315	3.143719	1.4696163	3204.5303
1069.4324	3.1470554	1.4722754	3202.5164
1070.3333	3.1489956	1.4751126	3195.2378
1071.2341	3.1507487	1.4780173	3194.0083
1072.135	3.1561832	1.4808861	3189.9346
1073.0359	3.1592698	1.4845649	3183.5508
1073.9368	3.1602283	1.4873914	3179.262
1074.8376	3.1640601	1.4903622	3178.1533
1075.7385	3.1675458	1.4930221	3173.4084
1076.6394	3.1679471	1.4966701	3171.6072
1077.5403	3.1726136	1.500362	3169.2258
1078.4412	3.1755462	1.5036703	3156.8162
1079.342	3.1747026	1.5075762	3149.5679
1080.2429	3.1803334	1.5115047	3139.5571
1081.1438	3.1820908	1.5145996	3132.0103
1082.0447	3.1857841	1.5180274	3125.1265
1082.9456	3.1856027	1.5216671	3118.8152
1083.8464	3.1902936	1.5257732	3103.0833
1084.7473	3.1943967	1.5366279	3034.3599
1084.9475	3.19858	1.5408602	3006.9229