File: datasets/am_bench_2022/raw_data/0-X.01-4/specimen.dat
MTS793|MPT|ENU|1|2|.|/|:|1|0|0|A

Operator Information						Time:	53.302246	Sec	10/12/2021 4:10:54 PM
Operator	Nick Derimow
Project	AM Bench 2022 mini-tensile challenge
Specimen ID	0-X.01-4
Material	PBF-L Inconel 625
Specimen Width	2.56	mm
Specimen Thickness	1.54	mm
Notes	Accidentally loaded to 220 N
Operator Information End

Data Acquisition						Time:	1054.2959	Sec	10/12/2021 4:27:35 PM
Time	Axial Displacement	Axial Extensometer	Axial Force
Sec	mm	mm	N
53.415771	0.0009959637	0.00011044065	63.565022
54.516846	0.0045913905	0.00033661671	81.136299
55.61792	0.0069466121	0.00033197799	98.111481
56.718994	0.0097767198	0.00040643127	113.43732
57.820068	0.015108495	0.00044847387	129.69032
58.921143	0.015938507	0.00051922578	145.19063
60.022217	0.019583313	0.00050260604	161.14151
61.123291	0.021518663	0.00058331876	183.64249
62.224365	0.025994454	0.00084090151	205.85556
63.325439	0.030308178	0.00070460601	227.55264
64.426514	0.033817753	0.00096049946	251.27592
65.527588	0.033458989	0.0010143438	269.9231
66.628662	0.039210383	0.0011658259	299.08563
67.729736	0.040606305	0.0014085243	321.01154
68.830811	0.045848183	0.0012902101	342.79611
69.931885	0.04864141	0.0014587758	366.40897
71.032959	0.05306844	0.0016516254	385.95328
72.134033	0.057818376	0.0015925103	417.52679
73.235107	0.059487212	0.0017858894	438.11255
74.336182	0.060607556	0.0017561556	460.13809
75.437256	0.063639484	0.0018504537	487.6564
76.53833	0.067816697	0.0021070151	513.3349
77.639404	0.069642067	0.0022172115	538.99585
78.740479	0.077968739	0.0023647198	567.44727
79.841553	0.081602633	0.0024966141	595.36108
80.942627	0.081098653	0.0025152469	622.95966
82.043701	0.086943321	0.0028195479	657.01575
83.144775	0.088908173	0.0028799938	687.05084
84.24585	0.089701921	0.002968641	711.86377
85.346924	0.093080312	0.0031790209	741.51984
86.447998	0.097692773	0.0033553236	770.16412
87.549072	0.1009993	0.0033145337	802.09851
88.650146	0.10275148	0.0034728551	819.46942
89.751221	0.10676872	0.003634722	857.20477
90.852295	0.11255602	0.0037423	894.42181
91.953369	0.11447626	0.0039137681	934.34802
93.054443	0.11731641	0.0041870447	962.69733
94.155518	0.12168171	0.0043090265	1002.9631
95.256592	0.12088597	0.0044921804	1032.9357
96.357666	0.12579018	0.0045545646	1054.5671
97.45874	0.13236237	0.0048901271	1097.2085
98.559814	0.13596042	0.004916898	1130.7218
99.660889	0.13636282	0.0050472077	1149.9664
100.76196	0.13992238	0.0052426551	1192.1017
101.86304	0.14249146	0.0053951535	1213.8175
102.96411	0.14619461	0.0055805203	1247.7172
104.06519	0.14945437	0.0057190573	1274.0569
105.16626	0.15330817	0.0058470885	1316.5348
106.26733	0.15759014	0.0059410916	1336.2374
107.36841	0.15800729	0.0060137697	1373.7013
108.46948	0.16584735	0.0061638583	1408.3507
109.57056	0.16877334	0.0064668478	1438.3334
110.67163	0.17108533	0.0065052598	1466.689
111.77271	0.1731223	0.0068589151	1494.3135
112.87378	0.17779869	0.0069076126	1521.677
113.97485	0.18029691	0.0070538577	1548.021
115.07593	0.18284346	0.0071934895	1579.5339
116.177	0.18803042	0.0073495735	1619.3385
117.27808	0.18963857	0.0075985459	1642.0594
118.37915	0.19301066	0.0076138922	1670.5505
119.48022	0.19887659	0.0078653637	1706.9553
120.5813	0.2016086	0.0080938395	1735.7864
121.68237	0.20341426	0.0082354145	1761.1414
122.78345	0.20626347	0.0085240323	1795.3606
123.88452	0.21131459	0.008585765	1814.2368
124.9856	0.21227241	0.0087199183	1835.0651
126.08667	0.21780953	0.0089143487	1871.9789
127.18774	0.22005822	0.0090146996	1894.8728
128.28882	0.22565717	0.0093024168	1930.4835
129.38989	0.22611919	0.0094326437	1950.7367
130.49097	0.22975904	0.0097057316	1973.3534
131.59204	0.23191859	0.0097952019	1994.4773
132.69312	0.23721579	0.0099981437	2020.8571
133.79419	0.24275102	0.010159277	2045.8094
134.89526	0.24276987	0.010393457	2069.0505
135.99634	0.24694903	0.0107408	2086.0706
137.09741	0.24886353	0.010994411	2114.3665
138.19849	0.25133631	0.011119631	2136.7432
139.29956	0.25430265	0.011499904	2163.1296
140.40063	0.26161435	0.011730879	2184.4092
141.50171	0.26313439	0.011999045	2195.5286
142.60278	0.26459548	0.012131829	2207.7598
143.70386	0.27051261	0.012443928	2241.3652
144.80493	0.27337167	0.012774807	2249.2979
145.90601	0.27834103	0.012877997	2265.5366
147.00708	0.28081197	0.013307698	2287.3557
148.10815	0.28493577	0.013571464	2297.823
149.20923	0.28822857	0.01379562	2308.6284
150.3103	0.29245645	0.014213563	2324.9639
151.41138	0.29373205	0.014576167	2341.3784
152.51245	0.29690105	0.014861012	2353.4612
153.61353	0.30388901	0.015265991	2371.8833
154.7146	0.30394781	0.015499711	2375.3755
155.81567	0.30868933	0.015996221	2383.9448
156.91675	0.31234536	0.016466977	2408.23
158.01782	0.31337267	0.01680704	2419.1382
159.1189	0.3167859	0.017404716	2432.9089
160.21997	0.32034031	0.017914778	2434.7185
161.32104	0.32355562	0.018381609	2443.9426
162.42212	0.32720819	0.019057909	2455.3679
163.52319	0.33022496	0.019639941	2469.0754
164.62427	0.33377054	0.020230545	2481.2859
165.72534	0.33607557	0.020775676	2478.0483
166.82642	0.34076199	0.021652143	2497.6404
167.92749	0.34601986	0.022171816	2504.9199
169.02856	0.3463968	0.022907373	2508.1052
170.12964	0.35186079	0.023739655	2524.1489
171.23071	0.35215992	0.024614776	2518.2798
172.33179	0.3549366	0.025383394	2526.6282
173.43286	0.36064231	0.026208641	2536.0696
174.53394	0.36538181	0.027242579	2545.4077
175.63501	0.36707667	0.02824668	2554.6179
176.73608	0.36624706	0.028993109	2547.3105
177.83716	0.37268466	0.030063845	2552.4929
178.93823	0.37998503	0.0310644	2571.6079
180.03931	0.378802	0.032259796	2571.9358
181.14038	0.38176492	0.033583704	2570.4968
182.24146	0.38403752	0.034478799	2576.2598
183.34253	0.38956565	0.035630427	2583.4299
184.4436	0.39640483	0.036782622	2592.8464
185.54468	0.39509866	0.038112726	2588.5012
186.64575	0.40021101	0.039673876	2591.5027
187.74683	0.40242833	0.040802408	2593.1868
188.8479	0.40974167	0.042063702	2602.6233
189.94897	0.40910015	0.043383591	2605.3027
191.05005	0.41223553	0.044840373	2605.1262
192.15112	0.4166548	0.046294585	2608.9143
193.2522	0.42116827	0.048093982	2625.8049
194.35327	0.42409426	0.04979505	2624.0698
195.45435	0.42827728	0.051021513	2617.8186
196.55542	0.43034294	0.052475836	2625.3782
197.65649	0.43311059	0.054246902	2619.7253
198.75757	0.43600798	0.055724353	2627.6689
199.85864	0.44034156	0.057399053	2626.1753
200.95972	0.44440505	0.059221938	2638.0408
202.06079	0.44776487	0.060717359	2630.1279
203.16187	0.44925791	0.062243458	2637.8813
204.26294	0.45198843	0.063763119	2634.4636
205.36401	0.45588478	0.065753341	2646.9385
206.46509	0.45995674	0.067564756	2644.0518
207.56616	0.46392155	0.069314934	2648.323
208.66724	0.46707952	0.070976354	2653.0103
209.76831	0.46975309	0.072563678	2644.9573
210.86938	0.47159767	0.07405477	2644.2832
211.97046	0.47686461	0.075761542	2658.635
213.07153	0.47673061	0.077462047	2652.5908
214.17261	0.48379576	0.07912419	2655.6868
215.27368	0.48679572	0.08094354	2656.8625
216.37476	0.4906821	0.082877904	2662.3127
217.47583	0.49348229	0.084404841	2662.7581
218.5769	0.49036944	0.085926898	2653.0215
219.67798	0.49782854	0.087346368	2663.1379
220.77905	0.50093609	0.089149557	2665.7068
221.88013	0.50597596	0.091262229	2666.6594
222.9812	0.50820965	0.092858039	2667.0999
224.08228	0.5126248	0.094782718	2672.7549
225.18335	0.51646692	0.096834198	2676.6682
226.28442	0.52029526	0.098502718	2673.1382
227.3855	0.52337903	0.099983096	2670.49
228.48657	0.52558726	0.10181324	2673.5249
229.58765	0.52797735	0.10387141	2679.1851
230.68872	0.53214538	0.10578971	2679.9382
231.78979	0.5355643	0.10789771	2682.0471
232.89087	0.54092467	0.11001635	2680.6035
233.99194	0.54416317	0.11165629	2693.9309
235.09302	0.54693937	0.11365743	2687.1565
236.19409	0.5492394	0.11522591	2685.2617
237.29517	0.55149484	0.11762275	2688.6821
238.39624	0.55762064	0.11949723	2689.1072
239.49731	0.5588606	0.12117133	2682.8054
240.59839	0.56267703	0.12324587	2692.1809
241.69946	0.56606424	0.12516439	2694.8079
242.80054	0.56915951	0.12697165	2691.8601
243.90161	0.57100457	0.12870921	2695.2639
245.00269	0.57527441	0.13051751	2694.4238
246.10376	0.58053797	0.13255276	2697.8076
247.20483	0.58297086	0.13445994	2696.3523
248.30591	0.58354741	0.13631332	2692.7163
249.40698	0.59005016	0.13815391	2709.116
250.50806	0.59051263	0.13985927	2696.6323
251.60913	0.59488291	0.14201041	2708.3794
252.71021	0.59923023	0.14377332	2701.3162
253.81128	0.60097504	0.14519033	2700.8521
254.91235	0.60413116	0.14700949	2699.2615
256.01343	0.60623819	0.14881067	2709.6411
257.1145	0.6112355	0.15061767	2707.21
258.21558	0.61404651	0.15240076	2703.4561
259.31665	0.61660945	0.15420055	2711.5967
260.41772	0.62196386	0.15616655	2719.6453
261.5188	0.62526274	0.1581167	2719.4822
262.61987	0.62599975	0.16017964	2710.292
263.72095	0.63219184	0.16212577	2711.8794
264.82202	0.63721246	0.16404407	2720.6064
265.9231	0.63966393	0.16592345	2723.7573
267.02417	0.64524382	0.16800347	2728.1704
268.12524	0.64394939	0.16995645	2723.4541
269.22632	0.64663815	0.17183979	2721.5872
270.32739	0.6517266	0.17375898	2727.2844
271.42847	0.65701842	0.17592534	2729.915
272.52954	0.6577515	0.1775178	2723.0764
273.63062	0.66230679	0.17943403	2728.4392
274.73169	0.66481388	0.18146831	2727.6189
275.83276	0.66768926	0.18348262	2730.156
276.93384	0.6695109	0.18571949	2740.7192
278.03491	0.67638719	0.18789327	2738.3511
279.13599	0.6767996	0.18996002	2734.3408
280.23706	0.68271905	0.19146326	2725.8037
281.33813	0.68772817	0.19313331	2736.676
282.43921	0.68745869	0.19494313	2736.324
283.54028	0.69341177	0.1967217	2739.2354
284.64136	0.69682723	0.19866888	2742.825
285.74243	0.69902301	0.200808	2744.3428
286.84351	0.69827318	0.20282435	2742.9548
287.94458	0.70446861	0.20487687	2741.4731
289.04565	0.70799065	0.20666312	2746.6624
290.14673	0.71120799	0.20863697	2740.5776
291.2478	0.71337628	0.2103076	2743.561
292.34888	0.71893024	0.21185149	2745.002
293.44995	0.71898705	0.21391089	2745.2561
294.55103	0.72239572	0.21578972	2747.3784
295.6521	0.73022228	0.21754327	2749.6428
296.75317	0.7335906	0.21913455	2749.6758
297.85425	0.73419708	0.22093159	2756.144
298.95532	0.73908085	0.22316098	2760.1501
300.0564	0.73928344	0.22494219	2755.9829
301.15747	0.74400783	0.22669387	2752.249
302.25854	0.74945903	0.22859365	2755.522
303.35962	0.74939221	0.23034742	2761.7625
304.46069	0.7527526	0.23245138	2754.1785
305.56177	0.75510621	0.23451906	2762.0559
306.66284	0.76167434	0.23667152	2761.9265
307.76392	0.76454788	0.23831484	2766.7261
308.86499	0.76419526	0.24037668	2761.1235
309.96606	0.77157497	0.24247591	2766.6147
311.06714	0.77421039	0.24452263	2758.1204
312.16821	0.77693319	0.24619263	2767.7649
313.26929	0.77946866	0.24791969	2762.6191
314.37036	0.78549039	0.24964324	2772.6907
315.47144	0.78813344	0.25180963	2769.3491
316.57251	0.78856307	0.25381047	2769.5342
317.67358	0.79391819	0.2559253	2776.3796
318.77466	0.79564607	0.25828278	2775.541
319.87573	0.7994386	0.26002494	2766.7278
320.97681	0.80370265	0.26206583	2774.9106
322.07788	0.80914086	0.26372123	2778.0488
323.17896	0.81079721	0.26554757	2771.0273
324.28003	0.81436634	0.26703736	2773.9043
325.3811	0.81714296	0.26866084	2771.99
326.48218	0.8210389	0.27034485	2776.8696
327.58325	0.82469887	0.27217424	2778.9009
328.68433	0.8250398	0.27415276	2777.9421
329.7854	0.82936031	0.27600199	2784.614
330.88647	0.8376888	0.27785411	2790.7258
331.98755	0.83656847	0.27967089	2786.9556
333.08862	0.84186876	0.28190756	2792.6572
334.1897	0.84207547	0.28393462	2784.0845
335.29077	0.84625214	0.28592739	2788.5374
336.39185	0.85262626	0.28778118	2790.969
337.49292	0.85594296	0.28981528	2793.7056
338.59399	0.85708433	0.29148445	2788.3281
339.69507	0.86125076	0.29338825	2798.2517
340.79614	0.8615796	0.29561403	2793.333
341.89722	0.86489534	0.29754955	2792.5122
342.99829	0.87293476	0.29952446	2792.1094
344.09937	0.87175745	0.30125222	2790.3694
345.20044	0.87567574	0.30282339	2795.7178
346.30151	0.88326591	0.30467522	2798.7905
347.40259	0.88446957	0.30670345	2799.7446
348.50366	0.88461053	0.30852553	2795.4075
349.60474	0.88909638	0.31041479	2798.4045
350.70581	0.89326936	0.31220651	2804.5103
351.80688	0.89647567	0.31425047	2801.2571
352.90796	0.89847636	0.3161718	2809.156
354.00903	0.90215844	0.31822979	2809.4714
355.11011	0.90748513	0.32002968	2809.0867
356.21118	0.91007841	0.32190299	2805.272
357.31226	0.91570383	0.32326099	2802.5686
358.41333	0.91613775	0.32483056	2810.1174
359.5144	0.91935229	0.32657167	2808.9063
360.61548	0.92200911	0.32828	2815.0945
361.71655	0.92437083	0.33050308	2813.4248
362.81763	0.9330188	0.33286479	2824.1089
363.9187	0.93263441	0.33479941	2814.0732
365.01978	0.93499982	0.33686858	2816.0315
366.12085	0.93935722	0.33882561	2816.073
367.22192	0.94330645	0.34078595	2815.2029
368.323	0.94499165	0.3426196	2819.6482
369.42407	0.94803917	0.34418371	2819.1885
370.52515	0.95568866	0.34632313	2830.103
371.62622	0.95326978	0.34809247	2815.8333
372.72729	0.95910108	0.34975395	2821.0073
373.82837	0.96097296	0.35164514	2818.3147
374.92944	0.96659303	0.35353094	2822.4128
376.03052	0.96826243	0.35548666	2818.2104
377.13159	0.97146755	0.35742393	2825.1372
378.23267	0.97523034	0.35907471	2827.2681
379.33374	0.97839421	0.36141306	2833.1567
380.43481	0.98121327	0.36334696	2832.2471
381.53589	0.98623186	0.36536461	2834.9946
382.63696	0.98689038	0.36717883	2832.5935
383.73804	0.99190539	0.36887759	2830.781
384.83911	0.99610478	0.370621	2829.8452
385.94019	1.0009947	0.37240639	2847.7271
387.04126	1.0030187	0.37485272	2840.9292
388.14233	1.0050521	0.37665981	2831.6138
389.24341	1.0074468	0.37823072	2840.9473
390.34448	1.0122122	0.3800191	2838.8789
391.44556	1.0132909	0.38192976	2835.5266
392.54663	1.015182	0.38374895	2837.062
393.64771	1.0226278	0.38531646	2845.1504
394.74878	1.022963	0.38730419	2842.894
395.84985	1.0294763	0.38920012	2851.0283
396.95093	1.0337033	0.39099452	2847.7075
398.052	1.0337179	0.39298859	2850.1885
399.15308	1.0386798	0.39516041	2850.4707
400.25415	1.0424818	0.39701286	2843.9854
401.35522	1.0408934	0.39869732	2846.9888
402.4563	1.050976	0.40069801	2855.928
403.55737	1.0511838	0.40245134	2852.5076
404.65845	1.0530286	0.40396482	2853.5808
405.75952	1.0582641	0.4059388	2855.4299
406.8606	1.0629773	0.40813965	2859.6165
407.96167	1.0628119	0.40997863	2858.0835
409.06274	1.0679634	0.41194502	2855.2122
410.16382	1.0743855	0.41396099	2865.2097
411.26489	1.0738881	0.41586933	2854.054
412.36597	1.0747418	0.41752738	2859.4502
413.46704	1.0817093	0.41917303	2861.8252
414.56812	1.082646	0.42133006	2866.0752
415.66919	1.0851355	0.42327738	2856.4521
416.77026	1.0897539	0.42502105	2863.2087
417.87134	1.0968981	0.42692775	2866.2964
418.97241	1.0985349	0.42855349	2861.1052
420.07349	1.1010008	0.4300769	2859.8872
421.17456	1.1061431	0.43225402	2875.4619
422.27563	1.107933	0.43404448	2870.8699
423.37671	1.1125572	0.43587834	2874.4788
424.47778	1.1154337	0.43813765	2877.8459
425.57886	1.1170257	0.43993336	2861.1169
426.67993	1.1203921	0.44176012	2880.0752
427.78101	1.1239471	0.44362816	2873.6794
428.88208	1.1283085	0.44555393	2876.4563
429.98315	1.1323713	0.44699165	2872.1707
431.08423	1.1308599	0.44881389	2879.012
432.1853	1.1367999	0.45056608	2872.1758
433.28638	1.1395203	0.45230365	2869.4719
434.38745	1.1449119	0.45391369	2883.1602
435.48853	1.1464332	0.45559686	2874.3223
436.5896	1.1487538	0.45759276	2881.2222
437.69067	1.1547014	0.45939112	2883.2026
438.79175	1.1563306	0.46127734	2883.2327
439.89282	1.1566377	0.46305066	2875.6375
440.9939	1.1659796	0.46486807	2886.4971
442.09497	1.1675576	0.46699104	2894.4714
443.19604	1.1730499	0.46931949	2897.4104
444.29712	1.1730676	0.47122672	2887.3579
445.39819	1.175643	0.47281304	2878.3259
446.49927	1.1783018	0.47441673	2884.3511
447.60034	1.1823337	0.47638252	2890.802
448.70142	1.1889722	0.47837713	2892.5757
449.80249	1.1879104	0.48020545	2896.2273
450.90356	1.1954815	0.48237917	2898.167
452.00464	1.1975706	0.48432782	2894.5427
453.10571	1.2013516	0.48634323	2895.1533
454.20679	1.2064475	0.48849094	2901.5452
455.30786	1.2064209	0.49022618	2895.6716
456.40894	1.2122822	0.49210137	2895.4988
457.51001	1.2118859	0.49374741	2902.5774
458.61108	1.2166065	0.4955987	2904.8977
459.71216	1.2187167	0.49718204	2890.1616
460.81323	1.2220013	0.4986999	2897.0193
461.91431	1.2281719	0.50053954	2905.9534
463.01538	1.2286366	0.50228643	2905.5078
464.11646	1.2323217	0.50429201	2904.7346
465.21753	1.2372495	0.50650656	2906.175
466.3186	1.2406027	0.50797307	2901.6033
467.41968	1.2450231	0.50945956	2901.0464
468.52075	1.2476474	0.51124531	2917.7603
469.62183	1.2523052	0.51318777	2913.7295
470.7229	1.251657	0.51473713	2911.1077
471.82397	1.258374	0.51653916	2912.0571
472.92505	1.2598633	0.51834929	2916.7393
474.02612	1.2614075	0.52015036	2917.6494
475.1272	1.2679646	0.52212107	2911.3535
476.22827	1.2678523	0.52345574	2908.2183
477.32935	1.273878	0.52549189	2916.8723
478.43042	1.2770118	0.52742308	2919.3135
479.53149	1.2817769	0.52925569	2919.6563
480.63257	1.2801813	0.5310477	2921.5
481.73364	1.2834409	0.53281027	2916.1843
482.83472	1.2901716	0.53483719	2928.3835
483.93579	1.2919066	0.53692144	2917.9331
485.03687	1.2936627	0.53860795	2928.8569
486.13794	1.3020942	0.54072458	2931.335
487.23901	1.2993686	0.54254794	2927.1321
488.34009	1.3072366	0.54444456	2925.7683
489.44116	1.3067001	0.54616553	2923.0234
490.54224	1.3139006	0.54810965	2934.3235
491.64331	1.3173363	0.55003428	2928.8611
492.74438	1.3172029	0.55207437	2925.3552
493.84546	1.3232429	0.55373752	2934.4063
494.94653	1.3268231	0.55568928	2932.6477
496.04761	1.3290043	0.55772555	2937.0737
497.14868	1.3304361	0.5595209	2933.2861
498.24976	1.3383918	0.56136101	2943.4426
499.35083	1.3424236	0.56324124	2941.0962
500.4519	1.344611	0.56483889	2936.7861
501.55298	1.3458972	0.56671143	2945.9456
502.65405	1.3471652	0.56843019	2931.4561
503.75513	1.3518865	0.57026792	2940.4927
504.8562	1.3527261	0.57191116	2937.481
505.95728	1.3561432	0.57380438	2939.8052
507.05835	1.3642503	0.57565504	2939.3345
508.15942	1.3670143	0.57748359	2945.3755
509.2605	1.3708888	0.57938117	2951.1589
510.36157	1.3698401	0.58136702	2942.54
511.46265	1.3762331	0.58301371	2942.842
512.56372	1.377751	0.5848906	2942.1389
513.66479	1.3817439	0.58683288	2943.9592
514.76587	1.3835771	0.5886184	2946.5144
515.86694	1.3891021	0.59064591	2951.2297
516.96802	1.3905547	0.59245551	2951.5962
518.06909	1.3955125	0.59431368	2951.301
519.17017	1.3987749	0.59609956	2957.3391
520.27124	1.401013	0.59778321	2948.8252
521.37231	1.4035435	0.59961677	2955.6226
522.47339	1.4068748	0.60171789	2948.3264
523.57446	1.4107541	0.60330653	2957.9763
524.67554	1.4157462	0.60520965	2958.0591
525.77661	1.4207877	0.60704261	2956.2141
526.87769	1.4228975	0.60877079	2958.5273
527.97876	1.4232117	0.61059749	2962.5786
529.07983	1.4291106	0.61244839	2958.1396
530.18091	1.4328343	0.61433208	2961.5967
531.28198	1.4368436	0.61606872	2966.2427
532.38306	1.4371923	0.61802244	2961.2708
533.48413	1.443089	0.61991537	2966.6904
534.58521	1.445613	0.62144178	2964.9426
535.68628	1.4453303	0.62347907	2965.6936
536.78735	1.4531986	0.62519568	2964.9216
537.88843	1.4518054	0.62679785	2951.6833
538.9895	1.4555007	0.62844181	2959.4382
540.09058	1.4616586	0.62987798	2965.8152
541.19165	1.4661347	0.63152474	2968.0476
542.29272	1.4702363	0.63321739	2976.3489
543.3938	1.4716477	0.6349923	2974.1133
544.49487	1.4737625	0.63704705	2970.7549
545.59595	1.4777187	0.63909066	2974.2061
546.69702	1.481964	0.64108586	2980.3718
547.7981	1.4836627	0.64309895	2974.1748
548.89917	1.48869	0.64499003	2973.4258
550.00024	1.490932	0.64690638	2977.0779
551.10132	1.4945085	0.64855826	2974.636
552.20239	1.4931459	0.65023762	2974.0374
553.30347	1.5010977	0.65193206	2971.2983
554.40454	1.5038486	0.65341413	2979.5547
555.50562	1.5075439	0.65520072	2980.5144
556.60669	1.5144988	0.65718776	2987.4124
557.70776	1.512019	0.6593039	2977.8645
558.80884	1.5182087	0.66106153	2983.728
559.90991	1.5166291	0.66284293	2982.5676
561.01099	1.5216148	0.66472721	2980.99
562.11206	1.5288908	0.66670871	2990.2012
563.21313	1.5280114	0.66819566	2974.8704
564.31421	1.5324252	0.66998392	2985.7739
565.41528	1.5384347	0.67197853	2998.1355
566.51636	1.5378096	0.67381144	2980.9692
567.61743	1.5458611	0.67558968	2993.3411
568.71851	1.5472543	0.67751962	2991.6023
569.81958	1.550126	0.67935532	2990.0969
570.92065	1.5567893	0.68139368	3000.1543
572.02173	1.5581505	0.68330419	2990.075
573.1228	1.5611335	0.68489975	2988.0645
574.22388	1.5645976	0.68662721	2998.0137
575.32495	1.5659566	0.68840933	2996.5684
576.42603	1.5697076	0.69020027	2994.3594
577.5271	1.5733092	0.69202816	3003.2747
578.62817	1.5756946	0.6939733	2998.8684
579.72925	1.5803258	0.69577301	2992.8694
580.83032	1.586023	0.6973815	2998.2773
581.9314	1.585747	0.69915658	3001.5635
583.03247	1.5881878	0.70101082	2997.7422
584.13354	1.5936568	0.70280492	2999.2424
585.23462	1.5934004	0.70474553	3003.7141
586.33569	1.602254	0.7063145	3002.6196
587.43677	1.5983771	0.70829898	3003.5732
588.53784	1.6091014	0.71005207	3005.1702
589.63892	1.6117748	0.71169156	3006.4373
590.73999	1.6124365	0.71364754	3002.7175
591.84106	1.6158912	0.71546191	3007.4421
592.94214	1.6216943	0.71753496	3010.7253
594.04321	1.6220589	0.71966124	3006.3828
595.14429	1.6275241	0.72146529	3008.7324
596.24536	1.6296741	0.72337985	3006.6157
597.34644	1.6350653	0.72496557	3012.0085
598.44751	1.6369793	0.72685409	3008.9241
599.54858	1.6405641	0.72877979	3013.5662
600.64966	1.6460505	0.73059744	3016.0952
601.75073	1.6473902	0.73256284	3020.447
602.85181	1.6511122	0.73423821	3017.8193
603.95288	1.6531111	0.7358647	3012.2913
605.05396	1.6553532	0.73761624	3018.9609
606.15503	1.6581845	0.73927873	3016.2678
607.2561	1.6615341	0.74105215	3016.0295
608.35718	1.665992	0.74294513	3022.5833
609.45825	1.6666571	0.74452025	3015.1702
610.55933	1.6710954	0.74636227	3008.6724
611.6604	1.6752839	0.74781978	3017.314
612.76147	1.6758518	0.74919903	3017.5151
613.86255	1.6833761	0.75098199	3023.6592
614.96362	1.6841866	0.75301528	3025.2605
616.0647	1.6873717	0.75487709	3019.8645
617.16577	1.6927508	0.75675339	3025.6311
618.26685	1.6948702	0.75857985	3025.6814
619.36792	1.6992844	0.76026839	3028.7834
620.46899	1.7031531	0.76215327	3029.25
621.57007	1.7060523	0.76406211	3030.8318
622.67114	1.7097275	0.7659561	3031.104
623.77222	1.7132922	0.76794404	3030.7178
624.87329	1.715932	0.76958299	3037.3149
625.97437	1.7179965	0.77168673	3031.7576
627.07544	1.7230003	0.77359629	3033.2834
628.17651	1.7278756	0.7753396	3036.4021
629.27759	1.7290629	0.77718186	3033.7937
630.37866	1.7284595	0.77897787	3030.9121
631.47974	1.7335747	0.78089792	3023.7083
632.58081	1.7385083	0.78242958	3031.22
633.68188	1.7438794	0.78410834	3046.5513
634.78296	1.7456931	0.78604174	3040.2832
635.88403	1.7487793	0.78785658	3039.0576
636.98511	1.7520666	0.78970551	3040.0122
638.08618	1.757576	0.79196012	3045.0193
639.18726	1.7560873	0.79328102	3032.897
640.28833	1.7607788	0.79497707	3034.1279
641.3894	1.7639643	0.79673016	3040.5269
642.49048	1.7695791	0.79880488	3042.416
643.59155	1.7706339	0.80086219	3038.5205
644.69263	1.7756115	0.80246747	3039.6912
645.7937	1.7795948	0.8042056	3045.6819
646.89478	1.7825142	0.80578727	3037.8027
647.99585	1.7857455	0.8075363	3047.218
649.09692	1.7905385	0.80954438	3047.9014
650.198	1.7896829	0.8110075	3040.7261
651.29907	1.7944173	0.81276357	3048.2795
652.40015	1.7972172	0.81471801	3051.3782
653.50122	1.8019797	0.81636906	3044.3237
654.60229	1.8070422	0.81818938	3052.7949
655.70337	1.8085588	0.81977928	3053.4648
656.80444	1.8102276	0.82188737	3049.8247
657.90552	1.8141159	0.82388711	3052.2109
659.00659	1.8191494	0.82570529	3054.5964
660.10767	1.8205024	0.82770467	3055.2935
661.20874	1.8223592	0.82962066	3056.4988
662.30981	1.8272502	0.8315798	3054.8862
663.41089	1.8321768	0.83321458	3052.3501
664.51196	1.8344314	0.83520103	3063.7126
665.61304	1.836336	0.83702552	3052.8333
666.71411	1.8405232	0.83873242	3058.8914
667.81519	1.842689	0.84051085	3052.4194
668.91626	1.8478959	0.84224862	3061.0383
670.01733	1.8519752	0.84412158	3057.218
671.11841	1.8557529	0.8460179	3066.584
672.21948	1.8557453	0.84778464	3063.9832
673.32056	1.8606776	0.84991801	3065.6311
674.42163	1.8627158	0.85176682	3062.5818
675.52271	1.8691989	0.85357994	3064.7466
676.62378	1.8713046	0.85554624	3066.0989
677.72485	1.8750811	0.85712028	3066.019
678.82593	1.8754253	0.85891384	3064.3979
679.927	1.8801234	0.8606264	3060.4846
681.02808	1.8842226	0.86215848	3068.6487
682.12915	1.8861845	0.86392087	3065.707
683.23022	1.8881056	0.86577988	3067.6072
684.3313	1.8940036	0.86752093	3074.0801
685.43237	1.8951018	0.8694061	3067.3462
686.53345	1.9028943	0.87111682	3074.9448
687.63452	1.9021587	0.87296623	3067.0947
688.7356	1.908849	0.8747949	3072.1226
689.83667	1.9128023	0.87651193	3075.645
690.93774	1.9120914	0.87843078	3072.5359
692.03882	1.9173484	0.88060439	3075.2266
693.13989	1.9201692	0.88247567	3077.0298
694.24097	1.926616	0.88440877	3078.8809
695.34204	1.9260283	0.88644129	3075.543
696.44312	1.9274359	0.88841778	3075.949
697.54419	1.9330025	0.89028078	3073.3901
698.64526	1.937441	0.89191276	3074.092
699.74634	1.9403068	0.89353502	3076.1301
700.84741	1.9428841	0.8951602	3081.2488
701.94849	1.9465048	0.89701629	3084.5798
703.04956	1.9510503	0.89899373	3084.6555
704.15063	1.9535303	0.90104014	3084.7871
705.25171	1.9565969	0.90282172	3080.5278
706.35278	1.9617743	0.90495634	3082.0298
707.45386	1.9649254	0.90675545	3084.043
708.55493	1.9673201	0.90832633	3081.3364
709.65601	1.9706258	0.91020167	3080.7444
710.75708	1.9744542	0.91181302	3085.9404
711.85815	1.9773371	0.91398835	3092.8335
712.95923	1.979075	0.91578853	3094.8997
714.0603	1.9848685	0.91772443	3085.3865
715.16138	1.9898105	0.91981286	3088.0667
716.26245	1.9894462	0.92119044	3090.4922
717.36353	1.9912398	0.92327595	3086.0325
718.4646	1.9970286	0.92518061	3088.3667
719.56567	2.0015943	0.92678589	3086.5815
720.66675	2.0013542	0.92858326	3084.0393
721.76782	2.0044289	0.93038064	3085.895
722.8689	2.0088406	0.93251956	3089.5276
723.96997	2.0106382	0.93440783	3084.8181
725.07104	2.0168672	0.93600982	3091.7612
726.17212	2.0223451	0.93771285	3093.1702
727.27319	2.0210984	0.93957847	3092.4661
728.37427	2.0276785	0.9413504	3097.4778
729.47534	2.030216	0.9430992	3095.6528
730.57642	2.0318058	0.94500583	3098.2981
731.67749	2.0322127	0.94683379	3096.6938
732.77856	2.038408	0.94873929	3096.6655
733.87964	2.0418823	0.95061177	3093.0864
734.98071	2.0461113	0.95239913	3099.1528
736.08179	2.0497885	0.95457405	3102.0681
737.18286	2.0533359	0.95664591	3104.7793
738.28394	2.0572116	0.95855719	3099.7893
739.38501	2.0648973	0.96033096	3095.7617
740.48608	2.0636306	0.96172059	3093.1877
741.58716	2.0654001	0.96358436	3102.3545
742.68823	2.0676675	0.96554482	3105.748
743.78931	2.0750828	0.96731091	3098.6846
744.89038	2.0736639	0.96910071	3104.6975
745.99146	2.0812287	0.97093856	3109.7351
747.09253	2.0833981	0.97294456	3112.6619
748.1936	2.0842462	0.97526497	3107.1802
749.29468	2.0879047	0.97709835	3105.1655
750.39575	2.0917037	0.9791106	3106.5505
751.49683	2.0963671	0.98061681	3111.4749
752.5979	2.1005242	0.98251885	3110.7571
753.69897	2.1034	0.98478317	3105.3723
754.80005	2.1060395	0.98607242	3097.929
755.90112	2.109535	0.98760319	3106.9558
757.0022	2.1125433	0.98888987	3105.8066
758.10327	2.1157458	0.99053955	3109.3792
759.20435	2.1177137	0.99267185	3114.5938
760.30542	2.1224036	0.99433237	3114.5486
761.40649	2.1265872	0.99631679	3117.7693
762.50757	2.1275637	0.99821186	3115.4495
763.60864	2.1338229	1.0001334	3115.5002
764.70972	2.1342909	1.0020483	3110.2778
765.81079	2.1406064	1.0040574	3119.0195
766.91187	2.1425006	1.0060179	3114.1001
768.01294	2.1443355	1.0079621	3114.6909
769.11401	2.1473131	1.0101212	3111.4111
770.21509	2.1518626	1.0121092	3118.5623
771.31616	2.1569324	1.013905	3116.5039
772.41724	2.1554108	1.0159112	3112.9141
773.51831	2.1600747	1.0181165	3126.0054
774.61938	2.1638639	1.0202466	3115.3586
775.72046	2.1696062	1.0218221	3111.2422
776.82153	2.1702385	1.0234529	3116.2227
777.92261	2.1758814	1.0256439	3126.0359
779.02368	2.1773033	1.0277791	3120.8293
780.12476	2.181927	1.0298164	3121.4399
781.22583	2.1840253	1.031667	3114.0413
782.3269	2.1886117	1.0331922	3118.7234
783.42798	2.1890271	1.0348599	3118.6946
784.52905	2.1935513	1.036729	3123.5466
785.63013	2.1985013	1.0385923	3125.8992
786.7312	2.200793	1.0403554	3122.2395
787.83228	2.205863	1.0421113	3126.3467
788.93335	2.2066736	1.044013	3120.5051
790.03442	2.208724	1.045743	3126.8459
791.1355	2.2145755	1.0475123	3125.354
792.23657	2.2185826	1.0499774	3132.8967
793.33765	2.2184062	1.0522255	3125.8806
794.43872	2.225147	1.0543596	3130.009
795.53979	2.230036	1.0562888	3126.0884
796.64087	2.2312899	1.0582719	3128.4236
797.74194	2.2330604	1.0602032	3129.3438
798.84302	2.2364962	1.0621682	3128.3259
799.94409	2.2380252	1.0641161	3124.1802
801.04517	2.2449131	1.0660031	3133.0967
802.14624	2.2462375	1.0678352	3130.4233
803.24731	2.2498331	1.0696126	3130.595
804.34839	2.2556782	1.0715408	3133.9683
805.44946	2.2560687	1.0734466	3133.7825
806.55054	2.2623544	1.0753409	3134.4792
807.65161	2.2632689	1.0774089	3126.5942
808.75269	2.2666726	1.0794086	3138.6567
809.85376	2.2705832	1.0815452	3139.5732
810.95483	2.2739904	1.0835798	3136.5884
812.05591	2.2771659	1.0855161	3130.6909
813.15698	2.2821963	1.0874406	3137.8059
814.25806	2.2866375	1.0891486	3137.4341
815.35913	2.2888124	1.0914327	3142.5881
816.46021	2.2931669	1.0934319	3137.8577
817.56128	2.291887	1.0952617	3135.5237
818.66235	2.2969594	1.0973792	3140.188
819.76343	2.2989223	1.0992869	3134.8357
820.8645	2.3008051	1.1009355	3140.7654
821.96558	2.3065438	1.1027828	3131.2314
823.06665	2.3131783	1.1046224	3139.3699
824.16772	2.3130178	1.1063286	3141.1345
825.2688	2.3124113	1.1083244	3138.4622
826.36987	2.3194203	1.1103007	3145.5879
827.47095	2.3211722	1.1121937	3131.1316
828.57202	2.3262162	1.1142738	3144.5364
829.6731	2.3312483	1.1160257	3141.6941
830.77417	2.3357632	1.1179026	3146.9927
831.87524	2.3359807	1.1199137	3147.1665
832.97632	2.3399284	1.122063	3146.0591
834.07739	2.3416011	1.1239202	3143.4414
835.17847	2.3506908	1.1257687	3143.6055
836.27954	2.3491871	1.1275728	3146.8933
837.38062	2.3522251	1.1296129	3148.4934
838.48169	2.3573079	1.1314443	3148.4299
839.58276	2.3609834	1.1335146	3148.2817
840.68384	2.3629472	1.1354847	3143.1406
841.78491	2.3683259	1.1375567	3149.0669
842.88599	2.3711097	1.1398306	3152.7981
843.98706	2.3730035	1.142295	3150.8435
845.08813	2.3753178	1.144712	3150.4978
846.18921	2.378613	1.1466229	3140.844
847.29028	2.3828864	1.148526	3151.5896
848.39136	2.3855858	1.1501439	3139.1824
849.49243	2.3893502	1.1521615	3152.5171
850.59351	2.3904603	1.153811	3143.8994
851.69458	2.3974948	1.1558071	3156.1084
852.79565	2.3980536	1.1579338	3151.7534
853.89673	2.4033012	1.1597667	3154.4106
854.9978	2.4074044	1.161938	3154.4409
856.09888	2.4089246	1.1637824	3149.7148
857.19995	2.4128296	1.1657515	3153.5195
858.30103	2.4136198	1.167812	3145.1497
859.4021	2.4199808	1.1698456	3157.5652
860.50317	2.4213159	1.1720763	3160.426
861.60425	2.4240389	1.1741743	3152.5828
862.70532	2.4329023	1.176237	3154.7288
863.8064	2.4311347	1.1779059	3147.2195
864.90747	2.4344203	1.1795976	3147.3853
866.00854	2.4389002	1.1818517	3153.114
867.10962	2.4420035	1.1838927	3158.2959
868.21069	2.4442143	1.1858168	3159.2178
869.31177	2.4489484	1.1881037	3164.5906
870.41284	2.4529614	1.1901245	3153.9084
871.51392	2.4541605	1.1918548	3154.696
872.61499	2.4594054	1.1937182	3153.7805
873.71606	2.4594293	1.1958191	3158.1853
874.81714	2.4622777	1.1978422	3156.4553
875.91821	2.4710591	1.199746	3155.9814
877.01929	2.4705143	1.2015699	3157.4329
878.12036	2.4756956	1.2037541	3160.7102
879.22144	2.4798384	1.2058768	3159.2634
880.32251	2.4818728	1.2080126	3162.0381
881.42358	2.4859085	1.2101188	3159.7273
882.52466	2.4916019	1.2121952	3161.6484
883.62573	2.4916544	1.2139626	3155.1794
884.72681	2.4948611	1.2158862	3153.3494
885.82788	2.5008202	1.217774	3158.4417
886.92896	2.5024154	1.2197481	3169.7646
888.03003	2.5057695	1.2219946	3164.8994
889.1311	2.5062876	1.2244014	3160.0479
890.23218	2.5116243	1.2267329	3162.3384
891.33325	2.5166001	1.2289957	3170.1299
892.43433	2.5217793	1.2311943	3161.0779
893.5354	2.5204062	1.2333949	3163.9248
894.63647	2.5242195	1.2354243	3159.822
895.73755	2.5291336	1.237757	3171.1389
896.83862	2.5302792	1.2397515	3161.8225
897.9397	2.5328753	1.2413781	3159.9761
899.04077	2.5390375	1.2433593	3165.8003
900.14185	2.5408902	1.2449636	3158.5342
901.24292	2.5458016	1.2467916	3167.4717
902.34399	2.5466893	1.248798	3164.6763
903.44507	2.5497499	1.250759	3166.6384
904.54614	2.5567398	1.2530502	3172.4958
905.64722	2.5608532	1.255249	3174.2332
906.74829	2.565263	1.2574025	3168.1594
907.84937	2.5632982	1.2597239	3165.0361
908.95044	2.5666416	1.2617992	3171.063
910.05151	2.5728598	1.2635216	3170.2175
911.15259	2.5746214	1.2658095	3166.4075
912.25366	2.5761998	1.2680601	3171.6265
913.35474	2.579102	1.2699742	3162.5391
914.45581	2.582588	1.2721027	3166.1357
915.55688	2.5866911	1.274694	3174.4678
916.65796	2.5889304	1.2773038	3173.4219
917.75903	2.5959411	1.2794571	3168.0037
918.86011	2.5994217	1.2816734	3172.7231
919.96118	2.5967975	1.2834843	3160.5171
921.06226	2.6043248	1.2855442	3171.9265
922.16333	2.6105649	1.2876508	3171.5107
923.2644	2.6072562	1.2897407	3167.6262
924.36548	2.6132147	1.2917305	3171.9695
925.46655	2.6197796	1.2939651	3177.8547
926.56763	2.6214986	1.2960777	3168.7415
927.6687	2.6241298	1.2982174	3174.5974
928.76978	2.6283619	1.3005592	3175.217
929.87085	2.6283736	1.3027892	3167.8633
930.97192	2.6339121	1.3050537	3176.0366
932.073	2.6374242	1.3073791	3172.6848
933.17407	2.6408083	1.3094136	3177.5264
934.27515	2.6412673	1.3116944	3176.5603
935.37622	2.6472511	1.3140647	3174.4553
936.47729	2.6508017	1.3158545	3170.8005
937.57837	2.6533129	1.318012	3170.6653
938.67944	2.6559591	1.3199224	3170.7603
939.78052	2.658798	1.3217725	3171.5566
940.88159	2.6645415	1.3240242	3180.0806
941.98267	2.6678529	1.3262036	3173.5107
943.08374	2.6685734	1.3287181	3175.8882
944.18481	2.673949	1.3308731	3176.6475
945.28589	2.6776526	1.332835	3178.3132
946.38696	2.6768799	1.3351513	3172.8391
947.48804	2.6816683	1.3372723	3171.9653
948.58911	2.6878822	1.3394251	3180.3235
949.69019	2.6907425	1.3418442	3179.5283
950.79126	2.692004	1.3443549	3181.9695
951.89233	2.6962414	1.346895	3179.4241
952.99341	2.7005289	1.348964	3177.7222
954.09448	2.70453	1.3512967	3179.1797
955.19556	2.7068934	1.3537747	3176.0564
956.29663	2.7079189	1.3556241	3175.4263
957.39771	2.7145841	1.3582163	3181.958
958.49878	2.7185156	1.3604264	3178.293
959.59985	2.7213926	1.3627039	3183.3767
960.70093	2.721858	1.3645688	3170.3669
961.802	2.7274888	1.3670802	3188.7251
962.90308	2.7309513	1.3694227	3178.6531
964.00415	2.7316453	1.3715456	3178.5029
965.10522	2.7346172	1.3734602	3175.623
966.2063	2.7361894	1.3753314	3178.7202
967.30737	2.7418292	1.377661	3178.9041
968.40845	2.7451153	1.3797381	3178.6753
969.50952	2.7501762	1.3816112	3177.2598
970.6106	2.754636	1.3840402	3188.4749
971.71167	2.7576971	1.3862106	3185.2659
972.81274	2.7608161	1.3887658	3182.9639
973.91382	2.7638102	1.3910205	3183.7585
975.01489	2.7640955	1.3929929	3176.2415
976.11597	2.7670214	1.395537	3179.4722
977.21704	2.7735257	1.3976972	3179.5313
978.31812	2.776185	1.4002861	3186.0959
979.41919	2.777667	1.4027774	3182.3337
980.52026	2.7816508	1.4048648	3177.9824
981.62134	2.7872014	1.4073181	3185.8982
982.72241	2.7902465	1.4095896	3177.0908
983.82349	2.7921679	1.4118634	3181.8689
984.92456	2.7972171	1.4143598	3182.0391
986.02563	2.7980604	1.4165992	3177.3535
987.12671	2.802125	1.4190716	3182.4653
988.22778	2.8048577	1.4218285	3186.3499
989.32886	2.8106508	1.4242588	3184.4934
990.42993	2.8125386	1.4263468	3176.2192
991.53101	2.8185763	1.4282906	3188.887
992.63208	2.817857	1.4309467	3185.7639
993.73315	2.8205795	1.4330078	3185.0386
994.83423	2.8241062	1.4351634	3181.533
995.9353	2.8272164	1.4375068	3188.6118
997.03638	2.8361297	1.4401397	3184.0532
998.13745	2.8384755	1.4425694	3184.3025
999.23853	2.8396988	1.4445875	3188.3752
1000.3396	2.8412974	1.4470783	3182.6501
1001.4407	2.8457921	1.4496404	3194.939
1002.5417	2.849179	1.4522222	3193.7949
1003.6428	2.8516352	1.4546982	3182.5581
1004.7439	2.8550038	1.4569473	3183.5325
1005.845	2.8573585	1.459173	3183.8083
1006.946	2.8656669	1.4612193	3183.946
1008.0471	2.8660715	1.4633846	3192.8264
1009.1482	2.8687451	1.4661335	3187.3274
1010.2493	2.8715672	1.4686426	3177.9607
1011.3503	2.8780591	1.4712682	3188.0364
1012.4514	2.8773005	1.473893	3190.6538
1013.5525	2.882998	1.4767795	3187.9341
1014.6536	2.8841014	1.4790959	3185.0044
1015.7546	2.8887913	1.481252	3184.8364
1016.8557	2.8932011	1.4835877	3191.1335
1017.9568	2.8939199	1.4860816	3190.2876
1019.0579	2.8955388	1.4884396	3182.3604
1020.1589	2.8996472	1.4909031	3182.5229
1021.26	2.9054806	1.4934516	3192.4509
1022.3611	2.9069827	1.4959821	3189.6357
1023.4622	2.9115648	1.4985213	3185.4753
1024.5632	2.9153569	1.5004957	3185.1416
1025.6643	2.9172013	1.5028027	3187.4055
1026.7654	2.9202554	1.5055236	3191.2512
1027.8665	2.9246144	1.5080657	3187.1943
1028.9675	2.9252701	1.5102671	3187.1978
1030.0686	2.9305253	1.5125688	3182.5181
1031.1697	2.9373066	1.5151421	3193.3083
1032.2708	2.9400785	1.5179449	3196.3577
1033.3718	2.9409585	1.5206344	3190.3025
1034.4729	2.9424794	1.5228624	3183.5791
1035.574	2.9490137	1.5255715	3193.5117
1036.675	2.9508133	1.5281305	3187.3821
1037.7761	2.9536736	1.5304903	3186.9441
1038.8772	2.9584596	1.5329272	3180.0564
1039.9783	2.9617898	1.5351441	3180.0571
1041.0793	2.9685619	1.5371084	3182.9785
1042.1804	2.9675653	1.5392973	3191.1724
1043.2815	2.9720695	1.5414596	3190.113
1044.3826	2.9754124	1.5439727	3192.2371
1045.4836	2.9765799	1.5461326	3181.448
1046.5847	2.9793167	1.5482442	3183.6755
1047.6858	2.9847846	1.5509875	3192.1438
1048.7869	2.9864507	1.553533	3193.2817
1049.8879	2.9889615	1.5566756	3190.3909
1050.989	2.9903388	1.5594596	3179.2278
1052.0901	2.998673	1.5612127	3173.0308
1053.1912	2.9977868	1.563118	3175.127
1054.2922	3.002249	1.5647814	3176.7727
1055.3933	3.0078185	1.5667574	3196.3728
1056.4944	3.010355	1.5691646	3186.9009
1057.5955	3.0144045	1.5713593	3192.0046
1058.6965	3.0178864	1.5739942	3194.7771
1059.7976	3.0174713	1.5767217	3190.4275
1060.8987	3.023051	1.5797085	3189.686
1061.9998	3.0265257	1.5825592	3190.2732
1063.1008	3.02933	1.5852975	3187.1619
1064.2019	3.0347311	1.5880113	3187.0039
1065.303	3.0359538	1.5908484	3185.7454
1066.4041	3.0405803	1.5938936	3190.9177
1067.5051	3.0440748	1.5967711	3185.6921
1068.6062	3.0468175	1.5992092	3182.7397
1069.7073	3.0496683	1.6018707	3189.6541
1070.8083	3.0523329	1.6048089	3190.3372
1071.9094	3.0587683	1.6074771	3189.24
1073.0105	3.0609138	1.6104196	3193.3662
1074.1116	3.0615976	1.6134901	3179.834
1075.2126	3.0650022	1.6160471	3182.5984
1076.3137	3.0710437	1.6186471	3188.5186
1077.4148	3.073838	1.6210201	3185.2305
1078.5159	3.0742583	1.6234268	3180.4204
1079.6169	3.0779274	1.6255789	3188.4709
1080.718	3.0852315	1.6281017	3184.8638
1081.8191	3.0860639	1.6307093	3183.5015
1082.9202	3.0894387	1.6335988	3190.4429
1084.0212	3.0949769	1.6363496	3184.7354
1085.1223	3.0943947	1.6391058	3187.4243
1086.2234	3.1014934	1.6420143	3185.7549
1087.3245	3.1049016	1.6440376	3180.1206
1088.4255	3.109277	1.6465775	3188.2395
1089.5266	3.1096728	1.6490802	3183.9553
1090.6277	3.1115518	1.6518029	3189.0396
1091.7288	3.1166816	1.6551456	3193.0779
1092.8298	3.1208897	1.65792	3188.6438
1093.9309	3.1210818	1.6607858	3183.6519
1095.032	3.1250191	1.6637782	3186.7346
1096.1331	3.1285741	1.6668639	3191.0625
1097.2341	3.1332176	1.6702051	3190.1228
1098.3352	3.1375189	1.6731496	3180.7927
1099.4363	3.1383576	1.6754278	3184.5032
1100.5374	3.1424265	1.6782134	3182.3269
1101.6384	3.1447287	1.6813176	3183.3938
1102.7395	3.1498768	1.6842489	3178.0466
1103.8406	3.155416	1.6869889	3185.6333
1104.9417	3.1545632	1.6901075	3183.7957
1106.0427	3.1580241	1.6930319	3182.6965
1107.1438	3.1629493	1.6956038	3184.8801
1108.2449	3.1659467	1.6981971	3176.3274
1109.3459	3.1685092	1.7008243	3177.7986
1110.447	3.1731572	1.7034042	3180.5496
1111.5481	3.1731629	1.7059708	3179.3501
1112.6492	3.1797631	1.7087711	3185.1343
1113.7502	3.1862195	1.7117496	3182.541
1114.8513	3.1881044	1.7145491	3186.113
1115.9524	3.1894267	1.7177086	3184.3721
1117.0535	3.1944973	1.7203751	3176.5525
1118.1545	3.1970892	1.7235315	3185.8086
1119.2556	3.1986301	1.7265919	3182.8376
1120.3567	3.2024498	1.7295227	3176.439
1121.4578	3.2008169	1.732217	3175.5715
1122.5588	3.2072539	1.7349571	3176.3462
1123.6599	3.2119882	1.7374399	3181.8101
1124.761	3.2138672	1.7404432	3185.6938
1125.8621	3.2211177	1.7436393	3186.1125
1126.9631	3.2209234	1.7466279	3175.7693
1128.0642	3.2251713	1.749458	3178.9836
1129.1653	3.2282045	1.752328	3181.0718
1130.2664	3.2303114	1.7554698	3180.8328
1131.3674	3.2363391	1.7589852	3179.1868
1132.4685	3.2370541	1.7616141	3179.6379
1133.5696	3.2434549	1.7644089	3173.7859
1134.6707	3.2427487	1.7673312	3179.2302
1135.7717	3.2476661	1.7708015	3181.8188
1136.8728	3.2521882	1.7738832	3173.0068
1137.9739	3.2553406	1.7762078	3166.4966
1139.075	3.2581494	1.7789534	3179.5376
1140.176	3.2615094	1.7824451	3182.3911
1141.2771	3.2652211	1.7855088	3177.0559
1142.3782	3.2667856	1.7884518	3171.3606
1143.4792	3.2721372	1.7914394	3179.0461
1144.5803	3.2728405	1.7947726	3176.564
1145.6814	3.2806866	1.7980269	3180.5229
1146.7825	3.2804875	1.8011588	3175.5593
1147.8835	3.2833302	1.8043634	3170.6514
1148.9846	3.2859576	1.8074554	3170.7407
1150.0857	3.2912059	1.8102913	3170.8965
1151.1868	3.2960446	1.8133365	3174.1777
1152.2878	3.2944274	1.8160138	3165.9385
1153.3889	3.2995362	1.8190213	3178.1042
1154.49	3.3048	1.8215784	3172.2461
1155.5911	3.3051283	1.8245134	3167.2534
1156.6921	3.313884	1.8276438	3169.782
1157.7932	3.3128324	1.8309805	3169.4229
1158.8943	3.3173685	1.834955	3173.0869
1159.9954	3.3181288	1.8383107	3163.115
1161.0964	3.3267927	1.8414077	3166.0288
1162.1975	3.3281152	1.8441652	3165.3423
1163.2986	3.3317544	1.8471066	3167.9099
1164.3997	3.3314769	1.8491559	3160.8308
1165.5007	3.335052	1.8528208	3172.8333
1166.6018	3.3415024	1.8568318	3169.2913
1167.7029	3.3419652	1.8605317	3174.1731
1168.804	3.345706	1.8645359	3162.7051
1169.905	3.3528206	1.8678087	3165.3438
1171.0061	3.3540425	1.8711246	3161.8027
1172.1072	3.359834	1.8738006	3158.6978
1173.2083	3.3634748	1.8763908	3165.2305
1174.3093	3.3620701	1.8793143	3159.6533
1175.4104	3.3677313	1.8829293	3164.9197
1176.5115	3.3706748	1.8865581	3169.6987
1177.6125	3.3764541	1.8903496	3165.0232
1178.7136	3.378027	1.8941106	3156.6455
1179.8147	3.3786781	1.8968049	3152.636
1180.9158	3.3855245	1.8997993	3157.5178
1182.0168	3.3901627	1.902914	3164.6606
1183.1179	3.3922532	1.9065582	3158.7673
1184.219	3.3941629	1.9095379	3157.3599
1185.3201	3.3966343	1.9122263	3148.7244
1186.4211	3.3980458	1.9145201	3141.9758
1187.5222	3.404562	1.9172627	3160.1809
1188.6233	3.4045193	1.9202454	3150.0645
1189.7244	3.4124057	1.9236376	3159.7991
1190.8254	3.4149673	1.9271075	3156.3032
1191.9265	3.4164951	1.9305832	3147.5823
1193.0276	3.4203773	1.933849	3148.7952
1194.1287	3.4226611	1.9370986	3148.9485
1195.2297	3.4268305	1.9401699	3143.5154
1196.3308	3.428787	1.9429541	3153.7876
1197.4319	3.4327273	1.9466894	3149.9397
1198.533	3.4349744	1.9504679	3149.9219
1199.634	3.4409115	1.9539417	3148.5491
1200.7351	3.4400282	1.9575713	3146.4504
1201.8362	3.4444392	1.9609852	3142.0918
1202.9373	3.4500353	1.964427	3145.981
1204.0383	3.4519947	1.9676973	3141.8945
1205.1394	3.457392	1.9712993	3143.7603
1206.2405	3.459965	1.9742092	3141.4312
1207.3416	3.4590194	1.9775536	3140.1519
1208.4426	3.4670444	1.9808733	3134.9504
1209.5437	3.470371	1.984156	3141.5627
1210.6448	3.4717126	1.9872437	3129.6267
1211.7458	3.4756973	1.9902749	3138.1267
1212.8469	3.4804034	1.9933944	3131.25
1213.948	3.4818873	1.9964099	3128.4304
1215.0491	3.485945	2.0002186	3139.3972
1216.1501	3.4869163	2.0039878	3126.5786
1217.2512	3.4926264	2.0071988	3126.9614
1218.3523	3.49389	2.0106885	3124.0586
1219.4534	3.4988756	2.0141361	3130.4111
1220.5544	3.502151	2.0184131	3135.697
1221.6555	3.5077543	2.0219896	3124.6619
1222.7566	3.5095875	2.0250406	3131.4187
1223.8577	3.5139043	2.0279567	3119.9492
1224.9587	3.5175753	2.0309281	3120.7134
1226.0598	3.5154712	2.034282	3119.4443
1227.1609	3.5201089	2.0375819	3121.4189
1228.262	3.5241275	2.0412245	3116.2893
1229.363	3.5265694	2.0443616	3117.4836
1230.4641	3.5302439	2.0470533	3113.2532
1231.5652	3.5355229	2.0491219	3122.8384
1232.6663	3.5397606	2.0504837	3114.8691
1233.7673	3.5426691	2.0506241	3115.5217
1234.8684	3.5436597	2.0508039	3118.3042
1235.9695	3.5532453	2.0507913	3117.9597
1237.0706	3.5491216	2.0506885	3107.5186
1238.1716	3.5540831	2.0506902	3115.3323
1239.2727	3.5605993	2.0503569	3108.2952
1240.3738	3.5614364	2.0506177	3099.6501
1241.4749	3.5618212	2.0505104	3104.1091
1242.5759	3.5698638	2.0499277	3111.0696
1243.677	3.5718632	2.0507321	3108.3447
1244.7781	3.5752559	2.0509512	3109.3484
1245.8792	3.5777013	2.0509369	3102.2573
1246.9802	3.581234	2.0509005	3094.5037
1248.0813	3.5856385	2.050874	3089.4822
1249.1824	3.5881212	2.0505755	3094.394
1250.2834	3.5911744	2.0503755	3101.063
1251.3845	3.5953665	2.050436	3094.4319
1252.4856	3.5982447	2.0503964	3090.9246
1253.5867	3.6001954	2.0500345	3092.5493
1254.6877	3.6008518	2.0501237	3084.3623
1255.7888	3.6082613	2.0498605	3092.0105
1256.8899	3.6116583	2.0498548	3090.6646
1257.991	3.6146009	2.0500822	3081.604
1259.092	3.6185932	2.0503314	3079.5637
1260.1931	3.6200957	2.050633	3075.8088
1261.2942	3.625175	2.0502744	3082.0112
1262.3953	3.6279671	2.0502305	3079.6868
1263.4963	3.6327877	2.050627	3078.053
1264.5974	3.6340325	2.0506492	3080.5938
1265.6985	3.6381676	2.0507207	3064.9729
1266.7996	3.6443682	2.0506098	3073.1379
1267.9006	3.6469059	2.050837	3070.0054
1269.0017	3.6476836	2.0505769	3067.2595
1270.1028	3.651629	2.050266	3064.012
1271.2039	3.6524382	2.050478	3064.2917
1272.3049	3.6591558	2.0504899	3064.5217
1273.406	3.6614799	2.0503395	3062.0483
1274.5071	3.666434	2.0503905	3062.624
1275.6082	3.66909	2.0503848	3056.4661
1276.7092	3.672653	2.0501347	3052.7327
1277.8103	3.6737273	2.0501106	3044.9993
1278.9114	3.6784277	2.0502656	3047.2361
1280.0125	3.6817472	2.0503693	3051.4739
1281.1135	3.683876	2.0501387	3046.4558
1282.2146	3.6872106	2.0501437	3042.436
1283.3157	3.6917415	2.0503221	3044.168
1284.4167	3.6954801	2.0507014	3036.217
1285.5178	3.6962368	2.0509531	3036.5149
1286.6189	3.6986642	2.0508583	3027.801
1287.72	3.7070925	2.0509186	3033.1968
1288.821	3.7070384	2.0510638	3028.6204
1289.9221	3.7112305	2.0512879	3022.0273
1291.0232	3.7132418	2.0514176	3018.5554
1292.1243	3.7141795	2.0509918	3013.6106
1293.2253	3.721746	2.0513084	3020.6655
1294.3264	3.7228506	2.0515053	3014.6306
1295.4275	3.7257144	2.051419	3010.925
1296.5286	3.7284915	2.0511837	3009.0625
1297.6296	3.7366483	2.0512829	3008.0344
1298.7307	3.7385886	2.0511661	3008.8096
1299.8318	3.7388663	2.0509925	3005.6519
1300.9329	3.7434151	2.0510461	3001.5857
1302.0339	3.746911	2.050684	2999.7483
1303.135	3.7507255	2.0508788	2999.1819
1304.2361	3.7577214	2.0507138	2994.1021
1305.3372	3.7564819	2.0506501	2985.356
1306.4382	3.7576029	2.0508537	2986.3914
1307.5393	3.7642963	2.0507202	2989.3369
1308.6404	3.766129	2.0509379	2973.4453
1309.7415	3.7700171	2.0509646	2974.415
1310.8425	3.7712409	2.0505807	2973.6902
1311.9436	3.7767384	2.0509222	2972.1206
1313.0447	3.7799623	2.0509877	2966.7881
1314.1458	3.7804043	2.0509379	2962.2988
1315.2468	3.7871251	2.0509441	2962.2673
1316.3479	3.7899201	2.0511823	2963.134
1317.449	3.7917275	2.0511546	2947.8152
1318.55	3.7981205	2.0511079	2951.563
1319.6511	3.8001928	2.0509391	2949.1497
1320.7522	3.8023927	2.0508862	2944.5916
1321.8533	3.8057191	2.050719	2939.8372
1322.9543	3.807045	2.0505655	2940.3542
1324.0554	3.8135104	2.050611	2933.7266
1325.1565	3.8137932	2.0508089	2924.3682
1326.2576	3.8225815	2.0507481	2937.5957
1327.3586	3.8265624	2.0509186	2922.8989
1328.4597	3.8268514	2.0509164	2919.9656
1329.5608	3.8298228	2.0509219	2919.8582
1330.6619	3.8299649	2.0507603	2912.835
1331.7629	3.8386512	2.0509408	2910.8687
1332.864	3.8398235	2.0508177	2910.906
1333.9651	3.8409622	2.0508137	2895.7646
1335.0662	3.8461061	2.0509231	2901.2886
1336.1672	3.850318	2.050791	2895.3293
1337.2683	3.8534107	2.0506532	2898.2761
1338.3694	3.8583047	2.0505068	2892.324
1339.4705	3.8613887	2.0508182	2880.2534
1340.5715	3.8629682	2.0509603	2877.2136
1341.6726	3.8654754	2.0508378	2871.0667
1342.7737	3.8691773	2.0508797	2869.658
1343.8748	3.8736446	2.050925	2860.1375
1344.9758	3.8772583	2.0511899	2853.0771
1346.0769	3.8786094	2.0511458	2848.9453
1347.178	3.8783531	2.0508404	2843.2576
1348.2791	3.8889077	2.0510867	2839.3179
1349.3801	3.891309	2.0510068	2835.9639
1350.4812	3.8932889	2.0511198	2833.0115
1351.5823	3.8950729	2.0510759	2815.5139
1352.6833	3.9004114	2.0508344	2815.802
1353.7844	3.9033074	2.0509286	2814.9045
1354.8855	3.9046817	2.0508299	2805.9417
1355.9866	3.9095051	2.0509689	2801.0186
1357.0876	3.9135902	2.0511868	2792.8501
1358.1887	3.9167023	2.0506127	2781.8997
1359.2898	3.9172821	2.0509322	2780.7637
1360.3909	3.9207375	2.0507646	2775.5757
1361.4919	3.9275198	2.0509074	2768.3542
1362.593	3.9275789	2.0506809	2758.0676
1363.6941	3.9346356	2.0498629	2746.0305
1364.7952	3.9352841	2.0502534	2722.5447
1365.8962	3.939117	2.0499821	2719.9299
1366.9973	3.9432518	2.050384	2706.0356
1368.0984	3.9495733	2.0502918	2691.5449
1369.1995	3.9491093	2.0502291	2666.104
1370.3005	3.9578664	2.049957	2632.6982
1371.4016	3.9601357	2.0501935	2603.0464
1371.7019	3.9597096	2.0501595	2560.7561