File: datasets/am_bench_2022/raw_data/60-X.14-1/specimen.dat
MTS793|MPT|ENU|1|2|.|/|:|1|0|0|A

Operator Information						Time:	29.0625	Sec	11/1/2021 11:45:53 AM
Operator	Nick Derimow
Project	AM Bench 2022 mini-tensile challenge
Specimen ID	60-X.14-1
Material	PBF-L Inconel 625
Specimen Width	2.55	mm
Specimen Thickness	1.52	mm
Notes
Operator Information End

Data Acquisition						Time:	1030.0593	Sec	11/1/2021 12:02:34 PM
Time	Axial Displacement	Axial Extensometer	Axial Force
Sec	mm	mm	N
29.177002	0.00070242293	1.9114699e-05	67.538605
30.077881	0.0063337488	0.00013881917	82.576042
30.97876	0.0079712374	9.6242831e-05	94.917976
31.879639	0.0087883426	0.00022822847	106.89763
32.780518	0.014216263	8.3400264e-05	115.85007
33.681396	0.014534868	3.0486148e-05	121.98673
34.582275	0.014143527	0.00012742313	132.06798
35.483154	0.019998183	0.00016243491	144.01134
36.384033	0.024020808	0.00016195956	155.33905
37.284912	0.025214503	0.00026245243	164.4729
38.185791	0.029309556	0.00034888671	186.87209
39.08667	0.03017645	0.00045435637	201.02827
39.987549	0.034765135	0.00049269048	217.74364
40.888428	0.033716299	0.00053363072	229.52477
41.789307	0.038542096	0.00064607797	244.90977
42.690186	0.040635005	0.00078132958	262.46216
43.591064	0.042584132	0.00077714981	276.67365
44.491943	0.04557877	0.00097138027	300.17538
45.392822	0.047987416	0.0010247206	320.51953
46.293701	0.053310636	0.0011814806	333.79639
47.19458	0.056755416	0.0012250199	356.38287
48.095459	0.05906925	0.0012862117	379.57385
48.996338	0.059978098	0.0013928604	397.19717
49.897217	0.060629241	0.0015364307	414.87854
50.798096	0.065521829	0.0015331729	431.34232
51.698975	0.068154424	0.0016430662	457.86853
52.599854	0.069865011	0.001773134	476.78931
53.500732	0.069990605	0.0018567039	493.94659
54.401611	0.07422176	0.0020044651	524.62421
55.30249	0.07533145	0.0020325598	534.57172
56.203369	0.080310248	0.0022145901	558.56195
57.104248	0.08400356	0.0023020457	578.87982
58.005127	0.085876264	0.0024091534	605.24817
58.906006	0.089360997	0.0024039205	623.37073
59.806885	0.094078973	0.0027020369	653.35846
60.707764	0.094281197	0.0026321169	670.31927
61.608643	0.094276279	0.0028387106	695.68195
62.509521	0.098344341	0.0030179664	721.77502
63.4104	0.10219419	0.0030262114	740.7016
64.311279	0.10645223	0.0031414255	761.5498
65.212158	0.10788376	0.0032586867	789.63373
66.113037	0.11102243	0.0033414494	818.20001
67.013916	0.11459178	0.0033814728	844.94592
67.914795	0.11651181	0.0036700587	867.68542
68.815674	0.11881356	0.0036565973	894.2674
69.716553	0.12129146	0.0038102143	915.90582
70.617432	0.12377674	0.0039807637	949.50275
71.518311	0.1298095	0.004111195	962.60748
72.419189	0.12972979	0.004162217	986.7113
73.320068	0.13046494	0.0042287647	1009.4975
74.220947	0.13480449	0.0044678291	1046.1433
75.121826	0.13591376	0.0045041554	1072.8937
76.022705	0.13759607	0.0046600141	1095.3018
76.923584	0.14357023	0.0048689637	1128.21
77.824463	0.14681566	0.0049245991	1160.5455
78.725342	0.14678943	0.0050189798	1182.1477
79.626221	0.15094517	0.0051411134	1209.4254
80.5271	0.1530742	0.0052210116	1229.3772
81.427979	0.15786286	0.0054440857	1260.0284
82.328857	0.15883322	0.0055310493	1282.5016
83.229736	0.16206247	0.0056197583	1297.5283
84.130615	0.16690086	0.0057232548	1327.9802
85.031494	0.16421336	0.0058026374	1346.7408
85.932373	0.16817364	0.0059471657	1371.6925
86.833252	0.17330924	0.0060805609	1400.1697
87.734131	0.17948946	0.0061950726	1430.6035
88.63501	0.17537408	0.0063392571	1447.1256
89.535889	0.18086566	0.0064170575	1471.2111
90.436768	0.1829996	0.006475897	1499.2704
91.337646	0.18817121	0.0066079851	1532.5214
92.238525	0.18824476	0.0066728117	1538.6837
93.139404	0.19160205	0.0068710498	1570.6572
94.040283	0.19347619	0.0069590453	1590.1207
94.941162	0.19741783	0.0070330468	1614.3289
95.842041	0.1993145	0.0071647866	1644.3342
96.74292	0.20264454	0.0072528138	1669.6937
97.643799	0.20391585	0.0073935157	1684.5917
98.544678	0.20697732	0.0074883178	1714.594
99.445557	0.21051635	0.0076151718	1740.0078
100.34644	0.21292423	0.0077097043	1765.6272
101.24731	0.21533145	0.0077473908	1791.5237
102.14819	0.22054648	0.0079471162	1811.5739
103.04907	0.2204383	0.0080263391	1824.5779
103.94995	0.22321267	0.0080564283	1846.9978
104.85083	0.22498253	0.0082693733	1870.8383
105.75171	0.23184484	0.00827034	1892.1791
106.65259	0.23298936	0.0083852997	1905.6393
107.55347	0.23534268	0.0084302761	1923.2008
108.45435	0.23500954	0.0085652042	1942.0826
109.35522	0.24089846	0.0086306371	1964.0177
110.2561	0.24200487	0.008709671	1975.2334
111.15698	0.24653578	0.0087215006	1994.7059
112.05786	0.24710456	0.0088376775	2009.0527
112.95874	0.25232655	0.0089794472	2035.2778
113.85962	0.25761449	0.0091040861	2051.6428
114.7605	0.25930136	0.0091351504	2057.6917
115.66138	0.26068008	0.0091812918	2069.418
116.56226	0.25980294	0.009349267	2088.5029
117.46313	0.26281661	0.0094719501	2100.356
118.36401	0.26891124	0.0093994401	2112.2988
119.26489	0.27060899	0.0096157705	2124.0305
120.16577	0.27427483	0.0096128155	2133.9539
121.06665	0.27558467	0.009740022	2143.4587
121.96753	0.27801815	0.0097923633	2155.9587
122.86841	0.28070119	0.0098612644	2164.9573
123.76929	0.28328893	0.0099505009	2171.8008
124.67017	0.28964803	0.0099863159	2188.1125
125.57104	0.28672305	0.01001618	2192.592
126.47192	0.29193276	0.010079302	2206.7244
127.3728	0.29420254	0.010218171	2220.1511
128.27368	0.29420006	0.010319243	2227.3135
129.17456	0.30115727	0.010330495	2237.9231
130.07544	0.30131066	0.010359242	2249.5139
130.97632	0.30642965	0.010524862	2262.0757
131.8772	0.30844185	0.01051013	2264.3652
132.77808	0.30886862	0.010564388	2268.6206
133.67896	0.31317416	0.01062878	2283.896
134.57983	0.31448853	0.010789061	2286.3035
135.48071	0.31752434	0.010800485	2301.5122
136.38159	0.3235229	0.010995634	2319.6223
137.28247	0.32405868	0.01096247	2320.7754
138.18335	0.32606411	0.01102206	2330.8467
139.08423	0.33219194	0.011140625	2339.6804
139.98511	0.33100867	0.011101597	2345.9995
140.88599	0.33540866	0.011226871	2356.6282
141.78687	0.33774382	0.011276105	2363.3997
142.68774	0.34236237	0.011415492	2371.2063
143.58862	0.3459506	0.011452585	2378.2507
144.4895	0.34731108	0.011571436	2387.3694
145.39038	0.34912536	0.011711178	2395.9399
146.29126	0.35301003	0.01179004	2401.2922
147.19214	0.35710514	0.011848859	2412.0181
148.09302	0.35858056	0.012029305	2421.3477
148.9939	0.35957304	0.011952726	2425.3303
149.89478	0.36273837	0.012142268	2439.0869
150.79565	0.36685333	0.012251347	2449.7964
151.69653	0.37123343	0.012294283	2446.0232
152.59741	0.36738831	0.012273238	2450.8201
153.49829	0.37499997	0.012510798	2468.1946
154.39917	0.37549534	0.012551472	2464.1909
155.30005	0.37901634	0.012720918	2480.1707
156.20093	0.38043457	0.012803744	2481.6665
157.10181	0.38544986	0.012898327	2491.563
158.00269	0.38646036	0.012958118	2495.2563
158.90356	0.38757068	0.013137974	2501.6755
159.80444	0.39274696	0.013265734	2514.8826
160.70532	0.39533344	0.013412218	2515.6057
161.6062	0.40141889	0.013462951	2529.5298
162.50708	0.40103042	0.013635775	2536.9761
163.40796	0.40579936	0.013802579	2548.376
164.30884	0.40516755	0.013976295	2553.6941
165.20972	0.40860555	0.014118493	2557.208
166.1106	0.40941709	0.014365867	2562.8472
167.01147	0.41270435	0.01444849	2565.8003
167.91235	0.41820684	0.014641733	2576.9226
168.81323	0.42043212	0.014788544	2584.55
169.71411	0.42317045	0.014990237	2587.4385
170.61499	0.42453071	0.015211656	2597.5354
171.51587	0.42881945	0.015471233	2605.6404
172.41675	0.43156663	0.015586532	2606.6931
173.31763	0.43507758	0.015996162	2622.0842
174.21851	0.43602145	0.016138306	2620.4143
175.11938	0.43700904	0.016286587	2618.479
176.02026	0.44031331	0.016521992	2630.502
176.92114	0.44139001	0.016756753	2633.1611
177.82202	0.44421253	0.017091276	2641.835
178.7229	0.45020404	0.017438963	2651.7263
179.62378	0.45177558	0.017713215	2658.3726
180.52466	0.45403039	0.018037261	2657.1719
181.42554	0.45772105	0.018338697	2662.3586
182.32642	0.45924681	0.018721296	2664.2566
183.22729	0.46267194	0.01898347	2672.8203
184.12817	0.46612763	0.019332932	2683.2219
185.02905	0.46997234	0.019751705	2687.0024
185.92993	0.47323334	0.020164436	2686.1169
186.83081	0.47746059	0.02046082	2692.7834
187.73169	0.47727826	0.020838611	2695.6638
188.63257	0.48027274	0.021152249	2698.1045
189.53345	0.48134062	0.02162203	2707.4517
190.43433	0.48654515	0.022170944	2713.283
191.33521	0.48615545	0.022572184	2712.3914
192.23608	0.49165201	0.023068938	2723.7554
193.13696	0.49317333	0.023482431	2720.8694
194.03784	0.49524763	0.024004573	2728.9795
194.93872	0.4980759	0.024575049	2733.2012
195.8396	0.50153726	0.025034808	2737.8518
196.74048	0.50327122	0.025535095	2736.6238
197.64136	0.50616306	0.026181225	2744.748
198.54224	0.50929338	0.026758658	2752.8691
199.44312	0.51267236	0.027435303	2755.1677
200.34399	0.51743275	0.028076658	2759.9473
201.24487	0.51592213	0.028682677	2759.9771
202.14575	0.51980907	0.029184047	2764.7363
203.04663	0.52280039	0.029875971	2768.5928
203.94751	0.52516651	0.030498469	2774.2312
204.84839	0.52918375	0.03119183	2787.5522
205.74927	0.53010285	0.031807143	2780.2498
206.65015	0.53596658	0.032437358	2783.1848
207.55103	0.53637856	0.032893695	2783.2495
208.4519	0.53909731	0.03346632	2790.502
209.35278	0.54014671	0.034104414	2790.8728
210.25366	0.54527956	0.034840126	2801.2378
211.15454	0.54702193	0.035528909	2800.9395
212.05542	0.55171061	0.035958931	2800.9402
212.9563	0.55312884	0.036687195	2808.1677
213.85718	0.55572724	0.037526608	2809.1333
214.75806	0.55769807	0.038388986	2821.6345
215.65894	0.56273282	0.039230369	2823.312
216.55981	0.56565493	0.040067229	2823.9163
217.46069	0.56625116	0.041006755	2825.0242
218.36157	0.5683015	0.0417169	2831.4138
219.26245	0.57207388	0.042516783	2830.6484
220.16333	0.57319748	0.043323662	2831.2336
221.06421	0.57764626	0.04394396	2833.5054
221.96509	0.58398938	0.044797841	2844.9612
222.86597	0.5844174	0.045786709	2844.7937
223.76685	0.58373487	0.046543136	2846.4456
224.66772	0.58598912	0.047455642	2844.4524
225.5686	0.5927642	0.047879882	2842.9685
226.46948	0.59189975	0.048670527	2851.2385
227.37036	0.5945428	0.049482983	2857.1592
228.27124	0.6014744	0.050298568	2862.0859
229.17212	0.60178173	0.051030982	2854.9363
230.073	0.60226345	0.051735718	2854.1826
230.97388	0.6069172	0.052590117	2863.0435
231.87476	0.61052036	0.053488784	2871.1379
232.77563	0.61397976	0.054439422	2871.406
233.67651	0.61562341	0.055142496	2867.4067
234.57739	0.61789352	0.056178387	2881.6216
235.47827	0.62211198	0.057115633	2882.988
236.37915	0.62108976	0.058026765	2877.9858
237.28003	0.62700433	0.058872297	2878.7842
238.18091	0.63170201	0.05973867	2887.821
239.08179	0.6297605	0.060620707	2889.1313
239.98267	0.63558114	0.061603136	2887.8401
240.88354	0.63670993	0.062474865	2896.5876
241.78442	0.6416387	0.063480154	2896.4604
242.6853	0.64141947	0.064273246	2896.3237
243.58618	0.64381647	0.065333918	2901.1804
244.48706	0.64843607	0.066270202	2901.8232
245.38794	0.64776564	0.067137904	2900.9004
246.28882	0.65243775	0.068174273	2902.4392
247.1897	0.65326488	0.069093488	2905.7158
248.09058	0.65746266	0.070034295	2905.885
248.99146	0.66078144	0.070928544	2912.7107
249.89233	0.66505951	0.071947783	2914.4951
250.79321	0.66734874	0.072951004	2918.3049
251.69409	0.66919011	0.073934071	2909.5955
252.59497	0.6729297	0.074899763	2919.6602
253.49585	0.67236096	0.075687498	2919.5967
254.39673	0.67511666	0.076501042	2916.5859
255.29761	0.68092632	0.077516124	2928.667
256.19849	0.68425	0.078637138	2934.9741
257.09937	0.68394017	0.079782262	2933.7957
258.00024	0.6869787	0.080807269	2927.9226
258.90112	0.68995166	0.081909142	2931.6836
259.802	0.69449466	0.082893364	2934.2993
260.70288	0.69506299	0.083853468	2938.4648
261.60376	0.69921958	0.084677681	2930.4319
262.50464	0.69995409	0.085504964	2935.8853
263.40552	0.70728564	0.086429521	2944.0247
264.3064	0.70604748	0.087321714	2937.5332
265.20728	0.7101537	0.088280387	2949.1755
266.10815	0.71321124	0.089286506	2942.5352
267.00903	0.71375334	0.090168707	2950.3679
267.90991	0.71623147	0.091405228	2952.7236
268.81079	0.72095621	0.092420876	2952.1506
269.71167	0.72134304	0.093483731	2953.7263
270.61255	0.72363251	0.094511896	2958.7722
271.51343	0.72827828	0.095653743	2961.8518
272.41431	0.73135859	0.096640043	2960.6072
273.31519	0.73553914	0.097667769	2960.6199
274.21606	0.73392791	0.098745562	2966.0913
275.11694	0.74047494	0.099714197	2958.0376
276.01782	0.74113977	0.10048909	2966.4358
276.9187	0.74265718	0.10152329	2968.4348
277.81958	0.74635684	0.10267572	2972.5588
278.72046	0.75039977	0.10369952	2971.7954
279.62134	0.75052267	0.10476294	2978.782
280.52222	0.75631958	0.10598378	2979.1526
281.4231	0.75754499	0.10689229	2971.8926
282.32397	0.75839877	0.10788815	2977.5645
283.22485	0.76385313	0.1090996	2984.0547
284.12573	0.76689965	0.11003727	2978.1194
285.02661	0.7691173	0.11099527	2985.1089
285.92749	0.77251661	0.11198455	2982.2896
286.82837	0.77370965	0.11306687	2986.9497
287.72925	0.77873826	0.1141073	2990.4299
288.63013	0.77939802	0.11520054	2991.7957
289.53101	0.78154421	0.11628295	2991.553
290.43188	0.78389084	0.11719444	2988.5132
291.33276	0.78657174	0.11844193	2995.0872
292.23364	0.79174316	0.1196366	3001.8701
293.13452	0.79375619	0.12092452	3000.208
294.0354	0.79600197	0.12191087	2999.1982
294.93628	0.79981738	0.122888	3008.7637
295.83716	0.80477846	0.12389819	3006.3303
296.73804	0.80626303	0.12488557	3002.6438
297.63892	0.80727905	0.1257048	3006.5652
298.53979	0.8098709	0.12667355	3003.5139
299.44067	0.81245899	0.12762196	3005.5254
300.34155	0.81577152	0.12857753	3011.0027
301.24243	0.81535906	0.12941925	3009.3447
302.14331	0.82164705	0.13050656	3015.1531
303.04419	0.82279098	0.13150617	3015.4714
303.94507	0.82643652	0.13274249	3026.8877
304.84595	0.82783943	0.13399591	3018.02
305.74683	0.83102012	0.13506256	3018.4863
306.64771	0.8328768	0.13614286	3016.8147
307.54858	0.83444464	0.13723502	3021.1357
308.44946	0.84083754	0.13822821	3024.4009
309.35034	0.8393054	0.13929589	3025.9006
310.25122	0.8452664	0.14053681	3026.313
311.1521	0.84765363	0.14162296	3022.5674
312.05298	0.84998357	0.14270967	3033.4226
312.95386	0.85384774	0.14378363	3033.615
313.85474	0.85634148	0.14478317	3026.8562
314.75562	0.8568238	0.14576039	3032.4978
315.65649	0.86007291	0.14680453	3031.3872
316.55737	0.86186177	0.14769144	3033.4624
317.45825	0.86918062	0.14874683	3041.4209
318.35913	0.87206113	0.14999215	3044.2891
319.26001	0.87347716	0.15124367	3048.1257
320.16089	0.87575775	0.15242991	3042.3955
321.06177	0.8786096	0.15337022	3041.2588
321.96265	0.88047713	0.15441899	3046.4512
322.86353	0.88200539	0.15517455	3037.9548
323.7644	0.88579321	0.15643889	3055.0684
324.66528	0.88642812	0.15761974	3048.6135
325.56616	0.89014173	0.15872633	3052.6626
326.46704	0.89408666	0.15974467	3051.7542
327.36792	0.896707	0.16076937	3058.1016
328.2688	0.89790356	0.1618776	3059.8325
329.16968	0.89746058	0.16292627	3047.075
330.07056	0.90428132	0.163941	3063.4285
330.97144	0.90367544	0.16514933	3059.1318
331.87231	0.90995878	0.1661521	3063.2051
332.77319	0.91201448	0.16729534	3060.3362
333.67407	0.91491872	0.16818014	3064.8062
334.57495	0.91704547	0.16926296	3062.9001
335.47583	0.92062956	0.17018348	3058.866
336.37671	0.92301983	0.17117563	3065.8098
337.27759	0.92902243	0.17225063	3072.7275
338.17847	0.9285807	0.17330155	3068.0859
339.07935	0.93016487	0.17435716	3068.3086
339.98022	0.93236864	0.17536452	3071.6045
340.8811	0.9390139	0.17643641	3075.0427
341.78198	0.93790007	0.17742814	3069.8564
342.68286	0.94066727	0.17860745	3075.5056
343.58374	0.94210052	0.17962439	3080.0366
344.48462	0.94717801	0.18078354	3079.6416
345.3855	0.95104325	0.18174246	3078.5024
346.28638	0.94968772	0.18286614	3079.4019
347.18726	0.95580262	0.18402286	3088.9817
348.08813	0.956608	0.18520862	3084.0605
348.98901	0.96076947	0.18628956	3090.5872
349.88989	0.96284175	0.18745619	3089.0928
350.79077	0.96466225	0.18851763	3083.2109
351.69165	0.96780419	0.18952055	3088.4561
352.59253	0.97057694	0.19059691	3096.9619
353.49341	0.977193	0.19165637	3092.6113
354.39429	0.97461915	0.19284403	3090.8491
355.29517	0.97962826	0.19399306	3097.0706
356.19604	0.98252398	0.19488466	3089.4231
357.09692	0.98321956	0.19587401	3095.7734
357.9978	0.99099737	0.19680488	3103.0151
358.89868	0.99009585	0.19783197	3100.3452
359.79956	0.99471426	0.19911323	3107.1677
360.70044	0.99845225	0.2002769	3110.2419
361.60132	0.99956822	0.20139667	3098.1768
362.5022	1.0035384	0.20222768	3102.916
363.40308	1.0044614	0.20329903	3107.6592
364.30396	1.0082526	0.20434305	3107.6836
365.20483	1.0118208	0.20539232	3113.0957
366.10571	1.0105659	0.20631357	3107.9622
367.00659	1.0179583	0.20752622	3113.5808
367.90747	1.0178382	0.20869523	3114.8525
368.80835	1.0189829	0.2098655	3116.2292
369.70923	1.0215933	0.21083127	3106.1423
370.61011	1.0268043	0.21179596	3116.6565
371.51099	1.0263947	0.21284725	3115.4868
372.41187	1.0344862	0.21393827	3122.8945
373.31274	1.0362675	0.21478084	3121.0212
374.21362	1.0367463	0.21585886	3125.4456
375.1145	1.0405617	0.21700177	3126.1477
376.01538	1.0454799	0.21821073	3125.0161
376.91626	1.0430342	0.21912591	3122.1936
377.81714	1.0468642	0.22011858	3129.3257
378.71802	1.0511932	0.22116476	3130.385
379.6189	1.051778	0.22229522	3125.1934
380.51978	1.0572282	0.22306708	3127.5076
381.42065	1.0591085	0.22401953	3132.5984
382.32153	1.0606992	0.22526336	3137.1819
383.22241	1.0650423	0.22624813	3132.3086
384.12329	1.065804	0.22720386	3131.3706
385.02417	1.0715803	0.22833872	3138.2349
385.92505	1.0710697	0.229507	3148.7688
386.82593	1.07467	0.23089112	3140.5796
387.72681	1.0745268	0.23197326	3136.3005
388.62769	1.0820841	0.23330075	3145.5398
389.52856	1.0838912	0.23440318	3142.5791
390.42944	1.0854533	0.23542461	3143.4495
391.33032	1.086431	0.23641872	3141.9333
392.2312	1.0910561	0.23755407	3150.9841
393.13208	1.0915766	0.23862308	3143.5728
394.03296	1.0961908	0.23950019	3146.2441
394.93384	1.0991421	0.24037173	3154.2019
395.83472	1.1040709	0.2413305	3150.6387
396.7356	1.103025	0.24234626	3146.7634
397.63647	1.1074429	0.24332421	3156.3193
398.53735	1.1097512	0.24428645	3151.1326
399.43823	1.11343	0.2454446	3158.6155
400.33911	1.1162238	0.24651138	3158.0913
401.23999	1.1177729	0.24762556	3157.8845
402.14087	1.1224096	0.24864949	3157.1406
403.04175	1.1244432	0.24974784	3160.9924
403.94263	1.1261393	0.25067386	3166.5667
404.84351	1.1269875	0.25178787	3161.6758
405.74438	1.1301332	0.25289607	3167.3872
406.64526	1.1375052	0.25390771	3161.25
407.54614	1.1381246	0.25505412	3170.6174
408.44702	1.1385792	0.25607762	3163.3159
409.3479	1.1440082	0.25709024	3165.4126
410.24878	1.1494361	0.2580466	3173.6509
411.14966	1.1482705	0.25892749	3167.7891
412.05054	1.1501093	0.25985825	3169.3574
412.95142	1.1516292	0.26080784	3170.3179
413.85229	1.1575533	0.26202926	3175.1611
414.75317	1.1570523	0.26319486	3170.1812
415.65405	1.1612042	0.26433641	3176.1028
416.55493	1.1618978	0.26540232	3177.1038
417.45581	1.1641862	0.26644817	3175.2651
418.35669	1.1696273	0.26750082	3178.7947
419.25757	1.1716067	0.26862156	3184.9355
420.15845	1.1751857	0.2696752	3185.8569
421.05933	1.1785583	0.27069247	3185.5918
421.96021	1.1774749	0.27164811	3182.2983
422.86108	1.1856641	0.27264389	3190.5569
423.76196	1.1849474	0.27369508	3190.4878
424.66284	1.1885111	0.27486601	3191.4636
425.56372	1.1923615	0.27583784	3189.3352
426.4646	1.1939712	0.27680764	3186.6082
427.36548	1.1965783	0.27785286	3193.5308
428.26636	1.200505	0.27881157	3186.7837
429.16724	1.200856	0.27983209	3193.7175
430.06812	1.2022492	0.28084382	3193.2388
430.96899	1.2105104	0.28197578	3193.1677
431.86987	1.2131149	0.2831586	3197.5977
432.77075	1.2125821	0.28406566	3197.3203
433.67163	1.2161463	0.2852169	3201.5747
434.57251	1.2171413	0.28621566	3197.4517
435.47339	1.2192935	0.28742218	3205.1221
436.37427	1.2211921	0.28848162	3196.9958
437.27515	1.2248507	0.28962225	3201.6265
438.17603	1.2310954	0.29068711	3203.7637
439.0769	1.2314751	0.2915526	3201.3418
439.97778	1.2358993	0.29257458	3201.0452
440.87866	1.2353535	0.29324219	3200.0686
441.77954	1.2391598	0.29413611	3204.3201
442.68042	1.240172	0.29504421	3208.3438
443.5813	1.2465165	0.29617068	3213.72
444.48218	1.2494361	0.29743642	3216.8811
445.38306	1.2487427	0.29833323	3209.8809
446.28394	1.2524129	0.29945925	3214.8042
447.18481	1.2559923	0.30055425	3211.4661
448.08569	1.2560253	0.30148521	3211.8892
448.98657	1.2630411	0.30265951	3222.4231
449.88745	1.2650162	0.30362421	3218.5105
450.78833	1.2659886	0.30473754	3220.1233
451.68921	1.2683088	0.30548471	3212.1462
452.59009	1.2737855	0.30643195	3217.7734
453.49097	1.2747315	0.30738819	3226.5056
454.39185	1.2777499	0.30850849	3224.2607
455.29272	1.2801933	0.30947667	3219.9468
456.1936	1.2830868	0.31062201	3235.002
457.09448	1.2838833	0.31200323	3232.7246
457.99536	1.2886382	0.31311208	3224.6296
458.89624	1.2895907	0.31418326	3227.3262
459.79712	1.2956202	0.31523359	3230.7698
460.698	1.2947701	0.31628031	3226.3606
461.59888	1.2990394	0.31737611	3233.0972
462.49976	1.3035529	0.31853408	3232.5671
463.40063	1.3028518	0.31946042	3224.687
464.30151	1.3090078	0.32057348	3234.5735
465.20239	1.3126551	0.32162899	3237.9539
466.10327	1.3136902	0.32246658	3228.4172
467.00415	1.3153102	0.32327828	3231.4827
467.90503	1.3169234	0.32413158	3238.6738
468.80591	1.3210213	0.32515639	3237.6184
469.70679	1.3229462	0.32626587	3241.8638
470.60767	1.3230265	0.32739204	3242.8875
471.50854	1.3309498	0.3288033	3250.376
472.40942	1.334904	0.32968143	3241.7908
473.3103	1.3331879	0.33068085	3240.988
474.21118	1.3392028	0.33169445	3247.2717
475.11206	1.3406541	0.33271483	3245.147
476.01294	1.3446865	0.33386359	3249.3518
476.91382	1.3470249	0.33503577	3253.646
477.8147	1.3480468	0.33591458	3246.7849
478.71558	1.3499626	0.3369309	3255.0164
479.61646	1.3541002	0.33796415	3250.3079
480.51733	1.3561251	0.33876193	3248.3457
481.41821	1.3585436	0.33986977	3256.9756
482.31909	1.3592402	0.34086272	3252.2246
483.21997	1.3631916	0.34174284	3253.3359
484.12085	1.3671255	0.34297958	3261.1553
485.02173	1.3693537	0.34424707	3262.3357
485.92261	1.3717513	0.34528694	3253.6826
486.82349	1.3757964	0.34637636	3266.3074
487.72437	1.3805927	0.3475917	3265.3303
488.62524	1.3823423	0.34858307	3259.458
489.52612	1.3822855	0.34953448	3260.4182
490.427	1.3859105	0.35072681	3263.615
491.32788	1.3889896	0.3516584	3261.0586
492.22876	1.3906831	0.35252514	3263.6104
493.12964	1.3947519	0.35376731	3265.425
494.03052	1.3963193	0.35496214	3270.6118
494.9314	1.3994608	0.3559739	3263.3096
495.83228	1.4003299	0.3570309	3265.968
496.73315	1.404344	0.35813105	3271.8992
497.63403	1.4076989	0.35924783	3268.7488
498.53491	1.4116406	0.36031353	3274.0732
499.43579	1.4138551	0.36125869	3270.8264
500.33667	1.4166168	0.36214772	3268.6311
501.23755	1.4169643	0.36320069	3267.9241
502.13843	1.4216774	0.36434147	3277.9456
503.03931	1.4252026	0.36516535	3271.5342
503.94019	1.4246341	0.36608002	3274.5056
504.84106	1.4274235	0.36707124	3277.8604
505.74194	1.4309864	0.36819077	3278.5959
506.64282	1.4360695	0.36924565	3283.1704
507.5437	1.4390091	0.37052161	3289.2217
508.44458	1.4384739	0.37153885	3279.4951
509.34546	1.4458476	0.37254852	3289.3276
510.24634	1.4444842	0.37334731	3274.9321
511.14722	1.4490862	0.37435359	3283.6948
512.0481	1.4490651	0.37530801	3283.6982
512.94897	1.4508182	0.37634379	3287.6851
513.84985	1.4568489	0.37737781	3289.3157
514.75073	1.4569477	0.37849328	3284.3975
515.65161	1.4608523	0.37944096	3291.6865
516.55249	1.4641315	0.38044026	3289.5847
517.45337	1.4673386	0.38140678	3288.9497
518.35425	1.4654986	0.38236743	3290.677
519.25513	1.4721758	0.38352603	3294.198
520.15601	1.4739738	0.38472295	3296.1836
521.05688	1.4771805	0.38580626	3294.9097
521.95776	1.4802423	0.3867152	3292.8928
522.85864	1.4798013	0.38775924	3299.5002
523.75952	1.4869003	0.38879439	3299.8635
524.6604	1.487808	0.39002532	3303.7212
525.56128	1.4908676	0.39119154	3294.7271
526.46216	1.4947928	0.39218497	3299.116
527.36304	1.4967264	0.39298338	3296.8613
528.26392	1.4979104	0.39412856	3301.0852
529.16479	1.4986538	0.39536184	3303.4229
530.06567	1.5058403	0.39671215	3308.7664
530.96655	1.5057528	0.39786509	3302.9739
531.86743	1.5109885	0.39908147	3311.2446
532.76831	1.5122796	0.39994091	3305.6987
533.66919	1.5160978	0.40082258	3299.2544
534.57007	1.5179143	0.40159816	3304.104
535.47095	1.5230429	0.40251002	3312.636
536.37183	1.5252471	0.4036026	3310.4814
537.27271	1.5256052	0.40479881	3315.1792
538.17358	1.5265855	0.40595201	3313.4875
539.07446	1.5294064	0.40715566	3309.1062
539.97534	1.5332525	0.40823695	3314.3059
540.87622	1.5374738	0.40923461	3318.5781
541.7771	1.5407643	0.41052875	3324.302
542.67798	1.5419946	0.4118011	3318.2449
543.57886	1.5437989	0.41286734	3310.3091
544.47974	1.5481457	0.41392359	3317.0928
545.38062	1.5510757	0.41493371	3317.5325
546.28149	1.5545589	0.4159373	3328.6775
547.18237	1.5591105	0.41713604	3326.6167
548.08325	1.5548048	0.41794685	3314.2122
548.98413	1.5604056	0.41887692	3319.9473
549.88501	1.5647547	0.42008173	3328.7998
550.78589	1.5640315	0.42098111	3315.2847
551.68677	1.5677117	0.42206827	3323.5449
552.58765	1.5715419	0.4231815	3327.1597
553.48853	1.5755968	0.42413107	3324.8284
554.3894	1.5780895	0.42532653	3330.4893
555.29028	1.5781958	0.42641243	3325.2554
556.19116	1.5851375	0.42733896	3328.9053
557.09204	1.5844749	0.42834279	3328.0056
557.99292	1.5893506	0.42929491	3331.7148
558.8938	1.5900024	0.43025047	3330.6021
559.79468	1.5954131	0.43135214	3338.9119
560.69556	1.5950525	0.43249828	3334.0276
561.59644	1.5979055	0.43358043	3332.8882
562.49731	1.6020596	0.43476707	3336.4607
563.39819	1.6045945	0.43598554	3343.6663
564.29907	1.6043439	0.43698204	3330.6912
565.19995	1.6104933	0.43812636	3339.9961
566.10083	1.6100329	0.43921417	3336.866
567.00171	1.6162022	0.44043246	3345.1792
567.90259	1.6166873	0.44146523	3339.4514
568.80347	1.6198653	0.44248906	3335.7732
569.70435	1.6252364	0.44360128	3341.761
570.60522	1.6236835	0.44480237	3342.3535
571.5061	1.6271124	0.44579744	3340.9729
572.40698	1.6315148	0.44701624	3345.9856
573.30786	1.6315652	0.44809034	3342.6653
574.20874	1.6357114	0.44923779	3356.373
575.10962	1.6379002	0.45027703	3346.9634
576.0105	1.640605	0.45129746	3347.3738
576.91138	1.6463866	0.45246872	3346.7214
577.81226	1.646969	0.45363221	3350.5808
578.71313	1.6512268	0.45450455	3342.9685
579.61401	1.6510069	0.45562261	3348.667
580.51489	1.6577122	0.45661432	3355.2053
581.41577	1.6598248	0.45779675	3356.3582
582.31665	1.663105	0.45905885	3355.7554
583.21753	1.6636438	0.46006274	3344.4888
584.11841	1.6642079	0.46112177	3349.6892
585.01929	1.6689005	0.46215752	3353.3953
585.92017	1.6743331	0.46326721	3354.5408
586.82104	1.6721674	0.4641867	3351.4846
587.72192	1.6783319	0.46529636	3358.4207
588.6228	1.6784065	0.46632779	3355.6807
589.52368	1.6818625	0.46742398	3358.686
590.42456	1.6866935	0.46834606	3358.4475
591.32544	1.6902454	0.46957806	3363.7944
592.22632	1.6898397	0.47061282	3360.9265
593.1272	1.6910987	0.47175497	3361.2793
594.02808	1.6967664	0.47284535	3363.6062
594.92896	1.7001822	0.47408497	3360.8315
595.82983	1.7016032	0.47501302	3361.4331
596.73071	1.7049785	0.47612792	3364.5923
597.63159	1.7058319	0.47714514	3372.166
598.53247	1.7100265	0.4783459	3376.011
599.43335	1.7124696	0.4796603	3369.2449
600.33423	1.7172242	0.48077479	3366.4714
601.23511	1.7197146	0.48207453	3372.6833
602.13599	1.7217996	0.48313779	3369.2742
603.03687	1.7228119	0.48455068	3365.1997
603.93774	1.7285196	0.48570454	3368.437
604.83862	1.7294605	0.48648772	3365.562
605.7395	1.7338455	0.48763812	3374.4907
606.64038	1.7348208	0.48860395	3370.9082
607.54126	1.7370106	0.48975286	3373.6567
608.44214	1.7416168	0.49089256	3372.1851
609.34302	1.7418863	0.49203271	3373.1155
610.2439	1.7479813	0.49316353	3376.0723
611.14478	1.7486455	0.49411717	3373.7725
612.04565	1.7502148	0.49519953	3374.5061
612.94653	1.7524272	0.49625909	3374.9197
613.84741	1.7537575	0.49722117	3374.2363
614.74829	1.7594887	0.4983795	3382.8252
615.64917	1.7586954	0.49955788	3378.001
616.55005	1.7629169	0.50080311	3385.1926
617.45093	1.7686064	0.50221193	3387.6702
618.35181	1.7683154	0.5033983	3385.9597
619.25269	1.7729802	0.50453365	3381.9846
620.15356	1.7755166	0.50569052	3388.0129
621.05444	1.7781793	0.50673503	3378.4954
621.95532	1.7781469	0.50781059	3386.1282
622.8562	1.7826002	0.50898796	3385.7803
623.75708	1.7861017	0.51020026	3391.0464
624.65796	1.7903814	0.51131392	3386.4739
625.55884	1.7930279	0.51247394	3394.1648
626.45972	1.7951789	0.51371616	3393.9138
627.3606	1.7955279	0.51497573	3385.5923
628.26147	1.7967446	0.51588452	3383.3062
629.16235	1.803273	0.51705498	3394.1323
630.06323	1.8050275	0.51825851	3396.2666
630.96411	1.8089006	0.5193786	3393.8701
631.86499	1.8105004	0.52043569	3393.6758
632.76587	1.8114163	0.5214889	3390.9241
633.66675	1.8130158	0.52253354	3396.0781
634.56763	1.8169723	0.52371842	3396.6667
635.46851	1.8218789	0.52491397	3396.647
636.36938	1.8214465	0.52613038	3399.073
637.27026	1.8270353	0.52743143	3406.1333
638.17114	1.8266163	0.52866733	3392.4478
639.07202	1.8296995	0.52986944	3394.5254
639.9729	1.8339311	0.53092802	3391.1448
640.87378	1.8370007	0.53223652	3401.4888
641.77466	1.8422723	0.53357226	3404.0684
642.67554	1.8426261	0.53456217	3396.1541
643.57642	1.8442196	0.53560561	3397.9299
644.47729	1.8465848	0.53684533	3401.7534
645.37817	1.8524764	0.53816861	3402.874
646.27905	1.8533037	0.53928679	3401.1882
647.17993	1.8532301	0.54023695	3399.2383
648.08081	1.8581803	0.54137349	3409.7275
648.98169	1.8636776	0.54258859	3404.563
649.88257	1.864445	0.54357272	3399.4167
650.78345	1.8673995	0.54472208	3410.656
651.68433	1.8707774	0.54593694	3412.9802
652.58521	1.8725374	0.54712003	3407.9834
653.48608	1.8749236	0.54824972	3411.8855
654.38696	1.8768067	0.54941767	3404.7053
655.28784	1.8799489	0.55034053	3410.0613
656.18872	1.8825853	0.55152863	3410.9668
657.0896	1.8846371	0.55267084	3406.1499
657.99048	1.8896774	0.55382407	3411.6357
658.89136	1.8933831	0.5547989	3415.7363
659.79224	1.8941009	0.55588877	3412.4854
660.69312	1.897745	0.55732071	3418.5969
661.59399	1.8971922	0.55867314	3416.0896
662.49487	1.9010327	0.55999959	3411.0388
663.39575	1.9036422	0.56114572	3411.7871
664.29663	1.9084593	0.56220001	3411.0325
665.19751	1.9091429	0.56328374	3417.519
666.09839	1.9145693	0.56456769	3419.4729
666.99927	1.9154253	0.56570691	3418.2952
667.90015	1.915876	0.5669148	3418.9587
668.80103	1.9188527	0.56829339	3419.1917
669.7019	1.9230322	0.56946999	3419.5667
670.60278	1.9243577	0.57061136	3419.3357
671.50366	1.929672	0.57177609	3417.1714
672.40454	1.9307293	0.57299554	3417.6919
673.30542	1.9353029	0.57405657	3419.7744
674.2063	1.9360082	0.57538438	3423.0317
675.10718	1.9405867	0.57652843	3417.4985
676.00806	1.9421376	0.5776512	3419.1006
676.90894	1.9477947	0.57889223	3425.3767
677.80981	1.9459252	0.58000839	3418.8506
678.71069	1.9519732	0.58122557	3426.9529
679.61157	1.9505591	0.58235848	3420.2903
680.51245	1.9560182	0.58371425	3425.5649
681.41333	1.9581926	0.58517236	3429.3618
682.31421	1.9646873	0.5865351	3431.0776
683.21509	1.9611093	0.58769423	3425.0991
684.11597	1.9673629	0.58887231	3422.9465
685.01685	1.9696362	0.59002447	3426.0364
685.91772	1.973851	0.5911113	3424.283
686.8186	1.9754759	0.59220606	3426.408
687.71948	1.9764636	0.59351206	3430.4297
688.62036	1.9777719	0.59470111	3430.5537
689.52124	1.9817061	0.59590179	3428.2683
690.42212	1.9847707	0.59703207	3429.2195
691.323	1.9867125	0.59822613	3429.7661
692.22388	1.9922494	0.5994212	3435.207
693.12476	1.9946979	0.6007787	3433.1003
694.02563	1.9972271	0.60212034	3437.5391
694.92651	1.9976932	0.60329068	3435.968
695.82739	2.0032475	0.60465401	3442.1458
696.72827	2.0050414	0.60596293	3438.3792
697.62915	2.0098634	0.60702419	3436.376
698.53003	2.0086832	0.60816592	3435.8955
699.43091	2.0101137	0.60942435	3438.7322
700.33179	2.0158339	0.61070043	3439.0801
701.23267	2.0192637	0.61197925	3438.9404
702.13354	2.0219877	0.61306357	3440.2339
703.03442	2.0239975	0.61423695	3437.019
703.9353	2.0234268	0.61537796	3436.729
704.83618	2.0282381	0.61682516	3441.9336
705.73706	2.029474	0.6180976	3438.2708
706.63794	2.0351136	0.61950213	3441.3269
707.53882	2.0383072	0.62073117	3442.291
708.4397	2.0413198	0.62219542	3445.5488
709.34058	2.0444667	0.6234566	3444.2393
710.24146	2.0465322	0.62491953	3445.0671
711.14233	2.0467739	0.62627977	3446.3479
712.04321	2.0499165	0.62753832	3436.6777
712.94409	2.052078	0.6284852	3439.6008
713.84497	2.0537288	0.62972361	3444.4644
714.74585	2.056787	0.63091093	3444.7124
715.64673	2.0614142	0.63186544	3440.981
716.54761	2.0623937	0.63317549	3449.1824
717.44849	2.0667515	0.63441974	3441.918
718.34937	2.068049	0.63564831	3448.6956
719.25024	2.0745554	0.63688332	3449.207
720.15112	2.0761523	0.63826543	3456.3411
721.052	2.076093	0.63949585	3448.2458
721.95288	2.083904	0.64081961	3452.0251
722.85376	2.0819626	0.64218605	3449.4131
723.75464	2.0868201	0.64353472	3447.8984
724.65552	2.0874949	0.64480078	3445.0955
725.5564	2.0930033	0.64579064	3443.6233
726.45728	2.0965631	0.64711058	3455.144
727.35815	2.0962217	0.64822066	3446.0901
728.25903	2.1020906	0.64940077	3451.5916
729.15991	2.1008818	0.65051657	3450.8196
730.06079	2.1026397	0.65177506	3450.9688
730.96167	2.1074224	0.65311283	3459.1975
731.86255	2.1098452	0.65444422	3453.9663
732.76343	2.1097686	0.65584767	3452.3784
733.66431	2.1154206	0.65757275	3460.5154
734.56519	2.1200113	0.65894246	3458.6575
735.46606	2.1196342	0.66023767	3456.698
736.36694	2.1249762	0.66129577	3456.8914
737.26782	2.1260552	0.66257179	3455.9861
738.1687	2.130183	0.66379976	3455.7805
739.06958	2.128654	0.66492313	3454.0608
739.97046	2.1349518	0.66600722	3458.9329
740.87134	2.1366348	0.6670416	3452.6091
741.77222	2.1392512	0.66797912	3453.8176
742.6731	2.1408415	0.66929013	3461.3069
743.57397	2.1424725	0.67049801	3455.1047
744.47485	2.1489949	0.67205065	3465.4353
745.37573	2.1521211	0.67353845	3464.3582
746.27661	2.1538577	0.67493534	3466.0405
747.17749	2.1570106	0.67647135	3467.9197
748.07837	2.1583445	0.67780274	3453.4871
748.97925	2.1616542	0.67918867	3464.926
749.88013	2.1628056	0.68056649	3461.8447
750.78101	2.1675119	0.68208379	3465.4663
751.68188	2.1702225	0.68346286	3462.0273
752.58276	2.1734166	0.68482882	3463.1914
753.48364	2.1729939	0.68629086	3470.5234
754.38452	2.1751809	0.68789923	3465.0222
755.2854	2.17888	0.68942815	3465.5562
756.18628	2.1824651	0.69066435	3459.9407
757.08716	2.1851974	0.69205016	3468.1311
757.98804	2.1872065	0.69328338	3465.0525
758.88892	2.19084	0.69448882	3468.8474
759.78979	2.1914887	0.69588971	3462.95
760.69067	2.1952899	0.69711387	3468.1956
761.59155	2.1982422	0.69842422	3467.1946
762.49243	2.2027595	0.6999523	3468.2019
763.39331	2.2020156	0.70103157	3463.6516
764.29419	2.2073143	0.70225024	3470.688
765.19507	2.2115433	0.70326805	3467.0908
766.09595	2.2135961	0.70457131	3470.1711
766.99683	2.2158885	0.70585179	3467.2102
767.89771	2.2185991	0.7072407	3472.9355
768.79858	2.2186606	0.70841235	3469.0137
769.69946	2.221797	0.70962876	3466.6904
770.60034	2.2265234	0.71089506	3477.9404
771.50122	2.2267385	0.71230882	3464.5579
772.4021	2.2309752	0.71352243	3469.1379
773.30298	2.2309537	0.71506917	3471.5923
774.20386	2.2386417	0.71634805	3472.9805
775.10474	2.2381508	0.71765846	3471.77
776.00562	2.2441332	0.71893388	3475.3042
776.90649	2.2461843	0.7205255	3475.1233
777.80737	2.2485161	0.7218796	3470.7771
778.70825	2.2516952	0.72312784	3474.4812
779.60913	2.2523317	0.72468764	3477.2334
780.51001	2.2581742	0.72662997	3484.1563
781.41089	2.2587671	0.72845739	3477.906
782.31177	2.2639308	0.72996736	3480.8853
783.21265	2.2634289	0.73131102	3472.5146
784.11353	2.2637184	0.73244464	3473.5747
785.0144	2.2697785	0.73371685	3470.8777
785.91528	2.272079	0.73485345	3468.4805
786.81616	2.2727647	0.73600006	3474.8232
787.71704	2.2762399	0.73746222	3481.7703
788.61792	2.27864	0.73880404	3473.7158
789.5188	2.2842841	0.74015987	3484.4082
790.41968	2.2826352	0.7416718	3480.2527
791.32056	2.289356	0.7431525	3477.0618
792.22144	2.2901905	0.74462718	3473.3811
793.12231	2.2901683	0.74591547	3478.8696
794.02319	2.2984006	0.74739939	3480.7817
794.92407	2.3005357	0.74887079	3478.5632
795.82495	2.3006232	0.75015098	3474.6296
796.72583	2.3069663	0.75140858	3479.905
797.62671	2.3073187	0.75254309	3477.7952
798.52759	2.309077	0.75388658	3474.9324
799.42847	2.3099954	0.75517225	3476.5288
800.32935	2.3180132	0.75642985	3485.7461
801.23022	2.3179483	0.75773156	3481.4097
802.1311	2.3184466	0.75920236	3481.6875
803.03198	2.3264349	0.76050341	3489.5203
803.93286	2.3253226	0.76232511	3488.5249
804.83374	2.3285642	0.76385379	3484.6763
805.73462	2.3296447	0.76538986	3474.3491
806.6355	2.3349817	0.7666654	3476.7251
807.53638	2.3389518	0.76785815	3479.1226
808.43726	2.3403838	0.76930356	3483.5793
809.33813	2.3432755	0.77057791	3486.1914
810.23901	2.344918	0.77247614	3485.4421
811.13989	2.3478804	0.77401221	3483.0242
812.04077	2.3515093	0.77536613	3490.1553
812.94165	2.3533623	0.77681756	3488.0002
813.84253	2.3546455	0.77833515	3482.9495
814.74341	2.3587153	0.77980065	3479.6067
815.64429	2.3632133	0.78109419	3483.7063
816.54517	2.3628817	0.7828306	3488.9768
817.44604	2.3676136	0.78438556	3486.604
818.34692	2.3700931	0.78573614	3484.042
819.2478	2.3750019	0.78698009	3485.0652
820.14868	2.375932	0.78864217	3492.2832
821.04956	2.3759375	0.79009014	3484.6243
821.95044	2.3800588	0.79157335	3488.7651
822.85132	2.382642	0.79317164	3486.8215
823.7522	2.3834543	0.79453486	3485.0684
824.65308	2.3873069	0.79589075	3481.8879
825.55396	2.3937514	0.79709566	3487.5349
826.45483	2.3924758	0.79852891	3485.9658
827.35571	2.3970585	0.79984611	3486.449
828.25659	2.3994651	0.80148309	3491.2771
829.15747	2.3994725	0.80300188	3491.259
830.05835	2.4037492	0.80485481	3492.8057
830.95923	2.4086993	0.80632442	3494.8137
831.86011	2.4097075	0.80812126	3490.5457
832.76099	2.4122336	0.80996072	3487.7856
833.66187	2.4149749	0.81131506	3483.6155
834.56274	2.4169049	0.81253451	3482.8647
835.46362	2.4199963	0.81383198	3487.7756
836.3645	2.4232416	0.81515706	3489.5891
837.26538	2.425921	0.81627053	3489.1609
838.16626	2.4292431	0.81779242	3495.8809
839.06714	2.432725	0.81927425	3498.071
839.96802	2.4338348	0.82093418	3494.7256
840.8689	2.4357951	0.82245964	3485.8193
841.76978	2.4368737	0.82406044	3487.7188
842.67065	2.4437957	0.82544339	3489.8921
843.57153	2.4453485	0.82716459	3492.8386
844.47241	2.4483631	0.82894456	3495.0454
845.37329	2.4490857	0.83062112	3487.6951
846.27417	2.4546933	0.83229554	3491.9646
847.17505	2.4562552	0.83356851	3488.9995
848.07593	2.4582558	0.83499795	3489.1855
848.97681	2.4638162	0.83644772	3498.2871
849.87769	2.4637284	0.83799183	3490.1174
850.77856	2.4684365	0.83957165	3496.5859
851.67944	2.4694214	0.84134388	3500.9348
852.58032	2.4710679	0.84304231	3490.8276
853.4812	2.4760613	0.84468508	3490.9863
854.38208	2.479382	0.84609354	3493.8931
855.28296	2.4810059	0.84787989	3492.9812
856.18384	2.48226	0.84936219	3495.7432
857.08472	2.4844398	0.85083365	3493.998
857.9856	2.4869437	0.85255766	3492.7239
858.88647	2.49262	0.85400486	3487.396
859.78735	2.4935703	0.85562617	3494.8953
860.68823	2.4959412	0.85703963	3494.8037
861.58911	2.4982259	0.85855061	3487.6724
862.48999	2.5022769	0.86014944	3496.4617
863.39087	2.5025315	0.86152512	3488.0164
864.29175	2.5088272	0.86302972	3494.428
865.19263	2.5075397	0.86441225	3486.1353
866.09351	2.5121658	0.86574966	3495.0479
866.99438	2.5166619	0.86720449	3496.1067
867.89526	2.5181613	0.8690632	3494.761
868.79614	2.5230036	0.87043619	3490.8291
869.69702	2.522645	0.87190795	3492.7727
870.5979	2.5264618	0.87316424	3489.0457
871.49878	2.5295966	0.87459314	3492.6992
872.39966	2.5326076	0.87605625	3499.0261
873.30054	2.5349832	0.87803996	3495.6636
874.20142	2.5370631	0.8800053	3491.7322
875.10229	2.540735	0.88144261	3488.9709
876.00317	2.5406215	0.883026	3488.002
876.90405	2.5452085	0.88463181	3493.6938
877.80493	2.5456898	0.88625908	3486.3735
878.70581	2.5504777	0.8879351	3498.5771
879.60669	2.5549912	0.8897115	3494.3586
880.50757	2.5553155	0.89129364	3483.5049
881.40845	2.5582435	0.8926369	3493.2114
882.30933	2.5637047	0.89395034	3492.7141
883.21021	2.5646944	0.89560616	3503.9734
884.11108	2.566962	0.89733732	3493.8889
885.01196	2.5684974	0.89892197	3494.822
885.91284	2.5728016	0.90043581	3490.5029
886.81372	2.5750027	0.90204543	3491.6614
887.7146	2.5751119	0.90366864	3493.4746
888.61548	2.5798736	0.90525877	3491.917
889.51636	2.5820267	0.90660888	3492.9534
890.41724	2.5876718	0.90810347	3489.167
891.31812	2.5885844	0.90951186	3495.4277
892.21899	2.5924854	0.91132963	3496.4424
893.11987	2.5938125	0.9132176	3490.478
894.02075	2.5978575	0.91490948	3499.1084
894.92163	2.5955865	0.91679126	3488.4705
895.82251	2.6022286	0.91840893	3490.2798
896.72339	2.603883	0.91998273	3493.8169
897.62427	2.608546	0.92180187	3494.2627
898.52515	2.6104596	0.92359221	3496.3748
899.42603	2.6130743	0.92551035	3489.3818
900.3269	2.6138816	0.92712265	3486.2502
901.22778	2.6169796	0.92886579	3491.2056
902.12866	2.6192627	0.93052882	3490.1521
903.02954	2.6219611	0.93254554	3489.3704
903.93042	2.6274042	0.93432289	3495.1899
904.8313	2.6296005	0.93616724	3493.439
905.73218	2.6298695	0.93812621	3490.2173
906.63306	2.6333442	0.94012737	3491.3142
907.53394	2.6340849	0.9418636	3485.0313
908.43481	2.6383154	0.94346088	3490.0737
909.33569	2.6428142	0.94497657	3491.8271
910.23657	2.645247	0.94694078	3491.4744
911.13745	2.646626	0.94886345	3490.9822
912.03833	2.6493611	0.95051461	3484.48
912.93921	2.6540005	0.9525249	3492.3662
913.84009	2.6549027	0.9544571	3486.5801
914.74097	2.6569729	0.95647526	3488.7817
915.64185	2.6632576	0.95813632	3494.0029
916.54272	2.6644292	0.96016824	3487.6196
917.4436	2.6665788	0.96203434	3492.5164
918.34448	2.6694298	0.96407545	3483.9561
919.24536	2.6723719	0.96599627	3499.1667
920.14624	2.6741312	0.9681558	3484.9282
921.04712	2.6807215	0.96991342	3493.5637
921.948	2.6800685	0.97191477	3488.8625
922.84888	2.6828001	0.97383422	3484.7612
923.74976	2.6867089	0.9755258	3484.6042
924.65063	2.6873598	0.97733861	3489.0347
925.55151	2.6926181	0.97916424	3492.2661
926.45239	2.6942508	0.98109925	3487.1982
927.35327	2.6987829	0.9833703	3493.5496
928.25415	2.6967969	0.98552752	3488.1265
929.15503	2.7000775	0.98759747	3485.2083
930.05591	2.7053163	0.98962039	3484.1501
930.95679	2.7077789	0.99137104	3485.4275
931.85767	2.7098451	0.99335456	3478.9519
932.75854	2.7147171	0.99493176	3481.386
933.65942	2.7163992	0.9968878	3482.196
934.5603	2.7191732	0.99868	3481.0706
935.46118	2.7234635	1.0006045	3486.5676
936.36206	2.7237206	1.0027821	3482.9246
937.26294	2.724442	1.0048282	3481.4609
938.16382	2.7291577	1.0069443	3480.2346
939.0647	2.7319262	1.0089334	3483.4023
939.96558	2.7332087	1.0112863	3482.1748
940.86646	2.7380598	1.0133353	3477.4939
941.76733	2.7381628	1.0153141	3476.2432
942.66821	2.744097	1.0174053	3479.7754
943.56909	2.7479606	1.0196381	3478.5688
944.46997	2.7497945	1.0214112	3476.0532
945.37085	2.752722	1.0231543	3475.5295
946.27173	2.7522242	1.0251688	3481.292
947.17261	2.7558689	1.0274248	3480.8159
948.07349	2.7598128	1.029667	3482.2307
948.97437	2.7600257	1.0320256	3469.6404
949.87524	2.7624419	1.0338733	3472.9351
950.77612	2.7662945	1.0358574	3474.71
951.677	2.7702851	1.0382415	3479.3486
952.57788	2.7705076	1.0405989	3472.458
953.47876	2.7751539	1.0427724	3472.7119
954.37964	2.7773819	1.0449673	3468.9827
955.28052	2.7816105	1.0475911	3480.2476
956.1814	2.7828226	1.0502356	3468.5396
957.08228	2.7868683	1.0526733	3468.2986
957.98315	2.7869251	1.0551716	3468.3176
958.88403	2.791441	1.0576615	3471.3931
959.78491	2.7922783	1.0602527	3472.0171
960.68579	2.7958255	1.0631137	3468.7297
961.58667	2.8001881	1.0656779	3471.4761
962.48755	2.8014762	1.0687563	3472.6021
963.38843	2.8044882	1.0720595	3469.9385
964.28931	2.8064198	1.0747277	3461.3088
965.19019	2.8086147	1.0769956	3466.313
966.09106	2.8122518	1.0794199	3462.2942
966.99194	2.8137727	1.0821812	3467.1482
967.89282	2.816592	1.0848451	3465.8645
968.7937	2.8214025	1.0871872	3467.5356
969.69458	2.8229899	1.0895553	3459.4978
970.59546	2.8240991	1.0916573	3456.6921
971.49634	2.8288515	1.0940628	3457.9749
972.39722	2.8290937	1.0966227	3461.2979
973.2981	2.8341124	1.099424	3461.543
974.19897	2.8384364	1.1019874	3459.8872
975.09985	2.8405137	1.1044677	3458.3276
976.00073	2.8440659	1.1069199	3461.9724
976.90161	2.8465335	1.1092987	3463.4539
977.80249	2.8484805	1.1114694	3452.1697
978.70337	2.8501365	1.1134644	3448.7842
979.60425	2.8543394	1.1154854	3461.3848
980.50513	2.8562949	1.1183186	3457.033
981.40601	2.8583999	1.1210145	3452.7078
982.30688	2.860409	1.1233577	3447.8208
983.20776	2.8649495	1.1257807	3453.0911
984.10864	2.866781	1.1283548	3451.2258
985.00952	2.8694506	1.1307268	3447.3047
985.9104	2.8719585	1.1330723	3444.5884
986.81128	2.8747761	1.1355684	3446.8027
987.71216	2.8753889	1.1383764	3442.7021
988.61304	2.8812113	1.140926	3445.8027
989.51392	2.8845658	1.1431849	3441.6885
990.41479	2.8857963	1.1457844	3442.0752
991.31567	2.885726	1.1486717	3438.3816
992.21655	2.8899376	1.151687	3439.2334
993.11743	2.896575	1.1543823	3436.4329
994.01831	2.8972013	1.1572849	3439.2424
994.91919	2.8995733	1.1601472	3433.9099
995.82007	2.9037008	1.1635274	3440.0464
996.72095	2.9046414	1.1667362	3432.9875
997.62183	2.9080179	1.1691662	3428.4026
998.52271	2.91049	1.1712204	3431.2654
999.42358	2.9121597	1.1733588	3436.2827
1000.3245	2.9157493	1.1761683	3434.282
1001.2253	2.9210014	1.1788803	3427.3696
1002.1262	2.9190729	1.1814435	3428.0552
1003.0271	2.9223306	1.1845254	3427.3953
1003.928	2.9256923	1.1876258	3424.7334
1004.8289	2.928884	1.1905888	3421.0479
1005.7297	2.9281418	1.1937662	3420.3335
1006.6306	2.9339976	1.1968945	3423.6299
1007.5315	2.9381948	1.1997761	3417.7949
1008.4324	2.9388583	1.2027003	3412.9905
1009.3333	2.9444067	1.204765	3410.0339
1010.2341	2.9445286	1.2067903	3403.0642
1011.135	2.9499447	1.2087191	3412.8005
1012.0359	2.9524479	1.211055	3412.8127
1012.9368	2.9543784	1.2139184	3416.2183
1013.8376	2.9552393	1.2168065	3406.7524
1014.7385	2.9594424	1.2192825	3404.2454
1015.6394	2.9585671	1.2219433	3406.73
1016.5403	2.9662142	1.2245231	3406.9958
1017.4412	2.9661634	1.227339	3408.1868
1018.342	2.9692309	1.2301455	3404.4197
1019.2429	2.969981	1.2334104	3398.5081
1020.1438	2.975316	1.2365706	3392.8682
1021.0447	2.9765985	1.2391608	3388.1187
1021.9456	2.9782977	1.2419366	3392.0647
1022.8464	2.9838164	1.2444277	3392.9055
1023.7473	2.9846208	1.247394	3388.6863
1024.6482	2.9908867	1.2494724	3379.5735
1025.5491	2.9929144	1.2514844	3386.519
1026.45	2.9922748	1.2532624	3378.3513
1027.3508	2.997241	1.2552854	3383.9924
1028.2517	3.0020897	1.2576846	3390.0095
1029.1526	3.0033956	1.2601568	3388.4106
1030.0535	3.0048039	1.262974	3388.5347
1030.9543	3.0083992	1.2663624	3381.2744
1031.8552	3.0096581	1.2693307	3384.8594
1032.7561	3.0138898	1.2719728	3378.2471
1033.657	3.0115242	1.2751402	3373.6831
1034.5579	3.0179224	1.2781096	3371.4275
1035.4587	3.0160561	1.2811191	3370.8147
1036.3596	3.0250649	1.2841566	3368.2805
1037.2605	3.0259013	1.2868901	3367.0032
1038.1614	3.0310364	1.2899545	3370.2766
1039.0623	3.0349247	1.2925684	3365.8823
1039.9631	3.0362566	1.2954454	3369.634
1040.864	3.0397441	1.2985266	3359.3596
1041.7649	3.0395024	1.3009889	3358.0085
1042.6658	3.044286	1.3038869	3355.707
1043.5667	3.0447168	1.3068852	3353.0361
1044.4675	3.0505409	1.3094289	3353.7268
1045.3684	3.0524371	1.312289	3354.7168
1046.2693	3.0567741	1.3153487	3350.3926
1047.1702	3.054076	1.3182256	3343.2732
1048.071	3.0587311	1.3210307	3341.8643
1048.9719	3.0616002	1.3233883	3345.1807
1049.8728	3.0660365	1.3265073	3346.4148
1050.7737	3.0678005	1.3297657	3330.6311
1051.6746	3.0697784	1.3325161	3333.7102
1052.5754	3.0753853	1.3352517	3333.1575
1053.4763	3.0753334	1.3385533	3332.7766
1054.3772	3.0769987	1.3412021	3323.9722
1055.2781	3.0816245	1.3442911	3324.8386
1056.179	3.0840604	1.3470374	3325.4126
1057.0798	3.0859787	1.3497169	3319.1682
1057.9807	3.0889957	1.3526161	3320.7136
1058.8816	3.09202	1.3552959	3317.7124
1059.7825	3.0934544	1.3578228	3314.5974
1060.6833	3.099046	1.3607936	3313.8889
1061.5842	3.0984981	1.3635542	3305.6008
1062.4851	3.1012065	1.3666167	3302.5256
1063.386	3.107259	1.3692561	3298.521
1064.2869	3.107496	1.3719292	3300.7336
1065.1877	3.1088295	1.3746675	3297.3679
1066.0886	3.1132011	1.3774294	3296.7622
1066.9895	3.1149826	1.380206	3295.0569
1067.8904	3.1180918	1.3835051	3290.8804
1068.7913	3.1247823	1.3864557	3292.0725
1069.6921	3.1214991	1.3894949	3280.8293
1070.593	3.1259384	1.3924142	3287.6355
1071.4939	3.1279631	1.3962547	3278.9026
1072.3948	3.1338305	1.3994272	3276.2114
1073.2957	3.1360166	1.4024199	3272.2734
1074.1965	3.1398964	1.4052169	3268.9922
1075.0974	3.139149	1.4078418	3264.6013
1075.9983	3.1445632	1.4108903	3267.4087
1076.8992	3.1467056	1.4136496	3259.7915
1077.8	3.1481907	1.4164319	3257.1257
1078.7009	3.1521688	1.4191788	3258.0295
1079.6018	3.1547523	1.4226255	3255.1973
1080.5027	3.1552882	1.425702	3245.8384
1081.4036	3.1607683	1.4289343	3244.7463
1082.3044	3.1617222	1.4319752	3237.6716
1083.2053	3.1658845	1.4345511	3230.1462
1084.1062	3.1675725	1.4372234	3240.2241
1085.0071	3.1705062	1.4409543	3233.9504
1085.908	3.1728756	1.4444951	3224.3899
1086.8088	3.1734159	1.4471105	3219.7126
1087.7097	3.1784317	1.4495775	3212.1353
1088.6106	3.1791041	1.4522412	3210.8179
1089.5115	3.1849301	1.4543358	3211.4387
1090.4124	3.1844716	1.4567293	3213.6514
1091.3132	3.1882565	1.4604442	3214.8157
1092.2141	3.1911595	1.4639434	3197.5596
1093.115	3.1943941	1.4665494	3195.9939
1094.0159	3.1956217	1.4693226	3191.6423
1094.9167	3.1973631	1.4725354	3186.7175
1095.8176	3.2016511	1.4761159	3187.3806
1096.7185	3.2065117	1.4792472	3174.6064
1097.6194	3.2046497	1.4822398	3174.1345
1098.5203	3.2090573	1.4852252	3170.9307
1099.4211	3.212225	1.488327	3165.3699
1100.322	3.216557	1.4917215	3162.2473
1101.2229	3.2193432	1.495306	3158.7822
1102.1238	3.2237036	1.4989055	3150.5901
1103.0247	3.2239022	1.5024121	3140.502
1103.9255	3.2273281	1.5058231	3133.1096
1104.8264	3.2298987	1.5095384	3118.7954
1105.7273	3.2322919	1.5140513	3095.873
1106.6282	3.235429	1.5201588	3052.0337
1107.5291	3.2400284	1.5241245	3051.9626
1108.4299	3.2405102	1.5292754	3014.7761
1109.3308	3.2451196	1.5341641	2992.178
1110.2317	3.2493253	1.5421532	2940.6904
1110.3318	3.2487042	1.5461932	2904.6135