File: datasets/am_bench_2022/raw_data/90-X.19-2/specimen.dat
MTS793|MPT|ENU|1|2|.|/|:|1|0|0|A

Operator Information						Time:	21.094971	Sec	11/2/2021 1:38:44 PM
Operator	Nick Derimow
Project	AM Bench 2022 mini-tensile challenge
Specimen ID	90-X.19-2
Material	PBF-L Inconel 625
Specimen Width	2.54	mm
Specimen Thickness	1.51	mm
Notes
Operator Information End

Data Acquisition						Time:	1022.0996	Sec	11/2/2021 1:55:25 PM
Time	Axial Displacement	Axial Extensometer	Axial Force
Sec	mm	mm	N
21.219482	0.0056292564	0.0001074609	70.125221
22.220459	0.0086513469	0.00011937735	81.080254
23.221436	0.013894456	0.00022867337	94.126808
24.222412	0.017104892	0.00026537242	103.53796
25.223389	0.016897747	0.00040456202	116.16997
26.224365	0.019129572	0.00053689495	123.17888
27.225342	0.02167099	0.00049812242	136.28879
28.226318	0.024835121	0.00071267807	150.56267
29.227295	0.026471123	0.00076976378	164.28819
30.228271	0.033458263	0.00077544333	183.56339
31.229248	0.033629961	0.0010182648	198.08807
32.230225	0.038097356	0.0012074509	214.40523
33.231201	0.041374534	0.0012447573	234.85562
34.232178	0.042761032	0.0015534502	246.65378
35.233154	0.044761792	0.0015030439	269.11526
36.234131	0.049484015	0.0016724447	287.74622
37.235107	0.04967026	0.0018196783	304.47034
38.236084	0.057043623	0.0019272451	326.24081
39.237061	0.058763016	0.0022022917	348.18472
40.238037	0.063035764	0.002152913	366.35815
41.239014	0.061173353	0.0024115397	388.9743
42.23999	0.068363287	0.0024915691	406.18863
43.240967	0.069081016	0.0026998715	430.62155
44.241943	0.070867464	0.0029417966	453.77597
45.24292	0.073383473	0.0028693809	471.7966
46.243896	0.0787718	0.0031628625	499.76321
47.244873	0.078839205	0.0033470534	515.95129
48.24585	0.085233241	0.0034529031	544.73462
49.246826	0.086045988	0.0037343341	568.62482
50.247803	0.089093484	0.0039222543	591.60364
51.248779	0.094232507	0.0039754962	620.43683
52.249756	0.098174199	0.0042829523	641.75012
53.250732	0.096347801	0.0044701551	666.97864
54.251709	0.10239117	0.0044914503	697.32928
55.252686	0.10723761	0.0047890968	726.66772
56.253662	0.10986328	0.0049020057	748.06836
57.254639	0.11180463	0.0052101426	781.87299
58.255615	0.11361478	0.0053349119	801.10211
59.256592	0.11756094	0.0054820706	829.64325
60.257568	0.12154683	0.0056058113	850.19818
61.258545	0.12469806	0.0058577708	880.40881
62.259521	0.12706511	0.0060252305	906.29266
63.260498	0.12862188	0.0062925569	928.93555
64.261475	0.13187118	0.0063608633	955.76465
65.262451	0.13288473	0.0066043283	985.54089
66.263428	0.13699484	0.0068984171	1013.2594
67.264404	0.14147966	0.0069891289	1043.5669
68.265381	0.14681613	0.0072635035	1072.5488
69.266357	0.146844	0.00752204	1096.5001
70.267334	0.1525539	0.0076012169	1132.0963
71.268311	0.15110716	0.0079625305	1152.1541
72.269287	0.15630884	0.0079514133	1178.8973
73.270264	0.15908982	0.0081426641	1193.9492
74.27124	0.16296139	0.0084210252	1232.5955
75.272217	0.16343386	0.0085122837	1251.3306
76.273193	0.16818954	0.0088187596	1287.8292
77.27417	0.17290337	0.0090462938	1317.499
78.275146	0.17147759	0.0091598174	1335.3514
79.276123	0.17675205	0.0094168456	1371.3162
80.2771	0.18258278	0.0095808562	1398.2357
81.278076	0.1830595	0.0097933821	1426.679
82.279053	0.18644404	0.009885652	1439.473
83.280029	0.18876669	0.01017102	1476.5259
84.281006	0.19185583	0.01027782	1506.7047
85.281982	0.19384117	0.010582236	1533.2795
86.282959	0.19950144	0.010820603	1563.6654
87.283936	0.20057236	0.010982351	1585.5068
88.284912	0.20140646	0.011252218	1607.4592
89.285889	0.20594624	0.01140404	1642.7229
90.286865	0.21047156	0.01154983	1662.228
91.287842	0.21340841	0.011698126	1695.0331
92.288818	0.21665061	0.01182432	1711.6429
93.289795	0.22162203	0.012027647	1738.9624
94.290771	0.21929678	0.012228664	1764.7766
95.291748	0.22310498	0.012417873	1786.0498
96.292725	0.22829871	0.012694039	1813.0939
97.293701	0.23154664	0.012875063	1842.2686
98.294678	0.23241805	0.01294064	1869.5621
99.295654	0.23675221	0.013209789	1895.0182
100.29663	0.23972313	0.013391906	1918.5079
101.29761	0.24048097	0.013624258	1947.8645
102.29858	0.244789	0.013749245	1967.9181
103.29956	0.2492898	0.013874601	1988.0035
104.30054	0.2513833	0.01403392	2006.6168
105.30151	0.25669956	0.014226876	2041.7518
106.30249	0.25798136	0.014510115	2057.8359
107.30347	0.25994483	0.014676386	2083.8669
108.30444	0.26500493	0.014733927	2102.8425
109.30542	0.26744124	0.01492624	2114.7678
110.3064	0.26822987	0.015152732	2141.0244
111.30737	0.27471727	0.015209028	2156.1936
112.30835	0.27424991	0.015469018	2182.3284
113.30933	0.28111735	0.015769094	2210.5776
114.3103	0.28091246	0.015872255	2228.3491
115.31128	0.28446752	0.015996993	2245.3228
116.31226	0.28850588	0.016210908	2259.8813
117.31323	0.29054919	0.016441427	2283.4102
118.31421	0.2931796	0.016464539	2298.1179
119.31519	0.29740071	0.016738808	2313.9485
120.31616	0.300859	0.017092945	2336.0461
121.31714	0.30272862	0.017114377	2347.8796
122.31812	0.30842164	0.017280029	2369.9426
123.31909	0.30834398	0.01756173	2379.4912
124.32007	0.31206092	0.017792434	2398.4292
125.32104	0.31354207	0.017823283	2407.9519
126.32202	0.31848681	0.018221304	2427.8557
127.323	0.32233542	0.018313155	2442.9141
128.32397	0.32555097	0.01840359	2449.6543
129.32495	0.32787645	0.018627085	2461.7456
130.32593	0.33242089	0.01883545	2477.7222
131.3269	0.33363876	0.019035073	2490.2004
132.32788	0.33768159	0.019215584	2497.6069
133.32886	0.33935967	0.019467378	2512.4485
134.32983	0.34210208	0.019639436	2525.4441
135.33081	0.34909245	0.020014379	2540.1116
136.33179	0.35290629	0.02013251	2552.2974
137.33276	0.35345662	0.02044398	2554.8003
138.33374	0.35478303	0.020733161	2574.6843
139.33472	0.35635474	0.020852566	2579.198
140.33569	0.36021546	0.021206938	2595.2578
141.33667	0.36686352	0.021360816	2598.4446
142.33765	0.37050417	0.021685781	2608.9478
143.33862	0.36921498	0.021866264	2608.0474
144.3396	0.37034947	0.022144323	2629.1785
145.34058	0.37425295	0.022625696	2635.2837
146.34155	0.37846223	0.02292273	2643.2517
147.34253	0.38338858	0.023330541	2655.5779
148.34351	0.38497397	0.023846975	2662.4653
149.34448	0.38694626	0.024030954	2668.6472
150.34546	0.39180437	0.024502816	2674.7937
151.34644	0.39365146	0.024811856	2680.8293
152.34741	0.39913753	0.025361521	2693.8169
153.34839	0.40144208	0.025842914	2695.9849
154.34937	0.40408251	0.026354128	2713.2981
155.35034	0.40683052	0.026886925	2712.3162
156.35132	0.41127184	0.027532479	2722.7427
157.35229	0.41227067	0.028131483	2728.4512
158.35327	0.41417965	0.028588139	2735.9897
159.35425	0.41783875	0.02926798	2739.3901
160.35522	0.42060927	0.029921792	2750.48
161.3562	0.4242155	0.030870082	2762.0396
162.35718	0.42639345	0.031562023	2762.3687
163.35815	0.43146342	0.032052036	2765.3301
164.35913	0.43572265	0.032795623	2771.2996
165.36011	0.4370313	0.033464778	2777.4558
166.36108	0.44001096	0.034215532	2782.385
167.36206	0.44055966	0.034934849	2783.2866
168.36304	0.44549093	0.035616811	2793.5698
169.36401	0.4479703	0.036487062	2802.3569
170.36499	0.45402393	0.037213042	2802.3113
171.36597	0.45575601	0.038075559	2804.4316
172.36694	0.45787334	0.038956523	2807.8401
173.36792	0.46239197	0.039787386	2814.488
174.3689	0.46397167	0.04051083	2817.9253
175.36987	0.46749595	0.041429542	2824.2507
176.37085	0.46993515	0.042184085	2827.9626
177.37183	0.47430936	0.043126184	2836.3877
178.3728	0.47777382	0.043956395	2831.6211
179.37378	0.48131877	0.044718876	2842.0037
180.37476	0.48072419	0.045660693	2842.3923
181.37573	0.48612425	0.046558809	2850.5061
182.37671	0.48879823	0.047532301	2851.1887
183.37769	0.49139008	0.04834877	2854.9507
184.37866	0.49596539	0.049384747	2862.29
185.37964	0.49898735	0.050139267	2866.5947
186.38062	0.49995443	0.051050603	2864.25
187.38159	0.50222027	0.051934797	2873.802
188.38257	0.50786722	0.052978538	2882.2708
189.38354	0.51216662	0.05406931	2885.2463
190.38452	0.51247478	0.054876905	2884.6611
191.3855	0.51471728	0.055864826	2884.8079
192.38647	0.51831061	0.05682005	2892.8518
193.38745	0.52124012	0.05776101	2894.804
194.38843	0.52408761	0.058713667	2892.3621
195.3894	0.52968538	0.059868421	2908.5229
196.39038	0.52856243	0.060748704	2902.0115
197.39136	0.5318523	0.061960034	2910.782
198.39233	0.53553408	0.063041992	2911.7573
199.39331	0.53854275	0.063987114	2908.6399
200.39429	0.54103255	0.065078534	2925.6277
201.39526	0.54787111	0.066175617	2925.6772
202.39624	0.54846752	0.067269854	2923.5459
203.39722	0.54860133	0.068361551	2927.4187
204.39819	0.552351	0.069407307	2929.2781
205.39917	0.55464923	0.070305824	2930.5815
206.40015	0.5605582	0.071281992	2932.968
207.40112	0.56279743	0.0722977	2937.2886
208.4021	0.5667426	0.073257618	2943.5103
209.40308	0.57297403	0.074477628	2951.8179
210.40405	0.57318735	0.075544551	2956.3433
211.40503	0.57504344	0.076627597	2953.3784
212.40601	0.57932335	0.077562243	2956.1306
213.40698	0.58249646	0.078646377	2955.5879
214.40796	0.58754081	0.079479545	2964.1875
215.40894	0.58628994	0.080573767	2963.6838
216.40991	0.58927494	0.081624791	2966.385
217.41089	0.59131134	0.082568727	2965.9634
218.41187	0.59520447	0.083680496	2969.4097
219.41284	0.60057026	0.084907189	2977.9043
220.41382	0.6022225	0.085833043	2976.7795
221.41479	0.60458875	0.08683075	2979.7603
222.41577	0.6086784	0.087989315	2986.9436
223.41675	0.61262816	0.089106716	2990.5925
224.41772	0.61524808	0.090064496	2989.8589
225.4187	0.61896521	0.091294035	2993.21
226.41968	0.61902541	0.092148826	2986.949
227.42065	0.62226641	0.093205541	2988.3557
228.42163	0.62653089	0.094387606	2996.4067
229.42261	0.62919343	0.095497705	3001.9294
230.42358	0.63241041	0.096577063	3003.7976
231.42456	0.63698435	0.097554035	3004.0911
232.42554	0.6384542	0.098725602	3008.6169
233.42651	0.64544296	0.099969067	3015.6006
234.42749	0.64199263	0.10109901	3018.9175
235.42847	0.64594924	0.10220978	3014.0244
236.42944	0.64984721	0.10330364	3016.6094
237.43042	0.65250915	0.10424452	3014.76
238.4314	0.65967554	0.10524258	3027.8022
239.43237	0.65911621	0.10624202	3021.8438
240.43335	0.66167587	0.10735348	3028.1702
241.43433	0.6663633	0.10851991	3034.241
242.4353	0.66953498	0.10958575	3031.8911
243.43628	0.6729095	0.11063716	3039.5601
244.43726	0.67479366	0.11171312	3035.092
245.43823	0.67795491	0.11260579	3035.0129
246.43921	0.67795223	0.11368477	3040.3494
247.44019	0.68389332	0.11475994	3043.2007
248.44116	0.68808603	0.11587154	3045.2725
249.44214	0.68980604	0.11682779	3046.0713
250.44312	0.69329607	0.11779922	3046.0789
251.44409	0.69760656	0.118769	3053.5376
252.44507	0.69794136	0.11983152	3056.6379
253.44604	0.70364404	0.12099388	3057.4639
254.44702	0.70782578	0.12221786	3069.0913
255.448	0.70897603	0.12306864	3061.0051
256.44897	0.71251363	0.12414564	3065.6594
257.44995	0.71299905	0.12527353	3063.5847
258.45093	0.71476394	0.12649736	3064.7656
259.4519	0.71834171	0.12756987	3064.8936
260.45288	0.72360361	0.12855531	3067.1492
261.45386	0.72421074	0.12949482	3069.4277
262.45483	0.72721893	0.13042665	3072.637
263.45581	0.72907054	0.13180026	3080.7307
264.45679	0.73618835	0.13299815	3081.2324
265.45776	0.73891848	0.1340376	3077.7263
266.45874	0.74256837	0.13479339	3081.9741
267.45972	0.74547225	0.13593921	3088.8335
268.46069	0.74720597	0.13695769	3086.8811
269.46167	0.74902314	0.13816912	3091.3877
270.46265	0.75299346	0.13923329	3093.9924
271.46362	0.75729614	0.1404229	3099.2122
272.4646	0.76060551	0.14143944	3096.9348
273.46558	0.76205468	0.14257708	3102.5137
274.46655	0.76426011	0.14368646	3101.9873
275.46753	0.76695049	0.14513664	3106.7644
276.46851	0.77150559	0.14639828	3110.7629
277.46948	0.77280563	0.14743488	3111.3286
278.47046	0.77424884	0.14836301	3102.1323
279.47144	0.7838192	0.14950801	3114.0112
280.47241	0.7831015	0.15042275	3116.2649
281.47339	0.78383577	0.15147628	3111.8008
282.47437	0.79019409	0.15234344	3109.9243
283.47534	0.79336864	0.15325636	3116.9973
284.47632	0.79570705	0.15420133	3121.7295
285.47729	0.80312216	0.15512758	3121.1309
286.47827	0.80267489	0.15596634	3123.7441
287.47925	0.8025499	0.1568947	3122.5107
288.48022	0.806979	0.1580569	3123.0176
289.4812	0.8081581	0.15889798	3123.5728
290.48218	0.81245446	0.15994647	3127.4954
291.48315	0.81365651	0.16088468	3131.0471
292.48413	0.82194179	0.16202879	3141.5923
293.48511	0.82163388	0.16313015	3140.9043
294.48608	0.82600534	0.16429365	3140.0979
295.48706	0.82636225	0.16531223	3140.4116
296.48804	0.83345634	0.16633926	3147.3486
297.48901	0.83455902	0.16725762	3143.1738
298.48999	0.8374486	0.16823411	3142.2434
299.49097	0.84142667	0.16937251	3149.219
300.49194	0.84382248	0.17045024	3147.5059
301.49292	0.84677756	0.17148659	3151.9885
302.4939	0.84752417	0.17256422	3151.9412
303.49487	0.85184777	0.17377481	3159.0684
304.49585	0.85351759	0.17494199	3154.0916
305.49683	0.85563099	0.17617747	3156.6851
306.4978	0.86136401	0.17720082	3156.6621
307.49878	0.86369544	0.17825115	3159.749
308.49976	0.86719477	0.17927241	3160.8008
309.50073	0.87108308	0.18019898	3165.6118
310.50171	0.87488544	0.18129702	3168.825
311.50269	0.87388825	0.18245155	3168.7852
312.50366	0.87887812	0.18351158	3170.9968
313.50464	0.88234907	0.18449607	3170.3013
314.50562	0.88338751	0.18564117	3180.8335
315.50659	0.88778991	0.18676966	3173.7385
316.50757	0.89501512	0.18788826	3183.6091
317.50854	0.89514005	0.18880546	3179.4968
318.50952	0.89713204	0.18981858	3178.4871
319.5105	0.90253127	0.19091277	3184.3325
320.51147	0.90444535	0.19179209	3179.2927
321.51245	0.9073779	0.19281887	3182.7007
322.51343	0.90945625	0.19370474	3186.2974
323.5144	0.91332477	0.19464256	3188.4231
324.51538	0.91445249	0.19585182	3193.3716
325.51636	0.91728407	0.19677977	3189.3833
326.51733	0.91801494	0.19804214	3194.5596
327.51831	0.92386138	0.19913824	3193.5723
328.51929	0.92547691	0.20018004	3191.813
329.52026	0.92924488	0.20124301	3196.1848
330.52124	0.93490875	0.20240405	3201.1096
331.52222	0.93949026	0.20345703	3203.7979
332.52319	0.94203871	0.20435661	3204.5415
333.52417	0.94399089	0.20518306	3204.6021
334.52515	0.94460535	0.20603526	3202.9822
335.52612	0.94417799	0.20706311	3204.6926
336.5271	0.94988531	0.20814162	3209.906
337.52808	0.95547819	0.20924824	3214.6855
338.52905	0.95538968	0.21048686	3223.2375
339.53003	0.9593364	0.21167532	3217.4514
340.53101	0.96274	0.2129523	3215.895
341.53198	0.96744895	0.21393445	3220.5603
342.53296	0.96901661	0.21489222	3220.5278
343.53394	0.9717766	0.21599114	3222.7515
344.53491	0.97686952	0.21710306	3226.1077
345.53589	0.97669458	0.21794906	3220.8586
346.53687	0.9804973	0.21886459	3227.6104
347.53784	0.98402655	0.21987095	3230.5273
348.53882	0.98715192	0.22096486	3227.2739
349.53979	0.99145395	0.22211711	3235.4565
350.54077	0.99566215	0.22337352	3235.5549
351.54175	0.99584264	0.22409829	3227.1631
352.54272	0.99951816	0.22500284	3231.7175
353.5437	1.0017226	0.2261143	3241.3845
354.54468	1.0054722	0.22722659	3237.6909
355.54565	1.0078809	0.22815806	3238.5918
356.54663	1.0139884	0.22933632	3242.8831
357.54761	1.0131046	0.23041987	3241.5061
358.54858	1.018117	0.23124813	3240.7422
359.54956	1.019522	0.23229304	3242.4832
360.55054	1.0230498	0.23314701	3246.9216
361.55151	1.0256745	0.23425971	3249.1567
362.55249	1.0282943	0.23537011	3248.6375
363.55347	1.0330573	0.23646161	3258.2888
364.55444	1.0325989	0.23758814	3257.2153
365.55542	1.0371722	0.23881063	3257.4827
366.5564	1.0403636	0.23981933	3254.959
367.55737	1.0461133	0.24071312	3253.3447
368.55835	1.0477629	0.24175312	3256.238
369.55933	1.0481677	0.24280079	3265.7288
370.5603	1.0539378	0.243815	3263.3594
371.56128	1.0525267	0.24493934	3262.9846
372.56226	1.0604383	0.24589555	3264.5896
373.56323	1.0652374	0.24688818	3264.4995
374.56421	1.0666189	0.24785398	3269.8152
375.56519	1.0642533	0.2488506	3270.3838
376.56616	1.0710515	0.24990286	3274.3777
377.56714	1.0749477	0.25097391	3276.9871
378.56812	1.0787009	0.25206095	3278.2595
379.56909	1.0826957	0.25328997	3276.4919
380.57007	1.0825412	0.25408524	3273.7593
381.57104	1.0876787	0.25505462	3276.1111
382.57202	1.0899073	0.25615168	3282.9321
383.573	1.0926797	0.25714949	3283.2695
384.57397	1.0992252	0.25825244	3285.533
385.57495	1.0988951	0.25923997	3285.5732
386.57593	1.0980569	0.26017565	3281.1755
387.5769	1.1021694	0.26127622	3285.3872
388.57788	1.1060183	0.26246846	3287.676
389.57886	1.1113142	0.2634322	3291.8809
390.57983	1.1133533	0.2645846	3294.4333
391.58081	1.1180192	0.26567009	3295.084
392.58179	1.123095	0.26669043	3294.7075
393.58276	1.121549	0.26763785	3291.7686
394.58374	1.1223806	0.26848283	3288.1919
395.58472	1.1286969	0.26935771	3295.6394
396.58569	1.128633	0.2705352	3301.2329
397.58667	1.1348908	0.27149984	3304.4185
398.58765	1.1373717	0.27233726	3302.114
399.58862	1.1434507	0.27337196	3307.374
400.5896	1.1432217	0.27447084	3309.6787
401.59058	1.1447066	0.27563682	3308.9375
402.59155	1.1513851	0.27688178	3317.2253
403.59253	1.1544973	0.27797857	3310.2732
404.59351	1.1565123	0.27897146	3315.0715
405.59448	1.1587418	0.27998751	3312.3062
406.59546	1.1608235	0.28127071	3322.0525
407.59644	1.1654546	0.28210208	3315.054
408.59741	1.168015	0.28311262	3320.208
409.59839	1.1705238	0.28414929	3316.6157
410.59937	1.1747916	0.28527066	3321.3447
411.60034	1.175697	0.28636223	3322.3457
412.60132	1.1801711	0.28736898	3325.064
413.60229	1.1807919	0.2884101	3323.6599
414.60327	1.185415	0.28947562	3328.4844
415.60425	1.1888421	0.29036105	3322.9258
416.60522	1.1919605	0.29136592	3321.7678
417.6062	1.1927006	0.29233196	3331.3
418.60718	1.195663	0.29348186	3337.282
419.60815	1.200473	0.29432935	3328.9561
420.60913	1.2024292	0.29551694	3333.2593
421.61011	1.2095939	0.29646149	3334.5942
422.61108	1.2104673	0.29741046	3339.2456
423.61206	1.213184	0.29854086	3336.0955
424.61304	1.2157927	0.29944834	3342.6641
425.61401	1.2199174	0.30046821	3343.6711
426.61499	1.2206688	0.301597	3339.6311
427.61597	1.2255009	0.30266809	3339.6267
428.61694	1.2280587	0.30343607	3336.1025
429.61792	1.2290339	0.30429512	3335.8972
430.6189	1.2354095	0.30506465	3339.9602
431.61987	1.2392522	0.30611008	3352.363
432.62085	1.2410374	0.30709895	3358.1199
433.62183	1.2415299	0.30822924	3352.3918
434.6228	1.2468216	0.30941811	3343.9768
435.62378	1.2463026	0.31058338	3356.0613
436.62476	1.2515115	0.31160325	3354.7993
437.62573	1.2537718	0.31252101	3350.6482
438.62671	1.2536262	0.31366348	3353.9941
439.62769	1.2601279	0.31467023	3355.6155
440.62866	1.2636052	0.31561762	3354.302
441.62964	1.2662663	0.31651554	3348.2932
442.63062	1.269285	0.31759813	3366.2046
443.63159	1.2718176	0.31871238	3362.6064
444.63257	1.2787675	0.31990728	3365.9944
445.63354	1.277962	0.32076138	3359.927
446.63452	1.2830143	0.32186946	3365.5461
447.6355	1.2846677	0.32298291	3371.2209
448.63647	1.2873856	0.32395539	3368.2126
449.63745	1.2932491	0.32503203	3371.2029
450.63843	1.2956107	0.32614666	3375.7849
451.6394	1.2984953	0.32717195	3374.1042
452.64038	1.2989995	0.32824436	3375.8586
453.64136	1.3030434	0.32923245	3372.1558
454.64233	1.3052673	0.33017051	3373.4297
455.64331	1.3082304	0.33131126	3379.0464
456.64429	1.311511	0.33222935	3377.9087
457.64526	1.3171403	0.33346719	3383.1931
458.64624	1.3168011	0.33451518	3381.7754
459.64722	1.3209528	0.33560076	3385.8406
460.64819	1.3237488	0.33672917	3385.4924
461.64917	1.3277127	0.33783242	3387.5105
462.65015	1.3280101	0.3385869	3382.6101
463.65112	1.3320442	0.3397648	3387.5803
464.6521	1.334525	0.34068921	3383.6304
465.65308	1.3398607	0.34153134	3382.2532
466.65405	1.3421891	0.34279734	3391.3469
467.65503	1.3476715	0.3438535	3400.5449
468.65601	1.3493841	0.34486338	3393.5957
469.65698	1.3498996	0.34585398	3393.6685
470.65796	1.3543406	0.34726086	3402.6279
471.65894	1.3552514	0.34825468	3399.3438
472.65991	1.3597921	0.34915212	3392.3501
473.66089	1.3629957	0.34997725	3401.7839
474.66187	1.3632065	0.35115865	3400.698
475.66284	1.366582	0.35220769	3397.1309
476.66382	1.3723034	0.35304278	3401.708
477.66479	1.3736095	0.35404927	3404.0645
478.66577	1.3780453	0.35526133	3409.5352
479.66675	1.3785412	0.35630187	3402.2002
480.66772	1.3823444	0.35739326	3407.2207
481.6687	1.3904366	0.35851905	3411.3489
482.66968	1.3908499	0.35958934	3414.8799
483.67065	1.3909595	0.36067325	3412.03
484.67163	1.3957573	0.36184558	3411.1038
485.67261	1.3981599	0.36297774	3411.6619
486.67358	1.4016995	0.36410564	3412.6104
487.67456	1.40312	0.3650223	3409.4487
488.67554	1.4089032	0.36598098	3412.3267
489.67651	1.4108568	0.36717552	3422.761
490.67749	1.4099808	0.36818686	3419.051
491.67847	1.4167199	0.36911041	3415.7041
492.67944	1.4179887	0.37020043	3421.9436
493.68042	1.42299	0.37113506	3418.5845
494.6814	1.4247329	0.37206364	3419.7031
495.68237	1.4290503	0.37325317	3423.5862
496.68335	1.4321175	0.37421346	3423.5605
497.68433	1.4371092	0.37532347	3431.9138
498.6853	1.4405309	0.37634346	3425.1113
499.68628	1.4414449	0.3774057	3434.1768
500.68726	1.4438134	0.37863404	3430.406
501.68823	1.4468379	0.37978566	3434.4561
502.68921	1.4491107	0.38078424	3426.3337
503.69019	1.4520369	0.38198954	3433.5669
504.69116	1.4566464	0.3831279	3435.1765
505.69214	1.4581118	0.38421905	3435.7351
506.69312	1.4639226	0.38528997	3435.356
507.69409	1.4650329	0.38626486	3438.325
508.69507	1.4671918	0.38724574	3432.0068
509.69604	1.470871	0.38793099	3426.7964
510.69702	1.4737693	0.38896462	3438.7646
511.698	1.4772112	0.39002284	3443.8035
512.69897	1.4810545	0.39118063	3445.9951
513.69995	1.4825404	0.39206281	3443.0708
514.70093	1.4853064	0.39319825	3444.5283
515.7019	1.4888544	0.39423922	3448.1826
516.70288	1.4878401	0.39535099	3445.4775
517.70386	1.4929779	0.39656195	3450.5061
518.70483	1.4970869	0.39776942	3449.2004
519.70581	1.5020366	0.39897281	3450.4441
520.70679	1.5032895	0.40009534	3446.2893
521.70776	1.5058739	0.40108135	3448.5107
522.70874	1.5107175	0.40211463	3451.7644
523.70972	1.5131446	0.40317333	3452.5745
524.71069	1.5151665	0.40411019	3451.0017
525.71167	1.519823	0.40499383	3454.094
526.71265	1.520622	0.40602538	3454.3225
527.71362	1.5248524	0.4070425	3458.0212
528.7146	1.5294054	0.40826464	3462.3159
529.71558	1.5300196	0.40947357	3463.8831
530.71655	1.5342344	0.41078058	3465.262
531.71753	1.537788	0.41208985	3467.0098
532.71851	1.5391082	0.41309598	3459.9219
533.71948	1.5422724	0.41413701	3458.7571
534.72046	1.544136	0.41511989	3455.3755
535.72144	1.550082	0.4162153	3468.1221
536.72241	1.5518237	0.41720918	3469.9023
537.72339	1.5558865	0.41827691	3471.6475
538.72437	1.5576345	0.41943571	3470.3721
539.72534	1.5608966	0.42037961	3465.9583
540.72632	1.5655895	0.42151767	3471.7527
541.72729	1.5683715	0.42269152	3471.0027
542.72827	1.5695261	0.42361045	3468.948
543.72925	1.5709409	0.42480615	3475.6138
544.73022	1.5747313	0.4259758	3468.208
545.7312	1.579144	0.4269602	3472.0176
546.73218	1.5845039	0.42811394	3476.3269
547.73315	1.585029	0.42926127	3479.5227
548.73413	1.5849122	0.43045095	3478.134
549.73511	1.5885791	0.43136579	3474.1682
550.73608	1.5970137	0.43274933	3482.5789
551.73706	1.5985941	0.43376648	3480.012
552.73804	1.6001155	0.43471956	3479.1692
553.73901	1.6041639	0.43569577	3482.5691
554.73999	1.6056027	0.43703055	3490.8838
555.74097	1.6089274	0.43812808	3492.3306
556.74194	1.6084005	0.43927106	3487.1787
557.74292	1.615471	0.44043961	3489.4595
558.7439	1.6183691	0.44184253	3494.5015
559.74487	1.6222321	0.44275647	3490.7378
560.74585	1.6224937	0.44384852	3486.5283
561.74683	1.6251031	0.4448714	3487.0083
562.7478	1.6293529	0.44593602	3498.0981
563.74878	1.6321754	0.44718418	3497.4968
564.74976	1.638528	0.448367	3494.2671
565.75073	1.6386942	0.44952181	3493.4531
566.75171	1.6393862	0.45051864	3492.4915
567.75269	1.6434844	0.45168585	3493.1887
568.75366	1.6498836	0.45282826	3495.7393
569.75464	1.6537994	0.4538939	3506.0647
570.75562	1.6547091	0.45517883	3500.5298
571.75659	1.6580795	0.45617288	3494.6873
572.75757	1.6602141	0.45714203	3499.8098
573.75854	1.6645366	0.45817888	3500.083
574.75952	1.6681416	0.45938131	3509.5842
575.7605	1.6698146	0.46027344	3503.8831
576.76147	1.6728586	0.46149805	3507.1238
577.76245	1.6754391	0.46289277	3503.416
578.76343	1.6754382	0.46395534	3500.4548
579.7644	1.6819497	0.46485576	3504.5942
580.76538	1.6850203	0.46592981	3509.9712
581.76636	1.6855069	0.46711138	3504.396
582.76733	1.6905687	0.46841541	3510.7849
583.76831	1.6941594	0.46954185	3511.8765
584.76929	1.6935716	0.47059479	3510.106
585.77026	1.698022	0.47176102	3514.6191
586.77124	1.7009256	0.4729639	3510.8237
587.77222	1.7042472	0.47411576	3515.3135
588.77319	1.7083869	0.47510165	3513.9338
589.77417	1.7089936	0.47632518	3515.8989
590.77515	1.7151031	0.47746512	3517.8997
591.77612	1.7182487	0.47878754	3523.884
592.7771	1.7196982	0.47981417	3517.0188
593.77808	1.7219152	0.48089489	3509.9771
594.77905	1.7267842	0.48214504	3521.8726
595.78003	1.7317356	0.48332945	3526.6746
596.78101	1.731373	0.48452735	3522.9695
597.78198	1.7349001	0.48565593	3522.9673
598.78296	1.7392067	0.48678729	3521.0967
599.78394	1.7414944	0.48781127	3520.9319
600.78491	1.7410914	0.48883894	3525.8618
601.78589	1.7457707	0.4900575	3521.3267
602.78687	1.7508154	0.49130252	3528.5723
603.78784	1.7530086	0.49260139	3531.2087
604.78882	1.7554797	0.49374494	3526.9648
605.78979	1.7580922	0.49504048	3532.8809
606.79077	1.7620305	0.49626169	3532.1904
607.79175	1.7637296	0.49738815	3525.0356
608.79272	1.7680593	0.49839056	3530.5381
609.7937	1.7712034	0.49959558	3530.1104
610.79468	1.7732044	0.50076663	3531.7739
611.79565	1.7751095	0.5019837	3533.0129
612.79663	1.7810893	0.50322962	3539.6638
613.79761	1.7856157	0.50441581	3536.7478
614.79858	1.7873737	0.50552464	3532.738
615.79956	1.7907625	0.50654781	3538.998
616.80054	1.7905569	0.50758672	3534.3362
617.80151	1.794487	0.5087204	3534.0356
618.80249	1.7979584	0.51005256	3545.0601
619.80347	1.8009886	0.51106274	3537.5894
620.80444	1.8030775	0.51231855	3543.179
621.80542	1.8070371	0.51350206	3538.5225
622.8064	1.8103055	0.51474142	3548.0303
623.80737	1.8136679	0.51587969	3544.8982
624.80835	1.8184477	0.51707453	3545.999
625.80933	1.8193675	0.51846182	3548.6025
626.8103	1.8191119	0.51980108	3542.0278
627.81128	1.8235277	0.5212186	3544.3403
628.81226	1.8288856	0.52224863	3547.9648
629.81323	1.8295183	0.52337331	3547.459
630.81421	1.8314418	0.52448159	3547.4624
631.81519	1.8391931	0.52576971	3551.4973
632.81616	1.8396627	0.52689868	3550.5535
633.81714	1.8405869	0.52807707	3553.082
634.81812	1.8463937	0.52920675	3547.0081
635.81909	1.8496264	0.53049815	3552.8723
636.82007	1.8515288	0.53170103	3551.5884
637.82104	1.8537782	0.53272396	3546.2922
638.82202	1.8553072	0.53399527	3556.1565
639.823	1.8596324	0.5353784	3556.1099
640.82397	1.8634974	0.53644502	3553.7937
641.82495	1.8692179	0.53770906	3555.1111
642.82593	1.8692158	0.53902149	3554.0564
643.8269	1.875016	0.54019523	3552.1836
644.82788	1.8778447	0.54133296	3558.0583
645.82886	1.8805488	0.5423696	3551.5051
646.82983	1.8793699	0.54351139	3553.5815
647.83081	1.8840817	0.54478091	3559.9473
648.83179	1.8881325	0.54620904	3561.9006
649.83276	1.891871	0.54739249	3555.1008
650.83374	1.8954854	0.54840177	3555.2007
651.83472	1.8976684	0.54956836	3562.7886
652.83569	1.9007406	0.5508672	3561.5295
653.83667	1.9004458	0.55187804	3555.8284
654.83765	1.904804	0.55308867	3558.0457
655.83862	1.9090424	0.55415535	3556.8911
656.8396	1.9128202	0.55538511	3565.4348
657.84058	1.9147549	0.55672777	3566.9875
658.84155	1.9180928	0.55826688	3573.9731
659.84253	1.9203175	0.55956167	3568.3259
660.84351	1.9246229	0.56121874	3572.1785
661.84448	1.9276429	0.56257552	3566.9878
662.84546	1.931152	0.56407923	3570.1758
663.84644	1.934325	0.5651837	3568.6853
664.84741	1.9368074	0.56633383	3561.5854
665.84839	1.9384885	0.56763631	3571.9373
666.84937	1.9425955	0.5689072	3570.3022
667.85034	1.9434091	0.57021946	3569.0305
668.85132	1.9486495	0.57141489	3570.2383
669.85229	1.9524393	0.57252556	3569.1448
670.85327	1.9545149	0.57365626	3570.8525
671.85425	1.9567076	0.57495826	3576.1646
672.85522	1.9595641	0.57604331	3572.7896
673.8562	1.9622711	0.57736111	3573.6978
674.85718	1.9655815	0.57849205	3568.6392
675.85815	1.9665062	0.5798648	3579.844
676.85913	1.9711974	0.58136237	3575.4189
677.86011	1.9778167	0.58263296	3582.3191
678.86108	1.9791857	0.58382505	3575.9915
679.86206	1.9804751	0.58503544	3576.5828
680.86304	1.9843204	0.58644271	3584.7678
681.86401	1.9888304	0.58769429	3580.0422
682.86499	1.9896525	0.58887726	3577.8884
683.86597	1.9931903	0.59019607	3582.231
684.86694	1.9958583	0.59159696	3579.8928
685.86792	2.0000978	0.59277213	3577.6328
686.8689	2.0045736	0.59409279	3583.5913
687.86987	2.0056903	0.59529287	3577.0764
688.87085	2.0097489	0.59665799	3585.4854
689.87183	2.0123577	0.59814721	3582.5632
690.8728	2.0142438	0.599464	3582.0378
691.87378	2.015554	0.60061187	3580.8989
692.87476	2.0223093	0.60204291	3582.5337
693.87573	2.0246556	0.60337204	3591.3398
694.87671	2.0280607	0.60473245	3584.7788
695.87769	2.0301609	0.60596436	3584.2087
696.87866	2.0318682	0.6071955	3584.657
697.87964	2.0359371	0.60867667	3592.0776
698.88062	2.0394628	0.60998183	3585.8206
699.88159	2.0425589	0.61113238	3583.7139
700.88257	2.0459321	0.61243403	3588.7659
701.88354	2.0448582	0.61375844	3585.9067
702.88452	2.05163	0.6152488	3593.4778
703.8855	2.0519199	0.61658925	3593.4063
704.88647	2.0563025	0.61790293	3585.051
705.88745	2.0577385	0.61921388	3591.6428
706.88843	2.0648167	0.62057316	3593.3765
707.8894	2.0628862	0.62203479	3591.4612
708.89038	2.0673108	0.62344992	3591.613
709.89136	2.0701132	0.62484306	3589.9961
710.89233	2.0773962	0.62622321	3593.7024
711.89331	2.0790317	0.6275872	3598.7947
712.89429	2.0810378	0.62917	3595.5808
713.89526	2.0836596	0.63091242	3594.1675
714.89624	2.084506	0.63224989	3591.7932
715.89722	2.0934846	0.63351661	3597.0869
716.89819	2.0934637	0.63480276	3592.8579
717.89917	2.0947256	0.63605404	3593.1794
718.90015	2.0993965	0.6372571	3591.908
719.90112	2.103519	0.63852686	3595.4324
720.9021	2.1066616	0.63985914	3593.6265
721.90308	2.1054192	0.64116216	3598.5051
722.90405	2.1116924	0.64261943	3599.8965
723.90503	2.1141119	0.64398414	3598.7195
724.90601	2.1156356	0.64543879	3596.3232
725.90698	2.1194925	0.64680409	3595.939
726.90796	2.1242588	0.64799923	3592.4197
727.90894	2.1255074	0.64934468	3603.2849
728.90991	2.1292698	0.65092623	3602.873
729.91089	2.129504	0.65231216	3597.583
730.91187	2.1338718	0.65367299	3604.7048
731.91284	2.1374116	0.65526259	3598.4612
732.91382	2.1425204	0.65671468	3610.3569
733.91479	2.1411819	0.65829581	3604.5618
734.91577	2.1474707	0.65990567	3604.666
735.91675	2.1490901	0.6614666	3600.2212
736.91772	2.1549668	0.66290933	3605.6904
737.9187	2.1548421	0.6643768	3603.9954
738.91968	2.1599991	0.66576713	3603.5046
739.92065	2.1633723	0.66709322	3601.2588
740.92163	2.1627779	0.66836441	3602.1924
741.92261	2.1661341	0.66997147	3604.4937
742.92358	2.1722462	0.67144692	3607.5554
743.92456	2.1725621	0.67298776	3608.3962
744.92554	2.1781554	0.67438704	3603.6321
745.92651	2.1785784	0.67577922	3609.1609
746.92749	2.1826911	0.67722487	3608.0417
747.92847	2.1836569	0.67887068	3610.1292
748.92944	2.1882982	0.68038011	3606.9336
749.93042	2.1942272	0.68207836	3610.0083
750.9314	2.1938193	0.68327874	3605.6182
751.93237	2.1971169	0.68472803	3610.7651
752.93335	2.1993487	0.68612814	3608.8176
753.93433	2.2045882	0.68754524	3601.3909
754.9353	2.2056899	0.68915164	3609.7661
755.93628	2.2091346	0.69096375	3616.7407
756.93726	2.2109587	0.69258803	3607.0352
757.93823	2.2151446	0.69401884	3606.501
758.93921	2.2191057	0.69546217	3608.0398
759.94019	2.2205729	0.6970216	3606.8521
760.94116	2.2236054	0.69848782	3608.9292
761.94214	2.2266583	0.70003414	3611.4026
762.94312	2.2296886	0.70130712	3604.1899
763.94409	2.2372305	0.70281923	3613.3384
764.94507	2.2354896	0.70431864	3609.9871
765.94604	2.2412584	0.70608652	3613.5071
766.94702	2.2427464	0.70748866	3608.6406
767.948	2.2447364	0.70913011	3614.8701
768.94897	2.2505555	0.71056563	3611.9983
769.94995	2.2526596	0.7121563	3609.9783
770.95093	2.2534142	0.71373504	3613.8013
771.9519	2.256871	0.71511668	3612.478
772.95288	2.2608221	0.71660811	3612.741
773.95386	2.2618055	0.7180537	3610.8606
774.95483	2.2673967	0.7194066	3614.4546
775.95581	2.2728317	0.72108477	3612.5791
776.95679	2.2735219	0.72310895	3620.6184
777.95776	2.2730784	0.72478122	3612.9819
778.95874	2.279238	0.72640425	3615.0786
779.95972	2.2782054	0.72802991	3615.562
780.96069	2.2843018	0.72966379	3612.8271
781.96167	2.2894249	0.73142523	3611.1536
782.96265	2.2917042	0.7328878	3613.1838
783.96362	2.2959623	0.73431683	3617.2146
784.9646	2.2942393	0.73569947	3605.4863
785.96558	2.2996068	0.73746085	3612.6396
786.96655	2.3043115	0.73911345	3619.1536
787.96753	2.3055189	0.74096268	3613.3208
788.96851	2.3082533	0.74247146	3611.8926
789.96948	2.3104584	0.74387199	3606.9727
790.97046	2.3176391	0.74554622	3619.7673
791.97144	2.3183515	0.74734801	3611.3301
792.97241	2.3202915	0.74893153	3611.8435
793.97339	2.3255489	0.75041443	3614.3562
794.97437	2.3277848	0.75221688	3616.7029
795.97534	2.3265302	0.75379211	3613.1926
796.97632	2.3332796	0.75551385	3614.6584
797.97729	2.3334389	0.75732142	3616.9604
798.97827	2.3358738	0.75903583	3613.4746
799.97925	2.3407922	0.76099592	3617.2097
800.98022	2.3468773	0.76282644	3616.8218
801.9812	2.3464079	0.76453227	3616.5249
802.98218	2.3488708	0.76624471	3615.0161
803.98315	2.3526659	0.76826775	3620.6594
804.98413	2.3547144	0.77012992	3613.927
805.98511	2.3620634	0.77216083	3617.637
806.98608	2.362561	0.77403963	3617.1328
807.98706	2.3646281	0.77559477	3609.1157
808.98804	2.3666191	0.77732617	3610.1814
809.98901	2.3726425	0.77906871	3620.0208
810.98999	2.3723342	0.78054917	3612.0125
811.99097	2.3783078	0.7825917	3620.7383
812.99194	2.3821926	0.78455579	3616.7473
813.99292	2.3842635	0.78615683	3614.6052
814.9939	2.3870819	0.78797233	3612.2231
815.99487	2.3907719	0.78971314	3621.4836
816.99585	2.3941777	0.79146934	3613.7715
817.99683	2.3973145	0.79372454	3618.7231
818.9978	2.396446	0.79556298	3612.9565
819.99878	2.4027159	0.79731292	3612.0706
820.99976	2.4045386	0.79903668	3610.0046
822.00073	2.4045384	0.800596	3608.5313
823.00171	2.4101946	0.80225462	3613.8928
824.00269	2.4177763	0.80418396	3623.1052
825.00366	2.4182105	0.80617177	3621.2422
826.00464	2.4213064	0.80805016	3616.2625
827.00562	2.4232979	0.80988663	3618.2595
828.00659	2.4272592	0.81178409	3617.4668
829.00757	2.4293404	0.81401455	3618.0601
830.00854	2.4304361	0.81598133	3613.6572
831.00952	2.4359503	0.81781751	3612.8481
832.0105	2.4408791	0.81953955	3612.3777
833.01147	2.4410806	0.82149017	3615.4265
834.01245	2.4432118	0.82351828	3614.5769
835.01343	2.4481463	0.8255496	3618.0334
836.0144	2.4500868	0.82788837	3617.6831
837.01538	2.4553158	0.82988006	3616.2268
838.01636	2.453896	0.83171868	3608.9341
839.01733	2.4586911	0.83358669	3610.0715
840.01831	2.4612989	0.83554012	3612.2722
841.01929	2.4657776	0.83771312	3614.5906
842.02026	2.4668491	0.84006888	3619.0686
843.02124	2.4719598	0.84209025	3609.585
844.02222	2.4739947	0.84386683	3609.8064
845.02319	2.4755297	0.84569335	3608.1704
846.02417	2.4823754	0.84731996	3609.123
847.02515	2.4822776	0.84947121	3611.4246
848.02612	2.4874475	0.85185808	3617.7847
849.0271	2.4869683	0.8540895	3609.9187
850.02808	2.49298	0.85639	3614.1404
851.02905	2.4942932	0.8587563	3610.4658
852.03003	2.4991186	0.86091363	3613.979
853.03101	2.5000417	0.86288577	3611.4812
854.03198	2.5041242	0.86466575	3607.8115
855.03296	2.5071037	0.86691916	3611.0422
856.03394	2.5072348	0.86910766	3607.3445
857.03491	2.51142	0.87121803	3611.2559
858.03589	2.5138845	0.87363255	3607.2231
859.03687	2.518991	0.87555689	3607.0454
860.03784	2.5222106	0.87736046	3603.5137
861.03882	2.5254939	0.87913209	3609.4592
862.03979	2.5288475	0.88148105	3610.8262
863.04077	2.528744	0.88352418	3608.4312
864.04175	2.5342162	0.88593072	3607.9722
865.04272	2.5346098	0.88807595	3603.9214
866.0437	2.5376379	0.89037329	3606.0466
867.04468	2.5432274	0.89295828	3607.4949
868.04565	2.547015	0.89500415	3597.4336
869.04663	2.5493174	0.8972488	3604.1709
870.04761	2.5531623	0.89956617	3601.1953
871.04858	2.557091	0.90175992	3605.467
872.04956	2.5572264	0.90387762	3601.4314
873.05054	2.5598483	0.90597975	3603.3276
874.05151	2.563827	0.90812403	3594.8071
875.05249	2.5667343	0.91052997	3602.7695
876.05347	2.5703151	0.91346318	3610.5557
877.05444	2.5693791	0.91619414	3603.8237
878.05542	2.5745404	0.91903669	3597.1589
879.0564	2.5774884	0.92141736	3596.6606
880.05737	2.5846357	0.92394346	3602.2559
881.05835	2.5865223	0.9266389	3602.2263
882.05933	2.5877285	0.92911464	3594.5244
883.0603	2.592459	0.93157923	3597.0229
884.06128	2.5919096	0.93390316	3592.4731
885.06226	2.6006408	0.9362222	3597.2151
886.06323	2.601331	0.93836331	3590.3325
887.06421	2.6025217	0.94046724	3592.1941
888.06519	2.6041436	0.94280761	3594.647
889.06616	2.6116281	0.94498664	3597.8125
890.06714	2.6140854	0.94752735	3595.6621
891.06812	2.6145785	0.95025235	3595.9321
892.06909	2.6191571	0.95305425	3594.2605
893.07007	2.6208868	0.95544189	3587.2712
894.07104	2.6240151	0.95783871	3587.1213
895.07202	2.6272759	0.9599995	3586.824
896.073	2.6331522	0.96245402	3589.4629
897.07397	2.6346397	0.96491736	3588.1885
898.07495	2.6382325	0.96763229	3591.2292
899.07593	2.6385758	0.97037417	3588.6812
900.0769	2.6422403	0.97295439	3584.1306
901.07788	2.6450098	0.97533965	3582.709
902.07886	2.6509955	0.97818744	3585.3896
903.07983	2.6532493	0.98086739	3583.7554
904.08081	2.6540902	0.98335743	3578.073
905.08179	2.6579068	0.98606837	3581.6016
906.08276	2.6652699	0.98882371	3581.3306
907.08374	2.6635463	0.99146736	3578.5815
908.08472	2.6644228	0.99426913	3578.0581
909.08569	2.6693161	0.99702883	3580.1499
910.08667	2.6726651	0.99991244	3571.5439
911.08765	2.6763771	1.002685	3575.2209
912.08862	2.6787603	1.0055101	3578.2925
913.0896	2.6832917	1.0083416	3571.4871
914.09058	2.6853583	1.0109991	3571.2898
915.09155	2.6876161	1.0134176	3566.9536
916.09253	2.6900001	1.0159767	3567.657
917.09351	2.6903627	1.0187005	3564.1392
918.09448	2.6982069	1.0218346	3569.5103
919.09546	2.6966758	1.0250462	3565.1982
920.09644	2.7031054	1.0284801	3557.8259
921.09741	2.7065833	1.0311183	3558.447
922.09839	2.7074518	1.0335661	3556.9946
923.09937	2.7104247	1.0361295	3558.3022
924.10034	2.7179143	1.0391645	3555.5999
925.10132	2.7177913	1.0416352	3556.0422
926.10229	2.721199	1.0444789	3553.3196
927.10327	2.7222056	1.0473319	3554.2629
928.10425	2.725189	1.050069	3548.0696
929.10522	2.7296743	1.0533344	3556.9807
930.1062	2.7298176	1.0565929	3543.677
931.10718	2.7352669	1.0591931	3543.6299
932.10815	2.7400956	1.0620329	3546.9919
933.10913	2.7390924	1.064769	3544.0493
934.11011	2.7432771	1.0676134	3540.9905
935.11108	2.7487934	1.0704985	3540.5938
936.11206	2.7514782	1.0731169	3538.873
937.11304	2.7542372	1.0761119	3539.4277
938.11401	2.7531159	1.0794213	3535.6272
939.11499	2.7592666	1.0825232	3528.605
940.11597	2.764008	1.0852189	3527.4685
941.11694	2.7648869	1.0882181	3525.762
942.11792	2.7686079	1.0911009	3523.5374
943.1189	2.7699661	1.0938392	3524.7244
944.11987	2.7733407	1.0969887	3521.1484
945.12085	2.77913	1.0999837	3524.5774
946.12183	2.7778447	1.1029452	3520.7241
947.1228	2.7820842	1.1055276	3514.8989
948.12378	2.7872243	1.108222	3517.9873
949.12476	2.7877896	1.1118051	3515.6777
950.12573	2.7931776	1.1151072	3516.4021
951.12671	2.7966459	1.1180469	3508.5093
952.12769	2.7982421	1.1206512	3504.8359
953.12866	2.8024082	1.1232653	3499.1035
954.12964	2.8049777	1.1259289	3507.7375
955.13062	2.8076253	1.1289719	3503.7126
956.13159	2.8111539	1.13262	3500.9419
957.13257	2.8130963	1.1359569	3490.6033
958.13354	2.8173041	1.1385936	3494.5444
959.13452	2.8183017	1.1420492	3493.6938
960.1355	2.8224289	1.1457326	3485.7183
961.13647	2.8237929	1.1487988	3488.8206
962.13745	2.8272045	1.1518351	3484.2671
963.13843	2.8360772	1.1544664	3482.7668
964.1394	2.8365722	1.1572895	3477.6921
965.14038	2.840703	1.1600955	3484.0593
966.14136	2.8424513	1.1632107	3481.5764
967.14233	2.8399348	1.1657348	3467.2727
968.14331	2.8466713	1.1681262	3472.1326
969.14429	2.849504	1.1712676	3471.4167
970.14526	2.8542991	1.1746751	3469.1492
971.14624	2.8554871	1.1778349	3465.8745
972.14722	2.8586028	1.1813397	3460.1963
973.14819	2.8617272	1.1848387	3458.5352
974.14917	2.8658454	1.1877238	3458.3647
975.15015	2.8697205	1.1911225	3456.2478
976.15112	2.8695128	1.1940576	3446.3828
977.1521	2.8716109	1.1970377	3443.6128
978.15308	2.8776157	1.1999352	3446.9722
979.15405	2.8816466	1.2028018	3449.8647
980.15503	2.8838844	1.2062776	3438.9089
981.15601	2.8864315	1.209452	3438.6887
982.15698	2.8871129	1.2129188	3438.73
983.15796	2.8899784	1.2163286	3426.6887
984.15894	2.8946233	1.2199777	3429.6282
985.15991	2.8959649	1.2230101	3421.4038
986.16089	2.8961177	1.2259703	3420.135
987.16187	2.9049702	1.2288229	3414.7935
988.16284	2.9050615	1.2318324	3411.7412
989.16382	2.9087012	1.2351786	3415.3584
990.16479	2.9112298	1.2388444	3411.9087
991.16577	2.9195285	1.2418507	3402.9861
992.16675	2.9161003	1.2450298	3400.0554
993.16772	2.9233968	1.2482167	3399.3464
994.1687	2.9255219	1.2511811	3399.5122
995.16968	2.9300547	1.2540294	3390.8132
996.17065	2.9322655	1.2576514	3397.7
997.17163	2.9353073	1.2611409	3387.488
998.17261	2.9360349	1.2643702	3383.9856
999.17358	2.9403281	1.2673572	3381.064
1000.1746	2.945493	1.2713501	3383.5796
1001.1755	2.9441719	1.2744424	3367.5862
1002.1765	2.9493265	1.2769057	3360.7859
1003.1775	2.9531333	1.2797015	3370.6396
1004.1785	2.9542634	1.2830002	3361.8149
1005.1794	2.9576395	1.2855577	3357.436
1006.1804	2.9608417	1.288426	3359.2327
1007.1814	2.9632964	1.2917383	3353.5515
1008.1824	2.9650452	1.2946587	3346.7156
1009.1833	2.968513	1.2978306	3347.6802
1010.1843	2.968981	1.3018984	3345.1309
1011.1853	2.9746811	1.305797	3334.4373
1012.1863	2.979811	1.3087095	3327.7405
1013.1873	2.9809861	1.3109864	3323.5532
1014.1882	2.9865181	1.3132205	3331.1301
1015.1892	2.990356	1.3154178	3328.0999
1016.1902	2.9905941	1.3177276	3322.8965
1017.1912	2.9958956	1.3207777	3321.2903
1018.1921	2.9973145	1.3236407	3317.4148
1019.1931	3.0009975	1.3271725	3313.5288
1020.1941	3.0012922	1.3308976	3311.1155
1021.1951	3.0064726	1.3346546	3307.8855
1022.196	3.0094903	1.3384976	3299.6733
1023.197	3.0104947	1.3416849	3289.8992
1024.198	3.012764	1.3447955	3287.9753
1025.199	3.0200694	1.3481976	3287.2102
1026.2	3.0207868	1.3515795	3282.7273
1027.2009	3.0269179	1.3546805	3280.1538
1028.2019	3.0256615	1.3580563	3273.6396
1029.2029	3.0283303	1.3615117	3272.845
1030.2039	3.0359852	1.3654735	3269.6702
1031.2048	3.0404217	1.3685429	3261.5466
1032.2058	3.0379751	1.3716702	3255.1401
1033.2068	3.0443225	1.3754715	3251.3025
1034.2078	3.0478802	1.3789822	3246.2776
1035.2087	3.0476849	1.3820933	3237.4585
1036.2097	3.05093	1.3851447	3237.78
1037.2107	3.0528934	1.3880543	3231.8118
1038.2117	3.0565238	1.3915515	3231.9414
1039.2126	3.0590355	1.395786	3223.9683
1040.2136	3.0638478	1.3991209	3218.4434
1041.2146	3.0650003	1.4023371	3214.6707
1042.2156	3.0686502	1.4056442	3205.1914
1043.2166	3.0721514	1.4083589	3199.5986
1044.2175	3.0757649	1.411155	3196.5625
1045.2185	3.0773146	1.4141939	3196.9189
1046.2195	3.0812347	1.4185543	3198.5483
1047.2205	3.0835338	1.4224383	3185.0205
1048.2214	3.0889463	1.4256378	3178.2859
1049.2224	3.0901563	1.4289507	3175.1555
1050.2234	3.0912988	1.4326322	3168.7195
1051.2244	3.0982218	1.4367127	3160.5981
1052.2253	3.1018479	1.4403433	3162.8472
1053.2263	3.1037531	1.4433811	3157.459
1054.2273	3.1037059	1.4467312	3146.283
1055.2283	3.1063654	1.4502817	3142.7266
1056.2292	3.1131427	1.4534813	3137.3301
1057.2302	3.1174433	1.4572015	3139.5051
1058.2312	3.1156871	1.4610872	3122.5676
1059.2322	3.1202719	1.4640255	3116.5671
1060.2332	3.1211882	1.4674515	3116.2354
1061.2341	3.1279981	1.4709985	3111.2854
1062.2351	3.1277492	1.4741685	3102.5664
1063.2361	3.1294625	1.4775236	3097.0757
1064.2371	3.1369245	1.4808358	3092.0881
1065.238	3.1382463	1.4843748	3088.2146
1066.239	3.1398811	1.4879984	3082.4119
1067.24	3.1449943	1.4910647	3074.7244
1068.241	3.1468983	1.4941807	3064.5027
1069.2419	3.1510544	1.4974178	3064.4719
1070.2429	3.1550825	1.5012207	3066.0459
1071.2439	3.1534824	1.5047444	3050.3293
1072.2449	3.1591499	1.5087956	3038.3872
1073.2458	3.1586916	1.512906	3037.7588
1074.2468	3.1640551	1.5161227	3028.551
1075.2478	3.1668332	1.5195284	3026.5413
1076.2488	3.1706398	1.5232464	3012.1721
1077.2498	3.1757839	1.5267993	3009.1321
1078.2507	3.1781268	1.5300386	3002.5542
1079.2517	3.1800363	1.5332918	3000.0759
1080.2527	3.1845295	1.5370767	2994.9141
1081.2537	3.1878283	1.5405285	2991.0684
1082.2546	3.1902673	1.5444216	2978.9258
1083.2556	3.1944366	1.5475367	2968.9485
1084.2566	3.1979797	1.5511739	2974.1304
1085.2576	3.1980364	1.5551543	2961.5049
1086.2585	3.2015445	1.5589464	2948.8962
1087.2595	3.2047715	1.5624	2938.5073
1088.2605	3.2106738	1.5655565	2935.356
1089.2615	3.2100861	1.5687295	2928.8484
1090.2625	3.2146697	1.5726274	2928.7307
1091.2634	3.2138166	1.5768913	2910.7107
1092.2644	3.2199757	1.5811759	2908.2295
1093.2654	3.221909	1.5852368	2900.3
1094.2664	3.2246296	1.5884984	2887.2473
1095.2673	3.2292709	1.5915776	2882.0105
1096.2683	3.2314692	1.5952649	2881.3008
1097.2693	3.2356789	1.5992683	2868.7471
1098.2703	3.2374454	1.6033415	2856.6829
1099.2712	3.2398672	1.606939	2848.3481
1100.2722	3.2436419	1.6107354	2844.5999
1101.2732	3.2481852	1.6147248	2833.395
1102.2742	3.249922	1.6181682	2832.448
1103.2751	3.2526059	1.6216689	2817.6042
1104.2761	3.2571023	1.6255554	2813.1221
1105.2771	3.2583382	1.6294714	2801.3528
1106.2781	3.2619922	1.6335953	2790.4336
1107.2791	3.2651894	1.6375419	2779.9775
1108.28	3.2708752	1.6412957	2777.5894
1109.281	3.2711332	1.6452563	2763.4236
1110.282	3.2745481	1.6490084	2745.1057
1111.283	3.2762561	1.6527925	2738.2563
1112.2839	3.276737	1.6565065	2728.7686
1113.2849	3.2838907	1.6602032	2723.2156
1114.2859	3.2857964	1.6634101	2715.5132
1115.2869	3.2884912	1.6671432	2712.002
1116.2878	3.2930391	1.6713974	2697.5701
1117.2888	3.2992725	1.6754926	2688.7732
1118.2898	3.2995293	1.6794482	2673.9521
1119.2908	3.3017623	1.6829333	2662.2649
1120.2917	3.3070612	1.6868358	2657.9526
1121.2927	3.3059425	1.6905075	2641.7424
1122.2937	3.3078833	1.6940105	2633.3745
1123.2947	3.31354	1.6983287	2627.9287
1124.2957	3.317498	1.7028461	2615.1289
1125.2966	3.3168004	1.7067082	2592.2385
1126.2976	3.3206234	1.7106371	2585.614
1127.2986	3.3257904	1.7156485	2571.7388
1128.2996	3.3273447	1.7204947	2548.3298
1129.3005	3.3329403	1.7243446	2534.5757
1130.3015	3.3321259	1.7289126	2507.6682
1131.3025	3.3359468	1.7342316	2492.3816
1132.3035	3.3439119	1.7404671	2458.5825
1133.0042	3.3424852	1.7484391	2407.1851