File: datasets/am_bench_2022/raw_data/90-X.08-3/specimen.dat
MTS793|MPT|ENU|1|2|.|/|:|1|0|0|A

Operator Information						Time:	16.66626	Sec	11/2/2021 11:07:36 AM
Operator	Nick Derimow
Project	AM Bench 2022 mini-tensile challenge
Specimen ID	90-X.08-3
Material	PBF-L Inconel 625
Specimen Width	2.54	mm
Specimen Thickness	1.5	mm
Notes
Operator Information End

Data Acquisition						Time:	1017.6604	Sec	11/2/2021 11:24:17 AM
Time	Axial Displacement	Axial Extensometer	Axial Force
Sec	mm	mm	N
16.780273	0.0034750353	0.00019473644	35.48851
17.681152	0.0013612265	0.00034133898	47.611835
18.582031	0.0063863313	0.00041089026	63.070915
19.48291	0.009406168	0.00045954366	72.118523
20.383789	0.010054033	0.00048652678	83.043358
21.284668	0.016387315	0.00046834885	92.249107
22.185547	0.016831109	0.00054485514	103.5963
23.086426	0.016756734	0.00053823309	112.73828
23.987305	0.021554871	0.00060386269	123.27513
24.888184	0.022735605	0.00074171129	138.646
25.789063	0.027619541	0.00081272243	146.9727
26.689941	0.029841121	0.00081173482	163.67139
27.59082	0.034823455	0.00099705253	179.58142
28.491699	0.033921525	0.00098299701	184.76254
29.392578	0.036175888	0.0010014854	201.74911
30.293457	0.041809317	0.001118638	219.03569
31.194336	0.042046376	0.0012452872	233.18481
32.095215	0.046612523	0.0012690863	251.98781
32.996094	0.048615742	0.0014379401	264.99863
33.896973	0.052645691	0.001435592	283.81717
34.797852	0.052452888	0.001599179	300.1062
35.69873	0.055485837	0.0016369363	317.2023
36.599609	0.060276754	0.0017103764	338.32181
37.500488	0.059977408	0.0018402752	355.90939
38.401367	0.065473348	0.0018790938	373.79117
39.302246	0.068305306	0.0020007037	389.14722
40.203125	0.070810251	0.0021438468	414.91708
41.104004	0.072132207	0.0021847307	429.83685
42.004883	0.074423298	0.0023688509	451.84375
42.905762	0.075482376	0.0024725995	474.763
43.806641	0.081276998	0.0026471021	500.67477
44.70752	0.079538144	0.0026838267	518.58496
45.608398	0.0845716	0.0028297028	543.63837
46.509277	0.087005086	0.0029187065	566.21594
47.410156	0.088955238	0.0030595353	585.8562
48.311035	0.09242215	0.0031488738	608.36652
49.211914	0.09412761	0.0032950256	630.39771
50.112793	0.10127702	0.0034837569	661.07391
51.013672	0.098451778	0.0035045573	675.48584
51.914551	0.10316858	0.0036861328	706.18494
52.81543	0.10762239	0.0038277975	734.4718
53.716309	0.11171032	0.0038827984	747.60425
54.617188	0.11172856	0.0039433795	768.758
55.518066	0.11248768	0.004148785	793.73401
56.418945	0.11849401	0.0044003758	829.94769
57.319824	0.11897407	0.0044667758	848.42828
58.220703	0.12058754	0.0046034777	876.91321
59.121582	0.12476255	0.0048293588	908.32318
60.022461	0.1271487	0.004835018	924.80432
60.92334	0.132366	0.005045475	955.99176
61.824219	0.13388583	0.0051951874	979.08099
62.725098	0.13407351	0.0052523757	1010.3735
63.625977	0.13861303	0.0053610285	1030.7097
64.526855	0.14085761	0.0056420905	1060.4498
65.427734	0.14309563	0.0057701454	1082.3214
66.328613	0.14481461	0.0058598784	1096.9581
67.229492	0.1473337	0.005941167	1122.724
68.130371	0.15037361	0.0060742334	1149.6112
69.03125	0.15417741	0.0062186066	1168.7694
69.932129	0.15710977	0.0063571846	1193.7217
70.833008	0.15943241	0.0065129981	1219.2084
71.733887	0.16103931	0.0065488662	1241.9998
72.634766	0.16390404	0.0067232675	1270.9058
73.535645	0.16897018	0.0068963654	1295.9507
74.436523	0.17108522	0.0070366533	1325.0276
75.337402	0.17423065	0.0071643516	1349.2031
76.238281	0.17848353	0.0073507512	1374.5309
77.13916	0.18015298	0.0075789569	1398.1033
78.040039	0.18452202	0.0076221591	1422.8201
78.940918	0.18524037	0.0077826316	1447.634
79.841797	0.18571961	0.007919779	1473.5853
80.742676	0.1893996	0.008055158	1500.8165
81.643555	0.19302715	0.0082891565	1531.1321
82.544434	0.19419461	0.0084095746	1552.3142
83.445313	0.19714259	0.008506692	1575.4974
84.346191	0.19985078	0.0087923994	1607.3151
85.24707	0.20199144	0.0087950146	1625.6359
86.147949	0.20571733	0.0089449035	1649.0594
87.048828	0.208904	0.0089839511	1674.688
87.949707	0.21160646	0.009196654	1703.3665
88.850586	0.21379367	0.0091642123	1718.6615
89.751465	0.21709932	0.0094720079	1744.6116
90.652344	0.22031073	0.0096003786	1766.9257
91.553223	0.22535633	0.0096889483	1785.6466
92.454102	0.22436814	0.0098508634	1808.0408
93.35498	0.22686493	0.010010648	1833.8776
94.255859	0.23180681	0.010173579	1859.0398
95.156738	0.22980569	0.010210459	1876.2091
96.057617	0.23559934	0.010432017	1906.7739
96.958496	0.24141118	0.010569482	1925.005
97.859375	0.24116878	0.010660231	1948.522
98.760254	0.24215554	0.010825981	1968.0405
99.661133	0.24792194	0.010932303	1992.4342
100.56201	0.24851264	0.011108617	2005.8481
101.46289	0.25276366	0.011207791	2030.2877
102.36377	0.25724375	0.01129055	2044.6589
103.26465	0.25594392	0.01134301	2062.7117
104.16553	0.26082888	0.01154796	2085.6985
105.06641	0.26219326	0.011700758	2103.7234
105.96729	0.26588762	0.011857408	2123.939
106.86816	0.26912379	0.011991511	2141.1545
107.76904	0.27429417	0.011962441	2156.2183
108.66992	0.27214283	0.012247494	2179.0967
109.5708	0.27923384	0.012314477	2198.769
110.47168	0.27851981	0.012471258	2209.6775
111.37256	0.28400981	0.012401383	2221.1453
112.27344	0.28738472	0.012586712	2238.6492
113.17432	0.28730932	0.012684128	2257.0757
114.0752	0.29222357	0.012931496	2278.896
114.97607	0.29477832	0.013028923	2292.1628
115.87695	0.29684585	0.013066361	2302.4856
116.77783	0.29861134	0.013178218	2315.8945
117.67871	0.30235019	0.013391707	2329.7778
118.57959	0.30479881	0.013575369	2348.3154
119.48047	0.30859271	0.01362022	2354.9678
120.38135	0.30842471	0.013665229	2362.9805
121.28223	0.30985096	0.013774337	2373.6172
122.18311	0.31257248	0.013917853	2391.5601
123.08398	0.31792381	0.014039189	2402.1277
123.98486	0.32243991	0.014156893	2419.3538
124.88574	0.32438517	0.014289432	2422.4148
125.78662	0.32526919	0.014374943	2430.3298
126.6875	0.33097684	0.014551615	2445.5369
127.58838	0.33202872	0.014602419	2455.6023
128.48926	0.33443412	0.014740145	2464.5649
129.39014	0.33813769	0.014916763	2478.1682
130.29102	0.33926025	0.014985044	2483.3115
131.19189	0.34422925	0.015106101	2497.0425
132.09277	0.34596607	0.015314202	2507.1501
132.99365	0.34664139	0.015473519	2508.6035
133.89453	0.35243046	0.015479613	2513.1582
134.79541	0.3545005	0.015651669	2531.3245
135.69629	0.35686472	0.015786171	2543.4958
136.59717	0.35642749	0.015984893	2554.6265
137.49805	0.36258414	0.016314603	2567.4456
138.39893	0.36501518	0.016386619	2566.5068
139.2998	0.36623138	0.016597066	2580.1018
140.20068	0.36887038	0.016726397	2577.6311
141.10156	0.374093	0.016917344	2591.5825
142.00244	0.37369961	0.016995702	2586.9907
142.90332	0.377422	0.01717986	2600.4912
143.8042	0.3807258	0.017457865	2612.7913
144.70508	0.38102412	0.01769568	2615.324
145.60596	0.38563147	0.017880481	2625.5046
146.50684	0.38971654	0.018263562	2642.8774
147.40771	0.39198789	0.018522115	2643.4084
148.30859	0.39468572	0.018998796	2651.1335
149.20947	0.39628077	0.019156728	2649.9958
150.11035	0.40100572	0.019537361	2659.8481
151.01123	0.40026996	0.019890361	2663.1697
151.91211	0.40382928	0.020252058	2672.855
152.81299	0.40896583	0.020632312	2678.6724
153.71387	0.41135508	0.021027902	2689.1665
154.61475	0.41371045	0.021594882	2691.5198
155.51563	0.41394749	0.022057308	2701.709
156.4165	0.41871443	0.022574099	2703.8782
157.31738	0.42094401	0.023084825	2708.4927
158.21826	0.42610925	0.023623722	2721.4426
159.11914	0.4258472	0.024235504	2722.4165
160.02002	0.43279374	0.02473546	2725.8975
160.9209	0.43417183	0.025302498	2734.2405
161.82178	0.43585604	0.02605905	2741.2593
162.72266	0.43781418	0.026674038	2742.2385
163.62354	0.44210064	0.027291352	2749.6121
164.52441	0.4425202	0.028131973	2755.4456
165.42529	0.44603384	0.02872381	2755.1123
166.32617	0.44986591	0.029496359	2763.8367
167.22705	0.45049411	0.030331386	2769.7834
168.12793	0.45579207	0.030919746	2771.8992
169.02881	0.45748508	0.031520657	2776.3972
169.92969	0.45931163	0.032246623	2776.1851
170.83057	0.46122777	0.032993127	2782.8372
171.73145	0.4640395	0.033681463	2784.8003
172.63232	0.46867839	0.03443059	2784.2383
173.5332	0.47021154	0.035045523	2792.5793
174.43408	0.47124419	0.035674896	2790.9675
175.33496	0.47426894	0.036546536	2798.5178
176.23584	0.47682679	0.03738654	2806.3743
177.13672	0.4819105	0.038209938	2815.9441
178.0376	0.48314553	0.039179061	2815.9531
178.93848	0.48555955	0.03994808	2817.5432
179.83936	0.48985013	0.04091423	2821.0762
180.74023	0.49179107	0.04163935	2821.2615
181.64111	0.49449456	0.042402122	2827.1553
182.54199	0.49922481	0.043210689	2830.2498
183.44287	0.50013757	0.044079725	2840.9631
184.34375	0.49993286	0.044881508	2839.5229
185.24463	0.50481749	0.045543104	2839.4133
186.14551	0.5064621	0.046431664	2853.2795
187.04639	0.51032937	0.047233496	2848.8413
187.94727	0.5161441	0.048243802	2858.8318
188.84814	0.51373047	0.049024843	2852.9272
189.74902	0.5193693	0.050070632	2868.2891
190.6499	0.52202994	0.050980013	2867.1416
191.55078	0.5249787	0.051908676	2867.1196
192.45166	0.52660322	0.052920826	2869.3176
193.35254	0.52781349	0.053805321	2875.0889
194.25342	0.53508854	0.054847755	2880.5732
195.1543	0.53546083	0.055793814	2881.4509
196.05518	0.53677577	0.056641303	2878.114
196.95605	0.53944159	0.057416543	2882.9727
197.85693	0.54255998	0.058155634	2885.6724
198.75781	0.548823	0.059079476	2892.9961
199.65869	0.55139828	0.059980974	2902.6023
200.55957	0.55122125	0.06116331	2904.0691
201.46045	0.55559766	0.062332928	2901.9832
202.36133	0.5573349	0.06306351	2901.3801
203.26221	0.55957848	0.063847303	2907.9392
204.16309	0.56352496	0.064740561	2908.7893
205.06396	0.56692183	0.065635271	2909.8018
205.96484	0.56769508	0.066600494	2918.4546
206.86572	0.56879926	0.067462042	2917.1782
207.7666	0.57422388	0.068429425	2924.6082
208.66748	0.57464433	0.069538027	2921.791
209.56836	0.57582283	0.070431888	2928.3491
210.46924	0.57945549	0.071440309	2935.5796
211.37012	0.5857501	0.072379582	2935.9485
212.271	0.5892908	0.073297851	2932.3911
213.17188	0.58679479	0.07397303	2930.4333
214.07275	0.59338653	0.074811995	2943.0818
214.97363	0.59584105	0.07574483	2942.2395
215.87451	0.5988062	0.076734036	2951.3887
216.77539	0.60030621	0.077718899	2948.6514
217.67627	0.60454822	0.078602128	2947.1626
218.57715	0.60719615	0.079493001	2958.552
219.47803	0.60589063	0.080443464	2954.1528
220.37891	0.61408639	0.081264682	2959.7532
221.27979	0.61417902	0.082109988	2960.3081
222.18066	0.61592549	0.083126351	2967.5706
223.08154	0.62040985	0.084279783	2973.2556
223.98242	0.62059402	0.085250653	2973.9424
224.8833	0.62573004	0.086422458	2974.4431
225.78418	0.62539649	0.087522514	2977.8955
226.68506	0.63082129	0.08842618	2978.8159
227.58594	0.63205367	0.089398712	2979.9812
228.48682	0.63453221	0.090227976	2978.9863
229.3877	0.6382485	0.091200076	2988.8733
230.28857	0.64025235	0.092082441	2984.3174
231.18945	0.64317751	0.093171708	2994.4836
232.09033	0.64416891	0.09441182	2997.2766
232.99121	0.65059489	0.095605902	3003.387
233.89209	0.65159434	0.096469112	2994.709
234.79297	0.65360659	0.097323559	3000.5393
235.69385	0.65534788	0.098319761	3001.0437
236.59473	0.65991181	0.09922453	3007.9006
237.49561	0.65898424	0.10020278	3006.6584
238.39648	0.66497666	0.10120033	3008.3997
239.29736	0.66650432	0.10220199	3011.8206
240.19824	0.67344528	0.10318628	3019.7192
241.09912	0.6723606	0.10397281	3014.0464
242	0.67518479	0.10504694	3017.8394
242.90088	0.68029493	0.10607527	3020.4014
243.80176	0.68067217	0.10715339	3024.8889
244.70264	0.68280995	0.10816904	3028.657
245.60352	0.68601704	0.10924742	3034.3643
246.50439	0.69022506	0.11015748	3030.8545
247.40527	0.69049549	0.11122806	3031.698
248.30615	0.694094	0.11207712	3035.6191
249.20703	0.70026171	0.1128801	3033.7439
250.10791	0.70316702	0.11377089	3047.0537
251.00879	0.70035905	0.11494936	3048.7
251.90967	0.70594555	0.11608995	3050.147
252.81055	0.70831877	0.11717796	3047.7319
253.71143	0.71085078	0.11818268	3048.8599
254.6123	0.7140376	0.11916289	3055.4321
255.51318	0.71741748	0.12016647	3055.8452
256.41406	0.72053468	0.1213219	3064.8115
257.31494	0.71907133	0.12228483	3056.104
258.21582	0.72452664	0.12323474	3059.0581
259.1167	0.72816896	0.12403087	3066.6914
260.01758	0.73104459	0.12510835	3064.8711
260.91846	0.73407555	0.12611236	3065.7168
261.81934	0.73837775	0.1270459	3075.1179
262.72021	0.73530954	0.12800358	3070.4072
263.62109	0.73964828	0.12882981	3072.7341
264.52197	0.74478322	0.13003409	3076.4287
265.42285	0.74906248	0.13086933	3077.9788
266.32373	0.7483083	0.13211691	3084.6221
267.22461	0.75156397	0.133414	3087.0476
268.12549	0.75346166	0.13445282	3085.0693
269.02637	0.75461555	0.13549356	3090.9619
269.92725	0.75896806	0.13643344	3089.2615
270.82813	0.7630263	0.13753085	3095.2439
271.729	0.76429397	0.13845274	3097.866
272.62988	0.76444519	0.13940492	3096.0029
273.53076	0.7729224	0.14061108	3098.5542
274.43164	0.77011073	0.14141262	3094.3066
275.33252	0.77611417	0.14247607	3107.6799
276.2334	0.77839392	0.14342982	3105.7651
277.13428	0.78461337	0.14440776	3116.3025
278.03516	0.78529483	0.14557372	3114.4351
278.93604	0.78785002	0.14662738	3111.1497
279.83691	0.78832364	0.14765923	3119.7322
280.73779	0.79213971	0.14863555	3113.033
281.63867	0.79485714	0.14958529	3117.8735
282.53955	0.79597789	0.15054476	3118.4031
283.44043	0.79994804	0.15169378	3124.4412
284.34131	0.8037346	0.15231475	3113.2302
285.24219	0.80818909	0.15328373	3127.6301
286.14307	0.80930096	0.15424447	3126.6667
287.04395	0.81084341	0.15519127	3123.7869
287.94482	0.8132062	0.15627398	3135.0474
288.8457	0.81505525	0.15726709	3134.0957
289.74658	0.81929219	0.15817818	3132.9556
290.64746	0.82268512	0.15899973	3131.4048
291.54834	0.82280457	0.15990564	3136.3887
292.44922	0.83023632	0.16088523	3141.0271
293.3501	0.83194447	0.16193028	3141.5457
294.25098	0.8310315	0.16281074	3144.2554
295.15186	0.83583158	0.16375823	3143.95
296.05273	0.83647412	0.16489351	3149.9993
296.95361	0.83946329	0.1660255	3147.1755
297.85449	0.8460834	0.16697487	3151.2292
298.75537	0.84459347	0.1680399	3153.853
299.65625	0.84909153	0.16908029	3155.9067
300.55713	0.85105789	0.16992866	3151.2231
301.45801	0.85642064	0.17109829	3164.7908
302.35889	0.8582983	0.17210364	3164.2563
303.25977	0.85867238	0.17295857	3159.0696
304.16064	0.86298567	0.1740763	3165.9495
305.06152	0.86819297	0.17520748	3172.4102
305.9624	0.87153345	0.17633468	3172.1758
306.86328	0.87105423	0.1772476	3170.6189
307.76416	0.87494606	0.17837052	3172.1062
308.66504	0.87602419	0.17943662	3172.7986
309.56592	0.87942189	0.18045828	3177.8508
310.4668	0.87852651	0.1814823	3180.4102
311.36768	0.88144088	0.18256266	3179.823
312.26855	0.88624221	0.18376352	3186.2229
313.16943	0.89013714	0.18491781	3190.2083
314.07031	0.89231837	0.18571241	3179.4736
314.97119	0.89213294	0.18665408	3186.3713
315.87207	0.89871502	0.18775481	3190.1858
316.77295	0.89845276	0.1885142	3186.5725
317.67383	0.90282381	0.1895031	3190.085
318.57471	0.9060154	0.19039692	3196.4004
319.47559	0.90455413	0.19160229	3193.5889
320.37646	0.91160393	0.19250008	3197.8748
321.27734	0.91418242	0.19364266	3201.51
322.17822	0.91588891	0.19475487	3209.4324
323.0791	0.92176461	0.19566116	3210.5083
323.97998	0.9205631	0.19656204	3202.4414
324.88086	0.92593729	0.19761032	3211.7808
325.78174	0.92545462	0.19884707	3213.2593
326.68262	0.93064481	0.19973262	3209.9199
327.5835	0.93132794	0.20071568	3216.7676
328.48438	0.93591172	0.20165646	3212.2722
329.38525	0.93582529	0.20257421	3214.509
330.28613	0.9423731	0.20359594	3219.9553
331.18701	0.9439972	0.20476627	3215.9895
332.08789	0.94524539	0.2057623	3225.2144
332.98877	0.95222783	0.20675097	3223.4299
333.88965	0.95386934	0.20785293	3231.8142
334.79053	0.95430517	0.20891902	3231.2881
335.69141	0.95522553	0.20980331	3228.4746
336.59229	0.95902067	0.21084204	3232.7678
337.49316	0.96455842	0.21201105	3241.229
338.39404	0.9637602	0.21290992	3237.0752
339.29492	0.96766716	0.21416558	3243.3984
340.1958	0.97096753	0.21512003	3233.8289
341.09668	0.97169137	0.21617009	3237.4719
341.99756	0.97803229	0.21733768	3245.1929
342.89844	0.97718835	0.21834311	3243.5864
343.79932	0.98157442	0.21910794	3240.4856
344.7002	0.9835065	0.22002815	3242.387
345.60107	0.98883551	0.22099265	3248.7632
346.50195	0.98919654	0.22190195	3249.604
347.40283	0.99428099	0.22289211	3259.0225
348.30371	0.99476594	0.22390297	3255.8613
349.20459	0.99832612	0.22478712	3253.3796
350.10547	1.0017906	0.22596401	3259.7559
351.00635	1.0058845	0.22691335	3257.8955
351.90723	1.0054989	0.22805037	3264.9082
352.80811	1.0088975	0.22912949	3263.7173
353.70898	1.0111839	0.22994164	3254.3276
354.60986	1.017073	0.23077272	3258.7966
355.51074	1.0174676	0.23166847	3265.4326
356.41162	1.0169849	0.23240733	3260.6807
357.3125	1.0227898	0.23345183	3276.907
358.21338	1.0241154	0.23453291	3275.0784
359.11426	1.0269605	0.2355544	3273.2307
360.01514	1.0327494	0.23661207	3280.4346
360.91602	1.0319771	0.2376727	3276.9146
361.81689	1.033254	0.23866579	3279.6594
362.71777	1.0381527	0.23962642	3275.5166
363.61865	1.0405306	0.24067611	3282.9016
364.51953	1.0433686	0.24180296	3285.6448
365.42041	1.0474709	0.2429207	3282.0889
366.32129	1.0498778	0.2437599	3287.1194
367.22217	1.0530449	0.24476518	3283.1594
368.12305	1.0582253	0.24562372	3290.0513
369.02393	1.0575953	0.24675532	3297.499
369.9248	1.0600693	0.24769428	3290.2593
370.82568	1.0660866	0.24855389	3296.718
371.72656	1.0667531	0.24941397	3295.4858
372.62744	1.0708487	0.25053531	3310.7017
373.52832	1.0706697	0.2515415	3297.3562
374.4292	1.0749586	0.2526716	3302.8569
375.33008	1.0780032	0.25388414	3308.031
376.23096	1.0808233	0.25483635	3305.2341
377.13184	1.081426	0.25581837	3310.2126
378.03271	1.0833405	0.25684732	3303.2725
378.93359	1.0863795	0.25793758	3307.2205
379.83447	1.0886557	0.25899825	3312.7627
380.73535	1.0952458	0.26000097	3309.114
381.63623	1.096735	0.26105312	3315.8984
382.53711	1.099358	0.26194516	3315.0142
383.43799	1.101711	0.26288399	3308.3374
384.33887	1.1032661	0.26375365	3320.4021
385.23975	1.1071523	0.26476371	3317.5259
386.14063	1.1072223	0.26575041	3317.8899
387.0415	1.1092983	0.26699823	3328.6812
387.94238	1.1127472	0.26801559	3322.9033
388.84326	1.1196345	0.26901099	3329.3618
389.74414	1.1207676	0.26998365	3324.2229
390.64502	1.1235166	0.27091521	3331.416
391.5459	1.1244012	0.27185747	3325.6624
392.44678	1.1303461	0.27287117	3335.6765
393.34766	1.1306331	0.2738685	3335.3586
394.24854	1.1309853	0.27486512	3335.4797
395.14941	1.1361004	0.27583796	3333.9214
396.05029	1.1382025	0.27674296	3339.2725
396.95117	1.14103	0.2776328	3338.2683
397.85205	1.1451913	0.27866036	3340.5417
398.75293	1.145816	0.27956337	3333.395
399.65381	1.1497712	0.28045282	3338.4473
400.55469	1.1505451	0.28155226	3345.3062
401.45557	1.1556374	0.2824626	3338.428
402.35645	1.1558013	0.28344584	3345.364
403.25732	1.1587801	0.28465092	3351.1997
404.1582	1.1640116	0.28585333	3354.3599
405.05908	1.1651137	0.28685191	3351.0273
405.95996	1.1681745	0.28796744	3351.4229
406.86084	1.1696048	0.28875896	3353.3572
407.76172	1.1756867	0.28963149	3346.3286
408.6626	1.1755581	0.29043955	3352.3652
409.56348	1.1768181	0.29143408	3361.8367
410.46436	1.1801752	0.29239917	3360.9849
411.36523	1.1834215	0.29348126	3360.5864
412.26611	1.1842704	0.29451174	3362.4917
413.16699	1.1937168	0.29550904	3366.7915
414.06787	1.1914457	0.29663447	3362.9336
414.96875	1.1954091	0.29764634	3364.7324
415.86963	1.195858	0.29846689	3361.8613
416.77051	1.204222	0.29940343	3374.4229
417.67139	1.2053579	0.30037859	3376.5647
418.57227	1.2066991	0.30160424	3371.8398
419.47314	1.2060909	0.30258101	3372.1309
420.37402	1.2095925	0.30364341	3374.5022
421.2749	1.2146549	0.30443823	3373.292
422.17578	1.2174668	0.30544928	3376.646
423.07666	1.2179118	0.30652153	3379.4944
423.97754	1.2211083	0.30739734	3377.0884
424.87842	1.2255496	0.30857214	3390.345
425.7793	1.2286322	0.30957633	3387.8623
426.68018	1.2301058	0.31058893	3386.0383
427.58105	1.2309698	0.31146869	3383.7959
428.48193	1.23239	0.31235781	3381.3435
429.38281	1.2389569	0.31304359	3383.8296
430.28369	1.2399137	0.31397	3389.9019
431.18457	1.2432119	0.31487313	3390.3379
432.08545	1.2465124	0.31585032	3392.4512
432.98633	1.2481827	0.31662884	3394.3872
433.88721	1.2524025	0.31757239	3395.803
434.78809	1.2530342	0.31863144	3397.4534
435.68896	1.2573354	0.31984475	3399.3865
436.58984	1.2607864	0.32112065	3403.6733
437.49072	1.2639043	0.3222568	3398.1775
438.3916	1.2664802	0.32321355	3406.1077
439.29248	1.2677876	0.32420209	3402.2463
440.19336	1.2693722	0.32526559	3404.5671
441.09424	1.2740034	0.32625884	3404.3267
441.99512	1.2743008	0.32727924	3406.8535
442.896	1.2795709	0.32812685	3408.2856
443.79688	1.2799615	0.32911095	3411.1353
444.69775	1.2847334	0.32998306	3409.2859
445.59863	1.2851274	0.33106408	3412.7776
446.49951	1.2895025	0.33208975	3412.5396
447.40039	1.2935442	0.33304149	3415.4063
448.30127	1.2945889	0.33414787	3416.6545
449.20215	1.2964461	0.33498025	3414.6279
450.10303	1.2959732	0.33581907	3422.4866
451.00391	1.3035946	0.33692682	3423.8115
451.90479	1.3058267	0.33793288	3424.0669
452.80566	1.3091625	0.3388229	3422.0679
453.70654	1.3127536	0.33971158	3428.4458
454.60742	1.3126578	0.34064239	3427.7607
455.5083	1.3188581	0.34167907	3430.3411
456.40918	1.318643	0.34264937	3429.9739
457.31006	1.3210044	0.34368718	3425.0437
458.21094	1.3252268	0.34465519	3429.3369
459.11182	1.3299716	0.34585533	3433.394
460.0127	1.3297392	0.34663716	3437.8904
460.91357	1.3317481	0.34763384	3434.8406
461.81445	1.3353691	0.34866363	3429.7061
462.71533	1.3378426	0.34966737	3438.7456
463.61621	1.3409219	0.35053438	3433.291
464.51709	1.3437194	0.35154945	3439.3379
465.41797	1.3457491	0.35241923	3441.3347
466.31885	1.3495376	0.35355446	3441
467.21973	1.3532971	0.35455304	3448.0842
468.12061	1.3549172	0.3554039	3442.8047
469.02148	1.3560477	0.35657907	3444.7136
469.92236	1.3634436	0.35754523	3449.1472
470.82324	1.362973	0.35873273	3454.6375
471.72412	1.364032	0.35980594	3451.0649
472.625	1.3696128	0.36101088	3458.6282
473.52588	1.3723531	0.36210468	3453.5935
474.42676	1.3754425	0.36310339	3454.8086
475.32764	1.3731694	0.36421889	3454.6323
476.22852	1.3785363	0.36524522	3457.6082
477.12939	1.3805786	0.36613449	3456.6399
478.03027	1.3819934	0.36709207	3459.5081
478.93115	1.3860193	0.3679665	3459.2317
479.83203	1.3925602	0.36903775	3462.814
480.73291	1.3925756	0.36994255	3461.4817
481.63379	1.3942891	0.37107012	3468.6946
482.53467	1.3986865	0.37197125	3462.7041
483.43555	1.4022683	0.37287018	3464.5051
484.33643	1.403469	0.37361035	3464.0691
485.2373	1.4053273	0.37452427	3463.3882
486.13818	1.4095706	0.37551385	3469.9309
487.03906	1.4098549	0.37642026	3470.697
487.93994	1.4152373	0.37746307	3472.4878
488.84082	1.4164751	0.37856191	3476.1221
489.7417	1.419578	0.37972242	3480.5886
490.64258	1.4185845	0.38060883	3462.8215
491.54346	1.4207599	0.38157788	3473.583
492.44434	1.4264755	0.38260299	3479.0769
493.34521	1.4292989	0.38371491	3472.7354
494.24609	1.4331756	0.38455856	3480.9343
495.14697	1.4361216	0.38542712	3478.9324
496.04785	1.4370471	0.38641346	3479.884
496.94873	1.4419827	0.38740167	3479.189
497.84961	1.4454201	0.38842633	3480.9526
498.75049	1.4467796	0.38940841	3493.3193
499.65137	1.448123	0.39029548	3486.2571
500.55225	1.4518294	0.39144471	3487.1189
501.45313	1.453263	0.39246595	3484.0093
502.354	1.4588727	0.39345273	3489.8259
503.25488	1.4591428	0.39442176	3488.9065
504.15576	1.466043	0.39532945	3491.2061
505.05664	1.4654791	0.39634752	3494.1741
505.95752	1.4687626	0.39716038	3490.9038
506.8584	1.4703841	0.398197	3499.6309
507.75928	1.4759706	0.39922842	3499.3081
508.66016	1.4785701	0.40032747	3497.7983
509.56104	1.4796634	0.4012793	3502.2419
510.46191	1.4824098	0.40246406	3500.0132
511.36279	1.4857975	0.40337598	3506.3743
512.26367	1.4844112	0.40448263	3501.5913
513.16455	1.4879757	0.4055374	3502.5339
514.06543	1.4909976	0.40655372	3505.354
514.96631	1.4959837	0.40775511	3509.3511
515.86719	1.4960973	0.40891498	3507.6396
516.76807	1.5014166	0.40991798	3515.355
517.66895	1.5043463	0.41111389	3512.0217
518.56982	1.5069598	0.41213045	3512.1306
519.4707	1.5078255	0.4131158	3513.0071
520.37158	1.5119821	0.41432348	3516.3647
521.27246	1.5123432	0.41525954	3504.0527
522.17334	1.517877	0.41596255	3508.5613
523.07422	1.5220011	0.41701493	3518.429
523.9751	1.5211854	0.41796872	3514.2996
524.87598	1.5240142	0.41892827	3512.2664
525.77686	1.5280204	0.41997525	3516.8779
526.67773	1.5286763	0.42092228	3513.7024
527.57861	1.5328429	0.42198423	3521.4082
528.47949	1.5318754	0.42277393	3517.8069
529.38037	1.5371279	0.42385018	3521.1157
530.28125	1.5404187	0.42479542	3519.719
531.18213	1.5415159	0.42577925	3520.6201
532.08301	1.5454383	0.42682573	3523.8921
532.98389	1.5477918	0.42781943	3527.75
533.88477	1.552641	0.42871723	3517.01
534.78564	1.5538843	0.42959988	3524.6763
535.68652	1.5559322	0.43057084	3527.1475
536.5874	1.5562948	0.43175972	3533.1765
537.48828	1.5642402	0.43280318	3530.2666
538.38916	1.564461	0.43393317	3528.6243
539.29004	1.5697373	0.43500385	3537.0408
540.19092	1.5709435	0.43592584	3530.6873
541.0918	1.5697935	0.43692756	3533.803
541.99268	1.5752053	0.43791127	3533.8428
542.89355	1.5778544	0.43879217	3536.0159
543.79443	1.5821294	0.43988162	3540.563
544.69531	1.5868447	0.44111177	3540.593
545.59619	1.5886948	0.44232976	3541.7832
546.49707	1.5893296	0.44327363	3544.3647
547.39795	1.5920159	0.44432363	3545.7834
548.29883	1.5942084	0.44527635	3543.3352
549.19971	1.5981178	0.44631022	3547.2656
550.10059	1.6003774	0.44741285	3539.2339
551.00146	1.6020507	0.44843489	3547.1152
551.90234	1.607581	0.44936529	3546.4946
552.80322	1.6085818	0.45021552	3548.3237
553.7041	1.6096742	0.45113784	3549.8423
554.60498	1.6138034	0.45213312	3547.9011
555.50586	1.6167129	0.45319012	3547.1309
556.40674	1.6179589	0.45429516	3552.5601
557.30762	1.6223392	0.45529711	3550.7612
558.2085	1.6218185	0.45648924	3550.8572
559.10938	1.6277657	0.45743999	3551.4697
560.01025	1.6313193	0.45884624	3560.5859
560.91113	1.6324093	0.45987889	3554.5161
561.81201	1.6364806	0.4610076	3558.9099
562.71289	1.6364964	0.46206379	3555.5046
563.61377	1.639951	0.46318838	3558.6284
564.51465	1.6440455	0.46422157	3558.8647
565.41553	1.6444203	0.46532258	3561.8259
566.31641	1.6478275	0.46633148	3558.4343
567.21729	1.6536841	0.46747744	3565.7944
568.11816	1.6531444	0.46841651	3565.8674
569.01904	1.657032	0.46950549	3566.0527
569.91992	1.6583103	0.47047669	3563.3452
570.8208	1.6649011	0.47146994	3563.2712
571.72168	1.6676321	0.47236326	3565.5132
572.62256	1.6682272	0.4732585	3563.4888
573.52344	1.6702104	0.47424534	3565.4348
574.42432	1.6746494	0.47515672	3567.1736
575.3252	1.6738156	0.47626719	3571.0923
576.22607	1.6829222	0.47724485	3578.5632
577.12695	1.6778318	0.47838601	3572.9709
578.02783	1.6825223	0.47952211	3572.4846
578.92871	1.6863797	0.48053801	3571.0408
579.82959	1.6898842	0.48160285	3576.7734
580.73047	1.6932442	0.48267466	3578.3274
581.63135	1.6952875	0.48379469	3574.4268
582.53223	1.6961708	0.48489413	3576.2283
583.43311	1.7016342	0.48604804	3581.675
584.33398	1.7034911	0.48727807	3585.8074
585.23486	1.7053698	0.48855734	3580.7722
586.13574	1.7097652	0.48982996	3583.0295
587.03662	1.7101645	0.49079171	3578.3259
587.9375	1.7128805	0.49185261	3585.5859
588.83838	1.7154176	0.49295583	3582.0547
589.73926	1.7206814	0.49403691	3587.9155
590.64014	1.7247399	0.49517503	3589.2258
591.54102	1.7258432	0.4963831	3587.9485
592.44189	1.7262639	0.49739236	3584.1335
593.34277	1.7313764	0.49824905	3583.1643
594.24365	1.7337296	0.4991464	3584.7393
595.14453	1.7362229	0.50025684	3591.2786
596.04541	1.7386955	0.50108898	3588.4082
596.94629	1.7404321	0.50218302	3588.772
597.84717	1.742871	0.50343728	3595.354
598.74805	1.7455359	0.50455081	3590.8506
599.64893	1.7476573	0.50565666	3585.7747
600.5498	1.7554888	0.50692123	3602.0317
601.45068	1.7544436	0.50795811	3593.3557
602.35156	1.756964	0.50904393	3595.4609
603.25244	1.7584618	0.5100835	3592.9312
604.15332	1.7596685	0.51118898	3595.0574
605.0542	1.7646198	0.51224917	3599.0369
605.95508	1.7668654	0.51340723	3599.002
606.85596	1.7683049	0.51445311	3593.6379
607.75684	1.7717348	0.51537347	3600.6821
608.65771	1.776507	0.51644212	3601.0132
609.55859	1.7805817	0.51737332	3595.3618
610.45947	1.7805372	0.51849455	3606.9172
611.36035	1.7814792	0.51963788	3603.3379
612.26123	1.7862444	0.52087492	3608.1587
613.16211	1.7881459	0.52194715	3602.8594
614.06299	1.7932352	0.52292776	3600.9873
614.96387	1.7933737	0.52403027	3606.3911
615.86475	1.7982242	0.52529138	3612.1572
616.76563	1.8017483	0.52647406	3609.3687
617.6665	1.8028852	0.52763945	3611.7393
618.56738	1.8092887	0.52892435	3617.9731
619.46826	1.8085371	0.53003448	3610.8347
620.36914	1.8091695	0.53136849	3612.104
621.27002	1.812799	0.53269094	3610.2039
622.1709	1.8114697	0.53379333	3608.3169
623.07178	1.8161957	0.53487414	3605.4312
623.97266	1.8226867	0.53602433	3608.3579
624.87354	1.82689	0.53712291	3620.6472
625.77441	1.8250622	0.53830522	3615.6062
626.67529	1.8298354	0.53918862	3612.4175
627.57617	1.8324692	0.54029006	3613.665
628.47705	1.8361212	0.54121494	3609.1348
629.37793	1.839414	0.54223633	3619.625
630.27881	1.840001	0.54332376	3624.8757
631.17969	1.845823	0.5446859	3623.5674
632.08057	1.8456219	0.54595649	3619.9065
632.98145	1.8502944	0.54729456	3623.7119
633.88232	1.8518265	0.54842502	3621.311
634.7832	1.8567713	0.5495646	3625.2563
635.68408	1.8572235	0.55050617	3614.4463
636.58496	1.8563808	0.55155379	3621.791
637.48584	1.862744	0.55297697	3627.7761
638.38672	1.8660491	0.55410731	3627.1716
639.2876	1.8672352	0.55552673	3626.252
640.18848	1.8712929	0.55674803	3627.7939
641.08936	1.8707598	0.55790377	3623.875
641.99023	1.8764341	0.55886501	3622.7573
642.89111	1.8806027	0.559928	3628.3523
643.79199	1.8800862	0.5610292	3629.2756
644.69287	1.883198	0.5620501	3625.8093
645.59375	1.883808	0.56311989	3629.9229
646.49463	1.889778	0.56418115	3631.4414
647.39551	1.8933028	0.56537849	3635.0049
648.29639	1.8933976	0.56660312	3635.9834
649.19727	1.897772	0.56799632	3637.5474
650.09814	1.8998852	0.56931406	3634.1755
650.99902	1.9028479	0.57047409	3631.1804
651.8999	1.9067123	0.57147419	3629.3425
652.80078	1.90795	0.57261992	3637.5151
653.70166	1.9094461	0.57373744	3634.0454
654.60254	1.9154406	0.57503229	3639.3462
655.50342	1.9131269	0.57637286	3640.5774
656.4043	1.919825	0.57774776	3638.4363
657.30518	1.9238325	0.57891589	3641.6211
658.20605	1.9228727	0.57978135	3630.0181
659.10693	1.9288106	0.58099717	3640.0793
660.00781	1.9291564	0.58219361	3644.0737
660.90869	1.9310457	0.58362919	3644.6211
661.80957	1.9385289	0.58498275	3649.2764
662.71045	1.9401981	0.58626157	3640.3984
663.61133	1.9398559	0.58727264	3637.3298
664.51221	1.9421488	0.58845645	3643.2546
665.41309	1.9482208	0.58974487	3645.5591
666.31396	1.9489899	0.59102732	3647.0339
667.21484	1.9521363	0.59246689	3647.0833
668.11572	1.9544227	0.59384197	3647.3997
669.0166	1.9575747	0.59522498	3650.4277
669.91748	1.9595475	0.59638745	3651.0798
670.81836	1.9629118	0.59768951	3650.0303
671.71924	1.9663247	0.59872311	3648.6436
672.62012	1.9668955	0.59979886	3647.3767
673.521	1.9707756	0.60105085	3650.1299
674.42188	1.9732791	0.60231757	3652.8379
675.32275	1.9784619	0.60363144	3650.9724
676.22363	1.9786882	0.60482502	3655.9373
677.12451	1.9837679	0.60607505	3659.7014
678.02539	1.9824748	0.60735452	3648.9231
678.92627	1.9854078	0.60856253	3651.572
679.82715	1.9883157	0.60958636	3648.0466
680.72803	1.9915985	0.61074924	3659.4509
681.62891	1.9977548	0.61187381	3652.1665
682.52979	1.9957511	0.61295289	3655.6355
683.43066	1.9993576	0.61396897	3649.5696
684.33154	2.0016439	0.61523193	3657.8601
685.23242	2.0089412	0.61656117	3667.0408
686.1333	2.0084651	0.61781126	3655.5557
687.03418	2.0113654	0.6193006	3659.9565
687.93506	2.0096979	0.62032682	3655.9783
688.83594	2.0159545	0.62155187	3654.7307
689.73682	2.0209002	0.62280273	3657.418
690.6377	2.0208628	0.62418056	3661.4685
691.53857	2.0257759	0.62553871	3665.0645
692.43945	2.0298514	0.626917	3660.2559
693.34033	2.0303576	0.62806702	3659.6379
694.24121	2.0318456	0.62934315	3662.959
695.14209	2.0370917	0.63070637	3666.303
696.04297	2.037859	0.63200057	3664.217
696.94385	2.0408194	0.63341278	3660.0625
697.84473	2.0421457	0.63467264	3664.0344
698.74561	2.0472839	0.63588589	3665.1587
699.64648	2.0486574	0.637205	3667.3149
700.54736	2.0501597	0.63851333	3666.5217
701.44824	2.0573611	0.63986164	3668.3079
702.34912	2.0574365	0.64112133	3660.9602
703.25	2.0606158	0.64250827	3667.7341
704.15088	2.0635805	0.64399016	3662.842
705.05176	2.0639181	0.6452716	3663.6362
705.95264	2.0714896	0.64658111	3668.5696
706.85352	2.0711122	0.64772844	3660.6812
707.75439	2.0738463	0.64897096	3669.6816
708.65527	2.0763192	0.65030044	3675.4099
709.55615	2.0777099	0.65171105	3668.1194
710.45703	2.081882	0.65299255	3674.7202
711.35791	2.0837708	0.65432054	3671.1125
712.25879	2.0849729	0.65579271	3673.5271
713.15967	2.0883398	0.65707558	3672.623
714.06055	2.0905244	0.65835094	3669.5034
714.96143	2.0983241	0.65957487	3672.8315
715.8623	2.0978048	0.66071916	3669.1411
716.76318	2.1007614	0.66193706	3668.7903
717.66406	2.1059937	0.6632024	3676.1697
718.56494	2.1088917	0.66483331	3682.0684
719.46582	2.1086836	0.66630769	3675.7112
720.3667	2.1127989	0.66776544	3676.9299
721.26758	2.1146634	0.66911668	3675.1201
722.16846	2.1188259	0.67024899	3670.0183
723.06934	2.1161549	0.67165536	3675.8901
723.97021	2.1212578	0.67306882	3677.6594
724.87109	2.1244705	0.67451996	3683.0295
725.77197	2.1282527	0.67603922	3676.1812
726.67285	2.1298158	0.67736179	3675.1738
727.57373	2.1346405	0.67855632	3676.2307
728.47461	2.1360879	0.68004894	3678.9712
729.37549	2.1398051	0.68135226	3682.6047
730.27637	2.1423404	0.68292212	3682.4539
731.17725	2.1392343	0.68441284	3680.7815
732.07813	2.1437004	0.68591601	3681.3066
732.979	2.1484785	0.68743438	3674.0461
733.87988	2.1513515	0.68864137	3680.3582
734.78076	2.1537306	0.69002086	3677.947
735.68164	2.1573341	0.69146687	3680.0789
736.58252	2.1622286	0.6928277	3681.3772
737.4834	2.1592929	0.69441503	3683.2827
738.38428	2.165513	0.69596654	3685.5479
739.28516	2.168685	0.69730413	3677.3862
740.18604	2.1705735	0.69877172	3684.9336
741.08691	2.1745086	0.70004743	3678.7175
741.98779	2.1782515	0.70130378	3676.8201
742.88867	2.178458	0.70249373	3680.1846
743.78955	2.1806157	0.7038995	3686.5063
744.69043	2.1829407	0.70543051	3684.5254
745.59131	2.1869633	0.70683521	3679.627
746.49219	2.1916273	0.70836031	3682.4724
747.39307	2.1908042	0.70958048	3679.7268
748.29395	2.1957338	0.71087533	3684.7344
749.19482	2.196759	0.71217906	3683.1958
750.0957	2.2000866	0.71360588	3682.0115
750.99658	2.2036047	0.71517342	3685.282
751.89746	2.2065248	0.71684557	3689.614
752.79834	2.2118435	0.71853644	3690.7798
753.69922	2.2101963	0.72014666	3685.3738
754.6001	2.2161624	0.722009	3694.2778
755.50098	2.2176428	0.72334337	3682.7146
756.40186	2.2209196	0.7247541	3688.1565
757.30273	2.2203386	0.72629809	3687.3616
758.20361	2.2238977	0.72797453	3685.3418
759.10449	2.2268841	0.72949988	3683.4609
760.00537	2.2319784	0.73084939	3685.7644
760.90625	2.2321162	0.73201013	3683.0518
761.80713	2.2355211	0.73349279	3691.6843
762.70801	2.2387891	0.73519617	3694.6191
763.60889	2.2430449	0.73667806	3689.0383
764.50977	2.2458143	0.73825014	3692.8179
765.41064	2.2460771	0.73985952	3687.1589
766.31152	2.2485785	0.74143136	3687.9614
767.2124	2.2527184	0.74296623	3690.2727
768.11328	2.2553937	0.74458581	3690.8982
769.01416	2.2562947	0.7460739	3687.0569
769.91504	2.261318	0.74761379	3687.822
770.81592	2.2623937	0.74904579	3691.0066
771.7168	2.2647316	0.75034076	3689.4036
772.61768	2.2691071	0.75183553	3695.0146
773.51855	2.2700169	0.75326318	3685.3523
774.41943	2.2711439	0.75479162	3689.2009
775.32031	2.2795413	0.75634199	3696.4856
776.22119	2.2771611	0.75794739	3694.0662
777.12207	2.2829223	0.7597279	3693.6069
778.02295	2.2835567	0.76146054	3689.2979
778.92383	2.2854812	0.76295853	3689.2639
779.82471	2.2882915	0.76455528	3692.2148
780.72559	2.2919743	0.76605922	3689.2676
781.62646	2.2944689	0.76791501	3694.3318
782.52734	2.2973475	0.76975465	3693.1663
783.42822	2.301142	0.77148074	3690.437
784.3291	2.3070419	0.77312434	3696.5671
785.22998	2.3054116	0.77464885	3693.3318
786.13086	2.3105166	0.77628052	3695.4631
787.03174	2.3116479	0.77793831	3698.1877
787.93262	2.3131328	0.77973771	3697.1572
788.8335	2.3153298	0.78150994	3696.9363
789.73438	2.3183355	0.78298968	3690.8643
790.63525	2.3257365	0.78450698	3695.731
791.53613	2.3258939	0.78609788	3697.9756
792.43701	2.3265862	0.78773737	3692.1296
793.33789	2.3271799	0.78960013	3696.9023
794.23877	2.3331389	0.79123586	3689.6816
795.13965	2.3347402	0.79276407	3690.7617
796.04053	2.3421769	0.79432911	3701.7168
796.94141	2.3401248	0.79598391	3695.511
797.84229	2.3401878	0.79743981	3692.8384
798.74316	2.3465617	0.79934001	3697.0098
799.64404	2.3503649	0.80089456	3698.5056
800.54492	2.3526144	0.80256814	3695.0715
801.4458	2.354907	0.80417675	3693.9729
802.34668	2.3590465	0.80588096	3699.8689
803.24756	2.3590109	0.80770254	3696.6052
804.14844	2.3599789	0.80944735	3697.2881
805.04932	2.3653669	0.81149501	3694.8848
805.9502	2.3677633	0.81346655	3692.8909
806.85107	2.3722575	0.81518859	3696.4751
807.75195	2.3729644	0.81675601	3696.1775
808.65283	2.3769605	0.81867296	3692.2478
809.55371	2.3803358	0.82029003	3699.7573
810.45459	2.3819377	0.82229227	3699.1912
811.35547	2.3830783	0.82416725	3693.7019
812.25635	2.3875279	0.82606924	3696.8328
813.15723	2.3906806	0.82761711	3689.0579
814.05811	2.3914621	0.82919359	3695.4648
814.95898	2.396373	0.83089089	3694.9502
815.85986	2.3970749	0.8328703	3689.9146
816.76074	2.4006574	0.83443731	3690.8127
817.66162	2.4001534	0.83629227	3696.2878
818.5625	2.4047284	0.83828914	3696.874
819.46338	2.4074473	0.84002441	3687.3486
820.36426	2.4108505	0.84183151	3694.4763
821.26514	2.4117792	0.84352648	3688.635
822.16602	2.4149516	0.84518921	3692.4031
823.06689	2.4200153	0.84694797	3697.6382
823.96777	2.4181633	0.84876722	3693.8584
824.86865	2.4241152	0.85072362	3694.0681
825.76953	2.4290402	0.85241413	3693.3975
826.67041	2.4318099	0.85412782	3695.7207
827.57129	2.4363656	0.85621309	3699.1462
828.47217	2.4334719	0.85801482	3690.9463
829.37305	2.4408076	0.86001819	3695.644
830.27393	2.4382	0.86185068	3692.4705
831.1748	2.4433081	0.8636564	3689.3667
832.07568	2.4468923	0.8656311	3696.6963
832.97656	2.4459989	0.86744547	3685.9319
833.87744	2.453413	0.86946052	3698.1365
834.77832	2.4526105	0.87180644	3697.7932
835.6792	2.4583797	0.87396586	3692.553
836.58008	2.4558158	0.87593371	3688.0896
837.48096	2.4615099	0.87761557	3687.3672
838.38184	2.4664345	0.87948519	3694.425
839.28271	2.468055	0.88159978	3698.9417
840.18359	2.4717073	0.88342965	3691.3955
841.08447	2.4721527	0.88531446	3692.4417
841.98535	2.4748361	0.88740849	3696.9363
842.88623	2.4786174	0.8896212	3690.7856
843.78711	2.4824584	0.89170146	3694.0139
844.68799	2.4852624	0.89376211	3693.4329
845.58887	2.4887323	0.8953833	3690.1895
846.48975	2.4883533	0.89698982	3685.6787
847.39063	2.4920764	0.89923072	3699.4744
848.2915	2.4987049	0.90149397	3695.9238
849.19238	2.49909	0.90382975	3692.699
850.09326	2.4991758	0.9058848	3687.7615
850.99414	2.5024717	0.90794909	3689.5386
851.89502	2.5072913	0.90994424	3689.3735
852.7959	2.5078874	0.91170585	3692.1257
853.69678	2.5137451	0.91360152	3692.9878
854.59766	2.5117021	0.9156757	3689.7681
855.49854	2.5166779	0.9175815	3683.2808
856.39941	2.5159264	0.91971385	3687.1499
857.30029	2.5255046	0.92209071	3690.1948
858.20117	2.5227091	0.92421514	3688.3062
859.10205	2.5265744	0.92624485	3688.2251
860.00293	2.5308495	0.92809439	3682.6189
860.90381	2.5341887	0.93019062	3691.8496
861.80469	2.5373745	0.93234617	3688.9973
862.70557	2.5379357	0.93429172	3686.7104
863.60645	2.5404942	0.93669724	3688.1304
864.50732	2.5431635	0.9386608	3680.6458
865.4082	2.5481579	0.94097769	3691.9023
866.30908	2.5513206	0.94308776	3682.6631
867.20996	2.5531566	0.94517154	3683.2124
868.11084	2.5551932	0.94699901	3677.187
869.01172	2.5555243	0.94902086	3687.0984
869.9126	2.5597019	0.95132279	3684.2937
870.81348	2.5621936	0.95351094	3684.4067
871.71436	2.5646796	0.95540786	3679.2505
872.61523	2.567059	0.95767814	3681.3809
873.51611	2.5692449	0.96011358	3687.127
874.41699	2.5702937	0.96260965	3683.8674
875.31787	2.5770199	0.96519309	3683.6108
876.21875	2.5796258	0.96747249	3679.0747
877.11963	2.5808971	0.96962601	3676.6113
878.02051	2.586668	0.97206777	3687.8103
878.92139	2.5842688	0.97470957	3683.3911
879.82227	2.5893967	0.97709358	3672.8882
880.72314	2.5935998	0.97944808	3681.2725
881.62402	2.5977564	0.9815948	3678.5715
882.5249	2.59869	0.98358345	3680.0505
883.42578	2.602488	0.98574591	3675.9409
884.32666	2.6045239	0.98774105	3676.2354
885.22754	2.6063929	0.98986936	3673.0793
886.12842	2.6089311	0.992033	3672.0315
887.0293	2.6131127	0.99397069	3672.6541
887.93018	2.6167159	0.99636775	3675.7051
888.83105	2.6159084	0.99883199	3676.769
889.73193	2.617928	1.001547	3670.7314
890.63281	2.6239393	1.0040205	3673.0735
891.53369	2.6258481	1.0062559	3669.3369
892.43457	2.6250484	1.0085917	3669.5366
893.33545	2.6269825	1.010998	3670.2024
894.23633	2.6333196	1.0133158	3668.0906
895.13721	2.6352921	1.0156428	3668.9622
896.03809	2.6380353	1.0181181	3673.0911
896.93896	2.6403508	1.0203292	3667.5479
897.83984	2.6457715	1.022609	3666.3354
898.74072	2.6451228	1.0248716	3661.3394
899.6416	2.6488264	1.0276878	3665.9673
900.54248	2.6520019	1.0302591	3666.7859
901.44336	2.6554465	1.0327837	3658.0933
902.34424	2.6561437	1.0355208	3661.76
903.24512	2.6577618	1.0382246	3663.9084
904.146	2.6636505	1.0408018	3658.0146
905.04688	2.663548	1.0430321	3651.1248
905.94775	2.6689911	1.0454015	3660.6338
906.84863	2.6732445	1.047593	3653.7209
907.74951	2.6719117	1.0496376	3655.3284
908.65039	2.6783719	1.0519159	3660.7217
909.55127	2.6780455	1.0542034	3657.1252
910.45215	2.6832089	1.0574106	3665.5554
911.35303	2.6836491	1.0606921	3652.7759
912.25391	2.6886458	1.0635136	3655.0962
913.15479	2.6897254	1.0664028	3652.8943
914.05566	2.6922197	1.0690963	3652.6531
914.95654	2.6943715	1.0716819	3654.0356
915.85742	2.7000065	1.0738969	3642.1233
916.7583	2.6996338	1.0762862	3650.6179
917.65918	2.7027063	1.0787214	3645.5664
918.56006	2.7067633	1.0817248	3652.126
919.46094	2.7102954	1.0850505	3648.9871
920.36182	2.7116392	1.0877298	3640.9509
921.2627	2.7132208	1.0904021	3645.5503
922.16357	2.7182257	1.0927089	3645.9409
923.06445	2.7216532	1.0948677	3637.6619
923.96533	2.7242911	1.0973485	3646.5774
924.86621	2.7256527	1.099986	3641.4248
925.76709	2.7264194	1.1027185	3638.2896
926.66797	2.730706	1.1053493	3634.6875
927.56885	2.7334471	1.1077942	3634.9587
928.46973	2.7349343	1.1104478	3635.0454
929.37061	2.740567	1.1127257	3633.3164
930.27148	2.7445474	1.1148362	3635.9412
931.17236	2.7464552	1.1174095	3634.269
932.07324	2.7463868	1.1203501	3634.0522
932.97412	2.7510684	1.1231767	3629.5374
933.875	2.7517841	1.1258649	3625.4895
934.77588	2.7559564	1.1282257	3626.3806
935.67676	2.7569282	1.130414	3622.1575
936.57764	2.76001	1.1332129	3622.8682
937.47852	2.7639334	1.1359098	3626.2119
938.37939	2.7653308	1.1389897	3626.3723
939.28027	2.7684131	1.1418954	3621.2974
940.18115	2.7718401	1.1448593	3618.2305
941.08203	2.772552	1.1475199	3619.5876
941.98291	2.7741857	1.1503458	3613.9121
942.88379	2.7789242	1.1530347	3613.4133
943.78467	2.7829459	1.1557282	3608.6831
944.68555	2.7838271	1.1578951	3604.4441
945.58643	2.7881706	1.1602221	3608.8933
946.4873	2.7906363	1.1631491	3616.0164
947.38818	2.793633	1.1664073	3609.9065
948.28906	2.795526	1.1694273	3603.5017
949.18994	2.7974553	1.1721109	3598.9175
950.09082	2.7998099	1.1748819	3602.0127
950.9917	2.8043275	1.1781874	3600.0073
951.89258	2.8078136	1.1814059	3599.1829
952.79346	2.8073845	1.1841408	3593.7148
953.69434	2.8116193	1.1866224	3597.6516
954.59521	2.8154793	1.1896114	3598.1038
955.49609	2.8177302	1.1923836	3594.312
956.39697	2.8201194	1.1952255	3584.5698
957.29785	2.8204751	1.1976136	3584.3435
958.19873	2.8258679	1.2000405	3583.0386
959.09961	2.8285122	1.2026322	3588.1956
960.00049	2.8313787	1.2053719	3584.3779
960.90137	2.8328974	1.2081425	3580.688
961.80225	2.8347719	1.2113008	3579.0723
962.70313	2.8395457	1.2138692	3573.74
963.604	2.8403211	1.2162381	3576.5715
964.50488	2.8437002	1.2189132	3575.7944
965.40576	2.8457267	1.2218374	3573.5386
966.30664	2.8477356	1.2244971	3578.4604
967.20752	2.8522527	1.2276534	3572.2876
968.1084	2.8529561	1.2307599	3566.9971
969.00928	2.8563027	1.2338997	3562.4839
969.91016	2.8579962	1.2364523	3559.5552
970.81104	2.8667431	1.2392569	3565.3855
971.71191	2.8680081	1.2419314	3563.2766
972.61279	2.8677256	1.2445383	3562.3438
973.51367	2.8728335	1.2476298	3554.1941
974.41455	2.8753638	1.2504288	3554.2524
975.31543	2.8766742	1.2529683	3549.5974
976.21631	2.88077	1.2557948	3550.9248
977.11719	2.8845992	1.2587582	3553.2739
978.01807	2.8864596	1.2620753	3549.6082
978.91895	2.8863041	1.2644891	3535.2205
979.81982	2.8895507	1.267001	3544.4841
980.7207	2.8913453	1.2695755	3542.417
981.62158	2.8977954	1.2721556	3539.4846
982.52246	2.8975387	1.2746416	3538.7097
983.42334	2.9002845	1.2778959	3534.9604
984.32422	2.9028876	1.2817001	3531.3386
985.2251	2.9068999	1.2845066	3526.5286
986.12598	2.9101644	1.2871933	3525.2649
987.02686	2.9100039	1.2896477	3522.8425
987.92773	2.9148114	1.2926418	3525.0366
988.82861	2.9175503	1.2956334	3524.5637
989.72949	2.9201696	1.2989761	3519.3257
990.63037	2.9267626	1.3016807	3511.9231
991.53125	2.9259405	1.3041118	3511.0471
992.43213	2.9271915	1.3069792	3517.6133
993.33301	2.9321468	1.3100097	3509.1426
994.23389	2.931705	1.3132055	3504.4822
995.13477	2.9359128	1.3160095	3501.7446
996.03564	2.9388292	1.3187832	3502.356
996.93652	2.939549	1.3215545	3500.2354
997.8374	2.9423151	1.324777	3492.5791
998.73828	2.9471889	1.3276178	3494.0686
999.63916	2.9519529	1.3305733	3494.498
1000.54	2.9523764	1.3329769	3485.7019
1001.4409	2.9534383	1.3358997	3487.959
1002.3418	2.9546802	1.3390118	3478.9148
1003.2427	2.9607193	1.3419428	3476.4116
1004.1436	2.964829	1.3446406	3482.1428
1005.0444	2.968437	1.3470117	3473.0305
1005.9453	2.9711792	1.3497655	3474.8083
1006.8462	2.9718032	1.3527157	3474.1704
1007.7471	2.9745617	1.3557608	3472.5647
1008.6479	2.9796009	1.3586953	3466.8682
1009.5488	2.9801114	1.3616405	3461.9016
1010.4497	2.9813037	1.3643956	3454.6714
1011.3506	2.9834654	1.3670702	3454.5203
1012.2515	2.990289	1.3694642	3446.8162
1013.1523	2.992394	1.3716333	3446.7769
1014.0532	2.9924629	1.3735582	3444.7529
1014.9541	2.9983025	1.376026	3447.0618
1015.855	2.9984069	1.378738	3447.4189
1016.7559	3.0002382	1.3821878	3444.4822
1017.6567	3.0036981	1.3851101	3436.271
1018.5576	3.007278	1.3877003	3434.7632
1019.4585	3.0080745	1.3909836	3430.1421
1020.3594	3.0120239	1.3943174	3425.4966
1021.2603	3.0140007	1.3977661	3425.1941
1022.1611	3.015908	1.4010262	3419.6421
1023.062	3.0214667	1.4044926	3423.0989
1023.9629	3.0219018	1.4072907	3407.8269
1024.8638	3.0248778	1.4098974	3411.1626
1025.7646	3.025569	1.41259	3403.876
1026.6655	3.0297537	1.415506	3412.2185
1027.5664	3.0360157	1.4185858	3404.2642
1028.4673	3.0358763	1.4213011	3389.7131
1029.3682	3.043211	1.4236307	3390.6531
1030.269	3.0427899	1.4261295	3390.8088
1031.1699	3.0440395	1.4287678	3389.0176
1032.0708	3.0467987	1.4317483	3385.3794
1032.9717	3.0503335	1.4350052	3378.6113
1033.8726	3.0549715	1.4379779	3382.353
1034.7734	3.0549648	1.4410307	3374.0774
1035.6743	3.0574453	1.4442564	3372.5032
1036.5752	3.0591855	1.447768	3367.0256
1037.4761	3.0631685	1.4508901	3361.343
1038.377	3.068562	1.4535545	3360.6064
1039.2778	3.0678575	1.4560233	3353.5017
1040.1787	3.0708001	1.4585655	3356.0364
1041.0796	3.0728407	1.4625651	3348.3806
1041.9805	3.078505	1.4657772	3334.9265
1042.8813	3.0806003	1.4686137	3342.49
1043.7822	3.0817862	1.471638	3337.6873
1044.6831	3.0869243	1.4749502	3334.6914
1045.584	3.0883694	1.4777857	3323.7268
1046.4849	3.090874	1.4806787	3325.373
1047.3857	3.0926132	1.4838744	3320.2661
1048.2866	3.0956309	1.486616	3312.8555
1049.1875	3.0971594	1.4895992	3309.302
1050.0884	3.1012607	1.4927825	3313.2188
1050.9893	3.1024699	1.49549	3298.2727
1051.8901	3.1064863	1.4982586	3307.7803
1052.791	3.109504	1.5016737	3294.5728
1053.6919	3.1130655	1.5053041	3290.1433
1054.5928	3.115624	1.5086466	3286.4807
1055.4937	3.1173148	1.5119569	3278.9731
1056.3945	3.1206315	1.5150132	3274.2224
1057.2954	3.1211655	1.517886	3269.187
1058.1963	3.1280255	1.5216541	3264.4634
1059.0972	3.1291695	1.5246861	3258.2029
1059.998	3.1311774	1.5282239	3255.8713
1060.8989	3.1340606	1.5305772	3244.7966
1061.7998	3.1379349	1.5331087	3248.1609
1062.7007	3.1381242	1.5359528	3246.4565
1063.6016	3.1417542	1.5392152	3240.8547
1064.5024	3.1479213	1.5421715	3233.4092
1065.4033	3.1479895	1.5451871	3232.054
1066.3042	3.149081	1.5481404	3218.9624
1067.2051	3.1548424	1.5513821	3223.313
1068.106	3.1528945	1.5545809	3213.0398
1069.0068	3.1597044	1.5578088	3208.9563
1069.9077	3.1626799	1.5608566	3204.9119
1070.8086	3.1640718	1.5639117	3202.1992
1071.7095	3.16645	1.566874	3197.0593
1072.6104	3.1695368	1.570421	3184.4475
1073.5112	3.1726246	1.5735923	3181.1216
1074.4121	3.1725814	1.576462	3175.5391
1075.313	3.1789455	1.5793285	3176.781
1076.2139	3.1785264	1.5824877	3170.3962
1077.1147	3.1792901	1.5857445	3160.3806
1078.0156	3.1843219	1.5888476	3153.2292
1078.9165	3.1868613	1.5913807	3150.9507
1079.8174	3.1912582	1.5943888	3153.9663
1080.7183	3.1932116	1.5973115	3139.9153
1081.6191	3.1975899	1.6005548	3140.4202
1082.52	3.2002735	1.6037345	3122.7764
1083.4209	3.2008588	1.6070212	3121.3486
1084.3218	3.204921	1.6102428	3112.6289
1085.2227	3.2090127	1.6137311	3114.9795
1086.1235	3.2096262	1.6173456	3100.0295
1087.0244	3.2123792	1.6211145	3093.5681
1087.9253	3.2159786	1.6245619	3081.1924
1088.8262	3.2168782	1.6272652	3071.948
1089.7271	3.2198627	1.6301169	3072.762
1090.6279	3.2238832	1.6334254	3066.0425
1091.5288	3.2271581	1.6372664	3059.2354
1092.4297	3.2277608	1.6412199	3045.1619
1093.3306	3.2310879	1.6446625	3041.8835
1094.2314	3.2347589	1.6488848	3029.3982
1095.1323	3.2386274	1.6525599	3020.2749
1096.0332	3.2408278	1.6558095	3008.3538
1096.9341	3.2428625	1.6592374	3005.1094
1097.835	3.2471738	1.6636329	2985.0085
1098.7358	3.2502353	1.6671444	2968.4055
1099.6367	3.2505069	1.6703155	2966.542
1100.5376	3.2546279	1.6739578	2952.9028
1101.4385	3.2531099	1.6782222	2934.1948
1102.3394	3.2589939	1.6828024	2919.8674
1103.2402	3.2617569	1.6875129	2890.1252
1104.1411	3.2647245	1.692982	2859.8896
1104.6416	3.2712214	1.7031221	2786.1973