File: datasets/am_bench_2022/raw_data/0-XY.20-4/specimen.dat
MTS793|MPT|ENU|1|2|.|/|:|1|0|0|A

Operator Information						Time:	13.261963	Sec	10/13/2021 4:59:04 PM
Operator	Jake Benzing
Project	AM Bench 2022 mini-tensile challenge
Specimen ID	0-XY.20-4
Material	PBF-L Inconel 625
Specimen Width	2.55	mm
Specimen Thickness	1.51	mm
Notes
Operator Information End

Data Acquisition						Time:	1014.2556	Sec	10/13/2021 5:15:45 PM
Time	Axial Displacement	Axial Extensometer	Axial Force
Sec	mm	mm	N
13.375488	0.00028740228	-3.1783849e-05	68.297646
14.376465	0.00066747505	0.00010709842	76.022629
15.377441	0.0048349574	0.00013393504	92.828926
16.378418	0.006872342	0.00030824501	106.7066
17.379395	0.011035061	0.00030534374	116.43842
18.380371	0.013236614	0.00041607401	130.90602
19.381348	0.017463258	0.00050022168	140.48404
20.382324	0.020851079	0.00044981955	156.05309
21.383301	0.025773533	0.0005448336	175.65569
22.384277	0.024304669	0.00067495985	190.84901
23.385254	0.027427977	0.000752591	203.40462
24.38623	0.030152412	0.00083684933	224.18851
25.387207	0.033528145	0.00092294865	237.94209
26.388184	0.035895865	0.0010394845	256.75015
27.38916	0.042420514	0.0010034575	277.67725
28.390137	0.041772444	0.0011443999	297.78845
29.391113	0.042833164	0.0013330205	321.34888
30.39209	0.048384633	0.001457171	344.84735
31.393066	0.05422454	0.0015023772	363.60269
32.394043	0.053879503	0.0016520317	380.92181
33.39502	0.060368143	0.0017600737	413.25189
34.395996	0.059552729	0.0017434662	430.41779
35.396973	0.067214675	0.0018920993	456.25818
36.397949	0.067480013	0.0020170992	471.29462
37.398926	0.071950324	0.0021466538	495.45758
38.399902	0.070801705	0.0021735099	517.78601
39.400879	0.072679527	0.0023082411	540.10138
40.401855	0.0750181	0.0024623047	567.11682
41.402832	0.080788143	0.0025630773	594.68079
42.403809	0.082887866	0.0026950906	619.1889
43.404785	0.084491134	0.0029352903	646.65393
44.405762	0.090609893	0.0030809955	682.17462
45.406738	0.090722173	0.0030163073	705.2027
46.407715	0.0975032	0.0032612719	731.04504
47.408691	0.097520411	0.0033845457	751.87354
48.409668	0.1036007	0.0034995694	783.32355
49.410645	0.10327001	0.0036620509	811.79382
50.411621	0.10841144	0.0037741119	826.94409
51.412598	0.11083489	0.0039694039	859.68475
52.413574	0.11371156	0.0040088738	882.45764
53.414551	0.11653859	0.0041816034	910.41656
54.415527	0.11982171	0.0043139812	936.43561
55.416504	0.12315872	0.0043883771	960.11011
56.41748	0.12659946	0.0046124673	996.87805
57.418457	0.12868519	0.0047816397	1029.6394
58.419434	0.13187756	0.0048644515	1057.9614
59.42041	0.13323987	0.0049557509	1081.6244
60.421387	0.13900894	0.0051440839	1114.9934
61.422363	0.1412174	0.0053641549	1152.0724
62.42334	0.14360684	0.0054541095	1181.8765
63.424316	0.14773898	0.0055958466	1212.2623
64.425293	0.15108629	0.0057902778	1232.0814
65.42627	0.15214045	0.0059579997	1260.2148
66.427246	0.15568726	0.0060212743	1292.2834
67.428223	0.15872492	0.0062207691	1316.1409
68.429199	0.15977663	0.0062901126	1345.1001
69.430176	0.1655082	0.0064186221	1369.2686
70.431152	0.16637817	0.00661809	1393.2234
71.432129	0.17369553	0.0067709242	1425.6171
72.433105	0.17277537	0.0069912034	1446.1917
73.434082	0.17321569	0.0070578707	1478.4211
74.435059	0.17957135	0.0072440901	1509.3318
75.436035	0.17986844	0.007399674	1528.3942
76.437012	0.18499246	0.0075416532	1563.3619
77.437988	0.18863946	0.007589729	1585.5068
78.438965	0.19071071	0.0077800294	1613.2059
79.439941	0.19479024	0.0080430368	1652.7169
80.440918	0.19738232	0.0080458149	1667.9458
81.441895	0.20129609	0.0082874727	1698.7888
82.442871	0.20497261	0.0083863605	1721.6678
83.443848	0.20559609	0.0084972996	1748.225
84.444824	0.20959428	0.0087401206	1766.6113
85.445801	0.21201502	0.008820531	1804.6597
86.446777	0.21485496	0.0090916976	1824.6868
87.447754	0.21793078	0.0091223447	1851.9957
88.44873	0.22037636	0.0093628392	1873.9012
89.449707	0.22200868	0.0095626255	1901.2698
90.450684	0.22897384	0.0096131796	1926.4484
91.45166	0.23077135	0.010003022	1963.7124
92.452637	0.23465608	0.0099963378	1977.7303
93.453613	0.23729031	0.010221469	1997.25
94.45459	0.24130121	0.010291943	2023.7717
95.455566	0.24248973	0.010491992	2035.5232
96.456543	0.24349923	0.010578411	2055.1809
97.45752	0.24976495	0.010832014	2083.2942
98.458496	0.25259015	0.010997293	2100.5149
99.459473	0.25582552	0.011067213	2118.6116
100.46045	0.25738576	0.011468303	2139.0759
101.46143	0.26146454	0.011440979	2158.1895
102.4624	0.26517439	0.011809349	2185.3254
103.46338	0.26723251	0.011949772	2197.7065
104.46436	0.2731868	0.012147935	2223.4294
105.46533	0.27376622	0.012318271	2229.9951
106.46631	0.27865258	0.012481625	2256.5854
107.46729	0.27923056	0.012794166	2266.9116
108.46826	0.28466055	0.012838344	2285.636
109.46924	0.28525287	0.013077421	2300.2659
110.47021	0.2888208	0.013220891	2315.7363
111.47119	0.29029828	0.013421703	2326.3977
112.47217	0.29752713	0.013736428	2348.8271
113.47314	0.29789552	0.013815676	2352.574
114.47412	0.29751444	0.014081273	2365.4783
115.4751	0.30062652	0.014191387	2374.0286
116.47607	0.30662316	0.014494754	2395.9321
117.47705	0.31023863	0.014744886	2407.7708
118.47803	0.31025767	0.014819654	2417.2805
119.479	0.31316015	0.015232964	2432.3752
120.47998	0.31962231	0.015472229	2447.3496
121.48096	0.3231222	0.015778787	2463.4377
122.48193	0.32501581	0.015984261	2467.7739
123.48291	0.33122149	0.016307326	2485.1865
124.48389	0.3298555	0.016599948	2497.0793
125.48486	0.33558953	0.016784012	2503.426
126.48584	0.3373419	0.017104749	2514.0635
127.48682	0.34113178	0.017380647	2524.2932
128.48779	0.34340253	0.017818043	2538.4741
129.48877	0.34659284	0.018226203	2543.8611
130.48975	0.35244057	0.018577959	2553.3818
131.49072	0.35189271	0.019043036	2564.9285
132.4917	0.35259178	0.019271823	2575.9321
133.49268	0.35963953	0.019794105	2583.8984
134.49365	0.36278453	0.020115107	2587.2678
135.49463	0.36425096	0.020702407	2599.7871
136.49561	0.36842641	0.021055641	2610.5601
137.49658	0.37046811	0.021628853	2614.0522
138.49756	0.37599352	0.022275502	2627.4246
139.49854	0.37644324	0.022777332	2620.6772
140.49951	0.37927136	0.023344226	2629.9387
141.50049	0.38120961	0.023846563	2640.9812
142.50146	0.38934472	0.02449454	2657.9814
143.50244	0.38722634	0.025135325	2656.4402
144.50342	0.3918052	0.025947515	2665.4089
145.50439	0.39436778	0.026572233	2660.0186
146.50537	0.39553607	0.027355371	2665.6868
147.50635	0.39779577	0.028205857	2686.0935
148.50732	0.40004069	0.028883705	2679.2957
149.5083	0.4057321	0.029800819	2690.8723
150.50928	0.41031995	0.030597664	2699.9453
151.51025	0.41386905	0.031636387	2707.344
152.51123	0.41521537	0.032470256	2699.2114
153.51221	0.42199579	0.033201739	2709.6157
154.51318	0.42448968	0.034194402	2717.4507
155.51416	0.4220013	0.035230871	2713.5046
156.51514	0.42689237	0.036511734	2727.665
157.51611	0.43116307	0.03742661	2733.8823
158.51709	0.43541476	0.038483631	2728.2673
159.51807	0.43591368	0.039649695	2737.375
160.51904	0.43861714	0.040718727	2738.3108
161.52002	0.44403008	0.042041481	2743.4248
162.521	0.44399112	0.042964716	2744.0371
163.52197	0.44969755	0.044193398	2751.1936
164.52295	0.45099097	0.044986919	2754.0352
165.52393	0.45747608	0.046213612	2766.7185
166.5249	0.45611629	0.047308773	2763.3054
167.52588	0.46259466	0.048475362	2771.2573
168.52686	0.46379304	0.049713627	2765.1873
169.52783	0.46845999	0.050977435	2776.2727
170.52881	0.46881405	0.052308686	2773.8523
171.52979	0.47342956	0.053441554	2779.8477
172.53076	0.47378218	0.054395404	2771.0176
173.53174	0.48000118	0.055520818	2780.1418
174.53271	0.48322713	0.056811668	2793.1958
175.53369	0.48293209	0.058092732	2785.563
176.53467	0.48563927	0.05951716	2788.7173
177.53564	0.48850796	0.060736749	2797.7617
178.53662	0.49576262	0.062094979	2803.7483
179.5376	0.49767873	0.063545488	2801.8396
180.53857	0.49962744	0.065149181	2813.9292
181.53955	0.50160527	0.066525586	2804.4946
182.54053	0.50731587	0.067861505	2805.3997
183.5415	0.50716549	0.068764076	2809.5784
184.54248	0.51235062	0.070056207	2813.3518
185.54346	0.51684529	0.071348764	2815.2739
186.54443	0.51655596	0.072768018	2817.8484
187.54541	0.52015096	0.074241504	2822.9155
188.54639	0.5240522	0.07557039	2818.9438
189.54736	0.52399665	0.077120602	2820.6086
190.54834	0.52588105	0.078582801	2824.3638
191.54932	0.5351162	0.079951338	2829.4309
192.55029	0.53872424	0.081267692	2834.1863
193.55127	0.53783035	0.082689188	2828.9785
194.55225	0.54256988	0.08432705	2841.2109
195.55322	0.54617119	0.085815527	2841.7705
196.5542	0.54681659	0.087256312	2834.3591
197.55518	0.55286199	0.088515863	2841.158
198.55615	0.55285788	0.089728437	2841.7021
199.55713	0.55812889	0.091120631	2846.2979
200.55811	0.56070513	0.092409335	2843.8291
201.55908	0.5648787	0.094028562	2860.7607
202.56006	0.56447774	0.095264748	2849.6245
203.56104	0.56920373	0.096867107	2852.2898
204.56201	0.5697965	0.098145686	2853.3506
205.56299	0.57726812	0.10000486	2867.5579
206.56396	0.5790869	0.10141455	2860.2903
207.56494	0.58203018	0.10303942	2860.0232
208.56592	0.58517581	0.10450131	2863.8071
209.56689	0.58767503	0.10578078	2863.407
210.56787	0.59262019	0.10725396	2862.427
211.56885	0.59503424	0.10856548	2863.061
212.56982	0.59739703	0.11015429	2876.4961
213.5708	0.59856915	0.11148089	2867.228
214.57178	0.6025176	0.11282585	2870.0513
215.57275	0.60468793	0.1144527	2877.3813
216.57373	0.60735929	0.11621851	2877.7925
217.57471	0.61222458	0.11765104	2873.3511
218.57568	0.6153391	0.11902061	2873.74
219.57666	0.61717123	0.1205127	2879.3784
220.57764	0.62438411	0.12198681	2880.5923
221.57861	0.62351602	0.1236878	2888.832
222.57959	0.62547779	0.12522407	2885.9749
223.58057	0.62999398	0.1267157	2888.5039
224.58154	0.63109314	0.12840718	2887.1169
225.58252	0.63505453	0.12992848	2887.9375
226.5835	0.63808584	0.13152182	2892.9246
227.58447	0.64294618	0.13306367	2895.6021
228.58545	0.64553863	0.1344049	2893.2654
229.58643	0.64610332	0.13601433	2891.1658
230.5874	0.6492992	0.13744886	2900.3799
231.58838	0.65310258	0.13904846	2899.4954
232.58936	0.65921557	0.14056881	2901.301
233.59033	0.66064614	0.14218187	2902.7336
234.59131	0.66016644	0.1435366	2898.9023
235.59229	0.66518235	0.14520641	2901.9023
236.59326	0.66826159	0.14681825	2901.5703
237.59424	0.66959441	0.14811291	2903.104
238.59521	0.6752727	0.14983071	2906.6619
239.59619	0.67367661	0.15150194	2909.4294
240.59717	0.68199611	0.15323894	2917.6509
241.59814	0.68492806	0.15469804	2915.573
242.59912	0.68757015	0.15614744	2913.637
243.6001	0.68776602	0.15786341	2918.9424
244.60107	0.69529974	0.15955713	2921.4531
245.60205	0.69533992	0.16126803	2915.0562
246.60303	0.69839376	0.16238749	2919.0332
247.604	0.69992697	0.16356112	2912.188
248.60498	0.70484126	0.16485593	2923.0032
249.60596	0.70569128	0.16631588	2919.9539
250.60693	0.70965016	0.16805913	2922.0762
251.60791	0.71355408	0.16941336	2928.6233
252.60889	0.71468347	0.17118174	2926.0986
253.60986	0.72107476	0.17289206	2931.5359
254.61084	0.72189838	0.17457998	2930.5159
255.61182	0.72170031	0.17619273	2925.3306
256.61279	0.72763199	0.17768721	2931.3064
257.61377	0.73471361	0.1787439	2935.4949
258.61475	0.73257226	0.18019055	2932.6162
259.61572	0.73522002	0.18191472	2936.0046
260.6167	0.74240226	0.18364163	2942.9038
261.61768	0.74347872	0.18515328	2941.8511
262.61865	0.74448514	0.18649341	2935.1497
263.61963	0.75156957	0.18829919	2946.9817
264.62061	0.75124806	0.18974292	2945.0103
265.62158	0.75487542	0.19111466	2942.3308
266.62256	0.75671148	0.1928695	2942.562
267.62354	0.75989479	0.19440366	2941.3254
268.62451	0.7672798	0.19581659	2950.364
269.62549	0.76658046	0.19725199	2949.1494
270.62646	0.7674728	0.19878057	2945.0212
271.62744	0.77692574	0.20055163	2962.7864
272.62842	0.7749359	0.20213664	2952.3582
273.62939	0.78240675	0.20368208	2950.4446
274.63037	0.78169352	0.2052809	2954.1936
275.63135	0.78403848	0.20684631	2957.4536
276.63232	0.78753549	0.20843473	2965.2485
277.6333	0.79219568	0.21033676	2963.802
278.63428	0.79569703	0.21208815	2965.5427
279.63525	0.79614741	0.21354517	2963.0503
280.63623	0.80113763	0.21510427	2961.6047
281.63721	0.80238926	0.21674867	2963.0889
282.63818	0.80639672	0.21823391	2962.563
283.63916	0.80953562	0.2193578	2961.6692
284.64014	0.8177703	0.22069947	2964.8542
285.64111	0.81640267	0.22204311	2967.2832
286.64209	0.81854129	0.22336031	2969.2307
287.64307	0.82072556	0.22493134	2971.0837
288.64404	0.82597446	0.22622165	2974.7832
289.64502	0.82956243	0.22754185	2973.1147
290.646	0.83266568	0.22944263	2978.2512
291.64697	0.83499956	0.23118043	2979.906
292.64795	0.84057194	0.23283599	2982.0857
293.64893	0.83715075	0.23461241	2973.3047
294.6499	0.84322155	0.23610634	2981.0325
295.65088	0.84571487	0.23767905	2985.4155
296.65186	0.85108358	0.23923683	2987.2566
297.65283	0.85234654	0.24101007	2986.3447
298.65381	0.85527027	0.24261934	2980.5266
299.65479	0.85923094	0.2440785	2989.8113
300.65576	0.86311358	0.24557102	2989.0212
301.65674	0.86333406	0.24714893	2990.7012
302.65771	0.86903161	0.24863027	2988.1643
303.65869	0.87063116	0.25016668	2996.3071
304.65967	0.87184042	0.25213274	2992.9917
305.66064	0.87920558	0.25372157	2996.9937
306.66162	0.87795019	0.25491342	2989.667
307.6626	0.88225019	0.25636694	2999.4438
308.66357	0.88564825	0.25809062	2999.2661
309.66455	0.88831079	0.25975713	3003.5286
310.66553	0.89383906	0.26105532	3003.5513
311.6665	0.89202851	0.2626797	2999.2805
312.66748	0.89654607	0.26433256	3004.085
313.66846	0.90071964	0.26615468	3004.5486
314.66943	0.90224159	0.26752275	3002.8604
315.67041	0.90495002	0.26891997	3004.5339
316.67139	0.91048932	0.27067408	3014.0708
317.67236	0.91174656	0.27231833	3005.1118
318.67334	0.91525835	0.27370855	3011.3875
319.67432	0.91925824	0.27528983	3009.4521
320.67529	0.92418718	0.27673107	3010.9666
321.67627	0.92756432	0.27815738	3013.3633
322.67725	0.92512703	0.27953553	3005.478
323.67822	0.93055248	0.28092355	3016.9976
324.6792	0.93150747	0.28227407	3012.8953
325.68018	0.93614823	0.28382808	3015.7559
326.68115	0.93831241	0.28553179	3015.5913
327.68213	0.94428533	0.28701603	3015.2673
328.68311	0.9457255	0.28816742	3013.6362
329.68408	0.94794279	0.28988209	3020.1621
330.68506	0.94917709	0.29147828	3014.9373
331.68604	0.9520756	0.29291695	3018.7966
332.68701	0.9610014	0.29444495	3022.2004
333.68799	0.95901215	0.29592693	3021.5378
334.68896	0.96249419	0.29752871	3022.2825
335.68994	0.96831155	0.29920438	3033.9192
336.69092	0.96949321	0.30070797	3028.7854
337.69189	0.97081882	0.30231857	3031.0056
338.69287	0.97622073	0.30391505	3028.8982
339.69385	0.97580153	0.30551937	3025.4487
340.69482	0.97698432	0.30730045	3032.0229
341.6958	0.98694605	0.30896437	3035.1758
342.69678	0.98623323	0.31066656	3037.9673
343.69775	0.9908219	0.3122786	3036.5142
344.69873	0.99414086	0.31361547	3027.2898
345.69971	0.9962846	0.31506312	3036.0237
346.70068	1.000505	0.31644544	3041.0886
347.70166	1.0061095	0.31797636	3042.6016
348.70264	1.0051801	0.31941462	3042.7222
349.70361	1.0082743	0.32096058	3043.2058
350.70459	1.010192	0.32259786	3044.3818
351.70557	1.0149975	0.32407504	3048.572
352.70654	1.020391	0.32572576	3047.0581
353.70752	1.0220461	0.32726175	3045.416
354.7085	1.0215831	0.32873377	3040.5466
355.70947	1.0260074	0.33020842	3042.6333
356.71045	1.0301113	0.33168358	3046.0337
357.71143	1.0312493	0.33306631	3048.3013
358.7124	1.037215	0.33459112	3050.623
359.71338	1.0404937	0.33620173	3052.1187
360.71436	1.0396568	0.33768111	3048.6987
361.71533	1.0445236	0.33924994	3049.7031
362.71631	1.0493979	0.34074938	3053.9666
363.71729	1.0505041	0.34225744	3056.9631
364.71826	1.0525451	0.34359232	3047.0791
365.71924	1.0556759	0.34493613	3055.521
366.72021	1.0567999	0.34636632	3056.6541
367.72119	1.0645982	0.34791464	3060.9321
368.72217	1.0654563	0.34951785	3061.6213
369.72314	1.0670215	0.35134217	3057.3494
370.72412	1.0706987	0.35283399	3060.7046
371.7251	1.0727718	0.35431847	3066.7046
372.72607	1.0763891	0.35572234	3064.7517
373.72705	1.0796938	0.35740235	3066.176
374.72803	1.082473	0.35901603	3066.2966
375.729	1.0881491	0.36054412	3066.6184
376.72998	1.0876197	0.36183724	3065.2112
377.73096	1.0939145	0.36320439	3070.9055
378.73193	1.0957402	0.36478159	3073.5784
379.73291	1.0982968	0.3663756	3070.9329
380.73389	1.1002964	0.36803377	3073.1138
381.73486	1.1051508	0.36966202	3074.4253
382.73584	1.1075534	0.37121394	3069.9707
383.73682	1.1097604	0.37275249	3073.7344
384.73779	1.1154656	0.37391445	3068.2183
385.73877	1.1165594	0.37560186	3075.2578
386.73975	1.1222342	0.37706056	3080.1887
387.74072	1.1226876	0.37868631	3079.1287
388.7417	1.1253772	0.38026378	3080.1313
389.74268	1.1279083	0.38209331	3083.9475
390.74365	1.1310048	0.38373202	3083.2119
391.74463	1.1342181	0.38516438	3083.3877
392.74561	1.136434	0.38668108	3076.363
393.74658	1.1408678	0.38805547	3083.0884
394.74756	1.1409315	0.38945234	3087.4084
395.74854	1.1416717	0.39113945	3082.0967
396.74951	1.1485155	0.39272997	3086.2461
397.75049	1.148751	0.39425698	3084.6748
398.75146	1.1537106	0.39535394	3083.1951
399.75244	1.1582472	0.39673772	3089.9937
400.75342	1.1597667	0.39808533	3092.6111
401.75439	1.1648861	0.39966238	3095.7058
402.75537	1.1656034	0.4011279	3094.0579
403.75635	1.1706821	0.40265879	3094.5
404.75732	1.1735104	0.40436587	3099.6396
405.7583	1.1785748	0.40601712	3094.0737
406.75928	1.1802845	0.40760526	3095.7095
407.76025	1.1820778	0.40915796	3098.938
408.76123	1.1868653	0.41041902	3095.6667
409.76221	1.1850718	0.4120481	3103.3311
410.76318	1.1911893	0.41369441	3101.02
411.76416	1.1943334	0.41519508	3104.6765
412.76514	1.1968001	0.41678047	3102.9819
413.76611	1.2015146	0.4181909	3101.6995
414.76709	1.2010612	0.41961211	3101.7029
415.76807	1.2057166	0.42099318	3103.0923
416.76904	1.2094259	0.42261079	3107.8149
417.77002	1.2118553	0.42425305	3109.0876
418.771	1.2127658	0.42550775	3103.1033
419.77197	1.2167464	0.4269551	3104.4958
420.77295	1.2190819	0.42887822	3108.0525
421.77393	1.2244691	0.43018457	3107.5046
422.7749	1.2256169	0.43175125	3111.8896
423.77588	1.2300005	0.4335587	3116.3584
424.77686	1.233284	0.43511584	3109.752
425.77783	1.2364893	0.43657529	3115.6997
426.77881	1.2395866	0.43799409	3117.7388
427.77979	1.2428641	0.43918771	3108.8394
428.78076	1.245438	0.44043046	3113.6177
429.78174	1.2458981	0.44179016	3118.1316
430.78271	1.2460699	0.4434137	3115.6475
431.78369	1.2543082	0.4449642	3114.6934
432.78467	1.2587484	0.44640106	3115.8311
433.78564	1.2601122	0.44785255	3119.1406
434.78662	1.261934	0.44927558	3116.0781
435.7876	1.2651227	0.45090356	3123.2554
436.78857	1.2711401	0.45244583	3128.8477
437.78955	1.2726611	0.45418146	3129.0227
438.79053	1.272563	0.45590654	3116.6987
439.7915	1.2774785	0.45733935	3128.561
440.79248	1.2828491	0.45892149	3128.5769
441.79346	1.2865742	0.46049711	3130.9663
442.79443	1.285336	0.4619225	3120.7256
443.79541	1.2908291	0.46332404	3126.907
444.79639	1.2933848	0.46474785	3132.5496
445.79736	1.2965832	0.46649039	3138.0051
446.79834	1.2975234	0.4680551	3128.9175
447.79932	1.3026847	0.46944633	3130.9446
448.80029	1.3060125	0.47089347	3130.2783
449.80127	1.3060356	0.47228283	3134.5571
450.80225	1.3113046	0.47387061	3136.8962
451.80322	1.3136991	0.47546083	3138.3188
452.8042	1.3160248	0.47723094	3137.0542
453.80518	1.3197863	0.47893801	3131.3071
454.80615	1.3252134	0.48021284	3136.7297
455.80713	1.3246909	0.48168877	3135.4031
456.80811	1.3299855	0.48315552	3137.8899
457.80908	1.3314271	0.48474541	3141.3271
458.81006	1.3381954	0.48627836	3142.783
459.81104	1.3394641	0.48760262	3140.2927
460.81201	1.3410077	0.48915875	3141.1357
461.81299	1.3401154	0.49055785	3143.3694
462.81396	1.3507588	0.49195224	3142.6663
463.81494	1.3530124	0.49359813	3154.5947
464.81592	1.3547205	0.49498725	3147.6692
465.81689	1.3545877	0.49664757	3151.6965
466.81787	1.3591133	0.498005	3144.4111
467.81885	1.3631053	0.49974585	3150.467
468.81982	1.3662492	0.50102454	3146.6816
469.8208	1.3684337	0.50243944	3146.4285
470.82178	1.3700992	0.50387174	3152.6467
471.82275	1.3765572	0.50519145	3149.8303
472.82373	1.3771932	0.50683856	3151.1184
473.82471	1.3833535	0.50839424	3158.084
474.82568	1.3837104	0.5099622	3155.7324
475.82666	1.3890678	0.51142913	3156.8618
476.82764	1.3901998	0.51301301	3158.8911
477.82861	1.3924968	0.5143221	3154.0498
478.82959	1.3960987	0.51588714	3159.0361
479.83057	1.3997912	0.5173772	3162.8352
480.83154	1.4030877	0.51858866	3158.7983
481.83252	1.4033012	0.52010185	3158.0322
482.8335	1.4048022	0.52174431	3163.3645
483.83447	1.410267	0.52375257	3165.3594
484.83545	1.4140667	0.52540451	3164.7622
485.83643	1.4161032	0.52690071	3165.0066
486.8374	1.4194483	0.52844298	3156.8445
487.83838	1.4215615	0.52989924	3164.595
488.83936	1.4258304	0.53142875	3167.5615
489.84033	1.4303519	0.53266698	3158.8567
490.84131	1.4290299	0.53396469	3155.8486
491.84229	1.4350932	0.5355832	3173.751
492.84326	1.4375135	0.53716969	3168.7695
493.84424	1.4413838	0.53895265	3172.4136
494.84521	1.4454871	0.54061502	3173.7039
495.84619	1.445009	0.54211187	3168.5474
496.84717	1.4511359	0.54358923	3169.2866
497.84814	1.4515945	0.5450682	3165.3467
498.84912	1.4566849	0.54627407	3167.7751
499.8501	1.4573771	0.54750073	3162.905
500.85107	1.4584869	0.54890907	3172.7605
501.85205	1.4650583	0.55023503	3173.9919
502.85303	1.4680843	0.5516597	3179.6406
503.854	1.4692668	0.55317396	3176.4858
504.85498	1.4728197	0.55470908	3175.2888
505.85596	1.478114	0.55647415	3176.3853
506.85693	1.4802881	0.55792075	3180.2427
507.85791	1.4815527	0.55965066	3176.6521
508.85889	1.4842869	0.56130356	3181.4189
509.85986	1.4907221	0.56281257	3178.1074
510.86084	1.4939581	0.56408107	3174.9836
511.86182	1.4957013	0.56539732	3181.8091
512.86279	1.4970779	0.56686002	3181.1267
513.86377	1.5011183	0.56821829	3183.3264
514.86475	1.5041285	0.56987166	3186.3892
515.86572	1.5060449	0.57153046	3187.8386
516.8667	1.5087202	0.57339174	3191.9951
517.86768	1.5120952	0.57524258	3191.0149
518.86865	1.5169274	0.57698768	3188.1428
519.86963	1.5190395	0.57847297	3185.8267
520.87061	1.5215102	0.57992929	3187.3342
521.87158	1.5246971	0.58142883	3191.6335
522.87256	1.5247518	0.58280522	3184.5129
523.87354	1.5313965	0.58413875	3179.5081
524.87451	1.5330631	0.58538377	3187.5898
525.87549	1.5358824	0.58686888	3185.7107
526.87646	1.5376401	0.58850884	3195.7285
527.87744	1.5419492	0.58995837	3198.3347
528.87842	1.5466659	0.59175831	3197.4016
529.87939	1.5476662	0.59342092	3191.8125
530.88037	1.5492202	0.59506977	3194.3018
531.88135	1.5539825	0.59674239	3198.314
532.88232	1.5579671	0.59859133	3196.4092
533.8833	1.5624757	0.60003406	3197.0933
534.88428	1.5626951	0.60139018	3194.6665
535.88525	1.5640253	0.60290504	3196.2188
536.88623	1.5736243	0.60445154	3206.1477
537.88721	1.5722345	0.60615134	3198.7495
538.88818	1.5733422	0.60755759	3199.3428
539.88916	1.5793344	0.60898167	3195.6741
540.89014	1.5806153	0.61057115	3206.9426
541.89111	1.5820472	0.61202031	3200.2065
542.89209	1.5882665	0.61361527	3201.8242
543.89307	1.5916358	0.61518317	3204.6348
544.89404	1.5916977	0.61686456	3202.7888
545.89502	1.5972596	0.61833471	3212.8049
546.896	1.6014684	0.61976254	3203.1558
547.89697	1.6044861	0.62095505	3202.1648
548.89795	1.6052217	0.62245578	3204.9814
549.89893	1.6085348	0.62407243	3208.3757
550.8999	1.611225	0.62568641	3212.1636
551.90088	1.6122227	0.6274361	3208.7021
552.90186	1.6203065	0.62912506	3215.481
553.90283	1.6207731	0.63099921	3212.1392
554.90381	1.6236939	0.63280606	3213.6021
555.90479	1.6262839	0.63439387	3210.1089
556.90576	1.6294749	0.63614041	3210.2314
557.90674	1.6344818	0.63756877	3215.2576
558.90771	1.6348276	0.63913071	3209.9768
559.90869	1.6358243	0.64054954	3206.8164
560.90967	1.6404729	0.64208335	3211.4165
561.91064	1.6443492	0.64345622	3212.9688
562.91162	1.6459129	0.64512199	3221.6038
563.9126	1.6499161	0.64652056	3212.248
564.91357	1.6562426	0.64810234	3220.0271
565.91455	1.6530881	0.64961469	3215.5342
566.91553	1.6587424	0.65123117	3215.0698
567.9165	1.6641779	0.65298033	3214.8794
568.91748	1.6646922	0.65427184	3220.0127
569.91846	1.6707245	0.65534413	3209.6389
570.91943	1.6712109	0.6566785	3217.3909
571.92041	1.6765409	0.65830827	3225.0933
572.92139	1.6785778	0.65988272	3222.2205
573.92236	1.679428	0.66123098	3214.4517
574.92334	1.6859288	0.66308832	3225.4277
575.92432	1.6893997	0.66451693	3218.0176
576.92529	1.687945	0.66599065	3218.9268
577.92627	1.691658	0.66772467	3219.5405
578.92725	1.6941266	0.6694023	3218.7642
579.92822	1.6986568	0.6711027	3228.7761
580.9292	1.7006766	0.67233884	3222.8708
581.93018	1.7044629	0.67395103	3219.6702
582.93115	1.7066468	0.67536688	3223.6921
583.93213	1.7111132	0.67689258	3230.4597
584.93311	1.7120512	0.67858142	3227.1963
585.93408	1.7155029	0.67984897	3226.9846
586.93506	1.7207532	0.6818077	3229.8071
587.93604	1.7219864	0.68377072	3231.3384
588.93701	1.7266032	0.68567151	3230.8298
589.93799	1.729461	0.687433	3234.7942
590.93896	1.7330905	0.6889838	3230.7678
591.93994	1.7328895	0.69044936	3232.134
592.94092	1.7365634	0.69182122	3224.8508
593.94189	1.7397628	0.69344729	3231.8147
594.94287	1.7444831	0.6949749	3230.833
595.94385	1.7463232	0.6966902	3234.1448
596.94482	1.7511115	0.69798857	3230.2627
597.9458	1.751456	0.69951016	3234.5332
598.94678	1.7568637	0.70148933	3239.0999
599.94775	1.7554537	0.70323497	3232.9709
600.94873	1.760191	0.70495939	3232.1797
601.94971	1.7647632	0.70629007	3232.8003
602.95068	1.7706028	0.70784551	3237.02
603.95166	1.7717865	0.7094624	3243.2478
604.95264	1.7731991	0.71116	3239.0061
605.95361	1.7752353	0.71281642	3239.9331
606.95459	1.779621	0.71431649	3244.3596
607.95557	1.7846411	0.71617103	3242.7463
608.95654	1.784192	0.71759605	3233.9946
609.95752	1.7888219	0.71939111	3238.9675
610.9585	1.7919312	0.72108281	3237.4082
611.95947	1.7956716	0.72230053	3228.3999
612.96045	1.7973969	0.72370487	3237.8313
613.96143	1.8008351	0.72514743	3237.6504
614.9624	1.8036839	0.72675949	3240.2212
615.96338	1.8082626	0.72835565	3246.448
616.96436	1.8094807	0.73011941	3245.5029
617.96533	1.8124777	0.73180193	3247.0615
618.96631	1.8180114	0.73324555	3243.281
619.96729	1.8166993	0.73498791	3245.9756
620.96826	1.8247757	0.73665762	3249.9136
621.96924	1.826665	0.738186	3244.1941
622.97021	1.8305659	0.73960751	3245.3623
623.97119	1.8334264	0.74132603	3254.9875
624.97217	1.8330352	0.74313158	3247.6003
625.97314	1.8375037	0.74482453	3244.644
626.97412	1.8407478	0.74645215	3248.6218
627.9751	1.8429343	0.74807775	3245.2383
628.97607	1.8430686	0.75003791	3254.5991
629.97705	1.8472893	0.75171119	3251.9412
630.97803	1.8497056	0.75351763	3247.4229
631.979	1.8561987	0.75493383	3243.7878
632.97998	1.8534743	0.7566694	3252.0857
633.98096	1.8615448	0.75854337	3254.4629
634.98193	1.8634536	0.76009917	3249.6519
635.98291	1.8658389	0.7619065	3252.728
636.98389	1.8720579	0.76367599	3259.4473
637.98486	1.8750563	0.76572663	3256.251
638.98584	1.8754127	0.76744694	3244.2268
639.98682	1.879021	0.76891732	3257.0764
640.98779	1.8818704	0.77046126	3248.6555
641.98877	1.8864599	0.77176046	3253.8867
642.98975	1.8870596	0.7730816	3249.4521
643.99072	1.8938072	0.77458698	3255.5554
644.9917	1.8926371	0.77640325	3257.8022
645.99268	1.8967712	0.7779662	3256.4224
646.99365	1.9011908	0.77980012	3257.7986
647.99463	1.9016078	0.78138924	3253.0557
648.99561	1.9068558	0.78308964	3254.8438
649.99658	1.9069059	0.78495157	3254.2705
650.99756	1.9126097	0.78668839	3252.824
651.99854	1.9174862	0.78824526	3254.3716
652.99951	1.9168613	0.78978568	3257.7888
654.00049	1.9204866	0.79155093	3259.9307
655.00146	1.9260887	0.79343021	3260.082
656.00244	1.9265436	0.79526329	3261.3816
657.00342	1.9333471	0.79723215	3268.98
658.00439	1.9314361	0.79885584	3259.5293
659.00537	1.9363743	0.80044389	3258.2842
660.00635	1.9423884	0.8020317	3266.5969
661.00732	1.9433913	0.80366796	3262.4355
662.0083	1.9453416	0.80549818	3264.4919
663.00928	1.947353	0.80693972	3260.0166
664.01025	1.9489198	0.80843419	3258.3518
665.01123	1.9523681	0.81062216	3263.1829
666.01221	1.9573462	0.81255478	3264.7166
667.01318	1.9601449	0.81422961	3265.2307
668.01416	1.9633952	0.81591827	3258.6265
669.01514	1.9643379	0.81757653	3258.1279
670.01611	1.9670832	0.81921852	3267.5171
671.01709	1.9708573	0.82076126	3254.8569
672.01807	1.9758745	0.82220787	3265.1609
673.01904	1.9787837	0.82400173	3263.0986
674.02002	1.9802699	0.82592475	3271.4651
675.021	1.9857805	0.8275997	3266.416
676.02197	1.9873064	0.82934755	3265.4885
677.02295	1.9902956	0.83110791	3271.6963
678.02393	1.9941015	0.83296812	3268.9407
679.0249	1.9925383	0.83470172	3259.9395
680.02588	1.9928019	0.83646721	3261.4709
681.02686	2.0032349	0.83819449	3262.209
682.02783	2.0052524	0.84010017	3268.2412
683.02881	2.0096657	0.84175551	3267.0278
684.02979	2.0104847	0.84319723	3264.686
685.03076	2.0126262	0.84485257	3267.3464
686.03174	2.0169222	0.84654891	3271.553
687.03271	2.0162773	0.84834409	3268.4497
688.03369	2.0213218	0.85057265	3274.3401
689.03467	2.0265183	0.85211235	3267.1658
690.03564	2.031486	0.85402876	3270.7517
691.03662	2.030314	0.8556174	3272.2278
692.0376	2.0347033	0.85729307	3270.6877
693.03857	2.0406592	0.85885561	3274.5325
694.03955	2.0392914	0.8607651	3270.3274
695.04053	2.0440345	0.86288738	3278.2842
696.0415	2.0476503	0.86502272	3274.6187
697.04248	2.0522468	0.86704117	3275.4565
698.04346	2.0537357	0.86874378	3270.7937
699.04443	2.0569108	0.87030327	3268.4092
700.04541	2.0599868	0.87222368	3275.0383
701.04639	2.062309	0.87395805	3272.0837
702.04736	2.0668292	0.87578696	3279.9946
703.04834	2.0685244	0.87730289	3268.7395
704.04932	2.0727105	0.87889755	3275.9976
705.05029	2.0762947	0.88066399	3274.6519
706.05127	2.0762537	0.88252336	3275.4766
707.05225	2.0800972	0.88443482	3274.6208
708.05322	2.0806608	0.88623172	3272.2576
709.0542	2.0881081	0.88794917	3273.8176
710.05518	2.0906546	0.88974375	3275.79
711.05615	2.0898201	0.89166921	3277.3999
712.05713	2.0918083	0.8934797	3267.9744
713.05811	2.0988822	0.89515734	3274.7705
714.05908	2.1021123	0.89681983	3276.0217
715.06006	2.1036551	0.89879185	3275.999
716.06104	2.1084235	0.90051472	3280.1177
717.06201	2.107882	0.90231258	3273.8643
718.06299	2.1114898	0.90392375	3274.0732
719.06396	2.1133699	0.90591145	3278.875
720.06494	2.1210699	0.90766537	3280.0911
721.06592	2.1209946	0.90978509	3279.8484
722.06689	2.1274624	0.91174179	3281.6531
723.06787	2.1277854	0.91356099	3275.9626
724.06885	2.128556	0.9152348	3276.5178
725.06982	2.1341429	0.91744864	3287.0159
726.0708	2.1339881	0.91931355	3276.5225
727.07178	2.142652	0.92107886	3275.5581
728.07275	2.1435714	0.92295194	3276.7141
729.07373	2.1438925	0.92471975	3276.4919
730.07471	2.1473098	0.92684168	3279.4641
731.07568	2.1539335	0.92877501	3283.1563
732.07666	2.1527476	0.93066597	3274.4922
733.07764	2.1587262	0.93219876	3277.4763
734.07861	2.1610508	0.93415499	3282.9033
735.07959	2.1661251	0.93588364	3283.3572
736.08057	2.1664138	0.93801904	3277.9961
737.08154	2.1694043	0.93986899	3277.8857
738.08252	2.1743772	0.94187981	3280.1064
739.0835	2.1751804	0.94384539	3281.0686
740.08447	2.1763339	0.9460305	3283.4336
741.08545	2.1829505	0.94804668	3287.4426
742.08643	2.1837151	0.94980991	3276.5466
743.0874	2.186033	0.95158911	3275.3552
744.08838	2.191314	0.95330173	3279.7354
745.08936	2.1961522	0.9553473	3288.6792
746.09033	2.1990261	0.95750958	3283.3958
747.09131	2.2007432	0.95935744	3284.0088
748.09229	2.2024093	0.96150374	3281.0247
749.09326	2.2064872	0.96328944	3279.2773
750.09424	2.2101123	0.96560991	3286.5081
751.09521	2.2109649	0.96758372	3278.8577
752.09619	2.2149434	0.96958143	3283.0442
753.09717	2.2193401	0.97148442	3280.0793
754.09814	2.2219129	0.97313386	3284.3059
755.09912	2.2253828	0.97505498	3282.7051
756.1001	2.2299943	0.97684103	3280.0193
757.10107	2.2280335	0.97865629	3281.9807
758.10205	2.2306945	0.98087448	3278.5779
759.10303	2.2357175	0.9827702	3289.1467
760.104	2.2434826	0.98500043	3289.9634
761.10498	2.2389724	0.98679191	3278.3721
762.10596	2.244343	0.98869741	3280.0034
763.10693	2.247916	0.99066406	3284.5398
764.10791	2.2518668	0.99270511	3281.1252
765.10889	2.257257	0.99462074	3287.1599
766.10986	2.2581463	0.99611366	3275.5786
767.11084	2.2602727	0.99828899	3282.0942
768.11182	2.2632122	1.0000168	3282.8911
769.11279	2.2680202	1.0020995	3292.0249
770.11377	2.2707903	1.0043885	3290.3347
771.11475	2.2719796	1.0064992	3285.8965
772.11572	2.2757654	1.0084338	3281.7854
773.1167	2.2772908	1.0104899	3283.2285
774.11768	2.2828052	1.0126493	3282.8115
775.11865	2.2824941	1.0148273	3285.2039
776.11963	2.2875283	1.0172087	3282.1191
777.12061	2.2886264	1.0196552	3283.1252
778.12158	2.2924967	1.0216689	3281.3235
779.12256	2.2955341	1.0234932	3280.6438
780.12354	2.3022709	1.0257002	3289.2153
781.12451	2.3023906	1.0280384	3282.5757
782.12549	2.3056483	1.0301697	3280.8958
783.12646	2.306231	1.0324348	3280.1665
784.12744	2.3111062	1.0345051	3279.4739
785.12842	2.3166907	1.036406	3286.2595
786.12939	2.3185122	1.0383831	3285.8442
787.13037	2.3220272	1.0400455	3280.8826
788.13135	2.3248863	1.0420953	3290.3169
789.13232	2.3244741	1.0439799	3279.9917
790.1333	2.3276043	1.0457683	3280.521
791.13428	2.3300104	1.0476185	3279.6274
792.13525	2.3331494	1.0497808	3282.0203
793.13623	2.3386447	1.0520784	3289.6699
794.13721	2.3400288	1.0547292	3288.0369
795.13818	2.3461764	1.0571017	3278.7439
796.13916	2.3492973	1.0590714	3284.0046
797.14014	2.3514192	1.0610571	3287.6553
798.14111	2.3551104	1.0633109	3287.3428
799.14209	2.3550098	1.0656031	3282.6975
800.14307	2.3613193	1.0680404	3287.0015
801.14404	2.3630993	1.070052	3282.1648
802.14502	2.3662472	1.0724672	3285.322
803.146	2.3702352	1.0747072	3287.7444
804.14697	2.3706541	1.077348	3282.8079
805.14795	2.3744791	1.0796926	3278.3328
806.14893	2.3781905	1.0819352	3280.9797
807.1499	2.3801622	1.0838431	3282.3337
808.15088	2.3837438	1.0857595	3283.5869
809.15186	2.3883312	1.0874766	3275.4316
810.15283	2.3895776	1.089299	3278.1694
811.15381	2.3941963	1.0914048	3288.2061
812.15479	2.3921187	1.0938638	3277.5813
813.15576	2.4002082	1.0963061	3288.7236
814.15674	2.4044764	1.0990628	3285.2939
815.15771	2.4070134	1.1013211	3286.9021
816.15869	2.4090292	1.1039166	3288.927
817.15967	2.4111032	1.1061308	3275.3616
818.16064	2.4146118	1.108264	3283.7568
819.16162	2.4154289	1.1103649	3276.4153
820.1626	2.4195554	1.1126251	3275.3599
821.16357	2.4240911	1.1147932	3284.0042
822.16455	2.4247379	1.1168841	3277.2974
823.16553	2.4278166	1.1190771	3276.1694
824.1665	2.4324462	1.1209086	3273.7749
825.16748	2.4324787	1.1229298	3278.8586
826.16846	2.4376702	1.1254729	3285.0049
827.16943	2.4379485	1.1282815	3281.0105
828.17041	2.4433794	1.1309137	3281.8901
829.17139	2.4461789	1.1335107	3279.5425
830.17236	2.451385	1.1361328	3285.4792
831.17334	2.4509821	1.1381923	3279.1475
832.17432	2.4531348	1.1401076	3276.4333
833.17529	2.4584031	1.1420364	3275.8159
834.17627	2.4612453	1.1443208	3279.1013
835.17725	2.462466	1.1464013	3273.981
836.17822	2.4693074	1.1484724	3277.0168
837.1792	2.4708869	1.1511	3287.2629
838.18018	2.4730973	1.1534809	3279.0996
839.18115	2.4775417	1.1559474	3273.9656
840.18213	2.4812276	1.1583658	3274.8748
841.18311	2.4827089	1.1609985	3275.437
842.18408	2.48757	1.1634598	3278.4148
843.18506	2.4874134	1.1659927	3282.7305
844.18604	2.4902365	1.1687894	3279.6021
845.18701	2.4946046	1.1715131	3277.166
846.18799	2.4979131	1.1737545	3272.0542
847.18896	2.5015173	1.1758397	3275.2251
848.18994	2.5052257	1.1779629	3271.0481
849.19092	2.505805	1.180065	3276.3696
850.19189	2.5071564	1.1823761	3276.312
851.19287	2.5139616	1.1849933	3273.9612
852.19385	2.5165317	1.1873226	3277.5042
853.19482	2.5171978	1.1901	3276.4805
854.1958	2.519448	1.192591	3274.9438
855.19678	2.5228438	1.1951745	3270.604
856.19775	2.5251415	1.1976068	3271.6643
857.19873	2.532449	1.1998669	3270.6279
858.19971	2.537241	1.2020233	3271.0657
859.20068	2.5364559	1.2040199	3269.8679
860.20166	2.5394373	1.2059491	3271.6775
861.20264	2.544349	1.2085184	3277.5701
862.20361	2.5493224	1.2111365	3270.8013
863.20459	2.5485094	1.21383	3267.8447
864.20557	2.550236	1.2164565	3268.9858
865.20654	2.5553777	1.2190334	3266.2622
866.20752	2.5580938	1.2216301	3269.1316
867.2085	2.5616214	1.2241721	3272.9651
868.20947	2.5640457	1.2269726	3268.0886
869.21045	2.5683987	1.2296183	3264.4019
870.21143	2.5683522	1.2317746	3262.9988
871.2124	2.5714719	1.2343367	3265.4199
872.21338	2.572197	1.2368683	3263.1377
873.21436	2.5813584	1.2394989	3264.97
874.21533	2.5806968	1.2421225	3264.5884
875.21631	2.5858912	1.2450022	3265.4023
876.21729	2.585494	1.2478957	3263.6411
877.21826	2.5881743	1.2505046	3258.1545
878.21924	2.5920279	1.2532978	3256.7007
879.22021	2.5954063	1.2560694	3260.9224
880.22119	2.6004388	1.2585038	3261.1167
881.22217	2.60337	1.2608881	3258.6895
882.22314	2.6056848	1.2637061	3266.6389
883.22412	2.6106138	1.266798	3267.1787
884.2251	2.6104627	1.2691642	3252.5176
885.22607	2.6152897	1.2716763	3263.0854
886.22705	2.6199002	1.2746856	3263.7837
887.22803	2.6234641	1.2771602	3257.375
888.229	2.6234305	1.2796948	3257.8047
889.22998	2.6298025	1.2824612	3257.6619
890.23096	2.6275778	1.2854533	3256.1128
891.23193	2.6344743	1.2883892	3263.8398
892.23291	2.6368854	1.2912041	3261.2324
893.23389	2.639333	1.2940199	3249.8164
894.23486	2.6419592	1.2965674	3247.5435
895.23584	2.6471756	1.2990565	3251.1389
896.23682	2.6487114	1.3019108	3251.1895
897.23779	2.6510797	1.304428	3251.2854
898.23877	2.6544752	1.3071437	3248.9277
899.23975	2.6575768	1.3096597	3248.2258
900.24072	2.6608355	1.3123198	3249.3647
901.2417	2.6659174	1.3146752	3251.1748
902.24268	2.665832	1.3173434	3256.5632
903.24365	2.6693237	1.3200129	3245.5427
904.24463	2.6707098	1.3225855	3248.2871
905.24561	2.6728768	1.3250127	3238.0623
906.24658	2.6774783	1.3275781	3249.6633
907.24756	2.6815636	1.3303951	3246.7637
908.24854	2.6828318	1.3329767	3242.2781
909.24951	2.6863618	1.3355674	3240.52
910.25049	2.6912205	1.3382432	3247.7212
911.25146	2.6926389	1.340987	3240.9617
912.25244	2.6947982	1.343861	3244.0337
913.25342	2.7006159	1.3468369	3239.019
914.25439	2.7009554	1.350202	3243.4998
915.25537	2.704752	1.3528544	3230.5427
916.25635	2.709476	1.3554467	3238.541
917.25732	2.71279	1.3580842	3235.9771
918.2583	2.7132871	1.3608236	3234.428
919.25928	2.7192776	1.3638419	3241.0623
920.26025	2.7199576	1.3669162	3236.4309
921.26123	2.7194536	1.3698547	3229.9468
922.26221	2.7262421	1.3726338	3226.1309
923.26318	2.7292836	1.3753337	3229.2739
924.26416	2.7312758	1.3781883	3226.262
925.26514	2.7378428	1.3813819	3231.8069
926.26611	2.7365055	1.3841786	3225.7893
927.26709	2.7383246	1.3869858	3222.1636
928.26807	2.7438142	1.3895262	3220.2183
929.26904	2.7490766	1.3915412	3221.8711
930.27002	2.7531488	1.3940946	3231.624
931.271	2.7557814	1.3973495	3224.3638
932.27197	2.7560029	1.4005868	3227.1545
933.27295	2.7592535	1.4037323	3219.0952
934.27393	2.7590024	1.4064617	3216.1592
935.2749	2.7659466	1.4091054	3221.3628
936.27588	2.7709146	1.4121619	3223.1455
937.27686	2.7707098	1.4154456	3213.7102
938.27783	2.773706	1.4182516	3207.4529
939.27881	2.7798944	1.4212832	3221.989
940.27979	2.7804921	1.4242803	3212.1545
941.28076	2.7827921	1.4274269	3209.2725
942.28174	2.7870324	1.430216	3210.491
943.28271	2.7891724	1.4327166	3208.1799
944.28369	2.791811	1.4353827	3209.1426
945.28467	2.7935832	1.4386852	3205.9309
946.28564	2.7983878	1.4414167	3203.9695
947.28662	2.8018789	1.444477	3203.5342
948.2876	2.8016987	1.4483441	3204.2593
949.28857	2.8056393	1.4514283	3195.1877
950.28955	2.8113317	1.4542785	3199.814
951.29053	2.8128226	1.4567456	3192.8911
952.2915	2.8180728	1.4597884	3202.3154
953.29248	2.8195662	1.4622352	3189.9609
954.29346	2.8245575	1.4649209	3200.9775
955.29443	2.8274817	1.4680233	3199.2393
956.29541	2.8274043	1.471125	3194.4756
957.29639	2.8308632	1.4744531	3193.4783
958.29736	2.8353398	1.4773107	3183.3892
959.29834	2.8395083	1.4803271	3193.2585
960.29932	2.8392186	1.4835641	3186.5964
961.30029	2.8441179	1.4867253	3183.9751
962.30127	2.8464079	1.4898007	3178.5579
963.30225	2.8492558	1.4926399	3181.3779
964.30322	2.8525279	1.4955547	3181.4561
965.3042	2.8548341	1.4983907	3176.7808
966.30518	2.8587215	1.5012641	3178.9441
967.30615	2.8611217	1.5041445	3172.0752
968.30713	2.8657687	1.5070556	3171.8699
969.30811	2.8639758	1.509432	3169.7458
970.30908	2.8697531	1.512112	3168.0332
971.31006	2.872591	1.5153453	3174.3745
972.31104	2.876627	1.5190445	3170.4424
973.31201	2.8837183	1.5221062	3159.1985
974.31299	2.8828654	1.5248443	3161.9712
975.31396	2.8869956	1.5276192	3166.803
976.31494	2.8890221	1.5307729	3159.635
977.31592	2.8883066	1.5335696	3157.8804
978.31689	2.8944395	1.5364089	3157.5474
979.31787	2.8981824	1.5395736	3161.665
980.31885	2.899179	1.5429245	3154.1897
981.31982	2.902416	1.5461411	3151.6357
982.3208	2.906745	1.5495178	3148.676
983.32178	2.9080963	1.5522591	3145.9001
984.32275	2.9135826	1.5547676	3142.0181
985.32373	2.9155977	1.557505	3145.9417
986.32471	2.9196951	1.5601337	3143.6023
987.32568	2.9238412	1.5639298	3149.3506
988.32666	2.9216101	1.5676963	3140.0901
989.32764	2.9263086	1.5707134	3130.8374
990.32861	2.9315894	1.5734491	3130.7412
991.32959	2.9313653	1.5760365	3131.4731
992.33057	2.9377916	1.5790573	3137.9839
993.33154	2.9395139	1.582821	3142.5437
994.33252	2.9390371	1.5863591	3127.1965
995.3335	2.9451556	1.5894514	3120.8157
996.33447	2.948663	1.5926981	3124.8916
997.33545	2.9506633	1.5963269	3124.9575
998.33643	2.9548028	1.6001165	3118.9197
999.3374	2.9581616	1.6026765	3113.3364
1000.3384	2.9569895	1.6053917	3110.9285
1001.3394	2.9609375	1.608456	3110.0383
1002.3403	2.9672754	1.6112894	3114.0662
1003.3413	2.9695816	1.6137172	3103.2744
1004.3423	2.9710093	1.6164706	3107.6763
1005.3433	2.9738207	1.6194403	3108.5134
1006.3442	2.9792557	1.622921	3100.4736
1007.3452	2.9794557	1.6259879	3097.8142
1008.3462	2.9846394	1.6297431	3098.7791
1009.3472	2.9875364	1.6326374	3090.1177
1010.3481	2.9898589	1.6354322	3093.6506
1011.3491	2.9894898	1.6384447	3091.0483
1012.3501	2.9948008	1.6408511	3078.8801
1013.3511	2.9971862	1.6428744	3078.2097
1014.3521	3.0019186	1.6448454	3080.7708
1015.353	3.0041945	1.6475298	3084.5693
1016.354	3.008656	1.6504838	3085.8606
1017.355	3.0111895	1.6536461	3075.8162
1018.356	3.0130501	1.6569296	3077.7969
1019.3569	3.0178475	1.6606921	3073.4387
1020.3579	3.0190048	1.664107	3071.3186
1021.3589	3.0272286	1.6672229	3070.7412
1022.3599	3.0269277	1.6706538	3067.6353
1023.3608	3.0263853	1.6740706	3059.2578
1024.3618	3.0334527	1.6773169	3061.092
1025.3628	3.036912	1.6803018	3060.0063
1026.3638	3.0366838	1.6831027	3056.5796
1027.3647	3.0420041	1.6862276	3052.7615
1028.3657	3.0468285	1.6896626	3053.6975
1029.3667	3.0466528	1.6929044	3049.6145
1030.3677	3.0487971	1.6957031	3036.1165
1031.3687	3.0508978	1.6988521	3048.1802
1032.3696	3.0594127	1.7019912	3044.2024
1033.3706	3.060041	1.7055321	3046.2881
1034.3716	3.0629008	1.709286	3031.5505
1035.3726	3.0656009	1.7123398	3027.7141
1036.3735	3.0691328	1.7152654	3028.2656
1037.3745	3.0730102	1.7181256	3032.6167
1038.3755	3.0722089	1.7209688	3019.8354
1039.3765	3.0753272	1.7236462	3018.238
1040.3774	3.0766845	1.7265614	3023.1526
1041.3784	3.0807836	1.7300243	3016.2866
1042.3794	3.0867436	1.7335417	3016.0671
1043.3804	3.0880754	1.7372823	3013.3896
1044.3813	3.0929363	1.740267	3005.9397
1045.3823	3.0974751	1.7429044	3008.3411
1046.3833	3.0953009	1.7460301	3004.4438
1047.3843	3.1021576	1.7495093	3006.3181
1048.3853	3.1030078	1.7529473	2998.1738
1049.3862	3.1080413	1.7562946	2992.7949
1050.3872	3.1111603	1.7600397	2990.2766
1051.3882	3.1102693	1.763595	2984.2825
1052.3892	3.1183817	1.7669278	2985.4817
1053.3901	3.1224837	1.7700433	2980.4602
1054.3911	3.1228778	1.7729728	2977.9036
1055.3921	3.1257484	1.7763437	2975.9543
1056.3931	3.1274035	1.7797455	2967.7622
1057.394	3.1312859	1.7831188	2970.5696
1058.395	3.1339917	1.7861068	2962.9067
1059.396	3.1383538	1.7889184	2960.7952
1060.397	3.1400013	1.7921424	2960.2712
1061.3979	3.1429257	1.7958002	2960.7178
1062.3989	3.1460178	1.7989393	2949.7961
1063.3999	3.1499975	1.8024315	2950.6807
1064.4009	3.151237	1.8056654	2938.0525
1065.4019	3.1545095	1.8086522	2944.3052
1066.4028	3.157388	1.8124571	2937.1809
1067.4038	3.160212	1.815465	2922.5449
1068.4048	3.1647735	1.8187302	2936.6196
1069.4058	3.1669846	1.822122	2930.2302
1070.4067	3.1719699	1.8256521	2928.2456
1071.4077	3.1748781	1.8290637	2918.4583
1072.4087	3.176826	1.8319786	2916.5793
1073.4097	3.1773248	1.834847	2911.8826
1074.4106	3.1821787	1.8380642	2913.4875
1075.4116	3.1841702	1.8415551	2904.6438
1076.4126	3.1896808	1.8448095	2901.8684
1077.4136	3.1941602	1.84805	2900.4971
1078.4146	3.1955523	1.850741	2890.8442
1079.4155	3.1979725	1.8536828	2899.1367
1080.4165	3.2032831	1.8570127	2891.7317
1081.4175	3.2038171	1.8601478	2886.5217
1082.4185	3.2074158	1.8635583	2880.1738
1083.4194	3.2062237	1.8669732	2879.1836
1084.4204	3.2152147	1.8710159	2875.9653
1085.4214	3.2156088	1.8748893	2865.4844
1086.4224	3.2199299	1.8775338	2861.5408
1087.4233	3.2193396	1.8802568	2854.3232
1088.4243	3.2269251	1.8839474	2856.7817
1089.4253	3.2292564	1.8879635	2858.1707
1090.4263	3.2353477	1.8914953	2849.928
1091.4272	3.2327199	1.8945943	2841.438
1092.4282	3.2374864	1.8984439	2840.395
1093.4292	3.2400055	1.9021065	2835.5874
1094.4302	3.2444184	1.9058625	2829.9546
1095.4312	3.2481661	1.9089661	2822.6528
1096.4321	3.2488363	1.9124553	2820.1001
1097.4331	3.2515268	1.9161075	2817.8457
1098.4341	3.2532427	1.9196944	2807.7014
1099.4351	3.259197	1.9232653	2804.103
1100.436	3.2592795	1.925299	2796.4255
1101.437	3.2593503	1.927965	2791.3513
1102.438	3.2687466	1.931895	2798.6907
1103.439	3.2684884	1.9362099	2785.3591
1104.4399	3.2722251	1.9397196	2779.7688
1105.4409	3.2759159	1.9431998	2775.8501
1106.4419	3.2800815	1.9465607	2776.0898
1107.4429	3.279098	1.9498892	2763.594
1108.4438	3.283586	1.9531766	2753.949
1109.4448	3.2886827	1.9565076	2755.876
1110.4458	3.2884879	1.9594845	2752.0779
1111.4468	3.2919331	1.9627297	2746.0613
1112.4478	3.2977359	1.9656568	2744.2246
1113.4487	3.2992849	1.9692907	2735.2202
1114.4497	3.3036392	1.9730248	2737.9651
1115.4507	3.306051	1.9771198	2724.822
1116.4517	3.3069217	1.9802756	2714.3655
1117.4526	3.3157737	1.983562	2718.571
1118.4536	3.3152456	1.9868006	2709.9685
1119.4546	3.3176935	1.9903964	2706.2053
1120.4556	3.3218229	1.9938686	2701.1733
1121.4565	3.3274732	1.9970479	2694.2151
1122.4575	3.3278306	2.0005805	2693.3699
1123.4585	3.3310051	2.0043259	2687.0005
1124.4595	3.3316209	2.0080016	2669.0654
1125.4604	3.3373799	2.0113719	2672.8127
1126.4614	3.3381295	2.0156307	2668.1487
1127.4624	3.3413153	2.0200255	2653.9163
1128.4634	3.3457754	2.0231726	2645.3967
1129.4644	3.3483322	2.0262189	2644.8142
1130.4653	3.3518515	2.0295358	2638.9055
1131.4663	3.3548646	2.0336919	2632.0039
1132.4673	3.3587403	2.0371492	2624.2231
1133.4683	3.3597608	2.0405676	2615.1667
1134.4692	3.3634322	2.0446103	2611.8306
1135.4702	3.3658044	2.047471	2596.259
1136.4712	3.3716917	2.0487864	2587.9043
1137.4722	3.3729715	2.0499306	2588.3147
1138.4731	3.3758039	2.0502872	2586.7422
1139.4741	3.3761477	2.0505042	2568.2969
1140.4751	3.3803146	2.0509887	2568.3408
1141.4761	3.3838887	2.0512691	2558.2493
1142.4771	3.3878956	2.0514331	2544.9377
1143.478	3.3936856	2.0513659	2545.8777
1144.479	3.39469	2.0514054	2533.3611
1145.48	3.3943751	2.0514915	2518.1282
1146.481	3.4031658	2.0516996	2506.0681
1147.4819	3.4054854	2.0515087	2510.4282
1148.4829	3.4087746	2.0516641	2491.2019
1149.4839	3.410054	2.0516613	2463.5681
1149.6841	3.4080832	2.0516012	2439.4619