File: datasets/am_bench_2022/raw_data/0-XY.10-4/specimen.dat
MTS793|MPT|ENU|1|2|.|/|:|1|0|0|A

Operator Information						Time:	17.699219	Sec	10/13/2021 3:18:03 PM
Operator	Nick Derimow
Project	AM Bench 2022 mini-tensile challenge
Specimen ID	0-XY.10-4
Material	PBF-L Inconel 625
Specimen Width	2.56	mm
Specimen Thickness	1.53	mm
Notes
Operator Information End

Data Acquisition						Time:	1018.6931	Sec	10/13/2021 3:34:44 PM
Time	Axial Displacement	Axial Extensometer	Axial Force
Sec	mm	mm	N
17.812988	0.00017327057	7.3126939e-05	46.644264
18.813965	0.00027837962	0.00020565656	60.415188
19.814941	0.0067338282	0.00016640355	72.550224
20.815918	0.0081690894	0.00021704441	83.630142
21.816895	0.010116937	0.00044048723	99.946777
22.817871	0.015634598	0.00047026196	111.03687
23.818848	0.015777817	0.0005265947	125.73353
24.819824	0.022204582	0.00060542341	139.96358
25.820801	0.021341581	0.00067170052	150.90663
26.821777	0.02584032	0.00070374855	164.61526
27.822754	0.029593667	0.00077685365	180.71346
28.82373	0.031701379	0.00094649312	197.7738
29.824707	0.035848528	0.0010406108	221.48271
30.825684	0.037379421	0.00097544317	230.95227
31.82666	0.040180843	0.0012214743	252.2204
32.827637	0.042542212	0.0013827992	270.30484
33.828613	0.045040242	0.0014370042	291.7085
34.82959	0.050078206	0.0016236342	312.46933
35.830566	0.050559495	0.0016194545	325.922
36.831543	0.053046871	0.0018275469	349.52859
37.83252	0.055879232	0.0017444973	365.64047
38.833496	0.059972081	0.0020312842	391.80222
39.834473	0.064666696	0.0020591361	413.81284
40.835449	0.066009551	0.0021975799	436.30212
41.836426	0.071085058	0.0023092763	459.3613
42.837402	0.072984606	0.0023453943	488.3887
43.838379	0.076453969	0.0025433374	511.3027
44.839355	0.080070198	0.002703676	533.77637
45.840332	0.083608456	0.0028832762	560.96747
46.841309	0.08390227	0.0028642295	582.43909
47.842285	0.08893045	0.0030939921	612.13336
48.843262	0.091330081	0.0032616646	639.34637
49.844238	0.095018066	0.0035072367	669.50403
50.845215	0.096051745	0.0034353284	686.08826
51.846191	0.099836692	0.0035423622	720.81793
52.847168	0.10364264	0.0037957274	743.85028
53.848145	0.10563316	0.0038203511	762.31537
54.849121	0.10885195	0.0039033147	781.03088
55.850098	0.10944613	0.0040620621	816.53973
56.851074	0.11363303	0.0041701617	842.21149
57.852051	0.11707371	0.0043615196	868.45264
58.853027	0.1224672	0.0044172569	903.11523
59.854004	0.12609787	0.0046387464	929.86792
60.85498	0.12843563	0.004737989	951.34613
61.855957	0.12907284	0.0049266671	978.2168
62.856934	0.13322408	0.0049842168	1006.264
63.85791	0.13447776	0.0051851762	1037.8235
64.858887	0.13866778	0.0053011626	1062.422
65.859863	0.13804533	0.0054440652	1097.197
66.86084	0.14252685	0.0056619686	1117.656
67.861816	0.14635724	0.005874462	1155.0413
68.862793	0.15269385	0.0058926647	1186.9192
69.86377	0.15529919	0.0060872384	1210.6807
70.864746	0.15525965	0.0062478185	1232.7145
71.865723	0.16012862	0.0062980936	1268.9272
72.866699	0.16273662	0.0065165013	1299.818
73.867676	0.16360189	0.0067074616	1324.973
74.868652	0.16933346	0.0068246615	1350.9313
75.869629	0.17137146	0.0069310805	1373.7721
76.870605	0.17376663	0.0071288683	1404.7784
77.871582	0.17815945	0.0072308616	1433.1133
78.872559	0.17940764	0.0074567348	1450.9492
79.873535	0.18430811	0.0075305607	1484.7802
80.874512	0.18755211	0.007682337	1510.7833
81.875488	0.18962725	0.0078415358	1546.2417
82.876465	0.19261578	0.0080106882	1574.1774
83.877441	0.19452429	0.0081020193	1596.7419
84.878418	0.19671765	0.008394273	1628.7224
85.879395	0.20396495	0.0085603427	1659.7465
86.880371	0.20404731	0.0086408267	1680.5632
87.881348	0.20776173	0.0088470848	1706.0288
88.882324	0.20869213	0.0089513818	1741.9232
89.883301	0.21084411	0.0090786209	1762.4371
90.884277	0.21599579	0.0092262346	1782.8954
91.885254	0.22042839	0.0094025955	1806.9158
92.88623	0.22335686	0.00968685	1845.8535
93.887207	0.22612119	0.0097077554	1872.2733
94.888184	0.22891831	0.0098902415	1892.3094
95.88916	0.22911131	0.010074032	1911.7479
96.890137	0.23562044	0.010304407	1940.6764
97.891113	0.23619188	0.010399607	1962.3982
98.89209	0.24224426	0.010641142	1981.6221
99.893066	0.24154744	0.010847747	2008.5068
100.89404	0.24518158	0.01097307	2034.5566
101.89502	0.24784578	0.011182916	2054.9363
102.896	0.25483835	0.011320332	2082.2603
103.89697	0.25750828	0.01151446	2107.0811
104.89795	0.25824425	0.011716857	2120.1152
105.89893	0.26172918	0.011897975	2134.3943
106.8999	0.26776585	0.012116734	2164.7781
107.90088	0.27037773	0.012306646	2191.5518
108.90186	0.27298683	0.012599718	2202.5129
109.90283	0.27428254	0.012747782	2215.0757
110.90381	0.27889782	0.012789403	2228.9155
111.90479	0.27680841	0.013116832	2244.3984
112.90576	0.2843653	0.013247244	2265.728
113.90674	0.28253418	0.013541131	2275.6621
114.90771	0.28759027	0.013680313	2296.6694
115.90869	0.29231456	0.014075051	2320.7734
116.90967	0.29679957	0.014204967	2331.1792
117.91064	0.29723126	0.014418498	2350.3115
118.91162	0.30097279	0.014697183	2359.9912
119.9126	0.30496928	0.015036495	2381.1917
120.91357	0.30554831	0.015178131	2386.4714
121.91455	0.3085835	0.015377946	2404.9878
122.91553	0.30972004	0.0157643	2422.0676
123.9165	0.31371459	0.016029963	2434.5764
124.91748	0.31871054	0.016232831	2439.6663
125.91846	0.32212582	0.016537128	2453.4812
126.91943	0.32480025	0.016755339	2466.0168
127.92041	0.32705531	0.017156711	2480.2966
128.92139	0.33009952	0.017415309	2490.8025
129.92236	0.33745438	0.017816449	2506.9004
130.92334	0.33835959	0.018112168	2517.0205
131.92432	0.34250325	0.018452328	2530.0618
132.92529	0.3402448	0.018755203	2537.1514
133.92627	0.34713519	0.019277301	2555.6526
134.92725	0.34849176	0.019644653	2559.4277
135.92822	0.35121122	0.02000697	2561.4717
136.9292	0.3572655	0.020456299	2577.3923
137.93018	0.36060598	0.020860991	2591.5173
138.93115	0.36347175	0.021291064	2596.8276
139.93213	0.36622158	0.021768579	2613.8386
140.93311	0.36655331	0.022337135	2614.1199
141.93408	0.37074941	0.022730816	2624.0674
142.93506	0.37680775	0.023254652	2634.4343
143.93604	0.37667847	0.023805793	2634.4714
144.93701	0.38256246	0.024484966	2654.5156
145.93799	0.38500354	0.024945633	2647.3713
146.93896	0.38766256	0.025453541	2658.9888
147.93994	0.38821226	0.02613212	2665.6013
148.94092	0.39255488	0.026615648	2669.1121
149.94189	0.39488819	0.027280206	2674.3809
150.94287	0.40047628	0.027951958	2683.5225
151.94385	0.40009478	0.028559521	2687.4465
152.94482	0.40265176	0.029422885	2693.8035
153.9458	0.40496272	0.030018881	2700.6367
154.94678	0.41060475	0.030988872	2710.5513
155.94775	0.41168001	0.031855877	2713.021
156.94873	0.41604123	0.032731201	2720.8528
157.94971	0.41911951	0.033569694	2724.1946
158.95068	0.42235821	0.034272917	2729.3057
159.95166	0.42553276	0.035209253	2740.6519
160.95264	0.42900378	0.036236789	2744.7961
161.95361	0.43000871	0.037360359	2748.2532
162.95459	0.44038734	0.038296018	2753.8599
163.95557	0.43769902	0.039201941	2754.6162
164.95654	0.4420523	0.040325299	2766.8257
165.95752	0.44417512	0.041296363	2761.1226
166.9585	0.44691288	0.042299163	2769.4849
167.95947	0.45081273	0.04346646	2776.1377
168.96045	0.45210311	0.044431746	2773.5342
169.96143	0.45426631	0.045564581	2779.6389
170.9624	0.45847225	0.046588287	2786.9414
171.96338	0.4627344	0.04773248	2781.9619
172.96436	0.46564811	0.048689816	2790.4514
173.96533	0.46989909	0.049932349	2800.678
174.96631	0.47273621	0.051340915	2801.2737
175.96729	0.47380614	0.05238783	2796.5449
176.96826	0.47938076	0.053423531	2801.6018
177.96924	0.47947195	0.054762665	2811.1084
178.97021	0.48325986	0.056202952	2809.9836
179.97119	0.48480803	0.057369526	2813.6592
180.97217	0.49000934	0.058392566	2814.8091
181.97314	0.49175379	0.059463188	2810.5659
182.97412	0.49507868	0.060408186	2820.3618
183.9751	0.49552187	0.061550498	2822.5813
184.97607	0.50331807	0.062943347	2831.3655
185.97705	0.49991837	0.064515591	2825.6074
186.97803	0.51081347	0.065656245	2831.1521
187.979	0.51008898	0.067097172	2832.5791
188.97998	0.51511234	0.06844645	2835.3381
189.98096	0.51618552	0.069638804	2838.8713
190.98193	0.51888454	0.070830017	2841.6909
191.98291	0.52163821	0.07244423	2851.0183
192.98389	0.52553684	0.073897183	2849.9854
193.98486	0.52841145	0.075203538	2848.1887
194.98584	0.53348625	0.076313242	2849.031
195.98682	0.53381103	0.07761316	2855.8267
196.98779	0.53688228	0.078966044	2854.8303
197.98877	0.53977001	0.080311149	2858.6868
198.98975	0.54300195	0.081799388	2859.7146
199.99072	0.54696977	0.083641477	2866.5635
200.9917	0.54857534	0.085232548	2866.6816
201.99268	0.55203527	0.086905763	2866.8167
202.99365	0.55462301	0.088314518	2869.1216
203.99463	0.55786699	0.089632004	2859.731
204.99561	0.56295931	0.090967879	2874.6887
205.99658	0.56171685	0.09214288	2871.0898
206.99756	0.56805325	0.093738474	2882.6719
207.99854	0.56884295	0.095153883	2871.2573
208.99951	0.57686001	0.096570872	2880.0337
210.00049	0.57433802	0.098028019	2872.5737
211.00146	0.57830667	0.099317603	2875.418
212.00244	0.58358568	0.1004957	2888.3955
213.00342	0.58478117	0.10186631	2889.7537
214.00439	0.58445317	0.10345645	2891.2678
215.00537	0.58952802	0.10495871	2886.0715
216.00635	0.59296691	0.10648751	2889.4321
217.00732	0.59544891	0.10791639	2884.0332
218.0083	0.59636992	0.10930384	2893.5779
219.00928	0.60236901	0.11060767	2896.98
220.01025	0.60614944	0.1120288	2898.6733
221.01123	0.60980284	0.11384544	2904.6165
222.01221	0.61228055	0.11542157	2900.8687
223.01318	0.61528051	0.11677172	2902.9004
224.01416	0.61762071	0.11837944	2905.041
225.01514	0.61996037	0.1198336	2904.3325
226.01611	0.62144929	0.12126506	2902.6028
227.01709	0.62779117	0.12278096	2908.9683
228.01807	0.63030642	0.1246297	2914.8472
229.01904	0.634462	0.12600568	2908.1741
230.02002	0.63347417	0.12732515	2911.7676
231.021	0.63726795	0.128804	2913.8376
232.02197	0.64270931	0.13013309	2913.052
233.02295	0.64309329	0.13156843	2914.1206
234.02393	0.64598447	0.1328741	2917.2957
235.0249	0.64985383	0.13449351	2921.4807
236.02588	0.65526325	0.13634072	2929.3975
237.02686	0.65664506	0.13823694	2922.8787
238.02783	0.65971959	0.13994749	2923.9109
239.02881	0.66433126	0.14154001	2929.6316
240.02979	0.66503465	0.1431569	2928.5259
241.03076	0.66986918	0.14464919	2925.2092
242.03174	0.67265874	0.14605603	2932.7603
243.03271	0.67652071	0.14749457	2923.5239
244.03369	0.67867345	0.14898506	2936.093
245.03467	0.68227905	0.15046921	2935.6575
246.03564	0.68228155	0.15198879	2934.2441
247.03662	0.68601072	0.15346336	2940.4209
248.0376	0.68982333	0.15501337	2935.7446
249.03857	0.69428289	0.15667485	2942.4326
250.03955	0.69795406	0.15813844	2944.6462
251.04053	0.70033425	0.15960743	2945.3438
252.0415	0.70309925	0.1612432	2943.8123
253.04248	0.70532042	0.16263765	2941.7861
254.04346	0.70744103	0.16386789	2940.832
255.04443	0.70907438	0.1653505	2941.8899
256.04541	0.71085185	0.16678974	2945.8523
257.04639	0.71661681	0.16863061	2951.0693
258.04736	0.71804196	0.17008674	2950.2156
259.04834	0.7242884	0.17157757	2953.3618
260.04932	0.72616172	0.17319068	2957.8066
261.05029	0.72743058	0.1749301	2956.9407
262.05127	0.73238808	0.17668252	2956.0674
263.05225	0.73635715	0.17827067	2957.5874
264.05322	0.73827672	0.17949818	2956.3645
265.0542	0.74219036	0.18102135	2961.1309
266.05518	0.74536979	0.18261564	2963.4758
267.05615	0.74689418	0.18429682	2962.4976
268.05713	0.75006384	0.18580744	2961.2634
269.05811	0.75515264	0.18734682	2966.9688
270.05908	0.75575399	0.18898174	2970.241
271.06006	0.76005954	0.19081134	2972.6892
272.06104	0.76166129	0.1922265	2965.103
273.06201	0.76480353	0.19366263	2966.2114
274.06299	0.76822597	0.1947864	2969.8191
275.06396	0.77299494	0.19659686	2971.6423
276.06494	0.77405691	0.19800097	2974.2002
277.06592	0.77604961	0.19966179	2967.9329
278.06689	0.78135151	0.20117971	2979.4363
279.06787	0.78225285	0.2029727	2977.2856
280.06885	0.78743488	0.20472167	2978.3318
281.06982	0.78739595	0.20639114	2984.0425
282.0708	0.79350674	0.20797533	2976.9521
283.07178	0.79549319	0.20961474	2980.4346
284.07275	0.80213237	0.21125795	2990.1367
285.07373	0.80098337	0.21272832	2986.1909
286.07471	0.80850273	0.21468531	2992.7456
287.07568	0.81150401	0.21625295	2987.1555
288.07666	0.81076783	0.21744366	2977.303
289.07764	0.81292039	0.21884441	2982.2751
290.07861	0.81683373	0.22004759	2985.6365
291.07959	0.81866461	0.22141369	2988.5159
292.08057	0.81962144	0.22284357	2989.5813
293.08154	0.82472444	0.22448538	2993.6465
294.08252	0.82741541	0.22624274	2998.4187
295.0835	0.82999533	0.22772384	2989.6355
296.08447	0.83377701	0.22970827	3000.241
297.08545	0.83763629	0.23101135	3000.7898
298.08643	0.83812743	0.2328667	3003.4998
299.0874	0.84220833	0.2341895	2996.3267
300.08838	0.84518868	0.23533173	2996.2666
301.08936	0.84524935	0.23695359	2997.4924
302.09033	0.85497397	0.23869075	3010.1116
303.09131	0.85839379	0.24044013	3005.8513
304.09229	0.85606313	0.24171759	2991.396
305.09326	0.85900551	0.24307418	3007.8123
306.09424	0.86673886	0.24452132	3006.3794
307.09521	0.86881769	0.24627908	3016.041
308.09619	0.87461352	0.24786562	3015.3257
309.09717	0.8748039	0.2491806	3011.813
310.09814	0.874659	0.25064087	3009.7693
311.09912	0.87797028	0.25209659	3007.7078
312.1001	0.88133395	0.25365609	3017.4856
313.10107	0.88724512	0.25511202	3016.4021
314.10205	0.88669008	0.25670493	3016.3728
315.10303	0.89070064	0.25853831	3015.9143
316.104	0.89529157	0.2599763	3021.8938
317.10498	0.89780694	0.26165873	3018.6448
318.10596	0.90017074	0.2632122	3018.4619
319.10693	0.90185982	0.26489812	3022.2686
320.10791	0.9039948	0.26662454	3017.7312
321.10889	0.90765554	0.26827934	3030.3059
322.10986	0.91093415	0.26988733	3019.8657
323.11084	0.91563863	0.2710692	3017.2668
324.11182	0.92212009	0.27252823	3032.5303
325.11279	0.9214257	0.27366894	3023.6521
326.11377	0.92567343	0.27522412	3025.0334
327.11475	0.92447937	0.27662903	3032.1194
328.11572	0.92980647	0.27829263	3029.6824
329.1167	0.93339264	0.27982143	3034.4133
330.11768	0.93530303	0.28154054	3039.6819
331.11865	0.93831712	0.28348002	3030.3889
332.11963	0.94565177	0.28484237	3032.0083
333.12061	0.94692713	0.28624028	3036.3999
334.12158	0.95050061	0.28753662	3038.478
335.12256	0.95177811	0.28905255	3035.2556
336.12354	0.95341676	0.2905435	3033.7158
337.12451	0.95749104	0.29208875	3044.3535
338.12549	0.96011233	0.29356208	3044.2012
339.12646	0.96563715	0.29501113	3048.3396
340.12744	0.96779466	0.29653525	3046.2454
341.12842	0.97169429	0.29803175	3049.8413
342.12939	0.97271794	0.29986626	3046.1003
343.13037	0.97786433	0.30199203	3049.6321
344.13135	0.97911823	0.30339435	3045.4026
345.13232	0.98042685	0.30480993	3046.2676
346.1333	0.98710907	0.30609944	3044.1624
347.13428	0.98777193	0.30744669	3047.4463
348.13525	0.99328339	0.30885407	3051.3865
349.13623	0.99253821	0.31025952	3052.96
350.13721	0.99541402	0.31179947	3050.9597
351.13818	0.99822086	0.31325167	3052.7476
352.13916	1.0027329	0.31496847	3054.7268
353.14014	1.0075645	0.31648785	3061.3682
354.14111	1.0084383	0.31797856	3055.2178
355.14209	1.0123545	0.31936753	3059.9082
356.14307	1.0142021	0.32080117	3065.9973
357.14404	1.0159365	0.32240519	3062.2837
358.14502	1.0206866	0.32416549	3060.2197
359.146	1.0246083	0.32585803	3066.8984
360.14697	1.0263232	0.32716188	3056.8745
361.14795	1.0287353	0.32860568	3061.1736
362.14893	1.0298162	0.33008057	3065.4006
363.1499	1.0368323	0.33162174	3063.5754
364.15088	1.0416154	0.33317426	3069.7925
365.15186	1.0425839	0.3345702	3071.6082
366.15283	1.0451987	0.33641082	3069.8782
367.15381	1.0469894	0.33785501	3076.6167
368.15479	1.0504465	0.33956316	3076.1487
369.15576	1.0508664	0.34076753	3067.4985
370.15674	1.0551122	0.34235969	3072.0381
371.15771	1.0585558	0.34382549	3068.0178
372.15869	1.0609989	0.34519988	3072.1626
373.15967	1.0645933	0.34679481	3077.9207
374.16064	1.0705268	0.3484903	3082.564
375.16162	1.0708249	0.35012093	3075.2412
376.1626	1.0755433	0.35159656	3078.7454
377.16357	1.0759184	0.35304794	3076.4741
378.16455	1.0825377	0.35477781	3080.8232
379.16553	1.0828474	0.3563174	3079.9309
380.1665	1.0872328	0.35776547	3080.4785
381.16748	1.0887816	0.35917348	3085.0344
382.16846	1.0917563	0.36078706	3082.6709
383.16943	1.0968194	0.36219314	3085.3455
384.17041	1.1010377	0.36367315	3087.6589
385.17139	1.1009393	0.36531347	3088.2373
386.17236	1.1074668	0.36679131	3087.6797
387.17334	1.106347	0.36795291	3084.4458
388.17432	1.1101547	0.36962149	3090.22
389.17529	1.1118754	0.37097684	3084.0757
390.17627	1.116326	0.37265661	3090.2495
391.17725	1.1208401	0.37448493	3095.5691
392.17822	1.1241515	0.37603974	3093.3406
393.1792	1.1251376	0.37724099	3088.1677
394.18018	1.1299601	0.37849218	3093.2795
395.18115	1.132084	0.37993571	3096.1414
396.18213	1.135613	0.38146061	3096.3193
397.18311	1.1362053	0.38273394	3090.9812
398.18408	1.1426864	0.38408905	3098.9844
399.18506	1.1439037	0.38576707	3105.0315
400.18604	1.1475747	0.38717002	3101.2114
401.18701	1.1531078	0.38881013	3106.7036
402.18799	1.1535327	0.39041209	3107.3018
403.18896	1.15578	0.39191982	3101.7798
404.18994	1.1579659	0.3932429	3099.8977
405.19092	1.1620108	0.3945277	3106.6016
406.19189	1.1668874	0.39588633	3107.5085
407.19287	1.1679764	0.39738813	3106.3611
408.19385	1.172044	0.39889428	3109.4331
409.19482	1.1753589	0.40040234	3111.1416
410.1958	1.1760533	0.40222505	3109.3008
411.19678	1.1807885	0.40373743	3109.9092
412.19775	1.1815666	0.40523604	3109.9194
413.19873	1.1870604	0.40696523	3116.637
414.19971	1.1882745	0.40869898	3111.863
415.20068	1.1910108	0.41030252	3113.3892
416.20166	1.197041	0.41190532	3114.3296
417.20264	1.1977602	0.41324988	3110.7822
418.20361	1.2016729	0.41470388	3116.8818
419.20459	1.2039043	0.4160566	3117.0815
420.20557	1.2075897	0.41753954	3120.9871
421.20654	1.2090428	0.41919094	3117.6748
422.20752	1.215413	0.42042994	3120.2673
423.2085	1.2164326	0.42195749	3121.125
424.20947	1.2194846	0.42355278	3123.1968
425.21045	1.2207167	0.4249692	3116.0134
426.21143	1.2246797	0.42640859	3120.5852
427.2124	1.2278804	0.42771685	3126.0061
428.21338	1.2329396	0.42930299	3130.908
429.21436	1.2340029	0.43073279	3126.9041
430.21533	1.2360216	0.43226165	3129.0498
431.21631	1.2403386	0.43402079	3131.8933
432.21729	1.2428949	0.4353022	3117.8403
433.21826	1.2467357	0.43671665	3127.5601
434.21924	1.2472005	0.43813211	3125.3462
435.22021	1.2492251	0.43931177	3129.8887
436.22119	1.25465	0.44074476	3132.3433
437.22217	1.2585607	0.44219708	3131.9207
438.22314	1.2605783	0.44373924	3134.7468
439.22412	1.265306	0.44557446	3147.718
440.2251	1.2635655	0.44720873	3133.0215
441.22607	1.2705061	0.44882345	3132.9182
442.22705	1.2704223	0.45009798	3128.687
443.22803	1.2772219	0.45165378	3138.071
444.229	1.2778065	0.45282969	3131.0725
445.22998	1.2829838	0.45437551	3139.1184
446.23096	1.2842577	0.45577034	3140.738
447.23193	1.2864929	0.45733321	3135.946
448.23291	1.2909269	0.45911077	3144.9351
449.23389	1.2938397	0.46048337	3148.3896
450.23486	1.2966835	0.46210483	3142.344
451.23584	1.3000162	0.46385753	3140.1814
452.23682	1.3027685	0.46528423	3140.8032
453.23779	1.3087842	0.466703	3147.4736
454.23877	1.3105215	0.46797082	3139.095
455.23975	1.3085605	0.46916279	3141.2363
456.24072	1.3129088	0.47054681	3149.8308
457.2417	1.3153725	0.47225401	3154.9399
458.24268	1.3203855	0.47406769	3150.793
459.24365	1.3255966	0.47575223	3154.1335
460.24463	1.3282201	0.47729459	3151.4719
461.24561	1.3317575	0.47869864	3150.7998
462.24658	1.3337868	0.48015767	3151.1282
463.24756	1.3359828	0.48160201	3155.9863
464.24854	1.3390317	0.48303574	3154.3987
465.24951	1.3404846	0.4846113	3157.4644
466.25049	1.3458529	0.48611474	3157.8574
467.25146	1.3516728	0.487701	3162.5596
468.25244	1.3493917	0.48934788	3155.7402
469.25342	1.3549571	0.49089727	3154.324
470.25439	1.3567528	0.49224436	3159.4614
471.25537	1.3599937	0.49372765	3158.4421
472.25635	1.362623	0.49523675	3157.345
473.25732	1.366109	0.49656364	3158.0732
474.2583	1.3687588	0.4979713	3162.9355
475.25928	1.374083	0.49934295	3162.7817
476.26025	1.3755445	0.50079763	3166.574
477.26123	1.3806431	0.50225419	3166.6072
478.26221	1.3836845	0.50388855	3174.8032
479.26318	1.384902	0.50558114	3165.4692
480.26416	1.3865255	0.5071578	3163.9573
481.26514	1.3887669	0.5087083	3167.2004
482.26611	1.3934735	0.51027888	3166.4187
483.26709	1.396086	0.51157814	3165.9268
484.26807	1.3994585	0.51294702	3167.9126
485.26904	1.4025218	0.51479357	3172.3323
486.27002	1.4033278	0.51656365	3170.7209
487.271	1.4076666	0.51827967	3171.303
488.27197	1.4105792	0.51957405	3173.5703
489.27295	1.41803	0.52100408	3175.1594
490.27393	1.4158019	0.52243805	3174.6572
491.2749	1.419781	0.52373403	3171.2969
492.27588	1.4227275	0.52533817	3173.2747
493.27686	1.4277253	0.52695757	3177.103
494.27783	1.4303256	0.52850497	3178.8481
495.27881	1.4339365	0.53003484	3180.7979
496.27979	1.4339732	0.53148693	3180.6587
497.28076	1.439773	0.53317541	3181.7349
498.28174	1.4411027	0.53449613	3182.894
499.28271	1.4445105	0.53604645	3185.0251
500.28369	1.4442924	0.53759134	3179.3215
501.28467	1.447896	0.5392983	3181.4575
502.28564	1.4536489	0.5407145	3179.217
503.28662	1.4562932	0.54198909	3187.614
504.2876	1.4561656	0.54324079	3179.3684
505.28857	1.4616305	0.54459894	3183.6392
506.28955	1.4663968	0.54583055	3186.4751
507.29053	1.4654121	0.54736996	3181.4373
508.2915	1.4721714	0.54914898	3190.717
509.29248	1.4729847	0.55046695	3186.8633
510.29346	1.4769931	0.5519951	3191.7434
511.29443	1.482402	0.55371338	3189.5552
512.29541	1.4809817	0.55541372	3187.2468
513.29639	1.4863442	0.55674893	3189.4338
514.29736	1.4905239	0.55820107	3187.4561
515.29834	1.4919547	0.55987144	3189.9072
516.29932	1.495265	0.56116545	3187.1733
517.30029	1.5005058	0.56287622	3203.8804
518.30127	1.4990854	0.56454301	3193.4497
519.30225	1.5072807	0.56618124	3195.0271
520.30322	1.5049611	0.56772429	3192.7986
521.3042	1.5114008	0.56947726	3197.8904
522.30518	1.5116166	0.57126611	3202.6201
523.30615	1.5181254	0.57267171	3199.7305
524.30713	1.5194814	0.5740515	3197.1611
525.30811	1.5217123	0.57564259	3195.0962
526.30908	1.524233	0.57723248	3196.5894
527.31006	1.5279871	0.57870519	3201.4971
528.31104	1.5346947	0.58014584	3202.395
529.31201	1.5337503	0.58161622	3199.9421
530.31299	1.535288	0.58307302	3210.052
531.31396	1.5391929	0.5845589	3204.5549
532.31494	1.5448931	0.58619803	3209.2417
533.31592	1.5447854	0.58778554	3207.377
534.31689	1.5479118	0.58942497	3200.3064
535.31787	1.5545379	0.59094852	3208.168
536.31885	1.5582507	0.59242243	3204.8889
537.31982	1.5602208	0.59392267	3206.2078
538.3208	1.5602399	0.59543514	3206.7146
539.32178	1.5646642	0.59711766	3210.8481
540.32275	1.5701575	0.59851694	3207.3528
541.32373	1.5708693	0.5998289	3212.5549
542.32471	1.5734227	0.60139877	3208.7195
543.32568	1.5786597	0.60289115	3209.3748
544.32666	1.5781183	0.60437578	3208.3005
545.32764	1.5812869	0.6060093	3216.4966
546.32861	1.5835751	0.60753232	3206.5713
547.32959	1.5848237	0.60881191	3209.1208
548.33057	1.5924556	0.61055171	3216.0361
549.33154	1.592279	0.61213064	3210.5024
550.33252	1.5976449	0.61388206	3215.3479
551.3335	1.5971878	0.61530465	3211.9893
552.33447	1.6034143	0.61666411	3211.5005
553.33545	1.6086004	0.61811167	3213.2388
554.33643	1.608248	0.61945969	3214.7427
555.3374	1.6134804	0.6208294	3214.9006
556.33838	1.6156285	0.62246704	3226.6287
557.33936	1.6166401	0.62437731	3224.3596
558.34033	1.6207429	0.62589842	3219.437
559.34131	1.6256701	0.62762982	3224.668
560.34229	1.6286564	0.62941313	3221.5847
561.34326	1.6306704	0.63091439	3217.5098
562.34424	1.6300094	0.63218689	3217.2192
563.34521	1.6375276	0.63377595	3223.3254
564.34619	1.6373961	0.63540471	3225.6953
565.34717	1.6402004	0.63690019	3221.5554
566.34814	1.6458371	0.63846684	3228.3706
567.34912	1.6490612	0.64009976	3221.2971
568.3501	1.6515533	0.64153963	3226.7859
569.35107	1.6539077	0.64335763	3229.4158
570.35205	1.6581786	0.64521009	3235.9465
571.35303	1.6637101	0.64694554	3235.7419
572.354	1.66348	0.64831328	3228.5728
573.35498	1.6659023	0.64965183	3219.8633
574.35596	1.6703117	0.6509822	3220.9707
575.35693	1.6697299	0.65214467	3222.7886
576.35791	1.6754484	0.65375125	3229.9253
577.35889	1.6779157	0.65522969	3224.9844
578.35986	1.6794361	0.65664637	3230.095
579.36084	1.6827325	0.65822768	3232.1199
580.36182	1.6848966	0.65969723	3226.3186
581.36279	1.6913342	0.6613695	3233.3181
582.36377	1.695244	0.6629256	3236.0017
583.36475	1.6984394	0.6645925	3237.9817
584.36572	1.6975687	0.66646236	3234.9414
585.3667	1.700249	0.66812491	3230.8459
586.36768	1.7064236	0.66966081	3236.542
587.36865	1.7098984	0.67133158	3238.655
588.36963	1.7090981	0.67309517	3235.2065
589.37061	1.7126486	0.67451751	3231.0208
590.37158	1.7159698	0.67585492	3238.1785
591.37256	1.7195916	0.67755103	3241.9495
592.37354	1.7242732	0.67914981	3240.8928
593.37451	1.7254933	0.68089592	3239.2957
594.37549	1.7294576	0.68257326	3237.7595
595.37646	1.7294108	0.68409467	3238.5598
596.37744	1.7369986	0.68592757	3242.0396
597.37842	1.7395921	0.68744284	3240.0139
598.37939	1.7427435	0.68908918	3244.958
599.38037	1.7433331	0.69082445	3249.5237
600.38135	1.7473098	0.69229865	3239.6494
601.38232	1.7496588	0.69404298	3241.1619
602.3833	1.7534186	0.6957978	3245.1257
603.38428	1.7549942	0.69706559	3239.4478
604.38525	1.7598084	0.69861537	3242.8721
605.38623	1.7628311	0.70003128	3244.9177
606.38721	1.7675552	0.7015152	3244.6179
607.38818	1.7678143	0.70321715	3250.6519
608.38916	1.7725254	0.70488787	3255.0022
609.39014	1.7771997	0.70655191	3244.8171
610.39111	1.7765913	0.70794749	3242.3303
611.39209	1.7797346	0.70940208	3245.0144
612.39307	1.7826679	0.7107662	3245.1809
613.39404	1.787612	0.71238863	3252.5381
614.39502	1.7865658	0.71369588	3245.3594
615.396	1.7931087	0.71519464	3255.3521
616.39697	1.798182	0.71690482	3252.6001
617.39795	1.7998831	0.71849763	3251.9001
618.39893	1.8004575	0.72011775	3252.5432
619.3999	1.8058299	0.72199428	3259.1802
620.40088	1.8080577	0.72345269	3252.0127
621.40186	1.8100239	0.72486144	3253.2395
622.40283	1.811602	0.72648036	3254.2625
623.40381	1.8170733	0.72822678	3259.5242
624.40479	1.8178447	0.72960186	3254.1318
625.40576	1.8229697	0.73105216	3255.9258
626.40674	1.8218482	0.73265618	3253.0991
627.40771	1.8296791	0.73454505	3258.885
628.40869	1.8316872	0.73620254	3256.6863
629.40967	1.8352144	0.7380324	3257.6606
630.41064	1.838055	0.73992252	3267.5227
631.41162	1.8402524	0.74161255	3263.2407
632.4126	1.8445922	0.74349749	3257.7825
633.41357	1.8468555	0.74519229	3255.6514
634.41455	1.8490385	0.74667358	3254.7461
635.41553	1.8526304	0.74811333	3258.9399
636.4165	1.8568375	0.74956709	3264.3972
637.41748	1.8596592	0.75147802	3262.5715
638.41846	1.8609511	0.75301147	3265.9678
639.41943	1.8651524	0.75460303	3263.114
640.42041	1.8643514	0.7564916	3257.9976
641.42139	1.8711152	0.75825506	3254.9329
642.42236	1.8738279	0.7600711	3264.0833
643.42334	1.876592	0.76144695	3255.1492
644.42432	1.8789647	0.76322764	3265.239
645.42529	1.8838947	0.76475626	3259.5176
646.42627	1.8828815	0.76629543	3258.8792
647.42725	1.8885088	0.76774931	3260.5869
648.42822	1.8874434	0.76904917	3258.3384
649.4292	1.8935258	0.77045614	3264.2158
650.43018	1.8946897	0.77211463	3262.325
651.43115	1.8990872	0.77384824	3270.5229
652.43213	1.9023708	0.77595007	3265.6758
653.43311	1.9102365	0.77772045	3269.248
654.43408	1.9098568	0.77963555	3266.0715
655.43506	1.911869	0.78143358	3268.0398
656.43604	1.9119798	0.78319424	3266.5198
657.43701	1.9179962	0.78483075	3266.7927
658.43799	1.92285	0.78633744	3271.2104
659.43896	1.9256871	0.7878437	3269.2324
660.43994	1.9287145	0.78954458	3269.5591
661.44092	1.9347577	0.7913096	3274.0557
662.44189	1.9325943	0.79296768	3265.2307
663.44287	1.9353164	0.79449111	3266.0742
664.44385	1.9387279	0.7961666	3268.876
665.44482	1.9420872	0.79808331	3272.1411
666.4458	1.9475136	0.79993057	3273.7339
667.44678	1.9486299	0.80167878	3278.0654
668.44775	1.9507974	0.80350935	3269.9285
669.44873	1.9547232	0.8049435	3266.1008
670.44971	1.957211	0.80663371	3274.2295
671.45068	1.9610823	0.80817324	3275.011
672.45166	1.9614829	0.81014198	3278.8857
673.45264	1.9653292	0.8117913	3271.4812
674.45361	1.9673287	0.81357241	3271.6887
675.45459	1.9723178	0.81532311	3274.8057
676.45557	1.9764857	0.81690907	3276.0547
677.45654	1.9792264	0.81876636	3282.49
678.45752	1.9833308	0.82034421	3274.7622
679.4585	1.9837695	0.82196194	3273.3523
680.45947	1.9872341	0.82350194	3271.7671
681.46045	1.9904741	0.82491446	3276.4756
682.46143	1.9961054	0.82678664	3284.0144
683.4624	1.9955838	0.8283543	3280.762
684.46338	2.0010836	0.83033854	3280.5032
685.46436	2.0002439	0.83205998	3276.6284
686.46533	2.0029218	0.83379728	3277.2129
687.46631	2.0075169	0.8353563	3279.4285
688.46729	2.0114281	0.83694398	3274.3972
689.46826	2.0162432	0.83854151	3278.3772
690.46924	2.0172117	0.8402124	3288.0715
691.47021	2.0240271	0.84187275	3284.5178
692.47119	2.0234337	0.84398508	3287.0264
693.47217	2.0286713	0.8458724	3281.5552
694.47314	2.0315251	0.84761465	3281.8728
695.47412	2.0333288	0.84924167	3282.9463
696.4751	2.0346761	0.85092819	3280.8672
697.47607	2.0362201	0.85279179	3281.2371
698.47705	2.040206	0.8546899	3276.72
699.47803	2.0463092	0.85619891	3280.769
700.479	2.045851	0.85826212	3283.9077
701.47998	2.0508418	0.86023998	3287.2178
702.48096	2.0515568	0.86197078	3281.6982
703.48193	2.0549974	0.86375284	3278.9521
704.48291	2.0585585	0.86552846	3282.646
705.48389	2.0644464	0.8673746	3282.1689
706.48486	2.066417	0.86900532	3290.1975
707.48584	2.0685372	0.871234	3297.3916
708.48682	2.0715961	0.8732444	3281.2544
709.48779	2.072597	0.87495935	3285.8127
710.48877	2.0767171	0.8767913	3283.425
711.48975	2.0818241	0.8781364	3286.7197
712.49072	2.0857122	0.87990505	3286.2986
713.4917	2.085269	0.88156968	3287.0791
714.49268	2.0867803	0.88349569	3285.4094
715.49365	2.0922775	0.88523799	3286.7397
716.49463	2.0979691	0.88671398	3288.314
717.49561	2.0974805	0.88837123	3280.0957
718.49658	2.103548	0.88993055	3291.906
719.49756	2.1062415	0.89166546	3287.3401
720.49854	2.1081831	0.89342093	3283.2817
721.49951	2.1105516	0.89507174	3289.3916
722.50049	2.1135097	0.89669007	3285.761
723.50146	2.1155415	0.89879578	3289.844
724.50244	2.119838	0.90107363	3294.3276
725.50342	2.1217449	0.90290034	3286.6643
726.50439	2.124331	0.90487641	3292.6707
727.50537	2.1303892	0.90655822	3295.1604
728.50635	2.130192	0.90860796	3288.3508
729.50732	2.1362958	0.91042465	3289.6086
730.5083	2.1383958	0.91232735	3289.9941
731.50928	2.1426456	0.91421175	3293.3257
732.51025	2.1445243	0.91590101	3287.8904
733.51123	2.1477525	0.91786337	3294.8982
734.51221	2.1497355	0.91942585	3288.0996
735.51318	2.1543031	0.92121571	3288.1919
736.51416	2.1579001	0.92288822	3290.929
737.51514	2.1579638	0.92483211	3295.697
738.51611	2.1621072	0.92694592	3293.9473
739.51709	2.1660028	0.92881823	3296.447
740.51807	2.1695805	0.93053043	3294.3474
741.51904	2.1715841	0.93229359	3295.3838
742.52002	2.1766737	0.93437815	3299.5862
743.521	2.1753261	0.93619931	3297.6174
744.52197	2.1790364	0.93833959	3293.1621
745.52295	2.1796346	0.94030464	3290.3313
746.52393	2.186862	0.94220513	3298.2739
747.5249	2.1907547	0.9441728	3296.1577
748.52588	2.1923676	0.94615597	3294.4507
749.52686	2.1942849	0.94795346	3294.1108
750.52783	2.1989517	0.95003784	3294.6196
751.52881	2.1986952	0.95172107	3287.6707
752.52979	2.2049122	0.95355874	3297.4211
753.53076	2.2056911	0.9558059	3299.8518
754.53174	2.2110655	0.95776379	3289.5439
755.53271	2.2116683	0.95943367	3287.5979
756.53369	2.2160156	0.96141338	3293.5935
757.53467	2.2187052	0.96337086	3300.9851
758.53564	2.223115	0.96531624	3299.2659
759.53662	2.2268155	0.96711874	3298.7068
760.5376	2.2290959	0.96927601	3299.3049
761.53857	2.2301276	0.97108239	3295.9329
762.53955	2.23423	0.97302824	3297.5439
763.54053	2.2349842	0.97494847	3291.4065
764.5415	2.2398474	0.97673249	3295.9893
765.54248	2.2418535	0.97882581	3296.9534
766.54346	2.2472663	0.98096722	3293.9731
767.54443	2.2462459	0.98261982	3287.0745
768.54541	2.2521348	0.98469478	3299.0757
769.54639	2.2563901	0.98670173	3295.9915
770.54736	2.2609806	0.98858494	3299.2998
771.54834	2.2609003	0.99060684	3303.0444
772.54932	2.2601237	0.99268967	3292.9771
773.55029	2.2648392	0.99476266	3300.168
774.55127	2.2711334	0.99681878	3298.2773
775.55225	2.2701094	0.99852598	3292.9395
776.55322	2.2764604	1.0005145	3299.5471
777.5542	2.2807441	1.0028169	3302.1794
778.55518	2.2822406	1.0047807	3297.8325
779.55615	2.2861886	1.0070242	3301.1047
780.55713	2.28824	1.0090448	3301.2168
781.55811	2.2919607	1.0109719	3298.5356
782.55908	2.2921145	1.0129279	3295.5625
783.56006	2.2994177	1.015023	3303.9734
784.56104	2.298902	1.0174278	3302.6289
785.56201	2.3039834	1.0190505	3296.9543
786.56299	2.3023219	1.0212446	3296.189
787.56396	2.3103483	1.0233612	3300.7813
788.56494	2.3133819	1.0252911	3301.5361
789.56592	2.3140116	1.0270209	3291.2739
790.56689	2.3192322	1.0290442	3296.8669
791.56787	2.3219385	1.0307071	3297.554
792.56885	2.3243721	1.0324514	3302.8079
793.56982	2.3279936	1.0347552	3306.7131
794.5708	2.3309875	1.0367986	3300.6182
795.57178	2.3348446	1.0387899	3301.2864
796.57275	2.3366609	1.0409495	3299.9033
797.57373	2.3358629	1.0430707	3297.6641
798.57471	2.3411937	1.0453205	3298.4053
799.57568	2.3452804	1.0474404	3306.3542
800.57666	2.3504634	1.0496711	3305.3972
801.57764	2.3515368	1.0518737	3299.8716
802.57861	2.3530078	1.0536861	3296.957
803.57959	2.3585222	1.0555658	3293.7183
804.58057	2.3582652	1.0574273	3300.4521
805.58154	2.362062	1.0593669	3294.1108
806.58252	2.3672619	1.0613279	3303.5339
807.5835	2.3685341	1.0640918	3304.8267
808.58447	2.371644	1.0667098	3298.4944
809.58545	2.3765323	1.0688931	3302.3313
810.58643	2.3791234	1.0711209	3303.3398
811.5874	2.3798573	1.0732875	3294.0151
812.58838	2.3855281	1.0751989	3291.3611
813.58936	2.3886471	1.0770535	3293.6306
814.59033	2.3895605	1.0790474	3297.1204
815.59131	2.3935814	1.0811136	3299.2483
816.59229	2.3980658	1.0833049	3304.6152
817.59326	2.4006357	1.0857457	3302.2532
818.59424	2.4016681	1.0881817	3304.5801
819.59521	2.4084375	1.0906415	3297.198
820.59619	2.4108493	1.0929317	3302.8167
821.59717	2.4134099	1.0950304	3293.7126
822.59814	2.4157646	1.0969143	3298.0806
823.59912	2.417747	1.0988199	3297.5742
824.6001	2.4217074	1.1008835	3303.6958
825.60107	2.4248552	1.103119	3300.9736
826.60205	2.429364	1.105415	3295.8013
827.60303	2.430964	1.1072389	3299.6152
828.604	2.4293804	1.1092476	3291.7917
829.60498	2.4371362	1.1117157	3307.3262
830.60596	2.4378746	1.1138712	3302.1289
831.60693	2.4415469	1.1160525	3297.0144
832.60791	2.4478452	1.1186234	3294.4329
833.60889	2.4502196	1.1206465	3295.782
834.60986	2.4517109	1.1228269	3299.8577
835.61084	2.4534085	1.1254411	3302.0293
836.61182	2.4568076	1.1281481	3302.0713
837.61279	2.458719	1.130619	3299.6375
838.61377	2.4611444	1.1331868	3296.3743
839.61475	2.4664552	1.1360897	3302.6003
840.61572	2.4678438	1.1388004	3294.8406
841.6167	2.4723074	1.1410547	3299.6399
842.61768	2.4743352	1.1433135	3288.6248
843.61865	2.4771116	1.1454639	3297.4524
844.61963	2.4823875	1.1472754	3295.2727
845.62061	2.4841866	1.1496658	3297.4382
846.62158	2.4841332	1.1518079	3293.333
847.62256	2.489604	1.153963	3293.2842
848.62354	2.4950359	1.1560944	3294.783
849.62451	2.4969149	1.1584718	3300.1052
850.62549	2.4993162	1.1609164	3290.0044
851.62646	2.5001509	1.1632031	3290.2356
852.62744	2.5038204	1.1656586	3295.041
853.62842	2.5067461	1.1681858	3295.3196
854.62939	2.507143	1.1705518	3291.5271
855.63037	2.5105963	1.1733139	3294.0024
856.63135	2.5196128	1.1759034	3300.3252
857.63232	2.5193901	1.1785182	3299.4097
858.6333	2.5232458	1.1805608	3290.6968
859.63428	2.5236316	1.1826859	3294.6284
860.63525	2.5285664	1.1849575	3289.0627
861.63623	2.5348179	1.1869689	3292.3511
862.63721	2.5362122	1.1892586	3293.9814
863.63818	2.5360346	1.1916974	3290.0435
864.63916	2.5390928	1.194667	3297.092
865.64014	2.5402551	1.1972041	3291.9146
866.64111	2.5457866	1.1995484	3286.6104
867.64209	2.5485065	1.2018247	3285.0493
868.64307	2.5522282	1.2040344	3288.51
869.64404	2.5561781	1.2063628	3290.3359
870.64502	2.5581203	1.2093176	3299.9507
871.646	2.5599685	1.2120887	3281.1509
872.64697	2.5661051	1.2145267	3292.3115
873.64795	2.5669339	1.216761	3284.4031
874.64893	2.572248	1.2191046	3289.5149
875.6499	2.5720994	1.2217507	3291.9736
876.65088	2.5751767	1.2245047	3290.4805
877.65186	2.5813587	1.2272605	3290.4626
878.65283	2.5824831	1.2298088	3288.8838
879.65381	2.5814764	1.2321302	3282.8501
880.65479	2.5885739	1.2344736	3287.8435
881.65576	2.5899153	1.2368714	3282.6526
882.65674	2.597178	1.2393531	3287.4353
883.65771	2.5978613	1.2422597	3290.812
884.65869	2.5986032	1.2447493	3281.7578
885.65967	2.604614	1.2473853	3285.6863
886.66064	2.6070247	1.2500178	3285.1077
887.66162	2.6098413	1.2523562	3280.092
888.6626	2.6112485	1.2549282	3288.2322
889.66357	2.6154523	1.2580391	3286.9075
890.66455	2.6163752	1.2610229	3282.4531
891.66553	2.6239986	1.263687	3282.833
892.6665	2.6277211	1.2664183	3282.6497
893.66748	2.626282	1.2687963	3277.1289
894.66846	2.6319485	1.2714314	3283.4121
895.66943	2.6342974	1.2740999	3280.9438
896.67041	2.6359601	1.2766447	3280.1526
897.67139	2.6384087	1.279182	3281.876
898.67236	2.6411905	1.2818586	3281.2717
899.67334	2.6444516	1.2844158	3273.3274
900.67432	2.6495864	1.2863015	3274.2432
901.67529	2.6517761	1.2886424	3285.5007
902.67627	2.6531069	1.291437	3278.8091
903.67725	2.6575608	1.2942164	3270.8752
904.67822	2.6592538	1.2969391	3281.2012
905.6792	2.665596	1.2998828	3277.9587
906.68018	2.6658401	1.3025935	3270.0071
907.68115	2.6711981	1.3052253	3275.0989
908.68213	2.6726046	1.3078585	3273.3252
909.68311	2.6757994	1.3107513	3275.7314
910.68408	2.6793585	1.3136634	3273.1357
911.68506	2.6839201	1.3163416	3275.939
912.68604	2.6815119	1.3192613	3275.7085
913.68701	2.6874971	1.3221748	3274.272
914.68799	2.6891668	1.324994	3270.5544
915.68896	2.6943841	1.3277546	3266.6001
916.68994	2.6947176	1.3306698	3270.8252
917.69092	2.7016456	1.3341032	3270.6379
918.69189	2.702239	1.33653	3263.5947
919.69287	2.7042346	1.3391143	3264.2231
920.69385	2.7074835	1.3420625	3267.6794
921.69482	2.7088809	1.3444082	3263.2317
922.6958	2.7133868	1.3473581	3265.0532
923.69678	2.7141428	1.3497465	3264.8577
924.69775	2.7214715	1.3529713	3264.8
925.69873	2.724122	1.3563565	3268.5781
926.69971	2.7247086	1.3596286	3262.7319
927.70068	2.7295196	1.3624604	3256.9639
928.70166	2.7335813	1.3650975	3262.6875
929.70264	2.7325559	1.3674971	3257.5725
930.70361	2.7380893	1.3704313	3261.8948
931.70459	2.7426624	1.3735834	3257.3269
932.70557	2.7460766	1.3766441	3261.8887
933.70654	2.7487164	1.3792659	3257.7083
934.70752	2.7531486	1.3822051	3256.0278
935.7085	2.752923	1.3850858	3253.969
936.70947	2.7575459	1.3882434	3258.3098
937.71045	2.7587874	1.3910044	3252.0952
938.71143	2.7636662	1.3942345	3256.3574
939.7124	2.7650485	1.3971462	3247.6406
940.71338	2.7704034	1.4001726	3255.5701
941.71436	2.7721181	1.4027932	3242.0918
942.71533	2.7748158	1.4057357	3253.7344
943.71631	2.7767301	1.4084276	3241.7883
944.71729	2.7803848	1.4106387	3242.9614
945.71826	2.7841234	1.4133421	3249.2485
946.71924	2.7875688	1.416382	3249.644
947.72021	2.7925489	1.4193037	3245.6274
948.72119	2.7945752	1.4223592	3246.165
949.72217	2.7970676	1.4256282	3246.3921
950.72314	2.7974839	1.4290403	3238.4209
951.72412	2.8007896	1.4321346	3240.1799
952.7251	2.8031595	1.4354137	3241.635
953.72607	2.8108993	1.4385351	3241.4243
954.72705	2.812978	1.4415303	3236.3503
955.72803	2.8130553	1.4442812	3235.3047
956.729	2.8172283	1.4473629	3233.6125
957.72998	2.8200448	1.4501197	3234.9258
958.73096	2.8233254	1.4532919	3234.0037
959.73193	2.826457	1.4565734	3234.012
960.73291	2.8314636	1.4594738	3227.1284
961.73389	2.8324094	1.462448	3233.0786
962.73486	2.8369663	1.4652714	3225.135
963.73584	2.8372996	1.468037	3227.2966
964.73682	2.8438363	1.4710115	3223.2993
965.73779	2.844733	1.4740667	3224.6821
966.73877	2.8496771	1.4767803	3220.6375
967.73975	2.8526752	1.4799558	3218.9092
968.74072	2.8500428	1.4829962	3217.8057
969.7417	2.8580394	1.4863583	3216.4053
970.74268	2.859411	1.4892927	3213.9988
971.74365	2.8611591	1.4922713	3210.0803
972.74463	2.8660648	1.4951274	3214.1548
973.74561	2.8672817	1.4985026	3213.2908
974.74658	2.8697255	1.501009	3203.4817
975.74756	2.8731256	1.5037222	3202.1143
976.74854	2.8777649	1.506898	3206.8552
977.74951	2.8814261	1.5096648	3202.6255
978.75049	2.8816361	1.5125141	3202.3074
979.75146	2.8857749	1.5157927	3204.4526
980.75244	2.8890736	1.5193691	3205.0554
981.75342	2.8922186	1.5234249	3200.1055
982.75439	2.8952188	1.5266672	3194.2722
983.75537	2.895891	1.5297031	3190.7468
984.75635	2.8982363	1.532115	3194.1597
985.75732	2.9060569	1.5348618	3190.3027
986.7583	2.9060204	1.5377433	3195.5071
987.75928	2.9086061	1.5411315	3185.6953
988.76025	2.9102173	1.5439622	3185.4243
989.76123	2.9138343	1.5463628	3180.978
990.76221	2.9193437	1.5494535	3190.7888
991.76318	2.9240608	1.5528678	3183.2495
992.76416	2.924762	1.5561386	3185.3511
993.76514	2.9282718	1.5597689	3181.0647
994.76611	2.9310071	1.5629123	3179.5603
995.76709	2.9320247	1.5663962	3174.8188
996.76807	2.9364645	1.5691953	3171.1946
997.76904	2.9396772	1.5720437	3170.9214
998.77002	2.9442098	1.5753218	3169.4829
999.771	2.9462693	1.5789675	3166.7107
1000.772	2.9471166	1.5822765	3165.353
1001.7729	2.9510961	1.5851372	3161.4148
1002.7739	2.9545753	1.5875887	3161.269
1003.7749	2.9606791	1.5903699	3165.1709
1004.7759	2.9620466	1.5934519	3160.3235
1005.7769	2.9613943	1.5962285	3153.5754
1006.7778	2.966687	1.5992668	3159.1418
1007.7788	2.9699814	1.6022955	3151.4131
1008.7798	2.9722161	1.6055406	3153.7473
1009.7808	2.9767466	1.6085676	3152.3535
1010.7817	2.9792099	1.611611	3147.2529
1011.7827	2.9832256	1.6150988	3148.1777
1012.7837	2.9867702	1.6183245	3144.6257
1013.7847	2.9843154	1.6215432	3142.0876
1014.7856	2.9919839	1.6247377	3136.5376
1015.7866	2.9921908	1.6273885	3130.6938
1016.7876	2.9976475	1.6298898	3135.5156
1017.7886	2.9972603	1.6325392	3132.1887
1018.7896	3.0027332	1.6351736	3129.6177
1019.7905	3.0067165	1.6374308	3124.3008
1020.7915	3.0096831	1.6401988	3130.2405
1021.7925	3.0097988	1.6431689	3128.4553
1022.7935	3.0151105	1.6465367	3126.4373
1023.7944	3.0196879	1.6501713	3131.1316
1024.7954	3.0245092	1.6536376	3121.1213
1025.7964	3.0234361	1.6572974	3121.3796
1026.7974	3.026968	1.6605256	3113.9622
1027.7983	3.0297542	1.6637747	3111.1289
1028.7993	3.0298057	1.6669718	3107.2773
1029.8003	3.0361922	1.6699719	3108.7622
1030.8013	3.0386436	1.6729342	3102.9922
1031.8022	3.0423338	1.6758497	3110.135
1032.8032	3.0437262	1.6792518	3098.5969
1033.8042	3.0461695	1.6824479	3098.1604
1034.8052	3.0519547	1.6857404	3098.8347
1035.8062	3.0521023	1.6886725	3091.8442
1036.8071	3.0590284	1.6918584	3093.9653
1037.8081	3.0603623	1.6952788	3094.6443
1038.8091	3.0606499	1.6985739	3083.9514
1039.8101	3.0636284	1.7023231	3085.313
1040.811	3.0688183	1.7056135	3080.5823
1041.812	3.0717537	1.7088587	3074.793
1042.813	3.0765724	1.7116766	3073.0176
1043.814	3.0776765	1.7145579	3071.1182
1044.8149	3.080265	1.7181182	3072.866
1045.8159	3.0840085	1.7217249	3064.8601
1046.8169	3.086889	1.7244129	3060.9253
1047.8179	3.0897117	1.727631	3066.0391
1048.8188	3.0942819	1.7310846	3058.8669
1049.8198	3.0944731	1.7341725	3057.8521
1050.8208	3.0984447	1.7375532	3057.3123
1051.8218	3.1019282	1.7405392	3051.824
1052.8228	3.1043639	1.7433342	3047.7869
1053.8237	3.1084137	1.7461803	3045.2109
1054.8247	3.1106584	1.7494552	3041.271
1055.8257	3.1140068	1.7532301	3042.7666
1056.8267	3.1144488	1.7563041	3027.9729
1057.8276	3.1195211	1.7592491	3034.8035
1058.8286	3.1243522	1.7624853	3032.7681
1059.8296	3.1247034	1.7658675	3027.4001
1060.8306	3.1288731	1.7693316	3027.7542
1061.8315	3.1321197	1.7732021	3021.0151
1062.8325	3.136373	1.776674	3020.0574
1063.8335	3.1363769	1.7798417	3011.0037
1064.8345	3.14293	1.7830064	3011.6375
1065.8354	3.1425817	1.7865145	3010.0203
1066.8364	3.1478503	1.7901601	3005.6035
1067.8374	3.1493404	1.7935569	3001.6597
1068.8384	3.1547153	1.7965785	2992.6399
1069.8394	3.1548462	1.7990621	2989.6216
1070.8403	3.159128	1.8019519	2993.5496
1071.8413	3.1634939	1.8053015	2992.7834
1072.8423	3.1638129	1.8088385	2984.8743
1073.8433	3.1648362	1.8124824	2977.989
1074.8442	3.1711037	1.8157573	2973.2117
1075.8452	3.1731918	1.8187863	2969.7236
1076.8462	3.1778982	1.8212734	2971.8013
1077.8472	3.179014	1.823682	2967.0952
1078.8481	3.182579	1.8269463	2965.9954
1079.8491	3.1894729	1.8304276	2965.2874
1080.8501	3.1897039	1.8337876	2956.9365
1081.8511	3.1942093	1.8375152	2956.9536
1082.8521	3.1959405	1.8411382	2948.2888
1083.853	3.1972175	1.8443494	2946.3494
1084.854	3.2024422	1.8476139	2943.9194
1085.855	3.2023444	1.8505464	2935.031
1086.856	3.2053611	1.8539889	2932.644
1087.8569	3.2103126	1.8574277	2933.5601
1088.8579	3.2149966	1.861075	2928.1392
1089.8589	3.2145629	1.8644732	2916.4426
1090.8599	3.2194409	1.8678461	2911.7312
1091.8608	3.2216811	1.870899	2913.7966
1092.8618	3.2219229	1.8741722	2905.8242
1093.8628	3.2284453	1.8778696	2909.2153
1094.8638	3.2334049	1.8813028	2904.8733
1095.8647	3.2349169	1.8847767	2899.3301
1096.8657	3.2374952	1.888417	2887.9209
1097.8667	3.2413647	1.8917353	2890.1169
1098.8677	3.239507	1.8952959	2878.563
1099.8687	3.2463412	1.8986294	2879.6028
1100.8696	3.248024	1.9022472	2877.1455
1101.8706	3.2509491	1.9056495	2864.9697
1102.8716	3.2536387	1.9092091	2864.4863
1103.8726	3.2577755	1.9132183	2861.5059
1104.8735	3.2620854	1.9166822	2854.292
1105.8745	3.2651427	1.9196807	2850.8225
1106.8755	3.2635994	1.9224664	2842.0012
1107.8765	3.2718937	1.9261389	2843.8384
1108.8774	3.2733109	1.9298058	2837.0852
1109.8784	3.2771561	1.9329685	2823.7888
1110.8794	3.2815893	1.9356595	2829.5686
1111.8804	3.2827284	1.9388344	2823.0513
1112.8813	3.2847502	1.9425565	2814.2078
1113.8823	3.2879643	1.9458872	2807.7852
1114.8833	3.2924485	1.9493732	2804.6328
1115.8843	3.2931473	1.9526006	2790.8774
1116.8853	3.2967856	1.9557936	2792.3108
1117.8862	3.3010294	1.9592031	2789.3735
1118.8872	3.305177	1.9632236	2790.6873
1119.8882	3.3067391	1.9673961	2778.8225
1120.8892	3.3118408	1.9706752	2769.2556
1121.8901	3.3153231	1.9739326	2768.2751
1122.8911	3.3181744	1.9776968	2764.2383
1123.8921	3.3191504	1.9812698	2753.7607
1124.8931	3.3228219	1.9846491	2745.936
1125.894	3.3228786	1.9884218	2741.3582
1126.895	3.3279524	1.9924437	2730.2395
1127.896	3.3317113	1.9962459	2726.1821
1128.897	3.3309932	1.9994768	2714.0488
1129.8979	3.337198	2.0023999	2714.5955
1130.8989	3.3394108	2.0061941	2710.3005
1131.8999	3.3432021	2.010143	2703.0813
1132.9009	3.3454883	2.014246	2691.6221
1133.9019	3.3470075	2.0187201	2679.0762
1134.9028	3.3521686	2.0228539	2672.1985
1135.9038	3.3542051	2.026804	2655.937
1136.9048	3.3589668	2.0303872	2649.4617
1137.9058	3.3623044	2.0345032	2639.2222
1138.9067	3.3614435	2.0383458	2615.0217
1139.9077	3.368526	2.0414603	2614.7036
1140.9087	3.3715615	2.0442955	2602.2058
1141.9097	3.3746197	2.0467193	2593.7361
1142.9106	3.3786454	2.0497851	2584.6565
1143.9116	3.3776538	2.0528853	2567.8066
1144.9126	3.3838415	2.0544238	2541.5708
1145.9136	3.3860674	2.05462	2517.905
1146.9146	3.3919291	2.054976	2501.9399
1147.9155	3.3929281	2.0557423	2456.3723
1148.0156	3.3941889	2.0553076	2456.3606