File: datasets/am_bench_2022/raw_data/90-XY.17-1/specimen.dat
MTS793|MPT|ENU|1|2|.|/|:|1|0|0|A

Operator Information						Time:	10.80127	Sec	11/3/2021 8:31:42 AM
Operator	Nick Derimow
Project	AM Bench 2022 mini-tensile challenge
Specimen ID	90-XY.17-1
Material	PBF-L Inconel 625
Specimen Width	2.54	mm
Specimen Thickness	1.51	mm
Notes
Operator Information End

Data Acquisition						Time:	972.65918	Sec	11/3/2021 8:47:43 AM
Time	Axial Displacement	Axial Extensometer	Axial Force
Sec	mm	mm	N
10.91626	-0.0018489306	4.7751844e-05	27.30275
11.717041	0.00042884224	0.00010396061	37.737164
12.517822	0.0038191217	0.00014444707	46.649685
13.318604	0.0037289697	0.00024702674	57.200455
14.119385	0.0091583245	0.00025582066	66.77562
14.920166	0.011751373	0.00033466477	78.451485
15.720947	0.011372171	0.00041841599	88.460472
16.521729	0.018623518	0.00034207362	101.54033
17.32251	0.019148653	0.00051107898	108.76613
18.123291	0.019951006	0.00052013103	115.93143
18.924072	0.020464873	0.00049509748	126.12726
19.724854	0.023867497	0.00067440368	137.22588
20.525635	0.029382855	0.0007046333	144.85754
21.326416	0.028947666	0.00068930339	155.31169
22.127197	0.031453893	0.00069026637	170.99933
22.927979	0.033966213	0.00084458815	186.00594
23.72876	0.037774112	0.00096225191	199.10225
24.529541	0.04273852	0.0010677861	213.21381
25.330322	0.039032094	0.0011045835	223.34175
26.131104	0.042727251	0.0011867234	237.43172
26.931885	0.047837999	0.0011559118	249.01656
27.732666	0.046645943	0.001295376	268.8696
28.533447	0.050727781	0.0014412603	285.76669
29.334229	0.051792342	0.0014179437	299.55215
30.13501	0.055144925	0.0015352643	318.48367
30.935791	0.057905421	0.0016516199	334.63635
31.736572	0.05789784	0.0017515114	347.42947
32.537354	0.062301509	0.0018235542	365.75577
33.338135	0.065303519	0.0019975333	392.45218
34.138916	0.067898259	0.0020724537	405.14572
34.939697	0.070959277	0.0021711558	424.36594
35.740479	0.070324525	0.0022523203	437.2562
36.54126	0.07397645	0.0022931385	459.46936
37.342041	0.07574077	0.0023581453	476.33463
38.142822	0.078764908	0.0024734037	500.48596
38.943604	0.080350555	0.0025744385	516.20319
39.744385	0.084127262	0.0026943837	537.36829
40.545166	0.089087211	0.002739263	552.17969
41.345947	0.088372141	0.002845834	568.72052
42.146729	0.092459463	0.0029685495	589.87494
42.94751	0.092657387	0.0030556885	613.60718
43.748291	0.094577216	0.0031891535	628.65704
44.549072	0.098394074	0.0033111272	650.61713
45.349854	0.10067999	0.0033795319	673.91943
46.150635	0.10398386	0.0034314955	702.9679
46.951416	0.10668243	0.0036503046	723.43866
47.752197	0.10718257	0.0037043784	739.77527
48.552979	0.10763046	0.0037041572	754.31378
49.35376	0.11112995	0.0038835823	783.87183
50.154541	0.1157635	0.003978794	800.04993
50.955322	0.11889009	0.0041360911	830.04468
51.756104	0.11997417	0.0041816668	850.4527
52.556885	0.11992151	0.0043431884	873.79614
53.357666	0.12747267	0.0044634053	897.67822
54.158447	0.12536889	0.0045552608	917.47736
54.959229	0.13065811	0.0046458002	932.4729
55.76001	0.1310685	0.0047221342	953.73322
56.560791	0.13377035	0.0047895918	970.81848
57.361572	0.13449606	0.0048985383	990.14301
58.162354	0.139558	0.0050193542	1024.6307
58.963135	0.14194396	0.0052419938	1047.1406
59.763916	0.14192696	0.0053352839	1069.4077
60.564697	0.14505196	0.005383838	1091.951
61.365479	0.15034685	0.0054622772	1111.4612
62.16626	0.14952564	0.005510685	1132.2958
62.967041	0.15298744	0.0056638718	1159.1742
63.767822	0.1574893	0.0057294318	1182.6157
64.568604	0.15755405	0.0058772676	1201.7947
65.369385	0.1617813	0.0060016592	1229.23
66.170166	0.16137233	0.0060885656	1245.9221
66.970947	0.16442475	0.0062507256	1263.998
67.771729	0.16725567	0.0063664028	1304.1763
68.57251	0.16655311	0.0063888784	1312.6096
69.373291	0.17350541	0.0064771976	1337.4763
70.174072	0.16992398	0.0067244447	1351.906
70.974854	0.17705202	0.0067672506	1378.5459
71.775635	0.17672583	0.0069131511	1410.598
72.576416	0.18092093	0.0069692996	1427.8073
73.377197	0.18493085	0.0070362776	1454.5619
74.177979	0.18683526	0.0072523975	1478.3545
74.97876	0.18749808	0.0072909496	1502.7775
75.779541	0.19161983	0.0074242344	1524.1957
76.580322	0.19699264	0.0075424956	1545.4772
77.381104	0.19686191	0.0076939049	1572.0775
78.181885	0.19900814	0.0077804946	1588.2817
78.982666	0.20022309	0.0078883311	1607.3575
79.783447	0.20509884	0.0079688858	1634.8912
80.584229	0.20444277	0.0080964323	1655.1539
81.38501	0.20845899	0.0081635704	1679.4353
82.185791	0.21034399	0.0082943588	1696.0104
82.986572	0.21419528	0.0084760254	1728.683
83.787354	0.21875015	0.0085241375	1740.5568
84.588135	0.21800148	0.0085857725	1755.4357
85.388916	0.22083241	0.0087344553	1787.0469
86.189697	0.22384103	0.0088948794	1803.3351
86.990479	0.22503534	0.0089147007	1827.1564
87.79126	0.22621858	0.0090428591	1847.8921
88.592041	0.23167759	0.0090436582	1871.3844
89.392822	0.23238201	0.0093268137	1891.6439
90.193604	0.23454827	0.0093919355	1910.2543
90.994385	0.23760934	0.0094799912	1931.436
91.795166	0.23683567	0.0095324023	1950.0955
92.595947	0.24203207	0.0096281348	1968.613
93.396729	0.24481444	0.0097753508	1991.1431
94.19751	0.24841821	0.0098688705	2006.4214
94.998291	0.25196591	0.010007489	2025.4457
95.799072	0.25116169	0.010044841	2046.0532
96.599854	0.25551948	0.010066179	2057.6162
97.400635	0.25596717	0.010219632	2087.3896
98.201416	0.25811088	0.010310729	2093.0369
99.002197	0.26023227	0.010372594	2118.8079
99.802979	0.26270449	0.010478103	2132.9316
100.60376	0.26507938	0.010558972	2149.9883
101.40454	0.26716307	0.010800295	2172.2212
102.20532	0.27095595	0.010776097	2182.0344
103.0061	0.27558234	0.010906202	2200.551
103.80688	0.27564278	0.010915598	2218.8977
104.60767	0.27638859	0.010964677	2233.0486
105.40845	0.28063533	0.011163271	2249.5925
106.20923	0.28276762	0.011228286	2267.5667
107.01001	0.28467265	0.011250624	2274.2612
107.81079	0.28830695	0.011446751	2288.6667
108.61157	0.28814241	0.011480319	2302.2202
109.41235	0.2889497	0.011584461	2313.4121
110.21313	0.29530638	0.011678136	2325.7219
111.01392	0.29716757	0.011783871	2344.4917
111.8147	0.29968914	0.01186526	2354.9548
112.61548	0.30583316	0.011958268	2374.7786
113.41626	0.30634335	0.012039473	2384.5801
114.21704	0.30869955	0.012144015	2391.9041
115.01782	0.30768371	0.012230307	2405.7097
115.8186	0.31230229	0.012221263	2415.8376
116.61938	0.31180605	0.012331181	2424.8672
117.42017	0.31817669	0.012422036	2440.0576
118.22095	0.31964573	0.012459675	2443.6973
119.02173	0.32131597	0.012586403	2455.8015
119.82251	0.32451609	0.012691821	2467.5039
120.62329	0.32718641	0.012746204	2475.8408
121.42407	0.32660434	0.012826061	2486.7688
122.22485	0.3327412	0.013037399	2504.6699
123.02563	0.33795291	0.013155976	2517.3699
123.82642	0.33673468	0.013180235	2527.2502
124.6272	0.33442411	0.013330247	2538.2107
125.42798	0.34012249	0.013453708	2546.6394
126.22876	0.34173512	0.013573048	2557.196
127.02954	0.34653327	0.013695186	2558.1858
127.83032	0.34954596	0.013728456	2569.7908
128.6311	0.34949514	0.013850315	2574.2883
129.43188	0.35110408	0.013975338	2587.4016
130.23267	0.35633162	0.013998306	2598.5083
131.03345	0.35951665	0.014179477	2602.1807
131.83423	0.35880527	0.014284499	2615.5015
132.63501	0.36436099	0.014353686	2620.2427
133.43579	0.36470214	0.014485856	2629.5095
134.23657	0.36543462	0.014601477	2634.1313
135.03735	0.37159523	0.014762157	2652.7654
135.83813	0.37422988	0.014808321	2653.875
136.63892	0.37405857	0.014950933	2658.8591
137.4397	0.37809017	0.015022619	2669.1125
138.24048	0.37890851	0.015197848	2670.3982
139.04126	0.38037777	0.015296875	2681.6003
139.84204	0.38374144	0.01540996	2689.0388
140.64282	0.38588214	0.015506827	2693.0938
141.4436	0.393271	0.01564545	2705.3538
142.24438	0.39194515	0.015920214	2715.2078
143.04517	0.39647996	0.016018279	2725.4307
143.84595	0.39504695	0.016220806	2725.0164
144.64673	0.40127498	0.01637678	2739.3259
145.44751	0.4030655	0.016438534	2740.1809
146.24829	0.40297988	0.016608674	2744.6296
147.04907	0.40361053	0.01686337	2756.2766
147.84985	0.41059452	0.01699093	2775.2378
148.65063	0.41018414	0.01722238	2778.1726
149.45142	0.41116187	0.017356271	2771.6101
150.2522	0.41346383	0.017485015	2777.4446
151.05298	0.41775334	0.017733974	2789.6704
151.85376	0.42063695	0.017938634	2794.1362
152.65454	0.42222419	0.018100897	2794.9749
153.45532	0.4255918	0.018293772	2797.3872
154.2561	0.42637283	0.018503049	2816.8984
155.05688	0.43100843	0.018750358	2818.707
155.85767	0.42758662	0.019062376	2820.9849
156.65845	0.43454394	0.019147927	2831.5806
157.45923	0.43805739	0.01944273	2832.8806
158.26001	0.43860036	0.019684928	2847.7822
159.06079	0.44450769	0.020100877	2850.2905
159.86157	0.44518197	0.020337934	2856.3704
160.66235	0.44475868	0.020624511	2863.1753
161.46313	0.45084471	0.020848237	2861.7214
162.26392	0.45067424	0.021261899	2870.8582
163.0647	0.45488593	0.02158759	2876.7773
163.86548	0.45264488	0.021936987	2880.3799
164.66626	0.4609203	0.022219889	2887.6807
165.46704	0.46440136	0.022674523	2896.1541
166.26782	0.46101066	0.022827253	2892.3049
167.0686	0.46675289	0.023214368	2903.991
167.86938	0.46982887	0.023744449	2916.1025
168.67017	0.472215	0.024099022	2912.3013
169.47095	0.47610191	0.024553968	2918.7014
170.27173	0.47583351	0.02502813	2925.4243
171.07251	0.47999525	0.025517583	2931.7593
171.87329	0.48265877	0.025911719	2934.1477
172.67407	0.48274586	0.026484653	2941.6794
173.47485	0.4848443	0.026884424	2935.0928
174.27563	0.49050805	0.027276073	2948.2476
175.07642	0.49030685	0.027631633	2944.1707
175.8772	0.4899106	0.028250717	2950.2527
176.67798	0.49571592	0.028751442	2954.1802
177.47876	0.5028618	0.02933774	2967.9644
178.27954	0.49957091	0.029884903	2964.5999
179.08032	0.50374097	0.030349651	2969.3516
179.8811	0.50540739	0.03087547	2971.9556
180.68188	0.50780112	0.031361166	2971.9387
181.48267	0.51051569	0.031911563	2980.1123
182.28345	0.51370513	0.032522161	2983.7402
183.08423	0.5154596	0.033221029	2991.0769
183.88501	0.51808363	0.033850431	2994.002
184.68579	0.51751977	0.034356035	2992.114
185.48657	0.52035177	0.034895457	2992.4041
186.28735	0.52358717	0.035552688	2998.5261
187.08813	0.52708173	0.036193851	3003.6174
187.88892	0.53050107	0.036891475	3009.3088
188.6897	0.53350133	0.037545271	3015.7417
189.49048	0.53631377	0.038181797	3017.0273
190.29126	0.53559297	0.038851503	3017.8647
191.09204	0.53928381	0.039540291	3016.5417
191.89282	0.54126555	0.040374536	3024.3123
192.6936	0.54391557	0.041100141	3026.7759
193.49438	0.54603082	0.041695278	3029.9807
194.29517	0.54623616	0.042342	3035.8313
195.09595	0.55121577	0.043083377	3035.561
195.89673	0.55458373	0.043896314	3034.4089
196.69751	0.5562613	0.044627111	3045.0083
197.49829	0.56168127	0.045334693	3046.541
198.29907	0.56218034	0.045985565	3041.759
199.09985	0.56321794	0.046794735	3050.1292
199.90063	0.56326258	0.047502819	3054.6792
200.70142	0.56816906	0.048277557	3056.2004
201.5022	0.56956762	0.049037565	3057.5354
202.30298	0.57066602	0.049867153	3056.7026
203.10376	0.57641459	0.050674472	3058.1948
203.90454	0.57673115	0.051483795	3064.6274
204.70532	0.57882178	0.052213781	3067.0593
205.5061	0.58172202	0.05304588	3066.9009
206.30688	0.58571142	0.053904597	3075.0608
207.10767	0.58595705	0.054703608	3082.8452
207.90845	0.58941168	0.055610247	3077.9958
208.70923	0.59187263	0.056441631	3079.2061
209.51001	0.59378403	0.057118028	3079.582
210.31079	0.59672314	0.057674784	3082.9963
211.11157	0.60077548	0.05859933	3091.7913
211.91235	0.60218263	0.059254214	3084.6355
212.71313	0.6035285	0.059973683	3090.0566
213.51392	0.60343856	0.060749635	3092.6201
214.3147	0.60881364	0.061579198	3102.6943
215.11548	0.61004561	0.062342137	3099.2708
215.91626	0.61344022	0.063123502	3101.0027
216.71704	0.61507177	0.064023629	3102.8992
217.51782	0.61945653	0.064792246	3099.7654
218.3186	0.6235373	0.065502532	3110.1174
219.11938	0.62577659	0.066445716	3108.9067
219.92017	0.62704092	0.067189105	3109.8992
220.72095	0.62643856	0.068113334	3116.2981
221.52173	0.62774026	0.069001004	3119.3511
222.32251	0.63379282	0.069860786	3121.0549
223.12329	0.63425279	0.070672542	3117.7424
223.92407	0.63498652	0.071642205	3124.9238
224.72485	0.6398946	0.072375715	3123.0498
225.52563	0.64286613	0.073333763	3128.5215
226.32642	0.64463127	0.074030474	3122.2256
227.1272	0.64744538	0.074938901	3135.7168
227.92798	0.64841735	0.075837545	3133.5806
228.72876	0.65285915	0.076761074	3135.5903
229.52954	0.65419853	0.077644818	3142.9497
230.33032	0.6588583	0.078613795	3139.4719
231.1311	0.65886343	0.079424553	3140.0059
231.93188	0.66027695	0.080212668	3140.478
232.73267	0.66632628	0.08097437	3136.2446
233.53345	0.66728437	0.081684016	3143.96
234.33423	0.66799778	0.082565308	3150.8586
235.13501	0.67008841	0.083552182	3152.3386
235.93579	0.67470253	0.084388852	3153.0176
236.73657	0.67589581	0.085305586	3158.176
237.53735	0.67943913	0.086292319	3158.9304
238.33813	0.68136531	0.087268546	3161.3689
239.13892	0.68337154	0.088175565	3161.4424
239.9397	0.68265265	0.088943377	3161.7446
240.74048	0.68593496	0.089796044	3155.4534
241.54126	0.69180906	0.090453416	3160.0425
242.34204	0.69046336	0.091205224	3171.0515
243.14282	0.69732958	0.092194229	3176.1062
243.9436	0.69690055	0.093157262	3168.2109
244.74438	0.69870543	0.093987517	3177.5039
245.54517	0.70376557	0.094821237	3175.3513
246.34595	0.70406389	0.095666692	3176.0173
247.14673	0.70760113	0.096478052	3172.2793
247.94751	0.7091046	0.097309411	3178.9453
248.74829	0.71281612	0.098160416	3184.0103
249.54907	0.71563601	0.099217497	3189.8855
250.34985	0.71759635	0.10003964	3184.8394
251.15063	0.72029126	0.10091264	3187.7031
251.95142	0.72407353	0.10185844	3196.4758
252.7522	0.72785145	0.10292485	3202.376
253.55298	0.72758591	0.10372134	3195.1675
254.35376	0.73010808	0.10458306	3196.7161
255.15454	0.73220038	0.10537779	3196.3945
255.95532	0.73430502	0.10618887	3198.5029
256.7561	0.73390365	0.10712217	3203.5461
257.55688	0.73570752	0.10816309	3207.3765
258.35767	0.7417056	0.10902513	3207.4492
259.15845	0.74290502	0.10976923	3199.7871
259.95923	0.74672437	0.11054762	3203.2061
260.76001	0.74849546	0.11142068	3204.738
261.56079	0.75140589	0.11229716	3214.5447
262.36157	0.75234056	0.11308029	3213.9053
263.16235	0.75339037	0.11401933	3219.0225
263.96313	0.75717938	0.1150974	3222.2957
264.76392	0.76126325	0.11591542	3215.1501
265.5647	0.76140177	0.11675185	3216.8801
266.36548	0.76401144	0.11794211	3226.7737
267.16626	0.76905209	0.11884796	3228.6211
267.96704	0.77032852	0.11968071	3223.552
268.76782	0.77201641	0.12071169	3228.0237
269.5686	0.77536619	0.12176678	3231.4473
270.36938	0.77560961	0.12255668	3231.3196
271.17017	0.77881628	0.12352062	3229.4609
271.97095	0.78078771	0.12444144	3233.3994
272.77173	0.78468567	0.12521712	3238.7295
273.57251	0.78705215	0.12629968	3238.7695
274.37329	0.78962356	0.12716821	3241.2275
275.17407	0.78974956	0.12825049	3244.7737
275.97485	0.7944935	0.12910573	3241.8523
276.77563	0.79533172	0.13000345	3241.8057
277.57642	0.79936314	0.13068989	3243.4597
278.3772	0.79734164	0.1315238	3237.8887
279.17798	0.80203509	0.13240393	3250.5845
279.97876	0.80624205	0.13343783	3254.9927
280.77954	0.80667007	0.134389	3249.7715
281.58032	0.81106305	0.13526104	3252.6672
282.3811	0.81422901	0.13608392	3253.4648
283.18188	0.8160001	0.13676512	3256.0264
283.98267	0.81666803	0.13750806	3251.9412
284.78345	0.82122183	0.13838863	3259.5571
285.58423	0.82259607	0.13922198	3259.9365
286.38501	0.82469797	0.14011727	3261.1091
287.18579	0.82514012	0.14116779	3264.2083
287.98657	0.83061457	0.14212263	3263.6431
288.78735	0.83221233	0.14288931	3257.7285
289.58813	0.83619636	0.14359805	3263.9143
290.38892	0.83642501	0.14441109	3265.6509
291.1897	0.8409766	0.14528522	3274.8765
291.99048	0.84157223	0.1463169	3274.5806
292.79126	0.84450293	0.14730214	3277.9878
293.59204	0.84913504	0.14839488	3278.8452
294.39282	0.85090202	0.14926672	3282.1421
295.1936	0.85141015	0.1500126	3271.5947
295.99438	0.85499549	0.15103599	3281.6101
296.79517	0.85511476	0.15193969	3279.6267
297.59595	0.85768366	0.15293111	3285.1509
298.39673	0.85923302	0.15371214	3278.7036
299.19751	0.86474901	0.15469989	3287.9768
299.99829	0.86793625	0.15564102	3290.4182
300.79907	0.8686235	0.15656361	3292.9771
301.59985	0.86994237	0.15747254	3287.7048
302.40063	0.87116528	0.15850762	3292.1838
303.20142	0.87321091	0.15934043	3290.7686
304.0022	0.87715322	0.16029148	3289.3308
304.80298	0.8811993	0.16124256	3295.8452
305.60376	0.88263172	0.16197748	3295.8391
306.40454	0.88565302	0.16278256	3298.7256
307.20532	0.88931578	0.16364536	3301.8713
308.0061	0.89204305	0.16449927	3301.3333
308.80688	0.8913458	0.16534169	3301.6631
309.60767	0.89449519	0.16620569	3304.0698
310.40845	0.89722699	0.16704662	3306.1379
311.20923	0.89837062	0.16788609	3307.175
312.01001	0.90423334	0.16873084	3306.7893
312.81079	0.90591687	0.16971318	3312.8557
313.61157	0.9058218	0.17067243	3309.311
314.41235	0.9096123	0.17167993	3311.5537
315.21313	0.90889025	0.17256917	3309.4822
316.01392	0.91306072	0.17338018	3314.3699
316.8147	0.91645223	0.17424226	3314.27
317.61548	0.92032301	0.17506869	3314.6655
318.41626	0.91956818	0.17591746	3308.6257
319.21704	0.92067313	0.17669432	3315.6199
320.01782	0.92893302	0.17764574	3330.9722
320.8186	0.92969626	0.17848435	3326.5635
321.61938	0.93297774	0.17937317	3326.4282
322.42017	0.93378252	0.18008634	3322.9236
323.22095	0.93422019	0.18113501	3327.804
324.02173	0.93712717	0.18215355	3329.4124
324.82251	0.93982697	0.18313171	3337.2461
325.62329	0.94284433	0.18409638	3332.261
326.42407	0.94641	0.18493989	3334.2058
327.22485	0.94967741	0.18587334	3334.8533
328.02563	0.95039064	0.18692017	3343.8025
328.82642	0.95398152	0.18800998	3341.9639
329.6272	0.95703167	0.18882899	3341.3777
330.42798	0.95587015	0.18963625	3339.5869
331.22876	0.95788938	0.19063294	3342.9595
332.02954	0.96127141	0.19150554	3348.1692
332.83032	0.9642989	0.19252665	3344.491
333.6311	0.96658278	0.19357824	3344.3625
334.43188	0.96751726	0.19431262	3339.4587
335.23267	0.97029901	0.19518946	3346.3479
336.03345	0.97364855	0.19601898	3349.4897
336.83423	0.97346312	0.19702035	3353.7917
337.63501	0.9807744	0.19790903	3354.3538
338.43579	0.98137659	0.19902167	3356.5891
339.23657	0.98555583	0.19992149	3355.4695
340.03735	0.9854511	0.20091546	3355.5996
340.83813	0.98954445	0.201915	3353.8882
341.63892	0.98983848	0.20274402	3365.043
342.4397	0.99537367	0.20381656	3362.4412
343.24048	0.99620044	0.20476143	3360.0305
344.04126	0.99557143	0.20559068	3361.7012
344.84204	0.99936146	0.20657165	3360.6455
345.64282	1.002678	0.20742069	3363.0398
346.4436	1.0020344	0.20844936	3368.8176
347.24438	1.0083841	0.20930277	3368.6399
348.04517	1.010902	0.21013434	3368.9753
348.84595	1.0124207	0.21111152	3369.303
349.64673	1.0128255	0.2118648	3368.7029
350.44751	1.0166637	0.21269415	3374.0278
351.24829	1.0204554	0.21367759	3373.3271
352.04907	1.0207486	0.2145987	3378.7813
352.84985	1.0255094	0.21556388	3377.5291
353.65063	1.0265397	0.21635655	3378.1841
354.45142	1.0276455	0.21732175	3378.8872
355.2522	1.0329779	0.21825148	3384.761
356.05298	1.0303464	0.21932761	3378.8071
356.85376	1.0364085	0.2201957	3379.2366
357.65454	1.0409321	0.22114746	3385.4673
358.45532	1.041501	0.22206211	3392.7507
359.2561	1.0448704	0.22295757	3388.812
360.05688	1.043873	0.22387516	3389.3442
360.85767	1.0476462	0.2248098	3392.2852
361.65845	1.0518858	0.22573161	3395.7424
362.45923	1.0554806	0.22671746	3390.9043
363.26001	1.0584885	0.22757417	3394.8691
364.06079	1.0542458	0.22851905	3392.0557
364.86157	1.0601361	0.22938754	3395.6455
365.66235	1.064212	0.23033594	3403.2209
366.46313	1.0632162	0.2313	3397.7441
367.26392	1.0648211	0.2321925	3398.3103
368.0647	1.0696659	0.23291767	3391.1118
368.86548	1.0722002	0.23377454	3400.7769
369.66626	1.0731605	0.23472488	3399.8721
370.46704	1.0786536	0.23564446	3405.3391
371.26782	1.0793084	0.23660964	3400.8682
372.0686	1.0842563	0.23742378	3406.5732
372.86938	1.0859371	0.23828523	3409.771
373.67017	1.0859861	0.23933333	3412.4299
374.47095	1.088334	0.24024898	3407.8867
375.27173	1.0936594	0.2413134	3417.1104
376.07251	1.0925488	0.24224503	3407.0574
376.87329	1.1006271	0.2432574	3414.5688
377.67407	1.0993525	0.24412324	3418.0854
378.47485	1.1016918	0.24517013	3423.072
379.27563	1.1045078	0.24603747	3420.145
380.07642	1.1069827	0.24696498	3423.594
380.8772	1.1107112	0.24805234	3423.3245
381.67798	1.1111376	0.24898078	3424.7507
382.47876	1.1144687	0.24990007	3423.6753
383.27954	1.1148174	0.25073943	3421.1794
384.08032	1.118227	0.2516371	3423.3254
384.8811	1.1180024	0.25246233	3418.907
385.68188	1.121864	0.25338933	3421.1489
386.48267	1.123263	0.25423446	3428.5623
387.28345	1.1278039	0.25515339	3427.3945
388.08423	1.1308774	0.2560727	3429.5586
388.88501	1.13212	0.25688037	3429.5532
389.68579	1.1332868	0.25790554	3433.5449
390.48657	1.1367857	0.25890931	3439.4277
391.28735	1.1398923	0.25972292	3428.0356
392.08813	1.1393787	0.26056188	3432.624
392.88892	1.1450901	0.2616041	3443.5869
393.6897	1.1485995	0.26259243	3438.2588
394.49048	1.1503325	0.26367721	3446.939
395.29126	1.1511934	0.26467714	3441.26
396.09204	1.1532593	0.26553085	3434.9841
396.89282	1.1573547	0.26645064	3443.3237
397.6936	1.1568745	0.26740745	3446.3706
398.49438	1.1607723	0.26834321	3444.416
399.29517	1.163365	0.26936832	3446.0698
400.09595	1.1648921	0.27011958	3444.8296
400.89673	1.1691154	0.2712031	3447.8459
401.69751	1.1704457	0.27222309	3448.3154
402.49829	1.1734378	0.27293703	3447.4917
403.29907	1.1732496	0.27382156	3452.0088
404.09985	1.178232	0.27497897	3459.9192
404.90063	1.1808382	0.2758674	3457.7
405.70142	1.183778	0.27689067	3457.0435
406.5022	1.1851881	0.27791873	3462.6272
407.30298	1.185781	0.27889144	3455.3186
408.10376	1.1902283	0.27975351	3450.2727
408.90454	1.1926677	0.28054178	3456.5828
409.70532	1.1951647	0.28159663	3464.322
410.5061	1.1962479	0.2825796	3466.8589
411.30688	1.2025511	0.28347388	3460.5955
412.10767	1.2011288	0.28443325	3464.8262
412.90845	1.2048572	0.28525391	3460.3235
413.70923	1.207954	0.28599581	3460.1116
414.51001	1.2087656	0.28689632	3470.0725
415.31079	1.2133142	0.2879642	3478.2053
416.11157	1.2142285	0.28906298	3474.3086
416.91235	1.2164176	0.29010117	3480.1628
417.71313	1.2187437	0.29100966	3468.4917
418.51392	1.2222307	0.29198709	3473.2053
419.3147	1.2241316	0.29299885	3472.8557
420.11548	1.2241341	0.2937969	3473.7673
420.91626	1.22835	0.29460117	3473.6113
421.71704	1.2331818	0.29546532	3478.344
422.51782	1.235105	0.29630086	3480.3108
423.3186	1.2376704	0.29716805	3478.0161
424.11938	1.2370974	0.29823747	3482.5132
424.92017	1.2430595	0.29910049	3481.4304
425.72095	1.244279	0.3000927	3489.2876
426.52173	1.2457675	0.30092406	3480.5813
427.32251	1.249806	0.30180246	3483.8691
428.12329	1.2504164	0.30263454	3481.7073
428.92407	1.254719	0.30346954	3481.4604
429.72485	1.2538868	0.30409488	3483.7102
430.52563	1.2567894	0.30512014	3487.4768
431.32642	1.2627661	0.30606142	3491.6873
432.1272	1.2632339	0.30700022	3489.0681
432.92798	1.264869	0.30780309	3491.8325
433.72876	1.2684004	0.30880776	3496.1899
434.52954	1.2668686	0.31000903	3494.9902
435.33032	1.2730715	0.31099796	3491.0085
436.1311	1.2749763	0.31176975	3497.9277
436.93188	1.275519	0.31267989	3488.2961
437.73267	1.2782475	0.31353414	3496.3472
438.53345	1.2792569	0.31434771	3492.6938
439.33423	1.2827328	0.31517541	3498.6899
440.13501	1.286049	0.31615707	3504.4644
440.93579	1.2893565	0.31721187	3503.9043
441.73657	1.2927978	0.31811768	3501.9487
442.53735	1.294208	0.31889686	3500.2512
443.33813	1.296167	0.31984341	3500.7861
444.13892	1.2974416	0.3208268	3505.2864
444.9397	1.3009838	0.32184198	3512.7195
445.74048	1.3030695	0.32290921	3507.8032
446.54126	1.3039523	0.32382861	3504.1289
447.34204	1.3087101	0.32477427	3516.0635
448.14282	1.3075827	0.32578233	3505.2119
448.9436	1.312662	0.32666269	3509.2559
449.74438	1.3141732	0.32766673	3514.0928
450.54517	1.3197489	0.32869381	3515.4094
451.34595	1.3212831	0.32972965	3517.3064
452.14673	1.3222877	0.33093867	3517.1238
452.94751	1.3252213	0.33185551	3516.5151
453.74829	1.3266547	0.3329235	3521.9573
454.54907	1.3323276	0.33385471	3517.3384
455.34985	1.3315617	0.33475649	3513.1533
456.15063	1.3329377	0.33565938	3519.2122
456.95142	1.3363901	0.33664662	3522.7197
457.7522	1.3392984	0.33755389	3523.9187
458.55298	1.342929	0.33834824	3526.5469
459.35376	1.3431257	0.33934912	3524.4949
460.15454	1.3456507	0.34036711	3529.3901
460.95532	1.3493153	0.34127834	3525.9133
461.7561	1.3495394	0.34236318	3526.2449
462.55688	1.3555645	0.34328794	3530.9597
463.35767	1.3564801	0.34417468	3525.8645
464.15845	1.3569232	0.34506574	3529.1953
464.95923	1.3620414	0.34598753	3524.8525
465.76001	1.3633435	0.34695801	3534.6211
466.56079	1.3627281	0.3478944	3529.8225
467.36157	1.3676429	0.34870476	3531.5115
468.16235	1.368745	0.34978992	3536.4309
468.96313	1.3718086	0.35074791	3534.855
469.76392	1.3743044	0.35178328	3540.4863
470.5647	1.3802609	0.3526994	3542.6484
471.36548	1.3786415	0.35384765	3538.261
472.16626	1.3825847	0.35471258	3536.46
472.96704	1.3860528	0.35555807	3535.7136
473.76782	1.3896208	0.35641575	3541.0288
474.5686	1.3906541	0.35725358	3539.2478
475.36938	1.3954818	0.35809597	3542.1484
476.17017	1.3973205	0.35904062	3544.5037
476.97095	1.3966167	0.35993299	3545.9424
477.77173	1.3997554	0.36094099	3550.1704
478.57251	1.4045712	0.36198875	3550.6399
479.37329	1.4046353	0.36292109	3547.575
480.17407	1.4045721	0.36388627	3546.9143
480.97485	1.4083687	0.36487898	3552.3181
481.77563	1.4114606	0.36587507	3549.8853
482.57642	1.4125204	0.36676189	3547.8503
483.3772	1.4146709	0.36767653	3549.7642
484.17798	1.4179497	0.36859423	3552.9683
484.97876	1.4232864	0.3695868	3555.5486
485.77954	1.4236553	0.37057343	3559.9119
486.58032	1.424422	0.37149957	3554.3289
487.3811	1.427668	0.3724623	3555.2795
488.18188	1.4300303	0.3733924	3560.7024
488.98267	1.4317552	0.37468049	3559.8721
489.78345	1.4368759	0.37560764	3557.2056
490.58423	1.4367343	0.37653449	3557.9343
491.38501	1.4417892	0.37754461	3563.5598
492.18579	1.443017	0.37858009	3563.2119
492.98657	1.4460036	0.37977025	3568.8875
493.78735	1.4485034	0.38091797	3562.489
494.58813	1.4516052	0.38194567	3574.1958
495.38892	1.4498452	0.38291615	3560.936
496.1897	1.4544768	0.38398504	3565.8396
496.99048	1.458065	0.38494629	3565.0525
497.79126	1.459049	0.38577464	3561.3501
498.59204	1.4603931	0.38654611	3560.6162
499.39282	1.4649289	0.38740379	3562.2417
500.1936	1.4689325	0.38808787	3565.9819
500.99438	1.4655658	0.38884294	3567.4976
501.79517	1.4737158	0.38968298	3571.5161
502.59595	1.4740275	0.39059687	3574.0085
503.39673	1.474987	0.39148009	3570.0867
504.19751	1.4796216	0.39257887	3575.3374
504.99829	1.4791223	0.39360744	3577.1577
505.79907	1.4836748	0.39478025	3581.6768
506.59985	1.4860361	0.39563656	3573.1348
507.40063	1.4881419	0.39672175	3582.0706
508.20142	1.4913808	0.3977012	3579.3091
509.0022	1.4947873	0.39873841	3585.3523
509.80298	1.4958061	0.39978474	3582.8162
510.60376	1.4987034	0.40075225	3588.9263
511.40454	1.502116	0.40175208	3585.2505
512.20532	1.5025984	0.40268251	3580.8298
513.0061	1.5037696	0.40364525	3580.5811
513.80688	1.5062727	0.40438494	3582.0986
514.60767	1.5087531	0.40538365	3586.1819
515.40845	1.5130584	0.40638858	3588.0928
516.20923	1.5158342	0.40749446	3592.6836
517.01001	1.5171862	0.40873837	3587.2515
517.81079	1.5187073	0.4098182	3590.1948
518.61157	1.5214874	0.4107835	3585.1345
519.41235	1.5242882	0.41197017	3594.533
520.21313	1.5270129	0.41306219	3594.1973
521.01392	1.5289383	0.41416296	3590.9905
521.8147	1.5319027	0.41532961	3598.7913
522.61548	1.5333893	0.41639766	3589.3899
523.41626	1.5349287	0.41720468	3587.4585
524.21704	1.539186	0.4182587	3593.8223
525.01782	1.5408767	0.41928232	3599.7864
525.8186	1.5455513	0.42021626	3597.0916
526.61938	1.5455736	0.42131528	3598.3081
527.42017	1.5505079	0.42228085	3598.4004
528.22095	1.5517932	0.42325208	3603.2444
529.02173	1.5526897	0.42429358	3593.5581
529.82251	1.5582671	0.42528731	3603.7534
530.62329	1.5580008	0.42616811	3597.1904
531.42407	1.5602427	0.42711383	3602.729
532.22485	1.5638742	0.42810327	3601.906
533.02563	1.5652583	0.42906365	3606.1763
533.82642	1.5653124	0.42996034	3602.3628
534.6272	1.5716081	0.43118173	3612.064
535.42798	1.5722268	0.43198019	3604.8743
536.22876	1.5757419	0.43297014	3601.1917
537.02954	1.5792866	0.43398196	3617.7305
537.83032	1.5816032	0.43490595	3610.3831
538.6311	1.5813874	0.43576002	3602.584
539.43188	1.5848944	0.43684655	3608.7864
540.23267	1.5858867	0.43793747	3613.0872
541.03345	1.5891899	0.43899798	3610.7156
541.83423	1.5934206	0.43988961	3610.9067
542.63501	1.593735	0.44085842	3617.8235
543.43579	1.5935651	0.44189945	3616.9756
544.23657	1.5965915	0.44302008	3610.5637
545.03735	1.6014758	0.4440819	3619.9419
545.83813	1.6040572	0.44509834	3614.8308
546.63892	1.605525	0.44598931	3611.6919
547.4397	1.6046239	0.44695997	3614.6448
548.24048	1.6120077	0.44809854	3617.4951
549.04126	1.6145686	0.44890612	3620.1377
549.84204	1.6149426	0.44984767	3618.4541
550.64282	1.6187366	0.45088267	3625.2642
551.4436	1.6190184	0.45195243	3622.4653
552.24438	1.6228906	0.45309353	3622.8066
553.04517	1.6253886	0.45408162	3620.1389
553.84595	1.6251993	0.4552319	3631.4993
554.64673	1.6311316	0.45653009	3624.3162
555.44751	1.6302885	0.45764101	3625.5317
556.24829	1.6378394	0.45879456	3625.2039
557.04907	1.635361	0.45976058	3623.0342
557.84985	1.6379762	0.46079105	3624.73
558.65063	1.6440896	0.46166363	3625.7302
559.45142	1.6452686	0.46250185	3627.7874
560.2522	1.6460721	0.46342888	3626.8987
561.05298	1.6484952	0.4644767	3631.271
561.85376	1.6535556	0.4655689	3634.9424
562.65454	1.6553825	0.46674231	3635.9146
563.45532	1.6555117	0.46801507	3636.2461
564.2561	1.6584038	0.46896249	3628.5491
565.05688	1.6636741	0.47003478	3633.6958
565.85767	1.6626114	0.47090736	3628.4363
566.65845	1.6674889	0.47173271	3633.0637
567.45923	1.6692313	0.4725683	3633.2502
568.26001	1.6694745	0.4737291	3640.6763
569.06079	1.6751077	0.47491482	3646.0613
569.86157	1.6762205	0.47594288	3632.947
570.66235	1.6783248	0.47674766	3631.6357
571.46313	1.6778895	0.47769299	3630.3992
572.26392	1.6828744	0.47859526	3634.5952
573.0647	1.6877873	0.47947806	3636.3931
573.86548	1.6886193	0.48051745	3642.0381
574.66626	1.6937363	0.48144379	3643.0247
575.46704	1.6927915	0.48248783	3646.2527
576.26782	1.6952868	0.48353222	3642.7151
577.0686	1.6977614	0.48472667	3647.7104
577.86938	1.697296	0.48581192	3641.8916
578.67017	1.6991729	0.48682687	3642.9541
579.47095	1.7069461	0.48804334	3654.3882
580.27173	1.7100674	0.48902151	3643.8613
581.07251	1.7110146	0.4899843	3637.9785
581.87329	1.7114969	0.49080226	3640.3267
582.67407	1.7134936	0.4919098	3644.4204
583.47485	1.7177327	0.49294415	3652.6362
584.27563	1.7176858	0.49401367	3650.6792
585.07642	1.7220166	0.49520478	3649.5535
585.8772	1.7220188	0.49637827	3650.5042
586.67798	1.7277867	0.49748167	3658.0139
587.47876	1.7297118	0.49861243	3655.842
588.27954	1.7317663	0.49978441	3656.6655
589.08032	1.7336497	0.50081307	3652.9827
589.8811	1.7388113	0.50197899	3665.8452
590.68188	1.7387229	0.50332367	3657.2319
591.48267	1.7438459	0.50450313	3656.3992
592.28345	1.7437272	0.50550061	3652.9075
593.08423	1.7448735	0.50642341	3657.6335
593.88501	1.7473043	0.50732172	3651.8555
594.68579	1.7484732	0.50828439	3651.3699
595.48657	1.7530198	0.50913942	3652.1628
596.28735	1.7527791	0.50998789	3652.2573
597.08813	1.7577496	0.51110291	3660.5449
597.88892	1.7606448	0.51212513	3664.8789
598.6897	1.7622153	0.51316667	3662.5298
599.49048	1.7623651	0.51435065	3660.6553
600.29126	1.7692149	0.51543778	3666.1633
601.09204	1.7705324	0.51652956	3661.5676
601.89282	1.7721921	0.51774859	3671.3635
602.6936	1.7745614	0.51882803	3663.0984
603.49438	1.7752284	0.51985615	3667.2942
604.29517	1.7771486	0.52113837	3662.7827
605.09595	1.7811111	0.52213204	3658.8801
605.89673	1.7861965	0.52322567	3665.7815
606.69751	1.7892678	0.52435052	3666.249
607.49829	1.7899075	0.52545023	3669.605
608.29907	1.7916291	0.52644151	3661.9866
609.09985	1.7920889	0.52743918	3664.1931
609.90063	1.7977526	0.5285511	3671.4585
610.70142	1.7994362	0.529589	3670.0203
611.5022	1.7977512	0.53081912	3673.8264
612.30298	1.8014643	0.53170103	3664.7429
613.10376	1.8032736	0.53285801	3671.9087
613.90454	1.809347	0.5339998	3673.5642
614.70532	1.8106706	0.53501832	3671.1277
615.5061	1.810468	0.53600436	3674.5347
616.30688	1.8121556	0.53710181	3667.1638
617.10767	1.8174043	0.53815341	3670.6643
617.90845	1.8175588	0.5392012	3679.0313
618.70923	1.8214058	0.54030836	3673.7856
619.51001	1.8240503	0.54135484	3675.9578
620.31079	1.8273799	0.54232991	3668.6626
621.11157	1.8303733	0.54320997	3671.854
621.91235	1.8316951	0.54423577	3673.4182
622.71313	1.8344914	0.54550093	3675.0686
623.51392	1.8357095	0.5468049	3688.4307
624.3147	1.8399363	0.54821765	3688.228
625.11548	1.8402313	0.54936528	3681.2593
625.91626	1.8415178	0.55055135	3677.7803
626.71704	1.844673	0.55151141	3679.1047
627.51782	1.849561	0.55271238	3684.5432
628.3186	1.8487897	0.55384809	3680.8018
629.11938	1.851449	0.55494601	3678.5635
629.92017	1.8573412	0.55585992	3674.3386
630.72095	1.8552353	0.55689758	3675.4189
631.52173	1.8620502	0.55787784	3675.5752
632.32251	1.8630443	0.55889958	3683.3245
633.12329	1.8645813	0.55988687	3682.7305
633.92407	1.870087	0.56101215	3686.4609
634.72485	1.870687	0.56232911	3688.3059
635.52563	1.8715246	0.56355149	3683.0525
636.32642	1.8720419	0.56461543	3683.4875
637.1272	1.8793882	0.56582963	3688.3081
637.92798	1.8779567	0.56693131	3684.3914
638.72876	1.8844913	0.56794327	3687.7549
639.52954	1.8831517	0.56913275	3686.1021
640.33032	1.8876852	0.57039332	3690.7576
641.1311	1.8898506	0.57161885	3693.2017
641.93188	1.8900582	0.57254469	3686.8069
642.73267	1.8937161	0.57354403	3692.5356
643.53345	1.8976489	0.57487208	3693.3315
644.33423	1.8992888	0.57608503	3693.5583
645.13501	1.9034033	0.57744777	3696.9092
645.93579	1.90361	0.57860386	3688.1785
646.73657	1.9069325	0.57940531	3684.8196
647.53735	1.9088787	0.58037478	3692.1877
648.33813	1.9106339	0.58136153	3692.1851
649.13892	1.9129615	0.58240652	3697.0491
649.9397	1.916532	0.58345449	3692.4954
650.74048	1.9189956	0.58472222	3698.3391
651.54126	1.920803	0.58582288	3695.8232
652.34204	1.9249784	0.58687943	3696.3335
653.14282	1.9224275	0.58809626	3694.9978
653.9436	1.9286487	0.58907974	3694.3901
654.74438	1.9297895	0.59017074	3694.5623
655.54517	1.9332108	0.59146905	3694.6907
656.34595	1.9369183	0.59246802	3696.2334
657.14673	1.936699	0.59361434	3695.7114
657.94751	1.9396516	0.59476137	3701.9775
658.74829	1.9447716	0.59599489	3703.8303
659.54907	1.9476135	0.59754854	3712.7466
660.34985	1.9466814	0.5988766	3704.395
661.15063	1.9487156	0.60016292	3694.7637
661.95142	1.9510874	0.60138863	3701.7183
662.7522	1.9541078	0.60248625	3697.2722
663.55298	1.9560063	0.60367244	3700.0339
664.35376	1.9595069	0.60488158	3700.7217
665.15454	1.9627388	0.6059528	3700.8569
665.95532	1.9640386	0.60690063	3698.4238
666.7561	1.9672545	0.60809749	3701.7925
667.55688	1.9720235	0.60919827	3701.947
668.35767	1.9696876	0.61025363	3698.0283
669.15845	1.9718456	0.61137128	3695.8188
669.95923	1.9751374	0.61238348	3704.7549
670.76001	1.9782853	0.61345297	3705.3284
671.56079	1.9813633	0.61462981	3712.5315
672.36157	1.9840136	0.61590183	3705.8962
673.16235	1.9847469	0.61730254	3708.5876
673.96313	1.9862248	0.61887479	3709.2744
674.76392	1.9886587	0.6200341	3704.269
675.5647	1.992399	0.62104821	3704.6255
676.36548	1.9966093	0.62231517	3709.0371
677.16626	1.998968	0.62339813	3708.0591
677.96704	1.998513	0.62443876	3705.4856
678.76782	2.0043402	0.62553805	3710.0852
679.5686	2.0063663	0.62691331	3712.8877
680.36938	2.0055289	0.62796944	3706.7576
681.17017	2.0138936	0.62916094	3710.1094
681.97095	2.0136545	0.63023722	3712.8179
682.77173	2.0154786	0.63143772	3709.4292
683.57251	2.0158429	0.63267964	3710.1191
684.37329	2.0193763	0.63378316	3713.5005
685.17407	2.0220177	0.63511568	3715.0435
685.97485	2.0223546	0.63624358	3711.251
686.77563	2.0243449	0.63753289	3714.0073
687.57642	2.0271256	0.63900173	3714.6558
688.3772	2.0312119	0.64028823	3716.2522
689.17798	2.0332034	0.64143836	3709.9312
689.97876	2.036592	0.64268249	3712.7185
690.77954	2.0346985	0.6438005	3708.8621
691.58032	2.0408058	0.64493656	3712.8987
692.3811	2.0440288	0.64608121	3712.2312
693.18188	2.0467982	0.64716631	3716.8313
693.98267	2.0504985	0.64845258	3719.7769
694.78345	2.0516145	0.64984399	3721.9988
695.58423	2.0536828	0.65097833	3715.6113
696.38501	2.0547957	0.65214455	3710.2556
697.18579	2.0569429	0.65341979	3714.5503
697.98657	2.0616565	0.6545977	3717.8882
698.78735	2.0607512	0.65594065	3716.2439
699.58813	2.0666339	0.65728307	3719.6252
700.38892	2.0652544	0.65865332	3719.8923
701.1897	2.0677388	0.66010714	3721.4941
701.99048	2.0707746	0.66117686	3712.2085
702.79126	2.0741894	0.6623807	3717.2803
703.59204	2.0784543	0.66360366	3716.9067
704.39282	2.0756829	0.66486448	3717.2419
705.1936	2.0847588	0.66621715	3726.073
705.99438	2.0808482	0.66738135	3718.4951
706.79517	2.0881038	0.66873133	3721.4219
707.59595	2.088279	0.66980439	3718.5649
708.39673	2.0929635	0.67111361	3722.4233
709.19751	2.0923181	0.67235893	3721.3577
709.99829	2.0943577	0.67352945	3722.3984
710.79907	2.1017096	0.67478782	3719.9353
711.59985	2.1021893	0.67613512	3733.5449
712.40063	2.1064932	0.67730409	3719.8867
713.20142	2.1065853	0.6785363	3724.1479
714.0022	2.1091573	0.67959726	3716.2258
714.80298	2.1103961	0.68075699	3727.0071
715.60376	2.1127849	0.68210596	3721.1694
716.40454	2.1146388	0.68344486	3725.415
717.20532	2.1190012	0.68474674	3725.6255
718.0061	2.1221063	0.685911	3720.1802
718.80688	2.1238897	0.68704849	3722.3916
719.60767	2.1239526	0.68811762	3721.0522
720.40845	2.1292188	0.68947142	3728.3999
721.20923	2.1296768	0.69084167	3728.4871
722.01001	2.1325493	0.69205457	3724.1057
722.81079	2.1352403	0.69330543	3729.4014
723.61157	2.1360373	0.69461626	3725.3618
724.41235	2.1384013	0.69591141	3721.469
725.21313	2.1428056	0.69714481	3722.1326
726.01392	2.1461549	0.69851041	3728.6924
726.8147	2.1482325	0.69979298	3727.7207
727.61548	2.1492333	0.70123446	3728.459
728.41626	2.154273	0.70245236	3726.6704
729.21704	2.1547608	0.70376498	3731.0869
730.01782	2.1603482	0.70532954	3730.9675
730.8186	2.1582091	0.70665145	3726.1667
731.61938	2.1627715	0.70823139	3730.5356
732.42017	2.1618915	0.70948821	3720.6526
733.22095	2.1651247	0.71067363	3723.7148
734.02173	2.1678495	0.71186042	3728.6218
734.82251	2.1708915	0.71330225	3732.6045
735.62329	2.1760974	0.714643	3727.1677
736.42407	2.1730828	0.71574152	3723.5596
737.22485	2.1758351	0.7172417	3729.2085
738.02563	2.1805	0.71857673	3728.5813
738.82642	2.1849031	0.71989542	3730.3394
739.6272	2.1859806	0.72109753	3730.9116
740.42798	2.1875355	0.72227013	3724.894
741.22876	2.1899383	0.72353989	3728.2234
742.02954	2.1908464	0.72480506	3731.2371
742.83032	2.1931596	0.72618175	3728.6387
743.6311	2.1955354	0.72757566	3729.4023
744.43188	2.2011497	0.72904116	3732.688
745.23267	2.2013998	0.73041606	3731.0867
746.03345	2.2050278	0.7316947	3725.7007
746.83423	2.207489	0.73306996	3736.783
747.63501	2.208421	0.73418111	3723.7417
748.43579	2.2120502	0.73543471	3733.1636
749.23657	2.2155316	0.73675621	3735.7197
750.03735	2.2156672	0.73839164	3728.2227
750.83813	2.2205384	0.73976874	3730.6096
751.63892	2.2208431	0.74081248	3727.9292
752.4397	2.2277339	0.74239743	3738.5142
753.24048	2.2265623	0.74393052	3738.854
754.04126	2.2252622	0.74541813	3730.7039
754.84204	2.2284453	0.74704862	3729.7188
755.64282	2.2343287	0.7482841	3728.9282
756.4436	2.2364323	0.7498526	3737.0962
757.24438	2.2372119	0.75115949	3736.6289
758.04517	2.2407374	0.75270057	3734.0291
758.84595	2.241533	0.7539196	3728.2651
759.64673	2.2451038	0.75495005	3727.4565
760.44751	2.24807	0.75615776	3726.5781
761.24829	2.2465463	0.75757247	3739.3755
762.04907	2.2543993	0.75915617	3738.9753
762.84985	2.2545574	0.76073718	3734.8381
763.65063	2.2572381	0.76210988	3735.6707
764.45142	2.2592847	0.76371258	3735.094
765.2522	2.2621741	0.76512074	3735.2534
766.05298	2.2641788	0.7666204	3734.8491
766.85376	2.2663956	0.768053	3740.1768
767.65454	2.2677395	0.76978725	3735.6401
768.45532	2.271878	0.77135658	3736.2634
769.2561	2.2748549	0.77269006	3727.9216
770.05688	2.2764938	0.77389753	3728.4495
770.85767	2.2776797	0.77514076	3732.4512
771.65845	2.2813983	0.77652305	3731.9829
772.45923	2.285001	0.77773964	3737.6724
773.26001	2.285615	0.77919644	3730.907
774.06079	2.2861905	0.78065509	3736.3362
774.86157	2.2891641	0.78235936	3734.5647
775.66235	2.2935226	0.78391862	3736.8721
776.46313	2.2971323	0.78561336	3739.3406
777.26392	2.2987521	0.78714383	3736.3931
778.0647	2.299789	0.78853089	3736.6531
778.86548	2.3011558	0.78991455	3733.4968
779.66626	2.3036397	0.79141223	3731.7815
780.46704	2.3085134	0.79314959	3740.2864
781.26782	2.3079655	0.79464877	3729.8257
782.0686	2.3121312	0.79597223	3733.1128
782.86938	2.3128221	0.79735982	3738.7456
783.67017	2.3173862	0.79898936	3735.261
784.47095	2.3185699	0.80045432	3730.6282
785.27173	2.3233168	0.80184138	3733.9292
786.07251	2.3230751	0.80299109	3732.8228
786.87329	2.3278735	0.80424213	3734.2278
787.67407	2.3288317	0.80557239	3733.7061
788.47485	2.3294325	0.80706292	3734.7322
789.27563	2.3319805	0.80864626	3737.2078
790.07642	2.3401418	0.81028116	3742.5857
790.8772	2.3415103	0.81204212	3741.4377
791.67798	2.3399343	0.81360584	3732.5007
792.47876	2.3426609	0.81500953	3729.1162
793.27954	2.348455	0.81615865	3727.6772
794.08032	2.3484015	0.81740558	3732.8594
794.8811	2.3501296	0.81910485	3738.0999
795.68188	2.3519514	0.82082283	3733.9731
796.48267	2.358094	0.82224333	3738.9927
797.28345	2.3573301	0.82393193	3733.3989
798.08423	2.3629093	0.82564598	3741.7683
798.88501	2.3627236	0.82728952	3733.7793
799.68579	2.3645165	0.82919538	3737.4148
800.48657	2.3682404	0.83093345	3738.748
801.28735	2.3706276	0.83244199	3730.6072
802.08813	2.3739057	0.8336069	3725.9153
802.88892	2.3766229	0.83503479	3736.0662
803.6897	2.3758471	0.83650106	3736.5459
804.49048	2.3791149	0.83842987	3742.2078
805.29126	2.3854239	0.84041321	3742.0171
806.09204	2.3821828	0.84200919	3730.6799
806.89282	2.3862991	0.84364486	3735.7117
807.6936	2.3914344	0.84522009	3736.8889
808.49438	2.3927839	0.84668428	3735.3259
809.29517	2.3942397	0.84816456	3730.8367
810.09595	2.3949816	0.84983599	3733.0229
810.89673	2.3989038	0.85153586	3730.3367
811.69751	2.4005013	0.8531065	3732.3594
812.49829	2.4023163	0.85456032	3729.0679
813.29907	2.4044976	0.85598242	3730.6633
814.09985	2.4089756	0.85751688	3734.1533
814.90063	2.4109044	0.85888875	3729.0232
815.70142	2.4130375	0.86026132	3730.8108
816.5022	2.4123964	0.86170667	3731.5674
817.30298	2.4198849	0.86348438	3739.4561
818.10376	2.4191058	0.86499953	3733.1445
818.90454	2.4260657	0.8667165	3738.9912
819.70532	2.4239466	0.86845511	3732.5942
820.5061	2.4278455	0.86998713	3731.4575
821.30688	2.4300985	0.87176967	3736.0591
822.10767	2.4314508	0.87351578	3736.4299
822.90845	2.4358101	0.87544423	3734.7478
823.70923	2.4377899	0.87740254	3739.4475
824.51001	2.4402826	0.87891954	3733.4766
825.31079	2.4411199	0.88045353	3731.0112
826.11157	2.4454222	0.88207716	3728.895
826.91235	2.4431005	0.88372129	3730.0513
827.71313	2.4500251	0.8854357	3730.7847
828.51392	2.4500859	0.88725448	3730.917
829.3147	2.455801	0.88908476	3733.8928
830.11548	2.4590759	0.89081317	3729.9492
830.91626	2.4613221	0.89248842	3733.7561
831.71704	2.4618814	0.89413899	3728.2407
832.51782	2.4653115	0.89606357	3732.02
833.3186	2.4667659	0.89773434	3725.3706
834.11938	2.4685667	0.89935112	3728.2214
834.92017	2.4688051	0.90119457	3724.2815
835.72095	2.4718237	0.90298814	3731.3459
836.52173	2.4776764	0.90468419	3728.9307
837.32251	2.4785647	0.90665805	3733.0432
838.12329	2.4809263	0.90845305	3729.3936
838.92407	2.481622	0.91043425	3732.1978
839.72485	2.4830525	0.91254377	3734.1233
840.52563	2.4877946	0.9145745	3730.2656
841.32642	2.4900689	0.91646367	3726.4255
842.1272	2.4906964	0.91820419	3719.3901
842.92798	2.4953239	0.91979146	3727.9104
843.72876	2.4984159	0.92127848	3717.979
844.52954	2.4967301	0.92272592	3721.8164
845.33032	2.5029356	0.92446166	3724.0691
846.1311	2.5022938	0.92631	3723.9512
846.93188	2.5058978	0.92824066	3726.4075
847.73267	2.5090981	0.93001324	3726.2017
848.53345	2.5109439	0.93173629	3716.2314
849.33423	2.5132267	0.93329906	3718.7832
850.13501	2.5186627	0.93502569	3725.197
850.93579	2.516196	0.93692464	3719.7476
851.73657	2.521425	0.9387719	3723.2715
852.53735	2.5256975	0.94058132	3725.5732
853.33813	2.5271807	0.94280767	3728.939
854.13892	2.529108	0.94471556	3720.9368
854.9397	2.5287166	0.94637269	3713.7092
855.74048	2.5310128	0.94788319	3714.8501
856.54126	2.5360548	0.9496581	3721.136
857.34204	2.5392394	0.95114917	3719.9363
858.14282	2.5418463	0.95324874	3720.3342
858.9436	2.5433846	0.95511383	3718.7351
859.74438	2.5456314	0.95683855	3722.012
860.54517	2.5489368	0.95876491	3717.3364
861.34595	2.5540073	0.96049017	3716.918
862.14673	2.5509789	0.96243322	3717.6267
862.94751	2.5544298	0.9641344	3711.3054
863.74829	2.5571501	0.96591437	3708.8472
864.54907	2.5588794	0.96784067	3718.2527
865.34985	2.5602558	0.97015202	3717.0928
866.15063	2.5631685	0.97235197	3715.6594
866.95142	2.5650077	0.97435915	3710.5073
867.7522	2.5729749	0.9758836	3708.6763
868.55298	2.5716772	0.97782737	3711.4033
869.35376	2.5747194	0.97992074	3717.438
870.15454	2.5766556	0.98204041	3714.074
870.95532	2.5802925	0.98399723	3710.2686
871.7561	2.5795724	0.98587275	3708.6868
872.55688	2.5827708	0.98784429	3711.085
873.35767	2.5854943	0.98987049	3709.0149
874.15845	2.5874689	0.9919222	3705.8618
874.95923	2.5897439	0.99408472	3712.4048
875.76001	2.5915215	0.99615961	3705.0127
876.56079	2.5951993	0.99838758	3701.8157
877.36157	2.597847	1.0002273	3702.3762
878.16235	2.6013286	1.0022836	3701.1106
878.96313	2.6025577	1.0045551	3705.1814
879.76392	2.6049562	1.0070314	3708.6287
880.5647	2.6073186	1.0092678	3704.5508
881.36548	2.6066158	1.0112618	3697.0786
882.16626	2.6117446	1.0133593	3705.2229
882.96704	2.6160326	1.0153518	3696.6912
883.76782	2.618753	1.0170277	3695.4548
884.5686	2.6215973	1.0192027	3707.2593
885.36938	2.6217191	1.0212386	3693.6907
886.17017	2.6256683	1.0233583	3697.8926
886.97095	2.6282084	1.0252782	3698.0769
887.77173	2.6300738	1.0275962	3702.2788
888.57251	2.6332746	1.030089	3698.9619
889.37329	2.6336279	1.0323505	3693.9744
890.17407	2.6380866	1.0345882	3695.6794
890.97485	2.6404572	1.0371772	3697.1086
891.77563	2.6369383	1.0396425	3687.2607
892.57642	2.644191	1.041411	3680.0171
893.3772	2.6467466	1.0431725	3687.5212
894.17798	2.6487286	1.0450816	3689.897
894.97876	2.6513772	1.0470473	3683.5903
895.77954	2.6517844	1.0489658	3686.9495
896.58032	2.6544757	1.050867	3684.4072
897.3811	2.6574161	1.0526134	3679.9299
898.18188	2.6601114	1.0546311	3685.1521
898.98267	2.6655631	1.057212	3684.9341
899.78345	2.6669083	1.0595036	3688.2864
900.58423	2.6671588	1.0615327	3675.3594
901.38501	2.6703351	1.0638509	3680.6235
902.18579	2.670527	1.0662262	3679.5603
902.98657	2.6767659	1.0684294	3682.1941
903.78735	2.6804101	1.0707127	3677.9011
904.58813	2.6790962	1.0732681	3677.4473
905.38892	2.6845272	1.0752847	3670.041
906.1897	2.6845322	1.077957	3673.7212
906.99048	2.6859982	1.0804497	3669.0002
907.79126	2.6897068	1.0827893	3664.5967
908.59204	2.6917856	1.0851113	3668.2251
909.39282	2.6922984	1.0874702	3666.2698
910.1936	2.6960006	1.0897582	3661.3101
910.99438	2.6990459	1.0921258	3662.3494
911.79517	2.699106	1.0949513	3665.1404
912.59595	2.703176	1.0973972	3656.7681
913.39673	2.7072387	1.0998471	3659.3535
914.19751	2.7105095	1.1020995	3656.8174
914.99829	2.7136559	1.1043719	3656.7217
915.79907	2.7153881	1.1066765	3648.1907
916.59985	2.7157845	1.1086366	3651.3694
917.40063	2.7205553	1.1105894	3648.4482
918.20142	2.7181656	1.1127371	3646.3225
919.0022	2.7242413	1.1150045	3646.075
919.80298	2.7255666	1.1172482	3646.8293
920.60376	2.7292604	1.1195529	3644.6086
921.40454	2.7334354	1.1216538	3644.9348
922.20532	2.73104	1.1239128	3639.5112
923.0061	2.7389905	1.1265581	3639.7146
923.80688	2.7353094	1.1293075	3636.8101
924.60767	2.740005	1.1321307	3636.9844
925.40845	2.7428594	1.1351043	3635.3806
926.20923	2.7465663	1.1378039	3631.0984
927.01001	2.7497764	1.1401912	3626.0066
927.81079	2.7479982	1.142616	3624.9456
928.61157	2.7506888	1.1452562	3627.0498
929.41235	2.7527812	1.1474798	3620.5398
930.21313	2.7546251	1.1495844	3615.583
931.01392	2.7575092	1.151503	3615.4766
931.8147	2.7608738	1.1539733	3613.3918
932.61548	2.7623422	1.1561161	3613.082
933.41626	2.7669773	1.1583301	3617.9771
934.21704	2.768785	1.1607252	3611.6484
935.01782	2.7718589	1.1631474	3608.4951
935.8186	2.7732236	1.1657037	3609.5269
936.61938	2.7809691	1.1685444	3605.6592
937.42017	2.7792039	1.1713092	3605.2251
938.22095	2.7834055	1.1740645	3597.7678
939.02173	2.783107	1.1766543	3593.3464
939.82251	2.7856719	1.1791921	3593.5896
940.62329	2.7882779	1.1813056	3581.5828
941.42407	2.7904496	1.1835599	3590.6589
942.22485	2.7945693	1.1860985	3582.8032
943.02563	2.7947555	1.1884139	3582.2471
943.82642	2.7947032	1.1913855	3571.5513
944.6272	2.8014076	1.1939926	3572.4824
945.42798	2.8034394	1.197069	3565.9067
946.22876	2.8049948	1.1999729	3561.8445
947.02954	2.8074331	1.202861	3559.3638
947.83032	2.8087928	1.2054784	3552.7429
948.6311	2.8141601	1.2079139	3546.4333
949.43188	2.8150699	1.2102072	3552.9858
950.23267	2.8164082	1.2127384	3541.9307
951.03345	2.8196065	1.2151203	3542.947
951.83423	2.8219264	1.2173564	3540.553
952.63501	2.82587	1.2198954	3534.1174
953.43579	2.8272805	1.2223431	3530.2551
954.23657	2.829767	1.2251066	3531.6912
955.03735	2.8289089	1.2283362	3519.4363
955.83813	2.8359468	1.2312834	3518.5789
956.63892	2.8377466	1.2339739	3510.9055
957.4397	2.841295	1.2364395	3506.9175
958.24048	2.843442	1.2389498	3504.2493
959.04126	2.8438387	1.2416238	3499.6235
959.84204	2.8497384	1.2444304	3500.0652
960.64282	2.8503745	1.2468425	3486.9426
961.4436	2.8524349	1.249705	3486.0752
962.24438	2.8527749	1.2527424	3474.0625
963.04517	2.8572831	1.2555186	3466.98
963.84595	2.8600457	1.2586737	3462.9724
964.64673	2.8614721	1.2612867	3453.5977
965.44751	2.862395	1.2640808	3446.6621
966.24829	2.8654189	1.266975	3438.2102
967.04907	2.8666713	1.2700815	3438.5032
967.84985	2.8721883	1.2733234	3430.5576
968.65063	2.8739607	1.276646	3417.4277
969.45142	2.8758972	1.2796828	3408.8472
970.2522	2.8795557	1.2830111	3391.5176
971.05298	2.8825879	1.2866188	3381.1384
971.85376	2.8816957	1.2914716	3353.5078
972.55444	2.8871136	1.2990634	3311.3752