File: datasets/am_bench_2022/raw_data/90-XY.17-2/specimen.dat
MTS793|MPT|ENU|1|2|.|/|:|1|0|0|A

Operator Information						Time:	12.221924	Sec	11/3/2021 9:46:25 AM
Operator	Nick Derimow
Project	AM Bench 2022 mini-tensile challenge
Specimen ID	90-XY.17-2
Material	PBF-L Inconel 625
Specimen Width	2.54	mm
Specimen Thickness	1.49	mm
Notes
Operator Information End

Data Acquisition						Time:	1003.6348	Sec	11/3/2021 10:02:56 AM
Time	Axial Displacement	Axial Extensometer	Axial Force
Sec	mm	mm	N
12.334961	0.0013804043	0.00018351866	36.383652
13.23584	0.0029686678	0.00015481343	46.42762
14.136719	0.0050284369	0.00021060114	59.331474
15.037598	0.0078905588	0.00023612133	68.316025
15.938477	0.014722341	0.00027981229	82.663857
16.839355	0.013224588	0.00038442449	90.766411
17.740234	0.015577146	0.00040547497	104.70055
18.641113	0.020664742	0.000562403	116.70701
19.541992	0.022006778	0.00057042245	124.88074
20.442871	0.023919178	0.0006610119	138.87823
21.34375	0.030781284	0.00068870909	146.12256
22.244629	0.028044403	0.00070480019	157.05344
23.145508	0.031995673	0.00072293717	163.07391
24.046387	0.0370888	0.00078963221	178.37808
24.947266	0.036983691	0.00097201183	200.32681
25.848145	0.040624145	0.0010499308	212.8654
26.749023	0.04272018	0.0010991292	234.41266
27.649902	0.044083267	0.0011762492	249.47885
28.550781	0.048947379	0.0012674083	270.38635
29.45166	0.051045205	0.0013424506	286.94443
30.352539	0.050949112	0.0014033073	300.76593
31.253418	0.057209045	0.001585694	323.97653
32.154297	0.056770578	0.0014894507	344.71045
33.055176	0.061496183	0.0016718589	365.65552
33.956055	0.064921089	0.0017010877	385.98651
34.856934	0.06869144	0.0018821149	409.55957
35.757813	0.06776759	0.001962088	419.32941
36.658691	0.073854849	0.0020585896	440.92542
37.55957	0.075755619	0.0021905014	466.20667
38.460449	0.078037232	0.0022307748	486.00415
39.361328	0.08143878	0.0023803136	511.58725
40.262207	0.082142994	0.0024078835	531.16156
41.163086	0.085382476	0.0024551684	558.99713
42.063965	0.090988033	0.0026030608	576.65662
42.964844	0.09129148	0.0026724767	605.14679
43.865723	0.094404742	0.0029363076	632.66211
44.766602	0.097669221	0.0030017416	647.21649
45.66748	0.098173864	0.0030182067	664.91003
46.568359	0.10284846	0.0032119157	687.31671
47.469238	0.10396465	0.0032758417	710.35571
48.370117	0.10667945	0.0034302741	727.34027
49.270996	0.11109721	0.003576508	756.95074
50.171875	0.11290579	0.003500809	779.12866
51.072754	0.11672966	0.0037202851	800.0451
51.973633	0.11896887	0.0038911467	827.84656
52.874512	0.12364484	0.0039178841	850.96631
53.775391	0.12350982	0.0039302921	870.29755
54.67627	0.12826078	0.004083226	893.77405
55.577148	0.13029842	0.0042803525	921.78735
56.478027	0.13124311	0.0042686081	938.67084
57.378906	0.13521385	0.0043750447	959.11554
58.279785	0.14033648	0.0044800579	990.50909
59.180664	0.13847259	0.0046271235	1013.7825
60.081543	0.13867113	0.0047503384	1047.1211
60.982422	0.1444613	0.0049951351	1070.8016
61.883301	0.14599019	0.0050500459	1091.119
62.78418	0.15116072	0.005240195	1126.4452
63.685059	0.15287812	0.0052721282	1142.0481
64.585938	0.1556216	0.0052676452	1169.9019
65.486816	0.16133018	0.0055437493	1198.559
66.387695	0.16080524	0.0056173899	1231.0084
67.288574	0.16235606	0.0057992656	1250.3658
68.189453	0.16824581	0.0059129177	1279.3347
69.090332	0.16758156	0.0059834942	1303.0793
69.991211	0.17274271	0.0061483467	1328.5544
70.89209	0.17471248	0.0062841228	1352.4828
71.792969	0.1756267	0.0063981842	1379.2587
72.693848	0.18028545	0.0065264613	1410.1669
73.594727	0.1818119	0.0066608354	1423.1615
74.495605	0.18570989	0.006671472	1459.171
75.396484	0.18440761	0.0068856794	1481.0879
76.297363	0.19383658	0.006982178	1511.2206
77.198242	0.1946291	0.0070269713	1530.4268
78.099121	0.19580723	0.0072097513	1550.7347
79	0.19846256	0.0072980882	1578.2234
79.900879	0.20158218	0.0074372645	1603.7314
80.801758	0.20758933	0.0076445299	1629.993
81.702637	0.20645341	0.0078706127	1657.8331
82.603516	0.21072641	0.0078976778	1676.146
83.504395	0.21491531	0.0078438092	1695.0081
84.405273	0.21445553	0.0079729334	1720.3844
85.306152	0.21797326	0.0081178471	1746.9271
86.207031	0.22058582	0.0082760621	1756.9048
87.10791	0.22175001	0.0083205886	1780.8196
88.008789	0.22498663	0.008510856	1812.3829
88.909668	0.22859204	0.0086365435	1840.9849
89.810547	0.23140575	0.0087212529	1854.4241
90.711426	0.23308688	0.0089532435	1874.5492
91.612305	0.23577711	0.0089542801	1903.663
92.513184	0.23823513	0.0090438332	1916.3243
93.414063	0.2442853	0.0092296135	1946.5449
94.314941	0.24587643	0.0093591763	1963.64
95.21582	0.24831608	0.0094796894	1988.2496
96.116699	0.25020456	0.0095290672	2010.7515
97.017578	0.25133651	0.0096109202	2026.3512
97.918457	0.25996909	0.0098113753	2051.2898
98.819336	0.25990742	0.0099106794	2074.0872
99.720215	0.25994307	0.0099080279	2090.7864
100.62109	0.26381695	0.010147667	2119.8838
101.52197	0.26565519	0.010276587	2136.7437
102.42285	0.26758546	0.010321371	2152.502
103.32373	0.27126116	0.010389447	2165.7559
104.22461	0.27504256	0.010534161	2186.2437
105.12549	0.27781802	0.010440382	2195.3359
106.02637	0.28060633	0.010585861	2214.6016
106.92725	0.28372595	0.010804847	2238.9785
107.82813	0.28731701	0.010871514	2254.9048
108.729	0.2877264	0.010919362	2264.6548
109.62988	0.29332745	0.011005268	2284.4753
110.53076	0.29719204	0.011100427	2298.3584
111.43164	0.29757354	0.011162197	2307.8325
112.33252	0.30008015	0.011363149	2322.7822
113.2334	0.30254868	0.011352937	2329.5186
114.13428	0.30380607	0.01147516	2351.6423
115.03516	0.3087959	0.011632262	2365.4211
115.93604	0.3114019	0.011736372	2382.7612
116.83691	0.3144623	0.011635101	2386.9985
117.73779	0.3173396	0.011821507	2402.3496
118.63867	0.31890941	0.011835814	2413.3535
119.53955	0.31910715	0.011920892	2418.7349
120.44043	0.32288915	0.012112061	2432.5161
121.34131	0.32443795	0.012153559	2444.2239
122.24219	0.32815871	0.012276869	2458.3135
123.14307	0.33187845	0.012346506	2471.1377
124.04395	0.33574736	0.012381587	2477.2109
124.94482	0.33879259	0.012513523	2488.2307
125.8457	0.34130332	0.012703878	2506.666
126.74658	0.34420007	0.012772704	2509.7209
127.64746	0.34587356	0.012847926	2521.0149
128.54834	0.34842038	0.012927501	2533.5752
129.44922	0.35024282	0.012855576	2539.6333
130.3501	0.35438547	0.013189013	2558.322
131.25098	0.35878423	0.01330775	2565.687
132.15186	0.35892537	0.01326317	2569.3877
133.05273	0.36185613	0.0134182	2584.042
133.95361	0.36466372	0.013594692	2595.1895
134.85449	0.36815214	0.013710827	2605.2388
135.75537	0.36856478	0.013738266	2606.2212
136.65625	0.37269861	0.013955464	2619.1707
137.55713	0.37686709	0.014017952	2629.9368
138.45801	0.37871826	0.014122472	2635.1384
139.35889	0.37964964	0.014255163	2643.395
140.25977	0.38025981	0.014410177	2651.3896
141.16064	0.38607436	0.014485715	2654.3242
142.06152	0.39158955	0.014656712	2671.2368
142.9624	0.39282152	0.014879606	2678.741
143.86328	0.39584491	0.014912093	2689.1011
144.76416	0.39694926	0.015197363	2697.0764
145.66504	0.40004879	0.015203215	2693.616
146.56592	0.40193871	0.015361517	2709.4795
147.4668	0.40396586	0.015642952	2723.6523
148.36768	0.40763497	0.01576581	2721.4287
149.26855	0.40937391	0.015819762	2725.9441
150.16943	0.41359746	0.016074782	2745.7449
151.07031	0.41847321	0.016352614	2752.2539
151.97119	0.4194636	0.016583169	2756.8914
152.87207	0.42188644	0.016788028	2764.2256
153.77295	0.42687854	0.016975518	2769.0098
154.67383	0.42815769	0.017248677	2776.4141
155.57471	0.42888772	0.01739281	2782.9292
156.47559	0.43387485	0.01760594	2790.1753
157.37646	0.43484092	0.017941654	2796.7754
158.27734	0.43741947	0.018190643	2813.3552
159.17822	0.44043788	0.018328575	2804.2656
160.0791	0.44584981	0.0186646	2817.5173
160.97998	0.4453294	0.018987844	2824.3706
161.88086	0.44850495	0.019167449	2826.8113
162.78174	0.45064297	0.019476742	2832.592
163.68262	0.4540095	0.019965867	2848.6052
164.5835	0.45747107	0.020253761	2849.3674
165.48438	0.45820335	0.02053277	2855.2341
166.38525	0.46217594	0.020984057	2863.637
167.28613	0.46579614	0.021341715	2869.031
168.18701	0.46935302	0.021773776	2882.8845
169.08789	0.46956483	0.02213099	2875.99
169.98877	0.47233105	0.022642886	2883.5178
170.88965	0.4747436	0.023138482	2887.7207
171.79053	0.47938457	0.023657743	2896.8513
172.69141	0.4814826	0.024014438	2899.9238
173.59229	0.4875356	0.024567289	2908.5679
174.49316	0.48461738	0.025140464	2911.0591
175.39404	0.49223068	0.025687948	2919.0872
176.29492	0.49082923	0.026160548	2915.0227
177.1958	0.49574471	0.026637586	2922.5874
178.09668	0.4959662	0.027170809	2934.4827
178.99756	0.50327843	0.0277924	2934.2886
179.89844	0.50321925	0.028338794	2931.9609
180.79932	0.50565743	0.028900461	2943.0557
181.7002	0.50883281	0.029601477	2951.2966
182.60107	0.51100582	0.030200804	2955.3066
183.50195	0.51533878	0.030903302	2960.1287
184.40283	0.51885617	0.031642981	2962.062
185.30371	0.51996416	0.032290414	2961.3765
186.20459	0.5217334	0.03291814	2962.2546
187.10547	0.5262934	0.033492099	2970.4548
188.00635	0.52795339	0.034202054	2974.9893
188.90723	0.52964288	0.034891408	2984.2422
189.80811	0.53335565	0.035686087	2985.7393
190.70898	0.53408039	0.036444653	2986.7512
191.60986	0.53752005	0.037322257	2990.636
192.51074	0.53991008	0.038091	2994.0745
193.41162	0.54344541	0.038916733	2993.1482
194.3125	0.54677629	0.039741714	3008.2998
195.21338	0.55295414	0.040629901	3009.5264
196.11426	0.55198765	0.041396555	3004.645
197.01514	0.55438197	0.042223763	3009.3796
197.91602	0.55701786	0.043058436	3011.8936
198.81689	0.56087118	0.043887138	3023.1194
199.71777	0.56335139	0.044741459	3025.6423
200.61865	0.56548506	0.045449276	3025.9822
201.51953	0.56749296	0.046362381	3035.5186
202.42041	0.57105172	0.047119305	3023.6436
203.32129	0.5752722	0.047935057	3035.8987
204.22217	0.57714754	0.048807185	3036.3164
205.12305	0.5794878	0.049483102	3031.1187
206.02393	0.58019489	0.050352931	3040.8762
206.9248	0.58361691	0.051314268	3049.0771
207.82568	0.58776712	0.051996332	3051.3147
208.72656	0.59169626	0.053009219	3060.4329
209.62744	0.59217143	0.054118723	3058.093
210.52832	0.59422028	0.055053268	3060.0623
211.4292	0.59835315	0.055890162	3060.4812
212.33008	0.59963244	0.056881018	3073.7654
213.23096	0.60441369	0.057764929	3069.6895
214.13184	0.60685825	0.058850523	3068.1487
215.03271	0.60928696	0.059718192	3067.0405
215.93359	0.61261874	0.060550496	3076.1951
216.83447	0.61288673	0.061490852	3082.7712
217.73535	0.61819965	0.062391438	3082.4741
218.63623	0.61947489	0.063372269	3085.2312
219.53711	0.6223861	0.064517237	3087.7153
220.43799	0.6262483	0.065269448	3090.8088
221.33887	0.62830025	0.066219531	3090.2654
222.23975	0.63174707	0.067012265	3085.2061
223.14063	0.63433093	0.067692578	3094.3059
224.0415	0.63497794	0.06861528	3095.1743
224.94238	0.63820726	0.069614813	3099.0444
225.84326	0.64157701	0.070679195	3106.1221
226.74414	0.64589751	0.071393661	3102.8472
227.64502	0.64825332	0.072170749	3108.8013
228.5459	0.65048045	0.072822899	3110.0203
229.44678	0.64797342	0.073701784	3111.5664
230.34766	0.654827	0.074629337	3107.9412
231.24854	0.65693754	0.075660571	3118.4824
232.14941	0.65976357	0.076493584	3112.3113
233.05029	0.66166204	0.077412337	3119.9617
233.95117	0.66685891	0.078369647	3130.2439
234.85205	0.6673404	0.079539269	3128.4038
235.75293	0.67101091	0.080736227	3133.2791
236.65381	0.67490482	0.081806891	3131.5071
237.55469	0.6771301	0.082864508	3138.4519
238.45557	0.67833364	0.083734564	3135.0818
239.35645	0.68267977	0.084656969	3136.6023
240.25732	0.68514884	0.085578874	3139.1248
241.1582	0.6883297	0.086454906	3145.2109
242.05908	0.68845695	0.087268576	3137.3435
242.95996	0.69273859	0.088318408	3147.834
243.86084	0.69575059	0.089284539	3144.5544
244.76172	0.69878912	0.090411544	3156.4202
245.6626	0.69898868	0.091331735	3146.521
246.56348	0.70584178	0.092477933	3159.7979
247.46436	0.70425946	0.093487091	3154.6936
248.36523	0.70754445	0.094467901	3159.2844
249.26611	0.71077615	0.095543921	3158.4248
250.16699	0.7108888	0.096337996	3160.6746
251.06787	0.71386874	0.097316332	3157.3967
251.96875	0.72245866	0.098308146	3162.8701
252.86963	0.72244984	0.099173017	3164.9861
253.77051	0.72296923	0.1001128	3175.1917
254.67139	0.72680128	0.10113658	3169.4785
255.57227	0.73015732	0.10233591	3183.6702
256.47314	0.73191983	0.10342265	3182.3289
257.37402	0.73614275	0.10446891	3179.4688
258.2749	0.73927242	0.10559967	3181.2175
259.17578	0.74019074	0.10636628	3173.7595
260.07666	0.74495095	0.10709594	3184.4956
260.97754	0.74757683	0.10801645	3186.3826
261.87842	0.74977481	0.10890521	3180.9143
262.7793	0.75377935	0.10980003	3190.6575
263.68018	0.75404471	0.11069074	3187.3633
264.58105	0.75608188	0.11165112	3189.9524
265.48193	0.76106071	0.11255766	3196.811
266.38281	0.76255888	0.11374701	3202.2197
267.28369	0.76225191	0.11470721	3198.2161
268.18457	0.76785809	0.11569539	3198.0498
269.08545	0.76913697	0.11649577	3196.8943
269.98633	0.7753154	0.11754263	3205.5073
270.88721	0.77563691	0.11858349	3208.9045
271.78809	0.77883786	0.11938075	3210.1931
272.68896	0.77862024	0.1203616	3207.7666
273.58984	0.78593665	0.12141757	3216.0396
274.49072	0.78517324	0.12240426	3212.8906
275.3916	0.79046959	0.12349323	3220.2273
276.29248	0.794626	0.12450098	3219.6802
277.19336	0.7961421	0.12549138	3221.8652
278.09424	0.7972008	0.12651622	3225.0315
278.99512	0.80181515	0.12758622	3228.1519
279.896	0.80132544	0.12850647	3226.7478
280.79688	0.8054924	0.12965235	3232.605
281.69775	0.80902386	0.13096274	3239.0562
282.59863	0.81150061	0.13193755	3233.7161
283.49951	0.81787509	0.13287106	3234.6177
284.40039	0.81646174	0.13381205	3230.657
285.30127	0.81868845	0.13472569	3230.9629
286.20215	0.82251024	0.13572428	3239.8096
287.10303	0.82649392	0.13670903	3245.5237
288.00391	0.82874399	0.13766997	3244.1772
288.90479	0.83217466	0.13891977	3249.6943
289.80566	0.83265924	0.13985834	3246.6538
290.70654	0.83611548	0.14078277	3246.345
291.60742	0.83970165	0.14199735	3248.686
292.5083	0.83905405	0.14299497	3256.7053
293.40918	0.84326589	0.14394505	3248.4844
294.31006	0.84658366	0.14478578	3248.7622
295.21094	0.8506552	0.14568573	3255.5186
296.11182	0.85194272	0.14666907	3253.4248
297.0127	0.85572231	0.14740784	3257.3921
297.91357	0.85762554	0.14843342	3265.4065
298.81445	0.86115801	0.14925945	3262.0715
299.71533	0.86116844	0.15013529	3258.675
300.61621	0.86309052	0.15099822	3264.72
301.51709	0.86829126	0.15196188	3263.5977
302.41797	0.87038499	0.15297823	3270.3362
303.31885	0.87505603	0.15397072	3269.7788
304.21973	0.87535453	0.15509665	3273.6035
305.12061	0.87890732	0.15605506	3274.6758
306.02148	0.8811273	0.15707178	3279.8342
306.92236	0.8842473	0.15824057	3279.6436
307.82324	0.88535619	0.15921487	3278.2651
308.72412	0.88955534	0.16030724	3275.2544
309.625	0.89433855	0.16114764	3281.0901
310.52588	0.89744049	0.16204849	3285.6372
311.42676	0.89745075	0.16303276	3282.5823
312.32764	0.90203637	0.16416262	3291.6987
313.22852	0.90330911	0.16509336	3285.7097
314.12939	0.90635502	0.16617738	3294.7805
315.03027	0.90936053	0.16726115	3291.7705
315.93115	0.91084701	0.1681328	3292.7229
316.83203	0.91436124	0.1692896	3298.3057
317.73291	0.91484272	0.17014194	3291.6333
318.63379	0.91763598	0.17120111	3296.5237
319.53467	0.92193437	0.17234537	3306.1843
320.43555	0.92624843	0.17350134	3309.5044
321.33643	0.92598605	0.17451389	3308.8518
322.2373	0.93221873	0.17556134	3307.4783
323.13818	0.93335301	0.17660737	3308.0107
324.03906	0.93735957	0.17755948	3308.6899
324.93994	0.9362089	0.17849569	3300.4375
325.84082	0.94210583	0.17938145	3313.2969
326.7417	0.942523	0.1804743	3309.8049
327.64258	0.94969958	0.18133686	3313.7761
328.54346	0.9502936	0.18219638	3320.7998
329.44434	0.95080316	0.18337363	3321.3145
330.34521	0.95563281	0.18430233	3315.7354
331.24609	0.95329827	0.18518387	3311.1301
332.14697	0.95827377	0.18619399	3316.7227
333.04785	0.96691698	0.18748552	3332.4363
333.94873	0.9651677	0.18830784	3316.272
334.84961	0.96994275	0.18917552	3325.2991
335.75049	0.96816558	0.19028528	3324.0146
336.65137	0.97370911	0.19141139	3335.4558
337.55225	0.97595799	0.19251084	3333.7397
338.45313	0.9783994	0.19358592	3335.0669
339.354	0.98311943	0.19452296	3324.0273
340.25488	0.98463249	0.19541298	3333.9324
341.15576	0.9876774	0.19637768	3327.4084
342.05664	0.9893052	0.19728363	3337.4812
342.95752	0.99256784	0.19836806	3345.8779
343.8584	0.99533242	0.19946972	3347.042
344.75928	0.99687725	0.20065543	3346.1423
345.66016	1.0016032	0.20154589	3350.1641
346.56104	1.0043598	0.20254351	3351.3728
347.46191	1.0071405	0.20336798	3342.876
348.36279	1.0089171	0.20431437	3344.2415
349.26367	1.0121979	0.20532152	3350.4109
350.16455	1.0144448	0.2063677	3350.6741
351.06543	1.0171978	0.207394	3351.7397
351.96631	1.018862	0.20845588	3354.1699
352.86719	1.0209531	0.20956507	3351.0022
353.76807	1.022861	0.21038936	3347.7717
354.66895	1.0235927	0.21141908	3355.5425
355.56982	1.0265663	0.21262413	3358.3286
356.4707	1.0358723	0.21359327	3358.0144
357.37158	1.0349938	0.21472085	3364.9609
358.27246	1.0389724	0.21561104	3359.6631
359.17334	1.0403956	0.21673624	3365.9021
360.07422	1.0434977	0.21772042	3364.4985
360.9751	1.0440274	0.21871294	3369.6304
361.87598	1.0483642	0.21964595	3366.0068
362.77686	1.0502225	0.22068009	3372.0903
363.67773	1.0568045	0.22176751	3380.6997
364.57861	1.0570015	0.22274564	3376.1836
365.47949	1.0601507	0.22374035	3379.127
366.38037	1.0628645	0.22485919	3383.7236
367.28125	1.0658954	0.22599778	3383.7195
368.18213	1.0668738	0.22715826	3380.5015
369.08301	1.0720404	0.22813009	3385.6533
369.98389	1.0727811	0.22895229	3378.6609
370.88477	1.076355	0.22982544	3380.5566
371.78564	1.0829791	0.23082535	3383.8401
372.68652	1.0824505	0.23144843	3380.0786
373.5874	1.0854449	0.23251387	3386.345
374.48828	1.0875728	0.23369756	3393.7327
375.38916	1.0908608	0.23464799	3387.7981
376.29004	1.0919367	0.23554988	3392.2837
377.19092	1.0950433	0.23659192	3397.2954
378.0918	1.0986372	0.23753424	3388.1797
378.99268	1.1023586	0.23862132	3400.9529
379.89355	1.1015298	0.23974934	3403.2664
380.79443	1.1047657	0.24072319	3399.4597
381.69531	1.1096959	0.24172677	3407.8928
382.59619	1.1142428	0.24284603	3402.8086
383.49707	1.1135643	0.24367781	3396.0642
384.39795	1.115821	0.24463309	3402.3218
385.29883	1.1167465	0.24548808	3404.5999
386.19971	1.1207722	0.24659035	3399.7302
387.10059	1.127041	0.24775681	3411.7273
388.00146	1.1254905	0.24888961	3410.3291
388.90234	1.1317507	0.25008467	3419.2532
389.80322	1.1351142	0.25123534	3411.5154
390.7041	1.1366109	0.25236765	3413.9292
391.60498	1.137949	0.25345874	3414.2
392.50586	1.1406593	0.25438744	3410.4189
393.40674	1.1426042	0.25532392	3414.9158
394.30762	1.1463107	0.25623161	3417.8904
395.2085	1.1473401	0.25732562	3422.5576
396.10938	1.1494168	0.25855845	3421.4175
397.01025	1.1556598	0.25953418	3423.303
397.91113	1.1562231	0.26056093	3421.894
398.81201	1.1612762	0.26158673	3423.9336
399.71289	1.1646267	0.26250872	3428.5742
400.61377	1.1637443	0.26363716	3429.0845
401.51465	1.1696842	0.26463836	3431.4221
402.41553	1.1718088	0.26566222	3430.6335
403.31641	1.1726568	0.26643282	3418.2383
404.21729	1.1786382	0.26736286	3437.9031
405.11816	1.1791462	0.26839069	3442.3472
406.01904	1.1824056	0.26934907	3437.9292
406.91992	1.1830831	0.27019709	3426.9773
407.8208	1.18933	0.27111098	3435.6917
408.72168	1.1916323	0.27197179	3438.958
409.62256	1.1940647	0.27309	3444.344
410.52344	1.1948769	0.27435145	3441.0684
411.42432	1.1980475	0.27552518	3448.9465
412.3252	1.2020627	0.27654883	3443.6733
413.22607	1.200722	0.27766508	3440.9578
414.12695	1.2081268	0.27873227	3447.115
415.02783	1.2082946	0.27968955	3452.4634
415.92871	1.2089736	0.28094855	3448.8657
416.82959	1.2150769	0.28220597	3454.6184
417.73047	1.2184916	0.28314191	3453.877
418.63135	1.2215347	0.28435248	3459.5769
419.53223	1.223497	0.28543097	3454.7979
420.43311	1.2248507	0.28640869	3454.9656
421.33398	1.2285078	0.28724965	3447.103
422.23486	1.2295879	0.28817013	3455.7827
423.13574	1.2301666	0.28921393	3460.3147
424.03662	1.234511	0.29031152	3468.0857
424.9375	1.2392472	0.29156741	3464.5034
425.83838	1.2379576	0.29261738	3464.3152
426.73926	1.2443922	0.29354641	3459.801
427.64014	1.2475351	0.29472324	3471.9895
428.54102	1.2489359	0.29559726	3462.1804
429.44189	1.2514374	0.29677263	3472.2339
430.34277	1.2566414	0.29775956	3464.7344
431.24365	1.256466	0.2987676	3467.3149
432.14453	1.2606657	0.30000791	3474.1069
433.04541	1.2611133	0.30091682	3470.2976
433.94629	1.2662497	0.30192286	3471.3416
434.84717	1.2654495	0.30288768	3467.1514
435.74805	1.2705394	0.30383262	3475.3745
436.64893	1.2729708	0.30505475	3477.2437
437.5498	1.2749277	0.30612713	3478.4675
438.45068	1.277445	0.30707157	3478.2424
439.35156	1.2810271	0.30815774	3477.2205
440.25244	1.2852318	0.30913311	3479.4958
441.15332	1.2871397	0.31000352	3478.7371
442.0542	1.2882955	0.31096488	3475.1638
442.95508	1.2966244	0.31169888	3481.0999
443.85596	1.2973399	0.31265771	3492.8962
444.75684	1.2975317	0.31356904	3495.1316
445.65771	1.3029379	0.31472784	3494.0811
446.55859	1.3012776	0.31569159	3486.6235
447.45947	1.3063338	0.31660485	3490.6621
448.36035	1.3077391	0.31765649	3488.3264
449.26123	1.3120314	0.31886616	3501.6277
450.16211	1.3134474	0.32017863	3500.5767
451.06299	1.3196936	0.32132438	3500.843
451.96387	1.3193423	0.32246283	3495.5017
452.86475	1.32173	0.32315591	3490.9729
453.76563	1.322827	0.3241621	3499.3337
454.6665	1.3291681	0.32535321	3498.6675
455.56738	1.3282969	0.32645479	3504.2222
456.46826	1.3343462	0.32762691	3511.3611
457.36914	1.3338441	0.32870424	3497.6414
458.27002	1.3401937	0.32992306	3511.8655
459.1709	1.3409557	0.33107531	3504.9858
460.07178	1.3425815	0.33205372	3508.0364
460.97266	1.3473647	0.33303794	3508.8123
461.87354	1.3480568	0.33405754	3507.4055
462.77441	1.3515546	0.33521566	3509.7383
463.67529	1.3552759	0.33627754	3517.158
464.57617	1.3580793	0.33732292	3514.1499
465.47705	1.3606889	0.33837354	3514.6357
466.37793	1.3633995	0.33933824	3508.5173
467.27881	1.3625401	0.34022266	3508.324
468.17969	1.3691874	0.34120888	3516.5481
469.08057	1.3706154	0.34228688	3518.9021
469.98145	1.3733104	0.34342268	3519.6824
470.88232	1.3773073	0.3445631	3523.7275
471.7832	1.3819993	0.34561065	3522.5098
472.68408	1.3787879	0.34667149	3518.8474
473.58496	1.3861859	0.34767953	3522.377
474.48584	1.3865111	0.3486177	3525.7439
475.38672	1.3893486	0.34982923	3526.6282
476.2876	1.3924453	0.35090625	3525.3767
477.18848	1.3967868	0.35191694	3530.4121
478.08936	1.4000751	0.35293049	3533.7231
478.99023	1.4018279	0.35401961	3528.1304
479.89111	1.4030046	0.35490999	3527.8147
480.79199	1.4042983	0.3561058	3531.8948
481.69287	1.4109393	0.35724622	3532.8809
482.59375	1.4103507	0.358156	3530.3982
483.49463	1.4153947	0.35918522	3528.269
484.39551	1.4132761	0.3599886	3526.4521
485.29639	1.4186528	0.36102149	3534.5427
486.19727	1.4228247	0.36201116	3534.9072
487.09814	1.4238739	0.36300755	3538.2905
487.99902	1.4290895	0.3640869	3539.9441
488.8999	1.4305273	0.36514959	3540.7144
489.80078	1.4326639	0.36628631	3539.842
490.70166	1.4365629	0.36754242	3543.5647
491.60254	1.4386618	0.36879694	3550.1619
492.50342	1.4418824	0.36973876	3543.947
493.4043	1.4453887	0.37074703	3549.2542
494.30518	1.4466475	0.37202075	3548.8013
495.20605	1.4503976	0.37316957	3547.2185
496.10693	1.4530362	0.37451231	3550.459
497.00781	1.4589945	0.37556016	3542.916
497.90869	1.4583262	0.37643999	3546.9678
498.80957	1.4599922	0.37747326	3550.3723
499.71045	1.4638758	0.37866488	3553.4558
500.61133	1.4666446	0.379691	3553.3799
501.51221	1.4661868	0.38074449	3553.0625
502.41309	1.4728292	0.38192347	3554.1982
503.31396	1.4731116	0.38279143	3553.5894
504.21484	1.4757743	0.38394853	3554.4307
505.11572	1.4787977	0.38492504	3559.2864
506.0166	1.4826934	0.38627809	3564.7615
506.91748	1.4830213	0.38721171	3560.77
507.81836	1.4868743	0.38827568	3561.5417
508.71924	1.4866017	0.38954455	3564.2688
509.62012	1.4907513	0.39072844	3564.1824
510.521	1.4941108	0.39186883	3564.8914
511.42188	1.4973567	0.39290121	3566.1753
512.32275	1.5003734	0.39386368	3564.7227
513.22363	1.5036163	0.39481473	3564.6541
514.12451	1.5073433	0.39585853	3570.4202
515.02539	1.5091703	0.39690983	3565.0007
515.92627	1.5129577	0.39781314	3569.4211
516.82715	1.5143362	0.398801	3569.7329
517.72803	1.5172919	0.39984301	3573.1675
518.62891	1.5206735	0.40104011	3573.3252
519.52979	1.523849	0.40197292	3572.7603
520.43066	1.5271989	0.40307498	3576.3711
521.33154	1.5272079	0.40412608	3573.8296
522.23242	1.5307717	0.40518969	3578.3403
523.1333	1.5334041	0.40632915	3575.938
524.03418	1.5347077	0.40745041	3582.1924
524.93506	1.536356	0.40866777	3578.4785
525.83594	1.5434146	0.40987456	3586.5645
526.73682	1.5432097	0.41101	3586.0771
527.6377	1.5444999	0.41231111	3580.1689
528.53857	1.5494159	0.413398	3586.8892
529.43945	1.5518906	0.41440576	3579.8958
530.34033	1.5529459	0.41564894	3590.0215
531.24121	1.5586485	0.41655338	3584.8657
532.14209	1.5578557	0.41772571	3586.6023
533.04297	1.5611694	0.41910955	3589.2974
533.94385	1.5660722	0.42016315	3587.52
534.84473	1.568917	0.42128554	3592.7102
535.74561	1.5709319	0.42233071	3594.9846
536.64648	1.574147	0.42373556	3595.376
537.54736	1.5767016	0.42494372	3595.1104
538.44824	1.5781282	0.42618623	3595.5134
539.34912	1.5839655	0.42729273	3591.9634
540.25	1.5838606	0.42821598	3585.9888
541.15088	1.5870925	0.42911476	3594.8735
542.05176	1.5900673	0.43015364	3599.1523
542.95264	1.5923836	0.4312678	3600.2529
543.85352	1.5959237	0.43247196	3599.9512
544.75439	1.5999184	0.43362144	3605.7632
545.65527	1.5998827	0.43480214	3595.6755
546.55615	1.6021659	0.4358083	3598.0088
547.45703	1.6040411	0.43695498	3600.8574
548.35791	1.6072241	0.43812728	3599.4351
549.25879	1.6104996	0.43914992	3599.2131
550.15967	1.6116015	0.44032869	3605.7815
551.06055	1.617784	0.44158754	3607.8604
551.96143	1.6214153	0.44264919	3600.856
552.8623	1.619292	0.44356227	3606.0242
553.76318	1.6272266	0.44453701	3607.5042
554.66406	1.6270745	0.44551641	3608.5735
555.56494	1.6294326	0.44674528	3610.5652
556.46582	1.6337531	0.44768706	3604.2212
557.3667	1.6353223	0.44877568	3613.1099
558.26758	1.6381561	0.44986215	3608.8071
559.16846	1.6415976	0.45112878	3613.6584
560.06934	1.6426032	0.45230198	3619.4219
560.97021	1.6464561	0.45355549	3612.5527
561.87109	1.6494721	0.45479178	3621.9343
562.77197	1.6525096	0.45602185	3621.7991
563.67285	1.6550207	0.45730352	3616.3552
564.57373	1.6560795	0.45826292	3614.4988
565.47461	1.6616058	0.45939493	3619.7859
566.37549	1.6619186	0.46054503	3619.2866
567.27637	1.6648287	0.46188933	3617.1921
568.17725	1.6674701	0.46302164	3622.1909
569.07813	1.6706637	0.46428916	3623.4731
569.979	1.6721324	0.46546984	3624.2664
570.87988	1.6756912	0.46662825	3622.5332
571.78076	1.6773388	0.46760681	3625.4377
572.68164	1.6827002	0.46878204	3627.0957
573.58252	1.6841581	0.46986181	3622.0554
574.4834	1.6870717	0.47102466	3629.7825
575.38428	1.6861322	0.47232759	3626.3633
576.28516	1.6940776	0.47375575	3632.571
577.18604	1.6983616	0.47491297	3631.6548
578.08691	1.6979635	0.4760662	3628.8823
578.98779	1.7020291	0.47744671	3633.9258
579.88867	1.7050301	0.47845525	3629.7764
580.78955	1.7074142	0.4796502	3636.4031
581.69043	1.7119486	0.4806861	3630.9087
582.59131	1.7122959	0.48170751	3630.8464
583.49219	1.7128438	0.48253399	3627.4128
584.39307	1.7177154	0.48336983	3629.8398
585.29395	1.7203338	0.48433614	3630.7129
586.19482	1.7222173	0.48541546	3639.1958
587.0957	1.7237631	0.48645079	3637.9758
587.99658	1.7262917	0.48768297	3636.9609
588.89746	1.7318013	0.48871765	3642.6892
589.79834	1.7337699	0.49012268	3637.0627
590.69922	1.7357755	0.4913677	3638.4602
591.6001	1.7360053	0.49249113	3636.1863
592.50098	1.740678	0.49373743	3649.011
593.40186	1.7444978	0.49496287	3640.5417
594.30273	1.7443837	0.49599251	3635.9607
595.20361	1.7484452	0.49734345	3647.4829
596.10449	1.7516527	0.4986991	3639.3223
597.00537	1.7537754	0.4998669	3642.1375
597.90625	1.7590073	0.50114781	3648.2952
598.80713	1.7633423	0.50236881	3647.9802
599.70801	1.7612112	0.50352478	3649.0222
600.60889	1.7640589	0.50462133	3645.0015
601.50977	1.7698168	0.50572461	3647.2358
602.41064	1.7690996	0.50694299	3653.3718
603.31152	1.7706664	0.508268	3646.2224
604.2124	1.7763444	0.50932038	3651.002
605.11328	1.7770189	0.51045936	3654.1912
606.01416	1.7819396	0.51195389	3659.6221
606.91504	1.7862813	0.5132286	3655.4138
607.81592	1.785908	0.51444817	3655.187
608.7168	1.7882137	0.51557487	3654.595
609.61768	1.7934862	0.5167293	3655.2683
610.51855	1.7946817	0.51820755	3656.6091
611.41943	1.7982488	0.51915067	3656.3403
612.32031	1.8015101	0.52029872	3657.595
613.22119	1.8015537	0.52147347	3654.8938
614.12207	1.8041792	0.52250963	3652.9109
615.02295	1.809067	0.52369004	3659.7783
615.92383	1.8113399	0.52498871	3660.6753
616.82471	1.8125261	0.52616727	3657.9438
617.72559	1.8155113	0.52735758	3659.6382
618.62646	1.8192912	0.52862954	3658.4851
619.52734	1.8239123	0.52987432	3665.2429
620.42822	1.8245941	0.53115183	3664.0039
621.3291	1.8260826	0.53254032	3666.7156
622.22998	1.8308979	0.53387213	3667.1143
623.13086	1.8348216	0.53521937	3669.7585
624.03174	1.8368485	0.53632039	3665.5669
624.93262	1.8372496	0.53727847	3656.4177
625.8335	1.8428355	0.53836983	3666.0706
626.73438	1.8440378	0.5393784	3668.3267
627.63525	1.8431104	0.54071856	3675.4329
628.53613	1.8508254	0.54213005	3668.0085
629.43701	1.8532343	0.54347873	3675.0098
630.33789	1.8555577	0.54468018	3673.3447
631.23877	1.8563704	0.54577404	3667.5264
632.13965	1.8572465	0.54701865	3674.4048
633.04053	1.864362	0.54828125	3677.6367
633.94141	1.8636152	0.54950005	3667.0981
634.84229	1.8684587	0.55083406	3667.2241
635.74316	1.8702688	0.55187839	3669.2834
636.64404	1.8769311	0.55314541	3678.7034
637.54492	1.8740516	0.55442196	3678.4585
638.4458	1.8814132	0.55569994	3678.999
639.34668	1.8820721	0.55688876	3676.5413
640.24756	1.8844675	0.55811256	3676.812
641.14844	1.8861104	0.55946738	3676.1157
642.04932	1.8881696	0.5607096	3677.0696
642.9502	1.8901874	0.56188416	3672.9045
643.85107	1.8915389	0.56314218	3676.9495
644.75195	1.8976626	0.564592	3685.6895
645.65283	1.8988433	0.56579077	3676.3694
646.55371	1.9052817	0.5667522	3676.6243
647.45459	1.9053243	0.56784111	3684.968
648.35547	1.9097151	0.56920695	3684.0737
649.25635	1.9118773	0.57054991	3682.9458
650.15723	1.9147449	0.57181007	3686.2068
651.05811	1.9152993	0.57313424	3684.7871
651.95898	1.9193518	0.57426077	3675.7927
652.85986	1.9211849	0.57544643	3685.0635
653.76074	1.9244875	0.57673794	3681.0591
654.66162	1.9267548	0.57812417	3688.7791
655.5625	1.9317255	0.57931507	3680.5127
656.46338	1.9307729	0.58042127	3684.5591
657.36426	1.9384279	0.58165509	3689.7434
658.26514	1.9400001	0.58314961	3697.3542
659.16602	1.941364	0.58465832	3692.6755
660.06689	1.9428864	0.58590353	3682.2253
660.96777	1.9477437	0.5874818	3692.4246
661.86865	1.9486622	0.58876663	3690.7297
662.76953	1.9532108	0.59016001	3688.8623
663.67041	1.9548849	0.59116733	3682.3259
664.57129	1.9575669	0.59231168	3689.5193
665.47217	1.9617312	0.59358615	3690.1555
666.37305	1.9638638	0.59493494	3693.8782
667.27393	1.9632634	0.59633237	3695.1963
668.1748	1.9685017	0.59772301	3691.5601
669.07568	1.9697117	0.59899741	3693.8833
669.97656	1.973473	0.60025811	3699.6899
670.87744	1.9778438	0.60168606	3690.6023
671.77832	1.9781628	0.60293931	3694.4211
672.6792	1.9791621	0.60418403	3696.6665
673.58008	1.9826725	0.60557789	3696.1475
674.48096	1.9883006	0.60693455	3692.9404
675.38184	1.990324	0.60842335	3706.9031
676.28271	1.9929153	0.60977328	3701.6833
677.18359	1.9930668	0.6111567	3695.1868
678.08447	1.9967145	0.61227638	3693.96
678.98535	1.997457	0.61347562	3696.2378
679.88623	2.0045855	0.6147508	3698.0642
680.78711	2.0068591	0.6159507	3703.1531
681.68799	2.0093095	0.61709511	3699.636
682.58887	2.008605	0.61867547	3704.9075
683.48975	2.0123429	0.62001914	3699.5271
684.39063	2.0169492	0.62125236	3703.0471
685.2915	2.0203292	0.62259221	3706.5503
686.19238	2.0225713	0.62407935	3704.0623
687.09326	2.0244751	0.6255278	3706.6523
687.99414	2.0232167	0.62685734	3701.6138
688.89502	2.0288415	0.62826753	3702.6277
689.7959	2.0346563	0.62962109	3710.3826
690.69678	2.0347855	0.63054472	3697.9695
691.59766	2.0380275	0.631688	3706.8691
692.49854	2.0393822	0.6330471	3706.187
693.39941	2.0430539	0.63446879	3710.6372
694.30029	2.0458949	0.63593531	3705.2876
695.20117	2.048022	0.63735789	3708.25
696.10205	2.0558422	0.63890904	3714.8208
697.00293	2.0552769	0.64014828	3701.7324
697.90381	2.0564897	0.64143538	3707.9114
698.80469	2.0624878	0.64278603	3709.6548
699.70557	2.0643137	0.64381593	3705.0559
700.60645	2.0650418	0.64515835	3712.1633
701.50732	2.0695367	0.6465947	3720.2603
702.4082	2.0714815	0.64811105	3711.2036
703.30908	2.0734575	0.64953613	3708.5723
704.20996	2.0711365	0.65094054	3709.0173
705.11084	2.0795031	0.65223604	3710.2886
706.01172	2.0818675	0.65360206	3713.8279
706.9126	2.0836291	0.65517813	3714.4097
707.81348	2.0870306	0.6569134	3716.8188
708.71436	2.0884612	0.65841472	3715.886
709.61523	2.0917921	0.6598596	3715.0576
710.51611	2.0936615	0.66151386	3709.009
711.41699	2.0973356	0.66292751	3715.9209
712.31787	2.1012926	0.66452438	3716.6323
713.21875	2.1033108	0.66579872	3714.9858
714.11963	2.1051393	0.66721231	3714.5352
715.02051	2.1117349	0.66855031	3715.3645
715.92139	2.1109889	0.6697793	3716.1575
716.82227	2.113229	0.67101812	3714.5356
717.72314	2.1176324	0.67251974	3718.7039
718.62402	2.1202054	0.67397618	3721.2991
719.5249	2.1239135	0.67525703	3719.0798
720.42578	2.1253784	0.67667097	3718.3198
721.32666	2.1287668	0.67793804	3715.7432
722.22754	2.1298432	0.67929327	3716.0989
723.12842	2.1344485	0.68078274	3721.7166
724.0293	2.1338575	0.68217236	3717.3232
724.93018	2.139559	0.68388665	3723.291
725.83105	2.1379261	0.68552101	3717.7605
726.73193	2.1453347	0.68695539	3721.4072
727.63281	2.148221	0.68824524	3721.3286
728.53369	2.1513157	0.68954915	3727.9177
729.43457	2.154006	0.69095808	3724.6514
730.33545	2.1537805	0.69241238	3727.5481
731.23633	2.1591411	0.69398016	3720.8655
732.13721	2.1589923	0.69511449	3719.8816
733.03809	2.1620677	0.69664186	3722.4172
733.93896	2.1663539	0.69813639	3730.4543
734.83984	2.1693935	0.69950664	3722.9971
735.74072	2.1722257	0.70095336	3726.0303
736.6416	2.1729867	0.70236468	3723.8113
737.54248	2.1771886	0.70391935	3728.5056
738.44336	2.1808016	0.7054438	3725.8799
739.34424	2.180831	0.7068876	3722.8738
740.24512	2.1821218	0.70808029	3718.3376
741.146	2.1851733	0.70939988	3722.8157
742.04688	2.1901975	0.71086192	3731.2385
742.94775	2.1914706	0.71224058	3723.4897
743.84863	2.192755	0.71367097	3726.5007
744.74951	2.1964679	0.71546572	3733.6067
745.65039	2.2015488	0.71715713	3730.4194
746.55127	2.2050848	0.71890122	3727.1133
747.45215	2.2069249	0.72032267	3729.4971
748.35303	2.2086565	0.72189635	3733.373
749.25391	2.2106333	0.72327703	3724.7092
750.15479	2.2145262	0.72473621	3728.1392
751.05566	2.2143786	0.72630072	3734.0574
751.95654	2.2188554	0.72803777	3726.9009
752.85742	2.2206447	0.72953981	3729.0596
753.7583	2.2223663	0.7311945	3727.9165
754.65918	2.2254851	0.73269969	3731.3301
755.56006	2.231307	0.73423606	3730.426
756.46094	2.2348611	0.7357682	3728.4358
757.36182	2.2360301	0.73710471	3732.8186
758.2627	2.2373128	0.73867649	3726.6917
759.16357	2.2404325	0.74029666	3725.0493
760.06445	2.2437215	0.74202228	3729.2051
760.96533	2.2464654	0.74351054	3727.6162
761.86621	2.2456682	0.74516833	3729.6096
762.76709	2.2523451	0.7467255	3732.4453
763.66797	2.2534647	0.74859738	3732.6921
764.56885	2.2580559	0.7502678	3729.0085
765.46973	2.258059	0.75178617	3728.2371
766.37061	2.2663295	0.75325143	3729.5515
767.27148	2.2661257	0.75467694	3728.2107
768.17236	2.2691481	0.75614643	3728.6265
769.07324	2.271601	0.75768524	3737.5205
769.97412	2.2735572	0.759381	3733.9863
770.875	2.2769549	0.76086909	3734.3557
771.77588	2.2801194	0.76264811	3743.3445
772.67676	2.280395	0.76446843	3732.3123
773.57764	2.2860804	0.76618147	3731.4817
774.47852	2.2861128	0.76789701	3726.575
775.37939	2.2882557	0.76919991	3730.7603
776.28027	2.2934027	0.77076143	3731.4229
777.18115	2.2956626	0.77229154	3727.9653
778.08203	2.3000906	0.7736907	3736.5601
778.98291	2.3005621	0.77533376	3738.3
779.88379	2.3016934	0.77703476	3735.239
780.78467	2.3062258	0.7787016	3738.478
781.68555	2.3083358	0.78046966	3734.2209
782.58643	2.30937	0.78206027	3731.8284
783.4873	2.3137279	0.78357404	3729.3467
784.38818	2.316612	0.78505695	3732.7146
785.28906	2.3180792	0.78679419	3732.897
786.18994	2.3209915	0.78840631	3735.0991
787.09082	2.323796	0.78998411	3731.7874
787.9917	2.3255703	0.79172122	3732.6045
788.89258	2.3295839	0.79357928	3731.4097
789.79346	2.3320093	0.79538423	3737.564
790.69434	2.3367169	0.79731351	3737.7979
791.59521	2.3371174	0.79900658	3733.8577
792.49609	2.3401542	0.80083245	3736.9363
793.39697	2.344805	0.80264288	3740.219
794.29785	2.3488235	0.80434519	3734.9854
795.19873	2.3500299	0.80593085	3732.8442
796.09961	2.3549643	0.80739802	3733.9087
797.00049	2.3521302	0.80890161	3731.1758
797.90137	2.3560452	0.81084019	3737.2742
798.80225	2.3624527	0.81268132	3740.0056
799.70313	2.3625538	0.81457263	3736.4976
800.604	2.3634784	0.81633133	3733.748
801.50488	2.3694539	0.81781548	3732.6514
802.40576	2.3733153	0.81950271	3738.5747
803.30664	2.373271	0.82126677	3735.3308
804.20752	2.3778837	0.82286555	3733.4998
805.1084	2.3783627	0.82434803	3731.2295
806.00928	2.3823216	0.82608503	3732.6992
806.91016	2.3849487	0.82782489	3737.114
807.81104	2.3849053	0.8298378	3738.1023
808.71191	2.3866479	0.83154821	3733.7114
809.61279	2.394537	0.83355498	3739.769
810.51367	2.3941064	0.83523589	3732.8467
811.41455	2.3970306	0.83717585	3734.1389
812.31543	2.4014263	0.83886856	3733.1133
813.21631	2.4022286	0.84093237	3743.179
814.11719	2.4056771	0.84281468	3732.1604
815.01807	2.4067159	0.84452546	3733.0027
815.91895	2.4111476	0.84628665	3725.697
816.81982	2.4136131	0.84767896	3730.0627
817.7207	2.4155786	0.84963423	3738.949
818.62158	2.4190321	0.8516258	3737.7637
819.52246	2.4225855	0.85370487	3734.4771
820.42334	2.4248457	0.85537851	3730.9438
821.32422	2.4284229	0.85739344	3736.5884
822.2251	2.4310167	0.85933924	3737.8811
823.12598	2.4302654	0.8611598	3729.3313
824.02686	2.436079	0.86335957	3736.9209
824.92773	2.4367213	0.86533743	3732.8301
825.82861	2.4396489	0.8673141	3737.4822
826.72949	2.4448881	0.8695448	3736.8301
827.63037	2.4456983	0.8717531	3738.4885
828.53125	2.4477582	0.87383705	3728.854
829.43213	2.4545593	0.87566966	3733.1689
830.33301	2.4545543	0.87734866	3727.761
831.23389	2.4573722	0.87945211	3733.5674
832.13477	2.4607449	0.8815316	3738.5073
833.03564	2.4596217	0.88347942	3728.4077
833.93652	2.4658372	0.88542724	3729.1377
834.8374	2.4685547	0.88709384	3728.7336
835.73828	2.4710236	0.88871551	3729.2922
836.63916	2.4728794	0.89050412	3733.7751
837.54004	2.4777727	0.89247096	3732.6069
838.44092	2.4774094	0.89445883	3731.9944
839.3418	2.480875	0.89646822	3726.8389
840.24268	2.4871871	0.8982141	3736.335
841.14355	2.4885573	0.90030247	3732.2327
842.04443	2.4887199	0.90234888	3730.2651
842.94531	2.4911785	0.90429819	3729.5735
843.84619	2.4985783	0.90628982	3734.4819
844.74707	2.4992526	0.90838325	3734.103
845.64795	2.5038381	0.91064721	3731.5095
846.54883	2.5042534	0.91262412	3730.9443
847.44971	2.5057821	0.91477454	3728.5503
848.35059	2.5094237	0.91669202	3729.3591
849.25146	2.5083406	0.91904306	3725.9729
850.15234	2.5162714	0.92117083	3724.1455
851.05322	2.5168109	0.92306542	3728.7551
851.9541	2.5206628	0.92533708	3734.0798
852.85498	2.5204885	0.92802495	3727.418
853.75586	2.5244758	0.93032968	3726.47
854.65674	2.525923	0.93233323	3723.061
855.55762	2.5314579	0.93442279	3726.8884
856.4585	2.5338016	0.93640178	3725.5859
857.35938	2.5365076	0.93862206	3734.6143
858.26025	2.5376022	0.94161445	3724.5073
859.16113	2.5411592	0.94386321	3718.0276
860.06201	2.5437415	0.94565612	3717.0513
860.96289	2.5447061	0.94723207	3715.011
861.86377	2.5494106	0.94986606	3733.3821
862.76465	2.554208	0.95240188	3726.8262
863.66553	2.5551617	0.95479405	3725.7056
864.56641	2.5549834	0.95682412	3719.2822
865.46729	2.5599949	0.95910066	3720.4995
866.36816	2.5622013	0.96133655	3717.4343
867.26904	2.5651064	0.96363407	3719.0615
868.16992	2.5696974	0.96626031	3723.3171
869.0708	2.5709364	0.96851462	3721.2537
869.97168	2.5752146	0.97057956	3720.6494
870.87256	2.5762062	0.97274566	3723.9919
871.77344	2.5814025	0.97514939	3716.7341
872.67432	2.5834506	0.97693169	3710.6382
873.5752	2.5824797	0.97897577	3717.7715
874.47607	2.5866523	0.98103279	3711.0535
875.37695	2.5906837	0.98316181	3721.2202
876.27783	2.5921819	0.98594791	3716.2366
877.17871	2.5943954	0.98832971	3716.7957
878.07959	2.5975218	0.99071622	3710.146
878.98047	2.6014738	0.99307102	3720.7742
879.88135	2.6011717	0.99559319	3718.8208
880.78223	2.6074767	0.99851465	3715.0051
881.68311	2.6063159	1.000954	3707.2727
882.58398	2.6093602	1.0032533	3708.0251
883.48486	2.6144307	1.0055206	3709.9707
884.38574	2.6142218	1.0076951	3704.1167
885.28662	2.6202302	1.0099843	3709.4182
886.1875	2.6237345	1.0125506	3707.3091
887.08838	2.6249092	1.0150313	3707.9297
887.98926	2.6264353	1.01745	3701.7852
888.89014	2.6314745	1.0200469	3711.7686
889.79102	2.6338744	1.0230625	3707.6025
890.69189	2.6378472	1.0261791	3708.166
891.59277	2.639086	1.029528	3707.3398
892.49365	2.640419	1.0323957	3702.6267
893.39453	2.6450663	1.0349783	3697.2163
894.29541	2.6485562	1.0372053	3694.6526
895.19629	2.6490593	1.039259	3698.2063
896.09717	2.6523051	1.0417702	3694.5859
896.99805	2.6573663	1.0439129	3693.3281
897.89893	2.6558015	1.0459054	3692.605
898.7998	2.6598876	1.0483898	3699.8203
899.70068	2.663388	1.0510631	3697.479
900.60156	2.6656399	1.0537947	3691.1245
901.50244	2.6681876	1.056456	3693.0149
902.40332	2.6733379	1.0589287	3688.7888
903.3042	2.673595	1.0612813	3689.7522
904.20508	2.6750121	1.0642496	3689.2939
905.10596	2.6793234	1.067377	3689.3289
906.00684	2.684025	1.0705984	3693.5405
906.90771	2.6845973	1.0734336	3682.0085
907.80859	2.688411	1.0760636	3686.4338
908.70947	2.6874442	1.0789968	3677.8091
909.61035	2.6942697	1.081647	3681.5698
910.51123	2.6953979	1.0847753	3679.3364
911.41211	2.6959333	1.0873741	3675.5117
912.31299	2.6984868	1.0899345	3674.6682
913.21387	2.7028813	1.09304	3673.6379
914.11475	2.70577	1.0956951	3668.3042
915.01563	2.709547	1.097851	3669.0266
915.9165	2.7123532	1.1002467	3671.1536
916.81738	2.7149947	1.1027608	3673.9365
917.71826	2.7170925	1.1056783	3667.4136
918.61914	2.7216442	1.1083212	3661.7363
919.52002	2.7226069	1.1112314	3670.8628
920.4209	2.7239726	1.1142805	3659.3064
921.32178	2.7295067	1.116877	3654.2983
922.22266	2.7295239	1.1197354	3661.4719
923.12354	2.7334199	1.1228535	3663.7671
924.02441	2.7346482	1.1261935	3657.7769
924.92529	2.7374852	1.1295832	3654.5281
925.82617	2.739393	1.1321419	3647.5854
926.72705	2.7428958	1.1344634	3654.5249
927.62793	2.7460315	1.1370269	3642.0698
928.52881	2.7463565	1.1402054	3648.4199
929.42969	2.7515051	1.1438782	3646.6123
930.33057	2.7562628	1.1464998	3638.8076
931.23145	2.7588353	1.1489723	3639.0864
932.13232	2.7601225	1.1515807	3639.5
933.0332	2.7594335	1.1541703	3633.2502
933.93408	2.7688248	1.1568338	3636.2305
934.83496	2.767699	1.1594071	3633.6406
935.73584	2.7699323	1.1623807	3635.5857
936.63672	2.7728446	1.1653594	3627.9255
937.5376	2.7768695	1.1686751	3626.1658
938.43848	2.7813277	1.172067	3622.0615
939.33936	2.784091	1.1748636	3617.3428
940.24023	2.7819152	1.1774157	3614.6245
941.14111	2.7892575	1.1801015	3615.3718
942.04199	2.7916079	1.183304	3620.0933
942.94287	2.7908852	1.1864438	3610.9841
943.84375	2.7993922	1.1890723	3608.2629
944.74463	2.7968957	1.1913325	3603.4167
945.64551	2.7998462	1.1938996	3607.218
946.54639	2.8039343	1.196961	3602.7051
947.44727	2.8076513	1.2002275	3602.4189
948.34814	2.8083124	1.2030332	3598.1504
949.24902	2.8100953	1.2056062	3593.0901
950.1499	2.8130701	1.2082419	3582.1177
951.05078	2.8174706	1.2111204	3594.7473
951.95166	2.8230937	1.2140549	3592.9072
952.85254	2.8226163	1.2170906	3585.3584
953.75342	2.8263481	1.2202244	3584.0598
954.6543	2.8291147	1.2229806	3576.1033
955.55518	2.8322518	1.225863	3577.8369
956.45605	2.8320234	1.2288439	3573.5361
957.35693	2.8352458	1.2317612	3568.7979
958.25781	2.8386781	1.2349393	3569.3105
959.15869	2.8437688	1.2381818	3574.5159
960.05957	2.8404615	1.2416313	3561.0801
960.96045	2.8445439	1.2446864	3555.3093
961.86133	2.8500497	1.2473798	3558.0149
962.76221	2.8533921	1.2499878	3548.5435
963.66309	2.855916	1.2522938	3542.9536
964.56396	2.8583872	1.2550702	3553.6782
965.46484	2.8633406	1.2580072	3546.2517
966.36572	2.8631735	1.2611949	3542.2717
967.2666	2.8657908	1.2646497	3545.752
968.16748	2.8676379	1.2680408	3531.45
969.06836	2.8714414	1.2713268	3527.3752
969.96924	2.8737109	1.2739929	3525.9316
970.87012	2.8759177	1.2770964	3521.9561
971.771	2.8810706	1.279873	3515.9753
972.67188	2.8798974	1.282778	3517.8879
973.57275	2.8865073	1.2856947	3509.4543
974.47363	2.8898878	1.2883016	3508.1311
975.37451	2.8894129	1.2910872	3514.8022
976.27539	2.891448	1.2944231	3502.8079
977.17627	2.8961067	1.2977165	3499.7263
978.07715	2.8994987	1.3010451	3492.9048
978.97803	2.9019303	1.3038759	3492.4705
979.87891	2.9035141	1.3068734	3484.9246
980.77979	2.9060481	1.3099052	3484.0574
981.68066	2.9095721	1.3125045	3475.0105
982.58154	2.9107456	1.3152821	3476.2373
983.48242	2.9159508	1.3181853	3477.4744
984.3833	2.9185328	1.3216184	3471.8821
985.28418	2.9206426	1.3249277	3461.1489
986.18506	2.9202719	1.3279091	3457.1516
987.08594	2.9269207	1.3312212	3448.2097
987.98682	2.9283996	1.334337	3456.3667
988.8877	2.9292762	1.3370252	3438.1299
989.78857	2.9351943	1.3400056	3442.9927
990.68945	2.9369574	1.3433703	3435.334
991.59033	2.942956	1.3464515	3427.9124
992.49121	2.9423335	1.3497789	3420.1228
993.39209	2.9444785	1.3531421	3419.197
994.29297	2.9482372	1.3562989	3418.5754
995.19385	2.9502611	1.3600101	3406.3433
996.09473	2.950666	1.363915	3395.3176
996.99561	2.9552195	1.3673224	3388.6973
997.89648	2.960108	1.3705058	3385.2017
998.79736	2.9618359	1.373384	3372.2791
999.69824	2.9620113	1.3764707	3363.55
1000.5991	2.9652867	1.379666	3364.115
1001.5	2.9677696	1.3832468	3349.1323
1002.4009	2.9694276	1.3884923	3324.2742
1003.3018	2.9756312	1.3945692	3298.6179
1003.6021	2.9739585	1.3990277	3264.6848