File: datasets/am_bench_2022/raw_data/0-XY.10-3/specimen.dat
MTS793|MPT|ENU|1|2|.|/|:|1|0|0|A

Operator Information						Time:	23.012695	Sec	10/13/2021 2:55:02 PM
Operator	Nick Derimow
Project	AM Bench 2022 mini-tensile challenge
Specimen ID	0-XY.10-3
Material	PBF-L Inconel 625
Specimen Width	2.56	mm
Specimen Thickness	1.5	mm
Notes
Operator Information End

Data Acquisition						Time:	1024.0061	Sec	10/13/2021 3:11:43 PM
Time	Axial Displacement	Axial Extensometer	Axial Force
Sec	mm	mm	N
23.125977	-0.0017059633	4.2044139e-05	76.878143
24.126953	0.002725777	7.3678275e-05	92.885292
25.12793	0.0054933932	0.00012614676	107.5734
26.128906	0.00636377	0.00010774345	116.4307
27.129883	0.013147044	0.00024224925	127.15793
28.130859	0.014714665	0.00028078823	141.06023
29.131836	0.014688849	0.00033489172	154.08777
30.132813	0.017654389	0.00035242116	166.9194
31.133789	0.022405298	0.00046244659	183.88774
32.134766	0.027358128	0.00053876441	202.98637
33.135742	0.028223792	0.0006309264	218.94104
34.136719	0.030687759	0.0007836757	240.68542
35.137695	0.031397913	0.00084350689	254.16324
36.138672	0.037799217	0.00086495082	272.5108
37.139648	0.04255202	0.00098881766	293.47153
38.140625	0.040548649	0.0010503054	313.05957
39.141602	0.043636303	0.0010933889	328.13419
40.142578	0.045454916	0.0012529599	356.77963
41.143555	0.049745437	0.0013727833	377.93207
42.144531	0.053345576	0.0015453773	404.46237
43.145508	0.053611524	0.0015243227	417.88431
44.146484	0.060747772	0.0016636353	440.57687
45.147461	0.065570034	0.0018226819	463.92706
46.148438	0.067612387	0.0018013773	486.92361
47.149414	0.066513762	0.0019000149	508.48608
48.150391	0.072870813	0.0022053444	541.58698
49.151367	0.076392017	0.0021790734	555.784
50.152344	0.078381918	0.002200841	581.12543
51.15332	0.080489017	0.0025069767	610.78088
52.154297	0.08361806	0.0026369053	637.22357
53.155273	0.085316814	0.0027207702	659.57239
54.15625	0.09010604	0.0027031701	682.73627
55.157227	0.091765448	0.0029663823	709.58331
56.158203	0.09516152	0.0029500125	730.65283
57.15918	0.097333312	0.0030331346	758.62048
58.160156	0.10153536	0.0032807228	794.58179
59.161133	0.10553642	0.003448592	821.32275
60.162109	0.10676208	0.0034926601	847.87445
61.163086	0.11079265	0.0035707788	885.99884
62.164063	0.111821	0.0038573486	911.2572
63.165039	0.11421448	0.0039749756	939.25281
64.166016	0.12142864	0.0041109677	973.2254
65.166992	0.12385368	0.004218223	991.3692
66.167969	0.1281254	0.0044266731	1021.9874
67.168945	0.12884273	0.0044523119	1047.6094
68.169922	0.13026133	0.0045598797	1065.902
69.170898	0.13541025	0.0047230148	1105.4546
70.171875	0.13672334	0.0048757028	1117.1487
71.172852	0.13848437	0.0048734448	1145.8536
72.173828	0.14546409	0.0051890383	1176.6702
73.174805	0.14743371	0.0052100481	1198.0145
74.175781	0.15072216	0.0053136768	1230.7283
75.176758	0.15422636	0.0053940914	1260.0022
76.177734	0.15731791	0.0056317956	1286.9662
77.178711	0.15990527	0.0057868334	1323.0038
78.179688	0.1601958	0.0057764258	1333.1061
79.180664	0.16409606	0.0059118159	1358.8658
80.181641	0.1724297	0.0061961156	1395.903
81.182617	0.17024842	0.0061611743	1423.5359
82.183594	0.17369592	0.006400492	1454.1991
83.18457	0.17883228	0.00653303	1477.4575
84.185547	0.17756708	0.0066820625	1498.2908
85.186523	0.1825299	0.0068490794	1531.1121
86.1875	0.184195	0.0071040592	1561.9946
87.188477	0.18633324	0.0070731821	1582.1982
88.189453	0.19165953	0.0072443387	1608.3743
89.19043	0.19747832	0.0074127275	1638.0005
90.191406	0.19916889	0.0075338371	1661.3601
91.192383	0.20010933	0.0076890728	1689.3314
92.193359	0.2050617	0.007719995	1717.8905
93.194336	0.20818603	0.0080437688	1746.2871
94.195313	0.20747793	0.0081109721	1764.3877
95.196289	0.2141903	0.0081907101	1786.4806
96.197266	0.21224302	0.0083070667	1808.7722
97.198242	0.21872716	0.0085434876	1839.2831
98.199219	0.22241494	0.0087167211	1871.8436
99.200195	0.22388744	0.0088495798	1895.1219
100.20117	0.22742672	0.0091472575	1922.5673
101.20215	0.22910786	0.0091897883	1942.2999
102.20313	0.23527703	0.0092663262	1961.0232
103.2041	0.23719311	0.0095550995	1981.6451
104.20508	0.23777111	0.0095696552	2002.9767
105.20605	0.24344045	0.0098284464	2030.7498
106.20703	0.24827228	0.0099843014	2057.1882
107.20801	0.24836776	0.010072945	2061.9243
108.20898	0.2490775	0.0101807	2086.25
109.20996	0.25759861	0.010348544	2108.4116
110.21094	0.25916317	0.010617251	2125.1572
111.21191	0.26209366	0.010804257	2147.0056
112.21289	0.26238278	0.01095935	2159.7935
113.21387	0.26690486	0.01108745	2186.7554
114.21484	0.27256799	0.011292966	2204.7671
115.21582	0.27363241	0.01156307	2218.7104
116.2168	0.27803048	0.011598861	2232.7981
117.21777	0.28040662	0.01191783	2245.4619
118.21875	0.28229877	0.012009121	2257.5115
119.21973	0.28880703	0.012167635	2282.9143
120.2207	0.28741869	0.01234902	2289.2002
121.22168	0.29488671	0.012752617	2310.5542
122.22266	0.29150191	0.012870715	2323.5815
123.22363	0.29898757	0.013036506	2340.3477
124.22461	0.29989871	0.013286942	2343.6758
125.22559	0.30420563	0.013494315	2363.0425
126.22656	0.30606624	0.013794078	2376.2673
127.22754	0.30936867	0.013949237	2390.1248
128.22852	0.31168348	0.014175999	2394.8691
129.22949	0.31224734	0.014416427	2409.4712
130.23047	0.31730604	0.014703792	2422.0413
131.23145	0.32315665	0.015024074	2439.8318
132.23242	0.32570913	0.015148056	2444.418
133.2334	0.32802764	0.015546868	2459.2009
134.23438	0.32905701	0.015722062	2460.5735
135.23535	0.33371371	0.01617636	2479.8025
136.23633	0.33900928	0.016513314	2489.415
137.2373	0.3400993	0.016653176	2500.0818
138.23828	0.34176686	0.017054992	2507.001
139.23926	0.34439802	0.017383637	2513.8938
140.24023	0.34642273	0.017873697	2527.2375
141.24121	0.35047978	0.018144051	2533.6018
142.24219	0.35524669	0.018535696	2540.4097
143.24316	0.35783419	0.018973481	2548.0264
144.24414	0.36306342	0.019358767	2555.9324
145.24512	0.36548376	0.019826291	2569.1345
146.24609	0.36622176	0.020198463	2576.3806
147.24707	0.36971673	0.020743933	2579.1372
148.24805	0.37614453	0.021223443	2591.032
149.24902	0.37787274	0.021587357	2590.2141
150.25	0.38165027	0.021985993	2593.2307
151.25098	0.38407248	0.022475094	2608.9563
152.25195	0.38815364	0.023072837	2612.5962
153.25293	0.38886094	0.023557877	2622.4045
154.25391	0.39285216	0.024177624	2621.0063
155.25488	0.39473814	0.024804575	2633.2917
156.25586	0.39596954	0.025584312	2632.8872
157.25684	0.4002558	0.026253572	2641.3018
158.25781	0.40430853	0.027150715	2651.9514
159.25879	0.40789407	0.027860969	2658.9771
160.25977	0.40908527	0.028608192	2660.0322
161.26074	0.41449824	0.029631248	2670.3562
162.26172	0.41345102	0.030323857	2666.1616
163.2627	0.41782442	0.031263057	2677.9609
164.26367	0.42209813	0.032344513	2679.8262
165.26465	0.42351824	0.033094641	2683.1782
166.26563	0.42990711	0.033964973	2694.0725
167.2666	0.42883348	0.034629468	2688.3901
168.26758	0.4344753	0.035605352	2699.636
169.26855	0.43807518	0.03649332	2705.875
170.26953	0.44153532	0.037584912	2707.9272
171.27051	0.44610864	0.038542148	2706.9192
172.27148	0.44798157	0.039389201	2714.0757
173.27246	0.44925797	0.040525939	2718.8584
174.27344	0.45071948	0.041706346	2719.1636
175.27441	0.45805061	0.042526446	2726.0857
176.27539	0.46019658	0.04355672	2727.0684
177.27637	0.46013656	0.044609129	2733.5398
178.27734	0.46477851	0.045872822	2734.6584
179.27832	0.46714702	0.046927273	2735.4922
180.2793	0.46924713	0.048230264	2737.2004
181.28027	0.47421202	0.04929639	2749.0466
182.28125	0.47306749	0.050809994	2744.3757
183.28223	0.48048115	0.051960189	2756.5576
184.2832	0.48326296	0.053158645	2754.1616
185.28418	0.48361558	0.054085974	2746.1504
186.28516	0.49063134	0.055363204	2754.877
187.28613	0.49399173	0.056558996	2760.729
188.28711	0.49827558	0.057881728	2768.302
189.28809	0.49771971	0.059029844	2766.3772
190.28906	0.49981302	0.060511474	2769.1953
191.29004	0.50129604	0.06162231	2771.5225
192.29102	0.50361168	0.063266017	2778.8196
193.29199	0.50973088	0.06478183	2781.0652
194.29297	0.51088482	0.066257402	2772.6265
195.29395	0.51430541	0.067463353	2778.4038
196.29492	0.5165422	0.068641677	2778.2214
197.2959	0.51962453	0.069622621	2776.7131
198.29688	0.52387249	0.070957057	2792.7017
199.29785	0.52880991	0.072246231	2787.0166
200.29883	0.53049117	0.073683046	2797.1646
201.2998	0.53355491	0.075260207	2795.1826
202.30078	0.53546345	0.076465003	2796.7051
203.30176	0.53911453	0.07768894	2796.3569
204.30273	0.5420441	0.078911185	2800.7666
205.30371	0.54691136	0.080511868	2804.2246
206.30469	0.5475381	0.08204779	2805.4016
207.30566	0.54937232	0.083461933	2805.8833
208.30664	0.5569489	0.084750012	2799.5315
209.30762	0.55586481	0.08585605	2806.2339
210.30859	0.56182915	0.08757022	2811.447
211.30957	0.56270278	0.088834487	2810.1592
212.31055	0.56626189	0.090224311	2819.3069
213.31152	0.56949419	0.091952421	2823.6584
214.3125	0.57183838	0.09353558	2818.4133
215.31348	0.57393229	0.095006317	2820.2273
216.31445	0.58078992	0.096459322	2820.5618
217.31543	0.57891029	0.09783721	2819.3438
218.31641	0.58486599	0.099216841	2820.7351
219.31738	0.59054202	0.10045841	2822.488
220.31836	0.59216517	0.10175189	2830.5037
221.31934	0.59336966	0.10286658	2829.3108
222.32031	0.5978471	0.104137	2832.019
223.32129	0.5979479	0.10553655	2834.345
224.32227	0.60153675	0.10715562	2831.0002
225.32324	0.60523522	0.10843879	2836.3252
226.32422	0.61089587	0.10985533	2838.5198
227.3252	0.60830033	0.11126036	2838.877
228.32617	0.61554188	0.11248701	2841.6472
229.32715	0.6164766	0.11410298	2840.4163
230.32813	0.6195938	0.11546892	2844.1179
231.3291	0.62099254	0.11701348	2843.1296
232.33008	0.6255157	0.11857264	2850.3062
233.33105	0.63165706	0.1202814	2847.4446
234.33203	0.63143188	0.12172408	2849.6165
235.33301	0.63598734	0.12309334	2849.0466
236.33398	0.63741541	0.12469283	2849.5852
237.33496	0.64383376	0.12618382	2854.092
238.33594	0.64680463	0.12786464	2856.9038
239.33691	0.64868182	0.12963614	2864.0818
240.33789	0.64801514	0.13100152	2853.3147
241.33887	0.65378845	0.13249968	2860.6711
242.33984	0.654607	0.13414985	2862.7336
243.34082	0.66012037	0.13560572	2860.6482
244.3418	0.66231757	0.13689445	2859.0945
245.34277	0.66920346	0.13837676	2863.3701
246.34375	0.6681245	0.13956366	2856.4907
247.34473	0.67190844	0.14096543	2871.1785
248.3457	0.67583245	0.14271356	2869.0535
249.34668	0.67910838	0.14416616	2868.6411
250.34766	0.68069339	0.14559023	2865.2712
251.34863	0.67851543	0.14715943	2870.0332
252.34961	0.68307912	0.14853668	2868.3037
253.35059	0.68937314	0.14989696	2871.658
254.35156	0.69172525	0.15132682	2878.4285
255.35254	0.69284022	0.15277755	2874.0527
256.35352	0.70051372	0.15444186	2883.6387
257.35449	0.69965547	0.1561677	2879.8796
258.35547	0.7042011	0.15772764	2876.7295
259.35645	0.70809704	0.15936267	2886.5132
260.35742	0.71328837	0.16084568	2886.8513
261.3584	0.71413308	0.16243967	2888.6873
262.35938	0.72003162	0.16396238	2888.8628
263.36035	0.71927685	0.16518375	2887.2341
264.36133	0.72117633	0.16672172	2885.0894
265.3623	0.72645962	0.16838373	2891.5337
266.36328	0.72624451	0.16979964	2884.228
267.36426	0.73327339	0.17118543	2892.0979
268.36523	0.73366392	0.17291667	2895.7368
269.36621	0.73592955	0.1746121	2895.4888
270.36719	0.74391365	0.17615236	2891.9917
271.36816	0.74375427	0.17759292	2895.7273
272.36914	0.75048506	0.1792616	2907.4753
273.37012	0.75111383	0.18070509	2902.0952
274.37109	0.75092763	0.18231472	2901.7053
275.37207	0.7568081	0.18395849	2898.8179
276.37305	0.75856525	0.185399	2900.4387
277.37402	0.76082104	0.18703084	2905.1841
278.375	0.76731396	0.1886085	2907.1824
279.37598	0.76738036	0.18994451	2900.5601
280.37695	0.77039468	0.1915002	2911.3374
281.37793	0.77643847	0.19301026	2911.2751
282.37891	0.77843511	0.19460453	2910.5515
283.37988	0.78026873	0.19623168	2909.8645
284.38086	0.78356886	0.19783241	2916.4106
285.38184	0.78319043	0.19951317	2913.9705
286.38281	0.78950506	0.20117351	2916.7805
287.38379	0.7909264	0.2022699	2906.946
288.38477	0.79831195	0.20402527	2916.3513
289.38574	0.79847485	0.20566562	2916.0928
290.38672	0.80010802	0.20741943	2920.6985
291.3877	0.80335039	0.20881936	2915.7927
292.38867	0.80599082	0.2103751	2914.7207
293.38965	0.8116129	0.21155976	2915.3809
294.39063	0.81368703	0.21269014	2918.8921
295.3916	0.81577545	0.21430251	2923.9607
296.39258	0.8202976	0.21595296	2925.4993
297.39355	0.82174385	0.21770121	2932.2507
298.39453	0.82549679	0.21939865	2931.0088
299.39551	0.82662433	0.2209744	2923.9602
300.39648	0.82896554	0.22232054	2932.2422
301.39746	0.83331394	0.22372033	2928.2207
302.39844	0.83441281	0.2251742	2931.0156
303.39941	0.84163994	0.22684188	2934.2612
304.40039	0.84452462	0.22833525	2931.7705
305.40137	0.84412897	0.22981939	2929.0291
306.40234	0.8488754	0.23131816	2937.1238
307.40332	0.84799212	0.23272531	2931.8911
308.4043	0.85532898	0.23418722	2937.6667
309.40527	0.85639381	0.2355143	2939.8826
310.40625	0.8609184	0.23738901	2946.8237
311.40723	0.86391121	0.2394926	2946.7429
312.4082	0.86571705	0.24102935	2934.9231
313.40918	0.86600101	0.24253073	2940.9495
314.41016	0.87125522	0.2440702	2944.0754
315.41113	0.87742543	0.24538207	2942.7412
316.41211	0.88205463	0.24669601	2940.7625
317.41309	0.88201696	0.24830857	2953.1592
318.41406	0.88159364	0.24982834	2943.7524
319.41504	0.88606334	0.25131679	2947.55
320.41602	0.8927142	0.25280264	2957.1995
321.41699	0.89571762	0.25467923	2960.9458
322.41797	0.896285	0.25617406	2954.1733
323.41895	0.90091079	0.25771141	2955.686
324.41992	0.90421975	0.25945801	2953.3091
325.4209	0.90674806	0.26098353	2960.2629
326.42188	0.90905404	0.26276162	2960.4026
327.42285	0.91084009	0.26414767	2953.2859
328.42383	0.91318816	0.26549998	2957.511
329.4248	0.9207862	0.26688769	2962.1812
330.42578	0.92328298	0.26801872	2958.4204
331.42676	0.9221409	0.2693814	2961.7561
332.42773	0.92590964	0.27077004	2960.3586
333.42871	0.92949337	0.2719532	2955.8081
334.42969	0.93122202	0.27348015	2962.2798
335.43066	0.93562317	0.27514368	2967.7808
336.43164	0.93901002	0.27659687	2966.9182
337.43262	0.94224811	0.27807567	2964.1252
338.43359	0.94554532	0.27972278	2971.429
339.43457	0.94860208	0.28134581	2970.8948
340.43555	0.95214337	0.28291544	2973.6033
341.43652	0.95303345	0.28454882	2970.4453
342.4375	0.95429617	0.28610358	2968.2964
343.43848	0.95975006	0.28758198	2975.5974
344.43945	0.9651022	0.28926212	2978.2583
345.44043	0.96354437	0.29072738	2972.7224
346.44141	0.96934831	0.29228213	2975.8271
347.44238	0.97368187	0.29408824	2979.481
348.44336	0.97724098	0.29578298	2982.7942
349.44434	0.97928107	0.29700479	2976.0747
350.44531	0.97944868	0.29816532	2974.4104
351.44629	0.98370588	0.29971799	2988.0781
352.44727	0.98615921	0.30132067	2982.1233
353.44824	0.98635095	0.30287945	2982.3689
354.44922	0.99253923	0.30431008	2983.8411
355.4502	0.99828637	0.30582863	2986.606
356.45117	0.99803108	0.30715469	2985.4224
357.45215	1.005064	0.30857977	2989.1099
358.45313	1.0061649	0.30998191	2991.5471
359.4541	1.0061902	0.31177184	2991.0298
360.45508	1.0126146	0.31351379	2993.1204
361.45605	1.0156142	0.31509233	2996.8477
362.45703	1.0132684	0.31667534	2993.1169
363.45801	1.0189112	0.31807035	2990.0781
364.45898	1.0242597	0.31961676	2998.6841
365.45996	1.0268	0.32127213	2996.8757
366.46094	1.0278507	0.32240853	2992.2576
367.46191	1.0303563	0.3238436	2994.189
368.46289	1.0333246	0.32541439	3001.7417
369.46387	1.0359961	0.3270348	2998.8752
370.46484	1.0414207	0.32858595	3002.3984
371.46582	1.0406128	0.32998547	2993.8025
372.4668	1.0475078	0.33149672	3006.8486
373.46777	1.0493946	0.33290204	3000.3723
374.46875	1.0533676	0.33427376	3010.7219
375.46973	1.0574582	0.33572346	3007.2007
376.4707	1.0621608	0.33740255	3013.1907
377.47168	1.0602686	0.3387053	3002.1812
378.47266	1.0638685	0.34031931	3011.7217
379.47363	1.0686808	0.34180447	3010.2764
380.47461	1.0704859	0.34323722	3000.0134
381.47559	1.0726187	0.34462443	3006.6887
382.47656	1.07664	0.34588546	3011.4236
383.47754	1.0806782	0.34756577	3013.1318
384.47852	1.0839062	0.34921908	3017.4016
385.47949	1.0836869	0.35074618	3012.6086
386.48047	1.0867209	0.35224566	3013.3855
387.48145	1.0925378	0.35414165	3017.0637
388.48242	1.0982101	0.35579577	3021.2429
389.4834	1.0996476	0.35721955	3016.6021
390.48438	1.1001246	0.35847729	3016.1772
391.48535	1.1048541	0.35970867	3020.8684
392.48633	1.1047602	0.36118925	3019.8516
393.4873	1.1081243	0.36259726	3023.9165
394.48828	1.1124587	0.3641327	3025.5725
395.48926	1.1139792	0.36552295	3024.5605
396.49023	1.1162814	0.3670308	3023.9944
397.49121	1.1245121	0.36880079	3030.7456
398.49219	1.1262524	0.36992407	3022.2949
399.49316	1.1279212	0.37121242	3024.0332
400.49414	1.1306987	0.3727237	3028.0278
401.49512	1.1351434	0.37402487	3025.1663
402.49609	1.1348433	0.37535504	3025.8721
403.49707	1.1375573	0.37668306	3027.2971
404.49805	1.1451989	0.37840393	3035.2295
405.49902	1.1431658	0.37986588	3032.0566
406.5	1.1476415	0.38133213	3032.8989
407.50098	1.1533815	0.38295355	3035.8948
408.50195	1.1550919	0.38442874	3030.8435
409.50293	1.1562836	0.38562587	3026.1907
410.50391	1.1588725	0.38674486	3028.1145
411.50488	1.1628622	0.38821891	3036.7041
412.50586	1.1677099	0.38980421	3039.4622
413.50684	1.1714232	0.39104879	3038.7156
414.50781	1.1733152	0.39261568	3047.4434
415.50879	1.1762307	0.39411297	3043.0313
416.50977	1.1797349	0.39578804	3046.1328
417.51074	1.1829351	0.39749673	3047.6799
418.51172	1.1862938	0.39912614	3047.2058
419.5127	1.1866065	0.4006151	3041.604
420.51367	1.1917194	0.40202639	3043.4011
421.51465	1.1915319	0.40334266	3038.7695
422.51563	1.1961863	0.40491179	3049.0227
423.5166	1.199261	0.40655872	3048.4338
424.51758	1.2048588	0.40810829	3046.6399
425.51855	1.2094444	0.40947986	3048.1992
426.51953	1.2126175	0.4107331	3056.6016
427.52051	1.2104807	0.41213441	3050.8652
428.52148	1.2131356	0.41369298	3055.9165
429.52246	1.2159166	0.41530541	3049.4634
430.52344	1.2203381	0.41660163	3051.2161
431.52441	1.2241033	0.41823211	3058.9402
432.52539	1.2279388	0.41982034	3061.4006
433.52637	1.2303338	0.42127848	3058.9722
434.52734	1.2361407	0.42265463	3058.3572
435.52832	1.2388167	0.42401919	3058.4717
436.5293	1.2404712	0.42557701	3066.6526
437.53027	1.2412535	0.42706966	3052.3091
438.53125	1.2455982	0.42828897	3058.658
439.53223	1.249252	0.43000481	3070.4443
440.5332	1.2508913	0.43143862	3062.6199
441.53418	1.2553647	0.4329063	3064.1514
442.53516	1.2580345	0.43421486	3062.9592
443.53613	1.2587001	0.43566015	3063.2451
444.53711	1.2604657	0.437141	3065.6145
445.53809	1.265353	0.43829945	3062.1697
446.53906	1.2704158	0.44012198	3069.7476
447.54004	1.2709693	0.44156164	3063.4961
448.54102	1.2776327	0.44292849	3071.2942
449.54199	1.2784936	0.44418961	3073.5894
450.54297	1.2803971	0.445645	3064.7625
451.54395	1.2858236	0.44701001	3075.5969
452.54492	1.2894284	0.44870555	3081.5378
453.5459	1.290637	0.45021567	3073.8235
454.54688	1.2929752	0.45183444	3076.9468
455.54785	1.297048	0.45325378	3069.6619
456.54883	1.2987645	0.4546721	3073.8638
457.5498	1.3026296	0.45601052	3081.4253
458.55078	1.3047531	0.45770749	3080.7463
459.55176	1.3059319	0.45919326	3079.6472
460.55273	1.3078741	0.46081856	3075.814
461.55371	1.3128343	0.46224877	3076.3572
462.55469	1.3169353	0.46364895	3080.4175
463.55566	1.3214951	0.46490675	3079.615
464.55664	1.3233211	0.46635449	3081.7139
465.55762	1.3270863	0.46749741	3081.1274
466.55859	1.3306868	0.46896806	3084.8831
467.55957	1.3311753	0.47064605	3085.7871
468.56055	1.3327082	0.47232118	3084.9905
469.56152	1.3371431	0.47357959	3076.4714
470.5625	1.3409243	0.47499797	3084.1943
471.56348	1.3452308	0.47653005	3091.7268
472.56445	1.3481939	0.47795415	3092.6199
473.56543	1.3493395	0.47925037	3086.2244
474.56641	1.3519839	0.48077929	3082.6812
475.56738	1.3554906	0.48227811	3087.8538
476.56836	1.3581839	0.48363712	3092.4768
477.56934	1.36183	0.48523659	3093.9392
478.57031	1.3649101	0.48655182	3086.9434
479.57129	1.370368	0.48808146	3096.8474
480.57227	1.3714507	0.48955306	3098.6067
481.57324	1.3761632	0.49107665	3093.9045
482.57422	1.3777747	0.49255317	3099.4734
483.5752	1.379598	0.49395797	3091.3748
484.57617	1.383705	0.49542618	3092.9626
485.57715	1.3879786	0.49697879	3102.4966
486.57813	1.3917667	0.49838433	3100.3386
487.5791	1.3932985	0.49971262	3104.8933
488.58008	1.3943849	0.50111699	3096.1423
489.58105	1.3984259	0.5026868	3109.8228
490.58203	1.4008412	0.5044257	3102.8252
491.58301	1.4031175	0.50614363	3104.2219
492.58398	1.4062148	0.507658	3101.9543
493.58496	1.4129139	0.50902826	3103.9263
494.58594	1.4157238	0.51045841	3105.2944
495.58691	1.4149262	0.51191849	3105.144
496.58789	1.4185578	0.51331133	3098.7959
497.58887	1.423519	0.51472992	3107.6096
498.58984	1.4241126	0.51642126	3104.9304
499.59082	1.4313687	0.51799059	3107.2422
500.5918	1.4331241	0.51954728	3110.6672
501.59277	1.4345424	0.52086765	3107.8779
502.59375	1.439188	0.52217567	3112.6907
503.59473	1.4396219	0.52345628	3105.573
504.5957	1.441743	0.52482897	3111.8154
505.59668	1.447479	0.52631831	3114.0781
506.59766	1.4463294	0.52770847	3116.7004
507.59863	1.4527467	0.52906591	3110.5032
508.59961	1.4583218	0.5304141	3121.4849
509.60059	1.4605757	0.53194147	3114.3196
510.60156	1.4594183	0.5333215	3114.7744
511.60254	1.4646404	0.53487259	3118.1785
512.60352	1.4693234	0.53652549	3122.4326
513.60449	1.4705304	0.53828782	3124.2939
514.60547	1.4723234	0.53969067	3121.1797
515.60645	1.4756856	0.54086989	3114.5535
516.60742	1.4788882	0.54234493	3120.7788
517.6084	1.4810935	0.54380625	3118.0032
518.60938	1.4850185	0.54522258	3120.4448
519.61035	1.4889147	0.54676169	3127.3491
520.61133	1.4927735	0.54812026	3121.165
521.6123	1.492851	0.54949093	3122.9568
522.61328	1.4975202	0.55080682	3125.1743
523.61426	1.5014553	0.552302	3124.6428
524.61523	1.503906	0.55370826	3122.6833
525.61621	1.5077831	0.55538934	3138.0251
526.61719	1.5127864	0.55732769	3134.1128
527.61816	1.5134081	0.55888367	3129.4431
528.61914	1.5168025	0.56049454	3129.3284
529.62012	1.5161433	0.56170058	3122.8271
530.62109	1.5224589	0.5632593	3133.4492
531.62207	1.524231	0.56452614	3128.4988
532.62305	1.5279275	0.56564331	3127.1548
533.62402	1.5316448	0.5673297	3136.7344
534.625	1.5327195	0.56891799	3136.2314
535.62598	1.5382627	0.57069951	3137.2454
536.62695	1.5346323	0.57227409	3130.7932
537.62793	1.5410222	0.5736385	3125.8728
538.62891	1.5452675	0.57496178	3138.1611
539.62988	1.5471888	0.57624936	3128.6956
540.63086	1.5511051	0.5777747	3136.8743
541.63184	1.5553507	0.57911754	3133.6377
542.63281	1.558308	0.58047843	3135.9282
543.63379	1.5601448	0.58195746	3139.385
544.63477	1.5649431	0.58373553	3137.1526
545.63574	1.5661342	0.5850668	3140.0483
546.63672	1.5681951	0.58664978	3139.8284
547.6377	1.5749569	0.58820963	3140.8191
548.63867	1.575053	0.58971375	3144.2947
549.63965	1.5768224	0.59132236	3139.4067
550.64063	1.5842865	0.59266794	3145.0625
551.6416	1.5835483	0.59420919	3146.5659
552.64258	1.5881748	0.5957846	3146.3223
553.64355	1.5914779	0.5971362	3138.7822
554.64453	1.5922644	0.59863156	3143.95
555.64551	1.5979837	0.60015696	3153.6978
556.64648	1.6010365	0.6015659	3145.8589
557.64746	1.6043249	0.6030373	3146.4121
558.64844	1.6043853	0.60441935	3145.4309
559.64941	1.6081994	0.60585922	3148.2976
560.65039	1.6124314	0.60732061	3150.2949
561.65137	1.6133628	0.60908407	3153.1152
562.65234	1.616195	0.61077577	3155.1265
563.65332	1.623544	0.61222905	3150.7744
564.6543	1.6234865	0.61374354	3156.0195
565.65527	1.6230178	0.61515921	3148.6399
566.65625	1.6312435	0.61669868	3153.4385
567.65723	1.6341026	0.61798298	3156.7231
568.6582	1.6365985	0.61963934	3154.0305
569.65918	1.6412027	0.62109572	3159.8381
570.66016	1.6415591	0.62248665	3157.9836
571.66113	1.6441814	0.62412733	3156.022
572.66211	1.6481014	0.62589043	3156.6414
573.66309	1.6502053	0.62745583	3153.7417
574.66406	1.6567019	0.62876582	3157.8987
575.66504	1.6541153	0.63025784	3159.2517
576.66602	1.660482	0.63164991	3159.6377
577.66699	1.6629579	0.63325465	3158.365
578.66797	1.6642728	0.63458723	3159.5078
579.66895	1.6700293	0.63602424	3158.0498
580.66992	1.6724946	0.63711745	3157.7778
581.6709	1.6764479	0.638349	3162.8481
582.67188	1.6763706	0.64005852	3168.8608
583.67285	1.6789858	0.64147425	3162.9219
584.67383	1.6820556	0.64340806	3167.0989
585.6748	1.6902331	0.64505494	3165.9763
586.67578	1.6907736	0.64668155	3169.041
587.67676	1.6940416	0.64798075	3158.637
588.67773	1.696691	0.64928877	3162.4294
589.67871	1.6982453	0.65048838	3159.3198
590.67969	1.7030841	0.6519767	3168.2859
591.68066	1.7047055	0.65353721	3161.9133
592.68164	1.7083496	0.65504479	3166.728
593.68262	1.7109344	0.65647429	3166.2185
594.68359	1.7146508	0.658059	3172.9385
595.68457	1.7163039	0.659688	3174.5686
596.68555	1.7204118	0.66153997	3174.6731
597.68652	1.7204145	0.66302174	3171.3301
598.6875	1.7248497	0.66444933	3165.6233
599.68848	1.7300938	0.66608	3167.9111
600.68945	1.7333831	0.66756594	3170.3596
601.69043	1.7318612	0.66885185	3171.7632
602.69141	1.7412362	0.67034954	3174.0144
603.69238	1.7399725	0.67202801	3174.8374
604.69336	1.7443295	0.67327899	3175.2925
605.69434	1.7444748	0.67471719	3168.5957
606.69531	1.7466525	0.67621017	3176.5771
607.69629	1.7522242	0.67800242	3181.1802
608.69727	1.7578802	0.67951125	3175.5315
609.69824	1.7572057	0.68105757	3175.7698
610.69922	1.7590505	0.68271834	3179.3301
611.7002	1.7633544	0.68444437	3183.7234
612.70117	1.7668662	0.68619609	3173.3965
613.70215	1.768181	0.68766558	3174.4963
614.70313	1.7753932	0.68936443	3183.8586
615.7041	1.7762796	0.6906091	3174.7095
616.70508	1.7806158	0.69210255	3179.123
617.70605	1.7816896	0.69351172	3178.3354
618.70703	1.7852421	0.69501126	3180.4846
619.70801	1.7888987	0.69647199	3176.1838
620.70898	1.7916545	0.69786841	3177.1123
621.70996	1.7956409	0.69937831	3179.8748
622.71094	1.799718	0.70083278	3187.6719
623.71191	1.8023525	0.70227432	3186.5237
624.71289	1.8053861	0.70375359	3185.6147
625.71387	1.8093848	0.70532674	3183.8599
626.71484	1.8083817	0.70674688	3183.5405
627.71582	1.8137009	0.70858181	3192.7659
628.7168	1.8131759	0.71038628	3190.8965
629.71777	1.8213699	0.71181393	3186.4573
630.71875	1.8205367	0.71314168	3178.2542
631.71973	1.8249931	0.71466953	3192.9854
632.7207	1.828721	0.71614951	3193.2405
633.72168	1.8317859	0.7178756	3191.916
634.72266	1.8333386	0.71936715	3184.1743
635.72363	1.8381875	0.7210663	3192.1272
636.72461	1.8398898	0.72271001	3194.2817
637.72559	1.8412843	0.7242704	3190.7295
638.72656	1.844594	0.72592902	3193.2424
639.72754	1.849323	0.72762716	3198.5088
640.72852	1.8498342	0.72939473	3189.865
641.72949	1.8569567	0.73108739	3196.6672
642.73047	1.8563458	0.73289639	3195.8064
643.73145	1.8608091	0.73435152	3191.1423
644.73242	1.8629996	0.73560232	3189.2803
645.7334	1.8658494	0.73723704	3192.9675
646.73438	1.8685921	0.7387026	3190.248
647.73535	1.8772573	0.7402786	3198.3413
648.73633	1.877345	0.7418353	3202.6621
649.7373	1.8785055	0.74340719	3191.3621
650.73828	1.880989	0.74484211	3191.7825
651.73926	1.8833536	0.74637079	3193.1885
652.74023	1.8887765	0.74788779	3199.6709
653.74121	1.8920653	0.74923635	3197.9465
654.74219	1.8954731	0.75074202	3199.0071
655.74316	1.8975825	0.75212216	3198.824
656.74414	1.9021506	0.75372815	3203.5715
657.74512	1.9017581	0.75521779	3204.0974
658.74609	1.9079611	0.75692677	3202.0522
659.74707	1.9102434	0.75869536	3202.5864
660.74805	1.9101237	0.76033789	3200.1218
661.74902	1.9146717	0.76210958	3204.3953
662.75	1.9190526	0.76377463	3203.3057
663.75098	1.9239063	0.76566523	3208.1545
664.75195	1.9243313	0.76707256	3198.7959
665.75293	1.9261482	0.76866221	3205.3669
666.75391	1.9273328	0.77030718	3199.5874
667.75488	1.9343917	0.7719118	3202.0754
668.75586	1.9371563	0.77355498	3208.499
669.75684	1.9386165	0.77506256	3207.3005
670.75781	1.9423125	0.77677828	3203.5894
671.75879	1.9465579	0.7784217	3212.4626
672.75977	1.9453754	0.78015238	3209.5999
673.76074	1.9521327	0.78205442	3212.1504
674.76172	1.953941	0.78353727	3208.677
675.7627	1.9562615	0.78519118	3205.8516
676.76367	1.9574232	0.78661036	3204.9856
677.76465	1.9638846	0.7882812	3212.5867
678.76563	1.9645813	0.78988963	3211.9824
679.7666	1.9688262	0.79136175	3205.2432
680.76758	1.9708329	0.79288393	3207.4077
681.76855	1.9750853	0.79444098	3203.7974
682.76953	1.97993	0.79601359	3213.7363
683.77051	1.983104	0.7975623	3214.4175
684.77148	1.9829167	0.79937679	3214.7502
685.77246	1.9898108	0.80118698	3217.3154
686.77344	1.991518	0.80282968	3211.6375
687.77441	1.994271	0.8043558	3212.7734
688.77539	1.9951326	0.80586487	3210.6785
689.77637	2.0007448	0.80773497	3217.124
690.77734	2.0015242	0.80950612	3211.937
691.77832	2.0059626	0.81114459	3211.543
692.7793	2.0069416	0.81264067	3217.2412
693.78027	2.0107238	0.81437457	3213.5286
694.78125	2.0136206	0.81634682	3212.3782
695.78223	2.0180657	0.81751043	3210.2314
696.7832	2.0193706	0.81895936	3215.6563
697.78418	2.0230539	0.82071549	3214.6387
698.78516	2.0279438	0.82221419	3217.3735
699.78613	2.0294011	0.82364875	3214.7761
700.78711	2.0330482	0.82550299	3220.636
701.78809	2.034662	0.82733452	3214.198
702.78906	2.0369291	0.82890737	3211.6387
703.79004	2.0412824	0.83046836	3211.4543
704.79102	2.0451918	0.83206743	3218.2129
705.79199	2.0497954	0.83413136	3225.9629
706.79297	2.0513246	0.83592123	3223.6455
707.79395	2.0552323	0.83797556	3222.5867
708.79492	2.0561376	0.83983094	3224.6875
709.7959	2.0590153	0.84158123	3221.5322
710.79688	2.06214	0.84322578	3217.1189
711.79785	2.0653617	0.84480911	3223.1653
712.79883	2.0690885	0.84647411	3218.4294
713.7998	2.0673466	0.84788263	3218.686
714.80078	2.0724957	0.84950417	3210.0093
715.80176	2.0766435	0.85137999	3221.7695
716.80273	2.0775633	0.85277545	3213.0496
717.80371	2.0827122	0.85443789	3221.7458
718.80469	2.0873911	0.85625714	3225.5405
719.80566	2.0899825	0.85812712	3223.9014
720.80664	2.0906556	0.86006361	3232.782
721.80762	2.0929897	0.86203843	3221.3679
722.80859	2.0994096	0.86368346	3218.2209
723.80957	2.1026409	0.86475277	3214.4731
724.81055	2.0990407	0.86603355	3216.2507
725.81152	2.1052489	0.86745077	3225.9961
726.8125	2.1074631	0.86901867	3222.0232
727.81348	2.1130826	0.87062258	3225.5701
728.81445	2.1171632	0.8722682	3225.9866
729.81543	2.1212752	0.87408173	3226.0283
730.81641	2.1212273	0.87568134	3220.4438
731.81738	2.1272948	0.87748277	3231.239
732.81836	2.1274805	0.87954533	3226.3364
733.81934	2.1330898	0.88137841	3231.458
734.82031	2.1335254	0.88304943	3224.3599
735.82129	2.1365223	0.88472229	3226.8333
736.82227	2.1375899	0.88640088	3221.1943
737.82324	2.1443653	0.88813341	3228.4773
738.82422	2.1467204	0.88997233	3230.2349
739.8252	2.1480949	0.89171499	3223.3462
740.82617	2.1531682	0.89354295	3235.0322
741.82715	2.1583016	0.89528131	3227.46
742.82813	2.1602304	0.89694196	3230.0701
743.8291	2.1599929	0.8986252	3224.6172
744.83008	2.1629307	0.90023696	3224.1387
745.83105	2.1656394	0.90203947	3228.2234
746.83203	2.1716568	0.90365529	3229.3533
747.83301	2.1711552	0.90538526	3227.1611
748.83398	2.1740305	0.90725762	3228.679
749.83496	2.1806786	0.90919179	3233.5068
750.83594	2.1830347	0.91100872	3227.4304
751.83691	2.1878455	0.91251326	3232.377
752.83789	2.1879416	0.91416395	3229.6409
753.83887	2.1901796	0.91607583	3227.7759
754.83984	2.1947253	0.91810846	3235.1199
755.84082	2.1995165	0.91996902	3233.0127
756.8418	2.2003696	0.92168087	3232.9644
757.84277	2.20017	0.92350727	3229.9668
758.84375	2.2077179	0.92522889	3233.7725
759.84473	2.21031	0.92676753	3229.0103
760.8457	2.2099581	0.92864209	3232.0459
761.84668	2.2149398	0.93039101	3236.646
762.84766	2.2188215	0.93212044	3233.0715
763.84863	2.2213032	0.934232	3239.5964
764.84961	2.2266638	0.93637991	3245.5623
765.85059	2.22787	0.93814915	3230.6931
766.85156	2.2315061	0.93975085	3231.6877
767.85254	2.2322004	0.94132304	3227.5952
768.85352	2.2374265	0.9432115	3238.0388
769.85449	2.2393856	0.9450469	3232.1001
770.85547	2.2407882	0.9471668	3234.8843
771.85645	2.2450156	0.94908828	3228.8108
772.85742	2.2474222	0.95078224	3233.9983
773.8584	2.2508705	0.95236593	3230.4878
774.85938	2.2546704	0.95387971	3231.9373
775.86035	2.2576611	0.95595592	3241.2888
776.86133	2.2612987	0.95803148	3242.427
777.8623	2.2635832	0.96023345	3242.8818
778.86328	2.2666287	0.96213448	3232.2671
779.86426	2.2699273	0.96360195	3230.8066
780.86523	2.2698662	0.96542537	3236.427
781.86621	2.2750537	0.96732491	3235.0806
782.86719	2.278754	0.96926528	3231.0886
783.86816	2.2839382	0.97110015	3236.8818
784.86914	2.2830715	0.97296429	3235.5608
785.87012	2.2885807	0.97488195	3240.6965
786.87109	2.2922306	0.97660106	3234.6184
787.87207	2.290535	0.97819537	3237.0989
788.87305	2.2983	0.98002738	3236.876
789.87402	2.2994528	0.98188502	3230.6951
790.875	2.3030376	0.98346877	3235.0505
791.87598	2.3063183	0.985237	3236.5383
792.87695	2.3068137	0.98724729	3236.3167
793.87793	2.3113518	0.98895693	3239.0439
794.87891	2.3149889	0.99097812	3235.2344
795.87988	2.3173954	0.99276876	3236.3931
796.88086	2.3200877	0.99474555	3239.4109
797.88184	2.3212404	0.99656433	3236.8062
798.88281	2.3253591	0.99864978	3238.0925
799.88379	2.3295736	1.0007143	3233.7864
800.88477	2.331768	1.00286	3239.2717
801.88574	2.3341155	1.004624	3228.3354
802.88672	2.3386583	1.0062468	3235.9771
803.8877	2.3399434	1.0081974	3238.7927
804.88867	2.3418026	1.0100687	3241.1055
805.88965	2.3467426	1.0119145	3236.2051
806.89063	2.3500767	1.0140181	3238.5288
807.8916	2.3552835	1.0159925	3239.78
808.89258	2.3536165	1.0177711	3233.3232
809.89355	2.3610401	1.0194788	3240.3076
810.89453	2.3608332	1.0212661	3234.5181
811.89551	2.3654766	1.0231814	3242.3276
812.89648	2.3696408	1.0251402	3237.656
813.89746	2.3706658	1.026947	3236.7729
814.89844	2.37343	1.0289388	3240.6604
815.89941	2.3789377	1.0311809	3239.2969
816.90039	2.3795841	1.0333066	3240.3237
817.90137	2.3814797	1.0352889	3238.6897
818.90234	2.3856931	1.0368961	3233.3696
819.90332	2.3882155	1.0383729	3230.324
820.9043	2.3927355	1.0403475	3243.2817
821.90527	2.3995316	1.0423937	3250.0996
822.90625	2.3984931	1.0442829	3240.5322
823.90723	2.4035914	1.0463011	3234.6794
824.9082	2.4069784	1.0484537	3248.97
825.90918	2.4066579	1.0509039	3243.1951
826.91016	2.4101944	1.0529001	3243.2205
827.91113	2.4140651	1.0550264	3244.9956
828.91211	2.4175475	1.0571294	3244.8877
829.91309	2.4192624	1.0593156	3233.5242
830.91406	2.4245095	1.0614535	3244.3948
831.91504	2.4259539	1.0634029	3241.9043
832.91602	2.4285452	1.0650254	3234.0928
833.91699	2.4307384	1.0665506	3239.7129
834.91797	2.435622	1.0683118	3239.397
835.91895	2.4381063	1.0704046	3242.6121
836.91992	2.4405959	1.0726657	3237.3618
837.9209	2.4434876	1.0746214	3240.1384
838.92188	2.448056	1.0767832	3239.8816
839.92285	2.4479878	1.079064	3242.1526
840.92383	2.4538386	1.0811787	3235.9868
841.9248	2.4550743	1.0833951	3242.8408
842.92578	2.4596038	1.0856187	3240.1934
843.92676	2.4630094	1.087894	3242.2141
844.92773	2.4633038	1.0897367	3237.7776
845.92871	2.467674	1.0916144	3236.6714
846.92969	2.4725704	1.0933999	3239.9551
847.93066	2.4738624	1.0954466	3239.7012
848.93164	2.4777968	1.0978186	3243.0071
849.93262	2.4818137	1.0999333	3237.5469
850.93359	2.4819343	1.101939	3241.1687
851.93457	2.4883342	1.1038167	3235.7842
852.93555	2.4882281	1.105996	3240.9075
853.93652	2.4908698	1.1084824	3241.8313
854.9375	2.4942279	1.1110047	3240.1775
855.93848	2.4994049	1.1131347	3239.1755
856.93945	2.5027206	1.1148655	3232.5049
857.94043	2.5048032	1.116689	3236.7
858.94141	2.5078127	1.1186736	3240.6992
859.94238	2.5075524	1.1207217	3237.0884
860.94336	2.5130336	1.1232307	3242.2979
861.94434	2.5165102	1.1255323	3239.354
862.94531	2.5162401	1.1276728	3236.825
863.94629	2.5219035	1.1297084	3237.9895
864.94727	2.5226095	1.1317896	3233.7146
865.94824	2.528214	1.1338205	3229.8862
866.94922	2.532068	1.135465	3232.448
867.9502	2.5315082	1.1370193	3229.334
868.95117	2.5359643	1.1387887	3235.4604
869.95215	2.5365145	1.1413188	3235.0999
870.95313	2.5446415	1.1434951	3237.1594
871.9541	2.5453162	1.1455452	3235.6824
872.95508	2.5455718	1.1478688	3231.9978
873.95605	2.5533366	1.150131	3234.679
874.95703	2.5518541	1.1521227	3233.8315
875.95801	2.5561972	1.1541669	3233.7883
876.95898	2.5589845	1.1565431	3233.9583
877.95996	2.5654507	1.1586366	3232.1013
878.96094	2.5684347	1.1604836	3232.5889
879.96191	2.571734	1.1628548	3234.3777
880.96289	2.5715523	1.1652501	3232.7126
881.96387	2.5772762	1.1674402	3233.0811
882.96484	2.5787807	1.1694325	3228.1306
883.96582	2.5825384	1.1719128	3230.7976
884.9668	2.5847573	1.1741617	3232.8542
885.96777	2.588165	1.1763188	3229.7256
886.96875	2.5901189	1.1784903	3231.2825
887.96973	2.5944006	1.1808983	3232.0413
888.9707	2.5937145	1.1829954	3231.6985
889.97168	2.6012168	1.1860251	3239.9104
890.97266	2.6021061	1.188616	3230.1458
891.97363	2.6063671	1.1904769	3226.9426
892.97461	2.6120024	1.1926708	3228.5295
893.97559	2.612767	1.1946914	3231.7261
894.97656	2.6154501	1.1972229	3232.8958
895.97754	2.6171134	1.1994325	3227.5906
896.97852	2.6237907	1.2016722	3235.9773
897.97949	2.6212091	1.2040997	3227.3503
898.98047	2.6260586	1.2060467	3220.7905
899.98145	2.6296082	1.2081127	3225.658
900.98242	2.6352441	1.2101495	3226.8215
901.9834	2.6353955	1.2123569	3226.3672
902.98438	2.6371951	1.2144535	3223.0056
903.98535	2.6400864	1.2171954	3232.8052
904.98633	2.6433196	1.219653	3221.6384
905.9873	2.6493888	1.2215827	3225.8352
906.98828	2.6526995	1.2238417	3232.2285
907.98926	2.6550486	1.2266071	3222.9026
908.99023	2.6580703	1.2287318	3224.0928
909.99121	2.6608677	1.2305676	3217.582
910.99219	2.6602633	1.2326978	3225.0459
911.99316	2.6644433	1.234971	3223.8201
912.99414	2.6670585	1.2376453	3229.9548
913.99512	2.6726613	1.2402816	3222.1628
914.99609	2.6736503	1.2425699	3216.7405
915.99707	2.6789243	1.2446896	3223.6816
916.99805	2.6826603	1.2467695	3215.9861
917.99902	2.68606	1.2492884	3219.2769
919	2.6888549	1.2518637	3227.4688
920.00098	2.6920745	1.2543455	3220.0129
921.00195	2.6936471	1.2566767	3210.1611
922.00293	2.6950605	1.2586898	3214.5354
923.00391	2.6964257	1.2610639	3214.9861
924.00488	2.7006853	1.263698	3223.3694
925.00586	2.7024755	1.2663668	3213.8289
926.00684	2.7074594	1.2687641	3207.7197
927.00781	2.7129388	1.2710984	3218.2791
928.00879	2.7133164	1.2735651	3217.1592
929.00977	2.718852	1.2764027	3216.635
930.01074	2.7167971	1.2789912	3208.793
931.01172	2.7238572	1.2813946	3208.7759
932.0127	2.7244785	1.2838293	3208.2534
933.01367	2.7298381	1.2864728	3212.3711
934.01465	2.7336376	1.2890019	3213.2952
935.01563	2.7328861	1.2910085	3203.677
936.0166	2.7382708	1.2929789	3201.2842
937.01758	2.743084	1.2948365	3207.9075
938.01855	2.7430155	1.2969347	3206.4668
939.01953	2.7475893	1.299587	3204.3062
940.02051	2.7491856	1.3020726	3201.5835
941.02148	2.7529871	1.3044981	3203.7607
942.02246	2.755331	1.3069252	3199.3276
943.02344	2.7580879	1.30969	3201.1123
944.02441	2.7627389	1.3123662	3199.6204
945.02539	2.7650445	1.3143102	3196.4863
946.02637	2.7686291	1.3161587	3196.6208
947.02734	2.7704422	1.3185633	3197.4075
948.02832	2.7720368	1.3209549	3198.8806
949.0293	2.7733529	1.3235304	3195.6797
950.03027	2.7766581	1.3265245	3200.3022
951.03125	2.7842238	1.3291382	3189.4204
952.03223	2.7856741	1.3316482	3196.0784
953.0332	2.7883143	1.3339818	3194.7942
954.03418	2.7904751	1.3369747	3193.0938
955.03516	2.7939637	1.3394114	3185.866
956.03613	2.7962654	1.3415133	3185.8718
957.03711	2.8023267	1.3442955	3193.2124
958.03809	2.805325	1.3470076	3193.2119
959.03906	2.8068988	1.3498455	3192.647
960.04004	2.8089001	1.3528496	3178.9116
961.04102	2.8162084	1.3553069	3182.4229
962.04199	2.81516	1.3573761	3184.0293
963.04297	2.8210304	1.3599048	3180.5085
964.04395	2.821667	1.3617886	3177.3567
965.04492	2.8228102	1.3640413	3180.8096
966.0459	2.8317816	1.3665277	3184.9126
967.04688	2.8327565	1.3690635	3180.0168
968.04785	2.8329575	1.3716055	3174.5225
969.04883	2.8384409	1.3744961	3182.3804
970.0498	2.8414159	1.3771623	3171.95
971.05078	2.844346	1.3795528	3174.5229
972.05176	2.845413	1.3819588	3165.9502
973.05273	2.8490567	1.3842325	3167.75
974.05371	2.851306	1.3865801	3167.2888
975.05469	2.8592122	1.3893983	3166.2688
976.05566	2.8591466	1.3917882	3165.437
977.05664	2.8585639	1.3941677	3160.4727
978.05762	2.8638835	1.3967534	3166.1047
979.05859	2.8655045	1.399173	3156.9021
980.05957	2.8678894	1.4020486	3159.8975
981.06055	2.8744411	1.4047155	3161.6313
982.06152	2.8746526	1.4068021	3157.0608
983.0625	2.8776128	1.4094517	3154.2805
984.06348	2.8839381	1.4119838	3160.5007
985.06445	2.8843589	1.4143426	3150.5337
986.06543	2.8874643	1.4172904	3154.4465
987.06641	2.8905246	1.4198862	3143.6272
988.06738	2.8925231	1.4221483	3147.3765
989.06836	2.8933861	1.4247589	3143.1201
990.06934	2.8997583	1.4272854	3150.1565
991.07031	2.9025004	1.4300791	3148.0623
992.07129	2.9041247	1.4331774	3142.9927
993.07227	2.9105318	1.436287	3141.9131
994.07324	2.9102521	1.4389474	3136.752
995.07422	2.9145873	1.4416351	3136.2432
996.0752	2.9184313	1.4442562	3130.7058
997.07617	2.920321	1.4466408	3128.4338
998.07715	2.9230857	1.4490609	3130.4414
999.07813	2.9284096	1.4514548	3129.7249
1000.0791	2.9298131	1.4539684	3133.9731
1001.0801	2.9322531	1.4571023	3129.166
1002.0811	2.9360566	1.4599013	3123.356
1003.082	2.9394641	1.4624964	3124.0427
1004.083	2.9375255	1.465162	3122.458
1005.084	2.9475255	1.4681389	3122.3242
1006.085	2.948992	1.4707457	3120.1663
1007.0859	2.950186	1.473402	3111.3997
1008.0869	2.9514618	1.4755734	3107.2178
1009.0879	2.9599228	1.4777819	3113.3328
1010.0889	2.9603825	1.4801816	3107.3228
1011.0898	2.9643207	1.4820933	3106.6213
1012.0908	2.9656389	1.4848878	3113.4063
1013.0918	2.9692566	1.4879146	3106.3074
1014.0928	2.9696515	1.4906809	3101.5779
1015.0938	2.9738283	1.4934748	3099.2886
1016.0947	2.9806728	1.4961233	3100.7842
1017.0957	2.9816458	1.498505	3091.627
1018.0967	2.9837258	1.5008912	3097.3198
1019.0977	2.9860191	1.5033979	3091.6714
1020.0986	2.987906	1.5052103	3079.3271
1021.0996	2.9954257	1.507044	3089.1584
1022.1006	2.994765	1.5091553	3082.5129
1023.1016	2.9985712	1.5111861	3077.9438
1024.1025	3.0030589	1.5136485	3089.1575
1025.1035	3.006608	1.5162585	3085.1262
1026.1045	3.0070825	1.5187604	3083.3687
1027.1055	3.0122411	1.522038	3083.2971
1028.1064	3.0157783	1.5251092	3076.6128
1029.1074	3.016645	1.5279738	3070.7595
1030.1084	3.0196836	1.5306481	3071.3577
1031.1094	3.0264301	1.5339216	3072.1384
1032.1104	3.027339	1.5367515	3067.7236
1033.1113	3.0295908	1.5393796	3065.9229
1034.1123	3.0299337	1.5420612	3059.571
1035.1133	3.0351911	1.5440905	3059.0596
1036.1143	3.0411024	1.5466883	3059.8872
1037.1152	3.0412347	1.5496895	3056.9351
1038.1162	3.0454702	1.553122	3051.3357
1039.1172	3.0471296	1.5559466	3050.7678
1040.1182	3.049994	1.558441	3040.8152
1041.1191	3.057493	1.561312	3049.7346
1042.1201	3.0552619	1.5642382	3040.7002
1043.1211	3.0593734	1.5668826	3034.4565
1044.1221	3.0634007	1.5694848	3039.5544
1045.123	3.0669816	1.5720341	3039.345
1046.124	3.0692418	1.5748339	3034.7349
1047.125	3.0676703	1.577635	3023.8604
1048.126	3.0741558	1.5804474	3026.8091
1049.127	3.0767784	1.5837868	3027.7544
1050.1279	3.078301	1.586955	3017.1128
1051.1289	3.0854445	1.5897814	3016.7217
1052.1299	3.0885446	1.5927738	3024.4412
1053.1309	3.0890384	1.5956455	3014.6836
1054.1318	3.0918508	1.5985593	3014.9736
1055.1328	3.0956931	1.6015927	3002.958
1056.1338	3.0991685	1.6042753	3003.2263
1057.1348	3.1009645	1.6070139	2998.3767
1058.1357	3.1042211	1.6095866	2993.4885
1059.1367	3.1072659	1.6122303	2996.7732
1060.1377	3.1101296	1.615032	2989.9343
1061.1387	3.1139672	1.6178908	2988.9878
1062.1396	3.1134579	1.6205858	2987.9497
1063.1406	3.1206129	1.623082	2986.8906
1064.1416	3.1215949	1.6261489	2984.116
1065.1426	3.1252165	1.6299829	2984.1951
1066.1436	3.1309185	1.63336	2978.4763
1067.1445	3.1311975	1.6364734	2975.178
1068.1455	3.1331935	1.6393386	2965.5469
1069.1465	3.1413596	1.6427648	2974.1001
1070.1475	3.1409647	1.6460921	2961.9409
1071.1484	3.1438725	1.6488551	2954.2905
1072.1494	3.149157	1.6511917	2956.7188
1073.1504	3.1511884	1.6539842	2953.4358
1074.1514	3.1504989	1.6569525	2949.3701
1075.1523	3.1536717	1.6598213	2945.0039
1076.1533	3.1607523	1.6629215	2949.6609
1077.1543	3.16117	1.6657228	2941.5923
1078.1553	3.1653316	1.668575	2927.8877
1079.1563	3.1683795	1.6716787	2935.9485
1080.1572	3.1710315	1.6747983	2927.2612
1081.1582	3.1726072	1.6775571	2927.5652
1082.1592	3.1751246	1.6801434	2915.3801
1083.1602	3.1810641	1.6827968	2916.2292
1084.1611	3.183495	1.6859044	2919.4917
1085.1621	3.1831381	1.6892949	2912.1252
1086.1631	3.1896822	1.6927915	2907.4919
1087.1641	3.1911778	1.696367	2903.4695
1088.165	3.1939154	1.6999675	2897.0732
1089.166	3.1962318	1.7031739	2893.4641
1090.167	3.2001626	1.7058158	2886.1626
1091.168	3.2044303	1.7085562	2887.2761
1092.1689	3.2068832	1.7117218	2880.6145
1093.1699	3.2103066	1.7149203	2882.4954
1094.1709	3.2142019	1.7184149	2878.5583
1095.1719	3.2160988	1.7220725	2870.3833
1096.1729	3.2189147	1.7250545	2859.4111
1097.1738	3.2212353	1.7285062	2862.5217
1098.1748	3.2249732	1.7315044	2853.6211
1099.1758	3.2285244	1.7343539	2852.72
1100.1768	3.2322764	1.7375613	2847.6489
1101.1777	3.2312603	1.7407278	2841.6646
1102.1787	3.2371297	1.7439799	2839.4666
1103.1797	3.2446351	1.7470241	2832.6963
1104.1807	3.2454891	1.749944	2835.8962
1105.1816	3.2453942	1.7531106	2820.9797
1106.1826	3.2497587	1.7562429	2820.3613
1107.1836	3.253123	1.7595342	2811.6387
1108.1846	3.2546437	1.7629718	2808.3779
1109.1855	3.258816	1.7662143	2811.803
1110.1865	3.2596948	1.7695366	2805.2983
1111.1875	3.2665508	1.7730819	2800.1897
1112.1885	3.267127	1.7767729	2790.8423
1113.1895	3.2719629	1.7803113	2784.0989
1114.1904	3.2734244	1.783883	2784.8616
1115.1914	3.2760572	1.7871659	2778.239
1116.1924	3.2797341	1.7903806	2767.7131
1117.1934	3.2794371	1.7935078	2765.4404
1118.1943	3.2860522	1.7963663	2762.679
1119.1953	3.2873268	1.7993833	2754.709
1120.1963	3.2916234	1.8025129	2752.3127
1121.1973	3.2922912	1.805869	2743.9829
1122.1982	3.2962291	1.8094264	2735.7256
1123.1992	3.2982836	1.812806	2729.6938
1124.2002	3.3025711	1.8160793	2725.5525
1125.2012	3.3044188	1.8195732	2715.397
1126.2021	3.3092754	1.8223524	2712.7119
1127.2031	3.3128977	1.8259099	2712.821
1128.2041	3.3139887	1.8293574	2702.6619
1129.2051	3.3176343	1.8335621	2696.4297
1130.2061	3.3220782	1.8370016	2688.3855
1131.207	3.3230748	1.8405863	2681.3708
1132.208	3.3259792	1.8441721	2679.0955
1133.209	3.3304939	1.8468379	2668.8477
1134.21	3.3369608	1.8499572	2661.9282
1135.2109	3.3351064	1.8532554	2659.6665
1136.2119	3.3381782	1.8569034	2656.2866
1137.2129	3.3443372	1.8611547	2649.3315
1138.2139	3.3477774	1.865658	2632.4287
1139.2148	3.3503597	1.8691033	2626.0364
1140.2158	3.3504195	1.8728142	2619.0886
1141.2168	3.3526244	1.8771813	2607.2969
1142.2178	3.3583419	1.8815249	2589.9585
1143.2188	3.3585491	1.8860607	2579.3152
1144.2197	3.3622158	1.8900737	2563.3975
1145.2207	3.3681924	1.8959556	2542.2209
1145.8213	3.3688676	1.9014829	2494.5244