File: datasets/am_bench_2022/raw_data/0-XY.05-4/specimen.dat
MTS793|MPT|ENU|1|2|.|/|:|1|0|0|A

Operator Information						Time:	30.755615	Sec	10/13/2021 1:25:11 PM
Operator	Nick Derimow
Project	AM Bench 2022 mini-tensile challenge
Specimen ID	0-XY.05-4
Material	PBF-L Inconel 625
Specimen Width	2.57	mm
Specimen Thickness	1.51	mm
Notes
Operator Information End

Data Acquisition						Time:	1031.7493	Sec	10/13/2021 1:41:52 PM
Time	Axial Displacement	Axial Extensometer	Axial Force
Sec	mm	mm	N
30.869141	0.0045621842	0.00026125408	79.513092
31.77002	0.0084618228	-0.00057580642	90.216537
32.670898	0.0067977495	0.00036756688	104.96755
33.571777	0.012517998	0.0001322363	117.94225
34.472656	0.014219822	3.1991349e-05	126.90787
35.373535	0.016383829	0.00041438756	140.41904
36.274414	0.019099249	0.00036451811	151.43301
37.175293	0.023486529	0.00037059927	164.90424
38.076172	0.02869373	0.00062854984	180.89676
38.977051	0.02706039	0.00026422093	189.40468
39.87793	0.029058846	0.00044301903	205.4234
40.778809	0.032612268	0.00064079824	226.70361
41.679688	0.034880362	0.00074615108	240.60518
42.580566	0.037725274	0.00083703152	256.8309
43.481445	0.042878792	0.00085794268	278.04062
44.382324	0.04424398	0.00092229486	292.66455
45.283203	0.046720292	0.0010212428	307.92361
46.184082	0.050599236	0.0011080009	327.65771
47.084961	0.053521957	0.0010038363	345.40457
47.98584	0.055649288	0.0012496328	361.94562
48.886719	0.056041244	0.00083179859	376.57874
49.787598	0.061006367	0.0013139716	401.86707
50.688477	0.062940694	0.0011944156	419.46649
51.589355	0.066155992	0.0016331836	437.73856
52.490234	0.068032794	0.0013379193	465.53497
53.391113	0.070783406	0.0014716382	483.11716
54.291992	0.071603581	0.0014612871	496.78467
55.192871	0.075855225	0.0017542443	525.79327
56.09375	0.077833243	0.0016972775	543.82465
56.994629	0.079853624	0.0017860803	555.01251
57.895508	0.082571857	0.0021334731	579.58582
58.796387	0.084025562	0.0023085093	608.99335
59.697266	0.088026054	0.0022794157	627.11987
60.598145	0.092387058	0.0024600117	656.25006
61.499023	0.093499616	0.0024179528	674.47815
62.399902	0.096374184	0.0027180321	693.383
63.300781	0.10106844	0.002545984	717.05341
64.20166	0.10289909	0.0029755605	739.32037
65.102539	0.10519346	0.0030422648	769.54138
66.003418	0.10599986	0.0031403615	786.65228
66.904297	0.10813441	0.0032637734	815.01459
67.805176	0.1104986	0.0034806321	839.70685
68.706055	0.11717144	0.003536091	869.5437
69.606934	0.11757405	0.0037302435	884.80035
70.507813	0.12077583	0.0037282479	913.31366
71.408691	0.12340678	0.0040561594	938.17969
72.30957	0.1282209	0.0040177642	968.63715
73.210449	0.12764311	0.0042202147	993.25867
74.111328	0.13579699	0.0042097368	1015.7556
75.012207	0.13453451	0.0043297433	1031.0886
75.913086	0.13500597	0.0046665976	1058.5869
76.813965	0.14146367	0.0047015231	1083.5427
77.714844	0.14228216	0.0048684734	1105.1633
78.615723	0.14707717	0.0049601253	1128.5212
79.516602	0.14570706	0.0049202167	1147.8534
80.41748	0.14547476	0.005245653	1180.8027
81.318359	0.15212071	0.005275432	1200.5714
82.219238	0.15381168	0.0055556623	1228.83
83.120117	0.15932335	0.0055426476	1245.7156
84.020996	0.15963151	0.0057268264	1276.3013
84.921875	0.16068526	0.0059468471	1297.8627
85.822754	0.16339263	0.0059789252	1321.6981
86.723633	0.16854666	0.006152892	1343.7751
87.624512	0.17093216	0.0061676111	1372.5969
88.525391	0.17631352	0.0064989198	1403.4415
89.42627	0.1747226	0.006682836	1421.6356
90.327148	0.17649096	0.0066923634	1450.1389
91.228027	0.18085063	0.0069553256	1475.7076
92.128906	0.18469228	0.006962657	1501.7076
93.029785	0.18650982	0.0070576882	1519.5651
93.930664	0.19288453	0.0074000447	1548.6171
94.831543	0.19203055	0.0074574021	1571.9072
95.732422	0.19757465	0.0077604358	1600.7295
96.633301	0.19923078	0.0077711227	1610.6235
97.53418	0.20118989	0.0079649435	1642.1606
98.435059	0.20517866	0.0081027998	1662.2668
99.335938	0.20826043	0.0082655512	1681.4727
100.23682	0.21028265	0.0084575247	1704.5665
101.1377	0.21247007	0.0085777733	1728.5585
102.03857	0.21476664	0.008705792	1751.7529
102.93945	0.21826735	0.0089761019	1775.9493
103.84033	0.21912155	0.0089166388	1797.1877
104.74121	0.22188245	0.0091183232	1813.3895
105.64209	0.22390857	0.0092384247	1835.7415
106.54297	0.23094319	0.0095200241	1860.0905
107.44385	0.23028262	0.0096164644	1876.241
108.34473	0.23571059	0.0098248357	1906.1196
109.24561	0.23416777	0.010049722	1925.6196
110.14648	0.23668684	0.010189345	1942.1747
111.04736	0.2391564	0.010283471	1961.8333
111.94824	0.24502233	0.010419287	1981.1049
112.84912	0.246609	0.010627459	2000.3965
113.75	0.25064531	0.010896248	2022.8524
114.65088	0.25370672	0.011112262	2035.985
115.55176	0.25747955	0.011235523	2055.4097
116.45264	0.2582112	0.01146329	2075.625
117.35352	0.26289174	0.011545355	2096.0291
118.25439	0.26568106	0.011824843	2115.7058
119.15527	0.2697694	0.011842242	2127.4021
120.05615	0.26814976	0.012103238	2137.7849
120.95703	0.27292877	0.012405544	2155.3279
121.85791	0.27314186	0.012532132	2174.4226
122.75879	0.27908346	0.012708087	2195.2988
123.65967	0.27933854	0.012837231	2204.2617
124.56055	0.28289375	0.013009515	2217.8821
125.46143	0.28494814	0.013208461	2227.6277
126.3623	0.2876904	0.013447324	2251.8225
127.26318	0.29043365	0.01373089	2261.5715
128.16406	0.29519096	0.013948507	2272.5452
129.06494	0.29555586	0.014084471	2287.5823
129.96582	0.298605	0.014275381	2293.1045
130.8667	0.30613244	0.014406417	2314.4204
131.76758	0.30456543	0.014718285	2319.8694
132.66846	0.30386326	0.015029388	2336.7219
133.56934	0.3106344	0.015187783	2345.5005
134.47021	0.31132877	0.015417652	2352.7207
135.37109	0.31736237	0.015567656	2371.2712
136.27197	0.3192572	0.015882432	2380.3376
137.17285	0.31965387	0.016111095	2386.2568
138.07373	0.32470188	0.01628427	2399.2129
138.97461	0.32595888	0.016625741	2409.4941
139.87549	0.32988232	0.016942101	2417.2715
140.77637	0.33277041	0.017297309	2435.4622
141.67725	0.33532289	0.017518921	2436.8796
142.57813	0.34134683	0.017741121	2452.915
143.479	0.34079549	0.018244188	2462.6543
144.37988	0.34526575	0.018481417	2468.1345
145.28076	0.3455188	0.018757472	2473.51
146.18164	0.35090423	0.019285403	2486.8347
147.08252	0.35146955	0.019552525	2498.9333
147.9834	0.3536891	0.020110523	2504.1858
148.88428	0.35848433	0.020292571	2509.991
149.78516	0.36132613	0.02079243	2517.4463
150.68604	0.36271918	0.021102922	2527.093
151.58691	0.36638933	0.021809882	2541.7725
152.48779	0.36632788	0.022123842	2545.5706
153.38867	0.37078133	0.022764685	2552.6775
154.28955	0.3707301	0.02327016	2554.2834
155.19043	0.37478608	0.023960974	2564.5872
156.09131	0.38185456	0.024457809	2576.5984
156.99219	0.38236576	0.02519533	2575.606
157.89307	0.38318104	0.025503725	2583.0876
158.79395	0.38727552	0.026167519	2587.1682
159.69482	0.39068732	0.026709462	2589.9998
160.5957	0.39339468	0.02726067	2598.9883
161.49658	0.39756233	0.027870698	2603.364
162.39746	0.39793214	0.028372806	2607.4851
163.29834	0.40108845	0.029235443	2618.3318
164.19922	0.401196	0.030097086	2619.3179
165.1001	0.40752298	0.030733418	2627.1064
166.00098	0.41059861	0.031450059	2631.166
166.90186	0.41024703	0.031950712	2635.0774
167.80273	0.41537678	0.032926377	2637.6963
168.70361	0.41410998	0.033431228	2634.3484
169.60449	0.41812021	0.034267146	2643.4802
170.50537	0.42161545	0.035217602	2648.8059
171.40625	0.42773134	0.035862189	2650.437
172.30713	0.42753941	0.036883041	2654.4558
173.20801	0.42761788	0.037776656	2660.5479
174.10889	0.43603429	0.038769569	2664.4963
175.00977	0.43735296	0.039715059	2678.2524
175.91064	0.43776637	0.040663987	2672.9121
176.81152	0.44209731	0.041685123	2677.8064
177.7124	0.44389257	0.042665776	2683.2026
178.61328	0.44670996	0.043784533	2682.8054
179.51416	0.4469831	0.044904582	2685.739
180.41504	0.4555802	0.04573521	2691.1409
181.31592	0.45628709	0.046750255	2694.4639
182.2168	0.45790631	0.04764723	2700.4954
183.11768	0.46030453	0.048859742	2704.5781
184.01855	0.46191233	0.049841646	2702.7217
184.91943	0.46480411	0.050769985	2704.179
185.82031	0.47116467	0.051994223	2718.7539
186.72119	0.4695057	0.052906726	2706.7327
187.62207	0.47074753	0.053986333	2712.7808
188.52295	0.47662088	0.055313524	2712.8855
189.42383	0.4776437	0.056344699	2717.3752
190.32471	0.47987655	0.057604555	2720.7732
191.22559	0.48340145	0.05838475	2719.6084
192.12646	0.48754901	0.0593796	2726.707
193.02734	0.49016157	0.060296446	2731.1772
193.92822	0.49277961	0.061411344	2731.2202
194.8291	0.49487907	0.062369682	2728.0576
195.72998	0.50043648	0.063425668	2737.2644
196.63086	0.50199324	0.06462685	2740.2275
197.53174	0.50683147	0.065925092	2747.8721
198.43262	0.50393009	0.066916935	2736.8005
199.3335	0.5091334	0.068104051	2741.2996
200.23438	0.51164961	0.068963818	2741.9692
201.13525	0.513551	0.070124254	2744.0967
202.03613	0.51718205	0.071410798	2753.5815
202.93701	0.52255523	0.072657026	2756.4414
203.83789	0.52590168	0.074040949	2760.6938
204.73877	0.52557284	0.075319409	2756.5894
205.63965	0.52701747	0.076347962	2759.5823
206.54053	0.53050679	0.077563308	2765.9443
207.44141	0.53416198	0.078795731	2770.0608
208.34229	0.53561133	0.080097094	2761.4849
209.24316	0.54059833	0.081464015	2776.6426
210.14404	0.54082412	0.082587771	2770.6941
211.04492	0.54530215	0.08396358	2776.4102
211.9458	0.54498506	0.08500696	2767.3284
212.84668	0.54984003	0.086202301	2778.2085
213.74756	0.55250031	0.087443374	2774.5837
214.64844	0.55328608	0.08871074	2771.5078
215.54932	0.55767399	0.089668997	2772.762
216.4502	0.55889386	0.090624616	2775.0183
217.35107	0.56358296	0.091820307	2791.0579
218.25195	0.56781125	0.093249112	2790.0107
219.15283	0.56742132	0.09479405	2789.248
220.05371	0.57196271	0.096211977	2789.4675
220.95459	0.57167447	0.097184353	2786.5527
221.85547	0.57759529	0.098480806	2794.2109
222.75635	0.57772011	0.099545941	2790.2744
223.65723	0.58170557	0.10095661	2795.0347
224.55811	0.58168566	0.10231607	2790.6736
225.45898	0.58617437	0.1037084	2800.7527
226.35986	0.59070837	0.10510737	2809.2405
227.26074	0.58947635	0.10637563	2801.1924
228.16162	0.59907293	0.1074164	2800.2859
229.0625	0.60209531	0.10868539	2803.947
229.96338	0.60232741	0.10954703	2806.4214
230.86426	0.59983802	0.11095702	2809.0535
231.76514	0.60638398	0.11207588	2810.3384
232.66602	0.61025089	0.11344969	2812.6541
233.56689	0.61186314	0.11461722	2805.0078
234.46777	0.61243129	0.11586842	2813.5984
235.36865	0.61880642	0.11709718	2812.9675
236.26953	0.61936653	0.11807895	2819.1511
237.17041	0.62243539	0.11919195	2819.5452
238.07129	0.62293369	0.12088922	2819.2698
238.97217	0.62950915	0.12228689	2827.5574
239.87305	0.62953496	0.12381227	2826.801
240.77393	0.63111264	0.12500308	2821.6138
241.6748	0.63499177	0.12606469	2821.8484
242.57568	0.63703024	0.12751044	2827.8054
243.47656	0.6408391	0.12843129	2823.176
244.37744	0.64486718	0.1298846	2836.0815
245.27832	0.6462059	0.13106762	2825.5852
246.1792	0.6491791	0.13215032	2827.9592
247.08008	0.65324569	0.13339145	2833.5569
247.98096	0.655294	0.13453808	2836.0967
248.88184	0.65603054	0.13612466	2840.168
249.78271	0.66223663	0.13747741	2839.0149
250.68359	0.66492397	0.13862537	2836.665
251.58447	0.66453898	0.13995565	2836.77
252.48535	0.66862446	0.14120683	2841.1594
253.38623	0.66878939	0.14260446	2842.6836
254.28711	0.67488134	0.14396225	2845.9209
255.18799	0.67746603	0.14538819	2846.9512
256.08887	0.68316847	0.14657786	2849.2915
256.98975	0.6844275	0.14802963	2854.4324
257.89063	0.68540257	0.14956817	2854.9976
258.7915	0.68637311	0.15101047	2848.6294
259.69238	0.68993551	0.15209129	2847.8743
260.59326	0.69374603	0.15330908	2850.5283
261.49414	0.69426996	0.15431747	2852.2612
262.39502	0.6970064	0.15572491	2858.2502
263.2959	0.70117015	0.15709744	2857.8257
264.19678	0.7048443	0.15837093	2861.7271
265.09766	0.70361143	0.15970434	2862.3472
265.99854	0.70930326	0.16111787	2860.6108
266.89941	0.71310836	0.16232833	2863.2834
267.80029	0.71648377	0.16346355	2863.9084
268.70117	0.71360993	0.1648156	2863.7102
269.60205	0.71879143	0.16589554	2862.7952
270.50293	0.72218233	0.16715764	2867.78
271.40381	0.72585827	0.16854374	2873.1934
272.30469	0.72552818	0.17003627	2869.6584
273.20557	0.73344463	0.1711746	2867.104
274.10645	0.73471761	0.1723692	2875.2202
275.00732	0.73697239	0.1735941	2876.2607
275.9082	0.73862833	0.17525032	2880.0491
276.80908	0.74470514	0.17647216	2877.5027
277.70996	0.74439716	0.17751093	2876.967
278.61084	0.74660176	0.17873354	2880.8584
279.51172	0.74684089	0.18002972	2878.7366
280.4126	0.7510913	0.18136787	2887.552
281.31348	0.75403899	0.18283358	2882.1055
282.21436	0.75925678	0.18433236	2888.4521
283.11523	0.7610575	0.18562278	2880.2822
284.01611	0.76262021	0.18687229	2884.5686
284.91699	0.76342821	0.18822427	2883.5244
285.81787	0.76930773	0.18947752	2889.1838
286.71875	0.77167833	0.1906856	2884.0286
287.61963	0.7732861	0.19168638	2884.45
288.52051	0.77506059	0.19272752	2884.7166
289.42139	0.77715188	0.19391681	2892.4373
290.32227	0.78020614	0.19527228	2896.4746
291.22314	0.78417897	0.19662984	2895.5977
292.12402	0.78596789	0.19800869	2890.7959
293.0249	0.78976095	0.19951056	2903.895
293.92578	0.79433423	0.20096625	2902.6606
294.82666	0.79685378	0.20215473	2899.1731
295.72754	0.79659623	0.20342132	2900.7744
296.62842	0.80103064	0.20482676	2899.3379
297.5293	0.8039667	0.20594649	2900.7861
298.43018	0.80627251	0.20714989	2901.9436
299.33105	0.80915898	0.20836465	2900.0908
300.23193	0.81266874	0.20967816	2906.7517
301.13281	0.81558573	0.21078646	2902.6504
302.03369	0.81942165	0.21167442	2907.7021
302.93457	0.82032335	0.21300785	2908.0942
303.83545	0.82639158	0.21445604	2914.3853
304.73633	0.82708573	0.2155735	2910.3289
305.63721	0.82932866	0.21676734	2912.8845
306.53809	0.83060771	0.21801472	2914.636
307.43896	0.83515316	0.219456	2915.3623
308.33984	0.83886582	0.22063243	2921.6113
309.24072	0.83890373	0.2219985	2916.2659
310.1416	0.83970094	0.22317101	2916.1301
311.04248	0.84629261	0.22451079	2919.147
311.94336	0.84678656	0.22569358	2917.1653
312.84424	0.84809005	0.22702463	2922.8472
313.74512	0.85343605	0.22840393	2921.6245
314.646	0.85313034	0.22982323	2922.3423
315.54688	0.85461539	0.23098157	2923.1187
316.44775	0.86001539	0.23256361	2929.3821
317.34863	0.86371571	0.23390232	2925.3691
318.24951	0.86706978	0.23522614	2928.1511
319.15039	0.86907721	0.23657724	2931.4333
320.05127	0.86951649	0.23785792	2928.8333
320.95215	0.87431169	0.23919496	2928.175
321.85303	0.87625486	0.2403495	2932.5908
322.75391	0.88098842	0.24167423	2932.073
323.65479	0.8782745	0.24299122	2931.5796
324.55566	0.88321453	0.24417481	2936.5308
325.45654	0.88966668	0.24540953	2934.9192
326.35742	0.89274454	0.24677247	2941.8259
327.2583	0.89742482	0.24803576	2944.0652
328.15918	0.89541322	0.24925952	2936.9805
329.06006	0.89958864	0.25056583	2941.8401
329.96094	0.90406871	0.2519179	2940.0813
330.86182	0.90299302	0.25345966	2947.5745
331.7627	0.90823698	0.25480038	2940.0671
332.66357	0.90917599	0.25579566	2939.0422
333.56445	0.91176432	0.25713837	2942.5046
334.46533	0.91128916	0.25822908	2942.5022
335.36621	0.91670215	0.25931925	2943.3262
336.26709	0.9192735	0.26090312	2948.0305
337.16797	0.92306828	0.26189789	2947.5251
338.06885	0.92573303	0.26320636	2949.2942
338.96973	0.92773992	0.26462409	2952.1433
339.87061	0.93219626	0.26573852	2954.3865
340.77148	0.93289286	0.26717114	2952.2756
341.67236	0.93513966	0.26861498	2957.1472
342.57324	0.94281131	0.26978928	2960.3818
343.47412	0.94196427	0.27106172	2952.6863
344.375	0.94437134	0.27247503	2962.9524
345.27588	0.94781536	0.27377906	2959.8706
346.17676	0.95095974	0.27504912	2957.7502
347.07764	0.95129001	0.27604443	2953.9648
347.97852	0.95202351	0.27741402	2962.5688
348.87939	0.9546504	0.27861705	2960.0571
349.78027	0.96173644	0.27999625	2961.8655
350.68115	0.96277159	0.28121793	2955.6621
351.58203	0.96586764	0.2823495	2968.1985
352.48291	0.96898562	0.28361547	2966.5679
353.38379	0.96969455	0.28476432	2960.8987
354.28467	0.97346902	0.28621837	2968.8862
355.18555	0.97828305	0.28781736	2976.7959
356.08643	0.98034811	0.28916082	2970.2813
356.9873	0.98286414	0.2905516	2970.9607
357.88818	0.98487496	0.29179639	2975.9761
358.78906	0.98493254	0.29318577	2966.7612
359.68994	0.99251932	0.29456007	2968.877
360.59082	0.99359089	0.29569554	2969.1968
361.4917	0.99684739	0.29679808	2974.9524
362.39258	0.99970174	0.29830772	2980.6328
363.29346	1.0004655	0.29952931	2973.6675
364.19434	1.0039473	0.30056366	2976.3992
365.09521	1.0077747	0.30166137	2974.1895
365.99609	1.0092605	0.3028647	2973.429
366.89697	1.0112292	0.30403861	2979.3525
367.79785	1.0147221	0.30541116	2981.5725
368.69873	1.0200042	0.30709121	2992.7485
369.59961	1.0227894	0.3082881	2986.7563
370.50049	1.0218127	0.30960634	2981.7954
371.40137	1.0281786	0.31055188	2985.7021
372.30225	1.0284021	0.31187323	2987.0798
373.20313	1.0313191	0.31308439	2988.4063
374.104	1.0343597	0.31418902	2981.8169
375.00488	1.038377	0.31537774	2993.9531
375.90576	1.0375112	0.31659332	2993.1643
376.80664	1.0427049	0.31780371	2992.3286
377.70752	1.0433825	0.31895125	2986.6206
378.6084	1.0494363	0.32041159	2999.6836
379.50928	1.0490122	0.32169521	2991.0513
380.41016	1.0526359	0.3228431	2995.3655
381.31104	1.0540966	0.32418141	2992.5435
382.21191	1.0573025	0.3252472	2991.9258
383.11279	1.0595181	0.32642165	2994.3816
384.01367	1.0610797	0.32781196	2996.553
384.91455	1.0631086	0.32887268	2994.7817
385.81543	1.0659393	0.33031535	3000.72
386.71631	1.0745289	0.33171913	3010.6785
387.61719	1.0717108	0.33278015	2995.7468
388.51807	1.0755843	0.33397481	2996.0962
389.41895	1.0802336	0.33505669	3004.4673
390.31982	1.0800109	0.33648771	3007.4736
391.2207	1.0856669	0.33794877	3009.1917
392.12158	1.0867794	0.33928746	3004.9941
393.02246	1.0893773	0.34094909	3005.0332
393.92334	1.09378	0.34221208	3004.1978
394.82422	1.0952454	0.34336448	3006.7832
395.7251	1.1005459	0.34450543	3011.7759
396.62598	1.1002204	0.34555131	3010.0781
397.52686	1.1035122	0.34687334	3014.8176
398.42773	1.1074572	0.34829149	3016.8311
399.32861	1.1096861	0.34977892	3014.5195
400.22949	1.1119834	0.35114881	3018.8582
401.13037	1.1138188	0.35246754	3016.5774
402.03125	1.1187664	0.35383675	3019.7966
402.93213	1.1192842	0.35491604	3013.9258
403.83301	1.1221477	0.35621387	3020.9187
404.73389	1.1259605	0.35757166	3023.3467
405.63477	1.1250793	0.35862887	3015.9553
406.53564	1.1293404	0.359934	3014.521
407.43652	1.1342156	0.36105224	3018.9009
408.3374	1.1367505	0.36218768	3025.5154
409.23828	1.1378671	0.3633548	3024.1558
410.13916	1.1435214	0.36433473	3022.7749
411.04004	1.1444516	0.36575088	3025.1724
411.94092	1.150206	0.36699682	3029.803
412.8418	1.1498138	0.36827791	3027.6165
413.74268	1.1552267	0.36968017	3030.1863
414.64355	1.1560268	0.37092721	3028.2566
415.54443	1.1561381	0.37241682	3029.5393
416.44531	1.1607866	0.37356985	3033.2949
417.34619	1.1639044	0.37478912	3032.4304
418.24707	1.1686881	0.37601444	3028.9373
419.14795	1.1669765	0.37708622	3026.7793
420.04883	1.171311	0.37840039	3039.9697
420.94971	1.1736861	0.37994701	3033.1572
421.85059	1.175691	0.38097551	3034.707
422.75146	1.1766802	0.38233167	3034.4922
423.65234	1.1824652	0.38347486	3039.2083
424.55322	1.1887406	0.38485569	3039.5718
425.4541	1.1881945	0.38596526	3035.8989
426.35498	1.1914163	0.38736859	3037.0757
427.25586	1.1939743	0.38863331	3038.6865
428.15674	1.1954159	0.39019549	3050.3843
429.05762	1.1979246	0.39142859	3034.2988
429.9585	1.2011845	0.39277059	3042.668
430.85938	1.2033255	0.39391491	3037.4297
431.76025	1.2034347	0.39508307	3036.8372
432.66113	1.2119112	0.39616916	3047.6309
433.56201	1.2148545	0.39754876	3052.2678
434.46289	1.2133403	0.39846998	3043.2292
435.36377	1.2164857	0.39986175	3045.5994
436.26465	1.2214913	0.40120244	3052.283
437.16553	1.2227669	0.40252462	3051.5757
438.06641	1.2260706	0.4040387	3052.3635
438.96729	1.2251505	0.40516672	3045.7705
439.86816	1.2334269	0.40639767	3056.9636
440.76904	1.2338966	0.40807486	3057.7952
441.66992	1.2374666	0.40938163	3055.8335
442.5708	1.238276	0.41069898	3047.2227
443.47168	1.2432209	0.41164598	3051.0725
444.37256	1.2453732	0.41280141	3054.7202
445.27344	1.2494974	0.41371301	3051.7078
446.17432	1.2490667	0.41487497	3060.7163
447.0752	1.2515999	0.41611302	3055.9797
447.97607	1.2557369	0.41729584	3060.7751
448.87695	1.2577596	0.41860667	3059.2568
449.77783	1.2629687	0.41991711	3061.8743
450.67871	1.2645714	0.42120704	3064.3721
451.57959	1.2675085	0.4225097	3065.5122
452.48047	1.267525	0.42357296	3060.0408
453.38135	1.2720233	0.4249599	3062.6921
454.28223	1.2714504	0.42626986	3059.158
455.18311	1.2776763	0.42743397	3067.9763
456.08398	1.278604	0.42875227	3065.5767
456.98486	1.2838857	0.42983198	3066.2048
457.88574	1.2854189	0.43110523	3065.3579
458.78662	1.2890871	0.43225497	3066.4836
459.6875	1.2920784	0.43352824	3070.4734
460.58838	1.2917851	0.43497831	3071.8691
461.48926	1.2945243	0.43646389	3069.2629
462.39014	1.2998585	0.43792588	3074.4502
463.29102	1.3008454	0.43916911	3065.7444
464.19189	1.3016846	0.44027215	3069.3123
465.09277	1.307197	0.44164628	3074.3564
465.99365	1.3095771	0.44275439	3070.6116
466.89453	1.3107276	0.44400012	3069.3037
467.79541	1.3112859	0.44538447	3073.9092
468.69629	1.3188719	0.44672886	3073.5688
469.59717	1.3221464	0.44802415	3078.325
470.49805	1.3220851	0.44945884	3081.6682
471.39893	1.3233436	0.45092517	3080.554
472.2998	1.326498	0.45233381	3081.9456
473.20068	1.3315295	0.45349276	3074.2771
474.10156	1.3326048	0.45451388	3074.4646
475.00244	1.3354027	0.45566416	3078.3032
475.90332	1.33974	0.45691821	3082.0667
476.8042	1.3403071	0.45825559	3082.3655
477.70508	1.3449715	0.45940739	3081.5024
478.60596	1.3455142	0.4607788	3083.0371
479.50684	1.3498232	0.46205711	3086.79
480.40771	1.3511537	0.4632777	3082.772
481.30859	1.3534745	0.46449122	3082.1282
482.20947	1.3591115	0.46568775	3086.9026
483.11035	1.3564447	0.46702799	3084.4143
484.01123	1.3653761	0.46843365	3095.3025
484.91211	1.3675041	0.46947622	3087.345
485.81299	1.3664019	0.47087359	3092.5852
486.71387	1.3709798	0.47208861	3089.3503
487.61475	1.3741213	0.47329986	3087.8875
488.51563	1.3747323	0.47428134	3084.9585
489.4165	1.3790983	0.47560868	3095.0901
490.31738	1.3816167	0.47694281	3100.2161
491.21826	1.3865541	0.47811624	3096.0769
492.11914	1.3863938	0.47935057	3093.0918
493.02002	1.389734	0.48055103	3099.5129
493.9209	1.3900692	0.48168758	3091.1653
494.82178	1.3940425	0.48303401	3098.5901
495.72266	1.3973457	0.4843863	3103.4395
496.62354	1.4028298	0.48597991	3099.5825
497.52441	1.4050281	0.4871318	3103.0649
498.42529	1.4078263	0.48855865	3099.3521
499.32617	1.4129105	0.48982319	3105.6946
500.22705	1.4136987	0.49101388	3102.825
501.12793	1.4156754	0.4922933	3105.0364
502.02881	1.4176435	0.49369726	3108.8987
502.92969	1.4178855	0.4947781	3102.241
503.83057	1.4195509	0.49609837	3102.8191
504.73145	1.4258926	0.4971008	3101.5779
505.63232	1.4289052	0.49813199	3111.344
506.5332	1.4301524	0.49983647	3112.6589
507.43408	1.4380482	0.5011043	3108.9263
508.33496	1.4363686	0.50245476	3109.3523
509.23584	1.4380378	0.50346339	3107.5291
510.13672	1.4410201	0.50480813	3110.616
511.0376	1.4467244	0.5059607	3111.929
511.93848	1.4460403	0.50723684	3107.8909
512.83936	1.4461255	0.50854045	3107.9399
513.74023	1.449037	0.50980723	3105.2725
514.64111	1.4569453	0.5111115	3110.2532
515.54199	1.4575844	0.51245427	3116.2156
516.44287	1.4616981	0.51373386	3117.5469
517.34375	1.4600052	0.51505423	3108.5095
518.24463	1.463716	0.51621318	3113.0752
519.14551	1.4691726	0.51748663	3108.1917
520.04639	1.4706626	0.51866144	3121.5544
520.94727	1.473869	0.51996976	3121.5454
521.84814	1.4760063	0.52121639	3113.2007
522.74902	1.478128	0.52260232	3119.8467
523.6499	1.4840293	0.5238837	3119.9551
524.55078	1.4850364	0.52513307	3122.5652
525.45166	1.4886006	0.52626574	3118.8972
526.35254	1.4888783	0.52761793	3125.0073
527.25342	1.4913908	0.52873659	3122.4226
528.1543	1.4956281	0.52997714	3120.4954
529.05518	1.4998618	0.53127044	3128.134
529.95605	1.5009972	0.53276664	3126.9355
530.85693	1.503426	0.53417945	3129.6064
531.75781	1.5099393	0.53539729	3126.5642
532.65869	1.512424	0.53680474	3130.5562
533.55957	1.5133082	0.5380311	3131.9299
534.46045	1.5127953	0.53932315	3123.9282
535.36133	1.517992	0.54067296	3137.2932
536.26221	1.5201231	0.54217476	3130.5295
537.16309	1.5246135	0.54357547	3131.303
538.06396	1.5268836	0.54466242	3127.9988
538.96484	1.5294672	0.54579335	3125.0073
539.86572	1.5305969	0.54724699	3134.4126
540.7666	1.533654	0.54851836	3127.1421
541.66748	1.5365734	0.54966515	3129.2654
542.56836	1.5393099	0.55091649	3135.5732
543.46924	1.5422304	0.55215317	3133.3389
544.37012	1.5470537	0.55351722	3138.0344
545.271	1.545871	0.55480081	3137.1533
546.17188	1.5532458	0.55633879	3141.4238
547.07275	1.5519772	0.55759436	3135.679
547.97363	1.5549892	0.55882519	3133.615
548.87451	1.5586635	0.5601204	3133.9365
549.77539	1.5615447	0.56114131	3142.0063
550.67627	1.5645858	0.56242096	3139.3154
551.57715	1.5666142	0.5636034	3143.1428
552.47803	1.5705025	0.56492221	3141.4878
553.37891	1.5729897	0.56589836	3139.4253
554.27979	1.5749	0.56709242	3139.7036
555.18066	1.5769625	0.56842631	3142.8047
556.08154	1.5786766	0.56998086	3147.6145
556.98242	1.5814842	0.57132155	3139.3384
557.8833	1.5832659	0.57272458	3141.9824
558.78418	1.5896839	0.57375097	3145.5388
559.68506	1.5906538	0.5750913	3149.9182
560.58594	1.5922046	0.57629824	3144.8848
561.48682	1.5969827	0.57758868	3147.5938
562.3877	1.5991116	0.57884532	3148.9409
563.28857	1.6031032	0.58011764	3150.8164
564.18945	1.6051131	0.58154923	3153.2566
565.09033	1.6072215	0.58275169	3151.6055
565.99121	1.6117911	0.58412188	3153.3438
566.89209	1.61095	0.58529121	3146.6997
567.79297	1.6156025	0.58653909	3146.5864
568.69385	1.6175473	0.58783525	3149.7319
569.59473	1.6182668	0.58915848	3151.0945
570.49561	1.6187268	0.59054869	3149.6975
571.39648	1.6244508	0.59207481	3155.0259
572.29736	1.6281617	0.59340811	3150.53
573.19824	1.6300519	0.59508198	3158.4695
574.09912	1.6329143	0.59651405	3154.7151
575	1.6373343	0.59790242	3155.2683
575.90088	1.6393666	0.59932458	3154.0984
576.80176	1.6422728	0.6006999	3157.7834
577.70264	1.6461778	0.60200816	3158.2178
578.60352	1.6460836	0.60330212	3155.7742
579.50439	1.6494597	0.60451013	3153.7935
580.40527	1.6535287	0.60583746	3159.8975
581.30615	1.6525522	0.60707057	3162.1333
582.20703	1.658373	0.60852933	3161.2937
583.10791	1.6617788	0.60971737	3161.769
584.00879	1.6632165	0.61126232	3160.4321
584.90967	1.6649798	0.61261964	3167.1584
585.81055	1.6717262	0.61394334	3160.9939
586.71143	1.670972	0.61506027	3156.4905
587.6123	1.6726156	0.61611176	3154.1389
588.51318	1.6774243	0.61716586	3163.6458
589.41406	1.6772031	0.61842519	3159.2803
590.31494	1.6825767	0.61947834	3160.7031
591.21582	1.68615	0.62069708	3164.2524
592.1167	1.6895759	0.62190413	3168.4941
593.01758	1.6924139	0.62325406	3167.2839
593.91846	1.6953201	0.6243785	3165.0647
594.81934	1.6957159	0.62564307	3172.5522
595.72021	1.6979429	0.62722903	3174.4946
596.62109	1.6974196	0.62832272	3162.178
597.52197	1.7060325	0.62957054	3172.9553
598.42285	1.7044872	0.63064194	3163.1667
599.32373	1.7107353	0.63192427	3172.6006
600.22461	1.7135379	0.63338327	3175.438
601.12549	1.7160796	0.63472778	3171.1433
602.02637	1.7168461	0.63610178	3173.2373
602.92725	1.7233274	0.63764369	3176.4502
603.82813	1.7225778	0.63901156	3170.092
604.729	1.724714	0.64046538	3170.0835
605.62988	1.727581	0.64198458	3175.1106
606.53076	1.7299895	0.64343226	3173.7986
607.43164	1.7297714	0.64474398	3171.021
608.33252	1.7361456	0.64610314	3180.4895
609.2334	1.7379835	0.64749849	3174.8743
610.13428	1.7394034	0.64882725	3172.2361
611.03516	1.7456934	0.64999574	3180.6135
611.93604	1.7478533	0.65146422	3183.3867
612.83691	1.7502245	0.65265304	3175.9485
613.73779	1.753337	0.65397674	3176.6536
614.63867	1.753577	0.65519267	3183.6492
615.53955	1.7586862	0.65643632	3177.3552
616.44043	1.7609385	0.65752876	3180.4434
617.34131	1.7621318	0.65907031	3182.3413
618.24219	1.7651275	0.66044301	3179.1533
619.14307	1.7690926	0.66180861	3179.6963
620.04395	1.7714704	0.66319835	3185.9067
620.94482	1.7742493	0.66464478	3181.2598
621.8457	1.7786006	0.6659196	3181.0432
622.74658	1.7783625	0.66736913	3183.8496
623.64746	1.7821831	0.66859603	3180.7898
624.54834	1.786208	0.66977835	3179.9927
625.44922	1.7881135	0.67110485	3187.8843
626.3501	1.787823	0.67236686	3180.2268
627.25098	1.7935354	0.67375249	3181.7742
628.15186	1.7951919	0.67490888	3181.1716
629.05273	1.8018923	0.67653352	3187.668
629.95361	1.7979404	0.6777631	3188.4204
630.85449	1.803038	0.67922628	3190.5471
631.75537	1.8064685	0.68078601	3185.8289
632.65625	1.8078254	0.68206567	3187.342
633.55713	1.8105942	0.68335122	3184.4526
634.45801	1.8133261	0.68472475	3186.7031
635.35889	1.8176638	0.6861406	3195.8284
636.25977	1.8178701	0.68732184	3182.3408
637.16064	1.82219	0.68853188	3183.6375
638.06152	1.8283075	0.69016254	3198.7385
638.9624	1.8319882	0.69127482	3197.4824
639.86328	1.8273103	0.69277048	3189.9519
640.76416	1.8334002	0.69422174	3188.5261
641.66504	1.8372115	0.69562632	3198.7764
642.56592	1.8368307	0.69720632	3191.7334
643.4668	1.8439121	0.6989674	3197.3279
644.36768	1.8408257	0.70017338	3187.907
645.26855	1.8464664	0.70157582	3194.4248
646.16943	1.8520519	0.70279896	3194.8635
647.07031	1.8526438	0.70424819	3199.6699
647.97119	1.8560996	0.70570672	3195.562
648.87207	1.8586779	0.70701289	3193.5918
649.77295	1.8620096	0.7080878	3190.0154
650.67383	1.8629118	0.70932555	3197.4629
651.57471	1.8667287	0.7107603	3200.0735
652.47559	1.8687863	0.71222311	3201.0664
653.37646	1.8712915	0.71342617	3197.3066
654.27734	1.8729481	0.71471763	3200.5288
655.17822	1.8752842	0.71597672	3199.6709
656.0791	1.8813444	0.71743917	3204.4402
656.97998	1.8838691	0.71903926	3205.8318
657.88086	1.8857511	0.72053766	3205.771
658.78174	1.8886716	0.72185683	3192.5205
659.68262	1.8886493	0.72299898	3195.1367
660.5835	1.894704	0.72433907	3204.6235
661.48438	1.8945138	0.72545093	3198.5288
662.38525	1.8976562	0.72651118	3202.7034
663.28613	1.9022191	0.72773558	3202.8271
664.18701	1.903924	0.72905719	3206.2688
665.08789	1.9040096	0.7305451	3207.3376
665.98877	1.9115077	0.73208576	3210.4065
666.88965	1.9101911	0.73352128	3203.4375
667.79053	1.9147513	0.73509061	3210.6729
668.69141	1.917487	0.73664242	3208.1777
669.59229	1.9173614	0.73843765	3202.3826
670.49316	1.922428	0.73985201	3208.1304
671.39404	1.926899	0.74130917	3211.4155
672.29492	1.9280148	0.74268138	3208.9026
673.1958	1.9286001	0.7440452	3209.1672
674.09668	1.9340366	0.74543971	3207.4893
674.99756	1.9374375	0.74675262	3206.0103
675.89844	1.9401704	0.74798477	3209.0562
676.79932	1.9416177	0.74956709	3212.4558
677.7002	1.9444405	0.75110608	3214.5654
678.60107	1.9504691	0.75266248	3212.8208
679.50195	1.9497737	0.75360811	3205.1306
680.40283	1.9505932	0.75500101	3207.8047
681.30371	1.9546915	0.75645918	3207.6404
682.20459	1.9599485	0.75798231	3213.0105
683.10547	1.9607012	0.75948298	3208.4333
684.00635	1.9640598	0.76074171	3205.4663
684.90723	1.965158	0.76201636	3209.2561
685.80811	1.9671582	0.76348144	3210.5671
686.70898	1.9710766	0.76473713	3213.3193
687.60986	1.9747243	0.76623088	3205.165
688.51074	1.977456	0.76778316	3215.0811
689.41162	1.9784774	0.76935661	3213.9133
690.3125	1.9819514	0.77091777	3215.7686
691.21338	1.985301	0.77236187	3214.2461
692.11426	1.9869936	0.77375436	3219.5979
693.01514	1.9904052	0.77507675	3215.6448
693.91602	1.9916977	0.776447	3211.4846
694.81689	1.9942901	0.7778151	3211.4399
695.71777	2.0002117	0.77917331	3216.7683
696.61865	1.9999602	0.78047651	3220.6472
697.51953	2.0032151	0.78186989	3216.1299
698.42041	2.0075858	0.78288394	3216.4509
699.32129	2.0077772	0.78438497	3216.0037
700.22217	2.0115399	0.7857098	3217.2925
701.12305	2.0170774	0.78735328	3220.0938
702.02393	2.0162597	0.78871965	3217.1431
702.9248	2.0183368	0.79011983	3213.6497
703.82568	2.0236847	0.79130739	3216.5779
704.72656	2.0236182	0.79264289	3224.6377
705.62744	2.0312231	0.7940495	3220.3467
706.52832	2.0307286	0.7954061	3219.6833
707.4292	2.0328896	0.79681617	3225.9412
708.33008	2.0385389	0.79842967	3222.176
709.23096	2.0414782	0.80003589	3225.2795
710.13184	2.0406454	0.80150342	3220.2065
711.03271	2.0465112	0.80309308	3222.9658
711.93359	2.0476353	0.80451846	3221.3989
712.83447	2.0520585	0.80629027	3230.105
713.73535	2.053302	0.80784523	3220.8696
714.63623	2.058423	0.80930275	3224.8186
715.53711	2.0573518	0.81105548	3227.0791
716.43799	2.0623558	0.81251067	3229.1287
717.33887	2.0650949	0.81391376	3221.377
718.23975	2.0661664	0.81510913	3222.5808
719.14063	2.0664134	0.81649709	3224.0483
720.0415	2.0709732	0.81776732	3228.0913
720.94238	2.0758708	0.81929123	3227.8157
721.84326	2.0780096	0.82085282	3234.3677
722.74414	2.0779042	0.82233489	3227.4065
723.64502	2.0811388	0.82383239	3223.0227
724.5459	2.0844617	0.82517093	3221.9087
725.44678	2.0890138	0.82657206	3221.751
726.34766	2.0902724	0.82790941	3228.1301
727.24854	2.0926523	0.82929403	3226.4473
728.14941	2.0943496	0.83071089	3228.0303
729.05029	2.0982606	0.8319931	3224.0125
729.95117	2.1034439	0.83329242	3226.6865
730.85205	2.1041424	0.83483201	3240.7124
731.75293	2.1062794	0.83615559	3220.6262
732.65381	2.108988	0.83725947	3224.7983
733.55469	2.1109416	0.83866549	3228.3271
734.45557	2.113929	0.84004796	3225.5327
735.35645	2.1158824	0.84148461	3234.3362
736.25732	2.1215515	0.84325165	3236.3396
737.1582	2.1232698	0.8448956	3232.0767
738.05908	2.1244836	0.84653121	3232.2275
738.95996	2.1291864	0.84809041	3229.9771
739.86084	2.1317828	0.84955972	3227.0623
740.76172	2.1338148	0.85076928	3224.1958
741.6626	2.1351287	0.85228121	3230.0703
742.56348	2.1386359	0.85388869	3230.9058
743.46436	2.1402431	0.85535955	3228.0222
744.36523	2.1479855	0.85700291	3237.616
745.26611	2.1457767	0.8583926	3229.1426
746.16699	2.1507401	0.85999334	3228.9429
747.06787	2.1495626	0.86149746	3226.8301
747.96875	2.1571398	0.86289591	3236.0962
748.86963	2.1592064	0.86463672	3235.0989
749.77051	2.1611514	0.86609834	3235.3772
750.67139	2.1642811	0.8677519	3237.6509
751.57227	2.1657548	0.8693006	3238.8953
752.47314	2.1708622	0.87111729	3241.3291
753.37402	2.1718974	0.8729254	3236.6194
754.2749	2.176383	0.87418056	3235.8582
755.17578	2.1775026	0.87546074	3230.9744
756.07666	2.1797097	0.87686962	3238.3694
756.97754	2.1823323	0.87838519	3239.4204
757.87842	2.1824379	0.8799299	3232.0254
758.7793	2.1865821	0.88167506	3233.1968
759.68018	2.1901021	0.88317144	3231.739
760.58105	2.1917775	0.88467896	3232.9607
761.48193	2.1965246	0.88621479	3232.2676
762.38281	2.1985953	0.88770491	3236.1948
763.28369	2.2004483	0.88911617	3238.3623
764.18457	2.2016525	0.89046514	3227.6423
765.08545	2.2091417	0.89182562	3232.9688
765.98633	2.2115605	0.89322865	3238.6023
766.88721	2.2148864	0.89469641	3238.4553
767.78809	2.214895	0.89648044	3242.1895
768.68896	2.2169051	0.89802361	3239.2253
769.58984	2.2241507	0.89958769	3235.2922
770.49072	2.221875	0.90084803	3230.8298
771.3916	2.2245059	0.90260792	3233.9729
772.29248	2.2275825	0.90411329	3234.9919
773.19336	2.2317491	0.90579718	3240.8704
774.09424	2.2336917	0.90716368	3236.9529
774.99512	2.2349727	0.90896517	3239.0488
775.896	2.2396991	0.91069943	3236.2139
776.79688	2.2408752	0.91210854	3235.5901
777.69775	2.2427049	0.91387016	3235.8552
778.59863	2.2488904	0.91548789	3234.6943
779.49951	2.248425	0.91699189	3235.9468
780.40039	2.2527733	0.91875672	3242.3147
781.30127	2.2538042	0.92027903	3239.8809
782.20215	2.2575655	0.922135	3237.8477
783.10303	2.2620802	0.92369741	3234.5591
784.00391	2.2631671	0.92517561	3237.6182
784.90479	2.2650673	0.92701018	3242.1587
785.80566	2.2695644	0.92872328	3242.3337
786.70654	2.2711143	0.9301343	3238.5015
787.60742	2.2777197	0.93172157	3242.9609
788.5083	2.2781377	0.9329834	3238.5046
789.40918	2.2792759	0.93467885	3245.9429
790.31006	2.2815647	0.93664551	3238.6917
791.21094	2.2853975	0.93840331	3238.7896
792.11182	2.2873814	0.94003886	3232.8362
793.0127	2.2902653	0.94147235	3239.7222
793.91357	2.2945461	0.94307536	3243.4404
794.81445	2.2961009	0.94440931	3238.4805
795.71533	2.2988977	0.94608009	3243.2085
796.61621	2.3007243	0.94759822	3242.5959
797.51709	2.3018975	0.94934815	3239.5486
798.41797	2.3105891	0.95124102	3243.6794
799.31885	2.3106284	0.95268542	3245.4207
800.21973	2.313612	0.95415324	3239.1528
801.12061	2.3155482	0.95547253	3239.8259
802.02148	2.3207088	0.95719284	3243.7002
802.92236	2.3199759	0.95903188	3239.426
803.82324	2.3236001	0.9605391	3237.5771
804.72412	2.324564	0.96199495	3234.1704
805.625	2.3278623	0.96337283	3245.1099
806.52588	2.329416	0.96512353	3237.2273
807.42676	2.3354678	0.96681899	3244.4707
808.32764	2.3340936	0.9681713	3234.3872
809.22852	2.3397925	0.96980113	3242.0981
810.12939	2.3423841	0.97150993	3241.886
811.03027	2.3455832	0.97319442	3239.843
811.93115	2.3482533	0.97476566	3239.3748
812.83203	2.3515637	0.97612596	3241.1235
813.73291	2.3512619	0.97774351	3237.45
814.63379	2.3539288	0.97917014	3242.6411
815.53467	2.3602448	0.98090047	3247.8032
816.43555	2.3615174	0.98290807	3239.7231
817.33643	2.3651063	0.98468465	3248.5017
818.2373	2.3680665	0.98649001	3240.4314
819.13818	2.3687344	0.98805135	3239.5566
820.03906	2.369607	0.98974401	3246.3962
820.93994	2.3749084	0.99177384	3241.8564
821.84082	2.3800569	0.99359995	3243.4712
822.7417	2.3803372	0.99542063	3243.0186
823.64258	2.3805208	0.99722832	3236.6401
824.54346	2.3839242	0.99900705	3238.3574
825.44434	2.3872736	1.0005683	3234.7764
826.34521	2.3912289	1.0021049	3242.0186
827.24609	2.3942969	1.0036247	3242.2607
828.14697	2.3984885	1.0050825	3240.2434
829.04785	2.3964767	1.0069263	3239.9727
829.94873	2.3993256	1.0085831	3240.5505
830.84961	2.4038463	1.0103844	3237.332
831.75049	2.4048464	1.0123131	3242.3384
832.65137	2.4094193	1.0141729	3242.5547
833.55225	2.4113922	1.0157913	3240.7651
834.45313	2.4190161	1.0177619	3244.1033
835.354	2.4171109	1.0191292	3236.9111
836.25488	2.4191985	1.0205684	3236.8623
837.15576	2.4193671	1.0222433	3237.551
838.05664	2.4272301	1.0239594	3241.6484
838.95752	2.4288728	1.0255482	3234.4419
839.8584	2.4315102	1.0273541	3243.0891
840.75928	2.4334152	1.0293506	3243.0061
841.66016	2.4345012	1.0311674	3235.5044
842.56104	2.4384604	1.0330058	3238.1563
843.46191	2.4401064	1.0344604	3228.1433
844.36279	2.4435935	1.0358342	3232.1816
845.26367	2.4454668	1.0374982	3240.7373
846.16455	2.4510167	1.0393142	3242.2114
847.06543	2.4524119	1.0410353	3239.8899
847.96631	2.4559386	1.0428475	3240.5601
848.86719	2.4584296	1.0445795	3240.8257
849.76807	2.4632106	1.0467323	3243.4788
850.66895	2.4661748	1.0486232	3239.7798
851.56982	2.4663398	1.0504768	3235.7937
852.4707	2.4698472	1.0522681	3234.353
853.37158	2.4711843	1.0539074	3229.9578
854.27246	2.4782414	1.0552024	3233.6917
855.17334	2.4761746	1.0569791	3236.6897
856.07422	2.4807544	1.0588322	3241.7856
856.9751	2.4800718	1.060884	3234.8557
857.87598	2.4850092	1.0627204	3236.8359
858.77686	2.4869716	1.0646324	3235.8347
859.67773	2.4897597	1.0663823	3233.4905
860.57861	2.4892154	1.0679854	3228.5564
861.47949	2.4942455	1.0697128	3225.5198
862.38037	2.5004451	1.0714159	3237.5415
863.28125	2.4997466	1.0730752	3237.6165
864.18213	2.5047522	1.0749203	3232.9885
865.08301	2.5047927	1.0768114	3231.5518
865.98389	2.5109513	1.0785723	3228.5164
866.88477	2.5137086	1.0801467	3232.3274
867.78564	2.5135942	1.0819339	3233.1702
868.68652	2.5173187	1.0836458	3232.3198
869.5874	2.5211682	1.0854992	3232.2876
870.48828	2.5241957	1.0874561	3233.3223
871.38916	2.5248005	1.0892596	3231.5718
872.29004	2.5287137	1.0910928	3232.5183
873.19092	2.5272696	1.0927968	3224.5112
874.0918	2.5334063	1.0941905	3226.6709
874.99268	2.5390317	1.0957744	3227.0466
875.89355	2.5377374	1.0972793	3226.9626
876.79443	2.5412891	1.0990151	3231.5205
877.69531	2.5446074	1.1011453	3231.3362
878.59619	2.5478284	1.1030289	3231.2764
879.49707	2.5484762	1.1049045	3224.3254
880.39795	2.5521369	1.1069546	3231.8433
881.29883	2.5564599	1.1088688	3223.6812
882.19971	2.5569263	1.1106405	3219.2043
883.10059	2.5583074	1.1121491	3217.7629
884.00146	2.5595398	1.113758	3219.7087
884.90234	2.5657101	1.115787	3229.2366
885.80322	2.5716653	1.1175578	3226.5198
886.7041	2.5722065	1.1197512	3225.894
887.60498	2.5757396	1.1218026	3226.9924
888.50586	2.577606	1.1239098	3221.239
889.40674	2.5793643	1.1253464	3214.6877
890.30762	2.5826583	1.1271082	3222.4351
891.2085	2.5846713	1.1289437	3227.6238
892.10938	2.5860474	1.1312833	3221.6917
893.01025	2.5900788	1.1331664	3216.9907
893.91113	2.5909653	1.1348734	3218.5657
894.81201	2.5981255	1.1366791	3213.3735
895.71289	2.5982094	1.1384708	3214.196
896.61377	2.6005414	1.1401956	3211.6016
897.51465	2.6041965	1.141657	3212.6221
898.41553	2.6063197	1.1438776	3223.9319
899.31641	2.6091802	1.145924	3216.4087
900.21729	2.6128368	1.1478289	3216.4553
901.11816	2.6146479	1.1499923	3222.4109
902.01904	2.617764	1.1520849	3217.1716
902.91992	2.6180005	1.1539272	3207.0957
903.8208	2.6211834	1.1556724	3210.0359
904.72168	2.6241765	1.1573839	3205.6553
905.62256	2.6278925	1.1589651	3210.9302
906.52344	2.6300392	1.1607682	3211.7031
907.42432	2.6358018	1.162613	3208.1016
908.3252	2.6356404	1.1644593	3209.03
909.22607	2.6365736	1.1664878	3211.1274
910.12695	2.6404426	1.1682382	3204.2908
911.02783	2.6457515	1.1703309	3211.9968
911.92871	2.6471305	1.172084	3211.9902
912.82959	2.6507924	1.1740192	3203.687
913.73047	2.6538732	1.1758007	3200.6797
914.63135	2.6549325	1.1778444	3203.0461
915.53223	2.6596541	1.1798966	3199.6355
916.43311	2.6617124	1.1814724	3200.2664
917.33398	2.6637139	1.1831721	3196.4092
918.23486	2.668514	1.184991	3202.9729
919.13574	2.6671264	1.1868618	3200.4897
920.03662	2.6700029	1.1890699	3202.002
920.9375	2.676399	1.1910081	3203.0891
921.83838	2.6784532	1.1930562	3196.2417
922.73926	2.6781647	1.1948354	3194.3057
923.64014	2.6863742	1.1967262	3199.2922
924.54102	2.6866095	1.1987655	3190.1389
925.44189	2.6862731	1.2003977	3185.001
926.34277	2.6907129	1.202368	3194.5022
927.24365	2.6941938	1.2042785	3193.6563
928.14453	2.6975658	1.2062744	3194.2708
929.04541	2.6990137	1.2084678	3195.5083
929.94629	2.7008064	1.2105789	3189.3682
930.84717	2.7031794	1.2124617	3183.5742
931.74805	2.7079265	1.2146198	3193.1389
932.64893	2.7114434	1.2170291	3192.7725
933.5498	2.7127533	1.219425	3182.9436
934.45068	2.7170758	1.2216007	3184.7668
935.35156	2.7166362	1.2234412	3179.864
936.25244	2.7199953	1.2252409	3175.6919
937.15332	2.7247584	1.2270607	3179.033
938.0542	2.7222009	1.2286353	3169.5361
938.95508	2.7301323	1.2301371	3170.7957
939.85596	2.7313981	1.2316798	3177.6428
940.75684	2.7341871	1.2336859	3179.5154
941.65771	2.7354293	1.2355957	3174.5359
942.55859	2.7407618	1.2376872	3177.7693
943.45947	2.7413394	1.2395204	3166.9905
944.36035	2.7452879	1.2414148	3168.1272
945.26123	2.748626	1.2431506	3167.6152
946.16211	2.7494557	1.2450377	3171.6375
947.06299	2.7560079	1.2472991	3170.2461
947.96387	2.7574725	1.2498523	3169.22
948.86475	2.7581606	1.2520049	3162.012
949.76563	2.764838	1.2540693	3165.0647
950.6665	2.7626653	1.2561122	3162.7383
951.56738	2.7670262	1.2581104	3162.7563
952.46826	2.7699296	1.259887	3164.0042
953.36914	2.7737887	1.2620776	3160.5222
954.27002	2.7727001	1.2638927	3158.2065
955.1709	2.7775531	1.2662145	3157.3091
956.07178	2.7796052	1.2682551	3150.1206
956.97266	2.7823951	1.2701175	3149.3438
957.87354	2.7839668	1.2715852	3145.1479
958.77441	2.7910185	1.2734442	3148.9741
959.67529	2.7906766	1.2754791	3155.2446
960.57617	2.7915974	1.2774292	3143.3555
961.47705	2.7949615	1.2794714	3137.4753
962.37793	2.796916	1.2814047	3143.7598
963.27881	2.8014741	1.2835357	3146.6963
964.17969	2.8035855	1.2856545	3142.7229
965.08057	2.8073287	1.2881064	3143.8574
965.98145	2.8097494	1.2902362	3144.8174
966.88232	2.8150008	1.2925032	3137.9258
967.7832	2.8164103	1.2944117	3135.6304
968.68408	2.8201873	1.2965736	3134.2341
969.58496	2.8216465	1.2987345	3132.1868
970.48584	2.8237259	1.3005052	3130.4941
971.38672	2.8278663	1.3026551	3133.0918
972.2876	2.8283389	1.3049337	3123.6912
973.18848	2.8340323	1.3070244	3126.4973
974.08936	2.8323727	1.3090833	3118.2937
974.99023	2.8367834	1.3111774	3124.7014
975.89111	2.8397393	1.3132635	3119.094
976.79199	2.8444984	1.3150622	3116.9204
977.69287	2.8435605	1.3167558	3115.9854
978.59375	2.8454151	1.3189416	3113.3618
979.49463	2.8495362	1.320852	3109.6394
980.39551	2.8520417	1.3231988	3118.6472
981.29639	2.857703	1.3253931	3112.2896
982.19727	2.8575447	1.3274968	3110.844
983.09814	2.8600111	1.3294274	3104.7644
983.99902	2.8635793	1.3316284	3101.2571
984.8999	2.8667145	1.3340666	3103.1736
985.80078	2.8702705	1.3363092	3100.0366
986.70166	2.8720202	1.3383816	3097.6138
987.60254	2.87585	1.3403651	3097.967
988.50342	2.877008	1.3421118	3092.1047
989.4043	2.8817904	1.3441828	3098.269
990.30518	2.8825514	1.3466147	3099.5598
991.20605	2.8848698	1.3489276	3088.9722
992.10693	2.8907914	1.3513514	3090.54
993.00781	2.8913519	1.3531795	3082.584
993.90869	2.8962703	1.3549545	3083.6245
994.80957	2.8967533	1.356721	3081.8477
995.71045	2.8980577	1.3586483	3080.0344
996.61133	2.9013903	1.3612065	3086.5491
997.51221	2.9037485	1.3636665	3076.5603
998.41309	2.9071732	1.3664678	3071.1824
999.31396	2.911725	1.3691154	3075.1604
1000.2148	2.9145169	1.3715701	3067.6272
1001.1157	2.9160068	1.3740851	3065.7246
1002.0166	2.9179516	1.3762439	3057.6045
1002.9175	2.918227	1.3780552	3052.4429
1003.8184	2.9224865	1.3795966	3052.6482
1004.7192	2.9293025	1.38147	3067.8755
1005.6201	2.9294412	1.3843596	3058.3015
1006.521	2.9328904	1.3864962	3054.907
1007.4219	2.9316959	1.3884747	3044.031
1008.3228	2.9384534	1.3903041	3048.8376
1009.2236	2.9396873	1.392579	3049.3433
1010.1245	2.9430196	1.394855	3047.3721
1011.0254	2.9430103	1.397128	3038.8091
1011.9263	2.9496443	1.3993006	3042.2195
1012.8271	2.9489129	1.4016289	3038.5437
1013.728	2.9550047	1.4038837	3035.4243
1014.6289	2.9549336	1.4056374	3022.9236
1015.5298	2.9586401	1.4079965	3037.8779
1016.4307	2.9621947	1.4105115	3024.053
1017.3315	2.9641263	1.4122851	3019.2041
1018.2324	2.9653854	1.4142591	3021.1326
1019.1333	2.9699733	1.4162803	3018.7822
1020.0342	2.9720457	1.4185233	3019.373
1020.9351	2.9752817	1.4208695	3021.5879
1021.8359	2.9747121	1.4235526	3014.2214
1022.7368	2.9813163	1.4258566	3008.3645
1023.6377	2.9835434	1.4282005	3014.4597
1024.5386	2.9837961	1.430511	3007.2515
1025.4395	2.9858141	1.4329795	3005.4382
1026.3403	2.9901266	1.4353403	2992.4802
1027.2412	2.9944947	1.4374871	3000.261
1028.1421	2.9966257	1.4393774	2985.9253
1029.043	2.9995465	1.4405499	2983.5454
1029.9438	2.9997833	1.4423119	2984.6543
1030.8447	3.0053067	1.4436715	2988.5447
1031.7456	3.0078905	1.445798	2989.5361
1032.6465	3.0091732	1.4479096	2987.7009
1033.5474	3.0104115	1.4501445	2983.7571
1034.4482	3.016408	1.4528425	2982.8374
1035.3491	3.0185525	1.4553187	2972.969
1036.25	3.022402	1.4575256	2972.7432
1037.1509	3.0236504	1.46013	2978.1287
1038.0518	3.0279984	1.4622635	2970.801
1038.9526	3.0284705	1.4643229	2965.5635
1039.8535	3.0286648	1.4665275	2962.2393
1040.7544	3.0344317	1.4689491	2958.1743
1041.6553	3.0371468	1.4719342	2956.9045
1042.5562	3.0406923	1.4745821	2955.4729
1043.457	3.0419159	1.476723	2951.7998
1044.3579	3.0450456	1.4792176	2951.5898
1045.2588	3.0501044	1.4817077	2950.4155
1046.1597	3.0534847	1.4846509	2950.6204
1047.0605	3.0559905	1.4873108	2944.5483
1047.9614	3.0560603	1.4899096	2932.3386
1048.8623	3.0598323	1.4920819	2931.093
1049.7632	3.0617616	1.4942582	2927.5435
1050.6641	3.0611393	1.4966849	2923.2236
1051.5649	3.0652649	1.4986386	2922.3208
1052.4658	3.0670176	1.5009899	2917.7073
1053.3667	3.0718298	1.5034978	2910.9304
1054.2676	3.0753059	1.5059265	2917.8127
1055.1685	3.0768101	1.5087397	2911.5063
1056.0693	3.0811911	1.5112221	2907.6597
1056.9702	3.0822771	1.5132841	2891.105
1057.8711	3.0852811	1.5154775	2896.8809
1058.772	3.0885384	1.5178454	2897.9771
1059.6729	3.0929441	1.520264	2897.9153
1060.5737	3.0939274	1.5229822	2892.8208
1061.4746	3.0967846	1.5256188	2886.2251
1062.3755	3.1010039	1.5284048	2881.9844
1063.2764	3.1039028	1.5308586	2882.3191
1064.1772	3.1059649	1.5336921	2876.1624
1065.0781	3.1058674	1.5359939	2871.9829
1065.979	3.1084187	1.5386747	2864.2134
1066.8799	3.1127114	1.5410484	2869.5305
1067.7808	3.1129041	1.5441263	2860.6404
1068.6816	3.1155856	1.5470781	2853.5244
1069.5825	3.122649	1.5499017	2852.7402
1070.4834	3.1192198	1.5527023	2845.958
1071.3843	3.1251552	1.5552098	2839.876
1072.2852	3.1293089	1.5578034	2838.5574
1073.186	3.1303248	1.5603021	2835.1106
1074.0869	3.1389401	1.5629629	2835.5752
1074.9878	3.1353791	1.5656309	2826.0723
1075.8887	3.138689	1.568411	2821.4006
1076.7896	3.1413374	1.5707905	2824.4255
1077.6904	3.1464779	1.5737295	2819.4424
1078.5913	3.14833	1.5762268	2816.9612
1079.4922	3.1543555	1.5790173	2806.0847
1080.3931	3.1532662	1.5819509	2805.0315
1081.2939	3.155364	1.584797	2799.2307
1082.1948	3.1571572	1.587472	2789.4294
1083.0957	3.1611218	1.5898019	2788.3145
1083.9966	3.1634798	1.5922745	2784.4661
1084.8975	3.1649251	1.5946972	2779.366
1085.7983	3.1701922	1.5975295	2780.9175
1086.6992	3.1729946	1.6006055	2775.6709
1087.6001	3.1766922	1.6034179	2766.5557
1088.501	3.17607	1.606288	2762.8228
1089.4019	3.1794512	1.6088276	2757.3772
1090.3027	3.1838298	1.6112583	2753.7397
1091.2036	3.1855874	1.6136756	2747.5684
1092.1045	3.1913846	1.6162401	2750.4116
1093.0054	3.1914806	1.6191168	2745.7148
1093.9063	3.1936114	1.6219687	2733.0356
1094.8071	3.1964338	1.6248668	2735.0571
1095.708	3.1990812	1.6277392	2727.9722
1096.6089	3.2009788	1.6310481	2726.9458
1097.5098	3.2037902	1.634275	2713.936
1098.4106	3.2063909	1.6372982	2713.7026
1099.3115	3.2122457	1.6398785	2703.0659
1100.2124	3.2133975	1.6423792	2699.5581
1101.1133	3.2171614	1.6452459	2700.7695
1102.0142	3.2174048	1.6480811	2686.9924
1102.915	3.2225473	1.650509	2690.1414
1103.8159	3.2222354	1.6534787	2678.6475
1104.7168	3.2293143	1.6564833	2677.4692
1105.6177	3.2287557	1.6593938	2670.5469
1106.5186	3.2334323	1.6622857	2668.175
1107.4194	3.2345309	1.665015	2660.7957
1108.3203	3.2377651	1.6681465	2653.4446
1109.2212	3.2415516	1.6713213	2651.1204
1110.1221	3.2444248	1.6741997	2639.6738
1111.0229	3.2458704	1.6765774	2635.7212
1111.9238	3.2480645	1.6794275	2629.3875
1112.8247	3.2530503	1.6826996	2626.4214
1113.7256	3.2525976	1.6859086	2619.499
1114.6265	3.2556181	1.6894977	2613.0396
1115.5273	3.2612226	1.6928685	2605.1077
1116.4282	3.2609878	1.696002	2593.4341
1117.3291	3.2648978	1.6988633	2593.0313
1118.23	3.269016	1.7019465	2587.5842
1119.1309	3.2705295	1.7051159	2581.8689
1120.0317	3.2688551	1.7093372	2567.7361
1120.9326	3.2779021	1.7130489	2565.2419
1121.8335	3.2751188	1.716399	2547.6514
1122.7344	3.281975	1.7193887	2545.0425
1123.6353	3.2836492	1.7231139	2538.2949
1124.5361	3.2844045	1.7267007	2525.8948
1125.437	3.2884769	1.7301024	2512.6812
1126.3379	3.2889426	1.7332339	2501.4182
1127.2388	3.2961087	1.7365322	2497.5308
1128.1396	3.2976518	1.7400795	2484.002
1129.0405	3.3013031	1.7442772	2465.3137
1129.4409	3.2998948	1.7485689	2438.9897