File: datasets/am_bench_2022/raw_data/0-X.01-1/specimen.dat
MTS793|MPT|ENU|1|2|.|/|:|1|0|0|A

Operator Information						Time:	55.62793	Sec	10/12/2021 1:28:21 PM
Operator	Nick Derimow
Project	AM Bench 2022 mini-tensile challenge
Specimen ID	0-X.01-1
Material	PBF-L Inconel 625
Specimen Width	2.55	mm
Specimen Thickness	1.53	mm
Notes
Operator Information End

Data Acquisition						Time:	1056.6218	Sec	10/12/2021 1:45:02 PM
Time	Axial Displacement	Axial Extensometer	Axial Force
Sec	mm	mm	N
55.741699	0.0058876565	0.00016032938	54.707108
56.842773	0.0089124618	0.00026912955	73.834137
57.943848	0.011731505	0.0004124979	87.309998
59.044922	0.014614321	0.00043509738	106.59924
60.145996	0.017529458	0.0004774596	121.38158
61.24707	0.024084894	0.00059443904	134.10121
62.348145	0.025124511	0.00060326984	147.3755
63.449219	0.026761742	0.00078468234	159.5247
64.550293	0.033209354	0.00088629394	181.092
65.651367	0.03400597	0.00090147636	198.9086
66.752441	0.040048152	0.0010344209	212.19513
67.853516	0.041624583	0.0010816595	227.63483
68.95459	0.044650979	0.0012735266	253.41815
70.055664	0.047679421	0.0013085087	274.75037
71.156738	0.048301265	0.0014599169	293.99536
72.257813	0.053513844	0.0015096726	320.16864
73.358887	0.058245953	0.0017041685	337.43588
74.459961	0.062768869	0.0018496482	363.7504
75.561035	0.062828697	0.0018722108	385.86047
76.662109	0.064502865	0.0020482962	407.35095
77.763184	0.068079591	0.0021371522	429.09717
78.864258	0.074754022	0.0023397505	462.20844
79.965332	0.074291378	0.0024996935	485.35767
81.066406	0.078949727	0.0026124122	509.22043
82.16748	0.080607086	0.0027985771	538.23163
83.268555	0.084287286	0.0028448128	567.77264
84.369629	0.08974205	0.0030964569	593.83789
85.470703	0.09205322	0.0032732061	615.82941
86.571777	0.097102858	0.0034280606	650.19427
87.672852	0.099806547	0.0035190599	672.58502
88.773926	0.10335629	0.0037809485	711.01178
89.875	0.10684881	0.0038833641	739.82336
90.976074	0.10809475	0.0041343528	769.93085
92.077148	0.11187801	0.0042297128	805.22687
93.178223	0.11626344	0.0044510001	829.99536
94.279297	0.11832424	0.0045582638	863.24585
95.380371	0.12248798	0.0046368046	886.96594
96.481445	0.12416086	0.0049719992	918.76978
97.58252	0.12834838	0.0050953589	952.9469
98.683594	0.13200629	0.0052095386	974.30487
99.784668	0.13678138	0.005354424	1007.4091
100.88574	0.14056423	0.0055458108	1040.2078
101.98682	0.14251746	0.0057006855	1075.0122
103.08789	0.14884177	0.0058803977	1112.7847
104.18896	0.14780073	0.0060804305	1132.8367
105.29004	0.14974181	0.0062334454	1161.1642
106.39111	0.15713689	0.0063346727	1199.1737
107.49219	0.1587752	0.0065952828	1232.8376
108.59326	0.16125965	0.0066538313	1249.6495
109.69434	0.16635662	0.0069258497	1282.437
110.79541	0.17053886	0.0069341436	1313.7943
111.89648	0.17825986	0.0073502678	1354.6687
112.99756	0.17889482	0.0073908567	1378.4915
114.09863	0.18051198	0.0075332788	1414.7739
115.19971	0.18037613	0.0078381533	1450.8319
116.30078	0.18408875	0.0079316599	1472.798
117.40186	0.18821152	0.0081578	1500.4203
118.50293	0.19023682	0.0083472645	1528.7607
119.604	0.1966099	0.0084955841	1570.9454
120.70508	0.20147642	0.0087246411	1601.5046
121.80615	0.20038168	0.0088097183	1627.2427
122.90723	0.20405614	0.0090218438	1652.395
124.0083	0.20752653	0.0093369791	1687.587
125.10938	0.21378283	0.0094294082	1718.174
126.21045	0.21537791	0.0097405883	1747.563
127.31152	0.22046095	0.0099104866	1777.369
128.4126	0.22114918	0.010058003	1798.6866
129.51367	0.22780275	0.010332238	1833.3416
130.61475	0.23115103	0.010496968	1860.2666
131.71582	0.2303911	0.010793515	1879.5797
132.81689	0.23401494	0.011014391	1914.7598
133.91797	0.23809473	0.011152665	1939.186
135.01904	0.24183539	0.011534508	1966.0862
136.12012	0.24410531	0.011682597	1985.1512
137.22119	0.24863049	0.011936995	2013.6176
138.32227	0.25471345	0.012127378	2037.6122
139.42334	0.25445652	0.012467357	2056.4224
140.52441	0.25909641	0.01274197	2081.3052
141.62549	0.26129875	0.012932336	2096.8733
142.72656	0.26160976	0.013228363	2109.8972
143.82764	0.26568073	0.013421439	2134.4802
144.92871	0.27012169	0.013642705	2148.5205
146.02979	0.27561495	0.014060665	2181.2654
147.13086	0.27619252	0.014364433	2198.2224
148.23193	0.2813051	0.014765115	2217.4819
149.33301	0.28622246	0.01506961	2230.7551
150.43408	0.28962421	0.015521165	2256.7131
151.53516	0.29075745	0.015812321	2268.9951
152.63623	0.29614562	0.016250966	2291.6711
153.7373	0.29665908	0.016705228	2305.0435
154.83838	0.30199927	0.017118318	2321.8813
155.93945	0.30507407	0.017502004	2337.5916
157.04053	0.3078599	0.017903393	2344.2456
158.1416	0.31229615	0.018318271	2364.7888
159.24268	0.31471157	0.018762711	2375.1318
160.34375	0.31745791	0.019241238	2392.2578
161.44482	0.31872907	0.019765668	2400.2188
162.5459	0.32745358	0.020428777	2417.5979
163.64697	0.32829815	0.020852953	2432.261
164.74805	0.3314178	0.021374119	2436.0269
165.84912	0.33636504	0.022101695	2454.4006
166.9502	0.33797216	0.022651125	2458.6804
168.05127	0.33947381	0.023359941	2474.2346
169.15234	0.34495479	0.024111181	2488.1846
170.25342	0.34793037	0.02506152	2497.0864
171.35449	0.34901384	0.025675364	2496.2839
172.45557	0.35584441	0.026313087	2519.1016
173.55664	0.35603821	0.027278876	2521.1665
174.65771	0.36193863	0.027939752	2532.9517
175.75879	0.36589462	0.028776651	2542.8782
176.85986	0.36750096	0.029586514	2540.4109
177.96094	0.37277806	0.030568341	2544.0825
179.06201	0.37369597	0.031731661	2556.3767
180.16309	0.37854749	0.032723755	2570.6523
181.26416	0.38211891	0.03381516	2576.8838
182.36523	0.38500559	0.034846015	2580.1284
183.46631	0.38617757	0.035680473	2573.697
184.56738	0.39276719	0.036836985	2587.9475
185.66846	0.39546227	0.037953209	2580.72
186.76953	0.39612162	0.038981669	2598.6577
187.87061	0.40385026	0.040291186	2606.2549
188.97168	0.40705225	0.041539725	2604.0171
190.07275	0.40907219	0.042757537	2613.2849
191.17383	0.41143686	0.043649599	2611.1838
192.2749	0.41612881	0.045107711	2617.0464
193.37598	0.41900542	0.046412669	2619.9973
194.47705	0.42227769	0.047807083	2636.011
195.57813	0.4231917	0.049192883	2629.3203
196.6792	0.42631054	0.050379682	2624.9116
197.78027	0.43140057	0.05179425	2634.105
198.88135	0.4341625	0.053237867	2647.365
199.98242	0.43516251	0.054702252	2641.6926
201.0835	0.4407126	0.056485776	2644.6709
202.18457	0.44574872	0.057785023	2645.4236
203.28564	0.44864109	0.059328008	2647.908
204.38672	0.45218715	0.060725171	2654.3301
205.48779	0.4541328	0.062152505	2656.8308
206.58887	0.45754048	0.063885197	2654.6816
207.68994	0.46259484	0.065516368	2659.6377
208.79102	0.46599746	0.067012772	2660.957
209.89209	0.46727496	0.068428293	2665.8235
210.99316	0.46984753	0.069839448	2669.0181
212.09424	0.47425508	0.071572483	2670.4841
213.19531	0.47648856	0.073224828	2671.001
214.29639	0.48147252	0.074950539	2670.7783
215.39746	0.48509023	0.076261267	2669.9917
216.49854	0.48692539	0.077633731	2670.6812
217.59961	0.49454114	0.079160675	2683.5908
218.70068	0.49564976	0.080570646	2674.3445
219.80176	0.49781463	0.082251444	2678.9746
220.90283	0.50223917	0.084021941	2686.3457
222.00391	0.50396681	0.085682519	2676.2878
223.10498	0.50852436	0.087068252	2689.1113
224.20605	0.50959283	0.08869338	2688.0747
225.30713	0.51578373	0.090293385	2691.4653
226.4082	0.51646686	0.091937669	2689.7766
227.50928	0.52252603	0.093869217	2692.0928
228.61035	0.52437741	0.095375262	2689.2749
229.71143	0.52695715	0.097220592	2694.4631
230.8125	0.52883387	0.099479817	2691.1001
231.91357	0.53464705	0.101139	2697.6948
233.01465	0.5385344	0.10277945	2702.9792
234.11572	0.54044515	0.10483326	2702.7214
235.2168	0.54288536	0.10646322	2703.8762
236.31787	0.54879749	0.10845375	2701.9922
237.41895	0.55328637	0.10976323	2705.6763
238.52002	0.55631191	0.11144	2713.0798
239.62109	0.55461508	0.11365768	2702.6465
240.72217	0.55953836	0.11530671	2713.2454
241.82324	0.5642969	0.11729822	2713.8054
242.92432	0.56884605	0.11920799	2713.4419
244.02539	0.56888068	0.12123647	2715.3838
245.12646	0.57228202	0.12298787	2716.8418
246.22754	0.57789761	0.1245338	2715.5645
247.32861	0.58248377	0.12640196	2726.6558
248.42969	0.58335823	0.12816076	2720.5413
249.53076	0.5867576	0.12993139	2721.6948
250.63184	0.5903073	0.13156398	2711.7371
251.73291	0.59440666	0.13313827	2727.4785
252.83398	0.59663075	0.1349515	2725.0566
253.93506	0.60135144	0.13676167	2728.6938
255.03613	0.60455358	0.13870202	2729.3965
256.13721	0.60776007	0.1404428	2735.6958
257.23828	0.61177737	0.14229687	2733.6848
258.33936	0.6132679	0.14426927	2731.2749
259.44043	0.61486876	0.14596468	2722.4456
260.5415	0.61740726	0.14752594	2729.6406
261.64258	0.62377107	0.14915183	2729.5469
262.74365	0.62647915	0.15087862	2734.1941
263.84473	0.6303407	0.15268394	2731.5767
264.9458	0.63455278	0.15428363	2741.447
266.04688	0.63450134	0.15634976	2737.928
267.14795	0.64128482	0.15818423	2741.999
268.24902	0.64244181	0.16005117	2740.8535
269.3501	0.64522648	0.16215654	2738.2109
270.45117	0.65237969	0.16395807	2743.551
271.55225	0.65395308	0.16587254	2747.636
272.65332	0.65418786	0.16774866	2742.7871
273.75439	0.65904927	0.1697087	2751.4253
274.85547	0.66278028	0.17164826	2752.2415
275.95654	0.6692816	0.17357393	2753.7793
277.05762	0.66853482	0.17556678	2757.45
278.15869	0.67338961	0.17755337	2747.4932
279.25977	0.67459476	0.17907821	2752.5728
280.36084	0.67734557	0.18081175	2749.3445
281.46191	0.68240249	0.18234378	2752.0308
282.56299	0.68424726	0.18413998	2754.3862
283.66406	0.6888386	0.18618388	2754.5164
284.76514	0.69145912	0.18766651	2754.1777
285.86621	0.69325972	0.18967868	2756.8921
286.96729	0.69776297	0.19119439	2756.313
288.06836	0.70367378	0.1928678	2763.2144
289.16943	0.70703745	0.19487385	2768.7244
290.27051	0.70899296	0.19695286	2771.6194
291.37158	0.71412802	0.19901271	2768.1982
292.47266	0.71196562	0.20070569	2762.5771
293.57373	0.72030193	0.20230377	2766.7568
294.6748	0.72073346	0.20400558	2770.3513
295.77588	0.72514635	0.20555787	2764.8494
296.87695	0.73179984	0.20758194	2773.5613
297.97803	0.73111123	0.20912862	2768.8679
299.0791	0.73370206	0.21086541	2774.2422
300.18018	0.73739988	0.21297337	2773.1172
301.28125	0.74335766	0.21495177	2773.1589
302.38232	0.7464205	0.21687809	2779.0371
303.4834	0.7491017	0.21872117	2786.1882
304.58447	0.75032717	0.22095095	2788.8728
305.68555	0.7550506	0.22300217	2780.4272
306.78662	0.75509143	0.22472958	2774.6196
307.8877	0.75918633	0.22666535	2780.1599
308.98877	0.76212323	0.22842798	2772.6975
310.08984	0.76895887	0.23013011	2785.3257
311.19092	0.7685917	0.23223577	2783.3818
312.29199	0.77305049	0.23401235	2784.8364
313.39307	0.77788711	0.23601539	2792.2085
314.49414	0.77759266	0.23794456	2784.8926
315.59521	0.78199923	0.23975831	2782.7852
316.69629	0.7891134	0.24153322	2790.0964
317.79736	0.79122907	0.2431159	2788.9338
318.89844	0.79209816	0.24471779	2789.3772
319.99951	0.79653567	0.24657138	2792.864
321.10059	0.80354804	0.24868129	2800.74
322.20166	0.80727863	0.25035772	2796.3333
323.30273	0.80912668	0.2520102	2802.4773
324.40381	0.81148022	0.25408658	2799.9524
325.50488	0.81513667	0.25572193	2795.6477
326.60596	0.81835139	0.25739682	2799.3552
327.70703	0.82363486	0.25914866	2801.0305
328.80811	0.82381272	0.26104316	2800.3386
329.90918	0.82817209	0.26306415	2803.9231
331.01025	0.828394	0.26482546	2798.4329
332.11133	0.83238667	0.26694489	2800.6843
333.2124	0.83641946	0.26883003	2802.8274
334.31348	0.83837473	0.27058563	2797.5352
335.41455	0.84445971	0.27245381	2809.6311
336.51563	0.84701222	0.27445883	2806.6396
337.6167	0.85173142	0.27631027	2812.6035
338.71777	0.85448205	0.27804849	2806.8152
339.81885	0.86018127	0.28027996	2824.4685
340.91992	0.86106867	0.28249142	2804.3796
342.021	0.86224264	0.2840572	2810.873
343.12207	0.86952502	0.28590846	2815.1392
344.22314	0.86913466	0.28771579	2817.5198
345.32422	0.87589127	0.2897999	2826.0234
346.42529	0.87526798	0.2918475	2814.6899
347.52637	0.87785041	0.29358488	2813.0786
348.62744	0.8875097	0.29566717	2827.2351
349.72852	0.88821226	0.29737538	2818.7898
350.82959	0.88979316	0.29915065	2821.8262
351.93066	0.89309126	0.30095768	2820.7944
353.03174	0.8980965	0.30279413	2830.3071
354.13281	0.90288824	0.30459937	2825.1062
355.23389	0.90348077	0.30662483	2826.5369
356.33496	0.90858662	0.30816227	2826.8809
357.43604	0.90929633	0.31018743	2823.2981
358.53711	0.91303372	0.31189477	2827.0964
359.63818	0.91885847	0.31384027	2839.4146
360.73926	0.92227846	0.31540728	2830.7563
361.84033	0.92201149	0.31714305	2836.0576
362.94141	0.92787731	0.31936398	2841.4968
364.04248	0.93236411	0.32139158	2835.8965
365.14355	0.93261588	0.32291344	2836.8787
366.24463	0.93458593	0.32476813	2834.207
367.3457	0.94056708	0.32651147	2835.3079
368.44678	0.94316483	0.32848778	2843.9189
369.54785	0.94528866	0.33015507	2837.0364
370.64893	0.95046157	0.33188111	2835.4543
371.75	0.95272183	0.33374581	2837.5159
372.85107	0.95860887	0.33565986	2850.0945
373.95215	0.96010315	0.33781192	2850.7324
375.05322	0.96352398	0.34015167	2847.5325
376.1543	0.96442491	0.34212181	2842.6111
377.25537	0.97264296	0.34391525	2845.9678
378.35645	0.97247493	0.34569925	2851.95
379.45752	0.97554994	0.34762496	2843.0103
380.55859	0.97950917	0.34930316	2844.9126
381.65967	0.98016936	0.35126054	2849.8887
382.76074	0.98735911	0.35333398	2853.3228
383.86182	0.98924345	0.35477799	2850.4553
384.96289	0.99451482	0.35673729	2857.8054
386.06396	0.99407595	0.35846817	2851.5479
387.16504	0.99993432	0.36041123	2861.5251
388.26611	1.0025795	0.36259836	2859.5271
389.36719	1.0069163	0.36434174	2861.6121
390.46826	1.0138782	0.36660263	2870.3496
391.56934	1.0138172	0.36825991	2859.1157
392.67041	1.0182545	0.37000981	2864.8247
393.77148	1.0217507	0.37208664	2865.2798
394.87256	1.0252995	0.37372792	2868.3503
395.97363	1.0272421	0.37543803	2863.1179
397.07471	1.0277627	0.37682667	2860.155
398.17578	1.0334955	0.37869856	2869.8333
399.27686	1.0341874	0.38111213	2873.9746
400.37793	1.0414546	0.38345239	2878.053
401.479	1.044749	0.3855601	2872.9128
402.58008	1.0454705	0.387319	2867.1604
403.68115	1.0477328	0.38885128	2863.0549
404.78223	1.0543522	0.39053878	2865.0654
405.8833	1.0553243	0.39232174	2875.0203
406.98438	1.0592577	0.39423084	2872.3132
408.08545	1.0639508	0.39596739	2880.9402
409.18652	1.0669936	0.39783907	2879.551
410.2876	1.0694734	0.39936158	2872.0061
411.38867	1.0701174	0.40117958	2876.6189
412.48975	1.0768188	0.40342268	2877.0691
413.59082	1.0801271	0.40560967	2882.8406
414.69189	1.0813597	0.4077296	2881.3047
415.79297	1.086108	0.40970898	2877.2832
416.89404	1.089013	0.41150627	2877.6335
417.99512	1.0906672	0.41317007	2879.824
419.09619	1.0975164	0.41485912	2884.5117
420.19727	1.098971	0.41666803	2883.7061
421.29834	1.103073	0.41823953	2887.9729
422.39941	1.1035547	0.42007923	2880.7241
423.50049	1.1093767	0.42207208	2894.8359
424.60156	1.112474	0.4240433	2892.553
425.70264	1.1164308	0.42609423	2893.1064
426.80371	1.1180466	0.42800668	2894.5457
427.90479	1.1214556	0.42998633	2892.6128
429.00586	1.1258802	0.4317314	2888.7439
430.10693	1.1287169	0.43342966	2891.7246
431.20801	1.1332197	0.43468076	2893.7981
432.30908	1.1362795	0.43638706	2896.158
433.41016	1.1377664	0.43826613	2900.1724
434.51123	1.1398665	0.43997377	2891.2854
435.6123	1.1444712	0.44171286	2899.0127
436.71338	1.152333	0.44363588	2900.7539
437.81445	1.1547018	0.4456161	2906.5251
438.91553	1.1544785	0.44752938	2907.2864
440.0166	1.1578275	0.44960138	2904.8235
441.11768	1.1659777	0.4517349	2906.2449
442.21875	1.1654583	0.45351335	2905.3469
443.31982	1.167263	0.45551887	2905.2351
444.4209	1.1711777	0.45738542	2905.3291
445.52197	1.171737	0.45931393	2901.0491
446.62305	1.1778774	0.46089149	2900.3293
447.72412	1.1790208	0.46250001	2905.6545
448.8252	1.1829702	0.46453705	2909.3955
449.92627	1.1905789	0.46643707	2916.5867
451.02734	1.1916693	0.46814334	2906.6179
452.12842	1.1935942	0.46994081	2911.5398
453.22949	1.1979033	0.47227535	2921.6152
454.33057	1.1992639	0.47437623	2912.0015
455.43164	1.2043579	0.47651535	2923.4834
456.53271	1.2069137	0.47826225	2909.2666
457.63379	1.2083286	0.47981948	2904.8662
458.73486	1.2134758	0.48137096	2911.6289
459.83594	1.2151127	0.48267111	2914.7939
460.93701	1.2226685	0.4841713	2922.5657
462.03809	1.223626	0.48603594	2920.686
463.13916	1.2272383	0.48788208	2919.0947
464.24023	1.2298448	0.49001953	2933.0413
465.34131	1.2361742	0.49205372	2931.5591
466.44238	1.236436	0.49378431	2919.4272
467.54346	1.2386427	0.49588081	2925.9194
468.64453	1.244297	0.49750385	2922.0762
469.74561	1.2488134	0.49927506	2928.9048
470.84668	1.2491276	0.5013054	2925.9524
471.94775	1.2547805	0.50308096	2930.4004
473.04883	1.2566669	0.5048629	2929.4893
474.1499	1.2570693	0.50664103	2926.3547
475.25098	1.2669843	0.50842875	2933.2031
476.35205	1.2685746	0.5103597	2933.9434
477.45313	1.2717196	0.51230347	2939.8318
478.5542	1.2721006	0.51435751	2934.7087
479.65527	1.2767141	0.51644129	2935.2581
480.75635	1.2806393	0.51819229	2936.9194
481.85742	1.2854552	0.5202508	2938.7122
482.9585	1.2873323	0.52196747	2939.3127
484.05957	1.2913175	0.52392894	2947.9297
485.16064	1.2932408	0.52611786	2943.8386
486.26172	1.2952026	0.52837467	2940.5249
487.36279	1.2992939	0.53028786	2942.0176
488.46387	1.3019636	0.5314315	2935.1433
489.56494	1.3057497	0.53298813	2945.3557
490.66602	1.3098948	0.53467053	2944.9121
491.76709	1.3159965	0.53650177	2945.5425
492.86816	1.3174963	0.53819138	2949.5059
493.96924	1.3224872	0.54010224	2952.071
495.07031	1.3227501	0.54196543	2950.8218
496.17139	1.3271446	0.54389048	2955.2603
497.27246	1.3285468	0.54585445	2953.188
498.37354	1.3376539	0.54788047	2958.2627
499.47461	1.336794	0.55005056	2953.5557
500.57568	1.3403161	0.55188072	2946.8257
501.67676	1.3431214	0.55347663	2948.1257
502.77783	1.3458627	0.55523777	2951.8179
503.87891	1.3494675	0.55675989	2947.7561
504.97998	1.3518227	0.55850661	2951.9182
506.08105	1.3594204	0.560426	2962.4592
507.18213	1.3647836	0.56215924	2958.7251
508.2832	1.3626224	0.56404382	2958.7471
509.38428	1.3663467	0.56601477	2954.1785
510.48535	1.3674271	0.56738538	2953.6108
511.58643	1.3717277	0.56940764	2963.4407
512.6875	1.3779815	0.57114643	2962.1316
513.78857	1.3786088	0.57268137	2957.196
514.88965	1.379674	0.57470518	2957.5806
515.99072	1.3843273	0.5765568	2965.9397
517.0918	1.3892114	0.57838911	2967.7834
518.19287	1.3923981	0.58066058	2964.5269
519.29395	1.3955915	0.58254564	2964.9243
520.39502	1.397786	0.58422947	2961.8235
521.49609	1.4034981	0.58600986	2968.8206
522.59717	1.4099305	0.58772802	2974.728
523.69824	1.409093	0.58960283	2968.1357
524.79932	1.4125849	0.59166747	2969.3159
525.90039	1.4137992	0.5933789	2970.5701
527.00146	1.4186711	0.59549648	2978.3655
528.10254	1.4226307	0.59746492	2968.2502
529.20361	1.4261434	0.59888762	2967.9822
530.30469	1.4295915	0.60060579	2978.741
531.40576	1.4335532	0.6024943	2982.092
532.50684	1.4366585	0.60453546	2978.6274
533.60791	1.4381844	0.60650045	2975.2649
534.70898	1.4427652	0.60809749	2976.1711
535.81006	1.4444096	0.60988343	2979.3479
536.91113	1.446448	0.61187267	2977.5452
538.01221	1.4523481	0.61339134	2977.7681
539.11328	1.4554851	0.61497504	2983.0964
540.21436	1.4584175	0.61661601	2987.0962
541.31543	1.4607069	0.61884379	2982.2356
542.4165	1.464875	0.62064505	2979.196
543.51758	1.4689215	0.62239242	2989.4001
544.61865	1.4688694	0.62456071	2984.8357
545.71973	1.4729524	0.6266613	2985.24
546.8208	1.4792643	0.62831217	2982.1875
547.92188	1.4807509	0.63012761	2987.4653
549.02295	1.4855058	0.63187158	2990.0803
550.12402	1.4876595	0.633762	2995.125
551.2251	1.4880483	0.63556069	2989.0193
552.32617	1.4961774	0.63731581	2994.5017
553.42725	1.4967452	0.63909048	2989.2981
554.52832	1.5019172	0.6410231	2996.8386
555.62939	1.5029361	0.6429171	2993.3821
556.73047	1.5089978	0.64467043	2998.2632
557.83154	1.5103993	0.64665926	2999.3716
558.93262	1.5162566	0.64883286	2998.5835
560.03369	1.521806	0.65078139	3002.5293
561.13477	1.5229404	0.65244246	2999.1211
562.23584	1.5236118	0.65376157	3001.2686
563.33691	1.5298544	0.65579939	3002.3892
564.43799	1.5306201	0.6575681	3002.4045
565.53906	1.5336699	0.65912932	2997.4001
566.64014	1.5375707	0.6613	3005.1853
567.74121	1.540796	0.66301727	3001.2473
568.84229	1.5433118	0.66504282	3009.916
569.94336	1.5502303	0.66725844	3015.176
571.04443	1.5529615	0.66931188	3011.7747
572.14551	1.553068	0.67076772	2999.2791
573.24658	1.5572819	0.67241019	3001.1138
574.34766	1.5638058	0.67381936	3005.6204
575.44873	1.5645553	0.67558944	3008.948
576.5498	1.5644125	0.6772843	3009.1628
577.65088	1.5703107	0.67911661	3007.0901
578.75195	1.5764678	0.68065894	3007.8579
579.85303	1.5754979	0.68249351	3012.5376
580.9541	1.5823485	0.68449575	3012.8086
582.05518	1.5844643	0.68621254	3014.4136
583.15625	1.590126	0.68817717	3015.3025
584.25732	1.5925902	0.68978024	3015.1047
585.3584	1.5944861	0.69151574	3018.9402
586.45947	1.5996052	0.69353294	3017.1855
587.56055	1.5998902	0.69530511	3012.9089
588.66162	1.6035036	0.69714969	3023.4998
589.7627	1.6078092	0.69920337	3018.6616
590.86377	1.6139537	0.70102024	3019.6033
591.96484	1.614928	0.7028321	3021.6067
593.06592	1.6167996	0.7045365	3018.3259
594.16699	1.6220596	0.7065568	3022.8323
595.26807	1.6258662	0.70860893	3026.1111
596.36914	1.6297605	0.7104789	3025.1902
597.47021	1.6295962	0.71209663	3022.5732
598.57129	1.6347791	0.71375453	3020.085
599.67236	1.6376954	0.71576226	3027.6541
600.77344	1.6395292	0.71752298	3026.9502
601.87451	1.6419313	0.7194913	3030.5286
602.97559	1.6471962	0.72123379	3026.7119
604.07666	1.6503875	0.72270113	3026.9595
605.17773	1.6553068	0.72463024	3035.8894
606.27881	1.6589553	0.726538	3036.6887
607.37988	1.6612202	0.72818482	3033.5767
608.48096	1.6640539	0.73033923	3034.438
609.58203	1.6679513	0.73220605	3036.5249
610.68311	1.6721621	0.73397428	3028.4363
611.78418	1.6727322	0.7355547	3032.821
612.88525	1.676016	0.73756033	3035.8071
613.98633	1.6806911	0.73982352	3034.3262
615.0874	1.6848147	0.74166435	3032.5171
616.18848	1.684417	0.74339014	3038.0022
617.28955	1.6893532	0.74532735	3034.2209
618.39063	1.6927851	0.74700654	3037.1357
619.4917	1.6972164	0.74872053	3032.9189
620.59277	1.6973835	0.75039124	3036.7581
621.69385	1.7042265	0.75240117	3039.2891
622.79492	1.7074047	0.75419712	3039.5522
623.896	1.708756	0.75558054	3037.4849
624.99707	1.7123522	0.75757211	3035.0088
626.09814	1.7170948	0.75929356	3042.916
627.19922	1.7215832	0.76130366	3042.7393
628.30029	1.7209488	0.7633906	3039.0269
629.40137	1.7276936	0.76518899	3049.2239
630.50244	1.7314137	0.76712906	3043.8789
631.60352	1.7377954	0.7688536	3048.2739
632.70459	1.7347854	0.7707786	3040.9329
633.80566	1.7374266	0.77284265	3048.1724
634.90674	1.7386826	0.77476621	3040.6104
636.00781	1.7472054	0.77675772	3056.1731
637.10889	1.7487986	0.77844256	3052.2095
638.20996	1.7520597	0.78031486	3048.4343
639.31104	1.754274	0.78194219	3046.6228
640.41211	1.7618891	0.78375441	3051.8345
641.51318	1.7613512	0.78584331	3052.7805
642.61426	1.7635366	0.78747052	3048.7068
643.71533	1.7723346	0.78919804	3052.6033
644.81641	1.773914	0.79054737	3050.7986
645.91748	1.7753539	0.79208177	3048.3538
647.01855	1.7777913	0.79354382	3049.708
648.11963	1.7808565	0.79542911	3058.6741
649.2207	1.7864923	0.79775316	3061.9841
650.32178	1.7901121	0.79958338	3057.158
651.42285	1.7953939	0.80153221	3062.9302
652.52393	1.7982156	0.8037315	3062.8147
653.625	1.8009137	0.8054024	3059.0454
654.72607	1.8014791	0.80712575	3064.78
655.82715	1.8034387	0.8089354	3055.4841
656.92822	1.8084226	0.81092626	3059.3762
658.0293	1.8113105	0.81276357	3058.9878
659.13037	1.8176067	0.81463939	3064.9871
660.23145	1.8186961	0.8167187	3063.7744
661.33252	1.8221202	0.81863856	3069.9731
662.43359	1.8271955	0.82014585	3061.927
663.53467	1.8279479	0.82208413	3064.6099
664.63574	1.830408	0.82382637	3067.4612
665.73682	1.8375486	0.82566524	3070.5671
666.83789	1.8386654	0.82725918	3067.1875
667.93896	1.8446398	0.82907009	3072.2209
669.04004	1.8474718	0.83093125	3072.8567
670.14111	1.848405	0.83319324	3071.0032
671.24219	1.8518442	0.83482534	3069.7644
672.34326	1.8536614	0.83689654	3068.3088
673.44434	1.8564942	0.83864576	3066.928
674.54541	1.862164	0.8404752	3075.6804
675.64648	1.8628476	0.84219372	3068.4229
676.74756	1.8668097	0.84377748	3062.6121
677.84863	1.8709062	0.84557927	3074.2339
678.94971	1.8762703	0.84736127	3070.9045
680.05078	1.8764429	0.84922457	3074.0647
681.15186	1.8797346	0.85112172	3074.8608
682.25293	1.8837466	0.85317826	3072.9536
683.354	1.887477	0.85519487	3084.9233
684.45508	1.8926888	0.85717094	3072.1694
685.55615	1.8955731	0.8586899	3075.6501
686.65723	1.8963698	0.8604061	3075.1465
687.7583	1.8994265	0.86251169	3074.1353
688.85938	1.9018993	0.86431056	3080.9053
689.96045	1.9082329	0.86617804	3077.4636
691.06152	1.9082031	0.86783051	3069.9226
692.1626	1.9133997	0.86949205	3080.051
693.26367	1.9174688	0.87149036	3086.1531
694.36475	1.9214158	0.87312323	3084.7856
695.46582	1.9214588	0.87508237	3086.6675
696.56689	1.9286338	0.87728995	3088.8855
697.66797	1.9312145	0.87919116	3087.4067
698.76904	1.9343132	0.88124269	3084.5432
699.87012	1.9386679	0.88283753	3085.2004
700.97119	1.9412813	0.88450098	3082.218
702.07227	1.9410592	0.88637066	3088.7102
703.17334	1.946524	0.8882972	3087.1716
704.27441	1.9496868	0.89006877	3082.1028
705.37549	1.955356	0.8919549	3086.0264
706.47656	1.9585388	0.89379668	3091.6316
707.57764	1.9604696	0.89563322	3088.9583
708.67871	1.9661255	0.89733702	3095.2695
709.77979	1.965844	0.89947283	3091.0898
710.88086	1.9698894	0.90124077	3085.6021
711.98193	1.9740087	0.90314776	3095.207
713.08301	1.9778973	0.90504521	3091.5671
714.18408	1.9810519	0.90693682	3096.7744
715.28516	1.9852341	0.90888488	3099.0957
716.38623	1.9878284	0.9108001	3096.2959
717.4873	1.992473	0.9126519	3096.2615
718.58838	1.9930129	0.91473395	3099.2251
719.68945	1.9978378	0.91657043	3096.7583
720.79053	2.0002067	0.91837692	3091.4424
721.8916	2.0068858	0.92016	3101.2339
722.99268	2.0092747	0.92176503	3097.772
724.09375	2.010464	0.92373812	3097.3176
725.19482	2.0138879	0.92571181	3102.021
726.2959	2.0145142	0.92757607	3092.6069
727.39697	2.019105	0.9289605	3089.4426
728.49805	2.0236194	0.93064618	3098.322
729.59912	2.0313649	0.93225837	3101.6011
730.7002	2.0329976	0.9339602	3107.3811
731.80127	2.0355611	0.93593955	3104.2314
732.90234	2.0358679	0.93755168	3095.7673
734.00342	2.0388169	0.93968111	3105.489
735.10449	2.0440609	0.94173878	3106.6843
736.20557	2.0463421	0.94362611	3102.8767
737.30664	2.0512013	0.94597024	3106.6841
738.40771	2.0546496	0.94788212	3107.4719
739.50879	2.0602567	0.9496178	3110.0134
740.60986	2.0614588	0.95137924	3095.8899
741.71094	2.0616572	0.95326352	3106.8088
742.81201	2.064657	0.95536	3109.8328
743.91309	2.070775	0.95748931	3112.8904
745.01416	2.0728397	0.95940506	3110.2642
746.11523	2.076097	0.96151417	3106.405
747.21631	2.0803204	0.96326262	3113.0774
748.31738	2.0861144	0.96499801	3108.9951
749.41846	2.0865858	0.96672982	3105.5293
750.51953	2.0918846	0.96864295	3110.4312
751.62061	2.0943782	0.97062212	3113.8916
752.72168	2.0954716	0.97236174	3109.7952
753.82275	2.1004612	0.97430432	3114.783
754.92383	2.1018763	0.97597867	3113.8025
756.0249	2.1058931	0.97794122	3114.4111
757.12598	2.1115298	0.97987139	3115.1921
758.22705	2.1090012	0.98154742	3111.4146
759.32813	2.1171272	0.98387253	3116.8892
760.4292	2.121474	0.98588932	3116.1309
761.53027	2.1197271	0.98775232	3109.04
762.63135	2.1248157	0.98952323	3114.6079
763.73242	2.1301126	0.99161488	3120.2585
764.8335	2.1325045	0.99363732	3114.0857
765.93457	2.1343186	0.99521679	3114.3472
767.03564	2.1387203	0.99694061	3114.7395
768.13672	2.1397579	0.99893534	3114.0752
769.23779	2.1458445	1.0006301	3118.2036
770.33887	2.1493084	1.0023878	3112.5413
771.43994	2.1493957	1.0045238	3120.8152
772.54102	2.157083	1.0065362	3121.5742
773.64209	2.159687	1.0088044	3127.2998
774.74316	2.1633956	1.0109501	3128.575
775.84424	2.1659856	1.0130293	3121.624
776.94531	2.166141	1.0149479	3122.5623
778.04639	2.1732979	1.0170244	3123.3882
779.14746	2.1754761	1.0190175	3116.9023
780.24854	2.1818926	1.0207653	3123.373
781.34961	2.1853662	1.0226419	3128.7068
782.45068	2.1829593	1.0244679	3121.1257
783.55176	2.1896987	1.0266107	3131.4595
784.65283	2.1900198	1.0284393	3116.6147
785.75391	2.1952667	1.0301852	3119.3181
786.85498	2.198169	1.0317692	3120.217
787.95605	2.2024405	1.0335869	3129.2366
789.05713	2.2070601	1.0351901	3126.7385
790.1582	2.2051616	1.0369223	3122.4482
791.25928	2.210053	1.0392137	3133.6113
792.36035	2.2142811	1.0409669	3127.8301
793.46143	2.2189822	1.042574	3127.0764
794.5625	2.2240801	1.0447147	3138.1489
795.66357	2.2254889	1.0465865	3133.4268
796.76465	2.2281146	1.0481381	3125.5923
797.86572	2.2269707	1.0503173	3131.511
798.9668	2.2337632	1.0521897	3127.8892
800.06787	2.2378452	1.0541536	3130.6213
801.16895	2.2423885	1.0561051	3136.8616
802.27002	2.2470169	1.0584384	3140.6846
803.37109	2.2465322	1.0605407	3130.5276
804.47217	2.249696	1.0621891	3122.6284
805.57324	2.2559509	1.0642306	3134.9866
806.67432	2.2575402	1.0665023	3134.6865
807.77539	2.2577362	1.0685567	3131.7488
808.87646	2.264586	1.0702655	3128.7856
809.97754	2.270107	1.072256	3141.303
811.07861	2.2712531	1.0738242	3135.5347
812.17969	2.2754476	1.0759947	3142.5208
813.28076	2.2771206	1.077849	3134.8223
814.38184	2.2817051	1.0797621	3131.541
815.48291	2.2832224	1.0822088	3137.4878
816.58398	2.2864499	1.0841062	3133.4041
817.68506	2.2880459	1.0860225	3136.5195
818.78613	2.2937198	1.0880821	3135.4268
819.88721	2.2957597	1.090017	3135.1267
820.98828	2.2996063	1.0919887	3137.3958
822.08936	2.3056755	1.0938147	3138.2114
823.19043	2.3089592	1.0954783	3137.5454
824.2915	2.3109202	1.0972208	3136.0059
825.39258	2.3143787	1.0991931	3139.3984
826.49365	2.3199029	1.1016701	3151.396
827.59473	2.3188679	1.1040454	3142.8042
828.6958	2.3242104	1.1062859	3142.9292
829.79688	2.328881	1.108216	3141.4111
830.89795	2.3293912	1.1100798	3139.4431
831.99902	2.3344889	1.1121409	3145.5415
833.1001	2.3401182	1.1141742	3145.1384
834.20117	2.3405366	1.1160485	3147.2656
835.30225	2.3455591	1.1177002	3143.6311
836.40332	2.3450222	1.1193699	3139.9016
837.50439	2.3487854	1.1209517	3146.6909
838.60547	2.3563428	1.1232831	3154.8691
839.70654	2.3556969	1.1251335	3144.0989
840.80762	2.3591907	1.1272978	3147.9131
841.90869	2.3641388	1.1296817	3144.551
843.00977	2.3679745	1.1317487	3151.3271
844.11084	2.3692627	1.1338285	3149.0146
845.21191	2.3736997	1.136025	3149.9707
846.31299	2.374733	1.1375587	3145.0376
847.41406	2.380784	1.1392266	3142.3269
848.51514	2.3854768	1.1411915	3150.2471
849.61621	2.3901975	1.1432968	3152.3418
850.71729	2.3915117	1.1456078	3155.2305
851.81836	2.3947856	1.1476092	3156.48
852.91943	2.3964467	1.149691	3143.5144
854.02051	2.4008217	1.1516339	3147.1658
855.12158	2.4056637	1.1536468	3156.969
856.22266	2.4067185	1.1558747	3146.5413
857.32373	2.4115918	1.1577798	3149.7241
858.4248	2.4123161	1.1596599	3152.8613
859.52588	2.416553	1.1618217	3154.4646
860.62695	2.4225097	1.1639766	3154.7534
861.72803	2.4233308	1.1657832	3154.384
862.8291	2.4286234	1.1674081	3151.0046
863.93018	2.4296119	1.1693213	3153.0244
865.03125	2.4320736	1.1712348	3155.5603
866.13232	2.438236	1.1732733	3154.4214
867.2334	2.4399536	1.1755105	3154.0715
868.33447	2.4407153	1.1776987	3154.2683
869.43555	2.4462025	1.1795621	3152.5728
870.53662	2.448143	1.1815228	3155.2979
871.6377	2.4550645	1.183419	3150.8865
872.73877	2.4564168	1.185519	3155.3623
873.83984	2.4628797	1.1877102	3159.5898
874.94092	2.4626777	1.1896268	3153.9976
876.04199	2.4670703	1.1914897	3153.3694
877.14307	2.4695501	1.1934155	3161.4543
878.24414	2.4729736	1.195897	3162.5645
879.34521	2.4777112	1.1984117	3164.6245
880.44629	2.4779513	1.2007406	3154.9392
881.54736	2.4851942	1.2028358	3159.9211
882.64844	2.4859157	1.204495	3149.5972
883.74951	2.4895349	1.2064035	3162.0127
884.85059	2.4946573	1.2086744	3166.7317
885.95166	2.4958506	1.2105775	3160.5745
887.05273	2.501338	1.2127966	3165.1177
888.15381	2.5030794	1.2149037	3164.2764
889.25488	2.5086083	1.2168226	3163.0728
890.35596	2.5106678	1.2187659	3165.4719
891.45703	2.5106239	1.2210096	3153.9099
892.55811	2.5163195	1.2231119	3165.1511
893.65918	2.5220447	1.2248935	3162.1819
894.76025	2.5226347	1.2271528	3168.2087
895.86133	2.523736	1.2292227	3158.1304
896.9624	2.5289686	1.231256	3158.926
898.06348	2.5323238	1.2336394	3162.9148
899.16455	2.5357866	1.2356694	3160.1265
900.26563	2.5418563	1.2379202	3167.6855
901.3667	2.5412359	1.2398896	3155.4973
902.46777	2.5448716	1.2415935	3161.8142
903.56885	2.5487196	1.2436364	3162.897
904.66992	2.5534101	1.2461205	3172.0107
905.771	2.5564895	1.2483789	3163.8135
906.87207	2.5603333	1.2501771	3160.8901
907.97314	2.5603707	1.2523201	3161.8401
909.07422	2.5645328	1.2541863	3162.7981
910.17529	2.5669253	1.2562979	3163.2825
911.27637	2.5745771	1.2583828	3171.2466
912.37744	2.5766225	1.2606494	3173.3254
913.47852	2.578912	1.2631471	3166.9199
914.57959	2.584311	1.2655345	3167.2473
915.68066	2.5840697	1.2676605	3167.4565
916.78174	2.5872927	1.2697982	3161.2371
917.88281	2.5908122	1.2718276	3166.9497
918.98389	2.5972328	1.2741754	3171.8691
920.08496	2.5985641	1.2762145	3163.6211
921.18604	2.6020942	1.2781041	3165.7131
922.28711	2.6058607	1.2804637	3168.3271
923.38818	2.6062858	1.282647	3166.7981
924.48926	2.6121752	1.2845932	3168.4341
925.59033	2.6160355	1.2866306	3166.8809
926.69141	2.6192114	1.2888607	3167.3438
927.79248	2.6200588	1.2908709	3161.0854
928.89355	2.624012	1.2928673	3165.3591
929.99463	2.6320071	1.2949406	3176.5994
931.0957	2.6345694	1.2972696	3169.9026
932.19678	2.6373084	1.299071	3173.939
933.29785	2.6397398	1.3010929	3170.0903
934.39893	2.6390748	1.3030854	3167.116
935.5	2.6459355	1.3054866	3172.603
936.60107	2.648294	1.3076795	3168.241
937.70215	2.6520481	1.3099855	3171.2383
938.80322	2.6546757	1.3122656	3170.4773
939.9043	2.6588051	1.3146045	3171.5503
941.00537	2.6640193	1.316993	3175.7817
942.10645	2.6643479	1.319015	3169.5264
943.20752	2.665036	1.3206872	3158.8594
944.30859	2.6695542	1.3225877	3168.2019
945.40967	2.6777909	1.3246094	3173.2195
946.51074	2.6774879	1.3268327	3173.1707
947.61182	2.6823008	1.329201	3175.6733
948.71289	2.6876905	1.331529	3178.1772
949.81396	2.690304	1.3340374	3172.2446
950.91504	2.6911902	1.3366067	3178.9971
952.01611	2.692018	1.3386024	3166.3306
953.11719	2.6966214	1.34104	3175.6741
954.21826	2.6994781	1.3432537	3168.4773
955.31934	2.7024984	1.3452202	3169.4639
956.42041	2.7108839	1.3473513	3177.8582
957.52148	2.7110314	1.3500203	3170.8777
958.62256	2.7154849	1.3524361	3175.8062
959.72363	2.718812	1.3546635	3171.7659
960.82471	2.7218034	1.356662	3170.991
961.92578	2.7238553	1.358593	3172.5034
963.02686	2.7241018	1.3609195	3170.0547
964.12793	2.7293284	1.3634424	3180.175
965.229	2.7339191	1.3660669	3178.9458
966.33008	2.7353907	1.3684568	3170.9211
967.43115	2.7436681	1.3705282	3175.7461
968.53223	2.7452629	1.3726052	3171.4521
969.6333	2.7482431	1.3743469	3173.1826
970.73438	2.7501621	1.3763865	3174.5791
971.83545	2.7528865	1.3790305	3178.9995
972.93652	2.75895	1.381318	3177.3584
974.0376	2.7630613	1.3838159	3177.7944
975.13867	2.7627742	1.3856668	3172.9258
976.23975	2.7640779	1.387929	3170.5063
977.34082	2.7707086	1.3900952	3173.8184
978.44189	2.7763619	1.392485	3178.0063
979.54297	2.7757926	1.3946971	3175.7844
980.64404	2.7787356	1.3969364	3164.0906
981.74512	2.7817652	1.3993146	3173.0081
982.84619	2.7869842	1.4014515	3175.8779
983.94727	2.7892962	1.4039413	3179.449
985.04834	2.7938023	1.4062619	3176.0735
986.14941	2.7940664	1.4089209	3178.0349
987.25049	2.7992148	1.4113065	3175.9124
988.35156	2.8028648	1.4140139	3172.6567
989.45264	2.8074136	1.4158427	3171.4043
990.55371	2.8112614	1.4180205	3175.7146
991.65479	2.814276	1.4200563	3175.231
992.75586	2.8174603	1.4223233	3182.3218
993.85693	2.8238778	1.4251966	3188.0339
994.95801	2.8235524	1.4275395	3175.3716
996.05908	2.8270359	1.4298559	3174.6372
997.16016	2.8274846	1.4322269	3175.415
998.26123	2.8332438	1.4342487	3173.2964
999.3623	2.834116	1.4370204	3179.1563
1000.4634	2.839709	1.4399012	3184.8608
1001.5645	2.84395	1.442366	3176.967
1002.6655	2.846858	1.4444219	3171.334
1003.7666	2.8507318	1.4465654	3176.7859
1004.8677	2.8559909	1.448701	3180.4907
1005.9688	2.8576303	1.4507936	3178.7903
1007.0698	2.8580501	1.4530553	3173.5754
1008.1709	2.8637137	1.4553406	3182.1982
1009.272	2.8678896	1.4574279	3179.6536
1010.373	2.8708005	1.4596813	3179.5356
1011.4741	2.8705101	1.4619718	3175.7485
1012.5752	2.8746982	1.4643945	3178.6392
1013.6763	2.8789444	1.4670073	3177.7451
1014.7773	2.8811193	1.4697291	3180.7874
1015.8784	2.8849983	1.4722801	3177.7454
1016.9795	2.8894098	1.4743235	3174.6252
1018.0806	2.8930399	1.4766151	3176.4368
1019.1816	2.895159	1.4791799	3176.4976
1020.2827	2.8988228	1.4818183	3178.3967
1021.3838	2.9021614	1.4847245	3178.7749
1022.4849	2.9026308	1.4874427	3173.6084
1023.5859	2.9101026	1.4901607	3175.9707
1024.687	2.9137208	1.4930297	3180.7666
1025.7881	2.9128535	1.4956486	3171.8738
1026.8892	2.9193029	1.4980136	3171.7871
1027.9902	2.9212754	1.5002307	3174.9805
1029.0913	2.9242635	1.5029918	3178.9695
1030.1924	2.9283266	1.5057316	3178.8721
1031.2935	2.9312959	1.5083076	3177.4111
1032.3945	2.9390647	1.5107429	3175.4702
1033.4956	2.9362996	1.5130067	3173.7954
1034.5967	2.9414756	1.5153799	3171.8833
1035.6978	2.9451308	1.5175285	3171.9785
1036.7988	2.9488358	1.5202568	3179.1462
1037.8999	2.9518335	1.5228297	3175.7554
1039.001	2.9558122	1.5251729	3181.8904
1040.1021	2.9584582	1.5271385	3174.1965
1041.2031	2.962939	1.5294645	3173.3542
1042.3042	2.9641757	1.5315578	3177.8416
1043.4053	2.9689555	1.5341251	3179.4238
1044.5063	2.9706583	1.5366701	3177.7068
1045.6074	2.9751723	1.539417	3178.6506
1046.7085	2.9793599	1.5419682	3176.229
1047.8096	2.9794517	1.5443764	3163.7488
1048.9106	2.9855902	1.546489	3174.7114
1050.0117	2.9895675	1.548986	3178.5747
1051.1128	2.9939871	1.5520214	3182.8145
1052.2139	2.9956119	1.5545862	3170.9229
1053.3149	2.9973323	1.5570612	3177.7996
1054.416	3.0043697	1.5594956	3175.4905
1055.5171	3.0055282	1.5620009	3179.9224
1056.6182	3.0058341	1.5647134	3173.3083
1057.7192	3.0096381	1.5680233	3180.9758
1058.8203	3.016355	1.5712646	3183.4519
1059.9214	3.0173306	1.5736686	3169.0869
1061.0225	3.0229571	1.5762341	3178.0801
1062.1235	3.026649	1.5787299	3177.2014
1063.2246	3.0313542	1.5813382	3182.5076
1064.3257	3.0325656	1.5837477	3177.6416
1065.4268	3.0352683	1.5862929	3173.2368
1066.5278	3.0369494	1.588608	3174.7529
1067.6289	3.0420494	1.5912068	3171.8083
1068.73	3.0456445	1.5941423	3179.0547
1069.8311	3.0481734	1.5966332	3174.4165
1070.9321	3.0514829	1.5995007	3176.425
1072.0332	3.0522566	1.601842	3167.6516
1073.1343	3.0576873	1.6041883	3170.1912
1074.2354	3.0589488	1.606532	3171.6885
1075.3364	3.0652108	1.6090472	3175.9456
1076.4375	3.0685179	1.6117423	3177.1299
1077.5386	3.0706213	1.6143426	3175.8923
1078.6396	3.0723085	1.6169237	3174.9492
1079.7407	3.0745435	1.6195271	3172.8416
1080.8418	3.0806677	1.621929	3176.0396
1081.9429	3.0846508	1.6244793	3173.4263
1083.0439	3.0867949	1.6272042	3174.7949
1084.145	3.0931511	1.6299762	3175.6191
1085.2461	3.0903351	1.6325364	3171.324
1086.3472	3.1020355	1.6349602	3172.814
1087.4482	3.1005511	1.6368887	3162.5359
1088.5493	3.1036823	1.6391735	3174.3047
1089.6504	3.107255	1.6416025	3179.8811
1090.7515	3.1100287	1.6439596	3176.3098
1091.8525	3.1150455	1.6468474	3176.2712
1092.9536	3.1159134	1.6497749	3171.5769
1094.0547	3.1207936	1.6525863	3173.3232
1095.1558	3.1247346	1.6551738	3170.5273
1096.2568	3.1260002	1.657728	3175.8188
1097.3579	3.1304734	1.6601734	3170.7012
1098.459	3.1341734	1.6632354	3173.2356
1099.5601	3.1372457	1.6662186	3174.5649
1100.6611	3.139538	1.6693619	3171.6367
1101.7622	3.1442316	1.6722726	3169.2476
1102.8633	3.1483209	1.675488	3171.783
1103.9644	3.1513724	1.6783382	3169.113
1105.0654	3.1528044	1.6808056	3159.6453
1106.1665	3.1563835	1.6835984	3173.043
1107.2676	3.1587093	1.6861956	3168.3633
1108.3687	3.1633809	1.6890601	3172.4387
1109.4697	3.1674039	1.6919748	3167.3682
1110.5708	3.17103	1.6942874	3162.1663
1111.6719	3.1757903	1.6968056	3166.1421
1112.7729	3.1763456	1.6993414	3167.9788
1113.874	3.1793265	1.70208	3172.1909
1114.9751	3.1828642	1.7053293	3167.9507
1116.0762	3.1845601	1.7083368	3174.3992
1117.1772	3.1896064	1.7110475	3166.571
1118.2783	3.1914716	1.7140404	3167.2109
1119.3794	3.1945858	1.7172948	3162.7764
1120.4805	3.2007568	1.7201183	3160.9431
1121.5815	3.2043035	1.7226365	3170.7429
1122.6826	3.2061629	1.7254244	3160.9468
1123.7837	3.2077985	1.7281682	3160.5376
1124.8848	3.2136252	1.7310667	3162.0767
1125.9858	3.2154489	1.7335966	3164.7913
1127.0869	3.2201703	1.7367417	3173.7314
1128.188	3.2229757	1.7399877	3158.7668
1129.2891	3.2280855	1.743222	3172.0039
1130.3901	3.2289791	1.7465229	3159.0547
1131.4912	3.2325699	1.749741	3158.9651
1132.5923	3.2349744	1.7524896	3156.0317
1133.6934	3.2387078	1.7552788	3160.8672
1134.7944	3.2402301	1.7580045	3157.8154
1135.8955	3.2479429	1.7607508	3165.7722
1136.9966	3.2497063	1.7640474	3161.5696
1138.0977	3.2527866	1.767089	3158.7712
1139.1987	3.2572565	1.770218	3158.864
1140.2998	3.2604158	1.7729921	3162.9009
1141.4009	3.2613554	1.7764144	3160.1189
1142.502	3.2693126	1.7802135	3159.9146
1143.603	3.2700016	1.7829077	3160.7649
1144.7041	3.2733951	1.7854456	3151.4021
1145.8052	3.2742846	1.7880179	3155.3687
1146.9063	3.2787526	1.7903483	3150.5896
1148.0073	3.2810543	1.7927681	3157.1279
1149.1084	3.2853835	1.7958411	3162.1606
1150.2095	3.2871618	1.7988042	3155.9436
1151.3105	3.290869	1.8019769	3149.2744
1152.4116	3.2970223	1.8045028	3155.3438
1153.5127	3.2976897	1.8072928	3153.7644
1154.6138	3.3015563	1.8103495	3158.7695
1155.7148	3.3052986	1.813822	3155.345
1156.8159	3.3063028	1.8170286	3149.437
1157.917	3.3132951	1.820312	3151.6418
1159.0181	3.3121376	1.8237678	3142.9712
1160.1191	3.3195751	1.8265539	3147.8513
1161.2202	3.3221707	1.8289258	3143.7722
1162.3213	3.3254714	1.8323298	3150.0569
1163.4224	3.3274508	1.8349521	3136.4417
1164.5234	3.3319089	1.8381256	3148.5977
1165.6245	3.3363585	1.8419918	3149.5781
1166.7256	3.3385537	1.8458863	3149.5461
1167.8267	3.3404777	1.8493203	3140.3701
1168.9277	3.3475177	1.8531042	3146.72
1170.0288	3.3478134	1.8566099	3145.8528
1171.1299	3.3493445	1.8596312	3135.623
1172.231	3.3573208	1.8626914	3139.4224
1173.332	3.3592093	1.8657699	3141.2874
1174.4331	3.3619764	1.8690504	3140.1433
1175.5342	3.3663058	1.8719462	3138.6926
1176.6353	3.3665385	1.875138	3135.9639
1177.7363	3.3695629	1.8782345	3130.2605
1178.8374	3.3744655	1.881042	3134.7625
1179.9385	3.3756962	1.8841028	3134.7842
1181.0396	3.3815167	1.8874794	3140.5469
1182.1406	3.3836615	1.8909714	3133.3022
1183.2417	3.3872008	1.8941553	3129.9617
1184.3428	3.3932393	1.8973051	3126.7754
1185.4438	3.3894801	1.9005071	3120.8938
1186.5449	3.3953481	1.9032311	3115.4907
1187.646	3.4010043	1.9060534	3124.5046
1188.7471	3.4059682	1.9087831	3130.6687
1189.8481	3.406234	1.9120156	3124.1445
1190.9492	3.4106123	1.9152968	3128.3123
1192.0503	3.4146004	1.9190161	3126.2568
1193.1514	3.4175799	1.9229363	3127.2747
1194.2524	3.4202313	1.9269638	3123.6533
1195.3535	3.4264846	1.9308486	3120.6343
1196.4546	3.4301026	1.9337983	3113.325
1197.5557	3.4308572	1.9364771	3115.8948
1198.6567	3.4334137	1.9392092	3118.0374
1199.7578	3.4380844	1.9422656	3118.7063
1200.8589	3.4414036	1.9456992	3120.45
1201.96	3.4422634	1.9489679	3116.2324
1203.061	3.4476585	1.9521632	3109.6404
1204.1621	3.4526722	1.9557282	3115.342
1205.2632	3.4547358	1.9590863	3106.8691
1206.3643	3.4601479	1.9623519	3109.4421
1207.4653	3.4577672	1.9656241	3105.1033
1208.5664	3.4638755	1.9687502	3102.5344
1209.6675	3.4680223	1.9717813	3106.2722
1210.7686	3.471375	1.9754428	3111.8464
1211.8696	3.474004	1.978723	3094.5066
1212.9707	3.4793634	1.982036	3106.1282
1214.0718	3.4830532	1.9858484	3106.085
1215.1729	3.4857876	1.9894973	3098.6567
1216.2739	3.4852064	1.9929614	3090.7847
1217.375	3.4893675	1.9952779	3086.8958
1218.4761	3.4971411	1.9980266	3093.9219
1219.5771	3.4930999	2.0004835	3080.3481
1220.6782	3.5008574	2.0036862	3099.4094
1221.7793	3.5014913	2.0075383	3094.3557
1222.8804	3.5080416	2.0112863	3085.8916
1223.9814	3.5114448	2.0146008	3089.6616
1225.0825	3.5139158	2.0178194	3089.0295
1226.1836	3.5162399	2.0207748	3076.8875
1227.2847	3.5195045	2.0239224	3083.5149
1228.3857	3.5258162	2.026911	3084.1777
1229.4868	3.5271757	2.0291643	3078.0015
1230.5879	3.528239	2.0307105	3074.5078
1231.689	3.5320649	2.0314891	3069.5415
1232.79	3.5368736	2.0321658	3074.2146
1233.8911	3.541786	2.0327351	3077.4209
1234.9922	3.5441492	2.0331812	3077.6995
1236.0933	3.5454929	2.0335829	3073.4243
1237.1943	3.5499053	2.0337579	3070.7805
1238.2954	3.5542395	2.0337336	3069.9961
1239.3965	3.5551958	2.0339174	3062.4856
1240.4976	3.5630102	2.0339229	3067.7908
1241.5986	3.5629435	2.0342042	3063.4338
1242.6997	3.5695205	2.0343208	3061.9258
1243.8008	3.569571	2.0344212	3050.1091
1244.9019	3.571826	2.0343583	3056.9792
1246.0029	3.5748229	2.0343049	3054.2825
1247.104	3.5776567	2.0343688	3056.3523
1248.2051	3.5851064	2.0343232	3044.5935
1249.3062	3.5850585	2.0346522	3038.3247
1250.4072	3.5892177	2.0344887	3043.7637
1251.5083	3.5925875	2.034497	3047.988
1252.6094	3.5972869	2.0344536	3041.6768
1253.7104	3.6000993	2.0345755	3038.8191
1254.8115	3.6024678	2.0346773	3040.283
1255.9126	3.6073492	2.034735	3029.1917
1257.0137	3.6075971	2.0343752	3030.2439
1258.1147	3.6121044	2.0345347	3023.7151
1259.2158	3.6170878	2.0345988	3029.321
1260.3169	3.6200469	2.0345385	3025.8162
1261.418	3.6208255	2.0344419	3024.4048
1262.519	3.62378	2.0344129	3021.5576
1263.6201	3.6322346	2.0344884	3015.3999
1264.7212	3.6298187	2.0344062	3019.4968
1265.8223	3.6371117	2.0343595	3015.8774
1266.9233	3.6383579	2.0343964	3016.5183
1268.0244	3.6462255	2.0343108	3009.7202
1269.1255	3.6446695	2.0345573	2998.0032
1270.2266	3.6510055	2.034384	3003.4961
1271.3276	3.6515236	2.0343955	3000.3726
1272.4287	3.6569483	2.034358	2999.7207
1273.5298	3.658839	2.0341816	2991.2163
1274.6309	3.6643643	2.0343461	2997.4949
1275.7319	3.667239	2.034302	2997.436
1276.833	3.6673288	2.0344164	2989.4756
1277.9341	3.6720097	2.0346048	2989.0439
1279.0352	3.6754994	2.0344944	2980.5757
1280.1362	3.6778324	2.0346787	2973.3022
1281.2373	3.6820822	2.034616	2971.3516
1282.3384	3.6850898	2.0346818	2983.7522
1283.4395	3.6869805	2.0344198	2966.9197
1284.5405	3.6907132	2.0343158	2958.874
1285.6416	3.6952453	2.0344286	2960.2859
1286.7427	3.6944821	2.0344112	2958.0818
1287.8438	3.7003374	2.0344281	2956.2671
1288.9448	3.7048965	2.0343044	2954.3152
1290.0459	3.7058058	2.0341821	2950.2065
1291.147	3.7122045	2.0340798	2951.5293
1292.248	3.7166166	2.0340905	2937.8142
1293.3491	3.7173586	2.0343206	2938.3389
1294.4502	3.7232413	2.034225	2937.4534
1295.5513	3.7271266	2.0340075	2937.4294
1296.6523	3.7279596	2.0341432	2940.6431
1297.7534	3.7285569	2.0342712	2929.8738
1298.8545	3.7366617	2.0341907	2931.4468
1299.9556	3.7360556	2.0342653	2921.1428
1301.0566	3.7427983	2.0340791	2921.4792
1302.1577	3.7446184	2.0340853	2919.166
1303.2588	3.7487836	2.0341711	2904.7737
1304.3599	3.7496829	2.0342133	2905.8625
1305.4609	3.7556238	2.0343683	2903.2334
1306.562	3.7571344	2.0341568	2890.8289
1307.6631	3.7625716	2.0341742	2895.7659
1308.7642	3.76436	2.0341363	2888.917
1309.8652	3.76794	2.0341637	2887.6516
1310.9663	3.7708213	2.0342131	2882.6912
1312.0674	3.7760584	2.034189	2882.1101
1313.1685	3.7779818	2.0341506	2868.0181
1314.2695	3.7809353	2.03422	2867.0298
1315.3706	3.7831867	2.0341845	2865.1729
1316.4717	3.788821	2.0342591	2873.2876
1317.5728	3.7889521	2.0341809	2854.749
1318.6738	3.7947547	2.0338988	2853.2207
1319.7749	3.7977605	2.033977	2846.6145
1320.876	3.8014221	2.0340261	2841.321
1321.9771	3.8033562	2.0340858	2839.0349
1323.0781	3.8084211	2.0337815	2839.2339
1324.1792	3.8088574	2.033839	2829.0916
1325.2803	3.8126965	2.0338078	2828.9556
1326.3813	3.8204358	2.0338881	2823.2419
1327.4824	3.8219719	2.0338418	2808.4761
1328.5835	3.8253367	2.0338473	2806.3123
1329.6846	3.8289309	2.0337658	2805.0193
1330.7856	3.8311408	2.0336957	2803.0742
1331.8867	3.8355169	2.0339355	2782.7324
1332.9878	3.8398659	2.0339813	2781.5349
1334.0889	3.8419142	2.0337942	2771.3223
1335.1899	3.8446043	2.0339231	2756.6733
1336.291	3.8452454	2.0338364	2750.2798
1337.3921	3.8512924	2.0339155	2744.9622
1338.4932	3.8515842	2.0340912	2727.4355
1339.5942	3.8592448	2.0338173	2711.9587
1340.6953	3.8636448	2.0337923	2700.3625
1341.6963	3.8678856	2.0338113	2658.0752