File: datasets/am_bench_2022/raw_data/60-XY.15-3/specimen.dat
MTS793|MPT|ENU|1|2|.|/|:|1|0|0|A

Operator Information						Time:	18.51001	Sec	11/2/2021 9:59:50 AM
Operator	Nick Derimow
Project	AM Bench 2022 mini-tensile challenge
Specimen ID	60-XY.15-3
Material	PBF-L Inconel 625
Specimen Width	2.55	mm
Specimen Thickness	1.51	mm
Notes
Operator Information End

Data Acquisition						Time:	1019.5044	Sec	11/2/2021 10:16:31 AM
Time	Axial Displacement	Axial Extensometer	Axial Force
Sec	mm	mm	N
18.624268	0.0027549972	-4.6755049e-05	76.485252
19.525146	0.0053275572	3.9774506e-05	87.168846
20.426025	0.008584504	-1.4208728e-06	99.387466
21.326904	0.0056580463	7.1581781e-05	107.6864
22.227783	0.012602979	8.2222788e-05	119.29767
23.128662	0.014304752	0.000336347	132.6273
24.029541	0.015710508	0.00044031075	141.90599
24.93042	0.019424107	0.00045289105	152.58994
25.831299	0.024322588	0.00056650618	168.26291
26.732178	0.027239366	0.00062521867	184.20161
27.633057	0.027183635	0.00080352917	196.33417
28.533936	0.032662984	0.00084977306	211.64339
29.434814	0.032073513	0.00097832363	222.95923
30.335693	0.037718002	0.0012560585	246.07431
31.236572	0.03819048	0.0013767014	259.41156
32.137451	0.043428261	0.0014192532	278.97205
33.03833	0.043659735	0.0015660134	294.50226
33.939209	0.045461956	0.0016611689	307.77963
34.840088	0.048830774	0.0017976079	332.42303
35.740967	0.05099253	0.0020147411	348.98776
36.641846	0.054686662	0.0020397818	371.56485
37.542725	0.059086643	0.0021890397	384.07205
38.443604	0.058442261	0.0022689586	405.84729
39.344482	0.063809738	0.0024169451	433.39117
40.245361	0.067236081	0.0025034572	455.28107
41.14624	0.068305202	0.0026398839	473.78891
42.047119	0.072862335	0.0027017037	500.77634
42.947998	0.072861105	0.0027974851	517.09204
43.848877	0.074796095	0.0028755884	540.90094
44.749756	0.078807808	0.0030781294	560.37189
45.650635	0.081611894	0.0030780474	585.25476
46.551514	0.083015807	0.0032552227	608.40479
47.452393	0.087217458	0.0033965625	632.10614
48.353271	0.089152649	0.003439642	652.03442
49.25415	0.094732963	0.0035972635	680.96582
50.155029	0.096799284	0.0037358005	693.88593
51.055908	0.096097328	0.0037980177	714.93158
51.956787	0.09933722	0.0039570113	745.50214
52.857666	0.10388554	0.0039443448	769.60156
53.758545	0.10552426	0.0040645944	794.1601
54.659424	0.10953987	0.0042516976	815.0528
55.560303	0.11085849	0.0043162098	829.57874
56.461182	0.11478625	0.0043709977	856.67352
57.362061	0.11351819	0.0046871854	881.34344
58.262939	0.11883915	0.0047230194	900.18579
59.163818	0.12217042	0.0047255112	930.04962
60.064697	0.12458808	0.004960191	954.29645
60.965576	0.13059221	0.0051759272	995.14355
61.866455	0.12753093	0.0053660013	1016.6744
62.767334	0.13226223	0.0053063012	1034.616
63.668213	0.13414881	0.0054548327	1058.2104
64.569092	0.13864386	0.00557716	1089.41
65.469971	0.14052579	0.0057054167	1112.6049
66.37085	0.14376511	0.0057857111	1143.1244
67.271729	0.1451202	0.0060189734	1156.7472
68.172607	0.14933518	0.0061579081	1188.2267
69.073486	0.15139161	0.0061723078	1208.0978
69.974365	0.15098859	0.0063458728	1241.1418
70.875244	0.15667719	0.0064508333	1263.4048
71.776123	0.1608272	0.006658549	1296.1174
72.677002	0.16343254	0.0067233597	1325.681
73.577881	0.16694044	0.0068779071	1346.5256
74.47876	0.16637944	0.0070177112	1359.5103
75.379639	0.1696454	0.006998546	1388.0596
76.280518	0.17224808	0.0072041918	1412.8495
77.181396	0.17500053	0.0073514213	1439.1697
78.082275	0.17819104	0.0073844497	1467.6353
78.983154	0.18069398	0.0076684821	1501.1564
79.884033	0.18322091	0.0076428428	1519.478
80.784912	0.18867645	0.0078142071	1552.0996
81.685791	0.19107571	0.0078644305	1569.2996
82.58667	0.19353394	0.0080462396	1590.4624
83.487549	0.19661653	0.0081338342	1611.5288
84.388428	0.19806813	0.0083279163	1643.8002
85.289307	0.20029058	0.0084591107	1672.1917
86.190186	0.20258613	0.0085956892	1693.5508
87.091064	0.20568095	0.0086159939	1710.9086
87.991943	0.20937453	0.00881737	1736.817
88.892822	0.21122223	0.0089937104	1763.2987
89.793701	0.21432485	0.0090706954	1788.0934
90.69458	0.21607579	0.0090825576	1811.4879
91.595459	0.21876699	0.0092215547	1828.9067
92.496338	0.21955787	0.0093863336	1852.3352
93.397217	0.22370097	0.0095237698	1879.2898
94.298096	0.22347313	0.0095945382	1895.4673
95.198975	0.23207881	0.0096384287	1916.3188
96.099854	0.23547815	0.0098366011	1942.3949
97.000732	0.23586969	0.009950052	1960.0623
97.901611	0.23849696	0.010079104	1985.1075
98.80249	0.24041823	0.010115897	2008.7915
99.703369	0.2426943	0.010287762	2029.2941
100.60425	0.24815726	0.010317004	2048.3782
101.50513	0.24978368	0.010478025	2076.8767
102.40601	0.25366408	0.010553909	2091.6675
103.30688	0.25517282	0.010637007	2108.8811
104.20776	0.25738648	0.010700621	2125.3911
105.10864	0.2604858	0.01084213	2143.5613
106.00952	0.26148424	0.01094214	2162.802
106.9104	0.264725	0.010864885	2175.1731
107.81128	0.26929808	0.01106945	2199.6101
108.71216	0.27176061	0.010998516	2214.0188
109.61304	0.2743955	0.01120536	2234.2009
110.51392	0.27547324	0.011300256	2242.3081
111.41479	0.27923334	0.0113252	2255.8472
112.31567	0.28235048	0.011391661	2269.9607
113.21655	0.28646648	0.011506489	2289.2712
114.11743	0.28980684	0.011505476	2298.2544
115.01831	0.28886494	0.01163395	2315.832
115.91919	0.29152361	0.011767901	2324.3975
116.82007	0.29753971	0.011860254	2342.8462
117.72095	0.29840991	0.011959182	2356.7568
118.62183	0.2992208	0.012080144	2364.0242
119.52271	0.30429411	0.01211273	2381.3325
120.42358	0.3112736	0.01222989	2393.374
121.32446	0.30831462	0.012217219	2399.4216
122.22534	0.31026331	0.012263638	2417.0049
123.12622	0.31420144	0.012368058	2426.9614
124.0271	0.31873769	0.012466216	2429.9431
124.92798	0.32205713	0.012635839	2451.7039
125.82886	0.3231684	0.012670638	2468.3369
126.72974	0.32258999	0.012736305	2470.1448
127.63062	0.33009532	0.012953708	2483.1931
128.53149	0.33103392	0.012939149	2491.1582
129.43237	0.33374131	0.013212773	2508.4463
130.33325	0.33752352	0.013246374	2509.7568
131.23413	0.3364124	0.013275445	2518.0186
132.13501	0.34125167	0.013485963	2536.1272
133.03589	0.34408185	0.013580949	2540.7681
133.93677	0.34709409	0.01364448	2551.1577
134.83765	0.34847179	0.01374788	2559.7729
135.73853	0.35269016	0.013931656	2568.479
136.6394	0.35668677	0.014055422	2574.7898
137.54028	0.35847446	0.014222013	2579.8521
138.44116	0.36169139	0.014315533	2590.1648
139.34204	0.36427626	0.014444932	2595.4697
140.24292	0.3685289	0.014583731	2609.5403
141.1438	0.37055734	0.014774974	2618.0525
142.04468	0.37046963	0.014917212	2628.0544
142.94556	0.37375236	0.015154363	2636.6653
143.84644	0.37672034	0.01527219	2643.249
144.74731	0.38165447	0.015571463	2649.7915
145.64819	0.38173684	0.015732439	2658.6816
146.54907	0.38469815	0.015931316	2667.3914
147.44995	0.3897281	0.016163608	2671.3359
148.35083	0.38755098	0.016353117	2672.8831
149.25171	0.39217758	0.016635368	2685.5813
150.15259	0.39393815	0.016903058	2695.2317
151.05347	0.40129164	0.017089454	2702.7278
151.95435	0.40268895	0.017256835	2704.1089
152.85522	0.40484378	0.017588533	2706.5581
153.7561	0.40603065	0.01785405	2720.5813
154.65698	0.41086936	0.018179843	2732.0984
155.55786	0.41198459	0.018618435	2737.2515
156.45874	0.41479114	0.018863404	2740.1577
157.35962	0.41801566	0.019288749	2745.5579
158.2605	0.42166471	0.019601654	2749.8657
159.16138	0.42410374	0.019863781	2761.542
160.06226	0.42686602	0.020180777	2762.446
160.96313	0.42909771	0.020692863	2769.6411
161.86401	0.43311059	0.021111527	2773.635
162.76489	0.43608809	0.021500677	2784.5186
163.66577	0.43807101	0.021907749	2781.4551
164.56665	0.44079947	0.022419864	2794.1011
165.46753	0.44115928	0.022955485	2794.9358
166.36841	0.44214603	0.023486298	2798.0183
167.26929	0.44511712	0.024058662	2808.0024
168.17017	0.44838753	0.024661601	2808.2764
169.07104	0.45292851	0.025248282	2815.6162
169.97192	0.45343497	0.02567604	2826.1462
170.8728	0.45881596	0.02630393	2822.4993
171.77368	0.46287274	0.026955632	2824.0876
172.67456	0.46648574	0.027423752	2835.209
173.57544	0.46503454	0.028128542	2840.731
174.47632	0.4711062	0.028810149	2845.9297
175.3772	0.47101521	0.02958582	2849.2209
176.27808	0.47424221	0.030350456	2854.5781
177.17896	0.47596368	0.030885035	2849.6968
178.07983	0.48039952	0.031480785	2854.5315
178.98071	0.4816967	0.032178845	2856.9407
179.88159	0.48297521	0.032737315	2859.8452
180.78247	0.48856106	0.033356018	2869.9902
181.68335	0.49118426	0.034292445	2875.408
182.58423	0.4929736	0.035052508	2875.3987
183.48511	0.49885958	0.035748489	2878.7676
184.38599	0.4979974	0.036564093	2878.8315
185.28687	0.50288445	0.037269183	2885.0078
186.18774	0.50529784	0.038084287	2888.4941
187.08862	0.5103727	0.038899302	2890.6292
187.9895	0.50899893	0.039634563	2892.3147
188.89038	0.51246053	0.040498383	2899.49
189.79126	0.51567435	0.041313924	2903.6042
190.69214	0.51876414	0.042118832	2905.5483
191.59302	0.51885575	0.042932637	2902.009
192.4939	0.52180672	0.043885279	2907.1733
193.39478	0.52779847	0.04476339	2915.9758
194.29565	0.52987176	0.045590937	2917.5405
195.19653	0.53202778	0.046524432	2915.5178
196.09741	0.53386623	0.047283184	2922.6763
196.99829	0.53762555	0.04828554	2927.9917
197.89917	0.53836972	0.049109355	2928.3767
198.80005	0.54301041	0.049917359	2926.4475
199.70093	0.54575902	0.050768338	2934.8708
200.60181	0.5494138	0.051835574	2941.6509
201.50269	0.55134654	0.05288491	2939.8411
202.40356	0.55528241	0.053946812	2943.5596
203.30444	0.55667567	0.054881725	2944.2791
204.20532	0.55771691	0.055903535	2950.2952
205.1062	0.56195629	0.056807991	2946.9485
206.00708	0.56606817	0.057785794	2948.8435
206.90796	0.56462699	0.058954213	2950.9988
207.80884	0.56863254	0.059926677	2955.8101
208.70972	0.57337987	0.060858056	2949.5371
209.6106	0.5741381	0.061642498	2958.7214
210.51147	0.57900178	0.062759072	2964.9236
211.41235	0.5805952	0.063752867	2967.4363
212.31323	0.58564758	0.064608596	2963.4238
213.21411	0.5829547	0.065640815	2971.3892
214.11499	0.58996683	0.066699237	2977.4636
215.01587	0.59221011	0.067688458	2973.7817
215.91675	0.59409118	0.068740457	2971.9763
216.81763	0.59861392	0.069572546	2973.9722
217.71851	0.59912103	0.07068149	2981.6062
218.61938	0.60272747	0.071815141	2991.6125
219.52026	0.60340053	0.072806306	2982.593
220.42114	0.60816723	0.073721476	2988.2527
221.32202	0.61105889	0.07470943	2991.3169
222.2229	0.6110884	0.075606689	2984.8462
223.12378	0.61350405	0.07648468	2987.5737
224.02466	0.61594176	0.077337094	2995.1213
224.92554	0.62193125	0.078317784	2990.2639
225.82642	0.62466347	0.079102062	2994.8899
226.72729	0.62685579	0.080160275	3002.0623
227.62817	0.62741226	0.081309706	3008.3394
228.52905	0.63127476	0.082304746	3006.8406
229.42993	0.63395518	0.083593875	3006.6331
230.33081	0.63674694	0.084581964	3004.1301
231.23169	0.63936937	0.08551015	3008.1641
232.13257	0.64326799	0.086446352	3011.3628
233.03345	0.6479103	0.087602653	3017.4492
233.93433	0.64820081	0.088766634	3015.2258
234.83521	0.65365255	0.089851998	3019.4622
235.73608	0.65355378	0.090675205	3013.6912
236.63696	0.65651262	0.09171886	3017.699
237.53784	0.65829796	0.092704542	3021.2705
238.43872	0.66267151	0.093851693	3027.353
239.3396	0.66311389	0.094920151	3022.5881
240.24048	0.66757351	0.095979333	3033.0208
241.14136	0.6702733	0.097192399	3035.2473
242.04224	0.67432028	0.098341994	3035.5732
242.94312	0.67632383	0.09936925	3031.4604
243.84399	0.67887557	0.10051277	3032.1455
244.74487	0.68096566	0.10147113	3033.6782
245.64575	0.68496197	0.10249663	3039.3083
246.54663	0.68538094	0.10341427	3035.5085
247.44751	0.69107729	0.10454574	3039.6277
248.34839	0.6913619	0.10554624	3045.7295
249.24927	0.69443196	0.10685108	3045.2205
250.15015	0.6963585	0.10796399	3044.6492
251.05103	0.70088267	0.10888463	3043.8574
251.9519	0.7021597	0.10986714	3050.1196
252.85278	0.70711988	0.11075022	3050.2332
253.75366	0.70645565	0.11193088	3058.1003
254.65454	0.71134859	0.11312947	3057.6577
255.55542	0.71275818	0.11435848	3057.1885
256.4563	0.71720487	0.11553535	3058.1619
257.35718	0.7189579	0.11663619	3055.6072
258.25806	0.72105539	0.11773823	3062.1152
259.15894	0.72397321	0.11871013	3063.6553
260.05981	0.72867841	0.11980247	3069.55
260.96069	0.72763067	0.1207924	3062.0349
261.86157	0.73144609	0.12173026	3062.8186
262.76245	0.73369455	0.12282757	3069.1636
263.66333	0.73794228	0.12391943	3071.8677
264.56421	0.73871613	0.12497334	3073.2708
265.46509	0.74284625	0.12629932	3074.8704
266.36597	0.74477857	0.127653	3069.9453
267.26685	0.74871796	0.12870355	3078.917
268.16772	0.75099123	0.12969477	3071.697
269.0686	0.75809121	0.13070433	3078.8271
269.96948	0.75462514	0.13144282	3079.8962
270.87036	0.75714833	0.13244176	3083.436
271.77124	0.76282519	0.13352309	3083.0674
272.67212	0.76441926	0.13476744	3080.5645
273.573	0.76930761	0.13585782	3093.7959
274.47388	0.76831049	0.13689242	3086.9834
275.37476	0.77248895	0.13801754	3092.1875
276.27563	0.7761991	0.13923694	3093.9761
277.17651	0.7777794	0.14021666	3101.7793
278.07739	0.77898329	0.14157997	3097.6936
278.97827	0.78320587	0.14286999	3095.9993
279.87915	0.78742844	0.14403729	3102.001
280.78003	0.79220968	0.14529254	3102.4895
281.68091	0.79329008	0.14625418	3098.8311
282.58179	0.79534942	0.1474268	3101.9653
283.48267	0.79853934	0.14848165	3106.3235
284.38354	0.79814595	0.14956696	3106.7427
285.28442	0.80368733	0.15070313	3105.9758
286.1853	0.80456448	0.15182261	3106.9438
287.08618	0.80778408	0.15289257	3110.6619
287.98706	0.81202036	0.15399392	3113.7542
288.88794	0.81110203	0.15524375	3106.1177
289.78882	0.81365621	0.15614714	3115.4912
290.6897	0.82099104	0.15726037	3119.0635
291.59058	0.82101315	0.1582844	3118.1326
292.49146	0.82521522	0.15927957	3118.1992
293.39233	0.82411927	0.16032647	3117.1477
294.29321	0.83132929	0.16132602	3120.4377
295.19409	0.83519328	0.16240996	3126.8804
296.09497	0.83256721	0.1633132	3116.7261
296.99585	0.83830267	0.16426948	3120.3691
297.89673	0.83908701	0.16516286	3128.1375
298.79761	0.84377503	0.16639382	3128.3584
299.69849	0.84329951	0.16749157	3129.1353
300.59937	0.845725	0.16847016	3126.6443
301.50024	0.85387117	0.16941762	3132.481
302.40112	0.85167247	0.17022009	3124.8171
303.302	0.85936868	0.17132294	3133.2976
304.20288	0.8603245	0.17252158	3136.6636
305.10376	0.86112422	0.17346917	3135.1519
306.00464	0.86357301	0.17459135	3139.0771
306.90552	0.8658514	0.17576531	3137.1963
307.8064	0.8706165	0.17716509	3147.5537
308.70728	0.87429565	0.17842741	3145.2839
309.60815	0.87577558	0.17945667	3145.1116
310.50903	0.87777406	0.18034914	3139.1431
311.40991	0.8810693	0.18126282	3144.0601
312.31079	0.88336402	0.18233521	3151.5952
313.21167	0.88519984	0.18348382	3151.7808
314.11255	0.88976556	0.18474303	3151.3276
315.01343	0.89243835	0.18583074	3147.6187
315.91431	0.89478844	0.18686786	3157.1741
316.81519	0.89716285	0.18807492	3157.1895
317.71606	0.8975755	0.18921509	3156.8765
318.61694	0.90267235	0.1903459	3152.8467
319.51782	0.90611529	0.19158223	3162.3145
320.4187	0.90899009	0.19268183	3161.7134
321.31958	0.91241068	0.19372392	3163.6726
322.22046	0.91337138	0.19467196	3159.4023
323.12134	0.91377705	0.19571309	3164.3831
324.02222	0.91652358	0.19684792	3165.1951
324.9231	0.92173886	0.19796574	3160.4878
325.82397	0.92518467	0.19894449	3169.2109
326.72485	0.92404854	0.20007767	3172.606
327.62573	0.9294402	0.2013845	3170.416
328.52661	0.93351686	0.20252202	3167.5891
329.42749	0.93626326	0.20351328	3170.0715
330.32837	0.93979448	0.20459118	3171.1543
331.22925	0.93990403	0.2054113	3172.8704
332.13013	0.94291961	0.20637502	3174.3167
333.03101	0.94686252	0.20727658	3176.8765
333.93188	0.94456673	0.2082683	3172.9438
334.83276	0.95178866	0.20939401	3181.4187
335.73364	0.95356071	0.21054758	3182.1089
336.63452	0.95529181	0.21162257	3186.7241
337.5354	0.95960861	0.21280609	3179.9458
338.43628	0.9616887	0.21386649	3185.313
339.33716	0.96708274	0.21512038	3188.4646
340.23804	0.96773487	0.21630773	3185.9648
341.13892	0.96890014	0.21747608	3187.9507
342.03979	0.97360659	0.21857607	3194.0852
342.94067	0.97693706	0.21957581	3187.1621
343.84155	0.97832745	0.22091162	3192.7756
344.74243	0.9820714	0.22200643	3195.7563
345.64331	0.98558027	0.22300799	3196.0957
346.54419	0.98549628	0.22405463	3199.009
347.44507	0.98917735	0.22533213	3198.0129
348.34595	0.9916448	0.22617592	3200.5039
349.24683	0.99395573	0.22734612	3203.1951
350.14771	0.99476379	0.22845782	3200.4685
351.04858	1.0001398	0.22947301	3200.8218
351.94946	1.001752	0.23058528	3205.6965
352.85034	1.0035808	0.23169407	3203.5024
353.75122	1.0102381	0.23273562	3205.3464
354.6521	1.010957	0.23391841	3206.7085
355.55298	1.0119209	0.23489463	3204.6079
356.45386	1.0178691	0.23585299	3210.5496
357.35474	1.0182004	0.23709525	3215.0957
358.25562	1.0218	0.23821588	3213.7639
359.15649	1.0268137	0.23929654	3210.6399
360.05737	1.0290025	0.24051566	3218.146
360.95825	1.0303717	0.24159467	3217.4253
361.85913	1.0328549	0.24268036	3220.9607
362.76001	1.0350709	0.24380781	3218.5898
363.66089	1.0355461	0.24477716	3209.7041
364.56177	1.0397342	0.24570355	3221.2881
365.46265	1.0442321	0.24678992	3222.2964
366.36353	1.0441996	0.24781716	3220.0654
367.2644	1.0484102	0.2489561	3228.7969
368.16528	1.052125	0.25003922	3228.1345
369.06616	1.054044	0.25130972	3227.8345
369.96704	1.0567091	0.25240007	3228.3396
370.86792	1.0580355	0.2534388	3227.5315
371.7688	1.0637951	0.2547248	3230.7683
372.66968	1.0661722	0.25589421	3230.6873
373.57056	1.069791	0.25702688	3229.1936
374.47144	1.0715069	0.25815234	3230.1377
375.37231	1.0717306	0.25924733	3233.8411
376.27319	1.0743958	0.26011166	3232.5239
377.17407	1.0773866	0.26104161	3229.4087
378.07495	1.0791007	0.26211426	3238.238
378.97583	1.0836433	0.26324689	3247.6257
379.87671	1.0863379	0.26448801	3244.1416
380.77759	1.0880543	0.26567096	3240.4995
381.67847	1.090413	0.26675048	3240.031
382.57935	1.0962056	0.26783916	3240.2314
383.48022	1.0985602	0.26876327	3243.6804
384.3811	1.1034472	0.26985267	3243.2815
385.28198	1.1042525	0.27094463	3250.022
386.18286	1.1054401	0.27182028	3243.8582
387.08374	1.1063889	0.27292225	3246.8691
387.98462	1.1102016	0.27411303	3250.5391
388.8855	1.1133519	0.2750738	3245.6226
389.78638	1.1171182	0.27626348	3250.7078
390.68726	1.1193222	0.27709326	3249.418
391.58813	1.1237855	0.27809545	3251.6084
392.48901	1.122111	0.27926081	3258.6396
393.38989	1.125198	0.2806603	3255.1499
394.29077	1.1305574	0.28178382	3255.1545
395.19165	1.1302911	0.28287256	3257.4243
396.09253	1.1349261	0.28401268	3261.074
396.99341	1.1366761	0.2851415	3256.2646
397.89429	1.1430237	0.28635275	3267.1167
398.79517	1.139262	0.28738517	3261.4402
399.69604	1.1465302	0.2885769	3264.0383
400.59692	1.148543	0.28961033	3262.4507
401.4978	1.1521634	0.29047763	3264.9282
402.39868	1.1540076	0.29167783	3267.002
403.29956	1.1548965	0.29270104	3259.99
404.20044	1.15811	0.29376435	3259.6919
405.10132	1.1591877	0.29486144	3262.2629
406.0022	1.1642828	0.29589891	3271.9001
406.90308	1.1670717	0.29693887	3273.1172
407.80396	1.1706625	0.29801559	3267.3013
408.70483	1.1704247	0.29913691	3273.8884
409.60571	1.1774706	0.30050167	3281.7788
410.50659	1.1780933	0.30161664	3276.9021
411.40747	1.1800253	0.30254814	3271.1775
412.30835	1.1856586	0.30354047	3276.124
413.20923	1.1876838	0.30474246	3277.7964
414.11011	1.1899287	0.30573788	3280.4399
415.01099	1.1932304	0.30669549	3276.5803
415.91187	1.1952908	0.30776635	3279.9658
416.81274	1.1978152	0.30872571	3280.616
417.71362	1.2002534	0.30978185	3283.0334
418.6145	1.2027218	0.31081688	3283.0571
419.51538	1.206072	0.31204897	3288.3145
420.41626	1.2078539	0.31330326	3287.7842
421.31714	1.2103939	0.31456262	3295.3562
422.21802	1.2139223	0.31572494	3288.9026
423.1189	1.2151246	0.31671858	3285.1553
424.01978	1.2176765	0.31793958	3294.6248
424.92065	1.219642	0.31910253	3289.4272
425.82153	1.2237459	0.32027221	3292.7339
426.72241	1.2242631	0.321192	3293.2627
427.62329	1.2272247	0.32230663	3293.7112
428.52417	1.2323688	0.32347316	3300.0171
429.42505	1.235024	0.32460091	3299.7034
430.32593	1.2367774	0.32561278	3293.75
431.22681	1.2410654	0.32673553	3292.8132
432.12769	1.2429295	0.32791021	3305.8093
433.02856	1.2456021	0.32902747	3300.574
433.92944	1.2484182	0.33026189	3298.9199
434.83032	1.2494249	0.3311426	3297.3438
435.7312	1.2553446	0.3322832	3300.574
436.63208	1.2562058	0.33334312	3299.457
437.53296	1.2609377	0.33435214	3305.2949
438.43384	1.2640299	0.33561665	3306.0493
439.33472	1.2660267	0.33652446	3306.6606
440.2356	1.2649648	0.33734664	3298.813
441.13647	1.2683929	0.33830562	3305.5847
442.03735	1.2732037	0.33912235	3311.4365
442.93823	1.2766012	0.34022892	3311.9375
443.83911	1.2752014	0.34145135	3311.3193
444.73999	1.2797587	0.34280896	3311.4241
445.64087	1.2841113	0.34406868	3318.281
446.54175	1.2867123	0.34526443	3310.98
447.44263	1.2885935	0.34618491	3313.7876
448.34351	1.2898313	0.34734449	3319.3203
449.24438	1.2959477	0.34846467	3320.9724
450.14526	1.2978522	0.34947857	3311.686
451.04614	1.3013475	0.35057253	3319.9827
451.94702	1.3019539	0.35161355	3323.6973
452.8479	1.3056934	0.35275611	3326.2676
453.74878	1.3074363	0.35402712	3325.6306
454.64966	1.309491	0.3550837	3318.4697
455.55054	1.3147908	0.35623744	3324.1597
456.45142	1.3161284	0.35727957	3327.2146
457.35229	1.3166741	0.35838979	3325.1677
458.25317	1.3222015	0.35950911	3328.4534
459.15405	1.3223931	0.3607527	3326.2676
460.05493	1.3246186	0.36181381	3326.4253
460.95581	1.330191	0.36290726	3327.2705
461.85669	1.3333396	0.36404559	3334.7458
462.75757	1.3334259	0.36508575	3337.3862
463.65845	1.3367883	0.36624807	3335.4529
464.55933	1.3416595	0.36734563	3333.6873
465.46021	1.3449801	0.36851203	3334.4404
466.36108	1.3470854	0.36960748	3339.939
467.26196	1.34452	0.37055892	3331.043
468.16284	1.3501962	0.37192065	3339.1216
469.06372	1.3552451	0.37290835	3337.4775
469.9646	1.3569014	0.37408394	3340.4246
470.86548	1.3584867	0.37524286	3345.0137
471.76636	1.3636005	0.3764433	3344.6841
472.66724	1.3627725	0.37754801	3345.1387
473.56812	1.3670967	0.37874198	3345.2034
474.46899	1.3695756	0.37980688	3340.4309
475.36987	1.3687615	0.38104236	3347.1018
476.27075	1.3728243	0.38203949	3339.9915
477.17163	1.377317	0.38303214	3347.2446
478.07251	1.3820287	0.38394591	3344.1863
478.97339	1.38432	0.38499987	3344.7219
479.87427	1.3859061	0.3859857	3351.5159
480.77515	1.3885936	0.38696584	3345.0281
481.67603	1.3889447	0.3881596	3355.0759
482.5769	1.3950697	0.38933405	3353.2317
483.47778	1.3985393	0.39055279	3353.2429
484.37866	1.3996871	0.39168653	3359.2959
485.27954	1.4028893	0.39294064	3357.1741
486.18042	1.4039569	0.39385048	3353.5107
487.0813	1.4082546	0.39513585	3359.0918
487.98218	1.4075742	0.39630866	3357.1633
488.88306	1.4121152	0.39734659	3355.8721
489.78394	1.4140543	0.39872992	3365.0723
490.68481	1.4157405	0.40013853	3363.3044
491.58569	1.423366	0.40140358	3363.0591
492.48657	1.4250945	0.40269777	3360.8652
493.38745	1.4255549	0.40374509	3367.5632
494.28833	1.4272724	0.40496382	3360.054
495.18921	1.4297421	0.40591857	3362.0432
496.09009	1.4332275	0.40696311	3364.9509
496.99097	1.4375402	0.40797186	3366.467
497.89185	1.4423912	0.40920186	3373.2107
498.79272	1.4441135	0.41044232	3367.7959
499.6936	1.4439818	0.41126812	3366.1758
500.59448	1.4487009	0.41236773	3371.1067
501.49536	1.4505539	0.41356468	3372.6426
502.39624	1.4523487	0.41481018	3377.595
503.29712	1.4556931	0.41604859	3370.3125
504.198	1.4591954	0.41715586	3372.7249
505.09888	1.4626514	0.41834679	3373.5149
505.99976	1.46069	0.41927865	3369.2161
506.90063	1.4688033	0.42032397	3373.2534
507.80151	1.4707412	0.42133695	3371.7183
508.70239	1.4739074	0.42231447	3373.3318
509.60327	1.4763709	0.42334813	3374.562
510.50415	1.4781364	0.42432866	3379.8586
511.40503	1.4797345	0.42557684	3380.9675
512.30591	1.4829415	0.42668992	3386.7078
513.20679	1.4852451	0.4278259	3381.6648
514.10767	1.489103	0.42897487	3386.1694
515.00854	1.4928106	0.43033445	3388.3608
515.90942	1.4933455	0.4315502	3387.2556
516.8103	1.4940708	0.43262121	3382.98
517.71118	1.4994773	0.43387738	3387.1594
518.61206	1.5031108	0.43504119	3387.4497
519.51294	1.5034355	0.43616924	3381.8059
520.41382	1.5102359	0.43727359	3386.6787
521.3147	1.5122536	0.43843994	3391.115
522.21558	1.5149637	0.43951756	3388.2327
523.11646	1.5167614	0.44057053	3388.4905
524.01733	1.5206387	0.44157216	3388.7346
524.91821	1.5234381	0.44277149	3398.0718
525.81909	1.5266981	0.44393748	3398.238
526.71997	1.5259315	0.44513217	3388.7271
527.62085	1.5309881	0.44639006	3393.3721
528.52173	1.5336763	0.44767618	3397.1096
529.42261	1.5344914	0.44863766	3392.5522
530.32349	1.5393093	0.44993404	3397.3394
531.22437	1.5416347	0.45121175	3403.6265
532.12524	1.54241	0.45233324	3392.7229
533.02612	1.5432187	0.45340213	3395.481
533.927	1.5474226	0.45466837	3405.7588
534.82788	1.5521183	0.45610312	3410.7324
535.72876	1.552307	0.45707738	3397.1235
536.62964	1.5541059	0.45805746	3393.2439
537.53052	1.5591171	0.45912683	3398.7932
538.4314	1.5622795	0.46018305	3404.9063
539.33228	1.5632612	0.46124467	3402.5559
540.23315	1.5671637	0.46235356	3405.5986
541.13403	1.572437	0.46336585	3404.0154
542.03491	1.5732507	0.46458122	3408.9629
542.93579	1.5745078	0.46566895	3403.8315
543.83667	1.5747143	0.46712503	3413.0571
544.73755	1.5799235	0.46848783	3411.0464
545.63843	1.5857716	0.46965611	3411.7366
546.53931	1.584501	0.47089452	3412.9648
547.44019	1.5866348	0.47197375	3412.5808
548.34106	1.5897741	0.47334155	3416.0815
549.24194	1.5936947	0.47459546	3416.4277
550.14282	1.5986478	0.47588292	3415.2195
551.0437	1.6010563	0.47708341	3417.1594
551.94458	1.6021249	0.4780128	3414.3826
552.84546	1.6047138	0.47906023	3413.7297
553.74634	1.6077327	0.48025036	3421.9641
554.64722	1.6109344	0.48131528	3422.4282
555.5481	1.6123321	0.48235989	3410.488
556.44897	1.6184837	0.48352388	3420.0476
557.34985	1.619132	0.48448849	3425.0984
558.25073	1.6226037	0.48553836	3420.2336
559.15161	1.6269003	0.48661277	3428.2017
560.05249	1.625168	0.48787752	3424.8032
560.95337	1.6297103	0.48902974	3423.6558
561.85425	1.6305153	0.49022624	3423.6414
562.75513	1.6387393	0.49167329	3429.7334
563.65601	1.6349043	0.49301171	3426.1008
564.55688	1.6413989	0.4943009	3427.967
565.45776	1.6465008	0.49532896	3425.3694
566.35864	1.6465992	0.4966107	3425.2263
567.25952	1.6496338	0.49770921	3426.9404
568.1604	1.6526265	0.49894151	3425.9341
569.06128	1.6517653	0.50004226	3425.6841
569.96216	1.6560947	0.50112545	3433.3279
570.86304	1.659436	0.50221819	3430.6677
571.76392	1.6618334	0.50353599	3439.9771
572.66479	1.6630265	0.50471127	3435.4023
573.56567	1.6691846	0.50604331	3436.8406
574.46655	1.6690027	0.50707555	3428.4775
575.36743	1.6725774	0.50837928	3435.2146
576.26831	1.6738812	0.50981164	3438.4458
577.16919	1.6786232	0.51123422	3441.7976
578.07007	1.6807871	0.51258767	3432.3562
578.97095	1.6835297	0.51354969	3433.3584
579.87183	1.6857554	0.51442522	3427.1721
580.77271	1.6883152	0.51519716	3428.0571
581.67358	1.6936209	0.51608247	3431.5024
582.57446	1.6931427	0.51694989	3439.2798
583.47534	1.6968879	0.51815146	3439.6133
584.37622	1.701116	0.51939493	3442.2939
585.2771	1.6989361	0.52050436	3435.2214
586.17798	1.7077287	0.52175653	3442.2014
587.07886	1.7101377	0.52275264	3443.9604
587.97974	1.7101353	0.52402115	3446.9502
588.88062	1.7127731	0.525433	3446.7876
589.78149	1.7137364	0.52675325	3444.6555
590.68237	1.718428	0.5280903	3443.26
591.58325	1.721634	0.52936757	3446.4136
592.48413	1.7236204	0.53068691	3448.6887
593.38501	1.726524	0.53196657	3451.3721
594.28589	1.7313905	0.53310591	3445.7195
595.18677	1.7320418	0.53412443	3449.5313
596.08765	1.7334971	0.53540313	3448.5977
596.98853	1.73795	0.53682977	3453.2583
597.8894	1.7378457	0.5378502	3446.0237
598.79028	1.7451383	0.5391596	3456.4097
599.69116	1.7440159	0.540402	3455.6404
600.59204	1.7472755	0.5418179	3456.0608
601.49292	1.7506686	0.54321665	3450.7083
602.3938	1.7548358	0.54426825	3449.916
603.29468	1.7577746	0.54523307	3452.4541
604.19556	1.7586266	0.54639161	3450.1392
605.09644	1.7603945	0.54760939	3456.3694
605.99731	1.7651044	0.54881173	3457.9871
606.89819	1.7672312	0.5499965	3455.106
607.79907	1.770822	0.55129719	3459.5161
608.69995	1.7735827	0.55241603	3454.0664
609.60083	1.7746408	0.55355042	3458.2004
610.50171	1.7789828	0.55489922	3465.7961
611.40259	1.7791272	0.55618358	3460.1848
612.30347	1.7850379	0.55744296	3465.0164
613.20435	1.7850559	0.55866838	3459.8889
614.10522	1.7878923	0.55980223	3462.3643
615.0061	1.789126	0.56114191	3458.8787
615.90698	1.7931042	0.56244189	3462.99
616.80786	1.7986406	0.5637539	3469.4421
617.70874	1.799018	0.56512344	3466.1506
618.60962	1.8016857	0.56615502	3465.2832
619.5105	1.8045088	0.5675028	3466.3979
620.41138	1.8066649	0.56860143	3464.855
621.31226	1.811471	0.57002711	3469.2969
622.21313	1.8129736	0.57125062	3467.8657
623.11401	1.8171294	0.57237297	3465.2473
624.01489	1.8186368	0.57348412	3467.1921
624.91577	1.8223449	0.57486582	3476.7434
625.81665	1.8210967	0.57608616	3474.4863
626.71753	1.8254058	0.57735932	3468.0159
627.61841	1.8283819	0.57885969	3474.3433
628.51929	1.8318615	0.58022261	3477.5029
629.42017	1.8356659	0.58148766	3467.926
630.32104	1.8376726	0.58260834	3474.5383
631.22192	1.8427993	0.58394396	3476.2324
632.1228	1.8430426	0.58513921	3473.9788
633.02368	1.8442888	0.58634567	3472.6018
633.92456	1.8474697	0.58760214	3471.4622
634.82544	1.8529416	0.58898038	3477.7693
635.72632	1.8526329	0.59021014	3482.9712
636.6272	1.8570138	0.59143949	3474.2522
637.52808	1.8585489	0.5924924	3469.0872
638.42896	1.8626753	0.59355032	3476.5393
639.32983	1.8664964	0.59472376	3480.5239
640.23071	1.8658599	0.59601277	3482.6194
641.13159	1.8709016	0.59725201	3479.2712
642.03247	1.87199	0.59848231	3474.4824
642.93335	1.876514	0.59992617	3481.9534
643.83423	1.8779864	0.60116881	3485.4719
644.73511	1.8782846	0.60248882	3482.0422
645.63599	1.8834143	0.60400534	3487.6509
646.53687	1.886987	0.60534614	3484.3818
647.43774	1.887818	0.60655642	3485.1074
648.33862	1.8945369	0.60772657	3487.6223
649.2395	1.8962153	0.60898572	3488.0173
650.14038	1.8989623	0.61016226	3488.9836
651.04126	1.900558	0.61147654	3484.7131
651.94214	1.9017433	0.61270332	3486.8245
652.84302	1.9062551	0.61429369	3492.147
653.7439	1.906427	0.6154713	3493.7922
654.64478	1.9113171	0.61690283	3489.2021
655.54565	1.9122796	0.61822718	3487.0483
656.44653	1.9172084	0.61974263	3493.7637
657.34741	1.9186841	0.62090147	3486.7366
658.24829	1.9192994	0.62210643	3487.7004
659.14917	1.923937	0.62322867	3488.7671
660.05005	1.9276904	0.62446862	3486.0906
660.95093	1.9321145	0.6255995	3492.3848
661.85181	1.9327857	0.62683386	3494.625
662.75269	1.9344181	0.62821788	3497.2827
663.65356	1.9372859	0.62944758	3494.2754
664.55444	1.9407645	0.63048834	3482.2236
665.45532	1.9435061	0.63171899	3496.9207
666.3562	1.9461539	0.63300192	3495.2922
667.25708	1.9512814	0.6341182	3499.738
668.15796	1.9514767	0.63549083	3500.2568
669.05884	1.9540434	0.6370725	3496.8713
669.95972	1.9581889	0.63817215	3496.7527
670.8606	1.957998	0.63949811	3501.0837
671.76147	1.9622946	0.64090765	3495.8247
672.66235	1.9629494	0.64244735	3502.1763
673.56323	1.9687297	0.64370841	3500.3152
674.46411	1.9691784	0.64501715	3500.8245
675.36499	1.973166	0.64648724	3502.365
676.26587	1.9756763	0.6477356	3499.7112
677.16675	1.9771564	0.64890289	3496.6577
678.06763	1.9808307	0.65011585	3497.7258
678.96851	1.983272	0.65124476	3502.7065
679.86938	1.9863977	0.6525929	3505.2273
680.77026	1.988458	0.65380353	3500.1128
681.67114	1.9922507	0.65512902	3502.7903
682.57202	1.993825	0.65641457	3500.9446
683.4729	1.998844	0.65779418	3508.5881
684.37378	2.0012496	0.65893823	3504.9578
685.27466	2.0009835	0.6602757	3506.6274
686.17554	2.0060089	0.66168219	3504.4976
687.07642	2.0060859	0.66312379	3504.0317
687.97729	2.0094597	0.66440868	3503.1709
688.87817	2.0149202	0.66559845	3508.364
689.77905	2.0126934	0.66695821	3505.3545
690.67993	2.0208783	0.66834474	3510.4292
691.58081	2.0230453	0.66975307	3509.2588
692.48169	2.0234125	0.67100662	3503.6792
693.38257	2.0276117	0.67241603	3514.8267
694.28345	2.0288684	0.67394209	3511.7627
695.18433	2.030426	0.67516065	3508.438
696.08521	2.0348978	0.67652512	3511.7207
696.98608	2.0395591	0.6778419	3510.4512
697.88696	2.0424576	0.67911893	3513.5999
698.78784	2.0448649	0.6804781	3512.668
699.68872	2.0458505	0.68188298	3513.6265
700.5896	2.0489726	0.68317777	3512.9189
701.49048	2.0510144	0.68471169	3518.3835
702.39136	2.0550842	0.68633705	3514.6296
703.29224	2.0551803	0.68754894	3511.365
704.19312	2.0545278	0.6889478	3509.3528
705.09399	2.060508	0.6902684	3515.1917
705.99487	2.0648277	0.69152719	3516.6865
706.89575	2.0671287	0.69294393	3517.0178
707.79663	2.0700202	0.6944648	3519.3701
708.69751	2.0749805	0.69603628	3517.6821
709.59839	2.0753448	0.69726825	3513.2595
710.49927	2.0814037	0.69857413	3515.571
711.40015	2.0817652	0.70001274	3518.5188
712.30103	2.0835249	0.7012893	3516.9866
713.2019	2.0866373	0.70250523	3518.6204
714.10278	2.0901597	0.70385009	3521.6313
715.00366	2.0930576	0.70559382	3520.4434
715.90454	2.09498	0.70701724	3520.4692
716.80542	2.095489	0.70837718	3514.2527
717.7063	2.0974016	0.70966333	3518.9539
718.60718	2.1035385	0.71099615	3522.144
719.50806	2.1029117	0.71246815	3518.8882
720.40894	2.1060362	0.71380997	3521.2439
721.30981	2.1070817	0.7153796	3516.9844
722.21069	2.1124132	0.71626985	3509.958
723.11157	2.1175501	0.71751481	3524.0063
724.01245	2.1177986	0.71868408	3521.8462
724.91333	2.1196976	0.71979266	3518.5671
725.81421	2.1241062	0.72096276	3524.823
726.71509	2.1267345	0.72218633	3521.2351
727.61597	2.1312225	0.72365808	3527.9138
728.51685	2.13133	0.72544616	3532.7341
729.41772	2.1352458	0.72703701	3528.9875
730.3186	2.1371248	0.72856981	3529.8169
731.21948	2.1419239	0.73021942	3525.5398
732.12036	2.1437082	0.73144388	3523.5586
733.02124	2.1457655	0.73272824	3522.2141
733.92212	2.1471832	0.73424864	3528.9058
734.823	2.150682	0.73570526	3527.5503
735.72388	2.1538424	0.73720115	3526.6799
736.62476	2.1560636	0.7386955	3530.6689
737.52563	2.1598606	0.74007946	3524.8406
738.42651	2.1614418	0.74143535	3527.5444
739.32739	2.1661012	0.74275571	3531.6238
740.22827	2.1688511	0.74432313	3535.2981
741.12915	2.1698775	0.74577922	3526.8867
742.03003	2.1724596	0.74730837	3532.7422
742.93091	2.1753948	0.74875873	3526.8809
743.83179	2.1791275	0.7502768	3532.4417
744.73267	2.1817846	0.7516855	3531.165
745.63354	2.183876	0.75326359	3525.9512
746.53442	2.1892316	0.75436521	3525.5791
747.4353	2.1876786	0.75554991	3527.5811
748.33618	2.1927333	0.75694358	3535.0823
749.23706	2.1934311	0.75846124	3535.8745
750.13794	2.197242	0.76012647	3538.3142
751.03882	2.2027493	0.76161909	3530.3823
751.9397	2.201565	0.76324487	3536.4736
752.84058	2.2040451	0.7647509	3530.78
753.74146	2.207191	0.76606309	3535.1392
754.64233	2.2129946	0.76784885	3542.8857
755.54321	2.2118306	0.76919132	3533.2476
756.44409	2.2131751	0.77066594	3528.3848
757.34497	2.2186148	0.77187115	3530.1333
758.24585	2.2229381	0.7731294	3539.2971
759.14673	2.2233515	0.77471828	3536.5596
760.04761	2.2299371	0.77606457	3536.259
760.94849	2.2303526	0.7774719	3533.3499
761.84937	2.234318	0.77884918	3539.6809
762.75024	2.2365167	0.78046006	3536.7766
763.65112	2.2369652	0.78189975	3541.2048
764.552	2.2412708	0.78353703	3539.9634
765.45288	2.2439125	0.78502858	3532.9368
766.35376	2.2407494	0.78630215	3529.4067
767.25464	2.2483559	0.7875492	3532.4229
768.15552	2.2493424	0.78879696	3532.6311
769.0564	2.2550812	0.79029047	3543.1128
769.95728	2.2549107	0.79206204	3542.5442
770.85815	2.2601254	0.79362464	3539.2832
771.75903	2.2645795	0.79504472	3541.894
772.65991	2.2639105	0.79651356	3542.5591
773.56079	2.2699175	0.79812396	3545.4973
774.46167	2.2694592	0.79984283	3542.1636
775.36255	2.2731223	0.80143285	3540.4714
776.26343	2.276957	0.80286562	3541.7002
777.16431	2.2826664	0.80437356	3546.6191
778.06519	2.2799408	0.80608833	3543.8694
778.96606	2.2832904	0.80804807	3543.5828
779.86694	2.2880523	0.80968398	3543.8838
780.76782	2.2884393	0.81109762	3540.8882
781.6687	2.2924685	0.81274742	3541.813
782.56958	2.2974398	0.81427157	3542.4968
783.47046	2.2960224	0.81568944	3539.4224
784.37134	2.2994146	0.81715178	3546.0527
785.27222	2.301007	0.81868118	3543.1082
786.1731	2.3058062	0.82034647	3546.0066
787.07397	2.3057561	0.82191527	3540.8484
787.97485	2.3127439	0.8237834	3547.2371
788.87573	2.3118699	0.82528645	3538.3564
789.77661	2.3153262	0.82681811	3546.5688
790.67749	2.3184671	0.82846349	3541.8091
791.57837	2.3195672	0.83003473	3545.0049
792.47925	2.3244712	0.83125293	3539.2375
793.38013	2.3285224	0.83258057	3540.8225
794.28101	2.3289008	0.83425134	3552.8152
795.18188	2.3308794	0.83587283	3550.5396
796.08276	2.332602	0.83747929	3549.1716
796.98364	2.3374939	0.83887339	3541.2793
797.88452	2.3407757	0.84012812	3541.3604
798.7854	2.3428068	0.84146118	3543.144
799.68628	2.3442826	0.84296757	3548.6187
800.58716	2.3491664	0.8446964	3555.6133
801.48804	2.3514855	0.84643149	3546.0959
802.38892	2.356046	0.84809172	3550.4441
803.28979	2.3579559	0.8496536	3548.2058
804.19067	2.3607244	0.85099632	3550.9348
805.09155	2.3630455	0.8526417	3553.2471
805.99243	2.3649504	0.85400188	3544.7908
806.89331	2.3659563	0.85549253	3545.511
807.79419	2.3683779	0.85704958	3551.6228
808.69507	2.3754151	0.85869437	3547.2214
809.59595	2.3783391	0.86014563	3545.6157
810.49683	2.3784277	0.86159104	3552.2886
811.39771	2.3811097	0.86325961	3550.0771
812.29858	2.3857148	0.86506814	3550.7588
813.19946	2.384846	0.86670583	3544.9016
814.10034	2.3891211	0.86841166	3547.0364
815.00122	2.3916135	0.87012327	3552.8
815.9021	2.3947759	0.87191659	3548.1917
816.80298	2.395848	0.87344664	3545.415
817.70386	2.39992	0.87502909	3551.1948
818.60474	2.4038346	0.87654269	3556.7336
819.50562	2.4055681	0.87829989	3553.9395
820.40649	2.4076595	0.88015831	3554.5964
821.30737	2.4109325	0.8819564	3551.5061
822.20825	2.4137182	0.88362318	3550.5557
823.10913	2.4136312	0.88527644	3545.9653
824.01001	2.4165349	0.88688231	3552.0388
824.91089	2.4209912	0.88879412	3550.2905
825.81177	2.4240549	0.89058948	3555.0066
826.71265	2.4293315	0.89235872	3551.1191
827.61353	2.4311514	0.89402443	3551.4768
828.5144	2.4309285	0.8954559	3544.3755
829.41528	2.4308391	0.89733911	3552.8857
830.31616	2.4377625	0.89921451	3554.6384
831.21704	2.4392352	0.90098774	3550.0615
832.11792	2.4438591	0.90264523	3549.5679
833.0188	2.4457421	0.90422374	3551.6062
833.91968	2.4514923	0.90577447	3550.8569
834.82056	2.4481409	0.90742195	3551.0337
835.72144	2.4524503	0.90911537	3553.551
836.62231	2.4559128	0.91091275	3557.915
837.52319	2.4611757	0.91265678	3553.7036
838.42407	2.4606333	0.91430575	3548.5818
839.32495	2.4641135	0.91582024	3551.1882
840.22583	2.4661276	0.91739476	3545.8933
841.12671	2.4690261	0.91910744	3556.7007
842.02759	2.4735389	0.92081356	3550.8086
842.92847	2.4775276	0.92261791	3551.8379
843.82935	2.4809959	0.92438477	3556.6504
844.73022	2.4808667	0.92608237	3549.0854
845.6311	2.4839585	0.92786616	3550.6663
846.53198	2.4863179	0.92963439	3555.9111
847.43286	2.4869986	0.93137634	3558.4431
848.33374	2.4918842	0.93321621	3550.7075
849.23462	2.4977992	0.93500435	3552.8906
850.1355	2.4982626	0.93650764	3554.4014
851.03638	2.503701	0.93810678	3553.8828
851.93726	2.4989808	0.94006467	3553.8584
852.83813	2.5056331	0.94204038	3552.2732
853.73901	2.5068383	0.94390625	3556.0195
854.63989	2.5108533	0.94583476	3550.5571
855.54077	2.5134687	0.94784015	3556.7124
856.44165	2.5147543	0.94950342	3548.9973
857.34253	2.5185945	0.95119786	3549.5586
858.24341	2.5200605	0.95301688	3554.95
859.14429	2.5265396	0.95490199	3560.6726
860.04517	2.5276463	0.95713776	3552.5762
860.94604	2.5303094	0.95897907	3550.1248
861.84692	2.5301354	0.96063805	3553.147
862.7478	2.5337877	0.96265399	3560.1245
863.64868	2.5376933	0.96460944	3554.584
864.54956	2.5403066	0.96629947	3546.3298
865.45044	2.5437052	0.96790683	3553.1653
866.35132	2.5458112	0.96960473	3552.6904
867.2522	2.5465136	0.97163862	3553.2209
868.15308	2.5515792	0.97323495	3547.2759
869.05396	2.5561357	0.97485393	3553.7791
869.95483	2.5559535	0.97656178	3553.9507
870.85571	2.55936	0.97846407	3555.3921
871.75659	2.5603662	0.98029423	3558.2659
872.65747	2.5655036	0.98191816	3548.584
873.55835	2.5665483	0.98365349	3554.4893
874.45923	2.5703704	0.98533827	3546.1765
875.36011	2.5746846	0.98710912	3554.98
876.26099	2.5758951	0.98881602	3551.6072
877.16187	2.5789943	0.99053836	3552.9089
878.06274	2.5799685	0.99219191	3552.4443
878.96362	2.5844402	0.99408627	3554.0486
879.8645	2.5861681	0.99594009	3553.2803
880.76538	2.5885909	0.9979133	3549.2124
881.66626	2.5938172	0.99981517	3555.8184
882.56714	2.5916953	1.0019076	3556.281
883.46802	2.596139	1.0038642	3549.593
884.3689	2.6001174	1.0058956	3556.9624
885.26978	2.6038897	1.0081267	3555.9807
886.17065	2.6084154	1.0102351	3553.1545
887.07153	2.6103044	1.0121162	3558.2686
887.97241	2.6102357	1.0144501	3553.001
888.87329	2.6136715	1.0165305	3552.1404
889.77417	2.6147878	1.0185916	3554.3987
890.67505	2.6194417	1.020494	3546.9248
891.57593	2.620985	1.0223587	3546.1475
892.47681	2.6232772	1.0243564	3551.6348
893.37769	2.6250944	1.0264468	3551.9751
894.27856	2.629209	1.0285237	3558.3093
895.17944	2.6319904	1.030399	3545.0549
896.08032	2.6334536	1.0323259	3553.031
896.9812	2.6370139	1.0343362	3552.2937
897.88208	2.6416156	1.0362035	3550.1831
898.78296	2.6434181	1.0384175	3556.4456
899.68384	2.6469207	1.0405178	3551.7947
900.58472	2.6449618	1.0423461	3549.176
901.4856	2.6511481	1.0445156	3552.5122
902.38647	2.6552408	1.0464671	3549.4485
903.28735	2.6576722	1.0486616	3552.0601
904.18823	2.6607525	1.050629	3544.0239
905.08911	2.660989	1.0528269	3555.9453
905.98999	2.6656547	1.054817	3547.8635
906.89087	2.6685333	1.056623	3549.1575
907.79175	2.6713269	1.0584356	3549.2566
908.69263	2.6720312	1.0605478	3544.3071
909.59351	2.6758888	1.0625261	3543.4045
910.49438	2.6752837	1.0644279	3544.8691
911.39526	2.6786804	1.0667527	3549.4255
912.29614	2.6833696	1.0687914	3543.3562
913.19702	2.6841056	1.0707513	3547.5173
914.0979	2.688822	1.0729553	3545.1733
914.99878	2.6911876	1.0750625	3545.8384
915.89966	2.6957786	1.0771804	3542.8967
916.80054	2.6992621	1.0792164	3542.2549
917.70142	2.7010651	1.0812591	3550.5286
918.60229	2.700927	1.0837953	3551.1018
919.50317	2.7052965	1.0864042	3541.1501
920.40405	2.7070405	1.0883371	3540.7373
921.30493	2.7109458	1.090569	3548.3
922.20581	2.7140532	1.0927148	3545.5425
923.10669	2.7172449	1.0952039	3541.4949
924.00757	2.7164195	1.0973649	3538.907
924.90845	2.7232058	1.0995623	3546.7422
925.80933	2.7254004	1.1019496	3546.707
926.71021	2.7234504	1.1044008	3538.9668
927.61108	2.7314208	1.106431	3543.6565
928.51196	2.7339988	1.1086376	3540.6406
929.41284	2.7352469	1.110821	3541.4448
930.31372	2.7387607	1.1129308	3543.7461
931.2146	2.7399447	1.1150962	3536.2307
932.11548	2.7421451	1.1170918	3536.541
933.01636	2.7451952	1.1191653	3542.9368
933.91724	2.7472112	1.1216029	3543.0889
934.81812	2.7523501	1.1243064	3545.7942
935.71899	2.75265	1.1265659	3529.72
936.61987	2.7567737	1.1287117	3537.5725
937.52075	2.7610204	1.1306802	3528.4265
938.42163	2.7601199	1.1327465	3534.8701
939.32251	2.7656088	1.135023	3534.98
940.22339	2.7679739	1.1371064	3529.4717
941.12427	2.76949	1.139238	3537.0671
942.02515	2.7733533	1.1415098	3534.7715
942.92603	2.7758284	1.1441352	3526.791
943.8269	2.778194	1.1462111	3529.8162
944.72778	2.7808864	1.148477	3534.792
945.62866	2.7869141	1.1507665	3538.1436
946.52954	2.7883334	1.1533555	3538.7744
947.43042	2.7884843	1.1558297	3537.3391
948.3313	2.7892628	1.158437	3531.4143
949.23218	2.7939939	1.1603863	3525.8743
950.13306	2.7962158	1.1628654	3530.7388
951.03394	2.7989841	1.1657878	3533.2842
951.93481	2.8023355	1.1682312	3525.7075
952.83569	2.8048496	1.1704861	3520.2488
953.73657	2.8076708	1.1727071	3529.3376
954.63745	2.8089972	1.174834	3524.9275
955.53833	2.8110676	1.1775661	3527.7844
956.43921	2.8170288	1.1801959	3524.7148
957.34009	2.8159111	1.1828026	3528.8367
958.24097	2.8235481	1.1854267	3521.7976
959.14185	2.8252134	1.1878991	3522.2576
960.04272	2.8299201	1.1902646	3522.374
960.9436	2.8285425	1.192283	3519.5208
961.84448	2.8346539	1.1945634	3522.3682
962.74536	2.832814	1.197179	3517.6208
963.64624	2.8379838	1.1999049	3518.7144
964.54712	2.8405268	1.2021439	3511.6392
965.448	2.8446567	1.204254	3509.7039
966.34888	2.8461699	1.2065977	3512.8428
967.24976	2.8494334	1.2088838	3511.8479
968.15063	2.8518119	1.2111747	3516.366
969.05151	2.8556495	1.2138836	3517.947
969.95239	2.8562863	1.2165184	3513.2395
970.85327	2.8586686	1.2191291	3508.9084
971.75415	2.8650522	1.2215509	3504.762
972.65503	2.8652678	1.2239205	3509.574
973.55591	2.8664482	1.2263846	3506.5127
974.45679	2.8697226	1.228647	3500.6741
975.35767	2.8765981	1.2307575	3506.1816
976.25854	2.8720865	1.233495	3505.1936
977.15942	2.8792112	1.2358286	3500.7495
978.0603	2.8806849	1.2382369	3505.3789
978.96118	2.884156	1.2407562	3506.6782
979.86206	2.8849182	1.2432268	3494.4089
980.76294	2.8906887	1.2462305	3502.8557
981.66382	2.8919995	1.2490084	3498.6738
982.5647	2.8926992	1.2516654	3494.6748
983.46558	2.8976419	1.2538955	3493.415
984.36646	2.8981071	1.2562394	3489.6194
985.26733	2.9013619	1.2588227	3494.7512
986.16821	2.9042537	1.261673	3488.4304
987.06909	2.9088724	1.2641473	3487.5308
987.96997	2.9099855	1.2663671	3487.8074
988.87085	2.9136729	1.2693199	3490.978
989.77173	2.912559	1.2718647	3484.7222
990.67261	2.9198129	1.2744344	3486.9778
991.57349	2.9218059	1.2773178	3483.5261
992.47437	2.923034	1.279904	3481.7568
993.37524	2.925864	1.2826571	3481.5713
994.27612	2.9283683	1.2858726	3486.5776
995.177	2.9337735	1.2887552	3476.8787
996.07788	2.9356205	1.2914617	3476.905
996.97876	2.9368594	1.2942904	3473.9905
997.87964	2.9403975	1.2970304	3474.9963
998.78052	2.9452477	1.2994168	3462.781
999.6814	2.946219	1.3017528	3468.0105
1000.5823	2.9484034	1.304008	3466.5569
1001.4832	2.9522238	1.3063939	3465.9878
1002.384	2.9512086	1.3090891	3467.7429
1003.2849	2.9546766	1.3120494	3466.7544
1004.1858	2.9585605	1.3146994	3459.7493
1005.0867	2.9658406	1.3170288	3463.0029
1005.9875	2.9672668	1.3193973	3458.7253
1006.8884	2.966929	1.3217049	3460.8508
1007.7893	2.9696612	1.3243915	3459.9719
1008.6902	2.9751184	1.3271447	3451.3184
1009.5911	2.9780312	1.3294638	3448.4629
1010.4919	2.9787662	1.3317647	3453.6563
1011.3928	2.9779723	1.334474	3444.6787
1012.2937	2.9837487	1.3369359	3447.6758
1013.1946	2.9873605	1.3392223	3438.7058
1014.0955	2.9931884	1.3419775	3447.7356
1014.9963	2.9914117	1.3446393	3443.5654
1015.8972	2.9952641	1.3472792	3439.6675
1016.7981	2.9982717	1.3499745	3441.217
1017.699	3.0012767	1.3526185	3433.0364
1018.5999	3.0066712	1.3551594	3437.3369
1019.5007	3.0039706	1.3576684	3436.4458
1020.4016	3.0067425	1.3602177	3430.2192
1021.3025	3.008615	1.3627114	3423.95
1022.2034	3.0139601	1.3648705	3415.4294
1023.1042	3.0137286	1.3669	3425.2744
1024.0051	3.0197582	1.3688655	3420.7065
1024.906	3.020895	1.3711126	3419.3816
1025.8069	3.028403	1.3736547	3421.5493
1026.7078	3.0280352	1.3763584	3422.6248
1027.6086	3.0289066	1.3792698	3417.4067
1028.5095	3.0318766	1.3821323	3415.7009
1029.4104	3.0363803	1.3856798	3411.7664
1030.3113	3.0411706	1.388952	3411.8784
1031.2122	3.0411437	1.3918535	3401.5815
1032.113	3.0448575	1.3944231	3400.9124
1033.0139	3.04652	1.3969241	3399.4126
1033.9148	3.0487092	1.3995398	3403.3142
1034.8157	3.0510499	1.4026381	3394.9993
1035.7166	3.0548105	1.4054462	3389.4705
1036.6174	3.053477	1.4078509	3385.0872
1037.5183	3.057734	1.4105806	3391.1296
1038.4192	3.0596421	1.4136858	3385.3108
1039.3201	3.0654943	1.4164904	3379.1367
1040.2209	3.0692286	1.4190459	3377.6624
1041.1218	3.0692492	1.4218731	3378.6348
1042.0227	3.0729203	1.4246337	3376.1873
1042.9236	3.0764635	1.4273237	3367.8247
1043.8245	3.078685	1.4297647	3364.8335
1044.7253	3.0805004	1.4326855	3367.4241
1045.6262	3.0839999	1.4359305	3365.071
1046.5271	3.087013	1.439338	3361.6743
1047.428	3.0898998	1.4424361	3354.7271
1048.3289	3.0947468	1.4455436	3353.3374
1049.2297	3.0945146	1.4486748	3353.0898
1050.1306	3.0957637	1.4516349	3346.3164
1051.0315	3.0999532	1.4543747	3338.2742
1051.9324	3.1041245	1.4570681	3342.7908
1052.8333	3.1036053	1.4600368	3335.9912
1053.7341	3.1105335	1.463101	3332.9006
1054.635	3.1134772	1.4659141	3325.3062
1055.5359	3.1117377	1.4687803	3324.575
1056.4368	3.1154828	1.4716102	3322.6609
1057.3376	3.1200793	1.474412	3323.2412
1058.2385	3.1220782	1.4770366	3322.2036
1059.1394	3.1244695	1.4796979	3313.1172
1060.0403	3.1268609	1.4822459	3309.8604
1060.9412	3.1319232	1.484987	3307.8625
1061.842	3.1330526	1.4876586	3303.877
1062.7429	3.1351428	1.4912118	3307.8059
1063.6438	3.140584	1.4942439	3300.6743
1064.5447	3.1414173	1.497378	3294.1743
1065.4456	3.1441004	1.500614	3296.9216
1066.3464	3.1456468	1.5039619	3282.2366
1067.2473	3.1514575	1.5065999	3275.4019
1068.1482	3.1521847	1.5093529	3274.9253
1069.0491	3.1574256	1.5124778	3270.2026
1069.95	3.1559579	1.5155823	3267.1658
1070.8508	3.1615138	1.5185575	3250.6816
1071.7517	3.1643786	1.5210946	3251.8877
1072.6526	3.1630664	1.5252844	3244.1365
1073.5535	3.1701384	1.53004	3219.1975
1074.4543	3.1718223	1.5340984	3197.907
1075.3552	3.1764123	1.5374609	3183.3259
1076.2561	3.1762073	1.5402445	3175.3376
1077.157	3.1807225	1.5438764	3170.6252
1078.0579	3.1810172	1.547254	3162.0776
1078.9587	3.1843128	1.5507895	3155.4731
1079.8596	3.1891098	1.5542302	3151.373
1080.7605	3.1909556	1.5579201	3137.605
1081.6614	3.1895354	1.5612167	3116.7607
1082.5623	3.1968482	1.5650873	3110.5217
1083.4631	3.1989031	1.5683889	3089.5408
1084.364	3.2005785	1.5710258	3083.8552
1085.2649	3.2075391	1.5742247	3069.2349
1086.1658	3.2086892	1.5794054	3051.7295
1087.0667	3.2117245	1.5884696	2980.1567
1087.3669	3.2099683	1.5923526	2941.0371