File: datasets/aisi_316_L/data/M1/test_2.csv
Time(s),Strain(%),Stress(MPa),Temp(C),Log_SR(s-1)
0.0,0.0,0.0,400.0,-3.0
0.2002002002002002,0.0002002002002002002,33.888757507507506,400.0,-3.0
0.4004004004004004,0.0004004004004004004,67.77751501501501,400.0,-3.0
0.6006006006006007,0.0006006006006006007,101.66627252252253,400.0,-3.0
0.8008008008008008,0.0008008008008008008,135.55503003003003,400.0,-3.0
1.0010010010010009,0.001001001001001001,145.89586568719957,400.0,-3.0
1.2012012012012014,0.0012012012012012014,146.8111998364646,400.0,-3.0
1.4014014014014016,0.0014014014014014015,147.66861730548524,400.0,-3.0
1.6016016016016017,0.0016016016016016017,148.47938538215718,400.0,-3.0
1.8018018018018018,0.0018018018018018018,149.2514584830377,400.0,-3.0
2.0020020020020017,0.002002002002002002,149.99071039507143,400.0,-3.0
2.2022022022022023,0.0022022022022022024,150.70163096823998,400.0,-3.0
2.402402402402403,0.0024024024024024027,151.38774756966328,400.0,-3.0
2.6026026026026026,0.0026026026026026027,152.05189389306042,400.0,-3.0
2.802802802802803,0.002802802802802803,152.69638887767974,400.0,-3.0
3.003003003003003,0.003003003003003003,153.32316005406562,400.0,-3.0
3.2032032032032034,0.0032032032032032033,153.93383112103146,400.0,-3.0
3.4034034034034035,0.0034034034034034037,154.5297857061071,400.0,-3.0
3.6036036036036037,0.0036036036036036037,155.11221480124112,400.0,-3.0
3.803803803803804,0.003803803803803804,155.68215272467575,400.0,-3.0
4.0040040040040035,0.004004004004004004,156.24050483972422,400.0,-3.0
4.2042042042042045,0.004204204204204204,156.7880692359241,400.0,-3.0
4.404404404404405,0.004404404404404405,157.32555391136228,400.0,-3.0
4.604604604604605,0.004604604604604605,157.85359055088998,400.0,-3.0
4.804804804804806,0.0048048048048048055,158.3727456927053,400.0,-3.0
5.005005005005005,0.005005005005005005,158.88352986607424,400.0,-3.0
5.205205205205205,0.005205205205205205,159.3864051348875,400.0,-3.0
5.405405405405405,0.005405405405405406,159.881791375537,400.0,-3.0
5.605605605605606,0.005605605605605606,160.3700715402916,400.0,-3.0
5.805805805805806,0.0058058058058058064,160.8515961003462,400.0,-3.0
6.006006006006006,0.006006006006006006,161.32668682016163,400.0,-3.0
6.206206206206206,0.006206206206206206,161.79563998258877,400.0,-3.0
6.406406406406407,0.006406406406406407,162.25872915976402,400.0,-3.0
6.606606606606607,0.006606606606606607,162.71620760589127,400.0,-3.0
6.806806806806807,0.0068068068068068074,163.16831033335794,400.0,-3.0
7.007007007007007,0.007007007007007007,163.6152559221402,400.0,-3.0
7.207207207207207,0.007207207207207207,164.05724810337284,400.0,-3.0
7.407407407407407,0.007407407407407408,164.49447715073967,400.0,-3.0
7.607607607607608,0.007607607607607608,164.92712110755076,400.0,-3.0
7.807807807807809,0.0078078078078078084,165.35534687270948,400.0,-3.0
8.008008008008007,0.008008008008008008,165.77931116498618,400.0,-3.0
8.208208208208209,0.00820820820820821,166.199161381926,400.0,-3.0
8.408408408408409,0.008408408408408409,166.6150363671851,400.0,-3.0
8.608608608608607,0.008608608608608608,167.027067097998,400.0,-3.0
8.80880880880881,0.00880880880880881,167.43537730274784,400.0,-3.0
9.00900900900901,0.009009009009009009,167.84008401716767,400.0,-3.0
9.20920920920921,0.00920920920920921,168.24129808649553,400.0,-3.0
9.40940940940941,0.00940940940940941,168.6391246198913,400.0,-3.0
9.609609609609612,0.009609609609609611,169.03366340257045,400.0,-3.0
9.80980980980981,0.00980980980980981,169.42500927038475,400.0,-3.0
10.01001001001001,0.01001001001001001,169.8132524509661,400.0,-3.0
10.21021021021021,0.010210210210210211,170.19847887502564,400.0,-3.0
10.41041041041041,0.01041041041041041,170.58077046095084,400.0,-3.0
10.610610610610612,0.010610610610610612,170.960205375459,400.0,-3.0
10.81081081081081,0.010810810810810811,171.33685827273447,400.0,-3.0
11.01101101101101,0.011011011011011011,171.71080051418994,400.0,-3.0
11.211211211211213,0.011211211211211212,172.08210037074397,400.0,-3.0
11.411411411411411,0.011411411411411412,172.45082320929316,400.0,-3.0
11.611611611611613,0.011611611611611613,172.81703166486798,400.0,-3.0
11.811811811811813,0.011811811811811812,173.18078579979928,400.0,-3.0
12.012012012012011,0.012012012012012012,173.542143251078,400.0,-3.0
12.212212212212213,0.012212212212212213,173.90115936696574,400.0,-3.0
12.412412412412412,0.012412412412412413,174.25788733380355,400.0,-3.0
12.612612612612613,0.012612612612612614,174.61237829386775,400.0,-3.0
12.812812812812814,0.012812812812812813,174.9646814550373,400.0,-3.0
13.013013013013012,0.013013013013013013,175.3148441929604,400.0,-3.0
13.213213213213214,0.013213213213213214,175.66291214633992,400.0,-3.0
13.413413413413414,0.013413413413413414,176.00892930589887,400.0,-3.0
13.613613613613614,0.013613613613613615,176.3529380975322,400.0,-3.0
13.813813813813814,0.013813813813813814,176.6949794601052,400.0,-3.0
14.014014014014014,0.014014014014014014,177.03509291831534,400.0,-3.0
14.214214214214214,0.014214214214214215,177.37331665099637,400.0,-3.0
14.414414414414415,0.014414414414414415,177.70968755521025,400.0,-3.0
14.614614614614615,0.014614614614614616,178.04424130644117,400.0,-3.0
14.814814814814815,0.014814814814814815,178.37701241517897,400.0,-3.0
15.015015015015015,0.015015015015015015,178.7080342801538,400.0,-3.0
15.215215215215215,0.015215215215215216,179.037339238463,400.0,-3.0
15.415415415415415,0.015415415415415416,179.36495861280898,400.0,-3.0
15.615615615615617,0.015615615615615617,179.6909227560507,400.0,-3.0
15.815815815815817,0.015815815815815818,180.01526109325366,400.0,-3.0
16.016016016016014,0.016016016016016016,180.3380021614084,400.0,-3.0
16.216216216216218,0.016216216216216217,180.65917364697506,400.0,-3.0
16.416416416416418,0.01641641641641642,180.97880242139692,400.0,-3.0
16.616616616616614,0.016616616616616616,181.29691457471785,400.0,-3.0
16.816816816816818,0.016816816816816817,181.61353544742494,400.0,-3.0
17.017017017017018,0.01701701701701702,181.92868966063136,400.0,-3.0
17.217217217217215,0.017217217217217216,182.2424011447029,400.0,-3.0
17.41741741741742,0.017417417417417418,182.5546931664273,400.0,-3.0
17.61761761761762,0.01761761761761762,182.8655883548149,400.0,-3.0
17.81781781781782,0.01781781781781782,183.17510872561516,400.0,-3.0
18.01801801801802,0.018018018018018018,183.48327570462638,400.0,-3.0
18.21821821821822,0.01821821821821822,183.7901101498709,400.0,-3.0
18.41841841841842,0.01841841841841842,184.09563237270257,400.0,-3.0
18.61861861861862,0.018618618618618618,184.3998621579089,400.0,-3.0
18.81881881881882,0.01881881881881882,184.70281878286673,400.0,-3.0
19.01901901901902,0.01901901901901902,185.00452103580452,400.0,-3.0
19.219219219219223,0.019219219219219222,185.30498723322287,400.0,-3.0
19.41941941941942,0.01941941941941942,185.60423523651932,400.0,-3.0
19.61961961961962,0.01961961961961962,185.90228246786305,400.0,-3.0
19.819819819819823,0.019819819819819822,186.199145925359,400.0,-3.0
20.02002002002002,0.02002002002002002,186.49484219754146,400.0,-3.0
20.22022022022022,0.02022022022022022,186.78938747723217,400.0,-3.0
20.42042042042042,0.020420420420420422,187.08279757479735,400.0,-3.0
20.62062062062062,0.02062062062062062,187.3750879308352,400.0,-3.0
20.82082082082082,0.02082082082082082,187.6662736283238,400.0,-3.0
21.02102102102102,0.021021021021021023,187.95636940425658,400.0,-3.0
21.221221221221224,0.021221221221221224,188.24538966079297,400.0,-3.0
21.42142142142142,0.02142142142142142,188.53334847594752,400.0,-3.0
21.62162162162162,0.021621621621621623,188.82025961384142,400.0,-3.0
21.821821821821825,0.021821821821821824,189.10613653453777,400.0,-3.0
22.02202202202202,0.022022022022022022,189.39099240348213,400.0,-3.0
22.22222222222222,0.022222222222222223,189.6748401005661,400.0,-3.0
22.422422422422425,0.022422422422422424,189.95769222883348,400.0,-3.0
22.62262262262262,0.022622622622622622,190.2395611228458,400.0,-3.0
22.822822822822822,0.022822822822822823,190.52045885672325,400.0,-3.0
23.023023023023026,0.023023023023023025,190.8003972518764,400.0,-3.0
23.223223223223226,0.023223223223223226,191.07938788444355,400.0,-3.0
23.423423423423422,0.023423423423423424,191.35744209244675,400.0,-3.0
23.623623623623626,0.023623623623623625,191.63457098267992,400.0,-3.0
23.823823823823826,0.023823823823823826,191.91078543734116,400.0,-3.0
24.024024024024023,0.024024024024024024,192.18609612042053,400.0,-3.0
24.224224224224226,0.024224224224224225,192.46051348385495,400.0,-3.0
24.424424424424426,0.024424424424424426,192.73404777345954,400.0,-3.0
24.624624624624623,0.024624624624624624,193.00670903464643,400.0,-3.0
24.824824824824823,0.024824824824824825,193.2785071179395,400.0,-3.0
25.025025025025027,0.025025025025025027,193.54945168429418,400.0,-3.0
25.225225225225227,0.025225225225225228,193.8195522102307,400.0,-3.0
25.425425425425423,0.025425425425425426,194.08881799278885,400.0,-3.0
25.625625625625627,0.025625625625625627,194.3572581543116,400.0,-3.0
25.825825825825827,0.025825825825825828,194.6248816470652,400.0,-3.0
26.026026026026024,0.026026026026026026,194.8916972577016,400.0,-3.0
26.226226226226228,0.026226226226226227,195.15771361157132,400.0,-3.0
26.426426426426428,0.02642642642642643,195.4229391768912,400.0,-3.0
26.626626626626628,0.02662662662662663,195.6873822687743,400.0,-3.0
26.826826826826828,0.026826826826826827,195.95105105312643,400.0,-3.0
27.027027027027028,0.02702702702702703,196.2139535504159,400.0,-3.0
27.227227227227228,0.02722722722722723,196.47609763932016,400.0,-3.0
27.42742742742743,0.027427427427427428,196.7374910602553,400.0,-3.0
27.62762762762763,0.02762762762762763,196.99814141879264,400.0,-3.0
27.82782782782783,0.02782782782782783,197.25805618896632,400.0,-3.0
28.02802802802803,0.028028028028028028,197.5172427164773,400.0,-3.0
28.22822822822823,0.02822822822822823,197.77570822179626,400.0,-3.0
28.42842842842843,0.02842842842842843,198.03345980317073,400.0,-3.0
28.628628628628633,0.02862862862862863,198.2905044395387,400.0,-3.0
28.82882882882883,0.02882882882882883,198.54684899335354,400.0,-3.0
29.02902902902903,0.02902902902902903,198.8025002133224,400.0,-3.0
29.22922922922923,0.029229229229229232,199.05746473706208,400.0,-3.0
29.42942942942943,0.02942942942942943,199.31174909367513,400.0,-3.0
29.62962962962963,0.02962962962962963,199.5653597062491,400.0,-3.0
29.82982982982983,0.029829829829829832,199.81830289428166,400.0,-3.0
30.03003003003003,0.03003003003003003,200.07058487603427,400.0,-3.0
30.23023023023023,0.03023023023023023,200.32221177081766,400.0,-3.0
30.43043043043043,0.030430430430430432,200.57318960121006,400.0,-3.0
30.630630630630634,0.030630630630630633,200.82352429521205,400.0,-3.0
30.83083083083083,0.03083083083083083,201.0732216883395,400.0,-3.0
31.03103103103103,0.031031031031031032,201.3222875256569,400.0,-3.0
31.231231231231234,0.031231231231231234,201.57072746375314,400.0,-3.0
31.431431431431434,0.031431431431431435,201.81854707266186,400.0,-3.0
31.631631631631635,0.031631631631631636,202.06575183772807,400.0,-3.0
31.83183183183183,0.03183183183183183,202.31234716142305,400.0,-3.0
32.03203203203203,0.03203203203203203,202.55833836510905,400.0,-3.0
32.232232232232235,0.03223223223223223,202.80373069075594,400.0,-3.0
32.432432432432435,0.032432432432432434,203.0485293026107,400.0,-3.0
32.632632632632635,0.032632632632632635,203.2927392888219,400.0,-3.0
32.832832832832835,0.03283283283283284,203.53636566302086,400.0,-3.0
33.033033033033036,0.03303303303303304,203.7794133658596,400.0,-3.0
33.23323323323323,0.03323323323323323,204.02188726650917,400.0,-3.0
33.433433433433436,0.033433433433433433,204.26379216411704,400.0,-3.0
33.633633633633636,0.033633633633633635,204.50513278922753,400.0,-3.0
33.833833833833836,0.033833833833833836,204.74591380516412,400.0,-3.0
34.034034034034036,0.03403403403403404,204.98613980937648,400.0,-3.0
34.234234234234236,0.03423423423423424,205.22581533475267,400.0,-3.0
34.43443443443443,0.03443443443443443,205.46494485089738,400.0,-3.0
34.63463463463464,0.034634634634634634,205.7035327653781,400.0,-3.0
34.83483483483484,0.034834834834834835,205.94158342493915,400.0,-3.0
35.03503503503504,0.035035035035035036,206.17910111668564,400.0,-3.0
35.23523523523524,0.03523523523523524,206.41609006923724,400.0,-3.0
35.43543543543544,0.03543543543543544,206.6525544538537,400.0,-3.0
35.63563563563564,0.03563563563563564,206.88849838553202,400.0,-3.0
35.83583583583583,0.035835835835835834,207.12392592407704,400.0,-3.0
36.03603603603604,0.036036036036036036,207.35884107514545,400.0,-3.0
36.23623623623624,0.03623623623623624,207.59324779126456,400.0,-3.0
36.43643643643644,0.03643643643643644,207.82714997282625,400.0,-3.0
36.63663663663664,0.03663663663663664,208.0605514690571,400.0,-3.0
36.83683683683684,0.03683683683683684,208.29345607896516,400.0,-3.0
37.03703703703704,0.03703703703703704,208.52586755226426,400.0,-3.0
37.23723723723724,0.037237237237237236,208.7577895902764,400.0,-3.0
37.43743743743744,0.03743743743743744,208.9892258468127,400.0,-3.0
37.63763763763764,0.03763763763763764,209.22017992903392,400.0,-3.0
37.83783783783784,0.03783783783783784,209.45065539829068,400.0,-3.0
38.03803803803804,0.03803803803803804,209.6806557709444,400.0,-3.0
38.23823823823824,0.03823823823823824,209.91018451916926,400.0,-3.0
38.438438438438446,0.038438438438438444,210.13924507173547,400.0,-3.0
38.63863863863864,0.03863863863863864,210.367840814775,400.0,-3.0
38.83883883883884,0.03883883883883884,210.59597509252973,400.0,-3.0
39.03903903903904,0.03903903903903904,210.82365120808282,400.0,-3.0
39.23923923923924,0.03923923923923924,211.0508724240733,400.0,-3.0
39.43943943943944,0.03943943943943944,211.27764196339515,400.0,-3.0
39.63963963963965,0.039639639639639644,211.50396300988038,400.0,-3.0
39.83983983983984,0.03983983983983984,211.72983870896738,400.0,-3.0
40.04004004004004,0.04004004004004004,211.95527216835416,400.0,-3.0
40.24024024024024,0.04024024024024024,212.18026645863748,400.0,-3.0
40.44044044044044,0.04044044044044044,212.404824613938,400.0,-3.0
40.64064064064064,0.04064064064064064,212.6289496325118,400.0,-3.0
40.84084084084084,0.040840840840840845,212.85264447734886,400.0,-3.0
41.04104104104105,0.041041041041041046,213.0759120767584,400.0,-3.0
41.24124124124124,0.04124124124124124,213.298755324942,400.0,-3.0
41.44144144144144,0.04144144144144144,213.52117708255426,400.0,-3.0
41.64164164164164,0.04164164164164164,213.7431801772515,400.0,-3.0
41.84184184184184,0.041841841841841844,213.9647674042296,400.0,-3.0
42.04204204204204,0.042042042042042045,214.18594152674947,400.0,-3.0
42.24224224224225,0.042242242242242246,214.4067052766524,400.0,-3.0
42.44244244244245,0.04244244244244245,214.62706135486434,400.0,-3.0
42.64264264264264,0.04264264264264264,214.84701243188974,400.0,-3.0
42.84284284284284,0.04284284284284284,215.06656114829534,400.0,-3.0
43.04304304304304,0.043043043043043044,215.28571011518412,400.0,-3.0
43.24324324324324,0.043243243243243246,215.5044619146592,400.0,-3.0
43.44344344344345,0.04344344344344345,215.7228191002787,400.0,-3.0
43.64364364364365,0.04364364364364365,215.94078419750136,400.0,-3.0
43.84384384384384,0.04384384384384384,216.1583597041229,400.0,-3.0
44.04404404404404,0.044044044044044044,216.37554809070417,400.0,-3.0
44.24424424424424,0.044244244244244245,216.59235180099003,400.0,-3.0
44.44444444444444,0.044444444444444446,216.8087732523208,400.0,-3.0
44.64464464464464,0.04464464464464465,217.02481483603466,400.0,-3.0
44.84484484484485,0.04484484484484485,217.240478917863,400.0,-3.0
45.04504504504505,0.04504504504504505,217.45576783831723,400.0,-3.0
45.24524524524524,0.045245245245245244,217.67068391306879,400.0,-3.0
45.44544544544544,0.045445445445445445,217.88522943332129,400.0,-3.0
45.645645645645644,0.04564564564564565,218.09940666617538,400.0,-3.0
45.845845845845844,0.04584584584584585,218.31321785498724,400.0,-3.0
46.04604604604605,0.04604604604604605,218.52666521971952,400.0,-3.0
46.24624624624625,0.04624624624624625,218.73975095728585,400.0,-3.0
46.44644644644645,0.04644644644644645,218.9524772418889,400.0,-3.0
46.646646646646644,0.046646646646646646,219.16484622535185,400.0,-3.0
46.846846846846844,0.04684684684684685,219.37686003744398,400.0,-3.0
47.047047047047045,0.04704704704704705,219.58852078619958,400.0,-3.0
47.24724724724725,0.04724724724724725,219.79983055823138,400.0,-3.0
47.44744744744745,0.04744744744744745,220.01079141903816,400.0,-3.0
47.64764764764765,0.04764764764764765,220.22140541330614,400.0,-3.0
47.84784784784785,0.04784784784784785,220.43167456520555,400.0,-3.0
48.048048048048045,0.04804804804804805,220.6416008786813,400.0,-3.0
48.248248248248245,0.04824824824824825,220.85118633773826,400.0,-3.0
48.44844844844845,0.04844844844844845,221.06043290672173,400.0,-3.0
48.64864864864865,0.04864864864864865,221.2693425305925,400.0,-3.0
48.84884884884885,0.04884884884884885,221.47791713519723,400.0,-3.0
49.04904904904905,0.049049049049049054,221.68615862753342,400.0,-3.0
49.249249249249246,0.04924924924924925,221.8940688960105,400.0,-3.0
49.449449449449446,0.04944944944944945,222.10164981070548,400.0,-3.0
49.649649649649646,0.04964964964964965,222.30890322361438,400.0,-3.0
49.84984984984985,0.04984984984984985,222.51583096889934,400.0,-3.0
50.050050050050054,0.05005005005005005,222.722434863131,400.0,-3.0
50.250250250250254,0.050250250250250254,222.9287167055272,400.0,-3.0
50.450450450450454,0.050450450450450456,223.13467827818673,400.0,-3.0
50.65065065065065,0.05065065065065065,223.34032134631983,400.0,-3.0
50.85085085085085,0.05085085085085085,223.54564765847405,400.0,-3.0
51.051051051051054,0.05105105105105105,223.75065894675674,400.0,-3.0
51.251251251251254,0.051251251251251254,223.9553569270531,400.0,-3.0
51.451451451451454,0.051451451451451455,224.15974329924114,400.0,-3.0
51.651651651651655,0.051651651651651656,224.3638197474024,400.0,-3.0
51.851851851851855,0.05185185185185186,224.56758794002968,400.0,-3.0
52.05205205205205,0.05205205205205205,224.77104953023067,400.0,-3.0
52.252252252252255,0.05225225225225225,224.97420615592839,400.0,-3.0
52.452452452452455,0.052452452452452454,225.17705944005843,400.0,-3.0
52.652652652652655,0.052652652652652655,225.37961099076264,400.0,-3.0
52.852852852852855,0.05285285285285286,225.58186240157968,400.0,-3.0
53.053053053053056,0.05305305305305306,225.7838152516324,400.0,-3.0
53.253253253253256,0.05325325325325326,225.9854711058122,400.0,-3.0
53.45345345345345,0.05345345345345345,226.1868315149601,400.0,-3.0
53.653653653653656,0.053653653653653655,226.3878980160451,400.0,-3.0
53.853853853853856,0.053853853853853856,226.58867213233964,400.0,-3.0
54.054054054054056,0.05405405405405406,226.7891553735919,400.0,-3.0
54.254254254254256,0.05425425425425426,226.9893492361955,400.0,-3.0
54.454454454454456,0.05445445445445446,227.1892552033566,400.0,-3.0
54.65465465465465,0.054654654654654654,227.38887474525794,400.0,-3.0
54.85485485485486,0.054854854854854855,227.5882093192206,400.0,-3.0
55.05505505505506,0.055055055055055056,227.78726036986293,400.0,-3.0
55.25525525525526,0.05525525525525526,227.98602932925704,400.0,-3.0
55.45545545545546,0.05545545545545546,228.18451761708283,400.0,-3.0
55.65565565565566,0.05565565565565566,228.3827266407795,400.0,-3.0
55.85585585585586,0.05585585585585586,228.58065779569478,400.0,-3.0
56.05605605605606,0.056056056056056056,228.77831246523164,400.0,-3.0
56.25625625625626,0.05625625625625626,228.97569202099288,400.0,-3.0
56.45645645645646,0.05645645645645646,229.17279782292337,400.0,-3.0
56.65665665665666,0.05665665665665666,229.36963121945018,400.0,-3.0
56.85685685685686,0.05685685685685686,229.56619354762026,400.0,-3.0
57.05705705705706,0.05705705705705706,229.7624861332364,400.0,-3.0
57.257257257257265,0.05725725725725726,229.95851029099083,400.0,-3.0
57.45745745745746,0.05745745745745746,230.15426732459662,400.0,-3.0
57.65765765765766,0.05765765765765766,230.34975852691758,400.0,-3.0
57.85785785785786,0.05785785785785786,230.54498518009575,400.0,-3.0
58.05805805805806,0.05805805805805806,230.73994855567705,400.0,-3.0
58.25825825825826,0.05825825825825826,230.93464991473505,400.0,-3.0
58.45845845845846,0.058458458458458464,231.12909050799297,400.0,-3.0
58.658658658658666,0.058658658658658665,231.32327157594375,400.0,-3.0
58.85885885885886,0.05885885885885886,231.51719434896827,400.0,-3.0
59.05905905905906,0.05905905905905906,231.71086004745194,400.0,-3.0
59.25925925925926,0.05925925925925926,231.90426988189944,400.0,-3.0
59.45945945945946,0.05945945945945946,232.09742505304777,400.0,-3.0
59.65965965965966,0.059659659659659664,232.29032675197791,400.0,-3.0
59.85985985985987,0.059859859859859865,232.48297616022415,400.0,-3.0
60.06006006006006,0.06006006006006006,232.67537444988272,400.0,-3.0
60.26026026026026,0.06026026026026026,232.86752278371807,400.0,-3.0
60.46046046046046,0.06046046046046046,233.05942231526802,400.0,-3.0
60.66066066066066,0.06066066066066066,233.25107418894729,400.0,-3.0
60.86086086086086,0.060860860860860864,233.44247954014935,400.0,-3.0
61.06106106106107,0.061061061061061066,233.63363949534724,400.0,-3.0
61.26126126126127,0.06126126126126127,233.82455517219225,400.0,-3.0
61.46146146146146,0.06146146146146146,234.01522767961197,400.0,-3.0
61.66166166166166,0.06166166166166166,234.2056581179064,400.0,-3.0
61.86186186186186,0.061861861861861864,234.39584757884288,400.0,-3.0
62.06206206206206,0.062062062062062065,234.58579714574958,400.0,-3.0
62.26226226226226,0.062262262262262266,234.77550789360765,400.0,-3.0
62.46246246246247,0.06246246246246247,234.9649808891425,400.0,-3.0
62.66266266266267,0.06266266266266267,235.1542171909131,400.0,-3.0
62.86286286286287,0.06286286286286287,235.34321784940047,400.0,-3.0
63.06306306306307,0.06306306306306307,235.53198390709483,400.0,-3.0
63.26326326326327,0.06326326326326327,235.7205163985817,400.0,-3.0
63.463463463463455,0.06346346346346346,235.90881635062638,400.0,-3.0
63.66366366366366,0.06366366366366366,236.09688478225777,400.0,-3.0
63.86386386386386,0.06386386386386386,236.28472270485054,400.0,-3.0
64.06406406406406,0.06406406406406406,236.47233112220684,400.0,-3.0
64.26426426426427,0.06426426426426426,236.65971103063592,400.0,-3.0
64.46446446446447,0.06446446446446447,236.8468634190337,400.0,-3.0
64.66466466466467,0.06466466466466467,237.03378926896036,400.0,-3.0
64.86486486486487,0.06486486486486487,237.22048955471772,400.0,-3.0
65.06506506506507,0.06506506506506507,237.40696524342482,400.0,-3.0
65.26526526526527,0.06526526526526527,237.59321729509276,400.0,-3.0
65.46546546546547,0.06546546546546547,237.77924666269897,400.0,-3.0
65.66566566566567,0.06566566566566567,237.96505429225957,400.0,-3.0
65.86586586586587,0.06586586586586587,238.15064112290162,400.0,-3.0
66.06606606606607,0.06606606606606608,238.33600808693393,400.0,-3.0
66.26626626626626,0.06626626626626626,238.52115610991717,400.0,-3.0
66.46646646646646,0.06646646646646646,238.70608611073285,400.0,-3.0
66.66666666666667,0.06666666666666667,238.8907990016514,400.0,-3.0
66.86686686686687,0.06686686686686687,239.0752956883996,400.0,-3.0
67.06706706706707,0.06706706706706707,239.2595770702268,400.0,-3.0
67.26726726726727,0.06726726726726727,239.44364403997076,400.0,-3.0
67.46746746746747,0.06746746746746747,239.62749748412176,400.0,-3.0
67.66766766766767,0.06766766766766767,239.81113828288684,400.0,-3.0
67.86786786786787,0.06786786786786787,239.9945673102527,400.0,-3.0
68.06806806806807,0.06806806806806807,240.1777854340478,400.0,-3.0
68.26826826826827,0.06826826826826828,240.36079351600364,400.0,-3.0
68.46846846846847,0.06846846846846848,240.54359241181564,400.0,-3.0
68.66866866866867,0.06866866866866868,240.72618297120255,400.0,-3.0
68.86886886886886,0.06886886886886887,240.90856603796578,400.0,-3.0
69.06906906906906,0.06906906906906907,241.09074245004763,400.0,-3.0
69.26926926926927,0.06926926926926927,241.27271303958867,400.0,-3.0
69.46946946946947,0.06946946946946947,241.4544786329847,400.0,-3.0
69.66966966966967,0.06966966966966967,241.63604005094288,400.0,-3.0
69.86986986986987,0.06986986986986987,241.81739810853693,400.0,-3.0
70.07007007007007,0.07007007007007007,241.99855361526204,400.0,-3.0
70.27027027027027,0.07027027027027027,242.17950737508858,400.0,-3.0
70.47047047047047,0.07047047047047048,242.36026018651583,400.0,-3.0
70.67067067067067,0.07067067067067068,242.54081284262423,400.0,-3.0
70.87087087087087,0.07087087087087088,242.72116613112783,400.0,-3.0
71.07107107107107,0.07107107107107108,242.9013208344251,400.0,-3.0
71.27127127127127,0.07127127127127128,243.08127772965025,400.0,-3.0
71.47147147147147,0.07147147147147148,243.26103758872284,400.0,-3.0
71.67167167167166,0.07167167167167167,243.4406011783975,400.0,-3.0
71.87187187187187,0.07187187187187187,243.619969260313,400.0,-3.0
72.07207207207207,0.07207207207207207,243.79914259104,400.0,-3.0
72.27227227227228,0.07227227227227227,243.97812192212947,400.0,-3.0
72.47247247247248,0.07247247247247247,244.15690800015904,400.0,-3.0
72.67267267267268,0.07267267267267268,244.3355015667801,400.0,-3.0
72.87287287287288,0.07287287287287288,244.51390335876357,400.0,-3.0
73.07307307307308,0.07307307307307308,244.69211410804525,400.0,-3.0
73.27327327327328,0.07327327327327328,244.870134541771,400.0,-3.0
73.47347347347348,0.07347347347347348,245.0479653823408,400.0,-3.0
73.67367367367368,0.07367367367367368,245.22560734745255,400.0,-3.0
73.87387387387388,0.07387387387387388,245.40306115014562,400.0,-3.0
74.07407407407408,0.07407407407407408,245.58032749884345,400.0,-3.0
74.27427427427428,0.07427427427427427,245.75740709739569,400.0,-3.0
74.47447447447448,0.07447447447447447,245.93430064512032,400.0,-3.0
74.67467467467468,0.07467467467467467,246.11100883684466,400.0,-3.0
74.87487487487488,0.07487487487487487,246.28753236294622,400.0,-3.0
75.07507507507508,0.07507507507507508,246.46387190939302,400.0,-3.0
75.27527527527528,0.07527527527527528,246.64002815778335,400.0,-3.0
75.47547547547548,0.07547547547547548,246.81600178538542,400.0,-3.0
75.67567567567568,0.07567567567567568,246.99179346517596,400.0,-3.0
75.87587587587588,0.07587587587587588,247.16740386587892,400.0,-3.0
76.07607607607608,0.07607607607607608,247.34283365200312,400.0,-3.0
76.27627627627628,0.07627627627627628,247.51808348388045,400.0,-3.0
76.47647647647648,0.07647647647647648,247.6931540177025,400.0,-3.0
76.67667667667668,0.07667667667667669,247.8680459055574,400.0,-3.0
76.87687687687689,0.07687687687687689,248.04275979546628,400.0,-3.0
77.07707707707708,0.07707707707707707,248.21729633141896,400.0,-3.0
77.27727727727728,0.07727727727727728,248.39165615340954,400.0,-3.0
77.47747747747748,0.07747747747747748,248.5658398974715,400.0,-3.0
77.67767767767768,0.07767767767767768,248.7398481957123,400.0,-3.0
77.87787787787788,0.07787787787787788,248.91368167634764,400.0,-3.0
78.07807807807808,0.07807807807807808,249.08734096373556,400.0,-3.0
78.27827827827828,0.07827827827827828,249.2608266784096,400.0,-3.0
78.47847847847848,0.07847847847847848,249.4341394371122,400.0,-3.0
78.67867867867868,0.07867867867867868,249.60727985282765,400.0,-3.0
78.87887887887888,0.07887887887887889,249.7802485348139,400.0,-3.0
79.07907907907908,0.07907907907907909,249.95304608863523,400.0,-3.0
79.2792792792793,0.07927927927927929,250.1256731161936,400.0,-3.0
79.4794794794795,0.07947947947947949,250.29813021576,400.0,-3.0
79.67967967967968,0.07967967967967968,250.4704179820056,400.0,-3.0
79.87987987987988,0.07987987987987988,250.64253700603211,400.0,-3.0
80.08008008008008,0.08008008008008008,250.81448787540248,400.0,-3.0
80.28028028028028,0.08028028028028028,250.98627117417064,400.0,-3.0
80.48048048048048,0.08048048048048048,251.15788748291092,400.0,-3.0
80.68068068068068,0.08068068068068068,251.32933737874805,400.0,-3.0
80.88088088088088,0.08088088088088088,251.5006214353855,400.0,-3.0
81.08108108108108,0.08108108108108109,251.67174022313444,400.0,-3.0
81.28128128128128,0.08128128128128129,251.84269430894224,400.0,-3.0
81.48148148148148,0.08148148148148149,252.0134842564202,400.0,-3.0
81.68168168168168,0.08168168168168169,252.1841106258718,400.0,-3.0
81.8818818818819,0.08188188188188189,252.35457397431963,400.0,-3.0
82.0820820820821,0.08208208208208209,252.5248748555332,400.0,-3.0
82.28228228228228,0.08228228228228228,252.695013820055,400.0,-3.0
82.48248248248248,0.08248248248248248,252.8649914152281,400.0,-3.0
82.68268268268268,0.08268268268268268,253.03480818522152,400.0,-3.0
82.88288288288288,0.08288288288288288,253.20446467105688,400.0,-3.0
83.08308308308308,0.08308308308308308,253.37396141063408,400.0,-3.0
83.28328328328328,0.08328328328328329,253.54329893875638,400.0,-3.0
83.48348348348348,0.08348348348348349,253.71247778715625,400.0,-3.0
83.68368368368368,0.08368368368368369,253.88149848451974,400.0,-3.0
83.88388388388388,0.08388388388388389,254.0503615565116,400.0,-3.0
84.08408408408408,0.08408408408408409,254.21906752579943,400.0,-3.0
84.28428428428428,0.08428428428428429,254.3876169120782,400.0,-3.0
84.4844844844845,0.08448448448448449,254.5560102320935,400.0,-3.0
84.6846846846847,0.0846846846846847,254.72424799966615,400.0,-3.0
84.8848848848849,0.0848848848848849,254.89233072571486,400.0,-3.0
85.08508508508508,0.08508508508508508,255.06025891827989,400.0,-3.0
85.28528528528528,0.08528528528528528,255.22803308254564,400.0,-3.0
85.48548548548548,0.08548548548548549,255.39565372086375,400.0,-3.0
85.68568568568568,0.08568568568568569,255.5631213327752,400.0,-3.0
85.88588588588588,0.08588588588588589,255.73043641503287,400.0,-3.0
86.08608608608608,0.08608608608608609,255.89759946162337,400.0,-3.0
86.28628628628628,0.08628628628628629,256.06461096378894,400.0,-3.0
86.48648648648648,0.08648648648648649,256.23147141004887,400.0,-3.0
86.68668668668668,0.08668668668668669,256.39818128622125,400.0,-3.0
86.8868868868869,0.0868868868868869,256.5647410754434,400.0,-3.0
87.0870870870871,0.0870870870870871,256.7311512581937,400.0,-3.0
87.2872872872873,0.0872872872872873,256.8974123123114,400.0,-3.0
87.4874874874875,0.0874874874874875,257.06352471301807,400.0,-3.0
87.68768768768768,0.08768768768768768,257.2294889329369,400.0,-3.0
87.88788788788789,0.08788788788788789,257.3953054421135,400.0,-3.0
88.08808808808809,0.08808808808808809,257.56097470803576,400.0,-3.0
88.28828828828829,0.08828828828828829,257.7264971956531,400.0,-3.0
88.48848848848849,0.08848848848848849,257.89187336739644,400.0,-3.0
88.68868868868869,0.08868868868868869,258.0571036831971,400.0,-3.0
88.88888888888889,0.08888888888888889,258.22218860050657,400.0,-3.0
89.08908908908909,0.0890890890890891,258.38712857431454,400.0,-3.0
89.28928928928929,0.0892892892892893,258.5519240571683,400.0,-3.0
89.4894894894895,0.0894894894894895,258.7165754991912,400.0,-3.0
89.6896896896897,0.0896896896896897,258.8810833481008,400.0,-3.0
89.8898898898899,0.0898898898898899,259.0454480492273,400.0,-3.0
90.0900900900901,0.0900900900900901,259.2096700455313,400.0,-3.0
90.2902902902903,0.0902902902902903,259.37374977762204,400.0,-3.0
90.49049049049049,0.09049049049049049,259.53768768377455,400.0,-3.0
90.69069069069069,0.09069069069069069,259.70148419994774,400.0,-3.0
90.89089089089089,0.09089089089089089,259.8651397598011,400.0,-3.0
91.09109109109109,0.09109109109109109,260.0286547947124,400.0,-3.0
91.29129129129129,0.0912912912912913,260.19202973379436,400.0,-3.0
91.49149149149149,0.0914914914914915,260.35526500391165,400.0,-3.0
91.69169169169169,0.0916916916916917,260.51836102969736,400.0,-3.0
91.8918918918919,0.0918918918918919,260.68131823356964,400.0,-3.0
92.0920920920921,0.0920920920920921,260.8441370357483,400.0,-3.0
92.2922922922923,0.0922922922922923,261.0068178542705,400.0,-3.0
92.4924924924925,0.0924924924924925,261.169361105007,400.0,-3.0
92.6926926926927,0.0926926926926927,261.3317672016784,400.0,-3.0
92.8928928928929,0.0928928928928929,261.49403655587037,400.0,-3.0
93.09309309309309,0.09309309309309309,261.65616957704935,400.0,-3.0
93.29329329329329,0.09329329329329329,261.81816667257834,400.0,-3.0
93.49349349349349,0.09349349349349349,261.9800282477317,400.0,-3.0
93.69369369369369,0.0936936936936937,262.1417547057108,400.0,-3.0
93.89389389389389,0.0938938938938939,262.3033464476585,400.0,-3.0
94.09409409409409,0.0940940940940941,262.46480387267445,400.0,-3.0
94.29429429429429,0.0942942942942943,262.6261273778298,400.0,-3.0
94.4944944944945,0.0944944944944945,262.78731735818144,400.0,-3.0
94.6946946946947,0.0946946946946947,262.94837420678675,400.0,-3.0
94.8948948948949,0.0948948948948949,263.109298314718,400.0,-3.0
95.0950950950951,0.0950950950950951,263.27009007107614,400.0,-3.0
95.2952952952953,0.0952952952952953,263.4307498630054,400.0,-3.0
95.4954954954955,0.0954954954954955,263.59127807570684,400.0,-3.0
95.6956956956957,0.0956956956956957,263.75167509245233,400.0,-3.0
95.89589589589589,0.0958958958958959,263.91194129459785,400.0,-3.0
96.09609609609609,0.0960960960960961,264.0720770615978,400.0,-3.0
96.29629629629629,0.0962962962962963,264.23208277101764,400.0,-3.0
96.49649649649649,0.0964964964964965,264.39195879854765,400.0,-3.0
96.69669669669669,0.0966966966966967,264.5517055180161,400.0,-3.0
96.8968968968969,0.0968968968968969,264.7113233014021,400.0,-3.0
97.0970970970971,0.0970970970970971,264.8708125188486,400.0,-3.0
97.2972972972973,0.0972972972972973,265.0301735386754,400.0,-3.0
97.4974974974975,0.0974974974974975,265.18940672739166,400.0,-3.0
97.6976976976977,0.0976976976976977,265.34851244970855,400.0,-3.0
97.8978978978979,0.0978978978978979,265.50749106855193,400.0,-3.0
98.0980980980981,0.09809809809809811,265.66634294507446,400.0,-3.0
98.2982982982983,0.09829829829829831,265.82506843866776,400.0,-3.0
98.49849849849849,0.0984984984984985,265.9836679069751,400.0,-3.0
98.69869869869869,0.0986986986986987,266.14214170590276,400.0,-3.0
98.89889889889889,0.0988988988988989,266.30049018963274,400.0,-3.0
99.09909909909909,0.0990990990990991,266.45871371063373,400.0,-3.0
99.29929929929929,0.0992992992992993,266.61681261967345,400.0,-3.0
99.4994994994995,0.0994994994994995,266.7747872658302,400.0,-3.0
99.6996996996997,0.0996996996996997,266.93263799650407,400.0,-3.0
99.8998998998999,0.0998998998998999,267.09036515742866,400.0,-3.0
100.0,0.1,267.1691825068238,400.0,-3.0