File: datasets/aisi_316_L/data/M1/test_0.csv
Time(s),Strain(%),Stress(MPa),Temp(C),Log_SR(s-1)
0.0,0.0,0.0,30.0,-3.0
0.2002002002002002,0.0002002002002002002,39.14735047547548,30.0,-3.0
0.4004004004004004,0.0004004004004004004,78.29470095095095,30.0,-3.0
0.6006006006006007,0.0006006006006006007,117.44205142642645,30.0,-3.0
0.8008008008008008,0.0008008008008008008,156.5894019019019,30.0,-3.0
1.0010010010010009,0.001001001001001001,195.73675237737737,30.0,-3.0
1.2012012012012014,0.0012012012012012014,234.8841028528529,30.0,-3.0
1.4014014014014016,0.0014014014014014015,274.0314533283283,30.0,-3.0
1.6016016016016017,0.0016016016016016017,281.33366254268094,30.0,-3.0
1.8018018018018018,0.0018018018018018018,282.79656025513003,30.0,-3.0
2.0020020020020017,0.002002002002002002,284.19726950119025,30.0,-3.0
2.2022022022022023,0.0022022022022022024,285.5442974950877,30.0,-3.0
2.402402402402403,0.0024024024024024027,286.84432777143167,30.0,-3.0
2.6026026026026026,0.0026026026026026027,288.1027295161902,30.0,-3.0
2.802802802802803,0.002802802802802803,289.32389657616056,30.0,-3.0
3.003003003003003,0.003003003003003003,290.5114811703113,30.0,-3.0
3.2032032032032034,0.0032032032032032033,291.66855982763576,30.0,-3.0
3.4034034034034035,0.0034034034034034037,292.7977541982678,30.0,-3.0
3.6036036036036037,0.0036036036036036037,293.90132093302856,30.0,-3.0
3.803803803803804,0.003803803803803804,294.98121982275757,30.0,-3.0
4.0040040040040035,0.004004004004004004,296.03916631890405,30.0,-3.0
4.2042042042042045,0.004204204204204204,297.0766726142352,30.0,-3.0
4.404404404404405,0.004404404404404405,298.09508019931775,30.0,-3.0
4.604604604604605,0.004604604604604605,299.095585969009,30.0,-3.0
4.804804804804806,0.0048048048048048055,300.07926338051533,30.0,-3.0
5.005005005005005,0.005005005005005005,301.04707976723364,30.0,-3.0
5.205205205205205,0.005205205205205205,301.99991063202503,30.0,-3.0
5.405405405405405,0.005405405405405406,302.93855154232017,30.0,-3.0
5.605605605605606,0.005605605605605606,303.86372810298406,30.0,-3.0
5.805805805805806,0.0058058058058058064,304.77610437485333,30.0,-3.0
6.006006006006006,0.006006006006006006,305.6762900262264,30.0,-3.0
6.206206206206206,0.006206206206206206,306.5648464437186,30.0,-3.0
6.406406406406407,0.006406406406406407,307.4422919824596,30.0,-3.0
6.606606606606607,0.006606606606606607,308.3091064998558,30.0,-3.0
6.806806806806807,0.0068068068068068074,309.16573528934305,30.0,-3.0
7.007007007007007,0.007007007007007007,310.0125925087865,30.0,-3.0
7.207207207207207,0.007207207207207207,310.8500641809743,30.0,-3.0
7.407407407407407,0.007407407407407408,311.6785108299765,30.0,-3.0
7.607607607607608,0.007607607607607608,312.4982698061694,30.0,-3.0
7.807807807807809,0.0078078078078078084,313.30965734388826,30.0,-3.0
8.008008008008007,0.008008008008008008,314.1129703885007,30.0,-3.0
8.208208208208209,0.00820820820820821,314.9084882238352,30.0,-3.0
8.408408408408409,0.008408408408408409,315.6964739261042,30.0,-3.0
8.608608608608607,0.008608608608608608,316.4771756664932,30.0,-3.0
8.80880880880881,0.00880880880880881,317.25082788131186,30.0,-3.0
9.00900900900901,0.009009009009009009,318.0176523258655,30.0,-3.0
9.20920920920921,0.00920920920920921,318.7778590259212,30.0,-3.0
9.40940940940941,0.00940940940940941,319.53164713872104,30.0,-3.0
9.609609609609612,0.009609609609609611,320.27920573387934,30.0,-3.0
9.80980980980981,0.00980980980980981,321.0207145031254,30.0,-3.0
10.01001001001001,0.01001001001001001,321.7563444066911,30.0,-3.0
10.21021021021021,0.010210210210210211,322.4862582631497,30.0,-3.0
10.41041041041041,0.01041041041041041,323.21061128866074,30.0,-3.0
10.610610610610612,0.010610610610610612,323.92955159084744,30.0,-3.0
10.81081081081081,0.010810810810810811,324.6432206219058,30.0,-3.0
11.01101101101101,0.011011011011011011,325.35175359500045,30.0,-3.0
11.211211211211213,0.011211211211211212,326.0552798675336,30.0,-3.0
11.411411411411411,0.011411411411411412,326.7539232944658,30.0,-3.0
11.611611611611613,0.011611611611611613,327.44780255451116,30.0,-3.0
11.811811811811813,0.011811811811811812,328.1370314517205,30.0,-3.0
12.012012012012011,0.012012012012012012,328.8217191946935,30.0,-3.0
12.212212212212213,0.012212212212212213,329.50197065542386,30.0,-3.0
12.412412412412412,0.012412412412412413,330.17788660957183,30.0,-3.0
12.612612612612613,0.012612612612612614,330.84956395977395,30.0,-3.0
12.812812812812814,0.012812812812812813,331.5170959434368,30.0,-3.0
13.013013013013012,0.013013013013013013,332.18057232631867,30.0,-3.0
13.213213213213214,0.013213213213213214,332.8400795830733,30.0,-3.0
13.413413413413414,0.013413413413413414,333.4957010658184,30.0,-3.0
13.613613613613614,0.013613613613613615,334.1475171616891,30.0,-3.0
13.813813813813814,0.013813813813813814,334.7956054402477,30.0,-3.0
14.014014014014014,0.014014014014014014,335.4400407915393,30.0,-3.0
14.214214214214214,0.014214214214214215,336.0808955555128,30.0,-3.0
14.414414414414415,0.014414414414414415,336.7182396434595,30.0,-3.0
14.614614614614615,0.014614614614614616,337.35214065206713,30.0,-3.0
14.814814814814815,0.014814814814814815,337.9826639706318,30.0,-3.0
15.015015015015015,0.015015015015015015,338.60987288192536,30.0,-3.0
15.215215215215215,0.015215215215215216,339.2338286571742,30.0,-3.0
15.415415415415415,0.015415415415415416,339.85459064556375,30.0,-3.0
15.615615615615617,0.015615615615615617,340.4722163586535,30.0,-3.0
15.815815815815817,0.015815815815815818,341.08676155005134,30.0,-3.0
16.016016016016014,0.016016016016016016,341.6982802906713,30.0,-3.0
16.216216216216218,0.016216216216216217,342.30682503987117,30.0,-3.0
16.416416416416418,0.01641641641641642,342.912446712743,30.0,-3.0
16.616616616616614,0.016616616616616616,343.51519474380984,30.0,-3.0
16.816816816816818,0.016816816816816817,344.1151171473603,30.0,-3.0
17.017017017017018,0.01701701701701702,344.71226057463747,30.0,-3.0
17.217217217217215,0.017217217217217216,345.3066703680805,30.0,-3.0
17.41741741741742,0.017417417417417418,345.89839061280304,30.0,-3.0
17.61761761761762,0.01761761761761762,346.4874641854802,30.0,-3.0
17.81781781781782,0.01781781781781782,347.07393280080134,30.0,-3.0
18.01801801801802,0.018018018018018018,347.65783705563643,30.0,-3.0
18.21821821821822,0.01821821821821822,348.239216471053,30.0,-3.0
18.41841841841842,0.01841841841841842,348.81810953230985,30.0,-3.0
18.61861861861862,0.018618618618618618,349.3945537269459,30.0,-3.0
18.81881881881882,0.01881881881881882,349.9685855810756,30.0,-3.0
19.01901901901902,0.01901901901901902,350.5402406939918,30.0,-3.0
19.219219219219223,0.019219219219219222,351.1095537711736,30.0,-3.0
19.41941941941942,0.01941941941941942,351.67655865578627,30.0,-3.0
19.61961961961962,0.01961961961961962,352.2412883587603,30.0,-3.0
19.819819819819823,0.019819819819819822,352.80377508752383,30.0,-3.0
20.02002002002002,0.02002002002002002,353.3640502734643,30.0,-3.0
20.22022022022022,0.02022022022022022,353.9221445981866,30.0,-3.0
20.42042042042042,0.020420420420420422,354.4780880186322,30.0,-3.0
20.62062062062062,0.02062062062062062,355.0319097911186,30.0,-3.0
20.82082082082082,0.02082082082082082,355.5836384943568,30.0,-3.0
21.02102102102102,0.021021021021021023,356.1333020514983,30.0,-3.0
21.221221221221224,0.021221221221221224,356.6809277512621,30.0,-3.0
21.42142142142142,0.02142142142142142,357.22654226818895,30.0,-3.0
21.62162162162162,0.021621621621621623,357.770171682065,30.0,-3.0
21.821821821821825,0.021821821821821824,358.3118414965576,30.0,-3.0
22.02202202202202,0.022022022022022022,358.85157665710284,30.0,-3.0
22.22222222222222,0.022222222222222223,359.3894015680789,30.0,-3.0
22.422422422422425,0.022422422422422424,359.9253401093023,30.0,-3.0
22.62262262262262,0.022622622622622622,360.4594156518784,30.0,-3.0
22.822822822822822,0.022822822822822823,360.99165107343725,30.0,-3.0
23.023023023023026,0.023023023023023025,361.52206877278354,30.0,-3.0
23.223223223223226,0.023223223223223226,362.05069068398825,30.0,-3.0
23.423423423423422,0.023423423423423424,362.5775382899479,30.0,-3.0
23.623623623623626,0.023623623623623625,363.1026326354357,30.0,-3.0
23.823823823823826,0.023823823823823826,363.62599433966875,30.0,-3.0
24.024024024024023,0.024024024024024024,364.14764360841065,30.0,-3.0
24.224224224224226,0.024224224224224225,364.6676002456341,30.0,-3.0
24.424424424424426,0.024424424424424426,365.1858836647593,30.0,-3.0
24.624624624624623,0.024624624624624624,365.70251289948965,30.0,-3.0
24.824824824824823,0.024824824824824825,366.21750661426097,30.0,-3.0
25.025025025025027,0.025025025025025027,366.73088311432133,30.0,-3.0
25.225225225225227,0.025225225225225228,367.24266035545713,30.0,-3.0
25.425425425425423,0.025425425425425426,367.7528559533815,30.0,-3.0
25.625625625625627,0.025625625625625627,368.2614871927982,30.0,-3.0
25.825825825825827,0.025825825825825828,368.7685710361549,30.0,-3.0
26.026026026026024,0.026026026026026026,369.27412413209953,30.0,-3.0
26.226226226226228,0.026226226226226227,369.7781628236512,30.0,-3.0
26.426426426426428,0.02642642642642643,370.2807031560977,30.0,-3.0
26.626626626626628,0.02662662662662663,370.7817608846308,30.0,-3.0
26.826826826826828,0.026826826826826827,371.2813514817298,30.0,-3.0
27.027027027027028,0.02702702702702703,371.77949014430374,30.0,-3.0
27.227227227227228,0.02722722722722723,372.27619180060117,30.0,-3.0
27.42742742742743,0.027427427427427428,372.771471116898,30.0,-3.0
27.62762762762763,0.02762762762762763,373.2653425039706,30.0,-3.0
27.82782782782783,0.02782782782782783,373.75782012336333,30.0,-3.0
28.02802802802803,0.028028028028028028,374.2489178934592,30.0,-3.0
28.22822822822823,0.02822822822822823,374.7386494953592,30.0,-3.0
28.42842842842843,0.02842842842842843,375.22702837858,30.0,-3.0
28.628628628628633,0.02862862862862863,375.71406776657466,30.0,-3.0
28.82882882882883,0.02882882882882883,376.19978066208523,30.0,-3.0
29.02902902902903,0.02902902902902903,376.6841798523312,30.0,-3.0
29.22922922922923,0.029229229229229232,377.1672779140421,30.0,-3.0
29.42942942942943,0.02942942942942943,377.64908721833797,30.0,-3.0
29.62962962962963,0.02962962962962963,378.1296199354656,30.0,-3.0
29.82982982982983,0.029829829829829832,378.60888803939304,30.0,-3.0
30.03003003003003,0.03003003003003003,379.08690331226956,30.0,-3.0
30.23023023023023,0.03023023023023023,379.56367734875585,30.0,-3.0
30.43043043043043,0.030430430430430432,380.0392215602272,30.0,-3.0
30.630630630630634,0.030630630630630633,380.51354717885647,30.0,-3.0
30.83083083083083,0.03083083083083083,380.9866652615795,30.0,-3.0
31.03103103103103,0.031031031031031032,381.4585866939481,30.0,-3.0
31.231231231231234,0.031231231231231234,381.9293221938736,30.0,-3.0
31.431431431431434,0.031431431431431435,382.3988823152651,30.0,-3.0
31.631631631631635,0.031631631631631636,382.8672774515669,30.0,-3.0
31.83183183183183,0.03183183183183183,383.3345178391968,30.0,-3.0
32.03203203203203,0.03203203203203203,383.80061356089004,30.0,-3.0
32.232232232232235,0.03223223223223223,384.2655745489519,30.0,-3.0
32.432432432432435,0.032432432432432434,384.72941058842093,30.0,-3.0
32.632632632632635,0.032632632632632635,385.1921313201472,30.0,-3.0
32.832832832832835,0.03283283283283284,385.6537462437878,30.0,-3.0
33.033033033033036,0.03303303303303304,386.1142647207213,30.0,-3.0
33.23323323323323,0.03323323323323323,386.5736959768864,30.0,-3.0
33.433433433433436,0.033433433433433433,387.0320491055438,30.0,-3.0
33.633633633633636,0.033633633633633635,387.489333069967,30.0,-3.0
33.833833833833836,0.033833833833833836,387.94555670606195,30.0,-3.0
34.034034034034036,0.03403403403403404,388.4007287249191,30.0,-3.0
34.234234234234236,0.03423423423423424,388.85485771529954,30.0,-3.0
34.43443443443443,0.03443443443443443,389.30795214605774,30.0,-3.0
34.63463463463464,0.034634634634634634,389.7600203685017,30.0,-3.0
34.83483483483484,0.034834834834834835,390.21107061869395,30.0,-3.0
35.03503503503504,0.035035035035035036,390.66111101969466,30.0,-3.0
35.23523523523524,0.03523523523523524,391.1101495837477,30.0,-3.0
35.43543543543544,0.03543543543543544,391.5581942144136,30.0,-3.0
35.63563563563564,0.03563563563563564,392.00525270864796,30.0,-3.0
35.83583583583583,0.035835835835835834,392.45133275883006,30.0,-3.0
36.03603603603604,0.036036036036036036,392.89644195474125,30.0,-3.0
36.23623623623624,0.03623623623623624,393.3405877854952,30.0,-3.0
36.43643643643644,0.03643643643643644,393.783777641421,30.0,-3.0
36.63663663663664,0.03663663663663664,394.2260188159016,30.0,-3.0
36.83683683683684,0.03683683683683684,394.66731850716764,30.0,-3.0
37.03703703703704,0.03703703703703704,395.1076838200485,30.0,-3.0
37.23723723723724,0.037237237237237236,395.5471217676827,30.0,-3.0
37.43743743743744,0.03743743743743744,395.9856392731865,30.0,-3.0
37.63763763763764,0.03763763763763764,396.42324317128487,30.0,-3.0
37.83783783783784,0.03783783783783784,396.85994020990313,30.0,-3.0
38.03803803803804,0.03803803803803804,397.29573705172265,30.0,-3.0
38.23823823823824,0.03823823823823824,397.73064027570047,30.0,-3.0
38.438438438438446,0.038438438438438444,398.164656378553,30.0,-3.0
38.63863863863864,0.03863863863863864,398.5977917762074,30.0,-3.0
38.83883883883884,0.03883883883883884,399.0300528052187,30.0,-3.0
39.03903903903904,0.03903903903903904,399.46144572415614,30.0,-3.0
39.23923923923924,0.03923923923923924,399.89197671495646,30.0,-3.0
39.43943943943944,0.03943943943943944,400.321651884249,30.0,-3.0
39.63963963963965,0.039639639639639644,400.7504772646498,30.0,-3.0
39.83983983983984,0.03983983983983984,401.178458816028,30.0,-3.0
40.04004004004004,0.04004004004004004,401.6056024267435,30.0,-3.0
40.24024024024024,0.04024024024024024,402.031913914858,30.0,-3.0
40.44044044044044,0.04044044044044044,402.4573990293196,30.0,-3.0
40.64064064064064,0.04064064064064064,402.8820634511215,30.0,-3.0
40.84084084084084,0.040840840840840845,403.30591279443576,30.0,-3.0
41.04104104104105,0.041041041041041046,403.72895260772253,30.0,-3.0
41.24124124124124,0.04124124124124124,404.15118837481594,30.0,-3.0
41.44144144144144,0.04144144144144144,404.5726255159866,30.0,-3.0
41.64164164164164,0.04164164164164164,404.9932693889811,30.0,-3.0
41.84184184184184,0.041841841841841844,405.41312529004085,30.0,-3.0
42.04204204204204,0.042042042042042045,405.8321984548983,30.0,-3.0
42.24224224224225,0.042242242242242246,406.25049405975267,30.0,-3.0
42.44244244244245,0.04244244244244245,406.66801722222635,30.0,-3.0
42.64264264264264,0.04264264264264264,407.08477300229976,30.0,-3.0
42.84284284284284,0.04284284284284284,407.5007664032285,30.0,-3.0
43.04304304304304,0.043043043043043044,407.9160023724412,30.0,-3.0
43.24324324324324,0.043243243243243246,408.3304858024186,30.0,-3.0
43.44344344344345,0.04344344344344345,408.74422153155524,30.0,-3.0
43.64364364364365,0.04364364364364365,409.157214345004,30.0,-3.0
43.84384384384384,0.04384384384384384,409.5694689755028,30.0,-3.0
44.04404404404404,0.044044044044044044,409.98099010418593,30.0,-3.0
44.24424424424424,0.044244244244244245,410.39178236137764,30.0,-3.0
44.44444444444444,0.044444444444444446,410.80185032737154,30.0,-3.0
44.64464464464464,0.04464464464464465,411.21119853319357,30.0,-3.0
44.84484484484485,0.04484484484484485,411.61983146135054,30.0,-3.0
45.04504504504505,0.04504504504504505,412.0277535465637,30.0,-3.0
45.24524524524524,0.045245245245245244,412.4349691764879,30.0,-3.0
45.44544544544544,0.045445445445445445,412.84148269241746,30.0,-3.0
45.645645645645644,0.04564564564564565,413.2472983899772,30.0,-3.0
45.845845845845844,0.04584584584584585,413.65242051980164,30.0,-3.0
46.04604604604605,0.04604604604604605,414.0568532882001,30.0,-3.0
46.24624624624625,0.04624624624624625,414.46060085780954,30.0,-3.0
46.44644644644645,0.04644644644644645,414.8636673482347,30.0,-3.0
46.646646646646644,0.046646646646646646,415.2660568366767,30.0,-3.0
46.846846846846844,0.04684684684684685,415.6677733585493,30.0,-3.0
47.047047047047045,0.04704704704704705,416.06882090808404,30.0,-3.0
47.24724724724725,0.04724724724724725,416.46920343892333,30.0,-3.0
47.44744744744745,0.04744744744744745,416.86892486470356,30.0,-3.0
47.64764764764765,0.04764764764764765,417.2679890596263,30.0,-3.0
47.84784784784785,0.04784784784784785,417.6663998590201,30.0,-3.0
48.048048048048045,0.04804804804804805,418.0641610598912,30.0,-3.0
48.248248248248245,0.04824824824824825,418.46127642146433,30.0,-3.0
48.44844844844845,0.04844844844844845,418.85774966571364,30.0,-3.0
48.64864864864865,0.04864864864864865,419.25358447788443,30.0,-3.0
48.84884884884885,0.04884884884884885,419.648784507005,30.0,-3.0
49.04904904904905,0.049049049049049054,420.0433533663891,30.0,-3.0
49.249249249249246,0.04924924924924925,420.4372946341304,30.0,-3.0
49.449449449449446,0.04944944944944945,420.83061185358673,30.0,-3.0
49.649649649649646,0.04964964964964965,421.22330853385694,30.0,-3.0
49.84984984984985,0.04984984984984985,421.6153881502487,30.0,-3.0
50.050050050050054,0.05005005005005005,422.00685414473793,30.0,-3.0
50.250250250250254,0.050250250250250254,422.39770992642104,30.0,-3.0
50.450450450450454,0.050450450450450456,422.787958871958,30.0,-3.0
50.65065065065065,0.05065065065065065,423.17760432600863,30.0,-3.0
50.85085085085085,0.05085085085085085,423.56664960166125,30.0,-3.0
51.051051051051054,0.05105105105105105,423.9550979808535,30.0,-3.0
51.251251251251254,0.051251251251251254,424.342952714786,30.0,-3.0
51.451451451451454,0.051451451451451455,424.7302170243296,30.0,-3.0
51.651651651651655,0.051651651651651656,425.1168941004243,30.0,-3.0
51.851851851851855,0.05185185185185186,425.5029871044732,30.0,-3.0
52.05205205205205,0.05205205205205205,425.8884991687283,30.0,-3.0
52.252252252252255,0.05225225225225225,426.27343339667004,30.0,-3.0
52.452452452452455,0.052452452452452454,426.6577928633815,30.0,-3.0
52.652652652652655,0.052652652652652655,427.04158061591454,30.0,-3.0
52.852852852852855,0.05285285285285286,427.424799673652,30.0,-3.0
53.053053053053056,0.05305305305305306,427.8074530286617,30.0,-3.0
53.253253253253256,0.05325325325325326,428.18954364604645,30.0,-3.0
53.45345345345345,0.05345345345345345,428.5710744642867,30.0,-3.0
53.653653653653656,0.053653653653653655,428.9520483955789,30.0,-3.0
53.853853853853856,0.053853853853853856,429.3324683261675,30.0,-3.0
54.054054054054056,0.05405405405405406,429.7123371166717,30.0,-3.0
54.254254254254256,0.05425425425425426,430.09165760240694,30.0,-3.0
54.454454454454456,0.05445445445445446,430.4704325937017,30.0,-3.0
54.65465465465465,0.054654654654654654,430.8486648762078,30.0,-3.0
54.85485485485486,0.054854854854854855,431.2263572112074,30.0,-3.0
55.05505505505506,0.055055055055055056,431.60351233591405,30.0,-3.0
55.25525525525526,0.05525525525525526,431.980132963769,30.0,-3.0
55.45545545545546,0.05545545545545546,432.3562217847332,30.0,-3.0
55.65565565565566,0.05565565565565566,432.73178146557416,30.0,-3.0
55.85585585585586,0.05585585585585586,433.1068146501492,30.0,-3.0
56.05605605605606,0.056056056056056056,433.4813239596829,30.0,-3.0
56.25625625625626,0.05625625625625626,433.8553119930415,30.0,-3.0
56.45645645645646,0.05645645645645646,434.22878132700185,30.0,-3.0
56.65665665665666,0.05665665665665666,434.6017345165175,30.0,-3.0
56.85685685685686,0.05685685685685686,434.9741740949794,30.0,-3.0
57.05705705705706,0.05705705705705706,435.3461025744732,30.0,-3.0
57.257257257257265,0.05725725725725726,435.71752244603283,30.0,-3.0
57.45745745745746,0.05745745745745746,436.0884361798893,30.0,-3.0
57.65765765765766,0.05765765765765766,436.45884622571674,30.0,-3.0
57.85785785785786,0.05785785785785786,436.82875501287396,30.0,-3.0
58.05805805805806,0.05805805805805806,437.1981649506427,30.0,-3.0
58.25825825825826,0.05825825825825826,437.5670784284622,30.0,-3.0
58.45845845845846,0.058458458458458464,437.93549781615985,30.0,-3.0
58.658658658658666,0.058658658658658665,438.3034254641794,30.0,-3.0
58.85885885885886,0.05885885885885886,438.6708637038044,30.0,-3.0
59.05905905905906,0.05905905905905906,439.03781484737937,30.0,-3.0
59.25925925925926,0.05925925925925926,439.4042811885273,30.0,-3.0
59.45945945945946,0.05945945945945946,439.77026500236354,30.0,-3.0
59.65965965965966,0.059659659659659664,440.13576854570755,30.0,-3.0
59.85985985985987,0.059859859859859865,440.50079405729014,30.0,-3.0
60.06006006006006,0.06006006006006006,440.86534375795924,30.0,-3.0
60.26026026026026,0.06026026026026026,441.2294198508811,30.0,-3.0
60.46046046046046,0.06046046046046046,441.5930245217397,30.0,-3.0
60.66066066066066,0.06066066066066066,441.956159938933,30.0,-3.0
60.86086086086086,0.060860860860860864,442.31882825376573,30.0,-3.0
61.06106106106107,0.061061061061061066,442.68103160064044,30.0,-3.0
61.26126126126127,0.06126126126126127,443.04277209724455,30.0,-3.0
61.46146146146146,0.06146146146146146,443.4040518447363,30.0,-3.0
61.66166166166166,0.06166166166166166,443.7648729279263,30.0,-3.0
61.86186186186186,0.061861861861861864,444.1252374154581,30.0,-3.0
62.06206206206206,0.062062062062062065,444.48514735998486,30.0,-3.0
62.26226226226226,0.062262262262262266,444.8446047983441,30.0,-3.0
62.46246246246247,0.06246246246246247,445.20361175173065,30.0,-3.0
62.66266266266267,0.06266266266266267,445.56217022586577,30.0,-3.0
62.86286286286287,0.06286286286286287,445.92028221116516,30.0,-3.0
63.06306306306307,0.06306306306306307,446.27794968290345,30.0,-3.0
63.26326326326327,0.06326326326326327,446.6351746013781,30.0,-3.0
63.463463463463455,0.06346346346346346,446.9919589120687,30.0,-3.0
63.66366366366366,0.06366366366366366,447.34830454579645,30.0,-3.0
63.86386386386386,0.06386386386386386,447.7042134188796,30.0,-3.0
64.06406406406406,0.06406406406406406,448.05968743328793,30.0,-3.0
64.26426426426427,0.06426426426426426,448.41472847679427,30.0,-3.0
64.46446446446447,0.06446446446446447,448.7693384231248,30.0,-3.0
64.66466466466467,0.06466466466466467,449.12351913210625,30.0,-3.0
64.86486486486487,0.06486486486486487,449.4772724498122,30.0,-3.0
65.06506506506507,0.06506506506506507,449.83060020870687,30.0,-3.0
65.26526526526527,0.06526526526526527,450.18350422778644,30.0,-3.0
65.46546546546547,0.06546546546546547,450.53598631271996,30.0,-3.0
65.66566566566567,0.06566566566566567,450.88804825598646,30.0,-3.0
65.86586586586587,0.06586586586586587,451.2396918370118,30.0,-3.0
66.06606606606607,0.06606606606606608,451.59091882230274,30.0,-3.0
66.26626626626626,0.06626626626626626,451.94173096558,30.0,-3.0
66.46646646646646,0.06646646646646646,452.29213000790895,30.0,-3.0
66.66666666666667,0.06666666666666667,452.64211767782837,30.0,-3.0
66.86686686686687,0.06686686686686687,452.99169569147824,30.0,-3.0
67.06706706706707,0.06706706706706707,453.3408657527258,30.0,-3.0
67.26726726726727,0.06726726726726727,453.68962955328914,30.0,-3.0
67.46746746746747,0.06746746746746747,454.03798877286,30.0,-3.0
67.66766766766767,0.06766766766766767,454.38594507922454,30.0,-3.0
67.86786786786787,0.06786786786786787,454.73350012838273,30.0,-3.0
68.06806806806807,0.06806806806806807,455.08065556466636,30.0,-3.0
68.26826826826827,0.06826826826826828,455.4274130208549,30.0,-3.0
68.46846846846847,0.06846846846846848,455.7737741182906,30.0,-3.0
68.66866866866867,0.06866866866866868,456.11974046699163,30.0,-3.0
68.86886886886886,0.06886886886886887,456.465313665764,30.0,-3.0
69.06906906906906,0.06906906906906907,456.8104953023121,30.0,-3.0
69.26926926926927,0.06926926926926927,457.1552869533475,30.0,-3.0
69.46946946946947,0.06946946946946947,457.4996901846966,30.0,-3.0
69.66966966966967,0.06966966966966967,457.84370655140737,30.0,-3.0
69.86986986986987,0.06986986986986987,458.18733759785357,30.0,-3.0
70.07007007007007,0.07007007007007007,458.5305848578391,30.0,-3.0
70.27027027027027,0.07027027027027027,458.8734498546993,30.0,-3.0
70.47047047047047,0.07047047047047048,459.21593410140355,30.0,-3.0
70.67067067067067,0.07067067067067068,459.55803910065345,30.0,-3.0
70.87087087087087,0.07087087087087088,459.8997663449826,30.0,-3.0
71.07107107107107,0.07107107107107108,460.241117316853,30.0,-3.0
71.27127127127127,0.07127127127127128,460.5820934887518,30.0,-3.0
71.47147147147147,0.07147147147147148,460.9226963232859,30.0,-3.0
71.67167167167166,0.07167167167167167,461.2629272732758,30.0,-3.0
71.87187187187187,0.07187187187187187,461.6027877818485,30.0,-3.0
72.07207207207207,0.07207207207207207,461.9422792825283,30.0,-3.0
72.27227227227228,0.07227227227227227,462.2814031993282,30.0,-3.0
72.47247247247248,0.07247247247247247,462.620160946838,30.0,-3.0
72.67267267267268,0.07267267267267268,462.95855393031337,30.0,-3.0
72.87287287287288,0.07287287287287288,463.29658354576276,30.0,-3.0
73.07307307307308,0.07307307307307308,463.63425118003295,30.0,-3.0
73.27327327327328,0.07327327327327328,463.9715582108952,30.0,-3.0
73.47347347347348,0.07347347347347348,464.3085060071282,30.0,-3.0
73.67367367367368,0.07367367367367368,464.64509592860134,30.0,-3.0
73.87387387387388,0.07387387387387388,464.98132932635735,30.0,-3.0
74.07407407407408,0.07407407407407408,465.3172075426927,30.0,-3.0
74.27427427427428,0.07427427427427427,465.65273191123765,30.0,-3.0
74.47447447447448,0.07447447447447447,465.987903757036,30.0,-3.0
74.67467467467468,0.07467467467467467,466.3227243966228,30.0,-3.0
74.87487487487488,0.07487487487487487,466.65719513810166,30.0,-3.0
75.07507507507508,0.07507507507507508,466.9913172812214,30.0,-3.0
75.27527527527528,0.07527527527527528,467.3250921174512,30.0,-3.0
75.47547547547548,0.07547547547547548,467.6585209300557,30.0,-3.0
75.67567567567568,0.07567567567567568,467.99160499416814,30.0,-3.0
75.87587587587588,0.07587587587587588,468.3243455768637,30.0,-3.0
76.07607607607608,0.07607607607607608,468.6567439372312,30.0,-3.0
76.27627627627628,0.07627627627627628,468.98880132644484,30.0,-3.0
76.47647647647648,0.07647647647647648,469.32051898783396,30.0,-3.0
76.67667667667668,0.07667667667667669,469.6518981569529,30.0,-3.0
76.87687687687689,0.07687687687687689,469.9829400616498,30.0,-3.0
77.07707707707708,0.07707707707707707,470.3136459221347,30.0,-3.0
77.27727727727728,0.07727727727727728,470.6440169510465,30.0,-3.0
77.47747747747748,0.07747747747747748,470.97405435351976,30.0,-3.0
77.67767767767768,0.07767767767767768,471.30375932725,30.0,-3.0
77.87787787787788,0.07787787787787788,471.63313306255884,30.0,-3.0
78.07807807807808,0.07807807807807808,471.96217674245855,30.0,-3.0
78.27827827827828,0.07827827827827828,472.29089154271486,30.0,-3.0
78.47847847847848,0.07847847847847848,472.61927863191045,30.0,-3.0
78.67867867867868,0.07867867867867868,472.94733917150666,30.0,-3.0
78.87887887887888,0.07887887887887889,473.2750743159048,30.0,-3.0
79.07907907907908,0.07907907907907909,473.6024852125074,30.0,-3.0
79.2792792792793,0.07927927927927929,473.9295730017776,30.0,-3.0
79.4794794794795,0.07947947947947949,474.25633881729897,30.0,-3.0
79.67967967967968,0.07967967967967968,474.5827837858339,30.0,-3.0
79.87987987987988,0.07987987987987988,474.90890902738187,30.0,-3.0
80.08008008008008,0.08008008008008008,475.234715655237,30.0,-3.0
80.28028028028028,0.08028028028028028,475.5602047760447,30.0,-3.0
80.48048048048048,0.08048048048048048,475.88537748985743,30.0,-3.0
80.68068068068068,0.08068068068068068,476.2102348901913,30.0,-3.0
80.88088088088088,0.08088088088088088,476.5347780640801,30.0,-3.0
81.08108108108108,0.08108108108108109,476.8590080921299,30.0,-3.0
81.28128128128128,0.08128128128128129,477.18292604857317,30.0,-3.0
81.48148148148148,0.08148148148148149,477.50653300132143,30.0,-3.0
81.68168168168168,0.08168168168168169,477.82983001201836,30.0,-3.0
81.8818818818819,0.08188188188188189,478.1528181360916,30.0,-3.0
82.0820820820821,0.08208208208208209,478.4754984228044,30.0,-3.0
82.28228228228228,0.08228228228228228,478.797871915306,30.0,-3.0
82.48248248248248,0.08248248248248248,479.11993965068325,30.0,-3.0
82.68268268268268,0.08268268268268268,479.4417026600091,30.0,-3.0
82.88288288288288,0.08288288288288288,479.76316196839286,30.0,-3.0
83.08308308308308,0.08308308308308308,480.08431859502866,30.0,-3.0
83.28328328328328,0.08328328328328329,480.40517355324357,30.0,-3.0
83.48348348348348,0.08348348348348349,480.72572785054615,30.0,-3.0
83.68368368368368,0.08368368368368369,481.0459824886725,30.0,-3.0
83.88388388388388,0.08388388388388389,481.36593846363434,30.0,-3.0
84.08408408408408,0.08408408408408409,481.6855967657643,30.0,-3.0
84.28428428428428,0.08428428428428429,482.00495837976257,30.0,-3.0
84.4844844844845,0.08448448448448449,482.32402428474126,30.0,-3.0
84.6846846846847,0.0846846846846847,482.6427954542702,30.0,-3.0
84.8848848848849,0.0848848848848849,482.9612728564209,30.0,-3.0
85.08508508508508,0.08508508508508508,483.2794574538106,30.0,-3.0
85.28528528528528,0.08528528528528528,483.5973502036454,30.0,-3.0
85.48548548548548,0.08548548548548549,483.91495205776414,30.0,-3.0
85.68568568568568,0.08568568568568569,484.2322639626799,30.0,-3.0
85.88588588588588,0.08588588588588589,484.5492868596229,30.0,-3.0
86.08608608608608,0.08608608608608609,484.86602168458234,30.0,-3.0
86.28628628628628,0.08628628628628629,485.18246936834703,30.0,-3.0
86.48648648648648,0.08648648648648649,485.4986308365468,30.0,-3.0
86.68668668668668,0.08668668668668669,485.8145070096929,30.0,-3.0
86.8868868868869,0.0868868868868869,486.1300988032177,30.0,-3.0
87.0870870870871,0.0870870870870871,486.4454071275149,30.0,-3.0
87.2872872872873,0.0872872872872873,486.7604328879783,30.0,-3.0
87.4874874874875,0.0874874874874875,487.0751769850412,30.0,-3.0
87.68768768768768,0.08768768768768768,487.3896403142139,30.0,-3.0
87.88788788788789,0.08788788788788789,487.70382376612304,30.0,-3.0
88.08808808808809,0.08808808808808809,488.0177282265483,30.0,-3.0
88.28828828828829,0.08828828828828829,488.3313545764601,30.0,-3.0
88.48848848848849,0.08848848848848849,488.6447036920569,30.0,-3.0
88.68868868868869,0.08868868868868869,488.95777644480063,30.0,-3.0
88.88888888888889,0.08888888888888889,489.2705737014547,30.0,-3.0
89.08908908908909,0.0890890890890891,489.5830963241182,30.0,-3.0
89.28928928928929,0.0892892892892893,489.8953451702621,30.0,-3.0
89.4894894894895,0.0894894894894895,490.2073210927648,30.0,-3.0
89.6896896896897,0.0896896896896897,490.51902493994623,30.0,-3.0
89.8898898898899,0.0898898898898899,490.83045755560283,30.0,-3.0
90.0900900900901,0.0900900900900901,491.14161977904126,30.0,-3.0
90.2902902902903,0.0902902902902903,491.4525124451127,30.0,-3.0
90.49049049049049,0.09049049049049049,491.76313638424574,30.0,-3.0
90.69069069069069,0.09069069069069069,492.0734924224805,30.0,-3.0
90.89089089089089,0.09089089089089089,492.38358138150005,30.0,-3.0
91.09109109109109,0.09109109109109109,492.69340407866434,30.0,-3.0
91.29129129129129,0.0912912912912913,493.00296132704136,30.0,-3.0
91.49149149149149,0.0914914914914915,493.3122539354398,30.0,-3.0
91.69169169169169,0.0916916916916917,493.6212827084398,30.0,-3.0
91.8918918918919,0.0918918918918919,493.93004844642496,30.0,-3.0
92.0920920920921,0.0920920920920921,494.2385519456133,30.0,-3.0
92.2922922922923,0.0922922922922923,494.5467939980874,30.0,-3.0
92.4924924924925,0.0924924924924925,494.85477539182506,30.0,-3.0
92.6926926926927,0.0926926926926927,495.1624969107297,30.0,-3.0
92.8928928928929,0.0928928928928929,495.46995933465985,30.0,-3.0
93.09309309309309,0.09309309309309309,495.7771634394586,30.0,-3.0
93.29329329329329,0.09329329329329329,496.0841099969834,30.0,-3.0
93.49349349349349,0.09349349349349349,496.3907997751342,30.0,-3.0
93.69369369369369,0.0936936936936937,496.6972335378832,30.0,-3.0
93.89389389389389,0.0938938938938939,497.0034120453022,30.0,-3.0
94.09409409409409,0.0940940940940941,497.30933605359155,30.0,-3.0
94.29429429429429,0.0942942942942943,497.6150063151081,30.0,-3.0
94.4944944944945,0.0944944944944945,497.92042357839205,30.0,-3.0
94.6946946946947,0.0946946946946947,498.22558858819525,30.0,-3.0
94.8948948948949,0.0948948948948949,498.53050208550786,30.0,-3.0
95.0950950950951,0.0950950950950951,498.83516480758533,30.0,-3.0
95.2952952952953,0.0952952952952953,499.13957748797515,30.0,-3.0
95.4954954954955,0.0954954954954955,499.44374085654295,30.0,-3.0
95.6956956956957,0.0956956956956957,499.7476556394994,30.0,-3.0
95.89589589589589,0.0958958958958959,500.0513225594247,30.0,-3.0
96.09609609609609,0.0960960960960961,500.35474233529607,30.0,-3.0
96.29629629629629,0.0962962962962963,500.65791568251177,30.0,-3.0
96.49649649649649,0.0964964964964965,500.9608433129166,30.0,-3.0
96.69669669669669,0.0966966966966967,501.2635259348279,30.0,-3.0
96.8968968968969,0.0968968968968969,501.5659642530587,30.0,-3.0
97.0970970970971,0.0970970970970971,501.8681589689433,30.0,-3.0
97.2972972972973,0.0972972972972973,502.17011078036154,30.0,-3.0
97.4974974974975,0.0974974974974975,502.4718203817625,30.0,-3.0
97.6976976976977,0.0976976976976977,502.7732884641882,30.0,-3.0
97.8978978978979,0.0978978978978979,503.0745157152983,30.0,-3.0
98.0980980980981,0.09809809809809811,503.37550281939247,30.0,-3.0
98.2982982982983,0.09829829829829831,503.6762504574337,30.0,-3.0
98.49849849849849,0.0984984984984985,503.97675930707214,30.0,-3.0
98.69869869869869,0.0986986986986987,504.2770300426671,30.0,-3.0
98.89889889889889,0.0988988988988989,504.57706333531013,30.0,-3.0
99.09909909909909,0.0990990990990991,504.8768598528472,30.0,-3.0
99.29929929929929,0.0992992992992993,505.17642025990085,30.0,-3.0
99.4994994994995,0.0994994994994995,505.4757452178926,30.0,-3.0
99.6996996996997,0.0996996996996997,505.7748353850644,30.0,-3.0
99.8998998998999,0.0998998998998999,506.0736914165004,30.0,-3.0
100.0,0.1,506.2230318351732,30.0,-3.0