File: datasets/aisi_316_L/data/M1/test_3.csv
Time(s),Strain(%),Stress(MPa),Temp(C),Log_SR(s-1)
0.0,0.0,0.0,400.0,5.0
2.0020020020020022e-09,0.0002002002002002002,33.888757507507506,400.0,5.0
4.0040040040040044e-09,0.0004004004004004004,67.77751501501501,400.0,5.0
6.006006006006007e-09,0.0006006006006006007,101.66627252252253,400.0,5.0
8.008008008008009e-09,0.0008008008008008008,135.55503003003003,400.0,5.0
1.001001001001001e-08,0.001001001001001001,169.44378753753753,400.0,5.0
1.2012012012012013e-08,0.0012012012012012014,175.8615493035833,400.0,5.0
1.4014014014014015e-08,0.0014014014014014015,176.88862874077813,400.0,5.0
1.6016016016016018e-08,0.0016016016016016017,177.85982801064472,400.0,5.0
1.8018018018018017e-08,0.0018018018018018018,178.78467551442995,400.0,5.0
2.002002002002002e-08,0.002002002002002002,179.67020731800284,400.0,5.0
2.2022022022022023e-08,0.0022022022022022024,180.52180170295767,400.0,5.0
2.4024024024024027e-08,0.0024024024024024027,181.34368401618457,400.0,5.0
2.6026026026026026e-08,0.0026026026026026027,182.13924867015513,400.0,5.0
2.802802802802803e-08,0.002802802802802803,182.91127346553716,400.0,5.0
3.003003003003003e-08,0.003003003003003003,183.6620673440753,400.0,5.0
3.2032032032032035e-08,0.0032032032032032033,184.39357529490678,400.0,5.0
3.403403403403404e-08,0.0034034034034034037,185.10745473164403,400.0,5.0
3.6036036036036035e-08,0.0036036036036036037,185.80513231444323,400.0,5.0
3.803803803803804e-08,0.003803803803803804,186.48784702785562,400.0,5.0
4.004004004004004e-08,0.004004004004004004,187.15668338447375,400.0,5.0
4.2042042042042044e-08,0.004204204204204204,187.8125973962552,400.0,5.0
4.404404404404405e-08,0.004404404404404405,188.45643715681018,400.0,5.0
4.604604604604605e-08,0.004604604604604605,189.08895934598812,400.0,5.0
4.804804804804805e-08,0.0048048048048048055,189.71084260605457,400.0,5.0
5.005005005005005e-08,0.005005005005005005,190.32269848754362,400.0,5.0
5.205205205205205e-08,0.005205205205205205,190.92508048550067,400.0,5.0
5.4054054054054056e-08,0.005405405405405406,191.51849155959678,400.0,5.0
5.605605605605606e-08,0.005605605605605606,192.1033904389984,400.0,5.0
5.805805805805806e-08,0.0058058058058058064,192.6801969445869,400.0,5.0
6.006006006006006e-08,0.006006006006006006,193.2492965101484,400.0,5.0
6.206206206206207e-08,0.006206206206206206,193.81104404567103,400.0,5.0
6.406406406406407e-08,0.006406406406406407,194.36576725653282,400.0,5.0
6.606606606606607e-08,0.006606606606606607,194.91376950975706,400.0,5.0
6.806806806806808e-08,0.0068068068068068074,195.45533232094064,400.0,5.0
7.007007007007007e-08,0.007007007007007007,195.99071752169644,400.0,5.0
7.207207207207207e-08,0.007207207207207207,196.52016915657322,400.0,5.0
7.407407407407407e-08,0.007407407407407408,197.043915149768,400.0,5.0
7.607607607607608e-08,0.007607607607607608,197.5621687750117,400.0,5.0
7.807807807807808e-08,0.0078078078078078084,198.07512995642307,400.0,5.0
8.008008008008008e-08,0.008008008008008008,198.58298642358787,400.0,5.0
8.20820820820821e-08,0.00820820820820821,199.08591474042424,400.0,5.0
8.408408408408409e-08,0.008408408408408409,199.58408122435557,400.0,5.0
8.608608608608608e-08,0.008608608608608608,200.07764276981098,400.0,5.0
8.80880880880881e-08,0.00880880880880881,200.56674758799755,400.0,5.0
9.009009009009008e-08,0.009009009009009009,201.05153587316053,400.0,5.0
9.20920920920921e-08,0.00920920920920921,201.53214040410225,400.0,5.0
9.40940940940941e-08,0.00940940940940941,202.00868708851723,400.0,5.0
9.60960960960961e-08,0.009609609609609611,202.4812954566771,400.0,5.0
9.809809809809811e-08,0.00980980980980981,202.95007911013158,400.0,5.0
1.001001001001001e-07,0.01001001001001001,203.41514613035648,400.0,5.0
1.0210210210210212e-07,0.010210210210210211,203.87659945165117,400.0,5.0
1.041041041041041e-07,0.01041041041041041,204.33453720205046,400.0,5.0
1.0610610610610612e-07,0.010610610610610612,204.78905301555514,400.0,5.0
1.0810810810810811e-07,0.010810810810810811,205.2402363185888,400.0,5.0
1.1011011011011011e-07,0.011011011011011011,205.68817259324405,400.0,5.0
1.1211211211211212e-07,0.011211211211211212,206.13294361958626,400.0,5.0
1.1411411411411412e-07,0.011411411411411412,206.57462769902364,400.0,5.0
1.1611611611611612e-07,0.011611611611611613,207.01329986052903,400.0,5.0
1.1811811811811813e-07,0.011811811811811812,207.449032051301,400.0,5.0
1.2012012012012013e-07,0.012012012012012012,207.88189331328275,400.0,5.0
1.2212212212212212e-07,0.012212212212212213,208.31194994680465,400.0,5.0
1.2412412412412414e-07,0.012412412412412413,208.73926566248505,400.0,5.0
1.2612612612612615e-07,0.012612612612612614,209.16390172240716,400.0,5.0
1.2812812812812814e-07,0.012812812812812813,209.5859170714871,400.0,5.0
1.3013013013013013e-07,0.013013013013013013,210.00536845985621,400.0,5.0
1.3213213213213215e-07,0.013213213213213214,210.42231055700165,400.0,5.0
1.3413413413413414e-07,0.013413413413413414,210.83679605833564,400.0,5.0
1.3613613613613615e-07,0.013613613613613615,211.24887578480116,400.0,5.0
1.3813813813813814e-07,0.013813813813813814,211.6585987760648,400.0,5.0
1.4014014014014013e-07,0.014014014014014014,212.0660123777959,400.0,5.0
1.4214214214214215e-07,0.014214214214214215,212.47116232348657,400.0,5.0
1.4414414414414414e-07,0.014414414414414415,212.87409281122586,400.0,5.0
1.4614614614614616e-07,0.014614614614614616,213.2748465758047,400.0,5.0
1.4814814814814815e-07,0.014814814814814815,213.6734649564956,400.0,5.0
1.5015015015015016e-07,0.015015015015015015,214.0699879608214,400.0,5.0
1.5215215215215215e-07,0.015215215215215216,214.464454324601,400.0,5.0
1.5415415415415417e-07,0.015415415415415416,214.85690156853425,400.0,5.0
1.5615615615615616e-07,0.015615615615615617,215.24736605156932,400.0,5.0
1.5815815815815817e-07,0.015815815815815818,215.63588302127323,400.0,5.0
1.6016016016016016e-07,0.016016016016016016,216.02248666140977,400.0,5.0
1.6216216216216218e-07,0.016216216216216217,216.407210136913,400.0,5.0
1.641641641641642e-07,0.01641641641641642,216.7900856364284,400.0,5.0
1.6616616616616616e-07,0.016616616616616616,217.1711444125819,400.0,5.0
1.6816816816816818e-07,0.016816816816816817,217.55041682012404,400.0,5.0
1.701701701701702e-07,0.01701701701701702,217.92793235208458,400.0,5.0
1.7217217217217216e-07,0.017217217217217216,218.30371967406415,400.0,5.0
1.7417417417417417e-07,0.017417417417417418,218.6778066567792,400.0,5.0
1.761761761761762e-07,0.01761761761761762,219.05022040696838,400.0,5.0
1.781781781781782e-07,0.01781781781781782,219.42098729676007,400.0,5.0
1.8018018018018017e-07,0.018018018018018018,219.7901329915946,400.0,5.0
1.8218218218218218e-07,0.01821821821821822,220.15768247678724,400.0,5.0
1.841841841841842e-07,0.01841841841841842,220.5236600828125,400.0,5.0
1.861861861861862e-07,0.018618618618618618,220.88808950938406,400.0,5.0
1.881881881881882e-07,0.01881881881881882,221.25099384840055,400.0,5.0
1.901901901901902e-07,0.01901901901901902,221.61239560582183,400.0,5.0
1.921921921921922e-07,0.019219219219219222,221.97231672253636,400.0,5.0
1.941941941941942e-07,0.01941941941941942,222.33077859427598,400.0,5.0
1.9619619619619622e-07,0.01961961961961962,222.68780209063144,400.0,5.0
1.981981981981982e-07,0.019819819819819822,223.0434075732173,400.0,5.0
2.002002002002002e-07,0.02002002002002002,223.39761491303352,400.0,5.0
2.0220220220220221e-07,0.02022022022022022,223.75044350706563,400.0,5.0
2.0420420420420423e-07,0.020420420420420422,224.10191229416503,400.0,5.0
2.062062062062062e-07,0.02062062062062062,224.452039770247,400.0,5.0
2.082082082082082e-07,0.02082082082082082,224.80084400284255,400.0,5.0
2.1021021021021023e-07,0.021021021021021023,225.14834264503602,400.0,5.0
2.1221221221221224e-07,0.021221221221221224,225.49455294882227,400.0,5.0
2.142142142142142e-07,0.02142142142142142,225.83949177791106,400.0,5.0
2.1621621621621622e-07,0.021621621621621623,226.1831756200067,400.0,5.0
2.1821821821821824e-07,0.021821821821821824,226.52562059859008,400.0,5.0
2.2022022022022023e-07,0.022022022022022022,226.86684248422674,400.0,5.0
2.2222222222222222e-07,0.022222222222222223,227.20685670542403,400.0,5.0
2.2422422422422423e-07,0.022422422422422424,227.54567835906036,400.0,5.0
2.2622622622622622e-07,0.022622622622622622,227.88332222040543,400.0,5.0
2.2822822822822824e-07,0.022822822822822823,228.21980275275297,400.0,5.0
2.3023023023023026e-07,0.023023023023023025,228.5551341166818,400.0,5.0
2.3223223223223225e-07,0.023223223223223226,228.8893301789652,400.0,5.0
2.3423423423423424e-07,0.023423423423423424,229.22240452114272,400.0,5.0
2.3623623623623625e-07,0.023623623623623625,229.55437044777148,400.0,5.0
2.3823823823823827e-07,0.023823823823823826,229.88524099437063,400.0,5.0
2.4024024024024026e-07,0.024024024024024024,230.2150289350734,400.0,5.0
2.422422422422423e-07,0.024224224224224225,230.54374678999955,400.0,5.0
2.4424424424424424e-07,0.024424424424424426,230.87140683236078,400.0,5.0
2.4624624624624625e-07,0.024624624624624624,231.1980210953108,400.0,5.0
2.4824824824824827e-07,0.024824824824824825,231.52360137855152,400.0,5.0
2.502502502502503e-07,0.025025025025025027,231.84815925470537,400.0,5.0
2.522522522522523e-07,0.025225225225225228,232.1717060754644,400.0,5.0
2.5425425425425427e-07,0.025425425425425426,232.49425297752543,400.0,5.0
2.562562562562563e-07,0.025625625625625627,232.81581088832033,400.0,5.0
2.582582582582583e-07,0.025825825825825828,233.13639053154986,400.0,5.0
2.6026026026026026e-07,0.026026026026026026,233.45600243253,400.0,5.0
2.622622622622623e-07,0.026226226226226227,233.77465692335716,400.0,5.0
2.642642642642643e-07,0.02642642642642643,234.09236414790155,400.0,5.0
2.662662662662663e-07,0.02662662662662663,234.40913406663384,400.0,5.0
2.682682682682683e-07,0.026826826826826827,234.72497646129318,400.0,5.0
2.702702702702703e-07,0.02702702702702703,235.03990093940254,400.0,5.0
2.722722722722723e-07,0.02722722722722723,235.35391693863716,400.0,5.0
2.7427427427427427e-07,0.027427427427427428,235.66703373105236,400.0,5.0
2.762762762762763e-07,0.02762762762762763,235.97926042717614,400.0,5.0
2.782782782782783e-07,0.02782782782782783,236.29060597997147,400.0,5.0
2.8028028028028027e-07,0.028028028028028028,236.60107918867402,400.0,5.0
2.822822822822823e-07,0.02822822822822823,236.91068870250916,400.0,5.0
2.842842842842843e-07,0.02842842842842843,237.21944302429426,400.0,5.0
2.862862862862863e-07,0.02862862862862863,237.52735051392858,400.0,5.0
2.882882882882883e-07,0.02882882882882883,237.83441939177735,400.0,5.0
2.902902902902903e-07,0.02902902902902903,238.14065774195194,400.0,5.0
2.922922922922923e-07,0.029229229229229232,238.44607351549138,400.0,5.0
2.942942942942943e-07,0.02942942942942943,238.75067453344818,400.0,5.0
2.962962962962963e-07,0.02962962962962963,239.05446848988177,400.0,5.0
2.982982982982983e-07,0.029829829829829832,239.35746295476417,400.0,5.0
3.003003003003003e-07,0.03003003003003003,239.65966537679884,400.0,5.0
3.023023023023023e-07,0.03023023023023023,239.96108308615854,400.0,5.0
3.043043043043043e-07,0.030430430430430432,240.26172329714262,400.0,5.0
3.063063063063063e-07,0.030630630630630633,240.5615931107581,400.0,5.0
3.0830830830830834e-07,0.03083083083083083,240.86069951722692,400.0,5.0
3.103103103103103e-07,0.031031031031031032,241.15904939842142,400.0,5.0
3.123123123123123e-07,0.031231231231231234,241.45664953023126,400.0,5.0
3.1431431431431433e-07,0.031431431431431435,241.7535065848636,400.0,5.0
3.1631631631631635e-07,0.031631631631631636,242.04962713307927,400.0,5.0
3.183183183183183e-07,0.03183183183183183,242.34501764636656,400.0,5.0
3.2032032032032033e-07,0.03203203203203203,242.63968449905533,400.0,5.0
3.2232232232232234e-07,0.03223223223223223,242.93363397037328,400.0,5.0
3.2432432432432436e-07,0.032432432432432434,243.22687224644548,400.0,5.0
3.263263263263264e-07,0.032632632632632635,243.519405422241,400.0,5.0
3.283283283283284e-07,0.03283283283283284,243.81123950346617,400.0,5.0
3.3033033033033036e-07,0.03303303303303304,244.10238040840744,400.0,5.0
3.323323323323323e-07,0.03323323323323323,244.3928339697257,400.0,5.0
3.3433433433433434e-07,0.033433433433433433,244.68260593620263,400.0,5.0
3.3633633633633635e-07,0.033633633633633635,244.97170197444157,400.0,5.0
3.3833833833833837e-07,0.033833833833833836,245.2601276705238,400.0,5.0
3.403403403403404e-07,0.03403403403403404,245.54788853162196,400.0,5.0
3.423423423423424e-07,0.03423423423423424,245.83498998757187,400.0,5.0
3.443443443443443e-07,0.03443443443443443,246.1214373924039,400.0,5.0
3.4634634634634633e-07,0.034634634634634634,246.40723602583535,400.0,5.0
3.4834834834834834e-07,0.034834834834834835,246.69239109472502,400.0,5.0
3.5035035035035036e-07,0.035035035035035036,246.97690773449145,400.0,5.0
3.523523523523524e-07,0.03523523523523524,247.2607910104948,400.0,5.0
3.543543543543544e-07,0.03543543543543544,247.54404591938516,400.0,5.0
3.563563563563564e-07,0.03563563563563564,247.82667739041702,400.0,5.0
3.583583583583583e-07,0.035835835835835834,248.1086902867313,400.0,5.0
3.6036036036036033e-07,0.036036036036036036,248.3900894066063,400.0,5.0
3.6236236236236235e-07,0.03623623623623624,248.67087948467795,400.0,5.0
3.6436436436436437e-07,0.03643643643643644,248.95106519313038,400.0,5.0
3.663663663663664e-07,0.03663663663663664,249.230651142858,400.0,5.0
3.683683683683684e-07,0.03683683683683684,249.50964188459974,400.0,5.0
3.703703703703704e-07,0.03703703703703704,249.78804191004633,400.0,5.0
3.723723723723724e-07,0.037237237237237236,250.0658556529208,400.0,5.0
3.743743743743744e-07,0.03743743743743744,250.34308749003424,400.0,5.0
3.763763763763764e-07,0.03763763763763764,250.61974174231648,400.0,5.0
3.783783783783784e-07,0.03783783783783784,250.8958226758223,400.0,5.0
3.803803803803804e-07,0.03803803803803804,251.17133450271524,400.0,5.0
3.823823823823824e-07,0.03823823823823824,251.44628138222782,400.0,5.0
3.843843843843844e-07,0.038438438438438444,251.72066742160018,400.0,5.0
3.863863863863864e-07,0.03863863863863864,251.99449667699702,400.0,5.0
3.883883883883884e-07,0.03883883883883884,252.26777315440398,400.0,5.0
3.903903903903904e-07,0.03903903903903904,252.54050081050372,400.0,5.0
3.9239239239239244e-07,0.03923923923923924,252.81268355353174,400.0,5.0
3.9439439439439445e-07,0.03943943943943944,253.08432524411407,400.0,5.0
3.963963963963964e-07,0.039639639639639644,253.35542969608534,400.0,5.0
3.983983983983984e-07,0.03983983983983984,253.6260006772892,400.0,5.0
4.004004004004004e-07,0.04004004004004004,253.89604191036128,400.0,5.0
4.024024024024024e-07,0.04024024024024024,254.1655570734943,400.0,5.0
4.0440440440440443e-07,0.04044044044044044,254.43454980118733,400.0,5.0
4.0640640640640644e-07,0.04064064064064064,254.70302368497815,400.0,5.0
4.0840840840840846e-07,0.040840840840840845,254.97098227415995,400.0,5.0
4.104104104104105e-07,0.041041041041041046,255.23842907648293,400.0,5.0
4.124124124124124e-07,0.04124124124124124,255.50536755884033,400.0,5.0
4.144144144144144e-07,0.04144144144144144,255.77180114794035,400.0,5.0
4.164164164164164e-07,0.04164164164164164,256.03773323096357,400.0,5.0
4.1841841841841844e-07,0.041841841841841844,256.30316715620677,400.0,5.0
4.2042042042042045e-07,0.042042042042042045,256.5681062337127,400.0,5.0
4.2242242242242247e-07,0.042242242242242246,256.8325537358872,400.0,5.0
4.244244244244245e-07,0.04244244244244245,257.0965128981035,400.0,5.0
4.264264264264264e-07,0.04264264264264264,257.35998691929376,400.0,5.0
4.284284284284284e-07,0.04284284284284284,257.62297896252835,400.0,5.0
4.3043043043043043e-07,0.043043043043043044,257.8854921555835,400.0,5.0
4.3243243243243244e-07,0.043243243243243246,258.14752959149774,400.0,5.0
4.3443443443443446e-07,0.04344344344344345,258.40909432911576,400.0,5.0
4.364364364364365e-07,0.04364364364364365,258.670189393623,400.0,5.0
4.3843843843843844e-07,0.04384384384384384,258.93081777706783,400.0,5.0
4.4044044044044046e-07,0.044044044044044044,259.1909824388748,400.0,5.0
4.4244244244244247e-07,0.044244244244244245,259.45068630634614,400.0,5.0
4.4444444444444444e-07,0.044444444444444446,259.7099322751547,400.0,5.0
4.4644644644644645e-07,0.04464464464464465,259.96872320982624,400.0,5.0
4.4844844844844847e-07,0.04484484484484485,260.2270619442124,400.0,5.0
4.504504504504505e-07,0.04504504504504505,260.4849512819547,400.0,5.0
4.5245245245245245e-07,0.045245245245245244,260.7423939969393,400.0,5.0
4.5445445445445446e-07,0.045445445445445445,260.9993928337432,400.0,5.0
4.564564564564565e-07,0.04564564564564565,261.25595050807067,400.0,5.0
4.584584584584585e-07,0.04584584584584585,261.51206970718346,400.0,5.0
4.604604604604605e-07,0.04604604604604605,261.7677530903204,400.0,5.0
4.6246246246246253e-07,0.04624624624624625,262.02300328911076,400.0,5.0
4.644644644644645e-07,0.04644644644644645,262.2778229079788,400.0,5.0
4.6646646646646646e-07,0.046646646646646646,262.5322145245409,400.0,5.0
4.6846846846846847e-07,0.04684684684684685,262.78618068999566,400.0,5.0
4.704704704704705e-07,0.04704704704704705,263.0397239295059,400.0,5.0
4.724724724724725e-07,0.04724724724724725,263.29284674257394,400.0,5.0
4.744744744744745e-07,0.04744744744744745,263.5455516034103,400.0,5.0
4.7647647647647654e-07,0.04764764764764765,263.79784096129475,400.0,5.0
4.784784784784786e-07,0.04784784784784785,264.0497172409313,400.0,5.0
4.804804804804805e-07,0.04804804804804805,264.3011828427965,400.0,5.0
4.824824824824825e-07,0.04824824824824825,264.5522401434814,400.0,5.0
4.844844844844845e-07,0.04844844844844845,264.8028914960273,400.0,5.0
4.864864864864865e-07,0.04864864864864865,265.05313923025517,400.0,5.0
4.884884884884885e-07,0.04884884884884885,265.3029856530895,400.0,5.0
4.904904904904905e-07,0.049049049049049054,265.55243304887625,400.0,5.0
4.924924924924925e-07,0.04924924924924925,265.80148367969485,400.0,5.0
4.944944944944945e-07,0.04944944944944945,266.0501397856648,400.0,5.0
4.964964964964965e-07,0.04964964964964965,266.29840358524694,400.0,5.0
4.984984984984985e-07,0.04984984984984985,266.54627727553935,400.0,5.0
5.005005005005006e-07,0.05005005005005005,266.7937630325674,400.0,5.0
5.025025025025025e-07,0.050250250250250254,267.0408630115704,400.0,5.0
5.045045045045046e-07,0.050450450450450456,267.2875793472809,400.0,5.0
5.065065065065065e-07,0.05065065065065065,267.533914154201,400.0,5.0
5.085085085085085e-07,0.05085085085085085,267.7798695268732,400.0,5.0
5.105105105105105e-07,0.05105105105105105,268.02544754014656,400.0,5.0
5.125125125125126e-07,0.051251251251251254,268.270650249438,400.0,5.0
5.145145145145145e-07,0.051451451451451455,268.51547969098993,400.0,5.0
5.165165165165166e-07,0.051651651651651656,268.7599378821224,400.0,5.0
5.185185185185186e-07,0.05185185185185186,269.0040268214823,400.0,5.0
5.205205205205205e-07,0.05205205205205205,269.24774848928666,400.0,5.0
5.225225225225225e-07,0.05225225225225225,269.49110484756375,400.0,5.0
5.245245245245246e-07,0.052452452452452454,269.73409784038836,400.0,5.0
5.265265265265265e-07,0.052652652652652655,269.9767293941142,400.0,5.0
5.285285285285286e-07,0.05285285285285286,270.2190014176025,400.0,5.0
5.305305305305306e-07,0.05305305305305306,270.46091580244587,400.0,5.0
5.325325325325326e-07,0.05325325325325326,270.7024744231893,400.0,5.0
5.345345345345346e-07,0.05345345345345345,270.9436791375476,400.0,5.0
5.365365365365365e-07,0.053653653653653655,271.18453178661827,400.0,5.0
5.385385385385385e-07,0.053853853853853856,271.4250341950922,400.0,5.0
5.405405405405406e-07,0.05405405405405406,271.6651881714598,400.0,5.0
5.425425425425425e-07,0.05425425425425426,271.9049955082145,400.0,5.0
5.445445445445446e-07,0.05445445445445446,272.1444579820526,400.0,5.0
5.465465465465466e-07,0.054654654654654654,272.38357735407016,400.0,5.0
5.485485485485485e-07,0.054854854854854855,272.62235536995655,400.0,5.0
5.505505505505506e-07,0.055055055055055056,272.86079376018466,400.0,5.0
5.525525525525526e-07,0.05525525525525526,273.0988942401988,400.0,5.0
5.545545545545545e-07,0.05545545545545546,273.3366585105987,400.0,5.0
5.565565565565566e-07,0.05565565565565566,273.5740882573216,400.0,5.0
5.585585585585586e-07,0.05585585585585586,273.81118515182015,400.0,5.0
5.605605605605605e-07,0.056056056056056056,274.0479508512393,400.0,5.0
5.625625625625626e-07,0.05625625625625626,274.28438699858833,400.0,5.0
5.645645645645646e-07,0.05645645645645646,274.5204952229121,400.0,5.0
5.665665665665666e-07,0.05665665665665666,274.75627713945823,400.0,5.0
5.685685685685686e-07,0.05685685685685686,274.9917343498429,400.0,5.0
5.705705705705707e-07,0.05705705705705706,275.22686844221266,400.0,5.0
5.725725725725726e-07,0.05725725725725726,275.4616809914052,400.0,5.0
5.745745745745746e-07,0.05745745745745746,275.69617355910674,400.0,5.0
5.765765765765766e-07,0.05765765765765766,275.9303476940071,400.0,5.0
5.785785785785786e-07,0.05785785785785786,276.16420493195284,400.0,5.0
5.805805805805806e-07,0.05805805805805806,276.3977467960979,400.0,5.0
5.825825825825827e-07,0.05825825825825826,276.6309747970515,400.0,5.0
5.845845845845846e-07,0.058458458458458464,276.8638904330243,400.0,5.0
5.865865865865867e-07,0.058658658658658665,277.09649518997264,400.0,5.0
5.885885885885885e-07,0.05885885885885886,277.3287905417396,400.0,5.0
5.905905905905906e-07,0.05905905905905906,277.560777950195,400.0,5.0
5.925925925925926e-07,0.05925925925925926,277.792458865373,400.0,5.0
5.945945945945947e-07,0.05945945945945946,278.023834725607,400.0,5.0
5.965965965965966e-07,0.059659659659659664,278.2549069576638,400.0,5.0
5.985985985985987e-07,0.059859859859859865,278.48567697687446,400.0,5.0
6.006006006006006e-07,0.06006006006006006,278.7161461872644,400.0,5.0
6.026026026026026e-07,0.06026026026026026,278.94631598168087,400.0,5.0
6.046046046046046e-07,0.06046046046046046,279.17618774191845,400.0,5.0
6.066066066066066e-07,0.06066066066066066,279.40576283884377,400.0,5.0
6.086086086086086e-07,0.060860860860860864,279.6350426325168,400.0,5.0
6.106106106106107e-07,0.061061061061061066,279.86402847231204,400.0,5.0
6.126126126126126e-07,0.06126126126126127,280.0927216970368,400.0,5.0
6.146146146146146e-07,0.06146146146146146,280.32112363504814,400.0,5.0
6.166166166166167e-07,0.06166166166166166,280.5492356043688,400.0,5.0
6.186186186186186e-07,0.061861861861861864,280.77705891280004,400.0,5.0
6.206206206206206e-07,0.062062062062062065,281.0045948580342,400.0,5.0
6.226226226226227e-07,0.062262262262262266,281.231844727765,400.0,5.0
6.246246246246246e-07,0.06246246246246247,281.4588097997968,400.0,5.0
6.266266266266267e-07,0.06266266266266267,281.68549134215135,400.0,5.0
6.286286286286287e-07,0.06286286286286287,281.91189061317436,400.0,5.0
6.306306306306307e-07,0.06306306306306307,282.1380088616394,400.0,5.0
6.326326326326327e-07,0.06326326326326327,282.36384732685093,400.0,5.0
6.346346346346346e-07,0.06346346346346346,282.58940723874633,400.0,5.0
6.366366366366366e-07,0.06366366366366366,282.81468981799526,400.0,5.0
6.386386386386386e-07,0.06386386386386386,283.0396962760988,400.0,5.0
6.406406406406407e-07,0.06406406406406406,283.26442781548695,400.0,5.0
6.426426426426426e-07,0.06426426426426426,283.4888856296143,400.0,5.0
6.446446446446447e-07,0.06446446446446447,283.713070903055,400.0,5.0
6.466466466466467e-07,0.06466466466466467,283.9369848115961,400.0,5.0
6.486486486486487e-07,0.06486486486486487,284.16062852232994,400.0,5.0
6.506506506506507e-07,0.06506506506506507,284.3840031937447,400.0,5.0
6.526526526526528e-07,0.06526526526526527,284.6071099758144,400.0,5.0
6.546546546546547e-07,0.06546546546546547,284.82995001008715,400.0,5.0
6.566566566566568e-07,0.06566566566566567,285.05252442977286,400.0,5.0
6.586586586586587e-07,0.06586586586586587,285.2748343598286,400.0,5.0
6.606606606606607e-07,0.06606606606606608,285.49688091704456,400.0,5.0
6.626626626626627e-07,0.06626626626626626,285.7186652101271,400.0,5.0
6.646646646646646e-07,0.06646646646646646,285.94018833978197,400.0,5.0
6.666666666666667e-07,0.06666666666666667,286.1614513987956,400.0,5.0
6.686686686686687e-07,0.06686686686686687,286.38245547211596,400.0,5.0
6.706706706706706e-07,0.06706706706706707,286.60320163693206,400.0,5.0
6.726726726726727e-07,0.06726726726726727,286.8236909627522,400.0,5.0
6.746746746746747e-07,0.06746746746746747,287.04392451148146,400.0,5.0
6.766766766766767e-07,0.06766766766766767,287.2639033374985,400.0,5.0
6.786786786786787e-07,0.06786786786786787,287.4836284877305,400.0,5.0
6.806806806806808e-07,0.06806806806806807,287.70310100172804,400.0,5.0
6.826826826826827e-07,0.06826826826826828,287.92232191173815,400.0,5.0
6.846846846846848e-07,0.06846846846846848,288.1412922427776,400.0,5.0
6.866866866866868e-07,0.06866866866866868,288.3600130127036,400.0,5.0
6.886886886886886e-07,0.06886886886886887,288.57848523228523,400.0,5.0
6.906906906906907e-07,0.06906906906906907,288.7967099052732,400.0,5.0
6.926926926926927e-07,0.06926926926926927,289.01468802846836,400.0,5.0
6.946946946946947e-07,0.06946946946946947,289.23242059178983,400.0,5.0
6.966966966966967e-07,0.06966966966966967,289.44990857834296,400.0,5.0
6.986986986986988e-07,0.06986986986986987,289.66715296448456,400.0,5.0
7.007007007007007e-07,0.07007007007007007,289.88415471988907,400.0,5.0
7.027027027027028e-07,0.07027027027027027,290.100914807613,400.0,5.0
7.047047047047048e-07,0.07047047047047048,290.317434184159,400.0,5.0
7.067067067067067e-07,0.07067067067067068,290.53371379953904,400.0,5.0
7.087087087087088e-07,0.07087087087087088,290.7497545973363,400.0,5.0
7.107107107107107e-07,0.07107107107107108,290.9655575147668,400.0,5.0
7.127127127127128e-07,0.07127127127127128,291.1811234827407,400.0,5.0
7.147147147147148e-07,0.07147147147147148,291.39645342592155,400.0,5.0
7.167167167167166e-07,0.07167167167167167,291.61154826278596,400.0,5.0
7.187187187187187e-07,0.07187187187187187,291.8264089056825,400.0,5.0
7.207207207207207e-07,0.07207207207207207,292.04103626088863,400.0,5.0
7.227227227227227e-07,0.07227227227227227,292.25543122866884,400.0,5.0
7.247247247247247e-07,0.07247247247247247,292.46959470333024,400.0,5.0
7.267267267267268e-07,0.07267267267267268,292.683527573279,400.0,5.0
7.287287287287287e-07,0.07287287287287288,292.8972307210749,400.0,5.0
7.307307307307308e-07,0.07307307307307308,293.110705023486,400.0,5.0
7.327327327327328e-07,0.07327327327327328,293.3239513515426,400.0,5.0
7.347347347347348e-07,0.07347347347347348,293.53697057058986,400.0,5.0
7.367367367367368e-07,0.07367367367367368,293.7497635403407,400.0,5.0
7.387387387387389e-07,0.07387387387387388,293.96233111492757,400.0,5.0
7.407407407407408e-07,0.07407407407407408,294.17467414295345,400.0,5.0
7.427427427427427e-07,0.07427427427427427,294.38679346754276,400.0,5.0
7.447447447447448e-07,0.07447447447447447,294.5986899263914,400.0,5.0
7.467467467467467e-07,0.07467467467467467,294.81036435181596,400.0,5.0
7.487487487487488e-07,0.07487487487487487,295.02181757080285,400.0,5.0
7.507507507507508e-07,0.07507507507507508,295.2330504050564,400.0,5.0
7.527527527527528e-07,0.07527527527527528,295.4440636710466,400.0,5.0
7.547547547547548e-07,0.07547547547547548,295.65485818005646,400.0,5.0
7.567567567567568e-07,0.07567567567567568,295.8654347382283,400.0,5.0
7.587587587587588e-07,0.07587587587587588,296.07579414661024,400.0,5.0
7.607607607607608e-07,0.07607607607607608,296.28593720120125,400.0,5.0
7.627627627627629e-07,0.07627627627627628,296.49586469299663,400.0,5.0
7.647647647647648e-07,0.07647647647647648,296.7055774080323,400.0,5.0
7.667667667667669e-07,0.07667667667667669,296.91507612742873,400.0,5.0
7.687687687687688e-07,0.07687687687687689,297.12436162743455,400.0,5.0
7.707707707707707e-07,0.07707707707707707,297.33343467946946,400.0,5.0
7.727727727727728e-07,0.07727727727727728,297.5422960501668,400.0,5.0
7.747747747747747e-07,0.07747747747747748,297.7509465014154,400.0,5.0
7.767767767767768e-07,0.07767767767767768,297.95938679040154,400.0,5.0
7.787787787787788e-07,0.07787787787787788,298.1676176696493,400.0,5.0
7.807807807807808e-07,0.07807807807807808,298.37563988706194,400.0,5.0
7.827827827827828e-07,0.07827827827827828,298.58345418596144,400.0,5.0
7.847847847847849e-07,0.07847847847847848,298.7910613051287,400.0,5.0
7.867867867867868e-07,0.07867867867867868,298.9984619788422,400.0,5.0
7.887887887887889e-07,0.07887887887887889,299.2056569369175,400.0,5.0
7.907907907907909e-07,0.07907907907907909,299.4126469047452,400.0,5.0
7.927927927927928e-07,0.07927927927927929,299.61943260332885,400.0,5.0
7.947947947947949e-07,0.07947947947947949,299.8260147493227,400.0,5.0
7.967967967967968e-07,0.07967967967967968,300.0323940550688,400.0,5.0
7.987987987987988e-07,0.07987987987987988,300.23857122863353,400.0,5.0
8.008008008008008e-07,0.08008008008008008,300.44454697384407,400.0,5.0
8.028028028028028e-07,0.08028028028028028,300.65032199032436,400.0,5.0
8.048048048048048e-07,0.08048048048048048,300.8558969735304,400.0,5.0
8.068068068068068e-07,0.08068068068068068,301.0612726147855,400.0,5.0
8.088088088088089e-07,0.08088088088088088,301.2664496013153,400.0,5.0
8.108108108108108e-07,0.08108108108108109,301.4714286162815,400.0,5.0
8.128128128128129e-07,0.08128128128128129,301.67621033881636,400.0,5.0
8.148148148148149e-07,0.08148148148148149,301.88079544405645,400.0,5.0
8.168168168168169e-07,0.08168168168168169,302.08518460317526,400.0,5.0
8.188188188188189e-07,0.08188188188188189,302.2893784834168,400.0,5.0
8.20820820820821e-07,0.08208208208208209,302.4933777481278,400.0,5.0
8.228228228228228e-07,0.08228228228228228,302.6971830567898,400.0,5.0
8.248248248248248e-07,0.08248248248248248,302.9007950650516,400.0,5.0
8.268268268268268e-07,0.08268268268268268,303.1042144247602,400.0,5.0
8.288288288288288e-07,0.08288288288288288,303.307441783992,400.0,5.0
8.308308308308309e-07,0.08308308308308308,303.510477787084,400.0,5.0
8.328328328328328e-07,0.08328328328328329,303.71332307466423,400.0,5.0
8.348348348348349e-07,0.08348348348348349,303.9159782836819,400.0,5.0
8.368368368368369e-07,0.08368368368368369,304.11844404743726,400.0,5.0
8.388388388388389e-07,0.08388388388388389,304.320720995611,400.0,5.0
8.408408408408409e-07,0.08408408408408409,304.5228097542941,400.0,5.0
8.428428428428429e-07,0.08428428428428429,304.7247109460162,400.0,5.0
8.448448448448449e-07,0.08448448448448449,304.92642518977465,400.0,5.0
8.468468468468469e-07,0.0846846846846847,305.1279531010625,400.0,5.0
8.48848848848849e-07,0.0848848848848849,305.3292952918968,400.0,5.0
8.508508508508508e-07,0.08508508508508508,305.5304523708467,400.0,5.0
8.528528528528528e-07,0.08528528528528528,305.73142494306023,400.0,5.0
8.548548548548549e-07,0.08548548548548549,305.93221361029214,400.0,5.0
8.568568568568568e-07,0.08568568568568569,306.1328189709303,400.0,5.0
8.588588588588589e-07,0.08588588588588589,306.333241620023,400.0,5.0
8.608608608608609e-07,0.08608608608608609,306.53348214930446,400.0,5.0
8.628628628628629e-07,0.08628628628628629,306.733541147222,400.0,5.0
8.648648648648649e-07,0.08648648648648649,306.9334191989609,400.0,5.0
8.66866866866867e-07,0.08668668668668669,307.1331168864707,400.0,5.0
8.688688688688689e-07,0.0868868868868869,307.3326347884899,400.0,5.0
8.70870870870871e-07,0.0870870870870871,307.53197348057165,400.0,5.0
8.72872872872873e-07,0.0872872872872873,307.7311335351081,400.0,5.0
8.74874874874875e-07,0.0874874874874875,307.9301155213554,400.0,5.0
8.768768768768769e-07,0.08768768768768768,308.12892000545736,400.0,5.0
8.788788788788788e-07,0.08788788788788789,308.32754755047023,400.0,5.0
8.808808808808809e-07,0.08808808808808809,308.52599871638625,400.0,5.0
8.828828828828829e-07,0.08828828828828829,308.72427406015703,400.0,5.0
8.848848848848849e-07,0.08848848848848849,308.9223741357172,400.0,5.0
8.868868868868869e-07,0.08868868868868869,309.12029949400727,400.0,5.0
8.888888888888889e-07,0.08888888888888889,309.3180506829971,400.0,5.0
8.908908908908909e-07,0.0890890890890891,309.515628247708,400.0,5.0
8.928928928928929e-07,0.0892892892892893,309.71303273023506,400.0,5.0
8.94894894894895e-07,0.0894894894894895,309.9102646697701,400.0,5.0
8.968968968968969e-07,0.0896896896896897,310.107324602623,400.0,5.0
8.98898898898899e-07,0.0898898898898899,310.3042130622442,400.0,5.0
9.00900900900901e-07,0.0900900900900901,310.50093057924505,400.0,5.0
9.02902902902903e-07,0.0902902902902903,310.69747768142076,400.0,5.0
9.049049049049049e-07,0.09049049049049049,310.8938548937702,400.0,5.0
9.069069069069069e-07,0.09069069069069069,311.090062738518,400.0,5.0
9.089089089089089e-07,0.09089089089089089,311.2861017351342,400.0,5.0
9.109109109109109e-07,0.09109109109109109,311.48197240035563,400.0,5.0
9.12912912912913e-07,0.0912912912912913,311.67767524820607,400.0,5.0
9.149149149149149e-07,0.0914914914914915,311.8732107900162,400.0,5.0
9.16916916916917e-07,0.0916916916916917,312.06857953444353,400.0,5.0
9.18918918918919e-07,0.0918918918918919,312.2637819874927,400.0,5.0
9.20920920920921e-07,0.0920920920920921,312.4588186525345,400.0,5.0
9.22922922922923e-07,0.0922922922922923,312.6536900303255,400.0,5.0
9.249249249249251e-07,0.0924924924924925,312.84839661902726,400.0,5.0
9.26926926926927e-07,0.0926926926926927,313.04293891422543,400.0,5.0
9.28928928928929e-07,0.0928928928928929,313.2373174089484,400.0,5.0
9.30930930930931e-07,0.09309309309309309,313.43153259368614,400.0,5.0
9.329329329329329e-07,0.09329329329329329,313.6255849564088,400.0,5.0
9.34934934934935e-07,0.09349349349349349,313.8194749825845,400.0,5.0
9.369369369369369e-07,0.0936936936936937,314.0132031551985,400.0,5.0
9.389389389389389e-07,0.0938938938938939,314.2067699547699,400.0,5.0
9.40940940940941e-07,0.0940940940940941,314.40017585937056,400.0,5.0
9.429429429429429e-07,0.0942942942942943,314.59342134464214,400.0,5.0
9.44944944944945e-07,0.0944944944944945,314.78650688381373,400.0,5.0
9.46946946946947e-07,0.0946946946946947,314.9794329477192,400.0,5.0
9.48948948948949e-07,0.0948948948948949,315.17220000481433,400.0,5.0
9.50950950950951e-07,0.0950950950950951,315.3648085211938,400.0,5.0
9.529529529529531e-07,0.0952952952952953,315.5572589606082,400.0,5.0
9.549549549549551e-07,0.0954954954954955,315.74955178448033,400.0,5.0
9.569569569569571e-07,0.0956956956956957,315.9416874519222,400.0,5.0
9.589589589589589e-07,0.0958958958958959,316.133666419751,400.0,5.0
9.60960960960961e-07,0.0960960960960961,316.3254891425058,400.0,5.0
9.62962962962963e-07,0.0962962962962963,316.5171560724631,400.0,5.0
9.64964964964965e-07,0.0964964964964965,316.708667659653,400.0,5.0
9.66966966966967e-07,0.0966966966966967,316.9000243518752,400.0,5.0
9.68968968968969e-07,0.0968968968968969,317.09122659471456,400.0,5.0
9.70970970970971e-07,0.0970970970970971,317.28227483155615,400.0,5.0
9.72972972972973e-07,0.0972972972972973,317.4731695036013,400.0,5.0
9.74974974974975e-07,0.0974974974974975,317.6639110498824,400.0,5.0
9.76976976976977e-07,0.0976976976976977,317.85449990727807,400.0,5.0
9.789789789789791e-07,0.0978978978978979,318.04493651052826,400.0,5.0
9.80980980980981e-07,0.09809809809809811,318.23522129224887,400.0,5.0
9.82982982982983e-07,0.09829829829829831,318.42535468294653,400.0,5.0
9.84984984984985e-07,0.0984984984984985,318.61533711103317,400.0,5.0
9.86986986986987e-07,0.0986986986986987,318.80516900284044,400.0,5.0
9.88988988988989e-07,0.0988988988988989,318.9948507826341,400.0,5.0
9.90990990990991e-07,0.0990990990990991,319.1843828726279,400.0,5.0
9.92992992992993e-07,0.0992992992992993,319.37376569299795,400.0,5.0
9.94994994994995e-07,0.0994994994994995,319.5629996618964,400.0,5.0
9.96996996996997e-07,0.0996996996996997,319.75208519546567,400.0,5.0
9.98998998998999e-07,0.0998998998998999,319.9410227078513,400.0,5.0
1e-06,0.1,320.0354360849783,400.0,5.0