File: datasets/aisi_316_L/data/M1/test_1.csv
Time(s),Strain(%),Stress(MPa),Temp(C),Log_SR(s-1)
0.0,0.0,0.0,30.0,5.0
2.0020020020020022e-09,0.0002002002002002002,39.14735047547548,30.0,5.0
4.0040040040040044e-09,0.0004004004004004004,78.29470095095095,30.0,5.0
6.006006006006007e-09,0.0006006006006006007,117.44205142642645,30.0,5.0
8.008008008008009e-09,0.0008008008008008008,156.5894019019019,30.0,5.0
1.001001001001001e-08,0.001001001001001001,195.73675237737737,30.0,5.0
1.2012012012012013e-08,0.0012012012012012014,234.8841028528529,30.0,5.0
1.4014014014014015e-08,0.0014014014014014015,274.0314533283283,30.0,5.0
1.6016016016016018e-08,0.0016016016016016017,313.1788038038038,30.0,5.0
1.8018018018018017e-08,0.0018018018018018018,338.7550900720774,30.0,5.0
2.002002002002002e-08,0.002002002002002002,340.43296545495275,30.0,5.0
2.2022022022022023e-08,0.0022022022022022024,342.04653737743536,30.0,5.0
2.4024024024024027e-08,0.0024024024024024027,343.60381188233754,30.0,5.0
2.6026026026026026e-08,0.0026026026026026027,345.111220586347,30.0,5.0
2.802802802802803e-08,0.002802802802802803,346.5740267711892,30.0,5.0
3.003003003003003e-08,0.003003003003003003,347.9966053407335,30.0,5.0
3.2032032032032035e-08,0.0032032032032032033,349.38264159389297,30.0,5.0
3.403403403403404e-08,0.0034034034034034037,350.73527594130945,30.0,5.0
3.6036036036036035e-08,0.0036036036036036037,352.05721156986584,30.0,5.0
3.803803803803804e-08,0.003803803803803804,353.35079606512573,30.0,5.0
4.004004004004004e-08,0.004004004004004004,354.6180843244675,30.0,5.0
4.2042042042042044e-08,0.004204204204204204,355.8608877666598,30.0,5.0
4.404404404404405e-08,0.004404404404404405,357.0808133304768,30.0,5.0
4.604604604604605e-08,0.004604604604604605,358.2792947470245,30.0,5.0
4.804804804804805e-08,0.0048048048048048055,359.4576178844633,30.0,5.0
5.005005005005005e-08,0.005005005005005005,360.61694148783454,30.0,5.0
5.205205205205205e-08,0.005205205205205205,361.758314300625,30.0,5.0
5.4054054054054056e-08,0.005405405405405406,362.882689313622,30.0,5.0
5.605605605605606e-08,0.005605605605605606,363.99093571116487,30.0,5.0
5.805805805805806e-08,0.0058058058058058064,365.0838489555051,30.0,5.0
6.006006006006006e-08,0.006006006006006006,366.1621593534017,30.0,5.0
6.206206206206207e-08,0.006206206206206206,367.2265393761648,30.0,5.0
6.406406406406407e-08,0.006406406406406407,368.2776099487396,30.0,5.0
6.606606606606607e-08,0.006606606606606607,369.315945880589,30.0,5.0
6.806806806806808e-08,0.0068068068068068074,370.3420805778404,30.0,5.0
7.007007007007007e-08,0.007007007007007007,371.356510150081,30.0,5.0
7.207207207207207e-08,0.007207207207207207,372.3596970045775,30.0,5.0
7.407407407407407e-08,0.007407407407407408,373.35207300430505,30.0,5.0
7.607607607607608e-08,0.007607607607607608,374.33404225303656,30.0,5.0
7.807807807807808e-08,0.0078078078078078084,375.30598356015633,30.0,5.0
8.008008008008008e-08,0.008008008008008008,376.2682526292646,30.0,5.0
8.20820820820821e-08,0.00820820820820821,377.22118400763634,30.0,5.0
8.408408408408409e-08,0.008408408408408409,378.16509282783846,30.0,5.0
8.608608608608608e-08,0.008608608608608608,379.1002763680707,30.0,5.0
8.80880880880881e-08,0.00880880880880881,380.0270154538606,30.0,5.0
9.009009009009008e-08,0.009009009009009009,380.94557572047034,30.0,5.0
9.20920920920921e-08,0.00920920920920921,381.85620875263464,30.0,5.0
9.40940940940941e-08,0.00940940940940941,382.75915311594787,30.0,5.0
9.60960960960961e-08,0.009609609609609611,383.6546352922818,30.0,5.0
9.809809809809811e-08,0.00980980980980981,384.5428705299684,30.0,5.0
1.001001001001001e-07,0.01001001001001001,385.42406361809265,30.0,5.0
1.0210210210210212e-07,0.010210210210210211,386.29840959304516,30.0,5.0
1.041041041041041e-07,0.01041041041041041,387.16609438447125,30.0,5.0
1.0610610610610612e-07,0.010610610610610612,388.027295406874,30.0,5.0
1.0810810810810811e-07,0.010810810810810811,388.882182102383,30.0,5.0
1.1011011011011011e-07,0.011011011011011011,389.73091643954456,30.0,5.0
1.1211211211211212e-07,0.011211211211211212,390.5736533724303,30.0,5.0
1.1411411411411412e-07,0.011411411411411412,391.4105412638712,30.0,5.0
1.1611611611611612e-07,0.011611611611611613,392.24172227619954,30.0,5.0
1.1811811811811813e-07,0.011811811811811812,393.06733273250705,30.0,5.0
1.2012012012012013e-07,0.012012012012012012,393.8875034511071,30.0,5.0
1.2212212212212212e-07,0.012212212212212213,394.7023600555986,30.0,5.0
1.2412412412412414e-07,0.012412412412412413,395.5120232626828,30.0,5.0
1.2612612612612615e-07,0.012612612612612614,396.31660914966034,30.0,5.0
1.2812812812812814e-07,0.012812812812812813,397.11622940334274,30.0,5.0
1.3013013013013013e-07,0.013013013013013013,397.9109915519384,30.0,5.0
1.3213213213213215e-07,0.013213213213213214,398.70099918132246,30.0,5.0
1.3413413413413414e-07,0.013413413413413414,399.48635213696,30.0,5.0
1.3613613613613615e-07,0.013613613613613615,400.2671467126363,30.0,5.0
1.3813813813813814e-07,0.013813813813813814,401.0434758270346,30.0,5.0
1.4014014014014013e-07,0.014014014014014014,401.8154291891105,30.0,5.0
1.4214214214214215e-07,0.014214214214214215,402.583093453121,30.0,5.0
1.4414414414414414e-07,0.014414414414414415,403.34655236409407,30.0,5.0
1.4614614614614616e-07,0.014614614614614616,404.1058868944502,30.0,5.0
1.4814814814814815e-07,0.014814814814814815,404.86117537242956,30.0,5.0
1.5015015015015016e-07,0.015015015015015015,405.6124936029185,30.0,5.0
1.5215215215215215e-07,0.015215215215215216,406.3599149812222,30.0,5.0
1.5415415415415417e-07,0.015415415415415416,407.1035106002796,30.0,5.0
1.5615615615615616e-07,0.015615615615615617,407.8433493517828,30.0,5.0
1.5815815815815817e-07,0.015815815815815818,408.57949802161636,30.0,5.0
1.6016016016016016e-07,0.016016016016016016,409.31202138000725,30.0,5.0
1.6216216216216218e-07,0.016216216216216217,410.04098226673835,30.0,5.0
1.641641641641642e-07,0.01641641641641642,410.76644167175465,30.0,5.0
1.6616616616616616e-07,0.016616616616616616,411.48845881146315,30.0,5.0
1.6816816816816818e-07,0.016816816816816817,412.2070912010072,30.0,5.0
1.701701701701702e-07,0.01701701701701702,412.9223947227711,30.0,5.0
1.7217217217217216e-07,0.017217217217217216,413.634423691355,30.0,5.0
1.7417417417417417e-07,0.017417417417417418,414.34323091523925,30.0,5.0
1.761761761761762e-07,0.01761761761761762,415.04886775534544,30.0,5.0
1.781781781781782e-07,0.01781781781781782,415.7513841806807,30.0,5.0
1.8018018018018017e-07,0.018018018018018018,416.4508288212438,30.0,5.0
1.8218218218218218e-07,0.01821821821821822,417.147249018356,30.0,5.0
1.841841841841842e-07,0.01841841841841842,417.8406908725682,30.0,5.0
1.861861861861862e-07,0.018618618618618618,418.53119928928754,30.0,5.0
1.881881881881882e-07,0.01881881881881882,419.2188180222542,30.0,5.0
1.901901901901902e-07,0.01901901901901902,419.90358971499114,30.0,5.0
1.921921921921922e-07,0.019219219219219222,420.5855559403438,30.0,5.0
1.941941941941942e-07,0.01941941941941942,421.26475723821324,30.0,5.0
1.9619619619619622e-07,0.01961961961961962,421.9412331515863,30.0,5.0
1.981981981981982e-07,0.019819819819819822,422.6150222609542,30.0,5.0
2.002002002002002e-07,0.02002002002002002,423.2861622172082,30.0,5.0
2.0220220220220221e-07,0.02022022022022022,423.9546897730932,30.0,5.0
2.0420420420420423e-07,0.020420420420420422,424.62064081329726,30.0,5.0
2.062062062062062e-07,0.02062062062062062,425.2840503832483,30.0,5.0
2.082082082082082e-07,0.02082082082082082,425.9449527166862,30.0,5.0
2.1021021021021023e-07,0.021021021021021023,426.6033812620716,30.0,5.0
2.1221221221221224e-07,0.021221221221221224,427.25936870789457,30.0,5.0
2.142142142142142e-07,0.02142142142142142,427.9129470069356,30.0,5.0
2.1621621621621622e-07,0.021621621621621623,428.56414739953317,30.0,5.0
2.1821821821821824e-07,0.021821821821821824,429.21300043590753,30.0,5.0
2.2022022022022023e-07,0.022022022022022022,429.85953599758705,30.0,5.0
2.2222222222222222e-07,0.022222222222222223,430.5037833179799,30.0,5.0
2.2422422422422423e-07,0.022422422422422424,431.14577100213506,30.0,5.0
2.2622622622622622e-07,0.022622622622622622,431.7855270457285,30.0,5.0
2.2822822822822824e-07,0.022822822822822823,432.4230788533144,30.0,5.0
2.3023023023023026e-07,0.023023023023023025,433.05845325587353,30.0,5.0
2.3223223223223225e-07,0.023223223223223226,433.6916765276936,30.0,5.0
2.3423423423423424e-07,0.023423423423423424,434.3227744026115,30.0,5.0
2.3623623623623625e-07,0.023623623623623625,434.9517720896471,30.0,5.0
2.3823823823823827e-07,0.023823823823823826,435.5786942880564,30.0,5.0
2.4024024024024026e-07,0.024024024024024024,436.20356520183014,30.0,5.0
2.422422422422423e-07,0.024224224224224225,436.82640855366327,30.0,5.0
2.4424424424424424e-07,0.024424424424424426,437.4472475984177,30.0,5.0
2.4624624624624625e-07,0.024624624624624624,438.0661051361015,30.0,5.0
2.4824824824824827e-07,0.024824824824824825,438.6830035243865,30.0,5.0
2.502502502502503e-07,0.025025025025025027,439.29796469068185,30.0,5.0
2.522522522522523e-07,0.025225225225225228,439.9110101437857,30.0,5.0
2.5425425425425427e-07,0.025425425425425426,440.5221609851302,30.0,5.0
2.562562562562563e-07,0.025625625625625627,441.1314379196397,30.0,5.0
2.582582582582583e-07,0.025825825825825828,441.73886126621585,30.0,5.0
2.6026026026026026e-07,0.026026026026026026,442.34445096786726,30.0,5.0
2.622622622622623e-07,0.026226226226226227,442.9482266014971,30.0,5.0
2.642642642642643e-07,0.02642642642642643,443.5502073873637,30.0,5.0
2.662662662662663e-07,0.02662662662662663,444.1504121982264,30.0,5.0
2.682682682682683e-07,0.026826826826826827,444.74885956818997,30.0,5.0
2.702702702702703e-07,0.02702702702702703,445.3455677012605,30.0,5.0
2.722722722722723e-07,0.02722722722722723,445.94055447962234,30.0,5.0
2.7427427427427427e-07,0.027427427427427428,446.5338374716489,30.0,5.0
2.762762762762763e-07,0.02762762762762763,447.12543393965706,30.0,5.0
2.782782782782783e-07,0.02782782782782783,447.7153608474149,30.0,5.0
2.8028028028028027e-07,0.028028028028028028,448.30363486741334,30.0,5.0
2.822822822822823e-07,0.02822822822822823,448.89027238790896,30.0,5.0
2.842842842842843e-07,0.02842842842842843,449.4752895197493,30.0,5.0
2.862862862862863e-07,0.02862862862862863,450.0587021029856,30.0,5.0
2.882882882882883e-07,0.02882882882882883,450.6405257132849,30.0,5.0
2.902902902902903e-07,0.02902902902902903,451.22077566814494,30.0,5.0
2.922922922922923e-07,0.029229229229229232,451.7994670329227,30.0,5.0
2.942942942942943e-07,0.02942942942942943,452.3766146266809,30.0,5.0
2.962962962962963e-07,0.02962962962962963,452.9522330278604,30.0,5.0
2.982982982982983e-07,0.029829829829829832,453.5263365797853,30.0,5.0
3.003003003003003e-07,0.03003003003003003,454.0989393960043,30.0,5.0
3.023023023023023e-07,0.03023023023023023,454.670055365478,30.0,5.0
3.043043043043043e-07,0.030430430430430432,455.23969815761416,30.0,5.0
3.063063063063063e-07,0.030630630630630633,455.8078812271582,30.0,5.0
3.0830830830830834e-07,0.03083083083083083,456.37461781894336,30.0,5.0
3.103103103103103e-07,0.031031031031031032,456.93992097250634,30.0,5.0
3.123123123123123e-07,0.031231231231231234,457.503803526571,30.0,5.0
3.1431431431431433e-07,0.031431431431431435,458.06627812340747,30.0,5.0
3.1631631631631635e-07,0.031631631631631636,458.62735721306854,30.0,5.0
3.183183183183183e-07,0.03183183183183183,459.18705305750905,30.0,5.0
3.2032032032032033e-07,0.03203203203203203,459.7453777345913,30.0,5.0
3.2232232232232234e-07,0.03223223223223223,460.30234314198105,30.0,5.0
3.2432432432432436e-07,0.032432432432432434,460.8579610009368,30.0,5.0
3.263263263263264e-07,0.032632632632632635,461.4122428599974,30.0,5.0
3.283283283283284e-07,0.03283283283283284,461.9652000985699,30.0,5.0
3.3033033033033036e-07,0.03303303303303304,462.51684393042103,30.0,5.0
3.323323323323323e-07,0.03323323323323323,463.0671854070773,30.0,5.0
3.3433433433433434e-07,0.033433433433433433,463.61623542113364,30.0,5.0
3.3633633633633635e-07,0.033633633633633635,464.16400470947633,30.0,5.0
3.3833833833833837e-07,0.033833833833833836,464.71050385642104,30.0,5.0
3.403403403403404e-07,0.03403403403403404,465.25574329677045,30.0,5.0
3.423423423423424e-07,0.03423423423423424,465.7997333187916,30.0,5.0
3.443443443443443e-07,0.03443443443443443,466.34248406711816,30.0,5.0
3.4634634634634633e-07,0.034634634634634634,466.8840055455781,30.0,5.0
3.4834834834834834e-07,0.034834834834834835,467.4243076199493,30.0,5.0
3.5035035035035036e-07,0.035035035035035036,467.96340002064727,30.0,5.0
3.523523523523524e-07,0.03523523523523524,468.50129234534324,30.0,5.0
3.543543543543544e-07,0.03543543543543544,469.03799406151893,30.0,5.0
3.563563563563564e-07,0.03563563563563564,469.5735145089572,30.0,5.0
3.583583583583583e-07,0.035835835835835834,470.1078629021713,30.0,5.0
3.6036036036036033e-07,0.036036036036036036,470.64104833277474,30.0,5.0
3.6236236236236235e-07,0.03623623623623624,471.1730797717939,30.0,5.0
3.6436436436436437e-07,0.03643643643643644,471.70396607192333,30.0,5.0
3.663663663663664e-07,0.03663663663663664,472.23371596972834,30.0,5.0
3.683683683683684e-07,0.03683683683683684,472.76233808779335,30.0,5.0
3.703703703703704e-07,0.03703703703703704,473.2898409368203,30.0,5.0
3.723723723723724e-07,0.037237237237237236,473.81623291767613,30.0,5.0
3.743743743743744e-07,0.03743743743743744,474.3415223233927,30.0,5.0
3.763763763763764e-07,0.03763763763763764,474.8657173411202,30.0,5.0
3.783783783783784e-07,0.03783783783783784,475.3888260540334,30.0,5.0
3.803803803803804e-07,0.03803803803803804,475.9108564431956,30.0,5.0
3.823823823823824e-07,0.03823823823823824,476.43181638937847,30.0,5.0
3.843843843843844e-07,0.038438438438438444,476.9517136748402,30.0,5.0
3.863863863863864e-07,0.03863863863863864,477.4705559850629,30.0,5.0
3.883883883883884e-07,0.03883883883883884,477.9883509104513,30.0,5.0
3.903903903903904e-07,0.03903903903903904,478.5051059479922,30.0,5.0
3.9239239239239244e-07,0.03923923923923924,479.0208285028769,30.0,5.0
3.9439439439439445e-07,0.03943943943943944,479.5355258900874,30.0,5.0
3.963963963963964e-07,0.039639639639639644,480.0492053359471,30.0,5.0
3.983983983983984e-07,0.03983983983983984,480.5618739796375,30.0,5.0
4.004004004004004e-07,0.04004004004004004,481.07353887468116,30.0,5.0
4.024024024024024e-07,0.04024024024024024,481.5842069903919,30.0,5.0
4.0440440440440443e-07,0.04044044044044044,482.0938852132944,30.0,5.0
4.0640640640640644e-07,0.04064064064064064,482.60258034851154,30.0,5.0
4.0840840840840846e-07,0.040840840840840845,483.11029912112264,30.0,5.0
4.104104104104105e-07,0.041041041041041046,483.61704817749296,30.0,5.0
4.124124124124124e-07,0.04124124124124124,484.1228340865732,30.0,5.0
4.144144144144144e-07,0.04144144144144144,484.62766334117293,30.0,5.0
4.164164164164164e-07,0.04164164164164164,485.1315423592061,30.0,5.0
4.1841841841841844e-07,0.041841841841841844,485.6344774849109,30.0,5.0
4.2042042042042045e-07,0.042042042042042045,486.1364749900432,30.0,5.0
4.2242242242242247e-07,0.042242242242242246,486.63754107504565,30.0,5.0
4.244244244244245e-07,0.04244244244244245,487.137681870193,30.0,5.0
4.264264264264264e-07,0.04264264264264264,487.6369034367123,30.0,5.0
4.284284284284284e-07,0.04284284284284284,488.1352117678812,30.0,5.0
4.3043043043043043e-07,0.043043043043043044,488.6326127901032,30.0,5.0
4.3243243243243244e-07,0.043243243243243246,489.1291123639619,30.0,5.0
4.3443443443443446e-07,0.04344344344344345,489.62471628525174,30.0,5.0
4.364364364364365e-07,0.04364364364364365,490.1194302859904,30.0,5.0
4.3843843843843844e-07,0.04384384384384384,490.61326003540916,30.0,5.0
4.4044044044044046e-07,0.044044044044044044,491.10621114092424,30.0,5.0
4.4244244244244247e-07,0.044244244244244245,491.59828914908786,30.0,5.0
4.4444444444444444e-07,0.044444444444444446,492.089499546522,30.0,5.0
4.4644644644644645e-07,0.04464464464464465,492.5798477608319,30.0,5.0
4.4844844844844847e-07,0.04484484484484485,493.0693391615031,30.0,5.0
4.504504504504505e-07,0.04504504504504505,493.5579790607794,30.0,5.0
4.5245245245245245e-07,0.045245245245245244,494.04577271452564,30.0,5.0
4.5445445445445446e-07,0.045445445445445445,494.53272532307216,30.0,5.0
4.564564564564565e-07,0.04564564564564565,495.0188420320431,30.0,5.0
4.584584584584585e-07,0.04584584584584585,495.5041279331696,30.0,5.0
4.604604604604605e-07,0.04604604604604605,495.9885880650868,30.0,5.0
4.6246246246246253e-07,0.04624624624624625,496.47222741411565,30.0,5.0
4.644644644644645e-07,0.04644644644644645,496.95505091503037,30.0,5.0
4.6646646646646646e-07,0.046646646646646646,497.4370634518103,30.0,5.0
4.6846846846846847e-07,0.04684684684684685,497.9182698583792,30.0,5.0
4.704704704704705e-07,0.04704704704704705,498.3986749193292,30.0,5.0
4.724724724724725e-07,0.04724724724724725,498.8782833706321,30.0,5.0
4.744744744744745e-07,0.04744744744744745,499.35709990033723,30.0,5.0
4.7647647647647654e-07,0.04764764764764765,499.83512914925615,30.0,5.0
4.784784784784786e-07,0.04784784784784785,500.31237571163507,30.0,5.0
4.804804804804805e-07,0.04804804804804805,500.788844135815,30.0,5.0
4.824824824824825e-07,0.04824824824824825,501.26453892487933,30.0,5.0
4.844844844844845e-07,0.04844844844844845,501.73946453729025,30.0,5.0
4.864864864864865e-07,0.04864864864864865,502.2136253875128,30.0,5.0
4.884884884884885e-07,0.04884884884884885,502.6870258466288,30.0,5.0
4.904904904904905e-07,0.049049049049049054,503.1596702429388,30.0,5.0
4.924924924924925e-07,0.04924924924924925,503.63156286255344,30.0,5.0
4.944944944944945e-07,0.04944944944944945,504.10270794997456,30.0,5.0
4.964964964964965e-07,0.04964964964964965,504.5731097086662,30.0,5.0
4.984984984984985e-07,0.04984984984984985,505.04277230161426,30.0,5.0
5.005005005005006e-07,0.05005005005005005,505.51169985187767,30.0,5.0
5.025025025025025e-07,0.050250250250250254,505.9798964431297,30.0,5.0
5.045045045045046e-07,0.050450450450450456,506.44736612018886,30.0,5.0
5.065065065065065e-07,0.05065065065065065,506.9141128895414,30.0,5.0
5.085085085085085e-07,0.05085085085085085,507.3801407198549,30.0,5.0
5.105105105105105e-07,0.05105105105105105,507.84545354248223,30.0,5.0
5.125125125125126e-07,0.051251251251251254,508.31005525195724,30.0,5.0
5.145145145145145e-07,0.051451451451451455,508.7739497064824,30.0,5.0
5.165165165165166e-07,0.051651651651651656,509.23714072840676,30.0,5.0
5.185185185185186e-07,0.05185185185185186,509.69963210469797,30.0,5.0
5.205205205205205e-07,0.05205205205205205,510.16142758740386,30.0,5.0
5.225225225225225e-07,0.05225225225225225,510.62253089410814,30.0,5.0
5.245245245245246e-07,0.052452452452452454,511.0829457083775,30.0,5.0
5.265265265265265e-07,0.052652652652652655,511.54267568020106,30.0,5.0
5.285285285285286e-07,0.05285285285285286,512.0017244264237,30.0,5.0
5.305305305305306e-07,0.05305305305305306,512.4600955311704,30.0,5.0
5.325325325325326e-07,0.05325325325325326,512.9177925462652,30.0,5.0
5.345345345345346e-07,0.05345345345345345,513.3748189916422,30.0,5.0
5.365365365365365e-07,0.053653653653653655,513.8311783557504,30.0,5.0
5.385385385385385e-07,0.053853853853853856,514.2868740959514,30.0,5.0
5.405405405405406e-07,0.05405405405405406,514.741909638911,30.0,5.0
5.425425425425425e-07,0.05425425425425426,515.1962883809845,30.0,5.0
5.445445445445446e-07,0.05445445445445446,515.6500136885954,30.0,5.0
5.465465465465466e-07,0.054654654654654654,516.1030888986085,30.0,5.0
5.485485485485485e-07,0.054854854854854855,516.5555173186957,30.0,5.0
5.505505505505506e-07,0.055055055055055056,517.0073022276985,30.0,5.0
5.525525525525526e-07,0.05525525525525526,517.4584468759816,30.0,5.0
5.545545545545545e-07,0.05545545545545546,517.9089544857837,30.0,5.0
5.565565565565566e-07,0.05565565565565566,518.3588282515608,30.0,5.0
5.585585585585586e-07,0.05585585585585586,518.8080713403243,30.0,5.0
5.605605605605605e-07,0.056056056056056056,519.2566868919756,30.0,5.0
5.625625625625626e-07,0.05625625625625626,519.7046780196326,30.0,5.0
5.645645645645646e-07,0.05645645645645646,520.152047809954,30.0,5.0
5.665665665665666e-07,0.05665665665665666,520.5987993234556,30.0,5.0
5.685685685685686e-07,0.05685685685685686,521.0449355948248,30.0,5.0
5.705705705705707e-07,0.05705705705705706,521.4904596332277,30.0,5.0
5.725725725725726e-07,0.05725725725725726,521.9353744226128,30.0,5.0
5.745745745745746e-07,0.05745745745745746,522.3796829220096,30.0,5.0
5.765765765765766e-07,0.05765765765765766,522.8233880658227,30.0,5.0
5.785785785785786e-07,0.05785785785785786,523.2664927641217,30.0,5.0
5.805805805805806e-07,0.05805805805805806,523.7089999029268,30.0,5.0
5.825825825825827e-07,0.05825825825825826,524.1509123444882,30.0,5.0
5.845845845845846e-07,0.058458458458458464,524.5922329275649,30.0,5.0
5.865865865865867e-07,0.058658658658658665,525.0329644676954,30.0,5.0
5.885885885885885e-07,0.05885885885885886,525.4731097574676,30.0,5.0
5.905905905905906e-07,0.05905905905905906,525.9126715667826,30.0,5.0
5.925925925925926e-07,0.05925925925925926,526.3516526431151,30.0,5.0
5.945945945945947e-07,0.05945945945945946,526.7900557117705,30.0,5.0
5.965965965965966e-07,0.059659659659659664,527.2278834761374,30.0,5.0
5.985985985985987e-07,0.059859859859859865,527.6651386179369,30.0,5.0
6.006006006006006e-07,0.06006006006006006,528.1018237974685,30.0,5.0
6.026026026026026e-07,0.06026026026026026,528.537941653851,30.0,5.0
6.046046046046046e-07,0.06046046046046046,528.9734948052621,30.0,5.0
6.066066066066066e-07,0.06066066066066066,529.4084858491726,30.0,5.0
6.086086086086086e-07,0.060860860860860864,529.842917362578,30.0,5.0
6.106106106106107e-07,0.061061061061061066,530.2767919022267,30.0,5.0
6.126126126126126e-07,0.06126126126126127,530.710112004845,30.0,5.0
6.146146146146146e-07,0.06146146146146146,531.1428801873587,30.0,5.0
6.166166166166167e-07,0.06166166166166166,531.575098947112,30.0,5.0
6.186186186186186e-07,0.061861861861861864,532.006770762082,30.0,5.0
6.206206206206206e-07,0.062062062062062065,532.4378980910919,30.0,5.0
6.226226226226227e-07,0.062262262262262266,532.8684833740197,30.0,5.0
6.246246246246246e-07,0.06246246246246247,533.2985290320053,30.0,5.0
6.266266266266267e-07,0.06266266266266267,533.728037467653,30.0,5.0
6.286286286286287e-07,0.06286286286286287,534.1570110652334,30.0,5.0
6.306306306306307e-07,0.06306306306306307,534.5854521908796,30.0,5.0
6.326326326326327e-07,0.06326326326326327,535.0133631927838,30.0,5.0
6.346346346346346e-07,0.06346346346346346,535.4407464013889,30.0,5.0
6.366366366366366e-07,0.06366366366366366,535.867604129578,30.0,5.0
6.386386386386386e-07,0.06386386386386386,536.2939386728624,30.0,5.0
6.406406406406407e-07,0.06406406406406406,536.7197523095648,30.0,5.0
6.426426426426426e-07,0.06426426426426426,537.1450473010024,30.0,5.0
6.446446446446447e-07,0.06446446446446447,537.5698258916658,30.0,5.0
6.466466466466467e-07,0.06466466466466467,537.9940903093961,30.0,5.0
6.486486486486487e-07,0.06486486486486487,538.41784276556,30.0,5.0
6.506506506506507e-07,0.06506506506506507,538.8410854552212,30.0,5.0
6.526526526526528e-07,0.06526526526526527,539.2638205573111,30.0,5.0
6.546546546546547e-07,0.06546546546546547,539.6860502347962,30.0,5.0
6.566566566566568e-07,0.06566566566566567,540.1077766348437,30.0,5.0
6.586586586586587e-07,0.06586586586586587,540.529001888984,30.0,5.0
6.606606606606607e-07,0.06606606606606608,540.9497281132728,30.0,5.0
6.626626626626627e-07,0.06626626626626626,541.3699574084491,30.0,5.0
6.646646646646646e-07,0.06646646646646646,541.7896918600924,30.0,5.0
6.666666666666667e-07,0.06666666666666667,542.2089335387772,30.0,5.0
6.686686686686687e-07,0.06686686686686687,542.6276845002258,30.0,5.0
6.706706706706706e-07,0.06706706706706707,543.0459467854589,30.0,5.0
6.726726726726727e-07,0.06726726726726727,543.4637224209446,30.0,5.0
6.746746746746747e-07,0.06746746746746747,543.8810134187441,30.0,5.0
6.766766766766767e-07,0.06766766766766767,544.2978217766581,30.0,5.0
6.786786786786787e-07,0.06786786786786787,544.7141494783684,30.0,5.0
6.806806806806808e-07,0.06806806806806807,545.1299984935798,30.0,5.0
6.826826826826827e-07,0.06826826826826828,545.5453707781589,30.0,5.0
6.846846846846848e-07,0.06846846846846848,545.9602682742723,30.0,5.0
6.866866866866868e-07,0.06866866866866868,546.3746929105209,30.0,5.0
6.886886886886886e-07,0.06886886886886887,546.7886466020758,30.0,5.0
6.906906906906907e-07,0.06906906906906907,547.2021312508092,30.0,5.0
6.926926926926927e-07,0.06926926926926927,547.6151487454252,30.0,5.0
6.946946946946947e-07,0.06946946946946947,548.0277009615891,30.0,5.0
6.966966966966967e-07,0.06966966966966967,548.4397897620547,30.0,5.0
6.986986986986988e-07,0.06986986986986987,548.85141699679,30.0,5.0
7.007007007007007e-07,0.07007007007007007,549.2625845031008,30.0,5.0
7.027027027027028e-07,0.07027027027027027,549.6732941057536,30.0,5.0
7.047047047047048e-07,0.07047047047047048,550.0835476170971,30.0,5.0
7.067067067067067e-07,0.07067067067067068,550.4933468371813,30.0,5.0
7.087087087087088e-07,0.07087087087087088,550.9026935538753,30.0,5.0
7.107107107107107e-07,0.07107107107107108,551.3115895429843,30.0,5.0
7.127127127127128e-07,0.07127127127127128,551.7200365683648,30.0,5.0
7.147147147147148e-07,0.07147147147147148,552.1280363820375,30.0,5.0
7.167167167167166e-07,0.07167167167167167,552.5355907243008,30.0,5.0
7.187187187187187e-07,0.07187187187187187,552.9427013238416,30.0,5.0
7.207207207207207e-07,0.07207207207207207,553.3493698978431,30.0,5.0
7.227227227227227e-07,0.07227227227227227,553.7555981520959,30.0,5.0
7.247247247247247e-07,0.07247247247247247,554.1613877811026,30.0,5.0
7.267267267267268e-07,0.07267267267267268,554.5667404681845,30.0,5.0
7.287287287287287e-07,0.07287287287287288,554.9716578855862,30.0,5.0
7.307307307307308e-07,0.07307307307307308,555.3761416945775,30.0,5.0
7.327327327327328e-07,0.07327327327327328,555.7801935455568,30.0,5.0
7.347347347347348e-07,0.07347347347347348,556.1838150781508,30.0,5.0
7.367367367367368e-07,0.07367367367367368,556.5870079213139,30.0,5.0
7.387387387387389e-07,0.07387387387387388,556.989773693427,30.0,5.0
7.407407407407408e-07,0.07407407407407408,557.3921140023942,30.0,5.0
7.427427427427427e-07,0.07427427427427427,557.7940304457388,30.0,5.0
7.447447447447448e-07,0.07447447447447447,558.1955246106984,30.0,5.0
7.467467467467467e-07,0.07467467467467467,558.5965980743179,30.0,5.0
7.487487487487488e-07,0.07487487487487487,558.9972524035428,30.0,5.0
7.507507507507508e-07,0.07507507507507508,559.3974891553106,30.0,5.0
7.527527527527528e-07,0.07527527527527528,559.7973098766405,30.0,5.0
7.547547547547548e-07,0.07547547547547548,560.1967161047238,30.0,5.0
7.567567567567568e-07,0.07567567567567568,560.5957093670118,30.0,5.0
7.587587587587588e-07,0.07587587587587588,560.9942911813024,30.0,5.0
7.607607607607608e-07,0.07607607607607608,561.3924630558279,30.0,5.0
7.627627627627629e-07,0.07627627627627628,561.7902264893388,30.0,5.0
7.647647647647648e-07,0.07647647647647648,562.187582971189,30.0,5.0
7.667667667667669e-07,0.07667667667667669,562.5845339814192,30.0,5.0
7.687687687687688e-07,0.07687687687687689,562.9810809908386,30.0,5.0
7.707707707707707e-07,0.07707707707707707,563.3772254611068,30.0,5.0
7.727727727727728e-07,0.07727727727727728,563.7729688448144,30.0,5.0
7.747747747747747e-07,0.07747747747747748,564.1683125855625,30.0,5.0
7.767767767767768e-07,0.07767767767767768,564.5632581180415,30.0,5.0
7.787787787787788e-07,0.07787787787787788,564.9578068681086,30.0,5.0
7.807807807807808e-07,0.07807807807807808,565.3519602528652,30.0,5.0
7.827827827827828e-07,0.07827827827827828,565.7457196807322,30.0,5.0
7.847847847847849e-07,0.07847847847847848,566.1390865515267,30.0,5.0
7.867867867867868e-07,0.07867867867867868,566.5320622565342,30.0,5.0
7.887887887887889e-07,0.07887887887887889,566.9246481785844,30.0,5.0
7.907907907907909e-07,0.07907907907907909,567.3168456921226,30.0,5.0
7.927927927927928e-07,0.07927927927927929,567.7086561632816,30.0,5.0
7.947947947947949e-07,0.07947947947947949,568.1000809499535,30.0,5.0
7.967967967967968e-07,0.07967967967967968,568.4911214018595,30.0,5.0
7.987987987987988e-07,0.07987987987987988,568.8817788606196,30.0,5.0
8.008008008008008e-07,0.08008008008008008,569.2720546598216,30.0,5.0
8.028028028028028e-07,0.08028028028028028,569.6619501250889,30.0,5.0
8.048048048048048e-07,0.08048048048048048,570.0514665741478,30.0,5.0
8.068068068068068e-07,0.08068068068068068,570.4406053168941,30.0,5.0
8.088088088088089e-07,0.08088088088088088,570.8293676554594,30.0,5.0
8.108108108108108e-07,0.08108108108108109,571.217754884275,30.0,5.0
8.128128128128129e-07,0.08128128128128129,571.6057682901378,30.0,5.0
8.148148148148149e-07,0.08148148148148149,571.9934091522731,30.0,5.0
8.168168168168169e-07,0.08168168168168169,572.3806787423978,30.0,5.0
8.188188188188189e-07,0.08188188188188189,572.7675783247829,30.0,5.0
8.20820820820821e-07,0.08208208208208209,573.154109156315,30.0,5.0
8.228228228228228e-07,0.08228228228228228,573.5402724865576,30.0,5.0
8.248248248248248e-07,0.08248248248248248,573.9260695578112,30.0,5.0
8.268268268268268e-07,0.08268268268268268,574.3115016051731,30.0,5.0
8.288288288288288e-07,0.08288288288288288,574.6965698565967,30.0,5.0
8.308308308308309e-07,0.08308308308308308,575.0812755329497,30.0,5.0
8.328328328328328e-07,0.08328328328328329,575.4656198480719,30.0,5.0
8.348348348348349e-07,0.08348348348348349,575.849604008833,30.0,5.0
8.368368368368369e-07,0.08368368368368369,576.2332292151885,30.0,5.0
8.388388388388389e-07,0.08388388388388389,576.6164966602364,30.0,5.0
8.408408408408409e-07,0.08408408408408409,576.9994075302718,30.0,5.0
8.428428428428429e-07,0.08428428428428429,577.3819630048431,30.0,5.0
8.448448448448449e-07,0.08448448448448449,577.7641642568049,30.0,5.0
8.468468468468469e-07,0.0846846846846847,578.1460124523727,30.0,5.0
8.48848848848849e-07,0.0848848848848849,578.5275087511753,30.0,5.0
8.508508508508508e-07,0.08508508508508508,578.9086543063089,30.0,5.0
8.528528528528528e-07,0.08528528528528528,579.289450264387,30.0,5.0
8.548548548548549e-07,0.08548548548548549,579.6698977655941,30.0,5.0
8.568568568568568e-07,0.08568568568568569,580.0499979437352,30.0,5.0
8.588588588588589e-07,0.08588588588588589,580.4297519262872,30.0,5.0
8.608608608608609e-07,0.08608608608608609,580.8091608344481,30.0,5.0
8.628628628628629e-07,0.08628628628628629,581.1882257831876,30.0,5.0
8.648648648648649e-07,0.08648648648648649,581.5669478812948,30.0,5.0
8.66866866866867e-07,0.08668668668668669,581.9453282314278,30.0,5.0
8.688688688688689e-07,0.0868868868868869,582.3233679301605,30.0,5.0
8.70870870870871e-07,0.0870870870870871,582.7010680680314,30.0,5.0
8.72872872872873e-07,0.0872872872872873,583.0784297295895,30.0,5.0
8.74874874874875e-07,0.0874874874874875,583.455453993442,30.0,5.0
8.768768768768769e-07,0.08768768768768768,583.8321419322988,30.0,5.0
8.788788788788788e-07,0.08788788788788789,584.2084946130194,30.0,5.0
8.808808808808809e-07,0.08808808808808809,584.5845130966583,30.0,5.0
8.828828828828829e-07,0.08828828828828829,584.960198438508,30.0,5.0
8.848848848848849e-07,0.08848848848848849,585.3355516881451,30.0,5.0
8.868868868868869e-07,0.08868868868868869,585.7105738894729,30.0,5.0
8.888888888888889e-07,0.08888888888888889,586.085266080766,30.0,5.0
8.908908908908909e-07,0.0890890890890891,586.4596292947118,30.0,5.0
8.928928928928929e-07,0.0892892892892893,586.833664558454,30.0,5.0
8.94894894894895e-07,0.0894894894894895,587.2073728936344,30.0,5.0
8.968968968968969e-07,0.0896896896896897,587.5807553164351,30.0,5.0
8.98898898898899e-07,0.0898898898898899,587.9538128376191,30.0,5.0
9.00900900900901e-07,0.0900900900900901,588.3265464625714,30.0,5.0
9.02902902902903e-07,0.0902902902902903,588.6989571913396,30.0,5.0
9.049049049049049e-07,0.09049049049049049,589.0710460186741,30.0,5.0
9.069069069069069e-07,0.09069069069069069,589.442813934068,30.0,5.0
9.089089089089089e-07,0.09089089089089089,589.8142619217956,30.0,5.0
9.109109109109109e-07,0.09109109109109109,590.1853909609521,30.0,5.0
9.12912912912913e-07,0.0912912912912913,590.556202025492,30.0,5.0
9.149149149149149e-07,0.0914914914914915,590.9266960842674,30.0,5.0
9.16916916916917e-07,0.0916916916916917,591.2968741010651,30.0,5.0
9.18918918918919e-07,0.0918918918918919,591.6667370346453,30.0,5.0
9.20920920920921e-07,0.0920920920920921,592.036285838778,30.0,5.0
9.22922922922923e-07,0.0922922922922923,592.4055214622794,30.0,5.0
9.249249249249251e-07,0.0924924924924925,592.774444849049,30.0,5.0
9.26926926926927e-07,0.0926926926926927,593.1430569381056,30.0,5.0
9.28928928928929e-07,0.0928928928928929,593.5113586636226,30.0,5.0
9.30930930930931e-07,0.09309309309309309,593.8793509549635,30.0,5.0
9.329329329329329e-07,0.09329329329329329,594.2470347367174,30.0,5.0
9.34934934934935e-07,0.09349349349349349,594.6144109287332,30.0,5.0
9.369369369369369e-07,0.0936936936936937,594.981480446154,30.0,5.0
9.389389389389389e-07,0.0938938938938939,595.3482441994518,30.0,5.0
9.40940940940941e-07,0.0940940940940941,595.7147030944602,30.0,5.0
9.429429429429429e-07,0.0942942942942943,596.0808580324091,30.0,5.0
9.44944944944945e-07,0.0944944944944945,596.4467099099567,30.0,5.0
9.46946946946947e-07,0.0946946946946947,596.8122596192228,30.0,5.0
9.48948948948949e-07,0.0948948948948949,597.1775080478216,30.0,5.0
9.50950950950951e-07,0.0950950950950951,597.5424560788933,30.0,5.0
9.529529529529531e-07,0.0952952952952953,597.9071045911365,30.0,5.0
9.549549549549551e-07,0.0954954954954955,598.2714544588396,30.0,5.0
9.569569569569571e-07,0.0956956956956957,598.6355065519122,30.0,5.0
9.589589589589589e-07,0.0958958958958959,598.999261735916,30.0,5.0
9.60960960960961e-07,0.0960960960960961,599.3627208720957,30.0,5.0
9.62962962962963e-07,0.0962962962962963,599.7258848174098,30.0,5.0
9.64964964964965e-07,0.0964964964964965,600.0887544245597,30.0,5.0
9.66966966966967e-07,0.0966966966966967,600.4513305420212,30.0,5.0
9.68968968968969e-07,0.0968968968968969,600.8136140140731,30.0,5.0
9.70970970970971e-07,0.0970970970970971,601.1756056808263,30.0,5.0
9.72972972972973e-07,0.0972972972972973,601.5373063782538,30.0,5.0
9.74974974974975e-07,0.0974974974974975,601.8987169382194,30.0,5.0
9.76976976976977e-07,0.0976976976976977,602.2598381885058,30.0,5.0
9.789789789789791e-07,0.0978978978978979,602.6206709528432,30.0,5.0
9.80980980980981e-07,0.09809809809809811,602.9812160509376,30.0,5.0
9.82982982982983e-07,0.09829829829829831,603.341474298498,30.0,5.0
9.84984984984985e-07,0.0984984984984985,603.7014465072649,30.0,5.0
9.86986986986987e-07,0.0986986986986987,604.0611334850369,30.0,5.0
9.88988988988989e-07,0.0988988988988989,604.4205360356981,30.0,5.0
9.90990990990991e-07,0.0990990990990991,604.7796549592449,30.0,5.0
9.92992992992993e-07,0.0992992992992993,605.1384910518124,30.0,5.0
9.94994994994995e-07,0.0994994994994995,605.4970451057013,30.0,5.0
9.96996996996997e-07,0.0996996996996997,605.8553179094037,30.0,5.0
9.98998998998999e-07,0.0998998998998999,606.2133102476286,30.0,5.0
1e-06,0.1,606.3922014863806,30.0,5.0