File: datasets/aisi_316_L/data/M1/train_0.csv
Time(s),Strain(%),Stress(MPa),Temp(C),Log_SR(s-1)
0.0,0.0,0.0,150.85861365567558,0.336176037620592
1.4756179879957868e-06,3.2e-06,0.60702145,150.85861365567558,0.336176037620592
1.2542752897964186e-05,2.7199999999999997e-05,5.1596823249999995,150.85861365567558,0.336176037620592
2.0658651831941014e-05,4.48e-05,8.4983003,150.85861365567558,0.336176037620592
2.5085505795928372e-05,5.4399999999999994e-05,10.319364649999999,150.85861365567558,0.336176037620592
2.9512359759915734e-05,6.4e-05,12.140429,150.85861365567558,0.336176037620592
4.021059017288519e-05,8.719999999999999e-05,16.541334512499997,150.85861365567558,0.336176037620592
4.6850871118866224e-05,0.00010159999999999999,19.272931037499998,150.85861365567558,0.336176037620592
5.312224756784832e-05,0.0001152,21.8527722,150.85861365567558,0.336176037620592
6.972294993280093e-05,0.0001512,28.681763512499998,150.85861365567558,0.336176037620592
7.74699443697788e-05,0.000168,31.868626125,150.85861365567558,0.336176037620592
8.92748882737451e-05,0.0001936,36.724797724999995,150.85861365567558,0.336176037620592
9.665297821372404e-05,0.0002096,39.759904975,150.85861365567558,0.336176037620592
9.849750069871876e-05,0.0002136,40.5186817875,150.85861365567558,0.336176037620592
0.00010476887714770086,0.0002272,43.098522949999996,150.85861365567558,0.336176037620592
0.0001114091580936819,0.0002416,45.830119475,150.85861365567558,0.336176037620592
0.00011583601205766926,0.0002512,47.651183825,150.85861365567558,0.336176037620592
0.00012063177051865556,0.00026159999999999996,49.624003537499995,150.85861365567558,0.336176037620592
0.00012616533797363977,0.0002736,51.900333974999995,150.85861365567558,0.336176037620592
0.00013501904590161446,0.00029279999999999996,55.542462674999996,150.85861365567558,0.336176037620592
0.00013797028187760606,0.0002992,56.756505575,150.85861365567558,0.336176037620592
0.00014313494483559133,0.0003104,58.88108065,150.85861365567558,0.336176037620592
0.00014793070329657763,0.0003208,60.8539003625,150.85861365567558,0.336176037620592
0.00015457098424255864,0.00033519999999999996,63.58549688749999,150.85861365567558,0.336176037620592
0.00015936674270354496,0.0003456,65.5583166,150.85861365567558,0.336176037620592
0.00016563811915252708,0.0003592,68.1381577625,150.85861365567558,0.336176037620592
0.00017818087205049123,0.00038639999999999996,73.29784008749999,150.85861365567558,0.336176037620592
0.0001848211529964723,0.0004008,76.02943661249999,150.85861365567558,0.336176037620592
0.0001874034844754649,0.00040639999999999996,77.09172414999999,150.85861365567558,0.336176037620592
0.00018924800696045965,0.0004104,77.8505009625,150.85861365567558,0.336176037620592
0.00019256814743345016,0.00041759999999999996,79.21629922499999,150.85861365567558,0.336176037620592
0.00019662609690043856,0.00042639999999999996,80.88560821249999,150.85861365567558,0.336176037620592
0.00020584870932541225,0.00044639999999999995,84.67949227499999,150.85861365567558,0.336176037620592
0.00021802255772637749,0.0004728,89.6874192375,150.85861365567558,0.336176037620592
0.00022060488920537012,0.0004784,90.74970677499999,150.85861365567558,0.336176037620592
0.00022576955216335536,0.0004896,92.87428184999999,150.85861365567558,0.336176037620592
0.00023905011405531747,0.0005184,98.3374749,150.85861365567558,0.336176037620592
0.00024126354103731111,0.0005231999999999999,99.24800707499999,150.85861365567558,0.336176037620592
0.0002467971084922953,0.0005352,101.5243375125,150.85861365567558,0.336176037620592
0.00024790382198329214,0.0005376,101.97960359999999,150.85861365567558,0.336176037620592
0.00025712643440826586,0.0005576,105.7734876625,150.85861365567558,0.336176037620592
0.0002578642434022637,0.0005591999999999999,106.07699838749998,150.85861365567558,0.336176037620592
0.0002608154793782553,0.0005656,107.2910412875,150.85861365567558,0.336176037620592
0.00027409604127021737,0.0005943999999999999,112.75423433749998,150.85861365567558,0.336176037620592
0.0002807363222161984,0.0006087999999999999,115.4858308625,150.85861365567558,0.336176037620592
0.0002873766031621795,0.0006232,118.2174273875,150.85861365567558,0.336176037620592
0.0003013949740481394,0.0006536,123.98413116249999,150.85861365567558,0.336176037620592
0.00031688896292209523,0.0006872,130.3578563875,150.85861365567558,0.336176037620592
0.0003301695248140573,0.000716,135.8210494375,150.85861365567558,0.336176037620592
0.00033717871025703726,0.0007312,138.704401325,150.85861365567558,0.336176037620592
0.00035304160362799195,0.0007656,145.2298819125,150.85861365567558,0.336176037620592
0.0003570995530949804,0.0007744,146.89919089999998,150.85861365567558,0.336176037620592
0.00036005078907097197,0.0007808,148.1132338,150.85861365567558,0.336176037620592
0.0003655843565259562,0.0007928,150.3895642375,150.85861365567558,0.336176037620592
0.00037591368244192666,0.0008152,154.6387143875,150.85861365567558,0.336176037620592
0.00038366067687890457,0.000832,157.82557699999998,150.85861365567558,0.336176037620592
0.00040727056468683716,0.0008832,167.5379202,150.85861365567558,0.336176037620592
0.00041427975012981713,0.0008983999999999999,170.4212720875,150.85861365567558,0.336176037620592
0.0004297737390037729,0.000932,176.7949973125,150.85861365567558,0.336176037620592
0.0004353073064587571,0.000944,179.07132775,150.85861365567558,0.336176037620592
0.00044342320539273393,0.0009616,182.409945725,150.85861365567558,0.336176037620592
0.0004482189638537202,0.000972,184.3827654375,150.85861365567558,0.336176037620592
0.00046961542467965916,0.0010184,193.18457646250002,150.85861365567558,0.336176037620592
0.0004876917450326075,0.0010576,200.62058922499997,150.85861365567558,0.336176037620592
0.0004924875034935938,0.001068,202.5934089375,150.85861365567558,0.336176037620592
0.0004965454529605823,0.0010768,204.26271792499998,150.85861365567558,0.336176037620592
0.0005028168294095644,0.0010904,206.8425590875,150.85861365567558,0.336176037620592
0.0005238443857385043,0.0011359999999999999,215.49261474999997,150.85861365567558,0.336176037620592
0.000525688908223499,0.00114,216.2513915625,150.85861365567558,0.336176037620592
0.0005389694701154611,0.0011688,221.7145846125,150.85861365567558,0.336176037620592
0.0005400761836064578,0.0011711999999999998,222.16985069999998,150.85861365567558,0.336176037620592
0.0005548323634864158,0.0012032,228.2400652,150.85861365567558,0.336176037620592
0.0005581525039594063,0.0012104,229.6058634625,150.85861365567558,0.336176037620592
0.0005655305938993853,0.0012263999999999999,230.1934814857446,150.85861365567558,0.336176037620592
0.0005765977288093537,0.0012504,230.35758117602742,150.85861365567558,0.336176037620592
0.0005843447232463316,0.0012672,230.47172081796808,150.85861365567558,0.336176037620592
0.0005876648637193221,0.0012744,230.52045697759166,150.85861365567558,0.336176037620592
0.0005946740491623021,0.0012896,230.622993182759,150.85861365567558,0.336176037620592
0.0006097991335392588,0.0013223999999999998,230.84266320585857,150.85861365567558,0.336176037620592
0.0006182839369702345,0.0013407999999999998,230.96496209786986,150.85861365567558,0.336176037620592
0.0006263998359042114,0.0013583999999999998,231.0813326144337,150.85861365567558,0.336176037620592
0.0006382047798081778,0.001384,231.24955456873624,150.85861365567558,0.336176037620592
0.0006418938247781672,0.001392,231.30187448307257,150.85861365567558,0.336176037620592
0.0006485341057241483,0.0014064,231.3957557655381,150.85861365567558,0.336176037620592
0.0006548054821731304,0.00142,231.48407778790386,150.85861365567558,0.336176037620592
0.000671037280041084,0.0014552,231.71115748335558,150.85861365567558,0.336176037620592
0.0006769397519930671,0.001468,231.79319947538562,150.85861365567558,0.336176037620592
0.0006872690779090377,0.0014904,231.93610479013446,150.85861365567558,0.336176037620592
0.0007009185442979986,0.0015199999999999999,232.12366571524592,150.85861365567558,0.336176037620592
0.0007060832072559839,0.0015312,232.19426255969606,150.85861365567558,0.336176037620592
0.0007116167747109682,0.0015432,232.26967892547304,150.85861365567558,0.336176037620592
0.0007178881511599502,0.0015568,232.35487486653986,150.85861365567558,0.336176037620592
0.0007260040500939271,0.0015743999999999999,232.464698799845,150.85861365567558,0.336176037620592
0.0007374400895008943,0.0015991999999999998,232.6186414736125,150.85861365567558,0.336176037620592
0.0007396535164828881,0.001604,232.64832898853,150.85861365567558,0.336176037620592
0.0007422358479618807,0.0016095999999999999,232.68292066722358,150.85861365567558,0.336176037620592
0.0007455559884348712,0.0016167999999999998,232.72732679372632,150.85861365567558,0.336176037620592
0.0007518273648838533,0.0016304,232.81099517623161,150.85861365567558,0.336176037620592
0.0007573609323388375,0.0016424,232.8845944422202,150.85861365567558,0.336176037620592
0.0007772817751767807,0.0016856,233.14783279620542,150.85861365567558,0.336176037620592
0.0007861354831047554,0.0017048,233.26398164835803,150.85861365567558,0.336176037620592
0.0007979404270087217,0.0017304,233.418056286142,150.85861365567558,0.336176037620592
0.0008079008484276932,0.0017519999999999999,233.5473665170206,150.85861365567558,0.336176037620592
0.0008285595002596343,0.0017967999999999999,233.81360006173477,150.85861365567558,0.336176037620592
0.0008340930677146185,0.0018088,233.88447141728847,150.85861365567558,0.336176037620592
0.0008540139105525616,0.001852,234.1381038993154,150.85861365567558,0.336176037620592
0.00085807186001955,0.0018608,234.18948573162643,150.85861365567558,0.336176037620592
0.000864343236468532,0.0018743999999999998,234.26870800927767,150.85861365567558,0.336176037620592
0.0008776237983604942,0.0019031999999999999,234.43573660958768,150.85861365567558,0.336176037620592
0.0008805750343364858,0.0019096,234.47271987176455,150.85861365567558,0.336176037620592
0.0008912732647494551,0.0019328,234.6063808739574,150.85861365567558,0.336176037620592
0.0008957001187134425,0.0019424,234.66150567917973,150.85861365567558,0.336176037620592
0.0009034471131504204,0.0019592,234.75771909669177,150.85861365567558,0.336176037620592
0.0009056605401324141,0.001964,234.7851494766052,150.85861365567558,0.336176037620592
0.0009089806806054046,0.0019711999999999998,234.82624607472945,150.85861365567558,0.336176037620592
0.0009152520570543868,0.0019848,234.90371360727028,150.85861365567558,0.336176037620592
0.0009229990514913646,0.0020016,234.99912357285055,150.85861365567558,0.336176037620592
0.0009311149504253415,0.0020192,235.09874249932403,150.85861365567558,0.336176037620592
0.0009348039953953308,0.0020272,235.14391182479662,150.85861365567558,0.336176037620592
0.0009392308493593183,0.0020368,235.19802335442145,150.85861365567558,0.336176037620592
0.0009447644168143024,0.0020488,235.2655230954382,150.85861365567558,0.336176037620592
0.0009510357932632845,0.0020624,235.3418366852578,150.85861365567558,0.336176037620592
0.0009569382652152676,0.0020751999999999997,235.41348215432808,150.85861365567558,0.336176037620592
0.0009628407371672509,0.002088,235.48495548237477,150.85861365567558,0.336176037620592
0.0009702188271072298,0.002104,235.57405729906026,150.85861365567558,0.336176037620592
0.0009746456810712171,0.0021135999999999998,235.62739155445752,150.85861365567558,0.336176037620592
0.0009768591080532108,0.0021184,235.65402324785651,150.85861365567558,0.336176037620592
0.0009864506249751834,0.0021392,235.7691563691388,150.85861365567558,0.336176037620592
0.0009927220014241654,0.0021528,235.84419973685868,150.85861365567558,0.336176037620592
0.0010015757093521402,0.002172,235.94982931674025,150.85861365567558,0.336176037620592
0.001010060512783116,0.0021904,236.05071647367927,150.85861365567558,0.336176037620592
0.0010229721701780791,0.0022183999999999997,236.20360854356437,150.85861365567558,0.336176037620592
0.0010329325915970507,0.00224,236.32104019054597,150.85861365567558,0.336176037620592
0.0010458442489920138,0.002268,236.4726111929267,150.85861365567558,0.336176037620592
0.001052484529937995,0.0022824,236.55027771403556,150.85861365567558,0.336176037620592
0.001058755906386977,0.002296,236.62345414102768,150.85861365567558,0.336176037620592
0.0010687163278059486,0.0023176,236.73932903152283,150.85861365567558,0.336176037620592
0.0010764633222429265,0.0023344,236.82916300500935,150.85861365567558,0.336176037620592
0.0010908505976258854,0.0023656,236.99533141338338,150.85861365567558,0.336176037620592
0.0011056067775058432,0.0023975999999999997,237.16487505693294,150.85861365567558,0.336176037620592
0.0011089269179788337,0.0024048,237.20290048723172,150.85861365567558,0.336176037620592
0.0011140915809368188,0.0024159999999999997,237.26196302197764,150.85861365567558,0.336176037620592
0.0011188873393978053,0.0024264,237.31671126217955,150.85861365567558,0.336176037620592
0.0011258965248407853,0.0024416,237.39656358426768,150.85861365567558,0.336176037620592
0.0011292166653137756,0.0024487999999999997,237.43432067935638,150.85861365567558,0.336176037620592
0.001135119137265759,0.0024616,237.5013376755251,150.85861365567558,0.336176037620592
0.0011424972272057379,0.0024776,237.58491810860454,150.85861365567558,0.336176037620592
0.0011502442216427158,0.0024944,237.67245132652187,150.85861365567558,0.336176037620592
0.0011590979295706906,0.0025136,237.77220824427832,150.85861365567558,0.336176037620592
0.0011749608229416452,0.002548,237.95019935209075,150.85861365567558,0.336176037620592
0.0011779120589176368,0.0025544,237.98321032175215,150.85861365567558,0.336176037620592
0.0011860279578516137,0.002572,238.07382458436453,150.85861365567558,0.336176037620592
0.001195988379270585,0.0025935999999999997,238.1847031596938,150.85861365567558,0.336176037620592
0.0012007841377315715,0.002604,238.23796064851754,150.85861365567558,0.336176037620592
0.0012022597557195672,0.0026072,238.25433087076257,150.85861365567558,0.336176037620592
0.001211113463647542,0.0026264,238.35238815315537,150.85861365567558,0.336176037620592
0.0012162781266055272,0.0026376,238.40945913028932,150.85861365567558,0.336176037620592
0.001231403210982484,0.0026704,238.57605436970843,150.85861365567558,0.336176037620592
0.001232509924473481,0.0026728,238.58821284154726,150.85861365567558,0.336176037620592
0.0012398880144134598,0.0026888,238.66916078385134,150.85861365567558,0.336176037620592
0.0012505862448264292,0.002712,238.7862024116804,150.85861365567558,0.336176037620592
0.0012535374808024208,0.0027183999999999997,238.818420956403,150.85861365567558,0.336176037620592
0.0012583332392634072,0.0027288,238.87071306910823,150.85861365567558,0.336176037620592
0.0012760406551193568,0.0027672,239.06312199668514,150.85861365567558,0.336176037620592
0.0012775162731073523,0.0027703999999999997,239.0791089194171,150.85861365567558,0.336176037620592
0.001280836413580343,0.0027776,239.1150531877365,150.85861365567558,0.336176037620592
0.0012837876495563345,0.002784,239.14697315407912,150.85861365567558,0.336176037620592
0.0012882145035203218,0.0027936,239.19479949752443,150.85861365567558,0.336176037620592
0.0012911657394963135,0.0028,239.2266481218608,150.85861365567558,0.336176037620592
0.0012930102619813082,0.002804,239.24653909557202,150.85861365567558,0.336176037620592
0.0012952236889633016,0.0028087999999999998,239.2703936624883,150.85861365567558,0.336176037620592
0.0012989127339332913,0.0028168,239.31011597434357,150.85861365567558,0.336176037620592
0.0013107176778372575,0.0028423999999999997,239.43693271969002,150.85861365567558,0.336176037620592
0.0013133000093162501,0.002848,239.46461441449418,150.85861365567558,0.336176037620592
0.0013199402902622313,0.0028623999999999998,239.53569861711733,150.85861365567558,0.336176037620592
0.0013239982397292196,0.0028712,239.57907031095203,150.85861365567558,0.336176037620592
0.0013387544196091774,0.0029032,239.73635042217154,150.85861365567558,0.336176037620592
0.0013476081275371522,0.0029224,239.8303939902877,150.85861365567558,0.336176037620592
0.0013520349815011395,0.0029319999999999997,239.8773253899999,150.85861365567558,0.336176037620592
0.001369742397357089,0.0029703999999999998,240.06445478689358,150.85861365567558,0.336176037620592
0.0013730625378300795,0.0029776,240.09943626700226,150.85861365567558,0.336176037620592
0.0013745381558180755,0.0029808,240.11497300083423,150.85861365567558,0.336176037620592
0.001384129672740048,0.0030015999999999997,240.2158036785253,150.85861365567558,0.336176037620592
0.0013859741952250426,0.0030055999999999998,240.23516291365277,150.85861365567558,0.336176037620592
0.0013892943356980333,0.0030128,240.26998423483758,150.85861365567558,0.336176037620592
0.0013926144761710235,0.0030199999999999997,240.3047731168199,150.85861365567558,0.336176037620592
0.0014029438020869943,0.0030424,240.41279891059833,150.85861365567558,0.336176037620592
0.0014095840830329752,0.0030567999999999997,240.4820803004054,150.85861365567558,0.336176037620592
0.0014173310774699532,0.0030735999999999997,240.5627479198821,150.85861365567558,0.336176037620592
0.0014224957404279385,0.0030848,240.61643082069475,150.85861365567558,0.336176037620592
0.0014302427348649163,0.0031016,240.69681286621048,150.85861365567558,0.336176037620592
0.0014335628753379067,0.0031087999999999997,240.73121031376098,150.85861365567558,0.336176037620592
0.0014490568642118627,0.0031424,240.8913227216702,150.85861365567558,0.336176037620592
0.0014538526226728489,0.0031528,240.9407458271081,150.85861365567558,0.336176037620592
0.0014641819485888194,0.0031752,241.04698015827256,150.85861365567558,0.336176037620592
0.0014793070329657762,0.003208,241.20201174247993,150.85861365567558,0.336176037620592
0.001480782650953772,0.0032112,241.21710360136808,150.85861365567558,0.336176037620592
0.0014896363588817467,0.0032304,241.30753189066385,150.85861365567558,0.336176037620592
0.0015032858252707077,0.00326,241.44653258130253,150.85861365567558,0.336176037620592
0.0015121395331986825,0.0032792,241.53643207927541,150.85861365567558,0.336176037620592
0.0015206243366296583,0.0032976,241.6223933296219,150.85861365567558,0.336176037620592
0.0015246822860966467,0.0033063999999999997,241.6634390883615,150.85861365567558,0.336176037620592
0.0015316914715396265,0.0033215999999999996,241.73423609910208,150.85861365567558,0.336176037620592
0.0015375939434916098,0.0033344,241.7937566886267,150.85861365567558,0.336176037620592
0.0015508745053835718,0.0033632,241.92735317129487,150.85861365567558,0.336176037620592
0.0015612038312995424,0.0033856,242.03095332373266,150.85861365567558,0.336176037620592
0.001563786162778535,0.0033912,242.05681155018578,150.85861365567558,0.336176037620592
0.0015645239717725328,0.0033927999999999996,242.06419655544624,150.85861365567558,0.336176037620592
0.0015781734381614938,0.0034224,242.20057511424946,150.85861365567558,0.336176037620592
0.0015811246741374854,0.0034287999999999996,242.2300017977291,150.85861365567558,0.336176037620592
0.001590347286562459,0.0034487999999999997,242.3218224201969,150.85861365567558,0.336176037620592
0.0015932985225384508,0.0034552,242.35116112949268,150.85861365567558,0.336176037620592
0.0015966186630114413,0.0034624,242.38414185587283,150.85861365567558,0.336176037620592
0.0016076857979214097,0.0034863999999999997,242.49388494593663,150.85861365567558,0.336176037620592
0.001613588269873393,0.0034992,242.55229410510623,150.85861365567558,0.336176037620592
0.0016279755452563518,0.0035304,242.69431842858774,150.85861365567558,0.336176037620592
0.0016346158262023327,0.0035448,242.7597029358068,150.85861365567558,0.336176037620592
0.001638673775669321,0.0035535999999999996,242.7996091428276,150.85861365567558,0.336176037620592
0.0016423628206393107,0.0035616,242.83585408109073,150.85861365567558,0.336176037620592
0.0016497409105792895,0.0035776,242.90824884518457,150.85861365567558,0.336176037620592
0.0016648659949562463,0.0036103999999999997,243.05626455614492,150.85861365567558,0.336176037620592
0.0016703995624112306,0.0036224,243.110285496228,150.85861365567558,0.336176037620592
0.001679622174836204,0.0036423999999999996,243.20016555879837,150.85861365567558,0.336176037620592
0.0016884758827641789,0.0036615999999999997,243.28626951436416,150.85861365567558,0.336176037620592
0.0016940094502191632,0.0036736,243.33999507897266,150.85861365567558,0.336176037620592
0.0017072900121111252,0.0037024,243.4686579485599,150.85861365567558,0.336176037620592
0.0017187260515180926,0.0037272,243.57913851718357,150.85861365567558,0.336176037620592
0.0017327444224040525,0.0037576,243.7141759752768,150.85861365567558,0.336176037620592
0.0017419670348290262,0.0037776,243.80278411274662,150.85861365567558,0.336176037620592
0.001751558551750999,0.0037984,243.89474271160864,150.85861365567558,0.336176037620592
0.0017552475967209883,0.0038063999999999997,243.93005908428546,150.85861365567558,0.336176037620592
0.0017604122596789737,0.0038176,243.97945341243633,150.85861365567558,0.336176037620592
0.0017666836361279557,0.0038312,244.0393563258221,150.85861365567558,0.336176037620592
0.0017740617260679347,0.0038472,244.1097242709128,150.85861365567558,0.336176037620592
0.0017807020070139156,0.0038615999999999998,244.17295789701535,150.85861365567558,0.336176037620592
0.0017821776250019114,0.0038648,244.1869973175551,150.85861365567558,0.336176037620592
0.0017895557149418904,0.0038808,244.25712653231227,150.85861365567558,0.336176037620592
0.0017906624284328872,0.0038832,244.26763618082236,150.85861365567558,0.336176037620592
0.0017928758554148808,0.003888,244.28864788124827,150.85861365567558,0.336176037620592
0.0017980405183728662,0.0038992,244.33763587875163,150.85861365567558,0.336176037620592
0.0018002539453548599,0.003904,244.35861393211272,150.85861365567558,0.336176037620592
0.0018227571196717958,0.0039528,244.57132290721512,150.85861365567558,0.336176037620592
0.001826815069138784,0.0039616,244.6095710193254,150.85861365567558,0.336176037620592
0.0018364065860607564,0.0039824,244.6998441706891,150.85861365567558,0.336176037620592
0.0018441535804977344,0.0039992,244.7726229342273,150.85861365567558,0.336176037620592
0.0019773546703514256,0.004288057611522305,246.00590263244882,150.85861365567558,0.336176037620592
0.0022518745200885894,0.004883376675335067,248.44975595579137,150.85861365567558,0.336176037620592
0.0022695854781361485,0.004921784356871375,248.60331013840883,150.85861365567558,0.336176037620592
0.002349284789350164,0.005094618923784757,249.28860107594525,150.85861365567558,0.336176037620592
0.002402417663492841,0.005209841968393679,249.7404306950505,150.85861365567558,0.336176037620592
0.0026238046390873273,0.005689937987597519,251.58256661414038,150.85861365567558,0.336176037620592
0.0026857929922537837,0.005824364872974595,252.08736633180672,150.85861365567558,0.336176037620592
0.0031197114644189784,0.006765353070614123,255.50171512065992,150.85861365567558,0.336176037620592
0.0033676648770848035,0.007303060612122424,257.3693766774939,150.85861365567558,0.336176037620592
0.003491641583417716,0.007571914382876575,258.28302974781315,150.85861365567558,0.336176037620592
0.0036864621219408647,0.007994398879775955,259.6936091627977,150.85861365567558,0.336176037620592
0.003987548408749366,0.008647329465893179,261.81768668437957,150.85861365567558,0.336176037620592
0.004377189485795664,0.009492298459691939,264.47578607199654,150.85861365567558,0.336176037620592
0.004465744276033459,0.009684336867373475,265.0668318142946,150.85861365567558,0.336176037620592
0.004704842209675505,0.010202840568113623,266.6402541587757,150.85861365567558,0.336176037620592
0.004890807269174873,0.010606121224244848,267.8425594851212,150.85861365567558,0.336176037620592
0.005298159304268729,0.011489497899579915,270.4155582351784,150.85861365567558,0.336176037620592
0.005492979842791877,0.011911982396479295,271.6187337094462,150.85861365567558,0.336176037620592
0.005608101070101011,0.012161632326465293,272.3218786574972,150.85861365567558,0.336176037620592
0.005918042835933292,0.01283376675335067,274.1875253096925,150.85861365567558,0.336176037620592
0.006440516098336282,0.013966793358671735,277.24839242288954,150.85861365567558,0.336176037620592
0.006679614031978328,0.014485297059411883,278.61665882988876,150.85861365567558,0.336176037620592
0.00698955579781061,0.01515743148629726,280.3622338994311,150.85861365567558,0.336176037620592
0.007104677025119743,0.015407081416283257,281.0028672609351,150.85861365567558,0.336176037620592
0.007281786605595333,0.01579115823164633,281.980607762488,150.85861365567558,0.336176037620592
0.007467751665094702,0.01619443888777756,282.99730510880033,150.85861365567558,0.336176037620592
0.007574017413380055,0.0164248849769954,283.5738410281558,150.85861365567558,0.336176037620592
0.007945947532378792,0.01723144628925785,285.56733159945196,150.85861365567558,0.336176037620592
0.008052213280664147,0.017461892378475695,286.1301721741237,150.85861365567558,0.336176037620592
0.008096490675783044,0.01755791158231646,286.3638332381132,150.85861365567558,0.336176037620592
0.008592397501114695,0.018633326665333065,288.94767396668914,150.85861365567558,0.336176037620592
0.008937761183042094,0.01938227645529106,290.7128706451027,150.85861365567558,0.336176037620592
0.009132581721565242,0.01980476095219044,291.6968819579101,150.85861365567558,0.336176037620592
0.009291980343993273,0.020150430086017204,292.49590680989564,150.85861365567558,0.336176037620592
0.009442523487397525,0.020476895379075814,293.2456469135201,150.85861365567558,0.336176037620592
0.00969047690006335,0.021014602920584116,294.4704293884157,150.85861365567558,0.336176037620592
0.009787887169324924,0.021225845169033808,294.9482423677759,150.85861365567558,0.336176037620592
0.01000927414491941,0.021705941188237647,296.0273369681115,150.85861365567558,0.336176037620592
0.010221805641490118,0.022166833366673334,297.05454375645866,150.85861365567558,0.336176037620592
0.010283793994656575,0.02230126025205041,297.352572311342,150.85861365567558,0.336176037620592
0.010354637826846811,0.02245489097819564,297.6923198204611,150.85861365567558,0.336176037620592
0.010823978215107123,0.023472694538907782,299.9206771396772,150.85861365567558,0.336176037620592
0.010903677526321138,0.023645529105821166,300.2953030062607,150.85861365567558,0.336176037620592
0.011063076148749167,0.02399119823964793,301.0413662103801,150.85861365567558,0.336176037620592
0.011080787106796728,0.024029605921184236,301.12400252517915,150.85861365567558,0.336176037620592
0.011373017914581451,0.024663332666533307,302.48015103276066,150.85861365567558,0.336176037620592
0.011452717225795465,0.02483616723344669,302.84764233881896,150.85861365567558,0.336176037620592
0.011638682285294836,0.025239447889577916,303.701265093279,150.85861365567558,0.336176037620592
0.011771514470651527,0.02552750550110022,304.3077420307352,150.85861365567558,0.336176037620592
0.011842358302841763,0.02568113622724545,304.6301047924988,150.85861365567558,0.336176037620592
0.011948624051127116,0.025911582316463292,305.11224233040997,150.85861365567558,0.336176037620592
0.012161155547697823,0.02637247449489898,306.07152957607235,150.85861365567558,0.336176037620592
0.01255079662474412,0.02721744348869774,307.81341034380563,150.85861365567558,0.336176037620592
0.012692484289124593,0.027524704940988198,308.44157587182616,150.85861365567558,0.336176037620592
0.012860738390576403,0.02788957791558312,309.18398145660206,150.85861365567558,0.336176037620592
0.013117547282266008,0.028446489297859572,310.3098650361886,150.85861365567558,0.336176037620592
0.013170680156408683,0.028561712342468494,310.541729528205,150.85861365567558,0.336176037620592
0.01323266850957514,0.028696139227845568,310.81177754062503,150.85861365567558,0.336176037620592
0.013524899317359864,0.02932986597319464,312.0782745709443,150.85861365567558,0.336176037620592
0.013719719855883012,0.02975235047009402,312.9166816586782,150.85861365567558,0.336176037620592
0.013870262999287262,0.03007881576315263,313.56136548486745,150.85861365567558,0.336176037620592
0.01390568491538238,0.030155631126225244,313.7126585186076,150.85861365567558,0.336176037620592
0.01393225135245372,0.030213242648529707,313.8260296783734,150.85861365567558,0.336176037620592
0.014242193118286001,0.030885377075415082,315.14252386344276,150.85861365567558,0.336176037620592
0.014516712968023164,0.03148069613922785,316.29925863562465,150.85861365567558,0.336176037620592
0.014684967069474973,0.03184556911382276,317.004009455606,150.85861365567558,0.336176037620592
0.014932920482140802,0.03238327665533107,318.0368765303266,150.85861365567558,0.336176037620592
0.015030330751402376,0.03259451890378076,318.44081308604365,150.85861365567558,0.336176037620592
0.015101174583592612,0.03274814962992599,318.7339441360393,150.85861365567558,0.336176037620592
0.015172018415782848,0.03290178035607122,319.0265393617193,150.85861365567558,0.336176037620592
0.01525171772699686,0.033074614922984594,319.3550728378753,150.85861365567558,0.336176037620592
0.015428827307472453,0.03345869173834767,320.0827595571443,150.85861365567558,0.336176037620592
0.015508526618686463,0.03363152630526105,320.40915499384755,150.85861365567558,0.336176037620592
0.01564135880404316,0.03391958391678336,320.9516974120493,150.85861365567558,0.336176037620592
0.015738769073304733,0.034130826165233046,321.3484204946382,150.85861365567558,0.336176037620592
0.015853890300613866,0.03438047609521905,321.816042569172,150.85861365567558,0.336176037620592
0.016199253982541264,0.035129425885177035,323.2110269875523,150.85861365567558,0.336176037620592
0.016323230688874178,0.03539827965593119,323.70895516000763,150.85861365567558,0.336176037620592
0.01640293000008819,0.03557111422284456,324.0282731688036,150.85861365567558,0.336176037620592
0.016686305328849134,0.03618563712742548,325.1587580906654,150.85861365567558,0.336176037620592
0.01675714916103937,0.03633926785357071,325.4402063487555,150.85861365567558,0.336176037620592
0.016889981346396066,0.03662732546509302,325.9666742300645,150.85861365567558,0.336176037620592
0.01705823544784788,0.03699219843968794,326.6312212132458,150.85861365567558,0.336176037620592
0.017164501196133226,0.03722264452890578,327.0496182699285,150.85861365567558,0.336176037620592
0.01727962242344236,0.037472294458891775,327.50174338198974,150.85861365567558,0.336176037620592
0.01734161077660882,0.03760672134426886,327.7447087201874,150.85861365567558,0.336176037620592
0.01739474365075149,0.03772194438887777,327.9526952613853,150.85861365567558,0.336176037620592
0.01744787652489417,0.037837167433486696,328.1604341817006,150.85861365567558,0.336176037620592
0.017598419668298424,0.03816363272654531,328.74769220496563,150.85861365567558,0.336176037620592
0.017713540895607557,0.03841328265653131,329.1954508693246,150.85861365567558,0.336176037620592
0.017926072392178263,0.038874174834966996,330.0191118958896,150.85861365567558,0.336176037620592
0.01807661553558251,0.0392006401280256,330.6002357855404,150.85861365567558,0.336176037620592
0.018112037451677634,0.03927745549109822,330.73669615065296,150.85861365567558,0.336176037620592
0.0183422799062959,0.03977675535107021,331.62116503294624,150.85861365567558,0.336176037620592
0.01851938948677149,0.04016083216643329,332.29858250635647,150.85861365567558,0.336176037620592
0.01870535454627086,0.040564112822564516,333.0071572140138,150.85861365567558,0.336176037620592
0.018909030563817784,0.041005801160232044,333.78007033969646,150.85861365567558,0.336176037620592
0.01916583945550739,0.0415627125425085,334.75000066647794,150.85861365567558,0.336176037620592
0.01922782780867385,0.04169713942788558,334.98336078819597,150.85861365567558,0.336176037620592
0.019369515473054322,0.04200440088017604,335.515656372702,150.85861365567558,0.336176037620592
0.01942264834719699,0.04211962392478495,335.7148754411844,150.85861365567558,0.336176037620592
0.019599757927672583,0.04250370074014803,336.3774092866108,150.85861365567558,0.336176037620592
0.019794578466195735,0.042926185237047415,337.10350555670533,150.85861365567558,0.336176037620592
0.019838855861314633,0.04302220444088818,337.2681381164808,150.85861365567558,0.336176037620592
0.02005138735788534,0.04348309661932387,338.05638832041046,150.85861365567558,0.336176037620592
0.020086809273980454,0.043559911982396476,338.1874459175167,150.85861365567558,0.336176037620592
0.020432172955907858,0.04430886177235448,339.46056894926124,150.85861365567558,0.336176037620592
0.02052072774614565,0.04450090018003601,339.7856554276685,150.85861365567558,0.336176037620592
0.021016634571477302,0.045576315263052614,341.59612898640415,150.85861365567558,0.336176037620592
0.021317720858285802,0.046229245849169834,342.68721853000153,150.85861365567558,0.336176037620592
0.021769350288498558,0.04720864172834567,344.3126509234375,150.85861365567558,0.336176037620592
0.022132424928473518,0.047995999199839975,345.60985490116093,150.85861365567558,0.336176037620592
0.022256401634806425,0.048264852970594116,346.05089832986863,150.85861365567558,0.336176037620592
0.022406944778210678,0.04859131826365273,346.5851650457161,150.85861365567558,0.336176037620592
0.022699175585995397,0.049225045009001794,347.61829153018886,150.85861365567558,0.336176037620592
0.022823152292328314,0.04949389877975595,348.05501901997513,150.85861365567558,0.336176037620592
0.02300911735182768,0.04989717943588717,348.70837948507307,150.85861365567558,0.336176037620592
0.023106527621089255,0.050108421684336865,349.0497938353535,150.85861365567558,0.336176037620592
0.023230504327422172,0.05037727545509102,349.4835104476324,150.85861365567558,0.336176037620592
0.023637856362516026,0.05126065213042609,350.90226553286084,150.85861365567558,0.336176037620592
0.023788399505920276,0.051587117423484694,351.42417083891416,150.85861365567558,0.336176037620592
0.023814965942991616,0.051644728945789156,351.5161379032409,150.85861365567558,0.336176037620592
0.023983220044443424,0.05200960192038408,352.09766958294705,150.85861365567558,0.336176037620592
0.024089485792728783,0.05224004800960193,352.4641330950605,150.85861365567558,0.336176037620592
0.024204607020037915,0.05248969793958792,352.86042450034483,150.85861365567558,0.336176037620592
0.024470271390751294,0.05306581316263252,353.77214824444604,150.85861365567558,0.336176037620592
0.024567681660012868,0.053277055411082214,354.1054786824647,150.85861365567558,0.336176037620592
0.0248156350726787,0.05381476295259052,354.95163862950506,150.85861365567558,0.336176037620592
0.024966178216082945,0.054141228245649126,355.46377007842386,150.85861365567558,0.336176037620592
0.02501045561120184,0.05423724744948989,355.6141675890429,150.85861365567558,0.336176037620592
0.02512557683851098,0.0544868973794759,356.0047159475534,150.85861365567558,0.336176037620592
0.025541784352628615,0.05538947789557912,357.4109131096803,150.85861365567558,0.336176037620592
0.02594913638772247,0.05627285457091419,358.77856343801704,150.85861365567558,0.336176037620592
0.026064257615031602,0.056522504500900184,359.1635524745671,150.85861365567558,0.336176037620592
0.02616166788429318,0.056733746749349875,359.48879473312417,150.85861365567558,0.336176037620592
0.026294500069649868,0.057021804360872175,359.93154679758175,150.85861365567558,0.336176037620592
0.026507031566220578,0.05748269653930786,360.6381400364835,150.85861365567558,0.336176037620592
0.026648719230601046,0.05778995799159832,361.1079750779515,150.85861365567558,0.336176037620592
0.02681697333205286,0.05815483096619324,361.66464070568566,150.85861365567558,0.336176037620592
0.026843539769124198,0.058212442488497704,361.75241061046654,150.85861365567558,0.336176037620592
0.026887817164243096,0.05830846169233847,361.89861854058245,150.85861365567558,0.336176037620592
0.02692323908033821,0.05838527705541108,362.01551728858936,150.85861365567558,0.336176037620592
0.027188903451051596,0.05896139227845569,362.89035399916565,150.85861365567558,0.336176037620592
0.027224325367146716,0.05903820764152831,363.0067464993294,150.85861365567558,0.336176037620592
0.02747227877981254,0.05957591518303661,363.81984664502534,150.85861365567558,0.336176037620592
0.027560833570050333,0.05976795359071814,364.10954528447195,150.85861365567558,0.336176037620592
0.02772908767150214,0.06013282656531306,364.6589745374323,150.85861365567558,0.336176037620592
0.02778222054564482,0.060248049609921986,364.8322081886785,150.85861365567558,0.336176037620592
0.027959330126120407,0.06063212642528505,365.40872278439593,150.85861365567558,0.336176037620592
0.028366682161214265,0.06151550310062012,366.7293283246171,150.85861365567558,0.336176037620592
0.02849065886754718,0.06178435687137428,367.1297810119796,150.85861365567558,0.336176037620592
0.028570358178761197,0.061957191438287665,367.3868560572067,150.85861365567558,0.336176037620592
0.02862349105290387,0.062072414482896576,367.5580840596158,150.85861365567558,0.336176037620592
0.028694334885094104,0.062226045209041805,367.7861953616391,150.85861365567558,0.336176037620592
0.028774034196308123,0.06239887977595519,368.04255819793605,150.85861365567558,0.336176037620592
0.028862588986545916,0.06259091818363673,368.3270812178473,150.85861365567558,0.336176037620592
0.028906866381664814,0.06268693738747749,368.4692150429551,150.85861365567558,0.336176037620592
0.02914596431530686,0.06320544108821764,369.2352755020706,150.85861365567558,0.336176037620592
0.029376206769925126,0.06370474094818963,369.97065028116856,150.85861365567558,0.336176037620592
0.029571027308448274,0.06412722544508902,370.5911364627239,150.85861365567558,0.336176037620592
0.02964187114063851,0.06428085617123425,370.8163722632336,150.85861365567558,0.336176037620592
0.029739281409900085,0.06449209841968394,371.1257289950249,150.85861365567558,0.336176037620592
0.02991639099037567,0.064876175235047,371.6871852234753,150.85861365567558,0.336176037620592
0.02997837934354213,0.06501060212042409,371.88338845343065,150.85861365567558,0.336176037620592
0.030084645091827483,0.06524104820964192,372.21936913371985,150.85861365567558,0.336176037620592
0.030252899193279295,0.06560592118423685,372.7503935292281,150.85861365567558,0.336176037620592
0.030562840959111576,0.06627805561112222,373.72559100373024,150.85861365567558,0.336176037620592
0.03088163820396764,0.06696939387877576,374.72463584570147,150.85861365567558,0.336176037620592
0.031049892305419453,0.06733426685337068,375.25028748924257,150.85861365567558,0.336176037620592
0.0312004354488237,0.06766073214642929,375.71966648712646,150.85861365567558,0.336176037620592
0.031297845718085276,0.06787197439487898,376.02291171481437,150.85861365567558,0.336176037620592
0.03142182242441819,0.06814082816563313,376.408328361831,150.85861365567558,0.336176037620592
0.03151037721465598,0.06833286657331467,376.6832629534705,150.85861365567558,0.336176037620592
0.031793752543416924,0.06894738947789558,377.561035535053,150.85861365567558,0.336176037620592
0.032006284039987634,0.06940828165633127,378.2173640278072,150.85861365567558,0.336176037620592
0.03208598335120165,0.06958111622324466,378.46304872981244,150.85861365567558,0.336176037620592
0.032263092931677236,0.06996519303860772,379.0081642313818,150.85861365567558,0.336176037620592
0.032519901823366844,0.07052210442088418,379.7965133013445,150.85861365567558,0.336176037620592
0.03264387852969976,0.07079095819163833,380.1762263091981,150.85861365567558,0.336176037620592
0.03294496481650826,0.07144388877775555,381.09605255606607,150.85861365567558,0.336176037620592
0.03327261754038809,0.07215443088617723,382.09332273563,150.85861365567558,0.336176037620592
0.03343201616281613,0.07250010002000401,382.57709574082253,150.85861365567558,0.336176037620592
0.033715391491577075,0.07311462292458493,383.4349213601966,150.85861365567558,0.336176037620592
0.03376852436571975,0.07322984596919384,383.5954501421655,150.85861365567558,0.336176037620592
0.033927922988147785,0.07357551510302061,384.0764464839335,150.85861365567558,0.336176037620592
0.034167020921789824,0.07409401880376075,384.796291816538,150.85861365567558,0.336176037620592
0.03441497433445565,0.07463172634526906,385.5407260599408,150.85861365567558,0.336176037620592
0.03486660376466841,0.0756111222244449,386.8913071220269,150.85861365567558,0.336176037620592
0.03503485786612021,0.07597599519903982,387.3927182073158,150.85861365567558,0.336176037620592
0.03512341265635801,0.07616803360672135,387.6562415219519,150.85861365567558,0.336176037620592
0.035273955799762266,0.07649449889977997,388.10363725540213,150.85861365567558,0.336176037620592
0.035513053733404305,0.0770130026005201,388.81267942363894,150.85861365567558,0.336176037620592
0.035566186607546985,0.07712822564512903,388.9699912351306,150.85861365567558,0.336176037620592
0.03580528454118903,0.07764672934586918,389.6767632330908,150.85861365567558,0.336176037620592
0.03597353864264084,0.0780116023204641,390.1730183404464,150.85861365567558,0.336176037620592
0.036097515348973756,0.07828045609121825,390.5381009568245,150.85861365567558,0.336176037620592
0.03621263657628289,0.07853010602120425,390.87666862155197,150.85861365567558,0.336176037620592
0.03662884409040052,0.07943268653730746,392.0972343280315,150.85861365567558,0.336176037620592
0.036646555048448076,0.07947109421884377,392.14905297224186,150.85861365567558,0.336176037620592
0.036850231065995005,0.07991278255651131,392.74426709123816,150.85861365567558,0.336176037620592
0.03690336394013768,0.08002800560112022,392.89932915795947,150.85861365567558,0.336176037620592
0.03711589543670839,0.08048889777955591,393.51870870700117,150.85861365567558,0.336176037620592
0.03739041528644556,0.08108421684336868,394.31669728751405,150.85861365567558,0.336176037620592
0.037470114597659566,0.08125705141028206,394.547942988271,150.85861365567558,0.336176037620592
0.037629513220087604,0.08160272054410883,395.0098597148978,150.85861365567558,0.336176037620592
0.03781547827958697,0.08200600120024006,395.54779918989453,150.85861365567558,0.336176037620592
0.03789517759080098,0.08217883576715343,395.7780287388765,150.85861365567558,0.336176037620592
0.037974876902015,0.08235167033406682,396.0080695241178,150.85861365567558,0.336176037620592
0.03805457621322902,0.0825245049009802,396.23792209606387,150.85861365567558,0.336176037620592
0.03815198648249059,0.08273574714942988,396.51859821768096,150.85861365567558,0.336176037620592
0.03852391660148933,0.08354230846169235,397.587709680069,150.85861365567558,0.336176037620592
0.03873644809806004,0.08400320064012803,398.1968230716331,150.85861365567558,0.336176037620592
0.03890470219951185,0.08436807361472295,398.678113986205,150.85861365567558,0.336176037620592
0.039010967947797195,0.08459851970394079,398.9816689829479,150.85861365567558,0.336176037620592
0.03904638986389232,0.08467533506701341,399.08278229639825,150.85861365567558,0.336176037620592
0.03912608917510633,0.08484816963392679,399.31015654573457,150.85861365567558,0.336176037620592
0.03918807752827279,0.08498259651930387,399.4868783262508,150.85861365567558,0.336176037620592
0.039276632318510585,0.0851746349269854,399.7391490118846,150.85861365567558,0.336176037620592
0.03934747615070082,0.08532826565313063,399.9408058835807,150.85861365567558,0.336176037620592
0.03968398435360444,0.08605801160232047,400.8967489951212,150.85861365567558,0.336176037620592
0.03985223845505625,0.08642288457691538,401.3735346544452,150.85861365567558,0.336176037620592
0.04003820351455562,0.08682616523304662,401.89959585186017,150.85861365567558,0.336176037620592
0.04041898911257814,0.08765193038607721,402.9738048264674,150.85861365567558,0.336176037620592
0.04058724321402994,0.08801680336067214,403.44719727336667,150.85861365567558,0.336176037620592
0.040764352794505535,0.08840088017603522,403.94467902459166,150.85861365567558,0.336176037620592
0.04095917333302868,0.08882336467293458,404.49093635645306,150.85861365567558,0.336176037620592
0.04130453701495609,0.08957231446289259,405.45681776592164,150.85861365567558,0.336176037620592
0.04136652536812254,0.08970674134826966,405.6298471782985,150.85861365567558,0.336176037620592
0.04151706851152679,0.09003320664132827,406.049641007196,150.85861365567558,0.336176037620592
0.041800443840287735,0.09064772954590919,406.8382341937306,150.85861365567558,0.336176037620592
0.04189785410954931,0.09085897179435888,407.10883120596014,150.85861365567558,0.336176037620592
0.041959842462715766,0.09099339867973595,407.2809015639571,150.85861365567558,0.336176037620592
0.042110385606120015,0.09131986397279457,407.69837449619,150.85861365567558,0.336176037620592
0.04219008491733403,0.09149269853970794,407.91915391620574,150.85861365567558,0.336176037620592
0.04244689380902363,0.0920496099219844,408.62945036430614,150.85861365567558,0.336176037620592
0.042615147910475444,0.09241448289657932,409.0939084570893,150.85861365567558,0.336176037620592
0.04304906638264064,0.09335547109421885,410.2884329246807,150.85861365567558,0.336176037620592
0.04331473075335403,0.09393158631726346,411.01745720853825,150.85861365567558,0.336176037620592
0.043668949914305207,0.09469973994798961,411.986782737128,150.85861365567558,0.336176037620592
0.043810637578685675,0.09500700140028007,412.3736537632231,150.85861365567558,0.336176037620592
0.043961180722089925,0.09533346669333867,412.78416995617846,150.85861365567558,0.336176037620592
0.04424455605085087,0.09594798959791959,413.555422060408,150.85861365567558,0.336176037620592
0.044572208774730705,0.09665853170634127,414.4447848824768,150.85861365567558,0.336176037620592
0.04465190808594473,0.09683136627325466,414.66073040476124,150.85861365567558,0.336176037620592
0.04471389643911118,0.09696579315863173,414.82858412371047,150.85861365567558,0.336176037620592
0.04493528341470567,0.09744588917783557,415.4273222665594,150.85861365567558,0.336176037620592
0.045085826558109915,0.09777235447089418,415.83380721827024,150.85861365567558,0.336176037620592
0.045307213533704406,0.09825245049009802,416.4306189339382,150.85861365567558,0.336176037620592
0.04537805736589464,0.09840608121624325,416.6213583372478,150.85861365567558,0.336176037620592
0.04562601077856047,0.09894378875775156,417.28803361572756,150.85861365567558,0.336176037620592
0.04568799913172693,0.09907821564312863,417.45448147329324,150.85861365567558,0.336176037620592
0.04577655392196472,0.09927025405081016,417.6921114259174,150.85861365567558,0.336176037620592
0.045882819670250076,0.09950070014002801,417.9770308493028,150.85861365567558,0.336176037620592
0.04594480802341653,0.09963512702540508,418.143114999518,150.85861365567558,0.336176037620592
0.046015651855606764,0.09978875775155031,418.3328184852365,150.85861365567558,0.336176037620592
0.046086495687797,0.09994238847769554,418.5224081017693,150.85861365567558,0.336176037620592