File: datasets/aisi_316_L/data/M1/train_93.csv
Time(s),Strain(%),Stress(MPa),Temp(C),Log_SR(s-1)
0.0,0.0,0.0,315.7058709310013,1.6271169150970541
3.586961149539642e-07,1.52e-05,2.680601225,315.7058709310013,1.6271169150970541
1.1327245735388341e-06,4.8e-05,8.465056500000001,315.7058709310013,1.6271169150970541
1.340390745354287e-06,5.68e-05,10.016983525,315.7058709310013,1.6271169150970541
1.6802081174159374e-06,7.12e-05,12.556500475,315.7058709310013,1.6271169150970541
2.32208537575461e-06,9.839999999999999e-05,17.353365824999997,315.7058709310013,1.6271169150970541
3.0583563485548526e-06,0.0001296,22.855652550000002,315.7058709310013,1.6271169150970541
3.643597378216583e-06,0.00015439999999999999,27.229265074999997,315.7058709310013,1.6271169150970541
3.889021035816664e-06,0.0001648,29.06336065,315.7058709310013,1.6271169150970541
4.266595893662942e-06,0.0001808,31.88504615,315.7058709310013,1.6271169150970541
4.512019551263023e-06,0.00019119999999999999,33.719141725,315.7058709310013,1.6271169150970541
4.700806980186162e-06,0.0001992,35.129984475,315.7058709310013,1.6271169150970541
4.98398812357087e-06,0.00021119999999999998,37.246248599999994,315.7058709310013,1.6271169150970541
5.191654295386323e-06,0.00021999999999999998,38.798175625,315.7058709310013,1.6271169150970541
5.512592924555659e-06,0.00023359999999999999,41.196608299999994,315.7058709310013,1.6271169150970541
5.909046525294252e-06,0.0002504,44.159378075,315.7058709310013,1.6271169150970541
6.116712697109705e-06,0.0002592,45.711305100000004,315.7058709310013,1.6271169150970541
6.3055001260328435e-06,0.0002672,47.12214785,315.7058709310013,1.6271169150970541
6.362136354709786e-06,0.0002696,47.545400674999996,315.7058709310013,1.6271169150970541
6.494287554955982e-06,0.00027519999999999997,48.53299059999999,315.7058709310013,1.6271169150970541
7.117286070402342e-06,0.0003016,53.188771675000005,315.7058709310013,1.6271169150970541
7.362709728002422e-06,0.000312,55.02286725,315.7058709310013,1.6271169150970541
7.55149715692556e-06,0.00031999999999999997,56.43371,315.7058709310013,1.6271169150970541
8.155616929479606e-06,0.0003456,60.9484068,315.7058709310013,1.6271169150970541
8.514313044433571e-06,0.0003608,63.629008025,315.7058709310013,1.6271169150970541
8.85413041649522e-06,0.00037519999999999996,66.168524975,315.7058709310013,1.6271169150970541
9.175069045664556e-06,0.00038879999999999996,68.56695764999999,315.7058709310013,1.6271169150970541
9.28834150301844e-06,0.00039359999999999997,69.41346329999999,315.7058709310013,1.6271169150970541
9.458250189049265e-06,0.0004008,70.68322177499999,315.7058709310013,1.6271169150970541
9.609280132187777e-06,0.0004072,71.811895975,315.7058709310013,1.6271169150970541
9.911340018464799e-06,0.00041999999999999996,74.069244375,315.7058709310013,1.6271169150970541
1.0100127447387938e-05,0.000428,75.480087125,315.7058709310013,1.6271169150970541
1.0515459791018844e-05,0.0004456,78.58394117499999,315.7058709310013,1.6271169150970541
1.0968549620434377e-05,0.00046479999999999997,81.969963775,315.7058709310013,1.6271169150970541
1.1591548135880738e-05,0.0004912,86.62574485,315.7058709310013,1.6271169150970541
1.1950244250834699e-05,0.0005064,89.306346075,315.7058709310013,1.6271169150970541
1.2422212823142548e-05,0.0005264,92.83345295,315.7058709310013,1.6271169150970541
1.325287751040436e-05,0.0005616,99.04116105,315.7058709310013,1.6271169150970541
1.3517179910896754e-05,0.0005727999999999999,101.01634089999999,315.7058709310013,1.6271169150970541
1.3649331111142952e-05,0.0005784,102.003930825,315.7058709310013,1.6271169150970541
1.4951964370712613e-05,0.0006336,111.7387458,315.7058709310013,1.6271169150970541
1.5027479342281866e-05,0.0006368,112.30308289999999,315.7058709310013,1.6271169150970541
1.5235145514097319e-05,0.0006456,113.85500992499999,315.7058709310013,1.6271169150970541
1.5537205400374342e-05,0.0006584,116.11235832499999,315.7058709310013,1.6271169150970541
1.655665751655929e-05,0.0007015999999999999,123.73090917499998,315.7058709310013,1.6271169150970541
1.6802081174159374e-05,0.000712,125.56500474999999,315.7058709310013,1.6271169150970541
1.7028626088867142e-05,0.0007216,127.25801605,315.7058709310013,1.6271169150970541
1.7783775804559695e-05,0.0007536,132.90138705,315.7058709310013,1.6271169150970541
1.8010320719267464e-05,0.0007632,134.59439835,315.7058709310013,1.6271169150970541
1.8614440491821507e-05,0.0007888,139.10909515,315.7058709310013,1.6271169150970541
1.8992015349667786e-05,0.0008047999999999999,141.93078065,315.7058709310013,1.6271169150970541
1.950174140776026e-05,0.0008263999999999999,145.74005607499998,315.7058709310013,1.6271169150970541
1.9992588722960425e-05,0.0008472,149.408247225,315.7058709310013,1.6271169150970541
2.046455729526827e-05,0.0008671999999999999,152.93535409999998,315.7058709310013,1.6271169150970541
2.0672223467083723e-05,0.0008759999999999999,154.48728112499998,315.7058709310013,1.6271169150970541
2.084213215311455e-05,0.0008832,155.7570396,315.7058709310013,1.6271169150970541
2.1030919582037688e-05,0.0008912,157.16788234999999,315.7058709310013,1.6271169150970541
2.1314100725422397e-05,0.0009031999999999999,159.284146475,315.7058709310013,1.6271169150970541
2.1578403125914793e-05,0.0009144,161.259326325,315.7058709310013,1.6271169150970541
2.1955977983761068e-05,0.0009304,164.081011825,315.7058709310013,1.6271169150970541
2.2390189070284288e-05,0.0009488,167.32595014999998,315.7058709310013,1.6271169150970541
2.2824400156807508e-05,0.0009672,170.570888475,315.7058709310013,1.6271169150970541
2.3258611243330727e-05,0.0009855999999999999,173.81582679999997,315.7058709310013,1.6271169150970541
2.3617307358284695e-05,0.0010008,176.496428025,315.7058709310013,1.6271169150970541
2.501433433231592e-05,0.00106,183.81730883541792,315.7058709310013,1.6271169150970541
2.510872804677749e-05,0.001064,183.84061628951937,315.7058709310013,1.6271169150970541
2.535415170437757e-05,0.0010743999999999999,183.9010563020325,315.7058709310013,1.6271169150970541
2.5599575361977653e-05,0.0010848,183.96126857152277,315.7058709310013,1.6271169150970541
2.578836279090079e-05,0.0010927999999999999,184.00743263414878,315.7058709310013,1.6271169150970541
2.6147058905854758e-05,0.001108,184.0947828538222,315.7058709310013,1.6271169150970541
2.643024004923946e-05,0.00112,184.16341386989265,315.7058709310013,1.6271169150970541
2.7072117307578135e-05,0.0011472,184.31792454289348,315.7058709310013,1.6271169150970541
2.724202599360896e-05,0.0011543999999999999,184.35858443354712,315.7058709310013,1.6271169150970541
2.7789509537486065e-05,0.0011776,184.48893193252553,315.7058709310013,1.6271169150970541
2.7883903251947633e-05,0.0011815999999999999,184.5113040357716,315.7058709310013,1.6271169150970541
2.8412508052932425e-05,0.001204,184.63604622761434,315.7058709310013,1.6271169150970541
2.867681045342482e-05,0.0012152,184.69807766417162,315.7058709310013,1.6271169150970541
2.9073264054163413e-05,0.001232,184.7907083771959,315.7058709310013,1.6271169150970541
2.9337566454655802e-05,0.0012431999999999999,184.85218864880827,315.7058709310013,1.6271169150970541
2.9545232626471257e-05,0.0012519999999999999,184.90034316635962,315.7058709310013,1.6271169150970541
2.984729251274828e-05,0.0012648,184.97015112792457,315.7058709310013,1.6271169150970541
3.0036079941671418e-05,0.0012728,185.01364121822186,315.7058709310013,1.6271169150970541
3.0300382342163814e-05,0.001284,185.07434867049986,315.7058709310013,1.6271169150970541
3.101777457207174e-05,0.0013143999999999999,185.23809387080914,315.7058709310013,1.6271169150970541
3.133871320124108e-05,0.001328,185.31086941743152,315.7058709310013,1.6271169150970541
3.15086218872719e-05,0.0013352,185.34927994526092,315.7058709310013,1.6271169150970541
3.1678530573302724e-05,0.0013423999999999999,185.38760977802553,315.7058709310013,1.6271169150970541
3.201834794536438e-05,0.0013568,185.46402975463818,315.7058709310013,1.6271169150970541
3.2622467717918425e-05,0.0013824,185.5991110136854,315.7058709310013,1.6271169150970541
3.2773497661056935e-05,0.0013888,185.6327284569685,315.7058709310013,1.6271169150970541
3.298116383287239e-05,0.0013976,185.67885395629088,315.7058709310013,1.6271169150970541
3.396285846327271e-05,0.0014391999999999999,185.89538667870232,315.7058709310013,1.6271169150970541
3.4510342007149814e-05,0.0014624,186.01508465799796,315.7058709310013,1.6271169150970541
3.479352315053452e-05,0.0014743999999999998,186.07670666844848,315.7058709310013,1.6271169150970541
3.577521778093485e-05,0.001516,186.28883148066117,315.7058709310013,1.6271169150970541
3.609615641010418e-05,0.0015295999999999999,186.35768596670871,315.7058709310013,1.6271169150970541
3.632270132481195e-05,0.0015392,186.40614545631698,315.7058709310013,1.6271169150970541
3.660588246819666e-05,0.0015512,186.46655437661715,315.7058709310013,1.6271169150970541
3.687018486868905e-05,0.0015624,186.52277180795647,315.7058709310013,1.6271169150970541
3.719112349785839e-05,0.001576,186.59082498064245,315.7058709310013,1.6271169150970541
3.7700849555950865e-05,0.0015976,186.6984405685872,315.7058709310013,1.6271169150970541
3.796515195644326e-05,0.0016087999999999999,186.75401775609873,315.7058709310013,1.6271169150970541
3.8399363042966474e-05,0.0016271999999999999,186.8449966680402,315.7058709310013,1.6271169150970541
3.858815047188962e-05,0.0016351999999999998,186.88442747623125,315.7058709310013,1.6271169150970541
3.904124030130515e-05,0.0016543999999999999,186.97875571510295,315.7058709310013,1.6271169150970541
3.911675527287441e-05,0.0016576,186.99443548748857,315.7058709310013,1.6271169150970541
3.960760258807457e-05,0.0016784,187.09606776806424,315.7058709310013,1.6271169150970541
4.0041813674597784e-05,0.0016967999999999998,187.18556449370098,315.7058709310013,1.6271169150970541
4.040050978955175e-05,0.001712,187.25921143964868,315.7058709310013,1.6271169150970541
4.045714601822869e-05,0.0017143999999999998,187.2708165529279,315.7058709310013,1.6271169150970541
4.094799333342886e-05,0.0017352,187.37113017692423,315.7058709310013,1.6271169150970541
4.136332567705976e-05,0.0017527999999999999,187.45564517932277,315.7058709310013,1.6271169150970541
4.192968796382917e-05,0.0017767999999999998,187.57036146624802,315.7058709310013,1.6271169150970541
4.300577630869107e-05,0.0018223999999999998,187.78667105725827,315.7058709310013,1.6271169150970541
4.3911955967522136e-05,0.0018608,187.96719407664858,315.7058709310013,1.6271169150970541
4.423289459669147e-05,0.0018743999999999998,188.030780147526,315.7058709310013,1.6271169150970541
4.4874771855030144e-05,0.0019015999999999998,188.15741505363974,315.7058709310013,1.6271169150970541
4.530898294155337e-05,0.0019199999999999998,188.24267951652456,315.7058709310013,1.6271169150970541
4.561104282783039e-05,0.0019328,188.30180606780323,315.7058709310013,1.6271169150970541
4.636619254352295e-05,0.0019648,188.44895823288712,315.7058709310013,1.6271169150970541
4.661161620112302e-05,0.0019752,188.4965810467979,315.7058709310013,1.6271169150970541
4.6838161115830795e-05,0.0019848,188.5404538423323,315.7058709310013,1.6271169150970541
4.740452340260021e-05,0.0020088,188.6497753080992,315.7058709310013,1.6271169150970541
4.757443208863104e-05,0.002016,188.68247226315393,315.7058709310013,1.6271169150970541
4.764994706020029e-05,0.0020192,188.6969896214203,315.7058709310013,1.6271169150970541
4.810303688961583e-05,0.0020384,188.78390609025092,315.7058709310013,1.6271169150970541
4.8612762947708294e-05,0.0020599999999999998,188.8813063722682,315.7058709310013,1.6271169150970541
4.900921654844689e-05,0.0020767999999999997,188.9567870396122,315.7058709310013,1.6271169150970541
4.910361026290846e-05,0.0020808,188.97472348337357,315.7058709310013,1.6271169150970541
4.933015517761623e-05,0.0020904,189.01771617270543,315.7058709310013,1.6271169150970541
4.9707730035462505e-05,0.0021064,189.08919993358853,315.7058709310013,1.6271169150970541
4.9858759978601015e-05,0.0021127999999999997,189.11773410641862,315.7058709310013,1.6271169150970541
5.008530489330879e-05,0.0021224,189.16047224188495,315.7058709310013,1.6271169150970541
5.044400100826275e-05,0.0021376,189.22798709246666,315.7058709310013,1.6271169150970541
5.09159695805706e-05,0.0021576,189.31653785206265,315.7058709310013,1.6271169150970541
5.116139323817067e-05,0.002168,189.3624577013563,315.7058709310013,1.6271169150970541
5.1463453124447704e-05,0.0021808,189.41885667450768,315.7058709310013,1.6271169150970541
5.199205792543248e-05,0.0022031999999999998,189.51724521018906,315.7058709310013,1.6271169150970541
5.280384386980198e-05,0.0022375999999999997,189.66758567567592,315.7058709310013,1.6271169150970541
5.301151004161744e-05,0.0022464,189.70589973829968,315.7058709310013,1.6271169150970541
5.367226604284842e-05,0.0022743999999999998,189.82742051560072,315.7058709310013,1.6271169150970541
5.4219749586725526e-05,0.0022976,189.92766778129146,315.7058709310013,1.6271169150970541
5.4389658272756356e-05,0.0023048,189.95869863034002,315.7058709310013,1.6271169150970541
5.465396067324875e-05,0.002316,190.00689380109264,315.7058709310013,1.6271169150970541
5.471059690192569e-05,0.0023184,190.01720950215315,315.7058709310013,1.6271169150970541
5.531471667447973e-05,0.0023439999999999997,190.1269857540571,315.7058709310013,1.6271169150970541
5.584332147546452e-05,0.0023664,190.22265697915014,315.7058709310013,1.6271169150970541
5.629641130488006e-05,0.0023856,190.30438011592886,315.7058709310013,1.6271169150970541
5.6504077476695517e-05,0.0023944,190.34175078664282,315.7058709310013,1.6271169150970541
5.688165233454179e-05,0.0024104,190.40956051614964,315.7058709310013,1.6271169150970541
5.748577210709583e-05,0.002436,190.51769208829782,315.7058709310013,1.6271169150970541
5.769343827891129e-05,0.0024448,190.5547598422866,315.7058709310013,1.6271169150970541
5.7919983193619055e-05,0.0024544,190.5951380962069,315.7058709310013,1.6271169150970541
5.895831405269632e-05,0.0024984,190.77942264851023,315.7058709310013,1.6271169150970541
5.922261645318871e-05,0.0025096,190.82612880187543,315.7058709310013,1.6271169150970541
6.0544128455650686e-05,0.0025656,191.05845117678467,315.7058709310013,1.6271169150970541
6.103497577085085e-05,0.0025864,191.14423756002748,315.7058709310013,1.6271169150970541
6.129927817134324e-05,0.0025976,191.1903187648649,315.7058709310013,1.6271169150970541
6.16579742862972e-05,0.0026127999999999998,191.25273379340916,315.7058709310013,1.6271169150970541
6.211106411571274e-05,0.002632,191.33137178952708,315.7058709310013,1.6271169150970541
6.22054578301743e-05,0.002636,191.34772651023835,315.7058709310013,1.6271169150970541
6.237536651620513e-05,0.0026432,191.37714063779444,315.7058709310013,1.6271169150970541
6.286621383140529e-05,0.0026639999999999997,191.46193976407105,315.7058709310013,1.6271169150970541
6.350809108974397e-05,0.0026912,191.57244232989225,315.7058709310013,1.6271169150970541
6.38290297189133e-05,0.0027048,191.62753021094727,315.7058709310013,1.6271169150970541
6.403669589072876e-05,0.0027136,191.663117755859,315.7058709310013,1.6271169150970541
6.407445337651338e-05,0.0027152,191.66958337999884,315.7058709310013,1.6271169150970541
6.43576345198981e-05,0.0027272,191.71802828685227,315.7058709310013,1.6271169150970541
6.471633063485205e-05,0.0027424,191.77927265901408,315.7058709310013,1.6271169150970541
6.50561480069137e-05,0.0027568,191.83717163961472,315.7058709310013,1.6271169150970541
6.524493543583685e-05,0.0027648,191.86928677143774,315.7058709310013,1.6271169150970541
6.549035909343692e-05,0.0027752,191.91098231466057,315.7058709310013,1.6271169150970541
6.569802526525238e-05,0.002784,191.9462155837737,315.7058709310013,1.6271169150970541
6.605672138020635e-05,0.0027992,192.00697091648317,315.7058709310013,1.6271169150970541
6.711393098217592e-05,0.0028439999999999997,192.1852952179657,315.7058709310013,1.6271169150970541
6.717056721085287e-05,0.0028464,192.1948172694514,315.7058709310013,1.6271169150970541
6.754814206869914e-05,0.0028623999999999998,192.25821778286974,315.7058709310013,1.6271169150970541
6.781244446919155e-05,0.0028736,192.30251593126238,315.7058709310013,1.6271169150970541
6.849207921331484e-05,0.0029024,192.4161173691292,315.7058709310013,1.6271169150970541
6.8982926528515e-05,0.0029232,192.49788961845888,315.7058709310013,1.6271169150970541
6.917171395743814e-05,0.0029311999999999997,192.52928002167437,315.7058709310013,1.6271169150970541
6.924722892900739e-05,0.0029343999999999998,192.5418268253973,315.7058709310013,1.6271169150970541
7.02100448165154e-05,0.0029752,192.701333678479,315.7058709310013,1.6271169150970541
7.039883224543854e-05,0.0029831999999999997,192.7325092525438,315.7058709310013,1.6271169150970541
7.056874093146937e-05,0.0029904,192.76053940284396,315.7058709310013,1.6271169150970541
7.070089213171557e-05,0.002996,192.7823224380194,315.7058709310013,1.6271169150970541
7.104070950377722e-05,0.0030104,192.83826316767852,315.7058709310013,1.6271169150970541
7.147492059030043e-05,0.0030288,192.90959135435781,315.7058709310013,1.6271169150970541
7.162595053343895e-05,0.0030352,192.9343615193598,315.7058709310013,1.6271169150970541
7.223007030599299e-05,0.0030608,193.03323915899207,315.7058709310013,1.6271169150970541
7.266428139251622e-05,0.0030792,193.1041083504003,315.7058709310013,1.6271169150970541
7.27775538498701e-05,0.003084,193.1225687792734,315.7058709310013,1.6271169150970541
7.289082630722398e-05,0.0030888,193.14101800598914,315.7058709310013,1.6271169150970541
7.31740074506087e-05,0.0031008,193.18709222186666,315.7058709310013,1.6271169150970541
7.357046105134728e-05,0.0031176,193.25147946937074,315.7058709310013,1.6271169150970541
7.394803590919355e-05,0.0031336,193.3126749687431,315.7058709310013,1.6271169150970541
7.408018710943975e-05,0.0031392,193.3340645884586,315.7058709310013,1.6271169150970541
7.430673202414752e-05,0.0031487999999999998,193.37069791891685,315.7058709310013,1.6271169150970541
7.45332769388553e-05,0.0031584,193.40728771725654,315.7058709310013,1.6271169150970541
7.481645808224e-05,0.0031704,193.45296402803805,315.7058709310013,1.6271169150970541
7.513739671140932e-05,0.0031839999999999998,193.5046490828037,315.7058709310013,1.6271169150970541
7.530730539744015e-05,0.0031912,193.53197689887972,315.7058709310013,1.6271169150970541
7.56471227695018e-05,0.0032056,193.58656049900625,315.7058709310013,1.6271169150970541
7.638339374230205e-05,0.0032367999999999997,193.70449798983825,315.7058709310013,1.6271169150970541
7.65721811712252e-05,0.0032448,193.73466685303555,315.7058709310013,1.6271169150970541
7.717630094377924e-05,0.0032703999999999997,193.83101285882702,315.7058709310013,1.6271169150970541
7.7402845858487e-05,0.00328,193.86706672431754,315.7058709310013,1.6271169150970541
7.838454048888732e-05,0.0033215999999999996,194.02282698498647,315.7058709310013,1.6271169150970541
7.846005546045657e-05,0.0033247999999999997,194.03477693886828,315.7058709310013,1.6271169150970541
7.881875157541054e-05,0.0033399999999999997,194.09147807769543,315.7058709310013,1.6271169150970541
7.923408391904144e-05,0.0033575999999999996,194.15700645524572,315.7058709310013,1.6271169150970541
7.93095988906107e-05,0.0033607999999999997,194.16890629929495,315.7058709310013,1.6271169150970541
7.94417500908569e-05,0.0033664,194.18972039891315,315.7058709310013,1.6271169150970541
8.000811237762633e-05,0.0033904,194.27877117090745,315.7058709310013,1.6271169150970541
8.046120220704186e-05,0.0034096,194.34983490639397,315.7058709310013,1.6271169150970541
8.089541329356508e-05,0.003428,194.41779134875068,315.7058709310013,1.6271169150970541
8.10653219795959e-05,0.0034352,194.44434425800424,315.7058709310013,1.6271169150970541
8.146177558033449e-05,0.0034519999999999998,194.50621678178118,315.7058709310013,1.6271169150970541
8.163168426636532e-05,0.0034592,194.53269761562083,315.7058709310013,1.6271169150970541
8.233019775338092e-05,0.0034888,194.6413381928437,315.7058709310013,1.6271169150970541
8.257562141098101e-05,0.0034992,194.67942378949357,315.7058709310013,1.6271169150970541
8.293431752593498e-05,0.0035144,194.7350080397077,315.7058709310013,1.6271169150970541
8.329301364088895e-05,0.0035296,194.79049861051192,315.7058709310013,1.6271169150970541
8.338740735535051e-05,0.0035336,194.80508589270173,315.7058709310013,1.6271169150970541
8.399152712790455e-05,0.0035591999999999998,194.89829246458896,315.7058709310013,1.6271169150970541
8.414255707104307e-05,0.0035656,194.92155321001854,315.7058709310013,1.6271169150970541
8.480331307227405e-05,0.0035935999999999997,195.02312811985004,315.7058709310013,1.6271169150970541
8.516200918722801e-05,0.0036087999999999997,195.07813950840642,315.7058709310013,1.6271169150970541
8.597379513159751e-05,0.0036431999999999997,195.2023063837563,315.7058709310013,1.6271169150970541
8.618146130341297e-05,0.003652,195.23399645293125,315.7058709310013,1.6271169150970541
8.62380975320899e-05,0.0036544,195.24263402869028,315.7058709310013,1.6271169150970541
8.695548976199784e-05,0.0036848,195.3518525322835,315.7058709310013,1.6271169150970541
8.725754964827486e-05,0.0036975999999999997,195.39773407384345,315.7058709310013,1.6271169150970541
8.737082210562874e-05,0.0037024,195.41492367698493,315.7058709310013,1.6271169150970541
8.776727570636732e-05,0.0037191999999999998,195.47501896318172,315.7058709310013,1.6271169150970541
8.831475925024444e-05,0.0037424,195.5578339363271,315.7058709310013,1.6271169150970541
8.863569787941377e-05,0.003756,195.60628755854447,315.7058709310013,1.6271169150970541
8.891887902279847e-05,0.0037679999999999996,195.64898396124684,315.7058709310013,1.6271169150970541
8.901327273726005e-05,0.0037719999999999997,195.66320430662464,315.7058709310013,1.6271169150970541
8.944748382378327e-05,0.0037903999999999998,195.72854229522562,315.7058709310013,1.6271169150970541
8.995720988187575e-05,0.003812,195.80508578444494,315.7058709310013,1.6271169150970541
9.033478473972202e-05,0.003828,195.86167565648364,315.7058709310013,1.6271169150970541
9.037254222550665e-05,0.0038296,195.86732956539453,315.7058709310013,1.6271169150970541
9.04480571970759e-05,0.0038328,195.87863462021016,315.7058709310013,1.6271169150970541
9.082563205492219e-05,0.0038488,195.93510477280904,315.7058709310013,1.6271169150970541
9.141087308458391e-05,0.0038735999999999996,196.02245291213745,315.7058709310013,1.6271169150970541
9.146750931326086e-05,0.0038759999999999997,196.030894366768,315.7058709310013,1.6271169150970541
9.171293297086095e-05,0.0038864,196.06745047290357,315.7058709310013,1.6271169150970541
9.21849015431688e-05,0.0039064,196.13764362483755,315.7058709310013,1.6271169150970541
9.244920394366119e-05,0.0039176,196.1768905666807,315.7058709310013,1.6271169150970541
9.278902131572282e-05,0.003932,196.22728668139223,315.7058709310013,1.6271169150970541
9.284565754439978e-05,0.0039344,196.23567903089955,315.7058709310013,1.6271169150970541
9.30155662304306e-05,0.0039416,196.26084410828926,315.7058709310013,1.6271169150970541
9.32987473738153e-05,0.0039536,196.30274610135703,315.7058709310013,1.6271169150970541
9.348753480273845e-05,0.0039616,196.33065321081602,315.7058709310013,1.6271169150970541
9.388398840347705e-05,0.0039784,196.38918670205516,315.7058709310013,1.6271169150970541
9.428044200421563e-05,0.0039952,196.44762387387783,315.7058709310013,1.6271169150970541
9.439371446156953e-05,0.004,196.4643025962256,315.7058709310013,1.6271169150970541
0.00010255096284072495,0.0043456691338267656,197.64566479814636,315.7058709310013,1.6271169150970541
0.0001107082112198804,0.004691338267653531,198.79089660003734,315.7058709310013,1.6271169150970541
0.00012158454239208766,0.005152230446089218,200.26789793935413,315.7058709310013,1.6271169150970541
0.00012430362518513948,0.00526745349069814,200.6289799393829,315.7058709310013,1.6271169150970541
0.0001478690093915885,0.0062660532106421285,203.63884081126812,315.7058709310013,1.6271169150970541
0.00015194763358116622,0.006438887777555511,204.14015904444724,315.7058709310013,1.6271169150970541
0.0001723407545290548,0.007303060612122424,206.57203898027709,315.7058709310013,1.6271169150970541
0.00017913846151168433,0.007591118223644729,207.35735153643114,315.7058709310013,1.6271169150970541
0.00018185754430473613,0.00770634126825365,207.6682116549413,315.7058709310013,1.6271169150970541
0.00019046797314940022,0.00807121424284857,208.6408517401116,315.7058709310013,1.6271169150970541
0.00020496974804567656,0.008685737147429486,210.24107207428597,315.7058709310013,1.6271169150970541
0.00022898831271763424,0.009703540708141629,212.79747345982457,315.7058709310013,1.6271169150970541
0.0002321605759761947,0.009837967593518704,213.12711300661425,315.7058709310013,1.6271169150970541
0.00023759874156229833,0.010068413682736548,213.68815137658618,315.7058709310013,1.6271169150970541
0.00024756871180348826,0.010490898179635926,214.70388299669625,315.7058709310013,1.6271169150970541
0.0002865422318372309,0.012142428485697139,218.53009445160768,315.7058709310013,1.6271169150970541
0.0003069353527851195,0.013006601320264053,220.45083473930126,315.7058709310013,1.6271169150970541
0.0003105607965091886,0.013160232046409282,220.78702215061952,315.7058709310013,1.6271169150970541
0.0003327666393191118,0.01410122024404881,222.81373307359027,315.7058709310013,1.6271169150970541
0.0003409238876982672,0.014446889377875576,223.54489935090234,315.7058709310013,1.6271169150970541
0.0003563320235255608,0.0150998199639928,224.90763804739356,315.7058709310013,1.6271169150970541
0.000378537866335484,0.01604080816163233,226.83182519610008,315.7058709310013,1.6271169150970541
0.00038669511471463937,0.01638647729545909,227.52754584827338,315.7058709310013,1.6271169150970541
0.0003948523630937948,0.016732146429285857,228.21756580810083,315.7058709310013,1.6271169150970541
0.00040210325054193297,0.017039407881576315,228.82626312153394,315.7058709310013,1.6271169150970541
0.0004166050254382093,0.01765393078615723,230.03096441545125,315.7058709310013,1.6271169150970541
0.0004234027324208388,0.017941988397679534,230.59002749096567,315.7058709310013,1.6271169150970541
0.0004270281761449079,0.018095619123824763,230.88676260569596,315.7058709310013,1.6271169150970541
0.0004360917854550806,0.018479695939187836,231.62433395166263,315.7058709310013,1.6271169150970541
0.00044107677057567563,0.018690938187637528,232.02744901545748,315.7058709310013,1.6271169150970541
0.00044742129709279653,0.01895979195839168,232.53794399186836,315.7058709310013,1.6271169150970541
0.00045240628221339147,0.019171034206841367,232.93706926509614,315.7058709310013,1.6271169150970541
0.00046101671105805555,0.019535907181436288,233.62245095452496,315.7058709310013,1.6271169150970541
0.00047098668129924554,0.019958391678335668,234.409844436309,315.7058709310013,1.6271169150970541
0.00047506530548882325,0.02013122624524905,234.73008316597813,315.7058709310013,1.6271169150970541
0.00048775435852306504,0.02066893378675735,235.71959224274235,315.7058709310013,1.6271169150970541
0.0004968179678332378,0.021053010602120423,236.42024722364087,315.7058709310013,1.6271169150970541
0.0005063347576089192,0.02145629125825165,237.15059067643017,315.7058709310013,1.6271169150970541
0.0005113197427295141,0.02166753350670134,237.53101384076493,315.7058709310013,1.6271169150970541
0.0005172110887811264,0.02191718343668734,237.97874503483257,315.7058709310013,1.6271169150970541
0.0005258215176257904,0.022282056411282256,238.62956005313944,315.7058709310013,1.6271169150970541
0.0005335255855394372,0.02260852170434087,239.20835340302514,315.7058709310013,1.6271169150970541
0.0005380573901945236,0.022800560112022406,239.5472975229718,315.7058709310013,1.6271169150970541
0.00054258919484961,0.022992598519703943,239.88513009463978,315.7058709310013,1.6271169150970541
0.0005457614581081704,0.023127025405081016,240.12095843319352,315.7058709310013,1.6271169150970541
0.000557544150211395,0.02362632526505301,240.9922508168031,315.7058709310013,1.6271169150970541
0.0005724991055731798,0.02426005201040208,242.08784874532515,315.7058709310013,1.6271169150970541
0.000574765007900723,0.02435607121424285,242.25286962363415,315.7058709310013,1.6271169150970541
0.0005924390460555598,0.02510502100420084,243.53143760380885,315.7058709310013,1.6271169150970541
0.0006019558358312412,0.025508301660332067,244.21373161324547,315.7058709310013,1.6271169150970541
0.0006105662646759052,0.025873174634926985,244.82742872230628,315.7058709310013,1.6271169150970541
0.0006259744005031988,0.02652610522104421,245.91726484624124,315.7058709310013,1.6271169150970541
0.0006323189270203198,0.02679495899179836,246.36297400784323,315.7058709310013,1.6271169150970541
0.0006382102730719321,0.02704460892178436,246.7752875969555,315.7058709310013,1.6271169150970541
0.0006486334237786306,0.02748629725945189,247.50114751428663,315.7058709310013,1.6271169150970541
0.0006595097549508379,0.027947189437887578,248.25373303949294,315.7058709310013,1.6271169150970541
0.0006626820182093983,0.028081616323264655,248.47232334474774,315.7058709310013,1.6271169150970541
0.0006699329056575365,0.028388877775555113,248.9704316561875,315.7058709310013,1.6271169150970541
0.0006762774321746574,0.02865773154630926,249.40455419516192,315.7058709310013,1.6271169150970541
0.0006803560563642351,0.028830566113222645,249.68279443721124,315.7058709310013,1.6271169150970541
0.0006848878610193215,0.02902260452090418,249.99118842382765,315.7058709310013,1.6271169150970541
0.0006912323875364423,0.029291458291658332,250.42160634529856,315.7058709310013,1.6271169150970541
0.0007007491773121237,0.029694738947789557,251.06435553332403,315.7058709310013,1.6271169150970541
0.0007197827568634864,0.03050130026005201,252.33973056741183,315.7058709310013,1.6271169150970541
0.0007283931857081505,0.03086617323464693,252.9123579823721,315.7058709310013,1.6271169150970541
0.000750145848052565,0.031787957591518305,254.34735965670322,315.7058709310013,1.6271169150970541
0.0007673667057418931,0.03251770354070814,255.4719245518153,315.7058709310013,1.6271169150970541
0.000776430315052066,0.03290178035607122,256.0598450970833,315.7058709310013,1.6271169150970541
0.0007941043532069026,0.033650730146029206,257.19864784689184,315.7058709310013,1.6271169150970541
0.0008104188499652135,0.03434206841368274,258.2411070871811,315.7058709310013,1.6271169150970541
0.0008253738053269985,0.034975795159031806,259.18952700709934,315.7058709310013,1.6271169150970541
0.0008398755802232747,0.03559031806361272,260.10282709729694,315.7058709310013,1.6271169150970541
0.0008643473253607412,0.03662732546509302,261.63019627506617,315.7058709310013,1.6271169150970541
0.0008688791300158274,0.036819363872774555,261.9111819399847,315.7058709310013,1.6271169150970541
0.0008856468072396469,0.03752990598119624,262.94589624944325,315.7058709310013,1.6271169150970541
0.0008951635970153282,0.03793318663732746,263.52976735679067,315.7058709310013,1.6271169150970541
0.0009205417030838119,0.039008601720344066,265.07504125393586,315.7058709310013,1.6271169150970541
0.000939122102169666,0.03979595919183837,266.19588690033476,315.7058709310013,1.6271169150970541
0.0009459198091522954,0.04008401680336067,266.6037872161733,315.7058709310013,1.6271169150970541
0.0009540770575314507,0.04042968593718743,267.09176165097324,315.7058709310013,1.6271169150970541
0.0009613279449795889,0.04073694738947789,267.52415237702695,315.7058709310013,1.6271169150970541
0.0009645002082381496,0.040871374274854974,267.71292315935756,315.7058709310013,1.6271169150970541
0.0009690320128932358,0.04106341268253651,267.98217620878427,315.7058709310013,1.6271169150970541
0.0009771892612723911,0.04140908181636327,268.4655974139981,315.7058709310013,1.6271169150970541
0.000982627426858495,0.04163952790558112,268.7870041604386,315.7058709310013,1.6271169150970541
0.00098761241197909,0.04185077015403081,269.0810181228989,315.7058709310013,1.6271169150970541
0.0009903314947721416,0.04196599319863972,269.24114540866117,315.7058709310013,1.6271169150970541
0.0009971292017547713,0.042254050810162036,269.6407152952819,315.7058709310013,1.6271169150970541
0.001009818254789013,0.04279175835167033,270.38374816360385,315.7058709310013,1.6271169150970541
0.0010252263906163064,0.04344468893778755,271.2811248774088,315.7058709310013,1.6271169150970541
0.0010265859320128324,0.043502300460092014,271.36005178027426,315.7058709310013,1.6271169150970541
0.0010528703990123336,0.044616123224644935,272.8780501520999,315.7058709310013,1.6271169150970541
0.0010546831208743679,0.04469293858771754,272.9821916519371,315.7058709310013,1.6271169150970541
0.0010601212864604717,0.04492338467693539,273.29419811567635,315.7058709310013,1.6271169150970541
0.0010714507980981874,0.045403480696139226,273.94221388463706,315.7058709310013,1.6271169150970541
0.0010741698808912393,0.04551870374074815,274.0973393619463,315.7058709310013,1.6271169150970541
0.0010886716557875157,0.04613322664532907,274.922103132098,315.7058709310013,1.6271169150970541
0.0010909375581150589,0.046229245849169834,275.05058440937864,315.7058709310013,1.6271169150970541
0.001103173430683792,0.046747749549909984,275.7425931815657,315.7058709310013,1.6271169150970541
0.0011226601907006633,0.04757351470294059,276.8385331791109,315.7058709310013,1.6271169150970541
0.001128098356286767,0.04780396079215843,277.1430495654254,315.7058709310013,1.6271169150970541
0.001138068326527957,0.04822644528905781,277.69984681986523,315.7058709310013,1.6271169150970541
0.0011457723944416037,0.04855291058211643,278.1287973091391,315.7058709310013,1.6271169150970541
0.0011543828232862675,0.048917783556711336,278.6068836447571,315.7058709310013,1.6271169150970541
0.0011575550865448282,0.04905221044208842,278.7826698841771,315.7058709310013,1.6271169150970541
0.0011620868911999145,0.04924424884976995,279.03346752216504,315.7058709310013,1.6271169150970541
0.0011657123349239837,0.04939787957591518,279.2338311082213,315.7058709310013,1.6271169150970541
0.0011702441395790698,0.049589917983596715,279.48394416441135,315.7058709310013,1.6271169150970541
0.001176588666096191,0.04985877175435087,279.83346876666985,315.7058709310013,1.6271169150970541
0.0011815736512167858,0.05007001400280056,280.10757984352557,315.7058709310013,1.6271169150970541
0.0012033263135612004,0.050991798359671936,281.2984614925801,315.7058709310013,1.6271169150970541
0.0012069517572852696,0.051145429085817165,281.49612265900606,315.7058709310013,1.6271169150970541
0.0012114835619403558,0.0513374674934987,281.7428737935829,315.7058709310013,1.6271169150970541
0.0012132962838023904,0.05141428285657132,281.8414734217933,315.7058709310013,1.6271169150970541
0.0012282512391641753,0.05204800960192038,282.6527397623949,315.7058709310013,1.6271169150970541
0.001235955307077822,0.052374474894979,283.0691608360835,315.7058709310013,1.6271169150970541
0.0012436593749914691,0.052700940188037615,283.484570818818,315.7058709310013,1.6271169150970541
0.0012509102624396072,0.05300820164032807,283.874629083293,315.7058709310013,1.6271169150970541
0.0012527229843016417,0.05308501700340068,283.9720057493722,315.7058709310013,1.6271169150970541
0.0012577079694222368,0.05329625925185037,284.23950863832243,315.7058709310013,1.6271169150970541
0.0012599738717497797,0.05339227845569114,284.36096413434103,315.7058709310013,1.6271169150970541
0.0012635993154738489,0.05354590918183637,284.555115894272,315.7058709310013,1.6271169150970541
0.0012776479099046165,0.054141228245649126,285.3054109103631,315.7058709310013,1.6271169150970541
0.0012812733536286855,0.054294858971794355,285.49851227020497,315.7058709310013,1.6271169150970541
0.0012903369629388584,0.054678935787157434,285.98033572504494,315.7058709310013,1.6271169150970541
0.0013021196550420829,0.055178235647129426,286.6047375171061,315.7058709310013,1.6271169150970541
0.001310730083886747,0.055543108621724346,287.05963848815924,315.7058709310013,1.6271169150970541
0.0013338422876276875,0.056522504500900184,288.2749623124024,315.7058709310013,1.6271169150970541
0.00136284583742024,0.057751550310062016,289.7885165824253,315.7058709310013,1.6271169150970541
0.0013809730560405855,0.05851970394078816,290.72811125978393,315.7058709310013,1.6271169150970541
0.0013859580411611807,0.058730946189237854,290.9856549561825,315.7058709310013,1.6271169150970541
0.0013886771239542321,0.058846169233846765,291.125981057342,315.7058709310013,1.6271169150970541
0.001394115289540336,0.059076615323064616,291.40631219927,315.7058709310013,1.6271169150970541
0.0014113361472296642,0.05980636127225446,292.29122701618496,315.7058709310013,1.6271169150970541
0.001416321132350259,0.060017603520704135,292.5465993426714,315.7058709310013,1.6271169150970541
0.0014222124784018715,0.060267253450690145,292.84795150477396,315.7058709310013,1.6271169150970541
0.0014267442830569576,0.06045929185837168,293.0794296965006,315.7058709310013,1.6271169150970541
0.0014530287500564584,0.061573114622924585,294.4163915230358,315.7058709310013,1.6271169150970541
0.0014602796375045967,0.06188037607521504,294.7835444316178,315.7058709310013,1.6271169150970541
0.0014729686905388386,0.06241808361672335,295.4243557702764,315.7058709310013,1.6271169150970541
0.00148248548031452,0.06282136427285458,295.90355235989415,315.7058709310013,1.6271169150970541
0.0014879236459006233,0.06305181036207241,296.1768403196813,315.7058709310013,1.6271169150970541
0.0014997063380038477,0.0635511102220444,296.7676314533981,315.7058709310013,1.6271169150970541
0.001508316766848512,0.06391598319663933,297.19821926608387,315.7058709310013,1.6271169150970541
0.001511035849641564,0.06403120624124825,297.33399506060925,315.7058709310013,1.6271169150970541
0.0015200994589517364,0.06441528305661132,297.7858944314976,315.7058709310013,1.6271169150970541
0.0015287098877964005,0.06478015603120624,298.2142264858072,315.7058709310013,1.6271169150970541
0.001533241692451487,0.06497219443888778,298.43928643061827,315.7058709310013,1.6271169150970541
0.0015500093696753066,0.06568273654730947,299.2697620437724,315.7058709310013,1.6271169150970541
0.0015545411743303928,0.065874774954991,299.49361253070856,315.7058709310013,1.6271169150970541
0.001570402490623195,0.06654690938187638,300.27509288835313,315.7058709310013,1.6271169150970541
0.0015853574459849802,0.06718063612722545,301.00910249460816,315.7058709310013,1.6271169150970541
0.0015898892506400666,0.06737267453490699,301.23099586760196,315.7058709310013,1.6271169150970541
0.0015939678748296444,0.06754550910182038,301.4304890909901,315.7058709310013,1.6271169150970541
0.0016048442060018512,0.06800640128025605,301.96150014030474,315.7058709310013,1.6271169150970541
0.0016098291911224463,0.06821764352870574,302.2044109669709,315.7058709310013,1.6271169150970541
0.0016152673567085502,0.06844808961792359,302.4690702691467,315.7058709310013,1.6271169150970541
0.0016306754925358435,0.06910102020404081,303.2170577493194,315.7058709310013,1.6271169150970541
0.0016433645455700857,0.06963872774554912,303.8309799414142,315.7058709310013,1.6271169150970541
0.0016506154330182237,0.06994598919783958,304.1809625523075,315.7058709310013,1.6271169150970541
0.0016687426516385692,0.07071414282856572,305.0533060470116,315.7058709310013,1.6271169150970541
0.0016750871781556899,0.07098299659931986,305.35775214902776,315.7058709310013,1.6271169150970541
0.001685963509327897,0.07144388877775555,305.87861555296496,315.7058709310013,1.6271169150970541
0.0016909484944484922,0.07165513102620524,306.1169064965338,315.7058709310013,1.6271169150970541
0.0016977462014311218,0.07194318863772756,306.4414076393563,315.7058709310013,1.6271169150970541
0.0017063566302757856,0.07230806161232246,306.85171591527,315.7058709310013,1.6271169150970541
0.0017163266005169758,0.07273054610922185,307.32580227969726,315.7058709310013,1.6271169150970541
0.001722217946568588,0.07298019603920784,307.6054393982494,315.7058709310013,1.6271169150970541
0.001742157887050968,0.07382516503300661,308.5491475198649,315.7058709310013,1.6271169150970541
0.0017503151354301234,0.07417083416683337,308.9339946852841,315.7058709310013,1.6271169150970541
0.0017679891735849602,0.07491978395679136,309.76543875019365,315.7058709310013,1.6271169150970541
0.0017765996024296242,0.07528465693138628,310.1693264380421,315.7058709310013,1.6271169150970541
0.0017879291140673402,0.07576475295059013,310.6995964232661,315.7058709310013,1.6271169150970541
0.001790648196860392,0.07587997599519905,310.8266660288353,315.7058709310013,1.6271169150970541
0.0018019777084981078,0.07636007201440288,311.3553147505522,315.7058709310013,1.6271169150970541
0.0018051499717566684,0.07649449889977997,311.5031038986891,315.7058709310013,1.6271169150970541
0.001825543092704557,0.07735867173434688,312.4507698982487,315.7058709310013,1.6271169150970541
0.0018364194238767644,0.07781956391278257,312.95450316797763,315.7058709310013,1.6271169150970541
0.0018386853262043073,0.07791558311662333,313.05930099894726,315.7058709310013,1.6271169150970541
0.0018432171308593937,0.07810762152430487,313.2687456806787,315.7058709310013,1.6271169150970541
0.0018568125448246528,0.07868373674734948,313.8958780538489,315.7058709310013,1.6271169150970541
0.0018645166127382994,0.07901020204040808,314.25045810840714,315.7058709310013,1.6271169150970541
0.0018681420564623686,0.07916383276655331,314.41712155624384,315.7058709310013,1.6271169150970541
0.0018758461243760154,0.07949029805961193,314.7708631360039,315.7058709310013,1.6271169150970541
0.001884909733686188,0.079874374874975,315.1863051214289,315.7058709310013,1.6271169150970541
0.0018980519671859388,0.08043128625725146,315.78731481890213,315.7058709310013,1.6271169150970541
0.0019030369523065334,0.08064252850570114,316.0148591853216,315.7058709310013,1.6271169150970541
0.0019125537420822151,0.08104580916183238,316.44861759771345,315.7058709310013,1.6271169150970541
0.0019220705318578964,0.0814490898179636,316.88153506014834,315.7058709310013,1.6271169150970541
0.0019261491560474738,0.08162192438487698,317.0668151171359,315.7058709310013,1.6271169150970541
0.001931134141168069,0.08183316663332667,317.2930608608864,315.7058709310013,1.6271169150970541
0.0019379318481506987,0.08212122424484898,317.60121106034126,315.7058709310013,1.6271169150970541
0.0019415572918747676,0.08227485497099421,317.7653854524438,315.7058709310013,1.6271169150970541
0.0019483549988573972,0.08256291258251651,318.0728905501663,315.7058709310013,1.6271169150970541
0.0019515272621159574,0.08269733946789358,318.2162497106413,315.7058709310013,1.6271169150970541
0.001963309954219182,0.08319663932786557,318.74793277082455,315.7058709310013,1.6271169150970541
0.0019687481198052857,0.08342708541708342,318.9929050920504,315.7058709310013,1.6271169150970541
0.0019728267439948636,0.08359991998399681,319.176461184472,315.7058709310013,1.6271169150970541
0.0019814371728395274,0.08396479295859172,319.56348318119217,315.7058709310013,1.6271169150970541
0.001999564391459873,0.08473294658931786,320.3761289069996,315.7058709310013,1.6271169150970541
0.002013159805425132,0.08530906181236247,320.9837290121412,315.7058709310013,1.6271169150970541
0.002014066166356149,0.08534746949389878,321.02417869532775,315.7058709310013,1.6271169150970541
0.00202041069287327,0.08561632326465293,321.3071279666802,315.7058709310013,1.6271169150970541
0.0020249424975283562,0.08580836167233447,321.5090224732244,315.7058709310013,1.6271169150970541
0.0020480547012692966,0.0867877575515103,322.53595616514565,315.7058709310013,1.6271169150970541
0.002058931032441504,0.08724864972994599,323.0176542698528,315.7058709310013,1.6271169150970541
0.002064822378493116,0.08749829965993199,323.27815968207085,315.7058709310013,1.6271169150970541
0.002073885987803289,0.08788237647529507,323.6783719235911,315.7058709310013,1.6271169150970541
0.0020865750408375306,0.08842008401680336,324.23752496821913,315.7058709310013,1.6271169150970541
0.0020920132064236345,0.08865053010602121,324.47675585125575,315.7058709310013,1.6271169150970541
0.002105155439923385,0.08920744148829766,325.05389807070645,315.7058709310013,1.6271169150970541
0.002111499966440506,0.08947629525905182,325.3320153854752,315.7058709310013,1.6271169150970541
0.0021187508538886442,0.08978355671134228,325.6494649810885,315.7058709310013,1.6271169150970541
0.0021278144631988165,0.09016763352670534,326.0456817896656,315.7058709310013,1.6271169150970541
0.002133705809250429,0.09041728345669134,326.3028697982971,315.7058709310013,1.6271169150970541
0.002151379847405266,0.09116623324664934,327.07277726756234,315.7058709310013,1.6271169150970541
0.0021531925692673004,0.09124304860972195,327.1516024087844,315.7058709310013,1.6271169150970541
0.0021581775543878952,0.09145429085817164,327.36823821211993,315.7058709310013,1.6271169150970541
0.0021676943441635765,0.09185757151430286,327.7812745160472,315.7058709310013,1.6271169150970541
0.0021740388706806973,0.09212642528505702,328.0562392293324,315.7058709310013,1.6271169150970541
0.002179477036266801,0.09235687137427485,328.2916742807377,315.7058709310013,1.6271169150970541
0.00218310247999087,0.09251050210042008,328.4485037135155,315.7058709310013,1.6271169150970541
0.0021903533674390084,0.09281776355271054,328.7618581918253,315.7058709310013,1.6271169150970541
0.0021957915330251122,0.09304820964192839,328.99660863052924,315.7058709310013,1.6271169150970541
0.0021976042548871462,0.093125025005001,329.07480837536605,315.7058709310013,1.6271169150970541
0.00220304242047325,0.09335547109421885,329.30925680982693,315.7058709310013,1.6271169150970541
0.0022211696390935956,0.094123624724945,330.0891266077619,315.7058709310013,1.6271169150970541
0.0022433754819035185,0.09506461292258452,331.0410925313036,315.7058709310013,1.6271169150970541
0.0022542518130757258,0.0955255051010202,331.50602019362356,315.7058709310013,1.6271169150970541
0.002257877256799795,0.09567913582716543,331.6608015642745,315.7058709310013,1.6271169150970541
0.002260596339592847,0.09579435887177436,331.7768239920732,315.7058709310013,1.6271169150970541
0.00226965994890302,0.09617843568713744,332.1631729436851,315.7058709310013,1.6271169150970541
0.0022719258512305628,0.0962744548909782,332.25966610752926,315.7058709310013,1.6271169150970541
0.0022796299191442096,0.0966009201840368,332.5874624862583,315.7058709310013,1.6271169150970541
0.0022891467089198913,0.09700420084016805,332.9917915502708,315.7058709310013,1.6271169150970541
0.0023099930103332882,0.0978875775155031,333.8751810421437,315.7058709310013,1.6271169150970541
0.0023167907173159176,0.09817563512702542,334.1625698973129,315.7058709310013,1.6271169150970541
0.0023258543266260904,0.09855971194238848,334.5452440014286,315.7058709310013,1.6271169150970541
0.0023276670484881253,0.0986365273054611,334.62170898429855,315.7058709310013,1.6271169150970541
0.002331292492212194,0.09879015803160633,334.77456931364264,315.7058709310013,1.6271169150970541
0.0023394497405913495,0.0991358271654331,335.1181664930787,315.7058709310013,1.6271169150970541
0.002346247447573979,0.09942388477695539,335.40414069892427,315.7058709310013,1.6271169150970541
0.0023485133499015222,0.09951990398079616,335.4993936033177,315.7058709310013,1.6271169150970541