File: datasets/aisi_316_L/data/M1/train_82.csv
Time(s),Strain(%),Stress(MPa),Temp(C),Log_SR(s-1)
0.0,0.0,0.0,308.51955488336114,3.0075394722186974
1.729709599243276e-08,1.76e-05,3.114459425,308.51955488336114,3.0075394722186974
2.6731875624668806e-08,2.7199999999999997e-05,4.813255474999999,308.51955488336114,3.0075394722186974
3.931158180098354e-08,3.9999999999999996e-05,7.078316875,308.51955488336114,3.0075394722186974
7.311954214982938e-08,7.439999999999999e-05,13.1656693875,308.51955488336114,3.0075394722186974
8.255432178206544e-08,8.4e-05,14.8644654375,308.51955488336114,3.0075394722186974
9.434779632236051e-08,9.6e-05,16.9879605,308.51955488336114,3.0075394722186974
1.0299634431857688e-07,0.0001048,18.5451902125,308.51955488336114,3.0075394722186974
1.210796719470293e-07,0.00012319999999999999,21.801215974999998,308.51955488336114,3.0075394722186974
1.328731464873244e-07,0.0001352,23.9247110375,308.51955488336114,3.0075394722186974
1.5252893738781616e-07,0.0001552,27.463869475,308.51955488336114,3.0075394722186974
1.5724632720393417e-07,0.00015999999999999999,28.3132675,308.51955488336114,3.0075394722186974
1.6117748538403254e-07,0.000164,29.0210991875,308.51955488336114,3.0075394722186974
1.7847458137646528e-07,0.0001816,32.1355586125,308.51955488336114,3.0075394722186974
2.1149631008929145e-07,0.0002152,38.0813447875,308.51955488336114,3.0075394722186974
2.1699993154142916e-07,0.0002208,39.07230915,308.51955488336114,3.0075394722186974
2.2879340608172422e-07,0.0002328,41.1958042125,308.51955488336114,3.0075394722186974
2.3665572244192093e-07,0.0002408,42.6114675875,308.51955488336114,3.0075394722186974
2.539528184343537e-07,0.0002584,45.7259270125,308.51955488336114,3.0075394722186974
2.7046368279076674e-07,0.00027519999999999997,48.69882009999999,308.51955488336114,3.0075394722186974
2.9247816859931753e-07,0.00029759999999999997,52.66267755,308.51955488336114,3.0075394722186974
2.987680216874749e-07,0.00030399999999999996,53.795208249999995,308.51955488336114,3.0075394722186974
3.160651176799077e-07,0.0003216,56.909667675,308.51955488336114,3.0075394722186974
3.27072360584183e-07,0.00033279999999999996,58.89159639999999,308.51955488336114,3.0075394722186974
3.459419198486552e-07,0.000352,62.2891885,308.51955488336114,3.0075394722186974
3.624527842050682e-07,0.00036879999999999997,65.26208158749999,308.51955488336114,3.0075394722186974
3.72673795473324e-07,0.0003792,67.102443975,308.51955488336114,3.0075394722186974
4.339998630828583e-07,0.0004416,78.1446183,308.51955488336114,3.0075394722186974
4.450071059871337e-07,0.0004528,80.126547025,308.51955488336114,3.0075394722186974
4.5208319071131073e-07,0.00045999999999999996,81.40064406249999,308.51955488336114,3.0075394722186974
4.827462245160779e-07,0.0004912,86.921731225,308.51955488336114,3.0075394722186974
4.87463614332196e-07,0.000496,87.77112925,308.51955488336114,3.0075394722186974
5.11050563412786e-07,0.00052,92.018119375,308.51955488336114,3.0075394722186974
5.228440379530811e-07,0.000532,94.14161443750001,308.51955488336114,3.0075394722186974
5.291338910412385e-07,0.0005384,95.2741451375,308.51955488336114,3.0075394722186974
5.322788175853171e-07,0.0005415999999999999,95.8404104875,308.51955488336114,3.0075394722186974
5.527208401218287e-07,0.0005624,99.5211352625,308.51955488336114,3.0075394722186974
5.645143146621236e-07,0.0005744,101.644630325,308.51955488336114,3.0075394722186974
5.865288004706745e-07,0.0005968,105.608487775,308.51955488336114,3.0075394722186974
6.101157495512647e-07,0.0006208,109.8554779,308.51955488336114,3.0075394722186974
6.447099415361301e-07,0.000656,116.08439675,308.51955488336114,3.0075394722186974
6.557171844404055e-07,0.0006672,118.06632547499999,308.51955488336114,3.0075394722186974
6.910976080612906e-07,0.0007032,124.4368106625,308.51955488336114,3.0075394722186974
7.154707887779004e-07,0.0007279999999999999,128.82536712499999,308.51955488336114,3.0075394722186974
7.343403480423725e-07,0.0007472,132.22295922499998,308.51955488336114,3.0075394722186974
7.422026644025692e-07,0.0007551999999999999,133.6386226,308.51955488336114,3.0075394722186974
7.587135287589824e-07,0.000772,136.6115156875,308.51955488336114,3.0075394722186974
7.752243931153954e-07,0.0007888,139.58440877499999,308.51955488336114,3.0075394722186974
8.02742500376084e-07,0.0008168,144.53923058750001,308.51955488336114,3.0075394722186974
8.168946698244379e-07,0.0008311999999999999,147.08742466249998,308.51955488336114,3.0075394722186974
8.294743760007527e-07,0.0008439999999999999,149.3524860625,308.51955488336114,3.0075394722186974
8.326193025448314e-07,0.0008472,149.9187514125,308.51955488336114,3.0075394722186974
8.373366923609495e-07,0.000852,150.7681494375,308.51955488336114,3.0075394722186974
8.467714719931855e-07,0.0008615999999999999,152.46694548749997,308.51955488336114,3.0075394722186974
8.522750934453232e-07,0.0008671999999999999,153.45790985,308.51955488336114,3.0075394722186974
8.601374098055199e-07,0.0008751999999999999,154.87357322499997,308.51955488336114,3.0075394722186974
8.687859578017362e-07,0.0008839999999999999,156.43080293749998,308.51955488336114,3.0075394722186974
8.845105905221297e-07,0.0009,159.2621296875,308.51955488336114,3.0075394722186974
9.049526130586411e-07,0.0009207999999999999,162.94285446249998,308.51955488336114,3.0075394722186974
9.246084039591329e-07,0.0009408,166.4820129,308.51955488336114,3.0075394722186974
9.371881101354476e-07,0.0009536,168.7470743,308.51955488336114,3.0075394722186974
9.513402795838018e-07,0.000968,171.295268375,308.51955488336114,3.0075394722186974
9.772859235724507e-07,0.0009943999999999999,175.9669575125,308.51955488336114,3.0075394722186974
9.969417144729426e-07,0.0010144,179.50611594999998,308.51955488336114,3.0075394722186974
1.0087351890132377e-06,0.0010264,181.6296110125,308.51955488336114,3.0075394722186974
1.0110938839212967e-06,0.0010287999999999999,182.05431002499998,308.51955488336114,3.0075394722186974
1.0315359064578082e-06,0.0010496,185.7350348,308.51955488336114,3.0075394722186974
1.0802822678910278e-06,0.0010992,191.6532226293897,308.51955488336114,3.0075394722186974
1.1117315333318146e-06,0.0011312,191.84372815442995,308.51955488336114,3.0075394722186974
1.1313873242323065e-06,0.0011512,191.96172734210032,308.51955488336114,3.0075394722186974
1.143967030408621e-06,0.0011639999999999999,192.03682742967004,308.51955488336114,3.0075394722186974
1.1628365896730932e-06,0.0011832,192.1488764622913,308.51955488336114,3.0075394722186974
1.173057600941349e-06,0.0011936,192.20927351639156,308.51955488336114,3.0075394722186974
1.2115829511063129e-06,0.0012328,192.43510254643104,308.51955488336114,3.0075394722186974
1.229666278734765e-06,0.0012511999999999998,192.54013648478798,308.51955488336114,3.0075394722186974
1.2508945329072962e-06,0.0012728,192.66267160267805,308.51955488336114,3.0075394722186974
1.3051445157926537e-06,0.001328,192.972188125667,308.51955488336114,3.0075394722186974
1.316151758696929e-06,0.0013392,193.03437172152348,308.51955488336114,3.0075394722186974
1.3216553801490667e-06,0.0013448,193.06538743764813,308.51955488336114,3.0075394722186974
1.3358075495974208e-06,0.0013591999999999999,193.14491172604718,308.51955488336114,3.0075394722186974
1.3546771088618928e-06,0.0013784,193.25043485408943,308.51955488336114,3.0075394722186974
1.3743328997623846e-06,0.0013984,193.35974700294696,308.51955488336114,3.0075394722186974
1.4167894081074468e-06,0.0014416,193.59380175807198,308.51955488336114,3.0075394722186974
1.4285828826477419e-06,0.0014536,193.6583294412803,308.51955488336114,3.0075394722186974
1.4608183797245483e-06,0.0014864,193.8336537211317,308.51955488336114,3.0075394722186974
1.4671082328127058e-06,0.0014927999999999999,193.86768670929519,308.51955488336114,3.0075394722186974
1.488336486985237e-06,0.0015144,193.98213024542466,308.51955488336114,3.0075394722186974
1.5056335829776697e-06,0.001532,194.07491056644272,308.51955488336114,3.0075394722186974
1.5150683626099058e-06,0.0015416,194.1253427700746,308.51955488336114,3.0075394722186974
1.544945164778653e-06,0.0015719999999999998,194.28424266856538,308.51955488336114,3.0075394722186974
1.5551661760469088e-06,0.0015823999999999999,194.33832744297533,308.51955488336114,3.0075394722186974
1.569318345495263e-06,0.0015968,194.4129857487871,308.51955488336114,3.0075394722186974
1.5756081985834203e-06,0.0016032,194.4460828862818,308.51955488336114,3.0075394722186974
1.5874016731237154e-06,0.0016152,194.5080014649559,308.51955488336114,3.0075394722186974
1.6062712323881874e-06,0.0016343999999999998,194.60669932351084,308.51955488336114,3.0075394722186974
1.6149197803844038e-06,0.0016431999999999998,194.65178461988188,308.51955488336114,3.0075394722186974
1.6259270232886793e-06,0.0016543999999999999,194.70902994945368,308.51955488336114,3.0075394722186974
1.6416516560090726e-06,0.0016703999999999998,194.7905475017982,308.51955488336114,3.0075394722186974
1.652658898913348e-06,0.0016816,194.84742869415504,308.51955488336114,3.0075394722186974
1.6589487520015053e-06,0.0016879999999999998,194.8798658938111,308.51955488336114,3.0075394722186974
1.674673384721899e-06,0.001704,194.9607497543064,308.51955488336114,3.0075394722186974
1.6856806276261741e-06,0.0017151999999999998,195.01719231147715,308.51955488336114,3.0075394722186974
1.6990465654385087e-06,0.0017288,195.08553683015657,308.51955488336114,3.0075394722186974
1.7116262716148233e-06,0.0017415999999999998,195.1496697893901,308.51955488336114,3.0075394722186974
1.7226335145190987e-06,0.0017527999999999999,195.20563548421742,308.51955488336114,3.0075394722186974
1.7312820625153151e-06,0.0017615999999999999,195.24951074882972,308.51955488336114,3.0075394722186974
1.7517240850518267e-06,0.0017824,195.35287751585673,308.51955488336114,3.0075394722186974
1.7611588646840628e-06,0.001792,195.40042648235584,308.51955488336114,3.0075394722186974
1.7768834974044562e-06,0.001808,195.47945458899162,308.51955488336114,3.0075394722186974
1.789463203580771e-06,0.0018208,195.54248086830404,308.51955488336114,3.0075394722186974
1.7941805933968889e-06,0.0018256,195.566071144196,308.51955488336114,3.0075394722186974
1.8067602995732036e-06,0.0018384,195.62886058451198,308.51955488336114,3.0075394722186974
1.81540884756942e-06,0.0018472,195.67192945605706,308.51955488336114,3.0075394722186974
1.8555066610064232e-06,0.001888,195.87057610081087,308.51955488336114,3.0075394722186974
1.8617965140945805e-06,0.0018943999999999999,195.90158380224503,308.51955488336114,3.0075394722186974
1.898749400987505e-06,0.001932,196.08293573364705,308.51955488336114,3.0075394722186974
1.916046496979938e-06,0.0019496,196.16735043053956,308.51955488336114,3.0075394722186974
1.930198666428292e-06,0.001964,196.23619616037882,308.51955488336114,3.0075394722186974
1.9482819940567446e-06,0.0019824,196.32387989536636,308.51955488336114,3.0075394722186974
1.952999383872862e-06,0.0019871999999999997,196.3467016408783,308.51955488336114,3.0075394722186974
1.9600754685970393e-06,0.0019944,196.38089399042937,308.51955488336114,3.0075394722186974
1.9632203951411183e-06,0.0019976,196.39607513410755,308.51955488336114,3.0075394722186974
1.9813037227695707e-06,0.002016,196.48318335587217,308.51955488336114,3.0075394722186974
2.008821830030259e-06,0.002044,196.61514676887995,308.51955488336114,3.0075394722186974
2.0190428412985147e-06,0.0020544,196.66398194890058,308.51955488336114,3.0075394722186974
2.0284776209307506e-06,0.002064,196.70897506954847,308.51955488336114,3.0075394722186974
2.03005008420279e-06,0.0020656,196.71646598108424,308.51955488336114,3.0075394722186974
2.0386986321990068e-06,0.0020744,196.75762561573566,308.51955488336114,3.0075394722186974
2.073292824183872e-06,0.0021096,196.92158771947376,308.51955488336114,3.0075394722186974
2.098452236536501e-06,0.0021352,197.04016346571885,308.51955488336114,3.0075394722186974
2.1055283212606788e-06,0.0021424,197.07341282919546,308.51955488336114,3.0075394722186974
2.111031942712816e-06,0.0021479999999999997,197.09924332562568,308.51955488336114,3.0075394722186974
2.1527022194218587e-06,0.0021904,197.29397197816613,308.51955488336114,3.0075394722186974
2.199089885947019e-06,0.0022375999999999997,197.5090243729908,308.51955488336114,3.0075394722186974
2.2407601626560617e-06,0.00228,197.70070317030317,308.51955488336114,3.0075394722186974
2.2674920382807305e-06,0.0023071999999999997,197.82293532989326,308.51955488336114,3.0075394722186974
2.2769268179129668e-06,0.0023168,197.86594174524765,308.51955488336114,3.0075394722186974
2.288720292453262e-06,0.0023288,197.91960215634586,308.51955488336114,3.0075394722186974
2.306803620081714e-06,0.0023472,198.00167248439197,308.51955488336114,3.0075394722186974
2.3185970946220093e-06,0.0023592,198.05506146763426,308.51955488336114,3.0075394722186974
2.337466653886481e-06,0.0023783999999999997,198.1402640770737,308.51955488336114,3.0075394722186974
2.3539775182428945e-06,0.0023952,198.21459655538132,308.51955488336114,3.0075394722186974
2.367343456055229e-06,0.0024088,198.27462164927687,308.51955488336114,3.0075394722186974
2.3728470775073663e-06,0.0024143999999999997,198.29929943102667,308.51955488336114,3.0075394722186974
2.4129448909443695e-06,0.0024552,198.47842572052073,308.51955488336114,3.0075394722186974
2.422379670576606e-06,0.0024648,198.52040391807878,308.51955488336114,3.0075394722186974
2.43653184002496e-06,0.0024792,198.58325185407705,308.51955488336114,3.0075394722186974
2.4483253145652548e-06,0.0024912,198.63551645597116,308.51955488336114,3.0075394722186974
2.4703398003738056e-06,0.0025136,198.73281509723407,308.51955488336114,3.0075394722186974
2.48449196982216e-06,0.002528,198.7951856993207,308.51955488336114,3.0075394722186974
2.490781822910317e-06,0.0025344,198.8228614757118,308.51955488336114,3.0075394722186974
2.517513698534986e-06,0.0025616,198.94018074331623,308.51955488336114,3.0075394722186974
2.525376014895183e-06,0.0025696,198.97459381899145,308.51955488336114,3.0075394722186974
2.538741952707517e-06,0.0025832,199.03300030727294,308.51955488336114,3.0075394722186974
2.5426731108876155e-06,0.0025872,199.05015584731441,308.51955488336114,3.0075394722186974
2.6024267152251103e-06,0.0026479999999999997,199.30965962738358,308.51955488336114,3.0075394722186974
2.612647726493366e-06,0.0026584,199.35381466823395,308.51955488336114,3.0075394722186974
2.6236549693976413e-06,0.0026696,199.40129097709314,308.51955488336114,3.0075394722186974
2.6496006133862907e-06,0.002696,199.5128931208821,308.51955488336114,3.0075394722186974
2.6676839410147434e-06,0.0027144,199.59042451898557,308.51955488336114,3.0075394722186974
2.673187562466881e-06,0.0027199999999999998,199.61398031250417,308.51955488336114,3.0075394722186974
2.6755462573749396e-06,0.0027224,199.62406986177493,308.51955488336114,3.0075394722186974
2.6818361104630973e-06,0.0027288,199.6509583817178,308.51955488336114,3.0075394722186974
2.701491901363589e-06,0.0027488,199.7348269232481,308.51955488336114,3.0075394722186974
2.7329411668043757e-06,0.0027808,199.86852326920175,308.51955488336114,3.0075394722186974
2.7423759464366116e-06,0.0027903999999999997,199.90851499370905,308.51955488336114,3.0075394722186974
2.763604200609143e-06,0.002812,199.9983007044721,308.51955488336114,3.0075394722186974
2.785618686417694e-06,0.0028344,200.09112816948075,308.51955488336114,3.0075394722186974
2.79426723441391e-06,0.0028431999999999997,200.12751777035314,308.51955488336114,3.0075394722186974
2.804488245682166e-06,0.0028536,200.17046707979458,308.51955488336114,3.0075394722186974
2.8202128784025592e-06,0.0028696,200.2364239294852,308.51955488336114,3.0075394722186974
2.8367237427589723e-06,0.0028864,200.3055244477211,308.51955488336114,3.0075394722186974
2.851662143843346e-06,0.0029016,200.3679089234304,308.51955488336114,3.0075394722186974
2.8666005449277197e-06,0.0029167999999999998,200.4301660763943,308.51955488336114,3.0075394722186974
2.8728903980158774e-06,0.0029232,200.45634174631346,308.51955488336114,3.0075394722186974
2.9106295165448214e-06,0.0029616,200.61292896995056,308.51955488336114,3.0075394722186974
2.940506318713569e-06,0.002992,200.7363329983059,308.51955488336114,3.0075394722186974
2.9538722565259032e-06,0.0030055999999999998,200.79138164929637,308.51955488336114,3.0075394722186974
2.968024425974257e-06,0.0030199999999999997,200.8495626778406,308.51955488336114,3.0075394722186974
2.981390363786592e-06,0.0030336,200.90441216230892,308.51955488336114,3.0075394722186974
2.9916113750548477e-06,0.003044,200.94629120298384,308.51955488336114,3.0075394722186974
2.9939700699629064e-06,0.0030464,200.95594766805672,308.51955488336114,3.0075394722186974
3.000259923051064e-06,0.0030528,200.9816837476383,308.51955488336114,3.0075394722186974
3.0136258608633985e-06,0.0030664,201.03630315508252,308.51955488336114,3.0075394722186974
3.0222744088596145e-06,0.0030751999999999997,201.0715947878687,308.51955488336114,3.0075394722186974
3.03406788339991e-06,0.0030872,201.11965633362615,308.51955488336114,3.0075394722186974
3.047433821212244e-06,0.0031008,201.1740380954786,308.51955488336114,3.0075394722186974
3.052937442664382e-06,0.0031064,201.19640353903057,308.51955488336114,3.0075394722186974
3.08202801319711e-06,0.003136,201.31436068782418,308.51955488336114,3.0075394722186974
3.0946077193734244e-06,0.0031487999999999998,201.36523461419063,308.51955488336114,3.0075394722186974
3.103256267369641e-06,0.0031576,201.4001636625138,308.51955488336114,3.0075394722186974
3.1056149622777e-06,0.00316,201.40968317512113,308.51955488336114,3.0075394722186974
3.1111185837298374e-06,0.0031655999999999998,201.43188441245172,308.51955488336114,3.0075394722186974
3.1370642277184867e-06,0.003192,201.53634177358384,308.51955488336114,3.0075394722186974
3.155147555346939e-06,0.0032104,201.60894622499885,308.51955488336114,3.0075394722186974
3.1685134931592735e-06,0.003224,201.66250612243462,308.51955488336114,3.0075394722186974
3.1755895778834506e-06,0.0032312,201.69082568599367,308.51955488336114,3.0075394722186974
3.1842381258796667e-06,0.00324,201.72540508641714,308.51955488336114,3.0075394722186974
3.1991765269640404e-06,0.0032551999999999998,201.78504699208483,308.51955488336114,3.0075394722186974
3.210183769868316e-06,0.0032664,201.82892418258888,308.51955488336114,3.0075394722186974
3.219618549500552e-06,0.003276,201.8664865231494,308.51955488336114,3.0075394722186974
3.233770718948906e-06,0.0032903999999999997,201.92274964356932,308.51955488336114,3.0075394722186974
3.2510678149413386e-06,0.0033079999999999997,201.99138543919872,308.51955488336114,3.0075394722186974
3.2683649109337716e-06,0.0033255999999999997,202.0598789644793,308.51955488336114,3.0075394722186974
3.280158385474067e-06,0.0033376,202.10649806146048,308.51955488336114,3.0075394722186974
3.2927380916503816e-06,0.0033504,202.15615310476656,308.51955488336114,3.0075394722186974
3.2950967865584404e-06,0.0033528,202.16545518309744,308.51955488336114,3.0075394722186974
3.2998141763745583e-06,0.0033575999999999996,202.1840515528532,308.51955488336114,3.0075394722186974
3.310821419278834e-06,0.0033688,202.2274028080995,308.51955488336114,3.0075394722186974
3.317111272366991e-06,0.0033751999999999996,202.25214971674097,308.51955488336114,3.0075394722186974
3.3336221367234047e-06,0.003392,202.31702343698115,308.51955488336114,3.0075394722186974
3.3501330010798177e-06,0.0034088,202.38177196723456,308.51955488336114,3.0075394722186974
3.3650714021641914e-06,0.003424,202.44024681238545,308.51955488336114,3.0075394722186974
3.369788791980309e-06,0.0034287999999999996,202.45869150870024,308.51955488336114,3.0075394722186974
3.376864876704486e-06,0.003436,202.48633968293345,308.51955488336114,3.0075394722186974
3.393375741060899e-06,0.0034528,202.55076436961528,308.51955488336114,3.0075394722186974
3.398879362513037e-06,0.0034584,202.57221208301874,308.51955488336114,3.0075394722186974
3.4035967523291553e-06,0.0034632,202.59058505940507,308.51955488336114,3.0075394722186974
3.4303286279538237e-06,0.0034904,202.69451161033814,308.51955488336114,3.0075394722186974
3.4586329668505318e-06,0.0035191999999999997,202.80420781022022,308.51955488336114,3.0075394722186974
3.468067746482768e-06,0.0035288,202.8406953348686,308.51955488336114,3.0075394722186974
3.4971583170154957e-06,0.0035583999999999998,202.95295559950847,308.51955488336114,3.0075394722186974
3.5034481701036534e-06,0.0035648,202.97718013713674,308.51955488336114,3.0075394722186974
3.5215314977321057e-06,0.0035832,203.04673138168667,308.51955488336114,3.0075394722186974
3.5293938140923023e-06,0.0035911999999999997,203.07692759271163,308.51955488336114,3.0075394722186974
3.53489743554444e-06,0.0035968,203.09804933302996,308.51955488336114,3.0075394722186974
3.542759751904637e-06,0.0036048,203.12820101348683,308.51955488336114,3.0075394722186974
3.551408299900853e-06,0.0036136,203.16133773645018,308.51955488336114,3.0075394722186974
3.6009408929700922e-06,0.0036639999999999997,203.3505179983042,308.51955488336114,3.0075394722186974
3.6127343675103877e-06,0.003676,203.3954110038818,308.51955488336114,3.0075394722186974
3.618237988962525e-06,0.0036815999999999997,203.41634151032454,308.51955488336114,3.0075394722186974
3.623741610414663e-06,0.0036872,203.43725960404154,308.51955488336114,3.0075394722186974
3.6410387064070954e-06,0.0037048,203.50292166671358,308.51955488336114,3.0075394722186974
3.661480728943607e-06,0.0037256,203.58036564983502,308.51955488336114,3.0075394722186974
3.6677705820317642e-06,0.0037319999999999996,203.60416061943278,308.51955488336114,3.0075394722186974
3.6772053616640006e-06,0.0037416,203.63982325626966,308.51955488336114,3.0075394722186974
3.7015785423806106e-06,0.0037664,203.7317869572691,308.51955488336114,3.0075394722186974
3.7432488190896527e-06,0.0038087999999999998,203.88847006618644,308.51955488336114,3.0075394722186974
3.751897367085869e-06,0.0038176,203.9209037951336,308.51955488336114,3.0075394722186974
3.764477073262184e-06,0.0038304,203.96802812652274,308.51955488336114,3.0075394722186974
3.785705327434715e-06,0.003852,204.0474114100966,308.51955488336114,3.0075394722186974
3.788850253978794e-06,0.0038552,204.05915711524366,308.51955488336114,3.0075394722186974
3.806933581607246e-06,0.0038735999999999996,204.12662127771253,308.51955488336114,3.0075394722186974
3.831306762323856e-06,0.0038983999999999998,204.21735382134864,308.51955488336114,3.0075394722186974
3.841527773592112e-06,0.0039088,204.2553359267591,308.51955488336114,3.0075394722186974
3.850176321588329e-06,0.0039176,204.28744385773655,308.51955488336114,3.0075394722186974
3.864328491036682e-06,0.003932,204.33992350212807,308.51955488336114,3.0075394722186974
3.880839355393095e-06,0.0039488,204.40105511235797,308.51955488336114,3.0075394722186974
3.905998767745724e-06,0.0039743999999999995,204.4940133600381,308.51955488336114,3.0075394722186974
3.931158180098354e-06,0.004,204.5867383805526,308.51955488336114,3.0075394722186974
4.195384855135971e-06,0.004268853770754151,205.54696281341143,308.51955488336114,3.0075394722186974
4.384118194448555e-06,0.004460892178435687,206.21844617602827,308.51955488336114,3.0075394722186974
4.535104865898622e-06,0.0046145229045809165,206.74754913406287,308.51955488336114,3.0075394722186974
4.761584873073722e-06,0.00484496899379876,207.52849869202652,308.51955488336114,3.0075394722186974
4.874824876661272e-06,0.004960192038407682,207.91353015129255,308.51955488336114,3.0075394722186974
5.271164889217698e-06,0.005363472694538908,209.2344938338818,308.51955488336114,3.0075394722186974
5.629758233911606e-06,0.005728345669133827,210.39661630098038,308.51955488336114,3.0075394722186974
6.063844914330548e-06,0.00617003400680136,211.76544333682594,308.51955488336114,3.0075394722186974
6.705538267993332e-06,0.006822964592918584,213.72085555743323,308.51955488336114,3.0075394722186974
6.818778271580883e-06,0.006938187637527506,214.05820929084058,308.51955488336114,3.0075394722186974
8.064418311043933e-06,0.008205641128225645,217.63533711097932,308.51955488336114,3.0075394722186974
8.234278316425258e-06,0.008378475695139028,218.10585229867667,308.51955488336114,3.0075394722186974
8.309771652150292e-06,0.008455291058211642,218.31375349592392,308.51955488336114,3.0075394722186974
8.706111664706718e-06,0.008858571714342869,219.39338072538834,308.51955488336114,3.0075394722186974
9.159071679056918e-06,0.009319463892778556,220.60403475627763,308.51955488336114,3.0075394722186974
1.038583838458871e-05,0.01056771354270854,223.7709141561167,308.51955488336114,3.0075394722186974
1.0593445057832554e-05,0.010778955791158232,224.29206647070646,308.51955488336114,3.0075394722186974
1.085767173287017e-05,0.011047809561912383,224.94962591898152,308.51955488336114,3.0075394722186974
1.108415174004527e-05,0.011278255651130227,225.50829619325228,308.51955488336114,3.0075394722186974
1.1574858422257988e-05,0.011777555511102222,226.70369904076688,308.51955488336114,3.0075394722186974
1.1801338429433087e-05,0.012008001600320064,227.2487406051689,308.51955488336114,3.0075394722186974
1.1857958431226861e-05,0.012065613122624524,227.3843617047596,308.51955488336114,3.0075394722186974
1.2159931774126995e-05,0.012372874574914983,228.10345309519315,308.51955488336114,3.0075394722186974
1.2273171777714546e-05,0.012488097619523904,228.37131251402784,308.51955488336114,3.0075394722186974
1.2895991797446072e-05,0.013121824364872975,229.82766212320442,308.51955488336114,3.0075394722186974
1.3160218472483688e-05,0.013390678135627125,230.4371894487004,308.51955488336114,3.0075394722186974
1.4273745174427931e-05,0.01452370474094819,232.95516004429746,308.51955488336114,3.0075394722186974
1.4575718517328065e-05,0.014830966193238648,233.62463919816244,308.51955488336114,3.0075394722186974
1.5009805197747008e-05,0.015272654530906182,234.5776149902961,308.51955488336114,3.0075394722186974
1.5387271876372178e-05,0.015656731346269256,235.39758530876952,308.51955488336114,3.0075394722186974
1.625544523721006e-05,0.01654010802160432,237.254308254583,308.51955488336114,3.0075394722186974
1.6519671912247675e-05,0.01680896179235847,237.81166700554482,308.51955488336114,3.0075394722186974
1.6651785249766483e-05,0.016943388677735545,238.0890417945684,308.51955488336114,3.0075394722186974
1.7425591940948078e-05,0.017730746149229846,239.69675576897524,308.51955488336114,3.0075394722186974
1.761432528026066e-05,0.017922784556911382,240.0846274187052,308.51955488336114,3.0075394722186974
1.806728529461086e-05,0.01838367673534707,241.0089652476547,308.51955488336114,3.0075394722186974
1.8312638635717216e-05,0.018633326665333065,241.5058727309428,308.51955488336114,3.0075394722186974
1.840700530537351e-05,0.018729345869173835,241.69629878159319,308.51955488336114,3.0075394722186974
1.923743199834888e-05,0.019574314862972595,243.35594284039982,308.51955488336114,3.0075394722186974
1.9426165337661463e-05,0.01976635327065413,243.72920980130345,308.51955488336114,3.0075394722186974
2.0105605359186764e-05,0.020457691538307662,245.06141629283536,308.51955488336114,3.0075394722186974
2.0860538716437098e-05,0.021225845169033808,246.5212185501074,308.51955488336114,3.0075394722186974
2.1294625396856036e-05,0.02166753350670134,247.35127320194198,308.51955488336114,3.0075394722186974
2.15399787379624e-05,0.02191718343668734,247.81751497439154,308.51955488336114,3.0075394722186974
2.17664587451375e-05,0.022147629525905183,248.24605693987212,308.51955488336114,3.0075394722186974
2.1955192084450084e-05,0.02233966793358672,248.60184844358108,308.51955488336114,3.0075394722186974
2.2464772100594055e-05,0.022858171634326865,249.55657702835228,308.51955488336114,3.0075394722186974
2.2521392102387834e-05,0.022915783156631328,249.66213402323552,308.51955488336114,3.0075394722186974
2.2710125441700417e-05,0.023107821564312864,250.01324558297665,308.51955488336114,3.0075394722186974
2.3144212122119356e-05,0.023549509901980396,250.81651176662422,308.51955488336114,3.0075394722186974
2.3295198793569425e-05,0.023703140628125625,251.09452859515636,308.51955488336114,3.0075394722186974
2.3389565463225715e-05,0.023799159831966392,251.26793228924456,308.51955488336114,3.0075394722186974
2.3634918804332074e-05,0.02404880976195239,251.71750976163574,308.51955488336114,3.0075394722186974
2.3785905475782143e-05,0.02420244048809762,251.9932682775756,308.51955488336114,3.0075394722186974
2.3936892147232208e-05,0.02435607121424285,252.26834495978673,308.51955488336114,3.0075394722186974
2.4238865490132342e-05,0.024663332666533307,252.8164766170632,308.51955488336114,3.0075394722186974
2.4918305511657643e-05,0.02535467093418684,254.0401277331454,308.51955488336114,3.0075394722186974
2.5163658852764e-05,0.025604320864172834,254.478794832092,308.51955488336114,3.0075394722186974
2.5333518858145328e-05,0.02577715543108622,254.78151076434037,308.51955488336114,3.0075394722186974
2.5446758861732876e-05,0.02589237847569514,254.98288173542915,308.51955488336114,3.0075394722186974
2.552225219745791e-05,0.025969193838767755,255.11693492553667,308.51955488336114,3.0075394722186974
2.5710985536770495e-05,0.02616123224644929,255.4513931088114,308.51955488336114,3.0075394722186974
2.6088452215395662e-05,0.026545309061812364,256.1174507397663,308.51955488336114,3.0075394722186974
2.6730145569058445e-05,0.027198239647929588,257.2411868259147,308.51955488336114,3.0075394722186974
2.712648558161487e-05,0.027601520304060812,257.93000505991114,308.51955488336114,3.0075394722186974
2.7560572262033815e-05,0.028043208641728348,258.6799369591033,308.51955488336114,3.0075394722186974
2.780592560314017e-05,0.028292858571714343,259.1017735696693,308.51955488336114,3.0075394722186974
2.8164518947834076e-05,0.02865773154630926,259.7157020678229,308.51955488336114,3.0075394722186974
2.8711845631840573e-05,0.029214642928585718,260.6469058153121,308.51955488336114,3.0075394722186974
2.9315792317640838e-05,0.029829165833166634,261.6664431118639,308.51955488336114,3.0075394722186974
3.035382568386005e-05,0.030885377075415082,263.39983712430507,308.51955488336114,3.0075394722186974
3.076903903034774e-05,0.031307861572314466,264.0867023745417,308.51955488336114,3.0075394722186974
3.142960571794178e-05,0.031979995999199845,265.1720388718862,308.51955488336114,3.0075394722186974
3.169383239297939e-05,0.03224884976995399,265.6036780613923,308.51955488336114,3.0075394722186974
3.1958059068017006e-05,0.03251770354070814,266.03391609149577,308.51955488336114,3.0075394722186974
3.229777907877966e-05,0.03286337267453491,266.5850462636808,308.51955488336114,3.0075394722186974
3.2958345766373695e-05,0.03353550710142028,267.65025878496715,308.51955488336114,3.0075394722186974
3.3600039120036485e-05,0.03418843768753751,268.6770921671972,308.51955488336114,3.0075394722186974
3.388313912900536e-05,0.034476495299059814,269.12767245744146,308.51955488336114,3.0075394722186974
3.416623913797423e-05,0.034764552910582114,269.57678689042376,308.51955488336114,3.0075394722186974
3.4430465813011855e-05,0.03503340668133627,269.99465270711136,308.51955488336114,3.0075394722186974
3.52231458381247e-05,0.03583996799359872,271.2408099604364,308.51955488336114,3.0075394722186974
3.550624584709359e-05,0.03612802560512103,271.6832092436244,308.51955488336114,3.0075394722186974
3.635554587400021e-05,0.03699219843968794,273.00222582643977,308.51955488336114,3.0075394722186974
3.671413921869412e-05,0.037357071414282864,273.5555294583294,308.51955488336114,3.0075394722186974
3.743132590808193e-05,0.03808681736347269,274.6558539330837,308.51955488336114,3.0075394722186974
3.78087925867071e-05,0.03847089417883577,275.2316678888494,308.51955488336114,3.0075394722186974
3.794090592422591e-05,0.03860532106421284,275.432672537667,308.51955488336114,3.0075394722186974
3.833724593678233e-05,0.039008601720344066,276.03405503995634,308.51955488336114,3.0075394722186974
3.8563725943957436e-05,0.03923904780956192,276.3766134783394,308.51955488336114,3.0075394722186974
3.911105262796392e-05,0.03979595919183837,277.2012398770719,308.51955488336114,3.0075394722186974
3.9469645972657836e-05,0.04016083216643329,277.73907321608874,308.51955488336114,3.0075394722186974
3.9847112651282996e-05,0.04054490898179636,278.3031588608163,308.51955488336114,3.0075394722186974
4.022457932990817e-05,0.04092898579715944,278.8651643434495,308.51955488336114,3.0075394722186974
4.0451059337083264e-05,0.04115943188637727,279.2013804474994,308.51955488336114,3.0075394722186974
4.071528601212089e-05,0.04142828565713143,279.59270609423237,308.51955488336114,3.0075394722186974
4.0847399349639685e-05,0.0415627125425085,279.7879974176965,308.51955488336114,3.0075394722186974
4.111162602467731e-05,0.04183156631326265,280.17784262021,308.51955488336114,3.0075394722186974
4.124373936219611e-05,0.04196599319863972,280.37239869580424,308.51955488336114,3.0075394722186974
4.154571270509624e-05,0.04227325465093018,280.816187915471,308.51955488336114,3.0075394722186974
4.2338392730209105e-05,0.043079815963192644,281.97518999995435,308.51955488336114,3.0075394722186974
4.2715859408834265e-05,0.04346389277855571,282.5241185427983,308.51955488336114,3.0075394722186974
4.2942339416009374e-05,0.04369433886777356,282.8525676845526,308.51955488336114,3.0075394722186974
4.326318609284076e-05,0.044020804160832164,283.31671652665324,308.51955488336114,3.0075394722186974
4.3489666100015867e-05,0.044251250250050014,283.6435430868823,308.51955488336114,3.0075394722186974
4.394262611436606e-05,0.0447121424284857,284.2952116405841,308.51955488336114,3.0075394722186974
4.4395586128716266e-05,0.04517303460692139,284.94426561547175,308.51955488336114,3.0075394722186974
4.501840614844778e-05,0.04580676135227045,285.83251353909225,308.51955488336114,3.0075394722186974
4.524488615562289e-05,0.0460372074414883,286.154322870903,308.51955488336114,3.0075394722186974
4.5490239496729245e-05,0.046286857371474296,286.50224152333476,308.51955488336114,3.0075394722186974
4.630179285577336e-05,0.047112622524504905,287.64787072551627,308.51955488336114,3.0075394722186974
4.6528272862948456e-05,0.04734306861372274,287.9661800785493,308.51955488336114,3.0075394722186974
4.6962359543367405e-05,0.047784756951390284,288.5745890658954,308.51955488336114,3.0075394722186974
4.739644622378634e-05,0.04822644528905781,289.1808087213641,308.51955488336114,3.0075394722186974
4.769841956668647e-05,0.04853370674134827,289.6012502611697,308.51955488336114,3.0075394722186974
4.820799958283045e-05,0.04905221044208842,290.30839900643537,308.51955488336114,3.0075394722186974
4.835898625428052e-05,0.04920584116823365,290.51736393180784,308.51955488336114,3.0075394722186974
4.86798329311119e-05,0.04953230646129225,290.9605714318145,308.51955488336114,3.0075394722186974
4.909504627759959e-05,0.049954790958191636,291.5324466050323,308.51955488336114,3.0075394722186974
4.928377961691217e-05,0.05014682936587317,291.79176600233717,308.51955488336114,3.0075394722186974
4.9698992963399856e-05,0.05056931386277255,292.3609092902874,308.51955488336114,3.0075394722186974
5.0189699645612574e-05,0.051068613722744544,293.03114787123076,308.51955488336114,3.0075394722186974
5.0321812983131385e-05,0.05120304060812163,293.2111594493226,308.51955488336114,3.0075394722186974
5.052941965637523e-05,0.05141428285657132,293.49366284743917,308.51955488336114,3.0075394722186974
5.085026633320662e-05,0.05174074814962992,293.92937025545075,308.51955488336114,3.0075394722186974
5.107674634038172e-05,0.05197119423884777,294.23628313311707,308.51955488336114,3.0075394722186974
5.122773301183179e-05,0.052124824964993,294.4405969118405,308.51955488336114,3.0075394722186974
5.1473086352938146e-05,0.052374474894979,294.7721066182482,308.51955488336114,3.0075394722186974
5.186942636549457e-05,0.05277775555111022,295.3063234312638,308.51955488336114,3.0075394722186974
5.200153970301337e-05,0.05291218243648729,295.4840416181014,308.51955488336114,3.0075394722186974
5.213365304053219e-05,0.05304660932186438,295.66158380506226,308.51955488336114,3.0075394722186974
5.2360133047707285e-05,0.053277055411082214,295.9655341536882,308.51955488336114,3.0075394722186974
5.264323305667617e-05,0.05356511302260453,296.3447520151429,308.51955488336114,3.0075394722186974
5.322830640854517e-05,0.054160432086417284,297.12595787099167,308.51955488336114,3.0075394722186974
5.366239308896411e-05,0.05460212042408481,297.7033999276748,308.51955488336114,3.0075394722186974
5.4134226437245575e-05,0.05508221644328866,298.32899202225815,308.51955488336114,3.0075394722186974
5.436070644442066e-05,0.055312662532506496,298.62852057373993,308.51955488336114,3.0075394722186974
5.445507311407697e-05,0.055408681736347276,298.75318045199276,308.51955488336114,3.0075394722186974
5.456831311766451e-05,0.05552390478095619,298.90266115080215,308.51955488336114,3.0075394722186974
5.4813666458770866e-05,0.05577355471094218,299.22612160558657,308.51955488336114,3.0075394722186974
5.581395315712757e-05,0.05679135827165434,300.5390431747667,308.51955488336114,3.0075394722186974
5.6115926500027706e-05,0.057098619723944796,300.9335893255738,308.51955488336114,3.0075394722186974
5.6380153175065316e-05,0.05736747349469894,301.2781384634912,308.51955488336114,3.0075394722186974
5.734269320555949e-05,0.058346869373874774,302.52799127864995,308.51955488336114,3.0075394722186974
5.751255321094082e-05,0.05851970394078816,302.74770150188243,308.51955488336114,3.0075394722186974
5.779565321990969e-05,0.05880776155231046,303.1133236600476,308.51955488336114,3.0075394722186974
5.830523323605367e-05,0.05932626525305061,303.76968827213545,308.51955488336114,3.0075394722186974
5.864495324681632e-05,0.05967193438687737,304.2060221911669,308.51955488336114,3.0075394722186974
5.879593991826638e-05,0.0598255651130226,304.39963184300007,308.51955488336114,3.0075394722186974
5.900354659151022e-05,0.060036807361472294,304.6655288071983,308.51955488336114,3.0075394722186974
5.921115326475407e-05,0.060248049609921986,304.9310611481903,308.51955488336114,3.0075394722186974
5.928664660047909e-05,0.060324864972994593,305.0275283080052,308.51955488336114,3.0075394722186974
5.972073328089805e-05,0.060766553310662136,305.58128761239465,308.51955488336114,3.0075394722186974
6.002270662379818e-05,0.061073814762952594,305.9655859929421,308.51955488336114,3.0075394722186974
6.0645526643529695e-05,0.061707541508301655,306.7558282149183,308.51955488336114,3.0075394722186974
6.075876664711725e-05,0.06182276455291058,306.8991679190659,308.51955488336114,3.0075394722186974
6.107961332394865e-05,0.0621492298459692,307.304732374261,308.51955488336114,3.0075394722186974
6.149482667043633e-05,0.06257171434286858,307.828349280091,308.51955488336114,3.0075394722186974
6.170243334368017e-05,0.06278295659131826,308.08964054082617,308.51955488336114,3.0075394722186974
6.206102668837407e-05,0.06314782956591318,308.5401556644982,308.51955488336114,3.0075394722186974
6.251398670272428e-05,0.06360872174434887,309.1077789325233,308.51955488336114,3.0075394722186974
6.315568005638706e-05,0.06426165233046609,309.9091737992091,308.51955488336114,3.0075394722186974
6.347652673321846e-05,0.0645881176235247,310.30867992395264,308.51955488336114,3.0075394722186974
6.36841334064623e-05,0.0647993598719744,310.5667642945718,308.51955488336114,3.0075394722186974
6.396723341543117e-05,0.0650874174834967,310.91816935870565,308.51955488336114,3.0075394722186974
6.415596675474376e-05,0.06527945589117824,311.1521024978963,308.51955488336114,3.0075394722186974
6.443906676371264e-05,0.06556751350270054,311.5024996031493,308.51955488336114,3.0075394722186974
6.462780010302522e-05,0.06575955191038207,311.73576419547726,308.51955488336114,3.0075394722186974
6.51751267870317e-05,0.06631646329265853,312.41073384221704,308.51955488336114,3.0075394722186974
6.642076682649476e-05,0.06758391678335668,313.9386848758379,308.51955488336114,3.0075394722186974
6.674161350332615e-05,0.06791038207641528,314.33043292428533,308.51955488336114,3.0075394722186974
6.710020684802005e-05,0.0682752550510102,314.76740085387183,308.51955488336114,3.0075394722186974
6.777964686954537e-05,0.06896659331866374,315.5928505836182,308.51955488336114,3.0075394722186974
6.817598688210179e-05,0.06936987397479497,316.0728726627653,308.51955488336114,3.0075394722186974
6.836472022141437e-05,0.0695619123824765,316.30107197662767,308.51955488336114,3.0075394722186974
6.893092023935213e-05,0.07013802760552111,316.9842002926786,308.51955488336114,3.0075394722186974
6.934613358583981e-05,0.0705605121024205,317.48377102332347,308.51955488336114,3.0075394722186974
7.055402695744035e-05,0.07178955791158233,318.9304770577008,308.51955488336114,3.0075394722186974
7.085600030034048e-05,0.07209681936387279,319.29064029236685,308.51955488336114,3.0075394722186974
7.10258603057218e-05,0.07226965393078616,319.4929690343672,308.51955488336114,3.0075394722186974
7.149769365400327e-05,0.07274974994999,320.0540055706732,308.51955488336114,3.0075394722186974
7.189403366655969e-05,0.07315303060612123,320.52416125777967,308.51955488336114,3.0075394722186974
7.221488034339106e-05,0.07347949589917983,320.90402354864307,308.51955488336114,3.0075394722186974
7.232812034697863e-05,0.07359471894378876,321.03793536952486,308.51955488336114,3.0075394722186974
7.263009368987876e-05,0.07390198039607922,321.3946344142433,308.51955488336114,3.0075394722186974
7.272446035953504e-05,0.07399799959991998,321.5059841900499,308.51955488336114,3.0075394722186974
7.302643370243519e-05,0.07430526105221044,321.86192539740586,308.51955488336114,3.0075394722186974
7.357376038644167e-05,0.0748621724344869,322.5056091824998,308.51955488336114,3.0075394722186974
7.3743620391823e-05,0.07503500700140028,322.704993044031,308.51955488336114,3.0075394722186974
7.404559373472314e-05,0.07534226845369074,323.0590115580668,308.51955488336114,3.0075394722186974
7.447968041514208e-05,0.07578395679135827,323.566928298067,308.51955488336114,3.0075394722186974
7.46495404205234e-05,0.07595679135827166,323.76536389647646,308.51955488336114,3.0075394722186974
7.491376709556103e-05,0.07622564512902581,324.07369183646364,308.51955488336114,3.0075394722186974
7.514024710273612e-05,0.07645609121824365,324.33763551267987,308.51955488336114,3.0075394722186974
7.531010710811744e-05,0.07662892578515704,324.53538970658747,308.51955488336114,3.0075394722186974
7.685772049048063e-05,0.07820364072814563,326.32920821351405,308.51955488336114,3.0075394722186974
7.734842717269334e-05,0.07870294058811762,326.89503119643405,308.51955488336114,3.0075394722186974
7.780138718704354e-05,0.07916383276655331,327.4160880126702,308.51955488336114,3.0075394722186974
7.83675872049813e-05,0.07973994798959792,328.0657482877562,308.51955488336114,3.0075394722186974
7.85940672121564e-05,0.07997039407881577,328.32509953042046,308.51955488336114,3.0075394722186974
7.931125390154421e-05,0.0807001400280056,329.1444621830895,308.51955488336114,3.0075394722186974
7.997182058913826e-05,0.08137227445489098,329.8965855134632,308.51955488336114,3.0075394722186974
8.080224728211364e-05,0.08221724344868975,330.83868329275947,308.51955488336114,3.0075394722186974
8.144394063577641e-05,0.08287017403480697,331.56408399570216,308.51955488336114,3.0075394722186974
8.227436732875177e-05,0.08371514302860572,332.49953760794773,308.51955488336114,3.0075394722186974
8.25763406716519e-05,0.08402240448089618,332.83878865183823,308.51955488336114,3.0075394722186974
8.297268068420833e-05,0.0844256851370274,333.2833222958026,308.51955488336114,3.0075394722186974
8.316141402352092e-05,0.08461772354470895,333.49471384790667,308.51955488336114,3.0075394722186974
8.353888070214608e-05,0.08500180036007202,333.91693648151755,308.51955488336114,3.0075394722186974
8.370874070752741e-05,0.0851746349269854,334.1066938575493,308.51955488336114,3.0075394722186974
8.393522071470251e-05,0.08540508101620324,334.35947025953425,308.51955488336114,3.0075394722186974
8.397296738256503e-05,0.08544348869773956,334.40157378509144,308.51955488336114,3.0075394722186974
8.470902740588411e-05,0.08619243848769755,335.22112301592233,308.51955488336114,3.0075394722186974
8.546396076313445e-05,0.08696059211842369,336.05880643017883,308.51955488336114,3.0075394722186974
8.56149474345845e-05,0.08711422284456892,336.22599627363144,308.51955488336114,3.0075394722186974
8.629438745610981e-05,0.08780556111222244,336.97693209410403,308.51955488336114,3.0075394722186974
8.66152341329412e-05,0.08813202640528106,337.3307388168932,308.51955488336114,3.0075394722186974
8.689833414191007e-05,0.08842008401680336,337.6424969688378,308.51955488336114,3.0075394722186974
8.699270081156635e-05,0.08851610322064413,337.7463282966224,308.51955488336114,3.0075394722186974
8.763439416522915e-05,0.08916903380676136,338.4512200152425,308.51955488336114,3.0075394722186974
8.791749417419803e-05,0.08945709141828366,338.76156141231536,308.51955488336114,3.0075394722186974
8.850256752606704e-05,0.09005241048209642,339.40170133653794,308.51955488336114,3.0075394722186974
8.889890753862346e-05,0.09045569113822766,339.83440708926014,308.51955488336114,3.0075394722186974
8.920088088152361e-05,0.09076295259051811,340.1635828629139,308.51955488336114,3.0075394722186974
8.925750088331737e-05,0.09082056411282256,340.22525490724195,308.51955488336114,3.0075394722186974
8.952172755835498e-05,0.09108941788357672,340.51285628709815,308.51955488336114,3.0075394722186974
9.082398759961181e-05,0.09241448289657932,341.9255120988847,308.51955488336114,3.0075394722186974
9.095610093713063e-05,0.0925489097819564,342.068382247493,308.51955488336114,3.0075394722186974
9.110708760858069e-05,0.09270254050810163,342.2315633543097,308.51955488336114,3.0075394722186974
9.114483427644321e-05,0.09274094818963793,342.2723421474611,308.51955488336114,3.0075394722186974
9.14656809532746e-05,0.09306741348269654,342.6186963682508,308.51955488336114,3.0075394722186974
9.17299076283122e-05,0.09333626725345069,342.9035736125919,308.51955488336114,3.0075394722186974
9.188089429976228e-05,0.09348989797959592,343.0662169216677,308.51955488336114,3.0075394722186974
9.212624764086863e-05,0.09373954790958192,343.33029016157343,308.51955488336114,3.0075394722186974
9.225836097838745e-05,0.093873974794959,343.4723698308015,308.51955488336114,3.0075394722186974
9.254146098735633e-05,0.0941620324064813,343.77655934836696,308.51955488336114,3.0075394722186974
9.265470099094388e-05,0.09427725545109022,343.89813351154584,308.51955488336114,3.0075394722186974
9.339076101426294e-05,0.09502620524104821,344.68695780368625,308.51955488336114,3.0075394722186974
9.459865438586348e-05,0.09625525105021004,345.9762046147804,308.51955488336114,3.0075394722186974
9.501386773235116e-05,0.09667773554710943,346.41789834036405,308.51955488336114,3.0075394722186974
9.537246107704508e-05,0.09704260852170435,346.79875564611393,308.51955488336114,3.0075394722186974
9.552344774849514e-05,0.09719623924784958,346.9589494913796,308.51955488336114,3.0075394722186974
9.588204109318906e-05,0.0975611122224445,347.33901461991303,308.51955488336114,3.0075394722186974
9.616514110215792e-05,0.0978491698339668,347.63867459897,308.51955488336114,3.0075394722186974
9.633500110753926e-05,0.09802200440088019,347.8183054492107,308.51955488336114,3.0075394722186974
9.671246778616442e-05,0.09840608121624325,348.2170434609115,308.51955488336114,3.0075394722186974
9.71276811326521e-05,0.09882856571314264,348.65495491131065,308.51955488336114,3.0075394722186974
9.716542780051461e-05,0.09886697339467894,348.6947288050333,308.51955488336114,3.0075394722186974
9.795810782562747e-05,0.09967353470694139,349.52859365761526,308.51955488336114,3.0075394722186974
9.818458783280257e-05,0.09990398079615924,349.7663568705189,308.51955488336114,3.0075394722186974
9.822233450066509e-05,0.09994238847769554,349.80596326837343,308.51955488336114,3.0075394722186974