File: datasets/aisi_316_L/data/M1/train_43.csv
Time(s),Strain(%),Stress(MPa),Temp(C),Log_SR(s-1)
0.0,0.0,0.0,74.89707862407282,3.314234627611908
5.8203167260509534e-09,1.2e-05,2.3318319375,74.89707862407282,3.314234627611908
1.552084460280254e-08,3.2e-05,6.2182185,74.89707862407282,3.314234627611908
2.1341161328853495e-08,4.4e-05,8.5500504375,74.89707862407282,3.314234627611908
2.2893245789133746e-08,4.7199999999999995e-05,9.1718722875,74.89707862407282,3.314234627611908
3.0265646975464954e-08,6.24e-05,12.125526075,74.89707862407282,3.314234627611908
3.6085963701515904e-08,7.439999999999999e-05,14.457358012499999,74.89707862407282,3.314234627611908
3.802606927686622e-08,7.84e-05,15.234635325,74.89707862407282,3.314234627611908
6.130733618107003e-08,0.00012639999999999998,24.561963074999998,74.89707862407282,3.314234627611908
6.984380071261144e-08,0.000144,27.98198325,74.89707862407282,3.314234627611908
7.566411743866238e-08,0.000156,30.313815187499998,74.89707862407282,3.314234627611908
7.993234970443308e-08,0.0001648,32.023825275,74.89707862407282,3.314234627611908
8.846881423597448e-08,0.0001824,35.44384545,74.89707862407282,3.314234627611908
1.0243757437849676e-07,0.00021119999999999998,41.04024209999999,74.89707862407282,3.314234627611908
1.1252612337031843e-07,0.000232,45.082084125,74.89707862407282,3.314234627611908
1.2183863013199994e-07,0.0002512,48.813015224999994,74.89707862407282,3.314234627611908
1.3037509466354134e-07,0.0002688,52.23303539999999,74.89707862407282,3.314234627611908
1.381355169649426e-07,0.0002848,55.342144649999994,74.89707862407282,3.314234627611908
1.478360448416942e-07,0.0003048,59.228531212499995,74.89707862407282,3.314234627611908
1.6607303724998717e-07,0.0003424,66.53493795,74.89707862407282,3.314234627611908
1.722813750911082e-07,0.00035519999999999996,69.02222535,74.89707862407282,3.314234627611908
1.8081783962264963e-07,0.0003728,72.442245525,74.89707862407282,3.314234627611908
1.8663815634870056e-07,0.0003848,74.77407746249999,74.89707862407282,3.314234627611908
1.9090638861447124e-07,0.00039359999999999997,76.48408755,74.89707862407282,3.314234627611908
1.936225364199617e-07,0.0003992,77.5722757875,74.89707862407282,3.314234627611908
2.033230642967133e-07,0.0004192,81.45866235,74.89707862407282,3.314234627611908
2.1729182443923559e-07,0.000448,87.055059,74.89707862407282,3.314234627611908
2.211720355899362e-07,0.00045599999999999997,88.609613625,74.89707862407282,3.314234627611908
2.223360989351464e-07,0.0004584,89.0759800125,74.89707862407282,3.314234627611908
2.2311214116528652e-07,0.00045999999999999996,89.3868909375,74.89707862407282,3.314234627611908
2.297085001214776e-07,0.00047359999999999997,92.0296338,74.89707862407282,3.314234627611908
2.5260174591061135e-07,0.0005208,101.2015060875,74.89707862407282,3.314234627611908
2.638543582476432e-07,0.000544,105.7097145,74.89707862407282,3.314234627611908
2.6657050605313366e-07,0.0005496,106.79790273750001,74.89707862407282,3.314234627611908
2.7083873831890434e-07,0.0005584,108.507912825,74.89707862407282,3.314234627611908
2.805392661956559e-07,0.0005784,112.3942993875,74.89707862407282,3.314234627611908
2.93343962992968e-07,0.0006048,117.52432964999998,74.89707862407282,3.314234627611908
2.9722417414366866e-07,0.0006127999999999999,119.078884275,74.89707862407282,3.314234627611908
3.0032834306422915e-07,0.0006192,120.322527975,74.89707862407282,3.314234627611908
3.073127231354903e-07,0.0006336,123.1207263,74.89707862407282,3.314234627611908
3.216695043930827e-07,0.0006632,128.8725784125,74.89707862407282,3.314234627611908
3.2826586334927376e-07,0.0006768,131.515321275,74.89707862407282,3.314234627611908
3.364143067657451e-07,0.0006935999999999999,134.7798859875,74.89707862407282,3.314234627611908
3.4650285575756675e-07,0.0007144,138.82172801250002,74.89707862407282,3.314234627611908
3.5387525694389793e-07,0.0007296,141.7753818,74.89707862407282,3.314234627611908
3.6124765813022916e-07,0.0007448,144.7290355875,74.89707862407282,3.314234627611908
3.6978412266177053e-07,0.0007624,148.1490557625,74.89707862407282,3.314234627611908
3.756044393878215e-07,0.0007744,150.48088769999998,74.89707862407282,3.314234627611908
3.8258881945908264e-07,0.0007888,153.279086025,74.89707862407282,3.314234627611908
3.872450728399234e-07,0.0007984,155.144551575,74.89707862407282,3.314234627611908
3.903492417604839e-07,0.0008047999999999999,156.388195275,74.89707862407282,3.314234627611908
3.9539351625639475e-07,0.0008152,158.40911628749998,74.89707862407282,3.314234627611908
4.1246644531947754e-07,0.0008504,165.2491566375,74.89707862407282,3.314234627611908
4.1479457200989794e-07,0.0008552,166.1818894125,74.89707862407282,3.314234627611908
4.186747831605985e-07,0.0008632,167.73644403749998,74.89707862407282,3.314234627611908
4.2604718434692975e-07,0.0008784,170.690097825,74.89707862407282,3.314234627611908
4.3419562776340107e-07,0.0008952,173.95466253749998,74.89707862407282,3.314234627611908
4.609690847032355e-07,0.0009504,184.68108945,74.89707862407282,3.314234627611908
4.667894014292864e-07,0.0009624,187.0129213875,74.89707862407282,3.314234627611908
4.7028159146491696e-07,0.0009695999999999999,188.41202055,74.89707862407282,3.314234627611908
4.7260971815533735e-07,0.0009743999999999999,189.344753325,74.89707862407282,3.314234627611908
4.834743093772992e-07,0.0009968,193.697506275,74.89707862407282,3.314234627611908
4.94726921714331e-07,0.0010199999999999999,198.20571468749998,74.89707862407282,3.314234627611908
5.020993229006622e-07,0.0010352,201.159368475,74.89707862407282,3.314234627611908
5.141279774678342e-07,0.00106,205.9784878125,74.89707862407282,3.314234627611908
5.242165264596559e-07,0.0010808,210.02032983750001,74.89707862407282,3.314234627611908
5.277087164952864e-07,0.001088,211.419429,74.89707862407282,3.314234627611908
5.335290332213373e-07,0.0010999999999999998,213.75126093749998,74.89707862407282,3.314234627611908
5.459457089035794e-07,0.0011256,218.7258357375,74.89707862407282,3.314234627611908
5.486618567090699e-07,0.0011312,219.814023975,74.89707862407282,3.314234627611908
5.509899833994901e-07,0.0011359999999999999,220.74675674999997,74.89707862407282,3.314234627611908
5.571983212406112e-07,0.0011488,223.23404415,74.89707862407282,3.314234627611908
5.719431236132737e-07,0.0011792,229.14135172500002,74.89707862407282,3.314234627611908
5.831957359503055e-07,0.0012024,233.6495601375,74.89707862407282,3.314234627611908
5.909561582517068e-07,0.0012184,236.7586693875,74.89707862407282,3.314234627611908
6.002686650133882e-07,0.0012376,240.48960048749998,74.89707862407282,3.314234627611908
6.068650239695793e-07,0.0012511999999999998,243.13234334999996,74.89707862407282,3.314234627611908
6.138494040408406e-07,0.0012656,245.930541675,74.89707862407282,3.314234627611908
6.188936785367514e-07,0.001276,247.9514626875,74.89707862407282,3.314234627611908
6.309223331039233e-07,0.0013008,252.77058202499998,74.89707862407282,3.314234627611908
6.328624386792735e-07,0.0013047999999999998,253.54785933749997,74.89707862407282,3.314234627611908
6.394587976354647e-07,0.0013184,256.1906022,74.89707862407282,3.314234627611908
6.421749454409551e-07,0.0013239999999999999,257.2787904375,74.89707862407282,3.314234627611908
6.503233888574264e-07,0.0013407999999999998,260.54335514999997,74.89707862407282,3.314234627611908
6.59635895619108e-07,0.0013599999999999999,264.27428625,74.89707862407282,3.314234627611908
6.739926768767003e-07,0.0013896,270.0261383625,74.89707862407282,3.314234627611908
6.763208035671207e-07,0.0013943999999999998,270.95887113749995,74.89707862407282,3.314234627611908
6.856333103288022e-07,0.0014135999999999999,274.6898022375,74.89707862407282,3.314234627611908
6.96109880435694e-07,0.0014352,278.887099725,74.89707862407282,3.314234627611908
6.992140493562545e-07,0.0014416,280.130743425,74.89707862407282,3.314234627611908
7.190031262248278e-07,0.0014824,285.3308194461892,74.89707862407282,3.314234627611908
7.252114640659488e-07,0.0014952,285.4310473939119,74.89707862407282,3.314234627611908
7.283156329865092e-07,0.0015015999999999999,285.4810358413342,74.89707862407282,3.314234627611908
7.345239708276302e-07,0.0015144,285.5807641552758,74.89707862407282,3.314234627611908
7.442244987043818e-07,0.0015344,285.73593403413827,74.89707862407282,3.314234627611908
7.469406465098723e-07,0.00154,285.77923999051876,74.89707862407282,3.314234627611908
7.484927309701526e-07,0.0015432,285.80395867650157,74.89707862407282,3.314234627611908
7.581932588469041e-07,0.0015631999999999998,285.95800000900937,74.89707862407282,3.314234627611908
7.632375333428149e-07,0.0015735999999999999,286.0377976272604,74.89707862407282,3.314234627611908
7.791463990606876e-07,0.0016064,286.2881302580044,74.89707862407282,3.314234627611908
7.88070884707299e-07,0.0016248,286.4276877703916,74.89707862407282,3.314234627611908
7.896229691675792e-07,0.0016279999999999999,286.45189558959675,74.89707862407282,3.314234627611908
7.935031803182798e-07,0.0016359999999999999,286.5123340908158,74.89707862407282,3.314234627611908
8.008755815046112e-07,0.0016512,286.62685064160394,74.89707862407282,3.314234627611908
8.039797504251717e-07,0.0016576,286.6749450559826,74.89707862407282,3.314234627611908
8.086360038060124e-07,0.0016672,286.74695111247814,74.89707862407282,3.314234627611908
8.210526794882544e-07,0.0016928,286.93818107801303,74.89707862407282,3.314234627611908
8.319172707102162e-07,0.0017151999999999998,287.1045839803155,74.89707862407282,3.314234627611908
8.36961545206127e-07,0.0017255999999999999,287.1815541673798,74.89707862407282,3.314234627611908
8.423938408171079e-07,0.0017368,287.26424308969314,74.89707862407282,3.314234627611908
8.493782208883691e-07,0.0017511999999999998,287.3702524849258,74.89707862407282,3.314234627611908
8.583027065349805e-07,0.0017695999999999999,287.5052155049718,74.89707862407282,3.314234627611908
8.637350021459614e-07,0.0017808,287.58709898538484,74.89707862407282,3.314234627611908
8.703313611021524e-07,0.0017943999999999998,287.68625940701384,74.89707862407282,3.314234627611908
8.773157411734137e-07,0.0018088,287.790933854394,74.89707862407282,3.314234627611908
8.827480367843946e-07,0.00182,287.87212278768646,74.89707862407282,3.314234627611908
8.963287758118467e-07,0.0018479999999999998,288.074247261417,74.89707862407282,3.314234627611908
9.052532614584582e-07,0.0018663999999999998,288.2064219287859,74.89707862407282,3.314234627611908
9.075813881488786e-07,0.0018712,288.2408185769135,74.89707862407282,3.314234627611908
9.118496204146493e-07,0.00188,288.3037898573505,74.89707862407282,3.314234627611908
9.184459793708403e-07,0.0018935999999999998,288.40088346834284,74.89707862407282,3.314234627611908
9.265944227873117e-07,0.0019103999999999998,288.52044797346247,74.89707862407282,3.314234627611908
9.425032885051844e-07,0.0019432,288.75270813366694,74.89707862407282,3.314234627611908
9.59188196453197e-07,0.0019776,288.9946613257112,74.89707862407282,3.314234627611908
9.673366398696683e-07,0.0019944,289.11222750429516,74.89707862407282,3.314234627611908
9.937220756944326e-07,0.0020488,289.4902948668947,74.89707862407282,3.314234627611908
9.987663501903435e-07,0.0020591999999999997,289.5621245156845,74.89707862407282,3.314234627611908
1.0061387513766748e-06,0.0020744,289.66685233133626,74.89707862407282,3.314234627611908
1.0138991736780761e-06,0.0020904,289.7767693308883,74.89707862407282,3.314234627611908
1.019719490404127e-06,0.0021024,289.8589918866532,74.89707862407282,3.314234627611908
1.0286439760507384e-06,0.0021208,289.9847118791842,74.89707862407282,3.314234627611908
1.0333002294315792e-06,0.0021303999999999997,290.050136009079,74.89707862407282,3.314234627611908
1.03873252504256e-06,0.0021416,290.1263190193085,74.89707862407282,3.314234627611908
1.0398965883877703e-06,0.002144,290.14262371654644,74.89707862407282,3.314234627611908
1.044552841768611e-06,0.0021536,290.2077714504974,74.89707862407282,3.314234627611908
1.0461049262288913e-06,0.0021568,290.2294621804701,74.89707862407282,3.314234627611908
1.051149200724802e-06,0.0021671999999999998,290.2998705311115,74.89707862407282,3.314234627611908
1.075594530974216e-06,0.0022175999999999997,290.63923105753327,74.89707862407282,3.314234627611908
1.0903393333468787e-06,0.002248,290.8424706401786,74.89707862407282,3.314234627611908
1.0973237134181397e-06,0.0022624,290.9383676445755,74.89707862407282,3.314234627611908
1.1019799667989803e-06,0.0022719999999999997,291.0021667659213,74.89707862407282,3.314234627611908
1.1070242412948912e-06,0.0022824,291.0711639567464,74.89707862407282,3.314234627611908
1.1124565369058721e-06,0.0022936,291.14533164342015,74.89707862407282,3.314234627611908
1.1163367480565728e-06,0.0023016,291.1982221107778,74.89707862407282,3.314234627611908
1.123709149242904e-06,0.0023168,291.29851689132016,74.89707862407282,3.314234627611908
1.1427221838813371e-06,0.002356,291.5559946647918,74.89707862407282,3.314234627611908
1.1504826061827383e-06,0.002372,291.66060684212925,74.89707862407282,3.314234627611908
1.1605711551745602e-06,0.0023928,291.7961921653722,74.89707862407282,3.314234627611908
1.165615429670471e-06,0.0024032,291.8638123991024,74.89707862407282,3.314234627611908
1.1687195985910315e-06,0.0024096,291.9053681292569,74.89707862407282,3.314234627611908
1.1714357463965217e-06,0.0024151999999999997,291.941694094965,74.89707862407282,3.314234627611908
1.1768680420075028e-06,0.0024264,292.01424763058355,74.89707862407282,3.314234627611908
1.1834644009636937e-06,0.00244,292.1021729983008,74.89707862407282,3.314234627611908
1.184628464308904e-06,0.0024424,292.117669378523,74.89707862407282,3.314234627611908
1.1927769077253753e-06,0.0024592,292.2259782413924,74.89707862407282,3.314234627611908
1.1943289921856555e-06,0.0024624,292.2465757434221,74.89707862407282,3.314234627611908
1.197821182221286e-06,0.0024695999999999997,292.29288199270053,74.89707862407282,3.314234627611908
1.2106258790185982e-06,0.002496,292.46222297792445,74.89707862407282,3.314234627611908
1.2315790192323816e-06,0.0025391999999999997,292.73782736985055,74.89707862407282,3.314234627611908
1.2428316315694135e-06,0.0025624,292.8850821225231,74.89707862407282,3.314234627611908
1.2439956949146238e-06,0.0025648,292.90028563627425,74.89707862407282,3.314234627611908
1.252144138331095e-06,0.0025816,293.0065553086545,74.89707862407282,3.314234627611908
1.2575764339420758e-06,0.0025927999999999997,293.0772519576765,74.89707862407282,3.314234627611908
1.2602925817475664e-06,0.0025984,293.1125556124517,74.89707862407282,3.314234627611908
1.265724877358547e-06,0.0026095999999999997,293.1830740279559,74.89707862407282,3.314234627611908
1.2680530040489676e-06,0.0026144,293.21326006194175,74.89707862407282,3.314234627611908
1.2808577008462797e-06,0.0026408,293.37889850203385,74.89707862407282,3.314234627611908
1.294826460988802e-06,0.0026696,293.55886018335906,74.89707862407282,3.314234627611908
1.299870735484713e-06,0.00268,293.6236600628809,74.89707862407282,3.314234627611908
1.302198862175133e-06,0.0026847999999999998,293.6535346155826,74.89707862407282,3.314234627611908
1.3161676223176556e-06,0.0027136,293.83234644752554,74.89707862407282,3.314234627611908
1.3212118968135664e-06,0.002724,293.8967352983964,74.89707862407282,3.314234627611908
1.3309124246903179e-06,0.002744,294.02029118035637,74.89707862407282,3.314234627611908
1.3421650370273498e-06,0.0027672,294.1631768567569,74.89707862407282,3.314234627611908
1.3456572270629803e-06,0.0027743999999999998,294.2074255924625,74.89707862407282,3.314234627611908
1.3658343250466237e-06,0.002816,294.4622134933101,74.89707862407282,3.314234627611908
1.3704905784274642e-06,0.0028255999999999997,294.52080173643753,74.89707862407282,3.314234627611908
1.3716546417726745e-06,0.002828,294.5354366610635,74.89707862407282,3.314234627611908
1.3832952752247766e-06,0.002852,294.6815204798072,74.89707862407282,3.314234627611908
1.3957119509070183e-06,0.0028775999999999997,294.8368157726448,74.89707862407282,3.314234627611908
1.398816119827579e-06,0.002884,294.875555292494,74.89707862407282,3.314234627611908
1.4026963309782798e-06,0.002892,294.9239325764442,74.89707862407282,3.314234627611908
1.4089046688194006e-06,0.0029048,295.00122781453223,74.89707862407282,3.314234627611908
1.4127848799701013e-06,0.0029127999999999997,295.049469889439,74.89707862407282,3.314234627611908
1.4186051966961523e-06,0.0029248,295.12173622672367,74.89707862407282,3.314234627611908
1.4255895767674134e-06,0.0029392,295.20830337388196,74.89707862407282,3.314234627611908
1.4275296823427637e-06,0.0029432,295.23232042904715,74.89707862407282,3.314234627611908
1.435678125759235e-06,0.00296,295.3330533662336,74.89707862407282,3.314234627611908
1.4383942735647255e-06,0.0029655999999999997,295.3665814300541,74.89707862407282,3.314234627611908
1.4434385480606364e-06,0.002976,295.4287823991461,74.89707862407282,3.314234627611908
1.4484828225565472e-06,0.0029863999999999997,295.4908986518738,74.89707862407282,3.314234627611908
1.4562432448579483e-06,0.0030023999999999997,295.58629763790026,74.89707862407282,3.314234627611908
1.4659437727346998e-06,0.0030223999999999997,295.705268010672,74.89707862407282,3.314234627611908
1.4674958571949802e-06,0.0030256,295.72427474113306,74.89707862407282,3.314234627611908
1.4740922161511712e-06,0.0030391999999999997,295.8049660386276,74.89707862407282,3.314234627611908
1.4857328496032732e-06,0.0030632,295.9470197577777,74.89707862407282,3.314234627611908
1.4938812930197446e-06,0.00308,296.0461992046054,74.89707862407282,3.314234627611908
1.5008656730910056e-06,0.0030943999999999998,296.13104235188933,74.89707862407282,3.314234627611908
1.509790158737617e-06,0.0031127999999999998,296.23922929543204,74.89707862407282,3.314234627611908
1.5187146443842287e-06,0.0031311999999999998,296.3471671189807,74.89707862407282,3.314234627611908
1.5295792356061905e-06,0.0031536,296.478236385327,74.89707862407282,3.314234627611908
1.538891742367872e-06,0.0031728,296.5902927475056,74.89707862407282,3.314234627611908
1.550144354704904e-06,0.003196,296.7253419609525,74.89707862407282,3.314234627611908
1.5567407136610949e-06,0.0032096,296.80433099065334,74.89707862407282,3.314234627611908
1.5738136427241776e-06,0.0032448,297.0081694182235,74.89707862407282,3.314234627611908
1.5757537482995282e-06,0.0032488,297.03127817971296,74.89707862407282,3.314234627611908
1.5831261494858592e-06,0.003264,297.118990460511,74.89707862407282,3.314234627611908
1.5959308462831713e-06,0.0032903999999999997,297.27095516781543,74.89707862407282,3.314234627611908
1.6017511630092223e-06,0.0033024,297.33987276643717,74.89707862407282,3.314234627611908
1.6040792896996426e-06,0.0033071999999999997,297.36741245093714,74.89707862407282,3.314234627611908
1.6087355430804834e-06,0.0033168,297.4224450990337,74.89707862407282,3.314234627611908
1.6320168099846871e-06,0.0033648,297.6966820046856,74.89707862407282,3.314234627611908
1.6440454645518591e-06,0.0033896,297.8377730297887,74.89707862407282,3.314234627611908
1.6471496334724195e-06,0.0033959999999999997,297.8741181919749,74.89707862407282,3.314234627611908
1.6521939079683305e-06,0.0034064,297.933122158513,74.89707862407282,3.314234627611908
1.6591782880395917e-06,0.0034208,298.01470410527065,74.89707862407282,3.314234627611908
1.661118393614942e-06,0.0034248,298.0373419738371,74.89707862407282,3.314234627611908
1.6661626681108528e-06,0.0034352,298.0961522266236,74.89707862407282,3.314234627611908
1.6735350692971838e-06,0.0034503999999999997,298.1819809203612,74.89707862407282,3.314234627611908
1.6843996605191458e-06,0.0034728,298.3081970238252,74.89707862407282,3.314234627611908
1.6871158083246363e-06,0.0034784,298.339701390856,74.89707862407282,3.314234627611908
1.6886678927849164e-06,0.0034815999999999996,298.3576950050726,74.89707862407282,3.314234627611908
1.6937121672808274e-06,0.003492,298.41612975711143,74.89707862407282,3.314234627611908
1.7026366529274388e-06,0.0035104,298.5193483225209,74.89707862407282,3.314234627611908
1.7131132230343306e-06,0.003532,298.64024909435665,74.89707862407282,3.314234627611908
1.7232017720261523e-06,0.0035528,298.7563998214979,74.89707862407282,3.314234627611908
1.7301861520974134e-06,0.0035672,298.83665655447595,74.89707862407282,3.314234627611908
1.741050743319375e-06,0.0035895999999999996,298.9612496743725,74.89707862407282,3.314234627611908
1.7422148066645852e-06,0.0035919999999999997,298.97458092812803,74.89707862407282,3.314234627611908
1.7480351233906362e-06,0.003604,299.0411851603937,74.89707862407282,3.314234627611908
1.7538554401166872e-06,0.003616,299.10770295919735,74.89707862407282,3.314234627611908
1.7565715879221777e-06,0.0036216,299.1387151314222,74.89707862407282,3.314234627611908
1.7581236723824577e-06,0.0036247999999999996,299.15642797590027,74.89707862407282,3.314234627611908
1.7627799257632987e-06,0.0036344,299.20952995486056,74.89707862407282,3.314234627611908
1.7686002424893495e-06,0.0036463999999999997,299.2758305649741,74.89707862407282,3.314234627611908
1.7697643058345597e-06,0.0036488,299.2890804697986,74.89707862407282,3.314234627611908
1.7744205592154005e-06,0.0036584,299.3420461354626,74.89707862407282,3.314234627611908
1.7790768125962413e-06,0.003668,299.3949576238123,74.89707862407282,3.314234627611908
1.7848971293222921e-06,0.0036799999999999997,299.4610210973923,74.89707862407282,3.314234627611908
1.7876132771277826e-06,0.0036856,299.491821961505,74.89707862407282,3.314234627611908
1.7992539105798846e-06,0.0037096,299.62361947184513,74.89707862407282,3.314234627611908
1.8054622484210056e-06,0.0037224,299.69377548235,74.89707862407282,3.314234627611908
1.807402353996356e-06,0.0037264,299.7156799328135,74.89707862407282,3.314234627611908
1.819819029678598e-06,0.0037519999999999997,299.8556518971808,74.89707862407282,3.314234627611908
1.827579451979999e-06,0.0037679999999999996,299.9429452600047,74.89707862407282,3.314234627611908
1.8333997687060501e-06,0.00378,300.0083204447766,74.89707862407282,3.314234627611908
1.8462044655033622e-06,0.0038063999999999997,300.1518616162169,74.89707862407282,3.314234627611908
1.8531888455746233e-06,0.0038207999999999996,300.2299931322493,74.89707862407282,3.314234627611908
1.8574570778403942e-06,0.0038296,300.2776836382301,74.89707862407282,3.314234627611908
1.8625013523363049e-06,0.0038399999999999997,300.33399007886476,74.89707862407282,3.314234627611908
1.8710378168678462e-06,0.0038575999999999997,300.42914260275757,74.89707862407282,3.314234627611908
1.874918028018547e-06,0.0038656,300.4723377651536,74.89707862407282,3.314234627611908
1.882290429204878e-06,0.0038808,300.55431264569575,74.89707862407282,3.314234627611908
1.8846185558952986e-06,0.0038856,300.58017342272603,74.89707862407282,3.314234627611908
1.8908268937364196e-06,0.0038983999999999998,300.6490746559097,74.89707862407282,3.314234627611908
1.8966472104624704e-06,0.0039104,300.7135894749725,74.89707862407282,3.314234627611908
1.9016914849583811e-06,0.0039207999999999995,300.7694398877522,74.89707862407282,3.314234627611908
1.916048266215974e-06,0.0039504,300.92808340071196,74.89707862407282,3.314234627611908
1.9265248363228652e-06,0.003972,301.043557856953,74.89707862407282,3.314234627611908
1.9680486842571436e-06,0.004057611522304461,301.49885175902097,74.89707862407282,3.314234627611908
2.014620532435187e-06,0.004153630726145229,302.0050609555092,74.89707862407282,3.314234627611908
2.1636504466049253e-06,0.004460892178435687,303.5950856264649,74.89707862407282,3.314234627611908
2.2940516215034467e-06,0.004729745949189838,304.95162040333724,74.89707862407282,3.314234627611908
2.4803390142156195e-06,0.005113822764552911,306.83845737906825,74.89707862407282,3.314234627611908
2.657312037292184e-06,0.00547869573914783,308.5803629055946,74.89707862407282,3.314234627611908
2.880856908546791e-06,0.005939587917583517,310.7172668722093,74.89707862407282,3.314234627611908
3.113716149437007e-06,0.006419683936787358,312.87548900568993,74.89707862407282,3.314234627611908
3.253431693971137e-06,0.006707741548309662,314.14020859318464,74.89707862407282,3.314234627611908
3.3652041295984407e-06,0.006938187637527506,315.1367958772587,74.89707862407282,3.314234627611908
3.4956053044969617e-06,0.007207041408281656,316.2833074342735,74.89707862407282,3.314234627611908
3.588749000853048e-06,0.007399079815963192,317.0920537032954,74.89707862407282,3.314234627611908
4.389784789515392e-06,0.009050610122024405,323.7381713444356,74.89707862407282,3.314234627611908
4.492242855507087e-06,0.009261852370474095,324.55268954476753,74.89707862407282,3.314234627611908
4.687844617854869e-06,0.009665133026605321,326.0878347676728,74.89707862407282,3.314234627611908
4.883446380202651e-06,0.010068413682736548,327.5981924023406,74.89707862407282,3.314234627611908
5.106991251457257e-06,0.010529305861172233,329.29571492214734,74.89707862407282,3.314234627611908
5.22807805672017e-06,0.010778955791158232,330.20309476769995,74.89707862407282,3.314234627611908
5.367793601254299e-06,0.011067013402680535,331.239948239589,74.89707862407282,3.314234627611908
5.768311495585471e-06,0.011892778555711142,334.1554670895083,74.89707862407282,3.314234627611908
5.9918563668400785e-06,0.012353670734146829,335.7483606689753,74.89707862407282,3.314234627611908
6.494832327162946e-06,0.013390678135627125,339.249953432791,74.89707862407282,3.314234627611908
6.532089805705381e-06,0.01346749349869974,339.5050441277053,74.89707862407282,3.314234627611908
6.8301496340448575e-06,0.014082016403280656,341.5257318905017,74.89707862407282,3.314234627611908
6.8767214822229005e-06,0.014178035607121425,341.8383305578659,74.89707862407282,3.314234627611908
6.969865178578987e-06,0.014370074014802961,342.46106190081497,74.89707862407282,3.314234627611908
7.221353158740421e-06,0.01488857771554311,344.1264330077665,74.89707862407282,3.314234627611908
7.798844076148156e-06,0.016079215843168633,347.8672704722994,74.89707862407282,3.314234627611908
7.873359033233025e-06,0.016232846569313862,348.3419634064937,74.89707862407282,3.314234627611908
7.966502729589111e-06,0.0164248849769954,348.93287284800004,74.89707862407282,3.314234627611908
8.068960795580806e-06,0.016636127225445087,349.5797698050966,74.89707862407282,3.314234627611908
8.12484701339446e-06,0.016751350270054012,349.9312721516011,74.89707862407282,3.314234627611908
8.283191297199806e-06,0.017077815563112622,350.9221111489498,74.89707862407282,3.314234627611908
8.39496373282711e-06,0.017308261652330466,351.6170840958281,74.89707862407282,3.314234627611908
8.916568432421195e-06,0.01838367673534707,354.81373658809446,74.89707862407282,3.314234627611908
8.94451154132802e-06,0.018441288257651532,354.9828974756729,74.89707862407282,3.314234627611908
9.028340868048498e-06,0.018614122824564913,355.489147833612,74.89707862407282,3.314234627611908
9.121484564404584e-06,0.01880616123224645,356.0495030128101,74.89707862407282,3.314234627611908
9.233257000031888e-06,0.019036607321464293,356.71899207730644,74.89707862407282,3.314234627611908
9.531316828371365e-06,0.01965113022604521,358.48902114138895,74.89707862407282,3.314234627611908
9.577888676549407e-06,0.019747149429885976,358.7636260048397,74.89707862407282,3.314234627611908
9.596517415820626e-06,0.019785557111422283,358.8733220819414,74.89707862407282,3.314234627611908
9.671032372905495e-06,0.019939187837567512,359.3112784606709,74.89707862407282,3.314234627611908
9.736232960354755e-06,0.02007361472294459,359.69341186401766,74.89707862407282,3.314234627611908
9.801433547804014e-06,0.020208041608321663,360.07454853850567,74.89707862407282,3.314234627611908
1.0052921527965449e-05,0.020726545309061813,361.535476890479,74.89707862407282,3.314234627611908
1.0248523290313231e-05,0.021129825965193038,362.66192201949144,74.89707862407282,3.314234627611908
1.0369610095576144e-05,0.021379475895179037,363.35504464303955,74.89707862407282,3.314234627611908
1.102161597006875e-05,0.02272374474894979,367.034344683559,74.89707862407282,3.314234627611908
1.1245160841323357e-05,0.02318463692738548,368.27614407058826,74.89707862407282,3.314234627611908
1.1291732689501399e-05,0.023280656131226245,368.5336362864128,74.89707862407282,3.314234627611908
1.1654993105290136e-05,0.024029605921184236,370.5280533057584,74.89707862407282,3.314234627611908
1.1859909237273527e-05,0.024452090418083616,371.64241053275873,74.89707862407282,3.314234627611908
1.2288370240511524e-05,0.025335467093418683,373.9484523777833,74.89707862407282,3.314234627611908
1.2586430068851001e-05,0.0259499899979996,375.5341923749066,74.89707862407282,3.314234627611908
1.3024205441724607e-05,0.026852570514102822,377.8369487795907,74.89707862407282,3.314234627611908
1.328500779152165e-05,0.027390278055611124,379.1944568960741,74.89707862407282,3.314234627611908
1.3396780227148955e-05,0.027620724144828968,379.7730599551695,74.89707862407282,3.314234627611908
1.3611010728767952e-05,0.0280624124824965,380.87681368330595,74.89707862407282,3.314234627611908
1.3881127448200602e-05,0.028619323864772953,382.258893348657,74.89707862407282,3.314234627611908
1.4095357949819602e-05,0.02906101220244049,383.34758130861564,74.89707862407282,3.314234627611908
1.4225759124718124e-05,0.02932986597319464,384.0071020114811,74.89707862407282,3.314234627611908
1.4290959712167383e-05,0.029464292858571713,384.3359778985554,74.89707862407282,3.314234627611908
1.4654220127956122e-05,0.030213242648529707,386.1576854660722,74.89707862407282,3.314234627611908
1.4672848867227338e-05,0.030251650330066014,386.25062871445044,74.89707862407282,3.314234627611908
1.4784621302854641e-05,0.030482096419283858,386.80732484176633,74.89707862407282,3.314234627611908
1.5045423652651684e-05,0.03101980396079216,388.09993814133446,74.89707862407282,3.314234627611908
1.513856734900777e-05,0.031211842368473696,388.5594641410018,74.89707862407282,3.314234627611908
1.547388465588968e-05,0.031903180636127224,390.2047052649724,74.89707862407282,3.314234627611908
1.5716058266415506e-05,0.03240248049609922,391.38429949818664,74.89707862407282,3.314234627611908
1.6200405487467158e-05,0.03340108021604321,393.72243262497324,74.89707862407282,3.314234627611908
1.6265606074916414e-05,0.03353550710142028,394.03508629100173,74.89707862407282,3.314234627611908
1.6619552121069544e-05,0.03426525305061012,395.7238962480632,74.89707862407282,3.314234627611908
1.679652514414611e-05,0.034630126025205044,396.5630367493897,74.89707862407282,3.314234627611908
1.687104010123098e-05,0.03478375675135027,396.91532667625955,74.89707862407282,3.314234627611908
1.7020070015400717e-05,0.03509101820364073,397.6180913052987,74.89707862407282,3.314234627611908
1.7085270602849976e-05,0.0352254450890178,397.92479574603834,74.89707862407282,3.314234627611908
1.7392644800825064e-05,0.035859171834366876,399.3645841850969,74.89707862407282,3.314234627611908
1.768139025952893e-05,0.036454490898179634,400.7080992208696,74.89707862407282,3.314234627611908
1.7821105804063062e-05,0.03674254850970195,401.3551129762311,74.89707862407282,3.314234627611908
1.7942192609325975e-05,0.03699219843968794,401.91425967415745,74.89707862407282,3.314234627611908
1.7988764457504017e-05,0.03708821764352871,402.12892399032035,74.89707862407282,3.314234627611908
1.830545302511471e-05,0.03774114822964593,403.58293574449755,74.89707862407282,3.314234627611908
1.8473111678555663e-05,0.03808681736347269,404.3487332915289,74.89707862407282,3.314234627611908
1.884568646398001e-05,0.03885497099419884,406.0408672171135,74.89707862407282,3.314234627611908
1.9050602595963402e-05,0.03927745549109822,406.96597798188634,74.89707862407282,3.314234627611908
1.9106488813777056e-05,0.039392678535707146,407.21760634677287,74.89707862407282,3.314234627611908
1.9171689401226315e-05,0.039527105421084216,407.5108102690779,74.89707862407282,3.314234627611908
1.9320719315396053e-05,0.039834366873374674,408.17953425312703,74.89707862407282,3.314234627611908
1.9479063599201403e-05,0.04016083216643329,408.88785304335795,74.89707862407282,3.314234627611908
1.9842324014990136e-05,0.04090978195639128,410.50438883035855,74.89707862407282,3.314234627611908
2.016832695223644e-05,0.04158191638327666,411.94532509624344,74.89707862407282,3.314234627611908
2.0224213170050095e-05,0.04169713942788558,412.19142785634347,74.89707862407282,3.314234627611908
2.0494329889482743e-05,0.042254050810162036,413.3772058008792,74.89707862407282,3.314234627611908
2.057815921620322e-05,0.04242688537707541,413.74396446923424,74.89707862407282,3.314234627611908
2.1034563328348045e-05,0.043367873574714944,415.73063213181064,74.89707862407282,3.314234627611908
2.117427887288217e-05,0.04365593118623724,416.3354254172612,74.89707862407282,3.314234627611908
2.124879382996704e-05,0.04380956191238247,416.6573453691017,74.89707862407282,3.314234627611908
2.1425766853043606e-05,0.04417443488697739,417.42014584637934,74.89707862407282,3.314234627611908
2.2105715836443038e-05,0.045576315263052614,420.32832862445616,74.89707862407282,3.314234627611908
2.2496919361138602e-05,0.04638287657531506,421.98571712095617,74.89707862407282,3.314234627611908
2.257143431822347e-05,0.04653650730146029,422.3001317516916,74.89707862407282,3.314234627611908
2.2850865407291733e-05,0.047112622524504905,423.47559863117067,74.89707862407282,3.314234627611908
2.2981266582190254e-05,0.04738147629525906,424.02223011690984,74.89707862407282,3.314234627611908
2.299989532146147e-05,0.04741988397679536,424.100221466987,74.89707862407282,3.314234627611908
2.3065095908910727e-05,0.04755431086217243,424.3729973967401,74.89707862407282,3.314234627611908
2.314892523563121e-05,0.04772714542908582,424.7232678351672,74.89707862407282,3.314234627611908
2.3437670694335074e-05,0.04832246449289858,425.9259864512782,74.89707862407282,3.314234627611908
2.3782302370852593e-05,0.04903300660132026,427.35395088589354,74.89707862407282,3.314234627611908
2.436910765789594e-05,0.05024284856971395,429.7669184109676,74.89707862407282,3.314234627611908
2.4601966898786155e-05,0.05072294458891778,430.7181517257268,74.89707862407282,3.314234627611908
2.4713739334413463e-05,0.05095339067813563,431.1734959274754,74.89707862407282,3.314234627611908
2.4872083618218803e-05,0.051279855971194235,431.81719443164286,74.89707862407282,3.314234627611908
2.498385605384611e-05,0.051510302060412086,432.2706079488206,74.89707862407282,3.314234627611908
2.5188772185829503e-05,0.05193278655731147,433.0998166993855,74.89707862407282,3.314234627611908
2.5263287142914374e-05,0.0520864172834567,433.40069434065055,74.89707862407282,3.314234627611908
2.532848773036363e-05,0.05222084416883377,433.66367847668243,74.89707862407282,3.314234627611908
2.6148152258297192e-05,0.05391078215643129,436.9475583375026,74.89707862407282,3.314234627611908
2.675358628461175e-05,0.05515903180636127,439.34742896898825,74.89707862407282,3.314234627611908
2.7126161070036097e-05,0.05592718543708741,440.81374815177867,74.89707862407282,3.314234627611908
2.725656224493462e-05,0.05619603920784157,441.3251014993039,74.89707862407282,3.314234627611908
2.7535993334002878e-05,0.05677215443088618,442.41765693327085,74.89707862407282,3.314234627611908
2.7675708878537008e-05,0.05706021204240848,442.9623125419842,74.89707862407282,3.314234627611908
2.7992397446147705e-05,0.05771314262852571,444.1929107703272,74.89707862407282,3.314234627611908
2.8150741729953048e-05,0.058039607921584316,444.8061728859844,74.89707862407282,3.314234627611908
2.8411544079750094e-05,0.058577315463092625,445.81332708474105,74.89707862407282,3.314234627611908
2.8569888363555438e-05,0.05890378075615123,446.4230546453798,74.89707862407282,3.314234627611908
2.8802747604445655e-05,0.059383876775355074,447.317324095811,74.89707862407282,3.314234627611908
2.893314877934418e-05,0.05965273054610923,447.8168832747377,74.89707862407282,3.314234627611908
2.9063549954242695e-05,0.05992158431686337,448.31556513477324,74.89707862407282,3.314234627611908
2.916600802023439e-05,0.06013282656531306,448.70677469336204,74.89707862407282,3.314234627611908
2.9212579868412433e-05,0.06022884576915383,448.88442000254327,74.89707862407282,3.314234627611908
2.9268466086226087e-05,0.06034406881376275,449.09744864423135,74.89707862407282,3.314234627611908
2.9566525914565563e-05,0.06095859171834367,450.2309333804181,74.89707862407282,3.314234627611908
2.9613097762743606e-05,0.061054610922184435,450.4076370157168,74.89707862407282,3.314234627611908
2.9790070785820173e-05,0.061419483896779356,451.0781247143996,74.89707862407282,3.314234627611908
2.9836642633998215e-05,0.06151550310062012,451.2543104327477,74.89707862407282,3.314234627611908
2.9976358178532348e-05,0.061803560712142436,451.7822251941525,74.89707862407282,3.314234627611908
3.0171959940880128e-05,0.06220684136827366,452.51969656046,74.89707862407282,3.314234627611908
3.0404819181770342e-05,0.06268693738747749,453.3952119660435,74.89707862407282,3.314234627611908
3.060042094411812e-05,0.06309021804360872,454.12862584886483,74.89707862407282,3.314234627611908
3.083328018500834e-05,0.06357031406281256,454.9993579991129,74.89707862407282,3.314234627611908
3.0926423881364425e-05,0.0637623524704941,455.3469323113662,74.89707862407282,3.314234627611908
3.139214236314485e-05,0.06472254450890177,457.07871742614,74.89707862407282,3.314234627611908
3.161568723439946e-05,0.06518343668733746,457.90641272055706,74.89707862407282,3.314234627611908
3.177403151820481e-05,0.06550990198039608,458.4913165137209,74.89707862407282,3.314234627611908
3.213729193399355e-05,0.06625885177035407,459.82887611065206,74.89707862407282,3.314234627611908
3.217454941253599e-05,0.06633566713342669,459.96572748068724,74.89707862407282,3.314234627611908
3.223974999998525e-05,0.06647009401880376,460.2050687562971,74.89707862407282,3.314234627611908
3.239809428379059e-05,0.06679655931186237,460.78554158166855,74.89707862407282,3.314234627611908
3.245398050160425e-05,0.0669117823564713,460.99015003931726,74.89707862407282,3.314234627611908
3.26123247854096e-05,0.06723824764952992,461.56912911676847,74.89707862407282,3.314234627611908
3.27240972210369e-05,0.06746869373874775,461.97716033182087,74.89707862407282,3.314234627611908
3.289175587447785e-05,0.06781436287257452,462.58818951162334,74.89707862407282,3.314234627611908
3.31618725939105e-05,0.06837127425485097,463.5700766300103,74.89707862407282,3.314234627611908
3.3245701920630985e-05,0.06854410882176436,463.8741653525484,74.89707862407282,3.314234627611908
3.34785611615212e-05,0.0690242048409682,464.71729123841254,74.89707862407282,3.314234627611908
3.368347729350459e-05,0.06944668933786757,465.45735195258476,74.89707862407282,3.314234627611908
3.373004914168263e-05,0.06954270854170834,465.6253024477015,74.89707862407282,3.314234627611908
3.394427964330163e-05,0.06998439687937588,466.39671286488584,74.89707862407282,3.314234627611908
3.3981537121844064e-05,0.07006121224244849,466.53067714586007,74.89707862407282,3.314234627611908
3.42330251020055e-05,0.07057971594318864,467.43344241608787,74.89707862407282,3.314234627611908
3.437274064653963e-05,0.07086777355471095,467.9338609599257,74.89707862407282,3.314234627611908
3.4465884342895716e-05,0.07105981196239249,468.2670326809615,74.89707862407282,3.314234627611908
3.4922288455040536e-05,0.072000800160032,469.8945254398545,74.89707862407282,3.314234627611908
3.4968860303218585e-05,0.07209681936387279,470.06012835799396,74.89707862407282,3.314234627611908
3.504337526030345e-05,0.07225045009001801,470.324914228187,74.89707862407282,3.314234627611908
3.521103391374441e-05,0.07259611922384478,470.91988090663443,74.89707862407282,3.314234627611908
3.528554887082928e-05,0.07274974994999,471.18395579113184,74.89707862407282,3.314234627611908
3.576058172224532e-05,0.07372914582916584,472.86234924119594,74.89707862407282,3.314234627611908
3.583509667933019e-05,0.07388277655531107,473.1248356296478,74.89707862407282,3.314234627611908
3.586303978823701e-05,0.07394038807761552,473.2232131349874,74.89707862407282,3.314234627611908
3.6095899029127225e-05,0.07442048409681937,474.04186636620483,74.89707862407282,3.314234627611908
3.63939588574667e-05,0.07503500700140028,475.0867432667089,74.89707862407282,3.314234627611908
3.643121633600914e-05,0.0751118223644729,475.2171178144975,74.89707862407282,3.314234627611908
3.685967733924714e-05,0.07599519903980796,476.7127068730528,74.89707862407282,3.314234627611908
3.7027335992688095e-05,0.07634086817363474,477.29608985609565,74.89707862407282,3.314234627611908
3.7139108428315396e-05,0.07657131426285257,477.6844396145691,74.89707862407282,3.314234627611908
3.734402456029879e-05,0.07699379875975196,478.39523237543847,74.89707862407282,3.314234627611908
3.74651113655617e-05,0.07724344868973795,478.8145313105216,74.89707862407282,3.314234627611908
3.7520997583375356e-05,0.07735867173434688,479.0078756074697,74.89707862407282,3.314234627611908
3.754894069228218e-05,0.07741628325665134,479.10450563661817,74.89707862407282,3.314234627611908
3.794014421697774e-05,0.07822284456891379,480.4543948741236,74.89707862407282,3.314234627611908
3.814506034896113e-05,0.07864532906581316,481.1593127044488,74.89707862407282,3.314234627611908
3.8443120177300604e-05,0.07925985197039408,482.1820170528825,74.89707862407282,3.314234627611908
3.855489261292791e-05,0.07949029805961193,482.5647333274563,74.89707862407282,3.314234627611908
3.877843748418252e-05,0.07995119023804761,483.3288702152244,74.89707862407282,3.314234627611908
3.894609613762347e-05,0.08029685937187438,483.9008459861461,74.89707862407282,3.314234627611908
3.8992667985801515e-05,0.08039287857571514,484.05955761939555,74.89707862407282,3.314234627611908
3.9216212857056124e-05,0.08085377075415083,484.82034676507686,74.89707862407282,3.314234627611908
3.9309356553412215e-05,0.08104580916183238,485.1368428497217,74.89707862407282,3.314234627611908
3.973781755665021e-05,0.08192918583716743,486.5889742676593,74.89707862407282,3.314234627611908
4.017559292952382e-05,0.08283176635327066,488.0663806785946,74.89707862407282,3.314234627611908
4.029667973478673e-05,0.08308141628325666,488.47391483181707,74.89707862407282,3.314234627611908
4.044570964895647e-05,0.08338867773554712,488.9748402930476,74.89707862407282,3.314234627611908
4.046433838822768e-05,0.08342708541708342,489.0374053223118,74.89707862407282,3.314234627611908
4.064131141130425e-05,0.08379195839167834,489.63121390293014,74.89707862407282,3.314234627611908
4.0781026955838374e-05,0.08408001600320064,490.09929811736055,74.89707862407282,3.314234627611908
4.1144287371627116e-05,0.08482896579315864,491.3133994237825,74.89707862407282,3.314234627611908
4.12374310679832e-05,0.08502100420084018,491.6240331692335,74.89707862407282,3.314234627611908
4.14516615696022e-05,0.0854626925385077,492.33745419469847,74.89707862407282,3.314234627611908
4.1488919048144635e-05,0.08553950790158033,492.4613804865271,74.89707862407282,3.314234627611908
4.1554119635593894e-05,0.0856739347869574,492.6781471120698,74.89707862407282,3.314234627611908
4.174040702830607e-05,0.08605801160232047,493.29675062800317,74.89707862407282,3.314234627611908
4.1982580638831895e-05,0.08655731146229247,494.0993278866183,74.89707862407282,3.314234627611908
4.2066409965552364e-05,0.08673014602920584,494.3767221567133,74.89707862407282,3.314234627611908
4.242967038134111e-05,0.08747909581916384,495.5762813568754,74.89707862407282,3.314234627611908
4.247624222951915e-05,0.08757511502300461,495.7297808108869,74.89707862407282,3.314234627611908
4.255075718660402e-05,0.08772874574914984,495.9752434830263,74.89707862407282,3.314234627611908
4.257870029551085e-05,0.0877863572714543,496.0672487573651,74.89707862407282,3.314234627611908
4.290470323275715e-05,0.08845849169833968,497.1389095060809,74.89707862407282,3.314234627611908
4.3146876843282976e-05,0.08895779155831167,497.93294574000527,74.89707862407282,3.314234627611908
4.339836482344441e-05,0.08947629525905182,498.75568431993975,74.89707862407282,3.314234627611908
4.3649852803605845e-05,0.08999479895979197,499.57656559765684,74.89707862407282,3.314234627611908
4.3882712044496056e-05,0.0904748949789958,500.33499774772645,74.89707862407282,3.314234627611908
4.402242758903019e-05,0.09076295259051811,500.7893036790625,74.89707862407282,3.314234627611908
4.418077187283553e-05,0.09108941788357672,501.303504503909,74.89707862407282,3.314234627611908
4.4432259852996967e-05,0.09160792158431687,502.1187016138444,74.89707862407282,3.314234627611908
4.4721005311700835e-05,0.09220324064812963,503.0524528502484,74.89707862407282,3.314234627611908
4.484209211696375e-05,0.09245289057811563,503.44332586323253,74.89707862407282,3.314234627611908
4.5047008248947136e-05,0.092875375075015,504.1038668255638,74.89707862407282,3.314234627611908
4.508426572748957e-05,0.09295219043808763,504.22383917465856,74.89707862407282,3.314234627611908
4.536369681655783e-05,0.09352830566113222,505.1224025540669,74.89707862407282,3.314234627611908
4.5428897404007096e-05,0.09366273254650931,505.3317564309268,74.89707862407282,3.314234627611908
4.5605870427083656e-05,0.09402760552110423,505.89941280638664,74.89707862407282,3.314234627611908
4.581078655906704e-05,0.0944500900180036,506.55562698593246,74.89707862407282,3.314234627611908
4.5941187733965566e-05,0.09471894378875775,506.9726218588395,74.89707862407282,3.314234627611908
4.604364579995726e-05,0.09493018603720745,507.2999369420194,74.89707862407282,3.314234627611908
4.612747512667774e-05,0.09510302060412083,507.56752896095816,74.89707862407282,3.314234627611908
4.6164732605220175e-05,0.09517983596719344,507.6863978619453,74.89707862407282,3.314234627611908
4.623924756230504e-05,0.09533346669333867,507.92402348101433,74.89707862407282,3.314234627611908
4.629513378011869e-05,0.0954486897379476,508.1021447001527,74.89707862407282,3.314234627611908
4.6341705628296735e-05,0.09554470894178836,508.25051499957374,74.89707862407282,3.314234627611908
4.646279243355965e-05,0.09579435887177436,508.6360058833932,74.89707862407282,3.314234627611908
4.681673847971278e-05,0.0965241048209642,509.7605852139768,74.89707862407282,3.314234627611908
4.704028335096739e-05,0.09698499699939989,510.4691377185342,74.89707862407282,3.314234627611908
4.7338343179306864e-05,0.0975995199039808,511.4118350080283,74.89707862407282,3.314234627611908
4.774817544327364e-05,0.09844448889777956,512.704272742695,74.89707862407282,3.314234627611908
4.7897205357443384e-05,0.09875175035007001,513.1731765197223,74.89707862407282,3.314234627611908
4.792514846635021e-05,0.09880936187237448,513.2610325964749,74.89707862407282,3.314234627611908
4.806486401088434e-05,0.09909741948389679,513.7000136705012,74.89707862407282,3.314234627611908
4.82418370339609e-05,0.0994622924584917,514.2553426139132,74.89707862407282,3.314234627611908