File: datasets/aisi_316_L/data/M1/train_1.csv
Time(s),Strain(%),Stress(MPa),Temp(C),Log_SR(s-1)
0.0,0.0,0.0,225.01149783531545,2.762595947537265
8.291732633392383e-08,4.8e-05,8.82710325,225.01149783531545,2.762595947537265
1.1055643511189843e-07,6.4e-05,11.769471,225.01149783531545,2.762595947537265
1.1884816774529081e-07,6.879999999999999e-05,12.652181324999999,225.01149783531545,2.762595947537265
1.271399003786832e-07,7.36e-05,13.53489165,225.01149783531545,2.762595947537265
1.506331428399616e-07,8.719999999999999e-05,16.0359042375,225.01149783531545,2.762595947537265
2.0591136039591083e-07,0.0001192,21.9206397375,225.01149783531545,2.762595947537265
2.487519790017715e-07,0.000144,26.48130975,225.01149783531545,2.762595947537265
2.6395348882965753e-07,0.0001528,28.0996120125,225.01149783531545,2.762595947537265
2.7915499865754356e-07,0.0001616,29.717914275,225.01149783531545,2.762595947537265
3.1232192919111307e-07,0.0001808,33.248755575000004,225.01149783531545,2.762595947537265
3.219956172634042e-07,0.0001864,34.2785842875,225.01149783531545,2.762595947537265
3.5239863691917626e-07,0.000204,37.5151888125,225.01149783531545,2.762595947537265
3.593084141136699e-07,0.000208,38.25078075,225.01149783531545,2.762595947537265
3.676001467470623e-07,0.0002128,39.133491075,225.01149783531545,2.762595947537265
4.159685871085179e-07,0.0002408,44.2826346375,225.01149783531545,2.762595947537265
4.546633393976823e-07,0.0002632,48.4019494875,225.01149783531545,2.762595947537265
4.643370274699734e-07,0.0002688,49.4317782,225.01149783531545,2.762595947537265
4.7539267098116323e-07,0.00027519999999999997,50.608725299999996,225.01149783531545,2.762595947537265
5.002678688813404e-07,0.0002896,53.256856275,225.01149783531545,2.762595947537265
5.12705467831429e-07,0.0002968,54.5809217625,225.01149783531545,2.762595947537265
5.292889330982137e-07,0.00030639999999999997,56.34634241249999,225.01149783531545,2.762595947537265
5.514002201205934e-07,0.0003192,58.7002366125,225.01149783531545,2.762595947537265
6.191160366266312e-07,0.0003584,65.90903759999999,225.01149783531545,2.762595947537265
6.398453682101122e-07,0.0003704,68.1158134125,225.01149783531545,2.762595947537265
6.495190562824033e-07,0.000376,69.145642125,225.01149783531545,2.762595947537265
6.992694520827575e-07,0.0004048,74.441904075,225.01149783531545,2.762595947537265
7.144709619106435e-07,0.00041359999999999997,76.06020633749999,225.01149783531545,2.762595947537265
7.186168282273398e-07,0.000416,76.5015615,225.01149783531545,2.762595947537265
7.37964204371922e-07,0.0004272,78.56121892499999,225.01149783531545,2.762595947537265
7.821867784166815e-07,0.0004528,83.269007325,225.01149783531545,2.762595947537265
7.987702436834662e-07,0.00046239999999999996,85.034427975,225.01149783531545,2.762595947537265
8.139717535113522e-07,0.00047119999999999996,86.6527302375,225.01149783531545,2.762595947537265
8.30555218778137e-07,0.0004808,88.41815088749999,225.01149783531545,2.762595947537265
9.065627679175671e-07,0.0005248,96.5096622,225.01149783531545,2.762595947537265
9.38347743012238e-07,0.0005432,99.8933851125,225.01149783531545,2.762595947537265
9.507853419623265e-07,0.0005503999999999999,101.21745059999999,225.01149783531545,2.762595947537265
9.756605398625037e-07,0.0005648,103.865581575,225.01149783531545,2.762595947537265
1.0212650693461617e-06,0.0005912,108.72048836249999,225.01149783531545,2.762595947537265
1.1041823956800854e-06,0.0006391999999999999,117.54759161249999,225.01149783531545,2.762595947537265
1.1608425686749334e-06,0.000672,123.57944549999999,225.01149783531545,2.762595947537265
1.1898636328918067e-06,0.0006887999999999999,126.6689316375,225.01149783531545,2.762595947537265
1.2257944743031739e-06,0.0007096,130.4940097125,225.01149783531545,2.762595947537265
1.2465238058866547e-06,0.0007216,132.700785525,225.01149783531545,2.762595947537265
1.2907463799314141e-06,0.0007472,137.40857392499998,225.01149783531545,2.762595947537265
1.3266772213427813e-06,0.000768,141.233652,225.01149783531545,2.762595947537265
1.383337394337629e-06,0.0008008,147.26550588749998,225.01149783531545,2.762595947537265
1.3930110824099203e-06,0.0008064,148.2953346,225.01149783531545,2.762595947537265
1.4068306367989075e-06,0.0008144,149.766518475,225.01149783531545,2.762595947537265
1.4676366761104516e-06,0.0008495999999999999,156.23972752499998,225.01149783531545,2.762595947537265
1.50218556208292e-06,0.0008696,159.9176872125,225.01149783531545,2.762595947537265
1.5160051164719074e-06,0.0008776,161.3888710875,225.01149783531545,2.762595947537265
1.5602276905166666e-06,0.0009031999999999999,166.09665948749998,225.01149783531545,2.762595947537265
1.594776576489135e-06,0.0009232,169.774619175,225.01149783531545,2.762595947537265
1.644526972289489e-06,0.0009519999999999999,175.070881125,225.01149783531545,2.762595947537265
1.661110437556274e-06,0.0009616,176.83630177499998,225.01149783531545,2.762595947537265
1.6694021701896662e-06,0.0009664,177.7190121,225.01149783531545,2.762595947537265
1.6873675908953497e-06,0.0009767999999999999,179.63155113749997,225.01149783531545,2.762595947537265
1.7288262540623118e-06,0.0010008,184.0451027625,225.01149783531545,2.762595947537265
1.7854864270571598e-06,0.0010336,190.07695665,225.01149783531545,2.762595947537265
1.8186533575907292e-06,0.0010528,193.60779795,225.01149783531545,2.762595947537265
1.8283270456630202e-06,0.0010584,194.6376266625,225.01149783531545,2.762595947537265
1.8614939761965898e-06,0.0010776,198.1684679625,225.01149783531545,2.762595947537265
1.8863691740967668e-06,0.0010919999999999999,200.81659893749998,225.01149783531545,2.762595947537265
1.8988067730468558e-06,0.0010992,202.140664425,225.01149783531545,2.762595947537265
1.914008282874742e-06,0.001108,203.75896668750002,225.01149783531545,2.762595947537265
1.9264458818248303e-06,0.0011152,205.083032175,225.01149783531545,2.762595947537265
1.967904544991792e-06,0.0011392,209.4965838,225.01149783531545,2.762595947537265
1.983106054819678e-06,0.001148,211.11488606249998,225.01149783531545,2.762595947537265
2.0148910299143487e-06,0.0011664,214.498608975,225.01149783531545,2.762595947537265
2.030092539742235e-06,0.0011752,215.94042802019575,225.01149783531545,2.762595947537265
2.085370757298184e-06,0.0012071999999999999,216.14913721107808,225.01149783531545,2.762595947537265
2.099190311687172e-06,0.0012152,216.20097599109505,225.01149783531545,2.762595947537265
2.142030930293032e-06,0.00124,216.36083681424606,225.01149783531545,2.762595947537265
2.1572324401209184e-06,0.0012488,216.41726126045404,225.01149783531545,2.762595947537265
2.1959271924100825e-06,0.0012711999999999999,216.56019183835375,225.01149783531545,2.762595947537265
2.204218925043475e-06,0.001276,216.59069164109718,225.01149783531545,2.762595947537265
2.2498234545271334e-06,0.0013024,216.75764750161323,225.01149783531545,2.762595947537265
2.2719347415495126e-06,0.0013151999999999999,216.83812025661842,225.01149783531545,2.762595947537265
2.3106294938386775e-06,0.0013376,216.97821643852382,225.01149783531545,2.762595947537265
2.331358825422158e-06,0.0013495999999999998,217.05289144585785,225.01149783531545,2.762595947537265
2.3534701124445377e-06,0.0013624,217.1322599341177,225.01149783531545,2.762595947537265
2.3797272657836134e-06,0.0013775999999999999,217.22613328439178,225.01149783531545,2.762595947537265
2.4115122408782843e-06,0.0013959999999999999,217.3392307045808,225.01149783531545,2.762595947537265
2.4267137507061706e-06,0.0014047999999999999,217.39311513334476,225.01149783531545,2.762595947537265
2.469554369312031e-06,0.0014295999999999998,217.5442675455414,225.01149783531545,2.762595947537265
2.4875197900177147e-06,0.0014399999999999999,217.60734930015366,225.01149783531545,2.762595947537265
2.513776943356791e-06,0.0014552,217.6992270327608,225.01149783531545,2.762595947537265
2.5510897402070564e-06,0.0014768,217.82914887673283,225.01149783531545,2.762595947537265
2.592548403374018e-06,0.0015007999999999998,217.97264036962096,225.01149783531545,2.762595947537265
2.6160416458352967e-06,0.0015144,218.05355492647178,225.01149783531545,2.762595947537265
2.66717399707455e-06,0.001544,218.228689890408,225.01149783531545,2.762595947537265
2.705868749363714e-06,0.0015664,218.3603553806058,225.01149783531545,2.762595947537265
2.7293619918249927e-06,0.00158,218.43993694080748,225.01149783531545,2.762595947537265
2.7348898135805874e-06,0.0015831999999999999,218.45862313535167,225.01149783531545,2.762595947537265
2.752855234286271e-06,0.0015936,218.5192517927132,225.01149783531545,2.762595947537265
2.765292833236359e-06,0.0016007999999999999,218.56113511384493,225.01149783531545,2.762595947537265
2.79707780833103e-06,0.0016192,218.66783785001292,225.01149783531545,2.762595947537265
2.8122793181589164e-06,0.0016279999999999999,218.71870233800612,225.01149783531545,2.762595947537265
2.8164251844756125e-06,0.0016304,218.73255584696693,225.01149783531545,2.762595947537265
2.8316266943034984e-06,0.0016392,218.78328414533564,225.01149783531545,2.762595947537265
2.8371545160590936e-06,0.0016424,218.80170445202296,225.01149783531545,2.762595947537265
2.8717034020315615e-06,0.0016623999999999999,218.9165158628334,225.01149783531545,2.762595947537265
2.902106421687334e-06,0.0016799999999999999,219.0171050300918,225.01149783531545,2.762595947537265
2.911780109759625e-06,0.0016856,219.0490243774438,225.01149783531545,2.762595947537265
2.946328995732093e-06,0.0017055999999999998,219.16268597996674,225.01149783531545,2.762595947537265
3.023718500310422e-06,0.0017503999999999998,219.41541848010067,225.01149783531545,2.762595947537265
3.036156099260511e-06,0.0017576,219.4557997214654,225.01149783531545,2.762595947537265
3.063795208038485e-06,0.0017736,219.5453055520215,225.01149783531545,2.762595947537265
3.070704985232979e-06,0.0017775999999999998,219.5676327375636,225.01149783531545,2.762595947537265
3.1038719157665482e-06,0.0017967999999999999,219.67453167136804,225.01149783531545,2.762595947537265
3.128747113666726e-06,0.0018112,219.75441376020098,225.01149783531545,2.762595947537265
3.141184712616814e-06,0.0018184,219.79426189279303,225.01149783531545,2.762595947537265
3.192317063856067e-06,0.0018479999999999998,219.9574396543226,225.01149783531545,2.762595947537265
3.2006087964894597e-06,0.0018528,219.98380456201795,225.01149783531545,2.762595947537265
3.2158103063173457e-06,0.0018616,220.0320711448324,225.01149783531545,2.762595947537265
3.2268659498285355e-06,0.0018679999999999999,220.06711824190208,225.01149783531545,2.762595947537265
3.250359192289814e-06,0.0018816,220.14143821428348,225.01149783531545,2.762595947537265
3.2724704793121937e-06,0.0018943999999999999,220.21119527742272,225.01149783531545,2.762595947537265
3.282144167384485e-06,0.0019,220.24165616408686,225.01149783531545,2.762595947537265
3.3084013207235606e-06,0.0019152,220.32415972661414,225.01149783531545,2.762595947537265
3.3346584740626363e-06,0.0019303999999999999,220.40640831258307,225.01149783531545,2.762595947537265
3.3609156274017125e-06,0.0019456,220.48840470845914,225.01149783531545,2.762595947537265
3.3692073600351047e-06,0.0019504,220.51424635303636,225.01149783531545,2.762595947537265
3.377499092668497e-06,0.0019552,220.5400632065917,225.01149783531545,2.762595947537265
3.3968464688130795e-06,0.0019664,220.60020659608298,225.01149783531545,2.762595947537265
3.4396870874189397e-06,0.0019912,220.732907849056,225.01149783531545,2.762595947537265
3.4479788200523323e-06,0.001996,220.75851734366788,225.01149783531545,2.762595947537265
3.5046389930471803e-06,0.0020288,220.93287716402446,225.01149783531545,2.762595947537265
3.536423968141851e-06,0.0020472,221.03020734615723,225.01149783531545,2.762595947537265
3.584792408503306e-06,0.0020751999999999997,221.17766643053963,225.01149783531545,2.762595947537265
3.6151954281590784e-06,0.0020927999999999997,221.2699579513034,225.01149783531545,2.762595947537265
3.6566540913260404e-06,0.0021168,221.39532368161528,225.01149783531545,2.762595947537265
3.6718556011539268e-06,0.0021256,221.44115206665685,225.01149783531545,2.762595947537265
3.7188420860764835e-06,0.0021528,221.58233785769377,225.01149783531545,2.762595947537265
3.7368075067821674e-06,0.0021632,221.63613659082702,225.01149783531545,2.762595947537265
3.7796481253880277e-06,0.002188,221.76402043112154,225.01149783531545,2.762595947537265
3.8045233232882044e-06,0.0022023999999999998,221.83801614442527,225.01149783531545,2.762595947537265
3.844600031016268e-06,0.0022256,221.95683581257398,225.01149783531545,2.762595947537265
3.859801540844155e-06,0.0022344,222.00177885532307,225.01149783531545,2.762595947537265
3.872239139794242e-06,0.0022416,222.03849911209556,225.01149783531545,2.762595947537265
3.89711433769442e-06,0.0022559999999999998,222.1118019203839,225.01149783531545,2.762595947537265
3.910933892083407e-06,0.002264,222.15244684871968,225.01149783531545,2.762595947537265
3.934427134544686e-06,0.0022776,222.22141491324078,225.01149783531545,2.762595947537265
3.966212109639356e-06,0.002296,222.3144695482519,225.01149783531545,2.762595947537265
3.992469262978432e-06,0.0023112,222.3911216030333,225.01149783531545,2.762595947537265
3.9979970847340266e-06,0.0023144,222.40723379731284,225.01149783531545,2.762595947537265
4.01596250543971e-06,0.0023247999999999997,222.45953852808216,225.01149783531545,2.762595947537265
4.057421168606672e-06,0.0023488,222.57989471436372,225.01149783531545,2.762595947537265
4.069858767556761e-06,0.002356,222.61590791953495,225.01149783531545,2.762595947537265
4.087824188262444e-06,0.0023664,222.6678513096912,225.01149783531545,2.762595947537265
4.1113174307237226e-06,0.0023799999999999997,222.73564314343366,225.01149783531545,2.762595947537265
4.132046762307204e-06,0.002392,222.79533410380597,225.01149783531545,2.762595947537265
4.176269336351963e-06,0.0024176,222.92228589266546,225.01149783531545,2.762595947537265
4.219109954957824e-06,0.0024424,223.04477142651402,225.01149783531545,2.762595947537265
4.232929509346811e-06,0.0024503999999999997,223.0841792929772,225.01149783531545,2.762595947537265
4.242603197419102e-06,0.002456,223.11173494988637,225.01149783531545,2.762595947537265
4.293735548658355e-06,0.0024855999999999997,223.25698122423884,225.01149783531545,2.762595947537265
4.32137465743633e-06,0.0025016,223.33521179200972,225.01149783531545,2.762595947537265
4.328284434630823e-06,0.0025055999999999998,223.35473891367403,225.01149783531545,2.762595947537265
4.351777677092102e-06,0.0025192,223.42104037693028,225.01149783531545,2.762595947537265
4.390472429381266e-06,0.0025415999999999998,223.5299392914431,225.01149783531545,2.762595947537265
4.405673939209152e-06,0.0025504,223.5726185196394,225.01149783531545,2.762595947537265
4.41949349359814e-06,0.0025583999999999997,223.61136800630536,225.01149783531545,2.762595947537265
4.426403270792633e-06,0.0025624,223.63072502678565,225.01149783531545,2.762595947537265
4.463716067642899e-06,0.002584,223.7350500053658,225.01149783531545,2.762595947537265
4.530049928710039e-06,0.0026224,223.9196807254738,225.01149783531545,2.762595947537265
4.568744680999203e-06,0.0026447999999999997,224.02689505751644,225.01149783531545,2.762595947537265
4.606057477849468e-06,0.0026663999999999998,224.1299454158461,225.01149783531545,2.762595947537265
4.624022898555152e-06,0.0026768,224.1794460966365,225.01149783531545,2.762595947537265
4.6350785420663415e-06,0.0026831999999999997,224.20987077556126,225.01149783531545,2.762595947537265
4.659953739966519e-06,0.0026976,224.278223014281,225.01149783531545,2.762595947537265
4.6793011161111016e-06,0.0027088,224.33128753485823,225.01149783531545,2.762595947537265
4.724905645594759e-06,0.0027351999999999997,224.4560307765971,225.01149783531545,2.762595947537265
4.742871066300443e-06,0.0027456,224.50504301983275,225.01149783531545,2.762595947537265
4.810586882806481e-06,0.0027848,224.68913430438278,225.01149783531545,2.762595947537265
4.854809456851239e-06,0.0028104,224.8088119229541,225.01149783531545,2.762595947537265
4.874156832995823e-06,0.0028216,224.86103710802539,225.01149783531545,2.762595947537265
4.88659443194591e-06,0.0028288,224.89456775371565,225.01149783531545,2.762595947537265
4.928053095112872e-06,0.0028528,225.00609696430672,225.01149783531545,2.762595947537265
4.959838070207543e-06,0.0028712,225.09135505772193,225.01149783531545,2.762595947537265
4.976421535474328e-06,0.0028807999999999998,225.13575293659176,225.01149783531545,2.762595947537265
5.002678688813403e-06,0.0028959999999999997,225.20593175341122,225.01149783531545,2.762595947537265
5.013734332324594e-06,0.0029024,225.23543773565035,225.01149783531545,2.762595947537265
5.077304282513935e-06,0.0029392,225.40460729171326,225.01149783531545,2.762595947537265
5.103561435853011e-06,0.0029544,225.47424037641798,225.01149783531545,2.762595947537265
5.143638143581075e-06,0.0029776,225.58025368322055,225.01149783531545,2.762595947537265
5.175423118675746e-06,0.002996,225.66410431576986,225.01149783531545,2.762595947537265
5.19200658394253e-06,0.0030055999999999998,225.70777273057448,225.01149783531545,2.762595947537265
5.262486311326365e-06,0.0030464,225.89275990112154,225.01149783531545,2.762595947537265
5.274923910276454e-06,0.0030536,225.9253041428652,225.01149783531545,2.762595947537265
5.288743464665441e-06,0.0030616,225.96142933257664,225.01149783531545,2.762595947537265
5.3343479941491e-06,0.003088,226.08038211725304,225.01149783531545,2.762595947537265
5.357841236610378e-06,0.0031016,226.1415059997147,225.01149783531545,2.762595947537265
5.379952523632757e-06,0.0031144,226.19893894462717,225.01149783531545,2.762595947537265
5.402063810655137e-06,0.0031271999999999997,226.25627990502574,225.01149783531545,2.762595947537265
5.415883365044124e-06,0.0031352,226.29207152695625,225.01149783531545,2.762595947537265
5.437994652066504e-06,0.0031479999999999998,226.3492641255565,225.01149783531545,2.762595947537265
5.476689404355669e-06,0.0031704,226.4491334191365,225.01149783531545,2.762595947537265
5.5029465576947446e-06,0.0031856,226.5167451941516,225.01149783531545,2.762595947537265
5.588627794906466e-06,0.0032351999999999997,226.7365030931486,225.01149783531545,2.762595947537265
5.603829304734352e-06,0.003244,226.7753547590851,225.01149783531545,2.762595947537265
5.624558636317833e-06,0.0032559999999999998,226.828268127905,225.01149783531545,2.762595947537265
5.643906012462415e-06,0.0032672,226.87758536175002,225.01149783531545,2.762595947537265
5.659107522290301e-06,0.003276,226.9162883776902,225.01149783531545,2.762595947537265
5.695038363701668e-06,0.0032968,227.0076074112972,225.01149783531545,2.762595947537265
5.697802274579466e-06,0.0032984,227.0146226316723,225.01149783531545,2.762595947537265
5.771045912841098e-06,0.0033407999999999997,227.2000451843617,225.01149783531545,2.762595947537265
5.804212843374668e-06,0.0033599999999999997,227.28370798467944,225.01149783531545,2.762595947537265
5.851199328297225e-06,0.0033872,227.40191182482354,225.01149783531545,2.762595947537265
5.907859501292072e-06,0.00342,227.5439605293666,225.01149783531545,2.762595947537265
5.925824921997756e-06,0.0034303999999999997,227.58888929204616,225.01149783531545,2.762595947537265
5.96451967428692e-06,0.0034528,227.68547890462446,225.01149783531545,2.762595947537265
5.97557531779811e-06,0.0034592,227.71303101026476,225.01149783531545,2.762595947537265
5.9893948721870975e-06,0.0034671999999999997,227.74744320163936,225.01149783531545,2.762595947537265
6.021179847281768e-06,0.0034855999999999997,227.82647394050895,225.01149783531545,2.762595947537265
6.0598745995709325e-06,0.003508,227.922466010045,225.01149783531545,2.762595947537265
6.072312198521022e-06,0.0035152,227.9532697973105,225.01149783531545,2.762595947537265
6.0958054409822994e-06,0.0035288,228.0113876755858,225.01149783531545,2.762595947537265
6.1054791290545915e-06,0.0035344,228.0352931687222,225.01149783531545,2.762595947537265
6.135882148710363e-06,0.003552,228.11032873132137,225.01149783531545,2.762595947537265
6.144173881343755e-06,0.0035567999999999997,228.1307677924098,225.01149783531545,2.762595947537265
6.169049079243932e-06,0.0035711999999999996,228.19202052873155,225.01149783531545,2.762595947537265
6.1731949455606285e-06,0.0035735999999999997,228.20221994596722,225.01149783531545,2.762595947537265
6.181486678194021e-06,0.0035784,228.2226107696617,225.01149783531545,2.762595947537265
6.222945341360983e-06,0.0036024,228.32440531754239,225.01149783531545,2.762595947537265
6.257494227333452e-06,0.0036224,228.40903222385555,225.01149783531545,2.762595947537265
6.271313781722438e-06,0.0036303999999999998,228.44283193998942,225.01149783531545,2.762595947537265
6.314154400328299e-06,0.0036552,228.5474269344147,225.01149783531545,2.762595947537265
6.3279739547172865e-06,0.0036631999999999997,228.5811081672765,225.01149783531545,2.762595947537265
6.343175464545173e-06,0.003672,228.61812440760391,225.01149783531545,2.762595947537265
6.370814573323147e-06,0.003688,228.6853381477017,225.01149783531545,2.762595947537265
6.392925860345526e-06,0.0037007999999999997,228.73902729467534,225.01149783531545,2.762595947537265
6.417801058245704e-06,0.0037151999999999997,228.799341094546,225.01149783531545,2.762595947537265
6.423328880001299e-06,0.0037183999999999997,228.81273177184215,225.01149783531545,2.762595947537265
6.437148434390286e-06,0.0037264,228.84618881760647,225.01149783531545,2.762595947537265
6.450967988779273e-06,0.0037343999999999997,228.87961786251446,225.01149783531545,2.762595947537265
6.470315364923856e-06,0.0037456,228.92637164255294,225.01149783531545,2.762595947537265
6.514537938968615e-06,0.0037711999999999997,229.0330331688841,225.01149783531545,2.762595947537265
6.524211627040906e-06,0.0037768,229.05632769354023,225.01149783531545,2.762595947537265
6.538031181429893e-06,0.0037847999999999996,229.0895822323918,225.01149783531545,2.762595947537265
6.58501766635245e-06,0.003812,229.20244317642428,225.01149783531545,2.762595947537265
6.615420686008222e-06,0.0038296,229.27530352430048,225.01149783531545,2.762595947537265
6.633386106713906e-06,0.0038399999999999997,229.3182959841812,225.01149783531545,2.762595947537265
6.694192146025449e-06,0.0038751999999999997,229.46347315158167,225.01149783531545,2.762595947537265
6.719067343925628e-06,0.0038896,229.52271547217416,225.01149783531545,2.762595947537265
6.808894447454045e-06,0.0039416,229.73593759974128,225.01149783531545,2.762595947537265
6.842061377987613e-06,0.0039607999999999996,229.81438809483342,225.01149783531545,2.762595947537265
6.8544989769377034e-06,0.003968,229.84376877597694,225.01149783531545,2.762595947537265
6.864172665009994e-06,0.0039736,229.8666060448403,225.01149783531545,2.762595947537265
6.897339595543563e-06,0.0039927999999999995,229.9448101364823,225.01149783531545,2.762595947537265
6.905631328176955e-06,0.0039976,229.96433822658682,225.01149783531545,2.762595947537265
7.042471455480128e-06,0.004076815363072615,230.28530502624454,225.01149783531545,2.762595947537265
7.904984151892219e-06,0.004576115223044609,232.2550900765999,225.01149783531545,2.762595947537265
8.17037267386517e-06,0.004729745949189838,232.84406114054877,225.01149783531545,2.762595947537265
8.70114971781107e-06,0.0050370074014802965,234.0000791079677,225.01149783531545,2.762595947537265
8.999711805030641e-06,0.005209841968393679,234.63824233430225,225.01149783531545,2.762595947537265
9.132406066017117e-06,0.005286657331466294,234.91921436045737,225.01149783531545,2.762595947537265
9.563662414223163e-06,0.005536307261452291,235.82156958964666,225.01149783531545,2.762595947537265
1.0625216502114965e-05,0.006150830166033207,237.97762903804528,225.01149783531545,2.762595947537265
1.1388208502787198e-05,0.00659251850370074,239.47566673591206,225.01149783531545,2.762595947537265
1.2847845373638426e-05,0.0074374874974994995,242.23656854084808,225.01149783531545,2.762595947537265
1.304688676511814e-05,0.007552710542108421,242.60334126621805,225.01149783531545,2.762595947537265
1.3677184504803898e-05,0.00791758351670334,243.7506474353561,225.01149783531545,2.762595947537265
1.4373829374982894e-05,0.008320864172834567,244.99498863404787,225.01149783531545,2.762595947537265
1.507047424516189e-05,0.008724144828965793,246.2160196076379,225.01149783531545,2.762595947537265
1.5335862767134843e-05,0.008877775555111022,246.67535815638954,225.01149783531545,2.762595947537265
1.646376398551988e-05,0.009530706141228246,248.59393692084396,225.01149783531545,2.762595947537265
1.7193582420945496e-05,0.009953190638127626,249.80809686629095,225.01149783531545,2.762595947537265
1.9548905553455436e-05,0.011316663332666534,253.5960099821366,225.01149783531545,2.762595947537265
1.9681599814441913e-05,0.011393478695739149,253.80395237476233,225.01149783531545,2.762595947537265
2.0378244684620906e-05,0.011796759351870374,254.8868077828464,225.01149783531545,2.762595947537265
2.0676806771840475e-05,0.011969593918783756,255.34645806271388,225.01149783531545,2.762595947537265
2.0942195293813426e-05,0.012123224644928985,255.75286747049665,225.01149783531545,2.762595947537265
2.2202790773184945e-05,0.012852970594118824,257.6565310115379,225.01149783531545,2.762595947537265
2.2435005729911277e-05,0.012987397479495899,258.0025587774494,225.01149783531545,2.762595947537265
2.3397039122063224e-05,0.013544308861772355,259.4214699430098,225.01149783531545,2.762595947537265
2.4160031122735457e-05,0.013985997199439888,260.5306957613024,225.01149783531545,2.762595947537265
2.4856675992914454e-05,0.014389277855571115,261.5315917023962,225.01149783531545,2.762595947537265
2.5686015124079924e-05,0.014869373874774956,262.7089800459375,225.01149783531545,2.762595947537265
2.6449007124752157e-05,0.01531106221244249,263.77914723053294,225.01149783531545,2.762595947537265
2.6813916342464966e-05,0.01552230446089218,264.2867040829622,225.01149783531545,2.762595947537265
2.7211999125424394e-05,0.015752750550110023,264.8373399064483,225.01149783531545,2.762595947537265
2.7610081908383818e-05,0.015983196639327867,265.3848430056258,225.01149783531545,2.762595947537265
2.780912329986353e-05,0.01609841968393679,265.657439433685,225.01149783531545,2.762595947537265
2.8074511821836482e-05,0.016252050410082017,266.0197206170188,225.01149783531545,2.762595947537265
2.930193373596138e-05,0.0169625925185037,267.6781977306478,225.01149783531545,2.762595947537265
2.983271077990728e-05,0.01726985397079416,268.38696015705574,225.01149783531545,2.762595947537265
3.0164446432373468e-05,0.017461892378475695,268.8274401181219,225.01149783531545,2.762595947537265
3.119282695501866e-05,0.01805721144228846,270.18107293887925,225.01149783531545,2.762595947537265
3.175677756421117e-05,0.01838367673534707,270.9159940398228,225.01149783531545,2.762595947537265
3.2552943130130026e-05,0.018844568913782757,271.9449227642662,225.01149783531545,2.762595947537265
3.470922487116025e-05,0.02009281856371274,274.68346207760084,225.01149783531545,2.762595947537265
3.49746133931332e-05,0.02024644928985797,275.01586510437266,225.01149783531545,2.762595947537265
3.530634904559939e-05,0.020438487697539507,275.42998880833744,225.01149783531545,2.762595947537265
3.577077895905205e-05,0.020707341468293658,276.0072215802853,225.01149783531545,2.762595947537265
3.600299391577839e-05,0.020841768353670735,276.2947413531355,225.01149783531545,2.762595947537265
3.666646522071077e-05,0.021225845169033808,277.1122680302893,225.01149783531545,2.762595947537265
3.8524184874521425e-05,0.02230126025205041,279.37120444030506,225.01149783531545,2.762595947537265
3.908813548371394e-05,0.02262772554510902,280.04849332980524,225.01149783531545,2.762595947537265
3.9486218266673366e-05,0.022858171634326865,280.5242869921396,225.01149783531545,2.762595947537265
4.011651600635913e-05,0.023223044608921786,281.27381879578417,225.01149783531545,2.762595947537265
4.028238383259222e-05,0.023319063812762553,281.47029888586366,225.01149783531545,2.762595947537265
4.0979028702771214e-05,0.023722344468893777,282.2920933170264,225.01149783531545,2.762595947537265
4.1476632181470496e-05,0.024010402080416084,282.87575693200995,225.01149783531545,2.762595947537265
4.154297931196374e-05,0.02404880976195239,282.95337189729696,225.01149783531545,2.762595947537265
4.303578974806158e-05,0.024912982596519303,284.68713089048845,225.01149783531545,2.762595947537265
4.353339322676087e-05,0.02520104020804161,285.25981717186164,225.01149783531545,2.762595947537265
4.396464957496691e-05,0.025450690138027605,285.7540833256887,225.01149783531545,2.762595947537265
4.505937722810534e-05,0.026084416883376677,287.00034135883715,225.01149783531545,2.762595947537265
4.6319972707476856e-05,0.026814162832566515,288.4208904219187,225.01149783531545,2.762595947537265
4.811134523079427e-05,0.02785117023404681,290.4138961224393,225.01149783531545,2.762595947537265
4.8210865926534125e-05,0.02790878175635127,290.52376227147874,225.01149783531545,2.762595947537265
4.847625444850708e-05,0.0280624124824965,290.8163071079801,225.01149783531545,2.762595947537265
4.860894870949355e-05,0.028139227845569114,290.9623452490458,225.01149783531545,2.762595947537265
4.887433723146651e-05,0.028292858571714343,291.25395593469995,225.01149783531545,2.762595947537265
4.953780853639888e-05,0.028676935387077416,291.98029383164595,225.01149783531545,2.762595947537265
5.1893131668908814e-05,0.030040408081616322,294.5287017939997,225.01149783531545,2.762595947537265
5.2755644365320906e-05,0.030539707941588317,295.4505843819567,225.01149783531545,2.762595947537265
5.3253247844020196e-05,0.030827765553110623,295.9797657524134,225.01149783531545,2.762595947537265
5.418210767092553e-05,0.03136547309461893,296.96243975174696,225.01149783531545,2.762595947537265
5.431480193191199e-05,0.031442288457691536,297.10228354480563,225.01149783531545,2.762595947537265
5.46797111496248e-05,0.03165353070614123,297.4861686269512,225.01149783531545,2.762595947537265
5.574126523751661e-05,0.032268053610722144,298.5972846390312,225.01149783531545,2.762595947537265
5.613934802047603e-05,0.03249849969993999,299.0118216145717,225.01149783531545,2.762595947537265
5.700186071688813e-05,0.032997799559911986,299.906072604131,225.01149783531545,2.762595947537265
5.789754697854683e-05,0.03351630326065213,300.8291500275901,225.01149783531545,2.762595947537265
5.812976193527317e-05,0.033650730146029206,301.0675551761563,225.01149783531545,2.762595947537265
5.942353097989129e-05,0.03439967993598719,302.3890750752644,225.01149783531545,2.762595947537265
6.071730002450944e-05,0.035148629725945194,303.6994202983691,225.01149783531545,2.762595947537265
6.11817299379621e-05,0.035417483496699334,304.16713866725894,225.01149783531545,2.762595947537265
6.151346559042829e-05,0.03560952190438088,304.5003758530411,225.01149783531545,2.762595947537265
6.177885411240125e-05,0.03576315263052611,304.766461248419,225.01149783531545,2.762595947537265
6.277406106979979e-05,0.03633926785357071,305.76033600192716,225.01149783531545,2.762595947537265
6.406783011441794e-05,0.03708821764352871,307.0432340715005,225.01149783531545,2.762595947537265
6.446591289737736e-05,0.037318663732746546,307.43593402571986,225.01149783531545,2.762595947537265
6.496351637607666e-05,0.03760672134426886,307.92548156679675,225.01149783531545,2.762595947537265
6.566016124625565e-05,0.038010002000400084,308.60839834958114,225.01149783531545,2.762595947537265
6.625728542069478e-05,0.038355671134226846,309.1915095122412,225.01149783531545,2.762595947537265
6.672171533414745e-05,0.038624524904981,309.6436246386191,225.01149783531545,2.762595947537265
6.711979811710687e-05,0.03885497099419884,310.03017589090456,225.01149783531545,2.762595947537265
6.721931881284672e-05,0.0389125825165033,310.12667387128863,225.01149783531545,2.762595947537265
6.781644298728587e-05,0.03925825165033006,310.70449598602585,225.01149783531545,2.762595947537265
6.901069133616416e-05,0.0399495899179836,311.85422168365704,225.01149783531545,2.762595947537265
6.99727247283161e-05,0.04050650130026005,312.77475653092404,225.01149783531545,2.762595947537265
7.023811325028904e-05,0.04066013202640528,313.0278268589567,225.01149783531545,2.762595947537265
7.100110525096127e-05,0.04110182036407281,313.75333506733864,225.01149783531545,2.762595947537265
7.15650558601538e-05,0.04142828565713143,314.2876275161307,225.01149783531545,2.762595947537265
7.183044438212675e-05,0.04158191638327666,314.53849084785276,225.01149783531545,2.762595947537265
7.219535359983956e-05,0.04179315863172635,314.88283851289145,225.01149783531545,2.762595947537265
7.249391568705912e-05,0.04196599319863972,315.16407290472154,225.01149783531545,2.762595947537265
7.408624681889682e-05,0.0428877775555111,316.6564289841021,225.01149783531545,2.762595947537265
7.478289168907584e-05,0.043291058211642336,317.3053954398633,225.01149783531545,2.762595947537265
7.511462734154202e-05,0.04348309661932387,317.6135980250614,225.01149783531545,2.762595947537265
7.538001586351497e-05,0.0436367273454691,317.8597780556579,225.01149783531545,2.762595947537265
7.597714003795411e-05,0.04398239647929586,318.41245058770744,225.01149783531545,2.762595947537265
7.644156995140679e-05,0.044251250250050014,318.8411366747189,225.01149783531545,2.762595947537265
7.667378490813311e-05,0.044385677135427085,319.05509871876734,225.01149783531545,2.762595947537265
7.697234699535268e-05,0.04455851170234047,319.3298217944344,225.01149783531545,2.762595947537265
7.7204561952079e-05,0.04469293858771754,319.5432080817249,225.01149783531545,2.762595947537265
7.816659534423094e-05,0.045249849969994,320.424583562529,225.01149783531545,2.762595947537265
7.89627609101498e-05,0.045710742148429684,321.1508028992678,225.01149783531545,2.762595947537265
8.032287708526118e-05,0.04649809961992399,322.38485573623905,225.01149783531545,2.762595947537265
8.082048056396045e-05,0.04678615723144629,322.83429883113496,225.01149783531545,2.762595947537265
8.12185633469199e-05,0.04701660332066414,323.1930767689872,225.01149783531545,2.762595947537265
8.181568752135903e-05,0.0473622724544909,323.72996044282786,225.01149783531545,2.762595947537265
8.237963813055157e-05,0.04768873774754952,324.2356157793183,225.01149783531545,2.762595947537265
8.364023360992306e-05,0.048418483696739345,325.3610480102537,225.01149783531545,2.762595947537265
8.480130839355472e-05,0.049090618123624724,326.391791584388,225.01149783531545,2.762595947537265
8.50998704807743e-05,0.04926345269053811,326.65594848249066,225.01149783531545,2.762595947537265
8.602873030767962e-05,0.04980116023204641,327.47546798316404,225.01149783531545,2.762595947537265
8.639363952539243e-05,0.0500124024804961,327.79647702965724,225.01149783531545,2.762595947537265
8.695759013458496e-05,0.050338867773554716,328.29154377383463,225.01149783531545,2.762595947537265
8.748836717853085e-05,0.050646129225845174,328.75634633219386,225.01149783531545,2.762595947537265
8.795279709198351e-05,0.050914982996599314,329.162147174287,225.01149783531545,2.762595947537265
8.831770630969632e-05,0.051126225245049006,329.4804047207931,225.01149783531545,2.762595947537265
8.89811776146287e-05,0.051510302060412086,330.0577440230447,225.01149783531545,2.762595947537265
8.964464891956107e-05,0.05189437887577515,330.6334068651843,225.01149783531545,2.762595947537265
9.024177309400023e-05,0.05224004800960193,331.1500842900869,225.01149783531545,2.762595947537265
9.070620300745287e-05,0.05250890178035607,331.55102324875253,225.01149783531545,2.762595947537265
9.130332718189203e-05,0.052854570914182844,332.0653417365385,225.01149783531545,2.762595947537265
9.236488126978382e-05,0.05346909381876375,332.97645832051853,225.01149783531545,2.762595947537265
9.276296405274325e-05,0.0536995399079816,333.317073003208,225.01149783531545,2.762595947537265
9.31942204009493e-05,0.05394918983796759,333.68542957864435,225.01149783531545,2.762595947537265
9.382451814063505e-05,0.054314062812562514,334.22260331035744,225.01149783531545,2.762595947537265
9.554954353345922e-05,0.055312662532506496,335.68561408801673,225.01149783531545,2.762595947537265
9.657792405610443e-05,0.05590798159631927,336.55289312230315,225.01149783531545,2.762595947537265
9.730774249153005e-05,0.05633046609321865,337.16619787584744,225.01149783531545,2.762595947537265
9.7573131013503e-05,0.05648409681936388,337.3887726715777,225.01149783531545,2.762595947537265
9.773899883973608e-05,0.056580116023204646,337.52776203216274,225.01149783531545,2.762595947537265
9.820342875318874e-05,0.05684896979395879,337.91644370730586,225.01149783531545,2.762595947537265
9.883372649287449e-05,0.05721384276855371,338.44279555383906,225.01149783531545,2.762595947537265
9.893324718861435e-05,0.05727145429085817,338.52578391986674,225.01149783531545,2.762595947537265
9.939767710206703e-05,0.057540308061612325,338.9126332947667,225.01149783531545,2.762595947537265
9.956354492830011e-05,0.05763632726545309,339.05062286393047,225.01149783531545,2.762595947537265
9.966306562403997e-05,0.057693938787757554,339.1333735718904,225.01149783531545,2.762595947537265
9.996162771125956e-05,0.05786677335467094,339.38143255190346,225.01149783531545,2.762595947537265
0.00010012749553749264,0.05796279255851171,339.5191182377305,225.01149783531545,2.762595947537265
0.00010085731397291823,0.05838527705541108,340.12388157550043,225.01149783531545,2.762595947537265
0.00010205156232179654,0.059076615323064616,341.1098258532084,225.01149783531545,2.762595947537265
0.00010301359571394848,0.05963352670534107,341.9007902731569,225.01149783531545,2.762595947537265
0.00010334533136641466,0.0598255651130226,342.17286797344553,225.01149783531545,2.762595947537265
0.00010364389345363423,0.05999839967993599,342.41744681958926,225.01149783531545,2.762595947537265
0.00010400880267134704,0.06020964192838568,342.7160036908801,225.01149783531545,2.762595947537265
0.0001043073647585666,0.060382476495299056,342.95997375909496,225.01149783531545,2.762595947537265
0.0001044732325847997,0.06047849569913982,343.09539500176226,225.01149783531545,2.762595947537265
0.00010473862110677265,0.06063212642528505,343.3118947105756,225.01149783531545,2.762595947537265
0.00010550161310744489,0.061073814762952594,343.9331428442015,225.01149783531545,2.762595947537265
0.00010609873728188402,0.061419483896779356,344.4181156055085,225.01149783531545,2.762595947537265
0.0001070939442392826,0.06199559911982397,345.2240447001508,225.01149783531545,2.762595947537265
0.00010752520058748865,0.062245249049809964,345.57237297581537,225.01149783531545,2.762595947537265
0.00010918387884981958,0.06320544108821764,346.9070498938029,225.01149783531545,2.762595947537265
0.00010984735015475196,0.06358951790358072,347.4387036892794,225.01149783531545,2.762595947537265
0.00011074303641641065,0.06410802160432086,348.15445402889287,225.01149783531545,2.762595947537265
0.00011084255711215051,0.06416563312662532,348.2338422348932,225.01149783531545,2.762595947537265
0.00011094207780789038,0.06422324464892978,348.3132026468651,225.01149783531545,2.762595947537265
0.00011183776406954909,0.06474174834966993,349.0262013162556,225.01149783531545,2.762595947537265
0.00011260075607022131,0.06518343668733746,349.63181575862825,225.01149783531545,2.762595947537265
0.0001137950044190996,0.065874774954991,350.57653090451544,225.01149783531545,2.762595947537265
0.00011744409659622769,0.0679871974394879,353.439485627906,225.01149783531545,2.762595947537265
0.00011814074146640668,0.06839047809561913,353.98208351120934,225.01149783531545,2.762595947537265
0.00011863834494510595,0.06867853570714143,354.36888973032654,225.01149783531545,2.762595947537265
0.00011910277485855862,0.06894738947789558,354.72933839870893,225.01149783531545,2.762595947537265
0.0001195672047720113,0.06921624324864974,355.0892393233012,225.01149783531545,2.762595947537265
0.00012049606459891661,0.06975395079015803,355.80740973424827,225.01149783531545,2.762595947537265
0.00012106001520810914,0.07008041608321665,356.24238848775354,225.01149783531545,2.762595947537265
0.00012195570146976786,0.0705989197839568,356.93161633257773,225.01149783531545,2.762595947537265
0.00012265234633994685,0.07100220044008802,357.46631849732546,225.01149783531545,2.762595947537265
0.0001232826440796326,0.07136707341468294,357.9490769109552,225.01149783531545,2.762595947537265
0.0001257374879078824,0.07278815763152631,359.82018989587704,225.01149783531545,2.762595947537265
0.00012610239712559522,0.072999399879976,360.0971072199547,225.01149783531545,2.762595947537265
0.00012653365347380124,0.073249049809962,360.4239705561073,225.01149783531545,2.762595947537265
0.00012686538912626744,0.07344108821764353,360.67510833423773,225.01149783531545,2.762595947537265
0.0001271971247787336,0.07363312662532506,360.9259901330893,225.01149783531545,2.762595947537265
0.0001274956868659532,0.07380596119223845,361.1515656564714,225.01149783531545,2.762595947537265
0.00012835819956236527,0.07430526105221044,361.8020739311815,225.01149783531545,2.762595947537265
0.00012892215017155782,0.07463172634526906,362.22648475150595,225.01149783531545,2.762595947537265
0.00012971831573747666,0.07509261852370475,362.82442241114995,225.01149783531545,2.762595947537265
0.0001299837042594496,0.07524624924984998,363.02341668004345,225.01149783531545,2.762595947537265
0.00013041496060765565,0.07549589917983597,363.34644475163077,225.01149783531545,2.762595947537265
0.0001313769939998076,0.07605281056211242,364.0655483981552,225.01149783531545,2.762595947537265
0.00013184142391326026,0.07632166433286658,364.4119666209746,225.01149783531545,2.762595947537265
0.00013369914356707092,0.07739707941588318,365.79290666483104,225.01149783531545,2.762595947537265
0.00013549051609038835,0.07843408681736348,367.1174575599327,225.01149783531545,2.762595947537265
0.0001357559046123613,0.07858771754350871,367.31310491308756,225.01149783531545,2.762595947537265
0.0001361208138300741,0.07879895979195839,367.5818766431684,225.01149783531545,2.762595947537265
0.00013658524374352677,0.07906781356271254,367.9235436963047,225.01149783531545,2.762595947537265
0.00013774631852715843,0.07973994798959792,368.7757350290548,225.01149783531545,2.762595947537265
0.00013847613696258405,0.0801624324864973,369.3099645346036,225.01149783531545,2.762595947537265
0.0001389073933107901,0.0804120824164833,369.6251294781135,225.01149783531545,2.762595947537265
0.0001391064347022698,0.08052730546109223,369.7704614927716,225.01149783531545,2.762595947537265
0.00013923912896325627,0.08060412082416483,369.86730444946295,225.01149783531545,2.762595947537265
0.0001396703853114623,0.08085377075415083,370.181795771544,225.01149783531545,2.762595947537265
0.00013986942670294204,0.08096899379875976,370.3268178609785,225.01149783531545,2.762595947537265
0.00014010164165966836,0.08110342068413683,370.4959086128657,225.01149783531545,2.762595947537265
0.00014079828652984738,0.08150670134026806,371.00252626705833,225.01149783531545,2.762595947537265
0.00014116319574756015,0.08171794358871774,371.26750721737466,225.01149783531545,2.762595947537265
0.00014222474983545196,0.08233246649329866,372.03684615265024,225.01149783531545,2.762595947537265
0.0001428218740098911,0.08267813562712543,372.468615089504,225.01149783531545,2.762595947537265
0.00014448055227222207,0.08363832766553311,373.6642949279896,225.01149783531545,2.762595947537265
0.00014534306496863413,0.0841376275255051,374.28393207089215,225.01149783531545,2.762595947537265
0.00014623875123029285,0.08465613122624525,374.92588544026387,225.01149783531545,2.762595947537265
0.00014680270183948537,0.08498259651930387,375.3292917178687,225.01149783531545,2.762595947537265
0.00014713443749195157,0.0851746349269854,375.5663072067298,225.01149783531545,2.762595947537265
0.00014816281801459673,0.08576995399079816,376.2997342478058,225.01149783531545,2.762595947537265
0.00014875994218903587,0.08611562312462492,376.72468404039677,225.01149783531545,2.762595947537265
0.00014919119853724195,0.08636527305461093,377.03117860887625,225.01149783531545,2.762595947537265
0.0001505513147123533,0.08715263052610522,377.99555979421183,225.01149783531545,2.762595947537265
0.00015078352966907966,0.08728705741148231,378.1598700735594,225.01149783531545,2.762595947537265
0.0001517787366264782,0.0878631726345269,378.8629421338588,225.01149783531545,2.762595947537265
0.00015300615854060308,0.08857371474294859,379.727593112596,225.01149783531545,2.762595947537265
0.00015376915054127533,0.08901540308061613,380.263715620382,225.01149783531545,2.762595947537265
0.0001544326218462077,0.0893994798959792,380.7290663451265,225.01149783531545,2.762595947537265
0.0001551624402816333,0.08982196439287858,381.2400525169969,225.01149783531545,2.762595947537265
0.00015579273802131908,0.0901868373674735,381.6806048863499,225.01149783531545,2.762595947537265
0.0001561576472390319,0.0903980796159232,381.93534380571776,225.01149783531545,2.762595947537265
0.00015632351506526498,0.09049409881976396,382.05105746715145,225.01149783531545,2.762595947537265
0.0001567215978482244,0.0907245449089818,382.32857506397903,225.01149783531545,2.762595947537265
0.00015768363124037634,0.09128145629125825,382.99811005247085,225.01149783531545,2.762595947537265
0.00015794901976234928,0.09143508701740348,383.18252876396014,225.01149783531545,2.762595947537265
0.00015841344967580195,0.09170394078815763,383.50497098621815,225.01149783531545,2.762595947537265
0.00015891105315450125,0.09199199839967995,383.85003595118803,225.01149783531545,2.762595947537265
0.000159541350894187,0.09235687137427485,384.28651389810625,225.01149783531545,2.762595947537265
0.00015977356585091334,0.09249129825965194,384.4471519721638,225.01149783531545,2.762595947537265
0.0001602711693296126,0.09277935587117424,384.79107012885703,225.01149783531545,2.762595947537265
0.00016053655785158559,0.09293298659731947,384.97432285851744,225.01149783531545,2.762595947537265
0.00016073559924306528,0.09304820964192839,385.1116848818112,225.01149783531545,2.762595947537265
0.0001616644590699706,0.09358591718343669,385.7518325709209,225.01149783531545,2.762595947537265
0.00016295822811458876,0.09433486697339469,386.6410815805021,225.01149783531545,2.762595947537265
0.00016355535228902788,0.09468053610722145,387.05057513257105,225.01149783531545,2.762595947537265
0.00016382074081100085,0.09483416683336668,387.2323850695799,225.01149783531545,2.762595947537265
0.00016421882359396025,0.09506461292258452,387.504884747969,225.01149783531545,2.762595947537265
0.0001646169063769197,0.09529505901180237,387.7771269269161,225.01149783531545,2.762595947537265
0.00016664049385696345,0.09646649329865974,389.1570746623954,225.01149783531545,2.762595947537265
0.0001672707915966492,0.09683136627325466,389.58555759854147,225.01149783531545,2.762595947537265
0.000168332345684541,0.09744588917783557,390.3057924701619,225.01149783531545,2.762595947537265
0.00016876360203274706,0.09769553910782157,390.59788164221715,225.01149783531545,2.762595947537265
0.00016985832968588547,0.09832926585317064,391.3380344418942,225.01149783531545,2.762595947537265
0.00017052180099081784,0.09871334266853371,391.78570653786954,225.01149783531545,2.762595947537265
0.00017095305733902388,0.0989629925985197,392.07632916704347,225.01149783531545,2.762595947537265
0.00017204778499216232,0.09959671934386878,392.8127823361759,225.01149783531545,2.762595947537265