File: datasets/aisi_316_L/data/M1/train_26.csv
Time(s),Strain(%),Stress(MPa),Temp(C),Log_SR(s-1)
0.0,0.0,0.0,234.54413211373338,-2.3196463090417767
0.0020040914816565115,9.6e-06,1.7579205,234.54413211373338,-2.3196463090417767
0.004342198210255775,2.0799999999999997e-05,3.8088277499999994,234.54413211373338,-2.3196463090417767
0.00784935830315467,3.76e-05,6.885188625,234.54413211373338,-2.3196463090417767
0.01035447265522531,4.96e-05,9.08258925,234.54413211373338,-2.3196463090417767
0.0131936022542387,6.319999999999999e-05,11.572976624999999,234.54413211373338,-2.3196463090417767
0.020040914816565118,9.6e-05,17.579205,234.54413211373338,-2.3196463090417767
0.02187799867475025,0.0001048,19.190632125,234.54413211373338,-2.3196463090417767
0.02354807490946401,0.00011279999999999999,20.655565874999997,234.54413211373338,-2.3196463090417767
0.025051143520706393,0.00011999999999999999,21.97400625,234.54413211373338,-2.3196463090417767
0.028391295990133913,0.000136,24.90387375,234.54413211373338,-2.3196463090417767
0.03239947895344694,0.0001552,28.41971475,234.54413211373338,-2.3196463090417767
0.03457057805857482,0.0001656,30.324128624999997,234.54413211373338,-2.3196463090417767
0.03757671528105959,0.00017999999999999998,32.961009374999996,234.54413211373338,-2.3196463090417767
0.03924679151577335,0.000188,34.425943124999996,234.54413211373338,-2.3196463090417767
0.04125088299742986,0.00019759999999999998,36.183863624999994,234.54413211373338,-2.3196463090417767
0.050770317535298294,0.0002432,44.533986,234.54413211373338,-2.3196463090417767
0.054945508122082695,0.0002632,48.196320375,234.54413211373338,-2.3196463090417767
0.0576176300976247,0.000276,50.540214375,234.54413211373338,-2.3196463090417767
0.06012274444969535,0.000288,52.737615,234.54413211373338,-2.3196463090417767
0.060790774943580844,0.0002912,53.32358849999999,234.54413211373338,-2.3196463090417767
0.06162581306093772,0.00029519999999999997,54.05605537499999,234.54413211373338,-2.3196463090417767
0.0694751713640924,0.00033279999999999996,60.94124399999999,234.54413211373338,-2.3196463090417767
0.07198028571616304,0.0003448,63.138644625,234.54413211373338,-2.3196463090417767
0.07415138482129092,0.00035519999999999996,65.04305849999999,234.54413211373338,-2.3196463090417767
0.0771575220437757,0.0003696,67.67993925,234.54413211373338,-2.3196463090417767
0.08083168976014596,0.0003872,70.9027935,234.54413211373338,-2.3196463090417767
0.08200074312444561,0.0003928,71.928247125,234.54413211373338,-2.3196463090417767
0.08584191846428724,0.00041119999999999997,75.29759474999999,234.54413211373338,-2.3196463090417767
0.08634294133470137,0.00041359999999999997,75.73707487499999,234.54413211373338,-2.3196463090417767
0.09402529201438467,0.0004504,82.475770125,234.54413211373338,-2.3196463090417767
0.09836749022464043,0.00047119999999999996,86.28459787499999,234.54413211373338,-2.3196463090417767
0.1000375664593542,0.0004792,87.749531625,234.54413211373338,-2.3196463090417767
0.10454677229308136,0.0005008,91.70485275,234.54413211373338,-2.3196463090417767
0.10621684852779512,0.0005088,93.1697865,234.54413211373338,-2.3196463090417767
0.11289715346665016,0.0005408,99.0295215,234.54413211373338,-2.3196463090417767
0.11607029831260629,0.000556,101.812895625,234.54413211373338,-2.3196463090417767
0.11807438979426281,0.0005656,103.570816125,234.54413211373338,-2.3196463090417767
0.11924344315856245,0.0005712,104.59626975,234.54413211373338,-2.3196463090417767
0.12458768710964646,0.0005968,109.28405775,234.54413211373338,-2.3196463090417767
0.12742681670865985,0.0006104,111.774445125,234.54413211373338,-2.3196463090417767
0.13176901491891563,0.0006312,115.58327287499999,234.54413211373338,-2.3196463090417767
0.1354431826352859,0.0006487999999999999,118.80612712499999,234.54413211373338,-2.3196463090417767
0.13995238846901303,0.0006703999999999999,122.76144824999999,234.54413211373338,-2.3196463090417767
0.14329254093844057,0.0006864,125.69131575,234.54413211373338,-2.3196463090417767
0.14396057143232607,0.0006896,126.27728925,234.54413211373338,-2.3196463090417767
0.14880379251299597,0.0007128,130.525597125,234.54413211373338,-2.3196463090417767
0.15180992973548074,0.0007272,133.162477875,234.54413211373338,-2.3196463090417767
0.15531708982837963,0.000744,136.23883874999999,234.54413211373338,-2.3196463090417767
0.1596592880386354,0.0007647999999999999,140.0476665,234.54413211373338,-2.3196463090417767
0.16216440239070606,0.0007768,142.245067125,234.54413211373338,-2.3196463090417767
0.16717463109484734,0.0008008,146.639868375,234.54413211373338,-2.3196463090417767
0.1715168293051031,0.0008215999999999999,150.448696125,234.54413211373338,-2.3196463090417767
0.17602603513883028,0.0008432,154.40401725,234.54413211373338,-2.3196463090417767
0.17819713424395814,0.0008535999999999999,156.308431125,234.54413211373338,-2.3196463090417767
0.1793661876082578,0.0008592,157.33388474999998,234.54413211373338,-2.3196463090417767
0.1813702790899143,0.0008688,159.09180525,234.54413211373338,-2.3196463090417767
0.18437641631239907,0.0008832,161.728686,234.54413211373338,-2.3196463090417767
0.1873825535348838,0.0008975999999999999,164.36556674999997,234.54413211373338,-2.3196463090417767
0.18771656878182658,0.0008992,164.65855349999998,234.54413211373338,-2.3196463090417767
0.19139073649819685,0.0009168,167.88140775,234.54413211373338,-2.3196463090417767
0.19573293470845263,0.0009375999999999999,171.69023549999997,234.54413211373338,-2.3196463090417767
0.19990812529523702,0.0009576,175.352569875,234.54413211373338,-2.3196463090417767
0.20308127014119318,0.0009728,178.135944,234.54413211373338,-2.3196463090417767
0.20692244548103483,0.0009912,181.505291625,234.54413211373338,-2.3196463090417767
0.20792449122186307,0.000996,182.384251875,234.54413211373338,-2.3196463090417767
0.21226668943211885,0.0010168,186.193079625,234.54413211373338,-2.3196463090417767
0.21710991051278875,0.00104,188.66409368890592,234.54413211373338,-2.3196463090417767
0.22262116208734414,0.0010664,188.82259528032824,234.54413211373338,-2.3196463090417767
0.2264623374271858,0.0010848,188.93216225044446,234.54413211373338,-2.3196463090417767
0.23080453563744158,0.0011056,189.05515151414417,234.54413211373338,-2.3196463090417767
0.23464571097728323,0.001124,189.16319944361325,234.54413211373338,-2.3196463090417767
0.24416514551515167,0.0011696,189.42803904508747,234.54413211373338,-2.3196463090417767
0.2493423818427643,0.0011944,189.57038264707222,234.54413211373338,-2.3196463090417767
0.2506784428305353,0.0012008,189.60692877961367,234.54413211373338,-2.3196463090417767
0.2540185952999628,0.0012167999999999999,189.69796332613566,234.54413211373338,-2.3196463090417767
0.2546866257938483,0.00122,189.7161140837241,234.54413211373338,-2.3196463090417767
0.2575257553928617,0.0012335999999999998,189.793048579633,234.54413211373338,-2.3196463090417767
0.2596968544979896,0.0012439999999999999,189.85165785229478,234.54413211373338,-2.3196463090417767
0.2605318926153465,0.001248,189.87414895888492,234.54413211373338,-2.3196463090417767
0.26220196885006025,0.001256,189.9190470076304,234.54413211373338,-2.3196463090417767
0.265208106072545,0.0012703999999999999,189.99958344407003,234.54413211373338,-2.3196463090417767
0.26570912894295917,0.0012728,190.01297149457497,234.54413211373338,-2.3196463090417767
0.26754621280114427,0.0012816,190.06197700656188,234.54413211373338,-2.3196463090417767
0.27055235002362904,0.0012959999999999998,190.14188571825363,234.54413211373338,-2.3196463090417767
0.2737254948695852,0.0013112,190.22585905147028,234.54413211373338,-2.3196463090417767
0.2752285634808276,0.0013184,190.2655033079593,234.54413211373338,-2.3196463090417767
0.27840170832678374,0.0013335999999999999,190.34892051992702,234.54413211373338,-2.3196463090417767
0.28090682267885436,0.0013456,190.41451457753524,234.54413211373338,-2.3196463090417767
0.28341193703092504,0.0013576,190.4798808915236,234.54413211373338,-2.3196463090417767
0.2854160285125815,0.0013671999999999998,190.53201184645033,234.54413211373338,-2.3196463090417767
0.2884221657350663,0.0013816,190.60994140385137,234.54413211373338,-2.3196463090417767
0.2899252343463087,0.0013888,190.64878734617415,234.54413211373338,-2.3196463090417767
0.2912612953340797,0.0013951999999999999,190.68325118475104,234.54413211373338,-2.3196463090417767
0.29276436394532207,0.0014024,190.72194939064747,234.54413211373338,-2.3196463090417767
0.2952694782973927,0.0014144,190.78627465499792,234.54413211373338,-2.3196463090417767
0.2986096307668202,0.0014303999999999999,190.87171156085077,234.54413211373338,-2.3196463090417767
0.3047889128352611,0.00146,191.02879365864842,234.54413211373338,-2.3196463090417767
0.30746103481080317,0.0014728,191.0963358316207,234.54413211373338,-2.3196463090417767
0.3119702406445303,0.0014944,191.20979642141154,234.54413211373338,-2.3196463090417767
0.31347330925577266,0.0015015999999999999,191.24747425153504,234.54413211373338,-2.3196463090417767
0.3153103931139578,0.0015103999999999999,191.2934293854435,234.54413211373338,-2.3196463090417767
0.31631243885478605,0.0015152,191.3184518056391,234.54413211373338,-2.3196463090417767
0.31748149221908567,0.0015207999999999999,191.347605590021,234.54413211373338,-2.3196463090417767
0.323827781910998,0.0015512,191.50514442156816,234.54413211373338,-2.3196463090417767
0.32683391913348275,0.0015655999999999999,191.57934739544658,234.54413211373338,-2.3196463090417767
0.3285039953681965,0.0015735999999999999,191.62045624315613,234.54413211373338,-2.3196463090417767
0.3313431249672099,0.0015872,191.69015471633074,234.54413211373338,-2.3196463090417767
0.33384823931928054,0.0015991999999999998,191.75146017616717,234.54413211373338,-2.3196463090417767
0.3353513079305229,0.0016064,191.78815734179983,234.54413211373338,-2.3196463090417767
0.3371883917887081,0.0016152,191.83292243578373,234.54413211373338,-2.3196463090417767
0.33869146039995046,0.0016224,191.869477715551,234.54413211373338,-2.3196463090417767
0.34002752138772147,0.0016288,191.90191821669126,234.54413211373338,-2.3196463090417767
0.3408625595050783,0.0016328,191.92216828740527,234.54413211373338,-2.3196463090417767
0.3452047577153341,0.0016535999999999999,192.02715840167855,234.54413211373338,-2.3196463090417767
0.34570578058574825,0.001656,192.03923941269758,234.54413211373338,-2.3196463090417767
0.3475428644439334,0.0016648,192.08347815310015,234.54413211373338,-2.3196463090417767
0.3503819940429468,0.0016784,192.15166815526086,234.54413211373338,-2.3196463090417767
0.35388915413584565,0.0016952,192.23560607884792,234.54413211373338,-2.3196463090417767
0.35656127611138766,0.0017079999999999999,192.2993412089414,234.54413211373338,-2.3196463090417767
0.3649116572849565,0.001748,192.49732332326445,234.54413211373338,-2.3196463090417767
0.3694208631186836,0.0017695999999999999,192.60349864370224,234.54413211373338,-2.3196463090417767
0.3710909393533974,0.0017775999999999998,192.64269441718835,234.54413211373338,-2.3196463090417767
0.3719259774707543,0.0017816,192.66226650131838,234.54413211373338,-2.3196463090417767
0.3787732900330807,0.0018143999999999999,192.82211622803285,234.54413211373338,-2.3196463090417767
0.3842845416076361,0.0018407999999999999,192.94995868052297,234.54413211373338,-2.3196463090417767
0.3861216254658212,0.0018495999999999999,192.9924136682057,234.54413211373338,-2.3196463090417767
0.38729067883012086,0.0018552,193.01938946759972,234.54413211373338,-2.3196463090417767
0.39163287704037664,0.0018759999999999998,193.1193084711445,234.54413211373338,-2.3196463090417767
0.3926349227812049,0.0018808,193.1423052346093,234.54413211373338,-2.3196463090417767
0.39580806762716103,0.001896,193.2149777737666,234.54413211373338,-2.3196463090417767
0.3974781438618748,0.0019039999999999999,193.25313519570255,234.54413211373338,-2.3196463090417767
0.3999832582139454,0.001916,193.31025429991922,234.54413211373338,-2.3196463090417767
0.4058285250354436,0.001944,193.44299237440347,234.54413211373338,-2.3196463090417767
0.4083336393875142,0.001956,193.49965163295104,234.54413211373338,-2.3196463090417767
0.41017072324569936,0.0019648,193.5411156340252,234.54413211373338,-2.3196463090417767
0.4133438680916555,0.00198,193.61256508414547,234.54413211373338,-2.3196463090417767
0.41467992907942647,0.0019863999999999997,193.64258502993437,234.54413211373338,-2.3196463090417767
0.41902212728968224,0.0020071999999999998,193.73989037245482,234.54413211373338,-2.3196463090417767
0.422028264512167,0.0020215999999999997,193.80702536318273,234.54413211373338,-2.3196463090417767
0.42269629500605255,0.0020247999999999998,193.82191889276447,234.54413211373338,-2.3196463090417767
0.42687148559283694,0.0020448,193.91479633289114,234.54413211373338,-2.3196463090417767
0.4293765999449076,0.0020568,193.97035275377337,234.54413211373338,-2.3196463090417767
0.43371879815516334,0.0020775999999999998,194.0663520219704,234.54413211373338,-2.3196463090417767
0.4370589506245908,0.0020935999999999997,194.13994277226197,234.54413211373338,-2.3196463090417767
0.4422361869522035,0.0021184,194.25357644559534,234.54413211373338,-2.3196463090417767
0.4450753165512169,0.0021319999999999998,194.3156713772117,234.54413211373338,-2.3196463090417767
0.450419560502301,0.0021576,194.4321384816499,234.54413211373338,-2.3196463090417767
0.4517556214900719,0.0021639999999999997,194.46117089544288,234.54413211373338,-2.3196463090417767
0.45542978920644217,0.0021815999999999997,194.540837879382,234.54413211373338,-2.3196463090417767
0.46060702553405486,0.0022064,194.6526717661577,234.54413211373338,-2.3196463090417767
0.46160907127488315,0.0022112,194.6742602954899,234.54413211373338,-2.3196463090417767
0.46361316275653963,0.0022207999999999998,194.71738260179745,234.54413211373338,-2.3196463090417767
0.47263157442399395,0.002264,194.91054031383672,234.54413211373338,-2.3196463090417767
0.4751366887760646,0.002276,194.96393944658558,234.54413211373338,-2.3196463090417767
0.47947888698632035,0.0022968,195.05623856484948,234.54413211373338,-2.3196463090417767
0.48031392510367726,0.0023008,195.07395096134425,234.54413211373338,-2.3196463090417767
0.4856581690547613,0.0023263999999999997,195.18702723982568,234.54413211373338,-2.3196463090417767
0.4930065044875018,0.0023615999999999997,195.34171792985273,234.54413211373338,-2.3196463090417767
0.497515710321229,0.0023832,195.4361966595104,234.54413211373338,-2.3196463090417767
0.5125463964336529,0.0024552,195.7487412325346,234.54413211373338,-2.3196463090417767
0.5132144269275384,0.0024584,195.76254852548755,234.54413211373338,-2.3196463090417767
0.5137154497979525,0.0024608,195.7728993958651,234.54413211373338,-2.3196463090417767
0.5147174955387808,0.0024656,195.79358933289527,234.54413211373338,-2.3196463090417767
0.5172226098908513,0.0024776,195.84524556828296,234.54413211373338,-2.3196463090417767
0.5247379529470633,0.0025136,195.9996319784371,234.54413211373338,-2.3196463090417767
0.5265750368052484,0.0025223999999999997,196.03723942324189,234.54413211373338,-2.3196463090417767
0.5287461359103763,0.0025328,196.0816186793278,234.54413211373338,-2.3196463090417767
0.5339233722379889,0.0025575999999999997,196.1871603181175,234.54413211373338,-2.3196463090417767
0.5364284865900596,0.0025696,196.23808550440097,234.54413211373338,-2.3196463090417767
0.5429417839054432,0.0026008,196.370058803456,234.54413211373338,-2.3196463090417767
0.5462819363748708,0.0026168,196.4374978176173,234.54413211373338,-2.3196463090417767
0.5496220888442983,0.0026328,196.50477620764545,234.54413211373338,-2.3196463090417767
0.5536302718076113,0.002652,196.58530015863124,234.54413211373338,-2.3196463090417767
0.5544653099249682,0.002656,196.60204732841524,234.54413211373338,-2.3196463090417767
0.5549663327953823,0.0026584,196.6120909088618,234.54413211373338,-2.3196463090417767
0.5569704242770388,0.002668,196.65222991854856,234.54413211373338,-2.3196463090417767
0.5576384547709243,0.0026712,196.66559706618554,234.54413211373338,-2.3196463090417767
0.5598095538760521,0.0026815999999999997,196.70899722882572,234.54413211373338,-2.3196463090417767
0.5604775843699377,0.0026847999999999998,196.72233791206708,234.54413211373338,-2.3196463090417767
0.5616466377342374,0.0026904,196.74566919556548,234.54413211373338,-2.3196463090417767
0.5699970189078062,0.0027304,196.91177387759367,234.54413211373338,-2.3196463090417767
0.5766773238466611,0.0027624,197.04397532184967,234.54413211373338,-2.3196463090417767
0.5813535373038597,0.0027848,197.136161186369,234.54413211373338,-2.3196463090417767
0.5871988041253579,0.0028128,197.25098785192978,234.54413211373338,-2.3196463090417767
0.5885348651131289,0.0028192,197.27717125303923,234.54413211373338,-2.3196463090417767
0.5923760404529705,0.0028376,197.35231971265287,234.54413211373338,-2.3196463090417767
0.5938791090642129,0.0028447999999999998,197.38167387034486,234.54413211373338,-2.3196463090417767
0.5950481624285126,0.0028504,197.40448485482048,234.54413211373338,-2.3196463090417767
0.5967182386632263,0.0028583999999999997,197.43704167997467,234.54413211373338,-2.3196463090417767
0.5993903606387684,0.0028712,197.48905878201043,234.54413211373338,-2.3196463090417767
0.6008934292500107,0.0028783999999999997,197.5182786566059,234.54413211373338,-2.3196463090417767
0.6020624826143103,0.002884,197.540985522945,234.54413211373338,-2.3196463090417767
0.6067386960715089,0.0029064,197.6316415601495,234.54413211373338,-2.3196463090417767
0.6084087723062226,0.0029143999999999997,197.66395262590382,234.54413211373338,-2.3196463090417767
0.611247901905236,0.002928,197.71880216531136,234.54413211373338,-2.3196463090417767
0.6145880543746636,0.002944,197.7832039914117,234.54413211373338,-2.3196463090417767
0.6159241153624345,0.0029503999999999997,197.8089264834095,234.54413211373338,-2.3196463090417767
0.6217693821839327,0.0029784,197.92120749599854,234.54413211373338,-2.3196463090417767
0.623272450795175,0.0029855999999999997,197.95001312362584,234.54413211373338,-2.3196463090417767
0.6247755194064175,0.0029928,197.97879167184848,234.54413211373338,-2.3196463090417767
0.6252765422768316,0.0029952,197.9883785192696,234.54413211373338,-2.3196463090417767
0.6287837023697305,0.003012,198.0554027656033,234.54413211373338,-2.3196463090417767
0.6304537786044442,0.0030199999999999997,198.0872678154635,234.54413211373338,-2.3196463090417767
0.6319568472156867,0.0030272,198.11591822462748,234.54413211373338,-2.3196463090417767
0.6356310149320569,0.0030448,198.18584090632183,234.54413211373338,-2.3196463090417767
0.6376351064137133,0.0030543999999999997,198.223914105894,234.54413211373338,-2.3196463090417767
0.6453174570933967,0.0030911999999999997,198.3694310677369,234.54413211373338,-2.3196463090417767
0.6468205257046391,0.0030984,198.39782258538204,234.54413211373338,-2.3196463090417767
0.6519977620322518,0.0031232,198.49541924575593,234.54413211373338,-2.3196463090417767
0.6538348458904368,0.003132,198.52997760762594,234.54413211373338,-2.3196463090417767
0.6561729526190362,0.0031432,198.5739062580186,234.54413211373338,-2.3196463090417767
0.6608491660762347,0.0031655999999999998,198.66158084786824,234.54413211373338,-2.3196463090417767
0.6615171965701202,0.0031688,198.67408600967687,234.54413211373338,-2.3196463090417767
0.6735417454600593,0.0032264,198.89834353309593,234.54413211373338,-2.3196463090417767
0.6798880351519715,0.0032568,199.01607187813536,234.54413211373338,-2.3196463090417767
0.6810570885162712,0.0032624,199.03771185256514,234.54413211373338,-2.3196463090417767
0.6837292104918131,0.0032752,199.0871203255373,234.54413211373338,-2.3196463090417767
0.6877373934551262,0.0032944,199.16109206787348,234.54413211373338,-2.3196463090417767
0.689908492560254,0.0033047999999999997,199.20108988584371,234.54413211373338,-2.3196463090417767
0.6917455764184393,0.0033136,199.2348958660837,234.54413211373338,-2.3196463090417767
0.6929146297827389,0.0033192,199.25639053347945,234.54413211373338,-2.3196463090417767
0.6965887974991092,0.0033368,199.32385331077253,234.54413211373338,-2.3196463090417767
0.6985928889807657,0.0033464,199.36059269234153,234.54413211373338,-2.3196463090417767
0.701432018579779,0.0033599999999999997,199.412569864663,234.54413211373338,-2.3196463090417767
0.7044381558022639,0.0033744,199.46751516648936,234.54413211373338,-2.3196463090417767
0.70761130064822,0.0033896,199.52541387129793,234.54413211373338,-2.3196463090417767
0.7086133463890482,0.0033943999999999997,199.54367662431798,234.54413211373338,-2.3196463090417767
0.712955544599304,0.0034151999999999997,199.62269912019337,234.54413211373338,-2.3196463090417767
0.716963727562617,0.0034343999999999998,199.6954765260421,234.54413211373338,-2.3196463090417767
0.7239780477484148,0.0034679999999999997,199.8224563221062,234.54413211373338,-2.3196463090417767
0.728487253582142,0.0034896,199.90383289711716,234.54413211373338,-2.3196463090417767
0.7299903221933843,0.0034968,199.93091473661522,234.54413211373338,-2.3196463090417767
0.7361696042618252,0.0035264,200.0420234734333,234.54413211373338,-2.3196463090417767
0.740511802472081,0.0035472,200.1198823882611,234.54413211373338,-2.3196463090417767
0.7441859701884513,0.0035648,200.18562403715194,234.54413211373338,-2.3196463090417767
0.7476931302813502,0.0035816,200.2482594449865,234.54413211373338,-2.3196463090417767
0.7532043818559055,0.0036079999999999997,200.34645550845505,234.54413211373338,-2.3196463090417767
0.7547074504671479,0.0036152,200.37318756936367,234.54413211373338,-2.3196463090417767
0.7563775267018618,0.0036232,200.40286551912493,234.54413211373338,-2.3196463090417767
0.758715633430461,0.0036344,200.44437175035247,234.54413211373338,-2.3196463090417767
0.7623898011468313,0.003652,200.50949518380227,234.54413211373338,-2.3196463090417767
0.7660639688632015,0.0036696,200.57449633097195,234.54413211373338,-2.3196463090417767
0.768068060344858,0.0036791999999999997,200.60990025166458,234.54413211373338,-2.3196463090417767
0.7722432509316424,0.0036991999999999997,200.68354291621824,234.54413211373338,-2.3196463090417767
0.7814286702225681,0.0037432,200.8450123941359,234.54413211373338,-2.3196463090417767
0.7827647312103391,0.0037495999999999996,200.86843705187204,234.54413211373338,-2.3196463090417767
0.785770868432824,0.003764,200.92108559460038,234.54413211373338,-2.3196463090417767
0.7911151123839079,0.0037895999999999997,201.01448945558178,234.54413211373338,-2.3196463090417767
0.7924511733716789,0.003796,201.0378019310573,234.54413211373338,-2.3196463090417767
0.7966263639584633,0.003816,201.1105548141835,234.54413211373338,-2.3196463090417767
0.8054777680024462,0.0038583999999999997,201.26430094398185,234.54413211373338,-2.3196463090417767
0.8068138289902173,0.0038648,201.28745054590334,234.54413211373338,-2.3196463090417767
0.8113230348239444,0.0038864,201.3654703102647,234.54413211373338,-2.3196463090417767
0.8143291720464292,0.0039008,201.41738955595406,234.54413211373338,-2.3196463090417767
0.8178363321393282,0.0039176,201.47786763017209,234.54413211373338,-2.3196463090417767
0.8223455379730551,0.0039391999999999995,201.55547673812936,234.54413211373338,-2.3196463090417767
0.8238486065842977,0.0039464,201.58130953597137,234.54413211373338,-2.3196463090417767
0.8256856904424827,0.0039552,201.61285800734439,234.54413211373338,-2.3196463090417767
0.8296938734057957,0.0039743999999999995,201.68159617097328,234.54413211373338,-2.3196463090417767
0.8318649725109237,0.0039848,201.71877526472147,234.54413211373338,-2.3196463090417767
0.8347041021099371,0.0039984,201.7673370287913,234.54413211373338,-2.3196463090417767
0.8631010106787353,0.0041344268853770755,202.24955789885777,234.54413211373338,-2.3196463090417767
0.9713435992058925,0.004652930586117224,204.03353131677122,234.54413211373338,-2.3196463090417767
1.051523294411194,0.0050370074014802965,205.30533198886246,234.54413211373338,-2.3196463090417767
1.2359365933833875,0.005920384076815363,208.09479253147856,234.54413211373338,-2.3196463090417767
1.4484127856774365,0.006938187637527506,211.11425519957794,234.54413211373338,-2.3196463090417767
1.4885026332800873,0.007130226045209041,211.66402929608063,234.54413211373338,-2.3196463090417767
1.5726913132456537,0.007533506701340268,212.80010212782685,234.54413211373338,-2.3196463090417767
1.6207991303688347,0.007763952790558111,213.43863194504132,234.54413211373338,-2.3196463090417767
1.7130057798549314,0.008205641128225645,214.64218658797998,234.54413211373338,-2.3196463090417767
1.7250327341357268,0.008263252650530106,214.79728779239312,234.54413211373338,-2.3196463090417767
1.8813831397860648,0.009012202440488098,216.7766873328472,234.54413211373338,-2.3196463090417767
1.945526895950306,0.009319463892778556,217.57005557453377,234.54413211373338,-2.3196463090417767
2.0257065911556076,0.009703540708141629,218.5475621819008,234.54413211373338,-2.3196463090417767
2.0738144082787886,0.009933986797359472,219.1268246066165,234.54413211373338,-2.3196463090417767
2.394533189099995,0.011470294058811763,222.86267797920047,234.54413211373338,-2.3196463090417767
2.474712884305296,0.011854370874174834,223.76546475173467,234.54413211373338,-2.3196463090417767
2.6270543051953688,0.012584116823364673,225.44993044242952,234.54413211373338,-2.3196463090417767
2.8154765889278277,0.013486697339467894,227.4815256472607,234.54413211373338,-2.3196463090417767
2.835521512729153,0.013582716543308662,227.69448479892077,234.54413211373338,-2.3196463090417767
2.9116922231741893,0.013947589517903581,228.49843056221445,234.54413211373338,-2.3196463090417767
2.995880903139756,0.014350870174034807,229.37751853000867,234.54413211373338,-2.3196463090417767
3.0119168421808165,0.014427685537107422,229.5438658948557,234.54413211373338,-2.3196463090417767
3.0199348117013463,0.01446609321864373,229.626910023719,234.54413211373338,-2.3196463090417767
3.0760605983450575,0.01473494698939788,230.2058300574585,234.54413211373338,-2.3196463090417767
3.136195369749034,0.015023004600920185,230.82154871747917,234.54413211373338,-2.3196463090417767
3.264482882077516,0.0156375275055011,232.11990004856412,234.54413211373338,-2.3196463090417767
3.3446625772828176,0.016021604320864174,232.92127123454912,234.54413211373338,-2.3196463090417767
3.456914150570239,0.016559311862372472,234.03071577738592,234.54413211373338,-2.3196463090417767
3.4729500896112997,0.016636127225445087,234.18805325414118,234.54413211373338,-2.3196463090417767
3.5370938457755408,0.016943388677735545,234.81459036849125,234.54413211373338,-2.3196463090417767
3.581192678138457,0.017154630926185237,235.24276642965114,234.54413211373338,-2.3196463090417767
3.597228617179517,0.01723144628925785,235.39795635431992,234.54413211373338,-2.3196463090417767
3.6653813581040233,0.01755791158231646,236.0545260568961,234.54413211373338,-2.3196463090417767
3.697453236186144,0.01771154230846169,236.3618509839886,234.54413211373338,-2.3196463090417767
3.8257407485146264,0.018326065213042607,237.58089428092097,234.54413211373338,-2.3196463090417767
3.845785672315952,0.018422084416883377,237.76992004360176,234.54413211373338,-2.3196463090417767
3.885875519918603,0.018614122824564913,238.146822771074,234.54413211373338,-2.3196463090417767
4.058261864610001,0.01943988797759552,239.75052350297315,234.54413211373338,-2.3196463090417767
4.102360696972917,0.01965113022604521,240.15647707786934,234.54413211373338,-2.3196463090417767
4.138441559815303,0.01982396479295859,240.48735651806848,234.54413211373338,-2.3196463090417767
4.234657194061664,0.020284856971394278,241.36424713490496,234.54413211373338,-2.3196463090417767
4.310827904506701,0.0206497299459892,242.05295337872624,234.54413211373338,-2.3196463090417767
4.330872828308026,0.020745749149829965,242.2334009918208,234.54413211373338,-2.3196463090417767
4.399025569232533,0.02107221444288858,242.8445010879957,234.54413211373338,-2.3196463090417767
4.415061508273594,0.021149029805961193,242.98775140208377,234.54413211373338,-2.3196463090417767
4.467178310157038,0.02139867973594719,243.45191978318275,234.54413211373338,-2.3196463090417767
4.52330409680075,0.02166753350670134,243.94943780803524,234.54413211373338,-2.3196463090417767
4.55537597488287,0.02182116423284657,244.23265280195503,234.54413211373338,-2.3196463090417767
4.683663487211353,0.022435687137427485,245.3578216680483,234.54413211373338,-2.3196463090417767
4.711726380533209,0.022570114022804563,245.60234271052826,234.54413211373338,-2.3196463090417767
4.864067801423282,0.0232998599719944,246.91996210426848,234.54413211373338,-2.3196463090417767
4.900148664265667,0.023472694538907782,247.22966059055787,234.54413211373338,-2.3196463090417767
4.948256481388848,0.023703140628125625,247.64121200804522,234.54413211373338,-2.3196463090417767
5.092579932758391,0.024394478895779156,248.8666038180992,234.54413211373338,-2.3196463090417767
5.1326697803610415,0.024586517303460693,249.20457712123346,234.54413211373338,-2.3196463090417767
5.220867445086873,0.025009001800360073,249.94451547508035,234.54413211373338,-2.3196463090417767
5.285011201251114,0.02531626325265053,250.47959390024184,234.54413211373338,-2.3196463090417767
5.325101048853766,0.025508301660332067,250.81273206702946,234.54413211373338,-2.3196463090417767
5.401271759298801,0.025873174634926985,251.44301214001462,234.54413211373338,-2.3196463090417767
5.525550286867019,0.02646849369873975,252.46397227245143,234.54413211373338,-2.3196463090417767
5.673882722996827,0.027179035807161432,253.67088752715364,234.54413211373338,-2.3196463090417767
5.713972570599478,0.02737107421484297,253.99496045494965,234.54413211373338,-2.3196463090417767
5.7620803877226585,0.027601520304060812,254.38267979651135,234.54413211373338,-2.3196463090417767
5.874331961010081,0.028139227845569114,255.2824815928849,234.54413211373338,-2.3196463090417767
5.974556580016707,0.028619323864772953,256.0802249006436,234.54413211373338,-2.3196463090417767
6.13491597042731,0.0293874774954991,257.3458429423441,234.54413211373338,-2.3196463090417767
6.175005818029961,0.029579515903180635,257.66022335136137,234.54413211373338,-2.3196463090417767
6.243158558954468,0.02990598119623925,258.1928493219196,234.54413211373338,-2.3196463090417767
6.299284345598179,0.0301748349669934,258.62978188525386,234.54413211373338,-2.3196463090417767
6.547841400734614,0.03136547309461893,260.5468020090897,234.54413211373338,-2.3196463090417767
6.595949217857794,0.031595919183836765,260.9145373320162,234.54413211373338,-2.3196463090417767
6.6761289130630965,0.031979995999199845,261.52511352708586,234.54413211373338,-2.3196463090417767
6.720227745426012,0.03219123824764953,261.85971120277253,234.54413211373338,-2.3196463090417767
6.8364883034737,0.03274814962992599,262.7377531251184,234.54413211373338,-2.3196463090417767
6.8605422120352895,0.03286337267453491,262.91868775205245,234.54413211373338,-2.3196463090417767
6.880587135836615,0.032959391878375675,263.0692776933535,234.54413211373338,-2.3196463090417767
7.016892617685628,0.0336123224644929,264.08878948979043,234.54413211373338,-2.3196463090417767
7.181260992856495,0.03439967993598719,265.30798487246454,234.54413211373338,-2.3196463090417767
7.42981804799293,0.03559031806361272,267.1311733852272,234.54413211373338,-2.3196463090417767
7.501979773677701,0.035935987197439484,267.65601024119127,234.54413211373338,-2.3196463090417767
7.654321194567775,0.036665733146629326,268.7575770148712,234.54413211373338,-2.3196463090417767
7.702429011690957,0.036896179235847176,269.10365941921356,234.54413211373338,-2.3196463090417767
7.71445596597175,0.036953790758151625,269.1900481741826,234.54413211373338,-2.3196463090417767
7.850761447820764,0.03760672134426886,270.165477985725,234.54413211373338,-2.3196463090417767
8.003102868710835,0.03833646729345869,271.2478813647711,234.54413211373338,-2.3196463090417767
8.027156777272426,0.03845169033806761,271.4180498545508,234.54413211373338,-2.3196463090417767
8.175489213402233,0.039162232446489295,272.46306147042503,234.54413211373338,-2.3196463090417767
8.24364195432674,0.03948869773954791,272.9407201274064,234.54413211373338,-2.3196463090417767
8.271704847648596,0.03962312462492498,273.1369551746233,234.54413211373338,-2.3196463090417767
8.319812664771778,0.03985357071414283,273.47275511610036,234.54413211373338,-2.3196463090417767
8.4320642380592,0.04039127825565113,274.25335711981484,234.54413211373338,-2.3196463090417767
8.50422596374397,0.04073694738947789,274.7530333710326,234.54413211373338,-2.3196463090417767
8.556342765627418,0.0409865973194639,275.11288284705216,234.54413211373338,-2.3196463090417767
8.66057636939431,0.04148589717943589,275.8300275380638,234.54413211373338,-2.3196463090417767
8.672603323675105,0.04154350870174035,275.9125578303597,234.54413211373338,-2.3196463090417767
8.748774034120142,0.041908381676335274,276.43421694956663,234.54413211373338,-2.3196463090417767
8.808908805524117,0.04219643928785757,276.84480294726353,234.54413211373338,-2.3196463090417767
8.836971698845971,0.042330866173234644,277.0360355174403,234.54413211373338,-2.3196463090417767
8.905124439770479,0.04265733146629326,277.4994741151122,234.54413211373338,-2.3196463090417767
9.00935804353737,0.04315663132626525,278.20559594066304,234.54413211373338,-2.3196463090417767
9.109582662543998,0.0436367273454691,278.88156067465593,234.54413211373338,-2.3196463090417767
9.177735403468503,0.0439631926385277,279.33956078446187,234.54413211373338,-2.3196463090417767
9.261924083434069,0.044366473294658926,279.9034984547332,234.54413211373338,-2.3196463090417767
9.342103778639371,0.044750550110022005,280.4387262078776,234.54413211373338,-2.3196463090417767
9.47440027572812,0.04538427685537108,281.31795179141386,234.54413211373338,-2.3196463090417767
9.486427230008912,0.04544188837767553,281.39764320884126,234.54413211373338,-2.3196463090417767
9.582642864255275,0.04590278055611122,282.0337621871768,234.54413211373338,-2.3196463090417767
9.694894437542699,0.046440488097619526,282.7727612360605,234.54413211373338,-2.3196463090417767
9.743002254665878,0.04667093418683736,283.0884527401103,234.54413211373338,-2.3196463090417767
9.819172965110916,0.04703580716143228,283.58705716972275,234.54413211373338,-2.3196463090417767
9.991559309802314,0.04786157231446289,284.70994104011163,234.54413211373338,-2.3196463090417767
10.03565814216523,0.04807281456291258,284.99597359097265,234.54413211373338,-2.3196463090417767
10.095792913569205,0.04836087217443488,285.3852292643831,234.54413211373338,-2.3196463090417767
10.212053471616892,0.048917783556711336,286.13523571347173,234.54413211373338,-2.3196463090417767
10.288224182061928,0.04928265653130626,286.6248143582854,234.54413211373338,-2.3196463090417767
10.336331999185111,0.04951310262052411,286.93329369892353,234.54413211373338,-2.3196463090417767
10.396466770589086,0.04980116023204641,287.3181065954705,234.54413211373338,-2.3196463090417767
10.504709359116244,0.05031966393278656,288.00858938284074,234.54413211373338,-2.3196463090417767
10.789347277095063,0.05168313662732546,289.8111887127676,234.54413211373338,-2.3196463090417767
10.949706667505666,0.052451290258051605,290.81856772793753,234.54413211373338,-2.3196463090417767
10.965742606546728,0.05252810562112423,290.91898813738425,234.54413211373338,-2.3196463090417767
11.082003164594415,0.05308501700340068,291.64533100599516,234.54413211373338,-2.3196463090417767
11.106057073156006,0.053200240048009606,291.79523713111155,234.54413211373338,-2.3196463090417767
11.274434433087139,0.054006801360272055,292.84105722666186,234.54413211373338,-2.3196463090417767
11.366641082573235,0.054448489697939584,293.4111863931092,234.54413211373338,-2.3196463090417767
11.406730930175888,0.05464052810562113,293.6585057347564,234.54413211373338,-2.3196463090417767
11.462856716819596,0.05490938187637527,294.00418405640823,234.54413211373338,-2.3196463090417767
11.543036412024898,0.05529345869173835,294.4968673625032,234.54413211373338,-2.3196463090417767
11.731458695757357,0.05619603920784157,295.6494491369776,234.54413211373338,-2.3196463090417767
11.823665345243455,0.05663772754550911,296.21084570844056,234.54413211373338,-2.3196463090417767
11.855737223325576,0.05679135827165434,296.4057135133176,234.54413211373338,-2.3196463090417767
12.092267324181213,0.05792438487697539,297.8365678465879,234.54413211373338,-2.3196463090417767
12.2085278822289,0.058481296259251844,298.5358646285358,234.54413211373338,-2.3196463090417767
12.296725546954733,0.05890378075615123,299.0646345280715,234.54413211373338,-2.3196463090417767
12.304743516475261,0.05894218843768753,299.11263105544685,234.54413211373338,-2.3196463090417767
12.384923211680565,0.05932626525305061,299.59192737451315,234.54413211373338,-2.3196463090417767
12.441048998324277,0.059595119023804766,299.9267150144913,234.54413211373338,-2.3196463090417767
12.497174784967985,0.059863972794558906,300.26091413718194,234.54413211373338,-2.3196463090417767
12.621453312536204,0.06045929185837168,300.99885043007686,234.54413211373338,-2.3196463090417767
12.66555214489912,0.06067053410682137,301.2600169130321,234.54413211373338,-2.3196463090417767
12.757758794385216,0.0611122224444889,301.8049490898292,234.54413211373338,-2.3196463090417767
12.773794733426278,0.06118903780756152,301.89956289422395,234.54413211373338,-2.3196463090417767
12.829920520069987,0.06145789157831566,302.23034703669845,234.54413211373338,-2.3196463090417767
12.87802833719317,0.06168833766753351,302.51342737751753,234.54413211373338,-2.3196463090417767
12.994288895240857,0.062245249049809964,303.195840917829,234.54413211373338,-2.3196463090417767
13.038387727603773,0.062456491298259656,303.4540640112624,234.54413211373338,-2.3196463090417767
13.17870219421305,0.06312862572514504,304.27342605674465,234.54413211373338,-2.3196463090417767
13.222801026575963,0.06333986797359471,304.53023624084494,234.54413211373338,-2.3196463090417767
13.35910650842498,0.06399279855971195,305.3219095004733,234.54413211373338,-2.3196463090417767
13.403205340787895,0.06420404080816164,305.5773637902927,234.54413211373338,-2.3196463090417767
13.415232295068687,0.06426165233046609,305.6469762261818,234.54413211373338,-2.3196463090417767
13.499420975034257,0.06466493298659733,306.1335835866179,234.54413211373338,-2.3196463090417767
13.768022953972014,0.06595159031806361,307.67824005046435,234.54413211373338,-2.3196463090417767
13.81212178633493,0.0661628325665133,307.9307129440233,234.54413211373338,-2.3196463090417767
13.860229603458114,0.06639327865573115,308.20577964752573,234.54413211373338,-2.3196463090417767
13.96847219198527,0.0669117823564713,308.8233219766489,234.54413211373338,-2.3196463090417767
14.040633917670041,0.06725745149029806,309.23398034900293,234.54413211373338,-2.3196463090417767
14.184957369039585,0.0679487897579516,310.05283601930614,234.54413211373338,-2.3196463090417767
14.26112807948462,0.0683136627325465,310.4836995404255,234.54413211373338,-2.3196463090417767
14.369370668011777,0.06883216643328666,311.09443856582857,234.54413211373338,-2.3196463090417767
14.40946051561443,0.0690242048409682,311.3201825418529,234.54413211373338,-2.3196463090417767
14.477613256538934,0.0693506701340268,311.7033859633254,234.54413211373338,-2.3196463090417767
14.513694119381322,0.0695235047009402,311.9059735127157,234.54413211373338,-2.3196463090417767
14.561801936504501,0.06975395079015803,312.1757849743382,234.54413211373338,-2.3196463090417767
14.59387381458662,0.06990758151630326,312.3554661762208,234.54413211373338,-2.3196463090417767
14.625945692668742,0.07006121224244849,312.53499344381214,234.54413211373338,-2.3196463090417767
14.706125387874044,0.07044528905781157,312.983141222,234.54413211373338,-2.3196463090417767
14.75824218975749,0.07069493898779756,313.2739263692089,234.54413211373338,-2.3196463090417767
14.766260159278021,0.07073334666933387,313.31862697542806,234.54413211373338,-2.3196463090417767
14.862475793524382,0.07119423884776956,313.8542980062324,234.54413211373338,-2.3196463090417767
14.886529702085973,0.07130946189237848,313.98800423599505,234.54413211373338,-2.3196463090417767
14.946664473489948,0.07159751950390078,314.32190171272225,234.54413211373338,-2.3196463090417767
15.014817214414455,0.0719239847969594,314.6996861519471,234.54413211373338,-2.3196463090417767
15.066934016297902,0.0721736347269454,314.9881290683906,234.54413211373338,-2.3196463090417767
15.163149650544263,0.07263452690538108,315.5196188460796,234.54413211373338,-2.3196463090417767
15.243329345749563,0.07301860372074415,315.9615230160437,234.54413211373338,-2.3196463090417767
15.315491071434337,0.07336427285457092,316.35846229663196,234.54413211373338,-2.3196463090417767
15.415715690440962,0.07384436887377475,316.9085589455526,234.54413211373338,-2.3196463090417767
15.435760614242287,0.07394038807761552,317.0184107064897,234.54413211373338,-2.3196463090417767
15.455805538043615,0.0740364072814563,317.1282068465053,234.54413211373338,-2.3196463090417767
15.511931324687323,0.07430526105221044,317.4353409873311,234.54413211373338,-2.3196463090417767
15.608146958933686,0.07476615323064613,317.96085024869956,234.54413211373338,-2.3196463090417767
15.75247041030323,0.07545749149829967,318.74675146219346,234.54413211373338,-2.3196463090417767
15.808596196946942,0.07572634526905382,319.0516207180847,234.54413211373338,-2.3196463090417767
15.944901678795954,0.07637927585517104,319.79026535625565,234.54413211373338,-2.3196463090417767
15.993009495919132,0.07660972194438888,320.050374979282,234.54413211373338,-2.3196463090417767
16.089225130165495,0.07707061412282457,320.5696805955322,234.54413211373338,-2.3196463090417767
16.157377871090002,0.07739707941588318,320.936789544175,234.54413211373338,-2.3196463090417767
16.23354858153504,0.0777619523904781,321.34637386825597,234.54413211373338,-2.3196463090417767
16.329764215781402,0.07822284456891379,321.86267379173444,234.54413211373338,-2.3196463090417767
16.586339240438367,0.07945189037807562,323.2337061278567,234.54413211373338,-2.3196463090417767
16.742689646088703,0.08020084016803361,324.0651238092745,234.54413211373338,-2.3196463090417767
16.895031066978778,0.08093058611722345,324.87231546890445,234.54413211373338,-2.3196463090417767
16.92309396030063,0.08106501300260052,325.02069854671294,234.54413211373338,-2.3196463090417767
17.059399442149644,0.08171794358871774,325.7400558004559,234.54413211373338,-2.3196463090417767
17.083453350711235,0.08183316663332667,325.86676815724525,234.54413211373338,-2.3196463090417767
17.107507259272825,0.08194838967793559,325.99341095164374,234.54413211373338,-2.3196463090417767
17.115525228793356,0.0819867973594719,326.0356097816389,234.54413211373338,-2.3196463090417767
17.29192055824502,0.08283176635327066,326.9620424935935,234.54413211373338,-2.3196463090417767
17.303947512525813,0.08288937787557511,327.0250738178977,234.54413211373338,-2.3196463090417767
17.34804634488873,0.0831006201240248,327.2560426415701,234.54413211373338,-2.3196463090417767
17.472324872456948,0.08369593918783758,327.9057260739369,234.54413211373338,-2.3196463090417767
17.548495582901985,0.0840608121624325,328.30302843520434,234.54413211373338,-2.3196463090417767
17.604621369545693,0.08432966593318664,328.5953473121256,234.54413211373338,-2.3196463090417767
17.68079207999073,0.08469453890778156,328.9914851023951,234.54413211373338,-2.3196463090417767
17.724890912353647,0.08490578115623125,329.22052382251707,234.54413211373338,-2.3196463090417767
17.797052638038416,0.08525145029005801,329.5948356665199,234.54413211373338,-2.3196463090417767
17.889259287524517,0.08569313862772555,330.0722627705817,234.54413211373338,-2.3196463090417767
17.937367104647695,0.08592358471694339,330.32097413670346,234.54413211373338,-2.3196463090417767
18.045609693174853,0.08644208841768354,330.8796255188633,234.54413211373338,-2.3196463090417767
18.12178040361989,0.08680696139227846,331.2719674284388,234.54413211373338,-2.3196463090417767
18.302184717831818,0.08767113422684537,332.19864165234225,234.54413211373338,-2.3196463090417767
18.44650816920136,0.0883624724944989,332.9374186916708,234.54413211373338,-2.3196463090417767
18.586822635810638,0.08903460692138428,333.65351601194965,234.54413211373338,-2.3196463090417767
18.66700233101594,0.08941868373674736,334.0617678617479,234.54413211373338,-2.3196463090417767
18.77925390430336,0.08995639127825565,334.632173394103,234.54413211373338,-2.3196463090417767
18.83537969094707,0.0902252450490098,334.9168774014549,234.54413211373338,-2.3196463090417767
19.05186486800139,0.0912622524504901,336.01193606540835,234.54413211373338,-2.3196463090417767
19.07591877656298,0.09137747549509903,336.1333089518688,234.54413211373338,-2.3196463090417767
19.18015238032987,0.09187677535507102,336.65856990728133,234.54413211373338,-2.3196463090417767
19.316457862178883,0.09252970594118824,337.34377291527227,234.54413211373338,-2.3196463090417767
19.420691465945772,0.09302900580116023,337.8664800986948,234.54413211373338,-2.3196463090417767
19.49686217639081,0.09339387877575515,338.2477667635547,234.54413211373338,-2.3196463090417767
19.681275475363005,0.09427725545109022,339.16848394340747,234.54413211373338,-2.3196463090417767
19.709338368684858,0.0944116823364673,339.3082975732216,234.54413211373338,-2.3196463090417767
19.80555400293122,0.09487257451490298,339.7870702791751,234.54413211373338,-2.3196463090417767
19.893751667657053,0.09529505901180237,340.2251490038362,234.54413211373338,-2.3196463090417767
20.00199425618421,0.09581356271254252,340.7617572053209,234.54413211373338,-2.3196463090417767
20.122263798992165,0.09638967793558713,341.3566620346329,234.54413211373338,-2.3196463090417767
20.150326692314017,0.0965241048209642,341.49527343504906,234.54413211373338,-2.3196463090417767
20.25456029608091,0.09702340468093619,342.00945797260914,234.54413211373338,-2.3196463090417767
20.322713037005418,0.09734986997399481,342.34509768439307,234.54413211373338,-2.3196463090417767
20.39086577792992,0.09767633526705341,342.6802987073332,234.54413211373338,-2.3196463090417767
20.430955625532576,0.09786837367473496,342.8772716773064,234.54413211373338,-2.3196463090417767
20.559243137861056,0.09848289657931587,343.5065746397625,234.54413211373338,-2.3196463090417767
20.74365643683325,0.09936627325465093,344.4085212397561,234.54413211373338,-2.3196463090417767
20.787755269196165,0.09957751550310062,344.6237401568693,234.54413211373338,-2.3196463090417767
20.84789004060014,0.09986557311462294,344.9169337641545,234.54413211373338,-2.3196463090417767
20.859916994880937,0.09992318463692738,344.9755328866042,234.54413211373338,-2.3196463090417767