File: datasets/aisi_316_L/data/M1/train_21.csv
Time(s),Strain(%),Stress(MPa),Temp(C),Log_SR(s-1)
0.0,0.0,0.0,39.69806514475613,4.74609260575518
3.5887019437146445e-10,1.9999999999999998e-05,3.9084756249999995,39.69806514475613,4.74609260575518
4.306442332457574e-10,2.4e-05,4.69017075,39.69806514475613,4.74609260575518
1.0048365442401004e-09,5.6e-05,10.94373175,39.69806514475613,4.74609260575518
1.6795125096584538e-09,9.36e-05,18.291665925,39.69806514475613,4.74609260575518
1.909189434056191e-09,0.0001064,20.793090324999998,39.69806514475613,4.74609260575518
2.282414436202514e-09,0.0001272,24.857904975,39.69806514475613,4.74609260575518
2.6412846305739785e-09,0.0001472,28.7663806,39.69806514475613,4.74609260575518
3.1149932871443113e-09,0.0001736,33.925568425,39.69806514475613,4.74609260575518
3.2728961726677557e-09,0.0001824,35.6452977,39.69806514475613,4.74609260575518
3.5025730970654932e-09,0.0001952,38.1467221,39.69806514475613,4.74609260575518
3.53128271261521e-09,0.00019679999999999999,38.45940015,39.69806514475613,4.74609260575518
4.306442332457573e-09,0.00023999999999999998,46.90170749999999,39.69806514475613,4.74609260575518
4.694022142378755e-09,0.00026159999999999996,51.12286117499999,39.69806514475613,4.74609260575518
4.765796181253048e-09,0.0002656,51.9045563,39.69806514475613,4.74609260575518
4.938053874551351e-09,0.00027519999999999997,53.780624599999996,39.69806514475613,4.74609260575518
5.210795222273665e-09,0.0002904,56.751066075000004,39.69806514475613,4.74609260575518
5.741923109943431e-09,0.00031999999999999997,62.53560999999999,39.69806514475613,4.74609260575518
6.6175663842098046e-09,0.00036879999999999997,72.072290525,39.69806514475613,4.74609260575518
6.689340423084098e-09,0.0003728,72.85398565,39.69806514475613,4.74609260575518
6.847243308607542e-09,0.0003816,74.573714925,39.69806514475613,4.74609260575518
7.3353067729527335e-09,0.00040879999999999996,79.88924177499999,39.69806514475613,4.74609260575518
7.493209658476177e-09,0.00041759999999999996,81.60897105,39.69806514475613,4.74609260575518
7.665467351774481e-09,0.0004272,83.48503935,39.69806514475613,4.74609260575518
7.737241390648774e-09,0.00043119999999999996,84.26673447499999,39.69806514475613,4.74609260575518
7.981273122821369e-09,0.00044479999999999997,86.92449789999999,39.69806514475613,4.74609260575518
8.454981779391703e-09,0.00047119999999999996,92.083685725,39.69806514475613,4.74609260575518
8.928690435962035e-09,0.0004976,97.24287354999998,39.69806514475613,4.74609260575518
9.043528898160905e-09,0.000504,98.49358575,39.69806514475613,4.74609260575518
9.416753900307227e-09,0.0005248,102.5584004,39.69806514475613,4.74609260575518
1.0062720250175863e-08,0.0005608,109.593656525,39.69806514475613,4.74609260575518
1.0435945252322185e-08,0.0005815999999999999,113.65847117499999,39.69806514475613,4.74609260575518
1.0694331792269641e-08,0.000596,116.472573625,39.69806514475613,4.74609260575518
1.0751751023369074e-08,0.0005991999999999999,117.09792972499999,39.69806514475613,4.74609260575518
1.1096266409965681e-08,0.0006184,120.85006632499999,39.69806514475613,4.74609260575518
1.1555620258761155e-08,0.0006439999999999999,125.85291512499998,39.69806514475613,4.74609260575518
1.1742232759834316e-08,0.0006544,127.88532244999999,39.69806514475613,4.74609260575518
1.192884526090748e-08,0.0006648,129.917729775,39.69806514475613,4.74609260575518
1.1986264492006913e-08,0.000668,130.543085875,39.69806514475613,4.74609260575518
1.2459973148577245e-08,0.0006944,135.7022737,39.69806514475613,4.74609260575518
1.263223084187555e-08,0.000704,137.578342,39.69806514475613,4.74609260575518
1.3077229882896164e-08,0.0007287999999999999,142.42485177499998,39.69806514475613,4.74609260575518
1.3206423152869893e-08,0.000736,143.831903,39.69806514475613,4.74609260575518
1.353658373169164e-08,0.0007544,147.427700575,39.69806514475613,4.74609260575518
1.3780615463864237e-08,0.000768,150.085464,39.69806514475613,4.74609260575518
1.412513085046084e-08,0.0007871999999999999,153.8376006,39.69806514475613,4.74609260575518
1.4469646237057448e-08,0.0008064,157.5897372,39.69806514475613,4.74609260575518
1.495770970140264e-08,0.0008336,162.90526405,39.69806514475613,4.74609260575518
1.502948374027693e-08,0.0008376,163.686959175,39.69806514475613,4.74609260575518
1.5072548163601506e-08,0.0008399999999999999,164.15597624999998,39.69806514475613,4.74609260575518
1.5244805856899808e-08,0.0008495999999999999,166.03204455,39.69806514475613,4.74609260575518
1.5574966435721558e-08,0.000868,169.627842125,39.69806514475613,4.74609260575518
1.5991255861192456e-08,0.0008912,174.16167385,39.69806514475613,4.74609260575518
1.6106094323391325e-08,0.0008975999999999999,175.41238604999998,39.69806514475613,4.74609260575518
1.6192223170040476e-08,0.0009023999999999999,176.35042019999997,39.69806514475613,4.74609260575518
1.6508028941087364e-08,0.0009199999999999999,179.78987874999999,39.69806514475613,4.74609260575518
1.6809479904359395e-08,0.0009368,183.072998275,39.69806514475613,4.74609260575518
1.6967382789882842e-08,0.0009456,184.79272755,39.69806514475613,4.74609260575518
1.767076837085091e-08,0.0009847999999999999,192.45333977499996,39.69806514475613,4.74609260575518
1.778560683304978e-08,0.0009912,193.704051975,39.69806514475613,4.74609260575518
1.807270298854695e-08,0.0010072,196.830832475,39.69806514475613,4.74609260575518
1.8230605874070394e-08,0.001016,198.55056174999999,39.69806514475613,4.74609260575518
1.837415395181898e-08,0.001024,200.11395199999998,39.69806514475613,4.74609260575518
1.867560491509101e-08,0.0010408,203.39707152499997,39.69806514475613,4.74609260575518
1.877608856951502e-08,0.0010463999999999998,204.49144469999996,39.69806514475613,4.74609260575518
1.8847862608389312e-08,0.0010504,205.273139825,39.69806514475613,4.74609260575518
1.919237799498592e-08,0.0010696,209.025276425,39.69806514475613,4.74609260575518
2.0125440500351727e-08,0.0011216,219.18731305,39.69806514475613,4.74609260575518
2.0197214539226022e-08,0.0011256,219.969008175,39.69806514475613,4.74609260575518
2.0455601079173473e-08,0.00114,222.78311062499998,39.69806514475613,4.74609260575518
2.0670923195796353e-08,0.001152,225.128196,39.69806514475613,4.74609260575518
2.0713987619120927e-08,0.0011543999999999999,225.59721307499998,39.69806514475613,4.74609260575518
2.107285781349239e-08,0.0011744,229.50568869999998,39.69806514475613,4.74609260575518
2.130253473789013e-08,0.0011872,232.0071131,39.69806514475613,4.74609260575518
2.161834050893702e-08,0.0012048,235.44657165,39.69806514475613,4.74609260575518
2.169011454781131e-08,0.0012088,236.22826677499998,39.69806514475613,4.74609260575518
2.1876727048884472e-08,0.0012192,238.2606741,39.69806514475613,4.74609260575518
2.2149468396606785e-08,0.0012343999999999999,241.23111557499996,39.69806514475613,4.74609260575518
2.2407854936554242e-08,0.0012488,244.045218025,39.69806514475613,4.74609260575518
2.2551403014302827e-08,0.0012568,245.608608275,39.69806514475613,4.74609260575518
2.2651886668726837e-08,0.0012624,246.70298144999998,39.69806514475613,4.74609260575518
2.272366070760113e-08,0.0012664,247.484676575,39.69806514475613,4.74609260575518
2.3082530901972597e-08,0.0012864,251.3931522,39.69806514475613,4.74609260575518
2.3742852059616087e-08,0.0013231999999999999,258.58474735,39.69806514475613,4.74609260575518
2.392946456068925e-08,0.0013335999999999999,260.617154675,39.69806514475613,4.74609260575518
2.410172225398755e-08,0.0013432,262.493222975,39.69806514475613,4.74609260575518
2.436010879393501e-08,0.0013576,265.307325425,39.69806514475613,4.74609260575518
2.4876881873829917e-08,0.0013863999999999999,270.935530325,39.69806514475613,4.74609260575518
2.4977365528253927e-08,0.001392,272.0299035,39.69806514475613,4.74609260575518
2.503478475935336e-08,0.0013951999999999999,272.65525959999997,39.69806514475613,4.74609260575518
2.5207042452651663e-08,0.0014047999999999999,274.53132789999995,39.69806514475613,4.74609260575518
2.5436719377049402e-08,0.0014176,277.03275229999997,39.69806514475613,4.74609260575518
2.5695105916996856e-08,0.001432,279.84685475,39.69806514475613,4.74609260575518
2.603962130359346e-08,0.0014512,283.59899135,39.69806514475613,4.74609260575518
2.6412846305739785e-08,0.001472,287.663806,39.69806514475613,4.74609260575518
2.6728652076786676e-08,0.0014896,291.10326455,39.69806514475613,4.74609260575518
2.724542515668158e-08,0.0015183999999999998,296.73146944999996,39.69806514475613,4.74609260575518
2.7532521312178756e-08,0.0015344,299.85824995,39.69806514475613,4.74609260575518
2.776219823657649e-08,0.0015471999999999999,302.35967435,39.69806514475613,4.74609260575518
2.7920101122099935e-08,0.0015559999999999999,304.079403625,39.69806514475613,4.74609260575518
2.825026170092168e-08,0.0015743999999999999,307.6752012,39.69806514475613,4.74609260575518
2.846558381754456e-08,0.0015864,310.020286575,39.69806514475613,4.74609260575518
2.9125904975188057e-08,0.0016232,317.211881725,39.69806514475613,4.74609260575518
2.929816266848636e-08,0.0016328,319.087950025,39.69806514475613,4.74609260575518
2.9441710746234945e-08,0.0016408,320.651340275,39.69806514475613,4.74609260575518
2.9800580940606406e-08,0.0016607999999999998,323.784094042975,39.69806514475613,4.74609260575518
2.985800017170584e-08,0.001664,323.81120075651495,39.69806514475613,4.74609260575518
3.005896748055386e-08,0.0016752,323.90591456985265,39.69806514475613,4.74609260575518
3.0288644404951596e-08,0.0016879999999999998,324.01385705035773,39.69806514475613,4.74609260575518
3.061880498377335e-08,0.0017063999999999998,324.1684667745195,39.69806514475613,4.74609260575518
3.076235306152193e-08,0.0017143999999999998,324.2354854455629,39.69806514475613,4.74609260575518
3.0948965562595095e-08,0.0017247999999999999,324.3224276617368,39.69806514475613,4.74609260575518
3.125041652586712e-08,0.0017415999999999998,324.46244213354635,39.69806514475613,4.74609260575518
3.1408319411390567e-08,0.0017503999999999998,324.535572773914,39.69806514475613,4.74609260575518
3.189638287573576e-08,0.0017775999999999998,324.7607116523587,39.69806514475613,4.74609260575518
3.2154769415683214e-08,0.001792,324.8793586933786,39.69806514475613,4.74609260575518
3.242751076340553e-08,0.0018072,325.0041945547245,39.69806514475613,4.74609260575518
3.2585413648928974e-08,0.001816,325.07628078424443,39.69806514475613,4.74609260575518
3.262847807225355e-08,0.0018184,325.09591700487744,39.69806514475613,4.74609260575518
3.29586386510753e-08,0.0018368,325.2461270157064,39.69806514475613,4.74609260575518
3.3044767497724445e-08,0.0018415999999999999,325.2852155799592,39.69806514475613,4.74609260575518
3.3705088655367945e-08,0.0018784,325.5835856930034,39.69806514475613,4.74609260575518
3.3906055964215966e-08,0.0018896,325.67394034703005,39.69806514475613,4.74609260575518
3.407831365751427e-08,0.0018992,325.75122108064755,39.69806514475613,4.74609260575518
3.482476366180691e-08,0.0019408,326.0843590736933,39.69806514475613,4.74609260575518
3.534153674170182e-08,0.0019695999999999997,326.31336343901665,39.69806514475613,4.74609260575518
3.591572905269617e-08,0.0020016,326.56628651009777,39.69806514475613,4.74609260575518
3.63176636703922e-08,0.0020239999999999998,326.7423951643307,39.69806514475613,4.74609260575518
3.6489921363690506e-08,0.0020336,326.81763742904917,39.69806514475613,4.74609260575518
3.663346944143909e-08,0.0020415999999999998,326.8802335560613,39.69806514475613,4.74609260575518
3.677701751918768e-08,0.0020496,326.9427340956134,39.69806514475613,4.74609260575518
3.6992339635810555e-08,0.0020616,327.03630681072707,39.69806514475613,4.74609260575518
3.712153290578429e-08,0.0020688,327.09234848462,39.69806514475613,4.74609260575518
3.7667015601228907e-08,0.0020992,327.328135166404,39.69806514475613,4.74609260575518
3.78105636789775e-08,0.0021072,327.3899624852674,39.69806514475613,4.74609260575518
3.7911047333401505e-08,0.0021127999999999997,327.43318715134234,39.69806514475613,4.74609260575518
3.8126369450024385e-08,0.0021248,327.5256612661908,39.69806514475613,4.74609260575518
3.824120791222325e-08,0.0021311999999999998,327.5748975014157,39.69806514475613,4.74609260575518
3.880104541544274e-08,0.0021624,327.8141032737844,39.69806514475613,4.74609260575518
3.917427041758906e-08,0.0021831999999999997,327.97282641096143,39.69806514475613,4.74609260575518
3.9332173303112504e-08,0.002192,328.03980084502706,39.69806514475613,4.74609260575518
3.9762817536358264e-08,0.002216,328.22192753434376,39.69806514475613,4.74609260575518
3.9949430037431426e-08,0.0022264,328.30061002039497,39.69806514475613,4.74609260575518
4.033700984735261e-08,0.002248,328.4635709516379,39.69806514475613,4.74609260575518
4.089684735057209e-08,0.0022792,328.6978849790491,39.69806514475613,4.74609260575518
4.109781465942011e-08,0.0022903999999999997,328.78169214846076,39.69806514475613,4.74609260575518
4.1169588698294404e-08,0.0022944,328.81158452702493,39.69806514475613,4.74609260575518
4.138491081491728e-08,0.0023063999999999997,328.9011399545222,39.69806514475613,4.74609260575518
4.171507139373902e-08,0.0023247999999999997,329.0381061428433,39.69806514475613,4.74609260575518
4.197345793368649e-08,0.0023392,329.14500238580666,39.69806514475613,4.74609260575518
4.2274908896958515e-08,0.002356,329.2693908464022,39.69806514475613,4.74609260575518
4.246152139803168e-08,0.0023664,329.3462198951215,39.69806514475613,4.74609260575518
4.2748617553528846e-08,0.0023824,329.4641617956699,39.69806514475613,4.74609260575518
4.333716467229804e-08,0.0024151999999999997,329.70498132900894,39.69806514475613,4.74609260575518
4.355248678892093e-08,0.0024272,329.79276691973234,39.69806514475613,4.74609260575518
4.3911356983292394e-08,0.0024472,329.938701027941,39.69806514475613,4.74609260575518
4.4141033907690127e-08,0.00246,330.0318548068666,39.69806514475613,4.74609260575518
4.4184098331014704e-08,0.0024624,330.04930007568106,39.69806514475613,4.74609260575518
4.4356356024313007e-08,0.002472,330.1190149407154,39.69806514475613,4.74609260575518
4.46003877564856e-08,0.0024855999999999997,330.2175971920334,39.69806514475613,4.74609260575518
4.4801355065333626e-08,0.0024968,330.2986247177146,39.69806514475613,4.74609260575518
4.4944903143082204e-08,0.0025047999999999997,330.3564147585125,39.69806514475613,4.74609260575518
4.514587045193023e-08,0.002516,330.437200029299,39.69806514475613,4.74609260575518
4.538990218410282e-08,0.0025296,330.53510812441664,39.69806514475613,4.74609260575518
4.5576514685175985e-08,0.0025399999999999997,330.6098405658387,39.69806514475613,4.74609260575518
4.594973968732231e-08,0.0025608,330.7589483989397,39.69806514475613,4.74609260575518
4.622248103504462e-08,0.0025759999999999997,330.8676132782484,39.69806514475613,4.74609260575518
4.6437803151667505e-08,0.002588,330.9532248033026,39.69806514475613,4.74609260575518
4.663877046051552e-08,0.0025992,331.0329893212536,39.69806514475613,4.74609260575518
4.68540925771384e-08,0.0026111999999999997,331.1183027006579,39.69806514475613,4.74609260575518
4.715554354041043e-08,0.0026279999999999997,331.23748499747325,39.69806514475613,4.74609260575518
4.7184253155960145e-08,0.0026295999999999997,331.2488201730532,39.69806514475613,4.74609260575518
4.7399575272583025e-08,0.0026416,331.33374841873655,39.69806514475613,4.74609260575518
4.757183296588133e-08,0.0026512,331.4015827316141,39.69806514475613,4.74609260575518
4.7873283929153356e-08,0.002668,331.52006272329635,39.69806514475613,4.74609260575518
4.798812239135223e-08,0.0026744,331.56512137999664,39.69806514475613,4.74609260575518
4.816038008465053e-08,0.0026839999999999998,331.6326305960606,39.69806514475613,4.74609260575518
4.824650893129968e-08,0.0026888,331.66634988535054,39.69806514475613,4.74609260575518
4.839005700904827e-08,0.0026968,331.7224965785755,39.69806514475613,4.74609260575518
4.8519250279021996e-08,0.002704,331.77297308812183,39.69806514475613,4.74609260575518
4.8619733933446003e-08,0.0027096,331.8121963648423,39.69806514475613,4.74609260575518
4.877763681896945e-08,0.0027183999999999997,331.8737691281672,39.69806514475613,4.74609260575518
4.8992958935592334e-08,0.0027304,331.9576068570076,39.69806514475613,4.74609260575518
4.9495377207712376e-08,0.0027584,332.1526713712895,39.69806514475613,4.74609260575518
4.978247336320955e-08,0.0027743999999999998,332.26379007811477,39.69806514475613,4.74609260575518
4.9954731056507854e-08,0.002784,332.33034134634636,39.69806514475613,4.74609260575518
5.006956951870672e-08,0.0027903999999999997,332.3746591431638,39.69806514475613,4.74609260575518
5.038537528975361e-08,0.0028079999999999997,332.49632914972483,39.69806514475613,4.74609260575518
5.065811663747592e-08,0.0028231999999999997,332.6011686420224,39.69806514475613,4.74609260575518
5.074424548412507e-08,0.002828,332.6342300852678,39.69806514475613,4.74609260575518
5.10456964473971e-08,0.0028447999999999998,332.74977318603965,39.69806514475613,4.74609260575518
5.1548114719517156e-08,0.0028728,332.94175540591795,39.69806514475613,4.74609260575518
5.27108541492807e-08,0.0029376,333.3832800416914,39.69806514475613,4.74609260575518
5.3184562805851035e-08,0.002964,333.56206949987285,39.69806514475613,4.74609260575518
5.334246569137448e-08,0.0029728,333.62152783188805,39.69806514475613,4.74609260575518
5.351472338467278e-08,0.0029824,333.68631323487966,39.69806514475613,4.74609260575518
5.3945367617918534e-08,0.0030064,333.8479219408216,39.69806514475613,4.74609260575518
5.428988300451514e-08,0.0030256,333.9768469328122,39.69806514475613,4.74609260575518
5.4576979160012315e-08,0.0030415999999999998,334.08404086953476,39.69806514475613,4.74609260575518
5.4792301276635195e-08,0.0030536,334.1642920630718,39.69806514475613,4.74609260575518
5.497891377770836e-08,0.003064,334.233743660506,39.69806514475613,4.74609260575518
5.517988108655637e-08,0.0030751999999999997,334.3084349513242,39.69806514475613,4.74609260575518
5.546697724205355e-08,0.0030911999999999997,334.41495302239554,39.69806514475613,4.74609260575518
5.558181570425241e-08,0.0030976,334.4575000189251,39.69806514475613,4.74609260575518
5.6184717630796476e-08,0.0031311999999999998,334.6803117820002,39.69806514475613,4.74609260575518
5.632826570854507e-08,0.0031392,334.7332245293327,39.69806514475613,4.74609260575518
5.6615361864042236e-08,0.0031552,334.8388925204325,39.69806514475613,4.74609260575518
5.694552244286398e-08,0.0031736,334.960152705425,39.69806514475613,4.74609260575518
5.726132821391087e-08,0.0031912,335.0758844014165,39.69806514475613,4.74609260575518
5.776374648603092e-08,0.0032191999999999998,335.25949129631846,39.69806514475613,4.74609260575518
5.8237455142601256e-08,0.0032456,335.4320367422759,39.69806514475613,4.74609260575518
5.8567615721423e-08,0.003264,335.5519721359536,39.69806514475613,4.74609260575518
5.8926485915794467e-08,0.003284,335.6820380168994,39.69806514475613,4.74609260575518
5.9285356110165924e-08,0.0033039999999999996,335.8117953358816,39.69806514475613,4.74609260575518
5.9457613803464234e-08,0.0033136,335.87397001066756,39.69806514475613,4.74609260575518
5.990261284448485e-08,0.0033384,336.03426363884,39.69806514475613,4.74609260575518
6.021841861553173e-08,0.003356,336.1477387975591,39.69806514475613,4.74609260575518
6.037632150105518e-08,0.0033648,336.2043893262301,39.69806514475613,4.74609260575518
6.070648207987693e-08,0.0033832,336.3226540556737,39.69806514475613,4.74609260575518
6.107970708202325e-08,0.003404,336.45604297617336,39.69806514475613,4.74609260575518
6.145293208416958e-08,0.0034248,336.5891143964769,39.69806514475613,4.74609260575518
6.163954458524274e-08,0.0034352,336.655531882191,39.69806514475613,4.74609260575518
6.194099554851476e-08,0.0034519999999999998,336.76265624973433,39.69806514475613,4.74609260575518
6.215631766513764e-08,0.0034639999999999996,336.83904920777655,39.69806514475613,4.74609260575518
6.228551093511137e-08,0.0034712,336.88483544344325,39.69806514475613,4.74609260575518
6.251518785950911e-08,0.0034839999999999997,336.9661418479441,39.69806514475613,4.74609260575518
6.298889651607944e-08,0.0035104,337.13346930503457,39.69806514475613,4.74609260575518
6.318986382492746e-08,0.0035215999999999997,337.20430836225876,39.69806514475613,4.74609260575518
6.354873401929893e-08,0.0035415999999999998,337.3305885242835,39.69806514475613,4.74609260575518
6.364921767372293e-08,0.0035472,337.3658970916015,39.69806514475613,4.74609260575518
6.406550709919384e-08,0.0035704,337.511944452362,39.69806514475613,4.74609260575518
6.436695806246586e-08,0.0035872,337.6174719425113,39.69806514475613,4.74609260575518
6.455357056353903e-08,0.0035976,337.6827019009263,39.69806514475613,4.74609260575518
6.486937633458591e-08,0.0036152,337.79292377501133,39.69806514475613,4.74609260575518
6.519953691340767e-08,0.0036336,337.9079322107966,39.69806514475613,4.74609260575518
6.534308499115626e-08,0.0036416,337.95786501030926,39.69806514475613,4.74609260575518
6.54292138378054e-08,0.0036463999999999997,337.9878041556868,39.69806514475613,4.74609260575518
6.578808403217687e-08,0.0036663999999999998,338.112385511912,39.69806514475613,4.74609260575518
6.646275999759521e-08,0.003704,338.3458832942101,39.69806514475613,4.74609260575518
6.68503398075164e-08,0.0037256,338.479602248228,39.69806514475613,4.74609260575518
6.690775903861584e-08,0.0037288,338.4993867191993,39.69806514475613,4.74609260575518
6.712308115523871e-08,0.0037408,338.57351958497856,39.69806514475613,4.74609260575518
6.748195134961018e-08,0.0037608,338.69686859238675,39.69806514475613,4.74609260575518
6.753937058070961e-08,0.003764,338.71658066803343,39.69806514475613,4.74609260575518
6.781211192843193e-08,0.0037792,338.8101239194148,39.69806514475613,4.74609260575518
6.818533693057825e-08,0.0038,338.9378930453672,39.69806514475613,4.74609260575518
6.840065904720112e-08,0.003812,339.011481930963,39.69806514475613,4.74609260575518
6.919017347481834e-08,0.0038559999999999996,339.2805383479983,39.69806514475613,4.74609260575518
6.937678597589151e-08,0.0038664,339.34395822899734,39.69806514475613,4.74609260575518
6.979307540136241e-08,0.0038896,339.4851940960642,39.69806514475613,4.74609260575518
6.983613982468698e-08,0.0038919999999999996,339.49978592669106,39.69806514475613,4.74609260575518
7.013759078795901e-08,0.0039088,339.60183066221765,39.69806514475613,4.74609260575518
7.022371963460817e-08,0.0039136,339.6309548653218,39.69806514475613,4.74609260575518
7.052517059788019e-08,0.0039304,339.732780050891,39.69806514475613,4.74609260575518
7.114242733219913e-08,0.0039648,339.94075114237904,39.69806514475613,4.74609260575518
7.167355521986888e-08,0.0039943999999999995,340.1191403545285,39.69806514475613,4.74609260575518
7.315237608812208e-08,0.004076815363072615,340.61313414437984,39.69806514475613,4.74609260575518
7.901030924689614e-08,0.0044032806561312265,342.5328383215328,39.69806514475613,4.74609260575518
8.314532088838371e-08,0.00463372674534907,343.85462284207,39.69806514475613,4.74609260575518
8.590199531604209e-08,0.004787357471494299,344.72159386024146,39.69806514475613,4.74609260575518
8.934783835061507e-08,0.004979395879175836,345.7901961225307,39.69806514475613,4.74609260575518
9.382743429555994e-08,0.005229045809161833,347.1556471884529,39.69806514475613,4.74609260575518
9.727327733013292e-08,0.005421084216843369,348.1887602383125,39.69806514475613,4.74609260575518
1.0382037909582155e-07,0.0057859571914382875,350.11316858239053,39.69806514475613,4.74609260575518
1.110566494684248e-07,0.006189237847569514,352.1858717152571,39.69806514475613,4.74609260575518
1.2001584135831454e-07,0.0066885377075415085,354.6804545945465,39.69806514475613,4.74609260575518
1.2621835882054588e-07,0.007034206841368274,356.36506286778587,39.69806514475613,4.74609260575518
1.348329664069783e-07,0.007514302860572114,358.6521728012026,39.69806514475613,4.74609260575518
1.468934170279837e-07,0.008186437287457491,361.76055672992095,39.69806514475613,4.74609260575518
1.5378510309712967e-07,0.008570514102820564,363.49203905443875,39.69806514475613,4.74609260575518
1.641226322008486e-07,0.009146629325865173,366.033554305231,39.69806514475613,4.74609260575518
1.861760276221156e-07,0.010375675135027004,371.2554969511469,39.69806514475613,4.74609260575518
2.0099315267077942e-07,0.011201440288057612,374.6289295584904,39.69806514475613,4.74609260575518
2.0960776025721183e-07,0.011681536307261452,376.5456152687211,39.69806514475613,4.74609260575518
2.1512110911252857e-07,0.01198879775955191,377.7561866055992,39.69806514475613,4.74609260575518
2.2166821087821725e-07,0.012353670734146829,379.17813462300876,39.69806514475613,4.74609260575518
2.3028281846464966e-07,0.01283376675335067,381.0244080336831,39.69806514475613,4.74609260575518
2.4130951617528317e-07,0.013448289657931586,383.3487915867003,39.69806514475613,4.74609260575518
2.4509994351331345e-07,0.013659531906381276,384.13818167644075,39.69806514475613,4.74609260575518
2.5061329236863024e-07,0.013966793358671735,385.2779388190767,39.69806514475613,4.74609260575518
2.544037197066605e-07,0.014178035607121425,386.0558552402555,39.69806514475613,4.74609260575518
2.6301832729309294e-07,0.014658131626325266,387.8072286448485,39.69806514475613,4.74609260575518
2.6370749590000754e-07,0.014696539307861573,387.9463646248865,39.69806514475613,4.74609260575518
2.712883505760681e-07,0.015119023804760953,389.4676170607767,39.69806514475613,4.74609260575518
2.8610547562473186e-07,0.01594478895779156,392.3939270990106,39.69806514475613,4.74609260575518
2.8851756574893293e-07,0.016079215843168633,392.8646515243362,39.69806514475613,4.74609260575518
2.954092518180789e-07,0.016463292658531706,394.2011949194642,39.69806514475613,4.74609260575518
3.0299010649413944e-07,0.016885777155431086,395.65742443369373,39.69806514475613,4.74609260575518
3.074697024390843e-07,0.017135427085417085,396.5112449617007,39.69806514475613,4.74609260575518
3.116047140805719e-07,0.01736587317463493,397.29509082210933,39.69806514475613,4.74609260575518
3.1573972572205943e-07,0.017596319263852772,398.07489036588163,39.69806514475613,4.74609260575518
3.322797722880097e-07,0.018518103620724147,401.15506148429995,39.69806514475613,4.74609260575518
3.3572561532258263e-07,0.01871014202840568,401.7891709619884,39.69806514475613,4.74609260575518
3.450293915159297e-07,0.01922864572914583,403.488713547525,39.69806514475613,4.74609260575518
3.5261024619199026e-07,0.01965113022604521,404.8603485311994,39.69806514475613,4.74609260575518
3.5502233631619133e-07,0.019785557111422283,405.29435962653946,39.69806514475613,4.74609260575518
3.5984651656459346e-07,0.020054410882176434,406.1589470682719,39.69806514475613,4.74609260575518
3.6639361833028216e-07,0.020419283856771355,407.32511979603936,39.69806514475613,4.74609260575518
3.7362988870288537e-07,0.02082256451290258,408.604632736288,39.69806514475613,4.74609260575518
3.767311474340011e-07,0.020995399079815964,409.15003276866406,39.69806514475613,4.74609260575518
3.7845406895128755e-07,0.02109141828365673,409.45227610754,39.69806514475613,4.74609260575518
3.92926609696494e-07,0.021897979595919183,411.97027581920855,39.69806514475613,4.74609260575518
4.0119663297946917e-07,0.02235887177435487,413.39288825323183,39.69806514475613,4.74609260575518
4.139462522073892e-07,0.023069413882776557,415.5638768956281,39.69806514475613,4.74609260575518
4.156691737246757e-07,0.023165433086617324,415.8552407012297,39.69806514475613,4.74609260575518
4.204933539730778e-07,0.023434286857371475,416.66856426537015,39.69806514475613,4.74609260575518
4.232500284007362e-07,0.023587917583516704,417.13168661986845,39.69806514475613,4.74609260575518
4.3048629877333944e-07,0.02399119823964793,418.3418199803363,39.69806514475613,4.74609260575518
4.335875575044551e-07,0.024164032806561313,418.85801708490413,39.69806514475613,4.74609260575518
4.3979007496668646e-07,0.024509701940388078,419.8861116548903,39.69806514475613,4.74609260575518
4.411684121805157e-07,0.024586517303460693,420.1138073663478,39.69806514475613,4.74609260575518
4.47370929642747e-07,0.024932186437287458,421.13502406056017,39.69806514475613,4.74609260575518
4.5391803140843567e-07,0.025297059411882376,422.2070025677758,39.69806514475613,4.74609260575518
4.683905721536421e-07,0.02610362072414483,424.55547030446763,39.69806514475613,4.74609260575518
4.7459308961587347e-07,0.026449289857971594,425.55327366863725,39.69806514475613,4.74609260575518
4.85619787326507e-07,0.02706381276255251,427.3146785870976,39.69806514475613,4.74609260575518
4.911331361818237e-07,0.02737107421484297,428.189526537801,39.69806514475613,4.74609260575518
5.080177670512314e-07,0.0283120624124825,430.84522370404176,39.69806514475613,4.74609260575518
5.1456486881692e-07,0.028676935387077416,431.8656936405897,39.69806514475613,4.74609260575518
5.283482409552119e-07,0.02944508901780356,433.99764583824657,39.69806514475613,4.74609260575518
5.328278369001567e-07,0.029694738947789557,434.685845305842,39.69806514475613,4.74609260575518
5.342061741139859e-07,0.02977155431086217,434.8971445390992,39.69806514475613,4.74609260575518
5.397195229693027e-07,0.03007881576315263,435.74022388932354,39.69806514475613,4.74609260575518
5.455774561280768e-07,0.030405281056211243,436.63232380746905,39.69806514475613,4.74609260575518
5.486787148591924e-07,0.030578115623124624,437.1030992492323,39.69806514475613,4.74609260575518
5.50401636376479e-07,0.030674134826965394,437.3641927157401,39.69806514475613,4.74609260575518
5.552258166248811e-07,0.030942988597719545,438.09356411946084,39.69806514475613,4.74609260575518
5.648741771216854e-07,0.03148069613922785,439.5449342453051,39.69806514475613,4.74609260575518
5.779683806530627e-07,0.03221044208841768,441.4992801671044,39.69806514475613,4.74609260575518
5.824479765980075e-07,0.03246009201840368,442.16389790109156,39.69806514475613,4.74609260575518
5.907179998809826e-07,0.032920984196839365,443.38567052348435,39.69806514475613,4.74609260575518
5.97954270253586e-07,0.033324264852970596,444.44925968835366,39.69806514475613,4.74609260575518
5.993326074674152e-07,0.03340108021604321,444.65127771438665,39.69806514475613,4.74609260575518
6.017446975916162e-07,0.03353550710142028,445.00437380585083,39.69806514475613,4.74609260575518
6.045013720192745e-07,0.03368913782756551,445.40723698280806,39.69806514475613,4.74609260575518
6.076026307503903e-07,0.0338619723944789,445.85960260986303,39.69806514475613,4.74609260575518
6.217305871921395e-07,0.034649329865973195,447.9090901175461,39.69806514475613,4.74609260575518
6.303451947785719e-07,0.035129425885177035,449.1498659130919,39.69806514475613,4.74609260575518
6.379260494546326e-07,0.03555191038207642,450.23628836628956,39.69806514475613,4.74609260575518
6.417164767926628e-07,0.03576315263052611,450.7776105647958,39.69806514475613,4.74609260575518
6.496419157721805e-07,0.03620484096819364,451.90545305690705,39.69806514475613,4.74609260575518
6.530877588067535e-07,0.03639687937587517,452.394144215586,39.69806514475613,4.74609260575518
6.575673547516983e-07,0.03664652930586117,453.02794199190964,39.69806514475613,4.74609260575518
6.634252879104724e-07,0.036972994598919784,453.8542194868383,39.69806514475613,4.74609260575518
6.689386367657892e-07,0.03728025605121024,454.6292969762398,39.69806514475613,4.74609260575518
6.765194914418498e-07,0.037702740548109626,455.69097283079145,39.69806514475613,4.74609260575518
6.809990873867946e-07,0.03795239047809562,456.31614597168124,39.69806514475613,4.74609260575518
6.816882559937092e-07,0.037990798159631925,456.4121839182724,39.69806514475613,4.74609260575518
6.958162124354585e-07,0.03877815563112623,458.3726940665286,39.69806514475613,4.74609260575518
6.968499653458305e-07,0.03883576715343069,458.51553356673674,39.69806514475613,4.74609260575518
7.023633142011472e-07,0.03914302860572115,459.27595307582493,39.69806514475613,4.74609260575518
7.147683491256098e-07,0.039834366873374674,460.97843659163675,39.69806514475613,4.74609260575518
7.171804392498107e-07,0.039968793758751744,461.3081326981026,39.69806514475613,4.74609260575518
7.185587764636401e-07,0.040045609121824366,461.4963363060037,39.69806514475613,4.74609260575518
7.192479450705546e-07,0.04008401680336067,461.5903853082763,39.69806514475613,4.74609260575518
7.344096544226758e-07,0.04092898579715944,463.65065514329495,39.69806514475613,4.74609260575518
7.361325759399622e-07,0.0410250050010002,463.8837223759436,39.69806514475613,4.74609260575518
7.419905090987361e-07,0.041351470294058806,464.6745644937769,39.69806514475613,4.74609260575518
7.523280382024551e-07,0.04192758551710342,466.0642536746045,39.69806514475613,4.74609260575518
7.609426457888876e-07,0.042407681536307265,467.2166481979856,39.69806514475613,4.74609260575518
7.630101516096315e-07,0.04252290458091619,467.492464428153,39.69806514475613,4.74609260575518
7.664559946442045e-07,0.04271494298859772,467.951511305136,39.69806514475613,4.74609260575518
7.719693434995212e-07,0.04302220444088818,468.6843157043945,39.69806514475613,4.74609260575518
7.733476807133502e-07,0.04309901980396079,468.8671975304675,39.69806514475613,4.74609260575518
7.802393667824964e-07,0.04348309661932387,469.77970677660136,39.69806514475613,4.74609260575518
7.957456604380747e-07,0.04434726945389078,471.8214371298441,39.69806514475613,4.74609260575518
7.991915034726476e-07,0.044539307861572314,472.27304091624165,39.69806514475613,4.74609260575518
8.047048523279644e-07,0.04484656931386277,472.9940306416331,39.69806514475613,4.74609260575518
8.133194599143969e-07,0.04532666533306662,474.1167322398891,39.69806514475613,4.74609260575518
8.174544715558843e-07,0.045557111422284455,474.65398087204176,39.69806514475613,4.74609260575518
8.229678204112011e-07,0.04586437287457491,475.36866659145204,39.69806514475613,4.74609260575518
8.295149221768898e-07,0.046229245849169834,476.2149351383621,39.69806514475613,4.74609260575518
8.370957768529503e-07,0.04665173034606922,477.1915774933871,39.69806514475613,4.74609260575518
8.477778902601265e-07,0.047247049409881975,478.56192083553265,39.69806514475613,4.74609260575518
8.519129019016142e-07,0.047477495499099825,479.09056640347967,39.69806514475613,4.74609260575518
8.643179368260768e-07,0.04816883376675335,480.6705312126367,39.69806514475613,4.74609260575518
8.756892188401677e-07,0.048802560512102425,482.1110804240802,39.69806514475613,4.74609260575518
8.860267479438864e-07,0.04937867573514702,483.4143522152515,39.69806514475613,4.74609260575518
8.905063438888315e-07,0.04962832566513303,483.9772601893459,39.69806514475613,4.74609260575518
9.067018061513244e-07,0.05053090618123625,486.0032397666784,39.69806514475613,4.74609260575518
9.163501666481286e-07,0.051068613722744544,487.20349853579427,39.69806514475613,4.74609260575518
9.215189311999882e-07,0.05135667133426686,487.84446642291744,39.69806514475613,4.74609260575518
9.301335387864205e-07,0.05183676735347069,488.90963917405844,39.69806514475613,4.74609260575518
9.308227073933353e-07,0.05187517503500701,488.99468642585083,39.69806514475613,4.74609260575518
9.380589777659386e-07,0.05227845569113823,489.8862049358872,39.69806514475613,4.74609260575518
9.477073382627427e-07,0.052816163232646526,491.0707352359266,39.69806514475613,4.74609260575518
9.54943608635346e-07,0.05321944388877775,491.9560489496475,39.69806514475613,4.74609260575518
9.614907104010345e-07,0.05358431686337267,492.7547951573233,39.69806514475613,4.74609260575518
9.71139070897839e-07,0.05412202440488098,493.9280393565528,39.69806514475613,4.74609260575518
9.825103529119298e-07,0.05475575115023004,495.3049712796623,39.69806514475613,4.74609260575518
9.866453645534175e-07,0.05498619723944789,495.8041310567254,39.69806514475613,4.74609260575518
9.9905039947788e-07,0.05567753550710142,497.296738016126,39.69806514475613,4.74609260575518
1.002496242512453e-06,0.05586957391478296,497.710066061406,39.69806514475613,4.74609260575518
1.00800959136777e-06,0.05617683536707342,498.3702403144838,39.69806514475613,4.74609260575518
1.0193808733818606e-06,0.05681056211242248,499.7274188272584,39.69806514475613,4.74609260575518
1.029029233878665e-06,0.05734826965393079,500.8743403262884,39.69806514475613,4.74609260575518
1.0366100885547254e-06,0.05777075415083016,501.772553341963,39.69806514475613,4.74609260575518
1.0445355275342435e-06,0.058212442488497704,502.70885939076084,39.69806514475613,4.74609260575518
1.0490151234791883e-06,0.0584620924184837,503.236850201856,39.69806514475613,4.74609260575518
1.0552176409414196e-06,0.05880776155231046,503.9664650424232,39.69806514475613,4.74609260575518
1.0665889229555105e-06,0.05944148829765954,505.29976294534885,39.69806514475613,4.74609260575518
1.069690181686626e-06,0.05961432286457291,505.6624260388323,39.69806514475613,4.74609260575518
1.0845073067352898e-06,0.06044008801760352,507.38952151959217,39.69806514475613,4.74609260575518
1.086919396859491e-06,0.0605745149029806,507.66980329327276,39.69806514475613,4.74609260575518
1.0931219143217224e-06,0.060920184036807365,508.3894162384291,39.69806514475613,4.74609260575518
1.0969123416597527e-06,0.06113142628525706,508.82839583523145,39.69806514475613,4.74609260575518
1.1079390393703862e-06,0.06174594918983797,510.10207607543396,39.69806514475613,4.74609260575518
1.1127632196187881e-06,0.062014802960592114,510.65775557795206,39.69806514475613,4.74609260575518
1.1158644783499039e-06,0.0621876375275055,511.01448204925697,39.69806514475613,4.74609260575518
1.1237899173294216e-06,0.06262932586517303,511.9243641494626,39.69806514475613,4.74609260575518
1.1324045249158542e-06,0.06310942188437688,512.9105326412266,39.69806514475613,4.74609260575518
1.136884120860799e-06,0.06335907181436287,513.4221837189435,39.69806514475613,4.74609260575518
1.1444649755368596e-06,0.06378155631126226,514.2862672334683,39.69806514475613,4.74609260575518
1.149289155785262e-06,0.06405041008201641,514.8349765309442,39.69806514475613,4.74609260575518
1.1520458302129203e-06,0.06420404080816164,515.1481213944888,39.69806514475613,4.74609260575518
1.1592821005855235e-06,0.06460732146429286,515.9687394244953,39.69806514475613,4.74609260575518
1.169275045385785e-06,0.06516423284656932,517.0986972027174,39.69806514475613,4.74609260575518
1.1754775628480163e-06,0.06550990198039608,517.7981563041023,39.69806514475613,4.74609260575518
1.1792679901860466e-06,0.06572114422884577,518.2248949936502,39.69806514475613,4.74609260575518
1.1851259233448208e-06,0.06604760952190439,518.8833495605421,39.69806514475613,4.74609260575518
1.1913284408070521e-06,0.06639327865573115,519.5791547482103,39.69806514475613,4.74609260575518
1.2044226443384295e-06,0.06712302460492099,521.0434541839196,39.69806514475613,4.74609260575518
1.2092468245868317e-06,0.06739187837567515,521.581366190692,39.69806514475613,4.74609260575518
1.2123480833179472e-06,0.06756471294258852,521.9267248721441,39.69806514475613,4.74609260575518
1.2140710048352336e-06,0.06766073214642929,522.1184419246429,39.69806514475613,4.74609260575518
1.2216518595112943e-06,0.06808321664332867,522.9607395517002,39.69806514475613,4.74609260575518
1.2302664670977268e-06,0.06856331266253252,523.9154255208008,39.69806514475613,4.74609260575518
1.2319893886150133e-06,0.06865933186637328,524.106049473413,39.69806514475613,4.74609260575518
1.2464619293602197e-06,0.06946589317863573,525.7032066669045,39.69806514475613,4.74609260575518
1.2485294351809634e-06,0.06958111622324466,525.9307801914873,39.69806514475613,4.74609260575518
1.2785082695817483e-06,0.07125185037007402,529.2142542568691,39.69806514475613,4.74609260575518
1.2916024731131257e-06,0.07198159631926386,530.638978405254,39.69806514475613,4.74609260575518
1.2957374847546131e-06,0.0722120424084817,531.0877195274442,39.69806514475613,4.74609260575518
1.3026291708237592e-06,0.07259611922384478,531.8343822834547,39.69806514475613,4.74609260575518
1.3274392406726846e-06,0.07397879575915184,534.509705308465,39.69806514475613,4.74609260575518
1.3319188366176294e-06,0.07422844568913783,534.9906641261022,39.69806514475613,4.74609260575518
1.3332971738314586e-06,0.07430526105221044,535.1385244820196,39.69806514475613,4.74609260575518
1.3377767697764034e-06,0.07455491098219644,535.6186594583949,39.69806514475613,4.74609260575518
1.3436347029351776e-06,0.07488137627525505,536.2455832401456,39.69806514475613,4.74609260575518
1.3488034674870368e-06,0.07516943388677735,536.7978665923142,39.69806514475613,4.74609260575518
1.361553086714957e-06,0.07587997599519905,538.1566482399663,39.69806514475613,4.74609260575518
1.3636205925357006e-06,0.07599519903980796,538.3765227715445,39.69806514475613,4.74609260575518
1.3687893570875603e-06,0.07628325665133028,538.9256410515684,39.69806514475613,4.74609260575518
1.3774039646739925e-06,0.07676335267053411,539.8390445062909,39.69806514475613,4.74609260575518
1.3815389763154803e-06,0.07699379875975196,540.2766865733247,39.69806514475613,4.74609260575518
1.40324778743329e-06,0.07820364072814563,542.5659800025952,39.69806514475613,4.74609260575518
1.405659877557491e-06,0.0783380676135227,542.8194904402359,39.69806514475613,4.74609260575518
1.4153082380542953e-06,0.07887577515503101,543.8318402086045,39.69806514475613,4.74609260575518
1.4266795200683863e-06,0.07950950190038009,545.0215178391628,39.69806514475613,4.74609260575518
1.4290916101925872e-06,0.07964392878575716,545.2733976329893,39.69806514475613,4.74609260575518
1.4315037003167883e-06,0.07977835567113423,545.5251116786575,39.69806514475613,4.74609260575518
1.4432195666343367e-06,0.08043128625725146,546.7453776436088,39.69806514475613,4.74609260575518
1.4490774997931104e-06,0.08075775155031006,547.3540614379044,39.69806514475613,4.74609260575518
1.4521787585242262e-06,0.08093058611722345,547.6759172571942,39.69806514475613,4.74609260575518
1.4556246015587991e-06,0.08112262452490498,548.0332205993351,39.69806514475613,4.74609260575518
1.4583812759864576e-06,0.08127625525105021,548.3188258212512,39.69806514475613,4.74609260575518
1.4673404678763471e-06,0.0817755551110222,549.2455921039771,39.69806514475613,4.74609260575518
1.4756104911593224e-06,0.08223644728945789,550.099111821657,39.69806514475613,4.74609260575518
1.4776779969800661e-06,0.08235167033406682,550.312200004581,39.69806514475613,4.74609260575518
1.4800900871042672e-06,0.08248609721944389,550.5606559803258,39.69806514475613,4.74609260575518
1.4835359301388403e-06,0.08267813562712543,550.9153193322262,39.69806514475613,4.74609260575518
1.49249512202873e-06,0.08317743548709743,551.8359437330292,39.69806514475613,4.74609260575518
1.50524474125665e-06,0.08388797759551911,553.1423557985757,39.69806514475613,4.74609260575518
1.5135147645396252e-06,0.0843488697739548,553.987451323165,39.69806514475613,4.74609260575518
1.5197172820018563e-06,0.08469453890778156,554.6200916295281,39.69806514475613,4.74609260575518
1.522818540732972e-06,0.08486737347469495,554.93603410295,39.69806514475613,4.74609260575518
1.53074397971249e-06,0.08530906181236247,555.7423047117668,39.69806514475613,4.74609260575518
1.5345344070505203e-06,0.08552030406081217,556.1273367442792,39.69806514475613,4.74609260575518
1.5359127442643495e-06,0.08559711942388479,556.2672564076228,39.69806514475613,4.74609260575518
1.539014002995465e-06,0.08576995399079816,556.5818967269106,39.69806514475613,4.74609260575518
1.5431490146369527e-06,0.08600040008001601,557.0010327780292,39.69806514475613,4.74609260575518
1.5476286105818977e-06,0.08625005001000201,557.4546028547068,39.69806514475613,4.74609260575518
1.5545202966510435e-06,0.08663412682536507,558.1514044658212,39.69806514475613,4.74609260575518
1.5565878024717873e-06,0.086749349869974,558.3602098845296,39.69806514475613,4.74609260575518
1.562101151327104e-06,0.08705661132226446,558.916496214446,39.69806514475613,4.74609260575518
1.5665807472720489e-06,0.08730626125225045,559.3679152512126,39.69806514475613,4.74609260575518
1.58174245662417e-06,0.08815123024604922,560.8920734346535,39.69806514475613,4.74609260575518
1.599316256100492e-06,0.08913062612522504,562.6515998989177,39.69806514475613,4.74609260575518
1.6058633578661807e-06,0.08949549909981996,563.3051798573081,39.69806514475613,4.74609260575518
1.616545471273357e-06,0.09009081816363274,564.3693205786167,39.69806514475613,4.74609260575518
1.618957561397558e-06,0.0902252450490098,564.6092304633877,39.69806514475613,4.74609260575518
1.6251600788597894e-06,0.09057091418283657,565.2255023600209,39.69806514475613,4.74609260575518
1.636186776570423e-06,0.09118543708741748,566.3188366965527,39.69806514475613,4.74609260575518
1.6382542823911668e-06,0.09130066013202641,566.5235165764892,39.69806514475613,4.74609260575518
1.6417001254257397e-06,0.09149269853970794,566.8644259835289,39.69806514475613,4.74609260575518
1.64549055276377e-06,0.09170394078815763,567.2391041741821,39.69806514475613,4.74609260575518
1.652382238832916e-06,0.09208801760352071,567.9194760182805,39.69806514475613,4.74609260575518
1.6634089365435496e-06,0.09270254050810163,569.0057735734786,39.69806514475613,4.74609260575518
1.679259814502585e-06,0.09358591718343669,570.5624189912825,39.69806514475613,4.74609260575518
1.688563590695932e-06,0.09410442088417684,571.4734333438198,39.69806514475613,4.74609260575518
1.692009433730505e-06,0.09429645929185837,571.8103490072023,39.69806514475613,4.74609260575518
1.7006240413169376e-06,0.09477655531106222,572.6514695513217,39.69806514475613,4.74609260575518
1.7088940645999127e-06,0.0952374474894979,573.457383344661,39.69806514475613,4.74609260575518
1.7144074134552295e-06,0.09554470894178836,573.9938143398056,39.69806514475613,4.74609260575518
1.7223328524347472e-06,0.09598639727945589,574.7637566999629,39.69806514475613,4.74609260575518
1.7292245385038933e-06,0.09637047409481897,575.432149326355,39.69806514475613,4.74609260575518
1.7557575298701053e-06,0.0978491698339668,577.9958196300444,39.69806514475613,4.74609260575518
1.7633383845461658e-06,0.09827165433086618,578.7255158880064,39.69806514475613,4.74609260575518
1.7864255328778046e-06,0.09955831166233248,580.9402727487609,39.69806514475613,4.74609260575518
1.7905605445192923e-06,0.09978875775155031,581.3357640700981,39.69806514475613,4.74609260575518
1.7940063875538652e-06,0.09998079615923185,581.6650681506458,39.69806514475613,4.74609260575518