File: datasets/aisi_316_L/data/M1/train_98.csv
Time(s),Strain(%),Stress(MPa),Temp(C),Log_SR(s-1)
0.0,0.0,0.0,258.2079920906133,-2.9770373837507282
0.01062320118698706,1.12e-05,2.028997425,258.2079920906133,-2.9770373837507282
0.02124640237397412,2.24e-05,4.05799485,258.2079920906133,-2.9770373837507282
0.0607040067827832,6.4e-05,11.594270999999999,258.2079920906133,-2.9770373837507282
0.07132720796977025,7.52e-05,13.623268425,258.2079920906133,-2.9770373837507282
0.07512120839369421,7.92e-05,14.3479103625,258.2079920906133,-2.9770373837507282
0.09333241042852916,9.839999999999999e-05,17.826191662499998,258.2079920906133,-2.9770373837507282
0.10395561161551622,0.0001096,19.855189087499998,258.2079920906133,-2.9770373837507282
0.10774961203944018,0.0001136,20.579831025,258.2079920906133,-2.9770373837507282
0.12444321390470556,0.0001312,23.76825555,258.2079920906133,-2.9770373837507282
0.1578304176352363,0.00016639999999999998,30.145104599999996,258.2079920906133,-2.9770373837507282
0.17755921983964085,0.0001872,33.913242675,258.2079920906133,-2.9770373837507282
0.19349402162012144,0.000204,36.9567388125,258.2079920906133,-2.9770373837507282
0.20032322238318453,0.00021119999999999998,38.261094299999996,258.2079920906133,-2.9770373837507282
0.22232842484194346,0.00023439999999999998,42.4640175375,258.2079920906133,-2.9770373837507282
0.22991642568979134,0.00024239999999999998,43.9133014125,258.2079920906133,-2.9770373837507282
0.242057227046348,0.00025519999999999997,46.232155612499994,258.2079920906133,-2.9770373837507282
0.2807560313703723,0.000296,53.623503375,258.2079920906133,-2.9770373837507282
0.29137923255735937,0.0003072,55.6525008,258.2079920906133,-2.9770373837507282
0.33690723764444674,0.00035519999999999996,64.34820404999999,258.2079920906133,-2.9770373837507282
0.3475304388314338,0.00036639999999999996,66.37720147499999,258.2079920906133,-2.9770373837507282
0.3513244392553578,0.0003704,67.1018434125,258.2079920906133,-2.9770373837507282
0.35360083950971216,0.0003728,67.536628575,258.2079920906133,-2.9770373837507282
0.3702944413749775,0.0003904,70.7250531,258.2079920906133,-2.9770373837507282
0.37408844179890144,0.0003944,71.44969503749999,258.2079920906133,-2.9770373837507282
0.37940004239239494,0.00039999999999999996,72.46419374999999,258.2079920906133,-2.9770373837507282
0.38319404281631897,0.000404,73.1888356875,258.2079920906133,-2.9770373837507282
0.393817244003306,0.00041519999999999995,75.21783311249999,258.2079920906133,-2.9770373837507282
0.4143048462924953,0.0004368,79.130899575,258.2079920906133,-2.9770373837507282
0.42644564764905196,0.0004496,81.44975377499999,258.2079920906133,-2.9770373837507282
0.4416216493447478,0.0004656,84.348321525,258.2079920906133,-2.9770373837507282
0.4545212507860892,0.0004792,86.8121041125,258.2079920906133,-2.9770373837507282
0.4659032520578611,0.0004912,88.986029925,258.2079920906133,-2.9770373837507282
0.469697252481785,0.0004952,89.7106718625,258.2079920906133,-2.9770373837507282
0.5015668560427462,0.0005288,95.79766413749999,258.2079920906133,-2.9770373837507282
0.5190192579927964,0.0005472,99.13101705,258.2079920906133,-2.9770373837507282
0.5334364596037073,0.0005624,101.88465641250001,258.2079920906133,-2.9770373837507282
0.5470948611298335,0.0005767999999999999,104.49336738749999,258.2079920906133,-2.9770373837507282
0.574411664182086,0.0006056,109.71078933749999,258.2079920906133,-2.9770373837507282
0.5933816663017057,0.0006255999999999999,113.33399902499998,258.2079920906133,-2.9770373837507282
0.6062812677430471,0.0006391999999999999,115.79778161249999,258.2079920906133,-2.9770373837507282
0.6229748696083125,0.0006567999999999999,118.98620613749999,258.2079920906133,-2.9770373837507282
0.6404272715583627,0.0006751999999999999,122.31955904999998,258.2079920906133,-2.9770373837507282
0.6556032732540585,0.0006912,125.2181268,258.2079920906133,-2.9770373837507282
0.6631912741019065,0.0006992,126.667410675,258.2079920906133,-2.9770373837507282
0.6685028746954,0.0007048,127.6819093875,258.2079920906133,-2.9770373837507282
0.6745732753736783,0.0007111999999999999,128.8413364875,258.2079920906133,-2.9770373837507282
0.7094780792737786,0.000748,135.50804231249998,258.2079920906133,-2.9770373837507282
0.7178248802064113,0.0007568,137.102254575,258.2079920906133,-2.9770373837507282
0.7276892813086137,0.0007672,138.9863236125,258.2079920906133,-2.9770373837507282
0.7633528852934987,0.0008047999999999999,145.797957825,258.2079920906133,-2.9770373837507282
0.7853580877522576,0.000828,150.00088106249999,258.2079920906133,-2.9770373837507282
0.7937048886848903,0.0008368,151.595093325,258.2079920906133,-2.9770373837507282
0.802051689617523,0.0008456,153.1893055875,258.2079920906133,-2.9770373837507282
0.820262891652358,0.0008648,156.6675868875,258.2079920906133,-2.9770373837507282
0.8498560949589647,0.000896,162.319794,258.2079920906133,-2.9770373837507282
0.8650320966546605,0.0009119999999999999,165.21836174999999,258.2079920906133,-2.9770373837507282
0.8832432986894956,0.0009312,168.69664305,258.2079920906133,-2.9770373837507282
0.896142900130837,0.0009448,171.1604256375,258.2079920906133,-2.9770373837507282
0.9158717023352415,0.0009655999999999999,174.9285637125,258.2079920906133,-2.9770373837507282
0.9447061055570635,0.000996,179.01031293854365,258.2079920906133,-2.9770373837507282
0.9507765062353417,0.0010023999999999999,179.04757991597137,258.2079920906133,-2.9770373837507282
0.968228908185392,0.0010207999999999999,179.15420904658342,258.2079920906133,-2.9770373837507282
0.9712641085245312,0.001024,179.1726764648799,258.2079920906133,-2.9770373837507282
1.0076865125942012,0.0010624,179.39255832479986,258.2079920906133,-2.9770373837507282
1.0160333135268338,0.0010712,179.44250875198128,258.2079920906133,-2.9770373837507282
1.0243801144594664,0.00108,179.49229939776288,258.2079920906133,-2.9770373837507282
1.050938117426934,0.001108,179.64968171732883,258.2079920906133,-2.9770373837507282
1.06611411912263,0.001124,179.73891794501773,258.2079920906133,-2.9770373837507282
1.0759785202248322,0.0011344,179.79665594979423,258.2079920906133,-2.9770373837507282
1.0812901208183257,0.00114,179.82766012145493,258.2079920906133,-2.9770373837507282
1.084325321157465,0.0011432,179.84535012218154,258.2079920906133,-2.9770373837507282
1.1070893237010087,0.0011672,179.9774150248042,258.2079920906133,-2.9770373837507282
1.1184713249727805,0.0011792,180.04305001292266,258.2079920906133,-2.9770373837507282
1.1389589272619698,0.0012008,180.1605402846047,258.2079920906133,-2.9770373837507282
1.152617328788096,0.0012152,180.23840953992575,258.2079920906133,-2.9770373837507282
1.167034530399007,0.0012304,180.32021545854212,258.2079920906133,-2.9770373837507282
1.1844869323490572,0.0012488,180.41871822159325,258.2079920906133,-2.9770373837507282
1.1905573330273354,0.0012552,180.45284716017684,258.2079920906133,-2.9770373837507282
1.206492134807816,0.001272,180.5421142763448,258.2079920906133,-2.9770373837507282
1.217874136079588,0.001284,180.60559521177615,258.2079920906133,-2.9770373837507282
1.2277385371817902,0.0012944,180.6604250925732,258.2079920906133,-2.9770373837507282
1.24670853930141,0.0013143999999999999,180.76538666627735,258.2079920906133,-2.9770373837507282
1.2550553402340425,0.0013231999999999999,180.81137223508085,258.2079920906133,-2.9770373837507282
1.2816133432015102,0.0013511999999999999,180.95690272416408,258.2079920906133,-2.9770373837507282
1.3362469493060152,0.0014088,181.25263244416632,258.2079920906133,-2.9770373837507282
1.3544581513408502,0.001428,181.35015605307063,258.2079920906133,-2.9770373837507282
1.3612873521039133,0.0014352,181.38659539500532,258.2079920906133,-2.9770373837507282
1.393915755749659,0.0014696,181.55971990289348,258.2079920906133,-2.9770373837507282
1.4007449565127224,0.0014768,181.59575443634967,258.2079920906133,-2.9770373837507282
1.415920958208418,0.0014927999999999999,181.6755867760437,258.2079920906133,-2.9770373837507282
1.4257853593106202,0.0015032,181.72729890820622,258.2079920906133,-2.9770373837507282
1.4455141615150249,0.001524,181.83030646605772,258.2079920906133,-2.9770373837507282
1.4902833665173276,0.0015712,182.06204190918228,258.2079920906133,-2.9770373837507282
1.502424167873884,0.001584,182.12441540208775,258.2079920906133,-2.9770373837507282
1.5236705702478583,0.0016064,182.2330980691593,258.2079920906133,-2.9770373837507282
1.5479521729609715,0.001632,182.35658570156798,258.2079920906133,-2.9770373837507282
1.560851774402313,0.0016455999999999999,182.4218811187796,258.2079920906133,-2.9770373837507282
1.5654045749110217,0.0016504,182.4448762689196,258.2079920906133,-2.9770373837507282
1.5874097773697806,0.0016736,182.55565389103143,258.2079920906133,-2.9770373837507282
1.5912037777937047,0.0016776,182.57469279090355,258.2079920906133,-2.9770373837507282
1.6063797794894004,0.0016936,182.6506720129525,258.2079920906133,-2.9770373837507282
1.6185205808459568,0.0017063999999999998,182.711254024055,258.2079920906133,-2.9770373837507282
1.6215557811850962,0.0017096,182.7263718027894,258.2079920906133,-2.9770373837507282
1.6359729827960072,0.0017247999999999999,182.79803108492715,258.2079920906133,-2.9770373837507282
1.658736985339551,0.0017488,182.91067790296842,258.2079920906133,-2.9770373837507282
1.6754305872048163,0.0017664,182.9929027499858,258.2079920906133,-2.9770373837507282
1.6822597879678793,0.0017736,183.02644802252522,258.2079920906133,-2.9770373837507282
1.708817790935347,0.0018016,183.1564001048647,258.2079920906133,-2.9770373837507282
1.7247525927158276,0.0018184,183.23399331550942,258.2079920906133,-2.9770373837507282
1.7285465931397515,0.0018223999999999998,183.2524266208055,258.2079920906133,-2.9770373837507282
1.7588985965311432,0.0018544,183.3993292558422,258.2079920906133,-2.9770373837507282
1.7642101971246367,0.0018599999999999999,183.42493524001645,258.2079920906133,-2.9770373837507282
1.7717981979724846,0.0018679999999999999,183.46146312303847,258.2079920906133,-2.9770373837507282
1.7786273987355476,0.0018751999999999998,183.49428608709394,258.2079920906133,-2.9770373837507282
1.799115001024737,0.0018968,183.59246133784438,258.2079920906133,-2.9770373837507282
1.8188438032291416,0.0019176,183.6865892029588,258.2079920906133,-2.9770373837507282
1.824155403822635,0.0019232,183.71186318009455,258.2079920906133,-2.9770373837507282
1.8438842060270397,0.001944,183.8054877253532,258.2079920906133,-2.9770373837507282
1.852989807044457,0.0019535999999999998,183.8485672076141,258.2079920906133,-2.9770373837507282
1.8567838074683811,0.0019576,183.86649261609233,258.2079920906133,-2.9770373837507282
1.8696834089097223,0.0019711999999999998,183.92733243986606,258.2079920906133,-2.9770373837507282
1.8886534110293423,0.0019912,184.0165062227818,258.2079920906133,-2.9770373837507282
1.911417413572886,0.0020152,184.1230549848139,258.2079920906133,-2.9770373837507282
1.9546690184056188,0.0020608,184.32414400761536,258.2079920906133,-2.9770373837507282
1.966051019677391,0.0020728,184.37677280182464,258.2079920906133,-2.9770373837507282
1.9789506211187322,0.0020864,184.43627533323715,258.2079920906133,-2.9770373837507282
1.9888150222209344,0.0020968,184.48167526025247,258.2079920906133,-2.9770373837507282
1.9979206232383522,0.0021064,184.523504999198,258.2079920906133,-2.9770373837507282
2.0146142251036174,0.002124,184.60000025936318,258.2079920906133,-2.9770373837507282
2.0214434258666802,0.0021311999999999998,184.63122247764983,258.2079920906133,-2.9770373837507282
2.044966228495009,0.002156,184.73845219760716,258.2079920906133,-2.9770373837507282
2.0646950306994136,0.0021768,184.82801638845743,258.2079920906133,-2.9770373837507282
2.1049114351930074,0.0022191999999999997,185.0095624987761,258.2079920906133,-2.9770373837507282
2.1064290353625768,0.0022207999999999998,185.01638668025157,258.2079920906133,-2.9770373837507282
2.11325823612564,0.002228,185.04707179935338,258.2079920906133,-2.9770373837507282
2.1405750391778926,0.0022567999999999998,185.16942750968317,258.2079920906133,-2.9770373837507282
2.161821441551867,0.0022792,185.26417253702255,258.2079920906133,-2.9770373837507282
2.173962242908423,0.0022919999999999998,185.3181494979079,258.2079920906133,-2.9770373837507282
2.1861030442649803,0.0023048,185.37200902361172,258.2079920906133,-2.9770373837507282
2.188379444519334,0.0023071999999999997,185.3820946845524,258.2079920906133,-2.9770373837507282
2.2179726478259414,0.0023384,185.51283815086154,258.2079920906133,-2.9770373837507282
2.2399778502846996,0.0023615999999999997,185.60961705819804,258.2079920906133,-2.9770373837507282
2.2490834513021176,0.0023712,185.64955496076914,258.2079920906133,-2.9770373837507282
2.2551538519803955,0.0023775999999999997,185.67614520157784,258.2079920906133,-2.9770373837507282
2.25743025223475,0.0023799999999999997,185.68610934336616,258.2079920906133,-2.9770373837507282
2.2748826541848004,0.0023983999999999998,185.7623713392612,258.2079920906133,-2.9770373837507282
2.278676654608724,0.0024024,185.7789198016528,258.2079920906133,-2.9770373837507282
2.286264655456572,0.0024104,185.8119845244302,258.2079920906133,-2.9770373837507282
2.289299855795711,0.0024135999999999997,185.82519842659622,258.2079920906133,-2.9770373837507282
2.3219282594414574,0.002448,185.96681903252252,258.2079920906133,-2.9770373837507282
2.341657061645862,0.0024687999999999997,186.0520736251513,258.2079920906133,-2.9770373837507282
2.3537978630024186,0.0024816,186.1043987720422,258.2079920906133,-2.9770373837507282
2.362903464019836,0.0024912,186.14357358487433,258.2079920906133,-2.9770373837507282
2.370491464867684,0.0024992,186.17617430823714,258.2079920906133,-2.9770373837507282
2.3826322662242405,0.002512,186.22825093996826,258.2079920906133,-2.9770373837507282
2.394773067580797,0.0025248,186.280224184061,258.2079920906133,-2.9770373837507282
2.406155068852569,0.0025368,186.32885585080646,258.2079920906133,-2.9770373837507282
2.416778270039556,0.002548,186.37416452348668,258.2079920906133,-2.9770373837507282
2.423607470802619,0.0025552,186.40325051699642,258.2079920906133,-2.9770373837507282
2.4554770743635803,0.0025888,186.53856476093344,258.2079920906133,-2.9770373837507282
2.478999876991909,0.0026135999999999998,186.63800062492007,258.2079920906133,-2.9770373837507282
2.485829077754972,0.0026208,186.66680008957982,258.2079920906133,-2.9770373837507282
2.490381878263681,0.0026256,186.6859825920406,258.2079920906133,-2.9770373837507282
2.5025226796202373,0.0026384,186.7370691857546,258.2079920906133,-2.9770373837507282
2.526045482248566,0.0026631999999999997,186.83577523379032,258.2079920906133,-2.9770373837507282
2.546533084537755,0.0026847999999999998,186.92145330555675,258.2079920906133,-2.9770373837507282
2.5594326859790963,0.0026983999999999997,186.97526086522436,258.2079920906133,-2.9770373837507282
2.568538286996514,0.002708,187.01317901230595,258.2079920906133,-2.9770373837507282
2.5799202882682857,0.0027199999999999998,187.0605030551338,258.2079920906133,-2.9770373837507282
2.586749489031349,0.0027272,187.08885839831265,258.2079920906133,-2.9770373837507282
2.5950962899639816,0.0027359999999999997,187.12347531183704,258.2079920906133,-2.9770373837507282
2.629242293779297,0.0027719999999999997,187.26464013284104,258.2079920906133,-2.9770373837507282
2.6459358956445627,0.0027895999999999997,187.3333936779157,258.2079920906133,-2.9770373837507282
2.6747702988663846,0.00282,187.45175266376467,258.2079920906133,-2.9770373837507282
2.7468563069209395,0.0028959999999999997,187.74549361823304,258.2079920906133,-2.9770373837507282
2.7498915072600787,0.0028991999999999998,187.75779526468304,258.2079920906133,-2.9770373837507282
2.761273508531851,0.0029112,187.80387935290608,258.2079920906133,-2.9770373837507282
2.7658263090405595,0.0029159999999999998,187.82229223752321,258.2079920906133,-2.9770373837507282
2.790866711838458,0.0029424,187.92335259812825,258.2079920906133,-2.9770373837507282
2.847017918112532,0.0030015999999999997,188.14869597851285,258.2079920906133,-2.9770373837507282
2.862193919808228,0.0030176,188.20930120466988,258.2079920906133,-2.9770373837507282
2.8849579223517714,0.0030415999999999998,188.29997459054005,258.2079920906133,-2.9770373837507282
2.9168275259127325,0.0030751999999999997,188.4264499522162,258.2079920906133,-2.9770373837507282
2.932762327693213,0.0030919999999999997,188.48948544876774,258.2079920906133,-2.9770373837507282
2.960079130745466,0.0031208,188.59723642001572,258.2079920906133,-2.9770373837507282
2.976772732610731,0.0031384,188.66289335015153,258.2079920906133,-2.9770373837507282
2.985119533543364,0.0031471999999999997,188.69566795456575,258.2079920906133,-2.9770373837507282
3.002571935493414,0.0031655999999999998,188.7640814062583,258.2079920906133,-2.9770373837507282
3.020024337443464,0.0031839999999999998,188.832339948233,258.2079920906133,-2.9770373837507282
3.0306475386304514,0.0031952,188.87381331158008,258.2079920906133,-2.9770373837507282
3.0435471400717926,0.0032088,188.9240976808896,258.2079920906133,-2.9770373837507282
3.05265274108921,0.0032183999999999997,188.9595424989196,258.2079920906133,-2.9770373837507282
3.074657943547969,0.0032416,189.04503100878932,258.2079920906133,-2.9770373837507282
3.078451943971893,0.0032456,189.0597462573477,258.2079920906133,-2.9770373837507282
3.0905927453284496,0.0032584,189.1067875938426,258.2079920906133,-2.9770373837507282
3.1057687470241455,0.0032744,189.16548804034784,258.2079920906133,-2.9770373837507282
3.124738749143765,0.0032944,189.23870652599206,258.2079920906133,-2.9770373837507282
3.134603150245967,0.0033047999999999997,189.27671161653436,258.2079920906133,-2.9770373837507282
3.1452263514329544,0.003316,189.3175880494601,258.2079920906133,-2.9770373837507282
3.1641963535525743,0.003336,189.39044800714157,258.2079920906133,-2.9770373837507282
3.1968247571983204,0.0033704,189.5153698914214,258.2079920906133,-2.9770373837507282
3.2074479583853073,0.0033816,189.55593469894458,258.2079920906133,-2.9770373837507282
3.2142771591483705,0.0033888,189.5819844088359,258.2079920906133,-2.9770373837507282
3.2173123594875097,0.003392,189.59355512820403,258.2079920906133,-2.9770373837507282
3.2271767605897117,0.0034024,189.6311305994583,258.2079920906133,-2.9770373837507282
3.266634364998521,0.003444,189.780986701722,258.2079920906133,-2.9770373837507282
3.280292766524647,0.0034584,189.8326952747359,258.2079920906133,-2.9770373837507282
3.284845567033356,0.0034632,189.84991279727652,258.2079920906133,-2.9770373837507282
3.290915967711634,0.0034695999999999998,189.87285502380246,258.2079920906133,-2.9770373837507282
3.296227568305128,0.0034752,189.89291593663106,258.2079920906133,-2.9770373837507282
3.3015391688986213,0.0034808,189.9129642460722,258.2079920906133,-2.9770373837507282
3.319750370933456,0.0034999999999999996,189.98160601032052,258.2079920906133,-2.9770373837507282
3.3288559719508735,0.0035096,190.015871810878,258.2079920906133,-2.9770373837507282
3.336443972798721,0.0035175999999999996,190.044398730172,258.2079920906133,-2.9770373837507282
3.341755573392215,0.0035231999999999998,190.06435252061132,258.2079920906133,-2.9770373837507282
3.363760775850974,0.0035464,190.14688679874573,258.2079920906133,-2.9770373837507282
3.3759015772075305,0.0035591999999999998,190.19233280671605,258.2079920906133,-2.9770373837507282
3.385765978309733,0.0035696,190.22921077215346,258.2079920906133,-2.9770373837507282
3.4221883823794026,0.0036079999999999997,190.36501408902956,258.2079920906133,-2.9770373837507282
3.445711185007731,0.0036328,190.4524209097945,258.2079920906133,-2.9770373837507282
3.4487463853468703,0.003636,190.4636822340454,258.2079920906133,-2.9770373837507282
3.476063188399123,0.0036647999999999997,190.5648608094877,258.2079920906133,-2.9770373837507282
3.5048975916209453,0.0036952,190.67132458012344,258.2079920906133,-2.9770373837507282
3.519314793231856,0.0037104,190.72442833049698,258.2079920906133,-2.9770373837507282
3.526143993994919,0.0037175999999999997,190.74955312002453,258.2079920906133,-2.9770373837507282
3.5420787957753994,0.0037343999999999997,190.80810394373393,258.2079920906133,-2.9770373837507282
3.5542195971319566,0.0037472,190.85264517040582,258.2079920906133,-2.9770373837507282
3.570913198997222,0.0037648,190.91379259151432,258.2079920906133,-2.9770373837507282
3.6096120033212458,0.0038055999999999997,191.05511625870147,258.2079920906133,-2.9770373837507282
3.6285820054408657,0.0038255999999999997,191.1241766440499,258.2079920906133,-2.9770373837507282
3.633893606034359,0.0038312,191.14348830098984,258.2079920906133,-2.9770373837507282
3.6475520075604853,0.0038456,191.1930963651474,258.2079920906133,-2.9770373837507282
3.6505872078996244,0.0038488,191.20411053493254,258.2079920906133,-2.9770373837507282
3.662728009256181,0.0038615999999999998,191.24813154683696,258.2079920906133,-2.9770373837507282
3.6794216111214464,0.0038791999999999997,191.30856763256307,258.2079920906133,-2.9770373837507282
3.6945976128171423,0.0038951999999999997,191.36341679536974,258.2079920906133,-2.9770373837507282
3.712808814851978,0.0039144,191.42911994300263,258.2079920906133,-2.9770373837507282
3.725708416293319,0.003928,191.4755836502686,258.2079920906133,-2.9770373837507282
3.754542819515141,0.0039584,191.57921743821103,258.2079920906133,-2.9770373837507282
3.75757801985428,0.0039616,191.5901081709881,258.2079920906133,-2.9770373837507282
3.767442420956482,0.003972,191.62547938188885,258.2079920906133,-2.9770373837507282
3.7773068220586845,0.0039824,191.66081449193308,258.2079920906133,-2.9770373837507282
3.787930023245672,0.0039936,191.69882746443503,258.2079920906133,-2.9770373837507282
3.7924828237543804,0.0039984,191.71510600830604,258.2079920906133,-2.9770373837507282
4.194727014008336,0.00442248449689938,193.1246298830881,258.2079920906133,-2.9770373837507282
4.340445774039022,0.004576115223044609,193.62210485434048,258.2079920906133,-2.9770373837507282
4.631883294100394,0.004883376675335067,194.597927710952,258.2079920906133,-2.9770373837507282
5.196543489219302,0.00547869573914783,196.42293756612963,258.2079920906133,-2.9770373837507282
5.378691939257658,0.005670734146829366,196.99491795509923,258.2079920906133,-2.9770373837507282
5.815848219349716,0.006131626325265053,198.33768689004168,258.2079920906133,-2.9770373837507282
5.9979966693880735,0.006323664732946589,198.88548351168168,258.2079920906133,-2.9770373837507282
6.635516244522324,0.006995799159831967,200.7536529352413,258.2079920906133,-2.9770373837507282
6.908738919579859,0.00728385677135427,201.53270295582536,258.2079920906133,-2.9770373837507282
7.163746749633559,0.007552710542108421,202.2490424867277,258.2079920906133,-2.9770373837507282
7.345895199671917,0.007744748949789958,202.75463738943972,258.2079920906133,-2.9770373837507282
7.491613959702603,0.007898379675935187,203.15560158694697,258.2079920906133,-2.9770373837507282
7.582688184721781,0.007994398879775955,203.4046601834883,258.2079920906133,-2.9770373837507282
7.783051479763974,0.008205641128225645,203.94851893048101,258.2079920906133,-2.9770373837507282
7.819481169771645,0.008244048809761952,204.04681286844266,258.2079920906133,-2.9770373837507282
7.965199929802331,0.008397679535907181,204.43821571374062,258.2079920906133,-2.9770373837507282
8.365926519886719,0.008820164032806561,205.50043120309428,258.2079920906133,-2.9770373837507282
8.620934349940418,0.009089017803560712,206.16606501226394,258.2079920906133,-2.9770373837507282
8.803082799978775,0.009281056211242249,206.63682448666142,258.2079920906133,-2.9770373837507282
9.094520320040147,0.009588317663532707,207.38221352442034,258.2079920906133,-2.9770373837507282
9.54989144513604,0.010068413682736548,208.52849704084403,258.2079920906133,-2.9770373837507282
9.64096567015522,0.010164432886577316,208.75517364458943,258.2079920906133,-2.9770373837507282
9.84132896519741,0.010375675135027004,209.2509431475634,258.2079920906133,-2.9770373837507282
10.05990710524344,0.010606121224244848,209.78731425228847,258.2079920906133,-2.9770373837507282
10.169196175266453,0.01072134426885377,210.05379394774988,258.2079920906133,-2.9770373837507282
11.262086875496598,0.011873574714942988,212.65987076375578,258.2079920906133,-2.9770373837507282
11.863176760623176,0.012507301460292058,214.05106977644908,258.2079920906133,-2.9770373837507282
12.591770560776606,0.013275455091018204,215.70103359520843,258.2079920906133,-2.9770373837507282
12.91963777084565,0.013621124224844969,216.4313232881805,258.2079920906133,-2.9770373837507282
13.338579205933872,0.014062812562512503,217.3540370511254,258.2079920906133,-2.9770373837507282
13.666446416002914,0.014408481696339268,218.0682989957083,258.2079920906133,-2.9770373837507282
14.395040216156344,0.015176635327065414,219.63204387550326,258.2079920906133,-2.9770373837507282
14.54075897618703,0.015330266053210643,219.94105474655237,258.2079920906133,-2.9770373837507282
14.996130101282924,0.015810362072414486,220.89901986684873,258.2079920906133,-2.9770373837507282
15.615434831413337,0.016463292658531706,222.18383971200493,258.2079920906133,-2.9770373837507282
15.815798126455531,0.016674534906981398,222.5952412783968,258.2079920906133,-2.9770373837507282
16.180095026532246,0.01705861172234447,223.33807385944579,258.2079920906133,-2.9770373837507282
16.307598941559096,0.017193038607721544,223.59652050107798,258.2079920906133,-2.9770373837507282
16.653680996631973,0.01755791158231646,224.2940763017582,258.2079920906133,-2.9770373837507282
16.781184911658823,0.01769233846769354,224.54964248453894,258.2079920906133,-2.9770373837507282
16.999763051704853,0.017922784556911382,224.98600103278488,258.2079920906133,-2.9770373837507282
17.236556036754717,0.018172434486897378,225.45626086863678,258.2079920906133,-2.9770373837507282
18.01979437191965,0.018998199639927986,226.99408924521285,258.2079920906133,-2.9770373837507282
18.183727976954174,0.019171034206841367,227.31263594183417,258.2079920906133,-2.9770373837507282
18.311231891981024,0.019305461092218444,227.55962078683785,258.2079920906133,-2.9770373837507282
18.74838817207308,0.01976635327065413,228.40138012019844,258.2079920906133,-2.9770373837507282
19.14911476215747,0.02018883776755351,229.16629225384426,258.2079920906133,-2.9770373837507282
19.422337437215003,0.020476895379075814,229.68424734449152,258.2079920906133,-2.9770373837507282
20.005212477337746,0.02109141828365673,230.7798151220198,258.2079920906133,-2.9770373837507282
20.187360927376105,0.021283456691338267,231.1196176086354,258.2079920906133,-2.9770373837507282
20.697376587483504,0.02182116423284657,232.06476138372767,258.2079920906133,-2.9770373837507282
21.608118837675292,0.02278135627125425,233.73022849158983,258.2079920906133,-2.9770373837507282
22.59172046788242,0.023818363672734547,235.49847064560316,258.2079920906133,-2.9770373837507282
22.737439227913107,0.023971994398879776,235.7578561582315,258.2079920906133,-2.9770373837507282
23.265669733024342,0.02452890578115623,236.69274243402074,258.2079920906133,-2.9770373837507282
23.57532209808955,0.024855371074214844,237.2369305809476,258.2079920906133,-2.9770373837507282
23.684611168112564,0.024970594118823766,237.42833050613712,258.2079920906133,-2.9770373837507282
23.83032992814325,0.025124224844968995,237.68299546647083,258.2079920906133,-2.9770373837507282
24.067122913193113,0.02537387477495499,238.09553453358336,258.2079920906133,-2.9770373837507282
24.340345588250653,0.025661932386477296,238.5695792367407,258.2079920906133,-2.9770373837507282
24.50427919328517,0.025834766953390677,238.85301002339753,258.2079920906133,-2.9770373837507282
25.06893938840408,0.026430086017203442,239.82366083826219,258.2079920906133,-2.9770373837507282
25.214658148434765,0.02658371674334867,240.07276251870908,258.2079920906133,-2.9770373837507282
25.888607413576686,0.027294258851770354,241.2176325530629,258.2079920906133,-2.9770373837507282
26.27111915865724,0.027697539507901582,241.86225177212353,258.2079920906133,-2.9770373837507282
26.48969729870327,0.027927985597119426,242.22896201911095,258.2079920906133,-2.9770373837507282
26.853994198779983,0.0283120624124825,242.83753412695475,258.2079920906133,-2.9770373837507282
27.181861408849024,0.02865773154630926,243.3825015866432,258.2079920906133,-2.9770373837507282
27.254720788864365,0.028734546909381875,243.50325662051912,258.2079920906133,-2.9770373837507282
27.473298928910395,0.02896499299859972,243.8647685971975,258.2079920906133,-2.9770373837507282
27.61901768894108,0.029118623724744948,244.10515360149688,258.2079920906133,-2.9770373837507282
27.801166138979436,0.029310662132426484,244.4049404196878,258.2079920906133,-2.9770373837507282
28.91227168421342,0.030482096419283858,246.21732342948906,258.2079920906133,-2.9770373837507282
29.130849824259446,0.0307125425085017,246.57063805867173,258.2079920906133,-2.9770373837507282
29.349427964305477,0.030942988597719545,246.92292028456527,258.2079920906133,-2.9770373837507282
29.823013934405203,0.031442288457691536,247.68270731118906,258.2079920906133,-2.9770373837507282
29.89587331442055,0.03151910382076416,247.79917865817936,258.2079920906133,-2.9770373837507282
29.96873269443589,0.031595919183836765,247.91553935500372,258.2079920906133,-2.9770373837507282
30.2783850595011,0.03192238447689538,248.4088465215743,258.2079920906133,-2.9770373837507282
31.025193704658363,0.03270974194838968,249.5905617200357,258.2079920906133,-2.9770373837507282
31.608068744781107,0.033324264852970596,250.50518452865435,258.2079920906133,-2.9770373837507282
31.680928124796452,0.03340108021604321,250.61904806152418,258.2079920906133,-2.9770373837507282
32.373092234942206,0.034130826165233046,251.6957058817612,258.2079920906133,-2.9770373837507282
32.70095944501125,0.034476495299059814,252.20256475589497,258.2079920906133,-2.9770373837507282
33.37490871015317,0.0351870374074815,253.23825932266405,258.2079920906133,-2.9770373837507282
33.77563530023756,0.03560952190438088,253.85021134373716,258.2079920906133,-2.9770373837507282
33.83027983524907,0.035667133426685343,253.9334394212553,258.2079920906133,-2.9770373837507282
34.03064313029125,0.03587837567513502,254.2381615082292,258.2079920906133,-2.9770373837507282
34.08528766530276,0.035935987197439484,254.32114599315943,258.2079920906133,-2.9770373837507282
34.577088480406324,0.036454490898179634,255.065686015746,258.2079920906133,-2.9770373837507282
34.868526000467696,0.03676175235047009,255.504946166203,258.2079920906133,-2.9770373837507282
35.17817836553291,0.03708821764352871,255.97009410041602,258.2079920906133,-2.9770373837507282
35.251037745548246,0.03716503300660132,256.0793082815984,258.2079920906133,-2.9770373837507282
35.30568228055976,0.03722264452890578,256.1611611536882,258.2079920906133,-2.9770373837507282
36.070705770720856,0.03802920584116823,257.3019627787908,258.2079920906133,-2.9770373837507282
36.12535030573236,0.03808681736347269,257.38308571036305,258.2079920906133,-2.9770373837507282
36.38035813578607,0.038355671134226846,257.7610284239907,258.2079920906133,-2.9770373837507282
36.74465503586278,0.03873974794958991,258.29915923706153,258.2079920906133,-2.9770373837507282
37.49146368102004,0.039527105421084216,259.3958659238934,258.2079920906133,-2.9770373837507282
37.89219027110443,0.0399495899179836,259.9808287955596,258.2079920906133,-2.9770373837507282
38.165412946161965,0.0402376475295059,260.378284515651,258.2079920906133,-2.9770373837507282
38.602569226254026,0.040698539707941586,261.0119132725725,258.2079920906133,-2.9770373837507282
38.73007314128088,0.04083296659331867,261.1961937163021,258.2079920906133,-2.9770373837507282
38.93043643632306,0.04104420884176835,261.485299958245,258.2079920906133,-2.9770373837507282
39.13079973136526,0.04125545109021804,261.7738264812749,258.2079920906133,-2.9770373837507282
39.73188961649184,0.041889177835567115,262.63596870649224,258.2079920906133,-2.9770373837507282
39.87760837652253,0.042042808561712344,262.84420500108723,258.2079920906133,-2.9770373837507282
40.314764656614585,0.04250370074014803,263.46714056584034,258.2079920906133,-2.9770373837507282
41.55337411687541,0.04380956191238247,265.217977467161,258.2079920906133,-2.9770373837507282
41.84481163693678,0.04411682336467293,265.6269668185375,258.2079920906133,-2.9770373837507282
42.008745241971305,0.04428965793158632,265.8565351050611,258.2079920906133,-2.9770373837507282
42.391256987051854,0.04469293858771754,266.3908400039223,258.2079920906133,-2.9770373837507282
42.828413267143915,0.04515383076615323,266.9991771654355,258.2079920906133,-2.9770373837507282
43.62986644731269,0.045998799759952,268.108209203317,258.2079920906133,-2.9770373837507282
43.975948502385556,0.046363672734546904,268.58465004490216,258.2079920906133,-2.9770373837507282
44.10345241741242,0.04649809961992399,268.7598119818452,258.2079920906133,-2.9770373837507282
44.34024540246228,0.046747749549909984,269.0845896502855,258.2079920906133,-2.9770373837507282
44.57703838751215,0.04699739947989598,269.4086915909237,258.2079920906133,-2.9770373837507282
45.433136102692416,0.047899979995999195,270.5748842310972,258.2079920906133,-2.9770373837507282
46.08887052283051,0.04859131826365273,271.4623511453785,258.2079920906133,-2.9770373837507282
46.47138226791106,0.04899459891978396,271.97776609534935,258.2079920906133,-2.9770373837507282
46.98139792801845,0.04953230646129225,272.66241961628276,258.2079920906133,-2.9770373837507282
47.18176122306065,0.049743548709741944,272.9305968328288,258.2079920906133,-2.9770373837507282
47.309265138087504,0.04987797559511903,273.1010238349483,258.2079920906133,-2.9770373837507282
48.0196440932371,0.050626925385077015,274.04728669938015,258.2079920906133,-2.9770373837507282
48.63894882336751,0.051279855971194235,274.8677881611567,258.2079920906133,-2.9770373837507282
49.440402003536285,0.052124824964993,275.9235905819596,258.2079920906133,-2.9770373837507282
49.586120763566974,0.05227845569113823,276.11483536176155,258.2079920906133,-2.9770373837507282
50.07792157867054,0.05279695939187838,276.7586744199952,258.2079920906133,-2.9770373837507282
50.53329270376642,0.053277055411082214,277.3526263996963,258.2079920906133,-2.9770373837507282
51.00687867386615,0.053776355271054205,277.9681263719428,258.2079920906133,-2.9770373837507282
51.15259743389684,0.053929985997199434,278.1570620621996,258.2079920906133,-2.9770373837507282
51.22545681391218,0.054006801360272055,278.2514511840074,258.2079920906133,-2.9770373837507282
52.42763658416534,0.05527425485097019,279.80139067454735,258.2079920906133,-2.9770373837507282
52.864792864257396,0.05573514702940588,280.3615604148335,258.2079920906133,-2.9770373837507282
53.028726469291925,0.05590798159631927,280.57115794390774,258.2079920906133,-2.9770373837507282
53.666246044426174,0.056580116023204646,281.383868529591,258.2079920906133,-2.9770373837507282
53.81196480445686,0.056733746749349875,281.569101250482,258.2079920906133,-2.9770373837507282
54.01232809949906,0.05694498899779957,281.8234771447644,258.2079920906133,-2.9770373837507282
54.55877344961412,0.057521104220844166,282.51536595600305,258.2079920906133,-2.9770373837507282
55.014144574710016,0.05800120024004801,283.08987787314663,258.2079920906133,-2.9770373837507282
55.542375079821255,0.058558111622324466,283.75399335997736,258.2079920906133,-2.9770373837507282
56.05239073992865,0.05909581916383276,284.3928749492046,258.2079920906133,-2.9770373837507282
56.28918372497852,0.05934546909381877,284.6887275171772,258.2079920906133,-2.9770373837507282
56.98134783512427,0.0600752150430086,285.55075690110266,258.2079920906133,-2.9770373837507282
57.090636905147285,0.06019043808761752,285.68649260244683,258.2079920906133,-2.9770373837507282
58.49317997044264,0.06166913382676535,287.41953534801684,258.2079920906133,-2.9770373837507282
58.693543265484834,0.06188037607521504,287.6657834171029,258.2079920906133,-2.9770373837507282
59.31284799561524,0.06253330666133226,288.42484927087355,258.2079920906133,-2.9770373837507282
59.34927768562292,0.06257171434286858,288.4694037001685,258.2079920906133,-2.9770373837507282
59.58607067067279,0.06282136427285458,288.75874794720306,258.2079920906133,-2.9770373837507282
60.09608633078018,0.06335907181436287,289.3804322315735,258.2079920906133,-2.9770373837507282
60.678961370902925,0.06397359471894379,290.0884145172438,258.2079920906133,-2.9770373837507282
61.40755517105635,0.06474174834966993,290.96967358553877,258.2079920906133,-2.9770373837507282
61.5350590860832,0.064876175235047,291.12347372993696,258.2079920906133,-2.9770373837507282
61.89935598615992,0.06526025205041008,291.5622193649466,258.2079920906133,-2.9770373837507282
62.09971928120212,0.06547149429885978,291.8031001775402,258.2079920906133,-2.9770373837507282
62.26365288623663,0.06564432886577315,291.9999591077641,258.2079920906133,-2.9770373837507282
63.0104615313939,0.06643168633726745,292.8942152712846,258.2079920906133,-2.9770373837507282
63.50226234649747,0.0669501900380076,293.48085926785853,258.2079920906133,-2.9770373837507282
63.77548502155501,0.06723824764952992,293.80600689322773,258.2079920906133,-2.9770373837507282
64.41300459668925,0.06791038207641528,294.5625793158514,258.2079920906133,-2.9770373837507282
64.66801242674295,0.06817923584716944,294.8643899064852,258.2079920906133,-2.9770373837507282
64.90480541179282,0.06842888577715543,295.1442272536163,258.2079920906133,-2.9770373837507282
65.03230932681967,0.06856331266253252,295.29474397037853,258.2079920906133,-2.9770373837507282
65.65161405695008,0.06921624324864974,296.02419437278553,258.2079920906133,-2.9770373837507282
65.92483673200762,0.06950430086017204,296.3451570671079,258.2079920906133,-2.9770373837507282
66.56235630714187,0.07017643528705741,297.09205928038955,258.2079920906133,-2.9770373837507282
66.90843836221475,0.07054130826165234,297.49635192742966,258.2079920906133,-2.9770373837507282
67.16344619226845,0.07081016203240649,297.79373009650516,258.2079920906133,-2.9770373837507282
67.2363055722838,0.0708869773954791,297.87861436588867,258.2079920906133,-2.9770373837507282
67.87382514741805,0.07155911182236448,298.6198277375771,258.2079920906133,-2.9770373837507282
68.52955956755613,0.07225045009001801,299.37939146018016,258.2079920906133,-2.9770373837507282
69.16707914269037,0.07292258451690338,300.11514336874717,258.2079920906133,-2.9770373837507282
69.2763682127134,0.0730378075615123,300.241006244646,258.2079920906133,-2.9770373837507282
69.60423542278244,0.07338347669533907,300.6181310643976,258.2079920906133,-2.9770373837507282
69.78638387282079,0.07357551510302061,300.82734547607674,258.2079920906133,-2.9770373837507282
70.13246592789366,0.07394038807761552,301.2242670700795,258.2079920906133,-2.9770373837507282
70.20532530790902,0.07401720344068814,301.30773209118865,258.2079920906133,-2.9770373837507282
70.40568860295122,0.07422844568913783,301.5370868926398,258.2079920906133,-2.9770373837507282
71.09785271309697,0.07495819163832768,302.3274522549748,258.2079920906133,-2.9770373837507282
71.18892693811615,0.07505421084216844,302.4312238422983,258.2079920906133,-2.9770373837507282
71.37107538815451,0.07524624924984998,302.6386118204006,258.2079920906133,-2.9770373837507282
71.80823166824656,0.07570714142828566,303.1355025812913,258.2079920906133,-2.9770373837507282
72.17252856832327,0.07609121824364873,303.5486776619922,258.2079920906133,-2.9770373837507282
72.31824732835395,0.07624484896979396,303.7137198577338,258.2079920906133,-2.9770373837507282
72.46396608838464,0.07639847969593919,303.8786324081402,258.2079920906133,-2.9770373837507282
72.75540360844602,0.07670574114822964,304.2080700201673,258.2079920906133,-2.9770373837507282
72.86469267846903,0.07682096419283857,304.3314763891443,258.2079920906133,-2.9770373837507282
73.06505597351122,0.07703220644128826,304.5575340751643,258.2079920906133,-2.9770373837507282
73.13791535352658,0.07710902180436088,304.6396769120379,258.2079920906133,-2.9770373837507282
73.22898957854575,0.07720504100820165,304.7423105933669,258.2079920906133,-2.9770373837507282
73.48399740859944,0.07747389477895579,305.02942040233006,258.2079920906133,-2.9770373837507282
73.53864194361095,0.07753150630126025,305.0908933488712,258.2079920906133,-2.9770373837507282
73.88472399868382,0.07789637927585517,305.47980912947514,258.2079920906133,-2.9770373837507282
74.30366543377205,0.0783380676135227,305.94965264163,258.2079920906133,-2.9770373837507282
74.3765248137874,0.07841488297659532,306.03125898204485,258.2079920906133,-2.9770373837507282
75.23262252896767,0.07931746349269854,306.98780986997366,258.2079920906133,-2.9770373837507282
75.9065717941096,0.08002800560112022,307.73785612720343,258.2079920906133,-2.9770373837507282
76.07050539914412,0.08020084016803361,307.91990655962553,258.2079920906133,-2.9770373837507282
76.54409136924384,0.0807001400280056,308.4449725284264,258.2079920906133,-2.9770373837507282
76.76266950928988,0.08093058611722345,308.68688320150335,258.2079920906133,-2.9770373837507282
76.81731404430138,0.08098819763952791,308.747318875967,258.2079920906133,-2.9770373837507282
77.12696640936659,0.08131466293258652,309.08947152483194,258.2079920906133,-2.9770373837507282
77.47304846443947,0.08167953590718144,309.47124407098664,258.2079920906133,-2.9770373837507282
78.2016422645929,0.08244768953790758,310.2728085075275,258.2079920906133,-2.9770373837507282
78.23807195460057,0.08248609721944389,310.31281009957434,258.2079920906133,-2.9770373837507282
78.49307978465427,0.08275495099019804,310.5926181315211,258.2079920906133,-2.9770373837507282
78.78451730471564,0.0830622124424885,310.9119649942261,258.2079920906133,-2.9770373837507282
79.2216735848077,0.08352310462092419,311.3901228064526,258.2079920906133,-2.9770373837507282
79.56775563988057,0.08388797759551911,311.7679350103949,258.2079920906133,-2.9770373837507282
79.89562284994962,0.08423364672934587,312.12527161809624,258.2079920906133,-2.9770373837507282
80.02312676497648,0.08436807361472295,312.2640813510437,258.2079920906133,-2.9770373837507282
80.16884552500717,0.08452170434086818,312.42261546934697,258.2079920906133,-2.9770373837507282
80.58778696009539,0.08496339267853571,312.87777626249505,258.2079920906133,-2.9770373837507282
81.55317374529868,0.08598119623924785,313.9231262185591,258.2079920906133,-2.9770373837507282
82.00854487039457,0.0864612922584517,314.4145397120881,258.2079920906133,-2.9770373837507282
82.44570115048663,0.08692218443688739,314.88529645302964,258.2079920906133,-2.9770373837507282
83.19250979564389,0.08770954190838168,315.68726006151724,258.2079920906133,-2.9770373837507282
83.37465824568224,0.08790158031606321,315.88243443512073,258.2079920906133,-2.9770373837507282
83.8118145257743,0.0883624724944989,316.3501756951737,258.2079920906133,-2.9770373837507282
84.066822355828,0.08863132626525305,316.62258536568544,258.2079920906133,-2.9770373837507282
84.7772013109776,0.08938027605521105,317.37974681757623,258.2079920906133,-2.9770373837507282
84.92292007100829,0.08953390678135628,317.53475570185697,258.2079920906133,-2.9770373837507282
85.50579511113104,0.0901484296859372,318.15375673096094,258.2079920906133,-2.9770373837507282
86.08867015125378,0.09076295259051811,318.7711142864646,258.2079920906133,-2.9770373837507282
86.23438891128446,0.09091658331666334,318.925198698262,258.2079920906133,-2.9770373837507282
86.83547879641104,0.0915503100620124,319.5597265026068,258.2079920906133,-2.9770373837507282
87.0176272464494,0.09174234846969394,319.751669158589,258.2079920906133,-2.9770373837507282
87.1269163164724,0.09185757151430286,319.86675954019665,258.2079920906133,-2.9770373837507282
87.76443589160665,0.09252970594118824,320.53700137036884,258.2079920906133,-2.9770373837507282
87.91015465163734,0.09268333666733347,320.6899325848934,258.2079920906133,-2.9770373837507282
88.20159217169872,0.09299059811962393,320.99549874558,258.2079920906133,-2.9770373837507282
88.56588907177542,0.093374674934987,321.3769032788297,258.2079920906133,-2.9770373837507282
88.8573265918368,0.09368193638727745,321.68158656324744,258.2079920906133,-2.9770373837507282
89.54949070198255,0.0944116823364673,322.40365163498,258.2079920906133,-2.9770373837507282
89.7680688420286,0.09464212842568515,322.6312195438329,258.2079920906133,-2.9770373837507282
89.91378760205927,0.09479575915183037,322.7828114376972,258.2079920906133,-2.9770373837507282
90.47844779717818,0.09539107821564313,323.36932726290115,258.2079920906133,-2.9770373837507282
90.6423814022127,0.09556391278255652,323.53933844243653,258.2079920906133,-2.9770373837507282
90.93381892227409,0.09587117423484698,323.8412847461301,258.2079920906133,-2.9770373837507282
91.24347128733928,0.09619763952790558,324.16168945934675,258.2079920906133,-2.9770373837507282
91.53490880740065,0.09650490098019604,324.46285967165664,258.2079920906133,-2.9770373837507282
91.68062756743133,0.09665853170634127,324.61330452299575,258.2079920906133,-2.9770373837507282
92.06313931251188,0.0970618123624725,325.00777922684495,258.2079920906133,-2.9770373837507282
92.26350260755407,0.09727305461092219,325.2141537022085,258.2079920906133,-2.9770373837507282
92.48208074760011,0.09750350070014004,325.4390902522121,258.2079920906133,-2.9770373837507282
92.60958466262696,0.0976379275855171,325.57020749138184,258.2079920906133,-2.9770373837507282
93.06495578772285,0.09811802360472095,326.03790971988553,258.2079920906133,-2.9770373837507282
93.15603001274204,0.09821404280856172,326.1313429719839,258.2079920906133,-2.9770373837507282
93.37460815278806,0.09844448889777956,326.355437548163,258.2079920906133,-2.9770373837507282
93.66604567284944,0.09875175035007001,326.6539123326643,258.2079920906133,-2.9770373837507282
93.82997927788395,0.0989245849169834,326.82164522975984,258.2079920906133,-2.9770373837507282
94.04855741792997,0.09915503100620124,327.0451114160413,258.2079920906133,-2.9770373837507282
94.72250668307191,0.09986557311462294,327.7328605036746,258.2079920906133,-2.9770373837507282
94.83179575309491,0.09998079615923185,327.84420730753675,258.2079920906133,-2.9770373837507282