File: datasets/aisi_316_L/data/M1/train_56.csv
Time(s),Strain(%),Stress(MPa),Temp(C),Log_SR(s-1)
0.0,0.0,0.0,102.30890801044795,1.5929408439361046
1.2254635365905106e-07,4.8e-06,0.9259706249999999,102.30890801044795,1.5929408439361046
6.331561605717638e-07,2.48e-05,4.7841815625,102.30890801044795,1.5929408439361046
9.395220447193915e-07,3.68e-05,7.099108125,102.30890801044795,1.5929408439361046
1.4705562439086128e-06,5.76e-05,11.1116475,102.30890801044795,1.5929408439361046
1.6952245589502065e-06,6.64e-05,12.809260312500001,102.30890801044795,1.5929408439361046
2.32838071952197e-06,9.12e-05,17.593441875,102.30890801044795,1.5929408439361046
2.5122002500105465e-06,9.839999999999999e-05,18.9823978125,102.30890801044795,1.5929408439361046
3.2679027642413616e-06,0.000128,24.692549999999997,102.30890801044795,1.5929408439361046
3.655966217495023e-06,0.00014319999999999998,27.624790312499997,102.30890801044795,1.5929408439361046
4.064454063025194e-06,0.0001592,30.711359062499998,102.30890801044795,1.5929408439361046
4.493366300831872e-06,0.000176,33.95225625,102.30890801044795,1.5929408439361046
4.799732184979499e-06,0.000188,36.267182812499996,102.30890801044795,1.5929408439361046
5.432888345551264e-06,0.0002128,41.051364375,102.30890801044795,1.5929408439361046
6.086468898399536e-06,0.0002384,45.989874375,102.30890801044795,1.5929408439361046
6.3315616057176385e-06,0.000248,47.841815625,102.30890801044795,1.5929408439361046
6.617503097588758e-06,0.0002592,50.00241375,102.30890801044795,1.5929408439361046
6.964717766289401e-06,0.00027279999999999996,52.62599718749999,102.30890801044795,1.5929408439361046
7.434478788649098e-06,0.0002912,56.17555125,102.30890801044795,1.5929408439361046
7.904239811008793e-06,0.0003096,59.7251053125,102.30890801044795,1.5929408439361046
8.08805934149737e-06,0.0003168,61.11406125,102.30890801044795,1.5929408439361046
8.598669148410082e-06,0.0003368,64.9722721875,102.30890801044795,1.5929408439361046
8.680366717516117e-06,0.00033999999999999997,65.58958593749999,102.30890801044795,1.5929408439361046
8.741639894345642e-06,0.0003424,66.05257125,102.30890801044795,1.5929408439361046
8.884610640281202e-06,0.000348,67.1328703125,102.30890801044795,1.5929408439361046
9.252249701258355e-06,0.00036239999999999997,69.91078218749999,102.30890801044795,1.5929408439361046
9.762859508171068e-06,0.00038239999999999997,73.768993125,102.30890801044795,1.5929408439361046
9.803708292724086e-06,0.000384,74.07765,102.30890801044795,1.5929408439361046
9.98752782321266e-06,0.00039119999999999997,75.46660593749999,102.30890801044795,1.5929408439361046
1.0498137630125373e-05,0.00041119999999999997,79.324816875,102.30890801044795,1.5929408439361046
1.0804503514273002e-05,0.0004232,81.6397434375,102.30890801044795,1.5929408439361046
1.1417235282568257e-05,0.0004472,86.2695965625,102.30890801044795,1.5929408439361046
1.2111664619969546e-05,0.0004744,91.5167634375,102.30890801044795,1.5929408439361046
1.2438454896393683e-05,0.00048719999999999997,93.9860184375,102.30890801044795,1.5929408439361046
1.2642698819158768e-05,0.0004952,95.5293028125,102.30890801044795,1.5929408439361046
1.3051186664688937e-05,0.0005112,98.61587156249999,102.30890801044795,1.5929408439361046
1.3316703764283548e-05,0.0005216,100.62214125,102.30890801044795,1.5929408439361046
1.3602645256154666e-05,0.0005327999999999999,102.78273937499999,102.30890801044795,1.5929408439361046
1.3704767217537208e-05,0.0005367999999999999,103.55438156249998,102.30890801044795,1.5929408439361046
1.4011133101684839e-05,0.0005488,105.869308125,102.30890801044795,1.5929408439361046
1.4399196554938499e-05,0.0005639999999999999,108.80154843749999,102.30890801044795,1.5929408439361046
1.5297869815104874e-05,0.0005991999999999999,115.59199968749999,102.30890801044795,1.5929408439361046
1.5583811306975994e-05,0.0006104,117.7525978125,102.30890801044795,1.5929408439361046
1.5665508876082026e-05,0.0006136,118.3699115625,102.30890801044795,1.5929408439361046
1.5808479622017586e-05,0.0006192,119.450210625,102.30890801044795,1.5929408439361046
1.6645879705354437e-05,0.000652,125.7776765625,102.30890801044795,1.5929408439361046
1.7238187081373183e-05,0.0006751999999999999,130.25320125,102.30890801044795,1.5929408439361046
1.7524128573244303e-05,0.0006864,132.413799375,102.30890801044795,1.5929408439361046
1.8157284733816063e-05,0.0007111999999999999,137.19798093749998,102.30890801044795,1.5929408439361046
1.8708743325281794e-05,0.0007327999999999999,141.36484875,102.30890801044795,1.5929408439361046
1.8994684817152914e-05,0.000744,143.525446875,102.30890801044795,1.5929408439361046
1.9198928739917998e-05,0.000752,145.06873124999998,102.30890801044795,1.5929408439361046
1.9403172662683085e-05,0.0007599999999999999,146.612015625,102.30890801044795,1.5929408439361046
1.972996293910722e-05,0.0007727999999999999,149.08127062499997,102.30890801044795,1.5929408439361046
1.9832084900489765e-05,0.0007768,149.8529128125,102.30890801044795,1.5929408439361046
2.003632882325485e-05,0.0007848,151.3961971875,102.30890801044795,1.5929408439361046
2.060821180699709e-05,0.0008072,155.7173934375,102.30890801044795,1.5929408439361046
2.122094357529234e-05,0.0008311999999999999,160.34724656249998,102.30890801044795,1.5929408439361046
2.2732348603753972e-05,0.0008904,171.7675509375,102.30890801044795,1.5929408439361046
2.2977441311072074e-05,0.0009,173.6194921875,102.30890801044795,1.5929408439361046
2.340635354887875e-05,0.0009168,176.86038937499998,102.30890801044795,1.5929408439361046
2.3488051117984787e-05,0.0009199999999999999,177.47770312499998,102.30890801044795,1.5929408439361046
2.387611457123845e-05,0.0009352,180.4099434375,102.30890801044795,1.5929408439361046
2.4407148770427667e-05,0.0009559999999999999,184.4224828125,102.30890801044795,1.5929408439361046
2.452969512408672e-05,0.0009607999999999999,185.34845343749998,102.30890801044795,1.5929408439361046
2.5081153715552452e-05,0.0009824,189.51532125,102.30890801044795,1.5929408439361046
2.5326246422870554e-05,0.000992,191.3672625,102.30890801044795,1.5929408439361046
2.5693885483847707e-05,0.0010064,194.14517437499998,102.30890801044795,1.5929408439361046
2.5734734268400725e-05,0.001008,194.45383125,102.30890801044795,1.5929408439361046
2.6000251367995336e-05,0.0010184,196.46010093750002,102.30890801044795,1.5929408439361046
2.6531285567184554e-05,0.0010391999999999999,200.47264031249998,102.30890801044795,1.5929408439361046
2.6796802666779165e-05,0.0010496,202.47890999999998,102.30890801044795,1.5929408439361046
2.7327836865968387e-05,0.0010704,206.491449375,102.30890801044795,1.5929408439361046
2.7450383219627435e-05,0.0010752,207.41742,102.30890801044795,1.5929408439361046
2.7511656396456962e-05,0.0010776,207.8804053125,102.30890801044795,1.5929408439361046
2.8042690595646187e-05,0.0010984,211.8929446875,102.30890801044795,1.5929408439361046
2.8165236949305234e-05,0.0011032,212.8189153125,102.30890801044795,1.5929408439361046
2.930900291678971e-05,0.001148,221.4613078125,102.30890801044795,1.5929408439361046
3.0105554215573547e-05,0.0011792,227.48011687500002,102.30890801044795,1.5929408439361046
3.069786159159229e-05,0.0012024,231.95564156249998,102.30890801044795,1.5929408439361046
3.126974457533453e-05,0.0012247999999999998,236.27683781249996,102.30890801044795,1.5929408439361046
3.178035438224724e-05,0.0012448,240.13504874999998,102.30890801044795,1.5929408439361046
3.2147993443224395e-05,0.0012592,242.912960625,102.30890801044795,1.5929408439361046
3.255648128875457e-05,0.0012752,245.999529375,102.30890801044795,1.5929408439361046
3.26381788578606e-05,0.0012783999999999998,246.61684312499997,102.30890801044795,1.5929408439361046
3.276072521151965e-05,0.0012832,247.54281375,102.30890801044795,1.5929408439361046
3.28832715651787e-05,0.0012879999999999999,248.46878437499998,102.30890801044795,1.5929408439361046
3.314878866477331e-05,0.0012984,250.4750540625,102.30890801044795,1.5929408439361046
3.3659398471686024e-05,0.0013184,254.33326499999998,102.30890801044795,1.5929408439361046
3.439467659364033e-05,0.0013472,258.9327887994885,102.30890801044795,1.5929408439361046
3.457849612412891e-05,0.0013544,258.98613114695905,102.30890801044795,1.5929408439361046
3.4803164439170504e-05,0.0013632,259.0511773997888,102.30890801044795,1.5929408439361046
3.557929134567782e-05,0.0013935999999999998,259.2746333179499,102.30890801044795,1.5929408439361046
3.6314569467632126e-05,0.0014223999999999999,259.48458116041417,102.30890801044795,1.5929408439361046
3.64779646058442e-05,0.0014288,259.53101033181196,102.30890801044795,1.5929408439361046
3.719281833552199e-05,0.0014567999999999998,259.7331917288104,102.30890801044795,1.5929408439361046
3.756045739649915e-05,0.0014712,259.8365802397533,102.30890801044795,1.5929408439361046
3.7928096457476304e-05,0.0014856,259.93957483137405,102.30890801044795,1.5929408439361046
3.825488673390044e-05,0.0014984,260.0307991671397,102.30890801044795,1.5929408439361046
3.856125261804807e-05,0.0015103999999999999,260.1160463493789,102.30890801044795,1.5929408439361046
3.8745072148536646e-05,0.0015176,260.1670678803595,102.30890801044795,1.5929408439361046
3.894931607130173e-05,0.0015256,260.22364787767265,102.30890801044795,1.5929408439361046
3.907186242496078e-05,0.0015304,260.2575403371295,102.30890801044795,1.5929408439361046
3.915355999406681e-05,0.0015336,260.28011228101,102.30890801044795,1.5929408439361046
3.974586737008556e-05,0.0015568,260.44321305526455,102.30890801044795,1.5929408439361046
4.052199427659288e-05,0.0015872,260.65550358472973,102.30890801044795,1.5929408439361046
4.1257272398547195e-05,0.001616,260.8551628348016,102.30890801044795,1.5929408439361046
4.1441091929035766e-05,0.0016232,260.90486021779856,102.30890801044795,1.5929408439361046
4.238061397375516e-05,0.00166,261.1575387490272,102.30890801044795,1.5929408439361046
4.2584857896520246e-05,0.001668,261.21217869702576,102.30890801044795,1.5929408439361046
4.315674088026248e-05,0.0016903999999999999,261.3646294863043,102.30890801044795,1.5929408439361046
4.3279287233921533e-05,0.0016952,261.3971947779383,102.30890801044795,1.5929408439361046
4.3810321433110755e-05,0.0017159999999999999,261.5378975163729,102.30890801044795,1.5929408439361046
4.4463901985959025e-05,0.0017415999999999998,261.7101603240978,102.30890801044795,1.5929408439361046
4.4688570301000614e-05,0.0017503999999999998,261.7691472178947,102.30890801044795,1.5929408439361046
4.481111665465967e-05,0.0017552,261.8012731360012,102.30890801044795,1.5929408439361046
4.548512159978445e-05,0.0017816,261.97735700610946,102.30890801044795,1.5929408439361046
4.56076679534435e-05,0.0017863999999999998,262.0092626252036,102.30890801044795,1.5929408439361046
4.5689365522549534e-05,0.0017896,262.03051446523943,102.30890801044795,1.5929408439361046
4.601615579897367e-05,0.0018024,262.1153740412393,102.30890801044795,1.5929408439361046
4.691482905914005e-05,0.0018376,262.3475345521671,102.30890801044795,1.5929408439361046
4.760925839654134e-05,0.0018648,262.52574537598474,102.30890801044795,1.5929408439361046
4.771138035792388e-05,0.0018687999999999999,262.5518670951826,102.30890801044795,1.5929408439361046
4.805859502662452e-05,0.0018824,262.6405182905407,102.30890801044795,1.5929408439361046
4.854878044126073e-05,0.0019015999999999998,262.76524884606357,102.30890801044795,1.5929408439361046
4.922278538638551e-05,0.0019279999999999998,262.9359543474365,102.30890801044795,1.5929408439361046
4.9896790331510283e-05,0.0019544,263.10575063485356,102.30890801044795,1.5929408439361046
5.024400500021093e-05,0.0019679999999999997,263.19287220708884,102.30890801044795,1.5929408439361046
5.0386975746146494e-05,0.0019736,263.2286775114261,102.30890801044795,1.5929408439361046
5.081588798395317e-05,0.0019904,263.3358564426887,102.30890801044795,1.5929408439361046
5.151031732135447e-05,0.0020176,263.50863922402465,102.30890801044795,1.5929408439361046
5.169413685184303e-05,0.0020247999999999998,263.55422347858394,102.30890801044795,1.5929408439361046
5.224559544330877e-05,0.0020464,263.69059844680976,102.30890801044795,1.5929408439361046
5.25723857197329e-05,0.0020591999999999997,263.7711483496687,102.30890801044795,1.5929408439361046
5.294002478071006e-05,0.0020736,263.8615339432184,102.30890801044795,1.5929408439361046
5.332808823396372e-05,0.0020888,263.95667579098273,102.30890801044795,1.5929408439361046
5.414506392502406e-05,0.0021208,264.1560963270149,102.30890801044795,1.5929408439361046
5.481906887014883e-05,0.0021471999999999997,264.3197363250087,102.30890801044795,1.5929408439361046
5.5023312792913923e-05,0.0021552,264.3691690411598,102.30890801044795,1.5929408439361046
5.5779015307144735e-05,0.0021847999999999998,264.55145117306756,102.30890801044795,1.5929408439361046
5.647344464454603e-05,0.002212,264.7181062874131,102.30890801044795,1.5929408439361046
5.661641539048158e-05,0.0022175999999999997,264.7523182105874,102.30890801044795,1.5929408439361046
5.694320566690573e-05,0.0022304,264.830390621077,102.30890801044795,1.5929408439361046
5.7106600805117786e-05,0.0022367999999999997,264.86936128523615,102.30890801044795,1.5929408439361046
5.733126912015939e-05,0.0022456,264.9228750177102,102.30890801044795,1.5929408439361046
5.755593743520098e-05,0.0022543999999999997,264.97630702618324,102.30890801044795,1.5929408439361046
5.771933257341305e-05,0.0022608,265.0151155910938,102.30890801044795,1.5929408439361046
5.8148244811219724e-05,0.0022776,265.11678476537253,102.30890801044795,1.5929408439361046
5.8740552187238476e-05,0.0023008,265.25670553783647,102.30890801044795,1.5929408439361046
5.935328395553373e-05,0.0023247999999999997,265.40087334958076,102.30890801044795,1.5929408439361046
5.963922544740485e-05,0.002336,265.46795291255586,102.30890801044795,1.5929408439361046
6.012941086204106e-05,0.0023552,265.58265536497163,102.30890801044795,1.5929408439361046
6.043577674618868e-05,0.0023672,265.65415923971165,102.30890801044795,1.5929408439361046
6.0680869453506785e-05,0.0023768,265.7112606094128,102.30890801044795,1.5929408439361046
6.084426459171885e-05,0.0023832,265.7492782263849,102.30890801044795,1.5929408439361046
6.092596216082489e-05,0.0023864,265.7682721019985,102.30890801044795,1.5929408439361046
6.141614757546108e-05,0.0024056,265.88202745971154,102.30890801044795,1.5929408439361046
6.211057691286237e-05,0.0024327999999999997,266.0425766100446,102.30890801044795,1.5929408439361046
6.260076232749858e-05,0.0024519999999999998,266.1554842021137,102.30890801044795,1.5929408439361046
6.268245989660461e-05,0.0024552,266.1742685614121,102.30890801044795,1.5929408439361046
6.343816241083543e-05,0.0024847999999999997,266.3475735911795,102.30890801044795,1.5929408439361046
6.370367951043004e-05,0.0024952,266.4082731625392,102.30890801044795,1.5929408439361046
6.417344053278974e-05,0.0025136,266.51542355612077,102.30890801044795,1.5929408439361046
6.441853324010784e-05,0.0025231999999999997,266.5712066499834,102.30890801044795,1.5929408439361046
6.466362594742595e-05,0.0025328,266.62690703235637,102.30890801044795,1.5929408439361046
6.50312650084031e-05,0.0025472,266.7103034733307,102.30890801044795,1.5929408439361046
6.519466014661517e-05,0.0025536,266.7473095170909,102.30890801044795,1.5929408439361046
6.570526995352787e-05,0.0025735999999999997,266.86272095431906,102.30890801044795,1.5929408439361046
6.595036266084598e-05,0.0025832,266.91799415504096,102.30890801044795,1.5929408439361046
6.615460658361106e-05,0.0025911999999999997,266.9639939863428,102.30890801044795,1.5929408439361046
6.631800172182313e-05,0.0025976,267.00075398509324,102.30890801044795,1.5929408439361046
6.703285545150093e-05,0.0026256,267.1611654558611,102.30890801044795,1.5929408439361046
6.738007012020158e-05,0.0026392,267.23883876275244,102.30890801044795,1.5929408439361046
6.754346525841364e-05,0.0026455999999999997,267.27533687916434,102.30890801044795,1.5929408439361046
6.766601161207268e-05,0.0026504,267.30268787329305,102.30890801044795,1.5929408439361046
6.795195310394382e-05,0.0026616,267.36643184339596,102.30890801044795,1.5929408439361046
6.811534824215588e-05,0.002668,267.40280999998816,102.30890801044795,1.5929408439361046
6.866680683362161e-05,0.0026896,267.5253357966367,102.30890801044795,1.5929408439361046
6.895274832549273e-05,0.0027007999999999997,267.5887165740795,102.30890801044795,1.5929408439361046
6.923868981736385e-05,0.002712,267.651994928377,102.30890801044795,1.5929408439361046
6.940208495557591e-05,0.0027183999999999997,267.68810822839856,102.30890801044795,1.5929408439361046
6.981057280110608e-05,0.0027343999999999997,267.77824671169094,102.30890801044795,1.5929408439361046
6.989227037021211e-05,0.0027375999999999998,267.7962496989709,102.30890801044795,1.5929408439361046
7.066839727671945e-05,0.002768,267.96687071424566,102.30890801044795,1.5929408439361046
7.093391437631405e-05,0.0027784,268.02507308454983,102.30890801044795,1.5929408439361046
7.097476316086708e-05,0.00278,268.0340197484536,102.30890801044795,1.5929408439361046
7.152622175233281e-05,0.0028016,268.1546038354275,102.30890801044795,1.5929408439361046
7.193470959786298e-05,0.0028176,268.2436917529563,102.30890801044795,1.5929408439361046
7.238404622794616e-05,0.0028352,268.34146089268575,102.30890801044795,1.5929408439361046
7.262913893526425e-05,0.0028447999999999998,268.3946897387972,102.30890801044795,1.5929408439361046
7.354823658770714e-05,0.0028807999999999998,268.5936770656575,102.30890801044795,1.5929408439361046
7.395672443323731e-05,0.0028967999999999997,268.68180433780066,102.30890801044795,1.5929408439361046
7.452860741697955e-05,0.0029192,268.8048642618509,102.30890801044795,1.5929408439361046
7.487582208568019e-05,0.0029327999999999997,268.8793995601633,102.30890801044795,1.5929408439361046
7.552940263852848e-05,0.0029584,269.01933663604984,102.30890801044795,1.5929408439361046
7.575407095357005e-05,0.0029671999999999997,269.06733083051154,102.30890801044795,1.5929408439361046
7.595831487633515e-05,0.0029752,269.1109137663207,102.30890801044795,1.5929408439361046
7.628510515275928e-05,0.0029879999999999998,269.18055151967656,102.30890801044795,1.5929408439361046
7.695911009788406e-05,0.0030144,269.3238130280244,102.30890801044795,1.5929408439361046
7.785778335805045e-05,0.0030496,269.5140695082667,102.30890801044795,1.5929408439361046
7.80211784962625e-05,0.0030559999999999997,269.54856938303317,102.30890801044795,1.5929408439361046
7.836839316496316e-05,0.0030696,269.6217881973862,102.30890801044795,1.5929408439361046
7.840924194951617e-05,0.0030712,269.6303938500055,102.30890801044795,1.5929408439361046
7.896070054098189e-05,0.0030927999999999997,269.74639955954734,102.30890801044795,1.5929408439361046
7.914452007147048e-05,0.0031,269.78499785763074,102.30890801044795,1.5929408439361046
7.934876399423555e-05,0.0031079999999999997,269.8278438734127,102.30890801044795,1.5929408439361046
7.953258352472414e-05,0.0031152,269.86636852685757,102.30890801044795,1.5929408439361046
8.043125678489051e-05,0.0031504,270.0542136912714,102.30890801044795,1.5929408439361046
8.061507631537909e-05,0.0031576,270.0925355308066,102.30890801044795,1.5929408439361046
8.128908126050387e-05,0.0031839999999999998,270.2327583242888,102.30890801044795,1.5929408439361046
8.149332518326896e-05,0.003192,270.275160463348,102.30890801044795,1.5929408439361046
8.1615871536928e-05,0.0031967999999999996,270.30058185331444,102.30890801044795,1.5929408439361046
8.175884228286356e-05,0.0032023999999999998,270.3302213345315,102.30890801044795,1.5929408439361046
8.194266181335215e-05,0.0032096,270.36829955403647,102.30890801044795,1.5929408439361046
8.241242283571183e-05,0.003228,270.4654595181244,102.30890801044795,1.5929408439361046
8.265751554302994e-05,0.0032375999999999998,270.51606591675323,102.30890801044795,1.5929408439361046
8.278006189668899e-05,0.0032424,270.54134716796494,102.30890801044795,1.5929408439361046
8.357661319547282e-05,0.0032735999999999998,270.70532095676117,102.30890801044795,1.5929408439361046
8.463868159385126e-05,0.0033152,270.9230077017844,102.30890801044795,1.5929408439361046
8.47408035552338e-05,0.0033192,270.9438828188026,102.30890801044795,1.5929408439361046
8.557820363857066e-05,0.003352,271.1146902671931,102.30890801044795,1.5929408439361046
8.647687689873703e-05,0.0033872,271.29727229949236,102.30890801044795,1.5929408439361046
8.702833549020276e-05,0.0034088,271.40894496711866,102.30890801044795,1.5929408439361046
8.755936968939198e-05,0.0034295999999999997,271.51622107300733,102.30890801044795,1.5929408439361046
8.798828192719865e-05,0.0034463999999999996,271.6026820393012,102.30890801044795,1.5929408439361046
8.8805257618259e-05,0.0034784,271.76691622146467,102.30890801044795,1.5929408439361046
8.902992593330059e-05,0.0034871999999999998,271.811977184069,102.30890801044795,1.5929408439361046
8.921374546378917e-05,0.0034944,271.8488122676897,102.30890801044795,1.5929408439361046
8.943841377883076e-05,0.0035031999999999997,271.89379275305635,102.30890801044795,1.5929408439361046
8.980605283980791e-05,0.0035175999999999996,271.96730224819686,102.30890801044795,1.5929408439361046
8.994902358574348e-05,0.0035231999999999998,271.9958575678573,102.30890801044795,1.5929408439361046
9.02553894698911e-05,0.0035351999999999996,272.05698800101555,102.30890801044795,1.5929408439361046
9.054133096176223e-05,0.0035464,272.11397009901947,102.30890801044795,1.5929408439361046
9.07047260999743e-05,0.0035528,272.14649978664863,102.30890801044795,1.5929408439361046
9.156255057558766e-05,0.0035864,272.3169071591231,102.30890801044795,1.5929408439361046
9.182806767518226e-05,0.0035968,272.3695259634439,102.30890801044795,1.5929408439361046
9.272674093534863e-05,0.003632,272.54718173854053,102.30890801044795,1.5929408439361046
9.309437999632579e-05,0.0036463999999999997,272.6196654118975,102.30890801044795,1.5929408439361046
9.325777513453786e-05,0.0036528,272.65184453527115,102.30890801044795,1.5929408439361046
9.340074588047343e-05,0.0036584,272.67998323521635,102.30890801044795,1.5929408439361046
9.376838494145057e-05,0.0036728,272.75226286586656,102.30890801044795,1.5929408439361046
9.391135568738612e-05,0.0036783999999999996,272.7803417531996,102.30890801044795,1.5929408439361046
9.442196549429883e-05,0.0036983999999999997,272.88048768645285,102.30890801044795,1.5929408439361046
9.507554604714711e-05,0.003724,273.0083668217775,102.30890801044795,1.5929408439361046
9.536148753901823e-05,0.0037351999999999997,273.0642060864275,102.30890801044795,1.5929408439361046
9.558615585405983e-05,0.003744,273.1080339979978,102.30890801044795,1.5929408439361046
9.628058519146112e-05,0.0037711999999999997,273.24324877735944,102.30890801044795,1.5929408439361046
9.642355593739667e-05,0.0037768,273.271039840979,102.30890801044795,1.5929408439361046
9.683204378292684e-05,0.0037928,273.35035446547784,102.30890801044795,1.5929408439361046
9.726095602073353e-05,0.0038096,273.4334945097615,102.30890801044795,1.5929408439361046
9.738350237439257e-05,0.0038144,273.45722252891454,102.30890801044795,1.5929408439361046
9.760817068943416e-05,0.0038231999999999997,273.50069367467995,102.30890801044795,1.5929408439361046
9.79145365735818e-05,0.0038352,273.5599096738922,102.30890801044795,1.5929408439361046
9.820047806545292e-05,0.0038464,273.61511277875314,102.30890801044795,1.5929408439361046
9.828217563455896e-05,0.0038496,273.6308735755442,102.30890801044795,1.5929408439361046
9.860896591098309e-05,0.0038623999999999998,273.6938657350406,102.30890801044795,1.5929408439361046
9.928297085610787e-05,0.0038888,273.82353052229337,102.30890801044795,1.5929408439361046
9.975273187846756e-05,0.0039071999999999996,273.9137000064589,102.30890801044795,1.5929408439361046
0.00010038588803903933,0.003932,274.0349711996453,102.30890801044795,1.5929408439361046
0.00010136625886831173,0.0039704,274.2221590663891,102.30890801044795,1.5929408439361046
0.0001015500783988003,0.0039775999999999995,274.2571780487374,102.30890801044795,1.5929408439361046
0.00010173389792928889,0.0039848,274.2921723180262,102.30890801044795,1.5929408439361046
0.00010187686867522444,0.0039904,274.31937303718473,102.30890801044795,1.5929408439361046
0.00010604422915318632,0.004153630726145229,275.10580628901084,102.30890801044795,1.5929408439361046
0.00011339848122314338,0.004441688337667534,276.46484810635025,102.30890801044795,1.5929408439361046
0.00012859726883438795,0.0050370074014802965,279.1690829264484,102.30890801044795,1.5929408439361046
0.00014085435561764974,0.0055171034206841375,281.26004653189733,102.30890801044795,1.5929408439361046
0.00015164059198692005,0.005939587917583517,283.0420257208526,102.30890801044795,1.5929408439361046
0.0001594851275282076,0.006246849369873975,284.3070901691762,102.30890801044795,1.5929408439361046
0.00017174221431146935,0.006726945389077816,286.236201456359,102.30890801044795,1.5929408439361046
0.00018841185233670532,0.007379875975195039,288.7756845177912,102.30890801044795,1.5929408439361046
0.00019919808870597568,0.007802360472094419,290.3722685647094,102.30890801044795,1.5929408439361046
0.00020655234077593274,0.008090418083616723,291.44155946353266,102.30890801044795,1.5929408439361046
0.0002188094275591945,0.008570514102820564,293.19128337915845,102.30890801044795,1.5929408439361046
0.0002271442465718125,0.008896979395879176,294.35930895676677,102.30890801044795,1.5929408439361046
0.00023155679781378675,0.009069813962792559,294.9709016257211,102.30890801044795,1.5929408439361046
0.00023253736475644767,0.009108221644328866,295.10619188035975,102.30890801044795,1.5929408439361046
0.0002550904044376493,0.009991598319663933,298.159003942409,102.30890801044795,1.5929408439361046
0.00025803210526563215,0.010106821364272855,298.54928641580733,102.30890801044795,1.5929408439361046
0.0002648960738642587,0.010375675135027004,299.4532587173722,102.30890801044795,1.5929408439361046
0.00028009486147550334,0.010970994198839769,301.4230178647111,102.30890801044795,1.5929408439361046
0.00029921591685739163,0.011719943988797759,303.8428462606068,102.30890801044795,1.5929408439361046
0.0003021576176853744,0.01183516703340668,304.2097047998145,102.30890801044795,1.5929408439361046
0.0003070604523986791,0.012027205441088217,304.8180553192316,102.30890801044795,1.5929408439361046
0.00031000215322666197,0.012142428485697139,305.18124748132107,102.30890801044795,1.5929408439361046
0.00033108434249387223,0.012968193638727745,307.74588590854927,102.30890801044795,1.5929408439361046
0.00033598717720717693,0.013160232046409282,308.33308802020895,102.30890801044795,1.5929408439361046
0.00035559851606039574,0.013928385677135427,310.64922551654865,102.30890801044795,1.5929408439361046
0.0003663847524296661,0.014350870174034807,311.9018433259238,102.30890801044795,1.5929408439361046
0.0003820738235122411,0.014965393078615724,313.69845624033667,102.30890801044795,1.5929408439361046
0.00038893779211086774,0.015234246849369875,314.47540094508486,102.30890801044795,1.5929408439361046
0.00039384062682417244,0.015426285257051411,315.02709094886745,102.30890801044795,1.5929408439361046
0.00040119487889412947,0.015714342868573716,315.8496301344383,102.30890801044795,1.5929408439361046
0.0004105102648494084,0.016079215843168633,316.8831198459212,102.30890801044795,1.5929408439361046
0.00041198111526339986,0.016136827365473096,317.0454625876705,102.30890801044795,1.5929408439361046
0.00042129650121867874,0.016501700340068013,318.06843339512557,102.30890801044795,1.5929408439361046
0.00042668961940331386,0.0167129425885177,318.6566474356483,102.30890801044795,1.5929408439361046
0.0004379661392439147,0.017154630926185237,319.8772615063356,102.30890801044795,1.5929408439361046
0.0004467912417278632,0.017500300060012002,320.82399490431993,102.30890801044795,1.5929408439361046
0.0004541454937978202,0.017788357671534305,321.60738093520894,102.30890801044795,1.5929408439361046
0.00046591229710975154,0.018249249849969992,322.85058520461064,102.30890801044795,1.5929408439361046
0.0004732665491797086,0.0185373074614923,323.6213725074264,102.30890801044795,1.5929408439361046
0.0004825819351349876,0.01890218043608722,324.59102991769134,102.30890801044795,1.5929408439361046
0.000500722423574215,0.019612722544508902,326.45861114149255,102.30890801044795,1.5929408439361046
0.0005085669591155025,0.01991998399679936,327.2580199933455,102.30890801044795,1.5929408439361046
0.0005384742508666612,0.02109141828365673,330.2626341604915,102.30890801044795,1.5929408439361046
0.0005443576525226268,0.021321864372874574,330.84596686036656,102.30890801044795,1.5929408439361046
0.0005512216211212533,0.021590718143628725,331.52342305074365,102.30890801044795,1.5929408439361046
0.0005678912591464894,0.02224364872974595,333.1551201054121,102.30890801044795,1.5929408439361046
0.0005713232434458027,0.022378075615123026,333.4887269664084,102.30890801044795,1.5929408439361046
0.0005796580624584206,0.022704540908181636,334.2956778071751,102.30890801044795,1.5929408439361046
0.0005835803302290645,0.022858171634326865,334.673852405227,102.30890801044795,1.5929408439361046
0.0005963277004836567,0.02335747149429886,335.89613005789136,102.30890801044795,1.5929408439361046
0.0006036819525536138,0.023645529105821166,336.5966546872624,102.30890801044795,1.5929408439361046
0.0006110362046235708,0.02393358671734347,337.2938588443422,102.30890801044795,1.5929408439361046
0.0006139779054515536,0.02404880976195239,337.5718232431359,102.30890801044795,1.5929408439361046
0.0006179001732221973,0.02420244048809762,337.94163583618433,102.30890801044795,1.5929408439361046
0.0006335892443047724,0.024816963392678536,339.41182179001805,102.30890801044795,1.5929408439361046
0.00064143377984606,0.025124224844968995,340.1415853306269,102.30890801044795,1.5929408439361046
0.0006546714335719826,0.02564272854570914,341.3652174874492,102.30890801044795,1.5929408439361046
0.000664477102998592,0.026026805361072214,342.2653995307563,102.30890801044795,1.5929408439361046
0.0006885009930937851,0.026967793558711744,344.44922425631086,102.30890801044795,1.5929408439361046
0.0007036997807050297,0.027563112622524505,345.8154905857584,102.30890801044795,1.5929408439361046
0.0007169374344309524,0.028081616323264655,346.99611416552165,102.30890801044795,1.5929408439361046
0.0007306653716282056,0.028619323864772953,348.21151914841425,102.30890801044795,1.5929408439361046
0.0007458641592394501,0.029214642928585718,349.54680467829314,102.30890801044795,1.5929408439361046
0.0007522378443667462,0.029464292858571713,350.10360008911886,102.30890801044795,1.5929408439361046
0.0007566503956087205,0.029637127425485098,350.48799648840213,102.30890801044795,1.5929408439361046
0.0007605726633793643,0.029790758151630327,350.8289488433047,102.30890801044795,1.5929408439361046
0.0007674366319779908,0.030059611922384478,351.42397000785706,102.30890801044795,1.5929408439361046
0.0007693977658633128,0.030136427285457092,351.59359436768085,102.30890801044795,1.5929408439361046
0.0007747908840479478,0.03034766953390678,352.0591941296246,102.30890801044795,1.5929408439361046
0.0007777325848759307,0.030462892578515702,352.3126248324875,102.30890801044795,1.5929408439361046
0.0007806742857039135,0.030578115623124624,352.5656819644868,102.30890801044795,1.5929408439361046
0.0007880285377738707,0.03086617323464693,353.1967032101145,102.30890801044795,1.5929408439361046
0.0007919508055445144,0.03101980396079216,353.53230858212675,102.30890801044795,1.5929408439361046
0.0007963633567864886,0.03119263852770554,353.9090907474877,102.30890801044795,1.5929408439361046
0.0007978342072004801,0.03125025005001,354.0345037535497,102.30890801044795,1.5929408439361046
0.0008125427113403942,0.031826365273054616,355.2837139295624,102.30890801044795,1.5929408439361046
0.0008169552625823682,0.03199919983996799,355.6567531802869,102.30890801044795,1.5929408439361046
0.0008262706485376472,0.03236407281456291,356.4417097878417,102.30890801044795,1.5929408439361046
0.000832154050193613,0.03259451890378076,356.9356940571909,102.30890801044795,1.5929408439361046
0.0008483334047475183,0.03322824564912982,358.2871769248973,102.30890801044795,1.5929408439361046
0.0008498042551615098,0.033285857171434285,358.4095383651876,102.30890801044795,1.5929408439361046
0.0008542168064034842,0.03345869173834767,358.7761280693623,102.30890801044795,1.5929408439361046
0.000862551625416102,0.03378515703140628,359.4665665696682,102.30890801044795,1.5929408439361046
0.0008694155940147286,0.03405401080216043,360.0332113676199,102.30890801044795,1.5929408439361046
0.000890497783281939,0.03487977595519104,361.7628094979921,102.30890801044795,1.5929408439361046
0.0009096188386638271,0.035628725745149026,363.3177526236172,102.30890801044795,1.5929408439361046
0.0009302107444597072,0.03643528705741149,364.97811799618785,102.30890801044795,1.5929408439361046
0.000935603862644342,0.03664652930586117,365.4105989906822,102.30890801044795,1.5929408439361046
0.000946880382484943,0.03708821764352871,366.3117482749302,102.30890801044795,1.5929408439361046
0.000965511154395501,0.03781796359271855,367.7914871664118,102.30890801044795,1.5929408439361046
0.0009782585246500932,0.03831726345269054,368.7975295718596,102.30890801044795,1.5929408439361046
0.0010066949659872603,0.03943108621724345,371.02353460068576,102.30890801044795,1.5929408439361046
0.0010091463833439126,0.039527105421084216,371.2142759325429,102.30890801044795,1.5929408439361046
0.001022874320541166,0.040064812962592525,372.2791066644477,102.30890801044795,1.5929408439361046
0.0010336605569104362,0.040487297459491894,373.11185431093753,102.30890801044795,1.5929408439361046
0.001044937076751037,0.04092898579715944,373.97883864161133,102.30890801044795,1.5929408439361046
0.0010699415337888912,0.041908381676335274,375.8883711772662,102.30890801044795,1.5929408439361046
0.0010728832346168738,0.042023604720944185,376.1118720650162,102.30890801044795,1.5929408439361046
0.0010920042899987624,0.042772554510902186,377.55884567680965,102.30890801044795,1.5929408439361046
0.0010993585420687193,0.043060612122424485,378.1127386454352,102.30890801044795,1.5929408439361046
0.0011277949834058866,0.04417443488697739,380.2409980184469,102.30890801044795,1.5929408439361046
0.0011341686685331824,0.04442408481696339,380.71513845580733,102.30890801044795,1.5929408439361046
0.0011425034875458006,0.044750550110022005,381.3336032439803,102.30890801044795,1.5929408439361046
0.0011518188735010796,0.045115423084616926,382.02275004048477,102.30890801044795,1.5929408439361046
0.0011626051098703502,0.04553790758151631,382.8179997488309,102.30890801044795,1.5929408439361046
0.0011753524801249421,0.0460372074414883,383.754140075154,102.30890801044795,1.5929408439361046
0.0011851581495515514,0.04642128425685137,384.47155609933776,102.30890801044795,1.5929408439361046
0.001188590133850865,0.04655571114222845,384.72210432289484,102.30890801044795,1.5929408439361046
0.0011974152363348133,0.04690138027605521,385.36507906657994,102.30890801044795,1.5929408439361046
0.0012028083545194486,0.047112622524504905,385.7570983630384,102.30890801044795,1.5929408439361046
0.0012116334570033969,0.04745829165833167,386.39710904728213,102.30890801044795,1.5929408439361046
0.0012175168586593629,0.04768873774754952,386.82277311299634,102.30890801044795,1.5929408439361046
0.001219968276016015,0.047784756951390284,386.99989629191856,102.30890801044795,1.5929408439361046
0.0012317350793279464,0.04824564912982597,387.84816291849074,102.30890801044795,1.5929408439361046
0.0012351670636272596,0.04838007601520304,388.0949779416987,102.30890801044795,1.5929408439361046
0.0012557589694231393,0.04918663732746549,389.57029027263025,102.30890801044795,1.5929408439361046
0.0012606618041364438,0.04937867573514702,389.92016083374887,102.30890801044795,1.5929408439361046
0.0012773314421616801,0.05003160632126426,391.1057713811513,102.30890801044795,1.5929408439361046
0.0012871371115882894,0.05041568313662732,391.8003706416038,102.30890801044795,1.5929408439361046
0.0013042970330848559,0.0510878175635127,393.0109738501819,102.30890801044795,1.5929408439361046
0.001318024970282109,0.05162552510502101,393.97498994312224,102.30890801044795,1.5929408439361046
0.0013248889388807355,0.05189437887577515,394.45552895224597,102.30890801044795,1.5929408439361046
0.0013278306397087184,0.05200960192038408,394.66117690935107,102.30890801044795,1.5929408439361046
0.0013322431909506929,0.052182436487297465,394.9693160043268,102.30890801044795,1.5929408439361046
0.0013410682934346411,0.05252810562112423,395.5844026915468,102.30890801044795,1.5929408439361046
0.0013547962306318941,0.05306581316263252,396.53807578243806,102.30890801044795,1.5929408439361046
0.0013680338843578168,0.05358431686337267,397.4541262560444,102.30890801044795,1.5929408439361046
0.0013945091918096625,0.05462132426485297,399.2759214650859,102.30890801044795,1.5929408439361046
0.0013964703256949841,0.05469813962792558,399.4103302460171,102.30890801044795,1.5929408439361046
0.0014028440108222807,0.05494778955791159,399.846651259833,102.30890801044795,1.5929408439361046
0.0014175525149621945,0.05552390478095619,400.85060587342525,102.30890801044795,1.5929408439361046
0.0014263776174461432,0.05586957391478296,401.45102874568005,102.30890801044795,1.5929408439361046
0.001430299885216787,0.05602320464092819,401.7174181286599,102.30890801044795,1.5929408439361046
0.0014415764050573876,0.05646489297859572,402.48170523256516,102.30890801044795,1.5929408439361046
0.0014479500901846837,0.05671454290858172,402.9126621561004,102.30890801044795,1.5929408439361046
0.0014494209405986752,0.05677215443088618,403.0120086135007,102.30890801044795,1.5929408439361046
0.0014886436183051128,0.05830846169233847,405.6469186071887,102.30890801044795,1.5929408439361046
0.001491095035661765,0.05840448089617924,405.8106957413468,102.30890801044795,1.5929408439361046
0.001492075602604426,0.05844288857771554,405.87617718824725,102.30890801044795,1.5929408439361046
0.001497468720789061,0.05865413082616523,406.2360255988229,102.30890801044795,1.5929408439361046
0.0015038424059163572,0.05890378075615123,406.6606500091502,102.30890801044795,1.5929408439361046
0.001507764673687001,0.05905741148229646,406.9216085032407,102.30890801044795,1.5929408439361046
0.0015165897761709494,0.05940308061612322,407.5077990565694,102.30890801044795,1.5929408439361046
0.001523453744769576,0.05967193438687737,407.96280580503844,102.30890801044795,1.5929408439361046
0.001540123382794812,0.060324864972994593,409.0645063499433,102.30890801044795,1.5929408439361046
0.0015533610365207346,0.06084336867373474,409.93607683224263,102.30890801044795,1.5929408439361046
0.0015695403910746405,0.06147709541908382,410.99740573172824,102.30890801044795,1.5929408439361046
0.001571501524959962,0.061553910782156426,411.1257610818846,102.30890801044795,1.5929408439361046
0.0015739529423166147,0.06164992998599721,411.28611745527184,102.30890801044795,1.5929408439361046
0.0015798363439725803,0.06188037607521504,411.67057586445264,102.30890801044795,1.5929408439361046
0.0015881711629851982,0.06220684136827366,412.21427081403647,102.30890801044795,1.5929408439361046
0.0015916031472845114,0.06234126825365073,412.4378216276417,102.30890801044795,1.5929408439361046
0.001619059021679018,0.06341668333666733,414.21950990651055,102.30890801044795,1.5929408439361046
0.0016298452580482882,0.06383916783356672,414.91623016815646,102.30890801044795,1.5929408439361046
0.001637689793589576,0.06414642928585718,415.421806848523,102.30890801044795,1.5929408439361046
0.0016533788646721508,0.06476095219043809,416.43013568413056,102.30890801044795,1.5929408439361046
0.0016622039671560992,0.06510662132426485,416.99568066662727,102.30890801044795,1.5929408439361046
0.0016872084241939533,0.06608601720344069,418.5917337250882,102.30890801044795,1.5929408439361046
0.0016916209754359274,0.06625885177035407,418.87242987635426,102.30890801044795,1.5929408439361046
0.0016975043770918932,0.06648929785957192,419.24624762051013,102.30890801044795,1.5929408439361046
0.0017063294795758414,0.06683496699339868,419.80602821053566,102.30890801044795,1.5929408439361046
0.0017107420308178159,0.06700780156031207,420.08549500477613,102.30890801044795,1.5929408439361046
0.0017656537796068286,0.06915863172634527,423.54011389347386,102.30890801044795,1.5929408439361046
0.0017793817168040816,0.06969633926785357,424.39718985588337,102.30890801044795,1.5929408439361046
0.0017818331341607342,0.06979235847169435,424.54996737695865,102.30890801044795,1.5929408439361046
0.0017896776697020219,0.07009961992398481,425.0383054992859,102.30890801044795,1.5929408439361046
0.0017945805044153264,0.07029165833166634,425.3430929469997,102.30890801044795,1.5929408439361046
0.0018029153234279441,0.07061812362472494,425.86048736632574,102.30890801044795,1.5929408439361046
0.00180879872508391,0.0708485697139428,426.22514546649774,102.30890801044795,1.5929408439361046
0.0018132112763258844,0.07102140428085618,426.49833554987896,102.30890801044795,1.5929408439361046
0.0018220363788098326,0.07136707341468294,427.04393911547857,102.30890801044795,1.5929408439361046
0.001824487796166485,0.07146309261852371,427.1953126315843,102.30890801044795,1.5929408439361046
0.0018323323317077727,0.07177035407081417,427.6791757102213,102.30890801044795,1.5929408439361046
0.001852433954032322,0.07255771154230847,428.91540170020437,102.30890801044795,1.5929408439361046
0.0018622396234589313,0.07294178835767154,429.51653936183266,102.30890801044795,1.5929408439361046
0.001873516143299532,0.07338347669533907,430.2063236736632,102.30890801044795,1.5929408439361046
0.0018818509623121501,0.07370994198839768,430.7151240268992,102.30890801044795,1.5929408439361046
0.0018882246474394462,0.07395959191838368,431.10361386712697,102.30890801044795,1.5929408439361046
0.0018965594664520642,0.0742860572114423,431.6108682434378,102.30890801044795,1.5929408439361046
0.0018995011672800469,0.07440128025605121,431.7896915305239,102.30890801044795,1.5929408439361046
0.0019019525846366995,0.07449729945989199,431.93862844691057,102.30890801044795,1.5929408439361046
0.0019191125061332657,0.07516943388677735,432.9790986091555,102.30890801044795,1.5929408439361046
0.0019372529945724934,0.07587997599519905,434.0750866702518,102.30890801044795,1.5929408439361046
0.0019416655458144674,0.07605281056211242,434.3410722717435,102.30890801044795,1.5929408439361046
0.0019524517821837377,0.07647529505901181,434.99026879280444,102.30890801044795,1.5929408439361046
0.0019666700028523215,0.07703220644128826,435.8438947700249,102.30890801044795,1.5929408439361046
0.0019720631210369565,0.07724344868973795,436.16705389742236,102.30890801044795,1.5929408439361046
0.00197549510533627,0.07737787557511502,436.3725211727912,102.30890801044795,1.5929408439361046
0.0020068732475014197,0.07860692138427686,438.24466830847894,102.30890801044795,1.5929408439361046
0.0020117760822147245,0.07879895979195839,438.5361568852653,102.30890801044795,1.5929408439361046
0.0020485473425645097,0.08023924784956991,440.7135586026203,102.30890801044795,1.5929408439361046
0.0020612947128191023,0.08073854770954192,441.46482618408237,102.30890801044795,1.5929408439361046
0.002070610098774381,0.08110342068413683,442.012684054401,102.30890801044795,1.5929408439361046
0.0020804157682009906,0.0814874974994999,442.5883391029106,102.30890801044795,1.5929408439361046
0.0020975756896975573,0.08215963192638528,443.5931956982089,102.30890801044795,1.5929408439361046
0.002116696745079445,0.08290858171634327,444.70912407808544,102.30890801044795,1.5929408439361046
0.002124541280620733,0.08321584316863373,445.1658027289678,102.30890801044795,1.5929408439361046
0.0021284635483913767,0.08336947389477896,445.393895411808,102.30890801044795,1.5929408439361046
0.0021338566665760118,0.08358071614322865,445.7072553723374,102.30890801044795,1.5929408439361046
0.0021451331864166126,0.08402240448089618,446.3614662231262,102.30890801044795,1.5929408439361046
0.0021500360211299174,0.08421444288857773,446.64548723317915,102.30890801044795,1.5929408439361046
0.0021637639583271706,0.08475215043008602,447.4394054219231,102.30890801044795,1.5929408439361046
0.0021740599112251104,0.08515543108621725,448.0335555483824,102.30890801044795,1.5929408439361046
0.0021907295492503464,0.08580836167233447,448.9931915377748,102.30890801044795,1.5929408439361046
0.002193671250078329,0.08592358471694339,449.1622430250236,102.30890801044795,1.5929408439361046
0.002208870037689574,0.08651890378075616,450.0342712570291,102.30890801044795,1.5929408439361046
0.0022167145732308615,0.08682616523304662,450.4834345713311,102.30890801044795,1.5929408439361046
0.002224559108772149,0.08713342668533708,450.9319784049517,102.30890801044795,1.5929408439361046
0.00223632591208408,0.08759431886377275,451.6036392598252,102.30890801044795,1.5929408439361046
0.002240738463326054,0.08776715343068614,451.8551565642512,102.30890801044795,1.5929408439361046
0.002250544132752664,0.08815123024604922,452.4133933587316,102.30890801044795,1.5929408439361046
0.002259369235236612,0.08849689937987598,452.91499596248633,102.30890801044795,1.5929408439361046
0.0022691749046632216,0.08888097619523905,453.4714368674507,102.30890801044795,1.5929408439361046
0.0022981016294717194,0.09001400280056011,455.1074996311065,102.30890801044795,1.5929408439361046
0.002301533613771033,0.0901484296859372,455.30107436158397,102.30890801044795,1.5929408439361046
0.0023064364484843376,0.09034046809361873,455.5774145224162,102.30890801044795,1.5929408439361046
0.00233046033857953,0.09128145629125825,456.92818375748396,102.30890801044795,1.5929408439361046
0.0023608579138020194,0.09247209441888378,458.62956269537835,102.30890801044795,1.5929408439361046
0.0023701732997572986,0.0928369673934787,459.14923995190316,102.30890801044795,1.5929408439361046
0.002372624717113951,0.09293298659731947,459.28586465586085,102.30890801044795,1.5929408439361046
0.0023829206700118908,0.09333626725345069,459.85908827162433,102.30890801044795,1.5929408439361046
0.002384881803897213,0.09341308261652331,459.9681641209414,102.30890801044795,1.5929408439361046
0.0024118473948203886,0.09446929385877176,461.464427428074,102.30890801044795,1.5929408439361046
0.0024241044816036505,0.0949493898779756,462.1423889046697,102.30890801044795,1.5929408439361046
0.002428026749374294,0.09510302060412083,462.3590540474287,102.30890801044795,1.5929408439361046
0.002438322702272234,0.09550630126025206,462.9271515904863,102.30890801044795,1.5929408439361046
0.0024422449700428777,0.09565993198639729,463.1433235228777,102.30890801044795,1.5929408439361046
0.0024466575212848517,0.09583276655331066,463.3863551696398,102.30890801044795,1.5929408439361046
0.0024554826237688007,0.09617843568713744,463.8719062502188,102.30890801044795,1.5929408439361046
0.002458424324596783,0.09629365873174635,464.03360530717543,102.30890801044795,1.5929408439361046
0.0024647980097240794,0.09654330866173236,464.3836946234715,102.30890801044795,1.5929408439361046
0.0024819579312206456,0.09721544308861772,465.3244923351734,102.30890801044795,1.5929408439361046
0.0024912733171759244,0.09758031606321264,465.83414862493,102.30890801044795,1.5929408439361046
0.002511374939500474,0.09836767353470695,466.93140781599794,102.30890801044795,1.5929408439361046
0.0025231417428124053,0.09882856571314264,467.5721165508786,102.30890801044795,1.5929408439361046
0.00252804457752571,0.09902060412082417,467.8387344734291,102.30890801044795,1.5929408439361046
0.0025393210973663105,0.0994622924584917,468.4511915814348,102.30890801044795,1.5929408439361046
0.002543733648608285,0.09963512702540508,468.69055986005435,102.30890801044795,1.5929408439361046