File: datasets/aisi_316_L/data/M1/train_68.csv
Time(s),Strain(%),Stress(MPa),Temp(C),Log_SR(s-1)
0.0,0.0,0.0,254.34190081173222,4.556758047926507
3.5518279603313535e-10,1.28e-05,2.3229618,254.34190081173222,4.556758047926507
4.439784950414192e-10,1.6e-05,2.90370225,254.34190081173222,4.556758047926507
6.659677425621289e-10,2.4e-05,4.355553375,254.34190081173222,4.556758047926507
9.767526890911224e-10,3.52e-05,6.38814495,254.34190081173222,4.556758047926507
1.3097365603721867e-09,4.7199999999999995e-05,8.565921637499999,254.34190081173222,4.556758047926507
1.3985322593804705e-09,5.04e-05,9.1466620875,254.34190081173222,4.556758047926507
2.108897851446741e-09,7.599999999999999e-05,13.792585687499999,254.34190081173222,4.556758047926507
2.6194731207443733e-09,9.439999999999999e-05,17.131843274999998,254.34190081173222,4.556758047926507
3.529629035579283e-09,0.0001272,23.0844328875,254.34190081173222,4.556758047926507
3.6406236593396373e-09,0.0001312,23.81035845,254.34190081173222,4.556758047926507
3.995806455372773e-09,0.000144,26.13332025,254.34190081173222,4.556758047926507
5.0169569939680376e-09,0.0001808,32.811835425,254.34190081173222,4.556758047926507
5.416537639505314e-09,0.0001952,35.425167450000004,254.34190081173222,4.556758047926507
5.682924736530166e-09,0.0002048,37.1673888,254.34190081173222,4.556758047926507
6.548682801860933e-09,0.000236,42.8296081875,254.34190081173222,4.556758047926507
6.8816666731419985e-09,0.000248,45.007384875,254.34190081173222,4.556758047926507
7.436639791943772e-09,0.000268,48.637012687500004,254.34190081173222,4.556758047926507
7.703026888968623e-09,0.00027759999999999997,50.3792340375,254.34190081173222,4.556758047926507
7.88061828698519e-09,0.00028399999999999996,51.54071493749999,254.34190081173222,4.556758047926507
8.080408609753829e-09,0.0002912,52.847380949999994,254.34190081173222,4.556758047926507
8.635381728555603e-09,0.0003112,56.4770087625,254.34190081173222,4.556758047926507
8.76857527706803e-09,0.000316,57.348119437499996,254.34190081173222,4.556758047926507
9.123758073101164e-09,0.00032879999999999997,59.6710812375,254.34190081173222,4.556758047926507
9.656532267150868e-09,0.000348,63.1555239375,254.34190081173222,4.556758047926507
1.0011715063184003e-08,0.0003608,65.4784857375,254.34190081173222,4.556758047926507
1.1121661300787552e-08,0.0004008,72.7377413625,254.34190081173222,4.556758047926507
1.1721032269093467e-08,0.00042239999999999997,76.6577394,254.34190081173222,4.556758047926507
1.2187209688886958e-08,0.0004392,79.7066267625,254.34190081173222,4.556758047926507
1.2453596785911808e-08,0.00044879999999999996,81.44884811249999,254.34190081173222,4.556758047926507
1.2764381732440801e-08,0.00045999999999999996,83.48143968749999,254.34190081173222,4.556758047926507
1.336375270074672e-08,0.0004816,87.401437725,254.34190081173222,4.556758047926507
1.3563543023515357e-08,0.0004888,88.7081037375,254.34190081173222,4.556758047926507
1.4074118292812989e-08,0.0005072,92.047361325,254.34190081173222,4.556758047926507
1.4384903239341984e-08,0.0005184,94.07995290000001,254.34190081173222,4.556758047926507
1.5383854853185173e-08,0.0005543999999999999,100.61328296249998,254.34190081173222,4.556758047926507
1.593882797198695e-08,0.0005744,104.242910775,254.34190081173222,4.556758047926507
1.6116419370003518e-08,0.0005808,105.404391675,254.34190081173222,4.556758047926507
1.649380109078872e-08,0.0005943999999999999,107.87253858749999,254.34190081173222,4.556758047926507
1.662699463930115e-08,0.0005991999999999999,108.74364926249999,254.34190081173222,4.556758047926507
1.7714741952152628e-08,0.0006384,115.857719775,254.34190081173222,4.556758047926507
1.829191399570647e-08,0.0006592,119.6325327,254.34190081173222,4.556758047926507
1.84251075442189e-08,0.000664,120.503643375,254.34190081173222,4.556758047926507
1.9313064534301735e-08,0.000696,126.311047875,254.34190081173222,4.556758047926507
1.9512854857070374e-08,0.0007032,127.61771388749999,254.34190081173222,4.556758047926507
1.9956833352111792e-08,0.0007191999999999999,130.52141613749998,254.34190081173222,4.556758047926507
2.0178822599632505e-08,0.0007272,131.9732672625,254.34190081173222,4.556758047926507
2.0844790342194632e-08,0.0007511999999999999,136.3288206375,254.34190081173222,4.556758047926507
2.0955784965954987e-08,0.0007551999999999999,137.05474619999998,254.34190081173222,4.556758047926507
2.144416131050055e-08,0.0007727999999999999,140.248818675,254.34190081173222,4.556758047926507
2.1821543031285753e-08,0.0007863999999999999,142.7169655875,254.34190081173222,4.556758047926507
2.2065731203558535e-08,0.0007951999999999999,144.314001825,254.34190081173222,4.556758047926507
2.2509709698599953e-08,0.0008112,147.217704075,254.34190081173222,4.556758047926507
2.295368819364137e-08,0.0008271999999999999,150.12140632499998,254.34190081173222,4.556758047926507
2.3064682817401726e-08,0.0008311999999999999,150.8473318875,254.34190081173222,4.556758047926507
2.3397666688682793e-08,0.0008432,153.025108575,254.34190081173222,4.556758047926507
2.406363443124492e-08,0.0008671999999999999,157.38066195,254.34190081173222,4.556758047926507
2.4396618302525987e-08,0.0008792,159.5584386375,254.34190081173222,4.556758047926507
2.492939249657569e-08,0.0008983999999999999,163.04288133749998,254.34190081173222,4.556758047926507
2.51513817440964e-08,0.0009063999999999999,164.4947324625,254.34190081173222,4.556758047926507
2.5595360239137817e-08,0.0009224,167.3984347125,254.34190081173222,4.556758047926507
2.6416720454964442e-08,0.0009519999999999999,172.770283875,254.34190081173222,4.556758047926507
2.677190325099758e-08,0.0009647999999999999,175.093245675,254.34190081173222,4.556758047926507
2.772645701533663e-08,0.0009992,181.3362055125,254.34190081173222,4.556758047926507
2.8281430134138406e-08,0.0010192,184.965833325,254.34190081173222,4.556758047926507
2.8348026908394616e-08,0.0010216,185.40138866249998,254.34190081173222,4.556758047926507
2.8769806478683968e-08,0.0010368,188.15990580000002,254.34190081173222,4.556758047926507
2.8947397876700533e-08,0.0010432,189.3213867,254.34190081173222,4.556758047926507
2.9235983898477456e-08,0.0010536,191.2087931625,254.34190081173222,4.556758047926507
2.9679962393518874e-08,0.0010696,194.1124954125,254.34190081173222,4.556758047926507
3.012394088856029e-08,0.0010856,197.0161976625,254.34190081173222,4.556758047926507
3.098969895389106e-08,0.0011168,202.67841705,254.34190081173222,4.556758047926507
3.1455876373684553e-08,0.0011336,205.7273044125,254.34190081173222,4.556758047926507
3.2010849492486326e-08,0.0011535999999999999,209.35693222499998,254.34190081173222,4.556758047926507
3.285440863306502e-08,0.001184,214.82172978147992,254.34190081173222,4.556758047926507
3.312079573008987e-08,0.0011936,214.88404962889123,254.34190081173222,4.556758047926507
3.329838712810644e-08,0.0012,214.92548762805117,254.34190081173222,4.556758047926507
3.434173659145378e-08,0.0012376,215.16721758081363,254.34190081173222,4.556758047926507
3.5496080678561464e-08,0.0012791999999999999,215.4313499909893,254.34190081173222,4.556758047926507
3.5740268850834246e-08,0.0012879999999999999,215.48679245025818,254.34190081173222,4.556758047926507
3.618424734587567e-08,0.001304,215.5872199074091,254.34190081173222,4.556758047926507
3.7427387131991645e-08,0.0013488,215.8658917472632,254.34190081173222,4.556758047926507
3.753838175575199e-08,0.0013528,215.89059627216224,254.34190081173222,4.556758047926507
3.811555379930584e-08,0.0013736,216.01860344998664,254.34190081173222,4.556758047926507
3.831534412207448e-08,0.0013808,216.06273720381392,254.34190081173222,4.556758047926507
3.8648327993355544e-08,0.0013928,216.1360945353324,254.34190081173222,4.556758047926507
3.962508068244667e-08,0.001428,216.34986722249113,254.34190081173222,4.556758047926507
3.978047315571116e-08,0.0014336,216.3836861112479,254.34190081173222,4.556758047926507
4.031324734976086e-08,0.0014528,216.4992474491541,254.34190081173222,4.556758047926507
4.0735026920050214e-08,0.001468,216.590311628532,254.34190081173222,4.556758047926507
4.093481724281885e-08,0.0014751999999999999,216.6333188768552,254.34190081173222,4.556758047926507
4.166738175963719e-08,0.0015015999999999999,216.7903165747896,254.34190081173222,4.556758047926507
4.213355917943068e-08,0.0015183999999999998,216.8896639564821,254.34190081173222,4.556758047926507
4.248874197546382e-08,0.0015312,216.96506972587954,254.34190081173222,4.556758047926507
4.28883226210011e-08,0.0015455999999999998,217.0496079800804,254.34190081173222,4.556758047926507
4.339889789029873e-08,0.0015639999999999999,217.15718340459566,254.34190081173222,4.556758047926507
4.362088713781944e-08,0.0015719999999999998,217.20380125230136,254.34190081173222,4.556758047926507
4.377627961108393e-08,0.0015776,217.23637870942204,254.34190081173222,4.556758047926507
4.4109263482365e-08,0.0015895999999999998,217.30603606868942,254.34190081173222,4.556758047926507
4.4420048428893993e-08,0.0016007999999999999,217.3708648026608,254.34190081173222,4.556758047926507
4.457544090215849e-08,0.0016064,217.40321281702174,254.34190081173222,4.556758047926507
4.528580649422476e-08,0.001632,217.55053297078783,254.34190081173222,4.556758047926507
4.5685387139762034e-08,0.0016464,217.63300443963792,254.34190081173222,4.556758047926507
4.599617208629103e-08,0.0016576,217.69695457910544,254.34190081173222,4.556758047926507
4.706172047439044e-08,0.001696,217.91494409901605,254.34190081173222,4.556758047926507
4.728370972191115e-08,0.001704,217.96011534436968,254.34190081173222,4.556758047926507
4.794967746447328e-08,0.001728,218.09513542381376,254.34190081173222,4.556758047926507
4.8526849508027124e-08,0.0017488,218.21156231209656,254.34190081173222,4.556758047926507
4.8704440906043686e-08,0.0017552,218.24727715501422,254.34190081173222,4.556758047926507
4.890423122881233e-08,0.0017624,218.28739570074652,254.34190081173222,4.556758047926507
4.917061832583718e-08,0.001772,218.3407878050314,254.34190081173222,4.556758047926507
4.972559144463895e-08,0.001792,218.45166038859355,254.34190081173222,4.556758047926507
5.023616671393658e-08,0.0018104,218.55323768044317,254.34190081173222,4.556758047926507
5.063574735947386e-08,0.0018248,218.63245236634538,254.34190081173222,4.556758047926507
5.103532800501114e-08,0.0018391999999999998,218.71142363307098,254.34190081173222,4.556758047926507
5.147930650005256e-08,0.0018552,218.7988872089258,254.34190081173222,4.556758047926507
5.172349467232534e-08,0.001864,218.84686676345032,254.34190081173222,4.556758047926507
5.192328499509398e-08,0.0018712,218.88605708925377,254.34190081173222,4.556758047926507
5.23672634901354e-08,0.0018872,218.9729367590212,254.34190081173222,4.556758047926507
5.2567053812904035e-08,0.0018943999999999999,219.01193884149436,254.34190081173222,4.556758047926507
5.332181725447445e-08,0.0019215999999999999,219.1587612257665,254.34190081173222,4.556758047926507
5.354380650199516e-08,0.0019295999999999998,219.20178973753337,254.34190081173222,4.556758047926507
5.3943387147532436e-08,0.001944,219.2790661426732,254.34190081173222,4.556758047926507
5.432076886831764e-08,0.0019576,219.35184468501686,254.34190081173222,4.556758047926507
5.49645376861277e-08,0.0019808,219.47554284886698,254.34190081173222,4.556758047926507
5.567490327819397e-08,0.0020063999999999998,219.6113834805036,254.34190081173222,4.556758047926507
5.585249467621054e-08,0.0020128,219.6452378133723,254.34190081173222,4.556758047926507
5.600788714947504e-08,0.0020184,219.67482593160918,254.34190081173222,4.556758047926507
5.6141080697987454e-08,0.0020231999999999997,219.70016170301565,254.34190081173222,4.556758047926507
5.651846241877267e-08,0.0020368,219.77181939782676,254.34190081173222,4.556758047926507
5.68736452148058e-08,0.0020496,219.83909166288566,254.34190081173222,4.556758047926507
5.740641940885551e-08,0.0020688,219.9396936581247,254.34190081173222,4.556758047926507
5.7495215107863795e-08,0.002072,219.956425192881,254.34190081173222,4.556758047926507
5.811678500092177e-08,0.0020943999999999997,220.0732650493013,254.34190081173222,4.556758047926507
5.918233338902118e-08,0.0021328,220.2724344008791,254.34190081173222,4.556758047926507
5.969290865831881e-08,0.0021512,220.36737367220067,254.34190081173222,4.556758047926507
5.984830113158331e-08,0.0021568,220.39620530312348,254.34190081173222,4.556758047926507
6.004809145435195e-08,0.0021639999999999997,220.43323168012483,254.34190081173222,4.556758047926507
6.058086564840165e-08,0.0021831999999999997,220.53173454899067,254.34190081173222,4.556758047926507
6.082505382067443e-08,0.002192,220.5767687314763,254.34190081173222,4.556758047926507
6.149102156323657e-08,0.002216,220.69923227561262,254.34190081173222,4.556758047926507
6.186840328402177e-08,0.0022296,220.76839865832588,254.34190081173222,4.556758047926507
6.202379575728626e-08,0.0022351999999999997,220.79683108596265,254.34190081173222,4.556758047926507
6.22235860800549e-08,0.0022424,220.83334627646607,254.34190081173222,4.556758047926507
6.291175274736911e-08,0.0022672,220.95877230656887,254.34190081173222,4.556758047926507
6.308934414538567e-08,0.0022735999999999998,220.99105331279844,254.34190081173222,4.556758047926507
6.464326887803063e-08,0.0023296,221.27201631356525,254.34190081173222,4.556758047926507
6.530923662059277e-08,0.0023536,221.3916212913448,254.34190081173222,4.556758047926507
6.555342479286554e-08,0.0023623999999999997,221.4353571508361,254.34190081173222,4.556758047926507
6.624159146017974e-08,0.0023872,221.55827222402885,254.34190081173222,4.556758047926507
6.679656457898153e-08,0.0024072,221.65703492367695,254.34190081173222,4.556758047926507
6.724054307402295e-08,0.0024232,221.73581486324534,254.34190081173222,4.556758047926507
6.803970436509749e-08,0.0024519999999999998,221.8771094241782,254.34190081173222,4.556758047926507
6.830609146212234e-08,0.0024616,221.92406358667873,254.34190081173222,4.556758047926507
6.850588178489098e-08,0.0024687999999999997,221.95923235649772,254.34190081173222,4.556758047926507
6.94160376997259e-08,0.0025016,222.11894215697336,254.34190081173222,4.556758047926507
6.992661296902352e-08,0.0025199999999999997,222.20817784206318,254.34190081173222,4.556758047926507
7.050378501257736e-08,0.0025407999999999997,222.30874754265534,254.34190081173222,4.556758047926507
7.105875813137915e-08,0.0025608,222.40514681121275,254.34190081173222,4.556758047926507
7.114755383038743e-08,0.002564,222.42054340428982,254.34190081173222,4.556758047926507
7.141394092741227e-08,0.0025735999999999997,222.46668828154534,254.34190081173222,4.556758047926507
7.190231727195784e-08,0.0025911999999999997,222.55111324718305,254.34190081173222,4.556758047926507
7.212430651947855e-08,0.0025992,222.58941427201617,254.34190081173222,4.556758047926507
7.236849469175134e-08,0.002608,222.6314923370841,254.34190081173222,4.556758047926507
7.272367748778447e-08,0.0026208,222.69259808306674,254.34190081173222,4.556758047926507
7.383362372538802e-08,0.0026608,222.88280763903464,254.34190081173222,4.556758047926507
7.436639791943772e-08,0.00268,222.97371183092758,254.34190081173222,4.556758047926507
7.461058609171049e-08,0.0026888,223.01529133422204,254.34190081173222,4.556758047926507
7.487697318873535e-08,0.0026983999999999997,223.06059031040465,254.34190081173222,4.556758047926507
7.605351620059512e-08,0.0027408,223.25991367867928,254.34190081173222,4.556758047926507
7.61423118996034e-08,0.002744,223.2749079691142,254.34190081173222,4.556758047926507
7.645309684613239e-08,0.0027551999999999997,223.32733436614424,254.34190081173222,4.556758047926507
7.780723125600873e-08,0.002804,223.5548004688566,254.34190081173222,4.556758047926507
7.802922050352942e-08,0.002812,223.5919421994416,254.34190081173222,4.556758047926507
7.876178502034777e-08,0.0028384,223.71421856891828,254.34190081173222,4.556758047926507
7.909476889162883e-08,0.0028504,223.7696520304048,254.34190081173222,4.556758047926507
8.038230652724894e-08,0.0028967999999999997,223.98314383810998,254.34190081173222,4.556758047926507
8.062649469952172e-08,0.0029056,224.02348277149812,254.34190081173222,4.556758047926507
8.075968824803417e-08,0.0029104,224.0454657424693,254.34190081173222,4.556758047926507
8.120366674307558e-08,0.0029264,224.11864040667848,254.34190081173222,4.556758047926507
8.178083878662943e-08,0.0029472,224.21353462688197,254.34190081173222,4.556758047926507
8.213602158266255e-08,0.00296,224.27180126195594,254.34190081173222,4.556758047926507
8.284638717472882e-08,0.0029855999999999997,224.38804056890788,254.34190081173222,4.556758047926507
8.302397857274539e-08,0.002992,224.4170395797841,254.34190081173222,4.556758047926507
8.349015599253888e-08,0.0030088,224.49304711638217,254.34190081173222,4.556758047926507
8.368994631530753e-08,0.003016,224.52557108717983,254.34190081173222,4.556758047926507
8.420052158460516e-08,0.0030344,224.60855062838795,254.34190081173222,4.556758047926507
8.435591405786965e-08,0.0030399999999999997,224.6337662905356,254.34190081173222,4.556758047926507
8.448910760638207e-08,0.0030448,224.65536530021677,254.34190081173222,4.556758047926507
8.506627964993592e-08,0.0030656,224.74880797619318,254.34190081173222,4.556758047926507
8.575444631725012e-08,0.0030903999999999997,224.85989785597098,254.34190081173222,4.556758047926507
8.593203771526668e-08,0.0030968,224.88850970554557,254.34190081173222,4.556758047926507
8.617622588753948e-08,0.0031056,224.9278133731202,254.34190081173222,4.556758047926507
8.675339793109331e-08,0.0031263999999999997,225.02054069271725,254.34190081173222,4.556758047926507
8.735276889939923e-08,0.0031479999999999998,225.11658014948412,254.34190081173222,4.556758047926507
8.746376352315959e-08,0.003152,225.13433699557137,254.34190081173222,4.556758047926507
8.804093556671343e-08,0.0031728,225.22653131144241,254.34190081173222,4.556758047926507
8.879569900828384e-08,0.0031999999999999997,225.34673822424412,254.34190081173222,4.556758047926507
8.895109148154834e-08,0.0032056,225.37143716716176,254.34190081173222,4.556758047926507
8.943946782609391e-08,0.0032232,225.44895309192069,254.34190081173222,4.556758047926507
9.041622051518502e-08,0.0032584,225.60349148432363,254.34190081173222,4.556758047926507
9.061601083795367e-08,0.0032656,225.63502124979024,254.34190081173222,4.556758047926507
9.086019901022644e-08,0.0032744,225.6735208357381,254.34190081173222,4.556758047926507
9.117098395675545e-08,0.0032856,225.72246199781253,254.34190081173222,4.556758047926507
9.21921344953507e-08,0.0033223999999999997,225.88281251304085,254.34190081173222,4.556758047926507
9.28803011626649e-08,0.0033472,225.99048430557662,254.34190081173222,4.556758047926507
9.292469901216904e-08,0.0033488,225.99742017005605,254.34190081173222,4.556758047926507
9.445642482006193e-08,0.003404,226.2359219481526,254.34190081173222,4.556758047926507
9.558856998241757e-08,0.0034448,226.41123754087013,254.34190081173222,4.556758047926507
9.585495707944241e-08,0.0034544,226.45237035659275,254.34190081173222,4.556758047926507
9.634333342398797e-08,0.003472,226.52766491783987,254.34190081173222,4.556758047926507
9.66985162200211e-08,0.0034847999999999997,226.5823311357124,254.34190081173222,4.556758047926507
9.732008611307909e-08,0.0035072,226.67780895801405,254.34190081173222,4.556758047926507
9.840783342593058e-08,0.0035464,226.84432485208293,254.34190081173222,4.556758047926507
9.867422052295542e-08,0.0035559999999999997,226.88499464325253,254.34190081173222,4.556758047926507
9.958437643779033e-08,0.0035887999999999996,227.02362782103785,254.34190081173222,4.556758047926507
9.996175815857554e-08,0.0036024,227.08096484571888,254.34190081173222,4.556758047926507
1.0018374740609624e-07,0.0036103999999999997,227.11465307278195,254.34190081173222,4.556758047926507
1.0025034418035246e-07,0.0036127999999999998,227.12475386236068,254.34190081173222,4.556758047926507
1.0036133880411281e-07,0.0036168,227.14158269826865,254.34190081173222,4.556758047926507
1.0107170439617907e-07,0.0036423999999999996,227.24911587444697,254.34190081173222,4.556758047926507
1.01360290417956e-07,0.0036528,227.29271698462327,254.34190081173222,4.556758047926507
1.0153788181597258e-07,0.0036592,227.3195243744782,254.34190081173222,4.556758047926507
1.0189306461200571e-07,0.003672,227.3730843599338,254.34190081173222,4.556758047926507
1.0218165063378263e-07,0.0036823999999999997,227.41654825353336,254.34190081173222,4.556758047926507
1.0224824740803884e-07,0.0036848,227.42657158111027,254.34190081173222,4.556758047926507
1.028920162258489e-07,0.003708,227.52333284121627,254.34190081173222,4.556758047926507
1.0313620439812167e-07,0.0037167999999999997,227.55997358731906,254.34190081173222,4.556758047926507
1.0380217214068382e-07,0.0037408,227.6597313366218,254.34190081173222,4.556758047926507
1.0484552160403115e-07,0.0037784,227.81551808952258,254.34190081173222,4.556758047926507
1.0553368827134534e-07,0.0038031999999999996,227.91794026585836,254.34190081173222,4.556758047926507
1.0588887106737849e-07,0.003816,227.97070139266677,254.34190081173222,4.556758047926507
1.0606646246539504e-07,0.0038223999999999997,227.9970560700386,254.34190081173222,4.556758047926507
1.0668803235845303e-07,0.0038447999999999998,228.08916222268533,254.34190081173222,4.556758047926507
1.0684342483171753e-07,0.0038504,228.1121560316932,254.34190081173222,4.556758047926507
1.070210162297341e-07,0.0038567999999999996,228.13841870632385,254.34190081173222,4.556758047926507
1.0719860762775067e-07,0.0038632,228.1646643900644,254.34190081173222,4.556758047926507
1.075537904237838e-07,0.0038759999999999997,228.21710494117366,254.34190081173222,4.556758047926507
1.0806436569308143e-07,0.0038943999999999997,228.29237006214012,254.34190081173222,4.556758047926507
1.0821975816634594e-07,0.0039,228.31524929380575,254.34190081173222,4.556758047926507
1.0830855386535422e-07,0.0039032,228.32831738794837,254.34190081173222,4.556758047926507
1.0848614526337079e-07,0.0039096,228.3544410479067,254.34190081173222,4.556758047926507
1.0881912913465186e-07,0.0039216,228.40337800175973,254.34190081173222,4.556758047926507
1.0935190332870154e-07,0.0039407999999999995,228.48155582926603,254.34190081173222,4.556758047926507
1.0977368289899089e-07,0.0039559999999999994,228.54334130950005,254.34190081173222,4.556758047926507
1.1015106461977612e-07,0.0039696,228.59854462000916,254.34190081173222,4.556758047926507
1.1023986031878438e-07,0.003972799999999999,228.6115229089118,254.34190081173222,4.556758047926507
1.1043965064155304e-07,0.00398,228.64070916188092,254.34190081173222,4.556758047926507
1.2111935839422596e-07,0.004364872974594919,230.1721347127368,254.34190081173222,4.556758047926507
1.2804680840687463e-07,0.0046145229045809165,231.13739413299888,254.34190081173222,4.556758047926507
1.3230985456850458e-07,0.004768153630726146,231.7212824847814,254.34190081173222,4.556758047926507
1.5895389307869176e-07,0.005728345669133827,235.21693887009604,254.34190081173222,4.556758047926507
1.8293352773786024e-07,0.00659251850370074,238.17149718985664,254.34190081173222,4.556758047926507
1.9039385852071265e-07,0.006861372274454891,239.05932707746706,254.34190081173222,4.556758047926507
1.9785418930356503e-07,0.007130226045209041,239.9336885267365,254.34190081173222,4.556758047926507
2.1064332778845489e-07,0.007591118223644729,241.40324722170865,254.34190081173222,4.556758047926507
2.1597213549049233e-07,0.007783156631326265,242.00524230775474,254.34190081173222,4.556758047926507
2.191694201117148e-07,0.007898379675935187,242.3636592624651,254.34190081173222,4.556758047926507
2.3675448552843835e-07,0.008532106421284257,244.29965955071592,254.34190081173222,4.556758047926507
2.602012394174031e-07,0.009377075415083017,246.79584751748635,254.34190081173222,4.556758047926507
2.655300471194405e-07,0.009569113822764553,247.35073794855975,254.34190081173222,4.556758047926507
2.724574971320892e-07,0.00981876375275055,248.0656453406592,254.34190081173222,4.556758047926507
2.825822317659603e-07,0.010183636727345468,249.09788696288786,254.34190081173222,4.556758047926507
2.93772727940239e-07,0.010586917383476696,250.2221451798103,254.34190081173222,4.556758047926507
3.007001779528876e-07,0.010836567313462692,250.90974898340127,254.34190081173222,4.556758047926507
3.044303433443138e-07,0.010970994198839769,251.27743701477863,254.34190081173222,4.556758047926507
3.1402219720798124e-07,0.011316663332666534,252.21494192738268,254.34190081173222,4.556758047926507
3.337387857055197e-07,0.012027205441088217,254.10766649155997,254.34190081173222,4.556758047926507
3.6411298960713314e-07,0.013121824364872975,256.94024981350884,254.34190081173222,4.556758047926507
3.689089165389668e-07,0.013294658931786357,257.37893166956866,254.34190081173222,4.556758047926507
3.785007704026342e-07,0.013640328065613123,258.2496790194344,254.34190081173222,4.556758047926507
3.8489533964507916e-07,0.013870774154830966,258.82540074280297,254.34190081173222,4.556758047926507
3.902241473471166e-07,0.014062812562512503,259.3023247386788,254.34190081173222,4.556758047926507
3.9608583581935776e-07,0.014274054810962193,259.82401698602337,254.34190081173222,4.556758047926507
4.0301328583200644e-07,0.01452370474094819,260.43669619299686,254.34190081173222,4.556758047926507
4.0461192814261766e-07,0.014581316263252651,260.57749878657853,254.34190081173222,4.556758047926507
4.317888474230086e-07,0.015560712142428487,262.9389070980697,254.34190081173222,4.556758047926507
4.3498613204423106e-07,0.01567593518703741,263.2128558943286,254.34190081173222,4.556758047926507
4.4351222436749096e-07,0.015983196639327867,263.93957370144085,254.34190081173222,4.556758047926507
4.664260974862519e-07,0.01680896179235847,265.86612144283913,254.34190081173222,4.556758047926507
4.861426859837905e-07,0.017519503900780158,267.4944800635584,254.34190081173222,4.556758047926507
4.978660629282728e-07,0.017941988397679534,268.45048415600644,254.34190081173222,4.556758047926507
5.021291090899028e-07,0.018095619123824763,268.7959400548682,254.34190081173222,4.556758047926507
5.175826514258114e-07,0.01865253050610122,270.03874195502055,254.34190081173222,4.556758047926507
5.223785783576451e-07,0.018825365073014605,270.4214853906618,254.34190081173222,4.556758047926507
5.26641624519275e-07,0.018978995799159834,270.7605527841187,254.34190081173222,4.556758047926507
5.388978822339611e-07,0.019420684136827366,271.7294595658943,254.34190081173222,4.556758047926507
5.447595707062022e-07,0.019631926385277054,272.1898083915964,254.34190081173222,4.556758047926507
5.506212591784435e-07,0.019843168633726746,272.64822938800296,254.34190081173222,4.556758047926507
5.74600893837612e-07,0.020707341468293658,274.50410346485137,254.34190081173222,4.556758047926507
5.783310592290382e-07,0.020841768353670735,274.79005742294993,254.34190081173222,4.556758047926507
5.847256284714831e-07,0.02107221444288858,275.27859635976796,254.34190081173222,4.556758047926507
6.017778131180029e-07,0.021686737347469495,276.5712859982829,254.34190081173222,4.556758047926507
6.124354285220778e-07,0.022070814162832568,277.3719661772694,254.34190081173222,4.556758047926507
6.166984746837078e-07,0.022224444888977797,277.6907144696824,254.34190081173222,4.556758047926507
6.236259246963563e-07,0.022474094818963793,278.20685374704055,254.34190081173222,4.556758047926507
6.401452285726725e-07,0.023069413882776557,279.4287063064843,254.34190081173222,4.556758047926507
6.529343670575623e-07,0.023530306061212244,280.36623015571905,254.34190081173222,4.556758047926507
6.59861817070211e-07,0.02377995599119824,280.87106414910477,254.34190081173222,4.556758047926507
6.710523132444895e-07,0.024183236647329465,281.68222064391523,254.34190081173222,4.556758047926507
6.822428094187682e-07,0.024586517303460693,282.48811848329626,254.34190081173222,4.556758047926507
6.865058555803982e-07,0.024740148029605922,282.79376905773626,254.34190081173222,4.556758047926507
6.99294994065288e-07,0.02520104020804161,283.7063099978775,254.34190081173222,4.556758047926507
7.243403902648639e-07,0.02610362072414483,285.4747306448725,254.34190081173222,4.556758047926507
7.376624095199576e-07,0.02658371674334867,286.4056553635367,254.34190081173222,4.556758047926507
7.600434018685149e-07,0.027390278055611124,287.95498135853035,254.34190081173222,4.556758047926507
7.701681365023859e-07,0.02775515103020604,288.6500110207333,254.34190081173222,4.556758047926507
7.754969442044234e-07,0.027947189437887578,289.01438433021093,254.34190081173222,4.556758047926507
7.797599903660533e-07,0.028100820164032807,289.30518040480473,254.34190081173222,4.556758047926507
7.93082009621147e-07,0.02858091618323665,290.209947360543,254.34190081173222,4.556758047926507
8.090684327272592e-07,0.029157031406281255,291.28788086752076,254.34190081173222,4.556758047926507
8.341138289268352e-07,0.030059611922384478,292.9600901573051,254.34190081173222,4.556758047926507
8.5329753665417e-07,0.03075095019003801,294.22772010046356,254.34190081173222,4.556758047926507
8.644880328284486e-07,0.031154230846169233,294.96203808445017,254.34190081173222,4.556758047926507
8.698168405304861e-07,0.03134626925385077,295.3104095232285,254.34190081173222,4.556758047926507
8.730141251517086e-07,0.031461492298459695,295.5190328771959,254.34190081173222,4.556758047926507
8.852703828663946e-07,0.031903180636127224,296.3160103930023,254.34190081173222,4.556758047926507
8.953951175002657e-07,0.032268053610722144,296.9711424490169,254.34190081173222,4.556758047926507
9.05519852134137e-07,0.032632926585317065,297.6233916940739,254.34190081173222,4.556758047926507
9.32163890644324e-07,0.033593118623724744,299.326388160566,254.34190081173222,4.556758047926507
9.36426936805954e-07,0.03374674934986997,299.5970959443142,254.34190081173222,4.556758047926507
9.492160752908438e-07,0.03420764152830566,300.40635011469436,254.34190081173222,4.556758047926507
9.518804791418625e-07,0.034303660732146427,300.57440825302945,254.34190081173222,4.556758047926507
9.67334021477771e-07,0.03486057211442288,301.54555188269,254.34190081173222,4.556758047926507
9.817218022732723e-07,0.03537907581516303,302.4442948996334,254.34190081173222,4.556758047926507
9.939780599879585e-07,0.03582076415283057,303.20584637356063,254.34190081173222,4.556758047926507
9.982411061495884e-07,0.0359743948789758,303.4698742527877,254.34190081173222,4.556758047926507
1.0041027946218294e-06,0.03618563712742548,303.8321956942585,254.34190081173222,4.556758047926507
1.0248851446597756e-06,0.03693458691738348,305.1101956163358,254.34190081173222,4.556758047926507
1.030213952361813e-06,0.03712662532506501,305.43625490684025,254.34190081173222,4.556758047926507
1.0344769985234429e-06,0.03728025605121024,305.6966290046507,254.34190081173222,4.556758047926507
1.0579237524124079e-06,0.03812522504500901,307.12127578398974,254.34190081173222,4.556758047926507
1.0696471293568898e-06,0.03854770954190838,307.82897740848887,254.34190081173222,4.556758047926507
1.0728444139781123e-06,0.038662932586517304,308.02146111699165,254.34190081173222,4.556758047926507
1.0941596447862621e-06,0.03943108621724345,309.2990160707272,254.34190081173222,4.556758047926507
1.0978898101776882e-06,0.03956551310262052,309.5215865766333,254.34190081173222,4.556758047926507
1.1170735179050232e-06,0.04025685137027406,310.66160951168206,254.34190081173222,4.556758047926507
1.1394545102535805e-06,0.04106341268253651,311.98203032109404,254.34190081173222,4.556758047926507
1.1538422910490816e-06,0.04158191638327666,312.8255338430044,254.34190081173222,4.556758047926507
1.1591710987511188e-06,0.04177395479095819,313.1369003008216,254.34190081173222,4.556758047926507
1.1756904026274351e-06,0.04236927385477096,314.0986076051557,254.34190081173222,4.556758047926507
1.1890124218825285e-06,0.042849369873974794,314.87034489713176,254.34190081173222,4.556758047926507
1.2135249373119009e-06,0.043732746549309864,316.28158741740214,254.34190081173222,4.556758047926507
1.2204523873245495e-06,0.04398239647929586,316.6783962397168,254.34190081173222,4.556758047926507
1.227912718107402e-06,0.044251250250050014,317.10474772903353,254.34190081173222,4.556758047926507
1.2332415258094394e-06,0.04444328865773155,317.40866622715004,254.34190081173222,4.556758047926507
1.243899141213514e-06,0.04482736547309461,318.0149710964193,254.34190081173222,4.556758047926507
1.2497608296857553e-06,0.045038607721544305,318.34757510250296,254.34190081173222,4.556758047926507
1.2540238758473852e-06,0.045192238447689534,318.5890869125127,254.34190081173222,4.556758047926507
1.2614842066302378e-06,0.04546109221844369,319.01096352119566,254.34190081173222,4.556758047926507
1.2689445374130903e-06,0.04572994598919784,319.43186821416896,254.34190081173222,4.556758047926507
1.2827994374383874e-06,0.046229245849169834,320.2109967872878,254.34190081173222,4.556758047926507
1.2891940066808325e-06,0.046459691938387684,320.5694870297308,254.34190081173222,4.556758047926507
1.3062461913273524e-06,0.0470742148429686,321.522086787553,254.34190081173222,4.556758047926507
1.308910595178371e-06,0.04717023404680937,321.6704912721416,254.34190081173222,4.556758047926507
1.3243641375142797e-06,0.04772714542908582,322.5289253253213,254.34190081173222,4.556758047926507
1.329692945216317e-06,0.047919183836767354,322.82403011076724,254.34190081173222,4.556758047926507
1.3387519183097808e-06,0.04824564912982597,323.3246519109264,254.34190081173222,4.556758047926507
1.341949202931003e-06,0.04836087217443488,323.5010263017785,254.34190081173222,4.556758047926507
1.3440807260118182e-06,0.048437687537507504,323.6185181892306,254.34190081173222,4.556758047926507
1.3584685068073193e-06,0.048956191238247654,324.40969629724293,254.34190081173222,4.556758047926507
1.3664617183603753e-06,0.04924424884976995,324.8478274065399,254.34190081173222,4.556758047926507
1.3696590029815978e-06,0.04935947189437888,325.02279984710714,254.34190081173222,4.556758047926507
1.3781850953048578e-06,0.04966673334666934,325.48861599626275,254.34190081173222,4.556758047926507
1.379783737615469e-06,0.0497243448689738,325.57583126330877,254.34190081173222,4.556758047926507
1.3893755914791363e-06,0.05007001400280056,326.0982976712111,254.34190081173222,4.556758047926507
1.3941715184109702e-06,0.05024284856971395,326.35900322103174,254.34190081173222,4.556758047926507
1.4053620145852487e-06,0.050646129225845174,326.96595977307965,254.34190081173222,4.556758047926507
1.4080264184362673e-06,0.05074214842968594,327.1101950698802,254.34190081173222,4.556758047926507
1.4112237030574899e-06,0.050857371474294866,327.28313699492475,254.34190081173222,4.556758047926507
1.4144209876787122e-06,0.05097259451890378,327.45592617781153,254.34190081173222,4.556758047926507
1.4250786030827872e-06,0.05135667133426686,328.0307931229791,254.34190081173222,4.556758047926507
1.431473172325232e-06,0.051587117423484694,328.37490853083295,254.34190081173222,4.556758047926507
1.4394663838782883e-06,0.05187517503500701,328.804210894005,254.34190081173222,4.556758047926507
1.4437294300399182e-06,0.052028805761152236,329.0327919600002,254.34190081173222,4.556758047926507
1.4474595954313443e-06,0.052163232646529306,329.2325845471067,254.34190081173222,4.556758047926507
1.4847612493456065e-06,0.053507501500300064,331.21958873082974,254.34190081173222,4.556758047926507
1.4996819109113111e-06,0.05404520904180836,332.0089274661016,254.34190081173222,4.556758047926507
1.5034120763027377e-06,0.05417963592718544,332.20578285818635,254.34190081173222,4.556758047926507
1.5066093609239598e-06,0.054294858971794355,332.3743644887629,254.34190081173222,4.556758047926507
1.5193984994088496e-06,0.05475575115023004,333.0473004192498,254.34190081173222,4.556758047926507
1.5257930686512948e-06,0.05498619723944789,333.38293972405876,254.34190081173222,4.556758047926507
1.531654757123536e-06,0.055197439487897584,333.69012747417463,254.34190081173222,4.556758047926507
1.5449767763786293e-06,0.05567753550710142,334.38658141400794,254.34190081173222,4.556758047926507
1.5487069417700558e-06,0.0558119623924785,334.58116830830943,254.34190081173222,4.556758047926507
1.5508384648508707e-06,0.05588877775555111,334.69227875250647,254.34190081173222,4.556758047926507
1.5609631994847417e-06,0.05625365073014603,335.21924217005784,254.34190081173222,4.556758047926507
1.575350980280243e-06,0.05677215443088618,335.9657975955599,254.34190081173222,4.556758047926507
1.5971990918585966e-06,0.057559511902380484,337.09439098848213,254.34190081173222,4.556758047926507
1.6126526341945052e-06,0.05811642328465694,337.88903179572674,254.34190081173222,4.556758047926507
1.6286390573006172e-06,0.058692538507701536,338.7079551169187,254.34190081173222,4.556758047926507
1.6403624342450997e-06,0.05911502300460092,339.3065078031903,254.34190081173222,4.556758047926507
1.6467570034875448e-06,0.05934546909381877,339.6322878269635,254.34190081173222,4.556758047926507
1.6584803804320269e-06,0.05976795359071814,340.2282726955558,254.34190081173222,4.556758047926507
1.6691379958361019e-06,0.06015203040608122,340.7686528894284,254.34190081173222,4.556758047926507
1.6851244189422143e-06,0.06072814562912583,341.57670691299916,254.34190081173222,4.556758047926507
1.692051868954863e-06,0.06097779555911183,341.9259345917304,254.34190081173222,4.556758047926507
1.695249153576085e-06,0.06109301860372074,342.086928484305,254.34190081173222,4.556758047926507
1.70590676898016e-06,0.06147709541908382,342.6227215943568,254.34190081173222,4.556758047926507
1.7133670997630127e-06,0.06174594918983797,342.9970002850118,254.34190081173222,4.556758047926507
1.714965742073624e-06,0.061803560712142436,343.0771201108357,254.34190081173222,4.556758047926507
1.7240247151670873e-06,0.06213002600520104,343.53058347968897,254.34190081173222,4.556758047926507
1.7325508074903473e-06,0.0624372874574915,343.95652439211403,254.34190081173222,4.556758047926507
1.7352152113413659e-06,0.06253330666133226,344.0894631772992,254.34190081173222,4.556758047926507
1.745339945975237e-06,0.06289817963592718,344.5939061833457,254.34190081173222,4.556758047926507
1.766122296013183e-06,0.06364712942588517,345.62578038695045,254.34190081173222,4.556758047926507
1.7783785537278694e-06,0.06408881776355271,346.23210181532426,254.34190081173222,4.556758047926507
1.789036169131944e-06,0.06447289457891578,346.7580143679658,254.34190081173222,4.556758047926507
1.7996937845360192e-06,0.06485697139427886,347.2827064769567,254.34190081173222,4.556758047926507
1.8247391807355949e-06,0.06575955191038207,348.510985963269,254.34190081173222,4.556758047926507
1.83113374997804e-06,0.06598999799959993,348.8235333954342,254.34190081173222,4.556758047926507
1.8561791461776159e-06,0.06689257851570314,350.043600917133,254.34190081173222,4.556758047926507
1.862573715420061e-06,0.06712302460492099,350.3540765374121,254.34190081173222,4.556758047926507
1.8673696423518944e-06,0.06729585917183437,350.58666051693666,254.34190081173222,4.556758047926507
1.8726984500539323e-06,0.06748789757951591,350.84481410529963,254.34190081173222,4.556758047926507
1.898276727023712e-06,0.06840968193638729,352.07998544244066,254.34190081173222,4.556758047926507
1.9073357001171752e-06,0.06873614722944589,352.51588322698615,254.34190081173222,4.556758047926507
1.9094672231979905e-06,0.06881296259251851,352.61832998076943,254.34190081173222,4.556758047926507
1.9254536463041024e-06,0.06938907781556311,353.38526405389706,254.34190081173222,4.556758047926507
1.9446373540314374e-06,0.07008041608321665,354.3023146572373,254.34190081173222,4.556758047926507
1.95636073097592e-06,0.07050290058011603,354.86099783251234,254.34190081173222,4.556758047926507
1.962755300218365e-06,0.07073334666933387,355.16518373175995,254.34190081173222,4.556758047926507
1.977143081013866e-06,0.07125185037007402,355.8481924142033,254.34190081173222,4.556758047926507
1.9819390079456998e-06,0.0714246849369874,356.07543085698853,254.34190081173222,4.556758047926507
1.987267815647737e-06,0.07161672334466894,356.327666648301,254.34190081173222,4.556758047926507
1.995261027200793e-06,0.07190478095619124,356.70552630840103,254.34190081173222,4.556758047926507
1.9989911925922192e-06,0.07203920784156832,356.88165873970354,254.34190081173222,4.556758047926507
2.003787119524053e-06,0.0722120424084817,357.10792649113415,254.34190081173222,4.556758047926507
2.02190506571098e-06,0.07286497299459892,357.9608164210635,254.34190081173222,4.556758047926507
2.033095561885259e-06,0.07326825365073016,358.48611258292254,254.34190081173222,4.556758047926507
2.044818938829741e-06,0.07369073814762953,359.03521484771005,254.34190081173222,4.556758047926507
2.053345031153001e-06,0.07399799959991998,359.43379109015007,254.34190081173222,4.556758047926507
2.058140958084835e-06,0.07417083416683337,359.6577065708661,254.34190081173222,4.556758047926507
2.070930096569725e-06,0.07463172634526906,360.2538219059377,254.34190081173222,4.556758047926507
2.084784996595022e-06,0.07513102620524105,360.8979956666086,254.34190081173222,4.556758047926507
2.0943768504586894e-06,0.07547669533906781,361.3429844074942,254.34190081173222,4.556758047926507
2.098639896620319e-06,0.07563032606521304,361.5405019846942,254.34190081173222,4.556758047926507
2.116757842807247e-06,0.07628325665133028,362.3782119836527,254.34190081173222,4.556758047926507
2.1386059543856003e-06,0.07707061412282457,363.3846816150923,254.34190081173222,4.556758047926507
2.1455334043982487e-06,0.07732026405281056,363.7029677717132,254.34190081173222,4.556758047926507
2.149796450559879e-06,0.07747389477895579,363.8986369754499,254.34190081173222,4.556758047926507
2.157256781342731e-06,0.07774274854970994,364.2406943477465,254.34190081173222,4.556758047926507
2.169513039057417e-06,0.07818443688737747,364.8016459167919,254.34190081173222,4.556758047926507
2.1753747275296585e-06,0.07839567913582716,365.06949009569564,254.34190081173222,4.556758047926507
2.201485885269642e-06,0.0793366673334667,366.25921105419474,254.34190081173222,4.556758047926507
2.210011977592902e-06,0.07964392878575716,366.64649781914267,254.34190081173222,4.556758047926507
2.222801116077792e-06,0.08010482096419284,367.22633717553606,254.34190081173222,4.556758047926507
2.230261446860644e-06,0.080373674734947,367.56397594604374,254.34190081173222,4.556758047926507
2.244649227656145e-06,0.08089217843568715,368.2138951358358,254.34190081173222,4.556758047926507
2.2483793930475715e-06,0.08102660532106422,368.3821272411812,254.34190081173222,4.556758047926507
2.2521095584389974e-06,0.08116103220644129,368.5502505307856,254.34190081173222,4.556758047926507
2.267563100774906e-06,0.08171794358871774,369.24560752730395,254.34190081173222,4.556758047926507
2.299535946987131e-06,0.08287017403480697,370.67843698194054,254.34190081173222,4.556758047926507
2.311792204701817e-06,0.0833118623724745,371.2256256024764,254.34190081173222,4.556758047926507
2.3203182970250767e-06,0.08361912382476495,371.6056114618713,254.34190081173222,4.556758047926507
2.3368376009013932e-06,0.08421444288857773,372.34028801524306,254.34190081173222,4.556758047926507
2.344297931684245e-06,0.08448329665933187,372.6714132326111,254.34190081173222,4.556758047926507
2.3501596201564864e-06,0.08469453890778156,372.93129483086994,254.34190081173222,4.556758047926507
2.3650802817221913e-06,0.08523224644928987,373.59167350471023,254.34190081173222,4.556758047926507
2.370409089424229e-06,0.0854242848569714,373.8271290087091,254.34190081173222,4.556758047926507
2.382132466368711e-06,0.08584676935387078,374.34440569444274,254.34190081173222,4.556758047926507
2.403447697176861e-06,0.08661492298459693,375.2823722916333,254.34190081173222,4.556758047926507
2.4226314049041957e-06,0.08730626125225045,376.12377205552497,254.34190081173222,4.556758047926507
2.4311574972274554e-06,0.08761352270454091,376.49689302219565,254.34190081173222,4.556758047926507
2.4418151126315307e-06,0.08799759951990399,376.96257735818034,254.34190081173222,4.556758047926507
2.4455452780229566e-06,0.08813202640528106,377.125379515563,254.34190081173222,4.556758047926507
2.4583344165078464e-06,0.08859291858371675,377.6828245854317,254.34190081173222,4.556758047926507
2.4721893165331437e-06,0.08909221844368874,378.2854486383648,254.34190081173222,4.556758047926507
2.47591948192457e-06,0.08922664532906582,378.44746834955185,254.34190081173222,4.556758047926507
2.482846931937219e-06,0.08947629525905182,378.7481097598719,254.34190081173222,4.556758047926507
2.490840143490275e-06,0.08976435287057412,379.0945974876351,254.34190081173222,4.556758047926507
2.5105567319878132e-06,0.0904748949789958,379.9474183478195,254.34190081173222,4.556758047926507
2.5137540166090358e-06,0.09059011802360473,380.08546711397145,254.34190081173222,4.556758047926507
2.5254773935535185e-06,0.09101260252050411,380.59106111269654,254.34190081173222,4.556758047926507
2.5313390820257594e-06,0.0912238447689538,380.84351480559945,254.34190081173222,4.556758047926507
2.5483912666722794e-06,0.09183836767353472,381.5766324272474,254.34190081173222,4.556758047926507
2.5585160013061504e-06,0.09220324064812963,382.01101584814853,254.34190081173222,4.556758047926507
2.561713285927373e-06,0.09231846369273855,382.1480502129639,254.34190081173222,4.556758047926507
2.5654434513187993e-06,0.09245289057811563,382.3078393621016,254.34190081173222,4.556758047926507
2.569706497480429e-06,0.09260652130426085,382.4903446232357,254.34190081173222,4.556758047926507
2.577166828263281e-06,0.092875375075015,382.80944495531514,254.34190081173222,4.556758047926507
2.580896993654708e-06,0.09300980196039209,382.96886001207537,254.34190081173222,4.556758047926507
2.5915546090587823e-06,0.09339387877575515,383.4238372264311,254.34190081173222,4.556758047926507
2.6102054360159135e-06,0.09406601320264053,384.218295370148,254.34190081173222,4.556758047926507
2.621928812960396e-06,0.09448849769953992,384.7165360805859,254.34190081173222,4.556758047926507
2.6272576206624334e-06,0.09468053610722145,384.94272183895106,254.34190081173222,4.556758047926507
2.629922024513452e-06,0.09477655531106222,385.05574761836647,254.34190081173222,4.556758047926507
2.6352508322154894e-06,0.09496859371874375,385.28166529242515,254.34190081173222,4.556758047926507
2.6523030168620093e-06,0.09558311662332467,386.003407507575,254.34190081173222,4.556758047926507
2.6602962284150657e-06,0.09587117423484698,386.3411009995647,254.34190081173222,4.556758047926507
2.6677565591979175e-06,0.09614002800560112,386.6559247478288,254.34190081173222,4.556758047926507
2.688538909235864e-06,0.09688897779555912,387.5311284129409,254.34190081173222,4.556758047926507
2.6954663592485126e-06,0.09713862772554512,387.82227612164894,254.34190081173222,4.556758047926507
2.706656855422791e-06,0.09754190838167634,388.29197595792,254.34190081173222,4.556758047926507
2.714650066975847e-06,0.09782996599319864,388.62701227138103,254.34190081173222,4.556758047926507
2.719445993907681e-06,0.09800280056011203,388.8278493907642,254.34190081173222,4.556758047926507
2.7375639400946084e-06,0.09865573114622925,389.5853240254565,254.34190081173222,4.556758047926507
2.740761224715831e-06,0.09877095419083817,389.71879281273976,254.34190081173222,4.556758047926507
2.7503530785794982e-06,0.09911662332466493,390.1188353112993,254.34190081173222,4.556758047926507
2.7658066209154064e-06,0.09967353470694139,390.7622056530709,254.34190081173222,4.556758047926507
2.7748655940088704e-06,0.1,391.13870199651586,254.34190081173222,4.556758047926507