File: datasets/aisi_316_L/data/M1/train_46.csv
Time(s),Strain(%),Stress(MPa),Temp(C),Log_SR(s-1)
0.0,0.0,0.0,113.51245528490624,4.2687640247447645
2.1542493301829733e-10,4e-06,0.7689428749999999,113.51245528490624,4.2687640247447645
5.170198392439136e-10,9.6e-06,1.8454629,113.51245528490624,4.2687640247447645
1.3356345847134435e-09,2.48e-05,4.767445825,113.51245528490624,4.2687640247447645
1.6372294909390598e-09,3.04e-05,5.84396585,113.51245528490624,4.2687640247447645
2.1111643435793138e-09,3.92e-05,7.535640174999999,113.51245528490624,4.2687640247447645
3.23137399527446e-09,5.9999999999999995e-05,11.534143124999998,113.51245528490624,4.2687640247447645
4.2223286871586276e-09,7.84e-05,15.071280349999999,113.51245528490624,4.2687640247447645
5.342538338853774e-09,9.92e-05,19.0697833,113.51245528490624,4.2687640247447645
6.333493030737942e-09,0.0001176,22.606920525,113.51245528490624,4.2687640247447645
7.669127615451385e-09,0.0001424,27.37436635,113.51245528490624,4.2687640247447645
8.703167293939212e-09,0.0001616,31.06529215,113.51245528490624,4.2687640247447645
1.0297311798274612e-08,0.00019119999999999999,36.755469424999994,113.51245528490624,4.2687640247447645
1.0986671583933164e-08,0.000204,39.216086625,113.51245528490624,4.2687640247447645
1.1848371316006352e-08,0.00021999999999999998,42.291858125,113.51245528490624,4.2687640247447645
1.2796241021286863e-08,0.0002376,45.675206775,113.51245528490624,4.2687640247447645
1.3959535659585669e-08,0.0002592,49.8274983,113.51245528490624,4.2687640247447645
1.697548472184183e-08,0.00031519999999999996,60.592698549999994,113.51245528490624,4.2687640247447645
1.8181864346744292e-08,0.00033759999999999997,64.89877865,113.51245528490624,4.2687640247447645
1.844037426636625e-08,0.0003424,65.8215101,113.51245528490624,4.2687640247447645
1.930207399843944e-08,0.0003584,68.8972816,113.51245528490624,4.2687640247447645
1.9905263810890673e-08,0.0003696,71.05032165,113.51245528490624,4.2687640247447645
2.098238847598216e-08,0.0003896,74.895036025,113.51245528490624,4.2687640247447645
2.1542493301829732e-08,0.00039999999999999996,76.89428749999999,113.51245528490624,4.2687640247447645
2.249036300711024e-08,0.00041759999999999996,80.27763614999999,113.51245528490624,4.2687640247447645
2.2791957913335857e-08,0.0004232,81.354156175,113.51245528490624,4.2687640247447645
2.348131769899441e-08,0.00043599999999999997,83.814773375,113.51245528490624,4.2687640247447645
2.4989292230122494e-08,0.000464,89.1973735,113.51245528490624,4.2687640247447645
2.5333972122951767e-08,0.0004704,90.4276821,113.51245528490624,4.2687640247447645
2.654035174785423e-08,0.0004927999999999999,94.73376219999999,113.51245528490624,4.2687640247447645
2.6885031640683508e-08,0.0004992,95.9640708,113.51245528490624,4.2687640247447645
2.8048326278982314e-08,0.0005208,100.116362325,113.51245528490624,4.2687640247447645
2.93408758770921e-08,0.0005448,104.730019575,113.51245528490624,4.2687640247447645
2.972864075652503e-08,0.000552,106.11411675,113.51245528490624,4.2687640247447645
2.994406568954333e-08,0.000556,106.88305962499999,113.51245528490624,4.2687640247447645
3.158129518048239e-08,0.0005863999999999999,112.72702547499999,113.51245528490624,4.2687640247447645
3.1969060059915325e-08,0.0005936,114.11112265,113.51245528490624,4.2687640247447645
3.3218524671421446e-08,0.0006167999999999999,118.57099132499998,113.51245528490624,4.2687640247447645
3.36924595240617e-08,0.0006255999999999999,120.26266564999999,113.51245528490624,4.2687640247447645
3.451107426953123e-08,0.0006408,123.184648575,113.51245528490624,4.2687640247447645
3.481266917575685e-08,0.0006464,124.2611686,113.51245528490624,4.2687640247447645
3.558819893462272e-08,0.0006608,127.02936295,113.51245528490624,4.2687640247447645
3.640681368009225e-08,0.000676,129.951345875,113.51245528490624,4.2687640247447645
3.7096173465750796e-08,0.0006887999999999999,132.411963075,113.51245528490624,4.2687640247447645
3.7570108318391055e-08,0.0006975999999999999,134.1036374,113.51245528490624,4.2687640247447645
3.903499786291548e-08,0.0007247999999999999,139.33244894999999,113.51245528490624,4.2687640247447645
3.985361260838501e-08,0.00074,142.254431875,113.51245528490624,4.2687640247447645
4.110307721989113e-08,0.0007632,146.71430055,113.51245528490624,4.2687640247447645
4.196477695196432e-08,0.0007792,149.79007205,113.51245528490624,4.2687640247447645
4.2180201884982616e-08,0.0007832,150.55901492499999,113.51245528490624,4.2687640247447645
4.2783391697433855e-08,0.0007944,152.712054975,113.51245528490624,4.2687640247447645
4.4420621188372914e-08,0.0008248,158.556020825,113.51245528490624,4.2687640247447645
4.523923593384244e-08,0.0008399999999999999,161.47800375,113.51245528490624,4.2687640247447645
4.648870054534856e-08,0.0008632,165.937872425,113.51245528490624,4.2687640247447645
4.713497534440345e-08,0.0008751999999999999,168.24470104999997,113.51245528490624,4.2687640247447645
4.7953590089872984e-08,0.0008904,171.16668397499998,113.51245528490624,4.2687640247447645
4.9030714754964475e-08,0.0009104,175.01139835,113.51245528490624,4.2687640247447645
4.928922467458643e-08,0.0009151999999999999,175.9341298,113.51245528490624,4.2687640247447645
5.0280179366470596e-08,0.0009335999999999999,179.47126702499997,113.51245528490624,4.2687640247447645
5.092645416552549e-08,0.0009456,181.77809565,113.51245528490624,4.2687640247447645
5.135730403156209e-08,0.0009536,183.3159814,113.51245528490624,4.2687640247447645
5.290836354929383e-08,0.0009824,188.8523701,113.51245528490624,4.2687640247447645
5.342538338853774e-08,0.000992,190.697833,113.51245528490624,4.2687640247447645
5.3770063281367015e-08,0.0009984,191.9281416,113.51245528490624,4.2687640247447645
5.4545593040232884e-08,0.0010128,194.69633595,113.51245528490624,4.2687640247447645
5.5148782852684116e-08,0.001024,196.84937599999998,113.51245528490624,4.2687640247447645
5.540729277230607e-08,0.0010287999999999999,197.77210744999996,113.51245528490624,4.2687640247447645
5.631207749098293e-08,0.0010456,201.00166752500002,113.51245528490624,4.2687640247447645
5.648441743739756e-08,0.0010488,201.616821825,113.51245528490624,4.2687640247447645
5.717377722305611e-08,0.0010616,204.077439025,113.51245528490624,4.2687640247447645
5.84663268211659e-08,0.0010856,208.69109627499998,113.51245528490624,4.2687640247447645
6.057749116474522e-08,0.0011248,216.22673645,113.51245528490624,4.2687640247447645
6.16546158298367e-08,0.0011447999999999999,220.07145082499997,113.51245528490624,4.2687640247447645
6.195621073606231e-08,0.0011504,221.14797085,113.51245528490624,4.2687640247447645
6.299025041455014e-08,0.0011696,224.83889665,113.51245528490624,4.2687640247447645
6.510141475812946e-08,0.0012088,232.37453682499998,113.51245528490624,4.2687640247447645
6.626470939642826e-08,0.0012304,236.52682835,113.51245528490624,4.2687640247447645
6.635087936963558e-08,0.001232,236.8344055,113.51245528490624,4.2687640247447645
6.936682843189174e-08,0.0012879999999999999,247.59960574999997,113.51245528490624,4.2687640247447645
6.988384827113565e-08,0.0012975999999999999,249.44506864999997,113.51245528490624,4.2687640247447645
7.134873781566008e-08,0.0013248,254.67388019999999,113.51245528490624,4.2687640247447645
7.147799277547106e-08,0.0013272,255.135245925,113.51245528490624,4.2687640247447645
7.221043754773327e-08,0.0013407999999999998,257.74965169999996,113.51245528490624,4.2687640247447645
7.242586248075157e-08,0.0013448,258.518594575,113.51245528490624,4.2687640247447645
7.333064719942841e-08,0.0013616,261.74815465,113.51245528490624,4.2687640247447645
7.46231967975382e-08,0.0013855999999999999,266.36181189999996,113.51245528490624,4.2687640247447645
7.587266140904433e-08,0.0014088,269.11210227241907,113.51245528490624,4.2687640247447645
7.725138098036142e-08,0.0014344,269.30499555358773,113.51245528490624,4.2687640247447645
7.763914585979435e-08,0.0014416,269.3590042783143,113.51245528490624,4.2687640247447645
7.785457079281265e-08,0.0014456,269.38896366592854,113.51245528490624,4.2687640247447645
7.931946033733708e-08,0.0014728,269.5918368653523,113.51245528490624,4.2687640247447645
8.018116006941027e-08,0.0014888,269.71049149157005,113.51245528490624,4.2687640247447645
8.160296462733103e-08,0.0015152,269.90519009199676,113.51245528490624,4.2687640247447645
8.311093915845911e-08,0.0015432,270.1102484112104,113.51245528490624,4.2687640247447645
8.349870403789204e-08,0.0015504,270.1627425156708,113.51245528490624,4.2687640247447645
8.414497883694695e-08,0.0015624,270.2500219048994,113.51245528490624,4.2687640247447645
8.509284854222745e-08,0.00158,270.37756024815235,113.51245528490624,4.2687640247447645
8.539444344845307e-08,0.0015856,270.418024278663,113.51245528490624,4.2687640247447645
8.789337267146531e-08,0.001632,270.7511801600265,113.51245528490624,4.2687640247447645
8.931517722938607e-08,0.0016584,270.9390851465922,113.51245528490624,4.2687640247447645
8.961677213561169e-08,0.001664,270.97879339541464,113.51245528490624,4.2687640247447645
9.1727936479191e-08,0.0017032,271.2553062677063,113.51245528490624,4.2687640247447645
9.21587863452276e-08,0.0017112,271.3114312777175,113.51245528490624,4.2687640247447645
9.41837807155996e-08,0.0017488,271.5738601683709,113.51245528490624,4.2687640247447645
9.543324532710572e-08,0.001772,271.7346869622246,113.51245528490624,4.2687640247447645
9.702738983144112e-08,0.0018016,271.9386924879659,113.51245528490624,4.2687640247447645
9.965557401426434e-08,0.0018503999999999999,272.2721946649047,113.51245528490624,4.2687640247447645
1.023699281702949e-07,0.0019008,272.6130499863957,113.51245528490624,4.2687640247447645
1.0280077803633149e-07,0.0019088,272.66682815975247,113.51245528490624,4.2687640247447645
1.0340396784878272e-07,0.0019199999999999998,272.74197016091983,113.51245528490624,4.2687640247447645
1.0478268742009983e-07,0.0019456,272.9130843149567,113.51245528490624,4.2687640247447645
1.0603215203160594e-07,0.0019687999999999997,273.0673995406586,113.51245528490624,4.2687640247447645
1.0633374693783157e-07,0.0019744,273.1045415945955,113.51245528490624,4.2687640247447645
1.0689385176367914e-07,0.0019848,273.17341087613244,113.51245528490624,4.2687640247447645
1.0762629653594136e-07,0.0019984,273.26325872543697,113.51245528490624,4.2687640247447645
1.0913427106706943e-07,0.0020264,273.44749218013413,113.51245528490624,4.2687640247447645
1.1021139573216092e-07,0.0020464,273.57848017174086,113.51245528490624,4.2687640247447645
1.1111618045083776e-07,0.0020632,273.6881246981684,113.51245528490624,4.2687640247447645
1.1176245524989264e-07,0.0020751999999999997,273.7662291445995,113.51245528490624,4.2687640247447645
1.1206405015611827e-07,0.0020808,273.8026175883556,113.51245528490624,4.2687640247447645
1.1318425980781342e-07,0.0021016,273.9374415794067,113.51245528490624,4.2687640247447645
1.1413212951309392e-07,0.0021192,274.0511174352126,113.51245528490624,4.2687640247447645
1.146060643657342e-07,0.002128,274.1078172482683,113.51245528490624,4.2687640247447645
1.149076592719598e-07,0.0021336,274.1438513410366,113.51245528490624,4.2687640247447645
1.153385091379964e-07,0.0021416,274.1952646976357,113.51245528490624,4.2687640247447645
1.1581244399063665e-07,0.0021504,274.25173295600035,113.51245528490624,4.2687640247447645
1.169326536423318e-07,0.0021712,274.3848463347548,113.51245528490624,4.2687640247447645
1.1818211825383792e-07,0.0021944,274.53273360762034,113.51245528490624,4.2687640247447645
1.1895764801270379e-07,0.0022088,274.624219067428,113.51245528490624,4.2687640247447645
1.2007785766439894e-07,0.0022296,274.7559551454059,113.51245528490624,4.2687640247447645
1.2098264238307578e-07,0.0022464,274.86200780111506,113.51245528490624,4.2687640247447645
1.212842372893014e-07,0.002252,274.8972898895762,113.51245528490624,4.2687640247447645
1.2145657723571604e-07,0.0022551999999999997,274.9174357202203,113.51245528490624,4.2687640247447645
1.21585832195527e-07,0.0022576,274.9325377778492,113.51245528490624,4.2687640247447645
1.2236136195439287e-07,0.0022719999999999997,275.0230189859371,113.51245528490624,4.2687640247447645
1.2279221182042947e-07,0.00228,275.0731896758934,113.51245528490624,4.2687640247447645
1.2442944131136854e-07,0.0023103999999999998,275.2632154199413,113.51245528490624,4.2687640247447645
1.2615284077551492e-07,0.0023423999999999997,275.462192048746,113.51245528490624,4.2687640247447645
1.2658369064155152e-07,0.0023504,275.51177021362207,113.51245528490624,4.2687640247447645
1.2783315525305764e-07,0.0023736,275.65517608039346,113.51245528490624,4.2687640247447645
1.292549598109784e-07,0.0024,275.8176987777168,113.51245528490624,4.2687640247447645
1.3033208447606988e-07,0.00242,275.9403582722108,113.51245528490624,4.2687640247447645
1.3089218930191746e-07,0.0024304,276.0039849309289,113.51245528490624,4.2687640247447645
1.3102144426172843e-07,0.0024327999999999997,276.01865291618066,113.51245528490624,4.2687640247447645
1.316246340741797e-07,0.002444,276.08702903492264,113.51245528490624,4.2687640247447645
1.324432488196492e-07,0.0024592,276.1796300531132,113.51245528490624,4.2687640247447645
1.3326186356511873e-07,0.0024744,276.27200811997227,113.51245528490624,4.2687640247447645
1.3464058313643585e-07,0.0025,276.42709354117966,113.51245528490624,4.2687640247447645
1.352006879622834e-07,0.0025104,276.48991993279424,113.51245528490624,4.2687640247447645
1.354161128953017e-07,0.0025144,276.51405689086675,113.51245528490624,4.2687640247447645
1.3623472764077123e-07,0.0025296,276.60564108073174,113.51245528490624,4.2687640247447645
1.363639826005822e-07,0.002532,276.6200820998972,113.51245528490624,4.2687640247447645
1.370102573996371e-07,0.002544,276.6922072749631,113.51245528490624,4.2687640247447645
1.3739802227907004e-07,0.0025512,276.7354186948432,113.51245528490624,4.2687640247447645
1.3769961718529564e-07,0.0025567999999999997,276.76899470378123,113.51245528490624,4.2687640247447645
1.3825972201114324e-07,0.0025672,276.83127415655395,113.51245528490624,4.2687640247447645
1.3907833675661276e-07,0.0025824,276.9221212653608,113.51245528490624,4.2687640247447645
1.4006929144849694e-07,0.0026008,277.031815538459,113.51245528490624,4.2687640247447645
1.4123258608679574e-07,0.0026224,277.1602016278948,113.51245528490624,4.2687640247447645
1.425251356849055e-07,0.0026463999999999997,277.30237011172403,113.51245528490624,4.2687640247447645
1.4304215552414944e-07,0.002656,277.35909660485555,113.51245528490624,4.2687640247447645
1.4437779010886287e-07,0.0026807999999999997,277.5052711700185,113.51245528490624,4.2687640247447645
1.4567033970697265e-07,0.0027048,277.6462291178604,113.51245528490624,4.2687640247447645
1.467043793854605e-07,0.002724,277.7586445838844,113.51245528490624,4.2687640247447645
1.472213992247044e-07,0.0027336,277.81473640428965,113.51245528490624,4.2687640247447645
1.4847086383621053e-07,0.0027568,277.94997541189406,113.51245528490624,4.2687640247447645
1.5032351826016788e-07,0.0027911999999999998,278.1496880639636,113.51245528490624,4.2687640247447645
1.5122830297884471e-07,0.0028079999999999997,278.24687308808075,113.51245528490624,4.2687640247447645
1.519176627645033e-07,0.0028208,278.3207666919065,113.51245528490624,4.2687640247447645
1.5204691772431426e-07,0.0028231999999999997,278.33460717219094,113.51245528490624,4.2687640247447645
1.5226234265733255e-07,0.0028271999999999998,278.35766444668513,113.51245528490624,4.2687640247447645
1.5269319252336915e-07,0.0028352,278.40374086334356,113.51245528490624,4.2687640247447645
1.5407191209468624e-07,0.0028607999999999997,278.55084582110857,113.51245528490624,4.2687640247447645
1.5433042201430821e-07,0.0028656,278.578370753033,113.51245528490624,4.2687640247447645
1.549766968133631e-07,0.0028775999999999997,278.6471045324508,113.51245528490624,4.2687640247447645
1.560107364918509e-07,0.0028967999999999997,278.7568465220185,113.51245528490624,4.2687640247447645
1.5704477617033875e-07,0.0029159999999999998,278.8663052010275,113.51245528490624,4.2687640247447645
1.57518711022979e-07,0.0029248,278.916379790166,113.51245528490624,4.2687640247447645
1.5820807080863755e-07,0.0029376,278.98911079309096,113.51245528490624,4.2687640247447645
1.5906977054071075e-07,0.0029536,279.0798509753451,113.51245528490624,4.2687640247447645
1.5971604533976564e-07,0.0029655999999999997,279.14778035928396,113.51245528490624,4.2687640247447645
1.6087933997806445e-07,0.0029871999999999998,279.26978372402414,113.51245528490624,4.2687640247447645
1.612671048574974e-07,0.0029944,279.3103749925825,113.51245528490624,4.2687640247447645
1.6238731450919254e-07,0.0030152,279.4274253861721,113.51245528490624,4.2687640247447645
1.6281816437522912e-07,0.0030231999999999998,279.4723608643381,113.51245528490624,4.2687640247447645
1.6342135418768038e-07,0.0030344,279.53519270318185,113.51245528490624,4.2687640247447645
1.6398145901352793e-07,0.0030448,279.59345561558825,113.51245528490624,4.2687640247447645
1.6484315874560113e-07,0.0030608,279.68293954371745,113.51245528490624,4.2687640247447645
1.6673889815616214e-07,0.003096,279.8791645367485,113.51245528490624,4.2687640247447645
1.6738517295521703e-07,0.0031079999999999997,279.9458602988321,113.51245528490624,4.2687640247447645
1.6755751290163166e-07,0.0031111999999999997,279.96362886438374,113.51245528490624,4.2687640247447645
1.6854846759351584e-07,0.0031295999999999997,280.06566013733624,113.51245528490624,4.2687640247447645
1.693239973523817e-07,0.0031439999999999997,280.1453475968178,113.51245528490624,4.2687640247447645
1.6997027215143661e-07,0.003156,280.21164513747544,113.51245528490624,4.2687640247447645
1.708319718835098e-07,0.003172,280.2998891310268,113.51245528490624,4.2687640247447645
1.7186601156199762e-07,0.0031912,280.4055531089297,113.51245528490624,4.2687640247447645
1.7246920137444883e-07,0.0032023999999999998,280.4670759322106,113.51245528490624,4.2687640247447645
1.7290005124048546e-07,0.0032104,280.51096944017536,113.51245528490624,4.2687640247447645
1.741926008385952e-07,0.0032343999999999997,280.6423947309902,113.51245528490624,4.2687640247447645
1.746234507046318e-07,0.0032424,280.68611857148534,113.51245528490624,4.2687640247447645
1.768638700080221e-07,0.003284,280.9128078763748,113.51245528490624,4.2687640247447645
1.7720854990085137e-07,0.0032903999999999997,280.947583503217,113.51245528490624,4.2687640247447645
1.7789790968650994e-07,0.0033032,281.01705571869735,113.51245528490624,4.2687640247447645
1.79405884217638e-07,0.0033312,281.1686612092572,113.51245528490624,4.2687640247447645
1.7966439413725998e-07,0.003336,281.19460074168734,113.51245528490624,4.2687640247447645
1.8052609386933316e-07,0.003352,281.2809609156102,113.51245528490624,4.2687640247447645
1.8082768877555876e-07,0.0033575999999999996,281.3111489761896,113.51245528490624,4.2687640247447645
1.822925783200832e-07,0.0033848,281.457498302097,113.51245528490624,4.2687640247447645
1.8289576813253443e-07,0.0033959999999999997,281.5176263922051,113.51245528490624,4.2687640247447645
1.8487767751630275e-07,0.0034327999999999997,281.7146478322176,113.51245528490624,4.2687640247447645
1.859978871679979e-07,0.0034536,281.8256433806668,113.51245528490624,4.2687640247447645
1.8668724695365645e-07,0.0034663999999999997,281.89381876128556,113.51245528490624,4.2687640247447645
1.872904367661077e-07,0.0034776,281.9533917215306,113.51245528490624,4.2687640247447645
1.8845373140440652e-07,0.0034992,282.0680715473882,113.51245528490624,4.2687640247447645
1.896170260427053e-07,0.0035207999999999997,282.1824756221467,113.51245528490624,4.2687640247447645
1.904787257747785e-07,0.0035367999999999997,282.2670429840223,113.51245528490624,4.2687640247447645
1.9073723569440044e-07,0.0035415999999999998,282.2923840809615,113.51245528490624,4.2687640247447645
1.916420204130773e-07,0.0035583999999999998,282.3809726302105,113.51245528490624,4.2687640247447645
1.9336541987722369e-07,0.0035903999999999997,282.5492627739546,113.51245528490624,4.2687640247447645
1.9405477966288223e-07,0.0036032,282.61641491852384,113.51245528490624,4.2687640247447645
1.9543349923419933e-07,0.0036287999999999997,282.75044075252043,113.51245528490624,4.2687640247447645
1.9603668904665058e-07,0.00364,282.8089610465369,113.51245528490624,4.2687640247447645
1.9707072872513842e-07,0.0036592,282.90911843488914,113.51245528490624,4.2687640247447645
1.9797551344381525e-07,0.003676,282.9965881410237,113.51245528490624,4.2687640247447645
1.9836327832324817e-07,0.0036831999999999998,283.03402741703553,113.51245528490624,4.2687640247447645
1.9892338314909577e-07,0.0036936,283.08805601999785,113.51245528490624,4.2687640247447645
2.0021593274720552e-07,0.0037175999999999997,283.21251148430673,113.51245528490624,4.2687640247447645
2.0107763247927873e-07,0.0037335999999999997,283.295307756144,113.51245528490624,4.2687640247447645
2.017669922649373e-07,0.0037464,283.3614451847274,113.51245528490624,4.2687640247447645
2.0198241719795556e-07,0.0037503999999999997,283.3820950506416,113.51245528490624,4.2687640247447645
2.0327496679606537e-07,0.0037744,283.5058143495044,113.51245528490624,4.2687640247447645
2.0405049655493123e-07,0.0037887999999999997,283.5798986697494,113.51245528490624,4.2687640247447645
2.0499836626021175e-07,0.0038063999999999997,283.67029721239965,113.51245528490624,4.2687640247447645
2.0521379119323004e-07,0.0038104,283.6908195841822,113.51245528490624,4.2687640247447645
2.0603240593869956e-07,0.0038255999999999997,283.7687280906626,113.51245528490624,4.2687640247447645
2.0736804052341302e-07,0.0038504,283.8955832975239,113.51245528490624,4.2687640247447645
2.0766963542963862e-07,0.0038559999999999996,283.92418387410436,113.51245528490624,4.2687640247447645
2.079281453492606e-07,0.0038607999999999997,283.94868576329077,113.51245528490624,4.2687640247447645
2.0818665526888254e-07,0.0038656,283.97317577503406,113.51245528490624,4.2687640247447645
2.090914399875594e-07,0.0038824,284.05879757662626,113.51245528490624,4.2687640247447645
2.0965154481340695e-07,0.0038927999999999996,284.1117291424798,113.51245528490624,4.2687640247447645
2.104270745722728e-07,0.0039071999999999996,284.1849280458934,113.51245528490624,4.2687640247447645
2.1064249950529115e-07,0.0039112,284.2052423930691,113.51245528490624,4.2687640247447645
2.1128877430434604e-07,0.0039232,284.2661368754378,113.51245528490624,4.2687640247447645
2.1171962417038264e-07,0.0039312,284.3066928457192,113.51245528490624,4.2687640247447645
2.1197813409000456e-07,0.003935999999999999,284.33101097829075,113.51245528490624,4.2687640247447645
2.1322759870151068e-07,0.0039591999999999995,284.44838596196746,113.51245528490624,4.2687640247447645
2.1426163837999854e-07,0.0039784,284.5453211619698,113.51245528490624,4.2687640247447645
2.1460631827282783e-07,0.0039848,284.57759232894153,113.51245528490624,4.2687640247447645
2.1542493301829735e-07,0.004,284.65415544449843,113.51245528490624,4.2687640247447645
2.433495892687188e-07,0.004518503700740148,287.2016577189975,113.51245528490624,4.2687640247447645
2.6093178024120634e-07,0.00484496899379876,288.74720812040124,113.51245528490624,4.2687640247447645
2.8368520385266083e-07,0.00526745349069814,290.6882934336868,113.51245528490624,4.2687640247447645
2.8989068301942114e-07,0.005382676535307062,291.2070150769567,113.51245528490624,4.2687640247447645
3.0023314829735496e-07,0.0055747149429885975,292.0620290156336,113.51245528490624,4.2687640247447645
3.2505506496439626e-07,0.006035607121424285,294.06849031043015,113.51245528490624,4.2687640247447645
3.6125369343716475e-07,0.006707741548309662,296.8905335391039,113.51245528490624,4.2687640247447645
3.715961587150986e-07,0.0068997799559911985,297.67627728805894,113.51245528490624,4.2687640247447645
3.86075610104206e-07,0.007168633726745349,298.7621369686685,113.51245528490624,4.2687640247447645
3.9952081496552e-07,0.007418283656731346,299.7562963460445,113.51245528490624,4.2687640247447645
4.305482107993216e-07,0.007994398879775955,302.0019901274947,113.51245528490624,4.2687640247447645
4.6157560663312317e-07,0.008570514102820564,304.1853830926477,113.51245528490624,4.2687640247447645
4.781235510778174e-07,0.008877775555111022,305.32640892373456,113.51245528490624,4.2687640247447645
5.246646448285198e-07,0.009741948389677936,308.45576136911257,113.51245528490624,4.2687640247447645
5.391440962176271e-07,0.010010802160432087,309.4069956431203,113.51245528490624,4.2687640247447645
5.670687524680485e-07,0.010529305861172233,311.21383962020457,113.51245528490624,4.2687640247447645
5.877536830239162e-07,0.010913382676535306,312.52994487764136,113.51245528490624,4.2687640247447645
6.498084746915194e-07,0.012065613122624524,316.3738957603292,113.51245528490624,4.2687640247447645
6.67390665664007e-07,0.012392078415683136,317.4366205783608,113.51245528490624,4.2687640247447645
6.746303913585607e-07,0.012526505301060212,317.8710327789238,113.51245528490624,4.2687640247447645
7.12897512886916e-07,0.013237047409481896,320.1376922306759,113.51245528490624,4.2687640247447645
7.501303878874779e-07,0.013928385677135427,322.2979639165591,113.51245528490624,4.2687640247447645
7.604728531654117e-07,0.014120424084816964,322.89056460196747,113.51245528490624,4.2687640247447645
7.780550441378993e-07,0.014446889377875576,323.89082234157996,113.51245528490624,4.2687640247447645
7.863290163602464e-07,0.014600520104020805,324.3584779385075,113.51245528490624,4.2687640247447645
7.98739974693767e-07,0.014830966193238648,325.0563789637114,113.51245528490624,4.2687640247447645
8.121851795550811e-07,0.015080616123224646,325.80768290133216,113.51245528490624,4.2687640247447645
8.587262733057835e-07,0.01594478895779156,328.37169515001364,113.51245528490624,4.2687640247447645
8.721714781670975e-07,0.01619443888777756,329.1022432900859,113.51245528490624,4.2687640247447645
8.89753669139585e-07,0.01652090418083617,330.05098215688395,113.51245528490624,4.2687640247447645
9.052673670564857e-07,0.01680896179235847,330.8820491599687,113.51245528490624,4.2687640247447645
9.125070927510394e-07,0.016943388677735545,331.26797782248167,113.51245528490624,4.2687640247447645
9.259522976123534e-07,0.017193038607721544,331.9815490755915,113.51245528490624,4.2687640247447645
9.549112003905683e-07,0.017730746149229846,333.5048894972249,113.51245528490624,4.2687640247447645
9.797331170576095e-07,0.018191638327665533,334.79632354071344,113.51245528490624,4.2687640247447645
1.0304111969194855e-06,0.019132626525305063,337.3940377740323,113.51245528490624,4.2687640247447645
1.0510961274753532e-06,0.019516703340668136,338.4399504913415,113.51245528490624,4.2687640247447645
1.085226262892535e-06,0.020150430086017204,340.14832419445236,113.51245528490624,4.2687640247447645
1.0976372212260556e-06,0.020380876175235048,340.7643389580881,113.51245528490624,4.2687640247447645
1.1079796865039895e-06,0.020572914582916584,341.27561224416286,113.51245528490624,4.2687640247447645
1.1307331101154439e-06,0.020995399079815964,342.3939071234128,113.51245528490624,4.2687640247447645
1.1534865337268985e-06,0.021417883576715344,343.5034594259434,113.51245528490624,4.2687640247447645
1.2000276274776007e-06,0.022282056411282256,345.7467589958178,113.51245528490624,4.2687640247447645
1.2320892698391957e-06,0.02287737547509502,347.27243933762804,113.51245528490624,4.2687640247447645
1.2651851587285842e-06,0.023491898379675937,348.83118047056837,113.51245528490624,4.2687640247447645
1.2806988566454848e-06,0.02377995599119824,349.5563584823941,113.51245528490624,4.2687640247447645
1.2900070753956252e-06,0.02395279055811162,349.98982100971705,113.51245528490624,4.2687640247447645
1.3448221413686749e-06,0.024970594118823766,352.5181195987301,113.51245528490624,4.2687640247447645
1.3717125510913028e-06,0.02546989397879576,353.7436955036111,113.51245528490624,4.2687640247447645
1.3955002212305506e-06,0.025911582316463292,354.82006928511805,113.51245528490624,4.2687640247447645
1.4048084399806912e-06,0.026084416883376677,355.23930822236406,113.51245528490624,4.2687640247447645
1.4223906309531787e-06,0.026410882176435287,356.02825992527175,113.51245528490624,4.2687640247447645
1.4772056969262283e-06,0.02742868573714743,358.46386698438636,113.51245528490624,4.2687640247447645
1.497890627482096e-06,0.027812762552510504,359.37377074731694,113.51245528490624,4.2687640247447645
1.5009933670654762e-06,0.027870374074814963,359.5098324801538,113.51245528490624,4.2687640247447645
1.5092673392878232e-06,0.028024004800960192,359.872128573867,113.51245528490624,4.2687640247447645
1.6002810337336411e-06,0.029713942788557712,363.8075687460776,113.51245528490624,4.2687640247447645
1.6199317177617155e-06,0.03007881576315263,364.6456942425611,113.51245528490624,4.2687640247447645
1.6313084295674428e-06,0.03029005801160232,365.12911245408236,113.51245528490624,4.2687640247447645
1.6354454156786163e-06,0.030366873374674936,365.30457467607425,113.51245528490624,4.2687640247447645
1.6457878809565501e-06,0.030558911782356472,365.74247461820113,113.51245528490624,4.2687640247447645
1.6519933601233105e-06,0.030674134826965394,366.0046994655615,113.51245528490624,4.2687640247447645
1.6706097976235914e-06,0.03101980396079216,366.7890787278665,113.51245528490624,4.2687640247447645
1.6788837698459386e-06,0.03117343468693739,367.13659674813607,113.51245528490624,4.2687640247447645
1.6871577420682856e-06,0.03132706541308262,367.48344746987505,113.51245528490624,4.2687640247447645
1.6975002073462197e-06,0.03151910382076416,367.91607940162487,113.51245528490624,4.2687640247447645
1.7336988358189878e-06,0.03219123824764953,369.42226148380576,113.51245528490624,4.2687640247447645
1.7730002038751364e-06,0.032920984196839365,371.0437246351285,113.51245528490624,4.2687640247447645
1.7864454087364506e-06,0.03317063412682537,371.5952097082946,113.51245528490624,4.2687640247447645
1.7947193809587978e-06,0.033324264852970596,371.9337806550913,113.51245528490624,4.2687640247447645
1.8195412976258387e-06,0.03378515703140628,372.9458597839271,113.51245528490624,4.2687640247447645
1.849534446931847e-06,0.03434206841368274,374.1616327625212,113.51245528490624,4.2687640247447645
1.878493349710062e-06,0.03487977595519104,375.32820733115176,113.51245528490624,4.2687640247447645
1.891938554571376e-06,0.035129425885177035,375.8674450868055,113.51245528490624,4.2687640247447645
1.9115892385994505e-06,0.035494298859771956,376.65288116717005,113.51245528490624,4.2687640247447645
1.916760471238417e-06,0.03559031806361272,376.8590507165747,113.51245528490624,4.2687640247447645
1.940548141377665e-06,0.03603200640128025,377.80465055260174,113.51245528490624,4.2687640247447645
1.9539933462389794e-06,0.03628165633126626,378.3371201555708,113.51245528490624,4.2687640247447645
1.9581303323501527e-06,0.03635847169433887,378.50066923401124,113.51245528490624,4.2687640247447645
1.9664043045724997e-06,0.0365121024204841,378.8273636770479,113.51245528490624,4.2687640247447645
1.9798495094338134e-06,0.03676175235047009,379.3571010615201,113.51245528490624,4.2687640247447645
1.9850207420727806e-06,0.03685777155431086,379.5604723966586,113.51245528490624,4.2687640247447645
2.0015686865174746e-06,0.03716503300660132,380.2098765178286,113.51245528490624,4.2687640247447645
2.025356356656723e-06,0.03760672134426886,381.13973850316813,113.51245528490624,4.2687640247447645
2.0367330684624504e-06,0.03781796359271855,381.5829486214609,113.51245528490624,4.2687640247447645
2.038801561518037e-06,0.037856371274254855,381.6634284397974,113.51245528490624,4.2687640247447645
2.116370051102541e-06,0.03929665933186638,384.658824221031,113.51245528490624,4.2687640247447645
2.1308495024916478e-06,0.03956551310262052,385.2131902700517,113.51245528490624,4.2687640247447645
2.1473974469363422e-06,0.03987277455491098,385.84495570226477,113.51245528490624,4.2687640247447645
2.1567056656864827e-06,0.040045609121824366,386.1994893210602,113.51245528490624,4.2687640247447645
2.1856645684646974e-06,0.04058331666333266,387.2986856675262,113.51245528490624,4.2687640247447645
2.2022125129093914e-06,0.04089057811562312,387.924247545659,113.51245528490624,4.2687640247447645
2.2621988115214082e-06,0.04200440088017604,390.1767019609974,113.51245528490624,4.2687640247447645
2.2746097698549285e-06,0.04223484696939388,390.63980521521677,113.51245528490624,4.2687640247447645
2.2952947004107967e-06,0.04261892378475696,391.40946003427075,113.51245528490624,4.2687640247447645
2.306671412216524e-06,0.04283016603320665,391.8316170036488,113.51245528490624,4.2687640247447645
2.328390589300185e-06,0.04323344668933787,392.6353049658956,113.51245528490624,4.2687640247447645
2.336664561522532e-06,0.0433870774154831,392.94070208514387,113.51245528490624,4.2687640247447645
2.36355497124516e-06,0.043886377275455093,393.9303427386048,113.51245528490624,4.2687640247447645
2.380102915689854e-06,0.04419363872774555,394.5371701921794,113.51245528490624,4.2687640247447645
2.417335790690416e-06,0.044884976995399076,395.89654793698946,113.51245528490624,4.2687640247447645
2.43698647471849e-06,0.045249849969994,396.61070388718883,113.51245528490624,4.2687640247447645
2.4493974330520113e-06,0.04548029605921185,397.06059282216125,113.51245528490624,4.2687640247447645
2.4680138705522918e-06,0.04582596519303861,397.7337628784415,113.51245528490624,4.2687640247447645
2.4752535962468454e-06,0.04596039207841568,397.99501606255825,113.51245528490624,4.2687640247447645
2.481459075413606e-06,0.046075615123024605,398.21871026181356,113.51245528490624,4.2687640247447645
2.4949042802749197e-06,0.0463252650530106,398.7026339673679,113.51245528490624,4.2687640247447645
2.5052467455528535e-06,0.04651730346069213,399.074191201301,113.51245528490624,4.2687640247447645
2.5124864712474076e-06,0.04665173034606922,399.3339254031685,113.51245528490624,4.2687640247447645
2.5321371552754823e-06,0.04701660332066414,400.0374510709174,113.51245528490624,4.2687640247447645
2.575575509442804e-06,0.04782316463292659,401.58510117287534,113.51245528490624,4.2687640247447645
2.6003974261098452e-06,0.048284056811362275,402.46490173718513,113.51245528490624,4.2687640247447645
2.6996850927780107e-06,0.050127625525105024,405.9518359162269,113.51245528490624,4.2687640247447645
2.7234727629172583e-06,0.05056931386277255,406.7797765278962,113.51245528490624,4.2687640247447645
2.750363172639886e-06,0.051068613722744544,407.7123208302052,113.51245528490624,4.2687640247447645
2.771048103195754e-06,0.05145269053810762,408.4272449988965,113.51245528490624,4.2687640247447645
2.783459061529274e-06,0.05168313662732546,408.85520054162134,113.51245528490624,4.2687640247447645
2.7875960476404483e-06,0.05175995199039808,408.997686929356,113.51245528490624,4.2687640247447645
2.8300001552799773e-06,0.052547309461892386,410.4534488703514,113.51245528490624,4.2687640247447645
2.8465480997246717e-06,0.052854570914182844,411.0192403416757,113.51245528490624,4.2687640247447645
2.8599933045859854e-06,0.05310422084416884,411.4780019658475,113.51245528490624,4.2687640247447645
2.883780974725233e-06,0.05354590918183637,412.28760198114236,113.51245528490624,4.2687640247447645
2.8951576865309603e-06,0.05375715143028606,412.6738809425025,113.51245528490624,4.2687640247447645
2.9086028913922745e-06,0.054006801360272055,413.12963005680035,113.51245528490624,4.2687640247447645
2.9127398775034474e-06,0.05408361672334466,413.26969515978635,113.51245528490624,4.2687640247447645
2.927219328892555e-06,0.05435247049409882,413.7593132104273,113.51245528490624,4.2687640247447645
2.936527547642696e-06,0.054525305061012205,414.0735689695776,113.51245528490624,4.2687640247447645
2.954109738615183e-06,0.05485177035407081,414.6661052566301,113.51245528490624,4.2687640247447645
2.957212478198563e-06,0.05490938187637527,414.7705275505911,113.51245528490624,4.2687640247447645
2.9696234365320843e-06,0.05513982796559312,415.1877901472863,113.51245528490624,4.2687640247447645
2.9944453531991253e-06,0.05560072014402881,416.02028059904194,113.51245528490624,4.2687640247447645
3.0151302837549926e-06,0.055984796959391875,416.7119687677938,113.51245528490624,4.2687640247447645
3.0378837073664477e-06,0.05640728145629126,417.47069177177184,113.51245528490624,4.2687640247447645
3.067876856672456e-06,0.05696419283856771,418.4674490269045,113.51245528490624,4.2687640247447645
3.076150828894803e-06,0.05711782356471294,418.74174680837154,113.51245528490624,4.2687640247447645
3.0906302802839105e-06,0.057386677335467096,419.22107656957337,113.51245528490624,4.2687640247447645
3.1175206900065383e-06,0.05788597719543909,420.10894327375075,113.51245528490624,4.2687640247447645
3.140274113617993e-06,0.05830846169233847,420.85788470494185,113.51245528490624,4.2687640247447645
3.14854808584034e-06,0.0584620924184837,421.12970194118384,113.51245528490624,4.2687640247447645
3.1681987698684143e-06,0.05882696539307862,421.77415382438636,113.51245528490624,4.2687640247447645
3.178541235146348e-06,0.05901900380076015,422.1127127743081,113.51245528490624,4.2687640247447645
3.186815207368695e-06,0.05917263452690538,422.3832507027392,113.51245528490624,4.2687640247447645
3.2116371240357366e-06,0.05963352670534107,423.1932256326427,113.51245528490624,4.2687640247447645
3.226116575424844e-06,0.059902380476095224,423.66458354940806,113.51245528490624,4.2687640247447645
3.2540412316752655e-06,0.060420884176835374,424.57130749813626,113.51245528490624,4.2687640247447645
3.2674864365365797e-06,0.06067053410682137,425.00679555276133,113.51245528490624,4.2687640247447645
3.288171367092447e-06,0.061054610922184435,425.6754150082535,113.51245528490624,4.2687640247447645
3.3016165719537607e-06,0.06130426085217043,426.10913818019094,113.51245528490624,4.2687640247447645
3.311959037231695e-06,0.06149629925985198,426.44230281938417,113.51245528490624,4.2687640247447645
3.3202330094540425e-06,0.06164992998599721,426.70854248088074,113.51245528490624,4.2687640247447645
3.331609721259769e-06,0.061861172234446885,427.0741999099617,113.51245528490624,4.2687640247447645
3.3760823219548847e-06,0.06268693738747749,428.4989399717172,113.51245528490624,4.2687640247447645
3.394698759455165e-06,0.06303260652130425,429.09316734175434,113.51245528490624,4.2687640247447645
3.4195206761222066e-06,0.06349349869973994,429.88349730689345,113.51245528490624,4.2687640247447645
3.439171360150281e-06,0.06385837167433486,430.50758955144306,113.51245528490624,4.2687640247447645
3.4805412212620164e-06,0.06462652530506101,431.81694036648855,113.51245528490624,4.2687640247447645
3.5394932733462398e-06,0.06572114422884577,433.67232641973214,113.51245528490624,4.2687640247447645
3.5456987525130003e-06,0.0658363672734547,433.86692654589723,113.51245528490624,4.2687640247447645
3.552938478207554e-06,0.06597079415883177,434.0937922296755,113.51245528490624,4.2687640247447645
3.5715549157078344e-06,0.06631646329265853,434.6763348278961,113.51245528490624,4.2687640247447645
3.5808631344579752e-06,0.06648929785957192,434.96716195917213,113.51245528490624,4.2687640247447645
3.5932740927914964e-06,0.06671974394878977,435.35447325143986,113.51245528490624,4.2687640247447645
3.6015480650138434e-06,0.066873374674935,435.61239097381196,113.51245528490624,4.2687640247447645
3.614993269875157e-06,0.06712302460492099,436.03101496017916,113.51245528490624,4.2687640247447645
3.6305069677920577e-06,0.06741108221644329,436.5132888428318,113.51245528490624,4.2687640247447645
3.634643953903232e-06,0.06748789757951591,436.6417593874165,113.51245528490624,4.2687640247447645
3.6698083358482068e-06,0.06814082816563313,437.73146606228113,113.51245528490624,4.2687640247447645
3.689459019876281e-06,0.06850570114022805,438.3386459325892,113.51245528490624,4.2687640247447645
3.703938471265388e-06,0.0687745549109822,438.78523488482836,113.51245528490624,4.2687640247447645
3.7297946344602227e-06,0.06925465093018604,439.58102536236925,113.51245528490624,4.2687640247447645
3.754616551127264e-06,0.06971554310862173,440.3429625399912,113.51245528490624,4.2687640247447645
3.7773699747387188e-06,0.07013802760552111,441.039680957831,113.51245528490624,4.2687640247447645
3.785643946961066e-06,0.07029165833166634,441.2926270614088,113.51245528490624,4.2687640247447645
3.846664492100876e-06,0.0714246849369874,443.151491352425,113.51245528490624,4.2687640247447645
3.902513804601718e-06,0.07246169233846769,444.8427696030616,113.51245528490624,4.2687640247447645
3.93354120043552e-06,0.0730378075615123,445.77828906166445,113.51245528490624,4.2687640247447645
3.948020651824628e-06,0.07330666133226646,446.2138795086292,113.51245528490624,4.2687640247447645
3.951123391408008e-06,0.07336427285457092,446.30713920959846,113.51245528490624,4.2687640247447645
3.957328870574768e-06,0.07347949589917983,446.4935729708254,113.51245528490624,4.2687640247447645
3.9873220198807765e-06,0.0740364072814563,447.3930671328858,113.51245528490624,4.2687640247447645
3.991459005991949e-06,0.07411322264452891,447.5169278869556,113.51245528490624,4.2687640247447645
4.002835717797677e-06,0.0743244648929786,447.857287071842,113.51245528490624,4.2687640247447645
4.012143936547818e-06,0.07449729945989199,448.13548224324916,113.51245528490624,4.2687640247447645
4.028691880992512e-06,0.07480456091218245,448.62943072378494,113.51245528490624,4.2687640247447645
4.032828867103685e-06,0.07488137627525505,448.7527941298721,113.51245528490624,4.2687640247447645
4.035931606687065e-06,0.07493898779755952,448.84528429828606,113.51245528490624,4.2687640247447645
4.043171332381618e-06,0.07507341468293659,449.06098691673185,113.51245528490624,4.2687640247447645
4.0483425650205854e-06,0.07516943388677735,449.21496800166335,113.51245528490624,4.2687640247447645
4.102123384465842e-06,0.07616803360672135,450.8118501737295,113.51245528490624,4.2687640247447645
4.1290137941884695e-06,0.07666733346669334,451.6072278547301,113.51245528490624,4.2687640247447645
4.148664478216544e-06,0.07703220644128826,452.1871884156974,113.51245528490624,4.2687640247447645
4.152801464327718e-06,0.07710902180436088,452.3091487492913,113.51245528490624,4.2687640247447645
4.1621096830778584e-06,0.07728185637127426,452.5833863877861,113.51245528490624,4.2687640247447645
4.172452148355792e-06,0.07747389477895579,452.8878144966802,113.51245528490624,4.2687640247447645
4.194171325439453e-06,0.07787717543508701,453.5261572644961,113.51245528490624,4.2687640247447645
4.212787762939735e-06,0.07822284456891379,454.07228280066954,113.51245528490624,4.2687640247447645
4.224164474745462e-06,0.07843408681736348,454.4055628731325,113.51245528490624,4.2687640247447645
4.229335707384429e-06,0.07853010602120425,454.55693807279306,113.51245528490624,4.2687640247447645
4.2355411865511885e-06,0.07864532906581316,454.7384930629079,113.51245528490624,4.2687640247447645
4.244849405301329e-06,0.07881816363272655,455.0106311601208,113.51245528490624,4.2687640247447645
4.261397349746023e-06,0.079125425085017,455.4938582700422,113.51245528490624,4.2687640247447645
4.290356252524239e-06,0.07966313262652532,456.33774844812024,113.51245528490624,4.2687640247447645
4.304835703913345e-06,0.07993198639727946,456.7588602777838,113.51245528490624,4.2687640247447645
4.3420685789139075e-06,0.080623324664933,457.8391905481924,113.51245528490624,4.2687640247447645
4.352411044191841e-06,0.08081536307261453,458.13864034636276,113.51245528490624,4.2687640247447645
4.372061728219915e-06,0.08118023604720945,458.70683152401426,113.51245528490624,4.2687640247447645
4.396883644886957e-06,0.08164112822564513,459.423125097537,113.51245528490624,4.2687640247447645
4.422739808081792e-06,0.08212122424484898,460.16758926600136,113.51245528490624,4.2687640247447645
4.437219259470899e-06,0.08239007801560312,460.58374773992546,113.51245528490624,4.2687640247447645
4.497205558082915e-06,0.08350390078015603,462.30222092480096,113.51245528490624,4.2687640247447645
4.556157610167138e-06,0.08459851970394079,463.98237694676703,113.51245528490624,4.2687640247447645
4.569602815028452e-06,0.08484816963392679,464.3643805625415,113.51245528490624,4.2687640247447645
4.586150759473147e-06,0.08515543108621725,464.8339376331324,113.51245528490624,4.2687640247447645
4.602698703917841e-06,0.0854626925385077,465.3028343991472,113.51245528490624,4.2687640247447645
4.618212401834742e-06,0.08575075015003002,465.74182835942963,113.51245528490624,4.2687640247447645
4.631657606696056e-06,0.08600040008001601,466.12182478420146,113.51245528490624,4.2687640247447645
4.643034318501783e-06,0.0862116423284657,466.44302432290146,113.51245528490624,4.2687640247447645
4.675095960863377e-06,0.08680696139227846,467.3465758114979,113.51245528490624,4.2687640247447645
4.682335686557931e-06,0.08694138827765553,467.5502687322617,113.51245528490624,4.2687640247447645
4.7154315754473194e-06,0.08755591118223645,468.4798766380467,113.51245528490624,4.2687640247447645
4.7340480129476e-06,0.08790158031606321,469.0016627921309,113.51245528490624,4.2687640247447645
4.745424724753328e-06,0.0881128225645129,469.3201381846601,113.51245528490624,4.2687640247447645
4.750595957392294e-06,0.08820884176835367,469.46480127639614,113.51245528490624,4.2687640247447645
4.758869929614642e-06,0.0883624724944989,469.6961345474648,113.51245528490624,4.2687640247447645
4.769212394892576e-06,0.08855451090218044,469.9850806705485,113.51245528490624,4.2687640247447645
4.783691846281683e-06,0.08882336467293458,470.3891950286861,113.51245528490624,4.2687640247447645
4.800239790726377e-06,0.08913062612522504,470.85045633505854,113.51245528490624,4.2687640247447645
4.820924721282245e-06,0.08951470294058812,471.42616182112533,113.51245528490624,4.2687640247447645
4.841609651838113e-06,0.08989877975595119,472.00090474905585,113.51245528490624,4.2687640247447645
4.867465815032948e-06,0.09037887577515503,472.71798850710195,113.51245528490624,4.2687640247447645
4.882979512949848e-06,0.09066693338667733,473.14752571831525,113.51245528490624,4.2687640247447645
4.925383620589377e-06,0.09145429085817164,474.3188871270025,113.51245528490624,4.2687640247447645
4.941931565034071e-06,0.0917615523104621,474.77493607004396,113.51245528490624,4.2687640247447645
4.955376769895385e-06,0.09201120224044809,475.1450374687982,113.51245528490624,4.2687640247447645
4.963650742117732e-06,0.09216483296659332,475.37259752802913,113.51245528490624,4.2687640247447645
5.003986356701674e-06,0.09291378275655131,476.47984132374637,113.51245528490624,4.2687640247447645
5.029842519896509e-06,0.09339387877575515,477.1877825943169,113.51245528490624,4.2687640247447645
5.0608699157303105e-06,0.09396999399879977,478.03544140969086,113.51245528490624,4.2687640247447645
5.105342516425426e-06,0.09479575915183037,479.2468930908281,113.51245528490624,4.2687640247447645
5.1156849817033605e-06,0.09498779755951191,479.5280353522873,113.51245528490624,4.2687640247447645
5.1322329261480546e-06,0.09529505901180237,479.97740233256314,113.51245528490624,4.2687640247447645
5.157054842815096e-06,0.09575595119023805,480.6503947461104,113.51245528490624,4.2687640247447645
5.194287717815657e-06,0.09644728945789158,481.65751950722535,113.51245528490624,4.2687640247447645
5.201527443510211e-06,0.09658171634326866,481.85302195338414,113.51245528490624,4.2687640247447645
5.206698676149178e-06,0.09667773554710943,481.9926015903871,113.51245528490624,4.2687640247447645
5.238760318510773e-06,0.09727305461092219,482.85679171311693,113.51245528490624,4.2687640247447645
5.277027440039128e-06,0.09798359671934387,483.88554896061777,113.51245528490624,4.2687640247447645
5.298746617122789e-06,0.09838687737547509,484.4681438721816,113.51245528490624,4.2687640247447645
5.313226068511896e-06,0.09865573114622925,484.85602316167314,113.51245528490624,4.2687640247447645
5.346321957401285e-06,0.09927025405081016,485.74105969663964,113.51245528490624,4.2687640247447645
5.37217812059612e-06,0.09975035007001401,486.4310086208483,113.51245528490624,4.2687640247447645