File: datasets/aisi_316_L/data/M1/train_58.csv
Time(s),Strain(%),Stress(MPa),Temp(C),Log_SR(s-1)
0.0,0.0,0.0,388.90739596267554,1.714444295226274
3.859985741628675e-07,1.9999999999999998e-05,3.4041484374999995,388.90739596267554,1.714444295226274
4.6319828899544106e-07,2.4e-05,4.084978125,388.90739596267554,1.714444295226274
5.403980038280145e-07,2.8e-05,4.7658078125,388.90739596267554,1.714444295226274
1.6057540685175288e-06,8.319999999999999e-05,14.161257499999998,388.90739596267554,1.714444295226274
2.2542316731111464e-06,0.00011679999999999999,19.880226874999998,388.90739596267554,1.714444295226274
2.470390874642352e-06,0.000128,21.78655,388.90739596267554,1.714444295226274
2.9644690495708227e-06,0.0001536,26.14386,388.90739596267554,1.714444295226274
3.134308422202484e-06,0.0001624,27.641685312499998,388.90739596267554,1.714444295226274
3.3813475096667195e-06,0.0001752,29.8203403125,388.90739596267554,1.714444295226274
3.890865627561705e-06,0.0002016,34.31381625,388.90739596267554,1.714444295226274
4.153344657992454e-06,0.0002152,36.6286371875,388.90739596267554,1.714444295226274
4.40038374545669e-06,0.00022799999999999999,38.807292187499996,388.90739596267554,1.714444295226274
4.493023403255778e-06,0.0002328,39.6242878125,388.90739596267554,1.714444295226274
4.6783027188539546e-06,0.00024239999999999998,41.258279062499994,388.90739596267554,1.714444295226274
4.755502433686527e-06,0.00024639999999999997,41.939108749999995,388.90739596267554,1.714444295226274
5.2187007226819695e-06,0.0002704,46.024086875,388.90739596267554,1.714444295226274
5.342220266414087e-06,0.0002768,47.113414375,388.90739596267554,1.714444295226274
6.160537243639366e-06,0.0003192,54.3302090625,388.90739596267554,1.714444295226274
6.345816559237542e-06,0.00032879999999999997,55.9642003125,388.90739596267554,1.714444295226274
6.932534391965101e-06,0.0003592,61.1385059375,388.90739596267554,1.714444295226274
7.179573479429336e-06,0.000372,63.3171609375,388.90739596267554,1.714444295226274
7.256773194261909e-06,0.000376,63.99799062499999,388.90739596267554,1.714444295226274
7.442052509860086e-06,0.0003856,65.631981875,388.90739596267554,1.714444295226274
7.704531540290837e-06,0.0003992,67.9468028125,388.90739596267554,1.714444295226274
8.21404965818582e-06,0.0004256,72.44027875,388.90739596267554,1.714444295226274
8.368449087850967e-06,0.00043359999999999997,73.80193812499999,388.90739596267554,1.714444295226274
9.171326122109733e-06,0.0004752,80.882566875,388.90739596267554,1.714444295226274
9.603644525172143e-06,0.0004976,84.695213125,388.90739596267554,1.714444295226274
1.031388190163182e-05,0.0005344,90.95884625,388.90739596267554,1.714444295226274
1.0715320418761202e-05,0.0005551999999999999,94.49916062499999,388.90739596267554,1.714444295226274
1.1039559221058013e-05,0.000572,97.3586453125,388.90739596267554,1.714444295226274
1.159539716785254e-05,0.0006008,102.2606190625,388.90739596267554,1.714444295226274
1.1950515856082379e-05,0.0006192,105.39243562499999,388.90739596267554,1.714444295226274
1.2027715570914951e-05,0.0006232,106.0732653125,388.90739596267554,1.714444295226274
1.2259314715412672e-05,0.0006351999999999999,108.115754375,388.90739596267554,1.714444295226274
1.3185711293403556e-05,0.0006832,116.28571062500001,388.90739596267554,1.714444295226274
1.3417310437901275e-05,0.0006952,118.3281996875,388.90739596267554,1.714444295226274
1.4621625989289423e-05,0.0007576,128.94914281249999,388.90739596267554,1.714444295226274
1.5100264221251377e-05,0.0007823999999999999,133.170286875,388.90739596267554,1.714444295226274
1.565610216804591e-05,0.0008112,138.07226062499998,388.90739596267554,1.714444295226274
1.622738005780695e-05,0.0008408,143.1104003125,388.90739596267554,1.714444295226274
1.64898590882377e-05,0.0008544,145.42522125,388.90739596267554,1.714444295226274
1.6644258517902847e-05,0.0008623999999999999,146.78688062499998,388.90739596267554,1.714444295226274
1.678321800460148e-05,0.0008696,148.0123740625,388.90739596267554,1.714444295226274
1.6968497320199657e-05,0.0008792,149.6463653125,388.90739596267554,1.714444295226274
1.724641629359692e-05,0.0008935999999999999,152.09735218749998,388.90739596267554,1.714444295226274
1.7462575495128128e-05,0.0009048,154.0036753125,388.90739596267554,1.714444295226274
1.7586095038860242e-05,0.0009111999999999999,155.09300281249998,388.90739596267554,1.714444295226274
1.7972093613023112e-05,0.0009312,158.49715125,388.90739596267554,1.714444295226274
1.8172812871587805e-05,0.0009416,160.2673084375,388.90739596267554,1.714444295226274
1.923816893627732e-05,0.0009968,165.50029005771373,388.90739596267554,1.714444295226274
1.9562407738574126e-05,0.0010136,165.59052010566506,388.90739596267554,1.714444295226274
1.980944682603836e-05,0.0010264,165.6588758601,388.90739596267554,1.714444295226274
2.004104597053608e-05,0.0010383999999999999,165.7226580588392,388.90739596267554,1.714444295226274
2.0180005457234714e-05,0.0010456,165.7607894094153,388.90739596267554,1.714444295226274
2.031896494393335e-05,0.0010528,165.79881849316342,388.90739596267554,1.714444295226274
2.0550564088431064e-05,0.0010647999999999999,165.8619756696044,388.90739596267554,1.714444295226274
2.0704963518096214e-05,0.0010728,165.90392630628205,388.90739596267554,1.714444295226274
2.084392300479485e-05,0.00108,165.941577680337,388.90739596267554,1.714444295226274
2.0998322434459992e-05,0.001088,165.98329791424456,388.90739596267554,1.714444295226274
2.1168161807091656e-05,0.0010968,166.02905223184771,388.90739596267554,1.714444295226274
2.1276241407857257e-05,0.0011024,166.05809408798243,388.90739596267554,1.714444295226274
2.161592015312058e-05,0.00112,166.14899616184653,388.90739596267554,1.714444295226274
2.1739439696852702e-05,0.0011264,166.18191311724001,388.90739596267554,1.714444295226274
2.1878399183551333e-05,0.0011336,166.21885762931097,388.90739596267554,1.714444295226274
2.2187198042881627e-05,0.0011496,166.30063047258693,388.90739596267554,1.714444295226274
2.2773915875609183e-05,0.0011799999999999998,166.45478627214757,388.90739596267554,1.714444295226274
2.3051834849006447e-05,0.0011944,166.52726611657235,388.90739596267554,1.714444295226274
2.325255410757114e-05,0.0012048,166.5794008901566,388.90739596267554,1.714444295226274
2.339151359426977e-05,0.001212,166.61539142483818,388.90739596267554,1.714444295226274
2.3870151826231725e-05,0.0012368,166.73872554605896,388.90739596267554,1.714444295226274
2.39473515410643e-05,0.0012408,166.75852746417655,388.90739596267554,1.714444295226274
2.407087108479642e-05,0.0012472,166.79015882809418,388.90739596267554,1.714444295226274
2.4688468803457004e-05,0.0012791999999999999,166.94737592830631,388.90739596267554,1.714444295226274
2.49972676627873e-05,0.0012952,167.02540872632076,388.90739596267554,1.714444295226274
2.5522225723648798e-05,0.0013223999999999998,167.15720714294164,388.90739596267554,1.714444295226274
2.569206509628046e-05,0.0013311999999999998,167.19962088653764,388.90739596267554,1.714444295226274
2.5954544126711213e-05,0.0013448,167.26495495015462,388.90739596267554,1.714444295226274
2.6062623727476815e-05,0.0013503999999999999,167.2917822546701,388.90739596267554,1.714444295226274
2.613982344230939e-05,0.0013544,167.31091805793577,388.90739596267554,1.714444295226274
2.6494942130539227e-05,0.0013728,167.3986604187652,388.90739596267554,1.714444295226274
2.6680221446137403e-05,0.0013824,167.4442568991508,388.90739596267554,1.714444295226274
2.686550076173558e-05,0.001392,167.48973005496154,388.90739596267554,1.714444295226274
2.70970999062333e-05,0.0014039999999999999,167.54639987133658,388.90739596267554,1.714444295226274
2.7375018879630567e-05,0.0014184,167.6141549112606,388.90739596267554,1.714444295226274
2.7436778651496622e-05,0.0014215999999999999,167.62917509368293,388.90739596267554,1.714444295226274
2.7961736712358123e-05,0.0014487999999999999,167.75631860905287,388.90739596267554,1.714444295226274
2.81470160279563e-05,0.0014583999999999999,167.8009700807617,388.90739596267554,1.714444295226274
2.831685540058796e-05,0.0014671999999999999,167.84180000080596,388.90739596267554,1.714444295226274
2.8625654259918254e-05,0.0014831999999999998,167.91579236731064,388.90739596267554,1.714444295226274
2.90888525489137e-05,0.0015072,168.02619989376768,388.90739596267554,1.714444295226274
2.9243251978578845e-05,0.0015152,168.06284975518744,388.90739596267554,1.714444295226274
2.9567490780875653e-05,0.001532,168.1395697265267,388.90739596267554,1.714444295226274
2.989172958317246e-05,0.0015488,168.2159622775833,388.90739596267554,1.714444295226274
2.9968929298005035e-05,0.0015528,168.23410326537345,388.90739596267554,1.714444295226274
3.061740690259865e-05,0.0015864,168.38577466698496,388.90739596267554,1.714444295226274
3.075636638929728e-05,0.0015936,168.4181120933306,388.90739596267554,1.714444295226274
3.14048439938909e-05,0.0016271999999999999,168.56827304575492,388.90739596267554,1.714444295226274
3.163644313838862e-05,0.0016392,168.6216082612674,388.90739596267554,1.714444295226274
3.174452273915422e-05,0.0016447999999999999,168.64644589651434,388.90739596267554,1.714444295226274
3.199156182661846e-05,0.0016576,168.70309412295595,388.90739596267554,1.714444295226274
3.2501079944513445e-05,0.001684,168.8193951279239,388.90739596267554,1.714444295226274
3.2717239146044654e-05,0.0016952,168.86851987934884,388.90739596267554,1.714444295226274
3.352011618030341e-05,0.0017368,169.0498855093749,388.90739596267554,1.714444295226274
3.356643600920296e-05,0.0017392,169.06029691777974,388.90739596267554,1.714444295226274
3.3782595210734164e-05,0.0017503999999999998,169.10880959651402,388.90739596267554,1.714444295226274
3.4045074241164916e-05,0.001764,169.1675554020782,388.90739596267554,1.714444295226274
3.440019292939475e-05,0.0017824,169.246754639672,388.90739596267554,1.714444295226274
3.446195270126081e-05,0.0017855999999999998,169.26049580774995,388.90739596267554,1.714444295226274
3.453915241609339e-05,0.0017896,169.27765876967186,388.90739596267554,1.714444295226274
3.4678111902792014e-05,0.0017967999999999999,169.30851444692746,388.90739596267554,1.714444295226274
3.503323059102186e-05,0.0018151999999999999,169.38714956691015,388.90739596267554,1.714444295226274
3.5172190077720485e-05,0.0018223999999999998,169.41783513407742,388.90739596267554,1.714444295226274
3.541922916518473e-05,0.0018352,169.4722707649608,388.90739596267554,1.714444295226274
3.568170819561547e-05,0.0018487999999999998,169.5299466307391,388.90739596267554,1.714444295226274
3.586698751121365e-05,0.0018583999999999999,169.57055942597714,388.90739596267554,1.714444295226274
3.617578637054394e-05,0.0018743999999999998,169.63806606621364,388.90739596267554,1.714444295226274
3.646914528690772e-05,0.0018896,169.70198951675354,388.90739596267554,1.714444295226274
3.657722488767332e-05,0.0018951999999999999,169.72548967030534,388.90739596267554,1.714444295226274
3.674706426030499e-05,0.0019039999999999999,169.76236384198552,388.90739596267554,1.714444295226274
3.696322346183619e-05,0.0019152,169.80919861882458,388.90739596267554,1.714444295226274
3.725658237819997e-05,0.0019303999999999999,169.8725896082115,388.90739596267554,1.714444295226274
3.7565381237530264e-05,0.0019463999999999998,169.9391070223988,388.90739596267554,1.714444295226274
3.761170106642981e-05,0.0019487999999999999,169.9490662115618,388.90739596267554,1.714444295226274
3.796681975465965e-05,0.0019672,170.02526172057378,388.90739596267554,1.714444295226274
3.816753901322434e-05,0.0019776,170.06820579015846,388.90739596267554,1.714444295226274
3.889321633265053e-05,0.0020152,170.22273564948418,388.90739596267554,1.714444295226274
3.9047615762315676e-05,0.0020231999999999997,170.25546880190447,388.90739596267554,1.714444295226274
3.92792149068134e-05,0.0020352,170.30447404293812,388.90739596267554,1.714444295226274
3.9773293081741866e-05,0.0020608,170.40864351188176,388.90739596267554,1.714444295226274
3.986593273954096e-05,0.0020656,170.42811897552681,388.90739596267554,1.714444295226274
4.009753188403868e-05,0.0020775999999999998,170.4767305745278,388.90739596267554,1.714444295226274
4.01284117699717e-05,0.0020792,170.48320383764081,388.90739596267554,1.714444295226274
4.020561148480428e-05,0.0020832,170.49937850181044,388.90739596267554,1.714444295226274
4.03291310285364e-05,0.0020896,170.5252327935962,388.90739596267554,1.714444295226274
4.0437210629302e-05,0.0020951999999999998,170.54782997610658,388.90739596267554,1.714444295226274
4.0653369830833206e-05,0.0021064,170.59295380030161,388.90739596267554,1.714444295226274
4.0699689659732756e-05,0.0021088,170.60261100626334,388.90739596267554,1.714444295226274
4.100848851906305e-05,0.0021248,170.6668831882476,388.90739596267554,1.714444295226274
4.2089284526719076e-05,0.0021808,170.89036431974606,388.90739596267554,1.714444295226274
4.2876721618011325e-05,0.0022216,171.0517793456728,388.90739596267554,1.714444295226274
4.313920064844207e-05,0.0022351999999999997,171.1053268924357,388.90739596267554,1.714444295226274
4.3370799792939796e-05,0.0022472,171.15246929599974,388.90739596267554,1.714444295226274
4.349431933667191e-05,0.0022535999999999997,171.17757176250697,388.90739596267554,1.714444295226274
4.3602398937437515e-05,0.0022592,171.1995136227922,388.90739596267554,1.714444295226274
4.403471734049993e-05,0.0022816,171.2870697773439,388.90739596267554,1.714444295226274
4.4142796941265535e-05,0.0022872,171.30890635529556,388.90739596267554,1.714444295226274
4.425087654203113e-05,0.0022928,171.33072209187756,388.90739596267554,1.714444295226274
4.449791562949537e-05,0.0023056,171.3805087498425,388.90739596267554,1.714444295226274
4.5655911351983966e-05,0.0023656,171.61246172961165,388.90739596267554,1.714444295226274
4.571767112385003e-05,0.0023688,171.6247677037582,388.90739596267554,1.714444295226274
4.6489668272175764e-05,0.0024088,171.77804938565657,388.90739596267554,1.714444295226274
4.712270593380287e-05,0.0024416,171.90300095736742,388.90739596267554,1.714444295226274
4.7601344165764824e-05,0.0024664,171.99704239038869,388.90739596267554,1.714444295226274
4.8589500515621765e-05,0.0025176,172.19003380997776,388.90739596267554,1.714444295226274
4.888285943198554e-05,0.0025328,172.24703267688946,388.90739596267554,1.714444295226274
4.9160778405382805e-05,0.0025472,172.30090867032732,388.90739596267554,1.714444295226274
4.9423257435813556e-05,0.0025608,172.35168258767675,388.90739596267554,1.714444295226274
4.977837612404339e-05,0.0025792,172.42020963843052,388.90739596267554,1.714444295226274
4.9963655439641576e-05,0.0025888,172.45588718019852,388.90739596267554,1.714444295226274
5.011805486930672e-05,0.0025968,172.48557906704318,388.90739596267554,1.714444295226274
5.0210694527105805e-05,0.0026016,172.50337707603813,388.90739596267554,1.714444295226274
5.050405344346958e-05,0.0026168,172.55965313552727,388.90739596267554,1.714444295226274
5.0596693101268674e-05,0.0026216,172.57739801792926,388.90739596267554,1.714444295226274
5.0874612074665936e-05,0.002636,172.63055679445728,388.90739596267554,1.714444295226274
5.1106211219163655e-05,0.0026479999999999997,172.67476931602542,388.90739596267554,1.714444295226274
5.14613299073935e-05,0.0026663999999999998,172.74241038645536,388.90739596267554,1.714444295226274
5.243404631428392e-05,0.0027167999999999997,172.92676223927444,388.90739596267554,1.714444295226274
5.2480366143183466e-05,0.0027191999999999997,172.93550747653245,388.90739596267554,1.714444295226274
5.291268454624588e-05,0.0027416,173.01698504589515,388.90739596267554,1.714444295226274
5.295900437514543e-05,0.002744,173.02569935915446,388.90739596267554,1.714444295226274
5.3020764147011486e-05,0.0027472,173.0373138209907,388.90739596267554,1.714444295226274
5.3360442892274806e-05,0.0027648,173.10109929806993,388.90739596267554,1.714444295226274
5.345308255007389e-05,0.0027695999999999997,173.11846782899354,388.90739596267554,1.714444295226274
5.411700009763403e-05,0.002804,173.24260055935565,388.90739596267554,1.714444295226274
5.453387855772992e-05,0.0028255999999999997,173.3202408979541,388.90739596267554,1.714444295226274
5.4981636903758846e-05,0.0028488,173.40337499676147,388.90739596267554,1.714444295226274
5.519779610529005e-05,0.0028599999999999997,173.4434141627312,388.90739596267554,1.714444295226274
5.53521955349552e-05,0.002868,173.47197613687436,388.90739596267554,1.714444295226274
5.578451393801762e-05,0.0028904,173.55178483572513,388.90739596267554,1.714444295226274
5.5861713652850186e-05,0.0028943999999999997,173.5660109694235,388.90739596267554,1.714444295226274
5.6479311371510775e-05,0.0029264,173.67954531260014,388.90739596267554,1.714444295226274
5.6587390972276376e-05,0.0029319999999999997,173.69936394016355,388.90739596267554,1.714444295226274
5.674179040194153e-05,0.00294,173.72765067590785,388.90739596267554,1.714444295226274
5.688074988864016e-05,0.0029472,173.75308308254122,388.90739596267554,1.714444295226274
5.7035149318305305e-05,0.0029552,173.78131290989043,388.90739596267554,1.714444295226274
5.757554732213332e-05,0.0029831999999999997,173.879883453328,388.90739596267554,1.714444295226274
5.788434618146362e-05,0.0029992,173.9360474714022,388.90739596267554,1.714444295226274
5.85019439001242e-05,0.0030312,174.04802617316162,388.90739596267554,1.714444295226274
5.8810742759454495e-05,0.0030472,174.10384256625673,388.90739596267554,1.714444295226274
5.893426230318662e-05,0.0030536,174.1261371055166,388.90739596267554,1.714444295226274
5.9474660307014626e-05,0.0030816,174.2234622322074,388.90739596267554,1.714444295226274
5.967537956557931e-05,0.0030919999999999997,174.25952364791692,388.90739596267554,1.714444295226274
5.978345916634492e-05,0.0030976,174.2789217385069,388.90739596267554,1.714444295226274
6.029297728423991e-05,0.003124,174.37018629583216,388.90739596267554,1.714444295226274
6.040105688500551e-05,0.0031295999999999997,174.389506719768,388.90739596267554,1.714444295226274
6.0570896257637175e-05,0.0031384,174.41984016753594,388.90739596267554,1.714444295226274
6.074073563026883e-05,0.0031471999999999997,174.45014046221485,388.90739596267554,1.714444295226274
6.108041437553216e-05,0.0031647999999999997,174.51064210658333,388.90739596267554,1.714444295226274
6.160537243639366e-05,0.003192,174.60388718544561,388.90739596267554,1.714444295226274
6.165169226529321e-05,0.0031944,174.61209978587894,388.90739596267554,1.714444295226274
6.222297015505425e-05,0.003224,174.71319147041828,388.90739596267554,1.714444295226274
6.23773695847194e-05,0.003232,174.74045132944238,388.90739596267554,1.714444295226274
6.314936673304512e-05,0.0032719999999999997,174.87635788304493,388.90739596267554,1.714444295226274
6.339640582050936e-05,0.0032848,174.91971092695374,388.90739596267554,1.714444295226274
6.34427256494089e-05,0.0032871999999999997,174.92783228265668,388.90739596267554,1.714444295226274
6.37360845657727e-05,0.0033024,174.9792139387284,388.90739596267554,1.714444295226274
6.392136388137086e-05,0.003312,175.0116179944284,388.90739596267554,1.714444295226274
6.410664319696903e-05,0.0033215999999999996,175.043985440092,388.90739596267554,1.714444295226274
6.430736245553373e-05,0.003332,175.07900902994533,388.90739596267554,1.714444295226274
6.46933610296966e-05,0.003352,175.14624249071335,388.90739596267554,1.714444295226274
6.514111937572552e-05,0.0033751999999999996,175.22403761714224,388.90739596267554,1.714444295226274
6.544991823505582e-05,0.0033912,175.27756796226186,388.90739596267554,1.714444295226274
6.551167800692188e-05,0.0033943999999999997,175.28826220159692,388.90739596267554,1.714444295226274
6.572783720845308e-05,0.0034056,175.3256611150538,388.90739596267554,1.714444295226274
6.597487629591731e-05,0.0034184,175.36834404487155,388.90739596267554,1.714444295226274
6.636087487008018e-05,0.0034384,175.43491155043242,388.90739596267554,1.714444295226274
6.685495304500866e-05,0.0034639999999999996,175.5198980200278,388.90739596267554,1.714444295226274
6.747255076366924e-05,0.003496,175.62578743188075,388.90739596267554,1.714444295226274
6.776590968003303e-05,0.0035112,175.67595242351186,388.90739596267554,1.714444295226274
6.802838871046377e-05,0.0035248,175.72076514429708,388.90739596267554,1.714444295226274
6.818278814012892e-05,0.0035328,175.74709406905473,388.90739596267554,1.714444295226274
6.89084654595551e-05,0.0035704,175.87052988704434,388.90739596267554,1.714444295226274
6.937166374855054e-05,0.0035943999999999998,175.94905370828306,388.90739596267554,1.714444295226274
6.966502266491433e-05,0.0036095999999999997,175.9986797172593,388.90739596267554,1.714444295226274
7.002014135314417e-05,0.0036279999999999997,176.0586443976454,388.90739596267554,1.714444295226274
7.029806032654143e-05,0.0036423999999999996,176.10549058367488,388.90739596267554,1.714444295226274
7.060685918587174e-05,0.0036584,176.15745727024526,388.90739596267554,1.714444295226274
7.102373764596762e-05,0.0036799999999999997,176.22747191417162,388.90739596267554,1.714444295226274
7.157957559276216e-05,0.0037088,176.32057596785762,388.90739596267554,1.714444295226274
7.170309513649426e-05,0.0037151999999999997,176.3412274168623,388.90739596267554,1.714444295226274
7.216629342548972e-05,0.0037392,176.41854709364438,388.90739596267554,1.714444295226274
7.303093023161454e-05,0.003784,176.562361277268,388.90739596267554,1.714444295226274
7.349412852060998e-05,0.0038079999999999998,176.63913136692693,388.90739596267554,1.714444295226274
7.364852795027513e-05,0.003816,176.66467943330008,388.90739596267554,1.714444295226274
7.375660755104072e-05,0.0038215999999999997,176.6825506526409,388.90739596267554,1.714444295226274
7.404996646740451e-05,0.0038368,176.73100683960683,388.90739596267554,1.714444295226274
7.462124435716555e-05,0.0038664,176.82515457204624,388.90739596267554,1.714444295226274
7.471388401496464e-05,0.0038712,176.8403952447644,388.90739596267554,1.714444295226274
7.476020384386417e-05,0.0038735999999999996,176.84801281726723,388.90739596267554,1.714444295226274
7.554764093515644e-05,0.0039144,176.97723124547727,388.90739596267554,1.714444295226274
7.581011996558718e-05,0.003928,177.0201871879576,388.90739596267554,1.714444295226274
7.610347888195097e-05,0.0039432,177.06812818881244,388.90739596267554,1.714444295226274
7.644315762721427e-05,0.0039607999999999996,177.12354887399675,388.90739596267554,1.714444295226274
7.658211711391292e-05,0.003968,177.14619328088364,388.90739596267554,1.714444295226274
7.710707517477442e-05,0.0039952,177.23159458851,388.90739596267554,1.714444295226274
7.942351137906092e-05,0.004115223044608922,177.60576168755753,388.90739596267554,1.714444295226274
8.535363550302737e-05,0.00442248449689938,178.54473912951735,388.90739596267554,1.714444295226274
9.01718613537501e-05,0.004672134426885377,179.2890500617839,388.90739596267554,1.714444295226274
9.758451650870815e-05,0.00505621124224845,180.40453423037903,388.90739596267554,1.714444295226274
0.00010351464063267459,0.005363472694538908,181.2732911353433,388.90739596267554,1.714444295226274
0.00012315817679331342,0.00638127625525105,184.021436626126,388.90739596267554,1.714444295226274
0.00013279462849475888,0.006880576115223045,185.30648888733634,388.90739596267554,1.714444295226274
0.00015243816465539768,0.007898379675935187,187.81842538675576,388.90739596267554,1.714444295226274
0.00015317943017089349,0.007936787357471494,187.9106580653588,388.90739596267554,1.714444295226274
0.0001683753732385575,0.008724144828965793,189.76468594533063,388.90739596267554,1.714444295226274
0.00017689992666675925,0.009165833166633327,190.77612882825517,388.90739596267554,1.714444295226274
0.0001835713163062215,0.009511502300460092,191.55448891252337,388.90739596267554,1.714444295226274
0.00018616574561045683,0.009645929185837168,191.8541952044711,388.90739596267554,1.714444295226274
0.00018987207318793586,0.009837967593518704,192.27953661816,388.90739596267554,1.714444295226274
0.00019357840076541488,0.01003000600120024,192.70165202145236,388.90739596267554,1.714444295226274
0.00020062042316262502,0.01039487897579516,193.4950869241905,388.90739596267554,1.714444295226274
0.00020469738349785193,0.010606121224244848,193.9494787305582,388.90739596267554,1.714444295226274
0.00021507510071479318,0.01114382876575315,195.0904658043994,388.90739596267554,1.714444295226274
0.00022397028690074284,0.011604720944188837,196.051464570757,388.90739596267554,1.714444295226274
0.00023508926963317992,0.012180836167233446,197.2320284997843,388.90739596267554,1.714444295226274
0.00023657180066417153,0.01225765153030606,197.38777518754281,388.90739596267554,1.714444295226274
0.0002436138230613817,0.01262252450490098,198.12243557508762,388.90739596267554,1.714444295226274
0.0002502852127008439,0.012968193638727745,198.81082617005112,388.90739596267554,1.714444295226274
0.00025918039888679357,0.013429085817163433,199.7176492320438,388.90739596267554,1.714444295226274
0.0002773414040164408,0.014370074014802961,201.53222929202383,388.90739596267554,1.714444295226274
0.0002799358333206761,0.014504500900180036,201.78762008393608,388.90739596267554,1.714444295226274
0.0002906841832953653,0.015061412282456492,202.83598081203596,388.90739596267554,1.714444295226274
0.00029290797984185275,0.015176635327065414,203.05098320174653,388.90739596267554,1.714444295226274
0.00029809683845032336,0.015445489097819565,203.5501948552618,388.90739596267554,1.714444295226274
0.00030625075912077724,0.015867973594718945,204.32787699496933,388.90739596267554,1.714444295226274
0.00033256568492087826,0.01723144628925785,206.78429601576022,388.90739596267554,1.714444295226274
0.0003351601142251136,0.01736587317463493,207.0222974116636,388.90739596267554,1.714444295226274
0.0003414608711068279,0.01769233846769354,207.5973290579197,388.90739596267554,1.714444295226274
0.00034924415901953383,0.018095619123824763,208.30198044165581,388.90739596267554,1.714444295226274
0.0003551742831435003,0.01840288057611522,208.83475433619654,388.90739596267554,1.714444295226274
0.00036221630554071047,0.018767753550710142,209.4629382653855,388.90739596267554,1.714444295226274
0.00036629326587593743,0.018978995799159834,209.82444660026013,388.90739596267554,1.714444295226274
0.00037259402275765174,0.019305461092218444,210.38006987712438,388.90739596267554,1.714444295226274
0.0003870487003098199,0.020054410882176434,211.6410705261518,388.90739596267554,1.714444295226274
0.00040187401061973603,0.02082256451290258,212.91546700734614,388.90739596267554,1.714444295226274
0.00040743350198595455,0.021110622124424886,213.3886215026982,388.90739596267554,1.714444295226274
0.00041410489162541683,0.02145629125825165,213.9530960688788,388.90739596267554,1.714444295226274
0.00042040564850713113,0.02178275655131026,214.48296310096916,388.90739596267554,1.714444295226274
0.00042893020193533293,0.022224444888977797,215.1949384447022,388.90739596267554,1.714444295226274
0.0004337484277860556,0.022474094818963793,215.59491782547514,388.90739596267554,1.714444295226274
0.00044004918466777,0.022800560112022406,216.11536287464318,388.90739596267554,1.714444295226274
0.0004541332294621903,0.023530306061212244,217.2683150589114,388.90739596267554,1.714444295226274
0.0004574689242819214,0.023703140628125625,217.53932991879822,388.90739596267554,1.714444295226274
0.00047414739838057697,0.024567313462692537,218.88301278582082,388.90739596267554,1.714444295226274
0.0004789656242312997,0.024816963392678536,219.26773936470377,388.90739596267554,1.714444295226274
0.000485637013870762,0.025162632526505302,219.79795513548862,388.90739596267554,1.714444295226274
0.0004963853638454512,0.025719543908781756,220.64625522282196,388.90739596267554,1.714444295226274
0.0005171407982793337,0.02679495899179836,222.26434644488322,388.90739596267554,1.714444295226274
0.0005204764930990648,0.026967793558711744,222.5220156749071,388.90739596267554,1.714444295226274
0.0005230709224033002,0.027102220444088818,222.7219800740892,388.90739596267554,1.714444295226274
0.0005282597810117708,0.02737107421484297,223.12075220471112,388.90739596267554,1.714444295226274
0.0005341899051357372,0.027678335667133427,223.57462598277604,388.90739596267554,1.714444295226274
0.0005397493965019558,0.027966393278655733,223.99835125410206,388.90739596267554,1.714444295226274
0.0005430850913216869,0.028139227845569114,224.25176946686872,388.90739596267554,1.714444295226274
0.0005467914188991658,0.02833126625325065,224.53263436317903,388.90739596267554,1.714444295226274
0.000549756480961149,0.02848489697939588,224.75679206217382,388.90739596267554,1.714444295226274
0.0005820015308852166,0.030155631126225244,227.16481916773756,388.90739596267554,1.714444295226274
0.0005834840619162082,0.03023244648929786,227.27426431578715,388.90739596267554,1.714444295226274
0.000587931655009183,0.030462892578515702,227.60195089626788,388.90739596267554,1.714444295226274
0.0005938617791331495,0.03077015403080616,228.0373664214405,388.90739596267554,1.714444295226274
0.0006009038015303596,0.03113502700540108,228.55222607833258,388.90739596267554,1.714444295226274
0.0006049807618655865,0.03134626925385077,228.8492271727332,388.90739596267554,1.714444295226274
0.0006123934170205445,0.03173034606921384,229.38723700168757,388.90739596267554,1.714444295226274
0.0006198060721755026,0.032114422884576915,229.92271295056457,388.90739596267554,1.714444295226274
0.0006257361962994691,0.032421684336867373,230.34929759825647,388.90739596267554,1.714444295226274
0.0006364845462741583,0.03297859571914383,231.11848510925762,388.90739596267554,1.714444295226274
0.0006390789755783935,0.033113022604520904,231.3033900601846,388.90739596267554,1.714444295226274
0.0006446384669446121,0.03340108021604321,231.69863203943038,388.90739596267554,1.714444295226274
0.0006476035290065953,0.03355471094218844,231.90888409218485,388.90739596267554,1.714444295226274
0.0006557574496770492,0.033977195439087816,232.48515027010362,388.90739596267554,1.714444295226274
0.000660575675527772,0.03422684536907382,232.8243577066792,388.90739596267554,1.714444295226274
0.000664282003105251,0.03441888377675535,233.08463031320923,388.90739596267554,1.714444295226274
0.0006668764324094862,0.03455331066213242,233.26648426376215,388.90739596267554,1.714444295226274
0.0006735478220489485,0.03489897979595919,233.73284624831558,388.90739596267554,1.714444295226274
0.0006894850306321082,0.03572474494898979,234.83970067674525,388.90739596267554,1.714444295226274
0.0006972683185448144,0.03612802560512103,235.37662735908282,388.90739596267554,1.714444295226274
0.0007028278099110328,0.03641608321664333,235.7587162996004,388.90739596267554,1.714444295226274
0.0007169118547054532,0.03714582916583317,236.7214367823833,388.90739596267554,1.714444295226274
0.0007213594477984279,0.03737627525505101,237.02391761252457,388.90739596267554,1.714444295226274
0.0007321077977731171,0.03793318663732746,237.751925776251,388.90739596267554,1.714444295226274
0.0007391498201703272,0.03829805961192238,238.22663760142046,388.90739596267554,1.714444295226274
0.0007491569046295206,0.03881656331266253,238.8982050507437,388.90739596267554,1.714444295226274
0.000751380701176008,0.03893178635727146,239.0469660903409,388.90739596267554,1.714444295226274
0.0007632409494239409,0.039546309261852375,239.83747708508713,388.90739596267554,1.714444295226274
0.0007665766442436719,0.03971914382876575,240.05894324989623,388.90739596267554,1.714444295226274
0.0007699123390634031,0.03989197839567914,240.28003389226245,388.90739596267554,1.714444295226274
0.0007728774011253863,0.040045609121824366,240.47624548150563,388.90739596267554,1.714444295226274
0.0007739892993986301,0.04010322064412883,240.54974911374362,388.90739596267554,1.714444295226274
0.0007773249942183611,0.0402760552110422,240.77001331779329,388.90739596267554,1.714444295226274
0.0007880733441930505,0.04083296659331867,241.47725899555954,388.90739596267554,1.714444295226274
0.0008021573889874706,0.0415627125425085,242.39832631200642,388.90739596267554,1.714444295226274
0.0008114232079311682,0.042042808561712344,243.0008541222018,388.90739596267554,1.714444295226274
0.0008273604165143281,0.04286857371474295,244.0309624294827,388.90739596267554,1.714444295226274
0.0008414444613087481,0.04359831966393278,244.93486657011644,388.90739596267554,1.714444295226274
0.0008484864837059584,0.0439631926385277,245.38460452571627,388.90739596267554,1.714444295226274
0.0008547872405876728,0.04428965793158632,245.78576919446158,388.90739596267554,1.714444295226274
0.0008599760991961435,0.04455851170234047,246.11527488083655,388.90739596267554,1.714444295226274
0.00086590622332011,0.04486577315463093,246.49090485329762,388.90739596267554,1.714444295226274
0.0008825846974187655,0.04572994598919784,247.54202296212958,388.90739596267554,1.714444295226274
0.0008877735560272362,0.045998799759952,247.86745377669826,388.90739596267554,1.714444295226274
0.0008899973525737235,0.04611402280456091,248.0066969475756,388.90739596267554,1.714444295226274
0.0009048226628836396,0.046882176435287054,248.9315413426354,388.90739596267554,1.714444295226274
0.0009063051939146313,0.046958991798359676,249.02369954979835,388.90739596267554,1.714444295226274
0.0009077877249456228,0.04703580716143228,249.11579898236488,388.90739596267554,1.714444295226274
0.0009126059507963454,0.04728545709141828,249.41471783462762,388.90739596267554,1.714444295226274
0.0009155710128583287,0.04743908781756351,249.59836199905928,388.90739596267554,1.714444295226274
0.0009177948094048162,0.04755431086217243,249.73594294779514,388.90739596267554,1.714444295226274
0.000929655057652749,0.04816883376675335,250.46752393495004,388.90739596267554,1.714444295226274
0.000933361385230228,0.04836087217443488,250.69539532410138,388.90739596267554,1.714444295226274
0.0009422565714161777,0.04882176435287057,251.24085163165336,388.90739596267554,1.714444295226274
0.0009437391024471694,0.04889857971594319,251.331565418828,388.90739596267554,1.714444295226274
0.0009492985938133878,0.04918663732746549,251.6712482824994,388.90739596267554,1.714444295226274
0.0009548580851796066,0.049474694938987804,252.0101561892515,388.90739596267554,1.714444295226274
0.000960046943788077,0.049743548709741944,252.32577658002907,388.90739596267554,1.714444295226274
0.0009619001075768165,0.04983956791358271,252.4383368277824,388.90739596267554,1.714444295226274
0.0009696833954895227,0.05024284856971395,252.91016929805156,388.90739596267554,1.714444295226274
0.0009722778247937578,0.05037727545509102,253.06711825985676,388.90739596267554,1.714444295226274
0.0009759841523712368,0.05056931386277255,253.29104802599235,388.90739596267554,1.714444295226274
0.0009822849092529513,0.05089577915583117,253.6709689904558,388.90739596267554,1.714444295226274
0.0009845087057994387,0.051011002200440095,253.8048316735059,388.90739596267554,1.714444295226274
0.000986732502345926,0.051126225245049006,253.9385764850622,388.90739596267554,1.714444295226274
0.000999334016109355,0.05177915583116624,254.69425499439595,388.90739596267554,1.714444295226274
0.0010000752816248506,0.051817563512702544,254.73859058397105,388.90739596267554,1.714444295226274
0.0010123061626305311,0.052451290258051605,255.4682875216459,388.90739596267554,1.714444295226274
0.00101786565399675,0.05273934786957392,255.7988304850634,388.90739596267554,1.714444295226274
0.0010234251453629683,0.05302740548109622,256.12867008919096,388.90739596267554,1.714444295226274
0.0010330615970644138,0.05352670534106821,256.6987414926046,388.90739596267554,1.714444295226274
0.0010382504556728845,0.053795559111822364,257.00484385209546,388.90739596267554,1.714444295226274
0.001044180579796851,0.05410282056411282,257.3539455081225,388.90739596267554,1.714444295226274
0.001048628172889826,0.05433326665333067,257.6152645483242,388.90739596267554,1.714444295226274
0.0010523345004673048,0.054525305061012205,257.8327003849336,388.90739596267554,1.714444295226274
0.0010567820935602796,0.05475575115023004,258.0932295477221,388.90739596267554,1.714444295226274
0.0010664185452617253,0.05525505101020205,258.65624693237277,388.90739596267554,1.714444295226274
0.0010753137314476748,0.055715943188637734,259.17419670958446,388.90739596267554,1.714444295226274
0.001081614488329389,0.05604240848169634,259.5400672897351,388.90739596267554,1.714444295226274
0.001086062081422364,0.05627285457091419,259.7978285910436,388.90739596267554,1.714444295226274
0.0011175658658309356,0.057905181036207246,261.6119952160963,388.90739596267554,1.714444295226274
0.0011246078882281459,0.058270054010802166,262.0147745021072,388.90739596267554,1.714444295226274
0.0011305380123521123,0.058577315463092625,262.35319471591066,388.90739596267554,1.714444295226274
0.0011401744640535576,0.059076615323064616,262.90165473007465,388.90739596267554,1.714444295226274
0.0011412863623268014,0.05913422684536908,262.96482203395414,388.90739596267554,1.714444295226274
0.0011549997743634738,0.05984476895379076,263.741922438253,388.90739596267554,1.714444295226274
0.001157594203667709,0.05997919583916783,263.88853577572536,388.90739596267554,1.714444295226274
0.0011642655933071712,0.060324864972994593,264.26495426308827,388.90739596267554,1.714444295226274
0.0011761258415551041,0.06093938787757551,264.93207220941974,388.90739596267554,1.714444295226274
0.0011853916604988018,0.061419483896779356,265.45143425645074,388.90739596267554,1.714444295226274
0.001195398744957995,0.061937987597519506,266.0105701293067,388.90739596267554,1.714444295226274
0.0012042939311439449,0.06239887977595519,266.506049114708,388.90739596267554,1.714444295226274
0.001210965320783407,0.06274454890978196,266.8767222343724,388.90739596267554,1.714444295226274
0.001215042281118634,0.06295579115823165,267.1028526638092,388.90739596267554,1.714444295226274
0.001218007343180617,0.06310942188437688,267.26712533573976,388.90739596267554,1.714444295226274
0.0012350564500370207,0.06399279855971195,268.2086841026408,388.90739596267554,1.714444295226274
0.00124580480001171,0.0645497099419884,268.7996710945542,388.90739596267554,1.714444295226274
0.001248399229315945,0.06468413682736547,268.94202479616206,388.90739596267554,1.714444295226274
0.0012502523931046845,0.06478015603120624,269.0436353813628,388.90739596267554,1.714444295226274
0.001256182517228651,0.0650874174834967,269.3683952425914,388.90739596267554,1.714444295226274
0.001260630110321626,0.06531786357271455,269.6115729034404,388.90739596267554,1.714444295226274
0.0012736022568428026,0.06598999799959993,270.31893716881694,388.90739596267554,1.714444295226274
0.0012769379516625336,0.0661628325665133,270.5003759757257,388.90739596267554,1.714444295226274
0.001280644279240013,0.06635487097419485,270.7017579939466,388.90739596267554,1.714444295226274
0.0012824974430287522,0.06645089017803561,270.8023637562079,388.90739596267554,1.714444295226274
0.0012884275671527186,0.06675815163032607,271.12392187167416,388.90739596267554,1.714444295226274
0.0012925045274879458,0.06696939387877576,271.3446583301834,388.90739596267554,1.714444295226274
0.0012973227533386684,0.06721904380876176,271.60517890545594,388.90739596267554,1.714444295226274
0.0013088123688288532,0.06781436287257452,272.2249021800887,388.90739596267554,1.714444295226274
0.0013121480636485844,0.0679871974394879,272.40442395965925,388.90739596267554,1.714444295226274
0.001314371860195072,0.06810242048409683,272.52400627518017,388.90739596267554,1.714444295226274
0.0013195607188035423,0.06837127425485097,272.8027252434855,388.90739596267554,1.714444295226274
0.0013240083118965173,0.06860172034406882,273.0412871815864,388.90739596267554,1.714444295226274
0.0013321622325669713,0.0690242048409682,273.4778405871815,388.90739596267554,1.714444295226274
0.0013358685601444502,0.06921624324864974,273.6759293328381,388.90739596267554,1.714444295226274
0.0013377217239331897,0.0693122624524905,273.77489331968906,388.90739596267554,1.714444295226274
0.0013488407066656269,0.06988837767553512,274.3675583109929,388.90739596267554,1.714444295226274
0.0013603303221558117,0.07048369673934787,274.97798055014124,388.90739596267554,1.714444295226274
0.001363295384217795,0.0706373274654931,275.13518205199347,388.90739596267554,1.714444295226274
0.001366260446279778,0.07079095819163833,275.29225026882153,388.90739596267554,1.714444295226274
0.0013703374066150052,0.07100220044008802,275.5080021753962,388.90739596267554,1.714444295226274
0.001378120694527711,0.07140548109621925,275.91919829271006,388.90739596267554,1.714444295226274
0.0013877571462291565,0.07190478095619124,276.4270455474738,388.90739596267554,1.714444295226274
0.0014281561168236778,0.07399799959991998,278.5412997921307,388.90739596267554,1.714444295226274
0.0014377925685251235,0.07449729945989199,279.0421562347307,388.90739596267554,1.714444295226274
0.0014674431891449557,0.07603360672134428,280.57510446589237,388.90739596267554,1.714444295226274
0.0014815272339393757,0.07676335267053411,281.2990188097998,388.90739596267554,1.714444295226274
0.0014907930528830734,0.07724344868973795,281.77381503410953,388.90739596267554,1.714444295226274
0.0014944993804605524,0.07743548709741949,281.963411103758,388.90739596267554,1.714444295226274
0.0014978350752802836,0.07760832166433287,282.13389083776275,388.90739596267554,1.714444295226274
0.0015030239338887541,0.07787717543508701,282.3987875239107,388.90739596267554,1.714444295226274
0.0015119191200747037,0.0783380676135227,282.852067862784,388.90739596267554,1.714444295226274
0.0015200730407451577,0.07876055211042209,283.2666620116238,388.90739596267554,1.714444295226274
0.001521926204533897,0.07885657131426285,283.3607668865958,388.90739596267554,1.714444295226274
0.0015241500010803846,0.07897179435887178,283.47363376821977,388.90739596267554,1.714444295226274
0.0015282269614156116,0.07918303660732147,283.6803897212705,388.90739596267554,1.714444295226274
0.0015323039217508385,0.07939427885577116,283.8869306706048,388.90739596267554,1.714444295226274
0.0015356396165705694,0.07956711342268454,284.0557593554075,388.90739596267554,1.714444295226274
0.0015393459441480487,0.07975915183036608,284.243179128781,388.90739596267554,1.714444295226274
0.0015430522717255278,0.07995119023804761,284.430422994719,388.90739596267554,1.714444295226274
0.001546387966545259,0.080124024804961,284.59879255845465,388.90739596267554,1.714444295226274
0.0015641783389171583,0.08104580916183238,285.49438265631323,388.90739596267554,1.714444295226274
0.0015656608699481497,0.08112262452490498,285.5688353752839,388.90739596267554,1.714444295226274
0.001575667954407343,0.08164112822564513,286.07067400596657,388.90739596267554,1.714444295226274
0.0015790036492270743,0.08181396279255852,286.23767712608816,388.90739596267554,1.714444295226274
0.0015864163043820322,0.08219803960792159,286.60830334826113,388.90739596267554,1.714444295226274
0.0015941995922947381,0.08260132026405281,286.99673472558027,388.90739596267554,1.714444295226274
0.001595311490567982,0.08265893178635728,287.0521644867457,388.90739596267554,1.714444295226274
0.001602353512965192,0.0830238047609522,287.4028703997263,388.90739596267554,1.714444295226274
0.0016082836370891584,0.08333106621324265,287.6977357157766,388.90739596267554,1.714444295226274
0.0016234795801568223,0.08411842368473695,288.4513991744467,388.90739596267554,1.714444295226274
0.001628668438765293,0.0843872774554911,288.7081169080118,388.90739596267554,1.714444295226274
0.0016327453991005201,0.08459851970394079,288.90959999428134,388.90739596267554,1.714444295226274
0.0016371929921934949,0.08482896579315864,289.12917608015454,388.90739596267554,1.714444295226274
0.0016457175456216966,0.08527065413082617,289.5493810888838,388.90739596267554,1.714444295226274
0.0016627666524781002,0.08615403080616124,290.38725311572864,388.90739596267554,1.714444295226274
0.0016709205731485538,0.08657651530306061,290.7867895382855,388.90739596267554,1.714444295226274
0.0016772213300302683,0.08690298059611923,291.09500165584996,388.90739596267554,1.714444295226274
0.0016905641093091926,0.08759431886377275,291.7461994904717,388.90739596267554,1.714444295226274
0.0016994592954951424,0.08805521104220844,292.17921815183166,388.90739596267554,1.714444295226274
0.0017116901765008232,0.08868893778755751,292.77317829701207,388.90739596267554,1.714444295226274
0.0017161377695937982,0.08891938387677537,292.9887531254288,388.90739596267554,1.714444295226274
0.0017183615661402853,0.08903460692138428,293.0964588233905,388.90739596267554,1.714444295226274
0.0017224385264755125,0.08924584916983397,293.2937781892499,388.90739596267554,1.714444295226274
0.0017257742212952436,0.08941868373674736,293.4550858593474,388.90739596267554,1.714444295226274
0.0017328162436924537,0.08978355671134228,293.79522550268945,388.90739596267554,1.714444295226274
0.0017405995316051596,0.0901868373674735,294.1705427335857,388.90739596267554,1.714444295226274
0.0017520891470953447,0.09078215643128626,294.72338841259887,388.90739596267554,1.714444295226274
0.0017606137005235466,0.0912238447689538,295.1326510220877,388.90739596267554,1.714444295226274
0.0017680263556785045,0.09160792158431687,295.48790377448097,388.90739596267554,1.714444295226274
0.0017706207849827397,0.09174234846969394,295.61210494336524,388.90739596267554,1.714444295226274
0.0017843341970194123,0.09245289057811563,296.2674215289134,388.90739596267554,1.714444295226274
0.0017939706487208576,0.09295219043808763,296.72673969714754,388.90739596267554,1.714444295226274
0.001795453179751849,0.09302900580116023,296.7973185347891,388.90739596267554,1.714444295226274
0.0017995301400870762,0.09324024804960993,296.9912932421994,388.90739596267554,1.714444295226274
0.001803977733180051,0.09347069413882778,297.2027066483639,388.90739596267554,1.714444295226274
0.001807313427999782,0.09364352870574115,297.36113332752325,388.90739596267554,1.714444295226274
0.001811761021092757,0.093873974794959,297.5721916230377,388.90739596267554,1.714444295226274
0.0018158379814279839,0.09408521704340869,297.76548428667763,388.90739596267554,1.714444295226274
0.0018206562072787067,0.09433486697339469,297.9937029954767,388.90739596267554,1.714444295226274
0.0018254744331294293,0.09458451690338068,298.2216862798259,388.90739596267554,1.714444295226274
0.0018358521503463706,0.09512222444488898,298.71193164514364,388.90739596267554,1.714444295226274
0.0018402997434393453,0.09535267053410683,298.9217058153425,388.90739596267554,1.714444295226274
0.001861055177873228,0.09642808561712343,299.8980495158924,388.90739596267554,1.714444295226274
0.0018640202399352111,0.09658171634326866,300.0371797409016,388.90739596267554,1.714444295226274
0.0018695797313014297,0.09686977395479096,300.29781649774986,388.90739596267554,1.714444295226274
0.0018710622623324214,0.09694658931786358,300.36726856127575,388.90739596267554,1.714444295226274
0.0018821812450648583,0.09752270454090818,300.8874766761719,388.90739596267554,1.714444295226274
0.0018929295950395474,0.09807961592318463,301.38920646057863,388.90739596267554,1.714444295226274
0.0018962652898592786,0.09825245049009802,301.544689630132,388.90739596267554,1.714444295226274
0.0018984890864057662,0.09836767353470695,301.6482858205603,388.90739596267554,1.714444295226274
0.0019088668036227072,0.09890538107621524,302.1311103444014,388.90739596267554,1.714444295226274
0.0019266571759946065,0.09982716543308662,302.9564345842507,388.90739596267554,1.714444295226274