File: datasets/aisi_316_L/data/M1/train_48.csv
Time(s),Strain(%),Stress(MPa),Temp(C),Log_SR(s-1)
0.0,0.0,0.0,237.0952833600327,-0.6977972913092101
5.983820225520078e-05,1.2e-05,2.1948823125,237.0952833600327,-0.6977972913092101
0.0001316440449614417,2.6399999999999998e-05,4.828741087499999,237.0952833600327,-0.6977972913092101
0.00021142831463504273,4.24e-05,7.7552508375,237.0952833600327,-0.6977972913092101
0.00029121258430864374,5.8399999999999997e-05,10.6817605875,237.0952833600327,-0.6977972913092101
0.0003031802247596839,6.08e-05,11.12073705,237.0952833600327,-0.6977972913092101
0.00037897528094960487,7.599999999999999e-05,13.900921312499998,237.0952833600327,-0.6977972913092101
0.0004348242697211256,8.719999999999999e-05,15.949478137499998,237.0952833600327,-0.6977972913092101
0.00047072719107424605,9.439999999999999e-05,17.266407524999998,237.0952833600327,-0.6977972913092101
0.0005185977528784066,0.000104,19.022313375,237.0952833600327,-0.6977972913092101
0.000538543820296807,0.000108,19.753940812499998,237.0952833600327,-0.6977972913092101
0.0006821555057092888,0.0001368,25.0216583625,237.0952833600327,-0.6977972913092101
0.0007021015731276891,0.0001408,25.7532858,237.0952833600327,-0.6977972913092101
0.0007260368540297693,0.0001456,26.631238725,237.0952833600327,-0.6977972913092101
0.0007579505618992097,0.00015199999999999998,27.801842624999995,237.0952833600327,-0.6977972913092101
0.0008497024720238509,0.0001704,31.167328837499998,237.0952833600327,-0.6977972913092101
0.0009015622473116917,0.0001808,33.069560175,237.0952833600327,-0.6977972913092101
0.0009574112360832125,0.000192,35.118117,237.0952833600327,-0.6977972913092101
0.0009693788765342524,0.00019439999999999998,35.5570934625,237.0952833600327,-0.6977972913092101
0.0009813465169852926,0.00019679999999999999,35.996069925,237.0952833600327,-0.6977972913092101
0.0010371955057568133,0.000208,38.04462675,237.0952833600327,-0.6977972913092101
0.0010611307866588938,0.0002128,38.922579675,237.0952833600327,-0.6977972913092101
0.0011050121349793743,0.0002216,40.5321600375,237.0952833600327,-0.6977972913092101
0.0011887856181366553,0.0002384,43.604995275,237.0952833600327,-0.6977972913092101
0.001236656179940816,0.000248,45.360901125000005,237.0952833600327,-0.6977972913092101
0.0012566022473592163,0.000252,46.0925285625,237.0952833600327,-0.6977972913092101
0.0014361168541248187,0.000288,52.677175500000004,237.0952833600327,-0.6977972913092101
0.0015079226968310593,0.0003024,55.311034275,237.0952833600327,-0.6977972913092101
0.0015597824721189,0.00031279999999999996,57.213265612499995,237.0952833600327,-0.6977972913092101
0.0017712107867539427,0.00035519999999999996,64.96851645,237.0952833600327,-0.6977972913092101
0.0018111029215907434,0.0003632,66.431771325,237.0952833600327,-0.6977972913092101
0.0018749303373296242,0.000376,68.77297912499999,237.0952833600327,-0.6977972913092101
0.0019108332586827447,0.0003832,70.0899085125,237.0952833600327,-0.6977972913092101
0.0019985959553237057,0.0004008,73.3090692375,237.0952833600327,-0.6977972913092101
0.0020664125845462665,0.0004144,75.796602525,237.0952833600327,-0.6977972913092101
0.002146196854219868,0.0004304,78.723112275,237.0952833600327,-0.6977972913092101
0.0022259811238934685,0.00044639999999999995,81.64962202499999,237.0952833600327,-0.6977972913092101
0.0023097546070507497,0.0004632,84.7224572625,237.0952833600327,-0.6977972913092101
0.00236161438233859,0.00047359999999999997,86.6246886,237.0952833600327,-0.6977972913092101
0.002485280000332672,0.0004984,91.16077871249999,237.0952833600327,-0.6977972913092101
0.0025770319104573133,0.0005168,94.52626492499999,237.0952833600327,-0.6977972913092101
0.0026129348318104334,0.0005239999999999999,95.84319431249999,237.0952833600327,-0.6977972913092101
0.0028084062925107563,0.0005632,103.0131432,237.0952833600327,-0.6977972913092101
0.0029280826970211576,0.0005872,107.402907825,237.0952833600327,-0.6977972913092101
0.00308765123636836,0.0006192,113.255927325,237.0952833600327,-0.6977972913092101
0.0031514786521072407,0.000632,115.597135125,237.0952833600327,-0.6977972913092101
0.0031993492139114014,0.0006416,117.353040975,237.0952833600327,-0.6977972913092101
0.003394820674611724,0.0006808,124.5229898625,237.0952833600327,-0.6977972913092101
0.003466626517317965,0.0006952,127.15684863749999,237.0952833600327,-0.6977972913092101
0.0035304539330568456,0.000708,129.4980564375,237.0952833600327,-0.6977972913092101
0.003574335281377326,0.0007168,131.1076368,237.0952833600327,-0.6977972913092101
0.0036222058431814867,0.0007264,132.86354265,237.0952833600327,-0.6977972913092101
0.0036501303375672473,0.000732,133.8878210625,237.0952833600327,-0.6977972913092101
0.0037099685398224477,0.000744,136.082703375,237.0952833600327,-0.6977972913092101
0.003965278202777971,0.0007951999999999999,145.447534575,237.0952833600327,-0.6977972913092101
0.004037084045484212,0.0008096,148.08139334999998,237.0952833600327,-0.6977972913092101
0.004224577079217175,0.0008472,154.9586912625,237.0952833600327,-0.6977972913092101
0.004244523146635575,0.0008512,155.6903187,237.0952833600327,-0.6977972913092101
0.004352231910694936,0.0008728,159.64110686249998,237.0952833600327,-0.6977972913092101
0.004400102472499097,0.0008824,161.3970127125,237.0952833600327,-0.6977972913092101
0.004432016180368537,0.0008887999999999999,162.5676166125,237.0952833600327,-0.6977972913092101
0.004463929888237977,0.0008952,163.7382205125,237.0952833600327,-0.6977972913092101
0.004591584719715739,0.0009207999999999999,168.42063611249998,237.0952833600327,-0.6977972913092101
0.0046992934837751,0.0009423999999999999,172.37142427499998,237.0952833600327,-0.6977972913092101
0.0047072719107424605,0.000944,172.66407525,237.0952833600327,-0.6977972913092101
0.004918700225377503,0.0009864,180.4193260875,237.0952833600327,-0.6977972913092101
0.004978538427632705,0.0009984,182.6142084,237.0952833600327,-0.6977972913092101
0.005034387416404226,0.0010096,184.66276522500002,237.0952833600327,-0.6977972913092101
0.005086247191692065,0.0010199999999999999,186.56499656249997,237.0952833600327,-0.6977972913092101
0.005241826517555588,0.0010512,192.27169057499998,237.0952833600327,-0.6977972913092101
0.005281718652392388,0.0010592,193.73494545,237.0952833600327,-0.6977972913092101
0.005305653933294469,0.001064,194.61289837500001,237.0952833600327,-0.6977972913092101
0.00548516854006007,0.0010999999999999998,195.73438013348445,237.0952833600327,-0.6977972913092101
0.005556974382766312,0.0011144,195.82217582722626,237.0952833600327,-0.6977972913092101
0.005652715506374633,0.0011336,195.9385515692963,237.0952833600327,-0.6977972913092101
0.0056926076412114335,0.0011416,195.9868142863862,237.0952833600327,-0.6977972913092101
0.005716542922113514,0.0011464,196.01570860744044,237.0952833600327,-0.6977972913092101
0.005772391910885034,0.0011576,196.0829458224635,237.0952833600327,-0.6977972913092101
0.005848186967074955,0.0011727999999999999,196.1737919260832,237.0952833600327,-0.6977972913092101
0.005955895731134317,0.0011944,196.30210305284962,237.0952833600327,-0.6977972913092101
0.006039669214291598,0.0012112,196.401275948845,237.0952833600327,-0.6977972913092101
0.0060835505626120785,0.00122,196.4530094713324,237.0952833600327,-0.6977972913092101
0.0061713132592530395,0.0012376,196.55604197298925,237.0952833600327,-0.6977972913092101
0.0062391298884756,0.0012511999999999998,196.6352670942612,237.0952833600327,-0.6977972913092101
0.006302957304214481,0.001264,196.70952567306222,237.0952833600327,-0.6977972913092101
0.0064186444952412025,0.0012871999999999998,196.84337611340825,237.0952833600327,-0.6977972913092101
0.0064744934840127236,0.0012984,196.90765654270274,237.0952833600327,-0.6977972913092101
0.006558266967170004,0.0013151999999999999,197.00367319889804,237.0952833600327,-0.6977972913092101
0.006654008090778325,0.0013344,197.1128227359697,237.0952833600327,-0.6977972913092101
0.006685921798647766,0.0013407999999999998,197.14906957929944,237.0952833600327,-0.6977972913092101
0.006713846293033527,0.0013464,197.1807302516111,237.0952833600327,-0.6977972913092101
0.006817565843609207,0.0013671999999999998,197.29788009121953,237.0952833600327,-0.6977972913092101
0.006833522697543928,0.0013704,197.31584126301425,237.0952833600327,-0.6977972913092101
0.006921285394184889,0.001388,197.41433687249204,237.0952833600327,-0.6977972913092101
0.00696516674250537,0.0013968,197.4634019322145,237.0952833600327,-0.6977972913092101
0.007080853933532092,0.00142,197.59218083896684,237.0952833600327,-0.6977972913092101
0.007112767641401532,0.0014264,197.62756131657235,237.0952833600327,-0.6977972913092101
0.007152659776238333,0.0014344,197.6716999722498,237.0952833600327,-0.6977972913092101
0.007168616630173053,0.0014376,197.68932853999746,237.0952833600327,-0.6977972913092101
0.007208508765009853,0.0014456,197.73333313830284,237.0952833600327,-0.6977972913092101
0.007272336180748734,0.0014583999999999999,197.8035434635875,237.0952833600327,-0.6977972913092101
0.0074319047200959365,0.0014904,197.97802595636057,237.0952833600327,-0.6977972913092101
0.007487753708867456,0.0015015999999999999,198.03874885358758,237.0952833600327,-0.6977972913092101
0.007603440899894179,0.0015248,198.16397296384574,237.0952833600327,-0.6977972913092101
0.007655300675182019,0.0015352,198.21986647188572,237.0952833600327,-0.6977972913092101
0.00773508494485562,0.0015512,198.30556899482062,237.0952833600327,-0.6977972913092101
0.007886675057235462,0.0015815999999999998,198.46745990660426,237.0952833600327,-0.6977972913092101
0.008018319102196903,0.0016079999999999998,198.60706730050939,237.0952833600327,-0.6977972913092101
0.008126027866256266,0.0016296,198.72062782374752,237.0952833600327,-0.6977972913092101
0.008273628765152427,0.0016592,198.87529893672135,237.0952833600327,-0.6977972913092101
0.008293574832570826,0.0016631999999999999,198.89611759477614,237.0952833600327,-0.6977972913092101
0.008321499326956588,0.0016688,198.92523094082287,237.0952833600327,-0.6977972913092101
0.00850500314720587,0.0017055999999999998,199.11560806325633,237.0952833600327,-0.6977972913092101
0.00859276584384683,0.0017231999999999998,199.20609110538376,237.0952833600327,-0.6977972913092101
0.008696485394422512,0.0017439999999999999,199.31256224690023,237.0952833600327,-0.6977972913092101
0.008768291237128753,0.0017584,199.38598310348036,237.0952833600327,-0.6977972913092101
0.008852064720286034,0.0017752,199.47134505198082,237.0952833600327,-0.6977972913092101
0.008939827416926996,0.0017928,199.56043462235266,237.0952833600327,-0.6977972913092101
0.008987697978731156,0.0018024,199.6088851435416,237.0952833600327,-0.6977972913092101
0.009027590113567957,0.0018104,199.6491837457326,237.0952833600327,-0.6977972913092101
0.009087428315823157,0.0018223999999999998,199.70950167523762,237.0952833600327,-0.6977972913092101
0.009135298877627318,0.0018319999999999999,199.75764456593998,237.0952833600327,-0.6977972913092101
0.0092789105630398,0.0018608,199.90148634614303,237.0952833600327,-0.6977972913092101
0.009430500675419642,0.0018912,200.05238056037606,237.0952833600327,-0.6977972913092101
0.009486349664191162,0.0019023999999999998,200.10773432940243,237.0952833600327,-0.6977972913092101
0.009629961349603644,0.0019311999999999999,200.249492135607,237.0952833600327,-0.6977972913092101
0.009649907417022045,0.0019352,200.2691153125597,237.0952833600327,-0.6977972913092101
0.009721713259728286,0.0019496,200.3396281488055,237.0952833600327,-0.6977972913092101
0.009829422023787646,0.0019711999999999998,200.44501774609003,237.0952833600327,-0.6977972913092101
0.009921173933912288,0.0019896,200.53443931090817,237.0952833600327,-0.6977972913092101
0.00998101213616749,0.0020016,200.59258401586618,237.0952833600327,-0.6977972913092101
0.010004947417069568,0.0020063999999999998,200.61580381280723,237.0952833600327,-0.6977972913092101
0.010072764046292131,0.00202,200.68147588046742,237.0952833600327,-0.6977972913092101
0.01009271011371053,0.0020239999999999998,200.70075834824334,237.0952833600327,-0.6977972913092101
0.01012063460809629,0.0020296,200.7277288537282,237.0952833600327,-0.6977972913092101
0.010228343372155653,0.0020512,200.8314872167245,237.0952833600327,-0.6977972913092101
0.010256267866541413,0.0020568,200.8583178647547,237.0952833600327,-0.6977972913092101
0.010375944271051813,0.0020808,200.9729851623654,237.0952833600327,-0.6977972913092101
0.010423814832855975,0.0020904,201.01870751589456,237.0952833600327,-0.6977972913092101
0.010507588316013255,0.0021072,201.0985250730915,237.0952833600327,-0.6977972913092101
0.010567426518268455,0.0021192,201.15538574156776,237.0952833600327,-0.6977972913092101
0.010675135282327818,0.0021408,201.25741951500748,237.0952833600327,-0.6977972913092101
0.010715027417164617,0.0021487999999999998,201.29510781122215,237.0952833600327,-0.6977972913092101
0.010938423372250702,0.0021936,201.505159651287,237.0952833600327,-0.6977972913092101
0.01098629393405486,0.0022031999999999998,201.5499523299514,237.0952833600327,-0.6977972913092101
0.011090013484630543,0.002224,201.64674283759467,237.0952833600327,-0.6977972913092101
0.011141873259918385,0.0022344,201.69500565412318,237.0952833600327,-0.6977972913092101
0.011193733035206224,0.0022448,201.7431809405483,237.0952833600327,-0.6977972913092101
0.011261549664428785,0.0022584,201.80604825608867,237.0952833600327,-0.6977972913092101
0.011349312361069746,0.002276,201.88718721998242,237.0952833600327,-0.6977972913092101
0.011441064271194387,0.0022944,201.97175311477804,237.0952833600327,-0.6977972913092101
0.01156871910267215,0.00232,202.08897134546612,237.0952833600327,-0.6977972913092101
0.01167642786673151,0.0023416,202.18748237853728,237.0952833600327,-0.6977972913092101
0.011863920900464472,0.0023791999999999997,202.35812329753688,237.0952833600327,-0.6977972913092101
0.011899823821817593,0.0023864,202.3906788941685,237.0952833600327,-0.6977972913092101
0.012139176630838395,0.0024343999999999998,202.6067454776784,237.0952833600327,-0.6977972913092101
0.012290766743218239,0.0024648,202.74272866310227,237.0952833600327,-0.6977972913092101
0.01243038921514704,0.0024928,202.86739877131163,237.0952833600327,-0.6977972913092101
0.012458313709532801,0.0024984,202.89226712691584,237.0952833600327,-0.6977972913092101
0.012474270563467522,0.0025016,202.90646785542242,237.0952833600327,-0.6977972913092101
0.012621871462363684,0.0025312,203.03749045988462,237.0952833600327,-0.6977972913092101
0.012657774383716801,0.0025383999999999997,203.06927030430094,237.0952833600327,-0.6977972913092101
0.012781440001710885,0.0025632,203.17846613144891,237.0952833600327,-0.6977972913092101
0.012829310563515047,0.0025728,203.22062476694646,237.0952833600327,-0.6977972913092101
0.012877181125319206,0.0025824,203.2627220966385,237.0952833600327,-0.6977972913092101
0.012948986968025447,0.0025968,203.32575383449213,237.0952833600327,-0.6977972913092101
0.012968933035443848,0.0026008,203.34323843981284,237.0952833600327,-0.6977972913092101
0.013044728091633769,0.002616,203.40958451245595,237.0952833600327,-0.6977972913092101
0.013100577080405289,0.0026271999999999997,203.45837492925824,237.0952833600327,-0.6977972913092101
0.01322025348491569,0.0026512,203.56265350442658,237.0952833600327,-0.6977972913092101
0.013347908316393453,0.0026768,203.673479019581,237.0952833600327,-0.6977972913092101
0.013395778878197612,0.0026864,203.71493192098998,237.0952833600327,-0.6977972913092101
0.013487530788322254,0.0027048,203.79422218958192,237.0952833600327,-0.6977972913092101
0.013543379777093774,0.0027159999999999997,203.84238284650047,237.0952833600327,-0.6977972913092101
0.013583271911930575,0.002724,203.87673590688766,237.0952833600327,-0.6977972913092101
0.013623164046767377,0.002732,203.91104964261476,237.0952833600327,-0.6977972913092101
0.013754808091728818,0.0027584,204.02400795919144,237.0952833600327,-0.6977972913092101
0.013814646293984018,0.0027703999999999997,204.0752131889956,237.0952833600327,-0.6977972913092101
0.01389044135017394,0.0027856,204.1399491412846,237.0952833600327,-0.6977972913092101
0.01399416090074962,0.0028063999999999997,204.22831237813637,237.0952833600327,-0.6977972913092101
0.01403006382210274,0.0028136,204.25884009531813,237.0952833600327,-0.6977972913092101
0.014101869664808982,0.002828,204.3198042822735,237.0952833600327,-0.6977972913092101
0.014281384271574583,0.002864,204.4716874668643,237.0952833600327,-0.6977972913092101
0.014393082249117626,0.0028864,204.56581686980138,237.0952833600327,-0.6977972913092101
0.014492812586209627,0.0029064,204.64962050675837,237.0952833600327,-0.6977972913092101
0.014588553709817948,0.0029256,204.7298606610046,237.0952833600327,-0.6977972913092101
0.014724186968263069,0.0029527999999999998,204.8431835436881,237.0952833600327,-0.6977972913092101
0.014823917305355072,0.0029728,204.92624963309046,237.0952833600327,-0.6977972913092101
0.014891733934577631,0.0029863999999999997,204.9826101204252,237.0952833600327,-0.6977972913092101
0.014939604496381794,0.002996,205.02233374248704,237.0952833600327,-0.6977972913092101
0.015143054384049474,0.0030367999999999997,205.19060831960962,237.0952833600327,-0.6977972913092101
0.015278687642494597,0.003064,205.30230178577978,237.0952833600327,-0.6977972913092101
0.015298633709912997,0.003068,205.3186946221118,237.0952833600327,-0.6977972913092101
0.015414320900939717,0.0030911999999999997,205.41360921600398,237.0952833600327,-0.6977972913092101
0.01554995415938484,0.0031184,205.52453532385942,237.0952833600327,-0.6977972913092101
0.01560580314815636,0.0031295999999999997,205.57010102763422,237.0952833600327,-0.6977972913092101
0.015749414833568842,0.0031584,205.68697891553404,237.0952833600327,-0.6977972913092101
0.015813242249307725,0.0031712,205.7387911495474,237.0952833600327,-0.6977972913092101
0.015936907867301807,0.003196,205.83894584073028,237.0952833600327,-0.6977972913092101
0.015976800002138605,0.003204,205.87118908922147,237.0952833600327,-0.6977972913092101
0.015988767642589646,0.0032064,205.88085593919334,237.0952833600327,-0.6977972913092101
0.01608051955271429,0.0032248,205.9548749351843,237.0952833600327,-0.6977972913092101
0.016132379328002128,0.0032351999999999997,205.99663889707696,237.0952833600327,-0.6977972913092101
0.016355775283088212,0.00328,206.1759499157862,237.0952833600327,-0.6977972913092101
0.016411624271859732,0.0032911999999999998,206.22062811303493,237.0952833600327,-0.6977972913092101
0.016515343822435413,0.003312,206.3034449081687,237.0952833600327,-0.6977972913092101
0.016551246743788533,0.0033192,206.33206496851489,237.0952833600327,-0.6977972913092101
0.016646987867396854,0.0033384,206.40826700615185,237.0952833600327,-0.6977972913092101
0.016678901575266296,0.0033447999999999998,206.433629678032,237.0952833600327,-0.6977972913092101
0.016714804496619416,0.003352,206.4621400717863,237.0952833600327,-0.6977972913092101
0.016798577979776696,0.0033688,206.5285716055941,237.0952833600327,-0.6977972913092101
0.016810545620227737,0.0033712,206.53805126685538,237.0952833600327,-0.6977972913092101
0.01694617887867286,0.0033983999999999998,206.6453041303975,237.0952833600327,-0.6977972913092101
0.0170179847213791,0.0034127999999999997,206.701949495783,237.0952833600327,-0.6977972913092101
0.017033941575313818,0.0034159999999999998,206.71452468722396,237.0952833600327,-0.6977972913092101
0.01715361797982422,0.00344,206.80869262048714,237.0952833600327,-0.6977972913092101
0.01720547775511206,0.0034503999999999997,206.84941911508471,237.0952833600327,-0.6977972913092101
0.017329143373106145,0.0034752,206.94634342733858,237.0952833600327,-0.6977972913092101
0.017396960002328703,0.0034888,206.9993809307253,237.0952833600327,-0.6977972913092101
0.017508657979871747,0.0035112,207.08656138272977,237.0952833600327,-0.6977972913092101
0.017568496182126945,0.0035231999999999998,207.13317595876504,237.0952833600327,-0.6977972913092101
0.01778391371024567,0.0035664,207.30047816182378,237.0952833600327,-0.6977972913092101
0.01783577348553351,0.0035767999999999998,207.34063635443766,237.0952833600327,-0.6977972913092101
0.01785173033946823,0.00358,207.35298355647262,237.0952833600327,-0.6977972913092101
0.01794348224959287,0.0035984,207.4238966166523,237.0952833600327,-0.6977972913092101
0.018039223373201192,0.0036176,207.4977422456024,237.0952833600327,-0.6977972913092101
0.018091083148489034,0.0036279999999999997,207.53767813433285,237.0952833600327,-0.6977972913092101
0.018218737979966794,0.0036536,207.63579212106842,237.0952833600327,-0.6977972913092101
0.018382295732797677,0.0036864,207.76110972879476,237.0952833600327,-0.6977972913092101
0.01849399371034072,0.0037088,207.84644269456172,237.0952833600327,-0.6977972913092101
0.0185378750586612,0.0037175999999999997,207.8799113378252,237.0952833600327,-0.6977972913092101
0.018605691687883757,0.0037311999999999996,207.93157489541466,237.0952833600327,-0.6977972913092101
0.01870542202497576,0.0037511999999999997,208.00741750164312,237.0952833600327,-0.6977972913092101
0.018765260227230962,0.0037632,208.0528473719839,237.0952833600327,-0.6977972913092101
0.018801163148584082,0.0037703999999999997,208.08007817613947,237.0952833600327,-0.6977972913092101
0.018833076856453523,0.0037768,208.10426631477208,237.0952833600327,-0.6977972913092101
0.01889291505870872,0.0037887999999999997,208.1495760328495,237.0952833600327,-0.6977972913092101
0.018976688541866005,0.0038055999999999997,208.21291572571127,237.0952833600327,-0.6977972913092101
0.019136257081213207,0.0038376,208.33326189215296,237.0952833600327,-0.6977972913092101
0.019148224721664248,0.0038399999999999997,208.3422720466832,237.0952833600327,-0.6977972913092101
0.01922003056437049,0.0038544,208.39628692537468,237.0952833600327,-0.6977972913092101
0.01929981483404409,0.0038704,208.45621123752755,237.0952833600327,-0.6977972913092101
0.01940353438461977,0.0038912,208.5339686066874,237.0952833600327,-0.6977972913092101
0.01943145887900553,0.0038967999999999997,208.55487556539208,237.0952833600327,-0.6977972913092101
0.01947932944080969,0.0039064,208.59068882544972,237.0952833600327,-0.6977972913092101
0.019531189216097533,0.0039168,208.6294478118881,237.0952833600327,-0.6977972913092101
0.019614962699254813,0.0039336,208.69197380476302,237.0952833600327,-0.6977972913092101
0.019762563598150977,0.0039632,208.80188584007175,237.0952833600327,-0.6977972913092101
0.019830380227373535,0.0039768,208.85227857850896,237.0952833600327,-0.6977972913092101
0.02195703320733279,0.0044032806561312265,210.40000143150291,237.0952833600327,-0.6977972913092101
0.023393437342284603,0.004691338267653531,211.41240043315983,237.0952833600327,-0.6977972913092101
0.02406375927192878,0.0048257651530306065,211.87652657377276,237.0952833600327,-0.6977972913092101
0.02578744423387095,0.005171434286857372,213.04741066627008,237.0952833600327,-0.6977972913092101
0.02904329360642838,0.005824364872974595,215.1789140378452,237.0952833600327,-0.6977972913092101
0.029617855260409106,0.005939587917583517,215.54517131841374,237.0952833600327,-0.6977972913092101
0.031724581325005094,0.006362072414482897,216.8650382705978,237.0952833600327,-0.6977972913092101
0.03354402656261072,0.006726945389077816,217.97763396906575,237.0952833600327,-0.6977972913092101
0.03517195124888944,0.007053410682136428,218.95331172771134,237.0952833600327,-0.6977972913092101
0.0356507526272067,0.007149429885977195,219.2369027598412,237.0952833600327,-0.6977972913092101
0.037182917037821964,0.007456691338267653,220.13457080707008,237.0952833600327,-0.6977972913092101
0.04024724585905249,0.00807121424284857,221.8877425938815,237.0952833600327,-0.6977972913092101
0.041109088340023574,0.008244048809761952,222.3713380925598,237.0952833600327,-0.6977972913092101
0.045992862398859725,0.009223444688937788,225.04047451727598,237.0952833600327,-0.6977972913092101
0.048386869290446076,0.009703540708141629,226.30827386813385,237.0952833600327,-0.6977972913092101
0.05097239673335933,0.010222044408881775,227.6503187693602,237.0952833600327,-0.6977972913092101
0.055377369413878205,0.011105421084216843,229.87714286437736,237.0952833600327,-0.6977972913092101
0.05643073244617621,0.011316663332666534,230.3992739650234,237.0952833600327,-0.6977972913092101
0.05738833520281075,0.01150870174034807,230.87064933907396,237.0952833600327,-0.6977972913092101
0.05939930099174327,0.011911982396479295,231.85066749836116,237.0952833600327,-0.6977972913092101
0.060069622921387456,0.01204640928185637,232.17445331138177,237.0952833600327,-0.6977972913092101
0.06188906815899308,0.01241128225645129,233.04627432387198,237.0952833600327,-0.6977972913092101
0.06428307505057942,0.012891378275655131,234.17832625921554,237.0952833600327,-0.6977972913092101
0.06686860249349269,0.013409881976395279,235.38262764559013,237.0952833600327,-0.6977972913092101
0.06763468469880031,0.013563512702540508,235.73595185940394,237.0952833600327,-0.6977972913092101
0.06868804773109831,0.013774754950990198,236.2192346935403,237.0952833600327,-0.6977972913092101
0.07232693820630956,0.014504500900180036,237.86695786368924,237.0952833600327,-0.6977972913092101
0.07405062316825173,0.014850170034006802,238.6361429588863,237.0952833600327,-0.6977972913092101
0.07644463005983808,0.015330266053210643,239.69297024508379,237.0952833600327,-0.6977972913092101
0.07778527391912643,0.015599119823964794,240.27915325009593,237.0952833600327,-0.6977972913092101
0.07950895888106861,0.01594478895779156,241.02705955989768,237.0952833600327,-0.6977972913092101
0.08132840411867423,0.016309661932386477,241.8096881086313,237.0952833600327,-0.6977972913092101
0.0821902465996453,0.016482496499299858,242.1780208507475,237.0952833600327,-0.6977972913092101
0.08362665073459712,0.016770554110822164,242.7885788834632,237.0952833600327,-0.6977972913092101
0.08697826038281802,0.017442688537707543,244.19752526423258,237.0952833600327,-0.6977972913092101
0.08841466451776982,0.017730746149229846,244.7948591538687,237.0952833600327,-0.6977972913092101
0.09147899333900035,0.018345269053810762,246.056666798455,237.0952833600327,-0.6977972913092101
0.09243659609563488,0.0185373074614923,246.4475867205975,237.0952833600327,-0.6977972913092101
0.09521364408987504,0.019094218843768752,247.57242064359576,237.0952833600327,-0.6977972913092101
0.09636276739783649,0.019324664932986596,248.0341178388719,237.0952833600327,-0.6977972913092101
0.1000974181487112,0.02007361472294459,249.52001819139585,237.0952833600327,-0.6977972913092101
0.10373630862392245,0.020803360672134428,250.94715766212923,237.0952833600327,-0.6977972913092101
0.10881160323408551,0.02182116423284657,252.90545236941142,237.0952833600327,-0.6977972913092101
0.1098649662663835,0.02203240648129626,253.30739001940154,237.0952833600327,-0.6977972913092101
0.1111098498500084,0.022282056411282256,253.78047469973328,237.0952833600327,-0.6977972913092101
0.11158865122832567,0.022378075615123026,253.961879348712,237.0952833600327,-0.6977972913092101
0.11398265811991201,0.022858171634326865,254.86438866722534,237.0952833600327,-0.6977972913092101
0.11675970611415219,0.023415083016603323,255.90208908517974,237.0952833600327,-0.6977972913092101
0.11752578831945983,0.02356871374274855,256.18665158808017,237.0952833600327,-0.6977972913092101
0.1196325143840558,0.02399119823964793,256.965492575919,237.0952833600327,-0.6977972913092101
0.1246120487185554,0.024989797959591917,258.7854277314838,237.0952833600327,-0.6977972913092101
0.12614421312917065,0.025297059411882376,259.33967201493357,237.0952833600327,-0.6977972913092101
0.12738909671279558,0.025546709341868375,259.78806479379637,237.0952833600327,-0.6977972913092101
0.13035766525836265,0.026142028405681136,260.85046835009354,237.0952833600327,-0.6977972913092101
0.1318898296689779,0.026449289857971594,261.39511127693675,237.0952833600327,-0.6977972913092101
0.13323047352826625,0.026718143628725745,261.8696528281285,237.0952833600327,-0.6977972913092101
0.13533719959286225,0.027140628125625125,262.61161559120916,237.0952833600327,-0.6977972913092101
0.1366778434521506,0.027409481896379276,263.08142933885864,237.0952833600327,-0.6977972913092101
0.13811424758710242,0.027697539507901582,263.5828112410801,237.0952833600327,-0.6977972913092101
0.14050825447868875,0.02817763552710542,264.41395196854154,237.0952833600327,-0.6977972913092101
0.14137009695965985,0.028350470094018806,264.71180825874734,237.0952833600327,-0.6977972913092101
0.14433866550522692,0.028945789157831567,265.7323804098894,237.0952833600327,-0.6977972913092101
0.14558354908885182,0.029195439087817562,266.15792224790664,237.0952833600327,-0.6977972913092101
0.14692419294814016,0.029464292858571713,266.61461409560184,237.0952833600327,-0.6977972913092101
0.14740299432645745,0.029560312062412483,266.7773240905754,237.0952833600327,-0.6977972913092101
0.1487436381857458,0.029829165833166634,267.23181914318315,237.0952833600327,-0.6977972913092101
0.15027580259636106,0.030136427285457092,267.74929037280197,237.0952833600327,-0.6977972913092101
0.1520952478339667,0.03050130026005201,268.36112254801964,237.0952833600327,-0.6977972913092101
0.15391469307157232,0.03086617323464693,268.9701068547516,237.0952833600327,-0.6977972913092101
0.15535109720652412,0.031154230846169233,269.4489029974583,237.0952833600327,-0.6977972913092101
0.15726630271979317,0.0315383076615323,270.0846207113054,237.0952833600327,-0.6977972913092101
0.1602348712653603,0.032133626725345074,271.06404848465826,237.0952833600327,-0.6977972913092101
0.1613839945733217,0.03236407281456291,271.44127874855155,237.0952833600327,-0.6977972913092101
0.16320343981092733,0.03272894578915783,272.03642464212675,237.0952833600327,-0.6977972913092101
0.16396952201623496,0.03288257651530306,272.2862376138494,237.0952833600327,-0.6977972913092101
0.16531016587552333,0.033151430286057215,272.72231777619896,237.0952833600327,-0.6977972913092101
0.1686617755237442,0.03382356471294259,273.8065269444358,237.0952833600327,-0.6977972913092101
0.17325826875559,0.03474534906981396,275.2798762471907,237.0952833600327,-0.6977972913092101
0.17517347426885907,0.035129425885177035,275.88926333061954,237.0952833600327,-0.6977972913092101
0.17574803592283983,0.03524464892978596,276.07157204619716,237.0952833600327,-0.6977972913092101
0.17670563867947434,0.03543668733746749,276.3749042110989,237.0952833600327,-0.6977972913092101
0.1783335633657531,0.03576315263052611,276.8891017073626,237.0952833600327,-0.6977972913092101
0.17852508391707997,0.035801560312062414,276.94947494285805,237.0952833600327,-0.6977972913092101
0.17881236474407033,0.035859171834366876,277.0399874561426,237.0952833600327,-0.6977972913092101
0.18082333053300287,0.0362624524904981,277.67199462569886,237.0952833600327,-0.6977972913092101
0.1838876593542334,0.03687697539507902,278.62980749635943,237.0952833600327,-0.6977972913092101
0.18561134431617554,0.03722264452890578,279.1658412710216,237.0952833600327,-0.6977972913092101
0.19039935809934824,0.03818283656731346,280.6447325855575,237.0952833600327,-0.6977972913092101
0.1915484814073097,0.03841328265653131,280.9974996169512,237.0952833600327,-0.6977972913092101
0.19308064581792497,0.03872054410882177,281.4665744481574,237.0952833600327,-0.6977972913092101
0.19413400885022297,0.03893178635727146,281.788221630255,237.0952833600327,-0.6977972913092101
0.1950916116068575,0.03912382476495299,282.0800380034632,237.0952833600327,-0.6977972913092101
0.19557041298517477,0.03921984396879376,282.225736667102,237.0952833600327,-0.6977972913092101
0.19767713904977077,0.03964232846569314,282.86516522385307,237.0952833600327,-0.6977972913092101
0.19806018015242455,0.03971914382876575,282.98113885813467,237.0952833600327,-0.6977972913092101
0.19892202263339565,0.03989197839567914,283.2417601910485,237.0952833600327,-0.6977972913092101
0.1994008240117129,0.0399879975995199,283.3863595268683,237.0952833600327,-0.6977972913092101
0.19978386511436677,0.040064812962592525,283.5019415222573,237.0952833600327,-0.6977972913092101
0.20141178980064545,0.04039127825565113,283.99220395177764,237.0952833600327,-0.6977972913092101
0.2016990706276358,0.04044888977795559,284.07856018525206,237.0952833600327,-0.6977972913092101
0.20457187889753944,0.0410250050010002,284.9395004876351,237.0952833600327,-0.6977972913092101
0.2071574063404527,0.04154350870174035,285.7103235457709,237.0952833600327,-0.6977972913092101
0.20916837212938524,0.04194678935787158,286.30726150138423,237.0952833600327,-0.6977972913092101
0.21022173516168324,0.04215803160632127,286.61904980095613,237.0952833600327,-0.6977972913092101
0.21328606398291378,0.042772554510902186,287.5226244828097,237.0952833600327,-0.6977972913092101
0.21759527638776918,0.0436367273454691,288.78475687320844,237.0952833600327,-0.6977972913092101
0.22046808465767276,0.0442128425685137,289.62076694755433,237.0952833600327,-0.6977972913092101
0.22190448879262462,0.04450090018003601,290.0371780009272,237.0952833600327,-0.6977972913092101
0.2243942559598744,0.045000200040008,290.7564754687088,237.0952833600327,-0.6977972913092101
0.22554337926783588,0.04523064612922585,291.0874084626455,237.0952833600327,-0.6977972913092101
0.2287992286403933,0.04588357671534307,292.0214998158299,237.0952833600327,-0.6977972913092101
0.23138475608330655,0.04640208041608322,292.7595904414184,237.0952833600327,-0.6977972913092101
0.23425756435321013,0.04697819563912782,293.575928917866,237.0952833600327,-0.6977972913092101
0.23885405758505593,0.047899979995999195,294.8739958977031,237.0952833600327,-0.6977972913092101
0.2400031808930174,0.048130426085217046,295.1969859015517,237.0952833600327,-0.6977972913092101
0.24278022888725756,0.0486873374674935,295.9750651921105,237.0952833600327,-0.6977972913092101
0.24325903026557483,0.048783356671334266,296.1088652149509,237.0952833600327,-0.6977972913092101
0.2446954344005266,0.049071414282856565,296.50965038691413,237.0952833600327,-0.6977972913092101
0.2492919276323724,0.04999319863972794,297.78604049444783,237.0952833600327,-0.6977972913092101
0.25254777700492986,0.050646129225845174,298.68460277299624,237.0952833600327,-0.6977972913092101
0.25427146196687206,0.050991798359671936,299.1584826037248,237.0952833600327,-0.6977972913092101
0.2546545030695258,0.051068613722744544,299.26361890342696,237.0952833600327,-0.6977972913092101
0.2559951469288142,0.0513374674934987,299.63111124489467,237.0952833600327,-0.6977972913092101
0.25704850996111217,0.05154870974194839,299.91932893718354,237.0952833600327,-0.6977972913092101
0.26087892098765036,0.052316863372674535,300.96353265021804,237.0952833600327,-0.6977972913092101
0.26250684567392907,0.05264332866573315,301.405506657106,237.0952833600327,-0.6977972913092101
0.2636559689818905,0.05287377475495099,301.71684495418657,237.0952833600327,-0.6977972913092101
0.264613571738525,0.05306581316263252,301.9758894853852,237.0952833600327,-0.6977972913092101
0.26643301697613064,0.05343068613722744,302.46706907302183,237.0952833600327,-0.6977972913092101
0.2672948594571018,0.05360352070414083,302.6992763511296,237.0952833600327,-0.6977972913092101
0.26834822248939977,0.05381476295259052,302.9826890877144,237.0952833600327,-0.6977972913092101
0.26959310607302467,0.05406441288257652,303.31707264898006,237.0952833600327,-0.6977972913092101
0.2705507088296592,0.05425645129025805,303.57388116790395,237.0952833600327,-0.6977972913092101
0.27294471572124557,0.0547365473094619,304.2143564058997,237.0952833600327,-0.6977972913092101
0.2739023184778801,0.05492858571714343,304.4699326045105,237.0952833600327,-0.6977972913092101
0.27897761308804314,0.05594638927785557,305.8187126301022,237.0952833600327,-0.6977972913092101
0.28424442824953305,0.057002600520104016,307.2083101555708,237.0952833600327,-0.6977972913092101
0.28443594880086004,0.057041008201640334,307.25865086797063,237.0952833600327,-0.6977972913092101
0.28884092148137885,0.05792438487697539,308.4128639607982,237.0952833600327,-0.6977972913092101
0.2908518872703114,0.058327665533106615,308.9375029380022,237.0952833600327,-0.6977972913092101
0.2912349283729652,0.05840448089617924,309.0372735767522,237.0952833600327,-0.6977972913092101
0.2932458941618978,0.05880776155231046,309.5602321982967,237.0952833600327,-0.6977972913092101
0.29477805857251305,0.05911502300460092,309.9577386337836,237.0952833600327,-0.6977972913092101
0.295831421604811,0.05932626525305061,310.23055701038754,237.0952833600327,-0.6977972913092101
0.2978423873937436,0.059729545909181836,310.75034236620075,237.0952833600327,-0.6977972913092101
0.2994703120800223,0.06005601120224045,311.17011923400815,237.0952833600327,-0.6977972913092101
0.30100247649063755,0.06036327265453091,311.564391120276,237.0952833600327,-0.6977972913092101
0.30272616145257975,0.06070894178835767,312.00701261821365,237.0952833600327,-0.6977972913092101
0.3033007231065605,0.0608241648329666,312.154334555091,237.0952833600327,-0.6977972913092101
0.3051201683441661,0.06118903780756152,312.6201375939855,237.0952833600327,-0.6977972913092101
0.3078972163384063,0.06174594918983797,313.32901704372756,237.0952833600327,-0.6977972913092101
0.3083760177167235,0.06184196839367874,313.45098518640606,237.0952833600327,-0.6977972913092101
0.30933362047335805,0.06203400680136027,313.6947001297632,237.0952833600327,-0.6977972913092101
0.3117276273649444,0.06251410282056412,314.30270370791857,237.0952833600327,-0.6977972913092101
0.3128767506729058,0.06274454890978196,314.5938983576752,237.0952833600327,-0.6977972913092101
0.3141216342565307,0.06299419883976795,314.90888894345505,237.0952833600327,-0.6977972913092101
0.3154622781158191,0.0632630526105221,315.2475656070366,237.0952833600327,-0.6977972913092101
0.3191011685910304,0.06399279855971195,316.1640131023937,237.0952833600327,-0.6977972913092101
0.3223570179635878,0.06464572914582917,316.98054328407346,237.0952833600327,-0.6977972913092101
0.3232188604445589,0.06481856371274256,317.1961444505096,237.0952833600327,-0.6977972913092101
0.3252298262334914,0.06522184436887378,317.69834380944786,237.0952833600327,-0.6977972913092101
0.3266662303684432,0.06550990198039608,318.056316473071,237.0952833600327,-0.6977972913092101
0.3285814358817123,0.06589397879575916,318.5326598863622,237.0952833600327,-0.6977972913092101
0.32963479891401026,0.06610522104420884,318.79418717260023,237.0952833600327,-0.6977972913092101
0.33126272360028897,0.06643168633726745,319.19772553094776,237.0952833600327,-0.6977972913092101
0.33269912773524085,0.06671974394878977,319.55314694862886,237.0952833600327,-0.6977972913092101
0.3355719360051444,0.06729585917183437,320.26219948610714,237.0952833600327,-0.6977972913092101
0.33968962785867296,0.06812162432486497,321.274393570048,237.0952833600327,-0.6977972913092101
0.3399769086856633,0.06817923584716944,321.344832676346,237.0952833600327,-0.6977972913092101
0.34342427860954766,0.06887057411482297,322.18829936729026,237.0952833600327,-0.6977972913092101
0.34610556632812434,0.06940828165633127,322.8420481597589,237.0952833600327,-0.6977972913092101
0.348978374598028,0.06998439687937588,323.5403052710048,237.0952833600327,-0.6977972913092101
0.35079781983563363,0.0703492698539708,323.98137551909787,237.0952833600327,-0.6977972913092101
0.3557773541701332,0.07134786957391479,325.18397634653485,237.0952833600327,-0.6977972913092101
0.35845864188870996,0.0718855771154231,325.8288108684138,237.0952833600327,-0.6977972913092101
0.3628636145692288,0.07276895379075815,326.8841130284045,237.0952833600327,-0.6977972913092101
0.36382121732586337,0.0729609921984397,327.112864060766,237.0952833600327,-0.6977972913092101
0.3669813064227573,0.07359471894378876,327.8660819572245,237.0952833600327,-0.6977972913092101
0.36994987496832443,0.07419003800760153,328.5713493390098,237.0952833600327,-0.6977972913092101
0.37071595717363204,0.07434366873374676,328.75299511349635,237.0952833600327,-0.6977972913092101
0.37176932020593,0.07455491098219644,329.0025192008039,237.0952833600327,-0.6977972913092101
0.37243964213557423,0.07468933786757352,329.16116370589816,237.0952833600327,-0.6977972913092101
0.37301420378955497,0.07480456091218245,329.29705609975196,237.0952833600327,-0.6977972913092101
0.3757912517837951,0.0753614722944589,329.95272200275804,237.0952833600327,-0.6977972913092101
0.378089498399718,0.07582236447289459,330.4939142206973,237.0952833600327,-0.6977972913092101
0.3795259025346698,0.07611042208441689,330.83150792733625,237.0952833600327,-0.6977972913092101
0.38019622446431395,0.07624484896979396,330.9888810925811,237.0952833600327,-0.6977972913092101
0.38306903273421755,0.07682096419283857,331.66211555566355,237.0952833600327,-0.6977972913092101
0.3848884779718232,0.07718583716743349,332.0874791214601,237.0952833600327,-0.6977972913092101
0.3869952040364192,0.07760832166433287,332.5790268793965,237.0952833600327,-0.6977972913092101
0.3882400876200441,0.07785797159431887,332.8689963972844,237.0952833600327,-0.6977972913092101
0.3912086561656111,0.07845329065813163,333.55900274455456,237.0952833600327,-0.6977972913092101
0.39187897809525535,0.07858771754350871,333.7145276685352,237.0952833600327,-0.6977972913092101
0.3961881905001108,0.07945189037807562,334.7118648201188,237.0952833600327,-0.6977972913092101
0.399827080975322,0.08018163632726545,335.55077032156896,237.0952833600327,-0.6977972913092101
0.4004974029049662,0.08031606321264254,335.7049802228053,237.0952833600327,-0.6977972913092101
0.40088044400762,0.08039287857571514,335.7930549714169,237.0952833600327,-0.6977972913092101
0.4046150947584947,0.08114182836567314,336.6500707106774,237.0952833600327,-0.6977972913092101
0.4053811769638024,0.08129545909181837,336.8254868772801,237.0952833600327,-0.6977972913092101
0.40806246468237906,0.08183316663332667,337.43842793942133,237.0952833600327,-0.6977972913092101
0.409115827714677,0.08204440888177636,337.67879622269726,237.0952833600327,-0.6977972913092101
0.4095946290929943,0.08214042808561713,337.78797473141356,237.0952833600327,-0.6977972913092101
0.41141407433059995,0.08250530106021205,338.2023999150519,237.0952833600327,-0.6977972913092101
0.4124674373628979,0.08271654330866174,338.44200358499506,237.0952833600327,-0.6977972913092101
0.4127547181898883,0.0827741548309662,338.5073086082214,237.0952833600327,-0.6977972913092101
0.4156275264597919,0.0833502700540108,339.15938682652296,237.0952833600327,-0.6977972913092101
0.4230968279615413,0.08484816963392679,340.84661639369085,237.0952833600327,-0.6977972913092101
0.42482051292348344,0.08519383876775355,341.23432261263105,237.0952833600327,-0.6977972913092101
0.4264484376097622,0.08552030406081217,341.599926653627,237.0952833600327,-0.6977972913092101
0.427884841744714,0.08580836167233447,341.92206667662026,237.0952833600327,-0.6977972913092101
0.42845940339869476,0.08592358471694339,342.05080456170236,237.0952833600327,-0.6977972913092101
0.4296085267066562,0.08615403080616124,342.30807852483457,237.0952833600327,-0.6977972913092101
0.43056612946329076,0.08634606921384277,342.52226854404194,237.0952833600327,-0.6977972913092101
0.43075765001461763,0.08638447689537908,342.5650842450273,237.0952833600327,-0.6977972913092101
0.4323855747008964,0.0867109421884377,342.92871843907926,237.0952833600327,-0.6977972913092101
0.43372621856018473,0.08697979595919185,343.2277811461058,237.0952833600327,-0.6977972913092101
0.43497110214380963,0.08722944588917785,343.50515958311314,237.0952833600327,-0.6977972913092101
0.43717358848406906,0.08767113422684537,343.99514880475925,237.0952833600327,-0.6977972913092101
0.4383227117920305,0.08790158031606321,344.2504131175122,237.0952833600327,-0.6977972913092101
0.43966335565131887,0.08817043408681736,344.54789185211985,237.0952833600327,-0.6977972913092101
0.43995063647830923,0.08822804560912183,344.6115912460559,237.0952833600327,-0.6977972913092101
0.44129128033759757,0.08849689937987598,344.90864085919566,237.0952833600327,-0.6977972913092101
0.44445136943449154,0.08913062612522504,345.6074401632861,237.0952833600327,-0.6977972913092101
0.447707218807049,0.08978355671134228,346.3253914989043,237.0952833600327,-0.6977972913092101
0.44818602018536624,0.08987957591518304,346.43080058457247,237.0952833600327,-0.6977972913092101
0.44923938321766427,0.09009081816363274,346.66254610652516,237.0952833600327,-0.6977972913092101
0.4513461092822602,0.0905133026605321,347.1254023625569,237.0952833600327,-0.6977972913092101
0.45335707507119277,0.09091658331666334,347.56643433432583,237.0952833600327,-0.6977972913092101
0.45383587644951007,0.09101260252050411,347.6713294139017,237.0952833600327,-0.6977972913092101
0.4564214038924233,0.09153110622124426,348.2370187991912,237.0952833600327,-0.6977972913092101
0.45737900664905784,0.09172314462892579,348.44621605765184,237.0952833600327,-0.6977972913092101
0.4605390957459518,0.09235687137427485,349.1353582531141,237.0952833600327,-0.6977972913092101
0.4621670204322305,0.09268333666733347,349.4896510228439,237.0952833600327,-0.6977972913092101
0.4640822259454996,0.09306741348269654,349.90584353918,237.0952833600327,-0.6977972913092101
0.4658059109074418,0.09341308261652331,350.2798444293367,237.0952833600327,-0.6977972913092101
0.46839143835035507,0.09393158631726346,350.8398353304178,237.0952833600327,-0.6977972913092101
0.4717430479985759,0.09460372074414883,351.5639584622365,237.0952833600327,-0.6977972913092101
0.4722218493768932,0.09469973994798961,351.6672405971957,237.0952833600327,-0.6977972913092101
0.4770098631600659,0.09565993198639729,352.69782555956147,237.0952833600327,-0.6977972913092101
0.4795953906029792,0.09617843568713744,353.25266362074484,237.0952833600327,-0.6977972913092101
0.4821809180458924,0.09669693938787759,353.80633634625804,237.0952833600327,-0.6977972913092101
0.48304276052686346,0.09686977395479096,353.9906364608273,237.0952833600327,-0.6977972913092101
0.48562828796977675,0.09738827765553111,354.5427688833976,237.0952833600327,-0.6977972913092101
0.4880222948613631,0.09786837367473496,355.0529812696881,237.0952833600327,-0.6977972913092101
0.48907565789366103,0.09807961592318463,355.2771653875923,237.0952833600327,-0.6977972913092101
0.49108662368259365,0.09848289657931587,355.7046310330242,237.0952833600327,-0.6977972913092101
0.4949170347091318,0.09925105021004202,356.5169674629419,237.0952833600327,-0.6977972913092101
0.4960661580170932,0.09948149629925986,356.76018977800584,237.0952833600327,-0.6977972913092101
0.49644919911974705,0.09955831166233248,356.8412150405878,237.0952833600327,-0.6977972913092101
0.4971195210493912,0.09969273854770955,356.9829506073045,237.0952833600327,-0.6977972913092101
0.497502562152045,0.09976955391078215,357.06390889440434,237.0952833600327,-0.6977972913092101
0.4979813635303623,0.09986557311462294,357.1650725762232,237.0952833600327,-0.6977972913092101