File: datasets/aisi_316_L/data/M1/train_73.csv
Time(s),Strain(%),Stress(MPa),Temp(C),Log_SR(s-1)
0.0,0.0,0.0,170.65223387071364,3.4591303096761905
1.806645875669551e-08,5.2e-05,9.787260437499999,170.65223387071364,3.4591303096761905
2.862838849137904e-08,8.24e-05,15.5090434625,170.65223387071364,3.4591303096761905
3.5299080955389686e-08,0.00010159999999999999,19.122801162499997,170.65223387071364,3.4591303096761905
3.919031822606257e-08,0.00011279999999999999,21.2308264875,170.65223387071364,3.4591303096761905
4.447128309340433e-08,0.000128,24.091718,170.65223387071364,3.4591303096761905
4.697279276740833e-08,0.0001352,25.4468771375,170.65223387071364,3.4591303096761905
4.7528683806075877e-08,0.0001368,25.7480236125,170.65223387071364,3.4591303096761905
4.891841140274477e-08,0.0001408,26.500889800000003,170.65223387071364,3.4591303096761905
5.169786659608254e-08,0.00014879999999999998,28.006622174999997,170.65223387071364,3.4591303096761905
5.6144994905422974e-08,0.0001616,30.415793975,170.65223387071364,3.4591303096761905
6.253774185009984e-08,0.00017999999999999998,33.878978437499995,170.65223387071364,3.4591303096761905
7.448939918145225e-08,0.00021439999999999998,40.35362764999999,170.65223387071364,3.4591303096761905
7.921447301012647e-08,0.00022799999999999999,42.9133726875,170.65223387071364,3.4591303096761905
9.08881848221451e-08,0.00026159999999999996,49.23744866249999,170.65223387071364,3.4591303096761905
9.366764001548288e-08,0.0002696,50.7431810375,170.65223387071364,3.4591303096761905
9.894860488282464e-08,0.0002848,53.60407255,170.65223387071364,3.4591303096761905
1.0117216903749486e-07,0.0002912,54.808658449999996,170.65223387071364,3.4591303096761905
1.0506340630816773e-07,0.0003024,56.916683774999996,170.65223387071364,3.4591303096761905
1.0645313390483662e-07,0.00030639999999999997,57.66954996249999,170.65223387071364,3.4591303096761905
1.092325890981744e-07,0.0003144,59.1752823375,170.65223387071364,3.4591303096761905
1.1256793533017971e-07,0.00032399999999999996,60.98216118749999,170.65223387071364,3.4591303096761905
1.1367971740751482e-07,0.0003272,61.584454137499996,170.65223387071364,3.4591303096761905
1.1451355396551616e-07,0.0003296,62.03617385,170.65223387071364,3.4591303096761905
1.153473905235175e-07,0.000332,62.4878935625,170.65223387071364,3.4591303096761905
1.3119028512554278e-07,0.00037759999999999996,71.07056809999999,170.65223387071364,3.4591303096761905
1.3508152239621565e-07,0.00038879999999999996,73.17859342499999,170.65223387071364,3.4591303096761905
1.4175221486022633e-07,0.000408,76.792351125,170.65223387071364,3.4591303096761905
1.453655066115654e-07,0.0004184,78.7498032125,170.65223387071364,3.4591303096761905
1.5620538186558272e-07,0.0004496,84.62215947499999,170.65223387071364,3.4591303096761905
1.6454374744559603e-07,0.00047359999999999997,89.1393566,170.65223387071364,3.4591303096761905
1.684349847162689e-07,0.00048479999999999997,91.247381925,170.65223387071364,3.4591303096761905
1.737159495836107e-07,0.0005,94.1082734375,170.65223387071364,3.4591303096761905
1.7955280548961998e-07,0.0005168,97.270311425,170.65223387071364,3.4591303096761905
1.8344404276029286e-07,0.0005279999999999999,99.37833674999999,170.65223387071364,3.4591303096761905
1.856676069149631e-07,0.0005344,100.58292265,170.65223387071364,3.4591303096761905
1.8955884418563595e-07,0.0005455999999999999,102.69094797499999,170.65223387071364,3.4591303096761905
1.9289419041764128e-07,0.0005551999999999999,104.49782682499999,170.65223387071364,3.4591303096761905
1.9345008145630886e-07,0.0005568,104.7989733,170.65223387071364,3.4591303096761905
1.9622953664964662e-07,0.0005648,106.304705675,170.65223387071364,3.4591303096761905
1.9900899184298437e-07,0.0005727999999999999,107.81043804999999,170.65223387071364,3.4591303096761905
2.017884470363222e-07,0.0005808,109.31617042500001,170.65223387071364,3.4591303096761905
2.0540173878766126e-07,0.0005912,111.2736225125,170.65223387071364,3.4591303096761905
2.1123859469367055e-07,0.0006079999999999999,114.43566049999998,170.65223387071364,3.4591303096761905
2.1651955956101234e-07,0.0006232,117.2965520125,170.65223387071364,3.4591303096761905
2.3764341903037938e-07,0.0006839999999999999,128.7401180625,170.65223387071364,3.4591303096761905
2.4292438389772117e-07,0.0006992,131.601009575,170.65223387071364,3.4591303096761905
2.4542589357172514e-07,0.0007063999999999999,132.9561687125,170.65223387071364,3.4591303096761905
2.576554964224113e-07,0.0007415999999999999,139.58139116249998,170.65223387071364,3.4591303096761905
2.587672784997465e-07,0.0007448,140.1836841125,170.65223387071364,3.4591303096761905
2.598790605770816e-07,0.000748,140.7859770625,170.65223387071364,3.4591303096761905
2.6154673369308425e-07,0.0007528,141.68941648749998,170.65223387071364,3.4591303096761905
2.732204455051029e-07,0.0007863999999999999,148.01349246249998,170.65223387071364,3.4591303096761905
2.7599990069844065e-07,0.0007944,149.5192248375,170.65223387071364,3.4591303096761905
2.8294853868178504e-07,0.0008144,153.283555775,170.65223387071364,3.4591303096761905
2.9045306770379705e-07,0.0008359999999999999,157.3490331875,170.65223387071364,3.4591303096761905
2.9295457737780107e-07,0.0008432,158.704192325,170.65223387071364,3.4591303096761905
2.960119780904726e-07,0.000852,160.3604979375,170.65223387071364,3.4591303096761905
3.0184883399648193e-07,0.0008688,163.522535925,170.65223387071364,3.4591303096761905
3.087974719798263e-07,0.0008887999999999999,167.28686686249998,170.65223387071364,3.4591303096761905
3.107430906151628e-07,0.0008944,168.340879525,170.65223387071364,3.4591303096761905
3.1824761963717474e-07,0.0009159999999999999,172.4063569375,170.65223387071364,3.4591303096761905
3.315890045651961e-07,0.0009544,179.6338723375,170.65223387071364,3.4591303096761905
3.379817515098729e-07,0.0009728,183.0970568,170.65223387071364,3.4591303096761905
3.3992737014520934e-07,0.0009784,184.15106946249998,170.65223387071364,3.4591303096761905
3.44096552935216e-07,0.0009904,186.409668025,170.65223387071364,3.4591303096761905
3.4632011708988623e-07,0.0009968,187.61425392499999,170.65223387071364,3.4591303096761905
3.493775178025578e-07,0.0010056,189.2705595375,170.65223387071364,3.4591303096761905
3.552143737085671e-07,0.0010224,192.43259752499998,170.65223387071364,3.4591303096761905
3.5799382890190486e-07,0.0010304,193.93832989999999,170.65223387071364,3.4591303096761905
3.627189027305791e-07,0.001044,196.4980749375,170.65223387071364,3.4591303096761905
3.663321944819182e-07,0.0010544,198.455527025,170.65223387071364,3.4591303096761905
3.730028869459288e-07,0.0010735999999999999,202.06928472499996,170.65223387071364,3.4591303096761905
3.793956338906057e-07,0.0010919999999999999,205.53246918749997,170.65223387071364,3.4591303096761905
3.9384880089596216e-07,0.0011336,213.3622775375,170.65223387071364,3.4591303096761905
3.9857387472463634e-07,0.0011472,215.92202257499997,170.65223387071364,3.4591303096761905
4.0802402238198476e-07,0.0011744,221.04151265,170.65223387071364,3.4591303096761905
4.088578589399861e-07,0.0011768,221.4932323625,170.65223387071364,3.4591303096761905
4.149726603653292e-07,0.0011944,224.8058435875,170.65223387071364,3.4591303096761905
4.166403334813318e-07,0.0011991999999999999,225.70928301249998,170.65223387071364,3.4591303096761905
4.258125356193465e-07,0.0012255999999999999,230.67819984999997,170.65223387071364,3.4591303096761905
4.3276117360269093e-07,0.0012456,234.44253078749998,170.65223387071364,3.4591303096761905
4.3415090119935984e-07,0.0012496,235.195396975,170.65223387071364,3.4591303096761905
4.383200839893664e-07,0.0012615999999999999,237.45399553749996,170.65223387071364,3.4591303096761905
4.5193941443672156e-07,0.0013008,239.31147012453312,170.65223387071364,3.4591303096761905
4.5610859722672824e-07,0.0013128,239.3948168115702,170.65223387071364,3.4591303096761905
4.6722641800007926e-07,0.0013448,239.61563469535497,170.65223387071364,3.4591303096761905
4.7139560079008594e-07,0.0013568,239.69791186386328,170.65223387071364,3.4591303096761905
4.822354760441033e-07,0.001388,239.91051517056735,170.65223387071364,3.4591303096761905
4.861267133147761e-07,0.0013992,239.98637862425082,170.65223387071364,3.4591303096761905
4.916856237014516e-07,0.0014152,240.09434544324512,170.65223387071364,3.4591303096761905
4.927974057787867e-07,0.0014184,240.11588156620095,170.65223387071364,3.4591303096761905
5.07528518303477e-07,0.0014608,240.39946958422155,170.65223387071364,3.4591303096761905
5.172566114801592e-07,0.0014888,240.58498648250517,170.65223387071364,3.4591303096761905
5.192022301154956e-07,0.0014944,240.62192602962213,170.65223387071364,3.4591303096761905
5.300421053695129e-07,0.0015256,240.82675227316713,170.65223387071364,3.4591303096761905
5.347671791981871e-07,0.0015392,240.91552353080118,170.65223387071364,3.4591303096761905
5.383804709495263e-07,0.0015496,240.9832011842726,170.65223387071364,3.4591303096761905
5.422717082201991e-07,0.0015608,241.05588700897644,170.65223387071364,3.4591303096761905
5.478306186068746e-07,0.0015768,241.15937202567196,170.65223387071364,3.4591303096761905
5.483865096455422e-07,0.0015784,241.16969795219006,170.65223387071364,3.4591303096761905
5.506100738002124e-07,0.0015848,241.21096090147822,170.65223387071364,3.4591303096761905
5.556130931482204e-07,0.0015991999999999998,241.3035656650856,170.65223387071364,3.4591303096761905
5.617278945735634e-07,0.0016167999999999998,241.41630880171803,170.65223387071364,3.4591303096761905
5.692324235955754e-07,0.0016384,241.55402331473053,170.65223387071364,3.4591303096761905
5.74791333982251e-07,0.0016543999999999999,241.65557799594143,170.65223387071364,3.4591303096761905
5.886886099489398e-07,0.0016944,241.90780310785195,170.65223387071364,3.4591303096761905
5.93413683777614e-07,0.0017079999999999999,241.99302923760405,170.65223387071364,3.4591303096761905
6.003623217609585e-07,0.001728,242.11788256483322,170.65223387071364,3.4591303096761905
6.134257611696461e-07,0.0017656,242.35109160216635,170.65223387071364,3.4591303096761905
6.267671460976673e-07,0.0018039999999999998,242.58727189979007,170.65223387071364,3.4591303096761905
6.314922199263415e-07,0.0018176,242.67044785550405,170.65223387071364,3.4591303096761905
6.376070213516846e-07,0.0018352,242.77772791503452,170.65223387071364,3.4591303096761905
6.476130600477007e-07,0.001864,242.95241562242182,170.65223387071364,3.4591303096761905
6.515042973183735e-07,0.0018751999999999998,243.0200650629778,170.65223387071364,3.4591303096761905
6.526160793957086e-07,0.0018784,243.03936450781418,170.65223387071364,3.4591303096761905
6.581749897823841e-07,0.0018943999999999999,243.1356700628702,170.65223387071364,3.4591303096761905
6.654015732850624e-07,0.0019152,243.26039436225395,170.65223387071364,3.4591303096761905
6.692928105557352e-07,0.0019264,243.32733473808452,170.65223387071364,3.4591303096761905
6.706825381524041e-07,0.0019303999999999999,243.35120520879644,170.65223387071364,3.4591303096761905
6.72072265749073e-07,0.0019344,243.37505639701578,170.65223387071364,3.4591303096761905
6.748517209424107e-07,0.0019424,243.4227011473073,170.65223387071364,3.4591303096761905
6.790209037324173e-07,0.0019544,243.49402503023686,170.65223387071364,3.4591303096761905
6.845798141190929e-07,0.0019703999999999998,243.58885843072008,170.65223387071364,3.4591303096761905
6.88193105870432e-07,0.0019808,243.65033913329904,170.65223387071364,3.4591303096761905
6.923622886604387e-07,0.0019928,243.7211221898477,170.65223387071364,3.4591303096761905
6.987550356051156e-07,0.0020112,243.82933420648286,170.65223387071364,3.4591303096761905
7.018124363177872e-07,0.00202,243.8809512338989,170.65223387071364,3.4591303096761905
7.168214943618111e-07,0.0020632,244.1330829097134,170.65223387071364,3.4591303096761905
7.223804047484866e-07,0.0020792,244.22594143900267,170.65223387071364,3.4591303096761905
7.240480778644893e-07,0.002084,244.25374460023002,170.65223387071364,3.4591303096761905
7.321084979251688e-07,0.0021072,244.3877760584735,170.65223387071364,3.4591303096761905
7.326643889638364e-07,0.0021088,244.3969983379519,170.65223387071364,3.4591303096761905
7.396130269471807e-07,0.0021287999999999997,244.51204754007475,170.65223387071364,3.4591303096761905
7.412807000631834e-07,0.0021336,244.53959652958716,170.65223387071364,3.4591303096761905
7.44338100775855e-07,0.0021424,244.59004031418124,170.65223387071364,3.4591303096761905
7.490631746045292e-07,0.002156,244.66784023665576,170.65223387071364,3.4591303096761905
7.512867387591995e-07,0.0021624,244.70438571643155,170.65223387071364,3.4591303096761905
7.540661939525372e-07,0.0021704,244.75000830005806,170.65223387071364,3.4591303096761905
7.571235946652088e-07,0.0021792,244.8001174601982,170.65223387071364,3.4591303096761905
7.590692133005452e-07,0.0021847999999999998,244.8319640231654,170.65223387071364,3.4591303096761905
7.612927774552154e-07,0.0021912,244.8683211396404,170.65223387071364,3.4591303096761905
7.660178512838896e-07,0.0022048,244.94544278971838,170.65223387071364,3.4591303096761905
7.749121079025705e-07,0.0022304,245.09011151242268,170.65223387071364,3.4591303096761905
7.79359236211911e-07,0.0022432,245.16220292383855,170.65223387071364,3.4591303096761905
7.801930727699123e-07,0.0022456,245.17570218436495,170.65223387071364,3.4591303096761905
7.968698039299388e-07,0.0022936,245.44451700979135,170.65223387071364,3.4591303096761905
7.977036404879402e-07,0.002296,245.45789985922457,170.65223387071364,3.4591303096761905
8.079876247032899e-07,0.0023255999999999997,245.62250895458968,170.65223387071364,3.4591303096761905
8.093773522999589e-07,0.0023296,245.64469059148914,170.65223387071364,3.4591303096761905
8.238305193053153e-07,0.0023712,245.8745058909617,170.65223387071364,3.4591303096761905
8.25498192421318e-07,0.002376,245.90092147194545,170.65223387071364,3.4591303096761905
8.313350483273273e-07,0.0023928,245.99321255489775,170.65223387071364,3.4591303096761905
8.34114503520665e-07,0.0024008,246.03707183745888,170.65223387071364,3.4591303096761905
8.377277952720042e-07,0.0024112,246.09400378717518,170.65223387071364,3.4591303096761905
8.391175228686729e-07,0.0024151999999999997,246.11587518057442,170.65223387071364,3.4591303096761905
8.410631415040094e-07,0.0024208,246.14647141300483,170.65223387071364,3.4591303096761905
8.494015070840228e-07,0.0024448,246.27728670806454,170.65223387071364,3.4591303096761905
8.56628090586701e-07,0.0024656,246.39025537008806,170.65223387071364,3.4591303096761905
8.658002927247156e-07,0.002492,246.53310485770234,170.65223387071364,3.4591303096761905
8.671900203213845e-07,0.002496,246.554697124057,170.65223387071364,3.4591303096761905
8.771960590174004e-07,0.0025248,246.7097650096291,170.65223387071364,3.4591303096761905
8.863682611554151e-07,0.0025512,246.85130562676017,170.65223387071364,3.4591303096761905
8.899815529067542e-07,0.0025616,246.90690707371596,170.65223387071364,3.4591303096761905
8.955404632934298e-07,0.0025775999999999998,246.99227616061654,170.65223387071364,3.4591303096761905
9.049906109507782e-07,0.0026048,247.13693082692367,170.65223387071364,3.4591303096761905
9.130510310114576e-07,0.0026279999999999997,247.2598478317039,170.65223387071364,3.4591303096761905
9.250026883428101e-07,0.0026623999999999997,247.44132797296342,170.65223387071364,3.4591303096761905
9.31395435287487e-07,0.0026807999999999997,247.53802324871575,170.65223387071364,3.4591303096761905
9.38899964309499e-07,0.0027023999999999998,247.65120544255737,170.65223387071364,3.4591303096761905
9.427912015801719e-07,0.0027136,247.70975357418718,170.65223387071364,3.4591303096761905
9.483501119668474e-07,0.0027296,247.79323054355945,170.65223387071364,3.4591303096761905
9.530751857955216e-07,0.0027432,247.86403603497445,170.65223387071364,3.4591303096761905
9.594679327401984e-07,0.0027616,247.95961417718547,170.65223387071364,3.4591303096761905
9.61413551375535e-07,0.0027672,247.98865383869625,170.65223387071364,3.4591303096761905
9.833712474029033e-07,0.0028304,248.3148139754599,170.65223387071364,3.4591303096761905
9.853168660382398e-07,0.002836,248.34357655097497,170.65223387071364,3.4591303096761905
1.0019935971982663e-06,0.002884,248.58921088730395,170.65223387071364,3.4591303096761905
1.0053289434302718e-06,0.0028936,248.63814586035107,170.65223387071364,3.4591303096761905
1.0072745620656081e-06,0.0028991999999999998,248.66666202154752,170.65223387071364,3.4591303096761905
1.019782110435628e-06,0.0029352,248.84946993945684,170.65223387071364,3.4591303096761905
1.0208938925129633e-06,0.0029384,248.86567709546378,170.65223387071364,3.4591303096761905
1.0228395111482996e-06,0.002944,248.89402306478232,170.65223387071364,3.4591303096761905
1.0239512932256348e-06,0.0029472,248.91021132014708,170.65223387071364,3.4591303096761905
1.030066094650978e-06,0.0029648,248.99912449447646,170.65223387071364,3.4591303096761905
1.0342352774409846e-06,0.0029768,249.0596291233866,170.65223387071364,3.4591303096761905
1.0381265147116573e-06,0.0029879999999999998,249.11601434492746,170.65223387071364,3.4591303096761905
1.046186934772337e-06,0.0030112,249.23255077089806,170.65223387071364,3.4591303096761905
1.0481325534076734e-06,0.0030168,249.2606277269139,170.65223387071364,3.4591303096761905
1.0528576272363476e-06,0.0030304,249.3287301309673,170.65223387071364,3.4591303096761905
1.0606401017776935e-06,0.0030528,249.44063952884642,170.65223387071364,3.4591303096761905
1.0664769576837028e-06,0.0030696,249.5243615375952,170.65223387071364,3.4591303096761905
1.074537377744382e-06,0.0030927999999999997,249.63968445267363,170.65223387071364,3.4591303096761905
1.0792624515730564e-06,0.0031064,249.70713068906403,170.65223387071364,3.4591303096761905
1.0887125992304047e-06,0.0031336,249.84167867012832,170.65223387071364,3.4591303096761905
1.0920479454624102e-06,0.0031432,249.88905734580638,170.65223387071364,3.4591303096761905
1.100942202081091e-06,0.0031688,250.01512538857574,170.65223387071364,3.4591303096761905
1.1065011124677665e-06,0.0031848,250.09371624259074,170.65223387071364,3.4591303096761905
1.1167850966831164e-06,0.0032144,250.23870457663912,170.65223387071364,3.4591303096761905
1.120954279473123e-06,0.0032264,250.29733518232922,170.65223387071364,3.4591303096761905
1.1265131898597986e-06,0.0032424,250.37537720129168,170.65223387071364,3.4591303096761905
1.1281808629758013e-06,0.0032472,250.39876050079576,170.65223387071364,3.4591303096761905
1.1317941547271402e-06,0.0032576,250.44937812132446,170.65223387071364,3.4591303096761905
1.1387427927104847e-06,0.0032776,250.54654291315808,170.65223387071364,3.4591303096761905
1.144579648616494e-06,0.0032944,250.62798277300135,170.65223387071364,3.4591303096761905
1.1462473217324967e-06,0.0032992,250.65122153408802,170.65223387071364,3.4591303096761905
1.1512503410805046e-06,0.0033136,250.72085883064065,170.65223387071364,3.4591303096761905
1.1601445976991855e-06,0.0033391999999999996,250.84436775223645,170.65223387071364,3.4591303096761905
1.1623681618538557e-06,0.0033456,250.8751872141958,170.65223387071364,3.4591303096761905
1.1679270722405313e-06,0.0033615999999999997,250.9521354454763,170.65223387071364,3.4591303096761905
1.1759874923012108e-06,0.0033848,251.0634571533758,170.65223387071364,3.4591303096761905
1.1776551654172136e-06,0.0033896,251.08645203386163,170.65223387071364,3.4591303096761905
1.1823802392458876e-06,0.0034032,251.15153533134207,170.65223387071364,3.4591303096761905
1.1834920213232228e-06,0.0034064,251.1668342976436,170.65223387071364,3.4591303096761905
1.1890509317098983e-06,0.0034224,251.24324521443162,170.65223387071364,3.4591303096761905
1.2010025890412507e-06,0.0034568,251.40705851267165,170.65223387071364,3.4591303096761905
1.202114371118586e-06,0.00346,251.42226456488586,170.65223387071364,3.4591303096761905
1.2087850635825966e-06,0.0034792,251.51338596558946,170.65223387071364,3.4591303096761905
1.2101747911792654e-06,0.0034831999999999997,251.53234488286435,170.65223387071364,3.4591303096761905
1.2165675381239422e-06,0.0035015999999999997,251.61944677126505,170.65223387071364,3.4591303096761905
1.2260176857812908e-06,0.0035288,251.7478798234024,170.65223387071364,3.4591303096761905
1.2310207051292987e-06,0.0035432,251.81571745894072,170.65223387071364,3.4591303096761905
1.240470852786647e-06,0.0035704,251.94356256904354,170.65223387071364,3.4591303096761905
1.2429723624606511e-06,0.0035776,251.97734027027232,170.65223387071364,3.4591303096761905
1.2471415452506577e-06,0.0035895999999999996,252.0335775839954,170.65223387071364,3.4591303096761905
1.2552019653113372e-06,0.0036127999999999998,252.1420955875628,170.65223387071364,3.4591303096761905
1.2574255294660074e-06,0.0036192,252.1719837178491,170.65223387071364,3.4591303096761905
1.2588152570626765e-06,0.0036232,252.1906533323802,170.65223387071364,3.4591303096761905
1.2657638950460208e-06,0.0036431999999999997,252.28388110135046,170.65223387071364,3.4591303096761905
1.2665977316040222e-06,0.0036455999999999997,252.29505500490862,170.65223387071364,3.4591303096761905
1.2690992412780262e-06,0.0036528,252.32855951502344,170.65223387071364,3.4591303096761905
1.272990478548699e-06,0.0036639999999999997,252.380626493857,170.65223387071364,3.4591303096761905
1.2763258247807044e-06,0.0036736,252.42520594868728,170.65223387071364,3.4591303096761905
1.2852200813993852e-06,0.0036991999999999997,252.54386293327704,170.65223387071364,3.4591303096761905
1.2896672097087257e-06,0.003712,252.6030713004564,170.65223387071364,3.4591303096761905
1.3024527035980792e-06,0.0037487999999999996,252.7728534367647,170.65223387071364,3.4591303096761905
1.3071777774267537e-06,0.0037624,252.83543435420594,170.65223387071364,3.4591303096761905
1.3127366878134292e-06,0.0037784,252.90894612600772,170.65223387071364,3.4591303096761905
1.316627925084102e-06,0.0037895999999999997,252.9603321477465,170.65223387071364,3.4591303096761905
1.318017652680771e-06,0.0037936,252.9786699400291,170.65223387071364,3.4591303096761905
1.3202412168354412e-06,0.0038,253.00799473053334,170.65223387071364,3.4591303096761905
1.325522181702783e-06,0.0038152,253.0775640183811,170.65223387071364,3.4591303096761905
1.3316369831281261e-06,0.0038328,253.1579830295088,170.65223387071364,3.4591303096761905
1.335250274879465e-06,0.0038431999999999997,253.20543566089964,170.65223387071364,3.4591303096761905
1.3408091852661406e-06,0.0038591999999999997,253.27834203689622,170.65223387071364,3.4591303096761905
1.3433106949401447e-06,0.0038664,253.31111143701028,170.65223387071364,3.4591303096761905
1.3460901501334824e-06,0.0038743999999999996,253.34749398195316,170.65223387071364,3.4591303096761905
1.3480357687688188e-06,0.0038799999999999998,253.3729443328983,170.65223387071364,3.4591303096761905
1.3547064612328294e-06,0.0038992,253.4600941275306,170.65223387071364,3.4591303096761905
1.3583197529841687e-06,0.0039096,253.50723038070223,170.65223387071364,3.4591303096761905
1.3713831923928561e-06,0.0039472,253.67723958987273,170.65223387071364,3.4591303096761905
1.3808333400502045e-06,0.0039743999999999995,253.7998315129936,170.65223387071364,3.4591303096761905
1.385280468359545e-06,0.0039872,253.85740856948243,170.65223387071364,3.4591303096761905
1.3880599235528829e-06,0.0039952,253.893357625637,170.65223387071364,3.4591303096761905
1.388893760110884e-06,0.0039976,253.9041368666426,170.65223387071364,3.4591303096761905
1.5031520534484225e-06,0.004326465293058612,255.3581824185982,170.65223387071364,3.4591303096761905
1.623248537097344e-06,0.004672134426885377,256.84076821282713,170.65223387071364,3.4591303096761905
1.6766247520524203e-06,0.0048257651530306065,257.48589209959823,170.65223387071364,3.4591303096761905
1.9568498805665703e-06,0.005632326465293058,260.7496230605422,170.65223387071364,3.4591303096761905
2.110306498562414e-06,0.006074014802960592,262.45931193819894,170.65223387071364,3.4591303096761905
2.343827438990873e-06,0.006746149229845969,264.97070754763735,170.65223387071364,3.4591303096761905
2.357171492729642e-06,0.006784556911382277,265.11119351738375,170.65223387071364,3.4591303096761905
2.523972164464255e-06,0.007264652930586117,266.8418833023385,170.65223387071364,3.4591303096761905
2.550660271941793e-06,0.007341468293658731,267.11459896892535,170.65223387071364,3.4591303096761905
2.7441490511539443e-06,0.007898379675935187,269.05953623065295,170.65223387071364,3.4591303096761905
2.864245534802866e-06,0.008244048809761952,270.2398575814286,170.65223387071364,3.4591303096761905
3.0844224214925556e-06,0.008877775555111022,272.3548111066508,170.65223387071364,3.4591303096761905
3.151142690186401e-06,0.009069813962792559,272.983969108771,170.65223387071364,3.4591303096761905
3.384663630614859e-06,0.009741948389677936,275.14623094207013,170.65223387071364,3.4591303096761905
3.431367818700551e-06,0.009876375275055011,275.57161319325684,170.65223387071364,3.4591303096761905
3.544792275480088e-06,0.010202840568113623,276.5953909401362,170.65223387071364,3.4591303096761905
3.57815240982701e-06,0.01029885977195439,276.8940601364853,170.65223387071364,3.4591303096761905
3.6515447053902403e-06,0.010510102020404082,277.547336116399,170.65223387071364,3.4591303096761905
4.085226451900234e-06,0.011758351670334066,281.3079200541403,170.65223387071364,3.4591303096761905
4.105242532508388e-06,0.011815963192638527,281.47762240948396,170.65223387071364,3.4591303096761905
4.131930639985926e-06,0.011892778555711142,281.70339109684016,170.65223387071364,3.4591303096761905
4.21199496241854e-06,0.012123224644928985,282.37730931255226,170.65223387071364,3.4591303096761905
4.338763472936847e-06,0.012488097619523904,283.43421739400435,170.65223387071364,3.4591303096761905
4.505564144671459e-06,0.012968193638727745,284.8067146596308,170.65223387071364,3.4591303096761905
4.5722844133653045e-06,0.013160232046409282,285.3501471210243,170.65223387071364,3.4591303096761905
4.759101165708072e-06,0.013697939587917584,286.8555459346399,170.65223387071364,3.4591303096761905
4.799133326924379e-06,0.013813162632526505,287.17511258055686,170.65223387071364,3.4591303096761905
5.059342374830376e-06,0.014562112422484497,289.2275169989387,170.65223387071364,3.4591303096761905
5.1927829122180664e-06,0.01494618923784757,290.2640330266584,170.65223387071364,3.4591303096761905
5.34623953021391e-06,0.015387877575515104,291.44326929762667,170.65223387071364,3.4591303096761905
5.432975879515909e-06,0.0156375275055011,292.1039531698099,170.65223387071364,3.4591303096761905
5.466336013862832e-06,0.01573354670934187,292.3569654099642,170.65223387071364,3.4591303096761905
5.639808712466829e-06,0.016232846569313862,293.6630461492805,170.65223387071364,3.4591303096761905
5.9667380290666706e-06,0.01717383476695339,296.0826810666009,170.65223387071364,3.4591303096761905
6.0668184321074385e-06,0.017461892378475695,296.8129740273332,170.65223387071364,3.4591303096761905
6.160226808278823e-06,0.017730746149229846,297.4903530367377,170.65223387071364,3.4591303096761905
6.193586942625745e-06,0.017826765353070616,297.73130178943893,170.65223387071364,3.4591303096761905
6.380403694968513e-06,0.018364472894578918,299.0713763821186,170.65223387071364,3.4591303096761905
6.560548420441894e-06,0.018882976595319064,300.34917183956566,170.65223387071364,3.4591303096761905
6.693988957829584e-06,0.019267053410682137,301.2868819318588,170.65223387071364,3.4591303096761905
6.800741387739737e-06,0.019574314862972595,302.0318114733081,170.65223387071364,3.4591303096761905
6.974214086343735e-06,0.02007361472294459,303.2326681943657,170.65223387071364,3.4591303096761905
7.0609504356457336e-06,0.020323264652930585,303.82872386516505,170.65223387071364,3.4591303096761905
7.1143266506008095e-06,0.020476895379075814,304.19410829558996,170.65223387071364,3.4591303096761905
7.1610308386865015e-06,0.02061132226445289,304.5129435483268,170.65223387071364,3.4591303096761905
7.1877189461640395e-06,0.020688137627525506,304.6947709966328,170.65223387071364,3.4591303096761905
7.294471376074192e-06,0.020995399079815964,305.4194631488893,170.65223387071364,3.4591303096761905
7.401223805984345e-06,0.021302660532106422,306.14003070151693,170.65223387071364,3.4591303096761905
7.474616101547574e-06,0.02151390278055611,306.6330712730898,170.65223387071364,3.4591303096761905
7.8082174450168e-06,0.022474094818963793,308.85078758571336,170.65223387071364,3.4591303096761905
7.861593659971877e-06,0.02262772554510902,309.2021638139683,170.65223387071364,3.4591303096761905
7.921641901796339e-06,0.022800560112022406,309.596351836262,170.65223387071364,3.4591303096761905
7.988362170490184e-06,0.022992598519703943,310.0329743020606,170.65223387071364,3.4591303096761905
8.108458654139105e-06,0.023338267653530708,310.81532747420056,170.65223387071364,3.4591303096761905
8.17517892283295e-06,0.023530306061212244,311.24801502828666,170.65223387071364,3.4591303096761905
8.255243245265564e-06,0.023760752150430085,311.76542640940477,170.65223387071364,3.4591303096761905
8.468748105085869e-06,0.024375275055011,313.1357104535855,170.65223387071364,3.4591303096761905
8.502108239432792e-06,0.02447129425885177,313.34859419384543,170.65223387071364,3.4591303096761905
8.675580938036789e-06,0.024970594118823766,314.4503818500861,170.65223387071364,3.4591303096761905
8.782333367946942e-06,0.025277855571114224,315.124135656522,170.65223387071364,3.4591303096761905
8.895757824726478e-06,0.025604320864172834,315.8365088091916,170.65223387071364,3.4591303096761905
8.94246201281217e-06,0.02573874774954991,316.1288082743427,170.65223387071364,3.4591303096761905
8.989166200897862e-06,0.025873174634926985,316.42051296617,170.65223387071364,3.4591303096761905
9.129278765154937e-06,0.026276455291058213,317.29210104865655,170.65223387071364,3.4591303096761905
9.209343087587551e-06,0.026506901380276057,317.7878088846033,170.65223387071364,3.4591303096761905
9.356127678714011e-06,0.026929385877175437,318.6922631436661,170.65223387071364,3.4591303096761905
9.462880108624163e-06,0.027236647329465895,319.3465758062182,170.65223387071364,3.4591303096761905
9.496240242971086e-06,0.02733266653330666,319.5504573134764,170.65223387071364,3.4591303096761905
9.556288484795547e-06,0.027505501100220046,319.91674150616944,170.65223387071364,3.4591303096761905
9.6630409147057e-06,0.027812762552510504,320.5657047275542,170.65223387071364,3.4591303096761905
9.789809425224006e-06,0.02817763552710542,321.3327281089566,170.65223387071364,3.4591303096761905
9.889889828264774e-06,0.028465693138627728,321.93554009194355,170.65223387071364,3.4591303096761905
9.98997023130554e-06,0.02875375075015003,322.5359776622296,170.65223387071364,3.4591303096761905
1.0016658338783079e-05,0.028830566113222645,322.69569756524197,170.65223387071364,3.4591303096761905
1.0070034553738155e-05,0.028984196839367874,323.0146403441891,170.65223387071364,3.4591303096761905
1.0216819144864615e-05,0.029406681336267254,323.8883513461065,170.65223387071364,3.4591303096761905
1.0416979950946151e-05,0.029982796559311863,325.07192655944084,170.65223387071364,3.4591303096761905
1.0557092515203225e-05,0.030386077215443088,325.8951572808587,170.65223387071364,3.4591303096761905
1.0597124676419532e-05,0.03050130026005201,326.12958198588825,170.65223387071364,3.4591303096761905
1.0877349804933684e-05,0.031307861572314466,327.7609914646954,170.65223387071364,3.4591303096761905
1.1044150476668298e-05,0.031787957591518305,328.7242872833895,170.65223387071364,3.4591303096761905
1.1130886825970294e-05,0.0320376075215043,329.2229577565445,170.65223387071364,3.4591303096761905
1.1250983309619217e-05,0.03238327665533107,329.9109298962177,170.65223387071364,3.4591303096761905
1.1371079793268139e-05,0.03272894578915783,330.5960439094424,170.65223387071364,3.4591303096761905
1.1484504250047678e-05,0.03305541108221645,331.2405094235865,170.65223387071364,3.4591303096761905
1.1544552491872134e-05,0.03322824564912982,331.58069185359375,170.65223387071364,3.4591303096761905
1.1818105593516903e-05,0.03401560312062413,333.12176182907996,170.65223387071364,3.4591303096761905
1.1838121674125056e-05,0.03407321464292859,333.2339738400301,170.65223387071364,3.4591303096761905
1.1924858023427054e-05,0.034322864572914585,333.719373342201,170.65223387071364,3.4591303096761905
1.2011594372729053e-05,0.03457251450290058,334.20339785104494,170.65223387071364,3.4591303096761905
1.2105002748900437e-05,0.034841368273654735,334.72313310296346,170.65223387071364,3.4591303096761905
1.2405243958022741e-05,0.03570554110822165,336.38321535687425,170.65223387071364,3.4591303096761905
1.2558700576018583e-05,0.036147229445889176,337.2256456368489,170.65223387071364,3.4591303096761905
1.2705485167145043e-05,0.03656971394278856,338.0276998740114,170.65223387071364,3.4591303096761905
1.2912318000095963e-05,0.03716503300660132,339.1517604550276,170.65223387071364,3.4591303096761905
1.2999054349397962e-05,0.03741468293658731,339.6210483277352,170.65223387071364,3.4591303096761905
1.3079118671830578e-05,0.03764512902580516,340.05315435473415,170.65223387071364,3.4591303096761905
1.3292623531650883e-05,0.03825965193038608,341.20042322877805,170.65223387071364,3.4591303096761905
1.3312639612259037e-05,0.03831726345269054,341.3076098868214,170.65223387071364,3.4591303096761905
1.3412720015299803e-05,0.03860532106421284,341.84260328519764,170.65223387071364,3.4591303096761905
1.3692945143813952e-05,0.03941188237647529,343.332365169815,170.65223387071364,3.4591303096761905
1.3766337439377183e-05,0.03962312462492498,343.72057004410283,170.65223387071364,3.4591303096761905
1.3873089869287335e-05,0.03993038607721544,344.2837939027944,170.65223387071364,3.4591303096761905
1.3966498245458719e-05,0.040199239847969595,344.77522969583873,170.65223387071364,3.4591303096761905
1.403989054102195e-05,0.04041048209641929,345.16045914677727,170.65223387071364,3.4591303096761905
1.4293427562058563e-05,0.04114022804560913,346.4852506661925,170.65223387071364,3.4591303096761905
1.444021215318502e-05,0.0415627125425085,347.24804622493633,170.65223387071364,3.4591303096761905
1.4593668771180867e-05,0.04200440088017604,348.0422880398369,170.65223387071364,3.4591303096761905
1.477381349665425e-05,0.04252290458091619,348.97051466821495,170.65223387071364,3.4591303096761905
1.482051768473994e-05,0.04265733146629326,349.21044414808256,170.65223387071364,3.4591303096761905
1.4880565926564402e-05,0.04283016603320665,349.5184920649903,170.65223387071364,3.4591303096761905
1.5427672129853933e-05,0.04440488097619524,352.30316870844996,170.65223387071364,3.4591303096761905
1.568120915089054e-05,0.04513462692538507,353.58054276330745,170.65223387071364,3.4591303096761905
1.6054842655576073e-05,0.046210042008401675,355.4484041219256,170.65223387071364,3.4591303096761905
1.6375099945306532e-05,0.04713182636527305,357.03597401859884,170.65223387071364,3.4591303096761905
1.6481852375216684e-05,0.04743908781756351,357.5624669683402,170.65223387071364,3.4591303096761905
1.6862157906771604e-05,0.04853370674134827,359.427385254695,170.65223387071364,3.4591303096761905
1.692887817546545e-05,0.0487257451490298,359.7528652987741,170.65223387071364,3.4591303096761905
1.69488942560736e-05,0.048783356671334266,359.85041170629245,170.65223387071364,3.4591303096761905
1.7015614524767447e-05,0.0489753950790158,360.1752424084896,170.65223387071364,3.4591303096761905
1.719575925024083e-05,0.04949389877975595,361.049813570837,170.65223387071364,3.4591303096761905
1.72958396532816e-05,0.04978195639127826,361.5341422577109,170.65223387071364,3.4591303096761905
1.7309183707020367e-05,0.049820364072814566,361.5986367362351,170.65223387071364,3.4591303096761905
1.732919978762852e-05,0.04987797559511903,361.69534210800174,170.65223387071364,3.4591303096761905
1.7702833292314055e-05,0.05095339067813563,363.4925892782529,170.65223387071364,3.4591303096761905
1.7836273829701745e-05,0.0513374674934987,364.13087012176743,170.65223387071364,3.4591303096761905
1.798973044769759e-05,0.05177915583116624,364.86259528739595,170.65223387071364,3.4591303096761905
1.8336675844905585e-05,0.05277775555111022,366.50801605433554,170.65223387071364,3.4591303096761905
1.852349259724835e-05,0.05331546309261852,367.38898071546356,170.65223387071364,3.4591303096761905
1.862357300028912e-05,0.05360352070414083,367.85950038705874,170.65223387071364,3.4591303096761905
1.8883782048195115e-05,0.05435247049409882,369.07825952648403,170.65223387071364,3.4591303096761905
1.8950502316888957e-05,0.05454450890178035,369.38970467426867,170.65223387071364,3.4591303096761905
1.903723866619096e-05,0.05479415883176636,369.7939447863194,170.65223387071364,3.4591303096761905
1.9110630961754187e-05,0.05500540108021604,370.1354333930891,170.65223387071364,3.4591303096761905
1.920403933792557e-05,0.05527425485097019,370.56931644272476,170.65223387071364,3.4591303096761905
1.9270759606619416e-05,0.055466293258651725,370.8787291453749,170.65223387071364,3.4591303096761905
1.9350823929052033e-05,0.055696739347869575,371.2494734483387,170.65223387071364,3.4591303096761905
1.948426446643972e-05,0.05608081616323264,371.8660539461142,170.65223387071364,3.4591303096761905
1.9571000815741723e-05,0.05633046609321865,372.2659483311891,170.65223387071364,3.4591303096761905
1.9697769326260027e-05,0.05669533906781356,372.8491682717034,170.65223387071364,3.4591303096761905
1.9731129460606953e-05,0.05679135827165434,373.0024036769087,170.65223387071364,3.4591303096761905
1.9757817568084488e-05,0.056868173634726946,373.124919263782,170.65223387071364,3.4591303096761905
1.9797849729300798e-05,0.05698339667933587,373.30857169961445,170.65223387071364,3.4591303096761905
1.9991338508512947e-05,0.057540308061612325,374.1941915581764,170.65223387071364,3.4591303096761905
2.013812309963941e-05,0.05796279255851171,374.8638129314439,170.65223387071364,3.4591303096761905
2.0164811207116944e-05,0.058039607921584316,374.9853574869832,170.65223387071364,3.4591303096761905
2.0278235663896483e-05,0.05836607321464293,375.5012235086192,170.65223387071364,3.4591303096761905
2.0318267825112786e-05,0.058481296259251844,375.68302503455254,170.65223387071364,3.4591303096761905
2.0478396469978016e-05,0.05894218843768753,376.4088385185368,170.65223387071364,3.4591303096761905
2.063185308797386e-05,0.059383876775355074,377.10233560356625,170.65223387071364,3.4591303096761905
2.083868592092478e-05,0.05997919583916783,378.03387450510223,170.65223387071364,3.4591303096761905
2.0918750243357397e-05,0.06020964192838568,378.39350126443964,170.65223387071364,3.4591303096761905
2.1052190780745085e-05,0.06059371874374875,378.9916885777727,170.65223387071364,3.4591303096761905
2.127236766743478e-05,0.06122744548909782,379.97547483847296,170.65223387071364,3.4591303096761905
2.142582428543062e-05,0.06166913382676535,380.6587969038602,170.65223387071364,3.4591303096761905
2.1465856446646928e-05,0.06178435687137428,380.836740593217,170.65223387071364,3.4591303096761905
2.1505888607863238e-05,0.0618995799159832,381.0145549075659,170.65223387071364,3.4591303096761905
2.1625985091512157e-05,0.062245249049809964,381.5472249394091,170.65223387071364,3.4591303096761905
2.1786113736377387e-05,0.06270614122824565,382.2556605303866,170.65223387071364,3.4591303096761905
2.1959586434981384e-05,0.06320544108821764,383.0208446905009,170.65223387071364,3.4591303096761905
2.2026306703675226e-05,0.06339747949589918,383.31451812331693,170.65223387071364,3.4591303096761905
2.232654791279753e-05,0.06426165233046609,384.6317787117231,170.65223387071364,3.4591303096761905
2.2453316423315836e-05,0.06462652530506101,385.1858790752138,170.65223387071364,3.4591303096761905
2.266682128313614e-05,0.06524104820964192,386.11635083323245,170.65223387071364,3.4591303096761905
2.2833621954870757e-05,0.06572114422884577,386.84090564118407,170.65223387071364,3.4591303096761905
2.3053798841560448e-05,0.06635487097419485,387.7941650969126,170.65223387071364,3.4591303096761905
2.3287319781988906e-05,0.06702700540108023,388.8013261007165,170.65223387071364,3.4591303096761905
2.3507496668678594e-05,0.06766073214642929,389.74733340158747,170.65223387071364,3.4591303096761905
2.3574216937372442e-05,0.06785277055411083,390.033319220364,170.65223387071364,3.4591303096761905
2.3907818280841666e-05,0.06881296259251851,391.45854052446435,170.65223387071364,3.4591303096761905
2.4081290979445663e-05,0.0693122624524905,392.1965892137991,170.65223387071364,3.4591303096761905
2.4188043409355818e-05,0.06961952390478096,392.64974253250773,170.65223387071364,3.4591303096761905
2.429479583926597e-05,0.06992678535707142,393.1021165330929,170.65223387071364,3.4591303096761905
2.451497272595566e-05,0.0705605121024205,394.0326969472821,170.65223387071364,3.4591303096761905
2.4735149612645348e-05,0.07119423884776956,394.96002345242766,170.65223387071364,3.4591303096761905
2.4821885961947345e-05,0.07144388877775555,395.3244493223438,170.65223387071364,3.4591303096761905
2.4921966364988116e-05,0.07173194638927786,395.7443241583106,170.65223387071364,3.4591303096761905
2.503539082176765e-05,0.07205841168233647,396.2193881759791,170.65223387071364,3.4591303096761905
2.506875095611457e-05,0.07215443088617723,396.3589530436955,170.65223387071364,3.4591303096761905
2.5215535547241033e-05,0.07257691538307662,396.97217997905415,170.65223387071364,3.4591303096761905
2.5362320138367495e-05,0.072999399879976,397.58401629547507,170.65223387071364,3.4591303096761905
2.5529120810102105e-05,0.07347949589917983,398.2776110178455,170.65223387071364,3.4591303096761905
2.5755969723661183e-05,0.07413242648529707,399.2180701907138,170.65223387071364,3.4591303096761905
2.616963538956302e-05,0.07532306461292258,400.9247504702548,170.65223387071364,3.4591303096761905
2.627638781947317e-05,0.07563032606521304,401.3634721006394,170.65223387071364,3.4591303096761905
2.6423172410599633e-05,0.07605281056211242,401.96558101906385,170.65223387071364,3.4591303096761905
2.6543268894248552e-05,0.07639847969593919,402.4572459113161,170.65223387071364,3.4591303096761905
2.6603317136073014e-05,0.07657131426285257,402.7027529601143,170.65223387071364,3.4591303096761905
2.671006956598317e-05,0.07687857571514303,403.1386769755376,170.65223387071364,3.4591303096761905
2.6790133888415785e-05,0.07710902180436088,403.4651742168615,170.65223387071364,3.4591303096761905
2.6876870237717782e-05,0.07735867173434688,403.8184504237737,170.65223387071364,3.4591303096761905
2.7130407258754392e-05,0.0780884176835367,404.8485634321144,170.65223387071364,3.4591303096761905
2.7450664548484848e-05,0.07901020204040808,406.1444082202892,170.65223387071364,3.4591303096761905
2.751071279030931e-05,0.07918303660732147,406.38672131854753,170.65223387071364,3.4591303096761905
2.7610793193350077e-05,0.07947109421884377,406.7901186032963,170.65223387071364,3.4591303096761905
2.8037802912990688e-05,0.0807001400280056,408.5049125542158,170.65223387071364,3.4591303096761905
2.8064491020468227e-05,0.08077695539107822,408.6117477524092,170.65223387071364,3.4591303096761905
2.82913399340273e-05,0.08142988597719544,409.51825274353627,170.65223387071364,3.4591303096761905
2.843812452515376e-05,0.08185237047409483,410.10330459515984,170.65223387071364,3.4591303096761905
2.857156506254145e-05,0.08223644728945789,410.63414873596184,170.65223387071364,3.4591303096761905
2.8678317492451602e-05,0.08254370874174835,411.0581282047351,170.65223387071364,3.4591303096761905
2.8818430056708677e-05,0.08294698939787958,411.613668353122,170.65223387071364,3.4591303096761905
2.8918510459749448e-05,0.08323504700940189,412.0098380098732,170.65223387071364,3.4591303096761905
2.929214396443498e-05,0.08431046209241849,413.48417063837746,170.65223387071364,3.4591303096761905
2.961907328103482e-05,0.08525145029005801,414.7682056661297,170.65223387071364,3.4591303096761905
2.9725825710944972e-05,0.08555871174234847,415.18628373552076,170.65223387071364,3.4591303096761905
2.9739169764683743e-05,0.08559711942388479,415.23850229136184,170.65223387071364,3.4591303096761905
2.9819234087116356e-05,0.08582756551310262,415.55162194554254,170.65223387071364,3.4591303096761905
2.9865938275202047e-05,0.0859619923984797,415.73412366011075,170.65223387071364,3.4591303096761905
2.9946002597634663e-05,0.08619243848769755,416.04672500238394,170.65223387071364,3.4591303096761905
3.0026066920067276e-05,0.08642288457691538,416.3590005605939,170.65223387071364,3.4591303096761905
3.0226227726148812e-05,0.08699899979996,417.1382720520749,170.65223387071364,3.4591303096761905
3.039970042475281e-05,0.08749829965993199,417.8120141652268,170.65223387071364,3.4591303096761905
3.054648501587927e-05,0.08792078415683137,418.38093332966264,170.65223387071364,3.4591303096761905
3.0639893392050655e-05,0.08818963792758552,418.7424177435826,170.65223387071364,3.4591303096761905
3.0733301768222036e-05,0.08845849169833968,419.1034726256173,170.65223387071364,3.4591303096761905
3.0920118520564804e-05,0.08899619923984797,419.8243010351262,170.65223387071364,3.4591303096761905
3.117365554160142e-05,0.08972594518903781,420.7998572721794,170.65223387071364,3.4591303096761905
3.130042405211972e-05,0.09009081816363274,421.2864746519113,170.65223387071364,3.4591303096761905
3.1467224723854334e-05,0.09057091418283657,421.92559125729167,170.65223387071364,3.4591303096761905
3.1647369449327715e-05,0.09108941788357672,422.6143549812211,170.65223387071364,3.4591303096761905
3.175412187923787e-05,0.09139667933586718,423.02178976260757,170.65223387071364,3.4591303096761905
3.186087430914802e-05,0.09170394078815763,423.42869069716005,170.65223387071364,3.4591303096761905
3.2187803625747865e-05,0.09264492898579717,424.67152988225615,170.65223387071364,3.4591303096761905
3.226786794818048e-05,0.092875375075015,424.9751470077022,170.65223387071364,3.4591303096761905
3.234126024374371e-05,0.0930866173234647,425.2532047060704,170.65223387071364,3.4591303096761905
3.2454684700523246e-05,0.09341308261652331,425.68244668666716,170.65223387071364,3.4591303096761905
3.264150145286601e-05,0.09395079015803161,426.38816029704043,170.65223387071364,3.4591303096761905
3.290171050077201e-05,0.09469973994798961,427.3684991520041,170.65223387071364,3.4591303096761905
3.292172658138016e-05,0.09475735147029406,427.4437843579607,170.65223387071364,3.4591303096761905
3.3101871306853545e-05,0.09527585517103421,428.12054980093234,170.65223387071364,3.4591303096761905
3.315524752180862e-05,0.09542948589717944,428.32079684800885,170.65223387071364,3.4591303096761905
3.326867197858816e-05,0.09575595119023805,428.745904852641,170.65223387071364,3.4591303096761905
3.334206427415139e-05,0.09596719343868775,429.0206735677446,170.65223387071364,3.4591303096761905
3.3428800623453384e-05,0.09621684336867374,429.34509630864966,170.65223387071364,3.4591303096761905
3.358892926831862e-05,0.09667773554710943,429.94316942214743,170.65223387071364,3.4591303096761905
3.37223698057063e-05,0.0970618123624725,430.44071473807645,170.65223387071364,3.4591303096761905
3.3869154396832766e-05,0.09748429685937188,430.9871285813816,170.65223387071364,3.4591303096761905
3.394254669239599e-05,0.09769553910782157,431.2599891144354,170.65223387071364,3.4591303096761905
3.402928304169799e-05,0.09794518903780756,431.58216417792863,170.65223387071364,3.4591303096761905
3.409600331039184e-05,0.0981372274454891,431.8297732690611,170.65223387071364,3.4591303096761905
3.420942776717137e-05,0.09846369273854771,432.25027548488663,170.65223387071364,3.4591303096761905
3.429616411647337e-05,0.09871334266853371,432.5714692213299,170.65223387071364,3.4591303096761905
3.4476308841946754e-05,0.09923184636927386,433.237553410024,170.65223387071364,3.4591303096761905
3.466312559428952e-05,0.09976955391078215,433.92687526540783,170.65223387071364,3.4591303096761905
3.4689813701767064e-05,0.09984636927385478,434.0252314103765,170.65223387071364,3.4591303096761905