File: datasets/aisi_316_L/data/M1/train_37.csv
Time(s),Strain(%),Stress(MPa),Temp(C),Log_SR(s-1)
0.0,0.0,0.0,173.50843830374356,3.6770053751789833
4.880705572333506e-09,2.3199999999999998e-05,4.361551425,173.50843830374356,3.6770053751789833
1.194931364260962e-08,5.68e-05,10.678281075,173.50843830374356,3.6770053751789833
1.9186221905035164e-08,9.12e-05,17.145409049999998,173.50843830374356,3.6770053751789833
2.0532623442230616e-08,9.76e-05,18.34859565,173.50843830374356,3.6770053751789833
2.389862728521924e-08,0.0001136,21.35656215,173.50843830374356,3.6770053751789833
2.9452533626150467e-08,0.00014,26.319706874999998,173.50843830374356,3.6770053751789833
3.551134054352999e-08,0.00016879999999999998,31.734046574999997,173.50843830374356,3.6770053751789833
3.668944188857601e-08,0.00017439999999999998,32.78683485,173.50843830374356,3.6770053751789833
3.9718845347265774e-08,0.00018879999999999998,35.4940047,173.50843830374356,3.6770053751789833
4.106524688446123e-08,0.0001952,36.6971913,173.50843830374356,3.6770053751789833
4.611425264894417e-08,0.0002192,41.20914105,173.50843830374356,3.6770053751789833
4.8302155146886774e-08,0.0002296,43.164319275,173.50843830374356,3.6770053751789833
5.099495822127767e-08,0.00024239999999999998,45.570692474999994,173.50843830374356,3.6770053751789833
5.6043963985760606e-08,0.00026639999999999997,50.082642224999994,173.50843830374356,3.6770053751789833
5.688546494650777e-08,0.0002704,50.83463385,173.50843830374356,3.6770053751789833
5.991486840519752e-08,0.0002848,53.541803699999996,173.50843830374356,3.6770053751789833
6.866647839696795e-08,0.00032639999999999996,61.36251659999999,173.50843830374356,3.6770053751789833
6.984457974201397e-08,0.000332,62.415304875,173.50843830374356,3.6770053751789833
7.203248223995658e-08,0.0003424,64.3704831,173.50843830374356,3.6770053751789833
7.657658742799121e-08,0.00036399999999999996,68.431237875,173.50843830374356,3.6770053751789833
8.145729300032472e-08,0.0003872,72.7927893,173.50843830374356,3.6770053751789833
8.314029492181903e-08,0.00039519999999999996,74.29677254999999,173.50843830374356,3.6770053751789833
9.222850529788833e-08,0.0004384,82.4182821,173.50843830374356,3.6770053751789833
9.710921087022184e-08,0.0004616,86.779833525,173.50843830374356,3.6770053751789833
1.0098011528965875e-07,0.00047999999999999996,90.23899499999999,173.50843830374356,3.6770053751789833
1.0636572143844054e-07,0.0005055999999999999,95.05174139999998,173.50843830374356,3.6770053751789833
1.0889022432068202e-07,0.0005176,97.307716275,173.50843830374356,3.6770053751789833
1.1023662585787747e-07,0.0005239999999999999,98.51090287499999,173.50843830374356,3.6770053751789833
1.1444413066161326e-07,0.000544,102.270861,173.50843830374356,3.6770053751789833
1.1781013450460187e-07,0.00056,105.27882749999999,173.50843830374356,3.6770053751789833
1.2083953796329164e-07,0.0005744,107.98599734999999,173.50843830374356,3.6770053751789833
1.2420554180628026e-07,0.0005903999999999999,110.99396384999999,173.50843830374356,3.6770053751789833
1.297594481472115e-07,0.0006167999999999999,115.95710857499999,173.50843830374356,3.6770053751789833
1.3161075026085522e-07,0.0006255999999999999,117.61149014999998,173.50843830374356,3.6770053751789833
1.3430355333524614e-07,0.0006384,120.01786335,173.50843830374356,3.6770053751789833
1.3699635640963706e-07,0.0006512,122.42423655,173.50843830374356,3.6770053751789833
1.4137216140552224e-07,0.000672,126.334593,173.50843830374356,3.6770053751789833
1.4187706198197057e-07,0.0006744,126.785787975,173.50843830374356,3.6770053751789833
1.4255026275056827e-07,0.0006776,127.387381275,173.50843830374356,3.6770053751789833
1.437283640956143e-07,0.0006832,128.44016955,173.50843830374356,3.6770053751789833
1.442332646720626e-07,0.0006856,128.891364525,173.50843830374356,3.6770053751789833
1.5147017293448813e-07,0.0007199999999999999,135.35849249999998,173.50843830374356,3.6770053751789833
1.5466787658532734e-07,0.0007352,138.216060675,173.50843830374356,3.6770053751789833
1.6089498369485628e-07,0.0007647999999999999,143.7807987,173.50843830374356,3.6770053751789833
1.6341948657709777e-07,0.0007768,146.036773575,173.50843830374356,3.6770053751789833
1.657756892671898e-07,0.000788,148.142350125,173.50843830374356,3.6770053751789833
1.6762699138083352e-07,0.0007968,149.79673169999998,173.50843830374356,3.6770053751789833
1.70151494263075e-07,0.0008087999999999999,152.05270657499997,173.50843830374356,3.6770053751789833
1.7217109656886817e-07,0.0008183999999999999,153.857486475,173.50843830374356,3.6770053751789833
1.7789330310194884e-07,0.0008456,158.97102952499998,173.50843830374356,3.6770053751789833
1.8226910809783405e-07,0.0008663999999999999,162.88138597499997,173.50843830374356,3.6770053751789833
1.87318113862317e-07,0.0008904,167.393335725,173.50843830374356,3.6770053751789833
1.8849621520736302e-07,0.000896,168.446124,173.50843830374356,3.6770053751789833
1.953965230854897e-07,0.0009287999999999999,174.61245532499998,173.50843830374356,3.6770053751789833
1.9893082712062777e-07,0.0009456,177.77082015,173.50843830374356,3.6770053751789833
2.0162363019501866e-07,0.0009584,180.17719335,173.50843830374356,3.6770053751789833
2.0599943519090387e-07,0.0009792,184.08754979999998,173.50843830374356,3.6770053751789833
2.1239484249258227e-07,0.0010096,189.80268615,173.50843830374356,3.6770053751789833
2.1407784441407657e-07,0.0010176,191.3066694,173.50843830374356,3.6770053751789833
2.1677064748846746e-07,0.0010304,193.71304259999997,173.50843830374356,3.6770053751789833
2.2013665133145607e-07,0.0010463999999999998,196.72100909999997,173.50843830374356,3.6770053751789833
2.2299775459799642e-07,0.00106,199.277780625,173.50843830374356,3.6770053751789833
2.2653205863313448e-07,0.0010768,202.43614545,173.50843830374356,3.6770053751789833
2.2939316189967482e-07,0.0010904,204.992916975,173.50843830374356,3.6770053751789833
2.3511536843275544e-07,0.0011175999999999998,210.10646002499996,173.50843830374356,3.6770053751789833
2.396594736207901e-07,0.0011392,214.16721479999998,173.50843830374356,3.6770053751789833
2.4033267438938787e-07,0.0011424,214.7688081,173.50843830374356,3.6770053751789833
2.418473761187327e-07,0.0011496,216.122393025,173.50843830374356,3.6770053751789833
2.524502882241469e-07,0.0012,225.59748749999997,173.50843830374356,3.6770053751789833
2.5379668976134235e-07,0.0012064,226.8006741,173.50843830374356,3.6770053751789833
2.612018982159173e-07,0.0012416,233.41820040000002,173.50843830374356,3.6770053751789833
2.660826037882508e-07,0.0012648,237.77975182499998,173.50843830374356,3.6770053751789833
2.6944860763123944e-07,0.0012808,239.18845380585856,173.50843830374356,3.6770053751789833
2.74329313203573e-07,0.001304,239.35030065174684,173.50843830374356,3.6770053751789833
2.771904164701133e-07,0.0013176,239.44465429192618,173.50843830374356,3.6770053751789833
2.7803191743086044e-07,0.0013216,239.47233297902832,173.50843830374356,3.6770053751789833
2.815662214659985e-07,0.0013384,239.58822848913306,173.50843830374356,3.6770053751789833
2.8459562492468824e-07,0.0013528,239.6871166473587,173.50843830374356,3.6770053751789833
2.8510052550113654e-07,0.0013552,239.70355801338,173.50843830374356,3.6770053751789833
2.8728842799907916e-07,0.0013656,239.77467311482732,173.50843830374356,3.6770053751789833
2.8779332857552746e-07,0.0013679999999999999,239.7910542592021,173.50843830374356,3.6770053751789833
2.898129308813206e-07,0.0013775999999999999,239.85646706554138,173.50843830374356,3.6770053751789833
2.960400379908496e-07,0.0014072,240.05704635246022,173.50843830374356,3.6770053751789833
3.0007924260243596e-07,0.0014264,240.18627256052167,173.50843830374356,3.6770053751789833
3.02435445292528e-07,0.0014376,240.2613412354679,173.50843830374356,3.6770053751789833
3.0714785067271206e-07,0.00146,240.4107977937973,173.50843830374356,3.6770053751789833
3.093357531706547e-07,0.0014704,240.4798840952064,173.50843830374356,3.6770053751789833
3.1371155816653987e-07,0.0014912,240.61748762565614,173.50843830374356,3.6770053751789833
3.1926546450747113e-07,0.0015176,240.79106501635567,173.50843830374356,3.6770053751789833
3.23136368926908e-07,0.001536,240.91134742413567,173.50843830374356,3.6770053751789833
3.2515597123270116e-07,0.0015455999999999998,240.9738803101966,173.50843830374356,3.6770053751789833
3.3188797891867845e-07,0.0015776,241.18123782535952,173.50843830374356,3.6770053751789833
3.3676868449101193e-07,0.0016007999999999999,241.33054763539369,173.50843830374356,3.6770053751789833
3.387882867968051e-07,0.0016104,241.39208386994287,173.50843830374356,3.6770053751789833
3.4164939006334547e-07,0.001624,241.47901586582472,173.50843830374356,3.6770053751789833
3.455202944827824e-07,0.0016424,241.59617917183564,173.50843830374356,3.6770053751789833
3.4753989678857554e-07,0.0016519999999999998,241.65710457342308,173.50843830374356,3.6770053751789833
3.5225230216875965e-07,0.0016744,241.7987293886656,173.50843830374356,3.6770053751789833
3.532621033216562e-07,0.0016791999999999998,241.8289812101289,173.50843830374356,3.6770053751789833
3.542719044745528e-07,0.001684,241.859199325097,173.50843830374356,3.6770053751789833
3.5612320658819654e-07,0.0016928,241.91451210160045,173.50843830374356,3.6770053751789833
3.5713300774109313e-07,0.0016975999999999998,241.94463543665327,173.50843830374356,3.6770053751789833
3.608356119683806e-07,0.0017151999999999998,242.0548046091069,173.50843830374356,3.6770053751789833
3.6336011485062207e-07,0.0017272,242.12966729519803,173.50843830374356,3.6770053751789833
3.6908232138370277e-07,0.0017544,242.29860910448454,173.50843830374356,3.6770053751789833
3.704287229208982e-07,0.0017607999999999999,242.33821129341172,173.50843830374356,3.6770053751789833
3.7278492561099023e-07,0.001772,242.4073803081567,173.50843830374356,3.6770053751789833
3.7345812637958796e-07,0.0017752,242.42711153999016,173.50843830374356,3.6770053751789833
3.742996273403351e-07,0.0017791999999999999,242.4517560839806,173.50843830374356,3.6770053751789833
3.7547772868538114e-07,0.0017848,242.48622217458643,173.50843830374356,3.6770053751789833
3.776656311833237e-07,0.0017951999999999998,242.55011894278067,173.50843830374356,3.6770053751789833
3.7918033291266865e-07,0.0018024,242.5942706229619,173.50843830374356,3.6770053751789833
3.822097363713584e-07,0.0018168,242.68236816843225,173.50843830374356,3.6770053751789833
3.8574404040649646e-07,0.0018336,242.7848051888705,173.50843830374356,3.6770053751789833
3.884368434808874e-07,0.0018464,242.8626069446124,173.50843830374356,3.6770053751789833
3.899515452102322e-07,0.0018536,242.90627798871498,173.50843830374356,3.6770053751789833
3.9449565039826683e-07,0.0018751999999999998,243.03689589723206,173.50843830374356,3.6770053751789833
3.9651525270406e-07,0.0018847999999999998,243.09475981461154,173.50843830374356,3.6770053751789833
4.030789601978879e-07,0.001916,243.28202868207455,173.50843830374356,3.6770053751789833
4.061083636565776e-07,0.0019303999999999999,243.3680589768151,173.50843830374356,3.6770053751789833
4.0829626615452023e-07,0.0019408,243.4300363888499,173.50843830374356,3.6770053751789833
4.098109678838651e-07,0.0019479999999999999,243.4728679739029,173.50843830374356,3.6770053751789833
4.1452337326404917e-07,0.0019703999999999998,243.60572865788166,173.50843830374356,3.6770053751789833
4.167112757619918e-07,0.0019808,243.66721361842798,173.50843830374356,3.6770053751789833
4.227700826793713e-07,0.0020096,243.83682606786215,173.50843830374356,3.6770053751789833
4.2781908844385427e-07,0.0020336,243.97744681121574,173.50843830374356,3.6770053751789833
4.30848491902544e-07,0.002048,244.0615086162187,173.50843830374356,3.6770053751789833
4.3185829305544064e-07,0.0020528,244.08947795144252,173.50843830374356,3.6770053751789833
4.338778953612338e-07,0.0020624,244.1453402214937,173.50843830374356,3.6770053751789833
4.409465034315099e-07,0.0020959999999999998,244.34006454317134,173.50843830374356,3.6770053751789833
4.4313440592945255e-07,0.0021064,244.40008913300278,173.50843830374356,3.6770053751789833
4.439759068901996e-07,0.0021103999999999997,244.42314472393872,173.50843830374356,3.6770053751789833
4.4751021092533774e-07,0.0021272,244.5197926895435,173.50843830374356,3.6770053751789833
4.5188601592122287e-07,0.0021479999999999997,244.63904062154515,173.50843830374356,3.6770053751789833
4.537373180348667e-07,0.0021568,244.68935600386115,173.50843830374356,3.6770053751789833
4.581131230307519e-07,0.0021776,244.80796606671882,173.50843830374356,3.6770053751789833
4.597961249522462e-07,0.0021855999999999998,244.85346756784287,173.50843830374356,3.6770053751789833
4.633304289873842e-07,0.0022023999999999998,244.94880983573444,173.50843830374356,3.6770053751789833
4.6635983244607405e-07,0.0022168,245.03030624707984,173.50843830374356,3.6770053751789833
4.7342844051635015e-07,0.0022504,245.21966583301608,173.50843830374356,3.6770053751789833
4.779725457043847e-07,0.0022719999999999997,245.3408149769606,173.50843830374356,3.6770053751789833
4.810019491630746e-07,0.0022864,245.42133161596743,173.50843830374356,3.6770053751789833
4.838630524296148e-07,0.0023,245.49719370605695,173.50843830374356,3.6770053751789833
4.862192551197069e-07,0.0023112,245.5595370958965,173.50843830374356,3.6770053751789833
4.867241556961552e-07,0.0023136,245.57288105191836,173.50843830374356,3.6770053751789833
4.905950601155921e-07,0.002332,245.67500597305423,173.50843830374356,3.6770053751789833
5.017028727974546e-07,0.0023848,245.96632975020262,173.50843830374356,3.6770053751789833
5.033858747189489e-07,0.0023928,246.01024930034964,173.50843830374356,3.6770053751789833
5.047322762561443e-07,0.0023991999999999998,246.04534372210355,173.50843830374356,3.6770053751789833
5.070884789462364e-07,0.0024104,246.10667123382595,173.50843830374356,3.6770053751789833
5.082665802912823e-07,0.0024159999999999997,246.13729330705434,173.50843830374356,3.6770053751789833
5.114642839421215e-07,0.0024311999999999997,246.22027114410707,173.50843830374356,3.6770053751789833
5.133155860557653e-07,0.00244,246.26821846859437,173.50843830374356,3.6770053751789833
5.170181902830528e-07,0.0024576,246.36391127368125,173.50843830374356,3.6770053751789833
5.197109933574437e-07,0.0024703999999999998,246.43333825209254,173.50843830374356,3.6770053751789833
5.218988958553863e-07,0.0024808,246.4896444278892,173.50843830374356,3.6770053751789833
5.237501979690301e-07,0.0024896,246.53721624876988,173.50843830374356,3.6770053751789833
5.266113012355703e-07,0.0025031999999999997,246.61060754801176,173.50843830374356,3.6770053751789833
5.286309035413636e-07,0.0025128,246.66231957287835,173.50843830374356,3.6770053751789833
5.301456052707084e-07,0.0025199999999999997,246.70105304301867,173.50843830374356,3.6770053751789833
5.33848209497996e-07,0.0025376,246.79555360670784,173.50843830374356,3.6770053751789833
5.37382513533134e-07,0.0025544,246.88552052354703,173.50843830374356,3.6770053751789833
5.446194217955596e-07,0.0025888,247.0690216648155,173.50843830374356,3.6770053751789833
5.473122248699505e-07,0.0026016,247.137058090222,173.50843830374356,3.6770053751789833
5.488269265992954e-07,0.0026088,247.1752712067458,173.50843830374356,3.6770053751789833
5.508465289050885e-07,0.0026184,247.22615810881638,173.50843830374356,3.6770053751789833
5.553906340931231e-07,0.00264,247.34038835279995,173.50843830374356,3.6770053751789833
5.570736360146175e-07,0.0026479999999999997,247.38260327715062,173.50843830374356,3.6770053751789833
5.633007431241465e-07,0.0026776,247.5383678877659,173.50843830374356,3.6770053751789833
5.698644506179742e-07,0.0027088,247.70182697093287,173.50843830374356,3.6770053751789833
5.708742517708708e-07,0.0027136,247.7269092020753,173.50843830374356,3.6770053751789833
5.757549573432043e-07,0.0027367999999999997,247.84789690517258,173.50843830374356,3.6770053751789833
5.781111600332964e-07,0.002748,247.90616154666733,173.50843830374356,3.6770053751789833
5.794575615704917e-07,0.0027543999999999997,247.93941404558083,173.50843830374356,3.6770053751789833
5.880408713701128e-07,0.0027952,248.15069474743063,173.50843830374356,3.6770053751789833
5.898921734837565e-07,0.002804,248.19610702036422,173.50843830374356,3.6770053751789833
5.966241811697338e-07,0.002836,248.36077607552434,173.50843830374356,3.6770053751789833
5.983071830912281e-07,0.0028439999999999997,248.40182991847232,173.50843830374356,3.6770053751789833
5.988120836676764e-07,0.0028464,248.41413728575003,173.50843830374356,3.6770053751789833
5.999901850127225e-07,0.002852,248.4428387480736,173.50843830374356,3.6770053751789833
6.040293896243088e-07,0.0028712,248.54107733187666,173.50843830374356,3.6770053751789833
6.07227093275148e-07,0.0028864,248.618667962765,173.50843830374356,3.6770053751789833
6.08405194620194e-07,0.002892,248.64721379452138,173.50843830374356,3.6770053751789833
6.090783953887917e-07,0.0028951999999999997,248.66351601946346,173.50843830374356,3.6770053751789833
6.116028982710332e-07,0.0029072,248.72458687828816,173.50843830374356,3.6770053751789833
6.121077988474815e-07,0.0029096,248.7367892440795,173.50843830374356,3.6770053751789833
6.144640015375736e-07,0.0029208,248.79368179583608,173.50843830374356,3.6770053751789833
6.203545082628036e-07,0.0029487999999999997,248.93554220547162,173.50843830374356,3.6770053751789833
6.211960092235507e-07,0.0029527999999999998,248.9557650108161,173.50843830374356,3.6770053751789833
6.228790111450451e-07,0.0029608,248.9961785981793,173.50843830374356,3.6770053751789833
6.274231163330797e-07,0.0029824,249.10508312626717,173.50843830374356,3.6770053751789833
6.297793190231718e-07,0.0029936,249.16143101307813,173.50843830374356,3.6770053751789833
6.351649251719535e-07,0.0030191999999999997,249.28991835462566,173.50843830374356,3.6770053751789833
6.397090303599882e-07,0.0030407999999999998,249.39799939809134,173.50843830374356,3.6770053751789833
6.420652330500802e-07,0.003052,249.453923517999,173.50843830374356,3.6770053751789833
6.494704415046553e-07,0.0030872,249.6291662282412,173.50843830374356,3.6770053751789833
6.504802426575517e-07,0.0030919999999999997,249.65300244276676,173.50843830374356,3.6770053751789833
6.556975486141841e-07,0.0031168,249.77592707512497,173.50843830374356,3.6770053751789833
6.568756499592303e-07,0.0031224,249.80363138826914,173.50843830374356,3.6770053751789833
6.61083154762966e-07,0.0031424,249.90241756693115,173.50843830374356,3.6770053751789833
6.63439357453058e-07,0.0031536,249.95763071488693,173.50843830374356,3.6770053751789833
6.676468622567938e-07,0.0031736,250.0560357863373,173.50843830374356,3.6770053751789833
6.705079655233341e-07,0.0031872,250.12281312575607,173.50843830374356,3.6770053751789833
6.735373689820239e-07,0.0032015999999999998,250.19339753267067,173.50843830374356,3.6770053751789833
6.740422695584722e-07,0.003204,250.20514955266995,173.50843830374356,3.6770053751789833
6.774082734014608e-07,0.0032199999999999998,250.2834088008054,173.50843830374356,3.6770053751789833
6.85654982816783e-07,0.0032592,250.47450575517252,173.50843830374356,3.6770053751789833
6.881794856990244e-07,0.0032711999999999997,250.53282534564627,173.50843830374356,3.6770053751789833
6.885160860833232e-07,0.0032727999999999998,250.54059498220667,173.50843830374356,3.6770053751789833
6.922186903106107e-07,0.0032903999999999997,250.62596344348722,173.50843830374356,3.6770053751789833
6.959212945378983e-07,0.0033079999999999997,250.71115400491078,173.50843830374356,3.6770053751789833
6.994555985730363e-07,0.0033247999999999997,250.79230752162053,173.50843830374356,3.6770053751789833
7.038314035689215e-07,0.0033456,250.89256207043826,173.50843830374356,3.6770053751789833
7.07534007796209e-07,0.0033632,250.97720312213067,173.50843830374356,3.6770053751789833
7.097219102941517e-07,0.0033736,251.02713709377352,173.50843830374356,3.6770053751789833
7.129196139449908e-07,0.0033888,251.1000096585658,173.50843830374356,3.6770053751789833
7.139294150978874e-07,0.0033935999999999997,251.12299554909373,173.50843830374356,3.6770053751789833
7.178003195173242e-07,0.0034119999999999997,251.2109909164711,173.50843830374356,3.6770053751789833
7.193150212466692e-07,0.0034192,251.24537348462144,173.50843830374356,3.6770053751789833
7.215029237446117e-07,0.0034295999999999997,251.29498738653106,173.50843830374356,3.6770053751789833
7.230176254739566e-07,0.0034368,251.32930110576802,173.50843830374356,3.6770053751789833
7.265519295090947e-07,0.0034536,251.40925760819536,173.50843830374356,3.6770053751789833
7.290764323913362e-07,0.0034655999999999997,251.46627655247187,173.50843830374356,3.6770053751789833
7.294130327756351e-07,0.0034671999999999997,251.4738732564841,173.50843830374356,3.6770053751789833
7.358084400773135e-07,0.0034976,251.61795188322085,173.50843830374356,3.6770053751789833
7.400159448810492e-07,0.0035175999999999996,251.712474186331,173.50843830374356,3.6770053751789833
7.411940462260952e-07,0.0035231999999999998,251.7389028419212,173.50843830374356,3.6770053751789833
7.460747517984288e-07,0.0035464,251.84821891486627,173.50843830374356,3.6770053751789833
7.482626542963714e-07,0.0035567999999999997,251.89713210058082,173.50843830374356,3.6770053751789833
7.507871571786129e-07,0.0035688,251.95350113540263,173.50843830374356,3.6770053751789833
7.558361629430957e-07,0.0035927999999999997,252.06601793260887,173.50843830374356,3.6770053751789833
7.570142642881419e-07,0.0035984,252.09222962847417,173.50843830374356,3.6770053751789833
7.592021667860844e-07,0.0036087999999999997,252.14086632393563,173.50843830374356,3.6770053751789833
7.635779717819696e-07,0.0036295999999999998,252.23797603364287,173.50843830374356,3.6770053751789833
7.679537767778548e-07,0.0036504,252.3348689482587,173.50843830374356,3.6770053751789833
7.716563810051424e-07,0.003668,252.41668720117832,173.50843830374356,3.6770053751789833
7.748540846559815e-07,0.0036831999999999998,252.48722528297753,173.50843830374356,3.6770053751789833
7.760321860010275e-07,0.0036888,252.51318436764822,173.50843830374356,3.6770053751789833
7.765370865774759e-07,0.0036912,252.52430498423237,173.50843830374356,3.6770053751789833
7.841105952242002e-07,0.0037272,252.69077730394605,173.50843830374356,3.6770053751789833
7.844471956084991e-07,0.0037288,252.69816148414498,173.50843830374356,3.6770053751789833
7.857935971456946e-07,0.0037351999999999997,252.7276858562013,173.50843830374356,3.6770053751789833
7.864667979142923e-07,0.0037384,252.74244064327965,173.50843830374356,3.6770053751789833
7.920207042552236e-07,0.0037648,252.86398026250637,173.50843830374356,3.6770053751789833
7.933671057924189e-07,0.0037711999999999997,252.8933943011023,173.50843830374356,3.6770053751789833
8.05484719627178e-07,0.0038288,253.15725034040838,173.50843830374356,3.6770053751789833
8.069994213565229e-07,0.003836,253.1901231490124,173.50843830374356,3.6770053751789833
8.083458228937183e-07,0.0038423999999999997,253.21932322746062,173.50843830374356,3.6770053751789833
8.123850275053046e-07,0.0038615999999999998,253.30680986560677,173.50843830374356,3.6770053751789833
8.17602333461937e-07,0.0038864,253.4195627697838,173.50843830374356,3.6770053751789833
8.206317369206268e-07,0.0039008,253.48490342884352,173.50843830374356,3.6770053751789833
8.246709415322132e-07,0.00392,253.5718781625478,173.50843830374356,3.6770053751789833
8.275320447987534e-07,0.0039336,253.63338477455957,173.50843830374356,3.6770053751789833
8.367885553669721e-07,0.0039775999999999995,253.83181095427616,173.50843830374356,3.6770053751789833
8.394813584413631e-07,0.0039904,253.8893739564998,173.50843830374356,3.6770053751789833
1.0313815536102875e-06,0.004902580516103221,257.8233013618396,173.50843830374356,3.6770053751789833
1.0717816797513792e-06,0.005094618923784757,258.61381546207423,173.50843830374356,3.6770053751789833
1.1081417932783618e-06,0.00526745349069814,259.3153950467299,173.50843830374356,3.6770053751789833
1.2051020960169818e-06,0.005728345669133827,261.14370351415346,173.50843830374356,3.6770053751789833
1.277822323070947e-06,0.006074014802960592,262.4774890758627,173.50843830374356,3.6770053751789833
1.4636629033199689e-06,0.006957391478295659,265.7579852776643,173.50843830374356,3.6770053751789833
1.6050633448137898e-06,0.007629525905181036,268.1460898663749,173.50843830374356,3.6770053751789833
1.629303420498445e-06,0.007744748949789958,268.54709621044805,173.50843830374356,3.6770053751789833
1.6697035466395366e-06,0.007936787357471494,269.2103076776298,173.50843830374356,3.6770053751789833
1.8111039881333577e-06,0.008608921784356871,271.48379864749273,173.50843830374356,3.6770053751789833
1.8595841395026678e-06,0.008839367873574715,272.24719867927814,173.50843830374356,3.6770053751789833
1.960584454855397e-06,0.009319463892778556,273.8131233251727,173.50843830374356,3.6770053751789833
2.000984580996489e-06,0.009511502300460092,274.43064394588566,173.50843830374356,3.6770053751789833
2.0211846440670346e-06,0.00960752150430086,274.73757940556834,173.50843830374356,3.6770053751789833
2.069664795436345e-06,0.009837967593518704,275.46938394033293,173.50843830374356,3.6770053751789833
2.1666250981749647e-06,0.01029885977195439,276.9132369811254,173.50843830374356,3.6770053751789833
2.2029852117019474e-06,0.010471694338867774,277.4481561647825,173.50843830374356,3.6770053751789833
2.2757054387559126e-06,0.01081736347269454,278.50777467848775,173.50843830374356,3.6770053751789833
2.3161055648970045e-06,0.011009401880376076,279.0907428961146,173.50843830374356,3.6770053751789833
2.485786094689589e-06,0.011815963192638527,281.4971166977759,173.50843830374356,3.6770053751789833
2.554466309129445e-06,0.012142428485697139,282.4528031266436,173.50843830374356,3.6770053751789833
2.6069864731128643e-06,0.012392078415683136,283.1768754607757,173.50843830374356,3.6770053751789833
2.6271865361834105e-06,0.012488097619523904,283.4538471901436,173.50843830374356,3.6770053751789833
2.7079867884655938e-06,0.012872174434886977,284.55352806268263,173.50843830374356,3.6770053751789833
2.7685869776772314e-06,0.013160232046409282,285.36990960865825,173.50843830374356,3.6770053751789833
2.821107141660651e-06,0.013409881976395279,286.071819047208,173.50843830374356,3.6770053751789833
2.897867381328725e-06,0.013774754950990198,287.0885877970037,173.50843830374356,3.6770053751789833
3.0715879237354193e-06,0.014600520104020805,289.3516826902008,173.50843830374356,3.6770053751789833
3.136228125561166e-06,0.014907781556311263,290.1809483711415,173.50843830374356,3.6770053751789833
3.1847082769304764e-06,0.015138227645529106,290.79853004873974,173.50843830374356,3.6770053751789833
3.245308466142114e-06,0.015426285257051411,291.56537511298376,173.50843830374356,3.6770053751789833
3.2816685796690966e-06,0.015599119823964794,292.0228019243356,173.50843830374356,3.6770053751789833
3.358428819337171e-06,0.015963992798559715,292.98204000651583,173.50843830374356,3.6770053751789833
3.4109489833205903e-06,0.01621364272854571,293.6334393301232,173.50843830374356,3.6770053751789833
3.447309096847572e-06,0.01638647729545909,294.0821184132241,173.50843830374356,3.6770053751789833
3.511949298673319e-06,0.01669373874774955,294.8752393517422,173.50843830374356,3.6770053751789833
3.697789878922341e-06,0.017577115423084617,297.1243503298103,173.50843830374356,3.6770053751789833
3.7381900050634327e-06,0.017769153830766153,297.6074034152725,173.50843830374356,3.6770053751789833
3.827070282573835e-06,0.018191638327665533,298.66301072409095,173.50843830374356,3.6770053751789833
3.9886707871382015e-06,0.01895979195839168,300.5581189109602,173.50843830374356,3.6770053751789833
4.033110925893402e-06,0.019171034206841367,301.0739931776363,173.50843830374356,3.6770053751789833
4.121991203403804e-06,0.01959351870374075,302.09913860023784,173.50843830374356,3.6770053751789833
4.259351632283516e-06,0.02024644928985797,303.6666573839347,173.50843830374356,3.6770053751789833
4.368431972864464e-06,0.02076495299059812,304.8974501471725,173.50843830374356,3.6770053751789833
4.380552010706791e-06,0.02082256451290258,305.03346096759066,173.50843830374356,3.6770053751789833
4.63103279278156e-06,0.022013202640528105,307.8123113083961,173.50843830374356,3.6770053751789833
4.849193473943455e-06,0.023050210042008402,310.18516440285885,173.50843830374356,3.6770053751789833
4.921913700997421e-06,0.023395879175835167,310.96681417961145,173.50843830374356,3.6770053751789833
5.035034054192477e-06,0.02393358671734347,312.17382029286705,173.50843830374356,3.6770053751789833
5.063314142491241e-06,0.024068013602720543,312.4739136052835,173.50843830374356,3.6770053751789833
5.099674256018224e-06,0.024240848169633927,312.85878909695214,173.50843830374356,3.6770053751789833
5.127954344316988e-06,0.024375275055011,313.15739728524846,173.50843830374356,3.6770053751789833
5.253194735354372e-06,0.024970594118823766,314.47215973191135,173.50843830374356,3.6770053751789833
5.350155038092993e-06,0.025431486297259453,315.48166205176426,173.50843830374356,3.6770053751789833
5.378435126391757e-06,0.025565913182636527,315.7747529147697,173.50843830374356,3.6770053751789833
5.5279155931137965e-06,0.026276455291058213,317.3140757393536,173.50843830374356,3.6770053751789833
5.572355731868997e-06,0.0264876975395079,317.7685704307289,173.50843830374356,3.6770053751789833
5.588515782325433e-06,0.026564512902580516,317.9334904640687,173.50843830374356,3.6770053751789833
5.645075958922962e-06,0.026833366673334667,318.50925162431145,173.50843830374356,3.6770053751789833
5.65719599676529e-06,0.02689097819563913,318.63233581057426,173.50843830374356,3.6770053751789833
5.6773960598358354e-06,0.026986997399479896,318.8372478298014,173.50843830374356,3.6770053751789833
5.790516413030892e-06,0.027524704940988198,319.97954354538217,173.50843830374356,3.6770053751789833
5.838996564400202e-06,0.02775515103020604,320.46643094435206,173.50843830374356,3.6770053751789833
5.8834367031554036e-06,0.027966393278655733,320.9113611822073,173.50843830374356,3.6770053751789833
5.927876841910604e-06,0.02817763552710542,321.3549826412556,173.50843830374356,3.6770053751789833
6.117757434773735e-06,0.02908021604320864,323.2360296071037,173.50843830374356,3.6770053751789833
6.137957497844282e-06,0.02917623524704941,323.4347917360291,173.50843830374356,3.6770053751789833
6.1702775987571546e-06,0.02932986597319464,323.75228133686414,173.50843830374356,3.6770053751789833
6.38439826730494e-06,0.03034766953390678,325.83950380013437,173.50843830374356,3.6770053751789833
6.428838406060142e-06,0.030558911782356472,326.2692596618906,173.50843830374356,3.6770053751789833
6.594478923238618e-06,0.03134626925385077,327.8609712362921,173.50843830374356,3.6770053751789833
6.7803195034876405e-06,0.03222964592918584,329.62834736470626,173.50843830374356,3.6770053751789833
6.897479869296806e-06,0.032786557311462294,330.73285863125403,173.50843830374356,3.6770053751789833
7.0146402351059715e-06,0.03334346869373875,331.8300767971491,173.50843830374356,3.6770053751789833
7.067160399089391e-06,0.033593118623724744,332.31961073575104,173.50843830374356,3.6770053751789833
7.111600537844591e-06,0.033804360872174435,332.73272457502037,173.50843830374356,3.6770053751789833
7.196440802740884e-06,0.03420764152830566,333.5186113932301,173.50843830374356,3.6770053751789833
7.257040991952522e-06,0.034495699139827966,334.0777484607351,173.50843830374356,3.6770053751789833
7.3338012316205955e-06,0.03486057211442288,334.7833815674078,173.50843830374356,3.6770053751789833
7.450961597429761e-06,0.035417483496699334,335.8548724091543,173.50843830374356,3.6770053751789833
7.527721837097835e-06,0.035782356471294255,336.5533227177667,173.50843830374356,3.6770053751789833
7.636802177678784e-06,0.036300860172034405,337.5410980394001,173.50843830374356,3.6770053751789833
7.822642757927805e-06,0.037184236847369476,339.21139420911777,173.50843830374356,3.6770053751789833
7.976163237263956e-06,0.03791398279655932,340.5795622474176,173.50843830374356,3.6770053751789833
8.133723729214213e-06,0.038662932586517304,341.9730972791704,173.50843830374356,3.6770053751789833
8.206443956268177e-06,0.039008601720344066,342.6127125830017,173.50843830374356,3.6770053751789833
8.29936424639269e-06,0.03945029005801161,343.42679117178363,173.50843830374356,3.6770053751789833
8.388244523903089e-06,0.03987277455491098,344.2021552806217,173.50843830374356,3.6770053751789833
8.59024515460855e-06,0.04083296659331867,345.95252797600364,173.50843830374356,3.6770053751789833
8.606405205064986e-06,0.04090978195639128,346.0918605058773,173.50843830374356,3.6770053751789833
8.614485230293202e-06,0.04094818963792758,346.16148850601945,173.50843830374356,3.6770053751789833
8.675085419504843e-06,0.041236247249449895,346.68288907696444,173.50843830374356,3.6770053751789833
8.699325495189495e-06,0.041351470294058806,346.89105133720795,173.50843830374356,3.6770053751789833
8.816485860998664e-06,0.041908381676335274,347.89399734734815,173.50843830374356,3.6770053751789833
8.852845974525645e-06,0.04208121624324865,348.2041978010734,173.50843830374356,3.6770053751789833
8.87304603759619e-06,0.042177235447089415,348.3763166762535,173.50843830374356,3.6770053751789833
8.949806277264265e-06,0.042542108421684335,349.02897941666674,173.50843830374356,3.6770053751789833
8.994246416019467e-06,0.04275335067013403,349.4058389616946,173.50843830374356,3.6770053751789833
9.014446479090011e-06,0.042849369873974794,349.5768986204997,173.50843830374356,3.6770053751789833
9.11140678182863e-06,0.04331026205241048,350.3959130774648,173.50843830374356,3.6770053751789833
9.204327071953141e-06,0.04375195039007801,351.1776182076606,173.50843830374356,3.6770053751789833
9.236647172866015e-06,0.04390558111622324,351.4487934295953,173.50843830374356,3.6770053751789833
9.289167336849437e-06,0.04415523104620925,351.8886652280372,173.50843830374356,3.6770053751789833
9.345727513446963e-06,0.04442408481696339,352.3612900106935,173.50843830374356,3.6770053751789833
9.503288005397223e-06,0.04517303460692139,353.6720415289218,173.50843830374356,3.6770053751789833
9.531568093695986e-06,0.04530746149229846,353.9064047110208,173.50843830374356,3.6770053751789833
9.571968219837076e-06,0.04549949989997999,354.24073937632994,173.50843830374356,3.6770053751789833
9.681048560418025e-06,0.04601800360072014,355.1407053681558,173.50843830374356,3.6770053751789833
9.786088888384862e-06,0.04651730346069213,356.0036089582925,173.50843830374356,3.6770053751789833
9.879009178509376e-06,0.046958991798359676,356.7639401885613,173.50843830374356,3.6770053751789833
1.0004249569546758e-05,0.04755431086217243,357.7843360846227,173.50843830374356,3.6770053751789833
1.0020409620003197e-05,0.047631126225245055,357.91563623320013,173.50843830374356,3.6770053751789833
1.010524988489949e-05,0.04803440688137628,358.6036118520522,173.50843830374356,3.6770053751789833
1.0190090149795781e-05,0.048437687537507504,359.2893384790252,173.50843830374356,3.6770053751789833
1.0214330225480437e-05,0.04855291058211643,359.4848509416845,173.50843830374356,3.6770053751789833
1.0287050452534401e-05,0.04889857971594319,360.07030549576,173.50843830374356,3.6770053751789833
1.0303210502990836e-05,0.0489753950790158,360.2001870557799,173.50843830374356,3.6770053751789833
1.0339570616517821e-05,0.04914822964592919,360.4921304364786,173.50843830374356,3.6770053751789833
1.0497131108468078e-05,0.04989717943588717,361.75261970665974,173.50843830374356,3.6770053751789833
1.0598131423820807e-05,0.05037727545509102,362.5567462284705,173.50843830374356,3.6770053751789833
1.0622371499505464e-05,0.050492498499699945,362.7492912048061,173.50843830374356,3.6770053751789833
1.0646611575190116e-05,0.050607721544308856,362.94166489726115,173.50843830374356,3.6770053751789833
1.0743571877928736e-05,0.051068613722744544,363.7094576208742,173.50843830374356,3.6770053751789833
1.087689229419434e-05,0.05170234046809362,364.7607746018846,173.50843830374356,3.6770053751789833
1.0998092672617615e-05,0.05227845569113823,365.71216427767405,173.50843830374356,3.6770053751789833
1.1058692861829252e-05,0.05256651330266053,366.18632512676675,173.50843830374356,3.6770053751789833
1.107485291228569e-05,0.05264332866573315,366.31259673958806,173.50843830374356,3.6770053751789833
1.1131413088883216e-05,0.05291218243648729,366.7539826167904,173.50843830374356,3.6770053751789833
1.1309173643904022e-05,0.05375715143028606,368.1355351397544,173.50843830374356,3.6770053751789833
1.1402093934028531e-05,0.05419883976795359,368.8543382698423,173.50843830374356,3.6770053751789833
1.1466734135854279e-05,0.054506101220244046,369.3530284013432,173.50843830374356,3.6770053751789833
1.1523294312451808e-05,0.0547749549909982,369.7884835876874,173.50843830374356,3.6770053751789833
1.1648534703489191e-05,0.05537027405481096,370.7497503363517,173.50843830374356,3.6770053751789833
1.170105486747261e-05,0.055619923984796954,371.151661662909,173.50843830374356,3.6770053751789833
1.1765695069298357e-05,0.05592718543708741,371.64535723749543,173.50843830374356,3.6770053751789833
1.1814175220667668e-05,0.05615763152630526,372.01493502735025,173.50843830374356,3.6770053751789833
1.1907095510792178e-05,0.05659931986397279,372.7216434058406,173.50843830374356,3.6770053751789833
1.2008095826144909e-05,0.05707941588317664,373.48736960358224,173.50843830374356,3.6770053751789833
1.2153536280252838e-05,0.05777075415083016,374.58561724929507,173.50843830374356,3.6770053751789833
1.223837654514913e-05,0.058174034806961386,375.22389467824917,173.50843830374356,3.6770053751789833
1.2323216810045425e-05,0.058577315463092625,375.860448773021,173.50843830374356,3.6770053751789833
1.2375736974028844e-05,0.05882696539307862,376.2536496655363,173.50843830374356,3.6770053751789833
1.2561577554277863e-05,0.05971034206841368,377.6397805405107,173.50843830374356,3.6770053751789833
1.258985764257663e-05,0.05984476895379076,377.85001030860025,173.50843830374356,3.6770053751789833
1.2719138046228123e-05,0.06045929185837168,378.8087250146048,173.50843830374356,3.6770053751789833
1.2743378121912778e-05,0.0605745149029806,378.98806014572676,173.50843830374356,3.6770053751789833
1.2795898285896198e-05,0.0608241648329666,379.37616383525244,173.50843830374356,3.6770053751789833
1.2933258714775909e-05,0.06147709541908382,380.38827839122166,173.50843830374356,3.6770053751789833
1.3005978941829873e-05,0.06182276455291058,380.9224060958603,173.50843830374356,3.6770053751789833
1.302617900490042e-05,0.06191878375675135,381.070568038635,173.50843830374356,3.6770053751789833
1.307465915626973e-05,0.0621492298459692,381.425791586109,173.50843830374356,3.6770053751789833
1.3187779509464787e-05,0.06268693738747749,382.25265483977694,173.50843830374356,3.6770053751789833
1.3212019585149442e-05,0.06280216043208642,382.42947942319086,173.50843830374356,3.6770053751789833
1.3272619774361079e-05,0.06309021804360872,382.87098824164303,173.50843830374356,3.6770053751789833
1.3300899862659843e-05,0.0632246449289858,383.07675657778765,173.50843830374356,3.6770053751789833
1.3337259976186825e-05,0.06339747949589918,383.34106532681676,173.50843830374356,3.6770053751789833
1.3506940505979412e-05,0.06420404080816164,384.5708095075109,173.50843830374356,3.6770053751789833
1.3628140884402686e-05,0.06478015603120624,385.4455122738833,173.50843830374356,3.6770053751789833
1.3688741073614324e-05,0.06506821364272855,385.8817255866745,173.50843830374356,3.6770053751789833
1.3696821098842543e-05,0.06510662132426485,385.9398304058658,173.50843830374356,3.6770053751789833
1.390286174216211e-05,0.06608601720344069,387.41701704174767,173.50843830374356,3.6770053751789833
1.3919021792618545e-05,0.0661628325665133,387.53251248798784,173.50843830374356,3.6770053751789833
1.3991742019672513e-05,0.06650850170034008,388.05159620122186,173.50843830374356,3.6770053751789833
1.405234220888415e-05,0.06679655931186237,388.4833627104309,173.50843830374356,3.6770053751789833
1.4222022738676734e-05,0.06760312062412482,389.6884627233186,173.50843830374356,3.6770053751789833
1.4254342839589608e-05,0.06775675135027005,389.9173684521333,173.50843830374356,3.6770053751789833
1.4294742965730702e-05,0.0679487897579516,390.20321616450804,173.50843830374356,3.6770053751789833
1.4403823306311648e-05,0.06846729345869174,390.97343556828366,173.50843830374356,3.6770053751789833
1.4573503836104234e-05,0.0692738547709542,392.16704843638485,173.50843830374356,3.6770053751789833
1.4646224063158198e-05,0.06961952390478096,392.676936265399,173.50843830374356,3.6770053751789833
1.4924984933531731e-05,0.07094458891778356,394.62242732296346,173.50843830374356,3.6770053751789833
1.494114498398817e-05,0.07102140428085618,394.7347728575111,173.50843830374356,3.6770053751789833
1.5013865211042134e-05,0.07136707341468294,395.2397424707208,173.50843830374356,3.6770053751789833
1.5090625450710208e-05,0.07173194638927786,395.7717322125601,173.50843830374356,3.6770053751789833
1.5413826459838943e-05,0.07326825365073016,398.0002101379186,173.50843830374356,3.6770053751789833
1.5648147191457275e-05,0.07438207641528306,399.6044765866973,173.50843830374356,3.6770053751789833
1.5716827405897127e-05,0.07470854170834167,400.0729135808111,173.50843830374356,3.6770053751789833
1.582186773386397e-05,0.07520784156831367,400.7878054120755,173.50843830374356,3.6770053751789833
1.585418783477684e-05,0.0753614722944589,401.00739942893205,173.50843830374356,3.6770053751789833
1.5939028099673133e-05,0.07576475295059013,401.5830046671303,173.50843830374356,3.6770053751789833
1.5975388213200114e-05,0.0759375875175035,401.8293267054419,173.50843830374356,3.6770053751789833
1.6072348515938735e-05,0.07639847969593919,402.4851188822109,173.50843830374356,3.6770053751789833
1.614102873037859e-05,0.0767249449889978,402.94870514850186,173.50843830374356,3.6770053751789833
1.6270309134030086e-05,0.07733946789357872,403.8192564950519,173.50843830374356,3.6770053751789833
1.629858922232885e-05,0.07747389477895579,404.0093295151837,173.50843830374356,3.6770053751789833
1.6379389474611033e-05,0.07785797159431887,404.5516878465932,173.50843830374356,3.6770053751789833
1.642786962598034e-05,0.0780884176835367,404.8766020184239,173.50843830374356,3.6770053751789833
1.6468269752121436e-05,0.07828045609121825,405.1470782692873,173.50843830374356,3.6770053751789833
1.6532909953947184e-05,0.07858771754350871,405.5793026338333,173.50843830374356,3.6770053751789833
1.6848030937847697e-05,0.08008561712342468,407.67703103652934,173.50843830374356,3.6770053751789833
1.692479117751577e-05,0.0804504900980196,408.18569168290446,173.50843830374356,3.6770053751789833
1.69369112153581e-05,0.08050810162032407,408.2659242032485,173.50843830374356,3.6770053751789833
1.697327132888508e-05,0.08068093618723746,408.50648752247537,173.50843830374356,3.6770053751789833
1.698539136672741e-05,0.08073854770954192,408.5866306223239,173.50843830374356,3.6770053751789833
1.7029831505482607e-05,0.0809497899579916,408.8802980368285,173.50843830374356,3.6770053751789833
1.707427164423781e-05,0.08116103220644129,409.1736667308291,173.50843830374356,3.6770053751789833
1.7195472022661088e-05,0.0817371474294859,409.9722535068386,173.50843830374356,3.6770053751789833
1.7304552363242035e-05,0.08225565113022605,410.689106647433,173.50843830374356,3.6770053751789833
1.7389392628138327e-05,0.08265893178635728,411.24544140613847,173.50843830374356,3.6770053751789833
1.7591393258843785e-05,0.08361912382476495,412.5658045290207,173.50843830374356,3.6770053751789833
1.7773193826478695e-05,0.08448329665933187,413.7490841982482,173.50843830374356,3.6770053751789833
1.7825713990462117e-05,0.08473294658931786,414.09004051240066,173.50843830374356,3.6770053751789833
1.7942874356271283e-05,0.08528985797159433,414.84922673718455,173.50843830374356,3.6770053751789833
1.809639483560743e-05,0.08601960392078416,415.8411025060693,173.50843830374356,3.6770053751789833
1.8136794961748526e-05,0.0862116423284657,416.10157633223594,173.50843830374356,3.6770053751789833
1.8177195087889615e-05,0.08640368073614724,416.3618239739892,173.50843830374356,3.6770053751789833
1.8262035352785907e-05,0.08680696139227846,416.90761089400934,173.50843830374356,3.6770053751789833
1.8314555516769325e-05,0.08705661132226446,417.244983470866,173.50843830374356,3.6770053751789833
1.8403435794279728e-05,0.08747909581916384,417.81506338112234,173.50843830374356,3.6770053751789833
1.8468075996105476e-05,0.0877863572714543,418.2289927463293,173.50843830374356,3.6770053751789833
1.863371651328395e-05,0.08857371474294859,419.2871159385178,173.50843830374356,3.6770053751789833
1.878319698000599e-05,0.08928425685137027,420.23886278965074,173.50843830374356,3.6770053751789833
1.8896317333201047e-05,0.08982196439287858,420.95714138082815,173.50843830374356,3.6770053751789833
1.8948837497184466e-05,0.09007161432286458,421.2900576498349,173.50843830374356,3.6770053751789833
1.8989237623325558e-05,0.09026365273054611,421.54590226648844,173.50843830374356,3.6770053751789833
1.902963774946665e-05,0.09045569113822766,421.80153468757277,173.50843830374356,3.6770053751789833
1.9061957850379524e-05,0.09060932186437289,422.00588826436035,173.50843830374356,3.6770053751789833
1.9138718090047598e-05,0.09097419483896779,422.4906871953041,173.50843830374356,3.6770053751789833
1.9227598367558e-05,0.09139667933586718,423.05108697157505,173.50843830374356,3.6770053751789833
1.9304358607226074e-05,0.0917615523104621,423.53425606172647,173.50843830374356,3.6770053751789833
1.932051865768251e-05,0.09183836767353472,423.6358803289341,173.50843830374356,3.6770053751789833
1.9393238884736477e-05,0.09218403680736148,424.09277991976495,173.50843830374356,3.6770053751789833
1.946191909917633e-05,0.09251050210042008,424.52368306269113,173.50843830374356,3.6770053751789833
1.9554839389300843e-05,0.09295219043808763,425.1057269048819,173.50843830374356,3.6770053751789833
1.9587159490213717e-05,0.09310582116423285,425.3079239694369,173.50843830374356,3.6770053751789833
1.970835986863699e-05,0.09368193638727745,426.0650068881204,173.50843830374356,3.6770053751789833
1.9777040083076846e-05,0.09400840168033607,426.49321450837255,173.50843830374356,3.6770053751789833
1.9869960373201356e-05,0.0944500900180036,427.0716322736604,173.50843830374356,3.6770053751789833
1.9975000701168196e-05,0.0949493898779756,427.7242270521778,173.50843830374356,3.6770053751789833
2.0047720928222162e-05,0.09529505901180237,428.1752396326394,173.50843830374356,3.6770053751789833
2.009620107959147e-05,0.0955255051010202,428.4755602747502,173.50843830374356,3.6770053751789833
2.01083211174338e-05,0.09558311662332467,428.5505962701162,173.50843830374356,3.6770053751789833
2.0152761256189e-05,0.09579435887177436,428.82557747563703,173.50843830374356,3.6770053751789833
2.0225481483242965e-05,0.09614002800560112,429.275037160918,173.50843830374356,3.6770053751789833
2.0326481798595694e-05,0.09662012402480497,429.8982425778434,173.50843830374356,3.6770053751789833
2.0383041975193223e-05,0.09688897779555912,430.2467100665107,173.50843830374356,3.6770053751789833
2.0463842227475404e-05,0.09727305461092219,430.7438673055732,173.50843830374356,3.6770053751789833
2.0496162328388278e-05,0.09742668533706741,430.9425157714912,173.50843830374356,3.6770053751789833
2.058504260589868e-05,0.0978491698339668,431.4881701312973,173.50843830374356,3.6770053751789833
2.06375627698821e-05,0.0980988197639528,431.8101703734341,173.50843830374356,3.6770053751789833
2.074260309784894e-05,0.09859811962392478,432.4532136990177,173.50843830374356,3.6770053751789833
2.083552338797345e-05,0.09903980796159233,433.0210018398772,173.50843830374356,3.6770053751789833
2.0916323640255635e-05,0.09942388477695539,433.51392840619974,173.50843830374356,3.6770053751789833
2.098096384208138e-05,0.09973114622924585,433.90773517363704,173.50843830374356,3.6770053751789833
2.1029443993450693e-05,0.0999615923184637,434.2027798010865,173.50843830374356,3.6770053751789833