File: datasets/aisi_316_L/data/M1/train_94.csv
Time(s),Strain(%),Stress(MPa),Temp(C),Log_SR(s-1)
0.0,0.0,0.0,365.89186542630387,0.26509442209024936
1.2600667819888927e-05,2.3199999999999998e-05,3.9936944,365.89186542630387,0.26509442209024936
2.21597951315288e-05,4.0799999999999996e-05,7.0233935999999995,365.89186542630387,0.26509442209024936
2.60703472135633e-05,4.8e-05,8.262816,365.89186542630387,0.26509442209024936
3.3456945590739566e-05,6.159999999999999e-05,10.603947199999999,365.89186542630387,0.26509442209024936
5.3878717574697485e-05,9.92e-05,17.0764864,365.89186542630387,0.26509442209024936
5.909278701741014e-05,0.00010879999999999999,18.7290496,365.89186542630387,0.26509442209024936
6.82174085421573e-05,0.0001256,21.621035199999998,365.89186542630387,0.26509442209024936
7.125894905040635e-05,0.0001312,22.585030399999997,365.89186542630387,0.26509442209024936
8.299060529650983e-05,0.0001528,26.3032976,365.89186542630387,0.26509442209024936
8.690115737854432e-05,0.00015999999999999999,27.54272,365.89186542630387,0.26509442209024936
9.037720367368609e-05,0.00016639999999999998,28.644428799999996,365.89186542630387,0.26509442209024936
9.385324996882787e-05,0.0001728,29.7461376,365.89186542630387,0.26509442209024936
0.00010167435413289686,0.0001872,32.2249824,365.89186542630387,0.26509442209024936
0.00011036446987075129,0.00020319999999999998,34.979254399999995,365.89186542630387,0.26509442209024936
0.00011905458560860573,0.0002192,37.733526399999995,365.89186542630387,0.26509442209024936
0.00013078624185470922,0.0002408,41.4517936,365.89186542630387,0.26509442209024936
0.0001360003112974219,0.0002504,43.104356800000005,365.89186542630387,0.26509442209024936
0.0001425178981008127,0.0002624,45.170060799999995,365.89186542630387,0.26509442209024936
0.00015251153119934528,0.0002808,48.337473599999996,365.89186542630387,0.26509442209024936
0.000168588245314376,0.0003104,53.4328768,365.89186542630387,0.26509442209024936
0.00017554033790465954,0.0003232,55.6362944,365.89186542630387,0.26509442209024936
0.0001829269362818358,0.0003368,57.977425600000004,365.89186542630387,0.26509442209024936
0.0001946585925279393,0.0003584,61.695692799999996,365.89186542630387,0.26509442209024936
0.00020117617933133013,0.0003704,63.7613968,365.89186542630387,0.26509442209024936
0.00021464585872500448,0.00039519999999999996,68.03051839999999,365.89186542630387,0.26509442209024936
0.00022116344552839531,0.0004072,70.0962224,365.89186542630387,0.26509442209024936
0.00025201335639777857,0.000464,79.873888,365.89186542630387,0.26509442209024936
0.0002563584142667058,0.000472,81.251024,365.89186542630387,0.26509442209024936
0.00026026896634874025,0.0004792,82.4904464,365.89186542630387,0.26509442209024936
0.0002628760010700966,0.000484,83.316728,365.89186542630387,0.26509442209024936
0.0002676555647259165,0.0004927999999999999,84.83157759999999,365.89186542630387,0.26509442209024936
0.00026982809366038013,0.0004967999999999999,85.52014559999999,365.89186542630387,0.26509442209024936
0.00028894634828365994,0.000532,91.579544,365.89186542630387,0.26509442209024936
0.00029329140615258714,0.00054,92.95668,365.89186542630387,0.26509442209024936
0.00029893998138219244,0.0005503999999999999,94.74695679999999,365.89186542630387,0.26509442209024936
0.0003058920739724761,0.0005632,96.9503744,365.89186542630387,0.26509442209024936
0.000313713178136545,0.0005775999999999999,99.42921919999999,365.89186542630387,0.26509442209024936
0.0003176237302185795,0.0005848,100.6686416,365.89186542630387,0.26509442209024936
0.00032457582280886305,0.0005976,102.8720592,365.89186542630387,0.26509442209024936
0.00033674198484185926,0.00062,106.72804,365.89186542630387,0.26509442209024936
0.000340218031137001,0.0006263999999999999,107.82974879999999,365.89186542630387,0.26509442209024936
0.0003536877105306754,0.0006512,112.0988704,365.89186542630387,0.26509442209024936
0.00036498486098988616,0.000672,115.679424,365.89186542630387,0.26509442209024936
0.00037888904617045324,0.0006975999999999999,120.08625919999999,365.89186542630387,0.26509442209024936
0.0003858411387607368,0.0007103999999999999,122.28967679999998,365.89186542630387,0.26509442209024936
0.00039018619662966404,0.0007184,123.6668128,365.89186542630387,0.26509442209024936
0.00039540026607237666,0.0007279999999999999,125.31937599999999,365.89186542630387,0.26509442209024936
0.0004049593933840166,0.0007456,128.34907520000002,365.89186542630387,0.26509442209024936
0.00041495302648254914,0.0007639999999999999,131.51648799999998,365.89186542630387,0.26509442209024936
0.0004179945669907982,0.0007696,132.48048319999998,365.89186542630387,0.26509442209024936
0.0004236431422204036,0.00078,134.27076,365.89186542630387,0.26509442209024936
0.0004253811653679745,0.0007832,134.8216144,365.89186542630387,0.26509442209024936
0.00043711282161407796,0.0008047999999999999,138.5398816,365.89186542630387,0.26509442209024936
0.0004418923852698979,0.0008135999999999999,140.0547312,365.89186542630387,0.26509442209024936
0.00044493392577814696,0.0008192,141.0187264,365.89186542630387,0.26509442209024936
0.00044840997207328876,0.0008256,142.1204352,365.89186542630387,0.26509442209024936
0.0004571000878111432,0.0008416,144.8747072,365.89186542630387,0.26509442209024936
0.00046014162831939224,0.0008472,145.8387024,365.89186542630387,0.26509442209024936
0.00046883174405724665,0.0008632,148.5929744,365.89186542630387,0.26509442209024936
0.00047100427299171026,0.0008671999999999999,149.28154239999998,365.89186542630387,0.26509442209024936
0.00047448031928685205,0.0008736,150.3832512,365.89186542630387,0.26509442209024936
0.0004909915391887754,0.000904,155.616368,365.89186542630387,0.26509442209024936
0.0004983781375659517,0.0009176,157.9574992,365.89186542630387,0.26509442209024936
0.0005066337475169134,0.0009327999999999999,160.57405759999997,365.89186542630387,0.26509442209024936
0.0005274900252877641,0.0009712,165.41756344191708,365.89186542630387,0.26509442209024936
0.0005309660715829058,0.0009776,165.452368096011,365.89186542630387,0.26509442209024936
0.0005379181641731894,0.0009904,165.52171195448145,365.89186542630387,0.26509442209024936
0.0005422632220421166,0.0009984,165.56487442044352,365.89186542630387,0.26509442209024936
0.0005453047625503657,0.001004,165.59500792670076,365.89186542630387,0.26509442209024936
0.0005600779593047182,0.0010312,165.74044840927954,365.89186542630387,0.26509442209024936
0.0005700715924032508,0.0010496,165.83798716686854,365.89186542630387,0.26509442209024936
0.0005735476386983926,0.0010559999999999999,165.87175707714974,365.89186542630387,0.26509442209024936
0.0005926658933216722,0.0010911999999999999,166.0560841369077,365.89186542630387,0.26509442209024936
0.000603963043780883,0.001112,166.1639147222707,365.89186542630387,0.26509442209024936
0.0006065700785022395,0.0011168,166.18868665266908,365.89186542630387,0.26509442209024936
0.0006109151363711667,0.0011248,166.22988112849958,365.89186542630387,0.26509442209024936
0.0006217777810434846,0.0011447999999999999,166.33237053241305,365.89186542630387,0.26509442209024936
0.0006261228389124119,0.0011528,166.373170479352,365.89186542630387,0.26509442209024936
0.0006317714141420172,0.0011631999999999999,166.42604570751715,365.89186542630387,0.26509442209024936
0.0006365509777978371,0.0011719999999999999,166.47064243566942,365.89186542630387,0.26509442209024936
0.0006387235067323008,0.001176,166.49087048525112,365.89186542630387,0.26509442209024936
0.0006526276919128678,0.0012016,166.61970034854747,365.89186542630387,0.26509442209024936
0.000658710772929366,0.0012128,166.6757263245182,365.89186542630387,0.26509442209024936
0.0006687044060278986,0.0012312,166.76733291911276,365.89186542630387,0.26509442209024936
0.0006756564986181821,0.0012439999999999999,166.8307445851609,365.89186542630387,0.26509442209024936
0.0006860846375036074,0.0012632,166.92538703822768,365.89186542630387,0.26509442209024936
0.0006912987069463201,0.0012728,166.97249775896933,365.89186542630387,0.26509442209024936
0.0006965127763890328,0.0012824,167.01947010340155,365.89186542630387,0.26509442209024936
0.0006986853053234964,0.0012864,167.03900141608074,365.89186542630387,0.26509442209024936
0.0007108514673564926,0.0013088,167.1479421953093,365.89186542630387,0.26509442209024936
0.0007225831236025961,0.0013304,167.2523056247695,365.89186542630387,0.26509442209024936
0.0007251901583239524,0.0013352,167.2754075132412,365.89186542630387,0.26509442209024936
0.0007312732393404505,0.0013464,167.32918632579867,365.89186542630387,0.26509442209024936
0.0007456119303079103,0.0013728,167.45526503007008,365.89186542630387,0.26509442209024936
0.0007634266675705119,0.0014056,167.61059866760195,365.89186542630387,0.26509442209024936
0.0007673372196525464,0.0014127999999999999,167.64450633286293,365.89186542630387,0.26509442209024936
0.0008003596594563933,0.0014736,167.92819900079817,365.89186542630387,0.26509442209024936
0.0008034011999646423,0.0014792,167.95409681173018,365.89186542630387,0.26509442209024936
0.0008186089025058876,0.0015072,168.08301670287614,365.89186542630387,0.26509442209024936
0.0008290370413913129,0.0015264,168.1708795390112,365.89186542630387,0.26509442209024936
0.0008464172728670218,0.0015584,168.3163657476982,365.89186542630387,0.26509442209024936
0.0008542383770310907,0.0015727999999999998,168.3814539485566,365.89186542630387,0.26509442209024936
0.0008637975043427306,0.0015903999999999998,168.46069142737383,365.89186542630387,0.26509442209024936
0.0008763981721626196,0.0016136,168.56462027809468,365.89186542630387,0.26509442209024936
0.0008781361953101904,0.0016167999999999998,168.57890942231464,365.89186542630387,0.26509442209024936
0.0008833502647529031,0.0016263999999999999,168.62171082303576,365.89186542630387,0.26509442209024936
0.0008968199441465775,0.0016512,168.73182754306075,365.89186542630387,0.26509442209024936
0.000900730496228612,0.0016584,168.76367585324957,365.89186542630387,0.26509442209024936
0.0009094206119664664,0.0016744,168.8342574434658,365.89186542630387,0.26509442209024936
0.0009115931409009301,0.0016784,168.85186168120387,365.89186542630387,0.26509442209024936
0.0009155036929829645,0.0016856,168.88350813137083,365.89186542630387,0.26509442209024936
0.0009246283145077117,0.0017024,168.95714553718815,365.89186542630387,0.26509442209024936
0.0009328839244586734,0.0017176,169.02352601009008,365.89186542630387,0.26509442209024936
0.0009407050286227423,0.0017319999999999998,169.08620175841196,365.89186542630387,0.26509442209024936
0.0009463536038523477,0.0017423999999999999,169.13134125619675,365.89186542630387,0.26509442209024936
0.0009624303179673785,0.001772,169.2592436553221,365.89186542630387,0.26509442209024936
0.0009715549394921256,0.0017888,169.3314661954489,365.89186542630387,0.26509442209024936
0.0009798105494430872,0.0018039999999999998,169.39658277266352,365.89186542630387,0.26509442209024936
0.0009858936304595854,0.0018151999999999999,169.4444265710229,365.89186542630387,0.26509442209024936
0.001003708367722187,0.0018479999999999998,169.5838826673243,365.89186542630387,0.26509442209024936
0.0010137020008207196,0.0018663999999999998,169.66169140411967,365.89186542630387,0.26509442209024936
0.0010258681628537158,0.0018888,169.756012464972,365.89186542630387,0.26509442209024936
0.001055414556362421,0.0019432,169.9832798020831,365.89186542630387,0.26509442209024936
0.0010593251084444553,0.0019504,170.01317226994675,365.89186542630387,0.26509442209024936
0.0010767053399201643,0.0019824,170.14551040516955,365.89186542630387,0.26509442209024936
0.0010836574325104478,0.0019952,170.19821206635757,365.89186542630387,0.26509442209024936
0.0010971271119041223,0.00202,170.2999478036705,365.89186542630387,0.26509442209024936
0.0011079897565764401,0.0020399999999999997,170.38163837907928,365.89186542630387,0.26509442209024936
0.0011353636211506818,0.0020904,170.5861253377903,365.89186542630387,0.26509442209024936
0.0011418812079540726,0.0021024,170.63452820747403,365.89186542630387,0.26509442209024936
0.0011483987947574633,0.0021144,170.6828234501801,365.89186542630387,0.26509442209024936
0.0011592614394297814,0.0021344,170.7630786486356,365.89186542630387,0.26509442209024936
0.001161433968364245,0.0021384,170.77909443568834,365.89186542630387,0.26509442209024936
0.0011718621072496704,0.0021576,170.85580816689557,365.89186542630387,0.26509442209024936
0.0011809867287744175,0.0021744,170.92271454762377,365.89186542630387,0.26509442209024936
0.0011905458560860574,0.002192,170.99259107172762,365.89186542630387,0.26509442209024936
0.0011979324544632334,0.0022056,171.04643680699834,365.89186542630387,0.26509442209024936
0.00120053948918459,0.0022104,171.06541024833578,365.89186542630387,0.26509442209024936
0.0012048845470535169,0.0022183999999999997,171.09699698128793,365.89186542630387,0.26509442209024936
0.0012196577438078695,0.0022456,171.20406113506246,365.89186542630387,0.26509442209024936
0.0012257408248243676,0.0022567999999999998,171.24799923135598,365.89186542630387,0.26509442209024936
0.001226609836398153,0.0022584,171.25426915310996,365.89186542630387,0.26509442209024936
0.0012339964347753292,0.0022719999999999997,171.3074937239581,365.89186542630387,0.26509442209024936
0.0012426865505131839,0.002288,171.3699520495746,365.89186542630387,0.26509442209024936
0.0012557217241199654,0.002312,171.46332109437998,365.89186542630387,0.26509442209024936
0.0012744054729563524,0.0023464,171.59649354745088,365.89186542630387,0.26509442209024936
0.0012804885539728506,0.0023576,171.6396874210842,365.89186542630387,0.26509442209024936
0.0012852681176286705,0.0023664,171.67356934883202,365.89186542630387,0.26509442209024936
0.0012883096581369196,0.002372,171.69510499323542,365.89186542630387,0.26509442209024936
0.001296999773874774,0.002388,171.75652641636808,365.89186542630387,0.26509442209024936
0.0013009103259568086,0.0023952,171.78411367300052,365.89186542630387,0.26509442209024936
0.001303082854891272,0.0023991999999999998,171.79942595137106,365.89186542630387,0.26509442209024936
0.0013091659359077703,0.0024104,171.84224745390202,365.89186542630387,0.26509442209024936
0.0013130764879898046,0.0024176,171.8697345912236,365.89186542630387,0.26509442209024936
0.001325242650022801,0.00244,171.9550466712227,365.89186542630387,0.26509442209024936
0.0013317602368261917,0.0024519999999999998,172.00062390129446,365.89186542630387,0.26509442209024936
0.001339146835203368,0.0024656,172.0521730646205,365.89186542630387,0.26509442209024936
0.0013408848583509388,0.0024687999999999997,172.06428614942914,365.89186542630387,0.26509442209024936
0.0013482714567281152,0.0024824,172.1156985972354,365.89186542630387,0.26509442209024936
0.0013573960782528624,0.0024992,172.17905668130098,365.89186542630387,0.26509442209024936
0.0013604376187611113,0.0025047999999999997,172.2001391026656,365.89186542630387,0.26509442209024936
0.0013639136650562531,0.0025112,172.22421080267299,365.89186542630387,0.26509442209024936
0.001365651688203824,0.0025144,172.236237679583,365.89186542630387,0.26509442209024936
0.0013747763097285712,0.0025312,172.2992811160208,365.89186542630387,0.26509442209024936
0.0013765143328761421,0.0025344,172.31127086542327,365.89186542630387,0.26509442209024936
0.001379555873384391,0.0025399999999999997,172.33223872998983,365.89186542630387,0.26509442209024936
0.0013856389544008893,0.0025512,172.3741204502153,365.89186542630387,0.26509442209024936
0.0013947635759256364,0.002568,172.43680883020232,365.89186542630387,0.26509442209024936
0.0014086677611062034,0.0025935999999999997,172.53202729960347,365.89186542630387,0.26509442209024936
0.0014104057842537743,0.0025968,172.5439037820341,365.89186542630387,0.26509442209024936
0.0014208339231391997,0.002616,172.61504318351075,365.89186542630387,0.26509442209024936
0.0014277860157294832,0.0026287999999999997,172.6623563571473,365.89186542630387,0.26509442209024936
0.0014334345909590887,0.0026392,172.7007321891052,365.89186542630387,0.26509442209024936
0.0014429937182707285,0.0026568,172.7655418203999,365.89186542630387,0.26509442209024936
0.0014442972356314067,0.0026592,172.7743665065956,365.89186542630387,0.26509442209024936
0.0014568979034512955,0.0026823999999999997,172.85951227199035,365.89186542630387,0.26509442209024936
0.0014673260423367209,0.0027015999999999997,172.92976074980209,365.89186542630387,0.26509442209024936
0.0014729746175663264,0.002712,172.96773070115592,365.89186542630387,0.26509442209024936
0.00148470627381243,0.0027336,173.0464104004125,365.89186542630387,0.26509442209024936
0.0015086040920915295,0.0027776,173.2059378165556,365.89186542630387,0.26509442209024936
0.0015146871731080275,0.0027887999999999997,173.24638705239977,365.89186542630387,0.26509442209024936
0.001535977956665771,0.002828,173.38746315206893,365.89186542630387,0.26509442209024936
0.00154857862448566,0.0028512,173.4705979425202,365.89186542630387,0.26509442209024936
0.0015568342344366216,0.0028664,173.52492255733787,365.89186542630387,0.26509442209024936
0.0015607447865186562,0.0028736,173.55061604622077,365.89186542630387,0.26509442209024936
0.0015742144659123304,0.0028983999999999998,173.63892430056762,365.89186542630387,0.26509442209024936
0.001579863041141936,0.0029088,173.67586903762913,365.89186542630387,0.26509442209024936
0.0015881186510928976,0.002924,173.72977266005117,365.89186542630387,0.26509442209024936
0.00161245097515889,0.0029687999999999997,173.88801437419178,365.89186542630387,0.26509442209024936
0.0016150580098802463,0.0029736,173.90491342413054,365.89186542630387,0.26509442209024936
0.0016211410908967443,0.0029847999999999997,173.94430322236616,365.89186542630387,0.26509442209024936
0.0016254861487656716,0.0029928,173.97240350875194,365.89186542630387,0.26509442209024936
0.0016272241719132426,0.002996,173.9836354189909,365.89186542630387,0.26509442209024936
0.0016446044033889514,0.003028,174.0956983843288,365.89186542630387,0.26509442209024936
0.0016611156232908748,0.0030583999999999997,174.20173116027897,365.89186542630387,0.26509442209024936
0.0016645916695860166,0.0030648,174.2240013841977,365.89186542630387,0.26509442209024936
0.0016658951869466948,0.0030672,174.23234804127927,365.89186542630387,0.26509442209024936
0.0016837099242092964,0.0031,174.3461649487716,365.89186542630387,0.26509442209024936
0.0017010901556850052,0.003132,174.45675408599138,365.89186542630387,0.26509442209024936
0.001710649282996645,0.0031496,174.51739025123825,365.89186542630387,0.26509442209024936
0.0017180358813738213,0.0031631999999999997,174.56415500576364,365.89186542630387,0.26509442209024936
0.0017228154450296413,0.003172,174.5943727735562,365.89186542630387,0.26509442209024936
0.001732809078128174,0.0031904,174.65744993386883,365.89186542630387,0.26509442209024936
0.0017401956765053502,0.003204,174.70398103438714,365.89186542630387,0.26509442209024936
0.0017501893096038828,0.0032224,174.76681245526458,365.89186542630387,0.26509442209024936
0.0017549688732597028,0.0032312,174.79681279054338,365.89186542630387,0.26509442209024936
0.0017619209658499863,0.003244,174.84039282210193,365.89186542630387,0.26509442209024936
0.001773218116309197,0.0032648,174.91106761337832,365.89186542630387,0.26509442209024936
0.0017823427378339442,0.0032816,174.96802298772172,365.89186542630387,0.26509442209024936
0.0017945088998669403,0.0033039999999999996,175.04378690943707,365.89186542630387,0.26509442209024936
0.0017971159345882967,0.0033087999999999998,175.05999594283603,365.89186542630387,0.26509442209024936
0.0018040680271785802,0.0033215999999999996,175.1031752611593,365.89186542630387,0.26509442209024936
0.0018110201197688639,0.0033344,175.14628973425738,365.89186542630387,0.26509442209024936
0.0018197102355067183,0.0033504,175.20009216345932,365.89186542630387,0.26509442209024936
0.0018270968338838945,0.003364,175.24574548892684,365.89186542630387,0.26509442209024936
0.0018314418917528218,0.003372,175.2725667622648,365.89186542630387,0.26509442209024936
0.0018375249727693198,0.0033832,175.31007489017546,365.89186542630387,0.26509442209024936
0.0018401320074906762,0.003388,175.32613497435102,365.89186542630387,0.26509442209024936
0.0018509946521629943,0.003408,175.3929566991598,365.89186542630387,0.26509442209024936
0.0018566432273925996,0.0034184,175.42764354538727,365.89186542630387,0.26509442209024936
0.001867071366278025,0.0034376,175.49157286485118,365.89186542630387,0.26509442209024936
0.0018827135746061628,0.0034663999999999997,175.5872063594094,365.89186542630387,0.26509442209024936
0.001884017091966841,0.0034687999999999997,175.59516180300113,365.89186542630387,0.26509442209024936
0.0018927072077046954,0.0034847999999999997,175.64814334157435,365.89186542630387,0.26509442209024936
0.0018953142424260518,0.0034896,175.66401929236844,365.89186542630387,0.26509442209024936
0.00189661775978673,0.003492,175.6719540738516,365.89186542630387,0.26509442209024936
0.0019053078755245844,0.003508,175.72479836935173,365.89186542630387,0.26509442209024936
0.0019283366822298988,0.0035504,175.86438312449138,365.89186542630387,0.26509442209024936
0.0019313782227381477,0.0035559999999999997,175.88277012332827,365.89186542630387,0.26509442209024936
0.0019326817400988259,0.0035583999999999998,175.8906468083259,365.89186542630387,0.26509442209024936
0.001963531650968209,0.0036152,176.07646125011175,365.89186542630387,0.26509442209024936
0.0019691802261978144,0.0036255999999999997,176.11035993308525,365.89186542630387,0.26509442209024936
0.001971787260919171,0.0036303999999999998,176.12599268651803,365.89186542630387,0.26509442209024936
0.0019752633072143127,0.0036368,176.14682382427364,365.89186542630387,0.26509442209024936
0.0019852569403128453,0.0036552,176.20663385641924,365.89186542630387,0.26509442209024936
0.001996554090772056,0.003676,176.27410398454285,365.89186542630387,0.26509442209024936
0.002005678712296803,0.0036928,176.3284904588702,365.89186542630387,0.26509442209024936
0.002021320920624941,0.0037216,176.42150044839187,365.89186542630387,0.26509442209024936
0.002026100484280761,0.0037304,176.44986412187475,365.89186542630387,0.26509442209024936
0.00204348071575647,0.0037624,176.552785511092,365.89186542630387,0.26509442209024936
0.0020530398430681097,0.00378,176.60924673825272,365.89186542630387,0.26509442209024936
0.0020565158893632515,0.0037863999999999997,176.62975266193604,365.89186542630387,0.26509442209024936
0.002074765132412746,0.0038199999999999996,176.73718779622305,365.89186542630387,0.26509442209024936
0.002091276352314669,0.0038504,176.83407386523817,365.89186542630387,0.26509442209024936
0.0020973594333311674,0.0038615999999999998,176.86969347258116,365.89186542630387,0.26509442209024936
0.002109091089577271,0.0038832,176.93827485513756,365.89186542630387,0.26509442209024936
0.0021173466995282326,0.0038983999999999998,176.986446671924,365.89186542630387,0.26509442209024936
0.002121257251610267,0.0039056,177.00923932910996,365.89186542630387,0.26509442209024936
0.002142982540954903,0.0039456,177.1355680545209,365.89186542630387,0.26509442209024936
0.002153845185627221,0.0039656,177.19854504239115,365.89186542630387,0.26509442209024936
0.0021651423360864322,0.0039864,177.26390984875422,365.89186542630387,0.26509442209024936
0.0021707909113160375,0.0039968,177.29654236271747,365.89186542630387,0.26509442209024936
0.0026418890563321214,0.004864172834566914,179.91190255440492,365.89186542630387,0.26509442209024936
0.002756621530566647,0.005075415083016604,180.5204451740521,365.89186542630387,0.26509442209024936
0.002829633105079527,0.005209841968393679,180.90256105827314,365.89186542630387,0.26509442209024936
0.0030903887283398115,0.005689937987597519,182.23693493059068,365.89186542630387,0.26509442209024936
0.0032677025521568055,0.006016403280656131,183.11930230827898,365.89186542630387,0.26509442209024936
0.0033198536768088626,0.006112422484496899,183.3752418599678,365.89186542630387,0.26509442209024936
0.0034763070507650338,0.006400480096019204,184.13381361817173,365.89186542630387,0.26509442209024936
0.0036223301997907933,0.006669333866773355,184.82988508290535,365.89186542630387,0.26509442209024936
0.0037892137986773756,0.006976595319063813,185.61213031152778,365.89186542630387,0.26509442209024936
0.004143841446311363,0.007629525905181036,187.23111607500616,365.89186542630387,0.26509442209024936
0.0042690041454763,0.00785997199439888,187.7894957812469,365.89186542630387,0.26509442209024936
0.004529759768736585,0.00834006801360272,188.93268327300487,365.89186542630387,0.26509442209024936
0.0049886896656746865,0.00918503700740148,190.8841923720185,365.89186542630387,0.26509442209024936
0.005061701240187567,0.009319463892778556,191.18808221929663,365.89186542630387,0.26509442209024936
0.005364177763169498,0.009876375275055011,192.42926151282694,365.89186542630387,0.26509442209024936
0.005478910237404023,0.010087617523504702,192.89287370371983,365.89186542630387,0.26509442209024936
0.0057813867603859525,0.010644528905781155,194.09732518822497,365.89186542630387,0.26509442209024936
0.0060108517088550036,0.011067013402680535,194.99471768477142,365.89186542630387,0.26509442209024936
0.006115153958159118,0.011259051810362072,195.39819619273158,365.89186542630387,0.26509442209024936
0.006323758456767346,0.011643128625725144,196.19718983681213,365.89186542630387,0.26509442209024936
0.006521932730445163,0.012008001600320064,196.9467646004434,365.89186542630387,0.26509442209024936
0.0066262349797492764,0.0122000400080016,197.33770671682925,365.89186542630387,0.26509442209024936
0.00702258352710491,0.012929785957191438,198.80189542837758,365.89186542630387,0.26509442209024936
0.007596245898277537,0.013985997199439888,200.86525379935162,365.89186542630387,0.26509442209024936
0.007648397022929594,0.014082016403280656,201.04976475815647,365.89186542630387,0.26509442209024936
0.007857001521537822,0.01446609321864373,201.78295417283732,365.89186542630387,0.26509442209024936
0.008065606020146051,0.014850170034006802,202.50858985197996,365.89186542630387,0.26509442209024936
0.008274210518754278,0.015234246849369875,203.2269420497433,365.89186542630387,0.26509442209024936
0.008388942992988804,0.015445489097819565,203.61902383891066,365.89186542630387,0.26509442209024936
0.008514105692153742,0.01567593518703741,204.04437190550763,365.89186542630387,0.26509442209024936
0.008597547491597033,0.015829565913182637,204.3265832605335,365.89186542630387,0.26509442209024936
0.00880615199020526,0.01621364272854571,205.02747808151292,365.89186542630387,0.26509442209024936
0.008847872889926906,0.016290458091618325,205.1668767373752,365.89186542630387,0.26509442209024936
0.009087768063326368,0.016732146429285857,205.96349947247842,365.89186542630387,0.26509442209024936
0.00925465166221295,0.017039407881576315,206.51284118660217,365.89186542630387,0.26509442209024936
0.009630139759707761,0.017730746149229846,207.73492697124578,365.89186542630387,0.26509442209024936
0.00992218605775928,0.018268453690738148,208.67263326802106,365.89186542630387,0.26509442209024936
0.01006820920678504,0.0185373074614923,209.13744515142523,365.89186542630387,0.26509442209024936
0.01044369730427985,0.01922864572914583,210.3207611392357,365.89186542630387,0.26509442209024936
0.010652301802888078,0.019612722544508902,210.97098548473525,365.89186542630387,0.26509442209024936
0.011017359675452476,0.020284856971394278,212.09705262137257,365.89186542630387,0.26509442209024936
0.011319836198434408,0.020841768353670735,213.01909620726965,365.89186542630387,0.26509442209024936
0.011528440697042636,0.021225845169033808,213.64939699779407,365.89186542630387,0.26509442209024936
0.011591022046625104,0.02134106821364273,213.83761781395543,365.89186542630387,0.26509442209024936
0.011716184745790042,0.021571514302860573,214.21287465663113,365.89186542630387,0.26509442209024936
0.011883068344676624,0.02187877575515103,214.71079406662648,365.89186542630387,0.26509442209024936
0.011966510144119915,0.02203240648129626,214.95873054213862,365.89186542630387,0.26509442209024936
0.012102103068215263,0.022282056411282256,215.36019408536671,365.89186542630387,0.26509442209024936
0.01214382396793691,0.02235887177435487,215.4833679052237,365.89186542630387,0.26509442209024936
0.01260275386487501,0.02320384076815363,216.82756420933237,365.89186542630387,0.26509442209024936
0.012738346788970359,0.02345349069813963,217.22104177235042,365.89186542630387,0.26509442209024936
0.012967811737439409,0.023875975195039006,217.8832258575339,365.89186542630387,0.26509442209024936
0.013061683761813112,0.02404880976195239,218.15280035794873,365.89186542630387,0.26509442209024936
0.013092974436604345,0.02410642128425685,218.24249047976815,365.89186542630387,0.26509442209024936
0.013332869610003809,0.024548109621924386,218.92735906150907,365.89186542630387,0.26509442209024936
0.013927392431037258,0.02564272854570914,220.60424778418317,365.89186542630387,0.26509442209024936
0.014052555130202194,0.025873174634926985,220.95369306013808,365.89186542630387,0.26509442209024936
0.014146427154575899,0.02604600920184037,221.2149809832204,365.89186542630387,0.26509442209024936
0.014313310753462481,0.026353270654130827,221.67782932738814,365.89186542630387,0.26509442209024936
0.01452191525207071,0.0267373474694939,222.25344070683923,365.89186542630387,0.26509442209024936
0.014667938401096469,0.02700620124024805,222.65445144465346,365.89186542630387,0.26509442209024936
0.014730519750678937,0.027121424284856973,222.82583623765285,365.89186542630387,0.26509442209024936
0.01490783357449593,0.027447889577915583,223.30989119267494,365.89186542630387,0.26509442209024936
0.014949554474217575,0.027524704940988198,223.42345953665748,365.89186542630387,0.26509442209024936
0.015147728747895394,0.02788957791558312,223.96123017818377,365.89186542630387,0.26509442209024936
0.015231170547338685,0.028043208641728348,224.1868382437287,365.89186542630387,0.26509442209024936
0.015366763471434031,0.028292858571714343,224.55242599316898,365.89186542630387,0.26509442209024936
0.015491926170598969,0.028523304660932187,224.88877651529282,365.89186542630387,0.26509442209024936
0.015596228419903083,0.028715343068613723,225.16825980465666,365.89186542630387,0.26509442209024936
0.015909135167815426,0.029291458291658332,226.00236841438738,365.89186542630387,0.26509442209024936
0.016232472140658177,0.029886777355471093,226.85758622437316,365.89186542630387,0.26509442209024936
0.01631591394010147,0.030040408081616322,227.07720587077418,365.89186542630387,0.26509442209024936
0.01654537888857052,0.030462892578515702,227.67891280223824,365.89186542630387,0.26509442209024936
0.01659753001322258,0.030558911782356472,227.8152094550534,365.89186542630387,0.26509442209024936
0.01683742518662204,0.031000600120024004,228.4400353175092,365.89186542630387,0.26509442209024936
0.016941727435926153,0.03119263852770554,228.7106147573581,365.89186542630387,0.26509442209024936
0.017546680481890013,0.03230646129225845,230.26735077134614,365.89186542630387,0.26509442209024936
0.017849157004871948,0.03286337267453491,231.0378583954944,365.89186542630387,0.26509442209024936
0.017995180153897703,0.033132226445289056,231.4080035793879,365.89186542630387,0.26509442209024936
0.018308086901810048,0.03370834166833367,232.1972502796769,365.89186542630387,0.26509442209024936
0.018589702974931156,0.03422684536907382,232.9030855306494,365.89186542630387,0.26509442209024936
0.0186314238746528,0.034303660732146427,233.00729796982728,365.89186542630387,0.26509442209024936
0.01870443544916568,0.034438087617523504,233.18945100954573,365.89186542630387,0.26509442209024936
0.01879830747353938,0.034610922184436885,233.42324083381365,365.89186542630387,0.26509442209024936
0.018850458598191438,0.03470694138827765,233.55292731911794,365.89186542630387,0.26509442209024936
0.019038202646938843,0.03505261052210442,234.0186445313442,365.89186542630387,0.26509442209024936
0.01929895827019913,0.03553270654130826,234.66251347281084,365.89186542630387,0.26509442209024936
0.019517992993737767,0.035935987197439484,235.2007456051386,365.89186542630387,0.26509442209024936
0.019591004568250654,0.03607041408281657,235.37963216073322,365.89186542630387,0.26509442209024936
0.01968487659262435,0.03624324864972994,235.60924758073676,365.89186542630387,0.26509442209024936
0.019799609066858875,0.036454490898179634,235.88930953780476,365.89186542630387,0.26509442209024936
0.02011251581477122,0.03703060612122425,236.64991634369608,365.89186542630387,0.26509442209024936
0.020488003912266028,0.03772194438887777,237.5565794998999,365.89186542630387,0.26509442209024936
0.02085306178483043,0.03839407881576315,238.43186490259853,365.89186542630387,0.26509442209024936
0.02097822448399537,0.038624524904981,238.73058438907253,365.89186542630387,0.26509442209024936
0.021124247633021124,0.03889337867573514,239.0782133713127,365.89186542630387,0.26509442209024936
0.02136414280642059,0.03933506701340268,239.64729047175584,365.89186542630387,0.26509442209024936
0.02145801483079429,0.03950790158031606,239.8692937548999,365.89186542630387,0.26509442209024936
0.021583177529959228,0.03973834766953391,240.1647098377885,365.89186542630387,0.26509442209024936
0.02198995630224527,0.040487297459491894,241.12023060068321,365.89186542630387,0.26509442209024936
0.022313293275088027,0.041082616523304666,241.87483848565563,365.89186542630387,0.26509442209024936
0.02257404889834831,0.0415627125425085,242.48029150221475,365.89186542630387,0.26509442209024936
0.02276179294709572,0.041908381676335274,242.9145300295026,365.89186542630387,0.26509442209024936
0.022918246321051886,0.04219643928785757,243.27532944777946,365.89186542630387,0.26509442209024936
0.023241583293894637,0.04279175835167033,244.01795179555987,365.89186542630387,0.26509442209024936
0.023356315768129163,0.04300300060012002,244.28049300643028,365.89186542630387,0.26509442209024936
0.023637931841250275,0.04352150430086017,244.92278893929756,365.89186542630387,0.26509442209024936
0.02381524566506727,0.04384796959391879,245.3256668302115,365.89186542630387,0.26509442209024936
0.024128152412979605,0.04442408481696339,246.03378562487094,365.89186542630387,0.26509442209024936
0.024555791635126476,0.04521144228845769,246.99578296697842,365.89186542630387,0.26509442209024936
0.025056442431786227,0.04613322664532907,248.11376040630176,365.89186542630387,0.26509442209024936
0.025119023781368696,0.04624844968993799,248.25289242646934,365.89186542630387,0.26509442209024936
0.02547365142900268,0.04690138027605521,249.03876855263024,365.89186542630387,0.26509442209024936
0.02560924435309803,0.04715103020604121,249.33812155101413,365.89186542630387,0.26509442209024936
0.0256718257026805,0.047266253250650134,249.47607592669823,365.89186542630387,0.26509442209024936
0.025786558176915025,0.047477495499099825,249.72865212186176,365.89186542630387,0.26509442209024936
0.026193336949201066,0.04822644528905781,250.62063935115557,365.89186542630387,0.26509442209024936
0.026349790323157235,0.04851450290058011,250.96227079082257,365.89186542630387,0.26509442209024936
0.02646452279739176,0.0487257451490298,251.21229793729918,365.89186542630387,0.26509442209024936
0.026579255271626287,0.048936987397479495,251.461902698674,365.89186542630387,0.26509442209024936
0.026777429545304106,0.049301860372074416,251.89205071801592,365.89186542630387,0.26509442209024936
0.0268608713447474,0.049455491098219645,252.07279403962,365.89186542630387,0.26509442209024936
0.02713205719293809,0.049954790958191636,252.6587033310347,365.89186542630387,0.26509442209024936
0.027194638542520563,0.05007001400280056,252.79358829832609,365.89186542630387,0.26509442209024936
0.02743453371592002,0.05051170234046809,253.30952975190786,365.89186542630387,0.26509442209024936
0.027601417314806604,0.05081896379275855,253.66740828621508,365.89186542630387,0.26509442209024936
0.027705719564110724,0.051011002200440095,253.89065388861945,365.89186542630387,0.26509442209024936
0.02810206811146635,0.05174074814962992,254.73601454819294,365.89186542630387,0.26509442209024936
0.028759172282082274,0.05295059011802361,256.127359618229,365.89186542630387,0.26509442209024936
0.028800893181803917,0.05302740548109622,256.21527809297163,365.89186542630387,0.26509442209024936
0.02890519543110803,0.05321944388877775,256.4348572539537,365.89186542630387,0.26509442209024936
0.02927025330367243,0.05389157831566313,257.2009626515668,365.89186542630387,0.26509442209024936
0.029384985777906956,0.05410282056411282,257.44096782966807,365.89186542630387,0.26509442209024936
0.029645741401167245,0.05458291658331667,257.98507911598625,365.89186542630387,0.26509442209024936
0.029916927249357936,0.05508221644328866,258.5489785722439,365.89186542630387,0.26509442209024936
0.030094241073174936,0.055408681736347276,258.91660454277604,365.89186542630387,0.26509442209024936
0.030438438495878507,0.05604240848169634,259.6278288320928,365.89186542630387,0.26509442209024936
0.030501019845460976,0.05615763152630526,259.7568046450042,365.89186542630387,0.26509442209024936
0.03058446164490427,0.05631126225245049,259.9286119682922,365.89186542630387,0.26509442209024936
0.030845217268164558,0.05679135827165434,260.46433538755093,365.89186542630387,0.26509442209024936
0.030886938167886197,0.056868173634726946,260.54988695664264,365.89186542630387,0.26509442209024936
0.03123113559058978,0.05750190038007602,261.25397596486005,365.89186542630387,0.26509442209024936
0.03133543783989389,0.057693938787757554,261.4667379415421,365.89186542630387,0.26509442209024936
0.03151275166371088,0.05802040408081617,261.82780052473794,365.89186542630387,0.26509442209024936
0.031836088636553635,0.05861572314462893,262.4841755790987,365.89186542630387,0.26509442209024936
0.03187780953627528,0.058692538507701536,262.5686793542354,365.89186542630387,0.26509442209024936
0.03197168156064899,0.058865373074614924,262.7586553041109,365.89186542630387,0.26509442209024936
0.032211576734048446,0.05930706141228245,263.2431637250365,365.89186542630387,0.26509442209024936
0.03238889055786544,0.05963352670534107,263.60037465733916,365.89186542630387,0.26509442209024936
0.03247233235730873,0.0597871574314863,263.76820994691116,365.89186542630387,0.26509442209024936
0.03257663460661284,0.05997919583916783,263.97776772034206,365.89186542630387,0.26509442209024936
0.03267050663098655,0.06015203040608122,264.16614609365496,365.89186542630387,0.26509442209024936
0.03283739022987313,0.06045929185837168,264.5005205885287,365.89186542630387,0.26509442209024936
0.03370309889909728,0.06205321064212843,266.22456572178174,365.89186542630387,0.26509442209024936
0.03373438957388852,0.062110822164432894,266.2865550819831,365.89186542630387,0.26509442209024936
0.033828261598262216,0.06228365673134627,266.47238875500307,365.89186542630387,0.26509442209024936
0.033849122048123036,0.06232206441288257,266.51365780224927,365.89186542630387,0.26509442209024936
0.03396385452235756,0.06253330666133226,266.7404605096574,365.89186542630387,0.26509442209024936
0.03436020306971319,0.0632630526105221,267.52167200569164,365.89186542630387,0.26509442209024936
0.03443321464422607,0.06339747949589918,267.66519524595174,365.89186542630387,0.26509442209024936
0.03452708666859978,0.06357031406281256,267.8495508507188,365.89186542630387,0.26509442209024936
0.03512160948963323,0.06466493298659733,269.01262949209337,365.89186542630387,0.26509442209024936
0.035434516237545566,0.06524104820964192,269.62169066652115,365.89186542630387,0.26509442209024936
0.035611830061362565,0.06556751350270054,269.965894193368,365.89186542630387,0.26509442209024936
0.0357369927605275,0.06579795959191838,270.20845908498507,365.89186542630387,0.26509442209024936
0.03584129500983162,0.06598999799959993,270.4103435058122,365.89186542630387,0.26509442209024936
0.036008178608718196,0.06629725945189038,270.732882647561,365.89186542630387,0.26509442209024936
0.03644624805579547,0.06710382076415283,271.57678624149264,365.89186542630387,0.26509442209024936
0.03676958502863823,0.0676991398279656,272.1971321724484,365.89186542630387,0.26509442209024936
0.03682173615329029,0.06779515903180637,272.29698838326965,365.89186542630387,0.26509442209024936
0.03694689885245522,0.06802560512102421,272.5364185177961,365.89186542630387,0.26509442209024936
0.03759357279814073,0.06921624324864974,273.7684708117522,365.89186542630387,0.26509442209024936
0.037843898196470604,0.06967713542708542,274.24317179234805,365.89186542630387,0.26509442209024936
0.03795863067070513,0.06988837767553512,274.46033365909904,365.89186542630387,0.26509442209024936
0.03825067696875665,0.07042608521704341,275.01195735451574,365.89186542630387,0.26509442209024936
0.038438421017504054,0.07077175435087017,275.3657054063256,365.89186542630387,0.26509442209024936
0.038511432592016934,0.07090618123624726,275.50309203489127,365.89186542630387,0.26509442209024936
0.03862616506625146,0.07111742348469695,275.71878025242097,365.89186542630387,0.26509442209024936
0.038813909114998865,0.07146309261852371,276.07118643680957,365.89186542630387,0.26509442209024936
0.03904337406346792,0.0718855771154231,276.50100359474027,365.89186542630387,0.26509442209024936
0.03932499013658903,0.07240408081616324,277.0271623458669,365.89186542630387,0.26509442209024936
0.03972133868394465,0.07313382676535307,277.76519937226607,365.89186542630387,0.26509442209024936
0.03989865250776165,0.07346029205841169,278.09444341008896,365.89186542630387,0.26509442209024936
0.040211559255674,0.0740364072814563,278.67407361973636,365.89186542630387,0.26509442209024936
0.04034715217976934,0.0742860572114423,278.9247001353398,365.89186542630387,0.26509442209024936
0.040597477578099214,0.07474694938987798,279.3865339340958,365.89186542630387,0.26509442209024936
0.04066005892768168,0.0748621724344869,279.5018186892591,365.89186542630387,0.26509442209024936
0.04088952387615073,0.07528465693138628,279.92393870293864,365.89186542630387,0.26509442209024936
0.041139849274480604,0.07574554910982197,280.38338100145745,365.89186542630387,0.26509442209024936
0.04147361647225377,0.07636007201440288,280.99427832518944,365.89186542630387,0.26509442209024936
0.04185953479467899,0.07707061412282457,281.698243303138,365.89186542630387,0.26509442209024936
0.042287174016825864,0.07785797159431887,282.47536282662537,365.89186542630387,0.26509442209024936
0.04240190649106039,0.07806921384276856,282.6833360851244,365.89186542630387,0.26509442209024936
0.042610510989668615,0.07845329065813163,283.06090787710286,365.89186542630387,0.26509442209024936
0.04267309233925108,0.07856851370274055,283.1740387511198,365.89186542630387,0.26509442209024936
0.04289212706278972,0.07897179435887178,283.569488267978,365.89186542630387,0.26509442209024936
0.04322589426056289,0.0795863172634527,284.17056694671567,365.89186542630387,0.26509442209024936
0.0436013823580577,0.08027765553110623,284.8446210498385,365.89186542630387,0.26509442209024936
0.04393514955583087,0.08089217843568715,285.44188202583507,365.89186542630387,0.26509442209024936
0.04434192832811691,0.08164112822564513,286.167406675555,365.89186542630387,0.26509442209024936
0.04450881192700349,0.08194838967793559,286.464306365085,365.89186542630387,0.26509442209024936
0.04481128844998542,0.08250530106021205,287.0013328331084,365.89186542630387,0.26509442209024936
0.0448843000244983,0.08263972794558912,287.13074788043315,365.89186542630387,0.26509442209024936
0.04497817204887201,0.0828125625125025,287.2970180819947,365.89186542630387,0.26509442209024936
0.04503032317352406,0.08290858171634327,287.3893319363036,365.89186542630387,0.26509442209024936
0.04505118362338488,0.08294698939787958,287.4262458021387,365.89186542630387,0.26509442209024936
0.045145055647758586,0.08311982396479296,287.59227577475673,365.89186542630387,0.26509442209024936
0.04528064857185393,0.08336947389477896,287.8318593446083,365.89186542630387,0.26509442209024936
0.04560398554469668,0.08396479295859172,288.40204769757713,365.89186542630387,0.26509442209024936
0.04611506656628685,0.08490578115623125,289.3001080072651,365.89186542630387,0.26509442209024936
0.04630281061503425,0.08525145029005801,289.6290317804282,365.89186542630387,0.26509442209024936
0.0467200196122507,0.08601960392078416,290.35811699089675,365.89186542630387,0.26509442209024936
0.046782600961833176,0.08613482696539308,290.4672603773302,365.89186542630387,0.26509442209024936
0.046907763660998116,0.08636527305461093,290.6853764783498,365.89186542630387,0.26509442209024936
0.047199809959049634,0.08690298059611923,291.193433264444,365.89186542630387,0.26509442209024936
0.04724153085877128,0.08697979595919185,291.2659125985661,365.89186542630387,0.26509442209024936
0.047648309631057324,0.08772874574914984,291.9712827380814,365.89186542630387,0.26509442209024936
0.04783605367980473,0.0880744148829766,292.2960457113386,365.89186542630387,0.26509442209024936
0.04805508840334337,0.08847769553910782,292.6743082386789,365.89186542630387,0.26509442209024936
0.048441006725768586,0.0891882376475295,293.3391388157163,365.89186542630387,0.26509442209024936
0.04860789032465517,0.08949549909981996,293.6259930039122,365.89186542630387,0.26509442209024936
0.04882692504819381,0.08989877975595119,294.00190691723856,365.89186542630387,0.26509442209024936
0.04931714561992315,0.09080136027205442,294.84086310744783,365.89186542630387,0.26509442209024936
0.04974478484207001,0.09158871774354871,295.5700659838014,365.89186542630387,0.26509442209024936
0.04985951731630454,0.0917999599919984,295.76528931154223,365.89186542630387,0.26509442209024936
0.05017242406421688,0.09237607521504301,296.296828120203,365.89186542630387,0.26509442209024936
0.05030801698831223,0.09262572514502901,296.5267599302025,365.89186542630387,0.26509442209024936
0.050474900587198814,0.09293298659731947,296.8094214052126,365.89186542630387,0.26509442209024936
0.05056877261157252,0.09310582116423285,296.96825831032606,365.89186542630387,0.26509442209024936
0.05091297003427609,0.09373954790958192,297.5496790723043,365.89186542630387,0.26509442209024936
0.050996411833719384,0.09389317863572715,297.69039845460003,365.89186542630387,0.26509442209024936
0.051048562958371436,0.09398919783956791,297.7783024699882,365.89186542630387,0.26509442209024936
0.05113200475781473,0.09414282856571314,297.9188760819066,365.89186542630387,0.26509442209024936
0.051205016332327616,0.09427725545109022,298.04180461843106,365.89186542630387,0.26509442209024936
0.05131974880656214,0.09448849769953992,298.2348400100207,365.89186542630387,0.26509442209024936
0.051351039481353375,0.09454610922184438,298.28745680623547,365.89186542630387,0.26509442209024936
0.05147620218051831,0.09477655531106222,298.4977990700346,365.89186542630387,0.26509442209024936
0.051716097353917766,0.09521824364872974,298.9003983899087,365.89186542630387,0.26509442209024936
0.052091585451412584,0.09590958191638328,299.5290947449061,365.89186542630387,0.26509442209024936
0.05231062017495122,0.09631286257251451,299.89501809786145,365.89186542630387,0.26509442209024936
0.052414922424255335,0.09650490098019604,300.0690572462336,365.89186542630387,0.26509442209024936
0.05261309669793315,0.09686977395479096,300.399359969699,365.89186542630387,0.26509442209024936
0.05266524782258521,0.09696579315863173,300.48620105004005,365.89186542630387,0.26509442209024936
0.052811270971610966,0.09723464692938588,300.7291778375248,365.89186542630387,0.26509442209024936
0.05285299187133262,0.0973114622924585,300.79855163365863,365.89186542630387,0.26509442209024936
0.05376042144027841,0.09898219643928786,302.30218829717336,365.89186542630387,0.26509442209024936
0.054156769987634044,0.0997119423884777,302.9558397196286,365.89186542630387,0.26509442209024936
0.05424021178707733,0.09986557311462294,303.0932125158105,365.89186542630387,0.26509442209024936