File: datasets/aisi_316_L/data/M1/train_30.csv
Time(s),Strain(%),Stress(MPa),Temp(C),Log_SR(s-1)
0.0,0.0,0.0,246.73093043956652,-2.2132253293355992
0.0015685434819449119,9.6e-06,1.74827325,246.73093043956652,-2.2132253293355992
0.007973429366553302,4.88e-05,8.8870556875,246.73093043956652,-2.2132253293355992
0.013594043510189235,8.319999999999999e-05,15.151701499999998,246.73093043956652,-2.2132253293355992
0.013986179380675463,8.56e-05,15.588769812499999,246.73093043956652,-2.2132253293355992
0.01568543481944912,9.6e-05,17.4827325,246.73093043956652,-2.2132253293355992
0.020129641351626367,0.00012319999999999999,22.436173375,246.73093043956652,-2.2132253293355992
0.021044625049427567,0.0001288,23.455999437499997,246.73093043956652,-2.2132253293355992
0.023920288099659903,0.00014639999999999998,26.661167062499995,246.73093043956652,-2.2132253293355992
0.0275802228908647,0.00016879999999999998,30.7404713125,246.73093043956652,-2.2132253293355992
0.028495206588665896,0.00017439999999999998,31.760297374999997,246.73093043956652,-2.2132253293355992
0.028887342459152126,0.0001768,32.197365687499996,246.73093043956652,-2.2132253293355992
0.029933038113782066,0.00018319999999999998,33.362881187499994,246.73093043956652,-2.2132253293355992
0.03215514137987069,0.00019679999999999999,35.839601625,246.73093043956652,-2.2132253293355992
0.033331548991329375,0.000204,37.1508065625,246.73093043956652,-2.2132253293355992
0.03947501096228028,0.0002416,43.998210125,246.73093043956652,-2.2132253293355992
0.04143569031471142,0.0002536,46.1835516875,246.73093043956652,-2.2132253293355992
0.04640274467420364,0.00028399999999999996,51.7197503125,246.73093043956652,-2.2132253293355992
0.049670543594922206,0.00030399999999999996,55.361986249999994,246.73093043956652,-2.2132253293355992
0.05437617404075694,0.00033279999999999996,60.60680599999999,246.73093043956652,-2.2132253293355992
0.05568329360904437,0.0003408,62.063700374999996,246.73093043956652,-2.2132253293355992
0.05751326100464677,0.000352,64.1033525,246.73093043956652,-2.2132253293355992
0.06457170667339887,0.00039519999999999996,71.97058212499999,246.73093043956652,-2.2132253293355992
0.06640167406900127,0.00040639999999999996,74.01023425,246.73093043956652,-2.2132253293355992
0.07071516864434978,0.0004328,78.8179856875,246.73093043956652,-2.2132253293355992
0.07241442408312343,0.0004432,80.71194837499999,246.73093043956652,-2.2132253293355992
0.07346011973775338,0.0004496,81.87746387499999,246.73093043956652,-2.2132253293355992
0.07829646214041686,0.0004792,87.2679730625,246.73093043956652,-2.2132253293355992
0.0827406686725941,0.0005064,92.22141393749999,246.73093043956652,-2.2132253293355992
0.0833942284567378,0.0005103999999999999,92.94986112499998,246.73093043956652,-2.2132253293355992
0.08548561976599768,0.0005231999999999999,95.28089212499998,246.73093043956652,-2.2132253293355992
0.08862270672988752,0.0005424,98.77743862499999,246.73093043956652,-2.2132253293355992
0.09175979369377735,0.0005616,102.273985125,246.73093043956652,-2.2132253293355992
0.09241335347792105,0.0005656,103.00243231249999,246.73093043956652,-2.2132253293355992
0.09332833717572225,0.0005712,104.022258375,246.73093043956652,-2.2132253293355992
0.09659613609644081,0.0005912,107.6644943125,246.73093043956652,-2.2132253293355992
0.09868752740570069,0.0006039999999999999,109.99552531249999,246.73093043956652,-2.2132253293355992
0.10090963067178932,0.0006175999999999999,112.47224574999998,246.73093043956652,-2.2132253293355992
0.10273959806739173,0.0006288,114.511897875,246.73093043956652,-2.2132253293355992
0.10600739698811029,0.0006487999999999999,118.15413381249999,246.73093043956652,-2.2132253293355992
0.1073145165563977,0.0006567999999999999,119.61102818749998,246.73093043956652,-2.2132253293355992
0.10927519590882886,0.0006688,121.79636975,246.73093043956652,-2.2132253293355992
0.11110516330443125,0.0006799999999999999,123.83602187499999,246.73093043956652,-2.2132253293355992
0.11385011439783484,0.0006967999999999999,126.89550006249999,246.73093043956652,-2.2132253293355992
0.11620292962075221,0.0007111999999999999,129.51790993749998,246.73093043956652,-2.2132253293355992
0.11829432093001209,0.0007239999999999999,131.84894093749998,246.73093043956652,-2.2132253293355992
0.12025500028244325,0.000736,134.0342825,246.73093043956652,-2.2132253293355992
0.1210392720234157,0.0007408,134.908419125,246.73093043956652,-2.2132253293355992
0.12365351115999056,0.0007568,137.822207875,246.73093043956652,-2.2132253293355992
0.13097338074240014,0.0008016,145.980816375,246.73093043956652,-2.2132253293355992
0.1338490437926325,0.0008192,149.185984,246.73093043956652,-2.2132253293355992
0.13594043510189235,0.000832,151.517015,246.73093043956652,-2.2132253293355992
0.1372475546701798,0.0008399999999999999,152.97390937499998,246.73093043956652,-2.2132253293355992
0.14417528838210314,0.0008824,160.6954495625,246.73093043956652,-2.2132253293355992
0.14665881556184926,0.0008975999999999999,163.463548875,246.73093043956652,-2.2132253293355992
0.1492730546984241,0.0009136,166.377337625,246.73093043956652,-2.2132253293355992
0.15280227753280015,0.0009352,170.3109524375,246.73093043956652,-2.2132253293355992
0.155416516669375,0.0009511999999999999,173.22474118749997,246.73093043956652,-2.2132253293355992
0.15737719602180616,0.0009632,175.41008275,246.73093043956652,-2.2132253293355992
0.15790004384912112,0.0009664,175.9928405,246.73093043956652,-2.2132253293355992
0.16286709820861334,0.0009968,181.529039125,246.73093043956652,-2.2132253293355992
0.16691916887030436,0.0010216,185.65279730003064,246.73093043956652,-2.2132253293355992
0.17084052757516666,0.0010456,185.79571650115102,246.73093043956652,-2.2132253293355992
0.17502331019368642,0.0010712,185.94676061120694,246.73093043956652,-2.2132253293355992
0.17959822868269243,0.0010992,186.11036210711228,246.73093043956652,-2.2132253293355992
0.1816896199919523,0.001112,186.18460922109102,246.73093043956652,-2.2132253293355992
0.18626453848095828,0.00114,186.34587256074835,246.73093043956652,-2.2132253293355992
0.18861735370387564,0.0011543999999999999,186.42820600773783,246.73093043956652,-2.2132253293355992
0.19162372871093672,0.0011727999999999999,186.53282929281056,246.73093043956652,-2.2132253293355992
0.19894359829334632,0.0012175999999999999,186.784922703778,246.73093043956652,-2.2132253293355992
0.20051214177529122,0.0012272,186.83846908914782,246.73093043956652,-2.2132253293355992
0.2032570928686948,0.0012439999999999999,186.93178382664047,246.73093043956652,-2.2132253293355992
0.20861628309867328,0.0012768,187.1125652235251,246.73093043956652,-2.2132253293355992
0.2124069298467068,0.0013,187.23934293583105,246.73093043956652,-2.2132253293355992
0.2146290331127954,0.0013135999999999998,187.31325067816556,246.73093043956652,-2.2132253293355992
0.2154133048537679,0.0013184,187.33926443613885,246.73093043956652,-2.2132253293355992
0.22051107117008883,0.0013495999999999998,187.5074623910621,246.73093043956652,-2.2132253293355992
0.22103391899740382,0.0013528,187.52462727611112,246.73093043956652,-2.2132253293355992
0.2243017179181224,0.0013728,187.63155125316229,246.73093043956652,-2.2132253293355992
0.2245631418317799,0.0013744,187.6400788372435,246.73093043956652,-2.2132253293355992
0.22704666901152598,0.0013896,187.7208987099541,246.73093043956652,-2.2132253293355992
0.23371297880979186,0.0014303999999999999,187.93614934810304,246.73093043956652,-2.2132253293355992
0.23580437011905175,0.0014432,188.0031837452334,246.73093043956652,-2.2132253293355992
0.23685006577368167,0.0014495999999999999,188.03661396327533,246.73093043956652,-2.2132253293355992
0.23789576142831162,0.0014559999999999998,188.06998666865758,246.73093043956652,-2.2132253293355992
0.24103284839220143,0.0014751999999999999,188.16976320152682,246.73093043956652,-2.2132253293355992
0.24260139187414637,0.0014847999999999999,188.21946145205848,246.73093043956652,-2.2132253293355992
0.24416993535609127,0.0014944,188.26903454270362,246.73093043956652,-2.2132253293355992
0.24626132666535117,0.0015072,188.33493923053774,246.73093043956652,-2.2132253293355992
0.24769915819046734,0.001516,188.3801221349465,246.73093043956652,-2.2132253293355992
0.25279692450678826,0.0015471999999999999,188.53949834666227,246.73093043956652,-2.2132253293355992
0.2563261473411643,0.0015688,188.64910220789068,246.73093043956652,-2.2132253293355992
0.25920181039139667,0.0015864,188.7379745494673,246.73093043956652,-2.2132253293355992
0.2614239136574853,0.0015999999999999999,188.80638551679084,246.73093043956652,-2.2132253293355992
0.26429957670771764,0.0016175999999999999,188.89458165384283,246.73093043956652,-2.2132253293355992
0.26652167997380627,0.0016312,188.9624771330227,246.73093043956652,-2.2132253293355992
0.2669138158442925,0.0016336,188.97443573520033,246.73093043956652,-2.2132253293355992
0.2684823593262374,0.0016431999999999998,189.02220178397636,246.73093043956652,-2.2132253293355992
0.2746258212971883,0.0016807999999999999,189.2082469081302,246.73093043956652,-2.2132253293355992
0.2759329408654757,0.0016887999999999998,189.24762075740418,246.73093043956652,-2.2132253293355992
0.2769786365201057,0.0016952,189.27906748790113,246.73093043956652,-2.2132253293355992
0.28037714739765296,0.0017159999999999999,189.380951072178,246.73093043956652,-2.2132253293355992
0.2816842669659404,0.0017239999999999998,189.42000867899677,246.73093043956652,-2.2132253293355992
0.28455993001617275,0.0017415999999999998,189.50568746667798,246.73093043956652,-2.2132253293355992
0.28939627241883625,0.0017712,189.64902597624678,246.73093043956652,-2.2132253293355992
0.29187979959858235,0.0017863999999999998,189.72226899765002,246.73093043956652,-2.2132253293355992
0.2944940387351572,0.0018024,189.79910482557125,246.73093043956652,-2.2132253293355992
0.29501688656247216,0.0018055999999999999,189.81444001996172,246.73093043956652,-2.2132253293355992
0.2967161420012458,0.001816,189.8642063594326,246.73093043956652,-2.2132253293355992
0.30011465287879313,0.0018368,189.96340682974028,246.73093043956652,-2.2132253293355992
0.3033824517995117,0.0018567999999999998,190.0583795598947,246.73093043956652,-2.2132253293355992
0.3065195387634015,0.0018759999999999998,190.14917874440852,246.73093043956652,-2.2132253293355992
0.3088723539863189,0.0018904,190.217040482108,246.73093043956652,-2.2132253293355992
0.31004876159777756,0.0018976,190.2508957279928,246.73093043956652,-2.2132253293355992
0.3155386637845848,0.0019311999999999999,190.40822918169187,246.73093043956652,-2.2132253293355992
0.31697649530970096,0.0019399999999999999,190.44925868976165,246.73093043956652,-2.2132253293355992
0.3174993431370159,0.0019432,190.464160506616,246.73093043956652,-2.2132253293355992
0.32037500618724823,0.0019608,190.54595006483365,246.73093043956652,-2.2132253293355992
0.3208978540145632,0.001964,190.5607900815434,246.73093043956652,-2.2132253293355992
0.3216821257555356,0.0019687999999999997,190.58303243779815,246.73093043956652,-2.2132253293355992
0.32455778880576797,0.0019863999999999997,190.66440743229995,246.73093043956652,-2.2132253293355992
0.32704131598551417,0.0020016,190.7344598086466,246.73093043956652,-2.2132253293355992
0.330178402949404,0.0020208,190.8226511799281,246.73093043956652,-2.2132253293355992
0.3305705388198901,0.0020231999999999997,190.8336520777479,246.73093043956652,-2.2132253293355992
0.33200837034500635,0.002032,190.87394523428247,246.73093043956652,-2.2132253293355992
0.33815183231595725,0.0020696,191.04534592840713,246.73093043956652,-2.2132253293355992
0.3424653268913057,0.0020959999999999998,191.16496611493642,246.73093043956652,-2.2132253293355992
0.3446874301573944,0.0021096,191.22635922511566,246.73093043956652,-2.2132253293355992
0.3488702127759141,0.0021352,191.34150560652282,246.73093043956652,-2.2132253293355992
0.3504387562578591,0.0021448,191.38454653022103,246.73093043956652,-2.2132253293355992
0.35475225083320755,0.0021712,191.5025233968679,246.73093043956652,-2.2132253293355992
0.3565822182288099,0.0021823999999999997,191.55240502041067,246.73093043956652,-2.2132253293355992
0.3571050660561249,0.0021855999999999998,191.56663856271174,246.73093043956652,-2.2132253293355992
0.35854289758124114,0.0021944,191.6057389581875,246.73093043956652,-2.2132253293355992
0.36220283237244594,0.0022168,191.70499229601106,246.73093043956652,-2.2132253293355992
0.36782344651608184,0.0022512,191.8566588631842,246.73093043956652,-2.2132253293355992
0.3731826367460603,0.002284,192.00043158864136,246.73093043956652,-2.2132253293355992
0.37448975631434767,0.0022919999999999998,192.03537568251295,246.73093043956652,-2.2132253293355992
0.37579687588263516,0.0023,192.07027224075415,246.73093043956652,-2.2132253293355992
0.3785418269760387,0.0023168,192.1434013039434,246.73093043956652,-2.2132253293355992
0.38141749002627107,0.0023344,192.21979123122583,246.73093043956652,-2.2132253293355992
0.3835088813355309,0.0023472,192.275206533538,246.73093043956652,-2.2132253293355992
0.3837703052491884,0.0023488,192.28212514999225,246.73093043956652,-2.2132253293355992
0.3845545769901609,0.0023536,192.30286997945845,246.73093043956652,-2.2132253293355992
0.3879530878677082,0.0023744,192.39257424701773,246.73093043956652,-2.2132253293355992
0.38965234330648185,0.0023848,192.43731141687158,246.73093043956652,-2.2132253293355992
0.3934429900545154,0.002408,192.53683644232584,246.73093043956652,-2.2132253293355992
0.3950115335364603,0.0024176,192.57790974222127,246.73093043956652,-2.2132253293355992
0.3955343813637753,0.0024208,192.59158670068433,246.73093043956652,-2.2132253293355992
0.396710788975234,0.002428,192.62233410366647,246.73093043956652,-2.2132253293355992
0.3988021802844938,0.0024408,192.67690849601087,246.73093043956652,-2.2132253293355992
0.4033770987734998,0.0024687999999999997,192.79590235450652,246.73093043956652,-2.2132253293355992
0.40742916943519086,0.0024936,192.90085807006017,246.73093043956652,-2.2132253293355992
0.4089977129171357,0.0025031999999999997,192.94137669825335,246.73093043956652,-2.2132253293355992
0.41161195205371065,0.0025192,193.00877333071205,246.73093043956652,-2.2132253293355992
0.4147490390176004,0.0025383999999999997,193.08942932886936,246.73093043956652,-2.2132253293355992
0.4177554140246615,0.0025567999999999997,193.16650169202512,246.73093043956652,-2.2132253293355992
0.4216767727295238,0.0025808,193.26670655723345,246.73093043956652,-2.2132253293355992
0.4259902673048723,0.0026072,193.37651308992167,246.73093043956652,-2.2132253293355992
0.42951949013924834,0.0026287999999999997,193.46603261772825,246.73093043956652,-2.2132253293355992
0.4327872890599669,0.0026487999999999998,193.54866562493802,246.73093043956652,-2.2132253293355992
0.43514010428288424,0.0026631999999999997,193.60801079205424,246.73093043956652,-2.2132253293355992
0.44089143038334894,0.0026983999999999997,193.7525523585836,246.73093043956652,-2.2132253293355992
0.4424599738652939,0.002708,193.79184492458282,246.73093043956652,-2.2132253293355992
0.44272139777895136,0.0027096,193.79838840042612,246.73093043956652,-2.2132253293355992
0.4475577401816148,0.0027392,193.91917221835956,246.73093043956652,-2.2132253293355992
0.4486034358362448,0.0027456,193.94522058760816,246.73093043956652,-2.2132253293355992
0.4493877075772173,0.0027504,193.9647413271794,246.73093043956652,-2.2132253293355992
0.45147909888647714,0.0027632,194.0167317864577,246.73093043956652,-2.2132253293355992
0.45513903367768194,0.0027856,194.10748964551834,246.73093043956652,-2.2132253293355992
0.45618472933231186,0.0027919999999999998,194.13336812621662,246.73093043956652,-2.2132253293355992
0.46350459891472146,0.0028368,194.31387408920793,246.73093043956652,-2.2132253293355992
0.4674259576195837,0.0028607999999999997,194.41011623504332,246.73093043956652,-2.2132253293355992
0.4689945011015287,0.0028704,194.44852486319783,246.73093043956652,-2.2132253293355992
0.46990948479932987,0.002876,194.47090676077545,246.73093043956652,-2.2132253293355992
0.47252372393590475,0.002892,194.53476157695255,246.73093043956652,-2.2132253293355992
0.4752686750293083,0.0029088,194.6016610282139,246.73093043956652,-2.2132253293355992
0.47644508264076696,0.0029159999999999998,194.63028607346791,246.73093043956652,-2.2132253293355992
0.4777522022090544,0.002924,194.66205936977332,246.73093043956652,-2.2132253293355992
0.4848106478778065,0.0029671999999999997,194.83305287312962,246.73093043956652,-2.2132253293355992
0.48520278374829273,0.0029695999999999998,194.8425239427153,246.73093043956652,-2.2132253293355992
0.4874248870143813,0.0029831999999999997,194.8961370566006,246.73093043956652,-2.2132253293355992
0.4880784467985251,0.0029871999999999998,194.91188746772292,246.73093043956652,-2.2132253293355992
0.49252265333070233,0.0030144,195.0187729655496,246.73093043956652,-2.2132253293355992
0.49448333268313344,0.0030264,195.0658086843327,246.73093043956652,-2.2132253293355992
0.49722828377653705,0.0030432,195.13153667822382,246.73093043956652,-2.2132253293355992
0.4994503870426257,0.0030567999999999997,195.1846414675589,246.73093043956652,-2.2132253293355992
0.5020646261792004,0.0030727999999999997,195.24699986420111,246.73093043956652,-2.2132253293355992
0.5042867294452892,0.0030864,195.29990500112064,246.73093043956652,-2.2132253293355992
0.5052017131430904,0.0030919999999999997,195.32166303423134,246.73093043956652,-2.2132253293355992
0.5104301914162401,0.003124,195.44570108950714,246.73093043956652,-2.2132253293355992
0.5127830066391574,0.0031384,195.50135645108648,246.73093043956652,-2.2132253293355992
0.5152665338189035,0.0031536,195.55999584070898,246.73093043956652,-2.2132253293355992
0.5199721642647382,0.0031823999999999997,195.67080064865203,246.73093043956652,-2.2132253293355992
0.5227171153581418,0.0031991999999999997,195.7352561870506,246.73093043956652,-2.2132253293355992
0.5255927784083742,0.0032167999999999997,195.80263961288134,246.73093043956652,-2.2132253293355992
0.5272920338471478,0.0032272,195.84238950979525,246.73093043956652,-2.2132253293355992
0.5285991534154353,0.0032351999999999997,195.872932367844,246.73093043956652,-2.2132253293355992
0.5289912892859215,0.0032375999999999998,195.8820894796387,246.73093043956652,-2.2132253293355992
0.5300369849405515,0.003244,195.90649551109857,246.73093043956652,-2.2132253293355992
0.5346119034295574,0.0032719999999999997,196.01305186681577,246.73093043956652,-2.2132253293355992
0.5352654632137012,0.003276,196.02824512251445,246.73093043956652,-2.2132253293355992
0.5397096697458784,0.0033032,196.13136806408343,246.73093043956652,-2.2132253293355992
0.5415396371414808,0.0033144,196.17373413196017,246.73093043956652,-2.2132253293355992
0.5442845882348845,0.0033312,196.23717869608754,246.73093043956652,-2.2132253293355992
0.5463759795441443,0.0033439999999999998,196.28543369013386,246.73093043956652,-2.2132253293355992
0.5506894741194929,0.0033704,196.38473270595853,246.73093043956652,-2.2132253293355992
0.552127305644609,0.0033791999999999997,196.41776490808527,246.73093043956652,-2.2132253293355992
0.5568329360904437,0.003408,196.5256364942156,246.73093043956652,-2.2132253293355992
0.5576172078314161,0.0034127999999999997,196.54358047131956,246.73093043956652,-2.2132253293355992
0.5581400556587311,0.0034159999999999998,196.55553765487272,246.73093043956652,-2.2132253293355992
0.5585321915292174,0.0034184,196.5645026759661,246.73093043956652,-2.2132253293355992
0.5599700230543335,0.0034272,196.59735343942992,246.73093043956652,-2.2132253293355992
0.561277142622621,0.0034352,196.6271892342347,246.73093043956652,-2.2132253293355992
0.5655906371979695,0.0034616,196.72545565730744,246.73093043956652,-2.2132253293355992
0.5661134850252844,0.0034647999999999997,196.73734684564167,246.73093043956652,-2.2132253293355992
0.5704269796006329,0.0034912,196.83528625510436,246.73093043956652,-2.2132253293355992
0.5716033872120917,0.0034984,196.86194682046684,246.73093043956652,-2.2132253293355992
0.5763090176579264,0.0035272,196.96837578479781,246.73093043956652,-2.2132253293355992
0.5787925448376725,0.0035424,197.024409962561,246.73093043956652,-2.2132253293355992
0.5827139035425347,0.0035664,197.1126944410975,246.73093043956652,-2.2132253293355992
0.5884652296429994,0.0036016,197.24176037065428,246.73093043956652,-2.2132253293355992
0.5889880774703145,0.0036048,197.25346918841274,246.73093043956652,-2.2132253293355992
0.5953929633549228,0.0036439999999999997,197.39657479581214,246.73093043956652,-2.2132253293355992
0.5967000829232102,0.003652,197.42570611655205,246.73093043956652,-2.2132253293355992
0.5993143220597851,0.003668,197.48389420242668,246.73093043956652,-2.2132253293355992
0.5999678818439288,0.003672,197.49842574645885,246.73093043956652,-2.2132253293355992
0.6017978492395312,0.0036831999999999998,197.539081263305,246.73093043956652,-2.2132253293355992
0.6024514090236749,0.0036872,197.5535894024708,246.73093043956652,-2.2132253293355992
0.6036278166351337,0.0036944,197.57968859423522,246.73093043956652,-2.2132253293355992
0.6058499199012222,0.003708,197.62893300771896,246.73093043956652,-2.2132253293355992
0.6061113438148797,0.0037096,197.63472183347113,246.73093043956652,-2.2132253293355992
0.6067649035990234,0.0037135999999999996,197.64918963932467,246.73093043956652,-2.2132253293355992
0.6102941264333994,0.0037351999999999997,197.72721102179653,246.73093043956652,-2.2132253293355992
0.6121240938290019,0.0037464,197.76759726757982,246.73093043956652,-2.2132253293355992
0.6159147405770353,0.0037695999999999997,197.8511050095241,246.73093043956652,-2.2132253293355992
0.6168297242748366,0.0037752,197.8712319914126,246.73093043956652,-2.2132253293355992
0.6191825394977539,0.0037895999999999997,197.92293369472478,246.73093043956652,-2.2132253293355992
0.6199668112387264,0.0037944,197.94015056190835,246.73093043956652,-2.2132253293355992
0.6229731862457875,0.0038128,198.00607001412214,246.73093043956652,-2.2132253293355992
0.6238881699435888,0.0038184,198.02610781537854,246.73093043956652,-2.2132253293355992
0.6259795612528486,0.0038312,198.07186551666373,246.73093043956652,-2.2132253293355992
0.6267638329938211,0.003836,198.08900927856538,246.73093043956652,-2.2132253293355992
0.6317308873533133,0.0038664,198.1973927983359,246.73093043956652,-2.2132253293355992
0.6336915667057443,0.0038783999999999997,198.24008421652064,246.73093043956652,-2.2132253293355992
0.6373515014969492,0.0039008,198.31963728593138,246.73093043956652,-2.2132253293355992
0.638397197151579,0.0039071999999999996,198.34233398498202,246.73093043956652,-2.2132253293355992
0.6398350286766954,0.003916,198.37351828610684,246.73093043956652,-2.2132253293355992
0.6428414036837564,0.0039344,198.43863364891305,246.73093043956652,-2.2132253293355992
0.6446713710793588,0.0039456,198.47821094315313,246.73093043956652,-2.2132253293355992
0.6476777460864198,0.003964,198.5431357990983,246.73093043956652,-2.2132253293355992
0.7602420773746136,0.004652930586117224,200.89554339928955,246.73093043956652,-2.2132253293355992
0.8135832239900637,0.004979395879175836,201.96238555236621,246.73093043956652,-2.2132253293355992
0.870062085112305,0.005325065013002601,203.0626526849678,246.73093043956652,-2.2132253293355992
1.011259237917908,0.006189237847569514,205.69784686506455,246.73093043956652,-2.2132253293355992
1.0300855249586551,0.006304460892178436,206.03802500741926,246.73093043956652,-2.2132253293355992
1.0551872410129846,0.006458091618323665,206.48784768938611,246.73093043956652,-2.2132253293355992
1.0991152441080612,0.006726945389077816,207.26512133752732,246.73093043956652,-2.2132253293355992
1.1555941052303025,0.007072614522904581,208.24689416559855,246.73093043956652,-2.2132253293355992
1.180695821284632,0.0072262452490498095,208.67721095098258,246.73093043956652,-2.2132253293355992
1.2654141129679937,0.007744748949789958,210.1038838772362,246.73093043956652,-2.2132253293355992
1.337581546624191,0.008186437287457491,211.2900419248365,246.73093043956652,-2.2132253293355992
1.3783718352124763,0.008436087217443489,211.9494309276184,246.73093043956652,-2.2132253293355992
1.4254375528143441,0.008724144828965793,212.700880090198,246.73093043956652,-2.2132253293355992
1.4787786994297942,0.009050610122024405,213.54092028297643,246.73093043956652,-2.2132253293355992
1.5038804154841237,0.009204240848169634,213.93213623161503,246.73093043956652,-2.2132253293355992
1.5132935590044971,0.009261852370474095,214.0781845955652,246.73093043956652,-2.2132253293355992
1.6199758522353975,0.009914782956591319,215.70937442034844,246.73093043956652,-2.2132253293355992
1.7799992920817478,0.010894178835767154,218.07966082251818,246.73093043956652,-2.2132253293355992
1.8615798692583185,0.011393478695739149,219.2559368253551,246.73093043956652,-2.2132253293355992
1.889819299819439,0.01156631326265253,219.65840222718143,246.73093043956652,-2.2132253293355992
1.9996393075571304,0.012238447689537907,221.20174276195706,246.73093043956652,-2.2132253293355992
2.012190165584295,0.012315263052610522,221.37599405579863,246.73093043956652,-2.2132253293355992
2.081219884733701,0.012737747549509902,222.32690487760405,246.73093043956652,-2.2132253293355992
2.1000461717744483,0.012852970594118824,222.5840990950754,246.73093043956652,-2.2132253293355992
2.266345040634381,0.013870774154830966,224.81820719368983,246.73093043956652,-2.2132253293355992
2.3416501887973693,0.014331666333266654,225.8087453997051,246.73093043956652,-2.2132253293355992
2.391853620906028,0.014638927785557112,226.4622103958292,246.73093043956652,-2.2132253293355992
2.4169553369603576,0.014792558511702341,226.78693531631944,246.73093043956652,-2.2132253293355992
2.473434198082599,0.015138227645529106,227.51279552526523,246.73093043956652,-2.2132253293355992
2.5330507737116315,0.015503100620124026,228.27200308676288,246.73093043956652,-2.2132253293355992
2.6052182073678285,0.01594478895779156,229.18178271629094,246.73093043956652,-2.2132253293355992
2.655421639476488,0.016252050410082017,229.80888403100974,246.73093043956652,-2.2132253293355992
2.71503821510552,0.016616923384676935,230.5475926372293,246.73093043956652,-2.2132253293355992
2.733864502146267,0.016732146429285857,230.77955118706745,246.73093043956652,-2.2132253293355992
2.8562353679111228,0.017481096219243847,232.27237646245567,246.73093043956652,-2.2132253293355992
2.890750227485826,0.01769233846769354,232.68889243025396,246.73093043956652,-2.2132253293355992
2.9566422321284405,0.018095619123824763,233.47871256317703,246.73093043956652,-2.2132253293355992
3.0162588077574735,0.018460492098419684,234.1874158271907,246.73093043956652,-2.2132253293355992
3.06018681085255,0.018729345869173835,234.70612739539277,246.73093043956652,-2.2132253293355992
3.069599954372923,0.018786957391478294,234.81690114369607,246.73093043956652,-2.2132253293355992
3.148042817042703,0.019267053410682137,235.73491957964637,246.73093043956652,-2.2132253293355992
3.2735513973143506,0.020035207041408282,237.18540532405925,246.73093043956652,-2.2132253293355992
3.389646834065624,0.020745749149829965,238.50790802692822,246.73093043956652,-2.2132253293355992
3.4053354065995802,0.020841768353670735,238.6852599751901,246.73093043956652,-2.2132253293355992
3.4335748371607004,0.021014602920584116,239.00369254614745,246.73093043956652,-2.2132253293355992
3.4931914127897334,0.021379475895179037,239.67260425396327,246.73093043956652,-2.2132253293355992
3.5088799853236887,0.021475495099019803,239.84789179553854,246.73093043956652,-2.2132253293355992
3.6155622785545893,0.022128425685137027,241.03184373553125,246.73093043956652,-2.2132253293355992
3.6908674267175776,0.022589317863572714,241.85938484139535,246.73093043956652,-2.2132253293355992
3.7285200007990715,0.022819763952790558,242.27068408850647,246.73093043956652,-2.2132253293355992
3.8791302971250485,0.023741548309661933,243.8999354949426,246.73093043956652,-2.2132253293355992
3.9701240178219925,0.024298459691938386,244.8723230513517,246.73093043956652,-2.2132253293355992
4.0297405934510255,0.024663332666533307,245.5046952214964,246.73093043956652,-2.2132253293355992
4.048566880491772,0.02477855571114223,245.703632289529,246.73093043956652,-2.2132253293355992
4.09563259809364,0.025066613322664532,246.19940302773603,246.73093043956652,-2.2132253293355992
4.1332851721751345,0.025297059411882376,246.5944216801526,246.73093043956652,-2.2132253293355992
4.170937746256628,0.02552750550110022,246.98803939933865,246.73093043956652,-2.2132253293355992
4.20231489132454,0.025719543908781756,247.31499667973648,246.73093043956652,-2.2132253293355992
4.265069181460364,0.02610362072414483,247.9660688575844,246.73093043956652,-2.2132253293355992
4.312134899062232,0.026391678335667135,248.45192399342716,246.73093043956652,-2.2132253293355992
4.327823471596187,0.0264876975395079,248.61341553770896,246.73093043956652,-2.2132253293355992
4.371751474691264,0.026756551310262052,249.06438174560157,246.73093043956652,-2.2132253293355992
4.418817192293132,0.02704460892178436,249.54560317925956,246.73093043956652,-2.2132253293355992
4.469020624401791,0.027351870374074817,250.05670796171506,246.73093043956652,-2.2132253293355992
4.569427488619109,0.027966393278655733,251.072248838895,246.73093043956652,-2.2132253293355992
4.676109781850008,0.028619323864772953,252.14177102760542,246.73093043956652,-2.2132253293355992
4.713762355931503,0.028849769953990797,252.51697186559682,246.73093043956652,-2.2132253293355992
4.779654360574118,0.029253050610122025,253.17077287977685,246.73093043956652,-2.2132253293355992
4.829857792682777,0.029560312062412483,253.66655028277333,246.73093043956652,-2.2132253293355992
4.845546365216732,0.02965633126625325,253.82106802362614,246.73093043956652,-2.2132253293355992
5.055773237171742,0.030942988597719545,255.87313433649953,246.73093043956652,-2.2132253293355992
5.109114383787192,0.031269453890778155,256.3884806721914,246.73093043956652,-2.2132253293355992
5.225209820538466,0.031979995999199845,257.5029185424199,246.73093043956652,-2.2132253293355992
5.319341255742201,0.03255611122224445,258.39944399155036,246.73093043956652,-2.2132253293355992
5.325616684755785,0.03259451890378076,258.45899142753126,246.73093043956652,-2.2132253293355992
5.378957831371233,0.032920984196839365,258.9640445067081,246.73093043956652,-2.2132253293355992
5.4009218329187725,0.03305541108221645,259.1714393597479,246.73093043956652,-2.2132253293355992
5.457400694041014,0.03340108021604321,259.703235641428,246.73093043956652,-2.2132253293355992
5.47622698108176,0.03351630326065213,259.8800235241464,246.73093043956652,-2.2132253293355992
5.567220701778705,0.03407321464292859,260.7311792690397,246.73093043956652,-2.2132253293355992
5.6488012789552755,0.03457251450290058,261.4896825593584,246.73093043956652,-2.2132253293355992
5.677040709516396,0.03474534906981396,261.7512444430449,246.73093043956652,-2.2132253293355992
5.79627386077446,0.0354750950190038,262.85006900945706,246.73093043956652,-2.2132253293355992
5.918644726539317,0.0362240448089618,263.968681768839,246.73093043956652,-2.2132253293355992
5.953159586114021,0.03643528705741149,264.28255240648093,246.73093043956652,-2.2132253293355992
5.997087589209095,0.03670414082816563,264.6809996042237,246.73093043956652,-2.2132253293355992
6.022189305263425,0.03685777155431086,264.90817265100736,246.73093043956652,-2.2132253293355992
6.050428735824546,0.03703060612122425,265.16330137201305,246.73093043956652,-2.2132253293355992
6.081805880892458,0.03722264452890578,265.44623368350983,246.73093043956652,-2.2132253293355992
6.113183025960369,0.03741468293658731,265.72859728158005,246.73093043956652,-2.2132253293355992
6.201039032150524,0.03795239047809562,266.5162241148274,246.73093043956652,-2.2132253293355992
6.216727604684479,0.03804840968193639,266.65641258666074,246.73093043956652,-2.2132253293355992
6.244967035245601,0.038221244248849776,266.90840463529054,246.73093043956652,-2.2132253293355992
6.373613330024038,0.039008601720344066,268.0507910723903,246.73093043956652,-2.2132253293355992
6.455193907200608,0.03950790158031606,268.7705739031281,246.73093043956652,-2.2132253293355992
6.4834333377617295,0.039680736147229445,269.0189017912763,246.73093043956652,-2.2132253293355992
6.524223626350015,0.03993038607721544,269.37685420570836,246.73093043956652,-2.2132253293355992
6.568151629445092,0.040199239847969595,269.76136672218115,246.73093043956652,-2.2132253293355992
6.596391060006213,0.04037207441488298,270.00802382963104,246.73093043956652,-2.2132253293355992
6.6277682050741245,0.040564112822564516,270.2816047904868,246.73093043956652,-2.2132253293355992
6.687384780703157,0.04092898579715944,270.8000210118045,246.73093043956652,-2.2132253293355992
6.775240786893309,0.04146669333866773,271.56072954965884,246.73093043956652,-2.2132253293355992
6.850545935056298,0.04192758551710342,272.2097085119563,246.73093043956652,-2.2132253293355992
7.051359663490933,0.04315663132626525,273.9268590438233,246.73093043956652,-2.2132253293355992
7.0827368085588445,0.043348669733946785,274.1934312404508,246.73093043956652,-2.2132253293355992
7.126664811653922,0.04361752350470094,274.56585986242794,246.73093043956652,-2.2132253293355992
7.154904242215043,0.04379035807161433,274.80480557909027,246.73093043956652,-2.2132253293355992
7.233347104884821,0.04427045409081816,275.4666215542224,246.73093043956652,-2.2132253293355992
7.261586535445943,0.04444328865773155,275.70418932660505,246.73093043956652,-2.2132253293355992
7.286688251500272,0.044596919383876776,275.9150583651695,246.73093043956652,-2.2132253293355992
7.41219683177192,0.04536507301460292,276.9651836987018,246.73093043956652,-2.2132253293355992
7.478088836414535,0.045768353670734147,277.5137221535426,246.73093043956652,-2.2132253293355992
7.62242370372693,0.04665173034606922,278.70873852626784,246.73093043956652,-2.2132253293355992
7.660076277808423,0.046882176435287054,279.01902644331756,246.73093043956652,-2.2132253293355992
7.7102797099170814,0.04718943788757751,279.43181995973146,246.73093043956652,-2.2132253293355992
7.754207713012159,0.04745829165833167,279.79215516303276,246.73093043956652,-2.2132253293355992
7.8295128611751466,0.047919183836767354,280.4080259520763,246.73093043956652,-2.2132253293355992
7.845201433709103,0.04801520304060812,280.53604110632483,246.73093043956652,-2.2132253293355992
7.901680294831343,0.04836087217443488,280.99607128882957,246.73093043956652,-2.2132253293355992
7.989536301021498,0.04889857971594319,281.70913303876125,246.73093043956652,-2.2132253293355992
7.995811730035079,0.048936987397479495,281.75994870003893,246.73093043956652,-2.2132253293355992
8.024051160596201,0.04910982196439288,281.9884269684732,246.73093043956652,-2.2132253293355992
8.039739733130157,0.04920584116823365,282.1152238295898,246.73093043956652,-2.2132253293355992
8.140146597347474,0.049820364072814566,282.9244506251187,246.73093043956652,-2.2132253293355992
8.209176316496881,0.05024284856971395,283.47853724983446,246.73093043956652,-2.2132253293355992
8.243691176071582,0.05045409081816363,283.75489893432393,246.73093043956652,-2.2132253293355992
8.334684896768529,0.051011002200440095,284.4813343387383,246.73093043956652,-2.2132253293355992
8.403714615917933,0.051433486697339464,285.0303618575077,246.73093043956652,-2.2132253293355992
8.425678617465472,0.05156791358271655,285.2046832175002,246.73093043956652,-2.2132253293355992
8.544911768723535,0.052297659531906376,286.14792476025127,246.73093043956652,-2.2132253293355992
8.620216916886523,0.052758551710342064,286.74101235385916,246.73093043956652,-2.2132253293355992
8.808479787293995,0.05391078215643129,288.21495882089954,246.73093043956652,-2.2132253293355992
8.830443788841533,0.05404520904180836,288.3861152383604,246.73093043956652,-2.2132253293355992
8.852407790389073,0.05417963592718544,288.5571057060575,246.73093043956652,-2.2132253293355992
8.965365512633555,0.05487097419483897,289.4338853085716,246.73093043956652,-2.2132253293355992
9.006155801221839,0.05512062412482496,289.74944001595003,246.73093043956652,-2.2132253293355992
9.106562665439158,0.05573514702940588,290.5238247147828,246.73093043956652,-2.2132253293355992
9.144215239520653,0.05596559311862373,290.81335958267243,246.73093043956652,-2.2132253293355992
9.197556386136101,0.05629205841168233,291.2227393272377,246.73093043956652,-2.2132253293355992
9.301100964860211,0.05692578515703141,292.01478401488623,246.73093043956652,-2.2132253293355992
9.379543827529991,0.057405881176235254,292.61253055567545,246.73093043956652,-2.2132253293355992
9.439160403159022,0.05777075415083016,293.0655149104784,246.73093043956652,-2.2132253293355992
9.511327836815221,0.058212442488497704,293.6123742643373,246.73093043956652,-2.2132253293355992
9.618010130046121,0.058865373074614924,294.4178201327508,246.73093043956652,-2.2132253293355992
9.705866136236272,0.05940308061612322,295.0785155326556,246.73093043956652,-2.2132253293355992
9.737243281304186,0.059595119023804766,295.31391239439535,246.73093043956652,-2.2132253293355992
9.837650145521504,0.06020964192838568,296.0652021026516,246.73093043956652,-2.2132253293355992
9.865889576082623,0.060382476495299056,296.27596275221316,246.73093043956652,-2.2132253293355992
9.953745582272777,0.060920184036807365,296.9301629844501,246.73093043956652,-2.2132253293355992
10.03846387395614,0.061438687737547515,297.5588694936096,246.73093043956652,-2.2132253293355992
10.051014731983303,0.06151550310062012,297.65183491120354,246.73093043956652,-2.2132253293355992
10.113769022119127,0.0618995799159832,298.11598461868584,246.73093043956652,-2.2132253293355992
10.14514616718704,0.062091618323664735,298.3476381787059,246.73093043956652,-2.2132253293355992
10.192211884788906,0.062379675935187034,298.6945952937443,246.73093043956652,-2.2132253293355992
10.261241603938313,0.06280216043208642,299.20233757804414,246.73093043956652,-2.2132253293355992
10.30516960703339,0.06307101420284057,299.52475283973195,246.73093043956652,-2.2132253293355992
10.36164846815563,0.06341668333666733,299.93850024673986,246.73093043956652,-2.2132253293355992
10.430678187305038,0.06383916783356672,300.4429990097671,246.73093043956652,-2.2132253293355992
10.484019333920486,0.06416563312662532,300.83194764738704,246.73093043956652,-2.2132253293355992
10.496570191947653,0.06424244848969794,300.92335272141366,246.73093043956652,-2.2132253293355992
10.553049053069893,0.0645881176235247,301.3341492164959,246.73093043956652,-2.2132253293355992
10.593839341658178,0.0648377675535107,301.630302512918,246.73093043956652,-2.2132253293355992
10.681695347848333,0.06537547509501901,302.2666649101985,246.73093043956652,-2.2132253293355992
10.747587352490946,0.06577875575115023,302.74259798358923,246.73093043956652,-2.2132253293355992
10.791515355586023,0.06604760952190439,303.05925464559834,246.73093043956652,-2.2132253293355992
10.976640511486703,0.06718063612722545,304.38825044405,246.73093043956652,-2.2132253293355992
11.045670230636109,0.06760312062412482,304.8815670535387,246.73093043956652,-2.2132253293355992
11.186867383441712,0.06846729345869174,305.88689457043864,246.73093043956652,-2.2132253293355992
11.309238249206569,0.06921624324864974,306.75418209986424,246.73093043956652,-2.2132253293355992
11.42219597145105,0.06990758151630326,307.55151227465063,246.73093043956652,-2.2132253293355992
11.434746829478216,0.06998439687937588,307.63991428171965,246.73093043956652,-2.2132253293355992
11.484950261586874,0.07029165833166634,307.9931445470226,246.73093043956652,-2.2132253293355992
11.52574055017516,0.07054130826165234,308.2797009431933,246.73093043956652,-2.2132253293355992
11.541429122709115,0.0706373274654931,308.3898095934211,246.73093043956652,-2.2132253293355992
11.585357125804192,0.07090618123624726,308.69780370457045,246.73093043956652,-2.2132253293355992
11.68576399002151,0.07152070414082817,309.40008508897455,246.73093043956652,-2.2132253293355992
11.748518280157333,0.07190478095619124,309.83781611305477,246.73093043956652,-2.2132253293355992
11.823823428320322,0.07236567313462693,310.36189151433075,246.73093043956652,-2.2132253293355992
11.94619429408518,0.07311462292458493,311.2107461742772,246.73093043956652,-2.2132253293355992
11.97757143915309,0.07330666133226646,311.42785413286435,246.73093043956652,-2.2132253293355992
12.040325729288913,0.07369073814762953,311.8614057577496,246.73093043956652,-2.2132253293355992
12.071702874356827,0.07388277655531107,312.0778510285592,246.73093043956652,-2.2132253293355992
12.150145737026605,0.0743628725745149,312.6180064957992,246.73093043956652,-2.2132253293355992
12.178385167587725,0.07453570714142829,312.81212930373704,246.73093043956652,-2.2132253293355992
12.294480604339,0.07524624924984998,313.6083523088543,246.73093043956652,-2.2132253293355992
12.37292346700878,0.07572634526905382,314.14468152821246,246.73093043956652,-2.2132253293355992
12.545497764882294,0.07678255651130227,315.31995995629075,246.73093043956652,-2.2132253293355992
12.592563482484161,0.07707061412282457,315.63939400034525,246.73093043956652,-2.2132253293355992
12.655317772619986,0.07745469093818765,316.06458269562916,246.73093043956652,-2.2132253293355992
12.711796633742226,0.07780036007201441,316.4465499919051,246.73093043956652,-2.2132253293355992
12.730622920782974,0.07791558311662333,316.57372526803806,246.73093043956652,-2.2132253293355992
12.771413209371259,0.07816523304660933,316.8490203518591,246.73093043956652,-2.2132253293355992
12.831029785000291,0.07853010602120425,317.2507586745241,246.73093043956652,-2.2132253293355992
12.953400650765147,0.07927905581116224,318.07310592854606,246.73093043956652,-2.2132253293355992
12.978502366819477,0.07943268653730746,318.2414174359137,246.73093043956652,-2.2132253293355992
13.01301722639418,0.07964392878575716,318.47263860881645,246.73093043956652,-2.2132253293355992
13.085184660050377,0.08008561712342468,318.95532961261983,246.73093043956652,-2.2132253293355992
13.182453809760904,0.08068093618723746,319.6042736215614,246.73093043956652,-2.2132253293355992
13.210693240322025,0.08085377075415083,319.79232658968226,246.73093043956652,-2.2132253293355992
13.285998388485012,0.08131466293258652,320.29303629783215,246.73093043956652,-2.2132253293355992
13.326788677073298,0.08156431286257251,320.5637918691,246.73093043956652,-2.2132253293355992
13.395818396222705,0.0819867973594719,321.0212584759452,246.73093043956652,-2.2132253293355992
13.452297257344945,0.08233246649329866,321.39486589359,246.73093043956652,-2.2132253293355992
13.51505154748077,0.08271654330866174,321.80926850832225,246.73093043956652,-2.2132253293355992
13.59663212465734,0.08321584316863373,322.3468717390899,246.73093043956652,-2.2132253293355992
13.646835556765998,0.08352310462092419,322.67707927677134,246.73093043956652,-2.2132253293355992
13.800583567598768,0.08446409281856372,323.6854051660579,246.73093043956652,-2.2132253293355992
13.819409854639513,0.08457931586317263,323.8085718569158,246.73093043956652,-2.2132253293355992
13.935505291390788,0.08528985797159433,324.5666588502086,246.73093043956652,-2.2132253293355992
14.029636726594523,0.08586597319463893,325.1795174085422,246.73093043956652,-2.2132253293355992
14.095528731237136,0.08626925385077015,325.6075645724036,246.73093043956652,-2.2132253293355992
14.130043590811841,0.08648049609921984,325.8314682701737,246.73093043956652,-2.2132253293355992
14.249276742069906,0.08721024204840969,326.60331791812007,246.73093043956652,-2.2132253293355992
14.271240743617444,0.08734466893378676,326.74522558967095,246.73093043956652,-2.2132253293355992
14.343408177273641,0.0877863572714543,327.21089509456976,246.73093043956652,-2.2132253293355992
14.384198465861926,0.0880360072014403,327.4736953875027,246.73093043956652,-2.2132253293355992
14.424988754450212,0.08828565713142629,327.73620519649575,246.73093043956652,-2.2132253293355992
14.47205447205208,0.08857371474294859,328.0387416638924,246.73093043956652,-2.2132253293355992
14.566185907255814,0.0891498299659932,328.64266588646365,246.73093043956652,-2.2132253293355992
14.638353340912012,0.08959151830366073,329.10464424664445,246.73093043956652,-2.2132253293355992
14.76072420667687,0.09034046809361873,329.88597395854606,246.73093043956652,-2.2132253293355992
14.804652209771946,0.09060932186437289,330.16583457645106,246.73093043956652,-2.2132253293355992
14.854855641880604,0.09091658331666334,330.4852790327061,246.73093043956652,-2.2132253293355992
14.89564593046889,0.09116623324664934,330.74451774139646,246.73093043956652,-2.2132253293355992
14.992915080179417,0.0917615523104621,331.3615876296432,246.73093043956652,-2.2132253293355992
15.043118512288075,0.09206881376275255,331.67946432017635,246.73093043956652,-2.2132253293355992
15.08077108636957,0.0922992598519704,331.91760039791393,246.73093043956652,-2.2132253293355992
15.174902521573305,0.092875375075015,332.511928368215,246.73093043956652,-2.2132253293355992
15.209417381148008,0.0930866173234647,332.729488152906,246.73093043956652,-2.2132253293355992
15.231381382695545,0.09322104420884177,332.8678350428403,246.73093043956652,-2.2132253293355992
15.247069955229502,0.09331706341268255,332.9666066186547,246.73093043956652,-2.2132253293355992
15.262758527763458,0.09341308261652331,333.065338566065,246.73093043956652,-2.2132253293355992
15.322375103392492,0.09377795559111823,333.44015955159665,246.73093043956652,-2.2132253293355992
15.369440820994358,0.09406601320264053,333.73566925128836,246.73093043956652,-2.2132253293355992
15.425919682116598,0.0944116823364673,334.089815438376,246.73093043956652,-2.2132253293355992
15.438470540143765,0.09448849769953992,334.1684458758009,246.73093043956652,-2.2132253293355992
15.444745969157346,0.09452690538107622,334.2077517454374,246.73093043956652,-2.2132253293355992
15.61732026703086,0.09558311662332467,335.28623464875045,246.73093043956652,-2.2132253293355992
15.680074557166686,0.09596719343868775,335.67725661673995,246.73093043956652,-2.2132253293355992
15.730277989275345,0.0962744548909782,335.9896349360619,246.73093043956652,-2.2132253293355992
15.742828847302508,0.09635127025405081,336.0676687339865,246.73093043956652,-2.2132253293355992
15.793032279411166,0.09665853170634127,336.37956160532036,246.73093043956652,-2.2132253293355992
15.93109171770998,0.09750350070014004,337.23527958638675,246.73093043956652,-2.2132253293355992
15.946780290243936,0.0975995199039808,337.3323369243067,246.73093043956652,-2.2132253293355992
15.996983722352594,0.09790678135627126,337.6426704548558,246.73093043956652,-2.2132253293355992
16.053462583474836,0.09825245049009802,337.9913420209936,246.73093043956652,-2.2132253293355992
16.09111515755633,0.09848289657931587,338.2235239870658,246.73093043956652,-2.2132253293355992
16.19465973628044,0.09911662332466493,338.8609344193798,246.73093043956652,-2.2132253293355992
16.257414026416264,0.09950070014002801,339.24647028204555,246.73093043956652,-2.2132253293355992
16.323306031058877,0.09990398079615924,339.6506588148313,246.73093043956652,-2.2132253293355992