File: datasets/aisi_316_L/data/M1/train_59.csv
Time(s),Strain(%),Stress(MPa),Temp(C),Log_SR(s-1)
0.0,0.0,0.0,343.326656551313,2.5980668801674494
4.0369475091758985e-08,1.6e-05,2.78459725,343.326656551313,2.5980668801674494
6.660963390140233e-08,2.6399999999999998e-05,4.5945854624999996,343.326656551313,2.5980668801674494
1.5945942661244798e-07,6.319999999999999e-05,10.999159137499998,343.326656551313,2.5980668801674494
1.8368111166750338e-07,7.28e-05,12.6699174875,343.326656551313,2.5980668801674494
1.9579195419503109e-07,7.76e-05,13.505296662500001,343.326656551313,2.5980668801674494
2.301060080230262e-07,9.12e-05,15.872204324999998,343.326656551313,2.5980668801674494
2.5634616683266955e-07,0.00010159999999999999,17.682192537499997,343.326656551313,2.5980668801674494
2.825863256423129e-07,0.000112,19.49218075,343.326656551313,2.5980668801674494
3.229558007340719e-07,0.000128,22.276778,343.326656551313,2.5980668801674494
3.5726985456206705e-07,0.0001416,24.6436856625,343.326656551313,2.5980668801674494
4.0369475091758985e-07,0.00015999999999999999,27.8459725,343.326656551313,2.5980668801674494
4.662674373098163e-07,0.0001848,32.1620982375,343.326656551313,2.5980668801674494
4.925075961194597e-07,0.0001952,33.97208645,343.326656551313,2.5980668801674494
5.470063874933342e-07,0.00021679999999999998,37.7312927375,343.326656551313,2.5980668801674494
5.631541775300378e-07,0.00022319999999999998,38.845131637499996,343.326656551313,2.5980668801674494
5.793019675667414e-07,0.0002296,39.9589705375,343.326656551313,2.5980668801674494
6.317822851860282e-07,0.0002504,43.578946962500005,343.326656551313,2.5980668801674494
6.681148127686112e-07,0.0002648,46.0850844875,343.326656551313,2.5980668801674494
7.306874991608376e-07,0.0002896,50.401210225,343.326656551313,2.5980668801674494
7.609646054796569e-07,0.0003016,52.4896581625,343.326656551313,2.5980668801674494
7.851862905347123e-07,0.0003112,54.16041651249999,343.326656551313,2.5980668801674494
8.134449230989435e-07,0.0003224,56.1096345875,343.326656551313,2.5980668801674494
8.457405031723506e-07,0.00033519999999999996,58.33731238749999,343.326656551313,2.5980668801674494
9.103316633191652e-07,0.0003608,62.792667987499996,343.326656551313,2.5980668801674494
9.648304546930398e-07,0.00038239999999999997,66.55187427499999,343.326656551313,2.5980668801674494
9.870336659935073e-07,0.00039119999999999997,68.0834027625,343.326656551313,2.5980668801674494
1.0253846673306782e-06,0.00040639999999999996,70.72877014999999,343.326656551313,2.5980668801674494
1.035477036103618e-06,0.0004104,71.4249194625,343.326656551313,2.5980668801674494
1.0617171949132612e-06,0.0004208,73.234907675,343.326656551313,2.5980668801674494
1.0899758274774926e-06,0.000432,75.18412574999999,343.326656551313,2.5980668801674494
1.1424561450967794e-06,0.0004528,78.804102175,343.326656551313,2.5980668801674494
1.1646593563972468e-06,0.0004616,80.3356306625,343.326656551313,2.5980668801674494
1.2131027265073575e-06,0.0004808,83.6771473625,343.326656551313,2.5980668801674494
1.2413613590715887e-06,0.0004919999999999999,85.62636543749998,343.326656551313,2.5980668801674494
1.2514537278445287e-06,0.000496,86.32251475000001,343.326656551313,2.5980668801674494
1.3039340454638152e-06,0.0005168,89.942491175,343.326656551313,2.5980668801674494
1.3160448879913429e-06,0.0005216,90.77787035,343.326656551313,2.5980668801674494
1.3604513105922778e-06,0.0005392,93.840927325,343.326656551313,2.5980668801674494
1.4633934720762633e-06,0.00058,100.9416503125,343.326656551313,2.5980668801674494
1.5340400534868413e-06,0.0006079999999999999,105.81469549999998,343.326656551313,2.5980668801674494
1.6087235824065957e-06,0.0006376,110.9662004125,343.326656551313,2.5980668801674494
1.6228528986887112e-06,0.0006432,111.94080945,343.326656551313,2.5980668801674494
1.6410191624800029e-06,0.0006504,113.1938782125,343.326656551313,2.5980668801674494
1.6490930574983545e-06,0.0006536,113.75079766249999,343.326656551313,2.5980668801674494
1.6652408475350582e-06,0.00066,114.8646365625,343.326656551313,2.5980668801674494
1.7157026913997568e-06,0.0006799999999999999,118.34538312499998,343.326656551313,2.5980668801674494
1.747998271473164e-06,0.0006927999999999999,120.573060925,343.326656551313,2.5980668801674494
1.828737221656682e-06,0.0007247999999999999,126.14225542499999,343.326656551313,2.5980668801674494
1.8388295904296217e-06,0.0007287999999999999,126.83840473749999,343.326656551313,2.5980668801674494
1.8751621180122048e-06,0.0007432,129.3445422625,343.326656551313,2.5980668801674494
1.8933283818034964e-06,0.0007503999999999999,130.597611025,343.326656551313,2.5980668801674494
1.9458086994227833e-06,0.0007712,134.21758745,343.326656551313,2.5980668801674494
1.9619564894594866e-06,0.0007775999999999999,135.33142635,343.326656551313,2.5980668801674494
1.972048858232426e-06,0.0007815999999999999,136.0275756625,343.326656551313,2.5980668801674494
2.0023259645512457e-06,0.0007936,138.1160236,343.326656551313,2.5980668801674494
2.0346215446246527e-06,0.0008064,140.3437014,343.326656551313,2.5980668801674494
2.083064914734764e-06,0.0008256,143.68521810000001,343.326656551313,2.5980668801674494
2.15572996989993e-06,0.0008544,148.69749314999999,343.326656551313,2.5980668801674494
2.1900440237279248e-06,0.000868,151.0644008125,343.326656551313,2.5980668801674494
2.238487393838036e-06,0.0008872,154.4059175125,343.326656551313,2.5980668801674494
2.2485797626109755e-06,0.0008912,155.102066825,343.326656551313,2.5980668801674494
2.266746026402267e-06,0.0008983999999999999,156.3551355875,343.326656551313,2.5980668801674494
2.3373926078128452e-06,0.0009264,161.228180775,343.326656551313,2.5980668801674494
2.3656512403770764e-06,0.0009375999999999999,163.17739884999997,343.326656551313,2.5980668801674494
2.424186979260127e-06,0.0009607999999999999,167.2150648625,343.326656551313,2.5980668801674494
2.4362978217876546e-06,0.0009655999999999999,168.0504440375,343.326656551313,2.5980668801674494
2.456482559333534e-06,0.0009735999999999999,169.4427426625,343.326656551313,2.5980668801674494
2.53923998327164e-06,0.0010064,175.151167025,343.326656551313,2.5980668801674494
2.6018126696638666e-06,0.0010312,179.4672927625,343.326656551313,2.5980668801674494
2.6098865646822183e-06,0.0010344,180.0242122125,343.326656551313,2.5980668801674494
2.6522745135285653e-06,0.0010512,180.4362501794119,343.326656551313,2.5980668801674494
2.6825516198473848e-06,0.0010632,180.50502719530783,343.326656551313,2.5980668801674494
2.7289765162029076e-06,0.0010816,180.60990018908635,343.326656551313,2.5980668801674494
2.787512255085958e-06,0.0011048,180.741144854219,343.326656551313,2.5980668801674494
2.819807835159365e-06,0.0011175999999999998,180.81309545250116,343.326656551313,2.5980668801674494
2.8662327315148876e-06,0.0011359999999999999,180.91596392259584,343.326656551313,2.5980668801674494
2.888435942815355e-06,0.0011447999999999999,180.96493200010337,343.326656551313,2.5980668801674494
2.9025652590974713e-06,0.0011504,180.99601708509624,343.326656551313,2.5980668801674494
2.95302710296217e-06,0.0011704,181.1065567154435,343.326656551313,2.5980668801674494
2.9691748929988736e-06,0.0011768,181.14177348661087,343.326656551313,2.5980668801674494
2.9792672617718128e-06,0.0011807999999999999,181.16374604178478,343.326656551313,2.5980668801674494
2.995415051808517e-06,0.0011872,181.1988418465667,343.326656551313,2.5980668801674494
3.029729105636512e-06,0.0012008,181.27317637704388,343.326656551313,2.5980668801674494
3.0721170544828588e-06,0.0012175999999999999,181.36454961398508,343.326656551313,2.5980668801674494
3.092301792028738e-06,0.0012255999999999999,181.40788774691146,343.326656551313,2.5980668801674494
3.1245973721021453e-06,0.0012384,181.4769999856947,343.326656551313,2.5980668801674494
3.195243953512724e-06,0.0012664,181.6272191185941,343.326656551313,2.5980668801674494
3.2759829036962416e-06,0.0012984,181.7973209647349,343.326656551313,2.5980668801674494
3.3143339050334123e-06,0.0013135999999999998,181.87754586516124,343.326656551313,2.5980668801674494
3.3930543814623425e-06,0.0013448,182.0410926001476,343.326656551313,2.5980668801674494
3.4414977515724537e-06,0.001364,182.1410014594472,343.326656551313,2.5980668801674494
3.457645541609157e-06,0.0013704,182.17418233170403,343.326656551313,2.5980668801674494
3.516181280492207e-06,0.0013935999999999998,182.29395968757476,343.326656551313,2.5980668801674494
3.5323290705289113e-06,0.0014,182.32686453948958,343.326656551313,2.5980668801674494
3.5464583868110267e-06,0.0014056,182.35560819154261,343.326656551313,2.5980668801674494
3.5646246506023183e-06,0.0014127999999999999,182.39249877585036,343.326656551313,2.5980668801674494
3.570680071866082e-06,0.0014152,182.4047793340961,343.326656551313,2.5980668801674494
3.604994125694078e-06,0.0014288,182.47421635376574,343.326656551313,2.5980668801674494
3.6352712320128965e-06,0.0014408,182.53527053446226,343.326656551313,2.5980668801674494
3.659492917067952e-06,0.0014504,182.58397121165646,343.326656551313,2.5980668801674494
3.683714602123007e-06,0.00146,182.63254633604564,343.326656551313,2.5980668801674494
3.7139917084418267e-06,0.001472,182.69309042715088,343.326656551313,2.5980668801674494
3.7341764459877062e-06,0.00148,182.73334624967362,343.326656551313,2.5980668801674494
3.7967491323799327e-06,0.0015048,182.85760336153942,343.326656551313,2.5980668801674494
3.8068415011528727e-06,0.0015088,182.87756979434602,343.326656551313,2.5980668801674494
3.847210976244632e-06,0.0015248,182.95722994774732,343.326656551313,2.5980668801674494
3.923912978918973e-06,0.0015551999999999999,183.10769181050773,343.326656551313,2.5980668801674494
3.940060768955677e-06,0.0015616,183.13922133797328,343.326656551313,2.5980668801674494
3.9804302440474364e-06,0.0015776,183.21782547514704,343.326656551313,2.5980668801674494
3.998596507838727e-06,0.0015848,183.25309584019308,343.326656551313,2.5980668801674494
4.0349290354213105e-06,0.0015991999999999998,183.32344964815098,343.326656551313,2.5980668801674494
4.063187667985542e-06,0.0016104,183.37799860530808,343.326656551313,2.5980668801674494
4.147963565678235e-06,0.0016439999999999998,183.5407645729033,343.326656551313,2.5980668801674494
4.180259145751643e-06,0.0016568,183.60242874071616,343.326656551313,2.5980668801674494
4.23273946337093e-06,0.0016776,183.70223821480297,343.326656551313,2.5980668801674494
4.315496887309036e-06,0.0017104,183.8586550167444,343.326656551313,2.5980668801674494
4.325589256081975e-06,0.0017143999999999998,183.87764987768048,343.326656551313,2.5980668801674494
4.355866362400795e-06,0.0017264,183.93453102570163,343.326656551313,2.5980668801674494
4.472937840166896e-06,0.0017728,184.1530357689996,343.326656551313,2.5980668801674494
4.5395474740682975e-06,0.0017992,184.2763617026468,343.326656551313,2.5980668801674494
4.6061571079697e-06,0.0018256,184.39898388366097,343.326656551313,2.5980668801674494
4.614231002988052e-06,0.0018288,184.41380003971457,343.326656551313,2.5980668801674494
4.6646928468527505e-06,0.0018487999999999998,184.506172989442,343.326656551313,2.5980668801674494
4.670748268116515e-06,0.0018512,184.51723149379274,343.326656551313,2.5980668801674494
4.686896058153218e-06,0.0018575999999999998,184.54669353730338,343.326656551313,2.5980668801674494
4.727265533244977e-06,0.0018736,184.62017598010738,343.326656551313,2.5980668801674494
4.771671955845912e-06,0.0018912,184.70072457851202,343.326656551313,2.5980668801674494
4.832226168483551e-06,0.0019152,184.81009401723293,343.326656551313,2.5980668801674494
4.872595643575309e-06,0.0019311999999999999,184.8827101698156,343.326656551313,2.5980668801674494
4.906909697403305e-06,0.0019448,184.94424960828232,343.326656551313,2.5980668801674494
4.921039013685421e-06,0.0019504,184.96954056791577,343.326656551313,2.5980668801674494
4.933149856212948e-06,0.0019552,184.99119600115884,343.326656551313,2.5980668801674494
4.9896671213414105e-06,0.0019776,185.09198180702694,343.326656551313,2.5980668801674494
4.9997594901143505e-06,0.0019816,185.1099323230096,343.326656551313,2.5980668801674494
5.062332176506576e-06,0.0020063999999999998,185.22091175487512,343.326656551313,2.5980668801674494
5.106738599107511e-06,0.0020239999999999998,185.29934703371222,343.326656551313,2.5980668801674494
5.132978757917155e-06,0.0020344,185.34557012780704,343.326656551313,2.5980668801674494
5.183440601781854e-06,0.0020544,185.4342024959587,343.326656551313,2.5980668801674494
5.213717708100673e-06,0.0020664,185.48722040390157,343.326656551313,2.5980668801674494
5.225828550628201e-06,0.0020712,185.50839392964298,343.326656551313,2.5980668801674494
5.233902445646553e-06,0.0020744,185.52249898271893,343.326656551313,2.5980668801674494
5.241976340664904e-06,0.0020775999999999998,185.53659555246452,343.326656551313,2.5980668801674494
5.320696817093835e-06,0.0021088,185.6735962250617,343.326656551313,2.5980668801674494
5.348955449658065e-06,0.00212,185.72258283868956,343.326656551313,2.5980668801674494
5.3651032396947696e-06,0.0021264,185.75052987241094,343.326656551313,2.5980668801674494
5.377214082222296e-06,0.0021311999999999998,185.77146862475436,343.326656551313,2.5980668801674494
5.401435767277353e-06,0.0021408,185.8132910345687,343.326656551313,2.5980668801674494
5.506396402515925e-06,0.0021823999999999997,185.9936827936474,343.326656551313,2.5980668801674494
5.575024510171916e-06,0.0022096,186.11090662372237,343.326656551313,2.5980668801674494
5.597227721472383e-06,0.0022183999999999997,186.1487113123721,343.326656551313,2.5980668801674494
5.631541775300379e-06,0.002232,186.20702190479784,343.326656551313,2.5980668801674494
5.637597196564143e-06,0.0022344,186.2172976089158,343.326656551313,2.5980668801674494
5.696132935447193e-06,0.0022576,186.31640849007536,343.326656551313,2.5980668801674494
5.7284285155206e-06,0.0022704,186.37092029818263,343.326656551313,2.5980668801674494
5.756687148084831e-06,0.0022816,186.41851988563596,343.326656551313,2.5980668801674494
5.801093570685766e-06,0.0022992,186.49313553714433,343.326656551313,2.5980668801674494
5.8394445720229375e-06,0.0023144,186.55739724230082,343.326656551313,2.5980668801674494
5.87577709960552e-06,0.0023288,186.618125090722,343.326656551313,2.5980668801674494
5.948442154770687e-06,0.0023576,186.73914321820305,343.326656551313,2.5980668801674494
5.9787192610895055e-06,0.0023696,186.78939711634735,343.326656551313,2.5980668801674494
6.067532106291375e-06,0.0024048,186.93623910962083,343.326656551313,2.5980668801674494
6.146252582720305e-06,0.002436,187.06569515819234,343.326656551313,2.5980668801674494
6.170474267775362e-06,0.0024456,187.1053974829854,343.326656551313,2.5980668801674494
6.184603584057476e-06,0.0024511999999999997,187.12852910370324,343.326656551313,2.5980668801674494
6.224973059149235e-06,0.0024671999999999997,187.1945061555403,343.326656551313,2.5980668801674494
6.251213217958879e-06,0.0024776,187.23730177481735,343.326656551313,2.5980668801674494
6.295619640559814e-06,0.0024952,187.30956587169587,343.326656551313,2.5980668801674494
6.331952168142397e-06,0.0025096,187.36854329583915,343.326656551313,2.5980668801674494
6.340026063160749e-06,0.0025128,187.38163144980203,343.326656551313,2.5980668801674494
6.374340116988744e-06,0.0025264,187.43718374146198,343.326656551313,2.5980668801674494
6.432875855871794e-06,0.0025496,187.5316809941864,343.326656551313,2.5980668801674494
6.44700517215391e-06,0.0025552,187.5544403610408,343.326656551313,2.5980668801674494
6.483337699736493e-06,0.0025696,187.61287530204132,343.326656551313,2.5980668801674494
6.5136148060553124e-06,0.0025816,187.6614735917411,343.326656551313,2.5980668801674494
6.533799543601192e-06,0.0025896,187.69382351595974,343.326656551313,2.5980668801674494
6.551965807392483e-06,0.0025968,187.7229051386814,343.326656551313,2.5980668801674494
6.626649336312238e-06,0.0026264,187.84213402376093,343.326656551313,2.5980668801674494
6.687203548949875e-06,0.0026504,187.93842183473248,343.326656551313,2.5980668801674494
6.707388286495756e-06,0.0026584,187.97044212771152,343.326656551313,2.5980668801674494
6.727573024041634e-06,0.0026663999999999998,188.00242486242547,343.326656551313,2.5980668801674494
6.761887077869631e-06,0.00268,188.05670975776002,343.326656551313,2.5980668801674494
6.782071815415509e-06,0.002688,188.0885918639277,343.326656551313,2.5980668801674494
6.864829239353615e-06,0.0027207999999999998,188.2189234660917,343.326656551313,2.5980668801674494
6.876940081881143e-06,0.0027256,188.23794486076793,343.326656551313,2.5980668801674494
6.895106345672435e-06,0.0027328,188.26645247559296,343.326656551313,2.5980668801674494
6.975845295855953e-06,0.0027648,188.3928002485506,343.326656551313,2.5980668801674494
7.012177823438536e-06,0.0027792,188.4494705480273,343.326656551313,2.5980668801674494
7.024288665966064e-06,0.002784,188.46833518496297,343.326656551313,2.5980668801674494
7.032362560984414e-06,0.0027871999999999997,188.48090456294213,343.326656551313,2.5980668801674494
7.0586027197940585e-06,0.0027976,188.52171622754815,343.326656551313,2.5980668801674494
7.094935247376642e-06,0.002812,188.5781271392997,343.326656551313,2.5980668801674494
7.135304722468401e-06,0.002828,188.64067396231906,343.326656551313,2.5980668801674494
7.161544881278044e-06,0.0028384,188.6812554028788,343.326656551313,2.5980668801674494
7.179711145069335e-06,0.0028455999999999998,188.70931628243537,343.326656551313,2.5980668801674494
7.242283831461562e-06,0.0028704,188.80575918242647,343.326656551313,2.5980668801674494
7.286690254062497e-06,0.002888,188.87400548515038,343.326656551313,2.5980668801674494
7.3432075191909595e-06,0.0029104,188.96063028103393,343.326656551313,2.5980668801674494
7.391650889301069e-06,0.0029295999999999997,189.03467335656276,343.326656551313,2.5980668801674494
7.421927995619889e-06,0.0029416,189.0808541867741,343.326656551313,2.5980668801674494
7.427983416883653e-06,0.002944,189.09008152979942,343.326656551313,2.5980668801674494
7.5188147358401115e-06,0.00298,189.2281415357312,343.326656551313,2.5980668801674494
7.534962525876814e-06,0.0029863999999999997,189.25261728545556,343.326656551313,2.5980668801674494
7.5531287896681064e-06,0.0029936,189.28012806513584,343.326656551313,2.5980668801674494
7.62781231858786e-06,0.0030231999999999998,189.39295788467052,343.326656551313,2.5980668801674494
7.660107898661268e-06,0.003036,189.44161563098763,343.326656551313,2.5980668801674494
7.66616331992503e-06,0.0030383999999999997,189.45073004462665,343.326656551313,2.5980668801674494
7.724699058808081e-06,0.0030616,189.53869176689028,343.326656551313,2.5980668801674494
7.773142428918193e-06,0.0030808,189.6112912556489,343.326656551313,2.5980668801674494
7.868010695383826e-06,0.0031184,189.75295613401752,343.326656551313,2.5980668801674494
7.892232380438881e-06,0.0031279999999999997,189.78901893990889,343.326656551313,2.5980668801674494
7.93260185553064e-06,0.0031439999999999997,189.8490278426702,343.326656551313,2.5980668801674494
7.95278659307652e-06,0.003152,189.87898762247448,343.326656551313,2.5980668801674494
8.005266910695808e-06,0.0031728,189.95674459013992,343.326656551313,2.5980668801674494
8.02141470073251e-06,0.0031791999999999996,189.9806297817856,343.326656551313,2.5980668801674494
8.071876544597208e-06,0.0031991999999999997,190.0551504268946,343.326656551313,2.5980668801674494
8.162707863553666e-06,0.0032351999999999997,190.18883133732746,343.326656551313,2.5980668801674494
8.265650025037653e-06,0.003276,190.33963702010087,343.326656551313,2.5980668801674494
8.324185763920704e-06,0.0032992,190.42506257005758,343.326656551313,2.5980668801674494
8.392813871576693e-06,0.0033263999999999998,190.52491888604084,343.326656551313,2.5980668801674494
8.435201820423039e-06,0.0033431999999999997,190.58643578297952,343.326656551313,2.5980668801674494
8.47355282176021e-06,0.0033583999999999997,190.64199012153736,343.326656551313,2.5980668801674494
8.485663664287738e-06,0.0033632,190.6595132129139,343.326656551313,2.5980668801674494
8.540162455661614e-06,0.0033848,190.7382467353532,343.326656551313,2.5980668801674494
8.57245803573502e-06,0.0033975999999999998,190.78481117606736,343.326656551313,2.5980668801674494
8.584568878262549e-06,0.0034024,190.80225519656315,343.326656551313,2.5980668801674494
8.618882932090543e-06,0.0034159999999999998,190.85162787708046,343.326656551313,2.5980668801674494
8.679437144728183e-06,0.00344,190.93856953434565,343.326656551313,2.5980668801674494
8.735954409856644e-06,0.0034624,191.01950189175145,343.326656551313,2.5980668801674494
8.796508622494282e-06,0.0034863999999999997,191.10598886338062,343.326656551313,2.5980668801674494
8.840915045095217e-06,0.0035039999999999997,191.16926514251008,343.326656551313,2.5980668801674494
8.875229098923213e-06,0.0035175999999999996,191.21807559003852,343.326656551313,2.5980668801674494
8.895413836469093e-06,0.0035256,191.24675323850235,343.326656551313,2.5980668801674494
8.913580100260384e-06,0.0035328,191.27254143084363,343.326656551313,2.5980668801674494
8.935783311560851e-06,0.0035415999999999998,191.30403251347434,343.326656551313,2.5980668801674494
9.01652226174437e-06,0.0035735999999999997,191.4182891948233,343.326656551313,2.5980668801674494
9.121482896982942e-06,0.0036152,191.56622811875368,343.326656551313,2.5980668801674494
9.145704582037997e-06,0.0036247999999999996,191.6002734111553,343.326656551313,2.5980668801674494
9.157815424565526e-06,0.0036295999999999998,191.6172828692439,343.326656551313,2.5980668801674494
9.224425058466928e-06,0.003656,191.71067854595728,343.326656551313,2.5980668801674494
9.270849954822452e-06,0.0036744,191.77561702085436,343.326656551313,2.5980668801674494
9.286997744859154e-06,0.0036807999999999997,191.79817457254865,343.326656551313,2.5980668801674494
9.34149653623303e-06,0.0037024,191.8741936312047,343.326656551313,2.5980668801674494
9.3798475375702e-06,0.0037175999999999997,191.92758487482894,343.326656551313,2.5980668801674494
9.448475645226192e-06,0.0037448,192.02291509765038,343.326656551313,2.5980668801674494
9.525177647900533e-06,0.0037752,192.12914164704708,343.326656551313,2.5980668801674494
9.640230651912045e-06,0.0038207999999999996,192.2878580934331,343.326656551313,2.5980668801674494
9.64628607317581e-06,0.0038231999999999997,192.29619106669523,343.326656551313,2.5980668801674494
9.682618600758393e-06,0.0038376,192.34614613182498,343.326656551313,2.5980668801674494
9.729043497113915e-06,0.0038559999999999996,192.40987134684988,343.326656551313,2.5980668801674494
9.783542288487789e-06,0.0038775999999999997,192.4845280829814,343.326656551313,2.5980668801674494
9.797671604769907e-06,0.0038832,192.50385703566903,343.326656551313,2.5980668801674494
9.836022606107077e-06,0.0038983999999999998,192.55626661488185,343.326656551313,2.5980668801674494
9.842078027370841e-06,0.0039008,192.5645345208814,343.326656551313,2.5980668801674494
9.92079850379977e-06,0.003932,192.6718374010537,343.326656551313,2.5980668801674494
9.967223400155293e-06,0.0039504,192.7349629315544,343.326656551313,2.5980668801674494
1.0013648296510817e-05,0.0039688,192.7979738965486,343.326656551313,2.5980668801674494
1.0066128614130102e-05,0.003989599999999999,192.8690666545086,343.326656551313,2.5980668801674494
1.1158336108829363e-05,0.00442248449689938,194.3173296452415,343.326656551313,2.5980668801674494
1.1545960594607405e-05,0.004576115223044609,194.81787692415477,343.326656551313,2.5980668801674494
1.362944220566438e-05,0.005401880376075216,197.4036051611626,343.326656551313,2.5980668801674494
1.4162425873609186e-05,0.005613122624524905,198.03967531859666,343.326656551313,2.5980668801674494
1.5083034027332036e-05,0.005977995599119824,199.1167740621738,343.326656551313,2.5980668801674494
1.5616017695276845e-05,0.006189237847569514,199.7286334101651,343.326656551313,2.5980668801674494
1.6100548302499397e-05,0.00638127625525105,200.27783701165444,343.326656551313,2.5980668801674494
1.740878094200029e-05,0.0068997799559911985,201.72939632856873,343.326656551313,2.5980668801674494
1.8523201338612156e-05,0.007341468293658731,202.93264046636958,343.326656551313,2.5980668801674494
2.002524622100207e-05,0.007936787357471494,204.51063114580438,343.326656551313,2.5980668801674494
2.021905846389109e-05,0.008013602720544109,204.7108255779733,343.326656551313,2.5980668801674494
2.0800495192558153e-05,0.008244048809761952,205.30696588633415,343.326656551313,2.5980668801674494
2.2496352317837088e-05,0.00891618323664733,207.00965809118375,343.326656551313,2.5980668801674494
2.3707678835893468e-05,0.00939627925585117,208.19533853488784,343.326656551313,2.5980668801674494
2.491900535394985e-05,0.009876375275055011,209.35761399319992,343.326656551313,2.5980668801674494
2.593651962911721e-05,0.010279655931186238,210.3169902141132,343.326656551313,2.5980668801674494
2.6566409418506523e-05,0.010529305861172233,210.90353778822364,343.326656551313,2.5980668801674494
2.753547063295163e-05,0.010913382676535306,211.79543660362927,343.326656551313,2.5980668801674494
2.8504531847396734e-05,0.011297459491898379,212.67517444572192,343.326656551313,2.5980668801674494
2.947359306184184e-05,0.011681536307261452,213.54332241645514,343.326656551313,2.5980668801674494
3.0055029790508903e-05,0.011911982396479295,214.05886878729214,343.326656551313,2.5980668801674494
3.112099712639852e-05,0.012334466893378675,214.99404558090185,343.326656551313,2.5980668801674494
3.150862161217656e-05,0.012488097619523904,215.33100158623552,343.326656551313,2.5980668801674494
3.2574588948066175e-05,0.012910582116423285,216.24939571195674,343.326656551313,2.5980668801674494
3.427044607334511e-05,0.013582716543308662,217.68667827012834,343.326656551313,2.5980668801674494
3.490033586273443e-05,0.013832366473294659,218.21342588690572,343.326656551313,2.5980668801674494
3.591785013790179e-05,0.014235647129425886,219.05656016225143,343.326656551313,2.5980668801674494
3.7855972566791997e-05,0.015003800760152031,220.63719302672905,343.326656551313,2.5980668801674494
3.843740929545906e-05,0.015234246849369875,221.10518614567602,343.326656551313,2.5980668801674494
3.911575214557063e-05,0.015503100620124026,221.64770276972453,343.326656551313,2.5980668801674494
4.013326642073799e-05,0.015906381276255252,222.45464782718503,343.326656551313,2.5980668801674494
4.066625008868281e-05,0.016117623524704944,222.87414669752718,343.326656551313,2.5980668801674494
4.124768681734986e-05,0.016348069613922784,223.32934381335937,343.326656551313,2.5980668801674494
4.294354394262879e-05,0.01702020404080816,224.64292134924855,343.326656551313,2.5980668801674494
4.3718792914184876e-05,0.017327465493098618,225.23665968225308,343.326656551313,2.5980668801674494
4.4251776582129685e-05,0.01753870774154831,225.6424749278344,343.326656551313,2.5980668801674494
4.497857249296352e-05,0.017826765353070616,226.1928005988518,343.326656551313,2.5980668801674494
4.5560009221630584e-05,0.01805721144228846,226.63056812956296,343.326656551313,2.5980668801674494
4.599608676813088e-05,0.01823004600920184,226.9574653186976,343.326656551313,2.5980668801674494
4.638371125390892e-05,0.01838367673534707,227.2470272502021,343.326656551313,2.5980668801674494
4.711050716474275e-05,0.018671734346869376,227.78742483084946,343.326656551313,2.5980668801674494
4.837028674352138e-05,0.019171034206841367,228.71647411092954,343.326656551313,2.5980668801674494
4.958161326157776e-05,0.01965113022604521,229.60093129311224,343.326656551313,2.5980668801674494
5.069603365818963e-05,0.02009281856371274,230.4072168686835,343.326656551313,2.5980668801674494
5.1229017326134444e-05,0.020304060812162433,230.79038555751234,343.326656551313,2.5980668801674494
5.248879690491308e-05,0.020803360672134428,231.68992901399062,343.326656551313,2.5980668801674494
5.360321730152495e-05,0.02124504900980196,232.4786833053711,343.326656551313,2.5980668801674494
5.403929484802525e-05,0.021417883576715344,232.78558217023988,343.326656551313,2.5980668801674494
5.5347527487526136e-05,0.02193638727745549,233.70053529511551,343.326656551313,2.5980668801674494
5.573515197330418e-05,0.02209001800360072,233.97000764514578,343.326656551313,2.5980668801674494
5.660730706630477e-05,0.022435687137427485,234.5736623075427,343.326656551313,2.5980668801674494
5.844852337375047e-05,0.023165433086617324,235.83626031672438,343.326656551313,2.5980668801674494
5.898150704169528e-05,0.023376675335067015,236.19884164547534,343.326656551313,2.5980668801674494
5.9320678466751064e-05,0.02351110222044409,236.42891006199912,343.326656551313,2.5980668801674494
5.975675601325136e-05,0.02368393678735747,236.7239598881023,343.326656551313,2.5980668801674494
6.038664580264068e-05,0.02393358671734347,237.14866479682047,343.326656551313,2.5980668801674494
6.217940904936413e-05,0.024644128825765152,238.34808555034564,343.326656551313,2.5980668801674494
6.314847026380923e-05,0.025028205641128225,238.9908022177591,343.326656551313,2.5980668801674494
6.532885799631071e-05,0.02589237847569514,240.42301420000808,343.326656551313,2.5980668801674494
6.600720084642229e-05,0.02616123224644929,240.8647729400808,343.326656551313,2.5980668801674494
6.799377633603475e-05,0.02694858971794359,242.1484216692277,343.326656551313,2.5980668801674494
7.031952325070301e-05,0.027870374074814963,243.6327884140586,343.326656551313,2.5980668801674494
7.041642937214752e-05,0.02790878175635127,243.6942180387969,343.326656551313,2.5980668801674494
7.196692731525968e-05,0.028523304660932187,244.67265162763863,343.326656551313,2.5980668801674494
7.29359885297048e-05,0.02890738147629526,245.2799994690554,343.326656551313,2.5980668801674494
7.39050497441499e-05,0.029291458291658332,245.88420823355042,343.326656551313,2.5980668801674494
7.477720483715049e-05,0.029637127425485098,246.42535941603165,343.326656551313,2.5980668801674494
7.647306196242942e-05,0.030309261852370473,247.47060249240016,343.326656551313,2.5980668801674494
7.758748235904129e-05,0.03075095019003801,248.15255801803252,343.326656551313,2.5980668801674494
7.845963745204189e-05,0.031096619323864774,248.6836011614901,343.326656551313,2.5980668801674494
8.068847824526564e-05,0.031979995999199845,250.03035667818412,343.326656551313,2.5980668801674494
8.175444558115524e-05,0.03240248049609922,250.6693213983927,343.326656551313,2.5980668801674494
8.233588230982231e-05,0.032632926585317065,251.0164778140866,343.326656551313,2.5980668801674494
8.301422515993389e-05,0.03290178035607122,251.42028753416287,343.326656551313,2.5980668801674494
8.32080374028229e-05,0.03297859571914383,251.5354251099286,343.326656551313,2.5980668801674494
8.703582919988106e-05,0.034495699139827966,253.7883923497016,343.326656551313,2.5980668801674494
8.74234536856591e-05,0.034649329865973195,254.01436470312683,343.326656551313,2.5980668801674494
8.83925149001042e-05,0.03503340668133627,254.57759273848782,343.326656551313,2.5980668801674494
8.970074753960511e-05,0.03555191038207642,255.33414543036696,343.326656551313,2.5980668801674494
9.023373120754991e-05,0.03576315263052611,255.64113543656924,343.326656551313,2.5980668801674494
9.066980875405019e-05,0.035935987197439484,255.89178341273794,343.326656551313,2.5980668801674494
9.178422915066208e-05,0.036377675535107026,256.5302016185803,343.326656551313,2.5980668801674494
9.289864954727395e-05,0.036819363872774555,257.1656037938979,343.326656551313,2.5980668801674494
9.314091485088521e-05,0.03691538307661532,257.3033405399283,343.326656551313,2.5980668801674494
9.51274903404977e-05,0.037702740548109626,258.4275593384054,343.326656551313,2.5980668801674494
9.8034673983833e-05,0.03885497099419884,260.0563915717326,343.326656551313,2.5980668801674494
9.885837601611135e-05,0.039181436287257454,260.5144549562949,343.326656551313,2.5980668801674494
9.973053110911193e-05,0.039527105421084216,260.99784381650244,343.326656551313,2.5980668801674494
0.0001011841229307796,0.04010322064412883,261.79984424356434,343.326656551313,2.5980668801674494
0.00010132948211294637,0.04016083216643329,261.8797963583083,343.326656551313,2.5980668801674494
0.00010195937190233569,0.04041048209641929,262.2257399244156,343.326656551313,2.5980668801674494
0.00010443047799917071,0.041389877975595124,263.5749301025227,343.326656551313,2.5980668801674494
0.00010506036778856001,0.04163952790558112,263.91684274370226,343.326656551313,2.5980668801674494
0.00010539953921361579,0.04177395479095819,264.1006183678207,343.326656551313,2.5980668801674494
0.00010559335145650483,0.04185077015403081,264.2055294565791,343.326656551313,2.5980668801674494
0.00010690158409600572,0.04236927385477096,264.911725246376,343.326656551313,2.5980668801674494
0.00010743456776395051,0.04258051610322064,265.1984673920513,343.326656551313,2.5980668801674494
0.00010990567386078553,0.043559911982396476,266.52072602844027,343.326656551313,2.5980668801674494
0.00011014793916439679,0.04365593118623724,266.6497319827709,343.326656551313,2.5980668801674494
0.00011053556365017484,0.04380956191238247,266.85591157652544,343.326656551313,2.5980668801674494
0.00011164998404678672,0.044251250250050014,267.4471130108131,343.326656551313,2.5980668801674494
0.00011300666974700985,0.04478895779155831,268.16373934142047,343.326656551313,2.5980668801674494
0.0001134912003542324,0.04498099619923984,268.4188631515025,343.326656551313,2.5980668801674494
0.00011421799626506626,0.045269053810762155,268.80075382869904,343.326656551313,2.5980668801674494
0.0001146056207508443,0.045422684536907385,269.0040412888571,343.326656551313,2.5980668801674494
0.00011528396360095588,0.04569153830766154,269.35915028332164,343.326656551313,2.5980668801674494
0.00011678600848334578,0.046286857371474296,270.14257589876445,343.326656551313,2.5980668801674494
0.0001178519758192354,0.04670934186837368,270.696173202885,343.326656551313,2.5980668801674494
0.00011877258397295825,0.0470742148429686,271.17271026803377,343.326656551313,2.5980668801674494
0.00011974164518740334,0.04745829165833167,271.67277461224813,343.326656551313,2.5980668801674494
0.00012041998803751492,0.04772714542908582,272.0218809667464,343.326656551313,2.5980668801674494
0.00012114678394834874,0.04801520304060812,272.39507348475024,343.326656551313,2.5980668801674494
0.00012192203291990483,0.04832246449289858,272.79218437370554,343.326656551313,2.5980668801674494
0.00012332717168085023,0.04887937587517503,273.50944689643546,343.326656551313,2.5980668801674494
0.0001235694369844615,0.0489753950790158,273.6327900260988,343.326656551313,2.5980668801674494
0.00012405396759168408,0.049167433486697346,273.8791937183743,343.326656551313,2.5980668801674494
0.00012434468595601757,0.04928265653130626,274.02685577803277,343.326656551313,2.5980668801674494
0.0001253137471704627,0.04966673334666934,274.51809312067064,343.326656551313,2.5980668801674494
0.00012574982471696297,0.04983956791358271,274.7386663511675,343.326656551313,2.5980668801674494
0.00012943225733185438,0.051299059811962394,276.5895367743934,343.326656551313,2.5980668801674494
0.00013078894303207754,0.05183676735347069,277.26624471819014,343.326656551313,2.5980668801674494
0.00013132192670002233,0.05204800960192038,277.53134458250014,343.326656551313,2.5980668801674494
0.0001321456287323007,0.052374474894979,277.94022050774475,343.326656551313,2.5980668801674494
0.00013359922055396835,0.05295059011802361,278.6593497604643,343.326656551313,2.5980668801674494
0.0001341806572826354,0.05318103620724145,278.94614626582995,343.326656551313,2.5980668801674494
0.0001356827021650253,0.053776355271054205,279.6848028953398,343.326656551313,2.5980668801674494
0.00013674866950091492,0.05419883976795359,280.207077400483,343.326656551313,2.5980668801674494
0.0001376208245939155,0.05454450890178035,280.63321293555504,343.326656551313,2.5980668801674494
0.00013781463683680456,0.05462132426485297,280.7277665398075,343.326656551313,2.5980668801674494
0.00013888060417269419,0.055043808761752355,281.24688733280755,343.326656551313,2.5980668801674494
0.0001395589470228057,0.055312662532506496,281.576428008703,343.326656551313,2.5980668801674494
0.0001407702735408621,0.05579275855171034,282.1633439391209,343.326656551313,2.5980668801674494
0.0001413517102695292,0.05602320464092819,282.44436368111417,343.326656551313,2.5980668801674494
0.00014324137963769713,0.05677215443088618,283.35458009000627,343.326656551313,2.5980668801674494
0.00014372591024491968,0.05696419283856771,283.5872130773247,343.326656551313,2.5980668801674494
0.00014421044085214223,0.057156231246249245,283.8195404053761,343.326656551313,2.5980668801674494
0.00014464651839864255,0.05732906581316263,284.0283748412479,343.326656551313,2.5980668801674494
0.0001462939224631992,0.05798199639927985,284.81509884174534,343.326656551313,2.5980668801674494
0.00014673000000969952,0.05815483096619324,285.0227700149577,343.326656551313,2.5980668801674494
0.00014774751428486688,0.058558111622324466,285.5064022608793,343.326656551313,2.5980668801674494
0.0001484743101957007,0.058846169233846765,285.85105891300844,343.326656551313,2.5980668801674494
0.00014920110610653454,0.05913422684536908,286.19505821007084,343.326656551313,2.5980668801674494
0.00014949182447086804,0.05924944988997799,286.33247486729573,343.326656551313,2.5980668801674494
0.00014963718365303483,0.05930706141228245,286.4011441098903,343.326656551313,2.5980668801674494
0.00015007326119953512,0.05947989597919584,286.6069959152991,343.326656551313,2.5980668801674494
0.00015113922853542475,0.059902380476095224,287.10920958781077,343.326656551313,2.5980668801674494
0.00015167221220336956,0.060113622724544916,287.35979826180017,343.326656551313,2.5980668801674494
0.00015230210199275888,0.06036327265453091,287.6555061808444,343.326656551313,2.5980668801674494
0.00015244746117492564,0.060420884176835374,287.72367868988357,343.326656551313,2.5980668801674494
0.00015361033463225977,0.06088177635527106,288.2681491025051,343.326656551313,2.5980668801674494
0.00015457939584670485,0.06126585317063413,288.720647577991,343.326656551313,2.5980668801674494
0.00015593608154692803,0.061803560712142436,289.35229122495434,343.326656551313,2.5980668801674494
0.0001583587345830408,0.06276375275055011,290.4749212183539,343.326656551313,2.5980668801674494
0.00015986077946543068,0.06335907181436287,291.1675889132634,343.326656551313,2.5980668801674494
0.0001602484039512087,0.0635127025405081,291.3459292542902,343.326656551313,2.5980668801674494
0.00016131437128709834,0.06393518703740748,291.8354998017082,343.326656551313,2.5980668801674494
0.0001641731018697114,0.06506821364272855,293.1422497457386,343.326656551313,2.5980668801674494
0.00016480299165910073,0.06531786357271455,293.4289811252615,343.326656551313,2.5980668801674494
0.00016533597532704554,0.06552910582116424,293.6712663109607,343.326656551313,2.5980668801674494
0.00016596586511643486,0.06577875575115023,293.9572109861244,343.326656551313,2.5980668801674494
0.00016649884878437967,0.06598999799959993,294.19883374486034,343.326656551313,2.5980668801674494
0.0001672256446952135,0.06627805561112222,294.52783375647755,343.326656551313,2.5980668801674494
0.00016732255081665799,0.06631646329265853,294.57165825240514,343.326656551313,2.5980668801674494
0.00016800089366676956,0.06658531706341268,294.8781530366311,343.326656551313,2.5980668801674494
0.00016984210997421527,0.06731506301260252,295.7076441924488,343.326656551313,2.5980668801674494
0.0001710049834315494,0.06777595519103821,296.22972686157794,343.326656551313,2.5980668801674494
0.0001722163099496058,0.06825605121024206,296.772092754215,343.326656551313,2.5980668801674494
0.00017289465279971735,0.0685249049809962,297.0751677397127,343.326656551313,2.5980668801674494
0.00017318537116405087,0.06864012802560512,297.2049150163404,343.326656551313,2.5980668801674494
0.00017429979156066274,0.06908181636327265,297.7014946644944,343.326656551313,2.5980668801674494
0.00017517194665366334,0.06942748549709943,298.08925900346895,343.326656551313,2.5980668801674494
0.00017720697520399808,0.07023404680936188,298.9911261147969,343.326656551313,2.5980668801674494
0.00017812758335772092,0.0705989197839568,299.3977857625678,343.326656551313,2.5980668801674494
0.00017841830172205447,0.07071414282856572,299.5260341991836,343.326656551313,2.5980668801674494
0.0001789997384507215,0.07094458891778356,299.7822868385465,343.326656551313,2.5980668801674494
0.00017996879966516663,0.07132866573314664,300.2086543564216,343.326656551313,2.5980668801674494
0.00018030797109022242,0.07146309261852371,300.35767133487457,343.326656551313,2.5980668801674494
0.00018088940781888944,0.07169353870774155,300.6128749239957,343.326656551313,2.5980668801674494
0.00018195537515477907,0.07211602320464093,301.07991881452887,343.326656551313,2.5980668801674494
0.00018224609351911262,0.07223124624924986,301.207109068795,343.326656551313,2.5980668801674494
0.0001829244363692242,0.07250010002000401,301.5035790050146,343.326656551313,2.5980668801674494
0.00018394195064439154,0.07290338067613523,301.9474812353014,343.326656551313,2.5980668801674494
0.00018728521183422717,0.07422844568913783,303.39932068454414,343.326656551313,2.5980668801674494
0.00018796355468433875,0.07449729945989199,303.69265945522864,343.326656551313,2.5980668801674494
0.0001892717873238396,0.07501580316063212,304.2572209192776,343.326656551313,2.5980668801674494
0.00019217897096717492,0.07616803360672135,305.5063817037318,343.326656551313,2.5980668801674494
0.00019285731381728653,0.0764368873774755,305.7967895400385,343.326656551313,2.5980668801674494
0.00019431090563895416,0.0770130026005201,306.4177540000281,343.326656551313,2.5980668801674494
0.00019489234236762124,0.07724344868973795,306.6656322013602,343.326656551313,2.5980668801674494
0.00019532841991412155,0.07741628325665134,306.85135162760895,343.326656551313,2.5980668801674494
0.00019620057500712213,0.0777619523904781,307.2223060796024,343.326656551313,2.5980668801674494
0.00019712118316084497,0.07812682536507302,307.6131721091625,343.326656551313,2.5980668801674494
0.00019784797907167878,0.07841488297659532,307.9212478975982,343.326656551313,2.5980668801674494
0.00020090052189718086,0.079624724944989,309.21037587739045,343.326656551313,2.5980668801674494
0.0002012881463829589,0.07977835567113423,309.3735263026049,343.326656551313,2.5980668801674494
0.00020264483208318207,0.08031606321264254,309.94359036409475,343.326656551313,2.5980668801674494
0.00020375925247979393,0.08075775155031006,310.4107446163639,343.326656551313,2.5980668801674494
0.00020579428103012864,0.08156431286257251,311.2612457863796,343.326656551313,2.5980668801674494
0.00020700560754818503,0.08204440888177636,311.7659393126226,343.326656551313,2.5980668801674494
0.00020773240345901885,0.08233246649329866,312.0682026004826,343.326656551313,2.5980668801674494
0.00020884682385563074,0.0827741548309662,312.53087316394664,343.326656551313,2.5980668801674494
0.00021068804016307642,0.08350390078015603,313.2931814323579,343.326656551313,2.5980668801674494
0.00021088185240596545,0.08358071614322865,313.3732729791096,343.326656551313,2.5980668801674494
0.00021122102383102124,0.08371514302860572,313.51336414323777,343.326656551313,2.5980668801674494
0.00021228699116691084,0.0841376275255051,313.9530805926664,343.326656551313,2.5980668801674494
0.00021446737889941234,0.08500180036007202,314.84982762340564,343.326656551313,2.5980668801674494
0.00021485500338519036,0.08515543108621725,315.0088763741903,343.326656551313,2.5980668801674494
0.00021567870541746873,0.08548189637927586,315.34648387948323,343.326656551313,2.5980668801674494
0.00021693848499624736,0.08598119623924785,315.8618537552901,343.326656551313,2.5980668801674494
0.00021747146866419218,0.08619243848769755,316.07954334214946,343.326656551313,2.5980668801674494
0.00021844052987863725,0.08657651530306061,316.47481026144106,343.326656551313,2.5980668801674494
0.00021940959109308238,0.08696059211842369,316.86939390007785,343.326656551313,2.5980668801674494
0.00021999102782174944,0.08719103820764153,317.10581785392316,343.326656551313,2.5980668801674494
0.00022071782373258328,0.08747909581916384,317.4010053753892,343.326656551313,2.5980668801674494
0.00022192915025063964,0.08795919183836767,317.89214355701876,343.326656551313,2.5980668801674494
0.00022309202370797377,0.08842008401680336,318.36265356626785,343.326656551313,2.5980668801674494
0.00022473942777253046,0.0890730146029206,319.02757537538037,343.326656551313,2.5980668801674494
0.0002255631298048088,0.0893994798959792,319.3593232519051,343.326656551313,2.5980668801674494
0.00022648373795853164,0.08976435287057412,319.72954168034164,343.326656551313,2.5980668801674494
0.0002300208113912563,0.09116623324664934,321.14653382700345,343.326656551313,2.5980668801674494
0.00023035998281631205,0.09130066013202641,321.2819617364604,343.326656551313,2.5980668801674494
0.00023142595015220168,0.09172314462892579,321.7070869249948,343.326656551313,2.5980668801674494
0.00023254037054881355,0.09216483296659332,322.1507202526407,343.326656551313,2.5980668801674494
0.00023312180727748063,0.09239527905581117,322.38185191944484,343.326656551313,2.5980668801674494
0.0002344300399169815,0.09291378275655131,322.90107773672884,343.326656551313,2.5980668801674494
0.0002360289909208159,0.09354750950190038,323.53415498752145,343.326656551313,2.5980668801674494
0.00023704650519598328,0.09395079015803161,323.9361516243531,343.326656551313,2.5980668801674494
0.00023762794192465036,0.09418123624724946,324.1655618343705,343.326656551313,2.5980668801674494
0.0002385485500783732,0.09454610922184438,324.5283474566078,343.326656551313,2.5980668801674494
0.00023869390926053993,0.09460372074414883,324.5855794456182,343.326656551313,2.5980668801674494
0.00023971142353570733,0.09500700140028007,324.985823461882,343.326656551313,2.5980668801674494
0.00024005059496076312,0.09514142828565714,325.1190908215287,343.326656551313,2.5980668801674494
0.0002414557337217085,0.09569833966793359,325.67041796233826,343.326656551313,2.5980668801674494
0.0002440721990007103,0.09673534706941389,326.6937042954551,343.326656551313,2.5980668801674494
0.000245913415308156,0.09746509301860372,327.41123166649504,343.326656551313,2.5980668801674494
0.00024712474182621237,0.09794518903780756,327.88214681222314,343.326656551313,2.5980668801674494
0.00024756081937271266,0.09811802360472095,328.0514557787767,343.326656551313,2.5980668801674494
0.00024833606834426876,0.09842528505701141,328.3521625860946,343.326656551313,2.5980668801674494
0.0002493535826194361,0.09882856571314264,328.7462852605215,343.326656551313,2.5980668801674494
0.0002510494397447151,0.09950070014002801,329.4017654112983,343.326656551313,2.5980668801674494
0.0002512917050483263,0.09959671934386878,329.4952642724196,343.326656551313,2.5980668801674494
0.00025187314177699336,0.09982716543308662,329.71951822422784,343.326656551313,2.5980668801674494
0.00025211540708060465,0.09992318463692738,329.8128977733949,343.326656551313,2.5980668801674494