File: datasets/aisi_316_L/data/M1/train_87.csv
Time(s),Strain(%),Stress(MPa),Temp(C),Log_SR(s-1)
0.0,0.0,0.0,266.6005259255778,4.7187203771870845
5.04525997456267e-10,2.6399999999999998e-05,4.7642091749999995,266.6005259255778,4.7187203771870845
7.9501066265836e-10,4.1599999999999995e-05,7.507238699999999,266.6005259255778,4.7187203771870845
1.1466499942187885e-09,5.9999999999999995e-05,10.827748125,266.6005259255778,4.7187203771870845
1.3759799930625463e-09,7.2e-05,12.99329775,266.6005259255778,4.7187203771870845
1.5747326587271362e-09,8.24e-05,14.870107424999999,266.6005259255778,4.7187203771870845
1.8499286573396456e-09,9.68e-05,17.468766974999998,266.6005259255778,4.7187203771870845
2.0486813230042353e-09,0.00010719999999999999,19.345576649999998,266.6005259255778,4.7187203771870845
2.2627226552584093e-09,0.00011839999999999999,21.3667563,266.6005259255778,4.7187203771870845
2.3544546547959122e-09,0.00012319999999999999,22.23297615,266.6005259255778,4.7187203771870845
2.675516653177173e-09,0.00014,25.264745624999996,266.6005259255778,4.7187203771870845
3.0883106510959372e-09,0.0001616,29.16273495,266.6005259255778,4.7187203771870845
3.3023519833501113e-09,0.0001728,31.1839146,266.6005259255778,4.7187203771870845
3.3635066497084464e-09,0.000176,31.761394499999998,266.6005259255778,4.7187203771870845
3.8680326471647135e-09,0.0002024,36.525603675,266.6005259255778,4.7187203771870845
4.005630646470968e-09,0.0002096,37.82493345,266.6005259255778,4.7187203771870845
4.112651312598055e-09,0.0002152,38.835523275,266.6005259255778,4.7187203771870845
4.234960645314726e-09,0.0002216,39.990483075,266.6005259255778,4.7187203771870845
4.663043309823073e-09,0.000244,44.032842375,266.6005259255778,4.7187203771870845
5.106414640921005e-09,0.0002672,48.21957165,266.6005259255778,4.7187203771870845
5.198146640458508e-09,0.000272,49.0857915,266.6005259255778,4.7187203771870845
5.626229304966856e-09,0.0002944,53.1281508,266.6005259255778,4.7187203771870845
6.314219301498129e-09,0.0003304,59.624799675,266.6005259255778,4.7187203771870845
6.742301966006477e-09,0.0003528,63.667158975,266.6005259255778,4.7187203771870845
6.83403396554398e-09,0.00035759999999999996,64.533378825,266.6005259255778,4.7187203771870845
6.971631964850234e-09,0.0003648,65.83270859999999,266.6005259255778,4.7187203771870845
7.155095963925241e-09,0.0003744,67.5651483,266.6005259255778,4.7187203771870845
7.323271296410663e-09,0.0003832,69.153218025,266.6005259255778,4.7187203771870845
7.720776627739843e-09,0.000404,72.906837375,266.6005259255778,4.7187203771870845
8.072415959300272e-09,0.00042239999999999997,76.22734679999999,266.6005259255778,4.7187203771870845
8.179436625427359e-09,0.000428,77.237936625,266.6005259255778,4.7187203771870845
8.271168624964861e-09,0.0004328,78.104156475,266.6005259255778,4.7187203771870845
8.362900624502364e-09,0.00043759999999999996,78.97037632499999,266.6005259255778,4.7187203771870845
8.653385289704459e-09,0.0004528,81.71340585,266.6005259255778,4.7187203771870845
8.867426621958632e-09,0.000464,83.7345855,266.6005259255778,4.7187203771870845
9.173199953750308e-09,0.00047999999999999996,86.621985,266.6005259255778,4.7187203771870845
9.708303284385742e-09,0.000508,91.674934125,266.6005259255778,4.7187203771870845
9.738880617564911e-09,0.0005096,91.963674075,266.6005259255778,4.7187203771870845
9.907055950050333e-09,0.0005184,93.55174380000001,266.6005259255778,4.7187203771870845
1.0381004614327432e-08,0.0005432,98.027213025,266.6005259255778,4.7187203771870845
1.0671489279529527e-08,0.0005584,100.77024255,266.6005259255778,4.7187203771870845
1.1176015276985792e-08,0.0005848,105.534451725,266.6005259255778,4.7187203771870845
1.132890194288163e-08,0.0005928,106.978151475,266.6005259255778,4.7187203771870845
1.1390056609239966e-08,0.000596,107.55563137499999,266.6005259255778,4.7187203771870845
1.1833427940337898e-08,0.0006192,111.74236065,266.6005259255778,4.7187203771870845
1.2093335272360824e-08,0.0006328,114.196650225,266.6005259255778,4.7187203771870845
1.2123912605539991e-08,0.0006344,114.485390175,266.6005259255778,4.7187203771870845
1.2292087938025413e-08,0.0006432,116.0734599,266.6005259255778,4.7187203771870845
1.23991086041525e-08,0.0006487999999999999,117.08404972499999,266.6005259255778,4.7187203771870845
1.2980077934556685e-08,0.0006791999999999999,122.57010877499998,266.6005259255778,4.7187203771870845
1.3606913264729624e-08,0.000712,128.48927774999999,266.6005259255778,4.7187203771870845
1.3744511264035877e-08,0.0007191999999999999,129.78860752499997,266.6005259255778,4.7187203771870845
1.3989129929469221e-08,0.000732,132.098527125,266.6005259255778,4.7187203771870845
1.470769725917966e-08,0.0007696,138.88391595,266.6005259255778,4.7187203771870845
1.4860583925075498e-08,0.0007775999999999999,140.3276157,266.6005259255778,4.7187203771870845
1.4998181924381754e-08,0.0007848,141.62694547499999,266.6005259255778,4.7187203771870845
1.5395687255710932e-08,0.0008056,145.380564825,266.6005259255778,4.7187203771870845
1.5793192587040114e-08,0.0008263999999999999,149.13418417499997,266.6005259255778,4.7187203771870845
1.5991945252704704e-08,0.0008368,151.01099385,266.6005259255778,4.7187203771870845
1.6496471250160972e-08,0.0008632,155.775203025,266.6005259255778,4.7187203771870845
1.680224458195265e-08,0.0008792,158.662602525,266.6005259255778,4.7187203771870845
1.7031574580796406e-08,0.0008912,160.82815215,266.6005259255778,4.7187203771870845
1.7948894576171438e-08,0.0009392,169.49035064999998,266.6005259255778,4.7187203771870845
1.906496723721106e-08,0.0009976,180.029358825,266.6005259255778,4.7187203771870845
1.9279008569465233e-08,0.0010088,182.050538475,266.6005259255778,4.7187203771870845
1.9447183901950653e-08,0.0010176,183.6386082,266.6005259255778,4.7187203771870845
1.958478190125691e-08,0.0010248,184.93793797499998,266.6005259255778,4.7187203771870845
1.990584389963817e-08,0.0010416,187.96970745,266.6005259255778,4.7187203771870845
2.0165751231661092e-08,0.0010551999999999998,190.42399702499998,266.6005259255778,4.7187203771870845
2.0486813230042356e-08,0.001072,193.4557665,266.6005259255778,4.7187203771870845
2.0593833896169443e-08,0.0010776,194.466356325,266.6005259255778,4.7187203771870845
2.0639699895938196e-08,0.00108,194.89946625,266.6005259255778,4.7187203771870845
2.109835989362571e-08,0.001104,199.23056549999998,266.6005259255778,4.7187203771870845
2.13888445588278e-08,0.0011191999999999999,201.97359502499998,266.6005259255778,4.7187203771870845
2.1969813889231987e-08,0.0011496,207.459654075,266.6005259255778,4.7187203771870845
2.206154588876949e-08,0.0011543999999999999,208.32587392499997,266.6005259255778,4.7187203771870845
2.252020588645701e-08,0.0011784,211.67250903042117,266.6005259255778,4.7187203771870845
2.2611937885994508e-08,0.0011832,211.70329830782248,266.6005259255778,4.7187203771870845
2.293299988437577e-08,0.0012,211.81067924998277,266.6005259255778,4.7187203771870845
2.3116463883450777e-08,0.0012096,211.87177653237893,266.6005259255778,4.7187203771870845
2.380445387998205e-08,0.0012456,212.0992263672236,266.6005259255778,4.7187203771870845
2.400320654564664e-08,0.001256,212.16445490131426,266.6005259255778,4.7187203771870845
2.4400711876975822e-08,0.0012768,212.2942834496063,266.6005259255778,4.7187203771870845
2.464533054240916e-08,0.0012896,212.37376805458595,266.6005259255778,4.7187203771870845
2.4981681207380005e-08,0.0013072,212.4825588179153,266.6005259255778,4.7187203771870845
2.528745453917168e-08,0.0013231999999999999,212.58096480087033,266.6005259255778,4.7187203771870845
2.563909387073211e-08,0.0013415999999999999,212.69355978960547,266.6005259255778,4.7187203771870845
2.57461145368592e-08,0.0013472,212.7277080789087,266.6005259255778,4.7187203771870845
2.6541125199517558e-08,0.0013888,212.97967045544667,266.6005259255778,4.7187203771870845
2.6709300532002982e-08,0.0013976,213.03259104615788,266.6005259255778,4.7187203771870845
2.7167960529690494e-08,0.0014215999999999999,213.1762635165431,266.6005259255778,4.7187203771870845
2.738200186194467e-08,0.0014328,213.2429866466554,266.6005259255778,4.7187203771870845
2.7596043194198845e-08,0.001444,213.30950667349367,266.6005259255778,4.7187203771870845
2.7733641193505097e-08,0.0014512,213.35216331572403,266.6005259255778,4.7187203771870845
2.8161723858013448e-08,0.0014736,213.4843480741579,266.6005259255778,4.7187203771870845
2.8406342523446787e-08,0.0014864,213.55953035651999,266.6005259255778,4.7187203771870845
2.900260052044056e-08,0.0015176,213.7417370909191,266.6005259255778,4.7187203771870845
2.909433251997806e-08,0.0015224,213.76963869727496,266.6005259255778,4.7187203771870845
2.9384817185180152e-08,0.0015375999999999999,213.85776829129202,266.6005259255778,4.7187203771870845
3.0072807181711426e-08,0.0015735999999999999,214.06515190199408,266.6005259255778,4.7187203771870845
3.050088984621977e-08,0.001596,214.1932571168209,266.6005259255778,4.7187203771870845
3.057733317916769e-08,0.0015999999999999999,214.21605906644785,266.6005259255778,4.7187203771870845
3.099012717708646e-08,0.0016216,214.3388075553087,266.6005259255778,4.7187203771870845
3.129590050887814e-08,0.0016376,214.42932164821147,266.6005259255778,4.7187203771870845
3.147936450795314e-08,0.0016472,214.4834645657461,266.6005259255778,4.7187203771870845
3.206033383835733e-08,0.0016776,214.65411086671978,266.6005259255778,4.7187203771870845
3.225908650402192e-08,0.0016879999999999998,214.7122124422229,266.6005259255778,4.7187203771870845
3.230495250379067e-08,0.0016903999999999999,214.72560065218173,266.6005259255778,4.7187203771870845
3.244255050309692e-08,0.0016975999999999998,214.76572087318425,266.6005259255778,4.7187203771870845
3.258014850240318e-08,0.0017048,214.80577478595075,266.6005259255778,4.7187203771870845
3.323756116575529e-08,0.0017392,214.99624027731542,266.6005259255778,4.7187203771870845
3.36044891639053e-08,0.0017584,215.1019075811099,266.6005259255778,4.7187203771870845
3.401728316182406e-08,0.00178,215.22024690447518,266.6005259255778,4.7187203771870845
3.413959249454073e-08,0.0017863999999999998,215.25520268066774,266.6005259255778,4.7187203771870845
3.4368922493384486e-08,0.0017984,215.32061340108345,266.6005259255778,4.7187203771870845
3.514864448945326e-08,0.0018391999999999998,215.5417475642628,266.6005259255778,4.7187203771870845
3.554614982078245e-08,0.0018599999999999999,215.65374577857744,266.6005259255778,4.7187203771870845
3.572961381985745e-08,0.0018696,215.7052724137484,266.6005259255778,4.7187203771870845
3.6035387151649125e-08,0.0018855999999999999,215.79092142751253,266.6005259255778,4.7187203771870845
3.6387026483209554e-08,0.0019039999999999999,215.88906817291948,266.6005259255778,4.7187203771870845
3.657049048228456e-08,0.0019136,215.940128287644,266.6005259255778,4.7187203771870845
3.690684114725541e-08,0.0019311999999999999,216.03347978660216,266.6005259255778,4.7187203771870845
3.7258480478815836e-08,0.0019496,216.13072046560563,266.6005259255778,4.7187203771870845
3.7319635145174173e-08,0.0019528,216.1475952867719,266.6005259255778,4.7187203771870845
3.7625408476965846e-08,0.0019687999999999997,216.23180816692985,266.6005259255778,4.7187203771870845
3.811464580783253e-08,0.0019944,216.36599572088372,266.6005259255778,4.7187203771870845
3.8252243807138786e-08,0.0020016,216.4036147217196,266.6005259255778,4.7187203771870845
3.8649749138467965e-08,0.0020223999999999997,216.51199651784125,266.6005259255778,4.7187203771870845
3.894023380367006e-08,0.0020376,216.5909238738336,266.6005259255778,4.7187203771870845
3.950591446748466e-08,0.0020672,216.7439686253233,266.6005259255778,4.7187203771870845
3.9567069133842996e-08,0.0020704,216.7604626505788,266.6005259255778,4.7187203771870845
3.981168779927634e-08,0.0020832,216.82633957123412,266.6005259255778,4.7187203771870845
4.07901624610097e-08,0.0021344,217.08828378649406,266.6005259255778,4.7187203771870845
4.111122445939096e-08,0.0021512,217.1736987416825,266.6005259255778,4.7187203771870845
4.141699779118264e-08,0.0021671999999999998,217.2548047770633,266.6005259255778,4.7187203771870845
4.213556512089308e-08,0.0022048,217.4444902436177,266.6005259255778,4.7187203771870845
4.238018378632642e-08,0.0022175999999999997,217.5087756272119,266.6005259255778,4.7187203771870845
4.2502493119043096e-08,0.002224,217.54086404044216,266.6005259255778,4.7187203771870845
4.283884378401394e-08,0.0022416,217.62892202019108,266.6005259255778,4.7187203771870845
4.2899998450372275e-08,0.0022448,217.64490355007038,266.6005259255778,4.7187203771870845
4.300701911649937e-08,0.0022504,217.67284986443897,266.6005259255778,4.7187203771870845
4.3496256447366046e-08,0.002276,217.80026063650038,266.6005259255778,4.7187203771870845
4.3817318445747307e-08,0.0022928,217.88357033151135,266.6005259255778,4.7187203771870845
4.40160711114119e-08,0.0023032,217.9350237106835,266.6005259255778,4.7187203771870845
4.4291267110024403e-08,0.0023176,218.00611751360088,266.6005259255778,4.7187203771870845
4.4749927107711926e-08,0.0023416,218.1242255433464,266.6005259255778,4.7187203771870845
4.4841659107249425e-08,0.0023464,218.14779039352928,266.6005259255778,4.7187203771870845
4.530031910493694e-08,0.0023704,218.26533381204496,266.6005259255778,4.7187203771870845
4.545320577083277e-08,0.0023783999999999997,218.30441168846193,266.6005259255778,4.7187203771870845
4.5743690436034876e-08,0.0023936,218.37851871466603,266.6005259255778,4.7187203771870845
4.5927154435109874e-08,0.0024032,218.4252286032656,266.6005259255778,4.7187203771870845
4.608004110100572e-08,0.0024112,218.4640979479345,266.6005259255778,4.7187203771870845
4.635523709961823e-08,0.0024256,218.53393626074674,266.6005259255778,4.7187203771870845
4.6737453764357826e-08,0.0024456,218.63066626391296,266.6005259255778,4.7187203771870845
4.679860843071615e-08,0.0024487999999999997,218.64611438893374,266.6005259255778,4.7187203771870845
4.7134959095687004e-08,0.0024664,218.730938765213,266.6005259255778,4.7187203771870845
4.763948509314327e-08,0.0024928,218.8577340418126,266.6005259255778,4.7187203771870845
4.7777083092449525e-08,0.0025,218.89222354365478,266.6005259255778,4.7187203771870845
4.8205165756957866e-08,0.0025223999999999997,218.99927731271467,266.6005259255778,4.7187203771870845
4.863324842146622e-08,0.0025448,219.1059609506594,266.6005259255778,4.7187203771870845
4.90307537527954e-08,0.0025656,219.2046968635294,266.6005259255778,4.7187203771870845
4.947412508389333e-08,0.0025888,219.31445782012113,266.6005259255778,4.7187203771870845
4.994807374817043e-08,0.0026135999999999998,219.431365134306,266.6005259255778,4.7187203771870845
5.0131537747245435e-08,0.0026232,219.47650333043705,266.6005259255778,4.7187203771870845
5.0223269746782934e-08,0.0026279999999999997,219.49904826617225,266.6005259255778,4.7187203771870845
5.052904307857462e-08,0.002644,219.57408233669426,266.6005259255778,4.7187203771870845
5.1079435075799635e-08,0.0026728,219.7086989258491,266.6005259255778,4.7187203771870845
5.124761040828505e-08,0.0026815999999999997,219.74971878181955,266.6005259255778,4.7187203771870845
5.156867240666631e-08,0.0026983999999999997,219.8278839283764,266.6005259255778,4.7187203771870845
5.2119064403891335e-08,0.0027272,219.96144119794624,266.6005259255778,4.7187203771870845
5.260830173475801e-08,0.0027527999999999997,220.07969768496213,266.6005259255778,4.7187203771870845
5.2761188400653855e-08,0.0027608,220.11656477754087,266.6005259255778,4.7187203771870845
5.285292040019136e-08,0.0027656,220.13866503501956,266.6005259255778,4.7187203771870845
5.305167306585595e-08,0.002776,220.18649767257037,266.6005259255778,4.7187203771870845
5.329629173128929e-08,0.0027887999999999997,220.24527277821278,266.6005259255778,4.7187203771870845
5.363264239626013e-08,0.0028063999999999997,220.3259170520955,266.6005259255778,4.7187203771870845
5.3739663062387224e-08,0.002812,220.3515351983107,266.6005259255778,4.7187203771870845
5.422890039325391e-08,0.0028376,220.4683942714952,266.6005259255778,4.7187203771870845
5.4519385058456e-08,0.0028528,220.53758481582682,266.6005259255778,4.7187203771870845
5.464169439117267e-08,0.0028591999999999997,220.56667464664037,266.6005259255778,4.7187203771870845
5.4779292390478924e-08,0.0028664,220.599370368975,266.6005259255778,4.7187203771870845
5.5390839054062276e-08,0.0028983999999999998,220.7442989037746,266.6005259255778,4.7187203771870845
5.548257105359978e-08,0.0029032,220.76598424192784,266.6005259255778,4.7187203771870845
5.588007638492896e-08,0.002924,220.8597929239174,266.6005259255778,4.7187203771870845
5.626229304966856e-08,0.002944,220.94974845670626,266.6005259255778,4.7187203771870845
5.6461045715333144e-08,0.0029544,220.99643112642627,266.6005259255778,4.7187203771870845
5.6736241713945655e-08,0.0029687999999999997,221.06096300364464,266.6005259255778,4.7187203771870845
5.7592407042962356e-08,0.0030136,221.26095257960105,266.6005259255778,4.7187203771870845
5.7974623707701954e-08,0.0030336,221.34985893452162,266.6005259255778,4.7187203771870845
5.8066355707239446e-08,0.0030383999999999997,221.3711624091869,266.6005259255778,4.7187203771870845
5.8402706372210294e-08,0.0030559999999999997,221.44916310774553,266.6005259255778,4.7187203771870845
5.847914970515821e-08,0.00306,221.46686608298214,266.6005259255778,4.7187203771870845
5.869319103741239e-08,0.0030712,221.5163864648356,266.6005259255778,4.7187203771870845
5.916713970168949e-08,0.003096,221.62578878999358,266.6005259255778,4.7187203771870845
5.979397503186243e-08,0.0031287999999999997,221.76995868957303,266.6005259255778,4.7187203771870845
6.01914803631916e-08,0.0031496,221.86107816955692,266.6005259255778,4.7187203771870845
6.034436702908745e-08,0.0031576,221.89606159605538,266.6005259255778,4.7187203771870845
6.052783102816245e-08,0.0031672,221.93799611277396,266.6005259255778,4.7187203771870845
6.112408902515622e-08,0.0031983999999999997,222.0739422154759,266.6005259255778,4.7187203771870845
6.175092435532917e-08,0.0032312,222.21630343247116,266.6005259255778,4.7187203771870845
6.202612035394166e-08,0.0032456,222.27862532972352,266.6005259255778,4.7187203771870845
6.239304835209169e-08,0.0032648,222.3615537031963,266.6005259255778,4.7187203771870845
6.262237835093544e-08,0.0032768,222.41328736190914,266.6005259255778,4.7187203771870845
6.274468768365211e-08,0.0032832,222.44084843251363,266.6005259255778,4.7187203771870845
6.311161568180212e-08,0.0033024,222.5234062010583,266.6005259255778,4.7187203771870845
6.324921368110837e-08,0.0033095999999999998,222.55431707635924,266.6005259255778,4.7187203771870845
6.357027567948963e-08,0.0033263999999999998,222.6263406416214,266.6005259255778,4.7187203771870845
6.395249234422923e-08,0.0033464,222.71189827355335,266.6005259255778,4.7187203771870845
6.427355434261049e-08,0.0033632,222.7836126805655,266.6005259255778,4.7187203771870845
6.453346167463341e-08,0.0033767999999999997,222.8415649273652,266.6005259255778,4.7187203771870845
6.51297196716272e-08,0.003408,222.9741713453448,266.6005259255778,4.7187203771870845
6.557309100272512e-08,0.0034311999999999997,223.07246940325598,266.6005259255778,4.7187203771870845
6.610819433336055e-08,0.0034592,223.1907604622006,266.6005259255778,4.7187203771870845
6.621521499948764e-08,0.0034647999999999997,223.2143737994193,266.6005259255778,4.7187203771870845
6.639867899856265e-08,0.0034744,223.25481920640829,266.6005259255778,4.7187203771870845
6.645983366492099e-08,0.0034776,223.26829132039055,266.6005259255778,4.7187203771870845
6.670445233035432e-08,0.0034904,223.32213149954583,266.6005259255778,4.7187203771870845
6.693378232919808e-08,0.0035023999999999997,223.37253677581714,266.6005259255778,4.7187203771870845
6.713253499486267e-08,0.0035128,223.41616689234965,266.6005259255778,4.7187203771870845
6.746888565983352e-08,0.0035304,223.4898878850034,266.6005259255778,4.7187203771870845
6.798870032387936e-08,0.0035575999999999997,223.6035390272862,266.6005259255778,4.7187203771870845
6.808043232341688e-08,0.0035624,223.62355988261234,266.6005259255778,4.7187203771870845
6.824860765590229e-08,0.0035711999999999996,223.66023748073454,266.6005259255778,4.7187203771870845
6.83403396554398e-08,0.0035759999999999998,223.6802285861865,266.6005259255778,4.7187203771870845
6.86155356540523e-08,0.0035903999999999997,223.74013920599208,266.6005259255778,4.7187203771870845
6.879899965312731e-08,0.0036,223.78002756618508,266.6005259255778,4.7187203771870845
6.896717498561273e-08,0.0036087999999999997,223.81655546906006,266.6005259255778,4.7187203771870845
6.916592765127733e-08,0.0036192,223.85968005260307,266.6005259255778,4.7187203771870845
7.000680431370444e-08,0.0036631999999999997,224.0415980271557,266.6005259255778,4.7187203771870845
7.026671164572736e-08,0.0036768,224.09765454924846,266.6005259255778,4.7187203771870845
7.095470164225863e-08,0.0037128,224.24565050195977,266.6005259255778,4.7187203771870845
7.106172230838572e-08,0.0037183999999999997,224.2686216990758,266.6005259255778,4.7187203771870845
7.132162964040864e-08,0.0037319999999999996,224.32435279312472,266.6005259255778,4.7187203771870845
7.16426916387899e-08,0.0037487999999999996,224.3930878524967,266.6005259255778,4.7187203771870845
7.18414443044545e-08,0.0037592,224.4355779298105,266.6005259255778,4.7187203771870845
7.204019697011909e-08,0.0037695999999999997,224.47802218698277,266.6005259255778,4.7187203771870845
7.213192896965659e-08,0.0037744,224.49759643865326,266.6005259255778,4.7187203771870845
7.26058776339337e-08,0.0037992,224.59857583013456,266.6005259255778,4.7187203771870845
7.295751696549412e-08,0.0038176,224.67332998334797,266.6005259255778,4.7187203771870845
7.324800163069622e-08,0.0038328,224.73497748725865,266.6005259255778,4.7187203771870845
7.364550696202539e-08,0.0038536,224.81918294271364,266.6005259255778,4.7187203771870845
7.370666162838373e-08,0.0038567999999999996,224.83212187858086,266.6005259255778,4.7187203771870845
7.38289709611004e-08,0.0038632,224.85798719665837,266.6005259255778,4.7187203771870845
7.436407429173584e-08,0.0038912,224.97095204269033,266.6005259255778,4.7187203771870845
7.456282695740042e-08,0.0039016,225.01282961546607,266.6005259255778,4.7187203771870845
7.517437362098378e-08,0.0039336,225.14141146508692,266.6005259255778,4.7187203771870845
7.549543561936504e-08,0.0039504,225.20875359519295,266.6005259255778,4.7187203771870845
7.575534295138796e-08,0.003964,225.26318688408483,266.6005259255778,4.7187203771870845
7.604582761659005e-08,0.0039792,225.32393797166827,266.6005259255778,4.7187203771870845
7.937934413535683e-08,0.004153630726145229,226.01474275388148,266.6005259255778,4.7187203771870845
8.231535532279442e-08,0.004307261452290458,226.61385374750043,266.6005259255778,4.7187203771870845
9.442640147097446e-08,0.004940988197639528,229.00184065467994,266.6005259255778,4.7187203771870845
9.846341685370115e-08,0.005152230446089218,229.7708559286519,266.6005259255778,4.7187203771870845
1.0506944202543571e-07,0.005497899579915984,231.00322873732702,266.6005259255778,4.7187203771870845
1.1020746160345148e-07,0.005766753350670134,231.9409572249795,266.6005259255778,4.7187203771870845
1.1277647139245937e-07,0.005901180236047209,232.4034152015299,266.6005259255778,4.7187203771870845
1.1791449097047515e-07,0.00617003400680136,233.31618507185178,266.6005259255778,4.7187203771870845
1.2598852173592852e-07,0.00659251850370074,234.7197959372443,266.6005259255778,4.7187203771870845
1.3883357068096794e-07,0.007264652930586117,236.882534451298,266.6005259255778,4.7187203771870845
1.43604588860554e-07,0.007514302860572114,237.66576596564616,266.6005259255778,4.7187203771870845
1.483756070401401e-07,0.007763952790558111,238.43891234185978,266.6005259255778,4.7187203771870845
1.527796238212965e-07,0.007994398879775955,239.1440227032895,266.6005259255778,4.7187203771870845
1.5865164619617166e-07,0.008301660332066413,240.0719594822076,266.6005259255778,4.7187203771870845
1.6232166018046863e-07,0.00849369873974795,240.64512225075813,266.6005259255778,4.7187203771870845
1.685606839537735e-07,0.008820164032806561,241.60803268143573,266.6005259255778,4.7187203771870845
1.7443270632864868e-07,0.00912742548509702,242.50167918465624,266.6005259255778,4.7187203771870845
1.7773571891451596e-07,0.009300260052010402,242.99919743685112,266.6005259255778,4.7187203771870845
1.8507574688310995e-07,0.009684336867373475,244.09206160152002,266.6005259255778,4.7187203771870845
2.0893083778104034e-07,0.010932586517303462,247.5324442174617,266.6005259255778,4.7187203771870845
2.1590386435120456e-07,0.011297459491898379,248.50867859699434,266.6005259255778,4.7187203771870845
2.2140888532765008e-07,0.011585517103420685,249.27072999107847,266.6005259255778,4.7187203771870845
2.28748913296244e-07,0.011969593918783756,250.27540103217677,266.6005259255778,4.7187203771870845
2.320519258821113e-07,0.012142428485697139,250.72339284012648,266.6005259255778,4.7187203771870845
2.3902495245227557e-07,0.012507301460292058,251.66106737232911,266.6005259255778,4.7187203771870845
2.522370027957447e-07,0.013198639727945589,253.40895893636673,266.6005259255778,4.7187203771870845
2.727890811078078e-07,0.014274054810962193,256.05851651484596,266.6005259255778,4.7187203771870845
2.8233111746698e-07,0.014773354670934187,257.26208198662266,266.6005259255778,4.7187203771870845
2.9040514823243335e-07,0.015195839167833567,258.26814196222034,266.6005259255778,4.7187203771870845
3.061862083649104e-07,0.016021604320864174,260.20357265384666,266.6005259255778,4.7187203771870845
3.0948922095077773e-07,0.01619443888777756,260.6036943923522,266.6005259255778,4.7187203771870845
3.2013226150523894e-07,0.016751350270054012,261.8817916714778,266.6005259255778,4.7187203771870845
3.2123326570052797e-07,0.01680896179235847,262.01305575177577,266.6005259255778,4.7187203771870845
3.37014325833005e-07,0.017634726945389076,263.8756356583575,266.6005259255778,4.7187203771870845
3.3811533002829414e-07,0.01769233846769354,264.00429937001655,266.6005259255778,4.7187203771870845
3.461893607937475e-07,0.01811482296459292,264.9428907273193,266.6005259255778,4.7187203771870845
3.4839136918432565e-07,0.01823004600920184,265.1973835266189,266.6005259255778,4.7187203771870845
3.5830040694192755e-07,0.01874854970994199,266.3349256394857,266.6005259255778,4.7187203771870845
3.7151245728539673e-07,0.01943988797759552,267.83274206967434,266.6005259255778,4.7187203771870845
3.7701747826184216e-07,0.019727945589117824,268.4506837971358,266.6005259255778,4.7187203771870845
3.7995348944927974e-07,0.019881576315263053,268.778813389573,266.6005259255778,4.7187203771870845
3.8215549783985794e-07,0.019996799359871975,269.0242620320169,266.6005259255778,4.7187203771870845
3.909635314021707e-07,0.020457691538307662,270.00059054397315,266.6005259255778,4.7187203771870845
4.038085803472101e-07,0.021129825965193038,271.4091636495416,266.6005259255778,4.7187203771870845
4.118826111126635e-07,0.021552310462092418,272.2856137458302,266.6005259255778,4.7187203771870845
4.2252565166712475e-07,0.022109221844368875,273.43076393343904,266.6005259255778,4.7187203771870845
4.2986567963571873e-07,0.022493298659731948,274.21397606288826,266.6005259255778,4.7187203771870845
4.364717048074533e-07,0.022838967793558713,274.9144186667243,266.6005259255778,4.7187203771870845
4.416097243854691e-07,0.023107821564312864,275.4563528293484,266.6005259255778,4.7187203771870845
4.5885879011166486e-07,0.024010402080416084,277.25798135430347,266.6005259255778,4.7187203771870845
4.6106079850224306e-07,0.024125625125025005,277.4860600632916,266.6005259255778,4.7187203771870845
4.6326280689282127e-07,0.024240848169633927,277.7137143406955,266.6005259255778,4.7187203771870845
4.790438670252982e-07,0.025066613322664532,279.3330623683989,266.6005259255778,4.7187203771870845
5.006969495326505e-07,0.0261996399279856,281.5214967603941,266.6005259255778,4.7187203771870845
5.025319565247989e-07,0.026295659131826365,281.7052435839063,266.6005259255778,4.7187203771870845
5.175790138604166e-07,0.027083016603320666,283.2022222823756,266.6005259255778,4.7187203771870845
5.208820264462839e-07,0.027255851170234047,283.5285443500969,266.6005259255778,4.7187203771870845
5.245520404305808e-07,0.027447889577915583,283.8901793947826,266.6005259255778,4.7187203771870845
5.326260711960342e-07,0.027870374074814963,284.6823211475998,266.6005259255778,4.7187203771870845
5.333600739928936e-07,0.02790878175635127,284.75410101053023,266.6005259255778,4.7187203771870845
5.381310921724797e-07,0.02815843168633727,285.2197345952801,266.6005259255778,4.7187203771870845
5.407001019614875e-07,0.028292858571714343,285.4697933811248,266.6005259255778,4.7187203771870845
5.447371173442143e-07,0.028504100820164035,285.86180876479466,266.6005259255778,4.7187203771870845
5.491411341253706e-07,0.028734546909381875,286.2881719477412,266.6005259255778,4.7187203771870845
5.583161690861131e-07,0.029214642928585718,287.1721691573816,266.6005259255778,4.7187203771870845
5.634541886641289e-07,0.02948349669933987,287.66473243831604,266.6005259255778,4.7187203771870845
5.64555192859418e-07,0.029541108221644328,287.7700534575799,266.6005259255778,4.7187203771870845
5.689592096405743e-07,0.02977155431086217,288.19053894439634,266.6005259255778,4.7187203771870845
5.729962250233011e-07,0.029982796559311863,288.57487021675405,266.6005259255778,4.7187203771870845
5.829052627809028e-07,0.03050130026005201,289.51377866280615,266.6005259255778,4.7187203771870845
5.917132963432157e-07,0.030962192438487697,290.34315070651616,266.6005259255778,4.7187203771870845
6.049253466866848e-07,0.03165353070614123,291.5782373466484,266.6005259255778,4.7187203771870845
6.163023900380054e-07,0.03224884976995399,292.6333774286763,266.6005259255778,4.7187203771870845
6.254774249987479e-07,0.03272894578915783,293.47877399033115,266.6005259255778,4.7187203771870845
6.262114277956072e-07,0.032767353470694136,293.54619606900883,266.6005259255778,4.7187203771870845
6.3501946135792e-07,0.03322824564912982,294.3528717806265,266.6005259255778,4.7187203771870845
6.471305075061001e-07,0.0338619723944789,295.4549616688016,266.6005259255778,4.7187203771870845
6.53369531279405e-07,0.03418843768753751,296.0195637819042,266.6005259255778,4.7187203771870845
6.566725438652722e-07,0.03436127225445089,296.3176193451901,266.6005259255778,4.7187203771870845
6.58140549458991e-07,0.034438087617523504,296.4499007478013,266.6005259255778,4.7187203771870845
6.599755564511396e-07,0.03453410682136428,296.61509079194917,266.6005259255778,4.7187203771870845
6.669485830213038e-07,0.03489897979595919,297.24118606713984,266.6005259255778,4.7187203771870845
6.724536039977493e-07,0.0351870374074815,297.73367032087685,266.6005259255778,4.7187203771870845
6.753896151851869e-07,0.035340668133626726,297.99568555000343,266.6005259255778,4.7187203771870845
6.856656543412183e-07,0.03587837567513502,298.9092610411198,266.6005259255778,4.7187203771870845
6.893356683255155e-07,0.03607041408281657,299.2342419007922,266.6005259255778,4.7187203771870845
6.941066865051015e-07,0.036320064012802564,299.65571001246724,266.6005259255778,4.7187203771870845
6.963086948956797e-07,0.03643528705741149,299.8498525438039,266.6005259255778,4.7187203771870845
7.036487228642736e-07,0.036819363872774555,300.4952719374873,266.6005259255778,4.7187203771870845
7.150257662155941e-07,0.03741468293658731,301.490506982101,266.6005259255778,4.7187203771870845
7.223657941841882e-07,0.03779875975195039,302.12931807997154,266.6005259255778,4.7187203771870845
7.289718193559228e-07,0.038144428885777154,302.7020868643372,266.6005259255778,4.7187203771870845
7.355778445276573e-07,0.038490098019603916,303.27283489537535,266.6005259255778,4.7187203771870845
7.370458501213762e-07,0.03856691338267654,303.3993959116173,266.6005259255778,4.7187203771870845
7.440188766915405e-07,0.03893178635727146,303.9992233310527,266.6005259255778,4.7187203771870845
7.476888906758374e-07,0.03912382476495299,304.3140411410283,266.6005259255778,4.7187203771870845
7.553959200428611e-07,0.039527105421084216,304.9732036310476,266.6005259255778,4.7187203771870845
7.649379564020332e-07,0.04002640528105621,305.78568687500405,266.6005259255778,4.7187203771870845
7.711769801753381e-07,0.040352870574114824,306.3147896506393,266.6005259255778,4.7187203771870845
7.788840095423617e-07,0.04075615123024605,306.9660879690767,266.6005259255778,4.7187203771870845
7.832880263235183e-07,0.0409865973194639,307.33712992583014,266.6005259255778,4.7187203771870845
7.873250417062447e-07,0.04119783956791358,307.67653761170436,266.6005259255778,4.7187203771870845
7.928300626826904e-07,0.04148589717943589,308.1382744916395,266.6005259255778,4.7187203771870845
8.001700906512842e-07,0.041869973994798956,308.751983331241,266.6005259255778,4.7187203771870845
8.049411088308702e-07,0.04211962392478495,309.149717057572,266.6005259255778,4.7187203771870845
8.155841493853318e-07,0.04267653530706142,310.0336710171518,266.6005259255778,4.7187203771870845
8.181531591743395e-07,0.04281096219243849,310.2463638165899,266.6005259255778,4.7187203771870845
8.434762556659887e-07,0.04413602720544109,312.3291543580569,266.6005259255778,4.7187203771870845
8.493482780408639e-07,0.04444328865773155,312.8086200262693,266.6005259255778,4.7187203771870845
8.629273297827627e-07,0.04515383076615323,313.9124601580479,266.6005259255778,4.7187203771870845
8.867824206806931e-07,0.04640208041608322,315.83537311111183,266.6005259255778,4.7187203771870845
8.897184318681307e-07,0.04655571114222845,316.07063701492064,266.6005259255778,4.7187203771870845
9.010954752194513e-07,0.04715103020604121,316.97943910599787,266.6005259255778,4.7187203771870845
9.047654892037482e-07,0.04734306861372274,317.2716450189452,266.6005259255778,4.7187203771870845
9.102705101801938e-07,0.047631126225245055,317.7090886461645,266.6005259255778,4.7187203771870845
9.13573522766061e-07,0.04780396079215843,317.9710596084062,266.6005259255778,4.7187203771870845
9.172435367503582e-07,0.047995999199839975,318.2617056053603,266.6005259255778,4.7187203771870845
9.220145549299442e-07,0.04824564912982597,318.63886826691726,266.6005259255778,4.7187203771870845
9.337585996796945e-07,0.04886017203440689,319.56404044117147,266.6005259255778,4.7187203771870845
9.366946108671322e-07,0.049013802760552116,319.79462304096876,266.6005259255778,4.7187203771870845
9.392636206561399e-07,0.04914822964592919,319.9961516921957,266.6005259255778,4.7187203771870845
9.484386556168825e-07,0.04962832566513303,320.71414862614773,266.6005259255778,4.7187203771870845
9.506406640074605e-07,0.049743548709741944,320.8860641960393,266.6005259255778,4.7187203771870845
9.524756709996089e-07,0.04983956791358271,321.02920856827126,266.6005259255778,4.7187203771870845
9.700917381242345e-07,0.050761352270454085,322.39796582923117,266.6005259255778,4.7187203771870845
9.737617521085317e-07,0.05095339067813563,322.68189962120033,266.6005259255778,4.7187203771870845
9.79266773084977e-07,0.05124144828965793,323.10701903767153,266.6005259255778,4.7187203771870845
9.818357828739847e-07,0.051375875175035,323.3050890401335,266.6005259255778,4.7187203771870845
1.0053238723734855e-06,0.052604920984196835,325.106738925035,266.6005259255778,4.7187203771870845
1.0130309017405095e-06,0.05300820164032807,325.69431832079664,266.6005259255778,4.7187203771870845
1.0368859926384396e-06,0.05425645129025805,327.5020636587441,266.6005259255778,4.7187203771870845
1.0453270248023227e-06,0.05469813962792558,328.13783271793613,266.6005259255778,4.7187203771870845
1.0537680569662058e-06,0.05513982796559312,328.7716027010107,266.6005259255778,4.7187203771870845
1.057071069552073e-06,0.055312662532506496,329.01906031520855,266.6005259255778,4.7187203771870845
1.0600070807395104e-06,0.055466293258651725,329.2387695918461,266.6005259255778,4.7187203771870845
1.0666131059112453e-06,0.0558119623924785,329.73224956120305,266.6005259255778,4.7187203771870845
1.0713841240908314e-06,0.056061612322464496,330.08791075563687,266.6005259255778,4.7187203771870845
1.0743201352782689e-06,0.056215243048609725,330.30647219022677,266.6005259255778,4.7187203771870845
1.0831281688405817e-06,0.05667613522704541,330.9607630589347,266.6005259255778,4.7187203771870845
1.0908351982076054e-06,0.05707941588317664,331.5315672330507,266.6005259255778,4.7187203771870845
1.0978082247777697e-06,0.05744428885777156,332.0466552702965,266.6005259255778,4.7187203771870845
1.1011112373636367e-06,0.05761712342468493,332.29019884754507,266.6005259255778,4.7187203771870845
1.1073502611369418e-06,0.05794358871774355,332.74944964467073,266.6005259255778,4.7187203771870845
1.1102862723243793e-06,0.05809721944388878,332.9652183875491,266.6005259255778,4.7187203771870845
1.114323287707106e-06,0.05830846169233847,333.2615374231405,266.6005259255778,4.7187203771870845
1.1205623114804107e-06,0.05863492698539707,333.71866285135434,266.6005259255778,4.7187203771870845
1.1249663282615672e-06,0.058865373074614924,334.0407421875218,266.6005259255778,4.7187203771870845
1.1451514051752006e-06,0.05992158431686337,335.5106924563225,266.6005259255778,4.7187203771870845
1.1480874163626383e-06,0.0600752150430086,335.7236585911918,266.6005259255778,4.7187203771870845
1.1579964541202402e-06,0.06059371874374875,336.44085634248364,266.6005259255778,4.7187203771870845
1.1657034834872637e-06,0.06099699939987997,336.99702335606906,266.6005259255778,4.7187203771870845
1.1767135254401547e-06,0.061573114622924585,337.7890664242082,266.6005259255778,4.7187203771870845
1.1796495366275923e-06,0.061726745349069814,337.99978911647514,266.6005259255778,4.7187203771870845
1.1803835394244517e-06,0.06176515303060612,338.0524378178416,266.6005259255778,4.7187203771870845
1.19469659396321e-06,0.06251410282056412,339.0765492797249,266.6005259255778,4.7187203771870845
1.2064406387129604e-06,0.06312862572514504,339.9132767220072,266.6005259255778,4.7187203771870845
1.2229557016422967e-06,0.06399279855971195,341.0845700799757,266.6005259255778,4.7187203771870845
1.2266257156265937e-06,0.06418483696739348,341.34401786909586,266.6005259255778,4.7187203771870845
1.2332317407983282e-06,0.06453050610122024,341.81026227040627,266.6005259255778,4.7187203771870845
1.2427737771575003e-06,0.06502980596119223,342.48201048743846,266.6005259255778,4.7187203771870845
1.2471777939386568e-06,0.06526025205041008,342.79136940291374,266.6005259255778,4.7187203771870845
1.256719830297829e-06,0.06575955191038207,343.4601892852784,266.6005259255778,4.7187203771870845
1.2702988820397277e-06,0.06647009401880376,344.4085668627581,266.6005259255778,4.7187203771870845
1.2802079197973296e-06,0.06698859771954391,345.09813271329733,266.6005259255778,4.7187203771870845
1.2886489519612128e-06,0.06743028605721145,345.6839004054565,266.6005259255778,4.7187203771870845
1.2970899841250959e-06,0.06787197439487898,346.26817358340514,266.6005259255778,4.7187203771870845
1.2989249911172443e-06,0.06796799359871974,346.39499305443115,266.6005259255778,4.7187203771870845
1.3095680316717055e-06,0.0685249049809962,347.12917279312234,266.6005259255778,4.7187203771870845
1.3209450750230262e-06,0.06912022404480897,347.9114170141,266.6005259255778,4.7187203771870845
1.3257160932026123e-06,0.06936987397479497,348.2386724309961,266.6005259255778,4.7187203771870845
1.3341571253664954e-06,0.0698115623124625,348.81653981769074,266.6005259255778,4.7187203771870845
1.3370931365539328e-06,0.06996519303860772,349.0172027100692,266.6005259255778,4.7187203771870845
1.343332160327238e-06,0.07029165833166634,349.44304168398247,266.6005259255778,4.7187203771870845
1.3594802218581445e-06,0.0711366273254651,350.5416467441339,266.6005259255778,4.7187203771870845
1.3686552568188871e-06,0.07161672334466894,351.16358669825587,266.6005259255778,4.7187203771870845
1.3712242666078948e-06,0.07175115023004601,351.33743822996723,266.6005259255778,4.7187203771870845
1.3778302917796295e-06,0.07209681936387279,351.7839027384368,266.6005259255778,4.7187203771870845
1.3800323001702077e-06,0.0722120424084817,351.932538622599,266.6005259255778,4.7187203771870845
1.3877393295372312e-06,0.07261532306461292,352.4520373870779,266.6005259255778,4.7187203771870845
1.38957433652938e-06,0.0727113422684537,352.57556157777566,266.6005259255778,4.7187203771870845
1.3932443505136768e-06,0.07290338067613523,352.82241927407483,266.6005259255778,4.7187203771870845
1.4079244064508648e-06,0.07367153430686138,353.8073245663921,266.6005259255778,4.7187203771870845
1.4134294274273101e-06,0.07395959191838368,354.175630470288,266.6005259255778,4.7187203771870845
1.4200354525990446e-06,0.07430526105221044,354.6168599102335,266.6005259255778,4.7187203771870845
1.4284764847629279e-06,0.07474694938987798,355.17948988028826,266.6005259255778,4.7187203771870845
1.4398535281142484e-06,0.07534226845369074,355.9357699826549,266.6005259255778,4.7187203771870845
1.4471935560828426e-06,0.07572634526905382,356.4224561021183,266.6005259255778,4.7187203771870845
1.4515975728639989e-06,0.07595679135827166,356.7140057057147,266.6005259255778,4.7187203771870845
1.4549005854498661e-06,0.07612962592518505,356.93244157671126,266.6005259255778,4.7187203771870845
1.4563685910435848e-06,0.07620644128825765,357.0294620969138,266.6005259255778,4.7187203771870845
1.4600386050278817e-06,0.07639847969593919,357.27184668287174,266.6005259255778,4.7187203771870845
1.4655436260043273e-06,0.0766865373074615,357.6349785110554,266.6005259255778,4.7187203771870845
1.473250655371351e-06,0.07708981796359272,358.1424706283521,266.6005259255778,4.7187203771870845
1.4824256903320937e-06,0.07756991398279657,358.74527990077496,266.6005259255778,4.7187203771870845
1.4927017294881251e-06,0.07810762152430487,359.4187015062294,266.6005259255778,4.7187203771870845
1.4985737518630003e-06,0.07841488297659532,359.8027020614908,266.6005259255778,4.7187203771870845
1.4993077546598596e-06,0.07845329065813163,359.8506608359168,266.6005259255778,4.7187203771870845
1.5015097630504377e-06,0.07856851370274055,359.994482249058,266.6005259255778,4.7187203771870845
1.5055467784331645e-06,0.07877975595119024,360.2579413788454,266.6005259255778,4.7187203771870845
1.5066477826284536e-06,0.07883736747349471,360.32974603403215,266.6005259255778,4.7187203771870845
1.5128868064017583e-06,0.07916383276655331,360.7362531985945,266.6005259255778,4.7187203771870845
1.5139878105970475e-06,0.07922144428885777,360.807921836487,266.6005259255778,4.7187203771870845
1.5246308511515088e-06,0.07977835567113423,361.4996739263252,266.6005259255778,4.7187203771870845
1.5275668623389462e-06,0.07993198639727946,361.69017033988877,266.6005259255778,4.7187203771870845
1.5286678665342353e-06,0.07998959791958392,361.7615696742812,266.6005259255778,4.7187203771870845
1.5360078945028295e-06,0.080373674734947,362.2370537443632,266.6005259255778,4.7187203771870845
1.5594959840023303e-06,0.08160272054410883,363.75268210957256,266.6005259255778,4.7187203771870845
1.5734420371426585e-06,0.08233246649329866,364.6483745105729,266.6005259255778,4.7187203771870845
1.5807820651112527e-06,0.08271654330866174,365.11854767103995,266.6005259255778,4.7187203771870845
1.5980311308374484e-06,0.08361912382476495,366.22011584340004,266.6005259255778,4.7187203771870845
1.602435147618605e-06,0.0838495699139828,366.5006229506447,266.6005259255778,4.7187203771870845
1.610509178384058e-06,0.08427205441088217,367.0141063402611,266.6005259255778,4.7187203771870845
1.6222532231338085e-06,0.08488657731546309,367.759202694368,266.6005259255778,4.7187203771870845
1.6273912427118243e-06,0.08515543108621725,368.0845205280549,266.6005259255778,4.7187203771870845
1.6292262497039727e-06,0.08525145029005801,368.2006083606028,266.6005259255778,4.7187203771870845
1.6417042972505827e-06,0.08590438087617525,368.9886576669488,266.6005259255778,4.7187203771870845
1.6453743112348795e-06,0.08609641928385678,369.2199918615488,266.6005259255778,4.7187203771870845
1.652347337805044e-06,0.0864612922584517,369.6589731785095,266.6005259255778,4.7187203771870845
1.6651923867500833e-06,0.08713342668533708,370.4657363415491,266.6005259255778,4.7187203771870845
1.6717984119218178e-06,0.08747909581916384,370.8796978150645,266.6005259255778,4.7187203771870845
1.68134044828099e-06,0.08797839567913583,371.47651769979933,266.6005259255778,4.7187203771870845
1.687212470655865e-06,0.08828565713142629,371.8431349576492,266.6005259255778,4.7187203771870845
1.697121508413467e-06,0.08880416083216644,372.46067520272305,266.6005259255778,4.7187203771870845
1.7048285377804907e-06,0.08920744148829766,372.94001260885193,266.6005259255778,4.7187203771870845
1.710333558756936e-06,0.08949549909981996,373.28187920225054,266.6005259255778,4.7187203771870845
1.7290506300768506e-06,0.0904748949789958,374.4410290639978,266.6005259255778,4.7187203771870845
1.7341886496548664e-06,0.09074374874974996,374.75836968440865,266.6005259255778,4.7187203771870845
1.7429966832171793e-06,0.09120464092818564,375.30153040412875,266.6005259255778,4.7187203771870845
1.7448316902093277e-06,0.09130066013202641,375.4145540318089,266.6005259255778,4.7187203771870845
1.7488687055920544e-06,0.0915119023804761,375.6630429637353,266.6005259255778,4.7187203771870845
1.758043740552797e-06,0.09199199839967995,376.22696007909536,266.6005259255778,4.7187203771870845
1.761713754537094e-06,0.09218403680736148,376.45220540724915,266.6005259255778,4.7187203771870845
1.7745588034821334e-06,0.09285617123424686,377.23912697026253,266.6005259255778,4.7187203771870845
1.7815318300522974e-06,0.09322104420884177,377.66538254351775,266.6005259255778,4.7187203771870845
1.7987808957784935e-06,0.094123624724945,378.71701822313145,266.6005259255778,4.7187203771870845
1.8097909377313844e-06,0.09469973994798961,379.38621917561215,266.6005259255778,4.7187203771870845
1.8182319698952675e-06,0.09514142828565714,379.8981985428414,266.6005259255778,4.7187203771870845
1.8196999754889861e-06,0.09521824364872974,379.98714372606605,266.6005259255778,4.7187203771870845
1.8208009796842752e-06,0.09527585517103421,380.05383424993704,266.6005259255778,4.7187203771870845
1.8255719978638613e-06,0.0955255051010202,380.34264497276575,266.6005259255778,4.7187203771870845
1.8384170468089006e-06,0.09619763952790558,381.11875290208144,266.6005259255778,4.7187203771870845
1.841720059394768e-06,0.09637047409481897,381.31798132646827,266.6005259255778,4.7187203771870845
1.8450230719806355e-06,0.09654330866173236,381.51707045091734,266.6005259255778,4.7187203771870845
1.846858078972784e-06,0.09663932786557312,381.627615456332,266.6005259255778,4.7187203771870845
1.8549321097382372e-06,0.0970618123624725,382.1135054824062,266.6005259255778,4.7187203771870845
1.8622721377068312e-06,0.09744588917783557,382.55450839917216,266.6005259255778,4.7187203771870845
1.8666761544879875e-06,0.09767633526705341,382.8187847727554,266.6005259255778,4.7187203771870845
1.8729151782612924e-06,0.09800280056011203,383.1927604291207,266.6005259255778,4.7187203771870845
1.8839252202141834e-06,0.09857891578315664,383.8515344131531,266.6005259255778,4.7187203771870845
1.9011742859403793e-06,0.09948149629925986,384.8806028176025,266.6005259255778,4.7187203771870845
1.9055783027215358e-06,0.0997119423884777,385.1427593616756,266.6005259255778,4.7187203771870845
1.9070463083152544e-06,0.09978875775155031,385.23009235336986,266.6005259255778,4.7187203771870845