File: datasets/aisi_316_L/data/M1/train_90.csv
Time(s),Strain(%),Stress(MPa),Temp(C),Log_SR(s-1)
0.0,0.0,0.0,127.41980508023106,-2.0820322163729985
0.0027057036948389137,2.24e-05,4.2859172999999995,127.41980508023106,-2.0820322163729985
0.003382129618548642,2.8e-05,5.357396625,127.41980508023106,-2.0820322163729985
0.00579793648894053,4.8e-05,9.1841085,127.41980508023106,-2.0820322163729985
0.00705415606154431,5.8399999999999997e-05,11.173998675,127.41980508023106,-2.0820322163729985
0.010436285680092952,8.64e-05,16.5313953,127.41980508023106,-2.0820322163729985
0.014301576672719972,0.00011839999999999999,22.6541343,127.41980508023106,-2.0820322163729985
0.014978002596429701,0.000124,23.725613625,127.41980508023106,-2.0820322163729985
0.015267899420876726,0.00012639999999999998,24.184819049999998,127.41980508023106,-2.0820322163729985
0.016427486718664834,0.000136,26.02164075,127.41980508023106,-2.0820322163729985
0.016814015817927533,0.0001392,26.633914649999998,127.41980508023106,-2.0820322163729985
0.021065835909817254,0.00017439999999999998,33.368927549999995,127.41980508023106,-2.0820322163729985
0.028409888795808594,0.0002352,45.00213165,127.41980508023106,-2.0820322163729985
0.029666108368412377,0.0002456,46.992021825,127.41980508023106,-2.0820322163729985
0.036043838506246956,0.0002984,57.094541174999996,127.41980508023106,-2.0820322163729985
0.03797648400256047,0.0003144,60.155910675,127.41980508023106,-2.0820322163729985
0.0390394390255329,0.0003232,61.8396639,127.41980508023106,-2.0820322163729985
0.04174514272037181,0.0003456,66.1255812,127.41980508023106,-2.0820322163729985
0.04271146546852856,0.0003536,67.65626594999999,127.41980508023106,-2.0820322163729985
0.043387891392238295,0.0003592,68.727745275,127.41980508023106,-2.0820322163729985
0.0441609495907637,0.0003656,69.952293075,127.41980508023106,-2.0820322163729985
0.04483737551447342,0.00037119999999999997,71.0237724,127.41980508023106,-2.0820322163729985
0.04522390461373613,0.0003744,71.6360463,127.41980508023106,-2.0820322163729985
0.04628685963670856,0.0003832,73.319799525,127.41980508023106,-2.0820322163729985
0.04821950513302207,0.0003992,76.381169025,127.41980508023106,-2.0820322163729985
0.050828576553045304,0.0004208,80.51401785,127.41980508023106,-2.0820322163729985
0.05237469295009611,0.00043359999999999997,82.96311345,127.41980508023106,-2.0820322163729985
0.0551770289197507,0.0004568,87.402099225,127.41980508023106,-2.0820322163729985
0.058752423087930696,0.0004864,93.0656328,127.41980508023106,-2.0820322163729985
0.06194128815684799,0.0005128,98.116892475,127.41980508023106,-2.0820322163729985
0.06290761090500474,0.0005208,99.64757722499999,127.41980508023106,-2.0820322163729985
0.06445372730205555,0.0005336,102.096672825,127.41980508023106,-2.0820322163729985
0.06754596009615715,0.0005591999999999999,106.99486402499998,127.41980508023106,-2.0820322163729985
0.06947860559247068,0.0005752,110.056233525,127.41980508023106,-2.0820322163729985
0.07189441246286256,0.0005951999999999999,113.88294539999998,127.41980508023106,-2.0820322163729985
0.0733438965850977,0.0006072,116.178972525,127.41980508023106,-2.0820322163729985
0.07624286482956795,0.0006312,120.771026775,127.41980508023106,-2.0820322163729985
0.07769234895180309,0.0006432,123.0670539,127.41980508023106,-2.0820322163729985
0.0792384653488539,0.000656,125.5161495,127.41980508023106,-2.0820322163729985
0.08117111084516741,0.000672,128.577519,127.41980508023106,-2.0820322163729985
0.08262059496740254,0.0006839999999999999,130.873546125,127.41980508023106,-2.0820322163729985
0.08349028544074362,0.0006912,132.2511624,127.41980508023106,-2.0820322163729985
0.08464987273853174,0.0007008,134.0879841,127.41980508023106,-2.0820322163729985
0.08619598913558253,0.0007136,136.5370797,127.41980508023106,-2.0820322163729985
0.08696904733410793,0.0007199999999999999,137.76162749999997,127.41980508023106,-2.0820322163729985
0.09170402880007603,0.0007591999999999999,145.26198277499998,127.41980508023106,-2.0820322163729985
0.09392657112083656,0.0007775999999999999,148.78255769999998,127.41980508023106,-2.0820322163729985
0.0953760552430717,0.0007896,151.078584825,127.41980508023106,-2.0820322163729985
0.09576258434233441,0.0007928,151.690858725,127.41980508023106,-2.0820322163729985
0.09672890709049116,0.0008008,153.221543475,127.41980508023106,-2.0820322163729985
0.10117399173201223,0.0008376,160.262693325,127.41980508023106,-2.0820322163729985
0.10281674040387871,0.0008512,162.8648574,127.41980508023106,-2.0820322163729985
0.10378306315203548,0.0008592,164.39554214999998,127.41980508023106,-2.0820322163729985
0.10503928272463926,0.0008696,166.385432325,127.41980508023106,-2.0820322163729985
0.10610223774761168,0.0008784,168.06918555,127.41980508023106,-2.0820322163729985
0.10629550229724304,0.0008799999999999999,168.37532249999998,127.41980508023106,-2.0820322163729985
0.10706856049576843,0.0008864,169.5998703,127.41980508023106,-2.0820322163729985
0.1088079414424506,0.0009008,172.35510285,127.41980508023106,-2.0820322163729985
0.10977426419060735,0.0009088,173.8857876,127.41980508023106,-2.0820322163729985
0.11122374831284249,0.0009207999999999999,176.18181472499998,127.41980508023106,-2.0820322163729985
0.11219007106099924,0.0009287999999999999,177.712499475,127.41980508023106,-2.0820322163729985
0.11412271655731275,0.0009448,180.773868975,127.41980508023106,-2.0820322163729985
0.11499240703065383,0.0009519999999999999,182.15148524999998,127.41980508023106,-2.0820322163729985
0.116731787977336,0.0009664,184.9067178,127.41980508023106,-2.0820322163729985
0.11847116892401814,0.0009808,187.66195034999998,127.41980508023106,-2.0820322163729985
0.11924422712254354,0.0009872,188.88649815,127.41980508023106,-2.0820322163729985
0.12088697579441005,0.0010008,191.488662225,127.41980508023106,-2.0820322163729985
0.12426910541295866,0.0010287999999999999,196.84605884999996,127.41980508023106,-2.0820322163729985
0.12658828000853486,0.0010479999999999999,200.51970224999997,127.41980508023106,-2.0820322163729985
0.12794113185595435,0.0010592,202.6626609,127.41980508023106,-2.0820322163729985
0.12871419005447973,0.0010655999999999999,203.88720869999997,127.41980508023106,-2.0820322163729985
0.13209631967302837,0.0010936,209.24460532499998,127.41980508023106,-2.0820322163729985
0.1331592746960008,0.0011024,210.92835854999998,127.41980508023106,-2.0820322163729985
0.13422222971897324,0.0011112,212.612111775,127.41980508023106,-2.0820322163729985
0.13712119796344352,0.0011352,217.204166025,127.41980508023106,-2.0820322163729985
0.14011679848272945,0.00116,221.94928875,127.41980508023106,-2.0820322163729985
0.1414696503301489,0.0011711999999999998,224.09224739999996,127.41980508023106,-2.0820322163729985
0.1434989281012781,0.001188,226.0822257942568,127.41980508023106,-2.0820322163729985
0.14765411591835215,0.0012224,226.315967380365,127.41980508023106,-2.0820322163729985
0.14881370321614026,0.001232,226.38073791140766,127.41980508023106,-2.0820322163729985
0.15045645188800671,0.0012456,226.47216023046488,127.41980508023106,-2.0820322163729985
0.15383858150655538,0.0012736,226.65916589173494,127.41980508023106,-2.0820322163729985
0.15499816880434347,0.0012832,226.722912100202,127.41980508023106,-2.0820322163729985
0.15673754975102563,0.0012975999999999999,226.81818378054743,127.41980508023106,-2.0820322163729985
0.15876682752215482,0.0013143999999999999,226.9288144844369,127.41980508023106,-2.0820322163729985
0.16185906031625644,0.00134,227.09634002936764,127.41980508023106,-2.0820322163729985
0.16437149946146398,0.0013608,227.23153730011722,127.41980508023106,-2.0820322163729985
0.1691064809274321,0.0014,227.48416132906817,127.41980508023106,-2.0820322163729985
0.1710391264237456,0.001416,227.58647857073672,127.41980508023106,-2.0820322163729985
0.17239197827116506,0.0014272,227.6578325256135,127.41980508023106,-2.0820322163729985
0.1742279914926629,0.0014424,227.75432171657678,127.41980508023106,-2.0820322163729985
0.17712695973713316,0.0014663999999999999,227.90586957895258,127.41980508023106,-2.0820322163729985
0.17925286978307803,0.0014839999999999999,228.01639058289922,127.41980508023106,-2.0820322163729985
0.18070235390531317,0.001496,228.09145287938455,127.41980508023106,-2.0820322163729985
0.1833114253253364,0.0015176,228.22597592403548,127.41980508023106,-2.0820322163729985
0.1847609094475715,0.0015295999999999999,228.3003882343041,127.41980508023106,-2.0820322163729985
0.18901272953946124,0.0015647999999999999,228.51736200308596,127.41980508023106,-2.0820322163729985
0.19249149143282557,0.0015936,228.69347356844068,127.41980508023106,-2.0820322163729985
0.1954870919521115,0.0016183999999999999,228.84413284188372,127.41980508023106,-2.0820322163729985
0.19838606019658178,0.0016424,228.98907717886067,127.41980508023106,-2.0820322163729985
0.19886922157066014,0.0016464,229.01315403325876,127.41980508023106,-2.0820322163729985
0.20118839616623635,0.0016656,229.12840687100112,127.41980508023106,-2.0820322163729985
0.20331430621218122,0.0016832,229.23360094313895,127.41980508023106,-2.0820322163729985
0.20746949402925527,0.0017176,229.43797705825602,127.41980508023106,-2.0820322163729985
0.20833918450259634,0.0017247999999999999,229.48055072498263,127.41980508023106,-2.0820322163729985
0.20959540407520014,0.0017352,229.54192386212546,127.41980508023106,-2.0820322163729985
0.2113347850218823,0.0017496,229.62666574422923,127.41980508023106,-2.0820322163729985
0.215586605113772,0.0017848,229.8326754780889,127.41980508023106,-2.0820322163729985
0.21626303103748173,0.0017904,229.86530309075135,127.41980508023106,-2.0820322163729985
0.21751925061008553,0.0018008,229.92579183035602,127.41980508023106,-2.0820322163729985
0.2190653670071363,0.0018135999999999998,230.00005280526096,127.41980508023106,-2.0820322163729985
0.21983842520566174,0.00182,230.03710662019196,127.41980508023106,-2.0820322163729985
0.22322055482421035,0.0018479999999999998,230.1986232292469,127.41980508023106,-2.0820322163729985
0.2245734066716298,0.0018591999999999999,230.26296229380924,127.41980508023106,-2.0820322163729985
0.22747237491610012,0.0018832,230.40032491946093,127.41980508023106,-2.0820322163729985
0.22959828496204496,0.0019008,230.50062398452897,127.41980508023106,-2.0820322163729985
0.23230398865688387,0.0019232,230.62775505330364,127.41980508023106,-2.0820322163729985
0.2341400018783817,0.0019383999999999998,230.71369384879185,127.41980508023106,-2.0820322163729985
0.23636254419914224,0.0019568,230.81737418563824,127.41980508023106,-2.0820322163729985
0.23848845424508708,0.0019744,230.91619147984466,127.41980508023106,-2.0820322163729985
0.24032446746658492,0.0019896,231.00125754628277,127.41980508023106,-2.0820322163729985
0.24264364206216113,0.0020088,231.10834801225846,127.41980508023106,-2.0820322163729985
0.24689546215405087,0.002044,231.30364943820592,127.41980508023106,-2.0820322163729985
0.2500843272229682,0.0020704,231.44926584521312,127.41980508023106,-2.0820322163729985
0.2539496182155952,0.0021024,231.6248033180638,127.41980508023106,-2.0820322163729985
0.2546260441393049,0.002108,231.65541493676483,127.41980508023106,-2.0820322163729985
0.2561721605363557,0.0021208,231.72526550608708,127.41980508023106,-2.0820322163729985
0.2582014383074849,0.0021376,231.81669537216456,127.41980508023106,-2.0820322163729985
0.2597475547045357,0.0021504,231.8861682459851,127.41980508023106,-2.0820322163729985
0.262936419773453,0.0021768,232.02894877201257,127.41980508023106,-2.0820322163729985
0.26612528484237025,0.0022031999999999998,232.1710555383868,127.41980508023106,-2.0820322163729985
0.26660844621644864,0.0022072,232.19252879526817,127.41980508023106,-2.0820322163729985
0.26989394356018165,0.0022344,232.3381465398631,127.41980508023106,-2.0820322163729985
0.2726962795298362,0.0022576,232.46180443161765,127.41980508023106,-2.0820322163729985
0.27520871867504376,0.0022784,232.57224941141,127.41980508023106,-2.0820322163729985
0.27569188004912215,0.0022824,232.59344367486455,127.41980508023106,-2.0820322163729985
0.27685146734691024,0.0022919999999999998,232.64425089106544,127.41980508023106,-2.0820322163729985
0.2783009514691454,0.002304,232.707643352289,127.41980508023106,-2.0820322163729985
0.27936390649211784,0.0023128,232.75404934940738,127.41980508023106,-2.0820322163729985
0.2848719461566114,0.0023584,232.99342269497876,127.41980508023106,-2.0820322163729985
0.285258475255874,0.0023615999999999997,233.0101527328789,127.41980508023106,-2.0820322163729985
0.2866113271032935,0.0023728,233.06863836935682,127.41980508023106,-2.0820322163729985
0.28786754667589726,0.0023832,233.12285013034645,127.41980508023106,-2.0820322163729985
0.2889305016988697,0.002392,233.16864959510957,127.41980508023106,-2.0820322163729985
0.2901867212714735,0.0024024,233.2226916020158,127.41980508023106,-2.0820322163729985
0.29086314719518325,0.002408,233.25175334941875,127.41980508023106,-2.0820322163729985
0.2920227344929713,0.0024176,233.3015122391641,127.41980508023106,-2.0820322163729985
0.2926025281418654,0.0024224,233.3263627827403,127.41980508023106,-2.0820322163729985
0.2948250704626259,0.0024408,233.42144582344608,127.41980508023106,-2.0820322163729985
0.2964678191344924,0.0024544,233.49154502115934,127.41980508023106,-2.0820322163729985
0.2977240387070962,0.0024648,233.5450481247779,127.41980508023106,-2.0820322163729985
0.2991735228293313,0.0024768,233.60667319482175,127.41980508023106,-2.0820322163729985
0.3046815624938248,0.0025223999999999997,233.83979409736102,127.41980508023106,-2.0820322163729985
0.30613104661605994,0.0025344,233.90086779600043,127.41980508023106,-2.0820322163729985
0.30729063391384803,0.002544,233.94964559370266,127.41980508023106,-2.0820322163729985
0.3077737952879264,0.002548,233.96994848313133,127.41980508023106,-2.0820322163729985
0.31057613125758105,0.0025712,234.08746104134497,127.41980508023106,-2.0820322163729985
0.3126054090287102,0.002588,234.17229835021686,127.41980508023106,-2.0820322163729985
0.31492458362428644,0.0026072,234.26899271990646,127.41980508023106,-2.0820322163729985
0.3174370227694939,0.0026279999999999997,234.3734320996704,127.41980508023106,-2.0820322163729985
0.3182100809680194,0.0026344,234.40550237113067,127.41980508023106,-2.0820322163729985
0.3188865068917291,0.00264,234.433538941378,127.41980508023106,-2.0820322163729985
0.32052925556359557,0.0026536,234.50153136746854,127.41980508023106,-2.0820322163729985
0.32265516560954044,0.0026712,234.5893201684164,127.41980508023106,-2.0820322163729985
0.3243945465562226,0.0026856,234.6609797000176,127.41980508023106,-2.0820322163729985
0.32922616029700635,0.0027256,234.85925195452845,127.41980508023106,-2.0820322163729985
0.3299992184955318,0.002732,234.89086990188756,127.41980508023106,-2.0820322163729985
0.33086890896887283,0.0027392,234.92640558446823,127.41980508023106,-2.0820322163729985
0.33173859944221396,0.0027464,234.9619048574381,127.41980508023106,-2.0820322163729985
0.332608289915555,0.0027535999999999997,234.99736785340775,127.41980508023106,-2.0820322163729985
0.3340577740377902,0.0027656,235.0563925886902,127.41980508023106,-2.0820322163729985
0.33531399361039393,0.002776,235.10746661164256,127.41980508023106,-2.0820322163729985
0.3371500068318918,0.0027911999999999998,235.18197923043377,127.41980508023106,-2.0820322163729985
0.33859949095412695,0.0028032,235.24069325680557,127.41980508023106,-2.0820322163729985
0.33995234280154635,0.0028144,235.29540463688053,127.41980508023106,-2.0820322163729985
0.34053213645044045,0.0028192,235.31882637014562,127.41980508023106,-2.0820322163729985
0.3473930279623534,0.002876,235.5948130008355,127.41980508023106,-2.0820322163729985
0.34797282161124743,0.0028807999999999998,235.6180379583029,127.41980508023106,-2.0820322163729985
0.3491324089090355,0.0028904,235.66444264670244,127.41980508023106,-2.0820322163729985
0.3500020993823766,0.0028975999999999997,235.699206726755,127.41980508023106,-2.0820322163729985
0.3515482157794274,0.0029104,235.76092646721858,127.41980508023106,-2.0820322163729985
0.3538673903750036,0.0029295999999999997,235.8533079546173,127.41980508023106,-2.0820322163729985
0.35502697767279173,0.0029392,235.8994101296439,127.41980508023106,-2.0820322163729985
0.35976195913875986,0.0029784,236.08705440114588,127.41980508023106,-2.0820322163729985
0.3657531601773317,0.003028,236.32310717183933,127.41980508023106,-2.0820322163729985
0.368652128421802,0.003052,236.43678447581902,127.41980508023106,-2.0820322163729985
0.36990834799440575,0.0030624,236.48593631358753,127.41980508023106,-2.0820322163729985
0.3704881416432998,0.0030672,236.50859981654102,127.41980508023106,-2.0820322163729985
0.37290394851369174,0.0030872,236.60288257653505,127.41980508023106,-2.0820322163729985
0.37425680036111114,0.0030984,236.6555768650055,127.41980508023106,-2.0820322163729985
0.3752231231092679,0.0031064,236.6931701712904,127.41980508023106,-2.0820322163729985
0.37667260723150303,0.0031184,236.74948941223798,127.41980508023106,-2.0820322163729985
0.3783153559033695,0.003132,236.813215807899,127.41980508023106,-2.0820322163729985
0.3815042209722868,0.0031584,236.9366127516809,127.41980508023106,-2.0820322163729985
0.38256717599525925,0.0031672,236.97765558963732,127.41980508023106,-2.0820322163729985
0.3837267632930474,0.0031768,237.02237890523543,127.41980508023106,-2.0820322163729985
0.3854661442397295,0.0031912,237.08936517734836,127.41980508023106,-2.0820322163729985
0.3865290992627019,0.0031999999999999997,237.1302432033232,127.41980508023106,-2.0820322163729985
0.39010449343088194,0.0032296,237.26742140588996,127.41980508023106,-2.0820322163729985
0.39213377120201115,0.0032464,237.3450611662224,127.41980508023106,-2.0820322163729985
0.39677212039316356,0.0032848,237.52193745827358,127.41980508023106,-2.0820322163729985
0.39889803043910843,0.0033024,237.60273607477268,127.41980508023106,-2.0820322163729985
0.3999609854620808,0.0033112,237.64307239339897,127.41980508023106,-2.0820322163729985
0.4009273082102376,0.0033192,237.67970550909558,127.41980508023106,-2.0820322163729985
0.4023767923324727,0.0033312,237.7345906839846,127.41980508023106,-2.0820322163729985
0.4045993346532333,0.0033496,237.81859842856068,127.41980508023106,-2.0820322163729985
0.40672524469917815,0.0033672,237.8987854168987,127.41980508023106,-2.0820322163729985
0.41059053569180515,0.0033992,238.04416240715636,127.41980508023106,-2.0820322163729985
0.41242654891330294,0.0034143999999999997,238.1130294133769,127.41980508023106,-2.0820322163729985
0.41300634256219704,0.0034192,238.1347520350544,127.41980508023106,-2.0820322163729985
0.4155187817074046,0.00344,238.22874629912278,127.41980508023106,-2.0820322163729985
0.4185143822266905,0.0034647999999999997,238.34052718948016,127.41980508023106,-2.0820322163729985
0.4202537631733727,0.0034792,238.4052890297294,127.41980508023106,-2.0820322163729985
0.4238291573415527,0.0035088,238.53808322560656,127.41980508023106,-2.0820322163729985
0.42585843511268184,0.0035256,238.61325854120207,127.41980508023106,-2.0820322163729985
0.42643822876157594,0.0035304,238.63471152576878,127.41980508023106,-2.0820322163729985
0.42711465468528564,0.0035359999999999996,238.6597256357367,127.41980508023106,-2.0820322163729985
0.43030351975420295,0.0035624,238.77744182506933,127.41980508023106,-2.0820322163729985
0.4312698425023597,0.0035704,238.81304616395337,127.41980508023106,-2.0820322163729985
0.4323327975253321,0.0035792,238.8521750206979,127.41980508023106,-2.0820322163729985
0.4331058557238575,0.0035856,238.88060880896919,127.41980508023106,-2.0820322163729985
0.4340721784720143,0.0035935999999999997,238.91612322544088,127.41980508023106,-2.0820322163729985
0.4358115594186964,0.0036079999999999997,238.9799715710488,127.41980508023106,-2.0820322163729985
0.4371644112661159,0.0036192,239.0295627115416,127.41980508023106,-2.0820322163729985
0.4396768504113235,0.00364,239.1215020443673,127.41980508023106,-2.0820322163729985
0.4402566440602175,0.0036447999999999997,239.1426896892589,127.41980508023106,-2.0820322163729985
0.44537815462544833,0.0036872,239.32937696522603,127.41980508023106,-2.0820322163729985
0.4464411096484207,0.0036959999999999996,239.36801825633745,127.41980508023106,-2.0820322163729985
0.4470209032973148,0.0037007999999999997,239.38908020016405,127.41980508023106,-2.0820322163729985
0.4474074323965775,0.003704,239.40311557752432,127.41980508023106,-2.0820322163729985
0.45001650381660074,0.0037256,239.49773098673802,127.41980508023106,-2.0820322163729985
0.4536885302595964,0.003756,239.63053178640692,127.41980508023106,-2.0820322163729985
0.45504138210701583,0.0037671999999999996,239.67935264362197,127.41980508023106,-2.0820322163729985
0.45658749850406666,0.00378,239.735078648094,127.41980508023106,-2.0820322163729985
0.4591965699240899,0.0038016,239.8289496901998,127.41980508023106,-2.0820322163729985
0.46209553816856014,0.0038255999999999997,239.93300722565553,127.41980508023106,-2.0820322163729985
0.4643180804893207,0.0038439999999999998,240.01261234507146,127.41980508023106,-2.0820322163729985
0.4661540937108185,0.0038591999999999997,240.07826106932583,127.41980508023106,-2.0820322163729985
0.4671204164589753,0.0038672,240.11277252147656,127.41980508023106,-2.0820322163729985
0.46799010693231635,0.0038743999999999996,240.1438090296659,127.41980508023106,-2.0820322163729985
0.47069581062715526,0.0038967999999999997,240.2402235175248,127.41980508023106,-2.0820322163729985
0.4732082497723629,0.0039176,240.32955789638143,127.41980508023106,-2.0820322163729985
0.47610721801683314,0.0039416,240.43240649124058,127.41980508023106,-2.0820322163729985
0.47861965716204063,0.0039624,240.52134454291104,127.41980508023106,-2.0820322163729985
0.478812921711672,0.003964,240.52817838057547,127.41980508023106,-2.0820322163729985
0.4808421994828012,0.0039808,240.59986884721235,127.41980508023106,-2.0820322163729985
0.48238831587985204,0.0039936,240.65441098451373,127.41980508023106,-2.0820322163729985
0.4993988437413435,0.0041344268853770755,241.25005593066973,127.41980508023106,-2.0820322163729985
0.6292986010450722,0.005209841968393679,245.56296175829436,127.41980508023106,-2.0820322163729985
0.6803306485572512,0.005632326465293058,247.16016211815648,127.41980508023106,-2.0820322163729985
0.6896092026503746,0.005709141828365673,247.44546960954779,127.41980508023106,-2.0820322163729985
0.7220841419763069,0.005977995599119824,248.43246478509295,127.41980508023106,-2.0820322163729985
0.770796550965205,0.00638127625525105,249.88109075680572,127.41980508023106,-2.0820322163729985
0.8195089599541033,0.006784556911382277,251.29442106184987,127.41980508023106,-2.0820322163729985
0.8496642607567546,0.007034206841368274,252.1529314998117,127.41980508023106,-2.0820322163729985
0.8844588386059675,0.007322264452890578,253.12888888977426,127.41980508023106,-2.0820322163729985
0.909974862362057,0.007533506701340268,253.83509894278188,127.41980508023106,-2.0820322163729985
0.9331712475948658,0.007725545109021804,254.47043408178814,127.41980508023106,-2.0820322163729985
0.965646186920798,0.007994398879775955,255.349650988575,127.41980508023106,-2.0820322163729985
0.9749247410139215,0.00807121424284857,255.59872782661927,127.41980508023106,-2.0820322163729985
1.0120389573864152,0.008378475695139028,256.585926514687,127.41980508023106,-2.0820322163729985
1.0398746196657858,0.008608921784356871,257.31708479166275,127.41980508023106,-2.0820322163729985
1.0909066671779648,0.009031406281256251,258.6380153898913,127.41980508023106,-2.0820322163729985
1.1976100392488849,0.009914782956591319,261.32448588623305,127.41980508023106,-2.0820322163729985
1.2231260630049743,0.010126025205041009,261.9528661107543,127.41980508023106,-2.0820322163729985
1.244002809714502,0.01029885977195439,262.4632012488017,127.41980508023106,-2.0820322163729985
1.3066330498430856,0.01081736347269454,263.9745319209073,127.41980508023106,-2.0820322163729985
1.3391079891690179,0.01108621724344869,264.7470443153472,127.41980508023106,-2.0820322163729985
1.3785418440647923,0.0114126825365073,265.67534076220613,127.41980508023106,-2.0820322163729985
1.4110167833907246,0.011681536307261452,266.4320681980949,127.41980508023106,-2.0820322163729985
1.545555817741015,0.012795359071814363,269.49732412398697,127.41980508023106,-2.0820322163729985
1.6244235275325645,0.013448289657931586,271.24578601398804,127.41980508023106,-2.0820322163729985
1.6731359365214626,0.013851570314062813,272.3091885670464,127.41980508023106,-2.0820322163729985
1.6777752135680244,0.01388997799559912,272.4098310872706,127.41980508023106,-2.0820322163729985
1.7404054536966078,0.014408481696339268,273.758054461461,127.41980508023106,-2.0820322163729985
1.8007160553019106,0.014907781556311263,275.03856977445355,127.41980508023106,-2.0820322163729985
1.900460511802988,0.01573354670934187,277.12022789893564,127.41980508023106,-2.0820322163729985
1.9329354511289198,0.01600240048009602,277.7887229319507,127.41980508023106,-2.0820322163729985
1.9561318363617288,0.01619443888777756,278.2635403435699,127.41980508023106,-2.0820322163729985
2.0373191846765586,0.01686657331466293,279.90837925687543,127.41980508023106,-2.0820322163729985
2.14866183379404,0.017788357671534305,282.12317176155614,127.41980508023106,-2.0820322163729985
2.2924794222374545,0.018978995799159834,284.9187711236048,127.41980508023106,-2.0820322163729985
2.3133561689469824,0.019151830366073215,285.31882455139686,127.41980508023106,-2.0820322163729985
2.336552554179791,0.01934386877375475,285.76168063824167,127.41980508023106,-2.0820322163729985
2.3504703853194764,0.019459091818363673,286.0265713340524,127.41980508023106,-2.0820322163729985
2.3736667705522847,0.01965113022604521,286.46670049149117,127.41980508023106,-2.0820322163729985
2.382945324645408,0.019727945589117824,286.6422820874461,127.41980508023106,-2.0820322163729985
2.4525344803438345,0.020304060812162433,287.9507495177263,127.41980508023106,-2.0820322163729985
2.4942879737628902,0.0206497299459892,288.7288810292687,127.41980508023106,-2.0820322163729985
2.563877129461316,0.021225845169033808,290.0145713677978,127.41980508023106,-2.0820322163729985
2.6172288154967758,0.02166753350670134,290.9910712629366,127.41980508023106,-2.0820322163729985
2.691457248241764,0.022282056411282256,292.3368624251172,127.41980508023106,-2.0820322163729985
2.744808934277224,0.02272374474894979,293.2952238085058,127.41980508023106,-2.0820322163729985
2.8816676071507947,0.023856771354270855,295.7209845387116,127.41980508023106,-2.0820322163729985
2.9234211005698505,0.02420244048809762,296.4520462656935,127.41980508023106,-2.0820322163729985
2.9674942325121867,0.024567313462692537,297.2193184980908,127.41980508023106,-2.0820322163729985
2.9906906177449954,0.024759351870374074,297.6213602103179,127.41980508023106,-2.0820322163729985
3.0811565201529496,0.025508301660332067,299.17783884380333,127.41980508023106,-2.0820322163729985
3.1693027840376224,0.026238047609521906,300.677353503674,127.41980508023106,-2.0820322163729985
3.2551294093990144,0.02694858971794359,302.1218554913017,127.41980508023106,-2.0820322163729985
3.301522179864632,0.02733266653330666,302.8964794176974,127.41980508023106,-2.0820322163729985
3.396627359319148,0.028120024004800962,304.4713118468544,127.41980508023106,-2.0820322163729985
3.4383808527382036,0.028465693138627728,305.15725908545664,127.41980508023106,-2.0820322163729985
3.4615772379710115,0.02865773154630926,305.53693696502927,127.41980508023106,-2.0820322163729985
3.48245398468054,0.028830566113222645,305.87779951090585,127.41980508023106,-2.0820322163729985
3.5358056707159995,0.029272254450890177,306.7452917412948,127.41980508023106,-2.0820322163729985
3.5706002485652126,0.029560312062412483,307.30829857214945,127.41980508023106,-2.0820322163729985
3.6680250665430094,0.030366873374674936,308.87344685604774,127.41980508023106,-2.0820322163729985
3.7167374755319074,0.03077015403080616,309.64993480878536,127.41980508023106,-2.0820322163729985
3.7306553066715926,0.030885377075415082,309.8710582043722,127.41980508023106,-2.0820322163729985
3.744573137811278,0.031000600120024004,310.0918601073144,127.41980508023106,-2.0820322163729985
3.800244462370019,0.031461492298459695,310.97188576852943,127.41980508023106,-2.0820322163729985
3.8512765098821977,0.03188397679535907,311.7741690892626,127.41980508023106,-2.0820322163729985
3.8698336180684447,0.0320376075215043,312.06487916277223,127.41980508023106,-2.0820322163729985
3.874472895115007,0.03207601520304061,312.1374716689512,127.41980508023106,-2.0820322163729985
3.9185460270573436,0.03244088817763553,312.8254180487365,127.41980508023106,-2.0820322163729985
3.957979881953117,0.032767353470694136,313.4383952729844,127.41980508023106,-2.0820322163729985
4.036847591744667,0.03342028405681136,314.65725059155204,127.41980508023106,-2.0820322163729985
4.07164216959388,0.03370834166833367,315.19202468583177,127.41980508023106,-2.0820322163729985
4.104117108919812,0.033977195439087816,315.68954138903666,127.41980508023106,-2.0820322163729985
4.136592048245744,0.034246049209841964,316.18552511275186,127.41980508023106,-2.0820322163729985
4.201541926897609,0.03478375675135027,317.17296012422554,127.41980508023106,-2.0820322163729985
4.224738312130417,0.034975795159031806,317.5241704415519,127.41980508023106,-2.0820322163729985
4.312884576015091,0.03570554110822165,318.8519663636399,127.41980508023106,-2.0820322163729985
4.389432647283359,0.03633926785357071,319.9964888497116,127.41980508023106,-2.0820322163729985
4.421907586609291,0.03660812162432486,320.47968912001795,127.41980508023106,-2.0820322163729985
4.505414573447403,0.0372994598919784,321.715891660904,127.41980508023106,-2.0820322163729985
4.54948770538974,0.03766433286657332,322.364727498769,127.41980508023106,-2.0820322163729985
4.565725175052705,0.03779875975195039,322.6031537524843,127.41980508023106,-2.0820322163729985
4.5982001143786375,0.038067613522704546,323.0790164876412,127.41980508023106,-2.0820322163729985
4.6469125233675355,0.03847089417883577,323.7903603555508,127.41980508023106,-2.0820322163729985
4.6909856553098725,0.03883576715343069,324.43145519556,127.41980508023106,-2.0820322163729985
4.704903486449557,0.0389509901980396,324.6334175989719,127.41980508023106,-2.0820322163729985
4.7953693888575115,0.039699939987997604,325.94053941367315,127.41980508023106,-2.0820322163729985
4.8510407134162525,0.04016083216643329,326.74014328093756,127.41980508023106,-2.0820322163729985
4.915990592068116,0.040698539707941586,327.66850522445395,127.41980508023106,-2.0820322163729985
4.95078516991733,0.0409865973194639,328.1638736994933,127.41980508023106,-2.0820322163729985
4.978620832196699,0.041217043408681736,328.55919157082565,127.41980508023106,-2.0820322163729985
5.020374325615754,0.0415627125425085,329.15055597315614,127.41980508023106,-2.0820322163729985
5.0412510723252835,0.041735547109421886,329.4455186532687,127.41980508023106,-2.0820322163729985
5.080684927221059,0.0420620124024805,330.00137387093,127.41980508023106,-2.0820322163729985
5.11084022802371,0.0423116623324665,330.42530507433116,127.41980508023106,-2.0820322163729985
5.14331516734964,0.04258051610322064,330.8807568912516,127.41980508023106,-2.0820322163729985
5.171150829629012,0.04281096219243849,331.27025223345044,127.41980508023106,-2.0820322163729985
5.198986491908381,0.043041408281656326,331.6589307526633,127.41980508023106,-2.0820322163729985
5.2987309484094585,0.043867173434686935,333.0450799055975,127.41980508023106,-2.0820322163729985
5.396155766387255,0.044673734746949384,334.3892022526125,127.41980508023106,-2.0820322163729985
5.46110564503912,0.04521144228845769,335.28002949412246,127.41980508023106,-2.0820322163729985
5.475023476178806,0.04532666533306662,335.47038238075896,127.41980508023106,-2.0820322163729985
5.558530463016917,0.04601800360072014,336.6085617316915,127.41980508023106,-2.0820322163729985
5.579407209726445,0.04619083816763353,336.8920621802754,127.41980508023106,-2.0820322163729985
5.611882149052377,0.046459691938387684,337.3322419571916,127.41980508023106,-2.0820322163729985
5.690749858843926,0.047112622524504905,338.39713442907606,127.41980508023106,-2.0820322163729985
5.718585521123296,0.04734306861372274,338.7716026031552,127.41980508023106,-2.0820322163729985
5.7301837137397005,0.04743908781756351,338.92742112514395,127.41980508023106,-2.0820322163729985
5.7788961227286,0.047842368473694746,339.5805202942071,127.41980508023106,-2.0820322163729985
5.948229734928102,0.04924424884976995,341.8342991072258,127.41980508023106,-2.0820322163729985
5.99462250539372,0.04962832566513303,342.44738795078536,127.41980508023106,-2.0820322163729985
6.003901059486843,0.04970514102820564,342.56978336261676,127.41980508023106,-2.0820322163729985
6.017818890626529,0.049820364072814566,342.7532382536991,127.41980508023106,-2.0820322163729985
6.152357924976819,0.05093418683736747,344.5181864849392,127.41980508023106,-2.0820322163729985
6.189472141349312,0.05124144828965793,345.0024115618148,127.41980508023106,-2.0820322163729985
6.224266719198525,0.05152950590118023,345.4553451417158,127.41980508023106,-2.0820322163729985
6.242823827384772,0.05168313662732546,345.69650590412454,127.41980508023106,-2.0820322163729985
6.298495151943513,0.05214402880576115,346.4183162956303,127.41980508023106,-2.0820322163729985
6.31705226012976,0.052297659531906376,346.65836626862523,127.41980508023106,-2.0820322163729985
6.349527199455692,0.05256651330266053,347.07779300870567,127.41980508023106,-2.0820322163729985
6.382002138781625,0.052835367073414685,347.49638395935074,127.41980508023106,-2.0820322163729985
6.412157439584276,0.05308501700340068,347.8843323469751,127.41980508023106,-2.0820322163729985
6.456230571526612,0.0534498899779956,348.45005635857837,127.41980508023106,-2.0820322163729985
6.4887055108525455,0.053718743748749756,348.8659423444548,127.41980508023106,-2.0820322163729985
6.5374179198414435,0.05412202440488098,349.4882524999833,127.41980508023106,-2.0820322163729985
6.579171413260498,0.05446769353870774,350.02022319895457,127.41980508023106,-2.0820322163729985
6.613965991109711,0.05475575115023004,350.4625270769963,127.41980508023106,-2.0820322163729985
6.651080207482205,0.0550630126025205,350.9333188221654,127.41980508023106,-2.0820322163729985
6.676596231238294,0.05527425485097019,351.2563939804141,127.41980508023106,-2.0820322163729985
6.727628278750474,0.055696739347869575,351.90110331421937,127.41980508023106,-2.0820322163729985
6.757783579553125,0.05594638927785557,352.28117146108644,127.41980508023106,-2.0820322163729985
6.790258518879058,0.056215243048609725,352.6897366683867,127.41980508023106,-2.0820322163729985
6.845929843437799,0.05667613522704541,353.38836564970507,127.41980508023106,-2.0820322163729985
6.8876833368568535,0.057021804360872175,353.91088425639526,127.41980508023106,-2.0820322163729985
6.910879722089662,0.05721384276855371,354.20063854530395,127.41980508023106,-2.0820322163729985
6.938715384369034,0.05744428885777156,354.54784349927894,127.41980508023106,-2.0820322163729985
7.005984901544179,0.05800120024004801,355.3846870966349,127.41980508023106,-2.0820322163729985
7.075574057242605,0.058577315463092625,356.2470963224569,127.41980508023106,-2.0820322163729985
7.11964718918494,0.05894218843768753,356.79157829251244,127.41980508023106,-2.0820322163729985
7.184597067836805,0.05947989597919584,357.5915829052956,127.41980508023106,-2.0820322163729985
7.230989838302421,0.059863972794558906,358.1612888647915,127.41980508023106,-2.0820322163729985
7.272743331721478,0.06020964192838568,358.67280657683216,127.41980508023106,-2.0820322163729985
7.2936200784310055,0.060382476495299056,358.928135852807,127.41980508023106,-2.0820322163729985
7.314496825140534,0.060555311062212444,359.1831802610662,127.41980508023106,-2.0820322163729985
7.333053933326781,0.06070894178835767,359.4096481668312,127.41980508023106,-2.0820322163729985
7.367848511175993,0.06099699939987997,359.83367397364276,127.41980508023106,-2.0820322163729985
7.40960200459505,0.06134266853370675,360.34147547036156,127.41980508023106,-2.0820322163729985
7.425839474258015,0.06147709541908382,360.5386522959372,127.41980508023106,-2.0820322163729985
7.439757305397701,0.061592318463692744,360.7075272085901,127.41980508023106,-2.0820322163729985
7.530223207805654,0.06234126825365073,361.8022262227208,127.41980508023106,-2.0820322163729985
7.597492724980799,0.06289817963592718,362.6129112120811,127.41980508023106,-2.0820322163729985
7.62532838726017,0.06312862572514504,362.94754765849956,127.41980508023106,-2.0820322163729985
7.634606941353293,0.06320544108821764,363.0589872275944,127.41980508023106,-2.0820322163729985
7.662442603632664,0.0634358871774355,363.39298944647965,127.41980508023106,-2.0820322163729985
7.692597904435315,0.06368553710742149,363.75429163755575,127.41980508023106,-2.0820322163729985
7.748269228994056,0.06414642928585718,364.4198632077818,127.41980508023106,-2.0820322163729985
7.790022722413111,0.06449209841968394,364.9178186450953,127.41980508023106,-2.0820322163729985
7.829456577308887,0.06481856371274256,365.38715498786837,127.41980508023106,-2.0820322163729985
7.868890432204661,0.06514502900580116,365.8555703253376,127.41980508023106,-2.0820322163729985
7.887447540390908,0.06529865973194639,366.0756842147076,127.41980508023106,-2.0820322163729985
7.91992247971684,0.06556751350270054,366.46039815044395,127.41980508023106,-2.0820322163729985
7.943118864949648,0.06575955191038207,366.73481724977006,127.41980508023106,-2.0820322163729985
7.987191996891985,0.066124424884977,367.25535401886265,127.41980508023106,-2.0820322163729985
8.008068743601514,0.06629725945189038,367.5015329765307,127.41980508023106,-2.0820322163729985
8.02894549031104,0.06647009401880376,367.7474617669835,127.41980508023106,-2.0820322163729985
8.089256091916344,0.06696939387877576,368.456525705401,127.41980508023106,-2.0820322163729985
8.110132838625871,0.06714222844568914,368.70149016315816,127.41980508023106,-2.0820322163729985
8.142607777951804,0.06741108221644329,369.08205774020274,127.41980508023106,-2.0820322163729985
8.170443440231175,0.06764152830566114,369.4077876214781,127.41980508023106,-2.0820322163729985
8.200598741033826,0.06789117823564714,369.76017365424593,127.41980508023106,-2.0820322163729985
8.23771295740632,0.0681984396879376,370.1931865584317,127.41980508023106,-2.0820322163729985
8.253950427069285,0.06833286657331467,370.38239038107747,127.41980508023106,-2.0820322163729985
8.32121994424443,0.06888977795559112,371.164693375094,127.41980508023106,-2.0820322163729985
8.36993235323333,0.06929305861172234,371.7296497750544,127.41980508023106,-2.0820322163729985
8.441841147455037,0.06988837767553512,372.56129501001226,127.41980508023106,-2.0820322163729985
8.45343934007144,0.06998439687937588,372.69517216759135,127.41980508023106,-2.0820322163729985
8.495192833490496,0.07033006601320264,373.176537929034,127.41980508023106,-2.0820322163729985
8.518389218723303,0.07052210442088418,373.4435646330451,127.41980508023106,-2.0820322163729985
8.578699820328607,0.07102140428085618,374.13651025813056,127.41980508023106,-2.0820322163729985
8.601896205561417,0.07121344268853771,374.4025215864949,127.41980508023106,-2.0820322163729985
8.706279939109056,0.07207761552310463,375.596127330468,127.41980508023106,-2.0820322163729985
8.80138511856357,0.07286497299459892,376.6787845436615,127.41980508023106,-2.0820322163729985
8.817622588226536,0.072999399879976,376.8631715350985,127.41980508023106,-2.0820322163729985
8.933604514390579,0.07395959191838368,378.1763918116216,127.41980508023106,-2.0820322163729985
8.968399092239792,0.07424764952990598,378.5690591115874,127.41980508023106,-2.0820322163729985
8.993915115995883,0.07445889177835567,378.85663762885605,127.41980508023106,-2.0820322163729985
9.12381487329961,0.07553430686137227,380.31576947874913,127.41980508023106,-2.0820322163729985
9.172527282288508,0.0759375875175035,380.8608522746403,127.41980508023106,-2.0820322163729985
9.214280775707566,0.07628325665133028,381.32716815168016,127.41980508023106,-2.0820322163729985
9.221239691277408,0.07634086817363474,381.4048072748079,127.41980508023106,-2.0820322163729985
9.251394992080058,0.07659051810362073,381.74097976966453,127.41980508023106,-2.0820322163729985
9.320984147778484,0.07716663332666533,382.5151356790873,127.41980508023106,-2.0820322163729985
9.365057279720821,0.07753150630126025,383.0042687623284,127.41980508023106,-2.0820322163729985
9.38593402643035,0.07770434086817364,383.2356499660119,127.41980508023106,-2.0820322163729985
9.409130411663158,0.07789637927585517,383.49250491557876,127.41980508023106,-2.0820322163729985
9.434646435419248,0.07810762152430487,383.7747602926814,127.41980508023106,-2.0820322163729985
9.464801736221899,0.07835727145429086,384.107951293135,127.41980508023106,-2.0820322163729985
9.536710530443605,0.07895259051810362,384.9008173750008,127.41980508023106,-2.0820322163729985
9.608619324665312,0.07954790958191639,385.69135528863654,127.41980508023106,-2.0820322163729985
9.63181570989812,0.07973994798959792,385.94587488131674,127.41980508023106,-2.0820322163729985
9.67820848036374,0.080124024804961,386.45419803488284,127.41980508023106,-2.0820322163729985
9.70836378116639,0.080373674734947,386.7840985660584,127.41980508023106,-2.0820322163729985
9.717642335259512,0.0804504900980196,386.88552599005516,127.41980508023106,-2.0820322163729985
9.745477997538885,0.08068093618723746,387.1895818882815,127.41980508023106,-2.0820322163729985
9.750117274585445,0.08071934386877376,387.2402249240526,127.41980508023106,-2.0820322163729985
9.770994021294975,0.08089217843568715,387.4680023880189,127.41980508023106,-2.0820322163729985
9.780272575388096,0.08096899379875976,387.56917588438574,127.41980508023106,-2.0820322163729985
9.794190406527782,0.08108421684336868,387.72086596945957,127.41980508023106,-2.0820322163729985
9.81738679176059,0.08127625525105021,387.97349609621733,127.41980508023106,-2.0820322163729985
9.873058116319331,0.0817371474294859,388.57886048229756,127.41980508023106,-2.0820322163729985
9.900893778598702,0.08196759351870375,388.88104334964976,127.41980508023106,-2.0820322163729985
9.94728654906432,0.08235167033406682,389.3839462112139,127.41980508023106,-2.0820322163729985
9.968163295773847,0.0825245049009802,389.6099539832745,127.41980508023106,-2.0820322163729985
10.00527751214634,0.08283176635327066,390.0112903002343,127.41980508023106,-2.0820322163729985
10.02847389737915,0.0830238047609522,390.26183068024426,127.41980508023106,-2.0820322163729985
10.160693293206158,0.08411842368473695,391.6856186840808,127.41980508023106,-2.0820322163729985
10.200127148101933,0.08444488897779556,392.1088559306067,127.41980508023106,-2.0820322163729985
10.26739666527708,0.08500180036007202,392.8293790518152,127.41980508023106,-2.0820322163729985
10.309150158696134,0.08534746949389878,393.2756744030112,127.41980508023106,-2.0820322163729985
10.457607024186109,0.08657651530306061,394.8568247248456,127.41980508023106,-2.0820322163729985
10.487762324988761,0.08682616523304662,395.1769235448838,127.41980508023106,-2.0820322163729985
10.529515818407818,0.08717183436687338,395.61954534957437,127.41980508023106,-2.0820322163729985
10.559671119210469,0.08742148429685938,395.9387910558576,127.41980508023106,-2.0820322163729985
10.580547865919995,0.08759431886377275,396.15959906315425,127.41980508023106,-2.0820322163729985
10.61534244376921,0.08788237647529507,396.5272351922433,127.41980508023106,-2.0820322163729985
10.715086900270286,0.08870814162832567,397.57852980593464,127.41980508023106,-2.0820322163729985
10.773077863352308,0.0891882376475295,398.1879930600379,127.41980508023106,-2.0820322163729985
10.78003677892215,0.08924584916983397,398.2610425708927,127.41980508023106,-2.0820322163729985
10.817150995294645,0.08955311062212443,398.6503298008279,127.41980508023106,-2.0820322163729985
10.826429549387768,0.08962992598519705,398.74757017353494,127.41980508023106,-2.0820322163729985
10.847306296097296,0.08980276055211042,398.9662422564796,127.41980508023106,-2.0820322163729985
10.902977620656037,0.09026365273054611,399.5485668665177,127.41980508023106,-2.0820322163729985
10.94009183702853,0.09057091418283657,399.9361391703267,127.41980508023106,-2.0820322163729985
10.958648945214778,0.0907245449089818,400.1297330030917,127.41980508023106,-2.0820322163729985
10.981845330447587,0.09091658331666334,400.37154559585645,127.41980508023106,-2.0820322163729985
11.06767195580898,0.09162712542508503,401.26452541369935,127.41980508023106,-2.0820322163729985
11.12334328036772,0.09208801760352071,401.84231187380925,127.41980508023106,-2.0820322163729985
11.17669496640318,0.09252970594118824,402.3949665411467,127.41980508023106,-2.0820322163729985
11.218448459822234,0.092875375075015,402.8267615413697,127.41980508023106,-2.0820322163729985
11.243964483578324,0.0930866173234647,403.0903277356377,127.41980508023106,-2.0820322163729985
11.348348217125963,0.09395079015803161,404.1661329643031,127.41980508023106,-2.0820322163729985
11.397060626114861,0.09435407081416283,404.66685405176946,127.41980508023106,-2.0820322163729985
11.452731950673602,0.09481496299259852,405.2380858317529,127.41980508023106,-2.0820322163729985
11.482887251476253,0.09506461292258452,405.5470508466497,127.41980508023106,-2.0820322163729985
11.557115684221241,0.09567913582716543,406.3062350578383,127.41980508023106,-2.0820322163729985
11.591910262070455,0.09596719343868775,406.6614478151106,127.41980508023106,-2.0820322163729985
11.654540502199039,0.0964856971394279,407.2997846739741,127.41980508023106,-2.0820322163729985
11.68469580300169,0.09673534706941389,407.6066547891629,127.41980508023106,-2.0820322163729985
11.758924235746678,0.09734986997399481,408.36071446570446,127.41980508023106,-2.0820322163729985
11.782120620979486,0.09754190838167634,408.59597710784374,127.41980508023106,-2.0820322163729985
11.879545438957281,0.09834846969393879,409.58211409693513,127.41980508023106,-2.0820322163729985
11.949134594655709,0.0989245849169834,410.28456756914346,127.41980508023106,-2.0820322163729985
12.051198689680065,0.09976955391078215,411.3119535099828,127.41980508023106,-2.0820322163729985
12.06047724377319,0.09984636927385478,411.40518363799,127.41980508023106,-2.0820322163729985