File: datasets/aisi_316_L/data/M1/train_65.csv
Time(s),Strain(%),Stress(MPa),Temp(C),Log_SR(s-1)
0.0,0.0,0.0,36.87319480564152,1.2871712473240926
2.47782134631264e-07,4.8e-06,0.9382442999999999,36.87319480564152,1.2871712473240926
7.020493814552478e-07,1.3599999999999999e-05,2.6583588499999995,36.87319480564152,1.2871712473240926
1.6931779199803036e-06,3.28e-05,6.411336049999999,36.87319480564152,1.2871712473240926
2.3539302789970077e-06,4.56e-05,8.91332085,36.87319480564152,1.2871712473240926
2.47782134631264e-06,4.8e-05,9.382443,36.87319480564152,1.2871712473240926
3.1798707277678875e-06,6.159999999999999e-05,12.04080185,36.87319480564152,1.2871712473240926
4.873048647748191e-06,9.439999999999999e-05,18.452137899999997,36.87319480564152,1.2871712473240926
5.120830782379456e-06,9.92e-05,19.3903822,36.87319480564152,1.2871712473240926
7.681246173569183e-06,0.00014879999999999998,29.085573299999997,36.87319480564152,1.2871712473240926
8.79626577940987e-06,0.0001704,33.30767265,36.87319480564152,1.2871712473240926
9.498315160865119e-06,0.000184,35.9660315,36.87319480564152,1.2871712473240926
9.828691340373471e-06,0.0001904,37.2170239,36.87319480564152,1.2871712473240926
1.011777049744328e-05,0.000196,38.31164225,36.87319480564152,1.2871712473240926
1.1604463305230863e-05,0.0002248,43.94110805,36.87319480564152,1.2871712473240926
1.1687057350107951e-05,0.0002264,44.25385615,36.87319480564152,1.2871712473240926
1.2967265045702814e-05,0.0002512,49.1014517,36.87319480564152,1.2871712473240926
1.3834502516912239e-05,0.000268,52.385306750000005,36.87319480564152,1.2871712473240926
1.4164878696420591e-05,0.0002744,53.63629915,36.87319480564152,1.2871712473240926
1.4288769763736223e-05,0.0002768,54.1054213,36.87319480564152,1.2871712473240926
1.6394917908101964e-05,0.00031759999999999997,62.08049784999999,36.87319480564152,1.2871712473240926
1.71795613344343e-05,0.00033279999999999996,65.05160479999999,36.87319480564152,1.2871712473240926
1.7964204760766637e-05,0.000348,68.02271175,36.87319480564152,1.2871712473240926
1.8666254142221886e-05,0.0003616,70.6810706,36.87319480564152,1.2871712473240926
1.998775886025529e-05,0.0003872,75.68504019999999,36.87319480564152,1.2871712473240926
2.0565917174394908e-05,0.0003984,77.8742769,36.87319480564152,1.2871712473240926
2.1226669533411612e-05,0.00041119999999999997,80.37626169999999,36.87319480564152,1.2871712473240926
2.242428318412939e-05,0.0004344,84.91110915,36.87319480564152,1.2871712473240926
2.283725340851483e-05,0.00044239999999999997,86.47484965,36.87319480564152,1.2871712473240926
2.3828381947039886e-05,0.0004616,90.22782685,36.87319480564152,1.2871712473240926
2.4489134306056587e-05,0.0004744,92.72981165,36.87319480564152,1.2871712473240926
2.5067292620196204e-05,0.0004856,94.91904835,36.87319480564152,1.2871712473240926
2.589323306896708e-05,0.0005015999999999999,98.04652934999999,36.87319480564152,1.2871712473240926
2.6182312226036893e-05,0.0005072,99.14114769999999,36.87319480564152,1.2871712473240926
2.700825267480777e-05,0.0005231999999999999,102.26862869999998,36.87319480564152,1.2871712473240926
2.7297331831877578e-05,0.0005288,103.36324704999998,36.87319480564152,1.2871712473240926
2.7792896101140107e-05,0.0005384,105.23973565,36.87319480564152,1.2871712473240926
2.8577539527472447e-05,0.0005536,108.2108426,36.87319480564152,1.2871712473240926
2.915569784161206e-05,0.0005648,110.40007929999999,36.87319480564152,1.2871712473240926
2.952737104355896e-05,0.000572,111.80744575,36.87319480564152,1.2871712473240926
3.1550925143047613e-05,0.0006112,119.4697742,36.87319480564152,1.2871712473240926
3.212908345718722e-05,0.0006224,121.65901089999998,36.87319480564152,1.2871712473240926
3.278983581620393e-05,0.0006351999999999999,124.16099569999999,36.87319480564152,1.2871712473240926
3.4070043511798796e-05,0.00066,129.00859125,36.87319480564152,1.2871712473240926
3.464820182593841e-05,0.0006711999999999999,131.19782794999998,36.87319480564152,1.2871712473240926
3.57632214317791e-05,0.0006927999999999999,135.41992729999998,36.87319480564152,1.2871712473240926
3.741510232932086e-05,0.0007247999999999999,141.6748893,36.87319480564152,1.2871712473240926
3.782807255370629e-05,0.0007327999999999999,143.23862979999998,36.87319480564152,1.2871712473240926
3.8530121935161545e-05,0.0007463999999999999,145.89698865,36.87319480564152,1.2871712473240926
3.9356062383932425e-05,0.0007624,149.02446965,36.87319480564152,1.2871712473240926
4.0264596877580394e-05,0.00078,152.46469875,36.87319480564152,1.2871712473240926
4.1255725416105444e-05,0.0007991999999999999,156.21767594999997,36.87319480564152,1.2871712473240926
4.228815097706905e-05,0.0008192,160.1270272,36.87319480564152,1.2871712473240926
4.377484378485663e-05,0.000848,165.756493,36.87319480564152,1.2871712473240926
4.447689316631188e-05,0.0008615999999999999,168.41485185,36.87319480564152,1.2871712473240926
4.4559487211188967e-05,0.0008632,168.72759994999998,36.87319480564152,1.2871712473240926
4.476597232338169e-05,0.0008671999999999999,169.50947019999998,36.87319480564152,1.2871712473240926
4.5344130637521307e-05,0.0008784,171.6987069,36.87319480564152,1.2871712473240926
4.5963585974099464e-05,0.0008904,174.04431764999998,36.87319480564152,1.2871712473240926
4.703730855750161e-05,0.0009111999999999999,178.11004294999998,36.87319480564152,1.2871712473240926
4.786324900627249e-05,0.0009272,181.23752395,36.87319480564152,1.2871712473240926
4.823492220821938e-05,0.0009343999999999999,182.64489039999998,36.87319480564152,1.2871712473240926
4.930864479162153e-05,0.0009551999999999999,186.71061569999998,36.87319480564152,1.2871712473240926
5.0299773330146584e-05,0.0009743999999999999,190.46359289999998,36.87319480564152,1.2871712473240926
5.100182271160183e-05,0.000988,193.12195175,36.87319480564152,1.2871712473240926
5.19103572052498e-05,0.0010056,196.56218084999998,36.87319480564152,1.2871712473240926
5.339705001303738e-05,0.0010344,202.19164665,36.87319480564152,1.2871712473240926
5.4140396416931175e-05,0.0010488,205.00637955,36.87319480564152,1.2871712473240926
5.4594663663755156e-05,0.0010576,206.72649409999997,36.87319480564152,1.2871712473240926
5.5833574336911484e-05,0.0010816,211.4177156,36.87319480564152,1.2871712473240926
5.60400594491042e-05,0.0010856,212.19958584999998,36.87319480564152,1.2871712473240926
5.6824702875436534e-05,0.0011007999999999999,215.17069279999998,36.87319480564152,1.2871712473240926
5.777453439152304e-05,0.0011191999999999999,218.76729594999998,36.87319480564152,1.2871712473240926
5.8641771862732465e-05,0.0011359999999999999,222.05115099999998,36.87319480564152,1.2871712473240926
5.996327658076589e-05,0.0011616,227.0551206,36.87319480564152,1.2871712473240926
6.0252355737835685e-05,0.0011672,228.14973895,36.87319480564152,1.2871712473240926
6.054143489490549e-05,0.0011727999999999999,229.2443573,36.87319480564152,1.2871712473240926
6.087181107441385e-05,0.0011792,230.49534970000002,36.87319480564152,1.2871712473240926
6.157386045586909e-05,0.0011928,233.15370854999998,36.87319480564152,1.2871712473240926
6.18629396129389e-05,0.0011983999999999999,234.24832689999997,36.87319480564152,1.2871712473240926
6.301925624121813e-05,0.0012208,238.62680029999999,36.87319480564152,1.2871712473240926
6.392779073486611e-05,0.0012384,242.0670294,36.87319480564152,1.2871712473240926
6.500151331826825e-05,0.0012592,246.1327547,36.87319480564152,1.2871712473240926
6.59926418567933e-05,0.0012783999999999998,249.88573189999997,36.87319480564152,1.2871712473240926
6.669469123824855e-05,0.001292,252.54409074999998,36.87319480564152,1.2871712473240926
6.735544359726525e-05,0.0013047999999999998,255.04607554999996,36.87319480564152,1.2871712473240926
6.917251258456119e-05,0.00134,261.92653375000003,36.87319480564152,1.2871712473240926
6.999845303333207e-05,0.001356,265.05401475,36.87319480564152,1.2871712473240926
7.123736370648838e-05,0.00138,269.74523625,36.87319480564152,1.2871712473240926
7.202200713282072e-05,0.0013951999999999999,272.7163432,36.87319480564152,1.2871712473240926
7.235238331232908e-05,0.0014016,273.9673356,36.87319480564152,1.2871712473240926
7.354999696304685e-05,0.0014248,278.50218305,36.87319480564152,1.2871712473240926
7.466501656888754e-05,0.0014464,282.7242824,36.87319480564152,1.2871712473240926
7.565614510741259e-05,0.0014655999999999998,286.47725959999997,36.87319480564152,1.2871712473240926
7.66885706683762e-05,0.0014856,290.38661084999995,36.87319480564152,1.2871712473240926
7.796877836397105e-05,0.0015103999999999999,295.23420639999995,36.87319480564152,1.2871712473240926
8.01575205532139e-05,0.0015528,302.5596452937945,36.87319480564152,1.2871712473240926
8.110735206930041e-05,0.0015712,302.7093026886181,36.87319480564152,1.2871712473240926
8.226366869757963e-05,0.0015936,302.89057490103244,36.87319480564152,1.2871712473240926
8.358517341561304e-05,0.0016192,303.0965307422161,36.87319480564152,1.2871712473240926
8.45763019541381e-05,0.0016384,303.2501652464588,36.87319480564152,1.2871712473240926
8.602169773948714e-05,0.0016664,303.472962854354,36.87319480564152,1.2871712473240926
8.697152925557366e-05,0.0016848,303.618578207222,36.87319480564152,1.2871712473240926
8.763228161459035e-05,0.0016975999999999998,303.7195102566036,36.87319480564152,1.2871712473240926
8.907767739993939e-05,0.0017255999999999999,303.939270114952,36.87319480564152,1.2871712473240926
8.949064762432483e-05,0.0017335999999999999,304.0018026422246,36.87319480564152,1.2871712473240926
8.990361784871027e-05,0.0017415999999999998,304.0642227289964,36.87319480564152,1.2871712473240926
9.139031065649786e-05,0.0017703999999999999,304.28801504213095,36.87319480564152,1.2871712473240926
9.176198385844475e-05,0.0017775999999999998,304.3437407182129,36.87319480564152,1.2871712473240926
9.287700346428544e-05,0.0017992,304.5103919632107,36.87319480564152,1.2871712473240926
9.316608262135524e-05,0.0018047999999999999,304.55347024305206,36.87319480564152,1.2871712473240926
9.357905284574069e-05,0.0018127999999999998,304.6149203244998,36.87319480564152,1.2871712473240926
9.423980520475739e-05,0.0018256,304.71302092798396,36.87319480564152,1.2871712473240926
9.457018138426575e-05,0.0018319999999999999,304.76197060936096,36.87319480564152,1.2871712473240926
9.547871587791371e-05,0.0018495999999999999,304.8962395574645,36.87319480564152,1.2871712473240926
9.576779503498352e-05,0.0018552,304.93885687924393,36.87319480564152,1.2871712473240926
9.601557716961479e-05,0.0018599999999999999,304.9753460960714,36.87319480564152,1.2871712473240926
9.675892357350858e-05,0.0018743999999999998,305.0845940335743,36.87319480564152,1.2871712473240926
9.737837891008674e-05,0.0018863999999999999,305.17538416592015,36.87319480564152,1.2871712473240926
9.878247767299723e-05,0.0019136,305.3803453438383,36.87319480564152,1.2871712473240926
9.923674491982122e-05,0.0019223999999999999,305.44641263822155,36.87319480564152,1.2871712473240926
0.00010047565559297753,0.0019463999999999998,305.6259993916699,36.87319480564152,1.2871712473240926
0.00010117770497443279,0.00196,305.7273818372223,36.87319480564152,1.2871712473240926
0.00010233402160271202,0.0019824,305.89376865433434,36.87319480564152,1.2871712473240926
0.00010291217991685163,0.0019936,305.9766869838231,36.87319480564152,1.2871712473240926
0.00010377941738806105,0.0020104,306.1007246488568,36.87319480564152,1.2871712473240926
0.00010406849654513087,0.002016,306.14198061876664,36.87319480564152,1.2871712473240926
0.00010431627867976214,0.0020208,306.17730731861906,36.87319480564152,1.2871712473240926
0.00010477054592658611,0.0020296,306.2419880567329,36.87319480564152,1.2871712473240926
0.00010576167446511117,0.0020488,306.3827312388035,36.87319480564152,1.2871712473240926
0.0001071244762055831,0.0020751999999999997,306.57541608262494,36.87319480564152,1.2871712473240926
0.0001076613374972842,0.0020856,306.6510594603125,36.87319480564152,1.2871712473240926
0.00010803301069923108,0.0020927999999999997,306.70334179879546,36.87319480564152,1.2871712473240926
0.00010856987199093216,0.0021032,306.778737058213,36.87319480564152,1.2871712473240926
0.00010943710946214158,0.00212,306.90022298078014,36.87319480564152,1.2871712473240926
0.00011001526777628119,0.0021311999999999998,306.9810050720831,36.87319480564152,1.2871712473240926
0.000110304346933351,0.0021368,307.0213340179945,36.87319480564152,1.2871712473240926
0.00011096509929236771,0.0021495999999999998,307.11336000085697,36.87319480564152,1.2871712473240926
0.00011117158440456043,0.0021536,307.1420742605969,36.87319480564152,1.2871712473240926
0.00011158455462894587,0.0021616,307.19944045707376,36.87319480564152,1.2871712473240926
0.00011261698018990946,0.0021815999999999997,307.3424948804278,36.87319480564152,1.2871712473240926
0.00011389718788550434,0.0022064,307.5191740093372,36.87319480564152,1.2871712473240926
0.00011410367299769706,0.0022104,307.54759795103786,36.87319480564152,1.2871712473240926
0.00011455794024452103,0.0022191999999999997,307.61006010614375,36.87319480564152,1.2871712473240926
0.00011505350451378357,0.0022288,307.67809057259177,36.87319480564152,1.2871712473240926
0.00011538388069329191,0.0022351999999999997,307.72338073923385,36.87319480564152,1.2871712473240926
0.00011674668243376387,0.0022616,307.90967058478424,36.87319480564152,1.2871712473240926
0.00011728354372546493,0.0022719999999999997,307.9828244022719,36.87319480564152,1.2871712473240926
0.00011757262288253475,0.0022776,308.0221608219733,36.87319480564152,1.2871712473240926
0.00011823337524155145,0.0022903999999999997,308.1119312709195,36.87319480564152,1.2871712473240926
0.0001190180186678838,0.0023056,308.21827995141655,36.87319480564152,1.2871712473240926
0.00012087638467761828,0.0023416,308.46907359226503,36.87319480564152,1.2871712473240926
0.00012128935490200371,0.0023496,308.524600777338,36.87319480564152,1.2871712473240926
0.00012215659237321312,0.0023664,308.64096843580256,36.87319480564152,1.2871712473240926
0.00012256956259759858,0.0023744,308.6962683245935,36.87319480564152,1.2871712473240926
0.00012426274051757888,0.0024072,308.9222422979093,36.87319480564152,1.2871712473240926
0.0001245518196746487,0.0024128,308.96070289582485,36.87319480564152,1.2871712473240926
0.00012599721545999772,0.0024408,309.1524861488239,36.87319480564152,1.2871712473240926
0.00012669926484145297,0.0024544,309.2453282661094,36.87319480564152,1.2871712473240926
0.0001271948291107155,0.002464,309.31074312052385,36.87319480564152,1.2871712473240926
0.000128598927873626,0.0024912,309.4955476109208,36.87319480564152,1.2871712473240926
0.00012884671000825727,0.002496,309.52807831208395,36.87319480564152,1.2871712473240926
0.00012938357129995833,0.0025063999999999998,309.59847791723075,36.87319480564152,1.2871712473240926
0.0001302921057936063,0.0025239999999999998,309.7173567307294,36.87319480564152,1.2871712473240926
0.00013099415517506155,0.0025376,309.808996341901,36.87319480564152,1.2871712473240926
0.00013173750157895533,0.002552,309.9058179916933,36.87319480564152,1.2871712473240926
0.00013202658073602515,0.0025575999999999997,309.9434132850886,36.87319480564152,1.2871712473240926
0.00013314160034186582,0.0025792,310.0881239720823,36.87319480564152,1.2871712473240926
0.00013462829314965342,0.002608,310.2803384633534,36.87319480564152,1.2871712473240926
0.00013475218421696904,0.0026103999999999997,310.29631887542945,36.87319480564152,1.2871712473240926
0.00013549553062086286,0.0026248,310.39208129425276,36.87319480564152,1.2871712473240926
0.00013652795618182643,0.0026447999999999997,310.52474544271325,36.87319480564152,1.2871712473240926
0.0001370648174735275,0.0026552,310.5935761445297,36.87319480564152,1.2871712473240926
0.00013917096561789327,0.002696,310.8625950363386,36.87319480564152,1.2871712473240926
0.0001395013417974016,0.0027023999999999998,310.9046495826279,36.87319480564152,1.2871712473240926
0.0001397904209544714,0.002708,310.94141545790114,36.87319480564152,1.2871712473240926
0.00014024468820129538,0.0027167999999999997,310.99913055314533,36.87319480564152,1.2871712473240926
0.00014152489589689025,0.0027416,311.1613912353657,36.87319480564152,1.2871712473240926
0.00014210305421102988,0.0027527999999999997,311.23448251673045,36.87319480564152,1.2871712473240926
0.00014276380657004658,0.0027656,311.31787354676896,36.87319480564152,1.2871712473240926
0.0001443743904451498,0.0027968,311.520511066313,36.87319480564152,1.2871712473240926
0.0001456958951631832,0.0028224,311.6861201007932,36.87319480564152,1.2871712473240926
0.00014586108325293737,0.0028255999999999997,311.7067799600733,36.87319480564152,1.2871712473240926
0.00014705869690365516,0.0028488,311.8562919969241,36.87319480564152,1.2871712473240926
0.00014825631055437295,0.002872,312.00532991950854,36.87319480564152,1.2871712473240926
0.00014928873611533654,0.002892,312.13343442828136,36.87319480564152,1.2871712473240926
0.00015044505274361576,0.0029143999999999997,312.2765019940859,36.87319480564152,1.2871712473240926
0.00015098191403531685,0.0029248,312.34278038459223,36.87319480564152,1.2871712473240926
0.00015193174555140336,0.0029432,312.45981743398727,36.87319480564152,1.2871712473240926
0.00015267509195529715,0.0029576,312.5512127151516,36.87319480564152,1.2871712473240926
0.0001532119532469982,0.0029679999999999997,312.61711252285903,36.87319480564152,1.2871712473240926
0.0001560201507728192,0.0030223999999999997,312.9603626141207,36.87319480564152,1.2871712473240926
0.00015614404184013483,0.0030248,312.9754502555731,36.87319480564152,1.2871712473240926
0.0001565570120645203,0.0030328,313.0257087090899,36.87319480564152,1.2871712473240926
0.00015701127931134427,0.0030415999999999998,313.08093332832215,36.87319480564152,1.2871712473240926
0.00015796111082743078,0.00306,313.1962020349904,36.87319480564152,1.2871712473240926
0.0001585392691415704,0.0030712,313.2662332581441,36.87319480564152,1.2871712473240926
0.00015895223936595584,0.0030792,313.31619459364555,36.87319480564152,1.2871712473240926
0.0001592826155454642,0.0030856,313.3561272228978,36.87319480564152,1.2871712473240926
0.0001598607738596038,0.0030968,313.42593168402664,36.87319480564152,1.2871712473240926
0.00016072801133081322,0.0031136,313.53045404999403,36.87319480564152,1.2871712473240926
0.00016143006071226847,0.0031271999999999997,313.6149063900805,36.87319480564152,1.2871712473240926
0.00016176043689177682,0.0031336,313.6545990933564,36.87319480564152,1.2871712473240926
0.00016316453565468734,0.0031608,313.8229415813072,36.87319480564152,1.2871712473240926
0.0001640730701483353,0.0031784,313.9315680921153,36.87319480564152,1.2871712473240926
0.00016580754509075413,0.003212,314.13829676747093,36.87319480564152,1.2871712473240926
0.0001664270004273323,0.003224,314.2119238217298,36.87319480564152,1.2871712473240926
0.00016758331705561154,0.0032464,314.34907566368986,36.87319480564152,1.2871712473240926
0.00016783109919024278,0.0032511999999999997,314.3784172707096,36.87319480564152,1.2871712473240926
0.00016816147536975114,0.0032576,314.417513146563,36.87319480564152,1.2871712473240926
0.00016865703963901368,0.0032672,314.47610084060364,36.87319480564152,1.2871712473240926
0.0001691526039082762,0.0032768,314.53462143527196,36.87319480564152,1.2871712473240926
0.00017014373244680125,0.003296,314.6514624169508,36.87319480564152,1.2871712473240926
0.00017072189076094087,0.0033071999999999997,314.7194970733811,36.87319480564152,1.2871712473240926
0.00017138264311995758,0.00332,314.797141034319,36.87319480564152,1.2871712473240926
0.00017200209845653574,0.003332,314.8698262856444,36.87319480564152,1.2871712473240926
0.00017295192997262226,0.0033504,314.98107903550635,36.87319480564152,1.2871712473240926
0.00017501678109454945,0.0033904,315.2221140895896,36.87319480564152,1.2871712473240926
0.00017576012749844324,0.0034048,315.3086148827698,36.87319480564152,1.2871712473240926
0.0001758840185657589,0.0034072,315.3230177989672,36.87319480564152,1.2871712473240926
0.00017670995901452975,0.0034232,315.4189363259887,36.87319480564152,1.2871712473240926
0.0001782792458671944,0.0034536,315.6007011973186,36.87319480564152,1.2871712473240926
0.00018112874041545396,0.0035088,315.9291607085232,36.87319480564152,1.2871712473240926
0.00018207857193154047,0.0035272,316.03819856714574,36.87319480564152,1.2871712473240926
0.00018273932429055718,0.0035399999999999997,316.11392019049026,36.87319480564152,1.2871712473240926
0.00018335877962713534,0.003552,316.1848122921196,36.87319480564152,1.2871712473240926
0.00018422601709834477,0.0035688,316.2839045146618,36.87319480564152,1.2871712473240926
0.0001857540069285709,0.0035984,316.4580540670927,36.87319480564152,1.2871712473240926
0.00018724069973635846,0.0036271999999999997,316.626961429598,36.87319480564152,1.2871712473240926
0.00018769496698318246,0.003636,316.6784675815865,36.87319480564152,1.2871712473240926
0.00018814923423000643,0.0036447999999999997,316.7299251400877,36.87319480564152,1.2871712473240926
0.00018930555085828565,0.0036672,316.8606898551577,36.87319480564152,1.2871712473240926
0.000190090194284618,0.0036823999999999997,316.9492456953724,36.87319480564152,1.2871712473240926
0.00019087483771095033,0.0036975999999999997,317.03765909085496,36.87319480564152,1.2871712473240926
0.0001911226198455816,0.0037024,317.0655496473474,36.87319480564152,1.2871712473240926
0.000191989857316791,0.0037191999999999998,317.1630557363946,36.87319480564152,1.2871712473240926
0.00019393081737140259,0.0037568,317.3806633618023,36.87319480564152,1.2871712473240926
0.00019438508461822659,0.0037656,317.43146994830823,36.87319480564152,1.2871712473240926
0.0001945089756855422,0.0037679999999999996,317.4453182509101,36.87319480564152,1.2871712473240926
0.00019541751017919016,0.0037855999999999996,317.5467675670761,36.87319480564152,1.2871712473240926
0.0001959956684933298,0.0037968,317.6112304605301,36.87319480564152,1.2871712473240926
0.00019616085658308397,0.0038,317.62963480323265,36.87319480564152,1.2871712473240926
0.00019735847023380173,0.0038231999999999997,317.76288599207106,36.87319480564152,1.2871712473240926
0.00019744106427867884,0.0038247999999999997,317.77206408832484,36.87319480564152,1.2871712473240926
0.00019810181663769554,0.0038376,317.84543503049713,36.87319480564152,1.2871712473240926
0.0001994646183781675,0.003864,317.99646186178853,36.87319480564152,1.2871712473240926
0.0001999188856249915,0.0038728,318.04671464097333,36.87319480564152,1.2871712473240926
0.0002001253707371842,0.0038767999999999997,318.0695420897264,36.87319480564152,1.2871712473240926
0.00020053834096156963,0.0038848,318.1151694490586,36.87319480564152,1.2871712473240926
0.0002009926082083936,0.0038935999999999997,318.16531724067363,36.87319480564152,1.2871712473240926
0.00020128168736546342,0.0038992,318.19720645849173,36.87319480564152,1.2871712473240926
0.00020206633079179577,0.0039144,318.283672997296,36.87319480564152,1.2871712473240926
0.0002035117265771448,0.0039423999999999996,318.4426114584977,36.87319480564152,1.2871712473240926
0.00020532879556444072,0.0039775999999999995,318.6417965888914,36.87319480564152,1.2871712473240926
0.00022532032146655083,0.004364872974594919,320.78969203228195,36.87319480564152,1.2871712473240926
0.00025307747197535413,0.004902580516103221,323.652420236699,36.87319480564152,1.2871712473240926
0.00026794737403364167,0.005190638127625526,325.13547109967703,36.87319480564152,1.2871712473240926
0.00027389533485695664,0.0053058611722344474,325.71965962734447,36.87319480564152,1.2871712473240926
0.00028678258330747244,0.005555511102220444,326.968691286605,36.87319480564152,1.2871712473240926
0.0003085917729929608,0.005977995599119824,329.0336663687869,36.87319480564152,1.2871712473240926
0.00031553106062016164,0.006112422484496899,329.678659618287,36.87319480564152,1.2871712473240926
0.0003224703482473625,0.006246849369873975,330.31814386410485,36.87319480564152,1.2871712473240926
0.0003323836162862208,0.006438887777555511,331.22245995661234,36.87319480564152,1.2871712473240926
0.0003442795379328508,0.006669333866773355,332.29386995473516,36.87319480564152,1.2871712473240926
0.0003670800544222249,0.007111022204440888,334.307876990224,36.87319480564152,1.2871712473240926
0.00037501066885331155,0.007264652930586117,334.9968843229602,36.87319480564152,1.2871712473240926
0.0004027678193621149,0.007802360472094419,337.36488500807366,36.87319480564152,1.2871712473240926
0.0004325076234786899,0.008378475695139028,339.8324297623178,36.87319480564152,1.2871712473240926
0.0004404382379097766,0.008532106421284257,340.47914900156195,36.87319480564152,1.2871712473240926
0.0004503515059486349,0.008724144828965793,341.28119658557324,36.87319480564152,1.2871712473240926
0.00047711732965355244,0.009242648529705941,343.41304991843424,36.87319480564152,1.2871712473240926
0.0004900045781040682,0.009492298459691939,344.42281477170246,36.87319480564152,1.2871712473240926
0.0005167704018089858,0.010010802160432087,346.4875076979002,36.87319480564152,1.2871712473240926
0.0005365969378867024,0.01039487897579516,347.9901145460839,36.87319480564152,1.2871712473240926
0.0006069811409625966,0.011758351670334066,353.157741158408,36.87319480564152,1.2871712473240926
0.0006238336966286557,0.012084816963392678,354.3596975812179,36.87319480564152,1.2871712473240926
0.0006268076770403132,0.012142428485697139,354.57048626602,36.87319480564152,1.2871712473240926
0.0006357296182752857,0.012315263052610522,355.20052439202567,36.87319480564152,1.2871712473240926
0.000657538807960774,0.012737747549509902,356.7262725834497,36.87319480564152,1.2871712473240926
0.0006684434028035182,0.012948989797959592,357.4817356604695,36.87319480564152,1.2871712473240926
0.0006734000368229474,0.01304500900180036,357.8235375235877,36.87319480564152,1.2871712473240926
0.0006793479976462623,0.013160232046409282,358.2324073104146,36.87319480564152,1.2871712473240926
0.0007041311677434082,0.013640328065613123,359.92121767246994,36.87319480564152,1.2871712473240926
0.000711070455370609,0.013774754950990198,360.3899095700158,36.87319480564152,1.2871712473240926
0.0007299056646444398,0.014139627925585117,361.6531667233485,36.87319480564152,1.2871712473240926
0.0007725327172115307,0.014965393078615724,364.4660839681632,36.87319480564152,1.2871712473240926
0.0007933505800931332,0.01536867373474695,365.81777575233497,36.87319480564152,1.2871712473240926
0.0008240817110135941,0.015963992798559715,367.7881162529756,36.87319480564152,1.2871712473240926
0.0008379602862679956,0.016232846569313862,368.6685324032732,36.87319480564152,1.2871712473240926
0.0008558041687379406,0.016578515703140628,369.7921843043467,36.87319480564152,1.2871712473240926
0.0008696827439923422,0.01684736947389478,370.65983042517877,36.87319480564152,1.2871712473240926
0.0008924832604817165,0.017289057811562314,372.073616672209,36.87319480564152,1.2871712473240926
0.0009043791821283466,0.017519503900780158,372.8056482033224,36.87319480564152,1.2871712473240926
0.0009063618357361181,0.01755791158231646,372.92728743733056,36.87319480564152,1.2871712473240926
0.0009430409274798939,0.018268453690738148,375.1592272601004,36.87319480564152,1.2871712473240926
0.0009648501171653823,0.018690938187637528,376.47027806823735,36.87319480564152,1.2871712473240926
0.0009955812480858433,0.019286257251450292,378.29821750474093,36.87319480564152,1.2871712473240926
0.0010104511501441305,0.019574314862972595,379.1747927941986,36.87319480564152,1.2871712473240926
0.0010481215686917924,0.020304060812162433,381.3732272447463,36.87319480564152,1.2871712473240926
0.0010600174903384223,0.020534506901380277,382.06103868081976,36.87319480564152,1.2871712473240926
0.001079844026416139,0.02091858371674335,383.2007387113348,36.87319480564152,1.2871712473240926
0.0010937226016705405,0.0211874374874975,383.99367772890344,36.87319480564152,1.2871712473240926
0.0011056185233171707,0.021417883576715344,384.67022148194377,36.87319480564152,1.2871712473240926
0.0011105751573365996,0.02151390278055611,384.9512761476041,36.87319480564152,1.2871712473240926
0.001120488425375458,0.021705941188237647,385.51192213933984,36.87319480564152,1.2871712473240926
0.001156176190315348,0.022397279455891178,387.5144248708051,36.87319480564152,1.2871712473240926
0.0011660894583542063,0.022589317863572714,388.06637861168815,36.87319480564152,1.2871712473240926
0.0012136731449407265,0.02351110222044409,390.6906963497964,36.87319480564152,1.2871712473240926
0.0012374649882339864,0.023971994398879776,391.9877833547601,36.87319480564152,1.2871712473240926
0.0012513435634883881,0.024240848169633927,392.7399259442524,36.87319480564152,1.2871712473240926
0.0012612568315272465,0.024432886577315464,393.2751801419459,36.87319480564152,1.2871712473240926
0.001310823171721538,0.025393078615723146,395.92722728649744,36.87319480564152,1.2871712473240926
0.0013375889954264555,0.025911582316463292,397.34305694109287,36.87319480564152,1.2871712473240926
0.0013534502242886289,0.02621884376875375,398.17685358270694,36.87319480564152,1.2871712473240926
0.0013683201263469163,0.026506901380276057,398.9550835673834,36.87319480564152,1.2871712473240926
0.0013950859500518338,0.027025405081016203,400.34763619014865,36.87319480564152,1.2871712473240926
0.001422843100560637,0.027563112622524505,401.7808029401265,36.87319480564152,1.2871712473240926
0.0014327563685994954,0.02775515103020604,402.2900002905171,36.87319480564152,1.2871712473240926
0.0014476262706577831,0.028043208641728348,403.05122756262995,36.87319480564152,1.2871712473240926
0.0014615048459121847,0.0283120624124825,403.7589595906128,36.87319480564152,1.2871712473240926
0.0014664614799316138,0.028408081616323265,404.0110851953197,36.87319480564152,1.2871712473240926
0.0014763747479704721,0.0286001200240048,404.5143415587398,36.87319480564152,1.2871712473240926
0.0014823227087937872,0.028715343068613723,404.81566283450974,36.87319480564152,1.2871712473240926
0.0015209844541453346,0.029464292858571713,406.76288189916045,36.87319480564152,1.2871712473240926
0.0015299063953803072,0.029637127425485098,407.2094873814358,36.87319480564152,1.2871712473240926
0.0015636115067124254,0.03029005801160232,408.8875750827722,36.87319480564152,1.2871712473240926
0.0015903773304173428,0.030808561712342468,410.2101452955984,36.87319480564152,1.2871712473240926
0.001602273252063973,0.03103900780156031,410.79516481271804,36.87319480564152,1.2871712473240926
0.0016121865201028313,0.031231046209241848,411.2813882189625,36.87319480564152,1.2871712473240926
0.0016240824417494614,0.031461492298459695,411.86331987869283,36.87319480564152,1.2871712473240926
0.0016805880695709538,0.03255611122224445,414.6051083807766,36.87319480564152,1.2871712473240926
0.0016994232788447843,0.032920984196839365,415.5110169004036,36.87319480564152,1.2871712473240926
0.0017291630829613595,0.03349709941988398,416.93346663000256,36.87319480564152,1.2871712473240926
0.00173610237058856,0.03363152630526105,417.2639948655342,36.87319480564152,1.2871712473240926
0.0017440329850196468,0.03378515703140628,417.6411111655378,36.87319480564152,1.2871712473240926
0.0017698074819206787,0.034284456891378275,418.86214604493756,36.87319480564152,1.2871712473240926
0.0018441569922121159,0.03572474494898979,422.3460948674448,36.87319480564152,1.2871712473240926
0.001868940162309262,0.03620484096819364,423.4951799881578,36.87319480564152,1.2871712473240926
0.0018818274107597777,0.036454490898179634,424.090354826051,36.87319480564152,1.2871712473240926
0.001916523848895782,0.03712662532506501,425.6848999960072,36.87319480564152,1.2871712473240926
0.0019234631365229826,0.03726105221044208,426.0024536914221,36.87319480564152,1.2871712473240926
0.0019393243653851558,0.03756831366273254,426.7266176923963,36.87319480564152,1.2871712473240926
0.001960142228266759,0.03797159431886378,427.6735871888064,36.87319480564152,1.2871712473240926
0.0019760034571289324,0.03827885577115424,428.39245737446447,36.87319480564152,1.2871712473240926
0.001992856012794991,0.03860532106421284,429.15379554431195,36.87319480564152,1.2871712473240926
0.002015656529284365,0.03904700940188037,430.1798566978996,36.87319480564152,1.2871712473240926
0.002031517758146538,0.03935427085417083,430.89097023778123,36.87319480564152,1.2871712473240926
0.0020463876602048263,0.03964232846569314,431.5556751667001,36.87319480564152,1.2871712473240926
0.0020533269478320267,0.03977675535107021,431.8652259055044,36.87319480564152,1.2871712473240926
0.002083066751948602,0.040352870574114824,433.1872773680754,36.87319480564152,1.2871712473240926
0.0020989279808107755,0.04066013202640528,433.8893605917605,36.87319480564152,1.2871712473240926
0.002120737170496264,0.041082616523304666,434.85135582388915,36.87319480564152,1.2871712473240926
0.0021385810529662088,0.04142828565713143,435.6355762783953,36.87319480564152,1.2871712473240926
0.0021504769746128385,0.041658731746349265,436.1569726501156,36.87319480564152,1.2871712473240926
0.0021802167787294134,0.04223484696939388,437.4555663658383,36.87319480564152,1.2871712473240926
0.0021940953539838154,0.04250370074014803,438.0592108366729,36.87319480564152,1.2871712473240926
0.002203017295218788,0.04267653530706142,438.4464817827619,36.87319480564152,1.2871712473240926
0.0022238351581003904,0.043079815963192644,439.347743036041,36.87319480564152,1.2871712473240926
0.00225952292304028,0.04377115423084617,440.885144381933,36.87319480564152,1.2871712473240926
0.002262496903451938,0.04382876575315063,441.0128321270874,36.87319480564152,1.2871712473240926
0.0022704275178830244,0.04398239647929586,441.3530131690363,36.87319480564152,1.2871712473240926
0.0022912453807646268,0.044385677135427085,442.2437908020315,36.87319480564152,1.2871712473240926
0.0023338724333317176,0.04521144228845769,444.0579755150653,36.87319480564152,1.2871712473240926
0.0023527076426055485,0.045576315263052614,444.85547054423665,36.87319480564152,1.2871712473240926
0.002363612237448293,0.045787557511502305,445.3160401057525,36.87319480564152,1.2871712473240926
0.0023903780611532104,0.046306061212242455,446.4430296342782,36.87319480564152,1.2871712473240926
0.0024072306168192695,0.04663252650530106,447.1500913643385,36.87319480564152,1.2871712473240926
0.002447875015778589,0.04741988397679536,448.84746216373475,36.87319480564152,1.2871712473240926
0.0024617535910329905,0.04768873774754952,449.4245301551178,36.87319480564152,1.2871712473240926
0.0024905020683456797,0.04824564912982597,450.615864697941,36.87319480564152,1.2871712473240926
0.00249744135597288,0.04838007601520304,450.90262321773486,36.87319480564152,1.2871712473240926
0.0025232158528739118,0.04887937587517503,451.96501662252126,36.87319480564152,1.2871712473240926
0.002549981676578829,0.04939787957591518,453.0638012417577,36.87319480564152,1.2871712473240926
0.0025559296374021443,0.04951310262052411,453.30736369277247,36.87319480564152,1.2871712473240926
0.00256881688585266,0.0497627525505101,453.8343252998361,36.87319480564152,1.2871712473240926
0.0025797214806954046,0.049973994798959795,454.2794110864145,36.87319480564152,1.2871712473240926
0.002619374552850838,0.05074214842968594,455.89175626340466,36.87319480564152,1.2871712473240926
0.00262829649408581,0.050914982996599314,456.25321876835517,36.87319480564152,1.2871712473240926
0.0026411837425363263,0.051164632926585324,456.77448760157876,36.87319480564152,1.2871712473240926
0.002664975585829586,0.05162552510502101,457.7342314236827,36.87319480564152,1.2871712473240926
0.0026947153899461607,0.05220164032806561,458.92922498860054,36.87319480564152,1.2871712473240926
0.002724455194062736,0.05277775555111022,460.1190860224898,36.87319480564152,1.2871712473240926
0.00273535978890548,0.052988997799559914,460.5540978417562,36.87319480564152,1.2871712473240926
0.002754194998179311,0.053353870774154835,461.3038922391267,36.87319480564152,1.2871712473240926
0.0027849261290997717,0.05394918983796759,462.52296203653714,36.87319480564152,1.2871712473240926
0.0028037613383736027,0.054314062812562514,463.2675411026171,36.87319480564152,1.2871712473240926
0.0028354837960979495,0.05492858571714343,464.51717456660174,36.87319480564152,1.2871712473240926
0.002868197580626182,0.055562312462492505,465.8001616584838,36.87319480564152,1.2871712473240926
0.0028929807507233275,0.05604240848169634,466.76832565179643,36.87319480564152,1.2871712473240926
0.0029028940187621854,0.05623444688937787,467.154684901315,36.87319480564152,1.2871712473240926
0.0029078506527816152,0.05633046609321865,467.34767153919097,36.87319480564152,1.2871712473240926
0.002928668515663218,0.056733746749349875,468.1568184361639,36.87319480564152,1.2871712473240926
0.0029435384177215053,0.057021804360872175,468.73340775101695,36.87319480564152,1.2871712473240926
0.0029762522022497378,0.05765553110622125,469.99792066650946,36.87319480564152,1.2871712473240926
0.0029950874115235687,0.05802040408081617,470.72351453919964,36.87319480564152,1.2871712473240926
0.0030030180259546548,0.058174034806961386,471.0284951041676,36.87319480564152,1.2871712473240926
0.0030079746599740846,0.058270054010802166,471.21894845566544,36.87319480564152,1.2871712473240926
0.0030168966012090567,0.05844288857771554,471.5614563382974,36.87319480564152,1.2871712473240926
0.0030357318104828877,0.05880776155231046,472.28323397606897,36.87319480564152,1.2871712473240926
0.003057541000168376,0.059230246049209845,473.11679816197466,36.87319480564152,1.2871712473240926
0.003087280804284951,0.05980636127225446,474.2497492370342,36.87319480564152,1.2871712473240926
0.0030981853991276947,0.060017603520704135,474.6640971565206,36.87319480564152,1.2871712473240926
0.0031150379547937542,0.06034406881376275,475.3033360626591,36.87319480564152,1.2871712473240926
0.00312792520324427,0.06059371874374875,475.79125617998085,36.87319480564152,1.2871712473240926
0.0031408124516947855,0.06084336867373474,476.2783929221902,36.87319480564152,1.2871712473240926
0.003146760412518101,0.06095859171834367,476.5029622865712,36.87319480564152,1.2871712473240926
0.0031665869485958177,0.06134266853370675,477.25033409508626,36.87319480564152,1.2871712473240926
0.00322309257641731,0.0624372874574915,479.37039672480694,36.87319480564152,1.2871712473240926
0.003242919112495027,0.06282136427285458,480.1108365023109,36.87319480564152,1.2871712473240926
0.003251841053729999,0.06299419883976795,480.44345819832347,36.87319480564152,1.2871712473240926
0.0032766242238271453,0.0634742948589718,481.3655450982035,36.87319480564152,1.2871712473240926
0.0033202426031981214,0.06431926385277055,482.9818388300652,36.87319480564152,1.2871712473240926
0.003329164544433094,0.06449209841968394,483.3114218625283,36.87319480564152,1.2871712473240926
0.0033440344464913813,0.06478015603120624,483.85996245442897,36.87319480564152,1.2871712473240926
0.0033598956753535547,0.0650874174834967,484.444024939453,36.87319480564152,1.2871712473240926
0.0033787308846273856,0.06545229045809162,485.13620434250925,36.87319480564152,1.2871712473240926
0.003388644152666244,0.06564432886577315,485.49990475613953,36.87319480564152,1.2871712473240926
0.0034312712052333347,0.06647009401880376,487.0591118100378,36.87319480564152,1.2871712473240926
0.003453080394918823,0.06689257851570314,487.8539232223769,36.87319480564152,1.2871712473240926
0.0034788548918198554,0.06739187837567515,488.79072615567816,36.87319480564152,1.2871712473240926
0.0034828201990353986,0.06746869373874775,488.9346090772739,36.87319480564152,1.2871712473240926
0.0034887681598587137,0.06758391678335668,489.1503137276886,36.87319480564152,1.2871712473240926
0.0035105773495442013,0.06800640128025605,489.9400066935588,36.87319480564152,1.2871712473240926
0.0035343691928374616,0.06846729345869174,490.7993110069656,36.87319480564152,1.2871712473240926
0.003598805435090041,0.06971554310862173,493.11533924971184,36.87319480564152,1.2871712473240926
0.003608718703128899,0.06990758151630326,493.47021073107624,36.87319480564152,1.2871712473240926
0.0036354845268338166,0.07042608521704341,494.4264697896016,36.87319480564152,1.2871712473240926
0.003643415141264903,0.07057971594318864,494.70927799374215,36.87319480564152,1.2871712473240926
0.00366324167734262,0.07096379275855172,495.4152501848456,36.87319480564152,1.2871712473240926
0.003694964135066967,0.07157831566313264,496.5417140393991,36.87319480564152,1.2871712473240926
0.003714790671144683,0.0719623924784957,497.2438389578894,36.87319480564152,1.2871712473240926
0.0037256952659874276,0.0721736347269454,497.6293846622602,36.87319480564152,1.2871712473240926
0.003732634553614628,0.07230806161232246,497.87450280781894,36.87319480564152,1.2871712473240926
0.00374651312886903,0.07257691538307662,498.36420658597234,36.87319480564152,1.2871712473240926
0.0037693136453584037,0.07301860372074415,499.16718684114613,36.87319480564152,1.2871712473240926
0.0037831922206128057,0.0732874574914983,499.65503004222325,36.87319480564152,1.2871712473240926
0.0038010361030827505,0.07363312662532506,500.2812326661152,36.87319480564152,1.2871712473240926
0.0038208626391604676,0.07401720344068814,500.9756702690951,36.87319480564152,1.2871712473240926
0.003831767234003212,0.07422844568913783,501.35701187818364,36.87319480564152,1.2871712473240926
0.0038436631556498413,0.07445889177835567,501.77253852473706,36.87319480564152,1.2871712473240926
0.0038545677504925858,0.07467013402680536,502.1529975633771,36.87319480564152,1.2871712473240926
0.0038902555154324762,0.0753614722944589,503.39521165253484,36.87319480564152,1.2871712473240926
0.003899177456667448,0.07553430686137227,503.70506977704787,36.87319480564152,1.2871712473240926
0.003986414215409402,0.0772242448489698,506.7203640985591,36.87319480564152,1.2871712473240926
0.003999301463859917,0.07747389477895579,507.1636140144035,36.87319480564152,1.2871712473240926
0.004030032594780379,0.07806921384276856,508.21835266145945,36.87319480564152,1.2871712473240926
0.0040439111700347795,0.0783380676135227,508.6936576003643,36.87319480564152,1.2871712473240926
0.004072659647347469,0.07889497899579917,509.6761988436593,36.87319480564152,1.2871712473240926
0.004080590261778556,0.0790486097219444,509.94676821731355,36.87319480564152,1.2871712473240926
0.00412024333393399,0.07981676335267054,511.29655103435823,36.87319480564152,1.2871712473240926
0.004151965791658336,0.08043128625725146,512.3727331604379,36.87319480564152,1.2871712473240926
0.0041618790596971945,0.080623324664933,512.7083818183685,36.87319480564152,1.2871712473240926
0.004172783654539938,0.08083456691338269,513.0772354189024,36.87319480564152,1.2871712473240926
0.004193601517421541,0.08123784756951391,513.7803682563501,36.87319480564152,1.2871712473240926
0.00419855815144097,0.08133386677335468,513.9475800349855,36.87319480564152,1.2871712473240926
0.0042213586679303436,0.0817755551110222,514.7157647962374,36.87319480564152,1.2871712473240926
0.004233254589576975,0.08200600120024006,515.1159143795837,36.87319480564152,1.2871712473240926
0.004257046432870234,0.08246689337867574,515.9149003467217,36.87319480564152,1.2871712473240926
0.004260020413281892,0.0825245049009802,516.0146509989601,36.87319480564152,1.2871712473240926
0.00426993368132075,0.08271654330866174,516.3469572024092,36.87319480564152,1.2871712473240926
0.004274890315340179,0.0828125625125025,516.5129974630446,36.87319480564152,1.2871712473240926
0.004280838276163494,0.08292778555711143,516.7121466996571,36.87319480564152,1.2871712473240926
0.004299673485437325,0.08329265853170635,517.3420751912785,36.87319480564152,1.2871712473240926
0.004316526041103384,0.08361912382476495,517.9047837701837,36.87319480564152,1.2871712473240926
0.004332387269965557,0.08392638527705541,518.4336096720878,36.87319480564152,1.2871712473240926
0.004370057688513219,0.08465613122624525,519.6865541806097,36.87319480564152,1.2871712473240926
0.004390875551394821,0.08505941188237648,520.3771635689477,36.87319480564152,1.2871712473240926
0.004397814839022022,0.08519383876775355,520.6070827724795,36.87319480564152,1.2871712473240926
0.004446389852412428,0.08613482696539308,522.212574025237,36.87319480564152,1.2871712473240926
0.004452337813235743,0.08625005001000201,522.4086936199293,36.87319480564152,1.2871712473240926
0.004474147002921232,0.08667253450690139,523.1269262601984,36.87319480564152,1.2871712473240926
0.004487034251371748,0.08692218443688739,523.5506946788122,36.87319480564152,1.2871712473240926
0.004553453147232098,0.08820884176835367,525.7272499868421,36.87319480564152,1.2871712473240926
0.004582201624544788,0.08876575315063014,526.6654977069298,36.87319480564152,1.2871712473240926
0.0045921148925836455,0.08895779155831167,526.9884987327493,36.87319480564152,1.2871712473240926
0.00461491540907302,0.0893994798959792,527.730370851719,36.87319480564152,1.2871712473240926
0.004644655213189595,0.08997559511902381,528.695885428677,36.87319480564152,1.2871712473240926
0.004660516442051768,0.09028285657131427,529.2098405420778,36.87319480564152,1.2871712473240926
0.004675386344110056,0.09057091418283657,529.6910542606594,36.87319480564152,1.2871712473240926
0.004692238899776115,0.09089737947589518,530.23570882377,36.87319480564152,1.2871712473240926
0.004706117475030517,0.09116623324664934,530.683675267519,36.87319480564152,1.2871712473240926
0.004730900645127662,0.09164632926585317,531.4823359739295,36.87319480564152,1.2871712473240926
0.004740813913166521,0.09183836767353472,531.801343180915,36.87319480564152,1.2871712473240926
0.00479335423377247,0.09285617123424686,533.4877578563458,36.87319480564152,1.2871712473240926
0.0048121894430463,0.09322104420884177,534.0905641767717,36.87319480564152,1.2871712473240926
0.004831024652320131,0.09358591718343669,534.692451021971,36.87319480564152,1.2871712473240926
0.004842920573966762,0.09381636327265454,535.0721185881837,36.87319480564152,1.2871712473240926
0.0048597731296328205,0.09414282856571314,535.6093589595483,36.87319480564152,1.2871712473240926
0.0048756343584949935,0.0944500900180036,536.114333614169,36.87319480564152,1.2871712473240926
0.004880590992514424,0.09454610922184438,536.2720067517224,36.87319480564152,1.2871712473240926
0.004897443548180482,0.09487257451490298,536.8076289075183,36.87319480564152,1.2871712473240926
0.0049123134502387705,0.0951606321264253,537.2796400363126,36.87319480564152,1.2871712473240926
0.004969810404864148,0.0962744548909782,539.099530771586,36.87319480564152,1.2871712473240926
0.004986662960530207,0.0966009201840368,539.631388508132,36.87319480564152,1.2871712473240926
0.005030281339901184,0.09744588917783557,541.0047165118136,36.87319480564152,1.2871712473240926
0.0050431685883517,0.09769553910782157,541.4095827033293,36.87319480564152,1.2871712473240926
0.005071917065664388,0.09825245049009802,542.3112945821993,36.87319480564152,1.2871712473240926
0.005092734928545992,0.09865573114622925,542.9630144865114,36.87319480564152,1.2871712473240926
0.005140318615132511,0.09957751550310062,544.4487710107777,36.87319480564152,1.2871712473240926
0.005158162497602456,0.09992318463692738,545.0045456050279,36.87319480564152,1.2871712473240926
0.005161136478014114,0.09998079615923185,545.0971017565083,36.87319480564152,1.2871712473240926