File: datasets/aisi_316_L/data/M1/train_52.csv
Time(s),Strain(%),Stress(MPa),Temp(C),Log_SR(s-1)
0.0,0.0,0.0,240.1971709103786,-1.3069750719995277
0.0002433079603464989,1.2e-05,2.191816125,240.1971709103786,-1.3069750719995277
0.00035685167517486506,1.76e-05,3.2146636500000003,240.1971709103786,-1.3069750719995277
0.0007299238810394967,3.6e-05,6.575448375000001,240.1971709103786,-1.3069750719995277
0.0009407907800064622,4.6399999999999996e-05,8.47502235,240.1971709103786,-1.3069750719995277
0.0011354371482836614,5.6e-05,10.22847525,240.1971709103786,-1.3069750719995277
0.0013300835165608604,6.56e-05,11.98192815,240.1971709103786,-1.3069750719995277
0.0013787451086301604,6.8e-05,12.420291375,240.1971709103786,-1.3069750719995277
0.0015571709462175929,7.68e-05,14.027623199999999,240.1971709103786,-1.3069750719995277
0.0018815815600129245,9.279999999999999e-05,16.9500447,240.1971709103786,-1.3069750719995277
0.002060007397600357,0.00010159999999999999,18.557376525,240.1971709103786,-1.3069750719995277
0.002287094827257089,0.00011279999999999999,20.603071574999998,240.1971709103786,-1.3069750719995277
0.002351976950016156,0.000116,21.187555875,240.1971709103786,-1.3069750719995277
0.0027412696865705545,0.0001352,24.694461675,240.1971709103786,-1.3069750719995277
0.0031143418924351857,0.0001536,28.055246399999998,240.1971709103786,-1.3069750719995277
0.00366583993588725,0.0001808,33.02336295,240.1971709103786,-1.3069750719995277
0.003860486304164449,0.0001904,34.77681585,240.1971709103786,-1.3069750719995277
0.004184896917959781,0.0002064,37.69923735,240.1971709103786,-1.3069750719995277
0.0043633227555472135,0.0002152,39.306569175,240.1971709103786,-1.3069750719995277
0.0045417485931346455,0.000224,40.913901,240.1971709103786,-1.3069750719995277
0.005352775127622975,0.00026399999999999997,48.21995474999999,240.1971709103786,-1.3069750719995277
0.0057745089255569065,0.0002848,52.0191027,240.1971709103786,-1.3069750719995277
0.005985375824523872,0.00029519999999999997,53.91867667499999,240.1971709103786,-1.3069750719995277
0.006471991745216871,0.0003192,58.302308925,240.1971709103786,-1.3069750719995277
0.0066017559907350035,0.0003256,59.471277525,240.1971709103786,-1.3069750719995277
0.0066828586441838355,0.0003296,60.2018829,240.1971709103786,-1.3069750719995277
0.007104592442117768,0.0003504,64.00103085,240.1971709103786,-1.3069750719995277
0.007396561994533566,0.0003648,66.6312102,240.1971709103786,-1.3069750719995277
0.007526326240051698,0.00037119999999999997,67.8001788,240.1971709103786,-1.3069750719995277
0.007574987832120998,0.0003736,68.238542025,240.1971709103786,-1.3069750719995277
0.008029162691434463,0.000396,72.329932125,240.1971709103786,-1.3069750719995277
0.008321132243850261,0.0004104,74.960111475,240.1971709103786,-1.3069750719995277
0.009197040901097657,0.00045359999999999997,82.850649525,240.1971709103786,-1.3069750719995277
0.00942412833075439,0.00046479999999999997,84.896344575,240.1971709103786,-1.3069750719995277
0.010364919110760852,0.0005112,93.37136692499999,240.1971709103786,-1.3069750719995277
0.010689329724556185,0.0005272,96.293788425,240.1971709103786,-1.3069750719995277
0.01146791519766498,0.0005656,103.307600025,240.1971709103786,-1.3069750719995277
0.011889648995598912,0.0005863999999999999,107.10674797499999,240.1971709103786,-1.3069750719995277
0.012392485446981677,0.0006112,111.6365013,240.1971709103786,-1.3069750719995277
0.012668234468707709,0.0006248,114.120559575,240.1971709103786,-1.3069750719995277
0.013657686840783471,0.0006736,123.03394515,240.1971709103786,-1.3069750719995277
0.014306508068374135,0.0007056,128.87878815,240.1971709103786,-1.3069750719995277
0.0145173749673411,0.000716,130.778362125,240.1971709103786,-1.3069750719995277
0.014582257090100165,0.0007191999999999999,131.362846425,240.1971709103786,-1.3069750719995277
0.0148093445197569,0.0007304,133.408541475,240.1971709103786,-1.3069750719995277
0.015166196194931763,0.000748,136.623205125,240.1971709103786,-1.3069750719995277
0.015717694238383827,0.0007752,141.591321675,240.1971709103786,-1.3069750719995277
0.016058325382868926,0.000792,144.65986425,240.1971709103786,-1.3069750719995277
0.01641517705804379,0.0008096,147.8745279,240.1971709103786,-1.3069750719995277
0.01660982342632099,0.0008192,149.6279808,240.1971709103786,-1.3069750719995277
0.017485732083568385,0.0008623999999999999,157.51851885,240.1971709103786,-1.3069750719995277
0.01774526057460465,0.0008751999999999999,159.85645605,240.1971709103786,-1.3069750719995277
0.017826363228053487,0.0008792,160.587061425,240.1971709103786,-1.3069750719995277
0.01865361029323158,0.0009199999999999999,168.03923625,240.1971709103786,-1.3069750719995277
0.019107785152545045,0.0009423999999999999,172.13062634999997,240.1971709103786,-1.3069750719995277
0.019432195766340376,0.0009584,175.05304784999998,240.1971709103786,-1.3069750719995277
0.01956196001185851,0.0009647999999999999,176.22201644999998,240.1971709103786,-1.3069750719995277
0.01965928319599711,0.0009695999999999999,177.0987429,240.1971709103786,-1.3069750719995277
0.02064873556807287,0.0010184,186.012128475,240.1971709103786,-1.3069750719995277
0.020956925651178435,0.0010336,188.78842889999999,240.1971709103786,-1.3069750719995277
0.02152464422532027,0.0010616,191.82481087863695,240.1971709103786,-1.3069750719995277
0.021751731654977003,0.0010728,191.89278175078326,240.1971709103786,-1.3069750719995277
0.023114256232917393,0.00114,192.29494218015267,240.1971709103786,-1.3069750719995277
0.023244020478435524,0.0011464,192.3327544044226,240.1971709103786,-1.3069750719995277
0.023438666846712725,0.001156,192.3893187436913,240.1971709103786,-1.3069750719995277
0.023633313214989925,0.0011656,192.44570017879994,240.1971709103786,-1.3069750719995277
0.02399016489016479,0.0011832,192.5485980102591,240.1971709103786,-1.3069750719995277
0.024249693381201056,0.001196,192.62305823463055,240.1971709103786,-1.3069750719995277
0.024330796034649885,0.0012,192.6462632333862,240.1971709103786,-1.3069750719995277
0.02470386824051452,0.0012184,192.7526200740847,240.1971709103786,-1.3069750719995277
0.024849853016722417,0.0012255999999999999,192.79406722424253,240.1971709103786,-1.3069750719995277
0.02489851460879172,0.001228,192.80786182443308,240.1971709103786,-1.3069750719995277
0.025012058323620082,0.0012335999999999998,192.84000840011092,240.1971709103786,-1.3069750719995277
0.025563556367072148,0.0012607999999999999,192.99534653912946,240.1971709103786,-1.3069750719995277
0.025871746450177716,0.001276,193.0815837443634,240.1971709103786,-1.3069750719995277
0.026212377594662814,0.0012928,193.1764337698858,240.1971709103786,-1.3069750719995277
0.026861198822253476,0.0013248,193.35578108062768,240.1971709103786,-1.3069750719995277
0.026974742537081844,0.0013304,193.3869923609516,240.1971709103786,-1.3069750719995277
0.02759112270329297,0.0013608,193.55553933770898,240.1971709103786,-1.3069750719995277
0.027915533317088303,0.0013767999999999999,193.64365808858065,240.1971709103786,-1.3069750719995277
0.028353487645712,0.0013984,193.76198748860412,240.1971709103786,-1.3069750719995277
0.028434590299160838,0.0014024,193.7838218934894,240.1971709103786,-1.3069750719995277
0.029132073118820802,0.0014368,193.97060563668487,240.1971709103786,-1.3069750719995277
0.029326719487098,0.0014464,194.02241900357708,240.1971709103786,-1.3069750719995277
0.029813335407790995,0.0014704,194.1513690819611,240.1971709103786,-1.3069750719995277
0.030186407613655628,0.0014888,194.24967567880856,240.1971709103786,-1.3069750719995277
0.030591920880899796,0.0015088,194.3559947841216,240.1971709103786,-1.3069750719995277
0.031500270599526724,0.0015536,194.59217503027023,240.1971709103786,-1.3069750719995277
0.03153271166090625,0.0015551999999999999,194.60056055248313,240.1971709103786,-1.3069750719995277
0.03174357855987322,0.0015655999999999999,194.65498466623097,240.1971709103786,-1.3069750719995277
0.03177601962125275,0.0015672,194.66334507587717,240.1971709103786,-1.3069750719995277
0.03211665076573785,0.001584,194.75092933804012,240.1971709103786,-1.3069750719995277
0.03239239978746389,0.0015976,194.8215658354395,240.1971709103786,-1.3069750719995277
0.032684369339879685,0.001612,194.89610229027576,240.1971709103786,-1.3069750719995277
0.033284528975401045,0.0016416,195.04850554530194,240.1971709103786,-1.3069750719995277
0.03336563162884988,0.0016455999999999999,195.0690180722938,240.1971709103786,-1.3069750719995277
0.03357649852781684,0.001656,195.12225984376522,240.1971709103786,-1.3069750719995277
0.03383602701885311,0.0016688,195.18760949923197,240.1971709103786,-1.3069750719995277
0.033949570733681475,0.0016744,195.21613847128364,240.1971709103786,-1.3069750719995277
0.03412799657126891,0.0016832,195.26089464541735,240.1971709103786,-1.3069750719995277
0.03443618665437447,0.0016983999999999999,195.33798641510649,240.1971709103786,-1.3069750719995277
0.03489036151368794,0.0017208,195.45110668995915,240.1971709103786,-1.3069750719995277
0.03576627017093534,0.001764,195.66765845043975,240.1971709103786,-1.3069750719995277
0.03581493176300463,0.0017664,195.67962809459104,240.1971709103786,-1.3069750719995277
0.035928475477833004,0.001772,195.70753262575437,240.1971709103786,-1.3069750719995277
0.036593517236113426,0.0018047999999999999,195.8702880732231,240.1971709103786,-1.3069750719995277
0.03673950201232133,0.001812,195.90586000128746,240.1971709103786,-1.3069750719995277
0.03683682519645993,0.0018168,195.92954400002918,240.1971709103786,-1.3069750719995277
0.03696658944197806,0.0018231999999999999,195.96108473882242,240.1971709103786,-1.3069750719995277
0.03740454377060176,0.0018448,196.06721738205474,240.1971709103786,-1.3069750719995277
0.03772895438439709,0.0018608,196.14552196676522,240.1971709103786,-1.3069750719995277
0.03811824712095149,0.00188,196.23914170395193,240.1971709103786,-1.3069750719995277
0.03860486304164449,0.0019039999999999999,196.35564365177822,240.1971709103786,-1.3069750719995277
0.03879950940992169,0.0019136,196.40208389896867,240.1971709103786,-1.3069750719995277
0.039156361085096555,0.0019311999999999999,196.48698904872413,240.1971709103786,-1.3069750719995277
0.03977274125130768,0.0019616,196.63293601334252,240.1971709103786,-1.3069750719995277
0.039886284966136054,0.0019672,196.65972449158636,240.1971709103786,-1.3069750719995277
0.039983608150274644,0.001972,196.6826623817899,240.1971709103786,-1.3069750719995277
0.04006471080372348,0.001976,196.7017606615846,240.1971709103786,-1.3069750719995277
0.04019447504924162,0.0019824,196.73228657782866,240.1971709103786,-1.3069750719995277
0.040810855215452746,0.0020128,196.87676305279678,240.1971709103786,-1.3069750719995277
0.04085951680752205,0.0020152,196.88813271787458,240.1971709103786,-1.3069750719995277
0.04100550158372994,0.0020223999999999997,196.9222100701301,240.1971709103786,-1.3069750719995277
0.04124880954407645,0.0020344,196.978900701325,240.1971709103786,-1.3069750719995277
0.04139479432028434,0.0020415999999999998,197.01285248511786,240.1971709103786,-1.3069750719995277
0.04155699962718201,0.0020496,197.05052196866248,240.1971709103786,-1.3069750719995277
0.04170298440338991,0.0020568,197.08437550448912,240.1971709103786,-1.3069750719995277
0.04191385130235687,0.0020672,197.13319357596194,240.1971709103786,-1.3069750719995277
0.04196251289442617,0.0020696,197.1444456711222,240.1971709103786,-1.3069750719995277
0.042011174486495474,0.002072,197.15569267854448,240.1971709103786,-1.3069750719995277
0.04212471820132384,0.0020775999999999998,197.18191595617614,240.1971709103786,-1.3069750719995277
0.042724877836845206,0.0021072,197.32006944114056,240.1971709103786,-1.3069750719995277
0.043000626858571235,0.0021208,197.38329140451302,240.1971709103786,-1.3069750719995277
0.043211493757538195,0.0021311999999999998,197.4315309836737,240.1971709103786,-1.3069750719995277
0.04343858118719494,0.0021424,197.48337874255245,240.1971709103786,-1.3069750719995277
0.044168505068234436,0.0021784,197.64932081389165,240.1971709103786,-1.3069750719995277
0.04463890045823766,0.0022015999999999997,197.75569481350342,240.1971709103786,-1.3069750719995277
0.045239060093759026,0.0022312,197.89078079833962,240.1971709103786,-1.3069750719995277
0.04564457336100319,0.0022512,197.98165967398194,240.1971709103786,-1.3069750719995277
0.04655292307963012,0.002296,198.18409343644993,240.1971709103786,-1.3069750719995277
0.04679623103997661,0.0023079999999999997,198.23805444347394,240.1971709103786,-1.3069750719995277
0.046893554224115216,0.0023128,198.25960819584282,240.1971709103786,-1.3069750719995277
0.047169303245841246,0.0023263999999999997,198.32058262517342,240.1971709103786,-1.3069750719995277
0.047234185368600315,0.0023296,198.33490932771852,240.1971709103786,-1.3069750719995277
0.04778568341205238,0.0023568,198.4563779718532,240.1971709103786,-1.3069750719995277
0.048158755617917014,0.0023752,198.5382380727117,240.1971709103786,-1.3069750719995277
0.04832096092481467,0.0023832,198.57375223989138,240.1971709103786,-1.3069750719995277
0.04846694570102258,0.0023904,198.60567525784347,240.1971709103786,-1.3069750719995277
0.04866159206929977,0.0024,198.64818100975282,240.1971709103786,-1.3069750719995277
0.04888867949895651,0.0024112,198.69768733733704,240.1971709103786,-1.3069750719995277
0.04940773648102904,0.0024368,198.81050911730486,240.1971709103786,-1.3069750719995277
0.049861911340342506,0.0024592,198.90884952314644,240.1971709103786,-1.3069750719995277
0.05012143983137877,0.002472,198.96488718671128,240.1971709103786,-1.3069750719995277
0.0506404968134513,0.0024976,199.07662417294557,240.1971709103786,-1.3069750719995277
0.05070537893621037,0.0025008,199.09055982221273,240.1971709103786,-1.3069750719995277
0.050867584243108034,0.0025088,199.12536855423926,240.1971709103786,-1.3069750719995277
0.051386641225180565,0.0025344,199.23646671464772,240.1971709103786,-1.3069750719995277
0.051548846532078224,0.0025423999999999998,199.27109502245023,240.1971709103786,-1.3069750719995277
0.052213888290358654,0.0025751999999999997,199.41262905805354,240.1971709103786,-1.3069750719995277
0.05252207837346423,0.0025904,199.4779794403008,240.1971709103786,-1.3069750719995277
0.05302491482484699,0.0026152,199.58428360223263,240.1971709103786,-1.3069750719995277
0.053235781723813956,0.0026256,199.62874567869892,240.1971709103786,-1.3069750719995277
0.05394948507416369,0.0026608,199.77872566204485,240.1971709103786,-1.3069750719995277
0.05443610099485668,0.0026847999999999998,199.88054135468184,240.1971709103786,-1.3069750719995277
0.05497137850761898,0.0027112,199.99212951436985,240.1971709103786,-1.3069750719995277
0.05508492222244734,0.0027167999999999997,200.0157451607833,240.1971709103786,-1.3069750719995277
0.05518224540658594,0.0027216,200.03597203746327,240.1971709103786,-1.3069750719995277
0.05553909708176081,0.0027392,200.11001852051308,240.1971709103786,-1.3069750719995277
0.055685081857968714,0.0027464,200.14025675683985,240.1971709103786,-1.3069750719995277
0.056415005739008206,0.0027824,200.29098666251156,240.1971709103786,-1.3069750719995277
0.05667453423004447,0.0027952,200.34439597775008,240.1971709103786,-1.3069750719995277
0.056755636883493304,0.0027992,200.36106681633873,240.1971709103786,-1.3069750719995277
0.0570476064359091,0.0028136,200.42100506170257,240.1971709103786,-1.3069750719995277
0.05784241243970767,0.0028528,200.5835672107098,240.1971709103786,-1.3069750719995277
0.057955956154536026,0.0028583999999999997,200.60671906054793,240.1971709103786,-1.3069750719995277
0.05810194093074393,0.0028656,200.6364597485408,240.1971709103786,-1.3069750719995277
0.058410131013849495,0.0028807999999999998,200.69915011171548,240.1971709103786,-1.3069750719995277
0.0586047773821267,0.0028904,200.73867756726895,240.1971709103786,-1.3069750719995277
0.05920493701764806,0.00292,200.860232806773,240.1971709103786,-1.3069750719995277
0.05954556816213316,0.0029368,200.9290098271713,240.1971709103786,-1.3069750719995277
0.05990241983730802,0.0029544,201.0008975712394,240.1971709103786,-1.3069750719995277
0.06019438938972382,0.0029687999999999997,201.05959066947966,240.1971709103786,-1.3069750719995277
0.06051880000351915,0.0029847999999999997,201.12467515971284,240.1971709103786,-1.3069750719995277
0.06089187220938378,0.0030031999999999997,201.19935435007585,240.1971709103786,-1.3069750719995277
0.06113518016973029,0.0030152,201.24796205313697,240.1971709103786,-1.3069750719995277
0.06136226759938702,0.0030264,201.29326121806238,240.1971709103786,-1.3069750719995277
0.061848883520080014,0.0030504,201.39011128653473,240.1971709103786,-1.3069750719995277
0.061897545112149316,0.0030528,201.399779919835,240.1971709103786,-1.3069750719995277
0.06210841201111628,0.0030632,201.44164312180683,240.1971709103786,-1.3069750719995277
0.06222195572594465,0.0030688,201.46416188473756,240.1971709103786,-1.3069750719995277
0.06248148421698091,0.0030816,201.51557324972654,240.1971709103786,-1.3069750719995277
0.06253014580905021,0.003084,201.52520360189277,240.1971709103786,-1.3069750719995277
0.06262746899318881,0.0030888,201.54445554222104,240.1971709103786,-1.3069750719995277
0.06296810013767391,0.0031056,201.61174564171435,240.1971709103786,-1.3069750719995277
0.06324384915939994,0.0031192,201.66611466045904,240.1971709103786,-1.3069750719995277
0.0634547160583669,0.0031295999999999997,201.70762861165665,240.1971709103786,-1.3069750719995277
0.06403865516319851,0.0031584,201.82231047194452,240.1971709103786,-1.3069750719995277
0.0643306247156143,0.0031728,201.87949841135398,240.1971709103786,-1.3069750719995277
0.06449283002251197,0.0031807999999999997,201.91122574722525,240.1971709103786,-1.3069750719995277
0.0648172406363073,0.0031967999999999996,201.97458721041016,240.1971709103786,-1.3069750719995277
0.06499566647389474,0.0032056,202.00938329347312,240.1971709103786,-1.3069750719995277
0.06532007708769007,0.0032216,202.07255360582957,240.1971709103786,-1.3069750719995277
0.06614732415286817,0.0032624,202.2330865794755,240.1971709103786,-1.3069750719995277
0.06645551423597373,0.0032776,202.2926925528112,240.1971709103786,-1.3069750719995277
0.06660149901218163,0.0032848,202.32088932511925,240.1971709103786,-1.3069750719995277
0.06712055599425415,0.0033104,202.4209498909198,240.1971709103786,-1.3069750719995277
0.06736386395460066,0.0033223999999999997,202.4677493559653,240.1971709103786,-1.3069750719995277
0.06759095138425739,0.0033336,202.51136941487044,240.1971709103786,-1.3069750719995277
0.06776937722184481,0.0033423999999999997,202.5456022350287,240.1971709103786,-1.3069750719995277
0.06806134677426062,0.0033568,202.6015438540871,240.1971709103786,-1.3069750719995277
0.06814244942770945,0.0033607999999999997,202.61706657312138,240.1971709103786,-1.3069750719995277
0.06836953685736619,0.003372,202.66049190127686,240.1971709103786,-1.3069750719995277
0.06869394747116152,0.003388,202.72243063140567,240.1971709103786,-1.3069750719995277
0.06893725543150801,0.0034,202.76880984278014,240.1971709103786,-1.3069750719995277
0.06913190179978522,0.0034096,202.8058672638615,240.1971709103786,-1.3069750719995277
0.06965095878185774,0.0034352,202.90448865464938,240.1971709103786,-1.3069750719995277
0.06984560515013495,0.0034448,202.94139772654145,240.1971709103786,-1.3069750719995277
0.07049442637772561,0.0034768,203.06413927249758,240.1971709103786,-1.3069750719995277
0.07062419062324374,0.0034831999999999997,203.0886346259168,240.1971709103786,-1.3069750719995277
0.07078639593014141,0.0034912,203.119229147938,240.1971709103786,-1.3069750719995277
0.07231112581497946,0.0035664,203.4054935569791,240.1971709103786,-1.3069750719995277
0.0726841980208441,0.0035848,203.47517732213404,240.1971709103786,-1.3069750719995277
0.07292750598119059,0.0035968,203.52054811711506,240.1971709103786,-1.3069750719995277
0.07328435765636546,0.0036144,203.58698530885388,240.1971709103786,-1.3069750719995277
0.07344656296326313,0.0036224,203.6171423118133,240.1971709103786,-1.3069750719995277
0.07362498880085055,0.0036312,203.65028503052946,240.1971709103786,-1.3069750719995277
0.07386829676119705,0.0036431999999999997,203.69542920955314,240.1971709103786,-1.3069750719995277
0.07458200011154678,0.0036783999999999996,203.8275187828329,240.1971709103786,-1.3069750719995277
0.07489019019465236,0.0036936,203.8844049644532,240.1971709103786,-1.3069750719995277
0.07534436505396581,0.0037159999999999997,203.96807110296993,240.1971709103786,-1.3069750719995277
0.07573365779052021,0.0037351999999999997,204.03962850577298,240.1971709103786,-1.3069750719995277
0.07596074522017696,0.0037464,204.08130407760643,240.1971709103786,-1.3069750719995277
0.07599318628155649,0.003748,204.08725376176506,240.1971709103786,-1.3069750719995277
0.07618783264983368,0.0037576,204.12293108731592,240.1971709103786,-1.3069750719995277
0.07651224326362902,0.0037736,204.1823144019636,240.1971709103786,-1.3069750719995277
0.07696641812294248,0.003796,204.2652863382331,240.1971709103786,-1.3069750719995277
0.07724216714466851,0.0038096,204.31556900265636,240.1971709103786,-1.3069750719995277
0.07740437245156619,0.0038176,204.34511433869082,240.1971709103786,-1.3069750719995277
0.07751791616639454,0.0038231999999999997,204.36578170846053,240.1971709103786,-1.3069750719995277
0.07774500359605127,0.0038344,204.40708106343152,240.1971709103786,-1.3069750719995277
0.0777774446574308,0.003836,204.4129771284723,240.1971709103786,-1.3069750719995277
0.07798831155639778,0.0038464,204.4512781996472,240.1971709103786,-1.3069750719995277
0.07815051686329544,0.0038544,204.4807130855136,240.1971709103786,-1.3069750719995277
0.07839382482364193,0.0038664,204.52482077910506,240.1971709103786,-1.3069750719995277
0.07858847119191914,0.0038759999999999997,204.5600685059026,240.1971709103786,-1.3069750719995277
0.07871823543743726,0.0038824,204.58354807713002,240.1971709103786,-1.3069750719995277
0.07886422021364517,0.0038896,204.60994455897193,240.1971709103786,-1.3069750719995277
0.0790426460512326,0.0038983999999999998,204.6421810610092,240.1971709103786,-1.3069750719995277
0.07925351295019957,0.0039088,204.68024217945504,240.1971709103786,-1.3069750719995277
0.0794806003798563,0.00392,204.72118693492104,240.1971709103786,-1.3069750719995277
0.08003209842330836,0.0039472,204.8204347157444,240.1971709103786,-1.3069750719995277
0.08038895009848324,0.0039648,204.88451176723595,240.1971709103786,-1.3069750719995277
0.08074580177365809,0.0039824,204.9484779818368,240.1971709103786,-1.3069750719995277
0.09200503054777591,0.004537707541508302,206.91341319488836,240.1971709103786,-1.3069750719995277
0.10057118398265964,0.004960192038407682,208.346046435778,240.1971709103786,-1.3069750719995277
0.10796922558551379,0.005325065013002601,209.54540350377107,240.1971709103786,-1.3069750719995277
0.12120782634851592,0.005977995599119824,211.61446285937816,240.1971709103786,-1.3069750719995277
0.1348357977221946,0.006650130026005201,213.65416405923315,240.1971709103786,-1.3069750719995277
0.13989761566098954,0.0068997799559911985,214.3910679955431,240.1971709103786,-1.3069750719995277
0.14846376909587325,0.007322264452890578,215.61487103924983,240.1971709103786,-1.3069750719995277
0.1539149576453447,0.007591118223644729,216.3793323114359,240.1971709103786,-1.3069750719995277
0.1617023698588754,0.007975195039007801,217.4533485368061,240.1971709103786,-1.3069750719995277
0.16715355840834686,0.008244048809761952,218.19318594303553,240.1971709103786,-1.3069750719995277
0.1733834881791714,0.00855131026205241,219.02728704488905,240.1971709103786,-1.3069750719995277
0.18350712405676128,0.009050610122024405,220.3581885374207,240.1971709103786,-1.3069750719995277
0.18623271833149702,0.00918503700740148,220.7115753303376,240.1971709103786,-1.3069750719995277
0.19791383665179302,0.00976115223044609,222.20379727100865,240.1971709103786,-1.3069750719995277
0.1998606897051757,0.009857171434286858,222.4491224969797,240.1971709103786,-1.3069750719995277
0.209594954972089,0.010337267453490697,223.66203980784243,240.1971709103786,-1.3069750719995277
0.2138780316895309,0.010548509701940389,224.1887410615544,240.1971709103786,-1.3069750719995277
0.22516977939915034,0.011105421084216843,225.55796357255014,240.1971709103786,-1.3069750719995277
0.23490404466606374,0.011585517103420685,226.71696647346243,240.1971709103786,-1.3069750719995277
0.2419127156582413,0.011931186237247449,227.53987881200976,240.1971709103786,-1.3069750719995277
0.2477532748183893,0.012219243848769754,228.21855958391362,240.1971709103786,-1.3069750719995277
0.2606025049707149,0.012852970594118824,229.69006974788567,240.1971709103786,-1.3069750719995277
0.26644306413086294,0.013141028205641128,230.34955482608632,240.1971709103786,-1.3069750719995277
0.27072614084830476,0.013352270454090818,230.82959935950294,240.1971709103786,-1.3069750719995277
0.27695607061912936,0.013659531906381276,231.52259192063556,240.1971709103786,-1.3069750719995277
0.28669033588604265,0.014139627925585117,232.59334359960948,240.1971709103786,-1.3069750719995277
0.3034332721451336,0.014965393078615724,234.40244106491923,240.1971709103786,-1.3069750719995277
0.3123887961906939,0.015407081416283257,235.3540932927133,240.1971709103786,-1.3069750719995277
0.3147250198547531,0.01552230446089218,235.6005929907365,240.1971709103786,-1.3069750719995277
0.3221230614576073,0.0158871774354871,236.37650879405595,240.1971709103786,-1.3069750719995277
0.3306892148924909,0.016309661932386477,237.26630730779112,240.1971709103786,-1.3069750719995277
0.3412022213807574,0.016828165633126627,238.3461398237583,240.1971709103786,-1.3069750719995277
0.34782152176225845,0.017154630926185237,239.01938134117395,240.1971709103786,-1.3069750719995277
0.35444082214375944,0.017481096219243847,239.68764420759544,240.1971709103786,-1.3069750719995277
0.3602813813039075,0.017769153830766153,240.2732562825384,240.1971709103786,-1.3069750719995277
0.3653431992427024,0.01801880376075215,240.77779821666186,240.1971709103786,-1.3069750719995277
0.3696262759601443,0.01823004600920184,241.20259250657435,240.1971709103786,-1.3069750719995277
0.37585620573096884,0.0185373074614923,241.81706408654682,240.1971709103786,-1.3069750719995277
0.3887054358832944,0.019171034206841367,243.07200658525392,240.1971709103786,-1.3069750719995277
0.39532473626479553,0.01949749949989998,243.7121711283262,240.1971709103786,-1.3069750719995277
0.4031121484783262,0.019881576315263053,244.4599782180675,240.1971709103786,-1.3069750719995277
0.40700585458509153,0.02007361472294459,244.8317674064778,240.1971709103786,-1.3069750719995277
0.41907634351606404,0.02066893378675735,245.97559529133616,240.1971709103786,-1.3069750719995277
0.42374879084418243,0.020899379875975194,246.41490875760894,240.1971709103786,-1.3069750719995277
0.42997872061500697,0.021206641328265653,246.9977324992989,240.1971709103786,-1.3069750719995277
0.4362086503858315,0.02151390278055611,247.577272040315,240.1971709103786,-1.3069750719995277
0.44049172710327344,0.021725145029005802,247.97383425992476,240.1971709103786,-1.3069750719995277
0.44750039809545106,0.022070814162832568,248.61952576895803,240.1971709103786,-1.3069750719995277
0.45606655153033476,0.022493298659731948,249.40337287025125,240.1971709103786,-1.3069750719995277
0.46424333435454196,0.022896579315863173,250.14625135209442,240.1971709103786,-1.3069750719995277
0.46696892862927775,0.02303100620124025,250.39274121821248,240.1971709103786,-1.3069750719995277
0.4693051522933369,0.02314622924584917,250.60357199303897,240.1971709103786,-1.3069750719995277
0.4813756412243094,0.023741548309661933,251.68641166685043,240.1971709103786,-1.3069750719995277
0.48877368282716355,0.02410642128425685,252.3448551670998,240.1971709103786,-1.3069750719995277
0.5000654305367831,0.024663332666533307,253.34240315509822,240.1971709103786,-1.3069750719995277
0.5113571782464025,0.02522024404880976,254.33120400928752,240.1971709103786,-1.3069750719995277
0.5179764786279036,0.025546709341868375,254.90688689268057,240.1971709103786,-1.3069750719995277
0.5234276671773751,0.025815563112622526,255.37882740909598,240.1971709103786,-1.3069750719995277
0.5308257087802292,0.026180436087217443,256.0162635212127,240.1971709103786,-1.3069750719995277
0.5409493446578191,0.026679735947189438,256.88295815623775,240.1971709103786,-1.3069750719995277
0.5436749389325548,0.026814162832566515,257.11521527389976,240.1971709103786,-1.3069750719995277
0.5565241690848804,0.027447889577915583,258.2040831119471,240.1971709103786,-1.3069750719995277
0.5596391339702926,0.027601520304060812,258.46656911788585,240.1971709103786,-1.3069750719995277
0.568594658015853,0.028043208641728348,259.2180610779284,240.1971709103786,-1.3069750719995277
0.5767714408400602,0.028446489297859572,259.90018407021927,240.1971709103786,-1.3069750719995277
0.6005230480913286,0.029617923584716942,261.86051907691484,240.1971709103786,-1.3069750719995277
0.6079210896941828,0.029982796559311863,262.4649078468105,240.1971709103786,-1.3069750719995277
0.6137616488543308,0.030270854170834166,262.9400330252166,240.1971709103786,-1.3069750719995277
0.6215490610678615,0.03065493098619724,263.57079937276796,240.1971709103786,-1.3069750719995277
0.6293364732813922,0.03103900780156031,264.1984910128926,240.1971709103786,-1.3069750719995277
0.6347876618308637,0.031307861572314466,264.6360740253906,240.1971709103786,-1.3069750719995277
0.6406282209910116,0.031595919183836765,265.10328985893324,240.1971709103786,-1.3069750719995277
0.6449112977084535,0.03180716143228646,265.4448596726049,240.1971709103786,-1.3069750719995277
0.6491943744258954,0.03201840368073615,265.7855459152796,240.1971709103786,-1.3069750719995277
0.6530880805326607,0.03221044208841768,266.0945007582719,240.1971709103786,-1.3069750719995277
0.6651585694636333,0.032805761152230446,267.04772693579883,240.1971709103786,-1.3069750719995277
0.6713884992344578,0.033113022604520904,267.53707362593394,240.1971709103786,-1.3069750719995277
0.6756715759518997,0.033324264852970596,267.8724726898611,240.1971709103786,-1.3069750719995277
0.6912464003789609,0.034092418483696735,269.0851778033123,240.1971709103786,-1.3069750719995277
0.7009806656458744,0.03457251450290058,269.8377092954721,240.1971709103786,-1.3069750719995277
0.7126617839661704,0.035148629725945194,270.7353885300937,240.1971709103786,-1.3069750719995277
0.7200598255690246,0.035513502700540114,271.30095183188826,240.1971709103786,-1.3069750719995277
0.7282366083932318,0.03591678335667134,271.9234180919228,240.1971709103786,-1.3069750719995277
0.737192132438792,0.03635847169433887,272.6020476115468,240.1971709103786,-1.3069750719995277
0.7586075160260012,0.03741468293658731,274.2119508615174,240.1971709103786,-1.3069750719995277
0.7640587045754728,0.03768353670734147,274.6189021059785,240.1971709103786,-1.3069750719995277
0.7714567461783269,0.03804840968193639,275.169386558872,240.1971709103786,-1.3069750719995277
0.7757398228957688,0.03825965193038608,275.4871470688466,240.1971709103786,-1.3069750719995277
0.7800228996132107,0.03847089417883577,275.8042240773832,240.1971709103786,-1.3069750719995277
0.7866421999947116,0.038797359471894374,276.29291986603687,240.1971709103786,-1.3069750719995277
0.7924827591548598,0.03908541708341669,276.7227917513769,240.1971709103786,-1.3069750719995277
0.8033851362538026,0.03962312462492498,277.5219278284324,240.1971709103786,-1.3069750719995277
0.8057213599178619,0.03973834766953391,277.6926197416334,240.1971709103786,-1.3069750719995277
0.8088363248032742,0.03989197839567914,277.9199090058716,240.1971709103786,-1.3069750719995277
0.8146768839634221,0.040180036007201436,278.3451583721583,240.1971709103786,-1.3069750719995277
0.8216855549555999,0.04052570514102821,278.8538913600349,240.1971709103786,-1.3069750719995277
0.8248005198410121,0.04067933586717344,279.0794514004589,240.1971709103786,-1.3069750719995277
0.8290835965584538,0.04089057811562312,279.38905474889674,240.1971709103786,-1.3069750719995277
0.8325879320545426,0.04106341268253651,279.64190287815586,240.1971709103786,-1.3069750719995277
0.8427115679321324,0.0415627125425085,280.37003200197137,240.1971709103786,-1.3069750719995277
0.8594545041912235,0.042388477695539106,281.5668033411709,240.1971709103786,-1.3069750719995277
0.865684433962048,0.042695739147829564,282.00978810024867,240.1971709103786,-1.3069750719995277
0.877365552282344,0.04327185437087418,282.83704778314797,240.1971709103786,-1.3069750719995277
0.8797017759464033,0.0433870774154831,283.00198304828723,240.1971709103786,-1.3069750719995277
0.8824273702211389,0.04352150430086017,283.19419177329604,240.1971709103786,-1.3069750719995277
0.8874891881599338,0.04377115423084617,283.55053767200957,240.1971709103786,-1.3069750719995277
0.8929403767094054,0.04404000800160032,283.93340950110036,240.1971709103786,-1.3069750719995277
0.896444712205494,0.0442128425685137,284.17906011452214,240.1971709103786,-1.3069750719995277
0.9065683480830842,0.0447121424284857,284.88662244750134,240.1971709103786,-1.3069750719995277
0.9104620541898494,0.044904180836167235,285.1579404462611,240.1971709103786,-1.3069750719995277
0.9147451309072913,0.045115423084616926,285.4558681130952,240.1971709103786,-1.3069750719995277
0.9213644312887922,0.04544188837767553,285.91523391540903,240.1971709103786,-1.3069750719995277
0.9322668083877352,0.04597959591918384,286.6690405691993,240.1971709103786,-1.3069750719995277
0.9373286263265301,0.046229245849169834,287.01785282937124,240.1971709103786,-1.3069750719995277
0.9408329618226191,0.04640208041608322,287.2589080126986,240.1971709103786,-1.3069750719995277
0.9497884858681792,0.04684376875375075,287.87335244120567,240.1971709103786,-1.3069750719995277
0.9595227511350927,0.047323864772954596,288.5386696930551,240.1971709103786,-1.3069750719995277
0.9603014923564457,0.0473622724544909,288.59178108807055,240.1971709103786,-1.3069750719995277
0.9692570164020059,0.04780396079215843,289.2013597559187,240.1971709103786,-1.3069750719995277
0.9715932400660652,0.047919183836767354,289.3600185307411,240.1971709103786,-1.3069750719995277
0.9895042881571857,0.048802560512102425,290.57149811642034,240.1971709103786,-1.3069750719995277
0.999238553424099,0.04928265653130626,291.22632268241773,240.1971709103786,-1.3069750719995277
1.0031322595308645,0.049474694938987804,291.4875553416827,240.1971709103786,-1.3069750719995277
1.016760230904543,0.05014682936587317,292.3987716665811,240.1971709103786,-1.3069750719995277
1.021043307621985,0.05035807161432286,292.6841685572708,240.1971709103786,-1.3069750719995277
1.0358393908276933,0.0510878175635127,293.6665125479768,240.1971709103786,-1.3069750719995277
1.0412905793771647,0.05135667133426686,294.02704731785417,240.1971709103786,-1.3069750719995277
1.0498567328120485,0.05177915583116624,294.5921183118336,240.1971709103786,-1.3069750719995277
1.051803585865431,0.05187517503500701,294.72029242875647,240.1971709103786,-1.3069750719995277
1.0669890396818158,0.05262412482496499,295.71689454844187,240.1971709103786,-1.3069750719995277
1.0759445637273761,0.05306581316263252,296.3020413061172,240.1971709103786,-1.3069750719995277
1.084121346551583,0.05346909381876375,296.8346489638138,240.1971709103786,-1.3069750719995277
1.0899619057117313,0.05375715143028606,297.21412426665603,240.1971709103786,-1.3069750719995277
1.1028111358640569,0.05439087817563512,298.04618960585685,240.1971709103786,-1.3069750719995277
1.1074835831921754,0.05462132426485297,298.3478202970728,240.1971709103786,-1.3069750719995277
1.109430436245558,0.05471734346869374,298.4733532265171,240.1971709103786,-1.3069750719995277
1.1191647015124715,0.055197439487897584,299.09973379714665,240.1971709103786,-1.3069750719995277
1.1316245610541205,0.0558119623924785,299.8984091379769,240.1971709103786,-1.3069750719995277
1.1355182671608859,0.056004000800160034,300.14729087693655,240.1971709103786,-1.3069750719995277
1.1464206442598286,0.05654170834166833,300.8423952840881,240.1971709103786,-1.3069750719995277
1.156154909526742,0.057021804360872175,301.4608486728605,240.1971709103786,-1.3069750719995277
1.1581017625801246,0.05711782356471294,301.5842952970418,240.1971709103786,-1.3069750719995277
1.1623848392975666,0.05732906581316263,301.8555933418512,240.1971709103786,-1.3069750719995277
1.1697828809004207,0.057693938787757554,302.3232825643961,240.1971709103786,-1.3069750719995277
1.1810746286100402,0.05825085017003401,303.03490613451197,240.1971709103786,-1.3069750719995277
1.1830214816634228,0.058346869373874774,303.1573311905137,240.1971709103786,-1.3069750719995277
1.184578964106129,0.058423684736947396,303.2552146719806,240.1971709103786,-1.3069750719995277
1.1888620408235708,0.05863492698539707,303.5241357858065,240.1971709103786,-1.3069750719995277
1.1923663763196597,0.05880776155231046,303.74388122131876,240.1971709103786,-1.3069750719995277
1.195481341205072,0.05896139227845569,303.9389991378167,240.1971709103786,-1.3069750719995277
1.1989856767011609,0.05913422684536908,304.15826994676974,240.1971709103786,-1.3069750719995277
1.2165073541816047,0.05999839967993599,305.25089713081036,240.1971709103786,-1.3069750719995277
1.226241619448518,0.06047849569913982,305.85525970853126,240.1971709103786,-1.3069750719995277
1.2375333671581377,0.06103540708141629,306.55398119148765,240.1971709103786,-1.3069750719995277
1.2425951850969326,0.061285057011402286,306.8663935901392,240.1971709103786,-1.3069750719995277
1.2445420381503152,0.06138107621524305,306.98641999762543,240.1971709103786,-1.3069750719995277
1.2484357442570806,0.061573114622924585,307.22625336051414,240.1971709103786,-1.3069750719995277
1.253108191585199,0.061803560712142436,307.5136686655027,240.1971709103786,-1.3069750719995277
1.2620637156307593,0.062245249049809964,308.06338244227544,240.1971709103786,-1.3069750719995277
1.267904274790907,0.06253330666133226,308.42107202197155,240.1971709103786,-1.3069750719995277
1.2854259522713511,0.06339747949589918,309.4903049315905,240.1971709103786,-1.3069750719995277
1.2920452526528523,0.06372394478895779,309.89275617177265,240.1971709103786,-1.3069750719995277
1.2990539236450298,0.06406961392278455,310.31800556102576,240.1971709103786,-1.3069750719995277
1.3025582591411187,0.06424244848969794,310.53029464528515,240.1971709103786,-1.3069750719995277
1.312292524408032,0.06472254450890177,311.11882102982344,240.1971709103786,-1.3069750719995277
1.317354342346827,0.06497219443888778,311.42418175616507,240.1971709103786,-1.3069750719995277
1.3255311251710342,0.06537547509501901,311.91649191449517,240.1971709103786,-1.3069750719995277
1.3344866492165943,0.06581716343268654,312.45433178194105,240.1971709103786,-1.3069750719995277
1.3403272083767424,0.06610522104420884,312.80433870644305,240.1971709103786,-1.3069750719995277
1.352397697307715,0.06670054010802161,313.5258070629567,240.1971709103786,-1.3069750719995277
1.3644681862386874,0.06729585917183437,314.24476842384826,240.1971709103786,-1.3069750719995277
1.3687512629561294,0.06750710142028406,314.4992869537322,240.1971709103786,-1.3069750719995277
1.382379234329808,0.06817923584716944,315.30705993592954,240.1971709103786,-1.3069750719995277
1.3897772759326623,0.06854410882176436,315.74426445265226,240.1971709103786,-1.3069750719995277
1.3956178350928101,0.06883216643328666,316.08878510158434,240.1971709103786,-1.3069750719995277
1.3987327999782224,0.06898579715943189,316.27229950874255,240.1971709103786,-1.3069750719995277
1.402626506084988,0.06917783556711343,316.50146853436456,240.1971709103786,-1.3069750719995277
1.4065202121917533,0.06936987397479497,316.7303895853593,240.1971709103786,-1.3069750719995277
1.4236525190615206,0.07021484296859372,317.73472030653437,240.1971709103786,-1.3069750719995277
1.451687203030231,0.07159751950390078,319.368062319669,240.1971709103786,-1.3069750719995277
1.4625895801291742,0.07213522704540909,319.9999228830375,240.1971709103786,-1.3069750719995277
1.4688195098999985,0.07244248849769955,320.3601613058899,240.1971709103786,-1.3069750719995277
1.4699876217320282,0.07250010002000401,320.4276396191717,240.1971709103786,-1.3069750719995277
1.4789431457775883,0.07294178835767154,320.94428041123473,240.1971709103786,-1.3069750719995277
1.4836155931057067,0.07317223444688938,321.21334770202253,240.1971709103786,-1.3069750719995277
1.4906242640978844,0.07351790358071615,321.6163298131383,240.1971709103786,-1.3069750719995277
1.4949073408153264,0.07372914582916584,321.86223290758727,240.1971709103786,-1.3069750719995277
1.501916011807504,0.0740748149629926,322.26402793158,240.1971709103786,-1.3069750719995277
1.5120396476850937,0.0745741148229646,322.8431099723352,240.1971709103786,-1.3069750719995277
1.5198270598986245,0.07495819163832768,323.28752935771047,240.1971709103786,-1.3069750719995277
1.5291719545548614,0.07541908381676336,323.8196620608249,240.1971709103786,-1.3069750719995277
1.5365699961577153,0.07578395679135827,324.24003487996197,240.1971709103786,-1.3069750719995277
1.5431892965392164,0.07611042208441689,324.61548931705283,240.1971709103786,-1.3069750719995277
1.5455255202032756,0.07622564512902581,324.74785262335706,240.1971709103786,-1.3069750719995277
1.5513660793634236,0.07651370274054811,325.078419959106,240.1971709103786,-1.3069750719995277
1.5653834213477789,0.07720504100820165,325.8698075469542,240.1971709103786,-1.3069750719995277
1.582905098828223,0.07806921384276856,326.85516622239146,240.1971709103786,-1.3069750719995277
1.5914712522631065,0.07849169833966793,327.33534821027604,240.1971709103786,-1.3069750719995277
1.5957543289805485,0.07870294058811762,327.5750611310273,240.1971709103786,-1.3069750719995277
1.6019842587513728,0.07901020204040808,327.92328702227553,240.1971709103786,-1.3069750719995277
1.605488594247462,0.07918303660732147,328.11893198515367,240.1971709103786,-1.3069750719995277
1.6097716709649037,0.07939427885577116,328.3578275809097,240.1971709103786,-1.3069750719995277
1.6163909713464046,0.07972074414882976,328.726542853102,240.1971709103786,-1.3069750719995277
1.6241783835599355,0.08010482096419284,329.15957245694887,240.1971709103786,-1.3069750719995277
1.6327445369948193,0.08052730546109223,329.6349708565287,240.1971709103786,-1.3069750719995277
1.6510449556966162,0.08142988597719544,330.64734812855374,240.1971709103786,-1.3069750719995277
1.6553280324140582,0.08164112822564513,330.8836543806847,240.1971709103786,-1.3069750719995277
1.666230409513001,0.08217883576715343,331.4840877140228,240.1971709103786,-1.3069750719995277
1.6744071923372084,0.08258211642328467,331.93340772196905,240.1971709103786,-1.3069750719995277
1.6833627163827685,0.0830238047609522,332.4245393827971,240.1971709103786,-1.3069750719995277
1.6977694289778003,0.08373434686937388,333.21248796883236,240.1971709103786,-1.3069750719995277
1.7075036942447137,0.08421444288857773,333.74341000223677,240.1971709103786,-1.3069750719995277
1.715680477068921,0.08461772354470895,334.18847290449173,240.1971709103786,-1.3069750719995277
1.7242466305038044,0.08504020804160832,334.653842923717,240.1971709103786,-1.3069750719995277
1.7308659308853056,0.08536667333466694,335.0128297302526,240.1971709103786,-1.3069750719995277
1.7394320843201894,0.08578915783156632,335.47660710660034,240.1971709103786,-1.3069750719995277
1.7483876083657495,0.08623084616923385,335.96051388465514,240.1971709103786,-1.3069750719995277
1.7577325030219864,0.08669173834766954,336.46443058651124,240.1971709103786,-1.3069750719995277
1.7635730621821346,0.08697979595919185,336.77884800628215,240.1971709103786,-1.3069750719995277
1.766688027067547,0.08713342668533708,336.9463712354821,240.1971709103786,-1.3069750719995277
1.7698029919529592,0.08728705741148231,337.1137793093925,240.1971709103786,-1.3069750719995277
1.7775904041664896,0.08767113422684537,337.53179753506333,240.1971709103786,-1.3069750719995277
1.7810947396625785,0.08784396879375876,337.7196726665366,240.1971709103786,-1.3069750719995277
1.7927758579828743,0.08842008401680336,338.344884534318,240.1971709103786,-1.3069750719995277
1.7962801934789632,0.08859291858371675,338.5321380297647,240.1971709103786,-1.3069750719995277
1.8130231297380541,0.08941868373674736,339.4248345907461,240.1971709103786,-1.3069750719995277
1.8141912415700838,0.08947629525905182,339.4869955033883,240.1971709103786,-1.3069750719995277
1.8211999125622613,0.08982196439287858,339.8596337128957,240.1971709103786,-1.3069750719995277
1.826651101111733,0.09009081816363274,340.1490769040704,240.1971709103786,-1.3069750719995277
1.8375534782106757,0.09062852570514103,340.72695465130164,240.1971709103786,-1.3069750719995277
1.8546857850804435,0.0914734946989398,341.63235397480025,240.1971709103786,-1.3069750719995277
1.8628625679046504,0.09187677535507102,342.0633260003194,240.1971709103786,-1.3069750719995277
1.874933056835623,0.09247209441888378,342.69817686947806,240.1971709103786,-1.3069750719995277
1.8940122167587732,0.09341308261652331,343.6984095308864,240.1971709103786,-1.3069750719995277
1.9080295587431284,0.09410442088417684,344.4307720834412,240.1971709103786,-1.3069750719995277
1.9154276003459825,0.09446929385877176,344.8164506455007,240.1971709103786,-1.3069750719995277
1.9204894182847774,0.09471894378875775,345.08000130767033,240.1971709103786,-1.3069750719995277
1.9259406068342488,0.09498779755951191,345.36352231218063,240.1971709103786,-1.3069750719995277
1.9302236835516908,0.0951990398079616,345.58606931918996,240.1971709103786,-1.3069750719995277
1.945798507978752,0.09596719343868775,346.3937127518907,240.1971709103786,-1.3069750719995277
1.9520284377495767,0.0962744548909782,346.7160637115706,240.1971709103786,-1.3069750719995277
1.956700885077695,0.09650490098019604,346.9575636919732,240.1971709103786,-1.3069750719995277
1.9707182270620502,0.09719623924784958,347.68071779377806,240.1971709103786,-1.3069750719995277
1.982399345382346,0.09777235447089418,348.281815101317,240.1971709103786,-1.3069750719995277
1.9960273167560247,0.09844448889777956,348.9813522075354,240.1971709103786,-1.3069750719995277
2.0010891346948196,0.09869413882776555,349.2407055463417,240.1971709103786,-1.3069750719995277
2.006150952633615,0.09894378875775156,349.4998031544357,240.1971709103786,-1.3069750719995277
2.0217257770606762,0.0997119423884777,350.29543205824035,240.1971709103786,-1.3069750719995277