File: datasets/aisi_316_L/data/M1/train_33.csv
Time(s),Strain(%),Stress(MPa),Temp(C),Log_SR(s-1)
0.0,0.0,0.0,36.89949706798892,1.2653222797841366
3.9085009031513214e-07,7.2e-06,1.40736375,36.89949706798892,1.2653222797841366
7.817001806302643e-07,1.44e-05,2.8147275,36.89949706798892,1.2653222797841366
1.4765447856349434e-06,2.7199999999999997e-05,5.3167075,36.89949706798892,1.2653222797841366
1.9542504515756605e-06,3.6e-05,7.03681875,36.89949706798892,1.2653222797841366
2.388528329703585e-06,4.4e-05,8.60055625,36.89949706798892,1.2653222797841366
2.866233995644302e-06,5.2799999999999996e-05,10.320667499999999,36.89949706798892,1.2653222797841366
3.5176508128361893e-06,6.48e-05,12.66627375,36.89949706798892,1.2653222797841366
5.081051174096717e-06,9.36e-05,18.29572875,36.89949706798892,1.2653222797841366
5.732467991288604e-06,0.00010559999999999999,20.641334999999998,36.89949706798892,1.2653222797841366
5.906179142539774e-06,0.00010879999999999999,21.26683,36.89949706798892,1.2653222797841366
6.210173657229321e-06,0.00011439999999999999,22.361446249999997,36.89949706798892,1.2653222797841366
7.295868352549133e-06,0.0001344,26.270789999999998,36.89949706798892,1.2653222797841366
8.598701986932907e-06,0.0001584,30.9620025,36.89949706798892,1.2653222797841366
8.98955207724804e-06,0.0001656,32.36936625,36.89949706798892,1.2653222797841366
1.0162102348193434e-05,0.0001872,36.5914575,36.89949706798892,1.2653222797841366
1.0683235801946944e-05,0.00019679999999999999,38.4679425,36.89949706798892,1.2653222797841366
1.1378080406951624e-05,0.0002096,40.9699225,36.89949706798892,1.2653222797841366
1.1986069436330719e-05,0.0002208,43.159155,36.89949706798892,1.2653222797841366
1.3028336343837736e-05,0.00023999999999999998,46.912124999999996,36.89949706798892,1.2653222797841366
1.3549469797591248e-05,0.0002496,48.78861,36.89949706798892,1.2653222797841366
1.4461453341659887e-05,0.00026639999999999997,52.072458749999996,36.89949706798892,1.2653222797841366
1.4895731219787813e-05,0.0002744,53.63619625,36.89949706798892,1.2653222797841366
1.55471480369797e-05,0.00028639999999999997,55.98180249999999,36.89949706798892,1.2653222797841366
1.6719698307925096e-05,0.000308,60.20389375,36.89949706798892,1.2653222797841366
1.7718537427619323e-05,0.00032639999999999996,63.800489999999996,36.89949706798892,1.2653222797841366
1.7935676366683286e-05,0.0003304,64.58235875,36.89949706798892,1.2653222797841366
1.802253194230887e-05,0.000332,64.89510625,36.89949706798892,1.2653222797841366
1.8760804335126342e-05,0.0003456,67.55346,36.89949706798892,1.2653222797841366
1.9368793364505437e-05,0.0003568,69.7426925,36.89949706798892,1.2653222797841366
2.036763248419966e-05,0.00037519999999999996,73.33928875,36.89949706798892,1.2653222797841366
2.1713893906396228e-05,0.00039999999999999996,78.18687499999999,36.89949706798892,1.2653222797841366
2.2148171784524155e-05,0.000408,79.7506125,36.89949706798892,1.2653222797841366
2.3016727540780003e-05,0.000424,82.8780875,36.89949706798892,1.2653222797841366
2.353786099453351e-05,0.00043359999999999997,84.7545725,36.89949706798892,1.2653222797841366
2.4058994448287022e-05,0.0004432,86.6310575,36.89949706798892,1.2653222797841366
2.4884122416730078e-05,0.0004584,89.60215875,36.89949706798892,1.2653222797841366
2.5665822597360344e-05,0.0004728,92.41688625,36.89949706798892,1.2653222797841366
2.666466171705457e-05,0.0004912,96.01348250000001,36.89949706798892,1.2653222797841366
2.7272650746433664e-05,0.0005024,98.202715,36.89949706798892,1.2653222797841366
2.8097778714876723e-05,0.0005176,101.17381625,36.89949706798892,1.2653222797841366
2.827148986612789e-05,0.0005208,101.79931124999999,36.89949706798892,1.2653222797841366
2.970460686395004e-05,0.0005472,106.959645,36.89949706798892,1.2653222797841366
2.9965173590826794e-05,0.000552,107.8978875,36.89949706798892,1.2653222797841366
3.0182312529890758e-05,0.000556,108.67975625,36.89949706798892,1.2653222797841366
3.274455201084552e-05,0.0006032,117.90580750000001,36.89949706798892,1.2653222797841366
3.430795237210604e-05,0.000632,123.53526249999999,36.89949706798892,1.2653222797841366
3.4611946886795586e-05,0.0006376,124.62987875,36.89949706798892,1.2653222797841366
3.491594140148514e-05,0.0006432,125.724495,36.89949706798892,1.2653222797841366
3.51330803405491e-05,0.0006472,126.50636375,36.89949706798892,1.2653222797841366
3.713075857993755e-05,0.0006839999999999999,133.69955624999997,36.89949706798892,1.2653222797841366
3.74347530946271e-05,0.0006896,134.7941725,36.89949706798892,1.2653222797841366
3.886787009244925e-05,0.000716,139.95450624999998,36.89949706798892,1.2653222797841366
3.951928690964113e-05,0.0007279999999999999,142.30011249999998,36.89949706798892,1.2653222797841366
3.977985363651789e-05,0.0007327999999999999,143.23835499999998,36.89949706798892,1.2653222797841366
4.0561553817148154e-05,0.0007472,146.0530825,36.89949706798892,1.2653222797841366
4.1777531875906345e-05,0.0007696,150.4315475,36.89949706798892,1.2653222797841366
4.2211809754034265e-05,0.0007775999999999999,151.995285,36.89949706798892,1.2653222797841366
4.2863226571226156e-05,0.0007896,154.34089125,36.89949706798892,1.2653222797841366
4.525175490092974e-05,0.0008336,162.9414475,36.89949706798892,1.2653222797841366
4.711914977687982e-05,0.000868,169.66551875,36.89949706798892,1.2653222797841366
4.764028323063333e-05,0.0008776,171.54200375,36.89949706798892,1.2653222797841366
4.876940571376593e-05,0.0008983999999999999,175.60772125,36.89949706798892,1.2653222797841366
4.959453368220899e-05,0.0009136,178.5788225,36.89949706798892,1.2653222797841366
5.050651722627763e-05,0.0009304,181.86267125,36.89949706798892,1.2653222797841366
5.1548784133784646e-05,0.0009496,185.61564125,36.89949706798892,1.2653222797841366
5.2200200950976536e-05,0.0009616,187.96124749999998,36.89949706798892,1.2653222797841366
5.241733989004049e-05,0.0009655999999999999,188.74311624999999,36.89949706798892,1.2653222797841366
5.259105104129166e-05,0.0009687999999999999,189.36861125,36.89949706798892,1.2653222797841366
5.285161776816842e-05,0.0009735999999999999,190.30685375,36.89949706798892,1.2653222797841366
5.328589564629635e-05,0.0009816,191.87059125,36.89949706798892,1.2653222797841366
5.389388467567544e-05,0.0009928,194.05982375000002,36.89949706798892,1.2653222797841366
5.4371590341616166e-05,0.0010016,195.77993500000002,36.89949706798892,1.2653222797841366
5.47190126441185e-05,0.001008,197.030925,36.89949706798892,1.2653222797841366
5.5544140612561554e-05,0.0010232,200.00202625,36.89949706798892,1.2653222797841366
5.6195557429753445e-05,0.0010352,202.3476325,36.89949706798892,1.2653222797841366
5.667326309569416e-05,0.001044,204.06774375,36.89949706798892,1.2653222797841366
5.8019524517890724e-05,0.0010688,208.91532999999998,36.89949706798892,1.2653222797841366
5.823666345695469e-05,0.0010728,209.69719875,36.89949706798892,1.2653222797841366
5.8410374608205856e-05,0.001076,210.32269374999998,36.89949706798892,1.2653222797841366
5.893150806195936e-05,0.0010856,212.19917875,36.89949706798892,1.2653222797841366
6.0364625059781515e-05,0.001112,217.3595125,36.89949706798892,1.2653222797841366
6.084233072572223e-05,0.0011208,219.07962375,36.89949706798892,1.2653222797841366
6.16240309063525e-05,0.0011352,221.89435125,36.89949706798892,1.2653222797841366
6.223201993573158e-05,0.0011464,224.08358374999997,36.89949706798892,1.2653222797841366
6.38822758726177e-05,0.0011768,230.02578625,36.89949706798892,1.2653222797841366
6.435998153855842e-05,0.0011856,231.74589749999998,36.89949706798892,1.2653222797841366
6.496797056793752e-05,0.0011968,233.93513000000002,36.89949706798892,1.2653222797841366
6.635765977794688e-05,0.0012224,238.93909,36.89949706798892,1.2653222797841366
6.744335447326668e-05,0.0012423999999999998,242.84843374999997,36.89949706798892,1.2653222797841366
6.783420456358183e-05,0.0012496,244.2557975,36.89949706798892,1.2653222797841366
6.891989925890162e-05,0.0012695999999999999,248.16514124999998,36.89949706798892,1.2653222797841366
6.996216616640864e-05,0.0012887999999999999,251.91811124999998,36.89949706798892,1.2653222797841366
7.078729413485171e-05,0.001304,254.8892125,36.89949706798892,1.2653222797841366
7.213355555704828e-05,0.0013288,259.73679875,36.89949706798892,1.2653222797841366
7.274154458642737e-05,0.00134,261.92603125,36.89949706798892,1.2653222797841366
7.443522831112627e-05,0.0013712,268.0246075,36.89949706798892,1.2653222797841366
7.495636176487978e-05,0.0013808,269.9010925,36.89949706798892,1.2653222797841366
7.573806194551004e-05,0.0013951999999999999,272.71581999999995,36.89949706798892,1.2653222797841366
7.682375664082986e-05,0.0014152,276.62516375,36.89949706798892,1.2653222797841366
7.730146230677057e-05,0.001424,278.34527499999996,36.89949706798892,1.2653222797841366
7.83003014264648e-05,0.0014424,281.94187124999996,36.89949706798892,1.2653222797841366
8.073225754398118e-05,0.0014872,290.69880125,36.89949706798892,1.2653222797841366
8.420648056900458e-05,0.0015512,302.37090798614685,36.89949706798892,1.2653222797841366
8.533560305213718e-05,0.0015719999999999998,302.5400047048258,36.89949706798892,1.2653222797841366
8.659500889870817e-05,0.0015952,302.72758649448656,36.89949706798892,1.2653222797841366
8.776755916965355e-05,0.0016167999999999998,302.9012774049381,36.89949706798892,1.2653222797841366
8.859268713809662e-05,0.001632,303.022962255004,36.89949706798892,1.2653222797841366
8.92441039552885e-05,0.0016439999999999998,303.118717303268,36.89949706798892,1.2653222797841366
9.054693758967228e-05,0.001668,303.30941352984456,36.89949706798892,1.2653222797841366
9.141549334592812e-05,0.001684,303.4359501814605,36.89949706798892,1.2653222797841366
9.306574928281422e-05,0.0017143999999999998,303.67508548501775,36.89949706798892,1.2653222797841366
9.619255000533529e-05,0.001772,304.1236966799616,36.89949706798892,1.2653222797841366
9.645311673221204e-05,0.0017767999999999998,304.1608222849819,36.89949706798892,1.2653222797841366
9.671368345908881e-05,0.0017816,304.1979087957683,36.89949706798892,1.2653222797841366
9.771252257878304e-05,0.0018,304.33971421304665,36.89949706798892,1.2653222797841366
9.875478948629005e-05,0.0018192,304.4870836590258,36.89949706798892,1.2653222797841366
9.96233452425459e-05,0.0018352,304.60942873304816,36.89949706798892,1.2653222797841366
0.00010005762312067383,0.0018432,304.6704452209116,36.89949706798892,1.2653222797841366
0.00010109989002818084,0.0018624,304.81646492960516,36.89949706798892,1.2653222797841366
0.00010196844578443669,0.0018784,304.9377000853946,36.89949706798892,1.2653222797841366
0.0001024461514503774,0.0018872,305.00420773184726,36.89949706798892,1.2653222797841366
0.00010331470720663325,0.0019031999999999999,305.1248216817742,36.89949706798892,1.2653222797841366
0.00010513867429477053,0.0019367999999999998,305.3768313075551,36.89949706798892,1.2653222797841366
0.00010678893023165666,0.0019672,305.60337457636206,36.89949706798892,1.2653222797841366
0.00010752720262447413,0.0019808,305.70428041892694,36.89949706798892,1.2653222797841366
0.00010856946953198115,0.002,305.84627694740345,36.89949706798892,1.2653222797841366
0.00010961173643948817,0.0020192,305.98774282513494,36.89949706798892,1.2653222797841366
0.00011026315325668005,0.0020312,306.0758926449963,36.89949706798892,1.2653222797841366
0.00011095799786168472,0.002044,306.1696955525734,36.89949706798892,1.2653222797841366
0.00011152255910325104,0.0020544,306.2457418411981,36.89949706798892,1.2653222797841366
0.00011178312583012778,0.0020591999999999997,306.2807894758491,36.89949706798892,1.2653222797841366
0.0001123476870716941,0.0020696,306.35661690179376,36.89949706798892,1.2653222797841366
0.00011330309840357553,0.0020872,306.48460256877644,36.89949706798892,1.2653222797841366
0.0001134768095548267,0.0020904,306.5078273992912,36.89949706798892,1.2653222797841366
0.00011391108743295461,0.0020984,306.565828896156,36.89949706798892,1.2653222797841366
0.00011447564867452092,0.0021088,306.6411020777374,36.89949706798892,1.2653222797841366
0.0001157350545210919,0.0021319999999999998,306.80849941516203,36.89949706798892,1.2653222797841366
0.0001163864713382838,0.002144,306.8948053932536,36.89949706798892,1.2653222797841366
0.00011695103257985009,0.0021544,306.96945163234864,36.89949706798892,1.2653222797841366
0.00011781958833610594,0.0021704,307.08401817147336,36.89949706798892,1.2653222797841366
0.00011894871081923854,0.0021912,307.23246344603155,36.89949706798892,1.2653222797841366
0.0001198172665754944,0.0022072,307.34627846769695,36.89949706798892,1.2653222797841366
0.00012020811666580953,0.0022144,307.3973902046043,36.89949706798892,1.2653222797841366
0.00012046868339268627,0.0022191999999999997,307.4314286933887,36.89949706798892,1.2653222797841366
0.00012168466145144446,0.0022416,307.58989686960666,36.89949706798892,1.2653222797841366
0.00012194522817832122,0.0022464,307.62377385030777,36.89949706798892,1.2653222797841366
0.0001237691952664585,0.00228,307.86012723289343,36.89949706798892,1.2653222797841366
0.00012468117881052714,0.0022968,307.9777942329443,36.89949706798892,1.2653222797841366
0.00012489831774959112,0.0023008,308.00576065351703,36.89949706798892,1.2653222797841366
0.0001266354292621028,0.0023328,308.22881343556816,36.89949706798892,1.2653222797841366
0.000127851407320861,0.0023552,308.38424090432954,36.89949706798892,1.2653222797841366
0.00012819882962336333,0.0023615999999999997,308.428542723634,36.89949706798892,1.2653222797841366
0.00012893710201618082,0.0023752,308.5225289231078,36.89949706798892,1.2653222797841366
0.00012932795210649593,0.0023824,308.5722013432966,36.89949706798892,1.2653222797841366
0.0001297188021968111,0.0023896,308.6218152517986,36.89949706798892,1.2653222797841366
0.00013275874734370655,0.0024456,309.0057307843082,36.89949706798892,1.2653222797841366
0.00013388786982683915,0.0024664,309.14745279463403,36.89949706798892,1.2653222797841366
0.0001342352921293415,0.0024728,309.1909656904031,36.89949706798892,1.2653222797841366
0.00013440900328059267,0.002476,309.21270566628596,36.89949706798892,1.2653222797841366
0.00013493013673434616,0.0024855999999999997,309.27785994227355,36.89949706798892,1.2653222797841366
0.0001353209868246613,0.0024928,309.3266612642197,36.89949706798892,1.2653222797841366
0.00013575526470278922,0.0025008,309.38082052773507,36.89949706798892,1.2653222797841366
0.00013840435975936958,0.0025496,309.70974066147886,36.89949706798892,1.2653222797841366
0.0001392729155156254,0.0025656,309.817047640988,36.89949706798892,1.2653222797841366
0.00014035861021094524,0.0025856,309.95081505510893,36.89949706798892,1.2653222797841366
0.00014187858278439294,0.0026135999999999998,310.1374134700542,36.89949706798892,1.2653222797841366
0.0001422260050868953,0.00262,310.17995487734646,36.89949706798892,1.2653222797841366
0.00014439739447753494,0.00266,310.44492630081527,36.89949706798892,1.2653222797841366
0.00014487510014347564,0.0026688,310.5030109446106,36.89949706798892,1.2653222797841366
0.0001456133725362931,0.0026823999999999997,310.5926314163811,36.89949706798892,1.2653222797841366
0.0001466990672316129,0.0027023999999999998,310.7241049776566,36.89949706798892,1.2653222797841366
0.00014713334510974086,0.0027104,310.7765880832365,36.89949706798892,1.2653222797841366
0.00014761105077568156,0.0027191999999999997,310.8342497702444,36.89949706798892,1.2653222797841366
0.00014778476192693274,0.0027224,310.85519960672275,36.89949706798892,1.2653222797841366
0.00014882702883443975,0.0027416,310.9806975386381,36.89949706798892,1.2653222797841366
0.00014921787892475488,0.0027488,311.027670834646,36.89949706798892,1.2653222797841366
0.00015012986246882353,0.0027656,311.137088979618,36.89949706798892,1.2653222797841366
0.00015151955167883288,0.0027911999999999998,311.3033242463831,36.89949706798892,1.2653222797841366
0.00015238810743508873,0.0028071999999999997,311.4069193901931,36.89949706798892,1.2653222797841366
0.00015360408549384692,0.0028296,311.5515665595352,36.89949706798892,1.2653222797841366
0.0001560360416113633,0.0028744,311.8395280735496,36.89949706798892,1.2653222797841366
0.00015690459736761916,0.0028904,311.9419465838733,36.89949706798892,1.2653222797841366
0.00015738230303355985,0.0028991999999999998,311.99818250975073,36.89949706798892,1.2653222797841366
0.0001578600086995006,0.002908,312.0543519042192,36.89949706798892,1.2653222797841366
0.0001589457033948204,0.002928,312.1817636661114,36.89949706798892,1.2653222797841366
0.00016103023720983442,0.0029663999999999997,312.42544679892234,36.89949706798892,1.2653222797841366
0.00016168165402702633,0.0029784,312.5013450737335,36.89949706798892,1.2653222797841366
0.0001628976320857845,0.0030007999999999996,312.64270352974097,36.89949706798892,1.2653222797841366
0.00016433074908360666,0.0030272,312.8087773361304,36.89949706798892,1.2653222797841366
0.0001658507216570544,0.0030551999999999997,312.98430018003876,36.89949706798892,1.2653222797841366
0.0001663718551108079,0.0030648,313.04433487388377,36.89949706798892,1.2653222797841366
0.0001668929885645614,0.0030743999999999997,313.10429627319166,36.89949706798892,1.2653222797841366
0.00016711012750362538,0.0030784,313.1292586331725,36.89949706798892,1.2653222797841366
0.00016732726644268933,0.0030824,313.1542083465092,36.89949706798892,1.2653222797841366
0.00016845638892582196,0.0031032,313.28374387141815,36.89949706798892,1.2653222797841366
0.00016906437795520104,0.0031144,313.35335349599353,36.89949706798892,1.2653222797841366
0.00016945522804551617,0.0031216,313.3980509918175,36.89949706798892,1.2653222797841366
0.00017001978928708246,0.003132,313.46254312386213,36.89949706798892,1.2653222797841366
0.00017127919513365347,0.0031552,313.60610998552414,36.89949706798892,1.2653222797841366
0.00017362429567554423,0.0031983999999999997,313.8723490857883,36.89949706798892,1.2653222797841366
0.00017375457903898262,0.0032007999999999997,313.8870988900099,36.89949706798892,1.2653222797841366
0.00017444942364398732,0.0032136,313.96569178673434,36.89949706798892,1.2653222797841366
0.0001767076686102525,0.0032551999999999998,314.2202796677253,36.89949706798892,1.2653222797841366
0.00017835792454713864,0.0032856,314.4055229285703,36.89949706798892,1.2653222797841366
0.00017870534684964097,0.003292,314.4444361985536,36.89949706798892,1.2653222797841366
0.00017926990809120729,0.0033024,314.50760739469575,36.89949706798892,1.2653222797841366
0.00017979104154496078,0.003312,314.56585043853323,36.89949706798892,1.2653222797841366
0.00018035560278652706,0.0033223999999999997,314.6288728209382,36.89949706798892,1.2653222797841366
0.00018065959730121663,0.003328,314.66277608020266,36.89949706798892,1.2653222797841366
0.00018165843642091084,0.0033464,314.77401618173235,36.89949706798892,1.2653222797841366
0.0001824401366015411,0.0033607999999999997,314.86090734434254,36.89949706798892,1.2653222797841366
0.00018274413111623065,0.0033664,314.8946591247705,36.89949706798892,1.2653222797841366
0.00018300469784310742,0.0033712,314.92357179782226,36.89949706798892,1.2653222797841366
0.00018452467041655515,0.0033992,315.09191017644196,36.89949706798892,1.2653222797841366
0.00018526294280937262,0.0034127999999999997,315.1734793347078,36.89949706798892,1.2653222797841366
0.00018747775998782503,0.0034536,315.4174295608126,36.89949706798892,1.2653222797841366
0.00018943201043940068,0.0034896,315.6317478863752,36.89949706798892,1.2653222797841366
0.00018995314389315423,0.0034992,315.6887535903904,36.89949706798892,1.2653222797841366
0.0001905611329225333,0.0035104,315.75518321314576,36.89949706798892,1.2653222797841366
0.00019129940531535078,0.003524,315.83573673389486,36.89949706798892,1.2653222797841366
0.00019190739434472986,0.0035351999999999996,315.90198393082636,36.89949706798892,1.2653222797841366
0.00019294966125223687,0.0035543999999999997,316.0153604360711,36.89949706798892,1.2653222797841366
0.00019342736691817762,0.0035632,316.0672448197419,36.89949706798892,1.2653222797841366
0.0001939485003719311,0.0035727999999999997,316.12378900375967,36.89949706798892,1.2653222797841366
0.00019442620603787183,0.0035816,316.1755691415605,36.89949706798892,1.2653222797841366
0.00019503419506725092,0.0035927999999999997,316.24139943103467,36.89949706798892,1.2653222797841366
0.0001951210506428765,0.0035943999999999998,316.25079722057797,36.89949706798892,1.2653222797841366
0.00019590275082350677,0.0036087999999999997,316.33530403671085,36.89949706798892,1.2653222797841366
0.00019724901224570335,0.0036336,316.480535926434,36.89949706798892,1.2653222797841366
0.0001980307124263336,0.0036479999999999998,316.5646867192047,36.89949706798892,1.2653222797841366
0.00019850841809227433,0.0036568,316.6160484329151,36.89949706798892,1.2653222797841366
0.0001992466904850918,0.0036704,316.6953309136861,36.89949706798892,1.2653222797841366
0.00020011524624134766,0.0036864,316.78845789018624,36.89949706798892,1.2653222797841366
0.00020081009084635233,0.0036991999999999997,316.86284602294796,36.89949706798892,1.2653222797841366
0.00020141807987573144,0.0037104,316.92785333062125,36.89949706798892,1.2653222797841366
0.00020224320784417447,0.0037256,317.0159552598473,36.89949706798892,1.2653222797841366
0.0002037631804176222,0.0037535999999999997,317.1778821962728,36.89949706798892,1.2653222797841366
0.00020419745829575013,0.0037616,317.2240604222883,36.89949706798892,1.2653222797841366
0.00020510944183981878,0.0037784,317.32091021084847,36.89949706798892,1.2653222797841366
0.00020563057529357227,0.0037879999999999997,317.37617754234213,36.89949706798892,1.2653222797841366
0.00020649913104982812,0.0038039999999999997,317.46816852635027,36.89949706798892,1.2653222797841366
0.00020810595919890147,0.0038336,317.63795501663697,36.89949706798892,1.2653222797841366
0.0002088876593795317,0.003848,317.7203689223948,36.89949706798892,1.2653222797841366
0.00020988649849922595,0.0038664,317.82550075419357,36.89949706798892,1.2653222797841366
0.00021036420416516665,0.0038751999999999997,317.87571220432494,36.89949706798892,1.2653222797841366
0.00021105904877017135,0.003888,317.9486677313991,36.89949706798892,1.2653222797841366
0.00021249216576799351,0.0039144,318.09884333943387,36.89949706798892,1.2653222797841366
0.0002130567270095598,0.0039248,318.15789491005415,36.89949706798892,1.2653222797841366
0.00021331729373643657,0.0039296,318.1851288955326,36.89949706798892,1.2653222797841366
0.00021357786046331332,0.0039344,318.21234991025216,36.89949706798892,1.2653222797841366
0.00021570582206614013,0.0039736,318.43417213608467,36.89949706798892,1.2653222797841366
0.00021666123339802155,0.0039911999999999994,318.5334880134313,36.89949706798892,1.2653222797841366
0.00021674808897364714,0.0039927999999999995,318.54250825157425,36.89949706798892,1.2653222797841366
0.00022339379147948753,0.004115223044608922,319.2285638420223,36.89949706798892,1.2653222797841366
0.00024007339792088812,0.00442248449689938,320.91628172588355,36.89949706798892,1.2653222797841366
0.00026300785677781395,0.00484496899379876,323.163999860652,36.89949706798892,1.2653222797841366
0.0002765600370114519,0.005094618923784757,324.45624993286947,36.89949706798892,1.2653222797841366
0.00028385736482956466,0.005229045809161833,325.1418353906851,36.89949706798892,1.2653222797841366
0.0003328537087511789,0.006131626325265053,329.5788478217221,36.89949706798892,1.2653222797841366
0.00033910856116670405,0.006246849369873975,330.12632570095144,36.89949706798892,1.2653222797841366
0.00036308549542621744,0.0066885377075415085,332.18948018861215,36.89949706798892,1.2653222797841366
0.00038393500347796815,0.007072614522904581,333.9406865257343,36.89949706798892,1.2653222797841366
0.0003995721345167812,0.007360672134426885,335.2298457774963,36.89949706798892,1.2653222797841366
0.0004152092655555942,0.0076487297459491895,336.4994726749359,36.89949706798892,1.2653222797841366
0.0004642056094772085,0.00855131026205241,340.36190286683376,36.89949706798892,1.2653222797841366
0.00046941798649014616,0.008647329465893179,340.76321348457253,36.89949706798892,1.2653222797841366
0.0004819276913211966,0.008877775555111022,341.7193337146993,36.89949706798892,1.2653222797841366
0.000548646117086799,0.010106821364272855,346.66380956747923,36.89949706798892,1.2653222797841366
0.0005705381005411373,0.010510102020404082,348.23431385923294,36.89949706798892,1.2653222797841366
0.0006247468214756891,0.01150870174034807,352.0252518467112,36.89949706798892,1.2653222797841366
0.0006351715755015645,0.011700740148029607,352.7393297199907,36.89949706798892,1.2653222797841366
0.000651851181942965,0.012008001600320064,353.87241964413505,36.89949706798892,1.2653222797841366
0.0006789555424102409,0.012507301460292058,355.68986438286026,36.89949706798892,1.2653222797841366
0.0007029324766697543,0.012948989797959592,357.2741434007979,36.89949706798892,1.2653222797841366
0.000723781984721505,0.013333066613322665,358.63472111718704,36.89949706798892,1.2653222797841366
0.0007435890173706683,0.013697939587917584,359.91317954271943,36.89949706798892,1.2653222797841366
0.0007519288205913685,0.013851570314062813,360.4474964499617,36.89949706798892,1.2653222797841366
0.0007623535746172439,0.01404360872174435,361.1121534936297,36.89949706798892,1.2653222797841366
0.0007873729842793448,0.014504500900180036,362.6930317374232,36.89949706798892,1.2653222797841366
0.0008144773447466208,0.015003800760152031,364.3837002383789,36.89949706798892,1.2653222797841366
0.0008676435902785851,0.015983196639327867,367.6375800470829,36.89949706798892,1.2653222797841366
0.000874940918096698,0.016117623524704944,368.0780431759655,36.89949706798892,1.2653222797841366
0.0008895355737329234,0.01638647729545909,368.9546946368054,36.89949706798892,1.2653222797841366
0.0009041302293691488,0.016655331066213242,369.82575423389045,36.89949706798892,1.2653222797841366
0.0009124700325898492,0.01680896179235847,370.3210402783782,36.89949706798892,1.2653222797841366
0.0009260222128234872,0.01705861172234447,371.12213120710027,36.89949706798892,1.2653222797841366
0.0009708486551347512,0.017884376875375075,373.7399047650784,36.89949706798892,1.2653222797841366
0.0009833583599658017,0.01811482296459292,374.4619771980069,36.89949706798892,1.2653222797841366
0.0009896132123813268,0.01823004600920184,374.821669343536,36.89949706798892,1.2653222797841366
0.0010198449990563654,0.018786957391478294,376.54783515482137,36.89949706798892,1.2653222797841366
0.001025057376069303,0.018882976595319064,376.84342151234273,36.89949706798892,1.2653222797841366
0.0010333971792900033,0.019036607321464293,377.31514332962627,36.89949706798892,1.2653222797841366
0.0010542466873417543,0.019420684136827366,378.4879983753709,36.89949706798892,1.2653222797841366
0.0010865634248219678,0.020016003200640127,380.2882018309406,36.89949706798892,1.2653222797841366
0.0011188801623021815,0.02061132226445289,382.06764093507513,36.89949706798892,1.2653222797841366
0.001162664129210858,0.021417883576715344,384.4468406696114,36.89949706798892,1.2653222797841366
0.0011793437356522585,0.021725145029005802,385.3439780432249,36.89949706798892,1.2653222797841366
0.0011949808666910716,0.022013202640528105,386.1805605081348,36.89949706798892,1.2653222797841366
0.001207490571522122,0.02224364872974595,386.8467565244806,36.89949706798892,1.2653222797841366
0.0012314675057816355,0.022685337067413484,388.11615616209804,36.89949706798892,1.2653222797841366
0.0012377223581971606,0.022800560112022406,388.4457140305886,36.89949706798892,1.2653222797841366
0.001306525734767938,0.024068013602720543,392.0289951604915,36.89949706798892,1.2653222797841366
0.0013315451444300388,0.02452890578115623,393.3136589538643,36.89949706798892,1.2653222797841366
0.001333630095235214,0.024567313462692537,393.42028747892647,36.89949706798892,1.2653222797841366
0.0013503097016766144,0.024874574914982996,394.2709877090077,36.89949706798892,1.2653222797841366
0.001376371586741303,0.02535467093418684,395.59204793933424,36.89949706798892,1.2653222797841366
0.001394093668585291,0.02568113622724545,396.4848011141916,36.89949706798892,1.2653222797841366
0.0014128582258318666,0.026026805361072214,397.42525835153054,36.89949706798892,1.2653222797841366
0.0014284953568706798,0.02631486297259452,398.2052573053841,36.89949706798892,1.2653222797841366
0.0014357926846887924,0.026449289857971594,398.56811657171147,36.89949706798892,1.2653222797841366
0.0014483023895198429,0.026679735947189438,399.188492136138,36.89949706798892,1.2653222797841366
0.0014608120943508933,0.02691018203640728,399.8067813741032,36.89949706798892,1.2653222797841366
0.001475406749987119,0.027179035807161432,400.5255149824506,36.89949706798892,1.2653222797841366
0.0015098084382725078,0.027812762552510504,402.20879001982064,36.89949706798892,1.2653222797841366
0.001537955274142371,0.02833126625325065,403.574916277308,36.89949706798892,1.2653222797841366
0.0015515074543760092,0.02858091618323665,404.22920010436815,36.89949706798892,1.2653222797841366
0.0015619322084018843,0.028772954590918182,404.7309798135058,36.89949706798892,1.2653222797841366
0.001587994093466573,0.029253050610122025,405.9797484254136,36.89949706798892,1.2653222797841366
0.001594248945882098,0.029368273654730947,406.2782604498882,36.89949706798892,1.2653222797841366
0.0016255232079597241,0.029944388877775556,407.7640236064666,36.89949706798892,1.2653222797841366
0.001636990437388187,0.030155631126225244,408.30600476758013,36.89949706798892,1.2653222797841366
0.0016567974700373504,0.030520504100820165,409.23867938214795,36.89949706798892,1.2653222797841366
0.0016588824208425253,0.030558911782356472,409.3366020261786,36.89949706798892,1.2653222797841366
0.0016818168796994511,0.030981396279255852,410.41060227514527,36.89949706798892,1.2653222797841366
0.001695369059933089,0.031231046209241848,411.0425541073861,36.89949706798892,1.2653222797841366
0.0017057938139589644,0.031423084616923384,411.527331215321,36.89949706798892,1.2653222797841366
0.001740195502244353,0.03205681136227245,413.11896024518876,36.89949706798892,1.2653222797841366
0.0017558326332831663,0.03234486897379476,413.83836658056816,36.89949706798892,1.2653222797841366
0.0017610450102961042,0.03244088817763553,414.077612859609,36.89949706798892,1.2653222797841366
0.0017829369937504423,0.03284416883376676,415.0794463285817,36.89949706798892,1.2653222797841366
0.0018204661082435933,0.03353550710142028,416.785784785383,36.89949706798892,1.2653222797841366
0.0018444430425031068,0.033977195439087816,417.86876692593944,36.89949706798892,1.2653222797841366
0.0019017791896454215,0.03503340668133627,420.4364820240954,36.89949706798892,1.2653222797841366
0.0019247136485023473,0.03545589117823565,421.4550925741579,36.89949706798892,1.2653222797841366
0.0019372233533333975,0.03568633726745349,422.0087027548611,36.89949706798892,1.2653222797841366
0.0020039417790989997,0.03691538307661532,424.93807151669364,36.89949706798892,1.2653222797841366
0.0020445983197999143,0.03766433286657332,426.7045103477894,36.89949706798892,1.2653222797841366
0.0020696177294620153,0.03812522504500901,427.7847426468825,36.89949706798892,1.2653222797841366
0.0020988070407344656,0.038662932586517304,429.0385976591402,36.89949706798892,1.2653222797841366
0.0021154866471758665,0.03897019403880776,429.752032572648,36.89949706798892,1.2653222797841366
0.0021269538766043295,0.039181436287257454,430.2412470007234,36.89949706798892,1.2653222797841366
0.0021561431878767802,0.03971914382876575,431.4819010540389,36.89949706798892,1.2653222797841366
0.0021728227943181807,0.04002640528105621,432.18790506786587,36.89949706798892,1.2653222797841366
0.002178035171331118,0.040122424484896974,432.4080974448933,36.89949706798892,1.2653222797841366
0.0022093094334087447,0.040698539707941586,433.7249616700903,36.89949706798892,1.2653222797841366
0.002261433203538121,0.041658731746349265,435.90369310463984,36.89949706798892,1.2653222797841366
0.002309387072057148,0.042542108421684335,437.8908898470496,36.89949706798892,1.2653222797841366
0.0023177268752778485,0.042695739147829564,438.23484005077995,36.89949706798892,1.2653222797841366
0.0023354489571218366,0.04302220444088818,438.96413571584526,36.89949706798892,1.2653222797841366
0.002341703809537362,0.04313742748549711,439.2210184685987,36.89949706798892,1.2653222797841366
0.002369850645407225,0.04365593118623724,440.3736952712378,36.89949706798892,1.2653222797841366
0.0023875727272512134,0.04398239647929586,441.09671624481064,36.89949706798892,1.2653222797841366
0.0024198894647314267,0.04457771554310862,442.4098008427344,36.89949706798892,1.2653222797841366
0.0024355265957702404,0.04486577315463093,443.0427076733249,36.89949706798892,1.2653222797841366
0.002466800857847866,0.04544188837767553,444.30378692550823,36.89949706798892,1.2653222797841366
0.002475140661068566,0.04559551910382076,444.6390196961787,36.89949706798892,1.2653222797841366
0.0025012025461332546,0.046075615123024605,445.68379401921993,36.89949706798892,1.2653222797841366
0.0025387316606264067,0.04676695339067814,447.18084093485743,36.89949706798892,1.2653222797841366
0.002561666119483332,0.04718943788757751,448.0914549452287,36.89949706798892,1.2653222797841366
0.0025647935456910944,0.047247049409881975,448.2153827792677,36.89949706798892,1.2653222797841366
0.0025856430537428456,0.047631126225245055,449.04006739574737,36.89949706798892,1.2653222797841366
0.0025898129553531954,0.04770794158831766,449.20469266067715,36.89949706798892,1.2653222797841366
0.0026231721682359968,0.04832246449289858,450.51799370090316,36.89949706798892,1.2653222797841366
0.002666956135144673,0.04912902580516103,452.23185862551395,36.89949706798892,1.2653222797841366
0.0026794658399757238,0.04935947189437888,452.71951424412543,36.89949706798892,1.2653222797841366
0.0027128250528585247,0.049973994798959795,454.0156077083329,36.89949706798892,1.2653222797841366
0.0027513966427542636,0.05068453690738148,455.5064924510933,36.89949706798892,1.2653222797841366
0.0027805859540267143,0.05122224444888977,456.6293173695828,36.89949706798892,1.2653222797841366
0.002784755855637065,0.051299059811962394,456.7893448719821,36.89949706798892,1.2653222797841366
0.0028035204128836404,0.051644728945789156,457.50831527280855,36.89949706798892,1.2653222797841366
0.002820200019325041,0.051951990398079614,458.14582601686334,36.89949706798892,1.2653222797841366
0.002827497347143154,0.0520864172834567,458.4242743903665,36.89949706798892,1.2653222797841366
0.0028379221011690294,0.05227845569113823,458.8215720972138,36.89949706798892,1.2653222797841366
0.0028764936910647683,0.052988997799559914,460.2866507071624,36.89949706798892,1.2653222797841366
0.0028858759696880564,0.0531618323664733,460.6418602387477,36.89949706798892,1.2653222797841366
0.002927574985791557,0.053929985997199434,462.2151516708944,36.89949706798892,1.2653222797841366
0.0029400846906226076,0.054160432086417284,462.68543170310346,36.89949706798892,1.2653222797841366
0.0029609341986743584,0.05454450890178035,463.4675012696267,36.89949706798892,1.2653222797841366
0.002977613805115759,0.05485177035407081,464.0916116684789,36.89949706798892,1.2653222797841366
0.0029807412313235214,0.05490938187637527,464.20848042163743,36.89949706798892,1.2653222797841366
0.0029942934115571593,0.05515903180636127,464.7143600837804,36.89949706798892,1.2653222797841366
0.0030015907393752725,0.05529345869173835,464.9863869320006,36.89949706798892,1.2653222797841366
0.003033907476855486,0.05588877775555111,466.18799028674596,36.89949706798892,1.2653222797841366
0.0030599693619201744,0.056368873774754955,467.15339324771935,36.89949706798892,1.2653222797841366
0.0030641392635305242,0.05644568913782756,467.30755964259,36.89949706798892,1.2653222797841366
0.0030735215421538124,0.05661852370474095,467.65413518286334,36.89949706798892,1.2653222797841366
0.003113135607452139,0.05734826965393079,469.1129285458011,36.89949706798892,1.2653222797841366
0.0031214754106728393,0.05750190038007602,469.4191184297708,36.89949706798892,1.2653222797841366
0.00313815501711424,0.05780916183236648,470.03054274165,36.89949706798892,1.2653222797841366
0.0031464948203349403,0.05796279255851171,470.33577952299504,36.89949706798892,1.2653222797841366
0.0031704717545944536,0.05840448089617924,471.2115826429786,36.89949706798892,1.2653222797841366
0.0031767266070099787,0.05851970394078816,471.43962772630056,36.89949706798892,1.2653222797841366
0.003189236311841029,0.058750150030006,471.89519322811816,36.89949706798892,1.2653222797841366
0.003231977803347118,0.0595375075015003,473.44647731871413,36.89949706798892,1.2653222797841366
0.003254912262204044,0.059959991998399687,474.2755743382979,36.89949706798892,1.2653222797841366
0.0032601246392169815,0.06005601120224045,474.4636873682656,36.89949706798892,1.2653222797841366
0.0032715918686454445,0.060267253450690145,474.87712364510526,36.89949706798892,1.2653222797841366
0.0032809741472687322,0.06044008801760352,475.2149694840657,36.89949706798892,1.2653222797841366
0.0033007811799178953,0.06080496099219844,475.9269647608776,36.89949706798892,1.2653222797841366
0.0033059935569308327,0.060900980196039206,476.11405475288035,36.89949706798892,1.2653222797841366
0.003340395245216222,0.06153470694138828,477.3459761081308,36.89949706798892,1.2653222797841366
0.0033768818843067858,0.06220684136827366,478.6471647413335,36.89949706798892,1.2653222797841366
0.003399816343163711,0.06262932586517303,479.4622489618026,36.89949706798892,1.2653222797841366
0.003443600310072388,0.0634358871774355,481.0123887582323,36.89949706798892,1.2653222797841366
0.0034519401132930886,0.06358951790358072,481.30677996676104,36.89949706798892,1.2653222797841366
0.0035113612112405777,0.06468413682736547,483.3963465863113,36.89949706798892,1.2653222797841366
0.0035593150797596047,0.06556751350270054,485.07262555652363,36.89949706798892,1.2653222797841366
0.0035937167680449933,0.06620124024804962,486.26975225897525,36.89949706798892,1.2653222797841366
0.003614566276096744,0.06658531706341268,486.9931086819516,36.89949706798892,1.2653222797841366
0.003632288357940732,0.0669117823564713,487.6066831281463,36.89949706798892,1.2653222797841366
0.0036635626200183587,0.06748789757951591,488.6866210356271,36.89949706798892,1.2653222797841366
0.003672944898641646,0.06766073214642929,489.0099005261115,36.89949706798892,1.2653222797841366
0.0036927519312908094,0.06802560512102421,489.691323732576,36.89949706798892,1.2653222797841366
0.0037063041115244473,0.0682752550510102,490.15673956488115,36.89949706798892,1.2653222797841366
0.0037136014393425606,0.06840968193638729,490.4070731639758,36.89949706798892,1.2653222797841366
0.003738620849004661,0.06887057411482297,491.2639070904988,36.89949706798892,1.2653222797841366
0.0037480031276279488,0.06904340868173635,491.5846429034528,36.89949706798892,1.2653222797841366
0.003763640258666762,0.06933146629325866,492.1185076291832,36.89949706798892,1.2653222797841366
0.003778234914302987,0.0696003200640128,492.61600142886266,36.89949706798892,1.2653222797841366
0.00379804194695215,0.06996519303860772,493.2899744701613,36.89949706798892,1.2653222797841366
0.003826188782822014,0.07048369673934787,494.24537236367576,36.89949706798892,1.2653222797841366
0.0038355710614453023,0.07065653130626126,494.56322869908695,36.89949706798892,1.2653222797841366
0.003838698487653065,0.07071414282856572,494.6691134073832,36.89949706798892,1.2653222797841366
0.003850165717081527,0.0709253850770154,495.0570698340017,36.89949706798892,1.2653222797841366
0.003872057700535866,0.07132866573314664,495.79646485407034,36.89949706798892,1.2653222797841366
0.003884567405366916,0.07155911182236448,496.218244276667,36.89949706798892,1.2653222797841366
0.0038970771101979667,0.07178955791158233,496.63949430089735,36.89949706798892,1.2653222797841366
0.003924181470665243,0.07228885777155432,497.55039777894666,36.89949706798892,1.2653222797841366
0.003938776126301468,0.07255771154230847,498.0398677907737,36.89949706798892,1.2653222797841366
0.003945030978716993,0.07267293458691738,498.2494240665238,36.89949706798892,1.2653222797841366
0.003954413257340281,0.07284576915383077,498.5635156850984,36.89949706798892,1.2653222797841366
0.003976305240794619,0.073249049809962,499.2952680549259,36.89949706798892,1.2653222797841366
0.003988814945625669,0.07347949589917983,499.7127068087869,36.89949706798892,1.2653222797841366
0.003995069798041195,0.07359471894378876,499.92123469742626,36.89949706798892,1.2653222797841366
0.004019046732300709,0.0740364072814563,500.7194148325802,36.89949706798892,1.2653222797841366
0.004062830699209385,0.07484296859371875,502.17218560268515,36.89949706798892,1.2653222797841366
0.004088892584274073,0.07532306461292258,503.0340313936241,36.89949706798892,1.2653222797841366
0.00413267655118275,0.07612962592518505,504.47712498346885,36.89949706798892,1.2653222797841366
0.004150398633026737,0.07645609121824365,505.05953764532757,36.89949706798892,1.2653222797841366
0.004169163190273314,0.07680176035207043,505.6751537326968,36.89949706798892,1.2653222797841366
0.004192097649130239,0.0772242448489698,506.42610787534113,36.89949706798892,1.2653222797841366
0.004222329435805278,0.07778115623124625,507.41355843846185,36.89949706798892,1.2653222797841366
0.00426819835351913,0.07862612522504502,508.90651002939137,36.89949706798892,1.2653222797841366
0.0042953027139864056,0.079125425085017,509.78576765711585,36.89949706798892,1.2653222797841366
0.004317194697440744,0.07952870574114823,510.494358653948,36.89949706798892,1.2653222797841366
0.004329704402271794,0.07975915183036608,510.89863860834583,36.89949706798892,1.2653222797841366
0.004373488369180471,0.08056571314262853,512.3100449379904,36.89949706798892,1.2653222797841366
0.004383913123206346,0.08075775155031006,512.6452805414298,36.89949706798892,1.2653222797841366
0.004417272336089147,0.08137227445489098,513.7159512396091,36.89949706798892,1.2653222797841366
0.004449589073569361,0.08196759351870375,514.7501603961414,36.89949706798892,1.2653222797841366
0.004465226204608174,0.08225565113022605,515.2495321760861,36.89949706798892,1.2653222797841366
0.0045079676961142625,0.08304300860172034,516.6110139410283,36.89949706798892,1.2653222797841366
0.004537157007386714,0.08358071614322865,517.537914607653,36.89949706798892,1.2653222797841366
0.004558006515438464,0.08396479295859172,518.198563231615,36.89949706798892,1.2653222797841366
0.0045705162202695155,0.08419523904780957,518.5943867151414,36.89949706798892,1.2653222797841366
0.004609087810165254,0.08490578115623125,519.8121910331196,36.89949706798892,1.2653222797841366
0.0046466169246584055,0.08559711942388479,520.993272559189,36.89949706798892,1.2653222797841366
0.004653914252476518,0.08573154630926186,521.222494651806,36.89949706798892,1.2653222797841366
0.004659126629489456,0.08582756551310262,521.3861389057201,36.89949706798892,1.2653222797841366
0.004686230989956732,0.08632686537307462,522.2359408094352,36.89949706798892,1.2653222797841366
0.004696655743982607,0.08651890378075616,522.5622770124488,36.89949706798892,1.2653222797841366
0.004740439710891284,0.08732546509301861,523.9298156699962,36.89949706798892,1.2653222797841366
0.004757119317332684,0.08763272654530907,524.4494859205494,36.89949706798892,1.2653222797841366
0.004786308628605135,0.08817043408681736,525.3572021810402,36.89949706798892,1.2653222797841366
0.0048290501201112244,0.08895779155831167,526.6824726554429,36.89949706798892,1.2653222797841366
0.004844687251150037,0.08924584916983397,527.1661837179809,36.89949706798892,1.2653222797841366
0.004855112005175913,0.0894378875775155,527.4883195288365,36.89949706798892,1.2653222797841366
0.004863451808396612,0.08959151830366073,527.7458339961511,36.89949706798892,1.2653222797841366
0.004894726070474239,0.09016763352670534,528.7099832851644,36.89949706798892,1.2653222797841366
0.00491557557852599,0.09055171034206842,529.3514150814029,36.89949706798892,1.2653222797841366
0.004939552512785503,0.09099339867973595,530.0877513868435,36.89949706798892,1.2653222797841366
0.0049551896438243155,0.09128145629125825,530.5672198442466,36.89949706798892,1.2653222797841366
0.004980209053486417,0.09174234846969394,531.3331438053159,36.89949706798892,1.2653222797841366
0.004989591332109705,0.09191518303660733,531.6199782192454,36.89949706798892,1.2653222797841366
0.005006270938551105,0.09222244448889778,532.1293872286126,36.89949706798892,1.2653222797841366
0.005022950544992506,0.09252970594118824,532.6381347506787,36.89949706798892,1.2653222797841366
0.0050479699546546065,0.09299059811962393,533.400022413184,36.89949706798892,1.2653222797841366
0.005061522134888244,0.09324024804960993,533.812096603475,36.89949706798892,1.2653222797841366
0.00507194688891412,0.09343228645729146,534.1287840131098,36.89949706798892,1.2653222797841366
0.005080286692134821,0.09358591718343669,534.3819512031987,36.89949706798892,1.2653222797841366
0.005091753921563283,0.09379715943188638,534.7297915970347,36.89949706798892,1.2653222797841366
0.005112603429615034,0.09418123624724946,535.3614469558232,36.89949706798892,1.2653222797841366
0.005130325511459022,0.09450770154030806,535.8975645363116,36.89949706798892,1.2653222797841366
0.005144920167095248,0.09477655531106222,536.3385310221246,36.89949706798892,1.2653222797841366
0.005159514822731474,0.09504540908181637,536.7790099279335,36.89949706798892,1.2653222797841366
0.005173067002965112,0.09529505901180237,537.1875911466423,36.89949706798892,1.2653222797841366
0.005184534232393574,0.09550630126025206,537.5329877662806,36.89949706798892,1.2653222797841366
0.005248125231951414,0.09667773554710943,539.4429890668987,36.89949706798892,1.2653222797841366
0.005288781772652328,0.09742668533706741,540.6594089106559,36.89949706798892,1.2653222797841366
0.005298164051275616,0.0975995199039808,540.939602634623,36.89949706798892,1.2653222797841366
0.005308588805301491,0.09779155831166234,541.2507021359676,36.89949706798892,1.2653222797841366
0.005319013559327366,0.09798359671934387,541.5615634686098,36.89949706798892,1.2653222797841366
0.005330480788755829,0.09819483896779356,541.9032366236643,36.89949706798892,1.2653222797841366
0.005346117919794642,0.09848289657931587,542.3686929495257,36.89949706798892,1.2653222797841366
0.005361755050833456,0.09877095419083817,542.833618616866,36.89949706798892,1.2653222797841366
0.0053888594113007315,0.09927025405081016,543.6382390324726,36.89949706798892,1.2653222797841366
0.005395114263716257,0.09938547709541909,543.8236963426548,36.89949706798892,1.2653222797841366
0.0054086664439498945,0.09963512702540508,544.225233093032,36.89949706798892,1.2653222797841366
0.005415963771768007,0.09976955391078215,544.4412826565839,36.89949706798892,1.2653222797841366
0.005420133673378357,0.09984636927385478,544.5646885776647,36.89949706798892,1.2653222797841366