File: datasets/aisi_316_L/data/M1/train_62.csv
Time(s),Strain(%),Stress(MPa),Temp(C),Log_SR(s-1)
0.0,0.0,0.0,259.3836158011105,2.555201261821961
6.460806334514828e-08,2.3199999999999998e-05,4.20065725,259.3836158011105,2.555201261821961
7.797524886483413e-08,2.8e-05,5.06975875,259.3836158011105,2.555201261821961
1.002538913976439e-07,3.6e-05,6.51826125,259.3836158011105,2.555201261821961
1.5372263347638732e-07,5.52e-05,9.994667250000001,259.3836158011105,2.555201261821961
1.737734117559161e-07,6.24e-05,11.2983195,259.3836158011105,2.555201261821961
1.8268486876903998e-07,6.56e-05,11.877720499999999,259.3836158011105,2.555201261821961
2.4729293211418823e-07,8.879999999999999e-05,16.078377749999998,259.3836158011105,2.555201261821961
2.6288798188715507e-07,9.439999999999999e-05,17.092329499999998,259.3836158011105,2.555201261821961
3.364075022454273e-07,0.0001208,21.872387749999998,259.3836158011105,2.555201261821961
3.965598370840136e-07,0.0001424,25.7833445,259.3836158011105,2.555201261821961
4.2106634387010434e-07,0.0001512,27.37669725,259.3836158011105,2.555201261821961
4.50028579162757e-07,0.0001616,29.2597505,259.3836158011105,2.555201261821961
4.879022714685336e-07,0.0001752,31.72220475,259.3836158011105,2.555201261821961
5.502824705604009e-07,0.00019759999999999998,35.77801175,259.3836158011105,2.555201261821961
5.903840271194585e-07,0.000212,38.38531625,259.3836158011105,2.555201261821961
6.772707329974165e-07,0.0002432,44.034476,259.3836158011105,2.555201261821961
6.884100542638214e-07,0.0002472,44.75872725,259.3836158011105,2.555201261821961
7.775246243950604e-07,0.0002792,50.55273725,259.3836158011105,2.555201261821961
8.13170452447556e-07,0.000292,52.87034125,259.3836158011105,2.555201261821961
9.357029863780097e-07,0.000336,60.837104999999994,259.3836158011105,2.555201261821961
1.0092225067362818e-06,0.00036239999999999997,65.61716324999999,259.3836158011105,2.555201261821961
1.0404126062822155e-06,0.0003736,67.64506675,259.3836158011105,2.555201261821961
1.0493240632953394e-06,0.0003768,68.22446775,259.3836158011105,2.555201261821961
1.1027928053740827e-06,0.000396,71.70087375,259.3836158011105,2.555201261821961
1.1362107691732975e-06,0.000408,73.8736275,259.3836158011105,2.555201261821961
1.1584894117061072e-06,0.000416,75.32213,259.3836158011105,2.555201261821961
1.178540189985636e-06,0.0004232,76.62578225,259.3836158011105,2.555201261821961
1.2097302895315696e-06,0.0004344,78.65368575,259.3836158011105,2.555201261821961
1.2453761175840653e-06,0.0004472,80.97128975,259.3836158011105,2.555201261821961
1.2854776741431229e-06,0.0004616,83.57859425,259.3836158011105,2.555201261821961
1.3166677736890566e-06,0.0004728,85.60649775,259.3836158011105,2.555201261821961
1.354541465994833e-06,0.0004864,88.068952,259.3836158011105,2.555201261821961
1.3835037012874855e-06,0.0004967999999999999,89.95200524999998,259.3836158011105,2.555201261821961
1.4369724433662292e-06,0.000516,93.42841125,259.3836158011105,2.555201261821961
1.4681625429121628e-06,0.0005272,95.45631475,259.3836158011105,2.555201261821961
1.4904411854449726e-06,0.0005352,96.90481725,259.3836158011105,2.555201261821961
1.6018343981090213e-06,0.0005752,104.14732975,259.3836158011105,2.555201261821961
1.6107458551221452e-06,0.0005784,104.72673074999999,259.3836158011105,2.555201261821961
1.637480226161517e-06,0.000588,106.46493375,259.3836158011105,2.555201261821961
1.6731260542140124e-06,0.0006008,108.78253774999999,259.3836158011105,2.555201261821961
1.6842653754804174e-06,0.0006048,109.506789,259.3836158011105,2.555201261821961
1.6998604252533841e-06,0.0006104,110.52074075,259.3836158011105,2.555201261821961
1.722139067786194e-06,0.0006184,111.96924324999999,259.3836158011105,2.555201261821961
1.7488734388255656e-06,0.000628,113.70744624999999,259.3836158011105,2.555201261821961
1.7733799456116563e-06,0.0006368,115.300799,259.3836158011105,2.555201261821961
1.7978864523977471e-06,0.0006456,116.89415174999999,259.3836158011105,2.555201261821961
1.8201650949305567e-06,0.0006536,118.34265425,259.3836158011105,2.555201261821961
1.891456751035548e-06,0.0006791999999999999,122.97786224999999,259.3836158011105,2.555201261821961
1.9115075293150767e-06,0.0006864,124.2815145,259.3836158011105,2.555201261821961
1.9560648143806963e-06,0.0007023999999999999,127.1785195,259.3836158011105,2.555201261821961
1.973887728406944e-06,0.0007088,128.3373215,259.3836158011105,2.555201261821961
2.0362679274988115e-06,0.0007312,132.3931285,259.3836158011105,2.555201261821961
2.071913755551307e-06,0.000744,134.7107325,259.3836158011105,2.555201261821961
2.14766114016286e-06,0.0007712,139.635641,259.3836158011105,2.555201261821961
2.167711918442389e-06,0.0007784,140.93929325,259.3836158011105,2.555201261821961
2.1989020179883225e-06,0.0007896,142.96719675,259.3836158011105,2.555201261821961
2.2189527962678514e-06,0.0007968,144.270849,259.3836158011105,2.555201261821961
2.2657379455867517e-06,0.0008135999999999999,147.31270425,259.3836158011105,2.555201261821961
2.2880165881195616e-06,0.0008215999999999999,148.76120674999999,259.3836158011105,2.555201261821961
2.423916307569701e-06,0.0008703999999999999,157.597072,259.3836158011105,2.555201261821961
2.435055628836106e-06,0.0008744,158.32132325,259.3836158011105,2.555201261821961
2.455106407115635e-06,0.0008816,159.6249755,259.3836158011105,2.555201261821961
2.492980099421411e-06,0.0008952,162.08742974999998,259.3836158011105,2.555201261821961
2.5174866062075023e-06,0.000904,163.6807825,259.3836158011105,2.555201261821961
2.5820946695526503e-06,0.0009272,167.88143975,259.3836158011105,2.555201261821961
2.6712092396838894e-06,0.0009592,173.67544975,259.3836158011105,2.555201261821961
2.738045167282319e-06,0.0009832,178.02095725,259.3836158011105,2.555201261821961
2.7647795383216907e-06,0.0009928,179.75916025,259.3836158011105,2.555201261821961
2.802653230627467e-06,0.0010064,182.2216145,259.3836158011105,2.555201261821961
2.813792551893872e-06,0.0010104,182.94586575000002,259.3836158011105,2.555201261821961
2.8271597374135577e-06,0.0010152,183.81496725,259.3836158011105,2.555201261821961
2.87840061523902e-06,0.0010336,187.146523,259.3836158011105,2.555201261821961
2.9207300360513585e-06,0.0010488,189.89867775,259.3836158011105,2.555201261821961
2.9363250858243257e-06,0.0010544,190.9126295,259.3836158011105,2.555201261821961
2.956375864103854e-06,0.0010616,192.21628175,259.3836158011105,2.555201261821961
2.9808823708899452e-06,0.0010704,193.8096345,259.3836158011105,2.555201261821961
3.0120724704358787e-06,0.0010816,195.83753800000002,259.3836158011105,2.555201261821961
3.0566297555014983e-06,0.0010976,198.734543,259.3836158011105,2.555201261821961
3.074452669527746e-06,0.001104,199.89334499999998,259.3836158011105,2.555201261821961
3.1034149048203985e-06,0.0011144,201.77639825,259.3836158011105,2.555201261821961
3.1301492758597707e-06,0.001124,203.51460125,259.3836158011105,2.555201261821961
3.2058966604713237e-06,0.0011512,204.1386550747122,259.3836158011105,2.555201261821961
3.2370867600172567e-06,0.0011623999999999998,204.2085548708999,259.3836158011105,2.555201261821961
3.2927833663492813e-06,0.0011824,204.3327261003027,259.3836158011105,2.555201261821961
3.35739142969443e-06,0.0012056,204.4757431114075,259.3836158011105,2.555201261821961
3.3752143437206776e-06,0.001212,204.5150066745823,259.3836158011105,2.555201261821961
3.4219994930395782e-06,0.0012288,204.61769072221736,259.3836158011105,2.555201261821961
3.450961728332231e-06,0.0012392,204.6809827223312,259.3836158011105,2.555201261821961
3.493291149144569e-06,0.0012544,204.77311503924997,259.3836158011105,2.555201261821961
3.5512156197298747e-06,0.0012752,204.8984883689748,259.3836158011105,2.555201261821961
3.593545040542213e-06,0.0012904,204.98960353495687,259.3836158011105,2.555201261821961
3.6425580541143945e-06,0.001308,205.09458400665937,259.3836158011105,2.555201261821961
3.693798931939857e-06,0.0013264,205.20374896717794,259.3836158011105,2.555201261821961
3.758406995285005e-06,0.0013495999999999998,205.34055358160725,259.3836158011105,2.555201261821961
3.805192144603906e-06,0.0013664,205.43904708130296,259.3836158011105,2.555201261821961
3.831926515643277e-06,0.0013759999999999998,205.49511702196466,259.3836158011105,2.555201261821961
3.863116615189211e-06,0.0013871999999999999,205.56033949428743,259.3836158011105,2.555201261821961
3.992332741879508e-06,0.0014336,205.82838763449496,259.3836158011105,2.555201261821961
4.054712940971375e-06,0.0014559999999999998,205.95657731256495,259.3836158011105,2.555201261821961
4.114865275809961e-06,0.0014776,206.0794623265778,259.3836158011105,2.555201261821961
4.1594225608755805e-06,0.0014935999999999999,206.17003706313707,259.3836158011105,2.555201261821961
4.195068388928077e-06,0.0015064,206.24222469407783,259.3836158011105,2.555201261821961
4.237397809740415e-06,0.0015216,206.32763753786932,259.3836158011105,2.555201261821961
4.2663600450330675e-06,0.001532,206.38588626666186,259.3836158011105,2.555201261821961
4.290866551819158e-06,0.0015408,206.43505330107845,259.3836158011105,2.555201261821961
4.315373058605249e-06,0.0015496,206.4841109413056,259.3836158011105,2.555201261821961
4.355474615164307e-06,0.0015639999999999999,206.56415336429936,259.3836158011105,2.555201261821961
4.377753257697117e-06,0.0015719999999999998,206.60849717136128,259.3836158011105,2.555201261821961
4.424538407016017e-06,0.0015888,206.7013337118816,259.3836158011105,2.555201261821961
4.433449864029141e-06,0.0015919999999999999,206.7189733727477,259.3836158011105,2.555201261821961
4.469095692081636e-06,0.0016048,206.78939417388492,259.3836158011105,2.555201261821961
4.500285791627571e-06,0.001616,206.85083287511154,259.3836158011105,2.555201261821961
4.596083954518653e-06,0.0016504,207.03850731844886,259.3836158011105,2.555201261821961
4.6696034748769246e-06,0.0016768,207.18150369016524,259.3836158011105,2.555201261821961
4.7208443527023865e-06,0.0016952,207.2806490139385,259.3836158011105,2.555201261821961
4.776540959034411e-06,0.0017151999999999998,207.38794084700004,259.3836158011105,2.555201261821961
4.907984949977988e-06,0.0017624,207.63923337047788,259.3836158011105,2.555201261821961
4.921352135497675e-06,0.0017672,207.66464062646372,259.3836158011105,2.555201261821961
4.992643791602666e-06,0.0017928,207.7996941408316,259.3836158011105,2.555201261821961
5.041656805174847e-06,0.0018104,207.89210745276148,259.3836158011105,2.555201261821961
5.1485942893323334e-06,0.0018487999999999998,208.09252896883658,259.3836158011105,2.555201261821961
5.202063031411077e-06,0.0018679999999999999,208.1921304244554,259.3836158011105,2.555201261821961
5.208746624170921e-06,0.0018704,208.20455247245536,259.3836158011105,2.555201261821961
5.288949737289035e-06,0.0018992,208.35313543661687,259.3836158011105,2.555201261821961
5.39143149293996e-06,0.001936,208.54171885323052,259.3836158011105,2.555201261821961
5.4114822712194895e-06,0.0019432,208.57845153019832,259.3836158011105,2.555201261821961
5.4515838277785464e-06,0.0019576,208.65175803021077,259.3836158011105,2.555201261821961
5.500596841350728e-06,0.0019752,208.74106988783856,259.3836158011105,2.555201261821961
5.538470533656504e-06,0.0019887999999999998,208.80987118764605,259.3836158011105,2.555201261821961
5.5807999544688425e-06,0.0020039999999999997,208.88654998701935,259.3836158011105,2.555201261821961
5.649863746320553e-06,0.0020288,209.01117234162413,259.3836158011105,2.555201261821961
5.66545879609352e-06,0.0020344,209.0392304829457,259.3836158011105,2.555201261821961
5.674370253106645e-06,0.0020376,209.0552501825181,259.3836158011105,2.555201261821961
5.6877374386263295e-06,0.0020423999999999998,209.07926134700097,259.3836158011105,2.555201261821961
5.721155402425545e-06,0.0020544,209.13919317437407,259.3836158011105,2.555201261821961
5.774624144504289e-06,0.0020736,209.2348009014661,259.3836158011105,2.555201261821961
5.8280928865830305e-06,0.0020927999999999997,209.3300639951769,259.3836158011105,2.555201261821961
5.84814366486256e-06,0.0021,209.36569970301144,259.3836158011105,2.555201261821961
5.879333764408493e-06,0.0021111999999999997,209.42103846085536,259.3836158011105,2.555201261821961
5.8949288141814605e-06,0.0021168,209.4486648960491,259.3836158011105,2.555201261821961
6.00632202684551e-06,0.0021568,209.64517424377567,259.3836158011105,2.555201261821961
6.097664461230029e-06,0.0021896,209.80525343933303,259.3836158011105,2.555201261821961
6.206829809640797e-06,0.0022288,209.99534602960563,259.3836158011105,2.555201261821961
6.313767293798285e-06,0.0022672,210.18029896291003,259.3836158011105,2.555201261821961
6.353868850357342e-06,0.0022816,210.24934082747004,259.3836158011105,2.555201261821961
6.407337592436085e-06,0.0023008,210.34113287210533,259.3836158011105,2.555201261821961
6.449667013248424e-06,0.002316,210.41358987969167,259.3836158011105,2.555201261821961
6.469717791527953e-06,0.0023232,210.44784686791027,259.3836158011105,2.555201261821961
6.496452162567324e-06,0.0023328,210.49345851292247,259.3836158011105,2.555201261821961
6.549920904646068e-06,0.002352,210.58446278307892,259.3836158011105,2.555201261821961
6.6412633390305876e-06,0.0023848,210.73926099903386,259.3836158011105,2.555201261821961
6.732605773415107e-06,0.0024176,210.89323107356742,259.3836158011105,2.555201261821961
6.766023737214322e-06,0.0024296,210.94935776147818,259.3836158011105,2.555201261821961
6.783846651240569e-06,0.002436,210.97924778380835,259.3836158011105,2.555201261821961
6.864049764358686e-06,0.0024648,211.11337568088913,259.3836158011105,2.555201261821961
6.959847927249767e-06,0.0024992,211.27278559591542,259.3836158011105,2.555201261821961
6.9910380267957e-06,0.0025104,211.3245015360324,259.3836158011105,2.555201261821961
7.017772397835072e-06,0.0025199999999999997,211.3687579058832,259.3836158011105,2.555201261821961
7.031139583354758e-06,0.0025248,211.39086143020464,259.3836158011105,2.555201261821961
7.060101818647411e-06,0.0025352,211.43869625616642,259.3836158011105,2.555201261821961
7.104659103713031e-06,0.0025512,211.51213913066994,259.3836158011105,2.555201261821961
7.122482017739278e-06,0.0025575999999999997,211.54146595642328,259.3836158011105,2.555201261821961
7.169267167058178e-06,0.0025743999999999997,211.61831302479752,259.3836158011105,2.555201261821961
7.258381737189418e-06,0.0026064,211.7641494826716,259.3836158011105,2.555201261821961
7.282888243975508e-06,0.0026152,211.804131874821,259.3836158011105,2.555201261821961
7.3073947507616e-06,0.002624,211.8440618312562,259.3836158011105,2.555201261821961
7.3385848503075325e-06,0.0026352,211.8948063242304,259.3836158011105,2.555201261821961
7.385369999626433e-06,0.002652,211.9707656383258,259.3836158011105,2.555201261821961
7.429927284692052e-06,0.002668,212.04293355953973,259.3836158011105,2.555201261821961
7.456661655731424e-06,0.0026776,212.08615329810922,259.3836158011105,2.555201261821961
7.461117384237987e-06,0.0026792,212.0933507084315,259.3836158011105,2.555201261821961
7.494535348037201e-06,0.0026912,212.14727795534878,259.3836158011105,2.555201261821961
7.576966325408597e-06,0.0027207999999999998,212.27989909092184,259.3836158011105,2.555201261821961
7.623751474727497e-06,0.0027375999999999998,212.35492021349853,259.3836158011105,2.555201261821961
7.668308759793117e-06,0.0027535999999999997,212.42620214816318,259.3836158011105,2.555201261821961
7.677220216806241e-06,0.0027568,212.44043913119216,259.3836158011105,2.555201261821961
7.69727099508577e-06,0.002764,212.47244879937946,259.3836158011105,2.555201261821961
7.735144687391547e-06,0.0027776,212.53282292044736,259.3836158011105,2.555201261821961
7.775246243950604e-06,0.0027919999999999998,212.59662293632232,259.3836158011105,2.555201261821961
7.830942850282628e-06,0.002812,212.68502158390763,259.3836158011105,2.555201261821961
7.868816542588405e-06,0.0028255999999999997,212.7449926501874,259.3836158011105,2.555201261821961
7.911145963400743e-06,0.0028407999999999997,212.81188607719108,259.3836158011105,2.555201261821961
7.99580480502542e-06,0.0028712,212.94525562916104,259.3836158011105,2.555201261821961
8.004716262038545e-06,0.0028744,212.95926241808144,259.3836158011105,2.555201261821961
8.026994904571353e-06,0.0028824,212.99425281042662,259.3836158011105,2.555201261821961
8.076007918143536e-06,0.0029,213.07109863145396,259.3836158011105,2.555201261821961
8.082691510903379e-06,0.0029024,213.08156349702796,259.3836158011105,2.555201261821961
8.140615981488685e-06,0.0029232,213.17211806686376,259.3836158011105,2.555201261821961
8.158438895514932e-06,0.0029295999999999997,213.19993041000345,259.3836158011105,2.555201261821961
8.19854045207399e-06,0.002944,213.26242168987525,259.3836158011105,2.555201261821961
8.229730551619923e-06,0.0029552,213.31094363942216,259.3836158011105,2.555201261821961
8.285427157951947e-06,0.0029752,213.3974119714804,259.3836158011105,2.555201261821961
8.305477936231477e-06,0.0029824,213.42848503877065,259.3836158011105,2.555201261821961
8.341123764283971e-06,0.0029952,213.4836539067522,259.3836158011105,2.555201261821961
8.38122532084303e-06,0.0030096,213.54560909474367,259.3836158011105,2.555201261821961
8.41018755613568e-06,0.0030199999999999997,213.59028263133513,259.3836158011105,2.555201261821961
8.436921927175054e-06,0.0030296,213.6314665179122,259.3836158011105,2.555201261821961
8.461428433961144e-06,0.0030383999999999997,213.66917372588196,259.3836158011105,2.555201261821961
8.572821646625194e-06,0.0030784,213.8400361621675,259.3836158011105,2.555201261821961
8.595100289158004e-06,0.0030864,213.87410450751753,259.3836158011105,2.555201261821961
8.715404958835174e-06,0.0031295999999999997,214.05748187951423,259.3836158011105,2.555201261821961
8.731000008608142e-06,0.0031352,214.08118053135766,259.3836158011105,2.555201261821961
8.753278651140953e-06,0.0031432,214.11500713095032,259.3836158011105,2.555201261821961
8.768873700913919e-06,0.0031487999999999998,214.1386657752243,259.3836158011105,2.555201261821961
8.775557293673762e-06,0.0031512,214.14880017023376,259.3836158011105,2.555201261821961
8.857988271045157e-06,0.0031807999999999997,214.2735445562591,259.3836158011105,2.555201261821961
8.911457013123901e-06,0.0031999999999999997,214.3542178292606,259.3836158011105,2.555201261821961
8.924824198643587e-06,0.0032048,214.37435662424477,259.3836158011105,2.555201261821961
9.011710904521546e-06,0.0032359999999999997,214.50497322648508,259.3836158011105,2.555201261821961
9.040673139814198e-06,0.0032464,214.54840282983616,259.3836158011105,2.555201261821961
9.060723918093727e-06,0.0032535999999999997,214.57843769801497,259.3836158011105,2.555201261821961
9.100825474652784e-06,0.0032679999999999996,214.63842978309393,259.3836158011105,2.555201261821961
9.120876252932312e-06,0.0032752,214.66838715855422,259.3836158011105,2.555201261821961
9.20776295881027e-06,0.0033063999999999997,214.79790678752315,259.3836158011105,2.555201261821961
9.245636651116048e-06,0.00332,214.85421479835836,259.3836158011105,2.555201261821961
9.301333257448072e-06,0.0033399999999999997,214.9368575549469,259.3836158011105,2.555201261821961
9.328067628487443e-06,0.0033496,214.97645750607794,259.3836158011105,2.555201261821961
9.354801999526815e-06,0.0033591999999999997,215.01601321920123,259.3836158011105,2.555201261821961
9.421637927125245e-06,0.0033832,215.11471011037517,259.3836158011105,2.555201261821961
9.515208225763046e-06,0.0034168,215.25242825215477,259.3836158011105,2.555201261821961
9.54862618956226e-06,0.0034287999999999996,215.30148517114256,259.3836158011105,2.555201261821961
9.568676967841788e-06,0.003436,215.33088718362384,259.3836158011105,2.555201261821961
9.61546211716069e-06,0.0034528,215.39939859511682,259.3836158011105,2.555201261821961
9.642196488200061e-06,0.0034624,215.4384896016277,259.3836158011105,2.555201261821961
9.666702994986151e-06,0.0034712,215.4742859070132,259.3836158011105,2.555201261821961
9.6845259090124e-06,0.0034776,215.50029735778068,259.3836158011105,2.555201261821961
9.715716008558332e-06,0.0034888,215.54577251821732,259.3836158011105,2.555201261821961
9.773640479143638e-06,0.0035096,215.63007562103718,259.3836158011105,2.555201261821961
9.807058442942852e-06,0.0035215999999999997,215.67862338916137,259.3836158011105,2.555201261821961
9.824881356969101e-06,0.003528,215.70448914987742,259.3836158011105,2.555201261821961
9.900628741580653e-06,0.0035551999999999997,215.81421510516563,259.3836158011105,2.555201261821961
9.91399592710034e-06,0.00356,215.8335444741364,259.3836158011105,2.555201261821961
9.947413890899555e-06,0.0035719999999999997,215.88182348140475,259.3836158011105,2.555201261821961
9.98305971895205e-06,0.0035848,215.9332514211443,259.3836158011105,2.555201261821961
1.0018705547004546e-05,0.0035976,215.9846077947557,259.3836158011105,2.555201261821961
1.0081085746096413e-05,0.00362,216.07431030471622,259.3836158011105,2.555201261821961
1.0112275845642348e-05,0.0036312,216.1190803626415,259.3836158011105,2.555201261821961
1.012118730265547e-05,0.0036344,216.13186191200543,259.3836158011105,2.555201261821961
1.0134554488175158e-05,0.0036392,216.15102600976888,259.3836158011105,2.555201261821961
1.0181339637494057e-05,0.003656,216.21802285846965,259.3836158011105,2.555201261821961
1.0250403429345767e-05,0.0036807999999999997,216.3167039440568,259.3836158011105,2.555201261821961
1.0265998479118734e-05,0.0036864,216.33895084315247,259.3836158011105,2.555201261821961
1.0350657320743411e-05,0.0037167999999999997,216.4594905252953,259.3836158011105,2.555201261821961
1.0372935963276221e-05,0.0037248,216.49114751109428,259.3836158011105,2.555201261821961
1.0428632569608245e-05,0.0037448,216.57017418558024,259.3836158011105,2.555201261821961
1.0491012768700112e-05,0.0037671999999999996,216.6584889034816,259.3836158011105,2.555201261821961
1.050660781847308e-05,0.0037727999999999998,216.6805355540364,259.3836158011105,2.555201261821961
1.0580127338831352e-05,0.0037992,216.78429834925558,259.3836158011105,2.555201261821961
1.0629140352403534e-05,0.0038168,216.85331736588924,259.3836158011105,2.555201261821961
1.064696326642978e-05,0.0038231999999999997,216.87838440198425,259.3836158011105,2.555201261821961
1.0671469773215872e-05,0.003832,216.9128248718236,259.3836158011105,2.555201261821961
1.0707115601268368e-05,0.0038447999999999998,216.9628650889208,259.3836158011105,2.555201261821961
1.085192677773163e-05,0.0038967999999999997,217.1654889210862,259.3836158011105,2.555201261821961
1.0925446298089903e-05,0.0039232,217.2679557120097,259.3836158011105,2.555201261821961
1.1021244460980984e-05,0.0039575999999999995,217.40107045731912,259.3836158011105,2.555201261821961
1.1068029610299884e-05,0.0039743999999999995,217.46591592059,259.3836158011105,2.555201261821961
1.1090308252832695e-05,0.0039824,217.4967571320491,259.3836158011105,2.555201261821961
1.1117042623872067e-05,0.003992,217.5337347097445,259.3836158011105,2.555201261821961
1.1192800704371214e-05,0.004019203840768154,217.63833139850996,259.3836158011105,2.555201261821961
1.188803339793359e-05,0.004268853770754151,218.58565832054362,259.3836158011105,2.555201261821961
1.3813293164721712e-05,0.004960192038407682,221.10234683021636,259.3836158011105,2.555201261821961
1.4936361362014783e-05,0.005363472694538908,222.50710471242553,259.3836158011105,2.555201261821961
1.5096799675913792e-05,0.005421084216843369,222.7043683175643,259.3836158011105,2.555201261821961
1.6861621128802902e-05,0.0060548109621924385,224.82289753314626,259.3836158011105,2.555201261821961
1.7503374384398942e-05,0.006285257051410282,225.57158157633324,259.3836158011105,2.555201261821961
1.974951077898508e-05,0.007091818363672734,228.11155257404673,259.3836158011105,2.555201261821961
2.0712140662379142e-05,0.0074374874974994995,229.1653004507162,259.3836158011105,2.555201261821961
2.1781729421705874e-05,0.007821564312862572,230.31397396752675,259.3836158011105,2.555201261821961
2.2744359305099936e-05,0.008167233446689338,231.32910048733882,259.3836158011105,2.555201261821961
2.4562660195955382e-05,0.008820164032806561,233.2019588583768,259.3836158011105,2.555201261821961
2.5632248955282118e-05,0.009204240848169634,234.27837336456645,259.3836158011105,2.555201261821961
2.606008445901281e-05,0.009357871574314863,234.70401634983585,259.3836158011105,2.555201261821961
2.6648358276642515e-05,0.009569113822764553,235.2848520473932,259.3836158011105,2.555201261821961
2.830622085359895e-05,0.010164432886577316,236.89544168219646,259.3836158011105,2.555201261821961
2.8627097481396973e-05,0.010279655931186238,237.2028733221476,259.3836158011105,2.555201261821961
3.076627500005044e-05,0.011047809561912383,239.21911273919503,259.3836158011105,2.555201261821961
3.183586375937718e-05,0.011431886377275456,240.20666633215308,259.3836158011105,2.555201261821961
3.221021982514153e-05,0.01156631326265253,240.5492418115664,259.3836158011105,2.555201261821961
3.467027397159302e-05,0.012449689937987597,242.76301514409957,259.3836158011105,2.555201261821961
3.590030104481876e-05,0.012891378275655131,243.8468560321838,259.3836158011105,2.555201261821961
3.766512249770787e-05,0.013525105021004201,245.37696643274683,259.3836158011105,2.555201261821961
3.809295800143856e-05,0.01367873574714943,245.74365970502012,259.3836158011105,2.555201261821961
3.846731406720292e-05,0.013813162632526505,246.0632007304232,259.3836158011105,2.555201261821961
3.932298507466431e-05,0.014120424084816964,246.78906063477643,259.3836158011105,2.555201261821961
4.23713130387455e-05,0.015215043008601721,249.32631339561718,259.3836158011105,2.555201261821961
4.322698404620689e-05,0.01552230446089218,250.02559403448817,259.3836158011105,2.555201261821961
4.381525786383659e-05,0.01573354670934187,250.50322090299403,259.3836158011105,2.555201261821961
4.563355875469203e-05,0.01638647729545909,251.9639512057327,259.3836158011105,2.555201261821961
4.846796896690787e-05,0.017404280856171232,254.1964836384396,259.3836158011105,2.555201261821961
4.975147547809995e-05,0.01786517303460692,255.19062908349093,259.3836158011105,2.555201261821961
5.226500906251778e-05,0.018767753550710142,257.1089852569096,259.3836158011105,2.555201261821961
5.2799803442181147e-05,0.01895979195839168,257.5124649413659,259.3836158011105,2.555201261821961
5.509941927473362e-05,0.019785557111422283,259.2295750199477,259.3836158011105,2.555201261821961
5.5848131406262334e-05,0.020054410882176434,259.7825721929022,259.3836158011105,2.555201261821961
5.648988466185838e-05,0.020284856971394278,260.2542724284035,259.3836158011105,2.555201261821961
5.825470611474749e-05,0.02091858371674335,261.54079276405787,259.3836158011105,2.555201261821961
5.9324294874074224e-05,0.021302660532106422,262.3131062758587,259.3836158011105,2.555201261821961
6.119607520289601e-05,0.021974794958991798,263.651712779114,259.3836158011105,2.555201261821961
6.178434902052571e-05,0.02218603720744149,264.0691071108833,259.3836158011105,2.555201261821961
6.258654059002076e-05,0.022474094818963793,264.63579193386573,259.3836158011105,2.555201261821961
6.290741721781878e-05,0.022589317863572714,264.86167184462107,259.3836158011105,2.555201261821961
6.392352653917918e-05,0.022954190838167635,265.57401176107226,259.3836158011105,2.555201261821961
6.477919754664057e-05,0.023261452290458094,266.1704582655425,259.3836158011105,2.555201261821961
6.670445731342868e-05,0.02395279055811162,267.5013414070982,259.3836158011105,2.555201261821961
6.718577225512572e-05,0.024125625125025005,267.83171090993653,259.3836158011105,2.555201261821961
6.756012832089007e-05,0.02426005201040208,268.08802723800306,259.3836158011105,2.555201261821961
6.798796382462077e-05,0.02441368273654731,268.38028290908824,259.3836158011105,2.555201261821961
6.996670302937522e-05,0.025124224844968995,269.72274367311934,259.3836158011105,2.555201261821961
7.119673010260096e-05,0.025565913182636527,270.54978678989806,259.3836158011105,2.555201261821961
7.365678424905245e-05,0.026449289857971594,272.1873415241198,259.3836158011105,2.555201261821961
7.515420851210987e-05,0.026986997399479896,273.1736740343942,259.3836158011105,2.555201261821961
7.53146468260089e-05,0.02704460892178436,273.278895929039,259.3836158011105,2.555201261821961
7.670511221313365e-05,0.027543908781756353,274.18718609923417,259.3836158011105,2.555201261821961
7.740034490669602e-05,0.02779355871174235,274.6389214967653,259.3836158011105,2.555201261821961
7.82560159141574e-05,0.028100820164032807,275.1927369719223,259.3836158011105,2.555201261821961
7.916516635958513e-05,0.02842728545709142,275.7785844879055,259.3836158011105,2.555201261821961
7.980691961518117e-05,0.02865773154630926,276.19054514666436,259.3836158011105,2.555201261821961
8.071607006060889e-05,0.028984196839367874,276.7719513423427,259.3836158011105,2.555201261821961
8.08765083745079e-05,0.029041808361672333,276.8742867542766,259.3836158011105,2.555201261821961
8.274828870332969e-05,0.029713942788557712,278.06240870910625,259.3836158011105,2.555201261821961
8.381787746265642e-05,0.030098019603920785,278.73662891605125,259.3836158011105,2.555201261821961
8.520834284978117e-05,0.03059731946389278,279.6081199252915,259.3836158011105,2.555201261821961
8.601053441927622e-05,0.030885377075415082,280.1083801544915,259.3836158011105,2.555201261821961
8.702664374063662e-05,0.03125025005001,280.73943859154616,259.3836158011105,2.555201261821961
8.825667081386236e-05,0.03169193838767753,281.49951970649687,259.3836158011105,2.555201261821961
8.863102687962674e-05,0.031826365273054616,281.73002724824045,259.3836158011105,2.555201261821961
8.905886238335743e-05,0.031979995999199845,281.9930000017986,259.3836158011105,2.555201261821961
9.146543709184257e-05,0.03284416883376676,283.46314298613163,259.3836158011105,2.555201261821961
9.269546416506831e-05,0.033285857171434285,284.2087184150314,259.3836158011105,2.555201261821961
9.504855943558712e-05,0.034130826165233046,285.6243721934574,259.3836158011105,2.555201261821961
9.579727156711582e-05,0.03439967993598719,286.0719323265663,259.3836158011105,2.555201261821961
9.649250426067821e-05,0.034649329865973195,286.48630389461687,259.3836158011105,2.555201261821961
9.724121639220691e-05,0.03491818363672734,286.93125017970175,259.3836158011105,2.555201261821961
9.873864065526437e-05,0.03545589117823565,287.8171545839695,259.3836158011105,2.555201261821961
9.938039391086039e-05,0.03568633726745349,288.19522216404187,259.3836158011105,2.555201261821961
0.0001001291060423891,0.03595519103820764,288.6350997073992,259.3836158011105,2.555201261821961
0.00010066390042205247,0.036147229445889176,288.94851294089676,259.3836158011105,2.555201261821961
0.00010162653030544652,0.03649289857971594,289.51102522410423,259.3836158011105,2.555201261821961
0.00010280307794070594,0.03691538307661532,290.19572612428163,259.3836158011105,2.555201261821961
0.00010328439288240298,0.03708821764352871,290.47494939018526,259.3836158011105,2.555201261821961
0.00010456789939359506,0.037549109821964397,291.2170748955241,259.3836158011105,2.555201261821961
0.00010531661152512379,0.03781796359271855,291.6483408569836,259.3836158011105,2.555201261821961
0.00010611880309461882,0.03810602120424085,292.1090867868041,259.3836158011105,2.555201261821961
0.00010793710398547426,0.03875895179035807,293.14844471371526,259.3836158011105,2.555201261821961
0.00010836493948920496,0.0389125825165033,293.39200445085004,259.3836158011105,2.555201261821961
0.00010922061049666634,0.03921984396879376,293.8780017646129,259.3836158011105,2.555201261821961
0.00011264329452651189,0.04044888977795559,295.80732288027957,259.3836158011105,2.555201261821961
0.00011456855429330003,0.04114022804560913,296.8825154056148,259.3836158011105,2.555201261821961
0.00011606597855635744,0.04167793558711742,297.7139119093079,259.3836158011105,2.555201261821961
0.00011815167663704456,0.04242688537707541,298.864990727671,259.3836158011105,2.555201261821961
0.00011986301865196733,0.043041408281656326,299.80355827754545,259.3836158011105,2.555201261821961
0.00012077216909739506,0.043367873574714944,300.3000458911138,259.3836158011105,2.555201261821961
0.00012312526436791387,0.0442128425685137,301.5783509513052,259.3836158011105,2.555201261821961
0.00012424833256520696,0.044616123224644935,302.1850890946132,259.3836158011105,2.555201261821961
0.00012633403064589408,0.04536507301460292,303.30624401983215,259.3836158011105,2.555201261821961
0.0001277779754709852,0.04588357671534307,304.0782029720004,259.3836158011105,2.555201261821961
0.0001284197287265812,0.04611402280456091,304.42020300660704,259.3836158011105,2.555201261821961
0.00012868712591641287,0.046210042008401675,304.56250622423755,259.3836158011105,2.555201261821961
0.00013071934455913367,0.04693978795759152,305.64026728833267,259.3836158011105,2.555201261821961
0.00013152153612862875,0.04722784556911383,306.06389803301136,259.3836158011105,2.555201261821961
0.00013323287814355153,0.047842368473694746,306.9642903174739,259.3836158011105,2.555201261821961
0.00013408854915101292,0.048149629925985205,307.4127942060564,259.3836158011105,2.555201261821961
0.00013489074072050797,0.048437687537507504,307.8322539218974,259.3836158011105,2.555201261821961
0.00013521161734830598,0.04855291058211643,307.99976527167746,259.3836158011105,2.555201261821961
0.00013665556217339704,0.049071414282856565,308.75165599235595,259.3836158011105,2.555201261821961
0.0001379390686845891,0.04953230646129225,309.4174060332796,259.3836158011105,2.555201261821961
0.00013906213688188223,0.04993558711742349,309.99795798782145,259.3836158011105,2.555201261821961
0.00013991780788934362,0.05024284856971395,310.4390567986267,259.3836158011105,2.555201261821961
0.0001403456433930743,0.05039647929585918,310.6592115970591,259.3836158011105,2.555201261821961
0.00014104087608663669,0.050646129225845174,311.01640572320315,259.3836158011105,2.555201261821961
0.0001412013144005357,0.05070374074814964,311.0987375424685,259.3836158011105,2.555201261821961
0.00014205698540799709,0.051011002200440095,311.53722594208233,259.3836158011105,2.555201261821961
0.0001425383003496941,0.05118383676735347,311.7834229762368,259.3836158011105,2.555201261821961
0.00014392876573681882,0.05168313662732546,312.49284413650236,259.3836158011105,2.555201261821961
0.00014521227224801092,0.05214402880576115,313.1453256580583,259.3836158011105,2.555201261821961
0.00014585402550360696,0.052374474894979,313.47072268916617,259.3836158011105,2.555201261821961
0.00014633534044530402,0.052547309461892386,313.7144041538866,259.3836158011105,2.555201261821961
0.00014911627121955352,0.05354590918183637,315.11626897403227,259.3836158011105,2.555201261821961
0.00014933018897141884,0.053622724544908976,315.2236805532451,259.3836158011105,2.555201261821961
0.00015061369548261092,0.05408361672334466,315.86689435483936,259.3836158011105,2.555201261821961
0.00015109501042430797,0.05425645129025805,316.1075479476318,259.3836158011105,2.555201261821961
0.00015168328424193766,0.05446769353870774,316.40127448401165,259.3836158011105,2.555201261821961
0.0001524319963734664,0.0547365473094619,316.7744665119863,259.3836158011105,2.555201261821961
0.00015473161220601886,0.055562312462492505,317.91625444009776,259.3836158011105,2.555201261821961
0.00015564076265144657,0.05588877775555111,318.3658312111653,259.3836158011105,2.555201261821961
0.0001562290364690763,0.0561000200040008,318.6561881630751,259.3836158011105,2.555201261821961
0.00015767298129416737,0.05661852370474095,319.36708059607827,259.3836158011105,2.555201261821961
0.00015820777567383075,0.05681056211242248,319.62972918689195,259.3836158011105,2.555201261821961
0.00015965172049892183,0.05732906581316263,320.33715654058943,259.3836158011105,2.555201261821961
0.00016302092509080102,0.05853890778155631,321.97818679575744,259.3836158011105,2.555201261821961
0.00016398355497419513,0.05888457691538308,322.44461617739154,259.3836158011105,2.555201261821961
0.00016462530822979114,0.05911502300460092,322.7549759879588,259.3836158011105,2.555201261821961
0.00016665752687251194,0.05984476895379076,323.7346836121018,259.3836158011105,2.555201261821961
0.00016692492406234361,0.05994078815763153,323.86324477207177,259.3836158011105,2.555201261821961
0.00016831538944946838,0.06044008801760352,324.5304725047193,259.3836158011105,2.555201261821961
0.00017008021090235748,0.061073814762952594,325.374250839256,259.3836158011105,2.555201261821961
0.0001720054706691456,0.06176515303060612,326.2908514300718,259.3836158011105,2.555201261821961
0.00017270070336270797,0.062014802960592114,326.6208616401492,259.3836158011105,2.555201261821961
0.00017409116874983274,0.06251410282056412,327.279331806117,259.3836158011105,2.555201261821961
0.00017425160706373177,0.06257171434286858,327.355176919815,259.3836158011105,2.555201261821961
0.00017494683975729413,0.06282136427285458,327.6835248692466,259.3836158011105,2.555201261821961
0.0001764977434583179,0.06337827565513103,328.41416511022464,259.3836158011105,2.555201261821961
0.0001768186200861159,0.06349349869973994,328.5650189671545,259.3836158011105,2.555201261821961
0.0001773534144657793,0.06368553710742149,328.81620502176526,259.3836158011105,2.555201261821961
0.00017820908547324068,0.06399279855971195,329.2174891548187,259.3836158011105,2.555201261821961
0.00017895779760476936,0.06426165233046609,329.567996759794,259.3836158011105,2.555201261821961
0.0001801878246779951,0.06470334066813363,330.1425916639612,259.3836158011105,2.555201261821961
0.00018099001624749016,0.06499139827965593,330.51650350919215,259.3836158011105,2.555201261821961
0.00018184568725495155,0.06529865973194639,330.9146311163372,259.3836158011105,2.555201261821961
0.00018211308444478322,0.06539467893578715,331.03889607223743,259.3836158011105,2.555201261821961
0.0001828083171383456,0.06564432886577315,331.3616523908841,259.3836158011105,2.555201261821961
0.00018345007039394167,0.065874774954991,331.6591566650905,259.3836158011105,2.555201261821961
0.00018425226196343668,0.0661628325665133,332.0304668438065,259.3836158011105,2.555201261821961
0.00018558924791259513,0.06664292858571715,332.64791914778516,259.3836158011105,2.555201261821961
0.0001867123161098882,0.06704620924184837,333.1652396077117,259.3836158011105,2.555201261821961
0.00018740754880345055,0.06729585917183437,333.4848775210513,259.3836158011105,2.555201261821961
0.0001897606440739694,0.06814082816563313,334.56331389850607,259.3836158011105,2.555201261821961
0.0001909371917092288,0.06856331266253252,335.10057536773786,259.3836158011105,2.555201261821961
0.00019120458889906048,0.06865933186637328,335.2225000011569,259.3836158011105,2.555201261821961
0.0001916859038407575,0.06883216643328666,335.44179689637144,259.3836158011105,2.555201261821961
0.00019238113653431986,0.06908181636327265,335.75818032972904,259.3836158011105,2.555201261821961
0.00019302288978991592,0.0693122624524905,336.0498310257692,259.3836158011105,2.555201261821961
0.00019387856079737732,0.06961952390478096,336.4381110372963,259.3836158011105,2.555201261821961
0.00019409247854924264,0.06969633926785357,336.5350765441487,259.3836158011105,2.555201261821961
0.00019505510843263673,0.07004200840168034,336.97090657379283,259.3836158011105,2.555201261821961
0.00019655253269569415,0.07057971594318864,337.64720075783833,259.3836158011105,2.555201261821961
0.00019687340932349217,0.07069493898779756,337.79185917472654,259.3836158011105,2.555201261821961
0.00019906606628011198,0.07148229645929187,338.7779089208136,259.3836158011105,2.555201261821961
0.0001992799840319773,0.07155911182236448,338.8738815517652,259.3836158011105,2.555201261821961
0.0002031839830035199,0.0729609921984397,340.61838575363004,259.3836158011105,2.555201261821961
0.00020591143433980306,0.07394038807761552,341.829400187476,259.3836158011105,2.555201261821961
0.00020649970815743275,0.07415163032606521,342.0897773629769,259.3836158011105,2.555201261821961
0.0002069810230991298,0.0743244648929786,342.30259812994797,259.3836158011105,2.555201261821961
0.00020853192680015355,0.07488137627525505,342.98704471919876,259.3836158011105,2.555201261821961
0.0002094410772455813,0.07520784156831367,343.38734905603803,259.3836158011105,2.555201261821961
0.00020997587162524466,0.0753998799759952,343.62250563410066,259.3836158011105,2.555201261821961
0.00021099198094660506,0.07576475295059013,344.0686606141176,259.3836158011105,2.555201261821961
0.00021286376127542685,0.0764368873774755,344.888337636156,259.3836158011105,2.555201261821961
0.00021650036305713772,0.07774274854970994,346.4728611283624,259.3836158011105,2.555201261821961
0.00021789082844426248,0.07824204840968194,347.0759608873939,259.3836158011105,2.555201261821961
0.00021970912933511795,0.07889497899579917,347.862369855602,259.3836158011105,2.555201261821961
0.000220671759218512,0.07924064812962593,348.2776762240256,259.3836158011105,2.555201261821961
0.00022136699191207436,0.07949029805961193,348.5771804222549,259.3836158011105,2.555201261821961
0.0002221691834815694,0.07977835567113423,348.92230672412165,259.3836158011105,2.555201261821961
0.00022281093673716547,0.08000880176035208,349.1980579736302,259.3836158011105,2.555201261821961
0.00022350616943072783,0.08025845169033807,349.4964391822149,259.3836158011105,2.555201261821961
0.00022382704605852587,0.080373674734947,349.6340314796302,259.3836158011105,2.555201261821961
0.00022548490863548228,0.08096899379875976,350.3437032289282,259.3836158011105,2.555201261821961
0.00022666145627074172,0.08139147829565914,350.8461072635317,259.3836158011105,2.555201261821961
0.0002289610721032942,0.08221724344868975,351.8251517590956,259.3836158011105,2.555201261821961
0.00022949586648295754,0.08240928185637128,352.0522860041468,259.3836158011105,2.555201261821961
0.00023072589355618327,0.08285097019403881,352.57391284106143,259.3836158011105,2.555201261821961
0.00023136764681177933,0.08308141628325666,352.84563537790467,259.3836158011105,2.555201261821961
0.00023184896175347633,0.08325425085017003,353.04923442586687,259.3836158011105,2.555201261821961
0.0002329720299507694,0.08365753150630126,353.5236589021413,259.3836158011105,2.555201261821961
0.00023521816634535558,0.08446409281856372,354.4698404827508,259.3836158011105,2.555201261821961
0.00023569948128705258,0.0846369273854771,354.6721344877493,259.3836158011105,2.555201261821961
0.00023660863173248031,0.08496339267853571,355.0538063618825,259.3836158011105,2.555201261821961
0.00023826649430943675,0.08555871174234847,355.7483270653334,259.3836158011105,2.555201261821961
0.0002389617270029991,0.08580836167233447,356.0390165007403,259.3836158011105,2.555201261821961
0.00024045915126605656,0.08634606921384277,356.6639989262847,259.3836158011105,2.555201261821961
0.00024142178114945062,0.08669173834766954,357.0649719552105,259.3836158011105,2.555201261821961
0.0002431331231643734,0.08730626125225045,357.776276689321,259.3836158011105,2.555201261821961
0.0002460210128145556,0.08834326865373075,358.9721916302689,259.3836158011105,2.555201261821961
0.00024666276607015163,0.08857371474294859,359.23720555181677,259.3836158011105,2.555201261821961
0.0002488554230267714,0.0893610722144429,360.1406477661412,259.3836158011105,2.555201261821961
0.00025094112110745856,0.09011002200440088,360.99714294399837,259.3836158011105,2.555201261821961
0.0002515828743630546,0.09034046809361873,361.2601207848484,259.3836158011105,2.555201261821961
0.0002523315864945833,0.09060932186437289,361.56659783634024,259.3836158011105,2.555201261821961
0.0002528129014362803,0.09078215643128626,361.763431534769,259.3836158011105,2.555201261821961
0.0002536150930057754,0.09107021404280857,362.0911632353833,259.3836158011105,2.555201261821961
0.00025425684626137143,0.09130066013202641,362.353057605475,259.3836158011105,2.555201261821961
0.00025489859951696747,0.09153110622124426,362.61469430013733,259.3836158011105,2.555201261821961
0.00025548687333459716,0.09174234846969394,362.8543023460858,259.3836158011105,2.555201261821961
0.0002569842975976546,0.09228005601120225,363.4632448433988,259.3836158011105,2.555201261821961
0.000258160845232914,0.09270254050810163,363.9407294077986,259.3836158011105,2.555201261821961
0.00025896303680240907,0.09299059811962393,364.2658005822411,259.3836158011105,2.555201261821961
0.0002605139405034328,0.09354750950190038,364.89316009498185,259.3836158011105,2.555201261821961
0.00026115569375902885,0.09377795559111823,365.1523308755951,259.3836158011105,2.555201261821961
0.0002625461591461536,0.09427725545109022,365.71301701531496,259.3836158011105,2.555201261821961
0.0002634553095915813,0.09460372074414883,366.0789934519912,259.3836158011105,2.555201261821961
0.0002638296656573457,0.09473814762952591,366.2295464312373,259.3836158011105,2.555201261821961
0.00026452489835090807,0.09498779755951191,366.50892397092287,259.3836158011105,2.555201261821961
0.00026479229554073974,0.09508381676335267,366.6163006016868,259.3836158011105,2.555201261821961
0.00026580840486210014,0.0954486897379476,367.0239467041523,259.3836158011105,2.555201261821961
0.00026639667867972984,0.09565993198639729,367.2596745647898,259.3836158011105,2.555201261821961
0.0002674662674390566,0.09604400880176035,367.68775121381157,259.3836158011105,2.555201261821961
0.00026784062350482094,0.09617843568713744,367.8374202468423,259.3836158011105,2.555201261821961
0.00026842889732245064,0.09638967793558713,368.0724497143814,259.3836158011105,2.555201261821961
0.0002700867598994071,0.09698499699939989,368.73372716559913,259.3836158011105,2.555201261821961
0.00027099591034483484,0.0973114622924585,369.0956910310543,259.3836158011105,2.555201261821961
0.00027185158135229615,0.09761872374474895,369.43593052456873,259.3836158011105,2.555201261821961
0.00027206549910416153,0.09769553910782157,369.5209251069694,259.3836158011105,2.555201261821961
0.00027356292336721893,0.09823324664932986,370.1151591131896,259.3836158011105,2.555201261821961
0.000274846429878411,0.09869413882776555,370.6234935863729,259.3836158011105,2.555201261821961
0.0002754881831340071,0.0989245849169834,370.8773135837093,259.3836158011105,2.555201261821961
0.0002765042924553675,0.09928945789157832,371.2787241510064,259.3836158011105,2.555201261821961
0.00027762736065266053,0.09969273854770955,371.7217197390313,259.3836158011105,2.555201261821961
0.0002781086755943576,0.09986557311462294,371.9113609848487,259.3836158011105,2.555201261821961
0.00027837607278418926,0.0999615923184637,372.01666192253214,259.3836158011105,2.555201261821961