File: datasets/aisi_316_L/data/M1/train_4.csv
Time(s),Strain(%),Stress(MPa),Temp(C),Log_SR(s-1)
0.0,0.0,0.0,366.1580058403257,-1.8259528734630956
0.0018754733823408633,2.8e-05,4.8193494999999995,366.1580058403257,-1.8259528734630956
0.002679247689058376,3.9999999999999996e-05,6.884784999999999,366.1580058403257,-1.8259528734630956
0.003911701626025229,5.8399999999999997e-05,10.0517861,366.1580058403257,-1.8259528734630956
0.005251325470554417,7.84e-05,13.4941786,366.1580058403257,-1.8259528734630956
0.00605509977727193,9.04e-05,15.559614100000001,366.1580058403257,-1.8259528734630956
0.00669811922264594,9.999999999999999e-05,17.2119625,366.1580058403257,-1.8259528734630956
0.008520007651205636,0.0001272,21.8936163,366.1580058403257,-1.8259528734630956
0.009645291680610155,0.000144,24.785226,366.1580058403257,-1.8259528734630956
0.010449065987327668,0.000156,26.8506615,366.1580058403257,-1.8259528734630956
0.011145670386482844,0.00016639999999999998,28.640705599999997,366.1580058403257,-1.8259528734630956
0.012056614600762692,0.00017999999999999998,30.981532499999997,366.1580058403257,-1.8259528734630956
0.012431709277230864,0.00018559999999999998,31.9454024,366.1580058403257,-1.8259528734630956
0.015378881735195079,0.0002296,39.5186659,366.1580058403257,-1.8259528734630956
0.016932845394848937,0.00025279999999999996,43.51184119999999,366.1580058403257,-1.8259528734630956
0.01736152502509828,0.0002592,44.6134068,366.1580058403257,-1.8259528734630956
0.019397753268782642,0.0002896,49.8458434,366.1580058403257,-1.8259528734630956
0.0206302072057495,0.000308,53.0128445,366.1580058403257,-1.8259528734630956
0.022398510680528026,0.0003344,57.5568026,366.1580058403257,-1.8259528734630956
0.02255926554187153,0.0003368,57.9698897,366.1580058403257,-1.8259528734630956
0.022827190310777366,0.0003408,58.6583682,366.1580058403257,-1.8259528734630956
0.02352379470993254,0.00035119999999999997,60.448412299999994,366.1580058403257,-1.8259528734630956
0.023845304432619546,0.000356,61.2745865,366.1580058403257,-1.8259528734630956
0.024595493785555894,0.0003672,63.202326299999996,366.1580058403257,-1.8259528734630956
0.026095872491428584,0.0003896,67.05780589999999,366.1580058403257,-1.8259528734630956
0.02727474147461427,0.0004072,70.08711129999999,366.1580058403257,-1.8259528734630956
0.02791776091998828,0.0004168,71.7394597,366.1580058403257,-1.8259528734630956
0.029096629903173965,0.0004344,74.7687651,366.1580058403257,-1.8259528734630956
0.029686064394766808,0.0004432,76.2834178,366.1580058403257,-1.8259528734630956
0.030329083840140818,0.0004528,77.9357662,366.1580058403257,-1.8259528734630956
0.03156153777710767,0.00047119999999999996,81.1027673,366.1580058403257,-1.8259528734630956
0.03241889703760635,0.000484,83.3058985,366.1580058403257,-1.8259528734630956
0.03300833152919919,0.0004927999999999999,84.8205512,366.1580058403257,-1.8259528734630956
0.033597766020792036,0.0005015999999999999,86.3352039,366.1580058403257,-1.8259528734630956
0.034026445651041376,0.000508,87.4367695,366.1580058403257,-1.8259528734630956
0.034455125281290716,0.0005143999999999999,88.53833509999998,366.1580058403257,-1.8259528734630956
0.0354732394031329,0.0005296,91.1545534,366.1580058403257,-1.8259528734630956
0.03756305260059843,0.0005608,96.52468569999999,366.1580058403257,-1.8259528734630956
0.03906343130647112,0.0005832,100.3801653,366.1580058403257,-1.8259528734630956
0.03938494102915813,0.000588,101.2063395,366.1580058403257,-1.8259528734630956
0.04040305515100032,0.0006032,103.8225578,366.1580058403257,-1.8259528734630956
0.04120682945771783,0.0006152,105.8879933,366.1580058403257,-1.8259528734630956
0.043671737331651535,0.000652,112.2219955,366.1580058403257,-1.8259528734630956
0.04511853108374306,0.0006736,115.9397794,366.1580058403257,-1.8259528734630956
0.04806570354170727,0.0007176,123.5130429,366.1580058403257,-1.8259528734630956
0.04940532738623645,0.0007375999999999999,126.95543539999998,366.1580058403257,-1.8259528734630956
0.049887591970266966,0.0007448,128.1946967,366.1580058403257,-1.8259528734630956
0.05058419636942214,0.0007551999999999999,129.9847408,366.1580058403257,-1.8259528734630956
0.05112004590723382,0.0007632,131.3616978,366.1580058403257,-1.8259528734630956
0.05170948039882666,0.000772,132.8763505,366.1580058403257,-1.8259528734630956
0.05278117947445001,0.000788,135.63026449999998,366.1580058403257,-1.8259528734630956
0.05417438827276036,0.0008087999999999999,139.2103527,366.1580058403257,-1.8259528734630956
0.05519250239460255,0.000824,141.826571,366.1580058403257,-1.8259528734630956
0.056371371377788235,0.0008416,144.8558764,366.1580058403257,-1.8259528734630956
0.05792533503744209,0.0008648,148.8490517,366.1580058403257,-1.8259528734630956
0.05883627925172194,0.0008784,151.1898786,366.1580058403257,-1.8259528734630956
0.05964005355843945,0.0008904,153.2553141,366.1580058403257,-1.8259528734630956
0.061086847310530976,0.0009119999999999999,156.973098,366.1580058403257,-1.8259528734630956
0.06226571629371666,0.0009295999999999999,157.22390983474608,366.1580058403257,-1.8259528734630956
0.06323024546177768,0.000944,157.29959733473652,366.1580058403257,-1.8259528734630956
0.06376609499958935,0.0009519999999999999,157.34145134422846,366.1580058403257,-1.8259528734630956
0.06430194453740103,0.0009599999999999999,157.38316840772157,366.1580058403257,-1.8259528734630956
0.06633817278108539,0.0009904,157.54047184456053,366.1580058403257,-1.8259528734630956
0.06703477718024058,0.0010008,157.5938523814947,366.1580058403257,-1.8259528734630956
0.06724911699536523,0.001004,157.61023358102028,366.1580058403257,-1.8259528734630956
0.06810647625586393,0.0010168,157.67555577707458,366.1580058403257,-1.8259528734630956
0.06853515588611327,0.0010232,157.7080965547457,366.1580058403257,-1.8259528734630956
0.06891025056258143,0.0010287999999999999,157.73650467403743,366.1580058403257,-1.8259528734630956
0.06955327000795544,0.0010383999999999999,157.78506440125898,366.1580058403257,-1.8259528734630956
0.07003553459198596,0.0010456,157.82136938017277,366.1580058403257,-1.8259528734630956
0.07089289385248464,0.0010584,157.88567174095985,366.1580058403257,-1.8259528734630956
0.07137515843651514,0.0010655999999999999,157.92170852442695,366.1580058403257,-1.8259528734630956
0.07228610265079499,0.0010792,157.98951996436026,366.1580058403257,-1.8259528734630956
0.07271478228104433,0.0010856,158.02131583458902,366.1580058403257,-1.8259528734630956
0.073250631818856,0.0010936,158.06095805604917,366.1580058403257,-1.8259528734630956
0.07625138923060139,0.0011384,158.28089917133653,366.1580058403257,-1.8259528734630956
0.07780535289025525,0.0011616,158.39346885719712,366.1580058403257,-1.8259528734630956
0.07866271215075392,0.0011744,158.45520081825376,366.1580058403257,-1.8259528734630956
0.08177063947006163,0.0012208,158.67681254887074,366.1580058403257,-1.8259528734630956
0.08541441632718104,0.0012752,158.9324918013995,366.1580058403257,-1.8259528734630956
0.08750422952464657,0.0013063999999999999,159.07721127255434,366.1580058403257,-1.8259528734630956
0.08841517373892642,0.00132,159.13987158470948,366.1580058403257,-1.8259528734630956
0.08937970290698742,0.0013344,159.20594398677255,366.1580058403257,-1.8259528734630956
0.09168385591957763,0.0013687999999999999,159.3626680347392,366.1580058403257,-1.8259528734630956
0.09345215939435615,0.0013951999999999999,159.481905024766,366.1580058403257,-1.8259528734630956
0.09468461333132301,0.0014135999999999999,159.56448974867803,366.1580058403257,-1.8259528734630956
0.09489895314644768,0.0014168,159.57880940890146,366.1580058403257,-1.8259528734630956
0.09613140708341454,0.0014352,159.66090398709423,366.1580058403257,-1.8259528734630956
0.09741744597416256,0.0014544,159.74613145379783,366.1580058403257,-1.8259528734630956
0.09875706981869174,0.0014743999999999998,159.8344447651212,366.1580058403257,-1.8259528734630956
0.09950725917162809,0.0014856,159.88369611633576,366.1580058403257,-1.8259528734630956
0.10106122283128195,0.0015088,159.98525849074667,366.1580058403257,-1.8259528734630956
0.10320462098252865,0.0015408,160.1243507331946,366.1580058403257,-1.8259528734630956
0.10465141473462018,0.0015624,160.21760166411647,366.1580058403257,-1.8259528734630956
0.10561594390268118,0.0015768,160.27948977783757,366.1580058403257,-1.8259528734630956
0.1060982084867117,0.001584,160.3103511474757,366.1580058403257,-1.8259528734630956
0.10749141728502205,0.0016048,160.39920038343115,366.1580058403257,-1.8259528734630956
0.10802726682283373,0.0016128,160.4332534369974,366.1580058403257,-1.8259528734630956
0.10861670131442656,0.0016216,160.47063579921888,366.1580058403257,-1.8259528734630956
0.10979557029761225,0.0016392,160.54516401433528,366.1580058403257,-1.8259528734630956
0.11156387377239078,0.0016656,160.65637383558433,366.1580058403257,-1.8259528734630956
0.11193896844885895,0.0016711999999999999,160.67987517968214,366.1580058403257,-1.8259528734630956
0.11252840294045179,0.0016799999999999999,160.7167439064637,366.1580058403257,-1.8259528734630956
0.11311783743204464,0.0016887999999999998,160.7535373921718,366.1580058403257,-1.8259528734630956
0.11413595155388682,0.001704,160.81691414546333,366.1580058403257,-1.8259528734630956
0.1168151992429452,0.0017439999999999999,160.9826503445918,366.1580058403257,-1.8259528734630956
0.11788689831856855,0.0017599999999999998,161.04852891034307,366.1580058403257,-1.8259528734630956
0.11836916290259906,0.0017672,161.07809802077335,366.1580058403257,-1.8259528734630956
0.1189585973941919,0.001776,161.1141743163689,366.1580058403257,-1.8259528734630956
0.11997671151603409,0.0017912,161.1763241433577,366.1580058403257,-1.8259528734630956
0.12078048582275158,0.0018031999999999998,161.2252446242995,366.1580058403257,-1.8259528734630956
0.12174501499081261,0.0018176,161.28378192284833,366.1580058403257,-1.8259528734630956
0.12238803443618662,0.0018272,161.32270633783537,366.1580058403257,-1.8259528734630956
0.1249065272639015,0.0018648,161.47439851602914,366.1580058403257,-1.8259528734630956
0.12678200064624234,0.0018927999999999998,161.58658703878962,366.1580058403257,-1.8259528734630956
0.1275321899991787,0.0019039999999999999,161.63128099361884,366.1580058403257,-1.8259528734630956
0.12790728467564688,0.0019096,161.65358951264707,366.1580058403257,-1.8259528734630956
0.12822879439833387,0.0019144,161.67269080085111,366.1580058403257,-1.8259528734630956
0.12838954925967738,0.0019168,161.68223443996652,366.1580058403257,-1.8259528734630956
0.12946124833530073,0.0019328,161.74574002292454,366.1580058403257,-1.8259528734630956
0.12978275805798772,0.0019375999999999998,161.7647516745947,366.1580058403257,-1.8259528734630956
0.13096162704117342,0.0019552,161.83430446959485,366.1580058403257,-1.8259528734630956
0.1333193650075448,0.0019904,161.97268182549982,366.1580058403257,-1.8259528734630956
0.1346054038982928,0.0020096,162.04775798856173,366.1580058403257,-1.8259528734630956
0.13524842334366682,0.0020192,162.08519112888828,366.1580058403257,-1.8259528734630956
0.13551634811257265,0.0020231999999999997,162.10076777815834,366.1580058403257,-1.8259528734630956
0.1361593675579467,0.0020328,162.13810281520028,366.1580058403257,-1.8259528734630956
0.13642729232685252,0.0020368,162.15363877859846,366.1580058403257,-1.8259528734630956
0.13803484094028753,0.0020608,162.24660590169265,366.1580058403257,-1.8259528734630956
0.13846352057053687,0.0020672,162.27132569997414,366.1580058403257,-1.8259528734630956
0.13980314441506608,0.0020872,162.34838339197967,366.1580058403257,-1.8259528734630956
0.14044616386044007,0.0020968,162.38526875132325,366.1580058403257,-1.8259528734630956
0.1412499381671576,0.0021088,162.43128296366615,366.1580058403257,-1.8259528734630956
0.14258956201168677,0.0021287999999999997,162.50774703495932,366.1580058403257,-1.8259528734630956
0.1430718265957173,0.002136,162.53520544966568,366.1580058403257,-1.8259528734630956
0.1451616397931828,0.0021671999999999998,162.6537772167756,366.1580058403257,-1.8259528734630956
0.14644767868393083,0.0021864,162.72641363158218,366.1580058403257,-1.8259528734630956
0.14751937775955418,0.0022023999999999998,162.78675414188774,366.1580058403257,-1.8259528734630956
0.14805522729736587,0.0022104,162.81686026916717,366.1580058403257,-1.8259528734630956
0.14944843609567623,0.0022312,162.8949379931581,366.1580058403257,-1.8259528734630956
0.15003787058726906,0.00224,162.92788536362528,366.1580058403257,-1.8259528734630956
0.15132390947801708,0.0022592,162.9995958237993,366.1580058403257,-1.8259528734630956
0.1516454192007041,0.002264,163.01748625284074,366.1580058403257,-1.8259528734630956
0.15212768378473457,0.0022711999999999997,163.04429418494706,366.1580058403257,-1.8259528734630956
0.15405674212085663,0.0023,163.1511961260453,366.1580058403257,-1.8259528734630956
0.15502127128891763,0.0023144,163.20445123332541,366.1580058403257,-1.8259528734630956
0.1558786305494163,0.0023271999999999998,163.2516807165172,366.1580058403257,-1.8259528734630956
0.1562537252258845,0.0023328,163.27231174643856,366.1580058403257,-1.8259528734630956
0.15770051897797602,0.0023544,163.35170830128558,366.1580058403257,-1.8259528734630956
0.15845070833091235,0.0023656,163.39276501618426,366.1580058403257,-1.8259528734630956
0.15941523749897338,0.0023799999999999997,163.44544099880395,366.1580058403257,-1.8259528734630956
0.16091561620484607,0.0024024,163.52713502717046,366.1580058403257,-1.8259528734630956
0.1613442958350954,0.0024088,163.55042154474313,366.1580058403257,-1.8259528734630956
0.16214807014181293,0.0024208,163.59401883204322,366.1580058403257,-1.8259528734630956
0.1625231648182811,0.0024264,163.6143353813139,366.1580058403257,-1.8259528734630956
0.16568467709136997,0.0024736,163.7848542729795,366.1580058403257,-1.8259528734630956
0.16691713102833683,0.002492,163.85098338924305,366.1580058403257,-1.8259528734630956
0.16820316991908485,0.0025112,163.91978497885253,366.1580058403257,-1.8259528734630956
0.16895335927202118,0.0025223999999999997,163.95982449828813,366.1580058403257,-1.8259528734630956
0.17034656807033155,0.0025432,164.03400013466506,366.1580058403257,-1.8259528734630956
0.17115034237704907,0.0025552,164.07668614577213,366.1580058403257,-1.8259528734630956
0.1723827963140159,0.0025735999999999997,164.1419864963519,366.1580058403257,-1.8259528734630956
0.17281147594426527,0.00258,164.16465694899048,366.1580058403257,-1.8259528734630956
0.17334732548207693,0.002588,164.19296419614673,366.1580058403257,-1.8259528734630956
0.17399034492745094,0.0025976,164.22688788607155,366.1580058403257,-1.8259528734630956
0.17441902455770028,0.002604,164.2494765193504,366.1580058403257,-1.8259528734630956
0.17565147849466714,0.0026224,164.3142985468125,366.1580058403257,-1.8259528734630956
0.17624091298625996,0.0026311999999999998,164.3452376615981,366.1580058403257,-1.8259528734630956
0.17865223590641252,0.0026671999999999998,164.47138880628196,366.1580058403257,-1.8259528734630956
0.18122431368790856,0.0027056,164.60522029175584,366.1580058403257,-1.8259528734630956
0.1818137481795014,0.0027144,164.63578543156117,366.1580058403257,-1.8259528734630956
0.18240318267109423,0.0027232,164.66631195012747,366.1580058403257,-1.8259528734630956
0.18288544725512476,0.0027304,164.69125958722884,366.1580058403257,-1.8259528734630956
0.18368922156184225,0.0027424,164.73278204310498,366.1580058403257,-1.8259528734630956
0.18422507109965394,0.0027504,164.76042432085242,366.1580058403257,-1.8259528734630956
0.1859397896206513,0.002776,164.8486696316206,366.1580058403257,-1.8259528734630956
0.187761678049211,0.0028032,164.9420832332009,366.1580058403257,-1.8259528734630956
0.18936922666264602,0.0028271999999999998,165.024213830283,366.1580058403257,-1.8259528734630956
0.19135186995254924,0.0028568,165.12513470845948,366.1580058403257,-1.8259528734630956
0.19247715398195375,0.0028736,165.18223269920406,366.1580058403257,-1.8259528734630956
0.19306658847354657,0.0028824,165.21208920574972,366.1580058403257,-1.8259528734630956
0.19408470259538876,0.0028975999999999997,165.2635759387226,366.1580058403257,-1.8259528734630956
0.19472772204076277,0.0029072,165.2960396106882,366.1580058403257,-1.8259528734630956
0.19504923176344977,0.0029119999999999997,165.31225576678355,366.1580058403257,-1.8259528734630956
0.19574583616260496,0.0029224,165.3473550525015,366.1580058403257,-1.8259528734630956
0.1960137609315108,0.0029264,165.36084180233397,366.1580058403257,-1.8259528734630956
0.1961745157928543,0.0029288,165.36893040132202,366.1580058403257,-1.8259528734630956
0.19697829009957182,0.0029408,165.4093346862862,366.1580058403257,-1.8259528734630956
0.19740696972982116,0.0029472,165.4308573445778,366.1580058403257,-1.8259528734630956
0.19799640422141399,0.002956,165.46042126115643,366.1580058403257,-1.8259528734630956
0.199282443112162,0.0029752,165.52480547110088,366.1580058403257,-1.8259528734630956
0.20153301117097105,0.0030088,165.63708927813832,366.1580058403257,-1.8259528734630956
0.20276546510793791,0.0030272,165.69837076871212,366.1580058403257,-1.8259528734630956
0.2041050889524671,0.0030472,165.76481655314754,366.1580058403257,-1.8259528734630956
0.20581980747346443,0.0030727999999999997,165.8496194972704,366.1580058403257,-1.8259528734630956
0.2072130162717748,0.0030935999999999997,165.91831918356266,366.1580058403257,-1.8259528734630956
0.20769528085580533,0.0031008,165.942057842246,366.1580058403257,-1.8259528734630956
0.20930282946924036,0.0031248,166.02103190570278,366.1580058403257,-1.8259528734630956
0.21080320817511303,0.0031471999999999997,166.09452786996923,366.1580058403257,-1.8259528734630956
0.2115533975280494,0.0031584,166.13119932790292,366.1580058403257,-1.8259528734630956
0.21241075678854807,0.0031712,166.1730475218036,366.1580058403257,-1.8259528734630956
0.21530434429273113,0.0032144,166.31380134768784,366.1580058403257,-1.8259528734630956
0.21557226906163693,0.0032183999999999997,166.32679667792038,366.1580058403257,-1.8259528734630956
0.21589377878432395,0.0032232,166.3423827624826,366.1580058403257,-1.8259528734630956
0.21701906281372846,0.00324,166.3968629153499,366.1580058403257,-1.8259528734630956
0.2196447255490057,0.0032792,166.52355662119996,366.1580058403257,-1.8259528734630956
0.2207700095784102,0.003296,166.57767295579976,366.1580058403257,-1.8259528734630956
0.2224311431456264,0.0033208,166.6573627750463,366.1580058403257,-1.8259528734630956
0.22350284222124975,0.0033368,166.708652413732,366.1580058403257,-1.8259528734630956
0.22462812625065426,0.0033536,166.7624034138335,366.1580058403257,-1.8259528734630956
0.2250032209271224,0.0033591999999999997,166.78029706394207,366.1580058403257,-1.8259528734630956
0.22559265541871526,0.003368,166.8083921702447,366.1580058403257,-1.8259528734630956
0.22580699523383996,0.0033712,166.81860147258556,366.1580058403257,-1.8259528734630956
0.22677152440190096,0.0033856,166.86449664313727,366.1580058403257,-1.8259528734630956
0.22736095889349378,0.0033943999999999997,166.8925062162829,366.1580058403257,-1.8259528734630956
0.2288077526455853,0.0034159999999999998,166.9611371893816,366.1580058403257,-1.8259528734630956
0.22993303667498982,0.0034327999999999997,167.01439989230514,366.1580058403257,-1.8259528734630956
0.23213001978001768,0.0034655999999999997,167.11809689369358,366.1580058403257,-1.8259528734630956
0.23480926746907607,0.0035055999999999998,167.24404007936118,366.1580058403257,-1.8259528734630956
0.23705983552788512,0.0035391999999999997,167.34939982711347,366.1580058403257,-1.8259528734630956
0.2382387045110708,0.0035567999999999997,167.40443254165083,366.1580058403257,-1.8259528734630956
0.23872096909510132,0.003564,167.4269153025568,366.1580058403257,-1.8259528734630956
0.2390960637715695,0.0035696,167.44438965013973,366.1580058403257,-1.8259528734630956
0.240542857523661,0.0035911999999999997,167.51169079293211,366.1580058403257,-1.8259528734630956
0.24241833090600187,0.0036192,167.5986985165123,366.1580058403257,-1.8259528734630956
0.24257908576734538,0.0036216,167.60614408432664,366.1580058403257,-1.8259528734630956
0.24327569016650055,0.003632,167.63838600073393,366.1580058403257,-1.8259528734630956
0.24413304942699923,0.0036447999999999997,167.67801897385425,366.1580058403257,-1.8259528734630956
0.24456172905724857,0.0036512,167.69781510193653,366.1580058403257,-1.8259528734630956
0.24622286262446477,0.003676,167.77439761702593,366.1580058403257,-1.8259528734630956
0.24659795730093292,0.0036815999999999997,167.79166252527983,366.1580058403257,-1.8259528734630956
0.24718739179252577,0.0036904,167.81877241703154,366.1580058403257,-1.8259528734630956
0.2476160714227751,0.0036967999999999997,167.83847286909116,366.1580058403257,-1.8259528734630956
0.24825909086814912,0.0037064,167.86799862558777,366.1580058403257,-1.8259528734630956
0.2492772049899913,0.0037216,167.91468681648385,366.1580058403257,-1.8259528734630956
0.2504024890193958,0.0037384,167.96620311733412,366.1580058403257,-1.8259528734630956
0.2523315473555178,0.0037671999999999996,168.05430721064369,366.1580058403257,-1.8259528734630956
0.253992680922734,0.003792,168.12996434017055,366.1580058403257,-1.8259528734630956
0.2555466445823879,0.0038152,168.20056585139105,366.1580058403257,-1.8259528734630956
0.25597532421263725,0.0038215999999999997,168.22001263947695,366.1580058403257,-1.8259528734630956
0.25774362768741577,0.003848,168.3000967517743,366.1580058403257,-1.8259528734630956
0.260047780700006,0.0038824,168.4041279942435,366.1580058403257,-1.8259528734630956
0.26192325408234685,0.0039104,168.4885394507166,366.1580058403257,-1.8259528734630956
0.2645489168176241,0.0039496,168.60632054441837,366.1580058403257,-1.8259528734630956
0.26604929552349676,0.003972,168.6734193254235,366.1580058403257,-1.8259528734630956
0.2662636353386214,0.0039752,168.6829928047065,366.1580058403257,-1.8259528734630956
0.26776401404449407,0.0039976,168.7499232048737,366.1580058403257,-1.8259528734630956
0.2743562496557277,0.004096019203840768,169.0422800747026,366.1580058403257,-1.8259528734630956
0.2885055073054859,0.004307261452290458,169.66068630566994,366.1580058403257,-1.8259528734630956
0.31423143030504624,0.004691338267653531,170.75556178582767,366.1580058403257,-1.8259528734630956
0.3193766149049583,0.004768153630726146,170.9702783564542,366.1580058403257,-1.8259528734630956
0.3618243878542328,0.005401880376075216,172.69294880847818,366.1580058403257,-1.8259528734630956
0.3939817916036832,0.005881976395279056,173.94592859724474,366.1580058403257,-1.8259528734630956
0.4248528992031556,0.006342868573714743,175.11175412809197,366.1580058403257,-1.8259528734630956
0.4428610453028478,0.006611722344468894,175.77655430058616,366.1580058403257,-1.8259528734630956
0.4647280798524741,0.006938187637527506,176.56980037796737,366.1580058403257,-1.8259528734630956
0.49688548360192447,0.007418283656731346,177.71038294746845,366.1580058403257,-1.8259528734630956
0.5097484451017047,0.007610322064412882,178.15850833333226,366.1580058403257,-1.8259528734630956
0.5329017758013089,0.007955991198239648,178.9541744021426,366.1580058403257,-1.8259528734630956
0.5457647373010891,0.008148029605921184,179.39038139471091,366.1580058403257,-1.8259528734630956
0.5740632526006055,0.008570514102820564,180.33616499588877,366.1580058403257,-1.8259528734630956
0.6268013947497042,0.009357871574314863,182.05158296289315,366.1580058403257,-1.8259528734630956
0.6345191716495723,0.009473094618923785,182.29781458895766,366.1580058403257,-1.8259528734630956
0.6782532407488249,0.010126025205041009,183.67167196726317,366.1580058403257,-1.8259528734630956
0.7091243483482972,0.010586917383476696,184.62071913981802,366.1580058403257,-1.8259528734630956
0.7271324944479894,0.010855771154230847,185.16688774331203,366.1580058403257,-1.8259528734630956
0.76572137894733,0.011431886377275456,186.3197934321951,366.1580058403257,-1.8259528734630956
0.8428991479460108,0.012584116823364673,188.55974067603367,366.1580058403257,-1.8259528734630956
0.8917784016451755,0.013313862772554511,189.93705319315382,366.1580058403257,-1.8259528734630956
0.9162180284947578,0.01367873574714943,190.61464285174233,366.1580058403257,-1.8259528734630956
0.9213632130946698,0.013755551110222045,190.75639093487098,366.1580058403257,-1.8259528734630956
0.9612383937439883,0.014350870174034807,191.84466070161477,366.1580058403257,-1.8259528734630956
1.0011135743933068,0.01494618923784757,192.9154596961618,366.1580058403257,-1.8259528734630956
1.0204080166429772,0.015234246849369875,193.42760514009342,366.1580058403257,-1.8259528734630956
1.0487065319424935,0.015656731346269256,194.17197212442292,366.1580058403257,-1.8259528734630956
1.0525654203924275,0.015714342868573716,194.27286635992624,366.1580058403257,-1.8259528734630956
1.084722824141878,0.01619443888777756,195.10811414762074,366.1580058403257,-1.8259528734630956
1.0962994894916802,0.01636727345469094,195.4064319851551,366.1580058403257,-1.8259528734630956
1.1284568932411305,0.01684736947389478,196.22871457879927,366.1580058403257,-1.8259528734630956
1.1400335585909325,0.01702020404080816,196.52249251010738,366.1580058403257,-1.8259528734630956
1.1516102239407346,0.017193038607721544,196.81510926332757,366.1580058403257,-1.8259528734630956
1.2004894776398993,0.017922784556911382,198.03816390681806,366.1580058403257,-1.8259528734630956
1.25194132363902,0.018690938187637528,199.30478751288797,366.1580058403257,-1.8259528734630956
1.2918165042883387,0.019286257251450292,200.2725055565226,366.1580058403257,-1.8259528734630956
1.331691684937657,0.019881576315263053,201.22864154152148,366.1580058403257,-1.8259528734630956
1.3419820541374812,0.020035207041408282,201.47356553832307,366.1580058403257,-1.8259528734630956
1.3548450156372613,0.02022724544908982,201.77869295618046,366.1580058403257,-1.8259528734630956
1.3689942732870195,0.020438487697539507,202.11303116890247,366.1580058403257,-1.8259528734630956
1.3767120501868875,0.02055371074214843,202.29482934313975,366.1580058403257,-1.8259528734630956
1.3947201962865798,0.02082256451290258,202.7174863551278,366.1580058403257,-1.8259528734630956
1.4268776000360304,0.021302660532106422,203.46697501014918,366.1580058403257,-1.8259528734630956
1.5079142574846451,0.0225125025005001,205.32704110024096,366.1580058403257,-1.8259528734630956
1.560652399633744,0.0232998599719944,206.5166484227689,366.1580058403257,-1.8259528734630956
1.6005275802830625,0.023895179035807162,207.40572627225754,366.1580058403257,-1.8259528734630956
1.6198220225327327,0.024183236647329465,207.83282033974265,366.1580058403257,-1.8259528734630956
1.6313986878825348,0.02435607121424285,208.088124528358,366.1580058403257,-1.8259528734630956
1.6352575763324688,0.02441368273654731,208.17306878465263,366.1580058403257,-1.8259528734630956
1.6712738685318533,0.02495139027805561,208.96214763004514,366.1580058403257,-1.8259528734630956
1.6892820146315455,0.02522024404880976,209.35419800600303,366.1580058403257,-1.8259528734630956
1.733016083730798,0.025873174634926985,210.29959543956917,366.1580058403257,-1.8259528734630956
1.7626008951802925,0.02631486297259452,210.9338584707828,366.1580058403257,-1.8259528734630956
1.7999034835296548,0.026871774354870974,211.72769438154876,366.1580058403257,-1.8259528734630956
1.8166253334793692,0.027121424284856973,212.08146632565186,366.1580058403257,-1.8259528734630956
1.8269157026791933,0.027275055011002202,212.29854098104028,366.1580058403257,-1.8259528734630956
1.8655045871785338,0.02785117023404681,213.10835865342855,366.1580058403257,-1.8259528734630956
1.8912305101780942,0.028235247049409884,213.64461045257522,366.1580058403257,-1.8259528734630956
1.9028071755278961,0.028408081616323265,213.88499485505076,366.1580058403257,-1.8259528734630956
1.9516864292270608,0.029137827565513103,214.89372662276938,366.1580058403257,-1.8259528734630956
1.9877027214264453,0.029675535107021405,215.63070898798355,366.1580058403257,-1.8259528734630956
2.0031382752261817,0.02990598119623925,215.94496222290672,366.1580058403257,-1.8259528734630956
2.044299752025478,0.030520504100820165,216.77838776338254,366.1580058403257,-1.8259528734630956
2.04944493662539,0.03059731946389278,216.88210382307494,366.1580058403257,-1.8259528734630956
2.061021601975192,0.03077015403080616,217.11509438815307,366.1580058403257,-1.8259528734630956
2.1330541863739607,0.03184556911382276,218.55351038886795,366.1580058403257,-1.8259528734630956
2.1652115901234117,0.03232566513302661,219.18953054776665,366.1580058403257,-1.8259528734630956
2.2398167668221363,0.033439487897579515,220.65107592390837,366.1580058403257,-1.8259528734630956
2.264256393671719,0.033804360872174435,221.12571302827573,366.1580058403257,-1.8259528734630956
2.3028452781710596,0.03438047609521905,221.8710921787115,366.1580058403257,-1.8259528734630956
2.3169945358208173,0.03459171834366873,222.14317530255136,366.1580058403257,-1.8259528734630956
2.336288978070488,0.03487977595519104,222.5131557497173,366.1580058403257,-1.8259528734630956
2.3542971241701802,0.035148629725945194,222.8573971422382,366.1580058403257,-1.8259528734630956
2.3710189741198944,0.03539827965593119,223.17613148183221,366.1580058403257,-1.8259528734630956
2.3825956394696957,0.03557111422284456,223.3962803432696,366.1580058403257,-1.8259528734630956
2.4044626740193227,0.03589757951590318,223.81098220959754,366.1580058403257,-1.8259528734630956
2.4121804509191906,0.036012802560512105,223.95699606138453,366.1580058403257,-1.8259528734630956
2.436620077768773,0.036377675535107026,224.41817584728636,366.1580058403257,-1.8259528734630956
2.445624150818619,0.0365121024204841,224.5876289861507,366.1580058403257,-1.8259528734630956
2.4790678507180473,0.03701140228045609,225.21490743710214,366.1580058403257,-1.8259528734630956
2.4996485891176956,0.037318663732746546,225.59928490364894,366.1580058403257,-1.8259528734630956
2.520229327517344,0.037625925185037004,225.98243007915102,366.1580058403257,-1.8259528734630956
2.563963396616597,0.03827885577115424,226.79258539943976,366.1580058403257,-1.8259528734630956
2.583257838866267,0.03856691338267654,227.14829161524037,366.1580058403257,-1.8259528734630956
2.6411411656152777,0.03943108621724345,228.2092447700079,366.1580058403257,-1.8259528734630956
2.668153384764816,0.039834366873374674,228.70124918550425,366.1580058403257,-1.8259528734630956
2.673298569364728,0.039911182236447296,228.79474365897906,366.1580058403257,-1.8259528734630956
2.6810163462645957,0.04002640528105621,228.93485389233896,366.1580058403257,-1.8259528734630956
2.688734123164464,0.04014162832566513,229.0748069142489,366.1580058403257,-1.8259528734630956
2.7131737500140467,0.04050650130026005,229.51696142125735,366.1580058403257,-1.8259528734630956
2.7234641192138707,0.04066013202640528,229.7026667299599,366.1580058403257,-1.8259528734630956
2.7504763383634088,0.04106341268253651,230.18884581614697,366.1580058403257,-1.8259528734630956
2.8006418882125512,0.041812362472494494,231.08683783200834,366.1580058403257,-1.8259528734630956
2.8173637381622663,0.0420620124024805,231.3847715823073,366.1580058403257,-1.8259528734630956
2.855952622661606,0.0426381276255251,232.06969133172075,366.1580058403257,-1.8259528734630956
2.9099770609606823,0.04344468893778755,233.02254616585145,366.1580058403257,-1.8259528734630956
2.918981134010529,0.043579115823164635,233.1806821539272,366.1580058403257,-1.8259528734630956
2.927985207060375,0.043713542708541706,233.33862801549924,366.1580058403257,-1.8259528734630956
2.948565945460023,0.044020804160832164,233.6989375300398,366.1580058403257,-1.8259528734630956
2.97686446075954,0.04444328865773155,234.1927657040772,366.1580058403257,-1.8259528734630956
3.0051629760590566,0.04486577315463093,234.6847664173568,366.1580058403257,-1.8259528734630956
3.0193122337088147,0.04507701540308062,234.9300889586343,366.1580058403257,-1.8259528734630956
3.037320379808506,0.04534586917383476,235.24167016341562,366.1580058403257,-1.8259528734630956
3.061760006658089,0.045710742148429684,235.66338043699957,366.1580058403257,-1.8259528734630956
3.069477783557957,0.04582596519303861,235.7962790902295,366.1580058403257,-1.8259528734630956
3.0952037065575166,0.046210042008401675,236.2383364016396,366.1580058403257,-1.8259528734630956
3.14536925640666,0.046958991798359676,237.09624822065157,366.1580058403257,-1.8259528734630956
3.1595185140564186,0.04717023404680937,237.33725638890053,366.1580058403257,-1.8259528734630956
3.198107398555758,0.047746349269853966,237.99242142366373,366.1580058403257,-1.8259528734630956
3.2225470254053405,0.04811122224444889,238.4057650962086,366.1580058403257,-1.8259528734630956
3.232837394605165,0.048264852970594116,238.5794385790112,366.1580058403257,-1.8259528734630956
3.2971522021040656,0.049225045009001794,239.66005357400098,366.1580058403257,-1.8259528734630956
3.325450717403582,0.04964752950590118,240.13291648083185,366.1580058403257,-1.8259528734630956
3.33959997505334,0.04985877175435087,240.3687592489112,366.1580058403257,-1.8259528734630956
3.344745159653253,0.04993558711742349,240.45442359549466,366.1580058403257,-1.8259528734630956
3.370471082652813,0.05031966393278656,240.88197685368726,366.1580058403257,-1.8259528734630956
3.378188859552681,0.05043488697739548,241.00999440292557,366.1580058403257,-1.8259528734630956
3.385906636452549,0.05055011002200441,241.13789794046946,366.1580058403257,-1.8259528734630956
3.398769597952329,0.05074214842968594,241.3508181235121,366.1580058403257,-1.8259528734630956
3.416777744052022,0.051011002200440095,241.648379165729,366.1580058403257,-1.8259528734630956
3.427068113251846,0.051164632926585324,241.81813942889778,366.1580058403257,-1.8259528734630956
3.45665292470134,0.05160632126425285,242.30509634482243,366.1580058403257,-1.8259528734630956
3.4643707016012084,0.05172154430886178,242.43186092413015,366.1580058403257,-1.8259528734630956
3.46951588620112,0.051798359671934385,242.51630946233607,366.1580058403257,-1.8259528734630956
3.528685509100109,0.052681736347269456,243.4839832481991,366.1580058403257,-1.8259528734630956
3.535116989849999,0.05277775555111022,243.58878246881073,366.1580058403257,-1.8259528734630956
3.5441210628998445,0.05291218243648729,243.73537654187808,366.1580058403257,-1.8259528734630956
3.565988097449471,0.05323864772954591,244.09078732288614,366.1580058403257,-1.8259528734630956
3.5698469858994053,0.05329625925185037,244.1534185386598,366.1580058403257,-1.8259528734630956
3.5801373550992297,0.0534498899779956,244.320306163047,366.1580058403257,-1.8259528734630956
3.6032906857988336,0.053795559111822364,244.69512083399442,366.1580058403257,-1.8259528734630956
3.608435870398746,0.053872374474894985,244.77828529036086,366.1580058403257,-1.8259528734630956
3.627730312648416,0.054160432086417284,245.08974097373348,366.1580058403257,-1.8259528734630956
3.6586014202478885,0.05462132426485297,245.58672966787,366.1580058403257,-1.8259528734630956
3.667605493297734,0.05475575115023004,245.7313762808319,366.1580058403257,-1.8259528734630956
3.689472527847361,0.05508221644328866,246.08208553571376,366.1580058403257,-1.8259528734630956
3.707480673947053,0.05535107021404281,246.37029663256376,366.1580058403257,-1.8259528734630956
3.7216299315968118,0.055562312462492505,246.59636537359233,366.1580058403257,-1.8259528734630956
3.7254888200467446,0.055619923984796954,246.65796227787544,366.1580058403257,-1.8259528734630956
3.7512147430463054,0.056004000800160034,247.06797425816814,366.1580058403257,-1.8259528734630956
3.760218816096151,0.056138427685537104,247.21121918250043,366.1580058403257,-1.8259528734630956
3.778226962195844,0.05640728145629126,247.4973083416438,366.1580058403257,-1.8259528734630956
3.792376219845602,0.05661852370474095,247.72171977701478,366.1580058403257,-1.8259528734630956
3.8489732504446343,0.0574634926985397,248.61611929099968,366.1580058403257,-1.8259528734630956
3.870840284994261,0.05778995799159832,248.96030721578137,366.1580058403257,-1.8259528734630956
3.8888484310939533,0.058058811762352475,249.24318707020777,366.1580058403257,-1.8259528734630956
3.906856577193645,0.058327665533106615,249.52555650853455,366.1580058403257,-1.8259528734630956
3.915860650243492,0.0584620924184837,249.66655084410726,366.1580058403257,-1.8259528734630956
3.9518769424428757,0.058999799959991994,250.22926838783442,366.1580058403257,-1.8259528734630956
3.987893234642261,0.0595375075015003,250.78998935377962,366.1580058403257,-1.8259528734630956
4.005901380741953,0.05980636127225446,251.06960896019308,366.1580058403257,-1.8259528734630956
4.034199896041469,0.06022884576915383,251.50802276830643,366.1580058403257,-1.8259528734630956
4.044490265241293,0.060382476495299056,251.66714839571483,366.1580058403257,-1.8259528734630956
4.0792202612907,0.060900980196039206,252.2030354917585,366.1580058403257,-1.8259528734630956
4.094655815090436,0.06113142628525706,252.44063607179342,366.1580058403257,-1.8259528734630956
4.098514703540371,0.06118903780756152,252.49998160491484,366.1580058403257,-1.8259528734630956
4.116522849640062,0.06145789157831566,252.77663980570614,366.1580058403257,-1.8259528734630956
4.131958403439799,0.06168833766753351,253.01339993932245,366.1580058403257,-1.8259528734630956
4.135817291889733,0.06174594918983797,253.07253604557738,366.1580058403257,-1.8259528734630956
4.149966549539491,0.061957191438287665,253.2891845750512,366.1580058403257,-1.8259528734630956
4.156398030289381,0.06205321064212843,253.38756592824845,366.1580058403257,-1.8259528734630956
4.164115807189249,0.06216843368673734,253.50554521775464,366.1580058403257,-1.8259528734630956
4.170547287939139,0.06226445289057812,253.60379616318866,366.1580058403257,-1.8259528734630956
4.206563580138523,0.06280216043208642,254.15291335859786,366.1580058403257,-1.8259528734630956
4.221999133938259,0.06303260652130425,254.38768765816303,366.1580058403257,-1.8259528734630956
4.231003206988106,0.06316703340668134,254.52448474483157,366.1580058403257,-1.8259528734630956
4.309467272136764,0.06433846769353871,255.71180614738913,366.1580058403257,-1.8259528734630956
4.332620602836369,0.06468413682736547,256.0605483868177,366.1580058403257,-1.8259528734630956
4.3776409680856,0.06535627125425085,256.73658462341245,366.1580058403257,-1.8259528734630956
4.42266133333483,0.06602840568113623,257.40991477186185,366.1580058403257,-1.8259528734630956
4.4329517025346545,0.06618203640728146,257.5634428535913,366.1580058403257,-1.8259528734630956
4.43552429483461,0.06622044408881776,257.60180314879415,366.1580058403257,-1.8259528734630956
4.457391329384237,0.06654690938187638,257.927516065304,366.1580058403257,-1.8259528734630956
4.493407621583621,0.06708461692338469,258.4626292028539,366.1580058403257,-1.8259528734630956
4.535855394532896,0.06771834366873375,259.0911555075939,366.1580058403257,-1.8259528734630956
4.571871686732281,0.06825605121024206,259.62265369949614,366.1580058403257,-1.8259528734630956
4.586020944382038,0.06846729345869174,259.8310094853887,366.1580058403257,-1.8259528734630956
4.650335751880939,0.06942748549709943,260.7749392591695,366.1580058403257,-1.8259528734630956
4.655480936480851,0.06950430086017204,260.85023298714356,366.1580058403257,-1.8259528734630956
4.688924636380279,0.07000360072014403,261.3388535562315,366.1580058403257,-1.8259528734630956
4.771247589978873,0.07123264652930586,262.5358569131688,366.1580058403257,-1.8259528734630956
4.787969439928587,0.07148229645929187,262.77801100754834,366.1580058403257,-1.8259528734630956
4.808550178328235,0.07178955791158233,263.0755945081045,366.1580058403257,-1.8259528734630956
4.871578689677158,0.07273054610922185,263.98386906586364,366.1580058403257,-1.8259528734630956
4.9513290509757955,0.07392118423684738,265.1265729413551,366.1580058403257,-1.8259528734630956
4.987345343175179,0.07445889177835567,265.64027759011697,366.1580058403257,-1.8259528734630956
5.0014946008249375,0.07467013402680536,265.8416940425461,366.1580058403257,-1.8259528734630956
5.01307126617474,0.07484296859371875,266.0063240818701,366.1580058403257,-1.8259528734630956
5.037510893024322,0.07520784156831367,266.353390271359,366.1580058403257,-1.8259528734630956
5.054232742974037,0.07545749149829967,266.5904783341111,366.1580058403257,-1.8259528734630956
5.068382000623795,0.07566873374674936,266.79085246667114,366.1580058403257,-1.8259528734630956
5.115974958172981,0.07637927585517104,267.46324289371887,366.1580058403257,-1.8259528734630956
5.142987177322519,0.07678255651130227,267.8437846165024,366.1580058403257,-1.8259528734630956
5.166140508022123,0.07712822564512903,268.1693432406573,366.1580058403257,-1.8259528734630956
5.206015688671442,0.0777235447089418,268.7286967853955,366.1580058403257,-1.8259528734630956
5.266471607720409,0.07862612522504502,269.5735724028279,366.1580058403257,-1.8259528734630956
5.314064565269596,0.0793366673334667,270.2360292204217,366.1580058403257,-1.8259528734630956
5.341076784419133,0.07973994798959792,270.61098884235247,366.1580058403257,-1.8259528734630956
5.357798634368848,0.07998959791958392,270.84273611242963,366.1580058403257,-1.8259528734630956
5.402818999618079,0.0806617323464693,271.46527326235696,366.1580058403257,-1.8259528734630956
5.413109368817903,0.08081536307261453,271.6072830209926,366.1580058403257,-1.8259528734630956
5.427258626467661,0.08102660532106422,271.80237464853457,366.1580058403257,-1.8259528734630956
5.450411957167265,0.08137227445489098,272.1211881686881,366.1580058403257,-1.8259528734630956
5.465847510967001,0.08160272054410883,272.33343712958674,366.1580058403257,-1.8259528734630956
5.536593799215792,0.08265893178635728,273.3032693935009,366.1580058403257,-1.8259528734630956
5.559747129915396,0.08300460092018404,273.61961776771346,366.1580058403257,-1.8259528734630956
5.5841867567649786,0.08336947389477896,273.9529841590613,366.1580058403257,-1.8259528734630956
5.640783787364012,0.08421444288857773,274.72281355714193,366.1580058403257,-1.8259528734630956
5.656219341163748,0.08444488897779556,274.9322434651099,366.1580058403257,-1.8259528734630956
5.728251925562517,0.08552030406081217,275.906650992212,366.1580058403257,-1.8259528734630956
5.751405256262121,0.08586597319463893,276.21883700145435,366.1580058403257,-1.8259528734630956
5.775844883111703,0.08623084616923385,276.54783541007487,366.1580058403257,-1.8259528734630956
5.787421548461506,0.08640368073614724,276.70348722565575,366.1580058403257,-1.8259528734630956
5.804143398411219,0.08665333066613323,276.92810342542333,366.1580058403257,-1.8259528734630956
5.838873394460626,0.08717183436687338,277.39380918459676,366.1580058403257,-1.8259528734630956
5.851736355960406,0.08736387277455492,277.5660184854189,366.1580058403257,-1.8259528734630956
5.896756721209637,0.0880360072014403,278.1675918869801,366.1580058403257,-1.8259528734630956
5.92119634805922,0.08840088017603522,278.49341008443133,366.1580058403257,-1.8259528734630956
5.939204494158911,0.08866973394678936,278.7331511452634,366.1580058403257,-1.8259528734630956
5.973934490208317,0.0891882376475295,279.19470982884417,366.1580058403257,-1.8259528734630956
6.003519301657812,0.08962992598519705,279.58706462746346,366.1580058403257,-1.8259528734630956
6.030531520807351,0.09003320664132827,279.9446435603843,366.1580058403257,-1.8259528734630956
6.063975220706779,0.09053250650130026,280.3864960587189,366.1580058403257,-1.8259528734630956
6.079410774506515,0.09076295259051811,280.59010734015754,366.1580058403257,-1.8259528734630956
6.117999659005855,0.09133906781356271,281.0982554546385,366.1580058403257,-1.8259528734630956
6.1797418742048,0.09226085217043409,281.908700152503,366.1580058403257,-1.8259528734630956
6.195177428004537,0.09249129825965194,282.1108171464067,366.1580058403257,-1.8259528734630956
6.197750020304492,0.09252970594118824,282.1444842087531,366.1580058403257,-1.8259528734630956
6.235052608653855,0.0930866173234647,282.63204578847365,366.1580058403257,-1.8259528734630956
6.249201866303613,0.09329785957191439,282.81668518258147,366.1580058403257,-1.8259528734630956
6.253060754753547,0.09335547109421885,282.8670130754108,366.1580058403257,-1.8259528734630956
6.286504454652976,0.09385477095419084,283.30268192636555,366.1580058403257,-1.8259528734630956
6.294222231552844,0.09396999399879977,283.40309241514035,366.1580058403257,-1.8259528734630956
6.312230377652536,0.09423884776955392,283.6371970091074,366.1580058403257,-1.8259528734630956
6.323807043002338,0.0944116823364673,283.7875552858993,366.1580058403257,-1.8259528734630956
6.332811116052184,0.09454610922184438,283.90442640836886,366.1580058403257,-1.8259528734630956
6.344387781401986,0.09471894378875775,284.0545940994312,366.1580058403257,-1.8259528734630956
6.362395927501678,0.09498779755951191,284.2879760501373,366.1580058403257,-1.8259528734630956
6.373972592851481,0.0951606321264253,284.4378712760664,366.1580058403257,-1.8259528734630956
6.399698515851041,0.09554470894178836,284.7705921666696,366.1580058403257,-1.8259528734630956
6.435714808050426,0.09608241648329667,285.23552642203157,366.1580058403257,-1.8259528734630956
6.4511503618501616,0.09631286257251451,285.43447320048676,366.1580058403257,-1.8259528734630956
6.479448877149679,0.09673534706941389,285.7987274644101,366.1580058403257,-1.8259528734630956
6.519324057798997,0.09733066613322665,286.3109435269618,366.1580058403257,-1.8259528734630956
6.538618500048666,0.09761872374474895,286.55835124320487,366.1580058403257,-1.8259528734630956
6.552767757698425,0.09782996599319864,286.7396026484487,366.1580058403257,-1.8259528734630956
6.563058126898249,0.09798359671934387,286.8713259963258,366.1580058403257,-1.8259528734630956
6.6157962690473475,0.09877095419083817,287.54514809105393,366.1580058403257,-1.8259528734630956
6.6209414536472595,0.09884776955391078,287.61077447440977,366.1580058403257,-1.8259528734630956
6.626086638247172,0.0989245849169834,287.67638097125734,366.1580058403257,-1.8259528734630956
6.658244041996623,0.09940468093618725,288.08597235673176,366.1580058403257,-1.8259528734630956
6.680111076546249,0.09973114622924585,288.3640539153567,366.1580058403257,-1.8259528734630956
6.696832926495962,0.09998079615923185,288.57646504508455,366.1580058403257,-1.8259528734630956