File: datasets/aisi_316_L/data/M1/train_40.csv
Time(s),Strain(%),Stress(MPa),Temp(C),Log_SR(s-1)
0.0,0.0,0.0,235.808886576455,4.910888711251958
9.822030439913333e-11,8e-06,1.46410175,235.808886576455,4.910888711251958
3.044829436373133e-10,2.48e-05,4.538715425,235.808886576455,4.910888711251958
4.4199136979609997e-10,3.6e-05,6.5884578750000005,235.808886576455,4.910888711251958
6.384319785943666e-10,5.2e-05,9.516661375,235.808886576455,4.910888711251958
8.643386787123733e-10,7.04e-05,12.884095400000001,235.808886576455,4.910888711251958
1.1393555310299464e-09,9.279999999999999e-05,16.9835803,235.808886576455,4.910888711251958
1.453660505107173e-09,0.00011839999999999999,21.6687059,235.808886576455,4.910888711251958
1.6009909617058733e-09,0.0001304,23.864858525,235.808886576455,4.910888711251958
1.7384993878646598e-09,0.0001416,25.914600975,235.808886576455,4.910888711251958
1.984050148862493e-09,0.0001616,29.57485535,235.808886576455,4.910888711251958
2.0920924837015396e-09,0.0001704,31.185367274999997,235.808886576455,4.910888711251958
2.2590670011800666e-09,0.000184,33.67434025,235.808886576455,4.910888711251958
2.308177153379633e-09,0.000188,34.406391125,235.808886576455,4.910888711251958
2.3769313664590264e-09,0.0001936,35.43126235,235.808886576455,4.910888711251958
2.5635499448173796e-09,0.00020879999999999998,38.213055675,235.808886576455,4.910888711251958
2.632304157896773e-09,0.00021439999999999998,39.2379269,235.808886576455,4.910888711251958
2.7698125840555597e-09,0.00022559999999999998,41.287669349999994,235.808886576455,4.910888711251958
2.868032888454693e-09,0.00023359999999999999,42.7517711,235.808886576455,4.910888711251958
3.1332277103323528e-09,0.00025519999999999997,46.70484582499999,235.808886576455,4.910888711251958
3.1725158320920063e-09,0.0002584,47.290486525,235.808886576455,4.910888711251958
3.2609141060512267e-09,0.0002656,48.6081781,235.808886576455,4.910888711251958
3.3296683191306196e-09,0.0002712,49.633049324999995,235.808886576455,4.910888711251958
3.467176745289406e-09,0.0002824,51.682791775,235.808886576455,4.910888711251958
3.6046851714481927e-09,0.0002936,53.732534224999995,235.808886576455,4.910888711251958
3.6832614149674994e-09,0.0003,54.90381562499999,235.808886576455,4.910888711251958
3.761837658486806e-09,0.00030639999999999997,56.07509702499999,235.808886576455,4.910888711251958
3.879702023765766e-09,0.000316,57.832019124999995,235.808886576455,4.910888711251958
4.076142632564033e-09,0.000332,60.760222625,235.808886576455,4.910888711251958
4.135074815203513e-09,0.0003368,61.638683675,235.808886576455,4.910888711251958
4.174362936963166e-09,0.00033999999999999997,62.224324374999995,235.808886576455,4.910888711251958
4.370803545761432e-09,0.000356,65.15252787499999,235.808886576455,4.910888711251958
4.508311971920219e-09,0.0003672,67.202270325,235.808886576455,4.910888711251958
4.675286489398746e-09,0.0003808,69.6912433,235.808886576455,4.910888711251958
4.773506793797879e-09,0.00038879999999999996,71.15534505,235.808886576455,4.910888711251958
4.930659280836493e-09,0.0004016,73.49790785,235.808886576455,4.910888711251958
5.087811767875106e-09,0.0004144,75.84047065,235.808886576455,4.910888711251958
5.637845472510253e-09,0.0004592,84.03944045,235.808886576455,4.910888711251958
5.765531868229126e-09,0.0004696,85.942772725,235.808886576455,4.910888711251958
6.24681135978488e-09,0.0005088,93.1168713,235.808886576455,4.910888711251958
6.394141816383579e-09,0.0005208,95.313023925,235.808886576455,4.910888711251958
6.6396925773814135e-09,0.0005408,98.9732783,235.808886576455,4.910888711251958
6.728090851340632e-09,0.000548,100.290969875,235.808886576455,4.910888711251958
6.8066670948599385e-09,0.0005543999999999999,101.46225127499999,235.808886576455,4.910888711251958
6.904887399259073e-09,0.0005624,102.926353025,235.808886576455,4.910888711251958
7.052217855857772e-09,0.0005744,105.12250565,235.808886576455,4.910888711251958
7.4254550125744785e-09,0.0006048,110.6860923,235.808886576455,4.910888711251958
7.936200595449972e-09,0.0006464,118.2994214,235.808886576455,4.910888711251958
8.19157338688772e-09,0.0006672,122.10608595,235.808886576455,4.910888711251958
8.476412269645206e-09,0.0006904,126.351981025,235.808886576455,4.910888711251958
8.584454604484252e-09,0.0006992,127.96249295,235.808886576455,4.910888711251958
8.869293487241739e-09,0.0007224,132.208388025,235.808886576455,4.910888711251958
8.9871578525207e-09,0.000732,133.965310125,235.808886576455,4.910888711251958
9.183598461318966e-09,0.000748,136.893513625,235.808886576455,4.910888711251958
9.674699983314631e-09,0.000788,144.21402237499998,235.808886576455,4.910888711251958
9.939894805192292e-09,0.0008096,148.16709709999998,235.808886576455,4.910888711251958
1.0126513383550646e-08,0.0008248,150.948890425,235.808886576455,4.910888711251958
1.0165801505310299e-08,0.000828,151.534531125,235.808886576455,4.910888711251958
1.0273843840149345e-08,0.0008368,153.14504305,235.808886576455,4.910888711251958
1.0460462418507699e-08,0.000852,155.926836375,235.808886576455,4.910888711251958
1.0607792875106398e-08,0.000864,158.122989,235.808886576455,4.910888711251958
1.0686369118625704e-08,0.0008703999999999999,159.2942704,235.808886576455,4.910888711251958
1.0725657240385359e-08,0.0008736,159.8799111,235.808886576455,4.910888711251958
1.09024537883038e-08,0.000888,162.51529425,235.808886576455,4.910888711251958
1.0931919879623538e-08,0.0008904,162.95452477499998,235.808886576455,4.910888711251958
1.1030140184022672e-08,0.0008983999999999999,164.41862652499998,235.808886576455,4.910888711251958
1.1344445158099897e-08,0.0009239999999999999,169.10375212499997,235.808886576455,4.910888711251958
1.1491775614698598e-08,0.000936,171.29990475,235.808886576455,4.910888711251958
1.1825724649655652e-08,0.0009632,176.2778507,235.808886576455,4.910888711251958
1.1982877136694266e-08,0.000976,178.62041349999998,235.808886576455,4.910888711251958
1.2198961806372358e-08,0.0009935999999999999,181.84143734999998,235.808886576455,4.910888711251958
1.2356114293410972e-08,0.0010064,184.18400015,235.808886576455,4.910888711251958
1.2582020993528979e-08,0.0010248,187.551434175,235.808886576455,4.910888711251958
1.2748995511007505e-08,0.0010383999999999999,190.04040714999996,235.808886576455,4.910888711251958
1.297490221112551e-08,0.0010567999999999999,193.407841175,235.808886576455,4.910888711251958
1.3190986880803604e-08,0.0010743999999999999,196.62886502499998,235.808886576455,4.910888711251958
1.3249919063443086e-08,0.0010792,197.507326075,235.808886576455,4.910888711251958
1.3397249520041783e-08,0.0010911999999999999,199.70347869999998,235.808886576455,4.910888711251958
1.3868706981157624e-08,0.0011296,206.7311671,235.808886576455,4.910888711251958
1.4143723833475199e-08,0.001152,210.83065200000001,235.808886576455,4.910888711251958
1.4330342411833551e-08,0.0011672,213.61244532499998,235.808886576455,4.910888711251958
1.4615181294591037e-08,0.0011903999999999999,217.85834039999997,235.808886576455,4.910888711251958
1.4919664238228353e-08,0.0012152,222.397055825,235.808886576455,4.910888711251958
1.5145570938346355e-08,0.0012335999999999998,222.75439610555932,235.808886576455,4.910888711251958
1.539112169934419e-08,0.0012536,222.88648180627357,235.808886576455,4.910888711251958
1.5617028399462196e-08,0.001272,223.0072765875957,235.808886576455,4.910888711251958
1.5685782612541592e-08,0.0012776,223.04390470222913,235.808886576455,4.910888711251958
1.595097743441925e-08,0.0012992,223.1846019100585,235.808886576455,4.910888711251958
1.6088485860578037e-08,0.0013104,223.25719668371428,235.808886576455,4.910888711251958
1.6137596012777603e-08,0.0013143999999999999,223.2830646928566,235.808886576455,4.910888711251958
1.6422434895535092e-08,0.0013376,223.4324981222313,235.808886576455,4.910888711251958
1.671709580873249e-08,0.0013616,223.58602453998543,235.808886576455,4.910888711251958
1.6913536417530756e-08,0.0013775999999999999,223.68778955704937,235.808886576455,4.910888711251958
1.710015499588911e-08,0.0013928,223.78404020251082,235.808886576455,4.910888711251958
1.724748545248781e-08,0.0014047999999999999,223.85973848475757,235.808886576455,4.910888711251958
1.7728764944043565e-08,0.001444,224.1052804799611,235.808886576455,4.910888711251958
1.7993959765921223e-08,0.0014655999999999998,224.23946776912973,235.808886576455,4.910888711251958
1.813146819208001e-08,0.0014768,224.30874258364776,235.808886576455,4.910888711251958
1.836719692263793e-08,0.001496,224.42702459298334,235.808886576455,4.910888711251958
1.8563637531436197e-08,0.0015119999999999999,224.52514135025967,235.808886576455,4.910888711251958
1.862256971407568e-08,0.0015168,224.55449730783073,235.808886576455,4.910888711251958
1.891723062727308e-08,0.0015408,224.70073712862816,235.808886576455,4.910888711251958
1.9143137327391084e-08,0.0015592,224.8122534906027,235.808886576455,4.910888711251958
1.922171357091039e-08,0.0015655999999999999,224.85092133110612,235.808886576455,4.910888711251958
1.9467264331908226e-08,0.0015856,224.971362898017,235.808886576455,4.910888711251958
1.951637448410779e-08,0.0015895999999999998,224.99537995443066,235.808886576455,4.910888711251958
1.966370494070649e-08,0.0016016,225.06729010198404,235.808886576455,4.910888711251958
1.981103539730519e-08,0.0016136,225.1389904268453,235.808886576455,4.910888711251958
2.0046764127863112e-08,0.0016328,225.25327990710306,235.808886576455,4.910888711251958
2.0135162401822332e-08,0.00164,225.29600318268072,235.808886576455,4.910888711251958
2.0449467375899557e-08,0.0016656,225.44731928636398,235.808886576455,4.910888711251958
2.0675374076017566e-08,0.001684,225.55551802689368,235.808886576455,4.910888711251958
2.0911102806575484e-08,0.0017032,225.6679306312792,235.808886576455,4.910888711251958
2.110754341537375e-08,0.0017192,225.76123076993065,235.808886576455,4.910888711251958
2.1412026359011065e-08,0.0017439999999999999,225.90517951652902,235.808886576455,4.910888711251958
2.1628111028689157e-08,0.0017615999999999999,226.0068527848833,235.808886576455,4.910888711251958
2.1854017728807163e-08,0.00178,226.11272488347709,235.808886576455,4.910888711251958
2.2020992246285692e-08,0.0017936,226.1907040534891,235.808886576455,4.910888711251958
2.2296009098603264e-08,0.001816,226.31863951411466,235.808886576455,4.910888711251958
2.2531737829161186e-08,0.0018352,226.42780940317434,235.808886576455,4.910888711251958
2.2649602194440145e-08,0.0018448,226.48222724310926,235.808886576455,4.910888711251958
2.302283935115685e-08,0.0018751999999999998,226.6538263035591,235.808886576455,4.910888711251958
2.3179991838195466e-08,0.001888,226.72575356489892,235.808886576455,4.910888711251958
2.3425542599193298e-08,0.001908,226.83776034524126,235.808886576455,4.910888711251958
2.349429681227269e-08,0.0019136,226.86904006981467,235.808886576455,4.910888711251958
2.3769313664590266e-08,0.001936,226.99380361555694,235.808886576455,4.910888711251958
2.3916644121188962e-08,0.0019479999999999999,227.06040958785488,235.808886576455,4.910888711251958
2.4397923612744716e-08,0.0019871999999999997,227.27688239707084,235.808886576455,4.910888711251958
2.4564898130223245e-08,0.0020008,227.35159524725793,235.808886576455,4.910888711251958
2.481044889122108e-08,0.0020208,227.4611082921067,235.808886576455,4.910888711251958
2.5134575895738215e-08,0.0020472,227.60502044139054,235.808886576455,4.910888711251958
2.5193508078377698e-08,0.002052,227.63110833935139,235.808886576455,4.910888711251958
2.5340838534976397e-08,0.002064,227.69622417747948,235.808886576455,4.910888711251958
2.5576567265534316e-08,0.0020832,227.80010325293603,235.808886576455,4.910888711251958
2.570425366125319e-08,0.0020935999999999997,227.8562151556261,235.808886576455,4.910888711251958
2.576318584389267e-08,0.0020984,227.88207628221028,235.808886576455,4.910888711251958
2.5939982391811108e-08,0.0021127999999999997,227.95952159009047,235.808886576455,4.910888711251958
2.6087312848409813e-08,0.0021248,228.02390222042217,235.808886576455,4.910888711251958
2.631321954852782e-08,0.0021432,228.12234445881666,235.808886576455,4.910888711251958
2.6460550005126518e-08,0.0021552,228.1863683900181,235.808886576455,4.910888711251958
2.6627524522605044e-08,0.0021688,228.25876101546385,235.808886576455,4.910888711251958
2.6981117618441925e-08,0.0021976,228.41148121077325,235.808886576455,4.910888711251958
2.7236490409879667e-08,0.0022183999999999997,228.52129410004073,235.808886576455,4.910888711251958
2.7373998836038456e-08,0.0022296,228.58025776311248,235.808886576455,4.910888711251958
2.747221914043759e-08,0.0022375999999999997,228.62230396354536,235.808886576455,4.910888711251958
2.7668659749235855e-08,0.0022535999999999997,228.70622089494537,235.808886576455,4.910888711251958
2.7806168175394644e-08,0.0022648,228.76482454800077,235.808886576455,4.910888711251958
2.7904388479793774e-08,0.0022727999999999997,228.80661512192225,235.808886576455,4.910888711251958
2.805171893639248e-08,0.0022848,228.86919357821898,235.808886576455,4.910888711251958
2.8454422184428924e-08,0.0023176,229.03959075071026,235.808886576455,4.910888711251958
2.859193061058771e-08,0.0023288,229.09755940609978,235.808886576455,4.910888711251958
2.8808015280265802e-08,0.0023464,229.18843381442494,235.808886576455,4.910888711251958
2.8837481371585542e-08,0.0023488,229.20080515042804,235.808886576455,4.910888711251958
2.8906235584664938e-08,0.0023544,229.22965244480042,235.808886576455,4.910888711251958
2.901427791950398e-08,0.0023631999999999998,229.27492990130142,235.808886576455,4.910888711251958
2.909285416302329e-08,0.0023696,229.3078176703827,235.808886576455,4.910888711251958
2.919107446742242e-08,0.0023775999999999997,229.34887870708926,235.808886576455,4.910888711251958
2.9701820050297914e-08,0.0024192,229.56153370865815,235.808886576455,4.910888711251958
2.982950644601679e-08,0.0024296,229.61447403354933,235.808886576455,4.910888711251958
2.986879456777644e-08,0.0024327999999999997,229.63074557426057,235.808886576455,4.910888711251958
2.997683690261549e-08,0.0024416,229.67544932817484,235.808886576455,4.910888711251958
3.023220969405324e-08,0.0024624,229.7808636960825,235.808886576455,4.910888711251958
3.071348918560899e-08,0.0025016,229.97859005576507,235.808886576455,4.910888711251958
3.077242136824847e-08,0.0025063999999999998,230.0027181286802,235.808886576455,4.910888711251958
3.086081964220769e-08,0.0025136,230.03887647628954,235.808886576455,4.910888711251958
3.10179721292463e-08,0.0025264,230.1030584046765,235.808886576455,4.910888711251958
3.140103131640292e-08,0.0025575999999999997,230.2589728516353,235.808886576455,4.910888711251958
3.1676048168720493e-08,0.00258,230.37045432503024,235.808886576455,4.910888711251958
3.1892132838398586e-08,0.0025976,230.45778231337366,235.808886576455,4.910888711251958
3.214750562983634e-08,0.0026184,230.56069116923774,235.808886576455,4.910888711251958
3.2226081873355644e-08,0.0026248,230.5922912269044,235.808886576455,4.910888711251958
3.2560030908312695e-08,0.002652,230.7262576147123,235.808886576455,4.910888711251958
3.259931903007235e-08,0.0026552,230.74198305860978,235.808886576455,4.910888711251958
3.2785937608430704e-08,0.0026704,230.81657821409652,235.808886576455,4.910888711251958
3.302166633898862e-08,0.0026896,230.9105674052726,235.808886576455,4.910888711251958
3.327703913042637e-08,0.0027104,231.0120942288658,235.808886576455,4.910888711251958
3.339490349570533e-08,0.0027199999999999998,231.05885023357544,235.808886576455,4.910888711251958
3.3679742378462816e-08,0.0027432,231.17157900443956,235.808886576455,4.910888711251958
3.371903050022247e-08,0.0027464,231.18709857023535,235.808886576455,4.910888711251958
3.377796268286195e-08,0.0027512,231.21036470244428,235.808886576455,4.910888711251958
3.3807428774181685e-08,0.0027535999999999997,231.2219918315485,235.808886576455,4.910888711251958
3.3886005017701e-08,0.00276,231.25297820317698,235.808886576455,4.910888711251958
3.395475923078039e-08,0.0027656,231.28006829846387,235.808886576455,4.910888711251958
3.407262359605935e-08,0.0027752,231.32645874298018,235.808886576455,4.910888711251958
3.4308352326617266e-08,0.0027944,231.41905230272,235.808886576455,4.910888711251958
3.438692857013658e-08,0.0028008,231.4498616419145,235.808886576455,4.910888711251958
3.4701233544213804e-08,0.0028263999999999997,231.57282542287234,235.808886576455,4.910888711251958
3.474052166597346e-08,0.0028296,231.58816529617576,235.808886576455,4.910888711251958
3.507447070093051e-08,0.0028568,231.71828218231815,235.808886576455,4.910888711251958
3.529055537060861e-08,0.0028744,231.80221807544095,235.808886576455,4.910888711251958
3.536913161412791e-08,0.0028807999999999998,231.83269049270834,235.808886576455,4.910888711251958
3.545752988808713e-08,0.002888,231.86694042107015,235.808886576455,4.910888711251958
3.581112298392401e-08,0.0029167999999999998,232.003608430803,235.808886576455,4.910888711251958
3.587005516656349e-08,0.0029216,232.0263351691549,235.808886576455,4.910888711251958
3.651830917559777e-08,0.0029744,232.2753757395052,235.808886576455,4.910888711251958
3.6714749784396036e-08,0.0029904,232.3505014024421,235.808886576455,4.910888711251958
3.687190227143465e-08,0.0030031999999999997,232.41048912469248,235.808886576455,4.910888711251958
3.702905475847326e-08,0.003016,232.47037721620075,235.808886576455,4.910888711251958
3.7333537702110576e-08,0.0030407999999999998,232.5861290622002,235.808886576455,4.910888711251958
3.743175800650971e-08,0.0030488,232.6233897514148,235.808886576455,4.910888711251958
3.748086815870928e-08,0.0030528,232.64200579556493,235.808886576455,4.910888711251958
3.7795173132786504e-08,0.0030784,232.76092400437554,235.808886576455,4.910888711251958
3.820769841126286e-08,0.0031119999999999997,232.91642049202844,235.808886576455,4.910888711251958
3.8355028867861564e-08,0.003124,232.9717960936877,235.808886576455,4.910888711251958
3.861040165929931e-08,0.0031447999999999997,233.06758435569753,235.808886576455,4.910888711251958
3.884613038985723e-08,0.0031639999999999997,233.15578521248864,235.808886576455,4.910888711251958
3.906221505953532e-08,0.0031815999999999997,233.2364527997729,235.808886576455,4.910888711251958
3.9239011607453766e-08,0.003196,233.3023241858728,235.808886576455,4.910888711251958
3.9415808155372205e-08,0.0032104,233.36807992417403,235.808886576455,4.910888711251958
3.978904531208891e-08,0.0032408,233.50652104466306,235.808886576455,4.910888711251958
3.988726561648804e-08,0.0032488,233.54286862477298,235.808886576455,4.910888711251958
3.996584186000735e-08,0.0032551999999999998,233.5719215624422,235.808886576455,4.910888711251958
4.030961292540432e-08,0.0032832,233.69876713686793,235.808886576455,4.910888711251958
4.0535519625522326e-08,0.0033016,233.78189315314097,235.808886576455,4.910888711251958
4.0663206021241195e-08,0.003312,233.82879750010852,235.808886576455,4.910888711251958
4.114448551279695e-08,0.0033512,234.00507689946184,235.808886576455,4.910888711251958
4.132128206071539e-08,0.0033656,234.06963039706315,235.808886576455,4.910888711251958
4.1674875156552266e-08,0.0033943999999999997,234.19841514629044,235.808886576455,4.910888711251958
4.193024794799001e-08,0.0034151999999999997,234.29116147435258,235.808886576455,4.910888711251958
4.197935810018958e-08,0.0034192,234.30897202306136,235.808886576455,4.910888711251958
4.205793434370889e-08,0.0034256,234.33745200823313,235.808886576455,4.910888711251958
4.225437495250715e-08,0.0034416,234.40856133424472,235.808886576455,4.910888711251958
4.249010368306508e-08,0.0034608,234.49372256558905,235.808886576455,4.910888711251958
4.2696366322303254e-08,0.0034776,234.56808760626757,235.808886576455,4.910888711251958
4.304995941814013e-08,0.0035064,234.6952453909536,235.808886576455,4.910888711251958
4.31678237834191e-08,0.003516,234.73754071772962,235.808886576455,4.910888711251958
4.334462033133754e-08,0.0035304,234.80089935966956,235.808886576455,4.910888711251958
4.3433018605296754e-08,0.0035375999999999997,234.83254087939866,235.808886576455,4.910888711251958
4.3491950787936233e-08,0.0035424,234.85362127384843,235.808886576455,4.910888711251958
4.362945921409502e-08,0.0035535999999999996,234.90276558611365,235.808886576455,4.910888711251958
4.3698213427174416e-08,0.0035591999999999998,234.92731508697432,235.808886576455,4.910888711251958
4.382589982289329e-08,0.0035696,234.97286708835225,235.808886576455,4.910888711251958
4.394376418817225e-08,0.0035792,235.01486917093797,235.808886576455,4.910888711251958
4.4199136979609996e-08,0.0036,235.1057232545047,235.808886576455,4.910888711251958
4.447415383192757e-08,0.0036224,235.2033374646006,235.808886576455,4.910888711251958
4.4660772410285924e-08,0.0036376,235.26944164515393,235.808886576455,4.910888711251958
4.488667911040393e-08,0.003656,235.34931853813652,235.808886576455,4.910888711251958
4.50143655061228e-08,0.0036663999999999998,235.3943969929797,235.808886576455,4.910888711251958
4.532867048020003e-08,0.003692,235.50514740876667,235.808886576455,4.910888711251958
4.553493311943821e-08,0.0037088,235.57766464625922,235.808886576455,4.910888711251958
4.603585667187378e-08,0.0037495999999999996,235.75324663897564,235.808886576455,4.910888711251958
4.6222475250232145e-08,0.0037648,235.8184688347867,235.808886576455,4.910888711251958
4.638944976771067e-08,0.0037784,235.8767385359943,235.808886576455,4.910888711251958
4.6615356467828677e-08,0.0037968,235.95544398524606,235.808886576455,4.910888711251958
4.6792153015747116e-08,0.0038112,236.0169358388008,235.808886576455,4.910888711251958
4.706716986806469e-08,0.0038336,236.11241003557964,235.808886576455,4.910888711251958
4.7518983268300705e-08,0.0038704,236.2687895337693,235.808886576455,4.910888711251958
4.757791545094018e-08,0.0038751999999999997,236.2891440237624,235.808886576455,4.910888711251958
4.7695779816219144e-08,0.0038848,236.3298235297203,235.808886576455,4.910888711251958
4.789222042501741e-08,0.0039008,236.3975356919866,235.808886576455,4.910888711251958
4.8019906820736286e-08,0.0039112,236.44149052003485,235.808886576455,4.910888711251958
4.806901697293585e-08,0.0039152,236.4583840829621,235.808886576455,4.910888711251958
4.832438976437359e-08,0.003935999999999999,236.54612233998301,235.808886576455,4.910888711251958
4.8471720220972297e-08,0.003948,236.59665830985253,235.808886576455,4.910888711251958
4.856011849493151e-08,0.0039552,236.62695113777343,235.808886576455,4.910888711251958
4.8638694738450826e-08,0.0039616,236.65386004584423,235.808886576455,4.910888711251958
4.8884245499448654e-08,0.0039816,236.73784131787062,235.808886576455,4.910888711251958
4.8923533621208314e-08,0.0039848,236.75126303897719,235.808886576455,4.910888711251958
4.9061042047367093e-08,0.0039959999999999996,236.798205995805,235.808886576455,4.910888711251958
5.123213517118227e-08,0.004172834566913383,237.53270897661673,235.808886576455,4.910888711251958
5.6419204657353745e-08,0.004595319063812763,239.24004192903328,235.808886576455,4.910888711251958
5.854118762896935e-08,0.004768153630726146,239.92070786156782,235.808886576455,4.910888711251958
6.160627414352522e-08,0.005017803560712143,240.88714174509872,235.808886576455,4.910888711251958
6.372825711514082e-08,0.005190638127625526,241.54525117842203,235.808886576455,4.910888711251958
6.53786883152863e-08,0.005325065013002601,242.05122267642167,235.808886576455,4.910888711251958
6.773644717263696e-08,0.0055171034206841375,242.76548140652878,235.808886576455,4.910888711251958
7.10373095729279e-08,0.0057859571914382875,243.7493618371153,235.808886576455,4.910888711251958
7.221618900160322e-08,0.005881976395279056,244.09640505865877,235.808886576455,4.910888711251958
7.999679323086045e-08,0.006515703140628126,246.33384995733724,235.808886576455,4.910888711251958
8.259032797394618e-08,0.006726945389077816,247.06057649979306,235.808886576455,4.910888711251958
8.659851803144232e-08,0.007053410682136428,248.16643082594473,235.808886576455,4.910888711251958
9.202136340334885e-08,0.00749509901980396,249.63131518125118,235.808886576455,4.910888711251958
9.767998466099047e-08,0.007955991198239648,251.124421215658,235.808886576455,4.910888711251958
9.980196763260606e-08,0.00812882576515303,251.67558832887832,235.808886576455,4.910888711251958
1.0357438180436713e-07,0.008436087217443489,252.6442860036548,235.808886576455,4.910888711251958
1.0923300306200875e-07,0.008896979395879176,254.07191752447653,235.808886576455,4.910888711251958
1.1276964134803475e-07,0.00918503700740148,254.9495516210926,235.808886576455,4.910888711251958
1.1630627963406076e-07,0.009473094618923785,255.81651464948013,235.808886576455,4.910888711251958
1.188998143771465e-07,0.009684336867373475,256.4457664414918,235.808886576455,4.910888711251958
1.2432265974905305e-07,0.010126025205041009,257.7444335712513,235.808886576455,4.910888711251958
1.2974550512095957e-07,0.01056771354270854,259.0211870916217,235.808886576455,4.910888711251958
1.3068860866389984e-07,0.010644528905781155,259.2410896505714,235.808886576455,4.910888711251958
1.3422524694992587e-07,0.010932586517303462,260.06026971951087,235.808886576455,4.910888711251958
1.3705455757874666e-07,0.011163032606521305,260.7095685945811,235.808886576455,4.910888711251958
1.396480923218324e-07,0.011374274854970993,261.300181435947,235.808886576455,4.910888711251958
1.4318473060785842e-07,0.0116623324664933,262.09871415657784,235.808886576455,4.910888711251958
1.4389205826506358e-07,0.011719943988797759,262.25749356839714,235.808886576455,4.910888711251958
1.4719292066535453e-07,0.01198879775955191,262.99447629450935,235.808886576455,4.910888711251958
1.5002223129417532e-07,0.012219243848769754,263.6210599758823,235.808886576455,4.910888711251958
1.5332309369446627e-07,0.012488097619523904,264.3462788188207,235.808886576455,4.910888711251958
1.5568085255181695e-07,0.01268013602720544,264.86056903384844,235.808886576455,4.910888711251958
1.5898171495210787e-07,0.012948989797959592,265.5755010050399,235.808886576455,4.910888711251958
1.608679220379884e-07,0.013102620524104821,265.98143405547523,235.808886576455,4.910888711251958
1.6511188798121963e-07,0.013448289657931586,266.8880570491837,235.808886576455,4.910888711251958
1.6912007803871577e-07,0.013774754950990198,267.73600227263773,235.808886576455,4.910888711251958
1.7147783689606645e-07,0.013966793358671735,268.231132514427,235.808886576455,4.910888711251958
1.7501447518209245e-07,0.01425485097019404,268.96887838790497,235.808886576455,4.910888711251958
1.825593035256146e-07,0.014869373874774956,270.52357906830696,235.808886576455,4.910888711251958
1.8798214889752114e-07,0.01531106221244249,271.6255796810291,235.808886576455,4.910888711251958
1.9340499426942766e-07,0.015752750550110023,272.7152495887057,235.808886576455,4.910888711251958
2.0330758147030046e-07,0.016559311862372472,274.67481635013735,235.808886576455,4.910888711251958
2.0495801267044595e-07,0.01669373874774955,274.9977571698049,235.808886576455,4.910888711251958
2.0731577152779662e-07,0.016885777155431086,275.4573474123252,235.808886576455,4.910888711251958
2.0896620272794206e-07,0.01702020404080816,275.77784844826914,235.808886576455,4.910888711251958
2.1674680695719928e-07,0.01765393078615723,277.27568145220107,235.808886576455,4.910888711251958
2.1886878992881493e-07,0.017826765353070616,277.6805229783323,235.808886576455,4.910888711251958
2.2169810055763572e-07,0.01805721144228846,278.2179384776275,235.808886576455,4.910888711251958
2.282998253582176e-07,0.01859491898379676,279.46161181684465,235.808886576455,4.910888711251958
2.311291359870384e-07,0.018825365073014605,279.99031206883313,235.808886576455,4.910888711251958
2.3230801541571373e-07,0.01892138427685537,280.20985819337056,235.808886576455,4.910888711251958
2.386739643305606e-07,0.01943988797759552,281.38798274526226,235.808886576455,4.910888711251958
2.4527568913114237e-07,0.01997759551910382,282.5968683584263,235.808886576455,4.910888711251958
2.539993969033399e-07,0.020688137627525506,284.17503584807616,235.808886576455,4.910888711251958
2.690890535903842e-07,0.02191718343668734,286.85581033994276,235.808886576455,4.910888711251958
2.705037089047946e-07,0.02203240648129626,287.10408802185924,235.808886576455,4.910888711251958
2.7427612307655564e-07,0.02233966793358672,287.7636986016113,235.808886576455,4.910888711251958
2.7710543370537646e-07,0.022570114022804563,288.2560870486236,235.808886576455,4.910888711251958
2.839429343916934e-07,0.023127025405081016,289.43800044359244,235.808886576455,4.910888711251958
2.89601555649335e-07,0.023587917583516704,290.4077639447762,235.808886576455,4.910888711251958
2.933739698210961e-07,0.023895179035807162,291.05017047487365,235.808886576455,4.910888711251958
2.9526017690697664e-07,0.02404880976195239,291.3701650461955,235.808886576455,4.910888711251958
3.00211470507413e-07,0.024452090418083616,292.2063803864209,235.808886576455,4.910888711251958
3.058700917650546e-07,0.024912982596519303,293.1554968152047,235.808886576455,4.910888711251958
3.0987828182255076e-07,0.025239447889577916,293.82364878703964,235.808886576455,4.910888711251958
3.115287130226962e-07,0.02537387477495499,294.09778952034355,235.808886576455,4.910888711251958
3.223744037665093e-07,0.026257251450290058,295.8853977288399,235.808886576455,4.910888711251958
3.2449638673812494e-07,0.026430086017203442,296.2323869927977,235.808886576455,4.910888711251958
3.280330250241509e-07,0.026718143628725745,296.8087423350033,235.808886576455,4.910888711251958
3.3227699096738214e-07,0.02706381276255251,297.4971796432905,235.808886576455,4.910888711251958
3.3840716399649387e-07,0.027563112622524505,298.4855655293568,235.808886576455,4.910888711251958
3.3935026753943414e-07,0.02763992798559712,298.6370028934987,235.808886576455,4.910888711251958
3.447731129113407e-07,0.028081616323264655,299.50460344546053,235.808886576455,4.910888711251958
3.476024235401615e-07,0.0283120624124825,299.9551509406191,235.808886576455,4.910888711251958
3.520821653691278e-07,0.028676935387077416,300.66560378309475,235.808886576455,4.910888711251958
3.6717182205617207e-07,0.02990598119623925,303.0331861988424,235.808886576455,4.910888711251958
3.700011326849929e-07,0.030136427285457092,303.4728510095795,235.808886576455,4.910888711251958
3.747166503996942e-07,0.030520504100820165,304.20272307708257,235.808886576455,4.910888711251958
3.8296880640042154e-07,0.03119263852770554,305.47143772770806,235.808886576455,4.910888711251958
3.907494106296788e-07,0.031826365273054616,306.65792355341915,235.808886576455,4.910888711251958
3.95229152458645e-07,0.03219123824764953,307.33687176575177,235.808886576455,4.910888711251958
3.9711535954452556e-07,0.03234486897379476,307.62184605239554,235.808886576455,4.910888711251958
4.053675155452529e-07,0.03301700340068014,308.8624529435288,235.808886576455,4.910888711251958
4.1079036091715946e-07,0.03345869173834767,309.67234956370334,235.808886576455,4.910888711251958
4.1574165451759585e-07,0.0338619723944789,310.4081861449015,235.808886576455,4.910888711251958
4.1833518926068163e-07,0.03407321464292859,310.79225991322943,235.808886576455,4.910888711251958
4.2588001760420375e-07,0.034687737547509506,311.9043201770745,235.808886576455,4.910888711251958
4.270588970328791e-07,0.03478375675135027,312.0773830997965,235.808886576455,4.910888711251958
4.2800200057581927e-07,0.03486057211442288,312.21569932815123,235.808886576455,4.910888711251958
4.3059553531890505e-07,0.03507181436287257,312.5954574155498,235.808886576455,4.910888711251958
4.327175182905207e-07,0.03524464892978596,312.9055055007025,235.808886576455,4.910888711251958
4.421485537199234e-07,0.036012802560512105,314.2763850075309,235.808886576455,4.910888711251958
4.4568519200594934e-07,0.036300860172034405,314.78751867241124,235.808886576455,4.910888711251958
4.473356232060949e-07,0.03643528705741149,315.0255061489686,235.808886576455,4.910888711251958
4.54880451549617e-07,0.037049809961992405,316.10911751262887,235.808886576455,4.910888711251958
4.560593309782924e-07,0.03714582916583317,316.2777965236847,235.808886576455,4.910888711251958
4.572382104069677e-07,0.03724184836967394,316.44630557135144,235.808886576455,4.910888711251958
4.6266105577887417e-07,0.03768353670734147,317.2192752183772,235.808886576455,4.910888711251958
4.7091321177960153e-07,0.038355671134226846,318.3887880656306,235.808886576455,4.910888711251958
4.7232786709401196e-07,0.03847089417883577,318.5884707609488,235.808886576455,4.910888711251958
4.7279941886548207e-07,0.038509301860372075,318.6549798094664,235.808886576455,4.910888711251958
4.782222642373885e-07,0.0389509901980396,319.41798377563686,235.808886576455,4.910888711251958
4.805800230947393e-07,0.03914302860572115,319.7486713300273,235.808886576455,4.910888711251958
4.838808854950301e-07,0.03941188237647529,320.21057289826337,235.808886576455,4.910888711251958
4.871817478953212e-07,0.039680736147229445,320.6712472266793,235.808886576455,4.910888711251958
4.926045932672277e-07,0.040122424484896974,321.42543544982203,235.808886576455,4.910888711251958
4.944908003531081e-07,0.0402760552110422,321.6870018879377,235.808886576455,4.910888711251958
4.968485592104589e-07,0.04046809361872375,322.0134133889875,235.808886576455,4.910888711251958
4.992063180678096e-07,0.04066013202640528,322.3392213507579,235.808886576455,4.910888711251958
5.017998528108953e-07,0.040871374274854974,322.69691774411194,235.808886576455,4.910888711251958
5.067511464113317e-07,0.0412746549309862,323.37779687079905,235.808886576455,4.910888711251958
5.093446811544175e-07,0.04148589717943589,323.73341211304336,235.808886576455,4.910888711251958
5.105235605830928e-07,0.04158191638327666,323.89482188247285,235.808886576455,4.910888711251958
5.180683889266149e-07,0.04219643928785757,324.92442350756346,235.808886576455,4.910888711251958
5.223123548698461e-07,0.042542108421684335,325.5010042140464,235.808886576455,4.910888711251958
5.317433902992488e-07,0.04331026205241048,326.77579314425896,235.808886576455,4.910888711251958
5.355158044710099e-07,0.04361752350470094,327.2832360168587,235.808886576455,4.910888711251958
5.369304597854204e-07,0.043732746549309864,327.4731674322885,235.808886576455,4.910888711251958
5.378735633283605e-07,0.04380956191238247,327.5996799643735,235.808886576455,4.910888711251958
5.461257193290878e-07,0.04448169633926785,328.7029986094072,235.808886576455,4.910888711251958
5.475403746434983e-07,0.044596919383876776,328.8914842245114,235.808886576455,4.910888711251958
5.631015831020127e-07,0.04586437287457491,330.95244485715347,235.808886576455,4.910888711251958
5.661666696165685e-07,0.04611402280456091,331.35576017057116,235.808886576455,4.910888711251958
5.697033079025947e-07,0.04640208041608322,331.82006737702613,235.808886576455,4.910888711251958
5.727683944171506e-07,0.04665173034606922,332.2215584150116,235.808886576455,4.910888711251958
5.765408085889115e-07,0.046958991798359676,332.71455279392603,235.808886576455,4.910888711251958
5.803132227606726e-07,0.047266253250650134,333.2062907217716,235.808886576455,4.910888711251958
5.833783092752285e-07,0.04751590318063613,333.604910460939,235.808886576455,4.910888711251958
5.902158099615454e-07,0.04807281456291258,334.49120747505407,235.808886576455,4.910888711251958
5.918662411616908e-07,0.04820724144828965,334.704540204807,235.808886576455,4.910888711251958
6.003541730481533e-07,0.04889857971594319,335.7980366627737,235.808886576455,4.910888711251958
6.093136567060859e-07,0.04962832566513303,336.94576183034206,235.808886576455,4.910888711251958
6.194520197926936e-07,0.05045409081816363,338.236595057354,235.808886576455,4.910888711251958
6.4161495305179e-07,0.05225925185037007,341.03006525504713,235.808886576455,4.910888711251958
6.491597813953122e-07,0.05287377475495099,341.9724138516829,235.808886576455,4.910888711251958
6.51989092024133e-07,0.05310422084416884,342.3246921196955,235.808886576455,4.910888711251958
6.538752991100136e-07,0.05325785157031407,342.5592131345347,235.808886576455,4.910888711251958
6.55525730310159e-07,0.05339227845569114,342.76420267643834,235.808886576455,4.910888711251958
6.666071969397071e-07,0.054294858971794355,344.1353851837929,235.808886576455,4.910888711251958
6.717942664258786e-07,0.05471734346869374,344.77415813852383,235.808886576455,4.910888711251958
6.73208921740289e-07,0.054832566513302664,344.94803474214206,235.808886576455,4.910888711251958
6.739162493974942e-07,0.054890178035607126,345.03491960333366,235.808886576455,4.910888711251958
6.897132337417438e-07,0.05617683536707342,346.96617818497873,235.808886576455,4.910888711251958
6.946645273421802e-07,0.056580116023204646,347.56793697684066,235.808886576455,4.910888711251958
7.005589244855567e-07,0.05706021204240848,348.2821398395876,235.808886576455,4.910888711251958
7.04567114543053e-07,0.057386677335467096,348.76645964339485,235.808886576455,4.910888711251958
7.111688393436347e-07,0.05792438487697539,349.5618269758836,235.808886576455,4.910888711251958
7.15648581172601e-07,0.05828925785157031,350.09990128596525,235.808886576455,4.910888711251958
7.172990123727466e-07,0.058423684736947396,350.297807859253,235.808886576455,4.910888711251958
7.22250305973183e-07,0.05882696539307862,350.89046476890866,235.808886576455,4.910888711251958
7.239007371733284e-07,0.05896139227845569,351.08766467899375,235.808886576455,4.910888711251958
7.26022720144944e-07,0.05913422684536908,351.340949964745,235.808886576455,4.910888711251958
7.283804790022947e-07,0.05932626525305061,351.62203968924365,235.808886576455,4.910888711251958
7.302666860881753e-07,0.05947989597919584,351.84665605759784,235.808886576455,4.910888711251958
7.330959967169959e-07,0.05971034206841368,352.1831568328466,235.808886576455,4.910888711251958
7.36396859117287e-07,0.05997919583916783,352.5751015939219,235.808886576455,4.910888711251958
7.43470135689339e-07,0.060555311062212444,353.41268343125193,235.808886576455,4.910888711251958
7.458278945466897e-07,0.06074734946989398,353.6911860065592,235.808886576455,4.910888711251958
7.505434122613911e-07,0.06113142628525706,354.24716320047287,235.808886576455,4.910888711251958
7.517222916900663e-07,0.06122744548909782,354.38594443357255,235.808886576455,4.910888711251958
7.599744476907937e-07,0.0618995799159832,355.35504743103354,235.808886576455,4.910888711251958
7.632753100910845e-07,0.06216843368673734,355.7415384717969,235.808886576455,4.910888711251958
7.661046207199055e-07,0.06239887977595519,356.07229797156054,235.808886576455,4.910888711251958
7.715274660918119e-07,0.06284056811362272,356.70492511551424,235.808886576455,4.910888711251958
7.793080703210692e-07,0.0634742948589718,357.60958687813593,235.808886576455,4.910888711251958
7.816658291784199e-07,0.06366633326665333,357.8830304613009,235.808886576455,4.910888711251958
7.863813468931213e-07,0.06405041008201641,358.42895452620695,235.808886576455,4.910888711251958
7.915684163792926e-07,0.06447289457891578,359.02799851497434,235.808886576455,4.910888711251958
7.943977270081135e-07,0.06470334066813363,359.3541044420106,235.808886576455,4.910888711251958
8.040645383232511e-07,0.06549069813962792,360.46489788468017,235.808886576455,4.910888711251958
8.064222971806019e-07,0.06568273654730947,360.73503156234756,235.808886576455,4.910888711251958
8.085442801522174e-07,0.06585557111422284,360.9778886284149,235.808886576455,4.910888711251958
8.153817808385344e-07,0.0664124824964993,361.7587425620321,235.808886576455,4.910888711251958
8.163248843814747e-07,0.06648929785957192,361.8662457980194,235.808886576455,4.910888711251958
8.191541950102956e-07,0.06671974394878977,362.1884652562811,235.808886576455,4.910888711251958
8.229266091820567e-07,0.06702700540108023,362.61741683670596,235.808886576455,4.910888711251958
8.257559198108774e-07,0.06725745149029806,362.9386274337579,235.808886576455,4.910888711251958
8.316503169542541e-07,0.06773754750950191,363.60644087220226,235.808886576455,4.910888711251958
8.384878176405711e-07,0.06829445889177836,364.37879624051016,235.808886576455,4.910888711251958
8.465041977555633e-07,0.06894738947789558,365.2811952121745,235.808886576455,4.910888711251958
8.483904048414438e-07,0.06910102020404081,365.49303929156866,235.808886576455,4.910888711251958
8.571141126136412e-07,0.0698115623124625,366.47043871114477,235.808886576455,4.910888711251958
8.623011820998128e-07,0.07023404680936188,367.04975598528733,235.808886576455,4.910888711251958
8.799843735299429e-07,0.0716743348669734,369.0145666711225,235.808886576455,4.910888711251958
8.865860983305246e-07,0.0722120424084817,369.7441408402209,235.808886576455,4.910888711251958
8.903585125022857e-07,0.07251930386077216,370.1600890784414,235.808886576455,4.910888711251958
9.023830826747742e-07,0.07349869973994799,371.4813603350957,235.808886576455,4.910888711251958
9.158223081616731e-07,0.07459331866373275,372.949976145952,235.808886576455,4.910888711251958
9.207736017621094e-07,0.07499659931986398,373.48892334339024,235.808886576455,4.910888711251958
9.252533435910757e-07,0.0753614722944589,373.9755691047,235.808886576455,4.910888711251958
9.325623960488627e-07,0.07595679135827166,374.76760199991287,235.808886576455,4.910888711251958
9.349201549062133e-07,0.07614882976595319,375.0225795559032,235.808886576455,4.910888711251958
9.365705861063589e-07,0.07628325665133028,375.20091465244343,235.808886576455,4.910888711251958
9.419934314782654e-07,0.0767249449889978,375.7860117855988,235.808886576455,4.910888711251958
9.469447250787018e-07,0.07712822564512903,376.3190846711364,235.808886576455,4.910888711251958
9.523675704506085e-07,0.07756991398279657,376.90168069295703,235.808886576455,4.910888711251958
9.551968810794292e-07,0.07780036007201441,377.20513016299356,235.808886576455,4.910888711251958
9.566115363938396e-07,0.07791558311662333,377.35672343076175,235.808886576455,4.910888711251958
9.636848129658915e-07,0.07849169833966793,378.113382277477,235.808886576455,4.910888711251958
9.816037802817566e-07,0.07995119023804761,380.02062116481704,235.808886576455,4.910888711251958
9.83254211481902e-07,0.08008561712342468,380.19560215077837,235.808886576455,4.910888711251958
9.896201603967488e-07,0.08060412082416483,380.8694585260073,235.808886576455,4.910888711251958
1.000937402912032e-06,0.08152590518103621,382.0632660279977,235.808886576455,4.910888711251958
1.0028236099979127e-06,0.08167953590718144,382.2617210342946,235.808886576455,4.910888711251958
1.0068318000554089e-06,0.08200600120024006,382.6829552124578,235.808886576455,4.910888711251958
1.0183848184564271e-06,0.08294698939787958,383.89345697402615,235.808886576455,4.910888711251958
1.021685680856718e-06,0.08321584316863373,384.2383293958729,235.808886576455,4.910888711251958
1.0308809404003855e-06,0.08396479295859172,385.1967616249853,235.808886576455,4.910888711251958
1.0384257687439077e-06,0.08457931586317263,385.98067982825364,235.808886576455,4.910888711251958
1.0447917176587545e-06,0.08509781956391278,386.640384529111,235.808886576455,4.910888711251958
1.053279649545217e-06,0.08578915783156632,387.51755739671376,235.808886576455,4.910888711251958
1.056816287831243e-06,0.08607721544308862,387.8822319484207,235.808886576455,4.910888711251958
1.0622391332031498e-06,0.08651890378075616,388.440476556484,235.808886576455,4.910888711251958
1.0657757714891756e-06,0.08680696139227846,388.8039504263549,235.808886576455,4.910888711251958
1.0744994792613731e-06,0.08751750350070014,389.6985139126214,235.808886576455,4.910888711251958
1.0768572381187236e-06,0.08770954190838168,389.9398010370101,235.808886576455,4.910888711251958
1.0787434452046043e-06,0.0878631726345269,390.13268242478296,235.808886576455,4.910888711251958
1.08039387640475e-06,0.08799759951990399,390.3013457688569,235.808886576455,4.910888711251958
1.091711118920033e-06,0.08891938387677537,391.4551994288529,235.808886576455,4.910888711251958
1.0950119813203238e-06,0.0891882376475295,391.7908601264942,235.808886576455,4.910888711251958
1.1037356890925213e-06,0.08989877975595119,392.67606925885946,235.808886576455,4.910888711251958
1.105621896178402e-06,0.09005241048209642,392.86710657924465,235.808886576455,4.910888711251958
1.1122236209789838e-06,0.09059011802360473,393.53473854464664,235.808886576455,4.910888711251958
1.1162318110364801e-06,0.09091658331666334,393.93933255923963,235.808886576455,4.910888711251958
1.1258986223516177e-06,0.09170394078815763,394.912794086969,235.808886576455,4.910888711251958
1.1310856918377892e-06,0.09212642528505702,395.43379526364964,235.808886576455,4.910888711251958
1.1391020719527814e-06,0.09277935587117424,396.2371498171862,235.808886576455,4.910888711251958
1.151362418011005e-06,0.09377795559111823,397.46155800544125,235.808886576455,4.910888711251958
1.1570210392686465e-06,0.09423884776955392,398.0249534390904,235.808886576455,4.910888711251958
1.1596145740117323e-06,0.0944500900180036,398.2828171137537,235.808886576455,4.910888711251958
1.1681025058981948e-06,0.09514142828565714,399.1251663649117,235.808886576455,4.910888711251958
1.1879076802999403e-06,0.09675455091018204,401.0814188744698,235.808886576455,4.910888711251958
1.1923874221289065e-06,0.09711942388477696,401.52213574320245,235.808886576455,4.910888711251958
1.1945094051005221e-06,0.09729225845169034,401.7306709394442,235.808886576455,4.910888711251958
1.1980460433865482e-06,0.09758031606321264,402.07790882842795,235.808886576455,4.910888711251958
1.201111129901104e-06,0.09782996599319864,402.3785250903726,235.808886576455,4.910888711251958
1.2034688887584547e-06,0.09802200440088019,402.60956482841533,235.808886576455,4.910888711251958
1.20464776818713e-06,0.09811802360472095,402.72501849431706,235.808886576455,4.910888711251958
1.2086559582446262e-06,0.09844448889777956,403.1172317821074,235.808886576455,4.910888711251958
1.2166723383596186e-06,0.09909741948389679,403.90013987889813,235.808886576455,4.910888711251958
1.219030097216969e-06,0.09928945789157832,404.1300237670048,235.808886576455,4.910888711251958
1.2239813908174055e-06,0.09969273854770955,404.61221627056545,235.808886576455,4.910888711251958