File: datasets/aisi_316_L/data/M1/train_71.csv
Time(s),Strain(%),Stress(MPa),Temp(C),Log_SR(s-1)
0.0,0.0,0.0,395.7879771326061,-1.9002023668300998
0.0028609144257399893,3.6e-05,6.106633875,395.7879771326061,-1.9002023668300998
0.0052767977185870915,6.64e-05,11.263346925,395.7879771326061,-1.9002023668300998
0.005531101223097312,6.96e-05,11.806158824999999,395.7879771326061,-1.9002023668300998
0.0073112257546688614,9.2e-05,15.605842125,395.7879771326061,-1.9002023668300998
0.009345653790750632,0.0001176,19.948337325,395.7879771326061,-1.9002023668300998
0.01099862657006707,0.0001384,23.476614675,395.7879771326061,-1.9002023668300998
0.014368148004827502,0.0001808,30.66887235,395.7879771326061,-1.9002023668300998
0.015957544908016385,0.0002008,34.061446725,395.7879771326061,-1.9002023668300998
0.01627542428865416,0.0002048,34.7399616,395.7879771326061,-1.9002023668300998
0.0167840312976746,0.00021119999999999998,35.825585399999994,395.7879771326061,-1.9002023668300998
0.01697475892605727,0.0002136,36.232694325,395.7879771326061,-1.9002023668300998
0.017737669439587933,0.00022319999999999998,37.861130024999994,395.7879771326061,-1.9002023668300998
0.01926349046664926,0.00024239999999999998,41.118001424999996,395.7879771326061,-1.9002023668300998
0.02021712860856259,0.0002544,43.15354605,395.7879771326061,-1.9002023668300998
0.021297918502731033,0.000268,45.460496625000005,395.7879771326061,-1.9002023668300998
0.02199725314013414,0.0002768,46.95322935,395.7879771326061,-1.9002023668300998
0.023904529423960798,0.0003008,51.0243186,395.7879771326061,-1.9002023668300998
0.02441313643298124,0.0003072,52.109942399999994,395.7879771326061,-1.9002023668300998
0.026383988592935455,0.000332,56.316734625,395.7879771326061,-1.9002023668300998
0.02740120261097634,0.0003448,58.487982224999996,395.7879771326061,-1.9002023668300998
0.029308478894802998,0.00036879999999999997,62.559071474999996,395.7879771326061,-1.9002023668300998
0.029880661779950995,0.000376,63.78039825,395.7879771326061,-1.9002023668300998
0.031406482807012324,0.00039519999999999996,67.03726965,395.7879771326061,-1.9002023668300998
0.03375879022373187,0.00042479999999999997,72.05827972499999,395.7879771326061,-1.9002023668300998
0.03483958011790031,0.0004384,74.3652303,395.7879771326061,-1.9002023668300998
0.03617467351657898,0.0004552,77.214992775,395.7879771326061,-1.9002023668300998
0.036874008153982084,0.000464,78.7077255,395.7879771326061,-1.9002023668300998
0.03782764629589541,0.00047599999999999997,80.743270125,395.7879771326061,-1.9002023668300998
0.039289891446829185,0.0004944,83.86443855,395.7879771326061,-1.9002023668300998
0.03998922608423229,0.0005032,85.357171275,395.7879771326061,-1.9002023668300998
0.04075213659776296,0.0005128,86.985606975,395.7879771326061,-1.9002023668300998
0.04119716773065585,0.0005184,87.9355278,395.7879771326061,-1.9002023668300998
0.04316801989061006,0.0005432,92.14232002499999,395.7879771326061,-1.9002023668300998
0.04507529617443672,0.0005672,96.213409275,395.7879771326061,-1.9002023668300998
0.04564747905958472,0.0005744,97.43473605,395.7879771326061,-1.9002023668300998
0.04679184482988071,0.0005888,99.8773896,395.7879771326061,-1.9002023668300998
0.047491179467283824,0.0005976,101.370122325,395.7879771326061,-1.9002023668300998
0.048444817609197145,0.0006096,103.40566695,395.7879771326061,-1.9002023668300998
0.04946203162723803,0.0006224,105.57691455,395.7879771326061,-1.9002023668300998
0.04977991100787581,0.0006263999999999999,106.25542942499999,395.7879771326061,-1.9002023668300998
0.051115004406554476,0.0006432,109.10519190000001,395.7879771326061,-1.9002023668300998
0.05168718729170247,0.0006504,110.326518675,395.7879771326061,-1.9002023668300998
0.052704401309743354,0.0006632,112.49776627499999,395.7879771326061,-1.9002023668300998
0.05327658419489135,0.0006703999999999999,113.71909304999998,395.7879771326061,-1.9002023668300998
0.05486598109808024,0.0006904,117.111667425,395.7879771326061,-1.9002023668300998
0.05702756088641712,0.0007176,121.725568575,395.7879771326061,-1.9002023668300998
0.058426230161223336,0.0007352,124.711034025,395.7879771326061,-1.9002023668300998
0.059697747683774435,0.0007511999999999999,127.425093525,395.7879771326061,-1.9002023668300998
0.06249508623338687,0.0007863999999999999,133.39602442499998,395.7879771326061,-1.9002023668300998
0.06306726911853487,0.0007936,134.6173512,395.7879771326061,-1.9002023668300998
0.06351230025142775,0.0007991999999999999,135.567272025,395.7879771326061,-1.9002023668300998
0.06421163488883087,0.000808,137.06000475,395.7879771326061,-1.9002023668300998
0.06491096952623399,0.0008168,138.55273747500001,395.7879771326061,-1.9002023668300998
0.0664367905532953,0.0008359999999999999,141.80960887499998,395.7879771326061,-1.9002023668300998
0.0681533392087393,0.0008575999999999999,145.4735892,395.7879771326061,-1.9002023668300998
0.06834406683712196,0.00086,145.880698125,395.7879771326061,-1.9002023668300998
0.06961558435967306,0.0008759999999999999,148.594757625,395.7879771326061,-1.9002023668300998
0.07006061549256595,0.0008816,149.54467845,395.7879771326061,-1.9002023668300998
0.07133213301511705,0.0008975999999999999,150.25637882256268,395.7879771326061,-1.9002023668300998
0.07171358827188239,0.0009023999999999999,150.280896104792,395.7879771326061,-1.9002023668300998
0.07222219528090283,0.0009088,150.31350684459298,395.7879771326061,-1.9002023668300998
0.0729851057944335,0.0009184,150.3622555211058,395.7879771326061,-1.9002023668300998
0.07514668558277038,0.0009456,150.49930911956696,395.7879771326061,-1.9002023668300998
0.07590959609630105,0.0009551999999999999,150.54731275356963,395.7879771326061,-1.9002023668300998
0.07959699691169926,0.0010016,150.77672892249865,395.7879771326061,-1.9002023668300998
0.08086851443425036,0.0010176,150.85487183461055,395.7879771326061,-1.9002023668300998
0.08105924206263301,0.0010199999999999999,150.866551811937,395.7879771326061,-1.9002023668300998
0.08144069731939836,0.0010248,150.8898796619529,395.7879771326061,-1.9002023668300998
0.08468306700190367,0.0010655999999999999,151.08647478277467,395.7879771326061,-1.9002023668300998
0.08760755730377122,0.0011024,151.2612915536845,395.7879771326061,-1.9002023668300998
0.08951483358759789,0.0011264,151.37407754215008,395.7879771326061,-1.9002023668300998
0.09015059234887345,0.0011344,151.4114640868403,395.7879771326061,-1.9002023668300998
0.09078635111014899,0.0011424,151.44874794560866,395.7879771326061,-1.9002023668300998
0.09167641337593475,0.0011535999999999999,151.50077473291918,395.7879771326061,-1.9002023668300998
0.09224859626108277,0.0011608,151.53411652808936,395.7879771326061,-1.9002023668300998
0.09243932388946542,0.0011631999999999999,151.54521252385499,395.7879771326061,-1.9002023668300998
0.09396514491652674,0.0011824,151.63366131532132,395.7879771326061,-1.9002023668300998
0.09421944842103698,0.0011856,151.64834815231538,395.7879771326061,-1.9002023668300998
0.09561811769584319,0.0012032,151.7288510970158,395.7879771326061,-1.9002023668300998
0.09784327336030763,0.0012312,151.85598385050076,395.7879771326061,-1.9002023668300998
0.09828830449320052,0.0012368,151.8812745420848,395.7879771326061,-1.9002023668300998
0.09924194263511385,0.0012488,151.93531898741517,395.7879771326061,-1.9002023668300998
0.10025915665315473,0.0012615999999999999,151.9927436345964,395.7879771326061,-1.9002023668300998
0.10267503994600183,0.001292,152.1282240790652,395.7879771326061,-1.9002023668300998
0.10318364695502227,0.0012984,152.15658721433934,395.7879771326061,-1.9002023668300998
0.10356510221178761,0.0013032,152.17782379803805,395.7879771326061,-1.9002023668300998
0.10375582984017026,0.0013055999999999999,152.18843064872917,395.7879771326061,-1.9002023668300998
0.10540880261948671,0.0013264,152.28004033112725,395.7879771326061,-1.9002023668300998
0.10674389601816536,0.0013432,152.35362441838157,395.7879771326061,-1.9002023668300998
0.1082697170452267,0.0013624,152.43728242104316,395.7879771326061,-1.9002023668300998
0.11043129683356358,0.0013896,152.5550150757312,395.7879771326061,-1.9002023668300998
0.11138493497547691,0.0014016,152.60666986395222,395.7879771326061,-1.9002023668300998
0.11500875991474756,0.0014471999999999998,152.801404776325,395.7879771326061,-1.9002023668300998
0.11621670156117112,0.0014624,152.86578267003395,395.7879771326061,-1.9002023668300998
0.1176789467121049,0.0014808,152.94336569905605,395.7879771326061,-1.9002023668300998
0.11869616073014577,0.0014935999999999999,152.99711490196114,395.7879771326061,-1.9002023668300998
0.11939549536754887,0.0015023999999999999,153.03396331529444,395.7879771326061,-1.9002023668300998
0.12136634752750308,0.0015271999999999998,153.13735869520977,395.7879771326061,-1.9002023668300998
0.12238356154554397,0.00154,153.1904677195082,395.7879771326061,-1.9002023668300998
0.12276501680230932,0.0015448,153.21033918443987,395.7879771326061,-1.9002023668300998
0.12371865494422264,0.0015568,153.2599127849997,395.7879771326061,-1.9002023668300998
0.12696102462672798,0.0015976,153.4273593631633,395.7879771326061,-1.9002023668300998
0.12835969390153418,0.0016152,153.49907540185208,395.7879771326061,-1.9002023668300998
0.12956763554795772,0.0016304,153.56076706629239,395.7879771326061,-1.9002023668300998
0.12994909080472306,0.0016351999999999998,153.58020199017747,395.7879771326061,-1.9002023668300998
0.13115703245114663,0.0016504,153.64159964539738,395.7879771326061,-1.9002023668300998
0.1324285499736977,0.0016664,153.705990985214,395.7879771326061,-1.9002023668300998
0.1328735811065906,0.0016719999999999999,153.72847093099742,395.7879771326061,-1.9002023668300998
0.1333186122394835,0.0016776,153.75092153212785,395.7879771326061,-1.9002023668300998
0.1344629780097795,0.001692,153.80851785258932,395.7879771326061,-1.9002023668300998
0.13738746831164703,0.0017288,153.95484659842234,395.7879771326061,-1.9002023668300998
0.13910401696709102,0.0017503999999999998,154.04016945492577,395.7879771326061,-1.9002023668300998
0.13935832047160124,0.0017536,154.05277486852677,395.7879771326061,-1.9002023668300998
0.1399940792328768,0.0017615999999999999,154.08424921793812,395.7879771326061,-1.9002023668300998
0.14062983799415235,0.0017695999999999999,154.1156678716965,395.7879771326061,-1.9002023668300998
0.14183777964057592,0.0017848,154.17521112166415,395.7879771326061,-1.9002023668300998
0.14247353840185145,0.0017928,154.2064702220578,395.7879771326061,-1.9002023668300998
0.14419008705729544,0.0018143999999999999,154.29059924757942,395.7879771326061,-1.9002023668300998
0.145970211588867,0.0018368,154.3774326241897,395.7879771326061,-1.9002023668300998
0.14635166684563233,0.0018415999999999999,154.3959859341082,395.7879771326061,-1.9002023668300998
0.1481317913772039,0.001864,154.48231990359497,395.7879771326061,-1.9002023668300998
0.1483860948817141,0.0018671999999999998,154.49462021674051,395.7879771326061,-1.9002023668300998
0.1489582777668621,0.0018743999999999998,154.52226590201312,395.7879771326061,-1.9002023668300998
0.15156488868809187,0.0019072,154.64768694354004,395.7879771326061,-1.9002023668300998
0.15328143734353586,0.0019287999999999998,154.72982216432612,395.7879771326061,-1.9002023668300998
0.15544301713187272,0.001956,154.83274319704552,395.7879771326061,-1.9002023668300998
0.1566509587782963,0.0019711999999999998,154.8900147402268,395.7879771326061,-1.9002023668300998
0.15792247630084738,0.0019871999999999997,154.95011481832648,395.7879771326061,-1.9002023668300998
0.15944829732790872,0.0020063999999999998,155.02198637358896,395.7879771326061,-1.9002023668300998
0.16205490824913849,0.0020391999999999997,155.14414950689456,395.7879771326061,-1.9002023668300998
0.16288139463879672,0.0020496,155.1827238280275,395.7879771326061,-1.9002023668300998
0.16358072927619982,0.0020583999999999997,155.21530405230592,395.7879771326061,-1.9002023668300998
0.1641529121613478,0.0020656,155.24192021404647,395.7879771326061,-1.9002023668300998
0.16440721566585806,0.0020688,155.25373800264785,395.7879771326061,-1.9002023668300998
0.16593303669291937,0.002088,155.32449560241818,395.7879771326061,-1.9002023668300998
0.16726813009159805,0.0021048,155.38620060595147,395.7879771326061,-1.9002023668300998
0.16777673710061847,0.0021111999999999997,155.40965671200513,395.7879771326061,-1.9002023668300998
0.16809461648125623,0.0021152,155.4243026968499,395.7879771326061,-1.9002023668300998
0.17063765152635846,0.0021471999999999997,155.54108422064752,395.7879771326061,-1.9002023668300998
0.1708283791547411,0.0021495999999999998,155.54981537642186,395.7879771326061,-1.9002023668300998
0.17120983441150645,0.0021544,155.56726629092392,395.7879771326061,-1.9002023668300998
0.17241777605793002,0.0021696,155.62242774967027,395.7879771326061,-1.9002023668300998
0.17279923131469535,0.0021744,155.6398158182273,395.7879771326061,-1.9002023668300998
0.17349856595209845,0.0021831999999999997,155.67165511360025,395.7879771326061,-1.9002023668300998
0.17438862821788423,0.0021944,155.7121055579782,395.7879771326061,-1.9002023668300998
0.17527869048367,0.0022056,155.75247556454974,395.7879771326061,-1.9002023668300998
0.1778217255287722,0.0022375999999999997,155.86738024367693,395.7879771326061,-1.9002023668300998
0.17871178779455799,0.0022488,155.90744524278205,395.7879771326061,-1.9002023668300998
0.18049191232612952,0.0022711999999999997,155.98734253840098,395.7879771326061,-1.9002023668300998
0.1811276710874051,0.0022792,156.01580273272975,395.7879771326061,-1.9002023668300998
0.1829713714951042,0.0023024,156.09811780839146,395.7879771326061,-1.9002023668300998
0.18475149602667573,0.0023247999999999997,156.17728803702184,395.7879771326061,-1.9002023668300998
0.1856415582924615,0.002336,156.21676154777535,395.7879771326061,-1.9002023668300998
0.18735810694790553,0.0023576,156.29268121571053,395.7879771326061,-1.9002023668300998
0.1879302898330535,0.0023648,156.31792742593697,395.7879771326061,-1.9002023668300998
0.1886296244704566,0.0023736,156.3487432314041,395.7879771326061,-1.9002023668300998
0.19110908363943127,0.0024048,156.4576420524982,395.7879771326061,-1.9002023668300998
0.19168126652457929,0.002412,156.4826941337503,395.7879771326061,-1.9002023668300998
0.19269848054262015,0.0024248,156.52715927342197,395.7879771326061,-1.9002023668300998
0.19664018486252857,0.0024744,156.69860393615969,395.7879771326061,-1.9002023668300998
0.19702164011929393,0.0024792,156.71512390396904,395.7879771326061,-1.9002023668300998
0.19746667125218678,0.0024847999999999997,156.73438144237076,395.7879771326061,-1.9002023668300998
0.198865340526993,0.0025023999999999997,156.794795234565,395.7879771326061,-1.9002023668300998
0.1993103716598859,0.002508,156.8139830232774,395.7879771326061,-1.9002023668300998
0.20007328217341658,0.0025176,156.84683754692543,395.7879771326061,-1.9002023668300998
0.2020441343333708,0.0025423999999999998,156.93148638649822,395.7879771326061,-1.9002023668300998
0.2038878347410699,0.0025656,157.01038294051008,395.7879771326061,-1.9002023668300998
0.20573153514876902,0.0025888,157.08900173870632,395.7879771326061,-1.9002023668300998
0.20674874916680988,0.0026016,157.132259991307,395.7879771326061,-1.9002023668300998
0.20763881143259563,0.0026127999999999998,157.1700429181086,395.7879771326061,-1.9002023668300998
0.21018184647769786,0.0026447999999999997,157.27764765196036,395.7879771326061,-1.9002023668300998
0.21196197100926942,0.0026671999999999998,157.35266905071896,395.7879771326061,-1.9002023668300998
0.21253415389441743,0.0026744,157.37673083467618,395.7879771326061,-1.9002023668300998
0.2129791850273103,0.00268,157.39542809351343,395.7879771326061,-1.9002023668300998
0.21437785430211653,0.0026976,157.4540919570915,395.7879771326061,-1.9002023668300998
0.21552222007241253,0.002712,157.50197871637366,395.7879771326061,-1.9002023668300998
0.2168573134710912,0.0027288,157.55772145038875,395.7879771326061,-1.9002023668300998
0.2173659204801116,0.0027351999999999997,157.57892155214594,395.7879771326061,-1.9002023668300998
0.21978180377295872,0.0027656,157.67935902705446,395.7879771326061,-1.9002023668300998
0.22016325902972403,0.0027703999999999997,157.6951781310865,395.7879771326061,-1.9002023668300998
0.22098974541938227,0.0027808,157.72941623321088,395.7879771326061,-1.9002023668300998
0.22168908005678536,0.0027895999999999997,157.75834794752814,395.7879771326061,-1.9002023668300998
0.22315132520771913,0.0028079999999999997,157.81872676572496,395.7879771326061,-1.9002023668300998
0.22556720850056627,0.0028384,157.91814610396906,395.7879771326061,-1.9002023668300998
0.22613939138571423,0.0028455999999999998,157.9416318607718,395.7879771326061,-1.9002023668300998
0.22868242643081646,0.0028775999999999997,158.0457338701034,395.7879771326061,-1.9002023668300998
0.23078043034302578,0.002904,158.13127856777285,395.7879771326061,-1.9002023668300998
0.23319631363587287,0.0029343999999999998,158.22940977339164,395.7879771326061,-1.9002023668300998
0.23395922414940357,0.002944,158.26031609803826,395.7879771326061,-1.9002023668300998
0.23465855878680666,0.0029527999999999998,158.28861238500772,395.7879771326061,-1.9002023668300998
0.2351671657958271,0.0029592,158.30917084982792,395.7879771326061,-1.9002023668300998
0.23701086620352624,0.0029824,158.38355036444221,395.7879771326061,-1.9002023668300998
0.23853668723058752,0.0030015999999999997,158.4449353278922,395.7879771326061,-1.9002023668300998
0.23910887011573553,0.0030088,158.46791518496497,395.7879771326061,-1.9002023668300998
0.2398717806292662,0.0030184,158.49852166140653,395.7879771326061,-1.9002023668300998
0.24018966000990397,0.0030223999999999997,158.5112631525658,395.7879771326061,-1.9002023668300998
0.24031681176215908,0.0030239999999999998,158.51635790741503,395.7879771326061,-1.9002023668300998
0.2421605121698582,0.0030472,158.5901141143906,395.7879771326061,-1.9002023668300998
0.24413136432981242,0.003072,158.66871519190573,395.7879771326061,-1.9002023668300998
0.2447035472149604,0.0030792,158.69148845673348,395.7879771326061,-1.9002023668300998
0.24807306864972084,0.0031216,158.8251788392707,395.7879771326061,-1.9002023668300998
0.24858167565874126,0.0031279999999999997,158.845296836117,395.7879771326061,-1.9002023668300998
0.2516333177128639,0.0031663999999999998,158.9656694191168,395.7879771326061,-1.9002023668300998
0.25271410760703233,0.0031799999999999997,159.0081646774287,395.7879771326061,-1.9002023668300998
0.2545578080147315,0.0032032,159.08049336653255,395.7879771326061,-1.9002023668300998
0.2553842944043897,0.0032136,159.11285022230524,395.7879771326061,-1.9002023668300998
0.25754587419272656,0.0032408,159.1972833536405,395.7879771326061,-1.9002023668300998
0.2590716952197879,0.00326,159.25671689438596,395.7879771326061,-1.9002023668300998
0.2611696991319972,0.0032863999999999997,159.33821559079493,395.7879771326061,-1.9002023668300998
0.2638398859293546,0.00332,159.4415728732124,395.7879771326061,-1.9002023668300998
0.26409418943386476,0.0033231999999999997,159.45139509907935,395.7879771326061,-1.9002023668300998
0.2652385552041608,0.0033376,159.49554954802088,395.7879771326061,-1.9002023668300998
0.2658743139654363,0.0033456,159.52004769250357,395.7879771326061,-1.9002023668300998
0.26657364860283944,0.0033544,159.54696927927364,395.7879771326061,-1.9002023668300998
0.2670822556118599,0.0033607999999999997,159.56653131759873,395.7879771326061,-1.9002023668300998
0.2687352283911763,0.0033816,159.6300078413641,395.7879771326061,-1.9002023668300998
0.2703246252943652,0.0034016,159.6908995164193,395.7879771326061,-1.9002023668300998
0.2731855397201052,0.0034376,159.80015383342257,395.7879771326061,-1.9002023668300998
0.27337626734848786,0.00344,159.80742154923993,395.7879771326061,-1.9002023668300998
0.27420275373814607,0.0034503999999999997,159.8388921610789,395.7879771326061,-1.9002023668300998
0.2759828782697176,0.0034728,159.90654964356088,395.7879771326061,-1.9002023668300998
0.2770000922877585,0.0034855999999999997,159.94513464557198,395.7879771326061,-1.9002023668300998
0.27725439579226874,0.0034888,159.95477225675913,395.7879771326061,-1.9002023668300998
0.2783987615625647,0.0035031999999999997,159.99809891484475,395.7879771326061,-1.9002023668300998
0.27992458258962605,0.0035223999999999997,160.05575990224514,395.7879771326061,-1.9002023668300998
0.28056034135090163,0.0035304,160.07974912144437,395.7879771326061,-1.9002023668300998
0.2823404658824732,0.0035528,160.1468064103259,395.7879771326061,-1.9002023668300998
0.2837391351572794,0.0035704,160.19937867557644,395.7879771326061,-1.9002023668300998
0.2851378044320856,0.003588,160.25184996863172,395.7879771326061,-1.9002023668300998
0.28710865659203977,0.0036127999999999998,160.32561673416802,395.7879771326061,-1.9002023668300998
0.2884437499907184,0.0036295999999999998,160.37547560079005,395.7879771326061,-1.9002023668300998
0.28971526751326954,0.0036455999999999997,160.4228766259133,395.7879771326061,-1.9002023668300998
0.2900967227700349,0.0036504,160.43708110329297,395.7879771326061,-1.9002023668300998
0.2906689056551829,0.0036576,160.45837416886258,395.7879771326061,-1.9002023668300998
0.2923218784344993,0.0036783999999999996,160.51979583621068,395.7879771326061,-1.9002023668300998
0.29346624420479533,0.0036928,160.56223920360233,395.7879771326061,-1.9002023668300998
0.2944198823467087,0.0037048,160.59755939163287,395.7879771326061,-1.9002023668300998
0.2954370963647495,0.0037175999999999997,160.63518511644756,395.7879771326061,-1.9002023668300998
0.29696291739181085,0.0037367999999999998,160.6915291100053,395.7879771326061,-1.9002023668300998
0.29842516254274465,0.0037551999999999998,160.74541958566994,395.7879771326061,-1.9002023668300998
0.29982383181755085,0.0037727999999999998,160.79687071612227,395.7879771326061,-1.9002023668300998
0.30192183572976017,0.0037992,160.87387224616438,395.7879771326061,-1.9002023668300998
0.3028754738716735,0.0038112,160.9088039292953,395.7879771326061,-1.9002023668300998
0.30567281242128597,0.0038464,161.01102359012657,395.7879771326061,-1.9002023668300998
0.30681717819158194,0.0038607999999999997,161.05273549571152,395.7879771326061,-1.9002023668300998
0.3085973027231535,0.0038832,161.11750028388104,395.7879771326061,-1.9002023668300998
0.3095509408650668,0.0038951999999999997,161.15213576462705,395.7879771326061,-1.9002023668300998
0.31082245838761796,0.0039112,161.19825174250903,395.7879771326061,-1.9002023668300998
0.3127933105475721,0.003935999999999999,161.26958637339465,395.7879771326061,-1.9002023668300998
0.31317476580433745,0.0039407999999999995,161.28337280624308,395.7879771326061,-1.9002023668300998
0.3157813767255672,0.0039736,161.37740543692541,395.7879771326061,-1.9002023668300998
0.316671438991353,0.0039848,161.4094447458248,395.7879771326061,-1.9002023668300998
0.32703613815164734,0.004115223044608922,161.77999059776062,395.7879771326061,-1.9002023668300998
0.35145415818863596,0.00442248449689938,162.6352993461277,395.7879771326061,-1.9002023668300998
0.38197668323487177,0.004806561312262453,163.6724981944463,395.7879771326061,-1.9002023668300998
0.38808118824411897,0.004883376675335067,163.87600196083667,395.7879771326061,-1.9002023668300998
0.4155514607857312,0.005229045809161833,164.77674315658896,395.7879771326061,-1.9002023668300998
0.4476001120842787,0.005632326465293058,165.798749443111,395.7879771326061,-1.9002023668300998
0.47354425837357916,0.00595879175835167,166.60532741993507,395.7879771326061,-1.9002023668300998
0.5132235409336857,0.006458091618323665,167.80633873845406,395.7879771326061,-1.9002023668300998
0.5376415609706744,0.006765353070614123,168.52743286880414,395.7879771326061,-1.9002023668300998
0.591055979801587,0.0074374874974994995,170.06171364204334,395.7879771326061,-1.9002023668300998
0.6032649898200813,0.007591118223644729,170.40469536801638,395.7879771326061,-1.9002023668300998
0.6307352623616935,0.007936787357471494,171.16665701708763,395.7879771326061,-1.9002023668300998
0.6444703986324997,0.008109621924384877,171.5427756749308,395.7879771326061,-1.9002023668300998
0.6704145449218001,0.008436087217443489,172.24479987395745,395.7879771326061,-1.9002023668300998
0.6795713024356708,0.00855131026205241,172.49003279318657,395.7879771326061,-1.9002023668300998
0.6933064387064769,0.008724144828965793,172.85547955381074,395.7879771326061,-1.9002023668300998
0.7161983324911537,0.009012202440488098,173.45834412446732,395.7879771326061,-1.9002023668300998
0.7345118475188953,0.009242648529705941,173.9352417378304,395.7879771326061,-1.9002023668300998
0.7696127513220664,0.009684336867373475,174.83652774398936,395.7879771326061,-1.9002023668300998
0.801661402620614,0.010087617523504702,175.64553321864446,395.7879771326061,-1.9002023668300998
0.8230271701529791,0.010356471294258852,176.17787258008437,395.7879771326061,-1.9002023668300998
0.8504974426945914,0.010702140428085618,176.85445493039623,395.7879771326061,-1.9002023668300998
0.8947551040116332,0.011259051810362072,177.92684458084148,395.7879771326061,-1.9002023668300998
0.9191731240486217,0.01156631326265253,178.50964433669517,395.7879771326061,-1.9002023668300998
0.9512217753471693,0.011969593918783756,179.26548618215182,395.7879771326061,-1.9002023668300998
0.9802181741410934,0.012334466893378675,179.94082681416288,395.7879771326061,-1.9002023668300998
1.0549983605043711,0.013275455091018204,181.6474790877923,395.7879771326061,-1.9002023668300998
1.0672073705228655,0.013429085817163433,181.92157229564955,395.7879771326061,-1.9002023668300998
1.1129911580922192,0.014005201040208042,182.93870873007415,395.7879771326061,-1.9002023668300998
1.1267262943630252,0.014178035607121425,183.24065017582342,395.7879771326061,-1.9002023668300998
1.187771344455497,0.01494618923784757,184.56561171311773,395.7879771326061,-1.9002023668300998
1.2121893644924855,0.015253450690138028,185.08812644517113,395.7879771326061,-1.9002023668300998
1.2213461220063564,0.01536867373474695,185.2830091127596,395.7879771326061,-1.9002023668300998
1.238133510781786,0.01557991598319664,185.6388204318333,395.7879771326061,-1.9002023668300998
1.288495677108075,0.01621364272854571,186.6951330063927,395.7879771326061,-1.9002023668300998
1.3403839696866757,0.01686657331466293,187.7667454241761,395.7879771326061,-1.9002023668300998
1.3709064947329115,0.017250650130026003,188.38954802408009,395.7879771326061,-1.9002023668300998
1.4197425348068888,0.01786517303460692,189.37489926256373,395.7879771326061,-1.9002023668300998
1.4640001961239308,0.018422084416883377,190.25651291572603,395.7879771326061,-1.9002023668300998
1.5097839836932845,0.018998199639927986,191.15765646538938,395.7879771326061,-1.9002023668300998
1.5998254325796801,0.02013122624524905,192.89939816086098,395.7879771326061,-1.9002023668300998
1.6471353464013456,0.020726545309061813,193.79920250290184,395.7879771326061,-1.9002023668300998
1.7020758914845702,0.021417883576715344,194.83158248848795,395.7879771326061,-1.9002023668300998
1.7142849015030646,0.021571514302860573,195.0592257190113,395.7879771326061,-1.9002023668300998
1.731072290278494,0.02178275655131026,195.37120543925195,395.7879771326061,-1.9002023668300998
1.7661731940816654,0.022224444888977797,196.0197393793704,395.7879771326061,-1.9002023668300998
1.7936434666232777,0.022570114022804563,196.52378769976207,395.7879771326061,-1.9002023668300998
1.8058524766417718,0.02272374474894979,196.74684183869692,395.7879771326061,-1.9002023668300998
1.8241659916695134,0.022954190838167635,197.0803234610686,395.7879771326061,-1.9002023668300998
1.857740769220373,0.023376675335067015,197.68833477874625,395.7879771326061,-1.9002023668300998
1.883684915509673,0.023703140628125625,198.1552310832034,395.7879771326061,-1.9002023668300998
1.8897894205189203,0.02377995599119824,198.26472375519364,395.7879771326061,-1.9002023668300998
1.9096290617989733,0.024029605921184236,198.61962608267544,395.7879771326061,-1.9002023668300998
1.9813569956576278,0.024932186437287458,199.8909084610132,395.7879771326061,-1.9002023668300998
1.9996705106853692,0.025162632526505302,200.21259883325902,395.7879771326061,-1.9002023668300998
2.0332452882362286,0.025585117023404682,200.79939603817098,395.7879771326061,-1.9002023668300998
2.108025474599506,0.02652610522104421,202.09293903185807,395.7879771326061,-1.9002023668300998
2.150757009664236,0.02706381276255251,202.8240692923649,395.7879771326061,-1.9002023668300998
2.161439893430419,0.027198239647929588,203.0059639483117,395.7879771326061,-1.9002023668300998
2.1950146709812786,0.027620724144828968,203.57536356990593,395.7879771326061,-1.9002023668300998
2.2469029635598794,0.02827365473094619,204.44870865914314,395.7879771326061,-1.9002023668300998
2.289634498624609,0.02881136227245449,205.1620428877042,395.7879771326061,-1.9002023668300998
2.3399966649508985,0.02944508901780356,205.9961265156446,395.7879771326061,-1.9002023668300998
2.3827282000156282,0.029982796559311863,206.6983578730012,395.7879771326061,-1.9002023668300998
2.4407209976034765,0.0307125425085017,207.6435799768978,395.7879771326061,-1.9002023668300998
2.4758219014066474,0.031154230846169233,208.21143387001626,395.7879771326061,-1.9002023668300998
2.4834525326682066,0.03125025005001,208.33446389956862,395.7879771326061,-1.9002023668300998
2.524657941480625,0.03176875375075015,208.99629581416778,395.7879771326061,-1.9002023668300998
2.5322885727421838,0.03186477295459092,209.11839358628015,395.7879771326061,-1.9002023668300998
2.5628110977884195,0.03224884976995399,209.60535658529363,395.7879771326061,-1.9002023668300998
2.5811246128161613,0.032479295859171836,209.89644880128768,395.7879771326061,-1.9002023668300998
2.689479576730298,0.03384276855371074,211.60254487879513,395.7879771326061,-1.9002023668300998
2.7138975967672865,0.0341500300060012,211.98329094911452,395.7879771326061,-1.9002023668300998
2.7505246268227697,0.034610922184436885,212.5519145142406,395.7879771326061,-1.9002023668300998
2.7718903943551347,0.03487977595519104,212.88224785014415,395.7879771326061,-1.9002023668300998
2.8237786869337356,0.03553270654130826,213.6803787197886,395.7879771326061,-1.9002023668300998
2.8604057169892183,0.03599359871974395,214.2403250406423,395.7879771326061,-1.9002023668300998
2.890928242035455,0.036377675535107026,214.704814067426,395.7879771326061,-1.9002023668300998
2.912294009567819,0.03664652930586117,215.02881904679538,395.7879771326061,-1.9002023668300998
2.939764282109432,0.03699219843968794,215.44403793874858,395.7879771326061,-1.9002023668300998
3.04048861476201,0.03825965193038608,216.9537306201848,395.7879771326061,-1.9002023668300998
3.1259516848914704,0.03933506701340268,218.21944642687535,395.7879771326061,-1.9002023668300998
3.179366103722383,0.04000720144028806,219.00366882953622,395.7879771326061,-1.9002023668300998
3.2297282700486716,0.040640928185637124,219.7383852889421,395.7879771326061,-1.9002023668300998
3.2388850275625427,0.04075615123024605,219.87148866514033,395.7879771326061,-1.9002023668300998
3.2510940375810367,0.04090978195639128,220.048731769039,395.7879771326061,-1.9002023668300998
3.315191340178132,0.04171634326865373,220.97503340683997,395.7879771326061,-1.9002023668300998
3.3335048552058737,0.04194678935787158,221.23840468989863,395.7879771326061,-1.9002023668300998
3.3579228752428625,0.042254050810162036,221.58869028877334,395.7879771326061,-1.9002023668300998
3.3670796327567336,0.04236927385477096,221.71979109840836,395.7879771326061,-1.9002023668300998
3.37318413776598,0.04244608921784357,221.8071143988654,395.7879771326061,-1.9002023668300998
3.379288642775228,0.04252290458091619,221.89437608918382,395.7879771326061,-1.9002023668300998
3.4174417990830217,0.04300300060012002,222.43837537996285,395.7879771326061,-1.9002023668300998
3.464751712904687,0.04359831966393278,223.1096560959893,395.7879771326061,-1.9002023668300998
3.5059571217171053,0.04411682336467293,223.69141258206668,395.7879771326061,-1.9002023668300998
3.585315686837319,0.045115423084616926,224.80437353791487,395.7879771326061,-1.9002023668300998
3.595998570603501,0.045249849969994,224.95345810883575,395.7879771326061,-1.9002023668300998
3.6570436206959727,0.04601800360072014,225.80207954499846,395.7879771326061,-1.9002023668300998
3.6738310094714026,0.046229245849169834,226.03447960628654,395.7879771326061,-1.9002023668300998
3.692144524499145,0.046459691938387684,226.28753511096167,395.7879771326061,-1.9002023668300998
3.786764352142475,0.0476503300660132,227.58727115394166,395.7879771326061,-1.9002023668300998
3.80813011967484,0.047919183836767354,227.8789997301813,395.7879771326061,-1.9002023668300998
3.82491750845027,0.048130426085217046,228.10776746509467,395.7879771326061,-1.9002023668300998
3.834074265964141,0.04824564912982597,228.2323848081888,395.7879771326061,-1.9002023668300998
3.8462832759826355,0.0483992798559712,228.39836086082187,395.7879771326061,-1.9002023668300998
3.9134328310843536,0.04924424884976995,229.3075826744531,395.7879771326061,-1.9002023668300998
3.9195373360936014,0.049321064212842575,229.38993631401402,395.7879771326061,-1.9002023668300998
3.963794997410643,0.04987797559511903,229.98551137687005,395.7879771326061,-1.9002023668300998
3.9958436487091906,0.05028125625125025,230.41517207520465,395.7879771326061,-1.9002023668300998
4.0248400475031145,0.050646129225845174,230.80275601956492,395.7879771326061,-1.9002023668300998
4.0584148250539736,0.051068613722744544,231.25017954740161,395.7879771326061,-1.9002023668300998
4.104198612623327,0.051644728945789156,231.85798304646903,395.7879771326061,-1.9002023668300998
4.1133553701371985,0.05175995199039808,231.9792258038589,395.7879771326061,-1.9002023668300998
4.139299516426499,0.0520864172834567,232.3221766500834,395.7879771326061,-1.9002023668300998
4.178978798986606,0.05258571714342869,232.84507262989865,395.7879771326061,-1.9002023668300998
4.1911878090051,0.05273934786957392,233.00557367948772,395.7879771326061,-1.9002023668300998
4.2247625865559595,0.0531618323664733,233.4460141080572,395.7879771326061,-1.9002023668300998
4.235445470322142,0.05329625925185037,233.58586769255774,395.7879771326061,-1.9002023668300998
4.267494121620689,0.0536995399079816,234.00460534313166,395.7879771326061,-1.9002023668300998
4.323960792956225,0.05441008201640328,234.7394093341059,395.7879771326061,-1.9002023668300998
4.383479716796384,0.05515903180636127,235.50989266174702,395.7879771326061,-1.9002023668300998
4.394162600562567,0.05529345869173835,235.64775156891292,395.7879771326061,-1.9002023668300998
4.420106746851867,0.055619923984796954,235.98200871732908,395.7879771326061,-1.9002023668300998
4.444524766888856,0.05592718543708741,236.29590539467057,395.7879771326061,-1.9002023668300998
4.45520765065504,0.056061612322464496,236.4330236228543,395.7879771326061,-1.9002023668300998
4.487256301953587,0.05646489297859572,236.8436110040304,395.7879771326061,-1.9002023668300998
4.496413059467458,0.056580116023204646,236.96071141824328,395.7879771326061,-1.9002023668300998
4.522357205756758,0.05690658131626325,237.2919919357993,395.7879771326061,-1.9002023668300998
4.580350003344606,0.05763632726545309,238.0298329148397,395.7879771326061,-1.9002023668300998
4.607820275886218,0.05798199639927985,238.37806408203966,395.7879771326061,-1.9002023668300998
4.645973432194013,0.0584620924184837,238.86037828913132,395.7879771326061,-1.9002023668300998
4.6917572197633675,0.05903820764152831,239.43712108820196,395.7879771326061,-1.9002023668300998
4.699387851024926,0.05913422684536908,239.5330310907097,395.7879771326061,-1.9002023668300998
4.777220289892828,0.060113622724544916,240.50786873035437,395.7879771326061,-1.9002023668300998
4.810795067443686,0.060536107221444285,240.9264724346526,395.7879771326061,-1.9002023668300998
4.830634708723739,0.06078575715143028,241.1732936362747,395.7879771326061,-1.9002023668300998
4.842843718742233,0.06093938787757551,241.32498711660796,395.7879771326061,-1.9002023668300998
4.8581049812653525,0.06113142628525706,241.51439439441702,395.7879771326061,-1.9002023668300998
4.905414895087017,0.061726745349069814,242.10008764560806,395.7879771326061,-1.9002023668300998
5.003086975234972,0.06295579115823165,243.30233761562354,395.7879771326061,-1.9002023668300998
5.03513562653352,0.06335907181436287,243.69482675195084,395.7879771326061,-1.9002023668300998
5.0381878790381425,0.06339747949589918,243.73215578332238,395.7879771326061,-1.9002023668300998
5.0488707628043255,0.06353190638127626,243.86273799427948,395.7879771326061,-1.9002023668300998
5.083971666607496,0.06397359471894379,244.29103714226434,395.7879771326061,-1.9002023668300998
5.112968065401421,0.06433846769353871,244.6439803123671,395.7879771326061,-1.9002023668300998
5.123650949167603,0.06447289457891578,244.77381511990595,395.7879771326061,-1.9002023668300998
5.132807706681474,0.0645881176235247,244.88501809051675,395.7879771326061,-1.9002023668300998
5.166382484232334,0.06501060212042409,245.29210206284534,395.7879771326061,-1.9002023668300998
5.198431135530881,0.06541388277655531,245.67972082688695,395.7879771326061,-1.9002023668300998
5.254897806866417,0.066124424884977,246.36040816927996,395.7879771326061,-1.9002023668300998
5.317468983211201,0.0669117823564713,247.11136015671468,395.7879771326061,-1.9002023668300998
5.367831149537491,0.06754550910182038,247.71328475980204,395.7879771326061,-1.9002023668300998
5.387670790817544,0.06779515903180637,247.94980135903333,395.7879771326061,-1.9002023668300998
5.416667189611466,0.06816003200640128,248.29486937519113,395.7879771326061,-1.9002023668300998
5.427350073377649,0.06829445889177836,248.42181800166364,395.7879771326061,-1.9002023668300998
5.450241967162326,0.06858251650330066,248.69352308278695,395.7879771326061,-1.9002023668300998
5.508234764750174,0.0693122624524905,249.3798582113517,395.7879771326061,-1.9002023668300998
5.511287017254798,0.0693506701340268,249.41590284646597,395.7879771326061,-1.9002023668300998
5.514339269759422,0.06938907781556311,249.45193969716863,395.7879771326061,-1.9002023668300998
5.601328466141194,0.07048369673934787,250.4757429336798,395.7879771326061,-1.9002023668300998
5.621168107421247,0.07073334666933387,250.70837130683628,395.7879771326061,-1.9002023668300998
5.63185099118743,0.07086777355471095,250.83350009827362,395.7879771326061,-1.9002023668300998
5.644060001205925,0.07102140428085618,250.9763911392534,395.7879771326061,-1.9002023668300998
5.6822131575137185,0.07150150030006001,251.42215064996924,395.7879771326061,-1.9002023668300998
5.694422167532212,0.07165513102620524,251.56454696218765,395.7879771326061,-1.9002023668300998
5.70968343005533,0.07184716943388678,251.7423750247716,395.7879771326061,-1.9002023668300998
5.749362712615437,0.07234646929385878,252.2038626099333,395.7879771326061,-1.9002023668300998
5.808881636455597,0.07309541908381677,252.8937717903574,395.7879771326061,-1.9002023668300998
5.83635190899721,0.07344108821764353,253.21126104462178,395.7879771326061,-1.9002023668300998
5.8607699290341975,0.07374834966993399,253.4929847843181,395.7879771326061,-1.9002023668300998
5.889766327828122,0.07411322264452891,253.82693786057683,395.7879771326061,-1.9002023668300998
5.8928185803327455,0.07415163032606521,253.8620534756056,395.7879771326061,-1.9002023668300998
5.9050275903512395,0.07430526105221044,254.00244505860584,395.7879771326061,-1.9002023668300998
5.917236600369734,0.07445889177835567,254.14272348250682,395.7879771326061,-1.9002023668300998
5.938602367902099,0.07472774554910983,254.38793941010937,395.7879771326061,-1.9002023668300998
5.97370327170527,0.07516943388677735,254.79004851812402,395.7879771326061,-1.9002023668300998
5.988964534228389,0.0753614722944589,254.96459103475055,395.7879771326061,-1.9002023668300998
5.993542912985324,0.07541908381676336,255.01691995346144,395.7879771326061,-1.9002023668300998
6.002699670499194,0.07553430686137227,255.1215310456336,395.7879771326061,-1.9002023668300998
6.036274448050054,0.07595679135827166,255.50457374992482,395.7879771326061,-1.9002023668300998
6.05000958432086,0.07612962592518505,255.66103344373542,395.7879771326061,-1.9002023668300998
6.059166341834731,0.07624484896979396,255.76526295216988,395.7879771326061,-1.9002023668300998
6.091214993133279,0.0766481296259252,256.12958345263763,395.7879771326061,-1.9002023668300998
6.129368149441073,0.07712822564512903,256.5623250509337,395.7879771326061,-1.9002023668300998
6.165995179496556,0.07758911782356472,256.9767697252768,395.7879771326061,-1.9002023668300998
6.173625810758114,0.07768513702740548,257.06299139237206,395.7879771326061,-1.9002023668300998
6.193465452038168,0.07793478695739148,257.28697343919345,395.7879771326061,-1.9002023668300998
6.21177896706591,0.07816523304660933,257.4934778636099,395.7879771326061,-1.9002023668300998
6.23772311335521,0.07849169833966793,257.7856198145207,395.7879771326061,-1.9002023668300998
6.274350143410692,0.07895259051810362,258.1972500483258,395.7879771326061,-1.9002023668300998
6.303346542204617,0.07931746349269854,258.52245974032235,395.7879771326061,-1.9002023668300998
6.347604203521659,0.079874374874975,259.0177098155666,395.7879771326061,-1.9002023668300998
6.3720222235586474,0.08018163632726545,259.2903747153182,395.7879771326061,-1.9002023668300998
6.39949249610026,0.08052730546109223,259.5966361084986,395.7879771326061,-1.9002023668300998
6.440697904912679,0.08104580916183238,260.0550686137316,395.7879771326061,-1.9002023668300998
6.503269081257462,0.08183316663332667,260.7490256687882,395.7879771326061,-1.9002023668300998
6.5261609750421385,0.08212122424484898,261.0022611604485,395.7879771326061,-1.9002023668300998
6.532265480051386,0.08219803960792159,261.0697320872455,395.7879771326061,-1.9002023668300998
6.559735752592998,0.08254370874174835,261.37304746533414,395.7879771326061,-1.9002023668300998
6.565840257602245,0.08262052410482097,261.4403835625809,395.7879771326061,-1.9002023668300998
6.584153772629986,0.08285097019403881,261.6422455114493,395.7879771326061,-1.9002023668300998
6.628411433947028,0.08340788157631526,262.12917666185564,395.7879771326061,-1.9002023668300998
6.639094317713211,0.08354230846169235,262.2465215974255,395.7879771326061,-1.9002023668300998
6.649777201479393,0.08367673534706942,262.36379291693305,395.7879771326061,-1.9002023668300998
6.665038464002511,0.08386877375475095,262.53119599770343,395.7879771326061,-1.9002023668300998
6.697087115301058,0.08427205441088217,262.88225665588345,395.7879771326061,-1.9002023668300998
6.735240271608854,0.08475215043008602,263.29933288369057,395.7879771326061,-1.9002023668300998
6.75813216539353,0.08504020804160832,263.5491363614771,395.7879771326061,-1.9002023668300998
6.839016856766056,0.08605801160232047,264.4291445233199,395.7879771326061,-1.9002023668300998
6.932110558157075,0.08722944588917785,265.43697533340264,395.7879771326061,-1.9002023668300998
6.944319568175569,0.08738307661532307,265.5687572440833,395.7879771326061,-1.9002023668300998
6.971789840717181,0.08772874574914984,265.8649366167483,395.7879771326061,-1.9002023668300998
7.000786239511106,0.08809361872374476,266.177077063726,395.7879771326061,-1.9002023668300998
7.0129952495296,0.08824724944988999,266.30835373017027,395.7879771326061,-1.9002023668300998
7.054200658342018,0.08876575315063014,266.7507559202754,395.7879771326061,-1.9002023668300998
7.063357415855888,0.08888097619523905,266.8489305192479,395.7879771326061,-1.9002023668300998
7.067935794612824,0.08893858771754351,266.8979992044533,395.7879771326061,-1.9002023668300998
7.096932193406748,0.08930346069213843,267.20848017299755,395.7879771326061,-1.9002023668300998
7.1167718346868005,0.08955311062212443,267.4206295206408,395.7879771326061,-1.9002023668300998
7.133559223462231,0.08976435287057412,267.5999604148325,395.7879771326061,-1.9002023668300998
7.170186253517714,0.0902252450490098,267.99065752026024,395.7879771326061,-1.9002023668300998
7.20070877856395,0.09060932186437289,268.31564422204116,395.7879771326061,-1.9002023668300998
7.219022293591691,0.09083976795359072,268.5103783737136,395.7879771326061,-1.9002023668300998
7.2388619348717445,0.09108941788357672,268.7211230841338,395.7879771326061,-1.9002023668300998
7.254123197394862,0.09128145629125825,268.8830811529752,395.7879771326061,-1.9002023668300998
7.281593469936475,0.09162712542508503,269.17427120666036,395.7879771326061,-1.9002023668300998
7.3044853637211515,0.09191518303660733,269.41660245808396,395.7879771326061,-1.9002023668300998
7.322798878748894,0.09214562912582518,269.610254272568,395.7879771326061,-1.9002023668300998
7.370108792570559,0.09274094818963793,270.1096492666775,395.7879771326061,-1.9002023668300998
7.400631317616794,0.093125025005001,270.4311762230455,395.7879771326061,-1.9002023668300998
7.414366453887601,0.09329785957191439,270.5756945846156,395.7879771326061,-1.9002023668300998
7.46472862021389,0.09393158631726346,271.10470430661115,395.7879771326061,-1.9002023668300998
7.501355650269373,0.09439247849569915,271.4885647763703,395.7879771326061,-1.9002023668300998
7.553243942847973,0.09504540908181637,272.03111818712813,395.7879771326061,-1.9002023668300998
7.608184487931197,0.0957367473494699,272.6040045383959,395.7879771326061,-1.9002023668300998
7.614288992940445,0.09581356271254252,272.66755882758787,395.7879771326061,-1.9002023668300998
7.6264980029589395,0.09596719343868775,272.7946078229138,395.7879771326061,-1.9002023668300998
7.657020528005175,0.09635127025405081,273.1118837726967,395.7879771326061,-1.9002023668300998
7.690595305556034,0.0967737547509502,273.46031816552295,395.7879771326061,-1.9002023668300998
7.724170083106894,0.09719623924784958,273.80815980940514,395.7879771326061,-1.9002023668300998
7.740957471882323,0.09740748149629927,273.98185947017447,395.7879771326061,-1.9002023668300998
7.776058375685494,0.0978491698339668,274.3445756625152,395.7879771326061,-1.9002023668300998
7.788267385703989,0.09800280056011203,274.4705880662062,395.7879771326061,-1.9002023668300998
7.826420542011784,0.09848289657931587,274.86388119490573,395.7879771326061,-1.9002023668300998
7.846260183291837,0.09873254650930187,275.06809807632527,395.7879771326061,-1.9002023668300998
7.879834960842696,0.09915503100620124,275.4132376954439,395.7879771326061,-1.9002023668300998
7.9286710009166725,0.09976955391078215,275.91423690018905,395.7879771326061,-1.9002023668300998
7.931723253421297,0.09980796159231847,275.94550933182524,395.7879771326061,-1.9002023668300998