File: datasets/aisi_316_L/data/M1/train_70.csv
Time(s),Strain(%),Stress(MPa),Temp(C),Log_SR(s-1)
0.0,0.0,0.0,147.42409144919947,4.227215322303068
4.077304212925799e-09,6.879999999999999e-05,13.068075174999999,147.42409144919947,4.227215322303068
5.736672206558392e-09,9.68e-05,18.386477862499998,147.42409144919947,4.227215322303068
6.1159563193886984e-09,0.0001032,19.6021127625,147.42409144919947,4.227215322303068
6.63747197453037e-09,0.000112,21.27361075,147.42409144919947,4.227215322303068
7.585682256606137e-09,0.000128,24.312697999999997,147.42409144919947,4.227215322303068
7.870145341228867e-09,0.0001328,25.224424175,147.42409144919947,4.227215322303068
8.154608425851598e-09,0.00013759999999999998,26.136150349999998,147.42409144919947,4.227215322303068
8.628713566889481e-09,0.0001456,27.655693975,147.42409144919947,4.227215322303068
9.197639736134942e-09,0.0001552,29.479146325000002,147.42409144919947,4.227215322303068
1.0525134131041014e-08,0.00017759999999999998,33.733868474999994,147.42409144919947,4.227215322303068
1.0951828757975112e-08,0.0001848,35.1014577375,147.42409144919947,4.227215322303068
1.2326733666984973e-08,0.000208,39.50813425,147.42409144919947,4.227215322303068
1.332235446316453e-08,0.0002248,42.6991758625,147.42409144919947,4.227215322303068
1.3843870118306201e-08,0.00023359999999999999,44.370673849999996,147.42409144919947,4.227215322303068
1.502913297090091e-08,0.0002536,48.169532912499996,147.42409144919947,4.227215322303068
1.5740290682457735e-08,0.0002656,50.44884835,147.42409144919947,4.227215322303068
1.6356627365806983e-08,0.000276,52.424255062499995,147.42409144919947,4.227215322303068
1.7257427133778962e-08,0.0002912,55.31138795,147.42409144919947,4.227215322303068
1.7731532274816848e-08,0.0002992,56.830931575,147.42409144919947,4.227215322303068
1.844268998637367e-08,0.0003112,59.1102470125,147.42409144919947,4.227215322303068
2.166660494543128e-08,0.0003656,69.4431436625,147.42409144919947,4.227215322303068
2.3373383453167663e-08,0.0003944,74.9135007125,147.42409144919947,4.227215322303068
2.3847488594205546e-08,0.00040239999999999997,76.4330443375,147.42409144919947,4.227215322303068
2.427418322113964e-08,0.0004096,77.8006336,147.42409144919947,4.227215322303068
2.574390915835708e-08,0.0004344,82.5112188375,147.42409144919947,4.227215322303068
2.6407656355810116e-08,0.0004456,84.63857991249999,147.42409144919947,4.227215322303068
2.7592919208404825e-08,0.0004656,88.43743897499999,147.42409144919947,4.227215322303068
2.7877382293027556e-08,0.0004704,89.34916515,147.42409144919947,4.227215322303068
2.8161845377650286e-08,0.0004752,90.260891325,147.42409144919947,4.227215322303068
3.0247907998216974e-08,0.0005103999999999999,96.94688327499999,147.42409144919947,4.227215322303068
3.1954686505953356e-08,0.0005392,102.417240325,147.42409144919947,4.227215322303068
3.290289678802912e-08,0.0005551999999999999,105.45632757499999,147.42409144919947,4.227215322303068
3.332959141496322e-08,0.0005624,106.82391683750001,147.42409144919947,4.227215322303068
3.38036965560011e-08,0.0005704,108.34346046249999,147.42409144919947,4.227215322303068
3.4325212211142774e-08,0.0005792,110.01495845,147.42409144919947,4.227215322303068
3.4751906838076866e-08,0.0005863999999999999,111.38254771249998,147.42409144919947,4.227215322303068
3.50363699226996e-08,0.0005912,112.2942738875,147.42409144919947,4.227215322303068
3.5226011979114746e-08,0.0005943999999999999,112.90209133749998,147.42409144919947,4.227215322303068
3.541565403552991e-08,0.0005976,113.5099087875,147.42409144919947,4.227215322303068
3.707502202916249e-08,0.0006255999999999999,118.82831147499998,147.42409144919947,4.227215322303068
3.91136741356254e-08,0.00066,125.3623490625,147.42409144919947,4.227215322303068
3.982483184718222e-08,0.000672,127.64166449999999,147.42409144919947,4.227215322303068
4.067822110105041e-08,0.0006864,130.376843025,147.42409144919947,4.227215322303068
4.1768662925437546e-08,0.0007048,133.8717933625,147.42409144919947,4.227215322303068
4.210053652416406e-08,0.0007103999999999999,134.93547389999998,147.42409144919947,4.227215322303068
4.233758909468301e-08,0.0007144,135.6952457125,147.42409144919947,4.227215322303068
4.375990451779665e-08,0.0007384,140.2538765875,147.42409144919947,4.227215322303068
4.4471062229353475e-08,0.0007503999999999999,142.53319202499998,147.42409144919947,4.227215322303068
4.6320072279401226e-08,0.0007815999999999999,148.45941216249997,147.42409144919947,4.227215322303068
4.7220872047373205e-08,0.0007968,151.34654505,147.42409144919947,4.227215322303068
4.755274564609972e-08,0.0008024,152.4102255875,147.42409144919947,4.227215322303068
4.7789798216618666e-08,0.0008064,153.1699974,147.42409144919947,4.227215322303068
4.84535454140717e-08,0.0008175999999999999,155.29735847499998,147.42409144919947,4.227215322303068
4.949657672435504e-08,0.0008351999999999999,158.64035445,147.42409144919947,4.227215322303068
5.17248708872331e-08,0.0008728,165.78220948749998,147.42409144919947,4.227215322303068
5.229379705647856e-08,0.0008824,167.6056618375,147.42409144919947,4.227215322303068
5.480655430397934e-08,0.0009247999999999999,175.65924305,147.42409144919947,4.227215322303068
5.494878584629071e-08,0.0009272,176.1151061375,147.42409144919947,4.227215322303068
5.532806995912101e-08,0.0009335999999999999,177.3307410375,147.42409144919947,4.227215322303068
5.632369075530057e-08,0.0009504,180.52178265,147.42409144919947,4.227215322303068
5.6845206410442245e-08,0.0009592,182.1932806375,147.42409144919947,4.227215322303068
5.712966949506497e-08,0.0009639999999999999,183.1050068125,147.42409144919947,4.227215322303068
5.765118515020665e-08,0.0009728,184.7765048,147.42409144919947,4.227215322303068
5.8362342861763466e-08,0.0009847999999999999,187.05582023749997,147.42409144919947,4.227215322303068
5.855198491817862e-08,0.000988,187.6636376875,147.42409144919947,4.227215322303068
5.9405374172046806e-08,0.0010023999999999999,190.39881621249998,147.42409144919947,4.227215322303068
6.063804753874532e-08,0.0010232,194.3496296375,147.42409144919947,4.227215322303068
6.243964707468927e-08,0.0010536,200.1238954125,147.42409144919947,4.227215322303068
6.305598375803853e-08,0.001064,202.099302125,147.42409144919947,4.227215322303068
6.405160455421808e-08,0.0010808,205.2903437375,147.42409144919947,4.227215322303068
6.47627622657749e-08,0.0010927999999999999,207.56965917499997,147.42409144919947,4.227215322303068
6.533168843502036e-08,0.0011024,209.393111525,147.42409144919947,4.227215322303068
6.708587745686053e-08,0.001132,215.0154229375,147.42409144919947,4.227215322303068
6.855560339407796e-08,0.0011568,219.72600817499998,147.42409144919947,4.227215322303068
6.926676110563479e-08,0.0011688,222.0053236125,147.42409144919947,4.227215322303068
7.32966548044568e-08,0.0012368,234.92144442499998,147.42409144919947,4.227215322303068
7.448191765705151e-08,0.0012568,238.7203034875,147.42409144919947,4.227215322303068
7.509825434040077e-08,0.0012672,240.6957102,147.42409144919947,4.227215322303068
7.543012793912728e-08,0.0012728,241.75939073749998,147.42409144919947,4.227215322303068
7.680503284813714e-08,0.0012959999999999998,246.16606724999997,147.42409144919947,4.227215322303068
7.813252724304322e-08,0.0013184,250.4207894,147.42409144919947,4.227215322303068
7.889109546870382e-08,0.0013311999999999998,252.85205919999996,147.42409144919947,4.227215322303068
7.936520060974172e-08,0.0013392,252.93137728524843,147.42409144919947,4.227215322303068
8.078751603285536e-08,0.0013632,253.1050848921644,147.42409144919947,4.227215322303068
8.18779578572425e-08,0.0013816,253.23745419105887,147.42409144919947,4.227215322303068
8.206759991365764e-08,0.0013847999999999998,253.26040457986704,147.42409144919947,4.227215322303068
8.47225887034698e-08,0.0014295999999999998,253.57956890667035,147.42409144919947,4.227215322303068
8.647677772530997e-08,0.0014592,253.78830755777398,147.42409144919947,4.227215322303068
8.71879354368668e-08,0.0014712,253.87246010535236,147.42409144919947,4.227215322303068
8.799391417663119e-08,0.0014847999999999999,253.96751005006348,147.42409144919947,4.227215322303068
8.936881908564106e-08,0.001508,254.12887414222803,147.42409144919947,4.227215322303068
9.126523964979259e-08,0.00154,254.34986551781418,147.42409144919947,4.227215322303068
9.183416581903805e-08,0.0015496,254.4158127524622,147.42409144919947,4.227215322303068
9.363576535498202e-08,0.00158,254.62360220479863,147.42409144919947,4.227215322303068
9.429951255243504e-08,0.0015911999999999999,254.69976241824597,147.42409144919947,4.227215322303068
9.501067026399187e-08,0.0016032,254.78113101587624,147.42409144919947,4.227215322303068
9.676485928583205e-08,0.0016328,254.98083123039277,147.42409144919947,4.227215322303068
9.728637494097371e-08,0.0016416,255.0399286389648,147.42409144919947,4.227215322303068
9.747601699738886e-08,0.0016447999999999999,255.06138795660326,147.42409144919947,4.227215322303068
9.832940625125706e-08,0.0016592,255.15775410019032,147.42409144919947,4.227215322303068
9.89457429346063e-08,0.0016695999999999998,255.22714913140229,147.42409144919947,4.227215322303068
1.018377842949374e-07,0.0017184,255.5505468068743,147.42409144919947,4.227215322303068
1.0330751023215483e-07,0.0017431999999999999,255.7135223991634,147.42409144919947,4.227215322303068
1.0458759411295712e-07,0.0017648,255.85473350629027,147.42409144919947,4.227215322303068
1.0515652028220258e-07,0.0017744,255.9172774680986,147.42409144919947,4.227215322303068
1.0643660416300487e-07,0.0017959999999999999,256.05752087831456,147.42409144919947,4.227215322303068
1.0776409855791094e-07,0.0018184,256.2022654412921,147.42409144919947,4.227215322303068
1.0809597215663746e-07,0.0018239999999999999,256.2383427222385,147.42409144919947,4.227215322303068
1.091390034669208e-07,0.0018415999999999999,256.351448255483,147.42409144919947,4.227215322303068
1.0975534015027005e-07,0.001852,256.4180851978998,147.42409144919947,4.227215322303068
1.1013462426310036e-07,0.0018583999999999999,256.4590200157982,147.42409144919947,4.227215322303068
1.1108283454517612e-07,0.0018743999999999998,256.56111725990843,147.42409144919947,4.227215322303068
1.1136729762979885e-07,0.0018792,256.59168008123345,147.42409144919947,4.227215322303068
1.1231550791187463e-07,0.0018951999999999999,256.6933369795785,147.42409144919947,4.227215322303068
1.1307407613753524e-07,0.001908,256.77442171374287,147.42409144919947,4.227215322303068
1.1497049670168677e-07,0.0019399999999999999,256.9762108932556,147.42409144919947,4.227215322303068
1.156342438991398e-07,0.0019512,257.04652988243026,147.42409144919947,4.227215322303068
1.1615575955428148e-07,0.00196,257.101670143568,147.42409144919947,4.227215322303068
1.168195067517345e-07,0.0019711999999999998,257.17170921733526,147.42409144919947,4.227215322303068
1.1776771703381028e-07,0.0019871999999999997,257.27149641042774,147.42409144919947,4.227215322303068
1.1961672708385803e-07,0.0020184,257.4651847500934,147.42409144919947,4.227215322303068
1.2075457942234895e-07,0.0020376,257.5837973337977,147.42409144919947,4.227215322303068
1.2241394741598155e-07,0.0020656,257.7559956371985,147.42409144919947,4.227215322303068
1.2284064204291565e-07,0.0020728,257.8001277592827,147.42409144919947,4.227215322303068
1.2412072592371792e-07,0.0020943999999999997,257.93216680237555,147.42409144919947,4.227215322303068
1.2554304134683158e-07,0.0021184,258.0782555426401,147.42409144919947,4.227215322303068
1.2611196751607706e-07,0.002128,258.13651013120887,147.42409144919947,4.227215322303068
1.275342829391907e-07,0.002152,258.28169998330503,147.42409144919947,4.227215322303068
1.291936509328233e-07,0.00218,258.45029239885065,147.42409144919947,4.227215322303068
1.2995221915848389e-07,0.0021928,258.5270817350689,147.42409144919947,4.227215322303068
1.3066337687004072e-07,0.0022048,258.5989131238457,147.42409144919947,4.227215322303068
1.311374820110786e-07,0.0022128,258.64671602790094,147.42409144919947,4.227215322303068
1.3137453458159754e-07,0.0022168,258.6705922011449,147.42409144919947,4.227215322303068
1.3189605023673923e-07,0.0022256,258.72306071893394,147.42409144919947,4.227215322303068
1.332235446316453e-07,0.002248,258.8562531576909,147.42409144919947,4.227215322303068
1.336502392585794e-07,0.0022551999999999997,258.8989549566994,147.42409144919947,4.227215322303068
1.3507255468169305e-07,0.0022792,259.04091184304286,147.42409144919947,4.227215322303068
1.3549924930862714e-07,0.0022864,259.08338507270844,147.42409144919947,4.227215322303068
1.3663710164711806e-07,0.0023056,259.1963927734755,147.42409144919947,4.227215322303068
1.376801329574014e-07,0.0023232,259.2996611643621,147.42409144919947,4.227215322303068
1.3791718552792034e-07,0.0023271999999999998,259.32308864872607,147.42409144919947,4.227215322303068
1.3995583763438324e-07,0.0023615999999999997,259.52392084867563,147.42409144919947,4.227215322303068
1.4185225819853478e-07,0.0023936,259.7097195975771,147.42409144919947,4.227215322303068
1.4289528950881812e-07,0.0024112,259.8114959023453,147.42409144919947,4.227215322303068
1.437012682485825e-07,0.0024248,259.8899429171882,147.42409144919947,4.227215322303068
1.4464947853065828e-07,0.0024408,259.9820141730654,147.42409144919947,4.227215322303068
1.4526581521400752e-07,0.0024511999999999997,260.0417342913161,147.42409144919947,4.227215322303068
1.462140254960833e-07,0.0024671999999999997,260.13341879856523,147.42409144919947,4.227215322303068
1.4768375143330075e-07,0.002492,260.2750728454253,147.42409144919947,4.227215322303068
1.478259829756121e-07,0.0024944,260.28875205910464,147.42409144919947,4.227215322303068
1.5000686662438638e-07,0.0025312,260.4978614280647,147.42409144919947,4.227215322303068
1.5057579279363183e-07,0.0025407999999999997,260.55221628103624,147.42409144919947,4.227215322303068
1.5090766639235834e-07,0.0025464,260.58388629064217,147.42409144919947,4.227215322303068
1.5138177153339625e-07,0.0025544,260.62908208308585,147.42409144919947,4.227215322303068
1.5299372901292503e-07,0.0025816,260.7823365373454,147.42409144919947,4.227215322303068
1.5408417083731216e-07,0.0026,260.8856517467394,147.42409144919947,4.227215322303068
1.5446345495014248e-07,0.0026064,260.92152058025624,147.42409144919947,4.227215322303068
1.5569612831684097e-07,0.0026271999999999997,261.0378577801265,147.42409144919947,4.227215322303068
1.559805914014637e-07,0.002632,261.0646537480628,147.42409144919947,4.227215322303068
1.5716585425405842e-07,0.002652,261.17609908960947,147.42409144919947,4.227215322303068
1.579718329938228e-07,0.0026655999999999997,261.25169475823134,147.42409144919947,4.227215322303068
1.5982084304387056e-07,0.0026968,261.42455403399373,147.42409144919947,4.227215322303068
1.6148021103750316e-07,0.0027248,261.57902121499586,147.42409144919947,4.227215322303068
1.6200172669264484e-07,0.0027336,261.62744002835655,147.42409144919947,4.227215322303068
1.6266547389009785e-07,0.0027448,261.6889761450043,147.42409144919947,4.227215322303068
1.6304475800292818e-07,0.0027512,261.7240956723244,147.42409144919947,4.227215322303068
1.6385073674269257e-07,0.0027648,261.79861905226227,147.42409144919947,4.227215322303068
1.6441966291193802e-07,0.0027743999999999998,261.85113773928373,147.42409144919947,4.227215322303068
1.6560492576453273e-07,0.0027944,261.96032458676115,147.42409144919947,4.227215322303068
1.6593679936325926e-07,0.0028,261.9908422342813,147.42409144919947,4.227215322303068
1.6693242015943883e-07,0.0028168,262.0822526734741,147.42409144919947,4.227215322303068
1.6716947272995777e-07,0.0028208,262.10398569486625,147.42409144919947,4.227215322303068
1.6807027249792975e-07,0.002836,262.1864617930601,147.42409144919947,4.227215322303068
1.6868660918127897e-07,0.0028464,262.2427935018233,147.42409144919947,4.227215322303068
1.7181570311212902e-07,0.0028991999999999998,262.5275563265391,147.42409144919947,4.227215322303068
1.722423977390631e-07,0.0029064,262.56623032192425,147.42409144919947,4.227215322303068
1.7338025007755403e-07,0.0029256,262.6691787406348,147.42409144919947,4.227215322303068
1.738543552185919e-07,0.0029335999999999997,262.7119961090296,147.42409144919947,4.227215322303068
1.747077444724601e-07,0.0029479999999999997,262.78895279288423,147.42409144919947,4.227215322303068
1.7527667064170558e-07,0.0029576,262.8401758179697,147.42409144919947,4.227215322303068
1.771256806917533e-07,0.0029888,263.00620461635134,147.42409144919947,4.227215322303068
1.7864281714307455e-07,0.0030144,263.14192911286534,147.42409144919947,4.227215322303068
1.7954361691104653e-07,0.0030296,263.2223028487878,147.42409144919947,4.227215322303068
1.8020736410849954e-07,0.0030407999999999998,263.2814250047647,147.42409144919947,4.227215322303068
1.809185218200564e-07,0.0030528,263.3446760079272,147.42409144919947,4.227215322303068
1.8205637415854732e-07,0.003072,263.445676299128,147.42409144919947,4.227215322303068
1.8272012135600035e-07,0.0030832,263.5044794454287,147.42409144919947,4.227215322303068
1.8352610009576474e-07,0.0030968,263.57577138828657,147.42409144919947,4.227215322303068
1.8418984729321775e-07,0.0031079999999999997,263.63439076152787,147.42409144919947,4.227215322303068
1.849484155188784e-07,0.0031208,263.7012835471786,147.42409144919947,4.227215322303068
1.853276996317087e-07,0.0031271999999999997,263.7346898085123,147.42409144919947,4.227215322303068
1.8589662580095417e-07,0.0031368,263.7847492500466,147.42409144919947,4.227215322303068
1.865129624843034e-07,0.0031471999999999997,263.8389129339877,147.42409144919947,4.227215322303068
1.8746117276637916e-07,0.0031631999999999997,263.9221055738368,147.42409144919947,4.227215322303068
1.8874125664718146e-07,0.0031848,264.0341557812078,147.42409144919947,4.227215322303068
1.9002134052798374e-07,0.0032064,264.1459099975216,147.42409144919947,4.227215322303068
1.9044803515491786e-07,0.0032136,264.1830961068715,147.42409144919947,4.227215322303068
1.9092214029595572e-07,0.0032216,264.2243759184009,147.42409144919947,4.227215322303068
1.9315043445883377e-07,0.0032592,264.4178580491477,147.42409144919947,4.227215322303068
1.9395641319859816e-07,0.0032727999999999998,264.4876263147834,147.42409144919947,4.227215322303068
1.9533131810760805e-07,0.003296,264.6063823736475,147.42409144919947,4.227215322303068
1.958054232486459e-07,0.0033039999999999996,264.64725709141896,147.42409144919947,4.227215322303068
1.963269389037876e-07,0.0033128,264.6921747257953,147.42409144919947,4.227215322303068
1.9699068610124063e-07,0.0033239999999999997,264.74927538036565,147.42409144919947,4.227215322303068
1.979388963833164e-07,0.0033399999999999997,264.83071775361003,147.42409144919947,4.227215322303068
1.9860264358076943e-07,0.0033512,264.8876369061707,147.42409144919947,4.227215322303068
1.995508538628452e-07,0.0033672,264.9688214543598,147.42409144919947,4.227215322303068
2.003568326026096e-07,0.0033807999999999998,265.0377100999351,147.42409144919947,4.227215322303068
2.01162811342374e-07,0.0033943999999999997,265.1064907532948,147.42409144919947,4.227215322303068
2.0139986391289296e-07,0.0033983999999999998,265.1266998926793,147.42409144919947,4.227215322303068
2.0154209545520431e-07,0.0034008,265.1388209234987,147.42409144919947,4.227215322303068
2.0192137956803464e-07,0.0034072,265.17112737382627,147.42409144919947,4.227215322303068
2.0324887396294068e-07,0.0034295999999999997,265.2840140472538,147.42409144919947,4.227215322303068
2.0467118938605434e-07,0.0034536,265.40464543510774,147.42409144919947,4.227215322303068
2.0552457863992253e-07,0.0034679999999999997,265.4768673476534,147.42409144919947,4.227215322303068
2.064253784078945e-07,0.0034831999999999997,265.5529748232219,147.42409144919947,4.227215322303068
2.0680466252072483e-07,0.0034896,265.58498131345596,147.42409144919947,4.227215322303068
2.0827438845794228e-07,0.0035144,265.70879083246746,147.42409144919947,4.227215322303068
2.1102419827596199e-07,0.0035608,265.93952314787157,147.42409144919947,4.227215322303068
2.1164053495931123e-07,0.0035711999999999996,265.99107779985155,147.42409144919947,4.227215322303068
2.122094611285567e-07,0.0035808,266.0386147629876,147.42409144919947,4.227215322303068
2.1249392421317944e-07,0.0035856,266.0623646038859,147.42409144919947,4.227215322303068
2.1457998683374613e-07,0.0036208,266.2361528077537,147.42409144919947,4.227215322303068
2.149592709465764e-07,0.0036271999999999997,266.26767974409034,147.42409144919947,4.227215322303068
2.1567042865813326e-07,0.0036392,266.3267343373739,147.42409144919947,4.227215322303068
2.1661863894020903e-07,0.0036552,266.4053557955745,147.42409144919947,4.227215322303068
2.1770908076459616e-07,0.0036736,266.4956047352657,147.42409144919947,4.227215322303068
2.187047015607757e-07,0.0036904,266.57785209570056,147.42409144919947,4.227215322303068
2.1922621721591735e-07,0.0036991999999999997,266.6208757625606,147.42409144919947,4.227215322303068
2.1979514338516283e-07,0.0037088,266.667765173455,147.42409144919947,4.227215322303068
2.2107522726596513e-07,0.0037304,266.77309362695337,147.42409144919947,4.227215322303068
2.2292423731601288e-07,0.0037616,266.924815781717,147.42409144919947,4.227215322303068
2.2444137376733408e-07,0.0037871999999999997,267.04893953097036,147.42409144919947,4.227215322303068
2.2519994199299473e-07,0.0038,267.1108786666756,147.42409144919947,4.227215322303068
2.268118994725235e-07,0.0038272,267.2422298101221,147.42409144919947,4.227215322303068
2.2719118358535383e-07,0.0038336,267.27308299134324,147.42409144919947,4.227215322303068
2.2804457283922202e-07,0.003848,267.34242929686303,147.42409144919947,4.227215322303068
2.2842385695205232e-07,0.0038544,267.3732173829012,147.42409144919947,4.227215322303068
2.2899278312129776e-07,0.003864,267.41936215559906,147.42409144919947,4.227215322303068
2.2994099340337354e-07,0.0038799999999999998,267.4961708747759,147.42409144919947,4.227215322303068
2.3112625625596825e-07,0.0039,267.59200828498285,147.42409144919947,4.227215322303068
2.313158983123834e-07,0.0039032,267.60732446542585,147.42409144919947,4.227215322303068
2.3188482448162887e-07,0.0039128,267.65324365077714,147.42409144919947,4.227215322303068
2.3321231887653495e-07,0.0039352,267.7602178852822,147.42409144919947,4.227215322303068
2.337338345316766e-07,0.003944,267.8021784717732,147.42409144919947,4.227215322303068
2.3449240275733722e-07,0.0039568,267.8631469300747,147.42409144919947,4.227215322303068
2.3472945532785614e-07,0.0039607999999999996,267.8821837924935,147.42409144919947,4.227215322303068
2.3648364434969633e-07,0.0039904,268.02282428151034,147.42409144919947,4.227215322303068
2.5753800969961453e-07,0.0043456691338267656,269.6802754442913,147.42409144919947,4.227215322303068
2.8257576869821453e-07,0.004768153630726146,271.5839766912877,147.42409144919947,4.227215322303068
2.9850888806095994e-07,0.0050370074014802965,272.76121707920106,147.42409144919947,4.227215322303068
3.0647544774233266e-07,0.005171434286857372,273.3406265790858,147.42409144919947,4.227215322303068
3.155800873781872e-07,0.005325065013002601,273.9956638314889,147.42409144919947,4.227215322303068
3.269608869230054e-07,0.0055171034206841375,274.80418606384615,147.42409144919947,4.227215322303068
3.4517016619471443e-07,0.005824364872974595,276.0753533956179,147.42409144919947,4.227215322303068
3.5882712564849625e-07,0.0060548109621924385,277.01163029206623,147.42409144919947,4.227215322303068
3.952456841919144e-07,0.006669333866773355,279.44277817195666,147.42409144919947,4.227215322303068
4.134549634636235e-07,0.006976595319063813,280.6254482785791,147.42409144919947,4.227215322303068
4.475973620980779e-07,0.007552710542108421,282.7895737621621,147.42409144919947,4.227215322303068
4.646685614153052e-07,0.007840768153630726,283.8474104189977,147.42409144919947,4.227215322303068
4.90844400368387e-07,0.00828245649129826,285.4404479273797,147.42409144919947,4.227215322303068
5.204344791849142e-07,0.008781756351270254,287.20188959171924,147.42409144919947,4.227215322303068
5.318152787297324e-07,0.00897379475895179,287.8689101547345,147.42409144919947,4.227215322303068
5.579911176828142e-07,0.009415483096619324,289.3822804587697,147.42409144919947,4.227215322303068
5.762003969545233e-07,0.009722744548909782,290.4187663191133,147.42409144919947,4.227215322303068
5.841669566358961e-07,0.009857171434286858,290.8682031109085,147.42409144919947,4.227215322303068
5.921335163172687e-07,0.009991598319663933,291.31525577952516,147.42409144919947,4.227215322303068
6.205855151793142e-07,0.010471694338867774,292.8930708999403,147.42409144919947,4.227215322303068
6.77489512903405e-07,0.011431886377275456,295.96647395704844,147.42409144919947,4.227215322303068
6.922845523116686e-07,0.011681536307261452,296.748850501202,147.42409144919947,4.227215322303068
7.241507910371594e-07,0.012219243848769754,298.4121564410039,147.42409144919947,4.227215322303068
7.33255430673014e-07,0.012372874574914983,298.88211120307585,147.42409144919947,4.227215322303068
7.423600703088685e-07,0.012526505301060212,299.3497956281758,147.42409144919947,4.227215322303068
7.765024689433231e-07,0.013102620524104821,301.0840382669977,147.42409144919947,4.227215322303068
7.992640680329594e-07,0.013486697339467894,302.2237035809004,147.42409144919947,4.227215322303068
8.311303067584504e-07,0.014024404880976196,303.7981934122477,147.42409144919947,4.227215322303068
8.345445466218958e-07,0.014082016403280656,303.9654804180462,147.42409144919947,4.227215322303068
8.493395860301594e-07,0.014331666333266654,304.68732815548407,147.42409144919947,4.227215322303068
8.618584655294594e-07,0.014542908581716344,305.29430015241525,147.42409144919947,4.227215322303068
8.664107853473867e-07,0.014619723944788958,305.51416347874687,147.42409144919947,4.227215322303068
8.937247042549503e-07,0.015080616123224646,306.8240048108907,147.42409144919947,4.227215322303068
9.01691263936323e-07,0.015215043008601721,307.20308877011917,147.42409144919947,4.227215322303068
9.073816637087321e-07,0.01531106221244249,307.4730637399348,147.42409144919947,4.227215322303068
9.187624632535503e-07,0.015503100620124026,308.01104089255983,147.42409144919947,4.227215322303068
9.392479024342228e-07,0.01584876975395079,308.9728956143297,147.42409144919947,4.227215322303068
9.847711006134957e-07,0.016616923384676935,311.0815300309803,147.42409144919947,4.227215322303068
1.0280181388838046e-06,0.017346669333866773,313.04978498965255,147.42409144919947,4.227215322303068
1.0348466186106954e-06,0.017461892378475695,313.3575853069369,147.42409144919947,4.227215322303068
1.0769555769265228e-06,0.018172434486897378,315.23847593610515,147.42409144919947,4.227215322303068
1.1031314158796045e-06,0.018614122824564913,316.39323047930765,147.42409144919947,4.227215322303068
1.132721494696132e-06,0.019113422684536908,317.68581318024644,147.42409144919947,4.227215322303068
1.1577592536947318e-06,0.019535907181436288,318.7692833421439,147.42409144919947,4.227215322303068
1.1816589327388498e-06,0.019939187837567512,319.7950115569542,147.42409144919947,4.227215322303068
1.1919016523291863e-06,0.020112022404480897,320.2321289550272,147.42409144919947,4.227215322303068
1.2044205318284862e-06,0.020323264652930585,320.7643990943223,147.42409144919947,4.227215322303068
1.218077491282268e-06,0.02055371074214843,321.34260261629436,147.42409144919947,4.227215322303068
1.2465294901443135e-06,0.02103380676135227,322.5391354570411,147.42409144919947,4.227215322303068
1.2715672491429136e-06,0.02145629125825165,323.58330085667467,147.42409144919947,4.227215322303068
1.3125381275042589e-06,0.022147629525905183,325.2748022409991,147.42409144919947,4.227215322303068
1.362613645501459e-06,0.022992598519703943,327.31447980395484,147.42409144919947,4.227215322303068
1.3648898054104226e-06,0.02303100620124025,327.40649139285784,147.42409144919947,4.227215322303068
1.3751325250007588e-06,0.02320384076815363,327.8198052210883,147.42409144919947,4.227215322303068
1.3887894844545407e-06,0.023434286857371475,328.3690274749186,147.42409144919947,4.227215322303068
1.424069963043477e-06,0.024029605921184236,329.77819008834877,147.42409144919947,4.227215322303068
1.4388650024517407e-06,0.024279255851170235,330.36506953446565,147.42409144919947,4.227215322303068
1.4456934821786315e-06,0.024394478895779156,330.63514274180926,147.42409144919947,4.227215322303068
1.4843882006310134e-06,0.02504740948189638,332.1562633307409,147.42409144919947,4.227215322303068
1.5299113988102861e-06,0.025815563112622526,333.9261571690989,147.42409144919947,4.227215322303068
1.536739878537177e-06,0.025930786157231447,334.1898590997263,147.42409144919947,4.227215322303068
1.5560872377633677e-06,0.026257251450290058,334.93454431806435,147.42409144919947,4.227215322303068
1.5640537974447406e-06,0.026391678335667135,335.2401288207396,147.42409144919947,4.227215322303068
1.5890915564433405e-06,0.026814162832566515,336.1966090030724,147.42409144919947,4.227215322303068
1.598196196079195e-06,0.026967793558711744,336.54296043552677,147.42409144919947,4.227215322303068
1.6186816352598678e-06,0.02731346269253851,337.3194499450126,147.42409144919947,4.227215322303068
1.6744475530294768e-06,0.028254450890178036,339.41404894303054,147.42409144919947,4.227215322303068
1.7074518717094493e-06,0.02881136227245449,340.64089492431447,147.42409144919947,4.227215322303068
1.710866111572895e-06,0.028868973794758952,340.7672798892703,147.42409144919947,4.227215322303068
1.7563893097521677e-06,0.029637127425485098,342.4431226111616,147.42409144919947,4.227215322303068
1.7916697883411038e-06,0.03023244648929786,343.73027545906143,147.42409144919947,4.227215322303068
1.804188667840404e-06,0.03044368873774755,344.1846260833707,147.42409144919947,4.227215322303068
1.8178456272941858e-06,0.030674134826965394,344.6788813253331,147.42409144919947,4.227215322303068
1.8315025867479676e-06,0.030904580916183238,345.171690522626,147.42409144919947,4.227215322303068
1.8417453063383038e-06,0.03107741548309662,345.5403574670582,147.42409144919947,4.227215322303068
1.8701973052003493e-06,0.03155751150230046,346.56026031177805,147.42409144919947,4.227215322303068
1.9191347432430674e-06,0.03238327665533107,348.3004497947746,147.42409144919947,4.227215322303068
1.953277141877522e-06,0.032959391878375675,349.50430008158787,147.42409144919947,4.227215322303068
1.965796021376822e-06,0.03317063412682537,349.9436520217661,147.42409144919947,4.227215322303068
1.9760387409671585e-06,0.03334346869373875,350.3023107219942,147.42409144919947,4.227215322303068
1.993109940284385e-06,0.03363152630526105,350.89846819093384,147.42409144919947,4.227215322303068
2.022700019100913e-06,0.034130826165233046,351.9271117871456,147.42409144919947,4.227215322303068
2.032942738691249e-06,0.034303660732146427,352.28181118991336,147.42409144919947,4.227215322303068
2.0625328175077764e-06,0.034802960592118425,353.3026041875137,147.42409144919947,4.227215322303068
2.096675216142231e-06,0.03537907581516303,354.4733718700593,147.42409144919947,4.227215322303068
2.1376460945035765e-06,0.03607041408281657,355.8685236783279,147.42409144919947,4.227215322303068
2.169512333229067e-06,0.03660812162432486,356.9464441669185,147.42409144919947,4.227215322303068
2.1911358523642217e-06,0.036972994598919784,357.6743758700386,147.42409144919947,4.227215322303068
2.211621291544894e-06,0.037318663732746546,358.3614153397138,147.42409144919947,4.227215322303068
2.246901770133831e-06,0.03791398279655932,359.53886034534605,147.42409144919947,4.227215322303068
2.259420649633131e-06,0.03812522504500901,359.95492735716067,147.42409144919947,4.227215322303068
2.2742156890413947e-06,0.038374874974995005,360.44548556044373,147.42409144919947,4.227215322303068
2.287872648495176e-06,0.03860532106421284,360.89720495379095,147.42409144919947,4.227215322303068
2.309496167630331e-06,0.03897019403880776,361.6102825667408,147.42409144919947,4.227215322303068
2.325429286993076e-06,0.03923904780956192,362.13404314002156,147.42409144919947,4.227215322303068
2.339086246446858e-06,0.03946949389877975,362.58186780346307,147.42409144919947,4.227215322303068
2.3618478455364944e-06,0.03985357071414283,363.32598282209443,147.42409144919947,4.227215322303068
2.3914379243530213e-06,0.040352870574114824,364.2891645066171,147.42409144919947,4.227215322303068
2.406232963761285e-06,0.04060252050410082,364.7690115538243,147.42409144919947,4.227215322303068
2.4096472036247304e-06,0.04066013202640528,364.8795819180524,147.42409144919947,4.227215322303068
2.425580322987476e-06,0.04092898579715944,365.3947712276843,147.42409144919947,4.227215322303068
2.4472038421226307e-06,0.04129385877175436,366.09185063479134,147.42409144919947,4.227215322303068
2.4563084817584852e-06,0.04144748949789959,366.38463862890006,147.42409144919947,4.227215322303068
2.5097982396191304e-06,0.0423500700140028,368.09629716117814,147.42409144919947,4.227215322303068
2.5325598387087666e-06,0.04273414682936587,368.82034062352363,147.42409144919947,4.227215322303068
2.537112158526694e-06,0.04281096219243849,368.9648442860474,147.42409144919947,4.227215322303068
2.5496310380259944e-06,0.04302220444088818,369.36170889671956,147.42409144919947,4.227215322303068
2.6213300751583483e-06,0.044232046409281855,371.6201890354609,147.42409144919947,4.227215322303068
2.6645771134286577e-06,0.0449617923584717,372.97080097003965,147.42409144919947,4.227215322303068
2.6816483127458847e-06,0.045249849969994,373.50158054555806,147.42409144919947,4.227215322303068
2.702133751926557e-06,0.04559551910382076,374.13677973786776,147.42409144919947,4.227215322303068
2.713514551471376e-06,0.045787557511502305,374.4888565914175,147.42409144919947,4.227215322303068
2.7351380706065308e-06,0.046152430486097226,375.15622007547194,147.42409144919947,4.227215322303068
2.7578996696961665e-06,0.04653650730146029,375.85648881549804,147.42409144919947,4.227215322303068
2.7738327890589123e-06,0.046805361072214446,376.3453364114285,147.42409144919947,4.227215322303068
2.7931801482851026e-06,0.04713182636527305,376.93746728158686,147.42409144919947,4.227215322303068
2.8034228678754392e-06,0.04730466093218644,377.25030064415256,147.42409144919947,4.227215322303068
2.8170798273292213e-06,0.04753510702140429,377.66671926643346,147.42409144919947,4.227215322303068
2.8284606268740395e-06,0.04772714542908582,378.0131337032927,147.42409144919947,4.227215322303068
2.854636465827121e-06,0.04816883376675335,378.80783050775517,147.42409144919947,4.227215322303068
2.8876407845070935e-06,0.0487257451490298,379.8058004260093,147.42409144919947,4.227215322303068
2.9058500637788025e-06,0.04903300660132026,380.35449999775983,147.42409144919947,4.227215322303068
2.9365782225498116e-06,0.04955151030206041,381.2773994860382,147.42409144919947,4.227215322303068
2.949097102049112e-06,0.0497627525505101,381.65231488879755,147.42409144919947,4.227215322303068
2.9934822202739026e-06,0.05051170234046809,382.97658790164934,147.42409144919947,4.227215322303068
3.0060010997732026e-06,0.05072294458891778,383.3487134025366,147.42409144919947,4.227215322303068
3.0822524567234843e-06,0.05200960192038408,385.60238053318443,147.42409144919947,4.227215322303068
3.093633256268302e-06,0.05220164032806561,385.93687458810734,147.42409144919947,4.227215322303068
3.114118695448976e-06,0.052547309461892386,386.53775702699494,147.42409144919947,4.227215322303068
3.127775654902757e-06,0.05277775555111022,386.9374891134186,147.42409144919947,4.227215322303068
3.1539514938558386e-06,0.05321944388877775,387.70174476401036,147.42409144919947,4.227215322303068
3.161918053537212e-06,0.053353870774154835,387.93385278638533,147.42409144919947,4.227215322303068
3.196060452171666e-06,0.053929985997199434,388.92602927732844,147.42409144919947,4.227215322303068
3.221098211170266e-06,0.05435247049409882,389.65100017445866,147.42409144919947,4.227215322303068
3.243859810259903e-06,0.0547365473094619,390.3081597391458,147.42409144919947,4.227215322303068
3.2541025298502386e-06,0.05490938187637527,390.60329457957624,147.42409144919947,4.227215322303068
3.2597929296226473e-06,0.05500540108021604,390.76710182457873,147.42409144919947,4.227215322303068
3.287106848530211e-06,0.055466293258651725,391.55182952345547,147.42409144919947,4.227215322303068
3.31100652757433e-06,0.05586957391478296,392.23638251954503,147.42409144919947,4.227215322303068
3.3155588473922567e-06,0.05594638927785557,392.3665547893749,147.42409144919947,4.227215322303068
3.3246634870281112e-06,0.0561000200040008,392.626690405032,147.42409144919947,4.227215322303068
3.369048605252902e-06,0.05684896979395879,393.8908944306492,147.42409144919947,4.227215322303068
3.4157098833866567e-06,0.05763632726545309,395.21294563817924,147.42409144919947,4.227215322303068
3.450990361975593e-06,0.05823164632926585,396.20787432392774,147.42409144919947,4.227215322303068
3.4646473214293753e-06,0.0584620924184837,396.59194204312735,147.42409144919947,4.227215322303068
3.477166200928675e-06,0.05867333466693339,396.9434857620817,147.42409144919947,4.227215322303068
3.504480119836239e-06,0.05913422684536908,397.70878144030775,147.42409144919947,4.227215322303068
3.5454509981975837e-06,0.0598255651130226,398.8523776389605,147.42409144919947,4.227215322303068
3.6160119553754567e-06,0.06101620324064813,400.80989577456194,147.42409144919947,4.227215322303068
3.6308069947837204e-06,0.06126585317063413,401.2184474569615,147.42409144919947,4.227215322303068
3.634221234647166e-06,0.06132346469293859,401.31263634976943,147.42409144919947,4.227215322303068
3.6433258742830204e-06,0.06147709541908382,401.56363816732534,147.42409144919947,4.227215322303068
3.6751921130085106e-06,0.062014802960592114,402.4402245638602,147.42409144919947,4.227215322303068
3.6934013922802197e-06,0.06232206441288257,402.9398001498775,147.42409144919947,4.227215322303068
3.722991471096748e-06,0.06282136427285458,403.7495666138634,147.42409144919947,4.227215322303068
3.7332341906870837e-06,0.06299419883976795,404.0292850776037,147.42409144919947,4.227215322303068
3.7377865105050112e-06,0.06307101420284057,404.1535083046825,147.42409144919947,4.227215322303068
3.752581549913275e-06,0.06332066413282657,404.556826905038,147.42409144919947,4.227215322303068
3.7742050690484294e-06,0.06368553710742149,405.14517880057326,147.42409144919947,4.227215322303068
3.7981047480925476e-06,0.06408881776355271,405.7939351141136,147.42409144919947,4.227215322303068
3.81859018727322e-06,0.06443448689737948,406.3487457879552,147.42409144919947,4.227215322303068
3.825418667000111e-06,0.0645497099419884,406.5334245687326,147.42409144919947,4.227215322303068
3.8663895453614565e-06,0.06524104820964192,407.6388093920912,147.42409144919947,4.227215322303068
3.885736904587648e-06,0.06556751350270054,408.15920786420804,147.42409144919947,4.227215322303068
3.911912743540729e-06,0.06600920184036807,408.8616707862019,147.42409144919947,4.227215322303068
3.940364742402775e-06,0.06648929785957192,409.62314149589014,147.42409144919947,4.227215322303068
3.947193222129666e-06,0.06660452090418084,409.8055750242525,147.42409144919947,4.227215322303068
3.964264421446893e-06,0.06689257851570314,410.26112117542186,147.42409144919947,4.227215322303068
4.033687298670284e-06,0.06806401280256051,412.10584792696204,147.42409144919947,4.227215322303068
4.061001217577847e-06,0.0685249049809962,412.8282427267244,147.42409144919947,4.227215322303068
4.084900896621965e-06,0.06892818563712742,413.4587851730405,147.42409144919947,4.227215322303068
4.0917293763488564e-06,0.06904340868173635,413.6386756838384,147.42409144919947,4.227215322303068
4.097419776121265e-06,0.06913942788557711,413.78849502276506,147.42409144919947,4.227215322303068
4.147495294118466e-06,0.06998439687937588,415.10342458419996,147.42409144919947,4.227215322303068
4.191880412343256e-06,0.07073334666933387,416.263762852677,147.42409144919947,4.227215322303068
4.221470491159783e-06,0.07123264652930586,417.0346608191134,147.42409144919947,4.227215322303068
4.227160890932193e-06,0.07132866573314664,417.1826685221415,147.42409144919947,4.227215322303068
4.236265530568048e-06,0.07148229645929187,417.4193193255852,147.42409144919947,4.227215322303068
4.312516887518329e-06,0.07276895379075815,419.3935424725576,147.42409144919947,4.227215322303068
4.327311926926592e-06,0.07301860372074415,419.7750186669742,147.42409144919947,4.227215322303068
4.351211605970711e-06,0.07342188437687538,420.3901766869572,147.42409144919947,4.227215322303068
4.366006645378975e-06,0.07367153430686138,420.7703284898946,147.42409144919947,4.227215322303068
4.381939764741719e-06,0.07394038807761552,421.1791613162148,147.42409144919947,4.227215322303068
4.4126679235127284e-06,0.07445889177835567,421.9659911115661,147.42409144919947,4.227215322303068
4.4399818424202925e-06,0.07491978395679136,422.6636032244378,147.42409144919947,4.227215322303068
4.485505040599565e-06,0.0756879375875175,423.82258215965953,147.42409144919947,4.227215322303068
4.513957039461611e-06,0.07616803360672135,424.54461495433736,147.42409144919947,4.227215322303068
4.536718638551247e-06,0.07655211042208442,425.1209640693101,147.42409144919947,4.227215322303068
4.567446797322255e-06,0.07707061412282457,425.8972496762604,147.42409144919947,4.227215322303068
4.57655143695811e-06,0.0772242448489698,426.12686872404635,147.42409144919947,4.227215322303068
4.60158919595671e-06,0.07764672934586918,426.7574043279705,147.42409144919947,4.227215322303068
4.615246155410492e-06,0.07787717543508701,427.1007688315552,147.42409144919947,4.227215322303068
4.6311792747732375e-06,0.07814602920584117,427.50086032718707,147.42409144919947,4.227215322303068
4.650526633999429e-06,0.07847249449889979,427.98596474110224,147.42409144919947,4.227215322303068
4.680116712815956e-06,0.07897179435887178,428.7263694984181,147.42409144919947,4.227215322303068
4.709706791632483e-06,0.07947109421884377,429.4649508161753,147.42409144919947,4.227215322303068
4.716535271359374e-06,0.0795863172634527,429.6351353931274,147.42409144919947,4.227215322303068
4.727916070904192e-06,0.07977835567113423,429.9185629731826,147.42409144919947,4.227215322303068
4.740434950403492e-06,0.07998959791958392,430.2300261686734,147.42409144919947,4.227215322303068
4.756368069766238e-06,0.08025845169033807,430.6259703145391,147.42409144919947,4.227215322303068
4.781405828764838e-06,0.08068093618723746,431.2471247491151,147.42409144919947,4.227215322303068
4.8132720674903285e-06,0.08121864372874575,432.0358533438897,147.42409144919947,4.227215322303068
4.829205186853074e-06,0.0814874974994999,432.4294537679085,147.42409144919947,4.227215322303068
4.834895586625483e-06,0.08158351670334067,432.5699025670476,147.42409144919947,4.227215322303068
4.8667618253509745e-06,0.08212122424484898,433.35522773883076,147.42409144919947,4.227215322303068
4.913423103484728e-06,0.08290858171634327,434.5015596219238,147.42409144919947,4.227215322303068
4.928218142892992e-06,0.08315823164632927,434.86414315973184,147.42409144919947,4.227215322303068
4.946427422164701e-06,0.08346549309861973,435.30981757417396,147.42409144919947,4.227215322303068
5.007883739706719e-06,0.08450250050010003,436.8092671320969,147.42409144919947,4.227215322303068
5.038611898477728e-06,0.08502100420084018,437.5562994921133,147.42409144919947,4.227215322303068
5.059097337658401e-06,0.08536667333466694,438.05333421381494,147.42409144919947,4.227215322303068
5.078444696884592e-06,0.08569313862772555,438.52203566867803,147.42409144919947,4.227215322303068
5.0921016563383736e-06,0.08592358471694339,438.85246456824734,147.42409144919947,4.227215322303068
5.108034775701119e-06,0.08619243848769755,439.237528443081,147.42409144919947,4.227215322303068
5.120553655200419e-06,0.08640368073614724,439.53975011033623,147.42409144919947,4.227215322303068
5.131934454745237e-06,0.08659571914382877,439.814247114638,147.42409144919947,4.227215322303068
5.174043413061064e-06,0.08730626125225045,440.8278283617547,147.42409144919947,4.227215322303068
5.201357331968628e-06,0.08776715343068614,441.48356671877565,147.42409144919947,4.227215322303068
5.2127381315134456e-06,0.08795919183836767,441.7563945171588,147.42409144919947,4.227215322303068
5.228671250876191e-06,0.08822804560912183,442.13796348441605,147.42409144919947,4.227215322303068
5.259399409647201e-06,0.08874654930986198,442.872568337227,147.42409144919947,4.227215322303068
5.300370288008546e-06,0.0894378875775155,443.84944297670785,147.42409144919947,4.227215322303068
5.316303407371291e-06,0.08970674134826966,444.2285428146415,147.42409144919947,4.227215322303068
5.332236526734037e-06,0.08997559511902381,444.60719980298484,147.42409144919947,4.227215322303068
5.358412365687118e-06,0.09041728345669134,445.2283225910289,147.42409144919947,4.227215322303068
5.373207405095382e-06,0.09066693338667733,445.5788685352201,147.42409144919947,4.227215322303068
5.414178283456728e-06,0.09135827165433087,446.5476520141839,147.42409144919947,4.227215322303068
5.417592523320173e-06,0.09141588317663533,446.6282546875206,147.42409144919947,4.227215322303068
5.436939882546363e-06,0.09174234846969394,447.0846295207113,147.42409144919947,4.227215322303068
5.439216042455328e-06,0.09178075615123026,447.13827900595686,147.42409144919947,4.227215322303068
5.488153480498045e-06,0.09260652130426085,448.28963367066547,147.42409144919947,4.227215322303068
5.50294851990631e-06,0.09285617123424686,448.6369285007058,147.42409144919947,4.227215322303068
5.5097769996332e-06,0.09297139427885577,448.7970955834232,147.42409144919947,4.227215322303068
5.557576357721437e-06,0.09377795559111823,449.9161054797968,147.42409144919947,4.227215322303068
5.588304516492446e-06,0.09429645929185837,450.63348739696164,147.42409144919947,4.227215322303068
5.613342275491046e-06,0.09471894378875775,451.2168840370896,147.42409144919947,4.227215322303068
5.650898913988946e-06,0.09535267053410683,452.090079754195,147.42409144919947,4.227215322303068
5.6645558734427275e-06,0.09558311662332467,452.4070439415934,147.42409144919947,4.227215322303068
5.666832033351692e-06,0.09562152430486098,452.45984231745314,147.42409144919947,4.227215322303068
5.675936672987546e-06,0.09577515503100621,452.6709531654806,147.42409144919947,4.227215322303068
5.6907317123958094e-06,0.09602480496099221,453.0137268339876,147.42409144919947,4.227215322303068
5.693007872304773e-06,0.09606321264252851,453.0664303808696,147.42409144919947,4.227215322303068
5.700974431986146e-06,0.09619763952790558,453.2508281132985,147.42409144919947,4.227215322303068
5.745359550210937e-06,0.09694658931786358,454.2763531642041,147.42409144919947,4.227215322303068
5.765844989391609e-06,0.09729225845169034,454.74862984959697,147.42409144919947,4.227215322303068
5.771535389164019e-06,0.09738827765553111,454.87970162415564,147.42409144919947,4.227215322303068
5.784054268663318e-06,0.0975995199039808,455.1678822535399,147.42409144919947,4.227215322303068
5.830715546797073e-06,0.09838687737547509,456.23987372691175,147.42409144919947,4.227215322303068
5.836405946569482e-06,0.09848289657931587,456.3703751178361,147.42409144919947,4.227215322303068
5.867134105340491e-06,0.09900140028005601,457.0742270167455,147.42409144919947,4.227215322303068
5.9081049837018365e-06,0.09969273854770955,458.0104639239348,147.42409144919947,4.227215322303068
5.911519223565282e-06,0.09975035007001401,458.08836918817576,147.42409144919947,4.227215322303068