File: datasets/aisi_316_L/data/M1/train_6.csv
Time(s),Strain(%),Stress(MPa),Temp(C),Log_SR(s-1)
0.0,0.0,0.0,35.85385985322583,-1.5099183089786328
0.0003105914827355497,9.6e-06,1.8766219499999999,35.85385985322583,-1.5099183089786328
0.0010611875660131282,3.28e-05,6.4117916625,35.85385985322583,-1.5099183089786328
0.0018117836492907067,5.6e-05,10.946961374999999,35.85385985322583,-1.5099183089786328
0.0025882623561295807,7.999999999999999e-05,15.638516249999999,35.85385985322583,-1.5099183089786328
0.0027694407210586513,8.56e-05,16.7332123875,35.85385985322583,-1.5099183089786328
0.003183562698039384,9.839999999999999e-05,19.2353749875,35.85385985322583,-1.5099183089786328
0.003675332545704005,0.0001136,22.206693075,35.85385985322583,-1.5099183089786328
0.004218867640491217,0.0001304,25.4907814875,35.85385985322583,-1.5099183089786328
0.004503576499665471,0.0001392,27.211018275,35.85385985322583,-1.5099183089786328
0.004684754864594541,0.0001448,28.3057144125,35.85385985322583,-1.5099183089786328
0.004865933229523612,0.0001504,29.40041055,35.85385985322583,-1.5099183089786328
0.00543535094787212,0.000168,32.840884124999995,35.85385985322583,-1.5099183089786328
0.006470655890323951,0.00019999999999999998,39.096290624999995,35.85385985322583,-1.5099183089786328
0.007065956232233756,0.0002184,42.6931493625,35.85385985322583,-1.5099183089786328
0.007971848056879107,0.00024639999999999997,48.166630049999995,35.85385985322583,-1.5099183089786328
0.008127143798246883,0.0002512,49.104941024999995,35.85385985322583,-1.5099183089786328
0.009214213987821308,0.0002848,55.67311785,35.85385985322583,-1.5099183089786328
0.009524805470556858,0.0002944,57.5497398,35.85385985322583,-1.5099183089786328
0.009654218588363336,0.0002984,58.3316656125,35.85385985322583,-1.5099183089786328
0.009783631706169815,0.0003024,59.113591424999996,35.85385985322583,-1.5099183089786328
0.010378932048079619,0.0003208,62.710450162499995,35.85385985322583,-1.5099183089786328
0.010560110413008689,0.00032639999999999996,63.80514629999999,35.85385985322583,-1.5099183089786328
0.010689523530815169,0.0003304,64.5870721125,35.85385985322583,-1.5099183089786328
0.011077762884234605,0.0003424,66.93284955,35.85385985322583,-1.5099183089786328
0.011388354366970155,0.000352,68.8094715,35.85385985322583,-1.5099183089786328
0.012889546533525312,0.0003984,77.879810925,35.85385985322583,-1.5099183089786328
0.013251903263383453,0.0004096,80.06920319999999,35.85385985322583,-1.5099183089786328
0.013924851475977145,0.0004304,84.135217425,35.85385985322583,-1.5099183089786328
0.014313090829396581,0.00044239999999999997,86.4809948625,35.85385985322583,-1.5099183089786328
0.015167217406919342,0.00046879999999999996,91.641705225,35.85385985322583,-1.5099183089786328
0.015633104631022667,0.0004832,94.45663815,35.85385985322583,-1.5099183089786328
0.016901353185526165,0.0005224,102.1195111125,35.85385985322583,-1.5099183089786328
0.017315475162506897,0.0005352,104.6216737125,35.85385985322583,-1.5099183089786328
0.017626066645242446,0.0005448,106.4982956625,35.85385985322583,-1.5099183089786328
0.0179107755044167,0.0005536,108.21853245,35.85385985322583,-1.5099183089786328
0.01827313223427484,0.0005648,110.40792472499999,35.85385985322583,-1.5099183089786328
0.019049610941113716,0.0005888,115.0994796,35.85385985322583,-1.5099183089786328
0.019903737518636475,0.0006152,120.2601899625,35.85385985322583,-1.5099183089786328
0.020369624742739803,0.0006296,123.0751228875,35.85385985322583,-1.5099183089786328
0.021016690331772194,0.0006496,126.98475194999999,35.85385985322583,-1.5099183089786328
0.021379047061630338,0.0006608,129.174144225,35.85385985322583,-1.5099183089786328
0.022466117251204763,0.0006944,135.74232105,35.85385985322583,-1.5099183089786328
0.023113182840237157,0.0007144,139.6519501125,35.85385985322583,-1.5099183089786328
0.02420025302981158,0.000748,146.2201269375,35.85385985322583,-1.5099183089786328
0.024717905501037495,0.0007639999999999999,149.3478301875,35.85385985322583,-1.5099183089786328
0.025106144854456936,0.000776,151.693607625,35.85385985322583,-1.5099183089786328
0.025416736337192485,0.0007856,153.570229575,35.85385985322583,-1.5099183089786328
0.025882623561295805,0.0007999999999999999,156.38516249999998,35.85385985322583,-1.5099183089786328
0.025986154055540993,0.0008032,157.01070315,35.85385985322583,-1.5099183089786328
0.027150872115799304,0.0008392,164.0480354625,35.85385985322583,-1.5099183089786328
0.027280285233605782,0.0008432,164.829961275,35.85385985322583,-1.5099183089786328
0.027823820328392992,0.00086,168.1140496875,35.85385985322583,-1.5099183089786328
0.028263824928935023,0.0008736,170.77259745,35.85385985322583,-1.5099183089786328
0.02883324264728353,0.0008912,174.213071025,35.85385985322583,-1.5099183089786328
0.029480308236315925,0.0009111999999999999,178.1227000875,35.85385985322583,-1.5099183089786328
0.030101491201787026,0.0009304,181.8759439875,35.85385985322583,-1.5099183089786328
0.03155091812121959,0.0009752,190.6335130875,35.85385985322583,-1.5099183089786328
0.03222386633381328,0.000996,194.69952731249998,35.85385985322583,-1.5099183089786328
0.033181523405581226,0.0010256,200.485778325,35.85385985322583,-1.5099183089786328
0.03377682374749103,0.001044,204.0826370625,35.85385985322583,-1.5099183089786328
0.034061532606665286,0.0010528,205.80287385,35.85385985322583,-1.5099183089786328
0.034294476218716945,0.00106,207.2103403125,35.85385985322583,-1.5099183089786328
0.03450153720720731,0.0010664,208.46142161249998,35.85385985322583,-1.5099183089786328
0.03514860279623971,0.0010864,212.371050675,35.85385985322583,-1.5099183089786328
0.03574390313814951,0.0011048,215.9679094125,35.85385985322583,-1.5099183089786328
0.03615802511513024,0.0011175999999999998,218.47007201249997,35.85385985322583,-1.5099183089786328
0.03711568218689819,0.0011472,224.25632302499997,35.85385985322583,-1.5099183089786328
0.03758156941100151,0.0011616,227.07125595000002,35.85385985322583,-1.5099183089786328
0.038254517623595205,0.0011824,231.13727017499997,35.85385985322583,-1.5099183089786328
0.03833216549427909,0.0011848,231.6064256625,35.85385985322583,-1.5099183089786328
0.03840981336496298,0.0011872,232.07558115,35.85385985322583,-1.5099183089786328
0.039005113706872784,0.0012056,235.67243988750002,35.85385985322583,-1.5099183089786328
0.039496883554537406,0.0012208,238.643757975,35.85385985322583,-1.5099183089786328
0.03983335766083425,0.0012312,240.6767650875,35.85385985322583,-1.5099183089786328
0.040428658002744054,0.0012496,244.27362382500002,35.85385985322583,-1.5099183089786328
0.040609836367673124,0.0012552,245.36831996249998,35.85385985322583,-1.5099183089786328
0.04161925868656366,0.0012864,251.46734130000002,35.85385985322583,-1.5099183089786328
0.041929850169299204,0.0012959999999999998,253.34396324999997,35.85385985322583,-1.5099183089786328
0.04213691115778958,0.0013024,254.59504455,35.85385985322583,-1.5099183089786328
0.04366398594790603,0.0013495999999999998,263.8217691375,35.85385985322583,-1.5099183089786328
0.04464752564323527,0.00138,269.7644053125,35.85385985322583,-1.5099183089786328
0.04485458663172563,0.0013863999999999999,271.01548661249996,35.85385985322583,-1.5099183089786328
0.04524282598514507,0.0013984,273.36126405,35.85385985322583,-1.5099183089786328
0.04544988697363544,0.0014047999999999999,274.61234535,35.85385985322583,-1.5099183089786328
0.04612283518622913,0.0014256,278.678359575,35.85385985322583,-1.5099183089786328
0.046252248304035605,0.0014295999999999998,279.4602853875,35.85385985322583,-1.5099183089786328
0.0469251965166293,0.0014504,283.5262996125,35.85385985322583,-1.5099183089786328
0.04723578799936485,0.00146,283.94225323200254,35.85385985322583,-1.5099183089786328
0.04770167522346817,0.0014743999999999998,284.0551721120261,35.85385985322583,-1.5099183089786328
0.04902168902509426,0.0015152,284.3727966351636,35.85385985322583,-1.5099183089786328
0.04935816313139111,0.0015256,284.45322406521285,35.85385985322583,-1.5099183089786328
0.04974640248481054,0.0015375999999999999,284.5457597232881,35.85385985322583,-1.5099183089786328
0.05065229430945589,0.0015655999999999999,284.7605878168458,35.85385985322583,-1.5099183089786328
0.050937003168630146,0.0015743999999999999,284.8277950590752,35.85385985322583,-1.5099183089786328
0.05176524712259161,0.0015999999999999999,285.0224790009329,35.85385985322583,-1.5099183089786328
0.053085260924217705,0.0016408,285.3302641566088,35.85385985322583,-1.5099183089786328
0.05349938290119843,0.0016535999999999999,285.4262071912675,35.85385985322583,-1.5099183089786328
0.05461233571433415,0.0016879999999999998,285.6826296252342,35.85385985322583,-1.5099183089786328
0.05536293179761173,0.0017112,285.8544159348541,35.85385985322583,-1.5099183089786328
0.05595823213952154,0.0017296,285.99001522780003,35.85385985322583,-1.5099183089786328
0.05626882362225709,0.0017392,286.0605392834369,35.85385985322583,-1.5099183089786328
0.05751118955319928,0.0017775999999999998,286.34113043316165,35.85385985322583,-1.5099183089786328
0.058365316130722045,0.0018039999999999998,286.53266698048725,35.85385985322583,-1.5099183089786328
0.05859825974277371,0.0018112,286.5847141002925,35.85385985322583,-1.5099183089786328
0.05893473384907055,0.0018215999999999998,286.6597510441599,35.85385985322583,-1.5099183089786328
0.05903826434331574,0.0018248,286.6828056969442,35.85385985322583,-1.5099183089786328
0.05937473844961259,0.0018352,286.7576246609257,35.85385985322583,-1.5099183089786328
0.0598665082972772,0.0018503999999999999,286.8666786898829,35.85385985322583,-1.5099183089786328
0.060151217156451456,0.0018591999999999999,286.9296555477,35.85385985322583,-1.5099183089786328
0.06056533913343219,0.001872,287.0210511212579,35.85385985322583,-1.5099183089786328
0.061160639475342,0.0018904,287.1520064219952,35.85385985322583,-1.5099183089786328
0.0623512401591616,0.0019272,287.4124351307906,35.85385985322583,-1.5099183089786328
0.06276536213614234,0.0019399999999999999,287.5025634703357,35.85385985322583,-1.5099183089786328
0.06325713198380695,0.0019552,287.6092902083412,35.85385985322583,-1.5099183089786328
0.06364537133722639,0.0019672,287.6933197582698,35.85385985322583,-1.5099183089786328
0.06390419757283934,0.0019752,287.7492284253523,35.85385985322583,-1.5099183089786328
0.06405949331420713,0.00198,287.7827312371302,35.85385985322583,-1.5099183089786328
0.06431831954982008,0.0019879999999999997,287.838498952754,35.85385985322583,-1.5099183089786328
0.06504303300953636,0.0020104,287.99418485007266,35.85385985322583,-1.5099183089786328
0.06532774186871063,0.0020192,288.05516189320184,35.85385985322583,-1.5099183089786328
0.06613010319911078,0.002044,288.2264511803977,35.85385985322583,-1.5099183089786328
0.06633716418760116,0.0020504,288.27052305488456,35.85385985322583,-1.5099183089786328
0.06654422517609153,0.0020568,288.3145413121825,35.85385985322583,-1.5099183089786328
0.066673638293898,0.0020608,288.34202559856743,35.85385985322583,-1.5099183089786328
0.06804541734264669,0.0021032,288.6320913149292,35.85385985322583,-1.5099183089786328
0.06877013080236297,0.0021256,288.78441242282605,35.85385985322583,-1.5099183089786328
0.06897719179085332,0.0021319999999999998,288.82781758925125,35.85385985322583,-1.5099183089786328
0.06931366589715018,0.0021424,288.8982427612184,35.85385985322583,-1.5099183089786328
0.06998661410974387,0.0021632,289.0386943876665,35.85385985322583,-1.5099183089786328
0.07135839315849254,0.0022056,289.3233789821627,35.85385985322583,-1.5099183089786328
0.07161721939410551,0.0022136,289.3768528682788,35.85385985322583,-1.5099183089786328
0.07241958072450566,0.0022383999999999998,289.5421449484196,35.85385985322583,-1.5099183089786328
0.07301488106641547,0.0022567999999999998,289.66431985634637,35.85385985322583,-1.5099183089786328
0.07337723779627361,0.002268,289.7384970091132,35.85385985322583,-1.5099183089786328
0.07436077749160286,0.0022984,289.9391183547428,35.85385985322583,-1.5099183089786328
0.07508549095131914,0.0023208,290.086283024274,35.85385985322583,-1.5099183089786328
0.07547373030473857,0.0023328,290.16489332081443,35.85385985322583,-1.5099183089786328
0.07656080049431299,0.0023664,290.3841675578272,35.85385985322583,-1.5099183089786328
0.07666433098855818,0.0023696,290.40498728782796,35.85385985322583,-1.5099183089786328
0.07694903984773244,0.0023783999999999997,290.462185082889,35.85385985322583,-1.5099183089786328
0.07772551855457131,0.0024024,290.6177611051823,35.85385985322583,-1.5099183089786328
0.07782904904881649,0.0024056,290.63845868252315,35.85385985322583,-1.5099183089786328
0.0784761146378489,0.0024256,290.7675761113177,35.85385985322583,-1.5099183089786328
0.07945965433317813,0.002456,290.96304223862404,35.85385985322583,-1.5099183089786328
0.08000318942796535,0.0024728,291.0706581105196,35.85385985322583,-1.5099183089786328
0.08018436779289441,0.0024784,291.106466653594,35.85385985322583,-1.5099183089786328
0.08070202026412034,0.0024944,291.2086033153165,35.85385985322583,-1.5099183089786328
0.08163379471232697,0.0025231999999999997,291.39180775064335,35.85385985322583,-1.5099183089786328
0.08204791668930772,0.002536,291.47296997807916,35.85385985322583,-1.5099183089786328
0.08248792128984975,0.0025496,291.55902998744403,35.85385985322583,-1.5099183089786328
0.08277263014902399,0.0025583999999999997,291.61462048990387,35.85385985322583,-1.5099183089786328
0.08339381311449509,0.0025775999999999998,291.7356506697404,35.85385985322583,-1.5099183089786328
0.0840149960799662,0.0025968,291.85632975985357,35.85385985322583,-1.5099183089786328
0.08494677052817284,0.0026256,292.0366979662953,35.85385985322583,-1.5099183089786328
0.08520559676378579,0.0026336,292.08666310039825,35.85385985322583,-1.5099183089786328
0.08595619284706338,0.0026568,292.23122833925703,35.85385985322583,-1.5099183089786328
0.0864997279418506,0.0026736,292.33560634785584,35.85385985322583,-1.5099183089786328
0.08681031942458614,0.0026831999999999997,292.39513607582785,35.85385985322583,-1.5099183089786328
0.08740561976649594,0.0027015999999999997,292.50900305607905,35.85385985322583,-1.5099183089786328
0.08774209387279279,0.002712,292.57322885832633,35.85385985322583,-1.5099183089786328
0.08823386372045741,0.0027272,292.666924823827,35.85385985322583,-1.5099183089786328
0.08869975094456073,0.0027416,292.75550173376035,35.85385985322583,-1.5099183089786328
0.0889326945566124,0.0027488,292.7997221337715,35.85385985322583,-1.5099183089786328
0.08981270375769645,0.002776,292.966370881196,35.85385985322583,-1.5099183089786328
0.09009741261687071,0.0027848,293.0201501496562,35.85385985322583,-1.5099183089786328
0.09061506508809662,0.0028008,293.11776114195294,35.85385985322583,-1.5099183089786328
0.09084800870014828,0.0028079999999999997,293.1616151140963,35.85385985322583,-1.5099183089786328
0.09105506968863865,0.0028144,293.2005596204907,35.85385985322583,-1.5099183089786328
0.09121036543000643,0.0028192,293.22974533838095,35.85385985322583,-1.5099183089786328
0.09152095691274198,0.0028288,293.28805869964293,35.85385985322583,-1.5099183089786328
0.09214213987821307,0.002848,293.4044543988091,35.85385985322583,-1.5099183089786328
0.09294450120861325,0.0028728,293.55434691060594,35.85385985322583,-1.5099183089786328
0.09343627105627787,0.002888,293.6459671088896,35.85385985322583,-1.5099183089786328
0.0944715759987297,0.00292,293.8382392886537,35.85385985322583,-1.5099183089786328
0.09483393272858784,0.0029311999999999997,293.9053401810574,35.85385985322583,-1.5099183089786328
0.09537746782337504,0.0029479999999999997,294.00580433891884,35.85385985322583,-1.5099183089786328
0.09550688094118152,0.0029519999999999998,294.02969143641945,35.85385985322583,-1.5099183089786328
0.09625747702445911,0.0029752,294.1679884833149,35.85385985322583,-1.5099183089786328
0.09680101211924633,0.002992,294.26787220559095,35.85385985322583,-1.5099183089786328
0.09731866459047224,0.003008,294.3627964024771,35.85385985322583,-1.5099183089786328
0.09850926527429184,0.0030448,294.5803778993426,35.85385985322583,-1.5099183089786328
0.09900103512195646,0.00306,294.66994894140504,35.85385985322583,-1.5099183089786328
0.09913044823976294,0.003064,294.69349140700393,35.85385985322583,-1.5099183089786328
0.09969986595811145,0.0030816,294.79693618550215,35.85385985322583,-1.5099183089786328
0.09993280957016312,0.0030888,294.83918806311186,35.85385985322583,-1.5099183089786328
0.10045046204138904,0.0031048,294.93294384755785,35.85385985322583,-1.5099183089786328
0.10107164500686014,0.003124,295.0452024285619,35.85385985322583,-1.5099183089786328
0.1018222410901377,0.0031471999999999997,295.1804898518681,35.85385985322583,-1.5099183089786328
0.10226224569067974,0.0031608,295.25961544729745,35.85385985322583,-1.5099183089786328
0.10254695454985399,0.0031696,295.3107436181522,35.85385985322583,-1.5099183089786328
0.10329755063313158,0.0031928,295.4452714014031,35.85385985322583,-1.5099183089786328
0.10404814671640913,0.0032159999999999997,295.5794184852468,35.85385985322583,-1.5099183089786328
0.1044363860698286,0.003228,295.6486567830135,35.85385985322583,-1.5099183089786328
0.10464344705831895,0.0032343999999999997,295.685542826498,35.85385985322583,-1.5099183089786328
0.10526463002379005,0.0032535999999999997,295.7960305439569,35.85385985322583,-1.5099183089786328
0.10547169101228042,0.00326,295.8328032378111,35.85385985322583,-1.5099183089786328
0.10593757823638374,0.0032744,295.91543901401207,35.85385985322583,-1.5099183089786328
0.106222287095558,0.0032832,295.96586888772663,35.85385985322583,-1.5099183089786328
0.10717994416732594,0.0033128,296.13511110495324,35.85385985322583,-1.5099183089786328
0.10749053565006149,0.0033223999999999997,296.1898736855751,35.85385985322583,-1.5099183089786328
0.10774936188567445,0.0033304,296.2354620444857,35.85385985322583,-1.5099183089786328
0.10837054485114554,0.0033496,296.34470020790786,35.85385985322583,-1.5099183089786328
0.10870701895744239,0.0033599999999999997,296.4037689068719,35.85385985322583,-1.5099183089786328
0.10943173241715867,0.0033824,296.5307521598604,35.85385985322583,-1.5099183089786328
0.1099235022648233,0.0033975999999999998,296.61673263919755,35.85385985322583,-1.5099183089786328
0.11015644587687497,0.0034048,296.65740786317326,35.85385985322583,-1.5099183089786328
0.11031174161824274,0.0034096,296.6845060443046,35.85385985322583,-1.5099183089786328
0.1105188026067331,0.0034159999999999998,296.72061382039885,35.85385985322583,-1.5099183089786328
0.11095880720727512,0.0034295999999999997,296.7972553613822,35.85385985322583,-1.5099183089786328
0.11129528131357197,0.00344,296.8557836494291,35.85385985322583,-1.5099183089786328
0.1116835206669914,0.0034519999999999998,296.9232306075433,35.85385985322583,-1.5099183089786328
0.11189058165548178,0.0034584,296.9591649268232,35.85385985322583,-1.5099183089786328
0.11279647348012713,0.0034863999999999997,297.1160736277187,35.85385985322583,-1.5099183089786328
0.11310706496286269,0.003496,297.16975765915896,35.85385985322583,-1.5099183089786328
0.11442707876448877,0.0035367999999999997,297.3972763693235,35.85385985322583,-1.5099183089786328
0.11507414435352116,0.0035567999999999997,297.5084311007751,35.85385985322583,-1.5099183089786328
0.11652357127295374,0.0036016,297.7565369384833,35.85385985322583,-1.5099183089786328
0.11719651948554742,0.0036224,297.87131952319913,35.85385985322583,-1.5099183089786328
0.11740358047403777,0.0036287999999999997,297.9065854910494,35.85385985322583,-1.5099183089786328
0.11794711556882499,0.0036455999999999997,297.99904343871617,35.85385985322583,-1.5099183089786328
0.11823182442799925,0.0036544,298.04740746751827,35.85385985322583,-1.5099183089786328
0.1185165332871735,0.0036631999999999997,298.0957260969058,35.85385985322583,-1.5099183089786328
0.11934477724113497,0.0036888,298.23603264956176,35.85385985322583,-1.5099183089786328
0.12107891301974179,0.0037424,298.5285755063154,35.85385985322583,-1.5099183089786328
0.12115656089042567,0.0037448,298.5416360821075,35.85385985322583,-1.5099183089786328
0.12128597400823214,0.0037487999999999996,298.56339645644323,35.85385985322583,-1.5099183089786328
0.12154480024384512,0.0037568,298.60689005853015,35.85385985322583,-1.5099183089786328
0.12201068746794844,0.0037711999999999997,298.68508762628016,35.85385985322583,-1.5099183089786328
0.12250245731561306,0.0037863999999999997,298.7675032751346,35.85385985322583,-1.5099183089786328
0.12335658389313582,0.0038128,298.9103402312547,35.85385985322583,-1.5099183089786328
0.12459894982407803,0.0038512,299.1174164487146,35.85385985322583,-1.5099183089786328
0.12509071967174265,0.0038664,299.1991614705189,35.85385985322583,-1.5099183089786328
0.1264624987204913,0.0039088,299.4265272859839,35.85385985322583,-1.5099183089786328
0.1266695597089817,0.0039152,299.4607629227034,35.85385985322583,-1.5099183089786328
0.12734250792157537,0.003935999999999999,299.5718783119372,35.85385985322583,-1.5099183089786328
0.12801545613416906,0.0039568,299.68276492961877,35.85385985322583,-1.5099183089786328
0.12897311320593702,0.0039864,299.84017396925185,35.85385985322583,-1.5099183089786328
0.13251965394106147,0.004096019203840768,300.41918706190694,35.85385985322583,-1.5099183089786328
0.1455671057063076,0.004499299859971995,302.4992061188656,35.85385985322583,-1.5099183089786328
0.16234240083305265,0.005017803560712143,305.069526398977,35.85385985322583,-1.5099183089786328
0.19340776217887676,0.005977995599119824,309.570591976916,35.85385985322583,-1.5099183089786328
0.20086344890187455,0.0062084416883376676,310.6077074107265,35.85385985322583,-1.5099183089786328
0.2213665873901185,0.006842168433686738,313.38508085191245,35.85385985322583,-1.5099183089786328
0.23130750302078218,0.007149429885977195,314.69539190539393,35.85385985322583,-1.5099183089786328
0.23689926806303055,0.007322264452890578,315.422785213893,35.85385985322583,-1.5099183089786328
0.2449762620129448,0.007571914382876575,316.4617520167591,35.85385985322583,-1.5099183089786328
0.2574024065512745,0.007955991198239648,318.03444423175307,35.85385985322583,-1.5099183089786328
0.276041623358769,0.008532106421284257,320.3390488135438,35.85385985322583,-1.5099183089786328
0.2822546956279338,0.008724144828965793,321.0936534961471,35.85385985322583,-1.5099183089786328
0.29033168957784805,0.00897379475895179,322.0650243273941,35.85385985322583,-1.5099183089786328
0.3077282919315096,0.009511502300460092,324.1221114566537,35.85385985322583,-1.5099183089786328
0.31083482806609203,0.00960752150430086,324.4846240676465,35.85385985322583,-1.5099183089786328
0.3126987497468415,0.009665133026605321,324.70145346351353,35.85385985322583,-1.5099183089786328
0.31891182201600626,0.009857171434286858,325.42060502687264,35.85385985322583,-1.5099183089786328
0.32326097260442166,0.009991598319663933,325.9207633403086,35.85385985322583,-1.5099183089786328
0.3381723460504172,0.010452490498099619,327.6160124124391,35.85385985322583,-1.5099183089786328
0.3419001894119161,0.01056771354270854,328.0352379993717,35.85385985322583,-1.5099183089786328
0.34624934000033153,0.010702140428085618,328.52208803130594,35.85385985322583,-1.5099183089786328
0.3611607134463271,0.011163032606521305,330.1734747759683,35.85385985322583,-1.5099183089786328
0.3717229363039073,0.011489497899579915,331.3271546150394,35.85385985322583,-1.5099183089786328
0.3953326109267336,0.012219243848769754,333.8607089320701,35.85385985322583,-1.5099183089786328
0.4071374482381468,0.012584116823364673,335.10530017380734,35.85385985322583,-1.5099183089786328
0.41024398437272924,0.01268013602720544,335.4304749168445,35.85385985322583,-1.5099183089786328
0.4145931349611446,0.012814562912582516,335.8841108291238,35.85385985322583,-1.5099183089786328
0.4245340505918083,0.013121824364872975,336.91408075862194,35.85385985322583,-1.5099183089786328
0.43509627344938856,0.013448289657931586,337.99817032863376,35.85385985322583,-1.5099183089786328
0.4363388879032215,0.013486697339467894,338.1250319590893,35.85385985322583,-1.5099183089786328
0.44627980353388524,0.013793958791758352,339.13490164942255,35.85385985322583,-1.5099183089786328
0.45808464084529843,0.014158831766353271,340.32279711416766,35.85385985322583,-1.5099183089786328
0.4655403275682962,0.014389277855571115,341.06689897028946,35.85385985322583,-1.5099183089786328
0.4848008516027072,0.014984596919383877,342.96796273425906,35.85385985322583,-1.5099183089786328
0.49039261664495554,0.01515743148629726,343.5143370657227,35.85385985322583,-1.5099183089786328
0.4978483033679533,0.015387877575515104,344.23907145407657,35.85385985322583,-1.5099183089786328
0.5158662129485313,0.01594478895779156,345.9732554746737,35.85385985322583,-1.5099183089786328
0.5220792852176962,0.016136827365473096,346.5657512060709,35.85385985322583,-1.5099183089786328
0.5568724899250191,0.0172122424484897,349.83426217488625,35.85385985322583,-1.5099183089786328
0.5730264778248476,0.01771154230846169,351.324610605068,35.85385985322583,-1.5099183089786328
0.5748903995055972,0.017769153830766153,351.49551301242866,35.85385985322583,-1.5099183089786328
0.5786182428670961,0.017884376875375075,351.836670904097,35.85385985322583,-1.5099183089786328
0.5891804657246763,0.01821084216843369,352.7986607970289,35.85385985322583,-1.5099183089786328
0.6152753692551685,0.019017403480696138,355.1469477356555,35.85385985322583,-1.5099183089786328
0.6314293571549972,0.019516703340668136,356.581194979929,35.85385985322583,-1.5099183089786328
0.6680864835430695,0.0206497299459892,359.78377744786025,35.85385985322583,-1.5099183089786328
0.6736782485853179,0.02082256451290258,360.26621521626356,35.85385985322583,-1.5099183089786328
0.6786487064006498,0.02097619523904781,360.6937392621857,35.85385985322583,-1.5099183089786328
0.6848617786698146,0.021168233646729345,361.22643092660013,35.85385985322583,-1.5099183089786328
0.6979092304350608,0.021571514302860573,362.33898743573957,35.85385985322583,-1.5099183089786328
0.7171697544694717,0.022166833366673334,363.9666200814491,35.85385985322583,-1.5099183089786328
0.7289745917808849,0.022531706341268255,364.9557778556918,35.85385985322583,-1.5099183089786328
0.7376728929577157,0.022800560112022406,365.68063808276906,35.85385985322583,-1.5099183089786328
0.7494777302691288,0.023165433086617324,366.6590675734524,35.85385985322583,-1.5099183089786328
0.7643891037151244,0.02362632526505301,367.8864297905105,35.85385985322583,-1.5099183089786328
0.7824070132957023,0.024183236647329465,369.3571034634466,35.85385985322583,-1.5099183089786328
0.7935905433801991,0.02452890578115623,370.26329440100835,35.85385985322583,-1.5099183089786328
0.796075772287865,0.024605721144228845,370.46399221973945,35.85385985322583,-1.5099183089786328
0.8053953806916122,0.02489377875575115,371.21444267468314,35.85385985322583,-1.5099183089786328
0.8345968203566869,0.02579635927185437,373.544217235146,35.85385985322583,-1.5099183089786328
0.8582064949795133,0.02652610522104421,375.40470401641284,35.85385985322583,-1.5099183089786328
0.868147410610177,0.026833366673334667,376.18208254945193,35.85385985322583,-1.5099183089786328
0.8799522479215902,0.027198239647929588,377.1007249173056,35.85385985322583,-1.5099183089786328
0.8898931635522539,0.027505501100220046,377.8705965799238,35.85385985322583,-1.5099183089786328
0.9029406153175,0.02790878175635127,378.8759821714761,35.85385985322583,-1.5099183089786328
0.9116389164943308,0.02817763552710542,379.54309330461945,35.85385985322583,-1.5099183089786328
0.9302781333018253,0.02875375075015003,380.96431503996604,35.85385985322583,-1.5099183089786328
0.9352485911171571,0.02890738147629526,381.3414263733687,35.85385985322583,-1.5099183089786328
0.9507812717900691,0.0293874774954991,382.51489267900786,35.85385985322583,-1.5099183089786328
0.954509115151568,0.02950270054010802,382.7954091948194,35.85385985322583,-1.5099183089786328
0.9663139524629812,0.02986757351470294,383.68090581070044,35.85385985322583,-1.5099183089786328
0.976254868093645,0.0301748349669934,384.4233197254223,35.85385985322583,-1.5099183089786328
0.9830892475897263,0.030386077215443088,384.9320198888416,35.85385985322583,-1.5099183089786328
0.9948940849011395,0.03075095019003801,385.80744715280093,35.85385985322583,-1.5099183089786328
1.0054563077587197,0.03107741548309662,386.587296189457,35.85385985322583,-1.5099183089786328
1.0191250667508822,0.031499899979996,387.59178619761377,35.85385985322583,-1.5099183089786328
1.02658075347388,0.03173034606921384,388.1374747221287,35.85385985322583,-1.5099183089786328
1.0359003618776275,0.03201840368073615,388.81741671209454,35.85385985322583,-1.5099183089786328
1.0427347413737087,0.03222964592918584,389.314525548697,35.85385985322583,-1.5099183089786328
1.0501904280967063,0.03246009201840368,389.8553791114409,35.85385985322583,-1.5099183089786328
1.0514330425505394,0.03249849969993999,389.94537558425657,35.85385985322583,-1.5099183089786328
1.0719361810387833,0.033132226445289056,391.4243802380429,35.85385985322583,-1.5099183089786328
1.0800131749886974,0.03338187637527505,392.0039841408615,35.85385985322583,-1.5099183089786328
1.0955458556616098,0.0338619723944789,393.1138775260816,35.85385985322583,-1.5099183089786328
1.103622849611524,0.034111622324464894,393.6885957156333,35.85385985322583,-1.5099183089786328
1.1154276869229371,0.034476495299059814,394.5256264413423,35.85385985322583,-1.5099183089786328
1.147114355495678,0.03545589117823565,396.7554837369486,35.85385985322583,-1.5099183089786328
1.1589191928070912,0.03582076415283057,397.58005639728805,35.85385985322583,-1.5099183089786328
1.1738305662530868,0.03628165633126626,398.61695469013443,35.85385985322583,-1.5099183089786328
1.1930910902874976,0.03687697539507902,399.94871010672193,35.85385985322583,-1.5099183089786328
1.2167007649103239,0.03760672134426886,401.5698005288366,35.85385985322583,-1.5099183089786328
1.233476060037069,0.03812522504500901,402.71418116577973,35.85385985322583,-1.5099183089786328
1.244038282894649,0.03845169033806761,403.4316040400128,35.85385985322583,-1.5099183089786328
1.2496300479368976,0.038624524904981,403.81045423219706,35.85385985322583,-1.5099183089786328
1.2558431202060623,0.03881656331266253,404.23062431918476,35.85385985322583,-1.5099183089786328
1.2881510960057192,0.039815163032606515,406.40257660371645,35.85385985322583,-1.5099183089786328
1.318595150124627,0.04075615123024605,408.4298616240783,35.85385985322583,-1.5099183089786328
1.3359917524782887,0.04129385877175436,409.58011310557515,35.85385985322583,-1.5099183089786328
1.339098288612871,0.041389877975595124,409.7848989690559,35.85385985322583,-1.5099183089786328
1.35338835483195,0.04183156631326265,410.7245377830925,35.85385985322583,-1.5099183089786328
1.3583588126472819,0.04198519703940788,411.05046064628056,35.85385985322583,-1.5099183089786328
1.3645718849164465,0.042177235447089415,411.4572108968446,35.85385985322583,-1.5099183089786328
1.373891493320194,0.04246529305861173,412.06598462510595,35.85385985322583,-1.5099183089786328
1.378861951135526,0.04261892378475696,412.39000532544895,35.85385985322583,-1.5099183089786328
1.396879860716104,0.04317583516703341,413.56078105057935,35.85385985322583,-1.5099183089786328
1.4037142402121852,0.0433870774154831,414.0033258554608,35.85385985322583,-1.5099183089786328
1.4105486197082662,0.04359831966393278,414.44503113844615,35.85385985322583,-1.5099183089786328
1.4217321497927633,0.043943988797759556,415.16602547392193,35.85385985322583,-1.5099183089786328
1.4559040472731697,0.045000200040008,417.35548096520944,35.85385985322583,-1.5099183089786328
1.4689514990384156,0.045403480696139226,418.18615616623254,35.85385985322583,-1.5099183089786328
1.4931824808881589,0.046152430486097226,419.72124422965555,35.85385985322583,-1.5099183089786328
1.5025020892919059,0.046440488097619526,420.30907194794537,35.85385985322583,-1.5099183089786328
1.506851239880321,0.046574914982996596,420.5829047531333,35.85385985322583,-1.5099183089786328
1.5279756855954818,0.04722784556911383,421.9085901743083,35.85385985322583,-1.5099183089786328
1.5354313723184794,0.04745829165833167,422.37477006565143,35.85385985322583,-1.5099183089786328
1.5472362096298926,0.04782316463292659,423.11108678058696,35.85385985322583,-1.5099183089786328
1.5546918963528902,0.048053610722144424,423.5750002616602,35.85385985322583,-1.5099183089786328
1.5776802637488,0.04876415283056611,424.99996829921645,35.85385985322583,-1.5099183089786328
1.5869998721525476,0.04905221044208842,425.57534843359116,35.85385985322583,-1.5099183089786328
1.6056390889600423,0.04962832566513303,426.72217055278514,35.85385985322583,-1.5099183089786328
1.6162013118176222,0.049954790958191636,427.3697315277594,35.85385985322583,-1.5099183089786328
1.619929155179121,0.05007001400280056,427.5978881338785,35.85385985322583,-1.5099183089786328
1.6304913780367014,0.05039647929585918,428.24322251636636,35.85385985322583,-1.5099183089786328
1.6472666731634462,0.050914982996599314,429.264824430415,35.85385985322583,-1.5099183089786328
1.6497519020711122,0.050991798359671936,429.4158270787566,35.85385985322583,-1.5099183089786328
1.6621780466094418,0.051375875175035,430.16951368362334,35.85385985322583,-1.5099183089786328
1.676468112828521,0.051817563512702544,431.0335420396966,35.85385985322583,-1.5099183089786328
1.681438570643853,0.05197119423884777,431.333399738825,35.85385985322583,-1.5099183089786328
1.6963499440898486,0.05243208641728346,432.23090549637055,35.85385985322583,-1.5099183089786328
1.698213865770598,0.05248969793958792,432.3428769740995,35.85385985322583,-1.5099183089786328
1.7081547814012619,0.05279695939187838,432.9392506547534,35.85385985322583,-1.5099183089786328
1.7236874620741736,0.053277055411082214,433.8683818755024,35.85385985322583,-1.5099183089786328
1.7367349138394197,0.05368033606721344,434.6463313526321,35.85385985322583,-1.5099183089786328
1.7479184439239166,0.054026005201040214,435.3113327629473,35.85385985322583,-1.5099183089786328
1.7553741306469142,0.05425645129025805,435.75374539488513,35.85385985322583,-1.5099183089786328
1.7591019740084133,0.054371674334866976,435.97467685192817,35.85385985322583,-1.5099183089786328
1.7696641968659932,0.05469813962792558,436.5996599080766,35.85385985322583,-1.5099183089786328
1.7808477269504903,0.055043808761752355,437.2598231030808,35.85385985322583,-1.5099183089786328
1.7951377931695691,0.055485497099419884,438.1010168074557,35.85385985322583,-1.5099183089786328
1.8025934798925671,0.055715943188637734,438.53886353430505,35.85385985322583,-1.5099183089786328
1.8137770099770638,0.056061612322464496,439.1943116768235,35.85385985322583,-1.5099183089786328
1.8224753111538947,0.05633046609321865,439.70301560346695,35.85385985322583,-1.5099183089786328
1.8404932207344726,0.056887377475495104,440.75375713456424,35.85385985322583,-1.5099183089786328
1.8504341363651364,0.05719463892778556,441.33175910290555,35.85385985322583,-1.5099183089786328
1.8591324375419667,0.0574634926985397,441.8365181473053,35.85385985322583,-1.5099183089786328
1.9051091723337867,0.05888457691538308,444.48938373654914,35.85385985322583,-1.5099183089786328
1.9175353168721163,0.05926865373074615,445.20207326803717,35.85385985322583,-1.5099183089786328
1.9212631602336152,0.059383876775355074,445.4155286007571,35.85385985322583,-1.5099183089786328
1.9262336180489472,0.0595375075015003,445.69988461840336,35.85385985322583,-1.5099183089786328
1.9336893047719448,0.05976795359071814,446.1258826770638,35.85385985322583,-1.5099183089786328
1.9349319192257781,0.05980636127225446,446.19682002893006,35.85385985322583,-1.5099183089786328
1.949221985444857,0.060248049609921986,447.0113267149708,35.85385985322583,-1.5099183089786328
1.9610268227562702,0.06061292258451691,447.6824250166446,35.85385985322583,-1.5099183089786328
1.9796660395637649,0.06118903780756152,448.7388549975368,35.85385985322583,-1.5099183089786328
1.9858791118329295,0.06138107621524305,449.09013535001594,35.85385985322583,-1.5099183089786328
2.0038970214135072,0.061937987597519506,450.10643263741497,35.85385985322583,-1.5099183089786328
2.015080551498004,0.06228365673134627,450.7354456441475,35.85385985322583,-1.5099183089786328
2.0299919249439995,0.06274454890978196,451.57201588075367,35.85385985322583,-1.5099183089786328
2.044903298389995,0.06320544108821764,452.40619294990796,35.85385985322583,-1.5099183089786328
2.054844214020659,0.0635127025405081,452.96099343771516,35.85385985322583,-1.5099183089786328
2.0560868284744918,0.0635511102220444,453.0302698229511,35.85385985322583,-1.5099183089786328
2.062921207970573,0.0637623524704941,453.4109984722134,35.85385985322583,-1.5099183089786328
2.067891665785905,0.06391598319663933,453.68758312901537,35.85385985322583,-1.5099183089786328
2.089637418727982,0.0645881176235247,454.89460529757685,35.85385985322583,-1.5099183089786328
2.094607876543314,0.06474174834966993,455.1698070869216,35.85385985322583,-1.5099183089786328
2.1076553283085597,0.06514502900580116,455.8910027384754,35.85385985322583,-1.5099183089786328
2.1343715390659685,0.06597079415883177,457.36232658675664,35.85385985322583,-1.5099183089786328
2.144933761923549,0.06629725945189038,457.9420294943485,35.85385985322583,-1.5099183089786328
2.151146834192714,0.06648929785957192,458.28251116115774,35.85385985322583,-1.5099183089786328
2.162951671504127,0.06685417083416684,458.9283715751042,35.85385985322583,-1.5099183089786328
2.192774418396118,0.06777595519103821,460.5539253918629,35.85385985322583,-1.5099183089786328
2.201472719572949,0.06804480896179237,461.0264181287828,35.85385985322583,-1.5099183089786328
2.2306741592380237,0.06894738947789558,462.60734557492304,35.85385985322583,-1.5099183089786328
2.238751153187938,0.06919703940788158,463.04319574298364,35.85385985322583,-1.5099183089786328
2.258632984449265,0.0698115623124625,464.11345315864713,35.85385985322583,-1.5099183089786328
2.2691952073068458,0.07013802760552111,464.6805326652281,35.85385985322583,-1.5099183089786328
2.281621351845175,0.07052210442088418,465.34636877441795,35.85385985322583,-1.5099183089786328
2.2847278879797575,0.07061812362472494,465.51260664164977,35.85385985322583,-1.5099183089786328
2.312065405964083,0.07146309261852371,466.9717182687567,35.85385985322583,-1.5099183089786328
2.3226276288216634,0.07178955791158233,467.53366201063216,35.85385985322583,-1.5099183089786328
2.33381115890616,0.07213522704540909,468.12757606883594,35.85385985322583,-1.5099183089786328
2.3530716829405707,0.07273054610922185,469.14783276217696,35.85385985322583,-1.5099183089786328
2.376681357563397,0.07346029205841169,470.39403769841505,35.85385985322583,-1.5099183089786328
2.378545279244147,0.07351790358071615,470.49221619534467,35.85385985322583,-1.5099183089786328
2.3835157370594784,0.07367153430686138,470.7538789392075,35.85385985322583,-1.5099183089786328
2.392214038236309,0.07394038807761552,471.2112772531966,35.85385985322583,-1.5099183089786328
2.4015336466400563,0.07422844568913783,471.70062769488754,35.85385985322583,-1.5099183089786328
2.413959791178386,0.0746125225045009,472.3519444356139,35.85385985322583,-1.5099183089786328
2.415202405632219,0.07465093018603722,472.4170041112134,35.85385985322583,-1.5099183089786328
2.4201728634475512,0.07480456091218245,472.6771123751986,35.85385985322583,-1.5099183089786328
2.427007242943632,0.07501580316063212,473.0344213181243,35.85385985322583,-1.5099183089786328
2.4363268513473795,0.07530386077215444,473.52102903996274,35.85385985322583,-1.5099183089786328
2.4531021464741247,0.07582236447289459,474.39509748940463,35.85385985322583,-1.5099183089786328
2.4555873753817905,0.0758991798359672,474.52439058266185,35.85385985322583,-1.5099183089786328
2.4593152187432894,0.07601440288057612,474.7182345769806,35.85385985322583,-1.5099183089786328
2.486031429500698,0.07684016803360673,476.10411183026173,35.85385985322583,-1.5099183089786328
2.494729730677529,0.07710902180436088,476.5540726714619,35.85385985322583,-1.5099183089786328
2.5189607125272717,0.07785797159431887,477.8043201474501,35.85385985322583,-1.5099183089786328
2.5264163992502695,0.0780884176835367,478.18806689636176,35.85385985322583,-1.5099183089786328
2.542570387150098,0.07858771754350871,479.01800630805985,35.85385985322583,-1.5099183089786328
2.549404766646179,0.07879895979195839,479.36851516977265,35.85385985322583,-1.5099183089786328
2.553753917234595,0.07893338667733547,479.5913754766632,35.85385985322583,-1.5099183089786328
2.566801368999841,0.0793366673334667,480.25906996379973,35.85385985322583,-1.5099183089786328
2.588547121941918,0.08000880176035208,481.36896013580173,35.85385985322583,-1.5099183089786328
2.5991093447994977,0.08033526705341068,481.90673711437836,35.85385985322583,-1.5099183089786328
2.6096715676570783,0.0806617323464693,482.44366245519114,35.85385985322583,-1.5099183089786328
2.6258255555569066,0.08116103220644129,483.263205982962,35.85385985322583,-1.5099183089786328
2.63576647118757,0.08146829365873175,483.7665632237703,35.85385985322583,-1.5099183089786328
2.6506778446335657,0.08192918583716743,484.52021307877476,35.85385985322583,-1.5099183089786328
2.664967910852645,0.08237087417483498,485.2409108212701,35.85385985322583,-1.5099183089786328
2.676772748164058,0.08273574714942988,485.8351337357236,35.85385985322583,-1.5099183089786328
2.686713663794722,0.08304300860172034,486.3347396945799,35.85385985322583,-1.5099183089786328
2.6916841216100535,0.08319663932786557,486.5842722856057,35.85385985322583,-1.5099183089786328
2.701003730013801,0.08348469693938788,487.05166206394154,35.85385985322583,-1.5099183089786328
2.7208855612751286,0.0840992198439688,488.0466633644326,35.85385985322583,-1.5099183089786328
2.7314477841327087,0.0844256851370274,488.5741042924386,35.85385985322583,-1.5099183089786328
2.7482230792594535,0.08494418883776755,489.4101726391508,35.85385985322583,-1.5099183089786328
2.7712114466553635,0.08565473094618924,490.5526705390514,35.85385985322583,-1.5099183089786328
2.7799097478321944,0.08592358471694339,490.9840024104627,35.85385985322583,-1.5099183089786328
2.7966850429589396,0.08644208841768354,491.81437321050606,35.85385985322583,-1.5099183089786328
2.815324259766434,0.08701820364072815,492.73473252654134,35.85385985322583,-1.5099183089786328
2.824643868170181,0.08730626125225045,493.1940208103983,35.85385985322583,-1.5099183089786328
2.85136007892759,0.08813202640528106,494.5073831852096,35.85385985322583,-1.5099183089786328
2.8557092295160054,0.08826645329065813,494.72073130987286,35.85385985322583,-1.5099183089786328
2.860058380104421,0.08840088017603522,494.9339527524728,35.85385985322583,-1.5099183089786328
2.8619223017851705,0.08845849169833968,495.025294656878,35.85385985322583,-1.5099183089786328
2.864407530692836,0.08853530706141229,495.147047780699,35.85385985322583,-1.5099183089786328
2.8737271390965833,0.08882336467293458,495.603255541981,35.85385985322583,-1.5099183089786328
2.88491066918108,0.08916903380676136,496.149943917289,35.85385985322583,-1.5099183089786328
2.8892598197694954,0.08930346069213843,496.3623216653132,35.85385985322583,-1.5099183089786328
2.89547289203866,0.08949549909981996,496.66550229714505,35.85385985322583,-1.5099183089786328
2.9010646570809087,0.08966833366673335,496.93814800507494,35.85385985322583,-1.5099183089786328
2.912869494392322,0.09003320664132827,497.5130612505962,35.85385985322583,-1.5099183089786328
2.92902348229215,0.09053250650130026,498.29831431445865,35.85385985322583,-1.5099183089786328
2.9594675364110583,0.0914734946989398,499.7736384810584,35.85385985322583,-1.5099183089786328
2.967544530360972,0.09172314462892579,500.1640560500579,35.85385985322583,-1.5099183089786328
2.9799706748993016,0.09210722144428886,500.7638902066746,35.85385985322583,-1.5099183089786328
2.983698518260801,0.09222244448889778,500.94365013132517,35.85385985322583,-1.5099183089786328
2.991775512210715,0.09247209441888378,501.3328297574469,35.85385985322583,-1.5099183089786328
3.0091721145643766,0.09300980196039209,502.16967378134,35.85385985322583,-1.5099183089786328
3.0141425723797086,0.09316343268653732,502.40842524466314,35.85385985322583,-1.5099183089786328
3.024083488010372,0.09347069413882778,502.8854680272771,35.85385985322583,-1.5099183089786328
3.048314469860115,0.09421964392878576,504.0457048323481,35.85385985322583,-1.5099183089786328
3.0570127710369457,0.09448849769953992,504.46132204008285,35.85385985322583,-1.5099183089786328
3.067574993894526,0.09481496299259852,504.9653805554305,35.85385985322583,-1.5099183089786328
3.073788066163691,0.09500700140028007,505.2615693833323,35.85385985322583,-1.5099183089786328
3.083107674567438,0.09529505901180237,505.7054152106849,35.85385985322583,-1.5099183089786328
3.0855929034751037,0.09537187437487497,505.8236856888252,35.85385985322583,-1.5099183089786328
3.092427282971185,0.09558311662332467,506.14873809962677,35.85385985322583,-1.5099183089786328
3.106096041963348,0.09600560112022405,506.7980036383694,35.85385985322583,-1.5099183089786328
3.119764800955511,0.09642808561712343,507.4461558309543,35.85385985322583,-1.5099183089786328
3.127220487678508,0.09665853170634127,507.7992265545969,35.85385985322583,-1.5099183089786328
3.1328122527207567,0.09683136627325466,508.0638141985819,35.85385985322583,-1.5099183089786328
3.1377827105360887,0.09698499699939989,508.29884863250464,35.85385985322583,-1.5099183089786328
3.151451469528251,0.09740748149629927,508.94444582278686,35.85385985322583,-1.5099183089786328
3.156421927343583,0.0975611122224445,509.1789375620956,35.85385985322583,-1.5099183089786328
3.157664541797416,0.0975995199039808,509.23753798990714,35.85385985322583,-1.5099183089786328
3.16574153574733,0.0978491698339668,509.6182217868554,35.85385985322583,-1.5099183089786328
3.1850020597817412,0.09844448889777956,510.52448085073587,35.85385985322583,-1.5099183089786328
3.196185589866238,0.09879015803160633,511.04971496811515,35.85385985322583,-1.5099183089786328
3.206126505496902,0.09909741948389679,511.515988328352,35.85385985322583,-1.5099183089786328
3.22228049339673,0.09959671934386878,512.2724817877644,35.85385985322583,-1.5099183089786328
3.2253870295313125,0.09969273854770955,512.4177915794186,35.85385985322583,-1.5099183089786328