File: datasets/aisi_316_L/data/M1/train_76.csv
Time(s),Strain(%),Stress(MPa),Temp(C),Log_SR(s-1)
0.0,0.0,0.0,277.6161705776783,4.420068643168271
6.08206895318721e-10,1.6e-05,2.872703,277.6161705776783,4.420068643168271
1.0643620668077617e-09,2.8e-05,5.02723025,277.6161705776783,4.420068643168271
1.6117482725946107e-09,4.24e-05,7.61266295,277.6161705776783,4.420068643168271
2.524058615572692e-09,6.64e-05,11.921717450000001,277.6161705776783,4.420068643168271
3.193086200423285e-09,8.4e-05,15.08169075,277.6161705776783,4.420068643168271
4.105396543401367e-09,0.000108,19.39074525,277.6161705776783,4.420068643168271
4.713603438720088e-09,0.000124,22.26344825,277.6161705776783,4.420068643168271
5.473862057868489e-09,0.000144,25.854327,277.6161705776783,4.420068643168271
5.869196539825657e-09,0.00015439999999999999,27.721583949999996,277.6161705776783,4.420068643168271
7.055199985697163e-09,0.00018559999999999998,33.3233548,277.6161705776783,4.420068643168271
7.511355157186204e-09,0.00019759999999999998,35.47788205,277.6161705776783,4.420068643168271
8.727768947823647e-09,0.0002296,41.22328805,277.6161705776783,4.420068643168271
8.910231016419261e-09,0.00023439999999999998,42.085098949999995,277.6161705776783,4.420068643168271
9.457617222206112e-09,0.0002488,44.670531649999994,277.6161705776783,4.420068643168271
9.700899980333599e-09,0.00025519999999999997,45.81961284999999,277.6161705776783,4.420068643168271
1.0400337909950128e-08,0.0002736,49.1232213,277.6161705776783,4.420068643168271
1.1343058597694146e-08,0.0002984,53.57591095,277.6161705776783,4.420068643168271
1.1677572390119443e-08,0.0003072,55.155897599999996,277.6161705776783,4.420068643168271
1.3015627559820629e-08,0.0003424,61.4758442,277.6161705776783,4.420068643168271
1.331973100747999e-08,0.0003504,62.9121957,277.6161705776783,4.420068643168271
1.3441372386543734e-08,0.0003536,63.4867363,277.6161705776783,4.420068643168271
1.3836706868500902e-08,0.00036399999999999996,65.35399324999999,277.6161705776783,4.420068643168271
1.41712206609262e-08,0.0003728,66.9339799,277.6161705776783,4.420068643168271
1.4870658590542728e-08,0.00039119999999999997,70.23758835,277.6161705776783,4.420068643168271
1.49314792800746e-08,0.0003928,70.52485865,277.6161705776783,4.420068643168271
1.5265993072499896e-08,0.0004016,72.1048453,277.6161705776783,4.420068643168271
1.633035513930766e-08,0.0004296,77.13207555,277.6161705776783,4.420068643168271
1.67865103107967e-08,0.0004416,79.2866028,277.6161705776783,4.420068643168271
1.730348617181761e-08,0.0004552,81.72840035,277.6161705776783,4.420068643168271
1.815497582526382e-08,0.00047759999999999995,85.75018454999999,277.6161705776783,4.420068643168271
1.8519899962455054e-08,0.00048719999999999997,87.47380634999999,277.6161705776783,4.420068643168271
1.924974823683752e-08,0.0005064,90.92104995,277.6161705776783,4.420068643168271
1.976672409785843e-08,0.00052,93.36284749999999,277.6161705776783,4.420068643168271
2.0648624096070577e-08,0.0005432,97.52826685,277.6161705776783,4.420068643168271
2.095272754372994e-08,0.0005512,98.96461835,277.6161705776783,4.420068643168271
2.1256830991389297e-08,0.0005591999999999999,100.40096984999998,277.6161705776783,4.420068643168271
2.1743396507644278e-08,0.000572,102.69913225,277.6161705776783,4.420068643168271
2.20170896105377e-08,0.0005792,103.9918486,277.6161705776783,4.420068643168271
2.2351603402962997e-08,0.000588,105.57183524999999,277.6161705776783,4.420068643168271
2.3081451677345462e-08,0.0006072,109.01907885,277.6161705776783,4.420068643168271
2.3628837883132307e-08,0.0006215999999999999,111.60451154999998,277.6161705776783,4.420068643168271
2.3993762020323543e-08,0.0006312,113.32813334999999,277.6161705776783,4.420068643168271
2.4754020639471945e-08,0.0006512,116.9190121,277.6161705776783,4.420068643168271
2.578797236151377e-08,0.0006784,121.8026072,277.6161705776783,4.420068643168271
2.6335358567300616e-08,0.0006927999999999999,124.38803989999998,277.6161705776783,4.420068643168271
2.679151373878966e-08,0.0007048,126.54256715,277.6161705776783,4.420068643168271
2.7217258565512764e-08,0.000716,128.55345925,277.6161705776783,4.420068643168271
2.7308489599810575e-08,0.0007184,128.98436470000001,277.6161705776783,4.420068643168271
2.8585724079979885e-08,0.000752,135.017041,277.6161705776783,4.420068643168271
2.925475166483048e-08,0.0007696,138.1770143,277.6161705776783,4.420068643168271
3.104896200602071e-08,0.0008168,146.65148815,277.6161705776783,4.420068643168271
3.174839993563723e-08,0.0008351999999999999,149.9550966,277.6161705776783,4.420068643168271
3.278235165767906e-08,0.0008623999999999999,154.8386917,277.6161705776783,4.420068643168271
3.311686545010436e-08,0.0008711999999999999,156.41867835,277.6161705776783,4.420068643168271
3.332973786346591e-08,0.0008768,157.42412439999998,277.6161705776783,4.420068643168271
3.415081717214618e-08,0.0008983999999999999,161.30227345,277.6161705776783,4.420068643168271
3.436368958550774e-08,0.000904,162.3077195,277.6161705776783,4.420068643168271
3.503271717035833e-08,0.0009216,165.46769279999998,277.6161705776783,4.420068643168271
3.5549693031379244e-08,0.0009352,167.90949035,277.6161705776783,4.420068643168271
3.697897923537824e-08,0.0009728,174.6603424,277.6161705776783,4.420068643168271
3.7800058544058506e-08,0.0009943999999999999,178.53849144999998,277.6161705776783,4.420068643168271
3.807375164695194e-08,0.0010016,179.83120780000002,277.6161705776783,4.420068643168271
3.895565164516408e-08,0.0010248,183.99662715,277.6161705776783,4.420068643168271
3.9472627506184986e-08,0.0010383999999999999,186.43842469999998,277.6161705776783,4.420068643168271
4.087150336541805e-08,0.0010752,193.04564159999998,277.6161705776783,4.420068643168271
4.1114786123545545e-08,0.0010816,194.19472280000002,277.6161705776783,4.420068643168271
4.157094129503458e-08,0.0010936,196.34925005,277.6161705776783,4.420068643168271
4.236161025894892e-08,0.0011144,200.08376395,277.6161705776783,4.420068643168271
4.254407232754453e-08,0.0011191999999999999,200.94557484999999,277.6161705776783,4.420068643168271
4.306104818856545e-08,0.0011328,203.3873724,277.6161705776783,4.420068643168271
4.531141370124471e-08,0.001192,207.09496205532653,277.6161705776783,4.420068643168271
4.5706748183201884e-08,0.0012024,207.15985273479978,277.6161705776783,4.420068643168271
4.7957113695881146e-08,0.0012615999999999999,207.52514413162046,277.6161705776783,4.420068643168271
4.880860334932736e-08,0.001284,207.66161119623138,277.6161705776783,4.420068643168271
4.929516886558233e-08,0.0012967999999999999,207.73917546364498,277.6161705776783,4.420068643168271
4.981214472660325e-08,0.0013104,207.8212610561218,277.6161705776783,4.420068643168271
5.011624817426261e-08,0.0013184,207.86939149967927,277.6161705776783,4.420068643168271
5.042035162192197e-08,0.0013264,207.91740817614246,277.6161705776783,4.420068643168271
5.054199300098572e-08,0.0013296,207.9365832058,277.6161705776783,4.420068643168271
5.172799644685722e-08,0.0013608,208.12260603907274,277.6161705776783,4.420068643168271
5.2062510239282517e-08,0.0013696,208.17477230957348,277.6161705776783,4.420068643168271
5.273153782413311e-08,0.0013871999999999999,208.27871433428982,277.6161705776783,4.420068643168271
5.3643848167111195e-08,0.0014112,208.41962837407013,277.6161705776783,4.420068643168271
5.4404106786259587e-08,0.0014311999999999999,208.53634417891175,277.6161705776783,4.420068643168271
5.5073134371110184e-08,0.0014487999999999999,208.63852891311842,277.6161705776783,4.420068643168271
5.565093092166297e-08,0.001464,208.72639038074354,277.6161705776783,4.420068643168271
5.628954816174763e-08,0.0014808,208.82308754802432,277.6161705776783,4.420068643168271
5.6350368851279504e-08,0.0014824,208.83227443079042,277.6161705776783,4.420068643168271
5.683693436753448e-08,0.0014952,208.90563079069955,277.6161705776783,4.420068643168271
5.8144579192469725e-08,0.0015295999999999999,209.10157244722794,277.6161705776783,4.420068643168271
5.875278608778844e-08,0.0015455999999999998,209.19212180799434,277.6161705776783,4.420068643168271
5.933058263834124e-08,0.0015608,209.27780568454298,277.6161705776783,4.420068643168271
5.954345505170278e-08,0.0015664,209.30929131566583,277.6161705776783,4.420068643168271
6.018207229178744e-08,0.0015831999999999999,209.40348585967627,277.6161705776783,4.420068643168271
6.075986884234022e-08,0.0015983999999999998,209.4883741261363,277.6161705776783,4.420068643168271
6.109438263476552e-08,0.0016072,209.53737606746822,277.6161705776783,4.420068643168271
6.194587228821174e-08,0.0016296,209.66163844726395,277.6161705776783,4.420068643168271
6.218915504633922e-08,0.0016359999999999999,209.6970193994186,277.6161705776783,4.420068643168271
6.228038608063703e-08,0.0016384,209.71027333465324,277.6161705776783,4.420068643168271
6.35272102160404e-08,0.0016711999999999999,209.89065824561544,277.6161705776783,4.420068643168271
6.404418607706132e-08,0.0016848,209.96504642814486,277.6161705776783,4.420068643168271
6.532142055723064e-08,0.0017184,210.14783201385606,277.6161705776783,4.420068643168271
6.586880676301747e-08,0.0017327999999999998,210.2257413999122,277.6161705776783,4.420068643168271
6.644660331357028e-08,0.001748,210.3077056472911,277.6161705776783,4.420068643168271
6.702439986412305e-08,0.0017632,210.38939239559022,277.6161705776783,4.420068643168271
6.729809296701648e-08,0.0017703999999999999,210.4279902208216,277.6161705776783,4.420068643168271
6.763260675944177e-08,0.0017791999999999999,210.47508230349922,277.6161705776783,4.420068643168271
6.796712055186707e-08,0.0017879999999999999,210.52208363469592,277.6161705776783,4.420068643168271
6.851450675765392e-08,0.0018024,210.598800769416,277.6161705776783,4.420068643168271
6.860573779195173e-08,0.0018047999999999999,210.61156368300925,277.6161705776783,4.420068643168271
6.915312399773858e-08,0.0018192,210.6880026262831,277.6161705776783,4.420068643168271
6.951804813492981e-08,0.0018288,210.738830866978,277.6161705776783,4.420068643168271
6.98525619273551e-08,0.0018376,210.78533208359872,277.6161705776783,4.420068643168271
7.146431019994972e-08,0.00188,211.00817738436305,277.6161705776783,4.420068643168271
7.23766205429278e-08,0.0019039999999999999,211.13344731501553,277.6161705776783,4.420068643168271
7.277195502488496e-08,0.0019144,211.18753953837634,277.6161705776783,4.420068643168271
7.414042053935208e-08,0.0019504,211.3739032376644,277.6161705776783,4.420068643168271
7.490067915850049e-08,0.0019703999999999998,211.4768588069603,277.6161705776783,4.420068643168271
7.526560329569172e-08,0.00198,211.5261326462944,277.6161705776783,4.420068643168271
7.651242743109511e-08,0.0020128,211.69378636895638,277.6161705776783,4.420068643168271
7.730309639500944e-08,0.0020336,211.79955149510732,277.6161705776783,4.420068643168271
7.797212397986004e-08,0.0020512,211.88871594651528,277.6161705776783,4.420068643168271
7.815458604845565e-08,0.002056,211.9129816767722,277.6161705776783,4.420068643168271
7.83674584618172e-08,0.0020616,211.9412637886341,277.6161705776783,4.420068643168271
7.900607570190185e-08,0.0020783999999999998,212.02593090165786,277.6161705776783,4.420068643168271
8.067864466402834e-08,0.0021224,212.24642270834113,277.6161705776783,4.420068643168271
8.134767224887894e-08,0.00214,212.3341193887371,277.6161705776783,4.420068643168271
8.165177569653829e-08,0.0021479999999999997,212.37388848457556,277.6161705776783,4.420068643168271
8.213834121279327e-08,0.0021608,212.43739909712886,277.6161705776783,4.420068643168271
8.277695845287792e-08,0.0021776,212.52053455367542,277.6161705776783,4.420068643168271
8.341557569296258e-08,0.0021944,212.6034202438215,277.6161705776783,4.420068643168271
8.365885845109007e-08,0.0022007999999999997,212.63493060225898,277.6161705776783,4.420068643168271
8.411501362257912e-08,0.0022128,212.69391636967822,277.6161705776783,4.420068643168271
8.444952741500441e-08,0.0022216,212.73709334204847,277.6161705776783,4.420068643168271
8.539224810274843e-08,0.0022464,212.85841650169965,277.6161705776783,4.420068643168271
8.569635155040778e-08,0.0022543999999999997,212.89744142685436,277.6161705776783,4.420068643168271
8.6547841203854e-08,0.0022768,213.006424932475,277.6161705776783,4.420068643168271
8.733851016776833e-08,0.0022976,213.10725006210566,277.6161705776783,4.420068643168271
8.746015154683208e-08,0.0023008,213.1227299682369,277.6161705776783,4.420068643168271
8.758179292589583e-08,0.002304,213.1382014800307,277.6161705776783,4.420068643168271
8.764261361542771e-08,0.0023056,213.145934093116,277.6161705776783,4.420068643168271
8.84941032688739e-08,0.0023279999999999998,213.25397187553878,277.6161705776783,4.420068643168271
8.901107912989483e-08,0.0023416,213.31936846842848,277.6161705776783,4.420068643168271
8.95888756804476e-08,0.0023568,213.3922837336772,277.6161705776783,4.420068643168271
9.00146205071707e-08,0.002368,213.44589346889657,277.6161705776783,4.420068643168271
9.02579032652982e-08,0.0023744,213.47648320364416,277.6161705776783,4.420068643168271
9.117021360827627e-08,0.0023983999999999998,213.59090944391923,277.6161705776783,4.420068643168271
9.123103429780814e-08,0.0024,213.59852194432452,277.6161705776783,4.420068643168271
9.150472740070158e-08,0.0024072,213.63275373253921,277.6161705776783,4.420068643168271
9.211293429602029e-08,0.0024232,213.7086817329055,277.6161705776783,4.420068643168271
9.241703774367964e-08,0.0024311999999999997,213.74657239395398,277.6161705776783,4.420068643168271
9.351181015525335e-08,0.00246,213.88257799387543,277.6161705776783,4.420068643168271
9.387673429244457e-08,0.0024695999999999997,213.92777501197304,277.6161705776783,4.420068643168271
9.424165842963582e-08,0.0024792,213.97290356151737,277.6161705776783,4.420068643168271
9.451535153252923e-08,0.0024863999999999997,214.00670526283943,277.6161705776783,4.420068643168271
9.503232739355016e-08,0.0025,214.07044895021681,277.6161705776783,4.420068643168271
9.551889290980513e-08,0.0025128,214.13031958114922,277.6161705776783,4.420068643168271
9.573176532316669e-08,0.0025184,214.156475568302,277.6161705776783,4.420068643168271
9.618792049465573e-08,0.0025304,214.21244785360327,277.6161705776783,4.420068643168271
9.716105152716566e-08,0.0025559999999999997,214.3315105782532,277.6161705776783,4.420068643168271
9.871197911022841e-08,0.0025968,214.5203100167056,277.6161705776783,4.420068643168271
9.919854462648338e-08,0.0026095999999999997,214.57930234352241,277.6161705776783,4.420068643168271
9.96242894532065e-08,0.0026208,214.63082812021014,277.6161705776783,4.420068643168271
9.983716186656805e-08,0.0026264,214.65655879983257,277.6161705776783,4.420068643168271
1.005670101409505e-07,0.0026455999999999997,214.74461628922904,277.6161705776783,4.420068643168271
1.00810292899078e-07,0.002652,214.77391335419773,277.6161705776783,4.420068643168271
1.0126644807056704e-07,0.0026639999999999997,214.8287711386136,277.6161705776783,4.420068643168271
1.0205711703448137e-07,0.0026847999999999998,214.92363021786423,277.6161705776783,4.420068643168271
1.02239579103077e-07,0.0026896,214.94548002111011,277.6161705776783,4.420068643168271
1.0303024806699134e-07,0.0027104,215.03998731056632,277.6161705776783,4.420068643168271
1.0397296875473534e-07,0.0027351999999999997,215.1523002034348,277.6161705776783,4.420068643168271
1.0491568944247937e-07,0.00276,215.2642166391307,277.6161705776783,4.420068643168271
1.05098151511075e-07,0.0027648,215.28583251137215,277.6161705776783,4.420068643168271
1.0601046185405306e-07,0.0027887999999999997,215.39369311304935,277.6161705776783,4.420068643168271
1.0616251357788275e-07,0.0027928,215.41163462634273,277.6161705776783,4.420068643168271
1.0661866874937179e-07,0.0028048,215.4653991320319,277.6161705776783,4.420068643168271
1.0835205840103015e-07,0.0028504,215.6688912738004,277.6161705776783,4.420068643168271
1.0871698253822137e-07,0.0028599999999999997,215.7115694992853,277.6161705776783,4.420068643168271
1.092339583992423e-07,0.0028736,215.77193480481608,277.6161705776783,4.420068643168271
1.0938601012307196e-07,0.0028775999999999997,215.78966808857172,277.6161705776783,4.420068643168271
1.1102816874043252e-07,0.0029208,215.98057897518805,277.6161705776783,4.420068643168271
1.111802204642622e-07,0.0029248,215.99820001853504,277.6161705776783,4.420068643168271
1.118492480491128e-07,0.0029424,216.0756212240553,277.6161705776783,4.420068643168271
1.1245745494443151e-07,0.0029584,216.14584755498626,277.6161705776783,4.420068643168271
1.1294402046068648e-07,0.0029712,216.20192202842014,277.6161705776783,4.420068643168271
1.1413002390655798e-07,0.0030023999999999997,216.3382103135922,277.6161705776783,4.420068643168271
1.15072744594302e-07,0.0030272,216.44614841765048,277.6161705776783,4.420068643168271
1.1537684804196138e-07,0.0030352,216.4808935221862,277.6161705776783,4.420068643168271
1.1555931011055699e-07,0.0030399999999999997,216.50172344172532,277.6161705776783,4.420068643168271
1.1741434114127909e-07,0.0030888,216.7127712474673,277.6161705776783,4.420068643168271
1.1799213769183188e-07,0.003104,216.7782413211547,277.6161705776783,4.420068643168271
1.1917814113770338e-07,0.0031352,216.91223683485546,277.6161705776783,4.420068643168271
1.1963429630919242e-07,0.0031471999999999997,216.96363497070223,277.6161705776783,4.420068643168271
1.2048578596263862e-07,0.0031696,217.0593741254675,277.6161705776783,4.420068643168271
1.2103317216842547e-07,0.0031839999999999998,217.12078141113815,277.6161705776783,4.420068643168271
1.2118522389225516e-07,0.003188,217.1378197563913,277.6161705776783,4.420068643168271
1.214893273399145e-07,0.003196,217.17187145514768,277.6161705776783,4.420068643168271
1.2215835492476512e-07,0.0032136,217.24666839990428,277.6161705776783,4.420068643168271
1.2304025492297725e-07,0.0032367999999999997,217.3450207307885,277.6161705776783,4.420068643168271
1.2334435837063663e-07,0.0032448,217.3788715306671,277.6161705776783,4.420068643168271
1.2364846181829598e-07,0.0032527999999999997,217.4126897973038,277.6161705776783,4.420068643168271
1.2377010319735971e-07,0.0032559999999999998,217.42620801957364,277.6161705776783,4.420068643168271
1.2410461698978502e-07,0.0032648,217.46335644042497,277.6161705776783,4.420068643168271
1.244391307822103e-07,0.0032735999999999998,217.5004658308375,277.6161705776783,4.420068643168271
1.2474323422986968e-07,0.0032816,217.53416789358818,277.6161705776783,4.420068643168271
1.2541226181472026e-07,0.0032992,217.60819984807446,277.6161705776783,4.420068643168271
1.257771859519115e-07,0.0033087999999999998,217.64851598941658,277.6161705776783,4.420068643168271
1.2617252043386868e-07,0.0033192,217.69214036438598,277.6161705776783,4.420068643168271
1.2650703422629396e-07,0.003328,217.72901167597388,277.6161705776783,4.420068643168271
1.273889342245061e-07,0.0033512,217.82603605686305,277.6161705776783,4.420068643168271
1.277234480169314e-07,0.0033599999999999997,217.86276983727265,277.6161705776783,4.420068643168271
1.2814919284365453e-07,0.0033712,217.90946770116378,277.6161705776783,4.420068643168271
1.293960169790579e-07,0.003404,218.04587892121523,277.6161705776783,4.420068643168271
1.3088612387258877e-07,0.0034432,218.20823637602635,277.6161705776783,4.420068643168271
1.316767928365031e-07,0.0034639999999999996,218.2940924163972,277.6161705776783,4.420068643168271
1.325282824899493e-07,0.0034863999999999997,218.38632822529237,277.6161705776783,4.420068643168271
1.327715652480768e-07,0.0034928,218.41263882592372,277.6161705776783,4.420068643168271
1.3398797903871422e-07,0.0035248,218.54391085341368,277.6161705776783,4.420068643168271
1.3471782731309669e-07,0.003544,218.62245099034,277.6161705776783,4.420068643168271
1.354780859322451e-07,0.003564,218.70408737615293,277.6161705776783,4.420068643168271
1.3654244799905285e-07,0.0035919999999999997,218.81807879498334,277.6161705776783,4.420068643168271
1.370898342048397e-07,0.0036063999999999996,218.87656798069946,277.6161705776783,4.420068643168271
1.3791091351351997e-07,0.0036279999999999997,218.96413127165698,277.6161705776783,4.420068643168271
1.3806296523734966e-07,0.003632,218.98032435972303,277.6161705776783,4.420068643168271
1.3827583765071123e-07,0.0036376,219.00298300319994,277.6161705776783,4.420068643168271
1.384278893745409e-07,0.0036416,219.0191594202657,277.6161705776783,4.420068643168271
1.3873199282220024e-07,0.0036496,219.05149148029616,277.6161705776783,4.420068643168271
1.390969169593915e-07,0.0036592,219.0902534900933,277.6161705776783,4.420068643168271
1.3946184109658273e-07,0.0036688,219.12897585982034,277.6161705776783,4.420068643168271
1.3988758592330582e-07,0.0036799999999999997,219.17410204939065,277.6161705776783,4.420068643168271
1.407998962662839e-07,0.003704,219.27062105847043,277.6161705776783,4.420068643168271
1.4277656867606975e-07,0.003756,219.4789128062205,277.6161705776783,4.420068643168271
1.4286779971036756e-07,0.0037584,219.48849902688372,277.6161705776783,4.420068643168271
1.434760066056863e-07,0.0037744,219.5523462636058,277.6161705776783,4.420068643168271
1.4390175143240938e-07,0.0037855999999999996,219.59697653884382,277.6161705776783,4.420068643168271
1.4460118936202591e-07,0.0038039999999999997,219.67018607312372,277.6161705776783,4.420068643168271
1.4481406177538746e-07,0.0038096,219.69243980662688,277.6161705776783,4.420068643168271
1.4545267901547211e-07,0.0038263999999999998,219.75912458614587,277.6161705776783,4.420068643168271
1.4600006522125896e-07,0.0038407999999999997,219.81619213749093,277.6161705776783,4.420068643168271
1.4624334797938646e-07,0.0038472,219.8415287028725,277.6161705776783,4.420068643168271
1.471860686671305e-07,0.003872,219.9395530250819,277.6161705776783,4.420068643168271
1.4800714797581074e-07,0.0038935999999999997,220.0247297142322,277.6161705776783,4.420068643168271
1.4840248245776793e-07,0.003904,220.06567497053945,277.6161705776783,4.420068643168271
1.4852412383683166e-07,0.0039071999999999996,220.07826494983826,277.6161705776783,4.420068643168271
1.4922356176644817e-07,0.0039256,220.15057944380825,277.6161705776783,4.420068643168271
1.4943643417980977e-07,0.0039312,220.17256194884487,277.6161705776783,4.420068643168271
1.4983176866176693e-07,0.0039416,220.2133542278194,277.6161705776783,4.420068643168271
1.5043997555708563e-07,0.0039575999999999995,220.27602971052272,277.6161705776783,4.420068643168271
1.5083531003904282e-07,0.003968,220.31671578830174,277.6161705776783,4.420068643168271
1.5168679969248902e-07,0.0039904,220.40420635670102,277.6161705776783,4.420068643168271
1.520213134849143e-07,0.0039992,220.4385252213578,277.6161705776783,4.420068643168271
1.5643168946910293e-07,0.004115223044608922,220.88828100324213,277.6161705776783,4.420068643168271
1.6227164365499985e-07,0.004268853770754151,221.4762828224575,277.6161705776783,4.420068643168271
1.8636145467182457e-07,0.004902580516103221,223.81929275487119,277.6161705776783,4.420068643168271
1.9512138595066993e-07,0.005133026605321065,224.6415788930939,277.6161705776783,4.420068643168271
2.0096134013656682e-07,0.005286657331466294,225.18178351795967,277.6161705776783,4.420068643168271
2.1556122560130904e-07,0.005670734146829366,226.5061722592631,277.6161705776783,4.420068643168271
2.34541076705474e-07,0.00617003400680136,228.1766783538666,277.6161705776783,4.420068643168271
2.520609392631647e-07,0.006630926185237048,229.6724337932734,277.6161705776783,4.420068643168271
2.571708991758245e-07,0.006765353070614123,230.10098350688563,277.6161705776783,4.420068643168271
2.6447084190819563e-07,0.006957391478295659,230.70748064515394,277.6161705776783,4.420068643168271
2.754207560067523e-07,0.007245449089817963,231.605124624482,277.6161705776783,4.420068643168271
2.790707273729378e-07,0.007341468293658731,231.90123183526205,277.6161705776783,4.420068643168271
2.878306586517832e-07,0.007571914382876575,232.60579342899442,277.6161705776783,4.420068643168271
3.097304868488966e-07,0.008148029605921184,234.3315564053226,277.6161705776783,4.420068643168271
3.2433037231363885e-07,0.008532106421284257,235.45568505737688,277.6161705776783,4.420068643168271
3.2725034940658727e-07,0.008608921784356871,235.67812329891004,277.6161705776783,4.420068643168271
3.498801718769378e-07,0.009204240848169634,237.37652175874453,277.6161705776783,4.420068643168271
3.8126992562613365e-07,0.01003000600120024,239.66303940287966,277.6161705776783,4.420068643168271
3.863798855387934e-07,0.010164432886577316,240.02819875958022,277.6161705776783,4.420068643168271
4.1411966792180374e-07,0.010894178835767154,241.97856509192357,277.6161705776783,4.420068643168271
4.360194961189171e-07,0.011470294058811763,243.48254651576357,277.6161705776783,4.420068643168271
4.403994617583398e-07,0.011585517103420685,243.77977534088274,277.6161705776783,4.420068643168271
4.571893300427933e-07,0.012027205441088217,244.90862902607086,277.6161705776783,4.420068643168271
4.6302928422869025e-07,0.012180836167233446,245.29746850634922,277.6161705776783,4.420068643168271
4.936890437046489e-07,0.012987397479495899,247.3083204192875,277.6161705776783,4.420068643168271
5.170488604482366e-07,0.013601920384076815,248.80786087875612,277.6161705776783,4.420068643168271
5.447886428312468e-07,0.014331666333266654,250.55466424948742,277.6161705776783,4.420068643168271
5.827483450395767e-07,0.015330266053210643,252.88980523173475,277.6161705776783,4.420068643168271
5.922382705916592e-07,0.01557991598319664,253.46422497087718,277.6161705776783,4.420068643168271
5.995382133240303e-07,0.015771954390878175,253.90364695196277,277.6161705776783,4.420068643168271
6.214380415211436e-07,0.016348069613922784,255.209560257319,277.6161705776783,4.420068643168271
6.272779957070406e-07,0.016501700340068013,255.55475668161844,277.6161705776783,4.420068643168271
6.411478868985456e-07,0.01686657331466293,256.369613282038,277.6161705776783,4.420068643168271
6.462578468112055e-07,0.017001000200040008,256.66808687878205,277.6161705776783,4.420068643168271
6.484478296309169e-07,0.01705861172234447,256.7957222185295,277.6161705776783,4.420068643168271
6.506378124506282e-07,0.01711622324464893,256.9231895555938,277.6161705776783,4.420068643168271
6.557477723632879e-07,0.017250650130026003,257.2199643989396,277.6161705776783,4.420068643168271
6.674276807350817e-07,0.01755791158231646,257.89494069648043,277.6161705776783,4.420068643168271
6.798375833801127e-07,0.017884376875375075,258.60707485664636,277.6161705776783,4.420068643168271
6.856775375660095e-07,0.018038007601520304,258.94044088919003,277.6161705776783,4.420068643168271
6.995474287575147e-07,0.01840288057611522,259.7277783150234,277.6161705776783,4.420068643168271
7.061173772166487e-07,0.018575715143028606,260.0986005421,277.6161705776783,4.420068643168271
7.119573314025457e-07,0.018729345869173835,260.42709215161716,277.6161705776783,4.420068643168271
7.250972283208137e-07,0.0190750150030006,261.16238018434564,277.6161705776783,4.420068643168271
7.462670622446899e-07,0.019631926385277054,262.3361731995163,277.6161705776783,4.420068643168271
7.842267644530197e-07,0.020630526105221043,264.4088875375345,277.6161705776783,4.420068643168271
7.871467415459682e-07,0.020707341468293658,264.5666876951169,277.6161705776783,4.420068643168271
8.178065010219269e-07,0.02151390278055611,266.2100357829248,277.6161705776783,4.420068643168271
8.192664895684012e-07,0.021552310462092418,266.2876854811174,277.6161705776783,4.420068643168271
8.448162891317002e-07,0.022224444888977797,267.6379391186094,277.6161705776783,4.420068643168271
8.667161173288135e-07,0.022800560112022406,268.7826709572122,277.6161705776783,4.420068643168271
8.805860085203186e-07,0.023165433086617324,269.5018364378567,277.6161705776783,4.420068643168271
9.010258481709578e-07,0.023703140628125625,270.55365873148276,277.6161705776783,4.420068643168271
9.251156591877825e-07,0.024336867373474694,271.7814332728092,277.6161705776783,4.420068643168271
9.703753041284835e-07,0.02552750550110022,274.05495378754836,277.6161705776783,4.420068643168271
9.769452525876176e-07,0.025700340068013604,274.38151051356994,277.6161705776783,4.420068643168271
9.908151437791226e-07,0.02606521304260852,275.06810872606695,277.6161705776783,4.420068643168271
1.0039550406973906e-06,0.026410882176435287,275.7151206302198,277.6161705776783,4.420068643168271
1.0112549834297619e-06,0.026602920584116823,276.07314441078796,277.6161705776783,4.420068643168271
1.0214749032550814e-06,0.026871774354870974,276.5726889747368,277.6161705776783,4.420068643168271
1.0368047829930607e-06,0.027275055011002202,277.3183664803396,277.6161705776783,4.420068643168271
1.0411847486324836e-06,0.027390278055611124,277.5306258148171,277.6161705776783,4.420068643168271
1.0594346054634113e-06,0.027870374074814963,278.4113172668398,277.6161705776783,4.420068643168271
1.0784144565675763e-06,0.028369673934786958,279.320982669415,277.6161705776783,4.420068643168271
1.0871743878464215e-06,0.0286001200240048,279.7387202316165,277.6161705776783,4.420068643168271
1.0930143420323184e-06,0.02875375075015003,280.0164828870437,277.6161705776783,4.420068643168271
1.1061542389505864e-06,0.029099419883976796,280.63934134231187,277.6161705776783,4.420068643168271
1.1171041530491432e-06,0.0293874774954991,281.1561888379337,277.6161705776783,4.420068643168271
1.12294410723504e-06,0.029541108221644328,281.43103277401815,277.6161705776783,4.420068643168271
1.1331640270603596e-06,0.02980996199239848,281.9106720707248,277.6161705776783,4.420068643168271
1.1448439354321533e-06,0.030117223444688937,282.4567702813977,277.6161705776783,4.420068643168271
1.1470339182518648e-06,0.0301748349669934,282.5589213466922,277.6161705776783,4.420068643168271
1.1528738724377618e-06,0.03032846569313863,282.8309530097428,277.6161705776783,4.420068643168271
1.1594438208968957e-06,0.03050130026005201,283.1363470674433,277.6161705776783,4.420068643168271
1.1762336891813493e-06,0.030942988597719545,283.9137481175224,277.6161705776783,4.420068643168271
1.192293563192566e-06,0.03136547309461893,284.653309450191,277.6161705776783,4.420068643168271
1.2090834314770194e-06,0.03180716143228646,285.4223451510153,277.6161705776783,4.420068643168271
1.2375532081332668e-06,0.03255611122224445,286.7169108838318,277.6161705776783,4.420068643168271
1.2397431909529779e-06,0.032613722744548906,286.8160091733953,277.6161705776783,4.420068643168271
1.2433931623191637e-06,0.03270974194838968,286.9810214095489,277.6161705776783,4.420068643168271
1.26456299624304e-06,0.033266653330666134,287.93439320392207,277.6161705776783,4.420068643168271
1.2718629389754112e-06,0.03345869173834767,288.26169618045526,277.6161705776783,4.420068643168271
1.2952227557189988e-06,0.03407321464292859,289.3041762642576,277.6161705776783,4.420068643168271
1.3061726698175553e-06,0.03436127225445089,289.79031222839933,277.6161705776783,4.420068643168271
1.3185825724625863e-06,0.034687737547509506,290.3393490149488,277.6161705776783,4.420068643168271
1.3273425037414315e-06,0.03491818363672734,290.72569172040863,277.6161705776783,4.420068643168271
1.3346424464738028e-06,0.03511022204440888,291.0468849592808,277.6161705776783,4.420068643168271
1.3616522345835762e-06,0.03582076415283057,292.2293891141007,277.6161705776783,4.420068643168271
1.3755221257750808e-06,0.03618563712742548,292.8330637514758,277.6161705776783,4.420068643168271
1.3966919596989575e-06,0.03674254850970195,293.7499049697297,277.6161705776783,4.420068643168271
1.4032619081580911e-06,0.03691538307661532,294.0333378080977,277.6161705776783,4.420068643168271
1.4164018050763592e-06,0.03726105221044208,294.59865564213186,277.6161705776783,4.420068643168271
1.420781770715782e-06,0.03737627525505101,294.786639918746,277.6161705776783,4.420068643168271
1.4302716962678643e-06,0.037625925185037004,295.19316559224256,277.6161705776783,4.420068643168271
1.4397616218199467e-06,0.037875575115023,295.59864066218694,277.6161705776783,4.420068643168271
1.4456015760058437e-06,0.03802920584116823,295.84764576060326,277.6161705776783,4.420068643168271
1.4485215530987923e-06,0.03810602120424085,295.9720011700497,277.6161705776783,4.420068643168271
1.453631513011452e-06,0.03824044808961792,296.18938814598926,277.6161705776783,4.420068643168271
1.46677140992972e-06,0.03858611722344468,296.7470191335427,277.6161705776783,4.420068643168271
1.470421381295906e-06,0.03868213642728546,296.9015704433746,277.6161705776783,4.420068643168271
1.5040011178648126e-06,0.03956551310262052,298.31649107279236,277.6161705776783,4.420068643168271
1.5098410720507096e-06,0.03971914382876575,298.56130122179064,277.6161705776783,4.420068643168271
1.5383108487069573e-06,0.04046809361872375,299.749502553739,277.6161705776783,4.420068643168271
1.5609406711773077e-06,0.04106341268253651,300.6878634621873,277.6161705776783,4.420068643168271
1.576270550915287e-06,0.04146669333866773,301.32051482426544,277.6161705776783,4.420068643168271
1.5857604764673694e-06,0.04171634326865373,301.71095383007474,277.6161705776783,4.420068643168271
1.594520407746215e-06,0.04194678935787158,302.0705510198477,277.6161705776783,4.420068643168271
1.600360361932112e-06,0.04210042008401681,302.3098545386162,277.6161705776783,4.420068643168271
1.6266401557686476e-06,0.04279175835167033,303.38253349681986,277.6161705776783,4.420068643168271
1.6390500584136788e-06,0.04311822364472895,303.88672500404493,277.6161705776783,4.420068643168271
1.652919949605184e-06,0.04348309661932387,304.44847462795843,277.6161705776783,4.420068643168271
1.6572999152446062e-06,0.04359831966393278,304.6254869231632,277.6161705776783,4.420068643168271
1.6667898407966892e-06,0.04384796959391879,305.00838887911925,277.6161705776783,4.420068643168271
1.6726297949825861e-06,0.04400160032006402,305.2435982934057,277.6161705776783,4.420068643168271
1.6864996861740909e-06,0.044366473294658926,305.80094074248746,277.6161705776783,4.420068643168271
1.7010995716388332e-06,0.044750550110022005,306.3856892409043,277.6161705776783,4.420068643168271
1.7040195487317815e-06,0.04482736547309461,306.50240371073767,277.6161705776783,4.420068643168271
1.739059273847163e-06,0.04574914982996599,307.896947857151,277.6161705776783,4.420068643168271
1.751469176492194e-06,0.046075615123024605,308.38821547506313,277.6161705776783,4.420068643168271
1.757309130678091e-06,0.046229245849169834,308.6189303338119,277.6161705776783,4.420068643168271
1.7945388386131837e-06,0.04720864172834567,310.0827701838768,277.6161705776783,4.420068643168271
1.8040287641652662e-06,0.04745829165833167,310.45400554537474,277.6161705776783,4.420068643168271
1.8259285923623797e-06,0.04803440688137628,311.30780794488845,277.6161705776783,4.420068643168271
1.835418517914462e-06,0.048284056811362275,311.67654768525574,277.6161705776783,4.420068643168271
1.8616983117509978e-06,0.0489753950790158,312.693812743682,277.6161705776783,4.420068643168271
1.8770281914889772e-06,0.04937867573514702,313.28463112005664,277.6161705776783,4.420068643168271
1.8952780483199052e-06,0.04985877175435087,313.9855382885893,277.6161705776783,4.420068643168271
1.901118002505802e-06,0.0500124024804961,314.209272023118,277.6161705776783,4.420068643168271
1.9281277906155753e-06,0.05072294458891778,315.2405738647281,277.6161705776783,4.420068643168271
1.936887721894421e-06,0.05095339067813563,315.57383812788964,277.6161705776783,4.420068643168271
1.9624375214577198e-06,0.05162552510502101,316.5425176552608,277.6161705776783,4.420068643168271
1.9865273324745443e-06,0.05225925185037007,317.45134881255683,277.6161705776783,4.420068643168271
1.988717315294256e-06,0.052316863372674535,317.53375610451207,277.6161705776783,4.420068643168271
1.9960172580266266e-06,0.05250890178035607,317.80819183143655,277.6161705776783,4.420068643168271
2.0047771893054723e-06,0.05273934786957392,318.13699855010833,277.6161705776783,4.420068643168271
2.0201070690434516e-06,0.05314262852570514,318.71106520539524,277.6161705776783,4.420068643168271
2.033976960234957e-06,0.053507501500300064,319.2289965219953,277.6161705776783,4.420068643168271
2.0427368915138018e-06,0.0537379475895179,319.5554014597386,277.6161705776783,4.420068643168271
2.069016685350338e-06,0.05442928585717144,320.5313565307622,277.6161705776783,4.420068643168271
2.0770466223559467e-06,0.05464052810562113,320.8285991653817,277.6161705776783,4.420068643168271
2.087996536454503e-06,0.05492858571714343,321.23320878599407,277.6161705776783,4.420068643168271
2.0938364906404e-06,0.05508221644328866,321.4486621786719,277.6161705776783,4.420068643168271
2.114276330291039e-06,0.055619923984796954,322.2009103886328,277.6161705776783,4.420068643168271
2.12668623293607e-06,0.05594638927785557,322.6562489261516,277.6161705776783,4.420068643168271
2.1376361470346263e-06,0.05623444688937787,323.0571583715323,277.6161705776783,4.420068643168271
2.155156009592317e-06,0.05669533906781356,323.69695158825704,277.6161705776783,4.420068643168271
2.176325843516194e-06,0.057252250450090025,324.467335106053,277.6161705776783,4.420068643168271
2.210635574358338e-06,0.05815483096619324,325.7097099592564,277.6161705776783,4.420068643168271
2.2398353452878226e-06,0.05892298459691939,326.76113819382533,277.6161705776783,4.420068643168271
2.247865282293431e-06,0.05913422684536908,327.049342045489,277.6161705776783,4.420068643168271
2.2748750704032038e-06,0.05984476895379076,328.0158217972804,277.6161705776783,4.420068643168271
2.2858249845017605e-06,0.06013282656531306,328.4063617578851,277.6161705776783,4.420068643168271
2.2996948756932655e-06,0.06049769953990798,328.89999988545486,277.6161705776783,4.420068643168271
2.3062648241524e-06,0.06067053410682137,329.13342308582,277.6161705776783,4.420068643168271
2.3683143373775544e-06,0.06230286057211443,331.32533218499816,277.6161705776783,4.420068643168271
2.3821842285690594e-06,0.06266773354670935,331.8122121826326,277.6161705776783,4.420068643168271
2.398974096853513e-06,0.06310942188437688,332.40011654546163,277.6161705776783,4.420068643168271
2.4084640224055954e-06,0.06335907181436287,332.7317004515046,277.6161705776783,4.420068643168271
2.410654005225307e-06,0.06341668333666733,332.8081474071856,277.6161705776783,4.420068643168271
2.417223953684441e-06,0.06358951790358072,333.03732592887906,277.6161705776783,4.420068643168271
2.424523896416812e-06,0.06378155631126226,333.2916840015674,277.6161705776783,4.420068643168271
2.42744387350976e-06,0.06385837167433486,333.3933435798473,277.6161705776783,4.420068643168271
2.434743816242132e-06,0.06405041008201641,333.64728409714616,277.6161705776783,4.420068643168271
2.457373638712482e-06,0.06464572914582917,334.4326192436715,277.6161705776783,4.420068643168271
2.4821934440025437e-06,0.06529865973194639,335.29071849597653,277.6161705776783,4.420068643168271
2.490223381008152e-06,0.06550990198039608,335.5676215424914,277.6161705776783,4.420068643168271
2.5128532034785023e-06,0.06610522104420884,336.34611737113147,277.6161705776783,4.420068643168271
2.5194231519376364e-06,0.06627805561112222,336.5716195331202,277.6161705776783,4.420068643168271
2.5427829686812242e-06,0.06689257851570314,337.3715542848903,277.6161705776783,4.420068643168271
2.580012676616317e-06,0.06787197439487898,338.6405518485122,277.6161705776783,4.420068643168271
2.5975325391740078e-06,0.06833286657331467,339.2352541948467,277.6161705776783,4.420068643168271
2.6230823387373066e-06,0.06900500100020004,340.09973194542994,277.6161705776783,4.420068643168271
2.630382281469678e-06,0.06919703940788158,340.34612161279443,277.6161705776783,4.420068643168271
2.6391422127485235e-06,0.06942748549709943,340.6414374784664,277.6161705776783,4.420068643168271
2.659582052399162e-06,0.06996519303860772,341.3290251519269,277.6161705776783,4.420068643168271
2.6814818805962756e-06,0.07054130826165234,342.06344323834617,277.6161705776783,4.420068643168271
2.6982717488807293e-06,0.07098299659931986,342.62491403074745,277.6161705776783,4.420068643168271
2.7121416400722342e-06,0.07134786957391479,343.0877107437528,277.6161705776783,4.420068643168271
2.726741525536977e-06,0.07173194638927786,343.5738691122679,277.6161705776783,4.420068643168271
2.736961445362296e-06,0.072000800160032,343.9135761101614,277.6161705776783,4.420068643168271
2.755211302193224e-06,0.07248089617923585,344.5189678491093,277.6161705776783,4.420068643168271
2.779301113210049e-06,0.07311462292458493,345.31569572517674,277.6161705776783,4.420068643168271
2.799740952860688e-06,0.07365233046609322,345.9895974719257,277.6161705776783,4.420068643168271
2.8136108440521933e-06,0.07401720344068814,346.44579553900144,277.6161705776783,4.420068643168271
2.826750740970461e-06,0.0743628725745149,346.87717482885995,277.6161705776783,4.420068643168271
2.8610604718126056e-06,0.07526545309061813,347.9998831727554,277.6161705776783,4.420068643168271
2.8756603572773477e-06,0.0756495299059812,348.4760374420637,277.6161705776783,4.420068643168271
2.8800403229167703e-06,0.07576475295059013,348.6186997537092,277.6161705776783,4.420068643168271
2.8953702026547496e-06,0.07616803360672135,349.1173528704473,277.6161705776783,4.420068643168271
2.9055901224800696e-06,0.0764368873774755,349.44921636376887,277.6161705776783,4.420068643168271
2.909240093846255e-06,0.07653290658131627,349.56762867469047,277.6161705776783,4.420068643168271
2.9238399793109968e-06,0.07691698339667934,350.04069967657773,277.6161705776783,4.420068643168271
2.939169859048976e-06,0.07732026405281056,350.5364337861961,277.6161705776783,4.420068643168271
2.9523097559672447e-06,0.07766593318663734,350.9605466784648,277.6161705776783,4.420068643168271
2.9712896070714095e-06,0.07816523304660933,351.5718568451102,277.6161705776783,4.420068643168271
2.9815095268967294e-06,0.07843408681736348,351.9003929882015,277.6161705776783,4.420068643168271
2.987349481082626e-06,0.07858771754350871,352.08793073407696,277.6161705776783,4.420068643168271
3.0048693436403168e-06,0.0790486097219444,352.64968796327713,277.6161705776783,4.420068643168271
3.019469229105059e-06,0.07943268653730746,353.1168438795129,277.6161705776783,4.420068643168271
3.030419143203615e-06,0.07972074414882976,353.4666329204542,277.6161705776783,4.420068643168271
3.040639063028935e-06,0.07998959791958392,353.79265822873685,277.6161705776783,4.420068643168271
3.0742187995978425e-06,0.08087297459491899,354.86088784423674,277.6161705776783,4.420068643168271
3.0968486220681926e-06,0.08146829365873175,355.57821618558097,277.6161705776783,4.420068643168271
3.101958581980853e-06,0.08160272054410883,355.73991028745684,277.6161705776783,4.420068643168271
3.107068541893512e-06,0.0817371474294859,355.901500540644,277.6161705776783,4.420068643168271
3.118748450265306e-06,0.08204440888177636,356.27046099987183,277.6161705776783,4.420068643168271
3.1304283586371e-06,0.08235167033406682,356.6388829567372,277.6161705776783,4.420068643168271
3.158898135293347e-06,0.0831006201240248,357.53467268520103,277.6161705776783,4.420068643168271
3.1720380322116157e-06,0.08344628925785158,357.9470516097354,277.6161705776783,4.420068643168271
3.177147992124275e-06,0.08358071614322865,358.10724120621023,277.6161705776783,4.420068643168271
3.1851779291298835e-06,0.08379195839167834,358.35876485449666,277.6161705776783,4.420068643168271
3.204887774507286e-06,0.08431046209241849,358.9750949051514,277.6161705776783,4.420068643168271
3.215837688605842e-06,0.08459851970394079,359.3168616924542,277.6161705776783,4.420068643168271
3.2253276141579245e-06,0.08484816963392679,359.6126926274102,277.6161705776783,4.420068643168271
3.2384675110761923e-06,0.08519383876775355,360.0217448832801,277.6161705776783,4.420068643168271
3.285917138836605e-06,0.08644208841768354,361.49351942649616,277.6161705776783,4.420068643168271
3.3078169670337184e-06,0.08701820364072815,362.1700021533404,277.6161705776783,4.420068643168271
3.3297167952308314e-06,0.08759431886377275,362.8447404090829,277.6161705776783,4.420068643168271
3.3574565776138418e-06,0.0883240648129626,363.69692945323084,277.6161705776783,4.420068643168271
3.366946503165924e-06,0.08857371474294859,363.9878368436665,277.6161705776783,4.420068643168271
3.3808163943574295e-06,0.08893858771754351,364.4124346258457,277.6161705776783,4.420068643168271
3.3990662511883575e-06,0.08941868373674736,364.9700823397961,277.6161705776783,4.420068643168271
3.4421359133093472e-06,0.09055171034206842,366.2815216680582,277.6161705776783,4.420068643168271
3.4501658503149557e-06,0.09076295259051811,366.5253178780199,277.6161705776783,4.420068643168271
3.458925781593801e-06,0.09099339867973595,366.79102513727014,277.6161705776783,4.420068643168271
3.4779056326979656e-06,0.09149269853970794,367.3658255604635,277.6161705776783,4.420068643168271
3.5027254379880277e-06,0.09214562912582518,368.11564512440344,277.6161705776783,4.420068643168271
3.5275452432780894e-06,0.0927985597119424,368.8633954141531,277.6161705776783,4.420068643168271
3.5377651631034085e-06,0.09306741348269654,369.17069587644284,277.6161705776783,4.420068643168271
3.5545550313878626e-06,0.09350910182036408,369.6747960971913,277.6161705776783,4.420068643168271
3.5669649340328932e-06,0.09383556711342268,370.04679526736913,277.6161705776783,4.420068643168271
3.5720748939455534e-06,0.09396999399879977,370.1998246472279,277.6161705776783,4.420068643168271
3.57791484813145e-06,0.094123624724945,370.3746108638919,277.6161705776783,4.420068643168271
3.5874047736835327e-06,0.09437327465493099,370.6584013499407,277.6161705776783,4.420068643168271
3.602734653421512e-06,0.09477655531106222,371.1162144372182,277.6161705776783,4.420068643168271
3.6136845675200683e-06,0.09506461292258452,371.4427587671896,277.6161705776783,4.420068643168271
3.6180645331594913e-06,0.09517983596719344,371.57326842177963,277.6161705776783,4.420068643168271
3.6377743785368933e-06,0.09569833966793359,372.15980102662087,277.6161705776783,4.420068643168271
3.6487242926354495e-06,0.09598639727945589,372.4851169059786,277.6161705776783,4.420068643168271
3.663324178100192e-06,0.09637047409481897,372.9182797536331,277.6161705776783,4.420068643168271
3.6706241208325634e-06,0.0965625125025005,373.13460866350096,277.6161705776783,4.420068643168271
3.6903339662099653e-06,0.09708101620324065,373.71786025573545,277.6161705776783,4.420068643168271
3.7100438115873676e-06,0.0975995199039808,374.2998982123347,277.6161705776783,4.420068643168271
3.7180737485929757e-06,0.0978107621524305,374.5366789086618,277.6161705776783,4.420068643168271
3.739243582516852e-06,0.09836767353470695,375.15996490977653,277.6161705776783,4.420068643168271
3.7531134737083573e-06,0.09873254650930187,375.5675786505562,277.6161705776783,4.420068643168271
3.779393267544893e-06,0.09942388477695539,376.33829193385196,277.6161705776783,4.420068643168271
3.7969131301025837e-06,0.09988477695539108,376.8509399687481,277.6161705776783,4.420068643168271
3.797643124375821e-06,0.09990398079615924,376.8722802601355,277.6161705776783,4.420068643168271