File: datasets/aisi_316_L/data/M1/train_84.csv
Time(s),Strain(%),Stress(MPa),Temp(C),Log_SR(s-1)
0.0,0.0,0.0,126.31658647406016,-0.8405768658797914
4.987803806368532e-05,7.2e-06,1.3781464875,126.31658647406016,-0.8405768658797914
0.00012746609727386248,1.84e-05,3.5219299125,126.31658647406016,-0.8405768658797914
0.00014409210996175757,2.0799999999999997e-05,3.9813120749999995,126.31658647406016,-0.8405768658797914
0.00025493219454772497,3.68e-05,7.043859825,126.31658647406016,-0.8405768658797914
0.0003103522368407087,4.48e-05,8.5751337,126.31658647406016,-0.8405768658797914
0.00044336033834386953,6.4e-05,12.250191,126.31658647406016,-0.8405768658797914
0.0006317884821400141,9.12e-05,17.456522175,126.31658647406016,-0.8405768658797914
0.0006982925328915944,0.0001008,19.294050825,126.31658647406016,-0.8405768658797914
0.0010973168374010772,0.0001584,30.319222725,126.31658647406016,-0.8405768658797914
0.0012081569219870444,0.00017439999999999998,33.381770474999996,126.31658647406016,-0.8405768658797914
0.0012912869854265201,0.0001864,35.6786812875,126.31658647406016,-0.8405768658797914
0.0013356230192609069,0.0001928,36.9037003875,126.31658647406016,-0.8405768658797914
0.0013577910361781003,0.000196,37.5162099375,126.31658647406016,-0.8405768658797914
0.0014409210996175759,0.000208,39.813120749999996,126.31658647406016,-0.8405768658797914
0.0015240511630570514,0.00021999999999999998,42.1100315625,126.31658647406016,-0.8405768658797914
0.0015794712053500352,0.00022799999999999999,43.641305437499994,126.31658647406016,-0.8405768658797914
0.0016348912476430188,0.000236,45.1725793125,126.31658647406016,-0.8405768658797914
0.0019009074506493406,0.0002744,52.5226939125,126.31658647406016,-0.8405768658797914
0.0020339155521525015,0.0002936,56.197751212499995,126.31658647406016,-0.8405768658797914
0.002117045615591977,0.0003056,58.494662025000004,126.31658647406016,-0.8405768658797914
0.002183549666343557,0.00031519999999999996,60.33219067499999,126.31658647406016,-0.8405768658797914
0.0022555957213244364,0.0003256,62.3228467125,126.31658647406016,-0.8405768658797914
0.0022943897509295247,0.0003312,63.39473842499999,126.31658647406016,-0.8405768658797914
0.002493901903184266,0.00035999999999999997,68.90732437499999,126.31658647406016,-0.8405768658797914
0.002632452008916725,0.00037999999999999997,72.7355090625,126.31658647406016,-0.8405768658797914
0.0027432920935026926,0.000396,75.7980568125,126.31658647406016,-0.8405768658797914
0.0028042541400249746,0.0004048,77.482458075,126.31658647406016,-0.8405768658797914
0.002876300195005853,0.00041519999999999995,79.47311411249999,126.31658647406016,-0.8405768658797914
0.0028873842034644504,0.0004168,79.7793688875,126.31658647406016,-0.8405768658797914
0.002959430258445329,0.0004272,81.770024925,126.31658647406016,-0.8405768658797914
0.0029982242880504176,0.0004328,82.8419166375,126.31658647406016,-0.8405768658797914
0.0030259343091969095,0.0004368,83.607553575,126.31658647406016,-0.8405768658797914
0.0030702703430312965,0.0004432,84.832572675,126.31658647406016,-0.8405768658797914
0.003203278444534457,0.00046239999999999996,88.50762997499999,126.31658647406016,-0.8405768658797914
0.0033584545629548115,0.00048479999999999997,92.79519682499999,126.31658647406016,-0.8405768658797914
0.0033861645841013034,0.0004888,93.5608337625,126.31658647406016,-0.8405768658797914
0.003469294647540779,0.0005008,95.85774457500001,126.31658647406016,-0.8405768658797914
0.0034914626644579724,0.000504,96.470254125,126.31658647406016,-0.8405768658797914
0.0035801347321267464,0.0005168,98.92029232499999,126.31658647406016,-0.8405768658797914
0.003624470765961133,0.0005231999999999999,100.14531142499999,126.31658647406016,-0.8405768658797914
0.003707600829400609,0.0005352,102.4422222375,126.31658647406016,-0.8405768658797914
0.003746394859005698,0.0005408,103.51411395000001,126.31658647406016,-0.8405768658797914
0.003829524922445173,0.0005528,105.8110247625,126.31658647406016,-0.8405768658797914
0.0038849449647381565,0.0005608,107.3422986375,126.31658647406016,-0.8405768658797914
0.003951449015489737,0.0005704,109.1798272875,126.31658647406016,-0.8405768658797914
0.004045663087387809,0.000584,111.782992875,126.31658647406016,-0.8405768658797914
0.004173129184661672,0.0006024,115.3049227875,126.31658647406016,-0.8405768658797914
0.004300595281935535,0.0006208,118.8268527,126.31658647406016,-0.8405768658797914
0.004389267349604309,0.0006336,121.2768909,126.31658647406016,-0.8405768658797914
0.0045001074341902755,0.0006496,124.33943864999999,126.31658647406016,-0.8405768658797914
0.004544443468024663,0.000656,125.56445775,126.31658647406016,-0.8405768658797914
0.004583237497629751,0.0006615999999999999,126.6363494625,126.31658647406016,-0.8405768658797914
0.004705161590674315,0.0006791999999999999,130.00515198749997,126.31658647406016,-0.8405768658797914
0.0049822618021392335,0.0007191999999999999,137.6615213625,126.31658647406016,-0.8405768658797914
0.005181773954393975,0.000748,143.17410731249998,126.31658647406016,-0.8405768658797914
0.005303698047438539,0.0007656,146.5429098375,126.31658647406016,-0.8405768658797914
0.005381286106648717,0.0007768,148.6866932625,126.31658647406016,-0.8405768658797914
0.0054644161700881915,0.0007888,150.983604075,126.31658647406016,-0.8405768658797914
0.0055586302419862645,0.0008024,153.5867696625,126.31658647406016,-0.8405768658797914
0.005641760305425739,0.0008144,155.88368047499998,126.31658647406016,-0.8405768658797914
0.005780310411158199,0.0008344,159.7118651625,126.31658647406016,-0.8405768658797914
0.005835730453451183,0.0008424,161.2431390375,126.31658647406016,-0.8405768658797914
0.005852356466139077,0.0008447999999999999,161.70252119999998,126.31658647406016,-0.8405768658797914
0.005874524483056271,0.000848,162.31503075,126.31658647406016,-0.8405768658797914
0.005913318512661359,0.0008535999999999999,163.3869224625,126.31658647406016,-0.8405768658797914
0.006057410622623117,0.0008744,167.3682345375,126.31658647406016,-0.8405768658797914
0.00615162469452119,0.000888,169.971400125,126.31658647406016,-0.8405768658797914
0.006256922774877859,0.0009031999999999999,172.8808204875,126.31658647406016,-0.8405768658797914
0.0064896869525083905,0.0009368,179.3121707625,126.31658647406016,-0.8405768658797914
0.0067002831132217285,0.0009672,185.1310114875,126.31658647406016,-0.8405768658797914
0.006872085244329978,0.000992,189.8779605,126.31658647406016,-0.8405768658797914
0.006977383324686647,0.0010072,192.7873808625,126.31658647406016,-0.8405768658797914
0.007016177354291735,0.0010128,193.85927257499998,126.31658647406016,-0.8405768658797914
0.007027261362750331,0.0010144,194.16552735,126.31658647406016,-0.8405768658797914
0.007082681405043315,0.0010224,195.69680122499997,126.31658647406016,-0.8405768658797914
0.007221231510775775,0.0010424,199.5249859125,126.31658647406016,-0.8405768658797914
0.007398575646113323,0.001068,204.4250623125,126.31658647406016,-0.8405768658797914
0.007448453684177007,0.0010752,205.8032088,126.31658647406016,-0.8405768658797914
0.007625797819514555,0.0011007999999999999,210.70328519999998,126.31658647406016,-0.8405768658797914
0.0076645918491196445,0.0011064,211.7751769125,126.31658647406016,-0.8405768658797914
0.007758805921017716,0.00112,214.37834249999997,126.31658647406016,-0.8405768658797914
0.007919524043667369,0.0011432,218.8190367375,126.31658647406016,-0.8405768658797914
0.007986028094418951,0.0011528,220.6565653875,126.31658647406016,-0.8405768658797914
0.008041448136711933,0.0011608,222.1878392625,126.31658647406016,-0.8405768658797914
0.008069158157858424,0.0011648,222.95347619999998,126.31658647406016,-0.8405768658797914
0.008135662208610006,0.0011744,224.79100484999998,126.31658647406016,-0.8405768658797914
0.00825204429742527,0.0011912,228.00667998749998,126.31658647406016,-0.8405768658797914
0.008368426386240536,0.0012079999999999999,231.22235512499998,126.31658647406016,-0.8405768658797914
0.00842384642853352,0.0012159999999999999,232.75362899999996,126.31658647406016,-0.8405768658797914
0.008551312525807382,0.0012343999999999999,233.64717910385895,126.31658647406016,-0.8405768658797914
0.00869540463576914,0.0012552,233.79120809350022,126.31658647406016,-0.8405768658797914
0.008806244720355108,0.0012711999999999999,233.90136712450996,126.31658647406016,-0.8405768658797914
0.008872748771106689,0.0012808,233.96720301308477,126.31658647406016,-0.8405768658797914
0.008928168813399672,0.0012887999999999999,234.0219193717486,126.31658647406016,-0.8405768658797914
0.009033466893756342,0.001304,234.12551690009082,126.31658647406016,-0.8405768658797914
0.009216353033323188,0.0013304,234.3043370160666,126.31658647406016,-0.8405768658797914
0.009305025100991961,0.0013432,234.39053907417193,126.31658647406016,-0.8405768658797914
0.009471285227870913,0.0013671999999999998,234.55130931834498,126.31658647406016,-0.8405768658797914
0.009565499299768986,0.0013808,234.64192382283667,126.31658647406016,-0.8405768658797914
0.009737301430877233,0.0014056,234.80627098669106,126.31658647406016,-0.8405768658797914
0.010069821684635136,0.0014536,235.12118450432172,126.31658647406016,-0.8405768658797914
0.010130783731157418,0.0014624,235.17847601465738,126.31658647406016,-0.8405768658797914
0.010197287781908999,0.001472,235.24082271807617,126.31658647406016,-0.8405768658797914
0.010208371790367597,0.0014736,235.25119839876854,126.31658647406016,-0.8405768658797914
0.010274875841119175,0.0014831999999999998,235.31336046774388,126.31658647406016,-0.8405768658797914
0.010358005904558652,0.0014952,235.39084283457348,126.31658647406016,-0.8405768658797914
0.010557518056813393,0.001524,235.5758176482371,126.31658647406016,-0.8405768658797914
0.010740404196380239,0.0015504,235.74418374741285,126.31658647406016,-0.8405768658797914
0.010829076264049012,0.0015631999999999998,235.82541300952184,126.31658647406016,-0.8405768658797914
0.010856786285195505,0.0015672,235.8507439021674,126.31658647406016,-0.8405768658797914
0.010901122319029892,0.0015735999999999999,235.89122094733304,126.31658647406016,-0.8405768658797914
0.010939916348634981,0.0015792,235.92658572408345,126.31658647406016,-0.8405768658797914
0.011017504407845156,0.0015903999999999998,235.99716889232215,126.31658647406016,-0.8405768658797914
0.011095092467055334,0.0016016,236.06755846943693,126.31658647406016,-0.8405768658797914
0.0112114745558706,0.0016183999999999999,236.17278395402332,126.31658647406016,-0.8405768658797914
0.01131677263622727,0.0016336,236.26762145692,126.31658647406016,-0.8405768658797914
0.011405444703896043,0.0016464,236.34721798830927,126.31658647406016,-0.8405768658797914
0.01144423873350113,0.0016519999999999998,236.38196554076086,126.31658647406016,-0.8405768658797914
0.011538452805399205,0.0016656,236.46616175676067,126.31658647406016,-0.8405768658797914
0.01162158286883868,0.0016776,236.54023013001697,126.31658647406016,-0.8405768658797914
0.011760132974571139,0.0016975999999999998,236.6632198855233,126.31658647406016,-0.8405768658797914
0.011882057067615703,0.0017151999999999998,236.7709841723319,126.31658647406016,-0.8405768658797914
0.011948561118367283,0.0017247999999999999,236.82958289111232,126.31658647406016,-0.8405768658797914
0.012020607173348161,0.0017352,236.89292148091582,126.31658647406016,-0.8405768658797914
0.012048317194494654,0.0017392,236.917243033193,126.31658647406016,-0.8405768658797914
0.012092653228329042,0.0017456,236.95611218970475,126.31658647406016,-0.8405768658797914
0.012242287342520098,0.0017672,237.0868872033197,126.31658647406016,-0.8405768658797914
0.012358669431335362,0.001784,237.18817059425905,126.31658647406016,-0.8405768658797914
0.012425173482086944,0.0017936,237.24587979974723,126.31658647406016,-0.8405768658797914
0.0125692655920487,0.0018143999999999999,237.37050476991425,126.31658647406016,-0.8405768658797914
0.01270781569778116,0.0018344,237.4898120722656,126.31658647406016,-0.8405768658797914
0.01274106772315695,0.0018391999999999998,237.5183702078422,126.31658647406016,-0.8405768658797914
0.01284636580351362,0.0018544,237.60861313649193,126.31658647406016,-0.8405768658797914
0.012957205888099586,0.0018704,237.70329459238798,126.31658647406016,-0.8405768658797914
0.013134550023437134,0.001896,237.85413053463324,126.31658647406016,-0.8405768658797914
0.01315117603612503,0.0018984,237.86823055754695,126.31658647406016,-0.8405768658797914
0.013195512069959416,0.0019048,237.90579667270953,126.31658647406016,-0.8405768658797914
0.01331743616300398,0.0019223999999999999,238.00885052254216,126.31658647406016,-0.8405768658797914
0.01338394021375556,0.001932,238.06490660015217,126.31658647406016,-0.8405768658797914
0.01345044426450714,0.0019416,238.1208541520066,126.31658647406016,-0.8405768658797914
0.013472612281424335,0.0019448,238.13947934816846,126.31658647406016,-0.8405768658797914
0.013539116332175914,0.0019544,238.19528335662113,126.31658647406016,-0.8405768658797914
0.01365549842099118,0.0019711999999999998,238.29268381873823,126.31658647406016,-0.8405768658797914
0.013672124433679076,0.0019736,238.30657169648708,126.31658647406016,-0.8405768658797914
0.013915972619768204,0.0020088,238.50950980151453,126.31658647406016,-0.8405768658797914
0.01407114873818856,0.0020312,238.6379304524066,126.31658647406016,-0.8405768658797914
0.01413211078471084,0.0020399999999999997,238.68823016218678,126.31658647406016,-0.8405768658797914
0.014254034877755404,0.0020575999999999997,238.78857643301737,126.31658647406016,-0.8405768658797914
0.014398126987717162,0.0020783999999999998,238.90673692625145,126.31658647406016,-0.8405768658797914
0.014508967072303128,0.0020943999999999997,238.99731606394542,126.31658647406016,-0.8405768658797914
0.014592097135742606,0.0021064,239.06507342118488,126.31658647406016,-0.8405768658797914
0.014786067283768047,0.0021344,239.2225911632849,126.31658647406016,-0.8405768658797914
0.014858113338748929,0.0021448,239.28089223490556,126.31658647406016,-0.8405768658797914
0.015002205448710684,0.0021655999999999997,239.39716467036246,126.31658647406016,-0.8405768658797914
0.015135213550213845,0.0021847999999999998,239.5041070844104,126.31658647406016,-0.8405768658797914
0.015295931672863498,0.002208,239.63284139036838,126.31658647406016,-0.8405768658797914
0.015495443825118239,0.0022367999999999997,239.79191793258536,126.31658647406016,-0.8405768658797914
0.01565616194776789,0.00226,239.91948277905746,126.31658647406016,-0.8405768658797914
0.015717123994290174,0.0022688,239.96773571793983,126.31658647406016,-0.8405768658797914
0.01576146002812456,0.0022752,240.00278293033523,126.31658647406016,-0.8405768658797914
0.015872300112710527,0.0022911999999999997,240.0902331687607,126.31658647406016,-0.8405768658797914
0.01599422420575509,0.0023087999999999997,240.18615380757504,126.31658647406016,-0.8405768658797914
0.016055186252277375,0.0023176,240.2340071578556,126.31658647406016,-0.8405768658797914
0.016110606294570357,0.0023255999999999997,240.27744874617548,126.31658647406016,-0.8405768658797914
0.01620482036646843,0.0023392,240.35116592993293,126.31658647406016,-0.8405768658797914
0.016332286463742296,0.0023576,240.45063544335503,126.31658647406016,-0.8405768658797914
0.016420958531411067,0.0023704,240.5196531333267,126.31658647406016,-0.8405768658797914
0.016481920577933348,0.0023791999999999997,240.56701850367554,126.31658647406016,-0.8405768658797914
0.01678118880631546,0.0024224,240.79855569790976,126.31658647406016,-0.8405768658797914
0.01689202889090143,0.0024384,240.8839008308068,126.31658647406016,-0.8405768658797914
0.01702503699240459,0.0024576,240.98602723880794,126.31658647406016,-0.8405768658797914
0.01712479306853196,0.002472,241.06241796628706,126.31658647406016,-0.8405768658797914
0.01722454914465933,0.0024863999999999997,241.13863534171728,126.31658647406016,-0.8405768658797914
0.017346473237703892,0.0025039999999999997,241.23155652702144,126.31658647406016,-0.8405768658797914
0.017446229313831267,0.0025184,241.3073936384706,126.31658647406016,-0.8405768658797914
0.017479481339207056,0.0025231999999999997,241.3326350697327,126.31658647406016,-0.8405768658797914
0.01759586342802232,0.0025399999999999997,241.42083298219669,126.31658647406016,-0.8405768658797914
0.017756581550671974,0.0025632,241.54225698923366,126.31658647406016,-0.8405768658797914
0.017823085601423556,0.0025728,241.59237594211064,126.31658647406016,-0.8405768658797914
0.01791729967332163,0.0025864,241.66325312272505,126.31658647406016,-0.8405768658797914
0.018033681762136895,0.0026032,241.75060693283933,126.31658647406016,-0.8405768658797914
0.018072475791741982,0.0026088,241.77967597542323,126.31658647406016,-0.8405768658797914
0.018116811825576368,0.0026152,241.81286795631527,126.31658647406016,-0.8405768658797914
0.01824427792285023,0.0026336,241.90811889627926,126.31658647406016,-0.8405768658797914
0.018399454041270587,0.002656,242.0237269772267,126.31658647406016,-0.8405768658797914
0.01848258410471006,0.002668,242.08550343204226,126.31658647406016,-0.8405768658797914
0.01865992824004761,0.0026936,242.21693219321622,126.31658647406016,-0.8405768658797914
0.01900353250226411,0.0027432,242.47019732798353,126.31658647406016,-0.8405768658797914
0.01919750265028955,0.0027711999999999997,242.6123807930735,126.31658647406016,-0.8405768658797914
0.01940255680677359,0.0028008,242.76208115865202,126.31658647406016,-0.8405768658797914
0.01954110691250605,0.0028208,242.86288091679324,126.31658647406016,-0.8405768658797914
0.019629778980174824,0.0028336,242.92724651344858,126.31658647406016,-0.8405768658797914
0.01966857300977991,0.0028392,242.95537079426038,126.31658647406016,-0.8405768658797914
0.019796039107053773,0.0028576,243.04762719932197,126.31658647406016,-0.8405768658797914
0.01983483313665886,0.0028631999999999998,243.07565921328379,126.31658647406016,-0.8405768658797914
0.01991242119586904,0.0028744,243.13165917656795,126.31658647406016,-0.8405768658797914
0.02017843739887536,0.0029127999999999997,243.32301629164158,126.31658647406016,-0.8405768658797914
0.02031698750460782,0.0029327999999999997,243.42229165441552,126.31658647406016,-0.8405768658797914
0.020339155521525015,0.002936,243.43815117787864,126.31658647406016,-0.8405768658797914
0.020361323538442208,0.0029392,243.45400396139493,126.31658647406016,-0.8405768658797914
0.020455537610340278,0.0029527999999999998,243.52130333532324,126.31658647406016,-0.8405768658797914
0.020505415648403965,0.00296,243.55688346981339,126.31658647406016,-0.8405768658797914
0.02062179773721923,0.0029768,243.63977278035117,126.31658647406016,-0.8405768658797914
0.02068830178797081,0.0029863999999999997,243.68705618635406,126.31658647406016,-0.8405768658797914
0.02092660796983064,0.0030207999999999997,243.85600377137763,126.31658647406016,-0.8405768658797914
0.02116491415169047,0.0030551999999999997,244.02420266952794,126.31658647406016,-0.8405768658797914
0.02128129624050574,0.003072,244.10607775176754,126.31658647406016,-0.8405768658797914
0.021486350396989776,0.0031016,244.24991023470704,126.31658647406016,-0.8405768658797914
0.021569480460429252,0.0031136,244.3080680755456,126.31658647406016,-0.8405768658797914
0.02164706851963943,0.0031248,244.36226990791675,126.31658647406016,-0.8405768658797914
0.021735740587308202,0.0031376,244.42412217101784,126.31658647406016,-0.8405768658797914
0.02195187875225084,0.0031688,244.5744762237094,126.31658647406016,-0.8405768658797914
0.022029466811461014,0.0031799999999999997,244.62830850409728,126.31658647406016,-0.8405768658797914
0.022112596874900494,0.003192,244.68590395870754,126.31658647406016,-0.8405768658797914
0.022179100925652073,0.0032015999999999998,244.73191954563316,126.31658647406016,-0.8405768658797914
0.022223436959486458,0.003208,244.76256671199937,126.31658647406016,-0.8405768658797914
0.022312109027155233,0.0032208,244.82378960290825,126.31658647406016,-0.8405768658797914
0.0224229491117412,0.0032367999999999997,244.90018494032773,126.31658647406016,-0.8405768658797914
0.02260583525130805,0.0032632,245.02591604741463,126.31658647406016,-0.8405768658797914
0.022783179386645595,0.0032887999999999997,245.14745881529888,126.31658647406016,-0.8405768658797914
0.022860767445855773,0.0033,245.20051769108306,126.31658647406016,-0.8405768658797914
0.022943897509295246,0.003312,245.257288612142,126.31658647406016,-0.8405768658797914
0.022966065526212442,0.0033152,245.27241396906956,126.31658647406016,-0.8405768658797914
0.0231101576361742,0.003336,245.3705903662256,126.31658647406016,-0.8405768658797914
0.023298585779970342,0.0033632,245.49861542310566,126.31658647406016,-0.8405768658797914
0.023414967868785608,0.0033799999999999998,245.5774880206588,126.31658647406016,-0.8405768658797914
0.023520265949142277,0.0033951999999999997,245.64871729718465,126.31658647406016,-0.8405768658797914
0.023547975970288768,0.0033992,245.6674411598125,126.31658647406016,-0.8405768658797914
0.023636648037957543,0.0034119999999999997,245.72729985778508,126.31658647406016,-0.8405768658797914
0.02371977810139702,0.003424,245.78333789824225,126.31658647406016,-0.8405768658797914
0.023830618185982987,0.00344,245.8579362845833,126.31658647406016,-0.8405768658797914
0.02391929025365176,0.0034528,245.9175176107254,126.31658647406016,-0.8405768658797914
0.023947000274798253,0.0034568,245.93611910125563,126.31658647406016,-0.8405768658797914
0.024052298355154923,0.003472,246.00672833871047,126.31658647406016,-0.8405768658797914
0.024140970422823694,0.0034847999999999997,246.0660952924746,126.31658647406016,-0.8405768658797914
0.024218558482033872,0.003496,246.11797164966924,126.31658647406016,-0.8405768658797914
0.024346024579307735,0.0035144,246.2030566052342,126.31658647406016,-0.8405768658797914
0.024379276604683524,0.0035191999999999997,246.22522408599966,126.31658647406016,-0.8405768658797914
0.024418070634288615,0.0035248,246.25107124895732,126.31658647406016,-0.8405768658797914
0.0244790326808109,0.0035336,246.29165588577007,126.31658647406016,-0.8405768658797914
0.024728422871129325,0.0035696,246.45727513303294,126.31658647406016,-0.8405768658797914
0.024955645044530555,0.0036024,246.60760640407585,126.31658647406016,-0.8405768658797914
0.025033233103740733,0.0036136,246.6588166483201,126.31658647406016,-0.8405768658797914
0.02507202713334582,0.0036192,246.68439855481202,126.31658647406016,-0.8405768658797914
0.025149615192556,0.0036303999999999998,246.7355161028028,126.31658647406016,-0.8405768658797914
0.025210577239078283,0.0036392,246.7756367567628,126.31658647406016,-0.8405768658797914
0.02531033331520565,0.0036536,246.84120721840273,126.31658647406016,-0.8405768658797914
0.025399005382874425,0.0036663999999999998,246.89940750758709,126.31658647406016,-0.8405768658797914
0.0254821354463139,0.0036783999999999996,246.9538983516695,126.31658647406016,-0.8405768658797914
0.025897785763511278,0.0037384,247.22531952986915,126.31658647406016,-0.8405768658797914
0.02592549578465777,0.0037424,247.24335363677946,126.31658647406016,-0.8405768658797914
0.02620259599612269,0.0037824,247.42328316437468,126.31658647406016,-0.8405768658797914
0.02630235207225006,0.0037968,247.48787593225657,126.31658647406016,-0.8405768658797914
0.026418734161065324,0.0038136,247.563113531437,126.31658647406016,-0.8405768658797914
0.026474154203358306,0.0038215999999999997,247.59889551746028,126.31658647406016,-0.8405768658797914
0.026540658254109888,0.0038312,247.64179536290584,126.31658647406016,-0.8405768658797914
0.02659607829640287,0.0038391999999999996,247.67751321868963,126.31658647406016,-0.8405768658797914
0.026734628402135332,0.0038591999999999997,247.76668110062258,126.31658647406016,-0.8405768658797914
0.026961850575536562,0.0038919999999999996,247.91252727208817,126.31658647406016,-0.8405768658797914
0.02700618660937095,0.0038983999999999998,247.94092908548348,126.31658647406016,-0.8405768658797914
0.027117026693956922,0.0039144,248.0118541771989,126.31658647406016,-0.8405768658797914
0.027338706863128857,0.0039464,248.15336608040715,126.31658647406016,-0.8405768658797914
0.027405210913880432,0.0039559999999999994,248.19573229406294,126.31658647406016,-0.8405768658797914
0.02764905909996956,0.0039911999999999994,248.35073321987224,126.31658647406016,-0.8405768658797914
0.028774298814050647,0.004153630726145229,249.05919130975497,126.31658647406016,-0.8405768658797914
0.03223320123361674,0.004652930586117224,251.17213349828913,126.31658647406016,-0.8405768658797914
0.03569210365318284,0.005152230446089218,253.1982775409348,126.31658647406016,-0.8405768658797914
0.03848583253052468,0.005555511102220444,254.77936276226134,126.31658647406016,-0.8405768658797914
0.041146526699421676,0.005939587917583517,256.24402110456765,126.31658647406016,-0.8405768658797914
0.04420632499365323,0.00638127625525105,257.883442885898,126.31658647406016,-0.8405768658797914
0.04952771333144722,0.007149429885977195,260.63281860628524,126.31658647406016,-0.8405768658797914
0.05405089341857211,0.007802360472094419,262.8802472875845,126.31658647406016,-0.8405768658797914
0.05804193467191761,0.008378475695139028,264.8029985993381,126.31658647406016,-0.8405768658797914
0.059638351173255805,0.008608921784356871,265.55757195737,126.31658647406016,-0.8405768658797914
0.06296421888437705,0.009089017803560712,267.1047543202036,126.31658647406016,-0.8405768658797914
0.0657579477617189,0.009492298459691939,268.37990182796955,126.31658647406016,-0.8405768658797914
0.0700150584319541,0.010106821364272855,270.2830770598518,126.31658647406016,-0.8405768658797914
0.07094630139106804,0.01024124824964993,270.69331721680464,126.31658647406016,-0.8405768658797914
0.07320789143463048,0.01056771354270854,271.68096794903977,126.31658647406016,-0.8405768658797914
0.07600162031197234,0.010970994198839769,272.88472782237136,126.31658647406016,-0.8405768658797914
0.08158907806665604,0.011777555511102222,275.2416712658801,126.31658647406016,-0.8405768658797914
0.08464887636088757,0.012219243848769754,276.5056617575675,126.31658647406016,-0.8405768658797914
0.09050240353246096,0.013064212842568514,278.8751402698401,126.31658647406016,-0.8405768658797914
0.09169971590846461,0.013237047409481896,279.3523571716167,126.31658647406016,-0.8405768658797914
0.0959568265786998,0.013851570314062813,281.02979246829045,126.31658647406016,-0.8405768658797914
0.09941572899826591,0.014350870174034807,282.3714334301183,126.31658647406016,-0.8405768658797914
0.10008090254049015,0.014446889377875576,282.62734093234593,126.31658647406016,-0.8405768658797914
0.10939333213162965,0.01579115823164633,286.14312467942307,126.31658647406016,-0.8405768658797914
0.11205402630052665,0.016175235047009403,287.12593025673453,126.31658647406016,-0.8405768658797914
0.11378347751030968,0.0164248849769954,287.75987679794247,126.31658647406016,-0.8405768658797914
0.12562356656190132,0.018134026805361074,292.0032390834842,126.31658647406016,-0.8405768658797914
0.12602267068723588,0.018191638327665533,292.14348832782565,126.31658647406016,-0.8405768658797914
0.12721998306323953,0.018364472894578918,292.56320040028595,126.31658647406016,-0.8405768658797914
0.1280181913139086,0.018479695939187836,292.8421529190211,126.31658647406016,-0.8405768658797914
0.1290824689814674,0.018633326665333065,293.2130367181889,126.31658647406016,-0.8405768658797914
0.13094495489969532,0.01890218043608722,293.8592264125904,126.31658647406016,-0.8405768658797914
0.1328074408179232,0.019171034206841367,294.50184138456416,126.31658647406016,-0.8405768658797914
0.13360564906859232,0.019286257251450292,294.77617080307215,126.31658647406016,-0.8405768658797914
0.1381288291557172,0.019939187837567512,296.31879730344104,126.31658647406016,-0.8405768658797914
0.1402573844908348,0.02024644928985797,297.03791025849125,126.31658647406016,-0.8405768658797914
0.14198683570061785,0.02049609921984397,297.619060605975,126.31658647406016,-0.8405768658797914
0.14384932161884575,0.02076495299059812,298.24183601544786,126.31658647406016,-0.8405768658797914
0.1453127034117391,0.02097619523904781,298.7289561132358,126.31658647406016,-0.8405768658797914
0.14757429345530154,0.021302660532106422,299.47803175333456,126.31658647406016,-0.8405768658797914
0.1482394669975258,0.02139867973594719,299.6974943361678,126.31658647406016,-0.8405768658797914
0.15302871650154037,0.02209001800360072,301.26644067989895,126.31658647406016,-0.8405768658797914
0.15422602887754405,0.022262852570514104,301.65567049522537,126.31658647406016,-0.8405768658797914
0.15635458421266166,0.022570114022804563,302.34473722364413,126.31658647406016,-0.8405768658797914
0.16021259075756228,0.023127025405081016,303.5844171848957,126.31658647406016,-0.8405768658797914
0.16194204196734535,0.023376675335067015,304.1363507718114,126.31658647406016,-0.8405768658797914
0.16686432617980476,0.024087217443488698,305.69479505803025,126.31658647406016,-0.8405768658797914
0.17245178393448846,0.02489377875575115,307.44227271923273,126.31658647406016,-0.8405768658797914
0.17537854752027515,0.02531626325265053,308.3487973358299,126.31658647406016,-0.8405768658797914
0.1768419293131685,0.02552750550110022,308.79984570484385,126.31658647406016,-0.8405768658797914
0.17883744993984127,0.025815563112622526,309.41257275642295,126.31658647406016,-0.8405768658797914
0.18203028294251766,0.026276455291058213,310.3874187743099,126.31658647406016,-0.8405768658797914
0.18282849119318675,0.026391678335667135,310.6300854925015,126.31658647406016,-0.8405768658797914
0.19134271253365714,0.027620724144828968,313.19333157665136,126.31658647406016,-0.8405768658797914
0.1933382331603299,0.02790878175635127,313.78761073585304,126.31658647406016,-0.8405768658797914
0.19639803145456144,0.028350470094018806,314.6942135942343,126.31658647406016,-0.8405768658797914
0.19759534383056507,0.028523304660932187,315.04746967127306,126.31658647406016,-0.8405768658797914
0.20610956517103549,0.02975235047009402,317.5358680322764,126.31658647406016,-0.8405768658797914
0.2075729469639288,0.029963592718543708,317.95949191019093,126.31658647406016,-0.8405768658797914
0.2120961270510537,0.03061652330466093,319.2615705272316,126.31658647406016,-0.8405768658797914
0.2134264741355022,0.030808561712342468,319.6424679249062,126.31658647406016,-0.8405768658797914
0.22233979960130715,0.03209521904380876,322.1710075305538,126.31658647406016,-0.8405768658797914
0.22712904910532175,0.032786557311462294,323.5132827159115,126.31658647406016,-0.8405768658797914
0.23032188210799814,0.03324744948989798,324.4020053491247,126.31658647406016,-0.8405768658797914
0.2315191944840018,0.03342028405681136,324.73403596006256,126.31658647406016,-0.8405768658797914
0.23271650686000542,0.033593118623724744,325.06539756868625,126.31658647406016,-0.8405768658797914
0.23803789519779942,0.03436127225445089,326.5301446521565,126.31658647406016,-0.8405768658797914
0.2393682422822479,0.03455331066213242,326.89432913212954,126.31658647406016,-0.8405768658797914
0.24229500586803462,0.034975795159031806,327.69276788794355,126.31658647406016,-0.8405768658797914
0.2425610752849243,0.03501420284056811,327.7651662008024,126.31658647406016,-0.8405768658797914
0.2468181859551595,0.035628725745149026,328.9193597093855,126.31658647406016,-0.8405768658797914
0.24947888012405653,0.036012802560512105,329.6367893340293,126.31658647406016,-0.8405768658797914
0.2517404701676189,0.03633926785357071,330.2442614046215,126.31658647406016,-0.8405768658797914
0.2529377825436226,0.0365121024204841,330.56500241164736,126.31658647406016,-0.8405768658797914
0.2537359907942917,0.03662732546509302,330.7785008539101,126.31658647406016,-0.8405768658797914
0.25772703204763725,0.037203440688137634,331.84208912275875,126.31658647406016,-0.8405768658797914
0.25852524029830626,0.037318663732746546,332.05403385259194,126.31658647406016,-0.8405768658797914
0.2593234485489754,0.03743388677735547,332.26572352388763,126.31658647406016,-0.8405768658797914
0.2625162815516518,0.03789477895579116,333.1099533165023,126.31658647406016,-0.8405768658797914
0.2643787674698797,0.03816363272654531,333.6005714191248,126.31658647406016,-0.8405768658797914
0.26637428809655245,0.03845169033806761,334.1247402421881,126.31658647406016,-0.8405768658797914
0.27049836405834277,0.03904700940188037,335.20319432229934,126.31658647406016,-0.8405768658797914
0.27462244002013314,0.03964232846569314,336.27525462072805,126.31658647406016,-0.8405768658797914
0.2767509953552508,0.0399495899179836,336.8261183006527,126.31658647406016,-0.8405768658797914
0.28087507131704104,0.04054490898179636,337.8887370940081,126.31658647406016,-0.8405768658797914
0.28313666136060356,0.040871374274854974,338.468879520195,126.31658647406016,-0.8405768658797914
0.28513218198727625,0.04115943188637727,338.9792707365195,126.31658647406016,-0.8405768658797914
0.28832501498995267,0.04162032406481296,339.7930085800289,126.31658647406016,-0.8405768658797914
0.29284819507707754,0.04227325465093018,340.93981354255993,126.31658647406016,-0.8405768658797914
0.29351336861930183,0.04236927385477096,341.10787687108433,126.31658647406016,-0.8405768658797914
0.29484371570375034,0.042561312262452494,341.4435585697336,126.31658647406016,-0.8405768658797914
0.29910082637398555,0.04317583516703341,342.5137920755864,126.31658647406016,-0.8405768658797914
0.3026927635019965,0.04369433886777356,343.4121886001599,126.31658647406016,-0.8405768658797914
0.3050873882540038,0.04404000800160032,344.00881081854845,126.31658647406016,-0.8405768658797914
0.30628470063000734,0.0442128425685137,344.3064368554019,126.31658647406016,-0.8405768658797914
0.3078811171313456,0.04444328865773155,344.70256669628293,126.31658647406016,-0.8405768658797914
0.3092114642157941,0.04463532706541308,345.0320633466842,126.31658647406016,-0.8405768658797914
0.31360160959447414,0.045269053810762155,346.11550075626116,126.31658647406016,-0.8405768658797914
0.3151980260958123,0.04549949989997999,346.5080093391071,126.31658647406016,-0.8405768658797914
0.31878996322382325,0.04601800360072014,347.3883299505915,126.31658647406016,-0.8405768658797914
0.3233131433109481,0.04667093418683736,348.4913983725109,126.31658647406016,-0.8405768658797914
0.3277032886896282,0.04730466093218644,349.5562823978827,126.31658647406016,-0.8405768658797914
0.3296988093163009,0.04759271854370874,350.03847988821457,126.31658647406016,-0.8405768658797914
0.3316943299429737,0.04788077615523105,350.51954048687344,126.31658647406016,-0.8405768658797914
0.33275860761053255,0.04803440688137628,350.775644561483,126.31658647406016,-0.8405768658797914
0.3384791000736611,0.04886017203440689,352.14676933984714,126.31658647406016,-0.8405768658797914
0.3414058636594477,0.04928265653130626,352.8447783621924,126.31658647406016,-0.8405768658797914
0.34419959253678956,0.04968593718743748,353.5088859332783,126.31658647406016,-0.8405768658797914
0.34632814787190713,0.04999319863972794,354.01346259982876,126.31658647406016,-0.8405768658797914
0.3467272519972417,0.0500508101620324,354.1079359279735,126.31658647406016,-0.8405768658797914
0.3475254602479108,0.05016603320664133,354.29675544942,126.31658647406016,-0.8405768658797914
0.35045222383369756,0.05058851770354071,354.9876513561449,126.31658647406016,-0.8405768658797914
0.3563057510052709,0.051433486697339464,356.362729048935,126.31658647406016,-0.8405768658797914
0.36122803521773034,0.05214402880576115,357.5122383790059,126.31658647406016,-0.8405768658797914
0.36202624346839946,0.05225925185037007,357.6980681331002,126.31658647406016,-0.8405768658797914
0.36309052113595824,0.0524128825765153,357.9455927637183,126.31658647406016,-0.8405768658797914
0.3676137012230831,0.05306581316263252,358.9944313067208,126.31658647406016,-0.8405768658797914
0.37147170776798377,0.053622724544908976,359.8850578013068,126.31658647406016,-0.8405768658797914
0.37346722839465657,0.05391078215643129,360.3443107211451,126.31658647406016,-0.8405768658797914
0.3750636448959947,0.054141228245649126,360.71102437739773,126.31658647406016,-0.8405768658797914
0.37985289440000936,0.054832566513302664,361.8075301991213,126.31658647406016,-0.8405768658797914
0.38211448444357177,0.05515903180636127,362.3234492058935,126.31658647406016,-0.8405768658797914
0.38424303977868934,0.055466293258651725,362.8079332491052,126.31658647406016,-0.8405768658797914
0.38929835869959367,0.05619603920784157,363.95440704321436,126.31658647406016,-0.8405768658797914
0.3931563652444943,0.05675295059011802,364.8254454519556,126.31658647406016,-0.8405768658797914
0.39767954533161926,0.057405881176235254,365.8424290773104,126.31658647406016,-0.8405768658797914
0.4037991419200823,0.05828925785157031,367.21119661377276,126.31658647406016,-0.8405768658797914
0.40539555842142055,0.05851970394078816,367.5669328990409,126.31658647406016,-0.8405768658797914
0.4057946625467551,0.058577315463092625,367.65578155391967,126.31658647406016,-0.8405768658797914
0.4091205302578763,0.05905741148229646,368.3948663512093,126.31658647406016,-0.8405768658797914
0.4121803285521079,0.059499099819964,369.0727574653274,126.31658647406016,-0.8405768658797914
0.41484102272100487,0.059883176635327065,369.66063427518054,126.31658647406016,-0.8405768658797914
0.4167035086392328,0.06015203040608122,370.0712734054935,126.31658647406016,-0.8405768658797914
0.4185659945574607,0.060420884176835374,370.48119735797485,126.31658647406016,-0.8405768658797914
0.42774538944015533,0.06174594918983797,372.4912358969992,126.31658647406016,-0.8405768658797914
0.4288096671077141,0.0618995799159832,372.7231904681628,126.31658647406016,-0.8405768658797914
0.43107125715127653,0.062226045209041805,373.21534977107103,126.31658647406016,-0.8405768658797914
0.4361265760721808,0.06295579115823165,374.3118438398748,126.31658647406016,-0.8405768658797914
0.4374569231566293,0.06314782956591318,374.59956964557523,126.31658647406016,-0.8405768658797914
0.4383881661157433,0.06328225645129026,374.80077469993154,126.31658647406016,-0.8405768658797914
0.4395854784917469,0.06345509101820364,375.0592221514327,126.31658647406016,-0.8405768658797914
0.44118189499308513,0.06368553710742149,375.4033921010448,126.31658647406016,-0.8405768658797914
0.44450776270420633,0.06416563312662532,376.11885677752184,126.31658647406016,-0.8405768658797914
0.44889790808288643,0.0647993598719744,377.0600815326927,126.31658647406016,-0.8405768658797914
0.45076039400111434,0.06506821364272855,377.4583036631744,126.31658647406016,-0.8405768658797914
0.4552835740882392,0.06572114422884577,378.4227523516911,126.31658647406016,-0.8405768658797914
0.45608178233890834,0.0658363672734547,378.59256054756855,126.31658647406016,-0.8405768658797914
0.46007282359225377,0.0664124824964993,379.4398691737732,126.31658647406016,-0.8405768658797914
0.46459600367937876,0.06706541308261653,380.39669453922454,126.31658647406016,-0.8405768658797914
0.46858704493272424,0.06764152830566114,381.23793926209595,126.31658647406016,-0.8405768658797914
0.4712477391016212,0.06802560512102421,381.7972171744374,126.31658647406016,-0.8405768658797914
0.4735093291451837,0.06835207041408282,382.27163580585005,126.31658647406016,-0.8405768658797914
0.4782985786491982,0.06904340868173635,383.2733797193521,126.31658647406016,-0.8405768658797914
0.4840190711123268,0.06986917383476696,384.4647948047595,126.31658647406016,-0.8405768658797914
0.48880832061634144,0.0705605121024205,385.45804107298505,126.31658647406016,-0.8405768658797914
0.48987259828390023,0.07071414282856572,385.6782462092889,126.31658647406016,-0.8405768658797914
0.4912029453683487,0.07090618123624726,385.9532404290618,126.31658647406016,-0.8405768658797914
0.49306543128657665,0.07117503500700141,386.3377448585529,126.31658647406016,-0.8405768658797914
0.4933315007034663,0.07121344268853771,386.3926277873324,126.31658647406016,-0.8405768658797914
0.49812075020748087,0.07190478095619124,387.3785550179694,126.31658647406016,-0.8405768658797914
0.5011805485017125,0.07234646929385878,388.00651798998814,126.31658647406016,-0.8405768658797914
0.5030430344199402,0.07261532306461292,388.38802432764584,126.31658647406016,-0.8405768658797914
0.5066349715479512,0.07313382676535307,389.1222344705065,126.31658647406016,-0.8405768658797914
0.5094287004252931,0.0735371074214843,389.6918841790987,126.31658647406016,-0.8405768658797914
0.510359943384407,0.07367153430686138,389.8814965001228,126.31658647406016,-0.8405768658797914
0.5116902904688556,0.07386357271454291,390.15213734507023,126.31658647406016,-0.8405768658797914
0.5135527763870835,0.07413242648529707,390.53057395700824,126.31658647406016,-0.8405768658797914
0.5143509846377525,0.07424764952990598,390.69259717929356,126.31658647406016,-0.8405768658797914
0.5176768523488738,0.07472774554910983,391.3666411280294,126.31658647406016,-0.8405768658797914
0.5203375465177709,0.0751118223644729,391.9046610840321,126.31658647406016,-0.8405768658797914
0.5229982406866678,0.07549589917983597,392.4416091701349,126.31658647406016,-0.8405768658797914
0.5248607266048957,0.07576475295059013,392.81683912644485,126.31658647406016,-0.8405768658797914
0.5284526637329067,0.07628325665133028,393.5390336701846,126.31658647406016,-0.8405768658797914
0.5288517678582413,0.07634086817363474,393.61915915832867,126.31658647406016,-0.8405768658797914
0.5328428091115867,0.07691698339667934,394.41912126258364,126.31658647406016,-0.8405768658797914
0.5340401214875904,0.07708981796359272,394.65865377422676,126.31658647406016,-0.8405768658797914
0.5377650933240461,0.07762752550510102,395.4025301494734,126.31658647406016,-0.8405768658797914
0.5393615098253843,0.07785797159431887,395.7207188458844,126.31658647406016,-0.8405768658797914
0.543219516370285,0.07841488297659532,396.4881622969288,126.31658647406016,-0.8405768658797914
0.544948967580068,0.07866453290658132,396.8314983450359,126.31658647406016,-0.8405768658797914
0.5465453840814063,0.07889497899579917,397.1480469445147,126.31658647406016,-0.8405768658797914
0.5492060782503032,0.07927905581116224,397.67482778705954,126.31658647406016,-0.8405768658797914
0.5522658765445347,0.07972074414882976,398.2793968842542,126.31658647406016,-0.8405768658797914
0.5553256748387663,0.0801624324864973,398.8826610470772,126.31658647406016,-0.8405768658797914
0.5589176119667773,0.08068093618723746,399.58918909986346,126.31658647406016,-0.8405768658797914
0.5625095490947882,0.0811994398879776,400.2939485332733,126.31658647406016,-0.8405768658797914
0.5650372085552403,0.08156431286257251,400.78883863557166,126.31658647406016,-0.8405768658797914
0.567963972141027,0.0819867973594719,401.3607919089062,126.31658647406016,-0.8405768658797914
0.5690282498085858,0.08214042808561713,401.56848978110764,126.31658647406016,-0.8405768658797914
0.5698264580592549,0.08225565113022605,401.72416377687557,126.31658647406016,-0.8405768658797914
0.5712898398521483,0.08246689337867574,402.00934539838084,126.31658647406016,-0.8405768658797914
0.5732853604788211,0.08275495099019804,402.39777072310034,126.31658647406016,-0.8405768658797914
0.5758130199392731,0.08311982396479296,402.88902000264454,126.31658647406016,-0.8405768658797914
0.5802031653179532,0.08375355071014204,403.74024825135245,126.31658647406016,-0.8405768658797914
0.5872540048655303,0.08477135427085418,405.1021343166241,126.31658647406016,-0.8405768658797914
0.5925753932033243,0.08553950790158033,406.1257542744584,126.31658647406016,-0.8405768658797914
0.5933736014539933,0.08565473094618924,406.2789875101502,126.31658647406016,-0.8405768658797914
0.5941718097046624,0.08576995399079816,406.4321403762413,126.31658647406016,-0.8405768658797914
0.5974976774157837,0.08625005001000201,407.06941554010405,126.31658647406016,-0.8405768658797914
0.5977637468326734,0.08628845769153831,407.12033771144195,126.31658647406016,-0.8405768658797914
0.6016217533775741,0.08684536907381477,407.8577186769529,126.31658647406016,-0.8405768658797914
0.603351204587357,0.08709501900380076,408.18766989386467,126.31658647406016,-0.8405768658797914
0.6042824475464711,0.08722944588917785,408.365183146293,126.31658647406016,-0.8405768658797914
0.6064110028815887,0.0875367073414683,408.77052758341574,126.31658647406016,-0.8405768658797914
0.6098699053011547,0.0880360072014403,409.428030822802,126.31658647406016,-0.8405768658797914
0.6133288077207208,0.08853530706141229,410.0840813279559,126.31658647406016,-0.8405768658797914
0.6157234324727281,0.08888097619523905,410.53742511573915,126.31658647406016,-0.8405768658797914
0.6197144737260736,0.08945709141828366,411.29147304737046,126.31658647406016,-0.8405768658797914
0.620246612559853,0.08953390678135628,411.391869485529,126.31658647406016,-0.8405768658797914
0.6214439249358567,0.08970674134826966,411.61763872996306,126.31658647406016,-0.8405768658797914
0.6245037232300883,0.0901484296859372,412.1938352105525,126.31658647406016,-0.8405768658797914
0.6266322785652059,0.09045569113822766,412.5940183449642,126.31658647406016,-0.8405768658797914
0.6332840139874484,0.09141588317663533,413.8411872855967,126.31658647406016,-0.8405768658797914
0.6375411246576835,0.09203040608121625,414.63669501964193,126.31658647406016,-0.8405768658797914
0.6392705758674666,0.09228005601120225,414.95927796269274,126.31658647406016,-0.8405768658797914
0.6420643047448084,0.09268333666733347,415.4796554464733,126.31658647406016,-0.8405768658797914
0.6431285824123671,0.0928369673934787,415.67766211656857,126.31658647406016,-0.8405768658797914
0.6436607212461466,0.09291378275655131,415.7766175269258,126.31658647406016,-0.8405768658797914
0.6453901724559297,0.09316343268653732,416.0980024849779,126.31658647406016,-0.8405768658797914
0.6475187277910472,0.09347069413882778,416.49309249336864,126.31658647406016,-0.8405768658797914
0.6479178319163817,0.09352830566113222,416.5671154467501,126.31658647406016,-0.8405768658797914
0.6536383243795103,0.09435407081416283,417.626164623396,126.31658647406016,-0.8405768658797914
0.6576293656328558,0.09493018603720745,418.3628964578257,126.31658647406016,-0.8405768658797914
0.6589597127173042,0.09512222444488898,418.60808597127385,126.31658647406016,-0.8405768658797914
0.6614873721777564,0.0954870974194839,419.07341484610254,126.31658647406016,-0.8405768658797914
0.6657444828479917,0.09610162032406482,419.85556219904146,126.31658647406016,-0.8405768658797914
0.6686712464337784,0.0965241048209642,420.3921573807138,126.31658647406016,-0.8405768658797914
0.670799801768896,0.09683136627325466,420.7818332663889,126.31658647406016,-0.8405768658797914
0.6763872595235796,0.0976379275855171,421.8024449406371,126.31658647406016,-0.8405768658797914
0.6789149189840318,0.09800280056011203,422.2630695031971,126.31658647406016,-0.8405768658797914
0.6809104396107045,0.09829085817163433,422.62624820267837,126.31658647406016,-0.8405768658797914
0.6823738214035979,0.09850210042008402,422.892315485689,126.31658647406016,-0.8405768658797914
0.6879612791582815,0.09930866173234647,423.9061683822187,126.31658647406016,-0.8405768658797914
0.6890255568258403,0.0994622924584917,424.0989185840521,126.31658647406016,-0.8405768658797914
0.6908880427440682,0.09973114622924585,424.4359522751828,126.31658647406016,-0.8405768658797914
0.6915532162862925,0.09982716543308662,424.55623555289094,126.31658647406016,-0.8405768658797914