File: datasets/aisi_316_L/data/M1/train_8.csv
Time(s),Strain(%),Stress(MPa),Temp(C),Log_SR(s-1)
0.0,0.0,0.0,285.63185948126187,0.1741397938453595
1.0714704269104551e-05,1.6e-05,2.86198825,285.63185948126187,0.1741397938453595
1.339338033638069e-05,1.9999999999999998e-05,3.5774853125,285.63185948126187,0.1741397938453595
3.053690716694797e-05,4.56e-05,8.1566665125,285.63185948126187,0.1741397938453595
3.857293536877639e-05,5.76e-05,10.3031577,285.63185948126187,0.1741397938453595
5.196631570515708e-05,7.76e-05,13.8806430125,285.63185948126187,0.1741397938453595
6.428822561462731e-05,9.6e-05,17.1719295,285.63185948126187,0.1741397938453595
7.339572424336618e-05,0.0001096,19.604619512499998,285.63185948126187,0.1741397938453595
8.036028201828414e-05,0.00011999999999999999,21.464911875,285.63185948126187,0.1741397938453595
9.536086799503051e-05,0.0001424,25.471695425,285.63185948126187,0.1741397938453595
0.00011036145397177689,0.0001648,29.478478974999998,285.63185948126187,0.1741397938453595
0.00012107615824088145,0.0001808,32.340467225,285.63185948126187,0.1741397938453595
0.00014036262592526965,0.0002096,37.492046075,285.63185948126187,0.1741397938453595
0.00016500644574421008,0.00024639999999999997,44.074619049999995,285.63185948126187,0.1741397938453595
0.00017464967958640421,0.0002608,46.650408475,285.63185948126187,0.1741397938453595
0.00017786409086713558,0.0002656,47.50900495,285.63185948126187,0.1741397938453595
0.00017947129650750125,0.000268,47.938303187500004,285.63185948126187,0.1741397938453595
0.00018214997257477738,0.000272,48.653800249999996,285.63185948126187,0.1741397938453595
0.00018750732470932966,0.00028,50.084794374999994,285.63185948126187,0.1741397938453595
0.00020090070504571035,0.0003,53.662279687499996,285.63185948126187,0.1741397938453595
0.00021268687974172534,0.00031759999999999997,56.81046676249999,285.63185948126187,0.1741397938453595
0.00021482982059554628,0.0003208,57.3828644125,285.63185948126187,0.1741397938453595
0.00022768746571847173,0.00033999999999999997,60.81725031249999,285.63185948126187,0.1741397938453595
0.00023733069956066583,0.0003544,63.3930397375,285.63185948126187,0.1741397938453595
0.00025608143203159877,0.00038239999999999997,68.40151917499999,285.63185948126187,0.1741397938453595
0.000275367899715987,0.00041119999999999997,73.553098025,285.63185948126187,0.1741397938453595
0.0002850111335581811,0.0004256,76.12888745,285.63185948126187,0.1741397938453595
0.00029626157304074086,0.00044239999999999997,79.1339751125,285.63185948126187,0.1741397938453595
0.0003069762773098454,0.0004584,81.99596336249999,285.63185948126187,0.1741397938453595
0.000315548040725129,0.00047119999999999996,84.28555396249999,285.63185948126187,0.1741397938453595
0.0003316200971287859,0.0004952,88.5785363375,285.63185948126187,0.1741397938453595
0.00034233480139789045,0.0005112,91.4405245875,285.63185948126187,0.1741397938453595
0.00034822788874589795,0.00052,93.014618125,285.63185948126187,0.1741397938453595
0.00038519361847430864,0.0005752,102.8884775875,285.63185948126187,0.1741397938453595
0.00040126567487796546,0.0005991999999999999,107.18145996249999,285.63185948126187,0.1741397938453595
0.00040662302701251776,0.0006072,108.6124540875,285.63185948126187,0.1741397938453595
0.0004093017030797939,0.0006112,109.32795115,285.63185948126187,0.1741397938453595
0.0004194806721354432,0.0006263999999999999,112.0468399875,285.63185948126187,0.1741397938453595
0.0004226950834161746,0.0006312,112.90543646249999,285.63185948126187,0.1741397938453595
0.00043394552289873433,0.0006479999999999999,115.91052412499998,285.63185948126187,0.1741397938453595
0.00043823140460637615,0.0006544,117.055319425,285.63185948126187,0.1741397938453595
0.0004575178722907644,0.0006832,122.206898275,285.63185948126187,0.1741397938453595
0.0004639466948522271,0.0006927999999999999,123.92409122499998,285.63185948126187,0.1741397938453595
0.0004698397822002346,0.0007015999999999999,125.49818476249999,285.63185948126187,0.1741397938453595
0.0004955550724460855,0.00074,132.3669565625,285.63185948126187,0.1741397938453595
0.0005191274218381155,0.0007752,138.6633307125,285.63185948126187,0.1741397938453595
0.0005293063908937648,0.0007903999999999999,141.38221954999997,285.63185948126187,0.1741397938453595
0.0005314493317475858,0.0007936,141.9546172,285.63185948126187,0.1741397938453595
0.0005330565373879515,0.0007959999999999999,142.38391543749998,285.63185948126187,0.1741397938453595
0.0005384138895225037,0.0008039999999999999,143.8149095625,285.63185948126187,0.1741397938453595
0.0005464499177243321,0.000816,145.96140075,285.63185948126187,0.1741397938453595
0.0005518072698588844,0.000824,147.392394875,285.63185948126187,0.1741397938453595
0.0005673435910490861,0.0008472,151.5422778375,285.63185948126187,0.1741397938453595
0.0005721652079701831,0.0008544,152.83017255,285.63185948126187,0.1741397938453595
0.0006048450559909519,0.0009031999999999999,161.5592367125,285.63185948126187,0.1741397938453595
0.0006203813771811535,0.0009264,165.70911967499998,285.63185948126187,0.1741397938453595
0.000640203580078997,0.0009559999999999999,171.0037979375,285.63185948126187,0.1741397938453595
0.0006546684308422881,0.0009776,174.867482075,285.63185948126187,0.1741397938453595
0.0006584185773364748,0.0009832,175.8691779625,285.63185948126187,0.1741397938453595
0.0006878840140765122,0.0010272,183.73964565,285.63185948126187,0.1741397938453595
0.0007168137156030945,0.0010704,185.8368548927358,285.63185948126187,0.1741397938453595
0.0007419932706354903,0.001108,186.05611180204855,285.63185948126187,0.1741397938453595
0.0007521722396911396,0.0011232,186.1439215681582,285.63185948126187,0.1741397938453595
0.0007575295918256918,0.0011312,186.1899510225881,285.63185948126187,0.1741397938453595
0.000783780617284998,0.0011704,186.41368566601,285.63185948126187,0.1741397938453595
0.0008052100258232071,0.0012024,186.59416716944935,285.63185948126187,0.1741397938453595
0.0008186034061595878,0.0012224,186.70601729653674,285.63185948126187,0.1741397938453595
0.0008207463470134086,0.0012255999999999999,186.72384687276156,285.63185948126187,0.1741397938453595
0.0008346754625632447,0.0012464,186.8392997174194,285.63185948126187,0.1741397938453595
0.0008437829611919834,0.0012599999999999998,186.91438206472867,285.63185948126187,0.1741397938453595
0.0008534261950341776,0.0012744,186.99353734178078,285.63185948126187,0.1741397938453595
0.0008694982514378343,0.0012984,187.1246920037819,285.63185948126187,0.1741397938453595
0.0008732483979320211,0.001304,187.15515830670572,285.63185948126187,0.1741397938453595
0.0008796772204934836,0.0013135999999999998,187.20726780689958,285.63185948126187,0.1741397938453595
0.0008903919247625884,0.0013296,187.2937881309344,285.63185948126187,0.1741397938453595
0.0009037853050989689,0.0013495999999999998,187.40136963373686,285.63185948126187,0.1741397938453595
0.0009080711868066109,0.001356,187.4356641609619,285.63185948126187,0.1741397938453595
0.0009268219192775438,0.001384,187.58496657727264,285.63185948126187,0.1741397938453595
0.0009445011813215663,0.0014104,187.7246620439029,285.63185948126187,0.1741397938453595
0.0009482513278157528,0.001416,187.75416289152386,285.63185948126187,0.1741397938453595
0.0009568230912310366,0.0014288,187.82142306955896,285.63185948126187,0.1741397938453595
0.0009718236772077828,0.0014512,187.9385656397907,285.63185948126187,0.1741397938453595
0.0009809311758365218,0.0014647999999999998,188.00934392818905,285.63185948126187,0.1741397938453595
0.0009873599983979844,0.0014743999999999998,188.05915085139546,285.63185948126187,0.1741397938453595
0.0009916458801056264,0.0014808,188.09228522023867,285.63185948126187,0.1741397938453595
0.0010012891139478204,0.0014952,188.16663402585485,285.63185948126187,0.1741397938453595
0.0010200398464187534,0.0015232,188.31040654615293,285.63185948126187,0.1741397938453595
0.001029147345047492,0.0015367999999999998,188.37986670208966,285.63185948126187,0.1741397938453595
0.001033433226755134,0.0015432,188.4124708452052,285.63185948126187,0.1741397938453595
0.001052183959226067,0.0015712,188.5544984024129,285.63185948126187,0.1741397938453595
0.001059148517000985,0.0015815999999999998,188.60699964575636,285.63185948126187,0.1741397938453595
0.0010703989564835447,0.0015983999999999998,188.69152582276382,285.63185948126187,0.1741397938453595
0.0010720061621239103,0.0016007999999999999,188.7035726462809,285.63185948126187,0.1741397938453595
0.0010773635142584627,0.0016087999999999999,188.74367794931263,285.63185948126187,0.1741397938453595
0.001080577925539194,0.0016136,188.76770379958268,285.63185948126187,0.1741397938453595
0.0010832566016064703,0.0016175999999999999,188.78770405678137,285.63185948126187,0.1741397938453595
0.0010859352776737463,0.0016216,188.80768503517228,285.63185948126187,0.1741397938453595
0.00109450704108903,0.0016343999999999998,188.87149537953408,285.63185948126187,0.1741397938453595
0.0011025430692908583,0.0016464,188.9311407984097,285.63185948126187,0.1741397938453595
0.0011041502749312242,0.0016488,188.94304951049597,285.63185948126187,0.1741397938453595
0.0011282583595367093,0.0016848,189.12087673237224,285.63185948126187,0.1741397938453595
0.0011346871820981722,0.0016944,189.16804626323912,285.63185948126187,0.1741397938453595
0.0011400445342327245,0.0017024,189.20727464025,285.63185948126187,0.1741397938453595
0.0011443304159403662,0.0017088,189.23860560280542,285.63185948126187,0.1741397938453595
0.0011518307089287395,0.00172,189.29332488960267,285.63185948126187,0.1741397938453595
0.0011652240892651201,0.00174,189.3906935186187,285.63185948126187,0.1741397938453595
0.0011748673231073141,0.0017544,189.46052886068708,285.63185948126187,0.1741397938453595
0.0011812961456687768,0.001764,189.50696160144912,285.63185948126187,0.1741397938453595
0.0011898679090840605,0.0017767999999999998,189.56871891054965,285.63185948126187,0.1741397938453595
0.0011984396724993441,0.0017896,189.6303029514212,285.63185948126187,0.1741397938453595
0.0012043327598473517,0.0017984,189.6725423655318,285.63185948126187,0.1741397938453595
0.0012145117289030008,0.0018135999999999998,189.74531198274195,285.63185948126187,0.1741397938453595
0.001219333345824098,0.0018208,189.779698747291,285.63185948126187,0.1741397938453595
0.0012396912839353967,0.0018512,189.9243065268502,285.63185948126187,0.1741397938453595
0.0012445129008564937,0.0018583999999999999,189.95841973064373,285.63185948126187,0.1741397938453595
0.001255227605125598,0.0018743999999999998,190.03404285027054,285.63185948126187,0.1741397938453595
0.0012761212784503523,0.0019056,190.18078770823263,285.63185948126187,0.1741397938453595
0.0012798714249445387,0.0019111999999999998,190.20702704001076,285.63185948126187,0.1741397938453595
0.0012889789235732776,0.0019248,190.27062660937045,285.63185948126187,0.1741397938453595
0.0013007650982692926,0.0019424,190.35267238414193,285.63185948126187,0.1741397938453595
0.0013173728898864048,0.0019672,190.46779193311727,285.63185948126187,0.1741397938453595
0.0013259446533016883,0.00198,190.52698693620704,285.63185948126187,0.1741397938453595
0.0013355878871438825,0.0019944,190.5934032121018,285.63185948126187,0.1741397938453595
0.0013495170026937185,0.0020152,190.6890086089412,285.63185948126187,0.1741397938453595
0.0013554100900417256,0.0020239999999999998,190.72934110459957,285.63185948126187,0.1741397938453595
0.0013602317069628229,0.0020312,190.76228957505603,285.63185948126187,0.1741397938453595
0.0013688034703781065,0.002044,190.82075238721535,285.63185948126187,0.1741397938453595
0.0013757680281530245,0.0020544,190.86814835821576,285.63185948126187,0.1741397938453595
0.0013779109690068452,0.0020575999999999997,190.88271289637,285.63185948126187,0.1741397938453595
0.0013891614084894054,0.0020744,190.95903227664945,285.63185948126187,0.1741397938453595
0.0013977331719046888,0.0020872,191.0170186886709,285.63185948126187,0.1741397938453595
0.0014063049353199724,0.0021,191.07486657805714,285.63185948126187,0.1741397938453595
0.0014261271382178158,0.0021295999999999997,191.20811569318974,285.63185948126187,0.1741397938453595
0.0014379133129138308,0.0021471999999999997,191.28700249909411,285.63185948126187,0.1741397938453595
0.0014539853693174877,0.0021712,191.39417021197147,285.63185948126187,0.1741397938453595
0.001468985955294234,0.0021936,191.49377733182592,285.63185948126187,0.1741397938453595
0.0014775577187095177,0.0022064,191.55051757395196,285.63185948126187,0.1741397938453595
0.0014882724229786223,0.0022224,191.62126267234203,285.63185948126187,0.1741397938453595
0.0014952369807535403,0.0022328,191.66714049201644,285.63185948126187,0.1741397938453595
0.0014968441863939057,0.0022351999999999997,191.67771583705152,285.63185948126187,0.1741397938453595
0.001511309037157197,0.0022567999999999998,191.77269549117008,285.63185948126187,0.1741397938453595
0.0015193450653590256,0.0022688,191.8253087550378,285.63185948126187,0.1741397938453595
0.0015289882992012196,0.0022832,191.88830163043548,285.63185948126187,0.1741397938453595
0.001546667561245242,0.0023095999999999998,192.00338760824707,285.63185948126187,0.1741397938453595
0.0015509534429528839,0.002316,192.0312098376343,285.63185948126187,0.1741397938453595
0.0015563107950874364,0.002324,192.06594549466558,285.63185948126187,0.1741397938453595
0.0015611324120085332,0.0023312,192.09716773503524,285.63185948126187,0.1741397938453595
0.0015782759388391005,0.0023568,192.2078768546235,285.63185948126187,0.1741397938453595
0.0015889906431082051,0.0023728,192.27683194590514,285.63185948126187,0.1741397938453595
0.0015954194656696678,0.0023824,192.31811796342967,285.63185948126187,0.1741397938453595
0.0015991696121638544,0.002388,192.3421715109661,285.63185948126187,0.1741397938453595
0.001602919758658041,0.0023936,192.36620306981325,285.63185948126187,0.1741397938453595
0.0016120272572867798,0.0024072,192.42447432066015,285.63185948126187,0.1741397938453595
0.0016227419615558844,0.0024232,192.49286460867282,285.63185948126187,0.1741397938453595
0.001637742547532631,0.0024456,192.58831588085104,285.63185948126187,0.1741397938453595
0.001640956958813362,0.0024503999999999997,192.60872529565128,285.63185948126187,0.1741397938453595
0.001647385781374825,0.00246,192.64949740967748,285.63185948126187,0.1741397938453595
0.0016554218095766531,0.002472,192.70037539534937,285.63185948126187,0.1741397938453595
0.0016693509251264893,0.0024928,192.78833631569577,285.63185948126187,0.1741397938453595
0.001684887246316691,0.002516,192.88610957981092,285.63185948126187,0.1741397938453595
0.0016993520970799822,0.0025376,192.976824256675,285.63185948126187,0.1741397938453595
0.0017106025365625419,0.0025544,193.0471720795838,285.63185948126187,0.1741397938453595
0.0017218529760451016,0.0025712,193.1173396909845,285.63185948126187,0.1741397938453595
0.0017314962098872956,0.0025856,193.1773411640295,285.63185948126187,0.1741397938453595
0.0017331034155276615,0.002588,193.18732872552312,285.63185948126187,0.1741397938453595
0.0017470325310774974,0.0026088,193.27373680432356,285.63185948126187,0.1741397938453595
0.0017593544409869673,0.0026271999999999997,193.34995100086854,285.63185948126187,0.1741397938453595
0.0017663189987618855,0.0026376,193.39293650128033,285.63185948126187,0.1741397938453595
0.0017716763508964376,0.0026455999999999997,193.42595730606288,285.63185948126187,0.1741397938453595
0.0017813195847386318,0.00266,193.48529678811082,285.63185948126187,0.1741397938453595
0.0018027489932768408,0.002692,193.6167155971224,285.63185948126187,0.1741397938453595
0.0018134636975459455,0.002708,193.68219642892817,285.63185948126187,0.1741397938453595
0.0018177495792535874,0.0027144,193.70834649258444,285.63185948126187,0.1741397938453595
0.001830607224376513,0.0027336,193.78665278725188,285.63185948126187,0.1741397938453595
0.0018429291342859828,0.0027519999999999997,193.86149528588587,285.63185948126187,0.1741397938453595
0.0018536438385550877,0.002768,193.9264172273635,285.63185948126187,0.1741397938453595
0.0018600726611165501,0.0027776,193.96530014509443,285.63185948126187,0.1741397938453595
0.001863822807610737,0.0027832,193.98795764339985,285.63185948126187,0.1741397938453595
0.0018707873653856547,0.0027936,194.02998874042657,285.63185948126187,0.1741397938453595
0.001878287658374028,0.0028048,194.07518481075226,285.63185948126187,0.1741397938453595
0.0018965026556315057,0.002832,194.18465466011162,285.63185948126187,0.1741397938453595
0.001916324858529349,0.0028615999999999997,194.3033187429315,285.63185948126187,0.1741397938453595
0.0019500761769770283,0.0029119999999999997,194.50427278372283,285.63185948126187,0.1741397938453595
0.0019532905882577597,0.0029167999999999998,194.52334024270434,285.63185948126187,0.1741397938453595
0.001968291174234506,0.0029392,194.61216041325292,285.63185948126187,0.1741397938453595
0.001972577055942148,0.0029456,194.63748906549662,285.63185948126187,0.1741397938453595
0.0019784701432901553,0.0029544,194.6722809458962,285.63185948126187,0.1741397938453595
0.001991327788413081,0.0029736,194.74805052436238,285.63185948126187,0.1741397938453595
0.002007399844816738,0.0029976,194.84249471986067,285.63185948126187,0.1741397938453595
0.002014900137805111,0.0030088,194.88646771300253,285.63185948126187,0.1741397938453595
0.0020277577829280365,0.003028,194.96170175673078,285.63185948126187,0.1741397938453595
0.0020379367519836856,0.0030432,195.02113017757947,285.63185948126187,0.1741397938453595
0.0020400796928375067,0.0030464,195.0336266604151,285.63185948126187,0.1741397938453595
0.002057758954881529,0.0030727999999999997,195.1365280338487,285.63185948126187,0.1741397938453595
0.0020631163070160816,0.0030808,195.16764212127904,285.63185948126187,0.1741397938453595
0.0020657949830833575,0.0030848,195.18318734761715,285.63185948126187,0.1741397938453595
0.00207222380564482,0.0030943999999999998,195.2204638517239,285.63185948126187,0.1741397938453595
0.0021011535071714027,0.0031376,195.38765310410588,285.63185948126187,0.1741397938453595
0.0021107967410135967,0.003152,195.44318303644184,285.63185948126187,0.1741397938453595
0.00211829703400197,0.0031631999999999997,195.486304609999,285.63185948126187,0.1741397938453595
0.0021241901213499776,0.003172,195.52014408729107,285.63185948126187,0.1741397938453595
0.002136512031259448,0.0031904,195.59078127494513,285.63185948126187,0.1741397938453595
0.002147226735528552,0.0032064,195.65207586908465,285.63185948126187,0.1741397938453595
0.002150441146809284,0.0032112,195.6704409715068,285.63185948126187,0.1741397938453595
0.0021536555580900147,0.0032159999999999997,195.68879537093062,285.63185948126187,0.1741397938453595
0.002161155851078388,0.0032272,195.73158080469463,285.63185948126187,0.1741397938453595
0.002174549231414769,0.0032472,195.80783960719944,285.63185948126187,0.1741397938453595
0.002183656730043508,0.0032608,195.85959099067065,285.63185948126187,0.1741397938453595
0.002186335406110784,0.0032648,195.87479595682203,285.63185948126187,0.1741397938453595
0.0021900855526049705,0.0032703999999999997,195.89607070941216,285.63185948126187,0.1741397938453595
0.0021970501103798883,0.0032808,195.9355433091122,285.63185948126187,0.1741397938453595
0.0022066933442220823,0.0032952,195.99011721068914,285.63185948126187,0.1741397938453595
0.0022141936372104556,0.0033063999999999997,196.0324993009425,285.63185948126187,0.1741397938453595
0.0022163365780642767,0.0033095999999999998,196.04459818098093,285.63185948126187,0.1741397938453595
0.0022345515753217546,0.0033368,196.1472551087328,285.63185948126187,0.1741397938453595
0.002250087896511956,0.0033599999999999997,196.23455779849758,285.63185948126187,0.1741397938453595
0.002274195981117441,0.0033959999999999997,196.3695634912878,285.63185948126187,0.1741397938453595
0.0022779461276116277,0.0034016,196.3905141071719,285.63185948126187,0.1741397938453595
0.0022875893614538218,0.0034159999999999998,196.44432544661478,285.63185948126187,0.1741397938453595
0.002295089654442195,0.0034272,196.48611757157028,285.63185948126187,0.1741397938453595
0.0023063400939247547,0.003444,196.54870602686242,285.63185948126187,0.1741397938453595
0.002315983327766949,0.0034584,196.60225856283046,285.63185948126187,0.1741397938453595
0.0023266980320360534,0.0034744,196.66165949174072,285.63185948126187,0.1741397938453595
0.0023309839137436953,0.0034808,196.68538998038943,285.63185948126187,0.1741397938453595
0.002337412736305158,0.0034904,196.72095383226014,285.63185948126187,0.1741397938453595
0.0023459844997204414,0.0035031999999999997,196.76831301727185,285.63185948126187,0.1741397938453595
0.002365806702618285,0.0035328,196.87757341028217,285.63185948126187,0.1741397938453595
0.002374378466033569,0.0035456,196.9247105076078,285.63185948126187,0.1741397938453595
0.00240116522670633,0.0035856,197.07158799421114,285.63185948126187,0.1741397938453595
0.0024086655196947034,0.0035968,197.11259899859712,285.63185948126187,0.1741397938453595
0.002424201840884905,0.00362,197.19739227096287,285.63185948126187,0.1741397938453595
0.002447774190276935,0.0036552,197.32564053153538,285.63185948126187,0.1741397938453595
0.0024536672776249422,0.0036639999999999997,197.35762722482255,285.63185948126187,0.1741397938453595
0.002467596393174778,0.0036848,197.4331132693976,285.63185948126187,0.1741397938453595
0.002478311097443883,0.0037007999999999997,197.4910664316281,285.63185948126187,0.1741397938453595
0.0024959903594879056,0.0037272,197.58647597345052,285.63185948126187,0.1741397938453595
0.0024975975651282713,0.0037296,197.5951364781076,285.63185948126187,0.1741397938453595
0.00250670506375701,0.0037432,197.64417167857368,285.63185948126187,0.1741397938453595
0.002514741091958838,0.0037551999999999998,197.68738036043743,285.63185948126187,0.1741397938453595
0.002518491238453025,0.0037608,197.70752598029912,285.63185948126187,0.1741397938453595
0.002524384325801032,0.0037695999999999997,197.73915976210495,285.63185948126187,0.1741397938453595
0.002532420354002861,0.0037816,197.78225036221966,285.63185948126187,0.1741397938453595
0.002544206528698876,0.0037992,197.84535357061614,285.63185948126187,0.1741397938453595
0.0025533140273276147,0.0038128,197.89403708664793,285.63185948126187,0.1741397938453595
0.002561350055529443,0.0038247999999999997,197.93693691702455,285.63185948126187,0.1741397938453595
0.0025822437288541967,0.0038559999999999996,198.04823153169988,285.63185948126187,0.1741397938453595
0.0025876010809887493,0.003864,198.07671197263818,285.63185948126187,0.1741397938453595
0.002591886962696391,0.0038704,198.09947977131222,285.63185948126187,0.1741397938453595
0.0025951013739771225,0.0038751999999999997,198.11654598596797,285.63185948126187,0.1741397938453595
0.0025972443148309433,0.0038783999999999997,198.12791888251888,285.63185948126187,0.1741397938453595
0.00260099446132513,0.003884,198.14781264951912,285.63185948126187,0.1741397938453595
0.0026042088726058615,0.0038888,198.16485554799212,285.63185948126187,0.1741397938453595
0.002615459312088421,0.0039056,198.22444119259254,285.63185948126187,0.1741397938453595
0.0026272454867844364,0.0039232,198.28675713475693,285.63185948126187,0.1741397938453595
0.002638495926266996,0.00394,198.34613890660867,285.63185948126187,0.1741397938453595
0.0026524250418168316,0.0039607999999999996,198.41952255795584,285.63185948126187,0.1741397938453595
0.0026679613630070332,0.003984,198.5011964757145,285.63185948126187,0.1741397938453595
0.002676533126422317,0.0039968,198.54617854091197,285.63185948126187,0.1741397938453595
0.002820138456106084,0.00421124224844969,199.29161585940693,285.63185948126187,0.1741397938453595
0.002923020193436954,0.004364872974594919,199.81658619864317,285.63185948126187,0.1741397938453595
0.0030516223651005417,0.004556911382276456,200.4627721832936,285.63185948126187,0.1741397938453595
0.0036560525719194024,0.0054594918983796765,203.36783364190836,285.63185948126187,0.1741397938453595
0.0037074934405848373,0.005536307261452291,203.60606502816873,285.63185948126187,0.1741397938453595
0.004119020389908317,0.006150830166033207,205.46758592729225,285.63185948126187,0.1741397938453595
0.004260482778738263,0.006362072414482897,206.09053098945066,285.63185948126187,0.1741397938453595
0.004646289293729025,0.006938187637527506,207.74975490343755,285.63185948126187,0.1741397938453595
0.00478775168255897,0.007149429885977195,208.34455411794247,285.63185948126187,0.1741397938453595
0.004980654940054351,0.0074374874974994995,209.1447131505044,285.63185948126187,0.1741397938453595
0.005173558197549733,0.007725545109021804,209.93287312901091,285.63185948126187,0.1741397938453595
0.005340741020712396,0.007975195039007801,210.60671803208993,285.63185948126187,0.1741397938453595
0.005687966884204082,0.00849369873974795,211.98050397591814,285.63185948126187,0.1741397938453595
0.005880870141699463,0.008781756351270254,212.72957015564143,285.63185948126187,0.1741397938453595
0.006240956222357508,0.009319463892778556,214.1026700314789,285.63185948126187,0.1741397938453595
0.006536741217183759,0.00976115223044609,215.20759644496363,285.63185948126187,0.1741397938453595
0.006652483171680988,0.009933986797359472,215.63462903894015,285.63185948126187,0.1741397938453595
0.006883967080675445,0.010279655931186238,216.48009887127284,285.63185948126187,0.1741397938453595
0.007051149903838107,0.010529305861172233,217.08383457853486,285.63185948126187,0.1741397938453595
0.007385515550163434,0.011028605721144228,218.27481141806348,285.63185948126187,0.1741397938453595
0.007565558590492457,0.011297459491898379,218.90738710459922,285.63185948126187,0.1741397938453595
0.007809902716653274,0.0116623324664933,219.75657058050368,285.63185948126187,0.1741397938453595
0.0081442683629786,0.012161632326465293,220.902006066536,285.63185948126187,0.1741397938453595
0.008414332923472134,0.012564912982596519,221.81383110526812,285.63185948126187,0.1741397938453595
0.00874869856979746,0.013064212842568514,222.9270936208083,285.63185948126187,0.1741397938453595
0.008800139438462896,0.013141028205641128,223.0968806344395,285.63185948126187,0.1741397938453595
0.009314548125117245,0.013909181836367274,224.773987031981,285.63185948126187,0.1741397938453595
0.009558892251278062,0.014274054810962193,225.55792060303025,285.63185948126187,0.1741397938453595
0.00967463420577529,0.014446889377875576,225.92652622554007,285.63185948126187,0.1741397938453595
0.010163322458096922,0.015176635327065414,227.46427224352476,285.63185948126187,0.1741397938453595
0.010652010710418554,0.015906381276255252,228.97343722433914,285.63185948126187,0.1741397938453595
0.011295021568736489,0.01686657331466293,230.91865458678114,285.63185948126187,0.1741397938453595
0.01161652699789546,0.017346669333866773,231.87502802587713,285.63185948126187,0.1741397938453595
0.011680828083727253,0.017442688537707543,232.06505783204753,285.63185948126187,0.1741397938453595
0.011963752861387143,0.01786517303460692,232.8963888223623,285.63185948126187,0.1741397938453595
0.012298118507712473,0.018364472894578918,233.86904943384556,285.63185948126187,0.1741397938453595
0.012529602416706928,0.01871014202840568,234.5363961784079,285.63185948126187,0.1741397938453595
0.012761086325701387,0.01905581116223245,235.1989514898128,285.63185948126187,0.1741397938453595
0.013288355229522094,0.019843168633726746,236.69085094687026,285.63185948126187,0.1741397938453595
0.013416957401185682,0.020035207041408282,237.0512045123835,285.63185948126187,0.1741397938453595
0.01363558109301378,0.020361672334466892,237.66072928113448,285.63185948126187,0.1741397938453595
0.014059968259503619,0.020995399079815964,238.83315210334126,285.63185948126187,0.1741397938453595
0.01416284999683449,0.021149029805961193,239.11528736227768,285.63185948126187,0.1741397938453595
0.014574376946157968,0.02176355271054211,240.23592585170647,285.63185948126187,0.1741397938453595
0.014844441506651502,0.022166833366673334,240.96464430429535,285.63185948126187,0.1741397938453595
0.014998764112647806,0.022397279455891178,241.37873318143488,285.63185948126187,0.1741397938453595
0.01638766756661455,0.02447129425885177,245.03360619812224,285.63185948126187,0.1741397938453595
0.016644871909941725,0.024855371074214844,245.69696120695087,285.63185948126187,0.1741397938453595
0.01669631277860716,0.024932186437287458,245.82915117195938,285.63185948126187,0.1741397938453595
0.01691493647043526,0.02525865173034607,246.38919571485295,285.63185948126187,0.1741397938453595
0.017159280596596074,0.02562352470494099,247.01179773688912,285.63185948126187,0.1741397938453595
0.01739076450559053,0.025969193838767755,247.59844940347412,285.63185948126187,0.1741397938453595
0.017545087111586838,0.0261996399279856,247.98785948853833,285.63185948126187,0.1741397938453595
0.017596527980252272,0.026276455291058213,248.1173657030512,285.63185948126187,0.1741397938453595
0.017660829066084065,0.02637247449489898,248.27904102499136,285.63185948126187,0.1741397938453595
0.01769940971758314,0.026430086017203442,248.3759360281472,285.63185948126187,0.1741397938453595
0.018085216232573902,0.02700620124024805,249.34039818452214,285.63185948126187,0.1741397938453595
0.01850960339906374,0.02763992798559712,250.3920853465514,285.63185948126187,0.1741397938453595
0.019448399252207926,0.029041808361672333,252.68569529542276,285.63185948126187,0.1741397938453595
0.01961558207537059,0.029291458291658332,253.08957519358668,285.63185948126187,0.1741397938453595
0.01996280793886228,0.02980996199239848,253.92413818017803,285.63185948126187,0.1741397938453595
0.02046435640835027,0.030558911782356472,255.11969183393276,285.63185948126187,0.1741397938453595
0.020605818797180216,0.03077015403080616,255.45482607117364,285.63185948126187,0.1741397938453595
0.02085016292334103,0.03113502700540108,256.03158849465893,285.63185948126187,0.1741397938453595
0.02136457160999538,0.031903180636127224,257.23727898959703,285.63185948126187,0.1741397938453595
0.0217632383421525,0.03249849969993999,258.16391817672184,285.63185948126187,0.1741397938453595
0.02196900181681424,0.032805761152230446,258.63959192313297,285.63185948126187,0.1741397938453595
0.02203330290264604,0.03290178035607122,258.78788322441056,285.63185948126187,0.1741397938453595
0.02262487289229853,0.03378515703140628,260.1443349398765,285.63185948126187,0.1741397938453595
0.02286921701845935,0.0341500300060012,260.7005635117377,285.63185948126187,0.1741397938453595
0.0230106794072893,0.03436127225445089,261.0215312001396,285.63185948126187,0.1741397938453595
0.023152141796119245,0.03457251450290058,261.3417302534551,285.63185948126187,0.1741397938453595
0.02348650744244457,0.03507181436287257,262.095546411749,285.63185948126187,0.1741397938453595
0.024296701123925176,0.03628165633126626,263.9049500722754,285.63185948126187,0.1741397938453595
0.024476744164254192,0.0365505101020204,264.30382619018326,285.63185948126187,0.1741397938453595
0.02473394850758137,0.03693458691738348,264.87166997232015,285.63185948126187,0.1741397938453595
0.024862550679244956,0.03712662532506501,265.15472792982774,285.63185948126187,0.1741397938453595
0.025016873285241267,0.037357071414282864,265.49364486288727,285.63185948126187,0.1741397938453595
0.02524835719423572,0.037702740548109626,266.00049544112204,285.63185948126187,0.1741397938453595
0.025788486315222785,0.038509301860372075,267.1761507364516,285.63185948126187,0.1741397938453595
0.025839927183888216,0.03858611722344468,267.2876146814257,285.63185948126187,0.1741397938453595
0.026032830441383603,0.038874174834966996,267.70483597385964,285.63185948126187,0.1741397938453595
0.02639291652204164,0.03941188237647529,268.480437190175,285.63185948126187,0.1741397938453595
0.026714421951200613,0.03989197839567914,269.16945774967735,285.63185948126187,0.1741397938453595
0.02735743280951855,0.040852170434086815,270.5378725506738,285.63185948126187,0.1741397938453595
0.027640357587178442,0.0412746549309862,271.13599496620054,285.63185948126187,0.1741397938453595
0.027794680193174742,0.041505101020204035,271.46123699241303,285.63185948126187,0.1741397938453595
0.028154766273832794,0.042042808561712344,272.2174084847579,285.63185948126187,0.1741397938453595
0.028617734091821702,0.04273414682936587,273.18410974605797,285.63185948126187,0.1741397938453595
0.029273605167306,0.043713542708541706,274.54322696155265,285.63185948126187,0.1741397938453595
0.029453648207635023,0.04398239647929586,274.9142338122475,285.63185948126187,0.1741397938453595
0.02980087407112671,0.04450090018003601,275.62725876685005,285.63185948126187,0.1741397938453595
0.030289562323448347,0.04523064612922585,276.6253106208642,285.63185948126187,0.1741397938453595
0.030443884929444647,0.04546109221844369,276.93917758680755,285.63185948126187,0.1741397938453595
0.0306753688384391,0.04580676135227045,277.40881710590304,285.63185948126187,0.1741397938453595
0.030893992530267204,0.04613322664532907,277.8510980282131,285.63185948126187,0.1741397938453595
0.031099756004928942,0.046440488097619526,278.2662486937418,285.63185948126187,0.1741397938453595
0.0313312399139234,0.04678615723144629,278.7320148683342,285.63185948126187,0.1741397938453595
0.031498422737086064,0.04703580716143228,279.06756729952366,285.63185948126187,0.1741397938453595
0.031691325994581444,0.047323864772954596,279.4538812958955,285.63185948126187,0.1741397938453595
0.03212857337823764,0.04797679535907182,280.32614716150357,285.63185948126187,0.1741397938453595
0.032462939024562966,0.04847609521904381,280.99005374624375,285.63185948126187,0.1741397938453595
0.03254010032756112,0.04859131826365273,281.14288359398535,285.63185948126187,0.1741397938453595
0.032900186408219165,0.04912902580516103,281.8542291086132,285.63185948126187,0.1741397938453595
0.032990207928383676,0.04926345269053811,282.0315902582479,285.63185948126187,0.1741397938453595
0.03308022944854819,0.04939787957591518,282.2087627591174,285.63185948126187,0.1741397938453595
0.0336074983523689,0.05018523704740949,283.24273624974165,285.63185948126187,0.1741397938453595
0.03412190703902325,0.05095339067813563,284.2454111092758,285.63185948126187,0.1741397938453595
0.03427622964501955,0.05118383676735347,284.54506173141556,285.63185948126187,0.1741397938453595
0.034391971599516784,0.05135667133426686,284.7694545287631,285.63185948126187,0.1741397938453595
0.03461059529134487,0.05168313662732546,285.19250567155314,285.63185948126187,0.1741397938453595
0.03476491789734118,0.05191358271654331,285.4905027609991,285.63185948126187,0.1741397938453595
0.03490638028617113,0.052124824964993,285.7632138692946,285.63185948126187,0.1741397938453595
0.035215025498163736,0.05258571714342869,286.35672827684084,285.63185948126187,0.1741397938453595
0.03562655244748722,0.053200240048009606,287.14493456953466,285.63185948126187,0.1741397938453595
0.03569085353331901,0.05329625925185037,287.2677703189624,285.63185948126187,0.1741397938453595
0.03634672460880331,0.05427565513102621,288.51580421824445,285.63185948126187,0.1741397938453595
0.03651390743196597,0.054525305061012205,288.8325219059429,285.63185948126187,0.1741397938453595
0.03714405807311754,0.055466293258651725,290.0212547577238,285.63185948126187,0.1741397938453595
0.03732410111344657,0.05573514702940588,290.35944473096976,285.63185948126187,0.1741397938453595
0.03767132697693826,0.05625365073014603,291.00987694324346,285.63185948126187,0.1741397938453595
0.03779992914860184,0.05644568913782756,291.25018387693603,285.63185948126187,0.1741397938453595
0.038018552840429945,0.05677215443088618,291.65797518814213,285.63185948126187,0.1741397938453595
0.03816001522925989,0.05698339667933587,291.92135290589243,285.63185948126187,0.1741397938453595
0.03872586478457967,0.057828365673134624,292.9710781356338,285.63185948126187,0.1741397938453595
0.03904737021373864,0.05830846169233847,293.564847681113,285.63185948126187,0.1741397938453595
0.03907309064807136,0.058346869373874774,293.61226671841615,285.63185948126187,0.1741397938453595
0.039381735860063966,0.05880776155231046,294.1803489198662,285.63185948126187,0.1741397938453595
0.039484617597394835,0.05896139227845569,294.3693234484233,285.63185948126187,0.1741397938453595
0.039780402592221084,0.05940308061612322,294.9115584796344,285.63185948126187,0.1741397938453595
0.0398704241123856,0.0595375075015003,295.07627413608793,285.63185948126187,0.1741397938453595
0.040140488672879136,0.05994078815763153,295.5695530458955,285.63185948126187,0.1741397938453595
0.040204789758710925,0.060036807361472294,295.686809428663,285.63185948126187,0.1741397938453595
0.04110500496035604,0.06138107621524305,297.32079469531556,285.63185948126187,0.1741397938453595
0.041657994298509464,0.06220684136827366,298.31761088930205,285.63185948126187,0.1741397938453595
0.04177373625300669,0.062379675935187034,298.5255922428323,285.63185948126187,0.1741397938453595
0.04195377929333571,0.06264852970594119,298.8486726494977,285.63185948126187,0.1741397938453595
0.0420823814649993,0.06284056811362272,299.07911339744925,285.63185948126187,0.1741397938453595
0.04241674711132463,0.06333986797359471,299.6769776627,285.63185948126187,0.1741397938453595
0.042532489065821855,0.0635127025405081,299.8835020722891,285.63185948126187,0.1741397938453595
0.04277683319198267,0.06387757551510302,300.318779648517,285.63185948126187,0.1741397938453595
0.04302117731814349,0.06424244848969794,300.7530886272456,285.63185948126187,0.1741397938453595
0.04313691927264071,0.06441528305661132,300.95847806514524,285.63185948126187,0.1741397938453595
0.04375420969662593,0.06533706741348269,302.0502798492997,285.63185948126187,0.1741397938453595
0.043831370999624086,0.06545229045809162,302.18633142156074,285.63185948126187,0.1741397938453595
0.043921392519788605,0.0655867173434687,302.3449402553818,285.63185948126187,0.1741397938453595
0.043972833388454036,0.06566353270654131,302.4355169511268,285.63185948126187,0.1741397938453595
0.04412715599445034,0.06589397879575916,302.7069994175392,285.63185948126187,0.1741397938453595
0.044178596863115774,0.06597079415883177,302.797411255736,285.63185948126187,0.1741397938453595
0.04433291946911209,0.06620124024804962,303.0684007499009,285.63185948126187,0.1741397938453595
0.04443580120644296,0.06635487097419485,303.24885605678855,285.63185948126187,0.1741397938453595
0.04497593032743002,0.0671614322864573,304.1935864093832,285.63185948126187,0.1741397938453595
0.04533601640808807,0.0676991398279656,304.82094959342896,285.63185948126187,0.1741397938453595
0.045606080968581604,0.06810242048409683,305.2901974608141,285.63185948126187,0.1741397938453595
0.04610762943806959,0.06885137027405482,306.1587926529946,285.63185948126187,0.1741397938453595
0.04655773703889215,0.0695235047009402,306.93516877355006,285.63185948126187,0.1741397938453595
0.04664775855905665,0.06965793158631726,307.0900921263643,285.63185948126187,0.1741397938453595
0.046827801599385675,0.06992678535707142,307.39958947647375,285.63185948126187,0.1741397938453595
0.04695640377104926,0.07011882376475295,307.6203749486402,285.63185948126187,0.1741397938453595
0.047110726377045574,0.0703492698539708,307.88500647167706,285.63185948126187,0.1741397938453595
0.04795950071002525,0.07161672334466894,309.3344813726129,285.63185948126187,0.1741397938453595
0.04821670505335242,0.072000800160032,309.77173648937725,285.63185948126187,0.1741397938453595
0.04846104917951324,0.07236567313462693,310.18628704280974,285.63185948126187,0.1741397938453595
0.04887257612883671,0.07298019603920784,310.8826395642243,285.63185948126187,0.1741397938453595
0.04910406003783117,0.0733258651730346,311.27333284572256,285.63185948126187,0.1741397938453595
0.04946414611848922,0.07386357271454291,311.87965325315594,285.63185948126187,0.1741397938453595
0.049811371981980906,0.07438207641528306,312.46269117692776,285.63185948126187,0.1741397938453595
0.05014573762830623,0.07488137627525505,313.02263885959906,285.63185948126187,0.1741397938453595
0.05023575914847074,0.07501580316063212,313.1731449743999,285.63185948126187,0.1741397938453595
0.05072444740079237,0.07574554910982197,313.98835015254195,285.63185948126187,0.1741397938453595
0.050801608703790524,0.07586077215443089,314.1167862335468,285.63185948126187,0.1741397938453595
0.050840189355289604,0.07591838367673535,314.1809757422405,285.63185948126187,0.1741397938453595
0.05122599587028037,0.07649449889977997,314.82182942511525,285.63185948126187,0.1741397938453595
0.05143175934494211,0.07680176035207043,315.162848251991,285.63185948126187,0.1741397938453595
0.0516503830367702,0.07712822564512903,315.5245982699441,285.63185948126187,0.1741397938453595
0.051843286294265586,0.07741628325665134,315.84329383708985,285.63185948126187,0.1741397938453595
0.05190758738009738,0.07751230246049211,315.9494228770252,285.63185948126187,0.1741397938453595
0.05226767346075542,0.0780500100020004,316.5428007001971,285.63185948126187,0.1741397938453595
0.05262775954141347,0.07858771754350871,317.13458635174845,285.63185948126187,0.1741397938453595
0.05284638323324156,0.07891418283656731,317.49311441225166,285.63185948126187,0.1741397938453595
0.052974985404905146,0.07910622124424885,317.7037430629009,285.63185948126187,0.1741397938453595
0.053077867142236015,0.07925985197039408,317.8721024395942,285.63185948126187,0.1741397938453595
0.053219329531065965,0.07947109421884377,318.10338892238553,285.63185948126187,0.1741397938453595
0.05341223278856135,0.07975915183036608,318.41839355426424,285.63185948126187,0.1741397938453595
0.05369515756622124,0.08018163632726545,318.87959894763316,285.63185948126187,0.1741397938453595
0.05381089952071847,0.08035447089417884,319.06800060294637,285.63185948126187,0.1741397938453595
0.05415812538421016,0.08087297459491899,319.6322596013489,285.63185948126187,0.1741397938453595
0.05435102864170553,0.08116103220644129,319.9451271355011,285.63185948126187,0.1741397938453595
0.054826856676860804,0.08187157431486297,320.71502115920356,285.63185948126187,0.1741397938453595
0.054891157762692606,0.08196759351870375,320.8188606679558,285.63185948126187,0.1741397938453595
0.054994039500023476,0.08212122424484898,320.98490526170815,285.63185948126187,0.1741397938453595
0.05507120080302162,0.08223644728945789,321.1093592161555,285.63185948126187,0.1741397938453595
0.055225523409017936,0.08246689337867574,321.3580632943812,285.63185948126187,0.1741397938453595
0.05545700731801239,0.0828125625125025,321.73061181126707,285.63185948126187,0.1741397938453595
0.055765652530005,0.08327345469093819,322.22640113378253,285.63185948126187,0.1741397938453595
0.05631864186815842,0.0840992198439688,323.1120222376203,285.63185948126187,0.1741397938453595
0.056987373160809075,0.08509781956391278,324.17848834346245,285.63185948126187,0.1741397938453595
0.05747606141313071,0.08582756551310262,324.95474488647,285.63185948126187,0.1741397938453595
0.057617523801960654,0.08603880776155232,325.1789697723471,285.63185948126187,0.1741397938453595
0.05783614749378876,0.08636527305461093,325.5250772991896,285.63185948126187,0.1741397938453595
0.05799047009978506,0.08659571914382877,325.76908135955955,285.63185948126187,0.1741397938453595
0.05806763140278321,0.0867109421884377,325.8909884149066,285.63185948126187,0.1741397938453595
0.05817051314011409,0.08686457291458292,326.05343292562935,285.63185948126187,0.1741397938453595
0.058337695963276745,0.08711422284456892,326.31716648206077,285.63185948126187,0.1741397938453595
0.05851773900360577,0.08738307661532307,326.6008578065884,285.63185948126187,0.1741397938453595
0.05896784660442832,0.08805521104220844,327.30860089239303,285.63185948126187,0.1741397938453595
0.059315072467920005,0.08857371474294859,327.85313553297453,285.63185948126187,0.1741397938453595
0.0593793735537518,0.08866973394678936,327.953838708179,285.63185948126187,0.1741397938453595
0.05957227681124719,0.08895779155831167,328.25569336601137,285.63185948126187,0.1741397938453595
0.059778040285908926,0.08926505301060213,328.5772518020279,285.63185948126187,0.1741397938453595
0.059932362891905226,0.08949549909981996,328.8181374227774,285.63185948126187,0.1741397938453595
0.06008668549790153,0.08972594518903781,329.058781260307,285.63185948126187,0.1741397938453595
0.06036961027556143,0.0901484296859372,329.49933652383186,285.63185948126187,0.1741397938453595
0.06057537375022317,0.09045569113822766,329.8192347513475,285.63185948126187,0.1741397938453595
0.06079399744205126,0.09078215643128626,330.15866262419985,285.63185948126187,0.1741397938453595
0.06111550287121023,0.0912622524504901,330.65695775127193,285.63185948126187,0.1741397938453595
0.06123124482570746,0.09143508701740348,330.83609359793803,285.63185948126187,0.1741397938453595
0.06133412656303833,0.09158871774354871,330.9952146281071,285.63185948126187,0.1741397938453595
0.061539890037700065,0.09189597919583917,331.31314474866815,285.63185948126187,0.1741397938453595
0.061681352426530014,0.09210722144428886,331.531481258044,285.63185948126187,0.1741397938453595
0.061809954598193606,0.0922992598519704,331.7297995873118,285.63185948126187,0.1741397938453595
0.06189997611835812,0.09243368673734748,331.86852667988467,285.63185948126187,0.1741397938453595
0.062002857855688986,0.0925873174634927,332.02697561836186,285.63185948126187,0.1741397938453595
0.062105739593019856,0.09274094818963793,332.1853220529729,285.63185948126187,0.1741397938453595
0.06247868589084426,0.09329785957191439,332.7584723067711,285.63185948126187,0.1741397938453595
0.0626201482796742,0.09350910182036408,332.97552489379586,285.63185948126187,0.1741397938453595
0.06273589023417143,0.09368193638727745,333.15297117222093,285.63185948126187,0.1741397938453595
0.06304453544616404,0.09414282856571314,333.62553816900856,285.63185948126187,0.1741397938453595
0.06321171826932671,0.09439247849569915,333.88113519372786,285.63185948126187,0.1741397938453595
0.06344320217832117,0.09473814762952591,334.23460395162573,285.63185948126187,0.1741397938453595
0.06367468608731562,0.09508381676335267,334.58757008515175,285.63185948126187,0.1741397938453595
0.06411193347097181,0.0957367473494699,335.25292149453236,285.63185948126187,0.1741397938453595
0.06448487976879622,0.09629365873174635,335.8190298317838,285.63185948126187,0.1741397938453595
0.0646520625919589,0.09654330866173236,336.07238789294234,285.63185948126187,0.1741397938453595
0.06487068628378698,0.09686977395479096,336.4033170827448,285.63185948126187,0.1741397938453595
0.0651150304099478,0.09723464692938588,336.7726648229695,285.63185948126187,0.1741397938453595
0.06519219171294595,0.09734986997399481,336.88918860116945,285.63185948126187,0.1741397938453595
0.06539795518760769,0.09765713142628527,337.19965601463167,285.63185948126187,0.1741397938453595
0.06550083692493856,0.0978107621524305,337.3547468429598,285.63185948126187,0.1741397938453595
0.0657066003996003,0.09811802360472095,337.66464378154194,285.63185948126187,0.1741397938453595
0.0665167940810809,0.09932786557311463,338.8812016957264,285.63185948126187,0.1741397938453595
0.06669683712140992,0.09959671934386878,339.150761499073,285.63185948126187,0.1741397938453595
0.0667997188587408,0.09975035007001401,339.3046682569916,285.63185948126187,0.1741397938453595