File: datasets/aisi_316_L/data/M1/train_31.csv
Time(s),Strain(%),Stress(MPa),Temp(C),Log_SR(s-1)
0.0,0.0,0.0,388.7504268782796,0.36886100004041733
9.580474478477163e-06,2.24e-05,3.8129419999999996,388.7504268782796,0.36886100004041733
1.5055031323321257e-05,3.52e-05,5.991766,388.7504268782796,0.36886100004041733
2.6346304815812197e-05,6.159999999999999e-05,10.485590499999999,388.7504268782796,0.36886100004041733
3.284734106906456e-05,7.68e-05,13.072944,388.7504268782796,0.36886100004041733
3.7295418505500384e-05,8.719999999999999e-05,14.843238499999998,388.7504268782796,0.36886100004041733
4.0032696927922435e-05,9.36e-05,15.9326505,388.7504268782796,0.36886100004041733
4.584941357556928e-05,0.00010719999999999999,18.247650999999998,388.7504268782796,0.36886100004041733
5.4403408645638176e-05,0.0001272,21.6520635,388.7504268782796,0.36886100004041733
6.090444489889053e-05,0.0001424,24.239417,388.7504268782796,0.36886100004041733
6.329956351850983e-05,0.000148,25.192652499999998,388.7504268782796,0.36886100004041733
6.672116154653739e-05,0.000156,26.5544175,388.7504268782796,0.36886100004041733
6.911628016615668e-05,0.0001616,27.507653,388.7504268782796,0.36886100004041733
7.185355858857872e-05,0.000168,28.597064999999997,388.7504268782796,0.36886100004041733
8.280267227826691e-05,0.0001936,32.954713,388.7504268782796,0.36886100004041733
8.622427030629447e-05,0.0002016,34.316478,388.7504268782796,0.36886100004041733
9.477826537636336e-05,0.0002216,37.720890499999996,388.7504268782796,0.36886100004041733
9.614690458757439e-05,0.0002248,38.2655965,388.7504268782796,0.36886100004041733
0.00010606953886885431,0.000248,42.214715000000005,388.7504268782796,0.36886100004041733
0.00012112457019217557,0.0002832,48.206481,388.7504268782796,0.36886100004041733
0.00014028551914912988,0.000328,55.832365,388.7504268782796,0.36886100004041733
0.00014678655540238225,0.0003432,58.4197185,388.7504268782796,0.36886100004041733
0.00015157679264162082,0.0003544,60.3261895,388.7504268782796,0.36886100004041733
0.0001618415867257035,0.0003784,64.4114845,388.7504268782796,0.36886100004041733
0.00017518581903501097,0.0004096,69.722368,388.7504268782796,0.36886100004041733
0.00018339765430227712,0.00042879999999999996,72.99060399999999,388.7504268782796,0.36886100004041733
0.00018853005134431846,0.0004408,75.03325149999999,388.7504268782796,0.36886100004041733
0.00019708404641438735,0.0004608,78.437664,388.7504268782796,0.36886100004041733
0.00020221644345642869,0.0004728,80.4803115,388.7504268782796,0.36886100004041733
0.00021521851596293341,0.0005032,85.6550185,388.7504268782796,0.36886100004041733
0.0002182979541881582,0.0005103999999999999,86.88060699999998,388.7504268782796,0.36886100004041733
0.00023437946491988774,0.000548,93.2809025,388.7504268782796,0.36886100004041733
0.0002460128982151814,0.0005752,97.9109035,388.7504268782796,0.36886100004041733
0.0002545668932852503,0.0005951999999999999,101.315316,388.7504268782796,0.36886100004041733
0.00025764633151047515,0.0006024,102.5409045,388.7504268782796,0.36886100004041733
0.00025935713052448894,0.0006064,103.221787,388.7504268782796,0.36886100004041733
0.00026927976480576883,0.0006296,107.1709055,388.7504268782796,0.36886100004041733
0.00027372784224220467,0.0006399999999999999,108.9412,388.7504268782796,0.36886100004041733
0.00029288879119915897,0.0006848,116.567084,388.7504268782796,0.36886100004041733
0.00030691734311407196,0.0007176,122.15032049999999,388.7504268782796,0.36886100004041733
0.00031410269897292985,0.0007344,125.010027,388.7504268782796,0.36886100004041733
0.0003188929362121684,0.0007456,126.916498,388.7504268782796,0.36886100004041733
0.000322314534240196,0.0007536,128.278263,388.7504268782796,0.36886100004041733
0.0003288155704934483,0.0007687999999999999,130.8656165,388.7504268782796,0.36886100004041733
0.0003305263695074621,0.0007727999999999999,131.54649899999998,388.7504268782796,0.36886100004041733
0.0003472921998447972,0.000812,138.2191475,388.7504268782796,0.36886100004041733
0.00035481971550645777,0.0008296,141.2150305,388.7504268782796,0.36886100004041733
0.0003630315507737239,0.0008487999999999999,144.48326649999998,388.7504268782796,0.36886100004041733
0.0003678217880129625,0.00086,146.3897375,388.7504268782796,0.36886100004041733
0.0003709012262381873,0.0008671999999999999,147.61532599999998,388.7504268782796,0.36886100004041733
0.0003770601026886369,0.0008816,150.06650299999998,388.7504268782796,0.36886100004041733
0.0003904043349979444,0.0009128,155.3773865,388.7504268782796,0.36886100004041733
0.0003962210516455912,0.0009264,157.692387,388.7504268782796,0.36886100004041733
0.00040374856730725185,0.000944,160.32443334148974,388.7504268782796,0.36886100004041733
0.00041709279961655936,0.0009752,160.49001930096742,388.7504268782796,0.36886100004041733
0.0004256467946866282,0.0009952,160.59507829992603,388.7504268782796,0.36886100004041733
0.0004335164701510916,0.0010136,160.69100759161856,388.7504268782796,0.36886100004041733
0.0004352272691651054,0.0010176,160.7117716399312,388.7504268782796,0.36886100004041733
0.00044412342403797703,0.0010383999999999999,160.81923583091083,388.7504268782796,0.36886100004041733
0.0004557568573332707,0.0010655999999999999,160.9585075899461,388.7504268782796,0.36886100004041733
0.00047491780629022506,0.0011103999999999999,161.18491107970976,388.7504268782796,0.36886100004041733
0.0004851826003743078,0.0011344,161.30473178665403,388.7504268782796,0.36886100004041733
0.0004957895542611932,0.0011592,161.4275124029143,388.7504268782796,0.36886100004041733
0.0005026327503172483,0.0011752,161.50618235839605,388.7504268782796,0.36886100004041733
0.0005163191424293585,0.0012071999999999999,161.66228015329045,388.7504268782796,0.36886100004041733
0.0005279525757246522,0.0012343999999999999,161.79369854501422,388.7504268782796,0.36886100004041733
0.0005399281688227487,0.0012624,161.92780779602913,388.7504268782796,0.36886100004041733
0.0005457448854703956,0.001276,161.99252757823842,388.7504268782796,0.36886100004041733
0.0005481400040900148,0.0012816,162.01909864114097,388.7504268782796,0.36886100004041733
0.0005625107158077306,0.0013151999999999999,162.1775844083347,388.7504268782796,0.36886100004041733
0.0005662744736385608,0.0013239999999999999,162.21883064656808,388.7504268782796,0.36886100004041733
0.0005799608657506712,0.001356,162.36792405341484,388.7504268782796,0.36886100004041733
0.0005850932627927125,0.0013679999999999999,162.42347950379946,388.7504268782796,0.36886100004041733
0.000589883500031951,0.0013792,162.4751600270333,388.7504268782796,0.36886100004041733
0.0005960423764824006,0.0013935999999999998,162.54136654587668,388.7504268782796,0.36886100004041733
0.0006015169333272448,0.0014064,162.59999313028922,388.7504268782796,0.36886100004041733
0.0006199935626785935,0.0014495999999999999,162.7963393126315,388.7504268782796,0.36886100004041733
0.0006240994803122267,0.0014592,162.8396603342574,388.7504268782796,0.36886100004041733
0.0006247837999178321,0.0014608,162.8468696843844,388.7504268782796,0.36886100004041733
0.0006275210783402541,0.0014671999999999999,162.87567634252352,388.7504268782796,0.36886100004041733
0.0006302583567626762,0.0014736,162.90443403626375,388.7504268782796,0.36886100004041733
0.0006418917900579699,0.0015007999999999998,163.02611478284484,388.7504268782796,0.36886100004041733
0.000645997707691603,0.0015103999999999999,163.06885518681236,388.7504268782796,0.36886100004041733
0.0006466820272972084,0.0015119999999999999,163.07596827465946,388.7504268782796,0.36886100004041733
0.0006607105792121215,0.0015448,163.22114588968103,388.7504268782796,0.36886100004041733
0.00066550081645136,0.0015559999999999999,163.27044274378045,388.7504268782796,0.36886100004041733
0.0006702910536905987,0.0015672,163.3196014044853,388.7504268782796,0.36886100004041733
0.0006726861723102179,0.0015727999999999998,163.3441293416268,388.7504268782796,0.36886100004041733
0.000678160729155062,0.0015856,163.40006565871158,388.7504268782796,0.36886100004041733
0.0006791872085634704,0.001588,163.4105340837255,388.7504268782796,0.36886100004041733
0.000686714724225131,0.0016056,163.48711488257797,388.7504268782796,0.36886100004041733
0.0006877412036335391,0.0016079999999999998,163.49753229575998,388.7504268782796,0.36886100004041733
0.0006897941624503558,0.0016128,163.5183489483616,388.7504268782796,0.36886100004041733
0.0006969795183092136,0.0016296,163.59101771683794,388.7504268782796,0.36886100004041733
0.0007000589565344384,0.0016367999999999999,163.62207196859103,388.7504268782796,0.36886100004041733
0.0007079286319989018,0.0016552,163.7011917633428,388.7504268782796,0.36886100004041733
0.0007106659104213238,0.0016615999999999998,163.72863119011916,388.7504268782796,0.36886100004041733
0.0007205885447026037,0.0016848,163.8277554469411,388.7504268782796,0.36886100004041733
0.0007246944623362368,0.0016944,163.86861650099777,388.7504268782796,0.36886100004041733
0.0007311954985894892,0.0017096,163.93312900228662,388.7504268782796,0.36886100004041733
0.0007387230142511498,0.0017272,164.0075488832552,388.7504268782796,0.36886100004041733
0.0007486456485324297,0.0017503999999999998,164.10519750371475,388.7504268782796,0.36886100004041733
0.0007530937259688656,0.0017607999999999999,164.1488070378771,388.7504268782796,0.36886100004041733
0.0007571996436024986,0.0017703999999999999,164.18897291500323,388.7504268782796,0.36886100004041733
0.0007609634014333289,0.0017791999999999999,164.2257170794994,388.7504268782796,0.36886100004041733
0.0007671222778837786,0.0017936,164.28569137701612,388.7504268782796,0.36886100004041733
0.0007832037886155081,0.0018311999999999998,164.44141221187044,388.7504268782796,0.36886100004041733
0.0007859410670379302,0.0018376,164.46779320581786,388.7504268782796,0.36886100004041733
0.0007934685826995908,0.0018552,164.54015681802653,388.7504268782796,0.36886100004041733
0.0008133138512621506,0.0019015999999999998,164.72966167820493,388.7504268782796,0.36886100004041733
0.0008174197688957836,0.0019111999999999998,164.76864346550835,388.7504268782796,0.36886100004041733
0.0008194727277126002,0.001916,164.78810571712265,388.7504268782796,0.36886100004041733
0.0008246051247546415,0.0019279999999999998,164.83667833893634,388.7504268782796,0.36886100004041733
0.0008348699188387242,0.001952,164.93347130660945,388.7504268782796,0.36886100004041733
0.0008400023158807656,0.001964,164.98169366024092,388.7504268782796,0.36886100004041733
0.0008526622285844675,0.0019936,165.10015343474345,388.7504268782796,0.36886100004041733
0.0008605319040489309,0.002012,165.1734449551178,388.7504268782796,0.36886100004041733
0.0008718231775414219,0.0020384,165.27814740477578,388.7504268782796,0.36886100004041733
0.0008831144510339127,0.0020648,165.38232231602444,388.7504268782796,0.36886100004041733
0.0008865360490619404,0.0020728,165.41378774470584,388.7504268782796,0.36886100004041733
0.0008930370853151927,0.002088,165.47344188334128,388.7504268782796,0.36886100004041733
0.0008974851627516285,0.0020984,165.51416032375778,388.7504268782796,0.36886100004041733
0.0009080921166385139,0.0021232,165.6109418371086,388.7504268782796,0.36886100004041733
0.0009180147509197938,0.0021463999999999997,165.70108101128548,388.7504268782796,0.36886100004041733
0.0009231471479618352,0.0021584,165.74755557533493,388.7504268782796,0.36886100004041733
0.0009286217048066793,0.0021712,165.7970175118687,388.7504268782796,0.36886100004041733
0.0009323854626375097,0.00218,165.83095664459498,388.7504268782796,0.36886100004041733
0.0009371756998767482,0.0021912,165.87407472831725,388.7504268782796,0.36886100004041733
0.0009423080969187895,0.0022031999999999998,165.92017740443518,388.7504268782796,0.36886100004041733
0.0009440188959328033,0.0022072,165.9355231872372,388.7504268782796,0.36886100004041733
0.0009505199321860556,0.0022224,165.9937385122376,388.7504268782796,0.36886100004041733
0.000962837685086955,0.0022512,166.10361714861992,388.7504268782796,0.36886100004041733
0.0009669436027205879,0.0022608,166.14012135412267,388.7504268782796,0.36886100004041733
0.0009717338399598264,0.0022719999999999997,166.18263327613934,388.7504268782796,0.36886100004041733
0.000987815350691556,0.0023095999999999998,166.32475786679683,388.7504268782796,0.36886100004041733
0.0009898683095083726,0.0023144,166.34283625730245,388.7504268782796,0.36886100004041733
0.0009950007065504139,0.0023263999999999997,166.38796837701295,388.7504268782796,0.36886100004041733
0.0009967115055644277,0.0023304,166.40299222902658,388.7504268782796,0.36886100004041733
0.0010080027790569186,0.0023568,166.50189861839291,388.7504268782796,0.36886100004041733
0.0010103978976765378,0.0023623999999999997,166.52282310678922,388.7504268782796,0.36886100004041733
0.001014503815310171,0.002372,166.55864870906495,388.7504268782796,0.36886100004041733
0.0010309274858447033,0.0024104,166.70138923400492,388.7504268782796,0.36886100004041733
0.0010333226044643225,0.0024159999999999997,166.72213122414607,388.7504268782796,0.36886100004041733
0.0010387971613091667,0.0024288,166.7694712069844,388.7504268782796,0.36886100004041733
0.0010463246769708274,0.0024464,166.83440511841403,388.7504268782796,0.36886100004041733
0.0010521413936184741,0.00246,166.8844566180373,388.7504268782796,0.36886100004041733
0.0010555629916465016,0.0024679999999999997,166.9138482670795,388.7504268782796,0.36886100004041733
0.0010606953886885431,0.00248,166.95786616843608,388.7504268782796,0.36886100004041733
0.0010651434661249788,0.0024904,166.99594786811136,388.7504268782796,0.36886100004041733
0.0010740396209978505,0.0025112,167.07192571045363,388.7504268782796,0.36886100004041733
0.0010805406572511028,0.0025264,167.1272928574408,388.7504268782796,0.36886100004041733
0.0010812249768567084,0.002528,167.13311341079716,388.7504268782796,0.36886100004041733
0.0010928584101520021,0.0025552,167.23184405165236,388.7504268782796,0.36886100004041733
0.0011038075238416903,0.0025808,167.32439324115404,388.7504268782796,0.36886100004041733
0.0011116771993061535,0.0025992,167.39069196169166,388.7504268782796,0.36886100004041733
0.0011157831169397868,0.0026088,167.42520992170955,388.7504268782796,0.36886100004041733
0.0011202311943762225,0.0026192,167.46254852378155,388.7504268782796,0.36886100004041733
0.0011328911070799244,0.0026487999999999998,167.56850476332423,388.7504268782796,0.36886100004041733
0.0011393921433331768,0.0026639999999999997,167.62273521134966,388.7504268782796,0.36886100004041733
0.0011506834168256677,0.0026904,167.71663899672618,388.7504268782796,0.36886100004041733
0.0011523942158396816,0.0026944,167.73083543221304,388.7504268782796,0.36886100004041733
0.0011595795716985394,0.0027112,167.79037092776568,388.7504268782796,0.36886100004041733
0.0011633433295293698,0.0027199999999999998,167.8214987580778,388.7504268782796,0.36886100004041733
0.0011732659638106497,0.0027432,167.90337535038512,388.7504268782796,0.36886100004041733
0.001182504278486324,0.0027648,167.97936285044653,388.7504268782796,0.36886100004041733
0.0011879788353311683,0.0027776,168.0242832330511,388.7504268782796,0.36886100004041733
0.0011948220313872232,0.0027936,168.0803203430698,388.7504268782796,0.36886100004041733
0.0011999544284292645,0.0028055999999999997,168.1222660703976,388.7504268782796,0.36886100004041733
0.0012061133048797143,0.00282,168.17250869676906,388.7504268782796,0.36886100004041733
0.0012153516195553885,0.0028415999999999997,168.24768543464282,388.7504268782796,0.36886100004041733
0.0012273272126534852,0.0028696,168.34480589583748,388.7504268782796,0.36886100004041733
0.0012416979243712008,0.0029032,168.4608639547536,388.7504268782796,0.36886100004041733
0.0012437508831880174,0.002908,168.477400813959,388.7504268782796,0.36886100004041733
0.0012492254400328616,0.0029208,168.52144714356055,388.7504268782796,0.36886100004041733
0.0012519627184552837,0.0029272,168.54344207357875,388.7504268782796,0.36886100004041733
0.0012646226311589855,0.0029568,168.6449256585533,388.7504268782796,0.36886100004041733
0.0012690707085954212,0.0029671999999999997,168.68048789181353,388.7504268782796,0.36886100004041733
0.0012827571007075315,0.0029992,168.78960647534686,388.7504268782796,0.36886100004041733
0.0012889159771579811,0.0030136,168.8385616063234,388.7504268782796,0.36886100004041733
0.001291995415383206,0.0030207999999999997,168.8630049543213,388.7504268782796,0.36886100004041733
0.0012991807712420637,0.0030375999999999997,168.91995124240654,388.7504268782796,0.36886100004041733
0.0013022602094672887,0.0030448,168.94431917842374,388.7504268782796,0.36886100004041733
0.0013049974878897109,0.0030512,168.9659607063279,388.7504268782796,0.36886100004041733
0.0013063661271009216,0.0030543999999999997,168.9767748309126,388.7504268782796,0.36886100004041733
0.0013097877251289493,0.0030624,169.0037908292013,388.7504268782796,0.36886100004041733
0.0013145779623681877,0.0030735999999999997,169.0415670320684,388.7504268782796,0.36886100004041733
0.001316973080987807,0.0030792,169.06043499887855,388.7504268782796,0.36886100004041733
0.0013275800348746926,0.003104,169.14383279282612,388.7504268782796,0.36886100004041733
0.001336818349550367,0.0031255999999999996,169.21625807489684,388.7504268782796,0.36886100004041733
0.0013532420200848992,0.0031639999999999997,169.34453399608623,388.7504268782796,0.36886100004041733
0.0013614538553521653,0.0031831999999999997,169.40844416594408,388.7504268782796,0.36886100004041733
0.001368981371013826,0.0032007999999999997,169.4668965432492,388.7504268782796,0.36886100004041733
0.0013771932062810921,0.0032199999999999998,169.5305199982816,388.7504268782796,0.36886100004041733
0.001397380634646455,0.0032672,169.68630196028147,388.7504268782796,0.36886100004041733
0.0013990914336604685,0.0032711999999999997,169.69946334432933,388.7504268782796,0.36886100004041733
0.0014014865522800877,0.0032768,169.71787874233655,388.7504268782796,0.36886100004041733
0.0014124356659697761,0.0033024,169.80190760595184,388.7504268782796,0.36886100004041733
0.0014353603727575608,0.003356,169.97702468884657,388.7504268782796,0.36886100004041733
0.0014387819707855883,0.003364,170.00306771586978,388.7504268782796,0.36886100004041733
0.0014469938060528544,0.0033832,170.0654726291878,388.7504268782796,0.36886100004041733
0.001455889960925726,0.003404,170.13292229258312,388.7504268782796,0.36886100004041733
0.00146136451777057,0.0034168,170.17434989220408,388.7504268782796,0.36886100004041733
0.0014641017961929922,0.0034232,170.19504099146462,388.7504268782796,0.36886100004041733
0.0014709449922490473,0.0034392,170.24670284456369,388.7504268782796,0.36886100004041733
0.0014801833069247217,0.0034608,170.31629790651317,388.7504268782796,0.36886100004041733
0.0014818941059387353,0.0034647999999999997,170.32916726954693,388.7504268782796,0.36886100004041733
0.0014866843431779742,0.003476,170.3651706967343,388.7504268782796,0.36886100004041733
0.0014976334568676621,0.0035015999999999997,170.44729478515654,388.7504268782796,0.36886100004041733
0.0015065296117405338,0.0035223999999999997,170.51384832480895,388.7504268782796,0.36886100004041733
0.0015113198489797725,0.0035336,170.54962135374876,388.7504268782796,0.36886100004041733
0.001513030647993786,0.0035375999999999997,170.56238671537176,388.7504268782796,0.36886100004041733
0.0015181630450358276,0.0035496,170.60064906760817,388.7504268782796,0.36886100004041733
0.0015195316842470388,0.0035528,170.61084383736573,388.7504268782796,0.36886100004041733
0.0015256905606974883,0.0035672,170.65667605701088,388.7504268782796,0.36886100004041733
0.0015297964783311212,0.0035767999999999998,170.68719079009404,388.7504268782796,0.36886100004041733
0.0015349288753731625,0.0035887999999999996,170.7252893265492,388.7504268782796,0.36886100004041733
0.0015362975145843736,0.0035919999999999997,170.73544054134854,388.7504268782796,0.36886100004041733
0.0015386926332039929,0.0035976,170.75319668468035,388.7504268782796,0.36886100004041733
0.0015410877518236123,0.0036032,170.77094205203176,388.7504268782796,0.36886100004041733
0.0015424563910348232,0.0036063999999999996,170.78107743271121,388.7504268782796,0.36886100004041733
0.0015458779890628507,0.0036144,170.8064005517963,388.7504268782796,0.36886100004041733
0.001551352545907695,0.0036271999999999997,170.84687212253857,388.7504268782796,0.36886100004041733
0.0015578535821609472,0.0036423999999999996,170.89485984010074,388.7504268782796,0.36886100004041733
0.001567776216442227,0.0036655999999999998,170.96795395065,388.7504268782796,0.36886100004041733
0.001576330211512296,0.0036856,171.03082142431703,388.7504268782796,0.36886100004041733
0.001583515567371154,0.0037024,171.0835273486569,388.7504268782796,0.36886100004041733
0.0015865950055963787,0.0037096,171.10608704027783,388.7504268782796,0.36886100004041733
0.0015900166036244062,0.0037175999999999997,171.13113334566933,388.7504268782796,0.36886100004041733
0.001605755954553333,0.0037543999999999998,171.2460766900759,388.7504268782796,0.36886100004041733
0.00161157267120098,0.0037679999999999996,171.28844444654425,388.7504268782796,0.36886100004041733
0.0016129413104121909,0.0037711999999999997,171.29840465820905,388.7504268782796,0.36886100004041733
0.0016228639446934708,0.0037944,171.370517875648,388.7504268782796,0.36886100004041733
0.0016303914603551315,0.003812,171.4251098047255,388.7504268782796,0.36886100004041733
0.001639629775030806,0.0038336,171.49197482587866,388.7504268782796,0.36886100004041733
0.0016457886514812555,0.003848,171.5364698971644,388.7504268782796,0.36886100004041733
0.0016536583269457189,0.0038664,171.59323032257163,388.7504268782796,0.36886100004041733
0.0016601593631989711,0.0038816,171.64003995444804,388.7504268782796,0.36886100004041733
0.0016680290386634346,0.0039,171.6966087075103,388.7504268782796,0.36886100004041733
0.0016697398376774484,0.003904,171.70889247833793,388.7504268782796,0.36886100004041733
0.0016752143945222924,0.0039168,171.74816760099884,388.7504268782796,0.36886100004041733
0.0016889007866344027,0.0039488,171.8461370440374,388.7504268782796,0.36886100004041733
0.0016899272660428112,0.0039512,171.85347224666342,388.7504268782796,0.36886100004041733
0.001695401822887655,0.003964,171.89256401977426,388.7504268782796,0.36886100004041733
0.0016991655807184853,0.003972799999999999,171.91941106136346,388.7504268782796,0.36886100004041733
0.0017354394479023553,0.004057611522304461,172.17697610942344,388.7504268782796,0.36886100004041733
0.0019489898749366818,0.004556911382276456,173.65278008907922,388.7504268782796,0.36886100004041733
0.0020393381325281277,0.004768153630726146,174.2579984957289,388.7504268782796,0.36886100004041733
0.0023021694273396066,0.005382676535307062,175.96181138731376,388.7504268782796,0.36886100004041733
0.0024664389865967805,0.005766753350670134,176.98819940391826,388.7504268782796,0.36886100004041733
0.0025814276780768025,0.006035607121424285,177.69085752718397,388.7504268782796,0.36886100004041733
0.002606068111965379,0.006093218643728746,177.83982668291233,388.7504268782796,0.36886100004041733
0.0027867646271482705,0.006515703140628126,178.9159595180943,388.7504268782796,0.36886100004041733
0.00291818027455401,0.006822964592918584,179.68157460392234,388.7504268782796,0.36886100004041733
0.003074236355848325,0.007187837567513502,180.57348901377267,388.7504268782796,0.36886100004041733
0.0031153037456626187,0.00728385677135427,180.80524593074907,388.7504268782796,0.36886100004041733
0.003304213738808369,0.007725545109021804,181.85634496567567,388.7504268782796,0.36886100004041733
0.003534191121768413,0.008263252650530106,183.1048140548584,388.7504268782796,0.36886100004041733
0.0035998989454712827,0.008416883376675335,183.45564590050736,388.7504268782796,0.36886100004041733
0.003764168504728457,0.008800960192038408,184.32197188424388,388.7504268782796,0.36886100004041733
0.0037888089386170333,0.008858571714342869,184.45063774237983,388.7504268782796,0.36886100004041733
0.0038298763284313267,0.008954590918183637,184.66435799229114,388.7504268782796,0.36886100004041733
0.004035213277502794,0.009434686937387478,185.71983813857247,388.7504268782796,0.36886100004041733
0.004174842402871393,0.00976115223044609,186.42562412928197,388.7504268782796,0.36886100004041733
0.004421246741757153,0.010337267453490697,187.64906755554142,388.7504268782796,0.36886100004041733
0.004536235433237176,0.010606121224244848,188.21087788839165,388.7504268782796,0.36886100004041733
0.00464301064675434,0.010855771154230847,188.72760549971224,388.7504268782796,0.36886100004041733
0.004782639772122937,0.011182236447289457,189.3963863920901,388.7504268782796,0.36886100004041733
0.004979763243231546,0.011643128625725144,190.32772554012422,388.7504268782796,0.36886100004041733
0.005316515839708754,0.012430486097219444,191.88615901702798,388.7504268782796,0.36886100004041733
0.005505425832854504,0.012872174434886977,192.7435294690495,388.7504268782796,0.36886100004041733
0.0056450549582231025,0.013198639727945589,193.3698812472553,388.7504268782796,0.36886100004041733
0.005948953642848875,0.013909181836367274,194.71260082206467,388.7504268782796,0.36886100004041733
0.006080369290254614,0.014216443288657732,195.2849200617874,388.7504268782796,0.36886100004041733
0.006211784937660354,0.01452370474094819,195.85243498905828,388.7504268782796,0.36886100004041733
0.006737447527283311,0.015752750550110023,198.07716464395926,388.7504268782796,0.36886100004041733
0.006926357520429062,0.01619443888777756,198.85999946000044,388.7504268782796,0.36886100004041733
0.006975638388206213,0.016309661932386477,199.0628421653714,388.7504268782796,0.36886100004041733
0.007057773167834801,0.016501700340068013,199.3996757706365,388.7504268782796,0.36886100004041733
0.007197402293203399,0.016828165633126627,199.96880530919088,388.7504268782796,0.36886100004041733
0.007328817940609139,0.017135427085417085,200.5005356137463,388.7504268782796,0.36886100004041733
0.007476660543940594,0.017481096219243847,201.0943071912491,388.7504268782796,0.36886100004041733
0.007657357059123487,0.01790358071614323,201.81384540721265,388.7504268782796,0.36886100004041733
0.007813413140417802,0.018268453690738148,202.42995175111847,388.7504268782796,0.36886100004041733
0.008684041804480826,0.020304060812162433,205.78292730301982,388.7504268782796,0.36886100004041733
0.008725109194295118,0.0204000800160032,205.9377642870839,388.7504268782796,0.36886100004041733
0.00884009788577514,0.02066893378675735,206.3698030184021,388.7504268782796,0.36886100004041733
0.00910292918058662,0.021283456691338267,207.34917305361395,388.7504268782796,0.36886100004041733
0.009382187431323815,0.02193638727745549,208.3777456722836,388.7504268782796,0.36886100004041733
0.009636805248172437,0.022531706341268255,209.3052017236872,388.7504268782796,0.36886100004041733
0.009907850020946773,0.023165433086617324,210.28205267276496,388.7504268782796,0.36886100004041733
0.010047479146315373,0.023491898379675937,210.78120789004734,388.7504268782796,0.36886100004041733
0.010154254359832535,0.023741548309661933,211.16109155697956,388.7504268782796,0.36886100004041733
0.010261029573349697,0.02399119823964793,211.5394204867725,388.7504268782796,0.36886100004041733
0.010367804786866861,0.024240848169633927,211.91621712269213,388.7504268782796,0.36886100004041733
0.010737411295195502,0.02510502100420084,213.20898415321994,388.7504268782796,0.36886100004041733
0.010794905640935515,0.025239447889577916,213.40851068964062,388.7504268782796,0.36886100004041733
0.010844186508712666,0.02535467093418684,213.57920379186666,388.7504268782796,0.36886100004041733
0.0110166695459327,0.025757951590318063,214.17426177376728,388.7504268782796,0.36886100004041733
0.011156298671301298,0.026084416883376677,214.65331847951683,388.7504268782796,0.36886100004041733
0.011230219972967026,0.026257251450290058,214.90598978263375,388.7504268782796,0.36886100004041733
0.011542332135555658,0.026986997399479896,215.96575129926578,388.7504268782796,0.36886100004041733
0.011805163430367136,0.027601520304060812,216.8495410795701,388.7504268782796,0.36886100004041733
0.011862657776107148,0.02773594718943789,217.04184329348914,388.7504268782796,0.36886100004041733
0.012117275592955766,0.02833126625325065,217.88913538043388,388.7504268782796,0.36886100004041733
0.012445814711470115,0.029099419883976796,218.97222496961263,388.7504268782796,0.36886100004041733
0.012585443836838713,0.029425885177035406,219.42915493139162,388.7504268782796,0.36886100004041733
0.012856488609613052,0.030059611922384478,220.31053169789487,388.7504268782796,0.36886100004041733
0.012913982955353061,0.03019403880776155,220.49655538772302,388.7504268782796,0.36886100004041733
0.013102892948498812,0.030635727145429087,221.10551450888644,388.7504268782796,0.36886100004041733
0.013275375985718846,0.03103900780156031,221.6585368296907,388.7504268782796,0.36886100004041733
0.013357510765347433,0.031231046209241848,221.9208952458362,388.7504268782796,0.36886100004041733
0.013513566846641747,0.031595919183836765,222.41764937257338,388.7504268782796,0.36886100004041733
0.013653195972010347,0.03192238447689538,222.86022034126992,388.7504268782796,0.36886100004041733
0.013842105965156096,0.03236407281456291,223.45619338632602,388.7504268782796,0.36886100004041733
0.013948881178673258,0.032613722744548906,223.7916444116673,388.7504268782796,0.36886100004041733
0.014022802480338988,0.032786557311462294,224.02329332544318,388.7504268782796,0.36886100004041733
0.014137791171819012,0.03305541108221645,224.3826917155241,388.7504268782796,0.36886100004041733
0.014178858561633305,0.033151430286057215,224.51077176886665,388.7504268782796,0.36886100004041733
0.014293847253113326,0.03342028405681136,224.86862851476394,388.7504268782796,0.36886100004041733
0.014466330290333358,0.03382356471294259,225.40331565418035,388.7504268782796,0.36886100004041733
0.014499184202184793,0.0339003800760152,225.50487832128982,388.7504268782796,0.36886100004041733
0.014597745937739097,0.034130826165233046,225.80902917597624,388.7504268782796,0.36886100004041733
0.01465524028347911,0.03426525305061012,225.98608065243528,388.7504268782796,0.36886100004041733
0.014959138968104881,0.034975795159031806,226.91746207419803,388.7504268782796,0.36886100004041733
0.015213756784953498,0.03557111422284456,227.6921407523657,388.7504268782796,0.36886100004041733
0.0153533859103221,0.03589757951590318,228.11481724265067,388.7504268782796,0.36886100004041733
0.015435520689950685,0.03608961792358471,228.3627501979837,388.7504268782796,0.36886100004041733
0.015550509381430709,0.03635847169433887,228.70899367629053,388.7504268782796,0.36886100004041733
0.015870835021982197,0.037107421484296854,229.6683032294524,388.7504268782796,0.36886100004041733
0.016109025882905102,0.03766433286657332,230.37674808987862,388.7504268782796,0.36886100004041733
0.016141879794756536,0.03774114822964593,230.47414303717068,388.7504268782796,0.36886100004041733
0.016289722398087993,0.03808681736347269,230.911467110515,388.7504268782796,0.36886100004041733
0.016314362831976566,0.038144428885777154,230.98420369956818,388.7504268782796,0.36886100004041733
0.016536126736973755,0.038662932586517304,231.6369162659979,388.7504268782796,0.36886100004041733
0.016651115428453777,0.03893178635727146,231.97401528943087,388.7504268782796,0.36886100004041733
0.016700396296230925,0.03904700940188037,232.11820823824445,388.7504268782796,0.36886100004041733
0.01681538498771095,0.039315863172634524,232.45401465740864,388.7504268782796,0.36886100004041733
0.016922160201228113,0.03956551310262052,232.76503387904796,388.7504268782796,0.36886100004041733
0.017028935414745275,0.039815163032606515,233.0752886742946,388.7504268782796,0.36886100004041733
0.01725891279770532,0.040352870574114824,233.7409645958721,388.7504268782796,0.36886100004041733
0.017373901489185346,0.04062172434486898,234.07250462721902,388.7504268782796,0.36886100004041733
0.017554598004368233,0.04104420884176835,234.5917723169186,388.7504268782796,0.36886100004041733
0.01775172147547684,0.041505101020204035,235.15587446356548,388.7504268782796,0.36886100004041733
0.01801455277028832,0.04211962392478495,235.9042250359295,388.7504268782796,0.36886100004041733
0.01821167624139693,0.04258051610322064,236.4626966776796,388.7504268782796,0.36886100004041733
0.018252743631211227,0.04267653530706142,236.57874764519093,388.7504268782796,0.36886100004041733
0.018384159278616967,0.04298379675935188,236.94942829473004,388.7504268782796,0.36886100004041733
0.01858949622768843,0.04346389277855571,237.52655467782972,388.7504268782796,0.36886100004041733
0.01884411404453705,0.04405921184236847,238.23875010740701,388.7504268782796,0.36886100004041733
0.01891803534620278,0.044232046409281855,238.44481228557416,388.7504268782796,0.36886100004041733
0.019074091427497095,0.044596919383876776,238.87880406022097,388.7504268782796,0.36886100004041733
0.019172653163051397,0.04482736547309461,239.1521907728897,388.7504268782796,0.36886100004041733
0.019607967495082916,0.04584516903380677,240.35315148730447,388.7504268782796,0.36886100004041733
0.01972295618656293,0.04611402280456091,240.6686445368059,388.7504268782796,0.36886100004041733
0.019805090966191524,0.046306061212242455,240.89355767286932,388.7504268782796,0.36886100004041733
0.019920079657671542,0.046574914982996596,241.2078258854067,388.7504268782796,0.36886100004041733
0.020100776172854436,0.04699739947989598,241.70025025494402,388.7504268782796,0.36886100004041733
0.02021576486433446,0.047266253250650134,242.01271255361684,388.7504268782796,0.36886100004041733
0.020265045732111613,0.04738147629525906,242.1464126936571,388.7504268782796,0.36886100004041733
0.0204457422472945,0.04780396079215843,242.63556542995445,388.7504268782796,0.36886100004041733
0.020536090504885945,0.04801520304060812,242.87950934006534,388.7504268782796,0.36886100004041733
0.02071678702006884,0.048437687537507504,243.36614509939398,388.7504268782796,0.36886100004041733
0.020798921799697424,0.04862972594518904,243.58679566091274,388.7504268782796,0.36886100004041733
0.021069966572471763,0.04926345269053811,244.31254336095822,388.7504268782796,0.36886100004041733
0.021398505690986114,0.05003160632126426,245.1873742168763,388.7504268782796,0.36886100004041733
0.02158741568413186,0.050473294658931786,245.68802984423982,388.7504268782796,0.36886100004041733
0.02168597741968617,0.05070374074814964,245.94856301252915,388.7504268782796,0.36886100004041733
0.02185024697894334,0.0510878175635127,246.38176106799204,388.7504268782796,0.36886100004041733
0.02194880871449765,0.05131826365273055,246.64107027381192,388.7504268782796,0.36886100004041733
0.022433403914306305,0.052451290258051605,247.9094606585161,388.7504268782796,0.36886100004041733
0.022458044348194883,0.05250890178035607,247.97366807533515,388.7504268782796,0.36886100004041733
0.022778369988746376,0.05325785157031407,248.8058799890611,388.7504268782796,0.36886100004041733
0.022835864334486387,0.05339227845569114,248.9547669592734,388.7504268782796,0.36886100004041733
0.022901572158189255,0.05354590918183637,249.12474460123101,388.7504268782796,0.36886100004041733
0.02337795388003506,0.054659731946389276,250.35144419394717,388.7504268782796,0.36886100004041733
0.023476515615589368,0.054890178035607126,250.60402262527225,388.7504268782796,0.36886100004041733
0.023673639086697975,0.05535107021404281,251.1079422265495,388.7504268782796,0.36886100004041733
0.02370649299854941,0.05542788557711542,251.19176947435818,388.7504268782796,0.36886100004041733
0.02382969516799229,0.055715943188637734,251.5057189532113,388.7504268782796,0.36886100004041733
0.023936470381509454,0.05596559311862373,251.77729680089584,388.7504268782796,0.36886100004041733
0.023977537771323748,0.056061612322464496,251.88162396421097,388.7504268782796,0.36886100004041733
0.024330717323726672,0.056887377475495104,252.77597902286297,388.7504268782796,0.36886100004041733
0.02447855992705813,0.057233046609321866,253.148855236474,388.7504268782796,0.36886100004041733
0.024757818177795324,0.05788597719543909,253.85078933941173,388.7504268782796,0.36886100004041733
0.02498779556075537,0.058423684736947396,254.42653707997425,388.7504268782796,0.36886100004041733
0.02505350338445824,0.058577315463092625,254.59065637862872,388.7504268782796,0.36886100004041733
0.02520955946575255,0.05894218843768753,254.9797683842387,388.7504268782796,0.36886100004041733
0.025398469458898305,0.059383876775355074,255.44954408560614,388.7504268782796,0.36886100004041733
0.025497031194452607,0.05961432286457291,255.6941033799058,388.7504268782796,0.36886100004041733
0.0255380985842669,0.05971034206841368,255.79589423773137,388.7504268782796,0.36886100004041733
0.025759862489264086,0.06022884576915383,256.3444656845457,388.7504268782796,0.36886100004041733
0.025998053350186987,0.06078575715143028,256.93162455513425,388.7504268782796,0.36886100004041733
0.026121255519629873,0.061073814762952594,257.23450396280975,388.7504268782796,0.36886100004041733
0.02631016551277562,0.06151550310062012,257.6978392234585,388.7504268782796,0.36886100004041733
0.026499075505921375,0.061957191438287665,258.15987883368535,388.7504268782796,0.36886100004041733
0.026564783329624243,0.062110822164432894,258.32028691554444,388.7504268782796,0.36886100004041733
0.02667977202110426,0.062379675935187034,258.6006292146197,388.7504268782796,0.36886100004041733
0.026770120278695707,0.06259091818363673,258.8205677221021,388.7504268782796,0.36886100004041733
0.026893322448138593,0.06287897579515904,259.1200179035231,388.7504268782796,0.36886100004041733
0.027008311139618612,0.06314782956591318,259.3990224011536,388.7504268782796,0.36886100004041733
0.027106872875172917,0.06337827565513103,259.63780058989414,388.7504268782796,0.36886100004041733
0.027197221132764366,0.06358951790358072,259.856383313075,388.7504268782796,0.36886100004041733
0.027295782868318665,0.06381996399279856,260.09451447102344,388.7504268782796,0.36886100004041733
0.027402558081835827,0.06406961392278455,260.3521117810176,388.7504268782796,0.36886100004041733
0.027468265905538698,0.06422324464892978,260.5104386440335,388.7504268782796,0.36886100004041733
0.027492906339427275,0.06428085617123425,260.5697731279663,388.7504268782796,0.36886100004041733
0.027616108508870155,0.06456891378275655,260.8661350238592,388.7504268782796,0.36886100004041733
0.027731097200350177,0.0648377675535107,261.1422745809231,388.7504268782796,0.36886100004041733
0.02792000719349593,0.06527945589117824,261.594964947718,388.7504268782796,0.36886100004041733
0.028067849796827388,0.065625125025005,261.94841163948195,388.7504268782796,0.36886100004041733
0.028396388915341735,0.06639327865573115,262.73125956570584,388.7504268782796,0.36886100004041733
0.028733141511818945,0.06718063612722545,263.5300214018206,388.7504268782796,0.36886100004041733
0.028839916725336107,0.06743028605721145,263.78252391335735,388.7504268782796,0.36886100004041733
0.028913838027001832,0.06760312062412482,263.95711980810523,388.7504268782796,0.36886100004041733
0.029004186284593277,0.06781436287257452,264.17027855782254,388.7504268782796,0.36886100004041733
0.029094534542184726,0.06802560512102421,264.3831785077435,388.7504268782796,0.36886100004041733
0.029225950189590465,0.06833286657331467,264.692391465423,388.7504268782796,0.36886100004041733
0.029340938881070488,0.06860172034406882,264.96250826028165,388.7504268782796,0.36886100004041733
0.029554489308104812,0.06910102020404081,265.46306093685837,388.7504268782796,0.36886100004041733
0.029628410609770544,0.0692738547709542,265.63600026929817,388.7504268782796,0.36886100004041733
0.029694118433473412,0.06942748549709943,265.7895829028619,388.7504268782796,0.36886100004041733
0.029858387992730585,0.0698115623124625,266.1729607537783,388.7504268782796,0.36886100004041733
0.030104792331616347,0.0703876775355071,266.7464887759627,388.7504268782796,0.36886100004041733
0.03035119667050211,0.07096379275855172,267.3181889303685,388.7504268782796,0.36886100004041733
0.030531893185685,0.07138627725545109,267.73628593970005,388.7504268782796,0.36886100004041733
0.030655095355127882,0.0716743348669734,268.02079894237903,388.7504268782796,0.36886100004041733
0.030753657090682184,0.07190478095619124,268.2480883945129,388.7504268782796,0.36886100004041733
0.030901499694013644,0.07225045009001801,268.58849063033045,388.7504268782796,0.36886100004041733
0.031131477076973686,0.07278815763152631,269.11674547630884,388.7504268782796,0.36886100004041733
0.03133681402604516,0.07326825365073016,269.5871168903847,388.7504268782796,0.36886100004041733
0.031386094893822304,0.07338347669533907,269.69982698170054,388.7504268782796,0.36886100004041733
0.03150929706326519,0.07367153430686138,269.9813006729258,388.7504268782796,0.36886100004041733
0.03155036445307948,0.07376755351070215,270.07502981135787,388.7504268782796,0.36886100004041733
0.03163249923270807,0.07395959191838368,270.26234546786105,388.7504268782796,0.36886100004041733
0.03169820705641094,0.07411322264452891,270.4120614562275,388.7504268782796,0.36886100004041733
0.0319446113952967,0.07468933786757352,270.97242170181823,388.7504268782796,0.36886100004041733
0.03210888095455387,0.07507341468293659,271.3450589793008,388.7504268782796,0.36886100004041733
0.03235528529343963,0.0756495299059812,271.90262385275213,388.7504268782796,0.36886100004041733
0.032527768330659665,0.07605281056211242,272.29193435007346,388.7504268782796,0.36886100004041733
0.03261811658825111,0.07626405281056212,272.49553753961203,388.7504268782796,0.36886100004041733
0.033045217442319766,0.07726265253050611,273.4550636623602,388.7504268782796,0.36886100004041733
0.03316020613379979,0.07753150630126025,273.71256969279943,388.7504268782796,0.36886100004041733
0.03326698134731695,0.07778115623124625,273.95137078464217,388.7504268782796,0.36886100004041733
0.03376800350305133,0.07895259051810362,275.0679310729725,388.7504268782796,0.36886100004041733
0.0341129695774914,0.07975915183036608,275.8329572617009,388.7504268782796,0.36886100004041733
0.03419510435711998,0.07995119023804761,276.0146609332862,388.7504268782796,0.36886100004041733
0.03427723913674857,0.08014322864572915,276.19619447186653,388.7504268782796,0.36886100004041733
0.03431009304860001,0.08022004400880177,276.26876037703954,388.7504268782796,0.36886100004041733
0.03450721651970862,0.08068093618723746,276.7035880811206,388.7504268782796,0.36886100004041733
0.03457292434341149,0.08083456691338269,276.8483152313279,388.7504268782796,0.36886100004041733
0.03470433999081723,0.08114182836567314,277.13744811057734,388.7504268782796,0.36886100004041733
0.03486039607211155,0.08150670134026806,277.48023939782695,388.7504268782796,0.36886100004041733
0.035008238675443,0.08185237047409483,277.8044374059913,388.7504268782796,0.36886100004041733
0.035032879109331574,0.08190998199639929,277.8584184531044,388.7504268782796,0.36886100004041733
0.03532035083803163,0.08258211642328467,278.48710716880817,388.7504268782796,0.36886100004041733
0.035451766485437367,0.08288937787557511,278.7738427618223,388.7504268782796,0.36886100004041733
0.03557496865488025,0.08317743548709743,279.0422811339857,388.7504268782796,0.36886100004041733
0.03562424952265741,0.08329265853170635,279.1495549360088,388.7504268782796,0.36886100004041733
0.035731024736174566,0.08354230846169235,279.3817831653361,388.7504268782796,0.36886100004041733
0.03596921559709747,0.0840992198439688,279.89885768148247,388.7504268782796,0.36886100004041733
0.03610063124450321,0.08440648129625926,280.1835684877458,388.7504268782796,0.36886100004041733
0.03619919298005751,0.0846369273854771,280.3968364093422,388.7504268782796,0.36886100004041733
0.03638810297320327,0.08507861572314464,280.8049679911662,388.7504268782796,0.36886100004041733
0.03644559731894327,0.08521304260852171,280.92901782305967,388.7504268782796,0.36886100004041733
0.03646202427486899,0.08525145029005801,280.9644466111224,388.7504268782796,0.36886100004041733
0.03682341730523477,0.08609641928385678,281.7423120321032,388.7504268782796,0.36886100004041733
0.03720123729152628,0.08697979595919185,282.55235825937575,388.7504268782796,0.36886100004041733
0.03726694511522915,0.08713342668533708,282.6929077141705,388.7504268782796,0.36886100004041733
0.03782546161670354,0.08843928785757152,283.88370099620096,388.7504268782796,0.36886100004041733
0.037915809874294985,0.08865053010602121,284.0756831112987,388.7504268782796,0.36886100004041733
0.03800615813188643,0.0888617723544709,284.2674868967569,388.7504268782796,0.36886100004041733
0.03814578725725502,0.0891882376475295,284.56356153281996,388.7504268782796,0.36886100004041733
0.03828541638262362,0.08951470294058812,284.859213805314,388.7504268782796,0.36886100004041733
0.038359337684289355,0.08968753750750151,285.0155653362404,388.7504268782796,0.36886100004041733
0.038416832030029366,0.08982196439287858,285.1370908571878,388.7504268782796,0.36886100004041733
0.03871251723669227,0.0905133026605321,285.7609623608055,388.7504268782796,0.36886100004041733
0.038843932884098015,0.09082056411282256,286.0376417748619,388.7504268782796,0.36886100004041733
0.0389260676637266,0.09101260252050411,286.2103810392119,388.7504268782796,0.36886100004041733
0.039024629399280905,0.09124304860972195,286.4174806340654,388.7504268782796,0.36886100004041733
0.03909033722298378,0.09139667933586718,286.5554337131857,388.7504268782796,0.36886100004041733
0.03923817982631523,0.09174234846969394,286.86549791206033,388.7504268782796,0.36886100004041733
0.039681707636309606,0.09277935587117424,287.79296823613475,388.7504268782796,0.36886100004041733
0.03975562893797534,0.09295219043808763,287.9471527167413,388.7504268782796,0.36886100004041733
0.03981312328371534,0.0930866173234647,288.0669966926646,388.7504268782796,0.36886100004041733
0.03996917936500966,0.09345149029805962,288.3919477331042,388.7504268782796,0.36886100004041733
0.04005952762260111,0.09366273254650931,288.5798511228904,388.7504268782796,0.36886100004041733
0.04030593196148687,0.09423884776955392,289.0914767460221,388.7504268782796,0.36886100004041733
0.040544122822409774,0.09479575915183037,289.58488993721164,388.7504268782796,0.36886100004041733
0.040585190212224065,0.09489177835567114,289.6698467898061,388.7504268782796,0.36886100004041733
0.040708392381666944,0.09517983596719344,289.9245164144808,388.7504268782796,0.36886100004041733
0.04079874063925839,0.09539107821564313,290.11108313793255,388.7504268782796,0.36886100004041733
0.04083980802907268,0.0954870974194839,290.19583292165737,388.7504268782796,0.36886100004041733
0.04100407758832986,0.09587117423484698,290.5345002189944,388.7504268782796,0.36886100004041733
0.041488672788138524,0.09700420084016805,291.5304993324756,388.7504268782796,0.36886100004041733
0.04155438061184139,0.09715783156631327,291.6651999115243,388.7504268782796,0.36886100004041733
0.04191577364220717,0.09800280056011203,292.40457357939613,388.7504268782796,0.36886100004041733
0.04208004320146435,0.09838687737547509,292.73983022926325,388.7504268782796,0.36886100004041733
0.042227885804795806,0.09873254650930187,293.04112506183094,388.7504268782796,0.36886100004041733
0.04228538015053582,0.09886697339467894,293.15818413865105,388.7504268782796,0.36886100004041733
0.0424085823199787,0.09915503100620124,293.40881620085156,388.7504268782796,0.36886100004041733
0.04270426752664161,0.09984636927385478,294.00917739736707,388.7504268782796,0.36886100004041733