File: datasets/aisi_316_L/data/M1/train_49.csv
Time(s),Strain(%),Stress(MPa),Temp(C),Log_SR(s-1)
0.0,0.0,0.0,34.64571265887287,-1.9597714230537786
0.00109383714966071,1.2e-05,2.3459593125000002,34.64571265887287,-1.9597714230537786
0.00298982154240594,3.28e-05,6.4122887875,34.64571265887287,-1.9597714230537786
0.0038648912621345086,4.24e-05,8.2890562375,34.64571265887287,-1.9597714230537786
0.0045941160285749814,5.04e-05,9.8530291125,34.64571265887287,-1.9597714230537786
0.006052565561455929,6.64e-05,12.9809748625,34.64571265887287,-1.9597714230537786
0.008094394907489253,8.879999999999999e-05,17.3600989125,34.64571265887287,-1.9597714230537786
0.00875069719728568,9.6e-05,18.767674500000002,34.64571265887287,-1.9597714230537786
0.009625766917014247,0.00010559999999999999,20.644441949999997,34.64571265887287,-1.9597714230537786
0.010792526543319005,0.00011839999999999999,23.14679855,34.64571265887287,-1.9597714230537786
0.01582417743175827,0.0001736,33.9382113875,34.64571265887287,-1.9597714230537786
0.016188789814978507,0.00017759999999999998,34.720197825,34.64571265887287,-1.9597714230537786
0.018230619161011832,0.00019999999999999998,39.099321874999994,34.64571265887287,-1.9597714230537786
0.01939737878731659,0.0002128,41.601678475,34.64571265887287,-1.9597714230537786
0.020637060890265395,0.0002264,44.2604323625,34.64571265887287,-1.9597714230537786
0.02289765766623086,0.0002512,49.108748274999996,34.64571265887287,-1.9597714230537786
0.024501952152399902,0.0002688,52.5494886,34.64571265887287,-1.9597714230537786
0.025814556731992757,0.0002832,55.364639775,34.64571265887287,-1.9597714230537786
0.02647085902178918,0.0002904,56.7722153625,34.64571265887287,-1.9597714230537786
0.02843976589117846,0.000312,60.994942125,34.64571265887287,-1.9597714230537786
0.03303388191975344,0.00036239999999999997,70.84797123749999,34.64571265887287,-1.9597714230537786
0.034784021359210576,0.0003816,74.6015061375,34.64571265887287,-1.9597714230537786
0.0355861686022951,0.0003904,76.3218763,34.64571265887287,-1.9597714230537786
0.03660708327531176,0.0004016,78.511438325,34.64571265887287,-1.9597714230537786
0.03850306766805699,0.00042239999999999997,82.57776779999999,34.64571265887287,-1.9597714230537786
0.03908644748120937,0.00042879999999999996,83.8289461,34.64571265887287,-1.9597714230537786
0.040180284630870075,0.0004408,86.1749054125,34.64571265887287,-1.9597714230537786
0.042805493790055785,0.0004696,91.80520776249999,34.64571265887287,-1.9597714230537786
0.04397225341636054,0.00048239999999999996,94.30756436249999,34.64571265887287,-1.9597714230537786
0.045357780472597434,0.0004976,97.27911282499998,34.64571265887287,-1.9597714230537786
0.04739960981863076,0.00052,101.65823687499999,34.64571265887287,-1.9597714230537786
0.04834760201500338,0.0005304,103.6914016125,34.64571265887287,-1.9597714230537786
0.049295594211376,0.0005408,105.72456635,34.64571265887287,-1.9597714230537786
0.05046235383768075,0.0005536,108.22692295,34.64571265887287,-1.9597714230537786
0.05097281117418908,0.0005591999999999999,109.32170396249998,34.64571265887287,-1.9597714230537786
0.05337925290344264,0.0005855999999999999,114.48281444999998,34.64571265887287,-1.9597714230537786
0.053525097856730736,0.0005872,114.79560902499999,34.64571265887287,-1.9597714230537786
0.05410847766988312,0.0005936,116.046787325,34.64571265887287,-1.9597714230537786
0.058046291408661674,0.0006368,124.49224085,34.64571265887287,-1.9597714230537786
0.06103611295106762,0.0006696,130.9045296375,34.64571265887287,-1.9597714230537786
0.06176533771750809,0.0006776,132.4685025125,34.64571265887287,-1.9597714230537786
0.062275795054016425,0.0006832,133.563283525,34.64571265887287,-1.9597714230537786
0.06344255468032117,0.000696,136.065640125,34.64571265887287,-1.9597714230537786
0.06446346935333784,0.0007072,138.25520215,34.64571265887287,-1.9597714230537786
0.06752621337238783,0.0007408,144.823888225,34.64571265887287,-1.9597714230537786
0.06883881795198067,0.0007551999999999999,147.63903939999997,34.64571265887287,-1.9597714230537786
0.06956804271842115,0.0007632,149.203012275,34.64571265887287,-1.9597714230537786
0.07109941472794615,0.00078,152.4873553125,34.64571265887287,-1.9597714230537786
0.07219325187760685,0.000792,154.83331462499999,34.64571265887287,-1.9597714230537786
0.07452677113021637,0.0008175999999999999,159.83802782499998,34.64571265887287,-1.9597714230537786
0.07540184084994493,0.0008271999999999999,161.714795275,34.64571265887287,-1.9597714230537786
0.07868335229892706,0.0008632,168.75267321249999,34.64571265887287,-1.9597714230537786
0.07933965458872348,0.0008703999999999999,170.16024879999998,34.64571265887287,-1.9597714230537786
0.0821107087011973,0.0009008,176.103345725,34.64571265887287,-1.9597714230537786
0.08283993346763777,0.0009088,177.6673186,34.64571265887287,-1.9597714230537786
0.08451715043045085,0.0009272,181.2644562125,34.64571265887287,-1.9597714230537786
0.08561098758011157,0.0009392,183.61041552499998,34.64571265887287,-1.9597714230537786
0.0873611270195687,0.0009584,187.36395042499998,34.64571265887287,-1.9597714230537786
0.08809035178600917,0.0009664,188.9279233,34.64571265887287,-1.9597714230537786
0.09093432837512702,0.0009976,195.0274175125,34.64571265887287,-1.9597714230537786
0.09261154533794011,0.001016,198.624555125,34.64571265887287,-1.9597714230537786
0.09334077010438058,0.001024,200.188528,34.64571265887287,-1.9597714230537786
0.09589305678692224,0.001052,205.66243306249999,34.64571265887287,-1.9597714230537786
0.09684104898329486,0.0010624,207.6955978,34.64571265887287,-1.9597714230537786
0.09764319622637938,0.0010712,209.4159679625,34.64571265887287,-1.9597714230537786
0.09990379300234484,0.001096,214.264283875,34.64571265887287,-1.9597714230537786
0.10099763015200555,0.001108,216.6102431875,34.64571265887287,-1.9597714230537786
0.10150808748851388,0.0011136,217.7050242,34.64571265887287,-1.9597714230537786
0.1036957617878353,0.0011376,222.39694282499997,34.64571265887287,-1.9597714230537786
0.10493544389078412,0.0011512,225.0556967125,34.64571265887287,-1.9597714230537786
0.106320970947021,0.0011664,228.027245175,34.64571265887287,-1.9597714230537786
0.10675850580688528,0.0011711999999999998,228.96562889999996,34.64571265887287,-1.9597714230537786
0.10712311819010553,0.0011752,229.74761533749998,34.64571265887287,-1.9597714230537786
0.10996709477922338,0.0012064,235.84710955,34.64571265887287,-1.9597714230537786
0.11098800945224004,0.0012175999999999999,238.03667157499999,34.64571265887287,-1.9597714230537786
0.11281107136834122,0.0012376,241.9466037625,34.64571265887287,-1.9597714230537786
0.11434244337786621,0.0012544,245.23094679999997,34.64571265887287,-1.9597714230537786
0.11456121080779835,0.0012568,245.7001386625,34.64571265887287,-1.9597714230537786
0.11521751309759477,0.001264,247.10771425,34.64571265887287,-1.9597714230537786
0.1164571952005436,0.0012776,249.7664681375,34.64571265887287,-1.9597714230537786
0.11733226492027214,0.0012871999999999998,251.64323558749996,34.64571265887287,-1.9597714230537786
0.11820733464000072,0.0012967999999999999,253.52000303749998,34.64571265887287,-1.9597714230537786
0.11951993921959357,0.0013112,256.3351542125,34.64571265887287,-1.9597714230537786
0.12039500893932215,0.0013208,258.2119216625,34.64571265887287,-1.9597714230537786
0.12127007865905072,0.0013304,260.0886891125,34.64571265887287,-1.9597714230537786
0.12396821029488045,0.0013599999999999999,265.87538874999996,34.64571265887287,-1.9597714230537786
0.1255725047810495,0.0013775999999999999,269.316129075,34.64571265887287,-1.9597714230537786
0.1269580318372864,0.0013928,272.28767753750003,34.64571265887287,-1.9597714230537786
0.1272497217438626,0.0013959999999999999,272.91326668749997,34.64571265887287,-1.9597714230537786
0.1287810937533876,0.0014127999999999999,276.19760972499995,34.64571265887287,-1.9597714230537786
0.1301666208096245,0.001428,279.1691581875,34.64571265887287,-1.9597714230537786
0.13089584557606496,0.001436,280.7331310625,34.64571265887287,-1.9597714230537786
0.132500140062234,0.0014536,282.08975035500396,34.64571265887287,-1.9597714230537786
0.13476073683819947,0.0014784,282.2830497352151,34.64571265887287,-1.9597714230537786
0.1377505583806054,0.0015111999999999999,282.5367724701218,34.64571265887287,-1.9597714230537786
0.13935485286677443,0.0015287999999999999,282.6720305461328,34.64571265887287,-1.9597714230537786
0.13986531020328277,0.0015344,282.714939674283,34.64571265887287,-1.9597714230537786
0.14125083725951967,0.0015496,282.8311005445663,34.64571265887287,-1.9597714230537786
0.14300097669897682,0.0015688,282.9771968474378,34.64571265887287,-1.9597714230537786
0.14489696109172204,0.0015895999999999998,283.1346831459843,34.64571265887287,-1.9597714230537786
0.14518865099829822,0.0015928,283.1588402894986,34.64571265887287,-1.9597714230537786
0.14613664319467085,0.0016032,283.2372206098744,34.64571265887287,-1.9597714230537786
0.1470117129143994,0.0016128,283.30939585160644,34.64571265887287,-1.9597714230537786
0.1486889298772125,0.0016312,283.44726512148884,34.64571265887287,-1.9597714230537786
0.1497827670268732,0.0016431999999999998,283.5368532197716,34.64571265887287,-1.9597714230537786
0.15109537160646608,0.0016576,283.6440228338498,34.64571265887287,-1.9597714230537786
0.15226213123277083,0.0016703999999999998,283.7389802691541,34.64571265887287,-1.9597714230537786
0.15262674361599107,0.0016744,283.7685962149966,34.64571265887287,-1.9597714230537786
0.15364765828900773,0.0016856,283.8513744306328,34.64571265887287,-1.9597714230537786
0.15415811562551604,0.0016912,283.8926830778361,34.64571265887287,-1.9597714230537786
0.15554364268175294,0.0017063999999999998,284.0045385194123,34.64571265887287,-1.9597714230537786
0.15692916973798987,0.0017216,284.1160060454521,34.64571265887287,-1.9597714230537786
0.15831469679422674,0.0017368,284.2270904085103,34.64571265887287,-1.9597714230537786
0.1599189912803958,0.0017544,284.3552418338257,34.64571265887287,-1.9597714230537786
0.16050237109354817,0.0017607999999999999,284.4017179157609,34.64571265887287,-1.9597714230537786
0.1622525105330053,0.00178,284.540752472894,34.64571265887287,-1.9597714230537786
0.16429433987903863,0.0018024,284.70222237530834,34.64571265887287,-1.9597714230537786
0.16582571188856363,0.0018192,284.82281169869145,34.64571265887287,-1.9597714230537786
0.16662785913164815,0.001828,284.88580416099484,34.64571265887287,-1.9597714230537786
0.16961768067405408,0.0018608,285.11955957244965,34.64571265887287,-1.9597714230537786
0.17107613020693502,0.0018767999999999999,285.233003021382,34.64571265887287,-1.9597714230537786
0.17297211459968026,0.0018976,285.37991721526333,34.64571265887287,-1.9597714230537786
0.17399302927269694,0.0019088,285.4587646660647,34.64571265887287,-1.9597714230537786
0.1742847191792731,0.0019119999999999999,285.4812593423073,34.64571265887287,-1.9597714230537786
0.17574316871215406,0.0019279999999999998,285.59351323402393,34.64571265887287,-1.9597714230537786
0.17647239347859453,0.001936,285.6495038956327,34.64571265887287,-1.9597714230537786
0.17712869576839096,0.0019432,285.69981838910815,34.64571265887287,-1.9597714230537786
0.17771207558154334,0.0019496,285.74448137812897,34.64571265887287,-1.9597714230537786
0.1796809824509326,0.0019711999999999998,285.89479859742795,34.64571265887287,-1.9597714230537786
0.18157696684367783,0.001992,286.03894254115625,34.64571265887287,-1.9597714230537786
0.18354587371306713,0.0020136,286.18801055211924,34.64571265887287,-1.9597714230537786
0.18500432324594807,0.0020296,286.2980295486799,34.64571265887287,-1.9597714230537786
0.18573354801238856,0.0020376,286.3529121645033,34.64571265887287,-1.9597714230537786
0.1870461525919814,0.002052,286.45148956785187,34.64571265887287,-1.9597714230537786
0.1901088966110314,0.0020856,286.6804602451782,34.64571265887287,-1.9597714230537786
0.19054643147089567,0.0020904,286.7130525158338,34.64571265887287,-1.9597714230537786
0.19353625301330163,0.0021232,286.9349903545299,34.64571265887287,-1.9597714230537786
0.19404671034980991,0.0021287999999999997,286.9727481513678,34.64571265887287,-1.9597714230537786
0.19696360941557184,0.0021608,287.18776848498686,34.64571265887287,-1.9597714230537786
0.19973466352804564,0.0021912,287.3908903860337,34.64571265887287,-1.9597714230537786
0.20235987268723132,0.0022199999999999998,287.58231022581776,34.64571265887287,-1.9597714230537786
0.2054226167062813,0.0022535999999999997,287.8044135827185,34.64571265887287,-1.9597714230537786
0.20607891899607775,0.0022608,287.8518387096318,34.64571265887287,-1.9597714230537786
0.20688106623916228,0.0022696,287.9097228364434,34.64571265887287,-1.9597714230537786
0.20870412815526343,0.0022895999999999997,288.0409531297997,34.64571265887287,-1.9597714230537786
0.21016257768814442,0.0023056,288.1456157626126,34.64571265887287,-1.9597714230537786
0.2118397946509575,0.002324,288.2656282424776,34.64571265887287,-1.9597714230537786
0.2129336318006182,0.002336,288.3436976563506,34.64571265887287,-1.9597714230537786
0.2133711666604825,0.0023408,288.3748816093743,34.64571265887287,-1.9597714230537786
0.2147566937167194,0.002356,288.4734666710985,34.64571265887287,-1.9597714230537786
0.21978834460515867,0.0024112,288.82941875820666,34.64571265887287,-1.9597714230537786
0.22008003451173483,0.0024143999999999997,288.8499556587969,34.64571265887287,-1.9597714230537786
0.22161140652125982,0.0024311999999999997,288.95760072391124,34.64571265887287,-1.9597714230537786
0.22285108862420866,0.0024448,289.04452964548597,34.64571265887287,-1.9597714230537786
0.22481999549359793,0.0024664,289.1822066024312,34.64571265887287,-1.9597714230537786
0.22722643722285146,0.0024928,289.34984149706855,34.64571265887287,-1.9597714230537786
0.22766397208271577,0.0024976,289.3802460347671,34.64571265887287,-1.9597714230537786
0.22868488675573242,0.0025088,289.45110147101025,34.64571265887287,-1.9597714230537786
0.2292682665688848,0.0025152,289.49153490262006,34.64571265887287,-1.9597714230537786
0.22985164638203717,0.0025215999999999997,289.5319282293014,34.64571265887287,-1.9597714230537786
0.2305079486718336,0.0025288,289.5773229599433,34.64571265887287,-1.9597714230537786
0.23626882432671334,0.0025919999999999997,289.9736477406257,34.64571265887287,-1.9597714230537786
0.23677928166322168,0.0025976,290.0085823408408,34.64571265887287,-1.9597714230537786
0.23794604128952643,0.0026103999999999997,290.088322747522,34.64571265887287,-1.9597714230537786
0.2383835761493907,0.0026152,290.1181860674519,34.64571265887287,-1.9597714230537786
0.2391128009158312,0.0026232,290.1679108075757,34.64571265887287,-1.9597714230537786
0.2411546302618645,0.0026455999999999997,290.306826426882,34.64571265887287,-1.9597714230537786
0.24166508759837285,0.0026512,290.3414835649676,34.64571265887287,-1.9597714230537786
0.24385276189769428,0.0026752,290.4896919534506,34.64571265887287,-1.9597714230537786
0.24458198666413472,0.0026831999999999997,290.5389793971211,34.64571265887287,-1.9597714230537786
0.2476447306831847,0.0027167999999999997,290.74536393168705,34.64571265887287,-1.9597714230537786
0.24997824993579423,0.0027424,290.9019418216437,34.64571265887287,-1.9597714230537786
0.2531868389081323,0.0027776,291.1163088259147,34.64571265887287,-1.9597714230537786
0.2550099008242335,0.0027976,291.23763621296786,34.64571265887287,-1.9597714230537786
0.25603081549725015,0.0028087999999999998,291.30543178165567,34.64571265887287,-1.9597714230537786
0.25719757512355496,0.0028216,291.3827834678227,34.64571265887287,-1.9597714230537786
0.2583643347498597,0.0028344,291.4599984231216,34.64571265887287,-1.9597714230537786
0.2591664819929442,0.0028431999999999997,291.513004836299,34.64571265887287,-1.9597714230537786
0.2604790865725371,0.0028576,291.59960479772326,34.64571265887287,-1.9597714230537786
0.2617187686754859,0.0028712,291.6812375091645,34.64571265887287,-1.9597714230537786
0.26434397783467156,0.0029,291.85361065047823,34.64571265887287,-1.9597714230537786
0.26616703975077277,0.00292,291.9729216310658,34.64571265887287,-1.9597714230537786
0.2668962645172132,0.002928,292.02055673405744,34.64571265887287,-1.9597714230537786
0.26806302414351796,0.0029408,292.09666745673,34.64571265887287,-1.9597714230537786
0.27112576816256795,0.0029744,292.2958459233206,34.64571265887287,-1.9597714230537786
0.27221960531222866,0.0029863999999999997,292.3667681807332,34.64571265887287,-1.9597714230537786
0.27294883007866916,0.0029944,292.41398794973344,34.64571265887287,-1.9597714230537786
0.2730946750319573,0.002996,292.42342599671,34.64571265887287,-1.9597714230537786
0.2761574190510072,0.0030296,292.621173177756,34.64571265887287,-1.9597714230537786
0.2768137213408036,0.0030367999999999997,292.6634360846458,34.64571265887287,-1.9597714230537786
0.2776158685838882,0.0030456,292.7150377161577,34.64571265887287,-1.9597714230537786
0.278928473163481,0.00306,292.7993514989089,34.64571265887287,-1.9597714230537786
0.27980354288320963,0.0030696,292.8554747365692,34.64571265887287,-1.9597714230537786
0.2809703025095144,0.0030824,292.93019935260116,34.64571265887287,-1.9597714230537786
0.281918294705887,0.0030927999999999997,292.99082403406936,34.64571265887287,-1.9597714230537786
0.28556441853808934,0.0031328,293.2232586773068,34.64571265887287,-1.9597714230537786
0.28702286807097027,0.0031487999999999998,293.3159081066908,34.64571265887287,-1.9597714230537786
0.2874604029308346,0.0031536,293.3436671090913,34.64571265887287,-1.9597714230537786
0.2903043795199524,0.0031848,293.5237006420379,34.64571265887287,-1.9597714230537786
0.2908877593331048,0.0031912,293.5605454326944,34.64571265887287,-1.9597714230537786
0.292710821249206,0.0032112,293.6755000990043,34.64571265887287,-1.9597714230537786
0.2944609606886631,0.0032304,293.7855941706334,34.64571265887287,-1.9597714230537786
0.2958464877449,0.0032456,293.87257109704984,34.64571265887287,-1.9597714230537786
0.29621110012812024,0.0032496,293.8954333402441,34.64571265887287,-1.9597714230537786
0.2970861698478488,0.0032592,293.9502579913976,34.64571265887287,-1.9597714230537786
0.29912799919388217,0.0032816,294.0779378401004,34.64571265887287,-1.9597714230537786
0.30109690606327144,0.0033032,294.20073617666,34.64571265887287,-1.9597714230537786
0.30284704550272856,0.0033223999999999997,294.3096275926161,34.64571265887287,-1.9597714230537786
0.30693070419479523,0.0033672,294.5627576020548,34.64571265887287,-1.9597714230537786
0.3087537661108964,0.0033872,294.67533764681986,34.64571265887287,-1.9597714230537786
0.3091913009707607,0.003392,294.7023182455487,34.64571265887287,-1.9597714230537786
0.3105039055503535,0.0034064,294.7831708417584,34.64571265887287,-1.9597714230537786
0.31167066517665826,0.0034192,294.85492797873053,34.64571265887287,-1.9597714230537786
0.31407710690591184,0.0034456,295.0025970523999,34.64571265887287,-1.9597714230537786
0.3167023160650976,0.0034744,295.16318824030867,34.64571265887287,-1.9597714230537786
0.3183066105512666,0.003492,295.26107175597684,34.64571265887287,-1.9597714230537786
0.3197650600841475,0.003508,295.3498899364759,34.64571265887287,-1.9597714230537786
0.32224442429004513,0.0035351999999999996,295.500519112761,34.64571265887287,-1.9597714230537786
0.32414040868279037,0.0035559999999999997,295.6154013530944,34.64571265887287,-1.9597714230537786
0.3247967109725868,0.0035632,295.6551071842125,34.64571265887287,-1.9597714230537786
0.3257447031689594,0.0035735999999999997,295.7124048549495,34.64571265887287,-1.9597714230537786
0.32749484260841655,0.0035927999999999997,295.81801460695976,34.64571265887287,-1.9597714230537786
0.3280052999449249,0.0035984,295.84877596025103,34.64571265887287,-1.9597714230537786
0.3318701912070594,0.0036408,296.0810805542536,34.64571265887287,-1.9597714230537786
0.33267233845014393,0.0036496,296.129162232737,34.64571265887287,-1.9597714230537786
0.33369325312316056,0.0036607999999999996,296.19029175334333,34.64571265887287,-1.9597714230537786
0.3340578655063808,0.0036647999999999997,296.21210604295464,34.64571265887287,-1.9597714230537786
0.33486001274946536,0.0036736,296.2600648211301,34.64571265887287,-1.9597714230537786
0.3362455398057022,0.0036888,296.3427973130823,34.64571265887287,-1.9597714230537786
0.3400375085911927,0.0037304,296.56854599521995,34.64571265887287,-1.9597714230537786
0.34135011317078556,0.0037448,296.64646074122174,34.64571265887287,-1.9597714230537786
0.34258979527373434,0.0037584,296.71993966952056,34.64571265887287,-1.9597714230537786
0.3432460975635308,0.0037656,296.7587982941962,34.64571265887287,-1.9597714230537786
0.34485039204969986,0.0037832,296.85366425566934,34.64571265887287,-1.9597714230537786
0.3459442291993605,0.0037952,296.91824693075546,34.64571265887287,-1.9597714230537786
0.34645468653586886,0.0038008,296.9483582536178,34.64571265887287,-1.9597714230537786
0.3473297562555974,0.0038104,296.99993744071287,34.64571265887287,-1.9597714230537786
0.35002788789142714,0.0038399999999999997,297.15865515584215,34.64571265887287,-1.9597714230537786
0.3523614071440367,0.0038656,297.295540136429,34.64571265887287,-1.9597714230537786
0.3538198566769176,0.0038816,297.38091373951283,34.64571265887287,-1.9597714230537786
0.35564291859301883,0.0039016,297.4874379883842,34.64571265887287,-1.9597714230537786
0.3563721433594593,0.0039096,297.5299880332833,34.64571265887287,-1.9597714230537786
0.3580493603222724,0.003928,297.6277244814391,34.64571265887287,-1.9597714230537786
0.3592161199485771,0.0039407999999999995,297.6956097711534,34.64571265887287,-1.9597714230537786
0.3627893213041355,0.00398,297.90297551771414,34.64571265887287,-1.9597714230537786
0.3634456235939319,0.0039872,297.9409763595761,34.64571265887287,-1.9597714230537786
0.3644665382669486,0.0039984,298.0000356295556,34.64571265887287,-1.9597714230537786
0.4276300065653626,0.004691338267653531,301.53758034235807,34.64571265887287,-1.9597714230537786
0.45913881823792557,0.0050370074014802965,303.22547320376486,34.64571265887287,-1.9597714230537786
0.5536652532556144,0.006074014802960592,308.03664188562146,34.64571265887287,-1.9597714230537786
0.6324372824370218,0.006938187637527506,311.8049556376117,34.64571265887287,-1.9597714230537786
0.6429402196612095,0.007053410682136428,312.2931847471921,34.64571265887287,-1.9597714230537786
0.6586946254974909,0.0072262452490498095,313.01973616485395,34.64571265887287,-1.9597714230537786
0.6937044162447831,0.007610322064412882,314.61045812152054,34.64571265887287,-1.9597714230537786
0.7409676337536275,0.00812882576515303,316.70911630055855,34.64571265887287,-1.9597714230537786
0.7742269349635551,0.00849369873974795,318.15475146515354,34.64571265887287,-1.9597714230537786
0.8039852570987535,0.008820164032806561,319.42780668393414,34.64571265887287,-1.9597714230537786
0.9020126711911717,0.009895579115823165,323.4970624891132,34.64571265887287,-1.9597714230537786
0.9335214828637346,0.01024124824964993,324.7678869832027,34.64571265887287,-1.9597714230537786
1.0052915538956835,0.011028605721144228,327.60167598104454,34.64571265887287,-1.9597714230537786
1.015794491119871,0.01114382876575315,328.00965995892597,34.64571265887287,-1.9597714230537786
1.029798407418788,0.011297459491898379,328.5510885758723,34.64571265887287,-1.9597714230537786
1.0578062400166217,0.011604720944188837,329.62540718303654,34.64571265887287,-1.9597714230537786
1.070059666778174,0.011739147829565914,330.091926845373,34.64571265887287,-1.9597714230537786
1.1348277796606645,0.012449689937987597,332.5240398969013,34.64571265887287,-1.9597714230537786
1.159334633183769,0.012718543708741748,333.43010199227325,34.64571265887287,-1.9597714230537786
1.1715880599453214,0.012852970594118824,333.880329604358,34.64571265887287,-1.9597714230537786
1.1943444239310612,0.013102620524104821,334.71162416430093,34.64571265887287,-1.9597714230537786
1.2433581309772703,0.013640328065613123,336.48140826887555,34.64571265887287,-1.9597714230537786
1.2608630263509164,0.013832366473294659,337.1068522871287,34.64571265887287,-1.9597714230537786
1.2976233066355731,0.014235647129425886,338.4093676592327,34.64571265887287,-1.9597714230537786
1.3326330973828655,0.014619723944788958,339.6365428461769,34.64571265887287,-1.9597714230537786
1.3798963148917098,0.015138227645529106,341.2734668289928,34.64571265887287,-1.9597714230537786
1.3939002311906268,0.015291858371674336,341.75426273756443,34.64571265887287,-1.9597714230537786
1.4306605114752833,0.01569513902780556,343.00747303364136,34.64571265887287,-1.9597714230537786
1.463919812685211,0.01606001200240048,344.1305493446032,34.64571265887287,-1.9597714230537786
1.5094325406566906,0.016559311862372472,345.6513956474514,34.64571265887287,-1.9597714230537786
1.5146840092687845,0.016616923384676935,345.82571950177737,34.64571265887287,-1.9597714230537786
1.5321889046424308,0.01680896179235847,346.40510413698615,34.64571265887287,-1.9597714230537786
1.5777016326139106,0.017308261652330466,347.89954947256524,34.64571265887287,-1.9597714230537786
1.6232143605853904,0.01780756151230246,349.3772729897569,34.64571265887287,-1.9597714230537786
1.6547231722579534,0.018153230646129226,350.39085930797546,34.64571265887287,-1.9597714230537786
1.7124893269909853,0.018786957391478294,352.22976245505663,34.64571265887287,-1.9597714230537786
1.7667545026492883,0.01938227645529106,353.9352989372081,34.64571265887287,-1.9597714230537786
1.7807584189482053,0.019535907181436288,354.3721054602127,34.64571265887287,-1.9597714230537786
1.7965128247844866,0.01970874174834967,354.86191463069844,34.64571265887287,-1.9597714230537786
1.898041217951634,0.02082256451290258,357.97920541691906,34.64571265887287,-1.9597714230537786
1.9225480714747385,0.02109141828365673,358.721827198972,34.64571265887287,-1.9597714230537786
2.0433318495528967,0.022416483296659333,362.32929066362976,34.64571265887287,-1.9597714230537786
2.0573357658518137,0.022570114022804563,362.74209669524424,34.64571265887287,-1.9597714230537786
2.101098004285929,0.023050210042008402,364.02510836950324,34.64571265887287,-1.9597714230537786
2.122103878734304,0.023280656131226245,364.6372483840596,34.64571265887287,-1.9597714230537786
2.130856326421127,0.023376675335067015,364.8916087419814,34.64571265887287,-1.9597714230537786
2.1868719916167945,0.02399119823964793,366.5099715251678,34.64571265887287,-1.9597714230537786
2.2008759079157114,0.024144828965793157,366.9120260997587,34.64571265887287,-1.9597714230537786
2.2131293346772636,0.024279255851170235,367.2630061277935,34.64571265887287,-1.9597714230537786
2.260392552186108,0.02479775955191038,368.609745895692,34.64571265887287,-1.9597714230537786
2.342665560442245,0.025700340068013604,370.9281607326791,34.64571265887287,-1.9597714230537786
2.3654219244279844,0.0259499899979996,371.56378983896985,34.64571265887287,-1.9597714230537786
2.3794258407269013,0.02610362072414483,371.9537610164307,34.64571265887287,-1.9597714230537786
2.389928777951089,0.02621884376875375,372.24565225688013,34.64571265887287,-1.9597714230537786
2.412685141936829,0.02646849369873975,372.8763725599157,34.64571265887287,-1.9597714230537786
2.423188079161017,0.02658371674334867,373.16669131519353,34.64571265887287,-1.9597714230537786
2.4424434640720274,0.02679495899179836,373.69767096396475,34.64571265887287,-1.9597714230537786
2.4774532548193196,0.027179035807161432,374.6589246528335,34.64571265887287,-1.9597714230537786
2.515964024641341,0.027601520304060812,375.71020542380967,34.64571265887287,-1.9597714230537786
2.5404708781644456,0.027870374074814963,376.37593600113905,34.64571265887287,-1.9597714230537786
2.631496334107405,0.028868973794758952,378.82702241638805,34.64571265887287,-1.9597714230537786
2.6980149365272603,0.02959871974394879,380.59733721887596,34.64571265887287,-1.9597714230537786
2.7312742377371877,0.029963592718543708,381.47610512017053,34.64571265887287,-1.9597714230537786
2.7750364761713033,0.03044368873774755,382.62604644151656,34.64571265887287,-1.9597714230537786
2.820549204142783,0.030942988597719545,383.81450775906194,34.64571265887287,-1.9597714230537786
2.864311442576898,0.031423084616923384,384.95022566824053,34.64571265887287,-1.9597714230537786
2.8870678065626385,0.03167273454690939,385.5381233606724,34.64571265887287,-1.9597714230537786
2.9010717228615555,0.031826365273054616,385.8990084022524,34.64571265887287,-1.9597714230537786
2.918576618235201,0.03201840368073615,386.3491607263298,34.64571265887287,-1.9597714230537786
2.923828086847295,0.03207601520304061,386.48400093600657,34.64571265887287,-1.9597714230537786
2.9640893462066806,0.03251770354070814,387.5146563162358,34.64571265887287,-1.9597714230537786
3.0323584381639006,0.033266653330666134,389.24989764399135,34.64571265887287,-1.9597714230537786
3.0463623544628176,0.03342028405681136,389.6039539306725,34.64571265887287,-1.9597714230537786
3.0726196975232867,0.03370834166833367,390.26610330495,34.64571265887287,-1.9597714230537786
3.1041285091958493,0.03405401080216043,391.05777667644014,34.64571265887287,-1.9597714230537786
3.1268848731815893,0.034303660732146427,391.6275929657681,34.64571265887287,-1.9597714230537786
3.130385852256319,0.03434206841368274,391.71511325627637,34.64571265887287,-1.9597714230537786
3.1688966220783397,0.034764552910582114,392.6753304896266,34.64571265887287,-1.9597714230537786
3.23366473496083,0.0354750950190038,394.28004082142195,34.64571265887287,-1.9597714230537786
3.28267844200704,0.036012802560512105,395.4860971251706,34.64571265887287,-1.9597714230537786
3.3579494921137183,0.036838567713542714,397.32466979814467,34.64571265887287,-1.9597714230537786
3.363200960725812,0.036896179235847176,397.45233929278777,34.64571265887287,-1.9597714230537786
3.387707814248916,0.03716503300660132,398.0471053157495,34.64571265887287,-1.9597714230537786
3.41921662592148,0.03751070214042809,398.8093446472819,34.64571265887287,-1.9597714230537786
3.4244680945335726,0.03756831366273254,398.9361177301171,34.64571265887287,-1.9597714230537786
3.4472244585193135,0.03781796359271855,399.48459395030636,34.64571265887287,-1.9597714230537786
3.4577273957435004,0.03793318663732746,399.7372603878897,34.64571265887287,-1.9597714230537786
3.522495508625991,0.038643728745749145,401.28880743861936,34.64571265887287,-1.9597714230537786
3.5592557889106473,0.03904700940188037,402.1644651200677,34.64571265887287,-1.9597714230537786
3.6275248808678677,0.03979595919183837,403.7813853946865,34.64571265887287,-1.9597714230537786
3.6397783076294195,0.03993038607721544,404.07034121323215,34.64571265887287,-1.9597714230537786
3.7027959309745464,0.04062172434486898,405.5504492180982,34.64571265887287,-1.9597714230537786
3.734304742647109,0.04096739347869574,406.2868167872341,34.64571265887287,-1.9597714230537786
3.748308658946026,0.04112102420484097,406.6133130435103,34.64571265887287,-1.9597714230537786
3.7745660020064946,0.04140908181636327,407.22421415633073,34.64571265887287,-1.9597714230537786
3.7920708973801416,0.041601120224044816,407.6305610580213,34.64571265887287,-1.9597714230537786
3.849837052113173,0.04223484696939388,408.96634540669004,34.64571265887287,-1.9597714230537786
3.86384096841209,0.042388477695539106,409.28899193762805,34.64571265887287,-1.9597714230537786
3.9076032068462054,0.04286857371474295,410.29433537873587,34.64571265887287,-1.9597714230537786
3.9356110394440393,0.04317583516703341,410.93545145002423,34.64571265887287,-1.9597714230537786
4.01613355816281,0.04405921184236847,412.76882255389,34.64571265887287,-1.9597714230537786
4.049392859372738,0.04442408481696339,413.5218943442753,34.64571265887287,-1.9597714230537786
4.091404608269489,0.044884976995399076,414.46970382271775,34.64571265887287,-1.9597714230537786
4.1299153780915105,0.04530746149229846,415.33520010734355,34.64571265887287,-1.9597714230537786
4.149170763002521,0.04551870374074815,415.7667675083263,34.64571265887287,-1.9597714230537786
4.261202093393856,0.046747749549909984,418.26238407981964,34.64571265887287,-1.9597714230537786
4.304964331827972,0.04722784556911383,419.2302677577113,34.64571265887287,-1.9597714230537786
4.324219716738981,0.04743908781756351,419.65492013177675,34.64571265887287,-1.9597714230537786
4.343475101649992,0.0476503300660132,420.07883567588,34.64571265887287,-1.9597714230537786
4.35397803887418,0.047765553110622125,420.3097533959395,34.64571265887287,-1.9597714230537786
4.481763775101797,0.049167433486697346,423.10207323901477,34.64571265887287,-1.9597714230537786
4.499268670475443,0.04935947189437888,423.48215040304996,34.64571265887287,-1.9597714230537786
4.525526013535912,0.04964752950590118,424.05118661378435,34.64571265887287,-1.9597714230537786
4.544781398446923,0.04985877175435087,424.46766181894975,34.64571265887287,-1.9597714230537786
4.564036783357934,0.05007001400280056,424.8834494242866,34.64571265887287,-1.9597714230537786
4.590294126418402,0.05035807161432286,425.4493316804724,34.64571265887287,-1.9597714230537786
4.597296084567861,0.05043488697739548,425.6000202308794,34.64571265887287,-1.9597714230537786
4.6410583230019755,0.050914982996599314,426.5398038247584,34.64571265887287,-1.9597714230537786
4.67256713467454,0.05126065213042609,427.214309340758,34.64571265887287,-1.9597714230537786
4.702325456809737,0.051587117423484694,427.8497153690669,34.64571265887287,-1.9597714230537786
4.707576925421831,0.051644728945789156,427.96168285895703,34.64571265887287,-1.9597714230537786
4.765343080154864,0.05227845569113823,429.1901274179665,34.64571265887287,-1.9597714230537786
4.800352870902155,0.0526625325065013,429.93181315825444,34.64571265887287,-1.9597714230537786
4.828360703499989,0.052969793958791755,430.52364395631355,34.64571265887287,-1.9597714230537786
4.875623921008834,0.053488297659531905,431.51933139313036,34.64571265887287,-1.9597714230537786
4.915885180368219,0.053929985997199434,432.364544093655,34.64571265887287,-1.9597714230537786
4.95789692926497,0.05439087817563512,433.24363187382636,34.64571265887287,-1.9597714230537786
5.008661125848545,0.05494778955791159,434.3019963609194,34.64571265887287,-1.9597714230537786
5.020914552610097,0.05508221644328866,434.55683587695006,34.64571265887287,-1.9597714230537786
5.043670916595836,0.055331866373274655,435.0294666838106,34.64571265887287,-1.9597714230537786
5.118941966702515,0.05615763152630526,436.5868925391996,34.64571265887287,-1.9597714230537786
5.127694414389337,0.05625365073014603,436.76740707862797,34.64571265887287,-1.9597714230537786
5.174957631898182,0.05677215443088618,437.74011698431883,34.64571265887287,-1.9597714230537786
5.20821693310811,0.0571370274054811,438.42254070493954,34.64571265887287,-1.9597714230537786
5.215218891257567,0.05721384276855371,438.5659920519384,34.64571265887287,-1.9597714230537786
5.257230640154318,0.057674734946989395,439.42512805071703,34.64571265887287,-1.9597714230537786
5.269484066915871,0.05780916183236648,439.6752044755259,34.64571265887287,-1.9597714230537786
5.288739451826882,0.05802040408081617,440.0677239916426,34.64571265887287,-1.9597714230537786
5.31849777396208,0.058346869373874774,440.6732505718086,34.64571265887287,-1.9597714230537786
5.348256096097279,0.05867333466693339,441.2774572361931,34.64571265887287,-1.9597714230537786
5.36751148100829,0.05888457691538308,441.6677159437481,34.64571265887287,-1.9597714230537786
5.400770782218216,0.05924944988997799,442.3405155653605,34.64571265887287,-1.9597714230537786
5.42877861481605,0.05955671134226845,442.90583128980643,34.64571265887287,-1.9597714230537786
5.4777923218622595,0.06009441888377676,443.8924044268262,34.64571265887287,-1.9597714230537786
5.532057497520562,0.060689737947589514,444.98067472019653,34.64571265887287,-1.9597714230537786
5.563566309193126,0.06103540708141629,445.6106630734489,34.64571265887287,-1.9597714230537786
5.579320715029406,0.061208241648329664,445.9251353361747,34.64571265887287,-1.9597714230537786
5.5968256104030525,0.0614002800560112,446.274143074745,34.64571265887287,-1.9597714230537786
5.631835401150345,0.06178435687137428,446.97088403029636,34.64571265887287,-1.9597714230537786
5.644088827911896,0.06191878375675135,447.2143440313864,34.64571265887287,-1.9597714230537786
5.703605472182295,0.06257171434286858,448.39394438204835,34.64571265887287,-1.9597714230537786
5.728112325705398,0.06284056811362272,448.8782657210485,34.64571265887287,-1.9597714230537786
5.76662309552742,0.0632630526105221,449.63771258071716,34.64571265887287,-1.9597714230537786
5.798131907199982,0.06360872174434887,450.25760804316053,34.64571265887287,-1.9597714230537786
5.810385333961536,0.06374314862972595,450.4983235244773,34.64571265887287,-1.9597714230537786
5.820888271185722,0.06385837167433486,450.70449354667744,34.64571265887287,-1.9597714230537786
5.859399041007744,0.06428085617123425,451.45921223426075,34.64571265887287,-1.9597714230537786
5.8699019782319315,0.06439607921584317,451.6647085413272,34.64571265887287,-1.9597714230537786
5.88040491545612,0.0645113022604521,451.8700614985231,34.64571265887287,-1.9597714230537786
5.964428413249621,0.06543308661732347,453.5077669367571,34.64571265887287,-1.9597714230537786
6.008190651683735,0.0659131826365273,454.3571735344716,34.64571265887287,-1.9597714230537786
6.065956806416768,0.06654690938187638,455.47470480403166,34.64571265887287,-1.9597714230537786
6.08171121225305,0.06671974394878977,455.77876474724513,34.64571265887287,-1.9597714230537786
6.10446757623879,0.06696939387877576,456.217420690311,34.64571265887287,-1.9597714230537786
6.141227856523447,0.06737267453490699,456.9246739743237,34.64571265887287,-1.9597714230537786
6.156982262359729,0.06754550910182038,457.22727688473856,34.64571265887287,-1.9597714230537786
6.188491074032291,0.06789117823564714,457.83157829973754,34.64571265887287,-1.9597714230537786
6.211247438018031,0.06814082816563313,458.267272190495,34.64571265887287,-1.9597714230537786
6.241005760153229,0.06846729345869174,458.83608755541667,34.64571265887287,-1.9597714230537786
6.293520446274167,0.06904340868173635,459.83730573100854,34.64571265887287,-1.9597714230537786
6.318027299797272,0.0693122624524905,460.3034253509757,34.64571265887287,-1.9597714230537786
6.3425341533203765,0.06958111622324466,460.7688403737684,34.64571265887287,-1.9597714230537786
6.395048839441314,0.07015723144628926,461.76380319462294,34.64571265887287,-1.9597714230537786
6.426557651113878,0.07050290058011603,462.359251495513,34.64571265887287,-1.9597714230537786
6.477321847697452,0.07105981196239249,463.316195575306,34.64571265887287,-1.9597714230537786
6.514082127982108,0.07146309261852371,464.0073301285691,34.64571265887287,-1.9597714230537786
6.536838491967848,0.0717127425485097,464.4344131388393,34.64571265887287,-1.9597714230537786
6.543840450117307,0.07178955791158233,464.5657065893893,34.64571265887287,-1.9597714230537786
6.601606604850338,0.07242328465693139,465.64679491716305,34.64571265887287,-1.9597714230537786
6.636616395597631,0.07280736147229447,466.30020459300715,34.64571265887287,-1.9597714230537786
6.664624228195465,0.07311462292458493,466.8219649630164,34.64571265887287,-1.9597714230537786
6.692632060793299,0.07342188437687538,467.3428708858668,34.64571265887287,-1.9597714230537786
6.741645767839507,0.07395959191838368,468.25241514710797,34.64571265887287,-1.9597714230537786
6.778406048124164,0.0743628725745149,468.9328818789108,34.64571265887287,-1.9597714230537786
6.801162412109903,0.0746125225045009,469.35340202437175,34.64571265887287,-1.9597714230537786
6.851926608693477,0.07516943388677735,470.2895130321122,34.64571265887287,-1.9597714230537786
6.892187868052864,0.0756111222244449,471.03002401847226,34.64571265887287,-1.9597714230537786
6.904441294814416,0.07574554910982197,471.25506181966756,34.64571265887287,-1.9597714230537786
6.914944232038604,0.07586077215443089,471.44782742152637,34.64571265887287,-1.9597714230537786
6.930698637874886,0.07603360672134428,471.7367618624145,34.64571265887287,-1.9597714230537786
6.939451085561709,0.07612962592518505,471.8971703127104,34.64571265887287,-1.9597714230537786
6.962207449547448,0.07637927585517104,472.31386345031,34.64571265887287,-1.9597714230537786
7.082991227625606,0.07770434086817364,474.5167137679113,34.64571265887287,-1.9597714230537786
7.123252486984992,0.07814602920584117,475.2477352016206,34.64571265887287,-1.9597714230537786
7.130254445134451,0.07822284456891379,475.3747046979871,34.64571265887287,-1.9597714230537786
7.17576717310593,0.07872214442888578,476.19882431953016,34.64571265887287,-1.9597714230537786
7.191521578942212,0.07889497899579917,476.48362121319735,34.64571265887287,-1.9597714230537786
7.210776963853222,0.07910622124424885,476.8313760835724,34.64571265887287,-1.9597714230537786
7.240535285988421,0.07943268653730746,477.368103917769,34.64571265887287,-1.9597714230537786
7.3070538884082765,0.0801624324864973,478.5647474213087,34.64571265887287,-1.9597714230537786
7.314055846557734,0.08023924784956991,478.6904622594013,34.64571265887287,-1.9597714230537786
7.378823959440225,0.0809497899579916,479.85110793274123,34.64571265887287,-1.9597714230537786
7.385825917589683,0.08102660532106422,479.9763446980653,34.64571265887287,-1.9597714230537786
7.398079344351236,0.08116103220644129,480.1953976760349,34.64571265887287,-1.9597714230537786
7.410332771112788,0.08129545909181837,480.414309200953,34.64571265887287,-1.9597714230537786
7.436590114173257,0.08158351670334067,480.8829305139559,34.64571265887287,-1.9597714230537786
7.476851373532642,0.0820252050410082,481.60023182106187,34.64571265887287,-1.9597714230537786
7.538118507340404,0.08269733946789358,482.68889372949457,34.64571265887287,-1.9597714230537786
7.597635151610801,0.0833502700540108,483.74315151111983,34.64571265887287,-1.9597714230537786
7.667654733105385,0.08411842368473695,484.9793400603642,34.64571265887287,-1.9597714230537786
7.716668440151595,0.08465613122624525,485.84205382473095,34.64571265887287,-1.9597714230537786
7.7446762727494285,0.08496339267853571,486.3340735908423,34.64571265887287,-1.9597714230537786
7.790189000720908,0.0854626925385077,487.1321282447253,34.64571265887287,-1.9597714230537786
7.833951239155024,0.08594278855771155,487.8977754431695,34.64571265887287,-1.9597714230537786
7.860208582215492,0.08623084616923385,488.3563631330679,34.64571265887287,-1.9597714230537786
7.912723268336431,0.08680696139227846,489.27175007846284,34.64571265887287,-1.9597714230537786
7.930228163710076,0.08699899979996,489.57635214386397,34.64571265887287,-1.9597714230537786
7.944232080008994,0.08715263052610522,489.8198450379036,34.64571265887287,-1.9597714230537786
7.966988443994733,0.08740228045609122,490.2151642679913,34.64571265887287,-1.9597714230537786
8.100025648834444,0.0888617723544709,492.5175094472577,34.64571265887287,-1.9597714230537786
8.119281033745455,0.0890730146029206,492.84951780798133,34.64571265887287,-1.9597714230537786
8.143787887268559,0.08934186837367473,493.2716301204473,34.64571265887287,-1.9597714230537786
8.194552083852132,0.08989877975595119,494.14443297073734,34.64571265887287,-1.9597714230537786
8.224310405987332,0.0902252450490098,494.6550956576847,34.64571265887287,-1.9597714230537786
8.234813343211519,0.09034046809361873,494.83515743003437,34.64571265887287,-1.9597714230537786
8.240064811823613,0.0903980796159232,494.92515472738563,34.64571265887287,-1.9597714230537786
8.2505677490478,0.0905133026605321,495.1050822435829,34.64571265887287,-1.9597714230537786
8.294329987481916,0.09099339867973595,495.8538207358282,34.64571265887287,-1.9597714230537786
8.362599079439134,0.09174234846969394,497.0187836828107,34.64571265887287,-1.9597714230537786
8.37135152712596,0.09183836767353472,497.1678692075088,34.64571265887287,-1.9597714230537786
8.385355443424876,0.09199199839967995,497.40627966573186,34.64571265887287,-1.9597714230537786
8.395858380649063,0.09210722144428886,497.5849856197623,34.64571265887287,-1.9597714230537786
8.399359359723793,0.09214562912582518,497.6445348935622,34.64571265887287,-1.9597714230537786
8.507889711040397,0.09333626725345069,499.4857889938807,34.64571265887287,-1.9597714230537786
8.528895585488772,0.09356671334266854,499.84110027244265,34.64571265887287,-1.9597714230537786
8.553402439011878,0.09383556711342268,500.2551990352101,34.64571265887287,-1.9597714230537786
8.574408313460253,0.09406601320264053,500.6097726808216,34.64571265887287,-1.9597714230537786
8.600665656520722,0.09435407081416283,501.0525137013595,34.64571265887287,-1.9597714230537786
8.623422020506462,0.09460372074414883,501.4357963538668,34.64571265887287,-1.9597714230537786
8.632174468193286,0.09469973994798961,501.58310769891744,34.64571265887287,-1.9597714230537786
8.677687196164765,0.0951990398079616,502.3481897045652,34.64571265887287,-1.9597714230537786
8.752958246271444,0.09602480496099221,503.6100922190508,34.64571265887287,-1.9597714230537786
8.76696216257036,0.09617843568713744,503.8443971093805,34.64571265887287,-1.9597714230537786
8.786217547481371,0.09638967793558713,504.1663281415623,34.64571265887287,-1.9597714230537786
8.826478806840756,0.09683136627325466,504.83856888639804,34.64571265887287,-1.9597714230537786
8.836981744064945,0.09694658931786358,505.0137392278126,34.64571265887287,-1.9597714230537786
8.885995451111153,0.09748429685937188,505.83012964461386,34.64571265887287,-1.9597714230537786
8.921005241858445,0.09786837367473496,506.4121907988599,34.64571265887287,-1.9597714230537786
8.977020907054113,0.09848289657931587,507.34163908318226,34.64571265887287,-1.9597714230537786
9.041789019936603,0.09919343868773756,508.4134987319366,34.64571265887287,-1.9597714230537786
9.066295873459707,0.0994622924584917,508.81828586144866,34.64571265887287,-1.9597714230537786
9.08205027929599,0.09963512702540508,509.0782808393794,34.64571265887287,-1.9597714230537786
9.092553216520177,0.09975035007001401,509.25151311336276,34.64571265887287,-1.9597714230537786
9.108307622356458,0.09992318463692738,509.51121527100037,34.64571265887287,-1.9597714230537786