File: datasets/aisi_316_L/data/M1/train_28.csv
Time(s),Strain(%),Stress(MPa),Temp(C),Log_SR(s-1)
0.0,0.0,0.0,75.94412659436712,-1.6413566434834488
0.0012260683308695879,2.8e-05,5.439643125,75.94412659436712,-1.6413566434834488
0.0016814651394782918,3.84e-05,7.460082,75.94412659436712,-1.6413566434834488
0.0018566177581739473,4.24e-05,8.237173875,75.94412659436712,-1.6413566434834488
0.0027323808516522244,6.24e-05,12.12263325,75.94412659436712,-1.6413566434834488
0.0031527471365217974,7.2e-05,13.98765375,75.94412659436712,-1.6413566434834488
0.004378815467391385,9.999999999999999e-05,19.427296875,75.94412659436712,-1.6413566434834488
0.005009364894695744,0.00011439999999999999,22.224827624999996,75.94412659436712,-1.6413566434834488
0.005569853274521842,0.0001272,24.711521625,75.94412659436712,-1.6413566434834488
0.0072863489377392645,0.00016639999999999998,32.32702199999999,75.94412659436712,-1.6413566434834488
0.008967814077217556,0.0002048,39.787104,75.94412659436712,-1.6413566434834488
0.009107936172174081,0.000208,40.4087775,75.94412659436712,-1.6413566434834488
0.009493271933304523,0.00021679999999999998,42.118379624999996,75.94412659436712,-1.6413566434834488
0.010228912931826276,0.00023359999999999999,45.3821655,75.94412659436712,-1.6413566434834488
0.010999584454087158,0.0002512,48.80136975,75.94412659436712,-1.6413566434834488
0.011279828644000208,0.0002576,50.04471674999999,75.94412659436712,-1.6413566434834488
0.01205050016626109,0.00027519999999999997,53.46392099999999,75.94412659436712,-1.6413566434834488
0.012365774879913272,0.0002824,54.862686374999996,75.94412659436712,-1.6413566434834488
0.012821171688521975,0.00029279999999999996,56.88312524999999,75.94412659436712,-1.6413566434834488
0.013066385354695894,0.0002984,57.971053874999996,75.94412659436712,-1.6413566434834488
0.014012209495652432,0.00031999999999999997,62.16734999999999,75.94412659436712,-1.6413566434834488
0.014747850494174186,0.0003368,65.431135875,75.94412659436712,-1.6413566434834488
0.015378399921478544,0.00035119999999999997,68.22866662499999,75.94412659436712,-1.6413566434834488
0.015728705158869857,0.0003592,69.782850375,75.94412659436712,-1.6413566434834488
0.01618410196747856,0.0003696,71.80328924999999,75.94412659436712,-1.6413566434834488
0.017585322917043802,0.0004016,78.02002425,75.94412659436712,-1.6413566434834488
0.017760475535739458,0.0004056,78.797116125,75.94412659436712,-1.6413566434834488
0.018426055486782947,0.0004208,81.75006524999999,75.94412659436712,-1.6413566434834488
0.01881139124791339,0.0004296,83.459667375,75.94412659436712,-1.6413566434834488
0.02010752062626124,0.0004592,89.21014725,75.94412659436712,-1.6413566434834488
0.02049285638739168,0.000468,90.919749375,75.94412659436712,-1.6413566434834488
0.02115843633843517,0.0004832,93.8726985,75.94412659436712,-1.6413566434834488
0.022104260479391714,0.0005048,98.068994625,75.94412659436712,-1.6413566434834488
0.023050084620348254,0.0005264,102.26529075,75.94412659436712,-1.6413566434834488
0.023680634047652614,0.0005408,105.0628215,75.94412659436712,-1.6413566434834488
0.024521366617391755,0.00056,108.79286249999998,75.94412659436712,-1.6413566434834488
0.02588755704321787,0.0005912,114.85417912499999,75.94412659436712,-1.6413566434834488
0.026728289612957014,0.0006104,118.584220125,75.94412659436712,-1.6413566434834488
0.027358839040261377,0.0006248,121.381750875,75.94412659436712,-1.6413566434834488
0.027814235848870078,0.0006351999999999999,123.40218974999999,75.94412659436712,-1.6413566434834488
0.028725029466087487,0.000656,127.4430675,75.94412659436712,-1.6413566434834488
0.030511586176783168,0.0006967999999999999,135.369404625,75.94412659436712,-1.6413566434834488
0.031037044032870137,0.0007088,137.70068025,75.94412659436712,-1.6413566434834488
0.03205292922130494,0.000732,142.207813125,75.94412659436712,-1.6413566434834488
0.03285863126730495,0.0007503999999999999,145.78243575,75.94412659436712,-1.6413566434834488
0.03306881440973974,0.0007551999999999999,146.714946,75.94412659436712,-1.6413566434834488
0.033278997552174526,0.0007599999999999999,147.64745624999998,75.94412659436712,-1.6413566434834488
0.0347152490254789,0.0007928,154.019609625,75.94412659436712,-1.6413566434834488
0.034890401644174555,0.0007968,154.79670149999998,75.94412659436712,-1.6413566434834488
0.03576616473765284,0.0008168,158.682160875,75.94412659436712,-1.6413566434834488
0.03597634788008762,0.0008215999999999999,159.61467112499997,75.94412659436712,-1.6413566434834488
0.03625659207000067,0.000828,160.858018125,75.94412659436712,-1.6413566434834488
0.03709732463973982,0.0008472,164.588059125,75.94412659436712,-1.6413566434834488
0.03727247725843547,0.0008512,165.365151,75.94412659436712,-1.6413566434834488
0.03856860663678332,0.0008807999999999999,171.115630875,75.94412659436712,-1.6413566434834488
0.0388838813504355,0.000888,172.51439625,75.94412659436712,-1.6413566434834488
0.04021504125252248,0.0009184,178.4202945,75.94412659436712,-1.6413566434834488
0.04067043806113118,0.0009287999999999999,180.44073337499998,75.94412659436712,-1.6413566434834488
0.042281842153131216,0.0009655999999999999,187.589978625,75.94412659436712,-1.6413566434834488
0.043613002055218196,0.000996,193.495876875,75.94412659436712,-1.6413566434834488
0.044663917767392126,0.0010199999999999999,198.15842812499997,75.94412659436712,-1.6413566434834488
0.04518937562347909,0.001032,200.48970375,75.94412659436712,-1.6413566434834488
0.0455396808608704,0.00104,202.04388749999998,75.94412659436712,-1.6413566434834488
0.04673071866800086,0.0010672,207.32811224999998,75.94412659436712,-1.6413566434834488
0.04694090181043565,0.001072,208.2606225,75.94412659436712,-1.6413566434834488
0.0476765428089574,0.0010888,211.524408375,75.94412659436712,-1.6413566434834488
0.048096909093826974,0.0010984,213.389428875,75.94412659436712,-1.6413566434834488
0.04862236694991394,0.0011103999999999999,215.72070449999998,75.94412659436712,-1.6413566434834488
0.04883255009234873,0.0011152,216.65321475,75.94412659436712,-1.6413566434834488
0.04956819109087048,0.001132,219.917000625,75.94412659436712,-1.6413566434834488
0.050128679470696574,0.0011447999999999999,222.40369462499999,75.94412659436712,-1.6413566434834488
0.05040892366060963,0.0011512,223.647041625,75.94412659436712,-1.6413566434834488
0.05107450361165312,0.0011664,226.59999075,75.94412659436712,-1.6413566434834488
0.05152990042026182,0.0011768,228.62042962499999,75.94412659436712,-1.6413566434834488
0.05212541932382705,0.0011903999999999999,231.26254199999997,75.94412659436712,-1.6413566434834488
0.053947006558261866,0.001232,239.3442975,75.94412659436712,-1.6413566434834488
0.054227250748174916,0.0012384,240.58764449999998,75.94412659436712,-1.6413566434834488
0.05534822750782711,0.001264,245.56103249999998,75.94412659436712,-1.6413566434834488
0.05629405164878365,0.0012856,249.757328625,75.94412659436712,-1.6413566434834488
0.056889570552348875,0.0012992,252.399441,75.94412659436712,-1.6413566434834488
0.05769527259834889,0.0013176,253.31875664186379,75.94412659436712,-1.6413566434834488
0.05818569993069673,0.0013288,253.4006605999478,75.94412659436712,-1.6413566434834488
0.05836085254939238,0.0013327999999999999,253.4298467087692,75.94412659436712,-1.6413566434834488
0.05857103569182717,0.0013376,253.46482498509678,75.94412659436712,-1.6413566434834488
0.05902643250043588,0.001348,253.5404437560577,75.94412659436712,-1.6413566434834488
0.05958692088026197,0.0013608,253.63320138604826,75.94412659436712,-1.6413566434834488
0.060392622926261984,0.0013792,253.76594654068597,75.94412659436712,-1.6413566434834488
0.061093233401044604,0.0013951999999999999,253.88081668134308,75.94412659436712,-1.6413566434834488
0.062179179636957675,0.00142,254.0578552630554,75.94412659436712,-1.6413566434834488
0.06256451539808812,0.0014288,254.1203850122359,75.94412659436712,-1.6413566434834488
0.06421095001382726,0.0014663999999999999,254.3858832395934,75.94412659436712,-1.6413566434834488
0.06463131629869684,0.0014759999999999999,254.4532428843068,75.94412659436712,-1.6413566434834488
0.06634781196191426,0.0015152,254.72653989712418,75.94412659436712,-1.6413566434834488
0.06659302562808818,0.0015207999999999999,254.76535603090747,75.94412659436712,-1.6413566434834488
0.06757388029278386,0.0015432,254.92006635770315,75.94412659436712,-1.6413566434834488
0.06788915500643604,0.0015504,254.96960835276312,75.94412659436712,-1.6413566434834488
0.06813436867260995,0.0015559999999999999,255.00807900788413,75.94412659436712,-1.6413566434834488
0.06883497914739257,0.0015719999999999998,255.11769875193974,75.94412659436712,-1.6413566434834488
0.06950055909843607,0.0015872,255.2214351642381,75.94412659436712,-1.6413566434834488
0.06957062014591434,0.0015888,255.23233220071793,75.94412659436712,-1.6413566434834488
0.06967571171713172,0.0015911999999999999,255.24866973425162,75.94412659436712,-1.6413566434834488
0.07002601695452303,0.0015991999999999998,255.30305890472704,75.94412659436712,-1.6413566434834488
0.07104190214295783,0.0016224,255.46019063546547,75.94412659436712,-1.6413566434834488
0.07139220738034914,0.0016304,255.51417048357214,75.94412659436712,-1.6413566434834488
0.07216287890261003,0.001648,255.6325638709478,75.94412659436712,-1.6413566434834488
0.07289851990113178,0.0016648,255.74511658212083,75.94412659436712,-1.6413566434834488
0.0735991303759144,0.0016807999999999999,255.85189852507196,75.94412659436712,-1.6413566434834488
0.07412458823200137,0.0016928,255.93172501770434,75.94412659436712,-1.6413566434834488
0.07454495451687095,0.0017024,255.99542742730367,75.94412659436712,-1.6413566434834488
0.0747201071355666,0.0017063999999999998,256.02192873208776,75.94412659436712,-1.6413566434834488
0.0750704123729579,0.0017143999999999998,256.0748587705715,75.94412659436712,-1.6413566434834488
0.07549077865782748,0.0017239999999999998,256.13824783593225,75.94412659436712,-1.6413566434834488
0.07587611441895792,0.0017327999999999998,256.1962336518357,75.94412659436712,-1.6413566434834488
0.0766467859412188,0.0017503999999999998,256.31186188613344,75.94412659436712,-1.6413566434834488
0.07790788479582753,0.0017791999999999999,256.5000984400817,75.94412659436712,-1.6413566434834488
0.07874861736556667,0.0017984,256.6249297042542,75.94412659436712,-1.6413566434834488
0.07958934993530582,0.0018176,256.7492422771707,75.94412659436712,-1.6413566434834488
0.08043008250504496,0.0018368,256.8730437594432,75.94412659436712,-1.6413566434834488
0.08155105926469716,0.0018624,257.03733015543844,75.94412659436712,-1.6413566434834488
0.08221663921574064,0.0018775999999999999,257.13445852889186,75.94412659436712,-1.6413566434834488
0.08316246335669719,0.0018992,257.2719571947444,75.94412659436712,-1.6413566434834488
0.08470380640121895,0.0019344,257.49472946250313,75.94412659436712,-1.6413566434834488
0.08575472211339288,0.0019584,257.6457139475874,75.94412659436712,-1.6413566434834488
0.08666551573061029,0.0019792,257.77598439719065,75.94412659436712,-1.6413566434834488
0.08680563782556683,0.0019824,257.7959785158726,75.94412659436712,-1.6413566434834488
0.08687569887304508,0.001984,257.8059708547717,75.94412659436712,-1.6413566434834488
0.0870158209680016,0.0019871999999999997,257.8259461093148,75.94412659436712,-1.6413566434834488
0.0881367977276538,0.0020128,257.9852990127002,75.94412659436712,-1.6413566434834488
0.08890746924991469,0.0020304,258.09439590472175,75.94412659436712,-1.6413566434834488
0.08897753029739294,0.002032,258.10429547964554,75.94412659436712,-1.6413566434834488
0.0898182628671321,0.0020512,258.22285423912194,75.94412659436712,-1.6413566434834488
0.0908341480555669,0.0020744,258.36553685217524,75.94412659436712,-1.6413566434834488
0.09132457538791473,0.0020856,258.4341952576097,75.94412659436712,-1.6413566434834488
0.0914997280066104,0.0020896,258.45868124893934,75.94412659436712,-1.6413566434834488
0.09192009429147996,0.0020992,258.5173731653267,75.94412659436712,-1.6413566434834488
0.09283088790869737,0.00212,258.64418107671275,75.94412659436712,-1.6413566434834488
0.09391683414461044,0.0021448,258.7947427148481,75.94412659436712,-1.6413566434834488
0.09496774985678436,0.0021688,258.9398023936922,75.94412659436712,-1.6413566434834488
0.09531805509417568,0.0021768,258.98801632256783,75.94412659436712,-1.6413566434834488
0.09650909290130612,0.002204,259.15142924058733,75.94412659436712,-1.6413566434834488
0.09741988651852354,0.0022248,259.27586191587704,75.94412659436712,-1.6413566434834488
0.09819055804078441,0.0022424,259.38079713577446,75.94412659436712,-1.6413566434834488
0.09878607694434964,0.0022559999999999998,259.4616635943512,75.94412659436712,-1.6413566434834488
0.09892619903930618,0.0022592,259.48066333950993,75.94412659436712,-1.6413566434834488
0.10001214527521925,0.002284,259.62755716160206,75.94412659436712,-1.6413566434834488
0.10106306098739316,0.0023079999999999997,259.76912134409986,75.94412659436712,-1.6413566434834488
0.10267446507939319,0.0023447999999999997,259.98507644566814,75.94412659436712,-1.6413566434834488
0.10362028922034973,0.0023664,260.11121710003124,75.94412659436712,-1.6413566434834488
0.10372538079156714,0.0023688,260.12520495462235,75.94412659436712,-1.6413566434834488
0.10446102179008888,0.0023856,260.22296564203094,75.94412659436712,-1.6413566434834488
0.10540684593104542,0.0024072,260.34826432996255,75.94412659436712,-1.6413566434834488
0.10624757850078458,0.0024264,260.4592733008338,75.94412659436712,-1.6413566434834488
0.10656285321443675,0.0024335999999999997,260.50081327692845,75.94412659436712,-1.6413566434834488
0.10701825002304545,0.002444,260.56073094619614,75.94412659436712,-1.6413566434834488
0.10750867735539328,0.0024552,260.62514656995234,75.94412659436712,-1.6413566434834488
0.1083143794013933,0.0024736,260.7307240053443,75.94412659436712,-1.6413566434834488
0.10880480673374113,0.0024847999999999997,260.79483858799966,75.94412659436712,-1.6413566434834488
0.10940032563730637,0.0024984,260.87254068890655,75.94412659436712,-1.6413566434834488
0.10961050877974114,0.0025031999999999997,260.899925552706,75.94412659436712,-1.6413566434834488
0.10985572244591507,0.0025088,260.9318486900518,75.94412659436712,-1.6413566434834488
0.11143209601417596,0.0025448,261.1364092763777,75.94412659436712,-1.6413566434834488
0.11192252334652379,0.0025559999999999997,261.1998197623194,75.94412659436712,-1.6413566434834488
0.11234288963139338,0.0025656,261.25408540733116,75.94412659436712,-1.6413566434834488
0.113043500106176,0.0025816,261.34435250096976,75.94412659436712,-1.6413566434834488
0.11346386639104557,0.0025911999999999997,261.39840803408634,75.94412659436712,-1.6413566434834488
0.11419950738956733,0.002608,261.49281765456766,75.94412659436712,-1.6413566434834488
0.11465490419817603,0.0026184,261.55114285874413,75.94412659436712,-1.6413566434834488
0.11511030100678472,0.0026287999999999997,261.6093777846441,75.94412659436712,-1.6413566434834488
0.11595103357652387,0.0026479999999999997,261.71665290382015,75.94412659436712,-1.6413566434834488
0.11668667457504563,0.0026647999999999997,261.8102700346126,75.94412659436712,-1.6413566434834488
0.11724716295487174,0.0026776,261.88144295773276,75.94412659436712,-1.6413566434834488
0.11854329233321957,0.0027072,262.04552406050254,75.94412659436712,-1.6413566434834488
0.1187885059993935,0.0027128,262.07648756806304,75.94412659436712,-1.6413566434834488
0.12032984904391526,0.002748,262.27054762431715,75.94412659436712,-1.6413566434834488
0.12106549004243702,0.0027648,262.36282522172854,75.94412659436712,-1.6413566434834488
0.12141579527982832,0.0027727999999999997,262.4066900523433,75.94412659436712,-1.6413566434834488
0.12218646680208921,0.0027903999999999997,262.50301931647266,75.94412659436712,-1.6413566434834488
0.12299216884808922,0.0028087999999999998,262.60347416868956,75.94412659436712,-1.6413566434834488
0.12390296246530663,0.0028296,262.71672330003963,75.94412659436712,-1.6413566434834488
0.12456854241635011,0.0028447999999999998,262.7992770669786,75.94412659436712,-1.6413566434834488
0.12495387817748058,0.0028536,262.8469927260889,75.94412659436712,-1.6413566434834488
0.12614491598461103,0.0028807999999999998,262.99411596522685,75.94412659436712,-1.6413566434834488
0.12642516017452407,0.0028872,263.02865434645526,75.94412659436712,-1.6413566434834488
0.12663534331695886,0.002892,263.0545385410832,75.94412659436712,-1.6413566434834488
0.12674043488817624,0.0028943999999999997,263.06747435492,75.94412659436712,-1.6413566434834488
0.12810662531400238,0.0029256,263.2352610664721,75.94412659436712,-1.6413566434834488
0.12912251050243714,0.0029487999999999997,263.3595735178816,75.94412659436712,-1.6413566434834488
0.13020845673835021,0.0029736,263.49203818621424,75.94412659436712,-1.6413566434834488
0.1316447082116546,0.0030064,263.6665735225268,75.94412659436712,-1.6413566434834488
0.13325611230365464,0.0030432,263.8615120485693,75.94412659436712,-1.6413566434834488
0.13346629544608943,0.003048,263.88687086332874,75.94412659436712,-1.6413566434834488
0.1343420585395677,0.003068,263.99236538421263,75.94412659436712,-1.6413566434834488
0.13553309634669813,0.0030951999999999998,264.1354085229801,75.94412659436712,-1.6413566434834488
0.13640885944017642,0.0031152,264.24027473333877,75.94412659436712,-1.6413566434834488
0.13654898153513295,0.0031184,264.2570289300564,75.94412659436712,-1.6413566434834488
0.13710946991495904,0.0031311999999999998,264.32397877454275,75.94412659436712,-1.6413566434834488
0.13798523300843732,0.0031512,264.42837462104114,75.94412659436712,-1.6413566434834488
0.13879093505443735,0.0031696,264.5241908029857,75.94412659436712,-1.6413566434834488
0.138966087673133,0.0031736,264.5449916746137,75.94412659436712,-1.6413566434834488
0.13935142343426343,0.0031823999999999997,264.59071763497917,75.94412659436712,-1.6413566434834488
0.13956160657669822,0.0031872,264.6156382824631,75.94412659436712,-1.6413566434834488
0.14085773595504608,0.0032167999999999997,264.7689934228946,75.94412659436712,-1.6413566434834488
0.14103288857374172,0.0032208,264.7896748001014,75.94412659436712,-1.6413566434834488
0.1413481632873939,0.003228,264.82687605378777,75.94412659436712,-1.6413566434834488
0.1420137432384374,0.0032432,264.90530592979644,75.94412659436712,-1.6413566434834488
0.14323981156930699,0.0032711999999999997,265.04940777319456,75.94412659436712,-1.6413566434834488
0.14383533047287222,0.0032848,265.1192264627943,75.94412659436712,-1.6413566434834488
0.14422066623400265,0.0032936,265.164343195281,75.94412659436712,-1.6413566434834488
0.14453594094765485,0.0033008,265.2012219277707,75.94412659436712,-1.6413566434834488
0.1452715819461766,0.0033176,265.28715051368476,75.94412659436712,-1.6413566434834488
0.14590213137348096,0.003332,265.36066860569696,75.94412659436712,-1.6413566434834488
0.1460422534684375,0.0033352,265.37698911974684,75.94412659436712,-1.6413566434834488
0.14681292499069837,0.0033528,265.4666430227955,75.94412659436712,-1.6413566434834488
0.14807402384530707,0.0033816,265.61295451372774,75.94412659436712,-1.6413566434834488
0.14835426803522014,0.003388,265.64540208840873,75.94412659436712,-1.6413566434834488
0.14873960379635057,0.0033967999999999997,265.689978498824,75.94412659436712,-1.6413566434834488
0.14947524479487231,0.0034135999999999997,265.7749540525553,75.94412659436712,-1.6413566434834488
0.14996567212722017,0.0034248,265.8315138281206,75.94412659436712,-1.6413566434834488
0.15063125207826364,0.00344,265.90815827746474,75.94412659436712,-1.6413566434834488
0.15129683202930713,0.0034552,265.98467076204,75.94412659436712,-1.6413566434834488
0.15248786983643758,0.0034823999999999996,266.1212610127015,75.94412659436712,-1.6413566434834488
0.15280314455008978,0.0034896,266.1573475295845,75.94412659436712,-1.6413566434834488
0.15388909078600285,0.0035144,266.28142387236585,75.94412659436712,-1.6413566434834488
0.15434448759461153,0.0035248,266.33335420935515,75.94412659436712,-1.6413566434834488
0.15455467073704635,0.0035296,266.35730189940364,75.94412659436712,-1.6413566434834488
0.15469479283200285,0.0035328,266.37325997028034,75.94412659436712,-1.6413566434834488
0.15483491492695936,0.0035359999999999996,266.38921240478976,75.94412659436712,-1.6413566434834488
0.1560960137815681,0.0035648,266.53253184347204,75.94412659436712,-1.6413566434834488
0.15662147163765505,0.0035767999999999998,266.59211491782503,75.94412659436712,-1.6413566434834488
0.15739214315991595,0.0035943999999999998,266.67936259899597,75.94412659436712,-1.6413566434834488
0.157672387349829,0.0036008,266.7110476995981,75.94412659436712,-1.6413566434834488
0.15847808939582902,0.0036192,266.80202025110447,75.94412659436712,-1.6413566434834488
0.15998440191661165,0.0036536,266.97161698476083,75.94412659436712,-1.6413566434834488
0.160614951343916,0.003668,267.042425927388,75.94412659436712,-1.6413566434834488
0.16268175224452472,0.0037151999999999997,267.27376553795915,75.94412659436712,-1.6413566434834488
0.16303205748191604,0.0037232,267.31286176255037,75.94412659436712,-1.6413566434834488
0.1644683089552204,0.003756,267.47281494889677,75.94412659436712,-1.6413566434834488
0.16464346157391607,0.00376,267.49228409778345,75.94412659436712,-1.6413566434834488
0.1652389804774813,0.0037736,267.558418867185,75.94412659436712,-1.6413566434834488
0.16569437728609002,0.003784,267.6089298124986,75.94412659436712,-1.6413566434834488
0.16632492671339438,0.0037984,267.6787787539307,75.94412659436712,-1.6413566434834488
0.16748093399678568,0.0038247999999999997,267.80656751210205,75.94412659436712,-1.6413566434834488
0.1676911171392205,0.0038296,267.82976482644705,75.94412659436712,-1.6413566434834488
0.1687070023276553,0.0038528,267.9417257185567,75.94412659436712,-1.6413566434834488
0.1694776738499162,0.0038704,268.026486262783,75.94412659436712,-1.6413566434834488
0.17045852851461182,0.0038927999999999996,268.13414623107224,75.94412659436712,-1.6413566434834488
0.17080883375200315,0.0039008,268.1725376328133,75.94412659436712,-1.6413566434834488
0.17115913898939444,0.0039088,268.21089833998303,75.94412659436712,-1.6413566434834488
0.1714043526555684,0.0039144,268.2377326184913,75.94412659436712,-1.6413566434834488
0.17213999365409013,0.0039312,268.3181457662971,75.94412659436712,-1.6413566434834488
0.1730858177950467,0.0039528,268.4213374432878,75.94412659436712,-1.6413566434834488
0.1743819471733945,0.0039824,268.5623917951289,75.94412659436712,-1.6413566434834488
0.18103892394487928,0.0041344268853770755,269.2805089790122,75.94412659436712,-1.6413566434834488
0.19449333594310528,0.004441688337667534,270.70119117292825,75.94412659436712,-1.6413566434834488
0.19785693894266176,0.004518503700740148,271.05030658559275,75.94412659436712,-1.6413566434834488
0.2171976561901116,0.004960192038407682,273.014530787637,75.94412659436712,-1.6413566434834488
0.24158377793689623,0.0055171034206841375,275.3964207277785,75.94412659436712,-1.6413566434834488
0.25083368618567653,0.005728345669133827,276.2751103159101,75.94412659436712,-1.6413566434834488
0.2802652124317959,0.006400480096019204,278.9903568217434,75.94412659436712,-1.6413566434834488
0.3130603416774717,0.007149429885977195,281.8879627381288,75.94412659436712,-1.6413566434834488
0.32651475367569766,0.007456691338267653,283.0421562788286,75.94412659436712,-1.6413566434834488
0.3509008754224823,0.008013602720544109,285.08791461908737,75.94412659436712,-1.6413566434834488
0.39462771441671674,0.009012202440488098,288.62232039570233,75.94412659436712,-1.6413566434834488
0.4013549204158297,0.009165833166633327,289.152202656194,75.94412659436712,-1.6413566434834488
0.41312753091427745,0.009434686937387478,290.0712361740481,75.94412659436712,-1.6413566434834488
0.43078644666194904,0.009837967593518704,291.43086129452297,75.94412659436712,-1.6413566434834488
0.45601346915862273,0.010414082816563312,293.33605881976075,75.94412659436712,-1.6413566434834488
0.4803995909054074,0.010970994198839769,295.139040430659,75.94412659436712,-1.6413566434834488
0.49805850665307894,0.011374274854970993,296.4224332308376,75.94412659436712,-1.6413566434834488
0.5182401246504179,0.01183516703340668,297.8676313452926,75.94412659436712,-1.6413566434834488
0.5224446283998635,0.011931186237247449,298.16593264938894,75.94412659436712,-1.6413566434834488
0.5535579561457611,0.012641728345669134,300.34497836252325,75.94412659436712,-1.6413566434834488
0.5880348868912152,0.013429085817163433,302.7045288079545,75.94412659436712,-1.6413566434834488
0.5947620928903282,0.013582716543308662,303.15857001294154,75.94412659436712,-1.6413566434834488
0.6014892988894411,0.013736347269453891,303.6106127147836,75.94412659436712,-1.6413566434834488
0.6292390236357823,0.014370074014802961,305.45481955167526,75.94412659436712,-1.6413566434834488
0.6326026266353387,0.014446889377875576,305.67618374208956,75.94412659436712,-1.6413566434834488
0.6452161378836756,0.01473494698939788,306.502242733251,75.94412659436712,-1.6413566434834488
0.647738840133343,0.014792558511702341,306.66669613791424,75.94412659436712,-1.6413566434834488
0.6569887483821234,0.015003800760152031,307.2675666751222,75.94412659436712,-1.6413566434834488
0.6914656791275775,0.01579115823164633,309.4786869080033,75.94412659436712,-1.6413566434834488
0.7276244113728098,0.016616923384676935,311.75194654840067,75.94412659436712,-1.6413566434834488
0.7360334188717009,0.01680896179235847,312.27424514460336,75.94412659436712,-1.6413566434834488
0.7520105331195942,0.01717383476695339,313.26024527101805,75.94412659436712,-1.6413566434834488
0.7663058458677094,0.017500300060012002,314.13555167074423,75.94412659436712,-1.6413566434834488
0.7999418758632744,0.018268453690738148,316.1703506293568,75.94412659436712,-1.6413566434834488
0.824327997610059,0.018825365073014605,317.6247682968023,75.94412659436712,-1.6413566434834488
0.8411460126078416,0.019209441888377678,318.6180518022327,75.94412659436712,-1.6413566434834488
0.8546004246060676,0.019516703340668136,319.4071130022695,75.94412659436712,-1.6413566434834488
0.8714184396038499,0.019900780156031205,320.3866592680656,75.94412659436712,-1.6413566434834488
0.8924409583510781,0.020380876175235048,321.6007849035372,75.94412659436712,-1.6413566434834488
0.9109407748486388,0.020803360672134428,322.6600181712622,75.94412659436712,-1.6413566434834488
0.9185088815976408,0.02097619523904781,323.09091886411125,75.94412659436712,-1.6413566434834488
0.939531400344869,0.02145629125825165,324.2806601297698,75.94412659436712,-1.6413566434834488
0.952985812343095,0.02176355271054211,325.03664903336073,75.94412659436712,-1.6413566434834488
0.9723265295905448,0.02220524104820964,326.11613082651195,75.94412659436712,-1.6413566434834488
0.9933490483377729,0.022685337067413484,327.2800260088828,75.94412659436712,-1.6413566434834488
1.0110079640854446,0.02308861772354471,328.2502925411855,75.94412659436712,-1.6413566434834488
1.0227805745838923,0.02335747149429886,328.8934674330464,75.94412659436712,-1.6413566434834488
1.027825979083227,0.023472694538907782,329.1682292419481,75.94412659436712,-1.6413566434834488
1.0715528180774614,0.02447129425885177,331.52785944414165,75.94412659436712,-1.6413566434834488
1.1060297488229154,0.02525865173034607,333.36195762250856,75.94412659436712,-1.6413566434834488
1.1110751533222503,0.02537387477495499,333.6284800812543,75.94412659436712,-1.6413566434834488
1.135461275069035,0.025930786157231447,334.9100767271519,75.94412659436712,-1.6413566434834488
1.1413475803182587,0.02606521304260852,335.21781387986306,75.94412659436712,-1.6413566434834488
1.1556428930663738,0.026391678335667135,335.9626099003497,75.94412659436712,-1.6413566434834488
1.1665746028149324,0.02664132826565313,336.52973789515875,75.94412659436712,-1.6413566434834488
1.1926425260614952,0.027236647329465895,337.8738205934205,75.94412659436712,-1.6413566434834488
1.2195513500579473,0.02785117023404681,339.24929682869765,75.94412659436712,-1.6413566434834488
1.2355284643058406,0.02821604320864173,340.0603861147309,75.94412659436712,-1.6413566434834488
1.2422556703049534,0.028369673934786958,340.40067245477525,75.94412659436712,-1.6413566434834488
1.252346479303623,0.0286001200240048,340.90975754292026,75.94412659436712,-1.6413566434834488
1.259914586052625,0.028772954590918182,341.29052217203315,75.94412659436712,-1.6413566434834488
1.2716871965510728,0.029041808361672333,341.88105449385534,75.94412659436712,-1.6413566434834488
1.2952324175479684,0.029579515903180635,343.0557614489223,75.94412659436712,-1.6413566434834488
1.319618539294753,0.030136427285457092,344.2636756752888,75.94412659436712,-1.6413566434834488
1.3288684475435333,0.03034766953390678,344.7195687518637,75.94412659436712,-1.6413566434834488
1.3372774550424245,0.030539707941588317,345.13294417891336,75.94412659436712,-1.6413566434834488
1.3440046610415375,0.030693338667733546,345.46291508284816,75.94412659436712,-1.6413566434834488
1.354936370790096,0.030942988597719545,345.99774730401106,75.94412659436712,-1.6413566434834488
1.3616635767892091,0.031096619323864774,346.32603847367056,75.94412659436712,-1.6413566434834488
1.3793224925368808,0.031499899979996,347.1848072631566,75.94412659436712,-1.6413566434834488
1.3944587060348848,0.03184556911382276,347.91748755122825,75.94412659436712,-1.6413566434834488
1.4154812247821131,0.03232566513302661,348.92997431166623,75.94412659436712,-1.6413566434834488
1.4213675300313366,0.03246009201840368,349.21241748993424,75.94412659436712,-1.6413566434834488
1.4390264457790085,0.03286337267453491,350.05702258875743,75.94412659436712,-1.6413566434834488
1.4457536517781215,0.03301700340068014,350.377712453325,75.94412659436712,-1.6413566434834488
1.4684579720251276,0.03353550710142028,351.4557699260592,75.94412659436712,-1.6413566434834488
1.4877986892725776,0.033977195439087816,352.36899762220395,75.94412659436712,-1.6413566434834488
1.5062985057701381,0.03439967993598719,353.2381971305996,75.94412659436712,-1.6413566434834488
1.5205938185182535,0.03472614522904581,353.90700283624835,75.94412659436712,-1.6413566434834488
1.529843726767034,0.0349373874774955,354.3384531650016,75.94412659436712,-1.6413566434834488
1.5357300320162577,0.03507181436287257,354.61248283418405,75.94412659436712,-1.6413566434834488
1.555070749263708,0.035513502700540114,355.50999567181066,75.94412659436712,-1.6413566434834488
1.5710478635116008,0.03587837567513502,356.24814034754166,75.94412659436712,-1.6413566434834488
1.587024977759494,0.03624324864972994,356.9833631391492,75.94412659436712,-1.6413566434834488
1.5929112830087184,0.036377675535107026,357.25350630467193,75.94412659436712,-1.6413566434834488
1.6038429927572768,0.03662732546509302,357.75417010754205,75.94412659436712,-1.6413566434834488
1.6282291145040615,0.037184236847369476,358.86626441467496,75.94412659436712,-1.6413566434834488
1.6425244272521768,0.03751070214042809,359.51516178322623,75.94412659436712,-1.6413566434834488
1.6450471295018436,0.03756831366273254,359.62944407374164,75.94412659436712,-1.6413566434834488
1.659342442249959,0.03789477895579116,360.27575732904114,75.94412659436712,-1.6413566434834488
1.6669105489989613,0.038067613522704546,360.6170438577323,75.94412659436712,-1.6413566434834488
1.6980238767448588,0.03877815563112623,362.01380837779914,75.94412659436712,-1.6413566434834488
1.7140009909927523,0.03914302860572115,362.72718471574353,75.94412659436712,-1.6413566434834488
1.7358644104898693,0.03964232846569314,363.69919548572386,75.94412659436712,-1.6413566434834488
1.7451143187386498,0.03985357071414283,364.1089921510882,75.94412659436712,-1.6413566434834488
1.7695004404854342,0.04041048209641929,365.1853249256918,75.94412659436712,-1.6413566434834488
1.7804321502339928,0.04066013202640528,365.6659394319908,75.94412659436712,-1.6413566434834488
1.7880002569829951,0.04083296659331867,365.99799859029815,75.94412659436712,-1.6413566434834488
1.8022955697311098,0.04115943188637727,366.6237296950667,75.94412659436712,-1.6413566434834488
1.8115454779798903,0.041370674134826965,367.0275833392205,75.94412659436712,-1.6413566434834488
1.8384543019763422,0.04198519703940788,368.1978825065959,75.94412659436712,-1.6413566434834488
1.8493860117249008,0.04223484696939388,368.6714060394398,75.94412659436712,-1.6413566434834488
1.9124535679665853,0.0436751350270054,371.38225411658124,75.94412659436712,-1.6413566434834488
1.9326351859639241,0.04413602720544109,372.24233210048163,75.94412659436712,-1.6413566434834488
1.9486123002118176,0.04450090018003601,372.9207455304985,75.94412659436712,-1.6413566434834488
1.9645894144597111,0.04486577315463093,373.59699303476646,75.94412659436712,-1.6413566434834488
1.9822483302073826,0.045269053810762155,374.34193399739763,75.94412659436712,-1.6413566434834488
2.001589047454832,0.045710742148429684,375.1548583391979,75.94412659436712,-1.6413566434834488
2.0327023752007296,0.04642128425685137,376.4562074385812,75.94412659436712,-1.6413566434834488
2.0352250774503973,0.04647889577915583,376.5613805480502,75.94412659436712,-1.6413566434834488
2.0545657946978473,0.04692058411682337,377.3660254721854,75.94412659436712,-1.6413566434834488
2.0713838096956296,0.04730466093218644,378.06331848140076,75.94412659436712,-1.6413566434834488
2.0781110156947427,0.04745829165833167,378.34161703132105,75.94412659436712,-1.6413566434834488
2.0814746186942994,0.04753510702140429,378.48063453376216,75.94412659436712,-1.6413566434834488
2.0856791224437448,0.047631126225245055,378.6542832680523,75.94412659436712,-1.6413566434834488
2.1285650606880897,0.04861052210442088,380.4177714366789,75.94412659436712,-1.6413566434834488
2.148746678685429,0.049071414282856565,381.2428483872574,75.94412659436712,-1.6413566434834488
2.168928296682768,0.04953230646129225,382.0649085673069,75.94412659436712,-1.6413566434834488
2.1823827086809935,0.04983956791358271,382.6112919731745,75.94412659436712,-1.6413566434834488
2.208450631927557,0.05043488697739548,383.6661858151167,75.94412659436712,-1.6413566434834488
2.2143369371767805,0.05056931386277255,383.90371426262135,75.94412659436712,-1.6413566434834488
2.2303140514246738,0.05093418683736747,384.5471962744391,75.94412659436712,-1.6413566434834488
2.2429275626730107,0.05122224444888977,385.05393937457984,75.94412659436712,-1.6413566434834488
2.2471320664224566,0.05131826365273055,385.22260660292875,75.94412659436712,-1.6413566434834488
2.2488138679222347,0.05135667133426686,385.290039026982,75.94412659436712,-1.6413566434834488
2.252177470921791,0.051433486697339464,385.42484490087,75.94412659436712,-1.6413566434834488
2.2597455776707935,0.05160632126425285,385.7278713627236,75.94412659436712,-1.6413566434834488
2.2647909821701284,0.05172154430886178,385.9296691460891,75.94412659436712,-1.6413566434834488
2.2950634091661364,0.0524128825765153,387.1367944175822,75.94412659436712,-1.6413566434834488
2.3101996226641406,0.052758551710342064,387.7380272507751,75.94412659436712,-1.6413566434834488
2.312722324913808,0.052816163232646526,387.8380831730813,75.94412659436712,-1.6413566434834488
2.3169268286632536,0.05291218243648729,388.00474850722003,75.94412659436712,-1.6413566434834488
2.361494568407377,0.053929985997199434,389.76420965420994,75.94412659436712,-1.6413566434834488
2.3707444766561574,0.054141228245649126,390.1277526853869,75.94412659436712,-1.6413566434834488
2.385880690154162,0.0544868973794759,390.72145031088996,75.94412659436712,-1.6413566434834488
2.392607896153275,0.05464052810562113,390.9848442280228,75.94412659436712,-1.6413566434834488
2.431289330648174,0.05552390478095619,392.4937916540637,75.94412659436712,-1.6413566434834488
2.4388574373971768,0.055696739347869575,392.7879222459581,75.94412659436712,-1.6413566434834488
2.459039055394516,0.05615763152630526,393.57053542084327,75.94412659436712,-1.6413566434834488
2.4741752688925196,0.056503300660132025,394.1558524677205,75.94412659436712,-1.6413566434834488
2.4876296808907457,0.05681056211242248,394.67496293356015,75.94412659436712,-1.6413566434834488
2.4977204898894154,0.057041008201640334,395.06357751147493,75.94412659436712,-1.6413566434834488
2.5195839093865326,0.057540308061612325,395.9034814337455,75.94412659436712,-1.6413566434834488
2.5313565198849806,0.05780916183236648,396.3545598684334,75.94412659436712,-1.6413566434834488
2.542288229633539,0.058058811762352475,396.77268637980364,75.94412659436712,-1.6413566434834488
2.5591062446313213,0.05844288857771554,397.4145913527056,75.94412659436712,-1.6413566434834488
2.5734015573794364,0.05876935387077416,397.95891808911114,75.94412659436712,-1.6413566434834488
2.5767651603789927,0.058846169233846765,398.0868234353698,75.94412659436712,-1.6413566434834488
2.5952649768765537,0.05926865373074615,398.78914235276125,75.94412659436712,-1.6413566434834488
2.6003103813758885,0.059383876775355074,398.9803446722858,75.94412659436712,-1.6413566434834488
2.6221738008730058,0.059883176635327065,399.8072217364351,75.94412659436712,-1.6413566434834488
2.6255374038725625,0.059959991998399687,399.93419454558193,75.94412659436712,-1.6413566434834488
2.6549689301186814,0.06063212642528505,401.0425135592936,75.94412659436712,-1.6413566434834488
2.6726278458663533,0.06103540708141629,401.70520519991925,75.94412659436712,-1.6413566434834488
2.6860822578645793,0.06134266853370675,402.20896756514105,75.94412659436712,-1.6413566434834488
2.708786578111585,0.061861172234446885,403.05684075699804,75.94412659436712,-1.6413566434834488
2.7197182878601445,0.062110822164432894,403.4640871187803,75.94412659436712,-1.6413566434834488
2.732331799108481,0.06239887977595519,403.9331943468204,75.94412659436712,-1.6413566434834488
2.759240623104933,0.06301340268053611,404.9311429932051,75.94412659436712,-1.6413566434834488
2.7768995388526045,0.06341668333666733,405.5839847517432,75.94412659436712,-1.6413566434834488
2.7836267448517176,0.06357031406281256,405.83226023517847,75.94412659436712,-1.6413566434834488
2.792876653100498,0.06378155631126226,406.17325728082795,75.94412659436712,-1.6413566434834488
2.801285660599389,0.06397359471894379,406.4828725753269,75.94412659436712,-1.6413566434834488
2.8298762860956193,0.06462652530506101,407.5328638587007,75.94412659436712,-1.6413566434834488
2.8727622243399646,0.06560592118423685,409.10012659818506,75.94412659436712,-1.6413566434834488
2.8786485295891886,0.06574034806961393,409.31452673733946,75.94412659436712,-1.6413566434834488
2.897148346086749,0.0661628325665133,409.98724532838645,75.94412659436712,-1.6413566434834488
2.902193750586084,0.06627805561112222,410.1704230142391,75.94412659436712,-1.6413566434834488
2.908920956585197,0.06643168633726745,410.41446685245273,75.94412659436712,-1.6413566434834488
2.9316252768322033,0.0669501900380076,411.23649463768254,75.94412659436712,-1.6413566434834488
2.9467614903302075,0.06729585917183437,411.783134220174,75.94412659436712,-1.6413566434834488
2.9518068948295424,0.06741108221644329,411.9651039246375,75.94412659436712,-1.6413566434834488
2.9703067113271033,0.06783356671334267,412.63129088737514,75.94412659436712,-1.6413566434834488
3.0073063443222243,0.06867853570714143,413.9588300151268,75.94412659436712,-1.6413566434834488
3.0258061608197853,0.06910102020404081,414.6202097540394,75.94412659436712,-1.6413566434834488
3.0342151683186764,0.06929305861172234,414.920315387546,75.94412659436712,-1.6413566434834488
3.054396786316015,0.06975395079015803,415.6392485705761,75.94412659436712,-1.6413566434834488
3.072055702063687,0.07015723144628926,416.2667967521612,75.94412659436712,-1.6413566434834488
3.089714617811359,0.0705605121024205,416.892939654045,75.94412659436712,-1.6413566434834488
3.119987044807367,0.07125185037007402,417.96309010400944,75.94412659436712,-1.6413566434834488
3.1359641590552605,0.07161672334466894,418.52625871574,75.94412659436712,-1.6413566434834488
3.146895868803819,0.07186637327465493,418.9109400229194,75.94412659436712,-1.6413566434834488
3.156986677802489,0.07209681936387279,419.2655681468781,75.94412659436712,-1.6413566434834488
3.1628729830517126,0.07223124624924986,419.47223040316993,75.94412659436712,-1.6413566434834488
3.1679183875510475,0.07234646929385878,419.6492501220078,75.94412659436712,-1.6413566434834488
3.205758921296058,0.0732106421284257,420.9734110249746,75.94412659436712,-1.6413566434834488
3.2250996385435076,0.07365233046609322,421.64784942487114,75.94412659436712,-1.6413566434834488
3.236031348292066,0.07390198039607922,422.02835596326526,75.94412659436712,-1.6413566434834488
3.26125837078874,0.07447809561912383,422.90453986080786,75.94412659436712,-1.6413566434834488
3.2713491797874092,0.07470854170834167,423.2542728259027,75.94412659436712,-1.6413566434834488
3.293212599284527,0.07520784156831367,424.0105875173493,75.94412659436712,-1.6413566434834488
3.320121423280979,0.07582236447289459,424.93875348656525,75.94412659436712,-1.6413566434834488
3.3428257435279853,0.07634086817363474,425.7196137584216,75.94412659436712,-1.6413566434834488
3.358802857775878,0.07670574114822964,426.267868601982,75.94412659436712,-1.6413566434834488
3.382348078772774,0.07724344868973795,427.07397287267275,75.94412659436712,-1.6413566434834488
3.3907570862716647,0.07743548709741949,427.3613365040166,75.94412659436712,-1.6413566434834488
3.42439311626723,0.07820364072814563,428.5080225316918,75.94412659436712,-1.6413566434834488
3.4546655432632387,0.07889497899579917,429.53628962487164,75.94412659436712,-1.6413566434834488
3.464756352261908,0.079125425085017,429.8782636301715,75.94412659436712,-1.6413566434834488
3.488301573258804,0.07966313262652532,430.6746959812564,75.94412659436712,-1.6413566434834488
3.518574000254812,0.08035447089417884,431.6956065670781,75.94412659436712,-1.6413566434834488
3.527823908503592,0.08056571314262853,432.0068674541081,75.94412659436712,-1.6413566434834488
3.540437419751929,0.08085377075415083,432.43080166292845,75.94412659436712,-1.6413566434834488
3.552210030250377,0.08112262452490498,432.8259424587812,75.94412659436712,-1.6413566434834488
3.5648235414987135,0.08141068213642728,433.2487412710892,75.94412659436712,-1.6413566434834488
3.5850051594960526,0.08187157431486297,433.92400783802435,75.94412659436712,-1.6413566434834488
3.6001413729940572,0.08221724344868975,434.42948527614544,75.94412659436712,-1.6413566434834488
3.616959387991839,0.08260132026405281,434.99015579535245,75.94412659436712,-1.6413566434834488
3.627891097740398,0.08285097019403881,435.3540464958503,75.94412659436712,-1.6413566434834488
3.6514363187372934,0.08338867773554712,436.13636183339366,75.94412659436712,-1.6413566434834488
3.676663341233967,0.08396479295859172,436.9723768504404,75.94412659436712,-1.6413566434834488
3.703572165230419,0.08457931586317263,437.86166418269465,75.94412659436712,-1.6413566434834488
3.7195492794783123,0.08494418883776755,438.3884863177161,75.94412659436712,-1.6413566434834488
3.7287991877270925,0.08515543108621725,438.6930852262792,75.94412659436712,-1.6413566434834488
3.7472990042246535,0.08557791558311663,439.3014004206433,75.94412659436712,-1.6413566434834488
3.777571431220662,0.08626925385077015,440.29430498568144,75.94412659436712,-1.6413566434834488
3.7977530492180005,0.08673014602920584,440.9545179202407,75.94412659436712,-1.6413566434834488
3.8019575529674468,0.08682616523304662,441.09188989994476,75.94412659436712,-1.6413566434834488
3.828866376963899,0.08744068813762754,441.96967175547206,75.94412659436712,-1.6413566434834488
3.8381162852126787,0.08765193038607721,442.27085318243496,75.94412659436712,-1.6413566434834488
3.85577520096035,0.08805521104220844,442.8450509917993,75.94412659436712,-1.6413566434834488
3.8835249257066917,0.08868893778755751,443.74529404277104,75.94412659436712,-1.6413566434834488
3.8986611392046955,0.08903460692138428,444.2352781768045,75.94412659436712,-1.6413566434834488
3.906229245953698,0.08920744148829766,444.47999198932587,75.94412659436712,-1.6413566434834488
3.9213654594517022,0.08955311062212443,444.968865600047,75.94412659436712,-1.6413566434834488
3.9440697796987085,0.09007161432286458,445.7007983954554,75.94412659436712,-1.6413566434834488
3.982751214193608,0.09095499099819965,446.94402165901926,75.94412659436712,-1.6413566434834488
4.007978236690282,0.09153110622124426,447.7522832314189,75.94412659436712,-1.6413566434834488
4.017228144939062,0.09174234846969394,448.04814837792406,75.94412659436712,-1.6413566434834488
4.033205259186955,0.09210722144428886,448.5585631505397,75.94412659436712,-1.6413566434834488
4.049182373434849,0.09247209441888378,449.0681899674985,75.94412659436712,-1.6413566434834488
4.0634776861829645,0.0927985597119424,449.5235074821969,75.94412659436712,-1.6413566434834488
4.071886693681855,0.09299059811962393,449.79104950120995,75.94412659436712,-1.6413566434834488
4.0887047086796375,0.093374674934987,450.32548797765367,75.94412659436712,-1.6413566434834488
4.092068311679195,0.09345149029805962,450.43227271803613,75.94412659436712,-1.6413566434834488
4.127386143174538,0.09425805161032207,451.5514534881383,75.94412659436712,-1.6413566434834488
4.155135867920879,0.09489177835567114,452.4281917474648,75.94412659436712,-1.6413566434834488
4.159340371670324,0.09498779755951191,452.5608314064648,75.94412659436712,-1.6413566434834488
4.166908478419327,0.0951606321264253,452.7994510941943,75.94412659436712,-1.6413566434834488
4.194658203165667,0.09579435887177436,453.67294761117773,75.94412659436712,-1.6413566434834488
4.207271714414005,0.09608241648329667,454.0692461838396,75.94412659436712,-1.6413566434834488
4.235021439160345,0.09671614322864573,454.9394756582148,75.94412659436712,-1.6413566434834488
4.2535212556579065,0.09713862772554512,455.5183935016244,75.94412659436712,-1.6413566434834488
4.260248461657019,0.09729225845169034,455.72866551000754,75.94412659436712,-1.6413566434834488
4.271180171405578,0.09754190838167634,456.07008155055706,75.94412659436712,-1.6413566434834488
4.311543407400255,0.09846369273854771,457.32775327849134,75.94412659436712,-1.6413566434834488
4.342656735146153,0.0991742348469694,458.294077173209,75.94412659436712,-1.6413566434834488
4.372929162142162,0.09986557311462294,459.2316959522822,75.94412659436712,-1.6413566434834488
4.377974566641496,0.09998079615923185,459.3877193107514,75.94412659436712,-1.6413566434834488