File: datasets/aisi_316_L/data/M1/train_39.csv
Time(s),Strain(%),Stress(MPa),Temp(C),Log_SR(s-1)
0.0,0.0,0.0,306.43500781275833,3.0011545195597398
8.776637327339113e-09,8.8e-06,1.5587672375000001,306.43500781275833,3.0011545195597398
3.3510797068022066e-08,3.36e-05,5.951656724999999,306.43500781275833,3.0011545195597398
6.781947025671133e-08,6.8e-05,12.0450195625,306.43500781275833,3.0011545195597398
7.819185982538482e-08,7.84e-05,13.887199025,306.43500781275833,3.0011545195597398
8.05854881873864e-08,8.08e-05,14.3123173625,306.43500781275833,3.0011545195597398
1.0611752404873655e-07,0.0001064,18.8469129625,306.43500781275833,3.0011545195597398
1.1090478077273968e-07,0.00011119999999999999,19.697149637499997,306.43500781275833,3.0011545195597398
1.196814181000788e-07,0.00011999999999999999,21.255916874999997,306.43500781275833,3.0011545195597398
1.8032000327078542e-07,0.0001808,32.025581425,306.43500781275833,3.0011545195597398
1.9308602120146047e-07,0.0001936,34.292879225,306.43500781275833,3.0011545195597398
1.99469030166798e-07,0.00019999999999999998,35.426528125,306.43500781275833,3.0011545195597398
2.0744779137346993e-07,0.000208,36.84358925,306.43500781275833,3.0011545195597398
2.194159331834778e-07,0.00021999999999999998,38.9691809375,306.43500781275833,3.0011545195597398
2.3537345559682165e-07,0.000236,41.8033031875,306.43500781275833,3.0011545195597398
2.4574584516549515e-07,0.00024639999999999997,43.64548265,306.43500781275833,3.0011545195597398
2.7606513775084844e-07,0.0002768,49.030314925,306.43500781275833,3.0011545195597398
2.808523944748516e-07,0.0002816,49.880551600000004,306.43500781275833,3.0011545195597398
2.928205362848595e-07,0.0002936,52.006143287499995,306.43500781275833,3.0011545195597398
3.0319292585353295e-07,0.00030399999999999996,53.848322749999994,306.43500781275833,3.0011545195597398
3.359058468008879e-07,0.0003368,59.6582733625,306.43500781275833,3.0011545195597398
3.5425699757623324e-07,0.00035519999999999996,62.91751394999999,306.43500781275833,3.0011545195597398
3.598421304209036e-07,0.0003608,63.9094567375,306.43500781275833,3.0011545195597398
3.74203900592913e-07,0.00037519999999999996,66.4601667625,306.43500781275833,3.0011545195597398
3.82182661799585e-07,0.0003832,67.8772278875,306.43500781275833,3.0011545195597398
3.845762901615866e-07,0.0003856,68.302346225,306.43500781275833,3.0011545195597398
3.877677946442553e-07,0.00038879999999999996,68.86917067499999,306.43500781275833,3.0011545195597398
4.2127859171227736e-07,0.00042239999999999997,74.8208274,306.43500781275833,3.0011545195597398
4.308531051602837e-07,0.000432,76.52130075,306.43500781275833,3.0011545195597398
4.4521487533229315e-07,0.00044639999999999995,79.072010775,306.43500781275833,3.0011545195597398
4.651617783489729e-07,0.00046639999999999995,82.61466358749999,306.43500781275833,3.0011545195597398
4.843108052449855e-07,0.0004856,86.0156102875,306.43500781275833,3.0011545195597398
4.970768231756606e-07,0.0004984,88.28290808749999,306.43500781275833,3.0011545195597398
5.273961157610139e-07,0.0005288,93.6677403625,306.43500781275833,3.0011545195597398
5.417578859330234e-07,0.0005432,96.2184503875,306.43500781275833,3.0011545195597398
5.513323993810297e-07,0.0005528,97.9189237375,306.43500781275833,3.0011545195597398
5.617047889497033e-07,0.0005632,99.76110320000001,306.43500781275833,3.0011545195597398
5.672899217943735e-07,0.0005688,100.75304598749999,306.43500781275833,3.0011545195597398
5.81651691966383e-07,0.0005832,103.30375601249999,306.43500781275833,3.0011545195597398
6.008007188623956e-07,0.0006024,106.7047027125,306.43500781275833,3.0011545195597398
6.10375232310402e-07,0.000612,108.4051760625,306.43500781275833,3.0011545195597398
6.351093920510848e-07,0.0006368,112.79806554999999,306.43500781275833,3.0011545195597398
6.446839054990912e-07,0.0006464,114.4985389,306.43500781275833,3.0011545195597398
6.478754099817599e-07,0.0006496,115.06536335,306.43500781275833,3.0011545195597398
6.750031980844445e-07,0.0006768,119.883371175,306.43500781275833,3.0011545195597398
6.797904548084477e-07,0.0006816,120.73360785,306.43500781275833,3.0011545195597398
7.053224906697978e-07,0.0007072,125.26820344999999,306.43500781275833,3.0011545195597398
7.468120489444918e-07,0.0007488,132.6369213,306.43500781275833,3.0011545195597398
7.595780668751668e-07,0.0007616,134.9042191,306.43500781275833,3.0011545195597398
7.635674474785027e-07,0.0007656,135.6127496625,306.43500781275833,3.0011545195597398
7.723440848058419e-07,0.0007744,137.1715169,306.43500781275833,3.0011545195597398
7.827164743745154e-07,0.0007848,139.01369636249999,306.43500781275833,3.0011545195597398
7.898973594605201e-07,0.000792,140.28905137499999,306.43500781275833,3.0011545195597398
8.090463863565327e-07,0.0008112,143.689998075,306.43500781275833,3.0011545195597398
8.321847938558813e-07,0.0008344,147.7994753375,306.43500781275833,3.0011545195597398
8.385678028212188e-07,0.0008408,148.93312423749998,306.43500781275833,3.0011545195597398
8.648977148032361e-07,0.0008671999999999999,153.60942595,306.43500781275833,3.0011545195597398
8.880361223025847e-07,0.0008904,157.71890321249998,306.43500781275833,3.0011545195597398
9.175575387672707e-07,0.0009199999999999999,162.962029375,306.43500781275833,3.0011545195597398
9.662279821279696e-07,0.0009687999999999999,171.60610223749998,306.43500781275833,3.0011545195597398
9.877706373859838e-07,0.0009904,175.432167275,306.43500781275833,3.0011545195597398
1.0252708150573419e-06,0.001028,182.09235456250002,306.43500781275833,3.0011545195597398
1.043621965832687e-06,0.0010463999999999998,185.35159514999998,306.43500781275833,3.0011545195597398
1.055590107642695e-06,0.0010584,187.4771868375,306.43500781275833,3.0011545195597398
1.0651646210907014e-06,0.001068,189.17766018749998,306.43500781275833,3.0011545195597398
1.0867072763487157e-06,0.0010896,192.14500303371213,306.43500781275833,3.0011545195597398
1.0898987808313842e-06,0.0010927999999999999,192.16427064641707,306.43500781275833,3.0011545195597398
1.0986754181587233e-06,0.0011015999999999999,192.21714345569913,306.43500781275833,3.0011545195597398
1.109047807727397e-06,0.001112,192.27941760183387,306.43500781275833,3.0011545195597398
1.1210159495374048e-06,0.001124,192.35099083196098,306.43500781275833,3.0011545195597398
1.126601082382075e-06,0.0011296,192.38428962920844,306.43500781275833,3.0011545195597398
1.1329840913474127e-06,0.0011359999999999999,192.42226666536715,306.43500781275833,3.0011545195597398
1.151335242122758e-06,0.0011543999999999999,192.53098860151033,306.43500781275833,3.0011545195597398
1.1648991361741003e-06,0.001168,192.61091441368842,306.43500781275833,3.0011545195597398
1.180058782466777e-06,0.0011832,192.6998149820278,306.43500781275833,3.0011545195597398
1.1824524108287786e-06,0.0011856,192.7138110953834,306.43500781275833,3.0011545195597398
1.1912290481561177e-06,0.0011944,192.76503591507355,306.43500781275833,3.0011545195597398
1.205590818328127e-06,0.0012088,192.8485419911856,306.43500781275833,3.0011545195597398
1.213569579534799e-06,0.0012167999999999999,192.89476659261044,306.43500781275833,3.0011545195597398
1.229527101948143e-06,0.0012328,192.98686174739143,306.43500781275833,3.0011545195597398
1.2383037392754822e-06,0.0012416,193.03731534599592,306.43500781275833,3.0011545195597398
1.27580391694684e-06,0.0012791999999999999,193.25133755705497,306.43500781275833,3.0011545195597398
1.3117083423768637e-06,0.0013151999999999999,193.45396482768712,306.43500781275833,3.0011545195597398
1.3412297588415498e-06,0.0013448,193.61895382182695,306.43500781275833,3.0011545195597398
1.353995776772225e-06,0.0013576,193.68986108717206,306.43500781275833,3.0011545195597398
1.3643681663408983e-06,0.0013679999999999999,193.74728144923435,306.43500781275833,3.0011545195597398
1.3659639185822328e-06,0.0013696,193.75610021773372,306.43500781275833,3.0011545195597398
1.39229383056425e-06,0.0013959999999999999,193.90103475644403,306.43500781275833,3.0011545195597398
1.3978789634089204e-06,0.0014016,193.93164057757133,306.43500781275833,3.0011545195597398
1.4018683440122564e-06,0.0014056,193.95347268730262,306.43500781275833,3.0011545195597398
1.4082513529775938e-06,0.0014119999999999998,193.9883537314937,306.43500781275833,3.0011545195597398
1.4194216186669347e-06,0.0014232,194.04924755371061,306.43500781275833,3.0011545195597398
1.4226131231496034e-06,0.0014264,194.06661142464236,306.43500781275833,3.0011545195597398
1.4393685216836144e-06,0.0014432,194.1575237021743,306.43500781275833,3.0011545195597398
1.450538787372955e-06,0.0014544,194.217902694825,306.43500781275833,3.0011545195597398
1.496017726250985e-06,0.0015,194.46188223544627,306.43500781275833,3.0011545195597398
1.4984113546129865e-06,0.0015023999999999999,194.4746425322088,306.43500781275833,3.0011545195597398
1.516762505388332e-06,0.0015207999999999999,194.57220874261597,306.43500781275833,3.0011545195597398
1.5271348949570055e-06,0.0015312,194.62715119893014,306.43500781275833,3.0011545195597398
1.545486045732351e-06,0.0015496,194.72400188433198,306.43500781275833,3.0011545195597398
1.5558584353010244e-06,0.00156,194.77854516489126,306.43500781275833,3.0011545195597398
1.6021352502997216e-06,0.0016064,195.0201847031446,306.43500781275833,3.0011545195597398
1.6300609145230733e-06,0.0016343999999999998,195.16468503141652,306.43500781275833,3.0011545195597398
1.6380396757297454e-06,0.0016424,195.20579309212906,306.43500781275833,3.0011545195597398
1.6508056936604203e-06,0.0016552,195.27140393150813,306.43500781275833,3.0011545195597398
1.6571887026257577e-06,0.0016615999999999998,195.30413512504427,306.43500781275833,3.0011545195597398
1.6731462250391018e-06,0.0016776,195.38574873313715,306.43500781275833,3.0011545195597398
1.681922862366441e-06,0.0016864,195.43050680288383,306.43500781275833,3.0011545195597398
1.703465517624455e-06,0.0017079999999999999,195.53998307635462,306.43500781275833,3.0011545195597398
1.71623153555513e-06,0.0017208,195.60460313079494,306.43500781275833,3.0011545195597398
1.7218166683998003e-06,0.0017264,195.6328154277176,306.43500781275833,3.0011545195597398
1.7266039251238037e-06,0.0017312,195.6569690017947,306.43500781275833,3.0011545195597398
1.740965695295813e-06,0.0017456,195.72927350087798,306.43500781275833,3.0011545195597398
1.7505402087438194e-06,0.0017552,195.7773473088103,306.43500781275833,3.0011545195597398
1.766497731157163e-06,0.0017712,195.8572430665604,306.43500781275833,3.0011545195597398
1.7704871117604992e-06,0.0017752,195.87717296447445,306.43500781275833,3.0011545195597398
1.7928276431391805e-06,0.0017976,195.98845842017639,306.43500781275833,3.0011545195597398
1.8279341924485368e-06,0.0018327999999999999,196.162249046683,306.43500781275833,3.0011545195597398
1.8422959626205464e-06,0.0018472,196.2329694431405,306.43500781275833,3.0011545195597398
1.849476847706551e-06,0.0018544,196.26824898917872,306.43500781275833,3.0011545195597398
1.857455608913223e-06,0.0018624,196.30738588955285,306.43500781275833,3.0011545195597398
1.8686258746025638e-06,0.0018736,196.3620675810039,306.43500781275833,3.0011545195597398
1.8805940164125715e-06,0.0018855999999999999,196.4205138335649,306.43500781275833,3.0011545195597398
1.8933600343432468e-06,0.0018984,196.48269684089982,306.43500781275833,3.0011545195597398
1.9141048134805934e-06,0.0019191999999999998,196.5833966108133,306.43500781275833,3.0011545195597398
1.9340517164972736e-06,0.0019391999999999999,196.67982268062693,306.43500781275833,3.0011545195597398
1.947615610548616e-06,0.0019528,196.74517097040493,306.43500781275833,3.0011545195597398
1.973147646409966e-06,0.0019784,196.86770002089423,306.43500781275833,3.0011545195597398
1.9922966733059784e-06,0.0019976,196.95919142658127,306.43500781275833,3.0011545195597398
2.002669062874652e-06,0.002008,197.00860605014157,306.43500781275833,3.0011545195597398
2.030594727098004e-06,0.002036,197.1411518005321,306.43500781275833,3.0011545195597398
2.0497437539940163e-06,0.0020552,197.2316297102716,306.43500781275833,3.0011545195597398
2.090435436148043e-06,0.0020959999999999998,197.4228079551187,306.43500781275833,3.0011545195597398
2.1008078257167167e-06,0.0021064,197.471306849858,306.43500781275833,3.0011545195597398
2.1055950824407197e-06,0.0021111999999999997,197.49365944899327,306.43500781275833,3.0011545195597398
2.1135738436473916e-06,0.0021192,197.53086978667952,306.43500781275833,3.0011545195597398
2.1167653481300605e-06,0.0021224,197.54573857766925,306.43500781275833,3.0011545195597398
2.119158976492062e-06,0.0021248,197.5568844339673,306.43500781275833,3.0011545195597398
2.16224428700809e-06,0.002168,197.75667782042075,306.43500781275833,3.0011545195597398
2.1917657034727766e-06,0.0021976,197.89267773046038,306.43500781275833,3.0011545195597398
2.1941593318347777e-06,0.0021999999999999997,197.90367334138452,306.43500781275833,3.0011545195597398
2.218893491575461e-06,0.0022248,198.0170220651881,306.43500781275833,3.0011545195597398
2.2308616333854688e-06,0.0022367999999999997,198.07169122842438,306.43500781275833,3.0011545195597398
2.2755426961428317e-06,0.0022816,198.2747866304611,306.43500781275833,3.0011545195597398
2.2795320767461677e-06,0.0022856,198.292844177413,306.43500781275833,3.0011545195597398
2.309851369331521e-06,0.002316,198.42968103181968,306.43500781275833,3.0011545195597398
2.333787652951537e-06,0.00234,198.53721593994376,306.43500781275833,3.0011545195597398
2.3672984500195587e-06,0.0023736,198.68704496427694,306.43500781275833,3.0011545195597398
2.380862344070901e-06,0.0023872,198.74745461101426,306.43500781275833,3.0011545195597398
2.3856496007949044e-06,0.002392,198.76874359767908,306.43500781275833,3.0011545195597398
2.3960219903635774e-06,0.0024024,198.81481266327987,306.43500781275833,3.0011545195597398
2.405596503811584e-06,0.002412,198.85726896740866,306.43500781275833,3.0011545195597398
2.4295327874315995e-06,0.002436,198.96312242004547,306.43500781275833,3.0011545195597398
2.4494796904482793e-06,0.002456,199.05102329128945,306.43500781275833,3.0011545195597398
2.459054203896286e-06,0.0024656,199.0931165126264,306.43500781275833,3.0011545195597398
2.4805968591543e-06,0.0024871999999999997,199.18759325976956,306.43500781275833,3.0011545195597398
2.4853841158783033e-06,0.002492,199.20854457466007,306.43500781275833,3.0011545195597398
2.5165012845843235e-06,0.0025231999999999997,199.3443465025908,306.43500781275833,3.0011545195597398
2.528469426394332e-06,0.0025352,199.39640343517715,306.43500781275833,3.0011545195597398
2.538841815963005e-06,0.0025456,199.4414417599016,306.43500781275833,3.0011545195597398
2.5452248249283427e-06,0.002552,199.46912198609812,306.43500781275833,3.0011545195597398
2.5532035861350146e-06,0.0025599999999999998,199.50368422728369,306.43500781275833,3.0011545195597398
2.5699589846690254e-06,0.0025767999999999998,199.57612812492454,306.43500781275833,3.0011545195597398
2.583522878720368e-06,0.0025904,199.6346383632803,306.43500781275833,3.0011545195597398
2.589108011565038e-06,0.002596,199.65869597838815,306.43500781275833,3.0011545195597398
2.5954910205303756e-06,0.0026024,199.68616562648188,306.43500781275833,3.0011545195597398
2.6074591623403835e-06,0.0026144,199.7376003090239,306.43500781275833,3.0011545195597398
2.621820932512393e-06,0.0026287999999999997,199.79920055207336,306.43500781275833,3.0011545195597398
2.6385763310464037e-06,0.0026455999999999997,199.8709014225792,306.43500781275833,3.0011545195597398
2.66251261466642e-06,0.0026696,199.97302396927654,306.43500781275833,3.0011545195597398
2.6704913758730917e-06,0.0026776,200.0069851679824,306.43500781275833,3.0011545195597398
2.6856510221657685e-06,0.0026928,200.07140262227438,306.43500781275833,3.0011545195597398
2.6992149162171105e-06,0.0027064,200.12891918558063,306.43500781275833,3.0011545195597398
2.7063958013031153e-06,0.0027136,200.1593234910327,306.43500781275833,3.0011545195597398
2.7167681908717887e-06,0.002724,200.20318533601497,306.43500781275833,3.0011545195597398
2.7359172177678015e-06,0.0027432,200.28398984967274,306.43500781275833,3.0011545195597398
2.7486832356984764e-06,0.0027559999999999998,200.3377370212341,306.43500781275833,3.0011545195597398
2.7662365103531547e-06,0.0027735999999999998,200.41148069320397,306.43500781275833,3.0011545195597398
2.7774067760424955e-06,0.0027848,200.45831348031538,306.43500781275833,3.0011545195597398
2.8069281925071817e-06,0.0028144,200.5817335872292,306.43500781275833,3.0011545195597398
2.8149069537138536e-06,0.0028224,200.61500334087043,306.43500781275833,3.0011545195597398
2.825279343282527e-06,0.0028328,200.65819908970406,306.43500781275833,3.0011545195597398
2.834055980609866e-06,0.0028415999999999997,200.6947010535226,306.43500781275833,3.0011545195597398
2.838045361213202e-06,0.0028455999999999998,200.71127827875807,306.43500781275833,3.0011545195597398
2.854800759747213e-06,0.0028623999999999998,200.78080361830317,306.43500781275833,3.0011545195597398
2.8675667776778885e-06,0.0028752,200.83366854124395,306.43500781275833,3.0011545195597398
2.8915030612979038e-06,0.0028991999999999998,200.93254353870086,306.43500781275833,3.0011545195597398
2.8954924419012397e-06,0.0029032,200.9489916207547,306.43500781275833,3.0011545195597398
2.9066627075905806e-06,0.0029143999999999997,200.99499929788328,306.43500781275833,3.0011545195597398
2.9114499643145836e-06,0.0029192,201.01469575952657,306.43500781275833,3.0011545195597398
2.9266096106072604e-06,0.0029343999999999998,201.0769847237392,306.43500781275833,3.0011545195597398
2.9345883718139323e-06,0.0029424,201.10971783958001,306.43500781275833,3.0011545195597398
2.943365009141271e-06,0.0029511999999999997,201.14568420450888,306.43500781275833,3.0011545195597398
2.9688970450026214e-06,0.0029768,201.25007657130624,306.43500781275833,3.0011545195597398
2.9896418241399686e-06,0.0029976,201.33463779869845,306.43500781275833,3.0011545195597398
2.991237576381303e-06,0.0029992,201.34113301469785,306.43500781275833,3.0011545195597398
3.0151738600013184e-06,0.0030231999999999998,201.43839966615045,306.43500781275833,3.0011545195597398
3.041503771983336e-06,0.0030496,201.54504582305984,306.43500781275833,3.0011545195597398
3.060652798879349e-06,0.0030688,201.62238064506585,306.43500781275833,3.0011545195597398
3.071025188448022e-06,0.0030792,201.6641915425257,306.43500781275833,3.0011545195597398
3.1117168706020488e-06,0.00312,201.8276898281274,306.43500781275833,3.0011545195597398
3.125280764653391e-06,0.0031336,201.88200367935778,306.43500781275833,3.0011545195597398
3.1364510303427315e-06,0.0031447999999999997,201.92666373788018,306.43500781275833,3.0011545195597398
3.1579936856007458e-06,0.0031663999999999998,202.01261906471416,306.43500781275833,3.0011545195597398
3.1675681990487526e-06,0.003176,202.0507479976013,306.43500781275833,3.0011545195597398
3.177940588617426e-06,0.0031864,202.09200365473444,306.43500781275833,3.0011545195597398
3.1938981110307694e-06,0.0032023999999999998,202.15537150113386,306.43500781275833,3.0011545195597398
3.2066641289614447e-06,0.0032151999999999997,202.2059769215676,306.43500781275833,3.0011545195597398
3.217036518530118e-06,0.0032256,202.2470359962065,306.43500781275833,3.0011545195597398
3.2457600588741372e-06,0.0032543999999999997,202.36046947559961,306.43500781275833,3.0011545195597398
3.254536696201476e-06,0.0032632,202.39505152942533,306.43500781275833,3.0011545195597398
3.2720899708561544e-06,0.0032808,202.46410671732295,306.43500781275833,3.0011545195597398
3.276079351459491e-06,0.0032848,202.47978091158342,306.43500781275833,3.0011545195597398
3.2856538649074968e-06,0.0032944,202.51736863781568,306.43500781275833,3.0011545195597398
3.307196520165511e-06,0.003316,202.60178518694644,306.43500781275833,3.0011545195597398
3.3279412993028583e-06,0.0033368,202.68287274449582,306.43500781275833,3.0011545195597398
3.3622499724915474e-06,0.0033712,202.8165478164332,306.43500781275833,3.0011545195597398
3.3798032471462257e-06,0.0033888,202.88473393438383,306.43500781275833,3.0011545195597398
3.383792627749561e-06,0.0033927999999999996,202.90021150170338,306.43500781275833,3.0011545195597398
3.3965586456802365e-06,0.0034056,202.94969196227018,306.43500781275833,3.0011545195597398
3.435654575592929e-06,0.0034448,203.10077662583146,306.43500781275833,3.0011545195597398
3.47794200998829e-06,0.0034871999999999998,203.26344185582258,306.43500781275833,3.0011545195597398
3.5050697980909748e-06,0.0035144,203.36738714069662,306.43500781275833,3.0011545195597398
3.5218251966249856e-06,0.0035312,203.43143192013693,306.43500781275833,3.0011545195597398
3.5242188249869875e-06,0.0035336,203.44057146437467,306.43500781275833,3.0011545195597398
3.5513466130896718e-06,0.0035608,203.5439843393277,306.43500781275833,3.0011545195597398
3.5744850205890205e-06,0.003584,203.63194622113926,306.43500781275833,3.0011545195597398
3.576080772830355e-06,0.0035856,203.63800435975656,306.43500781275833,3.0011545195597398
3.58884679076103e-06,0.0035984,203.6864315722014,306.43500781275833,3.0011545195597398
3.5920382952436988e-06,0.0036016,203.69852787237616,306.43500781275833,3.0011545195597398
3.6095915698983766e-06,0.0036192,203.76498275123285,306.43500781275833,3.0011545195597398
3.623155463949719e-06,0.0036328,203.81624796223008,306.43500781275833,3.0011545195597398
3.635123605759727e-06,0.0036447999999999997,203.86141984630083,306.43500781275833,3.0011545195597398
3.6750174117930864e-06,0.0036848,204.01157564070016,306.43500781275833,3.0011545195597398
3.6845919252410928e-06,0.0036944,204.04751827654113,306.43500781275833,3.0011545195597398
3.697357943171768e-06,0.0037072,204.095385180893,306.43500781275833,3.0011545195597398
3.7212942267917834e-06,0.0037311999999999996,204.18496225586188,306.43500781275833,3.0011545195597398
3.7244857312744523e-06,0.0037343999999999997,204.19688886506057,306.43500781275833,3.0011545195597398
3.734858120843126e-06,0.0037448,204.23562284746703,306.43500781275833,3.0011545195597398
3.748422014894468e-06,0.0037584,204.2862117358353,306.43500781275833,3.0011545195597398
3.768368917911148e-06,0.0037784,204.360477659798,306.43500781275833,3.0011545195597398
3.7755498029971523e-06,0.0037855999999999996,204.3871758413584,306.43500781275833,3.0011545195597398
3.798688210496501e-06,0.0038087999999999998,204.47306891452604,306.43500781275833,3.0011545195597398
3.805869095582506e-06,0.003816,204.49968386586033,306.43500781275833,3.0011545195597398
3.8130499806685104e-06,0.0038231999999999997,204.5262792397978,306.43500781275833,3.0011545195597398
3.833794759805858e-06,0.0038439999999999998,204.60300081622657,306.43500781275833,3.0011545195597398
3.8465607777365325e-06,0.0038567999999999996,204.65013362722078,306.43500781275833,3.0011545195597398
3.867305556873879e-06,0.0038775999999999997,204.7265945397029,306.43500781275833,3.0011545195597398
3.874486441959884e-06,0.0038848,204.75302448876053,306.43500781275833,3.0011545195597398
3.899220601700568e-06,0.0039096,204.84391511006828,306.43500781275833,3.0011545195597398
3.935922903251258e-06,0.0039464,204.9783717789484,306.43500781275833,3.0011545195597398
3.946295292819932e-06,0.0039568,205.0162816660466,306.43500781275833,3.0011545195597398
3.971029452560615e-06,0.0039816,205.10652568857202,306.43500781275833,3.0011545195597398
3.978210337646619e-06,0.0039888,205.132684471002,306.43500781275833,3.0011545195597398
3.989380603335961e-06,0.004,205.17333933745812,306.43500781275833,3.0011545195597398
4.180909178011022e-06,0.0041920384076815365,205.86365707757633,306.43500781275833,3.0011545195597398
4.640577757231169e-06,0.004652930586117224,207.4719185716858,306.43500781275833,3.0011545195597398
4.7938006169712176e-06,0.004806561312262453,207.99402883619481,306.43500781275833,3.0011545195597398
5.1002463364513155e-06,0.005113822764552911,209.0191185298741,306.43500781275833,3.0011545195597398
5.540762058203955e-06,0.005555511102220444,210.4515436029369,306.43500781275833,3.0011545195597398
5.9046663500865715e-06,0.005920384076815363,211.60162044273724,306.43500781275833,3.0011545195597398
6.191959212099163e-06,0.0062084416883376676,212.49015519834055,306.43500781275833,3.0011545195597398
6.4409463591767425e-06,0.006458091618323665,213.24728860066125,306.43500781275833,3.0011545195597398
6.958073510799408e-06,0.006976595319063813,214.78425310205367,306.43500781275833,3.0011545195597398
7.4368949474870595e-06,0.007456691338267653,216.16807862903923,306.43500781275833,3.0011545195597398
7.8774106692397e-06,0.007898379675935187,217.4107961986624,306.43500781275833,3.0011545195597398
8.107244958849775e-06,0.00812882576515303,218.04839156851307,306.43500781275833,3.0011545195597398
8.451996393264884e-06,0.008474494898979796,218.99172195040072,306.43500781275833,3.0011545195597398
8.739289255277476e-06,0.0087625525105021,219.76641923931626,306.43500781275833,3.0011545195597398
8.8159006851475e-06,0.008839367873574715,219.97131956917252,306.43500781275833,3.0011545195597398
9.773543558522807e-06,0.009799559911982397,222.47662347141792,306.43500781275833,3.0011545195597398
1.0003377848132879e-05,0.01003000600120024,223.06341621441285,306.43500781275833,3.0011545195597398
1.0328976425080484e-05,0.010356471294258852,223.8857835858763,306.43500781275833,3.0011545195597398
1.059711642962557e-05,0.010625325065013003,224.55546181050514,306.43500781275833,3.0011545195597398
1.0807797861768134e-05,0.010836567313462692,225.07701223232044,306.43500781275833,3.0011545195597398
1.1324925013390802e-05,0.011355071014202842,226.3406473180967,306.43500781275833,3.0011545195597398
1.182289930754596e-05,0.011854370874174834,227.53637592073213,306.43500781275833,3.0011545195597398
1.2148497884493563e-05,0.012180836167233446,228.3075915673135,306.43500781275833,3.0011545195597398
1.2301720744233613e-05,0.012334466893378675,228.667723252627,306.43500781275833,3.0011545195597398
1.2569860748778698e-05,0.012603320664132826,229.29377228221605,306.43500781275833,3.0011545195597398
1.285715361079129e-05,0.012891378275655131,229.95878683855085,306.43500781275833,3.0011545195597398
1.3278516475076423e-05,0.013313862772554511,230.92375245330385,306.43500781275833,3.0011545195597398
1.3719032196829065e-05,0.013755551110222045,231.91989587378504,306.43500781275833,3.0011545195597398
1.423615934845173e-05,0.014274054810962193,233.07350027791284,306.43500781275833,3.0011545195597398
1.4561757925399333e-05,0.014600520104020805,233.79146514527037,306.43500781275833,3.0011545195597398
1.5059732219554492e-05,0.0150998199639928,234.877535159767,306.43500781275833,3.0011545195597398
1.5672623658514688e-05,0.015714342868573716,236.19519491055482,306.43500781275833,3.0011545195597398
1.6457890814682438e-05,0.016501700340068013,237.85443595004296,306.43500781275833,3.0011545195597398
1.7032476538707623e-05,0.017077815563112622,239.04901286340416,306.43500781275833,3.0011545195597398
1.7300616543252708e-05,0.017346669333866773,239.60109343331243,306.43500781275833,3.0011545195597398
1.7990119412082926e-05,0.018038007601520304,241.00561974311233,306.43500781275833,3.0011545195597398
1.8794539425718184e-05,0.018844568913782757,242.6179652417491,306.43500781275833,3.0011545195597398
1.975218229909349e-05,0.01980476095219044,244.50273888435459,306.43500781275833,3.0011545195597398
2.0020322303638576e-05,0.02007361472294459,245.02404467487946,306.43500781275833,3.0011545195597398
2.028846230818366e-05,0.02034246849369874,245.5426344675525,306.43500781275833,3.0011545195597398
2.0365073738053687e-05,0.020419283856771355,245.69031112709527,306.43500781275833,3.0011545195597398
2.0556602312728746e-05,0.02061132226445289,246.05855803187717,306.43500781275833,3.0011545195597398
2.0901353747143857e-05,0.020956991398279657,246.71804803902617,306.43500781275833,3.0011545195597398
2.1495092328636544e-05,0.021552310462092418,247.84397697383727,306.43500781275833,3.0011545195597398
2.1897302335454175e-05,0.021955591118223646,248.59981968919996,306.43500781275833,3.0011545195597398
2.2491040916946862e-05,0.022550910182036407,249.70576564917937,306.43500781275833,3.0011545195597398
2.295070949616701e-05,0.023011802360472094,250.5541797213775,306.43500781275833,3.0011545195597398
2.298901521110202e-05,0.023050210042008402,250.6245803647675,306.43500781275833,3.0011545195597398
2.348698950525718e-05,0.023549509901980396,251.5356649579534,306.43500781275833,3.0011545195597398
2.3812588082204785e-05,0.023875975195039006,252.1273035912676,306.43500781275833,3.0011545195597398
2.413818665915239e-05,0.02420244048809762,252.71579552189002,306.43500781275833,3.0011545195597398
2.442547952116498e-05,0.024490498099619923,253.2324869272554,306.43500781275833,3.0011545195597398
2.471277238317757e-05,0.02477855571114223,253.7468135359386,306.43500781275833,3.0011545195597398
2.5402275252007793e-05,0.02546989397879576,254.97177500435328,306.43500781275833,3.0011545195597398
2.6072625263370506e-05,0.026142028405681136,256.15033725049847,306.43500781275833,3.0011545195597398
2.6130083835773026e-05,0.0261996399279856,256.25080370883836,306.43500781275833,3.0011545195597398
2.664721098739569e-05,0.026718143628725745,257.1511575649889,306.43500781275833,3.0011545195597398
2.670466955979821e-05,0.026775755151030207,257.2507744555201,306.43500781275833,3.0011545195597398
2.7087726709148332e-05,0.02715983196639328,257.91276367138073,306.43500781275833,3.0011545195597398
2.773892386304354e-05,0.027812762552510504,259.0298269118285,306.43500781275833,3.0011545195597398
2.8160286727328673e-05,0.028235247049409884,259.7471862794557,306.43500781275833,3.0011545195597398
2.827520387213371e-05,0.028350470094018806,259.94210165136974,306.43500781275833,3.0011545195597398
2.8351815302003735e-05,0.02842728545709142,260.0718736210462,306.43500781275833,3.0011545195597398
2.8773178166288865e-05,0.028849769953990797,260.78318980297024,306.43500781275833,3.0011545195597398
2.8888095311093902e-05,0.02896499299859972,260.97647857781647,306.43500781275833,3.0011545195597398
2.9232846745509013e-05,0.029310662132426484,261.55455363503523,306.43500781275833,3.0011545195597398
2.9462681035119087e-05,0.029541108221644328,261.93846058087075,306.43500781275833,3.0011545195597398
2.9654209609794146e-05,0.029733146629325864,262.2574916439065,306.43500781275833,3.0011545195597398
2.9998961044209257e-05,0.03007881576315263,262.8297298029765,306.43500781275833,3.0011545195597398
3.022879533381933e-05,0.030309261852370473,263.20979769925236,306.43500781275833,3.0011545195597398
3.0420323908494393e-05,0.03050130026005201,263.5256608139915,306.43500781275833,3.0011545195597398
3.10715210623896e-05,0.031154230846169233,264.5938411041808,306.43500781275833,3.0011545195597398
3.218238679550495e-05,0.032268053610722144,266.39609553818246,306.43500781275833,3.0011545195597398
3.2488832514985055e-05,0.0325753150630126,266.8889783021406,306.43500781275833,3.0011545195597398
3.277612537699765e-05,0.03286337267453491,267.3494117571278,306.43500781275833,3.0011545195597398
3.310172395394525e-05,0.03318983796759352,267.86933781683905,306.43500781275833,3.0011545195597398
3.333155824355532e-05,0.03342028405681136,268.2351442725628,306.43500781275833,3.0011545195597398
3.3676309677970436e-05,0.03376595319063813,268.7820148504763,306.43500781275833,3.0011545195597398
3.4231742544528115e-05,0.034322864572914585,269.6585138058406,306.43500781275833,3.0011545195597398
3.4289201116930635e-05,0.03438047609521905,269.7488684038807,306.43500781275833,3.0011545195597398
3.438496540426816e-05,0.034476495299059814,269.89932829126013,306.43500781275833,3.0011545195597398
3.490209255589083e-05,0.034994998999799964,270.7090050988479,306.43500781275833,3.0011545195597398
3.538091399257847e-05,0.0354750950190038,271.45454394527354,306.43500781275833,3.0011545195597398
3.559159542472104e-05,0.03568633726745349,271.78133333309313,306.43500781275833,3.0011545195597398
3.651093258316134e-05,0.03660812162432486,273.19858508241236,306.43500781275833,3.0011545195597398
3.677907258770642e-05,0.03687697539507902,273.6093195832222,306.43500781275833,3.0011545195597398
3.721958830945906e-05,0.037318663732746546,274.2815714201592,306.43500781275833,3.0011545195597398
3.73345054542641e-05,0.03743388677735547,274.4564302376316,306.43500781275833,3.0011545195597398
3.752603402893916e-05,0.037625925185037004,274.74739586132995,306.43500781275833,3.0011545195597398
3.76792568886792e-05,0.03777955591118223,274.97975157283366,306.43500781275833,3.0011545195597398
3.808146689549683e-05,0.03818283656731346,275.5879387683711,306.43500781275833,3.0011545195597398
3.8560288332184493e-05,0.038662932586517304,276.3087143984697,306.43500781275833,3.0011545195597398
3.915402691367718e-05,0.03925825165033006,277.1976466460366,306.43500781275833,3.0011545195597398
3.9671154065299845e-05,0.03977675535107021,277.96760314453945,306.43500781275833,3.0011545195597398
3.993929406984493e-05,0.040045609121824366,278.3652982359944,306.43500781275833,3.0011545195597398
4.0130822644519986e-05,0.0402376475295059,278.64872889149393,306.43500781275833,3.0011545195597398
4.032235121919505e-05,0.04042968593718743,278.9316324812455,306.43500781275833,3.0011545195597398
4.0877784085752734e-05,0.0409865973194639,279.74910427565396,306.43500781275833,3.0011545195597398
4.158643981205046e-05,0.04169713942788558,280.78582343303236,306.43500781275833,3.0011545195597398
4.166305124192048e-05,0.04177395479095819,280.89748694484354,306.43500781275833,3.0011545195597398
4.196949696140058e-05,0.04208121624324865,281.3433425262172,306.43500781275833,3.0011545195597398
4.221848410847815e-05,0.042330866173234644,281.7046660485482,306.43500781275833,3.0011545195597398
4.229509553834818e-05,0.042407681536307265,281.81567519577726,306.43500781275833,3.0011545195597398
4.3597489846138596e-05,0.043713542708541706,283.6909948205245,306.43500781275833,3.0011545195597398
4.382732413574868e-05,0.043943988797759556,284.01965270416645,306.43500781275833,3.0011545195597398
4.386562985068368e-05,0.04398239647929586,284.074363602642,306.43500781275833,3.0011545195597398
4.413376985522877e-05,0.044251250250050014,284.456819524602,306.43500781275833,3.0011545195597398
4.419122842763129e-05,0.04430886177235448,284.5386563415919,306.43500781275833,3.0011545195597398
4.4286992714968825e-05,0.04440488097619524,284.67495887807775,306.43500781275833,3.0011545195597398
4.45359798620464e-05,0.04465453090618124,285.02880860846284,306.43500781275833,3.0011545195597398
4.514887130100659e-05,0.045269053810762155,285.8965522534386,306.43500781275833,3.0011545195597398
4.570430416756427e-05,0.04582596519303861,286.67898478275936,306.43500781275833,3.0011545195597398
4.595329131464185e-05,0.046075615123024605,287.0285256980994,306.43500781275833,3.0011545195597398
4.6317195606524465e-05,0.046440488097619526,287.53806746781686,306.43500781275833,3.0011545195597398
4.712161562015972e-05,0.047247049409881975,288.65891522363614,306.43500781275833,3.0011545195597398
4.758128419937987e-05,0.04770794158831766,289.29604890569965,306.43500781275833,3.0011545195597398
4.828993992567759e-05,0.048418483696739345,290.2736136228515,306.43500781275833,3.0011545195597398
4.840485707048263e-05,0.04853370674134827,290.4316089240476,306.43500781275833,3.0011545195597398
4.8672997075027724e-05,0.048802560512102425,290.79969682823395,306.43500781275833,3.0011545195597398
4.89219842221053e-05,0.04905221044208842,291.14078524027866,306.43500781275833,3.0011545195597398
4.9228429941585396e-05,0.04935947189437888,291.5596583766456,306.43500781275833,3.0011545195597398
4.986047423801309e-05,0.04999319863972794,292.4203862220746,306.43500781275833,3.0011545195597398
4.997539138281813e-05,0.050108421684336865,292.57642394709507,306.43500781275833,3.0011545195597398
5.010946138509068e-05,0.05024284856971395,292.7582912091928,306.43500781275833,3.0011545195597398
5.028183710229823e-05,0.05041568313662732,292.991841941787,306.43500781275833,3.0011545195597398
5.072235282405088e-05,0.050857371474294866,293.58727959873755,306.43500781275833,3.0011545195597398
5.139270283541358e-05,0.05152950590118023,294.4895252520329,306.43500781275833,3.0011545195597398
5.235034570878889e-05,0.05248969793958792,295.7705260856347,306.43500781275833,3.0011545195597398
5.2561027140931464e-05,0.052700940188037615,296.05111603954276,306.43500781275833,3.0011545195597398
5.303984857761911e-05,0.05318103620724145,296.68719430975625,306.43500781275833,3.0011545195597398
5.328883572469669e-05,0.05343068613722744,297.01706974219655,306.43500781275833,3.0011545195597398
5.384426859125436e-05,0.053987597519503897,297.7507872638911,306.43500781275833,3.0011545195597398
5.397833859352691e-05,0.05412202440488098,297.92744853220216,306.43500781275833,3.0011545195597398
5.447631288768207e-05,0.05462132426485297,298.5821261003107,306.43500781275833,3.0011545195597398
5.48785228944997e-05,0.055024604920984196,299.10920191057943,306.43500781275833,3.0011545195597398
5.5165815756512285e-05,0.055312662532506496,299.4847626611522,306.43500781275833,3.0011545195597398
5.5280732901317325e-05,0.05542788557711542,299.6347732899123,306.43500781275833,3.0011545195597398
5.654482149417272e-05,0.05669533906781356,301.27694290853776,306.43500781275833,3.0011545195597398
5.733008865034048e-05,0.05748269653930786,302.28987157224054,306.43500781275833,3.0011545195597398
5.752161722501554e-05,0.057674734946989395,302.5361047558761,306.43500781275833,3.0011545195597398
5.823027295131326e-05,0.05838527705541108,303.4444005763095,306.43500781275833,3.0011545195597398
5.880485867533845e-05,0.05896139227845569,304.17769594229605,306.43500781275833,3.0011545195597398
5.939859725683113e-05,0.05955671134226845,304.932504808,306.43500781275833,3.0011545195597398
5.9800807263648774e-05,0.059959991998399687,305.4421558596551,306.43500781275833,3.0011545195597398
6.0011488695791325e-05,0.060171234246849364,305.7085823113548,306.43500781275833,3.0011545195597398
6.033708727273894e-05,0.06049769953990798,306.1196158997224,306.43500781275833,3.0011545195597398
6.064353299221903e-05,0.06080496099219844,306.505681535719,306.43500781275833,3.0011545195597398
6.162032872306186e-05,0.06178435687137428,307.73121872586466,306.43500781275833,3.0011545195597398
6.171609301039938e-05,0.06188037607521504,307.8509601668926,306.43500781275833,3.0011545195597398
6.211830301721701e-05,0.06228365673134627,308.3530849788905,306.43500781275833,3.0011545195597398
6.24247487366971e-05,0.06259091818363673,308.7348056604815,306.43500781275833,3.0011545195597398
6.26928887412422e-05,0.06285977195439088,309.06821216153355,306.43500781275833,3.0011545195597398
6.294187588831977e-05,0.06310942188437688,309.37730628567147,306.43500781275833,3.0011545195597398
6.315255732046234e-05,0.06332066413282657,309.6384751887384,306.43500781275833,3.0011545195597398
6.347815589740994e-05,0.06364712942588517,310.0414324877637,306.43500781275833,3.0011545195597398
6.36888373295525e-05,0.06385837167433486,310.301740090394,306.43500781275833,3.0011545195597398
6.39569773340976e-05,0.06412722544508902,310.63255549120373,306.43500781275833,3.0011545195597398
6.451241020065527e-05,0.06468413682736547,311.316100227178,306.43500781275833,3.0011545195597398
6.533598307175803e-05,0.06550990198039608,312.3254224711044,306.43500781275833,3.0011545195597398
6.547005307403057e-05,0.06564432886577315,312.489259974581,306.43500781275833,3.0011545195597398
6.608294451299076e-05,0.06625885177035407,313.2365713874422,306.43500781275833,3.0011545195597398
6.640854308993837e-05,0.06658531706341268,313.63248088865186,306.43500781275833,3.0011545195597398
6.656176594967843e-05,0.06673894778955791,313.81852922518027,306.43500781275833,3.0011545195597398
6.717465738863862e-05,0.06735347069413883,314.5610583525114,306.43500781275833,3.0011545195597398
6.723211596104114e-05,0.06741108221644329,314.63053471749754,306.43500781275833,3.0011545195597398
6.763432596785877e-05,0.06781436287257452,315.11622252291306,306.43500781275833,3.0011545195597398
6.811314740454643e-05,0.06829445889177836,315.69295603707747,306.43500781275833,3.0011545195597398
6.845789883896154e-05,0.06864012802560512,316.10722554036215,306.43500781275833,3.0011545195597398
6.884095598831166e-05,0.0690242048409682,316.56657190217663,306.43500781275833,3.0011545195597398
6.989436314902449e-05,0.07008041608321665,317.82466298398765,306.43500781275833,3.0011545195597398
7.08328531649323e-05,0.07102140428085618,318.9392922554736,306.43500781275833,3.0011545195597398
7.144574460389249e-05,0.0716359271854371,319.6641058800939,306.43500781275833,3.0011545195597398
7.186710746817762e-05,0.07205841168233647,320.1610091932977,306.43500781275833,3.0011545195597398
7.194371889804764e-05,0.07213522704540909,320.2512330447559,306.43500781275833,3.0011545195597398
7.265237462434537e-05,0.07284576915383077,321.08403490162317,306.43500781275833,3.0011545195597398
7.293966748635796e-05,0.07313382676535307,321.4207540465362,306.43500781275833,3.0011545195597398
7.324611320583805e-05,0.07344108821764353,321.77935152425863,306.43500781275833,3.0011545195597398
7.395476893213578e-05,0.07415163032606521,322.6063746414571,306.43500781275833,3.0011545195597398
7.435697893895341e-05,0.07455491098219644,323.0743911735794,306.43500781275833,3.0011545195597398
7.49698703779136e-05,0.07516943388677735,323.7856651744586,306.43500781275833,3.0011545195597398
7.533377466979623e-05,0.07553430686137227,324.20691118185823,306.43500781275833,3.0011545195597398
7.592751325128892e-05,0.07612962592518505,324.8925075928977,306.43500781275833,3.0011545195597398
7.644464040291158e-05,0.0766481296259252,325.4879381333849,306.43500781275833,3.0011545195597398
7.701922612693676e-05,0.0772242448489698,326.14768826935915,306.43500781275833,3.0011545195597398
7.722990755907934e-05,0.07743548709741949,326.3891153422564,306.43500781275833,3.0011545195597398
7.801517471524709e-05,0.07822284456891379,327.2867259475541,306.43500781275833,3.0011545195597398
7.897281758862239e-05,0.07918303660732147,328.37661836556623,306.43500781275833,3.0011545195597398
7.933672188050501e-05,0.07954790958191639,328.78942448022934,306.43500781275833,3.0011545195597398
7.958570902758258e-05,0.07979755951190239,329.07144538237844,306.43500781275833,3.0011545195597398
8.010283617920525e-05,0.08031606321264254,329.6560839803938,306.43500781275833,3.0011545195597398
8.048589332855536e-05,0.0807001400280056,330.08820104908386,306.43500781275833,3.0011545195597398
8.067742190323044e-05,0.08089217843568715,330.30395875563005,306.43500781275833,3.0011545195597398
8.075403333310046e-05,0.08096899379875976,330.3902058938845,306.43500781275833,3.0011545195597398
8.08689504779055e-05,0.08108421684336868,330.51951679257814,306.43500781275833,3.0011545195597398
8.136692477206065e-05,0.08158351670334067,331.0790379390673,306.43500781275833,3.0011545195597398
8.140523048699566e-05,0.08162192438487698,331.122022632141,306.43500781275833,3.0011545195597398
8.18265933512808e-05,0.08204440888177636,331.5943347998793,306.43500781275833,3.0011545195597398
8.251609622011102e-05,0.08273574714942988,332.36516836267447,306.43500781275833,3.0011545195597398
8.312898765907121e-05,0.0833502700540108,333.0482473993034,306.43500781275833,3.0011545195597398
8.33779748061488e-05,0.08359991998399681,333.3251868850641,306.43500781275833,3.0011545195597398
8.360780909575887e-05,0.08383036607321465,333.5805371966874,306.43500781275833,3.0011545195597398
8.389510195777146e-05,0.08411842368473695,333.8993404400934,306.43500781275833,3.0011545195597398
8.420154767725155e-05,0.0844256851370274,334.23892830099584,306.43500781275833,3.0011545195597398
8.479528625874425e-05,0.08502100420084018,334.895511269588,306.43500781275833,3.0011545195597398
8.558055341491199e-05,0.08580836167233447,335.76114793497663,306.43500781275833,3.0011545195597398
8.594445770679461e-05,0.08617323464692939,336.16124571932,306.43500781275833,3.0011545195597398
8.615513913893718e-05,0.08638447689537908,336.3925792988813,306.43500781275833,3.0011545195597398
8.642327914348226e-05,0.08665333066613323,336.68668502371185,306.43500781275833,3.0011545195597398
8.695955915257243e-05,0.08719103820764153,337.273831016556,306.43500781275833,3.0011545195597398
8.722769915711752e-05,0.08745989197839568,337.5668743296907,306.43500781275833,3.0011545195597398
8.741922773179258e-05,0.08765193038607721,337.7759759287986,306.43500781275833,3.0011545195597398
8.768736773633767e-05,0.08792078415683137,338.06841825359044,306.43500781275833,3.0011545195597398
8.801296631328527e-05,0.08824724944988999,338.4230583397554,306.43500781275833,3.0011545195597398
8.807042488568779e-05,0.08830486097219445,338.48558873330626,306.43500781275833,3.0011545195597398
8.849178774997292e-05,0.08872734546909382,338.94365979198506,306.43500781275833,3.0011545195597398
8.858755203731045e-05,0.08882336467293458,339.04764812439936,306.43500781275833,3.0011545195597398
8.897060918666057e-05,0.08920744148829766,339.46316379363384,306.43500781275833,3.0011545195597398
8.966011205549079e-05,0.08989877975595119,340.2093380524966,306.43500781275833,3.0011545195597398
9.031130920938601e-05,0.09055171034206842,340.91200596911415,306.43500781275833,3.0011545195597398
9.042622635419104e-05,0.09066693338667733,341.03580079234297,306.43500781275833,3.0011545195597398
9.061775492886611e-05,0.09085897179435888,341.2419892380904,306.43500781275833,3.0011545195597398
9.080928350354116e-05,0.09105101020204041,341.44800779274317,306.43500781275833,3.0011545195597398
9.128810494022883e-05,0.09153110622124426,341.96231416691273,306.43500781275833,3.0011545195597398
9.15370920873064e-05,0.09178075615123026,342.22933764116146,306.43500781275833,3.0011545195597398
9.167116208957894e-05,0.09191518303660733,342.37300217684225,306.43500781275833,3.0011545195597398
9.180523209185148e-05,0.0920496099219844,342.5165847926266,306.43500781275833,3.0011545195597398
9.195845495159153e-05,0.09220324064812963,342.68057911381896,306.43500781275833,3.0011545195597398
9.21499835262666e-05,0.09239527905581117,342.88542223205394,306.43500781275833,3.0011545195597398
9.287779211003182e-05,0.093125025005001,343.66231643093977,306.43500781275833,3.0011545195597398
9.316508497204442e-05,0.09341308261652331,343.9683311674397,306.43500781275833,3.0011545195597398
9.345237783405701e-05,0.09370114022804561,344.2739780983736,306.43500781275833,3.0011545195597398
9.400781070061468e-05,0.09425805161032207,344.86385839472945,306.43500781275833,3.0011545195597398
9.414188070288724e-05,0.09439247849569915,345.006039461244,306.43500781275833,3.0011545195597398
9.433340927756229e-05,0.09458451690338068,345.20901836064854,306.43500781275833,3.0011545195597398
9.490799500158747e-05,0.0951606321264253,345.81699289660554,306.43500781275833,3.0011545195597398
9.521444072106758e-05,0.09546789357871575,346.1406589461678,306.43500781275833,3.0011545195597398
9.53102050084051e-05,0.09556391278255652,346.2417212367829,306.43500781275833,3.0011545195597398
9.59230964473653e-05,0.09617843568713744,346.88758465117104,306.43500781275833,3.0011545195597398
9.651683502885799e-05,0.0967737547509502,347.51173183965483,306.43500781275833,3.0011545195597398
9.691904503567561e-05,0.09717703540708142,347.9336906875993,306.43500781275833,3.0011545195597398
9.776177076424589e-05,0.09802200440088019,348.81558685865497,306.43500781275833,3.0011545195597398
9.818313362853102e-05,0.09844448889777956,349.25542277377116,306.43500781275833,3.0011545195597398
9.850873220547862e-05,0.09877095419083817,349.5947919619537,306.43500781275833,3.0011545195597398
9.860449649281615e-05,0.09886697339467894,349.694523137765,306.43500781275833,3.0011545195597398
9.938976364898391e-05,0.09965433086617324,350.5108987764591,306.43500781275833,3.0011545195597398
9.956213936619146e-05,0.09982716543308662,350.68976603780305,306.43500781275833,3.0011545195597398