File: datasets/aisi_316_L/data/M1/train_13.csv
Time(s),Strain(%),Stress(MPa),Temp(C),Log_SR(s-1)
0.0,0.0,0.0,287.82271975126304,4.024939491127563
1.3596370825772221e-09,1.44e-05,2.5731515249999997,287.82271975126304,4.024939491127563
2.2660618042953703e-09,2.4e-05,4.288585875,287.82271975126304,4.024939491127563
3.399092706443055e-09,3.6e-05,6.4328788125,287.82271975126304,4.024939491127563
4.532123608590741e-09,4.8e-05,8.57717175,287.82271975126304,4.024939491127563
8.837641036751943e-09,9.36e-05,16.7254849125,287.82271975126304,4.024939491127563
9.970671938899628e-09,0.00010559999999999999,18.86977785,287.82271975126304,4.024939491127563
1.1481379808429876e-08,0.0001216,21.7288351,287.82271975126304,4.024939491127563
1.2010127562765461e-08,0.0001272,22.7295051375,287.82271975126304,4.024939491127563
1.2841016891007097e-08,0.000136,24.301986625,287.82271975126304,4.024939491127563
1.3520835432295707e-08,0.00014319999999999998,25.588562387499998,287.82271975126304,4.024939491127563
1.5333684875732004e-08,0.0001624,29.0194310875,287.82271975126304,4.024939491127563
1.6995463532215275e-08,0.00017999999999999998,32.164394062499994,287.82271975126304,4.024939491127563
1.9563666910416696e-08,0.0002072,37.0247913875,287.82271975126304,4.024939491127563
2.0923303992993918e-08,0.0002216,39.597942912499995,287.82271975126304,4.024939491127563
2.1754193321235554e-08,0.0002304,41.170424399999995,287.82271975126304,4.024939491127563
2.3113830403812773e-08,0.0002448,43.743575924999995,287.82271975126304,4.024939491127563
2.371811355162487e-08,0.0002512,44.887198825,287.82271975126304,4.024939491127563
2.432239669943697e-08,0.0002576,46.030821724999996,287.82271975126304,4.024939491127563
2.5455427601584656e-08,0.0002696,48.1751146625,287.82271975126304,4.024939491127563
2.636185232330281e-08,0.0002792,49.8905490125,287.82271975126304,4.024939491127563
2.840130794716864e-08,0.0003008,53.750276299999996,287.82271975126304,4.024939491127563
2.8703449521074684e-08,0.00030399999999999996,54.322087749999994,287.82271975126304,4.024939491127563
2.915666188193376e-08,0.00030879999999999997,55.17980492499999,287.82271975126304,4.024939491127563
3.172486526013518e-08,0.000336,60.04020225,287.82271975126304,4.024939491127563
3.240468380142379e-08,0.0003432,61.3267780125,287.82271975126304,4.024939491127563
3.376432088400101e-08,0.00035759999999999996,63.89992953749999,287.82271975126304,4.024939491127563
3.42930686383366e-08,0.0003632,64.900599575,287.82271975126304,4.024939491127563
3.633252426220243e-08,0.0003848,68.7603268625,287.82271975126304,4.024939491127563
3.6710201229584995e-08,0.00038879999999999996,69.47509117499999,287.82271975126304,4.024939491127563
3.8825192246927336e-08,0.00041119999999999997,73.47777132499999,287.82271975126304,4.024939491127563
3.965608157516897e-08,0.00041999999999999996,75.05025281249999,287.82271975126304,4.024939491127563
4.116678944469922e-08,0.00043599999999999997,77.9093100625,287.82271975126304,4.024939491127563
4.192214337946435e-08,0.000444,79.3388386875,287.82271975126304,4.024939491127563
4.305517428161203e-08,0.00045599999999999997,81.483131625,287.82271975126304,4.024939491127563
4.4414811364189254e-08,0.0004704,84.05628315,287.82271975126304,4.024939491127563
4.524570069243089e-08,0.0004792,85.6287646375,287.82271975126304,4.024939491127563
4.562337765981345e-08,0.0004832,86.34352894999999,287.82271975126304,4.024939491127563
4.645426698805508e-08,0.0004919999999999999,87.91601043749999,287.82271975126304,4.024939491127563
4.773836867715579e-08,0.0005055999999999999,90.34620909999998,287.82271975126304,4.024939491127563
4.8342651824967894e-08,0.000512,91.48983199999999,287.82271975126304,4.024939491127563
4.9249076546686047e-08,0.0005216,93.20526635,287.82271975126304,4.024939491127563
4.9626753514068606e-08,0.0005256,93.9200306625,287.82271975126304,4.024939491127563
5.279924004008212e-08,0.0005591999999999999,99.92405088749999,287.82271975126304,4.024939491127563
5.4234412516135854e-08,0.0005744,102.640155275,287.82271975126304,4.024939491127563
5.536744341828354e-08,0.0005863999999999999,104.7844482125,287.82271975126304,4.024939491127563
5.604726195957215e-08,0.0005936,106.071023975,287.82271975126304,4.024939491127563
5.6953686681290306e-08,0.0006032,107.786458325,287.82271975126304,4.024939491127563
5.906867769863264e-08,0.0006255999999999999,111.78913847499999,287.82271975126304,4.024939491127563
5.974849623992126e-08,0.0006328,113.0757142375,287.82271975126304,4.024939491127563
6.027724399425684e-08,0.0006384,114.07638427500001,287.82271975126304,4.024939491127563
6.405401366808246e-08,0.0006784,121.2240274,287.82271975126304,4.024939491127563
6.533811535718317e-08,0.000692,123.6542260625,287.82271975126304,4.024939491127563
6.67732878332369e-08,0.0007072,126.37033045,287.82271975126304,4.024939491127563
6.775524794843156e-08,0.0007176,128.2287176625,287.82271975126304,4.024939491127563
6.987023896577391e-08,0.00074,132.2313978125,287.82271975126304,4.024939491127563
7.085219908096857e-08,0.0007503999999999999,134.089785025,287.82271975126304,4.024939491127563
7.236290695049882e-08,0.0007664,136.948842275,287.82271975126304,4.024939491127563
7.311826088526394e-08,0.0007744,138.3783709,287.82271975126304,4.024939491127563
7.379807942655255e-08,0.0007815999999999999,139.66494666249997,287.82271975126304,4.024939491127563
7.394915021350557e-08,0.0007832,139.9508523875,287.82271975126304,4.024939491127563
7.455343336131768e-08,0.0007896,141.0944752875,287.82271975126304,4.024939491127563
7.59886058373714e-08,0.0008047999999999999,143.81057967499999,287.82271975126304,4.024939491127563
7.727270752647211e-08,0.0008183999999999999,146.2407783375,287.82271975126304,4.024939491127563
7.83302030351433e-08,0.0008296,148.2421184125,287.82271975126304,4.024939491127563
7.991644629815005e-08,0.0008464,151.244128525,287.82271975126304,4.024939491127563
8.218250810244541e-08,0.0008703999999999999,155.53271439999997,287.82271975126304,4.024939491127563
8.32400036111166e-08,0.0008816,157.534054475,287.82271975126304,4.024939491127563
8.565713620236499e-08,0.0009071999999999999,162.108546075,287.82271975126304,4.024939491127563
8.618588395670058e-08,0.0009128,163.10921611249998,287.82271975126304,4.024939491127563
8.731891485884826e-08,0.0009247999999999999,165.25350905,287.82271975126304,4.024939491127563
8.792319800666036e-08,0.0009312,166.39713195,287.82271975126304,4.024939491127563
9.011372441747922e-08,0.0009544,170.5427649625,287.82271975126304,4.024939491127563
9.253085700872761e-08,0.00098,175.1172565625,287.82271975126304,4.024939491127563
9.36638879108753e-08,0.000992,177.2615495,287.82271975126304,4.024939491127563
9.404156487825785e-08,0.000996,177.9763138125,287.82271975126304,4.024939491127563
9.592994971517067e-08,0.001016,181.550135375,287.82271975126304,4.024939491127563
9.74406575847009e-08,0.001032,184.40919262499997,287.82271975126304,4.024939491127563
1.0000886096290233e-07,0.0010592,189.26958994999998,287.82271975126304,4.024939491127563
1.0159510422590908e-07,0.001076,192.2716000625,287.82271975126304,4.024939491127563
1.0280367052153329e-07,0.0010888,194.5588458625,287.82271975126304,4.024939491127563
1.034834890628219e-07,0.001096,195.845421625,287.82271975126304,4.024939491127563
1.0386116603020445e-07,0.0010999999999999998,196.56018593749997,287.82271975126304,4.024939491127563
1.046165199649696e-07,0.001108,197.9897145625,287.82271975126304,4.024939491127563
1.0544740929321123e-07,0.0011168,199.56219605,287.82271975126304,4.024939491127563
1.0635383401492937e-07,0.0011264,201.27763040000002,287.82271975126304,4.024939491127563
1.0710918794969449e-07,0.0011344,202.01101838631158,287.82271975126304,4.024939491127563
1.072602587366475e-07,0.0011359999999999999,202.02097802218506,287.82271975126304,4.024939491127563
1.1005506829527847e-07,0.0011656,202.20425585733292,287.82271975126304,4.024939491127563
1.1164131155828523e-07,0.0011824,202.30747076314296,287.82271975126304,4.024939491127563
1.1194345313219128e-07,0.0011856,202.32706573183268,287.82271975126304,4.024939491127563
1.1360523178867456e-07,0.0012032,202.434471613812,287.82271975126304,4.024939491127563
1.1624897056035248e-07,0.0012312,202.6040903223863,287.82271975126304,4.024939491127563
1.1655111213425853e-07,0.0012343999999999999,202.6233790512426,287.82271975126304,4.024939491127563
1.1700432449511762e-07,0.0012392,202.65227562002386,287.82271975126304,4.024939491127563
1.1783521382335925e-07,0.001248,202.70513954110473,287.82271975126304,4.024939491127563
1.2032788180808416e-07,0.0012744,202.8628658601017,287.82271975126304,4.024939491127563
1.2214073125152046e-07,0.0012936,202.97677662044694,287.82271975126304,4.024939491127563
1.2455786384276885e-07,0.0013192,203.1276371796326,287.82271975126304,4.024939491127563
1.256908947449165e-07,0.0013311999999999998,203.19795962780117,287.82271975126304,4.024939491127563
1.278814211557354e-07,0.0013544,203.33321925351402,287.82271975126304,4.024939491127563
1.3060069532088983e-07,0.0013832,203.49987715913883,287.82271975126304,4.024939491127563
1.3135604925565495e-07,0.0013912,203.545930141473,287.82271975126304,4.024939491127563
1.31658190829561e-07,0.0013943999999999998,203.56432240166802,287.82271975126304,4.024939491127563
1.334710402729973e-07,0.0014135999999999999,203.67433225331868,287.82271975126304,4.024939491127563
1.3573710207729268e-07,0.0014376,203.81102850688316,287.82271975126304,4.024939491127563
1.37701022307682e-07,0.0014583999999999999,203.92878023996673,287.82271975126304,4.024939491127563
1.3913619478373574e-07,0.0014736,204.01441578810602,287.82271975126304,4.024939491127563
1.403447610793599e-07,0.0014864,204.08626306661654,287.82271975126304,4.024939491127563
1.4117565040760154e-07,0.0014952,204.1355181594551,287.82271975126304,4.024939491127563
1.421576105227962e-07,0.0015056,204.19358320176042,287.82271975126304,4.024939491127563
1.4412153075318555e-07,0.0015264,204.30924612941422,287.82271975126304,4.024939491127563
1.4676526952486346e-07,0.0015543999999999998,204.46398017893821,287.82271975126304,4.024939491127563
1.4767169424658162e-07,0.0015639999999999999,204.5167811099813,287.82271975126304,4.024939491127563
1.481249066074407e-07,0.0015688,204.54313416533665,287.82271975126304,4.024939491127563
1.49937756050877e-07,0.001588,204.64823343784693,287.82271975126304,4.024939491127563
1.5144846392040724e-07,0.001604,204.73543812541004,287.82271975126304,4.024939491127563
1.525814948225549e-07,0.001616,204.8006191806561,287.82271975126304,4.024939491127563
1.5530076898770934e-07,0.0016447999999999999,204.95628831543164,287.82271975126304,4.024939491127563
1.5771790157895773e-07,0.0016703999999999998,205.09377064901432,287.82271975126304,4.024939491127563
1.59228609448488e-07,0.0016864,205.1792799445067,287.82271975126304,4.024939491127563
1.597573572028236e-07,0.001692,205.20913337229422,287.82271975126304,4.024939491127563
1.616457420397364e-07,0.001712,205.31543962543128,287.82271975126304,4.024939491127563
1.6353412687664918e-07,0.0017319999999999998,205.42126262789418,287.82271975126304,4.024939491127563
1.6625340104180364e-07,0.0017607999999999999,205.5728143206477,287.82271975126304,4.024939491127563
1.6927481678086414e-07,0.0017928,205.74007575443423,287.82271975126304,4.024939491127563
1.7101213083082393e-07,0.0018112,205.8357238146612,287.82271975126304,4.024939491127563
1.7237176791340116e-07,0.0018256,205.9103147271882,287.82271975126304,4.024939491127563
1.7305158645468976e-07,0.0018327999999999999,205.94752411039389,287.82271975126304,4.024939491127563
1.7342926342207232e-07,0.0018368,205.96817135583888,287.82271975126304,4.024939491127563
1.788678117523812e-07,0.0018943999999999999,206.26357394341943,287.82271975126304,4.024939491127563
1.818892274914417e-07,0.0019264,206.42617221992157,287.82271975126304,4.024939491127563
1.8407975390226055e-07,0.0019496,206.5433979934499,287.82271975126304,4.024939491127563
1.8513724941093174e-07,0.0019608,206.59979492413714,287.82271975126304,4.024939491127563
1.854393909848378e-07,0.001964,206.61588523940154,287.82271975126304,4.024939491127563
1.867234926739385e-07,0.0019776,206.68415532815158,287.82271975126304,4.024939491127563
1.8687456346089152e-07,0.0019792,206.69217504761548,287.82271975126304,4.024939491127563
1.8876294829780432e-07,0.0019992,206.79220914997575,287.82271975126304,4.024939491127563
1.8921616065866337e-07,0.0020039999999999997,206.81615916761422,287.82271975126304,4.024939491127563
1.9065133313471714e-07,0.0020192,206.8918537158507,287.82271975126304,4.024939491127563
1.9193543482381786e-07,0.0020328,206.95939225399894,287.82271975126304,4.024939491127563
1.9284185954553598e-07,0.0020423999999999998,207.00696045808425,287.82271975126304,4.024939491127563
1.9533452753026092e-07,0.0020688,207.1373255079855,287.82271975126304,4.024939491127563
1.9744951854760326e-07,0.0020912,207.24743028031048,287.82271975126304,4.024939491127563
1.9812933708889184e-07,0.0020984,207.2827232903526,287.82271975126304,4.024939491127563
2.0054646968014025e-07,0.002124,207.40782885817637,287.82271975126304,4.024939491127563
2.0303913766486513e-07,0.0021504,207.53622958940036,287.82271975126304,4.024939491127563
2.0522966407568403e-07,0.0021736,207.64855993197452,287.82271975126304,4.024939491127563
2.0538073486263703e-07,0.0021752,207.65628957245252,287.82271975126304,4.024939491127563
2.0726911969954986e-07,0.0021952,207.75272374101044,287.82271975126304,4.024939491127563
2.077223320604089e-07,0.0021999999999999997,207.7758168816198,287.82271975126304,4.024939491127563
2.0908196914298616e-07,0.0022144,207.84497868984928,287.82271975126304,4.024939491127563
2.1293427421028824e-07,0.0022551999999999997,208.03999100678263,287.82271975126304,4.024939491127563
2.1580461916239576e-07,0.0022856,208.1844009518247,287.82271975126304,4.024939491127563
2.1693765006454342e-07,0.0022976,208.24119843159943,287.82271975126304,4.024939491127563
2.1799514557321458e-07,0.0023087999999999997,208.29410512240398,287.82271975126304,4.024939491127563
2.2063888434489254e-07,0.0023368,208.42593581564117,287.82271975126304,4.024939491127563
2.2192298603399323e-07,0.0023504,208.48974546611112,287.82271975126304,4.024939491127563
2.2366030008395302e-07,0.0023688,208.57584744563817,287.82271975126304,4.024939491127563
2.2449118941219463e-07,0.0023775999999999997,208.61693441444856,287.82271975126304,4.024939491127563
2.2562422031434236e-07,0.0023896,208.67286664840364,287.82271975126304,4.024939491127563
2.2743706975777864e-07,0.0024088,208.76213091234055,287.82271975126304,4.024939491127563
2.2781474672516122e-07,0.0024128,208.78069265916972,287.82271975126304,4.024939491127563
2.289477776273089e-07,0.0024248,208.83630602637166,287.82271975126304,4.024939491127563
2.3076062707074518e-07,0.002444,208.9250646727537,287.82271975126304,4.024939491127563
2.334043658424231e-07,0.002472,209.0540184475325,287.82271975126304,4.024939491127563
2.346129321380473e-07,0.0024847999999999997,209.1127788921089,287.82271975126304,4.024939491127563
2.3529275067933592e-07,0.002492,209.14577976225553,287.82271975126304,4.024939491127563
2.3627471079453056e-07,0.0025023999999999997,209.19338211300337,287.82271975126304,4.024939491127563
2.3665238776191315e-07,0.0025063999999999998,209.21167015721983,287.82271975126304,4.024939491127563
2.389184495662085e-07,0.0025304,209.3211603406304,287.82271975126304,4.024939491127563
2.409579051900744e-07,0.002552,209.41935570760467,287.82271975126304,4.024939491127563
2.423930776661281e-07,0.0025672,209.48826193961818,287.82271975126304,4.024939491127563
2.4299736081394016e-07,0.0025735999999999997,209.51722746730184,287.82271975126304,4.024939491127563
2.442059271095644e-07,0.0025864,209.57507438374023,287.82271975126304,4.024939491127563
2.45036816437806e-07,0.0025951999999999998,209.6147793888894,287.82271975126304,4.024939491127563
2.461698473399537e-07,0.0026072,209.6688380620472,287.82271975126304,4.024939491127563
2.4904019229206116e-07,0.0026376,209.8053542034608,287.82271975126304,4.024939491127563
2.4972001083334974e-07,0.0026447999999999997,209.83759692960663,287.82271975126304,4.024939491127563
2.5153286027678604e-07,0.0026639999999999997,209.92341061345996,287.82271975126304,4.024939491127563
2.519105372441686e-07,0.002668,209.9412580663656,287.82271975126304,4.024939491127563
2.5455427601584657e-07,0.002696,210.06589933671071,287.82271975126304,4.024939491127563
2.550074883767056e-07,0.0027007999999999997,210.087215620243,287.82271975126304,4.024939491127563
2.5757569175490704e-07,0.002728,210.20772997412075,287.82271975126304,4.024939491127563
2.5938854119834335e-07,0.0027472,210.29251694153731,287.82271975126304,4.024939491127563
2.6301424008521596e-07,0.0027856,210.46140072963078,287.82271975126304,4.024939491127563
2.6422280638084013e-07,0.0027984,210.51749323681102,287.82271975126304,4.024939491127563
2.658090496438469e-07,0.0028152,210.59096303527434,287.82271975126304,4.024939491127563
2.666399389720885e-07,0.0028239999999999997,210.62937896336612,287.82271975126304,4.024939491127563
2.6988796089157857e-07,0.0028583999999999997,210.7791044950958,287.82271975126304,4.024939491127563
2.7260723505673303e-07,0.0028872,210.90391641351354,287.82271975126304,4.024939491127563
2.7283384123716255e-07,0.0028896,210.91429543892224,287.82271975126304,4.024939491127563
2.733625889914981e-07,0.0028951999999999997,210.93850009933735,287.82271975126304,4.024939491127563
2.747977614675519e-07,0.0029104,211.00410659943523,287.82271975126304,4.024939491127563
2.75553115402317e-07,0.0029184,211.03858265539932,287.82271975126304,4.024939491127563
2.763840047305586e-07,0.0029272,211.0764637744804,287.82271975126304,4.024939491127563
2.7668614630446464e-07,0.0029303999999999997,211.0902277118782,287.82271975126304,4.024939491127563
2.778947126000889e-07,0.0029432,211.1452249447454,287.82271975126304,4.024939491127563
2.780457833870419e-07,0.0029448,211.1520930339802,287.82271975126304,4.024939491127563
2.793298850761426e-07,0.0029584,211.21041314993633,287.82271975126304,4.024939491127563
2.806139867652433e-07,0.002972,211.26862879926608,287.82271975126304,4.024939491127563
2.823513008152031e-07,0.0029904,211.34722604919895,287.82271975126304,4.024939491127563
2.84843968799928e-07,0.0030168,211.45966737434682,287.82271975126304,4.024939491127563
2.859014643085992e-07,0.003028,211.50725374558644,287.82271975126304,4.024939491127563
2.8695895981727033e-07,0.0030391999999999997,211.5547715210578,287.82271975126304,4.024939491127563
2.888473446541832e-07,0.0030591999999999998,211.63945517723002,287.82271975126304,4.024939491127563
2.9126447724543157e-07,0.0030848,211.74753585561365,287.82271975126304,4.024939491127563
2.9300179129539133e-07,0.0031032,211.82500289117874,287.82271975126304,4.024939491127563
2.9511678231273365e-07,0.0031255999999999996,211.91906922137233,287.82271975126304,4.024939491127563
2.9655195478878745e-07,0.0031408,211.98275026038192,287.82271975126304,4.024939491127563
3.0138621997128423e-07,0.003192,212.19637599083808,287.82271975126304,4.024939491127563
3.0297246323429096e-07,0.0032088,212.2661801946333,287.82271975126304,4.024939491127563
3.036522817755796e-07,0.0032159999999999997,212.2960526336227,287.82271975126304,4.024939491127563
3.052385250385863e-07,0.0032327999999999996,212.3656537426899,287.82271975126304,4.024939491127563
3.0584280818639845e-07,0.0032392,212.39213132825202,287.82271975126304,4.024939491127563
3.069003036950696e-07,0.0032503999999999996,212.43841806176195,287.82271975126304,4.024939491127563
3.0720244526897566e-07,0.0032535999999999997,212.45163141259408,287.82271975126304,4.024939491127563
3.087886885319824e-07,0.0032703999999999997,212.52091852890564,287.82271975126304,4.024939491127563
3.110547503362778e-07,0.0032944,212.61965981224222,287.82271975126304,4.024939491127563
3.121122458449489e-07,0.0033055999999999997,212.6656430330078,287.82271975126304,4.024939491127563
3.1301867056666713e-07,0.0033152,212.70500888168976,287.82271975126304,4.024939491127563
3.1505812619053296e-07,0.0033368,212.7934198561167,287.82271975126304,4.024939491127563
3.15209196977486e-07,0.0033384,212.7999599246739,287.82271975126304,4.024939491127563
3.158134801252981e-07,0.0033447999999999998,212.82610798375106,287.82271975126304,4.024939491127563
3.1755079417525784e-07,0.0033632,212.9011751831144,287.82271975126304,4.024939491127563
3.179284711426404e-07,0.0033672,212.9174729255367,287.82271975126304,4.024939491127563
3.192125728317411e-07,0.0033807999999999998,212.97282885854293,287.82271975126304,4.024939491127563
3.204211391273653e-07,0.0033935999999999997,213.0248492803914,287.82271975126304,4.024939491127563
3.214786346360365e-07,0.0034048,213.0703044096346,287.82271975126304,4.024939491127563
3.222339885708016e-07,0.0034127999999999997,213.1027366638548,287.82271975126304,4.024939491127563
3.2382023183380837e-07,0.0034295999999999997,213.17074804672075,287.82271975126304,4.024939491127563
3.2487772734247956e-07,0.0034408,213.21601679897833,287.82271975126304,4.024939491127563
3.266150413924393e-07,0.0034592,213.29026233427572,287.82271975126304,4.024939491127563
3.2888110319673467e-07,0.0034831999999999997,213.3868732814593,287.82271975126304,4.024939491127563
3.2986306331192937e-07,0.0034936,213.4286573635404,287.82271975126304,4.024939491127563
3.3099609421407705e-07,0.0035055999999999998,213.47680953426777,287.82271975126304,4.024939491127563
3.353771470357148e-07,0.003552,213.66239622039114,287.82271975126304,4.024939491127563
3.3628357175743293e-07,0.0035616,213.70067515207214,287.82271975126304,4.024939491127563
3.3703892569219805e-07,0.0035696,213.73254353316582,287.82271975126304,4.024939491127563
3.3900284592258734e-07,0.0035903999999999997,213.81527123760802,287.82271975126304,4.024939491127563
3.3922945210301686e-07,0.0035927999999999997,213.82480469935692,287.82271975126304,4.024939491127563
3.3953159367692293e-07,0.003596,213.83751211910743,287.82271975126304,4.024939491127563
3.4104230154645317e-07,0.0036119999999999998,213.90098318603478,287.82271975126304,4.024939491127563
3.4361050492465464e-07,0.0036392,214.0086329266171,287.82271975126304,4.024939491127563
3.478404869593393e-07,0.0036839999999999998,214.18525684672,287.82271975126304,4.024939491127563
3.501820841571112e-07,0.0037088,214.2826705413429,287.82271975126304,4.024939491127563
3.5108850887882934e-07,0.0037183999999999997,214.32031082506882,287.82271975126304,4.024939491127563
3.51919398207071e-07,0.0037272,214.3547811382912,287.82271975126304,4.024939491127563
3.532790352896482e-07,0.0037416,214.4111187199248,287.82271975126304,4.024939491127563
3.544120661917959e-07,0.0037535999999999997,214.4580021388497,287.82271975126304,4.024939491127563
3.5849097743952754e-07,0.0037968,214.62630059538472,287.82271975126304,4.024939491127563
3.6037936227644034e-07,0.0038168,214.70396348235872,287.82271975126304,4.024939491127563
3.622677471133532e-07,0.0038368,214.7814678189055,287.82271975126304,4.024939491127563
3.6408059655678944e-07,0.0038559999999999996,214.85572388318445,287.82271975126304,4.024939491127563
3.662711229676083e-07,0.0038791999999999997,214.9452578488007,287.82271975126304,4.024939491127563
3.6657326454151437e-07,0.0038824,214.95759095243264,287.82271975126304,4.024939491127563
3.6770629544366205e-07,0.0038943999999999997,215.00380482504212,287.82271975126304,4.024939491127563
3.680839724110446e-07,0.0038983999999999998,215.01919710348187,287.82271975126304,4.024939491127563
3.683861139849507e-07,0.0039016,215.03150649190297,287.82271975126304,4.024939491127563
3.6982128646100437e-07,0.0039168,215.08992240196193,287.82271975126304,4.024939491127563
3.70652175789246e-07,0.0039256,215.12370172966553,287.82271975126304,4.024939491127563
3.717096712979172e-07,0.0039368,215.16665092047478,287.82271975126304,4.024939491127563
3.7216288365877627e-07,0.0039416,215.18504312584022,287.82271975126304,4.024939491127563
3.7254056062615883e-07,0.0039456,215.20036329196626,287.82271975126304,4.024939491127563
3.740512684956891e-07,0.0039616,215.26158348113142,287.82271975126304,4.024939491127563
3.7503322861088376e-07,0.003972,215.30132490066939,287.82271975126304,4.024939491127563
3.759396533326019e-07,0.0039816,215.33797328350212,287.82271975126304,4.024939491127563
3.767705426608435e-07,0.0039904,215.3715373724224,287.82271975126304,4.024939491127563
4.066883607562172e-07,0.004307261452290458,216.56151094378058,287.82271975126304,4.024939491127563
4.17567633271338e-07,0.00442248449689938,216.98569949519003,287.82271975126304,4.024939491127563
4.3026011787231227e-07,0.004556911382276456,217.47517610212796,287.82271975126304,4.024939491127563
4.71963995846942e-07,0.004998599719943989,219.04519250867764,287.82271975126304,4.024939491127563
4.955357529630371e-07,0.0052482496499299865,219.9086240187399,287.82271975126304,4.024939491127563
5.027886013064509e-07,0.005325065013002601,220.17105263686338,287.82271975126304,4.024939491127563
5.390528430235202e-07,0.005709141828365673,221.4616774264338,287.82271975126304,4.024939491127563
6.206473868869263e-07,0.006573314662932587,224.2476532532082,287.82271975126304,4.024939491127563
6.605380527757025e-07,0.006995799159831967,225.55730894986453,287.82271975126304,4.024939491127563
7.058683549220392e-07,0.007475895179035807,227.00865887308817,287.82271975126304,4.024939491127563
7.312533241239877e-07,0.007744748949789958,227.8055204376281,287.82271975126304,4.024939491127563
8.182875042449541e-07,0.008666533306661332,230.45921582726913,287.82271975126304,4.024939491127563
8.400460492751958e-07,0.008896979395879176,231.10513926885199,287.82271975126304,4.024939491127563
8.527385338761701e-07,0.009031406281256251,231.47891462660675,287.82271975126304,4.024939491127563
8.871895635073859e-07,0.00939627925585117,232.4826676349749,287.82271975126304,4.024939491127563
9.270802293961621e-07,0.00981876375275055,233.62610664606817,287.82271975126304,4.024939491127563
9.34333077739576e-07,0.009895579115823165,233.83192636004827,287.82271975126304,4.024939491127563
9.452123502546969e-07,0.010010802160432087,234.1394914527642,287.82271975126304,4.024939491127563
9.579048348556711e-07,0.010145229045809162,234.49657785211605,287.82271975126304,4.024939491127563
9.92355864486887e-07,0.010510102020404082,235.4566299179415,287.82271975126304,4.024939491127563
1.0141144095171287e-06,0.010740548109621925,236.05628590862273,287.82271975126304,4.024939491127563
1.070323984178586e-06,0.011335867173434686,237.58261991652395,287.82271975126304,4.024939491127563
1.1084014379815088e-06,0.011739147829565914,238.59886249431176,287.82271975126304,4.024939491127563
1.1337864071834574e-06,0.012008001600320064,239.2688027406649,287.82271975126304,4.024939491127563
1.1664242247288197e-06,0.012353670734146829,240.1216202726612,287.82271975126304,4.024939491127563
1.2407659202488118e-06,0.013141028205641128,242.03014293071618,287.82271975126304,4.024939491127563
1.284283010309295e-06,0.013601920384076815,243.12662808747848,287.82271975126304,4.024939491127563
1.2933490707385624e-06,0.013697939587917584,243.3532278281911,287.82271975126304,4.024939491127563
1.3368661607990457e-06,0.014158831766353271,244.4323993153035,287.82271975126304,4.024939491127563
1.3549982816575804e-06,0.014350870174034807,244.878000276309,287.82271975126304,4.024939491127563
1.427526765091719e-06,0.015119023804760953,246.6376267854851,287.82271975126304,4.024939491127563
1.4764834914097627e-06,0.0156375275055011,247.8057017640671,287.82271975126304,4.024939491127563
1.5054948847834181e-06,0.01594478895779156,248.49076715313709,287.82271975126304,4.024939491127563
1.520000581470246e-06,0.01609841968393679,248.83136769326322,287.82271975126304,4.024939491127563
1.5290666418995133e-06,0.01619443888777756,249.04359941745852,287.82271975126304,4.024939491127563
1.5653308836165824e-06,0.016578515703140628,249.88766420900114,287.82271975126304,4.024939491127563
1.607034761591212e-06,0.01702020404080816,250.84896707154456,287.82271975126304,4.024939491127563
1.6795632450253506e-06,0.017788357671534305,252.49793806194353,287.82271975126304,4.024939491127563
1.706761426313153e-06,0.01807641528305661,253.10911184902332,287.82271975126304,4.024939491127563
1.7321463955151014e-06,0.018345269053810762,253.67612253800624,287.82271975126304,4.024939491127563
1.7557181526311966e-06,0.01859491898379676,254.19973741493018,287.82271975126304,4.024939491127563
1.7720370614038776e-06,0.018767753550710142,254.56063505104154,287.82271975126304,4.024939491127563
1.7865427580907054e-06,0.01892138427685537,254.88034621553794,287.82271975126304,4.024939491127563
1.8264334239794818e-06,0.01934386877375475,255.75437383517962,287.82271975126304,4.024939491127563
1.9461054216458105e-06,0.02061132226445289,258.33283957087497,287.82271975126304,4.024939491127563
2.056711358882872e-06,0.02178275655131026,260.6614790509433,287.82271975126304,4.024939491127563
2.1129209335443294e-06,0.022378075615123026,261.82612998824357,287.82271975126304,4.024939491127563
2.161877659862373e-06,0.022896579315863173,262.8306923103894,287.82271975126304,4.024939491127563
2.2217136586955378e-06,0.023530306061212244,264.0465216227997,287.82271975126304,4.024939491127563
2.236219355382365e-06,0.02368393678735747,264.3393366786576,287.82271975126304,4.024939491127563
2.2652307487560206e-06,0.02399119823964793,264.9227538960438,287.82271975126304,4.024939491127563
2.274296809185288e-06,0.024087217443488698,265.1044732087338,287.82271975126304,4.024939491127563
2.3141874750740643e-06,0.024509701940388078,265.90070537902204,287.82271975126304,4.024939491127563
2.3740234739072286e-06,0.025143428685737147,267.0850896371334,287.82271975126304,4.024939491127563
2.417540563967712e-06,0.025604320864172834,267.9391595315931,287.82271975126304,4.024939491127563
2.4773765628008765e-06,0.026238047609521906,269.1037794150631,287.82271975126304,4.024939491127563
2.5208936528613594e-06,0.026698939787957593,269.943896084271,287.82271975126304,4.024939491127563
2.6206203175833e-06,0.02775515103020604,271.8481157094971,287.82271975126304,4.024939491127563
2.635126014270128e-06,0.02790878175635127,272.12272040079773,287.82271975126304,4.024939491127563
2.6478184988711025e-06,0.028043208641728348,272.36251626482067,287.82271975126304,4.024939491127563
2.689522376845732e-06,0.02848489697939588,273.147279385972,287.82271975126304,4.024939491127563
2.729413042734508e-06,0.02890738147629526,273.8934934631866,287.82271975126304,4.024939491127563
2.763864072365724e-06,0.029272254450890177,274.5345346547689,287.82271975126304,4.024939491127563
2.8273264953705952e-06,0.029944388877775556,275.70730102998715,287.82271975126304,4.024939491127563
2.896228554633027e-06,0.030674134826965394,276.9690259396494,287.82271975126304,4.024939491127563
2.9143606754915618e-06,0.03086617323464693,277.29910623163414,287.82271975126304,4.024939491127563
2.9433720688652174e-06,0.03117343468693739,277.8255736514034,287.82271975126304,4.024939491127563
2.97600988641058e-06,0.03151910382076416,278.41543643619514,287.82271975126304,4.024939491127563
3.0195269764710635e-06,0.031979995999199845,279.19801048056553,287.82271975126304,4.024939491127563
3.0902422478193482e-06,0.03272894578915783,280.46037642557604,287.82271975126304,4.024939491127563
3.1537046708242196e-06,0.03340108021604321,281.5837083202125,287.82271975126304,4.024939491127563
3.1881557004554357e-06,0.03376595319063813,282.1898237447576,287.82271975126304,4.024939491127563
3.2498049113744533e-06,0.03441888377675535,283.2681141806219,287.82271975126304,4.024939491127563
3.29513521352079e-06,0.03489897979595919,284.055892015963,287.82271975126304,4.024939491127563
3.318706970636885e-06,0.035148629725945194,284.4638655013408,287.82271975126304,4.024939491127563
3.4057411507578516e-06,0.03607041408281657,285.96053807176855,287.82271975126304,4.024939491127563
3.4293129078739464e-06,0.036320064012802564,286.3633103187852,287.82271975126304,4.024939491127563
3.503654603393938e-06,0.037107421484296854,287.62657680620214,287.82271975126304,4.024939491127563
3.541732057196862e-06,0.03751070214042809,288.2695644644398,287.82271975126304,4.024939491127563
3.592501995600758e-06,0.03804840968193639,289.1227031425508,287.82271975126304,4.024939491127563
3.6414587219188023e-06,0.03856691338267654,289.9409304042818,287.82271975126304,4.024939491127563
3.690415448236846e-06,0.03908541708341669,290.7548785598427,287.82271975126304,4.024939491127563
3.710360781181234e-06,0.03929665933186638,291.08527846543217,287.82271975126304,4.024939491127563
3.7248664778680618e-06,0.03945029005801161,291.3251343958081,287.82271975126304,4.024939491127563
3.768383567928545e-06,0.039911182236447296,292.0425259480257,287.82271975126304,4.024939491127563
3.779262840443665e-06,0.04002640528105621,292.2213681093761,287.82271975126304,4.024939491127563
3.806461021731468e-06,0.04031446289257852,292.6675973268643,287.82271975126304,4.024939491127563
3.8155270821607354e-06,0.04041048209641929,292.8160638426953,287.82271975126304,4.024939491127563
3.828219566761709e-06,0.04054490898179636,293.0236860377918,287.82271975126304,4.024939491127563
3.8427252634485365e-06,0.040698539707941586,293.2606400970849,287.82271975126304,4.024939491127563
3.878989505165607e-06,0.041082616523304666,293.85150416136474,287.82271975126304,4.024939491127563
3.9279462314836505e-06,0.041601120224044816,294.6457646385341,287.82271975126304,4.024939491127563
3.944265140256331e-06,0.04177395479095819,294.90965894949005,287.82271975126304,4.024939491127563
4.009540775347056e-06,0.04246529305861173,295.9610057046765,287.82271975126304,4.024939491127563
4.043991804978272e-06,0.04283016603320665,296.51319082057256,287.82271975126304,4.024939491127563
4.11108065215485e-06,0.04354070814162833,297.58326185702384,287.82271975126304,4.024939491127563
4.143718469700212e-06,0.043886377275455093,298.1013726755434,287.82271975126304,4.024939491127563
4.15822416638704e-06,0.04404000800160032,298.33113303058366,287.82271975126304,4.024939491127563
4.201741256447524e-06,0.04450090018003601,299.018545867755,287.82271975126304,4.024939491127563
4.248884770679713e-06,0.045000200040008,299.76011729092517,287.82271975126304,4.024939491127563
4.272456527795808e-06,0.045249849969994,300.1296991357605,287.82271975126304,4.024939491127563
4.283335800310929e-06,0.04536507301460292,300.30000707865076,287.82271975126304,4.024939491127563
4.339545374972386e-06,0.04596039207841568,301.1772583484381,287.82271975126304,4.024939491127563
4.381249252947017e-06,0.04640208041608322,301.8252612509993,287.82271975126304,4.024939491127563
4.392128525462137e-06,0.04651730346069213,301.99390930246227,287.82271975126304,4.024939491127563
4.4066342221489644e-06,0.04667093418683736,302.21852016087377,287.82271975126304,4.024939491127563
4.4410852517801806e-06,0.04703580716143228,302.7508184280922,287.82271975126304,4.024939491127563
4.544438340673829e-06,0.048130426085217046,304.3381337427852,287.82271975126304,4.024939491127563
4.577076158219191e-06,0.04847609521904381,304.83645794110924,287.82271975126304,4.024939491127563
4.665923550426011e-06,0.04941708341668334,306.18603516490083,287.82271975126304,4.024939491127563
4.684055671284545e-06,0.049609121824364874,306.4602235644703,287.82271975126304,4.024939491127563
4.6913085196279584e-06,0.04968593718743748,306.5697829829186,287.82271975126304,4.024939491127563
4.705814216314786e-06,0.04983956791358271,306.78870384550675,287.82271975126304,4.024939491127563
4.7203199130016145e-06,0.04999319863972794,307.00736168409946,287.82271975126304,4.024939491127563
4.774716275577218e-06,0.05056931386277255,307.82500509253896,287.82271975126304,4.024939491127563
4.823673001895262e-06,0.0510878175635127,308.55778323346107,287.82271975126304,4.024939491127563
4.841805122753796e-06,0.051279855971194235,308.82844575003213,287.82271975126304,4.024939491127563
4.887135424900133e-06,0.05175995199039808,309.50337830580844,287.82271975126304,4.024939491127563
4.901641121586962e-06,0.05191358271654331,309.7188404970467,287.82271975126304,4.024939491127563
4.912520394102083e-06,0.052028805761152236,309.8802739852873,287.82271975126304,4.024939491127563
4.950597847905006e-06,0.05243208641728346,310.44419646463285,287.82271975126304,4.024939491127563
4.9741696050211e-06,0.052681736347269456,310.79244373584726,287.82271975126304,4.024939491127563
5.008620634652316e-06,0.05304660932186438,311.3002650094199,287.82271975126304,4.024939491127563
5.032192391768411e-06,0.05329625925185037,311.64693702558947,287.82271975126304,4.024939491127563
5.059390573056213e-06,0.05358431686337267,312.04615721826474,287.82271975126304,4.024939491127563
5.102907663116696e-06,0.05404520904180836,312.6831729928736,287.82271975126304,4.024939491127563
5.155490813606446e-06,0.05460212042408481,313.4500806597646,287.82271975126304,4.024939491127563
5.202634327838638e-06,0.05510142028405682,314.1350633419704,287.82271975126304,4.024939491127563
5.208073964096197e-06,0.05515903180636127,314.21394372994115,287.82271975126304,4.024939491127563
5.215326812439611e-06,0.05523584716943389,314.3190676169911,287.82271975126304,4.024939491127563
5.238898569555706e-06,0.055485497099419884,314.6603271622632,287.82271975126304,4.024939491127563
5.284228871702043e-06,0.05596559311862373,315.31491711336014,287.82271975126304,4.024939491127563
5.309613840903991e-06,0.05623444688937787,315.68053081999483,287.82271975126304,4.024939491127563
5.338625234277646e-06,0.05654170834166833,316.09754134406967,287.82271975126304,4.024939491127563
5.38214232433813e-06,0.057002600520104016,316.7214038364261,287.82271975126304,4.024939491127563
5.393021596853251e-06,0.05711782356471294,316.87706169656633,287.82271975126304,4.024939491127563
5.400274445196665e-06,0.05719463892778556,316.98076557409644,287.82271975126304,4.024939491127563
5.427472626484467e-06,0.05748269653930786,317.36917228725355,287.82271975126304,4.024939491127563
5.469176504459096e-06,0.05792438487697539,317.9632581729671,287.82271975126304,4.024939491127563
5.516320018691287e-06,0.058423684736947396,318.63271021712666,287.82271975126304,4.024939491127563
5.56527674500933e-06,0.05894218843768753,319.3255529994789,287.82271975126304,4.024939491127563
5.576156017524451e-06,0.05905741148229646,319.4791947906727,287.82271975126304,4.024939491127563
5.587035290039572e-06,0.05917263452690538,319.63271971967686,287.82271975126304,4.024939491127563
5.652310925130296e-06,0.059863972794558906,320.5514327919208,287.82271975126304,4.024939491127563
5.666816621817124e-06,0.060017603520704135,320.7550282476943,287.82271975126304,4.024939491127563
5.741158317337116e-06,0.06080496099219844,321.79528194045037,287.82271975126304,4.024939491127563
5.793741467826867e-06,0.06136187237447489,322.52790148792155,287.82271975126304,4.024939491127563
5.806433952427842e-06,0.06149629925985198,322.704351621199,287.82271975126304,4.024939491127563
5.880775647947833e-06,0.06228365673134627,323.73484047938024,287.82271975126304,4.024939491127563
5.897094556720515e-06,0.062456491298259656,323.9603638883877,287.82271975126304,4.024939491127563
5.927919162180023e-06,0.06278295659131826,324.3856895870893,287.82271975126304,4.024939491127563
5.951490919296118e-06,0.06303260652130425,324.7103569149314,287.82271975126304,4.024939491127563
6.002260857700016e-06,0.06357031406281256,325.40794197201063,287.82271975126304,4.024939491127563
6.036711887331232e-06,0.06393518703740748,325.87999319263366,287.82271975126304,4.024939491127563
6.105613946593664e-06,0.06466493298659733,326.82095545603266,287.82271975126304,4.024939491127563
6.1563838849975605e-06,0.06520264052810562,327.51164821538913,287.82271975126304,4.024939491127563
6.167263157512681e-06,0.06531786357271455,327.65936439053445,287.82271975126304,4.024939491127563
6.237978428860966e-06,0.06606681336267253,328.6170543289146,287.82271975126304,4.024939491127563
6.2561105497195004e-06,0.06625885177035407,328.86193266840104,287.82271975126304,4.024939491127563
6.270616246406328e-06,0.0664124824964993,329.0576361060015,287.82271975126304,4.024939491127563
6.375782547385831e-06,0.06752630526105222,330.47124317289484,287.82271975126304,4.024939491127563
6.397541092416072e-06,0.06775675135027005,330.7625749872204,287.82271975126304,4.024939491127563
6.433805334133141e-06,0.06814082816563313,331.24727074662155,287.82271975126304,4.024939491127563
6.511773453824841e-06,0.06896659331866374,332.2857733405557,287.82271975126304,4.024939491127563
6.52265272633996e-06,0.06908181636327265,332.43029419183244,287.82271975126304,4.024939491127563
6.544411271370203e-06,0.0693122624524905,332.71905417555246,287.82271975126304,4.024939491127563
6.569796240572151e-06,0.06958111622324466,333.0554680227112,287.82271975126304,4.024939491127563
6.5988076339458075e-06,0.06988837767553512,333.4393208623859,287.82271975126304,4.024939491127563
6.68946823823848e-06,0.0708485697139428,334.634640745773,287.82271975126304,4.024939491127563
6.780128842531153e-06,0.07180876175235047,335.8236591229299,287.82271975126304,4.024939491127563
6.805513811733102e-06,0.07207761552310463,336.1554710406721,287.82271975126304,4.024939491127563
6.852657325965292e-06,0.07257691538307662,336.77041537104463,287.82271975126304,4.024939491127563
6.8943612039399215e-06,0.07301860372074415,337.3130305719278,287.82271975126304,4.024939491127563
6.921559385227724e-06,0.07330666133226646,337.6662205395693,287.82271975126304,4.024939491127563
6.95601041485894e-06,0.07367153430686138,338.1128184530491,287.82271975126304,4.024939491127563
7.014033201606251e-06,0.0742860572114423,338.86303840317805,287.82271975126304,4.024939491127563
7.073869200439415e-06,0.07491978395679136,339.63417205918324,287.82271975126304,4.024939491127563
7.101067381727217e-06,0.07520784156831367,339.9838459820983,287.82271975126304,4.024939491127563
7.164529804732089e-06,0.07587997599519905,340.7977268108117,287.82271975126304,4.024939491127563
7.175409077247209e-06,0.07599519903980796,340.93696645560755,287.82271975126304,4.024939491127563
7.260630045282323e-06,0.07689777955591119,342.0248428836838,287.82271975126304,4.024939491127563
7.295081074913538e-06,0.07726265253050611,342.4632078765686,287.82271975126304,4.024939491127563
7.333158528716461e-06,0.07766593318663734,342.9467783063874,287.82271975126304,4.024939491127563
7.36942277043353e-06,0.0780500100020004,343.4064119555922,287.82271975126304,4.024939491127563
7.3966209517213315e-06,0.0783380676135227,343.7505585328139,287.82271975126304,4.024939491127563
7.440138041781814e-06,0.07879895979195839,344.30016828950215,287.82271975126304,4.024939491127563
7.523545797731074e-06,0.07968233646729346,345.3500952974142,287.82271975126304,4.024939491127563
7.625085674538868e-06,0.08075775155031006,346.62216012525323,287.82271975126304,4.024939491127563
7.648657431654964e-06,0.08100740148029606,346.9165140214797,287.82271975126304,4.024939491127563
7.672229188771059e-06,0.08125705141028206,347.21051434315467,287.82271975126304,4.024939491127563
7.722999127174956e-06,0.08179475895179036,347.84255198885717,287.82271975126304,4.024939491127563
7.746570884291051e-06,0.08204440888177636,348.13544702383666,287.82271975126304,4.024939491127563
7.828165428154457e-06,0.08290858171634327,349.14664128828286,287.82271975126304,4.024939491127563
7.833605064412018e-06,0.08296619323864773,349.21390772254074,287.82271975126304,4.024939491127563
7.839044700669578e-06,0.0830238047609522,349.2811559425007,287.82271975126304,4.024939491127563
7.8771221544725e-06,0.08342708541708342,349.75138495376905,287.82271975126304,4.024939491127563
7.9550902741642e-06,0.08425285057011403,350.7114778598985,287.82271975126304,4.024939491127563
7.978662031280295e-06,0.08450250050010003,351.0010151297803,287.82271975126304,4.024939491127563
8.016739485083218e-06,0.08490578115623125,351.46802546401176,287.82271975126304,4.024939491127563
8.045750878456873e-06,0.08521304260852171,351.82326244317886,287.82271975126304,4.024939491127563
8.138224694835401e-06,0.08619243848769755,352.95226078615514,287.82271975126304,4.024939491127563
8.198060693668565e-06,0.08682616523304662,353.68012397463866,287.82271975126304,4.024939491127563
8.212566390355393e-06,0.08697979595919185,353.856263280139,287.82271975126304,4.024939491127563
8.23251172329978e-06,0.08719103820764153,354.09825683919803,287.82271975126304,4.024939491127563
8.261523116673435e-06,0.08749829965993199,354.44983969622376,287.82271975126304,4.024939491127563
8.310479842991479e-06,0.08801680336067214,355.0420458781967,287.82271975126304,4.024939491127563
8.370315841824644e-06,0.08865053010602121,355.7640089566709,287.82271975126304,4.024939491127563
8.388447962683178e-06,0.08884256851370274,355.9823878971469,287.82271975126304,4.024939491127563
8.412019719799273e-06,0.08909221844368874,356.2660054957512,287.82271975126304,4.024939491127563
8.47366893071829e-06,0.08974514902980596,357.006313078663,287.82271975126304,4.024939491127563
8.480921779061705e-06,0.08982196439287858,357.09326977434966,287.82271975126304,4.024939491127563
8.511746384521214e-06,0.0901484296859372,357.46251264316584,287.82271975126304,4.024939491127563
8.558889898753404e-06,0.09064772954590919,358.0262299151445,287.82271975126304,4.024939491127563
8.633231594273397e-06,0.09143508701740348,358.9127144783035,287.82271975126304,4.024939491127563
8.703946865621682e-06,0.09218403680736148,359.7531971366139,287.82271975126304,4.024939491127563
8.809113166601183e-06,0.09329785957191439,360.9982371101874,287.82271975126304,4.024939491127563
8.852630256661667e-06,0.09375875175035008,361.5117288573036,287.82271975126304,4.024939491127563
8.874388801691907e-06,0.09398919783956791,361.76810550144603,287.82271975126304,4.024939491127563
8.91246625549483e-06,0.09439247849569915,362.21617551533427,287.82271975126304,4.024939491127563
8.961422981812873e-06,0.09491098219643929,362.7911700346063,287.82271975126304,4.024939491127563
8.99043437518653e-06,0.09521824364872974,363.131329456225,287.82271975126304,4.024939491127563
9.006753283959211e-06,0.09539107821564313,363.32248100051424,287.82271975126304,4.024939491127563
9.070215706964082e-06,0.09606321264252851,364.064567652177,287.82271975126304,4.024939491127563
9.159063099170903e-06,0.09700420084016805,365.1000960016223,287.82271975126304,4.024939491127563
9.175382007943583e-06,0.09717703540708142,365.28986846317133,287.82271975126304,4.024939491127563
9.180821644201143e-06,0.09723464692938588,365.3530966926433,287.82271975126304,4.024939491127563
9.249723703463575e-06,0.09796439287857572,366.15272716044564,287.82271975126304,4.024939491127563
9.26785582432211e-06,0.09815643128625726,366.3627697061565,287.82271975126304,4.024939491127563
9.285987945180644e-06,0.09834846969393879,366.57265204693937,287.82271975126304,4.024939491127563
9.336757883584542e-06,0.0988861772354471,367.15947400296886,287.82271975126304,4.024939491127563
9.416539215362093e-06,0.09973114622924585,368.0791147176708,287.82271975126304,4.024939491127563
9.427418487877215e-06,0.09984636927385478,368.20428441937315,287.82271975126304,4.024939491127563
9.429231699963068e-06,0.09986557311462294,368.22514055819437,287.82271975126304,4.024939491127563