File: datasets/aisi_316_L/data/M1/train_64.csv
Time(s),Strain(%),Stress(MPa),Temp(C),Log_SR(s-1)
0.0,0.0,0.0,88.01281601905117,-2.6003723284313027
0.004462624558562125,1.12e-05,2.169364925,88.01281601905117,-2.6003723284313027
0.007968972426003794,1.9999999999999998e-05,3.8738659374999997,88.01281601905117,-2.6003723284313027
0.0178504982342485,4.48e-05,8.6774597,88.01281601905117,-2.6003723284313027
0.018806774925368953,4.7199999999999995e-05,9.142323612499998,88.01281601905117,-2.6003723284313027
0.027732024042493204,6.96e-05,13.4810534625,88.01281601905117,-2.6003723284313027
0.0350634786744167,8.8e-05,17.045010125,88.01281601905117,-2.6003723284313027
0.03888858543889852,9.76e-05,18.904465775,88.01281601905117,-2.6003723284313027
0.04590128117378186,0.0001152,22.313467799999998,88.01281601905117,-2.6003723284313027
0.05004514683530383,0.0001256,24.327878087499997,88.01281601905117,-2.6003723284313027
0.051638941320504596,0.0001296,25.102651275,88.01281601905117,-2.6003723284313027
0.0634330205109902,0.0001592,30.8359728625,88.01281601905117,-2.6003723284313027
0.06980819845179324,0.0001752,33.9350656125,88.01281601905117,-2.6003723284313027
0.07458958190739552,0.0001872,36.259385175,88.01281601905117,-2.6003723284313027
0.08861497337716219,0.00022239999999999998,43.077389225,88.01281601905117,-2.6003723284313027
0.09148380345052357,0.0002296,44.4719809625,88.01281601905117,-2.6003723284313027
0.0984964991854069,0.0002472,47.8809829875,88.01281601905117,-2.6003723284313027
0.10423415933212962,0.00026159999999999996,50.67016646249999,88.01281601905117,-2.6003723284313027
0.107102989405491,0.0002688,52.06475819999999,88.01281601905117,-2.6003723284313027
0.11029057837589253,0.0002768,53.614304575,88.01281601905117,-2.6003723284313027
0.11602823852261525,0.0002912,56.40348804999999,88.01281601905117,-2.6003723284313027
0.1243159698456592,0.000312,60.432308625,88.01281601905117,-2.6003723284313027
0.12718479991902057,0.0003192,61.8269003625,88.01281601905117,-2.6003723284313027
0.14854164602071074,0.0003728,72.208861075,88.01281601905117,-2.6003723284313027
0.15427930616743346,0.0003872,74.99804455,88.01281601905117,-2.6003723284313027
0.15969820741711604,0.0004008,77.63227338749999,88.01281601905117,-2.6003723284313027
0.1612920019023168,0.0004048,78.407046575,88.01281601905117,-2.6003723284313027
0.16671090315199938,0.0004184,81.0412754125,88.01281601905117,-2.6003723284313027
0.1765924289602441,0.0004432,85.844869175,88.01281601905117,-2.6003723284313027
0.18073629462176605,0.00045359999999999997,87.8592794625,88.01281601905117,-2.6003723284313027
0.18679271366552894,0.00046879999999999996,90.803417575,88.01281601905117,-2.6003723284313027
0.19667423947377363,0.0004936,95.6070113375,88.01281601905117,-2.6003723284313027
0.19954306954713505,0.0005008,97.001603075,88.01281601905117,-2.6003723284313027
0.2011368640323358,0.0005048,97.77637626250001,88.01281601905117,-2.6003723284313027
0.21069963094354033,0.0005288,102.4250153875,88.01281601905117,-2.6003723284313027
0.2173935677813835,0.0005455999999999999,105.67906277499999,88.01281601905117,-2.6003723284313027
0.2234499868251464,0.0005608,108.62320088749999,88.01281601905117,-2.6003723284313027
0.22568129910442747,0.0005664,109.70788335,88.01281601905117,-2.6003723284313027
0.23078144145706989,0.0005792,112.18715755,88.01281601905117,-2.6003723284313027
0.23620034270675247,0.0005928,114.8213863875,88.01281601905117,-2.6003723284313027
0.24640062741203733,0.0006184,119.7799347875,88.01281601905117,-2.6003723284313027
0.2518195286617199,0.000632,122.414163625,88.01281601905117,-2.6003723284313027
0.2546883587350813,0.0006391999999999999,123.80875536249998,88.01281601905117,-2.6003723284313027
0.2597885010877237,0.000652,126.2880295625,88.01281601905117,-2.6003723284313027
0.2690325091018881,0.0006751999999999999,130.78171404999998,88.01281601905117,-2.6003723284313027
0.2836954183657351,0.000712,137.90962737499999,88.01281601905117,-2.6003723284313027
0.2862454895420563,0.0007184,139.149264475,88.01281601905117,-2.6003723284313027
0.2993146043207025,0.0007511999999999999,145.5024046125,88.01281601905117,-2.6003723284313027
0.3053710233644654,0.0007664,148.446542725,88.01281601905117,-2.6003723284313027
0.3120649602023086,0.0007832,151.70059011249998,88.01281601905117,-2.6003723284313027
0.3251340749809548,0.000816,158.05373025,88.01281601905117,-2.6003723284313027
0.32672786946615556,0.00082,158.8285034375,88.01281601905117,-2.6003723284313027
0.33023421733359726,0.0008288,160.53300445,88.01281601905117,-2.6003723284313027
0.3311904940247177,0.0008311999999999999,160.9978683625,88.01281601905117,-2.6003723284313027
0.3385219486566412,0.0008495999999999999,164.561825025,88.01281601905117,-2.6003723284313027
0.34011574314184195,0.0008535999999999999,165.33659821249998,88.01281601905117,-2.6003723284313027
0.35127230453824726,0.0008816,170.76001052499998,88.01281601905117,-2.6003723284313027
0.35350361681752834,0.0008872,171.8446929875,88.01281601905117,-2.6003723284313027
0.36115383034649196,0.0009063999999999999,175.56360428749997,88.01281601905117,-2.6003723284313027
0.3656164549050541,0.0009176,177.7329692125,88.01281601905117,-2.6003723284313027
0.3697603205665761,0.000928,179.7473795,88.01281601905117,-2.6003723284313027
0.3719916328458571,0.0009335999999999999,180.83206196249998,88.01281601905117,-2.6003723284313027
0.37549798071329876,0.0009423999999999999,182.53656297499998,88.01281601905117,-2.6003723284313027
0.37996060527186093,0.0009536,184.7059279,88.01281601905117,-2.6003723284313027
0.3866545421097041,0.0009704,187.9599752875,88.01281601905117,-2.6003723284313027
0.39016088997714576,0.0009792,189.6644763,88.01281601905117,-2.6003723284313027
0.3958985501238685,0.0009935999999999999,192.45365977499998,88.01281601905117,-2.6003723284313027
0.4038675225498723,0.0010136,196.32752571249998,88.01281601905117,-2.6003723284313027
0.41279277166699657,0.001036,200.6662555625,88.01281601905117,-2.6003723284313027
0.41948670850483977,0.0010528,203.92030295,88.01281601905117,-2.6003723284313027
0.42267429747524127,0.0010608,205.46984932499998,88.01281601905117,-2.6003723284313027
0.42586188644564277,0.0010688,207.0193957,88.01281601905117,-2.6003723284313027
0.42936823431308446,0.0010776,208.7238967125,88.01281601905117,-2.6003723284313027
0.43606217115092766,0.0010944,211.97794409999997,88.01281601905117,-2.6003723284313027
0.44498742026805194,0.0011168,216.31667395,88.01281601905117,-2.6003723284313027
0.45359391048813597,0.0011384,220.5004491625,88.01281601905117,-2.6003723284313027
0.45678149945853747,0.0011464,222.04999553749997,88.01281601905117,-2.6003723284313027
0.4622004007082201,0.00116,224.684224375,88.01281601905117,-2.6003723284313027
0.46443171298750113,0.0011656,225.7689068375,88.01281601905117,-2.6003723284313027
0.46506923078158147,0.0011672,226.0788161125,88.01281601905117,-2.6003723284313027
0.48610731798623147,0.00122,236.30582218749998,88.01281601905117,-2.6003723284313027
0.49280125482407466,0.0012368,239.559869575,88.01281601905117,-2.6003723284313027
0.5004514683530383,0.001256,240.87225463386162,88.01281601905117,-2.6003723284313027
0.5119267886464838,0.0012848,241.07609104465047,88.01281601905117,-2.6003723284313027
0.5214895555576883,0.0013088,241.2445969611763,88.01281601905117,-2.6003723284313027
0.5256334212192103,0.0013192,241.3172414688213,88.01281601905117,-2.6003723284313027
0.5361524648215353,0.0013456,241.50065074547513,88.01281601905117,-2.6003723284313027
0.5393400537919368,0.0013536,241.5559515408665,88.01281601905117,-2.6003723284313027
0.5447589550416193,0.0013671999999999998,241.649671249331,88.01281601905117,-2.6003723284313027
0.5476277851149808,0.0013744,241.69914033608796,88.01281601905117,-2.6003723284313027
0.5508153740853823,0.0013824,241.753987602544,88.01281601905117,-2.6003723284313027
0.558465587614346,0.0014016,241.88511843448057,88.01281601905117,-2.6003723284313027
0.5661158011433095,0.0014207999999999998,242.01555054642884,88.01281601905117,-2.6003723284313027
0.5699409079077914,0.0014303999999999999,242.08050868978435,88.01281601905117,-2.6003723284313027
0.573447255775233,0.0014391999999999999,242.13990444803014,88.01281601905117,-2.6003723284313027
0.5833287815834778,0.001464,242.3065352379904,88.01281601905117,-2.6003723284313027
0.5871538883479597,0.0014736,242.37074147778927,88.01281601905117,-2.6003723284313027
0.5976729319502846,0.0015,242.5464729500821,88.01281601905117,-2.6003723284313027
0.60914825224373,0.0015287999999999999,242.73680995212248,88.01281601905117,-2.6003723284313027
0.617435983566774,0.0015496,242.8734069260227,88.01281601905117,-2.6003723284313027
0.6225361259194164,0.0015624,242.95711125430924,88.01281601905117,-2.6003723284313027
0.6349677229039824,0.0015936,243.16002792247096,88.01281601905117,-2.6003723284313027
0.6451680076092672,0.0016192,243.32536891437664,88.01281601905117,-2.6003723284313027
0.6537744978293514,0.0016408,243.4640838840699,88.01281601905117,-2.6003723284313027
0.6658873359168771,0.0016711999999999999,243.6581118733715,88.01281601905117,-2.6003723284313027
0.6716249960635998,0.0016856,243.74953898586168,88.01281601905117,-2.6003723284313027
0.6894754942978484,0.0017304,244.0320500875315,88.01281601905117,-2.6003723284313027
0.6926630832682499,0.0017384,244.0821968622336,88.01281601905117,-2.6003723284313027
0.6996757790031332,0.001756,244.1922040504558,88.01281601905117,-2.6003723284313027
0.705732198046896,0.0017712,244.2868646617578,88.01281601905117,-2.6003723284313027
0.7175262772373817,0.0018008,244.4702994326329,88.01281601905117,-2.6003723284313027
0.7210326251048234,0.0018096,244.52460683771773,88.01281601905117,-2.6003723284313027
0.7274078030456264,0.0018256,244.62308443040462,88.01281601905117,-2.6003723284313027
0.7315516687071484,0.001836,244.6869144130938,88.01281601905117,-2.6003723284313027
0.7388831233390719,0.0018544,244.79950002117474,88.01281601905117,-2.6003723284313027
0.7417519534124332,0.0018616,244.84343655985688,88.01281601905117,-2.6003723284313027
0.7462145779709953,0.0018728,244.9116507883797,88.01281601905117,-2.6003723284313027
0.7497209258384371,0.0018816,244.96513613297617,88.01281601905117,-2.6003723284313027
0.7516334792206779,0.0018863999999999999,244.9942688354777,88.01281601905117,-2.6003723284313027
0.770759013043087,0.0019344,245.28402319113115,88.01281601905117,-2.6003723284313027
0.7768154320868499,0.0019496,245.37519236389696,88.01281601905117,-2.6003723284313027
0.7847844045128536,0.0019695999999999997,245.49473057237415,88.01281601905117,-2.6003723284313027
0.7956222070122189,0.0019968,245.6565455927385,88.01281601905117,-2.6003723284313027
0.7991285548796605,0.0020055999999999997,245.7087131609238,88.01281601905117,-2.6003723284313027
0.8026349027471023,0.0020144,245.76079153551112,88.01281601905117,-2.6003723284313027
0.8058224917175036,0.0020223999999999997,245.80805856847687,88.01281601905117,-2.6003723284313027
0.8074162862027044,0.0020264,245.8316647359956,88.01281601905117,-2.6003723284313027
0.8115601518642265,0.0020368,245.89295587893284,88.01281601905117,-2.6003723284313027
0.8201666420843104,0.0020583999999999997,246.01986424974993,88.01281601905117,-2.6003723284313027
0.8287731323043946,0.00208,246.14625429815536,88.01281601905117,-2.6003723284313027
0.8319607212747963,0.002088,246.19293539437612,88.01281601905117,-2.6003723284313027
0.8329169979659167,0.0020904,246.2069261145759,88.01281601905117,-2.6003723284313027
0.8386546581126394,0.0021048,246.29073925904962,88.01281601905117,-2.6003723284313027
0.8405672114948803,0.0021096,246.31862723954814,88.01281601905117,-2.6003723284313027
0.8434360415682416,0.0021168,246.3604128545769,88.01281601905117,-2.6003723284313027
0.8469423894356833,0.0021256,246.41140896267692,88.01281601905117,-2.6003723284313027
0.8542738440676069,0.002144,246.51777188701794,88.01281601905117,-2.6003723284313027
0.8676617177432933,0.0021776,246.71108574576058,88.01281601905117,-2.6003723284313027
0.8714868245077749,0.0021872,246.76610415741777,88.01281601905117,-2.6003723284313027
0.8778620024485779,0.0022031999999999998,246.85759268337225,88.01281601905117,-2.6003723284313027
0.8804120736248993,0.0022096,246.894115496631,88.01281601905117,-2.6003723284313027
0.8823246270071402,0.0022144,246.92148053799906,88.01281601905117,-2.6003723284313027
0.886149733771622,0.002224,246.976141318265,88.01281601905117,-2.6003723284313027
0.8960312595798667,0.0022488,247.1169241225651,88.01281601905117,-2.6003723284313027
0.898900089653228,0.0022559999999999998,247.15768296746418,88.01281601905117,-2.6003723284313027
0.9151567934022757,0.0022968,247.3876986210236,88.01281601905117,-2.6003723284313027
0.9196194179608378,0.0023079999999999997,247.45056070510594,88.01281601905117,-2.6003723284313027
0.9291821848720424,0.002332,247.5848659585279,88.01281601905117,-2.6003723284313027
0.9317322560483637,0.0023384,247.62058951419726,88.01281601905117,-2.6003723284313027
0.9352386039158053,0.0023472,247.66964720479436,88.01281601905117,-2.6003723284313027
0.9368323984010061,0.0023512,247.69192243731297,88.01281601905117,-2.6003723284313027
0.9390637106802873,0.0023568,247.7230829494562,88.01281601905117,-2.6003723284313027
0.9476702009003711,0.0023783999999999997,247.84300397716072,88.01281601905117,-2.6003723284313027
0.9677520114139009,0.0024288,248.12117995080368,88.01281601905117,-2.6003723284313027
0.9722146359724629,0.00244,248.18269004572602,88.01281601905117,-2.6003723284313027
0.9747647071487843,0.0024464,248.21778923190374,88.01281601905117,-2.6003723284313027
0.9808211261925471,0.0024616,248.30100658725442,88.01281601905117,-2.6003723284313027
0.9875150630303903,0.0024784,248.3927508567591,88.01281601905117,-2.6003723284313027
0.9900651342067114,0.0024847999999999997,248.42763721756674,88.01281601905117,-2.6003723284313027
1.0005841778090365,0.0025112,248.5711745915439,88.01281601905117,-2.6003723284313027
1.0088719091320804,0.002532,248.68385056253894,88.01281601905117,-2.6003723284313027
1.0107844625143214,0.0025368,248.70980137645154,88.01281601905117,-2.6003723284313027
1.0158846048669639,0.0025496,248.77891009507547,88.01281601905117,-2.6003723284313027
1.0171596404551244,0.0025528,248.79616611603458,88.01281601905117,-2.6003723284313027
1.020984747219606,0.0025624,248.847883633697,88.01281601905117,-2.6003723284313027
1.027359925160409,0.0025784,248.9339118875836,88.01281601905117,-2.6003723284313027
1.0292724785426501,0.0025832,248.9596797325022,88.01281601905117,-2.6003723284313027
1.033416344204172,0.0025935999999999997,249.01544608998222,88.01281601905117,-2.6003723284313027
1.0385164865568146,0.0026064,249.0839620307048,88.01281601905117,-2.6003723284313027
1.0407477988360956,0.0026119999999999997,249.11389647644262,88.01281601905117,-2.6003723284313027
1.0426603522183364,0.0026168,249.13953465690423,88.01281601905117,-2.6003723284313027
1.043616628909457,0.0026192,249.15234686880277,88.01281601905117,-2.6003723284313027
1.0525418780265812,0.0026416,249.27170754008654,88.01281601905117,-2.6003723284313027
1.0573232614821835,0.0026536,249.33548835232133,88.01281601905117,-2.6003723284313027
1.0636984394229865,0.0026696,249.42035473144884,88.01281601905117,-2.6003723284313027
1.0735799652312312,0.0026944,249.55150664189313,88.01281601905117,-2.6003723284313027
1.0758112775105122,0.0026999999999999997,249.5810563342422,88.01281601905117,-2.6003723284313027
1.0777238308927533,0.0027048,249.6063656226646,88.01281601905117,-2.6003723284313027
1.0825052143483553,0.0027167999999999997,249.66956232915533,88.01281601905117,-2.6003723284313027
1.0933430168477207,0.002744,249.81240654307965,88.01281601905117,-2.6003723284313027
1.0997181947885237,0.00276,249.8961746015996,88.01281601905117,-2.6003723284313027
1.1092809616997283,0.002784,250.02147245830946,88.01281601905117,-2.6003723284313027
1.1140623451553304,0.002796,250.0839633629204,88.01281601905117,-2.6003723284313027
1.1146998629494107,0.0027976,250.09228757351391,88.01281601905117,-2.6003723284313027
1.1252189065517357,0.0028239999999999997,250.22937011166604,88.01281601905117,-2.6003723284313027
1.1319128433895789,0.0028407999999999997,250.31634429543195,88.01281601905117,-2.6003723284313027
1.140200574712623,0.0028615999999999997,250.42374919273252,88.01281601905117,-2.6003723284313027
1.1440256814771048,0.0028712,250.47321795180906,88.01281601905117,-2.6003723284313027
1.1456194759623055,0.0028752,250.49381089156967,88.01281601905117,-2.6003723284313027
1.1497633416238275,0.0028856,250.5473003126562,88.01281601905117,-2.6003723284313027
1.1523134128001489,0.002892,250.58017951174926,88.01281601905117,-2.6003723284313027
1.1730327411077586,0.002944,250.84627911073218,88.01281601905117,-2.6003723284313027
1.1797266779456017,0.0029608,250.9318571429177,88.01281601905117,-2.6003723284313027
1.1848268202982442,0.0029736,250.99693240345485,88.01281601905117,-2.6003723284313027
1.1896082037538465,0.0029855999999999997,251.05784131264403,88.01281601905117,-2.6003723284313027
1.1918395160331274,0.0029912,251.0862327892934,88.01281601905117,-2.6003723284313027
1.1937520694153685,0.002996,251.11055184544523,88.01281601905117,-2.6003723284313027
1.2029960774295327,0.0030191999999999997,251.2278804112938,88.01281601905117,-2.6003723284313027
1.2087337375762557,0.0030336,251.30052821168948,88.01281601905117,-2.6003723284313027
1.2147901566200185,0.0030488,251.37706624760295,88.01281601905117,-2.6003723284313027
1.224034164634183,0.003072,251.49360116603114,88.01281601905117,-2.6003723284313027
1.2265842358105041,0.0030784,251.52568826301928,88.01281601905117,-2.6003723284313027
1.2441159751477124,0.0031224,251.74558701344495,88.01281601905117,-2.6003723284313027
1.2463472874269934,0.0031279999999999997,251.77348717600353,88.01281601905117,-2.6003723284313027
1.249534876397395,0.003136,251.8133107827281,88.01281601905117,-2.6003723284313027
1.2632415089701214,0.0031704,251.9841027894859,88.01281601905117,-2.6003723284313027
1.2689791691168442,0.0031848,252.05538235082662,88.01281601905117,-2.6003723284313027
1.2715292402931655,0.0031912,252.08702179859947,88.01281601905117,-2.6003723284313027
1.2753543470576472,0.0032007999999999997,252.13443460958072,88.01281601905117,-2.6003723284313027
1.2779044182339685,0.0032072,252.16601234332123,88.01281601905117,-2.6003723284313027
1.283323319483651,0.0032208,252.2330335460249,88.01281601905117,-2.6003723284313027
1.299898782129739,0.0032624,252.43735773993248,88.01281601905117,-2.6003723284313027
1.3164742447758269,0.0033039999999999996,252.6406683139545,88.01281601905117,-2.6003723284313027
1.3193430748491883,0.0033112,252.67575509306076,88.01281601905117,-2.6003723284313027
1.320618110437349,0.0033144,252.6913396649242,88.01281601905117,-2.6003723284313027
1.3222119049225496,0.0033184,252.71081213007812,88.01281601905117,-2.6003723284313027
1.3257182527899913,0.0033271999999999998,252.75361936001957,88.01281601905117,-2.6003723284313027
1.329224600657433,0.003336,252.79638245709478,88.01281601905117,-2.6003723284313027
1.3343247430100753,0.0033488,252.85850487516032,88.01281601905117,-2.6003723284313027
1.3371935730834368,0.003356,252.89340803856427,88.01281601905117,-2.6003723284313027
1.3489876522739224,0.0033856,253.0365930724131,88.01281601905117,-2.6003723284313027
1.3509002056561634,0.0033904,253.0597661840407,88.01281601905117,-2.6003723284313027
1.367156909405211,0.0034311999999999997,253.25622370108206,88.01281601905117,-2.6003723284313027
1.3779947119045761,0.0034584,253.38668946875134,88.01281601905117,-2.6003723284313027
1.3821385775660981,0.0034687999999999997,253.43646760544053,88.01281601905117,-2.6003723284313027
1.3878762377128209,0.0034831999999999997,253.50529519723048,88.01281601905117,-2.6003723284313027
1.411145637196752,0.0035415999999999998,253.78329919076674,88.01281601905117,-2.6003723284313027
1.4270835820487595,0.0035816,253.9726820400613,88.01281601905117,-2.6003723284313027
1.430271171019161,0.0035895999999999996,254.01045942937685,88.01281601905117,-2.6003723284313027
1.4379213845481247,0.0036087999999999997,254.10099144691034,88.01281601905117,-2.6003723284313027
1.4442965624889277,0.0036247999999999996,254.1762913895246,88.01281601905117,-2.6003723284313027
1.4503529815326908,0.00364,254.24770635866295,88.01281601905117,-2.6003723284313027
1.455453123885333,0.0036528,254.3077551172851,88.01281601905117,-2.6003723284313027
1.4608720251350156,0.0036663999999999998,254.37146707582494,88.01281601905117,-2.6003723284313027
1.465972167487658,0.0036791999999999997,254.43134712839586,88.01281601905117,-2.6003723284313027
1.4723473454284612,0.0036952,254.50608306465477,88.01281601905117,-2.6003723284313027
1.4831851479278262,0.0037224,254.63284516408638,88.01281601905117,-2.6003723284313027
1.4860539780011877,0.0037296,254.66633930511532,88.01281601905117,-2.6003723284313027
1.4876477724863884,0.0037335999999999997,254.6849362645156,88.01281601905117,-2.6003723284313027
1.4917916381479104,0.003744,254.73325203028747,88.01281601905117,-2.6003723284313027
1.5000793694709544,0.0037648,254.82972682169824,88.01281601905117,-2.6003723284313027
1.503904476235436,0.0037744,254.87418351586578,88.01281601905117,-2.6003723284313027
1.5128297253525604,0.0037968,254.97774466078178,88.01281601905117,-2.6003723284313027
1.5137860020436809,0.0037992,254.98882634663101,88.01281601905117,-2.6003723284313027
1.5300427057927286,0.0038399999999999997,255.1767992851346,88.01281601905117,-2.6003723284313027
1.5316365002779293,0.0038439999999999998,255.19518597939808,88.01281601905117,-2.6003723284313027
1.5386491960128126,0.0038615999999999998,255.27599895056954,88.01281601905117,-2.6003723284313027
1.558093488732262,0.0039104,255.49932341530015,88.01281601905117,-2.6003723284313027
1.5670187378493863,0.0039328,255.6014687832124,88.01281601905117,-2.6003723284313027
1.5705250857168278,0.0039416,255.64153521145707,88.01281601905117,-2.6003723284313027
1.5788128170398716,0.0039624,255.7360992529669,88.01281601905117,-2.6003723284313027
1.5864630305688356,0.0039816,255.82321744976184,88.01281601905117,-2.6003723284313027
1.670311923978151,0.0041920384076815365,256.76756472158576,88.01281601905117,-2.6003723284313027
1.9993369107209362,0.005017803560712143,260.3070269647514,88.01281601905117,-2.6003723284313027
2.029943886231893,0.005094618923784757,260.62426083027697,88.01281601905117,-2.6003723284313027
2.1676752760311984,0.005440288057611523,262.0293361614656,88.01281601905117,-2.6003723284313027
2.2059339954198944,0.005536307261452291,262.4133982507603,88.01281601905117,-2.6003723284313027
2.2594962025640686,0.005670734146829366,262.9467491391299,88.01281601905117,-2.6003723284313027
2.580869445429115,0.0064772954590918185,266.04899402302357,88.01281601905117,-2.6003723284313027
3.2236159311592067,0.008090418083616723,271.8332929725105,88.01281601905117,-2.6003723284313027
3.5296856862687744,0.008858571714342869,274.4273849889189,88.01281601905117,-2.6003723284313027
3.598551381168427,0.009031406281256251,274.9987835800541,88.01281601905117,-2.6003723284313027
3.6827205638235583,0.009242648529705941,275.6914005475142,88.01281601905117,-2.6003723284313027
3.9122728801557343,0.00981876375275055,277.54966470206546,88.01281601905117,-2.6003723284313027
4.203039147509823,0.010548509701940389,279.84349339582474,88.01281601905117,-2.6003723284313027
4.348422281186868,0.010913382676535306,280.96712833814456,88.01281601905117,-2.6003723284313027
4.509108902619391,0.011316663332666534,282.19212889662583,88.01281601905117,-2.6003723284313027
4.562671109763565,0.011451090218043608,282.59666320038775,88.01281601905117,-2.6003723284313027
4.593278085274521,0.011527905581116223,282.8269940660517,88.01281601905117,-2.6003723284313027
4.6774472679296535,0.011739147829565914,283.45733802735936,88.01281601905117,-2.6003723284313027
4.845785633239915,0.012161632326465293,284.704908394109,88.01281601905117,-2.6003723284313027
5.159507132227222,0.012948989797959592,286.9857170477339,88.01281601905117,-2.6003723284313027
5.343148985292963,0.013409881976395279,288.2957209781593,88.01281601905117,-2.6003723284313027
5.519139094480964,0.013851570314062813,289.53475961653305,88.01281601905117,-2.6003723284313027
5.672173972035748,0.014235647129425886,290.59971092580713,88.01281601905117,-2.6003723284313027
6.108323373066882,0.015330266053210643,293.5750117219729,88.01281601905117,-2.6003723284313027
6.215447787355231,0.015599119823964794,294.2929663720058,88.01281601905117,-2.6003723284313027
6.261358250621666,0.015714342868573716,294.5991820852066,88.01281601905117,-2.6003723284313027
6.4067413842987095,0.016079215843168633,295.5631383309896,88.01281601905117,-2.6003723284313027
6.544472774098016,0.0164248849769954,296.46852038072205,88.01281601905117,-2.6003723284313027
6.620990212875407,0.016616923384676935,296.9682985227609,88.01281601905117,-2.6003723284313027
6.682204163897321,0.016770554110822164,297.36650106506727,88.01281601905117,-2.6003723284313027
6.819935553696626,0.01711622324464893,298.2572916148737,88.01281601905117,-2.6003723284313027
6.942363455740454,0.017423484696939388,299.04323204108755,88.01281601905117,-2.6003723284313027
7.141308796561672,0.017922784556911382,300.3089530810526,88.01281601905117,-2.6003723284313027
7.3479058812606315,0.018441288257651532,301.6088840128251,88.01281601905117,-2.6003723284313027
7.684582611881156,0.019286257251450292,303.69715254933226,88.01281601905117,-2.6003723284313027
8.174294220056463,0.02051530306061212,306.67201699906065,88.01281601905117,-2.6003723284313027
8.426801768021857,0.021149029805961193,308.17871325081285,88.01281601905117,-2.6003723284313027
8.564533157821163,0.02149469893978796,308.9931219127671,88.01281601905117,-2.6003723284313027
8.809388961908816,0.022109221844368875,310.4284580823941,88.01281601905117,-2.6003723284313027
8.878254656808469,0.022282056411282256,310.8293320350731,88.01281601905117,-2.6003723284313027
9.092503485385166,0.022819763952790558,312.0688097963293,88.01281601905117,-2.6003723284313027
9.291448826206386,0.023319063812762553,313.20959217523347,88.01281601905117,-2.6003723284313027
9.42918021600569,0.023664732946589318,313.99379009215437,88.01281601905117,-2.6003723284313027
9.681687763971084,0.024298459691938386,315.4199803174735,88.01281601905117,-2.6003723284313027
9.918891824181,0.02489377875575115,316.74657603345577,88.01281601905117,-2.6003723284313027
9.941847055814216,0.02495139027805561,316.87429609716116,88.01281601905117,-2.6003723284313027
9.980105775202913,0.02504740948189638,317.08690758716796,88.01281601905117,-2.6003723284313027
10.056623213980304,0.025239447889577916,317.5111793581062,88.01281601905117,-2.6003723284313027
10.255568554801524,0.02573874774954991,318.60843542509946,88.01281601905117,-2.6003723284313027
10.324434249701175,0.025911582316463292,318.98631660019595,88.01281601905117,-2.6003723284313027
10.56929005378883,0.02652610522104421,320.32200516577905,88.01281601905117,-2.6003723284313027
10.860056321142919,0.027255851170234047,321.8925609496222,88.01281601905117,-2.6003723284313027
11.120215612986051,0.02790878175635127,323.2839466844166,88.01281601905117,-2.6003723284313027
11.189081307885706,0.028081616323264655,323.6501222952095,88.01281601905117,-2.6003723284313027
11.257947002785357,0.028254450890178036,324.01542000675767,88.01281601905117,-2.6003723284313027
11.296205722174054,0.028350470094018806,324.2179865894515,88.01281601905117,-2.6003723284313027
11.433937111973359,0.028696139227845568,324.94502126951176,88.01281601905117,-2.6003723284313027
11.556365014017185,0.029003400680136026,325.58841184753317,88.01281601905117,-2.6003723284313027
11.694096403816491,0.02934906981396279,326.30905720525794,88.01281601905117,-2.6003723284313027
11.755310354838404,0.02950270054010802,326.6282807052374,88.01281601905117,-2.6003723284313027
11.969559183415102,0.030040408081616322,327.7404931815086,88.01281601905117,-2.6003723284313027
12.114942317092147,0.030405281056211243,328.49079045558824,88.01281601905117,-2.6003723284313027
12.398056840568497,0.031115823164632926,329.9418938859789,88.01281601905117,-2.6003723284313027
12.466922535468148,0.03128865773154631,330.2929038752427,88.01281601905117,-2.6003723284313027
12.512832998734584,0.03140388077615523,330.5264905246748,88.01281601905117,-2.6003723284313027
12.719430083433544,0.03192238447689538,331.5735214303189,88.01281601905117,-2.6003723284313027
12.926027168132503,0.03244088817763553,332.6139404009931,88.01281601905117,-2.6003723284313027
13.002544606909893,0.032632926585317065,332.9976323756682,88.01281601905117,-2.6003723284313027
13.086713789565025,0.03284416883376676,333.4186778883432,88.01281601905117,-2.6003723284313027
13.201489947731112,0.033132226445289056,333.99113278863047,88.01281601905117,-2.6003723284313027
13.339221337530418,0.033477895579115825,334.67552284390064,88.01281601905117,-2.6003723284313027
13.431042264063288,0.03370834166833367,335.130252418902,88.01281601905117,-2.6003723284313027
13.576425397740334,0.03407321464292859,335.84776919009266,88.01281601905117,-2.6003723284313027
13.79832597019477,0.034630126025205044,336.9371758618796,88.01281601905117,-2.6003723284313027
13.813629457950247,0.03466853370674135,337.01205453498414,88.01281601905117,-2.6003723284313027
14.020226542649207,0.0351870374074815,338.01977095532897,88.01281601905117,-2.6003723284313027
14.379858504902945,0.03608961792358471,339.76023684580304,88.01281601905117,-2.6003723284313027
14.464027687558078,0.036300860172034405,340.1651184766643,88.01281601905117,-2.6003723284313027
14.586455589601904,0.03660812162432486,340.7524007530851,88.01281601905117,-2.6003723284313027
14.8389631375673,0.03724184836967394,341.9576337720142,88.01281601905117,-2.6003723284313027
14.94608755185565,0.03751070214042809,342.466525293449,88.01281601905117,-2.6003723284313027
15.045560222266259,0.03776035207041409,342.93779517184356,88.01281601905117,-2.6003723284313027
15.282764282476172,0.038355671134226846,344.05671568794287,88.01281601905117,-2.6003723284313027
15.321023001864868,0.03845169033806761,344.2365505033566,88.01281601905117,-2.6003723284313027
15.435799160030953,0.03873974794958991,344.7750070498593,88.01281601905117,-2.6003723284313027
15.527620086563827,0.03897019403880776,345.2046488632265,88.01281601905117,-2.6003723284313027
15.604137525341217,0.039162232446489295,345.5619273310114,88.01281601905117,-2.6003723284313027
15.680654964118608,0.03935427085417083,345.91852317885497,88.01281601905117,-2.6003723284313027
15.764824146773739,0.03956551310262052,346.30999570465394,88.01281601905117,-2.6003723284313027
15.864296817184348,0.039815163032606515,346.7715956924985,88.01281601905117,-2.6003723284313027
15.933162512084003,0.0399879975995199,347.0905038845375,88.01281601905117,-2.6003723284313027
16.047938670250087,0.0402760552110422,347.6208255368915,88.01281601905117,-2.6003723284313027
16.430525864137053,0.041236247249449895,349.37797714615584,88.01281601905117,-2.6003723284313027
16.545302022303137,0.041524304860972194,349.9020014556421,88.01281601905117,-2.6003723284313027
16.70598864373566,0.04192758551710342,350.63325994200187,88.01281601905117,-2.6003723284313027
16.851371777412705,0.04229245849169834,351.29251447450986,88.01281601905117,-2.6003723284313027
17.065620605989405,0.04283016603320665,352.2600186830383,88.01281601905117,-2.6003723284313027
17.256914202932883,0.04331026205241048,353.1198659305831,88.01281601905117,-2.6003723284313027
17.4558595437541,0.04380956191238247,354.0101730144141,88.01281601905117,-2.6003723284313027
17.471163031509583,0.04384796959391879,354.0784938263336,88.01281601905117,-2.6003723284313027
17.570635701920192,0.044097619523904785,354.522011572877,88.01281601905117,-2.6003723284313027
17.624197909064364,0.044232046409281855,354.76042317130504,88.01281601905117,-2.6003723284313027
18.067999053973235,0.04534586917383476,356.7250791168412,88.01281601905117,-2.6003723284313027
18.167471724383844,0.04559551910382076,357.16284050189216,88.01281601905117,-2.6003723284313027
18.213382187650282,0.045710742148429684,357.3645688407669,88.01281601905117,-2.6003723284313027
18.282247882549935,0.04588357671534307,357.66678990978346,88.01281601905117,-2.6003723284313027
18.31285485806089,0.04596039207841568,357.8009678393242,88.01281601905117,-2.6003723284313027
18.435282760104716,0.04626765353070614,358.33680726390827,88.01281601905117,-2.6003723284313027
18.657183332559153,0.04682456491298259,359.3044922477759,88.01281601905117,-2.6003723284313027
18.848476929502635,0.04730466093218644,360.13510634442656,88.01281601905117,-2.6003723284313027
19.024467038690634,0.047746349269853966,360.89637223961614,88.01281601905117,-2.6003723284313027
19.085680989712547,0.047899979995999195,361.16051594528864,88.01281601905117,-2.6003723284313027
19.307581562166984,0.04845689137827565,362.11527959791476,88.01281601905117,-2.6003723284313027
19.498875159110465,0.048936987397479495,362.93492202702424,88.01281601905117,-2.6003723284313027
19.544785622376903,0.04905221044208842,363.1311688449514,88.01281601905117,-2.6003723284313027
20.026845486674468,0.050262052410482094,365.18102156000407,88.01281601905117,-2.6003723284313027
20.080407693818646,0.05039647929585918,365.40758884337265,88.01281601905117,-2.6003723284313027
20.355870473417255,0.0510878175635127,366.5690898466248,88.01281601905117,-2.6003723284313027
20.577771045871692,0.051644728945789156,367.5002916921819,88.01281601905117,-2.6003723284313027
20.868537313225783,0.052374474894979,368.71458072007175,88.01281601905117,-2.6003723284313027
20.929751264247695,0.05252810562112423,368.96937770353276,88.01281601905117,-2.6003723284313027
21.021572190780564,0.052758551710342064,369.3510289192621,88.01281601905117,-2.6003723284313027
21.182258812213092,0.0531618323664733,370.0173578319013,88.01281601905117,-2.6003723284313027
21.342945433645614,0.05356511302260453,370.681718298962,88.01281601905117,-2.6003723284313027
21.373552409156567,0.053641928385677135,370.8080416791388,88.01281601905117,-2.6003723284313027
21.411811128545263,0.0537379475895179,370.96584673864896,88.01281601905117,-2.6003723284313027
21.473025079567176,0.05389157831566313,371.2181062953287,88.01281601905117,-2.6003723284313027
21.495980311200395,0.05394918983796759,371.3126313036853,88.01281601905117,-2.6003723284313027
21.679622164266135,0.05441008201640328,372.06741932472,88.01281601905117,-2.6003723284313027
21.794398322432222,0.05469813962792558,372.53789582332433,88.01281601905117,-2.6003723284313027
21.947433199987007,0.05508221644328866,373.1636974477523,88.01281601905117,-2.6003723284313027
22.123423309175006,0.05552390478095619,373.8812693192221,88.01281601905117,-2.6003723284313027
22.245851211218834,0.055831166233246646,374.3791373034866,88.01281601905117,-2.6003723284313027
22.368279113262663,0.056138427685537104,374.8759378395318,88.01281601905117,-2.6003723284313027
22.421841320406838,0.05627285457091419,375.0929544881006,88.01281601905117,-2.6003723284313027
22.766169794905103,0.0571370274054811,376.4832648501224,88.01281601905117,-2.6003723284313027
22.857990721437968,0.05736747349469894,376.8526261799732,88.01281601905117,-2.6003723284313027
22.919204672459884,0.057521104220844166,377.0985456432669,88.01281601905117,-2.6003723284313027
22.980418623481796,0.057674734946989395,377.3442090812945,88.01281601905117,-2.6003723284313027
23.041632574503712,0.057828365673134624,377.58961744152595,88.01281601905117,-2.6003723284313027
23.271184890835887,0.05840448089617924,378.50764300703304,88.01281601905117,-2.6003723284313027
23.347702329613277,0.05859651930386077,378.8128658193106,88.01281601905117,-2.6003723284313027
23.470130231657105,0.05890378075615123,379.30041212314103,88.01281601905117,-2.6003723284313027
23.561951158189977,0.05913422684536908,379.6654212165108,88.01281601905117,-2.6003723284313027
23.79150347452215,0.05971034206841368,380.57552527742746,88.01281601905117,-2.6003723284313027
23.845065681666327,0.05984476895379076,380.7873893567496,88.01281601905117,-2.6003723284313027
24.273563338819724,0.060920184036807365,382.4756713913261,88.01281601905117,-2.6003723284313027
24.418946472496767,0.061285057011402286,383.04583531455984,88.01281601905117,-2.6003723284313027
24.709712739850854,0.062014802960592114,384.18220694087915,88.01281601905117,-2.6003723284313027
24.732667971484073,0.062072414482896576,384.27169777027444,88.01281601905117,-2.6003723284313027
24.931613312305295,0.06257171434286858,385.04593274000837,88.01281601905117,-2.6003723284313027
25.023434238838163,0.06280216043208642,385.40245893782645,88.01281601905117,-2.6003723284313027
25.168817372515207,0.06316703340668134,385.96591707030655,88.01281601905117,-2.6003723284313027
25.283593530681294,0.06345509101820364,386.4098563138349,88.01281601905117,-2.6003723284313027
25.497842359257994,0.06399279855971195,387.23644568172296,88.01281601905117,-2.6003723284313027
25.551404566402166,0.06412722544508902,387.4426692355069,88.01281601905117,-2.6003723284313027
25.635573749057297,0.06433846769353871,387.7663945153538,88.01281601905117,-2.6003723284313027
26.171195820499044,0.06568273654730947,389.81683666368235,88.01281601905117,-2.6003723284313027
26.232409771520956,0.0658363672734547,390.05012617342453,88.01281601905117,-2.6003723284313027
26.3395341858093,0.06610522104420884,390.45787258757747,88.01281601905117,-2.6003723284313027
26.362489417442518,0.0661628325665133,390.54516261794066,88.01281601905117,-2.6003723284313027
26.431355112342175,0.06633566713342669,390.80685502350013,88.01281601905117,-2.6003723284313027
26.492569063364087,0.06648929785957192,391.039247342869,88.01281601905117,-2.6003723284313027
26.553783014386003,0.06664292858571715,391.27143033896766,88.01281601905117,-2.6003723284313027
26.722121379696265,0.06706541308261653,391.9088597155243,88.01281601905117,-2.6003723284313027
26.898111488884265,0.06750710142028406,392.573590961304,88.01281601905117,-2.6003723284313027
27.074101598072268,0.0679487897579516,393.2366281544826,88.01281601905117,-2.6003723284313027
27.380171353181836,0.06871694338867775,394.38574658687213,88.01281601905117,-2.6003723284313027
27.449037048081486,0.06888977795559112,394.64360655623847,88.01281601905117,-2.6003723284313027
27.80101726645749,0.06977315463092619,395.95763780594336,88.01281601905117,-2.6003723284313027
27.831624241968445,0.0698499699939988,396.0715938733539,88.01281601905117,-2.6003723284313027
28.045873070545145,0.0703876775355071,396.8679223110339,88.01281601905117,-2.6003723284313027
28.26777364299958,0.07094458891778356,397.69019394549605,88.01281601905117,-2.6003723284313027
28.405505032798885,0.07129025805161032,398.1993034570032,88.01281601905117,-2.6003723284313027
28.527932934842713,0.07159751950390078,398.651037582895,88.01281601905117,-2.6003723284313027
28.971734079751588,0.0727113422684537,400.28227388768255,88.01281601905117,-2.6003723284313027
29.13242070118411,0.07311462292458493,400.8704871570618,88.01281601905117,-2.6003723284313027
29.208938139961504,0.07330666133226646,401.1501438662031,88.01281601905117,-2.6003723284313027
29.3849282491495,0.07374834966993399,401.79227226128256,88.01281601905117,-2.6003723284313027
29.660391028748116,0.07443968793758753,402.7943399192364,88.01281601905117,-2.6003723284313027
29.866988113447075,0.07495819163832768,403.5435105187868,88.01281601905117,-2.6003723284313027
29.935853808346724,0.07513102620524105,403.792784572644,88.01281601905117,-2.6003723284313027
29.974112527735418,0.07522704540908182,403.9311735202886,88.01281601905117,-2.6003723284313027
30.012371247124115,0.07532306461292258,404.06949359601794,88.01281601905117,-2.6003723284313027
30.196013100189855,0.07578395679135827,404.73247510087737,88.01281601905117,-2.6003723284313027
30.540341574688124,0.0766481296259252,405.9713424272145,88.01281601905117,-2.6003723284313027
30.884670049186386,0.07751230246049211,407.20477418517106,88.01281601905117,-2.6003723284313027
31.167784572662736,0.07822284456891379,408.21491651431546,88.01281601905117,-2.6003723284313027
31.31316770633978,0.07858771754350871,408.73224722406013,88.01281601905117,-2.6003723284313027
31.328471194095258,0.07862612522504502,408.78664854065255,88.01281601905117,-2.6003723284313027
31.619237461449348,0.07935587117423486,409.81831257048714,88.01281601905117,-2.6003723284313027
31.741665363493176,0.07966313262652532,410.25158976033725,88.01281601905117,-2.6003723284313027
31.764620595126388,0.07972074414882976,410.3327566244129,88.01281601905117,-2.6003723284313027
31.971217679825347,0.08023924784956991,411.062231869419,88.01281601905117,-2.6003723284313027
32.216073483913,0.08085377075415083,411.9244188223086,88.01281601905117,-2.6003723284313027
32.30024266656813,0.08106501300260052,412.2202048458784,88.01281601905117,-2.6003723284313027
32.40736708085648,0.08133386677335468,412.5962253953498,88.01281601905117,-2.6003723284313027
32.55275021453353,0.0816987397479496,413.1057645606175,88.01281601905117,-2.6003723284313027
32.62161590943318,0.08187157431486297,413.34681538493294,88.01281601905117,-2.6003723284313027
32.72874032372153,0.08214042808561713,413.72138924191154,88.01281601905117,-2.6003723284313027
32.958292640053706,0.08271654330866174,414.522441221702,88.01281601905117,-2.6003723284313027
33.08837228597527,0.08304300860172034,414.9754047672618,88.01281601905117,-2.6003723284313027
33.30262111455197,0.08358071614322865,415.7199513776357,88.01281601905117,-2.6003723284313027
33.47095947986223,0.08400320064012803,416.30364256564076,88.01281601905117,-2.6003723284313027
33.524521687006406,0.0841376275255051,416.48912224732976,88.01281601905117,-2.6003723284313027
33.73111877170536,0.08465613122624525,417.20346388057595,88.01281601905117,-2.6003723284313027
33.94536760028206,0.08519383876775355,417.94246263672943,88.01281601905117,-2.6003723284313027
33.98362631967076,0.08528985797159433,418.074235056659,88.01281601905117,-2.6003723284313027
34.10605422171459,0.08559711942388479,418.49551853718174,88.01281601905117,-2.6003723284313027
34.3432582819245,0.08619243848769755,419.3100807241569,88.01281601905117,-2.6003723284313027
34.47333792784607,0.08651890378075616,419.7558444700458,88.01281601905117,-2.6003723284313027
34.565158854378936,0.086749349869974,420.070106364351,88.01281601905117,-2.6003723284313027
34.64932803703407,0.08696059211842369,420.35789387176834,88.01281601905117,-2.6003723284313027
34.74880070744467,0.08721024204840969,420.69765511127787,88.01281601905117,-2.6003723284313027
34.87888035336624,0.0875367073414683,421.14138647966263,88.01281601905117,-2.6003723284313027
34.92479081663267,0.08765193038607721,421.2978433974475,88.01281601905117,-2.6003723284313027
35.238512315619985,0.08843928785757152,422.364827028537,88.01281601905117,-2.6003723284313027
35.498671607463116,0.08909221844368874,423.24683567958647,88.01281601905117,-2.6003723284313027
35.766482643183984,0.08976435287057412,424.1521564929568,88.01281601905117,-2.6003723284313027
35.95012449624973,0.0902252450490098,424.77142048517067,88.01281601905117,-2.6003723284313027
36.087855886049034,0.09057091418283657,425.2350591839626,88.01281601905117,-2.6003723284313027
36.12611460543773,0.09066693338667733,425.36372517334416,88.01281601905117,-2.6003723284313027
36.31740820238121,0.09114702940588118,426.0062597146141,88.01281601905117,-2.6003723284313027
36.3939256411586,0.09133906781356271,426.2629037916791,88.01281601905117,-2.6003723284313027
36.53165703095791,0.09168473694738949,426.7243334517877,88.01281601905117,-2.6003723284313027
36.67704016463495,0.0920496099219844,427.21066264171054,88.01281601905117,-2.6003723284313027
36.85303027382295,0.09249129825965194,427.798372186185,88.01281601905117,-2.6003723284313027
36.9984134075,0.09285617123424686,428.283046242134,88.01281601905117,-2.6003723284313027
37.15910002893252,0.09325945189037808,428.8178752974353,88.01281601905117,-2.6003723284313027
37.411607576897914,0.09389317863572715,429.65650220495115,88.01281601905117,-2.6003723284313027
37.694722100374264,0.09460372074414883,430.59416019185966,88.01281601905117,-2.6003723284313027
37.801846514662614,0.09487257451490298,430.9482329610205,88.01281601905117,-2.6003723284313027
37.870712209562264,0.09504540908181637,431.17564454566866,88.01281601905117,-2.6003723284313027
38.00844359936157,0.09539107821564313,431.6299844571005,88.01281601905117,-2.6003723284313027
38.17678196467183,0.09581356271254252,432.18441775218287,88.01281601905117,-2.6003723284313027
38.345120329982095,0.0962360472094419,432.73789841341977,88.01281601905117,-2.6003723284313027
38.44459300039271,0.0964856971394279,433.06450975086847,88.01281601905117,-2.6003723284313027
38.521110439170094,0.09667773554710943,433.31552501985806,88.01281601905117,-2.6003723284313027
38.628234853458444,0.09694658931786358,433.66661995285745,88.01281601905117,-2.6003723284313027
38.6588418289694,0.09702340468093619,433.76686301852334,88.01281601905117,-2.6003723284313027
38.750662755502276,0.09725385077015404,434.0674066674294,88.01281601905117,-2.6003723284313027
38.819528450401926,0.09742668533706741,434.2926321728382,88.01281601905117,-2.6003723284313027
38.88839414530158,0.0975995199039808,434.51770190785885,88.01281601905117,-2.6003723284313027
39.35515052184367,0.09877095419083817,436.03909813762783,88.01281601905117,-2.6003723284313027
39.622961557564544,0.09944308861772355,436.9088530488991,88.01281601905117,-2.6003723284313027
39.668872020830975,0.09955831166233248,437.05772339217066,88.01281601905117,-2.6003723284313027
39.730085971852894,0.0997119423884777,437.2561127004264,88.01281601905117,-2.6003723284313027
39.753041203486106,0.09976955391078215,437.33047795263076,88.01281601905117,-2.6003723284313027
39.78364817899706,0.09984636927385478,437.42960557606364,88.01281601905117,-2.6003723284313027