File: datasets/aisi_316_L/data/M1/train_81.csv
Time(s),Strain(%),Stress(MPa),Temp(C),Log_SR(s-1)
0.0,0.0,0.0,107.76438366849065,1.989377656444871
7.378275033136876e-08,7.2e-06,1.3866343875,107.76438366849065,1.989377656444871
2.049520842538021e-07,1.9999999999999998e-05,3.8517621875,107.76438366849065,1.989377656444871
2.2134825099410628e-07,2.16e-05,4.1599031625,107.76438366849065,1.989377656444871
2.9513100132547506e-07,2.88e-05,5.54653755,107.76438366849065,1.989377656444871
5.246773356897334e-07,5.12e-05,9.8605112,107.76438366849065,1.989377656444871
8.362045037555126e-07,8.159999999999999e-05,15.715189724999998,107.76438366849065,1.989377656444871
8.689968372361209e-07,8.48e-05,16.331471675,107.76438366849065,1.989377656444871
1.0329585046391627e-06,0.0001008,19.412881425,107.76438366849065,1.989377656444871
1.164127838561596e-06,0.0001136,21.878009225,107.76438366849065,1.989377656444871
1.3854760895557024e-06,0.0001352,26.0379123875,107.76438366849065,1.989377656444871
1.541239673588592e-06,0.0001504,28.96525165,107.76438366849065,1.989377656444871
1.6068243405498085e-06,0.0001568,30.197815549999998,107.76438366849065,1.989377656444871
1.7215975077319376e-06,0.000168,32.354802375,107.76438366849065,1.989377656444871
1.754389841212546e-06,0.0001712,32.971084325,107.76438366849065,1.989377656444871
1.9757380922066524e-06,0.0001928,37.1309874875,107.76438366849065,1.989377656444871
2.1642940097201503e-06,0.00021119999999999998,40.6746087,107.76438366849065,1.989377656444871
2.2790671769022793e-06,0.00022239999999999998,42.831595525,107.76438366849065,1.989377656444871
2.3856422607142568e-06,0.0002328,44.8345118625,107.76438366849065,1.989377656444871
2.6889713454098836e-06,0.0002624,50.5351199,107.76438366849065,1.989377656444871
2.8119425959621652e-06,0.0002744,52.8461772125,107.76438366849065,1.989377656444871
2.9595080966249023e-06,0.00028879999999999997,55.619445987499994,107.76438366849065,1.989377656444871
3.008696596845815e-06,0.0002936,56.543868912499995,107.76438366849065,1.989377656444871
3.098875513917488e-06,0.0003024,58.238644275,107.76438366849065,1.989377656444871
3.2792333480608336e-06,0.00031999999999999997,61.628195,107.76438366849065,1.989377656444871
3.525175849165396e-06,0.00034399999999999996,66.25030962499999,107.76438366849065,1.989377656444871
3.6399490163475253e-06,0.00035519999999999996,68.40729644999999,107.76438366849065,1.989377656444871
3.902287684192392e-06,0.0003808,73.33755205,107.76438366849065,1.989377656444871
3.959674267783457e-06,0.00038639999999999996,74.4160454625,107.76438366849065,1.989377656444871
4.082645518335738e-06,0.0003984,76.72710277499999,107.76438366849065,1.989377656444871
4.459757353362733e-06,0.00043519999999999995,83.81434519999999,107.76438366849065,1.989377656444871
4.615520937395624e-06,0.0004504,86.7416844625,107.76438366849065,1.989377656444871
4.648313270876232e-06,0.00045359999999999997,87.35796641249999,107.76438366849065,1.989377656444871
4.787680688168817e-06,0.00046719999999999997,89.97716469999999,107.76438366849065,1.989377656444871
5.050019356013683e-06,0.0004927999999999999,94.90742029999998,107.76438366849065,1.989377656444871
5.164792523195813e-06,0.000504,97.064407125,107.76438366849065,1.989377656444871
5.238575273527182e-06,0.0005112,98.4510415125,107.76438366849065,1.989377656444871
5.46812160789144e-06,0.0005336,102.76501516249999,107.76438366849065,1.989377656444871
5.656677525404939e-06,0.000552,106.30863637499999,107.76438366849065,1.989377656444871
5.804243026067676e-06,0.0005664,109.08190515,107.76438366849065,1.989377656444871
6.0665816939125425e-06,0.000592,114.01216074999999,107.76438366849065,1.989377656444871
6.181354861094672e-06,0.0006032,116.16914757500001,107.76438366849065,1.989377656444871
6.492882029160451e-06,0.0006336,122.02382610000001,107.76438366849065,1.989377656444871
6.861795780817295e-06,0.0006696,128.9569980375,107.76438366849065,1.989377656444871
6.976568947999424e-06,0.0006808,131.1139848625,107.76438366849065,1.989377656444871
7.017559364850184e-06,0.0006848,131.8843373,107.76438366849065,1.989377656444871
7.091342115181554e-06,0.000692,133.2709716875,107.76438366849065,1.989377656444871
7.2471056992144425e-06,0.0007072,136.19831094999998,107.76438366849065,1.989377656444871
7.738990701423566e-06,0.0007551999999999999,145.4425402,107.76438366849065,1.989377656444871
7.919348535566913e-06,0.0007727999999999999,148.832090925,107.76438366849065,1.989377656444871
7.968537035787826e-06,0.0007775999999999999,149.75651384999998,107.76438366849065,1.989377656444871
8.099706369710259e-06,0.0007903999999999999,152.22164164999998,107.76438366849065,1.989377656444871
8.280064203853605e-06,0.000808,155.611192375,107.76438366849065,1.989377656444871
8.509610538217863e-06,0.0008303999999999999,159.92516602499998,107.76438366849065,1.989377656444871
8.591591371919385e-06,0.0008384,161.4658709,107.76438366849065,1.989377656444871
8.665374122250753e-06,0.0008456,162.85250528749998,107.76438366849065,1.989377656444871
8.92771279009562e-06,0.0008711999999999999,167.7827608875,107.76438366849065,1.989377656444871
9.132664874349422e-06,0.0008912,171.634523075,107.76438366849065,1.989377656444871
9.231041874791248e-06,0.0009008,173.483368925,107.76438366849065,1.989377656444871
9.329418875233073e-06,0.0009104,175.332214775,107.76438366849065,1.989377656444871
9.493380542636115e-06,0.0009264,178.413624525,107.76438366849065,1.989377656444871
9.599955626448092e-06,0.0009368,180.4165408625,107.76438366849065,1.989377656444871
1.0018057878325847e-05,0.0009776,188.27413572499998,107.76438366849065,1.989377656444871
1.0075444461916913e-05,0.0009832,189.3526291375,107.76438366849065,1.989377656444871
1.014922721224828e-05,0.0009904,190.739263525,107.76438366849065,1.989377656444871
1.04197639634633e-05,0.0010168,195.8235896125,107.76438366849065,1.989377656444871
1.0723093048158925e-05,0.0010463999999999998,201.52419764999996,107.76438366849065,1.989377656444871
1.0796875798490295e-05,0.0010536,202.9108320375,107.76438366849065,1.989377656444871
1.1001827882744096e-05,0.0010735999999999999,206.762594225,107.76438366849065,1.989377656444871
1.1100204883185921e-05,0.0010831999999999999,208.61144007499996,107.76438366849065,1.989377656444871
1.1305156967439724e-05,0.0011032,212.46320226249998,107.76438366849065,1.989377656444871
1.1690466885836873e-05,0.0011408,219.70451517499998,107.76438366849065,1.989377656444871
1.2026588304013108e-05,0.0011736,226.02140516249997,107.76438366849065,1.989377656444871
1.211676722108478e-05,0.0011824,227.71618052499997,107.76438366849065,1.989377656444871
1.2411898222410256e-05,0.0012112,233.26271807499998,107.76438366849065,1.989377656444871
1.255126563970284e-05,0.0012247999999999998,235.88191636249996,107.76438366849065,1.989377656444871
1.266603880688497e-05,0.001236,238.03890318749998,107.76438366849065,1.989377656444871
1.2911981307989532e-05,0.0012599999999999998,242.66101781249998,107.76438366849065,1.989377656444871
1.3280895059646376e-05,0.0012959999999999998,249.59418974999997,107.76438366849065,1.989377656444871
1.3625214561192765e-05,0.0013296,256.065150225,107.76438366849065,1.989377656444871
1.3731789645004742e-05,0.00134,258.0680665625,107.76438366849065,1.989377656444871
1.3871157062297326e-05,0.0013536,258.5849456822109,107.76438366849065,1.989377656444871
1.3985930229479457e-05,0.0013648,258.6675960317433,107.76438366849065,1.989377656444871
1.439583439798706e-05,0.0014047999999999999,258.96064064572187,107.76438366849065,1.989377656444871
1.4469617148318428e-05,0.0014119999999999998,259.01304122944714,107.76438366849065,1.989377656444871
1.4617182648981168e-05,0.0014264,259.11753081715756,107.76438366849065,1.989377656444871
1.4756550066273752e-05,0.0014399999999999999,259.21583831861506,107.76438366849065,1.989377656444871
1.4863125150085729e-05,0.0014504,259.2907705152604,107.76438366849065,1.989377656444871
1.5191048484891814e-05,0.0014824,259.5200275718105,107.76438366849065,1.989377656444871
1.5510773736327744e-05,0.0015136,259.7417020836991,107.76438366849065,1.989377656444871
1.568293348710094e-05,0.0015304,259.86032682573114,107.76438366849065,1.989377656444871
1.5789508570912916e-05,0.0015408,259.93350673174984,107.76438366849065,1.989377656444871
1.588788557135474e-05,0.0015504,260.0008866155136,107.76438366849065,1.989377656444871
1.592067790483535e-05,0.0015536,260.0233103926749,107.76438366849065,1.989377656444871
1.597806448842641e-05,0.0015592,260.0625087074284,107.76438366849065,1.989377656444871
1.608463957223839e-05,0.0015696,260.1351602176506,107.76438366849065,1.989377656444871
1.6232205072901128e-05,0.001584,260.2354454419852,107.76438366849065,1.989377656444871
1.6387968656934016e-05,0.0015991999999999998,260.3409170988059,107.76438366849065,1.989377656444871
1.6535534157596756e-05,0.0016136,260.4404775503508,107.76438366849065,1.989377656444871
1.6822467075552076e-05,0.0016416,260.63308090956895,107.76438366849065,1.989377656444871
1.6888051742513294e-05,0.001648,260.6769241386845,107.76438366849065,1.989377656444871
1.7117598076877552e-05,0.0016703999999999998,260.8298552401796,107.76438366849065,1.989377656444871
1.7338946327871658e-05,0.001692,260.9765688254728,107.76438366849065,1.989377656444871
1.7519304162015005e-05,0.0017096,261.09557389718105,107.76438366849065,1.989377656444871
1.774065241300911e-05,0.0017312,261.2409745434272,107.76438366849065,1.989377656444871
1.7945604497262913e-05,0.0017511999999999998,261.37497517078026,107.76438366849065,1.989377656444871
1.797019874737337e-05,0.0017536,261.3910150396415,107.76438366849065,1.989377656444871
1.8019387247594283e-05,0.0017584,261.4230691161847,107.76438366849065,1.989377656444871
1.820794316510778e-05,0.0017767999999999998,261.5456282399348,107.76438366849065,1.989377656444871
1.82899239988093e-05,0.0017848,261.5987603172747,107.76438366849065,1.989377656444871
1.840469716599143e-05,0.0017959999999999999,261.672989451995,107.76438366849065,1.989377656444871
1.888018600146025e-05,0.0018424,261.9786064507663,107.76438366849065,1.989377656444871
1.891297833494086e-05,0.0018456,261.9995721701583,107.76438366849065,1.989377656444871
1.898676108527223e-05,0.0018528,262.0466932732478,107.76438366849065,1.989377656444871
1.9085138085714054e-05,0.0018624,262.1094104723099,107.76438366849065,1.989377656444871
1.923270358637679e-05,0.0018767999999999999,262.20325038602624,107.76438366849065,1.989377656444871
1.9699994338475458e-05,0.0019223999999999999,262.4985744059925,107.76438366849065,1.989377656444871
1.974098475532622e-05,0.0019264,262.5243489722992,107.76438366849065,1.989377656444871
1.997053108969048e-05,0.0019487999999999999,262.6683026746002,107.76438366849065,1.989377656444871
2.0052511923391997e-05,0.0019568,262.7195581352746,107.76438366849065,1.989377656444871
2.0265662091015954e-05,0.0019776,262.85244132030715,107.76438366849065,1.989377656444871
2.0511604592120516e-05,0.0020016,263.0050926305988,107.76438366849065,1.989377656444871
2.084772601029675e-05,0.0020344,263.2125666404675,107.76438366849065,1.989377656444871
2.0921508760628117e-05,0.0020415999999999998,263.25793462720276,107.76438366849065,1.989377656444871
2.096249917747888e-05,0.0020456,263.2831121007733,107.76438366849065,1.989377656444871
2.112646084488192e-05,0.0020616,263.38363058081507,107.76438366849065,1.989377656444871
2.1339611012505874e-05,0.0020824,263.51385092506405,107.76438366849065,1.989377656444871
2.1405195679467092e-05,0.0020888,263.55381653890436,107.76438366849065,1.989377656444871
2.163474201383135e-05,0.0021111999999999997,263.69332165280287,107.76438366849065,1.989377656444871
2.1651138180571653e-05,0.0021127999999999997,263.7032641592297,107.76438366849065,1.989377656444871
2.1692128597422416e-05,0.0021168,263.7281075869918,107.76438366849065,1.989377656444871
2.1888882598306066e-05,0.002136,263.84710212060656,107.76438366849065,1.989377656444871
2.2175815516261387e-05,0.0021639999999999997,264.0198907717083,107.76438366849065,1.989377656444871
2.233977718366443e-05,0.00218,264.1182356400647,107.76438366849065,1.989377656444871
2.2413559933995797e-05,0.0021872,264.1623989502957,107.76438366849065,1.989377656444871
2.2700492851951124e-05,0.0022152,264.33360887273204,107.76438366849065,1.989377656444871
2.2757879435542184e-05,0.0022207999999999998,264.3677493514684,107.76438366849065,1.989377656444871
2.2889048769464623e-05,0.0022336,264.4456589052828,107.76438366849065,1.989377656444871
2.3159585520679637e-05,0.00226,264.60579958878816,107.76438366849065,1.989377656444871
2.324156635438116e-05,0.002268,264.65418281492043,107.76438366849065,1.989377656444871
2.343012227189466e-05,0.0022864,264.76521235061114,107.76438366849065,1.989377656444871
2.35940839392977e-05,0.0023024,264.8614768188056,107.76438366849065,1.989377656444871
2.3651470522888763e-05,0.0023079999999999997,264.8951076998702,107.76438366849065,1.989377656444871
2.3766243690070892e-05,0.0023192,264.96227414194624,107.76438366849065,1.989377656444871
2.4020384274545605e-05,0.0023439999999999997,265.11055129228396,107.76438366849065,1.989377656444871
2.4085968941506823e-05,0.0023504,265.14871688643854,107.76438366849065,1.989377656444871
2.443028844305321e-05,0.002384,265.34842519845637,107.76438366849065,1.989377656444871
2.4520467360124887e-05,0.0023928,265.40054797826747,107.76438366849065,1.989377656444871
2.4709023277638386e-05,0.0024112,265.50929101227246,107.76438366849065,1.989377656444871
2.489757919515188e-05,0.0024296,265.6177108922472,107.76438366849065,1.989377656444871
2.49795600288534e-05,0.0024376,265.6647500378467,107.76438366849065,1.989377656444871
2.5069738945925076e-05,0.0024464,265.7164236130667,107.76438366849065,1.989377656444871
2.5225502529957964e-05,0.0024616,265.80550755066344,107.76438366849065,1.989377656444871
2.5627208615095417e-05,0.0025008,266.0342658940408,107.76438366849065,1.989377656444871
2.5864953032829823e-05,0.0025239999999999998,266.16899477848153,107.76438366849065,1.989377656444871
2.604531086697317e-05,0.0025415999999999998,266.27088096559817,107.76438366849065,1.989377656444871
2.6168282117525454e-05,0.0025536,266.34019110917814,107.76438366849065,1.989377656444871
2.6266659117967276e-05,0.0025632,266.3955478095742,107.76438366849065,1.989377656444871
2.6373234201779253e-05,0.0025735999999999997,266.4554264017222,107.76438366849065,1.989377656444871
2.6684761369845036e-05,0.002604,266.6299174050502,107.76438366849065,1.989377656444871
2.682412878713762e-05,0.0026176,266.70772177451425,107.76438366849065,1.989377656444871
2.706187320487203e-05,0.0026408,266.84008399798574,107.76438366849065,1.989377656444871
2.725862720575568e-05,0.00266,266.94928253176295,107.76438366849065,1.989377656444871
2.734880612282735e-05,0.0026688,266.9992290848345,107.76438366849065,1.989377656444871
2.7553758207081157e-05,0.0026888,267.11250572202584,107.76438366849065,1.989377656444871
2.7611144790672223e-05,0.0026944,267.1441642330662,107.76438366849065,1.989377656444871
2.7668531374263282e-05,0.0026999999999999997,267.17579709304033,107.76438366849065,1.989377656444871
2.7684927541003586e-05,0.0027015999999999997,267.18483035196647,107.76438366849065,1.989377656444871
2.784888920840663e-05,0.0027175999999999997,267.2750484820885,107.76438366849065,1.989377656444871
2.8070237459400735e-05,0.0027392,267.3965150466567,107.76438366849065,1.989377656444871
2.851293396138895e-05,0.0027824,267.63833327676144,107.76438366849065,1.989377656444871
2.8644103295311383e-05,0.0027952,267.70970134154595,107.76438366849065,1.989377656444871
2.8693291795532298e-05,0.0028,267.73643149138354,107.76438366849065,1.989377656444871
2.8906441963156252e-05,0.0028208,267.85205624423855,107.76438366849065,1.989377656444871
2.896382854674731e-05,0.0028263999999999997,267.8831291126972,107.76438366849065,1.989377656444871
2.918517679774142e-05,0.002848,268.0027573647973,107.76438366849065,1.989377656444871
2.9521298215917656e-05,0.0028807999999999998,268.18374067162097,107.76438366849065,1.989377656444871
2.9718052216801306e-05,0.0029,268.28930922736384,107.76438366849065,1.989377656444871
2.9882013884204346e-05,0.0029159999999999998,268.377074959749,107.76438366849065,1.989377656444871
3.0185342968899977e-05,0.0029456,268.5389480355124,107.76438366849065,1.989377656444871
3.048047397022545e-05,0.0029744,268.6958383623039,107.76438366849065,1.989377656444871
3.063623755425834e-05,0.0029896,268.77840267729744,107.76438366849065,1.989377656444871
3.0857585805252444e-05,0.0030112,268.8954498443975,107.76438366849065,1.989377656444871
3.0947764722324114e-05,0.0030199999999999997,268.94304179637334,107.76438366849065,1.989377656444871
3.123469764027944e-05,0.003048,269.0941121725086,107.76438366849065,1.989377656444871
3.147244205801385e-05,0.0030712,269.2188751851393,107.76438366849065,1.989377656444871
3.151343247486461e-05,0.0030751999999999997,269.2403488467412,107.76438366849065,1.989377656444871
3.162000755867659e-05,0.0030856,269.2961294484706,107.76438366849065,1.989377656444871
3.177577114270948e-05,0.0031008,269.37752322936353,107.76438366849065,1.989377656444871
3.180856347619009e-05,0.003104,269.3946389176514,107.76438366849065,1.989377656444871
3.196432706022298e-05,0.0031192,269.4758446473206,107.76438366849065,1.989377656444871
3.212828872762602e-05,0.0031352,269.56115781184485,107.76438366849065,1.989377656444871
3.219387339458724e-05,0.0031416,269.59523551363844,107.76438366849065,1.989377656444871
3.2308646561769364e-05,0.0031528,269.654806415053,107.76438366849065,1.989377656444871
3.247260822917241e-05,0.0031688,269.73976473507435,107.76438366849065,1.989377656444871
3.262837181320529e-05,0.0031839999999999998,269.8203203111968,107.76438366849065,1.989377656444871
3.295629514801138e-05,0.0032159999999999997,269.98942240547996,107.76438366849065,1.989377656444871
3.3030077898342745e-05,0.0032232,270.0273797931699,107.76438366849065,1.989377656444871
3.3276020399447313e-05,0.0032472,270.15366627304536,107.76438366849065,1.989377656444871
3.3333406983038376e-05,0.0032527999999999997,270.1830806777764,107.76438366849065,1.989377656444871
3.335800123314883e-05,0.0032551999999999998,270.1956808047499,107.76438366849065,1.989377656444871
3.3571151400772786e-05,0.003276,270.3047305577838,107.76438366849065,1.989377656444871
3.377610348502659e-05,0.003296,270.4093317247061,107.76438366849065,1.989377656444871
3.381709390187735e-05,0.0033,270.43022222160835,107.76438366849065,1.989377656444871
3.411222490320282e-05,0.0033288,270.58034335272487,107.76438366849065,1.989377656444871
3.425159232049541e-05,0.0033423999999999997,270.6510577336292,107.76438366849065,1.989377656444871
3.4382761654417844e-05,0.0033552,270.71751000641547,107.76438366849065,1.989377656444871
3.4440148238008906e-05,0.0033607999999999997,270.74655177784234,107.76438366849065,1.989377656444871
3.454672332182089e-05,0.0033712,270.8004364751895,107.76438366849065,1.989377656444871
3.4677892655743316e-05,0.003384,270.86666718733267,107.76438366849065,1.989377656444871
3.494842940695833e-05,0.0034103999999999996,271.0029602663225,107.76438366849065,1.989377656444871
3.516157957458229e-05,0.0034311999999999997,271.1100531023217,107.76438366849065,1.989377656444871
3.530914507524503e-05,0.0034456,271.18404602590806,107.76438366849065,1.989377656444871
3.536653165883609e-05,0.0034511999999999998,271.21278846986127,107.76438366849065,1.989377656444871
3.5497700992758526e-05,0.0034639999999999996,271.27841727089856,107.76438366849065,1.989377656444871
3.556328565971974e-05,0.0034704,271.3111961997237,107.76438366849065,1.989377656444871
3.580922816082431e-05,0.0034944,271.43390778057886,107.76438366849065,1.989377656444871
3.594859557811689e-05,0.003508,271.50329843385555,107.76438366849065,1.989377656444871
3.602237832844826e-05,0.0035152,271.53999218323986,107.76438366849065,1.989377656444871
3.6358499746624494e-05,0.003548,271.70678307098143,107.76438366849065,1.989377656444871
3.6604442247729056e-05,0.0035719999999999997,271.8284444421581,107.76438366849065,1.989377656444871
3.692416749916499e-05,0.0036032,271.9861286818697,107.76438366849065,1.989377656444871
3.715371383352924e-05,0.0036255999999999997,272.09900966684233,107.76438366849065,1.989377656444871
3.7186506167009856e-05,0.0036287999999999997,272.115113290717,107.76438366849065,1.989377656444871
3.7293081250821836e-05,0.0036392,272.1674118612073,107.76438366849065,1.989377656444871
3.744884483485472e-05,0.0036544,272.2437435055123,107.76438366849065,1.989377656444871
3.7563618002036846e-05,0.0036655999999999998,272.299908666717,107.76438366849065,1.989377656444871
3.7661995002478675e-05,0.0036752,272.3479969855183,107.76438366849065,1.989377656444871
3.7940729837063844e-05,0.0037024,272.48398190965156,107.76438366849065,1.989377656444871
3.8203068504908716e-05,0.003728,272.61161223970834,107.76438366849065,1.989377656444871
3.835063400557145e-05,0.0037424,272.68325408287444,107.76438366849065,1.989377656444871
3.8490001422864037e-05,0.003756,272.75081717207615,107.76438366849065,1.989377656444871
3.859657650667602e-05,0.0037664,272.8024187076997,107.76438366849065,1.989377656444871
3.8612972673416314e-05,0.0037679999999999996,272.8103524706227,107.76438366849065,1.989377656444871
3.865396309026708e-05,0.0037719999999999997,272.83018113191304,107.76438366849065,1.989377656444871
3.874414200733875e-05,0.0037808,272.8737753435489,107.76438366849065,1.989377656444871
3.912125384236575e-05,0.0038176,273.05565131100775,107.76438366849065,1.989377656444871
3.925242317628818e-05,0.0038304,273.11875207586604,107.76438366849065,1.989377656444871
3.953115801087335e-05,0.0038575999999999997,273.2525688005707,107.76438366849065,1.989377656444871
3.9654129261425636e-05,0.0038696,273.31148855360414,107.76438366849065,1.989377656444871
3.9982052596231716e-05,0.0039016,273.46826055650536,107.76438366849065,1.989377656444871
4.008862768004369e-05,0.003912,273.5191033808099,107.76438366849065,1.989377656444871
4.0473937598440846e-05,0.0039496,273.7024815749195,107.76438366849065,1.989377656444871
4.068708776606479e-05,0.0039704,273.8036323003062,107.76438366849065,1.989377656444871
4.09248321837992e-05,0.0039936,273.91621077149466,107.76438366849065,1.989377656444871
4.354873052498272e-05,0.004249649929985997,275.14221607156105,107.76438366849065,1.989377656444871
5.161725826676073e-05,0.0050370074014802965,278.74300600449095,107.76438366849065,1.989377656444871
5.594671217698308e-05,0.0054594918983796765,280.5840969931638,107.76438366849065,1.989377656444871
6.106333952542766e-05,0.00595879175835167,282.68971904254744,107.76438366849065,1.989377656444871
6.185051296364991e-05,0.006035607121424285,283.0074476385746,107.76438366849065,1.989377656444871
6.480241335698332e-05,0.006323664732946589,284.1851394791836,107.76438366849065,1.989377656444871
6.736072703120562e-05,0.006573314662932587,285.1889784408983,107.76438366849065,1.989377656444871
7.365811453698357e-05,0.007187837567513502,287.59860213495745,107.76438366849065,1.989377656444871
7.542925477298362e-05,0.007360672134426885,288.26165039921653,107.76438366849065,1.989377656444871
7.641322157076143e-05,0.007456691338267653,288.6273860539688,107.76438366849065,1.989377656444871
8.093946884053933e-05,0.007898379675935187,290.28666121614117,107.76438366849065,1.989377656444871
8.723685634631729e-05,0.008512902580516103,292.53621176362395,107.76438366849065,1.989377656444871
9.2747070413873e-05,0.009050610122024405,294.45308192233404,107.76438366849065,1.989377656444871
9.471500400942862e-05,0.009242648529705941,295.1268448609133,107.76438366849065,1.989377656444871
9.786369776231759e-05,0.0095499099819964,296.1936185138124,107.76438366849065,1.989377656444871
9.825728448142872e-05,0.009588317663532707,296.3260175420377,107.76438366849065,1.989377656444871
0.0001043578786276511,0.010183636727345468,298.3524598634045,107.76438366849065,1.989377656444871
0.00011026167941431793,0.010759751950390077,300.26997568582146,107.76438366849065,1.989377656444871
0.00011262319972898468,0.01099019803960792,301.025717134462,107.76438366849065,1.989377656444871
0.00011439433996498474,0.011163032606521305,301.58847393775295,107.76438366849065,1.989377656444871
0.00011970776067298487,0.011681536307261452,303.2567001380702,107.76438366849065,1.989377656444871
0.0001236436278640961,0.012065613122624524,304.4738613242288,107.76438366849065,1.989377656444871
0.00012639873489787395,0.012334466893378675,305.31689810954316,107.76438366849065,1.989377656444871
0.00013151536224631854,0.01283376675335067,306.8637635572932,107.76438366849065,1.989377656444871
0.00013368008920142972,0.01304500900180036,307.5111201260099,107.76438366849065,1.989377656444871
0.00013643519623520757,0.013313862772554511,308.3291458714812,107.76438366849065,1.989377656444871
0.00013820633647120762,0.013486697339467894,308.85161946424745,107.76438366849065,1.989377656444871
0.00014017427006676324,0.01367873574714943,309.42909260210405,107.76438366849065,1.989377656444871
0.00014214220366231886,0.013870774154830966,310.0034124265839,107.76438366849065,1.989377656444871
0.0001448973106960967,0.014139627925585117,310.80227747422674,107.76438366849065,1.989377656444871
0.00014529089741520783,0.014178035607121425,310.9159155806149,107.76438366849065,1.989377656444871
0.00015040752476365243,0.01467733546709342,312.3824525384883,107.76438366849065,1.989377656444871
0.0001525722517187636,0.01488857771554311,312.99703815979467,107.76438366849065,1.989377656444871
0.00016457664665165284,0.01606001200240048,316.3454005654446,107.76438366849065,1.989377656444871
0.00016615099352809733,0.01621364272854571,316.7773534825945,107.76438366849065,1.989377656444871
0.00017599066150587536,0.01717383476695339,319.4417642088961,107.76438366849065,1.989377656444871
0.00018701108964098677,0.018249249849969992,322.3578401550724,107.76438366849065,1.989377656444871
0.00018838864315787573,0.01838367673534707,322.71757702488594,107.76438366849065,1.989377656444871
0.00018937260995565352,0.018479695939187836,322.9739041151503,107.76438366849065,1.989377656444871
0.0001992122779334316,0.01943988797759552,325.5092352691281,107.76438366849065,1.989377656444871
0.00020590325215832066,0.02009281856371274,327.20541895160403,107.76438366849065,1.989377656444871
0.0002072808056752096,0.02022724544908982,327.55194949231463,107.76438366849065,1.989377656444871
0.00021042949942809858,0.020534506901380277,328.34066415628365,107.76438366849065,1.989377656444871
0.0002127910197427653,0.02076495299059812,328.92918313920455,107.76438366849065,1.989377656444871
0.00021456215997876535,0.0209377875575115,329.36890221250525,107.76438366849065,1.989377656444871
0.00021672688693387653,0.021149029805961193,329.9044189059985,107.76438366849065,1.989377656444871
0.00022302427443965448,0.02176355271054211,331.4505500368726,107.76438366849065,1.989377656444871
0.00022538579475432123,0.021993998799759953,332.0259475393487,107.76438366849065,1.989377656444871
0.00022735372834987685,0.02218603720744149,332.5036515515815,107.76438366849065,1.989377656444871
0.00023069921546232136,0.0225125025005001,333.3120638782119,107.76438366849065,1.989377656444871
0.0002381773631254327,0.023242248449689938,335.1027512689212,107.76438366849065,1.989377656444871
0.0002446715439907662,0.023875975195039006,336.64010454227736,107.76438366849065,1.989377656444871
0.00024762344438409965,0.024164032806561313,337.333632199899,107.76438366849065,1.989377656444871
0.00025510159204721094,0.02489377875575115,339.07629117049754,107.76438366849065,1.989377656444871
0.0002610053928338778,0.02546989397879576,340.43803971323774,107.76438366849065,1.989377656444871
0.00026572843346321125,0.025930786157231447,341.51880864582864,107.76438366849065,1.989377656444871
0.0002684835404969891,0.0261996399279856,342.1457974636179,107.76438366849065,1.989377656444871
0.0002716322342498781,0.026506901380276057,342.8592916967758,107.76438366849065,1.989377656444871
0.0002781264151152116,0.027140628125625125,344.3207665093648,107.76438366849065,1.989377656444871
0.00027891358855343384,0.02721744348869774,344.4970060720943,107.76438366849065,1.989377656444871
0.00028304624910410064,0.027620724144828968,345.41910047394555,107.76438366849065,1.989377656444871
0.00028422700926143403,0.02773594718943789,345.68158967810064,107.76438366849065,1.989377656444871
0.0002852109760592118,0.027831966393278656,345.90000597480486,107.76438366849065,1.989377656444871
0.000287375703014323,0.028043208641728348,346.3794900517894,107.76438366849065,1.989377656444871
0.000290524396767212,0.028350470094018806,347.0744145057647,107.76438366849065,1.989377656444871
0.0002952474373965454,0.02881136227245449,348.1113188891974,107.76438366849065,1.989377656444871
0.0002989865112281011,0.02917623524704941,348.9276207235523,107.76438366849065,1.989377656444871
0.00030036406474499,0.029310662132426484,349.2273586598439,107.76438366849065,1.989377656444871
0.0003025287917001012,0.029521904380876176,349.69729449574515,107.76438366849065,1.989377656444871
0.0003044967252956568,0.029713942788557712,350.12337212237134,107.76438366849065,1.989377656444871
0.00030823579912721245,0.03007881576315263,350.92997250757486,107.76438366849065,1.989377656444871
0.00031177807959921255,0.030424484896979395,351.6906074329977,107.76438366849065,1.989377656444871
0.00031394280655432376,0.030635727145429087,352.1537809586002,107.76438366849065,1.989377656444871
0.00031591074014987935,0.030827765553110623,352.5737680809339,107.76438366849065,1.989377656444871
0.000317878673745435,0.03101980396079216,352.9927360898072,107.76438366849065,1.989377656444871
0.00032181454093654617,0.03140388077615523,353.82764967558717,107.76438366849065,1.989377656444871
0.00032791513508276856,0.03199919983996799,355.1139382916183,107.76438366849065,1.989377656444871
0.0003300798620378797,0.03221044208841768,355.56811548917057,107.76438366849065,1.989377656444871
0.0003322445889929909,0.032421684336867373,356.02113251449066,107.76438366849065,1.989377656444871
0.00033519648938632433,0.03270974194838968,356.63703223935903,107.76438366849065,1.989377656444871
0.0003359836628245466,0.032786557311462294,356.8009144529123,107.76438366849065,1.989377656444871
0.00033952594329654664,0.033132226445289056,357.5365391726928,107.76438366849065,1.989377656444871
0.00034267463704943567,0.033439487897579515,358.18791874198797,107.76438366849065,1.989377656444871
0.00034661050424054685,0.03382356471294259,358.99886994918995,107.76438366849065,1.989377656444871
0.00034916881791476924,0.03407321464292859,359.5240630567503,107.76438366849065,1.989377656444871
0.0003511367515103248,0.03426525305061012,359.9270372000232,107.76438366849065,1.989377656444871
0.0003540886519036582,0.03455331066213242,360.5298508446019,107.76438366849065,1.989377656444871
0.0003552694120609916,0.03466853370674135,360.7704271423664,107.76438366849065,1.989377656444871
0.000358221312454325,0.034956591318263654,361.37050763428164,107.76438366849065,1.989377656444871
0.00036117321284765845,0.03524464892978596,361.96866267469824,107.76438366849065,1.989377656444871
0.0003647154933196585,0.03559031806361272,362.6839378479683,107.76438366849065,1.989377656444871
0.0003666834269152141,0.035782356471294255,363.080142096645,107.76438366849065,1.989377656444871
0.0003714064675445475,0.03624324864972994,364.0276640137875,107.76438366849065,1.989377656444871
0.0003755391280952143,0.03664652930586117,364.85289746572647,107.76438366849065,1.989377656444871
0.0003771134749716588,0.036800160032006396,365.1663395483303,107.76438366849065,1.989377656444871
0.00037908140856721454,0.03699219843968794,365.55742542845815,107.76438366849065,1.989377656444871
0.0003810493421627701,0.037184236847369476,365.947720306806,107.76438366849065,1.989377656444871
0.0003845916226347702,0.03752990598119624,366.64827582607415,107.76438366849065,1.989377656444871
0.0003920697702978815,0.03825965193038608,368.11901578433014,107.76438366849065,1.989377656444871
0.0004032869917925484,0.03935427085417083,370.30477599945107,107.76438366849065,1.989377656444871
0.00041037155273654873,0.040045609121824366,371.6730467677637,107.76438366849065,1.989377656444871
0.0004125362796916599,0.04025685137027406,372.0892879221564,107.76438366849065,1.989377656444871
0.0004194240472761046,0.04092898579715944,373.40805999099825,107.76438366849065,1.989377656444871
0.0004213919808716601,0.04112102420484097,373.78329716721794,107.76438366849065,1.989377656444871
0.0004237535011863268,0.041351470294058806,374.2326808557136,107.76438366849065,1.989377656444871
0.0004298540953325493,0.04194678935787158,375.38909128379674,107.76438366849065,1.989377656444871
0.00043241240900677156,0.04219643928785757,375.872130658679,107.76438366849065,1.989377656444871
0.0004359546894787716,0.042542108421684335,376.53911843479904,107.76438366849065,1.989377656444871
0.00044717191097343867,0.0436367273454691,378.63743619622363,107.76438366849065,1.989377656444871
0.000453272505119661,0.044232046409281855,379.77000430242015,107.76438366849065,1.989377656444871
0.0004572083723107723,0.044616123224644935,380.49753970731643,107.76438366849065,1.989377656444871
0.00046035706606366127,0.04492338467693539,381.07781091713633,107.76438366849065,1.989377656444871
0.00046271858637832793,0.04515383076615323,381.51199908529196,107.76438366849065,1.989377656444871
0.00046901597388410594,0.045768353670734147,382.6656298734854,107.76438366849065,1.989377656444871
0.00047432939459210607,0.046286857371474296,383.63431460568455,107.76438366849065,1.989377656444871
0.00047747808834499504,0.046594118823764755,384.2063531388865,107.76438366849065,1.989377656444871
0.0004800364020192173,0.04684376875375075,384.67005193788225,107.76438366849065,1.989377656444871
0.00048220112897432853,0.04705501100220044,385.0616601738425,107.76438366849065,1.989377656444871
0.0004912536235138844,0.04793838767753551,386.6919210338309,107.76438366849065,1.989377656444871
0.0004995189446152179,0.04874494898979796,388.1702163422321,107.76438366849065,1.989377656444871
0.0005001093246938846,0.048802560512102425,388.2754423924669,107.76438366849065,1.989377656444871
0.000503454811806329,0.04912902580516103,388.87081079594884,107.76438366849065,1.989377656444871
0.0005068002989187737,0.049455491098219645,389.46463824272155,107.76438366849065,1.989377656444871
0.0005107361661098848,0.04983956791358271,390.161305046592,107.76438366849065,1.989377656444871
0.0005150656200201072,0.050262052410482094,390.9252246608057,107.76438366849065,1.989377656444871
0.0005184111071325518,0.05058851770354071,391.5138122306671,107.76438366849065,1.989377656444871
0.0005201822473685518,0.050761352270454085,391.8248176023804,107.76438366849065,1.989377656444871
0.0005252988747169964,0.05126065213042609,392.72096613648483,107.76438366849065,1.989377656444871
0.0005288411551889965,0.05160632126425285,393.33938344474086,107.76438366849065,1.989377656444871
0.0005323834356609966,0.051951990398079614,393.95618735806147,107.76438366849065,1.989377656444871
0.0005373032696498857,0.05243208641728346,394.81021080155966,107.76438366849065,1.989377656444871
0.0005384840298072191,0.052547309461892386,395.0147219670623,107.76438366849065,1.989377656444871
0.0005477333177063304,0.0534498899779956,396.6107194561148,107.76438366849065,1.989377656444871
0.0005493076645827748,0.05360352070414083,396.8813284226255,107.76438366849065,1.989377656444871
0.0005632799931112196,0.054966993398679734,399.26987223502647,107.76438366849065,1.989377656444871
0.0005707581407743311,0.055696739347869575,400.53874928701003,107.76438366849065,1.989377656444871
0.0005782362884374424,0.05642648529705942,401.8011589084939,107.76438366849065,1.989377656444871
0.0005809913954712201,0.05669533906781356,402.26465008853813,107.76438366849065,1.989377656444871
0.0005847304693027759,0.05706021204240848,402.89230510498237,107.76438366849065,1.989377656444871
0.0005916182368872205,0.05773234646929386,404.0444294293345,107.76438366849065,1.989377656444871
0.0005963412775165539,0.058193238647729545,404.83143580264925,107.76438366849065,1.989377656444871
0.000602638665022332,0.05880776155231046,405.87700658775606,107.76438366849065,1.989377656444871
0.0006077552923707764,0.05930706141228245,406.72339877315943,107.76438366849065,1.989377656444871
0.0006122815396405545,0.059748749749949995,407.4698165185751,107.76438366849065,1.989377656444871
0.0006136590931574434,0.059883176635327065,407.696559595205,107.76438366849065,1.989377656444871
0.0006166109935507767,0.060171234246849364,408.1817702520747,107.76438366849065,1.989377656444871
0.0006238923478543326,0.06088177635527106,409.3747660310758,107.76438366849065,1.989377656444871
0.000628615388483666,0.06134266853370675,410.14569872564084,107.76438366849065,1.989377656444871
0.0006323544623152216,0.061707541508301655,410.75441952151175,107.76438366849065,1.989377656444871
0.000637077502944555,0.06216843368673734,411.52132728513766,107.76438366849065,1.989377656444871
0.0006388486431805552,0.06234126825365073,411.8083456280223,107.76438366849065,1.989377656444871
0.0006402261966974441,0.0624756951390278,412.03136761958166,107.76438366849065,1.989377656444871
0.0006423909236525552,0.06268693738747749,412.381453005097,107.76438366849065,1.989377656444871
0.000647901137720111,0.0632246449289858,413.27050967440215,107.76438366849065,1.989377656444871
0.0006506562447538888,0.06349349869973994,413.7139318338346,107.76438366849065,1.989377656444871
0.0006545921119450001,0.06387757551510302,414.34612391132595,107.76438366849065,1.989377656444871
0.0006555760787427779,0.06397359471894379,414.503940082867,107.76438366849065,1.989377656444871
0.0006665965068778893,0.06504900980196039,416.2652160228962,107.76438366849065,1.989377656444871
0.0006681708537543338,0.06520264052810562,416.51589671967014,107.76438366849065,1.989377656444871
0.0006689580271925561,0.06527945589117824,416.6411506772659,107.76438366849065,1.989377656444871
0.000670729167428556,0.06545229045809162,416.92276210647987,107.76438366849065,1.989377656444871
0.0006730906877432228,0.06568273654730947,417.297793292566,107.76438366849065,1.989377656444871
0.0006756490014174451,0.06593238647729546,417.70349846708797,107.76438366849065,1.989377656444871
0.0006782073150916674,0.06618203640728146,418.10860497033514,107.76438366849065,1.989377656444871
0.0006793880752490009,0.06629725945189038,418.2953761530039,107.76438366849065,1.989377656444871
0.0006825367690018898,0.06660452090418084,418.79281476622197,107.76438366849065,1.989377656444871
0.0006848982893165565,0.06683496699339868,419.16530661470534,107.76438366849065,1.989377656444871
0.0006886373631481121,0.0671998399679936,419.7540626112282,107.76438366849065,1.989377656444871
0.0006898181233054455,0.06731506301260252,419.93972636858456,107.76438366849065,1.989377656444871
0.0006955251307325568,0.06787197439487898,420.8353598226258,107.76438366849065,1.989377656444871
0.0006994609979236681,0.06825605121024206,421.451368852438,107.76438366849065,1.989377656444871
0.000700838551440557,0.06839047809561913,421.6666524463903,107.76438366849065,1.989377656444871
0.0007063487655081126,0.06892818563712742,422.5261416275095,107.76438366849065,1.989377656444871
0.0007110718061374462,0.06938907781556311,423.26076746555077,107.76438366849065,1.989377656444871
0.0007118589795756684,0.06946589317863573,423.3830198554709,107.76438366849065,1.989377656444871
0.0007142204998903351,0.06969633926785357,423.7494610800259,107.76438366849065,1.989377656444871
0.0007175659870027797,0.07002280456091219,424.26777830477585,107.76438366849065,1.989377656444871
0.0007266184815423356,0.07090618123624726,425.6655799881969,107.76438366849065,1.989377656444871
0.0007337030424863357,0.07159751950390078,426.75477975995943,107.76438366849065,1.989377656444871
0.0007348838026436691,0.0717127425485097,426.93591353803293,107.76438366849065,1.989377656444871
0.0007433459171045582,0.07253850770154031,428.23073358885654,107.76438366849065,1.989377656444871
0.0007461010241383361,0.07280736147229447,428.65106072872686,107.76438366849065,1.989377656444871
0.0007565310721947808,0.07382516503300661,430.2368455237035,107.76438366849065,1.989377656444871
0.0007579086257116697,0.07395959191838368,430.4456495291145,107.76438366849065,1.989377656444871
0.0007590893858690031,0.0740748149629926,430.6245066134432,107.76438366849065,1.989377656444871
0.0007626316663410032,0.07442048409681937,431.1604279843702,107.76438366849065,1.989377656444871
0.0007663707401725588,0.07478535707141429,431.7250706311619,107.76438366849065,1.989377656444871
0.0007708969874423367,0.07522704540908182,432.4071499700746,107.76438366849065,1.989377656444871
0.0007730617143974479,0.07543828765753151,432.73280956201194,107.76438366849065,1.989377656444871
0.000777981548386337,0.07591838367673535,433.4716252437945,107.76438366849065,1.989377656444871
0.0007819174155774481,0.07630246049209842,434.06136668855964,107.76438366849065,1.989377656444871
0.0007836885558134483,0.07647529505901181,434.3263725158032,107.76438366849065,1.989377656444871
0.0007844757292516704,0.07655211042208442,434.4440778976223,107.76438366849065,1.989377656444871
0.0007943153972294486,0.07751230246049211,435.9115299893376,107.76438366849065,1.989377656444871
0.0008013999581734487,0.07820364072814563,436.96370912550344,107.76438366849065,1.989377656444871
0.0008073037589601156,0.07877975595119024,437.83775684659304,107.76438366849065,1.989377656444871
0.0008090748991961156,0.07895259051810362,438.0994845965895,107.76438366849065,1.989377656444871
0.0008130107663872269,0.0793366673334667,438.6803031449608,107.76438366849065,1.989377656444871
0.0008153722867018935,0.07956711342268454,439.0282679279212,107.76438366849065,1.989377656444871
0.0008183241870952271,0.07985517103420685,439.46267169157244,107.76438366849065,1.989377656444871
0.000820095327331227,0.08002800560112022,439.7230206165225,107.76438366849065,1.989377656444871
0.0008226536410054494,0.08027765553110623,440.0986933763417,107.76438366849065,1.989377656444871
0.000824621574601005,0.08046969393878776,440.3873624636115,107.76438366849065,1.989377656444871
0.0008261959214774494,0.080623324664933,440.61810433744125,107.76438366849065,1.989377656444871
0.0008356420027361164,0.08154510902180437,441.9989716607715,107.76438366849065,1.989377656444871
0.0008383971097698943,0.08181396279255852,442.4005761740095,107.76438366849065,1.989377656444871
0.0008405618367250053,0.0820252050410082,442.71576161430386,107.76438366849065,1.989377656444871
0.0008431201503992277,0.08227485497099421,443.0878456563594,107.76438366849065,1.989377656444871
0.000850598298062339,0.08300460092018404,444.1729595236299,107.76438366849065,1.989377656444871
0.0008582732390850059,0.08375355071014204,445.2827672736643,107.76438366849065,1.989377656444871
0.0008594539992423392,0.08386877375475095,445.45316278772606,107.76438366849065,1.989377656444871
0.0008622091062761171,0.0841376275255051,445.8503976679586,107.76438366849065,1.989377656444871
0.0008763782281641175,0.08552030406081217,447.88555266348584,107.76438366849065,1.989377656444871
0.0008795269219170065,0.08582756551310262,448.33606192688023,107.76438366849065,1.989377656444871
0.0008852339293441177,0.08638447689537908,449.1510100231123,107.76438366849065,1.989377656444871
0.0008870050695801179,0.08655731146229247,449.4035079884913,107.76438366849065,1.989377656444871
0.0008889730031756734,0.086749349869974,449.6838307814131,107.76438366849065,1.989377656444871
0.0008919249035690068,0.0870374074814963,450.1038616174978,107.76438366849065,1.989377656444871
0.0008974351176365626,0.08757511502300461,450.8864714786673,107.76438366849065,1.989377656444871
0.0008984190844343404,0.08767113422684537,451.026025811185,107.76438366849065,1.989377656444871
0.0009060940254570072,0.08842008401680336,452.1125112937104,107.76438366849065,1.989377656444871
0.0009098330992885629,0.08878495699139828,452.6405240468766,107.76438366849065,1.989377656444871
0.0009114074461650074,0.08893858771754351,452.8625919503286,107.76438366849065,1.989377656444871
0.0009143593465583408,0.08922664532906582,453.2785664616611,107.76438366849065,1.989377656444871
0.0009153433133561187,0.08932266453290659,453.4171082024208,107.76438366849065,1.989377656444871
0.0009163272801538965,0.08941868373674736,453.55559187332534,107.76438366849065,1.989377656444871
0.0009261669481316745,0.09037887577515503,454.9372536955922,107.76438366849065,1.989377656444871
0.0009283316750867856,0.09059011802360473,455.24044966579527,107.76438366849065,1.989377656444871
0.0009338418891543413,0.09112782556511302,456.01097964528907,107.76438366849065,1.989377656444871
0.0009364002028285637,0.09137747549509903,456.3681227751211,107.76438366849065,1.989377656444871
0.000942107210255675,0.09193438687737548,457.16345824445426,107.76438366849065,1.989377656444871
0.000950569324716564,0.09276015203040608,458.3392988992083,107.76438366849065,1.989377656444871
0.000956866712222342,0.093374674934987,459.21169544944667,107.76438366849065,1.989377656444871
0.0009635576864472312,0.09402760552110423,460.1361669058554,107.76438366849065,1.989377656444871
0.0009670999669192312,0.09437327465493099,460.62457922393344,107.76438366849065,1.989377656444871
0.0009694614872338979,0.09460372074414883,460.94979988705364,107.76438366849065,1.989377656444871
0.0009698550739530091,0.09464212842568515,461.00397327901493,107.76438366849065,1.989377656444871
0.0009718230075485647,0.09483416683336668,461.27471173537725,107.76438366849065,1.989377656444871
0.000980678708728565,0.09569833966793359,462.49039851144727,107.76438366849065,1.989377656444871
0.0009844177825601207,0.09606321264252851,463.0024021612197,107.76438366849065,1.989377656444871
0.000985598542717454,0.09617843568713744,463.1639298800355,107.76438366849065,1.989377656444871
0.0009875664763130095,0.09637047409481897,463.43297513511993,107.76438366849065,1.989377656444871
0.0009911087567850098,0.09671614322864573,463.91673027900634,107.76438366849065,1.989377656444871
0.0009928798970210097,0.09688897779555912,464.15835495572753,107.76438366849065,1.989377656444871
0.0009956350040547877,0.09715783156631327,464.53388171266624,107.76438366849065,1.989377656444871
0.000996815764212121,0.09727305461092219,464.69469766524395,107.76438366849065,1.989377656444871
0.0009972093509312322,0.0973114622924585,464.74828647126475,107.76438366849065,1.989377656444871
0.00099996445796501,0.09758031606321264,465.12317741669955,107.76438366849065,1.989377656444871
0.0010058682587516768,0.09815643128625726,465.9251613808452,107.76438366849065,1.989377656444871
0.001008426572425899,0.09840608121624325,466.27211742517665,107.76438366849065,1.989377656444871
0.0010153143400103437,0.09907821564312863,467.20452782840266,107.76438366849065,1.989377656444871
0.0010168886868867882,0.09923184636927386,467.41730345150944,107.76438366849065,1.989377656444871
0.001017872653684566,0.09932786557311463,467.5502229776387,107.76438366849065,1.989377656444871
0.0010218085208756774,0.0997119423884777,468.081400729742,107.76438366849065,1.989377656444871
0.001023776454471233,0.09990398079615924,468.34669033198486,107.76438366849065,1.989377656444871
0.001024170041190344,0.09994238847769554,468.3997243788186,107.76438366849065,1.989377656444871