File: datasets/aisi_316_L/data/M1/train_50.csv
Time(s),Strain(%),Stress(MPa),Temp(C),Log_SR(s-1)
0.0,0.0,0.0,56.630483485110105,-2.8450643370376234
0.011199130869242674,1.6e-05,3.120184,56.630483485110105,-2.8450643370376234
0.030237653346955225,4.32e-05,8.4244968,56.630483485110105,-2.8450643370376234
0.03751708841196296,5.3599999999999995e-05,10.452616399999998,56.630483485110105,-2.8450643370376234
0.04871621928120563,6.96e-05,13.5728004,56.630483485110105,-2.8450643370376234
0.06215517632429684,8.879999999999999e-05,17.3170212,56.630483485110105,-2.8450643370376234
0.07223439410661525,0.0001032,20.1251868,56.630483485110105,-2.8450643370376234
0.09407269930163846,0.0001344,26.2095456,56.630483485110105,-2.8450643370376234
0.10807161288819181,0.00015439999999999999,30.109775599999995,56.630483485110105,-2.8450643370376234
0.11367117832281315,0.0001624,31.669867599999996,56.630483485110105,-2.8450643370376234
0.12375039610513155,0.0001768,34.4780332,56.630483485110105,-2.8450643370376234
0.1293499615397529,0.0001848,36.038125199999996,56.630483485110105,-2.8450643370376234
0.15342809290862464,0.0002192,42.7465208,56.630483485110105,-2.8450643370376234
0.16126748451709452,0.0002304,44.930649599999995,56.630483485110105,-2.8450643370376234
0.1679869630386401,0.00023999999999999998,46.80276,56.630483485110105,-2.8450643370376234
0.1864655289728905,0.00026639999999999997,51.9510636,56.630483485110105,-2.8450643370376234
0.19262505095097399,0.00027519999999999997,53.667164799999995,56.630483485110105,-2.8450643370376234
0.1993445294725196,0.0002848,55.5392752,56.630483485110105,-2.8450643370376234
0.2139033996025351,0.0003056,59.5955144,56.630483485110105,-2.8450643370376234
0.21726313886330792,0.0003104,60.531569600000005,56.630483485110105,-2.8450643370376234
0.22510253047177778,0.0003216,62.7156984,56.630483485110105,-2.8450643370376234
0.22846226973255054,0.00032639999999999996,63.65175359999999,56.630483485110105,-2.8450643370376234
0.23854148751486898,0.0003408,66.4599192,56.630483485110105,-2.8450643370376234
0.25086053147103593,0.0003584,69.8921216,56.630483485110105,-2.8450643370376234
0.2670992712314378,0.0003816,74.4163884,56.630483485110105,-2.8450643370376234
0.297336924578393,0.00042479999999999997,82.84088519999999,56.630483485110105,-2.8450643370376234
0.3006966638391658,0.0004296,83.7769404,56.630483485110105,-2.8450643370376234
0.3090960119910978,0.0004416,86.1170784,56.630483485110105,-2.8450643370376234
0.3219750124907269,0.00045999999999999996,89.70528999999999,56.630483485110105,-2.8450643370376234
0.32589470829496187,0.0004656,90.7973544,56.630483485110105,-2.8450643370376234
0.334854012990356,0.0004784,93.2935016,56.630483485110105,-2.8450643370376234
0.33821375225112876,0.0004832,94.2295568,56.630483485110105,-2.8450643370376234
0.3466131004030608,0.0004952,96.5696948,56.630483485110105,-2.8450643370376234
0.3617319270765384,0.0005168,100.7819432,56.630483485110105,-2.8450643370376234
0.3751708841196296,0.000536,104.52616400000001,56.630483485110105,-2.8450643370376234
0.38692997153233444,0.0005528,107.8023572,56.630483485110105,-2.8450643370376234
0.3992490154885014,0.0005704,111.2345596,56.630483485110105,-2.8450643370376234
0.4065284505535091,0.0005808,113.26267920000001,56.630483485110105,-2.8450643370376234
0.4132479290750547,0.0005903999999999999,115.13478959999999,56.630483485110105,-2.8450643370376234
0.41660766833582746,0.0005951999999999999,116.07084479999999,56.630483485110105,-2.8450643370376234
0.42164727722698675,0.0006024,117.4749276,56.630483485110105,-2.8450643370376234
0.4289267122919944,0.0006127999999999999,119.50304719999998,56.630483485110105,-2.8450643370376234
0.43788601698738855,0.0006255999999999999,121.99919439999998,56.630483485110105,-2.8450643370376234
0.45580462637817687,0.0006512,126.9914888,56.630483485110105,-2.8450643370376234
0.46420397453010886,0.0006632,129.33162679999998,56.630483485110105,-2.8450643370376234
0.48212258392089713,0.0006887999999999999,134.3239212,56.630483485110105,-2.8450643370376234
0.48716219281205636,0.000696,135.728004,56.630483485110105,-2.8450643370376234
0.4950015844205262,0.0007072,137.9121328,56.630483485110105,-2.8450643370376234
0.5000411933116855,0.0007144,139.3162156,56.630483485110105,-2.8450643370376234
0.5078805849201553,0.0007256,141.5003444,56.630483485110105,-2.8450643370376234
0.5252392377674814,0.0007503999999999999,146.33662959999998,56.630483485110105,-2.8450643370376234
0.5476374995059667,0.0007823999999999999,152.5769976,56.630483485110105,-2.8450643370376234
0.552677108397126,0.0007896,153.9810804,56.630483485110105,-2.8450643370376234
0.5644361958098308,0.0008064,157.2572736,56.630483485110105,-2.8450643370376234
0.5722755874183006,0.0008175999999999999,159.4414024,56.630483485110105,-2.8450643370376234
0.5745154135921492,0.0008208,160.06543920000001,56.630483485110105,-2.8450643370376234
0.5918740664394754,0.0008456,164.90172439999998,56.630483485110105,-2.8450643370376234
0.6019532842217938,0.00086,167.70989,56.630483485110105,-2.8450643370376234
0.6125924585475743,0.0008751999999999999,170.6740648,56.630483485110105,-2.8450643370376234
0.615392241264885,0.0008792,171.4541108,56.630483485110105,-2.8450643370376234
0.6310710244818247,0.0009015999999999999,175.8223684,56.630483485110105,-2.8450643370376234
0.6349907202860596,0.0009071999999999999,176.9144328,56.630483485110105,-2.8450643370376234
0.6629885474591664,0.0009471999999999999,184.71489279999997,56.630483485110105,-2.8450643370376234
0.6713878956110984,0.0009592,187.0550308,56.630483485110105,-2.8450643370376234
0.6842668961107274,0.0009776,190.6432424,56.630483485110105,-2.8450643370376234
0.6977058531538186,0.0009968,194.38746319999998,56.630483485110105,-2.8450643370376234
0.7178642887184555,0.0010256,200.0037944,56.630483485110105,-2.8450643370376234
0.7307432892180846,0.001044,203.592006,56.630483485110105,-2.8450643370376234
0.7329831153919331,0.0010471999999999999,204.21604279999997,56.630483485110105,-2.8450643370376234
0.7374627677396302,0.0010536,205.4641164,56.630483485110105,-2.8450643370376234
0.7453021593481,0.0010647999999999999,207.64824519999996,56.630483485110105,-2.8450643370376234
0.749221855152335,0.0010704,208.7403096,56.630483485110105,-2.8450643370376234
0.7559413336738806,0.00108,210.61242000000001,56.630483485110105,-2.8450643370376234
0.7637807252823503,0.0010911999999999999,212.79654879999998,56.630483485110105,-2.8450643370376234
0.7738599430646689,0.0011056,215.6047144,56.630483485110105,-2.8450643370376234
0.7772196823254416,0.0011103999999999999,216.54076959999998,56.630483485110105,-2.8450643370376234
0.7816993346731388,0.0011168,217.7888432,56.630483485110105,-2.8450643370376234
0.7850590739339115,0.0011216,218.7248984,56.630483485110105,-2.8450643370376234
0.804097596411624,0.0011488,224.0292112,56.630483485110105,-2.8450643370376234
0.8096971618462454,0.0011568,225.5893032,56.630483485110105,-2.8450643370376234
0.8136168576504803,0.0011623999999999998,226.68136759999996,56.630483485110105,-2.8450643370376234
0.8242560319762609,0.0011776,229.6455424,56.630483485110105,-2.8450643370376234
0.8371350324758899,0.001196,233.233754,56.630483485110105,-2.8450643370376234
0.8466542937147462,0.0012096,235.88591039999997,56.630483485110105,-2.8450643370376234
0.8640129465620723,0.0012343999999999999,240.72219559999996,56.630483485110105,-2.8450643370376234
0.8774519036051636,0.0012536,244.46641639999999,56.630483485110105,-2.8450643370376234
0.8908908606482547,0.0012728,248.21063719999998,56.630483485110105,-2.8450643370376234
0.8942505999090277,0.0012776,249.1466924,56.630483485110105,-2.8450643370376234
0.9082495134955809,0.0012975999999999999,253.04692239999997,56.630483485110105,-2.8450643370376234
0.9188886878213616,0.0013128,256.0110972,56.630483485110105,-2.8450643370376234
0.925608166342907,0.0013223999999999998,257.4590523758332,56.630483485110105,-2.8450643370376234
0.9284079490602177,0.0013264,257.4887672090645,56.630483485110105,-2.8450643370376234
0.9312077317775285,0.0013304,257.51844711469107,56.630483485110105,-2.8450643370376234
0.9368072972121498,0.0013384,257.5777027256221,56.630483485110105,-2.8450643370376234
0.9597655154940973,0.0013712,257.81922042549746,56.630483485110105,-2.8450643370376234
0.9765642117979612,0.0013951999999999999,257.99451551330407,56.630483485110105,-2.8450643370376234
0.9804839076021963,0.0014008,258.03524801470013,56.630483485110105,-2.8450643370376234
0.9888832557541282,0.0014127999999999999,258.12231871411814,56.630483485110105,-2.8450643370376234
1.0012022997102952,0.0014303999999999999,258.2495024779337,56.630483485110105,-2.8450643370376234
1.0202408221880077,0.0014575999999999999,258.4448652787522,56.630483485110105,-2.8450643370376234
1.0403992577526444,0.0014864,258.6501765965794,56.630483485110105,-2.8450643370376234
1.0504784755349628,0.0015007999999999998,258.7522500288776,56.630483485110105,-2.8450643370376234
1.0661572587519026,0.0015232,258.9102749806058,56.630483485110105,-2.8450643370376234
1.0728767372734482,0.0015328,258.9777222241694,56.630483485110105,-2.8450643370376234
1.08911547703385,0.0015559999999999999,259.14004317306967,56.630483485110105,-2.8450643370376234
1.1227128696415782,0.001604,259.4729132231216,56.630483485110105,-2.8450643370376234
1.130552261250048,0.0016152,259.5500211781534,56.630483485110105,-2.8450643370376234
1.143991218293139,0.0016343999999999998,259.6817228618128,56.630483485110105,-2.8450643370376234
1.1462310444669876,0.0016376,259.7036143468058,56.630483485110105,-2.8450643370376234
1.164149653857776,0.0016631999999999999,259.87814962608473,56.630483485110105,-2.8450643370376234
1.180388393618178,0.0016864,260.03541930836866,56.630483485110105,-2.8450643370376234
1.184868045965875,0.0016928,260.0786552664302,56.630483485110105,-2.8450643370376234
1.201666742269739,0.0017167999999999999,260.2402254576918,56.630483485110105,-2.8450643370376234
1.2151056993128302,0.001736,260.36884826341793,56.630483485110105,-2.8450643370376234
1.219025395117065,0.0017415999999999998,260.40625858711286,56.630483485110105,-2.8450643370376234
1.2285446563559215,0.0017552,260.49691745350054,56.630483485110105,-2.8450643370376234
1.2324643521601564,0.0017607999999999999,260.5341678980886,56.630483485110105,-2.8450643370376234
1.239743787225164,0.0017712,260.6032249446256,56.630483485110105,-2.8450643370376234
1.2509429180944067,0.0017871999999999999,260.7091585636067,56.630483485110105,-2.8450643370376234
1.2554225704421038,0.0017936,260.7514283707013,56.630483485110105,-2.8450643370376234
1.2839803541586727,0.0018344,261.01952865778986,56.630483485110105,-2.8450643370376234
1.2867801368759835,0.0018384,261.04568719717275,56.630483485110105,-2.8450643370376234
1.2912597892236803,0.0018448,261.0874947374193,56.630483485110105,-2.8450643370376234
1.3074985289840824,0.0018679999999999999,261.23857519872206,56.630483485110105,-2.8450643370376234
1.3114182247883173,0.0018736,261.2749330440313,56.630483485110105,-2.8450643370376234
1.3321366168964162,0.0019031999999999999,261.4664107245625,56.630483485110105,-2.8450643370376234
1.3422158346787347,0.0019176,261.559141792694,56.630483485110105,-2.8450643370376234
1.352295052461053,0.001932,261.6516016772293,56.630483485110105,-2.8450643370376234
1.3702136618518412,0.0019576,261.81531390928103,56.630483485110105,-2.8450643370376234
1.3931718801337887,0.0019904,262.02385510425836,56.630483485110105,-2.8450643370376234
1.394851749764175,0.0019928,262.0390613891784,56.630483485110105,-2.8450643370376234
1.4082907068072663,0.002012,262.1604556060677,56.630483485110105,-2.8450643370376234
1.409970576437653,0.0020144,262.1755980526292,56.630483485110105,-2.8450643370376234
1.4256493596545927,0.0020368,262.31658989091767,56.630483485110105,-2.8450643370376234
1.4340487078065245,0.0020488,262.39187241935696,56.630483485110105,-2.8450643370376234
1.4469277083061536,0.0020672,262.50697249424724,56.630483485110105,-2.8450643370376234
1.469885926588101,0.0021,262.7111647995006,56.630483485110105,-2.8450643370376234
1.4962038841308214,0.0021376,262.94371490543176,56.630483485110105,-2.8450643370376234
1.503483319195829,0.0021479999999999997,263.00775492046284,56.630483485110105,-2.8450643370376234
1.5404404510643297,0.0022007999999999997,263.3310343113592,56.630483485110105,-2.8450643370376234
1.5527594950204968,0.0022183999999999997,263.43812005472904,56.630483485110105,-2.8450643370376234
1.5729179305851337,0.0022472,263.61263932251967,56.630483485110105,-2.8450643370376234
1.5801973656501414,0.0022576,263.6754455184466,56.630483485110105,-2.8450643370376234
1.5897166268889975,0.0022711999999999997,263.75740670342395,56.630483485110105,-2.8450643370376234
1.6059553666493995,0.0022944,263.8967824557652,56.630483485110105,-2.8450643370376234
1.620514236779415,0.0023152,264.02127342888986,56.630483485110105,-2.8450643370376234
1.6552315424740673,0.0023648,264.3163893183779,56.630483485110105,-2.8450643370376234
1.6798696303864011,0.0024,264.5243636671753,56.630483485110105,-2.8450643370376234
1.6927486308860302,0.0024184,264.6326038894581,56.630483485110105,-2.8450643370376234
1.7028278486683486,0.0024327999999999997,264.7170897534236,56.630483485110105,-2.8450643370376234
1.7056276313856593,0.0024368,264.7405234081668,56.630483485110105,-2.8450643370376234
1.7358652847326146,0.00248,264.99265831518824,56.630483485110105,-2.8450643370376234
1.7409048936237737,0.0024871999999999997,265.03451370860716,56.630483485110105,-2.8450643370376234
1.7599434161014864,0.0025144,265.19220944930515,56.630483485110105,-2.8450643370376234
1.7616232857318728,0.0025168,265.2060917589013,56.630483485110105,-2.8450643370376234
1.7722624600576533,0.002532,265.2938934640575,56.630483485110105,-2.8450643370376234
1.7829016343834339,0.0025472,265.3814898440089,56.630483485110105,-2.8450643370376234
1.7896211129049793,0.0025567999999999997,265.4367088524789,56.630483485110105,-2.8450643370376234
1.813699244273851,0.0025911999999999997,265.6339164110582,56.630483485110105,-2.8450643370376234
1.8220985924257833,0.0026032,265.7024691869443,56.630483485110105,-2.8450643370376234
1.8360975060123366,0.0026232,265.81645057211176,56.630483485110105,-2.8450643370376234
1.8472966368815793,0.0026392,265.90739184597595,56.630483485110105,-2.8450643370376234
1.8562559415769733,0.002652,265.9799901477631,56.630483485110105,-2.8450643370376234
1.8646552897289053,0.0026639999999999997,266.0479270434996,56.630483485110105,-2.8450643370376234
1.8758544205981482,0.00268,266.1383242085836,56.630483485110105,-2.8450643370376234
1.8965728127062471,0.0027096,266.30500603018,56.630483485110105,-2.8450643370376234
1.9077719435754896,0.0027256,266.39480857792313,56.630483485110105,-2.8450643370376234
1.9206509440751187,0.002744,266.49782773398505,56.630483485110105,-2.8450643370376234
1.9223308137055053,0.0027464,266.5112451253149,56.630483485110105,-2.8450643370376234
1.9346498576616722,0.002764,266.6094999852755,56.630483485110105,-2.8450643370376234
1.9396894665528313,0.0027711999999999997,266.649624792674,56.630483485110105,-2.8450643370376234
1.9665673806390136,0.0028095999999999998,266.8629410007192,56.630483485110105,-2.8450643370376234
1.9811262507690293,0.0028304,266.97801240416413,56.630483485110105,-2.8450643370376234
1.9861658596601885,0.0028376,267.0177679127191,56.630483485110105,-2.8450643370376234
1.9934452947251962,0.002848,267.0751231531247,56.630483485110105,-2.8450643370376234
1.9951251643555825,0.0028504,267.08834737104377,56.630483485110105,-2.8450643370376234
2.0108039475725223,0.0028728,267.211564711689,56.630483485110105,-2.8450643370376234
2.0203232088113787,0.0028864,267.28619244938324,56.630483485110105,-2.8450643370376234
2.0281626004198485,0.0028975999999999997,267.3475476712279,56.630483485110105,-2.8450643370376234
2.0365619485717805,0.0029096,267.41318286321064,56.630483485110105,-2.8450643370376234
2.0404816443760154,0.0029151999999999997,267.4437764825058,56.630483485110105,-2.8450643370376234
2.046641166354099,0.002924,267.49180590296777,56.630483485110105,-2.8450643370376234
2.05224073178872,0.0029319999999999997,267.5354201154936,56.630483485110105,-2.8450643370376234
2.0567203841364172,0.0029384,267.57027807905826,56.630483485110105,-2.8450643370376234
2.064559775744887,0.0029495999999999997,267.6312083506478,56.630483485110105,-2.8450643370376234
2.0695993846360463,0.0029568,267.67033016906186,56.630483485110105,-2.8450643370376234
2.081358472048751,0.0029736,267.7614702129677,56.630483485110105,-2.8450643370376234
2.105996559961085,0.0030088,267.9517816940492,56.630483485110105,-2.8450643370376234
2.111036168852244,0.003016,267.99060185367074,56.630483485110105,-2.8450643370376234
2.121675343178025,0.0030312,268.0724370329285,56.630483485110105,-2.8450643370376234
2.1295147347864947,0.0030424,268.13263426677327,56.630483485110105,-2.8450643370376234
2.1423937352861238,0.0030608,268.2313424382176,56.630483485110105,-2.8450643370376234
2.1479933007207452,0.0030688,268.2741868232087,56.630483485110105,-2.8450643370376234
2.156952605416139,0.0030816,268.34264734743715,56.630483485110105,-2.8450643370376234
2.164791997024609,0.0030927999999999997,268.4024593835314,56.630483485110105,-2.8450643370376234
2.1771110409807757,0.0031103999999999997,268.496279338438,56.630483485110105,-2.8450643370376234
2.1927898241977157,0.0031328,268.61538765559084,56.630483485110105,-2.8450643370376234
2.1961495634584884,0.0031376,268.64086760176315,56.630483485110105,-2.8450643370376234
2.197829433088875,0.00314,268.6536018736987,56.630483485110105,-2.8450643370376234
2.2073486943277314,0.0031536,268.7256911756005,56.630483485110105,-2.8450643370376234
2.222467521001209,0.0031752,268.8399372444518,56.630483485110105,-2.8450643370376234
2.226947173348906,0.0031815999999999997,268.87372967049356,56.630483485110105,-2.8450643370376234
2.2510253047177775,0.0032159999999999997,269.0549117777698,56.630483485110105,-2.8450643370376234
2.264464261760869,0.0032351999999999997,269.155707980351,56.630483485110105,-2.8450643370376234
2.290222262760127,0.0032719999999999997,269.34825098510254,56.630483485110105,-2.8450643370376234
2.2952618716512863,0.0032792,269.38582345982843,56.630483485110105,-2.8450643370376234
2.3187800464766957,0.0033128,269.56073802757055,56.630483485110105,-2.8450643370376234
2.33837852549787,0.0033407999999999997,269.70597226526814,56.630483485110105,-2.8450643370376234
2.340618351671719,0.0033439999999999998,269.7225401817256,56.630483485110105,-2.8450643370376234
2.347897786736727,0.0033544,269.7763432576741,56.630483485110105,-2.8450643370376234
2.353497352171348,0.0033623999999999998,269.8176859820303,56.630483485110105,-2.8450643370376234
2.357977004519045,0.0033688,269.8507325473798,56.630483485110105,-2.8450643370376234
2.3652564395840527,0.0033791999999999997,269.90438104266053,56.630483485110105,-2.8450643370376234
2.373655787735985,0.0033912,269.9662032024454,56.630483485110105,-2.8450643370376234
2.387094744779076,0.0034103999999999996,270.0649414941298,56.630483485110105,-2.8450643370376234
2.4055733107133266,0.0034368,270.20035339255463,56.630483485110105,-2.8450643370376234
2.428531528995274,0.0034695999999999998,270.36802863643356,56.630483485110105,-2.8450643370376234
2.440850572951441,0.0034871999999999998,270.4577458132093,56.630483485110105,-2.8450643370376234
2.452609660364146,0.0035039999999999997,270.54322034428026,56.630483485110105,-2.8450643370376234
2.4710882262983964,0.0035304,270.6772152593894,56.630483485110105,-2.8450643370376234
2.482287357167639,0.0035464,270.7582341282395,56.630483485110105,-2.8450643370376234
2.494606401123806,0.003564,270.84719041111487,56.630483485110105,-2.8450643370376234
2.523164184840375,0.0036048,271.0527509297837,56.630483485110105,-2.8450643370376234
2.5276438371880716,0.0036111999999999997,271.0849132041243,56.630483485110105,-2.8450643370376234
2.5422027073180873,0.003632,271.1892874052096,56.630483485110105,-2.8450643370376234
2.548362229296171,0.0036408,271.2333755150447,56.630483485110105,-2.8450643370376234
2.5595613601654135,0.0036568,271.31342938690017,56.630483485110105,-2.8450643370376234
2.571320447578118,0.0036736,271.39733907116965,56.630483485110105,-2.8450643370376234
2.5774799695562014,0.0036823999999999997,271.441232029133,56.630483485110105,-2.8450643370376234
2.604357883642384,0.0037208,271.63228820195485,56.630483485110105,-2.8450643370376234
2.6261961888374072,0.0037519999999999997,271.78695573543996,56.630483485110105,-2.8450643370376234
2.637955276250112,0.0037687999999999997,271.8700304569101,56.630483485110105,-2.8450643370376234
2.64523471131512,0.0037792,271.9213852954259,56.630483485110105,-2.8450643370376234
2.6519541898366654,0.0037887999999999997,271.96874086340483,56.630483485110105,-2.8450643370376234
2.6777121908359236,0.0038255999999999997,272.1498386777585,56.630483485110105,-2.8450643370376234
2.680511973553234,0.0038296,272.16948219908267,56.630483485110105,-2.8450643370376234
2.688351365161704,0.0038407999999999997,272.2244415346074,56.630483485110105,-2.8450643370376234
2.696190756770174,0.003852,272.27933840233163,56.630483485110105,-2.8450643370376234
2.7062699745524923,0.0038664,272.3498287058549,56.630483485110105,-2.8450643370376234
2.726428410117129,0.0038951999999999997,272.49050289790165,56.630483485110105,-2.8450643370376234
2.734827758269061,0.0039071999999999996,272.54899735685564,56.630483485110105,-2.8450643370376234
2.739307410616758,0.0039136,272.58016575134127,56.630483485110105,-2.8450643370376234
2.7465868456817657,0.0039239999999999995,272.6307720289019,56.630483485110105,-2.8450643370376234
2.761145715811782,0.0039448,272.73182793098783,56.630483485110105,-2.8450643370376234
2.765625368159479,0.0039512,272.76288021910665,56.630483485110105,-2.8450643370376234
2.775704585941797,0.0039656,272.83267623631065,56.630483485110105,-2.8450643370376234
2.788583586441426,0.003984,272.9217163625546,56.630483485110105,-2.8450643370376234
2.7975428911368203,0.0039968,272.9835627526882,56.630483485110105,-2.8450643370376234
3.2030320784756383,0.004576115223044609,275.7067448284926,56.630483485110105,-2.8450643370376234
3.3105652414529634,0.004729745949189838,276.40590407958143,56.630483485110105,-2.8450643370376234
3.5659565035241108,0.005094618923784757,278.0318252691218,56.630483485110105,-2.8450643370376234
3.606281439640608,0.005152230446089218,278.2843376901939,56.630483485110105,-2.8450643370376234
3.9826475100612453,0.005689937987597519,280.59028732047943,56.630483485110105,-2.8450643370376234
4.157388899899399,0.005939587917583517,281.63184359983705,56.630483485110105,-2.8450643370376234
4.627846487925196,0.006611722344468894,284.3544348077319,56.630483485110105,-2.8450643370376234
5.125187366695325,0.007322264452890578,287.117587832518,56.630483485110105,-2.8450643370376234
5.2192788843004845,0.007456691338267653,287.6283641022475,56.630483485110105,-2.8450643370376234
5.367136983394307,0.007667933586717343,288.42381582886617,56.630483485110105,-2.8450643370376234
5.676294826954116,0.008109621924384877,290.0599299561012,56.630483485110105,-2.8450643370376234
5.770386344559276,0.008244048809761952,290.5509296622326,56.630483485110105,-2.8450643370376234
6.119869124235583,0.008743348669733947,292.3479304777637,56.630483485110105,-2.8450643370376234
6.267727223329405,0.008954590918183637,293.0960980962517,56.630483485110105,-2.8450643370376234
6.563443421517049,0.009377075415083017,294.5720943540867,56.630483485110105,-2.8450643370376234
6.644093293750043,0.009492298459691939,294.97010783369666,56.630483485110105,-2.8450643370376234
7.154875817892337,0.010222044408881775,297.44845861749246,56.630483485110105,-2.8450643370376234
7.396825434591318,0.01056771354270854,298.59823282765535,56.630483485110105,-2.8450643370376234
7.504358597568643,0.01072134426885377,299.10452534216824,56.630483485110105,-2.8450643370376234
7.611891760545968,0.010874974994998999,299.60799622898065,56.630483485110105,-2.8450643370376234
7.6522166966624665,0.010932586517303462,299.79608169837286,56.630483485110105,-2.8450643370376234
7.8672830226171175,0.01123984796959392,300.7927503264106,56.630483485110105,-2.8450643370376234
8.1092326393161,0.011585517103420685,301.901386582546,56.630483485110105,-2.8450643370376234
8.539365291225398,0.0122000400080016,303.8409521534645,56.630483485110105,-2.8450643370376234
8.90228971627387,0.012718543708741748,305.4479938143777,56.630483485110105,-2.8450643370376234
9.345864013555337,0.013352270454090818,307.37786057614954,56.630483485110105,-2.8450643370376234
9.480280467276994,0.013544308861772355,307.95557157873486,56.630483485110105,-2.8450643370376234
9.628138566370815,0.013755551110222045,308.5873764341227,56.630483485110105,-2.8450643370376234
9.802879956208969,0.014005201040208042,309.32919694069943,56.630483485110105,-2.8450643370376234
10.474962224817252,0.014965393078615724,312.1355365528674,56.630483485110105,-2.8450643370376234
10.555612097050245,0.015080616123224646,312.46751161827365,56.630483485110105,-2.8450643370376234
10.703470196144067,0.015291858371674336,313.0735746621936,56.630483485110105,-2.8450643370376234
10.85132829523789,0.015503100620124026,313.6763812139523,56.630483485110105,-2.8450643370376234
11.617502081451331,0.016597719543908783,316.7501393979024,56.630483485110105,-2.8450643370376234
11.819126762033815,0.016885777155431086,317.54575013826855,56.630483485110105,-2.8450643370376234
12.195492832454454,0.017423484696939388,319.0168688589801,56.630483485110105,-2.8450643370376234
12.437442449153435,0.017769153830766153,319.95324548810316,56.630483485110105,-2.8450643370376234
12.679392065852417,0.01811482296459292,320.8825443670359,56.630483485110105,-2.8450643370376234
13.042316490900888,0.018633326665333065,322.2636287960526,56.630483485110105,-2.8450643370376234
13.23049952611121,0.01890218043608722,322.9738408594015,56.630483485110105,-2.8450643370376234
13.647190532648343,0.01949749949989998,324.532581461197,56.630483485110105,-2.8450643370376234
13.875698503975158,0.01982396479295859,325.3794900520136,56.630483485110105,-2.8450643370376234
13.96979002158032,0.019958391678335668,325.72663406480456,56.630483485110105,-2.8450643370376234
14.265506219767964,0.020380876175235048,326.8117685080052,56.630483485110105,-2.8450643370376234
14.440247609606116,0.020630526105221043,327.44886100870536,56.630483485110105,-2.8450643370376234
14.991355069864909,0.021417883576715344,329.43873589254224,56.630483485110105,-2.8450643370376234
15.313954558796883,0.02187877575515103,330.5903022398235,56.630483485110105,-2.8450643370376234
15.475254303262872,0.022109221844368875,331.1625346818077,56.630483485110105,-2.8450643370376234
15.542462530123698,0.02220524104820964,331.4002777896458,56.630483485110105,-2.8450643370376234
15.596229111612361,0.022282056411282256,331.5901837287963,56.630483485110105,-2.8450643370376234
16.25486973484848,0.023223044608921786,333.89618699029813,56.630483485110105,-2.8450643370376234
16.362402897825806,0.023376675335067015,334.26918920632386,56.630483485110105,-2.8450643370376234
17.2629931377609,0.024663332666533307,337.35641395691994,56.630483485110105,-2.8450643370376234
17.491501109087718,0.024989797959591917,338.1296674984431,56.630483485110105,-2.8450643370376234
17.814100598019692,0.025450690138027605,339.21464588436646,56.630483485110105,-2.8450643370376234
17.935075406369183,0.02562352470494099,339.61953377142385,56.630483485110105,-2.8450643370376234
18.096375150835172,0.025853970794158833,340.15773133934186,56.630483485110105,-2.8450643370376234
18.28455818604549,0.026122824564912984,340.78326958653895,56.630483485110105,-2.8450643370376234
18.80878235555995,0.026871774354870974,342.512737882294,56.630483485110105,-2.8450643370376234
19.03729032688677,0.027198239647929588,343.260714138738,56.630483485110105,-2.8450643370376234
19.252356652841417,0.027505501100220046,343.9614995768022,56.630483485110105,-2.8450643370376234
19.33300652507441,0.027620724144828968,344.22350615202356,56.630483485110105,-2.8450643370376234
19.440539688051736,0.027774354870974197,344.5721861335387,56.630483485110105,-2.8450643370376234
19.749697531611545,0.02821604320864173,345.57047557892304,56.630483485110105,-2.8450643370376234
19.964763857566197,0.028523304660932187,346.26134620630484,56.630483485110105,-2.8450643370376234
20.260480055753842,0.028945789157831567,347.2065727162825,56.630483485110105,-2.8450643370376234
20.435221445591992,0.029195439087817562,347.76258671388956,56.630483485110105,-2.8450643370376234
20.690612707663142,0.029560312062412483,348.5718986637372,56.630483485110105,-2.8450643370376234
20.81158751601263,0.029733146629325864,348.9538963083623,56.630483485110105,-2.8450643370376234
21.120745359572442,0.0301748349669934,349.92619886760974,56.630483485110105,-2.8450643370376234
21.18795358643327,0.030270854170834166,350.1368326911922,56.630483485110105,-2.8450643370376234
21.389578267015754,0.030558911782356472,350.76717626597014,56.630483485110105,-2.8450643370376234
21.6852944652034,0.030981396279255852,351.68750450628454,56.630483485110105,-2.8450643370376234
21.913802436530215,0.031307861572314466,352.3953188451753,56.630483485110105,-2.8450643370376234
22.06166053562404,0.03151910382076416,352.85178296360806,56.630483485110105,-2.8450643370376234
22.26328521620652,0.03180716143228646,353.4723159139881,56.630483485110105,-2.8450643370376234
22.411143315300343,0.03201840368073615,353.9259813394433,56.630483485110105,-2.8450643370376234
22.63965128662716,0.03234486897379476,354.62481135929244,56.630483485110105,-2.8450643370376234
22.72030115886015,0.03246009201840368,354.87079976833104,56.630483485110105,-2.8450643370376234
22.814392676465317,0.03259451890378076,355.15735625442187,56.630483485110105,-2.8450643370376234
23.056342293164295,0.03294018803760752,355.8921073694794,56.630483485110105,-2.8450643370376234
23.49991659044576,0.03357391478295659,357.2313881375395,56.630483485110105,-2.8450643370376234
23.943490887727226,0.03420764152830566,358.56084533303425,56.630483485110105,-2.8450643370376234
24.131673922937548,0.034476495299059814,359.1219515899512,56.630483485110105,-2.8450643370376234
24.54836492947468,0.03507181436287257,360.35836381685294,56.630483485110105,-2.8450643370376234
24.682781383196332,0.035263852770554105,360.75545687257954,56.630483485110105,-2.8450643370376234
24.870964418406654,0.03553270654130826,361.30997321569396,56.630483485110105,-2.8450643370376234
25.301097070315954,0.036147229445889176,362.571330974778,56.630483485110105,-2.8450643370376234
25.62369655924793,0.03660812162432486,363.51186817528037,56.630483485110105,-2.8450643370376234
25.78499630371392,0.036838567713542714,363.98040416163667,56.630483485110105,-2.8450643370376234
25.919412757435577,0.03703060612122425,364.36997827326155,56.630483485110105,-2.8450643370376234
26.362987054717046,0.03766433286657332,365.6500187224287,56.630483485110105,-2.8450643370376234
26.483961863066533,0.037837167433486696,365.9976593508579,56.630483485110105,-2.8450643370376234
26.591495026043855,0.037990798159631925,366.30615366820086,56.630483485110105,-2.8450643370376234
27.16948577704698,0.03881656331266253,367.95604890703714,56.630483485110105,-2.8450643370376234
27.250135649279976,0.03893178635727146,368.18517379455926,56.630483485110105,-2.8450643370376234
27.545851847467613,0.03935427085417083,369.02304523540795,56.630483485110105,-2.8450643370376234
27.666826655817108,0.039527105421084216,369.3647988675996,56.630483485110105,-2.8450643370376234
27.86845133639959,0.039815163032606515,369.9330960008265,56.630483485110105,-2.8450643370376234
28.043192726237752,0.040064812962592525,370.4243243616825,56.630483485110105,-2.8450643370376234
28.688391704101704,0.0409865973194639,372.2278410956195,56.630483485110105,-2.8450643370376234
28.849691448567686,0.041217043408681736,372.6762399889337,56.630483485110105,-2.8450643370376234
29.23949916436049,0.04177395479095819,373.7558531434538,56.630483485110105,-2.8450643370376234
29.360473972709983,0.04194678935787158,374.0897622500677,56.630483485110105,-2.8450643370376234
29.44112384494298,0.0420620124024805,374.31207027696144,56.630483485110105,-2.8450643370376234
29.615865234781133,0.0423116623324665,374.79292453686566,56.630483485110105,-2.8450643370376234
29.763723333874953,0.04252290458091619,375.19893759937196,56.630483485110105,-2.8450643370376234
29.87125649685228,0.04267653530706142,375.4937259208292,56.630483485110105,-2.8450643370376234
30.476130538599733,0.04354070814162833,377.14426279823306,56.630483485110105,-2.8450643370376234
30.54333876546056,0.0436367273454691,377.3268637114879,56.630483485110105,-2.8450643370376234
30.58366370157706,0.04369433886777356,377.43634904421964,56.630483485110105,-2.8450643370376234
30.664313573810045,0.04380956191238247,377.65515095746184,56.630483485110105,-2.8450643370376234
30.731521800670873,0.04390558111622324,377.8373144964124,56.630483485110105,-2.8450643370376234
31.01379635348636,0.04430886177235448,378.6007109210129,56.630483485110105,-2.8450643370376234
31.21542103406884,0.044596919383876776,379.1443359680301,56.630483485110105,-2.8450643370376234
31.349837487790495,0.04478895779155831,379.50599206890615,56.630483485110105,-2.8450643370376234
31.618670395233814,0.04517303460692139,380.2274951059727,56.630483485110105,-2.8450643370376234
31.87406165730496,0.04553790758151631,380.9107101953667,56.630483485110105,-2.8450643370376234
32.00847811102661,0.04572994598919784,381.26943937587663,56.630483485110105,-2.8450643370376234
32.45205240830808,0.046363672734546904,382.44909913817526,56.630483485110105,-2.8450643370376234
32.6805603796349,0.04669013802760552,383.05434742498466,56.630483485110105,-2.8450643370376234
32.70744367037922,0.046728545709141825,383.12544443392846,56.630483485110105,-2.8450643370376234
33.01660151393904,0.04717023404680937,383.941428752074,56.630483485110105,-2.8450643370376234
33.325759357498846,0.047611922384476896,384.7544386032954,56.630483485110105,-2.8450643370376234
33.52738403808133,0.047899979995999195,385.28307818894024,56.630483485110105,-2.8450643370376234
33.70212542791949,0.048149629925985205,385.74023039448514,56.630483485110105,-2.8450643370376234
33.997841626107125,0.048572114422884574,386.51177228467617,56.630483485110105,-2.8450643370376234
34.84466528455357,0.04978195639127826,388.7068402038506,56.630483485110105,-2.8450643370376234
35.20758970960203,0.0503004600920184,389.6412035001936,56.630483485110105,-2.8450643370376234
35.35544780869586,0.05051170234046809,390.02079222400465,56.630483485110105,-2.8450643370376234
35.63772236151133,0.050914982996599314,390.7437468356407,56.630483485110105,-2.8450643370376234
35.85278868746598,0.05122224444888977,391.2930714261965,56.630483485110105,-2.8450643370376234
36.05441336804847,0.051510302060412086,391.80689723535073,56.630483485110105,-2.8450643370376234
36.242596403258794,0.05177915583116624,392.28545784658917,56.630483485110105,-2.8450643370376234
37.425461196009365,0.05346909381876375,395.2716618515987,56.630483485110105,-2.8450643370376234
37.532994358986684,0.053622724544908976,395.54129643967434,56.630483485110105,-2.8450643370376234
38.56800105264345,0.05510142028405682,398.1213060972009,56.630483485110105,-2.8450643370376234
38.7427424424816,0.05535107021404281,398.55421407661703,56.630483485110105,-2.8450643370376234
39.11910851290224,0.05588877775555111,399.4840533501362,56.630483485110105,-2.8450643370376234
39.30729154811256,0.05615763152630526,399.9476641579353,56.630483485110105,-2.8450643370376234
39.60300774630021,0.056580116023204646,400.6744503573293,56.630483485110105,-2.8450643370376234
39.91216558986001,0.057021804360872175,401.43201292057114,56.630483485110105,-2.8450643370376234
40.15411520655899,0.05736747349469894,402.02329276825304,56.630483485110105,-2.8450643370376234
40.288531660280654,0.057559511902380484,402.35118113750633,56.630483485110105,-2.8450643370376234
40.34229824176931,0.05763632726545309,402.4822169927775,56.630483485110105,-2.8450643370376234
41.06814709186626,0.05867333466693339,404.24458746507696,56.630483485110105,-2.8450643370376234
41.21600519096008,0.05888457691538308,404.60209489640664,56.630483485110105,-2.8450643370376234
41.646137842869386,0.059499099819964,405.639283443101,56.630483485110105,-2.8450643370376234
41.67302113361371,0.0595375075015003,405.7039686657078,56.630483485110105,-2.8450643370376234
41.72678771510237,0.05961432286457291,405.8332903093216,56.630483485110105,-2.8450643370376234
41.767112651218866,0.05967193438687737,405.93023889798496,56.630483485110105,-2.8450643370376234
42.10315378552301,0.06015203040608122,406.73672908839103,56.630483485110105,-2.8450643370376234
42.439194919827145,0.06063212642528505,407.54071275827545,56.630483485110105,-2.8450643370376234
42.56016972817664,0.06080496099219844,407.82953860385675,56.630483485110105,-2.8450643370376234
42.70802782727046,0.06101620324064813,408.18211352742117,56.630483485110105,-2.8450643370376234
43.0843938976911,0.061553910782156426,409.0774355857325,56.630483485110105,-2.8450643370376234
43.232251996784925,0.06176515303060612,409.42833407865027,56.630483485110105,-2.8450643370376234
43.66238464869422,0.062379675935187034,410.44647820563546,56.630483485110105,-2.8450643370376234
43.9849841376262,0.06284056811362272,411.2075211929986,56.630483485110105,-2.8450643370376234
44.0253090737427,0.06289817963592718,411.30249826789174,56.630483485110105,-2.8450643370376234
44.374791853419,0.06339747949589918,412.12421657749616,56.630483485110105,-2.8450643370376234
44.8049245053283,0.06401200240048009,413.13210555776135,56.630483485110105,-2.8450643370376234
45.03343247665512,0.06433846769353871,413.6660113746618,56.630483485110105,-2.8450643370376234
45.181290575748946,0.0645497099419884,414.01091691942526,56.630483485110105,-2.8450643370376234
45.38291525633143,0.0648377675535107,414.4805340879245,56.630483485110105,-2.8450643370376234
45.58453993691392,0.06512582516503301,414.94933826607405,56.630483485110105,-2.8450643370376234
45.89369778047372,0.06556751350270054,415.6666037392388,56.630483485110105,-2.8450643370376234
46.2566222055222,0.06608601720344069,416.5062109925518,56.630483485110105,-2.8450643370376234
46.43136359536035,0.06633566713342669,416.90954972387607,56.630483485110105,-2.8450643370376234
46.87493789264182,0.06696939387877576,417.9307598815859,56.630483485110105,-2.8450643370376234
47.10344586396863,0.06729585917183437,418.45536657079276,56.630483485110105,-2.8450643370376234
47.62767003348309,0.06804480896179237,419.6551400382843,56.630483485110105,-2.8450643370376234
47.95026952241507,0.06850570114022805,420.39090275890976,56.630483485110105,-2.8450643370376234
48.17877749374188,0.06883216643328666,420.9109004487791,56.630483485110105,-2.8450643370376234
48.474493691929524,0.06925465093018604,421.58241305557357,56.630483485110105,-2.8450643370376234
48.90462634383883,0.06986917383476696,422.5563136784829,56.630483485110105,-2.8450643370376234
49.46917544946978,0.0706757351470294,423.829503548492,56.630483485110105,-2.8450643370376234
49.54982532170278,0.07079095819163833,424.01092415963075,56.630483485110105,-2.8450643370376234
49.96651632823991,0.07138627725545109,424.9464356894701,56.630483485110105,-2.8450643370376234
50.34288239866056,0.0719239847969594,425.7888018822141,56.630483485110105,-2.8450643370376234
50.85366492280285,0.07265373074614924,426.92809521189434,56.630483485110105,-2.8450643370376234
51.33756415620081,0.07334506901380276,428.00331598761636,56.630483485110105,-2.8450643370376234
51.606397063644124,0.07372914582916584,428.59895275958075,56.630483485110105,-2.8450643370376234
51.95587984332043,0.07422844568913783,429.371474578164,56.630483485110105,-2.8450643370376234
52.00964642480909,0.07430526105221044,429.49014397430324,56.630483485110105,-2.8450643370376234
52.09029629704209,0.07442048409681937,429.6680583996301,56.630483485110105,-2.8450643370376234
52.17094616927508,0.07453570714142829,429.84586542806346,56.630483485110105,-2.8450643370376234
52.34568755911324,0.07478535707141429,430.2307466566921,56.630483485110105,-2.8450643370376234
52.81614514713903,0.07545749149829967,431.26448287401803,56.630483485110105,-2.8450643370376234
53.07153640921018,0.07582236447289459,431.8241498576771,56.630483485110105,-2.8450643370376234
53.636085514841135,0.07662892578515704,433.0575947364362,56.630483485110105,-2.8450643370376234
53.878035131540116,0.0769745949189838,433.5846628407698,56.630483485110105,-2.8450643370376234
54.26784284733292,0.07753150630126025,434.43189064240994,56.630483485110105,-2.8450643370376234
54.36193436493809,0.07766593318663734,434.63603791510997,56.630483485110105,-2.8450643370376234
54.65765056312572,0.0780884176835367,435.27674833153054,56.630483485110105,-2.8450643370376234
54.9802500520577,0.0785493098619724,435.97416525820046,56.630483485110105,-2.8450643370376234
55.14154979652369,0.07877975595119024,436.3222751164554,56.630483485110105,-2.8450643370376234
55.316291186361845,0.07902940588117624,436.69894628161705,56.630483485110105,-2.8450643370376234
55.423824349339164,0.07918303660732147,436.93051327897456,56.630483485110105,-2.8450643370376234
55.8001904197598,0.07972074414882976,437.7396215093358,56.630483485110105,-2.8450643370376234
56.203439780924775,0.08029685937187438,438.60416495826325,56.630483485110105,-2.8450643370376234
56.64701407820624,0.08093058611722345,439.5523734377569,56.630483485110105,-2.8450643370376234
56.68733901432274,0.08098819763952791,439.63843036338733,56.630483485110105,-2.8450643370376234
56.86208040416089,0.08123784756951391,440.0110681630233,56.630483485110105,-2.8450643370376234
57.14435495697637,0.08164112822564513,440.6120794965798,56.630483485110105,-2.8450643370376234
57.27877141069802,0.08183316663332667,440.89786832488153,56.630483485110105,-2.8450643370376234
57.76267064409599,0.0825245049009802,441.92454948090716,56.630483485110105,-2.8450643370376234
57.964295324678474,0.0828125625125025,442.3513426663325,56.630483485110105,-2.8450643370376234
58.32721974972695,0.08333106621324265,443.11811422355674,56.630483485110105,-2.8450643370376234
58.69014417477542,0.0838495699139828,443.8830273258583,56.630483485110105,-2.8450643370376234
58.878327209985734,0.08411842368473695,444.27892256198254,56.630483485110105,-2.8450643370376234
59.2412516350342,0.0846369273854771,445.0410439980083,56.630483485110105,-2.8450643370376234
59.684825932315675,0.08527065413082617,445.9700574406303,56.630483485110105,-2.8450643370376234
60.02086706661982,0.08575075015003002,446.6720639245583,56.630483485110105,-2.8450643370376234
60.15528352034148,0.08594278855771155,446.95243712299066,56.630483485110105,-2.8450643370376234
60.49132465464561,0.08642288457691538,447.6523032864123,56.630483485110105,-2.8450643370376234
60.6526243991116,0.08665333066613323,447.9877003235282,56.630483485110105,-2.8450643370376234
61.109640341765235,0.08730626125225045,448.93610806358816,56.630483485110105,-2.8450643370376234
61.217173504742554,0.08745989197839568,449.15886033838603,56.630483485110105,-2.8450643370376234
61.48600641218587,0.08784396879375876,449.715074439148,56.630483485110105,-2.8450643370376234
61.727956028884854,0.08818963792758552,450.21485673240664,56.630483485110105,-2.8450643370376234
61.87581412797868,0.08840088017603522,450.5199031653352,56.630483485110105,-2.8450643370376234
62.26562184377148,0.08895779155831167,451.3227568892404,56.630483485110105,-2.8450643370376234
62.57477968733129,0.0893994798959792,451.9581099772069,56.630483485110105,-2.8450643370376234
62.70919614105294,0.08959151830366073,452.2339684764386,56.630483485110105,-2.8450643370376234
63.07212056610141,0.09011002200440088,452.9776369607761,56.630483485110105,-2.8450643370376234
63.59634473561588,0.09085897179435888,454.0488852472201,56.630483485110105,-2.8450643370376234
63.65011131710454,0.09093578715743149,454.1585617911136,56.630483485110105,-2.8450643370376234
64.06680232364168,0.09153110622124426,455.00733333175333,56.630483485110105,-2.8450643370376234
64.26842700422416,0.09181916383276656,455.41725609722636,56.630483485110105,-2.8450643370376234
64.33563523108499,0.09191518303660733,455.5537855239622,56.630483485110105,-2.8450643370376234
64.52381826629531,0.09218403680736148,455.9357723170049,56.630483485110105,-2.8450643370376234
64.77920952836647,0.0925489097819564,456.4534887409732,56.630483485110105,-2.8450643370376234
65.1555755987871,0.0930866173234647,457.2149906938211,56.630483485110105,-2.8450643370376234
65.18245888953142,0.093125025005001,457.26931795627934,56.630483485110105,-2.8450643370376234
65.33031698862524,0.09333626725345069,457.567961846792,56.630483485110105,-2.8450643370376234
65.47817508771907,0.09354750950190038,457.866342251402,56.630483485110105,-2.8450643370376234
65.85454115813971,0.09408521704340869,458.62467269582055,56.630483485110105,-2.8450643370376234
66.04272419335003,0.09435407081416283,459.0032039437095,56.630483485110105,-2.8450643370376234
66.3249987461655,0.09475735147029406,459.57021305092326,56.630483485110105,-2.8450643370376234
66.37876532765416,0.09483416683336668,459.67810799968237,56.630483485110105,-2.8450643370376234
66.44597355451499,0.09493018603720745,459.812928767238,56.630483485110105,-2.8450643370376234
66.5669483628645,0.09510302060412083,460.0554722035424,56.630483485110105,-2.8450643370376234
66.78201468881913,0.09541028205641129,460.4862365035411,56.630483485110105,-2.8450643370376234
67.21214734072844,0.09602480496099221,461.3461454555399,56.630483485110105,-2.8450643370376234
67.2659139222171,0.09610162032406482,461.45348296539964,56.630483485110105,-2.8450643370376234
67.49442189354392,0.09642808561712343,461.9092945941379,56.630483485110105,-2.8450643370376234
67.80357973710372,0.09686977395479096,462.52502412252227,56.630483485110105,-2.8450643370376234
68.34124555199035,0.0976379275855171,463.59325650401627,56.630483485110105,-2.8450643370376234
68.61007845943367,0.09802200440088019,464.12614322067833,56.630483485110105,-2.8450643370376234
69.22839414655328,0.09890538107621524,465.34870193188965,56.630483485110105,-2.8450643370376234
69.47034376325227,0.09925105021004202,465.8259343369195,56.630483485110105,-2.8450643370376234
69.75261831606774,0.09965433086617324,466.3818869764335,56.630483485110105,-2.8450643370376234