File: datasets/aisi_316_L/data/M1/train_63.csv
Time(s),Strain(%),Stress(MPa),Temp(C),Log_SR(s-1)
0.0,0.0,0.0,336.7229328335661,0.3134341562152212
6.2197913127861905e-06,1.28e-05,2.2347744,336.7229328335661,0.3134341562152212
1.982558480950598e-05,4.0799999999999996e-05,7.1233433999999995,336.7229328335661,0.3134341562152212
2.4879165251144762e-05,5.12e-05,8.9390976,336.7229328335661,0.3134341562152212
2.760032395048872e-05,5.68e-05,9.9168114,336.7229328335661,0.3134341562152212
4.042864353311024e-05,8.319999999999999e-05,14.526033599999998,336.7229328335661,0.3134341562152212
4.509348701769988e-05,9.279999999999999e-05,16.2021144,336.7229328335661,0.3134341562152212
5.2479489201633484e-05,0.000108,18.855909,336.7229328335661,0.3134341562152212
6.491907182720586e-05,0.0001336,23.3254578,336.7229328335661,0.3134341562152212
6.647401965540242e-05,0.0001368,23.884151399999997,336.7229328335661,0.3134341562152212
7.075012618294292e-05,0.0001456,25.4205588,336.7229328335661,0.3134341562152212
8.124602402326962e-05,0.0001672,29.1917406,336.7229328335661,0.3134341562152212
9.290813273474373e-05,0.00019119999999999999,33.381942599999995,336.7229328335661,0.3134341562152212
0.00010029413491867733,0.0002064,36.0357372,336.7229328335661,0.3134341562152212
0.00010768013710261093,0.0002216,38.6895318,336.7229328335661,0.3134341562152212
0.0001115675066731023,0.0002296,40.0862658,336.7229328335661,0.3134341562152212
0.00012011971972818331,0.0002472,43.159080599999996,336.7229328335661,0.3134341562152212
0.0001263395110409695,0.00026,45.393854999999995,336.7229328335661,0.3134341562152212
0.00012867193278326433,0.0002648,46.2318954,336.7229328335661,0.3134341562152212
0.00014266646323703324,0.0002936,51.260137799999995,336.7229328335661,0.3134341562152212
0.00015005246542096684,0.00030879999999999997,53.91393239999999,336.7229328335661,0.3134341562152212
0.00016093710021834268,0.0003312,57.82478759999999,336.7229328335661,0.3134341562152212
0.00016521320674588318,0.00033999999999999997,59.361194999999995,336.7229328335661,0.3134341562152212
0.00019553468939571586,0.00040239999999999997,70.2557202,336.7229328335661,0.3134341562152212
0.00020369816549374776,0.0004192,73.1888616,336.7229328335661,0.3134341562152212
0.0002118616415917796,0.00043599999999999997,76.12200299999999,336.7229328335661,0.3134341562152212
0.00021536027420522187,0.0004432,77.3790636,336.7229328335661,0.3134341562152212
0.00022119132856095893,0.0004552,79.4741646,336.7229328335661,0.3134341562152212
0.00022585617204554854,0.00046479999999999997,81.15024539999999,336.7229328335661,0.3134341562152212
0.00022896606770194164,0.00047119999999999996,82.2676326,336.7229328335661,0.3134341562152212
0.00023207596335833472,0.00047759999999999995,83.3850198,336.7229328335661,0.3134341562152212
0.00023518585901472784,0.000484,84.502407,336.7229328335661,0.3134341562152212
0.00024257186119866145,0.0004992,87.1562016,336.7229328335661,0.3134341562152212
0.00024412680902685798,0.0005024,87.71489519999999,336.7229328335661,0.3134341562152212
0.0002491803894684968,0.0005128,89.5306494,336.7229328335661,0.3134341562152212
0.0002530677590389881,0.0005208,90.9273834,336.7229328335661,0.3134341562152212
0.00025967628730882346,0.0005344,93.3018312,336.7229328335661,0.3134341562152212
0.00026472986775046226,0.0005448,95.1175854,336.7229328335661,0.3134341562152212
0.00027289334384849413,0.0005616,98.05072679999999,336.7229328335661,0.3134341562152212
0.00028066808298947687,0.0005775999999999999,100.8441948,336.7229328335661,0.3134341562152212
0.00028377797864586994,0.000584,101.96158199999999,336.7229328335661,0.3134341562152212
0.0003004936677989828,0.0006184,107.96753819999999,336.7229328335661,0.3134341562152212
0.000303992300412425,0.0006255999999999999,109.22459879999998,336.7229328335661,0.3134341562152212
0.00031332198738160435,0.0006448,112.5767604,336.7229328335661,0.3134341562152212
0.00031954177869439055,0.0006575999999999999,114.81153479999999,336.7229328335661,0.3134341562152212
0.00033664620480455256,0.0006927999999999999,120.95716439999998,336.7229328335661,0.3134341562152212
0.000346364628730781,0.0007128,124.44899939999999,336.7229328335661,0.3134341562152212
0.00035763800048520597,0.000736,128.499528,336.7229328335661,0.3134341562152212
0.00036152537005569737,0.000744,129.896262,336.7229328335661,0.3134341562152212
0.00036580147658323784,0.0007528,131.4326694,336.7229328335661,0.3134341562152212
0.0003766861113806137,0.0007752,135.3435246,336.7229328335661,0.3134341562152212
0.0003852383244356947,0.0007928,138.4163394,336.7229328335661,0.3134341562152212
0.00039184685270553005,0.0008064,140.79078719999998,336.7229328335661,0.3134341562152212
0.00040389769837405326,0.0008311999999999999,145.12066259999997,336.7229328335661,0.3134341562152212
0.00040856254185864287,0.0008408,146.7967434,336.7229328335661,0.3134341562152212
0.0004128386483861834,0.0008495999999999999,148.3331508,336.7229328335661,0.3134341562152212
0.0004283881266681489,0.0008816,153.9200868,336.7229328335661,0.3134341562152212
0.0004295543375392963,0.0008839999999999999,154.33910699999998,336.7229328335661,0.3134341562152212
0.00044277139407896695,0.0009111999999999999,159.08800259999998,336.7229328335661,0.3134341562152212
0.0004645406636737186,0.0009559999999999999,166.90971299999998,336.7229328335661,0.3134341562152212
0.00047348161368584876,0.0009743999999999999,170.12220119999998,336.7229328335661,0.3134341562152212
0.00047581403542814357,0.0009792,170.9602416,336.7229328335661,0.3134341562152212
0.0004816450897838807,0.0009912,172.77513496635044,336.7229328335661,0.3134341562152212
0.00048553245935437203,0.0009992,172.82017357548096,336.7229328335661,0.3134341562152212
0.0004991382528510918,0.0010272,172.9767130225835,336.7229328335661,0.3134341562152212
0.000510800361562566,0.0010512,173.1095696436612,336.7229328335661,0.3134341562152212
0.0005123553093907625,0.0010544,173.12719405295275,336.7229328335661,0.3134341562152212
0.000519741311574696,0.0010696,173.2106267780125,336.7229328335661,0.3134341562152212
0.0005356795268137107,0.0011024,173.38910636552563,336.7229328335661,0.3134341562152212
0.0005442317398687917,0.00112,173.48402151820537,336.7229328335661,0.3134341562152212
0.0005488965833533813,0.0011296,173.5355481756241,336.7229328335661,0.3134341562152212
0.0005558938485802659,0.001144,173.61251909490932,336.7229328335661,0.3134341562152212
0.0005609474290219045,0.0011543999999999999,173.66787439947672,336.7229328335661,0.3134341562152212
0.0005753306964327227,0.001184,173.8243695040722,336.7229328335661,0.3134341562152212
0.0005807730138314105,0.0011952,173.88318502016875,336.7229328335661,0.3134341562152212
0.0005842716464448528,0.0012024,173.9208815190731,336.7229328335661,0.3134341562152212
0.0005916576486287864,0.0012175999999999999,174.00017513706752,336.7229328335661,0.3134341562152212
0.0005955450181992778,0.0012255999999999999,174.04175350911078,336.7229328335661,0.3134341562152212
0.000610317022567145,0.001256,174.19879527455737,336.7229328335661,0.3134341562152212
0.0006142043921376363,0.001264,174.2398747853017,336.7229328335661,0.3134341562152212
0.0006192579725792752,0.0012744,174.29312687635286,336.7229328335661,0.3134341562152212
0.0006336412399900932,0.001304,174.44377071007023,336.7229328335661,0.3134341562152212
0.0006437484008733707,0.0013248,174.54883168813964,336.7229328335661,0.3134341562152212
0.0006491907182720587,0.001336,174.6051364386528,336.7229328335661,0.3134341562152212
0.0006511344030573044,0.00134,174.62520062660468,336.7229328335661,0.3134341562152212
0.0006709599878668103,0.0013808,174.82853855604156,336.7229328335661,0.3134341562152212
0.0006849545183205793,0.0014096,174.97066269223066,336.7229328335661,0.3134341562152212
0.000692729257461562,0.0014256,175.04913107108047,336.7229328335661,0.3134341562152212
0.0007160534748845102,0.0014736,175.2825008401641,336.7229328335661,0.3134341562152212
0.000723828214025493,0.0014896,175.35962943891676,336.7229328335661,0.3134341562152212
0.0007483186423195886,0.00154,175.60049916786153,336.7229328335661,0.3134341562152212
0.0007588145401599153,0.0015616,175.70278566068959,336.7229328335661,0.3134341562152212
0.0007716428597425368,0.001588,175.82705619569646,336.7229328335661,0.3134341562152212
0.0007759189662700773,0.0015968,175.86830031348958,336.7229328335661,0.3134341562152212
0.0007856373901963057,0.0016167999999999998,175.96170868425955,336.7229328335661,0.3134341562152212
0.0007910797075949936,0.0016279999999999999,176.01382050978285,336.7229328335661,0.3134341562152212
0.0008007981315212221,0.001648,176.10653090465453,336.7229328335661,0.3134341562152212
0.0008066291858769591,0.00166,176.1619465388789,336.7229328335661,0.3134341562152212
0.0008159588728461383,0.0016791999999999998,176.25028769297148,336.7229328335661,0.3134341562152212
0.0008241223489441704,0.001696,176.3272635503757,336.7229328335661,0.3134341562152212
0.0008318970880851531,0.001712,176.40029788885838,336.7229328335661,0.3134341562152212
0.0008365619315697427,0.0017216,176.44399072616395,336.7229328335661,0.3134341562152212
0.0008451141446248237,0.0017392,176.52384826802395,336.7229328335661,0.3134341562152212
0.0008474465663671184,0.0017439999999999999,176.54557281967607,336.7229328335661,0.3134341562152212
0.0008509451989805607,0.0017511999999999998,176.57811597518958,336.7229328335661,0.3134341562152212
0.0008559987794221995,0.0017615999999999999,176.62503078270493,336.7229328335661,0.3134341562152212
0.0008614410968208875,0.0017728,176.67543378255533,336.7229328335661,0.3134341562152212
0.0008649397294343297,0.00178,176.70777014411252,336.7229328335661,0.3134341562152212
0.000877379312059902,0.0018055999999999999,176.822333028434,336.7229328335661,0.3134341562152212
0.0008797117338021969,0.0018104,176.8437428630734,336.7229328335661,0.3134341562152212
0.0008863202620720322,0.0018239999999999999,176.90428416923717,336.7229328335661,0.3134341562152212
0.0008952612120841624,0.0018424,176.98591352387984,336.7229328335661,0.3134341562152212
0.0009003147925258011,0.0018528,177.03191120529013,336.7229328335661,0.3134341562152212
0.0009038134251392433,0.0018599999999999999,177.06369678440015,336.7229328335661,0.3134341562152212
0.0009069233207956364,0.0018663999999999998,177.09191037024652,336.7229328335661,0.3134341562152212
0.0009100332164520296,0.0018728,177.1200862502379,336.7229328335661,0.3134341562152212
0.0009150867968936684,0.0018832,177.16579209639764,336.7229328335661,0.3134341562152212
0.0009209178512494053,0.0018951999999999999,177.21840746765037,336.7229328335661,0.3134341562152212
0.0009403546991018622,0.0019352,177.3928611541669,336.7229328335661,0.3134341562152212
0.0009473519643287467,0.0019496,177.45531948055543,336.7229328335661,0.3134341562152212
0.0009520168078133364,0.0019592,177.49685844020476,336.7229328335661,0.3134341562152212
0.0009555154404267787,0.0019664,177.52796058664626,336.7229328335661,0.3134341562152212
0.000962123968696614,0.00198,177.58658817575002,336.7229328335661,0.3134341562152212
0.0009881693448189062,0.0020336,177.8161367421431,336.7229328335661,0.3134341562152212
0.0009916679774323483,0.0020407999999999997,177.84679086412888,336.7229328335661,0.3134341562152212
0.0010095498774566085,0.0020775999999999998,178.00281361035456,336.7229328335661,0.3134341562152212
0.001013825983984149,0.0020864,178.03996326298778,336.7229328335661,0.3134341562152212
0.001019268301382837,0.0020976,178.0871563776804,336.7229328335661,0.3134341562152212
0.001025488092695623,0.0021103999999999997,178.14097119725466,336.7229328335661,0.3134341562152212
0.001032874094879557,0.0021256,178.2047112418662,336.7229328335661,0.3134341562152212
0.001039093886192343,0.0021384,178.25824931144368,336.7229328335661,0.3134341562152212
0.0010433699927198834,0.0021471999999999997,178.29498425624215,336.7229328335661,0.3134341562152212
0.0010628068405723404,0.0021872,178.46122677831707,336.7229328335661,0.3134341562152212
0.0010896296906087307,0.0022424,178.68870724124713,336.7229328335661,0.3134341562152212
0.0010997368514920084,0.0022632,178.7738566693234,336.7229328335661,0.3134341562152212
0.0011059566428047946,0.002276,178.82610464137616,336.7229328335661,0.3134341562152212
0.001112953908031679,0.0022903999999999997,178.884746824828,336.7229328335661,0.3134341562152212
0.0011257822276143005,0.0023168,178.99188539612123,336.7229328335661,0.3134341562152212
0.0011444416015526592,0.0023552,179.14687724568668,336.7229328335661,0.3134341562152212
0.0011514388667795436,0.0023696,179.20474470433942,336.7229328335661,0.3134341562152212
0.001154937499392986,0.0023768,179.2336269918529,336.7229328335661,0.3134341562152212
0.0011603798167916738,0.002388,179.27848726429565,336.7229328335661,0.3134341562152212
0.0011619347646198703,0.0023912,179.29128940384334,336.7229328335661,0.3134341562152212
0.0011794279276870815,0.0024272,179.43485608820578,336.7229328335661,0.3134341562152212
0.0011852589820428184,0.0024392,179.4825267885453,336.7229328335661,0.3134341562152212
0.001189535088570359,0.002448,179.5174271919292,336.7229328335661,0.3134341562152212
0.0011973098277113419,0.002464,179.58075737308073,336.7229328335661,0.3134341562152212
0.0012085831994657667,0.0024871999999999997,179.6723019989747,336.7229328335661,0.3134341562152212
0.0012140255168644548,0.0024984,179.71637671403815,336.7229328335661,0.3134341562152212
0.001215191727735602,0.0025008,179.72581126299002,336.7229328335661,0.3134341562152212
0.001223355203833634,0.0025176,179.7917545141953,336.7229328335661,0.3134341562152212
0.0012299637321034691,0.0025312,179.84501153874123,336.7229328335661,0.3134341562152212
0.0012338511016739605,0.0025391999999999997,179.8762870709799,336.7229328335661,0.3134341562152212
0.0012357947864592063,0.0025432,179.8919104244339,336.7229328335661,0.3134341562152212
0.001254842897354614,0.0025824,180.04451551320005,336.7229328335661,0.3134341562152212
0.0012583415299680563,0.0025896,180.07244653618082,336.7229328335661,0.3134341562152212
0.0012641725843237934,0.0026016,180.1189310314633,336.7229328335661,0.3134341562152212
0.0012684486908513338,0.0026103999999999997,180.15296653312768,336.7229328335661,0.3134341562152212
0.0012707811125936286,0.0026152,180.17151249052765,336.7229328335661,0.3134341562152212
0.0012789445886916605,0.002632,180.23631905570633,336.7229328335661,0.3134341562152212
0.0012843869060903486,0.0026432,180.2794338291069,336.7229328335661,0.3134341562152212
0.001288663012617889,0.002652,180.31325975927493,336.7229328335661,0.3134341562152212
0.0012929391191454295,0.0026608,180.34704194292658,336.7229328335661,0.3134341562152212
0.0013022688061146087,0.00268,180.42059764819507,336.7229328335661,0.3134341562152212
0.0013100435452555914,0.002696,180.48173720831483,336.7229328335661,0.3134341562152212
0.0013244268126664095,0.0027256,180.59447363295328,336.7229328335661,0.3134341562152212
0.0013287029191939499,0.0027343999999999997,180.62789765694768,336.7229328335661,0.3134341562152212
0.0013329790257214905,0.0027432,180.6612797560121,336.7229328335661,0.3134341562152212
0.0013353114474637855,0.002748,180.67947056971803,336.7229328335661,0.3134341562152212
0.0013423087126906699,0.0027624,180.73396880407023,336.7229328335661,0.3134341562152212
0.0013481397670464068,0.0027743999999999998,180.77929941531755,336.7229328335661,0.3134341562152212
0.0013621342975001758,0.0028032,180.88778203206178,336.7229328335661,0.3134341562152212
0.0013737964062116499,0.0028271999999999998,180.97785256622714,336.7229328335661,0.3134341562152212
0.001376906301868043,0.0028336,181.0018209510434,336.7229328335661,0.3134341562152212
0.0013819598823096818,0.0028439999999999997,181.04072459598808,336.7229328335661,0.3134341562152212
0.0013905120953647627,0.0028615999999999997,181.10643537514073,336.7229328335661,0.3134341562152212
0.0013978980975486962,0.0028767999999999997,181.16305885231185,336.7229328335661,0.3134341562152212
0.0014045066258185318,0.0028904,181.21362313639915,336.7229328335661,0.3134341562152212
0.0014177236823582024,0.0029176,181.31447419903958,336.7229328335661,0.3134341562152212
0.0014223885258427922,0.0029272,181.34998105877085,336.7229328335661,0.3134341562152212
0.0014313294758549222,0.0029456,181.41790918999615,336.7229328335661,0.3134341562152212
0.001434050634554266,0.0029511999999999997,181.43855009609305,336.7229328335661,0.3134341562152212
0.0014371605302106593,0.0029576,181.46212100816447,336.7229328335661,0.3134341562152212
0.0014398816889100033,0.0029632,181.48272924328145,336.7229328335661,0.3134341562152212
0.0014546536932778704,0.0029936,181.59433860364848,336.7229328335661,0.3134341562152212
0.0014604847476336073,0.0030055999999999998,181.63827314441244,336.7229328335661,0.3134341562152212
0.0014643721172040989,0.0030136,181.66752483867035,336.7229328335661,0.3134341562152212
0.0014686482237316393,0.0030223999999999997,181.69966674613246,336.7229328335661,0.3134341562152212
0.001476034225915573,0.0030375999999999997,181.75509875303015,336.7229328335661,0.3134341562152212
0.0014779779107008185,0.0030415999999999998,181.76966813035486,336.7229328335661,0.3134341562152212
0.0014799215954860642,0.0030456,181.78423003713488,336.7229328335661,0.3134341562152212
0.001487696334627047,0.0030616,181.84240323085987,336.7229328335661,0.3134341562152212
0.0014931386520257348,0.0030727999999999997,181.88305394025699,336.7229328335661,0.3134341562152212
0.0015005246542096687,0.003088,181.93813045430883,336.7229328335661,0.3134341562152212
0.0015141304477063883,0.003116,182.0393112111907,336.7229328335661,0.3134341562152212
0.0015265700303319608,0.0031416,182.13150945985296,336.7229328335661,0.3134341562152212
0.0015300686629454029,0.0031487999999999998,182.15738736498318,336.7229328335661,0.3134341562152212
0.0015351222433870417,0.0031592,182.19472585749295,336.7229328335661,0.3134341562152212
0.0015483392999267123,0.0031864,182.2921544359311,336.7229328335661,0.3134341562152212
0.001550282984711958,0.0031904,182.3064547642101,336.7229328335661,0.3134341562152212
0.001566998673865071,0.0032248,182.4291502780194,336.7229328335661,0.3134341562152212
0.0015739959390919554,0.0032392,182.4803595087862,336.7229328335661,0.3134341562152212
0.0015809932043188398,0.0032535999999999997,182.53148003153646,336.7229328335661,0.3134341562152212
0.0015876017325886754,0.0032672,182.57967956413236,336.7229328335661,0.3134341562152212
0.0015996525782571984,0.003292,182.66737187043003,336.7229328335661,0.3134341562152212
0.0016023737369565425,0.0032976,182.68713765764196,336.7229328335661,0.3134341562152212
0.0016214218478519502,0.0033368,182.82513346238588,336.7229328335661,0.3134341562152212
0.0016256979543794905,0.0033456,182.85602504572486,336.7229328335661,0.3134341562152212
0.001629585323949982,0.0033536,182.88408081529772,336.7229328335661,0.3134341562152212
0.001632306482649326,0.0033591999999999997,182.90370432566667,336.7229328335661,0.3134341562152212
0.0016416361696185051,0.0033783999999999997,182.97088828600982,336.7229328335661,0.3134341562152212
0.001643579854403751,0.0033824,182.98486618318768,336.7229328335661,0.3134341562152212
0.001658351858771618,0.0034127999999999997,183.0908883278094,336.7229328335661,0.3134341562152212
0.0016614617544280113,0.0034192,183.11316177491247,336.7229328335661,0.3134341562152212
0.001671957652268338,0.0034408,183.18821490791044,336.7229328335661,0.3134341562152212
0.0016816760761945665,0.0034608,183.25754487595117,336.7229328335661,0.3134341562152212
0.0016875071305503034,0.0034728,183.29906785736563,336.7229328335661,0.3134341562152212
0.0016898395522925982,0.0034776,183.31566137745168,336.7229328335661,0.3134341562152212
0.0016945043957771878,0.0034871999999999998,183.3488216449402,336.7229328335661,0.3134341562152212
0.0017127750327584972,0.0035248,183.47835801423327,336.7229328335661,0.3134341562152212
0.0017139412436296447,0.0035272,183.48660794946133,336.7229328335661,0.3134341562152212
0.0017189948240712834,0.0035375999999999997,183.52233240061676,336.7229328335661,0.3134341562152212
0.0017326006175680034,0.0035656,183.61831061265488,336.7229328335661,0.3134341562152212
0.0017399866197519368,0.0035808,183.67028995749592,336.7229328335661,0.3134341562152212
0.0017411528306230844,0.0035832,183.67848934972548,336.7229328335661,0.3134341562152212
0.0017586459936902955,0.0036192,183.80122435612446,336.7229328335661,0.3134341562152212
0.0017609784154325903,0.003624,183.81755297526942,336.7229328335661,0.3134341562152212
0.0017664207328312782,0.0036352,183.85562032042972,336.7229328335661,0.3134341562152212
0.0017765278937145559,0.003656,183.92619568510426,336.7229328335661,0.3134341562152212
0.0017835251589414403,0.0036704,183.97496384738164,336.7229328335661,0.3134341562152212
0.0017893562132971772,0.0036823999999999997,184.01554700808873,336.7229328335661,0.3134341562152212
0.0017986859002663564,0.0037015999999999998,184.08037294864712,336.7229328335661,0.3134341562152212
0.0018122916937630764,0.0037296,184.17467620488776,336.7229328335661,0.3134341562152212
0.0018192889589899609,0.003744,184.22306748237733,336.7229328335661,0.3134341562152212
0.001822787591603403,0.0037511999999999997,184.24723589714543,336.7229328335661,0.3134341562152212
0.001825897487259796,0.0037576,184.26870374872567,336.7229328335661,0.3134341562152212
0.001831339804658484,0.0037687999999999997,184.306238207262,336.7229328335661,0.3134341562152212
0.0018546640220814324,0.0038168,184.46660994079195,336.7229328335661,0.3134341562152212
0.0018674923416640537,0.0038431999999999997,184.55447905811565,336.7229328335661,0.3134341562152212
0.0018690472894922502,0.0038464,184.56511384065718,336.7229328335661,0.3134341562152212
0.0018698247634063485,0.003848,184.5704299379309,336.7229328335661,0.3134341562152212
0.0018717684481915943,0.003852,184.58371641095437,336.7229328335661,0.3134341562152212
0.001879154450375528,0.0038672,184.63415601128077,336.7229328335661,0.3134341562152212
0.001883041819946019,0.0038751999999999997,184.6606721104144,336.7229328335661,0.3134341562152212
0.0018962588764856899,0.0039024,184.75066758871873,336.7229328335661,0.3134341562152212
0.0018985912982279847,0.0039071999999999996,184.7665237156937,336.7229328335661,0.3134341562152212
0.001917250672166343,0.0039456,184.89310039103034,336.7229328335661,0.3134341562152212
0.0019285240439207683,0.0039688,184.96934100667497,336.7229328335661,0.3134341562152212
0.0019304677287060137,0.003972799999999999,184.98246835378217,336.7229328335661,0.3134341562152212
0.001933188887405358,0.0039784,185.00083798311948,336.7229328335661,0.3134341562152212
0.00195301633852552,0.004019203840768154,185.1343833422436,336.7229328335661,0.3134341562152212
0.002064994977883543,0.004249649929985997,185.87890484699358,336.7229328335661,0.3134341562152212
0.002242294490200413,0.0046145229045809165,187.0262931261738,336.7229328335661,0.3134341562152212
0.0024475886623567884,0.0050370074014802965,188.31150460894,336.7229328335661,0.3134341562152212
0.0031474551583444326,0.0064772954590918185,192.40661118594193,336.7229328335661,0.3134341562152212
0.0033340862239411378,0.006861372274454891,193.43637557326355,336.7229328335661,0.3134341562152212
0.003474059523138666,0.007149429885977195,194.19400435483465,336.7229328335661,0.3134341562152212
0.0035207172895378425,0.007245449089817963,194.4438891380718,336.7229328335661,0.3134341562152212
0.0035673750559370187,0.007341468293658731,194.6924856998243,336.7229328335661,0.3134341562152212
0.004033952719928782,0.008301660332066413,197.1124057536174,336.7229328335661,0.3134341562152212
0.004229915338805322,0.00870494098819764,198.09589522241538,336.7229328335661,0.3134341562152212
0.004397883297842357,0.009050610122024405,198.92482214474228,336.7229328335661,0.3134341562152212
0.0045565197035995555,0.009377075415083017,199.69643031264988,336.7229328335661,0.3134341562152212
0.004603177469998732,0.009473094618923785,199.92137060416988,336.7229328335661,0.3134341562152212
0.004771145429035767,0.00981876375275055,200.72389530064333,336.7229328335661,0.3134341562152212
0.004845797855274449,0.00997239447889578,201.07702786359732,336.7229328335661,0.3134341562152212
0.005032428920871154,0.010356471294258852,201.9507011626874,336.7229328335661,0.3134341562152212
0.005293712412706542,0.010894178835767154,203.15290242740204,336.7229328335661,0.3134341562152212
0.005443017265183905,0.011201440288057612,203.8294796142913,336.7229328335661,0.3134341562152212
0.00584427405621682,0.012027205441088217,205.61283515860802,336.7229328335661,0.3134341562152212
0.005946921142295008,0.012238447689537907,206.06128923074255,336.7229328335661,0.3134341562152212
0.006086894441492537,0.012526505301060212,206.6679824307726,336.7229328335661,0.3134341562152212
0.006161546867731219,0.01268013602720544,206.9893261301023,336.7229328335661,0.3134341562152212
0.006264193953809407,0.012891378275655131,207.42870537267993,336.7229328335661,0.3134341562152212
0.006385504146447265,0.013141028205641128,207.9443678904556,336.7229328335661,0.3134341562152212
0.006712108511241499,0.013813162632526505,209.31404241944807,336.7229328335661,0.3134341562152212
0.006740103171081005,0.013870774154830966,209.43021984564248,336.7229328335661,0.3134341562152212
0.006889408023558369,0.014178035607121425,210.04668317636086,336.7229328335661,0.3134341562152212
0.00708537064243491,0.014581316263252651,210.84794112587988,336.7229328335661,0.3134341562152212
0.00745863277362832,0.015349469893978797,212.35062961998108,336.7229328335661,0.3134341562152212
0.007738579372023377,0.015925585117023404,213.4584682539406,336.7229328335661,0.3134341562152212
0.008401119654891681,0.017289057811562314,216.01985500549222,336.7229328335661,0.3134341562152212
0.008522429847529538,0.01753870774154831,216.48017895100853,336.7229328335661,0.3134341562152212
0.00859708227376822,0.01769233846769354,216.76218534792648,336.7229328335661,0.3134341562152212
0.008671734700006902,0.017845969193838768,217.04323831717866,336.7229328335661,0.3134341562152212
0.00869972935984641,0.01790358071614323,217.14838970725552,336.7229328335661,0.3134341562152212
0.008998339064801138,0.018518103620724147,218.26191459199,336.7229328335661,0.3134341562152212
0.009035665277920478,0.01859491898379676,218.4000846944054,336.7229328335661,0.3134341562152212
0.009240959450076853,0.019017403480696138,219.15607819232892,336.7229328335661,0.3134341562152212
0.00948357983535257,0.019516703340668136,220.04113155747032,336.7229328335661,0.3134341562152212
0.009744863327187957,0.020054410882176434,220.98444698112635,336.7229328335661,0.3134341562152212
0.009772857987027463,0.020112022404480897,221.08492795783025,336.7229328335661,0.3134341562152212
0.009856841966545979,0.020284856971394278,221.38569951628764,336.7229328335661,0.3134341562152212
0.01003414147886285,0.0206497299459892,222.01739917918093,336.7229328335661,0.3134341562152212
0.010155451671500707,0.020899379875975194,222.4471086087919,336.7229328335661,0.3134341562152212
0.010342082737097413,0.021283456691338267,223.10431152467473,336.7229328335661,0.3134341562152212
0.01037007739693692,0.02134106821364273,223.20249158365104,336.7229328335661,0.3134341562152212
0.010435398269895766,0.021475495099019803,223.43117728439654,336.7229328335661,0.3134341562152212
0.010668687101891648,0.021955591118223646,224.24339362259866,336.7229328335661,0.3134341562152212
0.011163259425722915,0.022973394678935787,225.94273181144143,336.7229328335661,0.3134341562152212
0.011340558938039785,0.023338267653530708,226.54474496392768,336.7229328335661,0.3134341562152212
0.01152719000363649,0.023722344468893777,227.1744908565139,336.7229328335661,0.3134341562152212
0.011825799708591218,0.024336867373474694,228.17387554255447,336.7229328335661,0.3134341562152212
0.011909783688109736,0.024509701940388078,228.45317294835925,336.7229328335661,0.3134341562152212
0.012236388052903968,0.025181836367273454,229.53210540757334,336.7229328335661,0.3134341562152212
0.012908259889052108,0.026564512902580516,231.71693020875895,336.7229328335661,0.3134341562152212
0.013076227848089142,0.02691018203640728,232.2561495839848,336.7229328335661,0.3134341562152212
0.013150880274327825,0.02706381276255251,232.49493484287234,336.7229328335661,0.3134341562152212
0.013318848233364858,0.027409481896379276,233.03027725524248,336.7229328335661,0.3134341562152212
0.013384169106323706,0.027543908781756353,233.2377540879007,336.7229328335661,0.3134341562152212
0.01369211036455827,0.02817763552710542,234.2105890644958,336.7229328335661,0.3134341562152212
0.01396272540967349,0.028734546909381875,235.05848176994945,336.7229328335661,0.3134341562152212
0.014102698708871021,0.02902260452090418,235.49453064831113,336.7229328335661,0.3134341562152212
0.014410639967105583,0.02965633126625325,236.44794049908168,336.7229328335661,0.3134341562152212
0.01447596084006443,0.029790758151630327,236.64915371184375,336.7229328335661,0.3134341562152212
0.014699918118780476,0.030251650330066014,237.33635518244108,336.7229328335661,0.3134341562152212
0.01502652248357471,0.03092378475695139,238.33124941310166,336.7229328335661,0.3134341562152212
0.015325132188529437,0.0315383076615323,239.23351110300592,336.7229328335661,0.3134341562152212
0.015661068106603507,0.03222964592918584,240.24039949251068,336.7229328335661,0.3134341562152212
0.015782378299241367,0.032479295859171836,240.60192342094328,336.7229328335661,0.3134341562152212
0.015978340918117905,0.03288257651530306,241.18364265922776,336.7229328335661,0.3134341562152212
0.016071656450916256,0.033074614922984594,241.45967329116223,336.7229328335661,0.3134341562152212
0.016183635090274283,0.033305061012202444,241.79008635217792,336.7229328335661,0.3134341562152212
0.01687417003298209,0.03472614522904581,243.8082753956942,336.7229328335661,0.3134341562152212
0.0170887957584183,0.03516783356671334,244.42895443946318,336.7229328335661,0.3134341562152212
0.01717277973793682,0.035340668133626726,244.67100035192962,336.7229328335661,0.3134341562152212
0.017219437504335994,0.03543668733746749,244.8052708112251,336.7229328335661,0.3134341562152212
0.01763935740192858,0.036300860172034405,246.00738645941075,336.7229328335661,0.3134341562152212
0.017928635553603477,0.036896179235847176,246.8290253842648,336.7229328335661,0.3134341562152212
0.017956630213442976,0.036953790758151625,246.90826344531237,336.7229328335661,0.3134341562152212
0.01800328797984216,0.037049809961992405,247.04021990211177,336.7229328335661,0.3134341562152212
0.018171255938879194,0.03739547909581917,247.5141628029121,336.7229328335661,0.3134341562152212
0.018339223897916226,0.03774114822964593,247.98640018328817,336.7229328335661,0.3134341562152212
0.018544518070072603,0.03816363272654531,248.56129464188123,336.7229328335661,0.3134341562152212
0.01875914379550881,0.03860532106421284,249.1596730713944,336.7229328335661,0.3134341562152212
0.018927111754545842,0.0389509901980396,249.6261087738793,336.7229328335661,0.3134341562152212
0.01921638990622074,0.039546309261852375,250.42564804286164,336.7229328335661,0.3134341562152212
0.019337700098858598,0.03979595919183837,250.75954013157624,336.7229328335661,0.3134341562152212
0.019570988930854474,0.0402760552110422,251.39935320869787,336.7229328335661,0.3134341562152212
0.019757619996451186,0.04066013202640528,251.90906466778952,336.7229328335661,0.3134341562152212
0.01999090882844707,0.04114022804560913,252.5435710774289,336.7229328335661,0.3134341562152212
0.020242860767002616,0.041658731746349265,253.2256031325045,336.7229328335661,0.3134341562152212
0.020392165619479978,0.04196599319863972,253.62820813400714,336.7229328335661,0.3134341562152212
0.020588128238356526,0.04236927385477096,254.15488686647814,336.7229328335661,0.3134341562152212
0.02073743309083389,0.04267653530706142,254.55485468033382,336.7229328335661,0.3134341562152212
0.020756096197393558,0.04271494298859772,254.60477157078464,336.7229328335661,0.3134341562152212
0.020989385029389435,0.043195039007801556,255.2272630433161,336.7229328335661,0.3134341562152212
0.021082700562187792,0.0433870774154831,255.47550339809519,336.7229328335661,0.3134341562152212
0.02132532094746351,0.043886377275455093,256.1189311284995,336.7229328335661,0.3134341562152212
0.021446631140101365,0.04413602720544109,256.4395739314661,336.7229328335661,0.3134341562152212
0.021623930652418237,0.04450090018003601,256.9069362810442,336.7229328335661,0.3134341562152212
0.021913208804093125,0.04509621924384877,257.66627917837,336.7229328335661,0.3134341562152212
0.02205318210329066,0.04538427685537108,258.032298830993,336.7229328335661,0.3134341562152212
0.022099839869689834,0.04548029605921185,258.1541038953188,336.7229328335661,0.3134341562152212
0.02214649763608901,0.045576315263052614,258.2758087091848,336.7229328335661,0.3134341562152212
0.0222491447221672,0.045787557511502305,258.5432078620418,336.7229328335661,0.3134341562152212
0.02236112336152522,0.04601800360072014,258.8343679049522,336.7229328335661,0.3134341562152212
0.02242644423448407,0.046152430486097226,259.00394866364513,336.7229328335661,0.3134341562152212
0.022594412193521103,0.04649809961992399,259.4391312954052,336.7229328335661,0.3134341562152212
0.022678396173039617,0.04667093418683736,259.65624933598366,336.7229328335661,0.3134341562152212
0.02280903791895731,0.04693978795759152,259.99336626678155,336.7229328335661,0.3134341562152212
0.023126310730471708,0.04759271854370874,260.80895894563446,336.7229328335661,0.3134341562152212
0.023340936455907922,0.04803440688137628,261.3582104195525,336.7229328335661,0.3134341562152212
0.02337826266902726,0.04811122224444889,261.4535310005677,336.7229328335661,0.3134341562152212
0.023490241308385288,0.04834166833366674,261.73913725306744,336.7229328335661,0.3134341562152212
0.023592888394463475,0.04855291058211643,262.00047687701664,336.7229328335661,0.3134341562152212
0.02374219324694084,0.04886017203440689,262.37981703304234,336.7229328335661,0.3134341562152212
0.024096792271574574,0.049589917983596715,263.2770405617367,336.7229328335661,0.3134341562152212
0.024255428677331776,0.04991638327665533,263.6767614128599,336.7229328335661,0.3134341562152212
0.024479385956047824,0.05037727545509102,264.2393418192969,336.7229328335661,0.3134341562152212
0.024591364595405844,0.050607721544308856,264.519879022792,336.7229328335661,0.3134341562152212
0.024731337894603377,0.05089577915583117,264.8698509139109,336.7229328335661,0.3134341562152212
0.024824653427401727,0.0510878175635127,265.1027364410953,336.7229328335661,0.3134341562152212
0.025020616046278265,0.05149109821964393,265.590687683078,336.7229328335661,0.3134341562152212
0.025328557304512833,0.052124824964993,266.35446764387626,336.7229328335661,0.3134341562152212
0.025748477202105418,0.052988997799559914,267.39017490081676,336.7229328335661,0.3134341562152212
0.025813798075064263,0.053123424684936985,267.55069094963375,336.7229328335661,0.3134341562152212
0.02609374467345932,0.0536995399079816,268.2368303821004,336.7229328335661,0.3134341562152212
0.026159065546418166,0.05383396679335867,268.3965157794446,336.7229328335661,0.3134341562152212
0.02630837039889553,0.054141228245649126,268.7609281646007,336.7229328335661,0.3134341562152212
0.02642968059153339,0.05439087817563512,269.05641969458713,336.7229328335661,0.3134341562152212
0.02647633835793257,0.0544868973794759,269.1699293796668,336.7229328335661,0.3134341562152212
0.026532327677611576,0.05460212042408481,269.30603807752,336.7229328335661,0.3134341562152212
0.026681632530088942,0.05490938187637527,269.66844808487195,336.7229328335661,0.3134341562152212
0.026756284956327623,0.0550630126025205,269.8493564359338,336.7229328335661,0.3134341562152212
0.027036231554722682,0.05563912782556511,270.5260166747424,336.7229328335661,0.3134341562152212
0.027129547087521032,0.055831166233246646,270.7509621368712,336.7229328335661,0.3134341562152212
0.027390830579356422,0.056368873774754955,271.3792097470316,336.7229328335661,0.3134341562152212
0.027502809218714442,0.05659931986397279,271.6477427599776,336.7229328335661,0.3134341562152212
0.02779208737038934,0.05719463892778556,272.3394868613819,336.7229328335661,0.3134341562152212
0.02826799658766093,0.058174034806961386,273.47143859839696,336.7229328335661,0.3134341562152212
0.028407969886858467,0.0584620924184837,273.8029479470952,336.7229328335661,0.3134341562152212
0.028519948526216483,0.058692538507701536,274.06769698810854,336.7229328335661,0.3134341562152212
0.02863192716557451,0.05892298459691939,274.33204093651625,336.7229328335661,0.3134341562152212
0.028921205317249402,0.059518303660732144,275.01307001327984,336.7229328335661,0.3134341562152212
0.02910783638284611,0.059902380476095224,275.4510341633594,336.7229328335661,0.3134341562152212
0.029191820362364625,0.0600752150430086,275.647760596632,336.7229328335661,0.3134341562152212
0.029350456768121827,0.060401680336067215,276.0187537778636,336.7229328335661,0.3134341562152212
0.029471766960759684,0.06065133026605321,276.3019270273427,336.7229328335661,0.3134341562152212
0.0295557509402782,0.0608241648329666,276.49770381209595,336.7229328335661,0.3134341562152212
0.0298730237517926,0.06147709541908382,277.2353551919064,336.7229328335661,0.3134341562152212
0.030022328604269965,0.06178435687137428,277.5814274402065,336.7229328335661,0.3134341562152212
0.030199628116586833,0.0621492298459692,277.99151765915536,336.7229328335661,0.3134341562152212
0.030292943649385184,0.06234126825365073,278.20697741374676,336.7229328335661,0.3134341562152212
0.030432916948582713,0.06262932586517303,278.5296823430999,336.7229328335661,0.3134341562152212
0.0308248421863358,0.0634358871774355,279.4301910818419,336.7229328335661,0.3134341562152212
0.03103013635849217,0.06385837167433486,279.90010343475103,336.7229328335661,0.3134341562152212
0.031216767424088878,0.06424244848969794,280.32624538650975,336.7229328335661,0.3134341562152212
0.031244762083928384,0.0643000600120024,280.3900808783994,336.7229328335661,0.3134341562152212
0.03160869266184196,0.06504900980196039,281.2179228072689,336.7229328335661,0.3134341562152212
0.031776660620878985,0.06539467893578715,281.5987491395109,336.7229328335661,0.3134341562152212
0.031832649940558004,0.06550990198039608,281.7255166841737,336.7229328335661,0.3134341562152212
0.032215243625031253,0.06629725945189038,282.5894460400043,336.7229328335661,0.3134341562152212
0.03233655381766911,0.06654690938187638,282.86253811968675,336.7229328335661,0.3134341562152212
0.03241120624390779,0.06670054010802161,283.0303962005671,336.7229328335661,0.3134341562152212
0.032747142161981865,0.06739187837567515,283.78389937064696,336.7229328335661,0.3134341562152212
0.033213719825973625,0.06835207041408282,284.8254494786054,336.7229328335661,0.3134341562152212
0.033381687785010654,0.06869773954790959,285.19900860518294,336.7229328335661,0.3134341562152212
0.033540324190767856,0.0690242048409682,285.5511419097801,336.7229328335661,0.3134341562152212
0.0336056450637267,0.06915863172634527,285.6959491124426,336.7229328335661,0.3134341562152212
0.033689629043245226,0.06933146629325866,285.88196860528376,336.7229328335661,0.3134341562152212
0.0339229178752411,0.0698115623124625,286.3977429034697,336.7229328335661,0.3134341562152212
0.03399757030147978,0.06996519303860772,286.56249827743136,336.7229328335661,0.3134341562152212
0.034268185346595,0.07052210442088418,287.1585574136807,336.7229328335661,0.3134341562152212
0.03496805184258265,0.0719623924784957,288.6916383772733,336.7229328335661,0.3134341562152212
0.035098693588500346,0.07223124624924986,288.9764832325246,336.7229328335661,0.3134341562152212
0.035462624166413916,0.07298019603920784,289.767807548267,336.7229328335661,0.3134341562152212
0.03560259746561145,0.07326825365073016,290.07131894468387,336.7229328335661,0.3134341562152212
0.03587321251072667,0.07382516503300661,290.6567912863341,336.7229328335661,0.3134341562152212
0.03616249066240156,0.07442048409681937,291.2807395076422,336.7229328335661,0.3134341562152212
0.036302463961599085,0.07470854170834167,291.581950864332,336.7229328335661,0.3134341562152212
0.03662906832639332,0.07538067613522705,292.28302140097134,336.7229328335661,0.3134341562152212
0.036685057646072335,0.07549589917983597,292.402959718311,336.7229328335661,0.3134341562152212
0.03681569939199003,0.07576475295059013,292.68253850719645,336.7229328335661,0.3134341562152212
0.03704898822398591,0.07624484896979396,293.1808258881694,336.7229328335661,0.3134341562152212
0.03720762462974311,0.07657131426285257,293.5189625524284,336.7229328335661,0.3134341562152212
0.037431581908459154,0.07703220644128826,293.99537634469254,336.7229328335661,0.3134341562152212
0.03757155520765668,0.07732026405281056,294.29257051410383,336.7229328335661,0.3134341562152212
0.03787949646589125,0.07795399079815964,294.9448819521523,336.7229328335661,0.3134341562152212
0.03804746442492828,0.0782996599319864,295.29981637177167,336.7229328335661,0.3134341562152212
0.03817810617084598,0.07856851370274055,295.5754541562724,336.7229328335661,0.3134341562152212
0.03843938966268136,0.07910622124424885,296.125628649638,336.7229328335661,0.3134341562152212
0.03863535228155791,0.07950950190038009,296.5373029004241,336.7229328335661,0.3134341562152212
0.03901794596603115,0.08029685937187438,297.33870838811407,336.7229328335661,0.3134341562152212
0.03909259839226983,0.0804504900980196,297.4947222258454,336.7229328335661,0.3134341562152212
0.03920457703162786,0.08068093618723746,297.72852529912524,336.7229328335661,0.3134341562152212
0.03943786586362373,0.08116103220644129,298.2147802005299,336.7229328335661,0.3134341562152212
0.039475192076743076,0.08123784756951391,298.2924767632281,336.7229328335661,0.3134341562152212
0.039755138675138135,0.08181396279255852,298.8742904560894,336.7229328335661,0.3134341562152212
0.03992310663417517,0.08215963192638528,299.2226117611526,336.7229328335661,0.3134341562152212
0.0400630799333727,0.08244768953790758,299.51244313720576,336.7229328335661,0.3134341562152212
0.04010973769977187,0.08254370874174835,299.6089658005072,336.7229328335661,0.3134341562152212
0.04028703721208874,0.08290858171634327,299.97535325404107,336.7229328335661,0.3134341562152212
0.04052032604408463,0.08338867773554712,300.4564853585348,336.7229328335661,0.3134341562152212
0.040632304683442644,0.08361912382476495,300.68704493833644,336.7229328335661,0.3134341562152212
0.04090291972855787,0.08417603520704141,301.2432099204533,336.7229328335661,0.3134341562152212
0.041033561474475566,0.08444488897779556,301.51118959246963,336.7229328335661,0.3134341562152212
0.041164203220393256,0.08471374274854972,301.7788367270842,336.7229328335661,0.3134341562152212
0.04132283962615045,0.08504020804160832,302.1033918707768,336.7229328335661,0.3134341562152212
0.041518802245027,0.08544348869773956,302.5036428365584,336.7229328335661,0.3134341562152212
0.04169610175734387,0.08580836167233447,302.86514026313074,336.7229328335661,0.3134341562152212
0.04206936388853728,0.08657651530306061,303.62423378308745,336.7229328335661,0.3134341562152212
0.042162679421335635,0.08676855371074216,303.81359618492746,336.7229328335661,0.3134341562152212
0.04230265272053316,0.08705661132226446,304.09733360820644,336.7229328335661,0.3134341562152212
0.0424986153394097,0.08745989197839568,304.493951640431,336.7229328335661,0.3134341562152212
0.04259193087220805,0.08765193038607721,304.6825666291888,336.7229328335661,0.3134341562152212
0.042815888150924096,0.0881128225645129,305.1345862654088,336.7229328335661,0.3134341562152212
0.042955861450121625,0.08840088017603522,305.41663033014316,336.7229328335661,0.3134341562152212
0.043105166302598995,0.08870814162832567,305.71708255277775,336.7229328335661,0.3134341562152212
0.04326380270835619,0.08903460692138428,306.0358686723332,336.7229328335661,0.3134341562152212
0.04340377600755372,0.08932266453290659,306.31677215842603,336.7229328335661,0.3134341562152212
0.043525086200191576,0.08957231446289259,306.5599361909452,336.7229328335661,0.3134341562152212
0.0436370648395496,0.08980276055211042,306.78416080272706,336.7229328335661,0.3134341562152212
0.04372104881906812,0.08997559511902381,306.9521820272446,336.7229328335661,0.3134341562152212
0.04401032697074301,0.09057091418283657,307.52996077090694,336.7229328335661,0.3134341562152212
0.04420628958961955,0.09097419483896779,307.92051801711295,336.7229328335661,0.3134341562152212
0.044467573081454936,0.0915119023804761,308.4402123055703,336.7229328335661,0.3134341562152212
0.04454222550769362,0.09166553310662133,308.5884774728106,336.7229328335661,0.3134341562152212
0.04476618278640967,0.09212642528505702,309.032692594689,336.7229328335661,0.3134341562152212
0.044784845892969334,0.09216483296659332,309.0696713541728,336.7229328335661,0.3134341562152212
0.04504612938480473,0.09270254050810163,309.58674457334325,336.7229328335661,0.3134341562152212
0.045214097343841755,0.09304820964192839,309.9185312203106,336.7229328335661,0.3134341562152212
0.0452794182168006,0.09318263652730546,310.0474294988395,336.7229328335661,0.3134341562152212
0.0454100599627183,0.09345149029805962,310.3050086995887,336.7229328335661,0.3134341562152212
0.04584864296687055,0.09435407081416283,311.1676329375847,336.7229328335661,0.3134341562152212
0.04601661092590759,0.09469973994798961,311.49714665871403,336.7229328335661,0.3134341562152212
0.04608193179886644,0.09483416683336668,311.62516416122907,336.7229328335661,0.3134341562152212
0.046203241991504294,0.09508381676335267,311.8627233491673,336.7229328335661,0.3134341562152212
0.046305889077582485,0.09529505901180237,312.0635450334471,336.7229328335661,0.3134341562152212
0.04655784101613804,0.09581356271254252,312.55573633129694,336.7229328335661,0.3134341562152212
0.046781798294854085,0.0962744548909782,312.99236831780786,336.7229328335661,0.3134341562152212
0.04701508712684996,0.09675455091018204,313.44632732221504,336.7229328335661,0.3134341562152212
0.04708040799980881,0.09688897779555912,313.5732783089641,336.7229328335661,0.3134341562152212
0.04722971285228617,0.09719623924784958,313.86319432617165,336.7229328335661,0.3134341562152212
0.04731369683180469,0.09736907381476295,314.02611500650585,336.7229328335661,0.3134341562152212
0.04749099634412156,0.09773394678935787,314.36968875096017,336.7229328335661,0.3134341562152212
0.04779893760235612,0.09836767353470695,314.9652355241907,336.7229328335661,0.3134341562152212
0.04786425847531497,0.09850210042008402,315.09137104913145,336.7229328335661,0.3134341562152212
0.04823752060650838,0.09927025405081016,315.8108617626327,336.7229328335661,0.3134341562152212
0.04853613031146311,0.09988477695539108,316.38489222408026,336.7229328335661,0.3134341562152212
0.04858278807786228,0.09998079615923185,316.4744599160666,336.7229328335661,0.3134341562152212