File: datasets/aisi_316_L/data/M1/train_86.csv
Time(s),Strain(%),Stress(MPa),Temp(C),Log_SR(s-1)
0.0,0.0,0.0,101.57068457063126,0.42472951897035927
6.6188592946058465e-06,1.76e-05,3.3959769250000003,101.57068457063126,0.42472951897035927
1.1733432385892181e-05,3.12e-05,6.0201409125,101.57068457063126,0.42472951897035927
2.376772201244826e-05,6.319999999999999e-05,12.194644412499999,101.57068457063126,0.42472951897035927
3.339515371369313e-05,8.879999999999999e-05,17.134247212499996,101.57068457063126,0.42472951897035927
3.7306297842323855e-05,9.92e-05,19.14096085,101.57068457063126,0.42472951897035927
5.0844873672199456e-05,0.0001352,26.0872772875,101.57068457063126,0.42472951897035927
5.86671619294609e-05,0.000156,30.1007045625,101.57068457063126,0.42472951897035927
6.348087778008333e-05,0.00016879999999999998,32.57050596249999,101.57068457063126,0.42472951897035927
6.739202190871407e-05,0.0001792,34.5772196,101.57068457063126,0.42472951897035927
7.009973707468919e-05,0.0001864,35.9664828875,101.57068457063126,0.42472951897035927
7.280745224066429e-05,0.0001936,37.355746175,101.57068457063126,0.42472951897035927
7.491345292531161e-05,0.0001992,38.4362842875,101.57068457063126,0.42472951897035927
7.972716877593406e-05,0.000212,40.9060856875,101.57068457063126,0.42472951897035927
8.424002738589258e-05,0.000224,43.2215245,101.57068457063126,0.42472951897035927
8.51425991078843e-05,0.0002264,43.6846122625,101.57068457063126,0.42472951897035927
9.236317288381794e-05,0.0002456,47.3893143625,101.57068457063126,0.42472951897035927
0.00010199060458506279,0.0002712,52.3289171625,101.57068457063126,0.42472951897035927
0.0001025923190663906,0.00027279999999999996,52.63764233749999,101.57068457063126,0.42472951897035927
0.00010680432043568522,0.00028399999999999996,54.79871856249999,101.57068457063126,0.42472951897035927
0.00011372403697095498,0.0003024,58.349058074999995,101.57068457063126,0.42472951897035927
0.0001158300376556023,0.000308,59.4295961875,101.57068457063126,0.42472951897035927
0.00012636004107883887,0.000336,64.83228675,101.57068457063126,0.42472951897035927
0.000129067756244814,0.0003432,66.2215500375,101.57068457063126,0.42472951897035927
0.0001314746141701252,0.0003496,67.45645073749999,101.57068457063126,0.42472951897035927
0.00014290718931535347,0.00037999999999999997,73.3222290625,101.57068457063126,0.42472951897035927
0.000144411475518673,0.000384,74.094042,101.57068457063126,0.42472951897035927
0.00014832261964730373,0.0003944,76.1007556375,101.57068457063126,0.42472951897035927
0.0001582509085892125,0.0004208,81.19472102499999,101.57068457063126,0.42472951897035927
0.00016276376719917101,0.0004328,83.5101598375,101.57068457063126,0.42472951897035927
0.00016757748304979344,0.0004456,85.97996123749999,101.57068457063126,0.42472951897035927
0.0001744971995850632,0.000464,89.53030075,101.57068457063126,0.42472951897035927
0.0001763023430290466,0.00046879999999999996,90.45647627499999,101.57068457063126,0.42472951897035927
0.00018292120232365247,0.0004864,93.8524532,101.57068457063126,0.42472951897035927
0.0001883366326556027,0.0005008,96.630979775,101.57068457063126,0.42472951897035927
0.00019525634919087241,0.0005191999999999999,100.18131928749999,101.57068457063126,0.42472951897035927
0.00019645977815352806,0.0005224,100.7987696375,101.57068457063126,0.42472951897035927
0.0002015743512448144,0.000536,103.422933625,101.57068457063126,0.42472951897035927
0.00020337949468879782,0.0005408,104.34910915,101.57068457063126,0.42472951897035927
0.00020969749674273975,0.0005576,107.5907234875,101.57068457063126,0.42472951897035927
0.000218121499481329,0.00058,111.9128759375,101.57068457063126,0.42472951897035927
0.00022744807394190996,0.0006048,116.69811614999999,101.57068457063126,0.42472951897035927
0.0002310583608298768,0.0006144,118.5504672,101.57068457063126,0.42472951897035927
0.00023587207668049922,0.0006272,121.0202686,101.57068457063126,0.42472951897035927
0.00023948236356846603,0.0006368,122.87261964999999,101.57068457063126,0.42472951897035927
0.00024369436493776065,0.0006479999999999999,125.03369587499998,101.57068457063126,0.42472951897035927
0.0002467029373443997,0.000656,126.57732175,101.57068457063126,0.42472951897035927
0.00024850808078838313,0.0006608,127.503497275,101.57068457063126,0.42472951897035927
0.00025181751043568606,0.0006696,129.2014857375,101.57068457063126,0.42472951897035927
0.00025633036904564456,0.0006816,131.51692455,101.57068457063126,0.42472951897035927
0.0002608432276556031,0.0006935999999999999,133.8323633625,101.57068457063126,0.42472951897035927
0.0002689663731535284,0.0007151999999999999,138.000153225,101.57068457063126,0.42472951897035927
0.0002752843752074704,0.000732,141.2417675625,101.57068457063126,0.42472951897035927
0.0002806998055394206,0.0007463999999999999,144.02029413749997,101.57068457063126,0.42472951897035927
0.00028431009242738743,0.0007559999999999999,145.87264518749998,101.57068457063126,0.42472951897035927
0.00028912380827800986,0.0007687999999999999,148.34244658749998,101.57068457063126,0.42472951897035927
0.00029905209721991865,0.0007951999999999999,153.436411975,101.57068457063126,0.42472951897035927
0.00030326409858921327,0.0008064,155.5974882,101.57068457063126,0.42472951897035927
0.0003113872440871386,0.000828,159.7652780625,101.57068457063126,0.42472951897035927
0.0003180061033817445,0.0008456,163.1612549875,101.57068457063126,0.42472951897035927
0.00032612924887966984,0.0008671999999999999,167.32904484999997,101.57068457063126,0.42472951897035927
0.0003285361068049811,0.0008736,168.56394555,101.57068457063126,0.42472951897035927
0.0003327481081742757,0.0008847999999999999,170.725021775,101.57068457063126,0.42472951897035927
0.00034327811159751224,0.0009128,176.1277123375,101.57068457063126,0.42472951897035927
0.0003477909702074708,0.0009247999999999999,178.44315114999998,101.57068457063126,0.42472951897035927
0.0003498969708921181,0.0009304,179.5236892625,101.57068457063126,0.42472951897035927
0.00035350725778008496,0.00094,181.37604031249998,101.57068457063126,0.42472951897035927
0.00035531240122406834,0.0009448,182.3022158375,101.57068457063126,0.42472951897035927
0.00035681668742738783,0.0009488,183.074028775,101.57068457063126,0.42472951897035927
0.00036704583360996055,0.000976,188.32235674999998,101.57068457063126,0.42472951897035927
0.0003781775515145249,0.0010056,194.0337724875,101.57068457063126,0.42472951897035927
0.0003847964108091307,0.0010232,197.4297494125,101.57068457063126,0.42472951897035927
0.0003971315576763507,0.0010559999999999999,203.75861549999996,101.57068457063126,0.42472951897035927
0.00039863584387967024,0.00106,204.5304284375,101.57068457063126,0.42472951897035927
0.0004010427018049814,0.0010664,205.76532913749998,101.57068457063126,0.42472951897035927
0.0004052547031742761,0.0010776,207.9264053625,101.57068457063126,0.42472951897035927
0.0004076615610995873,0.001084,209.1613060625,101.57068457063126,0.42472951897035927
0.0004136787059128653,0.0010999999999999998,212.24855781249997,101.57068457063126,0.42472951897035927
0.0004224035658921185,0.0011232,216.72507285,101.57068457063126,0.42472951897035927
0.00043383614103734673,0.0011535999999999999,222.59085117499998,101.57068457063126,0.42472951897035927
0.0004383489996473053,0.0011656,224.90628998749997,101.57068457063126,0.42472951897035927
0.0004434635727385917,0.0011792,227.530453975,101.57068457063126,0.42472951897035927
0.0004440652872199194,0.0011807999999999999,227.83917914999998,101.57068457063126,0.42472951897035927
0.0004539935761618282,0.0012071999999999999,232.93314453749997,101.57068457063126,0.42472951897035927
0.00045670129132780336,0.0012144,234.322407825,101.57068457063126,0.42472951897035927
0.0004750535830083013,0.0012632,243.7385256625,101.57068457063126,0.42472951897035927
0.00048588444367220185,0.001292,249.2955788125,101.57068457063126,0.42472951897035927
0.0005036350208713721,0.0013392,252.512036412932,101.57068457063126,0.42472951897035927
0.0005114573091286335,0.0013599999999999999,252.66240261215677,101.57068457063126,0.42472951897035927
0.0005156693104979281,0.0013712,252.7429974171305,101.57068457063126,0.42472951897035927
0.0005231907415145258,0.0013912,252.88628103035532,101.57068457063126,0.42472951897035927
0.0005421447476763515,0.0014416,253.24383778332842,101.57068457063126,0.42472951897035927
0.0005433481766390072,0.0014448,253.26637380325664,101.57068457063126,0.42472951897035927
0.0005487636069709574,0.0014592,253.36754596062752,101.57068457063126,0.42472951897035927
0.0005517721793775964,0.0014671999999999999,253.42358444419446,101.57068457063126,0.42472951897035927
0.0005592936103941939,0.0014872,253.56316181123458,101.57068457063126,0.42472951897035927
0.0005613996110788413,0.0014927999999999999,253.60211204381088,101.57068457063126,0.42472951897035927
0.0005698236138174305,0.0015152,253.7573464813961,101.57068457063126,0.42472951897035927
0.0005782476165560197,0.0015375999999999999,253.91168843956171,101.57068457063126,0.42472951897035927
0.0005833621896473061,0.0015512,254.00496829925376,101.57068457063126,0.42472951897035927
0.0005872733337759368,0.0015616,254.07608490738616,101.57068457063126,0.42472951897035927
0.0005993076234024929,0.0015936,254.29375549958962,101.57068457063126,0.42472951897035927
0.0006011127668464763,0.0015983999999999998,254.32625846865534,101.57068457063126,0.42472951897035927
0.0006116427702697128,0.0016263999999999999,254.51510592348194,101.57068457063126,0.42472951897035927
0.0006191642012863105,0.0016464,254.649221463222,101.57068457063126,0.42472951897035927
0.000626685632302908,0.0016664,254.7827031000762,101.57068457063126,0.42472951897035927
0.0006369147784854806,0.0016936,254.96323975442422,101.57068457063126,0.42472951897035927
0.0006429319232987588,0.0017096,255.06890957459422,101.57068457063126,0.42472951897035927
0.0006459404957053977,0.0017176,255.12159979900738,101.57068457063126,0.42472951897035927
0.0006570722136099622,0.0017472,255.31572696792412,101.57068457063126,0.42472951897035927
0.0006594790715352733,0.0017536,255.35753128091443,101.57068457063126,0.42472951897035927
0.0006766279342531158,0.0017992,255.65368346729937,101.57068457063126,0.42472951897035927
0.0006805390783817465,0.0018096,255.72081528403865,101.57068457063126,0.42472951897035927
0.0006853527942323689,0.0018223999999999998,255.80323285526796,101.57068457063126,0.42472951897035927
0.0006901665100829913,0.0018352,255.8854249712956,101.57068457063126,0.42472951897035927
0.0006937767969709582,0.0018448,255.94692241780837,101.57068457063126,0.42472951897035927
0.0006958827976556055,0.0018503999999999999,255.98273829148215,101.57068457063126,0.42472951897035927
0.0007052093721161864,0.0018751999999999998,256.1408460291511,101.57068457063126,0.42472951897035927
0.0007109256596888006,0.0018904,256.23734776550737,101.57068457063126,0.42472951897035927
0.0007133325176141118,0.0018968,256.2778894887736,101.57068457063126,0.42472951897035927
0.0007181462334647342,0.0019096,256.3588132426221,101.57068457063126,0.42472951897035927
0.0007334899527385932,0.0019504,256.61535716527294,101.57068457063126,0.42472951897035927
0.0007392062403112074,0.0019656,256.71039614499546,101.57068457063126,0.42472951897035927
0.000743418241680502,0.0019768,256.78024156036133,101.57068457063126,0.42472951897035927
0.0007479311002904605,0.0019887999999999998,256.8549048919187,101.57068457063126,0.42472951897035927
0.0007581602464730332,0.002016,257.0234943529218,101.57068457063126,0.42472951897035927
0.0007620713906016639,0.0020264,257.08772029901274,101.57068457063126,0.42472951897035927
0.0007638765340456474,0.0020312,257.1173196728965,101.57068457063126,0.42472951897035927
0.0007668851064522862,0.0020391999999999997,257.1665914136777,101.57068457063126,0.42472951897035927
0.0007732031085062284,0.002056,257.26981736150725,101.57068457063126,0.42472951897035927
0.0007807245395228258,0.0020759999999999997,257.3922774659806,101.57068457063126,0.42472951897035927
0.0007870425415767678,0.0020927999999999997,257.4947887889004,101.57068457063126,0.42472951897035927
0.0007915554001867264,0.0021048,257.56781476815314,101.57068457063126,0.42472951897035927
0.0007978734022406683,0.0021216,257.6697789411838,101.57068457063126,0.42472951897035927
0.0008008819746473072,0.0021295999999999997,257.7182225913406,101.57068457063126,0.42472951897035927
0.0008056956904979298,0.0021424,257.79558506884257,101.57068457063126,0.42472951897035927
0.0008068991194605854,0.0021456,257.81489749649893,101.57068457063126,0.42472951897035927
0.0008087042629045687,0.0021504,257.8438450891526,101.57068457063126,0.42472951897035927
0.0008132171215145274,0.0021624,257.9161040394236,101.57068457063126,0.42472951897035927
0.0008384891297302951,0.0022296,258.3179007557997,101.57068457063126,0.42472951897035927
0.0008496208476348594,0.0022592,258.4933812505726,101.57068457063126,0.42472951897035927
0.0008565405641701292,0.0022776,258.60201189195584,101.57068457063126,0.42472951897035927
0.0008592482793361043,0.0022848,258.64442630066475,101.57068457063126,0.42472951897035927
0.0008640619951867267,0.0022976,258.71970120979364,101.57068457063126,0.42472951897035927
0.0008763971420539467,0.0023304,258.91185043637796,101.57068457063126,0.42472951897035927
0.000878803999979258,0.0023368,258.9492196776162,101.57068457063126,0.42472951897035927
0.0008896348606431583,0.0023656,259.1168897533361,101.57068457063126,0.42472951897035927
0.0008959528626971003,0.0023824,259.21432965312243,101.57068457063126,0.42472951897035927
0.000903173436473034,0.0024016,259.32536200438733,101.57068457063126,0.42472951897035927
0.0009070845806016648,0.002412,259.3853599604625,101.57068457063126,0.42472951897035927
0.0009149068688589262,0.0024327999999999997,259.50505405066804,101.57068457063126,0.42472951897035927
0.0009326574460580964,0.00248,259.7751969212399,101.57068457063126,0.42472951897035927
0.0009362677329460632,0.0024896,259.8298950227453,101.57068457063126,0.42472951897035927
0.0009413823060373495,0.0025031999999999997,259.9072433998697,101.57068457063126,0.42472951897035927
0.0009458951646473081,0.0025152,259.97535596653785,101.57068457063126,0.42472951897035927
0.0009555225963485529,0.0025407999999999997,260.1202406407184,101.57068457063126,0.42472951897035927
0.0009597345977178476,0.002552,260.18344854087877,101.57068457063126,0.42472951897035927
0.0009630440273651504,0.0025608,260.2330360264687,101.57068457063126,0.42472951897035927
0.0009681586004564367,0.0025743999999999997,260.309540713842,101.57068457063126,0.42472951897035927
0.0009705654583817481,0.0025808,260.3454883646883,101.57068457063126,0.42472951897035927
0.0009732731735477233,0.002588,260.38588794107415,101.57068457063126,0.42472951897035927
0.0009816971762863123,0.0026103999999999997,260.51129610194477,101.57068457063126,0.42472951897035927
0.0009856083204149433,0.0026208,260.5693785898345,101.57068457063126,0.42472951897035927
0.0009910237507468934,0.0026352,260.64965231740337,101.57068457063126,0.42472951897035927
0.0009982443245228271,0.0026544,260.7564183424202,101.57068457063126,0.42472951897035927
0.0009997486107261467,0.0026584,260.77862330747354,101.57068457063126,0.42472951897035927
0.001004562326576769,0.0026712,260.8495917915625,101.57068457063126,0.42472951897035927
0.001016596616203325,0.0027032,261.0264352124351,101.57068457063126,0.42472951897035927
0.0010178000451659807,0.0027064,261.04407453145666,101.57068457063126,0.42472951897035927
0.0010217111892946113,0.0027167999999999997,261.10134622481087,101.57068457063126,0.42472951897035927
0.0010304360492738645,0.00274,261.22879894020014,101.57068457063126,0.42472951897035927
0.001034948907883823,0.0027519999999999997,261.2945575706938,101.57068457063126,0.42472951897035927
0.0010367540513278066,0.0027568,261.320829699684,101.57068457063126,0.42472951897035927
0.0010388600520124538,0.0027624,261.3514579796766,101.57068457063126,0.42472951897035927
0.0010560089147302963,0.0028079999999999997,261.59996463021264,101.57068457063126,0.42472951897035927
0.0010581149154149435,0.0028136,261.6303741051705,101.57068457063126,0.42472951897035927
0.0010614243450622466,0.0028224,261.6781127752967,101.57068457063126,0.42472951897035927
0.0010662380609128689,0.0028352,261.74744734584897,101.57068457063126,0.42472951897035927
0.0010737594919294664,0.0028552,261.85553871619555,101.57068457063126,0.42472951897035927
0.001081581780186728,0.002876,261.9676409623327,101.57068457063126,0.42472951897035927
0.001083988638112039,0.0028824,262.0020702899805,101.57068457063126,0.42472951897035927
0.0010866963532780143,0.0028896,262.0407676666145,101.57068457063126,0.42472951897035927
0.0010987306429045703,0.0029216,262.21230305494055,101.57068457063126,0.42472951897035927
0.0011056503594398402,0.00294,262.3106040994915,101.57068457063126,0.42472951897035927
0.001108658931846479,0.0029479999999999997,262.35326881455757,101.57068457063126,0.42472951897035927
0.0011188880780290517,0.0029752,262.49799228533345,101.57068457063126,0.42472951897035927
0.0011267103662863133,0.002996,262.60831527257614,101.57068457063126,0.42472951897035927
0.001130922367655608,0.0030072,262.6675962144299,101.57068457063126,0.42472951897035927
0.0011327275110995913,0.003012,262.69297596637927,101.57068457063126,0.42472951897035927
0.0011381429414315414,0.0030264,262.7690207476903,101.57068457063126,0.42472951897035927
0.0011450626579668113,0.0030448,262.8659840382945,101.57068457063126,0.42472951897035927
0.0011465669441701309,0.0030488,262.8870327443517,101.57068457063126,0.42472951897035927
0.0011522832317427448,0.003064,262.9669197954941,101.57068457063126,0.42472951897035927
0.0011576986620746952,0.0030784,263.04245981340176,101.57068457063126,0.42472951897035927
0.0011631140924066453,0.0030927999999999997,263.117862146846,101.57068457063126,0.42472951897035927
0.0011652200930912927,0.0030984,263.1471482849906,101.57068457063126,0.42472951897035927
0.0011721398096265624,0.0031168,263.24322915065125,101.57068457063126,0.42472951897035927
0.001173944953070546,0.0031216,263.268257311552,101.57068457063126,0.42472951897035927
0.0011754492392738653,0.0031255999999999996,263.2891026490138,101.57068457063126,0.42472951897035927
0.0011838732420124546,0.0031479999999999998,263.4056448429395,101.57068457063126,0.42472951897035927
0.0011871826716597575,0.0031568,263.45134073591464,101.57068457063126,0.42472951897035927
0.0011925981019917078,0.0031712,263.52600881941186,101.57068457063126,0.42472951897035927
0.0011992169612863137,0.0031888,263.61709047703073,101.57068457063126,0.42472951897035927
0.001204030677136936,0.0032015999999999998,263.68320858584434,101.57068457063126,0.42472951897035927
0.0012079418212655668,0.003212,263.7368536718126,101.57068457063126,0.42472951897035927
0.0012121538226348614,0.0032232,263.79454960141055,101.57068457063126,0.42472951897035927
0.0012169675384854839,0.0032359999999999997,263.8603921527256,101.57068457063126,0.42472951897035927
0.0012299043998340315,0.0032703999999999997,264.03684264566715,101.57068457063126,0.42472951897035927
0.001235018972925318,0.003284,264.1064023076035,101.57068457063126,0.42472951897035927
0.0012425404039419154,0.0033039999999999996,264.20849218674005,101.57068457063126,0.42472951897035927
0.001250362692199177,0.0033247999999999997,264.3144103245704,101.57068457063126,0.42472951897035927
0.0012657064114730359,0.0033656,264.5214251946339,101.57068457063126,0.42472951897035927
0.001277439843858928,0.0033967999999999997,264.67907096680955,101.57068457063126,0.42472951897035927
0.0012846604176348618,0.0034159999999999998,264.77580310185346,101.57068457063126,0.42472951897035927
0.0012888724190041566,0.0034272,264.83213225986424,101.57068457063126,0.42472951897035927
0.0012918809914107955,0.0034352,264.8723234273321,101.57068457063126,0.42472951897035927
0.0012978981362240735,0.0034511999999999998,264.95259641948104,101.57068457063126,0.42472951897035927
0.0013027118520746958,0.0034639999999999996,265.0167103623848,101.57068457063126,0.42472951897035927
0.0013084281396473101,0.0034792,265.09272578866086,101.57068457063126,0.42472951897035927
0.0013171529996265632,0.0035023999999999997,265.2085001023797,101.57068457063126,0.42472951897035927
0.0013246744306431607,0.0035223999999999997,265.3080656989723,101.57068457063126,0.42472951897035927
0.0013315941471784304,0.0035407999999999998,265.39947149506514,101.57068457063126,0.42472951897035927
0.0013385138637137003,0.0035591999999999998,265.4906922292255,101.57068457063126,0.42472951897035927
0.0013397172926763558,0.0035624,265.50653791224266,101.57068457063126,0.42472951897035927
0.001361078156763493,0.0036192,265.78688157951274,101.57068457063126,0.42472951897035927
0.0013679978732987627,0.0036376,265.87732848192127,101.57068457063126,0.42472951897035927
0.001373413303630713,0.003652,265.9479886124932,101.57068457063126,0.42472951897035927
0.0013746167325933685,0.0036552,265.9636760977524,101.57068457063126,0.42472951897035927
0.0013809347346473105,0.003672,266.04594768624696,101.57068457063126,0.42472951897035927
0.0013968801684024973,0.0037143999999999996,266.2529354065613,101.57068457063126,0.42472951897035927
0.0014179401752489704,0.0037703999999999997,266.524908648516,101.57068457063126,0.42472951897035927
0.001423054748340257,0.003784,266.59072098012075,101.57068457063126,0.42472951897035927
0.00143177960831951,0.0038071999999999997,266.7027765671076,101.57068457063126,0.42472951897035927
0.0014353898952074767,0.0038168,266.74906646275423,101.57068457063126,0.42472951897035927
0.0014510344717219997,0.0038583999999999997,266.9491335883402,101.57068457063126,0.42472951897035927
0.0014570516165352777,0.0038743999999999996,267.0258582602471,101.57068457063126,0.42472951897035927
0.0014645730475518752,0.0038943999999999997,267.12159055104064,101.57068457063126,0.42472951897035927
0.0014669799054771865,0.0039008,267.15218436354746,101.57068457063126,0.42472951897035927
0.001471793621327809,0.0039136,267.21331332378423,101.57068457063126,0.42472951897035927
0.0014760056226971036,0.0039248,267.26673723018394,101.57068457063126,0.42472951897035927
0.0014796159095850706,0.0039344,267.3124818446085,101.57068457063126,0.42472951897035927
0.0014904467702489708,0.0039632,267.4494552143266,101.57068457063126,0.42472951897035927
0.0014973664867842407,0.0039816,267.5367627858225,101.57068457063126,0.42472951897035927
0.0015042862033195104,0.004,267.62391314475366,101.57068457063126,0.42472951897035927
0.0015476183123969277,0.004115223044608922,268.1661466010617,101.57068457063126,0.42472951897035927
0.0016270605123721931,0.004326465293058612,269.14510482175973,101.57068457063126,0.42472951897035927
0.0017353907850657364,0.0046145229045809165,270.4505119458157,101.57068457063126,0.42472951897035927
0.002240932057635606,0.00595879175835167,276.1646140065398,101.57068457063126,0.42472951897035927
0.0026309210393323625,0.006995799159831967,280.2333064576662,101.57068457063126,0.42472951897035927
0.0026742531484097794,0.007111022204440888,280.6703561532614,101.57068457063126,0.42472951897035927
0.002753695348385045,0.007322264452890578,281.4645069526019,101.57068457063126,0.42472951897035927
0.002869247639258158,0.007629525905181036,282.6038658213634,101.57068457063126,0.42472951897035927
0.0029270237846947145,0.007783156631326265,283.16682344373316,101.57068457063126,0.42472951897035927
0.0030425760755678276,0.008090418083616723,284.27990213029517,101.57068457063126,0.42472951897035927
0.0031147962573635233,0.00828245649129826,284.96720950313596,101.57068457063126,0.42472951897035927
0.0032809026754936233,0.008724144828965793,286.5248520509289,101.57068457063126,0.42472951897035927
0.0033097907482119012,0.008800960192038408,286.79257612716776,101.57068457063126,0.42472951897035927
0.0034253430390850143,0.009108221644328866,287.85448273134864,101.57068457063126,0.42472951897035927
0.0036058934935742537,0.009588317663532707,289.4861565244086,101.57068457063126,0.42472951897035927
0.003764777893524784,0.010010802160432087,290.8958444645603,101.57068457063126,0.42472951897035927
0.003815332020781771,0.010145229045809162,291.33949004114277,101.57068457063126,0.42472951897035927
0.003880330184397897,0.010318063612722545,291.90653721016133,101.57068457063126,0.42472951897035927
0.004046436602527997,0.010759751950390077,293.3390793760956,101.57068457063126,0.42472951897035927
0.004111434766144124,0.010932586517303462,293.8933729506544,101.57068457063126,0.42472951897035927
0.004176432929760249,0.011105421084216843,294.44425934157323,101.57068457063126,0.42472951897035927
0.0043714274206086276,0.011623924784956993,296.077197022577,101.57068457063126,0.42472951897035927
0.004443647602404323,0.011815963192638527,296.67474709775604,101.57068457063126,0.42472951897035927
0.004732528329587106,0.012584116823364673,299.02801101278817,101.57068457063126,0.42472951897035927
0.004884190711358066,0.012987397479495899,300.2410042217114,101.57068457063126,0.42472951897035927
0.004970854929512901,0.013217843568713743,300.92754640613754,101.57068457063126,0.42472951897035927
0.005043075111308597,0.013409881976395279,301.4961061172959,101.57068457063126,0.42472951897035927
0.005108073274924723,0.013582716543308662,302.0051005311327,101.57068457063126,0.42472951897035927
0.005274179693054823,0.014024404880976196,303.29451925050074,101.57068457063126,0.42472951897035927
0.005433064093005353,0.014446889377875576,304.51313514594653,101.57068457063126,0.42472951897035927
0.005801387020163401,0.015426285257051411,307.28586117980035,101.57068457063126,0.42472951897035927
0.005830275092881679,0.015503100620124026,307.5003821520062,101.57068457063126,0.42472951897035927
0.005960271420113931,0.01584876975395079,308.4606421922367,101.57068457063126,0.42472951897035927
0.0060397136200891965,0.01606001200240048,309.04344783317435,101.57068457063126,0.42472951897035927
0.0061985980200397256,0.016482496499299858,310.20016644402347,101.57068457063126,0.42472951897035927
0.006444146638145093,0.017135427085417085,311.96533183605015,101.57068457063126,0.42472951897035927
0.006487478747222508,0.017250650130026003,312.27408882191213,101.57068457063126,0.42472951897035927
0.006682473238070887,0.017769153830766153,313.653660749355,101.57068457063126,0.42472951897035927
0.006783581492584861,0.018038007601520304,314.36280782779454,101.57068457063126,0.42472951897035927
0.007021908092510658,0.018671734346869376,316.0182546880662,101.57068457063126,0.42472951897035927
0.0074191190923869835,0.019727945589117824,318.72943840338917,101.57068457063126,0.42472951897035927
0.007700777801390196,0.020476895379075814,320.6177079893539,101.57068457063126,0.42472951897035927
0.00782355211044288,0.020803360672134428,321.4323488233545,101.57068457063126,0.42472951897035927
0.0079607704558547,0.021168233646729345,322.33695232276256,101.57068457063126,0.42472951897035927
0.00813409889216437,0.021629125825165033,323.4709639342489,101.57068457063126,0.42472951897035927
0.008213541092139636,0.021840368073614724,323.98756577941566,101.57068457063126,0.42472951897035927
0.008285761273935332,0.02203240648129626,324.4555152837149,101.57068457063126,0.42472951897035927
0.008350759437551456,0.02220524104820964,324.87531152716684,101.57068457063126,0.42472951897035927
0.008401313564808444,0.02233966793358672,325.200939328404,101.57068457063126,0.42472951897035927
0.008567419982938545,0.02278135627125425,326.2655189165228,101.57068457063126,0.42472951897035927
0.008870744746480466,0.023587917583516704,328.18899007080614,101.57068457063126,0.42472951897035927
0.009354619964511627,0.024874574914982996,331.20510964940524,101.57068457063126,0.42472951897035927
0.009556836473539573,0.025412282456491297,332.447475752544,101.57068457063126,0.42472951897035927
0.009607390600796562,0.025546709341868375,332.7564601284405,101.57068457063126,0.42472951897035927
0.009744608946208383,0.025911582316463292,333.59195215715295,101.57068457063126,0.42472951897035927
0.009860161237081496,0.02621884376875375,334.2919715598309,101.57068457063126,0.42472951897035927
0.00993960343705676,0.026430086017203442,334.77138005138806,101.57068457063126,0.42472951897035927
0.010062377746109444,0.026756551310262052,335.50935520601655,101.57068457063126,0.42472951897035927
0.010214040127880405,0.02715983196639328,336.4161410376356,101.57068457063126,0.42472951897035927
0.010235706182419113,0.02721744348869774,336.5452519127141,101.57068457063126,0.42472951897035927
0.010409034618728783,0.027678335667133427,337.5743295594611,101.57068457063126,0.42472951897035927
0.010748469473168553,0.02858091618323665,339.5704495580867,101.57068457063126,0.42472951897035927
0.0109506859821965,0.029118623724744948,340.74794314786567,101.57068457063126,0.42472951897035927
0.011225122673020144,0.029848369673934786,342.3324949123808,101.57068457063126,0.42472951897035927
0.011340674963893255,0.030155631126225244,342.99514622000515,101.57068457063126,0.42472951897035927
0.011384007072970673,0.030270854170834166,343.24296091836453,101.57068457063126,0.42472951897035927
0.011571779545639482,0.03077015403080616,344.31260142263807,101.57068457063126,0.42472951897035927
0.011737885963769583,0.031211842368473696,345.25319192467725,101.57068457063126,0.42472951897035927
0.011788440091026569,0.03134626925385077,345.5384263462338,101.57068457063126,0.42472951897035927
0.011990656600054517,0.03188397679535907,346.67462559549614,101.57068457063126,0.42472951897035927
0.012033988709131933,0.03199919983996799,346.9171218139932,101.57068457063126,0.42472951897035927
0.01210620889092763,0.03219123824764953,347.3205267869604,101.57068457063126,0.42472951897035927
0.012272315309057731,0.032632926585317065,348.2448132317187,101.57068457063126,0.42472951897035927
0.012330091454494287,0.032786557311462294,348.565158827861,101.57068457063126,0.42472951897035927
0.012373423563571706,0.03290178035607122,348.80503398604407,101.57068457063126,0.42472951897035927
0.01279230061798674,0.03401560312062413,351.10718073221625,101.57068457063126,0.42472951897035927
0.012857298781602865,0.03418843768753751,351.46175821225165,101.57068457063126,0.42472951897035927
0.013008961163373824,0.03459171834366873,352.2863981071972,101.57068457063126,0.42472951897035927
0.013348396017813596,0.035494298859771956,354.118554137384,101.57068457063126,0.42472951897035927
0.013492836381404983,0.03587837567513502,354.892673610037,101.57068457063126,0.42472951897035927
0.013702274908612507,0.03643528705741149,356.00943068875637,101.57068457063126,0.42472951897035927
0.013810605181306048,0.03672334466893379,356.58445025449686,101.57068457063126,0.42472951897035927
0.01391893545399959,0.03701140228045609,357.1577134116498,101.57068457063126,0.42472951897035927
0.01461947121741784,0.038874174834966996,360.8236724480559,101.57068457063126,0.42472951897035927
0.014735023508290953,0.039181436287257454,361.42172219311857,101.57068457063126,0.42472951897035927
0.014792799653727508,0.03933506701340268,361.7200609635962,101.57068457063126,0.42472951897035927
0.01492279598095976,0.039680736147229445,362.38966666222535,101.57068457063126,0.42472951897035927
0.01509612441726943,0.04014162832566513,363.2789461796964,101.57068457063126,0.42472951897035927
0.01542833725352963,0.0410250050010002,364.9723462403484,101.57068457063126,0.42472951897035927
0.015493335417145754,0.04119783956791358,365.3019938551711,101.57068457063126,0.42472951897035927
0.015695551926173702,0.041735547109421886,366.3241318768038,101.57068457063126,0.42472951897035927
0.01596998861699735,0.04246529305861173,367.70314204091096,101.57068457063126,0.42472951897035927
0.016020542744254334,0.0425997199439888,367.9561589742311,101.57068457063126,0.42472951897035927
0.016071096871511318,0.04273414682936587,368.20886471640165,101.57068457063126,0.42472951897035927
0.01620831521692314,0.04309901980396079,368.8932223820274,101.57068457063126,0.42472951897035927
0.016446641816848937,0.043732746549309864,370.0764973877482,101.57068457063126,0.42472951897035927
0.016692190434954304,0.044385677135427085,371.28865579976855,101.57068457063126,0.42472951897035927
0.01674996658039086,0.044539307861572314,371.5728565047047,101.57068457063126,0.42472951897035927
0.016814964744006986,0.0447121424284857,371.89212570584374,101.57068457063126,0.42472951897035927
0.01690885098034139,0.0449617923584717,372.35244391720573,101.57068457063126,0.42472951897035927
0.01696662712577795,0.045115423084616926,372.6352212531454,101.57068457063126,0.42472951897035927
0.017024403271214503,0.045269053810762155,372.91762329224804,101.57068457063126,0.42472951897035927
0.017161621616626325,0.045633926785357076,373.5868343276511,101.57068457063126,0.42472951897035927
0.017573276652861788,0.046728545709141825,375.58205727715773,101.57068457063126,0.42472951897035927
0.017688828943734903,0.04703580716143228,376.1388326357747,101.57068457063126,0.42472951897035927
0.018367698652614443,0.04884096819363873,379.3816901031951,101.57068457063126,0.42472951897035927
0.018598803234360667,0.049455491098219645,380.4749315036448,101.57068457063126,0.42472951897035927
0.018736021579772492,0.049820364072814566,381.1215370739232,101.57068457063126,0.42472951897035927
0.018873239925184315,0.05018523704740949,381.76629837888834,101.57068457063126,0.42472951897035927
0.019003236252416563,0.05053090618123625,382.3754405296929,101.57068457063126,0.42472951897035927
0.01906101239785312,0.05068453690738148,382.6456485041382,101.57068457063126,0.42472951897035927
0.019162120652367096,0.05095339067813563,383.11774510853866,101.57068457063126,0.42472951897035927
0.019277672943240207,0.05126065213042609,383.6560961349788,101.57068457063126,0.42472951897035927
0.019364337161395042,0.05149109821964393,384.0590338999635,101.57068457063126,0.42472951897035927
0.01960266376132084,0.052124824964993,385.1635025709674,101.57068457063126,0.42472951897035927
0.019898766506683187,0.05291218243648729,386.5284529956636,101.57068457063126,0.42472951897035927
0.019920432561221897,0.052969793958791755,386.6280153138274,101.57068457063126,0.42472951897035927
0.020093760997531566,0.05343068613722744,387.422999166845,101.57068457063126,0.42472951897035927
0.02016598117932726,0.053622724544908976,387.7534525914435,101.57068457063126,0.42472951897035927
0.020346531633816504,0.05410282056411282,388.57757329348897,101.57068457063126,0.42472951897035927
0.020779852724590677,0.05525505101020205,390.54391239947273,101.57068457063126,0.42472951897035927
0.020859294924565938,0.055466293258651725,390.90266654687343,101.57068457063126,0.42472951897035927
0.020945959142720776,0.055696739347869575,391.2934275294985,101.57068457063126,0.42472951897035927
0.020989291251798197,0.0558119623924785,391.48857153050665,101.57068457063126,0.42472951897035927
0.021025401342696044,0.05590798159631927,391.65107153811135,101.57068457063126,0.42472951897035927
0.021090399506312165,0.05608081616323264,391.9432975322259,101.57068457063126,0.42472951897035927
0.021285393997160545,0.05659931986397279,392.8178753390459,101.57068457063126,0.42472951897035927
0.021350392160776673,0.05677215443088618,393.1087061737854,101.57068457063126,0.42472951897035927
0.02150205454254763,0.057175435087017404,393.785971917813,101.57068457063126,0.42472951897035927
0.02171871508793472,0.057751550310062016,394.7502715116244,101.57068457063126,0.42472951897035927
0.021798157287909986,0.05796279255851171,395.1029070998345,101.57068457063126,0.42472951897035927
0.02187037746970568,0.05815483096619324,395.4230502117096,101.57068457063126,0.42472951897035927
0.022022039851476643,0.058558111622324466,396.0940118259449,101.57068457063126,0.42472951897035927
0.022094260033272337,0.058750150030006,396.41288374862427,101.57068457063126,0.42472951897035927
0.02223870039686373,0.05913422684536908,397.0494107085025,101.57068457063126,0.42472951897035927
0.022361474705916408,0.05946069213842768,397.58919193450004,101.57068457063126,0.42472951897035927
0.022491471033148667,0.05980636127225446,398.15946672368045,101.57068457063126,0.42472951897035927
0.022556469196764788,0.05997919583916783,398.4441219630225,101.57068457063126,0.42472951897035927
0.022635911396740056,0.06019043808761752,398.7915998624567,101.57068457063126,0.42472951897035927
0.02272257561489489,0.060420884176835374,399.17012468764153,101.57068457063126,0.42472951897035927
0.022809239833049725,0.06065133026605321,399.54808688716156,101.57068457063126,0.42472951897035927
0.022989790287538964,0.06113142628525706,400.33371404050735,101.57068457063126,0.42472951897035927
0.023047566432975522,0.061285057011402286,400.5846060425429,101.57068457063126,0.42472951897035927
0.02308367652387337,0.06138107621524305,400.74128899043774,101.57068457063126,0.42472951897035927
0.02317756276020777,0.06163072614522905,401.14821794995305,101.57068457063126,0.42472951897035927
0.023509775596467972,0.06251410282056412,402.58298693459653,101.57068457063126,0.42472951897035927
0.02371199210549592,0.06305181036207241,403.4524539152832,101.57068457063126,0.42472951897035927
0.023863654487266878,0.06345509101820364,404.10265767625083,101.57068457063126,0.42472951897035927
0.023878098523626018,0.06349349869973994,404.1644976725265,101.57068457063126,0.42472951897035927
0.023986428796319563,0.06378155631126226,404.62783352262676,101.57068457063126,0.42472951897035927
0.024051426959935687,0.06395439087817563,404.90544331957176,101.57068457063126,0.42472951897035927
0.024181423287167943,0.0643000600120024,405.45978669926046,101.57068457063126,0.42472951897035927
0.024347529705298042,0.06474174834966993,406.16642594337355,101.57068457063126,0.42472951897035927
0.024434193923452877,0.06497219443888778,406.53436077310295,101.57068457063126,0.42472951897035927
0.02450641410524857,0.06516423284656932,406.8405845095684,101.57068457063126,0.42472951897035927
0.024643632450660393,0.06552910582116424,407.42144172594084,101.57068457063126,0.42472951897035927
0.024686964559737807,0.06564432886577315,407.60460808485516,101.57068457063126,0.42472951897035927
0.02478085079607222,0.06589397879575916,408.00103893615614,101.57068457063126,0.42472951897035927
0.02488918106876576,0.06618203640728146,408.4577320163051,101.57068457063126,0.42472951897035927
0.024961401250561455,0.06637407481496299,408.761763463627,101.57068457063126,0.42472951897035927
0.02522139390502596,0.06706541308261653,409.85344755100147,101.57068457063126,0.42472951897035927
0.025257503995923806,0.0671614322864573,410.0047224925603,101.57068457063126,0.42472951897035927
0.025452498486772186,0.06767993598719745,410.82015429357233,101.57068457063126,0.42472951897035927
0.025654714995800132,0.06821764352870574,411.66321801882316,101.57068457063126,0.42472951897035927
0.02580637737757109,0.06862092418483696,412.29381609543265,101.57068457063126,0.42472951897035927
0.025994149850239904,0.06912022404480897,413.07255765021273,101.57068457063126,0.42472951897035927
0.02618192232290871,0.06961952390478096,413.84910838264136,101.57068457063126,0.42472951897035927
0.026362472777397953,0.07009961992398481,414.59374603738564,101.57068457063126,0.42472951897035927
0.02642024892283451,0.07025325065013004,414.83160967497054,101.57068457063126,0.42472951897035927
0.02655024525006676,0.0705989197839568,415.36606239092265,101.57068457063126,0.42472951897035927
0.026600799377323747,0.07073334666933387,415.57362938129074,101.57068457063126,0.42472951897035927
0.02676690579545385,0.07117503500700141,416.254554580599,101.57068457063126,0.42472951897035927
0.026839125977249544,0.07136707341468294,416.5500947790339,101.57068457063126,0.42472951897035927
0.027250781013485006,0.07246169233846769,418.2287890700889,101.57068457063126,0.42472951897035927
0.027323001195280704,0.07265373074614924,418.5222742019004,101.57068457063126,0.42472951897035927
0.027669658067900043,0.07357551510302061,419.9268131018147,101.57068457063126,0.42472951897035927
0.027994648885980675,0.07443968793758753,421.2373483716617,101.57068457063126,0.42472951897035927
0.028030758976878522,0.07453570714142829,421.38259620966977,101.57068457063126,0.42472951897035927
0.028110201176853786,0.07474694938987798,421.70188483295027,101.57068457063126,0.42472951897035927
0.02818242135864948,0.07493898779755952,421.99184197013415,101.57068457063126,0.42472951897035927
0.02820408741318819,0.07499659931986398,422.0787725840854,101.57068457063126,0.42472951897035927
0.02834852777677958,0.07538067613522705,422.65764588316034,101.57068457063126,0.42472951897035927
0.028406303922216134,0.07553430686137227,422.8888729853697,101.57068457063126,0.42472951897035927
0.028536300249448393,0.07587997599519905,423.40846440350987,101.57068457063126,0.42472951897035927
0.028608520431244087,0.07607201440288058,423.6967274009662,101.57068457063126,0.42472951897035927
0.028796292903912894,0.07657131426285257,424.44488612387323,101.57068457063126,0.42472951897035927
0.02883962501299031,0.0766865373074615,424.61726765567295,101.57068457063126,0.42472951897035927
0.028969621340222563,0.07703220644128826,425.13380719407263,101.57068457063126,0.42472951897035927
0.029020175467479547,0.07716663332666533,425.3344394550901,101.57068457063126,0.42472951897035927
0.02928739014012362,0.07787717543508701,426.3926684333714,101.57068457063126,0.42472951897035927
0.029410164449176306,0.07820364072814563,426.87761859265936,101.57068457063126,0.42472951897035927
0.029886817649027897,0.07947109421884377,428.75293078513954,101.57068457063126,0.42472951897035927
0.0299807038853623,0.07972074414882976,429.1209315035546,101.57068457063126,0.42472951897035927
0.03003125801261929,0.07985517103420685,429.31889956606244,101.57068457063126,0.42472951897035927
0.03024791855800638,0.08043128625725146,430.16586624898883,101.57068457063126,0.42472951897035927
0.030262362594365516,0.08046969393878776,430.2222464263603,101.57068457063126,0.42472951897035927
0.030435691030675185,0.08093058611722345,430.8979920159814,101.57068457063126,0.42472951897035927
0.03048624515793217,0.08106501300260052,431.09480155385944,101.57068457063126,0.42472951897035927
0.03050791121247088,0.08112262452490498,431.1791095305878,101.57068457063126,0.42472951897035927
0.030637907539703132,0.08146829365873175,431.68446789790056,101.57068457063126,0.42472951897035927
0.03071012772149883,0.0816603320664133,431.96486118637625,101.57068457063126,0.42472951897035927
0.030746237812396677,0.08175635127025406,432.104961385961,101.57068457063126,0.42472951897035927
0.03084734606691065,0.0820252050410082,432.49690096590984,101.57068457063126,0.42472951897035927
0.031027896521399888,0.08250530106021205,433.1955491950808,101.57068457063126,0.42472951897035927
0.031042340557759028,0.08254370874174835,433.2513724668573,101.57068457063126,0.42472951897035927
0.03118678092135042,0.08292778555711143,433.8090491572533,101.57068457063126,0.42472951897035927
0.031230113030427834,0.08304300860172034,433.9761556199322,101.57068457063126,0.42472951897035927
0.03149732770307191,0.08375355071014204,435.00465444725654,101.57068457063126,0.42472951897035927
0.03153343779396976,0.0838495699139828,435.14337931739556,101.57068457063126,0.42472951897035927
0.031757320357536416,0.08444488897779556,436.00209478387774,101.57068457063126,0.42472951897035927
0.03179343044843426,0.08454090818163633,436.1403758649247,101.57068457063126,0.42472951897035927
0.03190176072112781,0.08482896579315864,436.55485206472736,101.57068457063126,0.42472951897035927
0.032082311175617044,0.08530906181236247,437.2444280148569,101.57068457063126,0.42472951897035927
0.032103977230155754,0.08536667333466694,437.327075300184,101.57068457063126,0.42472951897035927
0.03221952952102887,0.0856739347869574,437.7674939871025,101.57068457063126,0.42472951897035927
0.03252285428457079,0.08648049609921984,438.9206720727187,101.57068457063126,0.42472951897035927
0.03260951850272562,0.0867109421884377,439.24938012354613,101.57068457063126,0.42472951897035927
0.03277562492085572,0.08715263052610522,439.8784531507586,101.57068457063126,0.42472951897035927
0.03294895335716539,0.08761352270454091,440.53355297962463,101.57068457063126,0.42472951897035927
0.03300672950260195,0.08776715343068614,440.75162074209106,101.57068457063126,0.42472951897035927
0.03312950381165463,0.08809361872374476,441.21452106637275,101.57068457063126,0.42472951897035927
0.03329561022978473,0.08853530706141229,441.83973449516145,101.57068457063126,0.42472951897035927
0.033591712975147084,0.08932266453290659,442.95123676512833,101.57068457063126,0.42472951897035927
0.03366393315694278,0.08951470294058812,443.2217544422286,101.57068457063126,0.42472951897035927
0.03372170930237934,0.08966833366673335,443.43800565751525,101.57068457063126,0.42472951897035927
0.03386614966597073,0.09005241048209642,443.9780024779234,101.57068457063126,0.42472951897035927
0.03395281388412556,0.09028285657131427,444.301569445518,101.57068457063126,0.42472951897035927
0.03407558819317825,0.09060932186437289,444.7594051523092,101.57068457063126,0.42472951897035927
0.03424169461130835,0.09105101020204041,445.3778072533972,101.57068457063126,0.42472951897035927
0.03430669277492447,0.0912238447689538,445.6194720753464,101.57068457063126,0.42472951897035927
0.034371690938540596,0.09139667933586718,445.86095839650375,101.57068457063126,0.42472951897035927
0.03448724322941371,0.09170394078815763,446.2898281262493,101.57068457063126,0.42472951897035927
0.03462446157482553,0.09206881376275255,446.7983837319788,101.57068457063126,0.42472951897035927
0.034754457902057785,0.09241448289657932,447.2794486889663,101.57068457063126,0.42472951897035927
0.034805012029314776,0.0925489097819564,447.46633992416935,101.57068457063126,0.42472951897035927
0.034978340465624445,0.09300980196039209,448.106307670725,101.57068457063126,0.42472951897035927
0.03516611293829325,0.09350910182036408,448.7982119950579,101.57068457063126,0.42472951897035927
0.03522388908372981,0.09366273254650931,449.0108155630194,101.57068457063126,0.42472951897035927
0.03527444321098679,0.09379715943188638,449.1967321455879,101.57068457063126,0.42472951897035927
0.03533221935642335,0.09395079015803161,449.40908104437545,101.57068457063126,0.42472951897035927
0.03546943770183517,0.09431566313262653,449.91286766588433,101.57068457063126,0.42472951897035927
0.03554887990181044,0.09452690538107622,450.2041861910845,101.57068457063126,0.42472951897035927
0.03557776797452871,0.09460372074414883,450.3100572364303,101.57068457063126,0.42472951897035927
0.035678876229042686,0.09487257451490298,450.6803421675488,101.57068457063126,0.42472951897035927
0.035693320265401826,0.09491098219643929,450.73320658848974,101.57068457063126,0.42472951897035927
0.03595331291986633,0.09560232046409282,451.68334412784407,101.57068457063126,0.42472951897035927
0.03598942301076418,0.09569833966793359,451.81509543125975,101.57068457063126,0.42472951897035927
0.036126641356176,0.09606321264252851,452.31528090241267,101.57068457063126,0.42472951897035927
0.03619163951979213,0.0962360472094419,452.55195220504885,101.57068457063126,0.42472951897035927
0.0363649679561018,0.09669693938787759,453.1822666566343,101.57068457063126,0.42472951897035927
0.03646607621061577,0.09696579315863173,453.54940900260266,101.57068457063126,0.42472951897035927
0.03655996244695017,0.09721544308861772,453.8899715722408,101.57068457063126,0.42472951897035927
0.03683439913777382,0.09794518903780756,454.8835119230959,101.57068457063126,0.42472951897035927
0.036986061519544776,0.09834846969393879,455.4313350267122,101.57068457063126,0.42472951897035927
0.037159389955854445,0.09880936187237448,456.0563469641394,101.57068457063126,0.42472951897035927
0.037361606464882395,0.09934706941388279,456.78409235252485,101.57068457063126,0.42472951897035927
0.03760715508298776,0.1,457.6657212632178,101.57068457063126,0.42472951897035927