File: datasets/aisi_316_L/data/M1/train_54.csv
Time(s),Strain(%),Stress(MPa),Temp(C),Log_SR(s-1)
0.0,0.0,0.0,123.36052549101966,0.9325852742427063
5.606037043159213e-07,4.8e-06,0.919703025,123.36052549101966,0.9325852742427063
1.5883771622284438e-06,1.3599999999999999e-05,2.6058252374999995,123.36052549101966,0.9325852742427063
5.886338895317175e-06,5.04e-05,9.6568817625,123.36052549101966,0.9325852742427063
7.007546303949017e-06,5.9999999999999995e-05,11.496287812499999,123.36052549101966,0.9325852742427063
8.595923466177462e-06,7.36e-05,14.10211305,123.36052549101966,0.9325852742427063
1.233328149495027e-05,0.00010559999999999999,20.23346655,123.36052549101966,0.9325852742427063
1.3828224706459393e-05,0.00011839999999999999,22.686007949999997,123.36052549101966,0.9325852742427063
1.6537809277319682e-05,0.0001416,27.1312392375,123.36052549101966,0.9325852742427063
1.6818111129477644e-05,0.000144,27.59109075,123.36052549101966,0.9325852742427063
1.7472148784512886e-05,0.0001496,28.6640776125,123.36052549101966,0.9325852742427063
1.7845884587390163e-05,0.0001528,29.2772129625,123.36052549101966,0.9325852742427063
1.952769570033793e-05,0.0001672,32.0363220375,123.36052549101966,0.9325852742427063
2.2517582123356176e-05,0.0001928,36.9414048375,123.36052549101966,0.9325852742427063
2.2704450024794815e-05,0.00019439999999999998,37.2479725125,123.36052549101966,0.9325852742427063
2.3265053729110738e-05,0.0001992,38.167675537499996,123.36052549101966,0.9325852742427063
2.4292827187023258e-05,0.000208,39.85379775,123.36052549101966,0.9325852742427063
2.5227166694216462e-05,0.000216,41.386636124999995,123.36052549101966,0.9325852742427063
2.7563015462199467e-05,0.000236,45.218732062499996,123.36052549101966,0.9325852742427063
2.8030185215796067e-05,0.00023999999999999998,45.985151249999994,123.36052549101966,0.9325852742427063
2.9338260525866552e-05,0.0002512,48.131124975,123.36052549101966,0.9325852742427063
3.064633583593703e-05,0.0002624,50.277098699999996,123.36052549101966,0.9325852742427063
3.223471299816548e-05,0.000276,52.882923937499996,123.36052549101966,0.9325852742427063
3.251501485032344e-05,0.0002784,53.34277545,123.36052549101966,0.9325852742427063
3.466399571686781e-05,0.0002968,56.8683037125,123.36052549101966,0.9325852742427063
3.7653882139886054e-05,0.0003224,61.7733865125,123.36052549101966,0.9325852742427063
4.176497597153614e-05,0.00035759999999999996,68.51787536249999,123.36052549101966,0.9325852742427063
4.4100824739519145e-05,0.00037759999999999996,72.34997129999999,123.36052549101966,0.9325852742427063
4.4567994493115756e-05,0.0003816,73.1163904875,123.36052549101966,0.9325852742427063
4.70907111625374e-05,0.0004032,77.2550541,123.36052549101966,0.9325852742427063
5.054776733915225e-05,0.0004328,82.9265560875,123.36052549101966,0.9325852742427063
5.176240869850341e-05,0.0004432,84.919245975,123.36052549101966,0.9325852742427063
5.250988030425797e-05,0.0004496,86.145516675,123.36052549101966,0.9325852742427063
5.4004823515767094e-05,0.00046239999999999996,88.598058075,123.36052549101966,0.9325852742427063
5.4752295121521656e-05,0.00046879999999999996,89.824328775,123.36052549101966,0.9325852742427063
5.858308710101378e-05,0.0005015999999999999,96.10896611249999,123.36052549101966,0.9325852742427063
6.250731303122524e-05,0.0005352,102.5468872875,123.36052549101966,0.9325852742427063
6.316135068626048e-05,0.0005408,103.61987415,123.36052549101966,0.9325852742427063
6.456285994705028e-05,0.0005528,105.9191317125,123.36052549101966,0.9325852742427063
6.521689760208552e-05,0.0005584,106.992118575,123.36052549101966,0.9325852742427063
6.801991612366513e-05,0.0005824,111.5906337,123.36052549101966,0.9325852742427063
6.858051982798105e-05,0.0005872,112.51033672499999,123.36052549101966,0.9325852742427063
6.988859513805154e-05,0.0005984,114.65631045,123.36052549101966,0.9325852742427063
7.241131180747319e-05,0.00062,118.7949740625,123.36052549101966,0.9325852742427063
7.62421037869653e-05,0.0006527999999999999,125.07961139999999,123.36052549101966,0.9325852742427063
7.698957539271987e-05,0.0006592,126.30588209999999,123.36052549101966,0.9325852742427063
7.89516883578256e-05,0.000676,129.52484268749998,123.36052549101966,0.9325852742427063
7.979259391429948e-05,0.0006832,130.904397225,123.36052549101966,0.9325852742427063
8.166127292868588e-05,0.0006992,133.970073975,123.36052549101966,0.9325852742427063
8.371681984451093e-05,0.0007168,137.34231839999998,123.36052549101966,0.9325852742427063
8.558549885889732e-05,0.0007327999999999999,140.40799514999998,123.36052549101966,0.9325852742427063
8.745417787328374e-05,0.0007488,143.4736719,123.36052549101966,0.9325852742427063
8.810821552831898e-05,0.0007544,144.54665876250002,123.36052549101966,0.9325852742427063
9.053749824702131e-05,0.0007752,148.5320385375,123.36052549101966,0.9325852742427063
9.343395071932023e-05,0.0007999999999999999,153.28383749999998,123.36052549101966,0.9325852742427063
9.41814223250748e-05,0.0008064,154.5101082,123.36052549101966,0.9325852742427063
9.642383714233849e-05,0.0008256,158.1889203,123.36052549101966,0.9325852742427063
9.903998776247945e-05,0.000848,162.48086775000002,123.36052549101966,0.9325852742427063
0.00010193644023477837,0.0008728,167.2326667125,123.36052549101966,0.9325852742427063
0.00010380511924916477,0.0008887999999999999,170.2983434625,123.36052549101966,0.9325852742427063
0.00010501976060851594,0.0008992,172.29103335,123.36052549101966,0.9325852742427063
0.00010754247727793758,0.0009207999999999999,176.42969696249997,123.36052549101966,0.9325852742427063
0.00011015862789807855,0.0009431999999999999,180.72164441249998,123.36052549101966,0.9325852742427063
0.00011062579765167514,0.0009471999999999999,181.48806359999998,123.36052549101966,0.9325852742427063
0.00011174700506030699,0.0009568,183.32746964999998,123.36052549101966,0.9325852742427063
0.0001131485143210968,0.0009687999999999999,185.6267272125,123.36052549101966,0.9325852742427063
0.00011417628777900932,0.0009776,187.312849425,123.36052549101966,0.9325852742427063
0.00011511062728620252,0.0009855999999999999,188.84568779999998,123.36052549101966,0.9325852742427063
0.00011557779703979913,0.0009896,189.6121069875,123.36052549101966,0.9325852742427063
0.00011763334395562417,0.0010072,192.9843514125,123.36052549101966,0.9325852742427063
0.00011922172111785261,0.0010207999999999999,195.59017665,123.36052549101966,0.9325852742427063
0.0001224919093930288,0.0010488,200.9551109625,123.36052549101966,0.9325852742427063
0.0001241737205059766,0.0010632,203.7142200375,123.36052549101966,0.9325852742427063
0.00012501462606245048,0.0010704,205.093774575,123.36052549101966,0.9325852742427063
0.00012707017297827552,0.001088,208.466019,123.36052549101966,0.9325852742427063
0.00012865855014050395,0.0011015999999999999,211.0718442375,123.36052549101966,0.9325852742427063
0.00012977975754913579,0.0011112,212.91125028749997,123.36052549101966,0.9325852742427063
0.0001315550026128029,0.0011264,215.82364320000002,123.36052549101966,0.9325852742427063
0.00013398428533150522,0.0011472,219.80902297499998,123.36052549101966,0.9325852742427063
0.00013566609644445298,0.0011616,222.56813205,123.36052549101966,0.9325852742427063
0.00013865598286747123,0.0011872,227.47321485,123.36052549101966,0.9325852742427063
0.00014239334089624403,0.0012192,233.60456835,123.36052549101966,0.9325852742427063
0.00014286051064984063,0.0012232,234.3709875375,123.36052549101966,0.9325852742427063
0.00014426201991063042,0.0012351999999999999,236.6702451,123.36052549101966,0.9325852742427063
0.00014472918966422705,0.0012392,237.4366642875,123.36052549101966,0.9325852742427063
0.0001459438310235782,0.0012496,239.42935417500001,123.36052549101966,0.9325852742427063
0.00015211047177105335,0.0013024,245.13974508137758,123.36052549101966,0.9325852742427063
0.00015267107547536926,0.0013072,245.1739144595284,123.36052549101966,0.9325852742427063
0.00015397915078543974,0.0013184,245.25345327882397,123.36052549101966,0.9325852742427063
0.00015809024461708982,0.0013536,245.50173388647354,123.36052549101966,0.9325852742427063
0.00015977205573003758,0.0013679999999999999,245.60257593468398,123.36052549101966,0.9325852742427063
0.0001607063952372308,0.0013759999999999998,245.65842039031583,123.36052549101966,0.9325852742427063
0.00016294881005449448,0.0013951999999999999,245.79193296958135,123.36052549101966,0.9325852742427063
0.00016547152672391613,0.0014168,245.94128104694587,123.36052549101966,0.9325852742427063
0.0001671533378368639,0.0014311999999999999,246.04035339228093,123.36052549101966,0.9325852742427063
0.0001676205075904605,0.0014352,246.0678043980257,123.36052549101966,0.9325852742427063
0.00017201190327426855,0.0014728,246.32440172708002,123.36052549101966,0.9325852742427063
0.0001722922051264265,0.0014751999999999999,246.34069300279884,123.36052549101966,0.9325852742427063
0.0001772442045145505,0.0015176,246.62682272603357,123.36052549101966,0.9325852742427063
0.00018079469464188464,0.001548,246.8300565296677,123.36052549101966,0.9325852742427063
0.00018247650575483243,0.0015624,246.92578134590397,123.36052549101966,0.9325852742427063
0.00018406488291706087,0.001576,247.0158726665276,123.36052549101966,0.9325852742427063
0.00018527952427641202,0.0015864,247.0845615969991,123.36052549101966,0.9325852742427063
0.00018873658045302687,0.001616,247.27910617501297,123.36052549101966,0.9325852742427063
0.00019153959897460647,0.00164,247.43582674488133,123.36052549101966,0.9325852742427063
0.0001935017119397122,0.0016568,247.5449993639251,123.36052549101966,0.9325852742427063
0.00019490322120050202,0.0016688,247.62271564235203,123.36052549101966,0.9325852742427063
0.0001957441267569759,0.001676,247.66924080081827,123.36052549101966,0.9325852742427063
0.00019920118293359073,0.0017055999999999998,247.85969764725002,123.36052549101966,0.9325852742427063
0.000199574918736468,0.0017088,247.88021006915963,123.36052549101966,0.9325852742427063
0.00020013552244078393,0.0017136,247.91095063507873,123.36052549101966,0.9325852742427063
0.00020144359775085442,0.0017247999999999999,247.98254832114603,123.36052549101966,0.9325852742427063
0.000202191069356609,0.0017312,248.0233798738717,123.36052549101966,0.9325852742427063
0.00020564812553322382,0.0017607999999999999,248.2114652898132,123.36052549101966,0.9325852742427063
0.00020676933294185566,0.0017703999999999999,248.27220061525378,123.36052549101966,0.9325852742427063
0.00020761023849832954,0.0017775999999999998,248.31766785532807,123.36052549101966,0.9325852742427063
0.00020901174775911935,0.0017896,248.3932873070156,123.36052549101966,0.9325852742427063
0.00021134759652710237,0.0018096,248.518881748239,123.36052549101966,0.9325852742427063
0.0002120016341821376,0.0018151999999999999,248.55395103106252,123.36052549101966,0.9325852742427063
0.00021256223788645353,0.00182,248.5839768463136,123.36052549101966,0.9325852742427063
0.0002147112187529979,0.0018384,248.69879083246278,123.36052549101966,0.9325852742427063
0.00021527182245731382,0.0018432,248.72866849189927,123.36052549101966,0.9325852742427063
0.00021788797307745476,0.0018655999999999998,248.8676983121168,123.36052549101966,0.9325852742427063
0.00022134502925406961,0.0018951999999999999,249.05042180647942,123.36052549101966,0.9325852742427063
0.00022424148172636854,0.0019199999999999998,249.20265912690908,123.36052549101966,0.9325852742427063
0.0002262970286421936,0.0019375999999999998,249.3102336234856,123.36052549101966,0.9325852742427063
0.00023031468852312436,0.001972,249.51939881685126,123.36052549101966,0.9325852742427063
0.0002327439712418267,0.0019928,249.64518057384697,123.36052549101966,0.9325852742427063
0.00023517325396052902,0.0020136,249.77045134642427,123.36052549101966,0.9325852742427063
0.00023778940458067001,0.002036,249.90479527129693,123.36052549101966,0.9325852742427063
0.0002388171780385825,0.0020448,249.95741537826052,123.36052549101966,0.9325852742427063
0.00024021868729937233,0.0020568,250.02902796086894,123.36052549101966,0.9325852742427063
0.0002425545360673553,0.0020767999999999997,250.14802122073937,123.36052549101966,0.9325852742427063
0.00024507725273677694,0.0020984,250.27603307950474,123.36052549101966,0.9325852742427063
0.00024825400706123387,0.0021256,250.43650451937484,123.36052549101966,0.9325852742427063
0.0002513373274349714,0.002152,250.5914920995948,123.36052549101966,0.9325852742427063
0.0002554484212666215,0.0021872,250.7969936100167,123.36052549101966,0.9325852742427063
0.000256756496576692,0.0021984,250.86210942860117,123.36052549101966,0.9325852742427063
0.0002582514397882011,0.0022112,250.93636929386693,123.36052549101966,0.9325852742427063
0.0002600266848518682,0.0022264,251.02433548985584,123.36052549101966,0.9325852742427063
0.0002606807225069035,0.002232,251.05668500756326,123.36052549101966,0.9325852742427063
0.00026124132621121933,0.0022367999999999997,251.0843879798481,123.36052549101966,0.9325852742427063
0.00026254940152128985,0.002248,251.1489382418079,123.36052549101966,0.9325852742427063
0.000266099891648624,0.0022784,251.32351694127203,123.36052549101966,0.9325852742427063
0.00026647362745150133,0.0022816,251.34184064461633,123.36052549101966,0.9325852742427063
0.00026703423115581723,0.0022864,251.36930741814268,123.36052549101966,0.9325852742427063
0.00026806200461372976,0.0022952,251.4196048329393,123.36052549101966,0.9325852742427063
0.00027002411757883545,0.002312,251.51541881522152,123.36052549101966,0.9325852742427063
0.0002708650231353094,0.0023192,251.55639878700757,123.36052549101966,0.9325852742427063
0.00027497611696695947,0.0023544,251.75603546384278,123.36052549101966,0.9325852742427063
0.00027637762622774925,0.0023664,251.82382691927648,123.36052549101966,0.9325852742427063
0.0002768447959813458,0.0023704,251.84639426039715,123.36052549101966,0.9325852742427063
0.00028207709722162776,0.0024151999999999997,252.0981421285457,123.36052549101966,0.9325852742427063
0.0002849735496939267,0.00244,252.23671922869994,123.36052549101966,0.9325852742427063
0.00028562758734896194,0.0024456,252.2679346814174,123.36052549101966,0.9325852742427063
0.00028740283241262903,0.0024608,252.35252213602485,123.36052549101966,0.9325852742427063
0.00028833717191982224,0.0024687999999999997,252.39695999002942,123.36052549101966,0.9325852742427063
0.0002935694731601042,0.0025136,252.64478188821224,123.36052549101966,0.9325852742427063
0.0002965593595831224,0.0025391999999999997,252.78562090785323,123.36052549101966,0.9325852742427063
0.0002972133972381576,0.0025448,252.81635550014119,123.36052549101966,0.9325852742427063
0.00029880177440038606,0.0025583999999999997,252.89088704450828,123.36052549101966,0.9325852742427063
0.0003001098497104566,0.0025696,252.95215001155776,123.36052549101966,0.9325852742427063
0.000301698226872685,0.0025832,253.02640093225,123.36052549101966,0.9325852742427063
0.00030281943428131687,0.0025927999999999997,253.07872158416785,123.36052549101966,0.9325852742427063
0.00030394064168994873,0.0026024,253.13096673944432,123.36052549101966,0.9325852742427063
0.0003049684151478612,0.0026111999999999997,253.1787921405264,123.36052549101966,0.9325852742427063
0.0003056224528028965,0.0026168,253.20919376143536,123.36052549101966,0.9325852742427063
0.0003059027546550544,0.0026192,253.2222152590054,123.36052549101966,0.9325852742427063
0.0003079583015708795,0.0026368,253.31756446080763,123.36052549101966,0.9325852742427063
0.0003095466787331079,0.0026504,253.39107348757435,123.36052549101966,0.9325852742427063
0.00031412494231835463,0.0026896,253.60213382802468,123.36052549101966,0.9325852742427063
0.0003163673571356183,0.0027088,253.7050723419716,123.36052549101966,0.9325852742427063
0.0003175819984949694,0.0027191999999999997,253.76071187663987,123.36052549101966,0.9325852742427063
0.00031945067750935584,0.0027351999999999997,253.84614937815903,123.36052549101966,0.9325852742427063
0.00032169309232661956,0.0027543999999999997,253.94841752314437,123.36052549101966,0.9325852742427063
0.000323281469488848,0.002768,254.02068931523408,123.36052549101966,0.9325852742427063
0.0003254304503553924,0.0027864,254.11824875714882,123.36052549101966,0.9325852742427063
0.00032617792196114694,0.0027928,254.1521235396908,123.36052549101966,0.9325852742427063
0.00032814003492625263,0.0028095999999999998,254.2409011137746,123.36052549101966,0.9325852742427063
0.0003287006386305686,0.0028144,254.2662280780234,123.36052549101966,0.9325852742427063
0.00032888750653200724,0.002816,254.27466665510093,123.36052549101966,0.9325852742427063
0.00033122335529999023,0.002836,254.37999158780207,123.36052549101966,0.9325852742427063
0.00033187739295502546,0.0028415999999999997,254.40943060716828,123.36052549101966,0.9325852742427063
0.0003344001096244471,0.0028631999999999998,254.52276979378445,123.36052549101966,0.9325852742427063
0.0003388849392589745,0.0029016,254.72344173552543,123.36052549101966,0.9325852742427063
0.00034019301456904495,0.0029127999999999997,254.78177560668848,123.36052549101966,0.9325852742427063
0.00034178139173127344,0.0029264,254.85249212292226,123.36052549101966,0.9325852742427063
0.0003457990516122042,0.0029608,255.03079358206983,123.36052549101966,0.9325852742427063
0.0003461727874150815,0.002964,255.04733858284638,123.36052549101966,0.9325852742427063
0.00034804146642946785,0.00298,255.12995932232673,123.36052549101966,0.9325852742427063
0.00035159195655680203,0.0030104,255.28646365545214,123.36052549101966,0.9325852742427063
0.00035626365409276807,0.0030504,255.4914545458555,123.36052549101966,0.9325852742427063
0.0003577585973042772,0.0030632,255.55682986872998,123.36052549101966,0.9325852742427063
0.00035822576705787375,0.0030672,255.5772377967672,123.36052549101966,0.9325852742427063
0.0003586929368114704,0.0030712,255.59763534782093,123.36052549101966,0.9325852742427063
0.00036074848372729545,0.0030888,255.68726176863413,123.36052549101966,0.9325852742427063
0.00036214999298808524,0.0031008,255.74825652892633,123.36052549101966,0.9325852742427063
0.0003628974645938398,0.0031072,255.78074942283206,123.36052549101966,0.9325852742427063
0.00036448584175606823,0.0031208,255.8497102850772,123.36052549101966,0.9325852742427063
0.00036644795472117397,0.0031376,255.93473563223,123.36052549101966,0.9325852742427063
0.0003680363318834024,0.0031512,256.00343570537495,123.36052549101966,0.9325852742427063
0.0003689706713905956,0.0031592,256.0437934981863,123.36052549101966,0.9325852742427063
0.00037018531274994674,0.0031696,256.09619909284845,123.36052549101966,0.9325852742427063
0.0003725211615179298,0.0031896,256.19679098053024,123.36052549101966,0.9325852742427063
0.00037326863312368434,0.003196,256.2289283917109,123.36052549101966,0.9325852742427063
0.0003745767084337548,0.0032072,256.285108533332,123.36052549101966,0.9325852742427063
0.0003773797269553344,0.0032312,256.4052375515336,123.36052549101966,0.9325852742427063
0.0003787812362161242,0.0032432,256.4651715301017,123.36052549101966,0.9325852742427063
0.00037980900967403674,0.0032519999999999997,256.50906816222096,123.36052549101966,0.9325852742427063
0.000382798896097055,0.0032776,256.63650481219514,123.36052549101966,0.9325852742427063
0.00038569534856935396,0.0033024,256.75958940203253,123.36052549101966,0.9325852742427063
0.0003866296880765471,0.0033104,256.7992171403239,123.36052549101966,0.9325852742427063
0.00038728372573158234,0.003316,256.8269343377473,123.36052549101966,0.9325852742427063
0.000387750895485179,0.00332,256.8467211604098,123.36052549101966,0.9325852742427063
0.0003893392726474074,0.0033336,256.9139269219806,123.36052549101966,0.9325852742427063
0.0003911145177110745,0.0033488,256.9889128328554,123.36052549101966,0.9325852742427063
0.0003920488572182677,0.0033568,257.0283257794575,123.36052549101966,0.9325852742427063
0.00039373066833121547,0.0033712,257.0991768932139,123.36052549101966,0.9325852742427063
0.00039606651709919846,0.0033912,257.1973857256902,123.36052549101966,0.9325852742427063
0.00040027104488156787,0.0034272,257.3735942735798,123.36052549101966,0.9325852742427063
0.00040195285599451563,0.0034416,257.4438753926186,123.36052549101966,0.9325852742427063
0.00040569021402328846,0.0034736,257.599646357842,123.36052549101966,0.9325852742427063
0.00040774576093911347,0.0034912,257.68508180326637,123.36052549101966,0.9325852742427063
0.0004112028171157283,0.0035207999999999997,257.82839085074966,123.36052549101966,0.9325852742427063
0.0004132583640315534,0.0035383999999999997,257.91337889103147,123.36052549101966,0.9325852742427063
0.00041764975971536145,0.0035759999999999998,258.09439388704124,123.36052549101966,0.9325852742427063
0.00041793006156751937,0.0035784,258.1059227701064,123.36052549101966,0.9325852742427063
0.0004197987405819058,0.0035943999999999998,258.1827050705245,123.36052549101966,0.9325852742427063
0.0004202659103355024,0.0035984,258.2018798038423,123.36052549101966,0.9325852742427063
0.00042334923070923996,0.0036247999999999996,258.32822520377795,123.36052549101966,0.9325852742427063
0.00042633911713225824,0.0036504,258.45039967522047,123.36052549101966,0.9325852742427063
0.00042727345663945144,0.0036584,258.4885106104789,123.36052549101966,0.9325852742427063
0.00042802092824520595,0.0036647999999999997,258.51897596230657,123.36052549101966,0.9325852742427063
0.0004299830412103117,0.0036815999999999997,258.5988489532009,123.36052549101966,0.9325852742427063
0.00043334666343620726,0.0037104,258.73544416086605,123.36052549101966,0.9325852742427063
0.0004337203992390845,0.0037135999999999996,258.75059583854426,123.36052549101966,0.9325852742427063
0.00043586938010562885,0.0037319999999999996,258.83761937383764,123.36052549101966,0.9325852742427063
0.0004368971535635414,0.0037408,258.87918016052754,123.36052549101966,0.9325852742427063
0.00043923300233152443,0.0037608,258.9734949490869,123.36052549101966,0.9325852742427063
0.0004401673418387176,0.0037687999999999997,259.01116606898177,123.36052549101966,0.9325852742427063
0.0004421294548038233,0.0037855999999999996,259.090174061646,123.36052549101966,0.9325852742427063
0.0004433440961631745,0.003796,259.139015249505,123.36052549101966,0.9325852742427063
0.0004468011523397893,0.0038255999999999997,259.2777399662069,123.36052549101966,0.9325852742427063
0.0004485763974034564,0.0038407999999999997,259.3488142692923,123.36052549101966,0.9325852742427063
0.000451659717777194,0.0038672,259.4719989394252,123.36052549101966,0.9325852742427063
0.00045511677395380885,0.0038967999999999997,259.6097257432274,123.36052549101966,0.9325852742427063
0.0004555839437074054,0.0039008,259.6283061309801,123.36052549101966,0.9325852742427063
0.000456611717165318,0.0039096,259.6691568483286,123.36052549101966,0.9325852742427063
0.00045745262272179184,0.0039168,259.70255349615525,123.36052549101966,0.9325852742427063
0.0004642733011243022,0.0039752,259.9725583546566,123.36052549101966,0.9325852742427063
0.00046455360297646014,0.0039775999999999995,259.98362122862045,123.36052549101966,0.9325852742427063
0.0005882843766534516,0.0050370074014802965,264.639888846932,123.36052549101966,0.9325852742427063
0.0005972558302132184,0.005113822764552911,264.96182834949906,123.36052549101966,0.9325852742427063
0.0006533274149617601,0.005593918783756751,266.93281831382717,123.36052549101966,0.9325852742427063
0.0007407990871694854,0.006342868573714743,269.8805016541151,123.36052549101966,0.9325852742427063
0.0007564991308990772,0.0064772954590918185,270.3948667576267,123.36052549101966,0.9325852742427063
0.0007901420817482023,0.006765353070614123,271.4832636049954,123.36052549101966,0.9325852742427063
0.0008215421692073857,0.007034206841368274,272.48290246134286,123.36052549101966,0.9325852742427063
0.0008820994807358109,0.007552710542108421,274.3696562468391,123.36052549101966,0.9325852742427063
0.000929199611924586,0.007955991198239648,275.8024017360946,123.36052549101966,0.9325852742427063
0.0010076998305725447,0.008628125625125025,278.1288862096526,123.36052549101966,0.9325852742427063
0.0010929286393903282,0.009357871574314863,280.5760971420103,123.36052549101966,0.9325852742427063
0.001142271633969045,0.009780356071214243,281.958860224596,123.36052549101966,0.9325852742427063
0.0011781574482081119,0.010087617523504702,282.94991375652825,123.36052549101966,0.9325852742427063
0.0012768434373655456,0.010932586517303462,285.61637549054694,123.36052549101966,0.9325852742427063
0.0013172149783844957,0.011278255651130227,286.68387894496004,123.36052549101966,0.9325852742427063
0.0013531007926235626,0.011585517103420685,287.6221040074562,123.36052549101966,0.9325852742427063
0.0013934723336425125,0.011931186237247449,288.6660831233923,123.36052549101966,0.9325852742427063
0.0014248724211016958,0.0122000400080016,289.4699323221349,123.36052549101966,0.9325852742427063
0.001438329601441346,0.012315263052610522,289.81232086413354,123.36052549101966,0.9325852742427063
0.0014495439183910544,0.01241128225645129,290.09669133211565,123.36052549101966,0.9325852742427063
0.0015325298638188963,0.013121824364872975,292.1749965680573,123.36052549101966,0.9325852742427063
0.0016087872190769133,0.013774754950990198,294.04640178185025,123.36052549101966,0.9325852742427063
0.0016648588038254552,0.01425485097019404,295.4004325526838,123.36052549101966,0.9325852742427063
0.0016760731207751635,0.014350870174034807,295.66909159017655,123.36052549101966,0.9325852742427063
0.0016917731645047552,0.014485297059411883,296.0440394622678,123.36052549101966,0.9325852742427063
0.001770273383152714,0.01515743148629726,297.8987996799168,123.36052549101966,0.9325852742427063
0.0018128877875616056,0.01552230446089218,298.89222370718267,123.36052549101966,0.9325852742427063
0.0018824165526497977,0.016117623524704944,300.49374009310014,123.36052549101966,0.9325852742427063
0.0019093309133290976,0.016348069613922784,301.10746710380477,123.36052549101966,0.9325852742427063
0.0019317595472285141,0.01654010802160432,301.6163331239001,123.36052549101966,0.9325852742427063
0.0019788596784172893,0.016943388677735545,302.6775120391246,123.36052549101966,0.9325852742427063
0.0020551170336753064,0.017596319263852772,304.3749593492529,123.36052549101966,0.9325852742427063
0.002093245711304315,0.017922784556911382,305.214457407219,123.36052549101966,0.9325852742427063
0.0021089457550339066,0.01805721144228846,305.5583971751539,123.36052549101966,0.9325852742427063
0.0022412746950404654,0.019190238047609522,308.4186756663027,123.36052549101966,0.9325852742427063
0.002299589143178949,0.019689537907581517,309.65814331291773,123.36052549101966,0.9325852742427063
0.0023466892743677237,0.02009281856371274,310.6503260572256,123.36052549101966,0.9325852742427063
0.002510418301833466,0.02149469893978796,314.0404809100516,123.36052549101966,0.9325852742427063
0.002523875482173116,0.02160992198439688,314.31522912302415,123.36052549101966,0.9325852742427063
0.0026629330123495,0.022800560112022406,317.1216202548217,123.36052549101966,0.9325852742427063
0.002723490323877925,0.023319063812762553,318.32582661862597,123.36052549101966,0.9325852742427063
0.002808719132695709,0.02404880976195239,320.0030921921838,123.36052549101966,0.9325852742427063
0.002896190804903434,0.02479775955191038,321.70398202719537,123.36052549101966,0.9325852742427063
0.002916376575412909,0.024970594118823766,322.09363576346556,123.36052549101966,0.9325852742427063
0.0029410480727022673,0.025181836367273454,322.5684537331169,123.36052549101966,0.9325852742427063
0.0030038482476206344,0.025719543908781756,323.77012457002894,123.36052549101966,0.9325852742427063
0.0030307626082999345,0.0259499899979996,324.2821224866305,123.36052549101966,0.9325852742427063
0.003068891285928943,0.026276455291058213,325.00442780353615,123.36052549101966,0.9325852742427063
0.0031070199635579512,0.026602920584116823,325.7232415788049,123.36052549101966,0.9325852742427063
0.0031496343679668433,0.026967793558711744,326.5225628319964,123.36052549101966,0.9325852742427063
0.0031967344991556184,0.02737107421484297,327.40113201797016,123.36052549101966,0.9325852742427063
0.003205705952715385,0.027447889577915583,327.5679046132049,123.36052549101966,0.9325852742427063
0.0032124345428852104,0.027505501100220046,327.69286463276933,123.36052549101966,0.9325852742427063
0.0032371060401745685,0.027716743348669734,328.150180655281,123.36052549101966,0.9325852742427063
0.003311120532042644,0.028350470094018806,329.51404160052624,123.36052549101966,0.9325852742427063
0.0033402777561118858,0.0286001200240048,330.04804919876153,123.36052549101966,0.9325852742427063
0.003425506564929669,0.02932986597319464,331.59866829357736,123.36052549101966,0.9325852742427063
0.003447935198829086,0.029521904380876176,332.00421589747737,123.36052549101966,0.9325852742427063
0.0034995210567977443,0.029963592718543708,332.9330909772293,123.36052549101966,0.9325852742427063
0.0035107353737474528,0.030059611922384478,333.1343119593562,123.36052549101966,0.9325852742427063
0.003551106914766403,0.030405281056211243,333.8566411142291,123.36052549101966,0.9325852742427063
0.0035757784120557614,0.03061652330466093,334.2964881070409,123.36052549101966,0.9325852742427063
0.0035892355923954115,0.030731746349269853,334.5359057352676,123.36052549101966,0.9325852742427063
0.0036363357235841866,0.03113502700540108,335.37112439733505,123.36052549101966,0.9325852742427063
0.003710350215452262,0.03176875375075015,336.67513652305917,123.36052549101966,0.9325852742427063
0.0037439931663013864,0.03205681136227245,337.2645116136488,123.36052549101966,0.9325852742427063
0.0037709075269806874,0.0322872574514903,337.7345259076499,123.36052549101966,0.9325852742427063
0.003800064751049929,0.0325369073814763,338.2422340995587,123.36052549101966,0.9325852742427063
0.0038337077018990536,0.0328249649929986,338.8261672234432,123.36052549101966,0.9325852742427063
0.0038942650134274792,0.03334346869373875,339.8722353749204,123.36052549101966,0.9325852742427063
0.003952579461565962,0.03384276855371074,340.87358059704746,123.36052549101966,0.9325852742427063
0.003997436729364797,0.03422684536907382,341.63993049192527,123.36052549101966,0.9325852742427063
0.004024351090044096,0.034457291458291656,342.0981307333223,123.36052549101966,0.9325852742427063
0.004033322543603863,0.03453410682136428,342.2505983634599,123.36052549101966,0.9325852742427063
0.004053508314113338,0.03470694138827765,342.59316777058694,123.36052549101966,0.9325852742427063
0.0041140656256417624,0.0352254450890178,343.6169061957479,123.36052549101966,0.9325852742427063
0.00417686580056013,0.03576315263052611,344.67237249027136,123.36052549101966,0.9325852742427063
0.004262094609377913,0.03649289857971594,346.09494460412157,123.36052549101966,0.9325852742427063
0.004277794653107505,0.03662732546509302,346.3557827964207,123.36052549101966,0.9325852742427063
0.004291251833447156,0.03674254850970195,346.5790613730821,123.36052549101966,0.9325852742427063
0.004315923330736513,0.036953790758151625,346.98769748162476,123.36052549101966,0.9325852742427063
0.004385452095824706,0.037549109821964397,348.1344357290791,123.36052549101966,0.9325852742427063
0.004407880729724123,0.03774114822964593,348.5028358535061,123.36052549101966,0.9325852742427063
0.004468438041252548,0.03825965193038608,349.49388261256524,123.36052549101966,0.9325852742427063
0.004486380948372081,0.03841328265653131,349.7865183555302,123.36052549101966,0.9325852742427063
0.004531238216170914,0.038797359471894374,350.5161178289445,123.36052549101966,0.9325852742427063
0.0045491811232904475,0.0389509901980396,350.8071682417823,123.36052549101966,0.9325852742427063
0.004591795527699339,0.039315863172634524,351.49662450669797,123.36052549101966,0.9325852742427063
0.004656838566007648,0.03987277455491098,352.5441607500946,123.36052549101966,0.9325852742427063
0.004701695833806482,0.04025685137027406,353.26327719687094,123.36052549101966,0.9325852742427063
0.00471291015075619,0.040352870574114824,353.4426376136159,123.36052549101966,0.9325852742427063
0.00472636733109584,0.04046809361872375,353.6576505542307,123.36052549101966,0.9325852742427063
0.004755524555165082,0.040717743548709745,354.122694565566,123.36052549101966,0.9325852742427063
0.0047712245988946736,0.040852170434086815,354.3726422307267,123.36052549101966,0.9325852742427063
0.004795896096184032,0.04106341268253651,354.7647700370872,123.36052549101966,0.9325852742427063
0.004816081866693508,0.041236247249449895,355.08501704880956,123.36052549101966,0.9325852742427063
0.004842996227372807,0.04146669333866773,355.51119994748336,123.36052549101966,0.9325852742427063
0.004863181997882282,0.04163952790558112,355.8302312077795,123.36052549101966,0.9325852742427063
0.004937196489750357,0.04227325465093018,356.9956200332153,123.36052549101966,0.9325852742427063
0.004977568030769308,0.04261892378475696,357.6284141029648,123.36052549101966,0.9325852742427063
0.004986539484329074,0.042695739147829564,357.76876281372057,123.36052549101966,0.9325852742427063
0.005015696708398316,0.04294538907781556,358.22421752295236,123.36052549101966,0.9325852742427063
0.005078496883316684,0.04348309661932387,359.2017045380749,123.36052549101966,0.9325852742427063
0.0050941969270462744,0.04361752350470094,359.4453383085888,123.36052549101966,0.9325852742427063
0.005116625560945691,0.04380956191238247,359.79287918221996,123.36052549101966,0.9325852742427063
0.005150268511794817,0.044097619523904785,360.3130785512317,123.36052549101966,0.9325852742427063
0.00516821141891435,0.044251250250050014,360.5899762559268,123.36052549101966,0.9325852742427063
0.005199611506373532,0.044520104020804155,361.0736467843104,123.36052549101966,0.9325852742427063
0.005257925954512017,0.04501940388077616,361.9688805891695,123.36052549101966,0.9325852742427063
0.005282597451801376,0.04523064612922585,362.3464667197368,123.36052549101966,0.9325852742427063
0.005336426173159976,0.04569153830766154,363.1679120090281,123.36052549101966,0.9325852742427063
0.0053431547633298,0.04574914982996599,363.2703649690185,123.36052549101966,0.9325852742427063
0.0053969834846884,0.046210042008401675,364.0881850305224,123.36052549101966,0.9325852742427063
0.005450812206047,0.04667093418683736,364.9028300495229,123.36052549101966,0.9325852742427063
0.005513612380965368,0.04720864172834567,365.84929431506555,123.36052549101966,0.9325852742427063
0.0055696839657139105,0.04768873774754952,366.690804751671,123.36052549101966,0.9325852742427063
0.005592112599613327,0.04788077615523105,367.02648303128865,123.36052549101966,0.9325852742427063
0.005625755550462451,0.04816883376675335,367.52901762720575,123.36052549101966,0.9325852742427063
0.005645941320971927,0.04834166833366674,367.8299758338569,123.36052549101966,0.9325852742427063
0.0056795842718210515,0.04862972594518904,368.3306419783737,123.36052549101966,0.9325852742427063
0.005702012905720468,0.04882176435287057,368.6637769932428,123.36052549101966,0.9325852742427063
0.005735655856569594,0.04910982196439288,369.16252290643894,123.36052549101966,0.9325852742427063
0.005776027397588543,0.049455491098219645,369.75951451389545,123.36052549101966,0.9325852742427063
0.005832098982337086,0.04993558711742349,370.5859768695716,123.36052549101966,0.9325852742427063
0.005935270698274402,0.05081896379275855,372.09861577194414,123.36052549101966,0.9325852742427063
0.006007042326752535,0.051433486697339464,373.14484363578805,123.36052549101966,0.9325852742427063
0.006047413867771487,0.05177915583116624,373.7312042007274,123.36052549101966,0.9325852742427063
0.006134885539979211,0.05252810562112423,374.9964403667598,123.36052549101966,0.9325852742427063
0.006157314173878628,0.05272014402880576,375.31972418438846,123.36052549101966,0.9325852742427063
0.006244785846086353,0.05346909381876375,376.5761672154352,123.36052549101966,0.9325852742427063
0.0063098288843946625,0.054026005201040214,377.5060005496542,123.36052549101966,0.9325852742427063
0.006406272010162153,0.05485177035407081,378.87786767391185,123.36052549101966,0.9325852742427063
0.0064511292779609875,0.05523584716943389,379.5131987639728,123.36052549101966,0.9325852742427063
0.006475800775250346,0.05544708941788358,379.861896401437,123.36052549101966,0.9325852742427063
0.006563272447458071,0.05619603920784157,381.0940349153273,123.36052549101966,0.9325852742427063
0.006576729627797722,0.05631126225245049,381.28302475419065,123.36052549101966,0.9325852742427063
0.006594672534917255,0.05646489297859572,381.53477677086534,123.36052549101966,0.9325852742427063
0.006711301431194221,0.0574634926985397,383.16470146529394,123.36052549101966,0.9325852742427063
0.006738215791873522,0.057693938787757554,383.5392647236682,123.36052549101966,0.9325852742427063
0.006830173190861129,0.058481296259251844,384.81464298454915,123.36052549101966,0.9325852742427063
0.0068548446881504885,0.058692538507701536,385.155676059658,123.36052549101966,0.9325852742427063
0.006875030458659964,0.058865373074614924,385.4343472080574,123.36052549101966,0.9325852742427063
0.006964744994257631,0.05963352670534107,386.6690450682228,123.36052549101966,0.9325852742427063
0.007027545169175997,0.060171234246849364,387.5296455227028,123.36052549101966,0.9325852742427063
0.0070365166227357645,0.060248049609921986,387.65234315748324,123.36052549101966,0.9325852742427063
0.00705670239324524,0.060420884176835374,387.92818998520397,123.36052549101966,0.9325852742427063
0.007099316797654131,0.06078575715143028,388.5095247473008,123.36052549101966,0.9325852742427063
0.0071957599234216225,0.06161152230446089,389.8201752326994,123.36052549101966,0.9325852742427063
0.0072630458251198736,0.0621876375275055,390.73052826231014,123.36052549101966,0.9325852742427063
0.007296688775968998,0.0624756951390278,391.1844709263797,123.36052549101966,0.9325852742427063
0.007321360273258357,0.06268693738747749,391.5168435976718,123.36052549101966,0.9325852742427063
0.007334817453598007,0.06280216043208642,391.6979536616365,123.36052549101966,0.9325852742427063
0.007366217541057191,0.06307101420284057,392.1200405987061,123.36052549101966,0.9325852742427063
0.007509760798013458,0.0643000600120024,394.0407145677873,123.36052549101966,0.9325852742427063
0.007561346655982116,0.06474174834966993,394.72745254236844,123.36052549101966,0.9325852742427063
0.007608446787170891,0.06514502900580116,395.3528800595062,123.36052549101966,0.9325852742427063
0.0076219039675105415,0.06526025205041008,395.53129606027926,123.36052549101966,0.9325852742427063
0.0077004041861585,0.06593238647729546,396.56961797823124,123.36052549101966,0.9325852742427063
0.007747504317347275,0.06633566713342669,397.1906297939308,123.36052549101966,0.9325852742427063
0.007765447224466809,0.06648929785957192,397.4268182090082,123.36052549101966,0.9325852742427063
0.007819275945825408,0.0669501900380076,398.13410972085796,123.36052549101966,0.9325852742427063
0.007852918896674535,0.06723824764952992,398.57520274708514,123.36052549101966,0.9325852742427063
0.00791347620820296,0.06775675135027005,399.36731747298785,123.36052549101966,0.9325852742427063
0.007944876295662142,0.06802560512102421,399.7771127282262,123.36052549101966,0.9325852742427063
0.007962819202781676,0.06817923584716944,400.01099784383575,123.36052549101966,0.9325852742427063
0.008003190743800626,0.0685249049809962,400.5364891605968,123.36052549101966,0.9325852742427063
0.008052533738379343,0.06894738947789558,401.1773544797216,123.36052549101966,0.9325852742427063
0.008097391006178177,0.06933146629325866,401.758631540628,123.36052549101966,0.9325852742427063
0.008108605323127885,0.06942748549709943,401.9037544139123,123.36052549101966,0.9325852742427063
0.008146734000756892,0.06975395079015803,402.3965877359401,123.36052549101966,0.9325852742427063
0.008187105541775845,0.07009961992398481,402.91743177253824,123.36052549101966,0.9325852742427063
0.00820953417567526,0.07029165833166634,403.20635673313706,123.36052549101966,0.9325852742427063
0.00829027725771316,0.07098299659931986,404.2439473130927,123.36052549101966,0.9325852742427063
0.008339620252291877,0.07140548109621925,404.8760905199952,123.36052549101966,0.9325852742427063
0.008373263203141001,0.07169353870774155,405.30626115484324,123.36052549101966,0.9325852742427063
0.008433820514669427,0.0722120424084817,406.07887348402323,123.36052549101966,0.9325852742427063
0.00847419205568838,0.07255771154230847,406.5927467354428,123.36052549101966,0.9325852742427063
0.008532506503826861,0.07305701140228046,407.33332572400104,123.36052549101966,0.9325852742427063
0.008628949629594354,0.07388277655531107,408.5538121811045,123.36052549101966,0.9325852742427063
0.00872987848214173,0.07474694938987798,409.8253821590677,123.36052549101966,0.9325852742427063
0.00874557852587132,0.07488137627525505,410.0226654585422,123.36052549101966,0.9325852742427063
0.008810621564179628,0.07543828765753151,410.8385148901866,123.36052549101966,0.9325852742427063
0.008844264515028755,0.07572634526905382,411.25958408059194,123.36052549101966,0.9325852742427063
0.008913793280116947,0.07632166433286658,412.1278193951811,123.36052549101966,0.9325852742427063
0.008951921957745955,0.0766481296259252,412.60282695721037,123.36052549101966,0.9325852742427063
0.009007993542494496,0.07712822564512903,413.29993661706334,123.36052549101966,0.9325852742427063
0.009032665039783854,0.07733946789357872,413.60612852557057,123.36052549101966,0.9325852742427063
0.00909322235131228,0.07785797159431887,414.3563109174434,123.36052549101966,0.9325852742427063
0.009117893848601639,0.07806921384276856,414.66138188469097,123.36052549101966,0.9325852742427063
0.009164993979790413,0.07847249449889979,415.2428976156262,123.36052549101966,0.9325852742427063
0.009265922832337788,0.0793366673334667,416.48509258650404,123.36052549101966,0.9325852742427063
0.009283865739457322,0.07949029805961193,416.70537367312954,123.36052549101966,0.9325852742427063
0.009339937324205865,0.07997039407881577,417.39268433702745,123.36052549101966,0.9325852742427063
0.009373580275054989,0.08025845169033807,417.80429834917226,123.36052549101966,0.9325852742427063
0.00941395181607394,0.08060412082416483,418.2974754143464,123.36052549101966,0.9325852742427063
0.009429651859803531,0.08073854770954192,418.4890436523239,123.36052549101966,0.9325852742427063
0.009492452034721897,0.08127625525105021,419.2540759513268,123.36052549101966,0.9325852742427063
0.009505909215061548,0.08139147829565914,419.417754346144,123.36052549101966,0.9325852742427063
0.0095193663954012,0.08150670134026806,419.58134239751286,123.36052549101966,0.9325852742427063
0.009539552165910672,0.08167953590718144,419.82655546866346,123.36052549101966,0.9325852742427063
0.009584409433709508,0.08206361272254452,420.3707500678808,123.36052549101966,0.9325852742427063
0.009676366832697115,0.08285097019403881,421.4832534931247,123.36052549101966,0.9325852742427063
0.00981766722626344,0.0840608121624325,423.1847079252518,123.36052549101966,0.9325852742427063
0.00985579590389245,0.0843872774554911,423.64219089641324,123.36052549101966,0.9325852742427063
0.009893924581521458,0.08471374274854972,424.0989841468271,123.36052549101966,0.9325852742427063
0.009925324668980641,0.08498259651930387,424.47465154652764,123.36052549101966,0.9325852742427063
0.010015039204578309,0.08575075015003002,425.54544144899904,123.36052549101966,0.9325852742427063
0.010026253521528018,0.08584676935387078,425.6790266547597,123.36052549101966,0.9325852742427063
0.010032982111697841,0.08590438087617525,425.75914980813525,123.36052549101966,0.9325852742427063
0.01007111078932685,0.08623084616923385,426.2127857918449,123.36052549101966,0.9325852742427063
0.010120453783905567,0.08665333066613323,426.7988510920085,123.36052549101966,0.9325852742427063
0.010136153827635159,0.0867877575515103,426.98509257747116,123.36052549101966,0.9325852742427063
0.010158582461534576,0.08697979595919185,427.2509568008549,123.36052549101966,0.9325852742427063
0.010263997040861833,0.08788237647529507,428.49746504031697,123.36052549101966,0.9325852742427063
0.010275211357811542,0.08797839567913583,428.62977780826236,123.36052549101966,0.9325852742427063
0.010304368581880784,0.08822804560912183,428.97352770481876,123.36052549101966,0.9325852742427063
0.010342497259509793,0.08855451090218044,429.4224749640584,123.36052549101966,0.9325852742427063
0.010362683030019268,0.08872734546909382,429.6598915812538,123.36052549101966,0.9325852742427063
0.0104344546584974,0.08934186837367473,430.50258273881497,123.36052549101966,0.9325852742427063
0.010461369019176702,0.08957231446289259,430.81800874019893,123.36052549101966,0.9325852742427063
0.010477069062906292,0.08970674134826966,431.0018610855718,123.36052549101966,0.9325852742427063
0.010548840691384426,0.09032126425285057,431.8409644210754,123.36052549101966,0.9325852742427063
0.01056678359850396,0.0904748949789958,432.0503919973222,123.36052549101966,0.9325852742427063
0.010640798090372034,0.09110862172434488,432.9128188141399,123.36052549101966,0.9325852742427063
0.01072602689918982,0.09183836767353472,433.90302356598835,123.36052549101966,0.9325852742427063
0.010815741434787484,0.09260652130426085,434.9420350012183,123.36052549101966,0.9325852742427063
0.01086284156597626,0.09300980196039209,435.48617019293494,123.36052549101966,0.9325852742427063
0.010867327292756144,0.09304820964192839,435.53794455664774,123.36052549101966,0.9325852742427063
0.010880784473095794,0.09316343268653732,435.6932176627824,123.36052549101966,0.9325852742427063
0.010894241653435444,0.09327865573114623,435.84841589162863,123.36052549101966,0.9325852742427063
0.01091442742394492,0.09345149029805962,436.0810731210463,123.36052549101966,0.9325852742427063
0.010939098921234278,0.09366273254650931,436.3652041881761,123.36052549101966,0.9325852742427063
0.010992927642592878,0.094123624724945,436.9842604812276,123.36052549101966,0.9325852742427063
0.011015356276492295,0.09431566313262653,437.2418515570406,123.36052549101966,0.9325852742427063
0.011082642178190546,0.09489177835567114,438.01340027638935,123.36052549101966,0.9325852742427063
0.011152170943278736,0.0954870974194839,438.80875048858303,123.36052549101966,0.9325852742427063
0.011174599577178153,0.09567913582716543,439.0649022328859,123.36052549101966,0.9325852742427063
0.011203756801247395,0.09592878575715144,439.3975999407978,123.36052549101966,0.9325852742427063
0.01124861406904623,0.09631286257251451,439.90878396647577,123.36052549101966,0.9325852742427063
0.011288985610065179,0.09665853170634127,440.36817025212645,123.36052549101966,0.9325852742427063
0.011367485828713136,0.09733066613322665,441.25959135557326,123.36052549101966,0.9325852742427063
0.011416828823291853,0.09775315063012603,441.8186845670599,123.36052549101966,0.9325852742427063
0.011477386134820279,0.09827165433086618,442.5035580889903,123.36052549101966,0.9325852742427063
0.011497571905329754,0.09844448889777956,442.7315358996191,123.36052549101966,0.9325852742427063
0.011522243402619113,0.09865573114622925,443.00996357215604,123.36052549101966,0.9325852742427063
0.011542429173128588,0.09882856571314264,443.23759513352013,123.36052549101966,0.9325852742427063
0.011560372080248122,0.09898219643928786,443.4398039944046,123.36052549101966,0.9325852742427063
0.01161195793821678,0.09942388477695539,444.0204737789584,123.36052549101966,0.9325852742427063
0.011654572342625671,0.09978875775155031,444.499399081587,123.36052549101966,0.9325852742427063
0.011672515249745205,0.09994238847769554,444.7008474664545,123.36052549101966,0.9325852742427063