File: datasets/aisi_316_L/data/M1/train_44.csv
Time(s),Strain(%),Stress(MPa),Temp(C),Log_SR(s-1)
0.0,0.0,0.0,46.484195061561834,-2.174191947378864
0.0015531925068098232,1.0399999999999999e-05,2.0309973125,46.484195061561834,-2.174191947378864
0.0022700505868758956,1.52e-05,2.9683806875,46.484195061561834,-2.174191947378864
0.005495911947173221,3.68e-05,7.186605875,46.484195061561834,-2.174191947378864
0.00848282061411519,5.68e-05,11.092369937499999,46.484195061561834,-2.174191947378864
0.009438631387536617,6.319999999999999e-05,12.3422144375,46.484195061561834,-2.174191947378864
0.010633394854313406,7.12e-05,13.9045200625,46.484195061561834,-2.174191947378864
0.012545016401156265,8.4e-05,16.404209062499998,46.484195061561834,-2.174191947378864
0.014576114294676803,9.76e-05,19.060128625,46.484195061561834,-2.174191947378864
0.017085117574908056,0.00011439999999999999,22.340970437499998,46.484195061561834,-2.174191947378864
0.01839935738836252,0.00012319999999999999,24.059506624999997,46.484195061561834,-2.174191947378864
0.020072026241850022,0.0001344,26.2467345,46.484195061561834,-2.174191947378864
0.02054993162856074,0.00013759999999999998,26.871656749999996,46.484195061561834,-2.174191947378864
0.02401474568221342,0.0001608,31.4023430625,46.484195061561834,-2.174191947378864
0.02759903608254378,0.0001848,36.089259937499996,46.484195061561834,-2.174191947378864
0.02998856301609736,0.0002008,39.2138711875,46.484195061561834,-2.174191947378864
0.032855995336361646,0.00021999999999999998,42.963404687499995,46.484195061561834,-2.174191947378864
0.03357285341642772,0.0002248,43.9007880625,46.484195061561834,-2.174191947378864
0.03405075880313843,0.00022799999999999999,44.525710312499996,46.484195061561834,-2.174191947378864
0.03655976208336969,0.0002448,47.806552124999996,46.484195061561834,-2.174191947378864
0.037874001896824154,0.0002536,49.525088312499996,46.484195061561834,-2.174191947378864
0.04038300517705541,0.0002704,52.805930125,46.484195061561834,-2.174191947378864
0.04731263328436077,0.0003168,61.86730275,46.484195061561834,-2.174191947378864
0.0482684440577822,0.0003232,63.11714725,46.484195061561834,-2.174191947378864
0.05018006560462506,0.000336,65.61683624999999,46.484195061561834,-2.174191947378864
0.053047497924889345,0.00035519999999999996,69.36636974999999,46.484195061561834,-2.174191947378864
0.056034406591831315,0.00037519999999999996,73.27213381249999,46.484195061561834,-2.174191947378864
0.06021607872555007,0.0004032,78.74020349999999,46.484195061561834,-2.174191947378864
0.061530318539004536,0.000412,80.4587396875,46.484195061561834,-2.174191947378864
0.0639198454725581,0.000428,83.5833509375,46.484195061561834,-2.174191947378864
0.06415879816591347,0.0004296,83.8958120625,46.484195061561834,-2.174191947378864
0.06750413587288848,0.000452,88.2702678125,46.484195061561834,-2.174191947378864
0.07335847686009474,0.0004912,95.925565375,46.484195061561834,-2.174191947378864
0.07562852744697061,0.0005064,98.89394606249999,46.484195061561834,-2.174191947378864
0.07957124688733402,0.0005327999999999999,104.04955462499998,46.484195061561834,-2.174191947378864
0.08208025016756529,0.0005496,107.3303964375,46.484195061561834,-2.174191947378864
0.08458925344779653,0.0005664,110.61123825,46.484195061561834,-2.174191947378864
0.08829302019480456,0.0005912,115.4543856875,46.484195061561834,-2.174191947378864
0.09510317195543226,0.0006368,124.35952775,46.484195061561834,-2.174191947378864
0.09880693870244028,0.0006615999999999999,129.20267518749998,46.484195061561834,-2.174191947378864
0.09964327312918404,0.0006672,130.296289125,46.484195061561834,-2.174191947378864
0.10083803659596083,0.0006751999999999999,131.85859474999998,46.484195061561834,-2.174191947378864
0.10466127968964656,0.0007008,136.85797275000002,46.484195061561834,-2.174191947378864
0.11135195510359656,0.0007456,145.60688425,46.484195061561834,-2.174191947378864
0.1133830529971171,0.0007591999999999999,148.26280381249998,46.484195061561834,-2.174191947378864
0.11529467454395996,0.000772,150.7624928125,46.484195061561834,-2.174191947378864
0.11625048531738139,0.0007784,152.0123373125,46.484195061561834,-2.174191947378864
0.11864001225093497,0.0007944,155.1369485625,46.484195061561834,-2.174191947378864
0.12079058649113317,0.0008087999999999999,157.9490986875,46.484195061561834,-2.174191947378864
0.12294116073133139,0.0008232,160.76124881249999,46.484195061561834,-2.174191947378864
0.12485278227817426,0.0008359999999999999,163.26093781249998,46.484195061561834,-2.174191947378864
0.12604754574495103,0.0008439999999999999,164.8232434375,46.484195061561834,-2.174191947378864
0.1273617855584055,0.0008527999999999999,166.54177962499998,46.484195061561834,-2.174191947378864
0.129034454411893,0.000864,168.7290075,46.484195061561834,-2.174191947378864
0.1296318361452814,0.000868,169.5101603125,46.484195061561834,-2.174191947378864
0.13261874481222338,0.000888,173.415924375,46.484195061561834,-2.174191947378864
0.1330966501989341,0.0008912,174.040846625,46.484195061561834,-2.174191947378864
0.1340524609723555,0.0008975999999999999,175.290691125,46.484195061561834,-2.174191947378864
0.1369198932926198,0.0009168,179.04022462499998,46.484195061561834,-2.174191947378864
0.1379951804127189,0.0009239999999999999,180.4462996875,46.484195061561834,-2.174191947378864
0.13966784926620643,0.0009352,182.6335275625,46.484195061561834,-2.174191947378864
0.14050418369295017,0.0009408,183.7271415,46.484195061561834,-2.174191947378864
0.14205737619975997,0.0009511999999999999,185.7581388125,46.484195061561834,-2.174191947378864
0.14564166660009034,0.0009752,190.4450556875,46.484195061561834,-2.174191947378864
0.15089862585390823,0.0010104,197.3192004375,46.484195061561834,-2.174191947378864
0.15340762913413947,0.0010272,200.60004225,46.484195061561834,-2.174191947378864
0.15531925068098232,0.00104,203.09973125,46.484195061561834,-2.174191947378864
0.15735034857450286,0.0010536,205.7556508125,46.484195061561834,-2.174191947378864
0.15973987550805643,0.0010696,208.8802620625,46.484195061561834,-2.174191947378864
0.16212940244161,0.0010856,212.0048733125,46.484195061561834,-2.174191947378864
0.1633241659083868,0.0010936,213.5671789375,46.484195061561834,-2.174191947378864
0.16368259494841983,0.001096,214.035870625,46.484195061561834,-2.174191947378864
0.16463840572184127,0.0011024,215.285715125,46.484195061561834,-2.174191947378864
0.1666695036153618,0.001116,217.9416346875,46.484195061561834,-2.174191947378864
0.16941745958894844,0.0011344,221.534937625,46.484195061561834,-2.174191947378864
0.17276279729592342,0.0011568,225.90939337499998,46.484195061561834,-2.174191947378864
0.17336017902931183,0.0011608,226.69054618750002,46.484195061561834,-2.174191947378864
0.17682499308296448,0.001184,231.22123249999999,46.484195061561834,-2.174191947378864
0.17873661462980736,0.0011968,233.7209215,46.484195061561834,-2.174191947378864
0.18208195233678234,0.0012192,238.09537724999998,46.484195061561834,-2.174191947378864
0.1863831008171788,0.001248,243.7196775,46.484195061561834,-2.174191947378864
0.18662205351053415,0.0012496,244.03213862500002,46.484195061561834,-2.174191947378864
0.18793629332398862,0.0012584,245.7506748125,46.484195061561834,-2.174191947378864
0.1903258202575422,0.0012744,248.87528606249998,46.484195061561834,-2.174191947378864
0.19343220527116184,0.0012952,252.93728068750002,46.484195061561834,-2.174191947378864
0.195224350471327,0.0013072,255.28073912499997,46.484195061561834,-2.174191947378864
0.19713597201816987,0.00132,257.780428125,46.484195061561834,-2.174191947378864
0.19928654625836809,0.0013344,260.59257825,46.484195061561834,-2.174191947378864
0.1998839279917565,0.0013384,261.3737310625,46.484195061561834,-2.174191947378864
0.2009592151118556,0.0013456,262.779806125,46.484195061561834,-2.174191947378864
0.2077693668724833,0.0013912,269.5553153394209,46.484195061561834,-2.174191947378864
0.20932255937929312,0.0014016,269.6343954395415,46.484195061561834,-2.174191947378864
0.20968098841932614,0.0014039999999999999,269.65261215563095,46.484195061561834,-2.174191947378864
0.2137431842063672,0.0014311999999999999,269.85822665448023,46.484195061561834,-2.174191947378864
0.21959752519357348,0.0014704,270.15189250756043,46.484195061561834,-2.174191947378864
0.2222260048204824,0.001488,270.282747630864,46.484195061561834,-2.174191947378864
0.22294286290054846,0.0014927999999999999,270.3183304534696,46.484195061561834,-2.174191947378864
0.22497396079406903,0.0015064,270.4189069403077,46.484195061561834,-2.174191947378864
0.22592977156749044,0.0015128,270.46611445957075,46.484195061561834,-2.174191947378864
0.22963353831449848,0.0015375999999999999,270.6483126203087,46.484195061561834,-2.174191947378864
0.23154515986134136,0.0015504,270.74190174017946,46.484195061561834,-2.174191947378864
0.23560735564838242,0.0015776,270.9397839282129,46.484195061561834,-2.174191947378864
0.23596578468841548,0.00158,270.9571799864617,46.484195061561834,-2.174191947378864
0.2362047373817708,0.0015815999999999998,270.9687716336935,46.484195061561834,-2.174191947378864
0.24050588586216726,0.0016104,271.1766455608864,46.484195061561834,-2.174191947378864
0.24265646010236547,0.0016248,271.2800384545879,46.484195061561834,-2.174191947378864
0.2434927945291092,0.0016304,271.32015021404044,46.484195061561834,-2.174191947378864
0.24719656127611725,0.0016552,271.4971460505039,46.484195061561834,-2.174191947378864
0.251378233409836,0.0016832,271.6957416813805,46.484195061561834,-2.174191947378864
0.25245352052993514,0.0016903999999999999,271.74660035607224,46.484195061561834,-2.174191947378864
0.257710479783753,0.0017255999999999999,271.9940368349697,46.484195061561834,-2.174191947378864
0.25998053037062885,0.0017407999999999998,272.1002749904447,46.484195061561834,-2.174191947378864
0.2615337228774387,0.0017511999999999998,272.1727558940057,46.484195061561834,-2.174191947378864
0.2649985369310914,0.0017744,272.33384184391224,46.484195061561834,-2.174191947378864
0.27300345215849586,0.001828,272.7028971773313,46.484195061561834,-2.174191947378864
0.27921622218573516,0.0018696,272.98642676643965,46.484195061561834,-2.174191947378864
0.28100836738590035,0.0018816,273.0677555216,46.484195061561834,-2.174191947378864
0.28315894162609856,0.001896,273.1650834987364,46.484195061561834,-2.174191947378864
0.2845926577862307,0.0019056,273.22980870496826,46.484195061561834,-2.174191947378864
0.2894911880000155,0.0019383999999999998,273.44999994938405,46.484195061561834,-2.174191947378864
0.29283652570699054,0.0019608,273.5995400700398,46.484195061561834,-2.174191947378864
0.2940312891737673,0.0019687999999999997,273.6527856004977,46.484195061561834,-2.174191947378864
0.2972571505340646,0.0019904,273.79612872944296,46.484195061561834,-2.174191947378864
0.29833243765416373,0.0019976,273.843774787873,46.484195061561834,-2.174191947378864
0.2994077247742628,0.0020047999999999997,273.89135391774454,46.484195061561834,-2.174191947378864
0.3007219645877173,0.0020136,273.94941578371925,46.484195061561834,-2.174191947378864
0.303828349601337,0.0020344,274.08626094239577,46.484195061561834,-2.174191947378864
0.30454520768140303,0.0020391999999999997,274.1177629756711,46.484195061561834,-2.174191947378864
0.3086074034684441,0.0020664,274.2957312551172,46.484195061561834,-2.174191947378864
0.3123111702154522,0.0020912,274.45720179060055,46.484195061561834,-2.174191947378864
0.31350593368222895,0.0020992,274.5091295226822,46.484195061561834,-2.174191947378864
0.317209700429237,0.002124,274.66961718601806,46.484195061561834,-2.174191947378864
0.31888236928272445,0.0021352,274.74185576991306,46.484195061561834,-2.174191947378864
0.32043556178953436,0.0021456,274.80880224391194,46.484195061561834,-2.174191947378864
0.32174980160298877,0.0021544,274.8653504721009,46.484195061561834,-2.174191947378864
0.3250951393099638,0.0021768,275.008886431969,46.484195061561834,-2.174191947378864
0.3259314737367075,0.0021823999999999997,275.04468027298503,46.484195061561834,-2.174191947378864
0.32820152432358346,0.0021976,275.1416548782384,46.484195061561834,-2.174191947378864
0.32927681144368254,0.0022048,275.18749888411054,46.484195061561834,-2.174191947378864
0.3325026728039799,0.0022264,275.3246818598378,46.484195061561834,-2.174191947378864
0.33477272339085573,0.0022416,275.4209070484339,46.484195061561834,-2.174191947378864
0.3399102062979959,0.002276,275.63774512619614,46.484195061561834,-2.174191947378864
0.3422997332315495,0.0022919999999999998,275.73816418578167,46.484195061561834,-2.174191947378864
0.34313606765829324,0.0022976,275.77324621953494,46.484195061561834,-2.174191947378864
0.34337502035164863,0.0022992,275.7832635306701,46.484195061561834,-2.174191947378864
0.3457645472852022,0.0023152,275.88328756664026,46.484195061561834,-2.174191947378864
0.3485125032587888,0.0023336,275.9979825345953,46.484195061561834,-2.174191947378864
0.3524552226991522,0.0023599999999999997,276.16193073802606,46.484195061561834,-2.174191947378864
0.35364998616592896,0.002368,276.2114705951691,46.484195061561834,-2.174191947378864
0.3558005604061272,0.0023824,276.3004781653491,46.484195061561834,-2.174191947378864
0.3574732292596147,0.0023936,276.3695612971263,46.484195061561834,-2.174191947378864
0.3577121819529701,0.0023952,276.3794200149691,46.484195061561834,-2.174191947378864
0.35950432715313524,0.0024072,276.45327870577603,46.484195061561834,-2.174191947378864
0.36177437774001114,0.0024224,276.5466272363807,46.484195061561834,-2.174191947378864
0.36380547563353166,0.002436,276.6299561470161,46.484195061561834,-2.174191947378864
0.3647612864069531,0.0024424,276.6691069537797,46.484195061561834,-2.174191947378864
0.3688234821939942,0.0024695999999999997,276.83505349715267,46.484195061561834,-2.174191947378864
0.37109353278087004,0.0024847999999999997,276.9274778257037,46.484195061561834,-2.174191947378864
0.37228829624764687,0.0024928,276.9760336301647,46.484195061561834,-2.174191947378864
0.3764699683813656,0.0025207999999999997,277.14550242553025,46.484195061561834,-2.174191947378864
0.3769478737680763,0.0025239999999999998,277.16482343063734,46.484195061561834,-2.174191947378864
0.37874001896824155,0.002536,277.2371922734391,46.484195061561834,-2.174191947378864
0.3792179243549522,0.0025391999999999997,277.2564680606784,46.484195061561834,-2.174191947378864
0.3814879749418282,0.0025544,277.3478989857842,46.484195061561834,-2.174191947378864
0.3849527889954808,0.0025775999999999998,277.48704342576406,46.484195061561834,-2.174191947378864
0.3877007449690674,0.002596,277.5970523636463,46.484195061561834,-2.174191947378864
0.3912850353693978,0.00262,277.74008636173284,46.484195061561834,-2.174191947378864
0.3920018934494639,0.0026248,277.76863174311706,46.484195061561834,-2.174191947378864
0.3951082784630835,0.0026455999999999997,277.8920938869533,46.484195061561834,-2.174191947378864
0.3995289032901576,0.0026752,278.0671393197574,46.484195061561834,-2.174191947378864
0.4020379065703889,0.002692,278.1661533858289,46.484195061561834,-2.174191947378864
0.4078922475575951,0.0027312,278.3962537404701,46.484195061561834,-2.174191947378864
0.4096843927577603,0.0027432,278.46643465966434,46.484195061561834,-2.174191947378864
0.4111181089178924,0.0027527999999999997,278.5224932268594,46.484195061561834,-2.174191947378864
0.41243234873134693,0.0027616,278.57381330530677,46.484195061561834,-2.174191947378864
0.4192425004919746,0.0028071999999999997,278.8387299858689,46.484195061561834,-2.174191947378864
0.42222940915891655,0.0028271999999999998,278.9543914697225,46.484195061561834,-2.174191947378864
0.42641108129263533,0.0028552,279.11578289035526,46.484195061561834,-2.174191947378864
0.4296369426529326,0.0028767999999999997,279.23986345482206,46.484195061561834,-2.174191947378864
0.4303538007329987,0.0028816,279.26738750964637,46.484195061561834,-2.174191947378864
0.4333407093999407,0.0029016,279.3818791362185,46.484195061561834,-2.174191947378864
0.4353718072934612,0.0029151999999999997,279.4595576977391,46.484195061561834,-2.174191947378864
0.43847819230708085,0.002936,279.5780873925187,46.484195061561834,-2.174191947378864
0.43871714500043624,0.0029376,279.5871914741972,46.484195061561834,-2.174191947378864
0.44027033750724603,0.0029479999999999997,279.6463209372246,46.484195061561834,-2.174191947378864
0.4423014354007666,0.0029616,279.7235214750074,46.484195061561834,-2.174191947378864
0.4438546279075764,0.002972,279.7824639270928,46.484195061561834,-2.174191947378864
0.4481557763879728,0.0030007999999999996,279.94527084463664,46.484195061561834,-2.174191947378864
0.4524569248683693,0.0030296,280.1074695034921,46.484195061561834,-2.174191947378864
0.45508540449527823,0.0030472,280.20629491517667,46.484195061561834,-2.174191947378864
0.45639964430873264,0.0030559999999999997,280.25562412422914,46.484195061561834,-2.174191947378864
0.4581917895088979,0.003068,280.32280204204767,46.484195061561834,-2.174191947378864
0.4597449820157077,0.0030784,280.3809400564019,46.484195061561834,-2.174191947378864
0.46261241433597194,0.0030976,280.4880709256882,46.484195061561834,-2.174191947378864
0.46547984665623626,0.0031168,280.5949431323785,46.484195061561834,-2.174191947378864
0.46774989724311217,0.003132,280.67936831319804,46.484195061561834,-2.174191947378864
0.469303089749922,0.0031424,280.73704086281543,46.484195061561834,-2.174191947378864
0.47049785321669874,0.0031504,280.78135372284856,46.484195061561834,-2.174191947378864
0.47336528553696305,0.0031696,280.8875259171896,46.484195061561834,-2.174191947378864
0.4744405726570622,0.0031768,280.92727578675067,46.484195061561834,-2.174191947378864
0.47515743073712824,0.0031815999999999997,280.95375618199387,46.484195061561834,-2.174191947378864
0.4774274813240041,0.0031967999999999996,281.0375081634963,46.484195061561834,-2.174191947378864
0.4788611974841363,0.0032064,281.0903241417473,46.484195061561834,-2.174191947378864
0.48053386633762374,0.0032175999999999997,281.1518649006278,46.484195061561834,-2.174191947378864
0.4848350148180202,0.0032464,281.3097301733047,46.484195061561834,-2.174191947378864
0.48949459233844966,0.0032776,281.4801357930245,46.484195061561834,-2.174191947378864
0.49200359561868096,0.0032944,281.57163058094335,46.484195061561834,-2.174191947378864
0.49415416985887917,0.0033087999999999998,281.64990994803657,46.484195061561834,-2.174191947378864
0.49534893332565594,0.0033168,281.69334107253826,46.484195061561834,-2.174191947378864
0.49953060545937467,0.0033447999999999998,281.84502932654163,46.484195061561834,-2.174191947378864
0.5021590850862836,0.0033623999999999998,281.9401227999709,46.484195061561834,-2.174191947378864
0.5053849464465809,0.003384,282.05656352537613,46.484195061561834,-2.174191947378864
0.5092081895402667,0.0034096,282.1941926654163,46.484195061561834,-2.174191947378864
0.5115977164738202,0.0034256,282.2800062576451,46.484195061561834,-2.174191947378864
0.5130314326339523,0.0034352,282.3314193843885,46.484195061561834,-2.174191947378864
0.5148235778341176,0.0034471999999999997,282.39560706212376,46.484195061561834,-2.174191947378864
0.5170936284209935,0.0034624,282.4767864939341,46.484195061561834,-2.174191947378864
0.5176910101543818,0.0034663999999999997,282.4981263869313,46.484195061561834,-2.174191947378864
0.5190052499678364,0.0034752,282.54504037578204,46.484195061561834,-2.174191947378864
0.5205584424746461,0.0034855999999999997,282.6004244906335,46.484195061561834,-2.174191947378864
0.5230674457548774,0.0035023999999999997,282.6897551916257,46.484195061561834,-2.174191947378864
0.5289217867420837,0.0035415999999999998,282.89754612783236,46.484195061561834,-2.174191947378864
0.5301165502088605,0.0035496,282.9398420213026,46.484195061561834,-2.174191947378864
0.5311918373289596,0.0035567999999999997,282.9778765497806,46.484195061561834,-2.174191947378864
0.5341787459959015,0.0035767999999999998,283.08337079110646,46.484195061561834,-2.174191947378864
0.5365682729294551,0.0035927999999999997,283.16760063964267,46.484195061561834,-2.174191947378864
0.5382409417829426,0.003604,283.2264745119484,46.484195061561834,-2.174191947378864
0.5413473267965622,0.0036247999999999996,283.3356227429228,46.484195061561834,-2.174191947378864
0.5433784246900828,0.0036384,283.4068568504908,46.484195061561834,-2.174191947378864
0.5451705698902479,0.0036504,283.4696242827164,46.484195061561834,-2.174191947378864
0.5476795731704792,0.0036672,283.55736366486036,46.484195061561834,-2.174191947378864
0.552578103384264,0.0036999999999999997,283.728213878081,46.484195061561834,-2.174191947378864
0.555923441091239,0.0037224,283.84455277461035,46.484195061561834,-2.174191947378864
0.5567597755179828,0.003728,283.8735947980845,46.484195061561834,-2.174191947378864
0.5601051132249578,0.0037503999999999997,283.98959315671243,46.484195061561834,-2.174191947378864
0.562972545545222,0.0037695999999999997,284.08880542743856,46.484195061561834,-2.174191947378864
0.5658399778654863,0.0037887999999999997,284.1878208157511,46.484195061561834,-2.174191947378864
0.5661984069055194,0.0037911999999999998,284.20018396518105,46.484195061561834,-2.174191947378864
0.568946362879106,0.0038096,284.2948669165735,46.484195061561834,-2.174191947378864
0.5709774607726266,0.0038231999999999997,284.3647353783055,46.484195061561834,-2.174191947378864
0.5733669877061801,0.0038391999999999996,284.44680959320755,46.484195061561834,-2.174191947378864
0.5774291834932213,0.0038664,284.5860302685781,46.484195061561834,-2.174191947378864
0.5792213286933864,0.0038783999999999997,284.6473296684148,46.484195061561834,-2.174191947378864
0.5828056190937168,0.0039024,284.7697070113954,46.484195061561834,-2.174191947378864
0.5838809062138159,0.0039096,284.806362931165,46.484195061561834,-2.174191947378864
0.5860314804540141,0.0039239999999999995,284.87959588386167,46.484195061561834,-2.174191947378864
0.589018389120956,0.003944,284.98113468121875,46.484195061561834,-2.174191947378864
0.5935584902947078,0.0039743999999999995,285.13508990337914,46.484195061561834,-2.174191947378864
0.6748178932675053,0.004518503700740148,287.8173439820746,46.484195061561834,-2.174191947378864
0.7264419998535797,0.004864172834566914,289.4560283754064,46.484195061561834,-2.174191947378864
0.752254053146617,0.0050370074014802965,290.25828536512074,46.484195061561834,-2.174191947378864
0.7780661064396541,0.005209841968393679,291.0498755413509,46.484195061561834,-2.174191947378864
0.8440302426329713,0.005651530306061212,293.02764055847103,46.484195061561834,-2.174191947378864
0.9759585150196061,0.006534906981396279,296.8107545586077,46.484195061561834,-2.174191947378864
1.0017705683126432,0.006707741548309662,297.526990252444,46.484195061561834,-2.174191947378864
1.0419226512129234,0.006976595319063813,298.6269907407957,46.484195061561834,-2.174191947378864
1.1021507755633435,0.007379875975195039,300.2464820409813,46.484195061561834,-2.174191947378864
1.1709829176781092,0.007840768153630726,302.0556350928176,46.484195061561834,-2.174191947378864
1.1967949709711465,0.008013602720544109,302.7233114792411,46.484195061561834,-2.174191947378864
1.2770991367717068,0.00855131026205241,304.76548471308763,46.484195061561834,-2.174191947378864
1.3201192255934355,0.008839367873574715,305.83886976580123,46.484195061561834,-2.174191947378864
1.4090274091583415,0.009434686937387478,308.0148988315118,46.484195061561834,-2.174191947378864
1.4721235394302103,0.009857171434286858,309.52679712413493,46.484195061561834,-2.174191947378864
1.5466916933878734,0.010356471294258852,311.2813758750175,46.484195061561834,-2.174191947378864
1.5811077644452562,0.010586917383476696,312.08002247061614,46.484195061561834,-2.174191947378864
1.604051811816845,0.010740548109621925,312.60869004713385,46.484195061561834,-2.174191947378864
1.6413358887956762,0.01099019803960792,313.46152773012375,46.484195061561834,-2.174191947378864
1.7273760664391336,0.01156631326265253,315.4012866787672,46.484195061561834,-2.174191947378864
1.7617921374965166,0.011796759351870374,316.166593068126,46.484195061561834,-2.174191947378864
1.8965884158045998,0.012699339867973595,319.1095256325103,46.484195061561834,-2.174191947378864
1.9195324631761885,0.012852970594118824,319.6022120574897,46.484195061561834,-2.174191947378864
1.9338724927834314,0.012948989797959592,319.9089750406009,46.484195061561834,-2.174191947378864
1.9797605875266087,0.01325625125025005,320.8847079538374,46.484195061561834,-2.174191947378864
2.0055726408196457,0.013429085817163433,321.4296806756749,46.484195061561834,-2.174191947378864
2.0600647533271688,0.013793958791758352,322.5712763083515,46.484195061561834,-2.174191947378864
2.074404782934412,0.01388997799559912,322.86973111291087,46.484195061561834,-2.174191947378864
2.1088208539917948,0.014120424084816964,323.582758674528,46.484195061561834,-2.174191947378864
2.134632907284832,0.014293258651730346,324.11455481993096,46.484195061561834,-2.174191947378864
2.1719169842636634,0.014542908581716344,324.87829847252027,46.484195061561834,-2.174191947378864
2.223541090849738,0.01488857771554311,325.9274014543688,46.484195061561834,-2.174191947378864
2.2464851382213267,0.015042208441688338,326.3906157048457,46.484195061561834,-2.174191947378864
2.387017428372307,0.015983196639327867,329.18856175754945,46.484195061561834,-2.174191947378864
2.4042254639009983,0.01609841968393679,329.5266957107804,46.484195061561834,-2.174191947378864
2.427169511272587,0.016252050410082017,329.9760763925963,46.484195061561834,-2.174191947378864
2.52181370668039,0.016885777155431086,331.8125254196824,46.484195061561834,-2.174191947378864
2.6107218902452956,0.017481096219243847,333.5133354945625,46.484195061561834,-2.174191947378864
2.6336659376168843,0.017634726945389076,333.94856826182377,46.484195061561834,-2.174191947378864
2.670950014595716,0.017884376875375075,334.65268078759317,46.484195061561834,-2.174191947378864
2.7254421271032387,0.018249249849969992,335.6749118071414,46.484195061561834,-2.174191947378864
2.808614298825248,0.01880616123224645,337.2199231887126,46.484195061561834,-2.174191947378864
2.854502393568425,0.019113422684536908,338.0647014481803,46.484195061561834,-2.174191947378864
3.0093747133266486,0.020150430086017204,340.87751445149513,46.484195061561834,-2.174191947378864
3.0380547725411344,0.02034246849369874,341.39215035830426,46.484195061561834,-2.174191947378864
3.0782068554414144,0.02061132226445289,342.1094687801223,46.484195061561834,-2.174191947378864
3.12696295610604,0.0209377875575115,342.9756110445821,46.484195061561834,-2.174191947378864
3.1757190567706663,0.021264252850570115,343.8365020765944,46.484195061561834,-2.174191947378864
3.3191193528430953,0.022224444888977797,346.33914735765933,46.484195061561834,-2.174191947378864
3.3277233706074405,0.022282056411282256,346.48795085281415,46.484195061561834,-2.174191947378864
3.344931406136132,0.022397279455891178,346.7851084610692,46.484195061561834,-2.174191947378864
3.4281035778581415,0.022954190838167635,348.213049382626,46.484195061561834,-2.174191947378864
3.488331702208561,0.02335747149429886,349.2386540420388,46.484195061561834,-2.174191947378864
3.5600318502447754,0.0238375675135027,350.45065078389786,46.484195061561834,-2.174191947378864
3.637468010123887,0.02435607121424285,351.7489633950429,46.484195061561834,-2.174191947378864
3.6833561048670647,0.024663332666533307,352.5132477220429,46.484195061561834,-2.174191947378864
3.7235081877673446,0.024932186437287458,353.1789554466737,46.484195061561834,-2.174191947378864
3.77226428843197,0.02525865173034607,353.98356281614053,46.484195061561834,-2.174191947378864
3.864040477918325,0.025873174634926985,355.48719979060814,46.484195061561834,-2.174191947378864
3.878380507525568,0.025969193838767755,355.7208789667322,46.484195061561834,-2.174191947378864
3.938608631875988,0.02637247449489898,356.6986744674988,46.484195061561834,-2.174191947378864
3.9701566970119226,0.02658371674334867,357.2085248383364,46.484195061561834,-2.174191947378864
4.05619687465538,0.02715983196639328,358.5910576611541,46.484195061561834,-2.174191947378864
4.082008927948417,0.02733266653330666,359.0035810172682,46.484195061561834,-2.174191947378864
4.1164249990058,0.027563112622524505,359.5520331188175,46.484195061561834,-2.174191947378864
4.13650104045594,0.027697539507901582,359.8711376633811,46.484195061561834,-2.174191947378864
4.208201188492154,0.02817763552710542,361.005898908781,46.484195061561834,-2.174191947378864
4.297109372057061,0.028772954590918182,362.4025844323881,46.484195061561834,-2.174191947378864
4.325789431271546,0.02896499299859972,362.85071799371065,46.484195061561834,-2.174191947378864
4.443377674050938,0.02975235047009402,364.6760798726202,46.484195061561834,-2.174191947378864
4.549493893144535,0.030462892578515702,366.3072476521526,46.484195061561834,-2.174191947378864
4.589645976044816,0.030731746349269853,366.9205682290406,46.484195061561834,-2.174191947378864
4.62119404118075,0.030942988597719545,367.4009961740243,46.484195061561834,-2.174191947378864
4.664214130002478,0.031231046209241848,368.0540688751979,46.484195061561834,-2.174191947378864
4.733046272117244,0.03169193838767753,369.09411996581474,46.484195061561834,-2.174191947378864
4.758858325410282,0.03186477295459092,369.4826161935911,46.484195061561834,-2.174191947378864
4.827690467525048,0.03232566513302661,370.5146092886043,46.484195061561834,-2.174191947378864
4.853502520818084,0.03249849969993999,370.9001252332983,46.484195061561834,-2.174191947378864
4.882182580032571,0.03269053810762153,371.3275396995451,46.484195061561834,-2.174191947378864
4.907994633325608,0.03286337267453491,371.7113762125684,46.484195061561834,-2.174191947378864
4.968222757676028,0.033266653330666134,372.6039460832833,46.484195061561834,-2.174191947378864
4.973958769518926,0.033305061012202444,372.68873204858784,46.484195061561834,-2.174191947378864
5.045658917555139,0.03378515703140628,373.7453594963039,46.484195061561834,-2.174191947378864
5.100151030062662,0.0341500300060012,374.5444845189588,46.484195061561834,-2.174191947378864
5.16611516625598,0.03459171834366873,375.50740492789197,46.484195061561834,-2.174191947378864
5.329591503778548,0.03568633726745349,377.87333354563634,46.484195061561834,-2.174191947378864
5.375479598521726,0.03599359871974395,378.53234444210676,46.484195061561834,-2.174191947378864
5.415631681422006,0.0362624524904981,379.10718127903766,46.484195061561834,-2.174191947378864
5.461519776165184,0.03656971394278856,379.7621062978295,46.484195061561834,-2.174191947378864
5.510275876829811,0.036896179235847176,380.4556170647223,46.484195061561834,-2.174191947378864
5.553295965651539,0.037184236847369476,381.0655533642948,46.484195061561834,-2.174191947378864
5.593448048551819,0.03745309061812363,381.6331667554868,46.484195061561834,-2.174191947378864
5.639336143294996,0.03776035207041409,382.27992558201186,46.484195061561834,-2.174191947378864
5.794208463053218,0.038797359471894374,384.44774065301516,46.484195061561834,-2.174191947378864
5.814284504503359,0.03893178635727146,384.7270898308723,46.484195061561834,-2.174191947378864
5.857304593325087,0.03921984396879376,385.3244316427818,46.484195061561834,-2.174191947378864
5.885984652539572,0.03941188237647529,385.7217092140705,46.484195061561834,-2.174191947378864
6.0351209604549,0.04041048209641929,387.77550782128617,46.484195061561834,-2.174191947378864
6.055197001905039,0.04054490898179636,388.05046132309184,46.484195061561834,-2.174191947378864
6.1641812269200855,0.0412746549309862,389.5369081723459,46.484195061561834,-2.174191947378864
6.187125274291674,0.04142828565713143,389.84853433409654,46.484195061561834,-2.174191947378864
6.204333309820366,0.04154350870174035,390.08195827514834,46.484195061561834,-2.174191947378864
6.2444853927206445,0.041812362472494494,390.6256344319637,46.484195061561834,-2.174191947378864
6.290373487463822,0.04211962392478495,391.2453119529008,46.484195061561834,-2.174191947378864
6.379281671028729,0.04271494298859772,392.4409429757472,46.484195061561834,-2.174191947378864
6.407961730243215,0.042906981396279256,392.8252417619226,46.484195061561834,-2.174191947378864
6.430905777614803,0.043060612122424485,393.13219803372544,46.484195061561834,-2.174191947378864
6.531285984865503,0.043732746549309864,394.47014107138756,46.484195061561834,-2.174191947378864
6.557098038158539,0.04390558111622324,394.81288433636774,46.484195061561834,-2.174191947378864
6.617326162508962,0.04430886177235448,395.6105788274222,46.484195061561834,-2.174191947378864
6.654610239487793,0.04455851170234047,396.10297096197036,46.484195061561834,-2.174191947378864
6.709102351995316,0.04492338467693539,396.8206900435004,46.484195061561834,-2.174191947378864
6.754990446738494,0.04523064612922585,397.4233234318406,46.484195061561834,-2.174191947378864
6.806614553324567,0.045576315263052614,398.099380825928,46.484195061561834,-2.174191947378864
6.829558600696156,0.04572994598919784,398.3992085851252,46.484195061561834,-2.174191947378864
6.906994760575268,0.04624844968993799,399.4082395562631,46.484195061561834,-2.174191947378864
7.093415145469424,0.04749669933986797,401.8194617913695,46.484195061561834,-2.174191947378864
7.133567228369705,0.047765553110622125,402.33555266301875,46.484195061561834,-2.174191947378864
7.199531364563022,0.04820724144828965,403.1809635796316,46.484195061561834,-2.174191947378864
7.259759488913441,0.04861052210442088,403.95022591095886,46.484195061561834,-2.174191947378864
7.32572362510676,0.04905221044208842,404.7899011335174,46.484195061561834,-2.174191947378864
7.440443861964703,0.049820364072814566,406.2432160812809,46.484195061561834,-2.174191947378864
7.474859933022086,0.0500508101620324,406.6775030053368,46.484195061561834,-2.174191947378864
7.503539992236573,0.05024284856971395,407.03881339326574,46.484195061561834,-2.174191947378864
7.54942808697975,0.05055011002200441,407.6157917616322,46.484195061561834,-2.174191947378864
7.575240140272786,0.05072294458891778,407.9397409963752,46.484195061561834,-2.174191947378864
7.5981841876443745,0.05087657531506301,408.2273346447752,46.484195061561834,-2.174191947378864
7.695696388973626,0.05152950590118023,409.44584838309675,46.484195061561834,-2.174191947378864
7.773132548852738,0.05204800960192038,410.4092073982663,46.484195061561834,-2.174191947378864
7.839096685046056,0.05248969793958792,411.2268980575958,46.484195061561834,-2.174191947378864
7.884984779789233,0.05279695939187838,411.7941443610273,46.484195061561834,-2.174191947378864
7.930872874532411,0.05310422084416884,412.36010465070274,46.484195061561834,-2.174191947378864
7.95094891598255,0.05323864772954591,412.6073105310935,46.484195061561834,-2.174191947378864
8.002573022568624,0.05358431686337267,413.24186757731434,46.484195061561834,-2.174191947378864
8.01404504625442,0.05366113222644529,413.38266321872476,46.484195061561834,-2.174191947378864
8.062801146919044,0.053987597519503897,413.9801699013308,46.484195061561834,-2.174191947378864
8.194729419305679,0.05487097419483897,415.58992922266583,46.484195061561834,-2.174191947378864
8.223409478520164,0.0550630126025205,415.93853582462947,46.484195061561834,-2.174191947378864
8.246353525891752,0.05521664332866573,416.21707982947714,46.484195061561834,-2.174191947378864
8.266429567341895,0.05535107021404281,416.4605579883706,46.484195061561834,-2.174191947378864
8.409829863414323,0.05631126225245049,418.1930301066225,46.484195061561834,-2.174191947378864
8.478662005529088,0.05677215443088618,419.02052109591096,46.484195061561834,-2.174191947378864
8.547494147643855,0.057233046609321866,419.84539625108096,46.484195061561834,-2.174191947378864
8.624930307522966,0.057751550310062016,420.77029044080615,46.484195061561834,-2.174191947378864
8.63927033713021,0.05784756951390278,420.94121116530937,46.484195061561834,-2.174191947378864
8.685158431873386,0.05815483096619324,421.487415442274,46.484195061561834,-2.174191947378864
8.710970485166422,0.058327665533106615,421.79416072581773,46.484195061561834,-2.174191947378864
8.748254562145256,0.058577315463092625,422.2366121674151,46.484195061561834,-2.174191947378864
8.762594591752498,0.05867333466693339,422.40658990277564,46.484195061561834,-2.174191947378864
8.794142656888432,0.05888457691538308,422.7801595178442,46.484195061561834,-2.174191947378864
8.868710810846096,0.059383876775355074,423.66107071112157,46.484195061561834,-2.174191947378864
8.943278964803758,0.059883176635327065,424.53909797993776,46.484195061561834,-2.174191947378864
8.951882982568105,0.05994078815763153,424.6402247614999,46.484195061561834,-2.174191947378864
8.966223012175346,0.060036807361472294,424.8086852007434,46.484195061561834,-2.174191947378864
9.014979112839974,0.06036327265453091,425.38066636409604,46.484195061561834,-2.174191947378864
9.023583130604319,0.060420884176835374,425.481478852297,46.484195061561834,-2.174191947378864
9.126831343776468,0.0611122224444889,426.6883192408936,46.484195061561834,-2.174191947378864
9.169851432598195,0.0614002800560112,427.1895965831928,46.484195061561834,-2.174191947378864
9.238683574712962,0.061861172234446885,427.9897368197677,46.484195061561834,-2.174191947378864
9.264495628006,0.06203400680136027,428.2891895838348,46.484195061561834,-2.174191947378864
9.347667799728008,0.06259091818363673,429.25188704372687,46.484195061561834,-2.174191947378864
9.373479853021045,0.06276375275055011,429.54997521319814,46.484195061561834,-2.174191947378864
9.407895924078428,0.06299419883976795,429.9469285982418,46.484195061561834,-2.174191947378864
9.44804800697871,0.0632630526105221,430.4093258071087,46.484195061561834,-2.174191947378864
9.539824196465062,0.06387757551510302,431.46336547811944,46.484195061561834,-2.174191947378864
9.582844285286791,0.06416563312662532,431.9560845386328,46.484195061561834,-2.174191947378864
9.64880842148011,0.06460732146429286,432.70991492475633,46.484195061561834,-2.174191947378864
9.674620474773146,0.06478015603120624,433.0043445883852,46.484195061561834,-2.174191947378864
9.694696516223287,0.06491458291658332,433.23313368387534,46.484195061561834,-2.174191947378864
9.754924640573707,0.06531786357271455,433.91839488422573,46.484195061561834,-2.174191947378864
9.792208717552539,0.06556751350270054,434.3417773951735,46.484195061561834,-2.174191947378864
9.823756782688472,0.06577875575115023,434.6995333132812,46.484195061561834,-2.174191947378864
9.978629102446696,0.06681576315263053,436.44933224167863,46.484195061561834,-2.174191947378864
10.03025320903277,0.0671614322864573,437.03024067512644,46.484195061561834,-2.174191947378864
10.061801274168705,0.06737267453490699,437.3846662931262,46.484195061561834,-2.174191947378864
10.202333564319684,0.0683136627325465,438.9582354700468,46.484195061561834,-2.174191947378864
10.233881629455619,0.0685249049809962,439.3103211933574,46.484195061561834,-2.174191947378864
10.31131778933473,0.06904340868173635,440.17274174952837,46.484195061561834,-2.174191947378864
10.368677907763704,0.06942748549709943,440.8099442086021,46.484195061561834,-2.174191947378864
10.411697996585431,0.06971554310862173,441.2869442538566,46.484195061561834,-2.174191947378864
10.463322103171505,0.07006121224244849,441.8583308811549,46.484195061561834,-2.174191947378864
10.503474186071786,0.07033006601320264,442.301982927313,46.484195061561834,-2.174191947378864
10.626798440694074,0.07115583116623325,443.66051101463813,46.484195061561834,-2.174191947378864
10.69563058280884,0.07161672334466894,444.4160852933037,46.484195061561834,-2.174191947378864
10.724310642023326,0.07180876175235047,444.73034793868,46.484195061561834,-2.174191947378864
10.764462724923607,0.07207761552310463,445.1697655485443,46.484195061561834,-2.174191947378864
10.876314955860101,0.07282656531306261,446.39049959505064,46.484195061561834,-2.174191947378864
10.913599032838931,0.07307621524304861,446.796321639807,46.484195061561834,-2.174191947378864
10.993903198639494,0.07361392278455692,447.6685679885939,46.484195061561834,-2.174191947378864
11.022583257853979,0.07380596119223845,447.979481904401,46.484195061561834,-2.174191947378864
11.074207364440053,0.07415163032606521,448.538333055548,46.484195061561834,-2.174191947378864
11.122963465104679,0.07447809561912383,449.0652047363112,46.484195061561834,-2.174191947378864
11.151643524319164,0.07467013402680536,449.3747085211697,46.484195061561834,-2.174191947378864
11.211871648669584,0.07507341468293659,450.02365782582183,46.484195061561834,-2.174191947378864
11.2835717967058,0.07555351070214043,450.79444654189706,46.484195061561834,-2.174191947378864
11.326591885527527,0.07584156831366273,451.2560029388056,46.484195061561834,-2.174191947378864
11.478596199364302,0.07685937187437487,452.88138815348384,46.484195061561834,-2.174191947378864
11.550296347400517,0.07733946789357872,453.6451636426452,46.484195061561834,-2.174191947378864
11.587580424379349,0.07758911782356472,454.0415960105323,46.484195061561834,-2.174191947378864
11.62773250727963,0.07785797159431887,454.46796724842375,46.484195061561834,-2.174191947378864
11.6850926257086,0.07824204840968194,455.07607429877123,46.484195061561834,-2.174191947378864
11.794076850723647,0.07897179435887178,456.2282799364775,46.484195061561834,-2.174191947378864
11.943213158638974,0.07997039407881577,457.79827601758456,46.484195061561834,-2.174191947378864
12.014913306675187,0.0804504900980196,458.55035866113155,46.484195061561834,-2.174191947378864
12.03212134220388,0.08056571314262853,458.73059779548174,46.484195061561834,-2.174191947378864
12.046461371811121,0.0806617323464693,458.8807202920087,46.484195061561834,-2.174191947378864
12.115293513925888,0.08112262452490498,459.60034037329604,46.484195061561834,-2.174191947378864
12.184125656040653,0.08158351670334067,460.3183677069855,46.484195061561834,-2.174191947378864
12.258693809998316,0.08208281656331266,461.0944477665546,46.484195061561834,-2.174191947378864
12.3934900883064,0.08298539707941589,462.4927055463014,46.484195061561834,-2.174191947378864
12.41356612975654,0.08311982396479296,462.70044813756834,46.484195061561834,-2.174191947378864
12.465190236342613,0.08346549309861973,463.23404259849235,46.484195061561834,-2.174191947378864
12.55123041398607,0.08404160832166434,464.1214554645546,46.484195061561834,-2.174191947378864
12.559834431750417,0.0840992198439688,464.21006606462157,46.484195061561834,-2.174191947378864
12.61145853833649,0.08444488897779556,464.7412333688788,46.484195061561834,-2.174191947378864
12.660214639001119,0.08477135427085418,465.2421132960065,46.484195061561834,-2.174191947378864
12.697498715979949,0.08502100420084018,465.624631688053,46.484195061561834,-2.174191947378864
12.806482940994997,0.08575075015003002,466.74025868931966,46.484195061561834,-2.174191947378864
12.903995142324247,0.08640368073614724,467.7353165636987,46.484195061561834,-2.174191947378864
13.027319396946536,0.08722944588917785,468.98958240244343,46.484195061561834,-2.174191947378864
13.067471479846814,0.08749829965993199,469.39694763199526,46.484195061561834,-2.174191947378864
13.156379663411721,0.08809361872374476,470.2972374531525,46.484195061561834,-2.174191947378864
13.242419841055177,0.08866973394678936,471.16622921851973,46.484195061561834,-2.174191947378864
13.273967906191112,0.08888097619523905,471.48430745779336,46.484195061561834,-2.174191947378864
13.305515971327047,0.08909221844368874,471.80209100410804,46.484195061561834,-2.174191947378864
13.342800048305879,0.08934186837367473,472.17727476941195,46.484195061561834,-2.174191947378864
13.491936356221206,0.09034046809361873,473.67393912022436,46.484195061561834,-2.174191947378864
13.537824450964383,0.09064772954590919,474.13315136040165,46.484195061561834,-2.174191947378864
13.62386462860784,0.0912238447689538,474.9925414191911,46.484195061561834,-2.174191947378864
13.712772812172746,0.09181916383276656,475.87835705413767,46.484195061561834,-2.174191947378864
13.790208972051857,0.09233766753350671,476.6480504838692,46.484195061561834,-2.174191947378864
13.82462504310924,0.09256811362272455,476.9895952034035,46.484195061561834,-2.174191947378864
13.910665220752698,0.09314422884576916,477.84200943542,46.484195061561834,-2.174191947378864
13.942213285888633,0.09335547109421885,478.154045808454,46.484195061561834,-2.174191947378864
13.96515733326022,0.09350910182036408,478.38080842184837,46.484195061561834,-2.174191947378864
14.019649445767744,0.093873974794959,478.9187880948048,46.484195061561834,-2.174191947378864
14.056933522746576,0.094123624724945,479.286409662112,46.484195061561834,-2.174191947378864
14.18599378921176,0.09498779755951191,480.5560197534625,46.484195061561834,-2.174191947378864
14.257693937247977,0.09546789357871575,481.2594119970977,46.484195061561834,-2.174191947378864
14.277769978698116,0.09560232046409282,481.4561144395588,46.484195061561834,-2.174191947378864
14.294978014226809,0.09571754350870175,481.6246306946056,46.484195061561834,-2.174191947378864
14.315054055676947,0.09585197039407882,481.82113303337974,46.484195061561834,-2.174191947378864
14.412566257006198,0.09650490098019604,482.7740483850531,46.484195061561834,-2.174191947378864
14.44985033398503,0.09675455091018204,483.13773346708894,46.484195061561834,-2.174191947378864
14.512946464256899,0.09717703540708142,483.75236790756674,46.484195061561834,-2.174191947378864
14.55309854715718,0.09744588917783557,484.14295637136115,46.484195061561834,-2.174191947378864
14.604722653743254,0.09779155831166234,484.6445245439395,46.484195061561834,-2.174191947378864
14.69363083730816,0.09838687737547509,485.50671859159496,46.484195061561834,-2.174191947378864
14.77680300903017,0.09894378875775156,486.31144709225316,46.484195061561834,-2.174191947378864
14.828427115616243,0.09928945789157832,486.81004534368833,46.484195061561834,-2.174191947378864
14.851371162987832,0.09944308861772355,487.03142721834456,46.484195061561834,-2.174191947378864
14.862843186673626,0.09951990398079616,487.14206813308806,46.484195061561834,-2.174191947378864
14.902995269573905,0.09978875775155031,487.52904932586733,46.484195061561834,-2.174191947378864