File: datasets/aisi_316_L/data/M1/train_72.csv
Time(s),Strain(%),Stress(MPa),Temp(C),Log_SR(s-1)
0.0,0.0,0.0,244.50573112094486,-1.8857892219939316
0.001045509853847745,1.3599999999999999e-05,2.4792221999999997,244.50573112094486,-1.8857892219939316
0.001414513331676361,1.84e-05,3.3542418,244.50573112094486,-1.8857892219939316
0.003136529561543235,4.0799999999999996e-05,7.437666599999999,244.50573112094486,-1.8857892219939316
0.004305040574667186,5.6e-05,10.208562,244.50573112094486,-1.8857892219939316
0.005043047530324417,6.56e-05,11.958601199999999,244.50573112094486,-1.8857892219939316
0.00836407883078196,0.00010879999999999999,19.833777599999998,244.50573112094486,-1.8857892219939316
0.011008603755220373,0.00014319999999999998,26.104751399999998,244.50573112094486,-1.8857892219939316
0.013161124042553967,0.0001712,31.209032399999998,244.50573112094486,-1.8857892219939316
0.014391135635316021,0.0001872,34.1257644,244.50573112094486,-1.8857892219939316
0.01488314027242084,0.0001936,35.2924572,244.50573112094486,-1.8857892219939316
0.015682647807716176,0.000204,37.188333,244.50573112094486,-1.8857892219939316
0.016912659400478227,0.00021999999999999998,40.105064999999996,244.50573112094486,-1.8857892219939316
0.01968018548419285,0.000256,46.667711999999995,244.50573112094486,-1.8857892219939316
0.02127920055478352,0.0002768,50.4594636,244.50573112094486,-1.8857892219939316
0.02195570693080265,0.0002856,52.0636662,244.50573112094486,-1.8857892219939316
0.02343172084211711,0.0003048,55.5637446,244.50573112094486,-1.8857892219939316
0.02484623417379347,0.0003232,58.9179864,244.50573112094486,-1.8857892219939316
0.025645741709088805,0.0003336,60.813862199999996,244.50573112094486,-1.8857892219939316
0.026568250403660346,0.0003456,63.0014112,244.50573112094486,-1.8857892219939316
0.027736761416784297,0.0003608,65.7723066,244.50573112094486,-1.8857892219939316
0.02829026663352722,0.000368,67.084836,244.50573112094486,-1.8857892219939316
0.030012282863394094,0.0003904,71.1682608,244.50573112094486,-1.8857892219939316
0.03093479155796563,0.00040239999999999997,73.35580979999999,244.50573112094486,-1.8857892219939316
0.032164803150727686,0.0004184,76.2725418,244.50573112094486,-1.8857892219939316
0.03345631532312784,0.00043519999999999995,79.33511039999999,244.50573112094486,-1.8857892219939316
0.03517833155299471,0.00045759999999999996,83.4185352,244.50573112094486,-1.8857892219939316
0.03690034778286159,0.00047999999999999996,87.50196,244.50573112094486,-1.8857892219939316
0.03763835473851882,0.0004896,89.2519992,244.50573112094486,-1.8857892219939316
0.03892986691091897,0.0005064,92.31456779999999,244.50573112094486,-1.8857892219939316
0.03985237560549052,0.0005184,94.50211680000001,244.50573112094486,-1.8857892219939316
0.04225089821137652,0.0005496,100.1897442,244.50573112094486,-1.8857892219939316
0.04298890516703375,0.0005591999999999999,101.93978339999998,244.50573112094486,-1.8857892219939316
0.04354241038377668,0.0005664,103.2523128,244.50573112094486,-1.8857892219939316
0.04458792023762442,0.00058,105.731535,244.50573112094486,-1.8857892219939316
0.0463099364674913,0.0006024,109.8149598,244.50573112094486,-1.8857892219939316
0.047908951538081966,0.0006232,113.6067114,244.50573112094486,-1.8857892219939316
0.04895446139192971,0.0006368,116.08593359999999,244.50573112094486,-1.8857892219939316
0.050553476462520376,0.0006575999999999999,119.87768519999999,244.50573112094486,-1.8857892219939316
0.051783488055282434,0.0006736,122.7944172,244.50573112094486,-1.8857892219939316
0.05252149501093967,0.0006832,124.5444564,244.50573112094486,-1.8857892219939316
0.05375150660370172,0.0006992,127.4611884,244.50573112094486,-1.8857892219939316
0.05590402689103531,0.0007272,132.5654694,244.50573112094486,-1.8857892219939316
0.05639603152814013,0.0007335999999999999,133.73216219999998,244.50573112094486,-1.8857892219939316
0.05750304196162598,0.000748,136.35722099999998,244.50573112094486,-1.8857892219939316
0.05842555065619751,0.0007599999999999999,138.54477,244.50573112094486,-1.8857892219939316
0.05873305355438803,0.0007639999999999999,139.27395299999998,244.50573112094486,-1.8857892219939316
0.05977856340823577,0.0007775999999999999,141.7531752,244.50573112094486,-1.8857892219939316
0.06186958311593126,0.0008047999999999999,146.71161959999998,244.50573112094486,-1.8857892219939316
0.06346859818652194,0.0008256,150.5033712,244.50573112094486,-1.8857892219939316
0.06432960630145537,0.0008368,152.5450836,244.50573112094486,-1.8857892219939316
0.06580562021276984,0.000856,156.045162,244.50573112094486,-1.8857892219939316
0.06654362716842707,0.0008656,157.7952012,244.50573112094486,-1.8857892219939316
0.06697413122589378,0.0008711999999999999,158.81605739999998,244.50573112094486,-1.8857892219939316
0.06814264223901774,0.0008864,161.5869528,244.50573112094486,-1.8857892219939316
0.06857314629648446,0.000892,162.607809,244.50573112094486,-1.8857892219939316
0.06918815209286548,0.0009,164.066175,244.50573112094486,-1.8857892219939316
0.07004916020779892,0.0009111999999999999,166.10788739999998,244.50573112094486,-1.8857892219939316
0.07177117643766578,0.0009335999999999999,170.1913122,244.50573112094486,-1.8857892219939316
0.07263218455259923,0.0009448,172.2330246,244.50573112094486,-1.8857892219939316
0.07330869092861836,0.0009536,173.8372272,244.50573112094486,-1.8857892219939316
0.07460020310101852,0.0009704,176.8997958,244.50573112094486,-1.8857892219939316
0.07681422396799022,0.0009992,182.1499134,244.50573112094486,-1.8857892219939316
0.07724472802545693,0.0010048,183.17076959999997,244.50573112094486,-1.8857892219939316
0.08019675584808586,0.0010432,187.87461511364626,244.50573112094486,-1.8857892219939316
0.08031975700736206,0.0010448,187.8842127439051,244.50573112094486,-1.8857892219939316
0.0813652668612098,0.0010584,187.96556245740155,244.50573112094486,-1.8857892219939316
0.08161126917976222,0.0010616,187.98464419784457,244.50573112094486,-1.8857892219939316
0.08253377787433375,0.0010735999999999999,188.05600181658727,244.50573112094486,-1.8857892219939316
0.0833947859892672,0.0010848,188.12232212356432,244.50573112094486,-1.8857892219939316
0.08382529004673392,0.0010904,188.15538209723425,244.50573112094486,-1.8857892219939316
0.08517830279877217,0.001108,188.2588563898143,244.50573112094486,-1.8857892219939316
0.08634681381189613,0.0011232,188.34770574814794,244.50573112094486,-1.8857892219939316
0.08739232366574386,0.0011367999999999999,188.42680583133134,244.50573112094486,-1.8857892219939316
0.0904058520680109,0.001176,188.65276105811535,244.50573112094486,-1.8857892219939316
0.0907133549662014,0.0011799999999999998,188.67565131386462,244.50573112094486,-1.8857892219939316
0.09145136192185864,0.0011895999999999999,188.73046481124675,244.50573112094486,-1.8857892219939316
0.09231237003679207,0.0012008,188.79419632881635,244.50573112094486,-1.8857892219939316
0.09317337815172552,0.001212,188.85769643534718,244.50573112094486,-1.8857892219939316
0.09514139670014479,0.0012376,189.00198636960448,244.50573112094486,-1.8857892219939316
0.09587940365580203,0.0012472,189.05579439561754,244.50573112094486,-1.8857892219939316
0.09624840713363064,0.0012519999999999999,189.08263781827412,244.50573112094486,-1.8857892219939316
0.09674041177073547,0.0012584,189.11836669724008,244.50573112094486,-1.8857892219939316
0.09753991930603081,0.0012688,189.17627534942844,244.50573112094486,-1.8857892219939316
0.09784742220422131,0.0012728,189.1984985794762,244.50573112094486,-1.8857892219939316
0.09840092742096423,0.0012799999999999999,189.238431875922,244.50573112094486,-1.8857892219939316
0.10098395176576454,0.0013135999999999998,189.42364109320582,244.50573112094486,-1.8857892219939316
0.10338247437165056,0.0013448,189.5939733784951,244.50573112094486,-1.8857892219939316
0.10535049292006984,0.0013704,189.73258499997712,244.50573112094486,-1.8857892219939316
0.1089790271187179,0.0014176,189.9855310886183,244.50573112094486,-1.8857892219939316
0.10990153581328943,0.0014295999999999998,190.04931304481806,244.50573112094486,-1.8857892219939316
0.11051654160967046,0.0014376,190.09171838771243,244.50573112094486,-1.8857892219939316
0.11230005841917544,0.0014608,190.2141765269326,244.50573112094486,-1.8857892219939316
0.11328406769338509,0.0014736,190.2814148828879,244.50573112094486,-1.8857892219939316
0.11383757291012801,0.0014808,190.31913635270882,244.50573112094486,-1.8857892219939316
0.11402207464904231,0.0014831999999999998,190.33169427154638,244.50573112094486,-1.8857892219939316
0.1159285926178235,0.001508,190.4609987461534,244.50573112094486,-1.8857892219939316
0.11820411406443329,0.0015375999999999999,190.61424924710778,244.50573112094486,-1.8857892219939316
0.11961862739610965,0.0015559999999999999,190.70893335491567,244.50573112094486,-1.8857892219939316
0.12011063203321448,0.0015624,190.74176446980792,244.50573112094486,-1.8857892219939316
0.1209716401481479,0.0015735999999999999,190.79909299431404,244.50573112094486,-1.8857892219939316
0.12386216739113874,0.0016112,190.99039969083054,244.50573112094486,-1.8857892219939316
0.12558418362100562,0.0016336,191.10354211939537,244.50573112094486,-1.8857892219939316
0.12675269463412955,0.0016488,191.1799729615676,244.50573112094486,-1.8857892219939316
0.12804420680652973,0.0016656,191.26413016069802,244.50573112094486,-1.8857892219939316
0.13044272941241572,0.0016967999999999998,191.4195489844341,244.50573112094486,-1.8857892219939316
0.13093473404952055,0.0017032,191.45129156551027,244.50573112094486,-1.8857892219939316
0.1317342415848159,0.0017136,191.50277422542922,244.50573112094486,-1.8857892219939316
0.13400976303142567,0.0017431999999999999,191.64863903573476,244.50573112094486,-1.8857892219939316
0.1347477699870829,0.0017527999999999999,191.69573867444018,244.50573112094486,-1.8857892219939316
0.1374537954911594,0.0017879999999999999,191.867583278184,244.50573112094486,-1.8857892219939316
0.13954481519885492,0.0018151999999999999,191.99947015331588,244.50573112094486,-1.8857892219939316
0.14034432273415023,0.0018256,192.04969351756145,244.50573112094486,-1.8857892219939316
0.14071332621197885,0.0018303999999999998,192.07283588550536,244.50573112094486,-1.8857892219939316
0.1413283320083599,0.0018384,192.1113539717408,244.50573112094486,-1.8857892219939316
0.1416358349065504,0.0018424,192.13058849710083,244.50573112094486,-1.8857892219939316
0.14464936330881745,0.0018816,192.31823286984286,244.50573112094486,-1.8857892219939316
0.14563337258302708,0.0018943999999999999,192.37917348702948,244.50573112094486,-1.8857892219939316
0.14790889402963686,0.001924,192.51948690917055,244.50573112094486,-1.8857892219939316
0.1484623992463798,0.0019311999999999999,192.55348959629146,244.50573112094486,-1.8857892219939316
0.15030741663552286,0.0019552,192.6664765023018,244.50573112094486,-1.8857892219939316
0.1507379206929896,0.0019608,192.69276213064143,244.50573112094486,-1.8857892219939316
0.15166042938756114,0.0019728,192.74899009193723,244.50573112094486,-1.8857892219939316
0.1555349659047616,0.0020231999999999997,192.98370557772142,244.50573112094486,-1.8857892219939316
0.15645747459933315,0.0020352,193.03925276850458,244.50573112094486,-1.8857892219939316
0.1575029844531809,0.0020488,193.10205206948496,244.50573112094486,-1.8857892219939316
0.15916350010340966,0.0020704,193.20145901044742,244.50573112094486,-1.8857892219939316
0.15940950242196208,0.0020736,193.2161514936424,244.50573112094486,-1.8857892219939316
0.16131602039074325,0.0020984,193.32971994210368,244.50573112094486,-1.8857892219939316
0.16150052212965757,0.0021008,193.3406825832585,244.50573112094486,-1.8857892219939316
0.1626075325631434,0.0021152,193.40635615206048,244.50573112094486,-1.8857892219939316
0.16322253835952444,0.0021232,193.442766117942,244.50573112094486,-1.8857892219939316
0.16365304241699113,0.0021287999999999997,193.46822126600125,244.50573112094486,-1.8857892219939316
0.16451405053192458,0.00214,193.51905335172188,244.50573112094486,-1.8857892219939316
0.1646985522708389,0.0021424,193.5299324308694,244.50573112094486,-1.8857892219939316
0.1654365592264961,0.002152,193.57340130166816,244.50573112094486,-1.8857892219939316
0.1667895719785344,0.0021696,193.65289831994238,244.50573112094486,-1.8857892219939316
0.16838858704912504,0.0021904,193.74652581393673,244.50573112094486,-1.8857892219939316
0.16931109574369657,0.0022023999999999998,193.800383945522,244.50573112094486,-1.8857892219939316
0.16974159980116332,0.002208,193.82547856302287,244.50573112094486,-1.8857892219939316
0.17097161139392536,0.002224,193.897041061213,244.50573112094486,-1.8857892219939316
0.17183261950885878,0.0022351999999999997,193.9470153890307,244.50573112094486,-1.8857892219939316
0.1723246241459636,0.0022416,193.97552829987717,244.50573112094486,-1.8857892219939316
0.17324713284053514,0.0022535999999999997,194.02890458080495,244.50573112094486,-1.8857892219939316
0.1736776368980019,0.0022592,194.05377556753393,244.50573112094486,-1.8857892219939316
0.17496914907040204,0.002276,194.12824466821755,244.50573112094486,-1.8857892219939316
0.17656816414099272,0.0022968,194.2201481549026,244.50573112094486,-1.8857892219939316
0.18007369718036453,0.0023423999999999997,194.42050063769614,244.50573112094486,-1.8857892219939316
0.18056570181746937,0.0023488,194.44849807038605,244.50573112094486,-1.8857892219939316
0.1816112116713171,0.0023623999999999997,194.5078940208535,244.50573112094486,-1.8857892219939316
0.18314872616226968,0.0023824,194.59499932663888,244.50573112094486,-1.8857892219939316
0.1851782452903271,0.0024088,194.70954290418675,244.50573112094486,-1.8857892219939316
0.18610075398489861,0.0024208,194.76144621205896,244.50573112094486,-1.8857892219939316
0.18646975746272723,0.0024256,194.78217942786648,244.50573112094486,-1.8857892219939316
0.18683876094055588,0.0024304,194.80289664860604,244.50573112094486,-1.8857892219939316
0.1880687725333179,0.0024464,194.87183909315783,244.50573112094486,-1.8857892219939316
0.18911428238716566,0.00246,194.9303020209576,244.50573112094486,-1.8857892219939316
0.19182030789124216,0.0024952,195.08103548586914,244.50573112094486,-1.8857892219939316
0.19415732991749007,0.0025256,195.21054822385693,244.50573112094486,-1.8857892219939316
0.195325840930614,0.0025407999999999997,195.27507649774716,244.50573112094486,-1.8857892219939316
0.19655585252337607,0.0025567999999999997,195.34283856195717,244.50573112094486,-1.8857892219939316
0.19692485600120468,0.0025616,195.3631349065226,244.50573112094486,-1.8857892219939316
0.19827786875324294,0.0025792,195.4374282756648,244.50573112094486,-1.8857892219939316
0.20036888846093845,0.0026064,195.55185758336012,244.50573112094486,-1.8857892219939316
0.2022754064297196,0.0026311999999999998,195.65578493367227,244.50573112094486,-1.8857892219939316
0.20289041222610066,0.0026392,195.68922829987264,244.50573112094486,-1.8857892219939316
0.20485843077451993,0.0026647999999999997,195.79598236226752,244.50573112094486,-1.8857892219939316
0.20781045859714883,0.0027032,195.95536655852038,244.50573112094486,-1.8857892219939316
0.20842546439352988,0.0027112,195.98846018367158,244.50573112094486,-1.8857892219939316
0.21193099743290172,0.0027568,196.17637168244477,244.50573112094486,-1.8857892219939316
0.2142680194591496,0.0027871999999999997,196.3009729926888,244.50573112094486,-1.8857892219939316
0.2154365304722736,0.0028024,196.36307480802188,244.50573112094486,-1.8857892219939316
0.21629753858720702,0.0028136,196.4087500137578,244.50573112094486,-1.8857892219939316
0.21648204032612134,0.002816,196.418528326227,244.50573112094486,-1.8857892219939316
0.2184500588745406,0.0028415999999999997,196.52262889387183,244.50573112094486,-1.8857892219939316
0.22078708090078852,0.002872,196.64577445493842,244.50573112094486,-1.8857892219939316
0.2211560843786171,0.0028767999999999997,196.66517192360203,244.50573112094486,-1.8857892219939316
0.22250909713065536,0.0028943999999999997,196.73618824071585,244.50573112094486,-1.8857892219939316
0.2227550994492078,0.0028975999999999997,196.7490821840338,244.50573112094486,-1.8857892219939316
0.22330860466595073,0.0029048,196.77807326907453,244.50573112094486,-1.8857892219939316
0.22460011683835088,0.0029216,196.8456103668879,244.50573112094486,-1.8857892219939316
0.22687563828496066,0.0029511999999999997,196.96423693809734,244.50573112094486,-1.8857892219939316
0.22822865103699894,0.0029687999999999997,197.0345516903917,244.50573112094486,-1.8857892219939316
0.2298276661075896,0.0029896,197.11744169234186,244.50573112094486,-1.8857892219939316
0.23111917827998976,0.0030064,197.18422723490227,244.50573112094486,-1.8857892219939316
0.23265669277094234,0.0030264,197.2635443568442,244.50573112094486,-1.8857892219939316
0.23351770088587576,0.0030375999999999997,197.3078726463543,244.50573112094486,-1.8857892219939316
0.2348092130582759,0.0030543999999999997,197.37424574960113,244.50573112094486,-1.8857892219939316
0.23505521537682833,0.0030575999999999997,197.3868720868887,244.50573112094486,-1.8857892219939316
0.2367157310270571,0.0030792,197.4719654662195,244.50573112094486,-1.8857892219939316
0.2375767391419905,0.0030903999999999997,197.5159962910377,244.50573112094486,-1.8857892219939316
0.23997526174787656,0.0031216,197.6383266419845,244.50573112094486,-1.8857892219939316
0.24157427681846722,0.0031424,197.71961539990312,244.50573112094486,-1.8857892219939316
0.24268128725195307,0.0031568,197.7757693477494,244.50573112094486,-1.8857892219939316
0.2433577936279722,0.0031655999999999998,197.81003647382576,244.50573112094486,-1.8857892219939316
0.24477230695964855,0.0031839999999999998,197.88156610264636,244.50573112094486,-1.8857892219939316
0.2461868202913249,0.0032023999999999998,197.95293470067836,244.50573112094486,-1.8857892219939316
0.2463713220302392,0.0032048,197.96223184387088,244.50573112094486,-1.8857892219939316
0.24698632782662025,0.0032128,197.99320272909333,244.50573112094486,-1.8857892219939316
0.24717082956553454,0.0032151999999999997,198.00248812788755,244.50573112094486,-1.8857892219939316
0.24766283420263938,0.0032216,198.02723598552083,244.50573112094486,-1.8857892219939316
0.2488928457954014,0.0032375999999999998,198.08902189162356,244.50573112094486,-1.8857892219939316
0.2497538539103349,0.0032488,198.13220119070672,244.50573112094486,-1.8857892219939316
0.2513528689809255,0.0032695999999999997,198.2122376087239,244.50573112094486,-1.8857892219939316
0.25227537767549707,0.0032816,198.25832213687406,244.50573112094486,-1.8857892219939316
0.2527673823126019,0.0032879999999999997,198.28287367648198,244.50573112094486,-1.8857892219939316
0.2555349083963165,0.0033239999999999997,198.42063038473884,244.50573112094486,-1.8857892219939316
0.255842411294507,0.003328,198.43590068349343,244.50573112094486,-1.8857892219939316
0.25608841361305945,0.0033312,198.44811176940397,244.50573112094486,-1.8857892219939316
0.2584869362189454,0.0033623999999999998,198.56693108428118,244.50573112094486,-1.8857892219939316
0.2592249431746027,0.003372,198.60340426518033,244.50573112094486,-1.8857892219939316
0.2618694680990411,0.0034064,198.73376858706064,244.50573112094486,-1.8857892219939316
0.26316098027144125,0.0034232,198.79724819950488,244.50573112094486,-1.8857892219939316
0.2635299837492699,0.003428,198.81536290038014,244.50573112094486,-1.8857892219939316
0.26414498954565085,0.003436,198.84553210115612,244.50573112094486,-1.8857892219939316
0.26592850635515586,0.0034592,198.9328682530993,244.50573112094486,-1.8857892219939316
0.2668510150497274,0.0034712,198.97795246977083,244.50573112094486,-1.8857892219939316
0.26857303127959425,0.0034936,199.06194737664805,244.50573112094486,-1.8857892219939316
0.27023354692982304,0.0035152,199.1427437738836,244.50573112094486,-1.8857892219939316
0.27257056895607096,0.0035456,199.25612997062166,244.50573112094486,-1.8857892219939316
0.27416958402666164,0.0035664,199.33349163256784,244.50573112094486,-1.8857892219939316
0.2749075909823188,0.0035759999999999998,199.3691376471429,244.50573112094486,-1.8857892219939316
0.2765066060529095,0.0035968,199.4462428999948,244.50573112094486,-1.8857892219939316
0.27681410895110004,0.0036008,199.46105087592073,244.50573112094486,-1.8857892219939316
0.2776751170660335,0.0036119999999999998,199.5024791177153,244.50573112094486,-1.8857892219939316
0.279212631556986,0.003632,199.5763337269593,244.50573112094486,-1.8857892219939316
0.2799506385126433,0.0036416,199.6117275872334,244.50573112094486,-1.8857892219939316
0.2804426431497481,0.0036479999999999998,199.6353032800487,244.50573112094486,-1.8857892219939316
0.28068864546830047,0.0036512,199.64708507703875,244.50573112094486,-1.8857892219939316
0.2814266524239577,0.0036607999999999996,199.6824063292303,244.50573112094486,-1.8857892219939316
0.2825336628574436,0.0036752,199.7353205505656,244.50573112094486,-1.8857892219939316
0.28456318198550096,0.0037015999999999998,199.83212042814588,244.50573112094486,-1.8857892219939316
0.28554719125971056,0.0037143999999999996,199.87895675169247,244.50573112094486,-1.8857892219939316
0.285793193578263,0.0037175999999999997,199.89065599207282,244.50573112094486,-1.8857892219939316
0.28628519821536785,0.003724,199.91404269718186,244.50573112094486,-1.8857892219939316
0.287576710387768,0.0037408,199.97535834115288,244.50573112094486,-1.8857892219939316
0.28837621792306334,0.0037511999999999997,200.01326183005196,244.50573112094486,-1.8857892219939316
0.2904057370511207,0.0037776,200.1092947789334,244.50573112094486,-1.8857892219939316
0.29065173936967315,0.0037808,200.1209173239664,244.50573112094486,-1.8857892219939316
0.2924967567588162,0.0038047999999999997,200.2079644547934,244.50573112094486,-1.8857892219939316
0.2963097926963786,0.0038544,200.38718619679193,244.50573112094486,-1.8857892219939316
0.29766280544841683,0.003872,200.45056450909857,244.50573112094486,-1.8857892219939316
0.2990158182004551,0.0038896,200.51383056800725,244.50573112094486,-1.8857892219939316
0.29926182051900746,0.0038927999999999996,200.52532148276686,244.50573112094486,-1.8857892219939316
0.30012282863394096,0.003904,200.56551070597962,244.50573112094486,-1.8857892219939316
0.3017218437045316,0.0039248,200.64002873968474,244.50573112094486,-1.8857892219939316
0.3041818668900557,0.0039568,200.7543718272516,244.50573112094486,-1.8857892219939316
0.30442786920860815,0.00396,200.76578626474435,244.50573112094486,-1.8857892219939316
0.30565788080137013,0.0039759999999999995,200.82280458214836,244.50573112094486,-1.8857892219939316
0.3062113860181131,0.0039832,200.84843362325992,244.50573112094486,-1.8857892219939316
0.3065188889163036,0.0039872,200.86266417234424,244.50573112094486,-1.8857892219939316
0.306764891234856,0.0039904,200.87404460325638,244.50573112094486,-1.8857892219939316
0.31488444405625876,0.004096019203840768,201.24769336545188,244.50573112094486,-1.8857892219939316
0.33850539082664427,0.0044032806561312265,202.31389380635943,244.50573112094486,-1.8857892219939316
0.37836573850166977,0.004921784356871375,204.04948718099772,244.50573112094486,-1.8857892219939316
0.4019866852720553,0.005229045809161833,205.0443136597437,244.50573112094486,-1.8857892219939316
0.4654679797174663,0.0060548109621924385,207.61085078509834,244.50573112094486,-1.8857892219939316
0.5112335640850881,0.006650130026005201,209.37699262205183,244.50573112094486,-1.8857892219939316
0.5437123658943682,0.007072614522904581,210.59313634450393,244.50573112094486,-1.8857892219939316
0.5540465301064118,0.007207041408281656,210.97410443056052,244.50573112094486,-1.8857892219939316
0.5702859310110518,0.007418283656731346,211.56721643522874,244.50573112094486,-1.8857892219939316
0.5968594961277356,0.007763952790558111,212.52374711698135,244.50573112094486,-1.8857892219939316
0.6057173511666302,0.007879175835167033,212.83888032268354,244.50573112094486,-1.8857892219939316
0.6396724621490593,0.008320864172834567,214.0305962306111,244.50573112094486,-1.8857892219939316
0.6765801914777867,0.008800960192038408,215.29828707013758,244.50573112094486,-1.8857892219939316
0.682485428170383,0.008877775555111022,215.49858744447118,244.50573112094486,-1.8857892219939316
0.6928195923824266,0.009012202440488098,215.84749424108773,244.50573112094486,-1.8857892219939316
0.7371088675768995,0.009588317663532707,217.32038699142183,244.50573112094486,-1.8857892219939316
0.7474430317889431,0.009722744548909782,217.65904592489096,244.50573112094486,-1.8857892219939316
0.775492906078776,0.010087617523504702,218.56918104025843,244.50573112094486,-1.8857892219939316
0.7873033794639687,0.01024124824964993,218.9485441517122,244.50573112094486,-1.8857892219939316
0.8138769445806524,0.010586917383476696,219.7940885436479,244.50573112094486,-1.8857892219939316
0.8522609830825288,0.01108621724344869,220.99666224318912,244.50573112094486,-1.8857892219939316
0.8788345481992125,0.011431886377275456,221.81686522440685,244.50573112094486,-1.8857892219939316
0.8847397848918089,0.01150870174034807,221.99781233650256,244.50573112094486,-1.8857892219939316
0.8995028766232999,0.011700740148029607,222.44813152489692,244.50573112094486,-1.8857892219939316
0.9290290600862816,0.012084816963392678,223.3402140420272,244.50573112094486,-1.8857892219939316
0.9615078618955617,0.012507301460292058,224.3088282702125,244.50573112094486,-1.8857892219939316
1.058944267323402,0.013774754950990198,227.14084048315414,244.50573112094486,-1.8857892219939316
1.076659977401191,0.014005201040208042,227.64463755489558,244.50573112094486,-1.8857892219939316
1.0914230691326818,0.014197239447889578,228.06200349822404,244.50573112094486,-1.8857892219939316
1.120949252595664,0.014581316263252651,228.8901879552776,244.50573112094486,-1.8857892219939316
1.156380672751242,0.015042208441688338,229.87286183882904,244.50573112094486,-1.8857892219939316
1.1696674553095838,0.015215043008601721,230.23832810243266,244.50573112094486,-1.8857892219939316
1.1918120929068203,0.015503100620124026,230.84386090030355,244.50573112094486,-1.8857892219939316
1.2316724405818458,0.016021604320864174,231.9228758867013,244.50573112094486,-1.8857892219939316
1.265627551564275,0.016463292658531706,232.83133692546457,244.50573112094486,-1.8857892219939316
1.3099168267587478,0.017039407881576315,234.00212618420935,244.50573112094486,-1.8857892219939316
1.3453482469143259,0.017500300060012002,234.92767845262438,244.50573112094486,-1.8857892219939316
1.360111338645817,0.01769233846769354,235.3105137330355,244.50573112094486,-1.8857892219939316
1.3896375221087989,0.01807641528305661,236.07135670454474,244.50573112094486,-1.8857892219939316
1.4044006138402898,0.018268453690738148,236.44941196200347,244.50573112094486,-1.8857892219939316
1.4501661982079115,0.01886377275455091,237.61165216173097,244.50573112094486,-1.8857892219939316
1.456071434900508,0.018940588117623523,237.76056968708838,244.50573112094486,-1.8857892219939316
1.5166001109996208,0.019727945589117824,239.27363481211145,244.50573112094486,-1.8857892219939316
1.5225053476922172,0.01980476095219044,239.41997852993083,244.50573112094486,-1.8857892219939316
1.5313632027311117,0.01991998399679936,239.63907972334766,244.50573112094486,-1.8857892219939316
1.5372684394237082,0.019996799359871975,239.78487265724516,244.50573112094486,-1.8857892219939316
1.5756524779255847,0.02049609921984397,240.72725807001598,244.50573112094486,-1.8857892219939316
1.5800814054450318,0.02055371074214843,240.8354156550277,244.50573112094486,-1.8857892219939316
1.5992734246959701,0.020803360672134428,241.3027388823107,244.50573112094486,-1.8857892219939316
1.6066549705617155,0.020899379875975194,241.48189556746357,244.50573112094486,-1.8857892219939316
1.6317522265052502,0.021225845169033808,242.0886414045496,244.50573112094486,-1.8857892219939316
1.661278409968232,0.02160992198439688,242.7978199598074,244.50573112094486,-1.8857892219939316
1.676041501699723,0.021801960392078417,243.15056458526894,244.50573112094486,-1.8857892219939316
1.7040913759895557,0.022166833366673334,243.8174587641015,244.50573112094486,-1.8857892219939316
1.754285887876625,0.022819763952790558,245.00025996044576,244.50573112094486,-1.8857892219939316
1.7926699263785013,0.023319063812762553,245.8958700650642,244.50573112094486,-1.8857892219939316
1.8797721675942978,0.024452090418083616,247.90092580797088,244.50573112094486,-1.8857892219939316
1.913727278576727,0.02489377875575115,248.67269984598948,244.50573112094486,-1.8857892219939316
1.9314429886545161,0.025124224844968995,249.07324344848573,244.50573112094486,-1.8857892219939316
1.9403008436934108,0.025239447889577916,249.27297775722394,244.50573112094486,-1.8857892219939316
1.9860664280610325,0.025834766953390677,250.29932746010695,244.50573112094486,-1.8857892219939316
2.0008295197925237,0.026026805361072214,250.62843491616232,244.50573112094486,-1.8857892219939316
2.0170689206971635,0.026238047609521906,250.9893612156011,244.50573112094486,-1.8857892219939316
2.0451187949869962,0.026602920584116823,251.61012142565136,244.50573112094486,-1.8857892219939316
2.1248394903370476,0.02763992798559712,253.35651261246846,244.50573112094486,-1.8857892219939316
2.1307447270296436,0.027716743348669734,253.48484928592006,244.50573112094486,-1.8857892219939316
2.164699838012073,0.02815843168633727,254.22011093974552,244.50573112094486,-1.8857892219939316
2.1957023306482037,0.028561712342468494,254.88751788241132,244.50573112094486,-1.8857892219939316
2.2119417315528436,0.028772954590918182,255.23564469327394,244.50573112094486,-1.8857892219939316
2.2385152966695276,0.029118623724744948,255.8031643395057,244.50573112094486,-1.8857892219939316
2.282804571864,0.029694738947789557,256.7432260721885,244.50573112094486,-1.8857892219939316
2.356620030521455,0.03065493098619724,258.2943401017017,244.50573112094486,-1.8857892219939316
2.405338233235375,0.03128865773154631,259.3077064168585,244.50573112094486,-1.8857892219939316
2.4141960882742697,0.03140388077615523,259.4910915807635,244.50573112094486,-1.8857892219939316
2.4481511992566984,0.03184556911382276,260.1916504157718,244.50573112094486,-1.8857892219939316
2.4540564359492953,0.03192238447689538,260.3130988945891,244.50573112094486,-1.8857892219939316
2.4821063102391285,0.0322872574514903,260.88842988718477,244.50573112094486,-1.8857892219939316
2.532300822126197,0.03294018803760752,261.911680475169,244.50573112094486,-1.8857892219939316
2.6002110440910555,0.03382356471294259,263.28357527962675,244.50573112094486,-1.8857892219939316
2.6090688991299498,0.033938787757551506,263.46148220621006,244.50573112094486,-1.8857892219939316
2.6164504449956953,0.03403480696139228,263.6095581087321,244.50573112094486,-1.8857892219939316
2.632689845900335,0.034246049209841964,263.9347528136976,244.50573112094486,-1.8857892219939316
2.666644956882765,0.034687737547509506,264.61218825253184,244.50573112094486,-1.8857892219939316
2.685836976133703,0.0349373874774955,264.9935982916014,244.50573112094486,-1.8857892219939316
2.721268396289281,0.03539827965593119,265.6949590072699,244.50573112094486,-1.8857892219939316
2.744889343059667,0.03570554110822165,266.1605552510307,244.50573112094486,-1.8857892219939316
2.8260863475828666,0.03676175235047009,267.74925793008333,244.50573112094486,-1.8857892219939316
2.855612531045849,0.03714582916583317,268.32254130468,244.50573112094486,-1.8857892219939316
2.9205701346644086,0.037990798159631925,269.57568962334796,244.50573112094486,-1.8857892219939316
2.930904298876453,0.03812522504500901,269.77404751604297,244.50573112094486,-1.8857892219939316
3.0239117767848454,0.03933506701340268,271.547159888253,244.50573112094486,-1.8857892219939316
3.044580105208933,0.03960392078415684,271.93828147259995,244.50573112094486,-1.8857892219939316
3.0534379602478268,0.03971914382876575,272.1055878641985,244.50573112094486,-1.8857892219939316
3.0711536703256166,0.0399495899179836,272.43963387221015,244.50573112094486,-1.8857892219939316
3.106585090481195,0.04041048209641929,273.1054798906735,244.50573112094486,-1.8857892219939316
3.1538269840219657,0.0410250050010002,273.98868560207654,244.50573112094486,-1.8857892219939316
3.2054978050821843,0.04169713942788558,274.9488047642776,244.50573112094486,-1.8857892219939316
3.2173082784673768,0.04185077015403081,275.1674108453536,244.50573112094486,-1.8857892219939316
3.2556923169692533,0.0423500700140028,275.8757289139904,244.50573112094486,-1.8857892219939316
3.267502790354446,0.04250370074014803,276.0930167260919,244.50573112094486,-1.8857892219939316
3.317697302241515,0.04315663132626525,277.01309355021937,244.50573112094486,-1.8857892219939316
3.3324603939730055,0.043348669733946785,277.28266911904103,244.50573112094486,-1.8857892219939316
3.3516524132239436,0.04359831966393278,277.6324220802774,244.50573112094486,-1.8857892219939316
3.3708444324748825,0.04384796959391879,277.9813948419629,244.50573112094486,-1.8857892219939316
3.378225978340628,0.043943988797759556,278.11540869762075,244.50573112094486,-1.8857892219939316
3.409228470976759,0.04434726945389078,278.6770243542237,244.50573112094486,-1.8857892219939316
3.43875465443974,0.04473134626925385,279.21004750774324,244.50573112094486,-1.8857892219939316
3.444659891132337,0.04480816163232647,279.31643762422857,244.50573112094486,-1.8857892219939316
3.4800913112879153,0.045269053810762155,279.9532909718235,244.50573112094486,-1.8857892219939316
3.525856895655537,0.04586437287457491,280.7721630513459,244.50573112094486,-1.8857892219939316
3.6129591368713334,0.04699739947989598,282.3192988462234,244.50573112094486,-1.8857892219939316
3.65134317537321,0.04749669933986797,282.99646245971655,244.50573112094486,-1.8857892219939316
3.703013996433428,0.04816883376675335,283.9036609865575,244.50573112094486,-1.8857892219939316
3.7443506532816033,0.04870654130826166,284.62587018218676,244.50573112094486,-1.8857892219939316
3.772400527571435,0.049071414282856565,285.1141706881993,244.50573112094486,-1.8857892219939316
3.7827346917834794,0.04920584116823365,285.2937136702784,244.50573112094486,-1.8857892219939316
3.803403020207567,0.049474694938987804,285.6522267793262,244.50573112094486,-1.8857892219939316
3.816689802765908,0.04964752950590118,285.8822983311037,244.50573112094486,-1.8857892219939316
3.853597532094636,0.050127625525105024,286.51975280752146,244.50573112094486,-1.8857892219939316
3.866884314652977,0.0503004600920184,286.74865297070306,244.50573112094486,-1.8857892219939316
3.887552643077065,0.05056931386277255,287.1041111436758,244.50573112094486,-1.8857892219939316
3.8964104981159595,0.05068453690738148,287.2562246564331,244.50573112094486,-1.8857892219939316
3.9082209715011524,0.05083816763352671,287.4588330511357,244.50573112094486,-1.8857892219939316
3.9333182274446874,0.051164632926585324,287.8885847521986,244.50573112094486,-1.8857892219939316
3.9613681017345193,0.05152950590118023,288.3676319326616,244.50573112094486,-1.8857892219939316
3.9687496476002657,0.05162552510502101,288.4934768776781,244.50573112094486,-1.8857892219939316
3.9835127393317564,0.051817563512702544,288.7448932506237,244.50573112094486,-1.8857892219939316
4.030754632872528,0.05243208641728346,289.54699459485664,244.50573112094486,-1.8857892219939316
4.052899270469763,0.05272014402880576,289.921716724131,244.50573112094486,-1.8857892219939316
4.10752270987628,0.05343068613722744,290.8426334411504,244.50573112094486,-1.8857892219939316
4.12376211078092,0.053641928385677135,291.1154968229748,244.50573112094486,-1.8857892219939316
4.168051385975393,0.05421804360872175,291.85754799335194,244.50573112094486,-1.8857892219939316
4.271393028095829,0.055562312462492505,293.5771435513569,244.50573112094486,-1.8857892219939316
4.292061356519916,0.055831166233246646,293.91910720902985,244.50573112094486,-1.8857892219939316
4.326016467502346,0.05627285457091419,294.479513729338,244.50573112094486,-1.8857892219939316
4.33635063171439,0.05640728145629126,294.64973139206785,244.50573112094486,-1.8857892219939316
4.370305742696818,0.05684896979395879,295.207907419014,244.50573112094486,-1.8857892219939316
4.396879307813503,0.05719463892778556,295.64356190763084,244.50573112094486,-1.8857892219939316
4.405737162852397,0.057309861972394474,295.78855172102277,244.50573112094486,-1.8857892219939316
4.426405491276484,0.05757871574314863,296.12641988851436,244.50573112094486,-1.8857892219939316
4.4367396554885286,0.05771314262852571,296.2951232057927,244.50573112094486,-1.8857892219939316
4.46478952977836,0.05807801560312062,296.7522614793237,244.50573112094486,-1.8857892219939316
4.478076312336702,0.05825085017003401,296.96840960403426,244.50573112094486,-1.8857892219939316
4.485457858202448,0.058346869373874774,297.08838381637923,244.50573112094486,-1.8857892219939316
4.509078804972833,0.05865413082616523,297.47178488384105,244.50573112094486,-1.8857892219939316
4.545986534301561,0.05913422684536908,298.06928464509247,244.50573112094486,-1.8857892219939316
4.569607481071946,0.05944148829765954,298.4506918572934,244.50573112094486,-1.8857892219939316
4.609467828746972,0.059959991998399687,299.09257757903106,244.50573112094486,-1.8857892219939316
4.630136157171059,0.06022884576915383,299.42455474843,244.50573112094486,-1.8857892219939316
4.658186031460891,0.06059371874374875,299.87417226025474,244.50573112094486,-1.8857892219939316
4.6847595965775755,0.06093938787757551,300.29915268593356,244.50573112094486,-1.8857892219939316
4.699522688309067,0.06113142628525706,300.5348466591031,244.50573112094486,-1.8857892219939316
4.737906726810943,0.06163072614522905,301.1463035485515,244.50573112094486,-1.8857892219939316
4.755622436888731,0.061861172234446885,301.4278625258485,244.50573112094486,-1.8857892219939316
4.770385528620223,0.06205321064212843,301.6621826682142,244.50573112094486,-1.8857892219939316
4.814674803814695,0.06262932586517303,302.3634520793089,244.50573112094486,-1.8857892219939316
4.8471536056239755,0.06305181036207241,302.8761183960634,244.50573112094486,-1.8857892219939316
4.894395499164746,0.06366633326665333,303.6194297502808,244.50573112094486,-1.8857892219939316
4.910634900069387,0.06387757551510302,303.8742961003443,244.50573112094486,-1.8857892219939316
4.925397991800877,0.06406961392278455,304.10570768387925,244.50573112094486,-1.8857892219939316
4.9549241752638595,0.06445369073814763,304.56772091157853,244.50573112094486,-1.8857892219939316
4.982974049553693,0.06481856371274256,305.00563995974613,244.50573112094486,-1.8857892219939316
5.040550107306507,0.06556751350270054,305.90152590747374,244.50573112094486,-1.8857892219939316
5.077457836635235,0.06604760952190439,306.4737132804133,244.50573112094486,-1.8857892219939316
5.130604966868602,0.06673894778955791,307.2948216131205,244.50573112094486,-1.8857892219939316
5.192609952140865,0.06754550910182038,308.2486004090148,244.50573112094486,-1.8857892219939316
5.219183517257548,0.06789117823564714,308.65600188048387,244.50573112094486,-1.8857892219939316
5.285617430049257,0.06875535107021405,309.67098220954404,244.50573112094486,-1.8857892219939316
5.344669796975221,0.0695235047009402,310.5690175907834,244.50573112094486,-1.8857892219939316
5.371243362091904,0.06986917383476696,310.97187017981946,244.50573112094486,-1.8857892219939316
5.377148598784501,0.06994598919783958,311.0612873321923,244.50573112094486,-1.8857892219939316
5.388959072169694,0.07009961992398481,311.2400068273074,244.50573112094486,-1.8857892219939316
5.419961564805825,0.07050290058011603,311.7084202209124,244.50573112094486,-1.8857892219939316
5.448011439095658,0.07086777355471095,312.1313231785716,244.50573112094486,-1.8857892219939316
5.564639863774436,0.07238487697539508,313.880680193783,244.50573112094486,-1.8857892219939316
5.597118665583716,0.07280736147229447,314.3652898741339,244.50573112094486,-1.8857892219939316
5.634026394912443,0.0732874574914983,314.9146534397551,244.50573112094486,-1.8857892219939316
5.6502657958170825,0.07349869973994799,315.15592857928635,244.50573112094486,-1.8857892219939316
5.706365544396749,0.07422844568913783,315.98735157708194,244.50573112094486,-1.8857892219939316
5.725557563647687,0.07447809561912383,316.27105314303617,244.50573112094486,-1.8857892219939316
5.7432732737254755,0.07470854170834167,316.53260250645934,244.50573112094486,-1.8857892219939316
5.7816573122273525,0.07520784156831367,317.09821583387856,244.50573112094486,-1.8857892219939316
5.802325640651439,0.07547669533906781,317.40217018927154,244.50573112094486,-1.8857892219939316
5.811183495690334,0.07559191838367674,317.53230704712803,244.50573112094486,-1.8857892219939316
5.8318518241144215,0.07586077215443089,317.8356592342816,244.50573112094486,-1.8857892219939316
5.859901698404254,0.07622564512902581,318.246681697704,244.50573112094486,-1.8857892219939316
5.884998954347789,0.07655211042208442,318.61378868444757,244.50573112094486,-1.8857892219939316
5.902714664425578,0.07678255651130227,318.8725555081451,244.50573112094486,-1.8857892219939316
5.9130488286376215,0.07691698339667934,319.0233629479467,244.50573112094486,-1.8857892219939316
5.9366697754080064,0.0772242448489698,319.36768021224475,244.50573112094486,-1.8857892219939316
5.972101195563585,0.07768513702740548,319.8831560063022,244.50573112094486,-1.8857892219939316
5.989816905641375,0.07791558311662333,320.14044653863925,244.50573112094486,-1.8857892219939316
6.028200944143251,0.07841488297659532,320.6968934470288,244.50573112094486,-1.8857892219939316
6.040011417528444,0.07856851370274055,320.86782965741617,244.50573112094486,-1.8857892219939316
6.069537600991425,0.07895259051810362,321.29460086901344,244.50573112094486,-1.8857892219939316
6.091682238588662,0.07924064812962593,321.6141481303818,244.50573112094486,-1.8857892219939316
6.159592460553521,0.080124024804961,322.59127990055777,244.50573112094486,-1.8857892219939316
6.218644827479484,0.08089217843568715,323.43754951157484,244.50573112094486,-1.8857892219939316
6.24226577424987,0.0811994398879776,323.7751791039032,244.50573112094486,-1.8857892219939316
6.277697194405448,0.0816603320664133,324.2806907480008,244.50573112094486,-1.8857892219939316
6.298365522829535,0.08192918583716743,324.5750586860726,244.50573112094486,-1.8857892219939316
6.329368015465666,0.08233246649329866,325.01590520591475,244.50573112094486,-1.8857892219939316
6.361846817274946,0.08275495099019804,325.4768421163217,244.50573112094486,-1.8857892219939316
6.386944073218481,0.08308141628325666,325.83239234257826,244.50573112094486,-1.8857892219939316
6.423851802547207,0.08356151230246049,326.35427209294136,244.50573112094486,-1.8857892219939316
6.494714642858364,0.08448329665933187,327.3530148135908,244.50573112094486,-1.8857892219939316
6.5080014254167065,0.08465613122624525,327.5398049995763,244.50573112094486,-1.8857892219939316
6.541956536399135,0.08509781956391278,328.0164832566765,244.50573112094486,-1.8857892219939316
6.562624864823222,0.08536667333466694,328.30616284771867,244.50573112094486,-1.8857892219939316
6.623153540922336,0.08615403080616124,329.15247042086315,244.50573112094486,-1.8857892219939316
6.629058777614932,0.08623084616923385,329.2348751856134,244.50573112094486,-1.8857892219939316
6.640869251000124,0.08638447689537908,329.3995988791755,244.50573112094486,-1.8857892219939316
6.692540072060343,0.08705661132226446,330.118925869548,244.50573112094486,-1.8857892219939316
6.7087794729649834,0.08726785357071415,330.34455230814314,244.50573112094486,-1.8857892219939316
6.744210893120561,0.08772874574914984,330.83609015725676,244.50573112094486,-1.8857892219939316
6.7707844582372445,0.0880744148829766,331.204082897134,244.50573112094486,-1.8857892219939316
6.798834332527077,0.08843928785757152,331.5919091295148,244.50573112094486,-1.8857892219939316
6.831313134336358,0.0888617723544709,332.0401923490718,244.50573112094486,-1.8857892219939316
6.89331811960862,0.08966833366673335,332.8937043249253,244.50573112094486,-1.8857892219939316
6.930225848937347,0.0901484296859372,333.40032571021504,244.50573112094486,-1.8857892219939316
6.936131085629944,0.0902252450490098,333.48128738195595,244.50573112094486,-1.8857892219939316
6.947941559015136,0.09037887577515503,333.6431301241213,244.50573112094486,-1.8857892219939316
6.980420360824416,0.09080136027205442,334.08764538176445,244.50573112094486,-1.8857892219939316
6.993707143382758,0.09097419483896779,334.26925995993327,244.50573112094486,-1.8857892219939316
7.030614872711485,0.09145429085817164,334.77304021754054,244.50573112094486,-1.8857892219939316
7.042425346096678,0.09160792158431687,334.93403192905055,244.50573112094486,-1.8857892219939316
7.067522602040213,0.09193438687737548,335.27579011831887,244.50573112094486,-1.8857892219939316
7.0911435488105985,0.09224164832966594,335.59701277799377,244.50573112094486,-1.8857892219939316
7.114764495580984,0.0925489097819564,335.91781840440547,244.50573112094486,-1.8857892219939316
7.133956514831922,0.0927985597119424,336.17816723069296,244.50573112094486,-1.8857892219939316
7.1413380606976675,0.09289457891578316,336.2782286431638,244.50573112094486,-1.8857892219939316
7.175293171680096,0.09333626725345069,336.73799260311654,244.50573112094486,-1.8857892219939316
7.216629828528271,0.093873974794959,337.29656157544383,244.50573112094486,-1.8857892219939316
7.294874214705174,0.09489177835567114,338.3504483604407,244.50573112094486,-1.8857892219939316
7.346545035765391,0.09556391278255652,339.0439953471676,244.50573112094486,-1.8857892219939316
7.370165982535777,0.09587117423484698,339.3604115260392,244.50573112094486,-1.8857892219939316
7.389358001786715,0.09612082416483297,339.6172085561441,244.50573112094486,-1.8857892219939316
7.445457750366381,0.09685057011402282,340.3663587765759,244.50573112094486,-1.8857892219939316
7.448410368712679,0.09688897779555912,340.40572664184157,244.50573112094486,-1.8857892219939316
7.485318098041406,0.09736907381476295,340.8973125509091,244.50573112094486,-1.8857892219939316
7.5118916631580905,0.09771474294858973,341.2506692600599,244.50573112094486,-1.8857892219939316
7.544370464967369,0.0981372274454891,341.6818883346557,244.50573112094486,-1.8857892219939316
7.5665151025646065,0.09842528505701141,341.9754863197786,244.50573112094486,-1.8857892219939316
7.578325575949799,0.09857891578315664,342.1319348795094,244.50573112094486,-1.8857892219939316
7.59308866768129,0.09877095419083817,342.3273619249524,244.50573112094486,-1.8857892219939316
7.632949015356315,0.09928945789157832,342.8542761665631,244.50573112094486,-1.8857892219939316
7.638854252048912,0.09936627325465093,342.93224617246676,244.50573112094486,-1.8857892219939316
7.65804627129985,0.09961592318463693,343.1854864999915,244.50573112094486,-1.8857892219939316
7.662475198819297,0.09967353470694139,343.24389141138334,244.50573112094486,-1.8857892219939316