File: datasets/aisi_316_L/data/M1/train_38.csv
Time(s),Strain(%),Stress(MPa),Temp(C),Log_SR(s-1)
0.0,0.0,0.0,349.5104861869886,-2.8536937812464656
0.008567912592523055,1.2e-05,2.0822163750000002,349.5104861869886,-2.8536937812464656
0.028559708641743516,3.9999999999999996e-05,6.940721249999999,349.5104861869886,-2.8536937812464656
0.049122698863798844,6.879999999999999e-05,11.938040549999998,349.5104861869886,-2.8536937812464656
0.05140747555513833,7.2e-05,12.49329825,349.5104861869886,-2.8536937812464656
0.06226016483900086,8.719999999999999e-05,15.130772324999999,349.5104861869886,-2.8536937812464656
0.06397374735750548,8.96e-05,15.5472156,349.5104861869886,-2.8536937812464656
0.06740091239451469,9.439999999999999e-05,16.38010215,349.5104861869886,-2.8536937812464656
0.07139927160435879,9.999999999999999e-05,17.351803125,349.5104861869886,-2.8536937812464656
0.07596882498703775,0.0001064,18.462318525,349.5104861869886,-2.8536937812464656
0.09481823269058848,0.0001328,23.04319455,349.5104861869886,-2.8536937812464656
0.09995898024610231,0.00014,24.292524375,349.5104861869886,-2.8536937812464656
0.10795569866579048,0.0001512,26.235926324999998,349.5104861869886,-2.8536937812464656
0.11195405787563457,0.0001568,27.2076273,349.5104861869886,-2.8536937812464656
0.12851868888784582,0.00017999999999999998,31.233245625,349.5104861869886,-2.8536937812464656
0.13594421313469915,0.0001904,33.03783315,349.5104861869886,-2.8536937812464656
0.15650720335675447,0.0002192,38.03515245,349.5104861869886,-2.8536937812464656
0.17135825185046108,0.00023999999999999998,41.644327499999996,349.5104861869886,-2.8536937812464656
0.1753566110603052,0.0002456,42.616028475,349.5104861869886,-2.8536937812464656
0.1827821353071585,0.000256,44.420615999999995,349.5104861869886,-2.8536937812464656
0.19706198962803026,0.000276,47.890976625,349.5104861869886,-2.8536937812464656
0.21134184394890201,0.000296,51.36133725,349.5104861869886,-2.8536937812464656
0.21534020315874614,0.0003016,52.333038225,349.5104861869886,-2.8536937812464656
0.22562169826977377,0.000316,54.831697874999996,349.5104861869886,-2.8536937812464656
0.23418961086229684,0.000328,56.91391425,349.5104861869886,-2.8536937812464656
0.2370455817264712,0.000332,57.607986374999996,349.5104861869886,-2.8536937812464656
0.24161513510915014,0.0003384,58.718501775,349.5104861869886,-2.8536937812464656
0.2461846884918291,0.0003448,59.829017175,349.5104861869886,-2.8536937812464656
0.25075424187450807,0.00035119999999999997,60.939532574999994,349.5104861869886,-2.8536937812464656
0.2770291738249121,0.000388,67.324996125,349.5104861869886,-2.8536937812464656
0.28788186310877467,0.0004032,69.9624702,349.5104861869886,-2.8536937812464656
0.29930574656547204,0.0004192,72.7387587,349.5104861869886,-2.8536937812464656
0.3095872416764997,0.00043359999999999997,75.23741835,349.5104861869886,-2.8536937812464656
0.32101112513319713,0.0004496,78.01370684999999,349.5104861869886,-2.8536937812464656
0.3232959018245366,0.0004528,78.56896455,349.5104861869886,-2.8536937812464656
0.33357739693556426,0.00046719999999999997,81.0676242,349.5104861869886,-2.8536937812464656
0.34043172700958274,0.0004768,82.7333973,349.5104861869886,-2.8536937812464656
0.34957083377494064,0.0004896,84.9544281,349.5104861869886,-2.8536937812464656
0.35699635802179397,0.0005,86.759015625,349.5104861869886,-2.8536937812464656
0.3615659114044729,0.0005064,87.86953102499999,349.5104861869886,-2.8536937812464656
0.3718474065155006,0.0005208,90.368190675,349.5104861869886,-2.8536937812464656
0.3889832317005467,0.0005448,94.532623425,349.5104861869886,-2.8536937812464656
0.40726144523126256,0.0005704,98.974685025,349.5104861869886,-2.8536937812464656
0.414115775305281,0.00058,100.640458125,349.5104861869886,-2.8536937812464656
0.418114134515125,0.0005855999999999999,101.61215909999999,349.5104861869886,-2.8536937812464656
0.42782443545331783,0.0005991999999999999,103.97200432499999,349.5104861869886,-2.8536937812464656
0.44153309560135473,0.0006184,107.30355052499999,349.5104861869886,-2.8536937812464656
0.449529814021043,0.0006296,109.246952475,349.5104861869886,-2.8536937812464656
0.4598113091320706,0.0006439999999999999,111.745612125,349.5104861869886,-2.8536937812464656
0.4643808625147496,0.0006504,112.85612752499999,349.5104861869886,-2.8536937812464656
0.4678080275517588,0.0006552,113.689014075,349.5104861869886,-2.8536937812464656
0.47980310518129105,0.000672,116.60411699999999,349.5104861869886,-2.8536937812464656
0.48551504690963976,0.0006799999999999999,117.99226124999998,349.5104861869886,-2.8536937812464656
0.5003660954033464,0.0007008,121.6014363,349.5104861869886,-2.8536937812464656
0.5140747555513833,0.0007199999999999999,124.9329825,349.5104861869886,-2.8536937812464656
0.5192155031068971,0.0007272,126.182312325,349.5104861869886,-2.8536937812464656
0.528354609872255,0.00074,128.403343125,349.5104861869886,-2.8536937812464656
0.5660534252793565,0.0007928,137.56509517499998,349.5104861869886,-2.8536937812464656
0.5711941728348703,0.0007999999999999999,138.814425,349.5104861869886,-2.8536937812464656
0.5774773087360539,0.0008087999999999999,140.34138367499997,349.5104861869886,-2.8536937812464656
0.5837604446372374,0.0008175999999999999,141.86834234999998,349.5104861869886,-2.8536937812464656
0.5883299980199165,0.000824,142.97885775,349.5104861869886,-2.8536937812464656
0.5951843280939348,0.0008336,144.64463085,349.5104861869886,-2.8536937812464656
0.6043234348592929,0.0008464,146.86566165,349.5104861869886,-2.8536937812464656
0.6277423959455225,0.0008792,152.557053075,349.5104861869886,-2.8536937812464656
0.6534461337230916,0.0009151999999999999,156.96146659973346,349.5104861869886,-2.8536937812464656
0.6705819589081378,0.0009392,157.08797129853943,349.5104861869886,-2.8536937812464656
0.6802922598463306,0.0009528,157.15909754167095,349.5104861869886,-2.8536937812464656
0.687146589920349,0.0009624,157.20906610726436,349.5104861869886,-2.8536937812464656
0.6922873374758628,0.0009695999999999999,157.24641506092192,349.5104861869886,-2.8536937812464656
0.7031400267597253,0.0009847999999999999,157.32490949994073,349.5104861869886,-2.8536937812464656
0.7059959976238998,0.0009888,157.34548722048206,349.5104861869886,-2.8536937812464656
0.7151351043892578,0.0010016,157.41111882572,349.5104861869886,-2.8536937812464656
0.7254165995002854,0.001016,157.4845646297576,349.5104861869886,-2.8536937812464656
0.731128541228634,0.001024,157.52519240121728,349.5104861869886,-2.8536937812464656
0.7568322790062032,0.00106,157.70650679323046,349.5104861869886,-2.8536937812464656
0.7768240750554236,0.001088,157.84587365050712,349.5104861869886,-2.8536937812464656
0.7865343759936164,0.0011015999999999999,157.91306081793846,349.5104861869886,-2.8536937812464656
0.7968158711046441,0.001116,157.98384852895197,349.5104861869886,-2.8536937812464656
0.8042413953514975,0.0011264,158.03475163179226,349.5104861869886,-2.8536937812464656
0.8082397545613416,0.001132,158.0620850600885,349.5104861869886,-2.8536937812464656
0.8122381137711856,0.0011376,158.08936580380163,349.5104861869886,-2.8536937812464656
0.8162364729810297,0.0011432,158.1165942230818,349.5104861869886,-2.8536937812464656
0.8425114049314336,0.0011799999999999998,158.29424702725308,349.5104861869886,-2.8536937812464656
0.8527929000424614,0.0011944,158.36317350665826,349.5104861869886,-2.8536937812464656
0.8636455893263238,0.0012096,158.43557856229353,349.5104861869886,-2.8536937812464656
0.8767830553015259,0.001228,158.52275374823404,349.5104861869886,-2.8536937812464656
0.8859221620668839,0.0012408,158.58309713700473,349.5104861869886,-2.8536937812464656
0.9036291814247649,0.0012656,158.699326016044,349.5104861869886,-2.8536937812464656
0.9127682881901227,0.0012783999999999998,158.75896736626981,349.5104861869886,-2.8536937812464656
0.9447551618688754,0.0013231999999999999,158.96590239997965,349.5104861869886,-2.8536937812464656
0.9573214336712426,0.0013407999999999998,159.04644844307805,349.5104861869886,-2.8536937812464656
0.9933066665598396,0.0013912,159.2748529118483,349.5104861869886,-2.8536937812464656
0.9978762199425184,0.0013976,159.30362395325656,349.5104861869886,-2.8536937812464656
1.004159355843702,0.0014064,159.3431003777787,349.5104861869886,-2.8536937812464656
1.01329846260906,0.0014192,159.40034909826127,349.5104861869886,-2.8536937812464656
1.0218663752015829,0.0014311999999999999,159.45383715888744,349.5104861869886,-2.8536937812464656
1.0281495111027665,0.0014399999999999999,159.4929506402427,349.5104861869886,-2.8536937812464656
1.0332902586582804,0.0014471999999999998,159.5248832884976,349.5104861869886,-2.8536937812464656
1.048141307151987,0.001468,159.61678695747952,349.5104861869886,-2.8536937812464656
1.0549956372260054,0.0014776,159.65903261312872,349.5104861869886,-2.8536937812464656
1.0584228022630147,0.0014824,159.68011528982544,349.5104861869886,-2.8536937812464656
1.0669907148555378,0.0014944,159.73270583744562,349.5104861869886,-2.8536937812464656
1.0886960934232628,0.0015248,159.8652034043335,349.5104861869886,-2.8536937812464656
1.1035471419169693,0.0015455999999999998,159.95526658449617,349.5104861869886,-2.8536937812464656
1.1223965496205202,0.0015719999999999998,160.06889971285412,349.5104861869886,-2.8536937812464656
1.1326780447315479,0.0015864,160.1305676331346,349.5104861869886,-2.8536937812464656
1.1572393941634473,0.0016208,160.27700839366798,349.5104861869886,-2.8536937812464656
1.176659996039833,0.001648,160.3919423457382,349.5104861869886,-2.8536937812464656
1.188655073669365,0.0016648,160.462561470657,349.5104861869886,-2.8536937812464656
1.2092180638914205,0.0016936,160.58297960789614,349.5104861869886,-2.8536937812464656
1.2137876172740993,0.0017,160.6096304315269,349.5104861869886,-2.8536937812464656
1.2189283648296132,0.0017071999999999999,160.63956588026875,349.5104861869886,-2.8536937812464656
1.224069112385127,0.0017143999999999998,160.66945213152616,349.5104861869886,-2.8536937812464656
1.2354929958418246,0.0017304,160.73569132562275,349.5104861869886,-2.8536937812464656
1.2434897142615127,0.0017415999999999998,160.78191670851646,349.5104861869886,-2.8536937812464656
1.2640527044835679,0.0017703999999999999,160.90025275189393,349.5104861869886,-2.8536937812464656
1.2726206170760912,0.0017824,160.94933757982278,349.5104861869886,-2.8536937812464656
1.27719017045877,0.0017888,160.97546344902304,349.5104861869886,-2.8536937812464656
1.2983243548536603,0.0018184,161.09582454737003,349.5104861869886,-2.8536937812464656
1.3131754033473668,0.0018391999999999998,161.17994590210543,349.5104861869886,-2.8536937812464656
1.3337383935694223,0.0018679999999999999,161.29581165424065,349.5104861869886,-2.8536937812464656
1.3365943644335965,0.001872,161.31184884470144,349.5104861869886,-2.8536937812464656
1.3405927236434405,0.0018775999999999999,161.3342784774837,349.5104861869886,-2.8536937812464656
1.361726908038331,0.0019072,161.45240448945614,349.5104861869886,-2.8536937812464656
1.3680100439395144,0.001916,161.48738486912126,349.5104861869886,-2.8536937812464656
1.373721985667863,0.001924,161.51913087961267,349.5104861869886,-2.8536937812464656
1.3811475099147166,0.0019344,161.56032383703263,349.5104861869886,-2.8536937812464656
1.382861092433221,0.0019367999999999998,161.56981762755456,349.5104861869886,-2.8536937812464656
1.3880018399887348,0.001944,161.59827150883237,349.5104861869886,-2.8536937812464656
1.3982833350997625,0.0019584,161.65505627041293,349.5104861869886,-2.8536937812464656
1.4039952768281114,0.0019664,161.68653299170333,349.5104861869886,-2.8536937812464656
1.4177039369761484,0.0019856,161.76187405159015,349.5104861869886,-2.8536937812464656
1.4217022961859922,0.0019912,161.78379493831676,349.5104861869886,-2.8536937812464656
1.431412597124185,0.0020047999999999997,161.8369315186566,349.5104861869886,-2.8536937812464656
1.4399805097167082,0.0020168,161.88370010155862,349.5104861869886,-2.8536937812464656
1.4588299174202588,0.0020432,161.98621066215318,349.5104861869886,-2.8536937812464656
1.4662554416671123,0.0020536,162.02645162006678,349.5104861869886,-2.8536937812464656
1.4736809659139654,0.002064,162.06661317737618,349.5104861869886,-2.8536937812464656
1.4782505192966444,0.0020704,162.0912887575025,349.5104861869886,-2.8536937812464656
1.4976711211730298,0.0020976,162.1958298281965,349.5104861869886,-2.8536937812464656
1.5319427715431224,0.0021456,162.3790334134775,349.5104861869886,-2.8536937812464656
1.5479362083824986,0.002168,162.46398073752906,349.5104861869886,-2.8536937812464656
1.5525057617651776,0.0021744,162.48818844166072,349.5104861869886,-2.8536937812464656
1.5667856160860494,0.0021944,162.5636590324815,349.5104861869886,-2.8536937812464656
1.5702127811230586,0.0021992,162.5817319996141,349.5104861869886,-2.8536937812464656
1.5810654704069211,0.0022144,162.63886183468753,349.5104861869886,-2.8536937812464656
1.5844926354439302,0.0022191999999999997,162.65687103467062,349.5104861869886,-2.8536937812464656
1.5890621888266092,0.0022256,162.68085968773994,349.5104861869886,-2.8536937812464656
1.6021996548018111,0.002244,162.74967766237944,349.5104861869886,-2.8536937812464656
1.6067692081844902,0.0022504,162.7735627180396,349.5104861869886,-2.8536937812464656
1.608482790702995,0.0022528,162.7825127821576,349.5104861869886,-2.8536937812464656
1.6239050333695362,0.0022743999999999998,162.86289671387433,349.5104861869886,-2.8536937812464656
1.6404696643817476,0.0022976,162.94890409907552,349.5104861869886,-2.8536937812464656
1.6478951886286008,0.0023079999999999997,162.9873491190262,349.5104861869886,-2.8536937812464656
1.6518935478384449,0.0023136,163.00802229693042,349.5104861869886,-2.8536937812464656
1.659890266258133,0.0023247999999999997,163.049310200322,349.5104861869886,-2.8536937812464656
1.6724565380605,0.0023423999999999997,163.11403480415166,349.5104861869886,-2.8536937812464656
1.67359892640617,0.0023439999999999997,163.11990943815445,349.5104861869886,-2.8536937812464656
1.6844516156900327,0.0023592,163.1756406811023,349.5104861869886,-2.8536937812464656
1.6878787807270417,0.0023639999999999998,163.19321090446712,349.5104861869886,-2.8536937812464656
1.6935907224553906,0.002372,163.2224637227973,349.5104861869886,-2.8536937812464656
1.6953043049738952,0.0023744,163.23123206188873,349.5104861869886,-2.8536937812464656
1.7055858000849229,0.0023888,163.28376969309593,349.5104861869886,-2.8536937812464656
1.7152961010231156,0.0024024,163.33327526969188,349.5104861869886,-2.8536937812464656
1.7232928194428037,0.0024135999999999997,163.3739625521621,349.5104861869886,-2.8536937812464656
1.7290047611711525,0.0024216,163.40297982795124,349.5104861869886,-2.8536937812464656
1.7489965572203727,0.0024495999999999997,163.5042471857144,349.5104861869886,-2.8536937812464656
1.7615628290227399,0.0024671999999999997,163.56766994819532,349.5104861869886,-2.8536937812464656
1.7695595474424284,0.0024784,163.60793803483398,349.5104861869886,-2.8536937812464656
1.7866953726274741,0.0025023999999999997,163.69398859030198,349.5104861869886,-2.8536937812464656
1.796976867738502,0.0025168,163.74546444131067,349.5104861869886,-2.8536937812464656
1.8049735861581901,0.002528,163.78542184394715,349.5104861869886,-2.8536937812464656
1.818682246306227,0.0025472,163.8537599963546,349.5104861869886,-2.8536937812464656
1.8203958288247317,0.0025496,163.86228811758048,349.5104861869886,-2.8536937812464656
1.8329621006270989,0.0025672,163.92473229015442,349.5104861869886,-2.8536937812464656
1.841530013219622,0.0025792,163.96721216759252,349.5104861869886,-2.8536937812464656
1.8483843432936404,0.0025888,164.00114059786736,349.5104861869886,-2.8536937812464656
1.853525090849154,0.002596,164.02655472888145,349.5104861869886,-2.8536937812464656
1.8649489743058514,0.0026119999999999997,164.08293236318016,349.5104861869886,-2.8536937812464656
1.8780864402810535,0.0026303999999999998,164.14760040665467,349.5104861869886,-2.8536937812464656
1.8975070421574394,0.0026576,164.2428744186408,349.5104861869886,-2.8536937812464656
1.9043613722314576,0.0026671999999999998,164.27640964553993,349.5104861869886,-2.8536937812464656
1.9106445081326413,0.002676,164.30710894012998,349.5104861869886,-2.8536937812464656
1.9569112361322656,0.0027408,164.53196733431633,349.5104861869886,-2.8536937812464656
1.9723334787988072,0.0027624,164.60645812183625,349.5104861869886,-2.8536937812464656
1.9797590030456604,0.0027727999999999997,164.6422430096147,349.5104861869886,-2.8536937812464656
1.9894693039838534,0.0027864,164.6889597488901,349.5104861869886,-2.8536937812464656
2.0111746825515784,0.0028168,164.79306504547725,349.5104861869886,-2.8536937812464656
2.022027371835441,0.002832,164.8449533082025,349.5104861869886,-2.8536937812464656
2.02659692521812,0.0028384,164.86676849108912,349.5104861869886,-2.8536937812464656
2.035164837810643,0.0028504,164.90762032303803,349.5104861869886,-2.8536937812464656
2.055727828032698,0.0028791999999999997,165.0053920252584,349.5104861869886,-2.8536937812464656
2.0717212648720746,0.0029016,165.08117322644884,349.5104861869886,-2.8536937812464656
2.078575594946093,0.0029112,165.11358100162295,349.5104861869886,-2.8536937812464656
2.087143507538616,0.0029232,165.15403216993786,349.5104861869886,-2.8536937812464656
2.089428284229956,0.0029264,165.16480820410007,349.5104861869886,-2.8536937812464656
2.096853808476809,0.0029368,165.19979861979283,349.5104861869886,-2.8536937812464656
2.1094200802791763,0.0029544,165.25890327995856,349.5104861869886,-2.8536937812464656
2.1265559054642225,0.0029784,165.33927972118383,349.5104861869886,-2.8536937812464656
2.136266206402415,0.002992,165.3847142418345,349.5104861869886,-2.8536937812464656
2.1385509830937544,0.0029952,165.39539300356662,349.5104861869886,-2.8536937812464656
2.1534020315874614,0.003016,165.4646968152188,349.5104861869886,-2.8536937812464656
2.15911397331581,0.0030239999999999998,165.49130246226702,349.5104861869886,-2.8536937812464656
2.1653971092169937,0.0030328,165.52053698914085,349.5104861869886,-2.8536937812464656
2.1916720411673976,0.0030696,165.64243374834615,349.5104861869886,-2.8536937812464656
2.2019535362784253,0.003084,165.68997717393526,349.5104861869886,-2.8536937812464656
2.2156621964264622,0.0031032,165.7532339511516,349.5104861869886,-2.8536937812464656
2.2225165265004803,0.0031127999999999998,165.7848050872213,349.5104861869886,-2.8536937812464656
2.22480130319182,0.003116,165.79532035782944,349.5104861869886,-2.8536937812464656
2.2350827983028476,0.0031303999999999998,165.84258705512303,349.5104861869886,-2.8536937812464656
2.250505040969389,0.003152,165.91332841640215,349.5104861869886,-2.8536937812464656
2.2579305652162422,0.0031623999999999997,165.9473216208565,349.5104861869886,-2.8536937812464656
2.2653560894630957,0.0031728,165.98127125449327,349.5104861869886,-2.8536937812464656
2.2796359437839677,0.0031928,166.0464372770013,349.5104861869886,-2.8536937812464656
2.2967717689690135,0.0032167999999999997,166.12442673564377,349.5104861869886,-2.8536937812464656
2.308766846598546,0.0032335999999999997,166.17888439002095,349.5104861869886,-2.8536937812464656
2.3144787883268947,0.0032416,166.2047778138245,349.5104861869886,-2.8536937812464656
2.3213331184009127,0.0032511999999999997,166.23581704850872,349.5104861869886,-2.8536937812464656
2.3321858076847755,0.0032664,166.2848895020716,349.5104861869886,-2.8536937812464656
2.3407537202772986,0.0032784,166.32356803255524,349.5104861869886,-2.8536937812464656
2.345323273659978,0.0032848,166.3441740037247,349.5104861869886,-2.8536937812464656
2.3578895454623447,0.0033024,166.4007598469778,349.5104861869886,-2.8536937812464656
2.370455817264712,0.00332,166.45722819869368,349.5104861869886,-2.8536937812464656
2.3767389531658956,0.0033288,166.48541858592495,349.5104861869886,-2.8536937812464656
2.3841644774127486,0.0033391999999999996,166.5186970542966,349.5104861869886,-2.8536937812464656
2.387020448276923,0.0033431999999999997,166.5314856988963,349.5104861869886,-2.8536937812464656
2.396159555042281,0.003356,166.57236931866575,349.5104861869886,-2.8536937812464656
2.4064410501533087,0.0033704,166.61829076927177,349.5104861869886,-2.8536937812464656
2.438999118004896,0.0034159999999999998,166.76320645722203,349.5104861869886,-2.8536937812464656
2.4464246422517495,0.0034264,166.79615151750642,349.5104861869886,-2.8536937812464656
2.4515653898072634,0.0034335999999999998,166.81893679437627,349.5104861869886,-2.8536937812464656
2.4629892732639607,0.0034495999999999997,166.86950413551006,349.5104861869886,-2.8536937812464656
2.470414797510814,0.00346,166.90232386296893,349.5104861869886,-2.8536937812464656
2.480696292621842,0.0034744,166.947703118834,349.5104861869886,-2.8536937812464656
2.497832117806888,0.0034984,167.02317254900458,349.5104861869886,-2.8536937812464656
2.5143967488190992,0.0035215999999999997,167.0959346306669,349.5104861869886,-2.8536937812464656
2.5355309332139893,0.0035512,167.18849816667893,349.5104861869886,-2.8536937812464656
2.5429564574608428,0.0035616,167.22094899343705,349.5104861869886,-2.8536937812464656
2.5532379525718705,0.0035759999999999998,167.26581996438134,349.5104861869886,-2.8536937812464656
2.562948253510063,0.0035895999999999996,167.30813344261628,349.5104861869886,-2.8536937812464656
2.568089001065577,0.0035968,167.33050938168049,349.5104861869886,-2.8536937812464656
2.57551452531243,0.0036071999999999996,167.3627993673374,349.5104861869886,-2.8536937812464656
2.589223185460467,0.0036263999999999997,167.42231642183552,349.5104861869886,-2.8536937812464656
2.607501398991183,0.003652,167.5014816773402,349.5104861869886,-2.8536937812464656
2.615498117410871,0.0036631999999999997,167.5360483892888,349.5104861869886,-2.8536937812464656
2.6229236416577244,0.0036736,167.56810916223225,349.5104861869886,-2.8536937812464656
2.6400594668427706,0.0036975999999999997,167.64196076708583,349.5104861869886,-2.8536937812464656
2.64348663187978,0.0037024,167.656708628872,349.5104861869886,-2.8536937812464656
2.6509121561266333,0.0037128,167.68863677284688,349.5104861869886,-2.8536937812464656
2.681756641459716,0.003756,167.82088973607213,349.5104861869886,-2.8536937812464656
2.7074603792372853,0.003792,167.93064797529658,349.5104861869886,-2.8536937812464656
2.7148859034841384,0.0038023999999999996,167.96228015622702,349.5104861869886,-2.8536937812464656
2.7160282918298084,0.0038039999999999997,167.96714364914286,349.5104861869886,-2.8536937812464656
2.7291657578050104,0.0038223999999999997,168.02301659770933,349.5104861869886,-2.8536937812464656
2.7628662140022677,0.0038696,168.16586531148252,349.5104861869886,-2.8536937812464656
2.8205568254585898,0.0039504,168.4088355567005,349.5104861869886,-2.8536937812464656
2.831980708915287,0.0039664,168.45671774011151,349.5104861869886,-2.8536937812464656
2.8439757865448194,0.0039832,168.5069130309178,349.5104861869886,-2.8536937812464656
2.8553996700015167,0.0039992,168.55464136282777,349.5104861869886,-2.8536937812464656
2.883393669031397,0.004038407681536307,168.67128493669847,349.5104861869886,-2.8536937812464656
3.020507693316623,0.004230446089217844,169.23634390014328,349.5104861869886,-2.8536937812464656
3.2261787297444617,0.004518503700740148,170.0655209506813,349.5104861869886,-2.8536937812464656
3.418138363743778,0.004787357471494299,170.8209992725502,349.5104861869886,-2.8536937812464656
3.5552523880290043,0.004979395879175836,171.3505271858586,349.5104861869886,-2.8536937812464656
3.760923424456843,0.00526745349069814,172.13012086940478,349.5104861869886,-2.8536937812464656
3.939171656027637,0.0055171034206841375,172.79241019501626,349.5104861869886,-2.8536937812464656
4.419070741025927,0.006189237847569514,174.51979686675804,349.5104861869886,-2.8536937812464656
4.611030375025243,0.006458091618323665,175.1900556248656,349.5104861869886,-2.8536937812464656
5.145775069737624,0.007207041408281656,177.00210265886372,349.5104861869886,-2.8536937812464656
5.625674154735916,0.007879175835167033,178.5666039268474,349.5104861869886,-2.8536937812464656
6.119284642162729,0.008570514102820564,180.12237830412715,349.5104861869886,-2.8536937812464656
6.434646898018748,0.009012202440488098,181.09075726350272,349.5104861869886,-2.8536937812464656
6.544338117446929,0.009165833166633327,181.42322212513008,349.5104861869886,-2.8536937812464656
6.736297751446246,0.009434686937387478,181.9998527733439,349.5104861869886,-2.8536937812464656
6.9008345805885165,0.009665133026605321,182.48902502497253,349.5104861869886,-2.8536937812464656
7.0516600073022655,0.009876375275055011,182.9334514674692,349.5104861869886,-2.8536937812464656
7.188774031587491,0.010068413682736548,183.33426873786945,349.5104861869886,-2.8536937812464656
7.380733665586806,0.010337267453490697,183.89043954842157,349.5104861869886,-2.8536937812464656
7.92918976272771,0.011105421084216843,185.44923001077242,349.5104861869886,-2.8536937812464656
8.09372659186998,0.011335867173434686,185.90858984660056,349.5104861869886,-2.8536937812464656
8.354243238011913,0.011700740148029607,186.62853016352827,349.5104861869886,-2.8536937812464656
8.45022305501157,0.01183516703340668,186.89155728029445,349.5104861869886,-2.8536937812464656
8.614759884153841,0.012065613122624524,187.3397661594275,349.5104861869886,-2.8536937812464656
8.861565127867246,0.01241128225645129,188.00586953414137,349.5104861869886,-2.8536937812464656
9.204350188580312,0.012891378275655131,188.9191319713099,349.5104861869886,-2.8536937812464656
9.35517561529406,0.013102620524104821,189.31675455378942,349.5104861869886,-2.8536937812464656
9.889920310006442,0.013851570314062813,190.70679336205467,349.5104861869886,-2.8536937812464656
10.027034334291669,0.01404360872174435,191.05845238238865,349.5104861869886,-2.8536937812464656
10.232705370719508,0.014331666333266654,191.58244472896834,349.5104861869886,-2.8536937812464656
10.4109536022903,0.014581316263252651,192.03325761433132,349.5104861869886,-2.8536937812464656
10.72631585814632,0.015023004600920185,192.82354373190518,349.5104861869886,-2.8536937812464656
10.890852687288591,0.015253450690138028,193.2322664996034,349.5104861869886,-2.8536937812464656
11.000543906716773,0.015407081416283257,193.50341122838913,349.5104861869886,-2.8536937812464656
11.069100918859386,0.015503100620124026,193.6723413308409,349.5104861869886,-2.8536937812464656
11.192503540716089,0.01567593518703741,193.975390809772,349.5104861869886,-2.8536937812464656
11.50786579657211,0.016117623524704944,194.7439891035918,349.5104861869886,-2.8536937812464656
12.193435917998237,0.017077815563112622,196.38706843787332,349.5104861869886,-2.8536937812464656
12.46766396656869,0.017461892378475695,197.03416164663582,349.5104861869886,-2.8536937812464656
12.68704640542505,0.017769153830766153,197.54784829596855,349.5104861869886,-2.8536937812464656
12.810449027281752,0.017941988397679534,197.83527442192792,349.5104861869886,-2.8536937812464656
13.180656892851864,0.018460492098419684,198.6911426725959,349.5104861869886,-2.8536937812464656
13.276636709851523,0.01859491898379676,198.91149756152265,349.5104861869886,-2.8536937812464656
13.660555977850157,0.019132626525305063,199.786774405861,349.5104861869886,-2.8536937812464656
14.400971708990374,0.020169633926785356,201.44817560531337,349.5104861869886,-2.8536937812464656
15.141387440130595,0.021206641328265653,203.0765776605732,349.5104861869886,-2.8536937812464656
15.388192683844002,0.021552310462092418,203.61243698457892,349.5104861869886,-2.8536937812464656
15.634997927557407,0.021897979595919183,204.14495476763298,349.5104861869886,-2.8536937812464656
15.96407158584195,0.02235887177435487,204.84990647905937,349.5104861869886,-2.8536937812464656
16.142319817412744,0.02260852170434087,205.22938808079678,349.5104861869886,-2.8536937812464656
16.375413658697628,0.02293498699739948,205.72317647705668,349.5104861869886,-2.8536937812464656
16.978715365552624,0.02377995599119824,206.98865277823637,349.5104861869886,-2.8536937812464656
17.102117987409326,0.02395279055811162,207.2453261940768,349.5104861869886,-2.8536937812464656
17.33521182869421,0.024279255851170235,207.72819157799077,349.5104861869886,-2.8536937812464656
17.55459426755057,0.024586517303460693,208.18034512688575,349.5104861869886,-2.8536937812464656
17.773976706406934,0.02489377875575115,208.63030022285895,349.5104861869886,-2.8536937812464656
18.048204754977384,0.025277855571114224,209.1897097395268,349.5104861869886,-2.8536937812464656
18.459546827833062,0.025853970794158833,210.02264816789844,349.5104861869886,-2.8536937812464656
18.528103839975675,0.0259499899979996,210.16076444208116,349.5104861869886,-2.8536937812464656
18.747486278832035,0.026257251450290058,210.60140312724982,349.5104861869886,-2.8536937812464656
19.323365180829985,0.02706381276255251,211.74861598507897,349.5104861869886,-2.8536937812464656
19.40563359540112,0.027179035807161432,211.91140838619313,349.5104861869886,-2.8536937812464656
19.748418656114186,0.027659131826365275,212.58683309402198,349.5104861869886,-2.8536937812464656
19.871821277970888,0.027831966393278656,212.82886469147275,349.5104861869886,-2.8536937812464656
20.118626521684295,0.02817763552710542,213.3111765078845,349.5104861869886,-2.8536937812464656
20.543679996968496,0.028772954590918182,214.13645009247884,349.5104861869886,-2.8536937812464656
20.639659813968155,0.02890738147629526,214.32187739907434,349.5104861869886,-2.8536937812464656
20.749351033396337,0.02906101220244049,214.53338303323272,349.5104861869886,-2.8536937812464656
20.859042252824516,0.029214642928585718,214.74445304651223,349.5104861869886,-2.8536937812464656
20.90017646011008,0.029272254450890177,214.82349264349975,349.5104861869886,-2.8536937812464656
21.105847496537923,0.029560312062412483,215.2177842497368,349.5104861869886,-2.8536937812464656
21.215538715966105,0.029713942788557712,215.42746025908443,349.5104861869886,-2.8536937812464656
21.421209752393942,0.030002000400080015,215.81946672320487,349.5104861869886,-2.8536937812464656
21.640592191250303,0.030309261852370473,216.23599250677017,349.5104861869886,-2.8536937812464656
22.010800056820415,0.030827765553110623,216.93516474274213,349.5104861869886,-2.8536937812464656
22.10677987382007,0.030962192438487697,217.11568108155313,349.5104861869886,-2.8536937812464656
22.531833349104275,0.03155751150230046,217.9114645770773,349.5104861869886,-2.8536937812464656
22.641524568532454,0.03171114222844569,218.11587495391862,349.5104861869886,-2.8536937812464656
22.764927190389155,0.03188397679535907,218.34537553804586,349.5104861869886,-2.8536937812464656
23.36822889724415,0.03272894578915783,219.46046856224294,349.5104861869886,-2.8536937812464656
23.62874554338608,0.03309381876375275,219.93850873241254,349.5104861869886,-2.8536937812464656
23.998953408956194,0.0336123224644929,220.6143080324733,349.5104861869886,-2.8536937812464656
24.58854371338266,0.034438087617523504,221.68224719885973,349.5104861869886,-2.8536937812464656
24.68452353038232,0.03457251450290058,221.85514811415794,349.5104861869886,-2.8536937812464656
24.890194566810155,0.03486057211442288,222.22476966275534,349.5104861869886,-2.8536937812464656
25.191845420237655,0.035283056611322264,222.76473386282834,349.5104861869886,-2.8536937812464656
25.32895944452288,0.0354750950190038,223.00933796373494,349.5104861869886,-2.8536937812464656
26.096797980520144,0.0365505101020204,224.36969576077308,349.5104861869886,-2.8536937812464656
26.32989182180503,0.03687697539507902,224.7795610054837,349.5104861869886,-2.8536937812464656
26.82350230923184,0.03756831366273254,225.64286875761712,349.5104861869886,-2.8536937812464656
27.111441760230825,0.03797159431886378,226.1436036659559,349.5104861869886,-2.8536937812464656
27.371958406372745,0.03833646729345869,226.59486518975024,349.5104861869886,-2.8536937812464656
27.632475052514675,0.03870134026805361,227.04445475861888,349.5104861869886,-2.8536937812464656
27.701032064657287,0.038797359471894374,227.16249266944598,349.5104861869886,-2.8536937812464656
28.0712399302274,0.039315863172634524,227.79793945682084,349.5104861869886,-2.8536937812464656
28.13979694237001,0.03941188237647529,227.9152552514819,349.5104861869886,-2.8536937812464656
28.414024990940465,0.03979595919183837,228.3834080247877,349.5104861869886,-2.8536937812464656
28.688253039510915,0.040180036007201436,228.84980197447197,349.5104861869886,-2.8536937812464656
28.976192490509888,0.04058331666333266,229.33764820398935,349.5104861869886,-2.8536937812464656
29.360111758508523,0.04112102420484097,229.98517896102285,349.5104861869886,-2.8536937812464656
30.484446757647376,0.042695739147829564,231.86278697657482,349.5104861869886,-2.8536937812464656
30.635272184361124,0.042906981396279256,232.11259077903034,349.5104861869886,-2.8536937812464656
30.978057245074194,0.0433870774154831,232.6785497464632,349.5104861869886,-2.8536937812464656
31.07403706207385,0.04352150430086017,232.83657990194814,349.5104861869886,-2.8536937812464656
31.361976513072822,0.0439247849569914,233.30953211395317,349.5104861869886,-2.8536937812464656
31.567647549500656,0.0442128425685137,233.64631888278277,349.5104861869886,-2.8536937812464656
31.718472976214407,0.04442408481696339,233.8927522151559,349.5104861869886,-2.8536937812464656
32.0201238296419,0.04484656931386277,234.38425211306085,349.5104861869886,-2.8536937812464656
32.84280797535327,0.045998799759952,235.71561285114075,349.5104861869886,-2.8536937812464656
32.92507638992439,0.04611402280456091,235.8480295474782,349.5104861869886,-2.8536937812464656
33.254150048208935,0.046574914982996596,236.37641104429093,349.5104861869886,-2.8536937812464656
33.43239827977973,0.04682456491298259,236.66176609643188,349.5104861869886,-2.8536937812464656
33.61064651135053,0.0470742148429686,236.94652841587464,349.5104861869886,-2.8536937812464656
33.93972016963507,0.04753510702140429,237.47070089147056,349.5104861869886,-2.8536937812464656
34.81724992506051,0.04876415283056611,238.85889337197983,349.5104861869886,-2.8536937812464656
34.98178675420279,0.04899459891978396,239.11765330703767,349.5104861869886,-2.8536937812464656
35.07776657120244,0.04912902580516103,239.26837740321605,349.5104861869886,-2.8536937812464656
35.22859199791619,0.04934026805361072,239.50490499852634,349.5104861869886,-2.8536937812464656
35.530242851343694,0.0497627525505101,239.97677870460467,349.5104861869886,-2.8536937812464656
35.74962529020005,0.05007001400280056,240.31897879095004,349.5104861869886,-2.8536937812464656
35.95529632662789,0.05035807161432286,240.63904832085706,349.5104861869886,-2.8536937812464656
36.18839016791278,0.05068453690738148,241.000931859723,349.5104861869886,-2.8536937812464656
36.39406120434061,0.05097259451890378,241.31948660903333,349.5104861869886,-2.8536937812464656
36.6271550456255,0.051299059811962394,241.67966780311002,349.5104861869886,-2.8536937812464656
36.81911467962482,0.05156791358271655,241.97561685328336,349.5104861869886,-2.8536937812464656
37.052208520909694,0.05189437887577515,242.33417580224568,349.5104861869886,-2.8536937812464656
37.38128217919424,0.05235527105421084,242.8388826352885,349.5104861869886,-2.8536937812464656
37.87489266662106,0.05304660932186438,243.5927060115275,349.5104861869886,-2.8536937812464656
38.12169791033446,0.05339227845569114,243.9681801790212,349.5104861869886,-2.8536937812464656
38.38221455647639,0.05375715143028606,244.36348697503993,349.5104861869886,-2.8536937812464656
38.601596995332756,0.05406441288257652,244.69556594872557,349.5104861869886,-2.8536937812464656
38.79355662933207,0.05433326665333067,244.98553173311205,349.5104861869886,-2.8536937812464656
38.90324784876025,0.0544868973794759,245.1509752221737,349.5104861869886,-2.8536937812464656
39.25974431190184,0.05498619723944789,245.68741447890028,349.5104861869886,-2.8536937812464656
39.424281141044105,0.05521664332866573,245.93436076659717,349.5104861869886,-2.8536937812464656
39.7807776041857,0.055715943188637734,246.46803637091682,349.5104861869886,-2.8536937812464656
39.93160303089944,0.05592718543708741,246.6932603454386,349.5104861869886,-2.8536937812464656
40.30181089646955,0.05644568913782756,247.24468082318097,349.5104861869886,-2.8536937812464656
41.083360834895345,0.057540308061612325,248.4023451748315,349.5104861869886,-2.8536937812464656
41.16562924946648,0.05765553110622125,248.52370284000645,349.5104861869886,-2.8536937812464656
41.24789766403761,0.05777075415083016,248.64496595523224,349.5104861869886,-2.8536937812464656
41.41243449317989,0.05800120024004801,248.8872095826814,349.5104861869886,-2.8536937812464656
41.810065163607035,0.058558111622324466,249.47108722465066,349.5104861869886,-2.8536937812464656
42.49563528503317,0.059518303660732144,250.47271241619015,349.5104861869886,-2.8536937812464656
42.61903790688987,0.05969113822764553,250.65233366377416,349.5104861869886,-2.8536937812464656
42.838420345746236,0.05999839967993599,250.97116030132221,349.5104861869886,-2.8536937812464656
43.11264839431668,0.060382476495299056,251.36879954770734,349.5104861869886,-2.8536937812464656
43.661104491457586,0.0611506301260252,252.16113107493067,349.5104861869886,-2.8536937812464656
43.75708430845725,0.061285057011402286,252.29938906222472,349.5104861869886,-2.8536937812464656
43.83935272302838,0.0614002800560112,252.4178017991742,349.5104861869886,-2.8536937812464656
44.031312357027694,0.06166913382676535,252.69376167654366,349.5104861869886,-2.8536937812464656
45.07337894159542,0.06312862572514504,254.18372158797663,349.5104861869886,-2.8536937812464656
45.22420436830916,0.06333986797359471,254.39825549973574,349.5104861869886,-2.8536937812464656
45.498432416879616,0.06372394478895779,254.78760362848556,349.5104861869886,-2.8536937812464656
45.53956662416518,0.06378155631126226,254.8459268164899,349.5104861869886,-2.8536937812464656
45.64925784359337,0.06393518703740748,255.0013549600085,349.5104861869886,-2.8536937812464656
45.97833150187791,0.06439607921584317,255.4667677915896,349.5104861869886,-2.8536937812464656
46.10173412373461,0.06456891378275655,255.6409624504886,349.5104861869886,-2.8536937812464656
46.19771394073427,0.06470334066813363,255.77632149451338,349.5104861869886,-2.8536937812464656
46.4582305868762,0.06506821364272855,256.1431728901372,349.5104861869886,-2.8536937812464656
46.67761302573256,0.06537547509501901,256.4514785335826,349.5104861869886,-2.8536937812464656
46.746170037875174,0.06547149429885978,256.54770808621976,349.5104861869886,-2.8536937812464656
47.308337537444594,0.06625885177035407,257.33472498153026,349.5104861869886,-2.8536937812464656
47.65112259815766,0.06673894778955791,257.81282356197966,349.5104861869886,-2.8536937812464656
47.95277345158516,0.0671614322864573,258.23244187899223,349.5104861869886,-2.8536937812464656
48.405249731726414,0.06779515903180637,258.859944259717,349.5104861869886,-2.8536937812464656
48.89886021915322,0.0684864972994599,259.54188901745664,349.5104861869886,-2.8536937812464656
48.96741723129583,0.06858251650330066,259.63639079405743,349.5104861869886,-2.8536937812464656
49.18679967015219,0.06888977795559112,259.93845031544527,349.5104861869886,-2.8536937812464656
49.35133649929447,0.06912022404480897,260.1646502672925,349.5104861869886,-2.8536937812464656
49.927215401292415,0.06992678535707142,260.9540442982232,349.5104861869886,-2.8536937812464656
50.17402064500582,0.07027245449089818,261.29126809097664,349.5104861869886,-2.8536937812464656
50.3385574741481,0.07050290058011603,261.51572461696924,349.5104861869886,-2.8536937812464656
51.33948985143024,0.07190478095619124,262.875054619125,349.5104861869886,-2.8536937812464656
51.46289247328695,0.07207761552310463,263.0419245833252,349.5104861869886,-2.8536937812464656
51.5588722902866,0.0722120424084817,263.17160446826654,349.5104861869886,-2.8536937812464656
51.778254729142965,0.07251930386077216,263.4676626153395,349.5104861869886,-2.8536937812464656
52.038771375284895,0.07288417683536708,263.8185970195898,349.5104861869886,-2.8536937812464656
52.299288021426825,0.073249049809962,264.1688469178229,349.5104861869886,-2.8536937812464656
53.355066008423066,0.07472774554910983,265.5813695155683,349.5104861869886,-2.8536937812464656
53.57444844727942,0.07503500700140028,265.8735081080249,349.5104861869886,-2.8536937812464656
53.697851069136135,0.07520784156831367,266.0376310327897,349.5104861869886,-2.8536937812464656
53.999501922563624,0.07563032606521304,266.4382023733563,349.5104861869886,-2.8536937812464656
54.23259576384851,0.07595679135827166,266.74713734993963,349.5104861869886,-2.8536937812464656
54.4108439954193,0.07620644128825765,266.9830324590891,349.5104861869886,-2.8536937812464656
54.520535214847484,0.07636007201440288,267.12804888673935,349.5104861869886,-2.8536937812464656
54.959300092560206,0.0769745949189838,267.7069803360126,349.5104861869886,-2.8536937812464656
55.16497112898805,0.07726265253050611,267.97773369552795,349.5104861869886,-2.8536937812464656
55.27466234841623,0.07741628325665134,268.1219745011031,349.5104861869886,-2.8536937812464656
55.4391991775585,0.07764672934586918,268.33812657157534,349.5104861869886,-2.8536937812464656
55.67229301884338,0.0779731946389278,268.64391421952615,349.5104861869886,-2.8536937812464656
56.45384295726917,0.07906781356271254,269.6655778532406,349.5104861869886,-2.8536937812464656
57.92096301712109,0.08112262452490498,271.5686630739077,349.5104861869886,-2.8536937812464656
58.35972789483381,0.0817371474294859,272.13414589796173,349.5104861869886,-2.8536937812464656
58.46941911426199,0.08189077815563113,272.2752572321006,349.5104861869886,-2.8536937812464656
58.55168752883313,0.08200600120024006,272.38102298811305,349.5104861869886,-2.8536937812464656
58.70251295554688,0.08221724344868975,272.5747764704837,349.5104861869886,-2.8536937812464656
58.89447258954619,0.08248609721944389,272.82109125092717,349.5104861869886,-2.8536937812464656
59.23725765025926,0.08296619323864773,273.2601617169182,349.5104861869886,-2.8536937812464656
59.401794479401524,0.08319663932786557,273.4705634813671,349.5104861869886,-2.8536937812464656
59.5114856988297,0.0833502700540108,273.61070506697655,349.5104861869886,-2.8536937812464656
59.67602252797198,0.08358071614322865,273.8207287058016,349.5104861869886,-2.8536937812464656
60.05994179597061,0.08411842368473695,274.30990756627375,349.5104861869886,-2.8536937812464656
60.34788124696959,0.08452170434086818,274.67599180473843,349.5104861869886,-2.8536937812464656
60.49870667368333,0.08473294658931786,274.86747831293127,349.5104861869886,-2.8536937812464656
60.63582069796856,0.08492498499699941,275.04139545762513,349.5104861869886,-2.8536937812464656
61.06087417325276,0.08552030406081217,275.5795664600994,349.5104861869886,-2.8536937812464656
61.34881362425173,0.08592358471694339,275.94330406288833,349.5104861869886,-2.8536937812464656
61.82871270925003,0.08659571914382877,276.54805731157336,349.5104861869886,-2.8536937812464656
62.020672343249345,0.08686457291458292,276.7894456988995,349.5104861869886,-2.8536937812464656
62.43201441610503,0.08744068813762754,277.3057275541602,349.5104861869886,-2.8536937812464656
62.78851087924661,0.08793998799759953,277.75209967229125,349.5104861869886,-2.8536937812464656
63.021604720531485,0.08826645329065813,278.0434240542287,349.5104861869886,-2.8536937812464656
63.13129593995967,0.08842008401680336,278.18037244688526,349.5104861869886,-2.8536937812464656
63.336966976387515,0.08870814162832567,278.43690081806284,349.5104861869886,-2.8536937812464656
63.515215207958306,0.08895779155831167,278.65896273206926,349.5104861869886,-2.8536937812464656
63.707174841957624,0.08922664532906582,278.8978346997788,349.5104861869886,-2.8536937812464656
63.92655728081399,0.08953390678135628,279.1704877825668,349.5104861869886,-2.8536937812464656
64.02253709781364,0.08966833366673335,279.289658730622,349.5104861869886,-2.8536937812464656
64.69439581681125,0.09060932186437289,280.1219130914106,349.5104861869886,-2.8536937812464656
64.80408703623944,0.09076295259051811,280.25747061811865,349.5104861869886,-2.8536937812464656
65.29769752366624,0.09145429085817164,280.86637548215424,349.5104861869886,-2.8536937812464656
65.68161679166488,0.09199199839967995,281.3387279157257,349.5104861869886,-2.8536937812464656
65.87357642566418,0.09226085217043409,281.57450025207925,349.5104861869886,-2.8536937812464656
66.14780447423465,0.09264492898579717,281.91085359307465,349.5104861869886,-2.8536937812464656
66.367186913091,0.09295219043808763,282.17954487903535,349.5104861869886,-2.8536937812464656
66.50430093737623,0.09314422884576916,282.34730104317913,349.5104861869886,-2.8536937812464656
66.87450880294634,0.09366273254650931,282.7995702781699,349.5104861869886,-2.8536937812464656
67.06646843694566,0.09393158631726346,283.0336957751295,349.5104861869886,-2.8536937812464656
67.32698508308758,0.09429645929185837,283.3510199288435,349.5104861869886,-2.8536937812464656
67.53265611951542,0.09458451690338068,283.6012008671313,349.5104861869886,-2.8536937812464656
68.03997800937076,0.09529505901180237,284.21704672787024,349.5104861869886,-2.8536937812464656
68.08111221665634,0.09535267053410683,284.26690155234803,349.5104861869886,-2.8536937812464656
68.3690516676553,0.09575595119023805,284.6155569813095,349.5104861869886,-2.8536937812464656
68.57472270408314,0.09604400880176035,284.86424605215416,349.5104861869886,-2.8536937812464656
69.36998404493745,0.09715783156631327,285.8231192480263,349.5104861869886,-2.8536937812464656
69.87730593479279,0.09786837367473496,286.43257510965145,349.5104861869886,-2.8536937812464656
70.13782258093471,0.09823324664932986,286.7448681801273,349.5104861869886,-2.8536937812464656
70.23380239793438,0.09836767353470695,286.859809443743,349.5104861869886,-2.8536937812464656
70.87823831207494,0.09927025405081016,287.6299775583808,349.5104861869886,-2.8536937812464656
70.98792953150311,0.09942388477695539,287.76079754803067,349.5104861869886,-2.8536937812464656