File: datasets/aisi_316_L/data/M1/train_29.csv
Time(s),Strain(%),Stress(MPa),Temp(C),Log_SR(s-1)
0.0,0.0,0.0,133.2979612341216,4.025140027435305
2.642518302041919e-09,2.8e-05,5.3462416875,133.2979612341216,4.025140027435305
3.54852457702772e-09,3.76e-05,7.1792388375,133.2979612341216,4.025140027435305
5.209536081168354e-09,5.52e-05,10.5397336125,133.2979612341216,4.025140027435305
6.568545493647056e-09,6.96e-05,13.2892293375,133.2979612341216,4.025140027435305
7.77655386029479e-09,8.24e-05,15.7332255375,133.2979612341216,4.025140027435305
8.078555951956723e-09,8.56e-05,16.344224587499998,133.2979612341216,4.025140027435305
8.833561181111558e-09,9.36e-05,17.8717222125,133.2979612341216,4.025140027435305
1.2231084712308311e-08,0.0001296,24.745461525,133.2979612341216,4.025140027435305
1.2986089941463143e-08,0.00013759999999999998,26.27295915,133.2979612341216,4.025140027435305
1.4118597785195396e-08,0.0001496,28.564205587500002,133.2979612341216,4.025140027435305
1.4571600922688295e-08,0.00015439999999999999,29.480704162499997,133.2979612341216,4.025140027435305
1.6308112949744413e-08,0.0001728,32.9939487,133.2979612341216,4.025140027435305
2.068714327884245e-08,0.0002192,41.853434924999995,133.2979612341216,4.025140027435305
2.6576184066250158e-08,0.0002816,53.767916400000004,133.2979612341216,4.025140027435305
2.7935193478728857e-08,0.000296,56.517412125,133.2979612341216,4.025140027435305
2.8992200799545623e-08,0.0003072,58.6559088,133.2979612341216,4.025140027435305
2.9445203937038524e-08,0.000312,59.572407375,133.2979612341216,4.025140027435305
3.0124708643277874e-08,0.0003192,60.9471552375,133.2979612341216,4.025140027435305
3.0502211257855294e-08,0.0003232,61.710904049999996,133.2979612341216,4.025140027435305
3.118171596409465e-08,0.0003304,63.085651912500005,133.2979612341216,4.025140027435305
3.306922903698173e-08,0.0003504,66.904395975,133.2979612341216,4.025140027435305
3.3975235311967525e-08,0.00035999999999999997,68.737393125,133.2979612341216,4.025140027435305
3.676875465984042e-08,0.0003896,74.3891343375,133.2979612341216,4.025140027435305
3.812776407231912e-08,0.000404,77.1386300625,133.2979612341216,4.025140027435305
4.0317279236868134e-08,0.0004272,81.56837317499999,133.2979612341216,4.025140027435305
4.1525287603515864e-08,0.00043999999999999996,84.01236937499999,133.2979612341216,4.025140027435305
4.326179963057198e-08,0.0004584,87.52561391249999,133.2979612341216,4.025140027435305
4.462080904305069e-08,0.0004728,90.2751096375,133.2979612341216,4.025140027435305
4.537581427220552e-08,0.0004808,91.80260726249999,133.2979612341216,4.025140027435305
4.658382263885326e-08,0.0004936,94.24660346249999,133.2979612341216,4.025140027435305
4.696132525343067e-08,0.0004976,95.01035227499999,133.2979612341216,4.025140027435305
4.809383309716293e-08,0.0005096,97.30159871250001,133.2979612341216,4.025140027435305
4.907533989506421e-08,0.00052,99.28734562499999,133.2979612341216,4.025140027435305
4.9679344078388077e-08,0.0005264,100.509343725,133.2979612341216,4.025140027435305
5.1415856105444196e-08,0.0005448,104.02258826250001,133.2979612341216,4.025140027435305
5.2850366040838374e-08,0.00056,106.92483374999999,133.2979612341216,4.025140027435305
5.4133874930401596e-08,0.0005736,109.52157971249999,133.2979612341216,4.025140027435305
5.511538172830288e-08,0.000584,111.507326625,133.2979612341216,4.025140027435305
5.73048968928519e-08,0.0006072,115.9370697375,133.2979612341216,4.025140027435305
5.805990212200673e-08,0.0006152,117.46456736249999,133.2979612341216,4.025140027435305
5.8663906305330593e-08,0.0006215999999999999,118.68656546249998,133.2979612341216,4.025140027435305
6.070242042404866e-08,0.0006432,122.81080905,133.2979612341216,4.025140027435305
6.342043924900605e-08,0.000672,128.3098005,133.2979612341216,4.025140027435305
6.5911956505217e-08,0.0006984,133.3505426625,133.2979612341216,4.025140027435305
6.742196696352667e-08,0.0007144,136.4055379125,133.2979612341216,4.025140027435305
6.893197742183634e-08,0.0007304,139.46053316249998,133.2979612341216,4.025140027435305
7.021548631139957e-08,0.000744,142.057279125,133.2979612341216,4.025140027435305
7.210299938428664e-08,0.0007639999999999999,145.87602318749998,133.2979612341216,4.025140027435305
7.572702448422984e-08,0.0008024,153.2080117875,133.2979612341216,4.025140027435305
7.633102866755371e-08,0.0008087999999999999,154.43000988749998,133.2979612341216,4.025140027435305
7.723703494253951e-08,0.0008183999999999999,156.2630070375,133.2979612341216,4.025140027435305
7.874704540084919e-08,0.0008344,159.3180022875,133.2979612341216,4.025140027435305
8.123856265706014e-08,0.0008608,164.35874445,133.2979612341216,4.025140027435305
8.342807782160915e-08,0.0008839999999999999,168.7884875625,133.2979612341216,4.025140027435305
8.569309350907365e-08,0.000908,173.37098043749998,133.2979612341216,4.025140027435305
8.742960553612977e-08,0.0009264,176.884224975,133.2979612341216,4.025140027435305
8.886411547152396e-08,0.0009416,179.7864704625,133.2979612341216,4.025140027435305
9.112913115898846e-08,0.0009655999999999999,184.3689633375,133.2979612341216,4.025140027435305
9.143113325065039e-08,0.0009687999999999999,184.9799623875,133.2979612341216,4.025140027435305
9.331864632353749e-08,0.0009888,188.79870645,133.2979612341216,4.025140027435305
9.55081614880865e-08,0.0010119999999999999,193.22844956249997,133.2979612341216,4.025140027435305
9.641416776307229e-08,0.0010216,195.0614467125,133.2979612341216,4.025140027435305
9.69426714234807e-08,0.0010272,196.13069505,133.2979612341216,4.025140027435305
9.792417822138195e-08,0.0010375999999999999,198.11644196249998,133.2979612341216,4.025140027435305
1.0434172266919806e-07,0.0011056,211.100171775,133.2979612341216,4.025140027435305
1.069087404483245e-07,0.0011328,216.2936637,133.2979612341216,4.025140027435305
1.0736174358581738e-07,0.0011376,217.210162275,133.2979612341216,4.025140027435305
1.0894725456704254e-07,0.0011543999999999999,220.4179072875,133.2979612341216,4.025140027435305
1.1068376659409865e-07,0.0011727999999999999,223.93115182499997,133.2979612341216,4.025140027435305
1.1302428280447866e-07,0.0011976,228.66639446250002,133.2979612341216,4.025140027435305
1.1362828698780251e-07,0.001204,229.8883925625,133.2979612341216,4.025140027435305
1.146097937857038e-07,0.0012144,231.874139475,133.2979612341216,4.025140027435305
1.177808157481541e-07,0.001248,238.2896295,133.2979612341216,4.025140027435305
1.1830931940856247e-07,0.0012536,239.3588778375,133.2979612341216,4.025140027435305
1.1989483038978762e-07,0.0012703999999999999,242.56662285,133.2979612341216,4.025140027435305
1.20574335096027e-07,0.0012776,243.9413707125,133.2979612341216,4.025140027435305
1.2080083666477344e-07,0.0012799999999999999,244.39961999999997,133.2979612341216,4.025140027435305
1.223108471230831e-07,0.0012959999999999998,247.45461524999996,133.2979612341216,4.025140027435305
1.2359435601264632e-07,0.0013096,250.05136121249998,133.2979612341216,4.025140027435305
1.2623687431468824e-07,0.0013376,255.3976029,133.2979612341216,4.025140027435305
1.2691637902092758e-07,0.0013448,256.77235076249997,133.2979612341216,4.025140027435305
1.2895489313964565e-07,0.0013664,258.1793859013645,133.2979612341216,4.025140027435305
1.2933239575422306e-07,0.0013704,258.20876938257135,133.2979612341216,4.025140027435305
1.2978539889171596e-07,0.0013752,258.24398544456506,133.2979612341216,4.025140027435305
1.3121990882711014e-07,0.0013904,258.3551880304899,133.2979612341216,4.025140027435305
1.3212591510209596e-07,0.0014,258.4251770231839,133.2979612341216,4.025140027435305
1.3303192137708176e-07,0.0014096,258.49497909361725,133.2979612341216,4.025140027435305
1.3695794856868688e-07,0.0014512,258.7953372781758,133.2979612341216,4.025140027435305
1.3922296425615137e-07,0.0014751999999999999,258.9670931957117,133.2979612341216,4.025140027435305
1.4111047732903848e-07,0.0014952,259.1093922178473,133.2979612341216,4.025140027435305
1.4382849615399587e-07,0.001524,259.3130055401279,133.2979612341216,4.025140027435305
1.447345024289817e-07,0.0015336,259.380542440535,133.2979612341216,4.025140027435305
1.473770207310236e-07,0.0015616,259.576589624856,133.2979612341216,4.025140027435305
1.4783002386851648e-07,0.0015664,259.6100595904331,133.2979612341216,4.025140027435305
1.4888703118933326e-07,0.0015776,259.6880010074583,133.2979612341216,4.025140027435305
1.4986853798723455e-07,0.001588,259.76018217033925,133.2979612341216,4.025140027435305
1.510010458309668e-07,0.0015999999999999999,259.84323943537544,133.2979612341216,4.025140027435305
1.518315515830371e-07,0.0016087999999999999,259.90399377441025,133.2979612341216,4.025140027435305
1.5228455472053002e-07,0.0016136,259.93707787294454,133.2979612341216,4.025140027435305
1.532660615184313e-07,0.001624,260.0086287012606,133.2979612341216,4.025140027435305
1.5432306883924806e-07,0.0016351999999999998,260.0854838836817,133.2979612341216,4.025140027435305
1.5447406988507902e-07,0.0016367999999999999,260.09644641313554,133.2979612341216,4.025140027435305
1.5477607197674096e-07,0.00164,260.11835894231086,133.2979612341216,4.025140027435305
1.556065777288113e-07,0.0016488,260.1785325857737,133.2979612341216,4.025140027435305
1.5855109812251512e-07,0.0016799999999999999,260.39087355889296,133.2979612341216,4.025140027435305
1.592306028287545e-07,0.0016872,260.4396562512945,133.2979612341216,4.025140027435305
1.6036311067248674e-07,0.0016991999999999999,260.5207807050198,133.2979612341216,4.025140027435305
1.6209962269954284e-07,0.0017176,260.6447389159157,133.2979612341216,4.025140027435305
1.6527064466199315e-07,0.0017511999999999998,260.86976922345355,133.2979612341216,4.025140027435305
1.6753566034945767e-07,0.0017752,261.02947539981733,133.2979612341216,4.025140027435305
1.68215165055697e-07,0.0017824,261.0772227580552,133.2979612341216,4.025140027435305
1.6934767289942926e-07,0.0017943999999999998,261.1566348684717,133.2979612341216,4.025140027435305
1.7576521734724534e-07,0.0018624,261.6027849511238,133.2979612341216,4.025140027435305
1.800687471534279e-07,0.001908,261.8984142355582,133.2979612341216,4.025140027435305
1.8120125499716014e-07,0.0019199999999999998,261.97575180972717,133.2979612341216,4.025140027435305
1.845232780054414e-07,0.0019552,262.20152852996466,133.2979612341216,4.025140027435305
1.859577879408356e-07,0.0019703999999999998,262.29853233831784,133.2979612341216,4.025140027435305
1.8678829369290593e-07,0.0019792,262.35455904806713,133.2979612341216,4.025140027435305
1.8754329892206074e-07,0.0019871999999999997,262.40540817190725,133.2979612341216,4.025140027435305
1.914693261136659e-07,0.0020288,262.66854762195743,133.2979612341216,4.025140027435305
1.9350784023238396e-07,0.0020504,262.8043472461206,133.2979612341216,4.025140027435305
1.9667886219483424e-07,0.002084,263.01448736006245,133.2979612341216,4.025140027435305
1.973583669010736e-07,0.0020912,263.05934500186186,133.2979612341216,4.025140027435305
2.0052938886352392e-07,0.0021248,263.2678893868535,133.2979612341216,4.025140027435305
2.0075589043227037e-07,0.0021272,263.28273601566593,133.2979612341216,4.025140027435305
2.0226590089058002e-07,0.0021432,263.38154712218846,133.2979612341216,4.025140027435305
2.0302090611973484e-07,0.0021512,263.4308447607874,133.2979612341216,4.025140027435305
2.038514118718052e-07,0.00216,263.4849896557244,133.2979612341216,4.025140027435305
2.0551242337594583e-07,0.0021776,263.59302204345556,133.2979612341216,4.025140027435305
2.059654265134387e-07,0.0021823999999999997,263.62242625376746,133.2979612341216,4.025140027435305
2.0785293958632578e-07,0.0022023999999999998,263.74467329609786,133.2979612341216,4.025140027435305
2.088344463842271e-07,0.0022128,263.80807061249635,133.2979612341216,4.025140027435305
2.0951395109046641e-07,0.0022199999999999998,263.8518930058394,133.2979612341216,4.025140027435305
2.1079745998002967e-07,0.0022336,263.93451770082595,133.2979612341216,4.025140027435305
2.1117496259460705e-07,0.0022375999999999997,263.958781711664,133.2979612341216,4.025140027435305
2.1540299187787414e-07,0.0022824,264.22939296050305,133.2979612341216,4.025140027435305
2.164599991986909e-07,0.0022936,264.2967211099518,133.2979612341216,4.025140027435305
2.1789450913408508e-07,0.0023087999999999997,264.3878902968198,133.2979612341216,4.025140027435305
2.2068802848195798e-07,0.0023384,264.5647612993445,133.2979612341216,4.025140027435305
2.242365530589857e-07,0.002376,264.7881812750304,133.2979612341216,4.025140027435305
2.2491605776522504e-07,0.0023832,264.8308060706546,133.2979612341216,4.025140027435305
2.2574656351729538e-07,0.002392,264.88283490079306,133.2979612341216,4.025140027435305
2.2944608914015402e-07,0.0024311999999999997,265.1136987165939,133.2979612341216,4.025140027435305
2.3027659489222435e-07,0.00244,265.1653252235396,133.2979612341216,4.025140027435305
2.3110710064429466e-07,0.0024487999999999997,265.21687916569834,133.2979612341216,4.025140027435305
2.3276811214843534e-07,0.0024664,265.3197708014213,133.2979612341216,4.025140027435305
2.3329661580884368e-07,0.002472,265.3524489468167,133.2979612341216,4.025140027435305
2.3397612051508305e-07,0.0024792,265.39442131389933,133.2979612341216,4.025140027435305
2.351086283588153e-07,0.0024912,265.4642697711352,133.2979612341216,4.025140027435305
2.3752464509211077e-07,0.0025168,265.61284276403626,133.2979612341216,4.025140027435305
2.3805314875251913e-07,0.0025223999999999997,265.6452644070459,133.2979612341216,4.025140027435305
2.394121581649979e-07,0.0025368,265.72850570729975,133.2979612341216,4.025140027435305
2.3978966077957523e-07,0.0025407999999999997,265.7515955605457,133.2979612341216,4.025140027435305
2.400161623483217e-07,0.0025432,265.76544266777654,133.2979612341216,4.025140027435305
2.420546764670398e-07,0.0025648,265.8898381398282,133.2979612341216,4.025140027435305
2.43187184310772e-07,0.0025767999999999998,265.95877017391973,133.2979612341216,4.025140027435305
2.4394218953992686e-07,0.0025848,266.00465532359175,133.2979612341216,4.025140027435305
2.442441916315888e-07,0.002588,266.0229938713884,133.2979612341216,4.025140027435305
2.4567870156698296e-07,0.0026032,266.1099814944176,133.2979612341216,4.025140027435305
2.4854772143777133e-07,0.0026336,266.283364743411,133.2979612341216,4.025140027435305
2.496802292815036e-07,0.0026455999999999997,266.35159041981245,133.2979612341216,4.025140027435305
2.50057731896081e-07,0.0026496,266.3743054781438,133.2979612341216,4.025140027435305
2.505862355564894e-07,0.0026552,266.4060841045316,133.2979612341216,4.025140027435305
2.5217174653771456e-07,0.002672,266.5012635187201,133.2979612341216,4.025140027435305
2.5337975490436227e-07,0.0026847999999999998,266.5736245989374,133.2979612341216,4.025140027435305
2.5488976536267195e-07,0.0027007999999999997,266.66388702420755,133.2979612341216,4.025140027435305
2.5723028157305193e-07,0.0027256,266.80338273786487,133.2979612341216,4.025140027435305
2.579097862792913e-07,0.0027328,266.8437886617328,133.2979612341216,4.025140027435305
2.607033056271642e-07,0.0027624,267.0094675796704,133.2979612341216,4.025140027435305
2.61458310856319e-07,0.0027703999999999997,267.0541266313099,133.2979612341216,4.025140027435305
2.617603129479809e-07,0.0027735999999999998,267.07197616608204,133.2979612341216,4.025140027435305
2.6213781556255837e-07,0.0027776,267.09427679426983,133.2979612341216,4.025140027435305
2.642518302041919e-07,0.0028,267.2189296248904,133.2979612341216,4.025140027435305
2.6545983857083963e-07,0.0028128,267.2899851917858,133.2979612341216,4.025140027435305
2.68177857395797e-07,0.0028415999999999997,267.4494007580223,133.2979612341216,4.025140027435305
2.7165088144990927e-07,0.0028783999999999997,267.65218441827284,133.2979612341216,4.025140027435305
2.720283840644867e-07,0.0028824,267.6741650254698,133.2979612341216,4.025140027435305
2.7550140811859893e-07,0.0029192,267.8758315103902,133.2979612341216,4.025140027435305
2.764074143935847e-07,0.0029288,267.9282767933691,133.2979612341216,4.025140027435305
2.773134206685705e-07,0.0029384,267.98065507617434,133.2979612341216,4.025140027435305
2.77539922237317e-07,0.0029408,267.9937392137841,133.2979612341216,4.025140027435305
2.804089421081053e-07,0.0029712,268.15911280649095,133.2979612341216,4.025140027435305
2.8214545413516147e-07,0.0029896,268.2588868075902,133.2979612341216,4.025140027435305
2.8312696093306275e-07,0.003,268.3151748667188,133.2979612341216,4.025140027435305
2.8357996407055565e-07,0.0030047999999999997,268.34112829869554,133.2979612341216,4.025140027435305
2.8516547505178077e-07,0.0030215999999999997,268.4318382535247,133.2979612341216,4.025140027435305
2.8546747714344273e-07,0.0030248,268.4490940168093,133.2979612341216,4.025140027435305
2.8576947923510465e-07,0.003028,268.4663426620182,133.2979612341216,4.025140027435305
2.887139996288085e-07,0.0030591999999999998,268.63414605513833,133.2979612341216,4.025140027435305
2.893180038121324e-07,0.0030656,268.6684846197692,133.2979612341216,4.025140027435305
2.902995106100336e-07,0.0030759999999999997,268.72422521759694,133.2979612341216,4.025140027435305
2.9128101740793497e-07,0.0030864,268.77989236438845,133.2979612341216,4.025140027435305
2.915075189766814e-07,0.0030888,268.7927282344776,133.2979612341216,4.025140027435305
2.9211152316000527e-07,0.0030951999999999998,268.826938219551,133.2979612341216,4.025140027435305
2.9279102786624464e-07,0.0031024,268.8653914945542,133.2979612341216,4.025140027435305
2.9430103832455427e-07,0.0031184,268.9507188283007,133.2979612341216,4.025140027435305
2.9671705505784974e-07,0.0031439999999999997,269.0868882752892,133.2979612341216,4.025140027435305
2.9724555871825813e-07,0.0031496,269.1166176216532,133.2979612341216,4.025140027435305
2.97849562901582e-07,0.003156,269.1505687863842,133.2979612341216,4.025140027435305
2.988310696994833e-07,0.0031663999999999998,269.2056822168306,133.2979612341216,4.025140027435305
3.00190079111962e-07,0.0031807999999999997,269.2818767142657,133.2979612341216,4.025140027435305
3.019265911390181e-07,0.0031991999999999997,269.3790408631769,133.2979612341216,4.025140027435305
3.0260609584525746e-07,0.0032064,269.4170022599912,133.2979612341216,4.025140027435305
3.0388960473482067e-07,0.0032199999999999998,269.4886165393897,133.2979612341216,4.025140027435305
3.0449360891814455e-07,0.0032264,269.5222765502201,133.2979612341216,4.025140027435305
3.0623012094520065e-07,0.0032448,269.61890433553714,133.2979612341216,4.025140027435305
3.0887263924724254e-07,0.0032727999999999998,269.7655376047969,133.2979612341216,4.025140027435305
3.1083565284304517e-07,0.0032936,269.874148660322,133.2979612341216,4.025140027435305
3.124211638242703e-07,0.0033104,269.9616778175113,133.2979612341216,4.025140027435305
3.1400667480549545e-07,0.0033271999999999998,270.0490339059426,133.2979612341216,4.025140027435305
3.1461067898881933e-07,0.0033336,270.08226714587056,133.2979612341216,4.025140027435305
3.1634719101587543e-07,0.003352,270.1776743863532,133.2979612341216,4.025140027435305
3.18159203565847e-07,0.0033712,270.27701226077664,133.2979612341216,4.025140027435305
3.197447145470722e-07,0.003388,270.3637520424129,133.2979612341216,4.025140027435305
3.2216073128036767e-07,0.0034135999999999997,270.49560508724545,133.2979612341216,4.025140027435305
3.2623775951780375e-07,0.0034568,270.7172359696518,133.2979612341216,4.025140027435305
3.302392872323244e-07,0.0034992,270.93371460779696,133.2979612341216,4.025140027435305
3.336368107635211e-07,0.0035351999999999996,271.116715387978,133.2979612341216,4.025140027435305
3.3401431337809855e-07,0.0035391999999999997,271.1370038450984,133.2979612341216,4.025140027435305
3.3507132069891533e-07,0.0035504,271.1937640051081,133.2979612341216,4.025140027435305
3.355243238364082e-07,0.0035551999999999997,271.2180684063718,133.2979612341216,4.025140027435305
3.36430330111394e-07,0.0035648,271.26663885032224,133.2979612341216,4.025140027435305
3.3884634684468945e-07,0.0035903999999999997,271.395911288673,133.2979612341216,4.025140027435305
3.406583593946611e-07,0.0036095999999999997,271.4926298438804,133.2979612341216,4.025140027435305
3.414133646238159e-07,0.0036176,271.53287000146116,133.2979612341216,4.025140027435305
3.4262137299046366e-07,0.0036303999999999998,271.59718214222755,133.2979612341216,4.025140027435305
3.4360287978836495e-07,0.0036408,271.64937066577903,133.2979612341216,4.025140027435305
3.4390488188002687e-07,0.0036439999999999997,271.665416971979,133.2979612341216,4.025140027435305
3.4594339599874493e-07,0.0036655999999999998,271.7735861554473,133.2979612341216,4.025140027435305
3.477554085487165e-07,0.0036848,271.86952802632305,133.2979612341216,4.025140027435305
3.494919205757726e-07,0.0037032,271.96128953531297,133.2979612341216,4.025140027435305
3.5039792685075847e-07,0.0037128,272.00909450793245,133.2979612341216,4.025140027435305
3.521344388778145e-07,0.0037311999999999996,272.1005861762445,133.2979612341216,4.025140027435305
3.5341794776737777e-07,0.0037448,272.16809739998746,133.2979612341216,4.025140027435305
3.5507895927151843e-07,0.0037624,272.2553230943079,133.2979612341216,4.025140027435305
3.5621146711525065e-07,0.0037744,272.3147039409428,133.2979612341216,4.025140027435305
3.580234796652223e-07,0.0037936,272.4095603783203,133.2979612341216,4.025140027435305
3.596844911693629e-07,0.0038112,272.49634776344305,133.2979612341216,4.025140027435305
3.610435005818416e-07,0.0038255999999999997,272.5672394233271,133.2979612341216,4.025140027435305
3.6330851626930614e-07,0.0038496,272.6851613613676,133.2979612341216,4.025140027435305
3.6436552359012286e-07,0.0038607999999999997,272.7400934455844,133.2979612341216,4.025140027435305
3.6768754659840413e-07,0.0038959999999999997,272.9123339252126,133.2979612341216,4.025140027435305
3.689710554879674e-07,0.0039096,272.9787187081956,133.2979612341216,4.025140027435305
3.7131157169834737e-07,0.0039344,273.0995419213599,133.2979612341216,4.025140027435305
3.738785894774738e-07,0.0039616,273.2317166877308,133.2979612341216,4.025140027435305
3.7599260411910733e-07,0.003984,273.34030094979914,133.2979612341216,4.025140027435305
3.7712511196283955e-07,0.0039959999999999996,273.39837313566306,133.2979612341216,4.025140027435305
4.0287586492708936e-07,0.004268853770754151,274.7009968835644,133.2979612341216,4.025140027435305
4.427481154765745e-07,0.004691338267653531,276.6556166937313,133.2979612341216,4.025140027435305
4.663089908012703e-07,0.004940988197639528,277.77833450814217,133.2979612341216,4.025140027435305
5.043688663257788e-07,0.005344268853770755,279.546291952265,133.2979612341216,4.025140027435305
5.351792417503809e-07,0.005670734146829366,280.9396587614696,133.2979612341216,4.025140027435305
5.641772421500064e-07,0.005977995599119824,282.2227416418808,133.2979612341216,4.025140027435305
6.040494926994916e-07,0.006400480096019204,283.94573766751984,133.2979612341216,4.025140027435305
6.257979929992108e-07,0.006630926185237048,284.8668296020781,133.2979612341216,4.025140027435305
6.674826185736726e-07,0.007072614522904581,286.5980800079068,133.2979612341216,4.025140027435305
6.96480618973298e-07,0.007379875975195039,287.77762940640304,133.2979612341216,4.025140027435305
7.490394946976194e-07,0.007936787357471494,289.86784909873114,133.2979612341216,4.025140027435305
7.653508699224087e-07,0.008109621924384877,290.5047997073069,133.2979612341216,4.025140027435305
8.015983704219407e-07,0.00849369873974795,291.90158941614504,133.2979612341216,4.025140027435305
8.54157246146262e-07,0.009050610122024405,293.8839400291645,133.2979612341216,4.025140027435305
8.740933714210046e-07,0.009261852370474095,294.623345632603,133.2979612341216,4.025140027435305
8.867799965958408e-07,0.00939627925585117,295.0904539063529,133.2979612341216,4.025140027435305
9.012789967956535e-07,0.0095499099819964,295.62111237570326,133.2979612341216,4.025140027435305
9.212151220703961e-07,0.00976115223044609,296.3453632691135,133.2979612341216,4.025140027435305
9.447759973950919e-07,0.010010802160432087,297.1934618312359,133.2979612341216,4.025140027435305
1.011833873319226e-06,0.01072134426885377,299.56326694013256,133.2979612341216,4.025140027435305
1.0299576235689918e-06,0.010913382676535306,300.193135746822,133.2979612341216,4.025140027435305
1.0480813738187578e-06,0.011105421084216843,300.8186965033022,133.2979612341216,4.025140027435305
1.1151392497428918e-06,0.011815963192638527,303.0974721903605,133.2979612341216,4.025140027435305
1.1205763748178217e-06,0.011873574714942988,303.2798619619481,133.2979612341216,4.025140027435305
1.1387001250675876e-06,0.012065613122624524,303.8853504867011,133.2979612341216,4.025140027435305
1.1658857504422367e-06,0.012353670734146829,304.78658318840036,133.2979612341216,4.025140027435305
1.2057580009917217e-06,0.012776155231046209,306.0937046263021,133.2979612341216,4.025140027435305
1.2347560013913474e-06,0.013083416683336667,307.0337726186881,133.2979612341216,4.025140027435305
1.240193126466277e-06,0.013141028205641128,307.2090726719616,133.2979612341216,4.025140027435305
1.2510673766161366e-06,0.01325625125025005,307.5587761761589,133.2979612341216,4.025140027435305
1.3090633774153878e-06,0.013870774154830966,309.4042136412099,133.2979612341216,4.025140027435305
1.3163128775152942e-06,0.013947589517903581,309.63262991193716,133.2979612341216,4.025140027435305
1.3271871276651538e-06,0.014062812562512503,309.97433656379445,133.2979612341216,4.025140027435305
1.3453108779149197e-06,0.01425485097019404,310.54143111489594,133.2979612341216,4.025140027435305
1.3779336283644986e-06,0.014600520104020805,311.55474921466606,133.2979612341216,4.025140027435305
1.4558657544384922e-06,0.015426285257051411,313.93830676375757,133.2979612341216,4.025140027435305
1.4884885048880709e-06,0.015771954390878175,314.9212368982582,133.2979612341216,4.025140027435305
1.5084246301628135e-06,0.015983196639327867,315.51778154509924,133.2979612341216,4.025140027435305
1.5283607554375564e-06,0.01619443888777756,316.1112591410827,133.2979612341216,4.025140027435305
1.551921630762252e-06,0.016444088817763554,316.8087632851452,133.2979612341216,4.025140027435305
1.562795880912111e-06,0.016559311862372472,317.129294183905,133.2979612341216,4.025140027435305
1.5899815062867603e-06,0.01684736947389478,317.92683926106616,133.2979612341216,4.025140027435305
1.6552270071859179e-06,0.01753870774154831,319.8195541532246,133.2979612341216,4.025140027435305
1.6606641322608478e-06,0.017596319263852772,319.97595485916474,133.2979612341216,4.025140027435305
1.7005363828103326e-06,0.01801880376075215,321.1168528890103,133.2979612341216,4.025140027435305
1.7367838833098645e-06,0.01840288057611522,322.14501125018785,133.2979612341216,4.025140027435305
1.7730313838093965e-06,0.018786957391478294,323.16483417838685,133.2979612341216,4.025140027435305
1.825590259533718e-06,0.01934386877375475,324.629250994556,133.2979612341216,4.025140027435305
1.883586260332969e-06,0.019958391678335668,326.2262064348297,133.2979612341216,4.025140027435305
1.9270832609324075e-06,0.020419283856771355,327.4113673059548,133.2979612341216,4.025140027435305
1.9415822611322203e-06,0.020572914582916584,327.8040964477866,133.2979612341216,4.025140027435305
2.0195143872062137e-06,0.02139867973594719,329.8957371134003,133.2979612341216,4.025140027435305
2.077510388005465e-06,0.022013202640528105,331.4319328066649,133.2979612341216,4.025140027435305
2.104696013380114e-06,0.02230126025205041,332.1462584459613,133.2979612341216,4.025140027435305
2.153630139054482e-06,0.022819763952790558,333.4230418185912,133.2979612341216,4.025140027435305
2.1663167642293182e-06,0.022954190838167635,333.7522065155431,133.2979612341216,4.025140027435305
2.2098137648287565e-06,0.023415083016603323,334.87510725019024,133.2979612341216,4.025140027435305
2.229749890103499e-06,0.02362632526505301,335.3868859612584,133.2979612341216,4.025140027435305
2.247873640353265e-06,0.023818363672734547,335.8505928417081,133.2979612341216,4.025140027435305
2.275059265727914e-06,0.02410642128425685,336.54342856427354,133.2979612341216,4.025140027435305
2.3312428915021885e-06,0.024701740348069615,337.96514026797905,133.2979612341216,4.025140027435305
2.3439295166770246e-06,0.02483616723344669,338.2843151486085,133.2979612341216,4.025140027435305
2.3747398921016268e-06,0.025162632526505302,339.0566620721596,133.2979612341216,4.025140027435305
2.436360642950831e-06,0.025815563112622526,340.5897302802887,133.2979612341216,4.025140027435305
2.447234893100691e-06,0.025930786157231447,340.8586944434683,133.2979612341216,4.025140027435305
2.450859643150644e-06,0.025969193838767755,340.94824553326725,133.2979612341216,4.025140027435305
2.505230893899942e-06,0.026545309061812364,342.28537398218594,133.2979612341216,4.025140027435305
2.517917519074778e-06,0.026679735947189438,342.5957363798259,133.2979612341216,4.025140027435305
2.5287917692246377e-06,0.02679495899179836,342.8612761970346,133.2979612341216,4.025140027435305
2.5704763947990993e-06,0.027236647329465895,343.87507984098545,133.2979612341216,4.025140027435305
2.613973395398538e-06,0.027697539507901582,344.9261492909603,133.2979612341216,4.025140027435305
2.6429713957981634e-06,0.02800480096019204,345.62307517744114,133.2979612341216,4.025140027435305
2.6973426465474614e-06,0.02858091618323665,346.9218256641396,133.2979612341216,4.025140027435305
2.7408396471468992e-06,0.029041808361672333,347.9534895710834,133.2979612341216,4.025140027435305
2.7843366477463375e-06,0.02950270054010802,348.978787619928,133.2979612341216,4.025140027435305
2.7988356479461502e-06,0.02965633126625325,349.3191629704729,133.2979612341216,4.025140027435305
2.845957398595542e-06,0.030155631126225244,350.42066373984613,133.2979612341216,4.025140027435305
2.8749553989951674e-06,0.030462892578515702,351.0949758583095,133.2979612341216,4.025140027435305
2.885829649145027e-06,0.030578115623124624,351.34715838424745,133.2979612341216,4.025140027435305
2.8985162743198636e-06,0.0307125425085017,351.64090340944745,133.2979612341216,4.025140027435305
2.927514274719489e-06,0.03101980396079216,352.3104441851626,133.2979612341216,4.025140027435305
2.9510751500441845e-06,0.031269453890778155,352.8525435695694,133.2979612341216,4.025140027435305
2.983697900493764e-06,0.031615123024604924,353.6003643641188,133.2979612341216,4.025140027435305
3.009071150843436e-06,0.03188397679535907,354.17980033167885,133.2979612341216,4.025140027435305
3.025382526068225e-06,0.03205681136227245,354.5512888918666,133.2979612341216,4.025140027435305
3.047131026367945e-06,0.0322872574514903,355.0453941653162,133.2979612341216,4.025140027435305
3.072504276717617e-06,0.03255611122224445,355.62011534346726,133.2979612341216,4.025140027435305
3.092440401992359e-06,0.032767353470694136,356.0703844656344,133.2979612341216,4.025140027435305
3.146811652741657e-06,0.03334346869373875,357.2926737360922,133.2979612341216,4.025140027435305
3.2609912793151822e-06,0.03455331066213242,359.8329906164317,133.2979612341216,4.025140027435305
3.2899892797148077e-06,0.03486057211442288,360.4725969302405,133.2979612341216,4.025140027435305
3.338923405389176e-06,0.03537907581516303,361.5469693667357,133.2979612341216,4.025140027435305
3.4096060313632644e-06,0.03612802560512103,363.088062184104,133.2979612341216,4.025140027435305
3.496600032562141e-06,0.037049809961992405,364.96779229329934,133.2979612341216,4.025140027435305
3.531035158036695e-06,0.03741468293658731,365.70680244351973,133.2979612341216,4.025140027435305
3.5835940337610177e-06,0.03797159431886378,366.82936927481774,133.2979612341216,4.025140027435305
3.628903409385432e-06,0.03845169033806761,367.7919553988004,133.2979612341216,4.025140027435305
3.6524642847101272e-06,0.03870134026805361,368.2906471211734,133.2979612341216,4.025140027435305
3.6778375350598e-06,0.03897019403880776,368.8262987544791,133.2979612341216,4.025140027435305
3.732208785809098e-06,0.039546309261852375,369.96929461946576,133.2979612341216,4.025140027435305
3.752144911083841e-06,0.03975755151030207,370.38676362475974,133.2979612341216,4.025140027435305
3.792017161633325e-06,0.040180036007201436,371.21911544739527,133.2979612341216,4.025140027435305
3.844576037357647e-06,0.04073694738947789,372.3111099259473,133.2979612341216,4.025140027435305
3.888073037957085e-06,0.04119783956791358,373.210433333975,133.2979612341216,4.025140027435305
3.920695788406665e-06,0.04154350870174035,373.8823531371383,133.2979612341216,4.025140027435305
3.931570038556523e-06,0.041658731746349265,374.105841405217,133.2979612341216,4.025140027435305
3.9424442887063826e-06,0.04177395479095819,374.3290887276477,133.2979612341216,4.025140027435305
3.962380413981125e-06,0.04198519703940788,374.7377527559264,133.2979612341216,4.025140027435305
4.020376414780377e-06,0.0425997199439888,375.92205859440827,133.2979612341216,4.025140027435305
4.036687790005167e-06,0.042772554510902186,376.25394171162026,133.2979612341216,4.025140027435305
4.045749665130049e-06,0.04286857371474295,376.43809521609927,133.2979612341216,4.025140027435305
4.0892466657294876e-06,0.04332946589317864,377.31980253214687,133.2979612341216,4.025140027435305
4.141805541453809e-06,0.043886377275455093,378.3803337591225,133.2979612341216,4.025140027435305
4.159929291703575e-06,0.044078415683136626,378.7448155064785,133.2979612341216,4.025140027435305
4.176240666928365e-06,0.044251250250050014,379.0723199169008,133.2979612341216,4.025140027435305
4.1853025420532475e-06,0.04434726945389078,379.25405124117003,133.2979612341216,4.025140027435305
4.281358418377007e-06,0.04536507301460292,381.1710623350943,133.2979612341216,4.025140027435305
4.317605918876538e-06,0.04574914982996599,381.8900942163995,133.2979612341216,4.025140027435305
4.333917294101328e-06,0.045921984396879376,382.2128901057566,133.2979612341216,4.025140027435305
4.404599920075415e-06,0.04667093418683736,383.60623267281323,133.2979612341216,4.025140027435305
4.440847420574948e-06,0.04705501100220044,384.31738295036223,133.2979612341216,4.025140027435305
4.489781546249316e-06,0.04757351470294059,385.27385524775855,133.2979612341216,4.025140027435305
4.5586517971984255e-06,0.04830326065213042,386.61314238859376,133.2979612341216,4.025140027435305
4.587649797598051e-06,0.04861052210442088,387.1746893439697,133.2979612341216,4.025140027435305
4.6093982978977706e-06,0.04884096819363873,387.5949415664132,133.2979612341216,4.025140027435305
4.661957173622092e-06,0.04939787957591518,388.6073712038564,133.2979612341216,4.025140027435305
4.718140799396366e-06,0.04999319863972794,389.6847134178513,133.2979612341216,4.025140027435305
4.779761550245572e-06,0.050646129225845174,390.86057775125937,133.2979612341216,4.025140027435305
4.803322425570267e-06,0.05089577915583117,391.30860866060556,133.2979612341216,4.025140027435305
4.875817426569331e-06,0.051663932786557315,392.6818197630339,133.2979612341216,4.025140027435305
4.884879301694214e-06,0.05175995199039808,392.85290950468544,133.2979612341216,4.025140027435305
4.912064927068862e-06,0.05204800960192038,393.36543758575414,133.2979612341216,4.025140027435305
4.946500052543418e-06,0.0524128825765153,394.0130545063061,133.2979612341216,4.025140027435305
4.960999052743231e-06,0.05256651330266053,394.28520902316376,133.2979612341216,4.025140027435305
5.0008713032927156e-06,0.052988997799559914,395.0320391276339,133.2979612341216,4.025140027435305
5.015370303492529e-06,0.05314262852570514,395.3030374811187,133.2979612341216,4.025140027435305
5.06249205414192e-06,0.053641928385677135,396.1816795089007,133.2979612341216,4.025140027435305
5.120488054941171e-06,0.05425645129025805,397.25871866806034,133.2979612341216,4.025140027435305
5.144048930265866e-06,0.054506101220244046,397.6949056089074,133.2979612341216,4.025140027435305
5.173046930665493e-06,0.054813362672534505,398.2306829378733,133.2979612341216,4.025140027435305
5.247354306689533e-06,0.05560072014402881,399.59829326496526,133.2979612341216,4.025140027435305
5.274539932064182e-06,0.05588877775555111,400.0967487039945,133.2979612341216,4.025140027435305
5.3089750575387375e-06,0.05625365073014603,400.72668958830195,133.2979612341216,4.025140027435305
5.319849307688597e-06,0.056368873774754955,400.9252869630712,133.2979612341216,4.025140027435305
5.336160682913385e-06,0.05654170834166833,401.22288643194725,133.2979612341216,4.025140027435305
5.357909183213106e-06,0.05677215443088618,401.6191344322165,133.2979612341216,4.025140027435305
5.401406183812544e-06,0.057233046609321866,402.40975357651894,133.2979612341216,4.025140027435305
5.421342309087287e-06,0.05744428885777156,402.7712904677792,133.2979612341216,4.025140027435305
5.446715559436959e-06,0.05771314262852571,403.23067931127554,133.2979612341216,4.025140027435305
5.470276434761655e-06,0.05796279255851171,403.6565079048094,133.2979612341216,4.025140027435305
5.48296305993649e-06,0.05809721944388878,403.8855039261583,133.2979612341216,4.025140027435305
5.517398185411046e-06,0.0584620924184837,404.50602527493254,133.2979612341216,4.025140027435305
5.5536456859105775e-06,0.058846169233846765,405.15757613908437,133.2979612341216,4.025140027435305
5.575394186210297e-06,0.059076615323064616,405.54771062851523,133.2979612341216,4.025140027435305
5.6116416867098284e-06,0.05946069213842768,406.1966184329362,133.2979612341216,4.025140027435305
5.627953061934619e-06,0.05963352670534107,406.48809341841695,133.2979612341216,4.025140027435305
5.6750748125840095e-06,0.06013282656531306,407.3282872916628,133.2979612341216,4.025140027435305
5.7330708133832605e-06,0.06074734946989398,408.3586462995819,133.2979612341216,4.025140027435305
5.769318313882794e-06,0.06113142628525706,409.0005568228366,133.2979612341216,4.025140027435305
5.825501939657067e-06,0.061726745349069814,409.99241847342336,133.2979612341216,4.025140027435305
5.841813314881857e-06,0.0618995799159832,410.2796786176331,133.2979612341216,4.025140027435305
5.8617494401566e-06,0.062110822164432894,410.63034989590034,133.2979612341216,4.025140027435305
5.932432066130686e-06,0.06285977195439088,411.86990838343604,133.2979612341216,4.025140027435305
5.94149394125557e-06,0.06295579115823165,412.02840853691225,133.2979612341216,4.025140027435305
5.992240441954914e-06,0.06349349869973994,412.9142732639283,133.2979612341216,4.025140027435305
5.999489942054821e-06,0.06357031406281256,413.0405861138127,133.2979612341216,4.025140027435305
6.041174567629282e-06,0.06401200240048009,413.76573315686613,133.2979612341216,4.025140027435305
6.120919068728253e-06,0.06485697139427886,415.14755661662684,133.2979612341216,4.025140027435305
6.184352194602434e-06,0.06552910582116424,416.2417270472798,133.2979612341216,4.025140027435305
6.19160169470234e-06,0.06560592118423685,416.36649578185063,133.2979612341216,4.025140027435305
6.207913069927129e-06,0.06577875575115023,416.6470173125661,133.2979612341216,4.025140027435305
6.327529821575585e-06,0.06704620924184837,418.695463144155,133.2979612341216,4.025140027435305
6.3601525720251645e-06,0.06739187837567515,419.2515019729526,133.2979612341216,4.025140027435305
6.374651572224977e-06,0.06754550910182038,419.4982731907716,133.2979612341216,4.025140027435305
6.416336197799439e-06,0.0679871974394879,420.2065240530481,133.2979612341216,4.025140027435305
6.441709448149111e-06,0.06825605121024206,420.6367547605032,133.2979612341216,4.025140027435305
6.555889074722636e-06,0.06946589317863573,422.5646721177489,133.2979612341216,4.025140027435305
6.593948950247145e-06,0.06986917383476696,423.2043953427273,133.2979612341216,4.025140027435305
6.624759325671747e-06,0.07019563912782557,423.72121243615265,133.2979612341216,4.025140027435305
6.657382076121326e-06,0.07054130826165234,424.2674098441671,133.2979612341216,4.025140027435305
6.673693451346116e-06,0.07071414282856572,424.5401170391505,133.2979612341216,4.025140027435305
6.680942951446022e-06,0.07079095819163833,424.6612367842251,133.2979612341216,4.025140027435305
6.738938952245273e-06,0.07140548109621925,425.62835635611253,133.2979612341216,4.025140027435305
6.748000827370155e-06,0.07150150030006001,425.77917507267887,133.2979612341216,4.025140027435305
6.793310202994571e-06,0.07198159631926386,426.53208707701356,133.2979612341216,4.025140027435305
6.842244328668939e-06,0.07250010002000401,427.34303567546306,133.2979612341216,4.025140027435305
6.876679454143493e-06,0.07286497299459892,427.9123478656658,133.2979612341216,4.025140027435305
7.016232331066692e-06,0.07434366873374676,430.208267900495,133.2979612341216,4.025140027435305
7.028918956241528e-06,0.07447809561912383,430.41610076309786,133.2979612341216,4.025140027435305
7.056104581616176e-06,0.07476615323064613,430.86096490599175,133.2979612341216,4.025140027435305
7.0977892071906395e-06,0.07520784156831367,431.5417938562565,133.2979612341216,4.025140027435305
7.115912957440405e-06,0.0753998799759952,431.83731986154834,133.2979612341216,4.025140027435305
7.121350082515335e-06,0.07545749149829967,431.92592040256284,133.2979612341216,4.025140027435305
7.1376614577401235e-06,0.07563032606521304,432.1915638688839,133.2979612341216,4.025140027435305
7.1630347080897965e-06,0.0758991798359672,432.604316937727,133.2979612341216,4.025140027435305
7.2137812087891415e-06,0.0764368873774755,433.42811641939835,133.2979612341216,4.025140027435305
7.25184108431365e-06,0.07684016803360673,434.0444836495599,133.2979612341216,4.025140027435305
7.313461835162854e-06,0.07749309861972395,435.0397434387107,133.2979612341216,4.025140027435305
7.378707336062011e-06,0.07818443688737747,436.08998987725,133.2979612341216,4.025140027435305
7.3950187112868e-06,0.07835727145429086,436.35198481071996,133.2979612341216,4.025140027435305
7.420391961636473e-06,0.07862612522504502,436.7590849601624,133.2979612341216,4.025140027435305
7.460264212185959e-06,0.0790486097219444,437.39771861643,133.2979612341216,4.025140027435305
7.500136462735443e-06,0.07947109421884377,438.0350224832713,133.2979612341216,4.025140027435305
7.521884963035163e-06,0.07970154030806162,438.38208580018687,133.2979612341216,4.025140027435305
7.543633463334881e-06,0.07993198639727946,438.72875797746264,133.2979612341216,4.025140027435305
7.627002714483805e-06,0.08081536307261453,440.05407259840194,133.2979612341216,4.025140027435305
7.67774921518315e-06,0.08135307061412284,440.8580200439965,133.2979612341216,4.025140027435305
7.699497715482869e-06,0.08158351670334067,441.2019342590006,133.2979612341216,4.025140027435305
7.723058590807565e-06,0.08183316663332667,441.5740807373251,133.2979612341216,4.025140027435305
7.750244216182215e-06,0.08212122424484898,442.0029307748396,133.2979612341216,4.025140027435305
7.820926842156302e-06,0.08287017403480697,443.1152042226258,133.2979612341216,4.025140027435305
7.880735217980529e-06,0.08350390078015603,444.05329996928714,133.2979612341216,4.025140027435305
7.898858968230296e-06,0.08369593918783758,444.3370226992091,133.2979612341216,4.025140027435305
7.945980718879686e-06,0.08419523904780957,445.07351614366337,133.2979612341216,4.025140027435305
7.985852969429172e-06,0.08461772354470895,445.6953734343459,133.2979612341216,4.025140027435305
8.00760146972889e-06,0.08484816963392679,446.03405790371875,133.2979612341216,4.025140027435305
8.042036595203446e-06,0.08521304260852171,446.56957555296407,133.2979612341216,4.025140027435305
8.080096470727954e-06,0.08561632326465293,447.1604241242545,133.2979612341216,4.025140027435305
8.12540584635237e-06,0.08609641928385678,447.8624019492782,133.2979612341216,4.025140027435305
8.159840971826925e-06,0.0864612922584517,448.3948845649503,133.2979612341216,4.025140027435305
8.199713222376409e-06,0.08688377675535107,449.01034975453143,133.2979612341216,4.025140027435305
8.212399847551247e-06,0.08701820364072815,449.2059346715622,133.2979612341216,4.025140027435305
8.272208223375474e-06,0.08765193038607721,450.1263953577,133.2979612341216,4.025140027435305
8.399074475123836e-06,0.08899619923984797,452.0703397967322,133.2979612341216,4.025140027435305
8.473381851147876e-06,0.08978355671134228,453.2036179784993,133.2979612341216,4.025140027435305
8.522315976822245e-06,0.09030206041208243,453.9478071233316,133.2979612341216,4.025140027435305
8.558563477321775e-06,0.09068613722744549,454.49798438240924,133.2979612341216,4.025140027435305
8.611122353046097e-06,0.09124304860972195,455.2941299864716,133.2979612341216,4.025140027435305
8.63105847832084e-06,0.09145429085817164,455.59562020958936,133.2979612341216,4.025140027435305
8.65280697862056e-06,0.09168473694738949,455.92420905621515,133.2979612341216,4.025140027435305
8.703553479319904e-06,0.09222244448889778,456.6896663062102,133.2979612341216,4.025140027435305
8.754299980019249e-06,0.09276015203040608,457.4533849376818,133.2979612341216,4.025140027435305
8.781485605393898e-06,0.09304820964192839,457.8618096076745,133.2979612341216,4.025140027435305
8.79598460559371e-06,0.09320184036807362,458.0794344557683,133.2979612341216,4.025140027435305
8.835856856143196e-06,0.093624324864973,458.67718260642795,133.2979612341216,4.025140027435305
8.879353856742635e-06,0.09408521704340869,459.3280730037151,133.2979612341216,4.025140027435305
8.901102357042352e-06,0.09431566313262653,459.6530517998955,133.2979612341216,4.025140027435305
8.915601357242165e-06,0.09446929385877176,459.86953230632076,133.2979612341216,4.025140027435305
8.959098357841605e-06,0.09493018603720745,460.518151523283,133.2979612341216,4.025140027435305
8.969972607991463e-06,0.09504540908181637,460.6801142874084,133.2979612341216,4.025140027435305
8.982659233166299e-06,0.09517983596719344,460.86897409494156,133.2979612341216,4.025140027435305
9.05152948411541e-06,0.09590958191638328,461.8924036222395,133.2979612341216,4.025140027435305
9.113150234964615e-06,0.0965625125025005,462.80553233679683,133.2979612341216,4.025140027435305
9.162084360638983e-06,0.09708101620324065,463.5289497238819,133.2979612341216,4.025140027435305
9.194707111088562e-06,0.09742668533706741,464.0103910191332,133.2979612341216,4.025140027435305
9.223705111488187e-06,0.09773394678935787,464.437779859622,133.2979612341216,4.025140027435305
9.274451612187532e-06,0.09827165433086618,465.1844515423344,133.2979612341216,4.025140027435305
9.30707436263711e-06,0.09861732346469294,465.6636135113924,133.2979612341216,4.025140027435305
9.330635237961807e-06,0.09886697339467894,466.0092676618083,133.2979612341216,4.025140027435305
9.348758988211572e-06,0.09905901180236047,466.2749238895503,133.2979612341216,4.025140027435305
9.363257988411384e-06,0.0992126425285057,466.4873042860551,133.2979612341216,4.025140027435305
9.385006488711104e-06,0.09944308861772355,466.8056345525542,133.2979612341216,4.025140027435305
9.395880738860964e-06,0.09955831166233248,466.96469178971466,133.2979612341216,4.025140027435305