File: datasets/aisi_316_L/data/M1/train_42.csv
Time(s),Strain(%),Stress(MPa),Temp(C),Log_SR(s-1)
0.0,0.0,0.0,52.16954511951832,-0.7564480634847586
2.2830112670492327e-05,4e-06,0.7805741875,52.16954511951832,-0.7564480634847586
0.0001461127210911509,2.56e-05,4.9956748,52.16954511951832,-0.7564480634847586
0.0003607157801937788,6.319999999999999e-05,12.333072162499999,52.16954511951832,-0.7564480634847586
0.0005524887266259143,9.68e-05,18.8898953375,52.16954511951832,-0.7564480634847586
0.0006849033801147699,0.00011999999999999999,23.417225624999997,52.16954511951832,-0.7564480634847586
0.0008447141688082162,0.000148,28.8812449375,52.16954511951832,-0.7564480634847586
0.0009634307546947762,0.00016879999999999998,32.9402307125,52.16954511951832,-0.7564480634847586
0.0010319210927062534,0.0001808,35.281953275,52.16954511951832,-0.7564480634847586
0.001264788241945275,0.0002216,43.2438099875,52.16954511951832,-0.7564480634847586
0.0012739202870134718,0.00022319999999999998,43.5560396625,52.16954511951832,-0.7564480634847586
0.0013241465348885551,0.000232,45.273302875,52.16954511951832,-0.7564480634847586
0.0013880708503659336,0.0002432,47.4589106,52.16954511951832,-0.7564480634847586
0.001520485503854789,0.00026639999999999997,51.986240887499996,52.16954511951832,-0.7564480634847586
0.00154788163905938,0.0002712,52.922929912499995,52.16954511951832,-0.7564480634847586
0.0016392020897413493,0.0002872,56.0452266625,52.16954511951832,-0.7564480634847586
0.0016620322024118415,0.0002912,56.82580084999999,52.16954511951832,-0.7564480634847586
0.0017487866305597123,0.00030639999999999997,59.79198276249999,52.16954511951832,-0.7564480634847586
0.0018264090136393863,0.00031999999999999997,62.44593499999999,52.16954511951832,-0.7564480634847586
0.001913163441787257,0.00033519999999999996,65.4121169125,52.16954511951832,-0.7564480634847586
0.0019725217347305373,0.0003456,67.4416098,52.16954511951832,-0.7564480634847586
0.0020821062755489003,0.0003648,71.1883659,52.16954511951832,-0.7564480634847586
0.002091238320617097,0.00036639999999999996,71.50059557499999,52.16954511951832,-0.7564480634847586
0.0022099549065036574,0.0003872,75.55958135,52.16954511951832,-0.7564480634847586
0.0023104074022538236,0.0004048,78.99410777499999,52.16954511951832,-0.7564480634847586
0.002383463762799399,0.00041759999999999996,81.491945175,52.16954511951832,-0.7564480634847586
0.00252957648389055,0.0004432,86.487619975,52.16954511951832,-0.7564480634847586
0.002616330912038421,0.0004584,89.45380188749999,52.16954511951832,-0.7564480634847586
0.0026756892049817006,0.00046879999999999996,91.48329477499999,52.16954511951832,-0.7564480634847586
0.00276700965566367,0.00048479999999999997,94.605591525,52.16954511951832,-0.7564480634847586
0.002794405790868261,0.0004896,95.54228055,52.16954511951832,-0.7564480634847586
0.002935952489425313,0.0005143999999999999,100.38184051249999,52.16954511951832,-0.7564480634847586
0.00303640498517548,0.000532,103.8163669375,52.16954511951832,-0.7564480634847586
0.0030774991879823663,0.0005392,105.221400475,52.16954511951832,-0.7564480634847586
0.0032053478189371233,0.0005616,109.592615925,52.16954511951832,-0.7564480634847586
0.0032966682696190922,0.0005775999999999999,112.714912675,52.16954511951832,-0.7564480634847586
0.00339255474283516,0.0005943999999999999,115.99332426249998,52.16954511951832,-0.7564480634847586
0.003474743148448932,0.0006087999999999999,118.80339133749999,52.16954511951832,-0.7564480634847586
0.0036117238244718864,0.0006328,123.4868364625,52.16954511951832,-0.7564480634847586
0.0037076102976879542,0.0006496,126.76524805,52.16954511951832,-0.7564480634847586
0.0038719871089154994,0.0006784,132.3853822,52.16954511951832,-0.7564480634847586
0.0040454959652112404,0.0007088,138.317746025,52.16954511951832,-0.7564480634847586
0.004141382438427308,0.0007256,141.59615761249998,52.16954511951832,-0.7564480634847586
0.004159646528563702,0.0007287999999999999,142.22061696249997,52.16954511951832,-0.7564480634847586
0.004246400956711574,0.000744,145.186798875,52.16954511951832,-0.7564480634847586
0.004269231069382065,0.000748,145.9673730625,52.16954511951832,-0.7564480634847586
0.004456437993280103,0.0007808,152.3680814,52.16954511951832,-0.7564480634847586
0.004488400151018791,0.0007863999999999999,153.46088526249997,52.16954511951832,-0.7564480634847586
0.004616248781973549,0.0008087999999999999,157.8321007125,52.16954511951832,-0.7564480634847586
0.004680173097450928,0.00082,160.0177084375,52.16954511951832,-0.7564480634847586
0.004771493548132897,0.0008359999999999999,163.14000518749998,52.16954511951832,-0.7564480634847586
0.004839983886144374,0.000848,165.48172775,52.16954511951832,-0.7564480634847586
0.005022624787508312,0.0008799999999999999,171.72632124999998,52.16954511951832,-0.7564480634847586
0.0050363228551106075,0.0008824,172.1946657625,52.16954511951832,-0.7564480634847586
0.00517786955366766,0.0009071999999999999,177.034225725,52.16954511951832,-0.7564480634847586
0.005223529779008644,0.0009151999999999999,178.5953741,52.16954511951832,-0.7564480634847586
0.005278322049417826,0.0009247999999999999,180.46875214999997,52.16954511951832,-0.7564480634847586
0.0054290007930430755,0.0009511999999999999,185.62054178749997,52.16954511951832,-0.7564480634847586
0.005543151356395538,0.0009712,189.523412725,52.16954511951832,-0.7564480634847586
0.00574405634789587,0.0010064,196.392465575,52.16954511951832,-0.7564480634847586
0.005976923497134891,0.0010471999999999999,204.35432228749997,52.16954511951832,-0.7564480634847586
0.006022583722475876,0.0010551999999999998,205.91547066249996,52.16954511951832,-0.7564480634847586
0.006104772128089649,0.0010696,208.7255377375,52.16954511951832,-0.7564480634847586
0.006136734285828338,0.0010752,209.81834159999997,52.16954511951832,-0.7564480634847586
0.006232620759044406,0.0010919999999999999,213.09675318749998,52.16954511951832,-0.7564480634847586
0.006314809164658179,0.0011064,215.9068202625,52.16954511951832,-0.7564480634847586
0.0063787334801355565,0.0011175999999999998,218.09242798749997,52.16954511951832,-0.7564480634847586
0.006456355863215231,0.0011312,220.746380225,52.16954511951832,-0.7564480634847586
0.006611600629374579,0.0011584,226.05428469999998,52.16954511951832,-0.7564480634847586
0.00669378903498835,0.0011727999999999999,228.864351775,52.16954511951832,-0.7564480634847586
0.006712053125124745,0.001176,229.48881112499998,52.16954511951832,-0.7564480634847586
0.006867297891284093,0.0012032,234.7967156,52.16954511951832,-0.7564480634847586
0.006894694026488683,0.0012079999999999999,235.73340462499996,52.16954511951832,-0.7564480634847586
0.007027108679977539,0.0012312,240.2607349125,52.16954511951832,-0.7564480634847586
0.007191485491205083,0.0012599999999999998,245.88086906249995,52.16954511951832,-0.7564480634847586
0.007273673896818857,0.0012744,248.6909361375,52.16954511951832,-0.7564480634847586
0.007342164234830334,0.0012864,251.0326587,52.16954511951832,-0.7564480634847586
0.00747001286578509,0.0013088,255.40387414999998,52.16954511951832,-0.7564480634847586
0.007561333316467059,0.0013248,258.52617089999995,52.16954511951832,-0.7564480634847586
0.007597861496739846,0.0013311999999999998,259.77508959999994,52.16954511951832,-0.7564480634847586
0.007712012060092309,0.0013511999999999999,263.6779605375,52.16954511951832,-0.7564480634847586
0.007753106262899195,0.0013583999999999998,265.082994075,52.16954511951832,-0.7564480634847586
0.007835294668512967,0.0013728,267.89306115,52.16954511951832,-0.7564480634847586
0.007903785006524444,0.0013847999999999998,270.23478371249996,52.16954511951832,-0.7564480634847586
0.007990539434672315,0.0014,273.200965625,52.16954511951832,-0.7564480634847586
0.008045331705081498,0.0014096,274.5707125730554,52.16954511951832,-0.7564480634847586
0.008118388065627072,0.0014223999999999999,274.6692643522588,52.16954511951832,-0.7564480634847586
0.00818231238110445,0.0014336,274.7552137805026,52.16954511951832,-0.7564480634847586
0.008314727034593307,0.0014567999999999998,274.9324232714756,52.16954511951832,-0.7564480634847586
0.008433443620479866,0.0014776,275.0903671647899,52.16954511951832,-0.7564480634847586
0.008529330093695935,0.0014944,275.2173051400227,52.16954511951832,-0.7564480634847586
0.008547594183832328,0.0014976,275.24142057326156,52.16954511951832,-0.7564480634847586
0.008702838949991677,0.0015248,275.44559666682875,52.16954511951832,-0.7564480634847586
0.008876347806287417,0.0015551999999999999,275.6721198688661,52.16954511951832,-0.7564480634847586
0.00896310223443529,0.0015704,275.78473339460675,52.16954511951832,-0.7564480634847586
0.008995064392173978,0.001576,275.82611532847915,52.16954511951832,-0.7564480634847586
0.009177705293537916,0.0016079999999999998,276.0614925944113,52.16954511951832,-0.7564480634847586
0.009218799496344804,0.0016152,276.11419988939116,52.16954511951832,-0.7564480634847586
0.009273591766753984,0.0016248,276.1843339668456,52.16954511951832,-0.7564480634847586
0.009392308352640544,0.0016455999999999999,276.33573911635483,52.16954511951832,-0.7564480634847586
0.009488194825856612,0.0016623999999999999,276.45748374618773,52.16954511951832,-0.7564480634847586
0.009579515276538582,0.0016784,276.57298568165294,52.16954511951832,-0.7564480634847586
0.009784986290573013,0.0017143999999999998,276.8313064136198,52.16954511951832,-0.7564480634847586
0.009880872763789081,0.0017312,276.9511312886573,52.16954511951832,-0.7564480634847586
0.009949363101800557,0.0017431999999999999,277.03644299939276,52.16954511951832,-0.7564480634847586
0.010136570025698595,0.001776,277.2684676767273,52.16954511951832,-0.7564480634847586
0.010218758431312367,0.0017904,277.3698036112578,52.16954511951832,-0.7564480634847586
0.010319210927062533,0.001808,277.49322800161764,52.16954511951832,-0.7564480634847586
0.010369437174937615,0.0018168,277.55476441632027,52.16954511951832,-0.7564480634847586
0.010410531377744501,0.0018239999999999999,277.6050259751947,52.16954511951832,-0.7564480634847586
0.010479021715755979,0.001836,277.688623632976,52.16954511951832,-0.7564480634847586
0.010529247963631062,0.0018448,277.74979321256194,52.16954511951832,-0.7564480634847586
0.010597738301642538,0.0018567999999999998,277.8330231989866,52.16954511951832,-0.7564480634847586
0.010634266481915327,0.0018632,277.87732673689453,52.16954511951832,-0.7564480634847586
0.010707322842460901,0.0018759999999999998,277.9657561623839,52.16954511951832,-0.7564480634847586
0.010730152955131396,0.00188,277.993342060211,52.16954511951832,-0.7564480634847586
0.010775813180472379,0.001888,278.04844528050666,52.16954511951832,-0.7564480634847586
0.01083517147341566,0.0018984,278.1199435233731,52.16954511951832,-0.7564480634847586
0.01086256760862025,0.0019031999999999999,278.15289117472133,52.16954511951832,-0.7564480634847586
0.010967586126904514,0.0019215999999999999,278.2788914202046,52.16954511951832,-0.7564480634847586
0.0110132463522455,0.0019295999999999998,278.3335272763619,52.16954511951832,-0.7564480634847586
0.01104064248745009,0.0019344,278.3662663877187,52.16954511951832,-0.7564480634847586
0.011072604645188779,0.0019399999999999999,278.40442200080633,52.16954511951832,-0.7564480634847586
0.011109132825461566,0.0019463999999999998,278.4479758578676,52.16954511951832,-0.7564480634847586
0.011127396915597961,0.0019496,278.4697318393298,52.16954511951832,-0.7564480634847586
0.011296339749359605,0.0019792,278.6703187705986,52.16954511951832,-0.7564480634847586
0.011529206898598628,0.00202,278.94489617424153,52.16954511951832,-0.7564480634847586
0.011606829281678301,0.0020336,279.03594020305445,52.16954511951832,-0.7564480634847586
0.011762074047837648,0.0020608,279.21731899129196,52.16954511951832,-0.7564480634847586
0.011803168250644534,0.002068,279.26517443870233,52.16954511951832,-0.7564480634847586
0.011853394498519616,0.0020767999999999997,279.323576277097,52.16954511951832,-0.7564480634847586
0.01199037517454257,0.0021008,279.4823655384965,52.16954511951832,-0.7564480634847586
0.012013205287213065,0.0021048,279.50876148174535,52.16954511951832,-0.7564480634847586
0.012063431535088145,0.0021135999999999998,279.5667637906962,52.16954511951832,-0.7564480634847586
0.012131921873099624,0.0021256,279.6457062954671,52.16954511951832,-0.7564480634847586
0.012182148120974706,0.0021344,279.70348704364574,52.16954511951832,-0.7564480634847586
0.01225977050405438,0.0021479999999999997,279.79260215402826,52.16954511951832,-0.7564480634847586
0.01235109095473635,0.0021639999999999997,279.897162226277,52.16954511951832,-0.7564480634847586
0.012373921067406842,0.002168,279.9232550809354,52.16954511951832,-0.7564480634847586
0.012419581292747827,0.002176,279.9753845325976,52.16954511951832,-0.7564480634847586
0.012602222194111766,0.002208,280.1831592122218,52.16954511951832,-0.7564480634847586
0.012666146509589143,0.0022191999999999997,280.25560247021076,52.16954511951832,-0.7564480634847586
0.012748334915202917,0.0022336,280.34853462858183,52.16954511951832,-0.7564480634847586
0.012844221388418986,0.0022504,280.4566606721656,52.16954511951832,-0.7564480634847586
0.012912711726430461,0.0022624,280.5337009099876,52.16954511951832,-0.7564480634847586
0.013049692402453416,0.0022864,280.6873049472332,52.16954511951832,-0.7564480634847586
0.013163842965805876,0.0023063999999999997,280.8148285478948,52.16954511951832,-0.7564480634847586
0.013241465348885552,0.00232,280.90129835150884,52.16954511951832,-0.7564480634847586
0.013282559551692436,0.0023271999999999998,280.9469964389115,52.16954511951832,-0.7564480634847586
0.013323653754499324,0.0023344,280.9926394201397,52.16954511951832,-0.7564480634847586
0.013360181934772113,0.0023408,281.0331648879482,52.16954511951832,-0.7564480634847586
0.013405842160113096,0.0023488,281.0837610067743,52.16954511951832,-0.7564480634847586
0.013428672272783588,0.0023528,281.1090338597297,52.16954511951832,-0.7564480634847586
0.01345606840798818,0.0023576,281.139339174957,52.16954511951832,-0.7564480634847586
0.013593049084011133,0.0023815999999999998,281.2905062983226,52.16954511951832,-0.7564480634847586
0.013661539422022612,0.0023936,281.36586698520966,52.16954511951832,-0.7564480634847586
0.013889840548727533,0.0024335999999999997,281.61601184704074,52.16954511951832,-0.7564480634847586
0.01401768917968229,0.002456,281.75539243982575,52.16954511951832,-0.7564480634847586
0.014177499968375737,0.002484,281.9289229513482,52.16954511951832,-0.7564480634847586
0.01425512235145541,0.0024976,282.0129338080326,52.16954511951832,-0.7564480634847586
0.014305348599330492,0.0025063999999999998,282.06719872104986,52.16954511951832,-0.7564480634847586
0.014323612689466888,0.0025096,282.0869129875695,52.16954511951832,-0.7564480634847586
0.014410367117614757,0.0025248,282.18042220025956,52.16954511951832,-0.7564480634847586
0.014442329275353447,0.0025304,282.2148175861871,52.16954511951832,-0.7564480634847586
0.01446972541055804,0.0025352,282.2442757239855,52.16954511951832,-0.7564480634847586
0.014492555523228529,0.0025391999999999997,282.26880755974565,52.16954511951832,-0.7564480634847586
0.014574743928842305,0.0025536,282.3569976503134,52.16954511951832,-0.7564480634847586
0.014684328469660668,0.0025728,282.4742833257079,52.16954511951832,-0.7564480634847586
0.014835007213285916,0.0025992,282.63499528398876,52.16954511951832,-0.7564480634847586
0.014921761641433787,0.0026144,282.72723761737524,52.16954511951832,-0.7564480634847586
0.015077006407593135,0.0026416,282.8917825192218,52.16954511951832,-0.7564480634847586
0.015090704475195432,0.002644,282.9062693884674,52.16954511951832,-0.7564480634847586
0.015172892880809202,0.0026584,282.9930831505388,52.16954511951832,-0.7564480634847586
0.015232251173752482,0.0026688,283.0556679612752,52.16954511951832,-0.7564480634847586
0.015291609466695763,0.0026792,283.11815772856033,52.16954511951832,-0.7564480634847586
0.015323571624434451,0.0026847999999999998,283.1517668774701,52.16954511951832,-0.7564480634847586
0.015364665827241338,0.002692,283.19493849469154,52.16954511951832,-0.7564480634847586
0.015396627984980028,0.0026976,283.22848529365393,52.16954511951832,-0.7564480634847586
0.015487948435661997,0.0027136,283.32418396149916,52.16954511951832,-0.7564480634847586
0.015556438773673473,0.0027256,283.39581361348786,52.16954511951832,-0.7564480634847586
0.015634061156753146,0.0027392,283.47684536946724,52.16954511951832,-0.7564480634847586
0.01574821172010561,0.0027592,283.5957252639324,52.16954511951832,-0.7564480634847586
0.015876060351060366,0.0027816,283.7284724915661,52.16954511951832,-0.7564480634847586
0.015930852621469548,0.0027911999999999998,283.7852364621485,52.16954511951832,-0.7564480634847586
0.016003908982015123,0.002804,283.8608034567789,52.16954511951832,-0.7564480634847586
0.016177417838310865,0.0028344,284.0397379201683,52.16954511951832,-0.7564480634847586
0.016200247950981357,0.0028384,284.0632260836881,52.16954511951832,-0.7564480634847586
0.016309832491799722,0.0028576,284.1757900654657,52.16954511951832,-0.7564480634847586
0.01640115294248169,0.0028736,284.2693682431375,52.16954511951832,-0.7564480634847586
0.016524435550902345,0.0028951999999999997,284.39537708736515,52.16954511951832,-0.7564480634847586
0.016675114294527598,0.0029216,284.5488910877094,52.16954511951832,-0.7564480634847586
0.016990169849380392,0.0029768,284.86813765289867,52.16954511951832,-0.7564480634847586
0.017022132007119082,0.0029824,284.9003954586126,52.16954511951832,-0.7564480634847586
0.017095188367664656,0.0029952,284.9740390132773,52.16954511951832,-0.7564480634847586
0.01714084859300564,0.0030031999999999997,285.02000391193036,52.16954511951832,-0.7564480634847586
0.017241301088755805,0.0030207999999999997,285.12095893496445,52.16954511951832,-0.7564480634847586
0.017282395291562693,0.003028,285.1621925696913,52.16954511951832,-0.7564480634847586
0.017515262440801715,0.0030688,285.3951315797551,52.16954511951832,-0.7564480634847586
0.017528960508404013,0.0030712,285.40879613963335,52.16954511951832,-0.7564480634847586
0.01762484698162008,0.003088,285.50433172284755,52.16954511951832,-0.7564480634847586
0.017725299477370244,0.0031056,285.60419946233725,52.16954511951832,-0.7564480634847586
0.017789223792847624,0.0031168,285.6676367526159,52.16954511951832,-0.7564480634847586
0.017875978220995493,0.003132,285.75358820141213,52.16954511951832,-0.7564480634847586
0.017967298671677463,0.0031479999999999998,285.8438878460903,52.16954511951832,-0.7564480634847586
0.018086015257564023,0.0031688,285.9610102415103,52.16954511951832,-0.7564480634847586
0.018140807527973205,0.0031784,286.0149655694455,52.16954511951832,-0.7564480634847586
0.01824582604625747,0.0031967999999999996,286.1182026293114,52.16954511951832,-0.7564480634847586
0.018328014451871242,0.0032112,286.19883528784845,52.16954511951832,-0.7564480634847586
0.01839193876734862,0.0032224,286.2614521246858,52.16954511951832,-0.7564480634847586
0.0184512970602919,0.0032327999999999996,286.3195203725962,52.16954511951832,-0.7564480634847586
0.018579145691246655,0.0032551999999999998,286.4443435757623,52.16954511951832,-0.7564480634847586
0.018611107848985346,0.0032608,286.47549697936716,52.16954511951832,-0.7564480634847586
0.018711560344735513,0.0032784,286.5732721123301,52.16954511951832,-0.7564480634847586
0.018962691584110927,0.0033223999999999997,286.8168185722372,52.16954511951832,-0.7564480634847586
0.019063144079861094,0.0033399999999999997,286.9138845497218,52.16954511951832,-0.7564480634847586
0.019095106237599784,0.0033456,286.9447273191959,52.16954511951832,-0.7564480634847586
0.01916816259814536,0.0033583999999999997,287.0151495722571,52.16954511951832,-0.7564480634847586
0.01925948304882733,0.0033744,287.10303035995753,52.16954511951832,-0.7564480634847586
0.019337105431907003,0.003388,287.17760133099296,52.16954511951832,-0.7564480634847586
0.01940102974738438,0.0033992,287.23892510046187,52.16954511951832,-0.7564480634847586
0.019460388040327663,0.0034096,287.29579807862063,52.16954511951832,-0.7564480634847586
0.01949235019806635,0.0034151999999999997,287.32639396547734,52.16954511951832,-0.7564480634847586
0.019661293031827995,0.0034448,287.4877912046821,52.16954511951832,-0.7564480634847586
0.01976631155011226,0.0034632,287.5878466566813,52.16954511951832,-0.7564480634847586
0.01982566984305554,0.0034736,287.64430802709995,52.16954511951832,-0.7564480634847586
0.020022008812021774,0.003508,287.8305969470289,52.16954511951832,-0.7564480634847586
0.020222913803522105,0.0035432,288.0204821501564,52.16954511951832,-0.7564480634847586
0.020254875961260795,0.0035488,288.0506231956906,52.16954511951832,-0.7564480634847586
0.020369026524613257,0.0035688,288.1581186935206,52.16954511951832,-0.7564480634847586
0.02045121493022703,0.0035832,288.2353700277543,52.16954511951832,-0.7564480634847586
0.020533403335840802,0.0035976,288.31250037932466,52.16954511951832,-0.7564480634847586
0.020606459696386376,0.0036103999999999997,288.38095967001453,52.16954511951832,-0.7564480634847586
0.020821062755489003,0.0036479999999999998,288.58151352432674,52.16954511951832,-0.7564480634847586
0.020875855025898185,0.0036576,288.63258937032964,52.16954511951832,-0.7564480634847586
0.020912383206170972,0.0036639999999999997,288.6666108916402,52.16954511951832,-0.7564480634847586
0.021003703656852942,0.0036799999999999997,288.75156345609497,52.16954511951832,-0.7564480634847586
0.021053929904728028,0.0036888,288.7982259614943,52.16954511951832,-0.7564480634847586
0.021181778535682785,0.0037112,288.91680777074873,52.16954511951832,-0.7564480634847586
0.02124570285116016,0.0037224,288.97599397567154,52.16954511951832,-0.7564480634847586
0.02148770204546738,0.0037648,289.1994296941363,52.16954511951832,-0.7564480634847586
0.021597286586285746,0.003784,289.3002850948301,52.16954511951832,-0.7564480634847586
0.021743399307376895,0.0038096,289.4344490543512,52.16954511951832,-0.7564480634847586
0.021802757600320175,0.0038199999999999996,289.48885267293247,52.16954511951832,-0.7564480634847586
0.021866681915797555,0.0038312,289.5473766249567,52.16954511951832,-0.7564480634847586
0.02195800236647952,0.0038472,289.63086665790166,52.16954511951832,-0.7564480634847586
0.022044756794627394,0.0038623999999999998,289.71005684802475,52.16954511951832,-0.7564480634847586
0.022154341335445756,0.0038816,289.8099130516242,52.16954511951832,-0.7564480634847586
0.022213699628389035,0.0038919999999999996,289.86392139058296,52.16954511951832,-0.7564480634847586
0.02227305792133232,0.0039024,289.91787347465225,52.16954511951832,-0.7564480634847586
0.022341548259343796,0.0039144,289.98005624884036,52.16954511951832,-0.7564480634847586
0.022432868710025762,0.0039304,290.06285109039766,52.16954511951832,-0.7564480634847586
0.022670301881798884,0.003972,290.2775048352946,52.16954511951832,-0.7564480634847586
0.02271139608460577,0.0039792,290.3145672617949,52.16954511951832,-0.7564480634847586
0.02278901846768544,0.0039927999999999995,290.38450278761894,52.16954511951832,-0.7564480634847586
0.022939719132603117,0.004019203840768154,290.52001503512724,52.16954511951832,-0.7564480634847586
0.024364603140043326,0.004268853770754151,291.78457826653914,52.16954511951832,-0.7564480634847586
0.026775945306480604,0.004691338267653531,293.8607553589095,52.16954511951832,-0.7564480634847586
0.031050597328801235,0.005440288057611523,297.3700734453582,52.16954511951832,-0.7564480634847586
0.03313312010890615,0.005805161032206441,299.0109357317629,52.16954511951832,-0.7564480634847586
0.03521564288901107,0.00617003400680136,300.61203400778635,52.16954511951832,-0.7564480634847586
0.03729816566911599,0.006534906981396279,302.17660329507964,52.16954511951832,-0.7564480634847586
0.038613443214445424,0.006765353070614123,303.14721547450756,52.16954511951832,-0.7564480634847586
0.04058635953243955,0.007111022204440888,304.5792957619889,52.16954511951832,-0.7564480634847586
0.04299770169887683,0.007533506701340268,306.2932534694332,52.16954511951832,-0.7564480634847586
0.04387455339576311,0.007687137427485497,306.9071614282771,52.16954511951832,-0.7564480634847586
0.047381960183308244,0.008301660332066413,309.31638979934627,52.16954511951832,-0.7564480634847586
0.05099897343296416,0.008935387077415483,311.7290971305087,52.16954511951832,-0.7564480634847586
0.0514373992814073,0.009012202440488098,312.01694066678454,52.16954511951832,-0.7564480634847586
0.05330070913729066,0.00933866773354671,313.2297524404435,52.16954511951832,-0.7564480634847586
0.05636969007639265,0.009876375275055011,315.19187801198234,52.16954511951832,-0.7564480634847586
0.05757536115961129,0.010087617523504702,315.9512573078751,52.16954511951832,-0.7564480634847586
0.0596578839397162,0.010452490498099619,317.24846371084647,52.16954511951832,-0.7564480634847586
0.06064434209871328,0.010625325065013003,317.85675461882386,52.16954511951832,-0.7564480634847586
0.06294607780303976,0.011028605721144228,319.26128693920265,52.16954511951832,-0.7564480634847586
0.06415174888625841,0.01123984796959392,319.9889917631683,52.16954511951832,-0.7564480634847586
0.06798797506013589,0.011911982396479295,322.26970670566857,52.16954511951832,-0.7564480634847586
0.07039931722657317,0.012334466893378675,323.67763319197564,52.16954511951832,-0.7564480634847586
0.07335869170356438,0.012852970594118824,325.38009274207815,52.16954511951832,-0.7564480634847586
0.07533160802155851,0.013198639727945589,326.5002063967281,52.16954511951832,-0.7564480634847586
0.07697570495322029,0.013486697339467894,327.42492084348766,52.16954511951832,-0.7564480634847586
0.07905822773332521,0.013851570314062813,328.58524161240234,52.16954511951832,-0.7564480634847586
0.08103114405131935,0.014197239447889578,329.6735450371878,52.16954511951832,-0.7564480634847586
0.08914202224751747,0.015618323664732947,334.0431916586483,52.16954511951832,-0.7564480634847586
0.09001887394440374,0.015771954390878175,334.5061042296964,52.16954511951832,-0.7564480634847586
0.09111493856551162,0.015963992798559715,335.0822793841486,52.16954511951832,-0.7564480634847586
0.09144375795184397,0.016021604320864174,335.25460399361936,52.16954511951832,-0.7564480634847586
0.09286864195928418,0.016271254250850173,335.99856869038126,52.16954511951832,-0.7564480634847586
0.09451273889094593,0.016559311862372472,336.8514800062318,52.16954511951832,-0.7564480634847586
0.0984585715269342,0.017250650130026003,338.8751963750609,52.16954511951832,-0.7564480634847586
0.10054109430703914,0.017615523104620924,339.93050233072506,52.16954511951832,-0.7564480634847586
0.10207558477659014,0.017884376875375075,340.7026491151609,52.16954511951832,-0.7564480634847586
0.1039388946324735,0.01821084216843369,341.63419642687717,52.16954511951832,-0.7564480634847586
0.10667905618524312,0.018690938187637528,342.9923733825062,52.16954511951832,-0.7564480634847586
0.10744630142001863,0.018825365073014605,343.3702159558975,52.16954511951832,-0.7564480634847586
0.1089807918895696,0.019094218843768752,344.12275905907404,52.16954511951832,-0.7564480634847586
0.11194016636656082,0.019612722544508902,345.5625230705355,52.16954511951832,-0.7564480634847586
0.11270741160133631,0.019747149429885976,345.9333623469612,52.16954511951832,-0.7564480634847586
0.11687245716154615,0.020476895379075814,347.9295677912498,52.16954511951832,-0.7564480634847586
0.117968521782654,0.02066893378675735,348.45024905095875,52.16954511951832,-0.7564480634847586
0.12257199319130699,0.021475495099019803,350.61682120917914,52.16954511951832,-0.7564480634847586
0.12618900644096293,0.022109221844368875,352.29694022736066,52.16954511951832,-0.7564480634847586
0.12717546459996,0.022282056411282256,352.7518813362334,52.16954511951832,-0.7564480634847586
0.1322173618570561,0.023165433086617324,355.0559847083733,52.16954511951832,-0.7564480634847586
0.1332038200160532,0.023338267653530708,355.50275170323596,52.16954511951832,-0.7564480634847586
0.1352863427961581,0.023703140628125625,356.44171107349854,52.16954511951832,-0.7564480634847586
0.14032824005325423,0.024586517303460693,358.69193643566206,52.16954511951832,-0.7564480634847586
0.14087627236380815,0.02468253650730146,358.9346110612281,52.16954511951832,-0.7564480634847586
0.14284918868180227,0.025028205641128225,359.8052076627718,52.16954511951832,-0.7564480634847586
0.14602777608301507,0.025585117023404682,361.198036080702,52.16954511951832,-0.7564480634847586
0.14920636348422783,0.026142028405681136,362.57908953320197,52.16954511951832,-0.7564480634847586
0.1501928216432249,0.02631486297259452,363.00535298955157,52.16954511951832,-0.7564480634847586
0.15117927980222196,0.0264876975395079,363.4305259605775,52.16954511951832,-0.7564480634847586
0.15271377027177296,0.026756551310262052,364.0897618500422,52.16954511951832,-0.7564480634847586
0.15556353828665337,0.027255851170234047,365.3072434306327,52.16954511951832,-0.7564480634847586
0.1576460610667583,0.027620724144828968,366.19144761713835,52.16954511951832,-0.7564480634847586
0.15863251922575536,0.02779355871174235,366.6086901593367,52.16954511951832,-0.7564480634847586
0.16071504200586031,0.02815843168633727,367.48622702468595,52.16954511951832,-0.7564480634847586
0.16301677771018677,0.028561712342468494,368.45099278748773,52.16954511951832,-0.7564480634847586
0.16444166171762697,0.02881136227245449,369.0455670257926,52.16954511951832,-0.7564480634847586
0.16542811987662406,0.028984196839367874,369.4560188391033,52.16954511951832,-0.7564480634847586
0.1710180494442741,0.029963592718543708,371.7641306092316,52.16954511951832,-0.7564480634847586
0.17211411406538196,0.030155631126225244,372.2132309135762,52.16954511951832,-0.7564480634847586
0.17310057222437905,0.03032846569313863,372.61646842260944,52.16954511951832,-0.7564480634847586
0.1756215208529271,0.03077015403080616,373.6429137034351,52.16954511951832,-0.7564480634847586
0.17858089532991828,0.03128865773154631,374.8405675589611,52.16954511951832,-0.7564480634847586
0.18044420518580168,0.031615123024604924,375.5906762675896,52.16954511951832,-0.7564480634847586
0.18406121843545759,0.03224884976995399,377.03820153030426,52.16954511951832,-0.7564480634847586
0.18449964428390073,0.03232566513302661,377.21290211513013,52.16954511951832,-0.7564480634847586
0.18822626399566741,0.03297859571914383,378.6913765148081,52.16954511951832,-0.7564480634847586
0.18997996738943998,0.033285857171434285,379.38317490525685,52.16954511951832,-0.7564480634847586
0.1912952449347694,0.03351630326065213,379.90039045862403,52.16954511951832,-0.7564480634847586
0.19556989695709004,0.03426525305061012,381.5718430393103,52.16954511951832,-0.7564480634847586
0.1963371421918655,0.03439967993598719,381.8703329812928,52.16954511951832,-0.7564480634847586
0.19798123912352733,0.034687737547509506,382.5084267574594,52.16954511951832,-0.7564480634847586
0.1997349425172999,0.034994998999799964,383.18678652057173,52.16954511951832,-0.7564480634847586
0.20477683977439595,0.03587837567513502,385.1242506715235,52.16954511951832,-0.7564480634847586
0.20696896901661171,0.0362624524904981,385.9608136303273,52.16954511951832,-0.7564480634847586
0.2091610982588274,0.03664652930586117,386.79392803398093,52.16954511951832,-0.7564480634847586
0.20992834349360293,0.03678095619123825,387.08471267048395,52.16954511951832,-0.7564480634847586
0.21507984721280982,0.03768353670734147,389.02649963949307,52.16954511951832,-0.7564480634847586
0.21705276353080394,0.03802920584116823,389.7653484576766,52.16954511951832,-0.7564480634847586
0.2189160733866873,0.038355671134226846,390.4607488317504,52.16954511951832,-0.7564480634847586
0.22450600295433737,0.03933506701340268,392.5332298759602,52.16954511951832,-0.7564480634847586
0.22680773865866385,0.03973834766953391,393.38074329682706,52.16954511951832,-0.7564480634847586
0.22735577096921777,0.039834366873374674,393.5820370025361,52.16954511951832,-0.7564480634847586
0.2294382937493227,0.040199239847969595,394.34523346072683,52.16954511951832,-0.7564480634847586
0.23108239068098446,0.040487297459491894,394.9458502944244,52.16954511951832,-0.7564480634847586
0.2360146814759698,0.041351470294058806,396.7377801637611,52.16954511951832,-0.7564480634847586
0.23974130118773654,0.04200440088017604,398.08201259805156,52.16954511951832,-0.7564480634847586
0.2403989399604012,0.04211962392478495,398.31838168015867,52.16954511951832,-0.7564480634847586
0.2456600501417189,0.043041408281656326,400.2003401638534,52.16954511951832,-0.7564480634847586
0.24631768891438363,0.04315663132626525,400.4344747113042,52.16954511951832,-0.7564480634847586
0.24774257292182383,0.04340628125625125,400.94093152037135,52.16954511951832,-0.7564480634847586
0.2503731280124827,0.043867173434686935,401.8729541388885,52.16954511951832,-0.7564480634847586
0.2546477800348034,0.044616123224644935,403.3793866320708,52.16954511951832,-0.7564480634847586
0.25585345111802194,0.04482736547309461,403.80249056333594,52.16954511951832,-0.7564480634847586
0.2581551868223485,0.04523064612922585,404.6080814135806,52.16954511951832,-0.7564480634847586
0.2630874776173338,0.046094818963792764,406.3249748904193,52.16954511951832,-0.7564480634847586
0.26495078747321715,0.04642128425685137,406.97030631230257,52.16954511951832,-0.7564480634847586
0.26637567148065733,0.04667093418683736,407.46260148555575,52.16954511951832,-0.7564480634847586
0.2715271751998643,0.04757351470294059,409.2339330615544,52.16954511951832,-0.7564480634847586
0.2749249755252986,0.04816883376675335,410.39508962834844,52.16954511951832,-0.7564480634847586
0.27788435000228984,0.0486873374674935,411.40186690351806,52.16954511951832,-0.7564480634847586
0.2816109697140565,0.04934026805361072,412.66373205116724,52.16954511951832,-0.7564480634847586
0.28270703433516436,0.04953230646129225,413.0336272810345,52.16954511951832,-0.7564480634847586
0.28467995065315854,0.04987797559511903,413.6980323414426,52.16954511951832,-0.7564480634847586
0.28939302852392235,0.05070374074814964,415.27799504561824,52.16954511951832,-0.7564480634847586
0.29092751899347324,0.05097259451890378,415.79023177570457,52.16954511951832,-0.7564480634847586
0.29191397715247036,0.051145429085817165,416.11897048591624,52.16954511951832,-0.7564480634847586
0.2923524030009135,0.05122224444888977,416.26493748173357,52.16954511951832,-0.7564480634847586
0.29377728700835376,0.05147189437887578,416.7387417177865,52.16954511951832,-0.7564480634847586
0.2960790227126802,0.05187517503500701,417.50222893266334,52.16954511951832,-0.7564480634847586
0.2969558744095665,0.052028805761152236,417.7924718838876,52.16954511951832,-0.7564480634847586
0.29870957780333907,0.052336067213442694,418.3719570031661,52.16954511951832,-0.7564480634847586
0.3006824941213332,0.052681736347269456,419.0222941309217,52.16954511951832,-0.7564480634847586
0.30397068798465676,0.05325785157031407,420.1025032707936,52.16954511951832,-0.7564480634847586
0.3060532107647616,0.053622724544908976,420.78427924569127,52.16954511951832,-0.7564480634847586
0.30769730769642345,0.05391078215643129,421.32124627079156,52.16954511951832,-0.7564480634847586
0.3112047144839686,0.054525305061012205,422.4630503836304,52.16954511951832,-0.7564480634847586
0.3123007791050764,0.05471734346869374,422.81883348497337,52.16954511951832,-0.7564480634847586
0.31482172773362443,0.05515903180636127,423.63529166606344,52.16954511951832,-0.7564480634847586
0.3150409406578461,0.055197439487897584,423.70616731001417,52.16954511951832,-0.7564480634847586
0.3175618892863941,0.05563912782556511,424.519859644062,52.16954511951832,-0.7564480634847586
0.3193155926801667,0.05594638927785557,425.0844213122864,52.16954511951832,-0.7564480634847586
0.3208500831497177,0.056215243048609725,425.57742155976837,52.16954511951832,-0.7564480634847586
0.3222749671571579,0.05646489297859572,426.03438476804666,52.16954511951832,-0.7564480634847586
0.3265496191794785,0.05721384276855371,427.4005699481573,52.16954511951832,-0.7564480634847586
0.32874174842169424,0.05759791958391679,428.0984710864112,52.16954511951832,-0.7564480634847586
0.3298378130428021,0.05778995799159832,428.4467408714752,52.16954511951832,-0.7564480634847586
0.33126269705024225,0.058039607921584316,428.89881756590495,52.16954511951832,-0.7564480634847586
0.33213954874712853,0.058193238647729545,429.17664169147093,52.16954511951832,-0.7564480634847586
0.3333452198303472,0.05840448089617924,429.55818325346587,52.16954511951832,-0.7564480634847586
0.3342220715272335,0.058558111622324466,429.8353300681672,52.16954511951832,-0.7564480634847586
0.3379486912390002,0.059211042208441686,431.0100544376591,52.16954511951832,-0.7564480634847586
0.3404696398675483,0.05965273054610923,431.80185759655814,52.16954511951832,-0.7564480634847586
0.34255216264765315,0.060017603520704135,432.454232718127,52.16954511951832,-0.7564480634847586
0.3466076017457523,0.06072814562912583,433.7202254798021,52.16954511951832,-0.7564480634847586
0.3481420922153032,0.06099699939987997,434.1977416373388,52.16954511951832,-0.7564480634847586
0.3500054020711866,0.06132346469293859,434.7764805785361,52.16954511951832,-0.7564480634847586
0.351320679616516,0.061553910782156426,435.1842789564981,52.16954511951832,-0.7564480634847586
0.3566913962599445,0.06249489897979596,436.84331333165125,52.16954511951832,-0.7564480634847586
0.3581162802673847,0.06274454890978196,437.28182648358137,52.16954511951832,-0.7564480634847586
0.36140447413070825,0.06332066413282657,438.2911911163734,52.16954511951832,-0.7564480634847586
0.36217171936548376,0.06345509101820364,438.52619342304666,52.16954511951832,-0.7564480634847586
0.36326778398659154,0.06364712942588517,438.86157447861933,52.16954511951832,-0.7564480634847586
0.36381581629714554,0.06374314862972595,439.0291169960312,52.16954511951832,-0.7564480634847586
0.36458306153192105,0.06387757551510302,439.2635112576335,52.16954511951832,-0.7564480634847586
0.36699440369835834,0.0643000600120024,439.9989296526637,52.16954511951832,-0.7564480634847586
0.3685288941679093,0.06456891378275655,440.46594215103875,52.16954511951832,-0.7564480634847586
0.3714882686449005,0.0650874174834967,441.36447301382833,52.16954511951832,-0.7564480634847586
0.37324197203867304,0.06539467893578715,441.8956185067351,52.16954511951832,-0.7564480634847586
0.37433803665978094,0.0655867173434687,442.2270902372264,52.16954511951832,-0.7564480634847586
0.3762013465156643,0.0659131826365273,442.7897248030786,52.16954511951832,-0.7564480634847586
0.37718780467466134,0.06608601720344069,443.08715011906276,52.16954511951832,-0.7564480634847586
0.3781742628336584,0.06625885177035407,443.3842722256249,52.16954511951832,-0.7564480634847586
0.3789415080684339,0.06639327865573115,443.6151582747735,52.16954511951832,-0.7564480634847586
0.38102403084853886,0.06675815163032607,444.24093179366804,52.16954511951832,-0.7564480634847586
0.38464104409819483,0.06739187837567515,445.32464053140194,52.16954511951832,-0.7564480634847586
0.3851890764087487,0.06748789757951591,445.4884914647522,52.16954511951832,-0.7564480634847586
0.38847727027207224,0.06806401280256051,446.4696945933108,52.16954511951832,-0.7564480634847586
0.3907790059763987,0.06846729345869174,447.1546104531133,52.16954511951832,-0.7564480634847586
0.39297113521861443,0.06885137027405482,447.8054499973267,52.16954511951832,-0.7564480634847586
0.39768421308937824,0.06967713542708542,449.19997961656696,52.16954511951832,-0.7564480634847586
0.39932831002103997,0.06996519303860772,449.68492510740793,52.16954511951832,-0.7564480634847586
0.39965712940737236,0.07002280456091219,449.78182069712096,52.16954511951832,-0.7564480634847586
0.4016300457253665,0.07036847369473895,450.3625426640071,52.16954511951832,-0.7564480634847586
0.40338374911913905,0.0706757351470294,450.87780663860684,52.16954511951832,-0.7564480634847586
0.4060143042097979,0.0711366273254651,451.64906755071985,52.16954511951832,-0.7564480634847586
0.4065623365203518,0.07123264652930586,451.8095013389225,52.16954511951832,-0.7564480634847586
0.41050816915634014,0.0719239847969594,452.96214509985845,52.16954511951832,-0.7564480634847586
0.413138724246999,0.07238487697539508,453.7281746670881,52.16954511951832,-0.7564480634847586
0.41587888579976856,0.07286497299459892,454.524102109286,52.16954511951832,-0.7564480634847586
0.41774219565565196,0.07319143828765753,455.06416487339806,52.16954511951832,-0.7564480634847586
0.419715111973646,0.0735371074214843,455.6349730494479,52.16954511951832,-0.7564480634847586
0.421797634753751,0.07390198039607922,456.2363587187469,52.16954511951832,-0.7564480634847586
0.42453779630652067,0.07438207641528306,457.02589436472704,52.16954511951832,-0.7564480634847586
0.4265107126245148,0.07472774554910983,457.593129912011,52.16954511951832,-0.7564480634847586
0.4277163837077334,0.07493898779755952,457.9392701321956,52.16954511951832,-0.7564480634847586
0.42837402248039813,0.07505421084216844,458.12791349251034,52.16954511951832,-0.7564480634847586
0.4301277258741707,0.0753614722944589,458.6304110913007,52.16954511951832,-0.7564480634847586
0.4382386040703688,0.07678255651130227,460.9441475430003,52.16954511951832,-0.7564480634847586
0.43944427515358747,0.07699379875975196,461.2866502362722,52.16954511951832,-0.7564480634847586
0.4404307333125845,0.07716663332666533,461.566607204543,52.16954511951832,-0.7564480634847586
0.44174601085791393,0.07739707941588318,461.93950305753077,52.16954511951832,-0.7564480634847586
0.44404774656224044,0.07780036007201441,462.5910305492924,52.16954511951832,-0.7564480634847586
0.4443765659485728,0.07785797159431887,462.68399827281644,52.16954511951832,-0.7564480634847586
0.4463494822665669,0.07820364072814563,463.24124225114116,52.16954511951832,-0.7564480634847586
0.4478839727361179,0.07847249449889979,463.6739903823186,52.16954511951832,-0.7564480634847586
0.45172019890999543,0.07914462892578517,464.7533386389249,52.16954511951832,-0.7564480634847586
0.45522760569754056,0.07975915183036608,465.73704703169005,52.16954511951832,-0.7564480634847586
0.4568717026292023,0.08004720944188838,466.19714240219804,52.16954511951832,-0.7564480634847586
0.45895422540930725,0.0804120824164833,466.77900396014246,52.16954511951832,-0.7564480634847586
0.459611864181972,0.08052730546109223,466.96253567277626,52.16954511951832,-0.7564480634847586
0.46103674818941215,0.08077695539107822,467.35983673877087,52.16954511951832,-0.7564480634847586
0.4644345485148465,0.08137227445489098,468.3053194174294,52.16954511951832,-0.7564480634847586
0.4693668393098318,0.08223644728945789,469.6730081017886,52.16954511951832,-0.7564480634847586
0.4696956586961642,0.08229405881176236,469.76398755278535,52.16954511951832,-0.7564480634847586
0.4730934590215985,0.08288937787557511,470.70265861807246,52.16954511951832,-0.7564480634847586
0.47429913010481717,0.0831006201240248,471.0351029719297,52.16954511951832,-0.7564480634847586
0.476929685195476,0.08356151230246049,471.75929426467906,52.16954511951832,-0.7564480634847586
0.4789026015134702,0.08390718143628727,472.3014158714752,52.16954511951832,-0.7564480634847586
0.4810947307556859,0.08429125825165033,472.90275269089864,52.16954511951832,-0.7564480634847586
0.4832868599979016,0.08467533506701341,473.5030218479724,52.16954511951832,-0.7564480634847586
0.48843836371710847,0.08557791558311663,474.90949002821543,52.16954511951832,-0.7564480634847586
0.489205608951884,0.0857123424684937,475.11846798888035,52.16954511951832,-0.7564480634847586
0.4918361640425428,0.08617323464692939,475.83399544800267,52.16954511951832,-0.7564480634847586
0.4931514415878723,0.08640368073614724,476.1911993740066,52.16954511951832,-0.7564480634847586
0.494795538519534,0.08669173834766954,476.6371822204443,52.16954511951832,-0.7564480634847586
0.5002758616250733,0.08765193038607721,478.11963526202305,52.16954511951832,-0.7564480634847586
0.5026872037915106,0.0880744148829766,478.7699067124045,52.16954511951832,-0.7564480634847586
0.5046601201095047,0.08842008401680336,479.30104261548087,52.16954511951832,-0.7564480634847586
0.5089347721318254,0.08916903380676136,480.44906693945893,52.16954511951832,-0.7564480634847586
0.5112365078361518,0.08957231446289259,481.0656759890971,52.16954511951832,-0.7564480634847586
0.5118941466088166,0.08968753750750151,481.24165101789094,52.16954511951832,-0.7564480634847586
0.5130998176920352,0.08989877975595119,481.56404307653315,52.16954511951832,-0.7564480634847586
0.5134286370783675,0.08995639127825565,481.651916890807,52.16954511951832,-0.7564480634847586
0.5145247016994754,0.0901484296859372,481.9446712187442,52.16954511951832,-0.7564480634847586
0.5154015533963617,0.09030206041208243,482.17869960131344,52.16954511951832,-0.7564480634847586
0.5184705343354636,0.09083976795359072,482.99657892115914,52.16954511951832,-0.7564480634847586
0.5192377795702391,0.09097419483896779,483.2007534688112,52.16954511951832,-0.7564480634847586
0.5200050248050146,0.09110862172434488,483.4048103888777,52.16954511951832,-0.7564480634847586
0.5226355798956736,0.09156951390278056,484.10354441144494,52.16954511951832,-0.7564480634847586
0.5250469220621108,0.09199199839967995,484.74284663583666,52.16954511951832,-0.7564480634847586
0.5316233097887579,0.09314422884576916,486.4806045778881,52.16954511951832,-0.7564480634847586
0.5332674067204196,0.09343228645729146,486.9137316131995,52.16954511951832,-0.7564480634847586
0.5392957621365129,0.09448849769953992,488.4974279501437,52.16954511951832,-0.7564480634847586
0.5410494655302854,0.09479575915183037,488.95684128272404,52.16954511951832,-0.7564480634847586
0.5414878913787285,0.09487257451490298,489.0716038291139,52.16954511951832,-0.7564480634847586
0.5440088400072767,0.09531426285257052,489.7307865746957,52.16954511951832,-0.7564480634847586
0.5454337240147169,0.09556391278255652,490.10284113610777,52.16954511951832,-0.7564480634847586
0.5475162467948218,0.09592878575715144,490.64593205289395,52.16954511951832,-0.7564480634847586
0.5517908988171424,0.09667773554710943,491.7581801633353,52.16954511951832,-0.7564480634847586
0.5531061763624718,0.09690818163632726,492.099733629066,52.16954511951832,-0.7564480634847586
0.5543118474456905,0.09711942388477696,492.41254614310486,52.16954511951832,-0.7564480634847586
0.5565039766879062,0.09750350070014004,492.9806171861758,52.16954511951832,-0.7564480634847586
0.558148073619568,0.09779155831166234,493.40609793614846,52.16954511951832,-0.7564480634847586
0.5613266610207808,0.09834846969393879,494.2273106128543,52.16954511951832,-0.7564480634847586
0.5632995773387749,0.09869413882776555,494.7361167363812,52.16954511951832,-0.7564480634847586
0.5653821001188798,0.09905901180236047,495.27243645585463,52.16954511951832,-0.7564480634847586
0.5700951779896436,0.09988477695539108,496.4833759481006,52.16954511951832,-0.7564480634847586
0.5702047844517544,0.09990398079615924,496.51149077756764,52.16954511951832,-0.7564480634847586