File: datasets/aisi_316_L/data/M1/train_83.csv
Time(s),Strain(%),Stress(MPa),Temp(C),Log_SR(s-1)
0.0,0.0,0.0,54.618498101022524,-0.20881326417725976
9.057352936993771e-06,5.6e-06,1.0924087999999998,54.618498101022524,-0.20881326417725976
1.552689074913218e-05,9.6e-06,1.8727007999999998,54.618498101022524,-0.20881326417725976
5.175630249710727e-05,3.2e-05,6.242336,54.618498101022524,-0.20881326417725976
5.6931932746818e-05,3.52e-05,6.8665696,54.618498101022524,-0.20881326417725976
7.11649159335225e-05,4.4e-05,8.583212,54.618498101022524,-0.20881326417725976
9.963088230693149e-05,6.159999999999999e-05,12.016496799999999,54.618498101022524,-0.20881326417725976
0.00011903949574334672,7.36e-05,14.3573728,54.618498101022524,-0.20881326417725976
0.00013068466380519587,8.08e-05,15.7618984,54.618498101022524,-0.20881326417725976
0.0001565628150537495,9.68e-05,18.8830664,54.618498101022524,-0.20881326417725976
0.00016691407555317095,0.0001032,20.1315336,54.618498101022524,-0.20881326417725976
0.00018502878142715847,0.00011439999999999999,22.316351199999996,54.618498101022524,-0.20881326417725976
0.00020184957973871836,0.0001248,24.3451104,54.618498101022524,-0.20881326417725976
0.00022125819317513358,0.0001368,26.685986399999997,54.618498101022524,-0.20881326417725976
0.0002406668066115488,0.00014879999999999998,29.026862399999995,54.618498101022524,-0.20881326417725976
0.00025360588223582564,0.0001568,30.587446399999997,54.618498101022524,-0.20881326417725976
0.00028854138642137305,0.0001784,34.8010232,54.618498101022524,-0.20881326417725976
0.0002988926469207945,0.0001848,36.049490399999996,54.618498101022524,-0.20881326417725976
0.0003118317225450713,0.0001928,37.6100744,54.618498101022524,-0.20881326417725976
0.0003208890754820651,0.0001984,38.702483199999996,54.618498101022524,-0.20881326417725976
0.0003325342435439142,0.00020559999999999998,40.107008799999996,54.618498101022524,-0.20881326417725976
0.0003519428569803294,0.00021759999999999998,42.4478848,54.618498101022524,-0.20881326417725976
0.0003571184872300402,0.0002208,43.0721184,54.618498101022524,-0.20881326417725976
0.0003674697477294616,0.0002272,44.3205856,54.618498101022524,-0.20881326417725976
0.0003713514704167447,0.0002296,44.7887608,54.618498101022524,-0.20881326417725976
0.0003894661762907322,0.0002408,46.9735784,54.618498101022524,-0.20881326417725976
0.0004256955880387073,0.0002632,51.3432136,54.618498101022524,-0.20881326417725976
0.00043992857122541183,0.000272,53.059855999999996,54.618498101022524,-0.20881326417725976
0.000459337184661827,0.00028399999999999996,55.40073199999999,54.618498101022524,-0.20881326417725976
0.000491684873722519,0.00030399999999999996,59.30219199999999,54.618498101022524,-0.20881326417725976
0.0005020361342219405,0.0003104,60.5506592,54.618498101022524,-0.20881326417725976
0.0005434411762196263,0.000336,65.544528,54.618498101022524,-0.20881326417725976
0.0005499107140317647,0.00033999999999999997,66.32481999999999,54.618498101022524,-0.20881326417725976
0.0005796705879676014,0.0003584,69.91416319999999,54.618498101022524,-0.20881326417725976
0.0006146060921531488,0.00037999999999999997,74.12773999999999,54.618498101022524,-0.20881326417725976
0.0006249573526525702,0.00038639999999999996,75.3762072,54.618498101022524,-0.20881326417725976
0.0006417781509641302,0.0003968,77.40496639999999,54.618498101022524,-0.20881326417725976
0.0006754197475872498,0.00041759999999999996,81.4624848,54.618498101022524,-0.20881326417725976
0.0006974161761485204,0.00043119999999999996,84.11547759999999,54.618498101022524,-0.20881326417725976
0.0007349394954589232,0.0004544,88.6411712,54.618498101022524,-0.20881326417725976
0.0007724628147693259,0.00047759999999999995,93.16686479999998,54.618498101022524,-0.20881326417725976
0.0007750506298941814,0.0004792,93.4789816,54.618498101022524,-0.20881326417725976
0.0008423338231404207,0.0005208,101.5940184,54.618498101022524,-0.20881326417725976
0.0008475094533901315,0.0005239999999999999,102.21825199999999,54.618498101022524,-0.20881326417725976
0.0008656241592641191,0.0005352,104.4030696,54.618498101022524,-0.20881326417725976
0.0008772693273259682,0.0005424,105.8075952,54.618498101022524,-0.20881326417725976
0.000910910923949088,0.0005632,109.8651136,54.618498101022524,-0.20881326417725976
0.0009393768903224971,0.0005808,113.29839840000001,54.618498101022524,-0.20881326417725976
0.000971724579383189,0.0006008,117.1998584,54.618498101022524,-0.20881326417725976
0.0009911331928196042,0.0006127999999999999,119.54073439999999,54.618498101022524,-0.20881326417725976
0.0010312443272548623,0.0006376,124.3785448,54.618498101022524,-0.20881326417725976
0.0010415955877542838,0.0006439999999999999,125.627012,54.618498101022524,-0.20881326417725976
0.0010674737390028374,0.00066,128.74818,54.618498101022524,-0.20881326417725976
0.0011114665961253786,0.0006872,134.0541656,54.618498101022524,-0.20881326417725976
0.0011308752095617939,0.0006992,136.39504159999998,54.618498101022524,-0.20881326417725976
0.0011476960078733538,0.0007096,138.4238008,54.618498101022524,-0.20881326417725976
0.001167104621309769,0.0007216,140.7646768,54.618498101022524,-0.20881326417725976
0.0011878071423086119,0.0007344,143.2616112,54.618498101022524,-0.20881326417725976
0.0012240365540565868,0.0007568,147.63124639999998,54.618498101022524,-0.20881326417725976
0.001256384243117279,0.0007768,151.5327064,54.618498101022524,-0.20881326417725976
0.0012706172263039835,0.0007856,153.2493488,54.618498101022524,-0.20881326417725976
0.0012822623943658327,0.0007928,154.6538744,54.618498101022524,-0.20881326417725976
0.001309434453176814,0.0008096,157.9311008,54.618498101022524,-0.20881326417725976
0.0013482516800496444,0.0008336,162.61285279999998,54.618498101022524,-0.20881326417725976
0.0013611907556739212,0.0008416,164.1734368,54.618498101022524,-0.20881326417725976
0.0013676602934860596,0.0008456,164.9537288,54.618498101022524,-0.20881326417725976
0.0014245922262328776,0.0008807999999999999,171.82029839999998,54.618498101022524,-0.20881326417725976
0.0014944632346039722,0.0009239999999999999,180.24745199999998,54.618498101022524,-0.20881326417725976
0.0015255170161022366,0.0009431999999999999,183.9928536,54.618498101022524,-0.20881326417725976
0.0015358682766016582,0.0009496,185.2413208,54.618498101022524,-0.20881326417725976
0.0015863306715363378,0.0009808,191.3275984,54.618498101022524,-0.20881326417725976
0.0015940941169109038,0.0009855999999999999,192.26394879999998,54.618498101022524,-0.20881326417725976
0.0016199722681594577,0.0010016,195.38511680000002,54.618498101022524,-0.20881326417725976
0.0016484382345328668,0.0010192,198.81840160000002,54.618498101022524,-0.20881326417725976
0.001678198108468703,0.0010375999999999999,202.40774479999996,54.618498101022524,-0.20881326417725976
0.0017027823521548293,0.0010528,205.3728544,54.618498101022524,-0.20881326417725976
0.0017648899151513576,0.0010911999999999999,212.86365759999998,54.618498101022524,-0.20881326417725976
0.0017713594529634963,0.0010952,213.64394959999998,54.618498101022524,-0.20881326417725976
0.0017881802512750562,0.0011056,215.6727088,54.618498101022524,-0.20881326417725976
0.0018037071420241883,0.0011152,217.5454096,54.618498101022524,-0.20881326417725976
0.0018101766798363267,0.0011191999999999999,218.32570159999997,54.618498101022524,-0.20881326417725976
0.001833467015960025,0.0011336,221.1347528,54.618498101022524,-0.20881326417725976
0.0018425243688970187,0.0011392,222.2271616,54.618498101022524,-0.20881326417725976
0.0018593451672085787,0.0011496,224.25592079999998,54.618498101022524,-0.20881326417725976
0.0018929867638316986,0.0011704,228.3134392,54.618498101022524,-0.20881326417725976
0.001938273528516667,0.0011983999999999999,233.77548319999997,54.618498101022524,-0.20881326417725976
0.00195897604951551,0.0012112,236.27241759999998,54.618498101022524,-0.20881326417725976
0.001974502940264642,0.0012208,238.1451184,54.618498101022524,-0.20881326417725976
0.0019900298310137747,0.0012304,240.0178192,54.618498101022524,-0.20881326417725976
0.0020184957973871836,0.001248,243.451104,54.618498101022524,-0.20881326417725976
0.0020430800410733093,0.0012632,246.4162136,54.618498101022524,-0.20881326417725976
0.002106481511632266,0.0013024,254.0630752,54.618498101022524,-0.20881326417725976
0.0021323596628808196,0.0013184,257.18424319999997,54.618498101022524,-0.20881326417725976
0.0021427109233802407,0.0013248,258.43271039999996,54.618498101022524,-0.20881326417725976
0.002202230671251914,0.0013616,265.61139679999997,54.618498101022524,-0.20881326417725976
0.0022397539905623168,0.0013847999999999998,270.1370904,54.618498101022524,-0.20881326417725976
0.0022617504191235877,0.0013984,272.79008319999997,54.618498101022524,-0.20881326417725976
0.002281159032560003,0.0014104,275.1309592,54.618498101022524,-0.20881326417725976
0.0022992737384339903,0.0014215999999999999,276.38926122062173,54.618498101022524,-0.20881326417725976
0.002321270166995261,0.0014352,276.49427288698405,54.618498101022524,-0.20881326417725976
0.002347148318243815,0.0014512,276.61732045546574,54.618498101022524,-0.20881326417725976
0.0023639691165553743,0.0014616,276.6970177481628,54.618498101022524,-0.20881326417725976
0.0024377218476137525,0.0015072,277.0438811047819,54.618498101022524,-0.20881326417725976
0.0025295892845461176,0.0015639999999999999,277.4702666652439,54.618498101022524,-0.20881326417725976
0.002556761343357099,0.0015807999999999998,277.5952177435792,54.618498101022524,-0.20881326417725976
0.002572288234106231,0.0015903999999999998,277.66638582609465,54.618498101022524,-0.20881326417725976
0.0026175749987912,0.0016183999999999999,277.87300864156344,54.618498101022524,-0.20881326417725976
0.0026421592424773262,0.0016336,277.9845912795828,54.618498101022524,-0.20881326417725976
0.002666743486163452,0.0016488,278.0957697338739,54.618498101022524,-0.20881326417725976
0.002683564284475012,0.0016592,278.1716089910791,54.618498101022524,-0.20881326417725976
0.0027068546205987103,0.0016736,278.27631184150096,54.618498101022524,-0.20881326417725976
0.0027223815113478424,0.0016832,278.3459186162338,54.618498101022524,-0.20881326417725976
0.002736614494534547,0.001692,278.4095889340945,54.618498101022524,-0.20881326417725976
0.002763786553345528,0.0017088,278.5307838781003,54.618498101022524,-0.20881326417725976
0.0028013098726559307,0.0017319999999999998,278.6973871323615,54.618498101022524,-0.20881326417725976
0.0028064855029056417,0.0017352,278.72029840070974,54.618498101022524,-0.20881326417725976
0.0028116611331553527,0.0017384,278.74319319660395,54.618498101022524,-0.20881326417725976
0.002841421007091189,0.0017568,278.8745207056998,54.618498101022524,-0.20881326417725976
0.0029332884440235545,0.0018135999999999998,279.2765795087021,54.618498101022524,-0.20881326417725976
0.0029630483179593913,0.0018319999999999999,279.40576680091397,54.618498101022524,-0.20881326417725976
0.003052327939766901,0.0018872,279.7903260782087,54.618498101022524,-0.20881326417725976
0.0031196111330131404,0.0019287999999999998,280.0772466054316,54.618498101022524,-0.20881326417725976
0.0031441953766992666,0.001944,280.1814796213901,54.618498101022524,-0.20881326417725976
0.0031532527296362603,0.0019496,280.21980107524377,54.618498101022524,-0.20881326417725976
0.003166191805260537,0.0019576,280.27447162485504,54.618498101022524,-0.20881326417725976
0.0032024212170085123,0.00198,280.4270875502985,54.618498101022524,-0.20881326417725976
0.0032101846623830785,0.0019848,280.4597031886395,54.618498101022524,-0.20881326417725976
0.0032295932758194938,0.0019968,280.5411079891918,54.618498101022524,-0.20881326417725976
0.00327617394806689,0.0020256,280.7357049881731,54.618498101022524,-0.20881326417725976
0.003299464284190588,0.0020399999999999997,280.8325986257949,54.618498101022524,-0.20881326417725976
0.003305933822002727,0.002044,280.8594661396725,54.618498101022524,-0.20881326417725976
0.0033149911749397205,0.0020496,280.89704623538125,54.618498101022524,-0.20881326417725976
0.0033356936959385635,0.0020624,280.9827935499009,54.618498101022524,-0.20881326417725976
0.003380980460623533,0.0020904,281.16964553147216,54.618498101022524,-0.20881326417725976
0.0034094464269969417,0.002108,281.2865958904203,54.618498101022524,-0.20881326417725976
0.003449557561432199,0.0021328,281.45074528039265,54.618498101022524,-0.20881326417725976
0.003484493065617747,0.0021544,281.5931085245017,54.618498101022524,-0.20881326417725976
0.0035090773093038726,0.0021696,281.6929565645777,54.618498101022524,-0.20881326417725976
0.003531073737865143,0.0021831999999999997,281.78206326911794,54.618498101022524,-0.20881326417725976
0.0035336615529899984,0.0021847999999999998,281.79253215947267,54.618498101022524,-0.20881326417725976
0.00356083361180098,0.0022015999999999997,281.9022755908901,54.618498101022524,-0.20881326417725976
0.003568597057175546,0.0022064,281.9335708069587,54.618498101022524,-0.20881326417725976
0.0035750665949876846,0.0022104,281.95962987597744,54.618498101022524,-0.20881326417725976
0.003589299578174389,0.0022191999999999997,282.0168951781688,54.618498101022524,-0.20881326417725976
0.00361129600673566,0.0022328,282.10522221330456,54.618498101022524,-0.20881326417725976
0.003643643695796352,0.0022528,282.23473470321096,54.618498101022524,-0.20881326417725976
0.003668227939482478,0.002268,282.3328645126968,54.618498101022524,-0.20881326417725976
0.003699281720980742,0.0022872,282.4564521157577,54.618498101022524,-0.20881326417725976
0.0037575075612899882,0.0023232,282.6870937600811,54.618498101022524,-0.20881326417725976
0.003809263863787095,0.0023552,282.89094095338254,54.618498101022524,-0.20881326417725976
0.003815733401599234,0.0023592,282.91634568443203,54.618498101022524,-0.20881326417725976
0.0038416115528477875,0.0023752,283.01779707171096,54.618498101022524,-0.20881326417725976
0.003885604409970328,0.0024024,283.1896548718272,54.618498101022524,-0.20881326417725976
0.0039127764687813095,0.0024192,283.2954233090346,54.618498101022524,-0.20881326417725976
0.0040007621830263915,0.0024736,283.63596260089224,54.618498101022524,-0.20881326417725976
0.004034403779649511,0.0024944,283.76539532531956,54.618498101022524,-0.20881326417725976
0.0040382855023367945,0.0024968,283.78030273546784,54.618498101022524,-0.20881326417725976
0.0040551063006483545,0.0025072,283.84483704240375,54.618498101022524,-0.20881326417725976
0.004066751468710204,0.0025144,283.889453495398,54.618498101022524,-0.20881326417725976
0.00407451491408477,0.0025192,283.9191701193559,54.618498101022524,-0.20881326417725976
0.0041094504182703166,0.0025407999999999997,284.0526226007937,54.618498101022524,-0.20881326417725976
0.0041366224770812985,0.0025575999999999997,284.15611331249465,54.618498101022524,-0.20881326417725976
0.0041573249980801415,0.0025704,284.2347855272784,54.618498101022524,-0.20881326417725976
0.004196142224952972,0.0025943999999999997,284.3818853365207,54.618498101022524,-0.20881326417725976
0.004227196006451236,0.0026135999999999998,284.49918343463617,54.618498101022524,-0.20881326417725976
0.0042388411745130855,0.0026208,284.54308352010446,54.618498101022524,-0.20881326417725976
0.004263425418199211,0.002636,284.63560731512956,54.618498101022524,-0.20881326417725976
0.0042893035694477645,0.002652,284.73277627785785,54.618498101022524,-0.20881326417725976
0.004328120796320596,0.002676,284.8781021314476,54.618498101022524,-0.20881326417725976
0.004366938023193425,0.0026999999999999997,285.02292055022247,54.618498101022524,-0.20881326417725976
0.004377289283692847,0.0027064,285.06145389691017,54.618498101022524,-0.20881326417725976
0.004430339493752382,0.0027392,285.2583822815697,54.618498101022524,-0.20881326417725976
0.004457511552563363,0.0027559999999999998,285.35889174883687,54.618498101022524,-0.20881326417725976
0.004485977518936772,0.0027735999999999998,285.4639314324217,54.618498101022524,-0.20881326417725976
0.004519619115559892,0.0027944,285.58773469024794,54.618498101022524,-0.20881326417725976
0.00455455461974544,0.002816,285.7159198147683,54.618498101022524,-0.20881326417725976
0.004623131720554107,0.0028583999999999997,285.96643275088786,54.618498101022524,-0.20881326417725976
0.00464900987180266,0.0028744,286.0605887787656,54.618498101022524,-0.20881326417725976
0.004667124577676648,0.0028856,286.1263764163713,54.618498101022524,-0.20881326417725976
0.004689121006237918,0.0028991999999999998,286.20612767728954,54.618498101022524,-0.20881326417725976
0.004708529619674334,0.0029112,286.27637535153,54.618498101022524,-0.20881326417725976
0.004716293065048899,0.0029159999999999998,286.3044427902119,54.618498101022524,-0.20881326417725976
0.0047240565104234656,0.0029208,286.332492216064,54.618498101022524,-0.20881326417725976
0.004735701678485316,0.002928,286.3745326707221,54.618498101022524,-0.20881326417725976
0.004764167644858724,0.0029456,286.4771288542736,54.618498101022524,-0.20881326417725976
0.0047887518885448505,0.0029608,286.5655424031194,54.618498101022524,-0.20881326417725976
0.004802984871731555,0.0029695999999999998,286.61664828566563,54.618498101022524,-0.20881326417725976
0.0048159239473558315,0.0029776,286.6630569484492,54.618498101022524,-0.20881326417725976
0.004834038653229819,0.0029888,286.7279474643755,54.618498101022524,-0.20881326417725976
0.004853447266666234,0.0030007999999999996,286.79736786931306,54.618498101022524,-0.20881326417725976
0.004874149787665078,0.0030136,286.8712970743162,54.618498101022524,-0.20881326417725976
0.0048832071406020704,0.0030191999999999997,286.90360258181494,54.618498101022524,-0.20881326417725976
0.004949196426285883,0.00306,287.1382699545799,54.618498101022524,-0.20881326417725976
0.00498413193047143,0.0030816,287.2620114413088,54.618498101022524,-0.20881326417725976
0.005020361342219406,0.003104,287.3899791834167,54.618498101022524,-0.20881326417725976
0.005028124787593971,0.0031087999999999997,287.4173539279021,54.618498101022524,-0.20881326417725976
0.005055296846404952,0.0031255999999999996,287.51303599230516,54.618498101022524,-0.20881326417725976
0.005095407980840211,0.0031504,287.65391517967953,54.618498101022524,-0.20881326417725976
0.005139400837962752,0.0031776,287.8079314472341,54.618498101022524,-0.20881326417725976
0.005161397266524022,0.0031912,287.8847467077838,54.618498101022524,-0.20881326417725976
0.005171748527023443,0.0031975999999999997,287.92085087883515,54.618498101022524,-0.20881326417725976
0.005183393695085293,0.0032048,287.9614344015203,54.618498101022524,-0.20881326417725976
0.00521315356902113,0.0032232,288.06498662890397,54.618498101022524,-0.20881326417725976
0.0052235048295205515,0.0032296,288.10095072104735,54.618498101022524,-0.20881326417725976
0.005237737812707256,0.0032384,288.1503559969945,54.618498101022524,-0.20881326417725976
0.0052674976866430925,0.0032568,288.2534890658111,54.618498101022524,-0.20881326417725976
0.0052843184849546525,0.0032672,288.31168114658306,54.618498101022524,-0.20881326417725976
0.00532442961938991,0.003292,288.4501561198805,54.618498101022524,-0.20881326417725976
0.005361952938700313,0.0033152,288.57932935927244,54.618498101022524,-0.20881326417725976
0.005466759451256955,0.0033799999999999998,288.93826929788145,54.618498101022524,-0.20881326417725976
0.005504282770567358,0.0034032,289.0661249201179,54.618498101022524,-0.20881326417725976
0.00557544768650088,0.0034471999999999997,289.3076798865507,54.618498101022524,-0.20881326417725976
0.005598738022624579,0.0034616,289.3864726857326,54.618498101022524,-0.20881326417725976
0.005605207560436717,0.0034655999999999997,289.4083368750899,54.618498101022524,-0.20881326417725976
0.005622028358748277,0.003476,289.4651377569486,54.618498101022524,-0.20881326417725976
0.005650494325121686,0.0034936,289.5611115687382,54.618498101022524,-0.20881326417725976
0.00571001407299336,0.0035304,289.76117689586084,54.618498101022524,-0.20881326417725976
0.0057358922242419135,0.0035464,289.84790795952375,54.618498101022524,-0.20881326417725976
0.005756594745240756,0.0035591999999999998,289.9171829845166,54.618498101022524,-0.20881326417725976
0.005781178988926882,0.0035743999999999997,289.99932100668565,54.618498101022524,-0.20881326417725976
0.005794118064551159,0.0035824,290.04249682339935,54.618498101022524,-0.20881326417725976
0.0058005876023632975,0.0035864,290.0640706295149,54.618498101022524,-0.20881326417725976
0.005822584030924568,0.0036,290.1373514793241,54.618498101022524,-0.20881326417725976
0.00585493171998526,0.00362,290.24492160564864,54.618498101022524,-0.20881326417725976
0.005875634240984103,0.0036328,290.3136448663367,54.618498101022524,-0.20881326417725976
0.005889867224170808,0.0036416,290.3608373374929,54.618498101022524,-0.20881326417725976
0.005898924577107801,0.0036471999999999997,290.39084575447924,54.618498101022524,-0.20881326417725976
0.005915745375419361,0.0036576,290.44652804080124,54.618498101022524,-0.20881326417725976
0.005929978358606066,0.0036663999999999998,290.4935956096811,54.618498101022524,-0.20881326417725976
0.00594421134179277,0.0036752,290.5406191406762,54.618498101022524,-0.20881326417725976
0.005975265123291034,0.0036944,290.643063784447,54.618498101022524,-0.20881326417725976
0.00599467373672745,0.0037064,290.7069862558647,54.618498101022524,-0.20881326417725976
0.006049017854349412,0.00374,290.8855412016563,54.618498101022524,-0.20881326417725976
0.006086541173659815,0.0037632,291.0084641886812,54.618498101022524,-0.20881326417725976
0.006144767013969061,0.0037992,291.1986232467076,54.618498101022524,-0.20881326417725976
0.00619522940890374,0.0038304,291.3628600370077,54.618498101022524,-0.20881326417725976
0.006236634450901425,0.0038559999999999996,291.49722911178594,54.618498101022524,-0.20881326417725976
0.006261218694587552,0.0038712,291.57684614475625,54.618498101022524,-0.20881326417725976
0.006327207980271364,0.003912,291.7899544797781,54.618498101022524,-0.20881326417725976
0.006347910501270207,0.0039248,291.8566331370178,54.618498101022524,-0.20881326417725976
0.006364731299581767,0.0039352,291.9107471204039,54.618498101022524,-0.20881326417725976
0.006372494744956333,0.00394,291.9357039905883,54.618498101022524,-0.20881326417725976
0.006393197265955176,0.0039528,292.0021977417028,54.618498101022524,-0.20881326417725976
0.0064216632323285845,0.0039704,292.0934896970328,54.618498101022524,-0.20881326417725976
0.006966497708089829,0.004307261452290458,293.81149001501814,54.618498101022524,-0.20881326417725976
0.007711937552016959,0.004768153630726146,296.0793883722104,54.618498101022524,-0.20881326417725976
0.008954337291895511,0.005536307261452291,299.67752464664414,54.618498101022524,-0.20881326417725976
0.009327057213859074,0.005766753350670134,300.7182354954876,54.618498101022524,-0.20881326417725976
0.010041437064289241,0.0062084416883376676,302.66866390983495,54.618498101022524,-0.20881326417725976
0.010383096992755842,0.006419683936787358,303.58227314890115,54.618498101022524,-0.20881326417725976
0.010538396960240662,0.006515703140628126,303.9936664109159,54.618498101022524,-0.20881326417725976
0.010755816914719407,0.006650130026005201,304.5656667160338,54.618498101022524,-0.20881326417725976
0.011004296862695117,0.00680376075215043,305.21388818228934,54.618498101022524,-0.20881326417725976
0.01178079670011921,0.00728385677135427,307.2037271848693,54.618498101022524,-0.20881326417725976
0.012277756596070631,0.007591118223644729,308.45041517998317,54.618498101022524,-0.20881326417725976
0.012743656498525087,0.007879175835167033,309.60142600570026,54.618498101022524,-0.20881326417725976
0.012930016459506869,0.007994398879775955,310.05722058338114,54.618498101022524,-0.20881326417725976
0.013395916361961326,0.00828245649129826,311.1856386693063,54.618498101022524,-0.20881326417725976
0.013986056238403637,0.008647329465893179,312.59323051742786,54.618498101022524,-0.20881326417725976
0.014607256108342914,0.009031406281256251,314.05010298047944,54.618498101022524,-0.20881326417725976
0.014886796049815586,0.009204240848169634,314.69779084428853,54.618498101022524,-0.20881326417725976
0.015011036023803442,0.009281056211242249,314.98412776145005,54.618498101022524,-0.20881326417725976
0.01532163595877308,0.009473094618923785,315.69595583483846,54.618498101022524,-0.20881326417725976
0.0154769359262579,0.009569113822764553,316.0497577948383,54.618498101022524,-0.20881326417725976
0.016439795724663777,0.010164432886577316,318.2132054607506,54.618498101022524,-0.20881326417725976
0.01690569562711823,0.010452490498099619,319.24224153658747,54.618498101022524,-0.20881326417725976
0.01786855542552411,0.011047809561912383,321.3345099916999,54.618498101022524,-0.20881326417725976
0.01914201515889962,0.01183516703340668,324.0353535877806,54.618498101022524,-0.20881326417725976
0.019266255132887475,0.011911982396479295,324.2950410055487,54.618498101022524,-0.20881326417725976
0.019607915061354078,0.012123224644928985,325.0058354636809,54.618498101022524,-0.20881326417725976
0.019763215028838897,0.012219243848769754,325.3273254125643,54.618498101022524,-0.20881326417725976
0.020135934950802462,0.012449689937987597,326.09490781150095,54.618498101022524,-0.20881326417725976
0.020695014833747808,0.012795359071814363,327.2359721231053,54.618498101022524,-0.20881326417725976
0.02103667476221441,0.013006601320264053,327.9273727132099,54.618498101022524,-0.20881326417725976
0.02153363465816583,0.013313862772554511,328.9252791728056,54.618498101022524,-0.20881326417725976
0.022061654547614214,0.013640328065613123,329.9757630869126,54.618498101022524,-0.20881326417725976
0.022496494456571706,0.013909181836367274,330.8335241849589,54.618498101022524,-0.20881326417725976
0.023987374144425967,0.014830966193238648,333.72653389415825,54.618498101022524,-0.20881326417725976
0.024794933975347027,0.015330266053210643,335.26425631239835,54.618498101022524,-0.20881326417725976
0.025136593903813627,0.015541508301660333,335.9089367425138,54.618498101022524,-0.20881326417725976
0.02597521372823165,0.01606001200240048,337.47701308585994,54.618498101022524,-0.20881326417725976
0.02653429361117699,0.016405681136227243,338.51144119581943,54.618498101022524,-0.20881326417725976
0.02703125350712841,0.0167129425885177,339.42381783268473,54.618498101022524,-0.20881326417725976
0.02746609341608591,0.016981796359271856,340.2167943045034,54.618498101022524,-0.20881326417725976
0.028180473266516074,0.017423484696939388,341.50899358716526,54.618498101022524,-0.20881326417725976
0.028397893220994817,0.01755791158231646,341.899727512169,54.618498101022524,-0.20881326417725976
0.029112273071424985,0.017999599919983997,343.1754307154363,54.618498101022524,-0.20881326417725976
0.02973347294136426,0.01838367673534707,344.2748456908053,54.618498101022524,-0.20881326417725976
0.030975872681242814,0.019151830366073215,346.44716128662986,54.618498101022524,-0.20881326417725976
0.0318455524991578,0.019689537907581517,347.94760488189104,54.618498101022524,-0.20881326417725976
0.03358491213498777,0.02076495299059812,350.90138198366486,54.618498101022524,-0.20881326417725976
0.03383339208296348,0.02091858371674335,351.3184273754282,54.618498101022524,-0.20881326417725976
0.03479625188136935,0.02151390278055611,352.9233200518884,54.618498101022524,-0.20881326417725976
0.03510685181633899,0.021705941188237647,353.4373202826638,54.618498101022524,-0.20881326417725976
0.0356969916927813,0.022070814162832568,354.4090608196809,54.618498101022524,-0.20881326417725976
0.03709469140014467,0.02293498699739948,356.68589422136057,54.618498101022524,-0.20881326417725976
0.03824391115953234,0.023645529105821166,358.53299318581657,54.618498101022524,-0.20881326417725976
0.03870981106198679,0.02393358671734347,359.27563483070054,54.618498101022524,-0.20881326417725976
0.04023175074333801,0.024874574914982996,361.6776602349878,54.618498101022524,-0.20881326417725976
0.04079083062628336,0.02522024404880976,362.55110241757427,54.618498101022524,-0.20881326417725976
0.04094613059376818,0.02531626325265053,362.79289506700644,54.618498101022524,-0.20881326417725976
0.041287790522234774,0.02552750550110022,363.3235835114682,54.618498101022524,-0.20881326417725976
0.0421264103466528,0.02604600920184037,364.6189727689676,54.618498101022524,-0.20881326417725976
0.04228171031413762,0.026142028405681136,364.85775194288846,54.618498101022524,-0.20881326417725976
0.04271655022309511,0.026410882176435287,365.5245207985712,54.618498101022524,-0.20881326417725976
0.04374153000849492,0.02704460892178436,367.08580309035887,54.618498101022524,-0.20881326417725976
0.0442695498979433,0.02737107421484297,367.8845274421056,54.618498101022524,-0.20881326417725976
0.04517028970935525,0.027927985597119426,369.23853485309536,54.618498101022524,-0.20881326417725976
0.04585360956628846,0.028350470094018806,370.2586998785768,54.618498101022524,-0.20881326417725976
0.04644374944273076,0.028715343068613723,371.1349892545361,54.618498101022524,-0.20881326417725976
0.04718918928665789,0.02917623524704941,372.23569874719703,54.618498101022524,-0.20881326417725976
0.04954974879242714,0.030635727145429087,375.67736383198815,54.618498101022524,-0.20881326417725976
0.050667908558317834,0.03132706541308262,377.28524995748046,54.618498101022524,-0.20881326417725976
0.05156864836972978,0.03188397679535907,378.57045013872,54.618498101022524,-0.20881326417725976
0.051910308298196386,0.03209521904380876,379.05564587419394,54.618498101022524,-0.20881326417725976
0.05231408821365691,0.03234486897379476,379.6274562580743,54.618498101022524,-0.20881326417725976
0.05277998811611137,0.032632926585317065,380.2851030044322,54.618498101022524,-0.20881326417725976
0.05383602789500813,0.033285857171434285,381.7674441708593,54.618498101022524,-0.20881326417725976
0.054084507842983846,0.033439487897579515,382.11457705540266,54.618498101022524,-0.20881326417725976
0.05445722776494741,0.03366993398679736,382.6341124376023,54.618498101022524,-0.20881326417725976
0.05542008756335329,0.03426525305061012,383.9698671957719,54.618498101022524,-0.20881326417725976
0.05591704745930471,0.03457251450290058,384.65574588061105,54.618498101022524,-0.20881326417725976
0.05616552740728042,0.03472614522904581,384.99779342690147,54.618498101022524,-0.20881326417725976
0.056569307322740944,0.034975795159031806,385.5523646654849,54.618498101022524,-0.20881326417725976
0.056786727277219694,0.03511022204440888,385.8503404219815,54.618498101022524,-0.20881326417725976
0.05697308723820147,0.0352254450890178,386.1053942538068,54.618498101022524,-0.20881326417725976
0.05715944719918326,0.035340668133626726,386.3601229210332,54.618498101022524,-0.20881326417725976
0.05759428710814076,0.03560952190438088,386.9532335333009,54.618498101022524,-0.20881326417725976
0.05796700703010431,0.03583996799359872,387.4602253829933,54.618498101022524,-0.20881326417725976
0.05883668684801931,0.036377675535107026,388.63828779608093,54.618498101022524,-0.20881326417725976
0.05902304680900108,0.03649289857971594,388.88984396914225,54.618498101022524,-0.20881326417725976
0.05983060663992215,0.03699219843968794,389.97636072610186,54.618498101022524,-0.20881326417725976
0.06038968652286749,0.037337867573514705,390.72521648972304,54.618498101022524,-0.20881326417725976
0.06088664641881891,0.03764512902580516,391.3885991837645,54.618498101022524,-0.20881326417725976
0.06125936634078247,0.037875575115023,391.8847512961255,54.618498101022524,-0.20881326417725976
0.06172526624323694,0.03816363272654531,392.5032889599293,54.618498101022524,-0.20881326417725976
0.06188056621072175,0.03825965193038608,392.7090632104877,54.618498101022524,-0.20881326417725976
0.06228434612618228,0.038509301860372075,393.24313588714233,54.618498101022524,-0.20881326417725976
0.06281236601563067,0.03883576715343069,393.939505608558,54.618498101022524,-0.20881326417725976
0.06464490563195151,0.039968793758751744,396.3388029946585,54.618498101022524,-0.20881326417725976
0.06486232558643028,0.04010322064412883,396.6216943273558,54.618498101022524,-0.20881326417725976
0.06576306539784223,0.04066013202640528,397.7897546091514,54.618498101022524,-0.20881326417725976
0.06626002529379364,0.04096739347869574,398.43153026271136,54.618498101022524,-0.20881326417725976
0.06709864511821166,0.04148589717943589,399.5102861624755,54.618498101022524,-0.20881326417725976
0.0675024250336722,0.041735547109421886,400.02781069731424,54.618498101022524,-0.20881326417725976
0.06781302496864182,0.04192758551710342,400.425085375373,54.618498101022524,-0.20881326417725976
0.06815468489710842,0.04213882776555311,400.8612687778567,54.618498101022524,-0.20881326417725976
0.06933496464999306,0.04286857371474295,402.36156613636985,54.618498101022524,-0.20881326417725976
0.06958344459796877,0.04302220444088818,402.6761452961794,54.618498101022524,-0.20881326417725976
0.06967662457845966,0.043079815963192644,402.79399949340456,54.618498101022524,-0.20881326417725976
0.0706705443703625,0.04369433886777356,404.0473099943946,54.618498101022524,-0.20881326417725976
0.07104326429232606,0.0439247849569914,404.5155267263412,54.618498101022524,-0.20881326417725976
0.07157128418177444,0.044251250250050014,405.177197151507,54.618498101022524,-0.20881326417725976
0.07247202399318639,0.04480816163232647,406.30155197295994,54.618498101022524,-0.20881326417725976
0.07284474391514995,0.045038607721544305,406.7652065248508,54.618498101022524,-0.20881326417725976
0.07352806377208315,0.04546109221844369,407.6128439759884,54.618498101022524,-0.20881326417725976
0.07445986357699208,0.0460372074414883,408.7637787619425,54.618498101022524,-0.20881326417725976
0.0752984834014101,0.04655571114222845,409.79482620167954,54.618498101022524,-0.20881326417725976
0.07579544329736151,0.04686297259451891,410.4037041314109,54.618498101022524,-0.20881326417725976
0.07595074326484634,0.046958991798359676,410.59365892917646,54.618498101022524,-0.20881326417725976
0.07604392324533724,0.04701660332066414,410.7075590990176,54.618498101022524,-0.20881326417725976
0.07725526299171881,0.047765553110622125,412.1833426792816,54.618498101022524,-0.20881326417725976
0.07790752285515505,0.04816883376675335,412.9742561904907,54.618498101022524,-0.20881326417725976
0.07834236276411255,0.048437687537507504,413.50009763424015,54.618498101022524,-0.20881326417725976
0.0815415420942998,0.05041568313662732,417.33439017081935,54.618498101022524,-0.20881326417725976
0.08259758187319656,0.051068613722744544,418.58713891536127,54.618498101022524,-0.20881326417725976
0.0827528818406814,0.051164632926585324,418.7708384620006,54.618498101022524,-0.20881326417725976
0.08390210160006906,0.05187517503500701,420.12606098060076,54.618498101022524,-0.20881326417725976
0.08424376152853566,0.0520864172834567,420.5275663823382,54.618498101022524,-0.20881326417725976
0.08517556133344456,0.0526625325065013,421.6193662886474,54.618498101022524,-0.20881326417725976
0.08585888119037777,0.05308501700340068,422.4170612899504,54.618498101022524,-0.20881326417725976
0.08604524115135956,0.053200240048009606,422.63418427499045,54.618498101022524,-0.20881326417725976
0.08685280098228061,0.0536995399079816,423.5729392094232,54.618498101022524,-0.20881326417725976
0.087380820871729,0.054026005201040214,424.18490053096735,54.618498101022524,-0.20881326417725976
0.08747400085221987,0.05408361672334466,424.29274382758035,54.618498101022524,-0.20881326417725976
0.08769142080669863,0.05421804360872175,424.5442041053563,54.618498101022524,-0.20881326417725976
0.08887170055958327,0.05494778955791159,425.90505489339984,54.618498101022524,-0.20881326417725976
0.0894307804425286,0.05529345869173835,426.5472066405469,54.618498101022524,-0.20881326417725976
0.09008304030596484,0.055696739347869575,427.29440824148196,54.618498101022524,-0.20881326417725976
0.09129438005234641,0.05644568913782756,428.6764942146732,54.618498101022524,-0.20881326417725976
0.09151180000682518,0.056580116023204646,428.92380201408383,54.618498101022524,-0.20881326417725976
0.09259889977921891,0.057252250450090025,430.15692033261007,54.618498101022524,-0.20881326417725976
0.09297161970118246,0.05748269653930786,430.5784023586621,54.618498101022524,-0.20881326417725976
0.0934685795971339,0.05778995799159832,431.1393547346558,54.618498101022524,-0.20881326417725976
0.0937170595451096,0.05794358871774355,431.4193946443856,54.618498101022524,-0.20881326417725976
0.09396553949308531,0.05809721944388878,431.6991451309308,54.618498101022524,-0.20881326417725976
0.09408977946707316,0.058174034806961386,431.83891217304677,54.618498101022524,-0.20881326417725976
0.09477309932400636,0.05859651930386077,432.60634818863883,54.618498101022524,-0.20881326417725976
0.0954253591874426,0.058999799959991994,433.3368901852692,54.618498101022524,-0.20881326417725976
0.09613973903787278,0.05944148829765954,434.1347767443511,54.618498101022524,-0.20881326417725976
0.09694729886879383,0.05994078815763153,435.0339564072151,54.618498101022524,-0.20881326417725976
0.09713365882977562,0.06005601120224045,435.2410440112597,54.618498101022524,-0.20881326417725976
0.09747531875824222,0.060267253450690145,435.6203026174597,54.618498101022524,-0.20881326417725976
0.09759955873223007,0.06034406881376275,435.7580862536286,54.618498101022524,-0.20881326417725976
0.09933891836806004,0.061419483896779356,437.6799310924947,54.618498101022524,-0.20881326417725976
0.09977375827701754,0.06168833766753351,438.1583361982057,54.618498101022524,-0.20881326417725976
0.10033283815996288,0.06203400680136027,438.7722353334347,54.618498101022524,-0.20881326417725976
0.10058131810793859,0.0621876375275055,439.04465100961994,54.618498101022524,-0.20881326417725976
0.10154417790634446,0.06278295659131826,440.0977919934901,54.618498101022524,-0.20881326417725976
0.10247597771125337,0.06335907181436287,441.1132588014457,54.618498101022524,-0.20881326417725976
0.10390473741211372,0.06424244848969794,442.6633416699866,54.618498101022524,-0.20881326417725976
0.10406003737959853,0.06433846769353871,442.83132654099757,54.618498101022524,-0.20881326417725976
0.10458805726904692,0.06466493298659733,443.4017451771318,54.618498101022524,-0.20881326417725976
0.10533349711297406,0.06512582516503301,444.20513375281394,54.618498101022524,-0.20881326417725976
0.10576833702193153,0.06539467893578715,444.67275310705855,54.618498101022524,-0.20881326417725976
0.10763193663174937,0.06654690938187638,446.6684030411523,54.618498101022524,-0.20881326417725976
0.10893645635862184,0.06735347069413883,448.05734722509993,54.618498101022524,-0.20881326417725976
0.11030309607248825,0.0681984396879376,449.5054920139602,54.618498101022524,-0.20881326417725976
0.11073793598144573,0.06846729345869174,449.96479568323593,54.618498101022524,-0.20881326417725976
0.11132807585788805,0.06883216643328666,450.587012894518,54.618498101022524,-0.20881326417725976
0.11166973578635465,0.06904340868173635,450.9466559684954,54.618498101022524,-0.20881326417725976
0.11210457569531215,0.0693122624524905,451.403763474315,54.618498101022524,-0.20881326417725976
0.11225987566279697,0.06940828165633127,451.5668485061592,54.618498101022524,-0.20881326417725976
0.11247729561727571,0.06954270854170834,451.7950198078544,54.618498101022524,-0.20881326417725976
0.11309849548721498,0.06992678535707142,452.4459919156114,54.618498101022524,-0.20881326417725976
0.11331591544169373,0.07006121224244849,452.6735025224703,54.618498101022524,-0.20881326417725976
0.11368863536365731,0.07029165833166634,453.06312502389744,54.618498101022524,-0.20881326417725976
0.11399923529862693,0.07048369673934787,453.3874300444262,54.618498101022524,-0.20881326417725976
0.11477573513605104,0.07096379275855172,454.196688602563,54.618498101022524,-0.20881326417725976
0.11542799499948728,0.07136707341468294,454.87481702749125,54.618498101022524,-0.20881326417725976
0.11592495489543869,0.0716743348669734,455.39048369039875,54.618498101022524,-0.20881326417725976
0.11614237484991743,0.07180876175235047,455.61581667583596,54.618498101022524,-0.20881326417725976
0.11642191479139012,0.07198159631926386,455.90528892991233,54.618498101022524,-0.20881326417725976
0.1174468945767899,0.07261532306461292,456.964375968424,54.618498101022524,-0.20881326417725976
0.11750901456378385,0.07265373074614924,457.0284469638801,54.618498101022524,-0.20881326417725976
0.11791279447924438,0.07290338067613523,457.44458691887354,54.618498101022524,-0.20881326417725976
0.118223394414214,0.07309541908381677,457.7643165096062,54.618498101022524,-0.20881326417725976
0.1184097543751958,0.0732106421284257,457.9559970193705,54.618498101022524,-0.20881326417725976
0.1194347341605956,0.07384436887377475,459.00814426088493,54.618498101022524,-0.20881326417725976
0.11999381404354095,0.07419003800760153,459.58055828282585,54.618498101022524,-0.20881326417725976
0.12070819389397111,0.07463172634526906,460.31046481743226,54.618498101022524,-0.20881326417725976
0.12142257374440127,0.07507341468293659,461.03868857636326,54.618498101022524,-0.20881326417725976
0.12182635365986179,0.07532306461292258,461.44955415105915,54.618498101022524,-0.20881326417725976
0.12232331355581322,0.07563032606521304,461.9545065155613,54.618498101022524,-0.20881326417725976
0.12254073351029197,0.07576475295059013,462.1751715235043,54.618498101022524,-0.20881326417725976
0.12313087338673429,0.07612962592518505,462.77335105558916,54.618498101022524,-0.20881326417725976
0.12412479317863713,0.07674414882976596,463.7782901272605,54.618498101022524,-0.20881326417725976
0.12437327312661284,0.07689777955591119,464.0290339306648,54.618498101022524,-0.20881326417725976
0.1249944729965521,0.07728185637127426,464.6550402080806,54.618498101022524,-0.20881326417725976
0.1267027726388851,0.0783380676135227,466.3703321789247,54.618498101022524,-0.20881326417725976
0.1271376125478426,0.07860692138427686,466.8055088733783,54.618498101022524,-0.20881326417725976
0.12831789230072724,0.0793366673334667,467.9837865204995,54.618498101022524,-0.20881326417725976
0.12999513194956328,0.080373674734947,469.6509358949794,54.618498101022524,-0.20881326417725976
0.13033679187802988,0.08058491698339669,469.98950959073164,54.618498101022524,-0.20881326417725976
0.13061633181950255,0.08075775155031006,470.26626705177983,54.618498101022524,-0.20881326417725976
0.13148601163741755,0.08129545909181837,471.1258167042093,54.618498101022524,-0.20881326417725976
0.13235569145533252,0.08183316663332667,471.98315194083295,54.618498101022524,-0.20881326417725976
0.1329768913252718,0.08221724344868975,472.59418968968146,54.618498101022524,-0.20881326417725976
0.1333185512537384,0.08242848569713944,472.92978590294126,54.618498101022524,-0.20881326417725976
0.13366021118220497,0.08263972794558912,473.26504686628857,54.618498101022524,-0.20881326417725976
0.13412611108465947,0.08292778555711143,473.721682778519,54.618498101022524,-0.20881326417725976
0.13434353103913818,0.0830622124424885,473.9345677983277,54.618498101022524,-0.20881326417725976
0.13484049093508962,0.08336947389477896,474.4206582119933,54.618498101022524,-0.20881326417725976
0.13555487078551978,0.08381116223244649,475.11819090164863,54.618498101022524,-0.20881326417725976
0.1363003106294469,0.08427205441088217,475.8445243180629,54.618498101022524,-0.20881326417725976
0.13735635040834368,0.08492498499699941,476.870850269196,54.618498101022524,-0.20881326417725976
0.13800861027177994,0.08532826565313063,477.5032203137667,54.618498101022524,-0.20881326417725976
0.13835027020024654,0.08553950790158033,477.83399652449907,54.618498101022524,-0.20881326417725976
0.13847451017423437,0.08561632326465293,477.9541997776629,54.618498101022524,-0.20881326417725976
0.1392510100116585,0.08609641928385678,478.70451942027876,54.618498101022524,-0.20881326417725976
0.13990326987509472,0.086499699939988,479.33352774588883,54.618498101022524,-0.20881326417725976
0.1399964498555856,0.08655731146229247,479.4232926262752,54.618498101022524,-0.20881326417725976
0.1403381097840522,0.08676855371074216,479.75223135660013,54.618498101022524,-0.20881326417725976
0.14074188969951273,0.08701820364072815,480.1405747429562,54.618498101022524,-0.20881326417725976
0.14095930965399148,0.08715263052610522,480.34950273490676,54.618498101022524,-0.20881326417725976
0.14186004946540343,0.08770954190838168,481.2137260766788,54.618498101022524,-0.20881326417725976
0.14238806935485182,0.0880360072014403,481.71934480422874,54.618498101022524,-0.20881326417725976
0.1428229092638093,0.08830486097219445,482.1351878585469,54.618498101022524,-0.20881326417725976
0.14344410913374858,0.08868893778755751,482.7283938461257,54.618498101022524,-0.20881326417725976
0.1435994091012334,0.08878495699139828,482.8765386944723,54.618498101022524,-0.20881326417725976
0.1444380289256514,0.08930346069213843,483.6754437486181,54.618498101022524,-0.20881326417725976
0.14490392882810588,0.08959151830366073,484.11849816189084,54.618498101022524,-0.20881326417725976
0.1453077087435664,0.08984116823364674,484.5020294554634,54.618498101022524,-0.20881326417725976
0.14595996860700264,0.09024444888977796,485.12070315717835,54.618498101022524,-0.20881326417725976
0.14636374852246317,0.09049409881976396,485.5031513428418,54.618498101022524,-0.20881326417725976
0.14655010848344496,0.09060932186437289,485.67952708600683,54.618498101022524,-0.20881326417725976
0.14664328846393584,0.09066693338667733,485.767682153988,54.618498101022524,-0.20881326417725976
0.14682964842491764,0.09078215643128626,485.94392677928477,54.618498101022524,-0.20881326417725976
0.1475440282753478,0.0912238447689538,486.6187245298471,54.618498101022524,-0.20881326417725976
0.15012200773559578,0.09281776355271054,489.04333944868534,54.618498101022524,-0.20881326417725976
0.150774267599032,0.09322104420884177,489.654215473694,54.618498101022524,-0.20881326417725976
0.1511469875209956,0.09345149029805962,490.00282473909397,54.618498101022524,-0.20881326417725976
0.15167500741044398,0.09377795559111823,490.49611450636985,54.618498101022524,-0.20881326417725976
0.15223408729338933,0.094123624724945,491.01769189347436,54.618498101022524,-0.20881326417725976
0.15269998719584377,0.0944116823364673,491.45176930410014,54.618498101022524,-0.20881326417725976
0.1527621071828377,0.0944500900180036,491.5096072417472,54.618498101022524,-0.20881326417725976
0.15347648703326788,0.09489177835567114,492.174085595846,54.618498101022524,-0.20881326417725976
0.15468782677964946,0.09564072814562913,493.29805957485667,54.618498101022524,-0.20881326417725976
0.15487418674063125,0.09575595119023805,493.47067350241326,54.618498101022524,-0.20881326417725976
0.15493630672762515,0.09579435887177436,493.52819347459405,54.618498101022524,-0.20881326417725976
0.15527796665609178,0.09600560112022405,493.84439269744837,54.618498101022524,-0.20881326417725976
0.1563029464414916,0.09663932786557312,494.7913663435506,54.618498101022524,-0.20881326417725976
0.1573900462138853,0.0973114622924585,495.79308968851916,54.618498101022524,-0.20881326417725976
0.15770064614885496,0.09750350070014004,496.0788002681963,54.618498101022524,-0.20881326417725976
0.1579180661033337,0.0976379275855171,496.27866710856694,54.618498101022524,-0.20881326417725976
0.15891198589523653,0.09825245049009802,497.19098089754095,54.618498101022524,-0.20881326417725976
0.1596263657456667,0.09869413882776555,497.8453324205311,54.618498101022524,-0.20881326417725976
0.15999908566763027,0.0989245849169834,498.18627977852555,54.618498101022524,-0.20881326417725976
0.1611793654205149,0.09965433086617324,499.2639085772327,54.618498101022524,-0.20881326417725976
0.16161420532947238,0.09992318463692738,499.66015336586486,54.618498101022524,-0.20881326417725976
0.1616763253164663,0.0999615923184637,499.71672580339913,54.618498101022524,-0.20881326417725976