File: datasets/aisi_316_L/data/M1/train_35.csv
Time(s),Strain(%),Stress(MPa),Temp(C),Log_SR(s-1)
0.0,0.0,0.0,116.20048132117756,-0.4758749519514964
6.940055392887878e-05,2.3199999999999998e-05,4.455949325,116.20048132117756,-0.4758749519514964
8.615241177378056e-05,2.88e-05,5.5315233,116.20048132117756,-0.4758749519514964
0.00013880110785775756,4.6399999999999996e-05,8.91189865,116.20048132117756,-0.4758749519514964
0.00017469794609683282,5.8399999999999997e-05,11.216700025,116.20048132117756,-0.4758749519514964
0.00018905668139246288,6.319999999999999e-05,12.138620575,116.20048132117756,-0.4758749519514964
0.0002201672745329948,7.36e-05,14.1361151,116.20048132117756,-0.4758749519514964
0.00026324348041988505,8.8e-05,16.90187675,116.20048132117756,-0.4758749519514964
0.0003350371568980355,0.000112,21.5114795,116.20048132117756,-0.4758749519514964
0.0003709339951371108,0.000124,23.816280875,116.20048132117756,-0.4758749519514964
0.00044272767161526125,0.000148,28.425883624999997,116.20048132117756,-0.4758749519514964
0.0005623837990788454,0.000188,36.108554874999996,116.20048132117756,-0.4758749519514964
0.0005695631667266604,0.0001904,36.56951515,116.20048132117756,-0.4758749519514964
0.0005863150245715621,0.000196,37.645089125,116.20048132117756,-0.4758749519514964
0.0006150324951628224,0.00020559999999999998,39.488930225,116.20048132117756,-0.4758749519514964
0.000670074313796071,0.000224,43.022959,116.20048132117756,-0.4758749519514964
0.0007490473579220366,0.0002504,48.093522025000006,116.20048132117756,-0.4758749519514964
0.00075383360302058,0.000252,48.400828875,116.20048132117756,-0.4758749519514964
0.0007873373187103835,0.0002632,50.551976825,116.20048132117756,-0.4758749519514964
0.000813661666752372,0.000272,52.2421645,116.20048132117756,-0.4758749519514964
0.000918959058920326,0.0003072,59.0029152,116.20048132117756,-0.4758749519514964
0.0011080157403127889,0.0003704,71.141535775,116.20048132117756,-0.4758749519514964
0.0011678438040445811,0.0003904,74.98287140000001,116.20048132117756,-0.4758749519514964
0.001196561274635841,0.00039999999999999996,76.8267125,116.20048132117756,-0.4758749519514964
0.0012252787452271014,0.0004096,78.67055359999999,116.20048132117756,-0.4758749519514964
0.0012851068089588934,0.0004296,82.51188922499999,116.20048132117756,-0.4758749519514964
0.0013210036471979687,0.0004416,84.8166906,116.20048132117756,-0.4758749519514964
0.0013497211177892288,0.00045119999999999996,86.66053169999999,116.20048132117756,-0.4758749519514964
0.0013951904462253908,0.00046639999999999995,89.579946775,116.20048132117756,-0.4758749519514964
0.0014478391423093679,0.000484,92.960322125,116.20048132117756,-0.4758749519514964
0.0014837359805484431,0.000496,95.2651235,116.20048132117756,-0.4758749519514964
0.0015004878383933448,0.0005015999999999999,96.34069747499998,116.20048132117756,-0.4758749519514964
0.001526812186435333,0.0005103999999999999,98.03088514999999,116.20048132117756,-0.4758749519514964
0.0015339915540831485,0.0005128,98.491845425,116.20048132117756,-0.4758749519514964
0.0015507434119280503,0.0005184,99.5674194,116.20048132117756,-0.4758749519514964
0.0015866402501671254,0.0005304,101.872220775,116.20048132117756,-0.4758749519514964
0.0016201439658569288,0.0005415999999999999,104.02336872499998,116.20048132117756,-0.4758749519514964
0.001627323333504744,0.000544,104.484329,116.20048132117756,-0.4758749519514964
0.0016536476815467325,0.0005528,106.17451667499999,116.20048132117756,-0.4758749519514964
0.0016775789070394493,0.0005608,107.711050925,116.20048132117756,-0.4758749519514964
0.00176373131881323,0.0005896,113.242574225,116.20048132117756,-0.4758749519514964
0.0017756969315595884,0.0005936,114.01084135,116.20048132117756,-0.4758749519514964
0.001802021279601577,0.0006024,115.701029025,116.20048132117756,-0.4758749519514964
0.001890566813924629,0.000632,121.38620574999999,116.20048132117756,-0.4758749519514964
0.0019527880002056927,0.0006527999999999999,125.38119479999999,116.20048132117756,-0.4758749519514964
0.00196236049040278,0.000656,125.9958085,116.20048132117756,-0.4758749519514964
0.002055692269824375,0.0006872,131.988292075,116.20048132117756,-0.4758749519514964
0.0021298790688517974,0.000712,136.75154824999998,116.20048132117756,-0.4758749519514964
0.0021681690296401442,0.0007247999999999999,139.21000304999998,116.20048132117756,-0.4758749519514964
0.0022256039708226645,0.000744,142.89768525,116.20048132117756,-0.4758749519514964
0.002266287054160283,0.0007576,145.509793475,116.20048132117756,-0.4758749519514964
0.0022782526669066416,0.0007616,146.2780606,116.20048132117756,-0.4758749519514964
0.0023548325884833353,0.0007871999999999999,151.1949702,116.20048132117756,-0.4758749519514964
0.0023715844463282373,0.0007928,152.270544175,116.20048132117756,-0.4758749519514964
0.002500813063988908,0.0008359999999999999,160.56782912499997,116.20048132117756,-0.4758749519514964
0.0025510686375236134,0.0008527999999999999,163.79455105,116.20048132117756,-0.4758749519514964
0.0026013242110583187,0.0008696,167.021272975,116.20048132117756,-0.4758749519514964
0.0026180760689032204,0.0008751999999999999,168.09684694999999,116.20048132117756,-0.4758749519514964
0.0026444004169452087,0.0008839999999999999,169.787034625,116.20048132117756,-0.4758749519514964
0.0027377321963668044,0.0009151999999999999,175.77951819999998,116.20048132117756,-0.4758749519514964
0.00278798776990151,0.000932,179.006240125,116.20048132117756,-0.4758749519514964
0.0028143121179434985,0.0009408,180.6964278,116.20048132117756,-0.4758749519514964
0.0028214914855913134,0.0009431999999999999,181.157388075,116.20048132117756,-0.4758749519514964
0.0028717470591260188,0.0009599999999999999,184.38411,116.20048132117756,-0.4758749519514964
0.002943540735604169,0.0009839999999999998,188.99371274999996,116.20048132117756,-0.4758749519514964
0.0029578994708997996,0.0009888,189.9156333,116.20048132117756,-0.4758749519514964
0.0030751624758141123,0.001028,197.444651125,116.20048132117756,-0.4758749519514964
0.003096700578757557,0.0010352,198.82753195,116.20048132117756,-0.4758749519514964
0.003125418049348817,0.0010448,200.67137305,116.20048132117756,-0.4758749519514964
0.0031852461130806088,0.0010647999999999999,204.51270867499997,116.20048132117756,-0.4758749519514964
0.0032953297503471066,0.0011015999999999999,211.580766225,116.20048132117756,-0.4758749519514964
0.003331226588586182,0.0011136,213.8855676,116.20048132117756,-0.4758749519514964
0.003359944059177442,0.0011232,215.7294087,116.20048132117756,-0.4758749519514964
0.0033671234268252575,0.0011256,216.190368975,116.20048132117756,-0.4758749519514964
0.0034269514905570487,0.0011455999999999999,220.03170459999998,116.20048132117756,-0.4758749519514964
0.0034317377356555922,0.0011472,220.33901145,116.20048132117756,-0.4758749519514964
0.003474813941542483,0.0011616,223.10477310000002,116.20048132117756,-0.4758749519514964
0.003489172676838113,0.0011664,224.02669365,116.20048132117756,-0.4758749519514964
0.0035872907013582518,0.0011991999999999999,230.32648407499997,116.20048132117756,-0.4758749519514964
0.0037165193190189225,0.0012423999999999998,238.62376902499997,116.20048132117756,-0.4758749519514964
0.003757202402356541,0.001256,240.1000863978319,116.20048132117756,-0.4758749519514964
0.0037763473827507146,0.0012624,240.14539387188032,116.20048132117756,-0.4758749519514964
0.003800278608243431,0.0012703999999999999,240.20190243815009,116.20048132117756,-0.4758749519514964
0.0038385685690317784,0.0012832,240.29202833438924,116.20048132117756,-0.4758749519514964
0.003898396632763571,0.0013032,240.43215128777436,116.20048132117756,-0.4758749519514964
0.003982155921988079,0.0013311999999999998,240.626922539094,116.20048132117756,-0.4758749519514964
0.004044377108269143,0.001352,240.7705770491999,116.20048132117756,-0.4758749519514964
0.004123350152395108,0.0013784,240.95167252807124,116.20048132117756,-0.4758749519514964
0.004152067622986369,0.001388,241.01718939562804,116.20048132117756,-0.4758749519514964
0.004207109441619617,0.0014064,241.142271517838,116.20048132117756,-0.4758749519514964
0.004269330627900681,0.0014272,241.2829027161284,116.20048132117756,-0.4758749519514964
0.004283689363196311,0.001432,241.31524228600404,116.20048132117756,-0.4758749519514964
0.004333944936731017,0.0014487999999999999,241.42809935422727,116.20048132117756,-0.4758749519514964
0.004400952368110624,0.0014712,241.57778469677746,116.20048132117756,-0.4758749519514964
0.00441052485830771,0.0014743999999999998,241.59909553410625,116.20048132117756,-0.4758749519514964
0.004434456083800427,0.0014824,241.6522938610311,116.20048132117756,-0.4758749519514964
0.004448814819096057,0.0014872,241.68415911599504,116.20048132117756,-0.4758749519514964
0.004491891024982948,0.0015015999999999999,241.7795150863189,116.20048132117756,-0.4758749519514964
0.004518215373024936,0.0015103999999999999,241.8376126378583,116.20048132117756,-0.4758749519514964
0.004561291578911827,0.0015248,241.93239741278583,116.20048132117756,-0.4758749519514964
0.00465223023578415,0.0015551999999999999,242.1313597559915,116.20048132117756,-0.4758749519514964
0.004738382647557931,0.001584,242.31845581783435,116.20048132117756,-0.4758749519514964
0.004747955137755018,0.0015872,242.33916204916312,116.20048132117756,-0.4758749519514964
0.004776672608346278,0.0015968,242.40118327658735,116.20048132117756,-0.4758749519514964
0.004812569446585353,0.0016087999999999999,242.47850569296668,116.20048132117756,-0.4758749519514964
0.004819748814233168,0.0016112,242.49394314899888,116.20048132117756,-0.4758749519514964
0.004944191186795295,0.0016527999999999998,242.7601170112726,116.20048132117756,-0.4758749519514964
0.005013591740724174,0.001676,242.90742488027396,116.20048132117756,-0.4758749519514964
0.005042309211315435,0.0016856,242.96814699101415,116.20048132117756,-0.4758749519514964
0.005071026681906695,0.0016952,243.02873437658175,116.20048132117756,-0.4758749519514964
0.0050949579073994115,0.0017032,243.07912171419036,116.20048132117756,-0.4758749519514964
0.0051906828093702785,0.0017352,243.27975484114705,116.20048132117756,-0.4758749519514964
0.005260083363299158,0.0017584,243.42431260969443,116.20048132117756,-0.4758749519514964
0.0052864077113411465,0.0017672,243.47895004334646,116.20048132117756,-0.4758749519514964
0.005372560123114926,0.0017959999999999999,243.65702614242693,116.20048132117756,-0.4758749519514964
0.005458712534888707,0.0018248,243.83399199028085,116.20048132117756,-0.4758749519514964
0.005542471824113216,0.0018528,244.0050007726522,116.20048132117756,-0.4758749519514964
0.005585548030000107,0.0018671999999999998,244.09255549873023,116.20048132117756,-0.4758749519514964
0.005640589848633355,0.0018855999999999999,244.20404870699463,116.20048132117756,-0.4758749519514964
0.005698024789815875,0.0019048,244.31993800408762,116.20048132117756,-0.4758749519514964
0.005709990402562234,0.0019088,244.34402416539004,116.20048132117756,-0.4758749519514964
0.005757852853547667,0.0019248,244.44017261279922,116.20048132117756,-0.4758749519514964
0.0057698184662940254,0.0019287999999999998,244.46416095893278,116.20048132117756,-0.4758749519514964
0.005784177201589656,0.0019336,244.49292137941572,116.20048132117756,-0.4758749519514964
0.005839219020222905,0.001952,244.60291267250446,116.20048132117756,-0.4758749519514964
0.005922978309447414,0.00198,244.76951804913745,116.20048132117756,-0.4758749519514964
0.0059612682702357605,0.0019928,244.84537422122955,116.20048132117756,-0.4758749519514964
0.005999558231024107,0.0020055999999999997,244.92104060848717,116.20048132117756,-0.4758749519514964
0.006035455069263183,0.0020176,244.99180697908142,116.20048132117756,-0.4758749519514964
0.00607374503005153,0.0020304,245.06711042074454,116.20048132117756,-0.4758749519514964
0.006109641868290604,0.0020423999999999998,245.13753942431626,116.20048132117756,-0.4758749519514964
0.006147931829078953,0.0020552,245.21248604989933,116.20048132117756,-0.4758749519514964
0.006157504319276038,0.0020583999999999997,245.23119423503704,116.20048132117756,-0.4758749519514964
0.006181435544768755,0.0020664,245.27791514205887,116.20048132117756,-0.4758749519514964
0.006202973647712201,0.0020736,245.31990367899698,116.20048132117756,-0.4758749519514964
0.00621733238300783,0.0020783999999999998,245.34786445275498,116.20048132117756,-0.4758749519514964
0.0062963054271337965,0.0021048,245.5012008957657,116.20048132117756,-0.4758749519514964
0.006375278471259761,0.0021311999999999998,245.65378907473087,116.20048132117756,-0.4758749519514964
0.006411175309498837,0.0021432,245.72290346843434,116.20048132117756,-0.4758749519514964
0.006492541476174074,0.0021704,245.87900644162136,116.20048132117756,-0.4758749519514964
0.006523652069314607,0.0021808,245.93849100740394,116.20048132117756,-0.4758749519514964
0.006616983848736202,0.002212,246.11628442397202,116.20048132117756,-0.4758749519514964
0.006674418789918722,0.0022312,246.2252097416449,116.20048132117756,-0.4758749519514964
0.0067174949958056125,0.0022456,246.3066639932948,116.20048132117756,-0.4758749519514964
0.006770143691889589,0.0022632,246.4059430739782,116.20048132117756,-0.4758749519514964
0.006839544245818468,0.0022864,246.5363521180433,116.20048132117756,-0.4758749519514964
0.006868261716409728,0.002296,246.59016340723372,116.20048132117756,-0.4758749519514964
0.006906551677198075,0.0023087999999999997,246.66177549442833,116.20048132117756,-0.4758749519514964
0.006932876025240064,0.0023176,246.710919011473,116.20048132117756,-0.4758749519514964
0.007026207804661659,0.0023488,246.88457175238958,116.20048132117756,-0.4758749519514964
0.007045352785055833,0.0023552,246.92008137483057,116.20048132117756,-0.4758749519514964
0.007179367647815046,0.0024,247.16760344569335,116.20048132117756,-0.4758749519514964
0.007191333260561405,0.002404,247.18961562841287,116.20048132117756,-0.4758749519514964
0.0072104782409555795,0.0024104,247.22480543314958,116.20048132117756,-0.4758749519514964
0.007279878794884457,0.0024335999999999997,247.35206414787115,116.20048132117756,-0.4758749519514964
0.007330134368419163,0.0024503999999999997,247.44392183381586,116.20048132117756,-0.4758749519514964
0.0073779968194045975,0.0024664,247.5311772645155,116.20048132117756,-0.4758749519514964
0.007413893657643672,0.0024784,247.5964740395591,116.20048132117756,-0.4758749519514964
0.007459362986079834,0.0024936,247.6790065542773,116.20048132117756,-0.4758749519514964
0.007466542353727649,0.002496,247.69202004706787,116.20048132117756,-0.4758749519514964
0.007569446623346332,0.0025304,247.8780137720775,116.20048132117756,-0.4758749519514964
0.007593377848839048,0.0025383999999999997,247.92112648320776,116.20048132117756,-0.4758749519514964
0.007629274687078124,0.0025504,247.98569632542623,116.20048132117756,-0.4758749519514964
0.007689102750809916,0.0025704,248.09305004757496,116.20048132117756,-0.4758749519514964
0.007715427098851904,0.0025792,248.14018242897538,116.20048132117756,-0.4758749519514964
0.007772862040034424,0.0025984,248.24279957102962,116.20048132117756,-0.4758749519514964
0.007861407574357476,0.0026279999999999997,248.4004235179894,116.20048132117756,-0.4758749519514964
0.007904483780244368,0.0026424,248.47685495939362,116.20048132117756,-0.4758749519514964
0.007933201250835627,0.002652,248.5277190272269,116.20048132117756,-0.4758749519514964
0.007957132476328344,0.00266,248.5700509202784,116.20048132117756,-0.4758749519514964
0.008002601804764507,0.0026752,248.6503449754074,116.20048132117756,-0.4758749519514964
0.00810789919693246,0.0027104,248.83560908908828,116.20048132117756,-0.4758749519514964
0.008287383388127836,0.0027703999999999997,249.1492517075588,116.20048132117756,-0.4758749519514964
0.008385501412647975,0.0028032,249.31958929886792,116.20048132117756,-0.4758749519514964
0.00843575698618268,0.00282,249.40653423950195,116.20048132117756,-0.4758749519514964
0.008469260701872483,0.0028312,249.46438533304033,116.20048132117756,-0.4758749519514964
0.008481226314618843,0.0028352,249.48502479880668,116.20048132117756,-0.4758749519514964
0.008557806236195535,0.0028607999999999997,249.6168494787561,116.20048132117756,-0.4758749519514964
0.008710966079348924,0.0029119999999999997,249.87912669668327,116.20048132117756,-0.4758749519514964
0.008785152878376347,0.0029368,250.0055201575686,116.20048132117756,-0.4758749519514964
0.008809084103869063,0.0029448,250.04620335520113,116.20048132117756,-0.4758749519514964
0.00889284339309357,0.0029728,250.18825634662647,116.20048132117756,-0.4758749519514964
0.008950278334276092,0.002992,250.28536266742657,116.20048132117756,-0.4758749519514964
0.008971816437219537,0.0029992,250.32171484443356,116.20048132117756,-0.4758749519514964
0.008976602682318079,0.0030007999999999996,250.32978848215478,116.20048132117756,-0.4758749519514964
0.008995747662712253,0.0030072,250.36206625852026,116.20048132117756,-0.4758749519514964
0.009055575726444045,0.0030272,250.4627620662382,116.20048132117756,-0.4758749519514964
0.009089079442133849,0.0030383999999999997,250.51903838066045,116.20048132117756,-0.4758749519514964
0.009122583157823654,0.0030496,250.57523385023055,116.20048132117756,-0.4758749519514964
0.009215914937245249,0.0030808,250.7313555365619,116.20048132117756,-0.4758749519514964
0.00925899114313214,0.0030951999999999998,250.80320360937134,116.20048132117756,-0.4758749519514964
0.009282922368624855,0.0031032,250.84306287278932,116.20048132117756,-0.4758749519514964
0.009337964187258106,0.0031216,250.9345874052621,116.20048132117756,-0.4758749519514964
0.009390612883342081,0.0031392,251.0219359359728,116.20048132117756,-0.4758749519514964
0.009471979050017319,0.0031663999999999998,251.15655438773706,116.20048132117756,-0.4758749519514964
0.009505482765707124,0.0031776,251.2118543413646,116.20048132117756,-0.4758749519514964
0.009567703951988185,0.0031983999999999997,251.3143529977443,116.20048132117756,-0.4758749519514964
0.009613173280424348,0.0032136,251.38909153576344,116.20048132117756,-0.4758749519514964
0.009634711383367793,0.0032208,251.42444587004815,116.20048132117756,-0.4758749519514964
0.009651463241212695,0.0032264,251.45192238018808,116.20048132117756,-0.4758749519514964
0.009680180711803954,0.0032359999999999997,251.49898173663917,116.20048132117756,-0.4758749519514964
0.009797443716718267,0.0032752,251.69057840173642,116.20048132117756,-0.4758749519514964
0.009840519922605158,0.0032895999999999997,251.76073597463073,116.20048132117756,-0.4758749519514964
0.00990034798633695,0.0033095999999999998,251.85797867554732,116.20048132117756,-0.4758749519514964
0.009962569172618013,0.0033304,251.95886828228507,116.20048132117756,-0.4758749519514964
0.009996072888307816,0.0033415999999999997,252.01309165641428,116.20048132117756,-0.4758749519514964
0.010020004113800534,0.0033496,252.0517792519547,116.20048132117756,-0.4758749519514964
0.010048721584391794,0.0033591999999999997,252.0981568320301,116.20048132117756,-0.4758749519514964
0.010063080319687424,0.003364,252.12132623620087,116.20048132117756,-0.4758749519514964
0.010118122138320673,0.0033824,252.21002309937302,116.20048132117756,-0.4758749519514964
0.01017077083440465,0.0034,252.2946876614737,116.20048132117756,-0.4758749519514964
0.010175557079503194,0.0034016,252.30237595438334,116.20048132117756,-0.4758749519514964
0.010194702059897367,0.003408,252.33311503288306,116.20048132117756,-0.4758749519514964
0.010232992020685713,0.0034208,252.39452573379174,116.20048132117756,-0.4758749519514964
0.010252137001079888,0.0034272,252.42519747316615,116.20048132117756,-0.4758749519514964
0.010309571942262407,0.0034463999999999996,252.5170789432952,116.20048132117756,-0.4758749519514964
0.010393331231486917,0.0034744,252.65071571542927,116.20048132117756,-0.4758749519514964
0.01045555241776798,0.0034952,252.74971701182815,116.20048132117756,-0.4758749519514964
0.010479483643260696,0.0035031999999999997,252.78773321863073,116.20048132117756,-0.4758749519514964
0.010532132339344673,0.0035207999999999997,252.8712498979545,116.20048132117756,-0.4758749519514964
0.010544097952091032,0.0035248,252.8902082354638,116.20048132117756,-0.4758749519514964
0.010637429731512627,0.0035559999999999997,253.03779639199456,116.20048132117756,-0.4758749519514964
0.010651788466808258,0.0035608,253.06045736004478,116.20048132117756,-0.4758749519514964
0.010733154633483497,0.003588,253.1886451927336,116.20048132117756,-0.4758749519514964
0.010821700167806548,0.0036176,253.32771385431275,116.20048132117756,-0.4758749519514964
0.010848024515848535,0.0036263999999999997,253.36897292083714,116.20048132117756,-0.4758749519514964
0.010915031947228144,0.0036488,253.47382019040947,116.20048132117756,-0.4758749519514964
0.011005970604100466,0.0036791999999999997,253.61571228161185,116.20048132117756,-0.4758749519514964
0.011032294952142455,0.003688,253.6567008763271,116.20048132117756,-0.4758749519514964
0.011037081197240999,0.0036896,253.66414924823968,116.20048132117756,-0.4758749519514964
0.011204599775690017,0.0037456,253.92405409450836,116.20048132117756,-0.4758749519514964
0.011218958510985646,0.0037503999999999997,253.94626089435525,116.20048132117756,-0.4758749519514964
0.01125246222667545,0.0037616,253.99803369921779,116.20048132117756,-0.4758749519514964
0.01127878657471744,0.0037703999999999997,254.03867016825453,116.20048132117756,-0.4758749519514964
0.011300324677660884,0.0037776,254.07189068277884,116.20048132117756,-0.4758749519514964
0.011333828393350688,0.0037887999999999997,254.12351799824822,116.20048132117756,-0.4758749519514964
0.01138169084433612,0.0038047999999999997,254.1971681773925,116.20048132117756,-0.4758749519514964
0.011405622069828838,0.0038128,254.23394796410275,116.20048132117756,-0.4758749519514964
0.011467843256109903,0.0038336,254.3294348324842,116.20048132117756,-0.4758749519514964
0.011482201991405531,0.0038383999999999996,254.3514415445466,116.20048132117756,-0.4758749519514964
0.011525278197292422,0.0038528,254.41739737438866,116.20048132117756,-0.4758749519514964
0.01153724381003878,0.0038567999999999996,254.43570136743364,116.20048132117756,-0.4758749519514964
0.011592285628672028,0.0038751999999999997,254.5198045607142,116.20048132117756,-0.4758749519514964
0.01167843804044581,0.003904,254.6511323580458,116.20048132117756,-0.4758749519514964
0.011707155511037069,0.0039136,254.6948242558013,116.20048132117756,-0.4758749519514964
0.011795701045360122,0.0039432,254.82927855886268,116.20048132117756,-0.4758749519514964
0.011802880413007937,0.0039456,254.84016297748298,116.20048132117756,-0.4758749519514964
0.011833991006148467,0.0039559999999999994,254.88729898576943,116.20048132117756,-0.4758749519514964
0.011867494721838272,0.0039672,254.93800682677505,116.20048132117756,-0.4758749519514964
0.011900998437528077,0.0039784,254.98865886764182,116.20048132117756,-0.4758749519514964
0.011965612746358413,0.004,255.0861881737905,116.20048132117756,-0.4758749519514964
0.014091130673697135,0.004710542108421685,258.1883338118777,116.20048132117756,-0.4758749519514964
0.015240059283069417,0.005094618923784757,259.7887732559285,116.20048132117756,-0.4758749519514964
0.015584737865881102,0.005209841968393679,260.2596341856358,116.20048132117756,-0.4758749519514964
0.016733666475253383,0.005593918783756751,261.8006309664901,116.20048132117756,-0.4758749519514964
0.01839961295884319,0.006150830166033207,263.9636662022167,116.20048132117756,-0.4758749519514964
0.021846398786960035,0.007303060612122424,268.20991554411205,116.20048132117756,-0.4758749519514964
0.0245463810189849,0.008205641128225645,271.35565577223537,116.20048132117756,-0.4758749519514964
0.026384666793980553,0.008820164032806561,273.4204914211743,116.20048132117756,-0.4758749519514964
0.02690168466819808,0.008992998599719944,273.99101494647175,116.20048132117756,-0.4758749519514964
0.027418702542415605,0.009165833166633327,274.5572778841209,116.20048132117756,-0.4758749519514964
0.02759104183382145,0.009223444688937788,274.74510477648084,116.20048132117756,-0.4758749519514964
0.027820827555695905,0.009300260052010402,274.9948304315623,116.20048132117756,-0.4758749519514964
0.02845273829085066,0.009511502300460092,275.67746219262375,116.20048132117756,-0.4758749519514964
0.028854863304130958,0.009645929185837168,276.10878734943094,116.20048132117756,-0.4758749519514964
0.029601666900222944,0.009895579115823165,276.90365067872574,116.20048132117756,-0.4758749519514964
0.030922934801001063,0.010337267453490697,278.2910474189822,116.20048132117756,-0.4758749519514964
0.03212930984084197,0.010740548109621925,279.5377361477645,116.20048132117756,-0.4758749519514964
0.03345057774162009,0.011182236447289457,280.8823909067622,116.20048132117756,-0.4758749519514964
0.03448461349005514,0.011527905581116223,281.920330816515,116.20048132117756,-0.4758749519514964
0.035116524225209896,0.011739147829565914,282.548654073589,116.20048132117756,-0.4758749519514964
0.037471827874423075,0.012526505301060212,284.85271875207684,116.20048132117756,-0.4758749519514964
0.03908032792754427,0.013064212842568514,286.3938497275984,116.20048132117756,-0.4758749519514964
0.04074627441113408,0.013621124224844969,287.964158644054,116.20048132117756,-0.4758749519514964
0.04149307800722606,0.013870774154830966,288.65994050074784,116.20048132117756,-0.4758749519514964
0.04235477446425527,0.014158831766353271,289.4567254701961,116.20048132117756,-0.4758749519514964
0.044078167378313694,0.01473494698939788,291.0315766478109,116.20048132117756,-0.4758749519514964
0.044767524543937065,0.014965393078615724,291.65477028451625,116.20048132117756,-0.4758749519514964
0.047237721054087474,0.01579115823164633,293.8577851390036,116.20048132117756,-0.4758749519514964
0.04798452465017946,0.01604080816163233,294.5149061745549,116.20048132117756,-0.4758749519514964
0.048788774676740046,0.016309661932386477,295.2181301514003,116.20048132117756,-0.4758749519514964
0.051144078325953225,0.017097019403880774,297.2520180566053,116.20048132117756,-0.4758749519514964
0.05246534622673135,0.01753870774154831,298.37697549878953,116.20048132117756,-0.4758749519514964
0.05275257837907442,0.017634726945389076,298.6200631454689,116.20048132117756,-0.4758749519514964
0.053614274836103634,0.017922784556911382,299.3462476216089,116.20048132117756,-0.4758749519514964
0.05539511418063068,0.018518103620724147,300.83276103199887,116.20048132117756,-0.4758749519514964
0.05596957848531681,0.01871014202840568,301.30829013105534,116.20048132117756,-0.4758749519514964
0.0567163820814088,0.01895979195839168,301.9236418768917,116.20048132117756,-0.4758749519514964
0.05798020355171831,0.01938227645529106,302.9578557087432,116.20048132117756,-0.4758749519514964
0.059014239300153364,0.019727945589117824,303.7975065296863,116.20048132117756,-0.4758749519514964
0.05953125717437088,0.019900780156031205,304.21517882614387,116.20048132117756,-0.4758749519514964
0.059818489326713964,0.019996799359871975,304.44660764238176,116.20048132117756,-0.4758749519514964
0.06045040006186871,0.020208041608321663,304.9542309666794,116.20048132117756,-0.4758749519514964
0.0611972036579607,0.020457691538307662,305.5514890429085,116.20048132117756,-0.4758749519514964
0.06246102512827021,0.020880176035207042,306.5557981221414,116.20048132117756,-0.4758749519514964
0.06539079308216952,0.021859571914382876,308.85397090999834,116.20048132117756,-0.4758749519514964
0.06659716812201043,0.022262852570514104,309.78856229958024,116.20048132117756,-0.4758749519514964
0.0689524717712236,0.023050210042008402,311.59442583694704,116.20048132117756,-0.4758749519514964
0.06964182893684696,0.023280656131226245,312.11839907940237,116.20048132117756,-0.4758749519514964
0.06987161465872142,0.02335747149429886,312.2926068097605,116.20048132117756,-0.4758749519514964
0.07130777542043677,0.0238375675135027,313.3763861038891,116.20048132117756,-0.4758749519514964
0.07216947187746599,0.024125625125025005,314.02256813649495,116.20048132117756,-0.4758749519514964
0.07268648975168351,0.024298459691938386,314.40883318398363,116.20048132117756,-0.4758749519514964
0.07492690053995947,0.02504740948189638,316.0704167569065,116.20048132117756,-0.4758749519514964
0.07670773988448651,0.02564272854570914,317.37737980179446,116.20048132117756,-0.4758749519514964
0.07722475775870404,0.025815563112622526,317.7545972010617,116.20048132117756,-0.4758749519514964
0.07825879350713909,0.02616123224644929,318.50609011911064,116.20048132117756,-0.4758749519514964
0.078718364950888,0.02631486297259452,318.8388428974043,116.20048132117756,-0.4758749519514964
0.0799247399907289,0.026718143628725745,319.70873398830105,116.20048132117756,-0.4758749519514964
0.08072899001728949,0.026986997399479896,320.28581819577096,116.20048132117756,-0.4758749519514964
0.08417577584540634,0.028139227845569114,322.7340640764799,116.20048132117756,-0.4758749519514964
0.08434811513681219,0.028196839367873577,322.85543954157635,116.20048132117756,-0.4758749519514964
0.08492257944149832,0.028388877775555113,323.25932772471106,116.20048132117756,-0.4758749519514964
0.08578427589852754,0.028676935387077416,323.8631678538166,116.20048132117756,-0.4758749519514964
0.08699065093836843,0.02908021604320864,324.70458491828384,116.20048132117756,-0.4758749519514964
0.08733532952118012,0.029195439087817562,324.9441523439279,116.20048132117756,-0.4758749519514964
0.0880821331172721,0.02944508901780356,325.46195377873124,116.20048132117756,-0.4758749519514964
0.088541704561021,0.02959871974394879,325.77974991057454,116.20048132117756,-0.4758749519514964
0.0897480796008619,0.030002000400080015,326.6109189542278,116.20048132117756,-0.4758749519514964
0.09106934750164003,0.03044368873774755,327.5162633292511,116.20048132117756,-0.4758749519514964
0.09141402608445172,0.030558911782356472,327.7515958195698,116.20048132117756,-0.4758749519514964
0.09233316897194954,0.03086617323464693,328.3774634232604,116.20048132117756,-0.4758749519514964
0.09307997256804153,0.031115823164632926,328.8841936100318,116.20048132117756,-0.4758749519514964
0.09440124046881965,0.03155751150230046,329.7768490340193,116.20048132117756,-0.4758749519514964
0.09526293692584885,0.03184556911382276,330.3563916610597,116.20048132117756,-0.4758749519514964
0.0958948476610036,0.03205681136227245,330.78009103867697,116.20048132117756,-0.4758749519514964
0.09750334771412482,0.03259451890378076,331.85371424600754,116.20048132117756,-0.4758749519514964
0.0978480262969365,0.03270974194838968,332.0828751553079,116.20048132117756,-0.4758749519514964
0.09830759774068541,0.03286337267453491,332.38793390920983,116.20048132117756,-0.4758749519514964
0.09847993703209124,0.032920984196839365,332.5021874884763,116.20048132117756,-0.4758749519514964
0.09922674062818324,0.03317063412682537,332.9963879856691,116.20048132117756,-0.4758749519514964
0.10095013354224165,0.03374674934986997,334.1313473920598,116.20048132117756,-0.4758749519514964
0.10163949070786502,0.033977195439087816,334.5832122639587,116.20048132117756,-0.4758749519514964
0.10416713364848404,0.034822164432886576,336.22992193805413,116.20048132117756,-0.4758749519514964
0.10485649081410742,0.03505261052210442,336.67631050688544,116.20048132117756,-0.4758749519514964
0.10629265157582275,0.03553270654130826,337.60262738260747,116.20048132117756,-0.4758749519514964
0.10675222301957167,0.03568633726745349,337.89801618768143,116.20048132117756,-0.4758749519514964
0.1073266873242578,0.03587837567513502,338.2665556983474,116.20048132117756,-0.4758749519514964
0.1080160444898812,0.03610882176435287,338.7077891704766,116.20048132117756,-0.4758749519514964
0.10887774094691038,0.03639687937587517,339.2577896824302,116.20048132117756,-0.4758749519514964
0.10927986596019071,0.036531306261252255,339.51387537795057,116.20048132117756,-0.4758749519514964
0.1100266695562827,0.03678095619123825,339.9884901826328,116.20048132117756,-0.4758749519514964
0.11152027674846665,0.03728025605121024,340.9339674024068,116.20048132117756,-0.4758749519514964
0.11330111609299368,0.037875575115023,342.0548369399368,116.20048132117756,-0.4758749519514964
0.11467983042424042,0.03833646729345869,342.9178946348324,116.20048132117756,-0.4758749519514964
0.11496706257658347,0.03843248649729945,343.097187921948,116.20048132117756,-0.4758749519514964
0.11582875903361271,0.03872054410882177,343.6340225184672,116.20048132117756,-0.4758749519514964
0.11801172339142006,0.03945029005801161,344.98707898620177,116.20048132117756,-0.4758749519514964
0.11898831270938648,0.03977675535107021,345.58922982348906,116.20048132117756,-0.4758749519514964
0.11921809843126095,0.03985357071414283,345.73063189491864,116.20048132117756,-0.4758749519514964
0.11979256273594709,0.040045609121824366,346.0836728406093,116.20048132117756,-0.4758749519514964
0.12036702704063322,0.0402376475295059,346.4360541283363,116.20048132117756,-0.4758749519514964
0.12076915205391354,0.04037207441488298,346.6823308765067,116.20048132117756,-0.4758749519514964
0.12174574137187995,0.040698539707941586,347.27910387320446,116.20048132117756,-0.4758749519514964
0.12254999139844056,0.04096739347869574,347.7691634211047,116.20048132117756,-0.4758749519514964
0.12346913428593839,0.0412746549309862,348.3276982481811,116.20048132117756,-0.4758749519514964
0.12438827717343622,0.04158191638327666,348.884613824933,116.20048132117756,-0.4758749519514964
0.12662868796171214,0.042330866173234644,350.2354140413194,116.20048132117756,-0.4758749519514964
0.1276052772796786,0.04265733146629326,350.821303919635,116.20048132117756,-0.4758749519514964
0.1284669737367078,0.04294538907781556,351.33681488623506,116.20048132117756,-0.4758749519514964
0.12961590234608011,0.04332946589317864,352.02206998701536,116.20048132117756,-0.4758749519514964
0.13139674169060714,0.0439247849569914,353.07955228269503,116.20048132117756,-0.4758749519514964
0.13237333100857357,0.044251250250050014,353.65708832776824,116.20048132117756,-0.4758749519514964
0.13277545602185387,0.044385677135427085,353.89441402011784,116.20048132117756,-0.4758749519514964
0.13300524174372835,0.044462492498499706,354.02990284241923,116.20048132117756,-0.4758749519514964
0.13392438463122616,0.044769753950790164,354.57094772286007,116.20048132117756,-0.4758749519514964
0.13518820610153565,0.045192238447689534,355.31252577384714,116.20048132117756,-0.4758749519514964
0.13662436686325102,0.04567233446689338,356.1519540040441,116.20048132117756,-0.4758749519514964
0.1369690454460627,0.045787557511502305,356.3529038614161,116.20048132117756,-0.4758749519514964
0.1389796705124642,0.046459691938387684,357.5212045911628,116.20048132117756,-0.4758749519514964
0.13978392053902478,0.046728545709141825,357.98667694347824,116.20048132117756,-0.4758749519514964
0.14041583127417953,0.04693978795759152,358.3516728983648,116.20048132117756,-0.4758749519514964
0.14231156347964383,0.04757351470294059,359.4428363579956,116.20048132117756,-0.4758749519514964
0.14369027781089055,0.04803440688137628,360.23285237772575,116.20048132117756,-0.4758749519514964
0.1447243135593256,0.04838007601520304,360.82342577242855,116.20048132117756,-0.4758749519514964
0.14598813502963512,0.048802560512102425,361.5430076127118,116.20048132117756,-0.4758749519514964
0.14776897437416214,0.04939787957591518,362.55285385330143,116.20048132117756,-0.4758749519514964
0.14817109938744244,0.04953230646129225,362.78022545797904,116.20048132117756,-0.4758749519514964
0.14943492085775195,0.049954790958191636,363.49326022847333,116.20048132117756,-0.4758749519514964
0.1504115101757184,0.05028125625125025,364.04263202572093,116.20048132117756,-0.4758749519514964
0.151962563798371,0.0507997599519904,364.9123130801699,116.20048132117756,-0.4758749519514964
0.1528817066858688,0.05110702140428086,365.42604611426833,116.20048132117756,-0.4758749519514964
0.1556391353483623,0.052028805761152236,366.9600660421643,116.20048132117756,-0.4758749519514964
0.1557540282092995,0.05206721344268854,367.02375249345016,116.20048132117756,-0.4758749519514964
0.15747742112335794,0.05264332866573315,367.976861426133,116.20048132117756,-0.4758749519514964
0.16029229621632002,0.05358431686337267,369.5249038874115,116.20048132117756,-0.4758749519514964
0.16063697479913172,0.0536995399079816,369.7137287793251,116.20048132117756,-0.4758749519514964
0.16293483201787629,0.05446769353870774,370.9685475165415,116.20048132117756,-0.4758749519514964
0.16339440346162518,0.05462132426485297,371.2186809928727,116.20048132117756,-0.4758749519514964
0.16368163561396826,0.05471734346869374,371.37487509022884,116.20048132117756,-0.4758749519514964
0.16563481424990112,0.05537027405481096,372.4341743024453,116.20048132117756,-0.4758749519514964
0.16655395713739896,0.05567753550710142,372.930981341869,116.20048132117756,-0.4758749519514964
0.16724331430302233,0.05590798159631927,373.30288522760065,116.20048132117756,-0.4758749519514964
0.16902415364754936,0.056503300660132025,374.2608803305767,116.20048132117756,-0.4758749519514964
0.16971351081317276,0.056733746749349875,374.6306593237258,116.20048132117756,-0.4758749519514964
0.17023052868739025,0.05690658131626325,374.90760927296805,116.20048132117756,-0.4758749519514964
0.17051776083973333,0.057002600520104016,375.0613286029948,116.20048132117756,-0.4758749519514964
0.17212626089285454,0.057540308061612325,375.9202979219197,116.20048132117756,-0.4758749519514964
0.17287306448894652,0.05778995799159832,376.3180404299908,116.20048132117756,-0.4758749519514964
0.17413688595925603,0.058212442488497704,376.9896199394912,116.20048132117756,-0.4758749519514964
0.17557304672097135,0.058692538507701536,377.75047538064484,116.20048132117756,-0.4758749519514964
0.17637729674753197,0.05896139227845569,378.17549412591165,116.20048132117756,-0.4758749519514964
0.17666452889987502,0.05905741148229646,378.32710327682537,116.20048132117756,-0.4758749519514964
0.17769856464831008,0.05940308061612322,378.8721020416362,116.20048132117756,-0.4758749519514964
0.1785028146748707,0.05967193438687737,379.29513532746455,116.20048132117756,-0.4758749519514964
0.17959429685377437,0.060036807361472294,379.8680648929482,116.20048132117756,-0.4758749519514964
0.18114535047642694,0.060555311062212444,380.6798974529018,116.20048132117756,-0.4758749519514964
0.18240917194673648,0.06097779555911183,381.33938806489425,116.20048132117756,-0.4758749519514964
0.18350065412564015,0.06134266853370675,381.90751535297795,116.20048132117756,-0.4758749519514964
0.18441979701313796,0.06164992998599721,382.38491685699205,116.20048132117756,-0.4758749519514964
0.1846495827350124,0.061726745349069814,382.5041221304594,116.20048132117756,-0.4758749519514964
0.18648786851000806,0.06234126825365073,383.455690426789,116.20048132117756,-0.4758749519514964
0.18671765423188252,0.06241808361672335,383.57437871049314,116.20048132117756,-0.4758749519514964
0.1870048863842256,0.06251410282056412,383.72265898832393,116.20048132117756,-0.4758749519514964
0.18958997575531322,0.06337827565513103,385.05320818786413,116.20048132117756,-0.4758749519514964
0.18976231504671906,0.0634358871774355,385.1416590750208,116.20048132117756,-0.4758749519514964
0.19062401150374828,0.06372394478895779,385.5834444534739,116.20048132117756,-0.4758749519514964
0.19160060082171473,0.06405041008201641,386.08319409603115,116.20048132117756,-0.4758749519514964
0.1933239937357731,0.06462652530506101,386.9626885824037,116.20048132117756,-0.4758749519514964
0.19550695809358046,0.06535627125425085,388.07233776600503,116.20048132117756,-0.4758749519514964
0.19700056528576443,0.06585557111422284,388.8287887453852,116.20048132117756,-0.4758749519514964
0.1975750295904506,0.06604760952190439,389.11913543919945,116.20048132117756,-0.4758749519514964
0.19849417247794843,0.06635487097419485,389.5830062689494,116.20048132117756,-0.4758749519514964
0.19878140463029148,0.06645089017803561,389.72779400730843,116.20048132117756,-0.4758749519514964
0.19918352964357178,0.06658531706341268,389.93035983973647,116.20048132117756,-0.4758749519514964
0.2005047975443499,0.06702700540108023,390.59481316800554,116.20048132117756,-0.4758749519514964
0.20136649400137913,0.06731506301260252,391.0272325023636,116.20048132117756,-0.4758749519514964
0.20153883329278496,0.06737267453490699,391.113629703932,116.20048132117756,-0.4758749519514964
0.20251542261075142,0.0676991398279656,391.602670692764,116.20048132117756,-0.4758749519514964
0.20395158337246674,0.06817923584716944,392.3201811248655,116.20048132117756,-0.4758749519514964
0.20481327982949593,0.06846729345869174,392.74974161941304,116.20048132117756,-0.4758749519514964
0.20561752985605655,0.06873614722944589,393.1500292700693,116.20048132117756,-0.4758749519514964
0.2066515656044916,0.06908181636327265,393.66378873423486,116.20048132117756,-0.4758749519514964
0.20877708353183036,0.06979235847169435,394.71671200944917,116.20048132117756,-0.4758749519514964
0.21164940505526106,0.07075255051010203,396.1329632262341,116.20048132117756,-0.4758749519514964
0.21262599437322746,0.07107901580316063,396.61277848507774,116.20048132117756,-0.4758749519514964
0.21388981584353697,0.07150150030006001,397.232441977859,116.20048132117756,-0.4758749519514964
0.21498129802244065,0.07186637327465493,397.7664576372793,116.20048132117756,-0.4758749519514964
0.21762383382399692,0.07274974994999,399.0549775465638,116.20048132117756,-0.4758749519514964
0.2192323338771181,0.0732874574914983,399.83630691188586,116.20048132117756,-0.4758749519514964
0.22130040537398823,0.07397879575915184,400.8375959445267,116.20048132117756,-0.4758749519514964
0.22250678041382912,0.07438207641528306,401.41999596792476,116.20048132117756,-0.4758749519514964
0.22664292340756934,0.07576475295059013,403.4075130769769,116.20048132117756,-0.4758749519514964
0.227734405586473,0.07612962592518505,403.9296313825025,116.20048132117756,-0.4758749519514964
0.22807908416928466,0.07624484896979396,404.0943079714766,116.20048132117756,-0.4758749519514964
0.2292854592091256,0.0766481296259252,404.6699132699329,116.20048132117756,-0.4758749519514964
0.2304918342489665,0.07705141028205642,405.24433864962276,116.20048132117756,-0.4758749519514964
0.2306067271099037,0.07708981796359272,405.298984604172,116.20048132117756,-0.4758749519514964
0.2322726735934935,0.07764672934586918,406.09016156268194,116.20048132117756,-0.4758749519514964
0.23244501288489935,0.07770434086817364,406.1718809419746,116.20048132117756,-0.4758749519514964
0.2326173521763052,0.0777619523904781,406.253576695224,116.20048132117756,-0.4758749519514964
0.23359394149427162,0.0780884176835367,406.7160741991379,116.20048132117756,-0.4758749519514964
0.23416840579895778,0.07828045609121825,406.98777930228994,116.20048132117756,-0.4758749519514964
0.2384768880841038,0.07972074414882976,409.0173460083189,116.20048132117756,-0.4758749519514964
0.23985560241535053,0.08018163632726545,409.6637804714146,116.20048132117756,-0.4758749519514964
0.2400279417067564,0.08023924784956991,409.74448276226866,116.20048132117756,-0.4758749519514964
0.24100453102472286,0.08056571314262853,410.20136961043954,116.20048132117756,-0.4758749519514964
0.24215345963409513,0.0809497899579916,410.7379601732208,116.20048132117756,-0.4758749519514964
0.24341728110440464,0.08137227445489098,411.3270642872592,116.20048132117756,-0.4758749519514964
0.24468110257471415,0.08179475895179036,411.9149767376493,116.20048132117756,-0.4758749519514964
0.24680662050205288,0.08250530106021205,412.9010747939254,116.20048132117756,-0.4758749519514964
0.24732363837627042,0.08267813562712543,413.1404350136194,116.20048132117756,-0.4758749519514964
0.24784065625048793,0.08285097019403881,413.3796001680819,116.20048132117756,-0.4758749519514964
0.24864490627704852,0.08311982396479296,413.7512484615521,116.20048132117756,-0.4758749519514964
0.24933426344267187,0.0833502700540108,414.06943115215745,116.20048132117756,-0.4758749519514964
0.2518044599528223,0.08417603520704141,415.2067792125828,116.20048132117756,-0.4758749519514964
0.25289594213172595,0.08454090818163633,415.7079413448852,116.20048132117756,-0.4758749519514964
0.2542746564629727,0.08500180036007202,416.33978413254164,116.20048132117756,-0.4758749519514964
0.2559406029465625,0.08555871174234847,417.1014809851376,116.20048132117756,-0.4758749519514964
0.2580086744434326,0.08625005001000201,418.0443509955343,116.20048132117756,-0.4758749519514964
0.2586405851785874,0.0864612922584517,418.3318616644684,116.20048132117756,-0.4758749519514964
0.25950228163561656,0.086749349869974,418.7234805624991,116.20048132117756,-0.4758749519514964
0.26013419237077134,0.08696059211842369,419.0103455046659,116.20048132117756,-0.4758749519514964
0.2608235495363947,0.08719103820764153,419.32297930424824,116.20048132117756,-0.4758749519514964
0.2629490674637334,0.08790158031606321,420.28491107743764,116.20048132117756,-0.4758749519514964
0.2635235317684196,0.08809361872374476,420.54437147726134,116.20048132117756,-0.4758749519514964
0.264500121086386,0.08842008401680336,420.9849484821179,116.20048132117756,-0.4758749519514964
0.2672001033184109,0.08932266453290659,422.19972500053757,116.20048132117756,-0.4758749519514964
0.27191071061683725,0.09089737947589518,424.30772205172565,116.20048132117756,-0.4758749519514964
0.2734617642394898,0.09141588317663533,424.9986954300782,116.20048132117756,-0.4758749519514964
0.27518515715354824,0.09199199839967995,425.76465347223854,116.20048132117756,-0.4758749519514964
0.2758745143191716,0.09222244448889778,426.0705125888393,116.20048132117756,-0.4758749519514964
0.2777702465246359,0.09285617123424686,426.91009208084665,116.20048132117756,-0.4758749519514964
0.2786319429816651,0.09314422884576916,427.2909800867538,116.20048132117756,-0.4758749519514964
0.2795510858691629,0.09345149029805962,427.69675462464545,116.20048132117756,-0.4758749519514964
0.2810446930613469,0.09395079015803161,428.3550302632705,116.20048132117756,-0.4758749519514964
0.283112764558217,0.09464212842568515,429.2642408536187,116.20048132117756,-0.4758749519514964
0.2840319074457148,0.0949493898779756,429.66750263974575,116.20048132117756,-0.4758749519514964
0.28615742537305355,0.09565993198639729,430.5981012778201,116.20048132117756,-0.4758749519514964
0.2870765682605514,0.09596719343868775,430.99968695579076,116.20048132117756,-0.4758749519514964
0.28736380041289444,0.09606321264252851,431.1250796028336,116.20048132117756,-0.4758749519514964
0.28816805043945504,0.09633206641328267,431.4759192360789,116.20048132117756,-0.4758749519514964
0.2895467647707018,0.09679295859171835,432.07647146882726,116.20048132117756,-0.4758749519514964
0.2901212290753879,0.09698499699939989,432.3263722943543,116.20048132117756,-0.4758749519514964
0.29144249697616603,0.09742668533706741,432.9004129809044,116.20048132117756,-0.4758749519514964
0.29201696128085214,0.09761872374474895,433.14967921864854,116.20048132117756,-0.4758749519514964
0.2925339791550697,0.09779155831166234,433.3738553684991,116.20048132117756,-0.4758749519514964
0.2933956756120989,0.09807961592318463,433.7471392134473,116.20048132117756,-0.4758749519514964
0.2946594970824084,0.09850210042008402,434.29384969551126,116.20048132117756,-0.4758749519514964
0.2963254435659982,0.09905901180236047,435.013118286187,116.20048132117756,-0.4758749519514964
0.29862330078474275,0.09982716543308662,436.00263045389613,116.20048132117756,-0.4758749519514964