File: datasets/aisi_316_L/data/M1/train_27.csv
Time(s),Strain(%),Stress(MPa),Temp(C),Log_SR(s-1)
0.0,0.0,0.0,341.5514301730541,-2.687561734136941
0.009740735031921865,1.9999999999999998e-05,3.4837278124999997,341.5514301730541,-2.687561734136941
0.01519554664979811,3.12e-05,5.4346153875,341.5514301730541,-2.687561734136941
0.026105169885550596,5.3599999999999995e-05,9.3363905375,341.5514301730541,-2.687561734136941
0.02961183449704247,6.08e-05,10.59053255,341.5514301730541,-2.687561734136941
0.03545627551619559,7.28e-05,12.6807692375,341.5514301730541,-2.687561734136941
0.0444177517455637,9.12e-05,15.885798824999998,341.5514301730541,-2.687561734136941
0.04948293396216307,0.00010159999999999999,17.697337287499998,341.5514301730541,-2.687561734136941
0.08338069187325116,0.0001712,29.820710074999997,341.5514301730541,-2.687561734136941
0.08571846828091241,0.000176,30.65680475,341.5514301730541,-2.687561734136941
0.10636882654858677,0.0002184,38.0423077125,341.5514301730541,-2.687561734136941
0.10792734415369426,0.0002216,38.5997041625,341.5514301730541,-2.687561734136941
0.11104437936390926,0.00022799999999999999,39.714497062499994,341.5514301730541,-2.687561734136941
0.12779844361881487,0.0002624,45.706508899999996,341.5514301730541,-2.687561734136941
0.13403251403924485,0.00027519999999999997,47.93609469999999,341.5514301730541,-2.687561734136941
0.14727991368265858,0.0003024,52.673964524999995,341.5514301730541,-2.687561734136941
0.15546213110947296,0.0003192,55.6002958875,341.5514301730541,-2.687561734136941
0.1628650897337336,0.0003344,58.247929025,341.5514301730541,-2.687561734136941
0.16909916015416357,0.0003472,60.477514825,341.5514301730541,-2.687561734136941
0.17143693656182482,0.000352,61.3136095,341.5514301730541,-2.687561734136941
0.1807880421924698,0.00037119999999999997,64.65798819999999,341.5514301730541,-2.687561734136941
0.18741174201417668,0.0003848,67.0269231125,341.5514301730541,-2.687561734136941
0.20611395327546667,0.0004232,73.7156805125,341.5514301730541,-2.687561734136941
0.21234802369589664,0.00043599999999999997,75.9452663125,341.5514301730541,-2.687561734136941
0.21390654130100417,0.0004392,76.5026627625,341.5514301730541,-2.687561734136941
0.22053024112271102,0.0004528,78.871597675,341.5514301730541,-2.687561734136941
0.22715394094441788,0.00046639999999999995,81.2405325875,341.5514301730541,-2.687561734136941
0.23105023495718663,0.0004744,82.6340237125,341.5514301730541,-2.687561734136941
0.2376739347788935,0.000488,85.002958625,341.5514301730541,-2.687561734136941
0.24429763460060036,0.0005015999999999999,87.37189353749999,341.5514301730541,-2.687561734136941
0.24975244621847661,0.0005128,89.3227811125,341.5514301730541,-2.687561734136941
0.25364874023124534,0.0005208,90.7162722375,341.5514301730541,-2.687561734136941
0.27001317508487405,0.0005543999999999999,96.56893496249998,341.5514301730541,-2.687561734136941
0.27468872790019655,0.0005639999999999999,98.24112431249999,341.5514301730541,-2.687561734136941
0.27819539251168846,0.0005712,99.495266325,341.5514301730541,-2.687561734136941
0.28131242772190346,0.0005775999999999999,100.61005922499999,341.5514301730541,-2.687561734136941
0.2875464981423334,0.0005903999999999999,102.83964502499998,341.5514301730541,-2.687561734136941
0.29494945676659406,0.0006056,105.48727816249999,341.5514301730541,-2.687561734136941
0.29962500958191657,0.0006152,107.1594675125,341.5514301730541,-2.687561734136941
0.3058590800023466,0.000628,109.3890533125,341.5514301730541,-2.687561734136941
0.31715833263937593,0.0006512,113.430177575,341.5514301730541,-2.687561734136941
0.32300277365852903,0.0006632,115.5204142625,341.5514301730541,-2.687561734136941
0.33352276749300463,0.0006848,119.28284029999999,341.5514301730541,-2.687561734136941
0.33819832030832714,0.0006944,120.95502965,341.5514301730541,-2.687561734136941
0.33936720851215774,0.0006967999999999999,121.37307698749999,341.5514301730541,-2.687561734136941
0.35027683174791024,0.0007191999999999999,125.27485213749999,341.5514301730541,-2.687561734136941
0.35339386695812525,0.0007256,126.38964503749999,341.5514301730541,-2.687561734136941
0.3600175667798321,0.0007392,128.75857994999998,341.5514301730541,-2.687561734136941
0.37014793121303086,0.0007599999999999999,132.38165687499998,341.5514301730541,-2.687561734136941
0.3740442252257996,0.000768,133.775148,341.5514301730541,-2.687561734136941
0.3880708836717671,0.0007968,138.79171605,341.5514301730541,-2.687561734136941
0.39586347169730457,0.0008127999999999999,141.57869829999999,341.5514301730541,-2.687561734136941
0.4036560597228421,0.0008288,144.36568055,341.5514301730541,-2.687561734136941
0.40755235373561083,0.0008368,145.759171675,341.5514301730541,-2.687561734136941
0.4161242005637021,0.0008544,148.82485215,341.5514301730541,-2.687561734136941
0.4297612296083927,0.0008824,153.7020710875,341.5514301730541,-2.687561734136941
0.4356056706275458,0.0008944,155.79230777499998,341.5514301730541,-2.687561734136941
0.43638492943009954,0.000896,156.071006,341.5514301730541,-2.687561734136941
0.4406708528441452,0.0009048,157.6038462375,341.5514301730541,-2.687561734136941
0.45352862308628206,0.0009312,159.49604843501137,341.5514301730541,-2.687561734136941
0.4570352876977739,0.0009383999999999999,159.53446888637905,341.5514301730541,-2.687561734136941
0.4617108405130964,0.000948,159.5855177935213,341.5514301730541,-2.687561734136941
0.47145157554501826,0.000968,159.69122665649866,341.5514301730541,-2.687561734136941
0.47262046374884886,0.0009704,159.7038542255633,341.5514301730541,-2.687561734136941
0.4882056397999238,0.0010023999999999999,159.8710746368348,341.5514301730541,-2.687561734136941
0.503401186449722,0.0010336,160.03212134587758,341.5514301730541,-2.687561734136941
0.5166485860931357,0.0010608,160.1709802214527,341.5514301730541,-2.687561734136941
0.5213241389084582,0.0010704,160.21965679115536,341.5514301730541,-2.687561734136941
0.5357404267557025,0.0010999999999999998,160.36868204571238,341.5514301730541,-2.687561734136941
0.5497670852016701,0.0011288,160.51218561008628,341.5514301730541,-2.687561734136941
0.5591181908323151,0.001148,160.60706211812794,341.5514301730541,-2.687561734136941
0.5641833730489144,0.0011584,160.6581950869266,341.5514301730541,-2.687561734136941
0.5704174434693443,0.0011711999999999998,160.7208828541776,341.5514301730541,-2.687561734136941
0.5731448492782826,0.0011768,160.74822467111184,341.5514301730541,-2.687561734136941
0.5953537251510644,0.0012224,160.96900708613927,341.5514301730541,-2.687561734136941
0.6093803835970318,0.0012511999999999998,161.10679486203728,341.5514301730541,-2.687561734136941
0.6132766776098006,0.0012592,161.1448490116508,341.5514301730541,-2.687561734136941
0.6218485244378918,0.0012768,161.22823781231014,341.5514301730541,-2.687561734136941
0.6280825948583219,0.0012896,161.28860289885813,341.5514301730541,-2.687561734136941
0.6319788888710905,0.0012975999999999999,161.3262124402974,341.5514301730541,-2.687561734136941
0.6331477770749212,0.0013,161.337477654779,341.5514301730541,-2.687561734136941
0.6405507356991818,0.0013151999999999999,161.4086365794602,341.5514301730541,-2.687561734136941
0.6456159179157812,0.0013256,161.4571395654087,341.5514301730541,-2.687561734136941
0.6573047999540874,0.0013495999999999998,161.5685066465437,341.5514301730541,-2.687561734136941
0.6658766467821786,0.0013671999999999998,161.64968555378036,341.5514301730541,-2.687561734136941
0.6744484936102698,0.0013847999999999998,161.73045791192297,341.5514301730541,-2.687561734136941
0.6884751520562373,0.0014135999999999999,161.86177256846074,341.5514301730541,-2.687561734136941
0.6970469988843286,0.0014311999999999999,161.94150690198987,341.5514301730541,-2.687561734136941
0.7099047691264655,0.0014575999999999999,162.0603951058044,341.5514301730541,-2.687561734136941
0.7138010631392342,0.0014655999999999998,162.0962556463183,341.5514301730541,-2.687561734136941
0.720814392362218,0.00148,162.160612830799,341.5514301730541,-2.687561734136941
0.7414647506298924,0.0015224,162.3487056970953,341.5514301730541,-2.687561734136941
0.7492573386554299,0.0015383999999999999,162.41915177203197,341.5514301730541,-2.687561734136941
0.7554914090758599,0.0015512,162.47530311402903,341.5514301730541,-2.687561734136941
0.7644528853052279,0.0015696,162.55570511340002,341.5514301730541,-2.687561734136941
0.7687388087192736,0.0015784,162.59402822938992,341.5514301730541,-2.687561734136941
0.7741936203371498,0.0015895999999999998,162.64268280320428,341.5514301730541,-2.687561734136941
0.7780899143499186,0.0015976,162.67735425105056,341.5514301730541,-2.687561734136941
0.792116572795886,0.0016263999999999999,162.80161470423656,341.5514301730541,-2.687561734136941
0.7995195314201468,0.0016416,162.86685047759312,341.5514301730541,-2.687561734136941
0.8026365666303616,0.001648,162.89424764688528,341.5514301730541,-2.687561734136941
0.8123773016622836,0.001668,162.97959757047016,341.5514301730541,-2.687561734136941
0.820559519089098,0.0016848,163.05098350697236,341.5514301730541,-2.687561734136941
0.8275728483120817,0.0016991999999999999,163.1119507759799,341.5514301730541,-2.687561734136941
0.829520995318466,0.0017032,163.1288503255148,341.5514301730541,-2.687561734136941
0.8334172893312348,0.0017112,163.16260306010128,341.5514301730541,-2.687561734136941
0.8392617303503879,0.0017231999999999998,163.2131170020417,341.5514301730541,-2.687561734136941
0.8435476537644334,0.0017319999999999998,163.25007341056582,341.5514301730541,-2.687561734136941
0.8486128359810329,0.0017423999999999999,163.293654887058,341.5514301730541,-2.687561734136941
0.854457277000186,0.0017544,163.34381534303841,341.5514301730541,-2.687561734136941
0.8727698588601991,0.001792,163.50012522056497,341.5514301730541,-2.687561734136941
0.8774454116755216,0.0018016,163.5398284920736,341.5514301730541,-2.687561734136941
0.8817313350895672,0.0018104,163.5761507353513,341.5514301730541,-2.687561734136941
0.8871861467074434,0.0018215999999999998,163.6222796137774,341.5514301730541,-2.687561734136941
0.8922513289240428,0.0018319999999999999,163.66501462721533,341.5514301730541,-2.687561734136941
0.9082261343763948,0.0018648,163.79917868566395,341.5514301730541,-2.687561734136941
0.9148498341981015,0.0018784,163.85453740324542,341.5514301730541,-2.687561734136941
0.9179668694083165,0.0018847999999999998,163.88053445612312,341.5514301730541,-2.687561734136941
0.9234216810261928,0.001896,163.92594660985793,341.5514301730541,-2.687561734136941
0.938227598274714,0.0019264,164.0486838492847,341.5514301730541,-2.687561734136941
0.9436824098925902,0.0019375999999999998,164.09371211844902,341.5514301730541,-2.687561734136941
0.9487475921091896,0.0019479999999999999,164.13543327530846,341.5514301730541,-2.687561734136941
0.9604364741474958,0.001972,164.2313827327936,341.5514301730541,-2.687561734136941
0.9803075736126164,0.0020128,164.39345813487935,341.5514301730541,-2.687561734136941
0.9834246088228316,0.0020192,164.41876500555762,341.5514301730541,-2.687561734136941
0.9873209028356001,0.0020272,164.4503546458568,341.5514301730541,-2.687561734136941
0.9919964556509228,0.0020368,164.4881981101769,341.5514301730541,-2.687561734136941
0.9935549732560301,0.0020399999999999997,164.50079713150456,341.5514301730541,-2.687561734136941
0.9997890436764603,0.0020528,164.55111633136133,341.5514301730541,-2.687561734136941
1.0056334846956134,0.0020648,164.59817956199907,341.5514301730541,-2.687561734136941
1.0181016255364734,0.0020904,164.69822608001667,341.5514301730541,-2.687561734136941
1.0219979195492421,0.0020984,164.72939247379097,341.5514301730541,-2.687561734136941
1.0251149547594571,0.0021048,164.75429223719127,341.5514301730541,-2.687561734136941
1.037583095600317,0.0021303999999999997,164.85359742697233,341.5514301730541,-2.687561734136941
1.041089760211809,0.0021376,164.88144301958255,341.5514301730541,-2.687561734136941
1.0687534477024672,0.0021944,165.09984570010093,341.5514301730541,-2.687561734136941
1.0816112179446038,0.0022207999999999998,165.20060521274607,341.5514301730541,-2.687561734136941
1.0855075119573727,0.0022288,165.23104603028904,341.5514301730541,-2.687561734136941
1.090572694173972,0.0022392,165.27055546307741,341.5514301730541,-2.687561734136941
1.0956378763905714,0.0022496,165.309993394482,341.5514301730541,-2.687561734136941
1.1081060172314312,0.0022752,165.406769655097,341.5514301730541,-2.687561734136941
1.113171199448031,0.0022856,165.4459635947397,341.5514301730541,-2.687561734136941
1.1174571228620762,0.0022944,165.47907340238376,341.5514301730541,-2.687561734136941
1.1256393402888907,0.0023112,165.54214583137585,341.5514301730541,-2.687561734136941
1.1275874872952751,0.0023152,165.55713669170441,341.5514301730541,-2.687561734136941
1.1326526695118744,0.0023255999999999997,165.59606573232622,341.5514301730541,-2.687561734136941
1.1357697047220894,0.002332,165.61998832093047,341.5514301730541,-2.687561734136941
1.1439519221489038,0.0023488,165.6826636078934,341.5514301730541,-2.687561734136941
1.1544719159833794,0.0023704,165.7629898187299,341.5514301730541,-2.687561734136941
1.158368209996148,0.0023783999999999997,165.7926677594157,341.5514301730541,-2.687561734136941
1.1759015330536073,0.0024143999999999997,165.9257396301066,341.5514301730541,-2.687561734136941
1.1790185682638226,0.0024208,165.94931561188443,341.5514301730541,-2.687561734136941
1.1864215268880831,0.002436,166.00521135876747,341.5514301730541,-2.687561734136941
1.1872007856906368,0.0024376,166.01108719807397,341.5514301730541,-2.687561734136941
1.1957726325187281,0.0024552,166.07562246961626,341.5514301730541,-2.687561734136941
1.2125266967736337,0.0024896,166.20124100159546,341.5514301730541,-2.687561734136941
1.2207089142004481,0.0025063999999999998,166.26234341369232,341.5514301730541,-2.687561734136941
1.2246052082132168,0.0025144,166.29138364185155,341.5514301730541,-2.687561734136941
1.2300600198310931,0.0025256,166.3319794960735,341.5514301730541,-2.687561734136941
1.2553859309140898,0.0025775999999999998,166.51954811695225,341.5514301730541,-2.687561734136941
1.263957777742181,0.0025951999999999998,166.5826978444882,341.5514301730541,-2.687561734136941
1.2659059247485656,0.0025992,166.5970267358386,341.5514301730541,-2.687561734136941
1.2717503657677185,0.0026111999999999997,166.6399618988225,341.5514301730541,-2.687561734136941
1.2896733182264548,0.0026479999999999997,166.7711524144904,341.5514301730541,-2.687561734136941
1.2943488710417774,0.0026576,166.80525884595502,341.5514301730541,-2.687561734136941
1.298634794455823,0.0026663999999999998,166.83648088900256,341.5514301730541,-2.687561734136941
1.3033103472711456,0.002676,166.87049550247224,341.5514301730541,-2.687561734136941
1.3087651588890217,0.0026872,166.91011912828785,341.5514301730541,-2.687561734136941
1.311882194099237,0.0026936,166.93273228201232,341.5514301730541,-2.687561734136941
1.3348703287745722,0.0027408,167.0988619553774,341.5514301730541,-2.687561734136941
1.3375977345835106,0.0027464,167.1184979379016,341.5514301730541,-2.687561734136941
1.342273287398833,0.0027559999999999998,167.15212333236127,341.5514301730541,-2.687561734136941
1.3481177284179862,0.002768,167.1940909075356,341.5514301730541,-2.687561734136941
1.3531829106345854,0.0027784,167.23040544285755,341.5514301730541,-2.687561734136941
1.3800673393226899,0.0028336,167.42227159366058,341.5514301730541,-2.687561734136941
1.3812362275265204,0.002836,167.43058037217313,341.5514301730541,-2.687561734136941
1.3839636333354584,0.0028415999999999997,167.44995686506203,341.5514301730541,-2.687561734136941
1.389028815552058,0.002852,167.48590231595557,341.5514301730541,-2.687561734136941
1.397990291781426,0.0028704,167.54937313507017,341.5514301730541,-2.687561734136941
1.413575467832501,0.0029024,167.65938051512683,341.5514301730541,-2.687561734136941
1.4272124968771915,0.0029303999999999997,167.75524952662704,341.5514301730541,-2.687561734136941
1.4299399026861297,0.002936,167.7743803863725,341.5514301730541,-2.687561734136941
1.4490317433486966,0.0029752,167.9079001838127,341.5514301730541,-2.687561734136941
1.4556554431704034,0.0029888,167.95406284232408,341.5514301730541,-2.687561734136941
1.4591621077818955,0.002996,167.97846872785618,341.5514301730541,-2.687561734136941
1.4611102547882797,0.003,167.9920176688822,341.5514301730541,-2.687561734136941
1.4642272899984947,0.0030064,168.0136813292171,341.5514301730541,-2.687561734136941
1.4755265426355242,0.0030296,168.09206177723019,341.5514301730541,-2.687561734136941
1.4891635716802147,0.0030575999999999997,168.18634781508206,341.5514301730541,-2.687561734136941
1.497345789107029,0.0030743999999999997,168.24275781723773,341.5514301730541,-2.687561734136941
1.5024109713236284,0.0030848,168.27761805530534,341.5514301730541,-2.687561734136941
1.5070865241389508,0.0030943999999999998,168.30975607603222,341.5514301730541,-2.687561734136941
1.513320594559381,0.0031072,168.35254634841223,341.5514301730541,-2.687561734136941
1.5207235531836416,0.0031224,168.40327061023424,341.5514301730541,-2.687561734136941
1.5281265118079022,0.0031376,168.45389866094234,341.5514301730541,-2.687561734136941
1.5339709528270553,0.0031496,168.49380063928044,341.5514301730541,-2.687561734136941
1.5374776174385472,0.0031568,168.5177133678563,341.5514301730541,-2.687561734136941
1.5581279757062214,0.0031991999999999997,168.65810371997156,341.5514301730541,-2.687561734136941
1.5608553815151596,0.0032048,168.67659144265227,341.5514301730541,-2.687561734136941
1.5725442635534659,0.0032288,168.75568226353266,341.5514301730541,-2.687561734136941
1.5756612987636809,0.0032351999999999997,168.77673438484183,341.5514301730541,-2.687561734136941
1.5865709219994333,0.0032576,168.8502892447313,341.5514301730541,-2.687561734136941
1.6107279448785996,0.0033071999999999997,169.0124623784102,341.5514301730541,-2.687561734136941
1.6302094149424433,0.0033472,169.14255729111963,341.5514301730541,-2.687561734136941
1.6418982969807496,0.0033712,169.22032323277642,341.5514301730541,-2.687561734136941
1.6457945909935183,0.0033791999999999997,169.2461971932907,341.5514301730541,-2.687561734136941
1.6535871790190557,0.0033951999999999997,169.29787355773936,341.5514301730541,-2.687561734136941
1.6641071728535313,0.0034168,169.36748624728588,341.5514301730541,-2.687561734136941
1.669172355070131,0.0034272,169.4009422389022,341.5514301730541,-2.687561734136941
1.6754064254905607,0.00344,169.44206453933378,341.5514301730541,-2.687561734136941
1.6769649430956683,0.0034432,169.45233578489464,341.5514301730541,-2.687561734136941
1.681250866509714,0.0034519999999999998,169.48056253216134,341.5514301730541,-2.687561734136941
1.693719007350574,0.0034776,169.56251757714872,341.5514301730541,-2.687561734136941
1.69917381896845,0.0034888,169.59829888597008,341.5514301730541,-2.687561734136941
1.7128108480131408,0.0035168,169.6875567220703,341.5514301730541,-2.687561734136941
1.7194345478348476,0.0035304,169.73081049129252,341.5514301730541,-2.687561734136941
1.7252789888540008,0.0035424,169.76892164524736,341.5514301730541,-2.687561734136941
1.73657824149103,0.0035656,169.84246074118744,341.5514301730541,-2.687561734136941
1.7404745355037987,0.0035735999999999997,169.8677757503776,341.5514301730541,-2.687561734136941
1.7548908233510432,0.0036032,169.9612497286146,341.5514301730541,-2.687561734136941
1.7622937819753037,0.0036184,170.00913347273521,341.5514301730541,-2.687561734136941
1.7700863700008413,0.0036344,170.05945274215705,341.5514301730541,-2.687561734136941
1.7778789580263787,0.0036504,170.10968569085074,341.5514301730541,-2.687561734136941
1.7821648814404245,0.0036592,170.1372772090274,341.5514301730541,-2.687561734136941
1.7891782106634082,0.0036736,170.18237121135684,341.5514301730541,-2.687561734136941
1.7969707986889456,0.0036896,170.23239488383211,341.5514301730541,-2.687561734136941
1.8121663453387438,0.0037208,170.32969837501994,341.5514301730541,-2.687561734136941
1.8226863391732193,0.0037424,170.396876004655,341.5514301730541,-2.687561734136941
1.824244856778327,0.0037456,170.40681537073715,341.5514301730541,-2.687561734136941
1.8320374448038643,0.0037616,170.45646261225536,341.5514301730541,-2.687561734136941
1.839050774026848,0.003776,170.501074757605,341.5514301730541,-2.687561734136941
1.8480122502562162,0.0037944,170.55798272700628,341.5514301730541,-2.687561734136941
1.8503500266638775,0.0037992,170.57281057142976,341.5514301730541,-2.687561734136941
1.857752985288138,0.0038144,170.61971728429393,341.5514301730541,-2.687561734136941
1.867883349721337,0.0038352,170.68378745762047,341.5514301730541,-2.687561734136941
1.8745070495430436,0.0038488,170.72560623575953,341.5514301730541,-2.687561734136941
1.8760655671481512,0.003852,170.73543756822562,341.5514301730541,-2.687561734136941
1.879572231759643,0.0038591999999999997,170.75754642776093,341.5514301730541,-2.687561734136941
1.8912611137979494,0.0038832,170.83112672026803,341.5514301730541,-2.687561734136941
1.8955470372119947,0.0038919999999999996,170.85806169593468,341.5514301730541,-2.687561734136941
1.9025603664349786,0.0039064,170.90208593468304,341.5514301730541,-2.687561734136941
1.9130803602694544,0.003928,170.96800380798115,341.5514301730541,-2.687561734136941
1.925938130511591,0.003954399999999999,171.048378429505,341.5514301730541,-2.687561734136941
1.932172200932021,0.0039672,171.08727259113783,341.5514301730541,-2.687561734136941
1.934899606740959,0.003972799999999999,171.10427339385342,341.5514301730541,-2.687561734136941
2.0697356973209455,0.004249649929985997,171.93345529514218,341.5514301730541,-2.687561734136941
2.163265459579847,0.004441688337667534,172.4962821852807,341.5514301730541,-2.687561734136941
2.219383316935188,0.004556911382276456,172.8294238360269,341.5514301730541,-2.687561734136941
2.3409720078717604,0.004806561312262453,173.54016311333987,341.5514301730541,-2.687561734136941
2.4719136750342225,0.005075415083016604,174.28965592874533,341.5514301730541,-2.687561734136941
2.668326175777916,0.00547869573914783,175.38548204202735,341.5514301730541,-2.687561734136941
2.8086208191662685,0.005766753350670134,176.14902861367275,341.5514301730541,-2.687561734136941
2.89279760519928,0.005939587917583517,176.60001795329947,341.5514301730541,-2.687561734136941
3.0143862961358523,0.006189237847569514,177.2425135223956,341.5514301730541,-2.687561734136941
3.201445820653656,0.006573314662932587,178.21157063982668,341.5514301730541,-2.687561734136941
3.323034511590228,0.006822964592918584,178.82963346061018,341.5514301730541,-2.687561734136941
3.556858917237482,0.007303060612122424,179.99396599786314,341.5514301730541,-2.687561734136941
3.6410357032704934,0.007475895179035807,180.40576594544535,341.5514301730541,-2.687561734136941
3.678447608174054,0.007552710542108421,180.58759454776515,341.5514301730541,-2.687561734136941
3.7158595130776146,0.007629525905181036,180.7687033366477,341.5514301730541,-2.687561734136941
3.968389871176649,0.008148029605921184,181.97310165948556,341.5514301730541,-2.687561734136941
4.099331538339112,0.008416883376675335,182.58581039811895,341.5514301730541,-2.687561734136941
4.211567253049794,0.008647329465893179,183.10493813628753,341.5514301730541,-2.687561734136941
4.2396261817274645,0.00870494098819764,183.2338735447698,341.5514301730541,-2.687561734136941
4.969158327346898,0.010202840568113623,186.47765114983528,341.5514301730541,-2.687561734136941
5.474219043544967,0.01123984796959392,188.61505300282448,341.5514301730541,-2.687561734136941
5.5396898771261975,0.011374274854970993,188.88637861948047,341.5514301730541,-2.687561734136941
5.64257261561099,0.011585517103420685,189.3102342729346,341.5514301730541,-2.687561734136941
5.876397021258244,0.012065613122624524,190.262489602516,341.5514301730541,-2.687561734136941
6.100868450679608,0.012526505301060212,191.16284522682986,341.5514301730541,-2.687561734136941
6.353398808778643,0.01304500900180036,192.16044044361848,341.5514301730541,-2.687561734136941
6.708811905362469,0.013774754950990198,193.53864822222582,341.5514301730541,-2.687561734136941
7.054872025720405,0.014485297059411883,194.8534750453496,341.5514301730541,-2.687561734136941
7.195166669108758,0.014773354670934187,195.37931714715776,341.5514301730541,-2.687561734136941
7.29804940759355,0.014984596919383877,195.76239668340347,341.5514301730541,-2.687561734136941
7.344814288723001,0.015080616123224646,195.93582691599389,341.5514301730541,-2.687561734136941
7.578638694370255,0.015560712142428487,196.79660094786647,341.5514301730541,-2.687561734136941
7.84052202869518,0.01609841968393679,197.74846344100257,341.5514301730541,-2.687561734136941
7.87793393359874,0.016175235047009403,197.88342463414955,341.5514301730541,-2.687561734136941
8.083699410568324,0.016597719543908783,198.62129079359562,341.5514301730541,-2.687561734136941
8.121111315471884,0.016674534906981398,198.7546575548461,341.5514301730541,-2.687561734136941
8.233347030182568,0.01690498099619924,199.15332753948232,341.5514301730541,-2.687561734136941
8.897408342220768,0.018268453690738148,201.4701515884383,341.5514301730541,-2.687561734136941
9.018997033157342,0.018518103620724147,201.88694981834573,341.5514301730541,-2.687561734136941
9.140585724093913,0.018767753550710142,202.3015623012715,341.5514301730541,-2.687561734136941
9.262174415030485,0.019017403480696138,202.71402934914005,341.5514301730541,-2.687561734136941
9.393116082192948,0.019286257251450292,203.15587006334044,341.5514301730541,-2.687561734136941
9.51470477312952,0.019535907181436288,203.56400460113144,341.5514301730541,-2.687561734136941
9.673705368969651,0.019862372474494898,204.09466289720092,341.5514301730541,-2.687561734136941
9.776588107454444,0.02007361472294459,204.43621827748032,341.5514301730541,-2.687561734136941
10.300354776104294,0.021149029805961193,206.1537755619871,341.5514301730541,-2.687561734136941
10.440649419492646,0.021437087417483496,206.60800783781286,341.5514301730541,-2.687561734136941
10.721238706269352,0.022013202640528105,207.50939315954133,341.5514301730541,-2.687561734136941
10.861533349657705,0.02230126025205041,207.95663214062998,341.5514301730541,-2.687561734136941
10.983122040594276,0.022550910182036407,208.3424199414281,341.5514301730541,-2.687561734136941
11.2450053749192,0.02308861772354471,209.16773525911185,341.5514301730541,-2.687561734136941
11.469476804340564,0.023549509901980396,209.86919946631397,341.5514301730541,-2.687561734136941
11.506888709244125,0.02362632526505301,209.98558765937196,341.5514301730541,-2.687561734136941
11.609771447728917,0.0238375675135027,210.3048967093078,341.5514301730541,-2.687561734136941
11.843595853376172,0.024317663532706542,211.0265231352363,341.5514301730541,-2.687561734136941
12.161597045056437,0.024970594118823766,211.99908071954795,341.5514301730541,-2.687561734136941
12.423480379381363,0.025508301660332067,212.79258471376505,341.5514301730541,-2.687561734136941
12.84436430954642,0.02637247449489898,214.05432611535352,341.5514301730541,-2.687561734136941
13.237189311033807,0.027179035807161432,215.21747870882368,341.5514301730541,-2.687561734136941
13.35877800197038,0.02742868573714743,215.57476352809294,341.5514301730541,-2.687561734136941
13.508425621584623,0.02773594718943789,216.0127623956307,341.5514301730541,-2.687561734136941
13.704838122328315,0.028139227845569114,216.58477479435362,341.5514301730541,-2.687561734136941
13.98542740910502,0.028715343068613723,217.39642005419185,341.5514301730541,-2.687561734136941
14.481135149077199,0.029733146629325864,218.8149733539799,341.5514301730541,-2.687561734136941
14.630782768691441,0.030040408081616322,219.23947751358025,341.5514301730541,-2.687561734136941
14.686900626046782,0.030155631126225244,219.3982295774636,341.5514301730541,-2.687561734136941
14.705606578498562,0.03019403880776155,219.45109433860048,341.5514301730541,-2.687561734136941
14.911372055468146,0.03061652330466093,220.03088635539154,341.5514301730541,-2.687561734136941
15.444491700343887,0.03171114222844569,221.51874234350996,341.5514301730541,-2.687561734136941
15.612845272409908,0.03205681136227245,221.9844122406933,341.5514301730541,-2.687561734136941
15.846669678057166,0.0325369073814763,222.62794022509576,341.5514301730541,-2.687561734136941
15.986964321445516,0.0328249649929986,223.01227965847755,341.5514301730541,-2.687561734136941
16.14596491728565,0.033151430286057215,223.4462777382,341.5514301730541,-2.687561734136941
16.492025037643586,0.0338619723944789,224.38514145894146,341.5514301730541,-2.687561734136941
16.61361372858016,0.034111622324464894,224.7131843738168,341.5514301730541,-2.687561734136941
16.959673848938092,0.034822164432886576,225.6417590453653,341.5514301730541,-2.687561734136941
17.081262539874665,0.03507181436287257,225.9662568913946,341.5514301730541,-2.687561734136941
17.249616111940686,0.035417483496699334,226.4140783292894,341.5514301730541,-2.687561734136941
17.30573396929603,0.03553270654130826,226.56297292595863,341.5514301730541,-2.687561734136941
17.558264327395065,0.03605121024204841,227.23068198389947,341.5514301730541,-2.687561734136941
17.651794089653965,0.03624324864972994,227.477029844926,341.5514301730541,-2.687561734136941
17.754676828138756,0.036454490898179634,227.74742526794333,341.5514301730541,-2.687561734136941
17.85755956662355,0.036665733146629326,228.01721030302141,341.5514301730541,-2.687561734136941
18.100736948496692,0.03716503300660132,228.652485704916,341.5514301730541,-2.687561734136941
18.222325639433265,0.03741468293658731,228.96887456417411,341.5514301730541,-2.687561734136941
18.25973754433683,0.037491498299659934,229.06605920181613,341.5514301730541,-2.687561734136941
18.44679706885463,0.037875575115023,229.5508224021854,341.5514301730541,-2.687561734136941
18.615150640920657,0.038221244248849776,229.9854725696021,341.5514301730541,-2.687561734136941
18.7647982605349,0.038528505701140234,230.3705429082633,341.5514301730541,-2.687561734136941
19.232447071829405,0.03948869773954791,231.56624000262238,341.5514301730541,-2.687561734136941
19.382094691443648,0.03979595919183837,231.9464611572361,341.5514301730541,-2.687561734136941
19.559801239735563,0.04016083216643329,232.39648995123667,341.5514301730541,-2.687561734136941
19.653331001994463,0.040352870574114824,232.63270658413302,341.5514301730541,-2.687561734136941
20.10227386083719,0.0412746549309862,233.76049967207638,341.5514301730541,-2.687561734136941
20.186450646870206,0.04144748949789959,233.97086281862858,341.5514301730541,-2.687561734136941
20.28933338535499,0.041658731746349265,234.22750931100106,341.5514301730541,-2.687561734136941
20.457686957421018,0.04200440088017604,234.64638421444272,341.5514301730541,-2.687561734136941
20.822453030230733,0.04275335067013403,235.54936221085444,341.5514301730541,-2.687561734136941
21.00951255474854,0.04313742748549711,236.0100334553601,341.5514301730541,-2.687561734136941
21.27139588907346,0.0436751350270054,236.6522948315198,341.5514301730541,-2.687561734136941
21.364925651332364,0.043867173434686935,236.88092558324323,341.5514301730541,-2.687561734136941
21.467808389817154,0.044078415683136626,237.13196903666412,341.5514301730541,-2.687561734136941
21.74839767659386,0.04465453090618124,237.814259451019,341.5514301730541,-2.687561734136941
21.795162557723312,0.044750550110022005,237.92763992404502,341.5514301730541,-2.687561734136941
21.888692319982212,0.04494258851770354,238.15411663893926,341.5514301730541,-2.687561734136941
21.982222082241112,0.04513462692538507,238.38021625261214,341.5514301730541,-2.687561734136941
22.262811369017818,0.045710742148429684,239.05627465790388,341.5514301730541,-2.687561734136941
22.300223273921382,0.045787557511502305,239.1461640437462,341.5514301730541,-2.687561734136941
22.403106012406177,0.045998799759952,239.39305711033617,341.5514301730541,-2.687561734136941
22.636930418053424,0.04647889577915583,239.9525390991012,341.5514301730541,-2.687561734136941
22.90816672860424,0.04703580716143228,240.59872235827467,341.5514301730541,-2.687561734136941
23.076520300670268,0.04738147629525906,240.99830114057266,341.5514301730541,-2.687561734136941
23.188756015380946,0.047611922384476896,241.26405557142377,341.5514301730541,-2.687561734136941
23.24487387273629,0.04772714542908582,241.39674463512458,341.5514301730541,-2.687561734136941
23.40387446857642,0.048053610722144424,241.77202023573432,341.5514301730541,-2.687561734136941
23.55352208819066,0.04836087217443488,242.12431352196685,341.5514301730541,-2.687561734136941
23.740581612708468,0.04874494898979796,242.56345496986447,341.5514301730541,-2.687561734136941
23.927641137226267,0.04912902580516103,243.001249020185,341.5514301730541,-2.687561734136941
24.217583400228868,0.0497243448689738,243.67720110549453,341.5514301730541,-2.687561734136941
24.245642328906538,0.04978195639127826,243.74244787498898,341.5514301730541,-2.687561734136941
24.339172091165437,0.049973994798959795,243.9597247374443,341.5514301730541,-2.687561734136941
24.432701853424337,0.05016603320664133,244.17667621454606,341.5514301730541,-2.687561734136941
24.57299649681269,0.05045409081816363,244.50149711292224,341.5514301730541,-2.687561734136941
24.750703045104604,0.05081896379275855,244.91190052137057,341.5514301730541,-2.687561734136941
24.89099768849296,0.05110702140428086,245.23509201958407,341.5514301730541,-2.687561734136941
25.19964590394733,0.05174074814962992,245.94362309187417,341.5514301730541,-2.687561734136941
25.424117333368695,0.05220164032806561,246.45679436458147,341.5514301730541,-2.687561734136941
25.53635304807938,0.05243208641728346,246.7127171471956,341.5514301730541,-2.687561734136941
26.097531621632786,0.05358431686337267,247.98580936406594,341.5514301730541,-2.687561734136941
26.12559055031046,0.053641928385677135,248.04918222462433,341.5514301730541,-2.687561734136941
26.350061979731823,0.05410282056411282,248.5552130216302,341.5514301730541,-2.687561734136941
26.742886981219208,0.05490938187637527,249.43674001886401,341.5514301730541,-2.687561734136941
26.78029888612277,0.05498619723944789,249.52043071827254,341.5514301730541,-2.687561734136941
26.827063767252223,0.05508221644328866,249.62497999956284,341.5514301730541,-2.687561734136941
26.958005434414687,0.05535107021404281,249.91734053092867,341.5514301730541,-2.687561734136941
27.004770315544135,0.05544708941788358,250.0216207209618,341.5514301730541,-2.687561734136941
27.36953638835385,0.05619603920784157,250.83260300456,341.5514301730541,-2.687561734136941
27.44436019816097,0.056349669933986796,250.99843611479722,341.5514301730541,-2.687561734136941
27.594007817775214,0.056656931386277254,251.32957429577053,341.5514301730541,-2.687561734136941
27.687537580034114,0.05684896979395879,251.53618004079416,341.5514301730541,-2.687561734136941
28.04295067661794,0.05757871574314863,252.31881191511593,341.5514301730541,-2.687561734136941
28.25806912981342,0.05802040408081617,252.7906311223529,341.5514301730541,-2.687561734136941
28.735070917333815,0.058999799959991994,253.83187069728052,341.5514301730541,-2.687561734136941
28.791188774689157,0.05911502300460092,253.95392470484933,341.5514301730541,-2.687561734136941
28.96889532298107,0.05947989597919584,254.3398183915336,341.5514301730541,-2.687561734136941
29.071778061465864,0.05969113822764553,254.56280855483664,341.5514301730541,-2.687561734136941
29.10918996636942,0.05976795359071814,254.64381955416107,341.5514301730541,-2.687561734136941
29.408485205597906,0.060382476495299056,255.2904521597528,341.5514301730541,-2.687561734136941
29.61425068256749,0.06080496099219844,255.73352401748295,341.5514301730541,-2.687561734136941
29.726486397278176,0.06103540708141629,255.97469346633247,341.5514301730541,-2.687561734136941
29.754545325955842,0.06109301860372074,256.03493030910727,341.5514301730541,-2.687561734136941
29.904192945570085,0.0614002800560112,256.3558200955325,341.5514301730541,-2.687561734136941
30.072546517636113,0.06174594918983797,256.7160734650373,341.5514301730541,-2.687561734136941
30.194135208572686,0.06199559911982397,256.97576746908356,341.5514301730541,-2.687561734136941
30.59631318628596,0.06282136427285458,257.8318643947689,341.5514301730541,-2.687561734136941
30.68984294854486,0.06301340268053611,258.0303263709816,341.5514301730541,-2.687561734136941
31.054609021354576,0.0637623524704941,258.8020847075731,341.5514301730541,-2.687561734136941
31.129432831161697,0.06391598319663933,258.9599562325685,341.5514301730541,-2.687561734136941
31.428728070390182,0.06453050610122024,259.5899680223979,341.5514301730541,-2.687561734136941
31.559669737552646,0.0647993598719744,259.86486194334515,341.5514301730541,-2.687561734136941
32.23308402581674,0.06618203640728146,261.2716367832281,341.5514301730541,-2.687561734136941
32.44820247901222,0.066623724744949,261.71860140224146,341.5514301730541,-2.687561734136941
32.59785009862646,0.06693098619723946,262.02885196014836,341.5514301730541,-2.687561734136941
32.831674504273714,0.06741108221644329,262.512508752416,341.5514301730541,-2.687561734136941
32.88779236162905,0.06752630526105222,262.6283862629234,341.5514301730541,-2.687561734136941
32.99067510011385,0.06773754750950191,262.84062828293236,341.5514301730541,-2.687561734136941
33.32738224424589,0.06842888577715543,263.5334406979317,341.5514301730541,-2.687561734136941
33.36479414914945,0.06850570114022805,263.6102509775645,341.5514301730541,-2.687561734136941
33.579912602344926,0.06894738947789558,264.0512599809902,341.5514301730541,-2.687561734136941
33.68279534082972,0.06915863172634527,264.2617877222868,341.5514301730541,-2.687561734136941
33.81373700799218,0.06942748549709943,264.52936976393624,341.5514301730541,-2.687561734136941
33.94467867515464,0.06969633926785357,264.79654799318075,341.5514301730541,-2.687561734136941
34.384268557771485,0.0705989197839568,265.69057818875785,341.5514301730541,-2.687561734136941
34.48715129625627,0.07081016203240649,265.89917424733113,341.5514301730541,-2.687561734136941
34.636798915870514,0.07111742348469695,266.2021539829173,341.5514301730541,-2.687561734136941
34.83321141661421,0.07152070414082817,266.59904126846106,341.5514301730541,-2.687561734136941
34.982859036228454,0.07182796559311863,266.9008460430859,341.5514301730541,-2.687561734136941
35.02027094113201,0.07190478095619124,266.9762185123512,341.5514301730541,-2.687561734136941
35.06703582226146,0.072000800160032,267.0703899534639,341.5514301730541,-2.687561734136941
35.244742370553375,0.07236567313462693,267.4277956329341,341.5514301730541,-2.687561734136941
35.47856677620063,0.07284576915383077,267.89699734024526,341.5514301730541,-2.687561734136941
35.59080249091131,0.07307621524304861,268.1217856562064,341.5514301730541,-2.687561734136941
35.637567372040756,0.07317223444688938,268.21536584109714,341.5514301730541,-2.687561734136941
36.03039237352815,0.07397879575915184,268.9995575619882,341.5514301730541,-2.687561734136941
36.22680487427184,0.07438207641528306,269.3904025081789,341.5514301730541,-2.687561734136941
36.30162868407896,0.07453570714142829,269.5390783281137,341.5514301730541,-2.687561734136941
36.329687612756636,0.07459331866373275,269.59480094237455,341.5514301730541,-2.687561734136941
36.40451142256376,0.07474694938987798,269.7433125846155,341.5514301730541,-2.687561734136941
36.7412185666958,0.07543828765753151,270.4101472680609,341.5514301730541,-2.687561734136941
36.82539535272882,0.0756111222244449,270.57648302211766,341.5514301730541,-2.687561734136941
36.928278091213606,0.07582236447289459,270.7795810401682,341.5514301730541,-2.687561734136941
37.124690591957304,0.07622564512902581,271.1667018840263,341.5514301730541,-2.687561734136941
37.274338211571546,0.07653290658131627,271.4611152057362,341.5514301730541,-2.687561734136941
37.37722095005633,0.07674414882976596,271.6632570134008,341.5514301730541,-2.687561734136941
37.48010368854113,0.07695539107821565,271.8651819389057,341.5514301730541,-2.687561734136941
37.74198702286605,0.07749309861972395,272.3781996404965,341.5514301730541,-2.687561734136941
37.77939892776961,0.07756991398279657,272.45137439424144,341.5514301730541,-2.687561734136941
38.14416500057933,0.07831886377275456,273.16335341003514,341.5514301730541,-2.687561734136941
38.24704773906412,0.07853010602120425,273.3636872788759,341.5514301730541,-2.687561734136941
38.452813216033704,0.07895259051810362,273.76372562951855,341.5514301730541,-2.687561734136941
38.9298150035541,0.07993198639727946,274.6878900852603,341.5514301730541,-2.687561734136941
39.16363940920136,0.0804120824164833,275.1392980346949,341.5514301730541,-2.687561734136941
39.44422869597806,0.08098819763952791,275.6796025006724,341.5514301730541,-2.687561734136941
39.58452333936641,0.08127625525105021,275.9491924729501,341.5514301730541,-2.687561734136941
39.70611203030298,0.08152590518103621,276.1825358366618,341.5514301730541,-2.687561734136941
39.9773483408538,0.08208281656331266,276.70206916116274,341.5514301730541,-2.687561734136941
40.30470250875996,0.08275495099019804,277.32726495525816,341.5514301730541,-2.687561734136941
40.603997747988444,0.08336947389477896,277.8971416901515,341.5514301730541,-2.687561734136941
40.66011560534378,0.08348469693938788,278.00381095113914,341.5514301730541,-2.687561734136941
40.8378221536357,0.0838495699139828,278.3412187802645,341.5514301730541,-2.687561734136941
41.3148239411561,0.08482896579315864,279.2440730196735,341.5514301730541,-2.687561734136941
41.5018834656739,0.08521304260852171,279.5970226579388,341.5514301730541,-2.687561734136941
41.98823822942019,0.0862116423284657,280.5118002928808,341.5514301730541,-2.687561734136941
42.016297158097856,0.08626925385077015,280.5644494887524,341.5514301730541,-2.687561734136941
42.14723882526032,0.08653810762152431,280.8099646582288,341.5514301730541,-2.687561734136941
42.212709658841554,0.08667253450690139,280.9326106767068,341.5514301730541,-2.687561734136941
42.39976918335935,0.08705661132226446,281.2826197590122,341.5514301730541,-2.687561734136941
42.51200489807004,0.08728705741148231,281.4923361510555,341.5514301730541,-2.687561734136941
42.614887636554826,0.08749829965993199,281.684386565125,341.5514301730541,-2.687561734136941
42.69906442258784,0.08767113422684537,281.8413842592012,341.5514301730541,-2.687561734136941
42.86741799465386,0.08801680336067214,282.15501799560354,341.5514301730541,-2.687561734136941
42.96094775691276,0.08820884176835367,282.3290513805968,341.5514301730541,-2.687561734136941
43.03577156671988,0.0883624724944989,282.4681717210271,341.5514301730541,-2.687561734136941
43.16671323388235,0.08863132626525305,282.7114055407002,341.5514301730541,-2.687561734136941
43.24153704368947,0.08878495699139828,282.85026709875126,341.5514301730541,-2.687561734136941
43.28830192481892,0.08888097619523905,282.93700798722176,341.5514301730541,-2.687561734136941
43.68112692630631,0.08968753750750151,283.6641942391785,341.5514301730541,-2.687561734136941
43.84948049837233,0.09003320664132827,283.9750642458037,341.5514301730541,-2.687561734136941
44.158128713826706,0.09066693338667733,284.5437863199497,341.5514301730541,-2.687561734136941
44.36389419079629,0.09108941788357672,284.92207332607836,341.5514301730541,-2.687561734136941
44.429365024377525,0.0912238447689538,285.04229379346435,341.5514301730541,-2.687561734136941
44.72866026360601,0.09183836767353472,285.5909956102764,341.5514301730541,-2.687561734136941
44.98119062170504,0.09235687137427485,286.0528498898656,341.5514301730541,-2.687561734136941
45.07472038396394,0.0925489097819564,286.22365026675794,341.5514301730541,-2.687561734136941
45.17760312244873,0.09276015203040608,286.4113711172477,341.5514301730541,-2.687561734136941
45.40207455187009,0.09322104420884177,286.8203661482825,341.5514301730541,-2.687561734136941
45.48625133790311,0.09339387877575515,286.9735358731305,341.5514301730541,-2.687561734136941
45.692016814872694,0.09381636327265454,287.3474861061301,341.5514301730541,-2.687561734136941
45.953900149197615,0.09435407081416283,287.82247426628703,341.5514301730541,-2.687561734136941
46.17837157861898,0.09481496299259852,288.2287673507049,341.5514301730541,-2.687561734136941
46.33737217445912,0.09514142828565714,288.5160923971503,341.5514301730541,-2.687561734136941
46.46831384162158,0.09541028205641129,288.7524244215817,341.5514301730541,-2.687561734136941
46.711491223494725,0.09590958191638328,289.19063884095783,341.5514301730541,-2.687561734136941
46.79566800952774,0.09608241648329667,289.34212103761985,341.5514301730541,-2.687561734136941
47.05755134385266,0.09662012402480497,289.81272080538866,341.5514301730541,-2.687561734136941
47.33814063062937,0.09719623924784958,290.31580283351434,341.5514301730541,-2.687561734136941
47.40361146421059,0.09733066613322665,290.43302114408226,341.5514301730541,-2.687561734136941
47.47843527401771,0.09748429685937188,290.56690764258803,341.5514301730541,-2.687561734136941
47.54390610759894,0.09761872374474895,290.6839908401675,341.5514301730541,-2.687561734136941
47.702906703439076,0.09794518903780756,290.9680742709165,341.5514301730541,-2.687561734136941
47.84320134682743,0.09823324664932986,291.21842958994654,341.5514301730541,-2.687561734136941
48.03961384757113,0.0986365273054611,291.5684465641416,341.5514301730541,-2.687561734136941
48.105084681152356,0.09877095419083817,291.68499480545694,341.5514301730541,-2.687561734136941
48.19861444341126,0.0989629925985197,291.85138503800755,341.5514301730541,-2.687561734136941
48.65691027847988,0.09990398079615924,292.66488398086716,341.5514301730541,-2.687561734136941
48.694322183383434,0.09998079615923185,292.73115984206515,341.5514301730541,-2.687561734136941