File: datasets/aisi_316_L/data/M1/train_20.csv
Time(s),Strain(%),Stress(MPa),Temp(C),Log_SR(s-1)
0.0,0.0,0.0,37.35564952072437,3.4059565494042934
5.340505405297774e-09,1.3599999999999999e-05,2.6582644999999996,37.35564952072437,3.4059565494042934
1.0995158187377772e-08,2.8e-05,5.4728975,37.35564952072437,3.4059565494042934
1.3508337201635547e-08,3.4399999999999996e-05,6.7238454999999995,37.35564952072437,3.4059565494042934
1.822054785336888e-08,4.6399999999999996e-05,9.069372999999999,37.35564952072437,3.4059565494042934
2.890155866396443e-08,7.36e-05,14.385902,37.35564952072437,3.4059565494042934
3.5498653576391095e-08,9.04e-05,17.6696405,37.35564952072437,3.4059565494042934
3.832597996743109e-08,9.76e-05,19.076957,37.35564952072437,3.4059565494042934
5.0263580285155525e-08,0.000128,25.01896,37.35564952072437,3.4059565494042934
5.780311732792886e-08,0.0001472,28.771804,37.35564952072437,3.4059565494042934
6.597094912426663e-08,0.000168,32.837385,37.35564952072437,3.4059565494042934
7.225389665991107e-08,0.000184,35.964755,37.35564952072437,3.4059565494042934
8.701882336867551e-08,0.0002216,43.3140745,37.35564952072437,3.4059565494042934
8.953200238293328e-08,0.00022799999999999999,44.5650225,37.35564952072437,3.4059565494042934
9.173103402040884e-08,0.00023359999999999999,45.659602,37.35564952072437,3.4059565494042934
9.644324467214217e-08,0.0002456,48.0051295,37.35564952072437,3.4059565494042934
9.707153942570662e-08,0.0002472,48.3178665,37.35564952072437,3.4059565494042934
9.895642368639995e-08,0.000252,49.256077499999996,37.35564952072437,3.4059565494042934
1.083808449898666e-07,0.000276,53.947132499999995,37.35564952072437,3.4059565494042934
1.1592038203263993e-07,0.00029519999999999997,57.69997649999999,37.35564952072437,3.4059565494042934
1.196901505540266e-07,0.0003048,59.576398499999996,37.35564952072437,3.4059565494042934
1.2754383497358216e-07,0.0003248,63.485611,37.35564952072437,3.4059565494042934
1.4545023545016882e-07,0.0003704,72.3986155,37.35564952072437,3.4059565494042934
1.507907408554666e-07,0.000384,75.05688,37.35564952072437,3.4059565494042934
1.6147175166606214e-07,0.00041119999999999997,80.373409,37.35564952072437,3.4059565494042934
1.639849306803199e-07,0.00041759999999999996,81.62435699999999,37.35564952072437,3.4059565494042934
1.7058202559274659e-07,0.0004344,84.9080955,37.35564952072437,3.4059565494042934
1.7246690985343992e-07,0.0004392,85.8463065,37.35564952072437,3.4059565494042934
1.837762154175999e-07,0.000468,91.4755725,37.35564952072437,3.4059565494042934
1.88174278692551e-07,0.0004792,93.6647315,37.35564952072437,3.4059565494042934
2.0576653179235542e-07,0.0005239999999999999,102.42136749999999,37.35564952072437,3.4059565494042934
2.1016459506730655e-07,0.0005352,104.6105265,37.35564952072437,3.4059565494042934
2.1770413211007985e-07,0.0005543999999999999,108.36337049999999,37.35564952072437,3.4059565494042934
2.2273049013859546e-07,0.0005672,110.8652665,37.35564952072437,3.4059565494042934
2.2744270079032875e-07,0.0005792,113.21079399999999,37.35564952072437,3.4059565494042934
2.3215491144206207e-07,0.0005912,115.5563215,37.35564952072437,3.4059565494042934
2.3749541684735987e-07,0.0006048,118.214586,37.35564952072437,3.4059565494042934
2.4315006962943986e-07,0.0006192,121.029219,37.35564952072437,3.4059565494042934
2.450349538901332e-07,0.000624,121.96743,37.35564952072437,3.4059565494042934
2.6011402797567985e-07,0.0006624,129.473118,37.35564952072437,3.4059565494042934
2.6419794387384874e-07,0.0006728,131.5059085,37.35564952072437,3.4059565494042934
2.761355441915732e-07,0.0007032,137.4479115,37.35564952072437,3.4059565494042934
2.7802042845226653e-07,0.000708,138.3861225,37.35564952072437,3.4059565494042934
2.836750812343465e-07,0.0007224,141.20075549999999,37.35564952072437,3.4059565494042934
2.8587411287182205e-07,0.0007279999999999999,142.295335,37.35564952072437,3.4059565494042934
2.9027217614677315e-07,0.0007392,144.48449399999998,37.35564952072437,3.4059565494042934
2.9467023942172426e-07,0.0007503999999999999,146.67365299999997,37.35564952072437,3.4059565494042934
3.172888505500443e-07,0.000808,157.932185,37.35564952072437,3.4059565494042934
3.242000928392532e-07,0.0008256,161.37229200000002,37.35564952072437,3.4059565494042934
3.3550939840341316e-07,0.0008544,167.001558,37.35564952072437,3.4059565494042934
3.3990746167836426e-07,0.0008656,169.190717,37.35564952072437,3.4059565494042934
3.4524796708366206e-07,0.0008792,171.8489815,37.35564952072437,3.4059565494042934
3.493318829818309e-07,0.0008895999999999999,173.88177199999998,37.35564952072437,3.4059565494042934
3.540440936335642e-07,0.0009015999999999999,176.2272995,37.35564952072437,3.4059565494042934
3.6158363067633757e-07,0.0009207999999999999,179.9801435,37.35564952072437,3.4059565494042934
3.644109570673776e-07,0.000928,181.38746,37.35564952072437,3.4059565494042934
3.7069390460302204e-07,0.000944,184.51483,37.35564952072437,3.4059565494042934
3.73521230994062e-07,0.0009511999999999999,185.9221465,37.35564952072437,3.4059565494042934
3.754061152547553e-07,0.0009559999999999999,186.8603575,37.35564952072437,3.4059565494042934
3.7823344164579534e-07,0.0009632,188.267674,37.35564952072437,3.4059565494042934
3.9645398949916424e-07,0.0010096,197.337047,37.35564952072437,3.4059565494042934
4.008520527741153e-07,0.0010207999999999999,199.52620599999997,37.35564952072437,3.4059565494042934
4.0336523178837317e-07,0.0010272,200.777154,37.35564952072437,3.4059565494042934
4.071350003097598e-07,0.0010368,202.65357600000002,37.35564952072437,3.4059565494042934
4.2472725340956426e-07,0.0010816,211.410212,37.35564952072437,3.4059565494042934
4.2629799029347533e-07,0.0010856,212.19205449999998,37.35564952072437,3.4059565494042934
4.391780327415464e-07,0.0011183999999999999,218.60316299999997,37.35564952072437,3.4059565494042934
4.4106291700223977e-07,0.0011232,219.541374,37.35564952072437,3.4059565494042934
4.501731909289242e-07,0.0011464,224.07606049999998,37.35564952072437,3.4059565494042934
4.545712542038753e-07,0.0011576,226.2652195,37.35564952072437,3.4059565494042934
4.6179664386986643e-07,0.001176,229.861695,37.35564952072437,3.4059565494042934
4.72477654680462e-07,0.0012032,235.178224,37.35564952072437,3.4059565494042934
4.759332758250664e-07,0.001212,236.8982775,37.35564952072437,3.4059565494042934
4.768757179554131e-07,0.0012144,237.36738300000002,37.35564952072437,3.4059565494042934
4.781323074625419e-07,0.0012175999999999999,237.992857,37.35564952072437,3.4059565494042934
4.831586654910576e-07,0.0012304,240.494753,37.35564952072437,3.4059565494042934
4.941538236784353e-07,0.0012584,245.9676505,37.35564952072437,3.4059565494042934
4.950962658087819e-07,0.0012607999999999999,246.43675599999997,37.35564952072437,3.4059565494042934
5.098611925175464e-07,0.0012984,253.78607549999998,37.35564952072437,3.4059565494042934
5.139451084157153e-07,0.0013088,255.81886599999999,37.35564952072437,3.4059565494042934
5.236836770959641e-07,0.0013335999999999999,260.6662895,37.35564952072437,3.4059565494042934
5.340505405297774e-07,0.0013599999999999999,265.82644999999997,37.35564952072437,3.4059565494042934
5.403334880654219e-07,0.0013759999999999998,268.95381999999995,37.35564952072437,3.4059565494042934
5.441032565868085e-07,0.0013855999999999999,270.830242,37.35564952072437,3.4059565494042934
5.497579093688886e-07,0.0014,273.644875,37.35564952072437,3.4059565494042934
5.563550042813152e-07,0.0014168,276.9286135,37.35564952072437,3.4059565494042934
5.598106254259197e-07,0.0014256,278.648667,37.35564952072437,3.4059565494042934
5.642086887008708e-07,0.0014368,280.837826,37.35564952072437,3.4059565494042934
5.720623731204264e-07,0.0014567999999999998,284.7470385,37.35564952072437,3.4059565494042934
5.81486794423893e-07,0.0014808,289.4380935,37.35564952072437,3.4059565494042934
5.95623426379093e-07,0.0015168,296.474676,37.35564952072437,3.4059565494042934
6.003356370308263e-07,0.0015287999999999999,298.8202035,37.35564952072437,3.4059565494042934
6.113307952182041e-07,0.0015568,304.293101,37.35564952072437,3.4059565494042934
6.144722689860263e-07,0.0015647999999999999,305.856786,37.35564952072437,3.4059565494042934
6.185561848841952e-07,0.0015752,307.8895765,37.35564952072437,3.4059565494042934
6.235825429127108e-07,0.001588,310.3914725,37.35564952072437,3.4059565494042934
6.330069642161774e-07,0.001612,315.08252749999997,37.35564952072437,3.4059565494042934
6.358342906072174e-07,0.0016192,316.489844,37.35564952072437,3.4059565494042934
6.418030907660796e-07,0.0016343999999999998,317.0521418111093,37.35564952072437,3.4059565494042934
6.512275120695463e-07,0.0016584,317.25210706455107,37.35564952072437,3.4059565494042934
6.556255753444973e-07,0.0016695999999999998,317.3450376498748,37.35564952072437,3.4059565494042934
6.59395343865884e-07,0.0016791999999999998,317.4244990956374,37.35564952072437,3.4059565494042934
6.678773230390041e-07,0.0017008,317.6026424148242,37.35564952072437,3.4059565494042934
6.71961238937173e-07,0.0017112,317.6881002494875,37.35564952072437,3.4059565494042934
6.741602705746485e-07,0.0017167999999999999,317.73403209695255,37.35564952072437,3.4059565494042934
6.835846918781151e-07,0.0017407999999999998,317.93022472256735,37.35564952072437,3.4059565494042934
6.845271340084618e-07,0.0017431999999999999,317.9497857869551,37.35564952072437,3.4059565494042934
6.91752523674453e-07,0.0017615999999999999,318.0994065758192,37.35564952072437,3.4059565494042934
7.027476818618307e-07,0.0017896,318.3259262188933,37.35564952072437,3.4059565494042934
7.065174503832174e-07,0.0017992,318.40327135414526,37.35564952072437,3.4059565494042934
7.190833454545062e-07,0.0018311999999999998,318.6599338893627,37.35564952072437,3.4059565494042934
7.253662929901508e-07,0.0018472,318.787608761731,37.35564952072437,3.4059565494042934
7.404453670756974e-07,0.0018855999999999999,319.0922814573016,37.35564952072437,3.4059565494042934
7.442151355970841e-07,0.0018951999999999999,319.1680703462974,37.35564952072437,3.4059565494042934
7.520688200166396e-07,0.0019152,319.3254846723453,37.35564952072437,3.4059565494042934
7.621215360736706e-07,0.0019408,319.5260426558296,37.35564952072437,3.4059565494042934
7.693469257396618e-07,0.0019592,319.6695569631008,37.35564952072437,3.4059565494042934
7.815986734341685e-07,0.0019904,319.9117117326605,37.35564952072437,3.4059565494042934
7.847401472019907e-07,0.0019984,319.97356367784596,37.35564952072437,3.4059565494042934
7.897665052305062e-07,0.0020112,320.07232631084594,37.35564952072437,3.4059565494042934
7.913372421144174e-07,0.0020152,320.1031393213244,37.35564952072437,3.4059565494042934
7.988767791571907e-07,0.0020344,320.2507110213109,37.35564952072437,3.4059565494042934
8.064163161999641e-07,0.0020536,320.39774054409503,37.35564952072437,3.4059565494042934
8.089294952142217e-07,0.0020599999999999998,320.44663112136675,37.35564952072437,3.4059565494042934
8.12070968982044e-07,0.002068,320.50766111928715,37.35564952072437,3.4059565494042934
8.145841479963018e-07,0.0020744,320.5564188488389,37.35564952072437,3.4059565494042934
8.268358956908085e-07,0.0021056,320.7932777606118,37.35564952072437,3.4059565494042934
8.36260316994275e-07,0.0021295999999999997,320.97454669044373,37.35564952072437,3.4059565494042934
8.397159381388795e-07,0.0021384,321.0408121200854,37.35564952072437,3.4059565494042934
8.45998885674524e-07,0.0021544,321.1610228880183,37.35564952072437,3.4059565494042934
8.488262120655641e-07,0.0021616,321.21500408929404,37.35564952072437,3.4059565494042934
8.551091596012085e-07,0.0021776,321.334711888102,37.35564952072437,3.4059565494042934
8.613921071368529e-07,0.0021936,321.4540771467515,37.35564952072437,3.4059565494042934
8.799268023670039e-07,0.0022408,321.8042419945437,37.35564952072437,3.4059565494042934
8.846390130187374e-07,0.0022528,321.89280684731244,37.35564952072437,3.4059565494042934
8.890370762936885e-07,0.002264,321.97530152452794,37.35564952072437,3.4059565494042934
8.921785500615105e-07,0.0022719999999999997,322.0341288793194,37.35564952072437,3.4059565494042934
9.016029713649772e-07,0.002296,322.2101281414557,37.35564952072437,3.4059565494042934
9.041161503792351e-07,0.0023024,322.2569399174576,37.35564952072437,3.4059565494042934
9.135405716827017e-07,0.0023263999999999997,322.43203393735456,37.35564952072437,3.4059565494042934
9.289337931450306e-07,0.0023656,322.7165133770765,37.35564952072437,3.4059565494042934
9.314469721592884e-07,0.002372,322.7627838536702,37.35564952072437,3.4059565494042934
9.367874775645862e-07,0.0023856,322.86094726387876,37.35564952072437,3.4059565494042934
9.509241095197862e-07,0.0024216,323.1197437922781,37.35564952072437,3.4059565494042934
9.594060886929061e-07,0.0024432,323.2743015746647,37.35564952072437,3.4059565494042934
9.638041519678572e-07,0.0024544,323.3542327935125,37.35564952072437,3.4059565494042934
9.773124891694928e-07,0.0024887999999999998,323.5988510414045,37.35564952072437,3.4059565494042934
9.826529945747905e-07,0.0025023999999999997,323.695196435988,37.35564952072437,3.4059565494042934
9.854803209658305e-07,0.0025096,323.74612013733434,37.35564952072437,3.4059565494042934
9.870510578497416e-07,0.0025136,323.77438646130423,37.35564952072437,3.4059565494042934
1.0011876898049417e-06,0.0025496,324.0279988132264,37.35564952072437,3.4059565494042934
1.0027584266888528e-06,0.0025536,324.0560914888794,37.35564952072437,3.4059565494042934
1.0055857530798928e-06,0.0025608,324.1066150953669,37.35564952072437,3.4059565494042934
1.0159526165137062e-06,0.0025872,324.2913962294503,37.35564952072437,3.4059565494042934
1.022863858802915e-06,0.0026048,324.4141752858584,37.35564952072437,3.4059565494042934
1.0288326589617772e-06,0.00262,324.51995160442925,37.35564952072437,3.4059565494042934
1.034173164367075e-06,0.0026336,324.61439087834447,37.35564952072437,3.4059565494042934
1.045796617308017e-06,0.0026631999999999997,324.8192802080237,37.35564952072437,3.4059565494042934
1.048309796322275e-06,0.0026696,324.86346361124373,37.35564952072437,3.4059565494042934
1.0571059228721772e-06,0.002692,325.017781254629,37.35564952072437,3.4059565494042934
1.0618181335239106e-06,0.002704,325.10024538481133,37.35564952072437,3.4059565494042934
1.0633888704078217e-06,0.002708,325.1277016951373,37.35564952072437,3.4059565494042934
1.0734415864648528e-06,0.0027336,325.3030490235723,37.35564952072437,3.4059565494042934
1.0775255023630216e-06,0.002744,325.37410080273753,37.35564952072437,3.4059565494042934
1.0885206605503993e-06,0.0027719999999999997,325.5648739661882,37.35564952072437,3.4059565494042934
1.0916621343182217e-06,0.00278,325.6192423570513,37.35564952072437,3.4059565494042934
1.1045421767662928e-06,0.0028128,325.8415177925989,37.35564952072437,3.4059565494042934
1.1086260926644616e-06,0.0028231999999999997,325.91178399596924,37.35564952072437,3.4059565494042934
1.1098826821715905e-06,0.0028263999999999997,325.933384047497,37.35564952072437,3.4059565494042934
1.1155373349536704e-06,0.0028407999999999997,326.03046649450266,37.35564952072437,3.4059565494042934
1.120563692982186e-06,0.0028536,326.116600998801,37.35564952072437,3.4059565494042934
1.1303022616624349e-06,0.0028783999999999997,326.2830590109022,37.35564952072437,3.4059565494042934
1.1434964514872882e-06,0.0029119999999999997,326.5076932523396,37.35564952072437,3.4059565494042934
1.147266220008675e-06,0.0029216,326.5716885032744,37.35564952072437,3.4059565494042934
1.1541774622978838e-06,0.0029392,326.68880053879747,37.35564952072437,3.4059565494042934
1.1610887045870926e-06,0.0029568,326.8056393963014,37.35564952072437,3.4059565494042934
1.1661150626156082e-06,0.0029695999999999998,326.8904428183135,37.35564952072437,3.4059565494042934
1.1720838627744705e-06,0.0029847999999999997,326.99096194821516,37.35564952072437,3.4059565494042934
1.184021463092195e-06,0.0030152,327.1914032906032,37.35564952072437,3.4059565494042934
1.1871629368600172e-06,0.0030231999999999998,327.2440198229223,37.35564952072437,3.4059565494042934
1.1918751475117505e-06,0.0030352,327.32284292114554,37.35564952072437,3.4059565494042934
1.198158095047395e-06,0.0030512,327.42775158643644,37.35564952072437,3.4059565494042934
1.2016137161919993e-06,0.00306,327.48535989432736,37.35564952072437,3.4059565494042934
1.206954221597297e-06,0.0030735999999999997,327.5742639912985,37.35564952072437,3.4059565494042934
1.211038137495466e-06,0.003084,327.64214599856615,37.35564952072437,3.4059565494042934
1.2242323273203194e-06,0.0031176,327.8608494645185,37.35564952072437,3.4059565494042934
1.2267455063345771e-06,0.003124,327.9024028392719,37.35564952072437,3.4059565494042934
1.2311435696095282e-06,0.0031352,327.97504144583183,37.35564952072437,3.4059565494042934
1.2377406645219548e-06,0.003152,328.08380989182916,37.35564952072437,3.4059565494042934
1.2465367910718572e-06,0.0031744,328.2284834347414,37.35564952072437,3.4059565494042934
1.253448033361066e-06,0.003192,328.34187638046495,37.35564952072437,3.4059565494042934
1.2594168335199282e-06,0.0032072,328.43961056462217,37.35564952072437,3.4059565494042934
1.2616158651574039e-06,0.0032128,328.47557233761734,37.35564952072437,3.4059565494042934
1.2641290441716614e-06,0.0032191999999999998,328.51664158632553,37.35564952072437,3.4059565494042934
1.2660139284323548e-06,0.003224,328.54742262919325,37.35564952072437,3.4059565494042934
1.2700978443305236e-06,0.0032343999999999997,328.6140536418946,37.35564952072437,3.4059565494042934
1.271982728591217e-06,0.0032392,328.6447782302154,37.35564952072437,3.4059565494042934
1.277637381373297e-06,0.0032535999999999997,328.736845633565,37.35564952072437,3.4059565494042934
1.2820354446482483e-06,0.0032648,328.8083437902076,37.35564952072437,3.4059565494042934
1.2870618026767637e-06,0.0032776,328.88993894165566,37.35564952072437,3.4059565494042934
1.297428666110577e-06,0.0033039999999999996,329.05783750447915,37.35564952072437,3.4059565494042934
1.3049682031533504e-06,0.0033231999999999997,329.1796171000116,37.35564952072437,3.4059565494042934
1.315649213963946e-06,0.0033504,329.35166952095494,37.35564952072437,3.4059565494042934
1.3191048351085503e-06,0.0033591999999999997,329.40721679529236,37.35564952072437,3.4059565494042934
1.3216180141228082e-06,0.0033656,329.44757917405633,37.35564952072437,3.4059565494042934
1.3291575511655816e-06,0.0033848,329.5684870905407,37.35564952072437,3.4059565494042934
1.3388961198458304e-06,0.0034096,329.7242646765789,37.35564952072437,3.4059565494042934
1.3410951514833058e-06,0.0034151999999999997,329.7593790303684,37.35564952072437,3.4059565494042934
1.3502054254099903e-06,0.0034384,329.90461420787574,37.35564952072437,3.4059565494042934
1.3571166676991993e-06,0.003456,330.01453782150503,37.35564952072437,3.4059565494042934
1.368111825886577e-06,0.0034839999999999997,330.1889674179183,37.35564952072437,3.4059565494042934
1.3690542680169236e-06,0.0034863999999999997,330.20389304004397,37.35564952072437,3.4059565494042934
1.370939152277617e-06,0.0034912,330.2337322684133,37.35564952072437,3.4059565494042934
1.375337215552568e-06,0.0035023999999999997,330.30329498195937,37.35564952072437,3.4059565494042934
1.3787928366971726e-06,0.0035112,330.357890557143,37.35564952072437,3.4059565494042934
1.3828767525953414e-06,0.0035215999999999997,330.4223438485705,37.35564952072437,3.4059565494042934
1.3888455527542037e-06,0.0035367999999999997,330.5164114402695,37.35564952072437,3.4059565494042934
1.3966992371737593e-06,0.0035567999999999997,330.6399447267962,37.35564952072437,3.4059565494042934
1.4004690056951458e-06,0.0035664,330.69914445321626,37.35564952072437,3.4059565494042934
1.4054953637236615e-06,0.0035792,330.77798083815196,37.35564952072437,3.4059565494042934
1.4102075743753946e-06,0.0035911999999999997,330.85179014651834,37.35564952072437,3.4059565494042934
1.4111500165057414e-06,0.0035935999999999997,330.86654045893533,37.35564952072437,3.4059565494042934
1.4139773428967814e-06,0.0036008,330.91076836196544,37.35564952072437,3.4059565494042934
1.4252866484609413e-06,0.0036295999999999998,331.08733616094366,37.35564952072437,3.4059565494042934
1.4265432379680704e-06,0.0036328,331.1069210186615,37.35564952072437,3.4059565494042934
1.4365959540251015e-06,0.0036584,331.2633583987312,37.35564952072437,3.4059565494042934
1.4409940173000526e-06,0.0036696,331.33166544154557,37.35564952072437,3.4059565494042934
1.4441354910678746e-06,0.0036775999999999996,331.3804064158988,37.35564952072437,3.4059565494042934
1.4538740597481236e-06,0.0037024,331.53124131675736,37.35564952072437,3.4059565494042934
1.4551306492552525e-06,0.0037056,331.5506751425467,37.35564952072437,3.4059565494042934
1.4570155335159459e-06,0.0037104,331.57981361374016,37.35564952072437,3.4059565494042934
1.4689531338336703e-06,0.0037408,331.76401704258194,37.35564952072437,3.4059565494042934
1.4720946076014924e-06,0.0037487999999999996,331.8123944808963,37.35564952072437,3.4059565494042934
1.4774351130067903e-06,0.0037624,331.894543824794,37.35564952072437,3.4059565494042934
1.4856029448031282e-06,0.0037832,332.01996034844353,37.35564952072437,3.4059565494042934
1.4934566292226836e-06,0.0038031999999999996,332.14029980061224,37.35564952072437,3.4059565494042934
1.4978546924976347e-06,0.0038144,332.2075820841487,37.35564952072437,3.4059565494042934
1.5022527557725858e-06,0.0038255999999999997,332.2747873644051,37.35564952072437,3.4059565494042934
1.5063366716707548e-06,0.003836,332.3371235919171,37.35564952072437,3.4059565494042934
1.5085357033082303e-06,0.0038415999999999997,332.3706619509297,37.35564952072437,3.4059565494042934
1.5182742719884793e-06,0.0038664,332.51896036992144,37.35564952072437,3.4059565494042934
1.5346099355811548e-06,0.003908,332.7668886511226,37.35564952072437,3.4059565494042934
1.5390079988561057e-06,0.003919199999999999,332.83346244304306,37.35564952072437,3.4059565494042934
1.5484324201595725e-06,0.0039432,332.9758712355725,37.35564952072437,3.4059565494042934
1.5641397889986837e-06,0.0039832,333.21247031790136,37.35564952072437,3.4059565494042934
1.5669671153897235e-06,0.0039904,333.2549595609487,37.35564952072437,3.4059565494042934
1.569166147027199e-06,0.0039959999999999996,333.2879860823512,37.35564952072437,3.4059565494042934
1.7140167436957606e-06,0.004364872974594919,335.42529271745656,37.35564952072437,3.4059565494042934
1.827132422473116e-06,0.004652930586117224,337.0456911209333,37.35564952072437,3.4059565494042934
1.902542874991353e-06,0.00484496899379876,338.1042647857185,37.35564952072437,3.4059565494042934
2.0609048252796505e-06,0.0052482496499299865,340.27541660596887,37.35564952072437,3.4059565494042934
2.1438563230497115e-06,0.0054594918983796765,341.38665076000245,37.35564952072437,3.4059565494042934
2.2041846850643006e-06,0.005613122624524905,342.1843143457735,37.35564952072437,3.4059565494042934
2.2418899113234192e-06,0.005709141828365673,342.67853243497484,37.35564952072437,3.4059565494042934
2.3474645448489507e-06,0.005977995599119824,344.0453873578389,37.35564952072437,3.4059565494042934
2.3776287258562455e-06,0.0060548109621924385,344.43148600633344,37.35564952072437,3.4059565494042934
2.490744404633601e-06,0.006342868573714743,345.86265027073995,37.35564952072437,3.4059565494042934
2.566154857151838e-06,0.006534906981396279,346.8026994835149,37.35564952072437,3.4059565494042934
2.882878757728433e-06,0.007341468293658731,350.6386602818336,37.35564952072437,3.4059565494042934
3.131733251038615e-06,0.007975195039007801,353.5383192561834,37.35564952072437,3.4059565494042934
3.2222257940604993e-06,0.008205641128225645,354.5702691874522,37.35564952072437,3.4059565494042934
3.4559981968670338e-06,0.008800960192038408,357.1851310746052,37.35564952072437,3.4059565494042934
3.554031785140742e-06,0.009050610122024405,358.2610437321948,37.35564952072437,3.4059565494042934
3.5992780566516843e-06,0.009165833166633327,358.7537088538087,37.35564952072437,3.4059565494042934
3.7199347806808634e-06,0.009473094618923785,360.0558146780975,37.35564952072437,3.4059565494042934
3.998953454998339e-06,0.010183636727345468,363.0054165944312,37.35564952072437,3.4059565494042934
4.066822862264754e-06,0.010356471294258852,363.7106128884642,37.35564952072437,3.4059565494042934
4.1573154052866375e-06,0.010586917383476696,364.6437758248909,37.35564952072437,3.4059565494042934
4.240266903056698e-06,0.010798159631926384,365.4922391807205,37.35564952072437,3.4059565494042934
4.474039305863233e-06,0.011393478695739149,367.8492190978629,37.35564952072437,3.4059565494042934
4.753057980180709e-06,0.012104020804160832,370.60039885985367,37.35564952072437,3.4059565494042934
4.798304251691651e-06,0.012219243848769754,371.0405313197898,37.35564952072437,3.4059565494042934
4.881255749461712e-06,0.012430486097219444,371.8432597007089,37.35564952072437,3.4059565494042934
4.9566662019799485e-06,0.01262252450490098,372.5684078310403,37.35564952072437,3.4059565494042934
5.115028152268247e-06,0.013025805161032206,374.07736095350674,37.35564952072437,3.4059565494042934
5.378964736082076e-06,0.013697939587917584,376.552403759247,37.35564952072437,3.4059565494042934
5.424211007593018e-06,0.013813162632526505,376.97189569651886,37.35564952072437,3.4059565494042934
5.612737138888611e-06,0.014293258651730346,378.7052888990068,37.35564952072437,3.4059565494042934
5.73339386291779e-06,0.014600520104020805,379.80275350293624,37.35564952072437,3.4059565494042934
5.823886405939674e-06,0.014830966193238648,380.61995036712676,37.35564952072437,3.4059565494042934
5.967166265724324e-06,0.015195839167833567,381.90378956302095,37.35564952072437,3.4059565494042934
6.2914312115527435e-06,0.016021604320864174,384.7657310706065,37.35564952072437,3.4059565494042934
6.366841664070981e-06,0.01621364272854571,385.4229833441885,37.35564952072437,3.4059565494042934
6.645860338388456e-06,0.016924184836967393,387.82885906728285,37.35564952072437,3.4059565494042934
6.849468560187697e-06,0.017442688537707543,389.5597028938561,37.35564952072437,3.4059565494042934
7.151110370260645e-06,0.01821084216843369,392.087475551591,37.35564952072437,3.4059565494042934
7.415046954074474e-06,0.018882976595319064,394.2653514150876,37.35564952072437,3.4059565494042934
7.792099216665658e-06,0.019843168633726746,397.324864130508,37.35564952072437,3.4059565494042934
7.852427578680248e-06,0.019996799359871975,397.8089762594547,37.35564952072437,3.4059565494042934
7.935379076450308e-06,0.020208041608321663,398.4722686394489,37.35564952072437,3.4059565494042934
8.161610434005019e-06,0.020784156831366273,400.26764428367915,37.35564952072437,3.4059565494042934
8.26718506753055e-06,0.021053010602120423,401.09883400732116,37.35564952072437,3.4059565494042934
8.327513429545141e-06,0.021206641328265653,401.5719408115264,37.35564952072437,3.4059565494042934
8.350136565300612e-06,0.021264252850570115,401.74901101026825,37.35564952072437,3.4059565494042934
8.606532103862618e-06,0.02191718343668734,403.74290388802234,37.35564952072437,3.4059565494042934
8.764894054150915e-06,0.022320464092818564,404.96285790693554,37.35564952072437,3.4059565494042934
8.870468687676446e-06,0.022589317863572714,405.77138814837514,37.35564952072437,3.4059565494042934
8.945879140194684e-06,0.02278135627125425,406.3466136851747,37.35564952072437,3.4059565494042934
9.089158999979335e-06,0.02314622924584917,407.4343588552231,37.35564952072437,3.4059565494042934
9.322931402785867e-06,0.023741548309661933,409.19485286867086,37.35564952072437,3.4059565494042934
9.405882900555927e-06,0.02395279055811162,409.8153948752062,37.35564952072437,3.4059565494042934
9.45112917206687e-06,0.024068013602720543,410.1529726101174,37.35564952072437,3.4059565494042934
9.63211425811064e-06,0.02452890578115623,411.49702797377944,37.35564952072437,3.4059565494042934
9.77539411789529e-06,0.02489377875575115,412.55409923549536,37.35564952072437,3.4059565494042934
9.89605084192447e-06,0.02520104020804161,413.4395859672306,37.35564952072437,3.4059565494042934
9.911132932428117e-06,0.025239447889577916,413.54997499151386,37.35564952072437,3.4059565494042934
1.0069494882716413e-05,0.02564272854570914,414.7051317949521,37.35564952072437,3.4059565494042934
1.0559662824084954e-05,0.02689097819563913,418.23651195247305,37.35564952072437,3.4059565494042934
1.0589827005092249e-05,0.026967793558711744,418.4517157115878,37.35564952072437,3.4059565494042934
1.0853763588906079e-05,0.02763992798559712,420.32465932536127,37.35564952072437,3.4059565494042934
1.1162946444230851e-05,0.02842728545709142,422.4962346190218,37.35564952072437,3.4059565494042934
1.1238356896749086e-05,0.028619323864772953,423.0223131806711,37.35564952072437,3.4059565494042934
1.1321308394519147e-05,0.028830566113222645,423.59941204917595,37.35564952072437,3.4059565494042934
1.1366554666030089e-05,0.028945789157831567,423.9134980984837,37.35564952072437,3.4059565494042934
1.1562621842577506e-05,0.02944508901780356,425.26894172591005,37.35564952072437,3.4059565494042934
1.1622950204592094e-05,0.02959871974394879,425.6841940253093,37.35564952072437,3.4059565494042934
1.1834099471643159e-05,0.030136427285457092,427.131003456352,37.35564952072437,3.4059565494042934
1.1947215150420513e-05,0.030424484896979395,427.90193693061343,37.35564952072437,3.4059565494042934
1.2030166648190575e-05,0.030635727145429087,428.465480126114,37.35564952072437,3.4059565494042934
1.2075412919701517e-05,0.03075095019003801,428.77222850393406,37.35564952072437,3.4059565494042934
1.2339349503515345e-05,0.031423084616923384,430.5527404654654,37.35564952072437,3.4059565494042934
1.28973868521503e-05,0.03284416883376676,434.26907418246697,37.35564952072437,3.4059565494042934
1.2935092078409419e-05,0.03294018803760752,434.51789233240544,37.35564952072437,3.4059565494042934
1.295771521416489e-05,0.032997799559911986,434.6670474510173,37.35564952072437,3.4059565494042934
1.322919284323054e-05,0.03368913782756551,436.4490594018971,37.35564952072437,3.4059565494042934
1.3342308522007897e-05,0.033977195439087816,437.1873484649612,37.35564952072437,3.4059565494042934
1.3417718974526135e-05,0.034169233846769356,437.67818546876236,37.35564952072437,3.4059565494042934
1.3478047336540724e-05,0.034322864572914585,438.0700808959352,37.35564952072437,3.4059565494042934
1.3666573467836316e-05,0.034802960592118425,439.2903678517429,37.35564952072437,3.4059565494042934
1.4051166775679323e-05,0.035782356471294255,441.7595829419347,37.35564952072437,3.4059565494042934
1.4126577228197564e-05,0.0359743948789758,442.24063668354336,37.35564952072437,3.4059565494042934
1.4156741409204856e-05,0.03605121024204841,442.43277763391455,37.35564952072437,3.4059565494042934
1.4307562314241332e-05,0.03643528705741149,443.39109778062715,37.35564952072437,3.4059565494042934
1.446592426452963e-05,0.036838567713542714,444.39310339191474,37.35564952072437,3.4059565494042934
1.4601663079062455e-05,0.037184236847369476,445.2485651453099,37.35564952072437,3.4059565494042934
1.4752483984098926e-05,0.03756831366273254,446.1954489341825,37.35564952072437,3.4059565494042934
1.488068175337993e-05,0.03789477895579116,446.99733553677487,37.35564952072437,3.4059565494042934
1.4933469070142694e-05,0.03802920584116823,447.3267405096154,37.35564952072437,3.4059565494042934
1.500133847740911e-05,0.03820204040808162,447.74959469061423,37.35564952072437,3.4059565494042934
1.5159700427697406e-05,0.03860532106421284,448.7333635295624,37.35564952072437,3.4059565494042934
1.5280357151726585e-05,0.0389125825165033,449.48021391141646,37.35564952072437,3.4059565494042934
1.5378390740000293e-05,0.039162232446489295,450.0853377656375,37.35564952072437,3.4059565494042934
1.5551834780792242e-05,0.03960392078415684,451.152268946528,37.35564952072437,3.4059565494042934
1.558954000705136e-05,0.039699939987997604,451.38359527691216,37.35564952072437,3.4059565494042934
1.5627245233310477e-05,0.03979595919183837,451.61470350832315,37.35564952072437,3.4059565494042934
1.614757735568631e-05,0.04112102420484097,454.7821109514137,37.35564952072437,3.4059565494042934
1.6336103486981907e-05,0.041601120224044816,455.91986563027,37.35564952072437,3.4059565494042934
1.6532170663529323e-05,0.04210042008401681,457.0977115840321,37.35564952072437,3.4059565494042934
1.6637745297054856e-05,0.04236927385477096,457.72967926631856,37.35564952072437,3.4059565494042934
1.6690532613817617e-05,0.04250370074014803,458.0450764848218,37.35564952072437,3.4059565494042934
1.691676397137233e-05,0.043079815963192644,459.3923962425446,37.35564952072437,3.4059565494042934
1.7173159509934334e-05,0.043732746549309864,460.91089250671746,37.35564952072437,3.4059565494042934
1.7301357279215333e-05,0.04405921184236847,461.66682308284464,37.35564952072437,3.4059565494042934
1.7339062505474457e-05,0.04415523104620925,461.88873946578786,37.35564952072437,3.4059565494042934
1.7685950587058342e-05,0.045038607721544305,463.9216154375818,37.35564952072437,3.4059565494042934
1.8032838668642234e-05,0.045921984396879376,465.9389993328596,37.35564952072437,3.4059565494042934
1.8093167030656824e-05,0.046075615123024605,466.2882981048456,37.35564952072437,3.4059565494042934
1.8236446890441474e-05,0.046440488097619526,467.1160672753035,37.35564952072437,3.4059565494042934
1.830431629770789e-05,0.046613322664532914,467.5072828325615,37.35564952072437,3.4059565494042934
1.836464465972248e-05,0.04676695339067814,467.8545553209328,37.35564952072437,3.4059565494042934
1.8477760338499833e-05,0.04705501100220044,468.5044944155801,37.35564952072437,3.4059565494042934
1.8507924519507125e-05,0.04713182636527305,468.6775492075034,37.35564952072437,3.4059565494042934
1.8651204379291775e-05,0.04749669933986797,469.49806202774835,37.35564952072437,3.4059565494042934
1.879448423907643e-05,0.04786157231446289,470.3161202355606,37.35564952072437,3.4059565494042934
1.9043338732386613e-05,0.04849529905981197,471.73120085676703,37.35564952072437,3.4059565494042934
1.941284994972597e-05,0.049436287257451486,473.81914853096373,37.35564952072437,3.4059565494042934
1.957875294526609e-05,0.04985877175435087,474.75154669118325,37.35564952072437,3.4059565494042934
1.963908130728068e-05,0.0500124024804961,475.089835954738,37.35564952072437,3.4059565494042934
1.9903017891094512e-05,0.05068453690738148,476.56511183704487,37.35564952072437,3.4059565494042934
1.9918099981598157e-05,0.05072294458891778,476.64918211787193,37.35564952072437,3.4059565494042934
2.0091544022390106e-05,0.051164632926585324,477.61421272291835,37.35564952072437,3.4059565494042934
2.0114167158145572e-05,0.05122224444888977,477.73984631771924,37.35564952072437,3.4059565494042934
2.0566629873254997e-05,0.052374474894979,480.2410609417155,37.35564952072437,3.4059565494042934
2.058925300901047e-05,0.05243208641728346,480.3655552676561,37.35564952072437,3.4059565494042934
2.0649581371025057e-05,0.05258571714342869,480.69727959612555,37.35564952072437,3.4059565494042934
2.0709909733039647e-05,0.05273934786957392,481.02862617365184,37.35564952072437,3.4059565494042934
2.079286123080971e-05,0.05295059011802361,481.4836137275244,37.35564952072437,3.4059565494042934
2.0807943321313355e-05,0.052988997799559914,481.56626262557484,37.35564952072437,3.4059565494042934
2.114729035764542e-05,0.053853170634126826,483.41973119562095,37.35564952072437,3.4059565494042934
2.144893216771837e-05,0.05462132426485297,485.0575429226829,37.35564952072437,3.4059565494042934
2.1494178439229312e-05,0.0547365473094619,485.30243772657093,37.35564952072437,3.4059565494042934
2.1614835163258493e-05,0.055043808761752355,485.95450961549125,37.35564952072437,3.4059565494042934
2.1644999344265785e-05,0.05512062412482496,486.1173055888935,37.35564952072437,3.4059565494042934
2.1931559063835086e-05,0.055850370074014805,487.6594796462903,37.35564952072437,3.4059565494042934
2.222565982865621e-05,0.05659931986397279,489.234087528159,37.35564952072437,3.4059565494042934
2.2384021778944504e-05,0.057002600520104016,490.0785865918708,37.35564952072437,3.4059565494042934
2.2474514321966393e-05,0.057233046609321866,490.5601112807731,37.35564952072437,3.4059565494042934
2.251221954822551e-05,0.05732906581316263,490.7605233317116,37.35564952072437,3.4059565494042934
2.2602712091247396e-05,0.057559511902380484,491.24097889538115,37.35564952072437,3.4059565494042934
2.280632031304663e-05,0.05807801560312062,492.3192694916689,37.35564952072437,3.4059565494042934
2.295714121808311e-05,0.0584620924184837,493.11558432412954,37.35564952072437,3.4059565494042934
2.300992853484587e-05,0.05859651930386077,493.3938121572477,37.35564952072437,3.4059565494042934
2.3092880032615934e-05,0.05880776155231046,493.83052490984693,37.35564952072437,3.4059565494042934
2.3258783028156055e-05,0.059230246049209845,494.7021193469527,37.35564952072437,3.4059565494042934
2.337189870693341e-05,0.059518303660732144,495.2949985862632,37.35564952072437,3.4059565494042934
2.3477473340458943e-05,0.0597871574314863,495.8473436847172,37.35564952072437,3.4059565494042934
2.351517856671806e-05,0.059883176635327065,496.04437492397807,37.35564952072437,3.4059565494042934
2.3786656195783717e-05,0.0605745149029806,497.45938039764565,37.35564952072437,3.4059565494042934
2.3846984557798304e-05,0.06072814562912583,497.77296910744417,37.35564952072437,3.4059565494042934
2.399026441758295e-05,0.06109301860372074,498.51650489695066,37.35564952072437,3.4059565494042934
2.423157786564131e-05,0.061707541508301655,499.7648728777895,37.35564952072437,3.4059565494042934
2.4359775634922316e-05,0.06203400680136027,500.42609584064775,37.35564952072437,3.4059565494042934
2.453321967571426e-05,0.0624756951390278,501.31853553745566,37.35564952072437,3.4059565494042934
2.4684040580750734e-05,0.06285977195439088,502.0925717978668,37.35564952072437,3.4059565494042934
2.4804697304779912e-05,0.06316703340668134,502.71047361131895,37.35564952072437,3.4059565494042934
2.4940436119312737e-05,0.0635127025405081,503.4042137209558,37.35564952072437,3.4059565494042934
2.5151585386363803e-05,0.06405041008201641,504.48044530269135,37.35564952072437,3.4059565494042934
2.5272242110392984e-05,0.06435767153430687,505.09385266389774,37.35564952072437,3.4059565494042934
2.535519360816304e-05,0.06456891378275655,505.514907847987,37.35564952072437,3.4059565494042934
2.5792574232768818e-05,0.06568273654730947,507.7261952774174,37.35564952072437,3.4059565494042934
2.602634663557535e-05,0.06627805561112222,508.90209089452264,37.35564952072437,3.4059565494042934
2.613946231435271e-05,0.06656611322264454,509.46959324652374,37.35564952072437,3.4059565494042934
2.6245036947878236e-05,0.06683496699339868,509.998398603005,37.35564952072437,3.4059565494042934
2.6441104124425658e-05,0.06733426685337068,510.97826990964666,37.35564952072437,3.4059565494042934
2.6667335481980365e-05,0.06791038207641528,512.10537633849,37.35564952072437,3.4059565494042934
2.675782802500225e-05,0.06814082816563313,512.5551740221501,37.35564952072437,3.4059565494042934
2.696143624680149e-05,0.06865933186637328,513.5650553615599,37.35564952072437,3.4059565494042934
2.7044387744571552e-05,0.06887057411482297,513.9756352632537,37.35564952072437,3.4059565494042934
2.712733924234161e-05,0.06908181636327265,514.385724313072,37.35564952072437,3.4059565494042934
2.7210290740111672e-05,0.06929305861172234,514.795324596105,37.35564952072437,3.4059565494042934
2.7670294500472915e-05,0.07046449289857971,517.0579675471861,37.35564952072437,3.4059565494042934
2.797947735579769e-05,0.07125185037007402,518.5705222418786,37.35564952072437,3.4059565494042934
2.8069969898819575e-05,0.07148229645929187,519.0119862168879,37.35564952072437,3.4059565494042934
2.8250954984863346e-05,0.07194318863772756,519.8932525412624,37.35564952072437,3.4059565494042934
2.8296201256374282e-05,0.07205841168233647,520.1132247506825,37.35564952072437,3.4059565494042934
2.8431940070907114e-05,0.07240408081616324,520.7723197778845,37.35564952072437,3.4059565494042934
2.865817142846182e-05,0.07298019603920784,521.8680909348534,37.35564952072437,3.4059565494042934
2.8846697559757415e-05,0.07346029205841169,522.7786589070996,37.35564952072437,3.4059565494042934
2.934440654637778e-05,0.07472774554910983,525.1714758459599,37.35564952072437,3.4059565494042934
2.945752222515513e-05,0.07501580316063212,525.7130842974929,37.35564952072437,3.4059565494042934
2.954047372292519e-05,0.07522704540908182,526.1097484671715,37.35564952072437,3.4059565494042934
2.9585719994436137e-05,0.07534226845369074,526.3259276372232,37.35564952072437,3.4059565494042934
2.9668671492206197e-05,0.07555351070214043,526.721921533463,37.35564952072437,3.4059565494042934
2.9789328216235375e-05,0.07586077215443089,527.2971427162217,37.35564952072437,3.4059565494042934
2.9894902849760908e-05,0.07612962592518505,527.7997162966685,37.35564952072437,3.4059565494042934
3.0090970026308323e-05,0.07662892578515704,528.7312346268528,37.35564952072437,3.4059565494042934
3.0121134207315615e-05,0.07670574114822964,528.8743347668675,37.35564952072437,3.4059565494042934
3.0136216297819266e-05,0.07674414882976596,528.9458638777982,37.35564952072437,3.4059565494042934
3.0415234972136745e-05,0.07745469093818765,530.2666446003122,37.35564952072437,3.4059565494042934
3.0513268560410453e-05,0.07770434086817364,530.7295797912212,37.35564952072437,3.4059565494042934
3.059622005818051e-05,0.07791558311662333,531.1208413002141,37.35564952072437,3.4059565494042934
3.0686712601202395e-05,0.07814602920584117,531.5472005136826,37.35564952072437,3.4059565494042934
3.075458200846881e-05,0.07831886377275456,531.8666482088886,37.35564952072437,3.4059565494042934
3.093556709451258e-05,0.07877975595119024,532.7171674657403,37.35564952072437,3.4059565494042934
3.095819023026805e-05,0.07883736747349471,532.8233457567046,37.35564952072437,3.4059565494042934
3.0973272320771696e-05,0.07887577515503101,532.8941144730653,37.35564952072437,3.4059565494042934
3.135032458336288e-05,0.07983596719343869,534.6589884643874,37.35564952072437,3.4059565494042934
3.159163803142124e-05,0.0804504900980196,535.7841647931705,37.35564952072437,3.4059565494042934
3.168213057444312e-05,0.08068093618723746,536.2052411181758,37.35564952072437,3.4059565494042934
3.1915902977249656e-05,0.08127625525105021,537.2908563478837,37.35564952072437,3.4059565494042934
3.1983772384516075e-05,0.0814490898179636,537.605453524651,37.35564952072437,3.4059565494042934
3.2074264927537954e-05,0.08167953590718144,538.0245117319454,37.35564952072437,3.4059565494042934
3.216475747055984e-05,0.08190998199639929,538.4431090921851,37.35564952072437,3.4059565494042934
3.227033210408537e-05,0.08217883576715343,538.9308926220051,37.35564952072437,3.4059565494042934
3.2413611963870023e-05,0.08254370874174835,539.5918902524461,37.35564952072437,3.4059565494042934
3.25644328689065e-05,0.08292778555711143,540.2864473586525,37.35564952072437,3.4059565494042934
3.272279481919479e-05,0.08333106621324265,541.0143834598623,37.35564952072437,3.4059565494042934
3.279820527171303e-05,0.08352310462092419,541.3605366922648,37.35564952072437,3.4059565494042934
3.288869781473492e-05,0.08375355071014204,541.7755111203097,37.35564952072437,3.4059565494042934
3.306968290077868e-05,0.08421444288857773,542.6041264894432,37.35564952072437,3.4059565494042934
3.312247021754145e-05,0.0843488697739548,542.8454725799218,37.35564952072437,3.4059565494042934
3.32657500773261e-05,0.08471374274854972,543.4997998563767,37.35564952072437,3.4059565494042934
3.362017920416181e-05,0.08561632326465293,545.113694360394,37.35564952072437,3.4059565494042934
3.3695589656680046e-05,0.08580836167233447,545.4562185397667,37.35564952072437,3.4059565494042934
3.383132847121288e-05,0.08615403080616124,546.0720096324126,37.35564952072437,3.4059565494042934
3.393690310473841e-05,0.08642288457691538,546.550292332894,37.35564952072437,3.4059565494042934
3.410280610027853e-05,0.08684536907381477,547.3007087046825,37.35564952072437,3.4059565494042934
3.440444791035147e-05,0.08761352270454091,548.6614646329502,37.35564952072437,3.4059565494042934
3.4419530000855124e-05,0.08765193038607721,548.7293800275605,37.35564952072437,3.4059565494042934
3.4525104634380654e-05,0.08792078415683137,549.2044632395491,37.35564952072437,3.4059565494042934
3.463067926790619e-05,0.08818963792758552,549.6789802112868,37.35564952072437,3.4059565494042934
3.472117181092807e-05,0.08842008401680336,550.0852601814211,37.35564952072437,3.4059565494042934
3.488707480646819e-05,0.08884256851370274,550.8290358624898,37.35564952072437,3.4059565494042934
3.510576511877108e-05,0.0893994798959792,551.8073632522342,37.35564952072437,3.4059565494042934
3.52415039333039e-05,0.08974514902980596,552.4134055945476,37.35564952072437,3.4059565494042934
3.5256586023807554e-05,0.08978355671134228,552.480687389965,37.35564952072437,3.4059565494042934
3.5377242747836735e-05,0.09009081816363274,553.0185382491494,37.35564952072437,3.4059565494042934
3.539986588359221e-05,0.0901484296859372,553.1193055907814,37.35564952072437,3.4059565494042934
3.572413082942062e-05,0.09097419483896779,554.5608887919507,37.35564952072437,3.4059565494042934
3.5927739051219864e-05,0.09149269853970794,555.4634612693934,37.35564952072437,3.4059565494042934
3.6003149503738105e-05,0.09168473694738949,555.7972408531255,37.35564952072437,3.4059565494042934
3.607101891100451e-05,0.09185757151430286,556.0974094298027,37.35564952072437,3.4059565494042934
3.6161511454026396e-05,0.09208801760352071,556.497291789096,37.35564952072437,3.4059565494042934
3.6500858490358466e-05,0.09295219043808763,557.9933875180097,37.35564952072437,3.4059565494042934
3.6772336119424116e-05,0.09364352870574115,559.186362074986,37.35564952072437,3.4059565494042934
3.6998567476978826e-05,0.09421964392878576,560.1778859473553,37.35564952072437,3.4059565494042934
3.7051354793741595e-05,0.09435407081416283,560.4089009604879,37.35564952072437,3.4059565494042934
3.7164470472518954e-05,0.09464212842568515,560.9035013435241,37.35564952072437,3.4059565494042934
3.757922796136925e-05,0.09569833966793359,562.7120348175991,37.35564952072437,3.4059565494042934
3.76244742328802e-05,0.09581356271254252,562.9088573021742,37.35564952072437,3.4059565494042934
3.767726154964296e-05,0.09594798959791959,563.1383669019544,37.35564952072437,3.4059565494042934
3.7714966775902076e-05,0.09604400880176035,563.3022255583587,37.35564952072437,3.4059565494042934
3.7828082454679434e-05,0.09633206641328267,563.7934186264099,37.35564952072437,3.4059565494042934
3.8009067540723206e-05,0.09679295859171835,564.5781377295394,37.35564952072437,3.4059565494042934
3.8054313812234145e-05,0.09690818163632726,564.7740896439469,37.35564952072437,3.4059565494042934
3.815234740050785e-05,0.09715783156631327,565.1983406824875,37.35564952072437,3.4059565494042934
3.825038098878156e-05,0.09740748149629927,565.6221667844281,37.35564952072437,3.4059565494042934
3.847661234633627e-05,0.09798359671934387,566.5986134956646,37.35564952072437,3.4059565494042934
3.857464593460998e-05,0.09823324664932986,567.0210447671674,37.35564952072437,3.4059565494042934
3.886120565417928e-05,0.0989629925985197,568.2534498040187,37.35564952072437,3.4059565494042934
3.90271086497194e-05,0.09938547709541909,568.9653275249387,37.35564952072437,3.4059565494042934